{"_local_timestamp": "2026-01-25T23:40:30.899360+00:00", "data": [{"market": "0x0bde18e0a0220d1f97173850504a1ed4fa90ef2c6a7bc0932952790053ca0c0e", "asset_id": "4041912122563547970024635557261696068618666839090786586996637505354743961673", "timestamp": "1769384426105", "hash": "0533f7c868bedfe749bf5378191afc5b80fb69e4", "bids": [{"price": "0.01", "size": "4500"}, {"price": "0.02", "size": "11.11"}, {"price": "0.03", "size": "2400"}, {"price": "0.05", "size": "680"}, {"price": "0.07", "size": "457.14"}, {"price": "0.08", "size": "1000"}, {"price": "0.09", "size": "561.11"}, {"price": "0.11", "size": "236.36"}, {"price": "0.12", "size": "200"}, {"price": "0.14", "size": "142.85"}, {"price": "0.15", "size": "406"}, {"price": "0.19", "size": "300"}, {"price": "0.2", "size": "6"}, {"price": "0.24", "size": "6"}, {"price": "0.26", "size": "76"}, {"price": "0.28", "size": "150"}, {"price": "0.29", "size": "154"}, {"price": "0.3", "size": "448.5"}, {"price": "0.31", "size": "81.42"}], "asks": [{"price": "0.99", "size": "5511.11"}, {"price": "0.98", "size": "2200"}, {"price": "0.97", "size": "8.57"}, {"price": "0.93", "size": "1514.28"}, {"price": "0.92", "size": "6.42"}, {"price": "0.89", "size": "859.09"}, {"price": "0.85", "size": "213.33"}, {"price": "0.84", "size": "1000"}, {"price": "0.82", "size": "155.55"}, {"price": "0.81", "size": "2660"}, {"price": "0.8", "size": "5.59"}, {"price": "0.78", "size": "268.18"}, {"price": "0.74", "size": "92.3"}, {"price": "0.71", "size": "3426.96"}, {"price": "0.7", "size": "300"}, {"price": "0.69", "size": "6"}, {"price": "0.66", "size": "125"}, {"price": "0.64", "size": "6"}, {"price": "0.52", "size": "150"}, {"price": "0.51", "size": "26"}, {"price": "0.43", "size": "6"}, {"price": "0.39", "size": "126.2"}, {"price": "0.37", "size": "56"}, {"price": "0.36", "size": "345"}, {"price": "0.35", "size": "645"}], "event_type": "book", "last_trade_price": "0.300"}, {"market": "0x1586e33dc57b17433d080829870d73631a146b24d44d73817634c9f7171f84c3", "asset_id": "45761844533847615095657975499649554423516098382359546239787965241599216489110", "timestamp": "1769383854488", "hash": "a121eeac10703b55cb6ace69fb8c25e57731e45a", "bids": [{"price": "0.001", "size": "18408.03"}], "asks": [{"price": "0.999", "size": "3804.52"}, {"price": "0.998", "size": "1384.23"}, {"price": "0.997", "size": "1406.96"}, {"price": "0.994", "size": "200"}, {"price": "0.993", "size": "10.25"}, {"price": "0.99", "size": "5510"}, {"price": "0.98", "size": "2200"}, {"price": "0.979", "size": "9.2"}, {"price": "0.95", "size": "30"}, {"price": "0.949", "size": "39"}, {"price": "0.94", "size": "500"}, {"price": "0.939", "size": "9.15"}, {"price": "0.9", "size": "860"}, {"price": "0.85", "size": "826.66"}, {"price": "0.8", "size": "560"}, {"price": "0.799", "size": "5.69"}, {"price": "0.75", "size": "212"}, {"price": "0.749", "size": "4659"}, {"price": "0.7", "size": "186.66"}, {"price": "0.65", "size": "68.57"}, {"price": "0.61", "size": "750"}, {"price": "0.6", "size": "50"}, {"price": "0.599", "size": "122"}, {"price": "0.59", "size": "5"}, {"price": "0.277", "size": "55"}, {"price": "0.22", "size": "150"}, {"price": "0.219", "size": "13.33"}, {"price": "0.218", "size": "20"}, {"price": "0.049", "size": "5"}, {"price": "0.005", "size": "184"}, {"price": "0.004", "size": "6.63"}, {"price": "0.003", "size": "599.27"}], "event_type": "book", "last_trade_price": "0.002"}, {"market": "0xca0329cd4392d91e39df0702949229573d2415ae4a37b0103d0c6e9d03b8dd44", "asset_id": "20535370510756332462433575263109694145574231213604117747907874615324086102913", "timestamp": "1769384426831", "hash": "b781af275854731f7b63f3620768c3799e30bc5b", "bids": [{"price": "0.01", "size": "5510.61"}, {"price": "0.02", "size": "2200"}, {"price": "0.03", "size": "5.31"}, {"price": "0.05", "size": "10"}, {"price": "0.06", "size": "500"}, {"price": "0.09", "size": "6.44"}, {"price": "0.1", "size": "1000"}, {"price": "0.15", "size": "550"}, {"price": "0.2", "size": "1250"}, {"price": "0.21", "size": "2003.5"}, {"price": "0.22", "size": "300"}, {"price": "0.27", "size": "100"}, {"price": "0.36", "size": "3145"}, {"price": "0.37", "size": "300"}, {"price": "0.39", "size": "175"}, {"price": "0.4", "size": "5"}, {"price": "0.43", "size": "41.9"}, {"price": "0.65", "size": "549.26"}, {"price": "0.71", "size": "69.05"}, {"price": "0.72", "size": "20"}, {"price": "0.76", "size": "51"}, {"price": "0.77", "size": "621"}, {"price": "0.78", "size": "74"}, {"price": "0.79", "size": "45.28"}], "asks": [{"price": "0.95", "size": "250"}, {"price": "0.92", "size": "500"}, {"price": "0.86", "size": "850"}, {"price": "0.85", "size": "500"}, {"price": "0.83", "size": "331.12"}, {"price": "0.82", "size": "840"}], "event_type": "book", "last_trade_price": "0.790"}, {"market": "0xc1c30becf85027a3fad693fe00aed610c574220f32fabef52c1ac53f76153622", "asset_id": "44162996630579613944619329601086604585114580039271806622718850166081603488312", "timestamp": "1769383854488", "hash": "389938093f7dc0eb75092f914236407878f22786", "bids": [{"price": "0.001", "size": "20199.29"}], "asks": [{"price": "0.999", "size": "3804.52"}, {"price": "0.998", "size": "1384.23"}, {"price": "0.997", "size": "1407"}, {"price": "0.994", "size": "200"}, {"price": "0.993", "size": "10.25"}, {"price": "0.99", "size": "5500"}, {"price": "0.98", "size": "2200"}, {"price": "0.979", "size": "9.28"}, {"price": "0.95", "size": "30"}, {"price": "0.949", "size": "39"}, {"price": "0.94", "size": "500"}, {"price": "0.939", "size": "9.15"}, {"price": "0.9", "size": "860"}, {"price": "0.85", "size": "776.66"}, {"price": "0.849", "size": "250"}, {"price": "0.8", "size": "660"}, {"price": "0.799", "size": "5.69"}, {"price": "0.75", "size": "362"}, {"price": "0.7", "size": "186.66"}, {"price": "0.65", "size": "68.57"}, {"price": "0.6", "size": "175"}, {"price": "0.248", "size": "3160"}, {"price": "0.22", "size": "150"}, {"price": "0.219", "size": "13.33"}, {"price": "0.218", "size": "20"}, {"price": "0.049", "size": "5"}, {"price": "0.005", "size": "330.47"}, {"price": "0.004", "size": "313.42"}, {"price": "0.003", "size": "610.41"}], "event_type": "book", "last_trade_price": ""}, {"market": "0xc1c30becf85027a3fad693fe00aed610c574220f32fabef52c1ac53f76153622", "asset_id": "86861447014827130074018921138137988822291708295577507404133014397402508069192", "timestamp": "1769383854488", "hash": "4478ba5b2f2187621b5e766cc8e5ab0f7d75c88a", "bids": [{"price": "0.001", "size": "3804.52"}, {"price": "0.002", "size": "1384.23"}, {"price": "0.003", "size": "1407"}, {"price": "0.006", "size": "200"}, {"price": "0.007", "size": "10.25"}, {"price": "0.01", "size": "5500"}, {"price": "0.02", "size": "2200"}, {"price": "0.021", "size": "9.28"}, {"price": "0.05", "size": "30"}, {"price": "0.051", "size": "39"}, {"price": "0.06", "size": "500"}, {"price": "0.061", "size": "9.15"}, {"price": "0.1", "size": "860"}, {"price": "0.15", "size": "776.66"}, {"price": "0.151", "size": "250"}, {"price": "0.2", "size": "660"}, {"price": "0.201", "size": "5.69"}, {"price": "0.25", "size": "362"}, {"price": "0.3", "size": "186.66"}, {"price": "0.35", "size": "68.57"}, {"price": "0.4", "size": "175"}, {"price": "0.752", "size": "3160"}, {"price": "0.78", "size": "150"}, {"price": "0.781", "size": "13.33"}, {"price": "0.782", "size": "20"}, {"price": "0.951", "size": "5"}, {"price": "0.995", "size": "330.47"}, {"price": "0.996", "size": "313.42"}, {"price": "0.997", "size": "610.41"}], "asks": [{"price": "0.999", "size": "20199.29"}], "event_type": "book", "last_trade_price": ""}, {"market": "0x1586e33dc57b17433d080829870d73631a146b24d44d73817634c9f7171f84c3", "asset_id": "97767433523834028432607127801550560819898564541831537765726721529534335838453", "timestamp": "1769383854488", "hash": "2742872762280e735350301c4f76cced5c1204c9", "bids": [{"price": "0.001", "size": "3804.52"}, {"price": "0.002", "size": "1384.23"}, {"price": "0.003", "size": "1406.96"}, {"price": "0.006", "size": "200"}, {"price": "0.007", "size": "10.25"}, {"price": "0.01", "size": "5510"}, {"price": "0.02", "size": "2200"}, {"price": "0.021", "size": "9.2"}, {"price": "0.05", "size": "30"}, {"price": "0.051", "size": "39"}, {"price": "0.06", "size": "500"}, {"price": "0.061", "size": "9.15"}, {"price": "0.1", "size": "860"}, {"price": "0.15", "size": "826.66"}, {"price": "0.2", "size": "560"}, {"price": "0.201", "size": "5.69"}, {"price": "0.25", "size": "212"}, {"price": "0.251", "size": "4659"}, {"price": "0.3", "size": "186.66"}, {"price": "0.35", "size": "68.57"}, {"price": "0.39", "size": "750"}, {"price": "0.4", "size": "50"}, {"price": "0.401", "size": "122"}, {"price": "0.41", "size": "5"}, {"price": "0.723", "size": "55"}, {"price": "0.78", "size": "150"}, {"price": "0.781", "size": "13.33"}, {"price": "0.782", "size": "20"}, {"price": "0.951", "size": "5"}, {"price": "0.995", "size": "184"}, {"price": "0.996", "size": "6.63"}, {"price": "0.997", "size": "599.27"}], "asks": [{"price": "0.999", "size": "18408.03"}], "event_type": "book", "last_trade_price": "0.002"}, {"market": "0x0bde18e0a0220d1f97173850504a1ed4fa90ef2c6a7bc0932952790053ca0c0e", "asset_id": "105325602140854796101190465907542426130401271786879982796716189175875071392057", "timestamp": "1769384426105", "hash": "b185b9f3c62cff7574196335205d3b0a8f992f11", "bids": [{"price": "0.01", "size": "5511.11"}, {"price": "0.02", "size": "2200"}, {"price": "0.03", "size": "8.57"}, {"price": "0.07", "size": "1514.28"}, {"price": "0.08", "size": "6.42"}, {"price": "0.11", "size": "859.09"}, {"price": "0.15", "size": "213.33"}, {"price": "0.16", "size": "1000"}, {"price": "0.18", "size": "155.55"}, {"price": "0.19", "size": "2660"}, {"price": "0.2", "size": "5.59"}, {"price": "0.22", "size": "268.18"}, {"price": "0.26", "size": "92.3"}, {"price": "0.29", "size": "3426.96"}, {"price": "0.3", "size": "300"}, {"price": "0.31", "size": "6"}, {"price": "0.34", "size": "125"}, {"price": "0.36", "size": "6"}, {"price": "0.48", "size": "150"}, {"price": "0.49", "size": "26"}, {"price": "0.57", "size": "6"}, {"price": "0.61", "size": "126.2"}, {"price": "0.63", "size": "56"}, {"price": "0.64", "size": "345"}, {"price": "0.65", "size": "645"}], "asks": [{"price": "0.99", "size": "4500"}, {"price": "0.98", "size": "11.11"}, {"price": "0.97", "size": "2400"}, {"price": "0.95", "size": "680"}, {"price": "0.93", "size": "457.14"}, {"price": "0.92", "size": "1000"}, {"price": "0.91", "size": "561.11"}, {"price": "0.89", "size": "236.36"}, {"price": "0.88", "size": "200"}, {"price": "0.86", "size": "142.85"}, {"price": "0.85", "size": "406"}, {"price": "0.81", "size": "300"}, {"price": "0.8", "size": "6"}, {"price": "0.76", "size": "6"}, {"price": "0.74", "size": "76"}, {"price": "0.72", "size": "150"}, {"price": "0.71", "size": "154"}, {"price": "0.7", "size": "448.5"}, {"price": "0.69", "size": "81.42"}], "event_type": "book", "last_trade_price": "0.300"}, {"market": "0x49d0b554fffebaabd8f70e7088c51ee132b36b51979687c5775fe1d39e6009df", "asset_id": "19835581196144925594226241068229934006876264875869838825630024545913250806260", "timestamp": "1769384156718", "hash": "bfad01539f6a69bedf770ba711171dc2824dd011", "bids": [{"price": "0.001", "size": "21311.03"}], "asks": [{"price": "0.999", "size": "3804.52"}, {"price": "0.998", "size": "1384.23"}, {"price": "0.997", "size": "1406.96"}, {"price": "0.994", "size": "200"}, {"price": "0.993", "size": "10.25"}, {"price": "0.99", "size": "5500"}, {"price": "0.98", "size": "2220"}, {"price": "0.979", "size": "9.2"}, {"price": "0.95", "size": "30"}, {"price": "0.949", "size": "39"}, {"price": "0.94", "size": "500"}, {"price": "0.939", "size": "9.15"}, {"price": "0.9", "size": "860"}, {"price": "0.85", "size": "776.66"}, {"price": "0.849", "size": "300"}, {"price": "0.8", "size": "660"}, {"price": "0.799", "size": "5.69"}, {"price": "0.75", "size": "362"}, {"price": "0.7", "size": "186.66"}, {"price": "0.65", "size": "68.57"}, {"price": "0.6", "size": "175"}, {"price": "0.477", "size": "43"}, {"price": "0.34", "size": "700"}, {"price": "0.339", "size": "3632"}, {"price": "0.338", "size": "5"}, {"price": "0.22", "size": "150"}, {"price": "0.177", "size": "44"}, {"price": "0.176", "size": "20"}, {"price": "0.077", "size": "192"}, {"price": "0.049", "size": "5"}, {"price": "0.005", "size": "513.99"}, {"price": "0.004", "size": "154.59"}, {"price": "0.003", "size": "252.86"}], "event_type": "book", "last_trade_price": "0.002"}, {"market": "0xc5452a97769a9aa7a264d11bf07c7da6ff6080061d426cd7ef92abb47f6d8160", "asset_id": "8922710639437477954990654098858414058444921382508505451184351067105680225969", "timestamp": "1769383921272", "hash": "eafde5630a5c1aeb7339d8fd7b9aa7025c300962", "bids": [{"price": "0.001", "size": "19219.35"}, {"price": "0.002", "size": "5"}], "asks": [{"price": "0.999", "size": "3804.51"}, {"price": "0.998", "size": "1384.23"}, {"price": "0.997", "size": "1406.96"}, {"price": "0.994", "size": "200"}, {"price": "0.993", "size": "10.24"}, {"price": "0.99", "size": "5500"}, {"price": "0.98", "size": "2200"}, {"price": "0.979", "size": "9.2"}, {"price": "0.95", "size": "30"}, {"price": "0.949", "size": "39"}, {"price": "0.94", "size": "500"}, {"price": "0.939", "size": "9.15"}, {"price": "0.9", "size": "860"}, {"price": "0.85", "size": "826.66"}, {"price": "0.81", "size": "400"}, {"price": "0.8", "size": "160"}, {"price": "0.799", "size": "5.69"}, {"price": "0.75", "size": "412"}, {"price": "0.7", "size": "186.66"}, {"price": "0.66", "size": "50"}, {"price": "0.65", "size": "68.57"}, {"price": "0.6", "size": "50"}, {"price": "0.565", "size": "5"}, {"price": "0.563", "size": "5444"}, {"price": "0.562", "size": "360"}, {"price": "0.23", "size": "150"}, {"price": "0.128", "size": "13.33"}, {"price": "0.127", "size": "13.33"}, {"price": "0.126", "size": "20"}, {"price": "0.005", "size": "419"}, {"price": "0.004", "size": "8.3"}, {"price": "0.003", "size": "833.05"}], "event_type": "book", "last_trade_price": ""}, {"market": "0x91f7e7f2d3727a5abca7eb77827355f9a968f6636606c3f47f35ce2c23c91cbc", "asset_id": "84252679223362616378739922435722781121510894501012248080679822792405868493637", "timestamp": "1769384266958", "hash": "41dc0305947fbd1d17061898a456e2ae200fa17d", "bids": [{"price": "0.001", "size": "3805.52"}, {"price": "0.002", "size": "1384.23"}, {"price": "0.003", "size": "1406.96"}, {"price": "0.006", "size": "200"}, {"price": "0.007", "size": "10.25"}, {"price": "0.01", "size": "5500"}, {"price": "0.02", "size": "2200"}, {"price": "0.021", "size": "9.2"}, {"price": "0.05", "size": "30"}, {"price": "0.051", "size": "39"}, {"price": "0.06", "size": "500"}, {"price": "0.061", "size": "9.15"}, {"price": "0.1", "size": "860"}, {"price": "0.15", "size": "776.66"}, {"price": "0.2", "size": "660"}, {"price": "0.201", "size": "5.69"}, {"price": "0.25", "size": "312"}, {"price": "0.3", "size": "136.66"}, {"price": "0.327", "size": "3523"}, {"price": "0.328", "size": "300"}, {"price": "0.35", "size": "68.57"}, {"price": "0.4", "size": "175"}, {"price": "0.401", "size": "5"}, {"price": "0.798", "size": "203"}, {"price": "0.864", "size": "99.99"}, {"price": "0.865", "size": "20"}, {"price": "0.934", "size": "13"}, {"price": "0.996", "size": "8.47"}, {"price": "0.997", "size": "610.53"}], "asks": [{"price": "0.999", "size": "19321.45"}, {"price": "0.998", "size": "905"}], "event_type": "book", "last_trade_price": ""}, {"market": "0xa05f081e032395b4527d964fcefb032834c81bef0e85ac533c81f66139c35af4", "asset_id": "56813972039885211974321877112282829005950793706240260412507113757740359845360", "timestamp": "1769384373311", "hash": "b2d86020e90c9784b64bbe3488fab614dbb44d36", "bids": [{"price": "0.001", "size": "3727.51"}, {"price": "0.002", "size": "1384.23"}, {"price": "0.003", "size": "1406.96"}, {"price": "0.006", "size": "200"}, {"price": "0.007", "size": "10.24"}, {"price": "0.01", "size": "5500"}, {"price": "0.02", "size": "2200"}, {"price": "0.021", "size": "9.2"}, {"price": "0.05", "size": "30"}, {"price": "0.051", "size": "39"}, {"price": "0.06", "size": "500"}, {"price": "0.061", "size": "9.15"}, {"price": "0.1", "size": "860"}, {"price": "0.15", "size": "776.66"}, {"price": "0.2", "size": "660"}, {"price": "0.201", "size": "5.69"}, {"price": "0.25", "size": "362"}, {"price": "0.3", "size": "186.66"}, {"price": "0.34", "size": "50"}, {"price": "0.35", "size": "68.57"}, {"price": "0.4", "size": "50"}, {"price": "0.41", "size": "700"}, {"price": "0.411", "size": "5797"}, {"price": "0.412", "size": "360"}, {"price": "0.413", "size": "5"}, {"price": "0.78", "size": "150"}, {"price": "0.781", "size": "20"}, {"price": "0.935", "size": "13"}, {"price": "0.951", "size": "5"}, {"price": "0.995", "size": "329.07"}, {"price": "0.996", "size": "84.24"}, {"price": "0.997", "size": "838.79"}], "asks": [{"price": "0.999", "size": "15528.42"}], "event_type": "book", "last_trade_price": "0.001"}, {"market": "0xeb44a06c677ce7a47e5fd2007182e020a577395dc3613ad55d3d576e33964c3d", "asset_id": "5305471862219565371067835325573032839634510465603099489495163186843068331171", "timestamp": "1769384428049", "hash": "9a0995c14ccd452a489aafddbe6affe88922b89c", "bids": [{"price": "0.01", "size": "5512.65"}, {"price": "0.02", "size": "1000"}, {"price": "0.03", "size": "5.98"}, {"price": "0.05", "size": "1620"}, {"price": "0.06", "size": "10.2"}, {"price": "0.08", "size": "425"}, {"price": "0.09", "size": "2576"}, {"price": "0.11", "size": "290.9"}, {"price": "0.12", "size": "1882"}, {"price": "0.14", "size": "200"}, {"price": "0.15", "size": "2848"}, {"price": "0.16", "size": "700"}, {"price": "0.17", "size": "152.94"}, {"price": "0.18", "size": "6.01"}, {"price": "0.19", "size": "126.31"}, {"price": "0.22", "size": "90.9"}, {"price": "0.23", "size": "3514"}, {"price": "0.24", "size": "20"}, {"price": "0.49", "size": "287"}, {"price": "0.5", "size": "2426"}], "asks": [{"price": "0.99", "size": "5500"}, {"price": "0.98", "size": "5217"}, {"price": "0.97", "size": "7.4"}, {"price": "0.95", "size": "720"}, {"price": "0.93", "size": "985.71"}, {"price": "0.91", "size": "355.55"}, {"price": "0.9", "size": "2100"}, {"price": "0.88", "size": "233.33"}, {"price": "0.87", "size": "3830"}, {"price": "0.86", "size": "185.71"}, {"price": "0.84", "size": "250"}, {"price": "0.82", "size": "411.11"}, {"price": "0.81", "size": "180"}, {"price": "0.8", "size": "100"}, {"price": "0.67", "size": "100"}, {"price": "0.58", "size": "101"}, {"price": "0.55", "size": "236.48"}, {"price": "0.54", "size": "134.49"}], "event_type": "book", "last_trade_price": ""}, {"market": "0x49d0b554fffebaabd8f70e7088c51ee132b36b51979687c5775fe1d39e6009df", "asset_id": "101417798695348023730451223679149302603865990290677002526337951186193092407966", "timestamp": "1769384156718", "hash": "3a138c5457ab688336162bf5aff062b5b96996ad", "bids": [{"price": "0.001", "size": "3804.52"}, {"price": "0.002", "size": "1384.23"}, {"price": "0.003", "size": "1406.96"}, {"price": "0.006", "size": "200"}, {"price": "0.007", "size": "10.25"}, {"price": "0.01", "size": "5500"}, {"price": "0.02", "size": "2220"}, {"price": "0.021", "size": "9.2"}, {"price": "0.05", "size": "30"}, {"price": "0.051", "size": "39"}, {"price": "0.06", "size": "500"}, {"price": "0.061", "size": "9.15"}, {"price": "0.1", "size": "860"}, {"price": "0.15", "size": "776.66"}, {"price": "0.151", "size": "300"}, {"price": "0.2", "size": "660"}, {"price": "0.201", "size": "5.69"}, {"price": "0.25", "size": "362"}, {"price": "0.3", "size": "186.66"}, {"price": "0.35", "size": "68.57"}, {"price": "0.4", "size": "175"}, {"price": "0.523", "size": "43"}, {"price": "0.66", "size": "700"}, {"price": "0.661", "size": "3632"}, {"price": "0.662", "size": "5"}, {"price": "0.78", "size": "150"}, {"price": "0.823", "size": "44"}, {"price": "0.824", "size": "20"}, {"price": "0.923", "size": "192"}, {"price": "0.951", "size": "5"}, {"price": "0.995", "size": "513.99"}, {"price": "0.996", "size": "154.59"}, {"price": "0.997", "size": "252.86"}], "asks": [{"price": "0.999", "size": "21311.03"}], "event_type": "book", "last_trade_price": "0.002"}, {"market": "0xeb44a06c677ce7a47e5fd2007182e020a577395dc3613ad55d3d576e33964c3d", "asset_id": "28227838360096074788232992585368970461718254845788738931649369286727917170476", "timestamp": "1769384428049", "hash": "c55413970e6ef1973d5a1b065a199725d3004863", "bids": [{"price": "0.01", "size": "5500"}, {"price": "0.02", "size": "5217"}, {"price": "0.03", "size": "7.4"}, {"price": "0.05", "size": "720"}, {"price": "0.07", "size": "985.71"}, {"price": "0.09", "size": "355.55"}, {"price": "0.1", "size": "2100"}, {"price": "0.12", "size": "233.33"}, {"price": "0.13", "size": "3830"}, {"price": "0.14", "size": "185.71"}, {"price": "0.16", "size": "250"}, {"price": "0.18", "size": "411.11"}, {"price": "0.19", "size": "180"}, {"price": "0.2", "size": "100"}, {"price": "0.33", "size": "100"}, {"price": "0.42", "size": "101"}, {"price": "0.45", "size": "236.48"}, {"price": "0.46", "size": "134.49"}], "asks": [{"price": "0.99", "size": "5512.65"}, {"price": "0.98", "size": "1000"}, {"price": "0.97", "size": "5.98"}, {"price": "0.95", "size": "1620"}, {"price": "0.94", "size": "10.2"}, {"price": "0.92", "size": "425"}, {"price": "0.91", "size": "2576"}, {"price": "0.89", "size": "290.9"}, {"price": "0.88", "size": "1882"}, {"price": "0.86", "size": "200"}, {"price": "0.85", "size": "2848"}, {"price": "0.84", "size": "700"}, {"price": "0.83", "size": "152.94"}, {"price": "0.82", "size": "6.01"}, {"price": "0.81", "size": "126.31"}, {"price": "0.78", "size": "90.9"}, {"price": "0.77", "size": "3514"}, {"price": "0.76", "size": "20"}, {"price": "0.51", "size": "287"}, {"price": "0.5", "size": "2426"}], "event_type": "book", "last_trade_price": ""}, {"market": "0x91f7e7f2d3727a5abca7eb77827355f9a968f6636606c3f47f35ce2c23c91cbc", "asset_id": "43986832901480115975770598885448914644973339441868156495326187103850202425816", "timestamp": "1769384266958", "hash": "018c219991d8974c19a425bd939df3a6e28ce299", "bids": [{"price": "0.001", "size": "19321.45"}, {"price": "0.002", "size": "905"}], "asks": [{"price": "0.999", "size": "3805.52"}, {"price": "0.998", "size": "1384.23"}, {"price": "0.997", "size": "1406.96"}, {"price": "0.994", "size": "200"}, {"price": "0.993", "size": "10.25"}, {"price": "0.99", "size": "5500"}, {"price": "0.98", "size": "2200"}, {"price": "0.979", "size": "9.2"}, {"price": "0.95", "size": "30"}, {"price": "0.949", "size": "39"}, {"price": "0.94", "size": "500"}, {"price": "0.939", "size": "9.15"}, {"price": "0.9", "size": "860"}, {"price": "0.85", "size": "776.66"}, {"price": "0.8", "size": "660"}, {"price": "0.799", "size": "5.69"}, {"price": "0.75", "size": "312"}, {"price": "0.7", "size": "136.66"}, {"price": "0.673", "size": "3523"}, {"price": "0.672", "size": "300"}, {"price": "0.65", "size": "68.57"}, {"price": "0.6", "size": "175"}, {"price": "0.599", "size": "5"}, {"price": "0.202", "size": "203"}, {"price": "0.136", "size": "99.99"}, {"price": "0.135", "size": "20"}, {"price": "0.066", "size": "13"}, {"price": "0.004", "size": "8.47"}, {"price": "0.003", "size": "610.53"}], "event_type": "book", "last_trade_price": ""}, {"market": "0xc5452a97769a9aa7a264d11bf07c7da6ff6080061d426cd7ef92abb47f6d8160", "asset_id": "114340618694795548048032631237414556707214948596108879651552052673573136118536", "timestamp": "1769383921272", "hash": "0a14b7584f40de7826f1b2010f660ab70e8869d1", "bids": [{"price": "0.001", "size": "3804.51"}, {"price": "0.002", "size": "1384.23"}, {"price": "0.003", "size": "1406.96"}, {"price": "0.006", "size": "200"}, {"price": "0.007", "size": "10.24"}, {"price": "0.01", "size": "5500"}, {"price": "0.02", "size": "2200"}, {"price": "0.021", "size": "9.2"}, {"price": "0.05", "size": "30"}, {"price": "0.051", "size": "39"}, {"price": "0.06", "size": "500"}, {"price": "0.061", "size": "9.15"}, {"price": "0.1", "size": "860"}, {"price": "0.15", "size": "826.66"}, {"price": "0.19", "size": "400"}, {"price": "0.2", "size": "160"}, {"price": "0.201", "size": "5.69"}, {"price": "0.25", "size": "412"}, {"price": "0.3", "size": "186.66"}, {"price": "0.34", "size": "50"}, {"price": "0.35", "size": "68.57"}, {"price": "0.4", "size": "50"}, {"price": "0.435", "size": "5"}, {"price": "0.437", "size": "5444"}, {"price": "0.438", "size": "360"}, {"price": "0.77", "size": "150"}, {"price": "0.872", "size": "13.33"}, {"price": "0.873", "size": "13.33"}, {"price": "0.874", "size": "20"}, {"price": "0.995", "size": "419"}, {"price": "0.996", "size": "8.3"}, {"price": "0.997", "size": "833.05"}], "asks": [{"price": "0.999", "size": "19219.35"}, {"price": "0.998", "size": "5"}], "event_type": "book", "last_trade_price": ""}, {"market": "0xca0329cd4392d91e39df0702949229573d2415ae4a37b0103d0c6e9d03b8dd44", "asset_id": "74768395815166461619548348007728690058055087254143355558596876906836785272025", "timestamp": "1769384426831", "hash": "fcc91f1b2421bdf42bf82368dde505f9200478ec", "bids": [{"price": "0.05", "size": "250"}, {"price": "0.08", "size": "500"}, {"price": "0.14", "size": "850"}, {"price": "0.15", "size": "500"}, {"price": "0.17", "size": "331.12"}, {"price": "0.18", "size": "840"}], "asks": [{"price": "0.99", "size": "5510.61"}, {"price": "0.98", "size": "2200"}, {"price": "0.97", "size": "5.31"}, {"price": "0.95", "size": "10"}, {"price": "0.94", "size": "500"}, {"price": "0.91", "size": "6.44"}, {"price": "0.9", "size": "1000"}, {"price": "0.85", "size": "550"}, {"price": "0.8", "size": "1250"}, {"price": "0.79", "size": "2003.5"}, {"price": "0.78", "size": "300"}, {"price": "0.73", "size": "100"}, {"price": "0.64", "size": "3145"}, {"price": "0.63", "size": "300"}, {"price": "0.61", "size": "175"}, {"price": "0.6", "size": "5"}, {"price": "0.57", "size": "41.9"}, {"price": "0.35", "size": "549.26"}, {"price": "0.29", "size": "69.05"}, {"price": "0.28", "size": "20"}, {"price": "0.24", "size": "51"}, {"price": "0.23", "size": "621"}, {"price": "0.22", "size": "74"}, {"price": "0.21", "size": "45.28"}], "event_type": "book", "last_trade_price": "0.790"}, {"market": "0xa05f081e032395b4527d964fcefb032834c81bef0e85ac533c81f66139c35af4", "asset_id": "69074333464069151404242315526218405459784935747253869832659873168984248759799", "timestamp": "1769384373311", "hash": "03941a3172b8f9600f6176c4aa2a757a53cde185", "bids": [{"price": "0.001", "size": "15528.42"}], "asks": [{"price": "0.999", "size": "3727.51"}, {"price": "0.998", "size": "1384.23"}, {"price": "0.997", "size": "1406.96"}, {"price": "0.994", "size": "200"}, {"price": "0.993", "size": "10.24"}, {"price": "0.99", "size": "5500"}, {"price": "0.98", "size": "2200"}, {"price": "0.979", "size": "9.2"}, {"price": "0.95", "size": "30"}, {"price": "0.949", "size": "39"}, {"price": "0.94", "size": "500"}, {"price": "0.939", "size": "9.15"}, {"price": "0.9", "size": "860"}, {"price": "0.85", "size": "776.66"}, {"price": "0.8", "size": "660"}, {"price": "0.799", "size": "5.69"}, {"price": "0.75", "size": "362"}, {"price": "0.7", "size": "186.66"}, {"price": "0.66", "size": "50"}, {"price": "0.65", "size": "68.57"}, {"price": "0.6", "size": "50"}, {"price": "0.59", "size": "700"}, {"price": "0.589", "size": "5797"}, {"price": "0.588", "size": "360"}, {"price": "0.587", "size": "5"}, {"price": "0.22", "size": "150"}, {"price": "0.219", "size": "20"}, {"price": "0.065", "size": "13"}, {"price": "0.049", "size": "5"}, {"price": "0.005", "size": "329.07"}, {"price": "0.004", "size": "84.24"}, {"price": "0.003", "size": "838.79"}], "event_type": "book", "last_trade_price": "0.001"}]}
{"_local_timestamp": "2026-01-25T23:40:31.689280+00:00", "data": {"market": "0xeb44a06c677ce7a47e5fd2007182e020a577395dc3613ad55d3d576e33964c3d", "price_changes": [{"asset_id": "5305471862219565371067835325573032839634510465603099489495163186843068331171", "price": "0.12", "size": "1657", "side": "BUY", "hash": "acbaaaa1830b7c9c4c43fe25c33190686b6bc3e9", "best_bid": "0.5", "best_ask": "0.54"}, {"asset_id": "28227838360096074788232992585368970461718254845788738931649369286727917170476", "price": "0.88", "size": "1657", "side": "SELL", "hash": "5082ac586f26a886a2ecdd7cae7210e975b410bd", "best_bid": "0.46", "best_ask": "0.5"}], "timestamp": "1769384431616", "event_type": "price_change"}}
{"_local_timestamp": "2026-01-25T23:40:31.963212+00:00", "data": {"market": "0xeb44a06c677ce7a47e5fd2007182e020a577395dc3613ad55d3d576e33964c3d", "price_changes": [{"asset_id": "5305471862219565371067835325573032839634510465603099489495163186843068331171", "price": "0.15", "size": "3073", "side": "BUY", "hash": "037d2262c05f3a141678d4dc38691a7dd9c4de88", "best_bid": "0.5", "best_ask": "0.54"}, {"asset_id": "28227838360096074788232992585368970461718254845788738931649369286727917170476", "price": "0.85", "size": "3073", "side": "SELL", "hash": "8e23488faec4c1d3cae16e8d6e694bb9a16d3a47", "best_bid": "0.46", "best_ask": "0.5"}], "timestamp": "1769384431887", "event_type": "price_change"}}
{"_local_timestamp": "2026-01-25T23:40:45.113742+00:00", "data": {"market": "0x0bde18e0a0220d1f97173850504a1ed4fa90ef2c6a7bc0932952790053ca0c0e", "price_changes": [{"asset_id": "4041912122563547970024635557261696068618666839090786586996637505354743961673", "price": "0.35", "size": "619", "side": "SELL", "hash": "dacae3fadcec731d78a116efdbc2dbad31ca9359", "best_bid": "0.31", "best_ask": "0.35"}, {"asset_id": "105325602140854796101190465907542426130401271786879982796716189175875071392057", "price": "0.65", "size": "619", "side": "BUY", "hash": "0bc745bd90d55fa7517460aaaeacdcdea4cd17b3", "best_bid": "0.65", "best_ask": "0.69"}], "timestamp": "1769384445004", "event_type": "price_change"}}
{"_local_timestamp": "2026-01-25T23:40:53.268989+00:00", "data": {"market": "0xeb44a06c677ce7a47e5fd2007182e020a577395dc3613ad55d3d576e33964c3d", "price_changes": [{"asset_id": "28227838360096074788232992585368970461718254845788738931649369286727917170476", "price": "0.13", "size": "3780", "side": "BUY", "hash": "f9033e5146f3b2589fdda8eb21726c3dbacb389c", "best_bid": "0.46", "best_ask": "0.5"}, {"asset_id": "5305471862219565371067835325573032839634510465603099489495163186843068331171", "price": "0.87", "size": "3780", "side": "SELL", "hash": "2f94f1d2a17821c9b2cc151e4c980eda4f6ae37e", "best_bid": "0.5", "best_ask": "0.54"}], "timestamp": "1769384453198", "event_type": "price_change"}}
{"_local_timestamp": "2026-01-25T23:40:53.571336+00:00", "data": {"market": "0xeb44a06c677ce7a47e5fd2007182e020a577395dc3613ad55d3d576e33964c3d", "price_changes": [{"asset_id": "28227838360096074788232992585368970461718254845788738931649369286727917170476", "price": "0.2", "size": "150", "side": "BUY", "hash": "c10327df1feff41e6c5aac0fdaf66d906e1132b7", "best_bid": "0.46", "best_ask": "0.5"}, {"asset_id": "5305471862219565371067835325573032839634510465603099489495163186843068331171", "price": "0.8", "size": "150", "side": "SELL", "hash": "77258f5bf9abc31d116e730d89f53d49a175a8a1", "best_bid": "0.5", "best_ask": "0.54"}], "timestamp": "1769384453498", "event_type": "price_change"}}
{"_local_timestamp": "2026-01-25T23:41:06.791251+00:00", "data": {"market": "0xc1c30becf85027a3fad693fe00aed610c574220f32fabef52c1ac53f76153622", "price_changes": [{"asset_id": "44162996630579613944619329601086604585114580039271806622718850166081603488312", "price": "0.001", "size": "20099.29", "side": "BUY", "hash": "0cd4097570ac8b8b0a0e12bb6e15f3f88e2d5104", "best_bid": "0.001", "best_ask": "0.003"}, {"asset_id": "86861447014827130074018921138137988822291708295577507404133014397402508069192", "price": "0.999", "size": "20099.29", "side": "SELL", "hash": "5a2ee879780e2e7b184dff83b5799e2d45539a44", "best_bid": "0.997", "best_ask": "0.999"}], "timestamp": "1769384466646", "event_type": "price_change"}}
{"_local_timestamp": "2026-01-25T23:41:06.799842+00:00", "data": {"market": "0xa05f081e032395b4527d964fcefb032834c81bef0e85ac533c81f66139c35af4", "price_changes": [{"asset_id": "69074333464069151404242315526218405459784935747253869832659873168984248759799", "price": "0.001", "size": "15428.42", "side": "BUY", "hash": "61894bb2d14af5a274c91bac65d6ba1febcf60b4", "best_bid": "0.001", "best_ask": "0.003"}, {"asset_id": "56813972039885211974321877112282829005950793706240260412507113757740359845360", "price": "0.999", "size": "15428.42", "side": "SELL", "hash": "f0f0f7bc838f8f84002109d73d8546846486f96c", "best_bid": "0.997", "best_ask": "0.999"}], "timestamp": "1769384466640", "event_type": "price_change"}}
{"_local_timestamp": "2026-01-25T23:41:06.838318+00:00", "data": {"market": "0x91f7e7f2d3727a5abca7eb77827355f9a968f6636606c3f47f35ce2c23c91cbc", "price_changes": [{"asset_id": "43986832901480115975770598885448914644973339441868156495326187103850202425816", "price": "0.002", "size": "805", "side": "BUY", "hash": "344cb2d29c7bf432aae4d10696e7601e844f583a", "best_bid": "0.002", "best_ask": "0.003"}, {"asset_id": "84252679223362616378739922435722781121510894501012248080679822792405868493637", "price": "0.998", "size": "805", "side": "SELL", "hash": "b60b3f79fc049e84ba0201363790500572181dad", "best_bid": "0.997", "best_ask": "0.998"}], "timestamp": "1769384466648", "event_type": "price_change"}}
{"_local_timestamp": "2026-01-25T23:41:06.858083+00:00", "data": {"market": "0xc5452a97769a9aa7a264d11bf07c7da6ff6080061d426cd7ef92abb47f6d8160", "price_changes": [{"asset_id": "8922710639437477954990654098858414058444921382508505451184351067105680225969", "price": "0.001", "size": "19119.35", "side": "BUY", "hash": "67666e5f4038e7ef1fb93bb35badd0fe74279f89", "best_bid": "0.002", "best_ask": "0.003"}, {"asset_id": "114340618694795548048032631237414556707214948596108879651552052673573136118536", "price": "0.999", "size": "19119.35", "side": "SELL", "hash": "2f7fe3cdbf3017aa60a66375110de78e5a595e89", "best_bid": "0.997", "best_ask": "0.998"}], "timestamp": "1769384466649", "event_type": "price_change"}}
{"_local_timestamp": "2026-01-25T23:41:09.605438+00:00", "data": {"market": "0xca0329cd4392d91e39df0702949229573d2415ae4a37b0103d0c6e9d03b8dd44", "price_changes": [{"asset_id": "20535370510756332462433575263109694145574231213604117747907874615324086102913", "price": "0.22", "size": "200", "side": "BUY", "hash": "4d7cc201902be8a2cd18aed35eb30975498ef2ab", "best_bid": "0.79", "best_ask": "0.82"}, {"asset_id": "74768395815166461619548348007728690058055087254143355558596876906836785272025", "price": "0.78", "size": "200", "side": "SELL", "hash": "95088ed47de8acda536ad64236b79b96bc980a20", "best_bid": "0.18", "best_ask": "0.21"}], "timestamp": "1769384469533", "event_type": "price_change"}}
{"_local_timestamp": "2026-01-25T23:41:09.904122+00:00", "data": {"market": "0xeb44a06c677ce7a47e5fd2007182e020a577395dc3613ad55d3d576e33964c3d", "price_changes": [{"asset_id": "28227838360096074788232992585368970461718254845788738931649369286727917170476", "price": "0.21", "size": "100", "side": "BUY", "hash": "7abfd88c37db7a6065492ebdbb98ce6e3b7c9d0a", "best_bid": "0.46", "best_ask": "0.5"}, {"asset_id": "5305471862219565371067835325573032839634510465603099489495163186843068331171", "price": "0.79", "size": "100", "side": "SELL", "hash": "e2c31e30c2bab1fea6cd7c2f604cb9f389b60684", "best_bid": "0.5", "best_ask": "0.54"}], "timestamp": "1769384469806", "event_type": "price_change"}}
{"_local_timestamp": "2026-01-25T23:41:09.905645+00:00", "data": {"market": "0xca0329cd4392d91e39df0702949229573d2415ae4a37b0103d0c6e9d03b8dd44", "price_changes": [{"asset_id": "20535370510756332462433575263109694145574231213604117747907874615324086102913", "price": "0.21", "size": "2103.5", "side": "BUY", "hash": "6e8263f360518fae313aec71fd117fabdcce68c2", "best_bid": "0.79", "best_ask": "0.82"}, {"asset_id": "74768395815166461619548348007728690058055087254143355558596876906836785272025", "price": "0.79", "size": "2103.5", "side": "SELL", "hash": "bcd3db4cdb13416a0835c9432891a3448efb7480", "best_bid": "0.18", "best_ask": "0.21"}], "timestamp": "1769384469805", "event_type": "price_change"}}
{"_local_timestamp": "2026-01-25T23:41:14.667611+00:00", "data": {"market": "0xca0329cd4392d91e39df0702949229573d2415ae4a37b0103d0c6e9d03b8dd44", "price_changes": [{"asset_id": "20535370510756332462433575263109694145574231213604117747907874615324086102913", "price": "0.21", "size": "105.5", "side": "BUY", "hash": "ce327264573d1ef9670308e24a4738da036fed0f", "best_bid": "0.79", "best_ask": "0.82"}, {"asset_id": "74768395815166461619548348007728690058055087254143355558596876906836785272025", "price": "0.79", "size": "105.5", "side": "SELL", "hash": "1ffb2e28be08afb321fbe2c5c5345cf2f8231530", "best_bid": "0.18", "best_ask": "0.21"}], "timestamp": "1769384474533", "event_type": "price_change"}}
{"_local_timestamp": "2026-01-25T23:41:23.504369+00:00", "data": {"market": "0xca0329cd4392d91e39df0702949229573d2415ae4a37b0103d0c6e9d03b8dd44", "price_changes": [{"asset_id": "20535370510756332462433575263109694145574231213604117747907874615324086102913", "price": "0.09", "size": "0", "side": "BUY", "hash": "f9d1e547269d5e11828ee34b79d5ce621d251499", "best_bid": "0.79", "best_ask": "0.82"}, {"asset_id": "74768395815166461619548348007728690058055087254143355558596876906836785272025", "price": "0.91", "size": "0", "side": "SELL", "hash": "a76c26a75a5189fcc9ef4b36f8591a39ebd46dc4", "best_bid": "0.18", "best_ask": "0.21"}], "timestamp": "1769384483436", "event_type": "price_change"}}
{"_local_timestamp": "2026-01-25T23:41:25.526496+00:00", "data": {"market": "0xca0329cd4392d91e39df0702949229573d2415ae4a37b0103d0c6e9d03b8dd44", "price_changes": [{"asset_id": "20535370510756332462433575263109694145574231213604117747907874615324086102913", "price": "0.07", "size": "8.28", "side": "BUY", "hash": "6103f9b8495f4f77fde6141c31be2d73ce81cfde", "best_bid": "0.79", "best_ask": "0.82"}, {"asset_id": "74768395815166461619548348007728690058055087254143355558596876906836785272025", "price": "0.93", "size": "8.28", "side": "SELL", "hash": "ba97f354322401ac27c10956ff80eae98216ea5f", "best_bid": "0.18", "best_ask": "0.21"}], "timestamp": "1769384485462", "event_type": "price_change"}}
{"_local_timestamp": "2026-01-25T23:41:46.173715+00:00", "data": {"market": "0xca0329cd4392d91e39df0702949229573d2415ae4a37b0103d0c6e9d03b8dd44", "price_changes": [{"asset_id": "20535370510756332462433575263109694145574231213604117747907874615324086102913", "price": "0.23", "size": "1826", "side": "BUY", "hash": "73077af74eee81d2ff9fdf9457ec3c4a447d1314", "best_bid": "0.79", "best_ask": "0.82"}, {"asset_id": "74768395815166461619548348007728690058055087254143355558596876906836785272025", "price": "0.77", "size": "1826", "side": "SELL", "hash": "91fc69a97c6a736d92df3c388be5a8e50e3d411c", "best_bid": "0.18", "best_ask": "0.21"}], "timestamp": "1769384506106", "event_type": "price_change"}}
{"_local_timestamp": "2026-01-25T23:41:49.353109+00:00", "data": {"market": "0x0bde18e0a0220d1f97173850504a1ed4fa90ef2c6a7bc0932952790053ca0c0e", "price_changes": [{"asset_id": "105325602140854796101190465907542426130401271786879982796716189175875071392057", "price": "0.7", "size": "222.09", "side": "SELL", "hash": "692adfe7f36b5a120637cdb664f53c2063450146", "best_bid": "0.65", "best_ask": "0.69"}, {"asset_id": "4041912122563547970024635557261696068618666839090786586996637505354743961673", "price": "0.3", "size": "222.09", "side": "BUY", "hash": "87dead5afcf783c1a724d1e6a92c9aede11669da", "best_bid": "0.31", "best_ask": "0.35"}], "timestamp": "1769384509284", "event_type": "price_change"}}
{"_local_timestamp": "2026-01-25T23:41:49.478891+00:00", "data": {"market": "0xca0329cd4392d91e39df0702949229573d2415ae4a37b0103d0c6e9d03b8dd44", "price_changes": [{"asset_id": "20535370510756332462433575263109694145574231213604117747907874615324086102913", "price": "0.21", "size": "5.5", "side": "BUY", "hash": "96e809dbdec58210247268d02f03e525c5f296a9", "best_bid": "0.79", "best_ask": "0.82"}, {"asset_id": "74768395815166461619548348007728690058055087254143355558596876906836785272025", "price": "0.79", "size": "5.5", "side": "SELL", "hash": "bace14647f28634735f45c8e4dfbbfae4c9ddba0", "best_bid": "0.18", "best_ask": "0.21"}], "timestamp": "1769384509399", "event_type": "price_change"}}
{"_local_timestamp": "2026-01-25T23:41:49.758664+00:00", "data": {"market": "0xca0329cd4392d91e39df0702949229573d2415ae4a37b0103d0c6e9d03b8dd44", "price_changes": [{"asset_id": "20535370510756332462433575263109694145574231213604117747907874615324086102913", "price": "0.22", "size": "300", "side": "BUY", "hash": "f32c0528562a23df4ac88ed1fb72fdffd69ce8af", "best_bid": "0.79", "best_ask": "0.82"}, {"asset_id": "74768395815166461619548348007728690058055087254143355558596876906836785272025", "price": "0.78", "size": "300", "side": "SELL", "hash": "9f7e6076cc8922fa25ee4624522e6684ff561b6f", "best_bid": "0.18", "best_ask": "0.21"}], "timestamp": "1769384509659", "event_type": "price_change"}}
{"_local_timestamp": "2026-01-25T23:41:50.599434+00:00", "data": {"market": "0x0bde18e0a0220d1f97173850504a1ed4fa90ef2c6a7bc0932952790053ca0c0e", "price_changes": [{"asset_id": "105325602140854796101190465907542426130401271786879982796716189175875071392057", "price": "0.7", "size": "448.5", "side": "SELL", "hash": "52192b588fbdb5c4be1c4b5726fae349e4321c22", "best_bid": "0.65", "best_ask": "0.69"}, {"asset_id": "4041912122563547970024635557261696068618666839090786586996637505354743961673", "price": "0.3", "size": "448.5", "side": "BUY", "hash": "366a697509065e14563172a6a647deb6e5bcdc7a", "best_bid": "0.31", "best_ask": "0.35"}], "timestamp": "1769384510536", "event_type": "price_change"}}
{"_local_timestamp": "2026-01-25T23:41:50.958401+00:00", "data": {"market": "0xeb44a06c677ce7a47e5fd2007182e020a577395dc3613ad55d3d576e33964c3d", "price_changes": [{"asset_id": "5305471862219565371067835325573032839634510465603099489495163186843068331171", "price": "0.12", "size": "1457", "side": "BUY", "hash": "d325d257db73a9ee42cbeef3010ada8ef6018ceb", "best_bid": "0.5", "best_ask": "0.54"}, {"asset_id": "28227838360096074788232992585368970461718254845788738931649369286727917170476", "price": "0.88", "size": "1457", "side": "SELL", "hash": "7fe99fb92631a0d59000d45277ec0539400d21de", "best_bid": "0.46", "best_ask": "0.5"}], "timestamp": "1769384510774", "event_type": "price_change"}}
{"_local_timestamp": "2026-01-25T23:41:50.960136+00:00", "data": {"market": "0xeb44a06c677ce7a47e5fd2007182e020a577395dc3613ad55d3d576e33964c3d", "price_changes": [{"asset_id": "28227838360096074788232992585368970461718254845788738931649369286727917170476", "price": "0.18", "size": "261.11", "side": "BUY", "hash": "4dbc683d068a10a88b299c2972820927f2ac5c4a", "best_bid": "0.46", "best_ask": "0.5"}, {"asset_id": "5305471862219565371067835325573032839634510465603099489495163186843068331171", "price": "0.82", "size": "261.11", "side": "SELL", "hash": "87bcf6bf712a80734192839339d1406d71bfd113", "best_bid": "0.5", "best_ask": "0.54"}], "timestamp": "1769384510774", "event_type": "price_change"}}
{"_local_timestamp": "2026-01-25T23:41:52.894984+00:00", "data": {"market": "0xeb44a06c677ce7a47e5fd2007182e020a577395dc3613ad55d3d576e33964c3d", "price_changes": [{"asset_id": "28227838360096074788232992585368970461718254845788738931649369286727917170476", "price": "0.16", "size": "400", "side": "BUY", "hash": "ee44698555b38eff70e7c2b957920f988ce06586", "best_bid": "0.46", "best_ask": "0.5"}, {"asset_id": "5305471862219565371067835325573032839634510465603099489495163186843068331171", "price": "0.84", "size": "400", "side": "SELL", "hash": "49729d05f21f4f1d1b1d7d285cccf02447d3357f", "best_bid": "0.5", "best_ask": "0.54"}], "timestamp": "1769384511834", "event_type": "price_change"}}
{"_local_timestamp": "2026-01-25T23:41:53.000178+00:00", "data": {"market": "0xeb44a06c677ce7a47e5fd2007182e020a577395dc3613ad55d3d576e33964c3d", "price_changes": [{"asset_id": "5305471862219565371067835325573032839634510465603099489495163186843068331171", "price": "0.15", "size": "3273", "side": "BUY", "hash": "95089d1674f8f48c22b4103a3619a602895d3386", "best_bid": "0.5", "best_ask": "0.54"}, {"asset_id": "28227838360096074788232992585368970461718254845788738931649369286727917170476", "price": "0.85", "size": "3273", "side": "SELL", "hash": "2f462d79595f3257f1a4701328aad49076382478", "best_bid": "0.46", "best_ask": "0.5"}], "timestamp": "1769384512672", "event_type": "price_change"}}
{"_local_timestamp": "2026-01-25T23:41:56.189035+00:00", "data": {"market": "0x0bde18e0a0220d1f97173850504a1ed4fa90ef2c6a7bc0932952790053ca0c0e", "price_changes": [{"asset_id": "4041912122563547970024635557261696068618666839090786586996637505354743961673", "price": "0.35", "size": "645", "side": "SELL", "hash": "c067077e82cafeb8815c91b19e4061d315fb6684", "best_bid": "0.31", "best_ask": "0.35"}, {"asset_id": "105325602140854796101190465907542426130401271786879982796716189175875071392057", "price": "0.65", "size": "645", "side": "BUY", "hash": "856aea38d49eed32944a8cdce283b7c07e972b5e", "best_bid": "0.65", "best_ask": "0.69"}], "timestamp": "1769384516123", "event_type": "price_change"}}
{"_local_timestamp": "2026-01-25T23:42:15.080396+00:00", "data": {"market": "0x0bde18e0a0220d1f97173850504a1ed4fa90ef2c6a7bc0932952790053ca0c0e", "price_changes": [{"asset_id": "4041912122563547970024635557261696068618666839090786586996637505354743961673", "price": "0.35", "size": "619", "side": "SELL", "hash": "5d6c7bb1a4144a9b58c6c15015256e75563755e6", "best_bid": "0.31", "best_ask": "0.35"}, {"asset_id": "105325602140854796101190465907542426130401271786879982796716189175875071392057", "price": "0.65", "size": "619", "side": "BUY", "hash": "53c540d9f5799a30481bdeaa89cbc1fbfa15e595", "best_bid": "0.65", "best_ask": "0.69"}], "timestamp": "1769384535001", "event_type": "price_change"}}
{"_local_timestamp": "2026-01-25T23:42:15.111761+00:00", "data": {"market": "0x91f7e7f2d3727a5abca7eb77827355f9a968f6636606c3f47f35ce2c23c91cbc", "price_changes": [{"asset_id": "84252679223362616378739922435722781121510894501012248080679822792405868493637", "price": "0.954", "size": "20", "side": "BUY", "hash": "9a1e42dc8ac7233d113f547b3f515f9ec38f1b55", "best_bid": "0.997", "best_ask": "0.998"}, {"asset_id": "43986832901480115975770598885448914644973339441868156495326187103850202425816", "price": "0.046", "size": "20", "side": "SELL", "hash": "16fc39c0ba3387fd2702cd0658e27a4ebf91a637", "best_bid": "0.002", "best_ask": "0.003"}], "timestamp": "1769384535030", "event_type": "price_change"}}
{"_local_timestamp": "2026-01-25T23:42:15.112693+00:00", "data": {"market": "0xa05f081e032395b4527d964fcefb032834c81bef0e85ac533c81f66139c35af4", "price_changes": [{"asset_id": "56813972039885211974321877112282829005950793706240260412507113757740359845360", "price": "0.955", "size": "20", "side": "BUY", "hash": "a40ed26787c574f40b8b99a771aaa35cb53aea43", "best_bid": "0.997", "best_ask": "0.999"}, {"asset_id": "69074333464069151404242315526218405459784935747253869832659873168984248759799", "price": "0.045", "size": "20", "side": "SELL", "hash": "54fd0e18635796f9bd4a9fff0fa7e4c2b0a052d9", "best_bid": "0.001", "best_ask": "0.003"}], "timestamp": "1769384535032", "event_type": "price_change"}}
{"_local_timestamp": "2026-01-25T23:42:15.113550+00:00", "data": {"market": "0xc1c30becf85027a3fad693fe00aed610c574220f32fabef52c1ac53f76153622", "price_changes": [{"asset_id": "86861447014827130074018921138137988822291708295577507404133014397402508069192", "price": "0.955", "size": "20", "side": "BUY", "hash": "8d9eaccd1e044bf69eeec6fea879bac19c0f6258", "best_bid": "0.997", "best_ask": "0.999"}, {"asset_id": "44162996630579613944619329601086604585114580039271806622718850166081603488312", "price": "0.045", "size": "20", "side": "SELL", "hash": "7e8cefa560fd91620f00e2de16510a42de12fe3a", "best_bid": "0.001", "best_ask": "0.003"}], "timestamp": "1769384535033", "event_type": "price_change"}}
{"_local_timestamp": "2026-01-25T23:42:15.114290+00:00", "data": {"market": "0x49d0b554fffebaabd8f70e7088c51ee132b36b51979687c5775fe1d39e6009df", "price_changes": [{"asset_id": "101417798695348023730451223679149302603865990290677002526337951186193092407966", "price": "0.955", "size": "20", "side": "BUY", "hash": "0912509feebf5a2a42b842a6023f6b6b44272bce", "best_bid": "0.997", "best_ask": "0.999"}, {"asset_id": "19835581196144925594226241068229934006876264875869838825630024545913250806260", "price": "0.045", "size": "20", "side": "SELL", "hash": "88a4f1443c01d75a16d81d6fe7ebe62ea37208e4", "best_bid": "0.001", "best_ask": "0.003"}], "timestamp": "1769384535033", "event_type": "price_change"}}
{"_local_timestamp": "2026-01-25T23:42:15.115388+00:00", "data": {"market": "0x1586e33dc57b17433d080829870d73631a146b24d44d73817634c9f7171f84c3", "price_changes": [{"asset_id": "97767433523834028432607127801550560819898564541831537765726721529534335838453", "price": "0.955", "size": "20", "side": "BUY", "hash": "b6eb3c11cdada0a04e33f66152191ea08f1770ce", "best_bid": "0.997", "best_ask": "0.999"}, {"asset_id": "45761844533847615095657975499649554423516098382359546239787965241599216489110", "price": "0.045", "size": "20", "side": "SELL", "hash": "e7eee8781d709cfad5fa41ae73c447e00281687c", "best_bid": "0.001", "best_ask": "0.003"}], "timestamp": "1769384535035", "event_type": "price_change"}}
{"_local_timestamp": "2026-01-25T23:42:22.367368+00:00", "data": {"market": "0xeb44a06c677ce7a47e5fd2007182e020a577395dc3613ad55d3d576e33964c3d", "price_changes": [{"asset_id": "28227838360096074788232992585368970461718254845788738931649369286727917170476", "price": "0.2", "size": "100", "side": "BUY", "hash": "fad9d23132134b8dabe6864d9f6ce5ee70bcc73d", "best_bid": "0.46", "best_ask": "0.5"}, {"asset_id": "5305471862219565371067835325573032839634510465603099489495163186843068331171", "price": "0.8", "size": "100", "side": "SELL", "hash": "8ea45b5d1d9a231d01565e1deef036dcdb94cc14", "best_bid": "0.5", "best_ask": "0.54"}], "timestamp": "1769384542226", "event_type": "price_change"}}
{"_local_timestamp": "2026-01-25T23:42:22.658484+00:00", "data": {"market": "0xeb44a06c677ce7a47e5fd2007182e020a577395dc3613ad55d3d576e33964c3d", "price_changes": [{"asset_id": "28227838360096074788232992585368970461718254845788738931649369286727917170476", "price": "0.13", "size": "3830", "side": "BUY", "hash": "c37d14b9391a54703f8ce9bbf870ef1b557bf7d6", "best_bid": "0.46", "best_ask": "0.5"}, {"asset_id": "5305471862219565371067835325573032839634510465603099489495163186843068331171", "price": "0.87", "size": "3830", "side": "SELL", "hash": "ed6796e5ae3bd558bf7fd11a805e96d8d63d1189", "best_bid": "0.5", "best_ask": "0.54"}], "timestamp": "1769384542531", "event_type": "price_change"}}
{"_local_timestamp": "2026-01-25T23:42:24.617079+00:00", "data": {"market": "0xca0329cd4392d91e39df0702949229573d2415ae4a37b0103d0c6e9d03b8dd44", "price_changes": [{"asset_id": "20535370510756332462433575263109694145574231213604117747907874615324086102913", "price": "0.22", "size": "250", "side": "BUY", "hash": "4ef7a1233cf66ded5dfe6045ebadc4c1407a54eb", "best_bid": "0.79", "best_ask": "0.82"}, {"asset_id": "74768395815166461619548348007728690058055087254143355558596876906836785272025", "price": "0.78", "size": "250", "side": "SELL", "hash": "87a294ae64d92788d18d8af5f67c650c664a0150", "best_bid": "0.18", "best_ask": "0.21"}], "timestamp": "1769384544473", "event_type": "price_change"}}
{"_local_timestamp": "2026-01-25T23:42:24.757249+00:00", "data": {"market": "0xeb44a06c677ce7a47e5fd2007182e020a577395dc3613ad55d3d576e33964c3d", "price_changes": [{"asset_id": "5305471862219565371067835325573032839634510465603099489495163186843068331171", "price": "0.12", "size": "1332", "side": "BUY", "hash": "8d9729e02b46e3f2f73e5316963df9a8a0828105", "best_bid": "0.5", "best_ask": "0.54"}, {"asset_id": "28227838360096074788232992585368970461718254845788738931649369286727917170476", "price": "0.88", "size": "1332", "side": "SELL", "hash": "b5a38f722b1c2040d64d275c2204cae404d00db1", "best_bid": "0.46", "best_ask": "0.5"}], "timestamp": "1769384544491", "event_type": "price_change"}}
{"_local_timestamp": "2026-01-25T23:42:24.763179+00:00", "data": {"market": "0xeb44a06c677ce7a47e5fd2007182e020a577395dc3613ad55d3d576e33964c3d", "price_changes": [{"asset_id": "28227838360096074788232992585368970461718254845788738931649369286727917170476", "price": "0.16", "size": "300", "side": "BUY", "hash": "436a5041290b9a985f0dfe710b17c51482910107", "best_bid": "0.46", "best_ask": "0.5"}, {"asset_id": "5305471862219565371067835325573032839634510465603099489495163186843068331171", "price": "0.84", "size": "300", "side": "SELL", "hash": "ec325ad21cbd2911cfea910e6fb5b12a92e73a8c", "best_bid": "0.5", "best_ask": "0.54"}], "timestamp": "1769384544492", "event_type": "price_change"}}
{"_local_timestamp": "2026-01-25T23:42:25.004668+00:00", "data": {"market": "0xca0329cd4392d91e39df0702949229573d2415ae4a37b0103d0c6e9d03b8dd44", "price_changes": [{"asset_id": "20535370510756332462433575263109694145574231213604117747907874615324086102913", "price": "0.22", "size": "150", "side": "BUY", "hash": "ff7353e93223e7b23b2d466f91f4e8c0171677fb", "best_bid": "0.79", "best_ask": "0.82"}, {"asset_id": "74768395815166461619548348007728690058055087254143355558596876906836785272025", "price": "0.78", "size": "150", "side": "SELL", "hash": "3e947b715b8d4c0d93fec5059316b30e8bf94171", "best_bid": "0.18", "best_ask": "0.21"}], "timestamp": "1769384544872", "event_type": "price_change"}}
{"_local_timestamp": "2026-01-25T23:42:25.016251+00:00", "data": {"market": "0xeb44a06c677ce7a47e5fd2007182e020a577395dc3613ad55d3d576e33964c3d", "price_changes": [{"asset_id": "28227838360096074788232992585368970461718254845788738931649369286727917170476", "price": "0.18", "size": "111.11", "side": "BUY", "hash": "498f04c0505cde7b6ad83f187159bdcc41f4ad6b", "best_bid": "0.46", "best_ask": "0.5"}, {"asset_id": "5305471862219565371067835325573032839634510465603099489495163186843068331171", "price": "0.82", "size": "111.11", "side": "SELL", "hash": "16098d2760b9c3c874434649306ded39e242b20f", "best_bid": "0.5", "best_ask": "0.54"}], "timestamp": "1769384544872", "event_type": "price_change"}}
{"_local_timestamp": "2026-01-25T23:42:25.093155+00:00", "data": {"market": "0xeb44a06c677ce7a47e5fd2007182e020a577395dc3613ad55d3d576e33964c3d", "price_changes": [{"asset_id": "28227838360096074788232992585368970461718254845788738931649369286727917170476", "price": "0.18", "size": "211.11", "side": "BUY", "hash": "9fc4ffdc022da84992a8848cb3ab7f2afb37f048", "best_bid": "0.46", "best_ask": "0.5"}, {"asset_id": "5305471862219565371067835325573032839634510465603099489495163186843068331171", "price": "0.82", "size": "211.11", "side": "SELL", "hash": "fc607976ea5759e898e3bafef0b96011005f4227", "best_bid": "0.5", "best_ask": "0.54"}], "timestamp": "1769384544903", "event_type": "price_change"}}
{"_local_timestamp": "2026-01-25T23:42:25.100585+00:00", "data": {"market": "0xca0329cd4392d91e39df0702949229573d2415ae4a37b0103d0c6e9d03b8dd44", "price_changes": [{"asset_id": "20535370510756332462433575263109694145574231213604117747907874615324086102913", "price": "0.21", "size": "55.5", "side": "BUY", "hash": "f92def58d3125b5eed0883f4a76deb57757e0a36", "best_bid": "0.79", "best_ask": "0.82"}, {"asset_id": "74768395815166461619548348007728690058055087254143355558596876906836785272025", "price": "0.79", "size": "55.5", "side": "SELL", "hash": "e005a88a2152721596b1843553c0bcdd72271550", "best_bid": "0.18", "best_ask": "0.21"}], "timestamp": "1769384544903", "event_type": "price_change"}}
{"_local_timestamp": "2026-01-25T23:42:25.174158+00:00", "data": {"market": "0xeb44a06c677ce7a47e5fd2007182e020a577395dc3613ad55d3d576e33964c3d", "price_changes": [{"asset_id": "5305471862219565371067835325573032839634510465603099489495163186843068331171", "price": "0.15", "size": "3398", "side": "BUY", "hash": "58ba90ad214ba3aac86f096660e950658737571b", "best_bid": "0.5", "best_ask": "0.54"}, {"asset_id": "28227838360096074788232992585368970461718254845788738931649369286727917170476", "price": "0.85", "size": "3398", "side": "SELL", "hash": "1e86be95354c98fee0e5a63d4b8074543f725682", "best_bid": "0.46", "best_ask": "0.5"}], "timestamp": "1769384544942", "event_type": "price_change"}}
{"_local_timestamp": "2026-01-25T23:42:25.287802+00:00", "data": {"market": "0xeb44a06c677ce7a47e5fd2007182e020a577395dc3613ad55d3d576e33964c3d", "price_changes": [{"asset_id": "28227838360096074788232992585368970461718254845788738931649369286727917170476", "price": "0.16", "size": "450", "side": "BUY", "hash": "f5388678d92ee3cb1c961c19628825e9609814fb", "best_bid": "0.46", "best_ask": "0.5"}, {"asset_id": "5305471862219565371067835325573032839634510465603099489495163186843068331171", "price": "0.84", "size": "450", "side": "SELL", "hash": "aaacf4f9f1292a98ac4b5df852283aaaf1e398c4", "best_bid": "0.5", "best_ask": "0.54"}], "timestamp": "1769384545149", "event_type": "price_change"}}
{"_local_timestamp": "2026-01-25T23:42:25.300802+00:00", "data": {"market": "0xca0329cd4392d91e39df0702949229573d2415ae4a37b0103d0c6e9d03b8dd44", "price_changes": [{"asset_id": "20535370510756332462433575263109694145574231213604117747907874615324086102913", "price": "0.23", "size": "1926", "side": "BUY", "hash": "a995ce83f0059281f3f2e3173f440cb680114553", "best_bid": "0.79", "best_ask": "0.82"}, {"asset_id": "74768395815166461619548348007728690058055087254143355558596876906836785272025", "price": "0.77", "size": "1926", "side": "SELL", "hash": "e642a009a6550a97937d0935ceca39a1c3d39709", "best_bid": "0.18", "best_ask": "0.21"}], "timestamp": "1769384545149", "event_type": "price_change"}}
{"_local_timestamp": "2026-01-25T23:42:45.356541+00:00", "data": {"market": "0xca0329cd4392d91e39df0702949229573d2415ae4a37b0103d0c6e9d03b8dd44", "price_changes": [{"asset_id": "20535370510756332462433575263109694145574231213604117747907874615324086102913", "price": "0.22", "size": "100", "side": "BUY", "hash": "bce518ceb8e103a168eec7dfd710149296dfc17a", "best_bid": "0.79", "best_ask": "0.82"}, {"asset_id": "74768395815166461619548348007728690058055087254143355558596876906836785272025", "price": "0.78", "size": "100", "side": "SELL", "hash": "2a9ac734a988100003dc26fedfd21535196c9bcb", "best_bid": "0.18", "best_ask": "0.21"}], "timestamp": "1769384565203", "event_type": "price_change"}}
{"_local_timestamp": "2026-01-25T23:42:45.776033+00:00", "data": {"market": "0xca0329cd4392d91e39df0702949229573d2415ae4a37b0103d0c6e9d03b8dd44", "price_changes": [{"asset_id": "20535370510756332462433575263109694145574231213604117747907874615324086102913", "price": "0.21", "size": "105.5", "side": "BUY", "hash": "5bd0fe40ec90c4b77839bbd31f486c11dcb3fce7", "best_bid": "0.79", "best_ask": "0.82"}, {"asset_id": "74768395815166461619548348007728690058055087254143355558596876906836785272025", "price": "0.79", "size": "105.5", "side": "SELL", "hash": "aa94c5b7667e9774e85cc372d6a236f5e66c3d9b", "best_bid": "0.18", "best_ask": "0.21"}], "timestamp": "1769384565602", "event_type": "price_change"}}
{"_local_timestamp": "2026-01-25T23:42:47.211440+00:00", "data": {"market": "0xeb44a06c677ce7a47e5fd2007182e020a577395dc3613ad55d3d576e33964c3d", "price_changes": [{"asset_id": "5305471862219565371067835325573032839634510465603099489495163186843068331171", "price": "0.15", "size": "600", "side": "BUY", "hash": "f2cf11e0e999cfe004e62384516a06e94ca22be6", "best_bid": "0.5", "best_ask": "0.54"}, {"asset_id": "28227838360096074788232992585368970461718254845788738931649369286727917170476", "price": "0.85", "size": "600", "side": "SELL", "hash": "f2a6b2b6db016348d57c3b37021a8ef1e4396872", "best_bid": "0.46", "best_ask": "0.5"}], "timestamp": "1769384566987", "event_type": "price_change"}}
{"_local_timestamp": "2026-01-25T23:42:53.505698+00:00", "data": {"market": "0xeb44a06c677ce7a47e5fd2007182e020a577395dc3613ad55d3d576e33964c3d", "price_changes": [{"asset_id": "5305471862219565371067835325573032839634510465603099489495163186843068331171", "price": "0.16", "size": "3324", "side": "BUY", "hash": "2ff0f68896778a0eaf51af7e13deaf77d29ff11a", "best_bid": "0.5", "best_ask": "0.54"}, {"asset_id": "28227838360096074788232992585368970461718254845788738931649369286727917170476", "price": "0.84", "size": "3324", "side": "SELL", "hash": "eff634a618976d34e93f68bcc4b3aebeb84d9c08", "best_bid": "0.46", "best_ask": "0.5"}], "timestamp": "1769384573367", "event_type": "price_change"}}
{"_local_timestamp": "2026-01-25T23:43:11.753292+00:00", "data": {"market": "0xc5452a97769a9aa7a264d11bf07c7da6ff6080061d426cd7ef92abb47f6d8160", "price_changes": [{"asset_id": "114340618694795548048032631237414556707214948596108879651552052673573136118536", "price": "0.435", "size": "0", "side": "BUY", "hash": "821f853f8b601a6b532f276b6abb1673d77327de", "best_bid": "0.997", "best_ask": "0.998"}, {"asset_id": "8922710639437477954990654098858414058444921382508505451184351067105680225969", "price": "0.565", "size": "0", "side": "SELL", "hash": "9f7d9e11ad2c655280767d2efa9ddb55ab342a3e", "best_bid": "0.002", "best_ask": "0.003"}], "timestamp": "1769384591619", "event_type": "price_change"}}
{"_local_timestamp": "2026-01-25T23:43:11.811503+00:00", "data": {"market": "0xc5452a97769a9aa7a264d11bf07c7da6ff6080061d426cd7ef92abb47f6d8160", "price_changes": [{"asset_id": "114340618694795548048032631237414556707214948596108879651552052673573136118536", "price": "0.439", "size": "5", "side": "BUY", "hash": "ce077081b5619734c0329d0d9d04491a8b432506", "best_bid": "0.997", "best_ask": "0.998"}, {"asset_id": "8922710639437477954990654098858414058444921382508505451184351067105680225969", "price": "0.561", "size": "5", "side": "SELL", "hash": "e2166ad02238d757b4e6c54f8db599be38d68008", "best_bid": "0.002", "best_ask": "0.003"}], "timestamp": "1769384591673", "event_type": "price_change"}}
{"_local_timestamp": "2026-01-25T23:43:26.181708+00:00", "data": {"market": "0x0bde18e0a0220d1f97173850504a1ed4fa90ef2c6a7bc0932952790053ca0c0e", "price_changes": [{"asset_id": "4041912122563547970024635557261696068618666839090786586996637505354743961673", "price": "0.35", "size": "645", "side": "SELL", "hash": "8c48233b34fe58b6e2257a2b57978d5f39bf7fff", "best_bid": "0.31", "best_ask": "0.35"}, {"asset_id": "105325602140854796101190465907542426130401271786879982796716189175875071392057", "price": "0.65", "size": "645", "side": "BUY", "hash": "5d7b9a00f06939da0fcef93c5aa7f5c1dda61c44", "best_bid": "0.65", "best_ask": "0.69"}], "timestamp": "1769384606076", "event_type": "price_change"}}
{"_local_timestamp": "2026-01-25T23:43:38.531485+00:00", "data": {"market": "0xeb44a06c677ce7a47e5fd2007182e020a577395dc3613ad55d3d576e33964c3d", "price_changes": [{"asset_id": "5305471862219565371067835325573032839634510465603099489495163186843068331171", "price": "0.15", "size": "375", "side": "BUY", "hash": "d3fc8f1445144c561e2adabcbc062d8c051c7492", "best_bid": "0.5", "best_ask": "0.54"}, {"asset_id": "28227838360096074788232992585368970461718254845788738931649369286727917170476", "price": "0.85", "size": "375", "side": "SELL", "hash": "262f8101936f53a190c9af636ed89adb7ad3ebf5", "best_bid": "0.46", "best_ask": "0.5"}], "timestamp": "1769384618453", "event_type": "price_change"}}
{"_local_timestamp": "2026-01-25T23:43:38.823096+00:00", "data": {"market": "0xeb44a06c677ce7a47e5fd2007182e020a577395dc3613ad55d3d576e33964c3d", "price_changes": [{"asset_id": "5305471862219565371067835325573032839634510465603099489495163186843068331171", "price": "0.12", "size": "1557", "side": "BUY", "hash": "ee2cb7792201354f25dd4419f01c792b2824be8c", "best_bid": "0.5", "best_ask": "0.54"}, {"asset_id": "28227838360096074788232992585368970461718254845788738931649369286727917170476", "price": "0.88", "size": "1557", "side": "SELL", "hash": "13378b1ec11cc97e1f987c0e23109006d52d7215", "best_bid": "0.46", "best_ask": "0.5"}], "timestamp": "1769384618722", "event_type": "price_change"}}
{"_local_timestamp": "2026-01-25T23:43:45.092087+00:00", "data": {"market": "0x0bde18e0a0220d1f97173850504a1ed4fa90ef2c6a7bc0932952790053ca0c0e", "price_changes": [{"asset_id": "4041912122563547970024635557261696068618666839090786586996637505354743961673", "price": "0.35", "size": "619", "side": "SELL", "hash": "98be4f59d139c4968015cb89fd1ff41790659362", "best_bid": "0.31", "best_ask": "0.35"}, {"asset_id": "105325602140854796101190465907542426130401271786879982796716189175875071392057", "price": "0.65", "size": "619", "side": "BUY", "hash": "0e5c91a55f98deb5cc9214459d6c0705adf64954", "best_bid": "0.65", "best_ask": "0.69"}], "timestamp": "1769384625000", "event_type": "price_change"}}
{"_local_timestamp": "2026-01-25T23:43:52.473613+00:00", "data": {"market": "0xeb44a06c677ce7a47e5fd2007182e020a577395dc3613ad55d3d576e33964c3d", "price_changes": [{"asset_id": "5305471862219565371067835325573032839634510465603099489495163186843068331171", "price": "0.15", "size": "325", "side": "BUY", "hash": "564524c057d3e1228864528039703b6c68159c4e", "best_bid": "0.5", "best_ask": "0.54"}, {"asset_id": "28227838360096074788232992585368970461718254845788738931649369286727917170476", "price": "0.85", "size": "325", "side": "SELL", "hash": "8fe4cd7c499646ed7b0419b00354369291b4aa50", "best_bid": "0.46", "best_ask": "0.5"}], "timestamp": "1769384632324", "event_type": "price_change"}}
{"_local_timestamp": "2026-01-25T23:43:52.795625+00:00", "data": {"market": "0xeb44a06c677ce7a47e5fd2007182e020a577395dc3613ad55d3d576e33964c3d", "price_changes": [{"asset_id": "5305471862219565371067835325573032839634510465603099489495163186843068331171", "price": "0.16", "size": "3374", "side": "BUY", "hash": "2f70bdff8fc5ea5319c6b57590a7be14695b9c09", "best_bid": "0.5", "best_ask": "0.54"}, {"asset_id": "28227838360096074788232992585368970461718254845788738931649369286727917170476", "price": "0.84", "size": "3374", "side": "SELL", "hash": "d2e560d9d0e4dbb8a3971f44e014b64cd4708b3d", "best_bid": "0.46", "best_ask": "0.5"}], "timestamp": "1769384632642", "event_type": "price_change"}}
{"_local_timestamp": "2026-01-25T23:44:08.547247+00:00", "data": {"market": "0xca0329cd4392d91e39df0702949229573d2415ae4a37b0103d0c6e9d03b8dd44", "price_changes": [{"asset_id": "20535370510756332462433575263109694145574231213604117747907874615324086102913", "price": "0.21", "size": "55.5", "side": "BUY", "hash": "a1d7b6d7578d2da3459b55707d9ed0d04ba51a31", "best_bid": "0.79", "best_ask": "0.82"}, {"asset_id": "74768395815166461619548348007728690058055087254143355558596876906836785272025", "price": "0.79", "size": "55.5", "side": "SELL", "hash": "ad74142677729a39aeb09c4f7edeba6ca9806d92", "best_bid": "0.18", "best_ask": "0.21"}], "timestamp": "1769384648346", "event_type": "price_change"}}
{"_local_timestamp": "2026-01-25T23:44:08.548564+00:00", "data": {"market": "0xeb44a06c677ce7a47e5fd2007182e020a577395dc3613ad55d3d576e33964c3d", "price_changes": [{"asset_id": "28227838360096074788232992585368970461718254845788738931649369286727917170476", "price": "0.18", "size": "111.11", "side": "BUY", "hash": "d3ab6bd782f59b4721253e2c2efde283f802d5dd", "best_bid": "0.46", "best_ask": "0.5"}, {"asset_id": "5305471862219565371067835325573032839634510465603099489495163186843068331171", "price": "0.82", "size": "111.11", "side": "SELL", "hash": "e758f51338380b9562aa57912e4f0a6d1f3876d8", "best_bid": "0.5", "best_ask": "0.54"}], "timestamp": "1769384648347", "event_type": "price_change"}}
{"_local_timestamp": "2026-01-25T23:44:08.999871+00:00", "data": {"market": "0xeb44a06c677ce7a47e5fd2007182e020a577395dc3613ad55d3d576e33964c3d", "price_changes": [{"asset_id": "28227838360096074788232992585368970461718254845788738931649369286727917170476", "price": "0.16", "size": "550", "side": "BUY", "hash": "0ed3811890de34e8e656a9671adf6d271fa22bf1", "best_bid": "0.46", "best_ask": "0.5"}, {"asset_id": "5305471862219565371067835325573032839634510465603099489495163186843068331171", "price": "0.84", "size": "550", "side": "SELL", "hash": "0c703ece125880c8ddb443ac07960fd91bee8640", "best_bid": "0.5", "best_ask": "0.54"}], "timestamp": "1769384648716", "event_type": "price_change"}}
{"_local_timestamp": "2026-01-25T23:44:09.001586+00:00", "data": {"market": "0xca0329cd4392d91e39df0702949229573d2415ae4a37b0103d0c6e9d03b8dd44", "price_changes": [{"asset_id": "20535370510756332462433575263109694145574231213604117747907874615324086102913", "price": "0.23", "size": "1976", "side": "BUY", "hash": "9365838152ad29f5aa438bff66c72243bc363e7d", "best_bid": "0.79", "best_ask": "0.82"}, {"asset_id": "74768395815166461619548348007728690058055087254143355558596876906836785272025", "price": "0.77", "size": "1976", "side": "SELL", "hash": "04e559e5c602ba15d707ceb5b85568370ba174f0", "best_bid": "0.18", "best_ask": "0.21"}], "timestamp": "1769384648716", "event_type": "price_change"}}
{"_local_timestamp": "2026-01-25T23:44:20.788054+00:00", "data": {"market": "0xeb44a06c677ce7a47e5fd2007182e020a577395dc3613ad55d3d576e33964c3d", "price_changes": [{"asset_id": "28227838360096074788232992585368970461718254845788738931649369286727917170476", "price": "0.16", "size": "400", "side": "BUY", "hash": "9b0ad72019dd46a37c0adf6554ac19af2d264e09", "best_bid": "0.46", "best_ask": "0.5"}, {"asset_id": "5305471862219565371067835325573032839634510465603099489495163186843068331171", "price": "0.84", "size": "400", "side": "SELL", "hash": "42d8c18ef70b6e3818552d469abd2955a881b014", "best_bid": "0.5", "best_ask": "0.54"}], "timestamp": "1769384660496", "event_type": "price_change"}}
{"_local_timestamp": "2026-01-25T23:44:20.789368+00:00", "data": {"market": "0xca0329cd4392d91e39df0702949229573d2415ae4a37b0103d0c6e9d03b8dd44", "price_changes": [{"asset_id": "20535370510756332462433575263109694145574231213604117747907874615324086102913", "price": "0.22", "size": "0", "side": "BUY", "hash": "7b31545c74b7b38054162d036646f07db514c1cd", "best_bid": "0.79", "best_ask": "0.82"}, {"asset_id": "74768395815166461619548348007728690058055087254143355558596876906836785272025", "price": "0.78", "size": "0", "side": "SELL", "hash": "3a801608c3ea4be15ac19155f811b557e892d645", "best_bid": "0.18", "best_ask": "0.21"}], "timestamp": "1769384660496", "event_type": "price_change"}}
{"_local_timestamp": "2026-01-25T23:44:21.486154+00:00", "data": {"market": "0xeb44a06c677ce7a47e5fd2007182e020a577395dc3613ad55d3d576e33964c3d", "price_changes": [{"asset_id": "28227838360096074788232992585368970461718254845788738931649369286727917170476", "price": "0.18", "size": "261.11", "side": "BUY", "hash": "ae9bca14d0534e2566801288e992dc796329a841", "best_bid": "0.46", "best_ask": "0.5"}, {"asset_id": "5305471862219565371067835325573032839634510465603099489495163186843068331171", "price": "0.82", "size": "261.11", "side": "SELL", "hash": "5f981b210996b5f859f81b332207e7d4f91c3b6d", "best_bid": "0.5", "best_ask": "0.54"}], "timestamp": "1769384660923", "event_type": "price_change"}}
{"_local_timestamp": "2026-01-25T23:44:21.493631+00:00", "data": {"market": "0xca0329cd4392d91e39df0702949229573d2415ae4a37b0103d0c6e9d03b8dd44", "price_changes": [{"asset_id": "20535370510756332462433575263109694145574231213604117747907874615324086102913", "price": "0.23", "size": "2076", "side": "BUY", "hash": "fec93d1e5a17d3ccd264b138b767b03948f0cdb3", "best_bid": "0.79", "best_ask": "0.82"}, {"asset_id": "74768395815166461619548348007728690058055087254143355558596876906836785272025", "price": "0.77", "size": "2076", "side": "SELL", "hash": "2e22fe5f062331569988e74b865ccae39be08011", "best_bid": "0.18", "best_ask": "0.21"}], "timestamp": "1769384660926", "event_type": "price_change"}}
{"_local_timestamp": "2026-01-25T23:44:22.787611+00:00", "data": {"market": "0x0bde18e0a0220d1f97173850504a1ed4fa90ef2c6a7bc0932952790053ca0c0e", "price_changes": [{"asset_id": "105325602140854796101190465907542426130401271786879982796716189175875071392057", "price": "0.7", "size": "222.09", "side": "SELL", "hash": "10f9cc3a6f62cfe0adb67579bfa36b3d49803f3e", "best_bid": "0.65", "best_ask": "0.69"}, {"asset_id": "4041912122563547970024635557261696068618666839090786586996637505354743961673", "price": "0.3", "size": "222.09", "side": "BUY", "hash": "05ad42620ca335a1b31f1a5ce8aa1f02c79a100b", "best_bid": "0.31", "best_ask": "0.35"}], "timestamp": "1769384662709", "event_type": "price_change"}}
{"_local_timestamp": "2026-01-25T23:44:24.013271+00:00", "data": {"market": "0x0bde18e0a0220d1f97173850504a1ed4fa90ef2c6a7bc0932952790053ca0c0e", "price_changes": [{"asset_id": "105325602140854796101190465907542426130401271786879982796716189175875071392057", "price": "0.7", "size": "448.5", "side": "SELL", "hash": "6dac7bdda25837dbe980e4e76d049348790102cd", "best_bid": "0.65", "best_ask": "0.69"}, {"asset_id": "4041912122563547970024635557261696068618666839090786586996637505354743961673", "price": "0.3", "size": "448.5", "side": "BUY", "hash": "8d573a20e35014afb988ffe39e0affab24a5b1f9", "best_bid": "0.31", "best_ask": "0.35"}], "timestamp": "1769384663947", "event_type": "price_change"}}
{"_local_timestamp": "2026-01-25T23:44:32.382134+00:00", "data": {"market": "0xca0329cd4392d91e39df0702949229573d2415ae4a37b0103d0c6e9d03b8dd44", "price_changes": [{"asset_id": "20535370510756332462433575263109694145574231213604117747907874615324086102913", "price": "0.23", "size": "250", "side": "BUY", "hash": "242d5cd083b72c36f5e2c41eac164e133f1f383e", "best_bid": "0.79", "best_ask": "0.82"}, {"asset_id": "74768395815166461619548348007728690058055087254143355558596876906836785272025", "price": "0.77", "size": "250", "side": "SELL", "hash": "549301c22c2eae4d11fb07cbe610a7a83a115c68", "best_bid": "0.18", "best_ask": "0.21"}], "timestamp": "1769384672292", "event_type": "price_change"}}
{"_local_timestamp": "2026-01-25T23:44:43.979915+00:00", "data": {"market": "0xeb44a06c677ce7a47e5fd2007182e020a577395dc3613ad55d3d576e33964c3d", "price_changes": [{"asset_id": "5305471862219565371067835325573032839634510465603099489495163186843068331171", "price": "0.54", "size": "126.49", "side": "SELL", "hash": "31e2e992ffe547e540366658d0a6616ce9380895", "best_bid": "0.5", "best_ask": "0.54"}, {"asset_id": "28227838360096074788232992585368970461718254845788738931649369286727917170476", "price": "0.46", "size": "126.49", "side": "BUY", "hash": "077044cf60a7c97c080dd58f0c19461c437dab2d", "best_bid": "0.46", "best_ask": "0.5"}], "timestamp": "1769384683900", "event_type": "price_change"}}
{"_local_timestamp": "2026-01-25T23:44:43.995329+00:00", "data": {"market": "0x91f7e7f2d3727a5abca7eb77827355f9a968f6636606c3f47f35ce2c23c91cbc", "price_changes": [{"asset_id": "84252679223362616378739922435722781121510894501012248080679822792405868493637", "price": "0.954", "size": "0", "side": "BUY", "hash": "fb0f1175d45ab538cc82accec864ca77f88c0712", "best_bid": "0.997", "best_ask": "0.998"}, {"asset_id": "43986832901480115975770598885448914644973339441868156495326187103850202425816", "price": "0.046", "size": "0", "side": "SELL", "hash": "675425347f01ebda93c489c8d0386e70790c5bc7", "best_bid": "0.002", "best_ask": "0.003"}], "timestamp": "1769384683921", "event_type": "price_change"}}
{"_local_timestamp": "2026-01-25T23:44:43.996258+00:00", "data": {"market": "0xa05f081e032395b4527d964fcefb032834c81bef0e85ac533c81f66139c35af4", "price_changes": [{"asset_id": "56813972039885211974321877112282829005950793706240260412507113757740359845360", "price": "0.955", "size": "0", "side": "BUY", "hash": "bf535e8b45aa2530d7237cf72734ce4d08bb4f60", "best_bid": "0.997", "best_ask": "0.999"}, {"asset_id": "69074333464069151404242315526218405459784935747253869832659873168984248759799", "price": "0.045", "size": "0", "side": "SELL", "hash": "785f03b7f19660346f8608fc44a5cebbae5c8f33", "best_bid": "0.001", "best_ask": "0.003"}], "timestamp": "1769384683922", "event_type": "price_change"}}
{"_local_timestamp": "2026-01-25T23:44:43.996978+00:00", "data": {"market": "0x1586e33dc57b17433d080829870d73631a146b24d44d73817634c9f7171f84c3", "price_changes": [{"asset_id": "97767433523834028432607127801550560819898564541831537765726721529534335838453", "price": "0.955", "size": "0", "side": "BUY", "hash": "8bf2f1fde02b91fb78b164aeb6210fd6c2bcd534", "best_bid": "0.997", "best_ask": "0.999"}, {"asset_id": "45761844533847615095657975499649554423516098382359546239787965241599216489110", "price": "0.045", "size": "0", "side": "SELL", "hash": "ac13b9297ceaff4874b82206f82119c547cac6c1", "best_bid": "0.001", "best_ask": "0.003"}], "timestamp": "1769384683923", "event_type": "price_change"}}
{"_local_timestamp": "2026-01-25T23:44:43.997651+00:00", "data": {"market": "0x49d0b554fffebaabd8f70e7088c51ee132b36b51979687c5775fe1d39e6009df", "price_changes": [{"asset_id": "101417798695348023730451223679149302603865990290677002526337951186193092407966", "price": "0.955", "size": "0", "side": "BUY", "hash": "564c4565a078c39a74ccd62b65d9e04c92d62a79", "best_bid": "0.997", "best_ask": "0.999"}, {"asset_id": "19835581196144925594226241068229934006876264875869838825630024545913250806260", "price": "0.045", "size": "0", "side": "SELL", "hash": "f870752a984fab080773d162e352f3266ab4880f", "best_bid": "0.001", "best_ask": "0.003"}], "timestamp": "1769384683925", "event_type": "price_change"}}
{"_local_timestamp": "2026-01-25T23:44:43.999187+00:00", "data": {"market": "0xc1c30becf85027a3fad693fe00aed610c574220f32fabef52c1ac53f76153622", "price_changes": [{"asset_id": "86861447014827130074018921138137988822291708295577507404133014397402508069192", "price": "0.955", "size": "0", "side": "BUY", "hash": "f7dd70fcbf998c1a10e209520cfc97d63a50582c", "best_bid": "0.997", "best_ask": "0.999"}, {"asset_id": "44162996630579613944619329601086604585114580039271806622718850166081603488312", "price": "0.045", "size": "0", "side": "SELL", "hash": "87b72ce6060964c71bed41340c7f74be406587e1", "best_bid": "0.001", "best_ask": "0.003"}], "timestamp": "1769384683928", "event_type": "price_change"}}
{"_local_timestamp": "2026-01-25T23:44:44.157291+00:00", "data": {"market": "0xeb44a06c677ce7a47e5fd2007182e020a577395dc3613ad55d3d576e33964c3d", "price_changes": [{"asset_id": "5305471862219565371067835325573032839634510465603099489495163186843068331171", "price": "0.54", "size": "134.49", "side": "SELL", "hash": "25c8988f5febea5b4200d4b38310ce6d6ff5cc0b", "best_bid": "0.5", "best_ask": "0.54"}, {"asset_id": "28227838360096074788232992585368970461718254845788738931649369286727917170476", "price": "0.46", "size": "134.49", "side": "BUY", "hash": "29a08c654edc98b8a9490c93cd89536845f1cf67", "best_bid": "0.46", "best_ask": "0.5"}], "timestamp": "1769384684086", "event_type": "price_change"}}
{"_local_timestamp": "2026-01-25T23:44:56.206624+00:00", "data": {"market": "0x0bde18e0a0220d1f97173850504a1ed4fa90ef2c6a7bc0932952790053ca0c0e", "price_changes": [{"asset_id": "4041912122563547970024635557261696068618666839090786586996637505354743961673", "price": "0.35", "size": "645", "side": "SELL", "hash": "7b8135e13b6acb01abfe22eb3051a3bf98f03dc4", "best_bid": "0.31", "best_ask": "0.35"}, {"asset_id": "105325602140854796101190465907542426130401271786879982796716189175875071392057", "price": "0.65", "size": "645", "side": "BUY", "hash": "5da46b9923a6e75831f371a1e6a4564e6584d8fe", "best_bid": "0.65", "best_ask": "0.69"}], "timestamp": "1769384696141", "event_type": "price_change"}}
{"_local_timestamp": "2026-01-25T23:44:57.519231+00:00", "data": {"market": "0xeb44a06c677ce7a47e5fd2007182e020a577395dc3613ad55d3d576e33964c3d", "price_changes": [{"asset_id": "28227838360096074788232992585368970461718254845788738931649369286727917170476", "price": "0.16", "size": "250", "side": "BUY", "hash": "1e542151d5439573435a415e14c119aa335e606c", "best_bid": "0.46", "best_ask": "0.5"}, {"asset_id": "5305471862219565371067835325573032839634510465603099489495163186843068331171", "price": "0.84", "size": "250", "side": "SELL", "hash": "c1752428b2775c605d0edddceb70d286cbe2d6d9", "best_bid": "0.5", "best_ask": "0.54"}], "timestamp": "1769384697452", "event_type": "price_change"}}
{"_local_timestamp": "2026-01-25T23:44:57.796440+00:00", "data": {"market": "0xeb44a06c677ce7a47e5fd2007182e020a577395dc3613ad55d3d576e33964c3d", "price_changes": [{"asset_id": "28227838360096074788232992585368970461718254845788738931649369286727917170476", "price": "0.18", "size": "411.11", "side": "BUY", "hash": "68c28c2beda2cbbcad06727cb9fd23aaf76f74e0", "best_bid": "0.46", "best_ask": "0.5"}, {"asset_id": "5305471862219565371067835325573032839634510465603099489495163186843068331171", "price": "0.82", "size": "411.11", "side": "SELL", "hash": "4acf596e76b99bc7abf201118619f76f8ace1260", "best_bid": "0.5", "best_ask": "0.54"}], "timestamp": "1769384697724", "event_type": "price_change"}}
{"_local_timestamp": "2026-01-25T23:44:57.868143+00:00", "data": {"market": "0xca0329cd4392d91e39df0702949229573d2415ae4a37b0103d0c6e9d03b8dd44", "price_changes": [{"asset_id": "20535370510756332462433575263109694145574231213604117747907874615324086102913", "price": "0.21", "size": "5.5", "side": "BUY", "hash": "11e68d86a084e1282fc3f8cfbc682b43f412231d", "best_bid": "0.79", "best_ask": "0.82"}, {"asset_id": "74768395815166461619548348007728690058055087254143355558596876906836785272025", "price": "0.79", "size": "5.5", "side": "SELL", "hash": "4a63e563df593ac3efa1f88bdfa6e38fa5f2a200", "best_bid": "0.18", "best_ask": "0.21"}], "timestamp": "1769384697749", "event_type": "price_change"}}
{"_local_timestamp": "2026-01-25T23:44:58.308123+00:00", "data": {"market": "0xca0329cd4392d91e39df0702949229573d2415ae4a37b0103d0c6e9d03b8dd44", "price_changes": [{"asset_id": "20535370510756332462433575263109694145574231213604117747907874615324086102913", "price": "0.23", "size": "300", "side": "BUY", "hash": "e4e1cea2ab5410fe86c9aa55acf255e07563008b", "best_bid": "0.79", "best_ask": "0.82"}, {"asset_id": "74768395815166461619548348007728690058055087254143355558596876906836785272025", "price": "0.77", "size": "300", "side": "SELL", "hash": "62b88ccde045bbc6dc623a90055ae98156334d83", "best_bid": "0.18", "best_ask": "0.21"}], "timestamp": "1769384698215", "event_type": "price_change"}}
{"_local_timestamp": "2026-01-25T23:45:01.209162+00:00", "data": {"market": "0xca0329cd4392d91e39df0702949229573d2415ae4a37b0103d0c6e9d03b8dd44", "price_changes": [{"asset_id": "74768395815166461619548348007728690058055087254143355558596876906836785272025", "price": "0.17", "size": "381.12", "side": "BUY", "hash": "d357cbbb9caa4eaff9051a19d3294026bf754f98", "best_bid": "0.18", "best_ask": "0.21"}, {"asset_id": "20535370510756332462433575263109694145574231213604117747907874615324086102913", "price": "0.83", "size": "381.12", "side": "SELL", "hash": "fb77ed575343f5c495201bd8ffdaa7979fe70fb7", "best_bid": "0.79", "best_ask": "0.82"}], "timestamp": "1769384701094", "event_type": "price_change"}}
{"_local_timestamp": "2026-01-25T23:45:03.694908+00:00", "data": {"market": "0xca0329cd4392d91e39df0702949229573d2415ae4a37b0103d0c6e9d03b8dd44", "price_changes": [{"asset_id": "20535370510756332462433575263109694145574231213604117747907874615324086102913", "price": "0.78", "size": "124", "side": "BUY", "hash": "76b08cc9574197a805d011fa6080d91e416bd67e", "best_bid": "0.79", "best_ask": "0.82"}, {"asset_id": "74768395815166461619548348007728690058055087254143355558596876906836785272025", "price": "0.22", "size": "124", "side": "SELL", "hash": "51c6af949001198c0d5cf180a2076776f5d87b58", "best_bid": "0.18", "best_ask": "0.21"}], "timestamp": "1769384703595", "event_type": "price_change"}}
{"_local_timestamp": "2026-01-25T23:45:04.909686+00:00", "data": {"market": "0xca0329cd4392d91e39df0702949229573d2415ae4a37b0103d0c6e9d03b8dd44", "price_changes": [{"asset_id": "20535370510756332462433575263109694145574231213604117747907874615324086102913", "price": "0.21", "size": "2003.5", "side": "BUY", "hash": "078e9099f595cd02b413a265cf928bbe3cf4da2b", "best_bid": "0.79", "best_ask": "0.82"}, {"asset_id": "74768395815166461619548348007728690058055087254143355558596876906836785272025", "price": "0.79", "size": "2003.5", "side": "SELL", "hash": "6f85265827a5443f936e8ee0915d919ea91a6b23", "best_bid": "0.18", "best_ask": "0.21"}], "timestamp": "1769384704836", "event_type": "price_change"}}
{"_local_timestamp": "2026-01-25T23:45:11.290174+00:00", "data": {"market": "0xa05f081e032395b4527d964fcefb032834c81bef0e85ac533c81f66139c35af4", "price_changes": [{"asset_id": "69074333464069151404242315526218405459784935747253869832659873168984248759799", "price": "0.001", "size": "15528.42", "side": "BUY", "hash": "f9c5006f08eba42a052fd79c3ce24fa0dcc9a4da", "best_bid": "0.001", "best_ask": "0.003"}, {"asset_id": "56813972039885211974321877112282829005950793706240260412507113757740359845360", "price": "0.999", "size": "15528.42", "side": "SELL", "hash": "a01d949fad267808d93fc8aa8831e64e8d5342d1", "best_bid": "0.997", "best_ask": "0.999"}], "timestamp": "1769384711159", "event_type": "price_change"}}
{"_local_timestamp": "2026-01-25T23:45:11.321817+00:00", "data": {"market": "0xc5452a97769a9aa7a264d11bf07c7da6ff6080061d426cd7ef92abb47f6d8160", "price_changes": [{"asset_id": "8922710639437477954990654098858414058444921382508505451184351067105680225969", "price": "0.001", "size": "19219.35", "side": "BUY", "hash": "9f5052f9ec3fdc015880eaf28b0d0474cc1d9279", "best_bid": "0.002", "best_ask": "0.003"}, {"asset_id": "114340618694795548048032631237414556707214948596108879651552052673573136118536", "price": "0.999", "size": "19219.35", "side": "SELL", "hash": "b60f931ba23cfef7f44e18cf803aeb2d0f21adf2", "best_bid": "0.997", "best_ask": "0.998"}], "timestamp": "1769384711172", "event_type": "price_change"}}
{"_local_timestamp": "2026-01-25T23:45:11.323856+00:00", "data": {"market": "0xc1c30becf85027a3fad693fe00aed610c574220f32fabef52c1ac53f76153622", "price_changes": [{"asset_id": "44162996630579613944619329601086604585114580039271806622718850166081603488312", "price": "0.001", "size": "20199.29", "side": "BUY", "hash": "512260d779983a206692f25c3bb5fde449b61e93", "best_bid": "0.001", "best_ask": "0.003"}, {"asset_id": "86861447014827130074018921138137988822291708295577507404133014397402508069192", "price": "0.999", "size": "20199.29", "side": "SELL", "hash": "a3f9c65a9f4e10b88ddf486533ef519de130003c", "best_bid": "0.997", "best_ask": "0.999"}], "timestamp": "1769384711160", "event_type": "price_change"}}
{"_local_timestamp": "2026-01-25T23:45:11.325582+00:00", "data": {"market": "0x91f7e7f2d3727a5abca7eb77827355f9a968f6636606c3f47f35ce2c23c91cbc", "price_changes": [{"asset_id": "43986832901480115975770598885448914644973339441868156495326187103850202425816", "price": "0.002", "size": "905", "side": "BUY", "hash": "354e08009981f15065b3de6060fa50267334a7a2", "best_bid": "0.002", "best_ask": "0.003"}, {"asset_id": "84252679223362616378739922435722781121510894501012248080679822792405868493637", "price": "0.998", "size": "905", "side": "SELL", "hash": "3e857dffdd1ed6ade2c3a61182e1b85243a7dcc0", "best_bid": "0.997", "best_ask": "0.998"}], "timestamp": "1769384711167", "event_type": "price_change"}}
{"_local_timestamp": "2026-01-25T23:45:16.091901+00:00", "data": {"market": "0x0bde18e0a0220d1f97173850504a1ed4fa90ef2c6a7bc0932952790053ca0c0e", "price_changes": [{"asset_id": "4041912122563547970024635557261696068618666839090786586996637505354743961673", "price": "0.35", "size": "619", "side": "SELL", "hash": "340ceb0836a41d71108dbc5b3347e920abacb2fe", "best_bid": "0.31", "best_ask": "0.35"}, {"asset_id": "105325602140854796101190465907542426130401271786879982796716189175875071392057", "price": "0.65", "size": "619", "side": "BUY", "hash": "7d2e30f19fa6cb751c6d4a8768d848fc76a5486d", "best_bid": "0.65", "best_ask": "0.69"}], "timestamp": "1769384716003", "event_type": "price_change"}}
{"_local_timestamp": "2026-01-25T23:45:32.459578+00:00", "data": {"market": "0xca0329cd4392d91e39df0702949229573d2415ae4a37b0103d0c6e9d03b8dd44", "price_changes": [{"asset_id": "20535370510756332462433575263109694145574231213604117747907874615324086102913", "price": "0.08", "size": "700", "side": "BUY", "hash": "31357e9039ffabe4bfbae28b487c67cbb304ebe0", "best_bid": "0.79", "best_ask": "0.82"}, {"asset_id": "74768395815166461619548348007728690058055087254143355558596876906836785272025", "price": "0.92", "size": "700", "side": "SELL", "hash": "2a751d619e1070a47fdfc3dc4cded4b11944bb1a", "best_bid": "0.18", "best_ask": "0.21"}], "timestamp": "1769384732393", "event_type": "price_change"}}
{"_local_timestamp": "2026-01-25T23:45:41.295548+00:00", "data": {"market": "0x0bde18e0a0220d1f97173850504a1ed4fa90ef2c6a7bc0932952790053ca0c0e", "price_changes": [{"asset_id": "4041912122563547970024635557261696068618666839090786586996637505354743961673", "price": "0.29", "size": "104", "side": "BUY", "hash": "c35b2b0d774181dd05e8d7b76260ddfa62cded35", "best_bid": "0.31", "best_ask": "0.35"}, {"asset_id": "105325602140854796101190465907542426130401271786879982796716189175875071392057", "price": "0.71", "size": "104", "side": "SELL", "hash": "ea7b54f75d6599027cea6bcd9a07d63ac8cb1aa9", "best_bid": "0.65", "best_ask": "0.69"}], "timestamp": "1769384741189", "event_type": "price_change"}}
{"_local_timestamp": "2026-01-25T23:45:41.303045+00:00", "data": {"market": "0x0bde18e0a0220d1f97173850504a1ed4fa90ef2c6a7bc0932952790053ca0c0e", "price_changes": [{"asset_id": "105325602140854796101190465907542426130401271786879982796716189175875071392057", "price": "0.63", "size": "6", "side": "BUY", "hash": "6e4bd7a9ba4b79df4c677cf9ec902eca74f5b959", "best_bid": "0.65", "best_ask": "0.69"}, {"asset_id": "4041912122563547970024635557261696068618666839090786586996637505354743961673", "price": "0.37", "size": "6", "side": "SELL", "hash": "b5cf18514085e6b0238290574c481d311418ecef", "best_bid": "0.31", "best_ask": "0.35"}], "timestamp": "1769384741193", "event_type": "price_change"}}
{"_local_timestamp": "2026-01-25T23:45:45.118353+00:00", "data": {"market": "0x0bde18e0a0220d1f97173850504a1ed4fa90ef2c6a7bc0932952790053ca0c0e", "price_changes": [{"asset_id": "105325602140854796101190465907542426130401271786879982796716189175875071392057", "price": "0.63", "size": "56", "side": "BUY", "hash": "17a47fc924b92f9b6284ea59986b76f13cd754a8", "best_bid": "0.65", "best_ask": "0.69"}, {"asset_id": "4041912122563547970024635557261696068618666839090786586996637505354743961673", "price": "0.37", "size": "56", "side": "SELL", "hash": "7d5bfa9102410c3288a55d60ce7e95484fafe149", "best_bid": "0.31", "best_ask": "0.35"}], "timestamp": "1769384745051", "event_type": "price_change"}}
{"_local_timestamp": "2026-01-25T23:45:45.188693+00:00", "data": {"market": "0xca0329cd4392d91e39df0702949229573d2415ae4a37b0103d0c6e9d03b8dd44", "price_changes": [{"asset_id": "20535370510756332462433575263109694145574231213604117747907874615324086102913", "price": "0.08", "size": "0", "side": "BUY", "hash": "2e557ece15a2cb6d377322c1c2677babafb62f05", "best_bid": "0.79", "best_ask": "0.82"}, {"asset_id": "74768395815166461619548348007728690058055087254143355558596876906836785272025", "price": "0.92", "size": "0", "side": "SELL", "hash": "7a6348840a8e81527c3c4c7772e12a1df15e671a", "best_bid": "0.18", "best_ask": "0.21"}], "timestamp": "1769384745125", "event_type": "price_change"}}
{"_local_timestamp": "2026-01-25T23:45:48.434235+00:00", "data": {"market": "0xca0329cd4392d91e39df0702949229573d2415ae4a37b0103d0c6e9d03b8dd44", "price_changes": [{"asset_id": "20535370510756332462433575263109694145574231213604117747907874615324086102913", "price": "0.77", "size": "571", "side": "BUY", "hash": "36c4e28ceaf19c5e57ab39b52d96ab3f7d144bff", "best_bid": "0.79", "best_ask": "0.82"}, {"asset_id": "74768395815166461619548348007728690058055087254143355558596876906836785272025", "price": "0.23", "size": "571", "side": "SELL", "hash": "825bec3346457439a6589fcccc07115b693b34a7", "best_bid": "0.18", "best_ask": "0.21"}], "timestamp": "1769384748352", "event_type": "price_change"}}
{"_local_timestamp": "2026-01-25T23:45:48.454795+00:00", "data": {"market": "0xca0329cd4392d91e39df0702949229573d2415ae4a37b0103d0c6e9d03b8dd44", "price_changes": [{"asset_id": "74768395815166461619548348007728690058055087254143355558596876906836785272025", "price": "0.15", "size": "450", "side": "BUY", "hash": "c473c2e081caa8ad7efeff0280bc20eb038622f6", "best_bid": "0.18", "best_ask": "0.21"}, {"asset_id": "20535370510756332462433575263109694145574231213604117747907874615324086102913", "price": "0.85", "size": "450", "side": "SELL", "hash": "ce62c3849ec465d77c41a0e8c693e09850ff9503", "best_bid": "0.79", "best_ask": "0.82"}], "timestamp": "1769384748355", "event_type": "price_change"}}
{"_local_timestamp": "2026-01-25T23:45:53.102058+00:00", "data": {"market": "0xeb44a06c677ce7a47e5fd2007182e020a577395dc3613ad55d3d576e33964c3d", "price_changes": [{"asset_id": "5305471862219565371067835325573032839634510465603099489495163186843068331171", "price": "0.15", "size": "200", "side": "BUY", "hash": "847c3a0e098028eb61837217b8043f68115805d4", "best_bid": "0.5", "best_ask": "0.54"}, {"asset_id": "28227838360096074788232992585368970461718254845788738931649369286727917170476", "price": "0.85", "size": "200", "side": "SELL", "hash": "aecd01b16ec6bfdf8d04e4914e9ff3f2e5eb20d2", "best_bid": "0.46", "best_ask": "0.5"}], "timestamp": "1769384752999", "event_type": "price_change"}}
{"_local_timestamp": "2026-01-25T23:45:53.662853+00:00", "data": {"market": "0xeb44a06c677ce7a47e5fd2007182e020a577395dc3613ad55d3d576e33964c3d", "price_changes": [{"asset_id": "5305471862219565371067835325573032839634510465603099489495163186843068331171", "price": "0.12", "size": "1682", "side": "BUY", "hash": "bb118fc1bba623b4ab19a5e10f02e2f8563a3e7d", "best_bid": "0.5", "best_ask": "0.54"}, {"asset_id": "28227838360096074788232992585368970461718254845788738931649369286727917170476", "price": "0.88", "size": "1682", "side": "SELL", "hash": "2e4f06b48f4092c7da71755a0e80c59fa0a5aba9", "best_bid": "0.46", "best_ask": "0.5"}], "timestamp": "1769384753519", "event_type": "price_change"}}
{"_local_timestamp": "2026-01-25T23:45:56.569571+00:00", "data": {"market": "0xeb44a06c677ce7a47e5fd2007182e020a577395dc3613ad55d3d576e33964c3d", "price_changes": [{"asset_id": "5305471862219565371067835325573032839634510465603099489495163186843068331171", "price": "0.16", "size": "3074", "side": "BUY", "hash": "0eee451f0503e87e697fcaefee3376277971f989", "best_bid": "0.5", "best_ask": "0.54"}, {"asset_id": "28227838360096074788232992585368970461718254845788738931649369286727917170476", "price": "0.84", "size": "3074", "side": "SELL", "hash": "9f566f0c4f74cb956bf38e1bdf47df1a7822e6c6", "best_bid": "0.46", "best_ask": "0.5"}], "timestamp": "1769384756083", "event_type": "price_change"}}
{"_local_timestamp": "2026-01-25T23:45:57.817459+00:00", "data": {"market": "0x0bde18e0a0220d1f97173850504a1ed4fa90ef2c6a7bc0932952790053ca0c0e", "price_changes": [{"asset_id": "4041912122563547970024635557261696068618666839090786586996637505354743961673", "price": "0.29", "size": "154", "side": "BUY", "hash": "e345e4f42895668be63109c1c007c653bc2ea16d", "best_bid": "0.31", "best_ask": "0.35"}, {"asset_id": "105325602140854796101190465907542426130401271786879982796716189175875071392057", "price": "0.71", "size": "154", "side": "SELL", "hash": "660960e3f9dc359266b06f751fc4a274e43babf8", "best_bid": "0.65", "best_ask": "0.69"}], "timestamp": "1769384757747", "event_type": "price_change"}}
{"_local_timestamp": "2026-01-25T23:45:58.894141+00:00", "data": {"market": "0xca0329cd4392d91e39df0702949229573d2415ae4a37b0103d0c6e9d03b8dd44", "price_changes": [{"asset_id": "20535370510756332462433575263109694145574231213604117747907874615324086102913", "price": "0.77", "size": "621", "side": "BUY", "hash": "8d78bfbc51a556bdd42fb795836281f964fb228d", "best_bid": "0.79", "best_ask": "0.82"}, {"asset_id": "74768395815166461619548348007728690058055087254143355558596876906836785272025", "price": "0.23", "size": "621", "side": "SELL", "hash": "6247eae0fda6f9dca25b44b3f44aea23a097a175", "best_bid": "0.18", "best_ask": "0.21"}], "timestamp": "1769384758825", "event_type": "price_change"}}
{"_local_timestamp": "2026-01-25T23:46:02.827228+00:00", "data": {"market": "0xeb44a06c677ce7a47e5fd2007182e020a577395dc3613ad55d3d576e33964c3d", "price_changes": [{"asset_id": "5305471862219565371067835325573032839634510465603099489495163186843068331171", "price": "0.17", "size": "452.94", "side": "BUY", "hash": "ac31f1be699b8e5ab8824dd56c714b3b0125a59f", "best_bid": "0.5", "best_ask": "0.54"}, {"asset_id": "28227838360096074788232992585368970461718254845788738931649369286727917170476", "price": "0.83", "size": "452.94", "side": "SELL", "hash": "6ccd52e332a666abfc56b8a40f3d084a6587095b", "best_bid": "0.46", "best_ask": "0.5"}], "timestamp": "1769384762724", "event_type": "price_change"}}
{"_local_timestamp": "2026-01-25T23:46:10.043336+00:00", "data": {"market": "0xca0329cd4392d91e39df0702949229573d2415ae4a37b0103d0c6e9d03b8dd44", "price_changes": [{"asset_id": "74768395815166461619548348007728690058055087254143355558596876906836785272025", "price": "0.15", "size": "500", "side": "BUY", "hash": "e030b3c9ceb09277af00c3db1dc1f62c29341586", "best_bid": "0.18", "best_ask": "0.21"}, {"asset_id": "20535370510756332462433575263109694145574231213604117747907874615324086102913", "price": "0.85", "size": "500", "side": "SELL", "hash": "8434eba5f44f6262ac800676ff4fb20147b01282", "best_bid": "0.79", "best_ask": "0.82"}], "timestamp": "1769384769976", "event_type": "price_change"}}
{"_local_timestamp": "2026-01-25T23:46:10.597209+00:00", "data": {"market": "0xca0329cd4392d91e39df0702949229573d2415ae4a37b0103d0c6e9d03b8dd44", "price_changes": [{"asset_id": "20535370510756332462433575263109694145574231213604117747907874615324086102913", "price": "0.21", "size": "5.5", "side": "BUY", "hash": "ea58f013d980a6db29863e29ad7f15dbfb4346c8", "best_bid": "0.79", "best_ask": "0.82"}, {"asset_id": "74768395815166461619548348007728690058055087254143355558596876906836785272025", "price": "0.79", "size": "5.5", "side": "SELL", "hash": "b74828826597e18a355eae6a65601d00b4d66249", "best_bid": "0.18", "best_ask": "0.21"}], "timestamp": "1769384770468", "event_type": "price_change"}}
{"_local_timestamp": "2026-01-25T23:46:12.358853+00:00", "data": {"market": "0xca0329cd4392d91e39df0702949229573d2415ae4a37b0103d0c6e9d03b8dd44", "price_changes": [{"asset_id": "20535370510756332462433575263109694145574231213604117747907874615324086102913", "price": "0.06", "size": "0", "side": "BUY", "hash": "66605024a691b4665f31eb9d71319280ab87be25", "best_bid": "0.79", "best_ask": "0.82"}, {"asset_id": "74768395815166461619548348007728690058055087254143355558596876906836785272025", "price": "0.94", "size": "0", "side": "SELL", "hash": "e2016f26b25688ec76f7e35675f98ac088ef6a95", "best_bid": "0.18", "best_ask": "0.21"}], "timestamp": "1769384772292", "event_type": "price_change"}}
{"_local_timestamp": "2026-01-25T23:46:12.760807+00:00", "data": {"market": "0xca0329cd4392d91e39df0702949229573d2415ae4a37b0103d0c6e9d03b8dd44", "price_changes": [{"asset_id": "20535370510756332462433575263109694145574231213604117747907874615324086102913", "price": "0.08", "size": "300", "side": "BUY", "hash": "5d1b331c6b89ea9b207098329c86679a4be021f7", "best_bid": "0.79", "best_ask": "0.82"}, {"asset_id": "74768395815166461619548348007728690058055087254143355558596876906836785272025", "price": "0.92", "size": "300", "side": "SELL", "hash": "d66f65fffe784f797490e1c239debc2df5d194e8", "best_bid": "0.18", "best_ask": "0.21"}], "timestamp": "1769384772690", "event_type": "price_change"}}
{"_local_timestamp": "2026-01-25T23:46:15.656245+00:00", "data": {"market": "0xca0329cd4392d91e39df0702949229573d2415ae4a37b0103d0c6e9d03b8dd44", "price_changes": [{"asset_id": "20535370510756332462433575263109694145574231213604117747907874615324086102913", "price": "0.08", "size": "1000", "side": "BUY", "hash": "a1963fdb7b5f50b79f478cfe91419d7a40c2fe26", "best_bid": "0.79", "best_ask": "0.82"}, {"asset_id": "74768395815166461619548348007728690058055087254143355558596876906836785272025", "price": "0.92", "size": "1000", "side": "SELL", "hash": "7a90951aff2b09a5275bd615e6a526ed08d86f79", "best_bid": "0.18", "best_ask": "0.21"}], "timestamp": "1769384775593", "event_type": "price_change"}}
{"_local_timestamp": "2026-01-25T23:46:17.314037+00:00", "data": {"market": "0xca0329cd4392d91e39df0702949229573d2415ae4a37b0103d0c6e9d03b8dd44", "price_changes": [{"asset_id": "20535370510756332462433575263109694145574231213604117747907874615324086102913", "price": "0.23", "size": "200", "side": "BUY", "hash": "67cfe430aea43bbbb16e7f6cdf17725c9fb0bbea", "best_bid": "0.79", "best_ask": "0.82"}, {"asset_id": "74768395815166461619548348007728690058055087254143355558596876906836785272025", "price": "0.77", "size": "200", "side": "SELL", "hash": "e3bf417f4fba3e4ec170b0e77d73485749aef395", "best_bid": "0.18", "best_ask": "0.21"}], "timestamp": "1769384777251", "event_type": "price_change"}}
{"_local_timestamp": "2026-01-25T23:46:17.718879+00:00", "data": {"market": "0xca0329cd4392d91e39df0702949229573d2415ae4a37b0103d0c6e9d03b8dd44", "price_changes": [{"asset_id": "20535370510756332462433575263109694145574231213604117747907874615324086102913", "price": "0.21", "size": "105.5", "side": "BUY", "hash": "f13a7bb2b383a6ab9a9eb5d3e7650b43fbb5d539", "best_bid": "0.79", "best_ask": "0.82"}, {"asset_id": "74768395815166461619548348007728690058055087254143355558596876906836785272025", "price": "0.79", "size": "105.5", "side": "SELL", "hash": "02b27fe0bf4505ba393bc22137bacaab94554f6b", "best_bid": "0.18", "best_ask": "0.21"}], "timestamp": "1769384777644", "event_type": "price_change"}}
{"_local_timestamp": "2026-01-25T23:46:26.181627+00:00", "data": {"market": "0x0bde18e0a0220d1f97173850504a1ed4fa90ef2c6a7bc0932952790053ca0c0e", "price_changes": [{"asset_id": "4041912122563547970024635557261696068618666839090786586996637505354743961673", "price": "0.35", "size": "645", "side": "SELL", "hash": "a20785c4e02165982bd77360d11a6e289f45b670", "best_bid": "0.31", "best_ask": "0.35"}, {"asset_id": "105325602140854796101190465907542426130401271786879982796716189175875071392057", "price": "0.65", "size": "645", "side": "BUY", "hash": "2e1240ff90509e444dda80e8c057355e3a789708", "best_bid": "0.65", "best_ask": "0.69"}], "timestamp": "1769384786112", "event_type": "price_change"}}
{"_local_timestamp": "2026-01-25T23:46:26.854490+00:00", "data": {"market": "0xca0329cd4392d91e39df0702949229573d2415ae4a37b0103d0c6e9d03b8dd44", "price_changes": [{"asset_id": "20535370510756332462433575263109694145574231213604117747907874615324086102913", "price": "0.08", "size": "300", "side": "BUY", "hash": "a10e7ebfc628d33c24d64e9dc55f1bd86f6de5f1", "best_bid": "0.79", "best_ask": "0.82"}, {"asset_id": "74768395815166461619548348007728690058055087254143355558596876906836785272025", "price": "0.92", "size": "300", "side": "SELL", "hash": "9e6dc3ddff43a6576f26690ad156985bb3259e02", "best_bid": "0.18", "best_ask": "0.21"}], "timestamp": "1769384786781", "event_type": "price_change"}}
{"_local_timestamp": "2026-01-25T23:46:45.087963+00:00", "data": {"market": "0x0bde18e0a0220d1f97173850504a1ed4fa90ef2c6a7bc0932952790053ca0c0e", "price_changes": [{"asset_id": "4041912122563547970024635557261696068618666839090786586996637505354743961673", "price": "0.35", "size": "619", "side": "SELL", "hash": "4c25f4042eb381f91e7cfe98f0000d318f59df83", "best_bid": "0.31", "best_ask": "0.35"}, {"asset_id": "105325602140854796101190465907542426130401271786879982796716189175875071392057", "price": "0.65", "size": "619", "side": "BUY", "hash": "3704817136d1fe78a2ccbb2ab449e294bed9171f", "best_bid": "0.65", "best_ask": "0.69"}], "timestamp": "1769384805000", "event_type": "price_change"}}
{"_local_timestamp": "2026-01-25T23:46:51.153885+00:00", "data": {"market": "0xeb44a06c677ce7a47e5fd2007182e020a577395dc3613ad55d3d576e33964c3d", "price_changes": [{"asset_id": "5305471862219565371067835325573032839634510465603099489495163186843068331171", "price": "0.15", "size": "0", "side": "BUY", "hash": "1b42495f3aeb6180ba99a027810cc4249667c455", "best_bid": "0.5", "best_ask": "0.54"}, {"asset_id": "28227838360096074788232992585368970461718254845788738931649369286727917170476", "price": "0.85", "size": "0", "side": "SELL", "hash": "5abf75630bec4b466f32e13b7c1067f29354ffe3", "best_bid": "0.46", "best_ask": "0.5"}], "timestamp": "1769384810868", "event_type": "price_change"}}
{"_local_timestamp": "2026-01-25T23:46:51.154629+00:00", "data": {"market": "0xeb44a06c677ce7a47e5fd2007182e020a577395dc3613ad55d3d576e33964c3d", "price_changes": [{"asset_id": "28227838360096074788232992585368970461718254845788738931649369286727917170476", "price": "0.18", "size": "261.11", "side": "BUY", "hash": "407fa30e1498f092230ad7ea8845d43124180356", "best_bid": "0.46", "best_ask": "0.5"}, {"asset_id": "5305471862219565371067835325573032839634510465603099489495163186843068331171", "price": "0.82", "size": "261.11", "side": "SELL", "hash": "a2b3e7ef4edb97ddceb511a4545bb050cadcab9f", "best_bid": "0.5", "best_ask": "0.54"}], "timestamp": "1769384810868", "event_type": "price_change"}}
{"_local_timestamp": "2026-01-25T23:46:51.608035+00:00", "data": {"market": "0xeb44a06c677ce7a47e5fd2007182e020a577395dc3613ad55d3d576e33964c3d", "price_changes": [{"asset_id": "28227838360096074788232992585368970461718254845788738931649369286727917170476", "price": "0.16", "size": "400", "side": "BUY", "hash": "0cae1091388b35b44f2674136499f2d4e14c240a", "best_bid": "0.46", "best_ask": "0.5"}, {"asset_id": "5305471862219565371067835325573032839634510465603099489495163186843068331171", "price": "0.84", "size": "400", "side": "SELL", "hash": "5896327044b8c8802e623e59dc28770a2edc66f1", "best_bid": "0.5", "best_ask": "0.54"}], "timestamp": "1769384811230", "event_type": "price_change"}}
{"_local_timestamp": "2026-01-25T23:46:51.951742+00:00", "data": {"market": "0xeb44a06c677ce7a47e5fd2007182e020a577395dc3613ad55d3d576e33964c3d", "price_changes": [{"asset_id": "5305471862219565371067835325573032839634510465603099489495163186843068331171", "price": "0.12", "size": "1882", "side": "BUY", "hash": "60b3d678a14939d9b62192e1fd89492b8c17e26c", "best_bid": "0.5", "best_ask": "0.54"}, {"asset_id": "28227838360096074788232992585368970461718254845788738931649369286727917170476", "price": "0.88", "size": "1882", "side": "SELL", "hash": "df2f797cbf192d565a038bd65a4405eb864e49d3", "best_bid": "0.46", "best_ask": "0.5"}], "timestamp": "1769384811270", "event_type": "price_change"}}
{"_local_timestamp": "2026-01-25T23:46:55.767073+00:00", "data": {"market": "0x0bde18e0a0220d1f97173850504a1ed4fa90ef2c6a7bc0932952790053ca0c0e", "price_changes": [{"asset_id": "105325602140854796101190465907542426130401271786879982796716189175875071392057", "price": "0.7", "size": "222.09", "side": "SELL", "hash": "edc244f2dc9f84803cb350b27be9bda115cbae8f", "best_bid": "0.65", "best_ask": "0.69"}, {"asset_id": "4041912122563547970024635557261696068618666839090786586996637505354743961673", "price": "0.3", "size": "222.09", "side": "BUY", "hash": "ca6e94f8b66316f5df65c8f75530ae1424a61409", "best_bid": "0.31", "best_ask": "0.35"}], "timestamp": "1769384815695", "event_type": "price_change"}}
{"_local_timestamp": "2026-01-25T23:46:57.053680+00:00", "data": {"market": "0x0bde18e0a0220d1f97173850504a1ed4fa90ef2c6a7bc0932952790053ca0c0e", "price_changes": [{"asset_id": "105325602140854796101190465907542426130401271786879982796716189175875071392057", "price": "0.7", "size": "448.5", "side": "SELL", "hash": "f8c341fb5ed68e40503d0f66d2444449f081234c", "best_bid": "0.65", "best_ask": "0.69"}, {"asset_id": "4041912122563547970024635557261696068618666839090786586996637505354743961673", "price": "0.3", "size": "448.5", "side": "BUY", "hash": "6d9da6431d989ee3e54dc3cc4af845bb8fb4617a", "best_bid": "0.31", "best_ask": "0.35"}], "timestamp": "1769384816962", "event_type": "price_change"}}
{"_local_timestamp": "2026-01-25T23:46:57.736722+00:00", "data": {"market": "0xca0329cd4392d91e39df0702949229573d2415ae4a37b0103d0c6e9d03b8dd44", "price_changes": [{"asset_id": "20535370510756332462433575263109694145574231213604117747907874615324086102913", "price": "0.08", "size": "1000", "side": "BUY", "hash": "f071a9a90fc3cfcc3782de21d5062d45df374b0d", "best_bid": "0.79", "best_ask": "0.82"}, {"asset_id": "74768395815166461619548348007728690058055087254143355558596876906836785272025", "price": "0.92", "size": "1000", "side": "SELL", "hash": "0731f758036cad73fe292c25cbe9d83138836e07", "best_bid": "0.18", "best_ask": "0.21"}], "timestamp": "1769384817665", "event_type": "price_change"}}
{"_local_timestamp": "2026-01-25T23:46:57.960621+00:00", "data": {"market": "0xca0329cd4392d91e39df0702949229573d2415ae4a37b0103d0c6e9d03b8dd44", "price_changes": [{"asset_id": "20535370510756332462433575263109694145574231213604117747907874615324086102913", "price": "0.24", "size": "1748", "side": "BUY", "hash": "51c1b84cfa968d32063d0341ea914ba80e877f15", "best_bid": "0.79", "best_ask": "0.82"}, {"asset_id": "74768395815166461619548348007728690058055087254143355558596876906836785272025", "price": "0.76", "size": "1748", "side": "SELL", "hash": "6899eba8a9dd7604cc7772e569306b832c1ce37b", "best_bid": "0.18", "best_ask": "0.21"}], "timestamp": "1769384817883", "event_type": "price_change"}}
{"_local_timestamp": "2026-01-25T23:46:58.921107+00:00", "data": {"market": "0xca0329cd4392d91e39df0702949229573d2415ae4a37b0103d0c6e9d03b8dd44", "price_changes": [{"asset_id": "20535370510756332462433575263109694145574231213604117747907874615324086102913", "price": "0.21", "size": "5.5", "side": "BUY", "hash": "62a7d995dc081c89c24a5b624cd49181e5d454c6", "best_bid": "0.79", "best_ask": "0.82"}, {"asset_id": "74768395815166461619548348007728690058055087254143355558596876906836785272025", "price": "0.79", "size": "5.5", "side": "SELL", "hash": "e8d6fb12bc93b6ba312d440ecb16368ab2dff88f", "best_bid": "0.18", "best_ask": "0.21"}], "timestamp": "1769384818843", "event_type": "price_change"}}
{"_local_timestamp": "2026-01-25T23:46:59.321687+00:00", "data": {"market": "0xca0329cd4392d91e39df0702949229573d2415ae4a37b0103d0c6e9d03b8dd44", "price_changes": [{"asset_id": "20535370510756332462433575263109694145574231213604117747907874615324086102913", "price": "0.23", "size": "300", "side": "BUY", "hash": "0c5aa0be139474678900a3bf960e2e9080afbe85", "best_bid": "0.79", "best_ask": "0.82"}, {"asset_id": "74768395815166461619548348007728690058055087254143355558596876906836785272025", "price": "0.77", "size": "300", "side": "SELL", "hash": "71bc91ddfa3c97bf687e22412dcc6667721aa7bb", "best_bid": "0.18", "best_ask": "0.21"}], "timestamp": "1769384819190", "event_type": "price_change"}}
{"_local_timestamp": "2026-01-25T23:46:59.538038+00:00", "data": {"market": "0x0bde18e0a0220d1f97173850504a1ed4fa90ef2c6a7bc0932952790053ca0c0e", "price_changes": [{"asset_id": "4041912122563547970024635557261696068618666839090786586996637505354743961673", "price": "0.29", "size": "56", "side": "BUY", "hash": "b61cdab1827173eaa6d2de92b3fbf7b89cacd55a", "best_bid": "0.31", "best_ask": "0.35"}, {"asset_id": "105325602140854796101190465907542426130401271786879982796716189175875071392057", "price": "0.71", "size": "56", "side": "SELL", "hash": "3d294cca5a3c644826449f384845358e02a33fc4", "best_bid": "0.65", "best_ask": "0.69"}], "timestamp": "1769384819474", "event_type": "price_change"}}
{"_local_timestamp": "2026-01-25T23:47:03.598783+00:00", "data": {"market": "0x0bde18e0a0220d1f97173850504a1ed4fa90ef2c6a7bc0932952790053ca0c0e", "price_changes": [{"asset_id": "4041912122563547970024635557261696068618666839090786586996637505354743961673", "price": "0.29", "size": "154", "side": "BUY", "hash": "aeda9813506b64663f901c611b8e81d231ce1a3e", "best_bid": "0.31", "best_ask": "0.35"}, {"asset_id": "105325602140854796101190465907542426130401271786879982796716189175875071392057", "price": "0.71", "size": "154", "side": "SELL", "hash": "1cd62aa18208521fa712f48db2f639c5e0484e49", "best_bid": "0.65", "best_ask": "0.69"}], "timestamp": "1769384823531", "event_type": "price_change"}}
{"_local_timestamp": "2026-01-25T23:47:23.468510+00:00", "data": {"market": "0xca0329cd4392d91e39df0702949229573d2415ae4a37b0103d0c6e9d03b8dd44", "price_changes": [{"asset_id": "20535370510756332462433575263109694145574231213604117747907874615324086102913", "price": "0.23", "size": "250", "side": "BUY", "hash": "0aa90327bdf1f56c60ac055309440c1582a57ff6", "best_bid": "0.79", "best_ask": "0.82"}, {"asset_id": "74768395815166461619548348007728690058055087254143355558596876906836785272025", "price": "0.77", "size": "250", "side": "SELL", "hash": "9913ef72ea24f81c12a67c8b7d6cc71977e073fb", "best_bid": "0.18", "best_ask": "0.21"}], "timestamp": "1769384843384", "event_type": "price_change"}}
{"_local_timestamp": "2026-01-25T23:47:23.961839+00:00", "data": {"market": "0xca0329cd4392d91e39df0702949229573d2415ae4a37b0103d0c6e9d03b8dd44", "price_changes": [{"asset_id": "20535370510756332462433575263109694145574231213604117747907874615324086102913", "price": "0.21", "size": "55.5", "side": "BUY", "hash": "76f2293bcc71b39ded918961df155559e0b6952e", "best_bid": "0.79", "best_ask": "0.82"}, {"asset_id": "74768395815166461619548348007728690058055087254143355558596876906836785272025", "price": "0.79", "size": "55.5", "side": "SELL", "hash": "d6fd605135931e39da8bd25e396dd90798135cb3", "best_bid": "0.18", "best_ask": "0.21"}], "timestamp": "1769384843837", "event_type": "price_change"}}
{"_local_timestamp": "2026-01-25T23:47:37.356123+00:00", "data": {"market": "0xca0329cd4392d91e39df0702949229573d2415ae4a37b0103d0c6e9d03b8dd44", "price_changes": [{"asset_id": "20535370510756332462433575263109694145574231213604117747907874615324086102913", "price": "0.23", "size": "150", "side": "BUY", "hash": "a818f5e106cb11cf5faaf6de24dcd12f924dcec1", "best_bid": "0.79", "best_ask": "0.82"}, {"asset_id": "74768395815166461619548348007728690058055087254143355558596876906836785272025", "price": "0.77", "size": "150", "side": "SELL", "hash": "0d9989544ca7677b28472ce75ba9281a0ca8661b", "best_bid": "0.18", "best_ask": "0.21"}], "timestamp": "1769384857286", "event_type": "price_change"}}
{"_local_timestamp": "2026-01-25T23:47:37.357780+00:00", "data": {"market": "0xeb44a06c677ce7a47e5fd2007182e020a577395dc3613ad55d3d576e33964c3d", "price_changes": [{"asset_id": "28227838360096074788232992585368970461718254845788738931649369286727917170476", "price": "0.18", "size": "111.11", "side": "BUY", "hash": "b4ad730e46b03a38aa1f4a09cb37da0b974e17e1", "best_bid": "0.46", "best_ask": "0.5"}, {"asset_id": "5305471862219565371067835325573032839634510465603099489495163186843068331171", "price": "0.82", "size": "111.11", "side": "SELL", "hash": "fb96d0f7621ba4c75be67c93448fdd0cf0b75ecd", "best_bid": "0.5", "best_ask": "0.54"}], "timestamp": "1769384857286", "event_type": "price_change"}}
{"_local_timestamp": "2026-01-25T23:47:37.809856+00:00", "data": {"market": "0xeb44a06c677ce7a47e5fd2007182e020a577395dc3613ad55d3d576e33964c3d", "price_changes": [{"asset_id": "28227838360096074788232992585368970461718254845788738931649369286727917170476", "price": "0.16", "size": "300", "side": "BUY", "hash": "9e54ff1a93c1ede3402392d7bcd40dbbc422939b", "best_bid": "0.46", "best_ask": "0.5"}, {"asset_id": "5305471862219565371067835325573032839634510465603099489495163186843068331171", "price": "0.84", "size": "300", "side": "SELL", "hash": "bc3c7ec3151b3da6bb04c1f0ef2dda1a0b3cbf74", "best_bid": "0.5", "best_ask": "0.54"}], "timestamp": "1769384857561", "event_type": "price_change"}}
{"_local_timestamp": "2026-01-25T23:47:37.817804+00:00", "data": {"market": "0xca0329cd4392d91e39df0702949229573d2415ae4a37b0103d0c6e9d03b8dd44", "price_changes": [{"asset_id": "20535370510756332462433575263109694145574231213604117747907874615324086102913", "price": "0.23", "size": "100", "side": "BUY", "hash": "46eac03b5171e8698e913be10525be09268c4c55", "best_bid": "0.79", "best_ask": "0.82"}, {"asset_id": "74768395815166461619548348007728690058055087254143355558596876906836785272025", "price": "0.77", "size": "100", "side": "SELL", "hash": "e0de9d1e961723429aefb28ad52d945936f9d67f", "best_bid": "0.18", "best_ask": "0.21"}], "timestamp": "1769384857561", "event_type": "price_change"}}
{"_local_timestamp": "2026-01-25T23:47:37.863072+00:00", "data": {"market": "0xca0329cd4392d91e39df0702949229573d2415ae4a37b0103d0c6e9d03b8dd44", "price_changes": [{"asset_id": "20535370510756332462433575263109694145574231213604117747907874615324086102913", "price": "0.24", "size": "1848", "side": "BUY", "hash": "e218036212d1c427fc5b2748fae9398a0cb36dbc", "best_bid": "0.79", "best_ask": "0.82"}, {"asset_id": "74768395815166461619548348007728690058055087254143355558596876906836785272025", "price": "0.76", "size": "1848", "side": "SELL", "hash": "abf2db028ee6f785f8f07dc49c1dc2de56aabab8", "best_bid": "0.18", "best_ask": "0.21"}], "timestamp": "1769384857589", "event_type": "price_change"}}
{"_local_timestamp": "2026-01-25T23:47:37.948794+00:00", "data": {"market": "0xeb44a06c677ce7a47e5fd2007182e020a577395dc3613ad55d3d576e33964c3d", "price_changes": [{"asset_id": "28227838360096074788232992585368970461718254845788738931649369286727917170476", "price": "0.16", "size": "450", "side": "BUY", "hash": "2dd0d394fd6120e71d8b4749fcf52d6cd7fcb9d5", "best_bid": "0.46", "best_ask": "0.5"}, {"asset_id": "5305471862219565371067835325573032839634510465603099489495163186843068331171", "price": "0.84", "size": "450", "side": "SELL", "hash": "18a7a8b07270e9e634202f988ab01c345a113374", "best_bid": "0.5", "best_ask": "0.54"}], "timestamp": "1769384857606", "event_type": "price_change"}}
{"_local_timestamp": "2026-01-25T23:47:38.350949+00:00", "data": {"market": "0xca0329cd4392d91e39df0702949229573d2415ae4a37b0103d0c6e9d03b8dd44", "price_changes": [{"asset_id": "20535370510756332462433575263109694145574231213604117747907874615324086102913", "price": "0.21", "size": "105.5", "side": "BUY", "hash": "58cddc6b7be31a11327acd196d1b2bbe3bcaff77", "best_bid": "0.79", "best_ask": "0.82"}, {"asset_id": "74768395815166461619548348007728690058055087254143355558596876906836785272025", "price": "0.79", "size": "105.5", "side": "SELL", "hash": "e55dec7662b20fbd72cdfde04c76e9539a662ee2", "best_bid": "0.18", "best_ask": "0.21"}], "timestamp": "1769384858058", "event_type": "price_change"}}
{"_local_timestamp": "2026-01-25T23:47:38.460158+00:00", "data": {"market": "0xeb44a06c677ce7a47e5fd2007182e020a577395dc3613ad55d3d576e33964c3d", "price_changes": [{"asset_id": "28227838360096074788232992585368970461718254845788738931649369286727917170476", "price": "0.18", "size": "211.11", "side": "BUY", "hash": "8455a7ec95cdb942c7b9c8fa14954f0bc4441805", "best_bid": "0.46", "best_ask": "0.5"}, {"asset_id": "5305471862219565371067835325573032839634510465603099489495163186843068331171", "price": "0.82", "size": "211.11", "side": "SELL", "hash": "d855041a6343a10ae953ecb4d15d399903b1ae72", "best_bid": "0.5", "best_ask": "0.54"}], "timestamp": "1769384858096", "event_type": "price_change"}}
{"_local_timestamp": "2026-01-25T23:47:55.651861+00:00", "data": {"market": "0xeb44a06c677ce7a47e5fd2007182e020a577395dc3613ad55d3d576e33964c3d", "price_changes": [{"asset_id": "5305471862219565371067835325573032839634510465603099489495163186843068331171", "price": "0.16", "size": "450", "side": "BUY", "hash": "0de333775f25ccb3c5749d09fa426d0c0dd8ea76", "best_bid": "0.5", "best_ask": "0.54"}, {"asset_id": "28227838360096074788232992585368970461718254845788738931649369286727917170476", "price": "0.84", "size": "450", "side": "SELL", "hash": "1f8b66237d839a1cd56c65325b72d044ffc1e000", "best_bid": "0.46", "best_ask": "0.5"}], "timestamp": "1769384875420", "event_type": "price_change"}}
{"_local_timestamp": "2026-01-25T23:47:56.216777+00:00", "data": {"market": "0x0bde18e0a0220d1f97173850504a1ed4fa90ef2c6a7bc0932952790053ca0c0e", "price_changes": [{"asset_id": "4041912122563547970024635557261696068618666839090786586996637505354743961673", "price": "0.35", "size": "645", "side": "SELL", "hash": "d6f6742b25fe8b64a08a23b0b25d73423b975d7b", "best_bid": "0.31", "best_ask": "0.35"}, {"asset_id": "105325602140854796101190465907542426130401271786879982796716189175875071392057", "price": "0.65", "size": "645", "side": "BUY", "hash": "cfa49673736d30e71dda2a3e1179d2b1b174aa83", "best_bid": "0.65", "best_ask": "0.69"}], "timestamp": "1769384876153", "event_type": "price_change"}}
{"_local_timestamp": "2026-01-25T23:48:16.071231+00:00", "data": {"market": "0x0bde18e0a0220d1f97173850504a1ed4fa90ef2c6a7bc0932952790053ca0c0e", "price_changes": [{"asset_id": "4041912122563547970024635557261696068618666839090786586996637505354743961673", "price": "0.35", "size": "619", "side": "SELL", "hash": "b92ad07db2ac9b4d0aea063a04b37826d662dddd", "best_bid": "0.31", "best_ask": "0.35"}, {"asset_id": "105325602140854796101190465907542426130401271786879982796716189175875071392057", "price": "0.65", "size": "619", "side": "BUY", "hash": "aa1803ab4899c5ec8e16d8db7ad4390e992350b7", "best_bid": "0.65", "best_ask": "0.69"}], "timestamp": "1769384896000", "event_type": "price_change"}}
{"_local_timestamp": "2026-01-25T23:48:24.477939+00:00", "data": {"market": "0xeb44a06c677ce7a47e5fd2007182e020a577395dc3613ad55d3d576e33964c3d", "price_changes": [{"asset_id": "5305471862219565371067835325573032839634510465603099489495163186843068331171", "price": "0.15", "size": "2798", "side": "BUY", "hash": "72c9de460df37c6b2e3b6cf90efbfad97386f6a6", "best_bid": "0.5", "best_ask": "0.54"}, {"asset_id": "28227838360096074788232992585368970461718254845788738931649369286727917170476", "price": "0.85", "size": "2798", "side": "SELL", "hash": "fa534dcf482207a66957c039a8457c2fb87b54af", "best_bid": "0.46", "best_ask": "0.5"}], "timestamp": "1769384904413", "event_type": "price_change"}}
{"_local_timestamp": "2026-01-25T23:48:26.119911+00:00", "data": {"market": "0xeb44a06c677ce7a47e5fd2007182e020a577395dc3613ad55d3d576e33964c3d", "price_changes": [{"asset_id": "5305471862219565371067835325573032839634510465603099489495163186843068331171", "price": "0.16", "size": "400", "side": "BUY", "hash": "dfa186204e2607f89d02e457496db9e88c02051b", "best_bid": "0.5", "best_ask": "0.54"}, {"asset_id": "28227838360096074788232992585368970461718254845788738931649369286727917170476", "price": "0.84", "size": "400", "side": "SELL", "hash": "2ea536b53fd31031b7863f83d1baa865890f7ec2", "best_bid": "0.46", "best_ask": "0.5"}], "timestamp": "1769384906026", "event_type": "price_change"}}
{"_local_timestamp": "2026-01-25T23:48:26.366931+00:00", "data": {"market": "0xeb44a06c677ce7a47e5fd2007182e020a577395dc3613ad55d3d576e33964c3d", "price_changes": [{"asset_id": "5305471862219565371067835325573032839634510465603099489495163186843068331171", "price": "0.12", "size": "1932", "side": "BUY", "hash": "0a3616fa4522d53155358cde63bd239b5229a048", "best_bid": "0.5", "best_ask": "0.54"}, {"asset_id": "28227838360096074788232992585368970461718254845788738931649369286727917170476", "price": "0.88", "size": "1932", "side": "SELL", "hash": "b2f6cd318a8ded3ab4037a10833b2b17d9cd9935", "best_bid": "0.46", "best_ask": "0.5"}], "timestamp": "1769384906300", "event_type": "price_change"}}
{"_local_timestamp": "2026-01-25T23:48:48.535618+00:00", "data": {"market": "0xeb44a06c677ce7a47e5fd2007182e020a577395dc3613ad55d3d576e33964c3d", "price_changes": [{"asset_id": "5305471862219565371067835325573032839634510465603099489495163186843068331171", "price": "0.16", "size": "250", "side": "BUY", "hash": "1a63cce5a5c7f2d0e241caa986300d67a40a655b", "best_bid": "0.5", "best_ask": "0.54"}, {"asset_id": "28227838360096074788232992585368970461718254845788738931649369286727917170476", "price": "0.84", "size": "250", "side": "SELL", "hash": "7e6b821e2bd310f0640260ce1a21ff36ff0aee0b", "best_bid": "0.46", "best_ask": "0.5"}], "timestamp": "1769384928463", "event_type": "price_change"}}
{"_local_timestamp": "2026-01-25T23:48:48.954495+00:00", "data": {"market": "0xeb44a06c677ce7a47e5fd2007182e020a577395dc3613ad55d3d576e33964c3d", "price_changes": [{"asset_id": "5305471862219565371067835325573032839634510465603099489495163186843068331171", "price": "0.17", "size": "602.94", "side": "BUY", "hash": "be09f1b8038c769a721aa07060b0e0b031f73e32", "best_bid": "0.5", "best_ask": "0.54"}, {"asset_id": "28227838360096074788232992585368970461718254845788738931649369286727917170476", "price": "0.83", "size": "602.94", "side": "SELL", "hash": "d0c3ca785bd63a5a032db44b032a1607b582be5d", "best_bid": "0.46", "best_ask": "0.5"}], "timestamp": "1769384928852", "event_type": "price_change"}}
{"_local_timestamp": "2026-01-25T23:49:09.178694+00:00", "data": {"market": "0xeb44a06c677ce7a47e5fd2007182e020a577395dc3613ad55d3d576e33964c3d", "price_changes": [{"asset_id": "5305471862219565371067835325573032839634510465603099489495163186843068331171", "price": "0.12", "size": "1882", "side": "BUY", "hash": "6e1e7ed3af3ad79a26d9d11bc1dc8212e137c636", "best_bid": "0.5", "best_ask": "0.54"}, {"asset_id": "28227838360096074788232992585368970461718254845788738931649369286727917170476", "price": "0.88", "size": "1882", "side": "SELL", "hash": "35fbacb5a6c378d89849b84e5a61ef17df78f92f", "best_bid": "0.46", "best_ask": "0.5"}], "timestamp": "1769384949102", "event_type": "price_change"}}
{"_local_timestamp": "2026-01-25T23:49:09.498648+00:00", "data": {"market": "0xeb44a06c677ce7a47e5fd2007182e020a577395dc3613ad55d3d576e33964c3d", "price_changes": [{"asset_id": "5305471862219565371067835325573032839634510465603099489495163186843068331171", "price": "0.15", "size": "2848", "side": "BUY", "hash": "fee83a243eef6ba0b1936bfdc4907478b2e50be6", "best_bid": "0.5", "best_ask": "0.54"}, {"asset_id": "28227838360096074788232992585368970461718254845788738931649369286727917170476", "price": "0.85", "size": "2848", "side": "SELL", "hash": "a6795f4490b1f911b4dd9e68ecc5550ec9ce018e", "best_bid": "0.46", "best_ask": "0.5"}], "timestamp": "1769384949416", "event_type": "price_change"}}
{"_local_timestamp": "2026-01-25T23:49:24.483219+00:00", "data": {"market": "0xeb44a06c677ce7a47e5fd2007182e020a577395dc3613ad55d3d576e33964c3d", "price_changes": [{"asset_id": "5305471862219565371067835325573032839634510465603099489495163186843068331171", "price": "0.12", "size": "1657", "side": "BUY", "hash": "9bb5ef17b1721432763d52fe8d4712345d044b4e", "best_bid": "0.5", "best_ask": "0.54"}, {"asset_id": "28227838360096074788232992585368970461718254845788738931649369286727917170476", "price": "0.88", "size": "1657", "side": "SELL", "hash": "e08dfc209557d0c8e4769f2485f2ffb7a5f0ba78", "best_bid": "0.46", "best_ask": "0.5"}], "timestamp": "1769384964409", "event_type": "price_change"}}
{"_local_timestamp": "2026-01-25T23:49:24.758484+00:00", "data": {"market": "0xeb44a06c677ce7a47e5fd2007182e020a577395dc3613ad55d3d576e33964c3d", "price_changes": [{"asset_id": "5305471862219565371067835325573032839634510465603099489495163186843068331171", "price": "0.15", "size": "3073", "side": "BUY", "hash": "8672d33daec171642c29fe5bba9e591e7d22b13c", "best_bid": "0.5", "best_ask": "0.54"}, {"asset_id": "28227838360096074788232992585368970461718254845788738931649369286727917170476", "price": "0.85", "size": "3073", "side": "SELL", "hash": "a3bcbd00e6ce9d81d42d01bd8fe8e8dd0a13d1cf", "best_bid": "0.46", "best_ask": "0.5"}], "timestamp": "1769384964681", "event_type": "price_change"}}
{"_local_timestamp": "2026-01-25T23:49:25.330732+00:00", "data": {"market": "0xca0329cd4392d91e39df0702949229573d2415ae4a37b0103d0c6e9d03b8dd44", "price_changes": [{"asset_id": "20535370510756332462433575263109694145574231213604117747907874615324086102913", "price": "0.21", "size": "55.5", "side": "BUY", "hash": "75ec7c370d6cc5b5eb673cf43f509b9be1a4fe7b", "best_bid": "0.79", "best_ask": "0.82"}, {"asset_id": "74768395815166461619548348007728690058055087254143355558596876906836785272025", "price": "0.79", "size": "55.5", "side": "SELL", "hash": "e9b1ec54d1e9593f4c7d7abbeae5445668592218", "best_bid": "0.18", "best_ask": "0.21"}], "timestamp": "1769384965261", "event_type": "price_change"}}
{"_local_timestamp": "2026-01-25T23:49:25.336648+00:00", "data": {"market": "0xeb44a06c677ce7a47e5fd2007182e020a577395dc3613ad55d3d576e33964c3d", "price_changes": [{"asset_id": "28227838360096074788232992585368970461718254845788738931649369286727917170476", "price": "0.18", "size": "111.11", "side": "BUY", "hash": "db0e35d4d6e5f7140393127b36ad433db9319e4a", "best_bid": "0.46", "best_ask": "0.5"}, {"asset_id": "5305471862219565371067835325573032839634510465603099489495163186843068331171", "price": "0.82", "size": "111.11", "side": "SELL", "hash": "8f8916771c4338012042ef796fac060cddc1cc1a", "best_bid": "0.5", "best_ask": "0.54"}], "timestamp": "1769384965261", "event_type": "price_change"}}
{"_local_timestamp": "2026-01-25T23:49:26.010447+00:00", "data": {"market": "0xca0329cd4392d91e39df0702949229573d2415ae4a37b0103d0c6e9d03b8dd44", "price_changes": [{"asset_id": "20535370510756332462433575263109694145574231213604117747907874615324086102913", "price": "0.24", "size": "1898", "side": "BUY", "hash": "6c3ff7fd27c04736fd09ccdcfa4203470e544ef5", "best_bid": "0.79", "best_ask": "0.82"}, {"asset_id": "74768395815166461619548348007728690058055087254143355558596876906836785272025", "price": "0.76", "size": "1898", "side": "SELL", "hash": "d2cc21bdae37dea03ed3900d5edb4613128c6f7e", "best_bid": "0.18", "best_ask": "0.21"}], "timestamp": "1769384965798", "event_type": "price_change"}}
{"_local_timestamp": "2026-01-25T23:49:26.049919+00:00", "data": {"market": "0xeb44a06c677ce7a47e5fd2007182e020a577395dc3613ad55d3d576e33964c3d", "price_changes": [{"asset_id": "28227838360096074788232992585368970461718254845788738931649369286727917170476", "price": "0.16", "size": "550", "side": "BUY", "hash": "3dca72c9a334472bff85a6be0d82d18d1196f602", "best_bid": "0.46", "best_ask": "0.5"}, {"asset_id": "5305471862219565371067835325573032839634510465603099489495163186843068331171", "price": "0.84", "size": "550", "side": "SELL", "hash": "959121afbd209076c9a3a5642e88278b7e017457", "best_bid": "0.5", "best_ask": "0.54"}], "timestamp": "1769384965804", "event_type": "price_change"}}
{"_local_timestamp": "2026-01-25T23:49:26.268555+00:00", "data": {"market": "0x0bde18e0a0220d1f97173850504a1ed4fa90ef2c6a7bc0932952790053ca0c0e", "price_changes": [{"asset_id": "4041912122563547970024635557261696068618666839090786586996637505354743961673", "price": "0.35", "size": "645", "side": "SELL", "hash": "00cf85842cb4c96cdf0cdfffd1558cda8e4c4d61", "best_bid": "0.31", "best_ask": "0.35"}, {"asset_id": "105325602140854796101190465907542426130401271786879982796716189175875071392057", "price": "0.65", "size": "645", "side": "BUY", "hash": "f7004c6e4477bd9fb48396aeb5e92f8680544c4b", "best_bid": "0.65", "best_ask": "0.69"}], "timestamp": "1769384966132", "event_type": "price_change"}}
{"_local_timestamp": "2026-01-25T23:49:29.320975+00:00", "data": {"market": "0x0bde18e0a0220d1f97173850504a1ed4fa90ef2c6a7bc0932952790053ca0c0e", "price_changes": [{"asset_id": "105325602140854796101190465907542426130401271786879982796716189175875071392057", "price": "0.7", "size": "222.09", "side": "SELL", "hash": "e94271c8c506ade24bd120988052717c43491f01", "best_bid": "0.65", "best_ask": "0.69"}, {"asset_id": "4041912122563547970024635557261696068618666839090786586996637505354743961673", "price": "0.3", "size": "222.09", "side": "BUY", "hash": "03db6d4c25fbf8e3bfcdec82620e74564028ac90", "best_bid": "0.31", "best_ask": "0.35"}], "timestamp": "1769384969252", "event_type": "price_change"}}
{"_local_timestamp": "2026-01-25T23:49:30.442836+00:00", "data": {"market": "0xeb44a06c677ce7a47e5fd2007182e020a577395dc3613ad55d3d576e33964c3d", "price_changes": [{"asset_id": "28227838360096074788232992585368970461718254845788738931649369286727917170476", "price": "0.16", "size": "400", "side": "BUY", "hash": "26eb0f761b1e764373d954e67ea7b0ca1f95d93a", "best_bid": "0.46", "best_ask": "0.5"}, {"asset_id": "5305471862219565371067835325573032839634510465603099489495163186843068331171", "price": "0.84", "size": "400", "side": "SELL", "hash": "d48130f9d23b59a176c896a7ecefdaa07802a1e0", "best_bid": "0.5", "best_ask": "0.54"}], "timestamp": "1769384970084", "event_type": "price_change"}}
{"_local_timestamp": "2026-01-25T23:49:30.494076+00:00", "data": {"market": "0xca0329cd4392d91e39df0702949229573d2415ae4a37b0103d0c6e9d03b8dd44", "price_changes": [{"asset_id": "20535370510756332462433575263109694145574231213604117747907874615324086102913", "price": "0.1", "size": "700", "side": "BUY", "hash": "cedd9f95892ae64f096c22320f3d50cd047f8bcb", "best_bid": "0.79", "best_ask": "0.82"}, {"asset_id": "74768395815166461619548348007728690058055087254143355558596876906836785272025", "price": "0.9", "size": "700", "side": "SELL", "hash": "bbd307b75298a308995e073df959392b3723db91", "best_bid": "0.18", "best_ask": "0.21"}], "timestamp": "1769384970085", "event_type": "price_change"}}
{"_local_timestamp": "2026-01-25T23:49:30.494841+00:00", "data": {"market": "0xca0329cd4392d91e39df0702949229573d2415ae4a37b0103d0c6e9d03b8dd44", "price_changes": [{"asset_id": "20535370510756332462433575263109694145574231213604117747907874615324086102913", "price": "0.23", "size": "0", "side": "BUY", "hash": "cedd9f95892ae64f096c22320f3d50cd047f8bcb", "best_bid": "0.79", "best_ask": "0.82"}, {"asset_id": "74768395815166461619548348007728690058055087254143355558596876906836785272025", "price": "0.77", "size": "0", "side": "SELL", "hash": "bbd307b75298a308995e073df959392b3723db91", "best_bid": "0.18", "best_ask": "0.21"}], "timestamp": "1769384970085", "event_type": "price_change"}}
{"_local_timestamp": "2026-01-25T23:49:30.795319+00:00", "data": {"market": "0x0bde18e0a0220d1f97173850504a1ed4fa90ef2c6a7bc0932952790053ca0c0e", "price_changes": [{"asset_id": "105325602140854796101190465907542426130401271786879982796716189175875071392057", "price": "0.7", "size": "448.5", "side": "SELL", "hash": "4a024866a5af50f4ae42971192c1d6ece93839c8", "best_bid": "0.65", "best_ask": "0.69"}, {"asset_id": "4041912122563547970024635557261696068618666839090786586996637505354743961673", "price": "0.3", "size": "448.5", "side": "BUY", "hash": "7cd0e33339bf5a126120a6f923570e86a911e868", "best_bid": "0.31", "best_ask": "0.35"}], "timestamp": "1769384970522", "event_type": "price_change"}}
{"_local_timestamp": "2026-01-25T23:49:31.194201+00:00", "data": {"market": "0xeb44a06c677ce7a47e5fd2007182e020a577395dc3613ad55d3d576e33964c3d", "price_changes": [{"asset_id": "28227838360096074788232992585368970461718254845788738931649369286727917170476", "price": "0.18", "size": "261.11", "side": "BUY", "hash": "7ec7a5cffba7e5f14c7ea69a7190186b097bcb8f", "best_bid": "0.46", "best_ask": "0.5"}, {"asset_id": "5305471862219565371067835325573032839634510465603099489495163186843068331171", "price": "0.82", "size": "261.11", "side": "SELL", "hash": "2b84d319b1594c12c5767a27c634324ab7c28249", "best_bid": "0.5", "best_ask": "0.54"}], "timestamp": "1769384970826", "event_type": "price_change"}}
{"_local_timestamp": "2026-01-25T23:49:31.197969+00:00", "data": {"market": "0xca0329cd4392d91e39df0702949229573d2415ae4a37b0103d0c6e9d03b8dd44", "price_changes": [{"asset_id": "20535370510756332462433575263109694145574231213604117747907874615324086102913", "price": "0.24", "size": "1998", "side": "BUY", "hash": "6da193cda598e930c04b26b39cfdbaf5c5ec2c1e", "best_bid": "0.79", "best_ask": "0.82"}, {"asset_id": "74768395815166461619548348007728690058055087254143355558596876906836785272025", "price": "0.76", "size": "1998", "side": "SELL", "hash": "2a5d35f827f48ae873dd012920cdeb1192fea913", "best_bid": "0.18", "best_ask": "0.21"}], "timestamp": "1769384970827", "event_type": "price_change"}}
{"_local_timestamp": "2026-01-25T23:49:31.199099+00:00", "data": {"market": "0xca0329cd4392d91e39df0702949229573d2415ae4a37b0103d0c6e9d03b8dd44", "price_changes": [{"asset_id": "20535370510756332462433575263109694145574231213604117747907874615324086102913", "price": "0.08", "size": "1300", "side": "BUY", "hash": "38959a7939f88be70788dab5ee75460fa4534d79", "best_bid": "0.79", "best_ask": "0.82"}, {"asset_id": "74768395815166461619548348007728690058055087254143355558596876906836785272025", "price": "0.92", "size": "1300", "side": "SELL", "hash": "c35ab7f01095f81f0dafcbe32898014c4724d6b9", "best_bid": "0.18", "best_ask": "0.21"}], "timestamp": "1769384970830", "event_type": "price_change"}}
{"_local_timestamp": "2026-01-25T23:49:41.936290+00:00", "data": {"market": "0xca0329cd4392d91e39df0702949229573d2415ae4a37b0103d0c6e9d03b8dd44", "price_changes": [{"asset_id": "20535370510756332462433575263109694145574231213604117747907874615324086102913", "price": "0.1", "size": "500", "side": "BUY", "hash": "b422107c09bc98f0b0460c3ace693f9113871d9a", "best_bid": "0.79", "best_ask": "0.82"}, {"asset_id": "74768395815166461619548348007728690058055087254143355558596876906836785272025", "price": "0.9", "size": "500", "side": "SELL", "hash": "21bc75fc2769f958ed72bad0db2c665eff6c26f2", "best_bid": "0.18", "best_ask": "0.21"}], "timestamp": "1769384981756", "event_type": "price_change"}}
{"_local_timestamp": "2026-01-25T23:49:42.044508+00:00", "data": {"market": "0xca0329cd4392d91e39df0702949229573d2415ae4a37b0103d0c6e9d03b8dd44", "price_changes": [{"asset_id": "20535370510756332462433575263109694145574231213604117747907874615324086102913", "price": "0.21", "size": "5.5", "side": "BUY", "hash": "ac32d64da3d92d4f16faf9a5faba3cbedfb06a4c", "best_bid": "0.79", "best_ask": "0.82"}, {"asset_id": "74768395815166461619548348007728690058055087254143355558596876906836785272025", "price": "0.79", "size": "5.5", "side": "SELL", "hash": "72b2ecbe1c8dd7b1ff655aeaa14655d538c2511d", "best_bid": "0.18", "best_ask": "0.21"}], "timestamp": "1769384981877", "event_type": "price_change"}}
{"_local_timestamp": "2026-01-25T23:49:42.206552+00:00", "data": {"market": "0xca0329cd4392d91e39df0702949229573d2415ae4a37b0103d0c6e9d03b8dd44", "price_changes": [{"asset_id": "20535370510756332462433575263109694145574231213604117747907874615324086102913", "price": "0.08", "size": "1500", "side": "BUY", "hash": "0604f462a47a9455396b5e9343e4cf04092ba195", "best_bid": "0.79", "best_ask": "0.82"}, {"asset_id": "74768395815166461619548348007728690058055087254143355558596876906836785272025", "price": "0.92", "size": "1500", "side": "SELL", "hash": "15b4d95bc4e6124521640e36d4de3f3a02b717c5", "best_bid": "0.18", "best_ask": "0.21"}], "timestamp": "1769384982091", "event_type": "price_change"}}
{"_local_timestamp": "2026-01-25T23:49:42.375875+00:00", "data": {"market": "0xca0329cd4392d91e39df0702949229573d2415ae4a37b0103d0c6e9d03b8dd44", "price_changes": [{"asset_id": "20535370510756332462433575263109694145574231213604117747907874615324086102913", "price": "0.24", "size": "2048", "side": "BUY", "hash": "5ec6aaa263cc5ec37150bf083437755ed3c59336", "best_bid": "0.79", "best_ask": "0.82"}, {"asset_id": "74768395815166461619548348007728690058055087254143355558596876906836785272025", "price": "0.76", "size": "2048", "side": "SELL", "hash": "b6e5c013edfbb397cc3d9c5a31e9331e16665372", "best_bid": "0.18", "best_ask": "0.21"}], "timestamp": "1769384982215", "event_type": "price_change"}}
{"_local_timestamp": "2026-01-25T23:49:45.088700+00:00", "data": {"market": "0x0bde18e0a0220d1f97173850504a1ed4fa90ef2c6a7bc0932952790053ca0c0e", "price_changes": [{"asset_id": "4041912122563547970024635557261696068618666839090786586996637505354743961673", "price": "0.35", "size": "619", "side": "SELL", "hash": "5ede77f6cbcf547133f93fe8e678bb27e9210014", "best_bid": "0.31", "best_ask": "0.35"}, {"asset_id": "105325602140854796101190465907542426130401271786879982796716189175875071392057", "price": "0.65", "size": "619", "side": "BUY", "hash": "fa5b29800bb658cc4c48e9566b09b1d830c73c9c", "best_bid": "0.65", "best_ask": "0.69"}], "timestamp": "1769384985001", "event_type": "price_change"}}
{"_local_timestamp": "2026-01-25T23:49:48.358345+00:00", "data": {"market": "0xeb44a06c677ce7a47e5fd2007182e020a577395dc3613ad55d3d576e33964c3d", "price_changes": [{"asset_id": "28227838360096074788232992585368970461718254845788738931649369286727917170476", "price": "0.02", "size": "2200", "side": "BUY", "hash": "0ca7ec0d845893ebf8df9ee93f02ec5fddb5bbea", "best_bid": "0.46", "best_ask": "0.5"}, {"asset_id": "5305471862219565371067835325573032839634510465603099489495163186843068331171", "price": "0.98", "size": "2200", "side": "SELL", "hash": "577764d4e4b4aa7a83cc5f82cb8b689e180d20af", "best_bid": "0.5", "best_ask": "0.54"}], "timestamp": "1769384988288", "event_type": "price_change"}}
{"_local_timestamp": "2026-01-25T23:49:48.513761+00:00", "data": {"market": "0xeb44a06c677ce7a47e5fd2007182e020a577395dc3613ad55d3d576e33964c3d", "price_changes": [{"asset_id": "28227838360096074788232992585368970461718254845788738931649369286727917170476", "price": "0.02", "size": "5241", "side": "BUY", "hash": "9d0cf60c6d68969ae4b3be106cdf9ac0cfad0c16", "best_bid": "0.46", "best_ask": "0.5"}, {"asset_id": "5305471862219565371067835325573032839634510465603099489495163186843068331171", "price": "0.98", "size": "5241", "side": "SELL", "hash": "2eb5dc47d8f89ca9a119208e90b02ad98e9a8334", "best_bid": "0.5", "best_ask": "0.54"}], "timestamp": "1769384988449", "event_type": "price_change"}}
{"_local_timestamp": "2026-01-25T23:49:48.723667+00:00", "data": {"market": "0xeb44a06c677ce7a47e5fd2007182e020a577395dc3613ad55d3d576e33964c3d", "price_changes": [{"asset_id": "5305471862219565371067835325573032839634510465603099489495163186843068331171", "price": "0.23", "size": "208", "side": "BUY", "hash": "49bd63178e5ccbe347c516053652005e63de11af", "best_bid": "0.5", "best_ask": "0.54"}, {"asset_id": "28227838360096074788232992585368970461718254845788738931649369286727917170476", "price": "0.77", "size": "208", "side": "SELL", "hash": "57cdcdd536c9aad8a06a6b14fa9792178541d608", "best_bid": "0.46", "best_ask": "0.5"}], "timestamp": "1769384988653", "event_type": "price_change"}}
{"_local_timestamp": "2026-01-25T23:49:48.893894+00:00", "data": {"market": "0xeb44a06c677ce7a47e5fd2007182e020a577395dc3613ad55d3d576e33964c3d", "price_changes": [{"asset_id": "5305471862219565371067835325573032839634510465603099489495163186843068331171", "price": "0.24", "size": "3187", "side": "BUY", "hash": "583616a9c7525011d4b5f396c16e47091dfcbe0f", "best_bid": "0.5", "best_ask": "0.54"}, {"asset_id": "28227838360096074788232992585368970461718254845788738931649369286727917170476", "price": "0.76", "size": "3187", "side": "SELL", "hash": "652cddbd23c4fab540e070b6a4193f3692acda1e", "best_bid": "0.46", "best_ask": "0.5"}], "timestamp": "1769384988828", "event_type": "price_change"}}
{"_local_timestamp": "2026-01-25T23:49:49.122614+00:00", "data": {"market": "0x0bde18e0a0220d1f97173850504a1ed4fa90ef2c6a7bc0932952790053ca0c0e", "price_changes": [{"asset_id": "105325602140854796101190465907542426130401271786879982796716189175875071392057", "price": "0.29", "size": "318.96", "side": "BUY", "hash": "b0ad255e0a1c68f151476bd48091e1216f60d515", "best_bid": "0.65", "best_ask": "0.69"}, {"asset_id": "4041912122563547970024635557261696068618666839090786586996637505354743961673", "price": "0.71", "size": "318.96", "side": "SELL", "hash": "dfe4ecbd0fd1d72f15c9834094774e33837a9296", "best_bid": "0.31", "best_ask": "0.35"}], "timestamp": "1769384989019", "event_type": "price_change"}}
{"_local_timestamp": "2026-01-25T23:49:49.262001+00:00", "data": {"market": "0x0bde18e0a0220d1f97173850504a1ed4fa90ef2c6a7bc0932952790053ca0c0e", "price_changes": [{"asset_id": "105325602140854796101190465907542426130401271786879982796716189175875071392057", "price": "0.3", "size": "3333", "side": "BUY", "hash": "ce1720bc73f1c77964ea8bab6b234ac6ab3f4f84", "best_bid": "0.65", "best_ask": "0.69"}, {"asset_id": "4041912122563547970024635557261696068618666839090786586996637505354743961673", "price": "0.7", "size": "3333", "side": "SELL", "hash": "754470fbe5bb6d6f573cede7d951467fc7efacea", "best_bid": "0.31", "best_ask": "0.35"}], "timestamp": "1769384989191", "event_type": "price_change"}}
{"_local_timestamp": "2026-01-25T23:49:49.428605+00:00", "data": {"market": "0xeb44a06c677ce7a47e5fd2007182e020a577395dc3613ad55d3d576e33964c3d", "price_changes": [{"asset_id": "5305471862219565371067835325573032839634510465603099489495163186843068331171", "price": "0.24", "size": "3167", "side": "BUY", "hash": "2dafb10aecf64ffcdbc1945aa8a3ae8b89b77248", "best_bid": "0.5", "best_ask": "0.54"}, {"asset_id": "28227838360096074788232992585368970461718254845788738931649369286727917170476", "price": "0.76", "size": "3167", "side": "SELL", "hash": "53cdaf966989259c8fdaa056f48a774c08e5cf3a", "best_bid": "0.46", "best_ask": "0.5"}], "timestamp": "1769384989359", "event_type": "price_change"}}
{"_local_timestamp": "2026-01-25T23:49:49.456016+00:00", "data": {"market": "0xeb44a06c677ce7a47e5fd2007182e020a577395dc3613ad55d3d576e33964c3d", "price_changes": [{"asset_id": "5305471862219565371067835325573032839634510465603099489495163186843068331171", "price": "0.25", "size": "20", "side": "BUY", "hash": "b96a7591db42d75256cdc2dd34d77448ab647d0b", "best_bid": "0.5", "best_ask": "0.54"}, {"asset_id": "28227838360096074788232992585368970461718254845788738931649369286727917170476", "price": "0.75", "size": "20", "side": "SELL", "hash": "b1a095c7e830d2be4a9e13662f533fbddc23aaa6", "best_bid": "0.46", "best_ask": "0.5"}], "timestamp": "1769384989383", "event_type": "price_change"}}
{"_local_timestamp": "2026-01-25T23:49:49.582152+00:00", "data": {"market": "0xca0329cd4392d91e39df0702949229573d2415ae4a37b0103d0c6e9d03b8dd44", "price_changes": [{"asset_id": "20535370510756332462433575263109694145574231213604117747907874615324086102913", "price": "0.36", "size": "50", "side": "BUY", "hash": "a363fa3d461b29ff172391d1b5d632e41ff55263", "best_bid": "0.79", "best_ask": "0.82"}, {"asset_id": "74768395815166461619548348007728690058055087254143355558596876906836785272025", "price": "0.64", "size": "50", "side": "SELL", "hash": "e6a904f2f139dba64d94269b6b784f95ec3826ec", "best_bid": "0.18", "best_ask": "0.21"}], "timestamp": "1769384989518", "event_type": "price_change"}}
{"_local_timestamp": "2026-01-25T23:49:49.749528+00:00", "data": {"market": "0xca0329cd4392d91e39df0702949229573d2415ae4a37b0103d0c6e9d03b8dd44", "price_changes": [{"asset_id": "20535370510756332462433575263109694145574231213604117747907874615324086102913", "price": "0.25", "size": "4472", "side": "BUY", "hash": "19ff642f10e3192fd68eec69b982f38fbb9150c6", "best_bid": "0.79", "best_ask": "0.82"}, {"asset_id": "74768395815166461619548348007728690058055087254143355558596876906836785272025", "price": "0.75", "size": "4472", "side": "SELL", "hash": "726e488d3b5d60acf1499ee96d0d31cef6fa6f1f", "best_bid": "0.18", "best_ask": "0.21"}], "timestamp": "1769384989683", "event_type": "price_change"}}
{"_local_timestamp": "2026-01-25T23:49:49.950455+00:00", "data": {"market": "0xa05f081e032395b4527d964fcefb032834c81bef0e85ac533c81f66139c35af4", "price_changes": [{"asset_id": "56813972039885211974321877112282829005950793706240260412507113757740359845360", "price": "0.411", "size": "0", "side": "BUY", "hash": "cd38f473e3c58435256168fc3b3cab72f2a62653", "best_bid": "0.997", "best_ask": "0.999"}, {"asset_id": "69074333464069151404242315526218405459784935747253869832659873168984248759799", "price": "0.589", "size": "0", "side": "SELL", "hash": "94298f3f005f263d5e10acf3d3b19181210b9589", "best_bid": "0.001", "best_ask": "0.003"}], "timestamp": "1769384989873", "event_type": "price_change"}}
{"_local_timestamp": "2026-01-25T23:49:50.209788+00:00", "data": {"market": "0xa05f081e032395b4527d964fcefb032834c81bef0e85ac533c81f66139c35af4", "price_changes": [{"asset_id": "56813972039885211974321877112282829005950793706240260412507113757740359845360", "price": "0.413", "size": "5785", "side": "BUY", "hash": "5f474c8690155a3e616a031764f0544fe9308a30", "best_bid": "0.997", "best_ask": "0.999"}, {"asset_id": "69074333464069151404242315526218405459784935747253869832659873168984248759799", "price": "0.587", "size": "5785", "side": "SELL", "hash": "fa2b67ab5ca6bebcba26e727b8b05030332923ff", "best_bid": "0.001", "best_ask": "0.003"}], "timestamp": "1769384990030", "event_type": "price_change"}}
{"_local_timestamp": "2026-01-25T23:49:50.401311+00:00", "data": {"market": "0x1586e33dc57b17433d080829870d73631a146b24d44d73817634c9f7171f84c3", "price_changes": [{"asset_id": "97767433523834028432607127801550560819898564541831537765726721529534335838453", "price": "0.251", "size": "200", "side": "BUY", "hash": "3c91286bf5bb3bfa3b7e1ff8adfeb8abaddfbf47", "best_bid": "0.997", "best_ask": "0.999"}, {"asset_id": "45761844533847615095657975499649554423516098382359546239787965241599216489110", "price": "0.749", "size": "200", "side": "SELL", "hash": "06a762168900e3b9074d50ece0f4dfb2bcf2d490", "best_bid": "0.001", "best_ask": "0.003"}], "timestamp": "1769384990226", "event_type": "price_change"}}
{"_local_timestamp": "2026-01-25T23:49:50.474599+00:00", "data": {"market": "0x1586e33dc57b17433d080829870d73631a146b24d44d73817634c9f7171f84c3", "price_changes": [{"asset_id": "97767433523834028432607127801550560819898564541831537765726721529534335838453", "price": "0.301", "size": "3733", "side": "BUY", "hash": "6dcf97037fadea7baa7242db6768f59ba34c3344", "best_bid": "0.997", "best_ask": "0.999"}, {"asset_id": "45761844533847615095657975499649554423516098382359546239787965241599216489110", "price": "0.699", "size": "3733", "side": "SELL", "hash": "dc940739dd9858afb9701d4331e6642536d8eee0", "best_bid": "0.001", "best_ask": "0.003"}], "timestamp": "1769384990390", "event_type": "price_change"}}
{"_local_timestamp": "2026-01-25T23:49:50.654462+00:00", "data": {"market": "0xc1c30becf85027a3fad693fe00aed610c574220f32fabef52c1ac53f76153622", "price_changes": [{"asset_id": "86861447014827130074018921138137988822291708295577507404133014397402508069192", "price": "0.752", "size": "0", "side": "BUY", "hash": "c4e721b925d693af99ad90009ce21af3cf1dfd59", "best_bid": "0.997", "best_ask": "0.999"}, {"asset_id": "44162996630579613944619329601086604585114580039271806622718850166081603488312", "price": "0.248", "size": "0", "side": "SELL", "hash": "f1f3b016209892c93e2aecacfbd644088eaf2f7c", "best_bid": "0.001", "best_ask": "0.003"}], "timestamp": "1769384990585", "event_type": "price_change"}}
{"_local_timestamp": "2026-01-25T23:49:50.856271+00:00", "data": {"market": "0xc1c30becf85027a3fad693fe00aed610c574220f32fabef52c1ac53f76153622", "price_changes": [{"asset_id": "86861447014827130074018921138137988822291708295577507404133014397402508069192", "price": "0.401", "size": "5928", "side": "BUY", "hash": "8136e8656870b8933daab7f18caf8d10b8cbc3a3", "best_bid": "0.997", "best_ask": "0.999"}, {"asset_id": "44162996630579613944619329601086604585114580039271806622718850166081603488312", "price": "0.599", "size": "5928", "side": "SELL", "hash": "020e6fd62c986534bbd4564c2914e0837d068813", "best_bid": "0.001", "best_ask": "0.003"}], "timestamp": "1769384990762", "event_type": "price_change"}}
{"_local_timestamp": "2026-01-25T23:49:51.021969+00:00", "data": {"market": "0xc5452a97769a9aa7a264d11bf07c7da6ff6080061d426cd7ef92abb47f6d8160", "price_changes": [{"asset_id": "114340618694795548048032631237414556707214948596108879651552052673573136118536", "price": "0.437", "size": "0", "side": "BUY", "hash": "23e696def4f75457a53f26526068a7675e1aec1a", "best_bid": "0.997", "best_ask": "0.998"}, {"asset_id": "8922710639437477954990654098858414058444921382508505451184351067105680225969", "price": "0.563", "size": "0", "side": "SELL", "hash": "6c377df18dd125f24528286f4d61b32c487977ba", "best_bid": "0.002", "best_ask": "0.003"}], "timestamp": "1769384990953", "event_type": "price_change"}}
{"_local_timestamp": "2026-01-25T23:49:51.144051+00:00", "data": {"market": "0xeb44a06c677ce7a47e5fd2007182e020a577395dc3613ad55d3d576e33964c3d", "price_changes": [{"asset_id": "5305471862219565371067835325573032839634510465603099489495163186843068331171", "price": "0.15", "size": "275", "side": "BUY", "hash": "72e29a9d9e2d5f614e3ebdb184d23cf87a5a8d50", "best_bid": "0.5", "best_ask": "0.54"}, {"asset_id": "28227838360096074788232992585368970461718254845788738931649369286727917170476", "price": "0.85", "size": "275", "side": "SELL", "hash": "9571fcb0292b28c63c28cc3f70059a9dee736c0e", "best_bid": "0.46", "best_ask": "0.5"}], "timestamp": "1769384991039", "event_type": "price_change"}}
{"_local_timestamp": "2026-01-25T23:49:51.211819+00:00", "data": {"market": "0xca0329cd4392d91e39df0702949229573d2415ae4a37b0103d0c6e9d03b8dd44", "price_changes": [{"asset_id": "20535370510756332462433575263109694145574231213604117747907874615324086102913", "price": "0.24", "size": "300", "side": "BUY", "hash": "2ae9df71273cb8aff9a86f18d738d8a322fe8732", "best_bid": "0.79", "best_ask": "0.82"}, {"asset_id": "74768395815166461619548348007728690058055087254143355558596876906836785272025", "price": "0.76", "size": "300", "side": "SELL", "hash": "6f966a99a4d1ea760d245a7215b0d02d3f4b2743", "best_bid": "0.18", "best_ask": "0.21"}], "timestamp": "1769384991043", "event_type": "price_change"}}
{"_local_timestamp": "2026-01-25T23:49:51.344843+00:00", "data": {"market": "0xc5452a97769a9aa7a264d11bf07c7da6ff6080061d426cd7ef92abb47f6d8160", "price_changes": [{"asset_id": "114340618694795548048032631237414556707214948596108879651552052673573136118536", "price": "0.439", "size": "5447", "side": "BUY", "hash": "22c75b8d6da321215fc4c28647983d7a182abcae", "best_bid": "0.997", "best_ask": "0.998"}, {"asset_id": "8922710639437477954990654098858414058444921382508505451184351067105680225969", "price": "0.561", "size": "5447", "side": "SELL", "hash": "743d9d8b155e602a5838185563d7e19356075550", "best_bid": "0.002", "best_ask": "0.003"}], "timestamp": "1769384991121", "event_type": "price_change"}}
{"_local_timestamp": "2026-01-25T23:49:51.513639+00:00", "data": {"market": "0x49d0b554fffebaabd8f70e7088c51ee132b36b51979687c5775fe1d39e6009df", "price_changes": [{"asset_id": "101417798695348023730451223679149302603865990290677002526337951186193092407966", "price": "0.661", "size": "0", "side": "BUY", "hash": "85f3447a360739a00ce8ca1dc1c3eeb3a8389b0f", "best_bid": "0.997", "best_ask": "0.999"}, {"asset_id": "19835581196144925594226241068229934006876264875869838825630024545913250806260", "price": "0.339", "size": "0", "side": "SELL", "hash": "61cc6d740291a651f83b70ea1594ffd4bbe3d189", "best_bid": "0.001", "best_ask": "0.003"}], "timestamp": "1769384991432", "event_type": "price_change"}}
{"_local_timestamp": "2026-01-25T23:49:51.673646+00:00", "data": {"market": "0x49d0b554fffebaabd8f70e7088c51ee132b36b51979687c5775fe1d39e6009df", "price_changes": [{"asset_id": "101417798695348023730451223679149302603865990290677002526337951186193092407966", "price": "0.661", "size": "3631", "side": "BUY", "hash": "afcf1ac9a4922b4908c89203b2acdab5e66fef82", "best_bid": "0.997", "best_ask": "0.999"}, {"asset_id": "19835581196144925594226241068229934006876264875869838825630024545913250806260", "price": "0.339", "size": "3631", "side": "SELL", "hash": "a41ba8888cbfd6c044d6a7316d75e6df35cde6e5", "best_bid": "0.001", "best_ask": "0.003"}], "timestamp": "1769384991598", "event_type": "price_change"}}
{"_local_timestamp": "2026-01-25T23:49:51.887360+00:00", "data": {"market": "0x91f7e7f2d3727a5abca7eb77827355f9a968f6636606c3f47f35ce2c23c91cbc", "price_changes": [{"asset_id": "84252679223362616378739922435722781121510894501012248080679822792405868493637", "price": "0.327", "size": "100", "side": "BUY", "hash": "15d74269317d429b63014b2213edaf307d38ef14", "best_bid": "0.997", "best_ask": "0.998"}, {"asset_id": "43986832901480115975770598885448914644973339441868156495326187103850202425816", "price": "0.673", "size": "100", "side": "SELL", "hash": "84ead7bb4822e1456fda2f50b0065439a3a27f37", "best_bid": "0.002", "best_ask": "0.003"}], "timestamp": "1769384991814", "event_type": "price_change"}}
{"_local_timestamp": "2026-01-25T23:49:52.048476+00:00", "data": {"market": "0x91f7e7f2d3727a5abca7eb77827355f9a968f6636606c3f47f35ce2c23c91cbc", "price_changes": [{"asset_id": "84252679223362616378739922435722781121510894501012248080679822792405868493637", "price": "0.329", "size": "3405", "side": "BUY", "hash": "4e83b7543d0d86ba1019fae39b1f4b69b19e01f4", "best_bid": "0.997", "best_ask": "0.998"}, {"asset_id": "43986832901480115975770598885448914644973339441868156495326187103850202425816", "price": "0.671", "size": "3405", "side": "SELL", "hash": "31944e43f2801d004977e26458ba91f02045b50d", "best_bid": "0.002", "best_ask": "0.003"}], "timestamp": "1769384991980", "event_type": "price_change"}}
{"_local_timestamp": "2026-01-25T23:50:02.405977+00:00", "data": {"market": "0xeb44a06c677ce7a47e5fd2007182e020a577395dc3613ad55d3d576e33964c3d", "price_changes": [{"asset_id": "5305471862219565371067835325573032839634510465603099489495163186843068331171", "price": "0.12", "size": "325", "side": "BUY", "hash": "007d50b62c6e45bd9b54a3ff31b01dd1fdf3bcb7", "best_bid": "0.5", "best_ask": "0.54"}, {"asset_id": "28227838360096074788232992585368970461718254845788738931649369286727917170476", "price": "0.88", "size": "325", "side": "SELL", "hash": "0e97f7185f949d50d4cd20cda5692e61ea55207d", "best_bid": "0.46", "best_ask": "0.5"}], "timestamp": "1769385002272", "event_type": "price_change"}}
{"_local_timestamp": "2026-01-25T23:50:02.430289+00:00", "data": {"market": "0x0bde18e0a0220d1f97173850504a1ed4fa90ef2c6a7bc0932952790053ca0c0e", "price_changes": [{"asset_id": "105325602140854796101190465907542426130401271786879982796716189175875071392057", "price": "0.16", "size": "0", "side": "BUY", "hash": "a636ecb73081fd89ac0b94bec5537486f04babed", "best_bid": "0.65", "best_ask": "0.69"}, {"asset_id": "4041912122563547970024635557261696068618666839090786586996637505354743961673", "price": "0.84", "size": "0", "side": "SELL", "hash": "ffcacc1809af7f616c2e092c89f44246896757f9", "best_bid": "0.31", "best_ask": "0.35"}], "timestamp": "1769385002275", "event_type": "price_change"}}
{"_local_timestamp": "2026-01-25T23:50:02.455520+00:00", "data": {"market": "0xeb44a06c677ce7a47e5fd2007182e020a577395dc3613ad55d3d576e33964c3d", "price_changes": [{"asset_id": "28227838360096074788232992585368970461718254845788738931649369286727917170476", "price": "0.1", "size": "500", "side": "BUY", "hash": "abc1ea6127d99b01515418c27fdf9c478eba794b", "best_bid": "0.46", "best_ask": "0.5"}, {"asset_id": "5305471862219565371067835325573032839634510465603099489495163186843068331171", "price": "0.9", "size": "500", "side": "SELL", "hash": "6b093f9e8d1beaf659c867b1f4b3dc29da41230d", "best_bid": "0.5", "best_ask": "0.54"}], "timestamp": "1769385002276", "event_type": "price_change"}}
{"_local_timestamp": "2026-01-25T23:50:02.746061+00:00", "data": {"market": "0xca0329cd4392d91e39df0702949229573d2415ae4a37b0103d0c6e9d03b8dd44", "price_changes": [{"asset_id": "20535370510756332462433575263109694145574231213604117747907874615324086102913", "price": "0.2", "size": "450", "side": "BUY", "hash": "101a0c4f9ec876801823927d4cc5a28da8be6634", "best_bid": "0.79", "best_ask": "0.82"}, {"asset_id": "74768395815166461619548348007728690058055087254143355558596876906836785272025", "price": "0.8", "size": "450", "side": "SELL", "hash": "18875efe1d9bf82f969f3f56c3699b2d50692a63", "best_bid": "0.18", "best_ask": "0.21"}], "timestamp": "1769385002291", "event_type": "price_change"}}
{"_local_timestamp": "2026-01-25T23:50:03.193943+00:00", "data": {"market": "0xeb44a06c677ce7a47e5fd2007182e020a577395dc3613ad55d3d576e33964c3d", "price_changes": [{"asset_id": "5305471862219565371067835325573032839634510465603099489495163186843068331171", "price": "0.09", "size": "800", "side": "BUY", "hash": "365bcc0056c27a4cdf14afd48af7d8f311599401", "best_bid": "0.5", "best_ask": "0.54"}, {"asset_id": "28227838360096074788232992585368970461718254845788738931649369286727917170476", "price": "0.91", "size": "800", "side": "SELL", "hash": "1bcf3af697fc0fcfbc6961bf6a8f262d695fc5ae", "best_bid": "0.46", "best_ask": "0.5"}], "timestamp": "1769385002726", "event_type": "price_change"}}
{"_local_timestamp": "2026-01-25T23:50:07.439604+00:00", "data": {"market": "0xeb44a06c677ce7a47e5fd2007182e020a577395dc3613ad55d3d576e33964c3d", "price_changes": [{"asset_id": "5305471862219565371067835325573032839634510465603099489495163186843068331171", "price": "0.16", "size": "2874", "side": "BUY", "hash": "aa1cdf55a002e1027b5093979b36b426cd9bdbb0", "best_bid": "0.5", "best_ask": "0.54"}, {"asset_id": "28227838360096074788232992585368970461718254845788738931649369286727917170476", "price": "0.84", "size": "2874", "side": "SELL", "hash": "fc52379f9b5ad441739fa9959130c8cce1acb1ed", "best_bid": "0.46", "best_ask": "0.5"}], "timestamp": "1769385007370", "event_type": "price_change"}}
{"_local_timestamp": "2026-01-25T23:50:31.083426+00:00", "data": {"market": "0xca0329cd4392d91e39df0702949229573d2415ae4a37b0103d0c6e9d03b8dd44", "price_changes": [{"asset_id": "20535370510756332462433575263109694145574231213604117747907874615324086102913", "price": "0.25", "size": "6152", "side": "BUY", "hash": "664073f43fed20cff30a65f4bbfd1cb030ac7cda", "best_bid": "0.79", "best_ask": "0.82"}, {"asset_id": "74768395815166461619548348007728690058055087254143355558596876906836785272025", "price": "0.75", "size": "6152", "side": "SELL", "hash": "c6d9aa25c953c66bf334977ad37b592ed71e5937", "best_bid": "0.18", "best_ask": "0.21"}], "timestamp": "1769385030903", "event_type": "price_change"}}
{"_local_timestamp": "2026-01-25T23:50:38.398893+00:00", "data": {"market": "0xeb44a06c677ce7a47e5fd2007182e020a577395dc3613ad55d3d576e33964c3d", "price_changes": [{"asset_id": "5305471862219565371067835325573032839634510465603099489495163186843068331171", "price": "0.15", "size": "225", "side": "BUY", "hash": "0417399271d5519fe084b40d61313cf0ce02f7f3", "best_bid": "0.5", "best_ask": "0.54"}, {"asset_id": "28227838360096074788232992585368970461718254845788738931649369286727917170476", "price": "0.85", "size": "225", "side": "SELL", "hash": "38087f4d004aebb6ad4ae4a7693b75bd7ecde4de", "best_bid": "0.46", "best_ask": "0.5"}], "timestamp": "1769385038180", "event_type": "price_change"}}
{"_local_timestamp": "2026-01-25T23:50:38.664082+00:00", "data": {"market": "0xeb44a06c677ce7a47e5fd2007182e020a577395dc3613ad55d3d576e33964c3d", "price_changes": [{"asset_id": "5305471862219565371067835325573032839634510465603099489495163186843068331171", "price": "0.12", "size": "375", "side": "BUY", "hash": "b4ea9b83150941ec7a340c1916ca5e35a6dd7f73", "best_bid": "0.5", "best_ask": "0.54"}, {"asset_id": "28227838360096074788232992585368970461718254845788738931649369286727917170476", "price": "0.88", "size": "375", "side": "SELL", "hash": "3749bfefcbd21bb98d56e4558305fd820b57187a", "best_bid": "0.46", "best_ask": "0.5"}], "timestamp": "1769385038464", "event_type": "price_change"}}
{"_local_timestamp": "2026-01-25T23:50:41.723260+00:00", "data": {"market": "0xca0329cd4392d91e39df0702949229573d2415ae4a37b0103d0c6e9d03b8dd44", "price_changes": [{"asset_id": "20535370510756332462433575263109694145574231213604117747907874615324086102913", "price": "0.08", "size": "800", "side": "BUY", "hash": "405a67c1eac0f11d99fe6b49bc8ba149e9e6a80f", "best_bid": "0.79", "best_ask": "0.82"}, {"asset_id": "74768395815166461619548348007728690058055087254143355558596876906836785272025", "price": "0.92", "size": "800", "side": "SELL", "hash": "cd9ad95fe72e710e2ae4d23f1ebcc6b4e3aa5f37", "best_bid": "0.18", "best_ask": "0.21"}], "timestamp": "1769385041530", "event_type": "price_change"}}
{"_local_timestamp": "2026-01-25T23:50:46.326468+00:00", "data": {"market": "0xca0329cd4392d91e39df0702949229573d2415ae4a37b0103d0c6e9d03b8dd44", "price_changes": [{"asset_id": "20535370510756332462433575263109694145574231213604117747907874615324086102913", "price": "0.24", "size": "200", "side": "BUY", "hash": "c8aaf0a3422a39e89ed44e390d6fd04a49a486d9", "best_bid": "0.79", "best_ask": "0.82"}, {"asset_id": "74768395815166461619548348007728690058055087254143355558596876906836785272025", "price": "0.76", "size": "200", "side": "SELL", "hash": "a0068c17bb36a5b3cb834be90a29764882784ef6", "best_bid": "0.18", "best_ask": "0.21"}], "timestamp": "1769385046259", "event_type": "price_change"}}
{"_local_timestamp": "2026-01-25T23:50:46.335914+00:00", "data": {"market": "0xeb44a06c677ce7a47e5fd2007182e020a577395dc3613ad55d3d576e33964c3d", "price_changes": [{"asset_id": "28227838360096074788232992585368970461718254845788738931649369286727917170476", "price": "0.16", "size": "250", "side": "BUY", "hash": "8a2de8cc2537a26e016abe967d8fb5fbfca1a804", "best_bid": "0.46", "best_ask": "0.5"}, {"asset_id": "5305471862219565371067835325573032839634510465603099489495163186843068331171", "price": "0.84", "size": "250", "side": "SELL", "hash": "6d388f84125ac705525b9b6028edae0f246a049e", "best_bid": "0.5", "best_ask": "0.54"}], "timestamp": "1769385046259", "event_type": "price_change"}}
{"_local_timestamp": "2026-01-25T23:50:46.336693+00:00", "data": {"market": "0x0bde18e0a0220d1f97173850504a1ed4fa90ef2c6a7bc0932952790053ca0c0e", "price_changes": [{"asset_id": "105325602140854796101190465907542426130401271786879982796716189175875071392057", "price": "0.29", "size": "268.96", "side": "BUY", "hash": "2d4ef5e7d5daf7870ff5b010cb7b4c59a9a4f5b0", "best_bid": "0.65", "best_ask": "0.69"}, {"asset_id": "4041912122563547970024635557261696068618666839090786586996637505354743961673", "price": "0.71", "size": "268.96", "side": "SELL", "hash": "e0be727b2f06bde37e90f4f699b6a4d7d931cdb1", "best_bid": "0.31", "best_ask": "0.35"}], "timestamp": "1769385046259", "event_type": "price_change"}}
{"_local_timestamp": "2026-01-25T23:50:46.347250+00:00", "data": {"market": "0xeb44a06c677ce7a47e5fd2007182e020a577395dc3613ad55d3d576e33964c3d", "price_changes": [{"asset_id": "5305471862219565371067835325573032839634510465603099489495163186843068331171", "price": "0.23", "size": "108", "side": "BUY", "hash": "ba4069939cf9f22c61dc5edb755fd0816e1d698a", "best_bid": "0.5", "best_ask": "0.54"}, {"asset_id": "28227838360096074788232992585368970461718254845788738931649369286727917170476", "price": "0.77", "size": "108", "side": "SELL", "hash": "17ba07b982b1f5dac3ed7d88cab4c44fbc505cb3", "best_bid": "0.46", "best_ask": "0.5"}], "timestamp": "1769385046260", "event_type": "price_change"}}
{"_local_timestamp": "2026-01-25T23:50:46.347959+00:00", "data": {"market": "0xeb44a06c677ce7a47e5fd2007182e020a577395dc3613ad55d3d576e33964c3d", "price_changes": [{"asset_id": "5305471862219565371067835325573032839634510465603099489495163186843068331171", "price": "0.17", "size": "452.94", "side": "BUY", "hash": "ba4069939cf9f22c61dc5edb755fd0816e1d698a", "best_bid": "0.5", "best_ask": "0.54"}, {"asset_id": "28227838360096074788232992585368970461718254845788738931649369286727917170476", "price": "0.83", "size": "452.94", "side": "SELL", "hash": "17ba07b982b1f5dac3ed7d88cab4c44fbc505cb3", "best_bid": "0.46", "best_ask": "0.5"}], "timestamp": "1769385046260", "event_type": "price_change"}}
{"_local_timestamp": "2026-01-25T23:50:46.348637+00:00", "data": {"market": "0xeb44a06c677ce7a47e5fd2007182e020a577395dc3613ad55d3d576e33964c3d", "price_changes": [{"asset_id": "5305471862219565371067835325573032839634510465603099489495163186843068331171", "price": "0.15", "size": "0", "side": "BUY", "hash": "ba4069939cf9f22c61dc5edb755fd0816e1d698a", "best_bid": "0.5", "best_ask": "0.54"}, {"asset_id": "28227838360096074788232992585368970461718254845788738931649369286727917170476", "price": "0.85", "size": "0", "side": "SELL", "hash": "17ba07b982b1f5dac3ed7d88cab4c44fbc505cb3", "best_bid": "0.46", "best_ask": "0.5"}], "timestamp": "1769385046260", "event_type": "price_change"}}
{"_local_timestamp": "2026-01-25T23:50:46.787269+00:00", "data": {"market": "0xca0329cd4392d91e39df0702949229573d2415ae4a37b0103d0c6e9d03b8dd44", "price_changes": [{"asset_id": "20535370510756332462433575263109694145574231213604117747907874615324086102913", "price": "0.25", "size": "6252", "side": "BUY", "hash": "62bbc12488ef541c3d2a67d2bfc09b3f36a6ab1e", "best_bid": "0.79", "best_ask": "0.82"}, {"asset_id": "74768395815166461619548348007728690058055087254143355558596876906836785272025", "price": "0.75", "size": "6252", "side": "SELL", "hash": "72a5de63b61bf27e046d8bb59c41034c551627b6", "best_bid": "0.18", "best_ask": "0.21"}], "timestamp": "1769385046643", "event_type": "price_change"}}
{"_local_timestamp": "2026-01-25T23:50:46.815242+00:00", "data": {"market": "0x0bde18e0a0220d1f97173850504a1ed4fa90ef2c6a7bc0932952790053ca0c0e", "price_changes": [{"asset_id": "105325602140854796101190465907542426130401271786879982796716189175875071392057", "price": "0.3", "size": "3383", "side": "BUY", "hash": "a6367acaf5b524eac3bb120b6cf06179bcd17a1d", "best_bid": "0.65", "best_ask": "0.69"}, {"asset_id": "4041912122563547970024635557261696068618666839090786586996637505354743961673", "price": "0.7", "size": "3383", "side": "SELL", "hash": "2d54a34b6299c0e6bd740bf24dac7becc24e90c4", "best_bid": "0.31", "best_ask": "0.35"}], "timestamp": "1769385046643", "event_type": "price_change"}}
{"_local_timestamp": "2026-01-25T23:50:46.817114+00:00", "data": {"market": "0xeb44a06c677ce7a47e5fd2007182e020a577395dc3613ad55d3d576e33964c3d", "price_changes": [{"asset_id": "28227838360096074788232992585368970461718254845788738931649369286727917170476", "price": "0.18", "size": "411.11", "side": "BUY", "hash": "f18e5f341eaf6e5a7169f5a3202b8bad2bedfe8b", "best_bid": "0.46", "best_ask": "0.5"}, {"asset_id": "5305471862219565371067835325573032839634510465603099489495163186843068331171", "price": "0.82", "size": "411.11", "side": "SELL", "hash": "a7b57979f5b220d4ddedbcff2954841e55bd416b", "best_bid": "0.5", "best_ask": "0.54"}], "timestamp": "1769385046639", "event_type": "price_change"}}
{"_local_timestamp": "2026-01-25T23:50:46.817875+00:00", "data": {"market": "0xeb44a06c677ce7a47e5fd2007182e020a577395dc3613ad55d3d576e33964c3d", "price_changes": [{"asset_id": "5305471862219565371067835325573032839634510465603099489495163186843068331171", "price": "0.24", "size": "3267", "side": "BUY", "hash": "317e95295ce6e9e0ebe55d08e12076c6ab45e02a", "best_bid": "0.5", "best_ask": "0.54"}, {"asset_id": "28227838360096074788232992585368970461718254845788738931649369286727917170476", "price": "0.76", "size": "3267", "side": "SELL", "hash": "24f68a53b49cdf7d595dbe30e2051cd789dffed3", "best_bid": "0.46", "best_ask": "0.5"}], "timestamp": "1769385046655", "event_type": "price_change"}}
{"_local_timestamp": "2026-01-25T23:50:46.831890+00:00", "data": {"market": "0xeb44a06c677ce7a47e5fd2007182e020a577395dc3613ad55d3d576e33964c3d", "price_changes": [{"asset_id": "5305471862219565371067835325573032839634510465603099489495163186843068331171", "price": "0.12", "size": "600", "side": "BUY", "hash": "ddfe634dc6a799542dda9b2b9ce2f9d8097fea41", "best_bid": "0.5", "best_ask": "0.54"}, {"asset_id": "28227838360096074788232992585368970461718254845788738931649369286727917170476", "price": "0.88", "size": "600", "side": "SELL", "hash": "a57db4cf5552c7de1a8f1c7cbb52d215dd861295", "best_bid": "0.46", "best_ask": "0.5"}], "timestamp": "1769385046657", "event_type": "price_change"}}
{"_local_timestamp": "2026-01-25T23:50:46.832701+00:00", "data": {"market": "0xeb44a06c677ce7a47e5fd2007182e020a577395dc3613ad55d3d576e33964c3d", "price_changes": [{"asset_id": "5305471862219565371067835325573032839634510465603099489495163186843068331171", "price": "0.16", "size": "3024", "side": "BUY", "hash": "fdb86f1260a77dcd803e538a9594fd4181a91bac", "best_bid": "0.5", "best_ask": "0.54"}, {"asset_id": "28227838360096074788232992585368970461718254845788738931649369286727917170476", "price": "0.84", "size": "3024", "side": "SELL", "hash": "5a342d54a158ab642c9d93760f0f064fd52bd230", "best_bid": "0.46", "best_ask": "0.5"}], "timestamp": "1769385046658", "event_type": "price_change"}}
{"_local_timestamp": "2026-01-25T23:50:56.341956+00:00", "data": {"market": "0x0bde18e0a0220d1f97173850504a1ed4fa90ef2c6a7bc0932952790053ca0c0e", "price_changes": [{"asset_id": "4041912122563547970024635557261696068618666839090786586996637505354743961673", "price": "0.35", "size": "645", "side": "SELL", "hash": "325b76bfaa51bb2601f807814858508cfe6a9be3", "best_bid": "0.31", "best_ask": "0.35"}, {"asset_id": "105325602140854796101190465907542426130401271786879982796716189175875071392057", "price": "0.65", "size": "645", "side": "BUY", "hash": "ed10fe965c0da10e378c26b408ad1b930ec1ac05", "best_bid": "0.65", "best_ask": "0.69"}], "timestamp": "1769385056268", "event_type": "price_change"}}
{"_local_timestamp": "2026-01-25T23:51:05.597739+00:00", "data": {"market": "0xeb44a06c677ce7a47e5fd2007182e020a577395dc3613ad55d3d576e33964c3d", "price_changes": [{"asset_id": "5305471862219565371067835325573032839634510465603099489495163186843068331171", "price": "0.16", "size": "2924", "side": "BUY", "hash": "d9ea8187492bac9b85a4e4aeca849b4bce9da1ac", "best_bid": "0.5", "best_ask": "0.54"}, {"asset_id": "28227838360096074788232992585368970461718254845788738931649369286727917170476", "price": "0.84", "size": "2924", "side": "SELL", "hash": "c4ff3646b96082db3be1af88ff5052b7b7f27679", "best_bid": "0.46", "best_ask": "0.5"}], "timestamp": "1769385065431", "event_type": "price_change"}}
{"_local_timestamp": "2026-01-25T23:51:05.598693+00:00", "data": {"market": "0xeb44a06c677ce7a47e5fd2007182e020a577395dc3613ad55d3d576e33964c3d", "price_changes": [{"asset_id": "5305471862219565371067835325573032839634510465603099489495163186843068331171", "price": "0.12", "size": "475", "side": "BUY", "hash": "d9ea8187492bac9b85a4e4aeca849b4bce9da1ac", "best_bid": "0.5", "best_ask": "0.54"}, {"asset_id": "28227838360096074788232992585368970461718254845788738931649369286727917170476", "price": "0.88", "size": "475", "side": "SELL", "hash": "c4ff3646b96082db3be1af88ff5052b7b7f27679", "best_bid": "0.46", "best_ask": "0.5"}], "timestamp": "1769385065431", "event_type": "price_change"}}
{"_local_timestamp": "2026-01-25T23:51:05.882517+00:00", "data": {"market": "0xeb44a06c677ce7a47e5fd2007182e020a577395dc3613ad55d3d576e33964c3d", "price_changes": [{"asset_id": "5305471862219565371067835325573032839634510465603099489495163186843068331171", "price": "0.15", "size": "125", "side": "BUY", "hash": "460a8fe9d112f94195757b2f7b67b70809c09371", "best_bid": "0.5", "best_ask": "0.54"}, {"asset_id": "28227838360096074788232992585368970461718254845788738931649369286727917170476", "price": "0.85", "size": "125", "side": "SELL", "hash": "81bf1e559009a0e18a53d81a8a71ef40ba018675", "best_bid": "0.46", "best_ask": "0.5"}], "timestamp": "1769385065767", "event_type": "price_change"}}
{"_local_timestamp": "2026-01-25T23:51:05.916494+00:00", "data": {"market": "0xeb44a06c677ce7a47e5fd2007182e020a577395dc3613ad55d3d576e33964c3d", "price_changes": [{"asset_id": "5305471862219565371067835325573032839634510465603099489495163186843068331171", "price": "0.17", "size": "552.94", "side": "BUY", "hash": "5e0d4bdba3f51fc9c015032aa4c5dd53a3ab6776", "best_bid": "0.5", "best_ask": "0.54"}, {"asset_id": "28227838360096074788232992585368970461718254845788738931649369286727917170476", "price": "0.83", "size": "552.94", "side": "SELL", "hash": "0cea6974520642c8576554ee8097a5d788b53363", "best_bid": "0.46", "best_ask": "0.5"}], "timestamp": "1769385065771", "event_type": "price_change"}}
{"_local_timestamp": "2026-01-25T23:51:12.949196+00:00", "data": {"market": "0xca0329cd4392d91e39df0702949229573d2415ae4a37b0103d0c6e9d03b8dd44", "price_changes": [{"asset_id": "20535370510756332462433575263109694145574231213604117747907874615324086102913", "price": "0.08", "size": "1500", "side": "BUY", "hash": "141622cb6a81d441116597d98f34af3a70344cbe", "best_bid": "0.79", "best_ask": "0.82"}, {"asset_id": "74768395815166461619548348007728690058055087254143355558596876906836785272025", "price": "0.92", "size": "1500", "side": "SELL", "hash": "df3a004a06f77817f1ad76aceb09ea552bbcb8d2", "best_bid": "0.18", "best_ask": "0.21"}], "timestamp": "1769385072887", "event_type": "price_change"}}
{"_local_timestamp": "2026-01-25T23:51:16.082330+00:00", "data": {"market": "0x0bde18e0a0220d1f97173850504a1ed4fa90ef2c6a7bc0932952790053ca0c0e", "price_changes": [{"asset_id": "4041912122563547970024635557261696068618666839090786586996637505354743961673", "price": "0.35", "size": "619", "side": "SELL", "hash": "51b3ea514116d21ab67977593a7b48dec491a5d3", "best_bid": "0.31", "best_ask": "0.35"}, {"asset_id": "105325602140854796101190465907542426130401271786879982796716189175875071392057", "price": "0.65", "size": "619", "side": "BUY", "hash": "aa57d2806023fae8a2ef4c50335ce05987adf9fc", "best_bid": "0.65", "best_ask": "0.69"}], "timestamp": "1769385076000", "event_type": "price_change"}}
{"_local_timestamp": "2026-01-25T23:51:22.906428+00:00", "data": {"market": "0xca0329cd4392d91e39df0702949229573d2415ae4a37b0103d0c6e9d03b8dd44", "price_changes": [{"asset_id": "20535370510756332462433575263109694145574231213604117747907874615324086102913", "price": "0.08", "size": "800", "side": "BUY", "hash": "364d5dc01a801feb4fd565fb75e2a2e4b15bd25f", "best_bid": "0.79", "best_ask": "0.82"}, {"asset_id": "74768395815166461619548348007728690058055087254143355558596876906836785272025", "price": "0.92", "size": "800", "side": "SELL", "hash": "f22256ad2d531269d39cdec70048ff89ced43798", "best_bid": "0.18", "best_ask": "0.21"}], "timestamp": "1769385082837", "event_type": "price_change"}}
{"_local_timestamp": "2026-01-25T23:51:24.013827+00:00", "data": {"market": "0x0bde18e0a0220d1f97173850504a1ed4fa90ef2c6a7bc0932952790053ca0c0e", "price_changes": [{"asset_id": "4041912122563547970024635557261696068618666839090786586996637505354743961673", "price": "0.3", "size": "498.5", "side": "BUY", "hash": "baa7b26fb6f980148137b55fcd72c4e305536787", "best_bid": "0.31", "best_ask": "0.35"}, {"asset_id": "105325602140854796101190465907542426130401271786879982796716189175875071392057", "price": "0.7", "size": "498.5", "side": "SELL", "hash": "90e12d903a3314c6358ebb0e51ee37eb1af30ed9", "best_bid": "0.65", "best_ask": "0.69"}], "timestamp": "1769385083939", "event_type": "price_change"}}
{"_local_timestamp": "2026-01-25T23:51:24.015447+00:00", "data": {"market": "0x0bde18e0a0220d1f97173850504a1ed4fa90ef2c6a7bc0932952790053ca0c0e", "price_changes": [{"asset_id": "105325602140854796101190465907542426130401271786879982796716189175875071392057", "price": "0.64", "size": "395", "side": "BUY", "hash": "1e0a4b9a7c2bbf3df238aa29752c0f3a4b472926", "best_bid": "0.65", "best_ask": "0.69"}, {"asset_id": "4041912122563547970024635557261696068618666839090786586996637505354743961673", "price": "0.36", "size": "395", "side": "SELL", "hash": "2fdf4bc33ceaa902235ea03f4bcbeb337e945549", "best_bid": "0.31", "best_ask": "0.35"}], "timestamp": "1769385083940", "event_type": "price_change"}}
{"_local_timestamp": "2026-01-25T23:51:25.712343+00:00", "data": {"market": "0xca0329cd4392d91e39df0702949229573d2415ae4a37b0103d0c6e9d03b8dd44", "price_changes": [{"asset_id": "20535370510756332462433575263109694145574231213604117747907874615324086102913", "price": "0.2", "size": "400", "side": "BUY", "hash": "1a33fbc4a105b4acad207e124a2d207efd897b40", "best_bid": "0.79", "best_ask": "0.82"}, {"asset_id": "74768395815166461619548348007728690058055087254143355558596876906836785272025", "price": "0.8", "size": "400", "side": "SELL", "hash": "3c6cf143320f39f32fb2ec3260ab3d4d1c243454", "best_bid": "0.18", "best_ask": "0.21"}], "timestamp": "1769385085598", "event_type": "price_change"}}
{"_local_timestamp": "2026-01-25T23:51:25.713189+00:00", "data": {"market": "0xeb44a06c677ce7a47e5fd2007182e020a577395dc3613ad55d3d576e33964c3d", "price_changes": [{"asset_id": "5305471862219565371067835325573032839634510465603099489495163186843068331171", "price": "0.12", "size": "425", "side": "BUY", "hash": "7ce0504ec0eceb7bce659847030768dedeb6473d", "best_bid": "0.5", "best_ask": "0.54"}, {"asset_id": "28227838360096074788232992585368970461718254845788738931649369286727917170476", "price": "0.88", "size": "425", "side": "SELL", "hash": "3209ccb802b55c0c9f4a6d68e09767424b34e2a1", "best_bid": "0.46", "best_ask": "0.5"}], "timestamp": "1769385085598", "event_type": "price_change"}}
{"_local_timestamp": "2026-01-25T23:51:26.093322+00:00", "data": {"market": "0xca0329cd4392d91e39df0702949229573d2415ae4a37b0103d0c6e9d03b8dd44", "price_changes": [{"asset_id": "20535370510756332462433575263109694145574231213604117747907874615324086102913", "price": "0.15", "size": "600", "side": "BUY", "hash": "7faa6febfffce2b6b18a5cc0a424d10784537417", "best_bid": "0.79", "best_ask": "0.82"}, {"asset_id": "74768395815166461619548348007728690058055087254143355558596876906836785272025", "price": "0.85", "size": "600", "side": "SELL", "hash": "fd75b3afcae7404e9aefcbc19b38ac2918e37f24", "best_bid": "0.18", "best_ask": "0.21"}], "timestamp": "1769385086010", "event_type": "price_change"}}
{"_local_timestamp": "2026-01-25T23:51:26.094130+00:00", "data": {"market": "0xeb44a06c677ce7a47e5fd2007182e020a577395dc3613ad55d3d576e33964c3d", "price_changes": [{"asset_id": "5305471862219565371067835325573032839634510465603099489495163186843068331171", "price": "0.16", "size": "2974", "side": "BUY", "hash": "485f56ad2bb6a84edc2b881e9a1f950a00eec47e", "best_bid": "0.5", "best_ask": "0.54"}, {"asset_id": "28227838360096074788232992585368970461718254845788738931649369286727917170476", "price": "0.84", "size": "2974", "side": "SELL", "hash": "a484f40e865ad5c505bb802141aae3a6494204c7", "best_bid": "0.46", "best_ask": "0.5"}], "timestamp": "1769385086010", "event_type": "price_change"}}
{"_local_timestamp": "2026-01-25T23:51:26.466600+00:00", "data": {"market": "0xeb44a06c677ce7a47e5fd2007182e020a577395dc3613ad55d3d576e33964c3d", "price_changes": [{"asset_id": "5305471862219565371067835325573032839634510465603099489495163186843068331171", "price": "0.12", "size": "200", "side": "BUY", "hash": "ae1506279ad80174479a81b359bb3bbde182d391", "best_bid": "0.5", "best_ask": "0.54"}, {"asset_id": "28227838360096074788232992585368970461718254845788738931649369286727917170476", "price": "0.88", "size": "200", "side": "SELL", "hash": "e634c81af09b50d28cda6b0d0be0255a1c406138", "best_bid": "0.46", "best_ask": "0.5"}], "timestamp": "1769385086379", "event_type": "price_change"}}
{"_local_timestamp": "2026-01-25T23:51:26.732312+00:00", "data": {"market": "0xeb44a06c677ce7a47e5fd2007182e020a577395dc3613ad55d3d576e33964c3d", "price_changes": [{"asset_id": "5305471862219565371067835325573032839634510465603099489495163186843068331171", "price": "0.11", "size": "515.9", "side": "BUY", "hash": "08d3f46c1bca91b119018fb8ba5ebcc020e40c93", "best_bid": "0.5", "best_ask": "0.54"}, {"asset_id": "28227838360096074788232992585368970461718254845788738931649369286727917170476", "price": "0.89", "size": "515.9", "side": "SELL", "hash": "b8d912335e949847c09156a00a242a628fa22ab5", "best_bid": "0.46", "best_ask": "0.5"}], "timestamp": "1769385086639", "event_type": "price_change"}}
