{"_local_timestamp": "2026-01-25T23:40:41.642290+00:00", "data": [{"market": "0x15a99b7ac17e9cb8972f852ee2798dfba6fc977a53ff3bf2f99527305e690411", "asset_id": "67804243531391989346875449219790559386739387253247872134999423217366474323425", "timestamp": "1769384339160", "hash": "6e032a084baa454cce597b1880668f493a83fe6c", "bids": [{"price": "0.001", "size": "22055.55"}], "asks": [{"price": "0.999", "size": "3859"}, {"price": "0.998", "size": "1250"}, {"price": "0.997", "size": "1406.62"}, {"price": "0.994", "size": "200"}, {"price": "0.993", "size": "9.76"}, {"price": "0.99", "size": "5500"}, {"price": "0.98", "size": "2200"}, {"price": "0.979", "size": "8.81"}, {"price": "0.95", "size": "30"}, {"price": "0.949", "size": "39"}, {"price": "0.94", "size": "500"}, {"price": "0.939", "size": "8.89"}, {"price": "0.9", "size": "860"}, {"price": "0.85", "size": "776.66"}, {"price": "0.8", "size": "660"}, {"price": "0.799", "size": "5.84"}, {"price": "0.75", "size": "362"}, {"price": "0.7", "size": "186.66"}, {"price": "0.66", "size": "50"}, {"price": "0.65", "size": "68.57"}, {"price": "0.6", "size": "50"}, {"price": "0.593", "size": "5"}, {"price": "0.592", "size": "5816"}, {"price": "0.591", "size": "60"}, {"price": "0.59", "size": "315"}, {"price": "0.589", "size": "15"}, {"price": "0.18", "size": "15"}, {"price": "0.178", "size": "9"}, {"price": "0.177", "size": "20"}, {"price": "0.164", "size": "10"}, {"price": "0.077", "size": "264"}, {"price": "0.076", "size": "172.4"}, {"price": "0.005", "size": "231.6"}, {"price": "0.004", "size": "11.81"}, {"price": "0.003", "size": "584.6"}, {"price": "0.002", "size": "113.15"}], "event_type": "book", "last_trade_price": "0.001"}, {"market": "0xd25c820d3aee1c735c0fa62c36f4905632ab8c6988653b5b4134593b3209eb7f", "asset_id": "45361184347486002884792387151438756924785609968030585696129487864334578884255", "timestamp": "1769384440646", "hash": "adec397861aa36f1e0640903f20787906d26f768", "bids": [{"price": "0.01", "size": "4511.18"}, {"price": "0.02", "size": "1000"}, {"price": "0.03", "size": "8.67"}, {"price": "0.05", "size": "3841"}, {"price": "0.07", "size": "1014.28"}, {"price": "0.08", "size": "7.04"}, {"price": "0.1", "size": "340"}, {"price": "0.14", "size": "228.57"}, {"price": "0.15", "size": "1785.53"}, {"price": "0.17", "size": "564.7"}, {"price": "0.18", "size": "11.72"}, {"price": "0.2", "size": "130"}, {"price": "0.21", "size": "5.07"}, {"price": "0.24", "size": "100"}, {"price": "0.25", "size": "200"}, {"price": "0.27", "size": "124.07"}, {"price": "0.28", "size": "62"}, {"price": "0.3", "size": "6"}, {"price": "0.31", "size": "110"}, {"price": "0.41", "size": "29"}, {"price": "0.43", "size": "100"}, {"price": "0.47", "size": "10"}, {"price": "0.48", "size": "20"}, {"price": "0.53", "size": "7.5"}, {"price": "0.55", "size": "25.5"}, {"price": "0.6", "size": "5"}], "asks": [{"price": "0.99", "size": "2505"}, {"price": "0.98", "size": "10"}, {"price": "0.97", "size": "1500"}, {"price": "0.96", "size": "400"}, {"price": "0.95", "size": "300"}, {"price": "0.94", "size": "675.33"}, {"price": "0.81", "size": "25.33"}, {"price": "0.78", "size": "230"}, {"price": "0.68", "size": "30"}, {"price": "0.67", "size": "25.33"}], "event_type": "book", "last_trade_price": "0.400"}, {"market": "0xba8add06562a7bfd4fdd8f0a1882b5e2596540bd61c67a32359487694838f0a5", "asset_id": "62853431799112511763784693741363968903595954956498708214160770466188703343964", "timestamp": "1769384431891", "hash": "03ab16a98883bbc5d4a1674d6e6bffa0ead29073", "bids": [{"price": "0.01", "size": "5510.09"}, {"price": "0.02", "size": "2200"}, {"price": "0.03", "size": "9.32"}, {"price": "0.05", "size": "10"}, {"price": "0.08", "size": "1250"}, {"price": "0.09", "size": "5.2"}, {"price": "0.12", "size": "283.33"}, {"price": "0.14", "size": "550"}, {"price": "0.16", "size": "200"}, {"price": "0.19", "size": "1042"}, {"price": "0.2", "size": "440"}, {"price": "0.21", "size": "5.48"}, {"price": "0.23", "size": "113.04"}, {"price": "0.24", "size": "1848"}, {"price": "0.27", "size": "88.88"}, {"price": "0.3", "size": "3291"}, {"price": "0.31", "size": "364.51"}, {"price": "0.34", "size": "50"}, {"price": "0.42", "size": "235"}, {"price": "0.43", "size": "5"}, {"price": "0.52", "size": "10"}, {"price": "0.54", "size": "25"}, {"price": "0.55", "size": "20"}, {"price": "0.75", "size": "455.85"}, {"price": "0.76", "size": "339.25"}], "asks": [{"price": "0.99", "size": "2505"}, {"price": "0.98", "size": "53"}, {"price": "0.97", "size": "6.66"}, {"price": "0.87", "size": "400"}, {"price": "0.86", "size": "52.66"}, {"price": "0.82", "size": "52.66"}, {"price": "0.8", "size": "284"}, {"price": "0.79", "size": "100"}, {"price": "0.78", "size": "31.95"}], "event_type": "book", "last_trade_price": "0.780"}, {"market": "0x0eada57dcf53965a321f61c9dc6adb655367fabeb1f2ecbe7746f3f1a6ff7769", "asset_id": "88775412427564636095391917176836120951442159831179966305257669968799086969217", "timestamp": "1769384398696", "hash": "329a3fc1824030970555c52675714a0899dfe2df", "bids": [{"price": "0.001", "size": "23142"}, {"price": "0.002", "size": "73.11"}], "asks": [{"price": "0.999", "size": "3870"}, {"price": "0.998", "size": "1250"}, {"price": "0.997", "size": "1406.62"}, {"price": "0.994", "size": "200"}, {"price": "0.993", "size": "9.76"}, {"price": "0.99", "size": "5500"}, {"price": "0.98", "size": "2200"}, {"price": "0.979", "size": "8.81"}, {"price": "0.95", "size": "30"}, {"price": "0.949", "size": "39"}, {"price": "0.94", "size": "500"}, {"price": "0.939", "size": "8.89"}, {"price": "0.9", "size": "860"}, {"price": "0.85", "size": "776.66"}, {"price": "0.8", "size": "660"}, {"price": "0.799", "size": "5.84"}, {"price": "0.75", "size": "362"}, {"price": "0.7", "size": "186.66"}, {"price": "0.66", "size": "50"}, {"price": "0.65", "size": "68.57"}, {"price": "0.6", "size": "50"}, {"price": "0.596", "size": "5967"}, {"price": "0.595", "size": "236"}, {"price": "0.594", "size": "30"}, {"price": "0.53", "size": "5"}, {"price": "0.521", "size": "10"}, {"price": "0.519", "size": "25"}, {"price": "0.518", "size": "20"}, {"price": "0.161", "size": "13.33"}, {"price": "0.022", "size": "193.31"}, {"price": "0.004", "size": "292.51"}, {"price": "0.003", "size": "1148.42"}], "event_type": "book", "last_trade_price": ""}, {"market": "0x15a99b7ac17e9cb8972f852ee2798dfba6fc977a53ff3bf2f99527305e690411", "asset_id": "16326880523082047267449204000618069867645781949928810368805306223220924298747", "timestamp": "1769384339160", "hash": "8d9b54f97ef522945a302dae245a78f1618af2f4", "bids": [{"price": "0.001", "size": "3859"}, {"price": "0.002", "size": "1250"}, {"price": "0.003", "size": "1406.62"}, {"price": "0.006", "size": "200"}, {"price": "0.007", "size": "9.76"}, {"price": "0.01", "size": "5500"}, {"price": "0.02", "size": "2200"}, {"price": "0.021", "size": "8.81"}, {"price": "0.05", "size": "30"}, {"price": "0.051", "size": "39"}, {"price": "0.06", "size": "500"}, {"price": "0.061", "size": "8.89"}, {"price": "0.1", "size": "860"}, {"price": "0.15", "size": "776.66"}, {"price": "0.2", "size": "660"}, {"price": "0.201", "size": "5.84"}, {"price": "0.25", "size": "362"}, {"price": "0.3", "size": "186.66"}, {"price": "0.34", "size": "50"}, {"price": "0.35", "size": "68.57"}, {"price": "0.4", "size": "50"}, {"price": "0.407", "size": "5"}, {"price": "0.408", "size": "5816"}, {"price": "0.409", "size": "60"}, {"price": "0.41", "size": "315"}, {"price": "0.411", "size": "15"}, {"price": "0.82", "size": "15"}, {"price": "0.822", "size": "9"}, {"price": "0.823", "size": "20"}, {"price": "0.836", "size": "10"}, {"price": "0.923", "size": "264"}, {"price": "0.924", "size": "172.4"}, {"price": "0.995", "size": "231.6"}, {"price": "0.996", "size": "11.81"}, {"price": "0.997", "size": "584.6"}, {"price": "0.998", "size": "113.15"}], "asks": [{"price": "0.999", "size": "22055.55"}], "event_type": "book", "last_trade_price": "0.001"}, {"market": "0x405b6e3ce8caf18dea56ec418ea5a5c715f43aad946059e3eb7e3d1281698a78", "asset_id": "24373928341866408058552921472563928863071297280035754284253945296860184628420", "timestamp": "1769384338504", "hash": "ac4a49b82ed9bac375c5e19740f0032f11fe4405", "bids": [{"price": "0.001", "size": "3858"}, {"price": "0.002", "size": "1250"}, {"price": "0.003", "size": "1406.64"}, {"price": "0.006", "size": "200"}, {"price": "0.007", "size": "9.78"}, {"price": "0.01", "size": "5500"}, {"price": "0.02", "size": "2200"}, {"price": "0.021", "size": "8.83"}, {"price": "0.05", "size": "20"}, {"price": "0.051", "size": "39"}, {"price": "0.06", "size": "500"}, {"price": "0.061", "size": "8.89"}, {"price": "0.1", "size": "860"}, {"price": "0.15", "size": "776.66"}, {"price": "0.2", "size": "660"}, {"price": "0.201", "size": "5.84"}, {"price": "0.223", "size": "453"}, {"price": "0.25", "size": "112"}, {"price": "0.3", "size": "186.66"}, {"price": "0.34", "size": "50"}, {"price": "0.35", "size": "68.57"}, {"price": "0.4", "size": "50"}, {"price": "0.403", "size": "4093"}, {"price": "0.404", "size": "300"}, {"price": "0.723", "size": "85"}, {"price": "0.74", "size": "5"}, {"price": "0.823", "size": "143"}, {"price": "0.832", "size": "10"}, {"price": "0.833", "size": "29"}, {"price": "0.923", "size": "178"}, {"price": "0.924", "size": "431.65"}, {"price": "0.925", "size": "155"}, {"price": "0.926", "size": "155.03"}, {"price": "0.927", "size": "30"}, {"price": "0.995", "size": "31"}, {"price": "0.996", "size": "16.39"}], "asks": [{"price": "0.999", "size": "29344.32"}, {"price": "0.998", "size": "5"}, {"price": "0.997", "size": "90.95"}], "event_type": "book", "last_trade_price": ""}, {"market": "0x405b6e3ce8caf18dea56ec418ea5a5c715f43aad946059e3eb7e3d1281698a78", "asset_id": "2350235314632053038507062516507369036092528887799666119386073644944240496673", "timestamp": "1769384338504", "hash": "d590de475c26e3a1f5e5532cb062f719c467be7d", "bids": [{"price": "0.001", "size": "29344.32"}, {"price": "0.002", "size": "5"}, {"price": "0.003", "size": "90.95"}], "asks": [{"price": "0.999", "size": "3858"}, {"price": "0.998", "size": "1250"}, {"price": "0.997", "size": "1406.64"}, {"price": "0.994", "size": "200"}, {"price": "0.993", "size": "9.78"}, {"price": "0.99", "size": "5500"}, {"price": "0.98", "size": "2200"}, {"price": "0.979", "size": "8.83"}, {"price": "0.95", "size": "20"}, {"price": "0.949", "size": "39"}, {"price": "0.94", "size": "500"}, {"price": "0.939", "size": "8.89"}, {"price": "0.9", "size": "860"}, {"price": "0.85", "size": "776.66"}, {"price": "0.8", "size": "660"}, {"price": "0.799", "size": "5.84"}, {"price": "0.777", "size": "453"}, {"price": "0.75", "size": "112"}, {"price": "0.7", "size": "186.66"}, {"price": "0.66", "size": "50"}, {"price": "0.65", "size": "68.57"}, {"price": "0.6", "size": "50"}, {"price": "0.597", "size": "4093"}, {"price": "0.596", "size": "300"}, {"price": "0.277", "size": "85"}, {"price": "0.26", "size": "5"}, {"price": "0.177", "size": "143"}, {"price": "0.168", "size": "10"}, {"price": "0.167", "size": "29"}, {"price": "0.077", "size": "178"}, {"price": "0.076", "size": "431.65"}, {"price": "0.075", "size": "155"}, {"price": "0.074", "size": "155.03"}, {"price": "0.073", "size": "30"}, {"price": "0.005", "size": "31"}, {"price": "0.004", "size": "16.39"}], "event_type": "book", "last_trade_price": ""}, {"market": "0xba8add06562a7bfd4fdd8f0a1882b5e2596540bd61c67a32359487694838f0a5", "asset_id": "7221299913764832338348128493889748182769672206962167820297840741811689706878", "timestamp": "1769384431891", "hash": "c617878e07891b9d63dd30ab68b635357684b5e6", "bids": [{"price": "0.01", "size": "2505"}, {"price": "0.02", "size": "53"}, {"price": "0.03", "size": "6.66"}, {"price": "0.13", "size": "400"}, {"price": "0.14", "size": "52.66"}, {"price": "0.18", "size": "52.66"}, {"price": "0.2", "size": "284"}, {"price": "0.21", "size": "100"}, {"price": "0.22", "size": "31.95"}], "asks": [{"price": "0.99", "size": "5510.09"}, {"price": "0.98", "size": "2200"}, {"price": "0.97", "size": "9.32"}, {"price": "0.95", "size": "10"}, {"price": "0.92", "size": "1250"}, {"price": "0.91", "size": "5.2"}, {"price": "0.88", "size": "283.33"}, {"price": "0.86", "size": "550"}, {"price": "0.84", "size": "200"}, {"price": "0.81", "size": "1042"}, {"price": "0.8", "size": "440"}, {"price": "0.79", "size": "5.48"}, {"price": "0.77", "size": "113.04"}, {"price": "0.76", "size": "1848"}, {"price": "0.73", "size": "88.88"}, {"price": "0.7", "size": "3291"}, {"price": "0.69", "size": "364.51"}, {"price": "0.66", "size": "50"}, {"price": "0.58", "size": "235"}, {"price": "0.57", "size": "5"}, {"price": "0.48", "size": "10"}, {"price": "0.46", "size": "25"}, {"price": "0.45", "size": "20"}, {"price": "0.25", "size": "455.85"}, {"price": "0.24", "size": "339.25"}], "event_type": "book", "last_trade_price": "0.780"}, {"market": "0x1fe1788d96d4c98e242549f91baf0de29eaf3b1545b5e2dda1d8714a3faf5305", "asset_id": "85121409960340786807237728711169263074482548425773836042297909052960286277119", "timestamp": "1769384376151", "hash": "085da2f50edbda807bffd6fb466aaa4d08839224", "bids": [{"price": "0.001", "size": "3859"}, {"price": "0.002", "size": "1250"}, {"price": "0.003", "size": "1406.62"}, {"price": "0.006", "size": "200"}, {"price": "0.007", "size": "9.76"}, {"price": "0.01", "size": "5500"}, {"price": "0.02", "size": "2200"}, {"price": "0.021", "size": "8.81"}, {"price": "0.05", "size": "30"}, {"price": "0.051", "size": "39"}, {"price": "0.06", "size": "500"}, {"price": "0.061", "size": "8.89"}, {"price": "0.1", "size": "860"}, {"price": "0.15", "size": "776.66"}, {"price": "0.2", "size": "660"}, {"price": "0.201", "size": "5.84"}, {"price": "0.25", "size": "212"}, {"price": "0.3", "size": "536.66"}, {"price": "0.302", "size": "244.95"}, {"price": "0.303", "size": "3795"}, {"price": "0.34", "size": "50"}, {"price": "0.35", "size": "68.57"}, {"price": "0.351", "size": "34"}, {"price": "0.4", "size": "50"}, {"price": "0.402", "size": "155"}, {"price": "0.403", "size": "5"}, {"price": "0.744", "size": "6.01"}, {"price": "0.748", "size": "10"}, {"price": "0.749", "size": "20"}, {"price": "0.96", "size": "200"}, {"price": "0.98", "size": "20.96"}, {"price": "0.995", "size": "6"}, {"price": "0.996", "size": "262.4"}, {"price": "0.997", "size": "279.26"}], "asks": [{"price": "0.999", "size": "23456"}, {"price": "0.998", "size": "2946.58"}], "event_type": "book", "last_trade_price": "0.002"}, {"market": "0xd25c820d3aee1c735c0fa62c36f4905632ab8c6988653b5b4134593b3209eb7f", "asset_id": "91117078941733659645786554099775611998962677612187928648088119165893475827434", "timestamp": "1769384440646", "hash": "a501b0845f6a1f64066c40481a3b6e690ba9fa3b", "bids": [{"price": "0.01", "size": "2505"}, {"price": "0.02", "size": "10"}, {"price": "0.03", "size": "1500"}, {"price": "0.04", "size": "400"}, {"price": "0.05", "size": "300"}, {"price": "0.06", "size": "675.33"}, {"price": "0.19", "size": "25.33"}, {"price": "0.22", "size": "230"}, {"price": "0.32", "size": "30"}, {"price": "0.33", "size": "25.33"}], "asks": [{"price": "0.99", "size": "4511.18"}, {"price": "0.98", "size": "1000"}, {"price": "0.97", "size": "8.67"}, {"price": "0.95", "size": "3841"}, {"price": "0.93", "size": "1014.28"}, {"price": "0.92", "size": "7.04"}, {"price": "0.9", "size": "340"}, {"price": "0.86", "size": "228.57"}, {"price": "0.85", "size": "1785.53"}, {"price": "0.83", "size": "564.7"}, {"price": "0.82", "size": "11.72"}, {"price": "0.8", "size": "130"}, {"price": "0.79", "size": "5.07"}, {"price": "0.76", "size": "100"}, {"price": "0.75", "size": "200"}, {"price": "0.73", "size": "124.07"}, {"price": "0.72", "size": "62"}, {"price": "0.7", "size": "6"}, {"price": "0.69", "size": "110"}, {"price": "0.59", "size": "29"}, {"price": "0.57", "size": "100"}, {"price": "0.53", "size": "10"}, {"price": "0.52", "size": "20"}, {"price": "0.47", "size": "7.5"}, {"price": "0.45", "size": "25.5"}, {"price": "0.4", "size": "5"}], "event_type": "book", "last_trade_price": "0.400"}, {"market": "0xbbd623c4191ca76dec466507375d6df85b403b7e14f9cbd3d09f2c450ae0cd96", "asset_id": "86988864427600902662654729368237087316370077858847155604307346968813506081632", "timestamp": "1769384426815", "hash": "bb914d42f6c2407c3170adb69c90f532bfd85737", "bids": [{"price": "0.03", "size": "300"}, {"price": "0.04", "size": "300"}, {"price": "0.05", "size": "200"}, {"price": "0.07", "size": "33"}, {"price": "0.08", "size": "100"}, {"price": "0.11", "size": "200"}, {"price": "0.13", "size": "130"}, {"price": "0.18", "size": "100"}, {"price": "0.19", "size": "54.94"}, {"price": "0.22", "size": "60"}, {"price": "0.23", "size": "16"}, {"price": "0.27", "size": "27.55"}], "asks": [{"price": "0.99", "size": "5810.44"}, {"price": "0.98", "size": "2200"}, {"price": "0.97", "size": "8.11"}, {"price": "0.95", "size": "10"}, {"price": "0.93", "size": "700"}, {"price": "0.92", "size": "5.24"}, {"price": "0.85", "size": "550"}, {"price": "0.84", "size": "1000"}, {"price": "0.83", "size": "2470"}, {"price": "0.81", "size": "4443"}, {"price": "0.8", "size": "350"}, {"price": "0.79", "size": "105.87"}, {"price": "0.74", "size": "157"}, {"price": "0.69", "size": "275"}, {"price": "0.65", "size": "20"}, {"price": "0.59", "size": "14.44"}, {"price": "0.49", "size": "615"}, {"price": "0.47", "size": "100"}, {"price": "0.46", "size": "76.66"}, {"price": "0.45", "size": "20"}, {"price": "0.43", "size": "337.56"}, {"price": "0.38", "size": "66.66"}, {"price": "0.35", "size": "50.83"}, {"price": "0.31", "size": "20"}, {"price": "0.3", "size": "66.66"}], "event_type": "book", "last_trade_price": ""}, {"market": "0x0eada57dcf53965a321f61c9dc6adb655367fabeb1f2ecbe7746f3f1a6ff7769", "asset_id": "93593125008177926269164142727030950699068997099893975938000261506053151609883", "timestamp": "1769384398696", "hash": "0a9b1b354a7f9797fb79060dace8a8e5f17a84c2", "bids": [{"price": "0.001", "size": "3870"}, {"price": "0.002", "size": "1250"}, {"price": "0.003", "size": "1406.62"}, {"price": "0.006", "size": "200"}, {"price": "0.007", "size": "9.76"}, {"price": "0.01", "size": "5500"}, {"price": "0.02", "size": "2200"}, {"price": "0.021", "size": "8.81"}, {"price": "0.05", "size": "30"}, {"price": "0.051", "size": "39"}, {"price": "0.06", "size": "500"}, {"price": "0.061", "size": "8.89"}, {"price": "0.1", "size": "860"}, {"price": "0.15", "size": "776.66"}, {"price": "0.2", "size": "660"}, {"price": "0.201", "size": "5.84"}, {"price": "0.25", "size": "362"}, {"price": "0.3", "size": "186.66"}, {"price": "0.34", "size": "50"}, {"price": "0.35", "size": "68.57"}, {"price": "0.4", "size": "50"}, {"price": "0.404", "size": "5967"}, {"price": "0.405", "size": "236"}, {"price": "0.406", "size": "30"}, {"price": "0.47", "size": "5"}, {"price": "0.479", "size": "10"}, {"price": "0.481", "size": "25"}, {"price": "0.482", "size": "20"}, {"price": "0.839", "size": "13.33"}, {"price": "0.978", "size": "193.31"}, {"price": "0.996", "size": "292.51"}, {"price": "0.997", "size": "1148.42"}], "asks": [{"price": "0.999", "size": "23142"}, {"price": "0.998", "size": "73.11"}], "event_type": "book", "last_trade_price": ""}, {"market": "0xbbd623c4191ca76dec466507375d6df85b403b7e14f9cbd3d09f2c450ae0cd96", "asset_id": "86141088804897222236928959539148501008650371218692800935714557867410378164931", "timestamp": "1769384426815", "hash": "15f69067936e8eecf0f29f3d20cb26740dcc8ab0", "bids": [{"price": "0.01", "size": "5810.44"}, {"price": "0.02", "size": "2200"}, {"price": "0.03", "size": "8.11"}, {"price": "0.05", "size": "10"}, {"price": "0.07", "size": "700"}, {"price": "0.08", "size": "5.24"}, {"price": "0.15", "size": "550"}, {"price": "0.16", "size": "1000"}, {"price": "0.17", "size": "2470"}, {"price": "0.19", "size": "4443"}, {"price": "0.2", "size": "350"}, {"price": "0.21", "size": "105.87"}, {"price": "0.26", "size": "157"}, {"price": "0.31", "size": "275"}, {"price": "0.35", "size": "20"}, {"price": "0.41", "size": "14.44"}, {"price": "0.51", "size": "615"}, {"price": "0.53", "size": "100"}, {"price": "0.54", "size": "76.66"}, {"price": "0.55", "size": "20"}, {"price": "0.57", "size": "337.56"}, {"price": "0.62", "size": "66.66"}, {"price": "0.65", "size": "50.83"}, {"price": "0.69", "size": "20"}, {"price": "0.7", "size": "66.66"}], "asks": [{"price": "0.97", "size": "300"}, {"price": "0.96", "size": "300"}, {"price": "0.95", "size": "200"}, {"price": "0.93", "size": "33"}, {"price": "0.92", "size": "100"}, {"price": "0.89", "size": "200"}, {"price": "0.87", "size": "130"}, {"price": "0.82", "size": "100"}, {"price": "0.81", "size": "54.94"}, {"price": "0.78", "size": "60"}, {"price": "0.77", "size": "16"}, {"price": "0.73", "size": "27.55"}], "event_type": "book", "last_trade_price": ""}, {"market": "0x96bc24f519f3008b984b623dfacfa6b87599381ba6afdbd36a576d0d85c4a59c", "asset_id": "48733707571584348634287808682190901692810422881953520223982749265958667182900", "timestamp": "1769384426814", "hash": "c0b7faec1cb4ca9253168dff56d14a560f29feda", "bids": [{"price": "0.001", "size": "22324"}], "asks": [{"price": "0.999", "size": "3861"}, {"price": "0.998", "size": "1250"}, {"price": "0.997", "size": "1406.63"}, {"price": "0.994", "size": "200"}, {"price": "0.993", "size": "9.76"}, {"price": "0.99", "size": "5500"}, {"price": "0.98", "size": "2200"}, {"price": "0.979", "size": "8.81"}, {"price": "0.95", "size": "30"}, {"price": "0.949", "size": "39"}, {"price": "0.94", "size": "500"}, {"price": "0.939", "size": "8.89"}, {"price": "0.9", "size": "860"}, {"price": "0.85", "size": "776.66"}, {"price": "0.8", "size": "660"}, {"price": "0.799", "size": "5.83"}, {"price": "0.75", "size": "312"}, {"price": "0.7", "size": "136.66"}, {"price": "0.699", "size": "8007"}, {"price": "0.698", "size": "300"}, {"price": "0.65", "size": "331.57"}, {"price": "0.6", "size": "125"}, {"price": "0.469", "size": "5"}, {"price": "0.45", "size": "10"}, {"price": "0.448", "size": "25"}, {"price": "0.447", "size": "20"}, {"price": "0.049", "size": "5"}, {"price": "0.009", "size": "13.34"}, {"price": "0.007", "size": "90.63"}, {"price": "0.005", "size": "109.72"}, {"price": "0.004", "size": "2.11"}, {"price": "0.003", "size": "1324.99"}], "event_type": "book", "last_trade_price": ""}, {"market": "0x1fe1788d96d4c98e242549f91baf0de29eaf3b1545b5e2dda1d8714a3faf5305", "asset_id": "30944797740926340411025345169348106947975350930232142082675991513705266362329", "timestamp": "1769384376151", "hash": "1079b919ea2e51f043d36c81eab92180015e6f33", "bids": [{"price": "0.001", "size": "23456"}, {"price": "0.002", "size": "2946.58"}], "asks": [{"price": "0.999", "size": "3859"}, {"price": "0.998", "size": "1250"}, {"price": "0.997", "size": "1406.62"}, {"price": "0.994", "size": "200"}, {"price": "0.993", "size": "9.76"}, {"price": "0.99", "size": "5500"}, {"price": "0.98", "size": "2200"}, {"price": "0.979", "size": "8.81"}, {"price": "0.95", "size": "30"}, {"price": "0.949", "size": "39"}, {"price": "0.94", "size": "500"}, {"price": "0.939", "size": "8.89"}, {"price": "0.9", "size": "860"}, {"price": "0.85", "size": "776.66"}, {"price": "0.8", "size": "660"}, {"price": "0.799", "size": "5.84"}, {"price": "0.75", "size": "212"}, {"price": "0.7", "size": "536.66"}, {"price": "0.698", "size": "244.95"}, {"price": "0.697", "size": "3795"}, {"price": "0.66", "size": "50"}, {"price": "0.65", "size": "68.57"}, {"price": "0.649", "size": "34"}, {"price": "0.6", "size": "50"}, {"price": "0.598", "size": "155"}, {"price": "0.597", "size": "5"}, {"price": "0.256", "size": "6.01"}, {"price": "0.252", "size": "10"}, {"price": "0.251", "size": "20"}, {"price": "0.04", "size": "200"}, {"price": "0.02", "size": "20.96"}, {"price": "0.005", "size": "6"}, {"price": "0.004", "size": "262.4"}, {"price": "0.003", "size": "279.26"}], "event_type": "book", "last_trade_price": "0.002"}, {"market": "0x306bbce53f9a77906b9a928d52728bdee2e48f3354d19a9d6f0db7c9a1d4230d", "asset_id": "34335512241828535299853623975656484642594791501285631499713239174540168255596", "timestamp": "1769384251912", "hash": "929e4dd3bd69d561e584864520dd6daf6cbb6f64", "bids": [{"price": "0.001", "size": "23441"}, {"price": "0.002", "size": "666"}, {"price": "0.003", "size": "250"}, {"price": "0.004", "size": "50"}, {"price": "0.021", "size": "1858.59"}, {"price": "0.037", "size": "1000"}, {"price": "0.041", "size": "20"}, {"price": "0.053", "size": "1149.78"}, {"price": "0.054", "size": "325.93"}], "asks": [{"price": "0.999", "size": "3858.04"}, {"price": "0.998", "size": "1250"}, {"price": "0.997", "size": "1406.65"}, {"price": "0.994", "size": "200"}, {"price": "0.993", "size": "9.8"}, {"price": "0.99", "size": "5500"}, {"price": "0.98", "size": "2200"}, {"price": "0.979", "size": "6.93"}, {"price": "0.95", "size": "30"}, {"price": "0.949", "size": "39"}, {"price": "0.948", "size": "10.46"}, {"price": "0.91", "size": "700"}, {"price": "0.909", "size": "3296"}, {"price": "0.907", "size": "3269"}, {"price": "0.906", "size": "4968"}, {"price": "0.86", "size": "242.85"}, {"price": "0.859", "size": "1734"}, {"price": "0.81", "size": "168.42"}, {"price": "0.808", "size": "1232"}, {"price": "0.807", "size": "6.27"}, {"price": "0.76", "size": "116.66"}, {"price": "0.756", "size": "109"}, {"price": "0.755", "size": "499.99"}, {"price": "0.72", "size": "142.85"}, {"price": "0.699", "size": "250"}, {"price": "0.67", "size": "72.72"}, {"price": "0.62", "size": "177.63"}, {"price": "0.57", "size": "5"}, {"price": "0.569", "size": "23"}, {"price": "0.563", "size": "10"}, {"price": "0.562", "size": "20"}, {"price": "0.181", "size": "100"}, {"price": "0.18", "size": "100"}, {"price": "0.124", "size": "100"}, {"price": "0.118", "size": "60"}, {"price": "0.082", "size": "100"}, {"price": "0.081", "size": "20"}, {"price": "0.077", "size": "20"}, {"price": "0.076", "size": "2.66"}, {"price": "0.069", "size": "149.78"}, {"price": "0.068", "size": "59.89"}], "event_type": "book", "last_trade_price": "0.068"}, {"market": "0x3935226f1baa202667795b3a558d26fb0a9ae894a482676d34820bfb1b9b4edd", "asset_id": "5083116961935871155736992778398112358288960843713086370981563262578268017242", "timestamp": "1769384344636", "hash": "876ff78410a91e337c249c82182b71fee68d3633", "bids": [{"price": "0.001", "size": "3869"}, {"price": "0.002", "size": "1250"}, {"price": "0.003", "size": "1406.63"}, {"price": "0.006", "size": "200"}, {"price": "0.007", "size": "9.77"}, {"price": "0.01", "size": "5500"}, {"price": "0.02", "size": "2200"}, {"price": "0.021", "size": "8.81"}, {"price": "0.05", "size": "30"}, {"price": "0.051", "size": "39"}, {"price": "0.067", "size": "5506"}, {"price": "0.068", "size": "7.77"}, {"price": "0.1", "size": "360"}, {"price": "0.15", "size": "776.66"}, {"price": "0.2", "size": "660"}, {"price": "0.201", "size": "198.23"}, {"price": "0.202", "size": "5.88"}, {"price": "0.25", "size": "212"}, {"price": "0.3", "size": "336.66"}, {"price": "0.301", "size": "100"}, {"price": "0.302", "size": "50"}, {"price": "0.34", "size": "50"}, {"price": "0.35", "size": "68.57"}, {"price": "0.4", "size": "50"}, {"price": "0.424", "size": "142"}, {"price": "0.472", "size": "5"}, {"price": "0.477", "size": "33"}, {"price": "0.478", "size": "20"}, {"price": "0.931", "size": "10.58"}, {"price": "0.941", "size": "167.3"}, {"price": "0.942", "size": "235.56"}, {"price": "0.95", "size": "10.57"}, {"price": "0.995", "size": "0.99"}], "asks": [{"price": "0.999", "size": "18906"}, {"price": "0.998", "size": "4015"}, {"price": "0.997", "size": "71.62"}], "event_type": "book", "last_trade_price": ""}, {"market": "0x96bc24f519f3008b984b623dfacfa6b87599381ba6afdbd36a576d0d85c4a59c", "asset_id": "37234028100441924867078516219629684611507504332898623831670509973866359367709", "timestamp": "1769384426814", "hash": "230248858cc9b69eb26902ce1e78231349c04dc0", "bids": [{"price": "0.001", "size": "3861"}, {"price": "0.002", "size": "1250"}, {"price": "0.003", "size": "1406.63"}, {"price": "0.006", "size": "200"}, {"price": "0.007", "size": "9.76"}, {"price": "0.01", "size": "5500"}, {"price": "0.02", "size": "2200"}, {"price": "0.021", "size": "8.81"}, {"price": "0.05", "size": "30"}, {"price": "0.051", "size": "39"}, {"price": "0.06", "size": "500"}, {"price": "0.061", "size": "8.89"}, {"price": "0.1", "size": "860"}, {"price": "0.15", "size": "776.66"}, {"price": "0.2", "size": "660"}, {"price": "0.201", "size": "5.83"}, {"price": "0.25", "size": "312"}, {"price": "0.3", "size": "136.66"}, {"price": "0.301", "size": "8007"}, {"price": "0.302", "size": "300"}, {"price": "0.35", "size": "331.57"}, {"price": "0.4", "size": "125"}, {"price": "0.531", "size": "5"}, {"price": "0.55", "size": "10"}, {"price": "0.552", "size": "25"}, {"price": "0.553", "size": "20"}, {"price": "0.951", "size": "5"}, {"price": "0.991", "size": "13.34"}, {"price": "0.993", "size": "90.63"}, {"price": "0.995", "size": "109.72"}, {"price": "0.996", "size": "2.11"}, {"price": "0.997", "size": "1324.99"}], "asks": [{"price": "0.999", "size": "22324"}], "event_type": "book", "last_trade_price": ""}, {"market": "0x3935226f1baa202667795b3a558d26fb0a9ae894a482676d34820bfb1b9b4edd", "asset_id": "80071381584983995567060219264871699619214990229460921095601419271143281499406", "timestamp": "1769384344636", "hash": "b7b5c3927a19ecc08885cc3201a3b26445929c7a", "bids": [{"price": "0.001", "size": "18906"}, {"price": "0.002", "size": "4015"}, {"price": "0.003", "size": "71.62"}], "asks": [{"price": "0.999", "size": "3869"}, {"price": "0.998", "size": "1250"}, {"price": "0.997", "size": "1406.63"}, {"price": "0.994", "size": "200"}, {"price": "0.993", "size": "9.77"}, {"price": "0.99", "size": "5500"}, {"price": "0.98", "size": "2200"}, {"price": "0.979", "size": "8.81"}, {"price": "0.95", "size": "30"}, {"price": "0.949", "size": "39"}, {"price": "0.933", "size": "5506"}, {"price": "0.932", "size": "7.77"}, {"price": "0.9", "size": "360"}, {"price": "0.85", "size": "776.66"}, {"price": "0.8", "size": "660"}, {"price": "0.799", "size": "198.23"}, {"price": "0.798", "size": "5.88"}, {"price": "0.75", "size": "212"}, {"price": "0.7", "size": "336.66"}, {"price": "0.699", "size": "100"}, {"price": "0.698", "size": "50"}, {"price": "0.66", "size": "50"}, {"price": "0.65", "size": "68.57"}, {"price": "0.6", "size": "50"}, {"price": "0.576", "size": "142"}, {"price": "0.528", "size": "5"}, {"price": "0.523", "size": "33"}, {"price": "0.522", "size": "20"}, {"price": "0.069", "size": "10.58"}, {"price": "0.059", "size": "167.3"}, {"price": "0.058", "size": "235.56"}, {"price": "0.05", "size": "10.57"}, {"price": "0.005", "size": "0.99"}], "event_type": "book", "last_trade_price": ""}, {"market": "0x306bbce53f9a77906b9a928d52728bdee2e48f3354d19a9d6f0db7c9a1d4230d", "asset_id": "64957256704343867164459890398860992515731454967968064924053896034568618595733", "timestamp": "1769384251912", "hash": "2599c0e5a263637b19179537f47a8f36832c78ed", "bids": [{"price": "0.001", "size": "3858.04"}, {"price": "0.002", "size": "1250"}, {"price": "0.003", "size": "1406.65"}, {"price": "0.006", "size": "200"}, {"price": "0.007", "size": "9.8"}, {"price": "0.01", "size": "5500"}, {"price": "0.02", "size": "2200"}, {"price": "0.021", "size": "6.93"}, {"price": "0.05", "size": "30"}, {"price": "0.051", "size": "39"}, {"price": "0.052", "size": "10.46"}, {"price": "0.09", "size": "700"}, {"price": "0.091", "size": "3296"}, {"price": "0.093", "size": "3269"}, {"price": "0.094", "size": "4968"}, {"price": "0.14", "size": "242.85"}, {"price": "0.141", "size": "1734"}, {"price": "0.19", "size": "168.42"}, {"price": "0.192", "size": "1232"}, {"price": "0.193", "size": "6.27"}, {"price": "0.24", "size": "116.66"}, {"price": "0.244", "size": "109"}, {"price": "0.245", "size": "499.99"}, {"price": "0.28", "size": "142.85"}, {"price": "0.301", "size": "250"}, {"price": "0.33", "size": "72.72"}, {"price": "0.38", "size": "177.63"}, {"price": "0.43", "size": "5"}, {"price": "0.431", "size": "23"}, {"price": "0.437", "size": "10"}, {"price": "0.438", "size": "20"}, {"price": "0.819", "size": "100"}, {"price": "0.82", "size": "100"}, {"price": "0.876", "size": "100"}, {"price": "0.882", "size": "60"}, {"price": "0.918", "size": "100"}, {"price": "0.919", "size": "20"}, {"price": "0.923", "size": "20"}, {"price": "0.924", "size": "2.66"}, {"price": "0.931", "size": "149.78"}, {"price": "0.932", "size": "59.89"}], "asks": [{"price": "0.999", "size": "23441"}, {"price": "0.998", "size": "666"}, {"price": "0.997", "size": "250"}, {"price": "0.996", "size": "50"}, {"price": "0.979", "size": "1858.59"}, {"price": "0.963", "size": "1000"}, {"price": "0.959", "size": "20"}, {"price": "0.947", "size": "1149.78"}, {"price": "0.946", "size": "325.93"}], "event_type": "book", "last_trade_price": "0.068"}]}
{"_local_timestamp": "2026-01-25T23:40:59.566254+00:00", "data": {"market": "0xd25c820d3aee1c735c0fa62c36f4905632ab8c6988653b5b4134593b3209eb7f", "price_changes": [{"asset_id": "45361184347486002884792387151438756924785609968030585696129487864334578884255", "price": "0.05", "size": "4241", "side": "BUY", "hash": "1845cf6c1ba482edf49edbc49791136990b6bfbe", "best_bid": "0.6", "best_ask": "0.67"}, {"asset_id": "91117078941733659645786554099775611998962677612187928648088119165893475827434", "price": "0.95", "size": "4241", "side": "SELL", "hash": "25bbbc73d220c15937b055b3ea2c2af7301d2de6", "best_bid": "0.33", "best_ask": "0.4"}], "timestamp": "1769384459438", "event_type": "price_change"}}
{"_local_timestamp": "2026-01-25T23:40:59.575800+00:00", "data": {"market": "0xd25c820d3aee1c735c0fa62c36f4905632ab8c6988653b5b4134593b3209eb7f", "price_changes": [{"asset_id": "45361184347486002884792387151438756924785609968030585696129487864334578884255", "price": "0.07", "size": "1214.28", "side": "BUY", "hash": "5192845db344c8e6a87709c2cd3a4d83e7ba9df6", "best_bid": "0.6", "best_ask": "0.67"}, {"asset_id": "91117078941733659645786554099775611998962677612187928648088119165893475827434", "price": "0.93", "size": "1214.28", "side": "SELL", "hash": "3ac4fe75167fd5518bc1dea1ed4700b76f3a9c44", "best_bid": "0.33", "best_ask": "0.4"}], "timestamp": "1769384459440", "event_type": "price_change"}}
{"_local_timestamp": "2026-01-25T23:41:06.832746+00:00", "data": {"market": "0x405b6e3ce8caf18dea56ec418ea5a5c715f43aad946059e3eb7e3d1281698a78", "price_changes": [{"asset_id": "2350235314632053038507062516507369036092528887799666119386073644944240496673", "price": "0.001", "size": "29244.32", "side": "BUY", "hash": "c1bb5c2256b06ac27d6b92a65bebd7130f36cee9", "best_bid": "0.003", "best_ask": "0.004"}, {"asset_id": "24373928341866408058552921472563928863071297280035754284253945296860184628420", "price": "0.999", "size": "29244.32", "side": "SELL", "hash": "2e01d191dc42f72ac97f845ced161fd6e8193cfe", "best_bid": "0.996", "best_ask": "0.997"}], "timestamp": "1769384466645", "event_type": "price_change"}}
{"_local_timestamp": "2026-01-25T23:41:07.001541+00:00", "data": {"market": "0x0eada57dcf53965a321f61c9dc6adb655367fabeb1f2ecbe7746f3f1a6ff7769", "price_changes": [{"asset_id": "88775412427564636095391917176836120951442159831179966305257669968799086969217", "price": "0.001", "size": "23042", "side": "BUY", "hash": "581492da2da1b6a014f2d345f86d3597fbf460c2", "best_bid": "0.002", "best_ask": "0.003"}, {"asset_id": "93593125008177926269164142727030950699068997099893975938000261506053151609883", "price": "0.999", "size": "23042", "side": "SELL", "hash": "ac5ea0482a18c8b1580e078bd9e3afe288b199b5", "best_bid": "0.997", "best_ask": "0.998"}], "timestamp": "1769384466653", "event_type": "price_change"}}
{"_local_timestamp": "2026-01-25T23:41:07.893148+00:00", "data": {"market": "0x1fe1788d96d4c98e242549f91baf0de29eaf3b1545b5e2dda1d8714a3faf5305", "price_changes": [{"asset_id": "30944797740926340411025345169348106947975350930232142082675991513705266362329", "price": "0.02", "size": "0", "side": "SELL", "hash": "44d2b6e48cec772671f32be8918127d2539d4b02", "best_bid": "0.002", "best_ask": "0.003"}, {"asset_id": "85121409960340786807237728711169263074482548425773836042297909052960286277119", "price": "0.98", "size": "0", "side": "BUY", "hash": "aaf8bdb8c0276ad4d39944abd660f3fffd274c1c", "best_bid": "0.997", "best_ask": "0.998"}], "timestamp": "1769384467822", "event_type": "price_change"}}
{"_local_timestamp": "2026-01-25T23:41:08.110834+00:00", "data": {"market": "0x1fe1788d96d4c98e242549f91baf0de29eaf3b1545b5e2dda1d8714a3faf5305", "price_changes": [{"asset_id": "30944797740926340411025345169348106947975350930232142082675991513705266362329", "price": "0.02", "size": "20.96", "side": "SELL", "hash": "39ec4d08bd5c9dd2020e68017fe8bf5a4c31df15", "best_bid": "0.002", "best_ask": "0.003"}, {"asset_id": "85121409960340786807237728711169263074482548425773836042297909052960286277119", "price": "0.98", "size": "20.96", "side": "BUY", "hash": "ce609cc2976ebe7d0461568051c22c24fdb66b7a", "best_bid": "0.997", "best_ask": "0.998"}], "timestamp": "1769384468021", "event_type": "price_change"}}
{"_local_timestamp": "2026-01-25T23:41:08.230407+00:00", "data": {"market": "0x96bc24f519f3008b984b623dfacfa6b87599381ba6afdbd36a576d0d85c4a59c", "price_changes": [{"asset_id": "37234028100441924867078516219629684611507504332898623831670509973866359367709", "price": "0.552", "size": "10", "side": "BUY", "hash": "fc23b802a2d37c96c11feab1a28a29e1489e1db7", "best_bid": "0.997", "best_ask": "0.999"}, {"asset_id": "48733707571584348634287808682190901692810422881953520223982749265958667182900", "price": "0.448", "size": "10", "side": "SELL", "hash": "6ba5b8b8912abf006d83e438175aadee2ba1a98b", "best_bid": "0.001", "best_ask": "0.003"}], "timestamp": "1769384468160", "event_type": "price_change"}}
{"_local_timestamp": "2026-01-25T23:41:09.652731+00:00", "data": {"market": "0xd25c820d3aee1c735c0fa62c36f4905632ab8c6988653b5b4134593b3209eb7f", "price_changes": [{"asset_id": "45361184347486002884792387151438756924785609968030585696129487864334578884255", "price": "0.25", "size": "100", "side": "BUY", "hash": "ad4afb1c7e29f39e8b41c20de43a90f1ea870cc7", "best_bid": "0.6", "best_ask": "0.67"}, {"asset_id": "91117078941733659645786554099775611998962677612187928648088119165893475827434", "price": "0.75", "size": "100", "side": "SELL", "hash": "6fe1cc56f52bb7fc0dd7fc714bbec2b3a8e9a9bf", "best_bid": "0.33", "best_ask": "0.4"}], "timestamp": "1769384469563", "event_type": "price_change"}}
{"_local_timestamp": "2026-01-25T23:41:09.655279+00:00", "data": {"market": "0xd25c820d3aee1c735c0fa62c36f4905632ab8c6988653b5b4134593b3209eb7f", "price_changes": [{"asset_id": "45361184347486002884792387151438756924785609968030585696129487864334578884255", "price": "0.27", "size": "74.07", "side": "BUY", "hash": "ad4afb1c7e29f39e8b41c20de43a90f1ea870cc7", "best_bid": "0.6", "best_ask": "0.67"}, {"asset_id": "91117078941733659645786554099775611998962677612187928648088119165893475827434", "price": "0.73", "size": "74.07", "side": "SELL", "hash": "6fe1cc56f52bb7fc0dd7fc714bbec2b3a8e9a9bf", "best_bid": "0.33", "best_ask": "0.4"}], "timestamp": "1769384469563", "event_type": "price_change"}}
{"_local_timestamp": "2026-01-25T23:41:18.480725+00:00", "data": {"market": "0xbbd623c4191ca76dec466507375d6df85b403b7e14f9cbd3d09f2c450ae0cd96", "price_changes": [{"asset_id": "86141088804897222236928959539148501008650371218692800935714557867410378164931", "price": "0.21", "size": "100", "side": "BUY", "hash": "d656fa361cead5ce7c77d087adf40836ef412302", "best_bid": "0.7", "best_ask": "0.73"}, {"asset_id": "86988864427600902662654729368237087316370077858847155604307346968813506081632", "price": "0.79", "size": "100", "side": "SELL", "hash": "8d5a3e20b01c655649e0b4f0a090238c385f094f", "best_bid": "0.27", "best_ask": "0.3"}], "timestamp": "1769384478348", "event_type": "price_change"}}
{"_local_timestamp": "2026-01-25T23:41:18.616867+00:00", "data": {"market": "0x96bc24f519f3008b984b623dfacfa6b87599381ba6afdbd36a576d0d85c4a59c", "price_changes": [{"asset_id": "37234028100441924867078516219629684611507504332898623831670509973866359367709", "price": "0.552", "size": "0", "side": "BUY", "hash": "c7aa817b735aaecf7931d69ba2a612b848feee7d", "best_bid": "0.997", "best_ask": "0.999"}, {"asset_id": "48733707571584348634287808682190901692810422881953520223982749265958667182900", "price": "0.448", "size": "0", "side": "SELL", "hash": "3a49d6fd472e3d603a318b4f18071e69e3c05f1e", "best_bid": "0.001", "best_ask": "0.003"}], "timestamp": "1769384478544", "event_type": "price_change"}}
{"_local_timestamp": "2026-01-25T23:41:18.624323+00:00", "data": {"market": "0xd25c820d3aee1c735c0fa62c36f4905632ab8c6988653b5b4134593b3209eb7f", "price_changes": [{"asset_id": "45361184347486002884792387151438756924785609968030585696129487864334578884255", "price": "0.55", "size": "45.5", "side": "BUY", "hash": "387bc3b29c9208962782681ae17f87e929b1220f", "best_bid": "0.6", "best_ask": "0.67"}, {"asset_id": "91117078941733659645786554099775611998962677612187928648088119165893475827434", "price": "0.45", "size": "45.5", "side": "SELL", "hash": "9c8a4abde48c120ad802131f3bb8126353a6186a", "best_bid": "0.33", "best_ask": "0.4"}], "timestamp": "1769384478555", "event_type": "price_change"}}
{"_local_timestamp": "2026-01-25T23:41:18.667161+00:00", "data": {"market": "0xbbd623c4191ca76dec466507375d6df85b403b7e14f9cbd3d09f2c450ae0cd96", "price_changes": [{"asset_id": "86141088804897222236928959539148501008650371218692800935714557867410378164931", "price": "0.61", "size": "20", "side": "BUY", "hash": "9ae54184bd4549d160e11bec4b50ae2cf05e5991", "best_bid": "0.7", "best_ask": "0.73"}, {"asset_id": "86988864427600902662654729368237087316370077858847155604307346968813506081632", "price": "0.39", "size": "20", "side": "SELL", "hash": "ea254b4ba2502b7e278bfd0d137b7e3e5252829f", "best_bid": "0.27", "best_ask": "0.3"}], "timestamp": "1769384478579", "event_type": "price_change"}}
{"_local_timestamp": "2026-01-25T23:41:18.668338+00:00", "data": {"market": "0xba8add06562a7bfd4fdd8f0a1882b5e2596540bd61c67a32359487694838f0a5", "price_changes": [{"asset_id": "62853431799112511763784693741363968903595954956498708214160770466188703343964", "price": "0.66", "size": "20", "side": "BUY", "hash": "42ae69d9ad33970f76be9ad7c72dd932c33aaeac", "best_bid": "0.76", "best_ask": "0.78"}, {"asset_id": "7221299913764832338348128493889748182769672206962167820297840741811689706878", "price": "0.34", "size": "20", "side": "SELL", "hash": "363c330d65ad202e1c18dabcc7af7567f2ea97a8", "best_bid": "0.22", "best_ask": "0.24"}], "timestamp": "1769384478602", "event_type": "price_change"}}
{"_local_timestamp": "2026-01-25T23:41:18.688297+00:00", "data": {"market": "0x306bbce53f9a77906b9a928d52728bdee2e48f3354d19a9d6f0db7c9a1d4230d", "price_changes": [{"asset_id": "64957256704343867164459890398860992515731454967968064924053896034568618595733", "price": "0.83", "size": "20", "side": "BUY", "hash": "bdef375b460f0e3cf66aa40c25324d6f29c9629e", "best_bid": "0.932", "best_ask": "0.946"}, {"asset_id": "34335512241828535299853623975656484642594791501285631499713239174540168255596", "price": "0.17", "size": "20", "side": "SELL", "hash": "96714c72b554b088962fedd779a325b421f5f2e0", "best_bid": "0.054", "best_ask": "0.068"}], "timestamp": "1769384478623", "event_type": "price_change"}}
{"_local_timestamp": "2026-01-25T23:41:18.765522+00:00", "data": {"market": "0xd25c820d3aee1c735c0fa62c36f4905632ab8c6988653b5b4134593b3209eb7f", "price_changes": [{"asset_id": "45361184347486002884792387151438756924785609968030585696129487864334578884255", "price": "0.47", "size": "0", "side": "BUY", "hash": "444aee4bc71c9bfc48befc4c03ed6cbf0249187d", "best_bid": "0.6", "best_ask": "0.67"}, {"asset_id": "91117078941733659645786554099775611998962677612187928648088119165893475827434", "price": "0.53", "size": "0", "side": "SELL", "hash": "9485103817c0a5603e788c1622b5b8201372119b", "best_bid": "0.33", "best_ask": "0.4"}], "timestamp": "1769384478694", "event_type": "price_change"}}
{"_local_timestamp": "2026-01-25T23:41:18.788448+00:00", "data": {"market": "0x15a99b7ac17e9cb8972f852ee2798dfba6fc977a53ff3bf2f99527305e690411", "price_changes": [{"asset_id": "16326880523082047267449204000618069867645781949928810368805306223220924298747", "price": "0.411", "size": "0", "side": "BUY", "hash": "6e7b8133dcd9ada867cdcf4f10306659eee595fa", "best_bid": "0.998", "best_ask": "0.999"}, {"asset_id": "67804243531391989346875449219790559386739387253247872134999423217366474323425", "price": "0.589", "size": "0", "side": "SELL", "hash": "d0dff9a03cf0f56ae0c0e54ae66f830769b16914", "best_bid": "0.001", "best_ask": "0.002"}], "timestamp": "1769384478710", "event_type": "price_change"}}
{"_local_timestamp": "2026-01-25T23:41:18.791583+00:00", "data": {"market": "0x15a99b7ac17e9cb8972f852ee2798dfba6fc977a53ff3bf2f99527305e690411", "price_changes": [{"asset_id": "16326880523082047267449204000618069867645781949928810368805306223220924298747", "price": "0.822", "size": "0", "side": "BUY", "hash": "6e7b8133dcd9ada867cdcf4f10306659eee595fa", "best_bid": "0.998", "best_ask": "0.999"}, {"asset_id": "67804243531391989346875449219790559386739387253247872134999423217366474323425", "price": "0.178", "size": "0", "side": "SELL", "hash": "d0dff9a03cf0f56ae0c0e54ae66f830769b16914", "best_bid": "0.001", "best_ask": "0.002"}], "timestamp": "1769384478710", "event_type": "price_change"}}
{"_local_timestamp": "2026-01-25T23:41:18.855893+00:00", "data": {"market": "0xd25c820d3aee1c735c0fa62c36f4905632ab8c6988653b5b4134593b3209eb7f", "price_changes": [{"asset_id": "91117078941733659645786554099775611998962677612187928648088119165893475827434", "price": "0.44", "size": "9.5", "side": "SELL", "hash": "5d0d2a9ab0003884cdad96791f98613ccd6d96ca", "best_bid": "0.33", "best_ask": "0.4"}, {"asset_id": "45361184347486002884792387151438756924785609968030585696129487864334578884255", "price": "0.56", "size": "9.5", "side": "BUY", "hash": "a7c62d9fbe2167c399a0a63c1f1b02c53363ec12", "best_bid": "0.6", "best_ask": "0.67"}], "timestamp": "1769384478776", "event_type": "price_change"}}
{"_local_timestamp": "2026-01-25T23:41:20.812176+00:00", "data": {"market": "0xbbd623c4191ca76dec466507375d6df85b403b7e14f9cbd3d09f2c450ae0cd96", "price_changes": [{"asset_id": "86141088804897222236928959539148501008650371218692800935714557867410378164931", "price": "0.21", "size": "105.87", "side": "BUY", "hash": "dc6502a4c854b9518da7a07ded54a6f477e953c8", "best_bid": "0.7", "best_ask": "0.73"}, {"asset_id": "86988864427600902662654729368237087316370077858847155604307346968813506081632", "price": "0.79", "size": "105.87", "side": "SELL", "hash": "f0f0306c32df0efed05256a388db41e961689d81", "best_bid": "0.27", "best_ask": "0.3"}], "timestamp": "1769384480736", "event_type": "price_change"}}
{"_local_timestamp": "2026-01-25T23:41:22.997869+00:00", "data": {"market": "0xd25c820d3aee1c735c0fa62c36f4905632ab8c6988653b5b4134593b3209eb7f", "price_changes": [{"asset_id": "45361184347486002884792387151438756924785609968030585696129487864334578884255", "price": "0.48", "size": "0", "side": "BUY", "hash": "5257844869c7b61827ccc5d95ea823481a36feea", "best_bid": "0.6", "best_ask": "0.67"}, {"asset_id": "91117078941733659645786554099775611998962677612187928648088119165893475827434", "price": "0.52", "size": "0", "side": "SELL", "hash": "06fe5670c35d34d3a11cc1e5655a4a4ac0ae04db", "best_bid": "0.33", "best_ask": "0.4"}], "timestamp": "1769384482918", "event_type": "price_change"}}
{"_local_timestamp": "2026-01-25T23:41:22.999679+00:00", "data": {"market": "0x15a99b7ac17e9cb8972f852ee2798dfba6fc977a53ff3bf2f99527305e690411", "price_changes": [{"asset_id": "16326880523082047267449204000618069867645781949928810368805306223220924298747", "price": "0.823", "size": "0", "side": "BUY", "hash": "f394d81a5f3524d93188ec356e005d9f60f38daf", "best_bid": "0.998", "best_ask": "0.999"}, {"asset_id": "67804243531391989346875449219790559386739387253247872134999423217366474323425", "price": "0.177", "size": "0", "side": "SELL", "hash": "0121fe894fe088c9003e461896c11edd3a58d490", "best_bid": "0.001", "best_ask": "0.002"}], "timestamp": "1769384482918", "event_type": "price_change"}}
{"_local_timestamp": "2026-01-25T23:41:23.001042+00:00", "data": {"market": "0x96bc24f519f3008b984b623dfacfa6b87599381ba6afdbd36a576d0d85c4a59c", "price_changes": [{"asset_id": "37234028100441924867078516219629684611507504332898623831670509973866359367709", "price": "0.553", "size": "0", "side": "BUY", "hash": "a1ebf61578d0c957daa8e39684e987291cf77cdc", "best_bid": "0.997", "best_ask": "0.999"}, {"asset_id": "48733707571584348634287808682190901692810422881953520223982749265958667182900", "price": "0.447", "size": "0", "side": "SELL", "hash": "05e7135a9f9a64e13a574b98149006302453df2c", "best_bid": "0.001", "best_ask": "0.003"}], "timestamp": "1769384482918", "event_type": "price_change"}}
{"_local_timestamp": "2026-01-25T23:41:23.020300+00:00", "data": {"market": "0xd25c820d3aee1c735c0fa62c36f4905632ab8c6988653b5b4134593b3209eb7f", "price_changes": [{"asset_id": "45361184347486002884792387151438756924785609968030585696129487864334578884255", "price": "0.44", "size": "20", "side": "BUY", "hash": "cd77ed21004726822ddc3e452e35036ffa4d4a4e", "best_bid": "0.6", "best_ask": "0.67"}, {"asset_id": "91117078941733659645786554099775611998962677612187928648088119165893475827434", "price": "0.56", "size": "20", "side": "SELL", "hash": "1b7402d931f17849973a125ec970e26be1bb976c", "best_bid": "0.33", "best_ask": "0.4"}], "timestamp": "1769384482952", "event_type": "price_change"}}
{"_local_timestamp": "2026-01-25T23:41:23.022401+00:00", "data": {"market": "0x96bc24f519f3008b984b623dfacfa6b87599381ba6afdbd36a576d0d85c4a59c", "price_changes": [{"asset_id": "37234028100441924867078516219629684611507504332898623831670509973866359367709", "price": "0.551", "size": "20", "side": "BUY", "hash": "9522718efd17b7abd21cef6769acd11cc43251c8", "best_bid": "0.997", "best_ask": "0.999"}, {"asset_id": "48733707571584348634287808682190901692810422881953520223982749265958667182900", "price": "0.449", "size": "20", "side": "SELL", "hash": "f67de506ccd51c050130af8419856d42809d3a83", "best_bid": "0.001", "best_ask": "0.003"}], "timestamp": "1769384482952", "event_type": "price_change"}}
{"_local_timestamp": "2026-01-25T23:41:23.025333+00:00", "data": {"market": "0x15a99b7ac17e9cb8972f852ee2798dfba6fc977a53ff3bf2f99527305e690411", "price_changes": [{"asset_id": "16326880523082047267449204000618069867645781949928810368805306223220924298747", "price": "0.821", "size": "20", "side": "BUY", "hash": "a344c2c610df16c76f947efdee94cdfd913b8aac", "best_bid": "0.998", "best_ask": "0.999"}, {"asset_id": "67804243531391989346875449219790559386739387253247872134999423217366474323425", "price": "0.179", "size": "20", "side": "SELL", "hash": "fe8e6e21bb815fc12564d149cd93385f1a81f93d", "best_bid": "0.001", "best_ask": "0.002"}], "timestamp": "1769384482952", "event_type": "price_change"}}
{"_local_timestamp": "2026-01-25T23:41:39.359468+00:00", "data": {"market": "0xd25c820d3aee1c735c0fa62c36f4905632ab8c6988653b5b4134593b3209eb7f", "price_changes": [{"asset_id": "45361184347486002884792387151438756924785609968030585696129487864334578884255", "price": "0.56", "size": "77.35", "side": "BUY", "hash": "a49327f2a415533e715ab0e6d815cfea51a82fa4", "best_bid": "0.6", "best_ask": "0.67"}, {"asset_id": "91117078941733659645786554099775611998962677612187928648088119165893475827434", "price": "0.44", "size": "77.35", "side": "SELL", "hash": "2e3779f545611930b6e3210b96c60f1dabad1fa3", "best_bid": "0.33", "best_ask": "0.4"}], "timestamp": "1769384499281", "event_type": "price_change"}}
{"_local_timestamp": "2026-01-25T23:41:50.913392+00:00", "data": {"market": "0x15a99b7ac17e9cb8972f852ee2798dfba6fc977a53ff3bf2f99527305e690411", "price_changes": [{"asset_id": "16326880523082047267449204000618069867645781949928810368805306223220924298747", "price": "0.409", "size": "0", "side": "BUY", "hash": "c6ffe4f7a8451a09acf48d72a01fb19cec18cd11", "best_bid": "0.998", "best_ask": "0.999"}, {"asset_id": "67804243531391989346875449219790559386739387253247872134999423217366474323425", "price": "0.591", "size": "0", "side": "SELL", "hash": "1eb0c7af48e99ee21b951d17e1fb7011925c9364", "best_bid": "0.001", "best_ask": "0.002"}], "timestamp": "1769384510755", "event_type": "price_change"}}
{"_local_timestamp": "2026-01-25T23:41:50.917360+00:00", "data": {"market": "0x405b6e3ce8caf18dea56ec418ea5a5c715f43aad946059e3eb7e3d1281698a78", "price_changes": [{"asset_id": "24373928341866408058552921472563928863071297280035754284253945296860184628420", "price": "0.403", "size": "4033", "side": "BUY", "hash": "5e9a9b9a0e4f753372e5fb6a0f5e36f10056d0f4", "best_bid": "0.996", "best_ask": "0.997"}, {"asset_id": "2350235314632053038507062516507369036092528887799666119386073644944240496673", "price": "0.597", "size": "4033", "side": "SELL", "hash": "4e98c017a8f53f194e2384897146a0133c283884", "best_bid": "0.003", "best_ask": "0.004"}], "timestamp": "1769384510754", "event_type": "price_change"}}
{"_local_timestamp": "2026-01-25T23:41:50.918488+00:00", "data": {"market": "0xba8add06562a7bfd4fdd8f0a1882b5e2596540bd61c67a32359487694838f0a5", "price_changes": [{"asset_id": "62853431799112511763784693741363968903595954956498708214160770466188703343964", "price": "0.2", "size": "290", "side": "BUY", "hash": "40c7a613aab6dc5ad832d6cb714f229e40f9f35f", "best_bid": "0.76", "best_ask": "0.78"}, {"asset_id": "7221299913764832338348128493889748182769672206962167820297840741811689706878", "price": "0.8", "size": "290", "side": "SELL", "hash": "084590aa4ea9207759b814976e9561ebbb4fca6f", "best_bid": "0.22", "best_ask": "0.24"}], "timestamp": "1769384510755", "event_type": "price_change"}}
{"_local_timestamp": "2026-01-25T23:41:52.214538+00:00", "data": {"market": "0x15a99b7ac17e9cb8972f852ee2798dfba6fc977a53ff3bf2f99527305e690411", "price_changes": [{"asset_id": "16326880523082047267449204000618069867645781949928810368805306223220924298747", "price": "0.41", "size": "375", "side": "BUY", "hash": "72e9ab564296ad4cd8bd90e8ca25599709f80c25", "best_bid": "0.998", "best_ask": "0.999"}, {"asset_id": "67804243531391989346875449219790559386739387253247872134999423217366474323425", "price": "0.59", "size": "375", "side": "SELL", "hash": "c0ea778e4ae56ad605b7ef2e8c520ac62c6ff093", "best_bid": "0.001", "best_ask": "0.002"}], "timestamp": "1769384511728", "event_type": "price_change"}}
{"_local_timestamp": "2026-01-25T23:41:52.311438+00:00", "data": {"market": "0xba8add06562a7bfd4fdd8f0a1882b5e2596540bd61c67a32359487694838f0a5", "price_changes": [{"asset_id": "62853431799112511763784693741363968903595954956498708214160770466188703343964", "price": "0.19", "size": "1192", "side": "BUY", "hash": "59b39938751a3c550bd5719cb6d8b7279ee9b88b", "best_bid": "0.76", "best_ask": "0.78"}, {"asset_id": "7221299913764832338348128493889748182769672206962167820297840741811689706878", "price": "0.81", "size": "1192", "side": "SELL", "hash": "8e19802423c1c6901d177d6ada9e6f029496380e", "best_bid": "0.22", "best_ask": "0.24"}], "timestamp": "1769384511732", "event_type": "price_change"}}
{"_local_timestamp": "2026-01-25T23:41:52.312414+00:00", "data": {"market": "0x405b6e3ce8caf18dea56ec418ea5a5c715f43aad946059e3eb7e3d1281698a78", "price_changes": [{"asset_id": "24373928341866408058552921472563928863071297280035754284253945296860184628420", "price": "0.404", "size": "360", "side": "BUY", "hash": "9bf7e53fa9785f4a45d41cb62f12ddefb22bbd9c", "best_bid": "0.996", "best_ask": "0.997"}, {"asset_id": "2350235314632053038507062516507369036092528887799666119386073644944240496673", "price": "0.596", "size": "360", "side": "SELL", "hash": "6ab9aa769d191f1d6bda4adc1170a124456c20fb", "best_bid": "0.003", "best_ask": "0.004"}], "timestamp": "1769384511732", "event_type": "price_change"}}
{"_local_timestamp": "2026-01-25T23:41:59.741434+00:00", "data": {"market": "0xd25c820d3aee1c735c0fa62c36f4905632ab8c6988653b5b4134593b3209eb7f", "price_changes": [{"asset_id": "45361184347486002884792387151438756924785609968030585696129487864334578884255", "price": "0.01", "size": "5511.18", "side": "BUY", "hash": "342579f13d82090b3271b70d03ba99a2d8cd0646", "best_bid": "0.6", "best_ask": "0.67"}, {"asset_id": "91117078941733659645786554099775611998962677612187928648088119165893475827434", "price": "0.99", "size": "5511.18", "side": "SELL", "hash": "4181f0da00204ce66049a2ca9dc538ba29b41d6c", "best_bid": "0.33", "best_ask": "0.4"}], "timestamp": "1769384519669", "event_type": "price_change"}}
{"_local_timestamp": "2026-01-25T23:42:06.836209+00:00", "data": {"market": "0xd25c820d3aee1c735c0fa62c36f4905632ab8c6988653b5b4134593b3209eb7f", "price_changes": [{"asset_id": "45361184347486002884792387151438756924785609968030585696129487864334578884255", "price": "0.6", "size": "25", "side": "BUY", "hash": "85e7398fd11c23ad9d05a76486e0483b3e368261", "best_bid": "0.6", "best_ask": "0.67"}, {"asset_id": "91117078941733659645786554099775611998962677612187928648088119165893475827434", "price": "0.4", "size": "25", "side": "SELL", "hash": "dd2ada35b9b367c8a910a90c755b534e0389e4ad", "best_bid": "0.33", "best_ask": "0.4"}], "timestamp": "1769384526744", "event_type": "price_change"}}
{"_local_timestamp": "2026-01-25T23:42:06.955448+00:00", "data": {"market": "0xd25c820d3aee1c735c0fa62c36f4905632ab8c6988653b5b4134593b3209eb7f", "price_changes": [{"asset_id": "45361184347486002884792387151438756924785609968030585696129487864334578884255", "price": "0.31", "size": "0", "side": "BUY", "hash": "48ea364af8e585430977d77287499cbf8c3cdc12", "best_bid": "0.6", "best_ask": "0.67"}, {"asset_id": "91117078941733659645786554099775611998962677612187928648088119165893475827434", "price": "0.69", "size": "0", "side": "SELL", "hash": "d9304b9aff6e72d12d19edff42a2e58a06f3f738", "best_bid": "0.33", "best_ask": "0.4"}], "timestamp": "1769384526875", "event_type": "price_change"}}
{"_local_timestamp": "2026-01-25T23:42:06.956419+00:00", "data": {"market": "0x96bc24f519f3008b984b623dfacfa6b87599381ba6afdbd36a576d0d85c4a59c", "price_changes": [{"asset_id": "37234028100441924867078516219629684611507504332898623831670509973866359367709", "price": "0.55", "size": "0", "side": "BUY", "hash": "95e20beb7fb50f551b6c676443dc33568e56bedc", "best_bid": "0.997", "best_ask": "0.999"}, {"asset_id": "48733707571584348634287808682190901692810422881953520223982749265958667182900", "price": "0.45", "size": "0", "side": "SELL", "hash": "24ca1cee6f5e05088a06cc88134fe9b2222cdeac", "best_bid": "0.001", "best_ask": "0.003"}], "timestamp": "1769384526875", "event_type": "price_change"}}
{"_local_timestamp": "2026-01-25T23:42:06.957299+00:00", "data": {"market": "0x1fe1788d96d4c98e242549f91baf0de29eaf3b1545b5e2dda1d8714a3faf5305", "price_changes": [{"asset_id": "85121409960340786807237728711169263074482548425773836042297909052960286277119", "price": "0.748", "size": "0", "side": "BUY", "hash": "401da770520b43964eedcf39331307434cb13fc7", "best_bid": "0.997", "best_ask": "0.998"}, {"asset_id": "30944797740926340411025345169348106947975350930232142082675991513705266362329", "price": "0.252", "size": "0", "side": "SELL", "hash": "d8e4498cba3495580a86e589f30b8469a143005e", "best_bid": "0.002", "best_ask": "0.003"}], "timestamp": "1769384526875", "event_type": "price_change"}}
{"_local_timestamp": "2026-01-25T23:42:06.958148+00:00", "data": {"market": "0x0eada57dcf53965a321f61c9dc6adb655367fabeb1f2ecbe7746f3f1a6ff7769", "price_changes": [{"asset_id": "93593125008177926269164142727030950699068997099893975938000261506053151609883", "price": "0.479", "size": "0", "side": "BUY", "hash": "57a05918344eb64cc9a84fcf344a5682a55ff0cb", "best_bid": "0.997", "best_ask": "0.998"}, {"asset_id": "88775412427564636095391917176836120951442159831179966305257669968799086969217", "price": "0.521", "size": "0", "side": "SELL", "hash": "a6ea82ec458448160c6ea21dbf3ef79e911a909f", "best_bid": "0.002", "best_ask": "0.003"}], "timestamp": "1769384526875", "event_type": "price_change"}}
{"_local_timestamp": "2026-01-25T23:42:07.077050+00:00", "data": {"market": "0x1fe1788d96d4c98e242549f91baf0de29eaf3b1545b5e2dda1d8714a3faf5305", "price_changes": [{"asset_id": "85121409960340786807237728711169263074482548425773836042297909052960286277119", "price": "0.404", "size": "66", "side": "BUY", "hash": "6cf361c781d97defad1a71b0181a9b2e8a41647f", "best_bid": "0.997", "best_ask": "0.998"}, {"asset_id": "30944797740926340411025345169348106947975350930232142082675991513705266362329", "price": "0.596", "size": "66", "side": "SELL", "hash": "3430eaeca37ffdc1e14a401e3f90b2cc0c6c20c3", "best_bid": "0.002", "best_ask": "0.003"}], "timestamp": "1769384526993", "event_type": "price_change"}}
{"_local_timestamp": "2026-01-25T23:42:07.077972+00:00", "data": {"market": "0x96bc24f519f3008b984b623dfacfa6b87599381ba6afdbd36a576d0d85c4a59c", "price_changes": [{"asset_id": "37234028100441924867078516219629684611507504332898623831670509973866359367709", "price": "0.552", "size": "23", "side": "BUY", "hash": "fde16190620a628eb3e5e634cba917d0edc90e5d", "best_bid": "0.997", "best_ask": "0.999"}, {"asset_id": "48733707571584348634287808682190901692810422881953520223982749265958667182900", "price": "0.448", "size": "23", "side": "SELL", "hash": "4bbe0117a4ff39a1dcb3a964ebedc873d01461ba", "best_bid": "0.001", "best_ask": "0.003"}], "timestamp": "1769384526993", "event_type": "price_change"}}
{"_local_timestamp": "2026-01-25T23:42:07.078830+00:00", "data": {"market": "0xd25c820d3aee1c735c0fa62c36f4905632ab8c6988653b5b4134593b3209eb7f", "price_changes": [{"asset_id": "45361184347486002884792387151438756924785609968030585696129487864334578884255", "price": "0.45", "size": "10", "side": "BUY", "hash": "22c6a0f8d9c1c575dc78b0fe0a6dfb8737742f93", "best_bid": "0.6", "best_ask": "0.67"}, {"asset_id": "91117078941733659645786554099775611998962677612187928648088119165893475827434", "price": "0.55", "size": "10", "side": "SELL", "hash": "37fab8a9ae1e0b612503ba8d5503bbf2b4262729", "best_bid": "0.33", "best_ask": "0.4"}], "timestamp": "1769384526993", "event_type": "price_change"}}
{"_local_timestamp": "2026-01-25T23:42:07.079731+00:00", "data": {"market": "0x0eada57dcf53965a321f61c9dc6adb655367fabeb1f2ecbe7746f3f1a6ff7769", "price_changes": [{"asset_id": "93593125008177926269164142727030950699068997099893975938000261506053151609883", "price": "0.483", "size": "133", "side": "BUY", "hash": "8f544d5183acd5e92806d0001ce9bde1b74fb6c4", "best_bid": "0.997", "best_ask": "0.998"}, {"asset_id": "88775412427564636095391917176836120951442159831179966305257669968799086969217", "price": "0.517", "size": "133", "side": "SELL", "hash": "d77bca5cafe406e47f872e77ce5733b90deebf58", "best_bid": "0.002", "best_ask": "0.003"}], "timestamp": "1769384526993", "event_type": "price_change"}}
{"_local_timestamp": "2026-01-25T23:42:07.080588+00:00", "data": {"market": "0x1fe1788d96d4c98e242549f91baf0de29eaf3b1545b5e2dda1d8714a3faf5305", "price_changes": [{"asset_id": "85121409960340786807237728711169263074482548425773836042297909052960286277119", "price": "0.75", "size": "10", "side": "BUY", "hash": "ea52a348319aeee5f919d0cb68ea59db0ec849cf", "best_bid": "0.997", "best_ask": "0.998"}, {"asset_id": "30944797740926340411025345169348106947975350930232142082675991513705266362329", "price": "0.25", "size": "10", "side": "SELL", "hash": "a45c61bc42fa1112fa6cea8731aa0af0242dd990", "best_bid": "0.002", "best_ask": "0.003"}], "timestamp": "1769384526994", "event_type": "price_change"}}
{"_local_timestamp": "2026-01-25T23:42:07.081424+00:00", "data": {"market": "0x96bc24f519f3008b984b623dfacfa6b87599381ba6afdbd36a576d0d85c4a59c", "price_changes": [{"asset_id": "37234028100441924867078516219629684611507504332898623831670509973866359367709", "price": "0.552", "size": "33", "side": "BUY", "hash": "bca18231bf9b4fe365a4a9ac4dd3a85b6a784489", "best_bid": "0.997", "best_ask": "0.999"}, {"asset_id": "48733707571584348634287808682190901692810422881953520223982749265958667182900", "price": "0.448", "size": "33", "side": "SELL", "hash": "8e72c4212db95fb1211f21782c73b4de55919504", "best_bid": "0.001", "best_ask": "0.003"}], "timestamp": "1769384526994", "event_type": "price_change"}}
{"_local_timestamp": "2026-01-25T23:42:07.082263+00:00", "data": {"market": "0x0eada57dcf53965a321f61c9dc6adb655367fabeb1f2ecbe7746f3f1a6ff7769", "price_changes": [{"asset_id": "93593125008177926269164142727030950699068997099893975938000261506053151609883", "price": "0.483", "size": "143", "side": "BUY", "hash": "66afd1fcdd312cc47e48adb39f8fc121c1d120ef", "best_bid": "0.997", "best_ask": "0.998"}, {"asset_id": "88775412427564636095391917176836120951442159831179966305257669968799086969217", "price": "0.517", "size": "143", "side": "SELL", "hash": "343e3a2de1d3d8668582087d20ebd39c4b3634f2", "best_bid": "0.002", "best_ask": "0.003"}], "timestamp": "1769384526994", "event_type": "price_change"}}
{"_local_timestamp": "2026-01-25T23:42:07.123839+00:00", "data": {"market": "0x0eada57dcf53965a321f61c9dc6adb655367fabeb1f2ecbe7746f3f1a6ff7769", "price_changes": [{"asset_id": "93593125008177926269164142727030950699068997099893975938000261506053151609883", "price": "0.405", "size": "0", "side": "BUY", "hash": "fd32cb97ee6be70070446a1111374c8d35bbc6d5", "best_bid": "0.997", "best_ask": "0.998"}, {"asset_id": "88775412427564636095391917176836120951442159831179966305257669968799086969217", "price": "0.595", "size": "0", "side": "SELL", "hash": "ac9691516f7ff979a7945be0c91d9f1e862028ce", "best_bid": "0.002", "best_ask": "0.003"}], "timestamp": "1769384527033", "event_type": "price_change"}}
{"_local_timestamp": "2026-01-25T23:42:07.132835+00:00", "data": {"market": "0x1fe1788d96d4c98e242549f91baf0de29eaf3b1545b5e2dda1d8714a3faf5305", "price_changes": [{"asset_id": "85121409960340786807237728711169263074482548425773836042297909052960286277119", "price": "0.749", "size": "0", "side": "BUY", "hash": "8937ba39998521de2531099b720a21127c405308", "best_bid": "0.997", "best_ask": "0.998"}, {"asset_id": "30944797740926340411025345169348106947975350930232142082675991513705266362329", "price": "0.251", "size": "0", "side": "SELL", "hash": "a475f293d38ad39b4ef2b41c7ddb48119f49a81b", "best_bid": "0.002", "best_ask": "0.003"}], "timestamp": "1769384527063", "event_type": "price_change"}}
{"_local_timestamp": "2026-01-25T23:42:07.133896+00:00", "data": {"market": "0x96bc24f519f3008b984b623dfacfa6b87599381ba6afdbd36a576d0d85c4a59c", "price_changes": [{"asset_id": "37234028100441924867078516219629684611507504332898623831670509973866359367709", "price": "0.551", "size": "0", "side": "BUY", "hash": "229a2d06333b5705db9e897bd7958d3245c82fa0", "best_bid": "0.997", "best_ask": "0.999"}, {"asset_id": "48733707571584348634287808682190901692810422881953520223982749265958667182900", "price": "0.449", "size": "0", "side": "SELL", "hash": "d5acd48622176477c5b0aff29ee06af015c49888", "best_bid": "0.001", "best_ask": "0.003"}], "timestamp": "1769384527063", "event_type": "price_change"}}
{"_local_timestamp": "2026-01-25T23:42:07.164674+00:00", "data": {"market": "0x1fe1788d96d4c98e242549f91baf0de29eaf3b1545b5e2dda1d8714a3faf5305", "price_changes": [{"asset_id": "85121409960340786807237728711169263074482548425773836042297909052960286277119", "price": "0.745", "size": "20", "side": "BUY", "hash": "a7e1638e70f05661dcc9b4f133d0481581e6f00f", "best_bid": "0.997", "best_ask": "0.998"}, {"asset_id": "30944797740926340411025345169348106947975350930232142082675991513705266362329", "price": "0.255", "size": "20", "side": "SELL", "hash": "0ce8b550e889ef02660842b4df0b313e512ae142", "best_bid": "0.002", "best_ask": "0.003"}], "timestamp": "1769384527094", "event_type": "price_change"}}
{"_local_timestamp": "2026-01-25T23:42:07.165633+00:00", "data": {"market": "0x96bc24f519f3008b984b623dfacfa6b87599381ba6afdbd36a576d0d85c4a59c", "price_changes": [{"asset_id": "37234028100441924867078516219629684611507504332898623831670509973866359367709", "price": "0.401", "size": "20", "side": "BUY", "hash": "404d1caa0bf43f84001dc0188e511c35537d1e43", "best_bid": "0.997", "best_ask": "0.999"}, {"asset_id": "48733707571584348634287808682190901692810422881953520223982749265958667182900", "price": "0.599", "size": "20", "side": "SELL", "hash": "018f4d2a2c6a6c7ebf34a77caa3e102d4627b7ab", "best_bid": "0.001", "best_ask": "0.003"}], "timestamp": "1769384527094", "event_type": "price_change"}}
{"_local_timestamp": "2026-01-25T23:42:07.274211+00:00", "data": {"market": "0xba8add06562a7bfd4fdd8f0a1882b5e2596540bd61c67a32359487694838f0a5", "price_changes": [{"asset_id": "62853431799112511763784693741363968903595954956498708214160770466188703343964", "price": "0.54", "size": "10", "side": "BUY", "hash": "e912327b2d887e67ca419a12d3085c97e3bafdcf", "best_bid": "0.76", "best_ask": "0.78"}, {"asset_id": "7221299913764832338348128493889748182769672206962167820297840741811689706878", "price": "0.46", "size": "10", "side": "SELL", "hash": "bb22660ab3c5bdbcb1e124588e57bd8c700ad3ac", "best_bid": "0.22", "best_ask": "0.24"}], "timestamp": "1769384527202", "event_type": "price_change"}}
{"_local_timestamp": "2026-01-25T23:42:07.320364+00:00", "data": {"market": "0xd25c820d3aee1c735c0fa62c36f4905632ab8c6988653b5b4134593b3209eb7f", "price_changes": [{"asset_id": "45361184347486002884792387151438756924785609968030585696129487864334578884255", "price": "0.44", "size": "0", "side": "BUY", "hash": "ad1a4f9048c0a7b1fd48a36a1b49eb6912a89d42", "best_bid": "0.6", "best_ask": "0.67"}, {"asset_id": "91117078941733659645786554099775611998962677612187928648088119165893475827434", "price": "0.56", "size": "0", "side": "SELL", "hash": "47f547c8cb00b11ed89b43ae228d5af8635ed4e0", "best_bid": "0.33", "best_ask": "0.4"}], "timestamp": "1769384527247", "event_type": "price_change"}}
{"_local_timestamp": "2026-01-25T23:42:07.321367+00:00", "data": {"market": "0x1fe1788d96d4c98e242549f91baf0de29eaf3b1545b5e2dda1d8714a3faf5305", "price_changes": [{"asset_id": "85121409960340786807237728711169263074482548425773836042297909052960286277119", "price": "0.745", "size": "0", "side": "BUY", "hash": "2daac3ffd1367e25dbc977c5447de3a5efd23457", "best_bid": "0.997", "best_ask": "0.998"}, {"asset_id": "30944797740926340411025345169348106947975350930232142082675991513705266362329", "price": "0.255", "size": "0", "side": "SELL", "hash": "a1e458220c2a8894c8ca0cce6c8e5131f7b8bff2", "best_bid": "0.002", "best_ask": "0.003"}], "timestamp": "1769384527247", "event_type": "price_change"}}
{"_local_timestamp": "2026-01-25T23:42:07.322260+00:00", "data": {"market": "0x0eada57dcf53965a321f61c9dc6adb655367fabeb1f2ecbe7746f3f1a6ff7769", "price_changes": [{"asset_id": "93593125008177926269164142727030950699068997099893975938000261506053151609883", "price": "0.482", "size": "0", "side": "BUY", "hash": "89de6c9438b5a37e3d033f078c7874f1717a0a74", "best_bid": "0.997", "best_ask": "0.998"}, {"asset_id": "88775412427564636095391917176836120951442159831179966305257669968799086969217", "price": "0.518", "size": "0", "side": "SELL", "hash": "fde8078900d285d63e82fc497e52528775477b32", "best_bid": "0.002", "best_ask": "0.003"}], "timestamp": "1769384527247", "event_type": "price_change"}}
{"_local_timestamp": "2026-01-25T23:42:07.323147+00:00", "data": {"market": "0x96bc24f519f3008b984b623dfacfa6b87599381ba6afdbd36a576d0d85c4a59c", "price_changes": [{"asset_id": "37234028100441924867078516219629684611507504332898623831670509973866359367709", "price": "0.401", "size": "0", "side": "BUY", "hash": "906cfaad3fdaccfdf5c08043390e05cd683d6597", "best_bid": "0.997", "best_ask": "0.999"}, {"asset_id": "48733707571584348634287808682190901692810422881953520223982749265958667182900", "price": "0.599", "size": "0", "side": "SELL", "hash": "dff9d4ac2a7cd8ce99684dc1c6fd2851480dc4bb", "best_bid": "0.001", "best_ask": "0.003"}], "timestamp": "1769384527247", "event_type": "price_change"}}
{"_local_timestamp": "2026-01-25T23:42:07.392154+00:00", "data": {"market": "0x96bc24f519f3008b984b623dfacfa6b87599381ba6afdbd36a576d0d85c4a59c", "price_changes": [{"asset_id": "37234028100441924867078516219629684611507504332898623831670509973866359367709", "price": "0.553", "size": "20", "side": "BUY", "hash": "f36fcd222ded5630aa0971a35131939854266755", "best_bid": "0.997", "best_ask": "0.999"}, {"asset_id": "48733707571584348634287808682190901692810422881953520223982749265958667182900", "price": "0.447", "size": "20", "side": "SELL", "hash": "681d1d584d7fa0e7b7d8a883765c620901f14773", "best_bid": "0.001", "best_ask": "0.003"}], "timestamp": "1769384527322", "event_type": "price_change"}}
{"_local_timestamp": "2026-01-25T23:42:07.393065+00:00", "data": {"market": "0x0eada57dcf53965a321f61c9dc6adb655367fabeb1f2ecbe7746f3f1a6ff7769", "price_changes": [{"asset_id": "93593125008177926269164142727030950699068997099893975938000261506053151609883", "price": "0.484", "size": "20", "side": "BUY", "hash": "d0d67191a8752a3113754bab18e1348532f11944", "best_bid": "0.997", "best_ask": "0.998"}, {"asset_id": "88775412427564636095391917176836120951442159831179966305257669968799086969217", "price": "0.516", "size": "20", "side": "SELL", "hash": "6d7ca81ed4caaa01173b7c3a05fc4f2ab86e2eb7", "best_bid": "0.002", "best_ask": "0.003"}], "timestamp": "1769384527322", "event_type": "price_change"}}
{"_local_timestamp": "2026-01-25T23:42:07.393913+00:00", "data": {"market": "0xd25c820d3aee1c735c0fa62c36f4905632ab8c6988653b5b4134593b3209eb7f", "price_changes": [{"asset_id": "45361184347486002884792387151438756924785609968030585696129487864334578884255", "price": "0.46", "size": "20", "side": "BUY", "hash": "93b4af4b4b0997526ea29a95d5fd11bd5cd6616f", "best_bid": "0.6", "best_ask": "0.67"}, {"asset_id": "91117078941733659645786554099775611998962677612187928648088119165893475827434", "price": "0.54", "size": "20", "side": "SELL", "hash": "9e1770b66e9ca782488b0cb605297ae18b072f83", "best_bid": "0.33", "best_ask": "0.4"}], "timestamp": "1769384527322", "event_type": "price_change"}}
{"_local_timestamp": "2026-01-25T23:42:07.394767+00:00", "data": {"market": "0x1fe1788d96d4c98e242549f91baf0de29eaf3b1545b5e2dda1d8714a3faf5305", "price_changes": [{"asset_id": "85121409960340786807237728711169263074482548425773836042297909052960286277119", "price": "0.751", "size": "20", "side": "BUY", "hash": "a0cfab8f8192c6732c83a8bab476eb4e40ec642a", "best_bid": "0.997", "best_ask": "0.998"}, {"asset_id": "30944797740926340411025345169348106947975350930232142082675991513705266362329", "price": "0.249", "size": "20", "side": "SELL", "hash": "530c39a0a4ae3ec93429acaec222765aa582a807", "best_bid": "0.002", "best_ask": "0.003"}], "timestamp": "1769384527322", "event_type": "price_change"}}
{"_local_timestamp": "2026-01-25T23:42:07.636873+00:00", "data": {"market": "0x96bc24f519f3008b984b623dfacfa6b87599381ba6afdbd36a576d0d85c4a59c", "price_changes": [{"asset_id": "37234028100441924867078516219629684611507504332898623831670509973866359367709", "price": "0.552", "size": "10", "side": "BUY", "hash": "7725f8990693537d4b5d6afd3ecf995537dcba73", "best_bid": "0.997", "best_ask": "0.999"}, {"asset_id": "48733707571584348634287808682190901692810422881953520223982749265958667182900", "price": "0.448", "size": "10", "side": "SELL", "hash": "c5a653fe438a48ddfeca5325affb87269fb57825", "best_bid": "0.001", "best_ask": "0.003"}], "timestamp": "1769384527552", "event_type": "price_change"}}
{"_local_timestamp": "2026-01-25T23:42:07.638060+00:00", "data": {"market": "0x0eada57dcf53965a321f61c9dc6adb655367fabeb1f2ecbe7746f3f1a6ff7769", "price_changes": [{"asset_id": "93593125008177926269164142727030950699068997099893975938000261506053151609883", "price": "0.483", "size": "10", "side": "BUY", "hash": "f6f9f7dd924968a974531f5b54223c895d75a907", "best_bid": "0.997", "best_ask": "0.998"}, {"asset_id": "88775412427564636095391917176836120951442159831179966305257669968799086969217", "price": "0.517", "size": "10", "side": "SELL", "hash": "1dc5ebc7e893291080b4712e7ede161dabcc7085", "best_bid": "0.002", "best_ask": "0.003"}], "timestamp": "1769384527552", "event_type": "price_change"}}
{"_local_timestamp": "2026-01-25T23:42:18.088034+00:00", "data": {"market": "0xd25c820d3aee1c735c0fa62c36f4905632ab8c6988653b5b4134593b3209eb7f", "price_changes": [{"asset_id": "91117078941733659645786554099775611998962677612187928648088119165893475827434", "price": "0.44", "size": "67.85", "side": "SELL", "hash": "02d91b4acc84626857bf60e38026c899a5b3c89c", "best_bid": "0.33", "best_ask": "0.4"}, {"asset_id": "45361184347486002884792387151438756924785609968030585696129487864334578884255", "price": "0.56", "size": "67.85", "side": "BUY", "hash": "f39c38024108240623b9593bb85168431d8b0fa9", "best_bid": "0.6", "best_ask": "0.67"}], "timestamp": "1769384537944", "event_type": "price_change"}}
{"_local_timestamp": "2026-01-25T23:42:18.115898+00:00", "data": {"market": "0xd25c820d3aee1c735c0fa62c36f4905632ab8c6988653b5b4134593b3209eb7f", "price_changes": [{"asset_id": "45361184347486002884792387151438756924785609968030585696129487864334578884255", "price": "0.55", "size": "72.5", "side": "BUY", "hash": "cd87c9d0d48bfe2432c5347d9938181fd7212ed1", "best_bid": "0.6", "best_ask": "0.67"}, {"asset_id": "91117078941733659645786554099775611998962677612187928648088119165893475827434", "price": "0.45", "size": "72.5", "side": "SELL", "hash": "1044be765227183623df6f8d2649d276fa9ed40f", "best_bid": "0.33", "best_ask": "0.4"}], "timestamp": "1769384537986", "event_type": "price_change"}}
{"_local_timestamp": "2026-01-25T23:42:18.116873+00:00", "data": {"market": "0x3935226f1baa202667795b3a558d26fb0a9ae894a482676d34820bfb1b9b4edd", "price_changes": [{"asset_id": "5083116961935871155736992778398112358288960843713086370981563262578268017242", "price": "0.881", "size": "25", "side": "BUY", "hash": "329a1ebae8e99de55ad53834de92c20a34130352", "best_bid": "0.995", "best_ask": "0.997"}, {"asset_id": "80071381584983995567060219264871699619214990229460921095601419271143281499406", "price": "0.119", "size": "25", "side": "SELL", "hash": "1e4f154d7ccce28e09a4fa944de7b37cee99ce47", "best_bid": "0.003", "best_ask": "0.005"}], "timestamp": "1769384537987", "event_type": "price_change"}}
{"_local_timestamp": "2026-01-25T23:42:18.117901+00:00", "data": {"market": "0x1fe1788d96d4c98e242549f91baf0de29eaf3b1545b5e2dda1d8714a3faf5305", "price_changes": [{"asset_id": "85121409960340786807237728711169263074482548425773836042297909052960286277119", "price": "0.883", "size": "25", "side": "BUY", "hash": "66c940328d797408fe8bf6e9058de3ca0ace9267", "best_bid": "0.997", "best_ask": "0.998"}, {"asset_id": "30944797740926340411025345169348106947975350930232142082675991513705266362329", "price": "0.117", "size": "25", "side": "SELL", "hash": "fd4d5546fe2a4d1dc05c883ec79f4c13b8947268", "best_bid": "0.002", "best_ask": "0.003"}], "timestamp": "1769384537989", "event_type": "price_change"}}
{"_local_timestamp": "2026-01-25T23:42:18.118886+00:00", "data": {"market": "0x0eada57dcf53965a321f61c9dc6adb655367fabeb1f2ecbe7746f3f1a6ff7769", "price_changes": [{"asset_id": "93593125008177926269164142727030950699068997099893975938000261506053151609883", "price": "0.883", "size": "25", "side": "BUY", "hash": "02f22bad67bb357334dfceae2a8711996411f941", "best_bid": "0.997", "best_ask": "0.998"}, {"asset_id": "88775412427564636095391917176836120951442159831179966305257669968799086969217", "price": "0.117", "size": "25", "side": "SELL", "hash": "bd3e774abc39797aedfa67c1736996b943fe39c9", "best_bid": "0.002", "best_ask": "0.003"}], "timestamp": "1769384537989", "event_type": "price_change"}}
{"_local_timestamp": "2026-01-25T23:42:24.727143+00:00", "data": {"market": "0xd25c820d3aee1c735c0fa62c36f4905632ab8c6988653b5b4134593b3209eb7f", "price_changes": [{"asset_id": "45361184347486002884792387151438756924785609968030585696129487864334578884255", "price": "0.15", "size": "1660.53", "side": "BUY", "hash": "1f8886c17ab76e91e94fabb36c1898c9667fba91", "best_bid": "0.6", "best_ask": "0.67"}, {"asset_id": "91117078941733659645786554099775611998962677612187928648088119165893475827434", "price": "0.85", "size": "1660.53", "side": "SELL", "hash": "52b41731cb5168e3f6dd48654bc524bbe170c92a", "best_bid": "0.33", "best_ask": "0.4"}], "timestamp": "1769384544488", "event_type": "price_change"}}
{"_local_timestamp": "2026-01-25T23:42:24.728257+00:00", "data": {"market": "0xd25c820d3aee1c735c0fa62c36f4905632ab8c6988653b5b4134593b3209eb7f", "price_changes": [{"asset_id": "45361184347486002884792387151438756924785609968030585696129487864334578884255", "price": "0.17", "size": "464.7", "side": "BUY", "hash": "1f8886c17ab76e91e94fabb36c1898c9667fba91", "best_bid": "0.6", "best_ask": "0.67"}, {"asset_id": "91117078941733659645786554099775611998962677612187928648088119165893475827434", "price": "0.83", "size": "464.7", "side": "SELL", "hash": "52b41731cb5168e3f6dd48654bc524bbe170c92a", "best_bid": "0.33", "best_ask": "0.4"}], "timestamp": "1769384544488", "event_type": "price_change"}}
{"_local_timestamp": "2026-01-25T23:42:24.757239+00:00", "data": {"market": "0xba8add06562a7bfd4fdd8f0a1882b5e2596540bd61c67a32359487694838f0a5", "price_changes": [{"asset_id": "62853431799112511763784693741363968903595954956498708214160770466188703343964", "price": "0.2", "size": "190", "side": "BUY", "hash": "a9c0f47f4bfbacab4b9247fa045d4b6bbca69665", "best_bid": "0.76", "best_ask": "0.78"}, {"asset_id": "7221299913764832338348128493889748182769672206962167820297840741811689706878", "price": "0.8", "size": "190", "side": "SELL", "hash": "58c3e779591482490f7a9b851a0f078a6ee6f9b5", "best_bid": "0.22", "best_ask": "0.24"}], "timestamp": "1769384544493", "event_type": "price_change"}}
{"_local_timestamp": "2026-01-25T23:42:25.133181+00:00", "data": {"market": "0xba8add06562a7bfd4fdd8f0a1882b5e2596540bd61c67a32359487694838f0a5", "price_changes": [{"asset_id": "62853431799112511763784693741363968903595954956498708214160770466188703343964", "price": "0.19", "size": "1292", "side": "BUY", "hash": "9d111c264dbe37aa415c1d88cfde304133825362", "best_bid": "0.76", "best_ask": "0.78"}, {"asset_id": "7221299913764832338348128493889748182769672206962167820297840741811689706878", "price": "0.81", "size": "1292", "side": "SELL", "hash": "f4ab9888a4ae345f9f1505389c53afb409106e2c", "best_bid": "0.22", "best_ask": "0.24"}], "timestamp": "1769384544934", "event_type": "price_change"}}
{"_local_timestamp": "2026-01-25T23:42:25.300739+00:00", "data": {"market": "0xd25c820d3aee1c735c0fa62c36f4905632ab8c6988653b5b4134593b3209eb7f", "price_changes": [{"asset_id": "45361184347486002884792387151438756924785609968030585696129487864334578884255", "price": "0.25", "size": "200", "side": "BUY", "hash": "358aa4e66705019c577f47d178133d24dd63f8da", "best_bid": "0.6", "best_ask": "0.67"}, {"asset_id": "91117078941733659645786554099775611998962677612187928648088119165893475827434", "price": "0.75", "size": "200", "side": "SELL", "hash": "0da80ff9d89e8756852618e43fda2d30c12637cb", "best_bid": "0.33", "best_ask": "0.4"}], "timestamp": "1769384545149", "event_type": "price_change"}}
{"_local_timestamp": "2026-01-25T23:42:39.285024+00:00", "data": {"market": "0x1fe1788d96d4c98e242549f91baf0de29eaf3b1545b5e2dda1d8714a3faf5305", "price_changes": [{"asset_id": "30944797740926340411025345169348106947975350930232142082675991513705266362329", "price": "0.02", "size": "0", "side": "SELL", "hash": "f9e3a925d261ef7d1f6e7f00a420e980906ea659", "best_bid": "0.002", "best_ask": "0.003"}, {"asset_id": "85121409960340786807237728711169263074482548425773836042297909052960286277119", "price": "0.98", "size": "0", "side": "BUY", "hash": "3c44c95ddae89aed1b25fdc164a139f034b7fde4", "best_bid": "0.997", "best_ask": "0.998"}], "timestamp": "1769384559147", "event_type": "price_change"}}
{"_local_timestamp": "2026-01-25T23:42:39.476684+00:00", "data": {"market": "0x1fe1788d96d4c98e242549f91baf0de29eaf3b1545b5e2dda1d8714a3faf5305", "price_changes": [{"asset_id": "30944797740926340411025345169348106947975350930232142082675991513705266362329", "price": "0.025", "size": "20.96", "side": "SELL", "hash": "f7986812b7bc7234bc7dac0c64fa1edbd215e9b8", "best_bid": "0.002", "best_ask": "0.003"}, {"asset_id": "85121409960340786807237728711169263074482548425773836042297909052960286277119", "price": "0.975", "size": "20.96", "side": "BUY", "hash": "c9a3b1c318b14886f30ec1cfbe4135903c70199f", "best_bid": "0.997", "best_ask": "0.998"}], "timestamp": "1769384559333", "event_type": "price_change"}}
{"_local_timestamp": "2026-01-25T23:42:39.544951+00:00", "data": {"market": "0xba8add06562a7bfd4fdd8f0a1882b5e2596540bd61c67a32359487694838f0a5", "price_changes": [{"asset_id": "62853431799112511763784693741363968903595954956498708214160770466188703343964", "price": "0.54", "size": "0", "side": "BUY", "hash": "01dd5f8233815ff0c25bcb6dfe877c1613808d6c", "best_bid": "0.76", "best_ask": "0.78"}, {"asset_id": "7221299913764832338348128493889748182769672206962167820297840741811689706878", "price": "0.46", "size": "0", "side": "SELL", "hash": "fbcc85bec6ed58021fda7f25d8b764699623acde", "best_bid": "0.22", "best_ask": "0.24"}], "timestamp": "1769384559405", "event_type": "price_change"}}
{"_local_timestamp": "2026-01-25T23:42:39.722578+00:00", "data": {"market": "0xba8add06562a7bfd4fdd8f0a1882b5e2596540bd61c67a32359487694838f0a5", "price_changes": [{"asset_id": "62853431799112511763784693741363968903595954956498708214160770466188703343964", "price": "0.56", "size": "10", "side": "BUY", "hash": "0786cc8252f13f489c38d8801b133de55fcab44e", "best_bid": "0.76", "best_ask": "0.78"}, {"asset_id": "7221299913764832338348128493889748182769672206962167820297840741811689706878", "price": "0.44", "size": "10", "side": "SELL", "hash": "c1ed63e9c65d1aa706bd8cda72b161944193962f", "best_bid": "0.22", "best_ask": "0.24"}], "timestamp": "1769384559545", "event_type": "price_change"}}
{"_local_timestamp": "2026-01-25T23:42:39.730310+00:00", "data": {"market": "0xba8add06562a7bfd4fdd8f0a1882b5e2596540bd61c67a32359487694838f0a5", "price_changes": [{"asset_id": "62853431799112511763784693741363968903595954956498708214160770466188703343964", "price": "0.56", "size": "25", "side": "BUY", "hash": "628df3c38447c478e7a2f688b10a8531ae692e3c", "best_bid": "0.76", "best_ask": "0.78"}, {"asset_id": "7221299913764832338348128493889748182769672206962167820297840741811689706878", "price": "0.44", "size": "25", "side": "SELL", "hash": "c89b57716c7bc36df7ad06dcdf29900a36ed6f7e", "best_bid": "0.22", "best_ask": "0.24"}], "timestamp": "1769384559551", "event_type": "price_change"}}
{"_local_timestamp": "2026-01-25T23:42:39.764738+00:00", "data": {"market": "0xd25c820d3aee1c735c0fa62c36f4905632ab8c6988653b5b4134593b3209eb7f", "price_changes": [{"asset_id": "45361184347486002884792387151438756924785609968030585696129487864334578884255", "price": "0.07", "size": "1014.28", "side": "BUY", "hash": "c5acafd5fd5317d015c811df1af53e31b3abeb4a", "best_bid": "0.6", "best_ask": "0.67"}, {"asset_id": "91117078941733659645786554099775611998962677612187928648088119165893475827434", "price": "0.93", "size": "1014.28", "side": "SELL", "hash": "59f2520c15ae1551b9f5b042368ec921c2edef4c", "best_bid": "0.33", "best_ask": "0.4"}], "timestamp": "1769384559587", "event_type": "price_change"}}
{"_local_timestamp": "2026-01-25T23:42:40.338084+00:00", "data": {"market": "0xba8add06562a7bfd4fdd8f0a1882b5e2596540bd61c67a32359487694838f0a5", "price_changes": [{"asset_id": "62853431799112511763784693741363968903595954956498708214160770466188703343964", "price": "0.55", "size": "0", "side": "BUY", "hash": "b15109de20293700c3af96016ea237dfa5f07634", "best_bid": "0.76", "best_ask": "0.78"}, {"asset_id": "7221299913764832338348128493889748182769672206962167820297840741811689706878", "price": "0.45", "size": "0", "side": "SELL", "hash": "2910c9948259f1d75813e59347a50fe8428c52a9", "best_bid": "0.22", "best_ask": "0.24"}], "timestamp": "1769384560196", "event_type": "price_change"}}
{"_local_timestamp": "2026-01-25T23:42:40.363280+00:00", "data": {"market": "0xba8add06562a7bfd4fdd8f0a1882b5e2596540bd61c67a32359487694838f0a5", "price_changes": [{"asset_id": "62853431799112511763784693741363968903595954956498708214160770466188703343964", "price": "0.57", "size": "20", "side": "BUY", "hash": "4a9987454415d40d8ea2dff54804bf622a09df9f", "best_bid": "0.76", "best_ask": "0.78"}, {"asset_id": "7221299913764832338348128493889748182769672206962167820297840741811689706878", "price": "0.43", "size": "20", "side": "SELL", "hash": "a891034d9228b5deed28163d59c74fc38ab8d59f", "best_bid": "0.22", "best_ask": "0.24"}], "timestamp": "1769384560229", "event_type": "price_change"}}
{"_local_timestamp": "2026-01-25T23:42:41.130132+00:00", "data": {"market": "0xba8add06562a7bfd4fdd8f0a1882b5e2596540bd61c67a32359487694838f0a5", "price_changes": [{"asset_id": "62853431799112511763784693741363968903595954956498708214160770466188703343964", "price": "0.57", "size": "33", "side": "BUY", "hash": "e08cea3a405081407f1c81208a8e733bdab12383", "best_bid": "0.76", "best_ask": "0.78"}, {"asset_id": "7221299913764832338348128493889748182769672206962167820297840741811689706878", "price": "0.43", "size": "33", "side": "SELL", "hash": "75245911013a97bc25a8341160a48bad041b8fae", "best_bid": "0.22", "best_ask": "0.24"}], "timestamp": "1769384560977", "event_type": "price_change"}}
{"_local_timestamp": "2026-01-25T23:42:41.179075+00:00", "data": {"market": "0xba8add06562a7bfd4fdd8f0a1882b5e2596540bd61c67a32359487694838f0a5", "price_changes": [{"asset_id": "62853431799112511763784693741363968903595954956498708214160770466188703343964", "price": "0.56", "size": "41.66", "side": "BUY", "hash": "3df5da27af3368b54e30daf55f0771b9da043d01", "best_bid": "0.76", "best_ask": "0.78"}, {"asset_id": "7221299913764832338348128493889748182769672206962167820297840741811689706878", "price": "0.44", "size": "41.66", "side": "SELL", "hash": "57de3c75c8715572b12de50f1a171851542a3977", "best_bid": "0.22", "best_ask": "0.24"}], "timestamp": "1769384561029", "event_type": "price_change"}}
{"_local_timestamp": "2026-01-25T23:42:43.481143+00:00", "data": {"market": "0xba8add06562a7bfd4fdd8f0a1882b5e2596540bd61c67a32359487694838f0a5", "price_changes": [{"asset_id": "62853431799112511763784693741363968903595954956498708214160770466188703343964", "price": "0.57", "size": "13", "side": "BUY", "hash": "b48846f2b80ec0049fcbdee7fb05355e387dcb42", "best_bid": "0.76", "best_ask": "0.78"}, {"asset_id": "7221299913764832338348128493889748182769672206962167820297840741811689706878", "price": "0.43", "size": "13", "side": "SELL", "hash": "651e195ba783e69e8f45907e3e88c11a2adba211", "best_bid": "0.22", "best_ask": "0.24"}], "timestamp": "1769384563343", "event_type": "price_change"}}
{"_local_timestamp": "2026-01-25T23:42:43.513848+00:00", "data": {"market": "0xba8add06562a7bfd4fdd8f0a1882b5e2596540bd61c67a32359487694838f0a5", "price_changes": [{"asset_id": "62853431799112511763784693741363968903595954956498708214160770466188703343964", "price": "0.58", "size": "20", "side": "BUY", "hash": "4f23190a248f040115016d1f1ab6fda8327e2cd0", "best_bid": "0.76", "best_ask": "0.78"}, {"asset_id": "7221299913764832338348128493889748182769672206962167820297840741811689706878", "price": "0.42", "size": "20", "side": "SELL", "hash": "16559393fe0d0cae8c109d5b6ba7af572f001d13", "best_bid": "0.22", "best_ask": "0.24"}], "timestamp": "1769384563374", "event_type": "price_change"}}
{"_local_timestamp": "2026-01-25T23:42:45.403642+00:00", "data": {"market": "0xba8add06562a7bfd4fdd8f0a1882b5e2596540bd61c67a32359487694838f0a5", "price_changes": [{"asset_id": "62853431799112511763784693741363968903595954956498708214160770466188703343964", "price": "0.2", "size": "140", "side": "BUY", "hash": "9611aec7b3bd12aae67f30d484b83aad97fb5ec4", "best_bid": "0.76", "best_ask": "0.78"}, {"asset_id": "7221299913764832338348128493889748182769672206962167820297840741811689706878", "price": "0.8", "size": "140", "side": "SELL", "hash": "0dcb7e1524d35a93df32402523e81130b382f600", "best_bid": "0.22", "best_ask": "0.24"}], "timestamp": "1769384565214", "event_type": "price_change"}}
{"_local_timestamp": "2026-01-25T23:42:45.799459+00:00", "data": {"market": "0xba8add06562a7bfd4fdd8f0a1882b5e2596540bd61c67a32359487694838f0a5", "price_changes": [{"asset_id": "62853431799112511763784693741363968903595954956498708214160770466188703343964", "price": "0.24", "size": "1898", "side": "BUY", "hash": "6e7b35ffaea91fba92f695fe8723b4754983c002", "best_bid": "0.76", "best_ask": "0.78"}, {"asset_id": "7221299913764832338348128493889748182769672206962167820297840741811689706878", "price": "0.76", "size": "1898", "side": "SELL", "hash": "6fd3167a2ce01d213ac3d51ac116749623b05c8b", "best_bid": "0.22", "best_ask": "0.24"}], "timestamp": "1769384565614", "event_type": "price_change"}}
{"_local_timestamp": "2026-01-25T23:42:47.195772+00:00", "data": {"market": "0xba8add06562a7bfd4fdd8f0a1882b5e2596540bd61c67a32359487694838f0a5", "price_changes": [{"asset_id": "62853431799112511763784693741363968903595954956498708214160770466188703343964", "price": "0.24", "size": "150", "side": "BUY", "hash": "de9a3d826517473c36b64057bbbf04bc23c45f96", "best_bid": "0.76", "best_ask": "0.78"}, {"asset_id": "7221299913764832338348128493889748182769672206962167820297840741811689706878", "price": "0.76", "size": "150", "side": "SELL", "hash": "bb976ca35e14a9fcae3b6f4909a07b69088ddc71", "best_bid": "0.22", "best_ask": "0.24"}], "timestamp": "1769384566994", "event_type": "price_change"}}
{"_local_timestamp": "2026-01-25T23:43:00.140726+00:00", "data": {"market": "0xba8add06562a7bfd4fdd8f0a1882b5e2596540bd61c67a32359487694838f0a5", "price_changes": [{"asset_id": "62853431799112511763784693741363968903595954956498708214160770466188703343964", "price": "0.75", "size": "355.85", "side": "BUY", "hash": "4f8bdce39aa67351adf97d26c81bc668156b91d5", "best_bid": "0.76", "best_ask": "0.78"}, {"asset_id": "7221299913764832338348128493889748182769672206962167820297840741811689706878", "price": "0.25", "size": "355.85", "side": "SELL", "hash": "b7662ee549283444a7105d153f49db1e076bdfac", "best_bid": "0.22", "best_ask": "0.24"}], "timestamp": "1769384580001", "event_type": "price_change"}}
{"_local_timestamp": "2026-01-25T23:43:00.144635+00:00", "data": {"market": "0xba8add06562a7bfd4fdd8f0a1882b5e2596540bd61c67a32359487694838f0a5", "price_changes": [{"asset_id": "7221299913764832338348128493889748182769672206962167820297840741811689706878", "price": "0.21", "size": "0", "side": "BUY", "hash": "91152de7d047ce6e3c65c4c3cfd6c21fc6112357", "best_bid": "0.22", "best_ask": "0.24"}, {"asset_id": "62853431799112511763784693741363968903595954956498708214160770466188703343964", "price": "0.79", "size": "0", "side": "SELL", "hash": "27fd57c4cc177aa412b3380d3c494ecd58eba48c", "best_bid": "0.76", "best_ask": "0.78"}], "timestamp": "1769384580002", "event_type": "price_change"}}
{"_local_timestamp": "2026-01-25T23:43:00.294412+00:00", "data": {"market": "0x306bbce53f9a77906b9a928d52728bdee2e48f3354d19a9d6f0db7c9a1d4230d", "price_changes": [{"asset_id": "64957256704343867164459890398860992515731454967968064924053896034568618595733", "price": "0.437", "size": "0", "side": "BUY", "hash": "ac9fa7c5f2947b21db053ba2259db5f1b997d50e", "best_bid": "0.932", "best_ask": "0.946"}, {"asset_id": "34335512241828535299853623975656484642594791501285631499713239174540168255596", "price": "0.563", "size": "0", "side": "SELL", "hash": "758db91d5d2672b01f550c3e0065f4e0f70522db", "best_bid": "0.054", "best_ask": "0.068"}], "timestamp": "1769384580163", "event_type": "price_change"}}
{"_local_timestamp": "2026-01-25T23:43:00.295609+00:00", "data": {"market": "0x0eada57dcf53965a321f61c9dc6adb655367fabeb1f2ecbe7746f3f1a6ff7769", "price_changes": [{"asset_id": "93593125008177926269164142727030950699068997099893975938000261506053151609883", "price": "0.481", "size": "10", "side": "BUY", "hash": "f06904178c77ea7abc912ac5b3415b81f23f924b", "best_bid": "0.997", "best_ask": "0.998"}, {"asset_id": "88775412427564636095391917176836120951442159831179966305257669968799086969217", "price": "0.519", "size": "10", "side": "SELL", "hash": "1eb16a115457b718e0fea5a8d07673be62990a8f", "best_bid": "0.002", "best_ask": "0.003"}], "timestamp": "1769384580164", "event_type": "price_change"}}
{"_local_timestamp": "2026-01-25T23:43:00.415600+00:00", "data": {"market": "0x306bbce53f9a77906b9a928d52728bdee2e48f3354d19a9d6f0db7c9a1d4230d", "price_changes": [{"asset_id": "64957256704343867164459890398860992515731454967968064924053896034568618595733", "price": "0.439", "size": "10", "side": "BUY", "hash": "bd754c9c899f94fbec8ac230612abcd0d39d1172", "best_bid": "0.932", "best_ask": "0.946"}, {"asset_id": "34335512241828535299853623975656484642594791501285631499713239174540168255596", "price": "0.561", "size": "10", "side": "SELL", "hash": "b069e8a0f5c1abaf5fbca63335a2333911778ff1", "best_bid": "0.054", "best_ask": "0.068"}], "timestamp": "1769384580283", "event_type": "price_change"}}
{"_local_timestamp": "2026-01-25T23:43:01.298379+00:00", "data": {"market": "0x306bbce53f9a77906b9a928d52728bdee2e48f3354d19a9d6f0db7c9a1d4230d", "price_changes": [{"asset_id": "64957256704343867164459890398860992515731454967968064924053896034568618595733", "price": "0.438", "size": "0", "side": "BUY", "hash": "089b7a014b758b327def20c9c79988ea369d2885", "best_bid": "0.932", "best_ask": "0.946"}, {"asset_id": "34335512241828535299853623975656484642594791501285631499713239174540168255596", "price": "0.562", "size": "0", "side": "SELL", "hash": "db1d3a49b3b29bad124aa77075f850437dcb61b3", "best_bid": "0.054", "best_ask": "0.068"}], "timestamp": "1769384581164", "event_type": "price_change"}}
{"_local_timestamp": "2026-01-25T23:43:01.338711+00:00", "data": {"market": "0x306bbce53f9a77906b9a928d52728bdee2e48f3354d19a9d6f0db7c9a1d4230d", "price_changes": [{"asset_id": "64957256704343867164459890398860992515731454967968064924053896034568618595733", "price": "0.44", "size": "20", "side": "BUY", "hash": "e7e24764f62261c2a7167ed819b0c406590dfb26", "best_bid": "0.932", "best_ask": "0.946"}, {"asset_id": "34335512241828535299853623975656484642594791501285631499713239174540168255596", "price": "0.56", "size": "20", "side": "SELL", "hash": "87b67962a570de6254e3861de25496e215f8d5ce", "best_bid": "0.054", "best_ask": "0.068"}], "timestamp": "1769384581198", "event_type": "price_change"}}
{"_local_timestamp": "2026-01-25T23:43:01.866175+00:00", "data": {"market": "0xba8add06562a7bfd4fdd8f0a1882b5e2596540bd61c67a32359487694838f0a5", "price_changes": [{"asset_id": "7221299913764832338348128493889748182769672206962167820297840741811689706878", "price": "0.2", "size": "184", "side": "BUY", "hash": "cd7ec206ecb5c2d33c3990b6c200fd2c7f93e9ef", "best_bid": "0.22", "best_ask": "0.24"}, {"asset_id": "62853431799112511763784693741363968903595954956498708214160770466188703343964", "price": "0.8", "size": "184", "side": "SELL", "hash": "4cf4a26d105b31044f21fb4d6d0b9bfce2a6c719", "best_bid": "0.76", "best_ask": "0.78"}], "timestamp": "1769384581734", "event_type": "price_change"}}
{"_local_timestamp": "2026-01-25T23:43:02.016692+00:00", "data": {"market": "0x1fe1788d96d4c98e242549f91baf0de29eaf3b1545b5e2dda1d8714a3faf5305", "price_changes": [{"asset_id": "85121409960340786807237728711169263074482548425773836042297909052960286277119", "price": "0.404", "size": "0", "side": "BUY", "hash": "a5074890e3857cc4bad1075660faf94c0cb79be8", "best_bid": "0.997", "best_ask": "0.998"}, {"asset_id": "30944797740926340411025345169348106947975350930232142082675991513705266362329", "price": "0.596", "size": "0", "side": "SELL", "hash": "f695fa1f7c5bc757170914630de595fffa3fd831", "best_bid": "0.002", "best_ask": "0.003"}], "timestamp": "1769384581874", "event_type": "price_change"}}
{"_local_timestamp": "2026-01-25T23:43:04.942792+00:00", "data": {"market": "0xba8add06562a7bfd4fdd8f0a1882b5e2596540bd61c67a32359487694838f0a5", "price_changes": [{"asset_id": "62853431799112511763784693741363968903595954956498708214160770466188703343964", "price": "0.76", "size": "139.25", "side": "BUY", "hash": "03a360a2632cf5bd7b505df4883386a10c14d7bc", "best_bid": "0.76", "best_ask": "0.78"}, {"asset_id": "7221299913764832338348128493889748182769672206962167820297840741811689706878", "price": "0.24", "size": "139.25", "side": "SELL", "hash": "fcac97378d9a4b2c94ceb080dd51735644dba03c", "best_bid": "0.22", "best_ask": "0.24"}], "timestamp": "1769384584803", "event_type": "price_change"}}
{"_local_timestamp": "2026-01-25T23:43:05.530255+00:00", "data": {"market": "0xba8add06562a7bfd4fdd8f0a1882b5e2596540bd61c67a32359487694838f0a5", "price_changes": [{"asset_id": "62853431799112511763784693741363968903595954956498708214160770466188703343964", "price": "0.77", "size": "66.66", "side": "BUY", "hash": "8b80bd51fb178f18f6b67c39f3edc5b7e999c1c6", "best_bid": "0.77", "best_ask": "0.78"}, {"asset_id": "7221299913764832338348128493889748182769672206962167820297840741811689706878", "price": "0.23", "size": "66.66", "side": "SELL", "hash": "484b3ef603230ac2b8d0f1c1d80f78e20a8e8810", "best_bid": "0.22", "best_ask": "0.23"}], "timestamp": "1769384585393", "event_type": "price_change"}}
{"_local_timestamp": "2026-01-25T23:43:05.562188+00:00", "data": {"market": "0xba8add06562a7bfd4fdd8f0a1882b5e2596540bd61c67a32359487694838f0a5", "price_changes": [{"asset_id": "62853431799112511763784693741363968903595954956498708214160770466188703343964", "price": "0.72", "size": "66.66", "side": "BUY", "hash": "fe0a40b407056fb3c2fda711e17753cf9f0cdbb8", "best_bid": "0.77", "best_ask": "0.78"}, {"asset_id": "7221299913764832338348128493889748182769672206962167820297840741811689706878", "price": "0.28", "size": "66.66", "side": "SELL", "hash": "0c3cf157f5383e3806843985458f5b1bda634777", "best_bid": "0.22", "best_ask": "0.23"}], "timestamp": "1769384585412", "event_type": "price_change"}}
{"_local_timestamp": "2026-01-25T23:43:05.563267+00:00", "data": {"market": "0xba8add06562a7bfd4fdd8f0a1882b5e2596540bd61c67a32359487694838f0a5", "price_changes": [{"asset_id": "62853431799112511763784693741363968903595954956498708214160770466188703343964", "price": "0.67", "size": "66.66", "side": "BUY", "hash": "28b07333ae492317e17f33f0c8a60830009f3de4", "best_bid": "0.77", "best_ask": "0.78"}, {"asset_id": "7221299913764832338348128493889748182769672206962167820297840741811689706878", "price": "0.33", "size": "66.66", "side": "SELL", "hash": "8bfad72a1d97f02a830f73fac2a8555fe08983e3", "best_bid": "0.22", "best_ask": "0.23"}], "timestamp": "1769384585417", "event_type": "price_change"}}
{"_local_timestamp": "2026-01-25T23:43:06.157915+00:00", "data": {"market": "0x306bbce53f9a77906b9a928d52728bdee2e48f3354d19a9d6f0db7c9a1d4230d", "price_changes": [{"asset_id": "64957256704343867164459890398860992515731454967968064924053896034568618595733", "price": "0.919", "size": "0", "side": "BUY", "hash": "796e4ac891e3bc1d8ae1d979254b250d370791b8", "best_bid": "0.932", "best_ask": "0.946"}, {"asset_id": "34335512241828535299853623975656484642594791501285631499713239174540168255596", "price": "0.081", "size": "0", "side": "SELL", "hash": "914e3bfa89a0267ed29dddcdba2b0353f103da1e", "best_bid": "0.054", "best_ask": "0.068"}], "timestamp": "1769384586000", "event_type": "price_change"}}
{"_local_timestamp": "2026-01-25T23:43:06.165587+00:00", "data": {"market": "0x306bbce53f9a77906b9a928d52728bdee2e48f3354d19a9d6f0db7c9a1d4230d", "price_changes": [{"asset_id": "34335512241828535299853623975656484642594791501285631499713239174540168255596", "price": "0.041", "size": "0", "side": "BUY", "hash": "0138c8aaf5218a0b7211a018a7e8550f192a6a63", "best_bid": "0.054", "best_ask": "0.068"}, {"asset_id": "64957256704343867164459890398860992515731454967968064924053896034568618595733", "price": "0.959", "size": "0", "side": "SELL", "hash": "81555643b81767a74823e738a15692d159716999", "best_bid": "0.932", "best_ask": "0.946"}], "timestamp": "1769384586002", "event_type": "price_change"}}
{"_local_timestamp": "2026-01-25T23:43:12.644842+00:00", "data": {"market": "0xba8add06562a7bfd4fdd8f0a1882b5e2596540bd61c67a32359487694838f0a5", "price_changes": [{"asset_id": "7221299913764832338348128493889748182769672206962167820297840741811689706878", "price": "0.18", "size": "152.66", "side": "BUY", "hash": "49d5594a58f91f26a185ef1fd97bd9bd6d2730f6", "best_bid": "0.22", "best_ask": "0.23"}, {"asset_id": "62853431799112511763784693741363968903595954956498708214160770466188703343964", "price": "0.82", "size": "152.66", "side": "SELL", "hash": "f00ea215d01f0ba98ae492a20942a3045b11f098", "best_bid": "0.77", "best_ask": "0.78"}], "timestamp": "1769384592531", "event_type": "price_change"}}
{"_local_timestamp": "2026-01-25T23:43:16.174084+00:00", "data": {"market": "0xba8add06562a7bfd4fdd8f0a1882b5e2596540bd61c67a32359487694838f0a5", "price_changes": [{"asset_id": "62853431799112511763784693741363968903595954956498708214160770466188703343964", "price": "0.75", "size": "455.85", "side": "BUY", "hash": "342cebffc60c43a401a0fbabbe6472eb4616e97f", "best_bid": "0.77", "best_ask": "0.78"}, {"asset_id": "7221299913764832338348128493889748182769672206962167820297840741811689706878", "price": "0.25", "size": "455.85", "side": "SELL", "hash": "160cf9ea7227fbfc200e043eedbe40f154e0c30f", "best_bid": "0.22", "best_ask": "0.23"}], "timestamp": "1769384596022", "event_type": "price_change"}}
{"_local_timestamp": "2026-01-25T23:43:20.484044+00:00", "data": {"market": "0xbbd623c4191ca76dec466507375d6df85b403b7e14f9cbd3d09f2c450ae0cd96", "price_changes": [{"asset_id": "86141088804897222236928959539148501008650371218692800935714557867410378164931", "price": "0.26", "size": "150", "side": "BUY", "hash": "2e1d9682c68f5b6f58e156775ceb2d4f826e3527", "best_bid": "0.7", "best_ask": "0.73"}, {"asset_id": "86988864427600902662654729368237087316370077858847155604307346968813506081632", "price": "0.74", "size": "150", "side": "SELL", "hash": "e4b4e1a92a4358b7aaa0934b25fcbc4352d2478f", "best_bid": "0.27", "best_ask": "0.3"}], "timestamp": "1769384600362", "event_type": "price_change"}}
{"_local_timestamp": "2026-01-25T23:43:20.518960+00:00", "data": {"market": "0xbbd623c4191ca76dec466507375d6df85b403b7e14f9cbd3d09f2c450ae0cd96", "price_changes": [{"asset_id": "86141088804897222236928959539148501008650371218692800935714557867410378164931", "price": "0.22", "size": "9", "side": "BUY", "hash": "7a18ed4d5f194d39ae0500c936b0aab83fcb8e08", "best_bid": "0.7", "best_ask": "0.73"}, {"asset_id": "86988864427600902662654729368237087316370077858847155604307346968813506081632", "price": "0.78", "size": "9", "side": "SELL", "hash": "b4525028cf0bd7ed88e6857ec4591cce310adf89", "best_bid": "0.27", "best_ask": "0.3"}], "timestamp": "1769384600412", "event_type": "price_change"}}
{"_local_timestamp": "2026-01-25T23:43:38.546885+00:00", "data": {"market": "0xba8add06562a7bfd4fdd8f0a1882b5e2596540bd61c67a32359487694838f0a5", "price_changes": [{"asset_id": "62853431799112511763784693741363968903595954956498708214160770466188703343964", "price": "0.24", "size": "50", "side": "BUY", "hash": "bf53298db0f2df6726f258e8a1a19b32d8abbcbe", "best_bid": "0.77", "best_ask": "0.78"}, {"asset_id": "7221299913764832338348128493889748182769672206962167820297840741811689706878", "price": "0.76", "size": "50", "side": "SELL", "hash": "99d867b155a1dec57f141e489e3a3a29f1be8b1b", "best_bid": "0.22", "best_ask": "0.23"}], "timestamp": "1769384618463", "event_type": "price_change"}}
{"_local_timestamp": "2026-01-25T23:43:38.568481+00:00", "data": {"market": "0xd25c820d3aee1c735c0fa62c36f4905632ab8c6988653b5b4134593b3209eb7f", "price_changes": [{"asset_id": "45361184347486002884792387151438756924785609968030585696129487864334578884255", "price": "0.55", "size": "45.5", "side": "BUY", "hash": "3d1c1a5571aaae9a386fb48cb0b5d0668fee3844", "best_bid": "0.6", "best_ask": "0.67"}, {"asset_id": "91117078941733659645786554099775611998962677612187928648088119165893475827434", "price": "0.45", "size": "45.5", "side": "SELL", "hash": "7f33db94127be312b5787cfcdba82a915cb391de", "best_bid": "0.33", "best_ask": "0.4"}], "timestamp": "1769384618495", "event_type": "price_change"}}
{"_local_timestamp": "2026-01-25T23:43:38.569444+00:00", "data": {"market": "0x3935226f1baa202667795b3a558d26fb0a9ae894a482676d34820bfb1b9b4edd", "price_changes": [{"asset_id": "5083116961935871155736992778398112358288960843713086370981563262578268017242", "price": "0.881", "size": "0", "side": "BUY", "hash": "0d03847d3117b8a42e91b0cde98a1b5c4f6345be", "best_bid": "0.995", "best_ask": "0.997"}, {"asset_id": "80071381584983995567060219264871699619214990229460921095601419271143281499406", "price": "0.119", "size": "0", "side": "SELL", "hash": "3b16fb743d5d32b8c9cadfc29476296d3110652f", "best_bid": "0.003", "best_ask": "0.005"}], "timestamp": "1769384618496", "event_type": "price_change"}}
{"_local_timestamp": "2026-01-25T23:43:38.570317+00:00", "data": {"market": "0x1fe1788d96d4c98e242549f91baf0de29eaf3b1545b5e2dda1d8714a3faf5305", "price_changes": [{"asset_id": "85121409960340786807237728711169263074482548425773836042297909052960286277119", "price": "0.883", "size": "0", "side": "BUY", "hash": "9e77d94a37818efcd01e36d205cfd341ff462fe1", "best_bid": "0.997", "best_ask": "0.998"}, {"asset_id": "30944797740926340411025345169348106947975350930232142082675991513705266362329", "price": "0.117", "size": "0", "side": "SELL", "hash": "c914637dee4d8f1e82694c401ef37b6b2436e468", "best_bid": "0.002", "best_ask": "0.003"}], "timestamp": "1769384618497", "event_type": "price_change"}}
{"_local_timestamp": "2026-01-25T23:43:38.571140+00:00", "data": {"market": "0x0eada57dcf53965a321f61c9dc6adb655367fabeb1f2ecbe7746f3f1a6ff7769", "price_changes": [{"asset_id": "93593125008177926269164142727030950699068997099893975938000261506053151609883", "price": "0.883", "size": "0", "side": "BUY", "hash": "32505871382527f6e670eb8155a6461f0e2a3bba", "best_bid": "0.997", "best_ask": "0.998"}, {"asset_id": "88775412427564636095391917176836120951442159831179966305257669968799086969217", "price": "0.117", "size": "0", "side": "SELL", "hash": "b961d7812094f2e8049db90ef02bc00c9f7a5a88", "best_bid": "0.002", "best_ask": "0.003"}], "timestamp": "1769384618497", "event_type": "price_change"}}
{"_local_timestamp": "2026-01-25T23:43:38.782712+00:00", "data": {"market": "0xba8add06562a7bfd4fdd8f0a1882b5e2596540bd61c67a32359487694838f0a5", "price_changes": [{"asset_id": "62853431799112511763784693741363968903595954956498708214160770466188703343964", "price": "0.23", "size": "213.04", "side": "BUY", "hash": "ec823d820321551794866622cb0338a0c67dabfd", "best_bid": "0.77", "best_ask": "0.78"}, {"asset_id": "7221299913764832338348128493889748182769672206962167820297840741811689706878", "price": "0.77", "size": "213.04", "side": "SELL", "hash": "47b7b7140442073d96cdeb507fb66c4b2141b960", "best_bid": "0.22", "best_ask": "0.23"}], "timestamp": "1769384618712", "event_type": "price_change"}}
{"_local_timestamp": "2026-01-25T23:43:39.206933+00:00", "data": {"market": "0xba8add06562a7bfd4fdd8f0a1882b5e2596540bd61c67a32359487694838f0a5", "price_changes": [{"asset_id": "62853431799112511763784693741363968903595954956498708214160770466188703343964", "price": "0.43", "size": "0", "side": "BUY", "hash": "9b8c40cf0174d6950d1fcee4b918f38d2cc1734c", "best_bid": "0.77", "best_ask": "0.78"}, {"asset_id": "7221299913764832338348128493889748182769672206962167820297840741811689706878", "price": "0.57", "size": "0", "side": "SELL", "hash": "47131781c54bc8331b2ddea24d214de0dc95dc42", "best_bid": "0.22", "best_ask": "0.23"}], "timestamp": "1769384619135", "event_type": "price_change"}}
{"_local_timestamp": "2026-01-25T23:43:39.252950+00:00", "data": {"market": "0xba8add06562a7bfd4fdd8f0a1882b5e2596540bd61c67a32359487694838f0a5", "price_changes": [{"asset_id": "62853431799112511763784693741363968903595954956498708214160770466188703343964", "price": "0.32", "size": "6", "side": "BUY", "hash": "4674355eadb4f7210eec30eae8b578a21c0e12e3", "best_bid": "0.77", "best_ask": "0.78"}, {"asset_id": "7221299913764832338348128493889748182769672206962167820297840741811689706878", "price": "0.68", "size": "6", "side": "SELL", "hash": "2b04b8e40d8f5b1a94fb3f7ea0cf3347f04c52f5", "best_bid": "0.22", "best_ask": "0.23"}], "timestamp": "1769384619187", "event_type": "price_change"}}
{"_local_timestamp": "2026-01-25T23:43:41.082196+00:00", "data": {"market": "0x0eada57dcf53965a321f61c9dc6adb655367fabeb1f2ecbe7746f3f1a6ff7769", "price_changes": [{"asset_id": "88775412427564636095391917176836120951442159831179966305257669968799086969217", "price": "0.003", "size": "948.42", "side": "SELL", "hash": "af45f9d88dd2399c57f16f5d29e22f7d76a899f7", "best_bid": "0.002", "best_ask": "0.003"}, {"asset_id": "93593125008177926269164142727030950699068997099893975938000261506053151609883", "price": "0.997", "size": "948.42", "side": "BUY", "hash": "816d439de7ea89a2c56b73dd7bc3daf7b72aa267", "best_bid": "0.997", "best_ask": "0.998"}], "timestamp": "1769384621001", "event_type": "price_change"}}
{"_local_timestamp": "2026-01-25T23:43:43.876864+00:00", "data": {"market": "0x0eada57dcf53965a321f61c9dc6adb655367fabeb1f2ecbe7746f3f1a6ff7769", "price_changes": [{"asset_id": "88775412427564636095391917176836120951442159831179966305257669968799086969217", "price": "0.003", "size": "1148.42", "side": "SELL", "hash": "1117313a0b7c50382ceffa0d5f8de10896c8ead3", "best_bid": "0.002", "best_ask": "0.003"}, {"asset_id": "93593125008177926269164142727030950699068997099893975938000261506053151609883", "price": "0.997", "size": "1148.42", "side": "BUY", "hash": "44dfffdf61b26965155a5271446abeefd6bcb4fd", "best_bid": "0.997", "best_ask": "0.998"}], "timestamp": "1769384623807", "event_type": "price_change"}}
{"_local_timestamp": "2026-01-25T23:43:46.647147+00:00", "data": {"market": "0xd25c820d3aee1c735c0fa62c36f4905632ab8c6988653b5b4134593b3209eb7f", "price_changes": [{"asset_id": "45361184347486002884792387151438756924785609968030585696129487864334578884255", "price": "0.56", "size": "0", "side": "BUY", "hash": "bee8c134bca18b8a7444ea5baeb52d345e8d2a83", "best_bid": "0.6", "best_ask": "0.67"}, {"asset_id": "91117078941733659645786554099775611998962677612187928648088119165893475827434", "price": "0.44", "size": "0", "side": "SELL", "hash": "2b65cf4283c3bdeabc67a9bcebeb2ce0cbebfa27", "best_bid": "0.33", "best_ask": "0.4"}], "timestamp": "1769384626578", "event_type": "price_change"}}
{"_local_timestamp": "2026-01-25T23:43:46.672028+00:00", "data": {"market": "0xd25c820d3aee1c735c0fa62c36f4905632ab8c6988653b5b4134593b3209eb7f", "price_changes": [{"asset_id": "45361184347486002884792387151438756924785609968030585696129487864334578884255", "price": "0.6", "size": "5", "side": "BUY", "hash": "62b3cd48e185051471bb4587f65c90a7bfc9dedf", "best_bid": "0.6", "best_ask": "0.67"}, {"asset_id": "91117078941733659645786554099775611998962677612187928648088119165893475827434", "price": "0.4", "size": "5", "side": "SELL", "hash": "f4375f7f52c797ab27a2d1d7a49124d6aca89be3", "best_bid": "0.33", "best_ask": "0.4"}], "timestamp": "1769384626608", "event_type": "price_change"}}
{"_local_timestamp": "2026-01-25T23:43:46.889840+00:00", "data": {"market": "0x0eada57dcf53965a321f61c9dc6adb655367fabeb1f2ecbe7746f3f1a6ff7769", "price_changes": [{"asset_id": "93593125008177926269164142727030950699068997099893975938000261506053151609883", "price": "0.481", "size": "0", "side": "BUY", "hash": "4fb9531721c1ea36c5523ddae48b4e3d6bf53ca6", "best_bid": "0.997", "best_ask": "0.998"}, {"asset_id": "88775412427564636095391917176836120951442159831179966305257669968799086969217", "price": "0.519", "size": "0", "side": "SELL", "hash": "f36ad28c1fe7c338b51bf732650e9ec061546bfe", "best_bid": "0.002", "best_ask": "0.003"}], "timestamp": "1769384626772", "event_type": "price_change"}}
{"_local_timestamp": "2026-01-25T23:43:46.901439+00:00", "data": {"market": "0x0eada57dcf53965a321f61c9dc6adb655367fabeb1f2ecbe7746f3f1a6ff7769", "price_changes": [{"asset_id": "93593125008177926269164142727030950699068997099893975938000261506053151609883", "price": "0.405", "size": "175", "side": "BUY", "hash": "31717ea72ca5d770faf2d2e55e7dbfbf5bbc0bfd", "best_bid": "0.997", "best_ask": "0.998"}, {"asset_id": "88775412427564636095391917176836120951442159831179966305257669968799086969217", "price": "0.595", "size": "175", "side": "SELL", "hash": "7f495ed5d260efe29660d31f3b3416ada2e52673", "best_bid": "0.002", "best_ask": "0.003"}], "timestamp": "1769384626834", "event_type": "price_change"}}
{"_local_timestamp": "2026-01-25T23:43:46.902536+00:00", "data": {"market": "0x0eada57dcf53965a321f61c9dc6adb655367fabeb1f2ecbe7746f3f1a6ff7769", "price_changes": [{"asset_id": "93593125008177926269164142727030950699068997099893975938000261506053151609883", "price": "0.485", "size": "11", "side": "BUY", "hash": "2681b154c2a4f2746a4eaaaa298d42cd79feaaa7", "best_bid": "0.997", "best_ask": "0.998"}, {"asset_id": "88775412427564636095391917176836120951442159831179966305257669968799086969217", "price": "0.515", "size": "11", "side": "SELL", "hash": "a43d1db4c3b56ca5c5e1b7aeff0e06524991e488", "best_bid": "0.002", "best_ask": "0.003"}], "timestamp": "1769384626835", "event_type": "price_change"}}
{"_local_timestamp": "2026-01-25T23:43:46.909785+00:00", "data": {"market": "0x0eada57dcf53965a321f61c9dc6adb655367fabeb1f2ecbe7746f3f1a6ff7769", "price_changes": [{"asset_id": "93593125008177926269164142727030950699068997099893975938000261506053151609883", "price": "0.485", "size": "21", "side": "BUY", "hash": "6121a94e3be68aa6680559ef26086dd4c03c946a", "best_bid": "0.997", "best_ask": "0.998"}, {"asset_id": "88775412427564636095391917176836120951442159831179966305257669968799086969217", "price": "0.515", "size": "21", "side": "SELL", "hash": "813da227d8de69411d01ebf79738aee775fd4895", "best_bid": "0.002", "best_ask": "0.003"}], "timestamp": "1769384626836", "event_type": "price_change"}}
{"_local_timestamp": "2026-01-25T23:43:48.973179+00:00", "data": {"market": "0x0eada57dcf53965a321f61c9dc6adb655367fabeb1f2ecbe7746f3f1a6ff7769", "price_changes": [{"asset_id": "93593125008177926269164142727030950699068997099893975938000261506053151609883", "price": "0.484", "size": "0", "side": "BUY", "hash": "aef50b9c4bb34bb34ea0544c576314eae2ffda2b", "best_bid": "0.997", "best_ask": "0.998"}, {"asset_id": "88775412427564636095391917176836120951442159831179966305257669968799086969217", "price": "0.516", "size": "0", "side": "SELL", "hash": "0242a5ecd0aba04d6f81ff5eb020c527c013cd9e", "best_bid": "0.002", "best_ask": "0.003"}], "timestamp": "1769384628905", "event_type": "price_change"}}
{"_local_timestamp": "2026-01-25T23:43:49.009166+00:00", "data": {"market": "0x0eada57dcf53965a321f61c9dc6adb655367fabeb1f2ecbe7746f3f1a6ff7769", "price_changes": [{"asset_id": "93593125008177926269164142727030950699068997099893975938000261506053151609883", "price": "0.486", "size": "20", "side": "BUY", "hash": "440c85b8511ebc9f11ff3a5dd0b2e1b5ead6694e", "best_bid": "0.997", "best_ask": "0.998"}, {"asset_id": "88775412427564636095391917176836120951442159831179966305257669968799086969217", "price": "0.514", "size": "20", "side": "SELL", "hash": "e89d9982a2ec6ee5e934886344abf3b73af0ce97", "best_bid": "0.002", "best_ask": "0.003"}], "timestamp": "1769384628933", "event_type": "price_change"}}
{"_local_timestamp": "2026-01-25T23:43:52.533941+00:00", "data": {"market": "0xba8add06562a7bfd4fdd8f0a1882b5e2596540bd61c67a32359487694838f0a5", "price_changes": [{"asset_id": "7221299913764832338348128493889748182769672206962167820297840741811689706878", "price": "0.01", "size": "5", "side": "BUY", "hash": "ee25afed35f50d9b5fb094f51530e31ae24f608d", "best_bid": "0.22", "best_ask": "0.23"}, {"asset_id": "62853431799112511763784693741363968903595954956498708214160770466188703343964", "price": "0.99", "size": "5", "side": "SELL", "hash": "89266d4b8edb3a5086869a1accd6e3f6b142dffd", "best_bid": "0.77", "best_ask": "0.78"}], "timestamp": "1769384632378", "event_type": "price_change"}}
{"_local_timestamp": "2026-01-25T23:43:56.583517+00:00", "data": {"market": "0xba8add06562a7bfd4fdd8f0a1882b5e2596540bd61c67a32359487694838f0a5", "price_changes": [{"asset_id": "62853431799112511763784693741363968903595954956498708214160770466188703343964", "price": "0.21", "size": "2003.48", "side": "BUY", "hash": "72dc7aeebb6ec00e1b16fb5bb4a41618c9ac213e", "best_bid": "0.77", "best_ask": "0.78"}, {"asset_id": "7221299913764832338348128493889748182769672206962167820297840741811689706878", "price": "0.79", "size": "2003.48", "side": "SELL", "hash": "f4aa7057b945e5e78009a2954a400268d464f2f7", "best_bid": "0.22", "best_ask": "0.23"}], "timestamp": "1769384636449", "event_type": "price_change"}}
{"_local_timestamp": "2026-01-25T23:44:09.084016+00:00", "data": {"market": "0xd25c820d3aee1c735c0fa62c36f4905632ab8c6988653b5b4134593b3209eb7f", "price_changes": [{"asset_id": "45361184347486002884792387151438756924785609968030585696129487864334578884255", "price": "0.15", "size": "1785.53", "side": "BUY", "hash": "96ee0bf416a756b2e8c3cc17a0d1400b6a85796e", "best_bid": "0.6", "best_ask": "0.67"}, {"asset_id": "91117078941733659645786554099775611998962677612187928648088119165893475827434", "price": "0.85", "size": "1785.53", "side": "SELL", "hash": "a965d32e3c670fd0b5e743ec534c71f998887a1e", "best_bid": "0.33", "best_ask": "0.4"}], "timestamp": "1769384648769", "event_type": "price_change"}}
{"_local_timestamp": "2026-01-25T23:44:09.153683+00:00", "data": {"market": "0xd25c820d3aee1c735c0fa62c36f4905632ab8c6988653b5b4134593b3209eb7f", "price_changes": [{"asset_id": "45361184347486002884792387151438756924785609968030585696129487864334578884255", "price": "0.17", "size": "564.7", "side": "BUY", "hash": "395d1c4788d69e406f75694b9ab3629d1a05c13f", "best_bid": "0.6", "best_ask": "0.67"}, {"asset_id": "91117078941733659645786554099775611998962677612187928648088119165893475827434", "price": "0.83", "size": "564.7", "side": "SELL", "hash": "f5e690447af9736ff60c0ad2f4c3bb4b814fe04f", "best_bid": "0.33", "best_ask": "0.4"}], "timestamp": "1769384648849", "event_type": "price_change"}}
{"_local_timestamp": "2026-01-25T23:44:09.161874+00:00", "data": {"market": "0xd25c820d3aee1c735c0fa62c36f4905632ab8c6988653b5b4134593b3209eb7f", "price_changes": [{"asset_id": "45361184347486002884792387151438756924785609968030585696129487864334578884255", "price": "0.25", "size": "250", "side": "BUY", "hash": "daa45e18383a2ce202f3f646fdec9e729216954d", "best_bid": "0.6", "best_ask": "0.67"}, {"asset_id": "91117078941733659645786554099775611998962677612187928648088119165893475827434", "price": "0.75", "size": "250", "side": "SELL", "hash": "564438a363febcd215d9c9c8e09ccc980f3ea828", "best_bid": "0.33", "best_ask": "0.4"}], "timestamp": "1769384648928", "event_type": "price_change"}}
{"_local_timestamp": "2026-01-25T23:44:10.650701+00:00", "data": {"market": "0x1fe1788d96d4c98e242549f91baf0de29eaf3b1545b5e2dda1d8714a3faf5305", "price_changes": [{"asset_id": "30944797740926340411025345169348106947975350930232142082675991513705266362329", "price": "0.025", "size": "0", "side": "SELL", "hash": "3b01064499c5bd91e1bbd4f0ceccffda8876a78b", "best_bid": "0.002", "best_ask": "0.003"}, {"asset_id": "85121409960340786807237728711169263074482548425773836042297909052960286277119", "price": "0.975", "size": "0", "side": "BUY", "hash": "2d6b8bd1d82821b36ff6020adb18006a0bae7879", "best_bid": "0.997", "best_ask": "0.998"}], "timestamp": "1769384650522", "event_type": "price_change"}}
{"_local_timestamp": "2026-01-25T23:44:10.768190+00:00", "data": {"market": "0x1fe1788d96d4c98e242549f91baf0de29eaf3b1545b5e2dda1d8714a3faf5305", "price_changes": [{"asset_id": "30944797740926340411025345169348106947975350930232142082675991513705266362329", "price": "0.02", "size": "20.96", "side": "SELL", "hash": "4be6e6a77d56a058ca6eb6e2c42d8e41e4480b75", "best_bid": "0.002", "best_ask": "0.003"}, {"asset_id": "85121409960340786807237728711169263074482548425773836042297909052960286277119", "price": "0.98", "size": "20.96", "side": "BUY", "hash": "b9e211d7973b6c40d5c0b6c5e394ba0b32a06fc8", "best_bid": "0.997", "best_ask": "0.998"}], "timestamp": "1769384650649", "event_type": "price_change"}}
{"_local_timestamp": "2026-01-25T23:44:18.945437+00:00", "data": {"market": "0xd25c820d3aee1c735c0fa62c36f4905632ab8c6988653b5b4134593b3209eb7f", "price_changes": [{"asset_id": "91117078941733659645786554099775611998962677612187928648088119165893475827434", "price": "0.44", "size": "9.5", "side": "SELL", "hash": "a221ddd05c0c9b6257eb8b71f95632e67fc46a9a", "best_bid": "0.33", "best_ask": "0.4"}, {"asset_id": "45361184347486002884792387151438756924785609968030585696129487864334578884255", "price": "0.56", "size": "9.5", "side": "BUY", "hash": "59ca52396c38328c9f651974be7c6a43bdcff27b", "best_bid": "0.6", "best_ask": "0.67"}], "timestamp": "1769384658875", "event_type": "price_change"}}
{"_local_timestamp": "2026-01-25T23:44:20.679100+00:00", "data": {"market": "0x0eada57dcf53965a321f61c9dc6adb655367fabeb1f2ecbe7746f3f1a6ff7769", "price_changes": [{"asset_id": "93593125008177926269164142727030950699068997099893975938000261506053151609883", "price": "0.404", "size": "5907", "side": "BUY", "hash": "83e11eea39ce236a4ac89cdfa8eaaa69f43c3800", "best_bid": "0.997", "best_ask": "0.998"}, {"asset_id": "88775412427564636095391917176836120951442159831179966305257669968799086969217", "price": "0.596", "size": "5907", "side": "SELL", "hash": "d209749ae5c803cc4795da3e60de4ada16fe5924", "best_bid": "0.002", "best_ask": "0.003"}], "timestamp": "1769384660485", "event_type": "price_change"}}
{"_local_timestamp": "2026-01-25T23:44:20.757683+00:00", "data": {"market": "0xbbd623c4191ca76dec466507375d6df85b403b7e14f9cbd3d09f2c450ae0cd96", "price_changes": [{"asset_id": "86141088804897222236928959539148501008650371218692800935714557867410378164931", "price": "0.26", "size": "50", "side": "BUY", "hash": "4b4db274b1d13a6715430577d3aa023111f0bfea", "best_bid": "0.7", "best_ask": "0.73"}, {"asset_id": "86988864427600902662654729368237087316370077858847155604307346968813506081632", "price": "0.74", "size": "50", "side": "SELL", "hash": "272060ac7c6a7cbd9a5882cbacaac9554eca2be6", "best_bid": "0.27", "best_ask": "0.3"}], "timestamp": "1769384660484", "event_type": "price_change"}}
{"_local_timestamp": "2026-01-25T23:44:21.494905+00:00", "data": {"market": "0xbbd623c4191ca76dec466507375d6df85b403b7e14f9cbd3d09f2c450ae0cd96", "price_changes": [{"asset_id": "86141088804897222236928959539148501008650371218692800935714557867410378164931", "price": "0.21", "size": "205.87", "side": "BUY", "hash": "40e3b7953b5d705b9fe56aac6f3e54f8a9ba5fe1", "best_bid": "0.7", "best_ask": "0.73"}, {"asset_id": "86988864427600902662654729368237087316370077858847155604307346968813506081632", "price": "0.79", "size": "205.87", "side": "SELL", "hash": "d3e23e55ddb5e5f2f4afe800355662060ff516e6", "best_bid": "0.27", "best_ask": "0.3"}], "timestamp": "1769384660912", "event_type": "price_change"}}
{"_local_timestamp": "2026-01-25T23:44:21.531016+00:00", "data": {"market": "0x0eada57dcf53965a321f61c9dc6adb655367fabeb1f2ecbe7746f3f1a6ff7769", "price_changes": [{"asset_id": "93593125008177926269164142727030950699068997099893975938000261506053151609883", "price": "0.405", "size": "235", "side": "BUY", "hash": "865d5a6d06939d50cb01275895d6882141f4f1a5", "best_bid": "0.997", "best_ask": "0.998"}, {"asset_id": "88775412427564636095391917176836120951442159831179966305257669968799086969217", "price": "0.595", "size": "235", "side": "SELL", "hash": "8700258c38fd7101e3f16a8913c2cfb74cbe9841", "best_bid": "0.002", "best_ask": "0.003"}], "timestamp": "1769384660914", "event_type": "price_change"}}
{"_local_timestamp": "2026-01-25T23:44:25.614241+00:00", "data": {"market": "0x306bbce53f9a77906b9a928d52728bdee2e48f3354d19a9d6f0db7c9a1d4230d", "price_changes": [{"asset_id": "34335512241828535299853623975656484642594791501285631499713239174540168255596", "price": "0.041", "size": "20", "side": "BUY", "hash": "c683dc5581894281a26a88ac32839a160937df70", "best_bid": "0.054", "best_ask": "0.068"}, {"asset_id": "64957256704343867164459890398860992515731454967968064924053896034568618595733", "price": "0.959", "size": "20", "side": "SELL", "hash": "938891ecf893a5613c99ca36093ee47a5be04991", "best_bid": "0.932", "best_ask": "0.946"}], "timestamp": "1769384665545", "event_type": "price_change"}}
{"_local_timestamp": "2026-01-25T23:44:25.615249+00:00", "data": {"market": "0x306bbce53f9a77906b9a928d52728bdee2e48f3354d19a9d6f0db7c9a1d4230d", "price_changes": [{"asset_id": "64957256704343867164459890398860992515731454967968064924053896034568618595733", "price": "0.919", "size": "20", "side": "BUY", "hash": "678421226ab3cfa42997f37518b7458909d29349", "best_bid": "0.932", "best_ask": "0.946"}, {"asset_id": "34335512241828535299853623975656484642594791501285631499713239174540168255596", "price": "0.081", "size": "20", "side": "SELL", "hash": "af4d168d66a1698fff47832b0fbd623998f4dc41", "best_bid": "0.054", "best_ask": "0.068"}], "timestamp": "1769384665546", "event_type": "price_change"}}
{"_local_timestamp": "2026-01-25T23:44:28.813487+00:00", "data": {"market": "0x306bbce53f9a77906b9a928d52728bdee2e48f3354d19a9d6f0db7c9a1d4230d", "price_changes": [{"asset_id": "34335512241828535299853623975656484642594791501285631499713239174540168255596", "price": "0.004", "size": "7.69", "side": "BUY", "hash": "67be3eb9327a8ab71878a3c2d95299c5d74fdeb7", "best_bid": "0.054", "best_ask": "0.068"}, {"asset_id": "64957256704343867164459890398860992515731454967968064924053896034568618595733", "price": "0.996", "size": "7.69", "side": "SELL", "hash": "64e7293e8921fae4d83c4a40dc42ad72df7e5fc0", "best_bid": "0.932", "best_ask": "0.946"}], "timestamp": "1769384668748", "event_type": "price_change"}}
{"_local_timestamp": "2026-01-25T23:44:31.110183+00:00", "data": {"market": "0x306bbce53f9a77906b9a928d52728bdee2e48f3354d19a9d6f0db7c9a1d4230d", "price_changes": [{"asset_id": "34335512241828535299853623975656484642594791501285631499713239174540168255596", "price": "0.003", "size": "256.24", "side": "BUY", "hash": "cfa978f0077e1b8f8923aaf6d053857ee0afb2b6", "best_bid": "0.054", "best_ask": "0.068"}, {"asset_id": "64957256704343867164459890398860992515731454967968064924053896034568618595733", "price": "0.997", "size": "256.24", "side": "SELL", "hash": "f4667533032945b875b0546ff7f2a4de5e7c51ec", "best_bid": "0.932", "best_ask": "0.946"}], "timestamp": "1769384671030", "event_type": "price_change"}}
{"_local_timestamp": "2026-01-25T23:44:31.111231+00:00", "data": {"market": "0x306bbce53f9a77906b9a928d52728bdee2e48f3354d19a9d6f0db7c9a1d4230d", "price_changes": [{"asset_id": "34335512241828535299853623975656484642594791501285631499713239174540168255596", "price": "0.005", "size": "30.1", "side": "BUY", "hash": "fcf966aa9f4c02c88276b46ad0b3efc27044db57", "best_bid": "0.054", "best_ask": "0.068"}, {"asset_id": "64957256704343867164459890398860992515731454967968064924053896034568618595733", "price": "0.995", "size": "30.1", "side": "SELL", "hash": "36617e344d9a93a419e778c84ef295e12d5b616a", "best_bid": "0.932", "best_ask": "0.946"}], "timestamp": "1769384671032", "event_type": "price_change"}}
{"_local_timestamp": "2026-01-25T23:44:31.990335+00:00", "data": {"market": "0x306bbce53f9a77906b9a928d52728bdee2e48f3354d19a9d6f0db7c9a1d4230d", "price_changes": [{"asset_id": "34335512241828535299853623975656484642594791501285631499713239174540168255596", "price": "0.003", "size": "250", "side": "BUY", "hash": "ca6ed8f001a7698654fabbd468aa0d1e590e772c", "best_bid": "0.054", "best_ask": "0.068"}, {"asset_id": "64957256704343867164459890398860992515731454967968064924053896034568618595733", "price": "0.997", "size": "250", "side": "SELL", "hash": "fb0011ff64cd1194fe16bb5179db259e05961b53", "best_bid": "0.932", "best_ask": "0.946"}], "timestamp": "1769384671919", "event_type": "price_change"}}
{"_local_timestamp": "2026-01-25T23:44:31.991367+00:00", "data": {"market": "0x306bbce53f9a77906b9a928d52728bdee2e48f3354d19a9d6f0db7c9a1d4230d", "price_changes": [{"asset_id": "34335512241828535299853623975656484642594791501285631499713239174540168255596", "price": "0.005", "size": "0", "side": "BUY", "hash": "ca6ed8f001a7698654fabbd468aa0d1e590e772c", "best_bid": "0.054", "best_ask": "0.068"}, {"asset_id": "64957256704343867164459890398860992515731454967968064924053896034568618595733", "price": "0.995", "size": "0", "side": "SELL", "hash": "fb0011ff64cd1194fe16bb5179db259e05961b53", "best_bid": "0.932", "best_ask": "0.946"}], "timestamp": "1769384671919", "event_type": "price_change"}}
{"_local_timestamp": "2026-01-25T23:44:32.447046+00:00", "data": {"market": "0xba8add06562a7bfd4fdd8f0a1882b5e2596540bd61c67a32359487694838f0a5", "price_changes": [{"asset_id": "62853431799112511763784693741363968903595954956498708214160770466188703343964", "price": "0.21", "size": "5.48", "side": "BUY", "hash": "a0ef4455ba2cbce4c4d8d33110b0dce2f07282aa", "best_bid": "0.77", "best_ask": "0.78"}, {"asset_id": "7221299913764832338348128493889748182769672206962167820297840741811689706878", "price": "0.79", "size": "5.48", "side": "SELL", "hash": "baa09e914fd6cb31691a1858d4e94b968fa76bcc", "best_bid": "0.22", "best_ask": "0.23"}], "timestamp": "1769384672296", "event_type": "price_change"}}
{"_local_timestamp": "2026-01-25T23:44:33.358475+00:00", "data": {"market": "0x306bbce53f9a77906b9a928d52728bdee2e48f3354d19a9d6f0db7c9a1d4230d", "price_changes": [{"asset_id": "34335512241828535299853623975656484642594791501285631499713239174540168255596", "price": "0.004", "size": "50", "side": "BUY", "hash": "b46679b4f1fb5aae1797d1319b25822f2491bf57", "best_bid": "0.054", "best_ask": "0.068"}, {"asset_id": "64957256704343867164459890398860992515731454967968064924053896034568618595733", "price": "0.996", "size": "50", "side": "SELL", "hash": "56bfb2a56c5d8841c26fc850d6baf55b6e498cba", "best_bid": "0.932", "best_ask": "0.946"}], "timestamp": "1769384673292", "event_type": "price_change"}}
{"_local_timestamp": "2026-01-25T23:44:35.913837+00:00", "data": {"market": "0xd25c820d3aee1c735c0fa62c36f4905632ab8c6988653b5b4134593b3209eb7f", "price_changes": [{"asset_id": "45361184347486002884792387151438756924785609968030585696129487864334578884255", "price": "0.07", "size": "1214.28", "side": "BUY", "hash": "b08412128c74a7053c9e4bef567210635c4c65b5", "best_bid": "0.6", "best_ask": "0.67"}, {"asset_id": "91117078941733659645786554099775611998962677612187928648088119165893475827434", "price": "0.93", "size": "1214.28", "side": "SELL", "hash": "229188febc59d39f5785cfa5da3a59edc6809af9", "best_bid": "0.33", "best_ask": "0.4"}], "timestamp": "1769384675809", "event_type": "price_change"}}
{"_local_timestamp": "2026-01-25T23:44:48.304410+00:00", "data": {"market": "0xba8add06562a7bfd4fdd8f0a1882b5e2596540bd61c67a32359487694838f0a5", "price_changes": [{"asset_id": "62853431799112511763784693741363968903595954956498708214160770466188703343964", "price": "0.24", "size": "1798", "side": "BUY", "hash": "414a15526d6ab076a70dfcdb395a99e39a07b4c9", "best_bid": "0.77", "best_ask": "0.78"}, {"asset_id": "7221299913764832338348128493889748182769672206962167820297840741811689706878", "price": "0.76", "size": "1798", "side": "SELL", "hash": "98de058e58685defd5d4fa582272dadeda9bb8d3", "best_bid": "0.22", "best_ask": "0.23"}], "timestamp": "1769384688239", "event_type": "price_change"}}
{"_local_timestamp": "2026-01-25T23:44:57.546881+00:00", "data": {"market": "0xba8add06562a7bfd4fdd8f0a1882b5e2596540bd61c67a32359487694838f0a5", "price_changes": [{"asset_id": "62853431799112511763784693741363968903595954956498708214160770466188703343964", "price": "0.23", "size": "113.04", "side": "BUY", "hash": "198d4616ead84fd7600d31dac0d1d2316fed29b3", "best_bid": "0.77", "best_ask": "0.78"}, {"asset_id": "7221299913764832338348128493889748182769672206962167820297840741811689706878", "price": "0.77", "size": "113.04", "side": "SELL", "hash": "94b7d9f876fafd7ad2b421dddeac15c54f974ad9", "best_bid": "0.22", "best_ask": "0.23"}], "timestamp": "1769384697466", "event_type": "price_change"}}
{"_local_timestamp": "2026-01-25T23:44:57.554938+00:00", "data": {"market": "0xd25c820d3aee1c735c0fa62c36f4905632ab8c6988653b5b4134593b3209eb7f", "price_changes": [{"asset_id": "45361184347486002884792387151438756924785609968030585696129487864334578884255", "price": "0.25", "size": "150", "side": "BUY", "hash": "aaef446320b562081fba9d086fccfe5a229343e4", "best_bid": "0.6", "best_ask": "0.67"}, {"asset_id": "91117078941733659645786554099775611998962677612187928648088119165893475827434", "price": "0.75", "size": "150", "side": "SELL", "hash": "6882715b0f582e672f5ebc3e752468e19e18f348", "best_bid": "0.33", "best_ask": "0.4"}], "timestamp": "1769384697466", "event_type": "price_change"}}
{"_local_timestamp": "2026-01-25T23:44:57.646991+00:00", "data": {"market": "0x405b6e3ce8caf18dea56ec418ea5a5c715f43aad946059e3eb7e3d1281698a78", "price_changes": [{"asset_id": "24373928341866408058552921472563928863071297280035754284253945296860184628420", "price": "0.833", "size": "20", "side": "BUY", "hash": "40477fec7aaf858eb777acd9de7df5abd60107d6", "best_bid": "0.996", "best_ask": "0.997"}, {"asset_id": "2350235314632053038507062516507369036092528887799666119386073644944240496673", "price": "0.167", "size": "20", "side": "SELL", "hash": "6f39482c8da7d847f73f0284fb9d3b2ebc791e3d", "best_bid": "0.003", "best_ask": "0.004"}], "timestamp": "1769384697583", "event_type": "price_change"}}
{"_local_timestamp": "2026-01-25T23:44:57.717627+00:00", "data": {"market": "0xba8add06562a7bfd4fdd8f0a1882b5e2596540bd61c67a32359487694838f0a5", "price_changes": [{"asset_id": "62853431799112511763784693741363968903595954956498708214160770466188703343964", "price": "0.24", "size": "1748", "side": "BUY", "hash": "8903c7d73e0615cc6b04ad360444bdccc24a78e1", "best_bid": "0.77", "best_ask": "0.78"}, {"asset_id": "7221299913764832338348128493889748182769672206962167820297840741811689706878", "price": "0.76", "size": "1748", "side": "SELL", "hash": "fcdc91b613ac7b33fd40533525bdf73635d5a24e", "best_bid": "0.22", "best_ask": "0.23"}], "timestamp": "1769384697640", "event_type": "price_change"}}
{"_local_timestamp": "2026-01-25T23:44:57.770571+00:00", "data": {"market": "0x405b6e3ce8caf18dea56ec418ea5a5c715f43aad946059e3eb7e3d1281698a78", "price_changes": [{"asset_id": "24373928341866408058552921472563928863071297280035754284253945296860184628420", "price": "0.741", "size": "11", "side": "BUY", "hash": "9c4ec4dc84dab8937cbee6811439e6ad31f9d876", "best_bid": "0.996", "best_ask": "0.997"}, {"asset_id": "2350235314632053038507062516507369036092528887799666119386073644944240496673", "price": "0.259", "size": "11", "side": "SELL", "hash": "242d9d080bb085cf732650fab6a34e908103b3bb", "best_bid": "0.003", "best_ask": "0.004"}], "timestamp": "1769384697703", "event_type": "price_change"}}
{"_local_timestamp": "2026-01-25T23:44:57.775888+00:00", "data": {"market": "0x405b6e3ce8caf18dea56ec418ea5a5c715f43aad946059e3eb7e3d1281698a78", "price_changes": [{"asset_id": "24373928341866408058552921472563928863071297280035754284253945296860184628420", "price": "0.824", "size": "10", "side": "BUY", "hash": "1ae57c147667f84fc403caddf463355a6e815fa3", "best_bid": "0.996", "best_ask": "0.997"}, {"asset_id": "2350235314632053038507062516507369036092528887799666119386073644944240496673", "price": "0.176", "size": "10", "side": "SELL", "hash": "e579ea3f8a9da98f1a53119fc6638431b9e83f35", "best_bid": "0.003", "best_ask": "0.004"}], "timestamp": "1769384697703", "event_type": "price_change"}}
{"_local_timestamp": "2026-01-25T23:44:57.848782+00:00", "data": {"market": "0xba8add06562a7bfd4fdd8f0a1882b5e2596540bd61c67a32359487694838f0a5", "price_changes": [{"asset_id": "62853431799112511763784693741363968903595954956498708214160770466188703343964", "price": "0.21", "size": "105.48", "side": "BUY", "hash": "76ec181e5d05b2e2c7dcd77af5c21e6e1b034378", "best_bid": "0.77", "best_ask": "0.78"}, {"asset_id": "7221299913764832338348128493889748182769672206962167820297840741811689706878", "price": "0.79", "size": "105.48", "side": "SELL", "hash": "dddb16f4490169d96ae6c3d405ae5889ad2ece90", "best_bid": "0.22", "best_ask": "0.23"}], "timestamp": "1769384697741", "event_type": "price_change"}}
{"_local_timestamp": "2026-01-25T23:44:58.407733+00:00", "data": {"market": "0xba8add06562a7bfd4fdd8f0a1882b5e2596540bd61c67a32359487694838f0a5", "price_changes": [{"asset_id": "62853431799112511763784693741363968903595954956498708214160770466188703343964", "price": "0.2", "size": "190", "side": "BUY", "hash": "a1251a01ea298815936129c007f2c5db8b9b762e", "best_bid": "0.77", "best_ask": "0.78"}, {"asset_id": "7221299913764832338348128493889748182769672206962167820297840741811689706878", "price": "0.8", "size": "190", "side": "SELL", "hash": "7d15939f752999298154c25b576793ffce602bc1", "best_bid": "0.22", "best_ask": "0.23"}], "timestamp": "1769384698234", "event_type": "price_change"}}
{"_local_timestamp": "2026-01-25T23:44:59.905649+00:00", "data": {"market": "0xd25c820d3aee1c735c0fa62c36f4905632ab8c6988653b5b4134593b3209eb7f", "price_changes": [{"asset_id": "45361184347486002884792387151438756924785609968030585696129487864334578884255", "price": "0.57", "size": "66.66", "side": "BUY", "hash": "c42d18f7330e7c8e27784afa9deafecff594a982", "best_bid": "0.6", "best_ask": "0.67"}, {"asset_id": "91117078941733659645786554099775611998962677612187928648088119165893475827434", "price": "0.43", "size": "66.66", "side": "SELL", "hash": "cd3d465f958ef29d48765d577300e22d38a62a69", "best_bid": "0.33", "best_ask": "0.4"}], "timestamp": "1769384699829", "event_type": "price_change"}}
{"_local_timestamp": "2026-01-25T23:45:11.235716+00:00", "data": {"market": "0x405b6e3ce8caf18dea56ec418ea5a5c715f43aad946059e3eb7e3d1281698a78", "price_changes": [{"asset_id": "2350235314632053038507062516507369036092528887799666119386073644944240496673", "price": "0.001", "size": "29344.32", "side": "BUY", "hash": "067ed484845b2c62be20bd8916d520f9ebb6254c", "best_bid": "0.003", "best_ask": "0.004"}, {"asset_id": "24373928341866408058552921472563928863071297280035754284253945296860184628420", "price": "0.999", "size": "29344.32", "side": "SELL", "hash": "866f32161a2b043c02ee1d9609d02b97c7f8649f", "best_bid": "0.996", "best_ask": "0.997"}], "timestamp": "1769384711145", "event_type": "price_change"}}
{"_local_timestamp": "2026-01-25T23:45:11.237382+00:00", "data": {"market": "0x0eada57dcf53965a321f61c9dc6adb655367fabeb1f2ecbe7746f3f1a6ff7769", "price_changes": [{"asset_id": "88775412427564636095391917176836120951442159831179966305257669968799086969217", "price": "0.001", "size": "23142", "side": "BUY", "hash": "b2345fefed48b2a13a7316239a167b637b8bae0f", "best_bid": "0.002", "best_ask": "0.003"}, {"asset_id": "93593125008177926269164142727030950699068997099893975938000261506053151609883", "price": "0.999", "size": "23142", "side": "SELL", "hash": "69078ec47cedbacda71ef01b98b04b9e1b9ddd23", "best_bid": "0.997", "best_ask": "0.998"}], "timestamp": "1769384711148", "event_type": "price_change"}}
{"_local_timestamp": "2026-01-25T23:45:11.327963+00:00", "data": {"market": "0x405b6e3ce8caf18dea56ec418ea5a5c715f43aad946059e3eb7e3d1281698a78", "price_changes": [{"asset_id": "24373928341866408058552921472563928863071297280035754284253945296860184628420", "price": "0.832", "size": "0", "side": "BUY", "hash": "c42f42951eb71001e98099a86d1dbbfc3bdc1956", "best_bid": "0.996", "best_ask": "0.997"}, {"asset_id": "2350235314632053038507062516507369036092528887799666119386073644944240496673", "price": "0.168", "size": "0", "side": "SELL", "hash": "5a31d8e03a999fb27790884b166564c915dbc3e0", "best_bid": "0.003", "best_ask": "0.004"}], "timestamp": "1769384711196", "event_type": "price_change"}}
{"_local_timestamp": "2026-01-25T23:45:11.505071+00:00", "data": {"market": "0x405b6e3ce8caf18dea56ec418ea5a5c715f43aad946059e3eb7e3d1281698a78", "price_changes": [{"asset_id": "24373928341866408058552921472563928863071297280035754284253945296860184628420", "price": "0.834", "size": "10", "side": "BUY", "hash": "fcc641d3a0821615a266f60196b2b6237452a218", "best_bid": "0.996", "best_ask": "0.997"}, {"asset_id": "2350235314632053038507062516507369036092528887799666119386073644944240496673", "price": "0.166", "size": "10", "side": "SELL", "hash": "6abe498b34fed676131b5ba9063a92812876c4ab", "best_bid": "0.003", "best_ask": "0.004"}], "timestamp": "1769384711407", "event_type": "price_change"}}
{"_local_timestamp": "2026-01-25T23:45:12.601843+00:00", "data": {"market": "0x405b6e3ce8caf18dea56ec418ea5a5c715f43aad946059e3eb7e3d1281698a78", "price_changes": [{"asset_id": "24373928341866408058552921472563928863071297280035754284253945296860184628420", "price": "0.833", "size": "0", "side": "BUY", "hash": "5790ebcbfbfd4751b4e3dd8214142132d47210e5", "best_bid": "0.996", "best_ask": "0.997"}, {"asset_id": "2350235314632053038507062516507369036092528887799666119386073644944240496673", "price": "0.167", "size": "0", "side": "SELL", "hash": "d200bd5a46f28941ee8c9ef8ee0c87c261c50e9b", "best_bid": "0.003", "best_ask": "0.004"}], "timestamp": "1769384712537", "event_type": "price_change"}}
{"_local_timestamp": "2026-01-25T23:45:12.633269+00:00", "data": {"market": "0x405b6e3ce8caf18dea56ec418ea5a5c715f43aad946059e3eb7e3d1281698a78", "price_changes": [{"asset_id": "24373928341866408058552921472563928863071297280035754284253945296860184628420", "price": "0.825", "size": "20", "side": "BUY", "hash": "f4dcd92c3eb8dbb85f642a9785db9b27d11914fc", "best_bid": "0.996", "best_ask": "0.997"}, {"asset_id": "2350235314632053038507062516507369036092528887799666119386073644944240496673", "price": "0.175", "size": "20", "side": "SELL", "hash": "f923fb0e714a80792200ab1db8c8dd0ab491983c", "best_bid": "0.003", "best_ask": "0.004"}], "timestamp": "1769384712569", "event_type": "price_change"}}
{"_local_timestamp": "2026-01-25T23:45:14.824919+00:00", "data": {"market": "0x306bbce53f9a77906b9a928d52728bdee2e48f3354d19a9d6f0db7c9a1d4230d", "price_changes": [{"asset_id": "64957256704343867164459890398860992515731454967968064924053896034568618595733", "price": "0.43", "size": "0", "side": "BUY", "hash": "30ff858bcf5c2c07cec0f6766bd27a30eb2e0546", "best_bid": "0.932", "best_ask": "0.946"}, {"asset_id": "34335512241828535299853623975656484642594791501285631499713239174540168255596", "price": "0.57", "size": "0", "side": "SELL", "hash": "b11f6ece51a1d1e210944f3b383310457f208409", "best_bid": "0.054", "best_ask": "0.068"}], "timestamp": "1769384714736", "event_type": "price_change"}}
{"_local_timestamp": "2026-01-25T23:45:14.879687+00:00", "data": {"market": "0x306bbce53f9a77906b9a928d52728bdee2e48f3354d19a9d6f0db7c9a1d4230d", "price_changes": [{"asset_id": "64957256704343867164459890398860992515731454967968064924053896034568618595733", "price": "0.441", "size": "5", "side": "BUY", "hash": "9e05cb527e429c7e1825802a14b3fcfe31fb4931", "best_bid": "0.932", "best_ask": "0.946"}, {"asset_id": "34335512241828535299853623975656484642594791501285631499713239174540168255596", "price": "0.559", "size": "5", "side": "SELL", "hash": "45235ef8c62deea42097aa1ca136db5312d7badc", "best_bid": "0.054", "best_ask": "0.068"}], "timestamp": "1769384714793", "event_type": "price_change"}}
{"_local_timestamp": "2026-01-25T23:45:16.611194+00:00", "data": {"market": "0xd25c820d3aee1c735c0fa62c36f4905632ab8c6988653b5b4134593b3209eb7f", "price_changes": [{"asset_id": "45361184347486002884792387151438756924785609968030585696129487864334578884255", "price": "0.6", "size": "25", "side": "BUY", "hash": "79344069655915b03357f84de6c4fcaf84a61434", "best_bid": "0.6", "best_ask": "0.67"}, {"asset_id": "91117078941733659645786554099775611998962677612187928648088119165893475827434", "price": "0.4", "size": "25", "side": "SELL", "hash": "0e79838f9d8c095fc3e5364944c292c1b0587ba5", "best_bid": "0.33", "best_ask": "0.4"}], "timestamp": "1769384716542", "event_type": "price_change"}}
{"_local_timestamp": "2026-01-25T23:45:17.937351+00:00", "data": {"market": "0xd25c820d3aee1c735c0fa62c36f4905632ab8c6988653b5b4134593b3209eb7f", "price_changes": [{"asset_id": "91117078941733659645786554099775611998962677612187928648088119165893475827434", "price": "0.44", "size": "0", "side": "SELL", "hash": "0d606aabddccf093b2fec1060826f31d753ed8e1", "best_bid": "0.33", "best_ask": "0.4"}, {"asset_id": "45361184347486002884792387151438756924785609968030585696129487864334578884255", "price": "0.56", "size": "0", "side": "BUY", "hash": "6ba76bc2f1c67b5b0ae2d974462a67ece69e7802", "best_bid": "0.6", "best_ask": "0.67"}], "timestamp": "1769384717873", "event_type": "price_change"}}
{"_local_timestamp": "2026-01-25T23:45:22.918676+00:00", "data": {"market": "0xba8add06562a7bfd4fdd8f0a1882b5e2596540bd61c67a32359487694838f0a5", "price_changes": [{"asset_id": "62853431799112511763784693741363968903595954956498708214160770466188703343964", "price": "0.75", "size": "355.85", "side": "BUY", "hash": "5bc8c03aae748198f1e8dd1e8d5a326f3eba6413", "best_bid": "0.77", "best_ask": "0.78"}, {"asset_id": "7221299913764832338348128493889748182769672206962167820297840741811689706878", "price": "0.25", "size": "355.85", "side": "SELL", "hash": "501559dbaa851ef2a8bcc6001c64a7c1d18c4db6", "best_bid": "0.22", "best_ask": "0.23"}], "timestamp": "1769384722771", "event_type": "price_change"}}
{"_local_timestamp": "2026-01-25T23:45:22.919636+00:00", "data": {"market": "0xba8add06562a7bfd4fdd8f0a1882b5e2596540bd61c67a32359487694838f0a5", "price_changes": [{"asset_id": "7221299913764832338348128493889748182769672206962167820297840741811689706878", "price": "0.18", "size": "52.66", "side": "BUY", "hash": "fc12382c48be13e39b08af1e863af80579f05bc4", "best_bid": "0.22", "best_ask": "0.23"}, {"asset_id": "62853431799112511763784693741363968903595954956498708214160770466188703343964", "price": "0.82", "size": "52.66", "side": "SELL", "hash": "1054fc5453f55b70a5fe3fae7745392972d90c57", "best_bid": "0.77", "best_ask": "0.78"}], "timestamp": "1769384722774", "event_type": "price_change"}}
{"_local_timestamp": "2026-01-25T23:45:22.997868+00:00", "data": {"market": "0x0eada57dcf53965a321f61c9dc6adb655367fabeb1f2ecbe7746f3f1a6ff7769", "price_changes": [{"asset_id": "93593125008177926269164142727030950699068997099893975938000261506053151609883", "price": "0.405", "size": "60", "side": "BUY", "hash": "14c4b894c4a3ee7fb05029fcb6a7aa2083c0f653", "best_bid": "0.997", "best_ask": "0.998"}, {"asset_id": "88775412427564636095391917176836120951442159831179966305257669968799086969217", "price": "0.595", "size": "60", "side": "SELL", "hash": "de37b844a60ff5ac55d008d865205bb30f378ece", "best_bid": "0.002", "best_ask": "0.003"}], "timestamp": "1769384722931", "event_type": "price_change"}}
{"_local_timestamp": "2026-01-25T23:45:22.998829+00:00", "data": {"market": "0x3935226f1baa202667795b3a558d26fb0a9ae894a482676d34820bfb1b9b4edd", "price_changes": [{"asset_id": "5083116961935871155736992778398112358288960843713086370981563262578268017242", "price": "0.477", "size": "23", "side": "BUY", "hash": "dab15b05e2cb57f72b5bb9c33a70db53bbafa97a", "best_bid": "0.995", "best_ask": "0.997"}, {"asset_id": "80071381584983995567060219264871699619214990229460921095601419271143281499406", "price": "0.523", "size": "23", "side": "SELL", "hash": "0c5c713660cfb3e26338c522a42cf7f52eb20552", "best_bid": "0.003", "best_ask": "0.005"}], "timestamp": "1769384722931", "event_type": "price_change"}}
{"_local_timestamp": "2026-01-25T23:45:38.916423+00:00", "data": {"market": "0xba8add06562a7bfd4fdd8f0a1882b5e2596540bd61c67a32359487694838f0a5", "price_changes": [{"asset_id": "62853431799112511763784693741363968903595954956498708214160770466188703343964", "price": "0.21", "size": "5.48", "side": "BUY", "hash": "0788248cc71d64d094354c774de35d253a547582", "best_bid": "0.77", "best_ask": "0.78"}, {"asset_id": "7221299913764832338348128493889748182769672206962167820297840741811689706878", "price": "0.79", "size": "5.48", "side": "SELL", "hash": "16a6cb090a65b5dfa33212c2cd48d4ad1f4cdcf8", "best_bid": "0.22", "best_ask": "0.23"}], "timestamp": "1769384738813", "event_type": "price_change"}}
{"_local_timestamp": "2026-01-25T23:45:39.189874+00:00", "data": {"market": "0xba8add06562a7bfd4fdd8f0a1882b5e2596540bd61c67a32359487694838f0a5", "price_changes": [{"asset_id": "62853431799112511763784693741363968903595954956498708214160770466188703343964", "price": "0.24", "size": "1848", "side": "BUY", "hash": "0cffb6becdd006dee32018d21492c81fc389931a", "best_bid": "0.77", "best_ask": "0.78"}, {"asset_id": "7221299913764832338348128493889748182769672206962167820297840741811689706878", "price": "0.76", "size": "1848", "side": "SELL", "hash": "4017700464f2de980b35547c14e048a8aab7693a", "best_bid": "0.22", "best_ask": "0.23"}], "timestamp": "1769384739078", "event_type": "price_change"}}
{"_local_timestamp": "2026-01-25T23:45:39.210389+00:00", "data": {"market": "0xd25c820d3aee1c735c0fa62c36f4905632ab8c6988653b5b4134593b3209eb7f", "price_changes": [{"asset_id": "45361184347486002884792387151438756924785609968030585696129487864334578884255", "price": "0.25", "size": "250", "side": "BUY", "hash": "f9fcca210730a2427dd54a852e7413bd8d17d04a", "best_bid": "0.6", "best_ask": "0.67"}, {"asset_id": "91117078941733659645786554099775611998962677612187928648088119165893475827434", "price": "0.75", "size": "250", "side": "SELL", "hash": "ea58b5f58b41f8e7e862ead35f906b7cc894482c", "best_bid": "0.33", "best_ask": "0.4"}], "timestamp": "1769384739077", "event_type": "price_change"}}
{"_local_timestamp": "2026-01-25T23:45:39.233440+00:00", "data": {"market": "0xd25c820d3aee1c735c0fa62c36f4905632ab8c6988653b5b4134593b3209eb7f", "price_changes": [{"asset_id": "45361184347486002884792387151438756924785609968030585696129487864334578884255", "price": "0.27", "size": "124.07", "side": "BUY", "hash": "e82c5ea9db2e277a5f04761fa1edb0cd57dd3ec0", "best_bid": "0.6", "best_ask": "0.67"}, {"asset_id": "91117078941733659645786554099775611998962677612187928648088119165893475827434", "price": "0.73", "size": "124.07", "side": "SELL", "hash": "c748b92bef885ff33b45786fbdf5215dd2d7551b", "best_bid": "0.33", "best_ask": "0.4"}], "timestamp": "1769384739092", "event_type": "price_change"}}
{"_local_timestamp": "2026-01-25T23:45:42.134106+00:00", "data": {"market": "0x1fe1788d96d4c98e242549f91baf0de29eaf3b1545b5e2dda1d8714a3faf5305", "price_changes": [{"asset_id": "30944797740926340411025345169348106947975350930232142082675991513705266362329", "price": "0.02", "size": "0", "side": "SELL", "hash": "5fe5c643bce5d30e99a1f18ae331887c7959ca4b", "best_bid": "0.002", "best_ask": "0.003"}, {"asset_id": "85121409960340786807237728711169263074482548425773836042297909052960286277119", "price": "0.98", "size": "0", "side": "BUY", "hash": "631b7f45de30421e2c74172bd3e2472a7eba52ce", "best_bid": "0.997", "best_ask": "0.998"}], "timestamp": "1769384742050", "event_type": "price_change"}}
{"_local_timestamp": "2026-01-25T23:45:42.327032+00:00", "data": {"market": "0x1fe1788d96d4c98e242549f91baf0de29eaf3b1545b5e2dda1d8714a3faf5305", "price_changes": [{"asset_id": "30944797740926340411025345169348106947975350930232142082675991513705266362329", "price": "0.02", "size": "20.96", "side": "SELL", "hash": "938cf0c2eaca7910723d50cac979b19c7a57245b", "best_bid": "0.002", "best_ask": "0.003"}, {"asset_id": "85121409960340786807237728711169263074482548425773836042297909052960286277119", "price": "0.98", "size": "20.96", "side": "BUY", "hash": "5eb961c5567dcc027fb89ef0a812cff4d90e7dbd", "best_bid": "0.997", "best_ask": "0.998"}], "timestamp": "1769384742260", "event_type": "price_change"}}
{"_local_timestamp": "2026-01-25T23:45:47.144814+00:00", "data": {"market": "0xbbd623c4191ca76dec466507375d6df85b403b7e14f9cbd3d09f2c450ae0cd96", "price_changes": [{"asset_id": "86141088804897222236928959539148501008650371218692800935714557867410378164931", "price": "0.21", "size": "200", "side": "BUY", "hash": "a7e80f962abf35d6708f01071ee82b69670d8b47", "best_bid": "0.7", "best_ask": "0.73"}, {"asset_id": "86988864427600902662654729368237087316370077858847155604307346968813506081632", "price": "0.79", "size": "200", "side": "SELL", "hash": "001a71d7dc4be361cccba7c76857febd8550d323", "best_bid": "0.27", "best_ask": "0.3"}], "timestamp": "1769384747064", "event_type": "price_change"}}
{"_local_timestamp": "2026-01-25T23:45:47.472462+00:00", "data": {"market": "0xbbd623c4191ca76dec466507375d6df85b403b7e14f9cbd3d09f2c450ae0cd96", "price_changes": [{"asset_id": "86141088804897222236928959539148501008650371218692800935714557867410378164931", "price": "0.21", "size": "205.87", "side": "BUY", "hash": "bff851b2f2e7479cc1dd392766d58855fbebded4", "best_bid": "0.7", "best_ask": "0.73"}, {"asset_id": "86988864427600902662654729368237087316370077858847155604307346968813506081632", "price": "0.79", "size": "205.87", "side": "SELL", "hash": "18a0694019cf83951e3693e6654b20d0e6548777", "best_bid": "0.27", "best_ask": "0.3"}], "timestamp": "1769384747411", "event_type": "price_change"}}
{"_local_timestamp": "2026-01-25T23:45:48.352639+00:00", "data": {"market": "0xba8add06562a7bfd4fdd8f0a1882b5e2596540bd61c67a32359487694838f0a5", "price_changes": [{"asset_id": "62853431799112511763784693741363968903595954956498708214160770466188703343964", "price": "0.75", "size": "455.85", "side": "BUY", "hash": "215961eed21889011d1fb086c0c64901be475880", "best_bid": "0.77", "best_ask": "0.78"}, {"asset_id": "7221299913764832338348128493889748182769672206962167820297840741811689706878", "price": "0.25", "size": "455.85", "side": "SELL", "hash": "bbb6cf929721a58c60265520f94e83adb41db30d", "best_bid": "0.22", "best_ask": "0.23"}], "timestamp": "1769384748287", "event_type": "price_change"}}
{"_local_timestamp": "2026-01-25T23:45:50.625915+00:00", "data": {"market": "0xba8add06562a7bfd4fdd8f0a1882b5e2596540bd61c67a32359487694838f0a5", "price_changes": [{"asset_id": "62853431799112511763784693741363968903595954956498708214160770466188703343964", "price": "0.72", "size": "0", "side": "BUY", "hash": "d3508ce397369cd5f32f162aef04bf3cc6a2b17a", "best_bid": "0.76", "best_ask": "0.78"}, {"asset_id": "7221299913764832338348128493889748182769672206962167820297840741811689706878", "price": "0.28", "size": "0", "side": "SELL", "hash": "23b38ee7e88da876902082de38dfd028628d66c9", "best_bid": "0.22", "best_ask": "0.24"}], "timestamp": "1769384750561", "event_type": "price_change"}}
{"_local_timestamp": "2026-01-25T23:45:50.628189+00:00", "data": {"market": "0xba8add06562a7bfd4fdd8f0a1882b5e2596540bd61c67a32359487694838f0a5", "price_changes": [{"asset_id": "62853431799112511763784693741363968903595954956498708214160770466188703343964", "price": "0.67", "size": "0", "side": "BUY", "hash": "d3508ce397369cd5f32f162aef04bf3cc6a2b17a", "best_bid": "0.76", "best_ask": "0.78"}, {"asset_id": "7221299913764832338348128493889748182769672206962167820297840741811689706878", "price": "0.33", "size": "0", "side": "SELL", "hash": "23b38ee7e88da876902082de38dfd028628d66c9", "best_bid": "0.22", "best_ask": "0.24"}], "timestamp": "1769384750561", "event_type": "price_change"}}
{"_local_timestamp": "2026-01-25T23:45:50.630583+00:00", "data": {"market": "0xba8add06562a7bfd4fdd8f0a1882b5e2596540bd61c67a32359487694838f0a5", "price_changes": [{"asset_id": "62853431799112511763784693741363968903595954956498708214160770466188703343964", "price": "0.77", "size": "0", "side": "BUY", "hash": "d3508ce397369cd5f32f162aef04bf3cc6a2b17a", "best_bid": "0.76", "best_ask": "0.78"}, {"asset_id": "7221299913764832338348128493889748182769672206962167820297840741811689706878", "price": "0.23", "size": "0", "side": "SELL", "hash": "23b38ee7e88da876902082de38dfd028628d66c9", "best_bid": "0.22", "best_ask": "0.24"}], "timestamp": "1769384750561", "event_type": "price_change"}}
{"_local_timestamp": "2026-01-25T23:45:51.118132+00:00", "data": {"market": "0xba8add06562a7bfd4fdd8f0a1882b5e2596540bd61c67a32359487694838f0a5", "price_changes": [{"asset_id": "62853431799112511763784693741363968903595954956498708214160770466188703343964", "price": "0.76", "size": "339.25", "side": "BUY", "hash": "dc0123b6d868edd0ba0a856fab6c97a842fa385b", "best_bid": "0.76", "best_ask": "0.78"}, {"asset_id": "7221299913764832338348128493889748182769672206962167820297840741811689706878", "price": "0.24", "size": "339.25", "side": "SELL", "hash": "13004170264e1b30974f5df6093e33fbe6a4fb01", "best_bid": "0.22", "best_ask": "0.24"}], "timestamp": "1769384751044", "event_type": "price_change"}}
{"_local_timestamp": "2026-01-25T23:45:51.440606+00:00", "data": {"market": "0xba8add06562a7bfd4fdd8f0a1882b5e2596540bd61c67a32359487694838f0a5", "price_changes": [{"asset_id": "7221299913764832338348128493889748182769672206962167820297840741811689706878", "price": "0.18", "size": "152.66", "side": "BUY", "hash": "7092230b004f26e7acd3770a78d820a05fdfb5a1", "best_bid": "0.22", "best_ask": "0.24"}, {"asset_id": "62853431799112511763784693741363968903595954956498708214160770466188703343964", "price": "0.82", "size": "152.66", "side": "SELL", "hash": "34016c24443ec61723ba4102b70469c77a2e29fb", "best_bid": "0.76", "best_ask": "0.78"}], "timestamp": "1769384751378", "event_type": "price_change"}}
{"_local_timestamp": "2026-01-25T23:45:53.254754+00:00", "data": {"market": "0xd25c820d3aee1c735c0fa62c36f4905632ab8c6988653b5b4134593b3209eb7f", "price_changes": [{"asset_id": "45361184347486002884792387151438756924785609968030585696129487864334578884255", "price": "0.15", "size": "1660.53", "side": "BUY", "hash": "6bb45eb08c5c3c34c75fe6bc62fb8a41296d13f6", "best_bid": "0.6", "best_ask": "0.67"}, {"asset_id": "91117078941733659645786554099775611998962677612187928648088119165893475827434", "price": "0.85", "size": "1660.53", "side": "SELL", "hash": "8e03a3f96068cd381cc0c0704f4c586df7a858ea", "best_bid": "0.33", "best_ask": "0.4"}], "timestamp": "1769384753024", "event_type": "price_change"}}
{"_local_timestamp": "2026-01-25T23:45:53.255812+00:00", "data": {"market": "0xd25c820d3aee1c735c0fa62c36f4905632ab8c6988653b5b4134593b3209eb7f", "price_changes": [{"asset_id": "45361184347486002884792387151438756924785609968030585696129487864334578884255", "price": "0.17", "size": "464.7", "side": "BUY", "hash": "6bb45eb08c5c3c34c75fe6bc62fb8a41296d13f6", "best_bid": "0.6", "best_ask": "0.67"}, {"asset_id": "91117078941733659645786554099775611998962677612187928648088119165893475827434", "price": "0.83", "size": "464.7", "side": "SELL", "hash": "8e03a3f96068cd381cc0c0704f4c586df7a858ea", "best_bid": "0.33", "best_ask": "0.4"}], "timestamp": "1769384753024", "event_type": "price_change"}}
{"_local_timestamp": "2026-01-25T23:45:53.256739+00:00", "data": {"market": "0xd25c820d3aee1c735c0fa62c36f4905632ab8c6988653b5b4134593b3209eb7f", "price_changes": [{"asset_id": "45361184347486002884792387151438756924785609968030585696129487864334578884255", "price": "0.25", "size": "200", "side": "BUY", "hash": "6bb45eb08c5c3c34c75fe6bc62fb8a41296d13f6", "best_bid": "0.6", "best_ask": "0.67"}, {"asset_id": "91117078941733659645786554099775611998962677612187928648088119165893475827434", "price": "0.75", "size": "200", "side": "SELL", "hash": "8e03a3f96068cd381cc0c0704f4c586df7a858ea", "best_bid": "0.33", "best_ask": "0.4"}], "timestamp": "1769384753024", "event_type": "price_change"}}
{"_local_timestamp": "2026-01-25T23:45:56.587075+00:00", "data": {"market": "0xd25c820d3aee1c735c0fa62c36f4905632ab8c6988653b5b4134593b3209eb7f", "price_changes": [{"asset_id": "91117078941733659645786554099775611998962677612187928648088119165893475827434", "price": "0.06", "size": "525.33", "side": "BUY", "hash": "597bf8f2f6f822e051e8cc198f39a2edee44b477", "best_bid": "0.33", "best_ask": "0.4"}, {"asset_id": "45361184347486002884792387151438756924785609968030585696129487864334578884255", "price": "0.94", "size": "525.33", "side": "SELL", "hash": "f9ffe9c45a9d66735d979f10d33daf34a3e5da2c", "best_bid": "0.6", "best_ask": "0.67"}], "timestamp": "1769384756088", "event_type": "price_change"}}
{"_local_timestamp": "2026-01-25T23:46:07.720429+00:00", "data": {"market": "0xba8add06562a7bfd4fdd8f0a1882b5e2596540bd61c67a32359487694838f0a5", "price_changes": [{"asset_id": "62853431799112511763784693741363968903595954956498708214160770466188703343964", "price": "0.75", "size": "355.85", "side": "BUY", "hash": "f516b316ad6ea64cee22825da7fd6e6d3b54b4ac", "best_bid": "0.76", "best_ask": "0.78"}, {"asset_id": "7221299913764832338348128493889748182769672206962167820297840741811689706878", "price": "0.25", "size": "355.85", "side": "SELL", "hash": "fb8811056e76c98bef72d3272d0462c25b37f8c5", "best_bid": "0.22", "best_ask": "0.24"}], "timestamp": "1769384767655", "event_type": "price_change"}}
{"_local_timestamp": "2026-01-25T23:46:07.721457+00:00", "data": {"market": "0xba8add06562a7bfd4fdd8f0a1882b5e2596540bd61c67a32359487694838f0a5", "price_changes": [{"asset_id": "7221299913764832338348128493889748182769672206962167820297840741811689706878", "price": "0.18", "size": "52.66", "side": "BUY", "hash": "4da6df7caebf4c4a2159593fcfe4bda2bf0bf3cd", "best_bid": "0.22", "best_ask": "0.24"}, {"asset_id": "62853431799112511763784693741363968903595954956498708214160770466188703343964", "price": "0.82", "size": "52.66", "side": "SELL", "hash": "b05e01a83d81a289b9731d7763472958fa525ab0", "best_bid": "0.76", "best_ask": "0.78"}], "timestamp": "1769384767655", "event_type": "price_change"}}
{"_local_timestamp": "2026-01-25T23:46:10.622712+00:00", "data": {"market": "0xba8add06562a7bfd4fdd8f0a1882b5e2596540bd61c67a32359487694838f0a5", "price_changes": [{"asset_id": "62853431799112511763784693741363968903595954956498708214160770466188703343964", "price": "0.24", "size": "100", "side": "BUY", "hash": "b2aed00d7972f7cd8f4e0f887e1e244c4bf4b8cf", "best_bid": "0.76", "best_ask": "0.78"}, {"asset_id": "7221299913764832338348128493889748182769672206962167820297840741811689706878", "price": "0.76", "size": "100", "side": "SELL", "hash": "6f22f2c5fc693a7f133ca12bdf2b0048392888b7", "best_bid": "0.22", "best_ask": "0.24"}], "timestamp": "1769384770470", "event_type": "price_change"}}
{"_local_timestamp": "2026-01-25T23:46:11.669423+00:00", "data": {"market": "0xd25c820d3aee1c735c0fa62c36f4905632ab8c6988653b5b4134593b3209eb7f", "price_changes": [{"asset_id": "91117078941733659645786554099775611998962677612187928648088119165893475827434", "price": "0.07", "size": "100", "side": "BUY", "hash": "c9698300a4eb4543cd1873379148ae33c936a5ec", "best_bid": "0.33", "best_ask": "0.4"}, {"asset_id": "45361184347486002884792387151438756924785609968030585696129487864334578884255", "price": "0.93", "size": "100", "side": "SELL", "hash": "c623cd1d0433358833aab7d4e61056a2739fd6ff", "best_bid": "0.6", "best_ask": "0.67"}], "timestamp": "1769384771578", "event_type": "price_change"}}
{"_local_timestamp": "2026-01-25T23:46:16.581836+00:00", "data": {"market": "0xd25c820d3aee1c735c0fa62c36f4905632ab8c6988653b5b4134593b3209eb7f", "price_changes": [{"asset_id": "91117078941733659645786554099775611998962677612187928648088119165893475827434", "price": "0.07", "size": "400", "side": "BUY", "hash": "2dd173ad9b6d9018f25a14331f5aeb99e2802828", "best_bid": "0.33", "best_ask": "0.4"}, {"asset_id": "45361184347486002884792387151438756924785609968030585696129487864334578884255", "price": "0.93", "size": "400", "side": "SELL", "hash": "38a527b004950068d960d9621b2cc51ab0585dbb", "best_bid": "0.6", "best_ask": "0.67"}], "timestamp": "1769384776515", "event_type": "price_change"}}
{"_local_timestamp": "2026-01-25T23:46:17.051219+00:00", "data": {"market": "0xd25c820d3aee1c735c0fa62c36f4905632ab8c6988653b5b4134593b3209eb7f", "price_changes": [{"asset_id": "45361184347486002884792387151438756924785609968030585696129487864334578884255", "price": "0.05", "size": "3841", "side": "BUY", "hash": "102c8de0239b5c0f2567a9329a5f2ab2fc401023", "best_bid": "0.6", "best_ask": "0.67"}, {"asset_id": "91117078941733659645786554099775611998962677612187928648088119165893475827434", "price": "0.95", "size": "3841", "side": "SELL", "hash": "4716d3042921772d0caa7ebfcce6b5ed2b85d946", "best_bid": "0.33", "best_ask": "0.4"}], "timestamp": "1769384776977", "event_type": "price_change"}}
{"_local_timestamp": "2026-01-25T23:46:17.052434+00:00", "data": {"market": "0xd25c820d3aee1c735c0fa62c36f4905632ab8c6988653b5b4134593b3209eb7f", "price_changes": [{"asset_id": "45361184347486002884792387151438756924785609968030585696129487864334578884255", "price": "0.07", "size": "1014.28", "side": "BUY", "hash": "102c8de0239b5c0f2567a9329a5f2ab2fc401023", "best_bid": "0.6", "best_ask": "0.67"}, {"asset_id": "91117078941733659645786554099775611998962677612187928648088119165893475827434", "price": "0.93", "size": "1014.28", "side": "SELL", "hash": "4716d3042921772d0caa7ebfcce6b5ed2b85d946", "best_bid": "0.33", "best_ask": "0.4"}], "timestamp": "1769384776977", "event_type": "price_change"}}
{"_local_timestamp": "2026-01-25T23:46:26.350013+00:00", "data": {"market": "0xba8add06562a7bfd4fdd8f0a1882b5e2596540bd61c67a32359487694838f0a5", "price_changes": [{"asset_id": "62853431799112511763784693741363968903595954956498708214160770466188703343964", "price": "0.21", "size": "2003.48", "side": "BUY", "hash": "31a893a24ddf85f3a2fabd25bda9a9798b4534e0", "best_bid": "0.76", "best_ask": "0.78"}, {"asset_id": "7221299913764832338348128493889748182769672206962167820297840741811689706878", "price": "0.79", "size": "2003.48", "side": "SELL", "hash": "ba46c21f7f90e79fdab337af75a056bc0ea64087", "best_bid": "0.22", "best_ask": "0.24"}], "timestamp": "1769384786284", "event_type": "price_change"}}
{"_local_timestamp": "2026-01-25T23:46:50.928505+00:00", "data": {"market": "0xd25c820d3aee1c735c0fa62c36f4905632ab8c6988653b5b4134593b3209eb7f", "price_changes": [{"asset_id": "45361184347486002884792387151438756924785609968030585696129487864334578884255", "price": "0.17", "size": "314.7", "side": "BUY", "hash": "1bba5310b387fb65bacc8867ac4a89c59c459553", "best_bid": "0.6", "best_ask": "0.67"}, {"asset_id": "91117078941733659645786554099775611998962677612187928648088119165893475827434", "price": "0.83", "size": "314.7", "side": "SELL", "hash": "06692d3f816e05e3c50f33114cda3e2ae9262c46", "best_bid": "0.33", "best_ask": "0.4"}], "timestamp": "1769384810667", "event_type": "price_change"}}
{"_local_timestamp": "2026-01-25T23:46:50.929718+00:00", "data": {"market": "0xd25c820d3aee1c735c0fa62c36f4905632ab8c6988653b5b4134593b3209eb7f", "price_changes": [{"asset_id": "45361184347486002884792387151438756924785609968030585696129487864334578884255", "price": "0.15", "size": "1460.53", "side": "BUY", "hash": "1bba5310b387fb65bacc8867ac4a89c59c459553", "best_bid": "0.6", "best_ask": "0.67"}, {"asset_id": "91117078941733659645786554099775611998962677612187928648088119165893475827434", "price": "0.85", "size": "1460.53", "side": "SELL", "hash": "06692d3f816e05e3c50f33114cda3e2ae9262c46", "best_bid": "0.33", "best_ask": "0.4"}], "timestamp": "1769384810667", "event_type": "price_change"}}
{"_local_timestamp": "2026-01-25T23:46:50.930851+00:00", "data": {"market": "0xd25c820d3aee1c735c0fa62c36f4905632ab8c6988653b5b4134593b3209eb7f", "price_changes": [{"asset_id": "45361184347486002884792387151438756924785609968030585696129487864334578884255", "price": "0.05", "size": "3541", "side": "BUY", "hash": "1bba5310b387fb65bacc8867ac4a89c59c459553", "best_bid": "0.6", "best_ask": "0.67"}, {"asset_id": "91117078941733659645786554099775611998962677612187928648088119165893475827434", "price": "0.95", "size": "3541", "side": "SELL", "hash": "06692d3f816e05e3c50f33114cda3e2ae9262c46", "best_bid": "0.33", "best_ask": "0.4"}], "timestamp": "1769384810667", "event_type": "price_change"}}
{"_local_timestamp": "2026-01-25T23:46:58.533237+00:00", "data": {"market": "0xd25c820d3aee1c735c0fa62c36f4905632ab8c6988653b5b4134593b3209eb7f", "price_changes": [{"asset_id": "91117078941733659645786554099775611998962677612187928648088119165893475827434", "price": "0.06", "size": "25.33", "side": "BUY", "hash": "1cb3f0cd6e05551d0b7a3e2fad7676b27e8eb2a3", "best_bid": "0.33", "best_ask": "0.4"}, {"asset_id": "45361184347486002884792387151438756924785609968030585696129487864334578884255", "price": "0.94", "size": "25.33", "side": "SELL", "hash": "aeb5b51b331856154bb900cd7cd4f6e0b4bf2d1b", "best_bid": "0.6", "best_ask": "0.67"}], "timestamp": "1769384818411", "event_type": "price_change"}}
{"_local_timestamp": "2026-01-25T23:46:58.686105+00:00", "data": {"market": "0xba8add06562a7bfd4fdd8f0a1882b5e2596540bd61c67a32359487694838f0a5", "price_changes": [{"asset_id": "62853431799112511763784693741363968903595954956498708214160770466188703343964", "price": "0.56", "size": "31.66", "side": "BUY", "hash": "f9b4a86cb9ca96b357718b66752b0566ef97239b", "best_bid": "0.76", "best_ask": "0.78"}, {"asset_id": "7221299913764832338348128493889748182769672206962167820297840741811689706878", "price": "0.44", "size": "31.66", "side": "SELL", "hash": "41d1b01a9b23b41bb613b55dd37d4ed1469a47af", "best_bid": "0.22", "best_ask": "0.24"}], "timestamp": "1769384818580", "event_type": "price_change"}}
{"_local_timestamp": "2026-01-25T23:46:58.794201+00:00", "data": {"market": "0xd25c820d3aee1c735c0fa62c36f4905632ab8c6988653b5b4134593b3209eb7f", "price_changes": [{"asset_id": "91117078941733659645786554099775611998962677612187928648088119165893475827434", "price": "0.07", "size": "900", "side": "BUY", "hash": "bd6a8b6413adfae2fdc0c0e3257f9db302e3d288", "best_bid": "0.33", "best_ask": "0.4"}, {"asset_id": "45361184347486002884792387151438756924785609968030585696129487864334578884255", "price": "0.93", "size": "900", "side": "SELL", "hash": "d63e26e338356fb8e7328cbd235469980852edb9", "best_bid": "0.6", "best_ask": "0.67"}], "timestamp": "1769384818706", "event_type": "price_change"}}
{"_local_timestamp": "2026-01-25T23:46:58.973117+00:00", "data": {"market": "0xba8add06562a7bfd4fdd8f0a1882b5e2596540bd61c67a32359487694838f0a5", "price_changes": [{"asset_id": "62853431799112511763784693741363968903595954956498708214160770466188703343964", "price": "0.24", "size": "0", "side": "BUY", "hash": "1c01b46a72c52caafa1c8cca2feae70fd30355ca", "best_bid": "0.76", "best_ask": "0.78"}, {"asset_id": "7221299913764832338348128493889748182769672206962167820297840741811689706878", "price": "0.76", "size": "0", "side": "SELL", "hash": "254e7abc8df1f1d8c47011808a8179ced9e776a1", "best_bid": "0.22", "best_ask": "0.24"}], "timestamp": "1769384818865", "event_type": "price_change"}}
{"_local_timestamp": "2026-01-25T23:46:59.305237+00:00", "data": {"market": "0xba8add06562a7bfd4fdd8f0a1882b5e2596540bd61c67a32359487694838f0a5", "price_changes": [{"asset_id": "62853431799112511763784693741363968903595954956498708214160770466188703343964", "price": "0.23", "size": "213.04", "side": "BUY", "hash": "f55b0b79dee5cde2e2ea4818a8f0e835ca2693f0", "best_bid": "0.76", "best_ask": "0.78"}, {"asset_id": "7221299913764832338348128493889748182769672206962167820297840741811689706878", "price": "0.77", "size": "213.04", "side": "SELL", "hash": "29cdcb7094f3d9aa583563000ec1abb2d03e1bc8", "best_bid": "0.22", "best_ask": "0.24"}], "timestamp": "1769384819169", "event_type": "price_change"}}
{"_local_timestamp": "2026-01-25T23:47:05.935455+00:00", "data": {"market": "0xd25c820d3aee1c735c0fa62c36f4905632ab8c6988653b5b4134593b3209eb7f", "price_changes": [{"asset_id": "45361184347486002884792387151438756924785609968030585696129487864334578884255", "price": "0.57", "size": "0", "side": "BUY", "hash": "9bc59472062d8743b9926aac658c1dc6434f899c", "best_bid": "0.6", "best_ask": "0.67"}, {"asset_id": "91117078941733659645786554099775611998962677612187928648088119165893475827434", "price": "0.43", "size": "0", "side": "SELL", "hash": "a25a206887e114a64d5b4296d2a58da8219c538e", "best_bid": "0.33", "best_ask": "0.4"}], "timestamp": "1769384825867", "event_type": "price_change"}}
{"_local_timestamp": "2026-01-25T23:47:05.967723+00:00", "data": {"market": "0xd25c820d3aee1c735c0fa62c36f4905632ab8c6988653b5b4134593b3209eb7f", "price_changes": [{"asset_id": "45361184347486002884792387151438756924785609968030585696129487864334578884255", "price": "0.6", "size": "5", "side": "BUY", "hash": "faaf9dcb4a3d673ca34d8240206041d210c5c44a", "best_bid": "0.6", "best_ask": "0.67"}, {"asset_id": "91117078941733659645786554099775611998962677612187928648088119165893475827434", "price": "0.4", "size": "5", "side": "SELL", "hash": "261eaac03214e6f8c997223cf58b7e66e0c83ee5", "best_bid": "0.33", "best_ask": "0.4"}], "timestamp": "1769384825902", "event_type": "price_change"}}
{"_local_timestamp": "2026-01-25T23:47:13.255600+00:00", "data": {"market": "0x1fe1788d96d4c98e242549f91baf0de29eaf3b1545b5e2dda1d8714a3faf5305", "price_changes": [{"asset_id": "30944797740926340411025345169348106947975350930232142082675991513705266362329", "price": "0.02", "size": "0", "side": "SELL", "hash": "2e60852e42d73ffb4792451c75a9aa5cd42f269b", "best_bid": "0.002", "best_ask": "0.003"}, {"asset_id": "85121409960340786807237728711169263074482548425773836042297909052960286277119", "price": "0.98", "size": "0", "side": "BUY", "hash": "3bd37a542a6ed0a50768479e8c911ebaf06f6a09", "best_bid": "0.997", "best_ask": "0.998"}], "timestamp": "1769384833190", "event_type": "price_change"}}
{"_local_timestamp": "2026-01-25T23:47:13.381642+00:00", "data": {"market": "0x1fe1788d96d4c98e242549f91baf0de29eaf3b1545b5e2dda1d8714a3faf5305", "price_changes": [{"asset_id": "30944797740926340411025345169348106947975350930232142082675991513705266362329", "price": "0.02", "size": "20.96", "side": "SELL", "hash": "4d0414d7f5315e299e428728837a8dbf5977cf16", "best_bid": "0.002", "best_ask": "0.003"}, {"asset_id": "85121409960340786807237728711169263074482548425773836042297909052960286277119", "price": "0.98", "size": "20.96", "side": "BUY", "hash": "36dffba2b3ecaa2a721b7221dbd5bd6d885ed044", "best_bid": "0.997", "best_ask": "0.998"}], "timestamp": "1769384833316", "event_type": "price_change"}}
{"_local_timestamp": "2026-01-25T23:47:19.152199+00:00", "data": {"market": "0xd25c820d3aee1c735c0fa62c36f4905632ab8c6988653b5b4134593b3209eb7f", "price_changes": [{"asset_id": "91117078941733659645786554099775611998962677612187928648088119165893475827434", "price": "0.44", "size": "9.5", "side": "SELL", "hash": "5e9b6ba25d1e09810f12fac75bff75c27fba83b8", "best_bid": "0.33", "best_ask": "0.4"}, {"asset_id": "45361184347486002884792387151438756924785609968030585696129487864334578884255", "price": "0.56", "size": "9.5", "side": "BUY", "hash": "bb7a19c140de5e94cea1089d22ebb658533370f6", "best_bid": "0.6", "best_ask": "0.67"}], "timestamp": "1769384838987", "event_type": "price_change"}}
{"_local_timestamp": "2026-01-25T23:47:23.506125+00:00", "data": {"market": "0xba8add06562a7bfd4fdd8f0a1882b5e2596540bd61c67a32359487694838f0a5", "price_changes": [{"asset_id": "62853431799112511763784693741363968903595954956498708214160770466188703343964", "price": "0.2", "size": "140", "side": "BUY", "hash": "2dfde708ba7d6600617fa42f5e750778c6fd0807", "best_bid": "0.76", "best_ask": "0.78"}, {"asset_id": "7221299913764832338348128493889748182769672206962167820297840741811689706878", "price": "0.8", "size": "140", "side": "SELL", "hash": "d73e6efa823a938b13135a44404fe9a2262d609a", "best_bid": "0.22", "best_ask": "0.24"}], "timestamp": "1769384843392", "event_type": "price_change"}}
{"_local_timestamp": "2026-01-25T23:47:23.918175+00:00", "data": {"market": "0xba8add06562a7bfd4fdd8f0a1882b5e2596540bd61c67a32359487694838f0a5", "price_changes": [{"asset_id": "62853431799112511763784693741363968903595954956498708214160770466188703343964", "price": "0.24", "size": "50", "side": "BUY", "hash": "29130282692984c511e0c10d3c6f163ebbfe3d61", "best_bid": "0.76", "best_ask": "0.78"}, {"asset_id": "7221299913764832338348128493889748182769672206962167820297840741811689706878", "price": "0.76", "size": "50", "side": "SELL", "hash": "87097c61b73abc8185714e41d35cceb18e48874e", "best_bid": "0.22", "best_ask": "0.24"}], "timestamp": "1769384843824", "event_type": "price_change"}}
{"_local_timestamp": "2026-01-25T23:47:24.987940+00:00", "data": {"market": "0x96bc24f519f3008b984b623dfacfa6b87599381ba6afdbd36a576d0d85c4a59c", "price_changes": [{"asset_id": "37234028100441924867078516219629684611507504332898623831670509973866359367709", "price": "0.531", "size": "0", "side": "BUY", "hash": "d7bd39645acfe3e8c642bf84b6f37333668da14f", "best_bid": "0.997", "best_ask": "0.999"}, {"asset_id": "48733707571584348634287808682190901692810422881953520223982749265958667182900", "price": "0.469", "size": "0", "side": "SELL", "hash": "19f083b6bd49ed40943da8c794dddd56c3b63535", "best_bid": "0.001", "best_ask": "0.003"}], "timestamp": "1769384844920", "event_type": "price_change"}}
{"_local_timestamp": "2026-01-25T23:47:25.040366+00:00", "data": {"market": "0x96bc24f519f3008b984b623dfacfa6b87599381ba6afdbd36a576d0d85c4a59c", "price_changes": [{"asset_id": "37234028100441924867078516219629684611507504332898623831670509973866359367709", "price": "0.401", "size": "5", "side": "BUY", "hash": "48a9266c5bb2f1d37705bd7524a579fa6de144fd", "best_bid": "0.997", "best_ask": "0.999"}, {"asset_id": "48733707571584348634287808682190901692810422881953520223982749265958667182900", "price": "0.599", "size": "5", "side": "SELL", "hash": "0576056a094472f94493524f149413beed14e353", "best_bid": "0.001", "best_ask": "0.003"}], "timestamp": "1769384844974", "event_type": "price_change"}}
{"_local_timestamp": "2026-01-25T23:47:25.178292+00:00", "data": {"market": "0xba8add06562a7bfd4fdd8f0a1882b5e2596540bd61c67a32359487694838f0a5", "price_changes": [{"asset_id": "62853431799112511763784693741363968903595954956498708214160770466188703343964", "price": "0.56", "size": "16.66", "side": "BUY", "hash": "710e9447ee8e719b085e2bbb8a19ca0ecc9018e0", "best_bid": "0.76", "best_ask": "0.78"}, {"asset_id": "7221299913764832338348128493889748182769672206962167820297840741811689706878", "price": "0.44", "size": "16.66", "side": "SELL", "hash": "8c0856aa50029a732ad18f84416d6be83c9ec13b", "best_bid": "0.22", "best_ask": "0.24"}], "timestamp": "1769384845111", "event_type": "price_change"}}
{"_local_timestamp": "2026-01-25T23:47:25.384070+00:00", "data": {"market": "0xba8add06562a7bfd4fdd8f0a1882b5e2596540bd61c67a32359487694838f0a5", "price_changes": [{"asset_id": "62853431799112511763784693741363968903595954956498708214160770466188703343964", "price": "0.58", "size": "35", "side": "BUY", "hash": "0a30bffbf77955697f965e9464765077b461c5de", "best_bid": "0.76", "best_ask": "0.78"}, {"asset_id": "7221299913764832338348128493889748182769672206962167820297840741811689706878", "price": "0.42", "size": "35", "side": "SELL", "hash": "6cf5e564f7da3bf7effab97dcbba3c4cf9d5e116", "best_bid": "0.22", "best_ask": "0.24"}], "timestamp": "1769384845314", "event_type": "price_change"}}
{"_local_timestamp": "2026-01-25T23:47:25.385051+00:00", "data": {"market": "0xba8add06562a7bfd4fdd8f0a1882b5e2596540bd61c67a32359487694838f0a5", "price_changes": [{"asset_id": "62853431799112511763784693741363968903595954956498708214160770466188703343964", "price": "0.59", "size": "10", "side": "BUY", "hash": "34f3aeb54747c1e8317c286dd91a7b5580672146", "best_bid": "0.76", "best_ask": "0.78"}, {"asset_id": "7221299913764832338348128493889748182769672206962167820297840741811689706878", "price": "0.41", "size": "10", "side": "SELL", "hash": "2619c108acc36d60b55182c47db727c5dc14e46f", "best_bid": "0.22", "best_ask": "0.24"}], "timestamp": "1769384845317", "event_type": "price_change"}}
{"_local_timestamp": "2026-01-25T23:47:28.461380+00:00", "data": {"market": "0xba8add06562a7bfd4fdd8f0a1882b5e2596540bd61c67a32359487694838f0a5", "price_changes": [{"asset_id": "62853431799112511763784693741363968903595954956498708214160770466188703343964", "price": "0.58", "size": "15", "side": "BUY", "hash": "db34e3eacaf7845aa509040ddc1910c8d464304c", "best_bid": "0.76", "best_ask": "0.78"}, {"asset_id": "7221299913764832338348128493889748182769672206962167820297840741811689706878", "price": "0.42", "size": "15", "side": "SELL", "hash": "c074e9a40f759cb9389eedcfd346c012b9d4b98b", "best_bid": "0.22", "best_ask": "0.24"}], "timestamp": "1769384848391", "event_type": "price_change"}}
{"_local_timestamp": "2026-01-25T23:47:28.489330+00:00", "data": {"market": "0xba8add06562a7bfd4fdd8f0a1882b5e2596540bd61c67a32359487694838f0a5", "price_changes": [{"asset_id": "62853431799112511763784693741363968903595954956498708214160770466188703343964", "price": "0.6", "size": "20", "side": "BUY", "hash": "442dd8c3920b2107653255f10f883142bb3e8076", "best_bid": "0.76", "best_ask": "0.78"}, {"asset_id": "7221299913764832338348128493889748182769672206962167820297840741811689706878", "price": "0.4", "size": "20", "side": "SELL", "hash": "5d787c6e6b9e5e9067208480e99a0604402d7f36", "best_bid": "0.22", "best_ask": "0.24"}], "timestamp": "1769384848421", "event_type": "price_change"}}
{"_local_timestamp": "2026-01-25T23:47:28.575299+00:00", "data": {"market": "0xba8add06562a7bfd4fdd8f0a1882b5e2596540bd61c67a32359487694838f0a5", "price_changes": [{"asset_id": "62853431799112511763784693741363968903595954956498708214160770466188703343964", "price": "0.58", "size": "0", "side": "BUY", "hash": "162740b711923a685f5a0ccbdf88a5233424802e", "best_bid": "0.76", "best_ask": "0.78"}, {"asset_id": "7221299913764832338348128493889748182769672206962167820297840741811689706878", "price": "0.42", "size": "0", "side": "SELL", "hash": "b8e36f9a9f754e20691972b03fbdb8ad1e9a0997", "best_bid": "0.22", "best_ask": "0.24"}], "timestamp": "1769384848507", "event_type": "price_change"}}
{"_local_timestamp": "2026-01-25T23:47:37.374625+00:00", "data": {"market": "0xba8add06562a7bfd4fdd8f0a1882b5e2596540bd61c67a32359487694838f0a5", "price_changes": [{"asset_id": "62853431799112511763784693741363968903595954956498708214160770466188703343964", "price": "0.23", "size": "113.04", "side": "BUY", "hash": "9520c4522af44eba8aa846d7f2005104cf3b362b", "best_bid": "0.76", "best_ask": "0.78"}, {"asset_id": "7221299913764832338348128493889748182769672206962167820297840741811689706878", "price": "0.77", "size": "113.04", "side": "SELL", "hash": "e53e5ada49016d2a3ac84a4859ade1f44a02e097", "best_bid": "0.22", "best_ask": "0.24"}], "timestamp": "1769384857291", "event_type": "price_change"}}
{"_local_timestamp": "2026-01-25T23:47:37.923474+00:00", "data": {"market": "0xba8add06562a7bfd4fdd8f0a1882b5e2596540bd61c67a32359487694838f0a5", "price_changes": [{"asset_id": "62853431799112511763784693741363968903595954956498708214160770466188703343964", "price": "0.21", "size": "2103.48", "side": "BUY", "hash": "0a209f2a086417c523bf8a9d579316b9f7cb40f2", "best_bid": "0.76", "best_ask": "0.78"}, {"asset_id": "7221299913764832338348128493889748182769672206962167820297840741811689706878", "price": "0.79", "size": "2103.48", "side": "SELL", "hash": "78e3c1aead24c94cf3767323d066383114ae77a1", "best_bid": "0.22", "best_ask": "0.24"}], "timestamp": "1769384857597", "event_type": "price_change"}}
{"_local_timestamp": "2026-01-25T23:47:38.406804+00:00", "data": {"market": "0xd25c820d3aee1c735c0fa62c36f4905632ab8c6988653b5b4134593b3209eb7f", "price_changes": [{"asset_id": "45361184347486002884792387151438756924785609968030585696129487864334578884255", "price": "0.15", "size": "1585.53", "side": "BUY", "hash": "f6a71c881aa27b0e47af3241ef117ce4c9aaa59c", "best_bid": "0.6", "best_ask": "0.67"}, {"asset_id": "91117078941733659645786554099775611998962677612187928648088119165893475827434", "price": "0.85", "size": "1585.53", "side": "SELL", "hash": "e7e74616a0accc289427fec92588cdbdc76b9dd9", "best_bid": "0.33", "best_ask": "0.4"}], "timestamp": "1769384858085", "event_type": "price_change"}}
{"_local_timestamp": "2026-01-25T23:47:38.490436+00:00", "data": {"market": "0xd25c820d3aee1c735c0fa62c36f4905632ab8c6988653b5b4134593b3209eb7f", "price_changes": [{"asset_id": "45361184347486002884792387151438756924785609968030585696129487864334578884255", "price": "0.17", "size": "414.7", "side": "BUY", "hash": "02976282f8bf643babf0f56337cf48652e0abdec", "best_bid": "0.6", "best_ask": "0.67"}, {"asset_id": "91117078941733659645786554099775611998962677612187928648088119165893475827434", "price": "0.83", "size": "414.7", "side": "SELL", "hash": "89d7a21c3a897cca336e5130b6015db6f32d9e9f", "best_bid": "0.33", "best_ask": "0.4"}], "timestamp": "1769384858344", "event_type": "price_change"}}
{"_local_timestamp": "2026-01-25T23:47:55.609515+00:00", "data": {"market": "0xba8add06562a7bfd4fdd8f0a1882b5e2596540bd61c67a32359487694838f0a5", "price_changes": [{"asset_id": "62853431799112511763784693741363968903595954956498708214160770466188703343964", "price": "0.21", "size": "105.48", "side": "BUY", "hash": "63832e38277acdf1f2e2d80cce63d9ad56e113b6", "best_bid": "0.76", "best_ask": "0.78"}, {"asset_id": "7221299913764832338348128493889748182769672206962167820297840741811689706878", "price": "0.79", "size": "105.48", "side": "SELL", "hash": "4e8eb6361410175240bb73b4d92fcab39f51df8d", "best_bid": "0.22", "best_ask": "0.24"}], "timestamp": "1769384875421", "event_type": "price_change"}}
{"_local_timestamp": "2026-01-25T23:48:02.922228+00:00", "data": {"market": "0xd25c820d3aee1c735c0fa62c36f4905632ab8c6988653b5b4134593b3209eb7f", "price_changes": [{"asset_id": "45361184347486002884792387151438756924785609968030585696129487864334578884255", "price": "0.05", "size": "3941", "side": "BUY", "hash": "3791fa5ba011fe30195d545638f0d1f29e93be81", "best_bid": "0.6", "best_ask": "0.67"}, {"asset_id": "91117078941733659645786554099775611998962677612187928648088119165893475827434", "price": "0.95", "size": "3941", "side": "SELL", "hash": "e2245d65c77f4c09823ffb708a95329530fa2ea5", "best_bid": "0.33", "best_ask": "0.4"}], "timestamp": "1769384882838", "event_type": "price_change"}}
{"_local_timestamp": "2026-01-25T23:48:02.950826+00:00", "data": {"market": "0xd25c820d3aee1c735c0fa62c36f4905632ab8c6988653b5b4134593b3209eb7f", "price_changes": [{"asset_id": "45361184347486002884792387151438756924785609968030585696129487864334578884255", "price": "0.07", "size": "1214.28", "side": "BUY", "hash": "d4ce3a13c1483cbbb6a65cb092dfc5c230e74458", "best_bid": "0.6", "best_ask": "0.67"}, {"asset_id": "91117078941733659645786554099775611998962677612187928648088119165893475827434", "price": "0.93", "size": "1214.28", "side": "SELL", "hash": "1f0305520c625febf103485b06ba90158398b1e2", "best_bid": "0.33", "best_ask": "0.4"}], "timestamp": "1769384882842", "event_type": "price_change"}}
{"_local_timestamp": "2026-01-25T23:48:03.682051+00:00", "data": {"market": "0xba8add06562a7bfd4fdd8f0a1882b5e2596540bd61c67a32359487694838f0a5", "price_changes": [{"asset_id": "62853431799112511763784693741363968903595954956498708214160770466188703343964", "price": "0.22", "size": "1908", "side": "BUY", "hash": "b4994d3413e4a3bcaf496988ebcbe8dc0dfd9e13", "best_bid": "0.76", "best_ask": "0.78"}, {"asset_id": "7221299913764832338348128493889748182769672206962167820297840741811689706878", "price": "0.78", "size": "1908", "side": "SELL", "hash": "57fe3f626597ba30eb2ed22569f379449e8b6d6b", "best_bid": "0.22", "best_ask": "0.24"}], "timestamp": "1769384883613", "event_type": "price_change"}}
{"_local_timestamp": "2026-01-25T23:48:11.522857+00:00", "data": {"market": "0xd25c820d3aee1c735c0fa62c36f4905632ab8c6988653b5b4134593b3209eb7f", "price_changes": [{"asset_id": "45361184347486002884792387151438756924785609968030585696129487864334578884255", "price": "0.25", "size": "100", "side": "BUY", "hash": "6f37e0665ca2ba10f8b65b5ff0194b444b7ee2d3", "best_bid": "0.6", "best_ask": "0.67"}, {"asset_id": "91117078941733659645786554099775611998962677612187928648088119165893475827434", "price": "0.75", "size": "100", "side": "SELL", "hash": "58b054958cb7509bd71bbd8e2b176bb4a8f5ece5", "best_bid": "0.33", "best_ask": "0.4"}], "timestamp": "1769384891442", "event_type": "price_change"}}
{"_local_timestamp": "2026-01-25T23:48:11.525511+00:00", "data": {"market": "0xd25c820d3aee1c735c0fa62c36f4905632ab8c6988653b5b4134593b3209eb7f", "price_changes": [{"asset_id": "45361184347486002884792387151438756924785609968030585696129487864334578884255", "price": "0.27", "size": "74.07", "side": "BUY", "hash": "6f37e0665ca2ba10f8b65b5ff0194b444b7ee2d3", "best_bid": "0.6", "best_ask": "0.67"}, {"asset_id": "91117078941733659645786554099775611998962677612187928648088119165893475827434", "price": "0.73", "size": "74.07", "side": "SELL", "hash": "58b054958cb7509bd71bbd8e2b176bb4a8f5ece5", "best_bid": "0.33", "best_ask": "0.4"}], "timestamp": "1769384891442", "event_type": "price_change"}}
{"_local_timestamp": "2026-01-25T23:48:11.642114+00:00", "data": {"market": "0x0eada57dcf53965a321f61c9dc6adb655367fabeb1f2ecbe7746f3f1a6ff7769", "price_changes": [{"asset_id": "93593125008177926269164142727030950699068997099893975938000261506053151609883", "price": "0.485", "size": "10", "side": "BUY", "hash": "ccaed5a605577b6980bc55ad2936761a53d08086", "best_bid": "0.997", "best_ask": "0.998"}, {"asset_id": "88775412427564636095391917176836120951442159831179966305257669968799086969217", "price": "0.515", "size": "10", "side": "SELL", "hash": "3770ee4b1d1f747069549c6b3d3db51eed16ecf5", "best_bid": "0.002", "best_ask": "0.003"}], "timestamp": "1769384891567", "event_type": "price_change"}}
{"_local_timestamp": "2026-01-25T23:48:20.129894+00:00", "data": {"market": "0xd25c820d3aee1c735c0fa62c36f4905632ab8c6988653b5b4134593b3209eb7f", "price_changes": [{"asset_id": "45361184347486002884792387151438756924785609968030585696129487864334578884255", "price": "0.57", "size": "66.66", "side": "BUY", "hash": "21ea78dc305c08ce3ec074042faca7553eb4e724", "best_bid": "0.6", "best_ask": "0.67"}, {"asset_id": "91117078941733659645786554099775611998962677612187928648088119165893475827434", "price": "0.43", "size": "66.66", "side": "SELL", "hash": "e84b958ec22f46500db2742947a9206fb7989533", "best_bid": "0.33", "best_ask": "0.4"}], "timestamp": "1769384900010", "event_type": "price_change"}}
{"_local_timestamp": "2026-01-25T23:48:20.313223+00:00", "data": {"market": "0x0eada57dcf53965a321f61c9dc6adb655367fabeb1f2ecbe7746f3f1a6ff7769", "price_changes": [{"asset_id": "93593125008177926269164142727030950699068997099893975938000261506053151609883", "price": "0.485", "size": "0", "side": "BUY", "hash": "060c7a70b09fe2bd71df2e23663fd3f1f825b04b", "best_bid": "0.997", "best_ask": "0.998"}, {"asset_id": "88775412427564636095391917176836120951442159831179966305257669968799086969217", "price": "0.515", "size": "0", "side": "SELL", "hash": "3ce1ca5accc8981c5fde1ffc0c3cf88d0a8f2940", "best_bid": "0.002", "best_ask": "0.003"}], "timestamp": "1769384900249", "event_type": "price_change"}}
{"_local_timestamp": "2026-01-25T23:48:20.443849+00:00", "data": {"market": "0x0eada57dcf53965a321f61c9dc6adb655367fabeb1f2ecbe7746f3f1a6ff7769", "price_changes": [{"asset_id": "93593125008177926269164142727030950699068997099893975938000261506053151609883", "price": "0.487", "size": "11", "side": "BUY", "hash": "c776603e265b526e64cd73ad2481fd30890cbfb2", "best_bid": "0.997", "best_ask": "0.998"}, {"asset_id": "88775412427564636095391917176836120951442159831179966305257669968799086969217", "price": "0.513", "size": "11", "side": "SELL", "hash": "05a387cc87913bcc828cd60a49629148d16aa81a", "best_bid": "0.002", "best_ask": "0.003"}], "timestamp": "1769384900377", "event_type": "price_change"}}
{"_local_timestamp": "2026-01-25T23:48:20.445048+00:00", "data": {"market": "0x0eada57dcf53965a321f61c9dc6adb655367fabeb1f2ecbe7746f3f1a6ff7769", "price_changes": [{"asset_id": "93593125008177926269164142727030950699068997099893975938000261506053151609883", "price": "0.487", "size": "21", "side": "BUY", "hash": "af139c73245dc0c2b94fe5da4b9068950a94cf6f", "best_bid": "0.997", "best_ask": "0.998"}, {"asset_id": "88775412427564636095391917176836120951442159831179966305257669968799086969217", "price": "0.513", "size": "21", "side": "SELL", "hash": "1f61ed537078b21fb7c2c5658a44daceb264a981", "best_bid": "0.002", "best_ask": "0.003"}], "timestamp": "1769384900378", "event_type": "price_change"}}
{"_local_timestamp": "2026-01-25T23:48:20.446066+00:00", "data": {"market": "0x0eada57dcf53965a321f61c9dc6adb655367fabeb1f2ecbe7746f3f1a6ff7769", "price_changes": [{"asset_id": "93593125008177926269164142727030950699068997099893975938000261506053151609883", "price": "0.405", "size": "164", "side": "BUY", "hash": "21523211c0dfa2b67966fb10210cce673e706c63", "best_bid": "0.997", "best_ask": "0.998"}, {"asset_id": "88775412427564636095391917176836120951442159831179966305257669968799086969217", "price": "0.595", "size": "164", "side": "SELL", "hash": "79bec9a2d71775260597fd00d3b326002d5d2341", "best_bid": "0.002", "best_ask": "0.003"}], "timestamp": "1769384900379", "event_type": "price_change"}}
{"_local_timestamp": "2026-01-25T23:48:25.666463+00:00", "data": {"market": "0x0eada57dcf53965a321f61c9dc6adb655367fabeb1f2ecbe7746f3f1a6ff7769", "price_changes": [{"asset_id": "93593125008177926269164142727030950699068997099893975938000261506053151609883", "price": "0.486", "size": "0", "side": "BUY", "hash": "149e3928a19f389d1a4ca4007130d477296a0d3b", "best_bid": "0.997", "best_ask": "0.998"}, {"asset_id": "88775412427564636095391917176836120951442159831179966305257669968799086969217", "price": "0.514", "size": "0", "side": "SELL", "hash": "dd0117cfcdf49b5506e9ba9230c84f09b2e674eb", "best_bid": "0.002", "best_ask": "0.003"}], "timestamp": "1769384905601", "event_type": "price_change"}}
{"_local_timestamp": "2026-01-25T23:48:25.719008+00:00", "data": {"market": "0x0eada57dcf53965a321f61c9dc6adb655367fabeb1f2ecbe7746f3f1a6ff7769", "price_changes": [{"asset_id": "93593125008177926269164142727030950699068997099893975938000261506053151609883", "price": "0.488", "size": "20", "side": "BUY", "hash": "296c02faf9675a34f995a6627f788158cd9e5dc4", "best_bid": "0.997", "best_ask": "0.998"}, {"asset_id": "88775412427564636095391917176836120951442159831179966305257669968799086969217", "price": "0.512", "size": "20", "side": "SELL", "hash": "c3293f0da43dd58437e8c774d7445fb0ad5d3aab", "best_bid": "0.002", "best_ask": "0.003"}], "timestamp": "1769384905652", "event_type": "price_change"}}
{"_local_timestamp": "2026-01-25T23:48:28.052574+00:00", "data": {"market": "0xba8add06562a7bfd4fdd8f0a1882b5e2596540bd61c67a32359487694838f0a5", "price_changes": [{"asset_id": "62853431799112511763784693741363968903595954956498708214160770466188703343964", "price": "0.76", "size": "139.25", "side": "BUY", "hash": "b89ee3c577e170f779b176ee34a7fb78e529f85d", "best_bid": "0.76", "best_ask": "0.78"}, {"asset_id": "7221299913764832338348128493889748182769672206962167820297840741811689706878", "price": "0.24", "size": "139.25", "side": "SELL", "hash": "cd8c4f783108c7ac94b16b77b39c7ff6f04632e9", "best_bid": "0.22", "best_ask": "0.24"}], "timestamp": "1769384907965", "event_type": "price_change"}}
{"_local_timestamp": "2026-01-25T23:48:28.053590+00:00", "data": {"market": "0xd25c820d3aee1c735c0fa62c36f4905632ab8c6988653b5b4134593b3209eb7f", "price_changes": [{"asset_id": "45361184347486002884792387151438756924785609968030585696129487864334578884255", "price": "0.43", "size": "0", "side": "BUY", "hash": "b3a17c63127245c1e4944e4120b597d50c653790", "best_bid": "0.6", "best_ask": "0.67"}, {"asset_id": "91117078941733659645786554099775611998962677612187928648088119165893475827434", "price": "0.57", "size": "0", "side": "SELL", "hash": "8deffa2c3cb1464ffd5234ee2156853e08fe5511", "best_bid": "0.33", "best_ask": "0.4"}], "timestamp": "1769384907965", "event_type": "price_change"}}
{"_local_timestamp": "2026-01-25T23:48:28.054507+00:00", "data": {"market": "0xd25c820d3aee1c735c0fa62c36f4905632ab8c6988653b5b4134593b3209eb7f", "price_changes": [{"asset_id": "45361184347486002884792387151438756924785609968030585696129487864334578884255", "price": "0.25", "size": "0", "side": "BUY", "hash": "b3a17c63127245c1e4944e4120b597d50c653790", "best_bid": "0.6", "best_ask": "0.67"}, {"asset_id": "91117078941733659645786554099775611998962677612187928648088119165893475827434", "price": "0.75", "size": "0", "side": "SELL", "hash": "8deffa2c3cb1464ffd5234ee2156853e08fe5511", "best_bid": "0.33", "best_ask": "0.4"}], "timestamp": "1769384907965", "event_type": "price_change"}}
