{"_local_timestamp": "2026-01-25T23:33:35.333486+00:00", "data": [{"market": "0x005c717a74e620db3360f9820aa2ed4d986c7f26de68491a969980cb1780ea62", "asset_id": "71896965718321739380350615937116799467572851624467621515057427915300050709178", "timestamp": "1769383926669", "hash": "a17b1cf1edc9ff069606e8967526d2e58eb7ca78", "bids": [{"price": "0.001", "size": "1829.05"}, {"price": "0.002", "size": "13754.95"}, {"price": "0.003", "size": "3025.97"}, {"price": "0.004", "size": "250"}, {"price": "0.005", "size": "743"}], "asks": [{"price": "0.999", "size": "3390.61"}, {"price": "0.998", "size": "1260.54"}, {"price": "0.997", "size": "1166"}, {"price": "0.996", "size": "7.82"}, {"price": "0.994", "size": "83"}, {"price": "0.993", "size": "5.86"}, {"price": "0.99", "size": "17030"}, {"price": "0.989", "size": "12.54"}, {"price": "0.98", "size": "5000"}, {"price": "0.97", "size": "4000"}, {"price": "0.95", "size": "30"}, {"price": "0.949", "size": "39"}, {"price": "0.94", "size": "2000"}, {"price": "0.881", "size": "1000"}, {"price": "0.879", "size": "1706.97"}, {"price": "0.878", "size": "6"}, {"price": "0.8", "size": "50"}, {"price": "0.73", "size": "50"}, {"price": "0.66", "size": "50"}, {"price": "0.05", "size": "5"}, {"price": "0.034", "size": "294.3"}, {"price": "0.02", "size": "240"}, {"price": "0.019", "size": "139.37"}, {"price": "0.018", "size": "12.07"}, {"price": "0.017", "size": "16"}], "event_type": "book", "last_trade_price": "0.006"}, {"market": "0x41373abec915e2e3a8cef7cba7c0d1d9e6ec4a5e178a91b66f9f865d42e25f5a", "asset_id": "100329420496717716452754922170157640544046003644556314600365703892190352929139", "timestamp": "1769384006722", "hash": "676cd9deeb461111f9f6422e493c0e08f6661a90", "bids": [{"price": "0.001", "size": "3461.61"}, {"price": "0.002", "size": "1260.54"}, {"price": "0.003", "size": "1000"}, {"price": "0.004", "size": "18.08"}, {"price": "0.01", "size": "62030"}, {"price": "0.011", "size": "12.54"}, {"price": "0.02", "size": "5025"}, {"price": "0.03", "size": "17250"}, {"price": "0.05", "size": "20"}, {"price": "0.051", "size": "39"}, {"price": "0.06", "size": "9440"}, {"price": "0.1", "size": "2100"}, {"price": "0.165", "size": "900"}, {"price": "0.2", "size": "50"}, {"price": "0.27", "size": "50"}, {"price": "0.336", "size": "1500"}, {"price": "0.34", "size": "50"}, {"price": "0.342", "size": "23"}, {"price": "0.908", "size": "200"}, {"price": "0.939", "size": "238.69"}, {"price": "0.959", "size": "100"}, {"price": "0.964", "size": "11"}, {"price": "0.965", "size": "26"}, {"price": "0.966", "size": "25"}, {"price": "0.967", "size": "101.94"}], "asks": [{"price": "0.999", "size": "6543.12"}, {"price": "0.998", "size": "111.05"}, {"price": "0.997", "size": "52"}, {"price": "0.996", "size": "16.65"}, {"price": "0.99", "size": "30"}], "event_type": "book", "last_trade_price": "0.025"}, {"market": "0x26f00204e5e6998d9356584f72286fa4aeee82fe94a16c81c2a28f4484af3eb7", "asset_id": "43869848633896688810093697675508388464557353551955271690890077141499773498664", "timestamp": "1769380227007", "hash": "ae7b3ee28affd76dea3cf59535e41791bb824cb9", "bids": [{"price": "0.001", "size": "5079.75"}, {"price": "0.002", "size": "446.23"}], "asks": [{"price": "0.999", "size": "3390.61"}, {"price": "0.998", "size": "1260.54"}, {"price": "0.997", "size": "1166"}, {"price": "0.996", "size": "7.82"}, {"price": "0.994", "size": "83"}, {"price": "0.993", "size": "10.19"}, {"price": "0.99", "size": "12030"}, {"price": "0.987", "size": "4000"}, {"price": "0.986", "size": "7.69"}, {"price": "0.98", "size": "1000"}, {"price": "0.97", "size": "4016"}, {"price": "0.95", "size": "20"}, {"price": "0.949", "size": "39"}, {"price": "0.947", "size": "5000"}, {"price": "0.94", "size": "2000"}, {"price": "0.85", "size": "900"}, {"price": "0.8", "size": "50"}, {"price": "0.797", "size": "62"}, {"price": "0.73", "size": "50"}, {"price": "0.66", "size": "50"}, {"price": "0.477", "size": "160"}, {"price": "0.007", "size": "41.25"}, {"price": "0.006", "size": "137"}], "event_type": "book", "last_trade_price": "0.002"}, {"market": "0xe9b3144e4d27aaef1f0821d70460d6d3260d79895e9968ccd2dc55a0dbdf6088", "asset_id": "83041154468219618230051081276875453907060636113065729539423582864425510953850", "timestamp": "1769383980858", "hash": "38b4b02d22fadb057f39a19931707aa389c4f2d6", "bids": [{"price": "0.001", "size": "9931.57"}, {"price": "0.002", "size": "1260.5"}, {"price": "0.003", "size": "1166"}, {"price": "0.004", "size": "7.78"}, {"price": "0.006", "size": "83"}, {"price": "0.007", "size": "5.84"}, {"price": "0.01", "size": "15035"}, {"price": "0.011", "size": "12.49"}, {"price": "0.02", "size": "4000"}, {"price": "0.04", "size": "12"}, {"price": "0.05", "size": "20"}, {"price": "0.051", "size": "39"}, {"price": "0.06", "size": "3000"}, {"price": "0.168", "size": "2000"}, {"price": "0.169", "size": "375.02"}, {"price": "0.209", "size": "46"}, {"price": "0.46", "size": "10"}, {"price": "0.56", "size": "20"}, {"price": "0.6", "size": "10"}, {"price": "0.78", "size": "15"}, {"price": "0.941", "size": "24.99"}, {"price": "0.956", "size": "15"}, {"price": "0.957", "size": "29.19"}], "asks": [{"price": "0.999", "size": "5300"}, {"price": "0.998", "size": "16.79"}, {"price": "0.996", "size": "14"}, {"price": "0.995", "size": "10.99"}, {"price": "0.99", "size": "30"}], "event_type": "book", "last_trade_price": "0.976"}, {"market": "0x26f00204e5e6998d9356584f72286fa4aeee82fe94a16c81c2a28f4484af3eb7", "asset_id": "74779851666016693536176049763523952181814820363978248066763707929069193960048", "timestamp": "1769380227007", "hash": "aa0d6ffed07f896b2886fd090544fcd40b542df9", "bids": [{"price": "0.001", "size": "3390.61"}, {"price": "0.002", "size": "1260.54"}, {"price": "0.003", "size": "1166"}, {"price": "0.004", "size": "7.82"}, {"price": "0.006", "size": "83"}, {"price": "0.007", "size": "10.19"}, {"price": "0.01", "size": "12030"}, {"price": "0.013", "size": "4000"}, {"price": "0.014", "size": "7.69"}, {"price": "0.02", "size": "1000"}, {"price": "0.03", "size": "4016"}, {"price": "0.05", "size": "20"}, {"price": "0.051", "size": "39"}, {"price": "0.053", "size": "5000"}, {"price": "0.06", "size": "2000"}, {"price": "0.15", "size": "900"}, {"price": "0.2", "size": "50"}, {"price": "0.203", "size": "62"}, {"price": "0.27", "size": "50"}, {"price": "0.34", "size": "50"}, {"price": "0.523", "size": "160"}, {"price": "0.993", "size": "41.25"}, {"price": "0.994", "size": "137"}], "asks": [{"price": "0.999", "size": "5079.75"}, {"price": "0.998", "size": "446.23"}], "event_type": "book", "last_trade_price": "0.002"}, {"market": "0x9a991a29bbb2bb8118237815223c4b906328b7e8a373aa97fdae409a025470dc", "asset_id": "68257431892288883729500648109357161057886471290823106810192273382603520923445", "timestamp": "1769384013687", "hash": "232397e13bb0e99f3919281699f2ba00573c226d", "bids": [{"price": "0.01", "size": "17118.4"}, {"price": "0.02", "size": "5032.85"}, {"price": "0.03", "size": "6000"}, {"price": "0.05", "size": "20"}, {"price": "0.06", "size": "3033"}, {"price": "0.08", "size": "2337"}, {"price": "0.13", "size": "707"}, {"price": "0.19", "size": "1500"}, {"price": "0.2", "size": "200"}, {"price": "0.21", "size": "249.99"}, {"price": "0.3", "size": "174"}, {"price": "0.34", "size": "50"}, {"price": "0.6", "size": "25"}, {"price": "0.7", "size": "225"}, {"price": "0.73", "size": "17.8"}, {"price": "0.74", "size": "24.86"}, {"price": "0.75", "size": "431"}, {"price": "0.81", "size": "69"}], "asks": [{"price": "0.99", "size": "115"}, {"price": "0.98", "size": "36.48"}, {"price": "0.97", "size": "250"}, {"price": "0.96", "size": "200"}, {"price": "0.95", "size": "260"}, {"price": "0.94", "size": "91.66"}, {"price": "0.93", "size": "10"}, {"price": "0.92", "size": "90"}, {"price": "0.91", "size": "178.98"}, {"price": "0.9", "size": "30"}], "event_type": "book", "last_trade_price": "0.120"}, {"market": "0xa13544013dbc02a521a76ed02f83ad6460685bd39feb473102e7bd70dd99d8ff", "asset_id": "26021751047369715375601287259643716564498254070983387986316147775059109952622", "timestamp": "1769377652452", "hash": "08c1ed31e21930a9f42fd7024eddf716652c46cd", "bids": [{"price": "0.001", "size": "6210"}, {"price": "0.002", "size": "151.78"}], "asks": [{"price": "0.999", "size": "3390.61"}, {"price": "0.998", "size": "1260.54"}, {"price": "0.997", "size": "1166"}, {"price": "0.996", "size": "7.82"}, {"price": "0.994", "size": "83"}, {"price": "0.993", "size": "5.86"}, {"price": "0.99", "size": "17030"}, {"price": "0.989", "size": "12.54"}, {"price": "0.98", "size": "5000"}, {"price": "0.97", "size": "6000"}, {"price": "0.96", "size": "12"}, {"price": "0.95", "size": "20"}, {"price": "0.949", "size": "39"}, {"price": "0.94", "size": "3000"}, {"price": "0.91", "size": "1400"}, {"price": "0.834", "size": "1900"}, {"price": "0.8", "size": "50"}, {"price": "0.797", "size": "62"}, {"price": "0.73", "size": "50"}, {"price": "0.66", "size": "50"}, {"price": "0.05", "size": "5"}, {"price": "0.041", "size": "200"}, {"price": "0.02", "size": "100"}, {"price": "0.019", "size": "38.8"}, {"price": "0.018", "size": "19"}], "event_type": "book", "last_trade_price": "0.002"}, {"market": "0x680784812145063cecedfa7f000654e89317e2aca612182884d7742ac6f801f9", "asset_id": "60410997855954556286106048831701517763027421942281960711866162404690269293947", "timestamp": "1769384008863", "hash": "867e0f652c896156660ff99711ba3811c0ea2d42", "bids": [{"price": "0.01", "size": "17123.4"}, {"price": "0.02", "size": "5032.85"}, {"price": "0.03", "size": "6000"}, {"price": "0.06", "size": "2000"}, {"price": "0.12", "size": "958"}, {"price": "0.14", "size": "900"}, {"price": "0.15", "size": "2798"}, {"price": "0.2", "size": "50"}, {"price": "0.24", "size": "45"}, {"price": "0.27", "size": "50"}, {"price": "0.28", "size": "91.87"}, {"price": "0.34", "size": "50"}, {"price": "0.5", "size": "225"}, {"price": "0.71", "size": "33.79"}, {"price": "0.72", "size": "10"}, {"price": "0.74", "size": "200"}, {"price": "0.78", "size": "975.68"}], "asks": [{"price": "0.99", "size": "10110"}, {"price": "0.98", "size": "2036.48"}, {"price": "0.96", "size": "250"}, {"price": "0.92", "size": "225"}, {"price": "0.9", "size": "130"}, {"price": "0.89", "size": "100"}, {"price": "0.88", "size": "208.12"}, {"price": "0.87", "size": "10"}, {"price": "0.85", "size": "284"}, {"price": "0.81", "size": "25.26"}], "event_type": "book", "last_trade_price": "0.780"}, {"market": "0xe220ab18b19107b4a06b18a0b5e2a9e9ab4cd7cb297c27cfa05a3369815a1579", "asset_id": "43938988181832985104138029041174463994072038957372562854085197368645176157001", "timestamp": "1769383980824", "hash": "8cca919cecbb642f756c2a7c76d09bd692b2336d", "bids": [{"price": "0.01", "size": "10035.79"}, {"price": "0.02", "size": "2008.98"}, {"price": "0.03", "size": "16"}, {"price": "0.04", "size": "133"}, {"price": "0.09", "size": "225"}, {"price": "0.11", "size": "30"}, {"price": "0.13", "size": "100"}, {"price": "0.16", "size": "68.75"}, {"price": "0.17", "size": "62"}, {"price": "0.18", "size": "8.5"}, {"price": "0.23", "size": "37.58"}], "asks": [{"price": "0.99", "size": "12038.4"}, {"price": "0.98", "size": "5007.85"}, {"price": "0.97", "size": "4016"}, {"price": "0.95", "size": "20"}, {"price": "0.94", "size": "2033"}, {"price": "0.93", "size": "1642"}, {"price": "0.85", "size": "900"}, {"price": "0.83", "size": "235"}, {"price": "0.8", "size": "950"}, {"price": "0.79", "size": "25"}, {"price": "0.73", "size": "50"}, {"price": "0.66", "size": "50"}, {"price": "0.53", "size": "225"}, {"price": "0.52", "size": "8.5"}, {"price": "0.46", "size": "24.07"}, {"price": "0.44", "size": "29.64"}, {"price": "0.33", "size": "37.58"}, {"price": "0.32", "size": "162.39"}], "event_type": "book", "last_trade_price": "0.700"}, {"market": "0x41373abec915e2e3a8cef7cba7c0d1d9e6ec4a5e178a91b66f9f865d42e25f5a", "asset_id": "29556010438361126694289480706796694499056500131992831406127167366453435201495", "timestamp": "1769384006722", "hash": "bc911770e34bc464499e999dfda10948c978d2c7", "bids": [{"price": "0.001", "size": "6543.12"}, {"price": "0.002", "size": "111.05"}, {"price": "0.003", "size": "52"}, {"price": "0.004", "size": "16.65"}, {"price": "0.01", "size": "30"}], "asks": [{"price": "0.999", "size": "3461.61"}, {"price": "0.998", "size": "1260.54"}, {"price": "0.997", "size": "1000"}, {"price": "0.996", "size": "18.08"}, {"price": "0.99", "size": "62030"}, {"price": "0.989", "size": "12.54"}, {"price": "0.98", "size": "5025"}, {"price": "0.97", "size": "17250"}, {"price": "0.95", "size": "20"}, {"price": "0.949", "size": "39"}, {"price": "0.94", "size": "9440"}, {"price": "0.9", "size": "2100"}, {"price": "0.835", "size": "900"}, {"price": "0.8", "size": "50"}, {"price": "0.73", "size": "50"}, {"price": "0.664", "size": "1500"}, {"price": "0.66", "size": "50"}, {"price": "0.658", "size": "23"}, {"price": "0.092", "size": "200"}, {"price": "0.061", "size": "238.69"}, {"price": "0.041", "size": "100"}, {"price": "0.036", "size": "11"}, {"price": "0.035", "size": "26"}, {"price": "0.034", "size": "25"}, {"price": "0.033", "size": "101.94"}], "event_type": "book", "last_trade_price": "0.025"}, {"market": "0x7bc1d3c8aaf0a20c853f576519446e1ee260e65d43205efd61696f3a9f9e62e7", "asset_id": "10966407605514195233392457845926539733586231163297093857244655359507639639996", "timestamp": "1769384013699", "hash": "c4e11fbf8a886ba70b5a78a6ffed72de3aa59898", "bids": [{"price": "0.001", "size": "7726.57"}, {"price": "0.002", "size": "857.7"}, {"price": "0.003", "size": "25.97"}, {"price": "0.004", "size": "125"}, {"price": "0.005", "size": "239.99"}, {"price": "0.006", "size": "251"}], "asks": [{"price": "0.999", "size": "9932.61"}, {"price": "0.998", "size": "1260.54"}, {"price": "0.997", "size": "1166"}, {"price": "0.996", "size": "7.82"}, {"price": "0.994", "size": "83"}, {"price": "0.993", "size": "10.19"}, {"price": "0.99", "size": "15035"}, {"price": "0.987", "size": "2000"}, {"price": "0.986", "size": "7.69"}, {"price": "0.976", "size": "291"}, {"price": "0.96", "size": "12"}, {"price": "0.95", "size": "20"}, {"price": "0.949", "size": "39"}, {"price": "0.889", "size": "3000"}, {"price": "0.888", "size": "10000"}, {"price": "0.887", "size": "172.88"}, {"price": "0.832", "size": "10"}, {"price": "0.176", "size": "33"}, {"price": "0.089", "size": "34.47"}, {"price": "0.087", "size": "25"}, {"price": "0.086", "size": "23.94"}], "event_type": "book", "last_trade_price": "0.004"}, {"market": "0x7bc1d3c8aaf0a20c853f576519446e1ee260e65d43205efd61696f3a9f9e62e7", "asset_id": "74853086974054252708530367393532530785660539289108031053683362073748574770022", "timestamp": "1769384013699", "hash": "092bd7090aaf99946468e4e681e8dc6569daa44d", "bids": [{"price": "0.001", "size": "9932.61"}, {"price": "0.002", "size": "1260.54"}, {"price": "0.003", "size": "1166"}, {"price": "0.004", "size": "7.82"}, {"price": "0.006", "size": "83"}, {"price": "0.007", "size": "10.19"}, {"price": "0.01", "size": "15035"}, {"price": "0.013", "size": "2000"}, {"price": "0.014", "size": "7.69"}, {"price": "0.024", "size": "291"}, {"price": "0.04", "size": "12"}, {"price": "0.05", "size": "20"}, {"price": "0.051", "size": "39"}, {"price": "0.111", "size": "3000"}, {"price": "0.112", "size": "10000"}, {"price": "0.113", "size": "172.88"}, {"price": "0.168", "size": "10"}, {"price": "0.824", "size": "33"}, {"price": "0.911", "size": "34.47"}, {"price": "0.913", "size": "25"}, {"price": "0.914", "size": "23.94"}], "asks": [{"price": "0.999", "size": "7726.57"}, {"price": "0.998", "size": "857.7"}, {"price": "0.997", "size": "25.97"}, {"price": "0.996", "size": "125"}, {"price": "0.995", "size": "239.99"}, {"price": "0.994", "size": "251"}], "event_type": "book", "last_trade_price": "0.004"}, {"market": "0xcba2e5c2ae0c304be0b0bda9766ea909d3200c485e9d177397bc3da9e6fa84fa", "asset_id": "58928745853810789409871848444700893878861272591834748654309903811018704088285", "timestamp": "1769383980817", "hash": "ef34e63072539e7389764f5a7cffc6916bd42154", "bids": [{"price": "0.001", "size": "5742.26"}, {"price": "0.002", "size": "481.5"}, {"price": "0.003", "size": "143"}], "asks": [{"price": "0.999", "size": "3401.61"}, {"price": "0.998", "size": "1260.54"}, {"price": "0.997", "size": "1166"}, {"price": "0.996", "size": "7.82"}, {"price": "0.994", "size": "83"}, {"price": "0.993", "size": "5.86"}, {"price": "0.99", "size": "17030"}, {"price": "0.989", "size": "12.54"}, {"price": "0.98", "size": "5000"}, {"price": "0.97", "size": "4016"}, {"price": "0.95", "size": "20"}, {"price": "0.949", "size": "39"}, {"price": "0.94", "size": "2000"}, {"price": "0.888", "size": "1900"}, {"price": "0.829", "size": "900"}, {"price": "0.827", "size": "8"}, {"price": "0.8", "size": "50"}, {"price": "0.73", "size": "50"}, {"price": "0.66", "size": "50"}, {"price": "0.099", "size": "200"}, {"price": "0.098", "size": "7.91"}, {"price": "0.043", "size": "9.47"}, {"price": "0.034", "size": "15"}], "event_type": "book", "last_trade_price": "0.010"}, {"market": "0x34c320af835b2d4b56224618b9930e3a6b26ed7f6854c4f8ce04b35f6d3ee801", "asset_id": "31278264626330879886341915760798723117251320102541744661396613642093503516942", "timestamp": "1769384013687", "hash": "72da1da81cb5112c94d12d28155efcc08dfbbaa4", "bids": [{"price": "0.001", "size": "12263.57"}, {"price": "0.002", "size": "1260.5"}, {"price": "0.003", "size": "1166"}, {"price": "0.004", "size": "7.78"}, {"price": "0.006", "size": "83"}, {"price": "0.007", "size": "5.84"}, {"price": "0.01", "size": "62035"}, {"price": "0.011", "size": "12.49"}, {"price": "0.02", "size": "5025"}, {"price": "0.03", "size": "17250"}, {"price": "0.05", "size": "20"}, {"price": "0.051", "size": "39"}, {"price": "0.06", "size": "9440"}, {"price": "0.096", "size": "5900"}, {"price": "0.097", "size": "1185"}, {"price": "0.174", "size": "4150"}, {"price": "0.175", "size": "228"}, {"price": "0.253", "size": "300"}, {"price": "0.254", "size": "3302"}, {"price": "0.27", "size": "50"}, {"price": "0.34", "size": "50"}, {"price": "0.732", "size": "17.75"}, {"price": "0.733", "size": "15"}, {"price": "0.74", "size": "225"}, {"price": "0.821", "size": "500"}, {"price": "0.833", "size": "7.19"}, {"price": "0.834", "size": "10"}, {"price": "0.851", "size": "1000"}, {"price": "0.852", "size": "115.31"}, {"price": "0.853", "size": "30"}], "asks": [{"price": "0.999", "size": "1030"}, {"price": "0.998", "size": "62.56"}, {"price": "0.99", "size": "30"}, {"price": "0.989", "size": "9.51"}, {"price": "0.985", "size": "798.64"}, {"price": "0.982", "size": "258.26"}, {"price": "0.98", "size": "67"}, {"price": "0.979", "size": "10"}, {"price": "0.915", "size": "10"}, {"price": "0.903", "size": "337.77"}], "event_type": "book", "last_trade_price": "0.903"}, {"market": "0xa13544013dbc02a521a76ed02f83ad6460685bd39feb473102e7bd70dd99d8ff", "asset_id": "62900796879922546488768913790997438430155783119511584193921241632996603987510", "timestamp": "1769377652452", "hash": "7c77b16517a6a4b7ae491fa9541a26274f8cbfa9", "bids": [{"price": "0.001", "size": "3390.61"}, {"price": "0.002", "size": "1260.54"}, {"price": "0.003", "size": "1166"}, {"price": "0.004", "size": "7.82"}, {"price": "0.006", "size": "83"}, {"price": "0.007", "size": "5.86"}, {"price": "0.01", "size": "17030"}, {"price": "0.011", "size": "12.54"}, {"price": "0.02", "size": "5000"}, {"price": "0.03", "size": "6000"}, {"price": "0.04", "size": "12"}, {"price": "0.05", "size": "20"}, {"price": "0.051", "size": "39"}, {"price": "0.06", "size": "3000"}, {"price": "0.09", "size": "1400"}, {"price": "0.166", "size": "1900"}, {"price": "0.2", "size": "50"}, {"price": "0.203", "size": "62"}, {"price": "0.27", "size": "50"}, {"price": "0.34", "size": "50"}, {"price": "0.95", "size": "5"}, {"price": "0.959", "size": "200"}, {"price": "0.98", "size": "100"}, {"price": "0.981", "size": "38.8"}, {"price": "0.982", "size": "19"}], "asks": [{"price": "0.999", "size": "6210"}, {"price": "0.998", "size": "151.78"}], "event_type": "book", "last_trade_price": "0.002"}, {"market": "0xe9b3144e4d27aaef1f0821d70460d6d3260d79895e9968ccd2dc55a0dbdf6088", "asset_id": "32376553431351473284586567513108813920800512906624908199970979285958436186934", "timestamp": "1769383980858", "hash": "dd62385c15296d6e22d8a1c1752695d9b2ebbeca", "bids": [{"price": "0.001", "size": "5300"}, {"price": "0.002", "size": "16.79"}, {"price": "0.004", "size": "14"}, {"price": "0.005", "size": "10.99"}, {"price": "0.01", "size": "30"}], "asks": [{"price": "0.999", "size": "9931.57"}, {"price": "0.998", "size": "1260.5"}, {"price": "0.997", "size": "1166"}, {"price": "0.996", "size": "7.78"}, {"price": "0.994", "size": "83"}, {"price": "0.993", "size": "5.84"}, {"price": "0.99", "size": "15035"}, {"price": "0.989", "size": "12.49"}, {"price": "0.98", "size": "4000"}, {"price": "0.96", "size": "12"}, {"price": "0.95", "size": "20"}, {"price": "0.949", "size": "39"}, {"price": "0.94", "size": "3000"}, {"price": "0.832", "size": "2000"}, {"price": "0.831", "size": "375.02"}, {"price": "0.791", "size": "46"}, {"price": "0.54", "size": "10"}, {"price": "0.44", "size": "20"}, {"price": "0.4", "size": "10"}, {"price": "0.22", "size": "15"}, {"price": "0.059", "size": "24.99"}, {"price": "0.044", "size": "15"}, {"price": "0.043", "size": "29.19"}], "event_type": "book", "last_trade_price": "0.976"}, {"market": "0x5e075035583f3bf066377b92593a81ee9b40c72886cd590571c953d957ec63fe", "asset_id": "115197249944798189466746855761602104266555395842031026841909545353040514904580", "timestamp": "1769384013272", "hash": "df05f746404b834e0bdb13616e94cbd975fcbd12", "bids": [{"price": "0.01", "size": "62037.95"}, {"price": "0.02", "size": "5008.07"}, {"price": "0.03", "size": "17266"}, {"price": "0.06", "size": "9440"}, {"price": "0.1", "size": "5900"}, {"price": "0.11", "size": "4181"}, {"price": "0.15", "size": "2650"}, {"price": "0.16", "size": "250"}, {"price": "0.25", "size": "225"}, {"price": "0.35", "size": "37.14"}, {"price": "0.36", "size": "30.55"}, {"price": "0.37", "size": "6.99"}, {"price": "0.38", "size": "10"}, {"price": "0.42", "size": "70"}, {"price": "0.43", "size": "204.83"}, {"price": "0.44", "size": "1410.01"}], "asks": [{"price": "0.99", "size": "17043.4"}, {"price": "0.98", "size": "5007.85"}, {"price": "0.97", "size": "6016"}, {"price": "0.94", "size": "3000"}, {"price": "0.93", "size": "1142"}, {"price": "0.9", "size": "21"}, {"price": "0.85", "size": "900"}, {"price": "0.84", "size": "2624"}, {"price": "0.83", "size": "250"}, {"price": "0.74", "size": "225"}, {"price": "0.65", "size": "37.14"}, {"price": "0.64", "size": "30.55"}, {"price": "0.49", "size": "50.7"}, {"price": "0.48", "size": "80"}, {"price": "0.47", "size": "472"}, {"price": "0.46", "size": "50.78"}], "event_type": "book", "last_trade_price": "0.460"}, {"market": "0xcba2e5c2ae0c304be0b0bda9766ea909d3200c485e9d177397bc3da9e6fa84fa", "asset_id": "18326549491448085673538041550737399122005663684871535659338787725758240014500", "timestamp": "1769383980817", "hash": "3ea5408e5cb3ee462fb2b2a85855b3f606935676", "bids": [{"price": "0.001", "size": "3401.61"}, {"price": "0.002", "size": "1260.54"}, {"price": "0.003", "size": "1166"}, {"price": "0.004", "size": "7.82"}, {"price": "0.006", "size": "83"}, {"price": "0.007", "size": "5.86"}, {"price": "0.01", "size": "17030"}, {"price": "0.011", "size": "12.54"}, {"price": "0.02", "size": "5000"}, {"price": "0.03", "size": "4016"}, {"price": "0.05", "size": "20"}, {"price": "0.051", "size": "39"}, {"price": "0.06", "size": "2000"}, {"price": "0.112", "size": "1900"}, {"price": "0.171", "size": "900"}, {"price": "0.173", "size": "8"}, {"price": "0.2", "size": "50"}, {"price": "0.27", "size": "50"}, {"price": "0.34", "size": "50"}, {"price": "0.901", "size": "200"}, {"price": "0.902", "size": "7.91"}, {"price": "0.957", "size": "9.47"}, {"price": "0.966", "size": "15"}], "asks": [{"price": "0.999", "size": "5742.26"}, {"price": "0.998", "size": "481.5"}, {"price": "0.997", "size": "143"}], "event_type": "book", "last_trade_price": "0.010"}, {"market": "0xc5c870d2ca29e41ac55e1fac0c7b3c1140eb58fdf26fd2a77284caa9aca1b3aa", "asset_id": "106940491396743186324486767673070552626952698856095995665708923002375094057739", "timestamp": "1769384011886", "hash": "aaaff8189d4465b4e46062938d9d55f4473eaa37", "bids": [{"price": "0.001", "size": "2454.99"}, {"price": "0.002", "size": "50255.5"}, {"price": "0.003", "size": "10.86"}, {"price": "0.006", "size": "83"}, {"price": "0.007", "size": "47.1"}, {"price": "0.009", "size": "36.55"}, {"price": "0.01", "size": "30"}, {"price": "0.011", "size": "13.06"}, {"price": "0.03", "size": "20.1"}, {"price": "0.043", "size": "46.35"}], "asks": [{"price": "0.999", "size": "3175.56"}, {"price": "0.998", "size": "1260.5"}, {"price": "0.997", "size": "1000"}, {"price": "0.996", "size": "18.01"}, {"price": "0.99", "size": "17030"}, {"price": "0.989", "size": "12.49"}, {"price": "0.98", "size": "5025"}, {"price": "0.97", "size": "4000"}, {"price": "0.95", "size": "20"}, {"price": "0.949", "size": "39"}, {"price": "0.94", "size": "2000"}, {"price": "0.889", "size": "2900"}, {"price": "0.885", "size": "17"}, {"price": "0.8", "size": "50"}, {"price": "0.73", "size": "50"}, {"price": "0.66", "size": "50"}, {"price": "0.15", "size": "225"}, {"price": "0.149", "size": "94.36"}, {"price": "0.045", "size": "46.02"}], "event_type": "book", "last_trade_price": "0.043"}, {"market": "0x34c320af835b2d4b56224618b9930e3a6b26ed7f6854c4f8ce04b35f6d3ee801", "asset_id": "21965236637806877423690456379421697078490533519739537235259143695240300903846", "timestamp": "1769384013687", "hash": "f6623be5e073701089378da5a687d4cceeb1034d", "bids": [{"price": "0.001", "size": "1030"}, {"price": "0.002", "size": "62.56"}, {"price": "0.01", "size": "30"}, {"price": "0.011", "size": "9.51"}, {"price": "0.015", "size": "798.64"}, {"price": "0.018", "size": "258.26"}, {"price": "0.02", "size": "67"}, {"price": "0.021", "size": "10"}, {"price": "0.085", "size": "10"}, {"price": "0.097", "size": "337.77"}], "asks": [{"price": "0.999", "size": "12263.57"}, {"price": "0.998", "size": "1260.5"}, {"price": "0.997", "size": "1166"}, {"price": "0.996", "size": "7.78"}, {"price": "0.994", "size": "83"}, {"price": "0.993", "size": "5.84"}, {"price": "0.99", "size": "62035"}, {"price": "0.989", "size": "12.49"}, {"price": "0.98", "size": "5025"}, {"price": "0.97", "size": "17250"}, {"price": "0.95", "size": "20"}, {"price": "0.949", "size": "39"}, {"price": "0.94", "size": "9440"}, {"price": "0.904", "size": "5900"}, {"price": "0.903", "size": "1185"}, {"price": "0.826", "size": "4150"}, {"price": "0.825", "size": "228"}, {"price": "0.747", "size": "300"}, {"price": "0.746", "size": "3302"}, {"price": "0.73", "size": "50"}, {"price": "0.66", "size": "50"}, {"price": "0.268", "size": "17.75"}, {"price": "0.267", "size": "15"}, {"price": "0.26", "size": "225"}, {"price": "0.179", "size": "500"}, {"price": "0.167", "size": "7.19"}, {"price": "0.166", "size": "10"}, {"price": "0.149", "size": "1000"}, {"price": "0.148", "size": "115.31"}, {"price": "0.147", "size": "30"}], "event_type": "book", "last_trade_price": "0.903"}, {"market": "0x680784812145063cecedfa7f000654e89317e2aca612182884d7742ac6f801f9", "asset_id": "76179285001548801832051437870901871012966717962774017789970710364900180173602", "timestamp": "1769384008863", "hash": "3d8107042a785d0376db6854f5105e6328466fed", "bids": [{"price": "0.01", "size": "10110"}, {"price": "0.02", "size": "2036.48"}, {"price": "0.04", "size": "250"}, {"price": "0.08", "size": "225"}, {"price": "0.1", "size": "130"}, {"price": "0.11", "size": "100"}, {"price": "0.12", "size": "208.12"}, {"price": "0.13", "size": "10"}, {"price": "0.15", "size": "284"}, {"price": "0.19", "size": "25.26"}], "asks": [{"price": "0.99", "size": "17123.4"}, {"price": "0.98", "size": "5032.85"}, {"price": "0.97", "size": "6000"}, {"price": "0.94", "size": "2000"}, {"price": "0.88", "size": "958"}, {"price": "0.86", "size": "900"}, {"price": "0.85", "size": "2798"}, {"price": "0.8", "size": "50"}, {"price": "0.76", "size": "45"}, {"price": "0.73", "size": "50"}, {"price": "0.72", "size": "91.87"}, {"price": "0.66", "size": "50"}, {"price": "0.5", "size": "225"}, {"price": "0.29", "size": "33.79"}, {"price": "0.28", "size": "10"}, {"price": "0.26", "size": "200"}, {"price": "0.22", "size": "975.68"}], "event_type": "book", "last_trade_price": "0.780"}, {"market": "0x005c717a74e620db3360f9820aa2ed4d986c7f26de68491a969980cb1780ea62", "asset_id": "76814623564203765431691483348264556272430488581668919316696049026942353449018", "timestamp": "1769383926669", "hash": "6e77648afa74bc09abbd4ff4206ccf696275af1c", "bids": [{"price": "0.001", "size": "3390.61"}, {"price": "0.002", "size": "1260.54"}, {"price": "0.003", "size": "1166"}, {"price": "0.004", "size": "7.82"}, {"price": "0.006", "size": "83"}, {"price": "0.007", "size": "5.86"}, {"price": "0.01", "size": "17030"}, {"price": "0.011", "size": "12.54"}, {"price": "0.02", "size": "5000"}, {"price": "0.03", "size": "4000"}, {"price": "0.05", "size": "30"}, {"price": "0.051", "size": "39"}, {"price": "0.06", "size": "2000"}, {"price": "0.119", "size": "1000"}, {"price": "0.121", "size": "1706.97"}, {"price": "0.122", "size": "6"}, {"price": "0.2", "size": "50"}, {"price": "0.27", "size": "50"}, {"price": "0.34", "size": "50"}, {"price": "0.95", "size": "5"}, {"price": "0.966", "size": "294.3"}, {"price": "0.98", "size": "240"}, {"price": "0.981", "size": "139.37"}, {"price": "0.982", "size": "12.07"}, {"price": "0.983", "size": "16"}], "asks": [{"price": "0.999", "size": "1829.05"}, {"price": "0.998", "size": "13754.95"}, {"price": "0.997", "size": "3025.97"}, {"price": "0.996", "size": "250"}, {"price": "0.995", "size": "743"}], "event_type": "book", "last_trade_price": "0.006"}, {"market": "0x9a991a29bbb2bb8118237815223c4b906328b7e8a373aa97fdae409a025470dc", "asset_id": "108210708594024455543283956523953124001017416937788990111411478336430517420393", "timestamp": "1769384013687", "hash": "c0aa3b06fc7f139e24275872ec9fefda7d1cc85c", "bids": [{"price": "0.01", "size": "115"}, {"price": "0.02", "size": "36.48"}, {"price": "0.03", "size": "250"}, {"price": "0.04", "size": "200"}, {"price": "0.05", "size": "260"}, {"price": "0.06", "size": "91.66"}, {"price": "0.07", "size": "10"}, {"price": "0.08", "size": "90"}, {"price": "0.09", "size": "178.98"}, {"price": "0.1", "size": "30"}], "asks": [{"price": "0.99", "size": "17118.4"}, {"price": "0.98", "size": "5032.85"}, {"price": "0.97", "size": "6000"}, {"price": "0.95", "size": "20"}, {"price": "0.94", "size": "3033"}, {"price": "0.92", "size": "2337"}, {"price": "0.87", "size": "707"}, {"price": "0.81", "size": "1500"}, {"price": "0.8", "size": "200"}, {"price": "0.79", "size": "249.99"}, {"price": "0.7", "size": "174"}, {"price": "0.66", "size": "50"}, {"price": "0.4", "size": "25"}, {"price": "0.3", "size": "225"}, {"price": "0.27", "size": "17.8"}, {"price": "0.26", "size": "24.86"}, {"price": "0.25", "size": "431"}, {"price": "0.19", "size": "69"}], "event_type": "book", "last_trade_price": "0.120"}, {"market": "0x5e075035583f3bf066377b92593a81ee9b40c72886cd590571c953d957ec63fe", "asset_id": "21309049201619161652065746140831735441976940779482114925077511349923500792596", "timestamp": "1769384013272", "hash": "b42b4bf3507fc3e1f6b43058c153f710bcbdb1ed", "bids": [{"price": "0.01", "size": "17043.4"}, {"price": "0.02", "size": "5007.85"}, {"price": "0.03", "size": "6016"}, {"price": "0.06", "size": "3000"}, {"price": "0.07", "size": "1142"}, {"price": "0.1", "size": "21"}, {"price": "0.15", "size": "900"}, {"price": "0.16", "size": "2624"}, {"price": "0.17", "size": "250"}, {"price": "0.26", "size": "225"}, {"price": "0.35", "size": "37.14"}, {"price": "0.36", "size": "30.55"}, {"price": "0.51", "size": "50.7"}, {"price": "0.52", "size": "80"}, {"price": "0.53", "size": "472"}, {"price": "0.54", "size": "50.78"}], "asks": [{"price": "0.99", "size": "62037.95"}, {"price": "0.98", "size": "5008.07"}, {"price": "0.97", "size": "17266"}, {"price": "0.94", "size": "9440"}, {"price": "0.9", "size": "5900"}, {"price": "0.89", "size": "4181"}, {"price": "0.85", "size": "2650"}, {"price": "0.84", "size": "250"}, {"price": "0.75", "size": "225"}, {"price": "0.65", "size": "37.14"}, {"price": "0.64", "size": "30.55"}, {"price": "0.63", "size": "6.99"}, {"price": "0.62", "size": "10"}, {"price": "0.58", "size": "70"}, {"price": "0.57", "size": "204.83"}, {"price": "0.56", "size": "1410.01"}], "event_type": "book", "last_trade_price": "0.460"}, {"market": "0xe220ab18b19107b4a06b18a0b5e2a9e9ab4cd7cb297c27cfa05a3369815a1579", "asset_id": "29294180043579351070208019085320546351829489739790080999397489613464945007446", "timestamp": "1769383980824", "hash": "b77bf594a96a57184fac0cbacab8468ac9510275", "bids": [{"price": "0.01", "size": "12038.4"}, {"price": "0.02", "size": "5007.85"}, {"price": "0.03", "size": "4016"}, {"price": "0.05", "size": "20"}, {"price": "0.06", "size": "2033"}, {"price": "0.07", "size": "1642"}, {"price": "0.15", "size": "900"}, {"price": "0.17", "size": "235"}, {"price": "0.2", "size": "950"}, {"price": "0.21", "size": "25"}, {"price": "0.27", "size": "50"}, {"price": "0.34", "size": "50"}, {"price": "0.47", "size": "225"}, {"price": "0.48", "size": "8.5"}, {"price": "0.54", "size": "24.07"}, {"price": "0.56", "size": "29.64"}, {"price": "0.67", "size": "37.58"}, {"price": "0.68", "size": "162.39"}], "asks": [{"price": "0.99", "size": "10035.79"}, {"price": "0.98", "size": "2008.98"}, {"price": "0.97", "size": "16"}, {"price": "0.96", "size": "133"}, {"price": "0.91", "size": "225"}, {"price": "0.89", "size": "30"}, {"price": "0.87", "size": "100"}, {"price": "0.84", "size": "68.75"}, {"price": "0.83", "size": "62"}, {"price": "0.82", "size": "8.5"}, {"price": "0.77", "size": "37.58"}], "event_type": "book", "last_trade_price": "0.700"}, {"market": "0xc5c870d2ca29e41ac55e1fac0c7b3c1140eb58fdf26fd2a77284caa9aca1b3aa", "asset_id": "83029595771494657564747548834030842590595300298406079594487838617400032504038", "timestamp": "1769384011886", "hash": "ae7602bba6433d98e0c9490cce2c04266faa4e85", "bids": [{"price": "0.001", "size": "3175.56"}, {"price": "0.002", "size": "1260.5"}, {"price": "0.003", "size": "1000"}, {"price": "0.004", "size": "18.01"}, {"price": "0.01", "size": "17030"}, {"price": "0.011", "size": "12.49"}, {"price": "0.02", "size": "5025"}, {"price": "0.03", "size": "4000"}, {"price": "0.05", "size": "20"}, {"price": "0.051", "size": "39"}, {"price": "0.06", "size": "2000"}, {"price": "0.111", "size": "2900"}, {"price": "0.115", "size": "17"}, {"price": "0.2", "size": "50"}, {"price": "0.27", "size": "50"}, {"price": "0.34", "size": "50"}, {"price": "0.85", "size": "225"}, {"price": "0.851", "size": "94.36"}, {"price": "0.955", "size": "46.02"}], "asks": [{"price": "0.999", "size": "2454.99"}, {"price": "0.998", "size": "50255.5"}, {"price": "0.997", "size": "10.86"}, {"price": "0.994", "size": "83"}, {"price": "0.993", "size": "47.1"}, {"price": "0.991", "size": "36.55"}, {"price": "0.99", "size": "30"}, {"price": "0.989", "size": "13.06"}, {"price": "0.97", "size": "20.1"}, {"price": "0.957", "size": "46.35"}], "event_type": "book", "last_trade_price": "0.043"}]}
{"_local_timestamp": "2026-01-25T23:33:35.335866+00:00", "data": {"market": "0x7bc1d3c8aaf0a20c853f576519446e1ee260e65d43205efd61696f3a9f9e62e7", "price_changes": [{"asset_id": "10966407605514195233392457845926539733586231163297093857244655359507639639996", "price": "0.006", "size": "0", "side": "BUY", "hash": "caa5c859c64b0eb8b278c61df2983a1dee6e50b5", "best_bid": "0.005", "best_ask": "0.086"}, {"asset_id": "74853086974054252708530367393532530785660539289108031053683362073748574770022", "price": "0.994", "size": "0", "side": "SELL", "hash": "90fb6018f27fd6a9f2346bebdd54e525639a6255", "best_bid": "0.914", "best_ask": "0.995"}], "timestamp": "1769384015171", "event_type": "price_change"}}
{"_local_timestamp": "2026-01-25T23:33:35.341450+00:00", "data": {"market": "0x7bc1d3c8aaf0a20c853f576519446e1ee260e65d43205efd61696f3a9f9e62e7", "price_changes": [{"asset_id": "10966407605514195233392457845926539733586231163297093857244655359507639639996", "price": "0.006", "size": "251", "side": "BUY", "hash": "49a812b7fa8bdb75791646a7a72b8e9f2a855f5b", "best_bid": "0.006", "best_ask": "0.086"}, {"asset_id": "74853086974054252708530367393532530785660539289108031053683362073748574770022", "price": "0.994", "size": "251", "side": "SELL", "hash": "7c47c8d14c503f5e8550822c8f039b4a080eb102", "best_bid": "0.914", "best_ask": "0.994"}], "timestamp": "1769384015203", "event_type": "price_change"}}
{"_local_timestamp": "2026-01-25T23:33:35.421602+00:00", "data": {"market": "0x9a991a29bbb2bb8118237815223c4b906328b7e8a373aa97fdae409a025470dc", "price_changes": [{"asset_id": "108210708594024455543283956523953124001017416937788990111411478336430517420393", "price": "0.79", "size": "150", "side": "SELL", "hash": "4491cfb845ddfe8e3e5db2efe2f8c43d27ac2961", "best_bid": "0.1", "best_ask": "0.19"}, {"asset_id": "68257431892288883729500648109357161057886471290823106810192273382603520923445", "price": "0.21", "size": "150", "side": "BUY", "hash": "8dcee4c0e8f35a3ab64868372f698deac1b09927", "best_bid": "0.81", "best_ask": "0.9"}], "timestamp": "1769384015348", "event_type": "price_change"}}
{"_local_timestamp": "2026-01-25T23:33:35.638031+00:00", "data": {"market": "0x9a991a29bbb2bb8118237815223c4b906328b7e8a373aa97fdae409a025470dc", "price_changes": [{"asset_id": "68257431892288883729500648109357161057886471290823106810192273382603520923445", "price": "0.21", "size": "50", "side": "BUY", "hash": "ec8a569757b0d8fcf355a6d31e4d4f44cba42736", "best_bid": "0.81", "best_ask": "0.9"}, {"asset_id": "108210708594024455543283956523953124001017416937788990111411478336430517420393", "price": "0.79", "size": "50", "side": "SELL", "hash": "6f97b46201297467ac56ee75efef8fb343942f94", "best_bid": "0.1", "best_ask": "0.19"}], "timestamp": "1769384015567", "event_type": "price_change"}}
{"_local_timestamp": "2026-01-25T23:33:35.790649+00:00", "data": {"market": "0x9a991a29bbb2bb8118237815223c4b906328b7e8a373aa97fdae409a025470dc", "price_changes": [{"asset_id": "108210708594024455543283956523953124001017416937788990111411478336430517420393", "price": "0.78", "size": "99.99", "side": "SELL", "hash": "9d8e55c68a251151968e0847a78da9be92e4172a", "best_bid": "0.1", "best_ask": "0.19"}, {"asset_id": "68257431892288883729500648109357161057886471290823106810192273382603520923445", "price": "0.22", "size": "99.99", "side": "BUY", "hash": "d8e26526e3b4cad1a15382e6554049da1e6092fe", "best_bid": "0.81", "best_ask": "0.9"}], "timestamp": "1769384015724", "event_type": "price_change"}}
{"_local_timestamp": "2026-01-25T23:33:36.403843+00:00", "data": {"market": "0x9a991a29bbb2bb8118237815223c4b906328b7e8a373aa97fdae409a025470dc", "price_changes": [{"asset_id": "68257431892288883729500648109357161057886471290823106810192273382603520923445", "price": "0.22", "size": "199.99", "side": "BUY", "hash": "da3a94c93d589b3fdf04f11898465aade75ffc99", "best_bid": "0.81", "best_ask": "0.9"}, {"asset_id": "108210708594024455543283956523953124001017416937788990111411478336430517420393", "price": "0.78", "size": "199.99", "side": "SELL", "hash": "31d0da71de09e2af7db44c7fb481ebcb123051e1", "best_bid": "0.1", "best_ask": "0.19"}], "timestamp": "1769384016338", "event_type": "price_change"}}
{"_local_timestamp": "2026-01-25T23:33:36.739494+00:00", "data": {"market": "0x7bc1d3c8aaf0a20c853f576519446e1ee260e65d43205efd61696f3a9f9e62e7", "price_changes": [{"asset_id": "10966407605514195233392457845926539733586231163297093857244655359507639639996", "price": "0.006", "size": "0", "side": "BUY", "hash": "1c632a2a5bc617bbcb582f8b90795f17b32b7224", "best_bid": "0.005", "best_ask": "0.086"}, {"asset_id": "74853086974054252708530367393532530785660539289108031053683362073748574770022", "price": "0.994", "size": "0", "side": "SELL", "hash": "c63b03cd7f0425a402ba98a4aab534743a9c7469", "best_bid": "0.914", "best_ask": "0.995"}], "timestamp": "1769384016671", "event_type": "price_change"}}
{"_local_timestamp": "2026-01-25T23:33:36.771554+00:00", "data": {"market": "0x7bc1d3c8aaf0a20c853f576519446e1ee260e65d43205efd61696f3a9f9e62e7", "price_changes": [{"asset_id": "10966407605514195233392457845926539733586231163297093857244655359507639639996", "price": "0.006", "size": "251", "side": "BUY", "hash": "d6c0ed66bbd754f4ed21efb52e312ae8fff92a98", "best_bid": "0.006", "best_ask": "0.086"}, {"asset_id": "74853086974054252708530367393532530785660539289108031053683362073748574770022", "price": "0.994", "size": "251", "side": "SELL", "hash": "2f678b4ea61ecca5d93325264ec93f04e2868331", "best_bid": "0.914", "best_ask": "0.994"}], "timestamp": "1769384016702", "event_type": "price_change"}}
{"_local_timestamp": "2026-01-25T23:33:37.099157+00:00", "data": {"market": "0x680784812145063cecedfa7f000654e89317e2aca612182884d7742ac6f801f9", "price_changes": [{"asset_id": "60410997855954556286106048831701517763027421942281960711866162404690269293947", "price": "0.78", "size": "1032.64", "side": "BUY", "hash": "72fd55c658728617b2022fafcc935c46a9a80052", "best_bid": "0.78", "best_ask": "0.81"}, {"asset_id": "76179285001548801832051437870901871012966717962774017789970710364900180173602", "price": "0.22", "size": "1032.64", "side": "SELL", "hash": "65634b8794340157deaffb74b972aa2f656cf850", "best_bid": "0.19", "best_ask": "0.22"}], "timestamp": "1769384017028", "event_type": "price_change"}}
{"_local_timestamp": "2026-01-25T23:33:37.593392+00:00", "data": {"market": "0xe9b3144e4d27aaef1f0821d70460d6d3260d79895e9968ccd2dc55a0dbdf6088", "price_changes": [{"asset_id": "83041154468219618230051081276875453907060636113065729539423582864425510953850", "price": "0.957", "size": "75.19", "side": "BUY", "hash": "f28278a4f1ea853d2903c5bfc7f06bd005dd4518", "best_bid": "0.957", "best_ask": "0.99"}, {"asset_id": "32376553431351473284586567513108813920800512906624908199970979285958436186934", "price": "0.043", "size": "75.19", "side": "SELL", "hash": "5e6e64e8dcaf62a1fa716095dae87c9e7978b3a0", "best_bid": "0.01", "best_ask": "0.043"}], "timestamp": "1769384017528", "event_type": "price_change"}}
{"_local_timestamp": "2026-01-25T23:33:37.668726+00:00", "data": {"market": "0xe9b3144e4d27aaef1f0821d70460d6d3260d79895e9968ccd2dc55a0dbdf6088", "price_changes": [{"asset_id": "83041154468219618230051081276875453907060636113065729539423582864425510953850", "price": "0.99", "size": "213.3", "side": "SELL", "hash": "625c75cdc5e148903ce069918e99b666a99cd2ee", "best_bid": "0.957", "best_ask": "0.99"}, {"asset_id": "32376553431351473284586567513108813920800512906624908199970979285958436186934", "price": "0.01", "size": "213.3", "side": "BUY", "hash": "b13686d8945ca144ab305aeff9e193af358d493c", "best_bid": "0.01", "best_ask": "0.043"}], "timestamp": "1769384017601", "event_type": "price_change"}}
{"_local_timestamp": "2026-01-25T23:33:37.849447+00:00", "data": {"market": "0xe220ab18b19107b4a06b18a0b5e2a9e9ab4cd7cb297c27cfa05a3369815a1579", "price_changes": [{"asset_id": "29294180043579351070208019085320546351829489739790080999397489613464945007446", "price": "0.68", "size": "227.72", "side": "BUY", "hash": "8988284247254b63925c5ccd704b592e4b29ce8e", "best_bid": "0.68", "best_ask": "0.77"}, {"asset_id": "43938988181832985104138029041174463994072038957372562854085197368645176157001", "price": "0.32", "size": "227.72", "side": "SELL", "hash": "01b7e522574016ba292601976e6c615b7164aabc", "best_bid": "0.23", "best_ask": "0.32"}], "timestamp": "1769384017781", "event_type": "price_change"}}
{"_local_timestamp": "2026-01-25T23:33:38.181748+00:00", "data": {"market": "0x34c320af835b2d4b56224618b9930e3a6b26ed7f6854c4f8ce04b35f6d3ee801", "price_changes": [{"asset_id": "21965236637806877423690456379421697078490533519739537235259143695240300903846", "price": "0.148", "size": "68.02", "side": "SELL", "hash": "20bd5c9b935ee2546bb072c7db531f70943090da", "best_bid": "0.097", "best_ask": "0.147"}, {"asset_id": "31278264626330879886341915760798723117251320102541744661396613642093503516942", "price": "0.852", "size": "68.02", "side": "BUY", "hash": "d2246ee36f4c33b7f3eee4aa5e6ed4c24f60a82b", "best_bid": "0.853", "best_ask": "0.903"}], "timestamp": "1769384018104", "event_type": "price_change"}}
{"_local_timestamp": "2026-01-25T23:33:38.251276+00:00", "data": {"market": "0x7bc1d3c8aaf0a20c853f576519446e1ee260e65d43205efd61696f3a9f9e62e7", "price_changes": [{"asset_id": "10966407605514195233392457845926539733586231163297093857244655359507639639996", "price": "0.006", "size": "0", "side": "BUY", "hash": "229a17daec7dd570096dae5ada49c8cf2ee83600", "best_bid": "0.005", "best_ask": "0.086"}, {"asset_id": "74853086974054252708530367393532530785660539289108031053683362073748574770022", "price": "0.994", "size": "0", "side": "SELL", "hash": "2762d6f0c5b531009543e4c037f94814d7d08f32", "best_bid": "0.914", "best_ask": "0.995"}], "timestamp": "1769384018182", "event_type": "price_change"}}
{"_local_timestamp": "2026-01-25T23:33:38.302688+00:00", "data": {"market": "0x7bc1d3c8aaf0a20c853f576519446e1ee260e65d43205efd61696f3a9f9e62e7", "price_changes": [{"asset_id": "10966407605514195233392457845926539733586231163297093857244655359507639639996", "price": "0.006", "size": "251", "side": "BUY", "hash": "777bd7d2dc87cf373311ddada905fd03de3b7a4b", "best_bid": "0.006", "best_ask": "0.086"}, {"asset_id": "74853086974054252708530367393532530785660539289108031053683362073748574770022", "price": "0.994", "size": "251", "side": "SELL", "hash": "d32f37c378d637a45fb29cd063654376252c6f8e", "best_bid": "0.914", "best_ask": "0.994"}], "timestamp": "1769384018214", "event_type": "price_change"}}
{"_local_timestamp": "2026-01-25T23:33:38.489339+00:00", "data": {"market": "0xcba2e5c2ae0c304be0b0bda9766ea909d3200c485e9d177397bc3da9e6fa84fa", "price_changes": [{"asset_id": "18326549491448085673538041550737399122005663684871535659338787725758240014500", "price": "0.966", "size": "60.12", "side": "BUY", "hash": "a0b1c84bc0cd067ca6b3210fb56f8edf5bc9b228", "best_bid": "0.966", "best_ask": "0.997"}, {"asset_id": "58928745853810789409871848444700893878861272591834748654309903811018704088285", "price": "0.034", "size": "60.12", "side": "SELL", "hash": "2a1ffbb3b47cdf20de62f5e4f95a4fc982f15125", "best_bid": "0.003", "best_ask": "0.034"}], "timestamp": "1769384018420", "event_type": "price_change"}}
{"_local_timestamp": "2026-01-25T23:33:38.821477+00:00", "data": {"market": "0x680784812145063cecedfa7f000654e89317e2aca612182884d7742ac6f801f9", "price_changes": [{"asset_id": "60410997855954556286106048831701517763027421942281960711866162404690269293947", "price": "0.14", "size": "400", "side": "BUY", "hash": "e825fb21b57cd6500274abd1a9e9cd991e15a892", "best_bid": "0.78", "best_ask": "0.81"}, {"asset_id": "76179285001548801832051437870901871012966717962774017789970710364900180173602", "price": "0.86", "size": "400", "side": "SELL", "hash": "3a5292e5cf0c166cef7c9269164b2a58fa337566", "best_bid": "0.19", "best_ask": "0.22"}], "timestamp": "1769384018754", "event_type": "price_change"}}
{"_local_timestamp": "2026-01-25T23:33:38.822644+00:00", "data": {"market": "0x7bc1d3c8aaf0a20c853f576519446e1ee260e65d43205efd61696f3a9f9e62e7", "price_changes": [{"asset_id": "74853086974054252708530367393532530785660539289108031053683362073748574770022", "price": "0.013", "size": "0", "side": "BUY", "hash": "70c817f940a65b5324a94bbbccc28051ede85f51", "best_bid": "0.914", "best_ask": "0.994"}, {"asset_id": "10966407605514195233392457845926539733586231163297093857244655359507639639996", "price": "0.987", "size": "0", "side": "SELL", "hash": "2023521847b5efc4f55c76be269c121876f15086", "best_bid": "0.006", "best_ask": "0.086"}], "timestamp": "1769384018754", "event_type": "price_change"}}
{"_local_timestamp": "2026-01-25T23:33:38.849603+00:00", "data": {"market": "0xc5c870d2ca29e41ac55e1fac0c7b3c1140eb58fdf26fd2a77284caa9aca1b3aa", "price_changes": [{"asset_id": "106940491396743186324486767673070552626952698856095995665708923002375094057739", "price": "0.149", "size": "74.36", "side": "SELL", "hash": "07eba9f5e678994be5b7ca56203ad0110318c9b0", "best_bid": "0.043", "best_ask": "0.045"}, {"asset_id": "83029595771494657564747548834030842590595300298406079594487838617400032504038", "price": "0.851", "size": "74.36", "side": "BUY", "hash": "d97527cd7eb475ea40567bfcc978b9e0fe1f17eb", "best_bid": "0.955", "best_ask": "0.957"}], "timestamp": "1769384018774", "event_type": "price_change"}}
{"_local_timestamp": "2026-01-25T23:33:39.050309+00:00", "data": {"market": "0x7bc1d3c8aaf0a20c853f576519446e1ee260e65d43205efd61696f3a9f9e62e7", "price_changes": [{"asset_id": "74853086974054252708530367393532530785660539289108031053683362073748574770022", "price": "0.914", "size": "63.07", "side": "BUY", "hash": "c5deef85b18e556541cf28357f9522ffdb91e5f2", "best_bid": "0.914", "best_ask": "0.994"}, {"asset_id": "10966407605514195233392457845926539733586231163297093857244655359507639639996", "price": "0.086", "size": "63.07", "side": "SELL", "hash": "8577d66514434096a3fe51631c84e4a14de4ae2c", "best_bid": "0.006", "best_ask": "0.086"}], "timestamp": "1769384018983", "event_type": "price_change"}}
{"_local_timestamp": "2026-01-25T23:33:39.099275+00:00", "data": {"market": "0x680784812145063cecedfa7f000654e89317e2aca612182884d7742ac6f801f9", "price_changes": [{"asset_id": "60410997855954556286106048831701517763027421942281960711866162404690269293947", "price": "0.15", "size": "3298", "side": "BUY", "hash": "52272eb8e40c7337ed9779d0e9bde66f16723215", "best_bid": "0.78", "best_ask": "0.81"}, {"asset_id": "76179285001548801832051437870901871012966717962774017789970710364900180173602", "price": "0.85", "size": "3298", "side": "SELL", "hash": "94f2ca2ecda38fdf75e90d39de67a74862dc98f1", "best_bid": "0.19", "best_ask": "0.22"}], "timestamp": "1769384019012", "event_type": "price_change"}}
{"_local_timestamp": "2026-01-25T23:33:39.151471+00:00", "data": {"market": "0xc5c870d2ca29e41ac55e1fac0c7b3c1140eb58fdf26fd2a77284caa9aca1b3aa", "price_changes": [{"asset_id": "106940491396743186324486767673070552626952698856095995665708923002375094057739", "price": "0.148", "size": "20", "side": "SELL", "hash": "34a3dd04920fe7e92b237c0f502334065b3d8070", "best_bid": "0.043", "best_ask": "0.045"}, {"asset_id": "83029595771494657564747548834030842590595300298406079594487838617400032504038", "price": "0.852", "size": "20", "side": "BUY", "hash": "9ef190b2460de886a20d93e38b52fe24ee99b37a", "best_bid": "0.955", "best_ask": "0.957"}], "timestamp": "1769384019070", "event_type": "price_change"}}
{"_local_timestamp": "2026-01-25T23:33:39.584167+00:00", "data": {"market": "0xcba2e5c2ae0c304be0b0bda9766ea909d3200c485e9d177397bc3da9e6fa84fa", "price_changes": [{"asset_id": "58928745853810789409871848444700893878861272591834748654309903811018704088285", "price": "0.034", "size": "45.12", "side": "SELL", "hash": "24680e23a1c6034e21498833a486a49594e0a222", "best_bid": "0.003", "best_ask": "0.034"}, {"asset_id": "18326549491448085673538041550737399122005663684871535659338787725758240014500", "price": "0.966", "size": "45.12", "side": "BUY", "hash": "f02d0b543a2e301adcc648e46e087dd860019776", "best_bid": "0.966", "best_ask": "0.997"}], "timestamp": "1769384019517", "event_type": "price_change"}}
{"_local_timestamp": "2026-01-25T23:33:39.758181+00:00", "data": {"market": "0x7bc1d3c8aaf0a20c853f576519446e1ee260e65d43205efd61696f3a9f9e62e7", "price_changes": [{"asset_id": "10966407605514195233392457845926539733586231163297093857244655359507639639996", "price": "0.006", "size": "0", "side": "BUY", "hash": "990d1076f72095f0572eb4742cdb75179b78dd78", "best_bid": "0.005", "best_ask": "0.086"}, {"asset_id": "74853086974054252708530367393532530785660539289108031053683362073748574770022", "price": "0.994", "size": "0", "side": "SELL", "hash": "9af960b438f15ecf1f13351dadd9f1d5581171c5", "best_bid": "0.914", "best_ask": "0.995"}], "timestamp": "1769384019680", "event_type": "price_change"}}
{"_local_timestamp": "2026-01-25T23:33:39.999250+00:00", "data": {"market": "0xcba2e5c2ae0c304be0b0bda9766ea909d3200c485e9d177397bc3da9e6fa84fa", "price_changes": [{"asset_id": "58928745853810789409871848444700893878861272591834748654309903811018704088285", "price": "0.033", "size": "15", "side": "SELL", "hash": "7faa74005586c61a6b89293476bab0e8c154c503", "best_bid": "0.003", "best_ask": "0.033"}, {"asset_id": "18326549491448085673538041550737399122005663684871535659338787725758240014500", "price": "0.967", "size": "15", "side": "BUY", "hash": "6cfbd1c64f979290e6978951ee52c25aa683139f", "best_bid": "0.967", "best_ask": "0.997"}], "timestamp": "1769384019931", "event_type": "price_change"}}
{"_local_timestamp": "2026-01-25T23:33:40.880284+00:00", "data": {"market": "0xe9b3144e4d27aaef1f0821d70460d6d3260d79895e9968ccd2dc55a0dbdf6088", "price_changes": [{"asset_id": "32376553431351473284586567513108813920800512906624908199970979285958436186934", "price": "0.01", "size": "252.68", "side": "BUY", "hash": "aba1469bb11672a555b5e0f67b73357dd862ce17", "best_bid": "0.01", "best_ask": "0.043"}, {"asset_id": "83041154468219618230051081276875453907060636113065729539423582864425510953850", "price": "0.99", "size": "252.68", "side": "SELL", "hash": "5c93757b074477056aa961b7331f757f4b031d19", "best_bid": "0.957", "best_ask": "0.99"}], "timestamp": "1769384020656", "event_type": "price_change"}}
{"_local_timestamp": "2026-01-25T23:33:43.217757+00:00", "data": {"market": "0x7bc1d3c8aaf0a20c853f576519446e1ee260e65d43205efd61696f3a9f9e62e7", "price_changes": [{"asset_id": "10966407605514195233392457845926539733586231163297093857244655359507639639996", "price": "0.087", "size": "0", "side": "SELL", "hash": "e6fddee091f37c3b004fdab730a7bfeb1731c82c", "best_bid": "0.005", "best_ask": "0.086"}, {"asset_id": "74853086974054252708530367393532530785660539289108031053683362073748574770022", "price": "0.913", "size": "0", "side": "BUY", "hash": "5e36e4608197429e6e12d9da996b15686c7efde5", "best_bid": "0.914", "best_ask": "0.995"}], "timestamp": "1769384023151", "event_type": "price_change"}}
{"_local_timestamp": "2026-01-25T23:33:43.250073+00:00", "data": {"market": "0x7bc1d3c8aaf0a20c853f576519446e1ee260e65d43205efd61696f3a9f9e62e7", "price_changes": [{"asset_id": "74853086974054252708530367393532530785660539289108031053683362073748574770022", "price": "0.169", "size": "953", "side": "BUY", "hash": "ba2bbb05062e35128b2b12fceec269e562feb811", "best_bid": "0.914", "best_ask": "0.995"}, {"asset_id": "10966407605514195233392457845926539733586231163297093857244655359507639639996", "price": "0.831", "size": "953", "side": "SELL", "hash": "bb5b55582c43e09cef23d24224b5bfdc408ca042", "best_bid": "0.005", "best_ask": "0.086"}], "timestamp": "1769384023182", "event_type": "price_change"}}
{"_local_timestamp": "2026-01-25T23:33:43.449134+00:00", "data": {"market": "0xe220ab18b19107b4a06b18a0b5e2a9e9ab4cd7cb297c27cfa05a3369815a1579", "price_changes": [{"asset_id": "29294180043579351070208019085320546351829489739790080999397489613464945007446", "price": "0.21", "size": "2023", "side": "BUY", "hash": "fa4bc58e65c31b25d9c0175c29f4579606f7c437", "best_bid": "0.68", "best_ask": "0.77"}, {"asset_id": "43938988181832985104138029041174463994072038957372562854085197368645176157001", "price": "0.79", "size": "2023", "side": "SELL", "hash": "57fab4746856db5b8115ab71a2154d8f83479a8c", "best_bid": "0.23", "best_ask": "0.32"}], "timestamp": "1769384023386", "event_type": "price_change"}}
{"_local_timestamp": "2026-01-25T23:33:43.861609+00:00", "data": {"market": "0x9a991a29bbb2bb8118237815223c4b906328b7e8a373aa97fdae409a025470dc", "price_changes": [{"asset_id": "68257431892288883729500648109357161057886471290823106810192273382603520923445", "price": "0.81", "size": "122.66", "side": "BUY", "hash": "0477313f47f93f90c055e432e23cf6989ae788e2", "best_bid": "0.81", "best_ask": "0.9"}, {"asset_id": "108210708594024455543283956523953124001017416937788990111411478336430517420393", "price": "0.19", "size": "122.66", "side": "SELL", "hash": "54f4bb84c4a4ddfb16d2372996df75e518764e29", "best_bid": "0.1", "best_ask": "0.19"}], "timestamp": "1769384023763", "event_type": "price_change"}}
{"_local_timestamp": "2026-01-25T23:33:44.130304+00:00", "data": {"market": "0x9a991a29bbb2bb8118237815223c4b906328b7e8a373aa97fdae409a025470dc", "price_changes": [{"asset_id": "68257431892288883729500648109357161057886471290823106810192273382603520923445", "price": "0.22", "size": "2107.99", "side": "BUY", "hash": "10b64c6ce29b71098f15383269162313234a8b6d", "best_bid": "0.81", "best_ask": "0.9"}, {"asset_id": "108210708594024455543283956523953124001017416937788990111411478336430517420393", "price": "0.78", "size": "2107.99", "side": "SELL", "hash": "dd49505011a089a82a16b5dc9cf20becd60bf29b", "best_bid": "0.1", "best_ask": "0.19"}], "timestamp": "1769384024053", "event_type": "price_change"}}
{"_local_timestamp": "2026-01-25T23:33:44.411384+00:00", "data": {"market": "0x9a991a29bbb2bb8118237815223c4b906328b7e8a373aa97fdae409a025470dc", "price_changes": [{"asset_id": "68257431892288883729500648109357161057886471290823106810192273382603520923445", "price": "0.22", "size": "2007.99", "side": "BUY", "hash": "f2a890d43b3f1f2ef8f93bde351fcc4954900ba6", "best_bid": "0.81", "best_ask": "0.9"}, {"asset_id": "108210708594024455543283956523953124001017416937788990111411478336430517420393", "price": "0.78", "size": "2007.99", "side": "SELL", "hash": "61a56da0c863b0de3f8489b458805197a482fdd6", "best_bid": "0.1", "best_ask": "0.19"}], "timestamp": "1769384024341", "event_type": "price_change"}}
{"_local_timestamp": "2026-01-25T23:33:44.980030+00:00", "data": {"market": "0x34c320af835b2d4b56224618b9930e3a6b26ed7f6854c4f8ce04b35f6d3ee801", "price_changes": [{"asset_id": "21965236637806877423690456379421697078490533519739537235259143695240300903846", "price": "0.148", "size": "115.31", "side": "SELL", "hash": "a5a70ecc5a88d6636420dd8b7d67a6b93514aafd", "best_bid": "0.097", "best_ask": "0.147"}, {"asset_id": "31278264626330879886341915760798723117251320102541744661396613642093503516942", "price": "0.852", "size": "115.31", "side": "BUY", "hash": "67ffb9c2e6c037ca7182b08d8f80207db4c34cad", "best_bid": "0.853", "best_ask": "0.903"}], "timestamp": "1769384024913", "event_type": "price_change"}}
{"_local_timestamp": "2026-01-25T23:33:45.009027+00:00", "data": {"market": "0x9a991a29bbb2bb8118237815223c4b906328b7e8a373aa97fdae409a025470dc", "price_changes": [{"asset_id": "68257431892288883729500648109357161057886471290823106810192273382603520923445", "price": "0.23", "size": "100", "side": "BUY", "hash": "b1264c2bdffc970837d05c44bee239fb879fad6b", "best_bid": "0.81", "best_ask": "0.9"}, {"asset_id": "108210708594024455543283956523953124001017416937788990111411478336430517420393", "price": "0.77", "size": "100", "side": "SELL", "hash": "45e7e422e31243c4a5f6956dea3f4b4e0d1db76e", "best_bid": "0.1", "best_ask": "0.19"}], "timestamp": "1769384024946", "event_type": "price_change"}}
{"_local_timestamp": "2026-01-25T23:33:48.148369+00:00", "data": {"market": "0x34c320af835b2d4b56224618b9930e3a6b26ed7f6854c4f8ce04b35f6d3ee801", "price_changes": [{"asset_id": "31278264626330879886341915760798723117251320102541744661396613642093503516942", "price": "0.853", "size": "82.48", "side": "BUY", "hash": "5d6488b180c77a98ab4ee8c4412051f86982c74d", "best_bid": "0.853", "best_ask": "0.903"}, {"asset_id": "21965236637806877423690456379421697078490533519739537235259143695240300903846", "price": "0.147", "size": "82.48", "side": "SELL", "hash": "3961c8d290e08f6789ac882bb41cb9474f73f4df", "best_bid": "0.097", "best_ask": "0.147"}], "timestamp": "1769384028069", "event_type": "price_change"}}
{"_local_timestamp": "2026-01-25T23:33:48.149287+00:00", "data": {"market": "0x680784812145063cecedfa7f000654e89317e2aca612182884d7742ac6f801f9", "price_changes": [{"asset_id": "60410997855954556286106048831701517763027421942281960711866162404690269293947", "price": "0.14", "size": "0", "side": "BUY", "hash": "5ba0917a172291f3e7f9f02e96cd6ff48235868b", "best_bid": "0.78", "best_ask": "0.81"}, {"asset_id": "76179285001548801832051437870901871012966717962774017789970710364900180173602", "price": "0.86", "size": "0", "side": "SELL", "hash": "a1a983ac936cdaade64161406ec30ab860e1fc41", "best_bid": "0.19", "best_ask": "0.22"}], "timestamp": "1769384028078", "event_type": "price_change"}}
{"_local_timestamp": "2026-01-25T23:33:48.340416+00:00", "data": {"market": "0x9a991a29bbb2bb8118237815223c4b906328b7e8a373aa97fdae409a025470dc", "price_changes": [{"asset_id": "108210708594024455543283956523953124001017416937788990111411478336430517420393", "price": "0.78", "size": "1908", "side": "SELL", "hash": "cd3ab8148289f7a48721d876883721555e180fe0", "best_bid": "0.1", "best_ask": "0.19"}, {"asset_id": "68257431892288883729500648109357161057886471290823106810192273382603520923445", "price": "0.22", "size": "1908", "side": "BUY", "hash": "df25fb7ded6257a8750b5b399220abc21a2440df", "best_bid": "0.81", "best_ask": "0.9"}], "timestamp": "1769384028259", "event_type": "price_change"}}
{"_local_timestamp": "2026-01-25T23:33:48.436062+00:00", "data": {"market": "0x680784812145063cecedfa7f000654e89317e2aca612182884d7742ac6f801f9", "price_changes": [{"asset_id": "60410997855954556286106048831701517763027421942281960711866162404690269293947", "price": "0.15", "size": "3698", "side": "BUY", "hash": "9302e896056c7dfad954c63445d330b67a789544", "best_bid": "0.78", "best_ask": "0.81"}, {"asset_id": "76179285001548801832051437870901871012966717962774017789970710364900180173602", "price": "0.85", "size": "3698", "side": "SELL", "hash": "060a8a7218ab3731aaaece07aa4c1e43361bc96a", "best_bid": "0.19", "best_ask": "0.22"}], "timestamp": "1769384028362", "event_type": "price_change"}}
{"_local_timestamp": "2026-01-25T23:33:48.705186+00:00", "data": {"market": "0x9a991a29bbb2bb8118237815223c4b906328b7e8a373aa97fdae409a025470dc", "price_changes": [{"asset_id": "108210708594024455543283956523953124001017416937788990111411478336430517420393", "price": "0.77", "size": "199.99", "side": "SELL", "hash": "f7e58a4cbd19ab03f7d596713b18915062573e81", "best_bid": "0.1", "best_ask": "0.19"}, {"asset_id": "68257431892288883729500648109357161057886471290823106810192273382603520923445", "price": "0.23", "size": "199.99", "side": "BUY", "hash": "1408ca00e5046785156f17ef6d09178e2dab551d", "best_bid": "0.81", "best_ask": "0.9"}], "timestamp": "1769384028641", "event_type": "price_change"}}
{"_local_timestamp": "2026-01-25T23:33:52.623011+00:00", "data": {"market": "0xe220ab18b19107b4a06b18a0b5e2a9e9ab4cd7cb297c27cfa05a3369815a1579", "price_changes": [{"asset_id": "29294180043579351070208019085320546351829489739790080999397489613464945007446", "price": "0.2", "size": "450", "side": "BUY", "hash": "24b29a61ad5ab4b5ea63171ba23015efa86dc65f", "best_bid": "0.68", "best_ask": "0.77"}, {"asset_id": "43938988181832985104138029041174463994072038957372562854085197368645176157001", "price": "0.8", "size": "450", "side": "SELL", "hash": "defc9f6378a9fa474f9b93e94244c862bf8b192b", "best_bid": "0.23", "best_ask": "0.32"}], "timestamp": "1769384032541", "event_type": "price_change"}}
{"_local_timestamp": "2026-01-25T23:33:52.882281+00:00", "data": {"market": "0x7bc1d3c8aaf0a20c853f576519446e1ee260e65d43205efd61696f3a9f9e62e7", "price_changes": [{"asset_id": "74853086974054252708530367393532530785660539289108031053683362073748574770022", "price": "0.013", "size": "2000", "side": "BUY", "hash": "426109bcffc61719f6789216417f12a9108c2e91", "best_bid": "0.914", "best_ask": "0.995"}, {"asset_id": "10966407605514195233392457845926539733586231163297093857244655359507639639996", "price": "0.987", "size": "2000", "side": "SELL", "hash": "a25b759c56b03f589fba9aa792d1a46142aa4574", "best_bid": "0.005", "best_ask": "0.086"}], "timestamp": "1769384032809", "event_type": "price_change"}}
{"_local_timestamp": "2026-01-25T23:33:53.479174+00:00", "data": {"market": "0x7bc1d3c8aaf0a20c853f576519446e1ee260e65d43205efd61696f3a9f9e62e7", "price_changes": [{"asset_id": "10966407605514195233392457845926539733586231163297093857244655359507639639996", "price": "0.085", "size": "25", "side": "SELL", "hash": "69cdabf2cf2ee99216ff22802e446f91775a0b01", "best_bid": "0.005", "best_ask": "0.085"}, {"asset_id": "74853086974054252708530367393532530785660539289108031053683362073748574770022", "price": "0.915", "size": "25", "side": "BUY", "hash": "c06dfedbc95f1ccaa03bc006a86d51854abad87e", "best_bid": "0.915", "best_ask": "0.995"}], "timestamp": "1769384033413", "event_type": "price_change"}}
{"_local_timestamp": "2026-01-25T23:33:53.505924+00:00", "data": {"market": "0x7bc1d3c8aaf0a20c853f576519446e1ee260e65d43205efd61696f3a9f9e62e7", "price_changes": [{"asset_id": "74853086974054252708530367393532530785660539289108031053683362073748574770022", "price": "0.169", "size": "0", "side": "BUY", "hash": "a833790c9a58070e8b05c2f33c3614f59773264e", "best_bid": "0.915", "best_ask": "0.995"}, {"asset_id": "10966407605514195233392457845926539733586231163297093857244655359507639639996", "price": "0.831", "size": "0", "side": "SELL", "hash": "7f085793e6092f5c92290715d22ea6ce44ce26d0", "best_bid": "0.005", "best_ask": "0.085"}], "timestamp": "1769384033441", "event_type": "price_change"}}
{"_local_timestamp": "2026-01-25T23:33:54.449451+00:00", "data": {"market": "0x7bc1d3c8aaf0a20c853f576519446e1ee260e65d43205efd61696f3a9f9e62e7", "price_changes": [{"asset_id": "10966407605514195233392457845926539733586231163297093857244655359507639639996", "price": "0.086", "size": "48.32", "side": "SELL", "hash": "fcbd6a5d54895718a9eb9b17ad289325d89253bd", "best_bid": "0.005", "best_ask": "0.085"}, {"asset_id": "74853086974054252708530367393532530785660539289108031053683362073748574770022", "price": "0.914", "size": "48.32", "side": "BUY", "hash": "3294b6042e6eda40220d74131b2a39d15675d8b5", "best_bid": "0.915", "best_ask": "0.995"}], "timestamp": "1769384034375", "event_type": "price_change"}}
{"_local_timestamp": "2026-01-25T23:33:55.273594+00:00", "data": {"market": "0x7bc1d3c8aaf0a20c853f576519446e1ee260e65d43205efd61696f3a9f9e62e7", "price_changes": [{"asset_id": "10966407605514195233392457845926539733586231163297093857244655359507639639996", "price": "0.084", "size": "14.75", "side": "SELL", "hash": "e1951c7443aa6908b18599d1011f2b11c55fabbe", "best_bid": "0.005", "best_ask": "0.084"}, {"asset_id": "74853086974054252708530367393532530785660539289108031053683362073748574770022", "price": "0.916", "size": "14.75", "side": "BUY", "hash": "0ca11e318f7173f8309651d6cc68e43a1f8bd002", "best_bid": "0.916", "best_ask": "0.995"}], "timestamp": "1769384035182", "event_type": "price_change"}}
{"_local_timestamp": "2026-01-25T23:33:55.276129+00:00", "data": {"market": "0x7bc1d3c8aaf0a20c853f576519446e1ee260e65d43205efd61696f3a9f9e62e7", "price_changes": [{"asset_id": "10966407605514195233392457845926539733586231163297093857244655359507639639996", "price": "0.006", "size": "251", "side": "BUY", "hash": "6abe715f6d7eaaf9f692b9f22f81f9ffc7ac046d", "best_bid": "0.006", "best_ask": "0.084"}, {"asset_id": "74853086974054252708530367393532530785660539289108031053683362073748574770022", "price": "0.994", "size": "251", "side": "SELL", "hash": "d5bcc03c34051b2426c08554ad6e3daf411ce6db", "best_bid": "0.916", "best_ask": "0.994"}], "timestamp": "1769384035187", "event_type": "price_change"}}
{"_local_timestamp": "2026-01-25T23:33:56.743636+00:00", "data": {"market": "0x7bc1d3c8aaf0a20c853f576519446e1ee260e65d43205efd61696f3a9f9e62e7", "price_changes": [{"asset_id": "10966407605514195233392457845926539733586231163297093857244655359507639639996", "price": "0.006", "size": "0", "side": "BUY", "hash": "567859e875e21df0f590120e0f206aca0d40c8d2", "best_bid": "0.005", "best_ask": "0.084"}, {"asset_id": "74853086974054252708530367393532530785660539289108031053683362073748574770022", "price": "0.994", "size": "0", "side": "SELL", "hash": "8ca613a86dea0ba3bc62a47c41b4eb6f48a71f4b", "best_bid": "0.916", "best_ask": "0.995"}], "timestamp": "1769384036673", "event_type": "price_change"}}
{"_local_timestamp": "2026-01-25T23:33:56.773218+00:00", "data": {"market": "0x7bc1d3c8aaf0a20c853f576519446e1ee260e65d43205efd61696f3a9f9e62e7", "price_changes": [{"asset_id": "10966407605514195233392457845926539733586231163297093857244655359507639639996", "price": "0.006", "size": "251", "side": "BUY", "hash": "b63c31f72331fb429c2c5fb3525957eb7ce28394", "best_bid": "0.006", "best_ask": "0.084"}, {"asset_id": "74853086974054252708530367393532530785660539289108031053683362073748574770022", "price": "0.994", "size": "251", "side": "SELL", "hash": "e0e2ae2e2716b85caca9740f90fdc46f77cca903", "best_bid": "0.916", "best_ask": "0.994"}], "timestamp": "1769384036706", "event_type": "price_change"}}
{"_local_timestamp": "2026-01-25T23:33:58.239349+00:00", "data": {"market": "0x7bc1d3c8aaf0a20c853f576519446e1ee260e65d43205efd61696f3a9f9e62e7", "price_changes": [{"asset_id": "10966407605514195233392457845926539733586231163297093857244655359507639639996", "price": "0.006", "size": "0", "side": "BUY", "hash": "852cc1d376cd9cb830645a884d39bc5fa364c9da", "best_bid": "0.005", "best_ask": "0.084"}, {"asset_id": "74853086974054252708530367393532530785660539289108031053683362073748574770022", "price": "0.994", "size": "0", "side": "SELL", "hash": "e4ffb2ceac8f1c0b6d081ece835404de4b327671", "best_bid": "0.916", "best_ask": "0.995"}], "timestamp": "1769384038171", "event_type": "price_change"}}
{"_local_timestamp": "2026-01-25T23:33:58.290332+00:00", "data": {"market": "0x7bc1d3c8aaf0a20c853f576519446e1ee260e65d43205efd61696f3a9f9e62e7", "price_changes": [{"asset_id": "10966407605514195233392457845926539733586231163297093857244655359507639639996", "price": "0.006", "size": "251", "side": "BUY", "hash": "5c322d7d488d04839227be6699b4d025a8db9cd1", "best_bid": "0.006", "best_ask": "0.084"}, {"asset_id": "74853086974054252708530367393532530785660539289108031053683362073748574770022", "price": "0.994", "size": "251", "side": "SELL", "hash": "905a9c2cfd72f63fb31b59466a4db70ad8965e9a", "best_bid": "0.916", "best_ask": "0.994"}], "timestamp": "1769384038210", "event_type": "price_change"}}
{"_local_timestamp": "2026-01-25T23:33:58.291061+00:00", "data": {"market": "0x680784812145063cecedfa7f000654e89317e2aca612182884d7742ac6f801f9", "price_changes": [{"asset_id": "60410997855954556286106048831701517763027421942281960711866162404690269293947", "price": "0.03", "size": "9750", "side": "BUY", "hash": "05d192db40f9da4ceb848636d80dc4024597a670", "best_bid": "0.78", "best_ask": "0.81"}, {"asset_id": "76179285001548801832051437870901871012966717962774017789970710364900180173602", "price": "0.97", "size": "9750", "side": "SELL", "hash": "c83750df7c0cd8531b0322da65bc95f3dfd7228a", "best_bid": "0.19", "best_ask": "0.22"}], "timestamp": "1769384038225", "event_type": "price_change"}}
{"_local_timestamp": "2026-01-25T23:33:58.297553+00:00", "data": {"market": "0x680784812145063cecedfa7f000654e89317e2aca612182884d7742ac6f801f9", "price_changes": [{"asset_id": "60410997855954556286106048831701517763027421942281960711866162404690269293947", "price": "0.08", "size": "1500", "side": "BUY", "hash": "849b8c6168d46833ce4d1aae1cca5cf5664319c0", "best_bid": "0.78", "best_ask": "0.81"}, {"asset_id": "76179285001548801832051437870901871012966717962774017789970710364900180173602", "price": "0.92", "size": "1500", "side": "SELL", "hash": "bd6989e4265ce44d811fb1ddd9cd024b7393da1b", "best_bid": "0.19", "best_ask": "0.22"}], "timestamp": "1769384038227", "event_type": "price_change"}}
{"_local_timestamp": "2026-01-25T23:33:58.298154+00:00", "data": {"market": "0x680784812145063cecedfa7f000654e89317e2aca612182884d7742ac6f801f9", "price_changes": [{"asset_id": "60410997855954556286106048831701517763027421942281960711866162404690269293947", "price": "0.06", "size": "4140", "side": "BUY", "hash": "af83561cff7dd7c1ea36b1ec831bc96121056509", "best_bid": "0.78", "best_ask": "0.81"}, {"asset_id": "76179285001548801832051437870901871012966717962774017789970710364900180173602", "price": "0.94", "size": "4140", "side": "SELL", "hash": "a54dd4c205d06b2ed54d9a331bfcae558f460fe4", "best_bid": "0.19", "best_ask": "0.22"}], "timestamp": "1769384038228", "event_type": "price_change"}}
{"_local_timestamp": "2026-01-25T23:33:58.298748+00:00", "data": {"market": "0x680784812145063cecedfa7f000654e89317e2aca612182884d7742ac6f801f9", "price_changes": [{"asset_id": "60410997855954556286106048831701517763027421942281960711866162404690269293947", "price": "0.15", "size": "4448", "side": "BUY", "hash": "70e818cef4fd71925e1b374f0e769dd8f5f7c264", "best_bid": "0.78", "best_ask": "0.81"}, {"asset_id": "76179285001548801832051437870901871012966717962774017789970710364900180173602", "price": "0.85", "size": "4448", "side": "SELL", "hash": "c8bf939daf751f6cf86f5b223b75341a0dc7ec5f", "best_bid": "0.19", "best_ask": "0.22"}], "timestamp": "1769384038228", "event_type": "price_change"}}
{"_local_timestamp": "2026-01-25T23:33:58.299163+00:00", "data": {"market": "0x680784812145063cecedfa7f000654e89317e2aca612182884d7742ac6f801f9", "price_changes": [{"asset_id": "60410997855954556286106048831701517763027421942281960711866162404690269293947", "price": "0.01", "size": "32123.4", "side": "BUY", "hash": "ae2d34d94d19eb89f597f9a4778514fa52ddbaeb", "best_bid": "0.78", "best_ask": "0.81"}, {"asset_id": "76179285001548801832051437870901871012966717962774017789970710364900180173602", "price": "0.99", "size": "32123.4", "side": "SELL", "hash": "902d9d21dd03b5ca0c3411a00d4bfd4494c8f509", "best_bid": "0.19", "best_ask": "0.22"}], "timestamp": "1769384038229", "event_type": "price_change"}}
{"_local_timestamp": "2026-01-25T23:33:59.744620+00:00", "data": {"market": "0x7bc1d3c8aaf0a20c853f576519446e1ee260e65d43205efd61696f3a9f9e62e7", "price_changes": [{"asset_id": "10966407605514195233392457845926539733586231163297093857244655359507639639996", "price": "0.006", "size": "0", "side": "BUY", "hash": "ef0e86356112c44687a4345837928be53986d596", "best_bid": "0.005", "best_ask": "0.084"}, {"asset_id": "74853086974054252708530367393532530785660539289108031053683362073748574770022", "price": "0.994", "size": "0", "side": "SELL", "hash": "a27ca72251e1616c2a15a1ef3569ba43ad8bd1e3", "best_bid": "0.916", "best_ask": "0.995"}], "timestamp": "1769384039671", "event_type": "price_change"}}
{"_local_timestamp": "2026-01-25T23:33:59.772008+00:00", "data": {"market": "0x7bc1d3c8aaf0a20c853f576519446e1ee260e65d43205efd61696f3a9f9e62e7", "price_changes": [{"asset_id": "10966407605514195233392457845926539733586231163297093857244655359507639639996", "price": "0.006", "size": "251", "side": "BUY", "hash": "06a28bae0f04708fe204dae580ba6c7ddae71588", "best_bid": "0.006", "best_ask": "0.084"}, {"asset_id": "74853086974054252708530367393532530785660539289108031053683362073748574770022", "price": "0.994", "size": "251", "side": "SELL", "hash": "147fcd96ec8d8199c8d584fb8ba8bac880fb3a0f", "best_bid": "0.916", "best_ask": "0.994"}], "timestamp": "1769384039697", "event_type": "price_change"}}
{"_local_timestamp": "2026-01-25T23:34:01.238067+00:00", "data": {"market": "0x7bc1d3c8aaf0a20c853f576519446e1ee260e65d43205efd61696f3a9f9e62e7", "price_changes": [{"asset_id": "10966407605514195233392457845926539733586231163297093857244655359507639639996", "price": "0.006", "size": "0", "side": "BUY", "hash": "6a668e35f837c23fc3a5289fea071c939a3e7216", "best_bid": "0.005", "best_ask": "0.084"}, {"asset_id": "74853086974054252708530367393532530785660539289108031053683362073748574770022", "price": "0.994", "size": "0", "side": "SELL", "hash": "bcd901eeebb843f3206ab18c6926cdfe056bde12", "best_bid": "0.916", "best_ask": "0.995"}], "timestamp": "1769384041174", "event_type": "price_change"}}
{"_local_timestamp": "2026-01-25T23:34:01.273610+00:00", "data": {"market": "0x7bc1d3c8aaf0a20c853f576519446e1ee260e65d43205efd61696f3a9f9e62e7", "price_changes": [{"asset_id": "10966407605514195233392457845926539733586231163297093857244655359507639639996", "price": "0.006", "size": "251", "side": "BUY", "hash": "8642287c08f7bfc856ff65f04e275eddbdc2574c", "best_bid": "0.006", "best_ask": "0.084"}, {"asset_id": "74853086974054252708530367393532530785660539289108031053683362073748574770022", "price": "0.994", "size": "251", "side": "SELL", "hash": "9f81196544d32af9e62936b19ef26da4ea2b4718", "best_bid": "0.916", "best_ask": "0.994"}], "timestamp": "1769384041210", "event_type": "price_change"}}
{"_local_timestamp": "2026-01-25T23:34:02.816879+00:00", "data": {"market": "0x7bc1d3c8aaf0a20c853f576519446e1ee260e65d43205efd61696f3a9f9e62e7", "price_changes": [{"asset_id": "10966407605514195233392457845926539733586231163297093857244655359507639639996", "price": "0.006", "size": "0", "side": "BUY", "hash": "a47afc3a95e499ed97685ed5547cd88ade64d191", "best_bid": "0.005", "best_ask": "0.084"}, {"asset_id": "74853086974054252708530367393532530785660539289108031053683362073748574770022", "price": "0.994", "size": "0", "side": "SELL", "hash": "33021de0f2576eefdc86f6bedad99b94f54d55a8", "best_bid": "0.916", "best_ask": "0.995"}], "timestamp": "1769384042672", "event_type": "price_change"}}
{"_local_timestamp": "2026-01-25T23:34:02.850364+00:00", "data": {"market": "0x7bc1d3c8aaf0a20c853f576519446e1ee260e65d43205efd61696f3a9f9e62e7", "price_changes": [{"asset_id": "10966407605514195233392457845926539733586231163297093857244655359507639639996", "price": "0.006", "size": "251", "side": "BUY", "hash": "294076874085984b2d4fbb1af08efcc091833b61", "best_bid": "0.006", "best_ask": "0.084"}, {"asset_id": "74853086974054252708530367393532530785660539289108031053683362073748574770022", "price": "0.994", "size": "251", "side": "SELL", "hash": "f28c17450a78c4d93c12bc8b1a56d3552ed8e117", "best_bid": "0.916", "best_ask": "0.994"}], "timestamp": "1769384042698", "event_type": "price_change"}}
{"_local_timestamp": "2026-01-25T23:34:03.093487+00:00", "data": {"market": "0xe220ab18b19107b4a06b18a0b5e2a9e9ab4cd7cb297c27cfa05a3369815a1579", "price_changes": [{"asset_id": "29294180043579351070208019085320546351829489739790080999397489613464945007446", "price": "0.03", "size": "6016", "side": "BUY", "hash": "3f12ec39c0e0470c90b18b2c74439de74e8dad64", "best_bid": "0.68", "best_ask": "0.77"}, {"asset_id": "43938988181832985104138029041174463994072038957372562854085197368645176157001", "price": "0.97", "size": "6016", "side": "SELL", "hash": "f806b0586c0cca8a98f1f8db106299e73332eee5", "best_bid": "0.23", "best_ask": "0.32"}], "timestamp": "1769384042898", "event_type": "price_change"}}
{"_local_timestamp": "2026-01-25T23:34:03.096105+00:00", "data": {"market": "0x680784812145063cecedfa7f000654e89317e2aca612182884d7742ac6f801f9", "price_changes": [{"asset_id": "60410997855954556286106048831701517763027421942281960711866162404690269293947", "price": "0.06", "size": "5140", "side": "BUY", "hash": "292de6eef4230ed75639a19623b54a65e7e482b9", "best_bid": "0.78", "best_ask": "0.81"}, {"asset_id": "76179285001548801832051437870901871012966717962774017789970710364900180173602", "price": "0.94", "size": "5140", "side": "SELL", "hash": "d1bb29166ccea081594ccd900256900d53fdf685", "best_bid": "0.19", "best_ask": "0.22"}], "timestamp": "1769384042898", "event_type": "price_change"}}
{"_local_timestamp": "2026-01-25T23:34:03.096687+00:00", "data": {"market": "0xe220ab18b19107b4a06b18a0b5e2a9e9ab4cd7cb297c27cfa05a3369815a1579", "price_changes": [{"asset_id": "29294180043579351070208019085320546351829489739790080999397489613464945007446", "price": "0.07", "size": "2642", "side": "BUY", "hash": "6bb169e9404620fbbf7f7b57f831c8ce9d9cc7eb", "best_bid": "0.68", "best_ask": "0.77"}, {"asset_id": "43938988181832985104138029041174463994072038957372562854085197368645176157001", "price": "0.93", "size": "2642", "side": "SELL", "hash": "f849ceea6e6a5b3d5c3af74c1b58a0384f4b5b82", "best_bid": "0.23", "best_ask": "0.32"}], "timestamp": "1769384042898", "event_type": "price_change"}}
{"_local_timestamp": "2026-01-25T23:34:03.097117+00:00", "data": {"market": "0x680784812145063cecedfa7f000654e89317e2aca612182884d7742ac6f801f9", "price_changes": [{"asset_id": "60410997855954556286106048831701517763027421942281960711866162404690269293947", "price": "0.15", "size": "4848", "side": "BUY", "hash": "f5e5da59b27a980eec7ee7f5635c265308b5d9a0", "best_bid": "0.78", "best_ask": "0.81"}, {"asset_id": "76179285001548801832051437870901871012966717962774017789970710364900180173602", "price": "0.85", "size": "4848", "side": "SELL", "hash": "9979c6ce11cc135997c38821133ae87ed8a3059d", "best_bid": "0.19", "best_ask": "0.22"}], "timestamp": "1769384042898", "event_type": "price_change"}}
{"_local_timestamp": "2026-01-25T23:34:03.097591+00:00", "data": {"market": "0xe220ab18b19107b4a06b18a0b5e2a9e9ab4cd7cb297c27cfa05a3369815a1579", "price_changes": [{"asset_id": "29294180043579351070208019085320546351829489739790080999397489613464945007446", "price": "0.01", "size": "17038.4", "side": "BUY", "hash": "b3aaa52efce798b5fb65e0431c88eccef4af1e8a", "best_bid": "0.68", "best_ask": "0.77"}, {"asset_id": "43938988181832985104138029041174463994072038957372562854085197368645176157001", "price": "0.99", "size": "17038.4", "side": "SELL", "hash": "2210ab1023775b90453d031045a09dac2ff7adcd", "best_bid": "0.23", "best_ask": "0.32"}], "timestamp": "1769384042899", "event_type": "price_change"}}
{"_local_timestamp": "2026-01-25T23:34:03.761085+00:00", "data": {"market": "0x680784812145063cecedfa7f000654e89317e2aca612182884d7742ac6f801f9", "price_changes": [{"asset_id": "60410997855954556286106048831701517763027421942281960711866162404690269293947", "price": "0.15", "size": "6348", "side": "BUY", "hash": "0ca69014701c1951383dff11bf8ee0dfea10201b", "best_bid": "0.78", "best_ask": "0.81"}, {"asset_id": "76179285001548801832051437870901871012966717962774017789970710364900180173602", "price": "0.85", "size": "6348", "side": "SELL", "hash": "fbf9ad160f3c41525f898e367b740656e70298ba", "best_bid": "0.19", "best_ask": "0.22"}], "timestamp": "1769384043532", "event_type": "price_change"}}
{"_local_timestamp": "2026-01-25T23:34:03.761674+00:00", "data": {"market": "0x680784812145063cecedfa7f000654e89317e2aca612182884d7742ac6f801f9", "price_changes": [{"asset_id": "60410997855954556286106048831701517763027421942281960711866162404690269293947", "price": "0.06", "size": "9440", "side": "BUY", "hash": "252ec9124c8eec09f028949e8826210136509044", "best_bid": "0.78", "best_ask": "0.81"}, {"asset_id": "76179285001548801832051437870901871012966717962774017789970710364900180173602", "price": "0.94", "size": "9440", "side": "SELL", "hash": "2cb7d1ea2ec999f0c95f5ce692c178782eda8afe", "best_bid": "0.19", "best_ask": "0.22"}], "timestamp": "1769384043533", "event_type": "price_change"}}
{"_local_timestamp": "2026-01-25T23:34:03.762153+00:00", "data": {"market": "0x680784812145063cecedfa7f000654e89317e2aca612182884d7742ac6f801f9", "price_changes": [{"asset_id": "60410997855954556286106048831701517763027421942281960711866162404690269293947", "price": "0.01", "size": "62123.4", "side": "BUY", "hash": "b3b068f0108991d0dbdc02f6b9979b57a8bbf639", "best_bid": "0.78", "best_ask": "0.81"}, {"asset_id": "76179285001548801832051437870901871012966717962774017789970710364900180173602", "price": "0.99", "size": "62123.4", "side": "SELL", "hash": "b24c57003d3b0a8413bd5e4b83cfa5f99c774af1", "best_bid": "0.19", "best_ask": "0.22"}], "timestamp": "1769384043534", "event_type": "price_change"}}
{"_local_timestamp": "2026-01-25T23:34:03.762594+00:00", "data": {"market": "0x680784812145063cecedfa7f000654e89317e2aca612182884d7742ac6f801f9", "price_changes": [{"asset_id": "60410997855954556286106048831701517763027421942281960711866162404690269293947", "price": "0.03", "size": "17250", "side": "BUY", "hash": "723109840fd18d39e04b0f3e91669e9f8d4d1de9", "best_bid": "0.78", "best_ask": "0.81"}, {"asset_id": "76179285001548801832051437870901871012966717962774017789970710364900180173602", "price": "0.97", "size": "17250", "side": "SELL", "hash": "a5931798e0cece384c4e8c46cf0f6dde7183f4e4", "best_bid": "0.19", "best_ask": "0.22"}], "timestamp": "1769384043534", "event_type": "price_change"}}
{"_local_timestamp": "2026-01-25T23:34:03.763013+00:00", "data": {"market": "0x680784812145063cecedfa7f000654e89317e2aca612182884d7742ac6f801f9", "price_changes": [{"asset_id": "60410997855954556286106048831701517763027421942281960711866162404690269293947", "price": "0.08", "size": "4500", "side": "BUY", "hash": "0a33a680e393fb14399b0704fb9c53bdd9eb257e", "best_bid": "0.78", "best_ask": "0.81"}, {"asset_id": "76179285001548801832051437870901871012966717962774017789970710364900180173602", "price": "0.92", "size": "4500", "side": "SELL", "hash": "90ee83927b6c1b9422c10592b59925c3817d12f8", "best_bid": "0.19", "best_ask": "0.22"}], "timestamp": "1769384043535", "event_type": "price_change"}}
{"_local_timestamp": "2026-01-25T23:34:04.385025+00:00", "data": {"market": "0x7bc1d3c8aaf0a20c853f576519446e1ee260e65d43205efd61696f3a9f9e62e7", "price_changes": [{"asset_id": "10966407605514195233392457845926539733586231163297093857244655359507639639996", "price": "0.006", "size": "0", "side": "BUY", "hash": "d506dd7a7f4875d97228e10b380f700de623998e", "best_bid": "0.005", "best_ask": "0.084"}, {"asset_id": "74853086974054252708530367393532530785660539289108031053683362073748574770022", "price": "0.994", "size": "0", "side": "SELL", "hash": "a07ade48fc565d623a95d4fed01602aab9b6c071", "best_bid": "0.916", "best_ask": "0.995"}], "timestamp": "1769384044173", "event_type": "price_change"}}
{"_local_timestamp": "2026-01-25T23:34:04.408765+00:00", "data": {"market": "0x7bc1d3c8aaf0a20c853f576519446e1ee260e65d43205efd61696f3a9f9e62e7", "price_changes": [{"asset_id": "10966407605514195233392457845926539733586231163297093857244655359507639639996", "price": "0.006", "size": "251", "side": "BUY", "hash": "ed41bc8e3f2bc81ff6f254dc7638baf0dcf46330", "best_bid": "0.006", "best_ask": "0.084"}, {"asset_id": "74853086974054252708530367393532530785660539289108031053683362073748574770022", "price": "0.994", "size": "251", "side": "SELL", "hash": "240c5dc13eee9d5eb2d2d9376b0aa6cbe7655273", "best_bid": "0.916", "best_ask": "0.994"}], "timestamp": "1769384044201", "event_type": "price_change"}}
{"_local_timestamp": "2026-01-25T23:34:05.929983+00:00", "data": {"market": "0x7bc1d3c8aaf0a20c853f576519446e1ee260e65d43205efd61696f3a9f9e62e7", "price_changes": [{"asset_id": "10966407605514195233392457845926539733586231163297093857244655359507639639996", "price": "0.006", "size": "0", "side": "BUY", "hash": "d1ca2c7d96687c88495e90c39f0877b03f1fafd5", "best_bid": "0.005", "best_ask": "0.084"}, {"asset_id": "74853086974054252708530367393532530785660539289108031053683362073748574770022", "price": "0.994", "size": "0", "side": "SELL", "hash": "e60da53c76857b0a855d89a10b29b50301ad3a43", "best_bid": "0.916", "best_ask": "0.995"}], "timestamp": "1769384045672", "event_type": "price_change"}}
{"_local_timestamp": "2026-01-25T23:34:05.962334+00:00", "data": {"market": "0x7bc1d3c8aaf0a20c853f576519446e1ee260e65d43205efd61696f3a9f9e62e7", "price_changes": [{"asset_id": "10966407605514195233392457845926539733586231163297093857244655359507639639996", "price": "0.006", "size": "251", "side": "BUY", "hash": "7addeb9a364cdeb1c3f9f7b69753509ee00866d1", "best_bid": "0.006", "best_ask": "0.084"}, {"asset_id": "74853086974054252708530367393532530785660539289108031053683362073748574770022", "price": "0.994", "size": "251", "side": "SELL", "hash": "9a60624a8bd77044c1b61c00972c4983469ec7ef", "best_bid": "0.916", "best_ask": "0.994"}], "timestamp": "1769384045707", "event_type": "price_change"}}
{"_local_timestamp": "2026-01-25T23:34:07.315464+00:00", "data": {"market": "0xe220ab18b19107b4a06b18a0b5e2a9e9ab4cd7cb297c27cfa05a3369815a1579", "price_changes": [{"asset_id": "29294180043579351070208019085320546351829489739790080999397489613464945007446", "price": "0.2", "size": "50", "side": "BUY", "hash": "75eaa1b6d2abc8a47806009ed182b29348a2f10f", "best_bid": "0.68", "best_ask": "0.77"}, {"asset_id": "43938988181832985104138029041174463994072038957372562854085197368645176157001", "price": "0.8", "size": "50", "side": "SELL", "hash": "6f83a1838c2b439cbc6790f1bc8aa5349ffbfe46", "best_bid": "0.23", "best_ask": "0.32"}], "timestamp": "1769384047087", "event_type": "price_change"}}
{"_local_timestamp": "2026-01-25T23:34:07.397053+00:00", "data": {"market": "0x7bc1d3c8aaf0a20c853f576519446e1ee260e65d43205efd61696f3a9f9e62e7", "price_changes": [{"asset_id": "10966407605514195233392457845926539733586231163297093857244655359507639639996", "price": "0.006", "size": "0", "side": "BUY", "hash": "9202f04d632abd9bad94fe3e44b527f39e294ab8", "best_bid": "0.005", "best_ask": "0.084"}, {"asset_id": "74853086974054252708530367393532530785660539289108031053683362073748574770022", "price": "0.994", "size": "0", "side": "SELL", "hash": "58d2d8eb4399968085f7bf645a7ece18ec373c81", "best_bid": "0.916", "best_ask": "0.995"}], "timestamp": "1769384047170", "event_type": "price_change"}}
{"_local_timestamp": "2026-01-25T23:34:07.443353+00:00", "data": {"market": "0x7bc1d3c8aaf0a20c853f576519446e1ee260e65d43205efd61696f3a9f9e62e7", "price_changes": [{"asset_id": "10966407605514195233392457845926539733586231163297093857244655359507639639996", "price": "0.006", "size": "251", "side": "BUY", "hash": "3bc2c5e0dbc8054b6934432cf4329eab7a92274e", "best_bid": "0.006", "best_ask": "0.084"}, {"asset_id": "74853086974054252708530367393532530785660539289108031053683362073748574770022", "price": "0.994", "size": "251", "side": "SELL", "hash": "396aa13b5be6e1511b1a3fc70f349578084731f0", "best_bid": "0.916", "best_ask": "0.994"}], "timestamp": "1769384047203", "event_type": "price_change"}}
{"_local_timestamp": "2026-01-25T23:34:08.915337+00:00", "data": {"market": "0x7bc1d3c8aaf0a20c853f576519446e1ee260e65d43205efd61696f3a9f9e62e7", "price_changes": [{"asset_id": "10966407605514195233392457845926539733586231163297093857244655359507639639996", "price": "0.006", "size": "0", "side": "BUY", "hash": "39858454e7a045e992ab97da955f333d9a6a3ab7", "best_bid": "0.005", "best_ask": "0.084"}, {"asset_id": "74853086974054252708530367393532530785660539289108031053683362073748574770022", "price": "0.994", "size": "0", "side": "SELL", "hash": "bd3bea586cd5256732b068e2d238e903cd07e619", "best_bid": "0.916", "best_ask": "0.995"}], "timestamp": "1769384048673", "event_type": "price_change"}}
{"_local_timestamp": "2026-01-25T23:34:08.937293+00:00", "data": {"market": "0x7bc1d3c8aaf0a20c853f576519446e1ee260e65d43205efd61696f3a9f9e62e7", "price_changes": [{"asset_id": "10966407605514195233392457845926539733586231163297093857244655359507639639996", "price": "0.006", "size": "251", "side": "BUY", "hash": "f1f0d57976c88843a1ce48bfd83afd3d1b33ec09", "best_bid": "0.006", "best_ask": "0.084"}, {"asset_id": "74853086974054252708530367393532530785660539289108031053683362073748574770022", "price": "0.994", "size": "251", "side": "SELL", "hash": "86930c0d2631ac3edbda05ace6058a188f65fc33", "best_bid": "0.916", "best_ask": "0.994"}], "timestamp": "1769384048699", "event_type": "price_change"}}
{"_local_timestamp": "2026-01-25T23:34:10.373511+00:00", "data": {"market": "0x7bc1d3c8aaf0a20c853f576519446e1ee260e65d43205efd61696f3a9f9e62e7", "price_changes": [{"asset_id": "10966407605514195233392457845926539733586231163297093857244655359507639639996", "price": "0.006", "size": "0", "side": "BUY", "hash": "73c36b686261ee0e115578eaa0ce59acec0cfd6e", "best_bid": "0.005", "best_ask": "0.084"}, {"asset_id": "74853086974054252708530367393532530785660539289108031053683362073748574770022", "price": "0.994", "size": "0", "side": "SELL", "hash": "4591881c18b64c170067fdb10882943d3b1728dd", "best_bid": "0.916", "best_ask": "0.995"}], "timestamp": "1769384050170", "event_type": "price_change"}}
{"_local_timestamp": "2026-01-25T23:34:10.400619+00:00", "data": {"market": "0x7bc1d3c8aaf0a20c853f576519446e1ee260e65d43205efd61696f3a9f9e62e7", "price_changes": [{"asset_id": "10966407605514195233392457845926539733586231163297093857244655359507639639996", "price": "0.006", "size": "251", "side": "BUY", "hash": "4a74b53c14de854faa4facbcfdf1bea67a67a304", "best_bid": "0.006", "best_ask": "0.084"}, {"asset_id": "74853086974054252708530367393532530785660539289108031053683362073748574770022", "price": "0.994", "size": "251", "side": "SELL", "hash": "25a0231e8a790cea8d7444d230da7f0ab1a40dda", "best_bid": "0.916", "best_ask": "0.994"}], "timestamp": "1769384050195", "event_type": "price_change"}}
{"_local_timestamp": "2026-01-25T23:34:11.861276+00:00", "data": {"market": "0x7bc1d3c8aaf0a20c853f576519446e1ee260e65d43205efd61696f3a9f9e62e7", "price_changes": [{"asset_id": "10966407605514195233392457845926539733586231163297093857244655359507639639996", "price": "0.006", "size": "0", "side": "BUY", "hash": "5626b562a875a1b46d7eba9fdb0a2e4fb90b91ac", "best_bid": "0.005", "best_ask": "0.084"}, {"asset_id": "74853086974054252708530367393532530785660539289108031053683362073748574770022", "price": "0.994", "size": "0", "side": "SELL", "hash": "4057d8b04813ad56afc64852339d8690a41219c5", "best_bid": "0.916", "best_ask": "0.995"}], "timestamp": "1769384051671", "event_type": "price_change"}}
{"_local_timestamp": "2026-01-25T23:34:11.917681+00:00", "data": {"market": "0x7bc1d3c8aaf0a20c853f576519446e1ee260e65d43205efd61696f3a9f9e62e7", "price_changes": [{"asset_id": "10966407605514195233392457845926539733586231163297093857244655359507639639996", "price": "0.006", "size": "251", "side": "BUY", "hash": "117d1ea69cf339bdfa725c75d678ff07568069d5", "best_bid": "0.006", "best_ask": "0.084"}, {"asset_id": "74853086974054252708530367393532530785660539289108031053683362073748574770022", "price": "0.994", "size": "251", "side": "SELL", "hash": "650c19228d5756e8438b2618d3b7b381f48e5e61", "best_bid": "0.916", "best_ask": "0.994"}], "timestamp": "1769384051709", "event_type": "price_change"}}
{"_local_timestamp": "2026-01-25T23:34:13.395725+00:00", "data": {"market": "0x7bc1d3c8aaf0a20c853f576519446e1ee260e65d43205efd61696f3a9f9e62e7", "price_changes": [{"asset_id": "10966407605514195233392457845926539733586231163297093857244655359507639639996", "price": "0.006", "size": "0", "side": "BUY", "hash": "8458c082410fa4f69113a3266843682b4f52408c", "best_bid": "0.005", "best_ask": "0.084"}, {"asset_id": "74853086974054252708530367393532530785660539289108031053683362073748574770022", "price": "0.994", "size": "0", "side": "SELL", "hash": "69a4baa0f805c649a1423f35c51cfbcb59b57f95", "best_bid": "0.916", "best_ask": "0.995"}], "timestamp": "1769384053178", "event_type": "price_change"}}
{"_local_timestamp": "2026-01-25T23:34:13.431056+00:00", "data": {"market": "0x7bc1d3c8aaf0a20c853f576519446e1ee260e65d43205efd61696f3a9f9e62e7", "price_changes": [{"asset_id": "10966407605514195233392457845926539733586231163297093857244655359507639639996", "price": "0.006", "size": "251", "side": "BUY", "hash": "e62ea2d23b134fb8ff85afcc2cb4421941327701", "best_bid": "0.006", "best_ask": "0.084"}, {"asset_id": "74853086974054252708530367393532530785660539289108031053683362073748574770022", "price": "0.994", "size": "251", "side": "SELL", "hash": "ea255eb6cc74934b6972034cf9894f646329ab78", "best_bid": "0.916", "best_ask": "0.994"}], "timestamp": "1769384053208", "event_type": "price_change"}}
{"_local_timestamp": "2026-01-25T23:34:14.908377+00:00", "data": {"market": "0x7bc1d3c8aaf0a20c853f576519446e1ee260e65d43205efd61696f3a9f9e62e7", "price_changes": [{"asset_id": "10966407605514195233392457845926539733586231163297093857244655359507639639996", "price": "0.006", "size": "0", "side": "BUY", "hash": "9d5a7df75e3f1fe1ec1f730f5b1c525a6a3444cf", "best_bid": "0.005", "best_ask": "0.084"}, {"asset_id": "74853086974054252708530367393532530785660539289108031053683362073748574770022", "price": "0.994", "size": "0", "side": "SELL", "hash": "29588791002a3ebd7edba3276b27f59e31e4a95e", "best_bid": "0.916", "best_ask": "0.995"}], "timestamp": "1769384054674", "event_type": "price_change"}}
{"_local_timestamp": "2026-01-25T23:34:14.941871+00:00", "data": {"market": "0x7bc1d3c8aaf0a20c853f576519446e1ee260e65d43205efd61696f3a9f9e62e7", "price_changes": [{"asset_id": "10966407605514195233392457845926539733586231163297093857244655359507639639996", "price": "0.006", "size": "251", "side": "BUY", "hash": "1befc9b29480bd4a51c97eaee2c8e3b3894a7dc9", "best_bid": "0.006", "best_ask": "0.084"}, {"asset_id": "74853086974054252708530367393532530785660539289108031053683362073748574770022", "price": "0.994", "size": "251", "side": "SELL", "hash": "d753e230322ad9dc9470668fc0287a833f6e61bc", "best_bid": "0.916", "best_ask": "0.994"}], "timestamp": "1769384054704", "event_type": "price_change"}}
{"_local_timestamp": "2026-01-25T23:34:16.408952+00:00", "data": {"market": "0x7bc1d3c8aaf0a20c853f576519446e1ee260e65d43205efd61696f3a9f9e62e7", "price_changes": [{"asset_id": "10966407605514195233392457845926539733586231163297093857244655359507639639996", "price": "0.006", "size": "0", "side": "BUY", "hash": "a619bbb886dd1cbfc049a3bfe59c047067c3194b", "best_bid": "0.005", "best_ask": "0.084"}, {"asset_id": "74853086974054252708530367393532530785660539289108031053683362073748574770022", "price": "0.994", "size": "0", "side": "SELL", "hash": "9dd037087aa56105c0598d2393e13667e8456b5c", "best_bid": "0.916", "best_ask": "0.995"}], "timestamp": "1769384056176", "event_type": "price_change"}}
{"_local_timestamp": "2026-01-25T23:34:16.436767+00:00", "data": {"market": "0x7bc1d3c8aaf0a20c853f576519446e1ee260e65d43205efd61696f3a9f9e62e7", "price_changes": [{"asset_id": "10966407605514195233392457845926539733586231163297093857244655359507639639996", "price": "0.006", "size": "251", "side": "BUY", "hash": "49fdc993aeed2f36abe82f16f00850fdfafa779e", "best_bid": "0.006", "best_ask": "0.084"}, {"asset_id": "74853086974054252708530367393532530785660539289108031053683362073748574770022", "price": "0.994", "size": "251", "side": "SELL", "hash": "1acf9acdd4ea0673896928d9b62c175414ba2f28", "best_bid": "0.916", "best_ask": "0.994"}], "timestamp": "1769384056203", "event_type": "price_change"}}
{"_local_timestamp": "2026-01-25T23:34:17.911716+00:00", "data": {"market": "0x7bc1d3c8aaf0a20c853f576519446e1ee260e65d43205efd61696f3a9f9e62e7", "price_changes": [{"asset_id": "10966407605514195233392457845926539733586231163297093857244655359507639639996", "price": "0.006", "size": "0", "side": "BUY", "hash": "e365ed46c4d32758275ab197ca29914001816243", "best_bid": "0.005", "best_ask": "0.084"}, {"asset_id": "74853086974054252708530367393532530785660539289108031053683362073748574770022", "price": "0.994", "size": "0", "side": "SELL", "hash": "a505f5bfb1fb6cb6861a2d903aa3fa162626c46e", "best_bid": "0.916", "best_ask": "0.995"}], "timestamp": "1769384057672", "event_type": "price_change"}}
{"_local_timestamp": "2026-01-25T23:34:17.939636+00:00", "data": {"market": "0x7bc1d3c8aaf0a20c853f576519446e1ee260e65d43205efd61696f3a9f9e62e7", "price_changes": [{"asset_id": "10966407605514195233392457845926539733586231163297093857244655359507639639996", "price": "0.006", "size": "251", "side": "BUY", "hash": "785783a053958f8a54255131c13ae54b842a9e4a", "best_bid": "0.006", "best_ask": "0.084"}, {"asset_id": "74853086974054252708530367393532530785660539289108031053683362073748574770022", "price": "0.994", "size": "251", "side": "SELL", "hash": "c41c1adfc3ce9a34d00f35334fff9801a766ae3b", "best_bid": "0.916", "best_ask": "0.994"}], "timestamp": "1769384057701", "event_type": "price_change"}}
{"_local_timestamp": "2026-01-25T23:34:19.408313+00:00", "data": {"market": "0x7bc1d3c8aaf0a20c853f576519446e1ee260e65d43205efd61696f3a9f9e62e7", "price_changes": [{"asset_id": "10966407605514195233392457845926539733586231163297093857244655359507639639996", "price": "0.006", "size": "0", "side": "BUY", "hash": "8cf8002bd225a6e5349b0b2bb287e6f202842a29", "best_bid": "0.005", "best_ask": "0.084"}, {"asset_id": "74853086974054252708530367393532530785660539289108031053683362073748574770022", "price": "0.994", "size": "0", "side": "SELL", "hash": "24d9431e1f87d7f763b3e6677db6808eb715fbfc", "best_bid": "0.916", "best_ask": "0.995"}], "timestamp": "1769384059171", "event_type": "price_change"}}
{"_local_timestamp": "2026-01-25T23:34:19.418785+00:00", "data": {"market": "0x7bc1d3c8aaf0a20c853f576519446e1ee260e65d43205efd61696f3a9f9e62e7", "price_changes": [{"asset_id": "10966407605514195233392457845926539733586231163297093857244655359507639639996", "price": "0.006", "size": "251", "side": "BUY", "hash": "0c34722dd0f250b901fd5a1bbf11073fabc3b750", "best_bid": "0.006", "best_ask": "0.084"}, {"asset_id": "74853086974054252708530367393532530785660539289108031053683362073748574770022", "price": "0.994", "size": "251", "side": "SELL", "hash": "dff4c683c423fcfd47243de2246e3ac7df70c2b9", "best_bid": "0.916", "best_ask": "0.994"}], "timestamp": "1769384059201", "event_type": "price_change"}}
{"_local_timestamp": "2026-01-25T23:34:20.009612+00:00", "data": {"market": "0xe220ab18b19107b4a06b18a0b5e2a9e9ab4cd7cb297c27cfa05a3369815a1579", "price_changes": [{"asset_id": "29294180043579351070208019085320546351829489739790080999397489613464945007446", "price": "0.21", "size": "25", "side": "BUY", "hash": "bd9793ca986d270f05206c5690ad55350a8069de", "best_bid": "0.68", "best_ask": "0.77"}, {"asset_id": "43938988181832985104138029041174463994072038957372562854085197368645176157001", "price": "0.79", "size": "25", "side": "SELL", "hash": "a81b80e86d714e5960ab92f301507dff76969e0b", "best_bid": "0.23", "best_ask": "0.32"}], "timestamp": "1769384059754", "event_type": "price_change"}}
{"_local_timestamp": "2026-01-25T23:34:20.015894+00:00", "data": {"market": "0x9a991a29bbb2bb8118237815223c4b906328b7e8a373aa97fdae409a025470dc", "price_changes": [{"asset_id": "68257431892288883729500648109357161057886471290823106810192273382603520923445", "price": "0.22", "size": "0", "side": "BUY", "hash": "f412600ec6358cbbea5071b6bf218281aa339546", "best_bid": "0.81", "best_ask": "0.9"}, {"asset_id": "108210708594024455543283956523953124001017416937788990111411478336430517420393", "price": "0.78", "size": "0", "side": "SELL", "hash": "02af5f9c024615fdee776df76ae8d704a9fbfe16", "best_bid": "0.1", "best_ask": "0.19"}], "timestamp": "1769384059758", "event_type": "price_change"}}
{"_local_timestamp": "2026-01-25T23:34:20.017646+00:00", "data": {"market": "0x680784812145063cecedfa7f000654e89317e2aca612182884d7742ac6f801f9", "price_changes": [{"asset_id": "60410997855954556286106048831701517763027421942281960711866162404690269293947", "price": "0.15", "size": "3550", "side": "BUY", "hash": "f5804c6c20dcdd31655ab877329f67485427f26b", "best_bid": "0.78", "best_ask": "0.81"}, {"asset_id": "76179285001548801832051437870901871012966717962774017789970710364900180173602", "price": "0.85", "size": "3550", "side": "SELL", "hash": "396cfcff031c3fe1972bb2c2aebfe01374009fd5", "best_bid": "0.19", "best_ask": "0.22"}], "timestamp": "1769384059758", "event_type": "price_change"}}
{"_local_timestamp": "2026-01-25T23:34:20.916341+00:00", "data": {"market": "0x7bc1d3c8aaf0a20c853f576519446e1ee260e65d43205efd61696f3a9f9e62e7", "price_changes": [{"asset_id": "10966407605514195233392457845926539733586231163297093857244655359507639639996", "price": "0.006", "size": "0", "side": "BUY", "hash": "fe9e8dc47c4be5f2cb5ac39597a3b1d1a505b3ec", "best_bid": "0.005", "best_ask": "0.084"}, {"asset_id": "74853086974054252708530367393532530785660539289108031053683362073748574770022", "price": "0.994", "size": "0", "side": "SELL", "hash": "cfce07a5d7ac0b40e8ad24e5e298e3f9e8fe3bca", "best_bid": "0.916", "best_ask": "0.995"}], "timestamp": "1769384060680", "event_type": "price_change"}}
{"_local_timestamp": "2026-01-25T23:34:20.944883+00:00", "data": {"market": "0x7bc1d3c8aaf0a20c853f576519446e1ee260e65d43205efd61696f3a9f9e62e7", "price_changes": [{"asset_id": "10966407605514195233392457845926539733586231163297093857244655359507639639996", "price": "0.006", "size": "251", "side": "BUY", "hash": "940882bb77aca556fd80c973dc375ba52d695900", "best_bid": "0.006", "best_ask": "0.084"}, {"asset_id": "74853086974054252708530367393532530785660539289108031053683362073748574770022", "price": "0.994", "size": "251", "side": "SELL", "hash": "4314b00f725bece69f7ea937f20085cc39c4866c", "best_bid": "0.916", "best_ask": "0.994"}], "timestamp": "1769384060707", "event_type": "price_change"}}
{"_local_timestamp": "2026-01-25T23:34:22.379097+00:00", "data": {"market": "0x7bc1d3c8aaf0a20c853f576519446e1ee260e65d43205efd61696f3a9f9e62e7", "price_changes": [{"asset_id": "10966407605514195233392457845926539733586231163297093857244655359507639639996", "price": "0.006", "size": "0", "side": "BUY", "hash": "3bc20382a444e9f4283c64441068509573d9d23f", "best_bid": "0.005", "best_ask": "0.084"}, {"asset_id": "74853086974054252708530367393532530785660539289108031053683362073748574770022", "price": "0.994", "size": "0", "side": "SELL", "hash": "8711dd8d28ea4f96ba4389b19a911b7aa8edcc29", "best_bid": "0.916", "best_ask": "0.995"}], "timestamp": "1769384062171", "event_type": "price_change"}}
{"_local_timestamp": "2026-01-25T23:34:22.455562+00:00", "data": {"market": "0x7bc1d3c8aaf0a20c853f576519446e1ee260e65d43205efd61696f3a9f9e62e7", "price_changes": [{"asset_id": "10966407605514195233392457845926539733586231163297093857244655359507639639996", "price": "0.006", "size": "251", "side": "BUY", "hash": "091ab6d1321d99d6713f3b9522d1f3c90f7f8042", "best_bid": "0.006", "best_ask": "0.084"}, {"asset_id": "74853086974054252708530367393532530785660539289108031053683362073748574770022", "price": "0.994", "size": "251", "side": "SELL", "hash": "9e5adeded0b36869242a5261c04bada1f7340f5a", "best_bid": "0.916", "best_ask": "0.994"}], "timestamp": "1769384062198", "event_type": "price_change"}}
{"_local_timestamp": "2026-01-25T23:34:22.456232+00:00", "data": {"market": "0x34c320af835b2d4b56224618b9930e3a6b26ed7f6854c4f8ce04b35f6d3ee801", "price_changes": [{"asset_id": "21965236637806877423690456379421697078490533519739537235259143695240300903846", "price": "0.002", "size": "25", "side": "BUY", "hash": "5c8dda1ebc511ca05a610928edcef06bad1c1931", "best_bid": "0.097", "best_ask": "0.147"}, {"asset_id": "31278264626330879886341915760798723117251320102541744661396613642093503516942", "price": "0.998", "size": "25", "side": "SELL", "hash": "db740aa2bc737389b8ffac2f5398362f240b00dd", "best_bid": "0.853", "best_ask": "0.903"}], "timestamp": "1769384062223", "event_type": "price_change"}}
{"_local_timestamp": "2026-01-25T23:34:22.719399+00:00", "data": {"market": "0x34c320af835b2d4b56224618b9930e3a6b26ed7f6854c4f8ce04b35f6d3ee801", "price_changes": [{"asset_id": "21965236637806877423690456379421697078490533519739537235259143695240300903846", "price": "0.002", "size": "62.52", "side": "BUY", "hash": "47db817472e3e01f7e19eaef84230cfd15927846", "best_bid": "0.097", "best_ask": "0.147"}, {"asset_id": "31278264626330879886341915760798723117251320102541744661396613642093503516942", "price": "0.998", "size": "62.52", "side": "SELL", "hash": "2deb97d3922d137cf84a5cf71f9b471c3d3af235", "best_bid": "0.853", "best_ask": "0.903"}], "timestamp": "1769384062491", "event_type": "price_change"}}
{"_local_timestamp": "2026-01-25T23:34:23.895410+00:00", "data": {"market": "0x7bc1d3c8aaf0a20c853f576519446e1ee260e65d43205efd61696f3a9f9e62e7", "price_changes": [{"asset_id": "10966407605514195233392457845926539733586231163297093857244655359507639639996", "price": "0.006", "size": "0", "side": "BUY", "hash": "c2cf4cf341b45e381a6e72740770e84ff74522b4", "best_bid": "0.005", "best_ask": "0.084"}, {"asset_id": "74853086974054252708530367393532530785660539289108031053683362073748574770022", "price": "0.994", "size": "0", "side": "SELL", "hash": "b644355760b1b329109ad7fd1413ef5c2437b7ba", "best_bid": "0.916", "best_ask": "0.995"}], "timestamp": "1769384063675", "event_type": "price_change"}}
{"_local_timestamp": "2026-01-25T23:34:23.921133+00:00", "data": {"market": "0x7bc1d3c8aaf0a20c853f576519446e1ee260e65d43205efd61696f3a9f9e62e7", "price_changes": [{"asset_id": "10966407605514195233392457845926539733586231163297093857244655359507639639996", "price": "0.006", "size": "251", "side": "BUY", "hash": "3e567a6362383b954cc24a8994d5c1e84260ef23", "best_bid": "0.006", "best_ask": "0.084"}, {"asset_id": "74853086974054252708530367393532530785660539289108031053683362073748574770022", "price": "0.994", "size": "251", "side": "SELL", "hash": "1450a46400ba3191d83cf3c6c5a3e3c119d329d5", "best_bid": "0.916", "best_ask": "0.994"}], "timestamp": "1769384063702", "event_type": "price_change"}}
{"_local_timestamp": "2026-01-25T23:34:24.255415+00:00", "data": {"market": "0x9a991a29bbb2bb8118237815223c4b906328b7e8a373aa97fdae409a025470dc", "price_changes": [{"asset_id": "108210708594024455543283956523953124001017416937788990111411478336430517420393", "price": "0.77", "size": "100", "side": "SELL", "hash": "b05ddf36c35deb3687a23c58cf1f931d84888ef1", "best_bid": "0.1", "best_ask": "0.19"}, {"asset_id": "68257431892288883729500648109357161057886471290823106810192273382603520923445", "price": "0.23", "size": "100", "side": "BUY", "hash": "b853dae2184103601a824d3e9dabe954b4687310", "best_bid": "0.81", "best_ask": "0.9"}], "timestamp": "1769384064006", "event_type": "price_change"}}
{"_local_timestamp": "2026-01-25T23:34:24.675730+00:00", "data": {"market": "0x9a991a29bbb2bb8118237815223c4b906328b7e8a373aa97fdae409a025470dc", "price_changes": [{"asset_id": "108210708594024455543283956523953124001017416937788990111411478336430517420393", "price": "0.78", "size": "99.99", "side": "SELL", "hash": "8235ac48347f224a77a3d51f268db0d73b0d7279", "best_bid": "0.1", "best_ask": "0.19"}, {"asset_id": "68257431892288883729500648109357161057886471290823106810192273382603520923445", "price": "0.22", "size": "99.99", "side": "BUY", "hash": "8f080e108447176b6338d6414364a79720e30b2f", "best_bid": "0.81", "best_ask": "0.9"}], "timestamp": "1769384064453", "event_type": "price_change"}}
{"_local_timestamp": "2026-01-25T23:34:24.704713+00:00", "data": {"market": "0x9a991a29bbb2bb8118237815223c4b906328b7e8a373aa97fdae409a025470dc", "price_changes": [{"asset_id": "68257431892288883729500648109357161057886471290823106810192273382603520923445", "price": "0.23", "size": "0", "side": "BUY", "hash": "a0b843d2fc80211c6bf8fd38f137e75af05c84eb", "best_bid": "0.81", "best_ask": "0.9"}, {"asset_id": "108210708594024455543283956523953124001017416937788990111411478336430517420393", "price": "0.77", "size": "0", "side": "SELL", "hash": "e6c16c2c91f14aa1b8bf1c8df0bfc724acf3802e", "best_bid": "0.1", "best_ask": "0.19"}], "timestamp": "1769384064478", "event_type": "price_change"}}
{"_local_timestamp": "2026-01-25T23:34:25.400673+00:00", "data": {"market": "0x9a991a29bbb2bb8118237815223c4b906328b7e8a373aa97fdae409a025470dc", "price_changes": [{"asset_id": "68257431892288883729500648109357161057886471290823106810192273382603520923445", "price": "0.22", "size": "199.99", "side": "BUY", "hash": "c79e329e73aff41628c88efe17a7325890fe0839", "best_bid": "0.81", "best_ask": "0.9"}, {"asset_id": "108210708594024455543283956523953124001017416937788990111411478336430517420393", "price": "0.78", "size": "199.99", "side": "SELL", "hash": "9d2ac7f8f364d2ee2615453e240b5121b6de9ccc", "best_bid": "0.1", "best_ask": "0.19"}], "timestamp": "1769384065165", "event_type": "price_change"}}
{"_local_timestamp": "2026-01-25T23:34:25.412834+00:00", "data": {"market": "0x7bc1d3c8aaf0a20c853f576519446e1ee260e65d43205efd61696f3a9f9e62e7", "price_changes": [{"asset_id": "10966407605514195233392457845926539733586231163297093857244655359507639639996", "price": "0.006", "size": "0", "side": "BUY", "hash": "e09464aa92df6b7590f3ee7943218c3cd1cdc5db", "best_bid": "0.005", "best_ask": "0.084"}, {"asset_id": "74853086974054252708530367393532530785660539289108031053683362073748574770022", "price": "0.994", "size": "0", "side": "SELL", "hash": "807714d494f66a00372411d378fbdfbfeec5dd9b", "best_bid": "0.916", "best_ask": "0.995"}], "timestamp": "1769384065171", "event_type": "price_change"}}
{"_local_timestamp": "2026-01-25T23:34:25.464550+00:00", "data": {"market": "0x7bc1d3c8aaf0a20c853f576519446e1ee260e65d43205efd61696f3a9f9e62e7", "price_changes": [{"asset_id": "10966407605514195233392457845926539733586231163297093857244655359507639639996", "price": "0.006", "size": "251", "side": "BUY", "hash": "a78371f5df5a2da66d93ff4d6420a00b9511e114", "best_bid": "0.006", "best_ask": "0.084"}, {"asset_id": "74853086974054252708530367393532530785660539289108031053683362073748574770022", "price": "0.994", "size": "251", "side": "SELL", "hash": "c9a93cc8e6b2f38c32dfd41c2df025056dc242ee", "best_bid": "0.916", "best_ask": "0.994"}], "timestamp": "1769384065213", "event_type": "price_change"}}
{"_local_timestamp": "2026-01-25T23:34:26.907619+00:00", "data": {"market": "0x7bc1d3c8aaf0a20c853f576519446e1ee260e65d43205efd61696f3a9f9e62e7", "price_changes": [{"asset_id": "10966407605514195233392457845926539733586231163297093857244655359507639639996", "price": "0.006", "size": "0", "side": "BUY", "hash": "d2d3cddb8ffcec553cdcb6895ce89b8624f38861", "best_bid": "0.005", "best_ask": "0.084"}, {"asset_id": "74853086974054252708530367393532530785660539289108031053683362073748574770022", "price": "0.994", "size": "0", "side": "SELL", "hash": "6bb8a70ebbf1beabfcdc49f0993c53656ef0098d", "best_bid": "0.916", "best_ask": "0.995"}], "timestamp": "1769384066671", "event_type": "price_change"}}
{"_local_timestamp": "2026-01-25T23:34:26.941042+00:00", "data": {"market": "0x7bc1d3c8aaf0a20c853f576519446e1ee260e65d43205efd61696f3a9f9e62e7", "price_changes": [{"asset_id": "10966407605514195233392457845926539733586231163297093857244655359507639639996", "price": "0.006", "size": "251", "side": "BUY", "hash": "b2e3ceaef65a20a85cf67a02fd1638a194175792", "best_bid": "0.006", "best_ask": "0.084"}, {"asset_id": "74853086974054252708530367393532530785660539289108031053683362073748574770022", "price": "0.994", "size": "251", "side": "SELL", "hash": "099206f95f30643532d37108ff105137bb81198d", "best_bid": "0.916", "best_ask": "0.994"}], "timestamp": "1769384066699", "event_type": "price_change"}}
{"_local_timestamp": "2026-01-25T23:34:27.760907+00:00", "data": {"market": "0x9a991a29bbb2bb8118237815223c4b906328b7e8a373aa97fdae409a025470dc", "price_changes": [{"asset_id": "68257431892288883729500648109357161057886471290823106810192273382603520923445", "price": "0.21", "size": "2048", "side": "BUY", "hash": "0a29e58394f0574bd1858e498bbd1fc3abe8cb45", "best_bid": "0.81", "best_ask": "0.9"}, {"asset_id": "108210708594024455543283956523953124001017416937788990111411478336430517420393", "price": "0.79", "size": "2048", "side": "SELL", "hash": "30f8bbb34c4a5d11b913400934816fb19d74cf27", "best_bid": "0.1", "best_ask": "0.19"}], "timestamp": "1769384067546", "event_type": "price_change"}}
{"_local_timestamp": "2026-01-25T23:34:28.004849+00:00", "data": {"market": "0x680784812145063cecedfa7f000654e89317e2aca612182884d7742ac6f801f9", "price_changes": [{"asset_id": "60410997855954556286106048831701517763027421942281960711866162404690269293947", "price": "0.16", "size": "2624", "side": "BUY", "hash": "7a84bd77b9339b011e26299b2acf9713a6713725", "best_bid": "0.78", "best_ask": "0.81"}, {"asset_id": "76179285001548801832051437870901871012966717962774017789970710364900180173602", "price": "0.84", "size": "2624", "side": "SELL", "hash": "5e2f13ddf2ca9041c251747c617dd5b67a406cee", "best_bid": "0.19", "best_ask": "0.22"}], "timestamp": "1769384067615", "event_type": "price_change"}}
{"_local_timestamp": "2026-01-25T23:34:28.417441+00:00", "data": {"market": "0x7bc1d3c8aaf0a20c853f576519446e1ee260e65d43205efd61696f3a9f9e62e7", "price_changes": [{"asset_id": "10966407605514195233392457845926539733586231163297093857244655359507639639996", "price": "0.006", "size": "0", "side": "BUY", "hash": "60988e15ad3b333a2ea153ed6cb32843c1b5b632", "best_bid": "0.005", "best_ask": "0.084"}, {"asset_id": "74853086974054252708530367393532530785660539289108031053683362073748574770022", "price": "0.994", "size": "0", "side": "SELL", "hash": "0e3a0cf8bb6b1f2548627874de52c3902509dc7c", "best_bid": "0.916", "best_ask": "0.995"}], "timestamp": "1769384068177", "event_type": "price_change"}}
{"_local_timestamp": "2026-01-25T23:34:28.935338+00:00", "data": {"market": "0xe220ab18b19107b4a06b18a0b5e2a9e9ab4cd7cb297c27cfa05a3369815a1579", "price_changes": [{"asset_id": "29294180043579351070208019085320546351829489739790080999397489613464945007446", "price": "0.22", "size": "1908", "side": "BUY", "hash": "82c5e90abe241b1188258d237def1bee84d3405f", "best_bid": "0.68", "best_ask": "0.77"}, {"asset_id": "43938988181832985104138029041174463994072038957372562854085197368645176157001", "price": "0.78", "size": "1908", "side": "SELL", "hash": "693a729c6a4265ae4933b8d35594a39f9e7c23a5", "best_bid": "0.23", "best_ask": "0.32"}], "timestamp": "1769384068206", "event_type": "price_change"}}
{"_local_timestamp": "2026-01-25T23:34:28.938864+00:00", "data": {"market": "0x7bc1d3c8aaf0a20c853f576519446e1ee260e65d43205efd61696f3a9f9e62e7", "price_changes": [{"asset_id": "10966407605514195233392457845926539733586231163297093857244655359507639639996", "price": "0.006", "size": "251", "side": "BUY", "hash": "fa068bac8e9aeb7e844d3d356b5940ba5f7e960b", "best_bid": "0.006", "best_ask": "0.084"}, {"asset_id": "74853086974054252708530367393532530785660539289108031053683362073748574770022", "price": "0.994", "size": "251", "side": "SELL", "hash": "7b6e3d7e6ff03c5e150ee61c6599f7c4de51bc02", "best_bid": "0.916", "best_ask": "0.994"}], "timestamp": "1769384068219", "event_type": "price_change"}}
{"_local_timestamp": "2026-01-25T23:34:29.981717+00:00", "data": {"market": "0x7bc1d3c8aaf0a20c853f576519446e1ee260e65d43205efd61696f3a9f9e62e7", "price_changes": [{"asset_id": "10966407605514195233392457845926539733586231163297093857244655359507639639996", "price": "0.006", "size": "0", "side": "BUY", "hash": "186715177555ed4112bd4cd42ab374e6324b286f", "best_bid": "0.005", "best_ask": "0.084"}, {"asset_id": "74853086974054252708530367393532530785660539289108031053683362073748574770022", "price": "0.994", "size": "0", "side": "SELL", "hash": "0ff616160f3a74642ec5d4a0c5f49e907f616ded", "best_bid": "0.916", "best_ask": "0.995"}], "timestamp": "1769384069673", "event_type": "price_change"}}
{"_local_timestamp": "2026-01-25T23:34:30.145518+00:00", "data": {"market": "0x7bc1d3c8aaf0a20c853f576519446e1ee260e65d43205efd61696f3a9f9e62e7", "price_changes": [{"asset_id": "10966407605514195233392457845926539733586231163297093857244655359507639639996", "price": "0.006", "size": "251", "side": "BUY", "hash": "133c1911d3becc3d9500f8dcb1fb12c6b53cae54", "best_bid": "0.006", "best_ask": "0.084"}, {"asset_id": "74853086974054252708530367393532530785660539289108031053683362073748574770022", "price": "0.994", "size": "251", "side": "SELL", "hash": "489bf9c6032f4e0b831fe56994ee8604fb31352b", "best_bid": "0.916", "best_ask": "0.994"}], "timestamp": "1769384069799", "event_type": "price_change"}}
{"_local_timestamp": "2026-01-25T23:34:31.430115+00:00", "data": {"market": "0x7bc1d3c8aaf0a20c853f576519446e1ee260e65d43205efd61696f3a9f9e62e7", "price_changes": [{"asset_id": "10966407605514195233392457845926539733586231163297093857244655359507639639996", "price": "0.006", "size": "0", "side": "BUY", "hash": "457a4be6ed6f6c4abb9e6d7085d492958be5afbe", "best_bid": "0.005", "best_ask": "0.084"}, {"asset_id": "74853086974054252708530367393532530785660539289108031053683362073748574770022", "price": "0.994", "size": "0", "side": "SELL", "hash": "4378dde88541f9402304aea3f89ef8d4c4158d82", "best_bid": "0.916", "best_ask": "0.995"}], "timestamp": "1769384071202", "event_type": "price_change"}}
{"_local_timestamp": "2026-01-25T23:34:31.500958+00:00", "data": {"market": "0x7bc1d3c8aaf0a20c853f576519446e1ee260e65d43205efd61696f3a9f9e62e7", "price_changes": [{"asset_id": "10966407605514195233392457845926539733586231163297093857244655359507639639996", "price": "0.006", "size": "251", "side": "BUY", "hash": "85207a7cd6f4cd5fdc96a70fb73d6369da7bfe38", "best_bid": "0.006", "best_ask": "0.084"}, {"asset_id": "74853086974054252708530367393532530785660539289108031053683362073748574770022", "price": "0.994", "size": "251", "side": "SELL", "hash": "1448bb84839be221ba57325f495b912e5940720b", "best_bid": "0.916", "best_ask": "0.994"}], "timestamp": "1769384071273", "event_type": "price_change"}}
{"_local_timestamp": "2026-01-25T23:34:32.905042+00:00", "data": {"market": "0x7bc1d3c8aaf0a20c853f576519446e1ee260e65d43205efd61696f3a9f9e62e7", "price_changes": [{"asset_id": "10966407605514195233392457845926539733586231163297093857244655359507639639996", "price": "0.006", "size": "0", "side": "BUY", "hash": "c1df15d9e930f52a17c1d097917f9d34ca77b673", "best_bid": "0.005", "best_ask": "0.084"}, {"asset_id": "74853086974054252708530367393532530785660539289108031053683362073748574770022", "price": "0.994", "size": "0", "side": "SELL", "hash": "2e922352291dcf76ac9891bc6e98083b25579e90", "best_bid": "0.916", "best_ask": "0.995"}], "timestamp": "1769384072678", "event_type": "price_change"}}
{"_local_timestamp": "2026-01-25T23:34:32.940636+00:00", "data": {"market": "0x7bc1d3c8aaf0a20c853f576519446e1ee260e65d43205efd61696f3a9f9e62e7", "price_changes": [{"asset_id": "10966407605514195233392457845926539733586231163297093857244655359507639639996", "price": "0.006", "size": "251", "side": "BUY", "hash": "72f2c521da54454041ab44e9aec3f89f292ee007", "best_bid": "0.006", "best_ask": "0.084"}, {"asset_id": "74853086974054252708530367393532530785660539289108031053683362073748574770022", "price": "0.994", "size": "251", "side": "SELL", "hash": "0a15400969c665bb40444f85b647e6d65292568d", "best_bid": "0.916", "best_ask": "0.994"}], "timestamp": "1769384072709", "event_type": "price_change"}}
{"_local_timestamp": "2026-01-25T23:34:33.329093+00:00", "data": {"market": "0x7bc1d3c8aaf0a20c853f576519446e1ee260e65d43205efd61696f3a9f9e62e7", "price_changes": [{"asset_id": "10966407605514195233392457845926539733586231163297093857244655359507639639996", "price": "0.005", "size": "0", "side": "BUY", "hash": "c91a2164f0c801020a5f991d5b5262f90dffcb8d", "best_bid": "0.006", "best_ask": "0.084"}, {"asset_id": "74853086974054252708530367393532530785660539289108031053683362073748574770022", "price": "0.995", "size": "0", "side": "SELL", "hash": "a6b31482b98ec085112f42246c3ad0a89cf41a89", "best_bid": "0.916", "best_ask": "0.994"}], "timestamp": "1769384073093", "event_type": "price_change"}}
{"_local_timestamp": "2026-01-25T23:34:34.389777+00:00", "data": {"market": "0x7bc1d3c8aaf0a20c853f576519446e1ee260e65d43205efd61696f3a9f9e62e7", "price_changes": [{"asset_id": "10966407605514195233392457845926539733586231163297093857244655359507639639996", "price": "0.006", "size": "0", "side": "BUY", "hash": "36713b3b2389d87f41d908adeae3dea038fc1e65", "best_bid": "0.004", "best_ask": "0.084"}, {"asset_id": "74853086974054252708530367393532530785660539289108031053683362073748574770022", "price": "0.994", "size": "0", "side": "SELL", "hash": "592bc72ae771f1e6b694a300eac109531f5ee073", "best_bid": "0.916", "best_ask": "0.996"}], "timestamp": "1769384074172", "event_type": "price_change"}}
{"_local_timestamp": "2026-01-25T23:34:34.419491+00:00", "data": {"market": "0x7bc1d3c8aaf0a20c853f576519446e1ee260e65d43205efd61696f3a9f9e62e7", "price_changes": [{"asset_id": "10966407605514195233392457845926539733586231163297093857244655359507639639996", "price": "0.005", "size": "251", "side": "BUY", "hash": "82b7c22f3ee469b3e455e92824fc11bdb0162409", "best_bid": "0.005", "best_ask": "0.084"}, {"asset_id": "74853086974054252708530367393532530785660539289108031053683362073748574770022", "price": "0.995", "size": "251", "side": "SELL", "hash": "e4590e8285c1b8bf7e5b7384e7a1145f95c22795", "best_bid": "0.916", "best_ask": "0.995"}], "timestamp": "1769384074201", "event_type": "price_change"}}
{"_local_timestamp": "2026-01-25T23:34:34.783024+00:00", "data": {"market": "0x7bc1d3c8aaf0a20c853f576519446e1ee260e65d43205efd61696f3a9f9e62e7", "price_changes": [{"asset_id": "10966407605514195233392457845926539733586231163297093857244655359507639639996", "price": "0.007", "size": "171.42", "side": "BUY", "hash": "99ac3002c6f417302c714219b0c36eca8f2cc6a5", "best_bid": "0.007", "best_ask": "0.084"}, {"asset_id": "74853086974054252708530367393532530785660539289108031053683362073748574770022", "price": "0.993", "size": "171.42", "side": "SELL", "hash": "e1cdbea4acec7f555a3dd576d87793cbddb505ce", "best_bid": "0.916", "best_ask": "0.993"}], "timestamp": "1769384074568", "event_type": "price_change"}}
{"_local_timestamp": "2026-01-25T23:34:34.993311+00:00", "data": {"market": "0xe220ab18b19107b4a06b18a0b5e2a9e9ab4cd7cb297c27cfa05a3369815a1579", "price_changes": [{"asset_id": "29294180043579351070208019085320546351829489739790080999397489613464945007446", "price": "0.03", "size": "4016", "side": "BUY", "hash": "e787657e1678b0c589d380c4fce670b143597062", "best_bid": "0.68", "best_ask": "0.77"}, {"asset_id": "43938988181832985104138029041174463994072038957372562854085197368645176157001", "price": "0.97", "size": "4016", "side": "SELL", "hash": "5cac1a41f8fea834f438dbc9a25d5495cd15f7e8", "best_bid": "0.23", "best_ask": "0.32"}], "timestamp": "1769384074776", "event_type": "price_change"}}
{"_local_timestamp": "2026-01-25T23:34:34.994032+00:00", "data": {"market": "0xe220ab18b19107b4a06b18a0b5e2a9e9ab4cd7cb297c27cfa05a3369815a1579", "price_changes": [{"asset_id": "29294180043579351070208019085320546351829489739790080999397489613464945007446", "price": "0.07", "size": "1642", "side": "BUY", "hash": "e787657e1678b0c589d380c4fce670b143597062", "best_bid": "0.68", "best_ask": "0.77"}, {"asset_id": "43938988181832985104138029041174463994072038957372562854085197368645176157001", "price": "0.93", "size": "1642", "side": "SELL", "hash": "5cac1a41f8fea834f438dbc9a25d5495cd15f7e8", "best_bid": "0.23", "best_ask": "0.32"}], "timestamp": "1769384074776", "event_type": "price_change"}}
{"_local_timestamp": "2026-01-25T23:34:34.994608+00:00", "data": {"market": "0xe220ab18b19107b4a06b18a0b5e2a9e9ab4cd7cb297c27cfa05a3369815a1579", "price_changes": [{"asset_id": "29294180043579351070208019085320546351829489739790080999397489613464945007446", "price": "0.01", "size": "12038.4", "side": "BUY", "hash": "e787657e1678b0c589d380c4fce670b143597062", "best_bid": "0.68", "best_ask": "0.77"}, {"asset_id": "43938988181832985104138029041174463994072038957372562854085197368645176157001", "price": "0.99", "size": "12038.4", "side": "SELL", "hash": "5cac1a41f8fea834f438dbc9a25d5495cd15f7e8", "best_bid": "0.23", "best_ask": "0.32"}], "timestamp": "1769384074776", "event_type": "price_change"}}
{"_local_timestamp": "2026-01-25T23:34:35.885311+00:00", "data": {"market": "0x7bc1d3c8aaf0a20c853f576519446e1ee260e65d43205efd61696f3a9f9e62e7", "price_changes": [{"asset_id": "10966407605514195233392457845926539733586231163297093857244655359507639639996", "price": "0.005", "size": "0", "side": "BUY", "hash": "f05c958982deb8419190acae66c52f2b4df4fb09", "best_bid": "0.007", "best_ask": "0.084"}, {"asset_id": "74853086974054252708530367393532530785660539289108031053683362073748574770022", "price": "0.995", "size": "0", "side": "SELL", "hash": "2e11dcd2b03723604a3aef525eb0133e65e55922", "best_bid": "0.916", "best_ask": "0.993"}], "timestamp": "1769384075671", "event_type": "price_change"}}
{"_local_timestamp": "2026-01-25T23:34:38.257090+00:00", "data": {"market": "0x680784812145063cecedfa7f000654e89317e2aca612182884d7742ac6f801f9", "price_changes": [{"asset_id": "60410997855954556286106048831701517763027421942281960711866162404690269293947", "price": "0.16", "size": "3124", "side": "BUY", "hash": "174e4f9c4c56757efddc31b6f8a86c5af979bb77", "best_bid": "0.78", "best_ask": "0.81"}, {"asset_id": "76179285001548801832051437870901871012966717962774017789970710364900180173602", "price": "0.84", "size": "3124", "side": "SELL", "hash": "309b88342e2becbd34412123ff817a7984945e20", "best_bid": "0.19", "best_ask": "0.22"}], "timestamp": "1769384078187", "event_type": "price_change"}}
{"_local_timestamp": "2026-01-25T23:34:38.325399+00:00", "data": {"market": "0x5e075035583f3bf066377b92593a81ee9b40c72886cd590571c953d957ec63fe", "price_changes": [{"asset_id": "21309049201619161652065746140831735441976940779482114925077511349923500792596", "price": "0.1", "size": "0", "side": "BUY", "hash": "c984161c9f8c82c200506d800886ffd12465a2ea", "best_bid": "0.54", "best_ask": "0.56"}, {"asset_id": "115197249944798189466746855761602104266555395842031026841909545353040514904580", "price": "0.9", "size": "0", "side": "SELL", "hash": "22f0bad0af03403fb10ffe891336f6d93de37900", "best_bid": "0.44", "best_ask": "0.46"}], "timestamp": "1769384078258", "event_type": "price_change"}}
{"_local_timestamp": "2026-01-25T23:34:43.859182+00:00", "data": {"market": "0x680784812145063cecedfa7f000654e89317e2aca612182884d7742ac6f801f9", "price_changes": [{"asset_id": "60410997855954556286106048831701517763027421942281960711866162404690269293947", "price": "0.15", "size": "2800", "side": "BUY", "hash": "c25a883a7de30add1791be27d6ef6a825452fc18", "best_bid": "0.78", "best_ask": "0.81"}, {"asset_id": "76179285001548801832051437870901871012966717962774017789970710364900180173602", "price": "0.85", "size": "2800", "side": "SELL", "hash": "9902bddd18389cc960ea4d2e3a3c5d69bfc8bf16", "best_bid": "0.19", "best_ask": "0.22"}], "timestamp": "1769384083789", "event_type": "price_change"}}
{"_local_timestamp": "2026-01-25T23:34:44.125385+00:00", "data": {"market": "0x680784812145063cecedfa7f000654e89317e2aca612182884d7742ac6f801f9", "price_changes": [{"asset_id": "60410997855954556286106048831701517763027421942281960711866162404690269293947", "price": "0.16", "size": "3874", "side": "BUY", "hash": "0be8481611ac3b60c3d7bd1ab1dee9436dcf6a81", "best_bid": "0.78", "best_ask": "0.81"}, {"asset_id": "76179285001548801832051437870901871012966717962774017789970710364900180173602", "price": "0.84", "size": "3874", "side": "SELL", "hash": "c8ff7dabd8b3a45237eb1d03f797eeefb207447b", "best_bid": "0.19", "best_ask": "0.22"}], "timestamp": "1769384084010", "event_type": "price_change"}}
{"_local_timestamp": "2026-01-25T23:34:49.213069+00:00", "data": {"market": "0x5e075035583f3bf066377b92593a81ee9b40c72886cd590571c953d957ec63fe", "price_changes": [{"asset_id": "21309049201619161652065746140831735441976940779482114925077511349923500792596", "price": "0.1", "size": "21", "side": "BUY", "hash": "8a7c267fdb617344e982be77bbe26f6835d18fa4", "best_bid": "0.54", "best_ask": "0.56"}, {"asset_id": "115197249944798189466746855761602104266555395842031026841909545353040514904580", "price": "0.9", "size": "21", "side": "SELL", "hash": "493e794b92429db0f58fd5b1b32159ddc5aebe74", "best_bid": "0.44", "best_ask": "0.46"}], "timestamp": "1769384089135", "event_type": "price_change"}}
{"_local_timestamp": "2026-01-25T23:34:49.680244+00:00", "data": {"market": "0x680784812145063cecedfa7f000654e89317e2aca612182884d7742ac6f801f9", "price_changes": [{"asset_id": "60410997855954556286106048831701517763027421942281960711866162404690269293947", "price": "0.16", "size": "4274", "side": "BUY", "hash": "f02735dd8cc066bc0b366a7f1f62c1c37183d811", "best_bid": "0.78", "best_ask": "0.81"}, {"asset_id": "76179285001548801832051437870901871012966717962774017789970710364900180173602", "price": "0.84", "size": "4274", "side": "SELL", "hash": "176d0d272f92a21fecdf19f8b2689e927ebfe3f7", "best_bid": "0.19", "best_ask": "0.22"}], "timestamp": "1769384089580", "event_type": "price_change"}}
{"_local_timestamp": "2026-01-25T23:34:50.627669+00:00", "data": {"market": "0x680784812145063cecedfa7f000654e89317e2aca612182884d7742ac6f801f9", "price_changes": [{"asset_id": "60410997855954556286106048831701517763027421942281960711866162404690269293947", "price": "0.15", "size": "1300", "side": "BUY", "hash": "489ca5a974ca7a296f84c329b31c36a3741c263d", "best_bid": "0.78", "best_ask": "0.81"}, {"asset_id": "76179285001548801832051437870901871012966717962774017789970710364900180173602", "price": "0.85", "size": "1300", "side": "SELL", "hash": "6e59f076cc7d3ced4ffea83a3ea0aaf1dbb7ea80", "best_bid": "0.19", "best_ask": "0.22"}], "timestamp": "1769384090486", "event_type": "price_change"}}
{"_local_timestamp": "2026-01-25T23:34:50.740827+00:00", "data": {"market": "0x680784812145063cecedfa7f000654e89317e2aca612182884d7742ac6f801f9", "price_changes": [{"asset_id": "60410997855954556286106048831701517763027421942281960711866162404690269293947", "price": "0.15", "size": "900", "side": "BUY", "hash": "cde0e58524180d8d07f2beee3dc88963a2ba6e29", "best_bid": "0.78", "best_ask": "0.81"}, {"asset_id": "76179285001548801832051437870901871012966717962774017789970710364900180173602", "price": "0.85", "size": "900", "side": "SELL", "hash": "02e1896df15b6407b90c8565f9f9f8ab6affd236", "best_bid": "0.19", "best_ask": "0.22"}], "timestamp": "1769384090608", "event_type": "price_change"}}
{"_local_timestamp": "2026-01-25T23:34:50.856335+00:00", "data": {"market": "0x680784812145063cecedfa7f000654e89317e2aca612182884d7742ac6f801f9", "price_changes": [{"asset_id": "60410997855954556286106048831701517763027421942281960711866162404690269293947", "price": "0.16", "size": "5774", "side": "BUY", "hash": "26764be469ee39cda7d78bc0389ed8d405bbb86c", "best_bid": "0.78", "best_ask": "0.81"}, {"asset_id": "76179285001548801832051437870901871012966717962774017789970710364900180173602", "price": "0.84", "size": "5774", "side": "SELL", "hash": "de6eae8d3df21806444cc154d8b30d62beca05bb", "best_bid": "0.19", "best_ask": "0.22"}], "timestamp": "1769384090718", "event_type": "price_change"}}
{"_local_timestamp": "2026-01-25T23:34:51.008357+00:00", "data": {"market": "0x680784812145063cecedfa7f000654e89317e2aca612182884d7742ac6f801f9", "price_changes": [{"asset_id": "60410997855954556286106048831701517763027421942281960711866162404690269293947", "price": "0.16", "size": "6174", "side": "BUY", "hash": "c359442485df61f1ce04fa0f0bdb774362716877", "best_bid": "0.78", "best_ask": "0.81"}, {"asset_id": "76179285001548801832051437870901871012966717962774017789970710364900180173602", "price": "0.84", "size": "6174", "side": "SELL", "hash": "ba25d352b1b5e296fb47a5ca94726b89dc984389", "best_bid": "0.19", "best_ask": "0.22"}], "timestamp": "1769384090863", "event_type": "price_change"}}
{"_local_timestamp": "2026-01-25T23:34:51.009030+00:00", "data": {"market": "0xe220ab18b19107b4a06b18a0b5e2a9e9ab4cd7cb297c27cfa05a3369815a1579", "price_changes": [{"asset_id": "29294180043579351070208019085320546351829489739790080999397489613464945007446", "price": "0.01", "size": "17038.4", "side": "BUY", "hash": "a89d522bb7dfd646b7419e029c8f462b9b224351", "best_bid": "0.68", "best_ask": "0.77"}, {"asset_id": "43938988181832985104138029041174463994072038957372562854085197368645176157001", "price": "0.99", "size": "17038.4", "side": "SELL", "hash": "375706edd1a5f73db0f6e1001f608005083ba3a4", "best_bid": "0.23", "best_ask": "0.32"}], "timestamp": "1769384090863", "event_type": "price_change"}}
{"_local_timestamp": "2026-01-25T23:34:51.009718+00:00", "data": {"market": "0xe220ab18b19107b4a06b18a0b5e2a9e9ab4cd7cb297c27cfa05a3369815a1579", "price_changes": [{"asset_id": "29294180043579351070208019085320546351829489739790080999397489613464945007446", "price": "0.03", "size": "6016", "side": "BUY", "hash": "ef794d6986b8bd9d133518bb8da63c2ae469f5df", "best_bid": "0.68", "best_ask": "0.77"}, {"asset_id": "43938988181832985104138029041174463994072038957372562854085197368645176157001", "price": "0.97", "size": "6016", "side": "SELL", "hash": "41cf1b477e7198cbec8a01933a22934a565bce35", "best_bid": "0.23", "best_ask": "0.32"}], "timestamp": "1769384090864", "event_type": "price_change"}}
{"_local_timestamp": "2026-01-25T23:34:51.012651+00:00", "data": {"market": "0xe220ab18b19107b4a06b18a0b5e2a9e9ab4cd7cb297c27cfa05a3369815a1579", "price_changes": [{"asset_id": "29294180043579351070208019085320546351829489739790080999397489613464945007446", "price": "0.07", "size": "2642", "side": "BUY", "hash": "1b7d3f8b44cb27634e25f5cbd150197c10296e73", "best_bid": "0.68", "best_ask": "0.77"}, {"asset_id": "43938988181832985104138029041174463994072038957372562854085197368645176157001", "price": "0.93", "size": "2642", "side": "SELL", "hash": "d2e3d42158e2e2de93959834aa891201daedf9da", "best_bid": "0.23", "best_ask": "0.32"}], "timestamp": "1769384090865", "event_type": "price_change"}}
{"_local_timestamp": "2026-01-25T23:34:53.100357+00:00", "data": {"market": "0x34c320af835b2d4b56224618b9930e3a6b26ed7f6854c4f8ce04b35f6d3ee801", "price_changes": [{"asset_id": "31278264626330879886341915760798723117251320102541744661396613642093503516942", "price": "0.74", "size": "0", "side": "BUY", "hash": "19c0a5859b567c96125bb3ff0da6f09d30a74e46", "best_bid": "0.853", "best_ask": "0.903"}, {"asset_id": "21965236637806877423690456379421697078490533519739537235259143695240300903846", "price": "0.26", "size": "0", "side": "SELL", "hash": "6134a2953072e5364212ecaa1119b40e4470b606", "best_bid": "0.097", "best_ask": "0.147"}], "timestamp": "1769384092948", "event_type": "price_change"}}
{"_local_timestamp": "2026-01-25T23:34:53.421939+00:00", "data": {"market": "0x34c320af835b2d4b56224618b9930e3a6b26ed7f6854c4f8ce04b35f6d3ee801", "price_changes": [{"asset_id": "31278264626330879886341915760798723117251320102541744661396613642093503516942", "price": "0.741", "size": "225", "side": "BUY", "hash": "cbf1710e52dba23ef297b0c6b73e93c617378d4b", "best_bid": "0.853", "best_ask": "0.903"}, {"asset_id": "21965236637806877423690456379421697078490533519739537235259143695240300903846", "price": "0.259", "size": "225", "side": "SELL", "hash": "cc765eb37c3ff324fccbf731da4404da0c3c7f47", "best_bid": "0.097", "best_ask": "0.147"}], "timestamp": "1769384093281", "event_type": "price_change"}}
{"_local_timestamp": "2026-01-25T23:35:08.878790+00:00", "data": {"market": "0x680784812145063cecedfa7f000654e89317e2aca612182884d7742ac6f801f9", "price_changes": [{"asset_id": "60410997855954556286106048831701517763027421942281960711866162404690269293947", "price": "0.15", "size": "500", "side": "BUY", "hash": "cac3e4e1ad73cad46b11547422af48b21ab310a3", "best_bid": "0.78", "best_ask": "0.81"}, {"asset_id": "76179285001548801832051437870901871012966717962774017789970710364900180173602", "price": "0.85", "size": "500", "side": "SELL", "hash": "de75f1282caeb378d23c440ed3fa6f0417c0a038", "best_bid": "0.19", "best_ask": "0.22"}], "timestamp": "1769384108805", "event_type": "price_change"}}
{"_local_timestamp": "2026-01-25T23:35:09.126222+00:00", "data": {"market": "0x680784812145063cecedfa7f000654e89317e2aca612182884d7742ac6f801f9", "price_changes": [{"asset_id": "60410997855954556286106048831701517763027421942281960711866162404690269293947", "price": "0.12", "size": "1358", "side": "BUY", "hash": "1789c8b06be47534f773d9be5f414f35777656ef", "best_bid": "0.78", "best_ask": "0.81"}, {"asset_id": "76179285001548801832051437870901871012966717962774017789970710364900180173602", "price": "0.88", "size": "1358", "side": "SELL", "hash": "1da4af91597b0d61460baa2d2e35eb4c193884ec", "best_bid": "0.19", "best_ask": "0.22"}], "timestamp": "1769384109060", "event_type": "price_change"}}
{"_local_timestamp": "2026-01-25T23:35:10.945415+00:00", "data": {"market": "0x680784812145063cecedfa7f000654e89317e2aca612182884d7742ac6f801f9", "price_changes": [{"asset_id": "60410997855954556286106048831701517763027421942281960711866162404690269293947", "price": "0.15", "size": "0", "side": "BUY", "hash": "a0ce3ad65cf9d788fb3d1200cba9d32437beb707", "best_bid": "0.78", "best_ask": "0.81"}, {"asset_id": "76179285001548801832051437870901871012966717962774017789970710364900180173602", "price": "0.85", "size": "0", "side": "SELL", "hash": "3847c59957a722c4486d73d7d4fe583276ecc4bf", "best_bid": "0.19", "best_ask": "0.22"}], "timestamp": "1769384110743", "event_type": "price_change"}}
{"_local_timestamp": "2026-01-25T23:35:11.080588+00:00", "data": {"market": "0x680784812145063cecedfa7f000654e89317e2aca612182884d7742ac6f801f9", "price_changes": [{"asset_id": "60410997855954556286106048831701517763027421942281960711866162404690269293947", "price": "0.08", "size": "5200", "side": "BUY", "hash": "8972f0df548ff2ac5c5b7a71240d26acf23feb46", "best_bid": "0.78", "best_ask": "0.81"}, {"asset_id": "76179285001548801832051437870901871012966717962774017789970710364900180173602", "price": "0.92", "size": "5200", "side": "SELL", "hash": "70b15f5e252b8cd19ddb1e3b334040982e9f894c", "best_bid": "0.19", "best_ask": "0.22"}], "timestamp": "1769384111015", "event_type": "price_change"}}
{"_local_timestamp": "2026-01-25T23:35:31.403265+00:00", "data": {"market": "0x9a991a29bbb2bb8118237815223c4b906328b7e8a373aa97fdae409a025470dc", "price_changes": [{"asset_id": "108210708594024455543283956523953124001017416937788990111411478336430517420393", "price": "0.08", "size": "0", "side": "BUY", "hash": "1ad586cab9a3fab00239913baea5dcce7d5f4f53", "best_bid": "0.1", "best_ask": "0.19"}, {"asset_id": "68257431892288883729500648109357161057886471290823106810192273382603520923445", "price": "0.92", "size": "0", "side": "SELL", "hash": "22b378bad7a15d79ca3e479733cfadb63a9cd731", "best_bid": "0.81", "best_ask": "0.9"}], "timestamp": "1769384131245", "event_type": "price_change"}}
{"_local_timestamp": "2026-01-25T23:35:31.421021+00:00", "data": {"market": "0xe220ab18b19107b4a06b18a0b5e2a9e9ab4cd7cb297c27cfa05a3369815a1579", "price_changes": [{"asset_id": "43938988181832985104138029041174463994072038957372562854085197368645176157001", "price": "0.17", "size": "10", "side": "BUY", "hash": "f7fcac7a9667dcbb228600be0a2af08c306621ce", "best_bid": "0.23", "best_ask": "0.32"}, {"asset_id": "29294180043579351070208019085320546351829489739790080999397489613464945007446", "price": "0.83", "size": "10", "side": "SELL", "hash": "c95fff603ad2747c484c661fc6d5b0e33966fac4", "best_bid": "0.68", "best_ask": "0.77"}], "timestamp": "1769384131247", "event_type": "price_change"}}
{"_local_timestamp": "2026-01-25T23:35:33.300962+00:00", "data": {"market": "0x9a991a29bbb2bb8118237815223c4b906328b7e8a373aa97fdae409a025470dc", "price_changes": [{"asset_id": "108210708594024455543283956523953124001017416937788990111411478336430517420393", "price": "0.1", "size": "120", "side": "BUY", "hash": "caa36ac89457b86283c4a7ba1a3dea12facb34cd", "best_bid": "0.1", "best_ask": "0.19"}, {"asset_id": "68257431892288883729500648109357161057886471290823106810192273382603520923445", "price": "0.9", "size": "120", "side": "SELL", "hash": "abfbcd055123e2aab4a5b18df1a252e616c7cdc5", "best_bid": "0.81", "best_ask": "0.9"}], "timestamp": "1769384133224", "event_type": "price_change"}}
{"_local_timestamp": "2026-01-25T23:35:33.647729+00:00", "data": {"market": "0xc5c870d2ca29e41ac55e1fac0c7b3c1140eb58fdf26fd2a77284caa9aca1b3aa", "price_changes": [{"asset_id": "106940491396743186324486767673070552626952698856095995665708923002375094057739", "price": "0.003", "size": "3010.86", "side": "BUY", "hash": "a8b4c42bcd12a22d63a94ad795ea908fa9dcf069", "best_bid": "0.043", "best_ask": "0.045"}, {"asset_id": "83029595771494657564747548834030842590595300298406079594487838617400032504038", "price": "0.997", "size": "3010.86", "side": "SELL", "hash": "04b57b339442c0d5cef4af96512291fc89981059", "best_bid": "0.955", "best_ask": "0.957"}], "timestamp": "1769384133576", "event_type": "price_change"}}
{"_local_timestamp": "2026-01-25T23:35:34.397064+00:00", "data": {"market": "0x9a991a29bbb2bb8118237815223c4b906328b7e8a373aa97fdae409a025470dc", "price_changes": [{"asset_id": "68257431892288883729500648109357161057886471290823106810192273382603520923445", "price": "0.91", "size": "100", "side": "SELL", "hash": "5183b8271433c8caecb848596624a3900ce3944c", "best_bid": "0.81", "best_ask": "0.9"}, {"asset_id": "108210708594024455543283956523953124001017416937788990111411478336430517420393", "price": "0.09", "size": "100", "side": "BUY", "hash": "552fac51b2a581e44657c3bc86bbc59fb58a20c7", "best_bid": "0.1", "best_ask": "0.19"}], "timestamp": "1769384134305", "event_type": "price_change"}}
{"_local_timestamp": "2026-01-25T23:35:34.564016+00:00", "data": {"market": "0x9a991a29bbb2bb8118237815223c4b906328b7e8a373aa97fdae409a025470dc", "price_changes": [{"asset_id": "68257431892288883729500648109357161057886471290823106810192273382603520923445", "price": "0.93", "size": "88.98", "side": "SELL", "hash": "a59d1c06461c06a5766f436814714d8114bbfccd", "best_bid": "0.81", "best_ask": "0.9"}, {"asset_id": "108210708594024455543283956523953124001017416937788990111411478336430517420393", "price": "0.07", "size": "88.98", "side": "BUY", "hash": "c07428fb815309930aaec4feefac5a64d5465879", "best_bid": "0.1", "best_ask": "0.19"}], "timestamp": "1769384134489", "event_type": "price_change"}}
{"_local_timestamp": "2026-01-25T23:35:34.782467+00:00", "data": {"market": "0x9a991a29bbb2bb8118237815223c4b906328b7e8a373aa97fdae409a025470dc", "price_changes": [{"asset_id": "108210708594024455543283956523953124001017416937788990111411478336430517420393", "price": "0.09", "size": "0", "side": "BUY", "hash": "49b69f535a832e8688c062d6cfaa0a8e699672d2", "best_bid": "0.1", "best_ask": "0.19"}, {"asset_id": "68257431892288883729500648109357161057886471290823106810192273382603520923445", "price": "0.91", "size": "0", "side": "SELL", "hash": "ea917586cd251664246cf4ccf87e0509869d0ea0", "best_bid": "0.81", "best_ask": "0.9"}], "timestamp": "1769384134712", "event_type": "price_change"}}
{"_local_timestamp": "2026-01-25T23:35:35.356560+00:00", "data": {"market": "0x9a991a29bbb2bb8118237815223c4b906328b7e8a373aa97fdae409a025470dc", "price_changes": [{"asset_id": "108210708594024455543283956523953124001017416937788990111411478336430517420393", "price": "0.07", "size": "188.98", "side": "BUY", "hash": "355cc80e82c8a16f2ee115ae742c8ea0f6930f0e", "best_bid": "0.1", "best_ask": "0.19"}, {"asset_id": "68257431892288883729500648109357161057886471290823106810192273382603520923445", "price": "0.93", "size": "188.98", "side": "SELL", "hash": "05ed12932ffece700d6a640fd6bd9d2200fbb6fe", "best_bid": "0.81", "best_ask": "0.9"}], "timestamp": "1769384135291", "event_type": "price_change"}}
{"_local_timestamp": "2026-01-25T23:35:36.178420+00:00", "data": {"market": "0x9a991a29bbb2bb8118237815223c4b906328b7e8a373aa97fdae409a025470dc", "price_changes": [{"asset_id": "108210708594024455543283956523953124001017416937788990111411478336430517420393", "price": "0.1", "size": "90", "side": "BUY", "hash": "770b2b1d369af94e0ec557ce0955109f27914673", "best_bid": "0.1", "best_ask": "0.19"}, {"asset_id": "68257431892288883729500648109357161057886471290823106810192273382603520923445", "price": "0.9", "size": "90", "side": "SELL", "hash": "e1274ece9a44f12f46e2808590032cf995c6daae", "best_bid": "0.81", "best_ask": "0.9"}], "timestamp": "1769384136108", "event_type": "price_change"}}
{"_local_timestamp": "2026-01-25T23:35:53.031982+00:00", "data": {"market": "0x005c717a74e620db3360f9820aa2ed4d986c7f26de68491a969980cb1780ea62", "price_changes": [{"asset_id": "71896965718321739380350615937116799467572851624467621515057427915300050709178", "price": "0.003", "size": "3016.37", "side": "BUY", "hash": "ae97d174e7a756939465b50acad0696a519fe590", "best_bid": "0.005", "best_ask": "0.017"}, {"asset_id": "76814623564203765431691483348264556272430488581668919316696049026942353449018", "price": "0.997", "size": "3016.37", "side": "SELL", "hash": "a90a46c59c0912edc4414b439c181065172ad859", "best_bid": "0.983", "best_ask": "0.995"}], "timestamp": "1769384152962", "event_type": "price_change"}}
{"_local_timestamp": "2026-01-25T23:35:53.284214+00:00", "data": {"market": "0x005c717a74e620db3360f9820aa2ed4d986c7f26de68491a969980cb1780ea62", "price_changes": [{"asset_id": "71896965718321739380350615937116799467572851624467621515057427915300050709178", "price": "0.003", "size": "3025.96", "side": "BUY", "hash": "61d7b1c80634398e03047bd0d51323c6d9054fcc", "best_bid": "0.005", "best_ask": "0.017"}, {"asset_id": "76814623564203765431691483348264556272430488581668919316696049026942353449018", "price": "0.997", "size": "3025.96", "side": "SELL", "hash": "0222e2ac98b912b457b83a37ad02d24578f68a24", "best_bid": "0.983", "best_ask": "0.995"}], "timestamp": "1769384153213", "event_type": "price_change"}}
{"_local_timestamp": "2026-01-25T23:35:56.377295+00:00", "data": {"market": "0xe220ab18b19107b4a06b18a0b5e2a9e9ab4cd7cb297c27cfa05a3369815a1579", "price_changes": [{"asset_id": "29294180043579351070208019085320546351829489739790080999397489613464945007446", "price": "0.2", "size": "0", "side": "BUY", "hash": "af5db29604fb9e21b35ff9de01f9bceb1616cad8", "best_bid": "0.68", "best_ask": "0.77"}, {"asset_id": "43938988181832985104138029041174463994072038957372562854085197368645176157001", "price": "0.8", "size": "0", "side": "SELL", "hash": "1a944b5be20a5db9882106346fe7403b1c612072", "best_bid": "0.23", "best_ask": "0.32"}], "timestamp": "1769384156281", "event_type": "price_change"}}
{"_local_timestamp": "2026-01-25T23:35:56.384890+00:00", "data": {"market": "0x9a991a29bbb2bb8118237815223c4b906328b7e8a373aa97fdae409a025470dc", "price_changes": [{"asset_id": "68257431892288883729500648109357161057886471290823106810192273382603520923445", "price": "0.21", "size": "1998", "side": "BUY", "hash": "08eab0ffe59ecc14146361de497975d05c211377", "best_bid": "0.81", "best_ask": "0.9"}, {"asset_id": "108210708594024455543283956523953124001017416937788990111411478336430517420393", "price": "0.79", "size": "1998", "side": "SELL", "hash": "1814724d6a4589034fdeb0fd0304d55fe29bda1b", "best_bid": "0.1", "best_ask": "0.19"}], "timestamp": "1769384156281", "event_type": "price_change"}}
{"_local_timestamp": "2026-01-25T23:35:56.854454+00:00", "data": {"market": "0x9a991a29bbb2bb8118237815223c4b906328b7e8a373aa97fdae409a025470dc", "price_changes": [{"asset_id": "68257431892288883729500648109357161057886471290823106810192273382603520923445", "price": "0.22", "size": "249.99", "side": "BUY", "hash": "c7bc03aa123f1b6e1b075ce9695b13d4818d3faa", "best_bid": "0.81", "best_ask": "0.9"}, {"asset_id": "108210708594024455543283956523953124001017416937788990111411478336430517420393", "price": "0.78", "size": "249.99", "side": "SELL", "hash": "f9f6c66d0637ccba0f8be9f0bf6d3a5fc7ed127d", "best_bid": "0.1", "best_ask": "0.19"}], "timestamp": "1769384156732", "event_type": "price_change"}}
{"_local_timestamp": "2026-01-25T23:35:56.861090+00:00", "data": {"market": "0xe220ab18b19107b4a06b18a0b5e2a9e9ab4cd7cb297c27cfa05a3369815a1579", "price_changes": [{"asset_id": "29294180043579351070208019085320546351829489739790080999397489613464945007446", "price": "0.21", "size": "75", "side": "BUY", "hash": "751b17497b7cb3f7f9fb7bc678958de198dc50ee", "best_bid": "0.68", "best_ask": "0.77"}, {"asset_id": "43938988181832985104138029041174463994072038957372562854085197368645176157001", "price": "0.79", "size": "75", "side": "SELL", "hash": "e1dfcb601ec80632c37f335154f5f434168ff96c", "best_bid": "0.23", "best_ask": "0.32"}], "timestamp": "1769384156734", "event_type": "price_change"}}
{"_local_timestamp": "2026-01-25T23:35:58.189090+00:00", "data": {"market": "0x9a991a29bbb2bb8118237815223c4b906328b7e8a373aa97fdae409a025470dc", "price_changes": [{"asset_id": "68257431892288883729500648109357161057886471290823106810192273382603520923445", "price": "0.21", "size": "0", "side": "BUY", "hash": "90390748c1132a19cb521db7d0602ebcf92c362d", "best_bid": "0.81", "best_ask": "0.9"}, {"asset_id": "108210708594024455543283956523953124001017416937788990111411478336430517420393", "price": "0.79", "size": "0", "side": "SELL", "hash": "bb5acc559cb542a9f85d660edc444a445d74bb32", "best_bid": "0.1", "best_ask": "0.19"}], "timestamp": "1769384158069", "event_type": "price_change"}}
{"_local_timestamp": "2026-01-25T23:35:58.204151+00:00", "data": {"market": "0xe220ab18b19107b4a06b18a0b5e2a9e9ab4cd7cb297c27cfa05a3369815a1579", "price_changes": [{"asset_id": "29294180043579351070208019085320546351829489739790080999397489613464945007446", "price": "0.22", "size": "0", "side": "BUY", "hash": "edb6c15755eef923026ad40974c2fe0372e1bda0", "best_bid": "0.68", "best_ask": "0.77"}, {"asset_id": "43938988181832985104138029041174463994072038957372562854085197368645176157001", "price": "0.78", "size": "0", "side": "SELL", "hash": "84f5d58120bb316bbbd808f29dff4fba3ec8b7bf", "best_bid": "0.23", "best_ask": "0.32"}], "timestamp": "1769384158074", "event_type": "price_change"}}
{"_local_timestamp": "2026-01-25T23:35:58.211887+00:00", "data": {"market": "0x680784812145063cecedfa7f000654e89317e2aca612182884d7742ac6f801f9", "price_changes": [{"asset_id": "60410997855954556286106048831701517763027421942281960711866162404690269293947", "price": "0.16", "size": "3550", "side": "BUY", "hash": "692c801d79f35db4bae83b49cd76515f5bfd8bf7", "best_bid": "0.78", "best_ask": "0.81"}, {"asset_id": "76179285001548801832051437870901871012966717962774017789970710364900180173602", "price": "0.84", "size": "3550", "side": "SELL", "hash": "e25228af40e71258b6fe7123872c66e14208facd", "best_bid": "0.19", "best_ask": "0.22"}], "timestamp": "1769384158077", "event_type": "price_change"}}
{"_local_timestamp": "2026-01-25T23:35:59.286455+00:00", "data": {"market": "0x9a991a29bbb2bb8118237815223c4b906328b7e8a373aa97fdae409a025470dc", "price_changes": [{"asset_id": "108210708594024455543283956523953124001017416937788990111411478336430517420393", "price": "0.78", "size": "150", "side": "SELL", "hash": "70ec6a287ec78632d876ec8409175ab882e31cdd", "best_bid": "0.1", "best_ask": "0.19"}, {"asset_id": "68257431892288883729500648109357161057886471290823106810192273382603520923445", "price": "0.22", "size": "150", "side": "BUY", "hash": "b40d888fc8e294ccbac8e96b133f4478d9548f27", "best_bid": "0.81", "best_ask": "0.9"}], "timestamp": "1769384159214", "event_type": "price_change"}}
{"_local_timestamp": "2026-01-25T23:35:59.522742+00:00", "data": {"market": "0x9a991a29bbb2bb8118237815223c4b906328b7e8a373aa97fdae409a025470dc", "price_changes": [{"asset_id": "68257431892288883729500648109357161057886471290823106810192273382603520923445", "price": "0.22", "size": "50", "side": "BUY", "hash": "cdb7fc3c64c33dd21f0b8ff4c0171cbb6e709005", "best_bid": "0.81", "best_ask": "0.9"}, {"asset_id": "108210708594024455543283956523953124001017416937788990111411478336430517420393", "price": "0.78", "size": "50", "side": "SELL", "hash": "9be78e7c0b092b956127ee56e24e86a9c2d1b58b", "best_bid": "0.1", "best_ask": "0.19"}], "timestamp": "1769384159453", "event_type": "price_change"}}
{"_local_timestamp": "2026-01-25T23:35:59.638589+00:00", "data": {"market": "0x9a991a29bbb2bb8118237815223c4b906328b7e8a373aa97fdae409a025470dc", "price_changes": [{"asset_id": "108210708594024455543283956523953124001017416937788990111411478336430517420393", "price": "0.77", "size": "99.99", "side": "SELL", "hash": "d3cb4e9400b12120a9c37dc34c122bbf7dab6a21", "best_bid": "0.1", "best_ask": "0.19"}, {"asset_id": "68257431892288883729500648109357161057886471290823106810192273382603520923445", "price": "0.23", "size": "99.99", "side": "BUY", "hash": "0c1125682ae62eaa10d83ae9fe8ac39eb5e2f308", "best_bid": "0.81", "best_ask": "0.9"}], "timestamp": "1769384159570", "event_type": "price_change"}}
{"_local_timestamp": "2026-01-25T23:36:00.197394+00:00", "data": {"market": "0x9a991a29bbb2bb8118237815223c4b906328b7e8a373aa97fdae409a025470dc", "price_changes": [{"asset_id": "68257431892288883729500648109357161057886471290823106810192273382603520923445", "price": "0.23", "size": "199.99", "side": "BUY", "hash": "a55adc4ae448835a807b8dd119feaad5a94f0afe", "best_bid": "0.81", "best_ask": "0.9"}, {"asset_id": "108210708594024455543283956523953124001017416937788990111411478336430517420393", "price": "0.77", "size": "199.99", "side": "SELL", "hash": "aafb6878ef5e35fe09c3a6408d3fbdb4132058e4", "best_bid": "0.1", "best_ask": "0.19"}], "timestamp": "1769384160109", "event_type": "price_change"}}
{"_local_timestamp": "2026-01-25T23:36:03.634747+00:00", "data": {"market": "0x7bc1d3c8aaf0a20c853f576519446e1ee260e65d43205efd61696f3a9f9e62e7", "price_changes": [{"asset_id": "10966407605514195233392457845926539733586231163297093857244655359507639639996", "price": "0.007", "size": "0", "side": "BUY", "hash": "af40d05775002077ce132765112fc25510026bbb", "best_bid": "0.004", "best_ask": "0.084"}, {"asset_id": "74853086974054252708530367393532530785660539289108031053683362073748574770022", "price": "0.993", "size": "0", "side": "SELL", "hash": "2aa22ec2d4a968206e2c2b60879f8571b4faaea7", "best_bid": "0.916", "best_ask": "0.996"}], "timestamp": "1769384163568", "event_type": "price_change"}}
{"_local_timestamp": "2026-01-25T23:36:03.674876+00:00", "data": {"market": "0x7bc1d3c8aaf0a20c853f576519446e1ee260e65d43205efd61696f3a9f9e62e7", "price_changes": [{"asset_id": "10966407605514195233392457845926539733586231163297093857244655359507639639996", "price": "0.008", "size": "251", "side": "BUY", "hash": "1fff440936e87c1ad5ec31426e899f2d60c12778", "best_bid": "0.008", "best_ask": "0.084"}, {"asset_id": "74853086974054252708530367393532530785660539289108031053683362073748574770022", "price": "0.992", "size": "251", "side": "SELL", "hash": "3952fae522c309717b5d5543752935e903e3e2b9", "best_bid": "0.916", "best_ask": "0.992"}], "timestamp": "1769384163609", "event_type": "price_change"}}
{"_local_timestamp": "2026-01-25T23:36:04.737410+00:00", "data": {"market": "0x7bc1d3c8aaf0a20c853f576519446e1ee260e65d43205efd61696f3a9f9e62e7", "price_changes": [{"asset_id": "10966407605514195233392457845926539733586231163297093857244655359507639639996", "price": "0.008", "size": "0", "side": "BUY", "hash": "21a2c8ab28270eed75438dcb692f62e637e0e026", "best_bid": "0.004", "best_ask": "0.084"}, {"asset_id": "74853086974054252708530367393532530785660539289108031053683362073748574770022", "price": "0.992", "size": "0", "side": "SELL", "hash": "30b69bbf7892bf3f7460f29773a83237742758cf", "best_bid": "0.916", "best_ask": "0.996"}], "timestamp": "1769384164674", "event_type": "price_change"}}
{"_local_timestamp": "2026-01-25T23:36:04.771262+00:00", "data": {"market": "0x7bc1d3c8aaf0a20c853f576519446e1ee260e65d43205efd61696f3a9f9e62e7", "price_changes": [{"asset_id": "10966407605514195233392457845926539733586231163297093857244655359507639639996", "price": "0.005", "size": "251", "side": "BUY", "hash": "03ae10c9410187ccfe62a1648aadeb0850166462", "best_bid": "0.005", "best_ask": "0.084"}, {"asset_id": "74853086974054252708530367393532530785660539289108031053683362073748574770022", "price": "0.995", "size": "251", "side": "SELL", "hash": "fa286fca2d5eb88a8675cd0c864982bebd5cece0", "best_bid": "0.916", "best_ask": "0.995"}], "timestamp": "1769384164701", "event_type": "price_change"}}
{"_local_timestamp": "2026-01-25T23:36:05.145158+00:00", "data": {"market": "0x7bc1d3c8aaf0a20c853f576519446e1ee260e65d43205efd61696f3a9f9e62e7", "price_changes": [{"asset_id": "10966407605514195233392457845926539733586231163297093857244655359507639639996", "price": "0.005", "size": "490.99", "side": "BUY", "hash": "a97fa2f7aadd2fd598fa89b5f070a975782fb883", "best_bid": "0.005", "best_ask": "0.084"}, {"asset_id": "74853086974054252708530367393532530785660539289108031053683362073748574770022", "price": "0.995", "size": "490.99", "side": "SELL", "hash": "93ae79baab0fc7017eccdabae4bdf1e1790f5919", "best_bid": "0.916", "best_ask": "0.995"}], "timestamp": "1769384165069", "event_type": "price_change"}}
{"_local_timestamp": "2026-01-25T23:36:07.102016+00:00", "data": {"market": "0xc5c870d2ca29e41ac55e1fac0c7b3c1140eb58fdf26fd2a77284caa9aca1b3aa", "price_changes": [{"asset_id": "83029595771494657564747548834030842590595300298406079594487838617400032504038", "price": "0.991", "size": "0", "side": "SELL", "hash": "b9c4f083d14d7a9a91ccd921291c88d5e07bd12a", "best_bid": "0.955", "best_ask": "0.957"}, {"asset_id": "106940491396743186324486767673070552626952698856095995665708923002375094057739", "price": "0.009", "size": "0", "side": "BUY", "hash": "6e1ec156db1565fce36c72b3d8bc516f2ee95ab3", "best_bid": "0.043", "best_ask": "0.045"}], "timestamp": "1769384167035", "event_type": "price_change"}}
{"_local_timestamp": "2026-01-25T23:36:08.165177+00:00", "data": {"market": "0xc5c870d2ca29e41ac55e1fac0c7b3c1140eb58fdf26fd2a77284caa9aca1b3aa", "price_changes": [{"asset_id": "83029595771494657564747548834030842590595300298406079594487838617400032504038", "price": "0.99", "size": "66.55", "side": "SELL", "hash": "31b0e641d907f03fa9ffc15ed0fdb26baf2f760d", "best_bid": "0.955", "best_ask": "0.957"}, {"asset_id": "106940491396743186324486767673070552626952698856095995665708923002375094057739", "price": "0.01", "size": "66.55", "side": "BUY", "hash": "8f799c434a6a5e71074a01f4ef8f971595ef5900", "best_bid": "0.043", "best_ask": "0.045"}], "timestamp": "1769384168099", "event_type": "price_change"}}
{"_local_timestamp": "2026-01-25T23:36:12.622661+00:00", "data": {"market": "0xe220ab18b19107b4a06b18a0b5e2a9e9ab4cd7cb297c27cfa05a3369815a1579", "price_changes": [{"asset_id": "29294180043579351070208019085320546351829489739790080999397489613464945007446", "price": "0.17", "size": "735", "side": "BUY", "hash": "38f76e9fc262e14a9f6386a4c583265d5a449a2d", "best_bid": "0.68", "best_ask": "0.77"}, {"asset_id": "43938988181832985104138029041174463994072038957372562854085197368645176157001", "price": "0.83", "size": "735", "side": "SELL", "hash": "d770d75f7588c6f84183fc4b98bf24d66e5850e6", "best_bid": "0.23", "best_ask": "0.32"}], "timestamp": "1769384172558", "event_type": "price_change"}}
{"_local_timestamp": "2026-01-25T23:36:19.708101+00:00", "data": {"market": "0xe220ab18b19107b4a06b18a0b5e2a9e9ab4cd7cb297c27cfa05a3369815a1579", "price_changes": [{"asset_id": "29294180043579351070208019085320546351829489739790080999397489613464945007446", "price": "0.01", "size": "12038.4", "side": "BUY", "hash": "56c27e372a7f434cc28067d79167ad50cd909d53", "best_bid": "0.68", "best_ask": "0.77"}, {"asset_id": "43938988181832985104138029041174463994072038957372562854085197368645176157001", "price": "0.99", "size": "12038.4", "side": "SELL", "hash": "0077e88d9b34270ec27f5e0b7fb70f99e809686b", "best_bid": "0.23", "best_ask": "0.32"}], "timestamp": "1769384179638", "event_type": "price_change"}}
{"_local_timestamp": "2026-01-25T23:36:19.709838+00:00", "data": {"market": "0xe220ab18b19107b4a06b18a0b5e2a9e9ab4cd7cb297c27cfa05a3369815a1579", "price_changes": [{"asset_id": "29294180043579351070208019085320546351829489739790080999397489613464945007446", "price": "0.03", "size": "4016", "side": "BUY", "hash": "56c27e372a7f434cc28067d79167ad50cd909d53", "best_bid": "0.68", "best_ask": "0.77"}, {"asset_id": "43938988181832985104138029041174463994072038957372562854085197368645176157001", "price": "0.97", "size": "4016", "side": "SELL", "hash": "0077e88d9b34270ec27f5e0b7fb70f99e809686b", "best_bid": "0.23", "best_ask": "0.32"}], "timestamp": "1769384179638", "event_type": "price_change"}}
{"_local_timestamp": "2026-01-25T23:36:19.710608+00:00", "data": {"market": "0xe220ab18b19107b4a06b18a0b5e2a9e9ab4cd7cb297c27cfa05a3369815a1579", "price_changes": [{"asset_id": "29294180043579351070208019085320546351829489739790080999397489613464945007446", "price": "0.07", "size": "1642", "side": "BUY", "hash": "56c27e372a7f434cc28067d79167ad50cd909d53", "best_bid": "0.68", "best_ask": "0.77"}, {"asset_id": "43938988181832985104138029041174463994072038957372562854085197368645176157001", "price": "0.93", "size": "1642", "side": "SELL", "hash": "0077e88d9b34270ec27f5e0b7fb70f99e809686b", "best_bid": "0.23", "best_ask": "0.32"}], "timestamp": "1769384179638", "event_type": "price_change"}}
{"_local_timestamp": "2026-01-25T23:36:22.765956+00:00", "data": {"market": "0xe220ab18b19107b4a06b18a0b5e2a9e9ab4cd7cb297c27cfa05a3369815a1579", "price_changes": [{"asset_id": "29294180043579351070208019085320546351829489739790080999397489613464945007446", "price": "0.17", "size": "1135", "side": "BUY", "hash": "87435fffd6e7119351fc1b5b6e3769a25a2222c5", "best_bid": "0.68", "best_ask": "0.77"}, {"asset_id": "43938988181832985104138029041174463994072038957372562854085197368645176157001", "price": "0.83", "size": "1135", "side": "SELL", "hash": "62f08972863fdc3b4f9bad47f483c043dd50ccaf", "best_bid": "0.23", "best_ask": "0.32"}], "timestamp": "1769384182701", "event_type": "price_change"}}
{"_local_timestamp": "2026-01-25T23:36:26.852534+00:00", "data": {"market": "0x9a991a29bbb2bb8118237815223c4b906328b7e8a373aa97fdae409a025470dc", "price_changes": [{"asset_id": "68257431892288883729500648109357161057886471290823106810192273382603520923445", "price": "0.23", "size": "2025.99", "side": "BUY", "hash": "ba41fdb10d060f9a6e409700ab9dcb6a6bb023d5", "best_bid": "0.81", "best_ask": "0.9"}, {"asset_id": "108210708594024455543283956523953124001017416937788990111411478336430517420393", "price": "0.77", "size": "2025.99", "side": "SELL", "hash": "b350886841e152268afc82bed63482a86edb0e13", "best_bid": "0.1", "best_ask": "0.19"}], "timestamp": "1769384186785", "event_type": "price_change"}}
{"_local_timestamp": "2026-01-25T23:36:28.573551+00:00", "data": {"market": "0x9a991a29bbb2bb8118237815223c4b906328b7e8a373aa97fdae409a025470dc", "price_changes": [{"asset_id": "108210708594024455543283956523953124001017416937788990111411478336430517420393", "price": "0.77", "size": "1926", "side": "SELL", "hash": "454fbeeded61b0364f11c5c8c9741dfc3617d8e8", "best_bid": "0.1", "best_ask": "0.19"}, {"asset_id": "68257431892288883729500648109357161057886471290823106810192273382603520923445", "price": "0.23", "size": "1926", "side": "BUY", "hash": "3fbba053fef7f01d05f84931cca195c422afdff7", "best_bid": "0.81", "best_ask": "0.9"}], "timestamp": "1769384188490", "event_type": "price_change"}}
{"_local_timestamp": "2026-01-25T23:36:28.961622+00:00", "data": {"market": "0xc5c870d2ca29e41ac55e1fac0c7b3c1140eb58fdf26fd2a77284caa9aca1b3aa", "price_changes": [{"asset_id": "106940491396743186324486767673070552626952698856095995665708923002375094057739", "price": "0.003", "size": "10.86", "side": "BUY", "hash": "bf137236c9c16adcce873a94948606f67d239e41", "best_bid": "0.043", "best_ask": "0.045"}, {"asset_id": "83029595771494657564747548834030842590595300298406079594487838617400032504038", "price": "0.997", "size": "10.86", "side": "SELL", "hash": "d7fd9f6f5d757f6dec8cf7bedeb2a30b6e551912", "best_bid": "0.955", "best_ask": "0.957"}], "timestamp": "1769384188848", "event_type": "price_change"}}
{"_local_timestamp": "2026-01-25T23:36:28.973568+00:00", "data": {"market": "0x9a991a29bbb2bb8118237815223c4b906328b7e8a373aa97fdae409a025470dc", "price_changes": [{"asset_id": "108210708594024455543283956523953124001017416937788990111411478336430517420393", "price": "0.1", "size": "0", "side": "BUY", "hash": "c1bdda89b2fa48e2f4d0d80bf968a9bcf06824e2", "best_bid": "0.07", "best_ask": "0.19"}, {"asset_id": "68257431892288883729500648109357161057886471290823106810192273382603520923445", "price": "0.9", "size": "0", "side": "SELL", "hash": "d4c893f3f5d2650695ce8b89fb7af68a6c18edb4", "best_bid": "0.81", "best_ask": "0.93"}], "timestamp": "1769384188849", "event_type": "price_change"}}
{"_local_timestamp": "2026-01-25T23:36:29.018831+00:00", "data": {"market": "0x9a991a29bbb2bb8118237815223c4b906328b7e8a373aa97fdae409a025470dc", "price_changes": [{"asset_id": "108210708594024455543283956523953124001017416937788990111411478336430517420393", "price": "0.76", "size": "99.99", "side": "SELL", "hash": "46720d4b5d43fd59835829907f7a39205cc2e5c2", "best_bid": "0.07", "best_ask": "0.19"}, {"asset_id": "68257431892288883729500648109357161057886471290823106810192273382603520923445", "price": "0.24", "size": "99.99", "side": "BUY", "hash": "da457024482f95d6dd1514f3a7e899c393fd4523", "best_bid": "0.81", "best_ask": "0.93"}], "timestamp": "1769384188909", "event_type": "price_change"}}
{"_local_timestamp": "2026-01-25T23:36:29.042365+00:00", "data": {"market": "0x9a991a29bbb2bb8118237815223c4b906328b7e8a373aa97fdae409a025470dc", "price_changes": [{"asset_id": "68257431892288883729500648109357161057886471290823106810192273382603520923445", "price": "0.23", "size": "1826", "side": "BUY", "hash": "853657785ffc90c4a421af6b0f29b37637f33a0d", "best_bid": "0.81", "best_ask": "0.93"}, {"asset_id": "108210708594024455543283956523953124001017416937788990111411478336430517420393", "price": "0.77", "size": "1826", "side": "SELL", "hash": "b5ca6e80668105e4d2efe59d974b58ab4ff5ffef", "best_bid": "0.07", "best_ask": "0.19"}], "timestamp": "1769384188922", "event_type": "price_change"}}
{"_local_timestamp": "2026-01-25T23:36:29.333770+00:00", "data": {"market": "0x9a991a29bbb2bb8118237815223c4b906328b7e8a373aa97fdae409a025470dc", "price_changes": [{"asset_id": "108210708594024455543283956523953124001017416937788990111411478336430517420393", "price": "0.07", "size": "218.98", "side": "BUY", "hash": "41a42fd665619fa027b5e7fd93403079ebdf44de", "best_bid": "0.07", "best_ask": "0.19"}, {"asset_id": "68257431892288883729500648109357161057886471290823106810192273382603520923445", "price": "0.93", "size": "218.98", "side": "SELL", "hash": "aa8b349f75b7e288be3f9db93c49444acf9b448a", "best_bid": "0.81", "best_ask": "0.93"}], "timestamp": "1769384189265", "event_type": "price_change"}}
{"_local_timestamp": "2026-01-25T23:36:29.618084+00:00", "data": {"market": "0x9a991a29bbb2bb8118237815223c4b906328b7e8a373aa97fdae409a025470dc", "price_changes": [{"asset_id": "68257431892288883729500648109357161057886471290823106810192273382603520923445", "price": "0.24", "size": "199.99", "side": "BUY", "hash": "36fa4ee1985374854b7073c42aa8bbd7a8f201ed", "best_bid": "0.81", "best_ask": "0.93"}, {"asset_id": "108210708594024455543283956523953124001017416937788990111411478336430517420393", "price": "0.76", "size": "199.99", "side": "SELL", "hash": "2d0998c210e48e5d21cf872a44fa6b50618727b2", "best_bid": "0.07", "best_ask": "0.19"}], "timestamp": "1769384189528", "event_type": "price_change"}}
{"_local_timestamp": "2026-01-25T23:36:30.764611+00:00", "data": {"market": "0x9a991a29bbb2bb8118237815223c4b906328b7e8a373aa97fdae409a025470dc", "price_changes": [{"asset_id": "108210708594024455543283956523953124001017416937788990111411478336430517420393", "price": "0.08", "size": "112", "side": "BUY", "hash": "833d17bc6c2da19e6c71c73b8d9ff3a4aa5a07e5", "best_bid": "0.08", "best_ask": "0.19"}, {"asset_id": "68257431892288883729500648109357161057886471290823106810192273382603520923445", "price": "0.92", "size": "112", "side": "SELL", "hash": "a00b30ca03d0f467e3078f2b10c372bf669efd4b", "best_bid": "0.81", "best_ask": "0.92"}], "timestamp": "1769384190689", "event_type": "price_change"}}
{"_local_timestamp": "2026-01-25T23:36:30.897032+00:00", "data": {"market": "0x9a991a29bbb2bb8118237815223c4b906328b7e8a373aa97fdae409a025470dc", "price_changes": [{"asset_id": "108210708594024455543283956523953124001017416937788990111411478336430517420393", "price": "0.07", "size": "188.98", "side": "BUY", "hash": "4eb13d9e9eaf08e811490b894581ca7befa47894", "best_bid": "0.08", "best_ask": "0.19"}, {"asset_id": "68257431892288883729500648109357161057886471290823106810192273382603520923445", "price": "0.93", "size": "188.98", "side": "SELL", "hash": "44958806eafc53363bddb270bf87596e33c6409f", "best_bid": "0.81", "best_ask": "0.92"}], "timestamp": "1769384190830", "event_type": "price_change"}}
{"_local_timestamp": "2026-01-25T23:36:30.965124+00:00", "data": {"market": "0x9a991a29bbb2bb8118237815223c4b906328b7e8a373aa97fdae409a025470dc", "price_changes": [{"asset_id": "108210708594024455543283956523953124001017416937788990111411478336430517420393", "price": "0.08", "size": "142", "side": "BUY", "hash": "b34911f0040af07d9198487328cdb079995e0f93", "best_bid": "0.08", "best_ask": "0.19"}, {"asset_id": "68257431892288883729500648109357161057886471290823106810192273382603520923445", "price": "0.92", "size": "142", "side": "SELL", "hash": "8aeaf4afad10efd504fb6f1f9e0dbd79e77e4f69", "best_bid": "0.81", "best_ask": "0.92"}], "timestamp": "1769384190895", "event_type": "price_change"}}
{"_local_timestamp": "2026-01-25T23:36:31.132242+00:00", "data": {"market": "0xe220ab18b19107b4a06b18a0b5e2a9e9ab4cd7cb297c27cfa05a3369815a1579", "price_changes": [{"asset_id": "43938988181832985104138029041174463994072038957372562854085197368645176157001", "price": "0.17", "size": "62", "side": "BUY", "hash": "2ed282e36a3424f9eb920d55170f2464306b8a96", "best_bid": "0.23", "best_ask": "0.32"}, {"asset_id": "29294180043579351070208019085320546351829489739790080999397489613464945007446", "price": "0.83", "size": "62", "side": "SELL", "hash": "5f4f5af1741078db1d57892b3a0ffe68a3354b24", "best_bid": "0.68", "best_ask": "0.77"}], "timestamp": "1769384191041", "event_type": "price_change"}}
{"_local_timestamp": "2026-01-25T23:36:32.923666+00:00", "data": {"market": "0x9a991a29bbb2bb8118237815223c4b906328b7e8a373aa97fdae409a025470dc", "price_changes": [{"asset_id": "68257431892288883729500648109357161057886471290823106810192273382603520923445", "price": "0.93", "size": "110", "side": "SELL", "hash": "7a46071a2984d33a2fa35118320f785164a0efa6", "best_bid": "0.81", "best_ask": "0.92"}, {"asset_id": "108210708594024455543283956523953124001017416937788990111411478336430517420393", "price": "0.07", "size": "110", "side": "BUY", "hash": "33a887c804ef41a602b0a30e7a09e8e3b2b508b5", "best_bid": "0.08", "best_ask": "0.19"}], "timestamp": "1769384192849", "event_type": "price_change"}}
{"_local_timestamp": "2026-01-25T23:36:33.329510+00:00", "data": {"market": "0x9a991a29bbb2bb8118237815223c4b906328b7e8a373aa97fdae409a025470dc", "price_changes": [{"asset_id": "68257431892288883729500648109357161057886471290823106810192273382603520923445", "price": "0.91", "size": "78.98", "side": "SELL", "hash": "90120201cc02eecce828c8a4d13de4592ef94f6d", "best_bid": "0.81", "best_ask": "0.91"}, {"asset_id": "108210708594024455543283956523953124001017416937788990111411478336430517420393", "price": "0.09", "size": "78.98", "side": "BUY", "hash": "d5033ca67214d5eb89b6c13c1806a5e2f49fc395", "best_bid": "0.09", "best_ask": "0.19"}], "timestamp": "1769384193249", "event_type": "price_change"}}
{"_local_timestamp": "2026-01-25T23:36:33.372135+00:00", "data": {"market": "0x9a991a29bbb2bb8118237815223c4b906328b7e8a373aa97fdae409a025470dc", "price_changes": [{"asset_id": "108210708594024455543283956523953124001017416937788990111411478336430517420393", "price": "0.07", "size": "10", "side": "BUY", "hash": "72b2501e21626739c49a4d9b47857536ef222181", "best_bid": "0.09", "best_ask": "0.19"}, {"asset_id": "68257431892288883729500648109357161057886471290823106810192273382603520923445", "price": "0.93", "size": "10", "side": "SELL", "hash": "182c97ad855849216de882329979ee5ee4b922dc", "best_bid": "0.81", "best_ask": "0.91"}], "timestamp": "1769384193285", "event_type": "price_change"}}
{"_local_timestamp": "2026-01-25T23:36:34.076938+00:00", "data": {"market": "0x9a991a29bbb2bb8118237815223c4b906328b7e8a373aa97fdae409a025470dc", "price_changes": [{"asset_id": "108210708594024455543283956523953124001017416937788990111411478336430517420393", "price": "0.09", "size": "178.98", "side": "BUY", "hash": "c9f64ef5f17cf554d562ac32923dfaa0bc8c8c47", "best_bid": "0.09", "best_ask": "0.19"}, {"asset_id": "68257431892288883729500648109357161057886471290823106810192273382603520923445", "price": "0.91", "size": "178.98", "side": "SELL", "hash": "08bf069171afc49037f5e59191edd0405812d8f1", "best_bid": "0.81", "best_ask": "0.91"}], "timestamp": "1769384194002", "event_type": "price_change"}}
{"_local_timestamp": "2026-01-25T23:36:34.327732+00:00", "data": {"market": "0x9a991a29bbb2bb8118237815223c4b906328b7e8a373aa97fdae409a025470dc", "price_changes": [{"asset_id": "108210708594024455543283956523953124001017416937788990111411478336430517420393", "price": "0.08", "size": "112", "side": "BUY", "hash": "6346cfa83783a9f9d0e1b418de2d2dcfdefbdd05", "best_bid": "0.09", "best_ask": "0.19"}, {"asset_id": "68257431892288883729500648109357161057886471290823106810192273382603520923445", "price": "0.92", "size": "112", "side": "SELL", "hash": "665937f584e2b9fb3077253009e79daff38cfc1d", "best_bid": "0.81", "best_ask": "0.91"}], "timestamp": "1769384194254", "event_type": "price_change"}}
{"_local_timestamp": "2026-01-25T23:36:34.405015+00:00", "data": {"market": "0x9a991a29bbb2bb8118237815223c4b906328b7e8a373aa97fdae409a025470dc", "price_changes": [{"asset_id": "108210708594024455543283956523953124001017416937788990111411478336430517420393", "price": "0.09", "size": "208.98", "side": "BUY", "hash": "1420ef9842ff2fb23d83722a9a6a1bdfcbbcb1c7", "best_bid": "0.09", "best_ask": "0.19"}, {"asset_id": "68257431892288883729500648109357161057886471290823106810192273382603520923445", "price": "0.91", "size": "208.98", "side": "SELL", "hash": "3131ce95b27016080e39b5640c05f2cdc1a26e5a", "best_bid": "0.81", "best_ask": "0.91"}], "timestamp": "1769384194340", "event_type": "price_change"}}
{"_local_timestamp": "2026-01-25T23:36:35.990932+00:00", "data": {"market": "0x9a991a29bbb2bb8118237815223c4b906328b7e8a373aa97fdae409a025470dc", "price_changes": [{"asset_id": "108210708594024455543283956523953124001017416937788990111411478336430517420393", "price": "0.09", "size": "178.98", "side": "BUY", "hash": "b475ad97d654d7a33b42713efd1f37aac45085a9", "best_bid": "0.09", "best_ask": "0.19"}, {"asset_id": "68257431892288883729500648109357161057886471290823106810192273382603520923445", "price": "0.91", "size": "178.98", "side": "SELL", "hash": "8e7090530154f7ac6d981d7c9b6385e51d15ced6", "best_bid": "0.81", "best_ask": "0.91"}], "timestamp": "1769384195920", "event_type": "price_change"}}
{"_local_timestamp": "2026-01-25T23:36:36.046359+00:00", "data": {"market": "0x9a991a29bbb2bb8118237815223c4b906328b7e8a373aa97fdae409a025470dc", "price_changes": [{"asset_id": "108210708594024455543283956523953124001017416937788990111411478336430517420393", "price": "0.1", "size": "30", "side": "BUY", "hash": "5b560aa778a3c0ea263fe5cc7cf09ac747de7666", "best_bid": "0.1", "best_ask": "0.19"}, {"asset_id": "68257431892288883729500648109357161057886471290823106810192273382603520923445", "price": "0.9", "size": "30", "side": "SELL", "hash": "0b07e825373bb3d6a71a5050d2581194a1cd3dc4", "best_bid": "0.81", "best_ask": "0.9"}], "timestamp": "1769384195976", "event_type": "price_change"}}
{"_local_timestamp": "2026-01-25T23:36:36.318529+00:00", "data": {"market": "0xe220ab18b19107b4a06b18a0b5e2a9e9ab4cd7cb297c27cfa05a3369815a1579", "price_changes": [{"asset_id": "29294180043579351070208019085320546351829489739790080999397489613464945007446", "price": "0.01", "size": "17038.4", "side": "BUY", "hash": "9a191dfa27cb2b4071eeb43522bf3861f66394ff", "best_bid": "0.68", "best_ask": "0.77"}, {"asset_id": "43938988181832985104138029041174463994072038957372562854085197368645176157001", "price": "0.99", "size": "17038.4", "side": "SELL", "hash": "f58c36d915a50092b81951e0c5aa537a55490927", "best_bid": "0.23", "best_ask": "0.32"}], "timestamp": "1769384196245", "event_type": "price_change"}}
{"_local_timestamp": "2026-01-25T23:36:36.330602+00:00", "data": {"market": "0xe220ab18b19107b4a06b18a0b5e2a9e9ab4cd7cb297c27cfa05a3369815a1579", "price_changes": [{"asset_id": "29294180043579351070208019085320546351829489739790080999397489613464945007446", "price": "0.03", "size": "6016", "side": "BUY", "hash": "510eff84e8cac2c20bdfec009fb94d7ee04785e0", "best_bid": "0.68", "best_ask": "0.77"}, {"asset_id": "43938988181832985104138029041174463994072038957372562854085197368645176157001", "price": "0.97", "size": "6016", "side": "SELL", "hash": "45b1e4a954d64b885cf8d63672475926fc574101", "best_bid": "0.23", "best_ask": "0.32"}], "timestamp": "1769384196245", "event_type": "price_change"}}
{"_local_timestamp": "2026-01-25T23:36:36.331370+00:00", "data": {"market": "0xe220ab18b19107b4a06b18a0b5e2a9e9ab4cd7cb297c27cfa05a3369815a1579", "price_changes": [{"asset_id": "29294180043579351070208019085320546351829489739790080999397489613464945007446", "price": "0.07", "size": "2642", "side": "BUY", "hash": "025ef289978a96d20123200f9150c44c9ab6383c", "best_bid": "0.68", "best_ask": "0.77"}, {"asset_id": "43938988181832985104138029041174463994072038957372562854085197368645176157001", "price": "0.93", "size": "2642", "side": "SELL", "hash": "50343c611ce5a8f63e2231308ad99a632dcd9d69", "best_bid": "0.23", "best_ask": "0.32"}], "timestamp": "1769384196246", "event_type": "price_change"}}
{"_local_timestamp": "2026-01-25T23:36:36.416703+00:00", "data": {"market": "0x34c320af835b2d4b56224618b9930e3a6b26ed7f6854c4f8ce04b35f6d3ee801", "price_changes": [{"asset_id": "21965236637806877423690456379421697078490533519739537235259143695240300903846", "price": "0.002", "size": "25", "side": "BUY", "hash": "c40e45d9e29dedbf074eeff60c46dcec8040aa50", "best_bid": "0.097", "best_ask": "0.147"}, {"asset_id": "31278264626330879886341915760798723117251320102541744661396613642093503516942", "price": "0.998", "size": "25", "side": "SELL", "hash": "9573f96b78d71835c715805090b0b32edbace91d", "best_bid": "0.853", "best_ask": "0.903"}], "timestamp": "1769384196345", "event_type": "price_change"}}
{"_local_timestamp": "2026-01-25T23:36:36.630458+00:00", "data": {"market": "0x34c320af835b2d4b56224618b9930e3a6b26ed7f6854c4f8ce04b35f6d3ee801", "price_changes": [{"asset_id": "21965236637806877423690456379421697078490533519739537235259143695240300903846", "price": "0.002", "size": "62.48", "side": "BUY", "hash": "341de2881bffb1d87a63ccb84f5e19c75ae0506b", "best_bid": "0.097", "best_ask": "0.147"}, {"asset_id": "31278264626330879886341915760798723117251320102541744661396613642093503516942", "price": "0.998", "size": "62.48", "side": "SELL", "hash": "8aa94d838728d9a0f7e0d2decf1468c95a741aa1", "best_bid": "0.853", "best_ask": "0.903"}], "timestamp": "1769384196556", "event_type": "price_change"}}
{"_local_timestamp": "2026-01-25T23:36:51.742833+00:00", "data": {"market": "0x680784812145063cecedfa7f000654e89317e2aca612182884d7742ac6f801f9", "price_changes": [{"asset_id": "76179285001548801832051437870901871012966717962774017789970710364900180173602", "price": "0.02", "size": "2025", "side": "BUY", "hash": "a5c84f9db4815f67245d650c7e30c4d689cee1f2", "best_bid": "0.19", "best_ask": "0.22"}, {"asset_id": "60410997855954556286106048831701517763027421942281960711866162404690269293947", "price": "0.98", "size": "2025", "side": "SELL", "hash": "08694e257bd6943b19fefb852293ea2f3197d43d", "best_bid": "0.78", "best_ask": "0.81"}], "timestamp": "1769384211671", "event_type": "price_change"}}
{"_local_timestamp": "2026-01-25T23:36:51.743721+00:00", "data": {"market": "0x9a991a29bbb2bb8118237815223c4b906328b7e8a373aa97fdae409a025470dc", "price_changes": [{"asset_id": "108210708594024455543283956523953124001017416937788990111411478336430517420393", "price": "0.02", "size": "25", "side": "BUY", "hash": "fc243433e861e5e08dd0fffa0c447e02656c6c5a", "best_bid": "0.1", "best_ask": "0.19"}, {"asset_id": "68257431892288883729500648109357161057886471290823106810192273382603520923445", "price": "0.98", "size": "25", "side": "SELL", "hash": "3c531a6b18791f3d170020588db9acc7bf35c4ba", "best_bid": "0.81", "best_ask": "0.9"}], "timestamp": "1769384211671", "event_type": "price_change"}}
{"_local_timestamp": "2026-01-25T23:36:52.014570+00:00", "data": {"market": "0x9a991a29bbb2bb8118237815223c4b906328b7e8a373aa97fdae409a025470dc", "price_changes": [{"asset_id": "108210708594024455543283956523953124001017416937788990111411478336430517420393", "price": "0.02", "size": "36.47", "side": "BUY", "hash": "5c160363eac18cbedf06f93fbb8085fc36e73c9d", "best_bid": "0.1", "best_ask": "0.19"}, {"asset_id": "68257431892288883729500648109357161057886471290823106810192273382603520923445", "price": "0.98", "size": "36.47", "side": "SELL", "hash": "38e783ada347e4879a8d86fd9151c12d76c8d0f6", "best_bid": "0.81", "best_ask": "0.9"}], "timestamp": "1769384211948", "event_type": "price_change"}}
{"_local_timestamp": "2026-01-25T23:36:52.015416+00:00", "data": {"market": "0x680784812145063cecedfa7f000654e89317e2aca612182884d7742ac6f801f9", "price_changes": [{"asset_id": "76179285001548801832051437870901871012966717962774017789970710364900180173602", "price": "0.02", "size": "2036.47", "side": "BUY", "hash": "0bf480309cb21314c37ac3e806847011fa7f6ceb", "best_bid": "0.19", "best_ask": "0.22"}, {"asset_id": "60410997855954556286106048831701517763027421942281960711866162404690269293947", "price": "0.98", "size": "2036.47", "side": "SELL", "hash": "36c68eb7647919b747fcf71201c09dbb09b7f217", "best_bid": "0.78", "best_ask": "0.81"}], "timestamp": "1769384211948", "event_type": "price_change"}}
{"_local_timestamp": "2026-01-25T23:36:52.750923+00:00", "data": {"market": "0xe220ab18b19107b4a06b18a0b5e2a9e9ab4cd7cb297c27cfa05a3369815a1579", "price_changes": [{"asset_id": "29294180043579351070208019085320546351829489739790080999397489613464945007446", "price": "0.18", "size": "2332", "side": "BUY", "hash": "e37b94e1685d146d23903378c4b69f034388a3cd", "best_bid": "0.68", "best_ask": "0.77"}, {"asset_id": "43938988181832985104138029041174463994072038957372562854085197368645176157001", "price": "0.82", "size": "2332", "side": "SELL", "hash": "afc41125f73a1be48075a987890c629b68e8fc97", "best_bid": "0.23", "best_ask": "0.32"}], "timestamp": "1769384212680", "event_type": "price_change"}}
{"_local_timestamp": "2026-01-25T23:36:52.792716+00:00", "data": {"market": "0x680784812145063cecedfa7f000654e89317e2aca612182884d7742ac6f801f9", "price_changes": [{"asset_id": "60410997855954556286106048831701517763027421942281960711866162404690269293947", "price": "0.13", "size": "3230", "side": "BUY", "hash": "eb5c9af4e6e6959e813d60444857b2770ed8ee99", "best_bid": "0.78", "best_ask": "0.81"}, {"asset_id": "76179285001548801832051437870901871012966717962774017789970710364900180173602", "price": "0.87", "size": "3230", "side": "SELL", "hash": "2dc0e99067f1ccc8732f0c7a827e2a84a985bf8e", "best_bid": "0.19", "best_ask": "0.22"}], "timestamp": "1769384212728", "event_type": "price_change"}}
{"_local_timestamp": "2026-01-25T23:36:56.266183+00:00", "data": {"market": "0x7bc1d3c8aaf0a20c853f576519446e1ee260e65d43205efd61696f3a9f9e62e7", "price_changes": [{"asset_id": "10966407605514195233392457845926539733586231163297093857244655359507639639996", "price": "0.003", "size": "16.49", "side": "BUY", "hash": "593aad8d4b67b5e7785a04061e4ed74c6b88828b", "best_bid": "0.005", "best_ask": "0.084"}, {"asset_id": "74853086974054252708530367393532530785660539289108031053683362073748574770022", "price": "0.997", "size": "16.49", "side": "SELL", "hash": "cf05a6e1c470ca3e2bf39adc0865503791ab5cc6", "best_bid": "0.916", "best_ask": "0.995"}], "timestamp": "1769384215843", "event_type": "price_change"}}
{"_local_timestamp": "2026-01-25T23:36:56.442865+00:00", "data": {"market": "0x7bc1d3c8aaf0a20c853f576519446e1ee260e65d43205efd61696f3a9f9e62e7", "price_changes": [{"asset_id": "10966407605514195233392457845926539733586231163297093857244655359507639639996", "price": "0.003", "size": "25.95", "side": "BUY", "hash": "6ca27d23edf2bd8750b418f544e72cfcd2efb7c6", "best_bid": "0.005", "best_ask": "0.084"}, {"asset_id": "74853086974054252708530367393532530785660539289108031053683362073748574770022", "price": "0.997", "size": "25.95", "side": "SELL", "hash": "a1a53773529fcf5c188a3708f147ac46a43a890f", "best_bid": "0.916", "best_ask": "0.995"}], "timestamp": "1769384216113", "event_type": "price_change"}}
{"_local_timestamp": "2026-01-25T23:36:57.350371+00:00", "data": {"market": "0x680784812145063cecedfa7f000654e89317e2aca612182884d7742ac6f801f9", "price_changes": [{"asset_id": "60410997855954556286106048831701517763027421942281960711866162404690269293947", "price": "0.24", "size": "0", "side": "BUY", "hash": "29b63838b3318630601a49bcf2f8a762e2693291", "best_bid": "0.78", "best_ask": "0.81"}, {"asset_id": "76179285001548801832051437870901871012966717962774017789970710364900180173602", "price": "0.76", "size": "0", "side": "SELL", "hash": "f647ab38eb8a68ea35c2701b9bf0fe24308e45e7", "best_bid": "0.19", "best_ask": "0.22"}], "timestamp": "1769384217222", "event_type": "price_change"}}
{"_local_timestamp": "2026-01-25T23:36:57.594955+00:00", "data": {"market": "0xe220ab18b19107b4a06b18a0b5e2a9e9ab4cd7cb297c27cfa05a3369815a1579", "price_changes": [{"asset_id": "29294180043579351070208019085320546351829489739790080999397489613464945007446", "price": "0.21", "size": "50", "side": "BUY", "hash": "2db074dd661e74996bc5ca39a745fe5e034b31f1", "best_bid": "0.68", "best_ask": "0.77"}, {"asset_id": "43938988181832985104138029041174463994072038957372562854085197368645176157001", "price": "0.79", "size": "50", "side": "SELL", "hash": "33ef20d663a54fdeab5b124999855b7caa84b54c", "best_bid": "0.23", "best_ask": "0.32"}], "timestamp": "1769384217233", "event_type": "price_change"}}
{"_local_timestamp": "2026-01-25T23:36:57.661502+00:00", "data": {"market": "0x9a991a29bbb2bb8118237815223c4b906328b7e8a373aa97fdae409a025470dc", "price_changes": [{"asset_id": "68257431892288883729500648109357161057886471290823106810192273382603520923445", "price": "0.3", "size": "75", "side": "BUY", "hash": "47b77b17fe8737b18eada261b1a32bd81fc1d301", "best_bid": "0.81", "best_ask": "0.9"}, {"asset_id": "108210708594024455543283956523953124001017416937788990111411478336430517420393", "price": "0.7", "size": "75", "side": "SELL", "hash": "cafa27d84adc3875c7ec31c003b985987acc3e44", "best_bid": "0.1", "best_ask": "0.19"}], "timestamp": "1769384217237", "event_type": "price_change"}}
{"_local_timestamp": "2026-01-25T23:36:57.774456+00:00", "data": {"market": "0x34c320af835b2d4b56224618b9930e3a6b26ed7f6854c4f8ce04b35f6d3ee801", "price_changes": [{"asset_id": "31278264626330879886341915760798723117251320102541744661396613642093503516942", "price": "0.253", "size": "0", "side": "BUY", "hash": "b94c8e0b216b4a24d2fa612d75928f65aff877df", "best_bid": "0.853", "best_ask": "0.903"}, {"asset_id": "21965236637806877423690456379421697078490533519739537235259143695240300903846", "price": "0.747", "size": "0", "side": "SELL", "hash": "3f27308e322faca1164c9c48452919f7f66b8366", "best_bid": "0.097", "best_ask": "0.147"}], "timestamp": "1769384217247", "event_type": "price_change"}}
{"_local_timestamp": "2026-01-25T23:36:59.706185+00:00", "data": {"market": "0x680784812145063cecedfa7f000654e89317e2aca612182884d7742ac6f801f9", "price_changes": [{"asset_id": "60410997855954556286106048831701517763027421942281960711866162404690269293947", "price": "0.28", "size": "0", "side": "BUY", "hash": "14c4aa855c0a57a7d18cc650335a3a98f0248b99", "best_bid": "0.78", "best_ask": "0.81"}, {"asset_id": "76179285001548801832051437870901871012966717962774017789970710364900180173602", "price": "0.72", "size": "0", "side": "SELL", "hash": "5ee5555b0d471f31383d8d5a8483223bbe5b5e9f", "best_bid": "0.19", "best_ask": "0.22"}], "timestamp": "1769384219627", "event_type": "price_change"}}
{"_local_timestamp": "2026-01-25T23:37:00.458472+00:00", "data": {"market": "0x680784812145063cecedfa7f000654e89317e2aca612182884d7742ac6f801f9", "price_changes": [{"asset_id": "60410997855954556286106048831701517763027421942281960711866162404690269293947", "price": "0.17", "size": "91.87", "side": "BUY", "hash": "56459e7bdad5934922c6542440c1e177389fd3c2", "best_bid": "0.78", "best_ask": "0.81"}, {"asset_id": "76179285001548801832051437870901871012966717962774017789970710364900180173602", "price": "0.83", "size": "91.87", "side": "SELL", "hash": "a45e96e65974933aefc7854f0f1ac92019fe9f53", "best_bid": "0.19", "best_ask": "0.22"}], "timestamp": "1769384220393", "event_type": "price_change"}}
{"_local_timestamp": "2026-01-25T23:37:15.023404+00:00", "data": {"market": "0xe220ab18b19107b4a06b18a0b5e2a9e9ab4cd7cb297c27cfa05a3369815a1579", "price_changes": [{"asset_id": "29294180043579351070208019085320546351829489739790080999397489613464945007446", "price": "0.17", "size": "635", "side": "BUY", "hash": "9b70b373b6029f91455efcc5d4f94f5e8a131e7d", "best_bid": "0.68", "best_ask": "0.77"}, {"asset_id": "43938988181832985104138029041174463994072038957372562854085197368645176157001", "price": "0.83", "size": "635", "side": "SELL", "hash": "7303c8a348221d290b85d608015cc82c38927001", "best_bid": "0.23", "best_ask": "0.32"}], "timestamp": "1769384234933", "event_type": "price_change"}}
{"_local_timestamp": "2026-01-25T23:37:15.024237+00:00", "data": {"market": "0x680784812145063cecedfa7f000654e89317e2aca612182884d7742ac6f801f9", "price_changes": [{"asset_id": "60410997855954556286106048831701517763027421942281960711866162404690269293947", "price": "0.08", "size": "4500", "side": "BUY", "hash": "ddc45be299e409bc5334f476eabd4d8fb5a385c0", "best_bid": "0.78", "best_ask": "0.81"}, {"asset_id": "76179285001548801832051437870901871012966717962774017789970710364900180173602", "price": "0.92", "size": "4500", "side": "SELL", "hash": "58ec1f2ae238f49df8a28afba43431ea8aed4e82", "best_bid": "0.19", "best_ask": "0.22"}], "timestamp": "1769384234934", "event_type": "price_change"}}
{"_local_timestamp": "2026-01-25T23:37:15.302458+00:00", "data": {"market": "0xe220ab18b19107b4a06b18a0b5e2a9e9ab4cd7cb297c27cfa05a3369815a1579", "price_changes": [{"asset_id": "29294180043579351070208019085320546351829489739790080999397489613464945007446", "price": "0.18", "size": "2832", "side": "BUY", "hash": "a112389dd81a27bc1122a9961565ed6e7f4d7bee", "best_bid": "0.68", "best_ask": "0.77"}, {"asset_id": "43938988181832985104138029041174463994072038957372562854085197368645176157001", "price": "0.82", "size": "2832", "side": "SELL", "hash": "a65040e97ca22ae881f1ab4fe491ea0180819b8e", "best_bid": "0.23", "best_ask": "0.32"}], "timestamp": "1769384235235", "event_type": "price_change"}}
{"_local_timestamp": "2026-01-25T23:37:15.303392+00:00", "data": {"market": "0x680784812145063cecedfa7f000654e89317e2aca612182884d7742ac6f801f9", "price_changes": [{"asset_id": "60410997855954556286106048831701517763027421942281960711866162404690269293947", "price": "0.13", "size": "3730", "side": "BUY", "hash": "dc5eb7a62c5ce2d95217604962e610718a1688a5", "best_bid": "0.78", "best_ask": "0.81"}, {"asset_id": "76179285001548801832051437870901871012966717962774017789970710364900180173602", "price": "0.87", "size": "3730", "side": "SELL", "hash": "0ca94653bc6c4c75cc15fe77b048a9c2c60ec3a0", "best_bid": "0.19", "best_ask": "0.22"}], "timestamp": "1769384235235", "event_type": "price_change"}}
{"_local_timestamp": "2026-01-25T23:37:23.369099+00:00", "data": {"market": "0x9a991a29bbb2bb8118237815223c4b906328b7e8a373aa97fdae409a025470dc", "price_changes": [{"asset_id": "68257431892288883729500648109357161057886471290823106810192273382603520923445", "price": "0.23", "size": "1925", "side": "BUY", "hash": "4297631e673ec1aa4775e310121c363ab9526abc", "best_bid": "0.81", "best_ask": "0.9"}, {"asset_id": "108210708594024455543283956523953124001017416937788990111411478336430517420393", "price": "0.77", "size": "1925", "side": "SELL", "hash": "691c0a99abe29e0986d27fd1475c5814b41b3c1e", "best_bid": "0.1", "best_ask": "0.19"}], "timestamp": "1769384243296", "event_type": "price_change"}}
{"_local_timestamp": "2026-01-25T23:37:23.370112+00:00", "data": {"market": "0x680784812145063cecedfa7f000654e89317e2aca612182884d7742ac6f801f9", "price_changes": [{"asset_id": "60410997855954556286106048831701517763027421942281960711866162404690269293947", "price": "0.17", "size": "391.87", "side": "BUY", "hash": "64f36ce6d5000838b90545152afc1c28d375dd96", "best_bid": "0.78", "best_ask": "0.81"}, {"asset_id": "76179285001548801832051437870901871012966717962774017789970710364900180173602", "price": "0.83", "size": "391.87", "side": "SELL", "hash": "839871b710fe1f2817cf676874539a8f1fcbefd8", "best_bid": "0.19", "best_ask": "0.22"}], "timestamp": "1769384243297", "event_type": "price_change"}}
{"_local_timestamp": "2026-01-25T23:37:23.372596+00:00", "data": {"market": "0x34c320af835b2d4b56224618b9930e3a6b26ed7f6854c4f8ce04b35f6d3ee801", "price_changes": [{"asset_id": "31278264626330879886341915760798723117251320102541744661396613642093503516942", "price": "0.255", "size": "300", "side": "BUY", "hash": "31ec90ecdbd3af4b7df0d81034ff7fee5b11b060", "best_bid": "0.853", "best_ask": "0.903"}, {"asset_id": "21965236637806877423690456379421697078490533519739537235259143695240300903846", "price": "0.745", "size": "300", "side": "SELL", "hash": "90f3059ce7f289bebd3c5bd2141dca11a9865b8d", "best_bid": "0.097", "best_ask": "0.147"}], "timestamp": "1769384243297", "event_type": "price_change"}}
{"_local_timestamp": "2026-01-25T23:37:23.373387+00:00", "data": {"market": "0xe220ab18b19107b4a06b18a0b5e2a9e9ab4cd7cb297c27cfa05a3369815a1579", "price_changes": [{"asset_id": "29294180043579351070208019085320546351829489739790080999397489613464945007446", "price": "0.23", "size": "300", "side": "BUY", "hash": "26424655209c236e17981376b2ff6e32b9a0ca69", "best_bid": "0.68", "best_ask": "0.77"}, {"asset_id": "43938988181832985104138029041174463994072038957372562854085197368645176157001", "price": "0.77", "size": "300", "side": "SELL", "hash": "472d93c44803b0fde7865111ce5d51c1cf4a940f", "best_bid": "0.23", "best_ask": "0.32"}], "timestamp": "1769384243298", "event_type": "price_change"}}
{"_local_timestamp": "2026-01-25T23:37:25.790804+00:00", "data": {"market": "0x680784812145063cecedfa7f000654e89317e2aca612182884d7742ac6f801f9", "price_changes": [{"asset_id": "60410997855954556286106048831701517763027421942281960711866162404690269293947", "price": "0.17", "size": "300", "side": "BUY", "hash": "7cf440c52bd7a58c94d6348ce1bebe6a55b04110", "best_bid": "0.78", "best_ask": "0.81"}, {"asset_id": "76179285001548801832051437870901871012966717962774017789970710364900180173602", "price": "0.83", "size": "300", "side": "SELL", "hash": "0514860ae55f1340536412adc770cf1be1dbf413", "best_bid": "0.19", "best_ask": "0.22"}], "timestamp": "1769384245723", "event_type": "price_change"}}
{"_local_timestamp": "2026-01-25T23:37:26.458984+00:00", "data": {"market": "0x680784812145063cecedfa7f000654e89317e2aca612182884d7742ac6f801f9", "price_changes": [{"asset_id": "60410997855954556286106048831701517763027421942281960711866162404690269293947", "price": "0.21", "size": "91.87", "side": "BUY", "hash": "2ec1fe842971d63bbb98ac6ca1240eb620341cf2", "best_bid": "0.78", "best_ask": "0.81"}, {"asset_id": "76179285001548801832051437870901871012966717962774017789970710364900180173602", "price": "0.79", "size": "91.87", "side": "SELL", "hash": "42b0b535ebe73aa486ab43f14d555f0621e9200b", "best_bid": "0.19", "best_ask": "0.22"}], "timestamp": "1769384246391", "event_type": "price_change"}}
{"_local_timestamp": "2026-01-25T23:37:28.185741+00:00", "data": {"market": "0xe220ab18b19107b4a06b18a0b5e2a9e9ab4cd7cb297c27cfa05a3369815a1579", "price_changes": [{"asset_id": "29294180043579351070208019085320546351829489739790080999397489613464945007446", "price": "0.17", "size": "235", "side": "BUY", "hash": "d6b3301985aad3b76b97507e8757bea8d596ba18", "best_bid": "0.68", "best_ask": "0.77"}, {"asset_id": "43938988181832985104138029041174463994072038957372562854085197368645176157001", "price": "0.83", "size": "235", "side": "SELL", "hash": "12548c2c62c6d2090ec50a8dbda9ebedf0beee56", "best_bid": "0.23", "best_ask": "0.32"}], "timestamp": "1769384248104", "event_type": "price_change"}}
