{"_local_timestamp": "2026-01-25T23:33:19.069477+00:00", "data": [{"market": "0xf2bf04609e7458df56c9bb4b1e051286dea11da1c944bbc1dafbcc6b76904e52", "asset_id": "105031123790227090351610621121319179238510007553875150023320472711583933704999", "timestamp": "1769383883734", "hash": "7b5f61b26108c8f3a40781ff618af8ef996fa520", "bids": [{"price": "0.01", "size": "3100"}, {"price": "0.02", "size": "1260.57"}, {"price": "0.03", "size": "500"}, {"price": "0.04", "size": "756.99"}, {"price": "0.05", "size": "280"}, {"price": "0.06", "size": "191.66"}, {"price": "0.07", "size": "192.97"}, {"price": "0.08", "size": "74.32"}, {"price": "0.09", "size": "74.32"}, {"price": "0.1", "size": "74.32"}, {"price": "0.11", "size": "1874.32"}, {"price": "0.12", "size": "200"}, {"price": "0.13", "size": "30"}], "asks": [{"price": "0.99", "size": "6109.79"}, {"price": "0.98", "size": "1000"}, {"price": "0.97", "size": "10.2"}, {"price": "0.96", "size": "12"}, {"price": "0.95", "size": "1320"}, {"price": "0.91", "size": "600"}, {"price": "0.9", "size": "1700"}, {"price": "0.89", "size": "5.41"}, {"price": "0.87", "size": "586.53"}, {"price": "0.86", "size": "5"}, {"price": "0.82", "size": "427.77"}, {"price": "0.79", "size": "5"}, {"price": "0.78", "size": "277.27"}, {"price": "0.74", "size": "105"}, {"price": "0.72", "size": "400"}, {"price": "0.71", "size": "200"}, {"price": "0.69", "size": "177.41"}, {"price": "0.68", "size": "50"}, {"price": "0.65", "size": "182.14"}, {"price": "0.64", "size": "5"}, {"price": "0.41", "size": "150"}, {"price": "0.4", "size": "97.58"}, {"price": "0.33", "size": "10"}, {"price": "0.3", "size": "100"}, {"price": "0.28", "size": "110"}, {"price": "0.25", "size": "57.71"}, {"price": "0.24", "size": "17.1"}, {"price": "0.23", "size": "14.28"}, {"price": "0.18", "size": "121.95"}, {"price": "0.17", "size": "36.25"}, {"price": "0.16", "size": "9.99"}], "event_type": "book", "last_trade_price": "0.160"}, {"market": "0xbad704f2ae063322169bf3add805258727ecd3e6c0ad37fc7e6590c993375732", "asset_id": "7222446780603193936485021555727686526767361285081920316169851879719387571951", "timestamp": "1769383803170", "hash": "6f7be0f03cae7cc9066c79e13a9a34d73dbb4387", "bids": [{"price": "0.01", "size": "5109.71"}, {"price": "0.02", "size": "2200"}, {"price": "0.03", "size": "10.14"}, {"price": "0.04", "size": "12"}, {"price": "0.05", "size": "20"}, {"price": "0.06", "size": "533"}, {"price": "0.09", "size": "600"}, {"price": "0.1", "size": "1450"}, {"price": "0.11", "size": "5.43"}, {"price": "0.14", "size": "242.85"}, {"price": "0.15", "size": "825"}, {"price": "0.18", "size": "427.77"}, {"price": "0.19", "size": "126"}, {"price": "0.2", "size": "5"}, {"price": "0.23", "size": "321.73"}, {"price": "0.25", "size": "5"}, {"price": "0.27", "size": "50"}, {"price": "0.28", "size": "92.85"}, {"price": "0.32", "size": "75"}, {"price": "0.37", "size": "179.05"}, {"price": "0.38", "size": "10"}, {"price": "0.55", "size": "100"}, {"price": "0.57", "size": "60"}, {"price": "0.8", "size": "100"}, {"price": "0.81", "size": "211.73"}, {"price": "0.83", "size": "200"}, {"price": "0.84", "size": "60"}, {"price": "0.9", "size": "166.18"}, {"price": "0.91", "size": "10.7"}], "asks": [{"price": "0.99", "size": "3100"}, {"price": "0.98", "size": "511.02"}, {"price": "0.97", "size": "13.65"}, {"price": "0.96", "size": "500"}, {"price": "0.95", "size": "37.4"}, {"price": "0.94", "size": "25000"}, {"price": "0.93", "size": "24902.88"}, {"price": "0.92", "size": "805.22"}], "event_type": "book", "last_trade_price": ""}, {"market": "0xd3320fd4b325ce3d629fbaffd90bebd0a4f45042d91bf207c9866704d630bdb9", "asset_id": "5111367619701907925753527368079368781350889833282062945485232751026085335030", "timestamp": "1769383961866", "hash": "399667b9235b6d706bee37b351fa529ddf921aa9", "bids": [{"price": "0.001", "size": "3163.07"}, {"price": "0.002", "size": "1255.04"}, {"price": "0.003", "size": "1000"}, {"price": "0.004", "size": "8.63"}, {"price": "0.01", "size": "323692"}, {"price": "0.011", "size": "12.27"}, {"price": "0.02", "size": "4048"}, {"price": "0.03", "size": "5200"}, {"price": "0.04", "size": "1024"}, {"price": "0.041", "size": "6.01"}, {"price": "0.05", "size": "1030"}, {"price": "0.051", "size": "39"}, {"price": "0.06", "size": "3600"}, {"price": "0.08", "size": "1006"}, {"price": "0.1", "size": "860"}, {"price": "0.101", "size": "250"}, {"price": "0.11", "size": "100"}, {"price": "0.111", "size": "5.12"}, {"price": "0.15", "size": "1101.66"}, {"price": "0.16", "size": "128"}, {"price": "0.19", "size": "418.42"}, {"price": "0.24", "size": "316.66"}, {"price": "0.241", "size": "8"}, {"price": "0.27", "size": "50"}, {"price": "0.29", "size": "89.65"}, {"price": "0.32", "size": "64"}, {"price": "0.34", "size": "70.58"}, {"price": "0.39", "size": "176.28"}, {"price": "0.64", "size": "32"}, {"price": "0.65", "size": "100"}, {"price": "0.7", "size": "123.99"}, {"price": "0.8", "size": "1016"}, {"price": "0.81", "size": "200"}, {"price": "0.82", "size": "150"}, {"price": "0.83", "size": "3350.67"}, {"price": "0.85", "size": "10"}, {"price": "0.9", "size": "213"}, {"price": "0.91", "size": "10"}, {"price": "0.92", "size": "1624.58"}, {"price": "0.93", "size": "352.04"}, {"price": "0.931", "size": "242.57"}, {"price": "0.938", "size": "129"}, {"price": "0.941", "size": "129"}, {"price": "0.944", "size": "129"}, {"price": "0.947", "size": "129"}, {"price": "0.95", "size": "608.47"}], "asks": [{"price": "0.999", "size": "1157.99"}, {"price": "0.998", "size": "5013.16"}, {"price": "0.997", "size": "68.77"}, {"price": "0.99", "size": "113871.05"}, {"price": "0.989", "size": "9.08"}, {"price": "0.988", "size": "175.74"}, {"price": "0.986", "size": "357.14"}, {"price": "0.985", "size": "11.34"}, {"price": "0.98", "size": "1005"}, {"price": "0.979", "size": "238.09"}, {"price": "0.978", "size": "12.64"}, {"price": "0.97", "size": "1018.13"}, {"price": "0.969", "size": "290"}, {"price": "0.967", "size": "151.51"}, {"price": "0.966", "size": "6.45"}, {"price": "0.961", "size": "87.3"}, {"price": "0.959", "size": "142"}, {"price": "0.958", "size": "25"}, {"price": "0.957", "size": "17.09"}], "event_type": "book", "last_trade_price": "0.050"}, {"market": "0xf2bf04609e7458df56c9bb4b1e051286dea11da1c944bbc1dafbcc6b76904e52", "asset_id": "76326875711147697076353707331532227929486722415800396469798548611383212234361", "timestamp": "1769383883734", "hash": "97c5dbf3ddf593cd025ede5a2627532eb11dd46d", "bids": [{"price": "0.01", "size": "6109.79"}, {"price": "0.02", "size": "1000"}, {"price": "0.03", "size": "10.2"}, {"price": "0.04", "size": "12"}, {"price": "0.05", "size": "1320"}, {"price": "0.09", "size": "600"}, {"price": "0.1", "size": "1700"}, {"price": "0.11", "size": "5.41"}, {"price": "0.13", "size": "586.53"}, {"price": "0.14", "size": "5"}, {"price": "0.18", "size": "427.77"}, {"price": "0.21", "size": "5"}, {"price": "0.22", "size": "277.27"}, {"price": "0.26", "size": "105"}, {"price": "0.28", "size": "400"}, {"price": "0.29", "size": "200"}, {"price": "0.31", "size": "177.41"}, {"price": "0.32", "size": "50"}, {"price": "0.35", "size": "182.14"}, {"price": "0.36", "size": "5"}, {"price": "0.59", "size": "150"}, {"price": "0.6", "size": "97.58"}, {"price": "0.67", "size": "10"}, {"price": "0.7", "size": "100"}, {"price": "0.72", "size": "110"}, {"price": "0.75", "size": "57.71"}, {"price": "0.76", "size": "17.1"}, {"price": "0.77", "size": "14.28"}, {"price": "0.82", "size": "121.95"}, {"price": "0.83", "size": "36.25"}, {"price": "0.84", "size": "9.99"}], "asks": [{"price": "0.99", "size": "3100"}, {"price": "0.98", "size": "1260.57"}, {"price": "0.97", "size": "500"}, {"price": "0.96", "size": "756.99"}, {"price": "0.95", "size": "280"}, {"price": "0.94", "size": "191.66"}, {"price": "0.93", "size": "192.97"}, {"price": "0.92", "size": "74.32"}, {"price": "0.91", "size": "74.32"}, {"price": "0.9", "size": "74.32"}, {"price": "0.89", "size": "1874.32"}, {"price": "0.88", "size": "200"}, {"price": "0.87", "size": "30"}], "event_type": "book", "last_trade_price": "0.160"}, {"market": "0xd3320fd4b325ce3d629fbaffd90bebd0a4f45042d91bf207c9866704d630bdb9", "asset_id": "16796294837862213749214191185380591986043723823732945104815587989221348740344", "timestamp": "1769383961866", "hash": "8d04317b09a94a33945a1810a2f590c99b6a1e72", "bids": [{"price": "0.001", "size": "1157.99"}, {"price": "0.002", "size": "5013.16"}, {"price": "0.003", "size": "68.77"}, {"price": "0.01", "size": "113871.05"}, {"price": "0.011", "size": "9.08"}, {"price": "0.012", "size": "175.74"}, {"price": "0.014", "size": "357.14"}, {"price": "0.015", "size": "11.34"}, {"price": "0.02", "size": "1005"}, {"price": "0.021", "size": "238.09"}, {"price": "0.022", "size": "12.64"}, {"price": "0.03", "size": "1018.13"}, {"price": "0.031", "size": "290"}, {"price": "0.033", "size": "151.51"}, {"price": "0.034", "size": "6.45"}, {"price": "0.039", "size": "87.3"}, {"price": "0.041", "size": "142"}, {"price": "0.042", "size": "25"}, {"price": "0.043", "size": "17.09"}], "asks": [{"price": "0.999", "size": "3163.07"}, {"price": "0.998", "size": "1255.04"}, {"price": "0.997", "size": "1000"}, {"price": "0.996", "size": "8.63"}, {"price": "0.99", "size": "323692"}, {"price": "0.989", "size": "12.27"}, {"price": "0.98", "size": "4048"}, {"price": "0.97", "size": "5200"}, {"price": "0.96", "size": "1024"}, {"price": "0.959", "size": "6.01"}, {"price": "0.95", "size": "1030"}, {"price": "0.949", "size": "39"}, {"price": "0.94", "size": "3600"}, {"price": "0.92", "size": "1006"}, {"price": "0.9", "size": "860"}, {"price": "0.899", "size": "250"}, {"price": "0.89", "size": "100"}, {"price": "0.889", "size": "5.12"}, {"price": "0.85", "size": "1101.66"}, {"price": "0.84", "size": "128"}, {"price": "0.81", "size": "418.42"}, {"price": "0.76", "size": "316.66"}, {"price": "0.759", "size": "8"}, {"price": "0.73", "size": "50"}, {"price": "0.71", "size": "89.65"}, {"price": "0.68", "size": "64"}, {"price": "0.66", "size": "70.58"}, {"price": "0.61", "size": "176.28"}, {"price": "0.36", "size": "32"}, {"price": "0.35", "size": "100"}, {"price": "0.3", "size": "123.99"}, {"price": "0.2", "size": "1016"}, {"price": "0.19", "size": "200"}, {"price": "0.18", "size": "150"}, {"price": "0.17", "size": "3350.67"}, {"price": "0.15", "size": "10"}, {"price": "0.1", "size": "213"}, {"price": "0.09", "size": "10"}, {"price": "0.08", "size": "1624.58"}, {"price": "0.07", "size": "352.04"}, {"price": "0.069", "size": "242.57"}, {"price": "0.062", "size": "129"}, {"price": "0.059", "size": "129"}, {"price": "0.056", "size": "129"}, {"price": "0.053", "size": "129"}, {"price": "0.05", "size": "608.47"}], "event_type": "book", "last_trade_price": "0.050"}, {"market": "0xbad704f2ae063322169bf3add805258727ecd3e6c0ad37fc7e6590c993375732", "asset_id": "96125857565472990401175521466987279074737231208177130423351312642992689722753", "timestamp": "1769383803170", "hash": "3ef081fe3d0ab3e40043ff316e346b9ebe3a338e", "bids": [{"price": "0.01", "size": "3100"}, {"price": "0.02", "size": "511.02"}, {"price": "0.03", "size": "13.65"}, {"price": "0.04", "size": "500"}, {"price": "0.05", "size": "37.4"}, {"price": "0.06", "size": "25000"}, {"price": "0.07", "size": "24902.88"}, {"price": "0.08", "size": "805.22"}], "asks": [{"price": "0.99", "size": "5109.71"}, {"price": "0.98", "size": "2200"}, {"price": "0.97", "size": "10.14"}, {"price": "0.96", "size": "12"}, {"price": "0.95", "size": "20"}, {"price": "0.94", "size": "533"}, {"price": "0.91", "size": "600"}, {"price": "0.9", "size": "1450"}, {"price": "0.89", "size": "5.43"}, {"price": "0.86", "size": "242.85"}, {"price": "0.85", "size": "825"}, {"price": "0.82", "size": "427.77"}, {"price": "0.81", "size": "126"}, {"price": "0.8", "size": "5"}, {"price": "0.77", "size": "321.73"}, {"price": "0.75", "size": "5"}, {"price": "0.73", "size": "50"}, {"price": "0.72", "size": "92.85"}, {"price": "0.68", "size": "75"}, {"price": "0.63", "size": "179.05"}, {"price": "0.62", "size": "10"}, {"price": "0.45", "size": "100"}, {"price": "0.43", "size": "60"}, {"price": "0.2", "size": "100"}, {"price": "0.19", "size": "211.73"}, {"price": "0.17", "size": "200"}, {"price": "0.16", "size": "60"}, {"price": "0.1", "size": "166.18"}, {"price": "0.09", "size": "10.7"}], "event_type": "book", "last_trade_price": ""}]}
{"_local_timestamp": "2026-01-25T23:34:08.525169+00:00", "data": {"market": "0xf2bf04609e7458df56c9bb4b1e051286dea11da1c944bbc1dafbcc6b76904e52", "price_changes": [{"asset_id": "105031123790227090351610621121319179238510007553875150023320472711583933704999", "price": "0.12", "size": "0", "side": "BUY", "hash": "0719a0c4149558a513fbf741803d6c0b827ebbfd", "best_bid": "0.13", "best_ask": "0.16"}, {"asset_id": "76326875711147697076353707331532227929486722415800396469798548611383212234361", "price": "0.88", "size": "0", "side": "SELL", "hash": "0456e8e38ad9f31bbfc2067c04353dec3375939d", "best_bid": "0.84", "best_ask": "0.87"}], "timestamp": "1769384048455", "event_type": "price_change"}}
{"_local_timestamp": "2026-01-25T23:34:08.945769+00:00", "data": {"market": "0xf2bf04609e7458df56c9bb4b1e051286dea11da1c944bbc1dafbcc6b76904e52", "price_changes": [{"asset_id": "105031123790227090351610621121319179238510007553875150023320472711583933704999", "price": "0.12", "size": "66.66", "side": "BUY", "hash": "e5007a7378a9d691b9f8f60f6973bdf48a85965f", "best_bid": "0.13", "best_ask": "0.16"}, {"asset_id": "76326875711147697076353707331532227929486722415800396469798548611383212234361", "price": "0.88", "size": "66.66", "side": "SELL", "hash": "afff8ad9c1a197b80d2281bb0dd61d0eaa7b4e9c", "best_bid": "0.84", "best_ask": "0.87"}], "timestamp": "1769384048879", "event_type": "price_change"}}
{"_local_timestamp": "2026-01-25T23:34:08.953684+00:00", "data": {"market": "0xf2bf04609e7458df56c9bb4b1e051286dea11da1c944bbc1dafbcc6b76904e52", "price_changes": [{"asset_id": "105031123790227090351610621121319179238510007553875150023320472711583933704999", "price": "0.13", "size": "96.66", "side": "BUY", "hash": "266efc3500e8b8241b1784b5b0cb5971782035fc", "best_bid": "0.13", "best_ask": "0.16"}, {"asset_id": "76326875711147697076353707331532227929486722415800396469798548611383212234361", "price": "0.87", "size": "96.66", "side": "SELL", "hash": "8713b227e5e1f360290c484bddf586748eec5d16", "best_bid": "0.84", "best_ask": "0.87"}], "timestamp": "1769384048884", "event_type": "price_change"}}
{"_local_timestamp": "2026-01-25T23:34:08.963898+00:00", "data": {"market": "0xf2bf04609e7458df56c9bb4b1e051286dea11da1c944bbc1dafbcc6b76904e52", "price_changes": [{"asset_id": "105031123790227090351610621121319179238510007553875150023320472711583933704999", "price": "0.14", "size": "66.66", "side": "BUY", "hash": "910f890588a713d9a50498b34ced4c2db27f5832", "best_bid": "0.14", "best_ask": "0.16"}, {"asset_id": "76326875711147697076353707331532227929486722415800396469798548611383212234361", "price": "0.86", "size": "66.66", "side": "SELL", "hash": "f8f3d4b7986c874da28b830294d36be0d7ef8c8f", "best_bid": "0.84", "best_ask": "0.86"}], "timestamp": "1769384048898", "event_type": "price_change"}}
{"_local_timestamp": "2026-01-25T23:34:09.452255+00:00", "data": {"market": "0xf2bf04609e7458df56c9bb4b1e051286dea11da1c944bbc1dafbcc6b76904e52", "price_changes": [{"asset_id": "105031123790227090351610621121319179238510007553875150023320472711583933704999", "price": "0.13", "size": "66.66", "side": "BUY", "hash": "b33c1a4ea248a341aa30ea79ec969845c1e5ffd3", "best_bid": "0.14", "best_ask": "0.16"}, {"asset_id": "76326875711147697076353707331532227929486722415800396469798548611383212234361", "price": "0.87", "size": "66.66", "side": "SELL", "hash": "e4a5a321028d1d9002c6806a78688a5a596e086b", "best_bid": "0.84", "best_ask": "0.86"}], "timestamp": "1769384049387", "event_type": "price_change"}}
{"_local_timestamp": "2026-01-25T23:34:36.568860+00:00", "data": {"market": "0xd3320fd4b325ce3d629fbaffd90bebd0a4f45042d91bf207c9866704d630bdb9", "price_changes": [{"asset_id": "16796294837862213749214191185380591986043723823732945104815587989221348740344", "price": "0.003", "size": "50.4", "side": "BUY", "hash": "af6ca99547d6a188cea574ad779e1c06ba783a8c", "best_bid": "0.043", "best_ask": "0.05"}, {"asset_id": "5111367619701907925753527368079368781350889833282062945485232751026085335030", "price": "0.997", "size": "50.4", "side": "SELL", "hash": "f1b852824afe4d71092383d7da2032371ac8d739", "best_bid": "0.95", "best_ask": "0.957"}], "timestamp": "1769384076495", "event_type": "price_change"}}
{"_local_timestamp": "2026-01-25T23:34:38.083469+00:00", "data": {"market": "0xd3320fd4b325ce3d629fbaffd90bebd0a4f45042d91bf207c9866704d630bdb9", "price_changes": [{"asset_id": "16796294837862213749214191185380591986043723823732945104815587989221348740344", "price": "0.003", "size": "68.77", "side": "BUY", "hash": "e6a9925dba7d3a048efe66fa33301d67ae8ed85b", "best_bid": "0.043", "best_ask": "0.05"}, {"asset_id": "5111367619701907925753527368079368781350889833282062945485232751026085335030", "price": "0.997", "size": "68.77", "side": "SELL", "hash": "3d4a9e2c56e640bc802630d887ca4be449c585bc", "best_bid": "0.95", "best_ask": "0.957"}], "timestamp": "1769384078008", "event_type": "price_change"}}
{"_local_timestamp": "2026-01-25T23:35:31.369700+00:00", "data": {"market": "0xd3320fd4b325ce3d629fbaffd90bebd0a4f45042d91bf207c9866704d630bdb9", "price_changes": [{"asset_id": "16796294837862213749214191185380591986043723823732945104815587989221348740344", "price": "0.031", "size": "0", "side": "BUY", "hash": "b4131cca47bbe3a4a8fa63666694993fe06d521a", "best_bid": "0.043", "best_ask": "0.05"}, {"asset_id": "5111367619701907925753527368079368781350889833282062945485232751026085335030", "price": "0.969", "size": "0", "side": "SELL", "hash": "2b30cedc3fa85cddec53589ab66cde95bead4077", "best_bid": "0.95", "best_ask": "0.957"}], "timestamp": "1769384131245", "event_type": "price_change"}}
{"_local_timestamp": "2026-01-25T23:35:40.570442+00:00", "data": {"market": "0xbad704f2ae063322169bf3add805258727ecd3e6c0ad37fc7e6590c993375732", "price_changes": [{"asset_id": "96125857565472990401175521466987279074737231208177130423351312642992689722753", "price": "0.03", "size": "0", "side": "BUY", "hash": "ff7a126a710c22b96110b4ff75cebff78345c54d", "best_bid": "0.08", "best_ask": "0.09"}, {"asset_id": "7222446780603193936485021555727686526767361285081920316169851879719387571951", "price": "0.97", "size": "0", "side": "SELL", "hash": "379b3fa89e405fddde8351083607ec1388119a79", "best_bid": "0.91", "best_ask": "0.92"}], "timestamp": "1769384140507", "event_type": "price_change"}}
{"_local_timestamp": "2026-01-25T23:35:42.128643+00:00", "data": {"market": "0xbad704f2ae063322169bf3add805258727ecd3e6c0ad37fc7e6590c993375732", "price_changes": [{"asset_id": "96125857565472990401175521466987279074737231208177130423351312642992689722753", "price": "0.03", "size": "13.65", "side": "BUY", "hash": "2733cecf582a462e143079ec4c20865ef02bcf1f", "best_bid": "0.08", "best_ask": "0.09"}, {"asset_id": "7222446780603193936485021555727686526767361285081920316169851879719387571951", "price": "0.97", "size": "13.65", "side": "SELL", "hash": "05eb0a287f9952d9831390de4d58706f1628473d", "best_bid": "0.91", "best_ask": "0.92"}], "timestamp": "1769384142063", "event_type": "price_change"}}
{"_local_timestamp": "2026-01-25T23:36:34.056269+00:00", "data": {"market": "0xd3320fd4b325ce3d629fbaffd90bebd0a4f45042d91bf207c9866704d630bdb9", "price_changes": [{"asset_id": "16796294837862213749214191185380591986043723823732945104815587989221348740344", "price": "0.031", "size": "290", "side": "BUY", "hash": "fae75ea76df8849292180fc30e20e3877cefe700", "best_bid": "0.043", "best_ask": "0.05"}, {"asset_id": "5111367619701907925753527368079368781350889833282062945485232751026085335030", "price": "0.969", "size": "290", "side": "SELL", "hash": "d230642254f23e26e8ae1f5bed0baf1bf8d42242", "best_bid": "0.95", "best_ask": "0.957"}], "timestamp": "1769384193983", "event_type": "price_change"}}
{"_local_timestamp": "2026-01-25T23:36:51.887608+00:00", "data": {"market": "0xf2bf04609e7458df56c9bb4b1e051286dea11da1c944bbc1dafbcc6b76904e52", "price_changes": [{"asset_id": "105031123790227090351610621121319179238510007553875150023320472711583933704999", "price": "0.14", "size": "0", "side": "BUY", "hash": "a1149f4380c1c38cebb0eef25cd98d412b59a272", "best_bid": "0.11", "best_ask": "0.16"}, {"asset_id": "76326875711147697076353707331532227929486722415800396469798548611383212234361", "price": "0.86", "size": "0", "side": "SELL", "hash": "92c591f6a4f5415617704c1ea3bd397d8b87d20a", "best_bid": "0.84", "best_ask": "0.89"}], "timestamp": "1769384211697", "event_type": "price_change"}}
{"_local_timestamp": "2026-01-25T23:36:51.888566+00:00", "data": {"market": "0xf2bf04609e7458df56c9bb4b1e051286dea11da1c944bbc1dafbcc6b76904e52", "price_changes": [{"asset_id": "105031123790227090351610621121319179238510007553875150023320472711583933704999", "price": "0.13", "size": "0", "side": "BUY", "hash": "a1149f4380c1c38cebb0eef25cd98d412b59a272", "best_bid": "0.11", "best_ask": "0.16"}, {"asset_id": "76326875711147697076353707331532227929486722415800396469798548611383212234361", "price": "0.87", "size": "0", "side": "SELL", "hash": "92c591f6a4f5415617704c1ea3bd397d8b87d20a", "best_bid": "0.84", "best_ask": "0.89"}], "timestamp": "1769384211697", "event_type": "price_change"}}
{"_local_timestamp": "2026-01-25T23:36:51.888905+00:00", "data": {"market": "0xf2bf04609e7458df56c9bb4b1e051286dea11da1c944bbc1dafbcc6b76904e52", "price_changes": [{"asset_id": "105031123790227090351610621121319179238510007553875150023320472711583933704999", "price": "0.12", "size": "0", "side": "BUY", "hash": "a1149f4380c1c38cebb0eef25cd98d412b59a272", "best_bid": "0.11", "best_ask": "0.16"}, {"asset_id": "76326875711147697076353707331532227929486722415800396469798548611383212234361", "price": "0.88", "size": "0", "side": "SELL", "hash": "92c591f6a4f5415617704c1ea3bd397d8b87d20a", "best_bid": "0.84", "best_ask": "0.89"}], "timestamp": "1769384211697", "event_type": "price_change"}}
{"_local_timestamp": "2026-01-25T23:36:51.990286+00:00", "data": {"market": "0xf2bf04609e7458df56c9bb4b1e051286dea11da1c944bbc1dafbcc6b76904e52", "price_changes": [{"asset_id": "105031123790227090351610621121319179238510007553875150023320472711583933704999", "price": "0.12", "size": "30", "side": "BUY", "hash": "29290f2eca72204b236632b37a9edd236f749111", "best_bid": "0.12", "best_ask": "0.16"}, {"asset_id": "76326875711147697076353707331532227929486722415800396469798548611383212234361", "price": "0.88", "size": "30", "side": "SELL", "hash": "2367aebcc9b5732c01744bea573ee84b1a4735c7", "best_bid": "0.84", "best_ask": "0.88"}], "timestamp": "1769384211799", "event_type": "price_change"}}
{"_local_timestamp": "2026-01-25T23:36:52.265706+00:00", "data": {"market": "0xf2bf04609e7458df56c9bb4b1e051286dea11da1c944bbc1dafbcc6b76904e52", "price_changes": [{"asset_id": "105031123790227090351610621121319179238510007553875150023320472711583933704999", "price": "0.12", "size": "230", "side": "BUY", "hash": "3f14a4f00f9d15bde35d24671fd1e8d493a82cb4", "best_bid": "0.12", "best_ask": "0.16"}, {"asset_id": "76326875711147697076353707331532227929486722415800396469798548611383212234361", "price": "0.88", "size": "230", "side": "SELL", "hash": "ec5e8846932f06283a315100273adfc76716813b", "best_bid": "0.84", "best_ask": "0.88"}], "timestamp": "1769384212074", "event_type": "price_change"}}
{"_local_timestamp": "2026-01-25T23:36:53.616537+00:00", "data": {"market": "0xf2bf04609e7458df56c9bb4b1e051286dea11da1c944bbc1dafbcc6b76904e52", "price_changes": [{"asset_id": "105031123790227090351610621121319179238510007553875150023320472711583933704999", "price": "0.12", "size": "200", "side": "BUY", "hash": "f6f29e7d7c6cda776b927638ae4e897d88211402", "best_bid": "0.12", "best_ask": "0.16"}, {"asset_id": "76326875711147697076353707331532227929486722415800396469798548611383212234361", "price": "0.88", "size": "200", "side": "SELL", "hash": "43e23fb2f2e64d6464e4a3d87282e3363a7a16ca", "best_bid": "0.84", "best_ask": "0.88"}], "timestamp": "1769384213434", "event_type": "price_change"}}
{"_local_timestamp": "2026-01-25T23:36:53.667389+00:00", "data": {"market": "0xf2bf04609e7458df56c9bb4b1e051286dea11da1c944bbc1dafbcc6b76904e52", "price_changes": [{"asset_id": "105031123790227090351610621121319179238510007553875150023320472711583933704999", "price": "0.13", "size": "30", "side": "BUY", "hash": "f797632492de0935eee0b11fa58ec31be9781c9c", "best_bid": "0.13", "best_ask": "0.16"}, {"asset_id": "76326875711147697076353707331532227929486722415800396469798548611383212234361", "price": "0.87", "size": "30", "side": "SELL", "hash": "db8014969ff177660217c6b44394584bdc67518f", "best_bid": "0.84", "best_ask": "0.87"}], "timestamp": "1769384213480", "event_type": "price_change"}}
{"_local_timestamp": "2026-01-25T23:37:04.947101+00:00", "data": {"market": "0xd3320fd4b325ce3d629fbaffd90bebd0a4f45042d91bf207c9866704d630bdb9", "price_changes": [{"asset_id": "16796294837862213749214191185380591986043723823732945104815587989221348740344", "price": "0.053", "size": "0", "side": "SELL", "hash": "913600915ad92f5cd93b4d5b744a6c6891f4dd30", "best_bid": "0.043", "best_ask": "0.05"}, {"asset_id": "5111367619701907925753527368079368781350889833282062945485232751026085335030", "price": "0.947", "size": "0", "side": "BUY", "hash": "085f2f1300e0d6deb86486b45fc010aed8a5c4ef", "best_bid": "0.95", "best_ask": "0.957"}], "timestamp": "1769384224720", "event_type": "price_change"}}
{"_local_timestamp": "2026-01-25T23:37:04.948595+00:00", "data": {"market": "0xd3320fd4b325ce3d629fbaffd90bebd0a4f45042d91bf207c9866704d630bdb9", "price_changes": [{"asset_id": "16796294837862213749214191185380591986043723823732945104815587989221348740344", "price": "0.056", "size": "0", "side": "SELL", "hash": "913600915ad92f5cd93b4d5b744a6c6891f4dd30", "best_bid": "0.043", "best_ask": "0.05"}, {"asset_id": "5111367619701907925753527368079368781350889833282062945485232751026085335030", "price": "0.944", "size": "0", "side": "BUY", "hash": "085f2f1300e0d6deb86486b45fc010aed8a5c4ef", "best_bid": "0.95", "best_ask": "0.957"}], "timestamp": "1769384224720", "event_type": "price_change"}}
{"_local_timestamp": "2026-01-25T23:37:04.949029+00:00", "data": {"market": "0xd3320fd4b325ce3d629fbaffd90bebd0a4f45042d91bf207c9866704d630bdb9", "price_changes": [{"asset_id": "16796294837862213749214191185380591986043723823732945104815587989221348740344", "price": "0.05", "size": "479.47", "side": "SELL", "hash": "913600915ad92f5cd93b4d5b744a6c6891f4dd30", "best_bid": "0.043", "best_ask": "0.05"}, {"asset_id": "5111367619701907925753527368079368781350889833282062945485232751026085335030", "price": "0.95", "size": "479.47", "side": "BUY", "hash": "085f2f1300e0d6deb86486b45fc010aed8a5c4ef", "best_bid": "0.95", "best_ask": "0.957"}], "timestamp": "1769384224720", "event_type": "price_change"}}
{"_local_timestamp": "2026-01-25T23:37:04.950669+00:00", "data": {"market": "0xd3320fd4b325ce3d629fbaffd90bebd0a4f45042d91bf207c9866704d630bdb9", "price_changes": [{"asset_id": "16796294837862213749214191185380591986043723823732945104815587989221348740344", "price": "0.059", "size": "0", "side": "SELL", "hash": "913600915ad92f5cd93b4d5b744a6c6891f4dd30", "best_bid": "0.043", "best_ask": "0.05"}, {"asset_id": "5111367619701907925753527368079368781350889833282062945485232751026085335030", "price": "0.941", "size": "0", "side": "BUY", "hash": "085f2f1300e0d6deb86486b45fc010aed8a5c4ef", "best_bid": "0.95", "best_ask": "0.957"}], "timestamp": "1769384224720", "event_type": "price_change"}}
{"_local_timestamp": "2026-01-25T23:37:04.951094+00:00", "data": {"market": "0xd3320fd4b325ce3d629fbaffd90bebd0a4f45042d91bf207c9866704d630bdb9", "price_changes": [{"asset_id": "16796294837862213749214191185380591986043723823732945104815587989221348740344", "price": "0.062", "size": "0", "side": "SELL", "hash": "913600915ad92f5cd93b4d5b744a6c6891f4dd30", "best_bid": "0.043", "best_ask": "0.05"}, {"asset_id": "5111367619701907925753527368079368781350889833282062945485232751026085335030", "price": "0.938", "size": "0", "side": "BUY", "hash": "085f2f1300e0d6deb86486b45fc010aed8a5c4ef", "best_bid": "0.95", "best_ask": "0.957"}], "timestamp": "1769384224720", "event_type": "price_change"}}
{"_local_timestamp": "2026-01-25T23:37:15.053140+00:00", "data": {"market": "0xd3320fd4b325ce3d629fbaffd90bebd0a4f45042d91bf207c9866704d630bdb9", "price_changes": [{"asset_id": "16796294837862213749214191185380591986043723823732945104815587989221348740344", "price": "0.062", "size": "129", "side": "SELL", "hash": "accbdef2ba9e5ffba96a875a363f0b441658354e", "best_bid": "0.043", "best_ask": "0.05"}, {"asset_id": "5111367619701907925753527368079368781350889833282062945485232751026085335030", "price": "0.938", "size": "129", "side": "BUY", "hash": "84b5b0fe884f9f5b3b5cbe82eb74ea54bf081163", "best_bid": "0.95", "best_ask": "0.957"}], "timestamp": "1769384234985", "event_type": "price_change"}}
{"_local_timestamp": "2026-01-25T23:37:15.053580+00:00", "data": {"market": "0xd3320fd4b325ce3d629fbaffd90bebd0a4f45042d91bf207c9866704d630bdb9", "price_changes": [{"asset_id": "16796294837862213749214191185380591986043723823732945104815587989221348740344", "price": "0.056", "size": "129", "side": "SELL", "hash": "51264ad9c2539256034a62518eebbc02523788f2", "best_bid": "0.043", "best_ask": "0.05"}, {"asset_id": "5111367619701907925753527368079368781350889833282062945485232751026085335030", "price": "0.944", "size": "129", "side": "BUY", "hash": "11e80f80f7b8b1621d950ce2427850eab7a01aa5", "best_bid": "0.95", "best_ask": "0.957"}], "timestamp": "1769384234986", "event_type": "price_change"}}
{"_local_timestamp": "2026-01-25T23:37:15.058153+00:00", "data": {"market": "0xd3320fd4b325ce3d629fbaffd90bebd0a4f45042d91bf207c9866704d630bdb9", "price_changes": [{"asset_id": "16796294837862213749214191185380591986043723823732945104815587989221348740344", "price": "0.059", "size": "129", "side": "SELL", "hash": "87436dc060560a614fbb3851e458563a5421cd6f", "best_bid": "0.043", "best_ask": "0.05"}, {"asset_id": "5111367619701907925753527368079368781350889833282062945485232751026085335030", "price": "0.941", "size": "129", "side": "BUY", "hash": "510636e8fd1462a37a2f75de0292da021aa232f8", "best_bid": "0.95", "best_ask": "0.957"}], "timestamp": "1769384234988", "event_type": "price_change"}}
{"_local_timestamp": "2026-01-25T23:37:15.058589+00:00", "data": {"market": "0xd3320fd4b325ce3d629fbaffd90bebd0a4f45042d91bf207c9866704d630bdb9", "price_changes": [{"asset_id": "16796294837862213749214191185380591986043723823732945104815587989221348740344", "price": "0.053", "size": "129", "side": "SELL", "hash": "312d373885615f51d930fd7b0538635a2cf157ca", "best_bid": "0.043", "best_ask": "0.05"}, {"asset_id": "5111367619701907925753527368079368781350889833282062945485232751026085335030", "price": "0.947", "size": "129", "side": "BUY", "hash": "51f11324a79e2c4f26dd137b594bc79d9d5263a6", "best_bid": "0.95", "best_ask": "0.957"}], "timestamp": "1769384234989", "event_type": "price_change"}}
{"_local_timestamp": "2026-01-25T23:37:15.060146+00:00", "data": {"market": "0xd3320fd4b325ce3d629fbaffd90bebd0a4f45042d91bf207c9866704d630bdb9", "price_changes": [{"asset_id": "16796294837862213749214191185380591986043723823732945104815587989221348740344", "price": "0.05", "size": "608.47", "side": "SELL", "hash": "d6fa5a5a9550ee16403ed389f7393649a25aa8a6", "best_bid": "0.043", "best_ask": "0.05"}, {"asset_id": "5111367619701907925753527368079368781350889833282062945485232751026085335030", "price": "0.95", "size": "608.47", "side": "BUY", "hash": "689a6733fec0ca5667ad9e9865a701a636b2e736", "best_bid": "0.95", "best_ask": "0.957"}], "timestamp": "1769384234990", "event_type": "price_change"}}
{"_local_timestamp": "2026-01-25T23:38:21.404096+00:00", "data": {"market": "0xd3320fd4b325ce3d629fbaffd90bebd0a4f45042d91bf207c9866704d630bdb9", "price_changes": [{"asset_id": "16796294837862213749214191185380591986043723823732945104815587989221348740344", "price": "0.003", "size": "50.4", "side": "BUY", "hash": "f4c2d34e843c996ebf0b3a4e17fbaf3ff2a7a1a1", "best_bid": "0.043", "best_ask": "0.05"}, {"asset_id": "5111367619701907925753527368079368781350889833282062945485232751026085335030", "price": "0.997", "size": "50.4", "side": "SELL", "hash": "d70fab3a63270cd7042eea7dc6fef443837de6c8", "best_bid": "0.95", "best_ask": "0.957"}], "timestamp": "1769384301282", "event_type": "price_change"}}
{"_local_timestamp": "2026-01-25T23:38:22.181083+00:00", "data": {"market": "0xd3320fd4b325ce3d629fbaffd90bebd0a4f45042d91bf207c9866704d630bdb9", "price_changes": [{"asset_id": "16796294837862213749214191185380591986043723823732945104815587989221348740344", "price": "0.004", "size": "13.77", "side": "BUY", "hash": "9889155ba8c90a19f830a0bea09a8cc42f031c22", "best_bid": "0.043", "best_ask": "0.05"}, {"asset_id": "5111367619701907925753527368079368781350889833282062945485232751026085335030", "price": "0.996", "size": "13.77", "side": "SELL", "hash": "7ecf14039e41a5e2d59435d85ed8a8b7064b83cb", "best_bid": "0.95", "best_ask": "0.957"}], "timestamp": "1769384302111", "event_type": "price_change"}}
{"_local_timestamp": "2026-01-25T23:39:28.912020+00:00", "data": {"market": "0xbad704f2ae063322169bf3add805258727ecd3e6c0ad37fc7e6590c993375732", "price_changes": [{"asset_id": "96125857565472990401175521466987279074737231208177130423351312642992689722753", "price": "0.03", "size": "0", "side": "BUY", "hash": "042c5c1b16f2778af8ab6071b3cd409de76915e9", "best_bid": "0.08", "best_ask": "0.09"}, {"asset_id": "7222446780603193936485021555727686526767361285081920316169851879719387571951", "price": "0.97", "size": "0", "side": "SELL", "hash": "bd5dc9132841064cef91e48ca34188adb5824669", "best_bid": "0.91", "best_ask": "0.92"}], "timestamp": "1769384368841", "event_type": "price_change"}}
{"_local_timestamp": "2026-01-25T23:39:29.745436+00:00", "data": {"market": "0xbad704f2ae063322169bf3add805258727ecd3e6c0ad37fc7e6590c993375732", "price_changes": [{"asset_id": "96125857565472990401175521466987279074737231208177130423351312642992689722753", "price": "0.03", "size": "13.65", "side": "BUY", "hash": "7a313f47ece9d9ead4bbdceedd614e7dbff33c5e", "best_bid": "0.08", "best_ask": "0.09"}, {"asset_id": "7222446780603193936485021555727686526767361285081920316169851879719387571951", "price": "0.97", "size": "13.65", "side": "SELL", "hash": "62a92b093fcf7e9b1a58554c9c3e8e465749691c", "best_bid": "0.91", "best_ask": "0.92"}], "timestamp": "1769384369680", "event_type": "price_change"}}
{"_local_timestamp": "2026-01-25T23:39:37.493817+00:00", "data": {"market": "0xf2bf04609e7458df56c9bb4b1e051286dea11da1c944bbc1dafbcc6b76904e52", "price_changes": [{"asset_id": "105031123790227090351610621121319179238510007553875150023320472711583933704999", "price": "0.12", "size": "0", "side": "BUY", "hash": "2829a38e5f7b1acb7716eb2ece193fce22d2bc1a", "best_bid": "0.13", "best_ask": "0.16"}, {"asset_id": "76326875711147697076353707331532227929486722415800396469798548611383212234361", "price": "0.88", "size": "0", "side": "SELL", "hash": "b0a8dbe7449e401e6ca2386aa9b59efacc9e6037", "best_bid": "0.84", "best_ask": "0.87"}], "timestamp": "1769384377431", "event_type": "price_change"}}
{"_local_timestamp": "2026-01-25T23:39:37.890808+00:00", "data": {"market": "0xf2bf04609e7458df56c9bb4b1e051286dea11da1c944bbc1dafbcc6b76904e52", "price_changes": [{"asset_id": "105031123790227090351610621121319179238510007553875150023320472711583933704999", "price": "0.14", "size": "66.66", "side": "BUY", "hash": "d8e6b3cbfa2f6c376798eab6270d03835e39bf26", "best_bid": "0.14", "best_ask": "0.16"}, {"asset_id": "76326875711147697076353707331532227929486722415800396469798548611383212234361", "price": "0.86", "size": "66.66", "side": "SELL", "hash": "ba6655188516e244254dfbf6c1cfe2fa78e0ce87", "best_bid": "0.84", "best_ask": "0.86"}], "timestamp": "1769384377827", "event_type": "price_change"}}
{"_local_timestamp": "2026-01-25T23:39:37.919057+00:00", "data": {"market": "0xf2bf04609e7458df56c9bb4b1e051286dea11da1c944bbc1dafbcc6b76904e52", "price_changes": [{"asset_id": "105031123790227090351610621121319179238510007553875150023320472711583933704999", "price": "0.13", "size": "96.66", "side": "BUY", "hash": "c92645cae2ff756797bde8155fdbd257727b3b48", "best_bid": "0.14", "best_ask": "0.16"}, {"asset_id": "76326875711147697076353707331532227929486722415800396469798548611383212234361", "price": "0.87", "size": "96.66", "side": "SELL", "hash": "bbb0735456b70c0c5d2fb5d04d4e6643ad58c034", "best_bid": "0.84", "best_ask": "0.86"}], "timestamp": "1769384377850", "event_type": "price_change"}}
{"_local_timestamp": "2026-01-25T23:39:37.940891+00:00", "data": {"market": "0xf2bf04609e7458df56c9bb4b1e051286dea11da1c944bbc1dafbcc6b76904e52", "price_changes": [{"asset_id": "105031123790227090351610621121319179238510007553875150023320472711583933704999", "price": "0.12", "size": "66.66", "side": "BUY", "hash": "1a69eeceb1a0262273c3e7b807d0bfe709470b0a", "best_bid": "0.14", "best_ask": "0.16"}, {"asset_id": "76326875711147697076353707331532227929486722415800396469798548611383212234361", "price": "0.88", "size": "66.66", "side": "SELL", "hash": "8c8975c7bf263d0351f08c7224a456f1cbb270bd", "best_bid": "0.84", "best_ask": "0.86"}], "timestamp": "1769384377873", "event_type": "price_change"}}
{"_local_timestamp": "2026-01-25T23:39:38.448828+00:00", "data": {"market": "0xf2bf04609e7458df56c9bb4b1e051286dea11da1c944bbc1dafbcc6b76904e52", "price_changes": [{"asset_id": "105031123790227090351610621121319179238510007553875150023320472711583933704999", "price": "0.13", "size": "66.66", "side": "BUY", "hash": "36f9ddd63f0ed415b502cacb8a7380ea50f7444d", "best_bid": "0.14", "best_ask": "0.16"}, {"asset_id": "76326875711147697076353707331532227929486722415800396469798548611383212234361", "price": "0.87", "size": "66.66", "side": "SELL", "hash": "e4b6e08e840fabd0eaed064edb9b36104dd62e42", "best_bid": "0.84", "best_ask": "0.86"}], "timestamp": "1769384378377", "event_type": "price_change"}}
