{"_local_timestamp": "2026-01-25T23:33:57.104041+00:00", "data": [{"market": "0x08ab4504d44c55feee89fe2deba77f288ac727f0287df8a04c0a0a2162256c8e", "asset_id": "679278415023314077827788027777238511637764586200547537110586042472687154713", "timestamp": "1769384032004", "hash": "109e1410449ef14e4dfd119821b088c0b0039ec7", "bids": [{"price": "0.01", "size": "397.79"}, {"price": "0.02", "size": "26.15"}, {"price": "0.05", "size": "20"}, {"price": "0.06", "size": "16.42"}], "asks": [{"price": "0.99", "size": "388.55"}, {"price": "0.98", "size": "55.15"}, {"price": "0.97", "size": "100"}, {"price": "0.96", "size": "6.35"}, {"price": "0.95", "size": "80"}, {"price": "0.94", "size": "33"}, {"price": "0.92", "size": "1350"}, {"price": "0.9", "size": "5.87"}, {"price": "0.6", "size": "1000"}, {"price": "0.59", "size": "500"}], "event_type": "book", "last_trade_price": "0.420"}, {"market": "0xdb343c4acad127a3347d940a9a234e4a34ee0336d5d592d257efd7becc95b78b", "asset_id": "10653521437809047751568321889649995103294547094143336041571623048083551756658", "timestamp": "1769384033001", "hash": "d4447b4634cc30742f37241445e703e681876d80", "bids": [{"price": "0.01", "size": "288.64"}, {"price": "0.02", "size": "5.23"}, {"price": "0.04", "size": "55.44"}, {"price": "0.05", "size": "60"}, {"price": "0.06", "size": "1799"}, {"price": "0.08", "size": "100"}, {"price": "0.1", "size": "5.8"}, {"price": "0.38", "size": "1000"}, {"price": "0.39", "size": "500"}], "asks": [{"price": "0.99", "size": "297.79"}, {"price": "0.98", "size": "26.15"}, {"price": "0.95", "size": "60"}, {"price": "0.94", "size": "16.42"}], "event_type": "book", "last_trade_price": ""}, {"market": "0xecec20726d06c83989ad891c245da1f609328d35c109b32f63ce3098923e7019", "asset_id": "104774616866155880825821159563210736089000783082480386520148006749660756239146", "timestamp": "1769383900005", "hash": "43e133782713cfc03d9da50cc4350a22124dbf3a", "bids": [{"price": "0.01", "size": "283"}, {"price": "0.04", "size": "49"}, {"price": "0.05", "size": "60"}, {"price": "0.06", "size": "33"}], "asks": [{"price": "0.99", "size": "297.79"}, {"price": "0.98", "size": "26.15"}, {"price": "0.95", "size": "100"}, {"price": "0.94", "size": "15.48"}], "event_type": "book", "last_trade_price": "0.060"}, {"market": "0x94a74511beecd2f5565a100a69bf010ed044ed839a452eadadeea5442e55addb", "asset_id": "96532776063346938031927063463353616543810050542368500862324915366311944696774", "timestamp": "1769384032001", "hash": "6dc81490fef35a3f537c33d3d9a817e549afef5b", "bids": [{"price": "0.01", "size": "288.68"}, {"price": "0.02", "size": "12.26"}, {"price": "0.04", "size": "49"}, {"price": "0.05", "size": "60"}, {"price": "0.06", "size": "1799"}, {"price": "0.07", "size": "9.96"}, {"price": "0.37", "size": "1000"}, {"price": "0.38", "size": "500"}], "asks": [{"price": "0.99", "size": "283"}, {"price": "0.95", "size": "60"}, {"price": "0.94", "size": "10.94"}], "event_type": "book", "last_trade_price": ""}, {"market": "0x699033710f3f9c616fc2c2faa8841e82774faef40be068a28d02ae48d3da5039", "asset_id": "6600280110979446792688496766284105163228498718832706118430734116375831805445", "timestamp": "1769384034780", "hash": "f83eb6ef54141930350e68cdc68699ab0bf0dd17", "bids": [{"price": "0.01", "size": "138.17"}, {"price": "0.02", "size": "5.1"}, {"price": "0.03", "size": "100"}, {"price": "0.04", "size": "5.37"}, {"price": "0.08", "size": "1350"}, {"price": "0.09", "size": "7.01"}, {"price": "0.29", "size": "4496"}, {"price": "0.32", "size": "3552.25"}, {"price": "0.35", "size": "2670"}, {"price": "0.38", "size": "1834"}, {"price": "0.39", "size": "1000"}, {"price": "0.4", "size": "500"}, {"price": "0.41", "size": "1031"}, {"price": "0.42", "size": "1038"}, {"price": "0.43", "size": "2629"}], "asks": [{"price": "0.99", "size": "147.93"}, {"price": "0.97", "size": "100"}, {"price": "0.96", "size": "5.97"}, {"price": "0.91", "size": "1211"}, {"price": "0.9", "size": "6.11"}, {"price": "0.86", "size": "50"}, {"price": "0.8", "size": "200"}, {"price": "0.62", "size": "4192"}, {"price": "0.59", "size": "3350.75"}, {"price": "0.56", "size": "2545"}, {"price": "0.53", "size": "1764"}, {"price": "0.52", "size": "1000"}, {"price": "0.51", "size": "650"}, {"price": "0.5", "size": "1000"}, {"price": "0.49", "size": "1013"}, {"price": "0.48", "size": "2874.7"}, {"price": "0.47", "size": "999"}], "event_type": "book", "last_trade_price": "0.540"}, {"market": "0x3f5cc35560a89e67a91b5e7bd0e00a3c01ad0e07f2deb5a97666b110e43f47f1", "asset_id": "83603974700861762645983613428945838380726029750034095407014914624732138624340", "timestamp": "1769384036208", "hash": "294d54a9d6d9c3e3012c7f583425deafdde96f59", "bids": [{"price": "0.01", "size": "248.09"}, {"price": "0.03", "size": "100"}, {"price": "0.04", "size": "6.1"}, {"price": "0.09", "size": "1211"}, {"price": "0.1", "size": "6.05"}, {"price": "0.14", "size": "50"}, {"price": "0.47", "size": "1000"}, {"price": "0.48", "size": "1150"}, {"price": "0.49", "size": "1030"}], "asks": [{"price": "0.99", "size": "238.23"}, {"price": "0.98", "size": "5"}, {"price": "0.97", "size": "100"}, {"price": "0.96", "size": "6.16"}, {"price": "0.91", "size": "1211"}, {"price": "0.9", "size": "6.01"}, {"price": "0.86", "size": "50"}, {"price": "0.57", "size": "1000"}, {"price": "0.56", "size": "1150"}, {"price": "0.55", "size": "1000"}], "event_type": "book", "last_trade_price": "0.460"}, {"market": "0x548bf24ac69dda721ac2c9f70ddf7d4907ddebfaa552b3c9d90c2ea579759850", "asset_id": "87069058062386204514440746177167230003061183275952307043291532056740705911527", "timestamp": "1769384033000", "hash": "8e14b2f82593d0aca8b7a5b13af2e171c3ced4b2", "bids": [{"price": "0.01", "size": "93046"}, {"price": "0.02", "size": "2300"}, {"price": "0.05", "size": "5"}, {"price": "0.06", "size": "2000"}, {"price": "0.08", "size": "100"}, {"price": "0.09", "size": "23"}, {"price": "0.1", "size": "111.11"}, {"price": "0.13", "size": "800"}, {"price": "0.14", "size": "50"}, {"price": "0.15", "size": "300"}, {"price": "0.16", "size": "625"}, {"price": "0.2", "size": "200"}, {"price": "0.27", "size": "200"}, {"price": "0.28", "size": "200"}, {"price": "0.34", "size": "100"}, {"price": "0.35", "size": "120"}, {"price": "0.4", "size": "225"}, {"price": "0.47", "size": "10000"}, {"price": "0.5", "size": "100"}, {"price": "0.54", "size": "5000"}, {"price": "0.55", "size": "10"}, {"price": "0.56", "size": "2540"}, {"price": "0.6", "size": "418"}, {"price": "0.61", "size": "2500"}, {"price": "0.63", "size": "2000"}, {"price": "0.64", "size": "444.44"}, {"price": "0.69", "size": "1250"}, {"price": "0.7", "size": "220"}, {"price": "0.73", "size": "5.55"}, {"price": "0.74", "size": "5"}, {"price": "0.75", "size": "600"}, {"price": "0.76", "size": "100"}, {"price": "0.77", "size": "2332.8"}, {"price": "0.78", "size": "3803.66"}, {"price": "0.79", "size": "40406.96"}, {"price": "0.8", "size": "27474.77"}, {"price": "0.81", "size": "53124.07"}], "asks": [{"price": "0.99", "size": "88431.53"}, {"price": "0.97", "size": "5841.54"}, {"price": "0.95", "size": "2005"}, {"price": "0.94", "size": "11.16"}, {"price": "0.92", "size": "450"}, {"price": "0.91", "size": "1450"}, {"price": "0.88", "size": "1010"}, {"price": "0.87", "size": "4650"}, {"price": "0.86", "size": "3914.27"}, {"price": "0.85", "size": "47667.62"}, {"price": "0.84", "size": "31465.32"}, {"price": "0.83", "size": "400526.81"}, {"price": "0.82", "size": "39071.46"}], "event_type": "book", "last_trade_price": "0.180"}, {"market": "0xb0b24c09b5764f4958ab0858288d58addde505228fdf2779d4cda72377064bda", "asset_id": "15251809086937127792933578667166031832416982573663896344745613445397107691001", "timestamp": "1769383899003", "hash": "3408e6f4f70a46ab61e444fa64d22b94ec70619d", "bids": [{"price": "0.01", "size": "289.37"}, {"price": "0.02", "size": "13.75"}, {"price": "0.04", "size": "49"}, {"price": "0.05", "size": "60"}, {"price": "0.06", "size": "33"}], "asks": [{"price": "0.99", "size": "297.79"}, {"price": "0.98", "size": "26.15"}, {"price": "0.95", "size": "60"}, {"price": "0.94", "size": "43.95"}], "event_type": "book", "last_trade_price": ""}, {"market": "0x4813bed77c03fbf16137a1a82d6205e681c5182ade34f62019fdf124d1a7ed9b", "asset_id": "60017116045841658588171975127368320820424758610672530610810028757397228532611", "timestamp": "1769384033001", "hash": "6f248855787f97593e1f59c5e137eaa354899fe2", "bids": [{"price": "0.01", "size": "297.79"}, {"price": "0.02", "size": "26.15"}, {"price": "0.05", "size": "60"}, {"price": "0.06", "size": "16.42"}], "asks": [{"price": "0.99", "size": "288.64"}, {"price": "0.97", "size": "100"}, {"price": "0.96", "size": "54.23"}, {"price": "0.95", "size": "60"}, {"price": "0.94", "size": "33"}, {"price": "0.91", "size": "1218.08"}, {"price": "0.86", "size": "50"}, {"price": "0.54", "size": "1000"}, {"price": "0.53", "size": "510.63"}], "event_type": "book", "last_trade_price": ""}, {"market": "0x86feba9d088e90971ca1d898a4c1bd5797b93dd49d1fdd5621b5e1dbab7bab6c", "asset_id": "27514912942320421059111797484653666814872354031839316574031804990218755493417", "timestamp": "1769384033000", "hash": "56e0dfe271acef00c6de8a648d815c10abf99a7d", "bids": [{"price": "0.01", "size": "297.79"}, {"price": "0.02", "size": "26.15"}, {"price": "0.05", "size": "60"}, {"price": "0.06", "size": "10.95"}], "asks": [{"price": "0.99", "size": "288.68"}, {"price": "0.98", "size": "12.26"}, {"price": "0.96", "size": "49"}, {"price": "0.95", "size": "60"}, {"price": "0.94", "size": "1799"}, {"price": "0.93", "size": "9.96"}, {"price": "0.63", "size": "1000"}, {"price": "0.62", "size": "500"}], "event_type": "book", "last_trade_price": ""}, {"market": "0x3f6580efc1ee6c9ccadc46c6a9cec02647b29f6ee3f825708b0bdb07e0ce411e", "asset_id": "115465028598646261292747068550744722498119611179707586190193737079563693789318", "timestamp": "1769384032001", "hash": "244b240f0182a0bb20c8c33afb369a03e73c23ea", "bids": [{"price": "0.01", "size": "288.68"}, {"price": "0.02", "size": "12.26"}, {"price": "0.04", "size": "49"}, {"price": "0.05", "size": "60"}, {"price": "0.06", "size": "1799"}, {"price": "0.07", "size": "9.96"}, {"price": "0.37", "size": "1000"}, {"price": "0.38", "size": "500"}], "asks": [{"price": "0.99", "size": "297.79"}, {"price": "0.98", "size": "26.15"}, {"price": "0.95", "size": "60"}, {"price": "0.94", "size": "16.42"}], "event_type": "book", "last_trade_price": ""}, {"market": "0xacaaef7c9046f6699e1e03914b57bbbe21b4cbf8fb3dcaaf8344ceb8e4b44025", "asset_id": "49448311072592590934852668469118736900980437754784941948093990588399063038511", "timestamp": "1769384032004", "hash": "0a1d80b8537fd9c41aa6245377870d615f261058", "bids": [{"price": "0.01", "size": "296.8"}, {"price": "0.02", "size": "26.53"}, {"price": "0.05", "size": "60"}, {"price": "0.06", "size": "10.99"}], "asks": [{"price": "0.99", "size": "296.45"}, {"price": "0.97", "size": "100"}, {"price": "0.96", "size": "54.38"}, {"price": "0.95", "size": "60"}, {"price": "0.94", "size": "33"}, {"price": "0.91", "size": "1211"}, {"price": "0.9", "size": "6.5"}, {"price": "0.86", "size": "50"}, {"price": "0.79", "size": "200"}, {"price": "0.48", "size": "1000"}, {"price": "0.47", "size": "500"}, {"price": "0.46", "size": "90.25"}], "event_type": "book", "last_trade_price": ""}, {"market": "0xdb343c4acad127a3347d940a9a234e4a34ee0336d5d592d257efd7becc95b78b", "asset_id": "98591285917995444537884769256106664682249607523363808171831009995760685313007", "timestamp": "1769384033001", "hash": "63e6f84504a1f170b3bf0abac0c0f95e06785a27", "bids": [{"price": "0.01", "size": "297.79"}, {"price": "0.02", "size": "26.15"}, {"price": "0.05", "size": "60"}, {"price": "0.06", "size": "16.42"}], "asks": [{"price": "0.99", "size": "288.64"}, {"price": "0.98", "size": "5.23"}, {"price": "0.96", "size": "55.44"}, {"price": "0.95", "size": "60"}, {"price": "0.94", "size": "1799"}, {"price": "0.92", "size": "100"}, {"price": "0.9", "size": "5.8"}, {"price": "0.62", "size": "1000"}, {"price": "0.61", "size": "500"}], "event_type": "book", "last_trade_price": ""}, {"market": "0x4f315c93639e2d5b0ad5afe5b7624a32c9c61712b36a5749a9723f0c866c282c", "asset_id": "100354985105422193069368093808391113026494155802303272252970274070884378086636", "timestamp": "1769384033002", "hash": "2563053cc400e4021f9c4581cb38e4428fc8873c", "bids": [{"price": "0.01", "size": "288.45"}, {"price": "0.02", "size": "5.05"}, {"price": "0.03", "size": "100"}, {"price": "0.04", "size": "55.23"}, {"price": "0.05", "size": "20"}, {"price": "0.06", "size": "33"}, {"price": "0.08", "size": "1350"}, {"price": "0.1", "size": "5.94"}, {"price": "0.41", "size": "1000"}, {"price": "0.42", "size": "500"}, {"price": "0.44", "size": "11.36"}], "asks": [{"price": "0.99", "size": "297.79"}, {"price": "0.98", "size": "13.72"}, {"price": "0.97", "size": "16"}, {"price": "0.96", "size": "6.21"}, {"price": "0.95", "size": "50"}, {"price": "0.94", "size": "10.95"}], "event_type": "book", "last_trade_price": "0.430"}, {"market": "0x3d891c4518177a2d0cdef2b26192198849326e69817fec3ec44b1dd5db382d66", "asset_id": "47152501071153124210643670797073071998156661386350906991394486559609354161760", "timestamp": "1769384032002", "hash": "f368f3b52bf92d574785ef4bec940e661663683e", "bids": [{"price": "0.01", "size": "389.69"}, {"price": "0.02", "size": "50"}, {"price": "0.03", "size": "100"}, {"price": "0.04", "size": "7.65"}, {"price": "0.05", "size": "80"}, {"price": "0.06", "size": "33"}, {"price": "0.08", "size": "1350"}, {"price": "0.1", "size": "6.27"}, {"price": "0.41", "size": "1000"}, {"price": "0.42", "size": "500"}], "asks": [{"price": "0.99", "size": "398.08"}, {"price": "0.98", "size": "20.23"}, {"price": "0.96", "size": "25"}, {"price": "0.94", "size": "10.94"}], "event_type": "book", "last_trade_price": ""}, {"market": "0xc6ff7f8ae1f58824aa11d979b259c782ef25a93a66b73fa37b1f87edaedfad91", "asset_id": "13633497108394864151898342255330331854488146311506893611678517594038032864012", "timestamp": "1769384032002", "hash": "21d357d367172f823403b79e83d4acac37423641", "bids": [{"price": "0.01", "size": "289.54"}, {"price": "0.03", "size": "100"}, {"price": "0.04", "size": "56.48"}, {"price": "0.05", "size": "60"}, {"price": "0.06", "size": "33"}, {"price": "0.08", "size": "1350"}, {"price": "0.1", "size": "6.35"}, {"price": "0.41", "size": "1000"}, {"price": "0.42", "size": "500"}, {"price": "0.43", "size": "11.62"}], "asks": [{"price": "0.99", "size": "297.79"}, {"price": "0.98", "size": "26.15"}, {"price": "0.95", "size": "60"}, {"price": "0.94", "size": "10.95"}], "event_type": "book", "last_trade_price": ""}, {"market": "0x970dab0b74ae35835fef12a63f824a981a2e8bd791d6a5d897d8c198b7a05581", "asset_id": "8409692319788303913925099179209639225305394841680202372226896582540503735241", "timestamp": "1769384032002", "hash": "1bf3405bff72c25d6303c1d779413b7d4ce6bf94", "bids": [{"price": "0.01", "size": "231.5"}, {"price": "0.03", "size": "120"}, {"price": "0.05", "size": "5"}, {"price": "0.09", "size": "1211"}, {"price": "0.19", "size": "10000"}, {"price": "0.24", "size": "5000"}, {"price": "0.29", "size": "2500"}, {"price": "0.33", "size": "1250"}, {"price": "0.4", "size": "1000"}, {"price": "0.41", "size": "2100"}, {"price": "0.42", "size": "1533"}, {"price": "0.43", "size": "39082.11"}, {"price": "0.44", "size": "31151.84"}, {"price": "0.45", "size": "2333.99"}, {"price": "0.46", "size": "5"}], "asks": [{"price": "0.99", "size": "231.5"}, {"price": "0.97", "size": "100"}, {"price": "0.95", "size": "5"}, {"price": "0.91", "size": "1211"}, {"price": "0.86", "size": "50"}, {"price": "0.8", "size": "200"}, {"price": "0.72", "size": "10000"}, {"price": "0.67", "size": "5000"}, {"price": "0.62", "size": "2500"}, {"price": "0.58", "size": "1250"}, {"price": "0.53", "size": "1000"}, {"price": "0.52", "size": "1500"}, {"price": "0.51", "size": "1100"}, {"price": "0.5", "size": "21000"}, {"price": "0.49", "size": "25563.99"}, {"price": "0.48", "size": "10178"}, {"price": "0.47", "size": "17419.84"}], "event_type": "book", "last_trade_price": "0.460"}, {"market": "0x699033710f3f9c616fc2c2faa8841e82774faef40be068a28d02ae48d3da5039", "asset_id": "43393460696979797431541641548274596146619752824207725942315186553106110134984", "timestamp": "1769384034780", "hash": "8d4683c45182af8e1c96eb30ebe0c3ef1e87accc", "bids": [{"price": "0.01", "size": "147.93"}, {"price": "0.03", "size": "100"}, {"price": "0.04", "size": "5.97"}, {"price": "0.09", "size": "1211"}, {"price": "0.1", "size": "6.11"}, {"price": "0.14", "size": "50"}, {"price": "0.2", "size": "200"}, {"price": "0.38", "size": "4192"}, {"price": "0.41", "size": "3350.75"}, {"price": "0.44", "size": "2545"}, {"price": "0.47", "size": "1764"}, {"price": "0.48", "size": "1000"}, {"price": "0.49", "size": "650"}, {"price": "0.5", "size": "1000"}, {"price": "0.51", "size": "1013"}, {"price": "0.52", "size": "2874.7"}, {"price": "0.53", "size": "999"}], "asks": [{"price": "0.99", "size": "138.17"}, {"price": "0.98", "size": "5.1"}, {"price": "0.97", "size": "100"}, {"price": "0.96", "size": "5.37"}, {"price": "0.92", "size": "1350"}, {"price": "0.91", "size": "7.01"}, {"price": "0.71", "size": "4496"}, {"price": "0.68", "size": "3552.25"}, {"price": "0.65", "size": "2670"}, {"price": "0.62", "size": "1834"}, {"price": "0.61", "size": "1000"}, {"price": "0.6", "size": "500"}, {"price": "0.59", "size": "1031"}, {"price": "0.58", "size": "1038"}, {"price": "0.57", "size": "2629"}], "event_type": "book", "last_trade_price": "0.540"}, {"market": "0x1555baa85050bf46a6d9da9c541a846acefc0628617420021491f54f9d500eb6", "asset_id": "61599985294999295036709505701627609233274312766724636571888085254678251971053", "timestamp": "1769384032002", "hash": "5c3c7d61342f39433cf080fbf568d8d1126b31bf", "bids": [{"price": "0.01", "size": "297.79"}, {"price": "0.02", "size": "13.72"}, {"price": "0.03", "size": "16"}, {"price": "0.04", "size": "6.21"}, {"price": "0.05", "size": "50"}, {"price": "0.06", "size": "10.95"}], "asks": [{"price": "0.99", "size": "296.68"}, {"price": "0.97", "size": "100"}, {"price": "0.96", "size": "54.47"}, {"price": "0.95", "size": "60"}, {"price": "0.94", "size": "33"}, {"price": "0.91", "size": "1211"}, {"price": "0.9", "size": "6.44"}, {"price": "0.86", "size": "50"}, {"price": "0.54", "size": "1000"}, {"price": "0.53", "size": "500"}, {"price": "0.52", "size": "10.41"}], "event_type": "book", "last_trade_price": ""}, {"market": "0x79ad62045cfccd5ee44c4b5524c882ae48b39a7361c3aff3aeab4ad60eff1641", "asset_id": "114811066368334224522427598750458344638137949385141925744534308089744998037607", "timestamp": "1769384032003", "hash": "500f28e9db72202695d0ee5d40482dc51d1ad029", "bids": [{"price": "0.01", "size": "296.68"}, {"price": "0.03", "size": "100"}, {"price": "0.04", "size": "54.47"}, {"price": "0.05", "size": "60"}, {"price": "0.06", "size": "33"}, {"price": "0.09", "size": "1211"}, {"price": "0.1", "size": "6.44"}, {"price": "0.14", "size": "50"}, {"price": "0.21", "size": "200"}, {"price": "0.52", "size": "1000"}, {"price": "0.53", "size": "500"}, {"price": "0.54", "size": "67.25"}], "asks": [{"price": "0.99", "size": "296.83"}, {"price": "0.98", "size": "26.58"}, {"price": "0.95", "size": "60"}, {"price": "0.94", "size": "10.97"}], "event_type": "book", "last_trade_price": ""}, {"market": "0x78ba1e90813a5437dea6ab7a7aeca53f910f3b5cecc5b5b2cbafe3ec3c3aeb57", "asset_id": "31355627987268222126547396163770855213217371487708271104745934082289374931694", "timestamp": "1769384033000", "hash": "8eb18a19ce697fd02452a45150c3e74063a4aaad", "bids": [{"price": "0.01", "size": "388.64"}, {"price": "0.02", "size": "5.23"}, {"price": "0.03", "size": "33"}, {"price": "0.04", "size": "6.44"}, {"price": "0.05", "size": "80"}, {"price": "0.06", "size": "1799"}, {"price": "0.08", "size": "100"}, {"price": "0.1", "size": "5.8"}, {"price": "0.38", "size": "1000"}, {"price": "0.39", "size": "500"}], "asks": [{"price": "0.99", "size": "398"}, {"price": "0.98", "size": "20.19"}, {"price": "0.96", "size": "25"}, {"price": "0.94", "size": "10.94"}], "event_type": "book", "last_trade_price": ""}, {"market": "0x268802a47370bb01163109f0e99a74043188847bd8c8978bf0ea913a982f1482", "asset_id": "107134792750941221686929312836830406685277398311446256346745836986234138404858", "timestamp": "1769383899000", "hash": "7ea06ee405b19b6ccf652b74028271f9713453b5", "bids": [{"price": "0.01", "size": "293.6"}, {"price": "0.02", "size": "13.53"}, {"price": "0.04", "size": "55.12"}, {"price": "0.05", "size": "60"}, {"price": "0.06", "size": "38.4"}], "asks": [{"price": "0.99", "size": "297.79"}, {"price": "0.98", "size": "26.15"}, {"price": "0.95", "size": "60"}, {"price": "0.94", "size": "10.95"}], "event_type": "book", "last_trade_price": ""}, {"market": "0x553717c180334e4b0693f864252ccaf7cb71b8be4c4c864e3dd3d6426c737a15", "asset_id": "57896995315976252262711688210496860966105380178462732161329389639530526897936", "timestamp": "1769384032002", "hash": "94d4e22b74c34203252c01a4c5a0081e891aa640", "bids": [{"price": "0.01", "size": "297.79"}, {"price": "0.02", "size": "26.15"}, {"price": "0.05", "size": "60"}, {"price": "0.06", "size": "10.95"}], "asks": [{"price": "0.99", "size": "298.69"}, {"price": "0.98", "size": "9.81"}, {"price": "0.96", "size": "2549"}, {"price": "0.95", "size": "60"}, {"price": "0.94", "size": "33"}, {"price": "0.93", "size": "9.24"}, {"price": "0.77", "size": "1000"}, {"price": "0.76", "size": "500"}], "event_type": "book", "last_trade_price": "0.430"}, {"market": "0x548bf24ac69dda721ac2c9f70ddf7d4907ddebfaa552b3c9d90c2ea579759850", "asset_id": "51674227959772201692995587953323756294034141098159045110117222361966129767794", "timestamp": "1769384033000", "hash": "e47b2a9bd908f75d3c6cc6583ecce08488a3b28b", "bids": [{"price": "0.01", "size": "88431.53"}, {"price": "0.03", "size": "5841.54"}, {"price": "0.05", "size": "2005"}, {"price": "0.06", "size": "11.16"}, {"price": "0.08", "size": "450"}, {"price": "0.09", "size": "1450"}, {"price": "0.12", "size": "1010"}, {"price": "0.13", "size": "4650"}, {"price": "0.14", "size": "3914.27"}, {"price": "0.15", "size": "47667.62"}, {"price": "0.16", "size": "31465.32"}, {"price": "0.17", "size": "400526.81"}, {"price": "0.18", "size": "39071.46"}], "asks": [{"price": "0.99", "size": "93046"}, {"price": "0.98", "size": "2300"}, {"price": "0.95", "size": "5"}, {"price": "0.94", "size": "2000"}, {"price": "0.92", "size": "100"}, {"price": "0.91", "size": "23"}, {"price": "0.9", "size": "111.11"}, {"price": "0.87", "size": "800"}, {"price": "0.86", "size": "50"}, {"price": "0.85", "size": "300"}, {"price": "0.84", "size": "625"}, {"price": "0.8", "size": "200"}, {"price": "0.73", "size": "200"}, {"price": "0.72", "size": "200"}, {"price": "0.66", "size": "100"}, {"price": "0.65", "size": "120"}, {"price": "0.6", "size": "225"}, {"price": "0.53", "size": "10000"}, {"price": "0.5", "size": "100"}, {"price": "0.46", "size": "5000"}, {"price": "0.45", "size": "10"}, {"price": "0.44", "size": "2540"}, {"price": "0.4", "size": "418"}, {"price": "0.39", "size": "2500"}, {"price": "0.37", "size": "2000"}, {"price": "0.36", "size": "444.44"}, {"price": "0.31", "size": "1250"}, {"price": "0.3", "size": "220"}, {"price": "0.27", "size": "5.55"}, {"price": "0.26", "size": "5"}, {"price": "0.25", "size": "600"}, {"price": "0.24", "size": "100"}, {"price": "0.23", "size": "2332.8"}, {"price": "0.22", "size": "3803.66"}, {"price": "0.21", "size": "40406.96"}, {"price": "0.2", "size": "27474.77"}, {"price": "0.19", "size": "53124.07"}], "event_type": "book", "last_trade_price": "0.180"}, {"market": "0x4aeb687ccd1da9f19d15cb7d6f820fe079af3c856f9104f42d46943ca45b27bd", "asset_id": "31999400366734158104301855635228245130465493243805955843366583423501887482170", "timestamp": "1769384036306", "hash": "7f4ff44c2fe243d2270edde90d751e71523631cb", "bids": [{"price": "0.01", "size": "238.39"}, {"price": "0.02", "size": "5"}, {"price": "0.03", "size": "100"}, {"price": "0.04", "size": "6.16"}, {"price": "0.09", "size": "1211"}, {"price": "0.1", "size": "5.99"}, {"price": "0.14", "size": "50"}, {"price": "0.43", "size": "2000"}, {"price": "0.44", "size": "1762"}, {"price": "0.45", "size": "5224"}, {"price": "0.46", "size": "3033"}, {"price": "0.49", "size": "5"}], "asks": [{"price": "0.99", "size": "248.31"}, {"price": "0.97", "size": "100"}, {"price": "0.96", "size": "6.13"}, {"price": "0.91", "size": "1211"}, {"price": "0.9", "size": "6.01"}, {"price": "0.86", "size": "50"}, {"price": "0.54", "size": "1000"}, {"price": "0.53", "size": "1500"}, {"price": "0.52", "size": "4177"}, {"price": "0.51", "size": "5093.99"}, {"price": "0.5", "size": "10"}], "event_type": "book", "last_trade_price": "0.450"}, {"market": "0xda9010c105fc532855d1427afbb54bac3a872106b13d70541948524bf3c1f13e", "asset_id": "78315379118406859624973110495963480819305867678789445335779496010870936073394", "timestamp": "1769384032002", "hash": "0ac16c3d3d7b4e6fac5720fed3bf005ce7275613", "bids": [{"price": "0.01", "size": "293.8"}, {"price": "0.02", "size": "19.1"}, {"price": "0.05", "size": "60"}, {"price": "0.06", "size": "13.96"}, {"price": "0.11", "size": "10"}], "asks": [{"price": "0.99", "size": "289.27"}, {"price": "0.98", "size": "13.54"}, {"price": "0.96", "size": "49"}, {"price": "0.95", "size": "2160"}, {"price": "0.94", "size": "33"}, {"price": "0.93", "size": "9.51"}, {"price": "0.72", "size": "1000"}, {"price": "0.71", "size": "500"}], "event_type": "book", "last_trade_price": "0.490"}, {"market": "0xd96573e2b56ec287fb0d47bf9014186c1e4f99702dda924fd8d9b60941cf26a6", "asset_id": "98488092907000911031005324087845962957388487171241715258741738454368088401315", "timestamp": "1769384036106", "hash": "569a3232868bccc9c56690139ff8953d3751c693", "bids": [{"price": "0.01", "size": "231.5"}, {"price": "0.03", "size": "100"}, {"price": "0.09", "size": "1211"}, {"price": "0.1", "size": "6.44"}, {"price": "0.14", "size": "50"}, {"price": "0.26", "size": "10000"}, {"price": "0.32", "size": "5000"}, {"price": "0.38", "size": "2500"}, {"price": "0.43", "size": "1250"}, {"price": "0.45", "size": "10"}, {"price": "0.46", "size": "1000"}, {"price": "0.47", "size": "1100"}, {"price": "0.48", "size": "2305"}, {"price": "0.49", "size": "3907.79"}, {"price": "0.5", "size": "13742"}, {"price": "0.51", "size": "13998.56"}, {"price": "0.52", "size": "11"}], "asks": [{"price": "0.99", "size": "237.93"}, {"price": "0.97", "size": "100"}, {"price": "0.96", "size": "7.66"}, {"price": "0.91", "size": "1211"}, {"price": "0.9", "size": "6.29"}, {"price": "0.86", "size": "50"}, {"price": "0.79", "size": "10000"}, {"price": "0.74", "size": "5000"}, {"price": "0.7", "size": "2500"}, {"price": "0.65", "size": "1250"}, {"price": "0.61", "size": "10"}, {"price": "0.59", "size": "1000"}, {"price": "0.58", "size": "1038"}, {"price": "0.57", "size": "3053"}, {"price": "0.56", "size": "11824.36"}, {"price": "0.55", "size": "12380.87"}, {"price": "0.54", "size": "12146.69"}], "event_type": "book", "last_trade_price": "0.540"}, {"market": "0xce87eb2516a5b532103a2135f1554236094e90dd3d9de97bfdbadc71354b3465", "asset_id": "113873798648996768464994374356614188404101228550867358872123015702830202946444", "timestamp": "1769384032003", "hash": "e68b0e6bbdcddc809661869de111f5ef5e3054ae", "bids": [{"price": "0.01", "size": "297.79"}, {"price": "0.02", "size": "26.15"}, {"price": "0.05", "size": "60"}, {"price": "0.06", "size": "10.95"}], "asks": [{"price": "0.99", "size": "288.84"}, {"price": "0.98", "size": "12.6"}, {"price": "0.96", "size": "49"}, {"price": "0.95", "size": "60"}, {"price": "0.94", "size": "1799"}, {"price": "0.93", "size": "9.84"}, {"price": "0.66", "size": "1000"}, {"price": "0.65", "size": "500"}], "event_type": "book", "last_trade_price": ""}, {"market": "0xb0b24c09b5764f4958ab0858288d58addde505228fdf2779d4cda72377064bda", "asset_id": "38127565379022096662358589007723974479791965443771108093757330785553900690892", "timestamp": "1769383899003", "hash": "4ad51a6651f42dc3f551d3e27f5204ce5bb47f7c", "bids": [{"price": "0.01", "size": "297.79"}, {"price": "0.02", "size": "26.15"}, {"price": "0.05", "size": "60"}, {"price": "0.06", "size": "43.95"}], "asks": [{"price": "0.99", "size": "289.37"}, {"price": "0.98", "size": "13.75"}, {"price": "0.96", "size": "49"}, {"price": "0.95", "size": "60"}, {"price": "0.94", "size": "33"}], "event_type": "book", "last_trade_price": ""}, {"market": "0xbf3100d84bfd1b4d2936ceb8dd3a29a65f1ad9f00f135636255eef0b5bdbe359", "asset_id": "56104088600014710064818932436571644113019907992309555438937676208970391548401", "timestamp": "1769384032002", "hash": "d4e599562f806c72c3cbeafd16f096bdd349fce8", "bids": [{"price": "0.01", "size": "180"}, {"price": "0.03", "size": "100"}, {"price": "0.08", "size": "100"}, {"price": "0.14", "size": "764"}, {"price": "0.2", "size": "200"}, {"price": "0.27", "size": "200"}, {"price": "0.34", "size": "100"}, {"price": "0.59", "size": "3956"}, {"price": "0.62", "size": "3217.5"}, {"price": "0.65", "size": "2482.5"}, {"price": "0.68", "size": "1748.25"}, {"price": "0.69", "size": "150"}, {"price": "0.7", "size": "1000"}, {"price": "0.71", "size": "2708"}, {"price": "0.72", "size": "2028"}, {"price": "0.73", "size": "3849"}], "asks": [{"price": "0.99", "size": "180"}, {"price": "0.98", "size": "5000"}, {"price": "0.92", "size": "8248"}, {"price": "0.91", "size": "6.89"}, {"price": "0.89", "size": "5538"}, {"price": "0.86", "size": "3752.5"}, {"price": "0.83", "size": "2397.5"}, {"price": "0.82", "size": "1000"}, {"price": "0.81", "size": "500"}, {"price": "0.8", "size": "2280"}, {"price": "0.79", "size": "2273"}, {"price": "0.78", "size": "6000.5"}, {"price": "0.77", "size": "150"}, {"price": "0.76", "size": "500"}], "event_type": "book", "last_trade_price": "0.740"}, {"market": "0x3d891c4518177a2d0cdef2b26192198849326e69817fec3ec44b1dd5db382d66", "asset_id": "102869039310147156187992762631729075600982777916006979703835908426915768394637", "timestamp": "1769384032002", "hash": "f83b9001bbec35fcae2c6b0e700436609b51bad6", "bids": [{"price": "0.01", "size": "398.08"}, {"price": "0.02", "size": "20.23"}, {"price": "0.04", "size": "25"}, {"price": "0.06", "size": "10.94"}], "asks": [{"price": "0.99", "size": "389.69"}, {"price": "0.98", "size": "50"}, {"price": "0.97", "size": "100"}, {"price": "0.96", "size": "7.65"}, {"price": "0.95", "size": "80"}, {"price": "0.94", "size": "33"}, {"price": "0.92", "size": "1350"}, {"price": "0.9", "size": "6.27"}, {"price": "0.59", "size": "1000"}, {"price": "0.58", "size": "500"}], "event_type": "book", "last_trade_price": ""}, {"market": "0xbeaaa3c19d9c2146bde70ce718dbe0bb8f4e0fb890d4db8d7ff8597a55b362bd", "asset_id": "114418909511071455670546163939010026272317267800095643774931937235891349628437", "timestamp": "1769384032001", "hash": "ba50b58b842a0988afd377f76d3e15bb9821927a", "bids": [{"price": "0.01", "size": "297.79"}, {"price": "0.02", "size": "26.15"}, {"price": "0.05", "size": "60"}, {"price": "0.06", "size": "10.95"}], "asks": [{"price": "0.99", "size": "283"}, {"price": "0.97", "size": "100"}, {"price": "0.96", "size": "54.17"}, {"price": "0.95", "size": "60"}, {"price": "0.94", "size": "33"}, {"price": "0.91", "size": "1211"}, {"price": "0.9", "size": "6.39"}, {"price": "0.86", "size": "50"}, {"price": "0.54", "size": "1000"}, {"price": "0.53", "size": "500"}, {"price": "0.52", "size": "10.41"}], "event_type": "book", "last_trade_price": "0.480"}, {"market": "0x4f315c93639e2d5b0ad5afe5b7624a32c9c61712b36a5749a9723f0c866c282c", "asset_id": "98740776252092008701353754345596258230814172513568009801637691746881492989205", "timestamp": "1769384033002", "hash": "a497c391bd0d19b815b02d6341c2cc5aebc9d107", "bids": [{"price": "0.01", "size": "297.79"}, {"price": "0.02", "size": "13.72"}, {"price": "0.03", "size": "16"}, {"price": "0.04", "size": "6.21"}, {"price": "0.05", "size": "50"}, {"price": "0.06", "size": "10.95"}], "asks": [{"price": "0.99", "size": "288.45"}, {"price": "0.98", "size": "5.05"}, {"price": "0.97", "size": "100"}, {"price": "0.96", "size": "55.23"}, {"price": "0.95", "size": "20"}, {"price": "0.94", "size": "33"}, {"price": "0.92", "size": "1350"}, {"price": "0.9", "size": "5.94"}, {"price": "0.59", "size": "1000"}, {"price": "0.58", "size": "500"}, {"price": "0.56", "size": "11.36"}], "event_type": "book", "last_trade_price": "0.430"}, {"market": "0xc321c61a4e4789503e1a312aeddfaa3a397b4096a859060223a0e276b724928a", "asset_id": "47639675551386288248370262662490783411705761858149174878754249181330435993189", "timestamp": "1769384033000", "hash": "a0ce0d99d9f4d13b08bdd4372396ef7bdb9c8cce", "bids": [{"price": "0.01", "size": "297.79"}, {"price": "0.02", "size": "26.15"}, {"price": "0.05", "size": "60"}, {"price": "0.06", "size": "10.95"}], "asks": [{"price": "0.99", "size": "283"}, {"price": "0.97", "size": "100"}, {"price": "0.96", "size": "49"}, {"price": "0.95", "size": "60"}, {"price": "0.94", "size": "33"}, {"price": "0.92", "size": "1350"}, {"price": "0.57", "size": "1000"}, {"price": "0.56", "size": "500"}, {"price": "0.55", "size": "11.11"}], "event_type": "book", "last_trade_price": "0.470"}, {"market": "0x027f856eb641875fd5d007085b8b821bb362cd6f1c03692e4bdced63d2b25a4b", "asset_id": "20255608086370617665171362197949393811510991087198640550304707929145511040025", "timestamp": "1769384032000", "hash": "295a7a5db4f548954fa19aa9721f194639c47de6", "bids": [{"price": "0.01", "size": "397.79"}, {"price": "0.02", "size": "26.15"}, {"price": "0.05", "size": "20"}, {"price": "0.06", "size": "10.95"}], "asks": [{"price": "0.99", "size": "393.74"}, {"price": "0.98", "size": "50"}, {"price": "0.97", "size": "10.85"}, {"price": "0.95", "size": "80"}, {"price": "0.94", "size": "1799"}, {"price": "0.92", "size": "100"}, {"price": "0.9", "size": "5.67"}, {"price": "0.62", "size": "1000"}, {"price": "0.61", "size": "500"}], "event_type": "book", "last_trade_price": "0.410"}, {"market": "0x78ba1e90813a5437dea6ab7a7aeca53f910f3b5cecc5b5b2cbafe3ec3c3aeb57", "asset_id": "49463105653994466683943093343279734251397612176513055641839956156740014377972", "timestamp": "1769384033000", "hash": "566b10684898503b169efdf8e3b02dea04e31f9f", "bids": [{"price": "0.01", "size": "398"}, {"price": "0.02", "size": "20.19"}, {"price": "0.04", "size": "25"}, {"price": "0.06", "size": "10.94"}], "asks": [{"price": "0.99", "size": "388.64"}, {"price": "0.98", "size": "5.23"}, {"price": "0.97", "size": "33"}, {"price": "0.96", "size": "6.44"}, {"price": "0.95", "size": "80"}, {"price": "0.94", "size": "1799"}, {"price": "0.92", "size": "100"}, {"price": "0.9", "size": "5.8"}, {"price": "0.62", "size": "1000"}, {"price": "0.61", "size": "500"}], "event_type": "book", "last_trade_price": ""}, {"market": "0x3f5cc35560a89e67a91b5e7bd0e00a3c01ad0e07f2deb5a97666b110e43f47f1", "asset_id": "78603243324556293353878442880948079627049482267281633215349873153372325985260", "timestamp": "1769384036208", "hash": "8182131b4c7d8ee5feba44263347334fffec29e0", "bids": [{"price": "0.01", "size": "238.23"}, {"price": "0.02", "size": "5"}, {"price": "0.03", "size": "100"}, {"price": "0.04", "size": "6.16"}, {"price": "0.09", "size": "1211"}, {"price": "0.1", "size": "6.01"}, {"price": "0.14", "size": "50"}, {"price": "0.43", "size": "1000"}, {"price": "0.44", "size": "1150"}, {"price": "0.45", "size": "1000"}], "asks": [{"price": "0.99", "size": "248.09"}, {"price": "0.97", "size": "100"}, {"price": "0.96", "size": "6.1"}, {"price": "0.91", "size": "1211"}, {"price": "0.9", "size": "6.05"}, {"price": "0.86", "size": "50"}, {"price": "0.53", "size": "1000"}, {"price": "0.52", "size": "1150"}, {"price": "0.51", "size": "1030"}], "event_type": "book", "last_trade_price": "0.460"}, {"market": "0x03464779bdf4de0a3ebd602b9eef80d7822f6258b52e83508e391ee18d4668eb", "asset_id": "27139615157740269866908006833759826848004875655274435602141899025932234359266", "timestamp": "1769384032004", "hash": "cf679b40eb7acc1372ffbaa96cefabafafd0f757", "bids": [{"price": "0.01", "size": "297.79"}, {"price": "0.02", "size": "26.15"}, {"price": "0.05", "size": "100"}, {"price": "0.06", "size": "10.95"}], "asks": [{"price": "0.99", "size": "288.9"}, {"price": "0.98", "size": "12.73"}, {"price": "0.96", "size": "49"}, {"price": "0.95", "size": "60"}, {"price": "0.94", "size": "1799"}, {"price": "0.93", "size": "9.8"}, {"price": "0.67", "size": "1000"}, {"price": "0.66", "size": "500"}], "event_type": "book", "last_trade_price": ""}, {"market": "0x3f9017bb85500ceb6e6d2386b9c7e5887d55d0440abd8ed43d17eab892c20b7b", "asset_id": "54355654810669966953019851931697565992077496147803498797699491383578754798343", "timestamp": "1769384032002", "hash": "31debbf7ea258487d545c1a23ccc4afe7b499673", "bids": [{"price": "0.01", "size": "297.79"}, {"price": "0.02", "size": "26.15"}, {"price": "0.05", "size": "60"}, {"price": "0.06", "size": "16.42"}], "asks": [{"price": "0.99", "size": "288.52"}, {"price": "0.98", "size": "5.12"}, {"price": "0.97", "size": "100"}, {"price": "0.96", "size": "55.31"}, {"price": "0.95", "size": "60"}, {"price": "0.94", "size": "33"}, {"price": "0.92", "size": "1350"}, {"price": "0.9", "size": "5.89"}, {"price": "0.6", "size": "1000"}, {"price": "0.59", "size": "500"}, {"price": "0.58", "size": "11.9"}], "event_type": "book", "last_trade_price": ""}, {"market": "0xe20347279d1e95825b4a4156680ce2adffee4ec693635d3a251d993880d47d8a", "asset_id": "85403516720171167773566543912461162711370406995858075142351224114108329589213", "timestamp": "1769384035372", "hash": "e0eac7b3d99659459c7fd964b59c76dfd00a400d", "bids": [{"price": "0.01", "size": "238.39"}, {"price": "0.02", "size": "5"}, {"price": "0.03", "size": "100"}, {"price": "0.04", "size": "6.16"}, {"price": "0.09", "size": "1211"}, {"price": "0.1", "size": "5.99"}, {"price": "0.14", "size": "50"}, {"price": "0.23", "size": "10000"}, {"price": "0.28", "size": "5000"}, {"price": "0.31", "size": "2500"}, {"price": "0.34", "size": "4304"}, {"price": "0.37", "size": "3425.5"}, {"price": "0.38", "size": "1250"}, {"price": "0.4", "size": "2592.5"}, {"price": "0.43", "size": "1788.5"}, {"price": "0.44", "size": "1033"}, {"price": "0.45", "size": "2422"}, {"price": "0.46", "size": "11712.61"}, {"price": "0.47", "size": "14929.45"}, {"price": "0.48", "size": "14689.67"}, {"price": "0.49", "size": "1000"}], "asks": [{"price": "0.99", "size": "233"}, {"price": "0.97", "size": "114"}, {"price": "0.91", "size": "1211"}, {"price": "0.86", "size": "50"}, {"price": "0.76", "size": "10000"}, {"price": "0.7", "size": "5000"}, {"price": "0.66", "size": "4304"}, {"price": "0.64", "size": "2500"}, {"price": "0.63", "size": "3425.5"}, {"price": "0.6", "size": "2592.5"}, {"price": "0.59", "size": "1250"}, {"price": "0.57", "size": "1788.5"}, {"price": "0.56", "size": "1000"}, {"price": "0.55", "size": "2100"}, {"price": "0.54", "size": "9095.52"}, {"price": "0.53", "size": "3272"}, {"price": "0.52", "size": "12893.24"}, {"price": "0.51", "size": "9144.44"}, {"price": "0.5", "size": "1452.88"}], "event_type": "book", "last_trade_price": "0.510"}, {"market": "0x276feb4e6900616b8bcc16cb8ed3999c9f1b4c8d787a6e39c64eae8a56331785", "asset_id": "9805663437273261911623793336871785235625194636606276182840463401876316400402", "timestamp": "1769384033000", "hash": "0b8aa21d452a0f997761ef941d1b6a7f3ab280ee", "bids": [{"price": "0.01", "size": "297.79"}, {"price": "0.02", "size": "26.15"}, {"price": "0.05", "size": "60"}, {"price": "0.06", "size": "10.95"}], "asks": [{"price": "0.99", "size": "296.79"}, {"price": "0.97", "size": "100"}, {"price": "0.96", "size": "54.52"}, {"price": "0.95", "size": "60"}, {"price": "0.94", "size": "33"}, {"price": "0.91", "size": "1211"}, {"price": "0.9", "size": "6.41"}, {"price": "0.86", "size": "50"}, {"price": "0.53", "size": "1000"}, {"price": "0.52", "size": "510.41"}], "event_type": "book", "last_trade_price": ""}, {"market": "0xc60d873e8bc171516c3631a8a31cc254cced6f2f3402e3c0a40475cab007b3c3", "asset_id": "107074978358193625457427782320573845396027159383434708562159503922684086133798", "timestamp": "1769384032001", "hash": "57a6661e7f91ca48331e16affa56ace6bb88387f", "bids": [{"price": "0.01", "size": "397.79"}, {"price": "0.02", "size": "26.15"}, {"price": "0.05", "size": "20"}, {"price": "0.06", "size": "16.42"}], "asks": [{"price": "0.99", "size": "388.42"}, {"price": "0.98", "size": "55.03"}, {"price": "0.97", "size": "100"}, {"price": "0.96", "size": "5.29"}, {"price": "0.95", "size": "80"}, {"price": "0.94", "size": "33"}, {"price": "0.92", "size": "1350"}, {"price": "0.91", "size": "7.03"}, {"price": "0.57", "size": "1000"}, {"price": "0.56", "size": "500"}, {"price": "0.55", "size": "11.11"}], "event_type": "book", "last_trade_price": ""}, {"market": "0x276feb4e6900616b8bcc16cb8ed3999c9f1b4c8d787a6e39c64eae8a56331785", "asset_id": "7423607558283097154922229155464812895905397994692604969007056718754573875966", "timestamp": "1769384033000", "hash": "d9b1cbf265a54c19c39070f29524e994595ce4ea", "bids": [{"price": "0.01", "size": "296.79"}, {"price": "0.03", "size": "100"}, {"price": "0.04", "size": "54.52"}, {"price": "0.05", "size": "60"}, {"price": "0.06", "size": "33"}, {"price": "0.09", "size": "1211"}, {"price": "0.1", "size": "6.41"}, {"price": "0.14", "size": "50"}, {"price": "0.47", "size": "1000"}, {"price": "0.48", "size": "510.41"}], "asks": [{"price": "0.99", "size": "297.79"}, {"price": "0.98", "size": "26.15"}, {"price": "0.95", "size": "60"}, {"price": "0.94", "size": "10.95"}], "event_type": "book", "last_trade_price": ""}, {"market": "0x72d347777d7cd1a36b33d82ee33e8647d979b8e97d7870f290e585068e2eaf18", "asset_id": "18064383735028350165016189664106232638333255077909753138952756695769424263258", "timestamp": "1769384033000", "hash": "c4ead903bbb4151ab0517b81e25931d2bce6b486", "bids": [{"price": "0.01", "size": "398.24"}, {"price": "0.02", "size": "50"}, {"price": "0.03", "size": "100"}, {"price": "0.04", "size": "6.1"}, {"price": "0.05", "size": "80"}, {"price": "0.06", "size": "33"}, {"price": "0.09", "size": "1211"}, {"price": "0.1", "size": "6.03"}, {"price": "0.14", "size": "50"}, {"price": "0.46", "size": "1000"}, {"price": "0.47", "size": "500"}, {"price": "0.48", "size": "10.41"}], "asks": [{"price": "0.99", "size": "383"}, {"price": "0.95", "size": "20"}, {"price": "0.94", "size": "10.94"}], "event_type": "book", "last_trade_price": ""}, {"market": "0x368753e3efb08f97336ad250758db1269b06a1ba8b3c8ec95a9a3cb9376a6922", "asset_id": "76238761818901615467747373039887925717004845403263853385609995415726570741554", "timestamp": "1769384032005", "hash": "c63b96c73bcdfccf0e3349754913cce0f566f006", "bids": [{"price": "0.01", "size": "383"}, {"price": "0.03", "size": "133"}, {"price": "0.05", "size": "80"}, {"price": "0.06", "size": "33"}, {"price": "0.09", "size": "1211"}, {"price": "0.14", "size": "50"}, {"price": "0.47", "size": "1000"}, {"price": "0.48", "size": "500"}, {"price": "0.49", "size": "10.2"}], "asks": [{"price": "0.99", "size": "397.79"}, {"price": "0.98", "size": "26.15"}, {"price": "0.95", "size": "20"}, {"price": "0.94", "size": "10.95"}, {"price": "0.93", "size": "5.47"}], "event_type": "book", "last_trade_price": ""}, {"market": "0xacaaef7c9046f6699e1e03914b57bbbe21b4cbf8fb3dcaaf8344ceb8e4b44025", "asset_id": "115334701046031659857669574453521035737847405682323794956661930269033800746444", "timestamp": "1769384032004", "hash": "0916561ab0a9e3c761856dba3b6feb14a4c99f7e", "bids": [{"price": "0.01", "size": "296.45"}, {"price": "0.03", "size": "100"}, {"price": "0.04", "size": "54.38"}, {"price": "0.05", "size": "60"}, {"price": "0.06", "size": "33"}, {"price": "0.09", "size": "1211"}, {"price": "0.1", "size": "6.5"}, {"price": "0.14", "size": "50"}, {"price": "0.21", "size": "200"}, {"price": "0.52", "size": "1000"}, {"price": "0.53", "size": "500"}, {"price": "0.54", "size": "90.25"}], "asks": [{"price": "0.99", "size": "296.8"}, {"price": "0.98", "size": "26.53"}, {"price": "0.95", "size": "60"}, {"price": "0.94", "size": "10.99"}], "event_type": "book", "last_trade_price": ""}, {"market": "0xbf3100d84bfd1b4d2936ceb8dd3a29a65f1ad9f00f135636255eef0b5bdbe359", "asset_id": "17231604872299400939311521877066387175626533356330458345531604304528475721436", "timestamp": "1769384032002", "hash": "106cc7bc4d6104086a8d29690e5a8601ec41b88d", "bids": [{"price": "0.01", "size": "180"}, {"price": "0.02", "size": "5000"}, {"price": "0.08", "size": "8248"}, {"price": "0.09", "size": "6.89"}, {"price": "0.11", "size": "5538"}, {"price": "0.14", "size": "3752.5"}, {"price": "0.17", "size": "2397.5"}, {"price": "0.18", "size": "1000"}, {"price": "0.19", "size": "500"}, {"price": "0.2", "size": "2280"}, {"price": "0.21", "size": "2273"}, {"price": "0.22", "size": "6000.5"}, {"price": "0.23", "size": "150"}, {"price": "0.24", "size": "500"}], "asks": [{"price": "0.99", "size": "180"}, {"price": "0.97", "size": "100"}, {"price": "0.92", "size": "100"}, {"price": "0.86", "size": "764"}, {"price": "0.8", "size": "200"}, {"price": "0.73", "size": "200"}, {"price": "0.66", "size": "100"}, {"price": "0.41", "size": "3956"}, {"price": "0.38", "size": "3217.5"}, {"price": "0.35", "size": "2482.5"}, {"price": "0.32", "size": "1748.25"}, {"price": "0.31", "size": "150"}, {"price": "0.3", "size": "1000"}, {"price": "0.29", "size": "2708"}, {"price": "0.28", "size": "2028"}, {"price": "0.27", "size": "3849"}], "event_type": "book", "last_trade_price": "0.740"}, {"market": "0xda9010c105fc532855d1427afbb54bac3a872106b13d70541948524bf3c1f13e", "asset_id": "54156514034087263487569029617230664616612015268241749973657295711641068204713", "timestamp": "1769384032002", "hash": "c9071359d1664181a0041a12a802d97af36e6fb8", "bids": [{"price": "0.01", "size": "289.27"}, {"price": "0.02", "size": "13.54"}, {"price": "0.04", "size": "49"}, {"price": "0.05", "size": "2160"}, {"price": "0.06", "size": "33"}, {"price": "0.07", "size": "9.51"}, {"price": "0.28", "size": "1000"}, {"price": "0.29", "size": "500"}], "asks": [{"price": "0.99", "size": "293.8"}, {"price": "0.98", "size": "19.1"}, {"price": "0.95", "size": "60"}, {"price": "0.94", "size": "13.96"}, {"price": "0.89", "size": "10"}], "event_type": "book", "last_trade_price": "0.490"}, {"market": "0xce87eb2516a5b532103a2135f1554236094e90dd3d9de97bfdbadc71354b3465", "asset_id": "88608754828258084988933745325690635842462641669820818068243390744454078703539", "timestamp": "1769384032003", "hash": "f45d2bb44adbd4b2521e65d6026f6ba5d33f9c7b", "bids": [{"price": "0.01", "size": "288.84"}, {"price": "0.02", "size": "12.6"}, {"price": "0.04", "size": "49"}, {"price": "0.05", "size": "60"}, {"price": "0.06", "size": "1799"}, {"price": "0.07", "size": "9.84"}, {"price": "0.34", "size": "1000"}, {"price": "0.35", "size": "500"}], "asks": [{"price": "0.99", "size": "297.79"}, {"price": "0.98", "size": "26.15"}, {"price": "0.95", "size": "60"}, {"price": "0.94", "size": "10.95"}], "event_type": "book", "last_trade_price": ""}, {"market": "0xdb478719e450e8668c1b1f4277cb277337eeb28e3187893b2cf9274606acdc10", "asset_id": "30360992174849273502988106860990606977917338461653496359799172209662656370135", "timestamp": "1769384032001", "hash": "e2eaa4bfaf64a3a7a35e949e2124ac90e0febf70", "bids": [{"price": "0.01", "size": "298.31"}, {"price": "0.03", "size": "100"}, {"price": "0.04", "size": "55.13"}, {"price": "0.05", "size": "60"}, {"price": "0.06", "size": "33"}, {"price": "0.09", "size": "1211"}, {"price": "0.1", "size": "6.01"}, {"price": "0.14", "size": "50"}, {"price": "0.45", "size": "1000"}, {"price": "0.46", "size": "500"}, {"price": "0.47", "size": "123.63"}], "asks": [{"price": "0.99", "size": "297.79"}, {"price": "0.98", "size": "26.15"}, {"price": "0.95", "size": "60"}, {"price": "0.94", "size": "10.95"}], "event_type": "book", "last_trade_price": ""}, {"market": "0xc321c61a4e4789503e1a312aeddfaa3a397b4096a859060223a0e276b724928a", "asset_id": "45409360042913098746939749067676955227585590134571136184211831824538810637766", "timestamp": "1769384033000", "hash": "996da8623a8c01c0d4a05b78dc615ccee8983eac", "bids": [{"price": "0.01", "size": "283"}, {"price": "0.03", "size": "100"}, {"price": "0.04", "size": "49"}, {"price": "0.05", "size": "60"}, {"price": "0.06", "size": "33"}, {"price": "0.08", "size": "1350"}, {"price": "0.43", "size": "1000"}, {"price": "0.44", "size": "500"}, {"price": "0.45", "size": "11.11"}], "asks": [{"price": "0.99", "size": "297.79"}, {"price": "0.98", "size": "26.15"}, {"price": "0.95", "size": "60"}, {"price": "0.94", "size": "10.95"}], "event_type": "book", "last_trade_price": "0.470"}, {"market": "0x3f6580efc1ee6c9ccadc46c6a9cec02647b29f6ee3f825708b0bdb07e0ce411e", "asset_id": "77171203581469637987029219487468322466761142309609924047224127291598835517668", "timestamp": "1769384032001", "hash": "13025b37e2f86487004025cca8f95bc2c79be879", "bids": [{"price": "0.01", "size": "297.79"}, {"price": "0.02", "size": "26.15"}, {"price": "0.05", "size": "60"}, {"price": "0.06", "size": "16.42"}], "asks": [{"price": "0.99", "size": "288.68"}, {"price": "0.98", "size": "12.26"}, {"price": "0.96", "size": "49"}, {"price": "0.95", "size": "60"}, {"price": "0.94", "size": "1799"}, {"price": "0.93", "size": "9.96"}, {"price": "0.63", "size": "1000"}, {"price": "0.62", "size": "500"}], "event_type": "book", "last_trade_price": ""}, {"market": "0x14953309778fb38ad4b7d6998ad6c95fce695600381214a2558d0660d54d58e3", "asset_id": "60314365318504400021660468969193291406919501032199440844019272800649402550119", "timestamp": "1769384032763", "hash": "785cbfddebd5bf8dc719f5f950e75dc459722874", "bids": [{"price": "0.01", "size": "246.48"}, {"price": "0.03", "size": "100"}, {"price": "0.04", "size": "5.12"}, {"price": "0.05", "size": "55"}, {"price": "0.09", "size": "1218.16"}, {"price": "0.14", "size": "50"}, {"price": "0.2", "size": "200"}, {"price": "0.29", "size": "10000"}, {"price": "0.34", "size": "5000"}, {"price": "0.4", "size": "2500"}, {"price": "0.45", "size": "1300"}, {"price": "0.49", "size": "1229"}, {"price": "0.5", "size": "2629"}, {"price": "0.51", "size": "1500"}, {"price": "0.52", "size": "4703"}, {"price": "0.53", "size": "8589.57"}, {"price": "0.54", "size": "9861.55"}], "asks": [{"price": "0.99", "size": "231.5"}, {"price": "0.97", "size": "100"}, {"price": "0.95", "size": "5"}, {"price": "0.92", "size": "1350"}, {"price": "0.91", "size": "6.98"}, {"price": "0.81", "size": "10000"}, {"price": "0.77", "size": "5000"}, {"price": "0.73", "size": "2500"}, {"price": "0.67", "size": "1250"}, {"price": "0.66", "size": "50"}, {"price": "0.61", "size": "1000"}, {"price": "0.6", "size": "2100"}, {"price": "0.59", "size": "2120"}, {"price": "0.58", "size": "13154.9"}, {"price": "0.57", "size": "9907.31"}, {"price": "0.56", "size": "8070.36"}], "event_type": "book", "last_trade_price": "0.550"}, {"market": "0xd96573e2b56ec287fb0d47bf9014186c1e4f99702dda924fd8d9b60941cf26a6", "asset_id": "34438968861365109913426207322647965910661206508063798834616500635073575974183", "timestamp": "1769384036106", "hash": "68b43429549624116e55867b82320d382beaa105", "bids": [{"price": "0.01", "size": "237.93"}, {"price": "0.03", "size": "100"}, {"price": "0.04", "size": "7.66"}, {"price": "0.09", "size": "1211"}, {"price": "0.1", "size": "6.29"}, {"price": "0.14", "size": "50"}, {"price": "0.21", "size": "10000"}, {"price": "0.26", "size": "5000"}, {"price": "0.3", "size": "2500"}, {"price": "0.35", "size": "1250"}, {"price": "0.39", "size": "10"}, {"price": "0.41", "size": "1000"}, {"price": "0.42", "size": "1038"}, {"price": "0.43", "size": "3053"}, {"price": "0.44", "size": "11824.36"}, {"price": "0.45", "size": "12380.87"}, {"price": "0.46", "size": "12146.69"}], "asks": [{"price": "0.99", "size": "231.5"}, {"price": "0.97", "size": "100"}, {"price": "0.91", "size": "1211"}, {"price": "0.9", "size": "6.44"}, {"price": "0.86", "size": "50"}, {"price": "0.74", "size": "10000"}, {"price": "0.68", "size": "5000"}, {"price": "0.62", "size": "2500"}, {"price": "0.57", "size": "1250"}, {"price": "0.55", "size": "10"}, {"price": "0.54", "size": "1000"}, {"price": "0.53", "size": "1100"}, {"price": "0.52", "size": "2305"}, {"price": "0.51", "size": "3907.79"}, {"price": "0.5", "size": "13742"}, {"price": "0.49", "size": "13998.56"}, {"price": "0.48", "size": "11"}], "event_type": "book", "last_trade_price": "0.540"}, {"market": "0xc60d873e8bc171516c3631a8a31cc254cced6f2f3402e3c0a40475cab007b3c3", "asset_id": "25038904154097477604831493054093732539212779801414767373024639544798326517822", "timestamp": "1769384032001", "hash": "bbf459ae5ff34aa69a7eeaba135290d2caad33fd", "bids": [{"price": "0.01", "size": "388.42"}, {"price": "0.02", "size": "55.03"}, {"price": "0.03", "size": "100"}, {"price": "0.04", "size": "5.29"}, {"price": "0.05", "size": "80"}, {"price": "0.06", "size": "33"}, {"price": "0.08", "size": "1350"}, {"price": "0.09", "size": "7.03"}, {"price": "0.43", "size": "1000"}, {"price": "0.44", "size": "500"}, {"price": "0.45", "size": "11.11"}], "asks": [{"price": "0.99", "size": "397.79"}, {"price": "0.98", "size": "26.15"}, {"price": "0.95", "size": "20"}, {"price": "0.94", "size": "16.42"}], "event_type": "book", "last_trade_price": ""}, {"market": "0x970dab0b74ae35835fef12a63f824a981a2e8bd791d6a5d897d8c198b7a05581", "asset_id": "64061694358496011599518776148350330301400678821287070763604124728970432722704", "timestamp": "1769384032002", "hash": "07640ba1ce94366a8ae7a16f38bc0b67ac199737", "bids": [{"price": "0.01", "size": "231.5"}, {"price": "0.03", "size": "100"}, {"price": "0.05", "size": "5"}, {"price": "0.09", "size": "1211"}, {"price": "0.14", "size": "50"}, {"price": "0.2", "size": "200"}, {"price": "0.28", "size": "10000"}, {"price": "0.33", "size": "5000"}, {"price": "0.38", "size": "2500"}, {"price": "0.42", "size": "1250"}, {"price": "0.47", "size": "1000"}, {"price": "0.48", "size": "1500"}, {"price": "0.49", "size": "1100"}, {"price": "0.5", "size": "21000"}, {"price": "0.51", "size": "25563.99"}, {"price": "0.52", "size": "10178"}, {"price": "0.53", "size": "17419.84"}], "asks": [{"price": "0.99", "size": "231.5"}, {"price": "0.97", "size": "120"}, {"price": "0.95", "size": "5"}, {"price": "0.91", "size": "1211"}, {"price": "0.81", "size": "10000"}, {"price": "0.76", "size": "5000"}, {"price": "0.71", "size": "2500"}, {"price": "0.67", "size": "1250"}, {"price": "0.6", "size": "1000"}, {"price": "0.59", "size": "2100"}, {"price": "0.58", "size": "1533"}, {"price": "0.57", "size": "39082.11"}, {"price": "0.56", "size": "31151.84"}, {"price": "0.55", "size": "2333.99"}, {"price": "0.54", "size": "5"}], "event_type": "book", "last_trade_price": "0.460"}, {"market": "0x4813bed77c03fbf16137a1a82d6205e681c5182ade34f62019fdf124d1a7ed9b", "asset_id": "94529826770937052659833277332473040384030874510786347744954589719895985192344", "timestamp": "1769384033001", "hash": "8aa7dcd0af115bde3cad56a309041e696a02907c", "bids": [{"price": "0.01", "size": "288.64"}, {"price": "0.03", "size": "100"}, {"price": "0.04", "size": "54.23"}, {"price": "0.05", "size": "60"}, {"price": "0.06", "size": "33"}, {"price": "0.09", "size": "1218.08"}, {"price": "0.14", "size": "50"}, {"price": "0.46", "size": "1000"}, {"price": "0.47", "size": "510.63"}], "asks": [{"price": "0.99", "size": "297.79"}, {"price": "0.98", "size": "26.15"}, {"price": "0.95", "size": "60"}, {"price": "0.94", "size": "16.42"}], "event_type": "book", "last_trade_price": ""}, {"market": "0x08ab4504d44c55feee89fe2deba77f288ac727f0287df8a04c0a0a2162256c8e", "asset_id": "18307980820661182087850178444391190250642095340280044705782700446895498486234", "timestamp": "1769384032004", "hash": "61ed42d9f7adc7a633b8a70be5c76c7492dac3bb", "bids": [{"price": "0.01", "size": "388.55"}, {"price": "0.02", "size": "55.15"}, {"price": "0.03", "size": "100"}, {"price": "0.04", "size": "6.35"}, {"price": "0.05", "size": "80"}, {"price": "0.06", "size": "33"}, {"price": "0.08", "size": "1350"}, {"price": "0.1", "size": "5.87"}, {"price": "0.4", "size": "1000"}, {"price": "0.41", "size": "500"}], "asks": [{"price": "0.99", "size": "397.79"}, {"price": "0.98", "size": "26.15"}, {"price": "0.95", "size": "20"}, {"price": "0.94", "size": "16.42"}], "event_type": "book", "last_trade_price": "0.420"}, {"market": "0x40f679a98a4fafef4fbcc988385f4c35c9a0c05f10a4847863062e3a811cd3fb", "asset_id": "96518840264527551423161991822159133271365099061102190292241495549856572100367", "timestamp": "1769384033001", "hash": "9b84270964ea1ea1f1a8b2d7c421e14bcc8a016e", "bids": [{"price": "0.01", "size": "248.24"}, {"price": "0.03", "size": "100"}, {"price": "0.04", "size": "6.1"}, {"price": "0.09", "size": "1211"}, {"price": "0.1", "size": "6.03"}, {"price": "0.14", "size": "50"}, {"price": "0.34", "size": "4304"}, {"price": "0.37", "size": "3425.5"}, {"price": "0.4", "size": "2592.5"}, {"price": "0.43", "size": "1788.5"}, {"price": "0.44", "size": "1000"}, {"price": "0.45", "size": "500"}, {"price": "0.46", "size": "2111"}, {"price": "0.47", "size": "2269"}, {"price": "0.48", "size": "3476"}], "asks": [{"price": "0.99", "size": "243.52"}, {"price": "0.97", "size": "100"}, {"price": "0.91", "size": "1211"}, {"price": "0.86", "size": "50"}, {"price": "0.66", "size": "4304"}, {"price": "0.63", "size": "3425.5"}, {"price": "0.6", "size": "2592.5"}, {"price": "0.57", "size": "2788.5"}, {"price": "0.56", "size": "500"}, {"price": "0.55", "size": "150"}, {"price": "0.54", "size": "2123"}, {"price": "0.53", "size": "2016"}, {"price": "0.52", "size": "3473.15"}, {"price": "0.51", "size": "999"}], "event_type": "book", "last_trade_price": "0.480"}, {"market": "0x4aeb687ccd1da9f19d15cb7d6f820fe079af3c856f9104f42d46943ca45b27bd", "asset_id": "37176936087015401749148910450904482030865323565946722820937013963453694752742", "timestamp": "1769384036306", "hash": "be5b47948716bc38e64a771c1f4a1389a5e1b427", "bids": [{"price": "0.01", "size": "248.31"}, {"price": "0.03", "size": "100"}, {"price": "0.04", "size": "6.13"}, {"price": "0.09", "size": "1211"}, {"price": "0.1", "size": "6.01"}, {"price": "0.14", "size": "50"}, {"price": "0.46", "size": "1000"}, {"price": "0.47", "size": "1500"}, {"price": "0.48", "size": "4177"}, {"price": "0.49", "size": "5093.99"}, {"price": "0.5", "size": "10"}], "asks": [{"price": "0.99", "size": "238.39"}, {"price": "0.98", "size": "5"}, {"price": "0.97", "size": "100"}, {"price": "0.96", "size": "6.16"}, {"price": "0.91", "size": "1211"}, {"price": "0.9", "size": "5.99"}, {"price": "0.86", "size": "50"}, {"price": "0.57", "size": "2000"}, {"price": "0.56", "size": "1762"}, {"price": "0.55", "size": "5224"}, {"price": "0.54", "size": "3033"}, {"price": "0.51", "size": "5"}], "event_type": "book", "last_trade_price": "0.450"}, {"market": "0x022a494a4694f3e321b54bb614b9f28d6518affc42c2f5103268777aff340676", "asset_id": "115051638738409169136056281271864361408130311808920398707671348119359366272512", "timestamp": "1769384032004", "hash": "4ede76bc32e462b8ca0f9ec68f3fc49951cf272e", "bids": [{"price": "0.01", "size": "233"}, {"price": "0.03", "size": "100"}, {"price": "0.09", "size": "1211"}, {"price": "0.11", "size": "5.77"}, {"price": "0.14", "size": "50"}, {"price": "0.21", "size": "10000"}, {"price": "0.27", "size": "5000"}, {"price": "0.33", "size": "2500"}, {"price": "0.38", "size": "1300"}, {"price": "0.41", "size": "1000"}, {"price": "0.42", "size": "1000"}, {"price": "0.43", "size": "1100"}, {"price": "0.44", "size": "300"}, {"price": "0.45", "size": "6815.56"}, {"price": "0.46", "size": "9350"}, {"price": "0.47", "size": "1398.94"}, {"price": "0.48", "size": "6.42"}], "asks": [{"price": "0.99", "size": "233"}, {"price": "0.97", "size": "100"}, {"price": "0.91", "size": "1218.1"}, {"price": "0.86", "size": "50"}, {"price": "0.74", "size": "10000"}, {"price": "0.7", "size": "5000"}, {"price": "0.65", "size": "2500"}, {"price": "0.6", "size": "1250"}, {"price": "0.59", "size": "50"}, {"price": "0.54", "size": "1000"}, {"price": "0.53", "size": "1100"}, {"price": "0.52", "size": "1309"}, {"price": "0.51", "size": "8497.75"}, {"price": "0.5", "size": "9224"}, {"price": "0.49", "size": "9484.55"}], "event_type": "book", "last_trade_price": "0.510"}, {"market": "0x368753e3efb08f97336ad250758db1269b06a1ba8b3c8ec95a9a3cb9376a6922", "asset_id": "99514244780500968567376277247005595883580395398625637766786354333245186778286", "timestamp": "1769384032005", "hash": "1f3c665755f6c3899ed14725e6f1ebc55b8b7d05", "bids": [{"price": "0.01", "size": "397.79"}, {"price": "0.02", "size": "26.15"}, {"price": "0.05", "size": "20"}, {"price": "0.06", "size": "10.95"}, {"price": "0.07", "size": "5.47"}], "asks": [{"price": "0.99", "size": "383"}, {"price": "0.97", "size": "133"}, {"price": "0.95", "size": "80"}, {"price": "0.94", "size": "33"}, {"price": "0.91", "size": "1211"}, {"price": "0.86", "size": "50"}, {"price": "0.53", "size": "1000"}, {"price": "0.52", "size": "500"}, {"price": "0.51", "size": "10.2"}], "event_type": "book", "last_trade_price": ""}, {"market": "0xbeaaa3c19d9c2146bde70ce718dbe0bb8f4e0fb890d4db8d7ff8597a55b362bd", "asset_id": "15665430989345325971273692347463559296866176989612289943080209656894471940771", "timestamp": "1769384032001", "hash": "0adb194700fb39f61056a0a7eb0db4f3cafd04ee", "bids": [{"price": "0.01", "size": "283"}, {"price": "0.03", "size": "100"}, {"price": "0.04", "size": "54.17"}, {"price": "0.05", "size": "60"}, {"price": "0.06", "size": "33"}, {"price": "0.09", "size": "1211"}, {"price": "0.1", "size": "6.39"}, {"price": "0.14", "size": "50"}, {"price": "0.46", "size": "1000"}, {"price": "0.47", "size": "500"}, {"price": "0.48", "size": "10.41"}], "asks": [{"price": "0.99", "size": "297.79"}, {"price": "0.98", "size": "26.15"}, {"price": "0.95", "size": "60"}, {"price": "0.94", "size": "10.95"}], "event_type": "book", "last_trade_price": "0.480"}, {"market": "0x553717c180334e4b0693f864252ccaf7cb71b8be4c4c864e3dd3d6426c737a15", "asset_id": "102511791078625420334874150607165490922635280507748374937515274449950760080038", "timestamp": "1769384032002", "hash": "9f748cb068876bef8a267a8a4ec1dc637ab6c119", "bids": [{"price": "0.01", "size": "298.69"}, {"price": "0.02", "size": "9.81"}, {"price": "0.04", "size": "2549"}, {"price": "0.05", "size": "60"}, {"price": "0.06", "size": "33"}, {"price": "0.07", "size": "9.24"}, {"price": "0.23", "size": "1000"}, {"price": "0.24", "size": "500"}], "asks": [{"price": "0.99", "size": "297.79"}, {"price": "0.98", "size": "26.15"}, {"price": "0.95", "size": "60"}, {"price": "0.94", "size": "10.95"}], "event_type": "book", "last_trade_price": "0.430"}, {"market": "0x14953309778fb38ad4b7d6998ad6c95fce695600381214a2558d0660d54d58e3", "asset_id": "22578179344466948255817514384170808830444290334458668905786911133364969780566", "timestamp": "1769384032763", "hash": "6f5cbdc7371174abfa599c5f97e4e2992f1e9813", "bids": [{"price": "0.01", "size": "231.5"}, {"price": "0.03", "size": "100"}, {"price": "0.05", "size": "5"}, {"price": "0.08", "size": "1350"}, {"price": "0.09", "size": "6.98"}, {"price": "0.19", "size": "10000"}, {"price": "0.23", "size": "5000"}, {"price": "0.27", "size": "2500"}, {"price": "0.33", "size": "1250"}, {"price": "0.34", "size": "50"}, {"price": "0.39", "size": "1000"}, {"price": "0.4", "size": "2100"}, {"price": "0.41", "size": "2120"}, {"price": "0.42", "size": "13154.9"}, {"price": "0.43", "size": "9907.31"}, {"price": "0.44", "size": "8070.36"}], "asks": [{"price": "0.99", "size": "246.48"}, {"price": "0.97", "size": "100"}, {"price": "0.96", "size": "5.12"}, {"price": "0.95", "size": "55"}, {"price": "0.91", "size": "1218.16"}, {"price": "0.86", "size": "50"}, {"price": "0.8", "size": "200"}, {"price": "0.71", "size": "10000"}, {"price": "0.66", "size": "5000"}, {"price": "0.6", "size": "2500"}, {"price": "0.55", "size": "1300"}, {"price": "0.51", "size": "1229"}, {"price": "0.5", "size": "2629"}, {"price": "0.49", "size": "1500"}, {"price": "0.48", "size": "4703"}, {"price": "0.47", "size": "8589.57"}, {"price": "0.46", "size": "9861.55"}], "event_type": "book", "last_trade_price": "0.550"}, {"market": "0x40f679a98a4fafef4fbcc988385f4c35c9a0c05f10a4847863062e3a811cd3fb", "asset_id": "23091360226463319683483053319743342815863812458439400577707829686077988900282", "timestamp": "1769384033001", "hash": "7fd7e210a45d7fb63fd978a3fba725566fcfb02d", "bids": [{"price": "0.01", "size": "243.52"}, {"price": "0.03", "size": "100"}, {"price": "0.09", "size": "1211"}, {"price": "0.14", "size": "50"}, {"price": "0.34", "size": "4304"}, {"price": "0.37", "size": "3425.5"}, {"price": "0.4", "size": "2592.5"}, {"price": "0.43", "size": "2788.5"}, {"price": "0.44", "size": "500"}, {"price": "0.45", "size": "150"}, {"price": "0.46", "size": "2123"}, {"price": "0.47", "size": "2016"}, {"price": "0.48", "size": "3473.15"}, {"price": "0.49", "size": "999"}], "asks": [{"price": "0.99", "size": "248.24"}, {"price": "0.97", "size": "100"}, {"price": "0.96", "size": "6.1"}, {"price": "0.91", "size": "1211"}, {"price": "0.9", "size": "6.03"}, {"price": "0.86", "size": "50"}, {"price": "0.66", "size": "4304"}, {"price": "0.63", "size": "3425.5"}, {"price": "0.6", "size": "2592.5"}, {"price": "0.57", "size": "1788.5"}, {"price": "0.56", "size": "1000"}, {"price": "0.55", "size": "500"}, {"price": "0.54", "size": "2111"}, {"price": "0.53", "size": "2269"}, {"price": "0.52", "size": "3476"}], "event_type": "book", "last_trade_price": "0.480"}, {"market": "0x3f9017bb85500ceb6e6d2386b9c7e5887d55d0440abd8ed43d17eab892c20b7b", "asset_id": "80950492467797193193379494114234135632842600086519859752413283727659795329849", "timestamp": "1769384032002", "hash": "ff4aaf2864dc75c95e2b1734f079891926a9d9e9", "bids": [{"price": "0.01", "size": "288.52"}, {"price": "0.02", "size": "5.12"}, {"price": "0.03", "size": "100"}, {"price": "0.04", "size": "55.31"}, {"price": "0.05", "size": "60"}, {"price": "0.06", "size": "33"}, {"price": "0.08", "size": "1350"}, {"price": "0.1", "size": "5.89"}, {"price": "0.4", "size": "1000"}, {"price": "0.41", "size": "500"}, {"price": "0.42", "size": "11.9"}], "asks": [{"price": "0.99", "size": "297.79"}, {"price": "0.98", "size": "26.15"}, {"price": "0.95", "size": "60"}, {"price": "0.94", "size": "16.42"}], "event_type": "book", "last_trade_price": ""}, {"market": "0x027f856eb641875fd5d007085b8b821bb362cd6f1c03692e4bdced63d2b25a4b", "asset_id": "47192306828537745743716888869289118723245249412466437172347900202017700987092", "timestamp": "1769384032000", "hash": "18b34e2b9cc548a91fddcf56774dd4cd0babaa31", "bids": [{"price": "0.01", "size": "393.74"}, {"price": "0.02", "size": "50"}, {"price": "0.03", "size": "10.85"}, {"price": "0.05", "size": "80"}, {"price": "0.06", "size": "1799"}, {"price": "0.08", "size": "100"}, {"price": "0.1", "size": "5.67"}, {"price": "0.38", "size": "1000"}, {"price": "0.39", "size": "500"}], "asks": [{"price": "0.99", "size": "397.79"}, {"price": "0.98", "size": "26.15"}, {"price": "0.95", "size": "20"}, {"price": "0.94", "size": "10.95"}], "event_type": "book", "last_trade_price": "0.410"}, {"market": "0x1555baa85050bf46a6d9da9c541a846acefc0628617420021491f54f9d500eb6", "asset_id": "32274055423245537060314713137501562171927568362585652608301331862191261412289", "timestamp": "1769384032002", "hash": "b2fbde255a201fdafbd3e19f66130dc0c7a0b650", "bids": [{"price": "0.01", "size": "296.68"}, {"price": "0.03", "size": "100"}, {"price": "0.04", "size": "54.47"}, {"price": "0.05", "size": "60"}, {"price": "0.06", "size": "33"}, {"price": "0.09", "size": "1211"}, {"price": "0.1", "size": "6.44"}, {"price": "0.14", "size": "50"}, {"price": "0.46", "size": "1000"}, {"price": "0.47", "size": "500"}, {"price": "0.48", "size": "10.41"}], "asks": [{"price": "0.99", "size": "297.79"}, {"price": "0.98", "size": "13.72"}, {"price": "0.97", "size": "16"}, {"price": "0.96", "size": "6.21"}, {"price": "0.95", "size": "50"}, {"price": "0.94", "size": "10.95"}], "event_type": "book", "last_trade_price": ""}, {"market": "0x26284260436580ed8697a8ecc82ced8166bbefa7e1e3e2762f37e841dd276cfe", "asset_id": "30033822247502365818165812637815631798884613269431345774686010358646875241490", "timestamp": "1769384033001", "hash": "2f71633e10dec927927e7568d5c2d21a60ae9ba3", "bids": [{"price": "0.01", "size": "388.29"}, {"price": "0.02", "size": "9.35"}, {"price": "0.05", "size": "20"}, {"price": "0.06", "size": "1678.66"}, {"price": "0.5", "size": "30"}], "asks": [{"price": "0.99", "size": "383"}, {"price": "0.98", "size": "50"}, {"price": "0.97", "size": "110.46"}, {"price": "0.95", "size": "80"}, {"price": "0.94", "size": "33"}, {"price": "0.92", "size": "1350"}, {"price": "0.9", "size": "6.29"}, {"price": "0.57", "size": "1000"}, {"price": "0.56", "size": "500"}], "event_type": "book", "last_trade_price": "0.490"}, {"market": "0x94a74511beecd2f5565a100a69bf010ed044ed839a452eadadeea5442e55addb", "asset_id": "101678853064867442294540875677023485238334853345098354004151246822798822107376", "timestamp": "1769384032001", "hash": "b70c4ff7984fa4e332835cb3088708f7893d30f6", "bids": [{"price": "0.01", "size": "283"}, {"price": "0.05", "size": "60"}, {"price": "0.06", "size": "10.94"}], "asks": [{"price": "0.99", "size": "288.68"}, {"price": "0.98", "size": "12.26"}, {"price": "0.96", "size": "49"}, {"price": "0.95", "size": "60"}, {"price": "0.94", "size": "1799"}, {"price": "0.93", "size": "9.96"}, {"price": "0.63", "size": "1000"}, {"price": "0.62", "size": "500"}], "event_type": "book", "last_trade_price": ""}, {"market": "0xe20347279d1e95825b4a4156680ce2adffee4ec693635d3a251d993880d47d8a", "asset_id": "15760759017607793635266566763936429339574160223404740070777269991176507478842", "timestamp": "1769384035372", "hash": "30ee0b7f422bcf704150f3c53c3e8ddd1e87e6bf", "bids": [{"price": "0.01", "size": "233"}, {"price": "0.03", "size": "114"}, {"price": "0.09", "size": "1211"}, {"price": "0.14", "size": "50"}, {"price": "0.24", "size": "10000"}, {"price": "0.3", "size": "5000"}, {"price": "0.34", "size": "4304"}, {"price": "0.36", "size": "2500"}, {"price": "0.37", "size": "3425.5"}, {"price": "0.4", "size": "2592.5"}, {"price": "0.41", "size": "1250"}, {"price": "0.43", "size": "1788.5"}, {"price": "0.44", "size": "1000"}, {"price": "0.45", "size": "2100"}, {"price": "0.46", "size": "9095.52"}, {"price": "0.47", "size": "3272"}, {"price": "0.48", "size": "12893.24"}, {"price": "0.49", "size": "9144.44"}, {"price": "0.5", "size": "1452.88"}], "asks": [{"price": "0.99", "size": "238.39"}, {"price": "0.98", "size": "5"}, {"price": "0.97", "size": "100"}, {"price": "0.96", "size": "6.16"}, {"price": "0.91", "size": "1211"}, {"price": "0.9", "size": "5.99"}, {"price": "0.86", "size": "50"}, {"price": "0.77", "size": "10000"}, {"price": "0.72", "size": "5000"}, {"price": "0.69", "size": "2500"}, {"price": "0.66", "size": "4304"}, {"price": "0.63", "size": "3425.5"}, {"price": "0.62", "size": "1250"}, {"price": "0.6", "size": "2592.5"}, {"price": "0.57", "size": "1788.5"}, {"price": "0.56", "size": "1033"}, {"price": "0.55", "size": "2422"}, {"price": "0.54", "size": "11712.61"}, {"price": "0.53", "size": "14929.45"}, {"price": "0.52", "size": "14689.67"}, {"price": "0.51", "size": "1000"}], "event_type": "book", "last_trade_price": "0.510"}, {"market": "0x86feba9d088e90971ca1d898a4c1bd5797b93dd49d1fdd5621b5e1dbab7bab6c", "asset_id": "10171001349424486222245429395998181161288444563211665633638034159023476393263", "timestamp": "1769384033000", "hash": "a3efbd16724bfb3861d0e0b3068cb7eac9377781", "bids": [{"price": "0.01", "size": "288.68"}, {"price": "0.02", "size": "12.26"}, {"price": "0.04", "size": "49"}, {"price": "0.05", "size": "60"}, {"price": "0.06", "size": "1799"}, {"price": "0.07", "size": "9.96"}, {"price": "0.37", "size": "1000"}, {"price": "0.38", "size": "500"}], "asks": [{"price": "0.99", "size": "297.79"}, {"price": "0.98", "size": "26.15"}, {"price": "0.95", "size": "60"}, {"price": "0.94", "size": "10.95"}], "event_type": "book", "last_trade_price": ""}, {"market": "0x72d347777d7cd1a36b33d82ee33e8647d979b8e97d7870f290e585068e2eaf18", "asset_id": "46035028623017636966245851645568333453935371029373895359296143781534136191296", "timestamp": "1769384033000", "hash": "16a0f48bac24d47de06d11e13bb1595d3871a676", "bids": [{"price": "0.01", "size": "383"}, {"price": "0.05", "size": "20"}, {"price": "0.06", "size": "10.94"}], "asks": [{"price": "0.99", "size": "398.24"}, {"price": "0.98", "size": "50"}, {"price": "0.97", "size": "100"}, {"price": "0.96", "size": "6.1"}, {"price": "0.95", "size": "80"}, {"price": "0.94", "size": "33"}, {"price": "0.91", "size": "1211"}, {"price": "0.9", "size": "6.03"}, {"price": "0.86", "size": "50"}, {"price": "0.54", "size": "1000"}, {"price": "0.53", "size": "500"}, {"price": "0.52", "size": "10.41"}], "event_type": "book", "last_trade_price": ""}, {"market": "0x26284260436580ed8697a8ecc82ced8166bbefa7e1e3e2762f37e841dd276cfe", "asset_id": "92333856247840035551458927633430297221426206023828654020510594713109183061083", "timestamp": "1769384033001", "hash": "eb3985c2b1cb59f503aa4653f28cad1eeb226918", "bids": [{"price": "0.01", "size": "383"}, {"price": "0.02", "size": "50"}, {"price": "0.03", "size": "110.46"}, {"price": "0.05", "size": "80"}, {"price": "0.06", "size": "33"}, {"price": "0.08", "size": "1350"}, {"price": "0.1", "size": "6.29"}, {"price": "0.43", "size": "1000"}, {"price": "0.44", "size": "500"}], "asks": [{"price": "0.99", "size": "388.29"}, {"price": "0.98", "size": "9.35"}, {"price": "0.95", "size": "20"}, {"price": "0.94", "size": "1678.66"}, {"price": "0.5", "size": "30"}], "event_type": "book", "last_trade_price": "0.490"}, {"market": "0x03464779bdf4de0a3ebd602b9eef80d7822f6258b52e83508e391ee18d4668eb", "asset_id": "55145875173360773600221507709955334901875000631205798113036313355415179334123", "timestamp": "1769384032004", "hash": "c395fdfedb7ea628b931c82a08119374be6e65ec", "bids": [{"price": "0.01", "size": "288.9"}, {"price": "0.02", "size": "12.73"}, {"price": "0.04", "size": "49"}, {"price": "0.05", "size": "60"}, {"price": "0.06", "size": "1799"}, {"price": "0.07", "size": "9.8"}, {"price": "0.33", "size": "1000"}, {"price": "0.34", "size": "500"}], "asks": [{"price": "0.99", "size": "297.79"}, {"price": "0.98", "size": "26.15"}, {"price": "0.95", "size": "100"}, {"price": "0.94", "size": "10.95"}], "event_type": "book", "last_trade_price": ""}, {"market": "0x268802a47370bb01163109f0e99a74043188847bd8c8978bf0ea913a982f1482", "asset_id": "19982332579966095630823029629997249795935324511394732600473614139535481793651", "timestamp": "1769383899000", "hash": "919d79022142791e76a87567288cd6faefe88eec", "bids": [{"price": "0.01", "size": "297.79"}, {"price": "0.02", "size": "26.15"}, {"price": "0.05", "size": "60"}, {"price": "0.06", "size": "10.95"}], "asks": [{"price": "0.99", "size": "293.6"}, {"price": "0.98", "size": "13.53"}, {"price": "0.96", "size": "55.12"}, {"price": "0.95", "size": "60"}, {"price": "0.94", "size": "38.4"}], "event_type": "book", "last_trade_price": ""}, {"market": "0x79ad62045cfccd5ee44c4b5524c882ae48b39a7361c3aff3aeab4ad60eff1641", "asset_id": "81576114709932199356896157795242982589847910718483671004907600344374780896079", "timestamp": "1769384032003", "hash": "d67ab06fd9b8d5ab985b3c80a94aa76d2114b8cd", "bids": [{"price": "0.01", "size": "296.83"}, {"price": "0.02", "size": "26.58"}, {"price": "0.05", "size": "60"}, {"price": "0.06", "size": "10.97"}], "asks": [{"price": "0.99", "size": "296.68"}, {"price": "0.97", "size": "100"}, {"price": "0.96", "size": "54.47"}, {"price": "0.95", "size": "60"}, {"price": "0.94", "size": "33"}, {"price": "0.91", "size": "1211"}, {"price": "0.9", "size": "6.44"}, {"price": "0.86", "size": "50"}, {"price": "0.79", "size": "200"}, {"price": "0.48", "size": "1000"}, {"price": "0.47", "size": "500"}, {"price": "0.46", "size": "67.25"}], "event_type": "book", "last_trade_price": ""}, {"market": "0x022a494a4694f3e321b54bb614b9f28d6518affc42c2f5103268777aff340676", "asset_id": "25773853969587863829989803215799191248993842554985046236206202852592687161509", "timestamp": "1769384032004", "hash": "8874c236b1254e8717622868e8e1ebab161c4f5c", "bids": [{"price": "0.01", "size": "233"}, {"price": "0.03", "size": "100"}, {"price": "0.09", "size": "1218.1"}, {"price": "0.14", "size": "50"}, {"price": "0.26", "size": "10000"}, {"price": "0.3", "size": "5000"}, {"price": "0.35", "size": "2500"}, {"price": "0.4", "size": "1250"}, {"price": "0.41", "size": "50"}, {"price": "0.46", "size": "1000"}, {"price": "0.47", "size": "1100"}, {"price": "0.48", "size": "1309"}, {"price": "0.49", "size": "8497.75"}, {"price": "0.5", "size": "9224"}, {"price": "0.51", "size": "9484.55"}], "asks": [{"price": "0.99", "size": "233"}, {"price": "0.97", "size": "100"}, {"price": "0.91", "size": "1211"}, {"price": "0.89", "size": "5.77"}, {"price": "0.86", "size": "50"}, {"price": "0.79", "size": "10000"}, {"price": "0.73", "size": "5000"}, {"price": "0.67", "size": "2500"}, {"price": "0.62", "size": "1300"}, {"price": "0.59", "size": "1000"}, {"price": "0.58", "size": "1000"}, {"price": "0.57", "size": "1100"}, {"price": "0.56", "size": "300"}, {"price": "0.55", "size": "6815.56"}, {"price": "0.54", "size": "9350"}, {"price": "0.53", "size": "1398.94"}, {"price": "0.52", "size": "6.42"}], "event_type": "book", "last_trade_price": "0.510"}, {"market": "0xc6ff7f8ae1f58824aa11d979b259c782ef25a93a66b73fa37b1f87edaedfad91", "asset_id": "82879689812327174643178891537605396737802568583972628524772921113776829540299", "timestamp": "1769384032002", "hash": "570c9e845d5dd9282f0d87a70bfbb109e69e7569", "bids": [{"price": "0.01", "size": "297.79"}, {"price": "0.02", "size": "26.15"}, {"price": "0.05", "size": "60"}, {"price": "0.06", "size": "10.95"}], "asks": [{"price": "0.99", "size": "289.54"}, {"price": "0.97", "size": "100"}, {"price": "0.96", "size": "56.48"}, {"price": "0.95", "size": "60"}, {"price": "0.94", "size": "33"}, {"price": "0.92", "size": "1350"}, {"price": "0.9", "size": "6.35"}, {"price": "0.59", "size": "1000"}, {"price": "0.58", "size": "500"}, {"price": "0.57", "size": "11.62"}], "event_type": "book", "last_trade_price": ""}, {"market": "0xecec20726d06c83989ad891c245da1f609328d35c109b32f63ce3098923e7019", "asset_id": "19153916485039164561633633362182475996956647655613969227442988124525778805792", "timestamp": "1769383900005", "hash": "329034ccade0a21f2764d8a0b923503f9583fa80", "bids": [{"price": "0.01", "size": "297.79"}, {"price": "0.02", "size": "26.15"}, {"price": "0.05", "size": "100"}, {"price": "0.06", "size": "15.48"}], "asks": [{"price": "0.99", "size": "283"}, {"price": "0.96", "size": "49"}, {"price": "0.95", "size": "60"}, {"price": "0.94", "size": "33"}], "event_type": "book", "last_trade_price": "0.060"}, {"market": "0xd43333b568660feff4879dc11ec96d96ea840467e931fc1d1a30038d3c1f36ba", "asset_id": "103558162642701244581198729484531317361688802804085124145550183881006710535142", "timestamp": "1769384035647", "hash": "e63edf2b5f2dc06f92f56b4f18894b8fbfa5692c", "bids": [{"price": "0.01", "size": "248.31"}, {"price": "0.03", "size": "100"}, {"price": "0.04", "size": "6.13"}, {"price": "0.09", "size": "1211"}, {"price": "0.1", "size": "6.01"}, {"price": "0.14", "size": "50"}, {"price": "0.24", "size": "10000"}, {"price": "0.29", "size": "5000"}, {"price": "0.34", "size": "6804"}, {"price": "0.37", "size": "3425.5"}, {"price": "0.38", "size": "1250"}, {"price": "0.4", "size": "2642.5"}, {"price": "0.43", "size": "1788.5"}, {"price": "0.45", "size": "2033"}, {"price": "0.46", "size": "3806"}, {"price": "0.47", "size": "27161.69"}, {"price": "0.48", "size": "14937.89"}, {"price": "0.49", "size": "15743.93"}], "asks": [{"price": "0.99", "size": "246.95"}, {"price": "0.97", "size": "100"}, {"price": "0.96", "size": "5.58"}, {"price": "0.91", "size": "1211"}, {"price": "0.9", "size": "6.37"}, {"price": "0.86", "size": "50"}, {"price": "0.76", "size": "10000"}, {"price": "0.71", "size": "5000"}, {"price": "0.66", "size": "6804"}, {"price": "0.63", "size": "3425.5"}, {"price": "0.62", "size": "1250"}, {"price": "0.6", "size": "2642.5"}, {"price": "0.57", "size": "2788.5"}, {"price": "0.56", "size": "1500"}, {"price": "0.55", "size": "1133"}, {"price": "0.54", "size": "3206"}, {"price": "0.53", "size": "13129.55"}, {"price": "0.52", "size": "327437"}, {"price": "0.51", "size": "305729.91"}], "event_type": "book", "last_trade_price": "0.490"}, {"market": "0xdb478719e450e8668c1b1f4277cb277337eeb28e3187893b2cf9274606acdc10", "asset_id": "48272372840153531931189816289176921610011981289675528105214127064708913654280", "timestamp": "1769384032001", "hash": "2a35c364182086f912254e04a63fb725cf640937", "bids": [{"price": "0.01", "size": "297.79"}, {"price": "0.02", "size": "26.15"}, {"price": "0.05", "size": "60"}, {"price": "0.06", "size": "10.95"}], "asks": [{"price": "0.99", "size": "298.31"}, {"price": "0.97", "size": "100"}, {"price": "0.96", "size": "55.13"}, {"price": "0.95", "size": "60"}, {"price": "0.94", "size": "33"}, {"price": "0.91", "size": "1211"}, {"price": "0.9", "size": "6.01"}, {"price": "0.86", "size": "50"}, {"price": "0.55", "size": "1000"}, {"price": "0.54", "size": "500"}, {"price": "0.53", "size": "123.63"}], "event_type": "book", "last_trade_price": ""}, {"market": "0xd43333b568660feff4879dc11ec96d96ea840467e931fc1d1a30038d3c1f36ba", "asset_id": "75835791470537447401195508884423769567933455236872042191341629176792194183781", "timestamp": "1769384035647", "hash": "473b2b183309d75b56edcdcb85c08f527d5f2d99", "bids": [{"price": "0.01", "size": "246.95"}, {"price": "0.03", "size": "100"}, {"price": "0.04", "size": "5.58"}, {"price": "0.09", "size": "1211"}, {"price": "0.1", "size": "6.37"}, {"price": "0.14", "size": "50"}, {"price": "0.24", "size": "10000"}, {"price": "0.29", "size": "5000"}, {"price": "0.34", "size": "6804"}, {"price": "0.37", "size": "3425.5"}, {"price": "0.38", "size": "1250"}, {"price": "0.4", "size": "2642.5"}, {"price": "0.43", "size": "2788.5"}, {"price": "0.44", "size": "1500"}, {"price": "0.45", "size": "1133"}, {"price": "0.46", "size": "3206"}, {"price": "0.47", "size": "13129.55"}, {"price": "0.48", "size": "327437"}, {"price": "0.49", "size": "305729.91"}], "asks": [{"price": "0.99", "size": "248.31"}, {"price": "0.97", "size": "100"}, {"price": "0.96", "size": "6.13"}, {"price": "0.91", "size": "1211"}, {"price": "0.9", "size": "6.01"}, {"price": "0.86", "size": "50"}, {"price": "0.76", "size": "10000"}, {"price": "0.71", "size": "5000"}, {"price": "0.66", "size": "6804"}, {"price": "0.63", "size": "3425.5"}, {"price": "0.62", "size": "1250"}, {"price": "0.6", "size": "2642.5"}, {"price": "0.57", "size": "1788.5"}, {"price": "0.55", "size": "2033"}, {"price": "0.54", "size": "3806"}, {"price": "0.53", "size": "27161.69"}, {"price": "0.52", "size": "14937.89"}, {"price": "0.51", "size": "15743.93"}], "event_type": "book", "last_trade_price": "0.490"}]}
{"_local_timestamp": "2026-01-25T23:33:57.105151+00:00", "data": {"market": "0xe20347279d1e95825b4a4156680ce2adffee4ec693635d3a251d993880d47d8a", "price_changes": [{"asset_id": "15760759017607793635266566763936429339574160223404740070777269991176507478842", "price": "0.1", "size": "6.01", "side": "BUY", "hash": "758d59a48ef759bd497d79e80d65340a593dfa72", "best_bid": "0.5", "best_ask": "0.51"}, {"asset_id": "85403516720171167773566543912461162711370406995858075142351224114108329589213", "price": "0.9", "size": "6.01", "side": "SELL", "hash": "14105d3f93feb14977e84bc19dbf1bcdf404de55", "best_bid": "0.49", "best_ask": "0.5"}], "timestamp": "1769384036758", "event_type": "price_change"}}
{"_local_timestamp": "2026-01-25T23:33:57.105443+00:00", "data": {"market": "0xe20347279d1e95825b4a4156680ce2adffee4ec693635d3a251d993880d47d8a", "price_changes": [{"asset_id": "15760759017607793635266566763936429339574160223404740070777269991176507478842", "price": "0.04", "size": "6.13", "side": "BUY", "hash": "2cceccf8c576aba6e9ab77c9aae4958a52af8fd5", "best_bid": "0.5", "best_ask": "0.51"}, {"asset_id": "85403516720171167773566543912461162711370406995858075142351224114108329589213", "price": "0.96", "size": "6.13", "side": "SELL", "hash": "498683b8d5ddc912d41a85f7f74ccd52d1d41203", "best_bid": "0.49", "best_ask": "0.5"}], "timestamp": "1769384036761", "event_type": "price_change"}}
{"_local_timestamp": "2026-01-25T23:33:57.105701+00:00", "data": {"market": "0xe20347279d1e95825b4a4156680ce2adffee4ec693635d3a251d993880d47d8a", "price_changes": [{"asset_id": "15760759017607793635266566763936429339574160223404740070777269991176507478842", "price": "0.01", "size": "248.31", "side": "BUY", "hash": "aa733b24fc4649590badd807cfbe1aa252172725", "best_bid": "0.5", "best_ask": "0.51"}, {"asset_id": "85403516720171167773566543912461162711370406995858075142351224114108329589213", "price": "0.99", "size": "248.31", "side": "SELL", "hash": "6c9e7fd833ce0ffb8f8546b022898d32f26dbc4e", "best_bid": "0.49", "best_ask": "0.5"}], "timestamp": "1769384036766", "event_type": "price_change"}}
{"_local_timestamp": "2026-01-25T23:33:57.105993+00:00", "data": {"market": "0x26284260436580ed8697a8ecc82ced8166bbefa7e1e3e2762f37e841dd276cfe", "price_changes": [{"asset_id": "30033822247502365818165812637815631798884613269431345774686010358646875241490", "price": "0.06", "size": "12.66", "side": "BUY", "hash": "8714c50f53941a49f8186ba02553e7d76f01e011", "best_bid": "0.5", "best_ask": "0.56"}, {"asset_id": "92333856247840035551458927633430297221426206023828654020510594713109183061083", "price": "0.94", "size": "12.66", "side": "SELL", "hash": "4c88121c6188c127540cae0fb0660cafcffa8087", "best_bid": "0.44", "best_ask": "0.5"}], "timestamp": "1769384037000", "event_type": "price_change"}}
{"_local_timestamp": "2026-01-25T23:33:57.148706+00:00", "data": {"market": "0x4aeb687ccd1da9f19d15cb7d6f820fe079af3c856f9104f42d46943ca45b27bd", "price_changes": [{"asset_id": "31999400366734158104301855635228245130465493243805955843366583423501887482170", "price": "0.09", "size": "100", "side": "BUY", "hash": "a7f696ab0448d1f98ecad54c1eb8ee605b00a197", "best_bid": "0.49", "best_ask": "0.5"}, {"asset_id": "37176936087015401749148910450904482030865323565946722820937013963453694752742", "price": "0.91", "size": "100", "side": "SELL", "hash": "9221ae5fcdae170f78fe1ba89972885e5f6b9c7e", "best_bid": "0.5", "best_ask": "0.51"}], "timestamp": "1769384037000", "event_type": "price_change"}}
{"_local_timestamp": "2026-01-25T23:33:57.149152+00:00", "data": {"market": "0x86feba9d088e90971ca1d898a4c1bd5797b93dd49d1fdd5621b5e1dbab7bab6c", "price_changes": [{"asset_id": "10171001349424486222245429395998181161288444563211665633638034159023476393263", "price": "0.06", "size": "133", "side": "BUY", "hash": "ab4786c2c254150988891902e2d0d466b6983846", "best_bid": "0.38", "best_ask": "0.94"}, {"asset_id": "27514912942320421059111797484653666814872354031839316574031804990218755493417", "price": "0.94", "size": "133", "side": "SELL", "hash": "43c6e4bd9b73b1d8b352bb8480497a5c713bebb0", "best_bid": "0.06", "best_ask": "0.62"}], "timestamp": "1769384037000", "event_type": "price_change"}}
{"_local_timestamp": "2026-01-25T23:33:57.149425+00:00", "data": {"market": "0x72d347777d7cd1a36b33d82ee33e8647d979b8e97d7870f290e585068e2eaf18", "price_changes": [{"asset_id": "18064383735028350165016189664106232638333255077909753138952756695769424263258", "price": "0.09", "size": "100", "side": "BUY", "hash": "3772191dfd9a21b114a83767e21da01befcdd9c1", "best_bid": "0.48", "best_ask": "0.94"}, {"asset_id": "46035028623017636966245851645568333453935371029373895359296143781534136191296", "price": "0.91", "size": "100", "side": "SELL", "hash": "267a109be30aa862d720e9b3cb9b9de89044fc41", "best_bid": "0.06", "best_ask": "0.52"}], "timestamp": "1769384037000", "event_type": "price_change"}}
{"_local_timestamp": "2026-01-25T23:33:57.149689+00:00", "data": {"market": "0x3d891c4518177a2d0cdef2b26192198849326e69817fec3ec44b1dd5db382d66", "price_changes": [{"asset_id": "47152501071153124210643670797073071998156661386350906991394486559609354161760", "price": "0.08", "size": "100", "side": "BUY", "hash": "10eff9718edda20abcf8dd8b4042dd99fbb75a5f", "best_bid": "0.42", "best_ask": "0.94"}, {"asset_id": "102869039310147156187992762631729075600982777916006979703835908426915768394637", "price": "0.92", "size": "100", "side": "SELL", "hash": "d46557c661ade19e2fe8e73028f0936883b5659e", "best_bid": "0.06", "best_ask": "0.58"}], "timestamp": "1769384037000", "event_type": "price_change"}}
{"_local_timestamp": "2026-01-25T23:33:57.149951+00:00", "data": {"market": "0x3f5cc35560a89e67a91b5e7bd0e00a3c01ad0e07f2deb5a97666b110e43f47f1", "price_changes": [{"asset_id": "78603243324556293353878442880948079627049482267281633215349873153372325985260", "price": "0.09", "size": "100", "side": "BUY", "hash": "f2bd8b6db1f3c536fffeb3ef1e4744cb2fa9acb8", "best_bid": "0.45", "best_ask": "0.51"}, {"asset_id": "83603974700861762645983613428945838380726029750034095407014914624732138624340", "price": "0.91", "size": "100", "side": "SELL", "hash": "650df0087357b76e7382e90ab1e031e9fe173231", "best_bid": "0.49", "best_ask": "0.55"}], "timestamp": "1769384037000", "event_type": "price_change"}}
{"_local_timestamp": "2026-01-25T23:33:57.150207+00:00", "data": {"market": "0xbf3100d84bfd1b4d2936ceb8dd3a29a65f1ad9f00f135636255eef0b5bdbe359", "price_changes": [{"asset_id": "56104088600014710064818932436571644113019907992309555438937676208970391548401", "price": "0.14", "size": "50", "side": "BUY", "hash": "f2961cc8c2cc554e43ae6c4bee361d450551ef7b", "best_bid": "0.73", "best_ask": "0.76"}, {"asset_id": "17231604872299400939311521877066387175626533356330458345531604304528475721436", "price": "0.86", "size": "50", "side": "SELL", "hash": "2508a8ad13495c49dfd37445707c2e9bc412922a", "best_bid": "0.24", "best_ask": "0.27"}], "timestamp": "1769384037000", "event_type": "price_change"}}
{"_local_timestamp": "2026-01-25T23:33:57.150482+00:00", "data": {"market": "0x78ba1e90813a5437dea6ab7a7aeca53f910f3b5cecc5b5b2cbafe3ec3c3aeb57", "price_changes": [{"asset_id": "31355627987268222126547396163770855213217371487708271104745934082289374931694", "price": "0.06", "size": "133", "side": "BUY", "hash": "ea77e85526d680629cfa55e8de1623a765317756", "best_bid": "0.39", "best_ask": "0.94"}, {"asset_id": "49463105653994466683943093343279734251397612176513055641839956156740014377972", "price": "0.94", "size": "133", "side": "SELL", "hash": "913f948cd792ceee68955e98e978fb434b10cc07", "best_bid": "0.06", "best_ask": "0.61"}], "timestamp": "1769384037000", "event_type": "price_change"}}
{"_local_timestamp": "2026-01-25T23:33:57.150763+00:00", "data": {"market": "0xd43333b568660feff4879dc11ec96d96ea840467e931fc1d1a30038d3c1f36ba", "price_changes": [{"asset_id": "103558162642701244581198729484531317361688802804085124145550183881006710535142", "price": "0.09", "size": "100", "side": "BUY", "hash": "b91d7ed756318f728d15628b672d6483dc763b70", "best_bid": "0.49", "best_ask": "0.51"}, {"asset_id": "75835791470537447401195508884423769567933455236872042191341629176792194183781", "price": "0.91", "size": "100", "side": "SELL", "hash": "609670e6177cebadc7a652292d71e6ce8d734165", "best_bid": "0.49", "best_ask": "0.51"}], "timestamp": "1769384037001", "event_type": "price_change"}}
{"_local_timestamp": "2026-01-25T23:33:57.151022+00:00", "data": {"market": "0x3f5cc35560a89e67a91b5e7bd0e00a3c01ad0e07f2deb5a97666b110e43f47f1", "price_changes": [{"asset_id": "83603974700861762645983613428945838380726029750034095407014914624732138624340", "price": "0.09", "size": "100", "side": "BUY", "hash": "0d64dae6effede544fafd4d0b4175a7ffa6fb4e2", "best_bid": "0.49", "best_ask": "0.55"}, {"asset_id": "78603243324556293353878442880948079627049482267281633215349873153372325985260", "price": "0.91", "size": "100", "side": "SELL", "hash": "a2a8aa467a96cb015eb6ca225768441c1b2d16ae", "best_bid": "0.45", "best_ask": "0.51"}], "timestamp": "1769384037001", "event_type": "price_change"}}
{"_local_timestamp": "2026-01-25T23:33:57.151313+00:00", "data": {"market": "0x548bf24ac69dda721ac2c9f70ddf7d4907ddebfaa552b3c9d90c2ea579759850", "price_changes": [{"asset_id": "87069058062386204514440746177167230003061183275952307043291532056740705911527", "price": "0.16", "size": "0", "side": "BUY", "hash": "b1ce94debfe0eb4fd26ebd00951c8288958cb93c", "best_bid": "0.81", "best_ask": "0.82"}, {"asset_id": "51674227959772201692995587953323756294034141098159045110117222361966129767794", "price": "0.84", "size": "0", "side": "SELL", "hash": "4958b116de04e847cfbc6f5a9aa84b20579f3621", "best_bid": "0.18", "best_ask": "0.19"}], "timestamp": "1769384037000", "event_type": "price_change"}}
{"_local_timestamp": "2026-01-25T23:33:57.151578+00:00", "data": {"market": "0xc60d873e8bc171516c3631a8a31cc254cced6f2f3402e3c0a40475cab007b3c3", "price_changes": [{"asset_id": "25038904154097477604831493054093732539212779801414767373024639544798326517822", "price": "0.08", "size": "100", "side": "BUY", "hash": "0088fa87ab2f081a7d7bd1a81d45163297745d4c", "best_bid": "0.45", "best_ask": "0.94"}, {"asset_id": "107074978358193625457427782320573845396027159383434708562159503922684086133798", "price": "0.92", "size": "100", "side": "SELL", "hash": "2098e260effb82e55210b2a7ec6bfd850088511a", "best_bid": "0.06", "best_ask": "0.55"}], "timestamp": "1769384037002", "event_type": "price_change"}}
{"_local_timestamp": "2026-01-25T23:33:57.151854+00:00", "data": {"market": "0x022a494a4694f3e321b54bb614b9f28d6518affc42c2f5103268777aff340676", "price_changes": [{"asset_id": "25773853969587863829989803215799191248993842554985046236206202852592687161509", "price": "0.09", "size": "107.1", "side": "BUY", "hash": "dec75d19f6e0dfc21724a370f70cd772f9a5d10e", "best_bid": "0.51", "best_ask": "0.52"}, {"asset_id": "115051638738409169136056281271864361408130311808920398707671348119359366272512", "price": "0.91", "size": "107.1", "side": "SELL", "hash": "a0fff1fbd52cfcc2489e219ef9f23c280f272fa8", "best_bid": "0.48", "best_ask": "0.49"}], "timestamp": "1769384037000", "event_type": "price_change"}}
{"_local_timestamp": "2026-01-25T23:33:57.152121+00:00", "data": {"market": "0xda9010c105fc532855d1427afbb54bac3a872106b13d70541948524bf3c1f13e", "price_changes": [{"asset_id": "54156514034087263487569029617230664616612015268241749973657295711641068204713", "price": "0.05", "size": "160", "side": "BUY", "hash": "f98e92d4033a29f6c1683085ca2263c20e48fc2e", "best_bid": "0.29", "best_ask": "0.89"}, {"asset_id": "78315379118406859624973110495963480819305867678789445335779496010870936073394", "price": "0.95", "size": "160", "side": "SELL", "hash": "120784e57393b26fe3ad9e9b024e941789b8088f", "best_bid": "0.11", "best_ask": "0.71"}], "timestamp": "1769384037000", "event_type": "price_change"}}
{"_local_timestamp": "2026-01-25T23:33:57.152416+00:00", "data": {"market": "0x14953309778fb38ad4b7d6998ad6c95fce695600381214a2558d0660d54d58e3", "price_changes": [{"asset_id": "22578179344466948255817514384170808830444290334458668905786911133364969780566", "price": "0.08", "size": "100", "side": "BUY", "hash": "f30ce83e87e774be3e03972b6ffbc5f0a3d56056", "best_bid": "0.44", "best_ask": "0.46"}, {"asset_id": "60314365318504400021660468969193291406919501032199440844019272800649402550119", "price": "0.92", "size": "100", "side": "SELL", "hash": "0f3efea875b8cf7bba692e858843537dd4bfcf5d", "best_bid": "0.54", "best_ask": "0.56"}], "timestamp": "1769384037002", "event_type": "price_change"}}
{"_local_timestamp": "2026-01-25T23:33:57.152687+00:00", "data": {"market": "0xd43333b568660feff4879dc11ec96d96ea840467e931fc1d1a30038d3c1f36ba", "price_changes": [{"asset_id": "75835791470537447401195508884423769567933455236872042191341629176792194183781", "price": "0.09", "size": "100", "side": "BUY", "hash": "24ef20ab55ae42dd4beccf37ca1a39c4ccb02268", "best_bid": "0.49", "best_ask": "0.51"}, {"asset_id": "103558162642701244581198729484531317361688802804085124145550183881006710535142", "price": "0.91", "size": "100", "side": "SELL", "hash": "c1574243f1d63a8cbc0f1bfc6d5ed3c22faafd1c", "best_bid": "0.49", "best_ask": "0.51"}], "timestamp": "1769384037002", "event_type": "price_change"}}
{"_local_timestamp": "2026-01-25T23:33:57.152970+00:00", "data": {"market": "0x08ab4504d44c55feee89fe2deba77f288ac727f0287df8a04c0a0a2162256c8e", "price_changes": [{"asset_id": "18307980820661182087850178444391190250642095340280044705782700446895498486234", "price": "0.08", "size": "100", "side": "BUY", "hash": "efa5c13aa3feea6cdc877a5376475436dc9494e3", "best_bid": "0.41", "best_ask": "0.94"}, {"asset_id": "679278415023314077827788027777238511637764586200547537110586042472687154713", "price": "0.92", "size": "100", "side": "SELL", "hash": "7050f468e1b045b566d0f9b453d6c3ff13ccccf0", "best_bid": "0.06", "best_ask": "0.59"}], "timestamp": "1769384037003", "event_type": "price_change"}}
{"_local_timestamp": "2026-01-25T23:33:57.153258+00:00", "data": {"market": "0x1555baa85050bf46a6d9da9c541a846acefc0628617420021491f54f9d500eb6", "price_changes": [{"asset_id": "32274055423245537060314713137501562171927568362585652608301331862191261412289", "price": "0.09", "size": "100", "side": "BUY", "hash": "6785d3eb6950db10aa8593cf76b5bac65b704c91", "best_bid": "0.48", "best_ask": "0.94"}, {"asset_id": "61599985294999295036709505701627609233274312766724636571888085254678251971053", "price": "0.91", "size": "100", "side": "SELL", "hash": "50a514d69ea870d52ab6a62fa6757d910ac4ac03", "best_bid": "0.06", "best_ask": "0.52"}], "timestamp": "1769384037004", "event_type": "price_change"}}
{"_local_timestamp": "2026-01-25T23:33:57.153536+00:00", "data": {"market": "0x03464779bdf4de0a3ebd602b9eef80d7822f6258b52e83508e391ee18d4668eb", "price_changes": [{"asset_id": "55145875173360773600221507709955334901875000631205798113036313355415179334123", "price": "0.06", "size": "133", "side": "BUY", "hash": "a9f9a93570577c79b81a0b6d88ee5d04fafc6587", "best_bid": "0.34", "best_ask": "0.94"}, {"asset_id": "27139615157740269866908006833759826848004875655274435602141899025932234359266", "price": "0.94", "size": "133", "side": "SELL", "hash": "0f3647e258667d85d2ffb15f1890b5895fe51fe7", "best_bid": "0.06", "best_ask": "0.66"}], "timestamp": "1769384037004", "event_type": "price_change"}}
{"_local_timestamp": "2026-01-25T23:33:57.153894+00:00", "data": {"market": "0x40f679a98a4fafef4fbcc988385f4c35c9a0c05f10a4847863062e3a811cd3fb", "price_changes": [{"asset_id": "23091360226463319683483053319743342815863812458439400577707829686077988900282", "price": "0.09", "size": "100", "side": "BUY", "hash": "a6bc2f37c51bbbb4817552f25b9f23cffc03d9b5", "best_bid": "0.49", "best_ask": "0.52"}, {"asset_id": "96518840264527551423161991822159133271365099061102190292241495549856572100367", "price": "0.91", "size": "100", "side": "SELL", "hash": "b9301b65e3e31d3c86594a318e07c222efbb7399", "best_bid": "0.48", "best_ask": "0.51"}], "timestamp": "1769384037001", "event_type": "price_change"}}
{"_local_timestamp": "2026-01-25T23:33:57.154367+00:00", "data": {"market": "0x3f6580efc1ee6c9ccadc46c6a9cec02647b29f6ee3f825708b0bdb07e0ce411e", "price_changes": [{"asset_id": "115465028598646261292747068550744722498119611179707586190193737079563693789318", "price": "0.06", "size": "133", "side": "BUY", "hash": "6ed03b895f2b1c0a7676c7d65bd58b565fde8591", "best_bid": "0.38", "best_ask": "0.94"}, {"asset_id": "77171203581469637987029219487468322466761142309609924047224127291598835517668", "price": "0.94", "size": "133", "side": "SELL", "hash": "63ceacb4b2055411922d24bd0962942bbc8b1fea", "best_bid": "0.06", "best_ask": "0.62"}], "timestamp": "1769384037003", "event_type": "price_change"}}
{"_local_timestamp": "2026-01-25T23:33:57.154747+00:00", "data": {"market": "0xbf3100d84bfd1b4d2936ceb8dd3a29a65f1ad9f00f135636255eef0b5bdbe359", "price_changes": [{"asset_id": "17231604872299400939311521877066387175626533356330458345531604304528475721436", "price": "0.02", "size": "0", "side": "BUY", "hash": "79999485bc0af71fc146ae3b1556141c0889fb9c", "best_bid": "0.24", "best_ask": "0.27"}, {"asset_id": "56104088600014710064818932436571644113019907992309555438937676208970391548401", "price": "0.98", "size": "0", "side": "SELL", "hash": "8f4c469a4d2f5de06752fa81cd4b05dcf7483264", "best_bid": "0.73", "best_ask": "0.76"}], "timestamp": "1769384037001", "event_type": "price_change"}}
{"_local_timestamp": "2026-01-25T23:33:57.155043+00:00", "data": {"market": "0x26284260436580ed8697a8ecc82ced8166bbefa7e1e3e2762f37e841dd276cfe", "price_changes": [{"asset_id": "92333856247840035551458927633430297221426206023828654020510594713109183061083", "price": "0.08", "size": "100", "side": "BUY", "hash": "41e47def378ddd1bbadd07d0d5b0607ec034e7a5", "best_bid": "0.44", "best_ask": "0.5"}, {"asset_id": "30033822247502365818165812637815631798884613269431345774686010358646875241490", "price": "0.92", "size": "100", "side": "SELL", "hash": "0cd328c87812cd59219eec4efb255f2edeeecb50", "best_bid": "0.5", "best_ask": "0.56"}], "timestamp": "1769384037004", "event_type": "price_change"}}
{"_local_timestamp": "2026-01-25T23:33:57.155334+00:00", "data": {"market": "0x548bf24ac69dda721ac2c9f70ddf7d4907ddebfaa552b3c9d90c2ea579759850", "price_changes": [{"asset_id": "51674227959772201692995587953323756294034141098159045110117222361966129767794", "price": "0.03", "size": "2508.54", "side": "BUY", "hash": "6ede97fab58ad69b615ce5be7bce73f0dce1e4ae", "best_bid": "0.18", "best_ask": "0.19"}, {"asset_id": "87069058062386204514440746177167230003061183275952307043291532056740705911527", "price": "0.97", "size": "2508.54", "side": "SELL", "hash": "1a05465cb87b0f03f2aa3ec63f8e56661eea020c", "best_bid": "0.81", "best_ask": "0.82"}], "timestamp": "1769384037004", "event_type": "price_change"}}
{"_local_timestamp": "2026-01-25T23:33:57.155610+00:00", "data": {"market": "0x699033710f3f9c616fc2c2faa8841e82774faef40be068a28d02ae48d3da5039", "price_changes": [{"asset_id": "43393460696979797431541641548274596146619752824207725942315186553106110134984", "price": "0.09", "size": "100", "side": "BUY", "hash": "86421940363afcdd43c2acfcbfebae05ce1cd1b5", "best_bid": "0.53", "best_ask": "0.57"}, {"asset_id": "6600280110979446792688496766284105163228498718832706118430734116375831805445", "price": "0.91", "size": "100", "side": "SELL", "hash": "f43eb1dad2e8df6061eb8df3027b2e2ff433ddbb", "best_bid": "0.43", "best_ask": "0.47"}], "timestamp": "1769384037005", "event_type": "price_change"}}
{"_local_timestamp": "2026-01-25T23:33:57.155899+00:00", "data": {"market": "0xd96573e2b56ec287fb0d47bf9014186c1e4f99702dda924fd8d9b60941cf26a6", "price_changes": [{"asset_id": "34438968861365109913426207322647965910661206508063798834616500635073575974183", "price": "0.09", "size": "100", "side": "BUY", "hash": "502e145ea4f4840210d534fbebc427fdecb7664e", "best_bid": "0.46", "best_ask": "0.48"}, {"asset_id": "98488092907000911031005324087845962957388487171241715258741738454368088401315", "price": "0.91", "size": "100", "side": "SELL", "hash": "cf4fa79ce3bd357b529c99ab2cea8a355fb7c018", "best_bid": "0.52", "best_ask": "0.54"}], "timestamp": "1769384037002", "event_type": "price_change"}}
{"_local_timestamp": "2026-01-25T23:33:57.156387+00:00", "data": {"market": "0x553717c180334e4b0693f864252ccaf7cb71b8be4c4c864e3dd3d6426c737a15", "price_changes": [{"asset_id": "102511791078625420334874150607165490922635280507748374937515274449950760080038", "price": "0.04", "size": "49", "side": "BUY", "hash": "ab475a8692b5571fa0627ccadf4ca2c181960f83", "best_bid": "0.24", "best_ask": "0.94"}, {"asset_id": "57896995315976252262711688210496860966105380178462732161329389639530526897936", "price": "0.96", "size": "49", "side": "SELL", "hash": "8432f08357d9ae8cbfa7cdf23ce7604f6c1ca294", "best_bid": "0.06", "best_ask": "0.76"}], "timestamp": "1769384037002", "event_type": "price_change"}}
{"_local_timestamp": "2026-01-25T23:33:57.156749+00:00", "data": {"market": "0xd96573e2b56ec287fb0d47bf9014186c1e4f99702dda924fd8d9b60941cf26a6", "price_changes": [{"asset_id": "98488092907000911031005324087845962957388487171241715258741738454368088401315", "price": "0.09", "size": "100", "side": "BUY", "hash": "41ef59a2fa83a9aa0ce7c0d7480ddc9129c487c1", "best_bid": "0.52", "best_ask": "0.54"}, {"asset_id": "34438968861365109913426207322647965910661206508063798834616500635073575974183", "price": "0.91", "size": "100", "side": "SELL", "hash": "2059d66c0b1867f4f5a082dab3284f94157187e4", "best_bid": "0.46", "best_ask": "0.48"}], "timestamp": "1769384037006", "event_type": "price_change"}}
{"_local_timestamp": "2026-01-25T23:33:57.157064+00:00", "data": {"market": "0xe20347279d1e95825b4a4156680ce2adffee4ec693635d3a251d993880d47d8a", "price_changes": [{"asset_id": "15760759017607793635266566763936429339574160223404740070777269991176507478842", "price": "0.09", "size": "100", "side": "BUY", "hash": "892a28b8b261d4c8ebd15bf8f7fe4b735d371cfe", "best_bid": "0.5", "best_ask": "0.51"}, {"asset_id": "85403516720171167773566543912461162711370406995858075142351224114108329589213", "price": "0.91", "size": "100", "side": "SELL", "hash": "018d24164310835ab38ce67f7e4da6139e0797f9", "best_bid": "0.49", "best_ask": "0.5"}], "timestamp": "1769384037000", "event_type": "price_change"}}
{"_local_timestamp": "2026-01-25T23:33:57.157408+00:00", "data": {"market": "0xce87eb2516a5b532103a2135f1554236094e90dd3d9de97bfdbadc71354b3465", "price_changes": [{"asset_id": "88608754828258084988933745325690635842462641669820818068243390744454078703539", "price": "0.06", "size": "133", "side": "BUY", "hash": "470a9d87038fe4729d4be034bd91b6ae4f508a68", "best_bid": "0.35", "best_ask": "0.94"}, {"asset_id": "113873798648996768464994374356614188404101228550867358872123015702830202946444", "price": "0.94", "size": "133", "side": "SELL", "hash": "cdf371a276784e507b797f75604999f273fd9348", "best_bid": "0.06", "best_ask": "0.65"}], "timestamp": "1769384037003", "event_type": "price_change"}}
{"_local_timestamp": "2026-01-25T23:33:57.157732+00:00", "data": {"market": "0xe20347279d1e95825b4a4156680ce2adffee4ec693635d3a251d993880d47d8a", "price_changes": [{"asset_id": "85403516720171167773566543912461162711370406995858075142351224114108329589213", "price": "0.09", "size": "100", "side": "BUY", "hash": "a1063f639cd2c57847413f04ee828cf52596be40", "best_bid": "0.49", "best_ask": "0.5"}, {"asset_id": "15760759017607793635266566763936429339574160223404740070777269991176507478842", "price": "0.91", "size": "100", "side": "SELL", "hash": "39ae7f5fad1007722aecff77f40fed61067ada50", "best_bid": "0.5", "best_ask": "0.51"}], "timestamp": "1769384037006", "event_type": "price_change"}}
{"_local_timestamp": "2026-01-25T23:33:57.589638+00:00", "data": {"market": "0xbf3100d84bfd1b4d2936ceb8dd3a29a65f1ad9f00f135636255eef0b5bdbe359", "price_changes": [{"asset_id": "56104088600014710064818932436571644113019907992309555438937676208970391548401", "price": "0.09", "size": "7.35", "side": "BUY", "hash": "5a7d19e1021ccbc4184277eafb581e238bbf8a83", "best_bid": "0.73", "best_ask": "0.76"}, {"asset_id": "17231604872299400939311521877066387175626533356330458345531604304528475721436", "price": "0.91", "size": "7.35", "side": "SELL", "hash": "d860958bbe9b56a82bc377f63848e50335199856", "best_bid": "0.24", "best_ask": "0.27"}], "timestamp": "1769384037521", "event_type": "price_change"}}
{"_local_timestamp": "2026-01-25T23:33:57.593925+00:00", "data": {"market": "0xbf3100d84bfd1b4d2936ceb8dd3a29a65f1ad9f00f135636255eef0b5bdbe359", "price_changes": [{"asset_id": "56104088600014710064818932436571644113019907992309555438937676208970391548401", "price": "0.02", "size": "14.42", "side": "BUY", "hash": "0ec104fe4711bbe08236111dcba7b0db681bcd2b", "best_bid": "0.73", "best_ask": "0.76"}, {"asset_id": "17231604872299400939311521877066387175626533356330458345531604304528475721436", "price": "0.98", "size": "14.42", "side": "SELL", "hash": "22f3834c3fe052a469e4642555e0bd6ce9ea302f", "best_bid": "0.24", "best_ask": "0.27"}], "timestamp": "1769384037523", "event_type": "price_change"}}
{"_local_timestamp": "2026-01-25T23:33:57.594344+00:00", "data": {"market": "0xbf3100d84bfd1b4d2936ceb8dd3a29a65f1ad9f00f135636255eef0b5bdbe359", "price_changes": [{"asset_id": "56104088600014710064818932436571644113019907992309555438937676208970391548401", "price": "0.01", "size": "185", "side": "BUY", "hash": "639c01fab590e02050afed2ff407b0c7027a17b0", "best_bid": "0.73", "best_ask": "0.76"}, {"asset_id": "17231604872299400939311521877066387175626533356330458345531604304528475721436", "price": "0.99", "size": "185", "side": "SELL", "hash": "c7f006a5b0c25e9fa98a65a37145b00b519c2357", "best_bid": "0.24", "best_ask": "0.27"}], "timestamp": "1769384037524", "event_type": "price_change"}}
{"_local_timestamp": "2026-01-25T23:33:57.628857+00:00", "data": {"market": "0x72d347777d7cd1a36b33d82ee33e8647d979b8e97d7870f290e585068e2eaf18", "price_changes": [{"asset_id": "18064383735028350165016189664106232638333255077909753138952756695769424263258", "price": "0.15", "size": "533", "side": "BUY", "hash": "9736c1e9855e292713fab305a4a244c82b12e8ef", "best_bid": "0.48", "best_ask": "0.94"}, {"asset_id": "46035028623017636966245851645568333453935371029373895359296143781534136191296", "price": "0.85", "size": "533", "side": "SELL", "hash": "d02945c6f793582d72c1da0a81e62a4603fcaa09", "best_bid": "0.06", "best_ask": "0.52"}], "timestamp": "1769384037562", "event_type": "price_change"}}
{"_local_timestamp": "2026-01-25T23:33:57.629331+00:00", "data": {"market": "0xce87eb2516a5b532103a2135f1554236094e90dd3d9de97bfdbadc71354b3465", "price_changes": [{"asset_id": "88608754828258084988933745325690635842462641669820818068243390744454078703539", "price": "0.06", "size": "1466", "side": "BUY", "hash": "6fc3324b719e54b85704c54a5c7e7cc975fbdd80", "best_bid": "0.35", "best_ask": "0.94"}, {"asset_id": "113873798648996768464994374356614188404101228550867358872123015702830202946444", "price": "0.94", "size": "1466", "side": "SELL", "hash": "6aa726df20bf310c5574f64f08d686c2aeabdeb2", "best_bid": "0.06", "best_ask": "0.65"}], "timestamp": "1769384037562", "event_type": "price_change"}}
{"_local_timestamp": "2026-01-25T23:33:57.635078+00:00", "data": {"market": "0xd96573e2b56ec287fb0d47bf9014186c1e4f99702dda924fd8d9b60941cf26a6", "price_changes": [{"asset_id": "98488092907000911031005324087845962957388487171241715258741738454368088401315", "price": "0.39", "size": "615", "side": "BUY", "hash": "136ca3c44a30e52a2dfae42aa56d805870d081c3", "best_bid": "0.52", "best_ask": "0.54"}, {"asset_id": "34438968861365109913426207322647965910661206508063798834616500635073575974183", "price": "0.61", "size": "615", "side": "SELL", "hash": "ce5ebbf3a7f77207c9caf6bb8628279db0d11b1f", "best_bid": "0.46", "best_ask": "0.48"}], "timestamp": "1769384037562", "event_type": "price_change"}}
{"_local_timestamp": "2026-01-25T23:33:57.840796+00:00", "data": {"market": "0x4aeb687ccd1da9f19d15cb7d6f820fe079af3c856f9104f42d46943ca45b27bd", "price_changes": [{"asset_id": "31999400366734158104301855635228245130465493243805955843366583423501887482170", "price": "0.15", "size": "533", "side": "BUY", "hash": "7baaf978dbcb2005d7cc9e7240c3cf2e50e710b4", "best_bid": "0.49", "best_ask": "0.5"}, {"asset_id": "37176936087015401749148910450904482030865323565946722820937013963453694752742", "price": "0.85", "size": "533", "side": "SELL", "hash": "19b81d718c6a63a822d53ebdce61bd072de9f306", "best_bid": "0.5", "best_ask": "0.51"}], "timestamp": "1769384037772", "event_type": "price_change"}}
{"_local_timestamp": "2026-01-25T23:33:57.841277+00:00", "data": {"market": "0x1555baa85050bf46a6d9da9c541a846acefc0628617420021491f54f9d500eb6", "price_changes": [{"asset_id": "32274055423245537060314713137501562171927568362585652608301331862191261412289", "price": "0.15", "size": "533", "side": "BUY", "hash": "df3cd194b7f27077eb47bb0feb8cb7365934d988", "best_bid": "0.48", "best_ask": "0.94"}, {"asset_id": "61599985294999295036709505701627609233274312766724636571888085254678251971053", "price": "0.85", "size": "533", "side": "SELL", "hash": "f383b5f4eee60c34f41961427d6f8669fc315897", "best_bid": "0.06", "best_ask": "0.52"}], "timestamp": "1769384037772", "event_type": "price_change"}}
{"_local_timestamp": "2026-01-25T23:33:57.841667+00:00", "data": {"market": "0x276feb4e6900616b8bcc16cb8ed3999c9f1b4c8d787a6e39c64eae8a56331785", "price_changes": [{"asset_id": "7423607558283097154922229155464812895905397994692604969007056718754573875966", "price": "0.15", "size": "533", "side": "BUY", "hash": "f2dab70ba73417150a7e16add8f2bcecbb57295e", "best_bid": "0.48", "best_ask": "0.94"}, {"asset_id": "9805663437273261911623793336871785235625194636606276182840463401876316400402", "price": "0.85", "size": "533", "side": "SELL", "hash": "28217c2d140ff2865bc62b3a2e92f94575470a55", "best_bid": "0.06", "best_ask": "0.52"}], "timestamp": "1769384037772", "event_type": "price_change"}}
{"_local_timestamp": "2026-01-25T23:33:57.842136+00:00", "data": {"market": "0xc60d873e8bc171516c3631a8a31cc254cced6f2f3402e3c0a40475cab007b3c3", "price_changes": [{"asset_id": "25038904154097477604831493054093732539212779801414767373024639544798326517822", "price": "0.09", "size": "895.03", "side": "BUY", "hash": "75380dd9d57a7abef2c6053cfe71af5b12025f55", "best_bid": "0.45", "best_ask": "0.94"}, {"asset_id": "107074978358193625457427782320573845396027159383434708562159503922684086133798", "price": "0.91", "size": "895.03", "side": "SELL", "hash": "ae6442124088446ad854f76e25a0f4010795301a", "best_bid": "0.06", "best_ask": "0.55"}], "timestamp": "1769384037772", "event_type": "price_change"}}
{"_local_timestamp": "2026-01-25T23:33:57.842521+00:00", "data": {"market": "0xc6ff7f8ae1f58824aa11d979b259c782ef25a93a66b73fa37b1f87edaedfad91", "price_changes": [{"asset_id": "13633497108394864151898342255330331854488146311506893611678517594038032864012", "price": "0.09", "size": "888", "side": "BUY", "hash": "6ba6b4c6fae65ef1b9764afe8dbcb7c9a37d061b", "best_bid": "0.43", "best_ask": "0.94"}, {"asset_id": "82879689812327174643178891537605396737802568583972628524772921113776829540299", "price": "0.91", "size": "888", "side": "SELL", "hash": "1affc325eb3ba92efc7dbed11493f1bee66006ab", "best_bid": "0.06", "best_ask": "0.57"}], "timestamp": "1769384037772", "event_type": "price_change"}}
{"_local_timestamp": "2026-01-25T23:33:57.842915+00:00", "data": {"market": "0xbf3100d84bfd1b4d2936ceb8dd3a29a65f1ad9f00f135636255eef0b5bdbe359", "price_changes": [{"asset_id": "17231604872299400939311521877066387175626533356330458345531604304528475721436", "price": "0.19", "size": "921", "side": "BUY", "hash": "9a054b8cb5b922df27054d03f945e3167481bfbb", "best_bid": "0.24", "best_ask": "0.27"}, {"asset_id": "56104088600014710064818932436571644113019907992309555438937676208970391548401", "price": "0.81", "size": "921", "side": "SELL", "hash": "f1ca2307f5d6439d4e818d8730f9cd536ec00b48", "best_bid": "0.73", "best_ask": "0.76"}], "timestamp": "1769384037772", "event_type": "price_change"}}
{"_local_timestamp": "2026-01-25T23:33:57.843355+00:00", "data": {"market": "0x4813bed77c03fbf16137a1a82d6205e681c5182ade34f62019fdf124d1a7ed9b", "price_changes": [{"asset_id": "94529826770937052659833277332473040384030874510786347744954589719895985192344", "price": "0.15", "size": "533", "side": "BUY", "hash": "6556467709e481971bd56d33b605456f7c13642d", "best_bid": "0.47", "best_ask": "0.94"}, {"asset_id": "60017116045841658588171975127368320820424758610672530610810028757397228532611", "price": "0.85", "size": "533", "side": "SELL", "hash": "d3e921d64cb8b873e0ec16b5a1ce2b49a0fd6148", "best_bid": "0.06", "best_ask": "0.53"}], "timestamp": "1769384037772", "event_type": "price_change"}}
{"_local_timestamp": "2026-01-25T23:33:57.843764+00:00", "data": {"market": "0x027f856eb641875fd5d007085b8b821bb362cd6f1c03692e4bdced63d2b25a4b", "price_changes": [{"asset_id": "47192306828537745743716888869289118723245249412466437172347900202017700987092", "price": "0.09", "size": "888", "side": "BUY", "hash": "928685ba73be5a7184984ae7ae26deb448818f89", "best_bid": "0.39", "best_ask": "0.94"}, {"asset_id": "20255608086370617665171362197949393811510991087198640550304707929145511040025", "price": "0.91", "size": "888", "side": "SELL", "hash": "fc0f88335ee2ffbc98e60a03388a1b7a29d7beff", "best_bid": "0.06", "best_ask": "0.61"}], "timestamp": "1769384037772", "event_type": "price_change"}}
{"_local_timestamp": "2026-01-25T23:33:57.844127+00:00", "data": {"market": "0x548bf24ac69dda721ac2c9f70ddf7d4907ddebfaa552b3c9d90c2ea579759850", "price_changes": [{"asset_id": "51674227959772201692995587953323756294034141098159045110117222361966129767794", "price": "0.14", "size": "4485.27", "side": "BUY", "hash": "2be204fd678b0c80467ff1e356bb93b4d027268c", "best_bid": "0.18", "best_ask": "0.19"}, {"asset_id": "87069058062386204514440746177167230003061183275952307043291532056740705911527", "price": "0.86", "size": "4485.27", "side": "SELL", "hash": "b0d7ed550cde579de97a36fc38f1d9304b3916ca", "best_bid": "0.81", "best_ask": "0.82"}], "timestamp": "1769384037772", "event_type": "price_change"}}
{"_local_timestamp": "2026-01-25T23:33:57.844528+00:00", "data": {"market": "0xacaaef7c9046f6699e1e03914b57bbbe21b4cbf8fb3dcaaf8344ceb8e4b44025", "price_changes": [{"asset_id": "115334701046031659857669574453521035737847405682323794956661930269033800746444", "price": "0.22", "size": "1089", "side": "BUY", "hash": "7a5dfc16db225c6d260e213f1016e6c9ad32558a", "best_bid": "0.54", "best_ask": "0.94"}, {"asset_id": "49448311072592590934852668469118736900980437754784941948093990588399063038511", "price": "0.78", "size": "1089", "side": "SELL", "hash": "91b9c1c124b3d7b388989db22406e2f1943d06a2", "best_bid": "0.06", "best_ask": "0.46"}], "timestamp": "1769384037772", "event_type": "price_change"}}
{"_local_timestamp": "2026-01-25T23:33:57.846963+00:00", "data": {"market": "0x368753e3efb08f97336ad250758db1269b06a1ba8b3c8ec95a9a3cb9376a6922", "price_changes": [{"asset_id": "76238761818901615467747373039887925717004845403263853385609995415726570741554", "price": "0.15", "size": "533", "side": "BUY", "hash": "39b3c1035fd6bbf82a69d0f3b108e32ca791e2ad", "best_bid": "0.49", "best_ask": "0.93"}, {"asset_id": "99514244780500968567376277247005595883580395398625637766786354333245186778286", "price": "0.85", "size": "533", "side": "SELL", "hash": "0180bce6af07734613de86faa07dbbb146c94591", "best_bid": "0.07", "best_ask": "0.51"}], "timestamp": "1769384037772", "event_type": "price_change"}}
{"_local_timestamp": "2026-01-25T23:33:57.847425+00:00", "data": {"market": "0x40f679a98a4fafef4fbcc988385f4c35c9a0c05f10a4847863062e3a811cd3fb", "price_changes": [{"asset_id": "23091360226463319683483053319743342815863812458439400577707829686077988900282", "price": "0.38", "size": "630", "side": "BUY", "hash": "dd3fb77037eed945dcbfe0c8d8a2bc8033c9243d", "best_bid": "0.49", "best_ask": "0.52"}, {"asset_id": "96518840264527551423161991822159133271365099061102190292241495549856572100367", "price": "0.62", "size": "630", "side": "SELL", "hash": "783f929611acfc852e8c1c466112afae0df0023c", "best_bid": "0.48", "best_ask": "0.51"}], "timestamp": "1769384037772", "event_type": "price_change"}}
{"_local_timestamp": "2026-01-25T23:33:57.847860+00:00", "data": {"market": "0xd43333b568660feff4879dc11ec96d96ea840467e931fc1d1a30038d3c1f36ba", "price_changes": [{"asset_id": "103558162642701244581198729484531317361688802804085124145550183881006710535142", "price": "0.39", "size": "615", "side": "BUY", "hash": "ff77bf7729a9058bf2c46a84c3ab95424a93574d", "best_bid": "0.49", "best_ask": "0.51"}, {"asset_id": "75835791470537447401195508884423769567933455236872042191341629176792194183781", "price": "0.61", "size": "615", "side": "SELL", "hash": "55f2a2f28b7447a7d6ac2aac514436c80e92e2f3", "best_bid": "0.49", "best_ask": "0.51"}], "timestamp": "1769384037772", "event_type": "price_change"}}
{"_local_timestamp": "2026-01-25T23:33:57.848266+00:00", "data": {"market": "0x970dab0b74ae35835fef12a63f824a981a2e8bd791d6a5d897d8c198b7a05581", "price_changes": [{"asset_id": "64061694358496011599518776148350330301400678821287070763604124728970432722704", "price": "0.42", "size": "1820", "side": "BUY", "hash": "f6563cf20ccc43834040ee55625c298980213596", "best_bid": "0.53", "best_ask": "0.54"}, {"asset_id": "8409692319788303913925099179209639225305394841680202372226896582540503735241", "price": "0.58", "size": "1820", "side": "SELL", "hash": "be306acb39775fcaa3846bdbd1ee249a94bd818c", "best_bid": "0.46", "best_ask": "0.47"}], "timestamp": "1769384037772", "event_type": "price_change"}}
{"_local_timestamp": "2026-01-25T23:33:57.848639+00:00", "data": {"market": "0x14953309778fb38ad4b7d6998ad6c95fce695600381214a2558d0660d54d58e3", "price_changes": [{"asset_id": "60314365318504400021660468969193291406919501032199440844019272800649402550119", "price": "0.41", "size": "585", "side": "BUY", "hash": "494131a9c76d761576f29efe1ff663874fb5fdcc", "best_bid": "0.54", "best_ask": "0.56"}, {"asset_id": "22578179344466948255817514384170808830444290334458668905786911133364969780566", "price": "0.59", "size": "585", "side": "SELL", "hash": "05798efcd787dfc32441b330c94e3f256b03669e", "best_bid": "0.44", "best_ask": "0.46"}], "timestamp": "1769384037772", "event_type": "price_change"}}
{"_local_timestamp": "2026-01-25T23:33:57.920984+00:00", "data": {"market": "0xbf3100d84bfd1b4d2936ceb8dd3a29a65f1ad9f00f135636255eef0b5bdbe359", "price_changes": [{"asset_id": "17231604872299400939311521877066387175626533356330458345531604304528475721436", "price": "0.02", "size": "18.99", "side": "BUY", "hash": "9bc24c85b6e4ef4181c34bd0eebbc31e8eccb42c", "best_bid": "0.24", "best_ask": "0.27"}, {"asset_id": "56104088600014710064818932436571644113019907992309555438937676208970391548401", "price": "0.98", "size": "18.99", "side": "SELL", "hash": "9d2fef73c6e528b16882b7a30b174b2488d76776", "best_bid": "0.73", "best_ask": "0.76"}], "timestamp": "1769384037852", "event_type": "price_change"}}
{"_local_timestamp": "2026-01-25T23:33:58.079315+00:00", "data": {"market": "0xc321c61a4e4789503e1a312aeddfaa3a397b4096a859060223a0e276b724928a", "price_changes": [{"asset_id": "45409360042913098746939749067676955227585590134571136184211831824538810637766", "price": "0.08", "size": "100", "side": "BUY", "hash": "1a50154e404f4ff1d7c22f070a1c062c476fa92b", "best_bid": "0.45", "best_ask": "0.94"}, {"asset_id": "47639675551386288248370262662490783411705761858149174878754249181330435993189", "price": "0.92", "size": "100", "side": "SELL", "hash": "cef88f7f5634cc04f35d9c961b8c313e535b68bb", "best_bid": "0.06", "best_ask": "0.55"}], "timestamp": "1769384038000", "event_type": "price_change"}}
{"_local_timestamp": "2026-01-25T23:33:58.080017+00:00", "data": {"market": "0xc6ff7f8ae1f58824aa11d979b259c782ef25a93a66b73fa37b1f87edaedfad91", "price_changes": [{"asset_id": "13633497108394864151898342255330331854488146311506893611678517594038032864012", "price": "0.08", "size": "100", "side": "BUY", "hash": "b917d127fb1c30757f367cdbd0195f9cdb3161cc", "best_bid": "0.43", "best_ask": "0.94"}, {"asset_id": "82879689812327174643178891537605396737802568583972628524772921113776829540299", "price": "0.92", "size": "100", "side": "SELL", "hash": "315e0af6aaef7cba74f91a4c34ef0e64dc082127", "best_bid": "0.06", "best_ask": "0.57"}], "timestamp": "1769384038000", "event_type": "price_change"}}
{"_local_timestamp": "2026-01-25T23:33:58.082364+00:00", "data": {"market": "0x4813bed77c03fbf16137a1a82d6205e681c5182ade34f62019fdf124d1a7ed9b", "price_changes": [{"asset_id": "94529826770937052659833277332473040384030874510786347744954589719895985192344", "price": "0.09", "size": "107.08", "side": "BUY", "hash": "b9dfe80c5923607ca7bb6c88feab9c185b7b6b64", "best_bid": "0.47", "best_ask": "0.94"}, {"asset_id": "60017116045841658588171975127368320820424758610672530610810028757397228532611", "price": "0.91", "size": "107.08", "side": "SELL", "hash": "ecd7e558e5bc89995e5f4c26537cc9248bdee568", "best_bid": "0.06", "best_ask": "0.53"}], "timestamp": "1769384038000", "event_type": "price_change"}}
{"_local_timestamp": "2026-01-25T23:33:58.082864+00:00", "data": {"market": "0x368753e3efb08f97336ad250758db1269b06a1ba8b3c8ec95a9a3cb9376a6922", "price_changes": [{"asset_id": "76238761818901615467747373039887925717004845403263853385609995415726570741554", "price": "0.09", "size": "100", "side": "BUY", "hash": "204a690b056025da153643966b4ff1b692e05da1", "best_bid": "0.49", "best_ask": "0.93"}, {"asset_id": "99514244780500968567376277247005595883580395398625637766786354333245186778286", "price": "0.91", "size": "100", "side": "SELL", "hash": "d5b83a989c9259a1fa5d9b846d29520f4431494e", "best_bid": "0.07", "best_ask": "0.51"}], "timestamp": "1769384038000", "event_type": "price_change"}}
{"_local_timestamp": "2026-01-25T23:33:58.084442+00:00", "data": {"market": "0x40f679a98a4fafef4fbcc988385f4c35c9a0c05f10a4847863062e3a811cd3fb", "price_changes": [{"asset_id": "96518840264527551423161991822159133271365099061102190292241495549856572100367", "price": "0.09", "size": "100", "side": "BUY", "hash": "a66184eee3d2d0049de651064eb5b5ef06a6ac80", "best_bid": "0.48", "best_ask": "0.51"}, {"asset_id": "23091360226463319683483053319743342815863812458439400577707829686077988900282", "price": "0.91", "size": "100", "side": "SELL", "hash": "2549f6c21f9382a905b54655065174f77801d10f", "best_bid": "0.49", "best_ask": "0.52"}], "timestamp": "1769384038000", "event_type": "price_change"}}
{"_local_timestamp": "2026-01-25T23:33:58.085165+00:00", "data": {"market": "0x3f9017bb85500ceb6e6d2386b9c7e5887d55d0440abd8ed43d17eab892c20b7b", "price_changes": [{"asset_id": "80950492467797193193379494114234135632842600086519859752413283727659795329849", "price": "0.08", "size": "100", "side": "BUY", "hash": "2805d50c1bf8bb9adb66810047b3fd495893c99a", "best_bid": "0.42", "best_ask": "0.94"}, {"asset_id": "54355654810669966953019851931697565992077496147803498797699491383578754798343", "price": "0.92", "size": "100", "side": "SELL", "hash": "1a221b1a3e497f7e6208dd7bb25a732a79e9e68f", "best_bid": "0.06", "best_ask": "0.58"}], "timestamp": "1769384038000", "event_type": "price_change"}}
{"_local_timestamp": "2026-01-25T23:33:58.086465+00:00", "data": {"market": "0x970dab0b74ae35835fef12a63f824a981a2e8bd791d6a5d897d8c198b7a05581", "price_changes": [{"asset_id": "64061694358496011599518776148350330301400678821287070763604124728970432722704", "price": "0.09", "size": "100", "side": "BUY", "hash": "04cdeba892c129802223d09ddb74a50c7d7760ec", "best_bid": "0.53", "best_ask": "0.54"}, {"asset_id": "8409692319788303913925099179209639225305394841680202372226896582540503735241", "price": "0.91", "size": "100", "side": "SELL", "hash": "cd7a55ac6cefffa740b18c8498696324086065b1", "best_bid": "0.46", "best_ask": "0.47"}], "timestamp": "1769384038000", "event_type": "price_change"}}
{"_local_timestamp": "2026-01-25T23:33:58.088285+00:00", "data": {"market": "0x699033710f3f9c616fc2c2faa8841e82774faef40be068a28d02ae48d3da5039", "price_changes": [{"asset_id": "6600280110979446792688496766284105163228498718832706118430734116375831805445", "price": "0.08", "size": "100", "side": "BUY", "hash": "8b6b7af7c61e5e7c0676c409097e04925af84512", "best_bid": "0.43", "best_ask": "0.47"}, {"asset_id": "43393460696979797431541641548274596146619752824207725942315186553106110134984", "price": "0.92", "size": "100", "side": "SELL", "hash": "2cc3f69e3c71acbb787160b52d7a21c6be51f007", "best_bid": "0.53", "best_ask": "0.57"}], "timestamp": "1769384038000", "event_type": "price_change"}}
{"_local_timestamp": "2026-01-25T23:33:58.090090+00:00", "data": {"market": "0x027f856eb641875fd5d007085b8b821bb362cd6f1c03692e4bdced63d2b25a4b", "price_changes": [{"asset_id": "47192306828537745743716888869289118723245249412466437172347900202017700987092", "price": "0.06", "size": "133", "side": "BUY", "hash": "fe7ac63b209d97af9b7b25111da4220bae0ec73d", "best_bid": "0.39", "best_ask": "0.94"}, {"asset_id": "20255608086370617665171362197949393811510991087198640550304707929145511040025", "price": "0.94", "size": "133", "side": "SELL", "hash": "cff9b9c9e2f701575f0233bdbb3e06fe4c245057", "best_bid": "0.06", "best_ask": "0.61"}], "timestamp": "1769384038001", "event_type": "price_change"}}
{"_local_timestamp": "2026-01-25T23:33:58.093852+00:00", "data": {"market": "0x4aeb687ccd1da9f19d15cb7d6f820fe079af3c856f9104f42d46943ca45b27bd", "price_changes": [{"asset_id": "37176936087015401749148910450904482030865323565946722820937013963453694752742", "price": "0.09", "size": "100", "side": "BUY", "hash": "09a26d0a83e808d2de7baac57da10b01141d0aca", "best_bid": "0.5", "best_ask": "0.51"}, {"asset_id": "31999400366734158104301855635228245130465493243805955843366583423501887482170", "price": "0.91", "size": "100", "side": "SELL", "hash": "4aa8b3b4451043b98c107d367636db2d465cb4d4", "best_bid": "0.49", "best_ask": "0.5"}], "timestamp": "1769384038001", "event_type": "price_change"}}
{"_local_timestamp": "2026-01-25T23:33:58.094369+00:00", "data": {"market": "0x79ad62045cfccd5ee44c4b5524c882ae48b39a7361c3aff3aeab4ad60eff1641", "price_changes": [{"asset_id": "114811066368334224522427598750458344638137949385141925744534308089744998037607", "price": "0.09", "size": "100", "side": "BUY", "hash": "12a49aaca6ba8b567f39cbbea284d8bf19120e12", "best_bid": "0.54", "best_ask": "0.94"}, {"asset_id": "81576114709932199356896157795242982589847910718483671004907600344374780896079", "price": "0.91", "size": "100", "side": "SELL", "hash": "b1160dd3cd584c484cd5c80fcca8dce1dc1aee40", "best_bid": "0.06", "best_ask": "0.46"}], "timestamp": "1769384038001", "event_type": "price_change"}}
{"_local_timestamp": "2026-01-25T23:33:58.095668+00:00", "data": {"market": "0xdb343c4acad127a3347d940a9a234e4a34ee0336d5d592d257efd7becc95b78b", "price_changes": [{"asset_id": "10653521437809047751568321889649995103294547094143336041571623048083551756658", "price": "0.06", "size": "133", "side": "BUY", "hash": "29eccf4c426bd20fb3fb45bd41ac78dbf1ecdca0", "best_bid": "0.39", "best_ask": "0.94"}, {"asset_id": "98591285917995444537884769256106664682249607523363808171831009995760685313007", "price": "0.94", "size": "133", "side": "SELL", "hash": "bae48460b281e6344498a29563dcc8d33a3149e7", "best_bid": "0.06", "best_ask": "0.61"}], "timestamp": "1769384038001", "event_type": "price_change"}}
{"_local_timestamp": "2026-01-25T23:33:58.096252+00:00", "data": {"market": "0x022a494a4694f3e321b54bb614b9f28d6518affc42c2f5103268777aff340676", "price_changes": [{"asset_id": "115051638738409169136056281271864361408130311808920398707671348119359366272512", "price": "0.09", "size": "100", "side": "BUY", "hash": "293987a81353973eedae8bdab28a79b8ef580518", "best_bid": "0.48", "best_ask": "0.49"}, {"asset_id": "25773853969587863829989803215799191248993842554985046236206202852592687161509", "price": "0.91", "size": "100", "side": "SELL", "hash": "ddaca41c1a976a690a2dd8f211c4ea4f68fb6506", "best_bid": "0.51", "best_ask": "0.52"}], "timestamp": "1769384038000", "event_type": "price_change"}}
{"_local_timestamp": "2026-01-25T23:33:58.097321+00:00", "data": {"market": "0x276feb4e6900616b8bcc16cb8ed3999c9f1b4c8d787a6e39c64eae8a56331785", "price_changes": [{"asset_id": "7423607558283097154922229155464812895905397994692604969007056718754573875966", "price": "0.09", "size": "100", "side": "BUY", "hash": "c898e7a68b200289efcdf41a35d7ccb6d8948d30", "best_bid": "0.48", "best_ask": "0.94"}, {"asset_id": "9805663437273261911623793336871785235625194636606276182840463401876316400402", "price": "0.91", "size": "100", "side": "SELL", "hash": "45d1893a6b9a9df88493798c19262bfdeb6f8c34", "best_bid": "0.06", "best_ask": "0.52"}], "timestamp": "1769384038001", "event_type": "price_change"}}
{"_local_timestamp": "2026-01-25T23:33:58.098770+00:00", "data": {"market": "0xbeaaa3c19d9c2146bde70ce718dbe0bb8f4e0fb890d4db8d7ff8597a55b362bd", "price_changes": [{"asset_id": "15665430989345325971273692347463559296866176989612289943080209656894471940771", "price": "0.09", "size": "100", "side": "BUY", "hash": "f23ec489811166848e2d91b914009ad2757bfe8f", "best_bid": "0.48", "best_ask": "0.94"}, {"asset_id": "114418909511071455670546163939010026272317267800095643774931937235891349628437", "price": "0.91", "size": "100", "side": "SELL", "hash": "869aa37d87e79af6fbe3177f923870b06a70c718", "best_bid": "0.06", "best_ask": "0.52"}], "timestamp": "1769384038001", "event_type": "price_change"}}
{"_local_timestamp": "2026-01-25T23:33:58.100213+00:00", "data": {"market": "0x94a74511beecd2f5565a100a69bf010ed044ed839a452eadadeea5442e55addb", "price_changes": [{"asset_id": "96532776063346938031927063463353616543810050542368500862324915366311944696774", "price": "0.06", "size": "133", "side": "BUY", "hash": "f1f2c01665720824c5e84a7b265068fa348fd5a2", "best_bid": "0.38", "best_ask": "0.94"}, {"asset_id": "101678853064867442294540875677023485238334853345098354004151246822798822107376", "price": "0.94", "size": "133", "side": "SELL", "hash": "2e265742c2e360e72873e9b9e5d02d19dc6d1281", "best_bid": "0.06", "best_ask": "0.62"}], "timestamp": "1769384038001", "event_type": "price_change"}}
{"_local_timestamp": "2026-01-25T23:33:58.100782+00:00", "data": {"market": "0x022a494a4694f3e321b54bb614b9f28d6518affc42c2f5103268777aff340676", "price_changes": [{"asset_id": "115051638738409169136056281271864361408130311808920398707671348119359366272512", "price": "0.34", "size": "705", "side": "BUY", "hash": "997b25bf90387100cdb96277ced8dc4f44a4abf3", "best_bid": "0.48", "best_ask": "0.49"}, {"asset_id": "25773853969587863829989803215799191248993842554985046236206202852592687161509", "price": "0.66", "size": "705", "side": "SELL", "hash": "b43889c2426fb8578ce69b1c757e76c9785e4025", "best_bid": "0.51", "best_ask": "0.52"}], "timestamp": "1769384038002", "event_type": "price_change"}}
{"_local_timestamp": "2026-01-25T23:33:58.101250+00:00", "data": {"market": "0xe20347279d1e95825b4a4156680ce2adffee4ec693635d3a251d993880d47d8a", "price_changes": [{"asset_id": "15760759017607793635266566763936429339574160223404740070777269991176507478842", "price": "0.4", "size": "3192.5", "side": "BUY", "hash": "cccb15ebc7e2939174984545f3fc85d175bd9510", "best_bid": "0.5", "best_ask": "0.51"}, {"asset_id": "85403516720171167773566543912461162711370406995858075142351224114108329589213", "price": "0.6", "size": "3192.5", "side": "SELL", "hash": "0cea84b671ae79eb16efc203053a65d4bbaf152b", "best_bid": "0.49", "best_ask": "0.5"}], "timestamp": "1769384038002", "event_type": "price_change"}}
{"_local_timestamp": "2026-01-25T23:33:58.102169+00:00", "data": {"market": "0xdb478719e450e8668c1b1f4277cb277337eeb28e3187893b2cf9274606acdc10", "price_changes": [{"asset_id": "30360992174849273502988106860990606977917338461653496359799172209662656370135", "price": "0.09", "size": "100", "side": "BUY", "hash": "41890b3078c8e036b94b2f242b07c79614f711d5", "best_bid": "0.47", "best_ask": "0.94"}, {"asset_id": "48272372840153531931189816289176921610011981289675528105214127064708913654280", "price": "0.91", "size": "100", "side": "SELL", "hash": "ffd8f3a83b82f78fe13e8b4ef903aeebb37864d9", "best_bid": "0.06", "best_ask": "0.53"}], "timestamp": "1769384038002", "event_type": "price_change"}}
{"_local_timestamp": "2026-01-25T23:33:58.103511+00:00", "data": {"market": "0x553717c180334e4b0693f864252ccaf7cb71b8be4c4c864e3dd3d6426c737a15", "price_changes": [{"asset_id": "102511791078625420334874150607165490922635280507748374937515274449950760080038", "price": "0.06", "size": "1366", "side": "BUY", "hash": "8ce29fdf79543fb63fce8e984c6afb7480aed6c8", "best_bid": "0.24", "best_ask": "0.94"}, {"asset_id": "57896995315976252262711688210496860966105380178462732161329389639530526897936", "price": "0.94", "size": "1366", "side": "SELL", "hash": "9a3af18a686e7a075945ebe2206bda8a6f3db859", "best_bid": "0.06", "best_ask": "0.76"}], "timestamp": "1769384038003", "event_type": "price_change"}}
{"_local_timestamp": "2026-01-25T23:33:58.106243+00:00", "data": {"market": "0x4f315c93639e2d5b0ad5afe5b7624a32c9c61712b36a5749a9723f0c866c282c", "price_changes": [{"asset_id": "100354985105422193069368093808391113026494155802303272252970274070884378086636", "price": "0.08", "size": "100", "side": "BUY", "hash": "aa25559a5c94da0f8984b5d348967b66eafb7352", "best_bid": "0.44", "best_ask": "0.94"}, {"asset_id": "98740776252092008701353754345596258230814172513568009801637691746881492989205", "price": "0.92", "size": "100", "side": "SELL", "hash": "367ae86b0b04102d0691a96383bd62cfb7ddaaf6", "best_bid": "0.06", "best_ask": "0.56"}], "timestamp": "1769384038001", "event_type": "price_change"}}
{"_local_timestamp": "2026-01-25T23:33:58.108318+00:00", "data": {"market": "0x970dab0b74ae35835fef12a63f824a981a2e8bd791d6a5d897d8c198b7a05581", "price_changes": [{"asset_id": "8409692319788303913925099179209639225305394841680202372226896582540503735241", "price": "0.09", "size": "100", "side": "BUY", "hash": "536cc679cdef7b3f1b27d9814de748ddebb734d1", "best_bid": "0.46", "best_ask": "0.47"}, {"asset_id": "64061694358496011599518776148350330301400678821287070763604124728970432722704", "price": "0.91", "size": "100", "side": "SELL", "hash": "3eb8142f9f20d1e54ed8d6a77b928f5a91732f0e", "best_bid": "0.53", "best_ask": "0.54"}], "timestamp": "1769384038001", "event_type": "price_change"}}
{"_local_timestamp": "2026-01-25T23:33:58.109353+00:00", "data": {"market": "0x26284260436580ed8697a8ecc82ced8166bbefa7e1e3e2762f37e841dd276cfe", "price_changes": [{"asset_id": "92333856247840035551458927633430297221426206023828654020510594713109183061083", "price": "0.09", "size": "888", "side": "BUY", "hash": "6f5dab97aa7c852e6e8da29aa0da79ca19f80f44", "best_bid": "0.44", "best_ask": "0.5"}, {"asset_id": "30033822247502365818165812637815631798884613269431345774686010358646875241490", "price": "0.91", "size": "888", "side": "SELL", "hash": "42759b983895c2ad69dbd853bed41e110d97b4a0", "best_bid": "0.5", "best_ask": "0.56"}], "timestamp": "1769384038003", "event_type": "price_change"}}
{"_local_timestamp": "2026-01-25T23:33:58.109999+00:00", "data": {"market": "0xacaaef7c9046f6699e1e03914b57bbbe21b4cbf8fb3dcaaf8344ceb8e4b44025", "price_changes": [{"asset_id": "115334701046031659857669574453521035737847405682323794956661930269033800746444", "price": "0.09", "size": "100", "side": "BUY", "hash": "5e7d54fe7dcd0a7382c4f1b66031e3ec983fe004", "best_bid": "0.54", "best_ask": "0.94"}, {"asset_id": "49448311072592590934852668469118736900980437754784941948093990588399063038511", "price": "0.91", "size": "100", "side": "SELL", "hash": "c8a2bccce73b049f6db71da8732b3d871e818f3d", "best_bid": "0.06", "best_ask": "0.46"}], "timestamp": "1769384038003", "event_type": "price_change"}}
{"_local_timestamp": "2026-01-25T23:33:58.111934+00:00", "data": {"market": "0xbf3100d84bfd1b4d2936ceb8dd3a29a65f1ad9f00f135636255eef0b5bdbe359", "price_changes": [{"asset_id": "56104088600014710064818932436571644113019907992309555438937676208970391548401", "price": "0.35", "size": "684", "side": "BUY", "hash": "877ae1923456d16325b75cac66e15d2ff073d491", "best_bid": "0.73", "best_ask": "0.76"}, {"asset_id": "17231604872299400939311521877066387175626533356330458345531604304528475721436", "price": "0.65", "size": "684", "side": "SELL", "hash": "eba5d8c0ee24f469dc63bef9f46dde7e5c41c65a", "best_bid": "0.24", "best_ask": "0.27"}], "timestamp": "1769384038003", "event_type": "price_change"}}
{"_local_timestamp": "2026-01-25T23:33:58.113735+00:00", "data": {"market": "0xda9010c105fc532855d1427afbb54bac3a872106b13d70541948524bf3c1f13e", "price_changes": [{"asset_id": "54156514034087263487569029617230664616612015268241749973657295711641068204713", "price": "0.06", "size": "1366", "side": "BUY", "hash": "284ddb40606fc72210435e8b71b1441a22afb555", "best_bid": "0.29", "best_ask": "0.89"}, {"asset_id": "78315379118406859624973110495963480819305867678789445335779496010870936073394", "price": "0.94", "size": "1366", "side": "SELL", "hash": "f436212d72803528524de8be8564558ed93c4ecf", "best_bid": "0.11", "best_ask": "0.71"}], "timestamp": "1769384038003", "event_type": "price_change"}}
{"_local_timestamp": "2026-01-25T23:33:58.115792+00:00", "data": {"market": "0x14953309778fb38ad4b7d6998ad6c95fce695600381214a2558d0660d54d58e3", "price_changes": [{"asset_id": "60314365318504400021660468969193291406919501032199440844019272800649402550119", "price": "0.09", "size": "107.16", "side": "BUY", "hash": "025060005e29d81de0c16eba05dc9ff70a0a1ebf", "best_bid": "0.54", "best_ask": "0.56"}, {"asset_id": "22578179344466948255817514384170808830444290334458668905786911133364969780566", "price": "0.91", "size": "107.16", "side": "SELL", "hash": "f426a99e5478dfb1853e1d8d681fadb9767953da", "best_bid": "0.44", "best_ask": "0.46"}], "timestamp": "1769384038001", "event_type": "price_change"}}
{"_local_timestamp": "2026-01-25T23:33:58.116551+00:00", "data": {"market": "0x970dab0b74ae35835fef12a63f824a981a2e8bd791d6a5d897d8c198b7a05581", "price_changes": [{"asset_id": "8409692319788303913925099179209639225305394841680202372226896582540503735241", "price": "0.34", "size": "705", "side": "BUY", "hash": "93e06b23c4d127395e86668db006ba3ff1cbff19", "best_bid": "0.46", "best_ask": "0.47"}, {"asset_id": "64061694358496011599518776148350330301400678821287070763604124728970432722704", "price": "0.66", "size": "705", "side": "SELL", "hash": "b3a0ea88d128b387ffdd4d11293061f6933ff6dc", "best_bid": "0.53", "best_ask": "0.54"}], "timestamp": "1769384038003", "event_type": "price_change"}}
{"_local_timestamp": "2026-01-25T23:33:58.117098+00:00", "data": {"market": "0x3f5cc35560a89e67a91b5e7bd0e00a3c01ad0e07f2deb5a97666b110e43f47f1", "price_changes": [{"asset_id": "78603243324556293353878442880948079627049482267281633215349873153372325985260", "price": "0.21", "size": "1140", "side": "BUY", "hash": "72b816e5db10ae0890e3107504bd4eea1ab227a2", "best_bid": "0.45", "best_ask": "0.51"}, {"asset_id": "83603974700861762645983613428945838380726029750034095407014914624732138624340", "price": "0.79", "size": "1140", "side": "SELL", "hash": "2c660c56b04dce922ea346aace698e98077aa9f2", "best_bid": "0.49", "best_ask": "0.55"}], "timestamp": "1769384038004", "event_type": "price_change"}}
{"_local_timestamp": "2026-01-25T23:33:58.117912+00:00", "data": {"market": "0x699033710f3f9c616fc2c2faa8841e82774faef40be068a28d02ae48d3da5039", "price_changes": [{"asset_id": "6600280110979446792688496766284105163228498718832706118430734116375831805445", "price": "0.33", "size": "726", "side": "BUY", "hash": "46be54f9b6678f8b05578f2f054acc0f93f82a04", "best_bid": "0.43", "best_ask": "0.47"}, {"asset_id": "43393460696979797431541641548274596146619752824207725942315186553106110134984", "price": "0.67", "size": "726", "side": "SELL", "hash": "65a3691e3fa41d874693c7a3890491cbdb406277", "best_bid": "0.53", "best_ask": "0.57"}], "timestamp": "1769384038004", "event_type": "price_change"}}
{"_local_timestamp": "2026-01-25T23:33:58.118853+00:00", "data": {"market": "0xdb343c4acad127a3347d940a9a234e4a34ee0336d5d592d257efd7becc95b78b", "price_changes": [{"asset_id": "10653521437809047751568321889649995103294547094143336041571623048083551756658", "price": "0.09", "size": "888", "side": "BUY", "hash": "7b08189cde056f3ee707b171dafb2d21534a4a9b", "best_bid": "0.39", "best_ask": "0.94"}, {"asset_id": "98591285917995444537884769256106664682249607523363808171831009995760685313007", "price": "0.91", "size": "888", "side": "SELL", "hash": "b63fd9dec8b89d8625102c65c84b9f367007ade0", "best_bid": "0.06", "best_ask": "0.61"}], "timestamp": "1769384038004", "event_type": "price_change"}}
{"_local_timestamp": "2026-01-25T23:33:58.120226+00:00", "data": {"market": "0x022a494a4694f3e321b54bb614b9f28d6518affc42c2f5103268777aff340676", "price_changes": [{"asset_id": "25773853969587863829989803215799191248993842554985046236206202852592687161509", "price": "0.4", "size": "1850", "side": "BUY", "hash": "765053271bf932b2675e6de19ec4408afa32ea48", "best_bid": "0.51", "best_ask": "0.52"}, {"asset_id": "115051638738409169136056281271864361408130311808920398707671348119359366272512", "price": "0.6", "size": "1850", "side": "SELL", "hash": "f0271b91b089001b3654915da25935adbdaa39bb", "best_bid": "0.48", "best_ask": "0.49"}], "timestamp": "1769384038004", "event_type": "price_change"}}
{"_local_timestamp": "2026-01-25T23:33:58.202823+00:00", "data": {"market": "0x94a74511beecd2f5565a100a69bf010ed044ed839a452eadadeea5442e55addb", "price_changes": [{"asset_id": "96532776063346938031927063463353616543810050542368500862324915366311944696774", "price": "0.06", "size": "1466", "side": "BUY", "hash": "3e60f578d86e3dedf6f9d2c10ad58dd670d9c8c6", "best_bid": "0.38", "best_ask": "0.94"}, {"asset_id": "101678853064867442294540875677023485238334853345098354004151246822798822107376", "price": "0.94", "size": "1466", "side": "SELL", "hash": "c82d5baf8b05861d60e1c67af897c4689b135c5f", "best_bid": "0.06", "best_ask": "0.62"}], "timestamp": "1769384038004", "event_type": "price_change"}}
{"_local_timestamp": "2026-01-25T23:33:58.204806+00:00", "data": {"market": "0xd43333b568660feff4879dc11ec96d96ea840467e931fc1d1a30038d3c1f36ba", "price_changes": [{"asset_id": "75835791470537447401195508884423769567933455236872042191341629176792194183781", "price": "0.39", "size": "615", "side": "BUY", "hash": "c1ad66a22eacd5c5d1b9f7168d3fc3c2773a4755", "best_bid": "0.49", "best_ask": "0.51"}, {"asset_id": "103558162642701244581198729484531317361688802804085124145550183881006710535142", "price": "0.61", "size": "615", "side": "SELL", "hash": "0da4d342bdb76d08963f96f9322b7270292ee318", "best_bid": "0.49", "best_ask": "0.51"}], "timestamp": "1769384038004", "event_type": "price_change"}}
{"_local_timestamp": "2026-01-25T23:33:58.205524+00:00", "data": {"market": "0x86feba9d088e90971ca1d898a4c1bd5797b93dd49d1fdd5621b5e1dbab7bab6c", "price_changes": [{"asset_id": "10171001349424486222245429395998181161288444563211665633638034159023476393263", "price": "0.06", "size": "1466", "side": "BUY", "hash": "9fd6f8e1c00e0eb8c4f4b839a70858cac9833793", "best_bid": "0.38", "best_ask": "0.94"}, {"asset_id": "27514912942320421059111797484653666814872354031839316574031804990218755493417", "price": "0.94", "size": "1466", "side": "SELL", "hash": "5038977a423f8c49953c6cab4d32e2f9f68c607f", "best_bid": "0.06", "best_ask": "0.62"}], "timestamp": "1769384038005", "event_type": "price_change"}}
{"_local_timestamp": "2026-01-25T23:33:58.206548+00:00", "data": {"market": "0x79ad62045cfccd5ee44c4b5524c882ae48b39a7361c3aff3aeab4ad60eff1641", "price_changes": [{"asset_id": "114811066368334224522427598750458344638137949385141925744534308089744998037607", "price": "0.22", "size": "1089", "side": "BUY", "hash": "0e1f180a2b15519c036298b9cd2f2729d9b502cf", "best_bid": "0.54", "best_ask": "0.94"}, {"asset_id": "81576114709932199356896157795242982589847910718483671004907600344374780896079", "price": "0.78", "size": "1089", "side": "SELL", "hash": "14cfcefcc93be232c96633c440e8adf418edbe27", "best_bid": "0.06", "best_ask": "0.46"}], "timestamp": "1769384038005", "event_type": "price_change"}}
{"_local_timestamp": "2026-01-25T23:33:58.295784+00:00", "data": {"market": "0x78ba1e90813a5437dea6ab7a7aeca53f910f3b5cecc5b5b2cbafe3ec3c3aeb57", "price_changes": [{"asset_id": "31355627987268222126547396163770855213217371487708271104745934082289374931694", "price": "0.09", "size": "888", "side": "BUY", "hash": "bac6a3104769512459e8c44cb7bbbd7542b947c3", "best_bid": "0.39", "best_ask": "0.94"}, {"asset_id": "49463105653994466683943093343279734251397612176513055641839956156740014377972", "price": "0.91", "size": "888", "side": "SELL", "hash": "14eb28fbe951833b81fa3a254e69365dd05198b9", "best_bid": "0.06", "best_ask": "0.61"}], "timestamp": "1769384038220", "event_type": "price_change"}}
{"_local_timestamp": "2026-01-25T23:33:58.298391+00:00", "data": {"market": "0xc321c61a4e4789503e1a312aeddfaa3a397b4096a859060223a0e276b724928a", "price_changes": [{"asset_id": "45409360042913098746939749067676955227585590134571136184211831824538810637766", "price": "0.09", "size": "888", "side": "BUY", "hash": "3fa1c99a495b30d677749a06f098872147a089a7", "best_bid": "0.45", "best_ask": "0.94"}, {"asset_id": "47639675551386288248370262662490783411705761858149174878754249181330435993189", "price": "0.91", "size": "888", "side": "SELL", "hash": "019a838a5545ab4f0b078649a051964d6b6b5246", "best_bid": "0.06", "best_ask": "0.55"}], "timestamp": "1769384038220", "event_type": "price_change"}}
{"_local_timestamp": "2026-01-25T23:33:58.300456+00:00", "data": {"market": "0xbeaaa3c19d9c2146bde70ce718dbe0bb8f4e0fb890d4db8d7ff8597a55b362bd", "price_changes": [{"asset_id": "15665430989345325971273692347463559296866176989612289943080209656894471940771", "price": "0.15", "size": "533", "side": "BUY", "hash": "ce55163ad4210dddbc7b88951799db86df25768b", "best_bid": "0.48", "best_ask": "0.94"}, {"asset_id": "114418909511071455670546163939010026272317267800095643774931937235891349628437", "price": "0.85", "size": "533", "side": "SELL", "hash": "f7992a4af6951d7592ea06df17b4fa69fefd5a75", "best_bid": "0.06", "best_ask": "0.52"}], "timestamp": "1769384038220", "event_type": "price_change"}}
{"_local_timestamp": "2026-01-25T23:33:58.301627+00:00", "data": {"market": "0x699033710f3f9c616fc2c2faa8841e82774faef40be068a28d02ae48d3da5039", "price_changes": [{"asset_id": "43393460696979797431541641548274596146619752824207725942315186553106110134984", "price": "0.42", "size": "570", "side": "BUY", "hash": "535a96b79861d5b12eb2d2e5c263536892007957", "best_bid": "0.53", "best_ask": "0.57"}, {"asset_id": "6600280110979446792688496766284105163228498718832706118430734116375831805445", "price": "0.58", "size": "570", "side": "SELL", "hash": "27999259b8ec714c478bc3e5b026ad23ef0bea49", "best_bid": "0.43", "best_ask": "0.47"}], "timestamp": "1769384038220", "event_type": "price_change"}}
{"_local_timestamp": "2026-01-25T23:33:58.302663+00:00", "data": {"market": "0x3d891c4518177a2d0cdef2b26192198849326e69817fec3ec44b1dd5db382d66", "price_changes": [{"asset_id": "47152501071153124210643670797073071998156661386350906991394486559609354161760", "price": "0.09", "size": "888", "side": "BUY", "hash": "a9c733b2a38076fc9fa768acc9c8175da52a7f68", "best_bid": "0.42", "best_ask": "0.94"}, {"asset_id": "102869039310147156187992762631729075600982777916006979703835908426915768394637", "price": "0.91", "size": "888", "side": "SELL", "hash": "05e36999ad142db6f8a0ea7cee0e970819677d04", "best_bid": "0.06", "best_ask": "0.58"}], "timestamp": "1769384038220", "event_type": "price_change"}}
{"_local_timestamp": "2026-01-25T23:33:58.303987+00:00", "data": {"market": "0x3f6580efc1ee6c9ccadc46c6a9cec02647b29f6ee3f825708b0bdb07e0ce411e", "price_changes": [{"asset_id": "115465028598646261292747068550744722498119611179707586190193737079563693789318", "price": "0.06", "size": "1466", "side": "BUY", "hash": "dc5aa28b9b925d84247ff763ffc30c6aca81053d", "best_bid": "0.38", "best_ask": "0.94"}, {"asset_id": "77171203581469637987029219487468322466761142309609924047224127291598835517668", "price": "0.94", "size": "1466", "side": "SELL", "hash": "19f1717a77aaab6c84dddf8f84d1c064d8a48eff", "best_bid": "0.06", "best_ask": "0.62"}], "timestamp": "1769384038220", "event_type": "price_change"}}
{"_local_timestamp": "2026-01-25T23:33:58.305180+00:00", "data": {"market": "0x3f9017bb85500ceb6e6d2386b9c7e5887d55d0440abd8ed43d17eab892c20b7b", "price_changes": [{"asset_id": "80950492467797193193379494114234135632842600086519859752413283727659795329849", "price": "0.09", "size": "888", "side": "BUY", "hash": "46069807d23ff15cdd7597f61134b97222311c90", "best_bid": "0.42", "best_ask": "0.94"}, {"asset_id": "54355654810669966953019851931697565992077496147803498797699491383578754798343", "price": "0.91", "size": "888", "side": "SELL", "hash": "1477089c060d9c2956bb8c67d81ac85614495e90", "best_bid": "0.06", "best_ask": "0.58"}], "timestamp": "1769384038220", "event_type": "price_change"}}
{"_local_timestamp": "2026-01-25T23:33:58.308008+00:00", "data": {"market": "0xd96573e2b56ec287fb0d47bf9014186c1e4f99702dda924fd8d9b60941cf26a6", "price_changes": [{"asset_id": "34438968861365109913426207322647965910661206508063798834616500635073575974183", "price": "0.36", "size": "666", "side": "BUY", "hash": "41e4cae74a472678aeba90c629c3751bbf36d644", "best_bid": "0.46", "best_ask": "0.48"}, {"asset_id": "98488092907000911031005324087845962957388487171241715258741738454368088401315", "price": "0.64", "size": "666", "side": "SELL", "hash": "6c0baa9128a1b316661b5d2a80bd4d1a767a1890", "best_bid": "0.52", "best_ask": "0.54"}], "timestamp": "1769384038220", "event_type": "price_change"}}
{"_local_timestamp": "2026-01-25T23:33:58.309287+00:00", "data": {"market": "0x4aeb687ccd1da9f19d15cb7d6f820fe079af3c856f9104f42d46943ca45b27bd", "price_changes": [{"asset_id": "37176936087015401749148910450904482030865323565946722820937013963453694752742", "price": "0.15", "size": "533", "side": "BUY", "hash": "b233e69f7f1c1f1379a5d2d572ffd527ba876d09", "best_bid": "0.5", "best_ask": "0.51"}, {"asset_id": "31999400366734158104301855635228245130465493243805955843366583423501887482170", "price": "0.85", "size": "533", "side": "SELL", "hash": "43d2b3a31d3e3d2307dc9a732b5df136ce581a20", "best_bid": "0.49", "best_ask": "0.5"}], "timestamp": "1769384038220", "event_type": "price_change"}}
{"_local_timestamp": "2026-01-25T23:33:58.311264+00:00", "data": {"market": "0x4f315c93639e2d5b0ad5afe5b7624a32c9c61712b36a5749a9723f0c866c282c", "price_changes": [{"asset_id": "100354985105422193069368093808391113026494155802303272252970274070884378086636", "price": "0.09", "size": "888", "side": "BUY", "hash": "edb2f1d44ac1ed29a2815bbc9f48865738e44c0e", "best_bid": "0.44", "best_ask": "0.94"}, {"asset_id": "98740776252092008701353754345596258230814172513568009801637691746881492989205", "price": "0.91", "size": "888", "side": "SELL", "hash": "7e3aebe41afffec115770f191ab86ba5299cc330", "best_bid": "0.06", "best_ask": "0.56"}], "timestamp": "1769384038221", "event_type": "price_change"}}
{"_local_timestamp": "2026-01-25T23:33:58.314205+00:00", "data": {"market": "0x08ab4504d44c55feee89fe2deba77f288ac727f0287df8a04c0a0a2162256c8e", "price_changes": [{"asset_id": "18307980820661182087850178444391190250642095340280044705782700446895498486234", "price": "0.09", "size": "888", "side": "BUY", "hash": "9ce69388c31ad9ef6e7bd776333fe6c9ec16613c", "best_bid": "0.41", "best_ask": "0.94"}, {"asset_id": "679278415023314077827788027777238511637764586200547537110586042472687154713", "price": "0.91", "size": "888", "side": "SELL", "hash": "85b428986cf266a84e166b7adce8b00e33d765fb", "best_bid": "0.06", "best_ask": "0.59"}], "timestamp": "1769384038221", "event_type": "price_change"}}
{"_local_timestamp": "2026-01-25T23:33:58.315443+00:00", "data": {"market": "0x40f679a98a4fafef4fbcc988385f4c35c9a0c05f10a4847863062e3a811cd3fb", "price_changes": [{"asset_id": "96518840264527551423161991822159133271365099061102190292241495549856572100367", "price": "0.38", "size": "630", "side": "BUY", "hash": "562008da8c3eca4b226751b179de9eeeb969b6c0", "best_bid": "0.48", "best_ask": "0.51"}, {"asset_id": "23091360226463319683483053319743342815863812458439400577707829686077988900282", "price": "0.62", "size": "630", "side": "SELL", "hash": "750562a563775756dcbea6255c80183253095c86", "best_bid": "0.49", "best_ask": "0.52"}], "timestamp": "1769384038221", "event_type": "price_change"}}
{"_local_timestamp": "2026-01-25T23:33:58.316683+00:00", "data": {"market": "0x548bf24ac69dda721ac2c9f70ddf7d4907ddebfaa552b3c9d90c2ea579759850", "price_changes": [{"asset_id": "87069058062386204514440746177167230003061183275952307043291532056740705911527", "price": "0.64", "size": "819.44", "side": "BUY", "hash": "aea7de2f3665b67836eb1de63ba697c76e61ebee", "best_bid": "0.81", "best_ask": "0.82"}, {"asset_id": "51674227959772201692995587953323756294034141098159045110117222361966129767794", "price": "0.36", "size": "819.44", "side": "SELL", "hash": "4198623bbc3387a3a9152bc9f8487060a36f9b66", "best_bid": "0.18", "best_ask": "0.19"}], "timestamp": "1769384038220", "event_type": "price_change"}}
{"_local_timestamp": "2026-01-25T23:33:58.317245+00:00", "data": {"market": "0xe20347279d1e95825b4a4156680ce2adffee4ec693635d3a251d993880d47d8a", "price_changes": [{"asset_id": "85403516720171167773566543912461162711370406995858075142351224114108329589213", "price": "0.39", "size": "615", "side": "BUY", "hash": "2d258d25e5144714438d2071ca32302a9c6e9d06", "best_bid": "0.49", "best_ask": "0.5"}, {"asset_id": "15760759017607793635266566763936429339574160223404740070777269991176507478842", "price": "0.61", "size": "615", "side": "SELL", "hash": "89c81449cf47cb4f8aa9e9b352c9222dbe642361", "best_bid": "0.5", "best_ask": "0.51"}], "timestamp": "1769384038221", "event_type": "price_change"}}
{"_local_timestamp": "2026-01-25T23:33:58.407046+00:00", "data": {"market": "0x26284260436580ed8697a8ecc82ced8166bbefa7e1e3e2762f37e841dd276cfe", "price_changes": [{"asset_id": "30033822247502365818165812637815631798884613269431345774686010358646875241490", "price": "0.06", "size": "1345.66", "side": "BUY", "hash": "d1ecec14c59468c9914bd90119035c9fe19ca70d", "best_bid": "0.5", "best_ask": "0.56"}, {"asset_id": "92333856247840035551458927633430297221426206023828654020510594713109183061083", "price": "0.94", "size": "1345.66", "side": "SELL", "hash": "6dad3f0fdcd6add2e365dc9d454860dcd664e938", "best_bid": "0.44", "best_ask": "0.5"}], "timestamp": "1769384038331", "event_type": "price_change"}}
{"_local_timestamp": "2026-01-25T23:33:58.408806+00:00", "data": {"market": "0x3f5cc35560a89e67a91b5e7bd0e00a3c01ad0e07f2deb5a97666b110e43f47f1", "price_changes": [{"asset_id": "83603974700861762645983613428945838380726029750034095407014914624732138624340", "price": "0.15", "size": "533", "side": "BUY", "hash": "1d54c188aae7bb4c48732f472b8a8290957e6624", "best_bid": "0.49", "best_ask": "0.55"}, {"asset_id": "78603243324556293353878442880948079627049482267281633215349873153372325985260", "price": "0.85", "size": "533", "side": "SELL", "hash": "d57b2bd02e7527bbe8c7032e01a9c5e7301a1014", "best_bid": "0.45", "best_ask": "0.51"}], "timestamp": "1769384038331", "event_type": "price_change"}}
{"_local_timestamp": "2026-01-25T23:33:58.409836+00:00", "data": {"market": "0xdb478719e450e8668c1b1f4277cb277337eeb28e3187893b2cf9274606acdc10", "price_changes": [{"asset_id": "30360992174849273502988106860990606977917338461653496359799172209662656370135", "price": "0.15", "size": "533", "side": "BUY", "hash": "24baa54a9e8436c02edc4c6d66119e29d9b5c732", "best_bid": "0.47", "best_ask": "0.94"}, {"asset_id": "48272372840153531931189816289176921610011981289675528105214127064708913654280", "price": "0.85", "size": "533", "side": "SELL", "hash": "436c6f95439f78e5381a7f5f8be2a379d9e0e5fa", "best_bid": "0.06", "best_ask": "0.53"}], "timestamp": "1769384038331", "event_type": "price_change"}}
{"_local_timestamp": "2026-01-25T23:33:58.410927+00:00", "data": {"market": "0x03464779bdf4de0a3ebd602b9eef80d7822f6258b52e83508e391ee18d4668eb", "price_changes": [{"asset_id": "55145875173360773600221507709955334901875000631205798113036313355415179334123", "price": "0.06", "size": "1466", "side": "BUY", "hash": "7877d037174fd1061c53cebc4016da742949a72c", "best_bid": "0.34", "best_ask": "0.94"}, {"asset_id": "27139615157740269866908006833759826848004875655274435602141899025932234359266", "price": "0.94", "size": "1466", "side": "SELL", "hash": "d08f35c6c03eaf4136c40411bbeed1018690903d", "best_bid": "0.06", "best_ask": "0.66"}], "timestamp": "1769384038331", "event_type": "price_change"}}
{"_local_timestamp": "2026-01-25T23:33:58.413605+00:00", "data": {"market": "0x14953309778fb38ad4b7d6998ad6c95fce695600381214a2558d0660d54d58e3", "price_changes": [{"asset_id": "22578179344466948255817514384170808830444290334458668905786911133364969780566", "price": "0.35", "size": "684", "side": "BUY", "hash": "0b1bf80fdade194937e210dc7b28fecbb8ecbf4f", "best_bid": "0.44", "best_ask": "0.46"}, {"asset_id": "60314365318504400021660468969193291406919501032199440844019272800649402550119", "price": "0.65", "size": "684", "side": "SELL", "hash": "c542d111b2cb27e8b463d4236f096ee634d95ef7", "best_bid": "0.54", "best_ask": "0.56"}], "timestamp": "1769384038331", "event_type": "price_change"}}
{"_local_timestamp": "2026-01-25T23:33:58.542274+00:00", "data": {"market": "0xbf3100d84bfd1b4d2936ceb8dd3a29a65f1ad9f00f135636255eef0b5bdbe359", "price_changes": [{"asset_id": "17231604872299400939311521877066387175626533356330458345531604304528475721436", "price": "0.18", "size": "2111", "side": "BUY", "hash": "457b70a7924dfab93746e53365b05610a366f39d", "best_bid": "0.24", "best_ask": "0.27"}, {"asset_id": "56104088600014710064818932436571644113019907992309555438937676208970391548401", "price": "0.82", "size": "2111", "side": "SELL", "hash": "9606d6db23d005d3f51d1a241583a262cb82be8c", "best_bid": "0.73", "best_ask": "0.76"}], "timestamp": "1769384038473", "event_type": "price_change"}}
{"_local_timestamp": "2026-01-25T23:33:58.543429+00:00", "data": {"market": "0x699033710f3f9c616fc2c2faa8841e82774faef40be068a28d02ae48d3da5039", "price_changes": [{"asset_id": "6600280110979446792688496766284105163228498718832706118430734116375831805445", "price": "0.32", "size": "4177.25", "side": "BUY", "hash": "d6b47c3caccc32c5dc37c95d5abb62abf00b108c", "best_bid": "0.43", "best_ask": "0.47"}, {"asset_id": "43393460696979797431541641548274596146619752824207725942315186553106110134984", "price": "0.68", "size": "4177.25", "side": "SELL", "hash": "b0e26a9add0691e2f13984edcf03052b0f96df31", "best_bid": "0.53", "best_ask": "0.57"}], "timestamp": "1769384038473", "event_type": "price_change"}}
{"_local_timestamp": "2026-01-25T23:33:58.545337+00:00", "data": {"market": "0xc321c61a4e4789503e1a312aeddfaa3a397b4096a859060223a0e276b724928a", "price_changes": [{"asset_id": "45409360042913098746939749067676955227585590134571136184211831824538810637766", "price": "0.09", "size": "3110", "side": "BUY", "hash": "f7aba36d3293cb247208e4c029643333a7a655ca", "best_bid": "0.45", "best_ask": "0.94"}, {"asset_id": "47639675551386288248370262662490783411705761858149174878754249181330435993189", "price": "0.91", "size": "3110", "side": "SELL", "hash": "3ca77dba55498f1b7ac3979cbf838d9a4aa7b6ae", "best_bid": "0.06", "best_ask": "0.55"}], "timestamp": "1769384038473", "event_type": "price_change"}}
{"_local_timestamp": "2026-01-25T23:33:58.546420+00:00", "data": {"market": "0xdb478719e450e8668c1b1f4277cb277337eeb28e3187893b2cf9274606acdc10", "price_changes": [{"asset_id": "30360992174849273502988106860990606977917338461653496359799172209662656370135", "price": "0.15", "size": "1866", "side": "BUY", "hash": "a70ad0df6797bd76f318d2cb72d3b133df8c86ca", "best_bid": "0.47", "best_ask": "0.94"}, {"asset_id": "48272372840153531931189816289176921610011981289675528105214127064708913654280", "price": "0.85", "size": "1866", "side": "SELL", "hash": "1d71fdf835352128d3e2fac198f01a0f03ce85af", "best_bid": "0.06", "best_ask": "0.53"}], "timestamp": "1769384038473", "event_type": "price_change"}}
{"_local_timestamp": "2026-01-25T23:33:58.547651+00:00", "data": {"market": "0x3f5cc35560a89e67a91b5e7bd0e00a3c01ad0e07f2deb5a97666b110e43f47f1", "price_changes": [{"asset_id": "78603243324556293353878442880948079627049482267281633215349873153372325985260", "price": "0.21", "size": "2092", "side": "BUY", "hash": "f7f985714f6969d61d8e0043bd16d0113e539d03", "best_bid": "0.45", "best_ask": "0.51"}, {"asset_id": "83603974700861762645983613428945838380726029750034095407014914624732138624340", "price": "0.79", "size": "2092", "side": "SELL", "hash": "36cb822ad03194c4e754963ce11e142e2f58b72c", "best_bid": "0.49", "best_ask": "0.55"}], "timestamp": "1769384038473", "event_type": "price_change"}}
{"_local_timestamp": "2026-01-25T23:33:58.548656+00:00", "data": {"market": "0xd96573e2b56ec287fb0d47bf9014186c1e4f99702dda924fd8d9b60941cf26a6", "price_changes": [{"asset_id": "98488092907000911031005324087845962957388487171241715258741738454368088401315", "price": "0.38", "size": "3026", "side": "BUY", "hash": "9581de66c9fcdec4aed487687668332ef63fcd15", "best_bid": "0.52", "best_ask": "0.54"}, {"asset_id": "34438968861365109913426207322647965910661206508063798834616500635073575974183", "price": "0.62", "size": "3026", "side": "SELL", "hash": "12805645f353d4eefc2a7d718068bcc8ae92b341", "best_bid": "0.46", "best_ask": "0.48"}], "timestamp": "1769384038473", "event_type": "price_change"}}
{"_local_timestamp": "2026-01-25T23:33:58.549257+00:00", "data": {"market": "0x027f856eb641875fd5d007085b8b821bb362cd6f1c03692e4bdced63d2b25a4b", "price_changes": [{"asset_id": "47192306828537745743716888869289118723245249412466437172347900202017700987092", "price": "0.09", "size": "3110", "side": "BUY", "hash": "fc765ff7c8d4ed518a3281ec4fe2f2321487d3ab", "best_bid": "0.39", "best_ask": "0.94"}, {"asset_id": "20255608086370617665171362197949393811510991087198640550304707929145511040025", "price": "0.91", "size": "3110", "side": "SELL", "hash": "7ecd721564943c4888eefddb74613ee977829054", "best_bid": "0.06", "best_ask": "0.61"}], "timestamp": "1769384038473", "event_type": "price_change"}}
{"_local_timestamp": "2026-01-25T23:33:58.774289+00:00", "data": {"market": "0x368753e3efb08f97336ad250758db1269b06a1ba8b3c8ec95a9a3cb9376a6922", "price_changes": [{"asset_id": "76238761818901615467747373039887925717004845403263853385609995415726570741554", "price": "0.15", "size": "1866", "side": "BUY", "hash": "968b017872255416dc35820f054a5b07a4d19606", "best_bid": "0.49", "best_ask": "0.93"}, {"asset_id": "99514244780500968567376277247005595883580395398625637766786354333245186778286", "price": "0.85", "size": "1866", "side": "SELL", "hash": "cb5b0df4c8745d5ed1918b0fbf04f0c5488c78a7", "best_bid": "0.07", "best_ask": "0.51"}], "timestamp": "1769384038688", "event_type": "price_change"}}
{"_local_timestamp": "2026-01-25T23:33:58.775644+00:00", "data": {"market": "0x4aeb687ccd1da9f19d15cb7d6f820fe079af3c856f9104f42d46943ca45b27bd", "price_changes": [{"asset_id": "31999400366734158104301855635228245130465493243805955843366583423501887482170", "price": "0.15", "size": "1866", "side": "BUY", "hash": "d37f79ba150ff16da5906f4d015288fe4e593007", "best_bid": "0.49", "best_ask": "0.5"}, {"asset_id": "37176936087015401749148910450904482030865323565946722820937013963453694752742", "price": "0.85", "size": "1866", "side": "SELL", "hash": "8ea576da6f50a2ecd0f1b25577b65631be9b5f84", "best_bid": "0.5", "best_ask": "0.51"}], "timestamp": "1769384038688", "event_type": "price_change"}}
{"_local_timestamp": "2026-01-25T23:33:58.776279+00:00", "data": {"market": "0x3d891c4518177a2d0cdef2b26192198849326e69817fec3ec44b1dd5db382d66", "price_changes": [{"asset_id": "47152501071153124210643670797073071998156661386350906991394486559609354161760", "price": "0.09", "size": "3110", "side": "BUY", "hash": "f4c84cf8276772c8860bb83213f4ebb47a938e39", "best_bid": "0.42", "best_ask": "0.94"}, {"asset_id": "102869039310147156187992762631729075600982777916006979703835908426915768394637", "price": "0.91", "size": "3110", "side": "SELL", "hash": "0ee9ca52157715733703f423cbc98fab168d3af3", "best_bid": "0.06", "best_ask": "0.58"}], "timestamp": "1769384038688", "event_type": "price_change"}}
{"_local_timestamp": "2026-01-25T23:33:58.777267+00:00", "data": {"market": "0xe20347279d1e95825b4a4156680ce2adffee4ec693635d3a251d993880d47d8a", "price_changes": [{"asset_id": "15760759017607793635266566763936429339574160223404740070777269991176507478842", "price": "0.37", "size": "3965.5", "side": "BUY", "hash": "ee460ba75fb21210a0ad2a6dac38579640b3a429", "best_bid": "0.5", "best_ask": "0.51"}, {"asset_id": "85403516720171167773566543912461162711370406995858075142351224114108329589213", "price": "0.63", "size": "3965.5", "side": "SELL", "hash": "dd599a6584f31486c28241c900c73afba89ddd84", "best_bid": "0.49", "best_ask": "0.5"}], "timestamp": "1769384038688", "event_type": "price_change"}}
{"_local_timestamp": "2026-01-25T23:33:58.781933+00:00", "data": {"market": "0x94a74511beecd2f5565a100a69bf010ed044ed839a452eadadeea5442e55addb", "price_changes": [{"asset_id": "96532776063346938031927063463353616543810050542368500862324915366311944696774", "price": "0.06", "size": "4799", "side": "BUY", "hash": "966a1fd8457ba85a5c6493ad258fa97b01649aa1", "best_bid": "0.38", "best_ask": "0.94"}, {"asset_id": "101678853064867442294540875677023485238334853345098354004151246822798822107376", "price": "0.94", "size": "4799", "side": "SELL", "hash": "4498657b17ebc7a8197999ffbc5edd2da0fa5626", "best_bid": "0.06", "best_ask": "0.62"}], "timestamp": "1769384038688", "event_type": "price_change"}}
{"_local_timestamp": "2026-01-25T23:33:58.782983+00:00", "data": {"market": "0x553717c180334e4b0693f864252ccaf7cb71b8be4c4c864e3dd3d6426c737a15", "price_changes": [{"asset_id": "102511791078625420334874150607165490922635280507748374937515274449950760080038", "price": "0.06", "size": "4699", "side": "BUY", "hash": "5c6f98e0b6068b7682edb972509b3d6b471d29a3", "best_bid": "0.24", "best_ask": "0.94"}, {"asset_id": "57896995315976252262711688210496860966105380178462732161329389639530526897936", "price": "0.94", "size": "4699", "side": "SELL", "hash": "b194256412d8338955ebdd988f8fa520c76b7db8", "best_bid": "0.06", "best_ask": "0.76"}], "timestamp": "1769384038688", "event_type": "price_change"}}
{"_local_timestamp": "2026-01-25T23:33:58.783579+00:00", "data": {"market": "0x4813bed77c03fbf16137a1a82d6205e681c5182ade34f62019fdf124d1a7ed9b", "price_changes": [{"asset_id": "94529826770937052659833277332473040384030874510786347744954589719895985192344", "price": "0.15", "size": "1866", "side": "BUY", "hash": "3594b02401596912f0a980de15db230c77e001b2", "best_bid": "0.47", "best_ask": "0.94"}, {"asset_id": "60017116045841658588171975127368320820424758610672530610810028757397228532611", "price": "0.85", "size": "1866", "side": "SELL", "hash": "9cebcd39a57d03a1a72f9d14d561a2cf2b23a74d", "best_bid": "0.06", "best_ask": "0.53"}], "timestamp": "1769384038688", "event_type": "price_change"}}
{"_local_timestamp": "2026-01-25T23:33:58.784156+00:00", "data": {"market": "0xacaaef7c9046f6699e1e03914b57bbbe21b4cbf8fb3dcaaf8344ceb8e4b44025", "price_changes": [{"asset_id": "115334701046031659857669574453521035737847405682323794956661930269033800746444", "price": "0.22", "size": "1998", "side": "BUY", "hash": "a3198c49384b6a5cf0a7029c7f47c84fd66d1010", "best_bid": "0.54", "best_ask": "0.94"}, {"asset_id": "49448311072592590934852668469118736900980437754784941948093990588399063038511", "price": "0.78", "size": "1998", "side": "SELL", "hash": "7a3295b29d4cda66ff172c5069906dd9000d017c", "best_bid": "0.06", "best_ask": "0.46"}], "timestamp": "1769384038688", "event_type": "price_change"}}
{"_local_timestamp": "2026-01-25T23:33:58.784700+00:00", "data": {"market": "0x14953309778fb38ad4b7d6998ad6c95fce695600381214a2558d0660d54d58e3", "price_changes": [{"asset_id": "22578179344466948255817514384170808830444290334458668905786911133364969780566", "price": "0.33", "size": "1856", "side": "BUY", "hash": "228dc863a1342ec954e6364f031d39be7d932049", "best_bid": "0.44", "best_ask": "0.46"}, {"asset_id": "60314365318504400021660468969193291406919501032199440844019272800649402550119", "price": "0.67", "size": "1856", "side": "SELL", "hash": "1ee09d27a853a0573eb440d1e082176982d72a38", "best_bid": "0.54", "best_ask": "0.56"}], "timestamp": "1769384038688", "event_type": "price_change"}}
{"_local_timestamp": "2026-01-25T23:33:58.785582+00:00", "data": {"market": "0x1555baa85050bf46a6d9da9c541a846acefc0628617420021491f54f9d500eb6", "price_changes": [{"asset_id": "32274055423245537060314713137501562171927568362585652608301331862191261412289", "price": "0.15", "size": "1866", "side": "BUY", "hash": "614c67d52b5014542a23373e57c2e8fef0173881", "best_bid": "0.48", "best_ask": "0.94"}, {"asset_id": "61599985294999295036709505701627609233274312766724636571888085254678251971053", "price": "0.85", "size": "1866", "side": "SELL", "hash": "64ca063baadd93d8bd1068ae38b4735490952065", "best_bid": "0.06", "best_ask": "0.52"}], "timestamp": "1769384038688", "event_type": "price_change"}}
{"_local_timestamp": "2026-01-25T23:33:58.787127+00:00", "data": {"market": "0x03464779bdf4de0a3ebd602b9eef80d7822f6258b52e83508e391ee18d4668eb", "price_changes": [{"asset_id": "55145875173360773600221507709955334901875000631205798113036313355415179334123", "price": "0.06", "size": "4799", "side": "BUY", "hash": "30797c0cf3f655b33eb2f88f73c0b15dcca3910b", "best_bid": "0.34", "best_ask": "0.94"}, {"asset_id": "27139615157740269866908006833759826848004875655274435602141899025932234359266", "price": "0.94", "size": "4799", "side": "SELL", "hash": "f620f772bc5e35de377435dd9cdc47dd6a7c63ae", "best_bid": "0.06", "best_ask": "0.66"}], "timestamp": "1769384038689", "event_type": "price_change"}}
{"_local_timestamp": "2026-01-25T23:33:58.789351+00:00", "data": {"market": "0x548bf24ac69dda721ac2c9f70ddf7d4907ddebfaa552b3c9d90c2ea579759850", "price_changes": [{"asset_id": "87069058062386204514440746177167230003061183275952307043291532056740705911527", "price": "0.6", "size": "751", "side": "BUY", "hash": "ad3eeff65d01a574f2fdbd1f7b658b0e6475bf9e", "best_bid": "0.81", "best_ask": "0.82"}, {"asset_id": "51674227959772201692995587953323756294034141098159045110117222361966129767794", "price": "0.4", "size": "751", "side": "SELL", "hash": "4a222328af3f0c4b17f6b42f198588664ffadd16", "best_bid": "0.18", "best_ask": "0.19"}], "timestamp": "1769384038688", "event_type": "price_change"}}
{"_local_timestamp": "2026-01-25T23:33:58.790615+00:00", "data": {"market": "0x40f679a98a4fafef4fbcc988385f4c35c9a0c05f10a4847863062e3a811cd3fb", "price_changes": [{"asset_id": "96518840264527551423161991822159133271365099061102190292241495549856572100367", "price": "0.35", "size": "571", "side": "BUY", "hash": "2a6887777035fa2edc963b6cc7d4d3919e8f0d70", "best_bid": "0.48", "best_ask": "0.51"}, {"asset_id": "23091360226463319683483053319743342815863812458439400577707829686077988900282", "price": "0.65", "size": "571", "side": "SELL", "hash": "62472c01426c7ae778be94561bdccdcea2122352", "best_bid": "0.49", "best_ask": "0.52"}], "timestamp": "1769384038689", "event_type": "price_change"}}
{"_local_timestamp": "2026-01-25T23:33:58.791344+00:00", "data": {"market": "0xbf3100d84bfd1b4d2936ceb8dd3a29a65f1ad9f00f135636255eef0b5bdbe359", "price_changes": [{"asset_id": "56104088600014710064818932436571644113019907992309555438937676208970391548401", "price": "0.35", "size": "1255", "side": "BUY", "hash": "68fb4887855302d4ae889f47af10d5ae7af63a0a", "best_bid": "0.73", "best_ask": "0.76"}, {"asset_id": "17231604872299400939311521877066387175626533356330458345531604304528475721436", "price": "0.65", "size": "1255", "side": "SELL", "hash": "c4ea2d160936e7e3f5e9bfa7edd541c4b3f4c68d", "best_bid": "0.24", "best_ask": "0.27"}], "timestamp": "1769384038689", "event_type": "price_change"}}
{"_local_timestamp": "2026-01-25T23:33:58.986441+00:00", "data": {"market": "0xce87eb2516a5b532103a2135f1554236094e90dd3d9de97bfdbadc71354b3465", "price_changes": [{"asset_id": "88608754828258084988933745325690635842462641669820818068243390744454078703539", "price": "0.06", "size": "4799", "side": "BUY", "hash": "08a45ce424dce22de0d1b08f69f560d5a4364cac", "best_bid": "0.35", "best_ask": "0.94"}, {"asset_id": "113873798648996768464994374356614188404101228550867358872123015702830202946444", "price": "0.94", "size": "4799", "side": "SELL", "hash": "0517ec14932d615673db17fc8cb292b5fb3a7fcd", "best_bid": "0.06", "best_ask": "0.65"}], "timestamp": "1769384038903", "event_type": "price_change"}}
{"_local_timestamp": "2026-01-25T23:33:58.989961+00:00", "data": {"market": "0x72d347777d7cd1a36b33d82ee33e8647d979b8e97d7870f290e585068e2eaf18", "price_changes": [{"asset_id": "18064383735028350165016189664106232638333255077909753138952756695769424263258", "price": "0.15", "size": "1866", "side": "BUY", "hash": "30f1d686e1acdb7c7952423ec5d7653f0906337e", "best_bid": "0.48", "best_ask": "0.94"}, {"asset_id": "46035028623017636966245851645568333453935371029373895359296143781534136191296", "price": "0.85", "size": "1866", "side": "SELL", "hash": "bcc690878c24a8ee7a5aface73b65f7984e50cf0", "best_bid": "0.06", "best_ask": "0.52"}], "timestamp": "1769384038903", "event_type": "price_change"}}
{"_local_timestamp": "2026-01-25T23:33:58.991476+00:00", "data": {"market": "0xd96573e2b56ec287fb0d47bf9014186c1e4f99702dda924fd8d9b60941cf26a6", "price_changes": [{"asset_id": "34438968861365109913426207322647965910661206508063798834616500635073575974183", "price": "0.31", "size": "645", "side": "BUY", "hash": "59cf814858cb2a175cf04277c9fbe640850c0ccf", "best_bid": "0.46", "best_ask": "0.48"}, {"asset_id": "98488092907000911031005324087845962957388487171241715258741738454368088401315", "price": "0.69", "size": "645", "side": "SELL", "hash": "eba8a6e0bafa45be66fcc92f42edd547292ccef1", "best_bid": "0.52", "best_ask": "0.54"}], "timestamp": "1769384038903", "event_type": "price_change"}}
{"_local_timestamp": "2026-01-25T23:33:58.992219+00:00", "data": {"market": "0x4f315c93639e2d5b0ad5afe5b7624a32c9c61712b36a5749a9723f0c866c282c", "price_changes": [{"asset_id": "100354985105422193069368093808391113026494155802303272252970274070884378086636", "price": "0.09", "size": "3110", "side": "BUY", "hash": "94f3f41fffbb127dbb67185bce31405a54cce853", "best_bid": "0.44", "best_ask": "0.94"}, {"asset_id": "98740776252092008701353754345596258230814172513568009801637691746881492989205", "price": "0.91", "size": "3110", "side": "SELL", "hash": "5e3c100e0df37ddbd052467e1193313af028bc8a", "best_bid": "0.06", "best_ask": "0.56"}], "timestamp": "1769384038903", "event_type": "price_change"}}
{"_local_timestamp": "2026-01-25T23:33:58.994173+00:00", "data": {"market": "0x86feba9d088e90971ca1d898a4c1bd5797b93dd49d1fdd5621b5e1dbab7bab6c", "price_changes": [{"asset_id": "10171001349424486222245429395998181161288444563211665633638034159023476393263", "price": "0.06", "size": "4799", "side": "BUY", "hash": "4a05dfd03e646a98a4ca70d785b416b56870922e", "best_bid": "0.38", "best_ask": "0.94"}, {"asset_id": "27514912942320421059111797484653666814872354031839316574031804990218755493417", "price": "0.94", "size": "4799", "side": "SELL", "hash": "5b571dbfc0ea45d5bbc0ed3fe9a9e4f5c522dd36", "best_bid": "0.06", "best_ask": "0.62"}], "timestamp": "1769384038903", "event_type": "price_change"}}
{"_local_timestamp": "2026-01-25T23:33:58.998921+00:00", "data": {"market": "0xd43333b568660feff4879dc11ec96d96ea840467e931fc1d1a30038d3c1f36ba", "price_changes": [{"asset_id": "75835791470537447401195508884423769567933455236872042191341629176792194183781", "price": "0.35", "size": "571", "side": "BUY", "hash": "c44230d3270550ed91637fdc0179d0fbf8656573", "best_bid": "0.49", "best_ask": "0.51"}, {"asset_id": "103558162642701244581198729484531317361688802804085124145550183881006710535142", "price": "0.65", "size": "571", "side": "SELL", "hash": "9e612a01b105daebf466f485f3b9f2aaaf520466", "best_bid": "0.49", "best_ask": "0.51"}], "timestamp": "1769384038903", "event_type": "price_change"}}
{"_local_timestamp": "2026-01-25T23:33:59.005850+00:00", "data": {"market": "0x4aeb687ccd1da9f19d15cb7d6f820fe079af3c856f9104f42d46943ca45b27bd", "price_changes": [{"asset_id": "37176936087015401749148910450904482030865323565946722820937013963453694752742", "price": "0.15", "size": "1866", "side": "BUY", "hash": "3f6c6205d9ea5b69003612e7c4be375fbb31c450", "best_bid": "0.5", "best_ask": "0.51"}, {"asset_id": "31999400366734158104301855635228245130465493243805955843366583423501887482170", "price": "0.85", "size": "1866", "side": "SELL", "hash": "ecdd626a505355b162860030fc080114a638fada", "best_bid": "0.49", "best_ask": "0.5"}], "timestamp": "1769384038903", "event_type": "price_change"}}
{"_local_timestamp": "2026-01-25T23:33:59.011677+00:00", "data": {"market": "0x276feb4e6900616b8bcc16cb8ed3999c9f1b4c8d787a6e39c64eae8a56331785", "price_changes": [{"asset_id": "7423607558283097154922229155464812895905397994692604969007056718754573875966", "price": "0.15", "size": "1866", "side": "BUY", "hash": "4221d8745488c50bad540a531ad75b7c231752c1", "best_bid": "0.48", "best_ask": "0.94"}, {"asset_id": "9805663437273261911623793336871785235625194636606276182840463401876316400402", "price": "0.85", "size": "1866", "side": "SELL", "hash": "b045a10e7de1e103c1a061edda681227ee5697d7", "best_bid": "0.06", "best_ask": "0.52"}], "timestamp": "1769384038903", "event_type": "price_change"}}
{"_local_timestamp": "2026-01-25T23:33:59.017155+00:00", "data": {"market": "0x699033710f3f9c616fc2c2faa8841e82774faef40be068a28d02ae48d3da5039", "price_changes": [{"asset_id": "43393460696979797431541641548274596146619752824207725942315186553106110134984", "price": "0.39", "size": "512", "side": "BUY", "hash": "c820b1bb92166030dac8f1c70887c5a6e97ffe4c", "best_bid": "0.53", "best_ask": "0.57"}, {"asset_id": "6600280110979446792688496766284105163228498718832706118430734116375831805445", "price": "0.61", "size": "512", "side": "SELL", "hash": "2891e5738d4846a694398b2c28289aedebeff122", "best_bid": "0.43", "best_ask": "0.47"}], "timestamp": "1769384038903", "event_type": "price_change"}}
{"_local_timestamp": "2026-01-25T23:33:59.019273+00:00", "data": {"market": "0xc6ff7f8ae1f58824aa11d979b259c782ef25a93a66b73fa37b1f87edaedfad91", "price_changes": [{"asset_id": "13633497108394864151898342255330331854488146311506893611678517594038032864012", "price": "0.09", "size": "3110", "side": "BUY", "hash": "9f7c1af995034790d34bfcbf755626ff38533223", "best_bid": "0.43", "best_ask": "0.94"}, {"asset_id": "82879689812327174643178891537605396737802568583972628524772921113776829540299", "price": "0.91", "size": "3110", "side": "SELL", "hash": "0a08ea9eda0a736541753960117c9b4830b81589", "best_bid": "0.06", "best_ask": "0.57"}], "timestamp": "1769384038903", "event_type": "price_change"}}
{"_local_timestamp": "2026-01-25T23:33:59.025766+00:00", "data": {"market": "0x79ad62045cfccd5ee44c4b5524c882ae48b39a7361c3aff3aeab4ad60eff1641", "price_changes": [{"asset_id": "114811066368334224522427598750458344638137949385141925744534308089744998037607", "price": "0.22", "size": "1998", "side": "BUY", "hash": "092ed54593ff263ebc7c259a2ff0876543d6206e", "best_bid": "0.54", "best_ask": "0.94"}, {"asset_id": "81576114709932199356896157795242982589847910718483671004907600344374780896079", "price": "0.78", "size": "1998", "side": "SELL", "hash": "5b9d90ae4db71501cfad95d1b39ea659ca809dc1", "best_bid": "0.06", "best_ask": "0.46"}], "timestamp": "1769384038903", "event_type": "price_change"}}
{"_local_timestamp": "2026-01-25T23:33:59.030291+00:00", "data": {"market": "0x08ab4504d44c55feee89fe2deba77f288ac727f0287df8a04c0a0a2162256c8e", "price_changes": [{"asset_id": "18307980820661182087850178444391190250642095340280044705782700446895498486234", "price": "0.09", "size": "3110", "side": "BUY", "hash": "13eff8f3cce657661acdbb44e0f1c8cbaa5b361c", "best_bid": "0.41", "best_ask": "0.94"}, {"asset_id": "679278415023314077827788027777238511637764586200547537110586042472687154713", "price": "0.91", "size": "3110", "side": "SELL", "hash": "8411ec5974839610c0e28a9f4952b8da5f4a0cec", "best_bid": "0.06", "best_ask": "0.59"}], "timestamp": "1769384038903", "event_type": "price_change"}}
{"_local_timestamp": "2026-01-25T23:33:59.032194+00:00", "data": {"market": "0x022a494a4694f3e321b54bb614b9f28d6518affc42c2f5103268777aff340676", "price_changes": [{"asset_id": "115051638738409169136056281271864361408130311808920398707671348119359366272512", "price": "0.34", "size": "1293", "side": "BUY", "hash": "312f273e53c0fad9ca759d4b5b0b62be2bb1408f", "best_bid": "0.48", "best_ask": "0.49"}, {"asset_id": "25773853969587863829989803215799191248993842554985046236206202852592687161509", "price": "0.66", "size": "1293", "side": "SELL", "hash": "b485b346d7d16592ae7331ee4eb2ff08a4bae304", "best_bid": "0.51", "best_ask": "0.52"}], "timestamp": "1769384038903", "event_type": "price_change"}}
{"_local_timestamp": "2026-01-25T23:33:59.036862+00:00", "data": {"market": "0xe20347279d1e95825b4a4156680ce2adffee4ec693635d3a251d993880d47d8a", "price_changes": [{"asset_id": "85403516720171167773566543912461162711370406995858075142351224114108329589213", "price": "0.35", "size": "571", "side": "BUY", "hash": "e37ec998db28022a6576ae46fd8f47a7347dcb1e", "best_bid": "0.49", "best_ask": "0.5"}, {"asset_id": "15760759017607793635266566763936429339574160223404740070777269991176507478842", "price": "0.65", "size": "571", "side": "SELL", "hash": "6c3bff48cae3db61ba2f9de0eb84653bdb794715", "best_bid": "0.5", "best_ask": "0.51"}], "timestamp": "1769384038903", "event_type": "price_change"}}
{"_local_timestamp": "2026-01-25T23:33:59.041761+00:00", "data": {"market": "0xdb343c4acad127a3347d940a9a234e4a34ee0336d5d592d257efd7becc95b78b", "price_changes": [{"asset_id": "10653521437809047751568321889649995103294547094143336041571623048083551756658", "price": "0.09", "size": "3110", "side": "BUY", "hash": "f20cc48b516c297e373497541ac58ef9c601895d", "best_bid": "0.39", "best_ask": "0.94"}, {"asset_id": "98591285917995444537884769256106664682249607523363808171831009995760685313007", "price": "0.91", "size": "3110", "side": "SELL", "hash": "664807b6d06e224ddd817392997f30663c89ee95", "best_bid": "0.06", "best_ask": "0.61"}], "timestamp": "1769384038903", "event_type": "price_change"}}
{"_local_timestamp": "2026-01-25T23:33:59.203165+00:00", "data": {"market": "0xbeaaa3c19d9c2146bde70ce718dbe0bb8f4e0fb890d4db8d7ff8597a55b362bd", "price_changes": [{"asset_id": "15665430989345325971273692347463559296866176989612289943080209656894471940771", "price": "0.15", "size": "1866", "side": "BUY", "hash": "7092138cc7e8856073069a3842fe21b29a660fa7", "best_bid": "0.48", "best_ask": "0.94"}, {"asset_id": "114418909511071455670546163939010026272317267800095643774931937235891349628437", "price": "0.85", "size": "1866", "side": "SELL", "hash": "f105f9abdf54871cc1e100945f0fd20cfb9317b8", "best_bid": "0.06", "best_ask": "0.52"}], "timestamp": "1769384039126", "event_type": "price_change"}}
{"_local_timestamp": "2026-01-25T23:33:59.235919+00:00", "data": {"market": "0x970dab0b74ae35835fef12a63f824a981a2e8bd791d6a5d897d8c198b7a05581", "price_changes": [{"asset_id": "8409692319788303913925099179209639225305394841680202372226896582540503735241", "price": "0.33", "size": "1856", "side": "BUY", "hash": "61d7f279e37a89e415627af2a14fab07ac97e9ba", "best_bid": "0.46", "best_ask": "0.47"}, {"asset_id": "64061694358496011599518776148350330301400678821287070763604124728970432722704", "price": "0.67", "size": "1856", "side": "SELL", "hash": "d3554594e297354449253100ecfd8b19daed052b", "best_bid": "0.53", "best_ask": "0.54"}], "timestamp": "1769384039126", "event_type": "price_change"}}
{"_local_timestamp": "2026-01-25T23:33:59.237254+00:00", "data": {"market": "0x26284260436580ed8697a8ecc82ced8166bbefa7e1e3e2762f37e841dd276cfe", "price_changes": [{"asset_id": "30033822247502365818165812637815631798884613269431345774686010358646875241490", "price": "0.06", "size": "4678.66", "side": "BUY", "hash": "9a803ec9a75f687aabe0daf0d28d268c02328325", "best_bid": "0.5", "best_ask": "0.56"}, {"asset_id": "92333856247840035551458927633430297221426206023828654020510594713109183061083", "price": "0.94", "size": "4678.66", "side": "SELL", "hash": "98f77cffb44c60bfc7fbfef40fb5ca62d50de423", "best_bid": "0.44", "best_ask": "0.5"}], "timestamp": "1769384039126", "event_type": "price_change"}}
{"_local_timestamp": "2026-01-25T23:33:59.239491+00:00", "data": {"market": "0x78ba1e90813a5437dea6ab7a7aeca53f910f3b5cecc5b5b2cbafe3ec3c3aeb57", "price_changes": [{"asset_id": "31355627987268222126547396163770855213217371487708271104745934082289374931694", "price": "0.09", "size": "3110", "side": "BUY", "hash": "6f28897e1f25e8f911b7c7bf30695fad62c2afa8", "best_bid": "0.39", "best_ask": "0.94"}, {"asset_id": "49463105653994466683943093343279734251397612176513055641839956156740014377972", "price": "0.91", "size": "3110", "side": "SELL", "hash": "a1d08711907938773d59e74e77399c8fe28842cf", "best_bid": "0.06", "best_ask": "0.61"}], "timestamp": "1769384039126", "event_type": "price_change"}}
{"_local_timestamp": "2026-01-25T23:33:59.240182+00:00", "data": {"market": "0x3f6580efc1ee6c9ccadc46c6a9cec02647b29f6ee3f825708b0bdb07e0ce411e", "price_changes": [{"asset_id": "115465028598646261292747068550744722498119611179707586190193737079563693789318", "price": "0.06", "size": "4799", "side": "BUY", "hash": "5accbd41cdccc9d15711ba279070750858bfe0f3", "best_bid": "0.38", "best_ask": "0.94"}, {"asset_id": "77171203581469637987029219487468322466761142309609924047224127291598835517668", "price": "0.94", "size": "4799", "side": "SELL", "hash": "6007a595f0c72258b27309d8f7b1257c696e682e", "best_bid": "0.06", "best_ask": "0.62"}], "timestamp": "1769384039126", "event_type": "price_change"}}
{"_local_timestamp": "2026-01-25T23:33:59.240802+00:00", "data": {"market": "0x3f9017bb85500ceb6e6d2386b9c7e5887d55d0440abd8ed43d17eab892c20b7b", "price_changes": [{"asset_id": "80950492467797193193379494114234135632842600086519859752413283727659795329849", "price": "0.09", "size": "3110", "side": "BUY", "hash": "5f2691679ac76411387a1e684ce92b95db2f608d", "best_bid": "0.42", "best_ask": "0.94"}, {"asset_id": "54355654810669966953019851931697565992077496147803498797699491383578754798343", "price": "0.91", "size": "3110", "side": "SELL", "hash": "6eb52e7651252add1c5bb1df2d198389dac0e058", "best_bid": "0.06", "best_ask": "0.58"}], "timestamp": "1769384039126", "event_type": "price_change"}}
{"_local_timestamp": "2026-01-25T23:33:59.242289+00:00", "data": {"market": "0xc60d873e8bc171516c3631a8a31cc254cced6f2f3402e3c0a40475cab007b3c3", "price_changes": [{"asset_id": "25038904154097477604831493054093732539212779801414767373024639544798326517822", "price": "0.09", "size": "3117.03", "side": "BUY", "hash": "be9265cf855973d039905befbfe0dece39b23d66", "best_bid": "0.45", "best_ask": "0.94"}, {"asset_id": "107074978358193625457427782320573845396027159383434708562159503922684086133798", "price": "0.91", "size": "3117.03", "side": "SELL", "hash": "e387dd6cc34e308d641678ff0f8220d096076bbd", "best_bid": "0.06", "best_ask": "0.55"}], "timestamp": "1769384039126", "event_type": "price_change"}}
{"_local_timestamp": "2026-01-25T23:33:59.243642+00:00", "data": {"market": "0x3f5cc35560a89e67a91b5e7bd0e00a3c01ad0e07f2deb5a97666b110e43f47f1", "price_changes": [{"asset_id": "83603974700861762645983613428945838380726029750034095407014914624732138624340", "price": "0.15", "size": "1866", "side": "BUY", "hash": "1f4cefe2045a22e0d4b92542456f6411417d67cb", "best_bid": "0.49", "best_ask": "0.55"}, {"asset_id": "78603243324556293353878442880948079627049482267281633215349873153372325985260", "price": "0.85", "size": "1866", "side": "SELL", "hash": "b6edf495b73b1e3abfa10bd5af416ee66f101a4e", "best_bid": "0.45", "best_ask": "0.51"}], "timestamp": "1769384039126", "event_type": "price_change"}}
{"_local_timestamp": "2026-01-25T23:33:59.244484+00:00", "data": {"market": "0x40f679a98a4fafef4fbcc988385f4c35c9a0c05f10a4847863062e3a811cd3fb", "price_changes": [{"asset_id": "23091360226463319683483053319743342815863812458439400577707829686077988900282", "price": "0.35", "size": "571", "side": "BUY", "hash": "f9994047e251581d2d0253faca25edbedf1a4640", "best_bid": "0.49", "best_ask": "0.52"}, {"asset_id": "96518840264527551423161991822159133271365099061102190292241495549856572100367", "price": "0.65", "size": "571", "side": "SELL", "hash": "52d3e25350fa6e7660096ff2b9015cc417b400cd", "best_bid": "0.48", "best_ask": "0.51"}], "timestamp": "1769384039126", "event_type": "price_change"}}
{"_local_timestamp": "2026-01-25T23:33:59.245153+00:00", "data": {"market": "0x14953309778fb38ad4b7d6998ad6c95fce695600381214a2558d0660d54d58e3", "price_changes": [{"asset_id": "60314365318504400021660468969193291406919501032199440844019272800649402550119", "price": "0.4", "size": "3000", "side": "BUY", "hash": "103ea727072b5fee26b2b53671ccf00c3bea814a", "best_bid": "0.54", "best_ask": "0.56"}, {"asset_id": "22578179344466948255817514384170808830444290334458668905786911133364969780566", "price": "0.6", "size": "3000", "side": "SELL", "hash": "4947dd12dc535eae645a2bb94df19e479c901988", "best_bid": "0.44", "best_ask": "0.46"}], "timestamp": "1769384039126", "event_type": "price_change"}}
{"_local_timestamp": "2026-01-25T23:33:59.245802+00:00", "data": {"market": "0x022a494a4694f3e321b54bb614b9f28d6518affc42c2f5103268777aff340676", "price_changes": [{"asset_id": "25773853969587863829989803215799191248993842554985046236206202852592687161509", "price": "0.36", "size": "555", "side": "BUY", "hash": "3609da2452ec3e98ad07c92122f5f89af9bd3c18", "best_bid": "0.51", "best_ask": "0.52"}, {"asset_id": "115051638738409169136056281271864361408130311808920398707671348119359366272512", "price": "0.64", "size": "555", "side": "SELL", "hash": "b9dfecac24d812d57b763a39c82c206eb472d1fa", "best_bid": "0.48", "best_ask": "0.49"}], "timestamp": "1769384039126", "event_type": "price_change"}}
{"_local_timestamp": "2026-01-25T23:33:59.249342+00:00", "data": {"market": "0x548bf24ac69dda721ac2c9f70ddf7d4907ddebfaa552b3c9d90c2ea579759850", "price_changes": [{"asset_id": "51674227959772201692995587953323756294034141098159045110117222361966129767794", "price": "0.13", "size": "6188", "side": "BUY", "hash": "3ee110e8be21105fdabd3b6e8fb98a76aaba4471", "best_bid": "0.18", "best_ask": "0.19"}, {"asset_id": "87069058062386204514440746177167230003061183275952307043291532056740705911527", "price": "0.87", "size": "6188", "side": "SELL", "hash": "3fc662cc6e485485e15a5905b160b5ec4357c6ce", "best_bid": "0.81", "best_ask": "0.82"}], "timestamp": "1769384039126", "event_type": "price_change"}}
{"_local_timestamp": "2026-01-25T23:33:59.250521+00:00", "data": {"market": "0xd43333b568660feff4879dc11ec96d96ea840467e931fc1d1a30038d3c1f36ba", "price_changes": [{"asset_id": "103558162642701244581198729484531317361688802804085124145550183881006710535142", "price": "0.35", "size": "571", "side": "BUY", "hash": "53ac5299bec45785e878c485b84ad0a694673c9f", "best_bid": "0.49", "best_ask": "0.51"}, {"asset_id": "75835791470537447401195508884423769567933455236872042191341629176792194183781", "price": "0.65", "size": "571", "side": "SELL", "hash": "fbf8d57f9d7d9638a49211fb5937532e8a512442", "best_bid": "0.49", "best_ask": "0.51"}], "timestamp": "1769384039126", "event_type": "price_change"}}
{"_local_timestamp": "2026-01-25T23:33:59.251668+00:00", "data": {"market": "0x970dab0b74ae35835fef12a63f824a981a2e8bd791d6a5d897d8c198b7a05581", "price_changes": [{"asset_id": "64061694358496011599518776148350330301400678821287070763604124728970432722704", "price": "0.39", "size": "512", "side": "BUY", "hash": "298bfd64d4fb69163f5c89343dbc208d311548b2", "best_bid": "0.53", "best_ask": "0.54"}, {"asset_id": "8409692319788303913925099179209639225305394841680202372226896582540503735241", "price": "0.61", "size": "512", "side": "SELL", "hash": "bf21c363c0bdb0f5091d9b11ec467e9fc264ffad", "best_bid": "0.46", "best_ask": "0.47"}], "timestamp": "1769384039127", "event_type": "price_change"}}
{"_local_timestamp": "2026-01-25T23:33:59.252756+00:00", "data": {"market": "0x26284260436580ed8697a8ecc82ced8166bbefa7e1e3e2762f37e841dd276cfe", "price_changes": [{"asset_id": "92333856247840035551458927633430297221426206023828654020510594713109183061083", "price": "0.09", "size": "3110", "side": "BUY", "hash": "0e6eb68c6e43d13125fe4a18ecf97269307b8ef5", "best_bid": "0.44", "best_ask": "0.5"}, {"asset_id": "30033822247502365818165812637815631798884613269431345774686010358646875241490", "price": "0.91", "size": "3110", "side": "SELL", "hash": "e3054dcfce0799d87b421865c08c58c0fc10c5a7", "best_bid": "0.5", "best_ask": "0.56"}], "timestamp": "1769384039127", "event_type": "price_change"}}
{"_local_timestamp": "2026-01-25T23:33:59.429218+00:00", "data": {"market": "0xda9010c105fc532855d1427afbb54bac3a872106b13d70541948524bf3c1f13e", "price_changes": [{"asset_id": "54156514034087263487569029617230664616612015268241749973657295711641068204713", "price": "0.06", "size": "4699", "side": "BUY", "hash": "8b4fb7fa494044cae09e1b386aa10b18ccb0a8ee", "best_bid": "0.29", "best_ask": "0.89"}, {"asset_id": "78315379118406859624973110495963480819305867678789445335779496010870936073394", "price": "0.94", "size": "4699", "side": "SELL", "hash": "c44b30585ea95bc6ba9ebca1bc5943fd40291fbe", "best_bid": "0.11", "best_ask": "0.71"}], "timestamp": "1769384039342", "event_type": "price_change"}}
{"_local_timestamp": "2026-01-25T23:33:59.491214+00:00", "data": {"market": "0x970dab0b74ae35835fef12a63f824a981a2e8bd791d6a5d897d8c198b7a05581", "price_changes": [{"asset_id": "8409692319788303913925099179209639225305394841680202372226896582540503735241", "price": "0.04", "size": "6.29", "side": "BUY", "hash": "0f2b84887353a7b07536f7e0560610dc1dc43c6a", "best_bid": "0.46", "best_ask": "0.47"}, {"asset_id": "64061694358496011599518776148350330301400678821287070763604124728970432722704", "price": "0.96", "size": "6.29", "side": "SELL", "hash": "63bff77a8a465827cd1f03de06349ac0aa3504c5", "best_bid": "0.53", "best_ask": "0.54"}], "timestamp": "1769384039406", "event_type": "price_change"}}
{"_local_timestamp": "2026-01-25T23:33:59.493794+00:00", "data": {"market": "0x970dab0b74ae35835fef12a63f824a981a2e8bd791d6a5d897d8c198b7a05581", "price_changes": [{"asset_id": "8409692319788303913925099179209639225305394841680202372226896582540503735241", "price": "0.02", "size": "5.1", "side": "BUY", "hash": "637d2f945a5923b5ade779edfd1877a7166835c9", "best_bid": "0.46", "best_ask": "0.47"}, {"asset_id": "64061694358496011599518776148350330301400678821287070763604124728970432722704", "price": "0.98", "size": "5.1", "side": "SELL", "hash": "6682d2449fb946df60ab79a633f96c4e0c648915", "best_bid": "0.53", "best_ask": "0.54"}], "timestamp": "1769384039407", "event_type": "price_change"}}
{"_local_timestamp": "2026-01-25T23:33:59.495660+00:00", "data": {"market": "0x970dab0b74ae35835fef12a63f824a981a2e8bd791d6a5d897d8c198b7a05581", "price_changes": [{"asset_id": "8409692319788303913925099179209639225305394841680202372226896582540503735241", "price": "0.01", "size": "236.67", "side": "BUY", "hash": "9f4f1e8aa260eda9bc2f4d3dbc1341e5c2504c06", "best_bid": "0.46", "best_ask": "0.47"}, {"asset_id": "64061694358496011599518776148350330301400678821287070763604124728970432722704", "price": "0.99", "size": "236.67", "side": "SELL", "hash": "d86e1772d9ea76eed903b736038c79c9c4ffc3d2", "best_bid": "0.53", "best_ask": "0.54"}], "timestamp": "1769384039408", "event_type": "price_change"}}
{"_local_timestamp": "2026-01-25T23:33:59.759185+00:00", "data": {"market": "0x970dab0b74ae35835fef12a63f824a981a2e8bd791d6a5d897d8c198b7a05581", "price_changes": [{"asset_id": "8409692319788303913925099179209639225305394841680202372226896582540503735241", "price": "0.1", "size": "5.94", "side": "BUY", "hash": "70afe742359885d17cb25df6871657f31776cd92", "best_bid": "0.46", "best_ask": "0.47"}, {"asset_id": "64061694358496011599518776148350330301400678821287070763604124728970432722704", "price": "0.9", "size": "5.94", "side": "SELL", "hash": "0fe2e550d487944b23200589e6dd865292df6be1", "best_bid": "0.53", "best_ask": "0.54"}], "timestamp": "1769384039688", "event_type": "price_change"}}
{"_local_timestamp": "2026-01-25T23:34:00.340598+00:00", "data": {"market": "0xd43333b568660feff4879dc11ec96d96ea840467e931fc1d1a30038d3c1f36ba", "price_changes": [{"asset_id": "103558162642701244581198729484531317361688802804085124145550183881006710535142", "price": "0.49", "size": "15720.4", "side": "BUY", "hash": "181c61d5e0669a9570f8edbba7dcec6eb7ffbbf0", "best_bid": "0.49", "best_ask": "0.51"}, {"asset_id": "75835791470537447401195508884423769567933455236872042191341629176792194183781", "price": "0.51", "size": "15720.4", "side": "SELL", "hash": "bb0ddc9da23d22f4cf14357bb93a8081854bedd5", "best_bid": "0.49", "best_ask": "0.51"}], "timestamp": "1769384040260", "event_type": "price_change"}}
