{"_local_timestamp": "2026-01-25T23:41:09.019506+00:00", "data": [{"market": "0xa9c0c820fd79b4339ed4711288ce15236196a6015234350f42b37341e9094398", "asset_id": "91609514063242777856043730063938310894548353925882406409927495687846407164056", "timestamp": "1769384459407", "hash": "4bc885b8660e583f0348c6e7e92f6a7a8353dd6f", "bids": [{"price": "0.01", "size": "15275.55"}, {"price": "0.02", "size": "2255.32"}, {"price": "0.03", "size": "250"}, {"price": "0.04", "size": "21.89"}, {"price": "0.1", "size": "100"}, {"price": "0.12", "size": "300"}, {"price": "0.14", "size": "200"}, {"price": "0.15", "size": "1058"}, {"price": "0.16", "size": "75"}, {"price": "0.18", "size": "1000"}, {"price": "0.19", "size": "493.76"}, {"price": "0.2", "size": "64.17"}, {"price": "0.22", "size": "259.09"}, {"price": "0.23", "size": "47.82"}, {"price": "0.25", "size": "1576.5"}, {"price": "0.26", "size": "666.02"}, {"price": "0.27", "size": "534.85"}, {"price": "0.28", "size": "4618.49"}, {"price": "0.29", "size": "536.09"}, {"price": "0.3", "size": "4"}, {"price": "0.31", "size": "5.65"}], "asks": [{"price": "0.99", "size": "14086.32"}, {"price": "0.98", "size": "2450"}, {"price": "0.97", "size": "9.24"}, {"price": "0.93", "size": "3999.11"}, {"price": "0.92", "size": "2799.11"}, {"price": "0.91", "size": "250"}, {"price": "0.9", "size": "6.23"}, {"price": "0.89", "size": "200"}, {"price": "0.86", "size": "250"}, {"price": "0.8", "size": "400"}, {"price": "0.73", "size": "200"}, {"price": "0.69", "size": "833"}, {"price": "0.66", "size": "100"}, {"price": "0.64", "size": "300"}, {"price": "0.59", "size": "200"}, {"price": "0.56", "size": "125"}, {"price": "0.53", "size": "75"}, {"price": "0.5", "size": "280"}, {"price": "0.46", "size": "200"}, {"price": "0.44", "size": "156.21"}, {"price": "0.43", "size": "19.29"}, {"price": "0.36", "size": "1050"}, {"price": "0.35", "size": "269.54"}, {"price": "0.34", "size": "6.8"}, {"price": "0.33", "size": "10"}], "event_type": "book", "last_trade_price": "0.310"}, {"market": "0xa9c0c820fd79b4339ed4711288ce15236196a6015234350f42b37341e9094398", "asset_id": "78438315737001038193507108078052969359305687599144926740526502005681502958823", "timestamp": "1769384459407", "hash": "6ec42980e288704dadc7abe5ac0721094deff034", "bids": [{"price": "0.01", "size": "14086.32"}, {"price": "0.02", "size": "2450"}, {"price": "0.03", "size": "9.24"}, {"price": "0.07", "size": "3999.11"}, {"price": "0.08", "size": "2799.11"}, {"price": "0.09", "size": "250"}, {"price": "0.1", "size": "6.23"}, {"price": "0.11", "size": "200"}, {"price": "0.14", "size": "250"}, {"price": "0.2", "size": "400"}, {"price": "0.27", "size": "200"}, {"price": "0.31", "size": "833"}, {"price": "0.34", "size": "100"}, {"price": "0.36", "size": "300"}, {"price": "0.41", "size": "200"}, {"price": "0.44", "size": "125"}, {"price": "0.47", "size": "75"}, {"price": "0.5", "size": "280"}, {"price": "0.54", "size": "200"}, {"price": "0.56", "size": "156.21"}, {"price": "0.57", "size": "19.29"}, {"price": "0.64", "size": "1050"}, {"price": "0.65", "size": "269.54"}, {"price": "0.66", "size": "6.8"}, {"price": "0.67", "size": "10"}], "asks": [{"price": "0.99", "size": "15275.55"}, {"price": "0.98", "size": "2255.32"}, {"price": "0.97", "size": "250"}, {"price": "0.96", "size": "21.89"}, {"price": "0.9", "size": "100"}, {"price": "0.88", "size": "300"}, {"price": "0.86", "size": "200"}, {"price": "0.85", "size": "1058"}, {"price": "0.84", "size": "75"}, {"price": "0.82", "size": "1000"}, {"price": "0.81", "size": "493.76"}, {"price": "0.8", "size": "64.17"}, {"price": "0.78", "size": "259.09"}, {"price": "0.77", "size": "47.82"}, {"price": "0.75", "size": "1576.5"}, {"price": "0.74", "size": "666.02"}, {"price": "0.73", "size": "534.85"}, {"price": "0.72", "size": "4618.49"}, {"price": "0.71", "size": "536.09"}, {"price": "0.7", "size": "4"}, {"price": "0.69", "size": "5.65"}], "event_type": "book", "last_trade_price": "0.310"}]}
{"_local_timestamp": "2026-01-25T23:41:10.919075+00:00", "data": {"market": "0xa9c0c820fd79b4339ed4711288ce15236196a6015234350f42b37341e9094398", "price_changes": [{"asset_id": "78438315737001038193507108078052969359305687599144926740526502005681502958823", "price": "0.11", "size": "0", "side": "BUY", "hash": "7e0a601521947e839b1d00e6534d93e33d5a6e53", "best_bid": "0.67", "best_ask": "0.69"}, {"asset_id": "91609514063242777856043730063938310894548353925882406409927495687846407164056", "price": "0.89", "size": "0", "side": "SELL", "hash": "2c61470397e0de37494e48314fc5ec0be04b9efe", "best_bid": "0.31", "best_ask": "0.33"}], "timestamp": "1769384470855", "event_type": "price_change"}}
{"_local_timestamp": "2026-01-25T23:41:11.290675+00:00", "data": {"market": "0xa9c0c820fd79b4339ed4711288ce15236196a6015234350f42b37341e9094398", "price_changes": [{"asset_id": "78438315737001038193507108078052969359305687599144926740526502005681502958823", "price": "0.14", "size": "450", "side": "BUY", "hash": "5b2e394f6cb0b37b0301934a4977003105ec1dc1", "best_bid": "0.67", "best_ask": "0.69"}, {"asset_id": "91609514063242777856043730063938310894548353925882406409927495687846407164056", "price": "0.86", "size": "450", "side": "SELL", "hash": "96a3bfa5fd9451902e20351cc55b1416b5b8d9c8", "best_bid": "0.31", "best_ask": "0.33"}], "timestamp": "1769384471142", "event_type": "price_change"}}
{"_local_timestamp": "2026-01-25T23:41:11.395927+00:00", "data": {"market": "0xa9c0c820fd79b4339ed4711288ce15236196a6015234350f42b37341e9094398", "price_changes": [{"asset_id": "78438315737001038193507108078052969359305687599144926740526502005681502958823", "price": "0.14", "size": "250", "side": "BUY", "hash": "92b350ab8142d969bf434e39fe7a78417d42a69d", "best_bid": "0.67", "best_ask": "0.69"}, {"asset_id": "91609514063242777856043730063938310894548353925882406409927495687846407164056", "price": "0.86", "size": "250", "side": "SELL", "hash": "82ce25cdea689fab50e5694a14a0aa371fa068de", "best_bid": "0.31", "best_ask": "0.33"}], "timestamp": "1769384471263", "event_type": "price_change"}}
{"_local_timestamp": "2026-01-25T23:41:11.418175+00:00", "data": {"market": "0xa9c0c820fd79b4339ed4711288ce15236196a6015234350f42b37341e9094398", "price_changes": [{"asset_id": "78438315737001038193507108078052969359305687599144926740526502005681502958823", "price": "0.15", "size": "200", "side": "BUY", "hash": "590b5afb11cc80a3b4f70cc4e1e1b602d29016b5", "best_bid": "0.67", "best_ask": "0.69"}, {"asset_id": "91609514063242777856043730063938310894548353925882406409927495687846407164056", "price": "0.85", "size": "200", "side": "SELL", "hash": "54cb4628deecfeb8c454dc253ad21770d624505b", "best_bid": "0.31", "best_ask": "0.33"}], "timestamp": "1769384471279", "event_type": "price_change"}}
{"_local_timestamp": "2026-01-25T23:41:17.949269+00:00", "data": {"market": "0xa9c0c820fd79b4339ed4711288ce15236196a6015234350f42b37341e9094398", "price_changes": [{"asset_id": "91609514063242777856043730063938310894548353925882406409927495687846407164056", "price": "0.34", "size": "0", "side": "SELL", "hash": "3a4004b6c68f5ec52de3e0754c4bbcec86cf4d8c", "best_bid": "0.31", "best_ask": "0.33"}, {"asset_id": "78438315737001038193507108078052969359305687599144926740526502005681502958823", "price": "0.66", "size": "0", "side": "BUY", "hash": "a0a4ed66a675eef09e849ccf959912c81938e979", "best_bid": "0.67", "best_ask": "0.69"}], "timestamp": "1769384477840", "event_type": "price_change"}}
{"_local_timestamp": "2026-01-25T23:41:18.928117+00:00", "data": {"market": "0xa9c0c820fd79b4339ed4711288ce15236196a6015234350f42b37341e9094398", "price_changes": [{"asset_id": "91609514063242777856043730063938310894548353925882406409927495687846407164056", "price": "0.34", "size": "6.8", "side": "SELL", "hash": "b06c11f9699677f2baf401332b37f939d2662cb2", "best_bid": "0.31", "best_ask": "0.33"}, {"asset_id": "78438315737001038193507108078052969359305687599144926740526502005681502958823", "price": "0.66", "size": "6.8", "side": "BUY", "hash": "67c9f819084a6f7061ad8f357f19da8d02b62dda", "best_bid": "0.67", "best_ask": "0.69"}], "timestamp": "1769384478854", "event_type": "price_change"}}
{"_local_timestamp": "2026-01-25T23:41:22.392554+00:00", "data": {"market": "0xa9c0c820fd79b4339ed4711288ce15236196a6015234350f42b37341e9094398", "price_changes": [{"asset_id": "78438315737001038193507108078052969359305687599144926740526502005681502958823", "price": "0.14", "size": "50", "side": "BUY", "hash": "c579670d479c828ba38bc35e793dee861418e59b", "best_bid": "0.67", "best_ask": "0.69"}, {"asset_id": "91609514063242777856043730063938310894548353925882406409927495687846407164056", "price": "0.86", "size": "50", "side": "SELL", "hash": "fce95ee88643b824f31eef21f33415da51386db3", "best_bid": "0.31", "best_ask": "0.33"}], "timestamp": "1769384482319", "event_type": "price_change"}}
{"_local_timestamp": "2026-01-25T23:41:22.425841+00:00", "data": {"market": "0xa9c0c820fd79b4339ed4711288ce15236196a6015234350f42b37341e9094398", "price_changes": [{"asset_id": "78438315737001038193507108078052969359305687599144926740526502005681502958823", "price": "0.15", "size": "0", "side": "BUY", "hash": "1e1f680899218346da260064676d7ab26f77a414", "best_bid": "0.67", "best_ask": "0.69"}, {"asset_id": "91609514063242777856043730063938310894548353925882406409927495687846407164056", "price": "0.85", "size": "0", "side": "SELL", "hash": "f29c0e3ac5fb70e278568c4cd9350d9970b2f703", "best_bid": "0.31", "best_ask": "0.33"}], "timestamp": "1769384482362", "event_type": "price_change"}}
{"_local_timestamp": "2026-01-25T23:41:22.436224+00:00", "data": {"market": "0xa9c0c820fd79b4339ed4711288ce15236196a6015234350f42b37341e9094398", "price_changes": [{"asset_id": "78438315737001038193507108078052969359305687599144926740526502005681502958823", "price": "0.14", "size": "250", "side": "BUY", "hash": "c926d1c3d77e0412ba7b5f88a5c2624d620553fd", "best_bid": "0.67", "best_ask": "0.69"}, {"asset_id": "91609514063242777856043730063938310894548353925882406409927495687846407164056", "price": "0.86", "size": "250", "side": "SELL", "hash": "80582e6ae3ae84c41e8466ac2d8db127a75d5b64", "best_bid": "0.31", "best_ask": "0.33"}], "timestamp": "1769384482365", "event_type": "price_change"}}
{"_local_timestamp": "2026-01-25T23:41:22.674358+00:00", "data": {"market": "0xa9c0c820fd79b4339ed4711288ce15236196a6015234350f42b37341e9094398", "price_changes": [{"asset_id": "78438315737001038193507108078052969359305687599144926740526502005681502958823", "price": "0.15", "size": "200", "side": "BUY", "hash": "22ddfc085bb022e638d00fc73f8ac14aabed6cb2", "best_bid": "0.67", "best_ask": "0.69"}, {"asset_id": "91609514063242777856043730063938310894548353925882406409927495687846407164056", "price": "0.85", "size": "200", "side": "SELL", "hash": "ccd12adb94f4fc9a6bca937253fcd3eab3218640", "best_bid": "0.31", "best_ask": "0.33"}], "timestamp": "1769384482595", "event_type": "price_change"}}
{"_local_timestamp": "2026-01-25T23:41:24.475148+00:00", "data": {"market": "0xa9c0c820fd79b4339ed4711288ce15236196a6015234350f42b37341e9094398", "price_changes": [{"asset_id": "78438315737001038193507108078052969359305687599144926740526502005681502958823", "price": "0.16", "size": "200", "side": "BUY", "hash": "deb90a89b338464fb3f04099d293c24cb27a0bb2", "best_bid": "0.67", "best_ask": "0.69"}, {"asset_id": "91609514063242777856043730063938310894548353925882406409927495687846407164056", "price": "0.84", "size": "200", "side": "SELL", "hash": "b59d653858be9e549d8b040892068a4c2effd184", "best_bid": "0.31", "best_ask": "0.33"}], "timestamp": "1769384484366", "event_type": "price_change"}}
{"_local_timestamp": "2026-01-25T23:41:24.476014+00:00", "data": {"market": "0xa9c0c820fd79b4339ed4711288ce15236196a6015234350f42b37341e9094398", "price_changes": [{"asset_id": "78438315737001038193507108078052969359305687599144926740526502005681502958823", "price": "0.14", "size": "50", "side": "BUY", "hash": "94b185c23a9f832e9646863c5d7bcc78ad929d75", "best_bid": "0.67", "best_ask": "0.69"}, {"asset_id": "91609514063242777856043730063938310894548353925882406409927495687846407164056", "price": "0.86", "size": "50", "side": "SELL", "hash": "d72a04c40779b3b26de94cf827715c9ad8f8d6ff", "best_bid": "0.31", "best_ask": "0.33"}], "timestamp": "1769384484367", "event_type": "price_change"}}
{"_local_timestamp": "2026-01-25T23:41:34.047523+00:00", "data": {"market": "0xa9c0c820fd79b4339ed4711288ce15236196a6015234350f42b37341e9094398", "price_changes": [{"asset_id": "78438315737001038193507108078052969359305687599144926740526502005681502958823", "price": "0.15", "size": "0", "side": "BUY", "hash": "aa9fb947158042f551461f44a34d87bdc48fdbe3", "best_bid": "0.67", "best_ask": "0.69"}, {"asset_id": "91609514063242777856043730063938310894548353925882406409927495687846407164056", "price": "0.85", "size": "0", "side": "SELL", "hash": "dd6688f9ef211754a622433a34a08971bc256736", "best_bid": "0.31", "best_ask": "0.33"}], "timestamp": "1769384493970", "event_type": "price_change"}}
{"_local_timestamp": "2026-01-25T23:41:34.083542+00:00", "data": {"market": "0xa9c0c820fd79b4339ed4711288ce15236196a6015234350f42b37341e9094398", "price_changes": [{"asset_id": "78438315737001038193507108078052969359305687599144926740526502005681502958823", "price": "0.14", "size": "250", "side": "BUY", "hash": "19f45a8297099bcf66eb42ab88404f30c5034cb5", "best_bid": "0.67", "best_ask": "0.69"}, {"asset_id": "91609514063242777856043730063938310894548353925882406409927495687846407164056", "price": "0.86", "size": "250", "side": "SELL", "hash": "944cb7d718fc545e52b1b95a7cf16e5337cd265f", "best_bid": "0.31", "best_ask": "0.33"}], "timestamp": "1769384494011", "event_type": "price_change"}}
{"_local_timestamp": "2026-01-25T23:41:34.093272+00:00", "data": {"market": "0xa9c0c820fd79b4339ed4711288ce15236196a6015234350f42b37341e9094398", "price_changes": [{"asset_id": "78438315737001038193507108078052969359305687599144926740526502005681502958823", "price": "0.16", "size": "0", "side": "BUY", "hash": "ac2f057cf7c0479b3b3043f63fd3c18901581e3e", "best_bid": "0.67", "best_ask": "0.69"}, {"asset_id": "91609514063242777856043730063938310894548353925882406409927495687846407164056", "price": "0.84", "size": "0", "side": "SELL", "hash": "fdf75ae16927d0827145153873ee3c2693055d28", "best_bid": "0.31", "best_ask": "0.33"}], "timestamp": "1769384494013", "event_type": "price_change"}}
{"_local_timestamp": "2026-01-25T23:41:34.312811+00:00", "data": {"market": "0xa9c0c820fd79b4339ed4711288ce15236196a6015234350f42b37341e9094398", "price_changes": [{"asset_id": "78438315737001038193507108078052969359305687599144926740526502005681502958823", "price": "0.11", "size": "200", "side": "BUY", "hash": "7b26b1816deb0a9ae8e125ca7e68eccf3199e715", "best_bid": "0.67", "best_ask": "0.69"}, {"asset_id": "91609514063242777856043730063938310894548353925882406409927495687846407164056", "price": "0.89", "size": "200", "side": "SELL", "hash": "a667f5883552ddc3101c80951ab2853ccb6086db", "best_bid": "0.31", "best_ask": "0.33"}], "timestamp": "1769384494244", "event_type": "price_change"}}
{"_local_timestamp": "2026-01-25T23:41:44.405769+00:00", "data": {"market": "0xa9c0c820fd79b4339ed4711288ce15236196a6015234350f42b37341e9094398", "price_changes": [{"asset_id": "78438315737001038193507108078052969359305687599144926740526502005681502958823", "price": "0.11", "size": "0", "side": "BUY", "hash": "66d27f15106a55fbcd32f401ea6f90165c18f2af", "best_bid": "0.67", "best_ask": "0.69"}, {"asset_id": "91609514063242777856043730063938310894548353925882406409927495687846407164056", "price": "0.89", "size": "0", "side": "SELL", "hash": "50df43eeec5193473c812e432cfcc0e3abe78647", "best_bid": "0.31", "best_ask": "0.33"}], "timestamp": "1769384504331", "event_type": "price_change"}}
{"_local_timestamp": "2026-01-25T23:41:44.663587+00:00", "data": {"market": "0xa9c0c820fd79b4339ed4711288ce15236196a6015234350f42b37341e9094398", "price_changes": [{"asset_id": "78438315737001038193507108078052969359305687599144926740526502005681502958823", "price": "0.14", "size": "450", "side": "BUY", "hash": "b74b2ad8167acfcedd2195a719636e26cecc4365", "best_bid": "0.67", "best_ask": "0.69"}, {"asset_id": "91609514063242777856043730063938310894548353925882406409927495687846407164056", "price": "0.86", "size": "450", "side": "SELL", "hash": "9cda8850c1ddda81eb12339a0ca3565a38d2f129", "best_bid": "0.31", "best_ask": "0.33"}], "timestamp": "1769384504593", "event_type": "price_change"}}
{"_local_timestamp": "2026-01-25T23:41:44.698513+00:00", "data": {"market": "0xa9c0c820fd79b4339ed4711288ce15236196a6015234350f42b37341e9094398", "price_changes": [{"asset_id": "78438315737001038193507108078052969359305687599144926740526502005681502958823", "price": "0.15", "size": "200", "side": "BUY", "hash": "0e273769e0fbbe6b6587a87c537b6f2685932e45", "best_bid": "0.67", "best_ask": "0.69"}, {"asset_id": "91609514063242777856043730063938310894548353925882406409927495687846407164056", "price": "0.85", "size": "200", "side": "SELL", "hash": "bf305614f5c0bccffea011658023a652cc4a216e", "best_bid": "0.31", "best_ask": "0.33"}], "timestamp": "1769384504631", "event_type": "price_change"}}
{"_local_timestamp": "2026-01-25T23:41:44.699583+00:00", "data": {"market": "0xa9c0c820fd79b4339ed4711288ce15236196a6015234350f42b37341e9094398", "price_changes": [{"asset_id": "78438315737001038193507108078052969359305687599144926740526502005681502958823", "price": "0.14", "size": "250", "side": "BUY", "hash": "7e554d730f5f7fe9017c519701ea0beb39afed5b", "best_bid": "0.67", "best_ask": "0.69"}, {"asset_id": "91609514063242777856043730063938310894548353925882406409927495687846407164056", "price": "0.86", "size": "250", "side": "SELL", "hash": "f4b8a67964c323a8c18dacbad08c6b71b71d338e", "best_bid": "0.31", "best_ask": "0.33"}], "timestamp": "1769384504632", "event_type": "price_change"}}
{"_local_timestamp": "2026-01-25T23:41:46.709920+00:00", "data": {"market": "0xa9c0c820fd79b4339ed4711288ce15236196a6015234350f42b37341e9094398", "price_changes": [{"asset_id": "78438315737001038193507108078052969359305687599144926740526502005681502958823", "price": "0.15", "size": "0", "side": "BUY", "hash": "cbea40cb8f341da38b167f9badf904e88c5e6e77", "best_bid": "0.67", "best_ask": "0.69"}, {"asset_id": "91609514063242777856043730063938310894548353925882406409927495687846407164056", "price": "0.85", "size": "0", "side": "SELL", "hash": "52c3d20c5287439d4aaa27890c9dcfaf4ea0cca3", "best_bid": "0.31", "best_ask": "0.33"}], "timestamp": "1769384506645", "event_type": "price_change"}}
{"_local_timestamp": "2026-01-25T23:41:54.928994+00:00", "data": {"market": "0xa9c0c820fd79b4339ed4711288ce15236196a6015234350f42b37341e9094398", "price_changes": [{"asset_id": "78438315737001038193507108078052969359305687599144926740526502005681502958823", "price": "0.07", "size": "3799.11", "side": "BUY", "hash": "700c353db69f1f0e585fb7ab2be4dc33f604d6c7", "best_bid": "0.67", "best_ask": "0.69"}, {"asset_id": "91609514063242777856043730063938310894548353925882406409927495687846407164056", "price": "0.93", "size": "3799.11", "side": "SELL", "hash": "f64bd21a1b200d21b7f83aecd3ec43aeba3164a8", "best_bid": "0.31", "best_ask": "0.33"}], "timestamp": "1769384514815", "event_type": "price_change"}}
{"_local_timestamp": "2026-01-25T23:41:54.932837+00:00", "data": {"market": "0xa9c0c820fd79b4339ed4711288ce15236196a6015234350f42b37341e9094398", "price_changes": [{"asset_id": "78438315737001038193507108078052969359305687599144926740526502005681502958823", "price": "0.14", "size": "50", "side": "BUY", "hash": "700c353db69f1f0e585fb7ab2be4dc33f604d6c7", "best_bid": "0.67", "best_ask": "0.69"}, {"asset_id": "91609514063242777856043730063938310894548353925882406409927495687846407164056", "price": "0.86", "size": "50", "side": "SELL", "hash": "f64bd21a1b200d21b7f83aecd3ec43aeba3164a8", "best_bid": "0.31", "best_ask": "0.33"}], "timestamp": "1769384514815", "event_type": "price_change"}}
{"_local_timestamp": "2026-01-25T23:41:54.934039+00:00", "data": {"market": "0xa9c0c820fd79b4339ed4711288ce15236196a6015234350f42b37341e9094398", "price_changes": [{"asset_id": "78438315737001038193507108078052969359305687599144926740526502005681502958823", "price": "0.15", "size": "200", "side": "BUY", "hash": "a93cdaa66192a54d2bf16571c95de356c2f4369b", "best_bid": "0.67", "best_ask": "0.69"}, {"asset_id": "91609514063242777856043730063938310894548353925882406409927495687846407164056", "price": "0.85", "size": "200", "side": "SELL", "hash": "f7f4c9aab896919231aa34e3d26273bd2e27b2cc", "best_bid": "0.31", "best_ask": "0.33"}], "timestamp": "1769384514854", "event_type": "price_change"}}
{"_local_timestamp": "2026-01-25T23:41:55.148864+00:00", "data": {"market": "0xa9c0c820fd79b4339ed4711288ce15236196a6015234350f42b37341e9094398", "price_changes": [{"asset_id": "78438315737001038193507108078052969359305687599144926740526502005681502958823", "price": "0.11", "size": "200", "side": "BUY", "hash": "3f736b7b5415a92e0e39874ac5c6379cd53bb8fc", "best_bid": "0.67", "best_ask": "0.69"}, {"asset_id": "91609514063242777856043730063938310894548353925882406409927495687846407164056", "price": "0.89", "size": "200", "side": "SELL", "hash": "07cd819030f6fbf9f049b098dbaa8afa4ee44bb5", "best_bid": "0.31", "best_ask": "0.33"}], "timestamp": "1769384515085", "event_type": "price_change"}}
{"_local_timestamp": "2026-01-25T23:41:55.150630+00:00", "data": {"market": "0xa9c0c820fd79b4339ed4711288ce15236196a6015234350f42b37341e9094398", "price_changes": [{"asset_id": "78438315737001038193507108078052969359305687599144926740526502005681502958823", "price": "0.09", "size": "450", "side": "BUY", "hash": "8b4c2e69d230d1e982560da0c2063b7aed96ecc2", "best_bid": "0.67", "best_ask": "0.69"}, {"asset_id": "91609514063242777856043730063938310894548353925882406409927495687846407164056", "price": "0.91", "size": "450", "side": "SELL", "hash": "de451b9284fd014914f055b535d45f9a38054c52", "best_bid": "0.31", "best_ask": "0.33"}], "timestamp": "1769384515086", "event_type": "price_change"}}
{"_local_timestamp": "2026-01-25T23:41:56.918544+00:00", "data": {"market": "0xa9c0c820fd79b4339ed4711288ce15236196a6015234350f42b37341e9094398", "price_changes": [{"asset_id": "78438315737001038193507108078052969359305687599144926740526502005681502958823", "price": "0.15", "size": "0", "side": "BUY", "hash": "c2f50c9040b54e8b036db2db44c952f1215c03fb", "best_bid": "0.67", "best_ask": "0.69"}, {"asset_id": "91609514063242777856043730063938310894548353925882406409927495687846407164056", "price": "0.85", "size": "0", "side": "SELL", "hash": "c4cd89038d20d7bd05764a4e2395f305b25980e9", "best_bid": "0.31", "best_ask": "0.33"}], "timestamp": "1769384516852", "event_type": "price_change"}}
{"_local_timestamp": "2026-01-25T23:41:56.919383+00:00", "data": {"market": "0xa9c0c820fd79b4339ed4711288ce15236196a6015234350f42b37341e9094398", "price_changes": [{"asset_id": "78438315737001038193507108078052969359305687599144926740526502005681502958823", "price": "0.14", "size": "250", "side": "BUY", "hash": "a0308cd4517c11dc2c8029373265e6017fffa253", "best_bid": "0.67", "best_ask": "0.69"}, {"asset_id": "91609514063242777856043730063938310894548353925882406409927495687846407164056", "price": "0.86", "size": "250", "side": "SELL", "hash": "f1b6e956a5df386639ae4597518cbf03f59512e5", "best_bid": "0.31", "best_ask": "0.33"}], "timestamp": "1769384516853", "event_type": "price_change"}}
{"_local_timestamp": "2026-01-25T23:41:59.462478+00:00", "data": {"market": "0xa9c0c820fd79b4339ed4711288ce15236196a6015234350f42b37341e9094398", "price_changes": [{"asset_id": "91609514063242777856043730063938310894548353925882406409927495687846407164056", "price": "0.01", "size": "14275.55", "side": "BUY", "hash": "2fe8b435cb9d16d6fdc38c17a27badd942448bdb", "best_bid": "0.31", "best_ask": "0.33"}, {"asset_id": "78438315737001038193507108078052969359305687599144926740526502005681502958823", "price": "0.99", "size": "14275.55", "side": "SELL", "hash": "16da5c77d1ec1b3f37bb97aa5a7c02cc84599e9e", "best_bid": "0.67", "best_ask": "0.69"}], "timestamp": "1769384519386", "event_type": "price_change"}}
{"_local_timestamp": "2026-01-25T23:42:06.792758+00:00", "data": {"market": "0xa9c0c820fd79b4339ed4711288ce15236196a6015234350f42b37341e9094398", "price_changes": [{"asset_id": "78438315737001038193507108078052969359305687599144926740526502005681502958823", "price": "0.11", "size": "0", "side": "BUY", "hash": "06be70d9759d0288b197fba970e46d1941728e32", "best_bid": "0.67", "best_ask": "0.69"}, {"asset_id": "91609514063242777856043730063938310894548353925882406409927495687846407164056", "price": "0.89", "size": "0", "side": "SELL", "hash": "faccfd91eb8ed21cfcc9d721d8ac6a534cd1302a", "best_bid": "0.31", "best_ask": "0.33"}], "timestamp": "1769384526728", "event_type": "price_change"}}
{"_local_timestamp": "2026-01-25T23:42:06.793931+00:00", "data": {"market": "0xa9c0c820fd79b4339ed4711288ce15236196a6015234350f42b37341e9094398", "price_changes": [{"asset_id": "78438315737001038193507108078052969359305687599144926740526502005681502958823", "price": "0.09", "size": "250", "side": "BUY", "hash": "06be70d9759d0288b197fba970e46d1941728e32", "best_bid": "0.67", "best_ask": "0.69"}, {"asset_id": "91609514063242777856043730063938310894548353925882406409927495687846407164056", "price": "0.91", "size": "250", "side": "SELL", "hash": "faccfd91eb8ed21cfcc9d721d8ac6a534cd1302a", "best_bid": "0.31", "best_ask": "0.33"}], "timestamp": "1769384526728", "event_type": "price_change"}}
{"_local_timestamp": "2026-01-25T23:42:06.876864+00:00", "data": {"market": "0xa9c0c820fd79b4339ed4711288ce15236196a6015234350f42b37341e9094398", "price_changes": [{"asset_id": "91609514063242777856043730063938310894548353925882406409927495687846407164056", "price": "0.02", "size": "256.21", "side": "BUY", "hash": "5cbae5d9af6e8ed22b99656d9ca02bd0eacf421f", "best_bid": "0.31", "best_ask": "0.33"}, {"asset_id": "78438315737001038193507108078052969359305687599144926740526502005681502958823", "price": "0.98", "size": "256.21", "side": "SELL", "hash": "22bf1089f7559eb1bf118892818227eb0cd980a3", "best_bid": "0.67", "best_ask": "0.69"}], "timestamp": "1769384526806", "event_type": "price_change"}}
{"_local_timestamp": "2026-01-25T23:42:07.068886+00:00", "data": {"market": "0xa9c0c820fd79b4339ed4711288ce15236196a6015234350f42b37341e9094398", "price_changes": [{"asset_id": "78438315737001038193507108078052969359305687599144926740526502005681502958823", "price": "0.07", "size": "3999.11", "side": "BUY", "hash": "ec8c255cadec32f775193807c23d4cf4c9e18eca", "best_bid": "0.67", "best_ask": "0.69"}, {"asset_id": "91609514063242777856043730063938310894548353925882406409927495687846407164056", "price": "0.93", "size": "3999.11", "side": "SELL", "hash": "b6ce230ee63b897320776abb163461a9aff69417", "best_bid": "0.31", "best_ask": "0.33"}], "timestamp": "1769384526998", "event_type": "price_change"}}
{"_local_timestamp": "2026-01-25T23:42:07.069817+00:00", "data": {"market": "0xa9c0c820fd79b4339ed4711288ce15236196a6015234350f42b37341e9094398", "price_changes": [{"asset_id": "78438315737001038193507108078052969359305687599144926740526502005681502958823", "price": "0.14", "size": "450", "side": "BUY", "hash": "0b3b7347695f84a387ec09edb190b827047ddda6", "best_bid": "0.67", "best_ask": "0.69"}, {"asset_id": "91609514063242777856043730063938310894548353925882406409927495687846407164056", "price": "0.86", "size": "450", "side": "SELL", "hash": "cada5ce630a9f73bf08a74ef53d3f3079b94038f", "best_bid": "0.31", "best_ask": "0.33"}], "timestamp": "1769384526998", "event_type": "price_change"}}
{"_local_timestamp": "2026-01-25T23:42:07.102121+00:00", "data": {"market": "0xa9c0c820fd79b4339ed4711288ce15236196a6015234350f42b37341e9094398", "price_changes": [{"asset_id": "78438315737001038193507108078052969359305687599144926740526502005681502958823", "price": "0.14", "size": "250", "side": "BUY", "hash": "9f6c2cbc613d34b7a76fcc6913602ea367de1406", "best_bid": "0.67", "best_ask": "0.69"}, {"asset_id": "91609514063242777856043730063938310894548353925882406409927495687846407164056", "price": "0.86", "size": "250", "side": "SELL", "hash": "22af44fcdda29359ad4f32ba3bec26d10d85d7ec", "best_bid": "0.31", "best_ask": "0.33"}], "timestamp": "1769384527039", "event_type": "price_change"}}
{"_local_timestamp": "2026-01-25T23:42:07.102986+00:00", "data": {"market": "0xa9c0c820fd79b4339ed4711288ce15236196a6015234350f42b37341e9094398", "price_changes": [{"asset_id": "78438315737001038193507108078052969359305687599144926740526502005681502958823", "price": "0.15", "size": "200", "side": "BUY", "hash": "ca21f955d73c1b9837f11f3318a867451b19d75e", "best_bid": "0.67", "best_ask": "0.69"}, {"asset_id": "91609514063242777856043730063938310894548353925882406409927495687846407164056", "price": "0.85", "size": "200", "side": "SELL", "hash": "e507e4eae8bb51a69e3426f7973b643f479e0d15", "best_bid": "0.31", "best_ask": "0.33"}], "timestamp": "1769384527040", "event_type": "price_change"}}
{"_local_timestamp": "2026-01-25T23:42:18.036458+00:00", "data": {"market": "0xa9c0c820fd79b4339ed4711288ce15236196a6015234350f42b37341e9094398", "price_changes": [{"asset_id": "91609514063242777856043730063938310894548353925882406409927495687846407164056", "price": "0.34", "size": "0", "side": "SELL", "hash": "e6def08585908a062e4db2976bbce6a3a3979d71", "best_bid": "0.31", "best_ask": "0.33"}, {"asset_id": "78438315737001038193507108078052969359305687599144926740526502005681502958823", "price": "0.66", "size": "0", "side": "BUY", "hash": "8416e5ff25ef15d8a8911bb5b8b30c1872a7460a", "best_bid": "0.67", "best_ask": "0.69"}], "timestamp": "1769384537944", "event_type": "price_change"}}
{"_local_timestamp": "2026-01-25T23:42:18.233464+00:00", "data": {"market": "0xa9c0c820fd79b4339ed4711288ce15236196a6015234350f42b37341e9094398", "price_changes": [{"asset_id": "78438315737001038193507108078052969359305687599144926740526502005681502958823", "price": "0.14", "size": "50", "side": "BUY", "hash": "1e8dad39a8f87d4dc9ab2c977bdf61ac39e0d0c9", "best_bid": "0.67", "best_ask": "0.69"}, {"asset_id": "91609514063242777856043730063938310894548353925882406409927495687846407164056", "price": "0.86", "size": "50", "side": "SELL", "hash": "6351dad2cff83165d5ec5de2bd54d974ad7cd8eb", "best_bid": "0.31", "best_ask": "0.33"}], "timestamp": "1769384538155", "event_type": "price_change"}}
{"_local_timestamp": "2026-01-25T23:42:18.276075+00:00", "data": {"market": "0xa9c0c820fd79b4339ed4711288ce15236196a6015234350f42b37341e9094398", "price_changes": [{"asset_id": "78438315737001038193507108078052969359305687599144926740526502005681502958823", "price": "0.15", "size": "0", "side": "BUY", "hash": "aed61d380f3d208a3bd33ebdf0e0fd09ac531f68", "best_bid": "0.67", "best_ask": "0.69"}, {"asset_id": "91609514063242777856043730063938310894548353925882406409927495687846407164056", "price": "0.85", "size": "0", "side": "SELL", "hash": "8a3a4b89bf9f6abed3e21dba01a0d3b59551f7e9", "best_bid": "0.31", "best_ask": "0.33"}], "timestamp": "1769384538200", "event_type": "price_change"}}
{"_local_timestamp": "2026-01-25T23:42:18.283878+00:00", "data": {"market": "0xa9c0c820fd79b4339ed4711288ce15236196a6015234350f42b37341e9094398", "price_changes": [{"asset_id": "78438315737001038193507108078052969359305687599144926740526502005681502958823", "price": "0.14", "size": "250", "side": "BUY", "hash": "a9566aa70f3c8c7d5f21a32d18729a1788912561", "best_bid": "0.67", "best_ask": "0.69"}, {"asset_id": "91609514063242777856043730063938310894548353925882406409927495687846407164056", "price": "0.86", "size": "250", "side": "SELL", "hash": "d7756ed8769d2716a5b4e30b2d327e836c2a1cf9", "best_bid": "0.31", "best_ask": "0.33"}], "timestamp": "1769384538203", "event_type": "price_change"}}
{"_local_timestamp": "2026-01-25T23:42:18.508240+00:00", "data": {"market": "0xa9c0c820fd79b4339ed4711288ce15236196a6015234350f42b37341e9094398", "price_changes": [{"asset_id": "78438315737001038193507108078052969359305687599144926740526502005681502958823", "price": "0.15", "size": "200", "side": "BUY", "hash": "a519f33084d5eefb92f507d1e21cadfe27e669b1", "best_bid": "0.67", "best_ask": "0.69"}, {"asset_id": "91609514063242777856043730063938310894548353925882406409927495687846407164056", "price": "0.85", "size": "200", "side": "SELL", "hash": "2eb140e46a0c6cd9869fb0546836e964a80c1f70", "best_bid": "0.31", "best_ask": "0.33"}], "timestamp": "1769384538424", "event_type": "price_change"}}
{"_local_timestamp": "2026-01-25T23:42:18.860010+00:00", "data": {"market": "0xa9c0c820fd79b4339ed4711288ce15236196a6015234350f42b37341e9094398", "price_changes": [{"asset_id": "91609514063242777856043730063938310894548353925882406409927495687846407164056", "price": "0.34", "size": "6.8", "side": "SELL", "hash": "2363490ec51411cf38e4f33827e6b123fa747e6a", "best_bid": "0.31", "best_ask": "0.33"}, {"asset_id": "78438315737001038193507108078052969359305687599144926740526502005681502958823", "price": "0.66", "size": "6.8", "side": "BUY", "hash": "54a4b7dbf5840cd41952df87209adf7f95909c97", "best_bid": "0.67", "best_ask": "0.69"}], "timestamp": "1769384538775", "event_type": "price_change"}}
{"_local_timestamp": "2026-01-25T23:42:20.290125+00:00", "data": {"market": "0xa9c0c820fd79b4339ed4711288ce15236196a6015234350f42b37341e9094398", "price_changes": [{"asset_id": "78438315737001038193507108078052969359305687599144926740526502005681502958823", "price": "0.14", "size": "50", "side": "BUY", "hash": "adf4ef4e75d46506009803a6d9fdce9e5353ab0e", "best_bid": "0.67", "best_ask": "0.69"}, {"asset_id": "91609514063242777856043730063938310894548353925882406409927495687846407164056", "price": "0.86", "size": "50", "side": "SELL", "hash": "b1253536551309d1f32cfa04aa1ecc8484b568a7", "best_bid": "0.31", "best_ask": "0.33"}], "timestamp": "1769384540203", "event_type": "price_change"}}
{"_local_timestamp": "2026-01-25T23:42:20.291118+00:00", "data": {"market": "0xa9c0c820fd79b4339ed4711288ce15236196a6015234350f42b37341e9094398", "price_changes": [{"asset_id": "78438315737001038193507108078052969359305687599144926740526502005681502958823", "price": "0.16", "size": "200", "side": "BUY", "hash": "0f62b07c8105244689e41c3291e4581e93ff904a", "best_bid": "0.67", "best_ask": "0.69"}, {"asset_id": "91609514063242777856043730063938310894548353925882406409927495687846407164056", "price": "0.84", "size": "200", "side": "SELL", "hash": "dd5c15cd7d49d15a78d6d5f47ac7a17caba42a5c", "best_bid": "0.31", "best_ask": "0.33"}], "timestamp": "1769384540204", "event_type": "price_change"}}
{"_local_timestamp": "2026-01-25T23:42:23.179460+00:00", "data": {"market": "0xa9c0c820fd79b4339ed4711288ce15236196a6015234350f42b37341e9094398", "price_changes": [{"asset_id": "91609514063242777856043730063938310894548353925882406409927495687846407164056", "price": "0.02", "size": "156.21", "side": "BUY", "hash": "6910f0ee15d11d173d461053c2ae0b7ad9040923", "best_bid": "0.31", "best_ask": "0.33"}, {"asset_id": "78438315737001038193507108078052969359305687599144926740526502005681502958823", "price": "0.98", "size": "156.21", "side": "SELL", "hash": "160ae54681fdecca269efbf13669d81863942eee", "best_bid": "0.67", "best_ask": "0.69"}], "timestamp": "1769384543026", "event_type": "price_change"}}
{"_local_timestamp": "2026-01-25T23:42:23.492657+00:00", "data": {"market": "0xa9c0c820fd79b4339ed4711288ce15236196a6015234350f42b37341e9094398", "price_changes": [{"asset_id": "91609514063242777856043730063938310894548353925882406409927495687846407164056", "price": "0.01", "size": "14375.55", "side": "BUY", "hash": "9204af8599c69fb24a54815e36f505880edac74d", "best_bid": "0.31", "best_ask": "0.33"}, {"asset_id": "78438315737001038193507108078052969359305687599144926740526502005681502958823", "price": "0.99", "size": "14375.55", "side": "SELL", "hash": "c4c74588f43eb75fa9161d2649a173d7ad5f023f", "best_bid": "0.67", "best_ask": "0.69"}], "timestamp": "1769384543388", "event_type": "price_change"}}
{"_local_timestamp": "2026-01-25T23:42:29.074173+00:00", "data": {"market": "0xa9c0c820fd79b4339ed4711288ce15236196a6015234350f42b37341e9094398", "price_changes": [{"asset_id": "78438315737001038193507108078052969359305687599144926740526502005681502958823", "price": "0.15", "size": "0", "side": "BUY", "hash": "71aee9a46b1b0a0ef0247ae53d3f486a9f1b9f3a", "best_bid": "0.67", "best_ask": "0.69"}, {"asset_id": "91609514063242777856043730063938310894548353925882406409927495687846407164056", "price": "0.85", "size": "0", "side": "SELL", "hash": "9697dd6e80f971cc8817f4fbe440a23558079ed9", "best_bid": "0.31", "best_ask": "0.33"}], "timestamp": "1769384548960", "event_type": "price_change"}}
{"_local_timestamp": "2026-01-25T23:42:29.114770+00:00", "data": {"market": "0xa9c0c820fd79b4339ed4711288ce15236196a6015234350f42b37341e9094398", "price_changes": [{"asset_id": "78438315737001038193507108078052969359305687599144926740526502005681502958823", "price": "0.16", "size": "0", "side": "BUY", "hash": "0c1ff45d66d4049a1278bf2a1b873598bb8786e5", "best_bid": "0.67", "best_ask": "0.69"}, {"asset_id": "91609514063242777856043730063938310894548353925882406409927495687846407164056", "price": "0.84", "size": "0", "side": "SELL", "hash": "2b57365099f8e440bac8b6d8901a81331528384a", "best_bid": "0.31", "best_ask": "0.33"}], "timestamp": "1769384549002", "event_type": "price_change"}}
{"_local_timestamp": "2026-01-25T23:42:29.122922+00:00", "data": {"market": "0xa9c0c820fd79b4339ed4711288ce15236196a6015234350f42b37341e9094398", "price_changes": [{"asset_id": "78438315737001038193507108078052969359305687599144926740526502005681502958823", "price": "0.14", "size": "250", "side": "BUY", "hash": "86cc972ebd99bc0361376a899b2faf77a3137778", "best_bid": "0.67", "best_ask": "0.69"}, {"asset_id": "91609514063242777856043730063938310894548353925882406409927495687846407164056", "price": "0.86", "size": "250", "side": "SELL", "hash": "4cc54ea6d7bcc21c404223b39a8697df3830605e", "best_bid": "0.31", "best_ask": "0.33"}], "timestamp": "1769384549016", "event_type": "price_change"}}
{"_local_timestamp": "2026-01-25T23:42:29.328750+00:00", "data": {"market": "0xa9c0c820fd79b4339ed4711288ce15236196a6015234350f42b37341e9094398", "price_changes": [{"asset_id": "78438315737001038193507108078052969359305687599144926740526502005681502958823", "price": "0.11", "size": "200", "side": "BUY", "hash": "9148c573bd0950409d2742a14f8a2c448f11e729", "best_bid": "0.67", "best_ask": "0.69"}, {"asset_id": "91609514063242777856043730063938310894548353925882406409927495687846407164056", "price": "0.89", "size": "200", "side": "SELL", "hash": "4c21ce23ce4d4913ce5e055bc76c0c32febad328", "best_bid": "0.31", "best_ask": "0.33"}], "timestamp": "1769384549228", "event_type": "price_change"}}
{"_local_timestamp": "2026-01-25T23:42:40.016981+00:00", "data": {"market": "0xa9c0c820fd79b4339ed4711288ce15236196a6015234350f42b37341e9094398", "price_changes": [{"asset_id": "78438315737001038193507108078052969359305687599144926740526502005681502958823", "price": "0.11", "size": "0", "side": "BUY", "hash": "3feef48b07d35347d62a2556ccf9e45ef240cab6", "best_bid": "0.67", "best_ask": "0.69"}, {"asset_id": "91609514063242777856043730063938310894548353925882406409927495687846407164056", "price": "0.89", "size": "0", "side": "SELL", "hash": "982de01a8624dfde4167f94252f0d11c040c7a5e", "best_bid": "0.31", "best_ask": "0.33"}], "timestamp": "1769384559910", "event_type": "price_change"}}
{"_local_timestamp": "2026-01-25T23:42:40.282175+00:00", "data": {"market": "0xa9c0c820fd79b4339ed4711288ce15236196a6015234350f42b37341e9094398", "price_changes": [{"asset_id": "78438315737001038193507108078052969359305687599144926740526502005681502958823", "price": "0.14", "size": "450", "side": "BUY", "hash": "11c8a77144033d669647704b92d93ed4faf00cfb", "best_bid": "0.67", "best_ask": "0.69"}, {"asset_id": "91609514063242777856043730063938310894548353925882406409927495687846407164056", "price": "0.86", "size": "450", "side": "SELL", "hash": "9c3f84a8bbb02f53c2df446ce47ab986aa46390d", "best_bid": "0.31", "best_ask": "0.33"}], "timestamp": "1769384560162", "event_type": "price_change"}}
{"_local_timestamp": "2026-01-25T23:42:40.322708+00:00", "data": {"market": "0xa9c0c820fd79b4339ed4711288ce15236196a6015234350f42b37341e9094398", "price_changes": [{"asset_id": "78438315737001038193507108078052969359305687599144926740526502005681502958823", "price": "0.14", "size": "250", "side": "BUY", "hash": "6c7d42c0c1bc0ba37bb8bb6c9ca69101d4d6573f", "best_bid": "0.67", "best_ask": "0.69"}, {"asset_id": "91609514063242777856043730063938310894548353925882406409927495687846407164056", "price": "0.86", "size": "250", "side": "SELL", "hash": "bfcb939d929a9d5722de32a8fd1232fecda83a0c", "best_bid": "0.31", "best_ask": "0.33"}], "timestamp": "1769384560218", "event_type": "price_change"}}
{"_local_timestamp": "2026-01-25T23:42:40.328805+00:00", "data": {"market": "0xa9c0c820fd79b4339ed4711288ce15236196a6015234350f42b37341e9094398", "price_changes": [{"asset_id": "78438315737001038193507108078052969359305687599144926740526502005681502958823", "price": "0.15", "size": "200", "side": "BUY", "hash": "df73ea33d8e112957b0e2060262d8658abccc2b0", "best_bid": "0.67", "best_ask": "0.69"}, {"asset_id": "91609514063242777856043730063938310894548353925882406409927495687846407164056", "price": "0.85", "size": "200", "side": "SELL", "hash": "e2ecf53f9d66fe0e9e57642a9361788b7b7935ca", "best_bid": "0.31", "best_ask": "0.33"}], "timestamp": "1769384560223", "event_type": "price_change"}}
{"_local_timestamp": "2026-01-25T23:42:51.230070+00:00", "data": {"market": "0xa9c0c820fd79b4339ed4711288ce15236196a6015234350f42b37341e9094398", "price_changes": [{"asset_id": "78438315737001038193507108078052969359305687599144926740526502005681502958823", "price": "0.14", "size": "50", "side": "BUY", "hash": "d215a4aaa448665b2aca3f4e2df65bc5f07260f4", "best_bid": "0.67", "best_ask": "0.69"}, {"asset_id": "91609514063242777856043730063938310894548353925882406409927495687846407164056", "price": "0.86", "size": "50", "side": "SELL", "hash": "084f0b6b4a833563a91216e115056dd98073ddd1", "best_bid": "0.31", "best_ask": "0.33"}], "timestamp": "1769384571134", "event_type": "price_change"}}
{"_local_timestamp": "2026-01-25T23:42:51.271279+00:00", "data": {"market": "0xa9c0c820fd79b4339ed4711288ce15236196a6015234350f42b37341e9094398", "price_changes": [{"asset_id": "78438315737001038193507108078052969359305687599144926740526502005681502958823", "price": "0.15", "size": "0", "side": "BUY", "hash": "020d7f524a3bf04edf011ada27f59d6ea75539eb", "best_bid": "0.67", "best_ask": "0.69"}, {"asset_id": "91609514063242777856043730063938310894548353925882406409927495687846407164056", "price": "0.85", "size": "0", "side": "SELL", "hash": "f02ff929956ef1eb0aec1283e71f6deb8650fe8d", "best_bid": "0.31", "best_ask": "0.33"}], "timestamp": "1769384571173", "event_type": "price_change"}}
{"_local_timestamp": "2026-01-25T23:42:51.310087+00:00", "data": {"market": "0xa9c0c820fd79b4339ed4711288ce15236196a6015234350f42b37341e9094398", "price_changes": [{"asset_id": "78438315737001038193507108078052969359305687599144926740526502005681502958823", "price": "0.14", "size": "250", "side": "BUY", "hash": "b915db85ef6d14f632cc2479acd6b40527232836", "best_bid": "0.67", "best_ask": "0.69"}, {"asset_id": "91609514063242777856043730063938310894548353925882406409927495687846407164056", "price": "0.86", "size": "250", "side": "SELL", "hash": "2fe8daacae232c7ef02d3fcd24bd6b1946b115dc", "best_bid": "0.31", "best_ask": "0.33"}], "timestamp": "1769384571174", "event_type": "price_change"}}
{"_local_timestamp": "2026-01-25T23:42:51.545418+00:00", "data": {"market": "0xa9c0c820fd79b4339ed4711288ce15236196a6015234350f42b37341e9094398", "price_changes": [{"asset_id": "78438315737001038193507108078052969359305687599144926740526502005681502958823", "price": "0.15", "size": "200", "side": "BUY", "hash": "a6f7ec7d89695d12978a1953fee36a11441e5348", "best_bid": "0.67", "best_ask": "0.69"}, {"asset_id": "91609514063242777856043730063938310894548353925882406409927495687846407164056", "price": "0.85", "size": "200", "side": "SELL", "hash": "dd533833e31e0b343d4ca3c32b90991552215083", "best_bid": "0.31", "best_ask": "0.33"}], "timestamp": "1769384571437", "event_type": "price_change"}}
{"_local_timestamp": "2026-01-25T23:42:53.283693+00:00", "data": {"market": "0xa9c0c820fd79b4339ed4711288ce15236196a6015234350f42b37341e9094398", "price_changes": [{"asset_id": "78438315737001038193507108078052969359305687599144926740526502005681502958823", "price": "0.16", "size": "200", "side": "BUY", "hash": "2284e0dd4e3e0205c5c48be5d7e928f6badfe341", "best_bid": "0.67", "best_ask": "0.69"}, {"asset_id": "91609514063242777856043730063938310894548353925882406409927495687846407164056", "price": "0.84", "size": "200", "side": "SELL", "hash": "e6ec34e4cd3b4d5a4aca624e21655119ad92894e", "best_bid": "0.31", "best_ask": "0.33"}], "timestamp": "1769384573173", "event_type": "price_change"}}
{"_local_timestamp": "2026-01-25T23:42:53.300838+00:00", "data": {"market": "0xa9c0c820fd79b4339ed4711288ce15236196a6015234350f42b37341e9094398", "price_changes": [{"asset_id": "78438315737001038193507108078052969359305687599144926740526502005681502958823", "price": "0.14", "size": "50", "side": "BUY", "hash": "dec3edb08c5449dfa642493d9c198d6f9a800c71", "best_bid": "0.67", "best_ask": "0.69"}, {"asset_id": "91609514063242777856043730063938310894548353925882406409927495687846407164056", "price": "0.86", "size": "50", "side": "SELL", "hash": "4d8fd11d38249c32202b9ac81763149741462ebc", "best_bid": "0.31", "best_ask": "0.33"}], "timestamp": "1769384573183", "event_type": "price_change"}}
{"_local_timestamp": "2026-01-25T23:43:02.761828+00:00", "data": {"market": "0xa9c0c820fd79b4339ed4711288ce15236196a6015234350f42b37341e9094398", "price_changes": [{"asset_id": "78438315737001038193507108078052969359305687599144926740526502005681502958823", "price": "0.15", "size": "0", "side": "BUY", "hash": "3c0ab5f0b855eb696199d6b4704bb1b433ac4de7", "best_bid": "0.67", "best_ask": "0.69"}, {"asset_id": "91609514063242777856043730063938310894548353925882406409927495687846407164056", "price": "0.85", "size": "0", "side": "SELL", "hash": "23b9549702d7cc29bfa324bb7018f2ca8f5b98dc", "best_bid": "0.31", "best_ask": "0.33"}], "timestamp": "1769384582655", "event_type": "price_change"}}
{"_local_timestamp": "2026-01-25T23:43:02.827917+00:00", "data": {"market": "0xa9c0c820fd79b4339ed4711288ce15236196a6015234350f42b37341e9094398", "price_changes": [{"asset_id": "78438315737001038193507108078052969359305687599144926740526502005681502958823", "price": "0.14", "size": "250", "side": "BUY", "hash": "64c20b2de3638b1106532bb5aebc46101d3634f2", "best_bid": "0.67", "best_ask": "0.69"}, {"asset_id": "91609514063242777856043730063938310894548353925882406409927495687846407164056", "price": "0.86", "size": "250", "side": "SELL", "hash": "8c2f48e0b6bce4ff9209259a82bd0b6f473b838f", "best_bid": "0.31", "best_ask": "0.33"}], "timestamp": "1769384582718", "event_type": "price_change"}}
{"_local_timestamp": "2026-01-25T23:43:02.828958+00:00", "data": {"market": "0xa9c0c820fd79b4339ed4711288ce15236196a6015234350f42b37341e9094398", "price_changes": [{"asset_id": "78438315737001038193507108078052969359305687599144926740526502005681502958823", "price": "0.16", "size": "0", "side": "BUY", "hash": "7a4b2b133824b2f86dda83db9990a5f68f3069b6", "best_bid": "0.67", "best_ask": "0.69"}, {"asset_id": "91609514063242777856043730063938310894548353925882406409927495687846407164056", "price": "0.84", "size": "0", "side": "SELL", "hash": "cf2805baa937e19a179291d7355f8d28c52f78e8", "best_bid": "0.31", "best_ask": "0.33"}], "timestamp": "1769384582719", "event_type": "price_change"}}
{"_local_timestamp": "2026-01-25T23:43:03.341943+00:00", "data": {"market": "0xa9c0c820fd79b4339ed4711288ce15236196a6015234350f42b37341e9094398", "price_changes": [{"asset_id": "78438315737001038193507108078052969359305687599144926740526502005681502958823", "price": "0.11", "size": "200", "side": "BUY", "hash": "19593971c5ceaad7366943b5009b5b4c930fdd17", "best_bid": "0.67", "best_ask": "0.69"}, {"asset_id": "91609514063242777856043730063938310894548353925882406409927495687846407164056", "price": "0.89", "size": "200", "side": "SELL", "hash": "ec4ff5b771514114e21196b2adf774fd024cb347", "best_bid": "0.31", "best_ask": "0.33"}], "timestamp": "1769384583248", "event_type": "price_change"}}
{"_local_timestamp": "2026-01-25T23:43:13.681123+00:00", "data": {"market": "0xa9c0c820fd79b4339ed4711288ce15236196a6015234350f42b37341e9094398", "price_changes": [{"asset_id": "78438315737001038193507108078052969359305687599144926740526502005681502958823", "price": "0.11", "size": "0", "side": "BUY", "hash": "112dadbdff9dd7f19c71476e9473c4104827d64c", "best_bid": "0.67", "best_ask": "0.69"}, {"asset_id": "91609514063242777856043730063938310894548353925882406409927495687846407164056", "price": "0.89", "size": "0", "side": "SELL", "hash": "706a2473b17e834ecbb2fa0cce4938511cae6ca3", "best_bid": "0.31", "best_ask": "0.33"}], "timestamp": "1769384593556", "event_type": "price_change"}}
{"_local_timestamp": "2026-01-25T23:43:13.936793+00:00", "data": {"market": "0xa9c0c820fd79b4339ed4711288ce15236196a6015234350f42b37341e9094398", "price_changes": [{"asset_id": "78438315737001038193507108078052969359305687599144926740526502005681502958823", "price": "0.14", "size": "450", "side": "BUY", "hash": "da4b3634c223b004478c5043cd7d1b8e4c7bfe7f", "best_bid": "0.67", "best_ask": "0.69"}, {"asset_id": "91609514063242777856043730063938310894548353925882406409927495687846407164056", "price": "0.86", "size": "450", "side": "SELL", "hash": "c389cc0a5ad4ddc8265e18bda3f368e3c367d554", "best_bid": "0.31", "best_ask": "0.33"}], "timestamp": "1769384593814", "event_type": "price_change"}}
{"_local_timestamp": "2026-01-25T23:43:13.991966+00:00", "data": {"market": "0xa9c0c820fd79b4339ed4711288ce15236196a6015234350f42b37341e9094398", "price_changes": [{"asset_id": "78438315737001038193507108078052969359305687599144926740526502005681502958823", "price": "0.15", "size": "200", "side": "BUY", "hash": "333b02da8db146c2d19c875eafa17d651d42dddd", "best_bid": "0.67", "best_ask": "0.69"}, {"asset_id": "91609514063242777856043730063938310894548353925882406409927495687846407164056", "price": "0.85", "size": "200", "side": "SELL", "hash": "8720401dc56fc10e9e17c0217ec4e7ab0702b4ea", "best_bid": "0.31", "best_ask": "0.33"}], "timestamp": "1769384593851", "event_type": "price_change"}}
{"_local_timestamp": "2026-01-25T23:43:13.993010+00:00", "data": {"market": "0xa9c0c820fd79b4339ed4711288ce15236196a6015234350f42b37341e9094398", "price_changes": [{"asset_id": "78438315737001038193507108078052969359305687599144926740526502005681502958823", "price": "0.14", "size": "250", "side": "BUY", "hash": "d527a236cf9f0f2fe59bd01c8bdae81da7db2c42", "best_bid": "0.67", "best_ask": "0.69"}, {"asset_id": "91609514063242777856043730063938310894548353925882406409927495687846407164056", "price": "0.86", "size": "250", "side": "SELL", "hash": "0942679e8fc79bfb7951b0b9f4e097bfb19df80b", "best_bid": "0.31", "best_ask": "0.33"}], "timestamp": "1769384593851", "event_type": "price_change"}}
{"_local_timestamp": "2026-01-25T23:43:24.763883+00:00", "data": {"market": "0xa9c0c820fd79b4339ed4711288ce15236196a6015234350f42b37341e9094398", "price_changes": [{"asset_id": "78438315737001038193507108078052969359305687599144926740526502005681502958823", "price": "0.14", "size": "50", "side": "BUY", "hash": "2cda8a712bf6e3b3571e0cf6ae1e330cc320d3fb", "best_bid": "0.67", "best_ask": "0.69"}, {"asset_id": "91609514063242777856043730063938310894548353925882406409927495687846407164056", "price": "0.86", "size": "50", "side": "SELL", "hash": "ed6076f851037c6fa9db717ec0acae18fab1f916", "best_bid": "0.31", "best_ask": "0.33"}], "timestamp": "1769384604629", "event_type": "price_change"}}
{"_local_timestamp": "2026-01-25T23:43:24.795348+00:00", "data": {"market": "0xa9c0c820fd79b4339ed4711288ce15236196a6015234350f42b37341e9094398", "price_changes": [{"asset_id": "78438315737001038193507108078052969359305687599144926740526502005681502958823", "price": "0.15", "size": "0", "side": "BUY", "hash": "a5540edcd56702c662413907213d93c48e566a20", "best_bid": "0.67", "best_ask": "0.69"}, {"asset_id": "91609514063242777856043730063938310894548353925882406409927495687846407164056", "price": "0.85", "size": "0", "side": "SELL", "hash": "95dc9adb36f578dcbd57979a62a41e715f1e60d9", "best_bid": "0.31", "best_ask": "0.33"}], "timestamp": "1769384604669", "event_type": "price_change"}}
{"_local_timestamp": "2026-01-25T23:43:24.799727+00:00", "data": {"market": "0xa9c0c820fd79b4339ed4711288ce15236196a6015234350f42b37341e9094398", "price_changes": [{"asset_id": "78438315737001038193507108078052969359305687599144926740526502005681502958823", "price": "0.14", "size": "250", "side": "BUY", "hash": "59f2a6a7930d75d36e63b72f3ee9c395af0f4c9f", "best_bid": "0.67", "best_ask": "0.69"}, {"asset_id": "91609514063242777856043730063938310894548353925882406409927495687846407164056", "price": "0.86", "size": "250", "side": "SELL", "hash": "c01fdbde8b6b0cf7b4a5103e8e5fb5e7fe3d2a57", "best_bid": "0.31", "best_ask": "0.33"}], "timestamp": "1769384604670", "event_type": "price_change"}}
{"_local_timestamp": "2026-01-25T23:43:25.024407+00:00", "data": {"market": "0xa9c0c820fd79b4339ed4711288ce15236196a6015234350f42b37341e9094398", "price_changes": [{"asset_id": "78438315737001038193507108078052969359305687599144926740526502005681502958823", "price": "0.15", "size": "200", "side": "BUY", "hash": "8a569686d9afec9514bdad79eea14bcb088fec35", "best_bid": "0.67", "best_ask": "0.69"}, {"asset_id": "91609514063242777856043730063938310894548353925882406409927495687846407164056", "price": "0.85", "size": "200", "side": "SELL", "hash": "43319c89bc93edd00949c6370af406d63a06db13", "best_bid": "0.31", "best_ask": "0.33"}], "timestamp": "1769384604891", "event_type": "price_change"}}
{"_local_timestamp": "2026-01-25T23:43:26.801105+00:00", "data": {"market": "0xa9c0c820fd79b4339ed4711288ce15236196a6015234350f42b37341e9094398", "price_changes": [{"asset_id": "78438315737001038193507108078052969359305687599144926740526502005681502958823", "price": "0.14", "size": "50", "side": "BUY", "hash": "da2404a68cff3087900ec28553f79aa0b9b27e68", "best_bid": "0.67", "best_ask": "0.69"}, {"asset_id": "91609514063242777856043730063938310894548353925882406409927495687846407164056", "price": "0.86", "size": "50", "side": "SELL", "hash": "06879c178743d33af7ee0ada40f9742a5b72291d", "best_bid": "0.31", "best_ask": "0.33"}], "timestamp": "1769384606665", "event_type": "price_change"}}
{"_local_timestamp": "2026-01-25T23:43:26.802063+00:00", "data": {"market": "0xa9c0c820fd79b4339ed4711288ce15236196a6015234350f42b37341e9094398", "price_changes": [{"asset_id": "78438315737001038193507108078052969359305687599144926740526502005681502958823", "price": "0.16", "size": "200", "side": "BUY", "hash": "237e0da13cafc8d3f7a8d5710d3ebeb47aff0a89", "best_bid": "0.67", "best_ask": "0.69"}, {"asset_id": "91609514063242777856043730063938310894548353925882406409927495687846407164056", "price": "0.84", "size": "200", "side": "SELL", "hash": "14d07c282e89a47bf08981797b7a92ac3e37e1d9", "best_bid": "0.31", "best_ask": "0.33"}], "timestamp": "1769384606666", "event_type": "price_change"}}
{"_local_timestamp": "2026-01-25T23:43:36.946364+00:00", "data": {"market": "0xa9c0c820fd79b4339ed4711288ce15236196a6015234350f42b37341e9094398", "price_changes": [{"asset_id": "78438315737001038193507108078052969359305687599144926740526502005681502958823", "price": "0.15", "size": "0", "side": "BUY", "hash": "debe3ccdaee9f5de0b2ddd28e4484bfaec589b93", "best_bid": "0.67", "best_ask": "0.69"}, {"asset_id": "91609514063242777856043730063938310894548353925882406409927495687846407164056", "price": "0.85", "size": "0", "side": "SELL", "hash": "6779e2af41841c3ce29f22430d384133cc5fc42a", "best_bid": "0.31", "best_ask": "0.33"}], "timestamp": "1769384616798", "event_type": "price_change"}}
{"_local_timestamp": "2026-01-25T23:43:36.982740+00:00", "data": {"market": "0xa9c0c820fd79b4339ed4711288ce15236196a6015234350f42b37341e9094398", "price_changes": [{"asset_id": "78438315737001038193507108078052969359305687599144926740526502005681502958823", "price": "0.14", "size": "250", "side": "BUY", "hash": "6b5a87eca76f50534226e0ff61fd4e66875b7ff0", "best_bid": "0.67", "best_ask": "0.69"}, {"asset_id": "91609514063242777856043730063938310894548353925882406409927495687846407164056", "price": "0.86", "size": "250", "side": "SELL", "hash": "11f651e787bddc9f2010069eb7aef56047b5f670", "best_bid": "0.31", "best_ask": "0.33"}], "timestamp": "1769384616837", "event_type": "price_change"}}
{"_local_timestamp": "2026-01-25T23:43:36.997684+00:00", "data": {"market": "0xa9c0c820fd79b4339ed4711288ce15236196a6015234350f42b37341e9094398", "price_changes": [{"asset_id": "78438315737001038193507108078052969359305687599144926740526502005681502958823", "price": "0.16", "size": "0", "side": "BUY", "hash": "ddacb85bbf512f87d69be171d11f73e47048439d", "best_bid": "0.67", "best_ask": "0.69"}, {"asset_id": "91609514063242777856043730063938310894548353925882406409927495687846407164056", "price": "0.84", "size": "0", "side": "SELL", "hash": "ceb4c4fa039cef238f888096508c7440e4a6d505", "best_bid": "0.31", "best_ask": "0.33"}], "timestamp": "1769384616853", "event_type": "price_change"}}
{"_local_timestamp": "2026-01-25T23:43:37.185537+00:00", "data": {"market": "0xa9c0c820fd79b4339ed4711288ce15236196a6015234350f42b37341e9094398", "price_changes": [{"asset_id": "78438315737001038193507108078052969359305687599144926740526502005681502958823", "price": "0.11", "size": "200", "side": "BUY", "hash": "800671cea32f030fb868d7bf8eddc19cbc7cf840", "best_bid": "0.67", "best_ask": "0.69"}, {"asset_id": "91609514063242777856043730063938310894548353925882406409927495687846407164056", "price": "0.89", "size": "200", "side": "SELL", "hash": "32255736e47c4ba900838ba1a78779723212a134", "best_bid": "0.31", "best_ask": "0.33"}], "timestamp": "1769384617055", "event_type": "price_change"}}
{"_local_timestamp": "2026-01-25T23:43:48.635132+00:00", "data": {"market": "0xa9c0c820fd79b4339ed4711288ce15236196a6015234350f42b37341e9094398", "price_changes": [{"asset_id": "91609514063242777856043730063938310894548353925882406409927495687846407164056", "price": "0.02", "size": "1156.21", "side": "BUY", "hash": "ec0dd37edcfdabdd0bfcf8f33c5ff05fcf1ab171", "best_bid": "0.31", "best_ask": "0.33"}, {"asset_id": "78438315737001038193507108078052969359305687599144926740526502005681502958823", "price": "0.98", "size": "1156.21", "side": "SELL", "hash": "68d8041c89ba7bc23371b5424f733f8ad59f6da8", "best_bid": "0.67", "best_ask": "0.69"}], "timestamp": "1769384628548", "event_type": "price_change"}}
{"_local_timestamp": "2026-01-25T23:43:49.281322+00:00", "data": {"market": "0xa9c0c820fd79b4339ed4711288ce15236196a6015234350f42b37341e9094398", "price_changes": [{"asset_id": "78438315737001038193507108078052969359305687599144926740526502005681502958823", "price": "0.11", "size": "0", "side": "BUY", "hash": "d9053167990c1c606124ed13cd653e50718327e0", "best_bid": "0.67", "best_ask": "0.69"}, {"asset_id": "91609514063242777856043730063938310894548353925882406409927495687846407164056", "price": "0.89", "size": "0", "side": "SELL", "hash": "f47d26ea97a80501f5de769bcf5af2dd7134938d", "best_bid": "0.31", "best_ask": "0.33"}], "timestamp": "1769384629192", "event_type": "price_change"}}
{"_local_timestamp": "2026-01-25T23:43:49.548423+00:00", "data": {"market": "0xa9c0c820fd79b4339ed4711288ce15236196a6015234350f42b37341e9094398", "price_changes": [{"asset_id": "78438315737001038193507108078052969359305687599144926740526502005681502958823", "price": "0.14", "size": "450", "side": "BUY", "hash": "d655f0aebbe4df1eaba7acf15507cfe3d7d1ba39", "best_bid": "0.67", "best_ask": "0.69"}, {"asset_id": "91609514063242777856043730063938310894548353925882406409927495687846407164056", "price": "0.86", "size": "450", "side": "SELL", "hash": "4f649bd976375f97221bfcaef8665d073fd24539", "best_bid": "0.31", "best_ask": "0.33"}], "timestamp": "1769384629443", "event_type": "price_change"}}
{"_local_timestamp": "2026-01-25T23:43:49.588822+00:00", "data": {"market": "0xa9c0c820fd79b4339ed4711288ce15236196a6015234350f42b37341e9094398", "price_changes": [{"asset_id": "78438315737001038193507108078052969359305687599144926740526502005681502958823", "price": "0.14", "size": "250", "side": "BUY", "hash": "d11456fbd19c574dea27805a6135be17e8bb3a45", "best_bid": "0.67", "best_ask": "0.69"}, {"asset_id": "91609514063242777856043730063938310894548353925882406409927495687846407164056", "price": "0.86", "size": "250", "side": "SELL", "hash": "d4a35ed53ec89392e7cebeaa956fc6cfd94c7b4e", "best_bid": "0.31", "best_ask": "0.33"}], "timestamp": "1769384629481", "event_type": "price_change"}}
{"_local_timestamp": "2026-01-25T23:43:49.592597+00:00", "data": {"market": "0xa9c0c820fd79b4339ed4711288ce15236196a6015234350f42b37341e9094398", "price_changes": [{"asset_id": "78438315737001038193507108078052969359305687599144926740526502005681502958823", "price": "0.15", "size": "200", "side": "BUY", "hash": "71765677aee99015e0595d4ec7a93a9f544a3800", "best_bid": "0.67", "best_ask": "0.69"}, {"asset_id": "91609514063242777856043730063938310894548353925882406409927495687846407164056", "price": "0.85", "size": "200", "side": "SELL", "hash": "9b284f159cdf63fe356baa720a414748ca47dca8", "best_bid": "0.31", "best_ask": "0.33"}], "timestamp": "1769384629485", "event_type": "price_change"}}
{"_local_timestamp": "2026-01-25T23:44:00.762010+00:00", "data": {"market": "0xa9c0c820fd79b4339ed4711288ce15236196a6015234350f42b37341e9094398", "price_changes": [{"asset_id": "78438315737001038193507108078052969359305687599144926740526502005681502958823", "price": "0.14", "size": "50", "side": "BUY", "hash": "da2c85c9b1245528fcd5828929c94b12199ababb", "best_bid": "0.67", "best_ask": "0.69"}, {"asset_id": "91609514063242777856043730063938310894548353925882406409927495687846407164056", "price": "0.86", "size": "50", "side": "SELL", "hash": "59f2237880577ca0383a797d7600a465f660b92d", "best_bid": "0.31", "best_ask": "0.33"}], "timestamp": "1769384640616", "event_type": "price_change"}}
{"_local_timestamp": "2026-01-25T23:44:00.797906+00:00", "data": {"market": "0xa9c0c820fd79b4339ed4711288ce15236196a6015234350f42b37341e9094398", "price_changes": [{"asset_id": "78438315737001038193507108078052969359305687599144926740526502005681502958823", "price": "0.14", "size": "250", "side": "BUY", "hash": "d5eeedad25bfa1049b8cb24cc3fdef551774b824", "best_bid": "0.67", "best_ask": "0.69"}, {"asset_id": "91609514063242777856043730063938310894548353925882406409927495687846407164056", "price": "0.86", "size": "250", "side": "SELL", "hash": "680601c6c9d386c14761dd24505ffbbee42105c7", "best_bid": "0.31", "best_ask": "0.33"}], "timestamp": "1769384640661", "event_type": "price_change"}}
{"_local_timestamp": "2026-01-25T23:44:00.799064+00:00", "data": {"market": "0xa9c0c820fd79b4339ed4711288ce15236196a6015234350f42b37341e9094398", "price_changes": [{"asset_id": "78438315737001038193507108078052969359305687599144926740526502005681502958823", "price": "0.15", "size": "0", "side": "BUY", "hash": "9a09bee21532c440253c45fc61ea712cd97b88f7", "best_bid": "0.67", "best_ask": "0.69"}, {"asset_id": "91609514063242777856043730063938310894548353925882406409927495687846407164056", "price": "0.85", "size": "0", "side": "SELL", "hash": "b3f75d9831c246997a28cce2148c5655495442de", "best_bid": "0.31", "best_ask": "0.33"}], "timestamp": "1769384640661", "event_type": "price_change"}}
{"_local_timestamp": "2026-01-25T23:44:01.014145+00:00", "data": {"market": "0xa9c0c820fd79b4339ed4711288ce15236196a6015234350f42b37341e9094398", "price_changes": [{"asset_id": "78438315737001038193507108078052969359305687599144926740526502005681502958823", "price": "0.15", "size": "200", "side": "BUY", "hash": "5e3feb8cbc88b7491a7527c1e40f8ac55b06f163", "best_bid": "0.67", "best_ask": "0.69"}, {"asset_id": "91609514063242777856043730063938310894548353925882406409927495687846407164056", "price": "0.85", "size": "200", "side": "SELL", "hash": "1a88f9921d87500044a7d911a5b21f880701c641", "best_bid": "0.31", "best_ask": "0.33"}], "timestamp": "1769384640871", "event_type": "price_change"}}
{"_local_timestamp": "2026-01-25T23:44:02.805152+00:00", "data": {"market": "0xa9c0c820fd79b4339ed4711288ce15236196a6015234350f42b37341e9094398", "price_changes": [{"asset_id": "78438315737001038193507108078052969359305687599144926740526502005681502958823", "price": "0.14", "size": "50", "side": "BUY", "hash": "d298073c79730b5555ec755b59abde6182887040", "best_bid": "0.67", "best_ask": "0.69"}, {"asset_id": "91609514063242777856043730063938310894548353925882406409927495687846407164056", "price": "0.86", "size": "50", "side": "SELL", "hash": "99b425f2db87c3480072cde220c5381d045c2973", "best_bid": "0.31", "best_ask": "0.33"}], "timestamp": "1769384642661", "event_type": "price_change"}}
{"_local_timestamp": "2026-01-25T23:44:02.814495+00:00", "data": {"market": "0xa9c0c820fd79b4339ed4711288ce15236196a6015234350f42b37341e9094398", "price_changes": [{"asset_id": "78438315737001038193507108078052969359305687599144926740526502005681502958823", "price": "0.16", "size": "200", "side": "BUY", "hash": "f7f04aa36eb7a22aa6275b4b52e8d849af59a8c0", "best_bid": "0.67", "best_ask": "0.69"}, {"asset_id": "91609514063242777856043730063938310894548353925882406409927495687846407164056", "price": "0.84", "size": "200", "side": "SELL", "hash": "90aaceb39d5c43c2cb4540361932d242596a099f", "best_bid": "0.31", "best_ask": "0.33"}], "timestamp": "1769384642668", "event_type": "price_change"}}
{"_local_timestamp": "2026-01-25T23:44:13.083612+00:00", "data": {"market": "0xa9c0c820fd79b4339ed4711288ce15236196a6015234350f42b37341e9094398", "price_changes": [{"asset_id": "78438315737001038193507108078052969359305687599144926740526502005681502958823", "price": "0.15", "size": "0", "side": "BUY", "hash": "8ce1b7f4a02aab6177554e4dbb2c355b335c4fe6", "best_bid": "0.67", "best_ask": "0.69"}, {"asset_id": "91609514063242777856043730063938310894548353925882406409927495687846407164056", "price": "0.85", "size": "0", "side": "SELL", "hash": "e03e3c237c8d17cc10a797667c033320d23f6297", "best_bid": "0.31", "best_ask": "0.33"}], "timestamp": "1769384652936", "event_type": "price_change"}}
{"_local_timestamp": "2026-01-25T23:44:13.124707+00:00", "data": {"market": "0xa9c0c820fd79b4339ed4711288ce15236196a6015234350f42b37341e9094398", "price_changes": [{"asset_id": "78438315737001038193507108078052969359305687599144926740526502005681502958823", "price": "0.14", "size": "250", "side": "BUY", "hash": "2e9008324dfd7b01b3997c6d0dc6f98b673143be", "best_bid": "0.67", "best_ask": "0.69"}, {"asset_id": "91609514063242777856043730063938310894548353925882406409927495687846407164056", "price": "0.86", "size": "250", "side": "SELL", "hash": "5849be719a2e904ab3414bdc0c2f651c99d2e8df", "best_bid": "0.31", "best_ask": "0.33"}], "timestamp": "1769384652978", "event_type": "price_change"}}
{"_local_timestamp": "2026-01-25T23:44:13.135266+00:00", "data": {"market": "0xa9c0c820fd79b4339ed4711288ce15236196a6015234350f42b37341e9094398", "price_changes": [{"asset_id": "78438315737001038193507108078052969359305687599144926740526502005681502958823", "price": "0.16", "size": "0", "side": "BUY", "hash": "e458d72d8afb4aba9453049b5326bfcd47ce4705", "best_bid": "0.67", "best_ask": "0.69"}, {"asset_id": "91609514063242777856043730063938310894548353925882406409927495687846407164056", "price": "0.84", "size": "0", "side": "SELL", "hash": "91178d88e7b02137d1b417367d1c6ae84df71946", "best_bid": "0.31", "best_ask": "0.33"}], "timestamp": "1769384652989", "event_type": "price_change"}}
{"_local_timestamp": "2026-01-25T23:44:13.312244+00:00", "data": {"market": "0xa9c0c820fd79b4339ed4711288ce15236196a6015234350f42b37341e9094398", "price_changes": [{"asset_id": "91609514063242777856043730063938310894548353925882406409927495687846407164056", "price": "0.01", "size": "14275.55", "side": "BUY", "hash": "ff6f5dda8f83e3167a795c70b039b5a7aeb918c3", "best_bid": "0.31", "best_ask": "0.33"}, {"asset_id": "78438315737001038193507108078052969359305687599144926740526502005681502958823", "price": "0.99", "size": "14275.55", "side": "SELL", "hash": "df9be969a79b989546cbe4152f6c12f89ba30805", "best_bid": "0.67", "best_ask": "0.69"}], "timestamp": "1769384653122", "event_type": "price_change"}}
{"_local_timestamp": "2026-01-25T23:44:13.366976+00:00", "data": {"market": "0xa9c0c820fd79b4339ed4711288ce15236196a6015234350f42b37341e9094398", "price_changes": [{"asset_id": "78438315737001038193507108078052969359305687599144926740526502005681502958823", "price": "0.11", "size": "200", "side": "BUY", "hash": "e0e5b7e99152dd4f98bd090208fc92aaa6f41fc6", "best_bid": "0.67", "best_ask": "0.69"}, {"asset_id": "91609514063242777856043730063938310894548353925882406409927495687846407164056", "price": "0.89", "size": "200", "side": "SELL", "hash": "f17e5803e0834eac88b123210f60779b1055eb1c", "best_bid": "0.31", "best_ask": "0.33"}], "timestamp": "1769384653219", "event_type": "price_change"}}
{"_local_timestamp": "2026-01-25T23:44:13.580046+00:00", "data": {"market": "0xa9c0c820fd79b4339ed4711288ce15236196a6015234350f42b37341e9094398", "price_changes": [{"asset_id": "91609514063242777856043730063938310894548353925882406409927495687846407164056", "price": "0.02", "size": "1256.21", "side": "BUY", "hash": "1b4e65e43dbf16025ffd374dd2ecb8dd40a1cc21", "best_bid": "0.31", "best_ask": "0.33"}, {"asset_id": "78438315737001038193507108078052969359305687599144926740526502005681502958823", "price": "0.98", "size": "1256.21", "side": "SELL", "hash": "9d3b2693c014ede2316f7da0be4f15f12c6e3cb6", "best_bid": "0.67", "best_ask": "0.69"}], "timestamp": "1769384653406", "event_type": "price_change"}}
{"_local_timestamp": "2026-01-25T23:44:18.018413+00:00", "data": {"market": "0xa9c0c820fd79b4339ed4711288ce15236196a6015234350f42b37341e9094398", "price_changes": [{"asset_id": "91609514063242777856043730063938310894548353925882406409927495687846407164056", "price": "0.34", "size": "0", "side": "SELL", "hash": "b927ac4866d63a222f7a2846d8102c5bb36d7fd8", "best_bid": "0.31", "best_ask": "0.33"}, {"asset_id": "78438315737001038193507108078052969359305687599144926740526502005681502958823", "price": "0.66", "size": "0", "side": "BUY", "hash": "a676d5b5badc72d750bd5f658b97854a351f6a48", "best_bid": "0.67", "best_ask": "0.69"}], "timestamp": "1769384657758", "event_type": "price_change"}}
{"_local_timestamp": "2026-01-25T23:44:19.233089+00:00", "data": {"market": "0xa9c0c820fd79b4339ed4711288ce15236196a6015234350f42b37341e9094398", "price_changes": [{"asset_id": "91609514063242777856043730063938310894548353925882406409927495687846407164056", "price": "0.34", "size": "6.8", "side": "SELL", "hash": "d9f3d79c8c7d564ca5741e720bd1185bea23bd00", "best_bid": "0.31", "best_ask": "0.33"}, {"asset_id": "78438315737001038193507108078052969359305687599144926740526502005681502958823", "price": "0.66", "size": "6.8", "side": "BUY", "hash": "0a0205e39d4db787b2ab5186282c0c43864cd96d", "best_bid": "0.67", "best_ask": "0.69"}], "timestamp": "1769384658972", "event_type": "price_change"}}
{"_local_timestamp": "2026-01-25T23:44:24.057295+00:00", "data": {"market": "0xa9c0c820fd79b4339ed4711288ce15236196a6015234350f42b37341e9094398", "price_changes": [{"asset_id": "78438315737001038193507108078052969359305687599144926740526502005681502958823", "price": "0.11", "size": "0", "side": "BUY", "hash": "e70eae3b0838ca735fd1f50910a5102200494109", "best_bid": "0.67", "best_ask": "0.69"}, {"asset_id": "91609514063242777856043730063938310894548353925882406409927495687846407164056", "price": "0.89", "size": "0", "side": "SELL", "hash": "1c69f3526e4e1f4c2b88b45de9749da1e0e14d94", "best_bid": "0.31", "best_ask": "0.33"}], "timestamp": "1769384663780", "event_type": "price_change"}}
{"_local_timestamp": "2026-01-25T23:44:24.334506+00:00", "data": {"market": "0xa9c0c820fd79b4339ed4711288ce15236196a6015234350f42b37341e9094398", "price_changes": [{"asset_id": "78438315737001038193507108078052969359305687599144926740526502005681502958823", "price": "0.14", "size": "450", "side": "BUY", "hash": "1d90376deac186dd90c9b3fc8379d5fd38d81d9e", "best_bid": "0.67", "best_ask": "0.69"}, {"asset_id": "91609514063242777856043730063938310894548353925882406409927495687846407164056", "price": "0.86", "size": "450", "side": "SELL", "hash": "1c8b6d069570d16d481f9338a6a0690b2027d683", "best_bid": "0.31", "best_ask": "0.33"}], "timestamp": "1769384664062", "event_type": "price_change"}}
{"_local_timestamp": "2026-01-25T23:44:24.358861+00:00", "data": {"market": "0xa9c0c820fd79b4339ed4711288ce15236196a6015234350f42b37341e9094398", "price_changes": [{"asset_id": "78438315737001038193507108078052969359305687599144926740526502005681502958823", "price": "0.14", "size": "250", "side": "BUY", "hash": "99d1d8c4c417a01aa3e1fe64971869a6b608c722", "best_bid": "0.67", "best_ask": "0.69"}, {"asset_id": "91609514063242777856043730063938310894548353925882406409927495687846407164056", "price": "0.86", "size": "250", "side": "SELL", "hash": "142ab1fe68f347aa2f92cc67973907f430fcf037", "best_bid": "0.31", "best_ask": "0.33"}], "timestamp": "1769384664103", "event_type": "price_change"}}
{"_local_timestamp": "2026-01-25T23:44:24.362103+00:00", "data": {"market": "0xa9c0c820fd79b4339ed4711288ce15236196a6015234350f42b37341e9094398", "price_changes": [{"asset_id": "78438315737001038193507108078052969359305687599144926740526502005681502958823", "price": "0.15", "size": "200", "side": "BUY", "hash": "4eb81b83a6af562b71df5187630008a5b114884c", "best_bid": "0.67", "best_ask": "0.69"}, {"asset_id": "91609514063242777856043730063938310894548353925882406409927495687846407164056", "price": "0.85", "size": "200", "side": "SELL", "hash": "76f808f574f72893d5fdce10ba31361a3fd04e54", "best_bid": "0.31", "best_ask": "0.33"}], "timestamp": "1769384664107", "event_type": "price_change"}}
{"_local_timestamp": "2026-01-25T23:44:34.972920+00:00", "data": {"market": "0xa9c0c820fd79b4339ed4711288ce15236196a6015234350f42b37341e9094398", "price_changes": [{"asset_id": "78438315737001038193507108078052969359305687599144926740526502005681502958823", "price": "0.14", "size": "50", "side": "BUY", "hash": "36aaf1e6fe19ab0fc5616764037b0cb32564e76b", "best_bid": "0.67", "best_ask": "0.69"}, {"asset_id": "91609514063242777856043730063938310894548353925882406409927495687846407164056", "price": "0.86", "size": "50", "side": "SELL", "hash": "a656ce88035c4e7bc4da0a49907752a0f630e0f7", "best_bid": "0.31", "best_ask": "0.33"}], "timestamp": "1769384674708", "event_type": "price_change"}}
{"_local_timestamp": "2026-01-25T23:44:35.021022+00:00", "data": {"market": "0xa9c0c820fd79b4339ed4711288ce15236196a6015234350f42b37341e9094398", "price_changes": [{"asset_id": "78438315737001038193507108078052969359305687599144926740526502005681502958823", "price": "0.15", "size": "0", "side": "BUY", "hash": "b2e378fd24434a8865972f664c2ff44889109395", "best_bid": "0.67", "best_ask": "0.69"}, {"asset_id": "91609514063242777856043730063938310894548353925882406409927495687846407164056", "price": "0.85", "size": "0", "side": "SELL", "hash": "bd4317a44194140298c07010b12698d17172ecad", "best_bid": "0.31", "best_ask": "0.33"}], "timestamp": "1769384674746", "event_type": "price_change"}}
{"_local_timestamp": "2026-01-25T23:44:35.022051+00:00", "data": {"market": "0xa9c0c820fd79b4339ed4711288ce15236196a6015234350f42b37341e9094398", "price_changes": [{"asset_id": "78438315737001038193507108078052969359305687599144926740526502005681502958823", "price": "0.14", "size": "250", "side": "BUY", "hash": "83d2cf805c7d602d6f53e88bb615ead341c3c5db", "best_bid": "0.67", "best_ask": "0.69"}, {"asset_id": "91609514063242777856043730063938310894548353925882406409927495687846407164056", "price": "0.86", "size": "250", "side": "SELL", "hash": "d311a00f9e7e6594b1a06c6be1eebf2e8f94e2e9", "best_bid": "0.31", "best_ask": "0.33"}], "timestamp": "1769384674748", "event_type": "price_change"}}
{"_local_timestamp": "2026-01-25T23:44:35.228539+00:00", "data": {"market": "0xa9c0c820fd79b4339ed4711288ce15236196a6015234350f42b37341e9094398", "price_changes": [{"asset_id": "78438315737001038193507108078052969359305687599144926740526502005681502958823", "price": "0.15", "size": "200", "side": "BUY", "hash": "830be06fc813d880277dbd2955538b3b113413f4", "best_bid": "0.67", "best_ask": "0.69"}, {"asset_id": "91609514063242777856043730063938310894548353925882406409927495687846407164056", "price": "0.85", "size": "200", "side": "SELL", "hash": "fbd751ae62792f105dd9968b0f64f061999f7e00", "best_bid": "0.31", "best_ask": "0.33"}], "timestamp": "1769384674963", "event_type": "price_change"}}
{"_local_timestamp": "2026-01-25T23:44:37.029224+00:00", "data": {"market": "0xa9c0c820fd79b4339ed4711288ce15236196a6015234350f42b37341e9094398", "price_changes": [{"asset_id": "78438315737001038193507108078052969359305687599144926740526502005681502958823", "price": "0.16", "size": "200", "side": "BUY", "hash": "4f8bfcc58bf25dba05f0aa63568180893553de7a", "best_bid": "0.67", "best_ask": "0.69"}, {"asset_id": "91609514063242777856043730063938310894548353925882406409927495687846407164056", "price": "0.84", "size": "200", "side": "SELL", "hash": "96296c45b6b6c01786f80f248d77aa008e2077d1", "best_bid": "0.31", "best_ask": "0.33"}], "timestamp": "1769384676747", "event_type": "price_change"}}
{"_local_timestamp": "2026-01-25T23:44:37.040739+00:00", "data": {"market": "0xa9c0c820fd79b4339ed4711288ce15236196a6015234350f42b37341e9094398", "price_changes": [{"asset_id": "78438315737001038193507108078052969359305687599144926740526502005681502958823", "price": "0.14", "size": "50", "side": "BUY", "hash": "bc89388e706701ee4a0d2764ab88e998d0aa2059", "best_bid": "0.67", "best_ask": "0.69"}, {"asset_id": "91609514063242777856043730063938310894548353925882406409927495687846407164056", "price": "0.86", "size": "50", "side": "SELL", "hash": "516cd0c619fc8231be3a11fc54a74cac774885b2", "best_bid": "0.31", "best_ask": "0.33"}], "timestamp": "1769384676748", "event_type": "price_change"}}
{"_local_timestamp": "2026-01-25T23:44:46.409927+00:00", "data": {"market": "0xa9c0c820fd79b4339ed4711288ce15236196a6015234350f42b37341e9094398", "price_changes": [{"asset_id": "78438315737001038193507108078052969359305687599144926740526502005681502958823", "price": "0.15", "size": "0", "side": "BUY", "hash": "442e434db266f1b613e492e4d6de80a72baed710", "best_bid": "0.67", "best_ask": "0.69"}, {"asset_id": "91609514063242777856043730063938310894548353925882406409927495687846407164056", "price": "0.85", "size": "0", "side": "SELL", "hash": "7317d1b6c0b0dd97324d85241c16ebc2ff0326fd", "best_bid": "0.31", "best_ask": "0.33"}], "timestamp": "1769384686216", "event_type": "price_change"}}
{"_local_timestamp": "2026-01-25T23:44:46.458502+00:00", "data": {"market": "0xa9c0c820fd79b4339ed4711288ce15236196a6015234350f42b37341e9094398", "price_changes": [{"asset_id": "78438315737001038193507108078052969359305687599144926740526502005681502958823", "price": "0.16", "size": "0", "side": "BUY", "hash": "a763ebaeb25d2ba82cc10b0968a05e683b303cfd", "best_bid": "0.67", "best_ask": "0.69"}, {"asset_id": "91609514063242777856043730063938310894548353925882406409927495687846407164056", "price": "0.84", "size": "0", "side": "SELL", "hash": "6d54e92aca987e06979b6dea560e254eb09a3253", "best_bid": "0.31", "best_ask": "0.33"}], "timestamp": "1769384686255", "event_type": "price_change"}}
{"_local_timestamp": "2026-01-25T23:44:46.459487+00:00", "data": {"market": "0xa9c0c820fd79b4339ed4711288ce15236196a6015234350f42b37341e9094398", "price_changes": [{"asset_id": "78438315737001038193507108078052969359305687599144926740526502005681502958823", "price": "0.14", "size": "250", "side": "BUY", "hash": "a8dadf34c0c47d5c1cf5184e5e52d1887d5ce61c", "best_bid": "0.67", "best_ask": "0.69"}, {"asset_id": "91609514063242777856043730063938310894548353925882406409927495687846407164056", "price": "0.86", "size": "250", "side": "SELL", "hash": "1b39a61dcef7b4aad852a54774ae1f21a8e5195b", "best_bid": "0.31", "best_ask": "0.33"}], "timestamp": "1769384686255", "event_type": "price_change"}}
{"_local_timestamp": "2026-01-25T23:44:46.663138+00:00", "data": {"market": "0xa9c0c820fd79b4339ed4711288ce15236196a6015234350f42b37341e9094398", "price_changes": [{"asset_id": "78438315737001038193507108078052969359305687599144926740526502005681502958823", "price": "0.11", "size": "200", "side": "BUY", "hash": "42c6103ac14fce342096752044ec15c26aee916d", "best_bid": "0.67", "best_ask": "0.69"}, {"asset_id": "91609514063242777856043730063938310894548353925882406409927495687846407164056", "price": "0.89", "size": "200", "side": "SELL", "hash": "e09278598889d1ec722ba7a247f4655e41c3eb1c", "best_bid": "0.31", "best_ask": "0.33"}], "timestamp": "1769384686469", "event_type": "price_change"}}
{"_local_timestamp": "2026-01-25T23:44:57.927822+00:00", "data": {"market": "0xa9c0c820fd79b4339ed4711288ce15236196a6015234350f42b37341e9094398", "price_changes": [{"asset_id": "78438315737001038193507108078052969359305687599144926740526502005681502958823", "price": "0.11", "size": "0", "side": "BUY", "hash": "4acc35b4ffa0516ef8679f34c04845d511e52933", "best_bid": "0.67", "best_ask": "0.69"}, {"asset_id": "91609514063242777856043730063938310894548353925882406409927495687846407164056", "price": "0.89", "size": "0", "side": "SELL", "hash": "866eb42c6debb2fbbaa5f8c1b8d5a3556055bfa4", "best_bid": "0.31", "best_ask": "0.33"}], "timestamp": "1769384697854", "event_type": "price_change"}}
{"_local_timestamp": "2026-01-25T23:44:58.190491+00:00", "data": {"market": "0xa9c0c820fd79b4339ed4711288ce15236196a6015234350f42b37341e9094398", "price_changes": [{"asset_id": "78438315737001038193507108078052969359305687599144926740526502005681502958823", "price": "0.14", "size": "450", "side": "BUY", "hash": "f6c15b83fed7c38ebd4c75af28c8389caa6b8054", "best_bid": "0.67", "best_ask": "0.69"}, {"asset_id": "91609514063242777856043730063938310894548353925882406409927495687846407164056", "price": "0.86", "size": "450", "side": "SELL", "hash": "14237d99bf09a1e523284c024d6acfc399c96990", "best_bid": "0.31", "best_ask": "0.33"}], "timestamp": "1769384698120", "event_type": "price_change"}}
{"_local_timestamp": "2026-01-25T23:44:58.232921+00:00", "data": {"market": "0xa9c0c820fd79b4339ed4711288ce15236196a6015234350f42b37341e9094398", "price_changes": [{"asset_id": "78438315737001038193507108078052969359305687599144926740526502005681502958823", "price": "0.14", "size": "250", "side": "BUY", "hash": "745ed110eb78ded64c68bdd6b17e879f2fc33195", "best_bid": "0.67", "best_ask": "0.69"}, {"asset_id": "91609514063242777856043730063938310894548353925882406409927495687846407164056", "price": "0.86", "size": "250", "side": "SELL", "hash": "5cd1b2cb3fea35ba027baa8f475c3c28786cef1f", "best_bid": "0.31", "best_ask": "0.33"}], "timestamp": "1769384698160", "event_type": "price_change"}}
{"_local_timestamp": "2026-01-25T23:44:58.233898+00:00", "data": {"market": "0xa9c0c820fd79b4339ed4711288ce15236196a6015234350f42b37341e9094398", "price_changes": [{"asset_id": "78438315737001038193507108078052969359305687599144926740526502005681502958823", "price": "0.15", "size": "200", "side": "BUY", "hash": "da292d29d1bc09ec5759b6a0bcf75ab0d130cb30", "best_bid": "0.67", "best_ask": "0.69"}, {"asset_id": "91609514063242777856043730063938310894548353925882406409927495687846407164056", "price": "0.85", "size": "200", "side": "SELL", "hash": "ad77890abe1674af949e01f89c6ba3206d0ac861", "best_bid": "0.31", "best_ask": "0.33"}], "timestamp": "1769384698162", "event_type": "price_change"}}
{"_local_timestamp": "2026-01-25T23:45:08.728714+00:00", "data": {"market": "0xa9c0c820fd79b4339ed4711288ce15236196a6015234350f42b37341e9094398", "price_changes": [{"asset_id": "78438315737001038193507108078052969359305687599144926740526502005681502958823", "price": "0.14", "size": "50", "side": "BUY", "hash": "0e2ee21558c6aa244d209d730de1fdd665cc4de9", "best_bid": "0.67", "best_ask": "0.69"}, {"asset_id": "91609514063242777856043730063938310894548353925882406409927495687846407164056", "price": "0.86", "size": "50", "side": "SELL", "hash": "da46c725a2a1ee2aec570ba0dde5848aa2927f24", "best_bid": "0.31", "best_ask": "0.33"}], "timestamp": "1769384708658", "event_type": "price_change"}}
{"_local_timestamp": "2026-01-25T23:45:08.768441+00:00", "data": {"market": "0xa9c0c820fd79b4339ed4711288ce15236196a6015234350f42b37341e9094398", "price_changes": [{"asset_id": "78438315737001038193507108078052969359305687599144926740526502005681502958823", "price": "0.14", "size": "250", "side": "BUY", "hash": "7a36c7e86599be8b9c3e21e7872590915fee9cfe", "best_bid": "0.67", "best_ask": "0.69"}, {"asset_id": "91609514063242777856043730063938310894548353925882406409927495687846407164056", "price": "0.86", "size": "250", "side": "SELL", "hash": "793283a60263f3bc26eaa015fdd7023594b0535f", "best_bid": "0.31", "best_ask": "0.33"}], "timestamp": "1769384708698", "event_type": "price_change"}}
{"_local_timestamp": "2026-01-25T23:45:08.782894+00:00", "data": {"market": "0xa9c0c820fd79b4339ed4711288ce15236196a6015234350f42b37341e9094398", "price_changes": [{"asset_id": "78438315737001038193507108078052969359305687599144926740526502005681502958823", "price": "0.15", "size": "0", "side": "BUY", "hash": "f50089b4d039edda149626de1a44a4445e0796d0", "best_bid": "0.67", "best_ask": "0.69"}, {"asset_id": "91609514063242777856043730063938310894548353925882406409927495687846407164056", "price": "0.85", "size": "0", "side": "SELL", "hash": "c7aeac879a778a79fa51c3fc50c741c50202acd3", "best_bid": "0.31", "best_ask": "0.33"}], "timestamp": "1769384708703", "event_type": "price_change"}}
{"_local_timestamp": "2026-01-25T23:45:08.986525+00:00", "data": {"market": "0xa9c0c820fd79b4339ed4711288ce15236196a6015234350f42b37341e9094398", "price_changes": [{"asset_id": "78438315737001038193507108078052969359305687599144926740526502005681502958823", "price": "0.15", "size": "200", "side": "BUY", "hash": "10df6b13f200fc4664165f5be05cce20a266066f", "best_bid": "0.67", "best_ask": "0.69"}, {"asset_id": "91609514063242777856043730063938310894548353925882406409927495687846407164056", "price": "0.85", "size": "200", "side": "SELL", "hash": "386ca03a9da7804a09bce858005ece0942a14cc9", "best_bid": "0.31", "best_ask": "0.33"}], "timestamp": "1769384708915", "event_type": "price_change"}}
{"_local_timestamp": "2026-01-25T23:45:10.767082+00:00", "data": {"market": "0xa9c0c820fd79b4339ed4711288ce15236196a6015234350f42b37341e9094398", "price_changes": [{"asset_id": "78438315737001038193507108078052969359305687599144926740526502005681502958823", "price": "0.14", "size": "50", "side": "BUY", "hash": "77928aa26b34435acd6b32d666ccdf7eb3ca1445", "best_bid": "0.67", "best_ask": "0.69"}, {"asset_id": "91609514063242777856043730063938310894548353925882406409927495687846407164056", "price": "0.86", "size": "50", "side": "SELL", "hash": "774ef0b27e622bb73a9a5624e7fbc8a4701f3bf3", "best_bid": "0.31", "best_ask": "0.33"}], "timestamp": "1769384710700", "event_type": "price_change"}}
{"_local_timestamp": "2026-01-25T23:45:10.768181+00:00", "data": {"market": "0xa9c0c820fd79b4339ed4711288ce15236196a6015234350f42b37341e9094398", "price_changes": [{"asset_id": "78438315737001038193507108078052969359305687599144926740526502005681502958823", "price": "0.16", "size": "200", "side": "BUY", "hash": "79101970c13d662640afa0742448943502314b72", "best_bid": "0.67", "best_ask": "0.69"}, {"asset_id": "91609514063242777856043730063938310894548353925882406409927495687846407164056", "price": "0.84", "size": "200", "side": "SELL", "hash": "47ea4d3346bd5e7b19ff301a2f7b7dd14cdbec83", "best_bid": "0.31", "best_ask": "0.33"}], "timestamp": "1769384710701", "event_type": "price_change"}}
{"_local_timestamp": "2026-01-25T23:45:17.947331+00:00", "data": {"market": "0xa9c0c820fd79b4339ed4711288ce15236196a6015234350f42b37341e9094398", "price_changes": [{"asset_id": "91609514063242777856043730063938310894548353925882406409927495687846407164056", "price": "0.34", "size": "0", "side": "SELL", "hash": "d0cb5559dd8466f47a3024e97a42e36849b4e297", "best_bid": "0.31", "best_ask": "0.33"}, {"asset_id": "78438315737001038193507108078052969359305687599144926740526502005681502958823", "price": "0.66", "size": "0", "side": "BUY", "hash": "d31595f42ad35ecf611d776edd0f655a899b1375", "best_bid": "0.67", "best_ask": "0.69"}], "timestamp": "1769384717873", "event_type": "price_change"}}
{"_local_timestamp": "2026-01-25T23:45:18.890558+00:00", "data": {"market": "0xa9c0c820fd79b4339ed4711288ce15236196a6015234350f42b37341e9094398", "price_changes": [{"asset_id": "91609514063242777856043730063938310894548353925882406409927495687846407164056", "price": "0.34", "size": "6.8", "side": "SELL", "hash": "358274e9e223f7b59ae0b588883e5bb2003034ea", "best_bid": "0.31", "best_ask": "0.33"}, {"asset_id": "78438315737001038193507108078052969359305687599144926740526502005681502958823", "price": "0.66", "size": "6.8", "side": "BUY", "hash": "6c851e001bf488421a75ebcd11a32a9e9b750366", "best_bid": "0.67", "best_ask": "0.69"}], "timestamp": "1769384718824", "event_type": "price_change"}}
{"_local_timestamp": "2026-01-25T23:45:20.128812+00:00", "data": {"market": "0xa9c0c820fd79b4339ed4711288ce15236196a6015234350f42b37341e9094398", "price_changes": [{"asset_id": "78438315737001038193507108078052969359305687599144926740526502005681502958823", "price": "0.15", "size": "0", "side": "BUY", "hash": "e2faf80a26d35a85fb7c610e66c5626aec2219eb", "best_bid": "0.67", "best_ask": "0.69"}, {"asset_id": "91609514063242777856043730063938310894548353925882406409927495687846407164056", "price": "0.85", "size": "0", "side": "SELL", "hash": "b6c723d15d5ac657b7b8fe9a82334a2c641420da", "best_bid": "0.31", "best_ask": "0.33"}], "timestamp": "1769384720052", "event_type": "price_change"}}
{"_local_timestamp": "2026-01-25T23:45:20.170833+00:00", "data": {"market": "0xa9c0c820fd79b4339ed4711288ce15236196a6015234350f42b37341e9094398", "price_changes": [{"asset_id": "78438315737001038193507108078052969359305687599144926740526502005681502958823", "price": "0.14", "size": "250", "side": "BUY", "hash": "f0f51158884459052200466376001ab509a9d081", "best_bid": "0.67", "best_ask": "0.69"}, {"asset_id": "91609514063242777856043730063938310894548353925882406409927495687846407164056", "price": "0.86", "size": "250", "side": "SELL", "hash": "bd7778cb0241c1d0d8d99c01f27df1287780ca2a", "best_bid": "0.31", "best_ask": "0.33"}], "timestamp": "1769384720105", "event_type": "price_change"}}
{"_local_timestamp": "2026-01-25T23:45:20.171896+00:00", "data": {"market": "0xa9c0c820fd79b4339ed4711288ce15236196a6015234350f42b37341e9094398", "price_changes": [{"asset_id": "78438315737001038193507108078052969359305687599144926740526502005681502958823", "price": "0.16", "size": "0", "side": "BUY", "hash": "39b3fa0cc327639d8487aa7ec8ad3bb4aed6cd58", "best_bid": "0.67", "best_ask": "0.69"}, {"asset_id": "91609514063242777856043730063938310894548353925882406409927495687846407164056", "price": "0.84", "size": "0", "side": "SELL", "hash": "3081c44a328b014602cd8999d5ad0b1df70d2d3f", "best_bid": "0.31", "best_ask": "0.33"}], "timestamp": "1769384720106", "event_type": "price_change"}}
{"_local_timestamp": "2026-01-25T23:45:20.372864+00:00", "data": {"market": "0xa9c0c820fd79b4339ed4711288ce15236196a6015234350f42b37341e9094398", "price_changes": [{"asset_id": "78438315737001038193507108078052969359305687599144926740526502005681502958823", "price": "0.11", "size": "200", "side": "BUY", "hash": "739642f2edc33931637c0c2cad8c758f8867d885", "best_bid": "0.67", "best_ask": "0.69"}, {"asset_id": "91609514063242777856043730063938310894548353925882406409927495687846407164056", "price": "0.89", "size": "200", "side": "SELL", "hash": "eae4e2d8ee7a245f63c06472a9113c5be16b66e6", "best_bid": "0.31", "best_ask": "0.33"}], "timestamp": "1769384720306", "event_type": "price_change"}}
{"_local_timestamp": "2026-01-25T23:45:31.925736+00:00", "data": {"market": "0xa9c0c820fd79b4339ed4711288ce15236196a6015234350f42b37341e9094398", "price_changes": [{"asset_id": "78438315737001038193507108078052969359305687599144926740526502005681502958823", "price": "0.11", "size": "0", "side": "BUY", "hash": "89cb7916482443828283bf52e50203d7ac8515c9", "best_bid": "0.67", "best_ask": "0.69"}, {"asset_id": "91609514063242777856043730063938310894548353925882406409927495687846407164056", "price": "0.89", "size": "0", "side": "SELL", "hash": "2d926eb8754f3416664795cc88cf9bc2345a6128", "best_bid": "0.31", "best_ask": "0.33"}], "timestamp": "1769384731853", "event_type": "price_change"}}
{"_local_timestamp": "2026-01-25T23:45:32.192007+00:00", "data": {"market": "0xa9c0c820fd79b4339ed4711288ce15236196a6015234350f42b37341e9094398", "price_changes": [{"asset_id": "78438315737001038193507108078052969359305687599144926740526502005681502958823", "price": "0.14", "size": "450", "side": "BUY", "hash": "7c328eced391423b59c5119af570d15ebc9f29ff", "best_bid": "0.67", "best_ask": "0.69"}, {"asset_id": "91609514063242777856043730063938310894548353925882406409927495687846407164056", "price": "0.86", "size": "450", "side": "SELL", "hash": "58ade073eff77bc545108417e61ada92b1631718", "best_bid": "0.31", "best_ask": "0.33"}], "timestamp": "1769384732119", "event_type": "price_change"}}
{"_local_timestamp": "2026-01-25T23:45:32.231345+00:00", "data": {"market": "0xa9c0c820fd79b4339ed4711288ce15236196a6015234350f42b37341e9094398", "price_changes": [{"asset_id": "78438315737001038193507108078052969359305687599144926740526502005681502958823", "price": "0.15", "size": "200", "side": "BUY", "hash": "296263be415c1ff34e0d729b8d5a1a4f038e99dd", "best_bid": "0.67", "best_ask": "0.69"}, {"asset_id": "91609514063242777856043730063938310894548353925882406409927495687846407164056", "price": "0.85", "size": "200", "side": "SELL", "hash": "113d9dab3ba07169215252338ac8fb5224e86231", "best_bid": "0.31", "best_ask": "0.33"}], "timestamp": "1769384732157", "event_type": "price_change"}}
{"_local_timestamp": "2026-01-25T23:45:32.238047+00:00", "data": {"market": "0xa9c0c820fd79b4339ed4711288ce15236196a6015234350f42b37341e9094398", "price_changes": [{"asset_id": "78438315737001038193507108078052969359305687599144926740526502005681502958823", "price": "0.14", "size": "250", "side": "BUY", "hash": "8ec71afde94c3091601f60b362167b667c369b2b", "best_bid": "0.67", "best_ask": "0.69"}, {"asset_id": "91609514063242777856043730063938310894548353925882406409927495687846407164056", "price": "0.86", "size": "250", "side": "SELL", "hash": "525971933f6ae3a8e1a6d0148aea81ecd42fe2cf", "best_bid": "0.31", "best_ask": "0.33"}], "timestamp": "1769384732167", "event_type": "price_change"}}
{"_local_timestamp": "2026-01-25T23:45:34.213894+00:00", "data": {"market": "0xa9c0c820fd79b4339ed4711288ce15236196a6015234350f42b37341e9094398", "price_changes": [{"asset_id": "78438315737001038193507108078052969359305687599144926740526502005681502958823", "price": "0.15", "size": "0", "side": "BUY", "hash": "42f73fbefa2e78df28b95a2ebb8a9c187553e3cd", "best_bid": "0.67", "best_ask": "0.69"}, {"asset_id": "91609514063242777856043730063938310894548353925882406409927495687846407164056", "price": "0.85", "size": "0", "side": "SELL", "hash": "4e822f45238d1a306986650fe1fae0eb3dabb7bb", "best_bid": "0.31", "best_ask": "0.33"}], "timestamp": "1769384734150", "event_type": "price_change"}}
{"_local_timestamp": "2026-01-25T23:45:34.256707+00:00", "data": {"market": "0xa9c0c820fd79b4339ed4711288ce15236196a6015234350f42b37341e9094398", "price_changes": [{"asset_id": "78438315737001038193507108078052969359305687599144926740526502005681502958823", "price": "0.15", "size": "200", "side": "BUY", "hash": "ffbe85ccb1ab60384d8bb5b6b1f5ae28db28637c", "best_bid": "0.67", "best_ask": "0.69"}, {"asset_id": "91609514063242777856043730063938310894548353925882406409927495687846407164056", "price": "0.85", "size": "200", "side": "SELL", "hash": "f81d9481db880c446ccdb713a36ccef223c6b038", "best_bid": "0.31", "best_ask": "0.33"}], "timestamp": "1769384734189", "event_type": "price_change"}}
{"_local_timestamp": "2026-01-25T23:45:44.530680+00:00", "data": {"market": "0xa9c0c820fd79b4339ed4711288ce15236196a6015234350f42b37341e9094398", "price_changes": [{"asset_id": "78438315737001038193507108078052969359305687599144926740526502005681502958823", "price": "0.14", "size": "50", "side": "BUY", "hash": "6893f3ec64ed0da7f0c7e9897456d822c169c593", "best_bid": "0.67", "best_ask": "0.69"}, {"asset_id": "91609514063242777856043730063938310894548353925882406409927495687846407164056", "price": "0.86", "size": "50", "side": "SELL", "hash": "1cd717bf1cd016acdc0a3a9f36c92b175104f3e0", "best_bid": "0.31", "best_ask": "0.33"}], "timestamp": "1769384744450", "event_type": "price_change"}}
{"_local_timestamp": "2026-01-25T23:45:44.556729+00:00", "data": {"market": "0xa9c0c820fd79b4339ed4711288ce15236196a6015234350f42b37341e9094398", "price_changes": [{"asset_id": "78438315737001038193507108078052969359305687599144926740526502005681502958823", "price": "0.15", "size": "0", "side": "BUY", "hash": "ac2938496b091c6315e785d8bb409460f15c1f79", "best_bid": "0.67", "best_ask": "0.69"}, {"asset_id": "91609514063242777856043730063938310894548353925882406409927495687846407164056", "price": "0.85", "size": "0", "side": "SELL", "hash": "16504b4369aadc4347c88aab3c207c7fac97a256", "best_bid": "0.31", "best_ask": "0.33"}], "timestamp": "1769384744490", "event_type": "price_change"}}
{"_local_timestamp": "2026-01-25T23:45:44.557712+00:00", "data": {"market": "0xa9c0c820fd79b4339ed4711288ce15236196a6015234350f42b37341e9094398", "price_changes": [{"asset_id": "78438315737001038193507108078052969359305687599144926740526502005681502958823", "price": "0.14", "size": "250", "side": "BUY", "hash": "d24b6fc95d5435c14038e08bb875423cd68f2200", "best_bid": "0.67", "best_ask": "0.69"}, {"asset_id": "91609514063242777856043730063938310894548353925882406409927495687846407164056", "price": "0.86", "size": "250", "side": "SELL", "hash": "f7124b39ab27bc8fdda3d1b2dcea1a7e459d9cd9", "best_bid": "0.31", "best_ask": "0.33"}], "timestamp": "1769384744493", "event_type": "price_change"}}
{"_local_timestamp": "2026-01-25T23:45:44.773801+00:00", "data": {"market": "0xa9c0c820fd79b4339ed4711288ce15236196a6015234350f42b37341e9094398", "price_changes": [{"asset_id": "78438315737001038193507108078052969359305687599144926740526502005681502958823", "price": "0.15", "size": "200", "side": "BUY", "hash": "91bf9e0883fd821456a7e9eda2a7192810d27eaa", "best_bid": "0.67", "best_ask": "0.69"}, {"asset_id": "91609514063242777856043730063938310894548353925882406409927495687846407164056", "price": "0.85", "size": "200", "side": "SELL", "hash": "453c97e51c8c27bc3dbcfad2eef6100fee60cd51", "best_bid": "0.31", "best_ask": "0.33"}], "timestamp": "1769384744710", "event_type": "price_change"}}
{"_local_timestamp": "2026-01-25T23:45:46.559030+00:00", "data": {"market": "0xa9c0c820fd79b4339ed4711288ce15236196a6015234350f42b37341e9094398", "price_changes": [{"asset_id": "78438315737001038193507108078052969359305687599144926740526502005681502958823", "price": "0.14", "size": "50", "side": "BUY", "hash": "30169eeb41a0eb54a2a221c31961dbe109a56189", "best_bid": "0.67", "best_ask": "0.69"}, {"asset_id": "91609514063242777856043730063938310894548353925882406409927495687846407164056", "price": "0.86", "size": "50", "side": "SELL", "hash": "b9bbfe34c52c0be68984626fdf0572e7695c97d4", "best_bid": "0.31", "best_ask": "0.33"}], "timestamp": "1769384746489", "event_type": "price_change"}}
{"_local_timestamp": "2026-01-25T23:45:46.560080+00:00", "data": {"market": "0xa9c0c820fd79b4339ed4711288ce15236196a6015234350f42b37341e9094398", "price_changes": [{"asset_id": "78438315737001038193507108078052969359305687599144926740526502005681502958823", "price": "0.16", "size": "200", "side": "BUY", "hash": "1cc9711b4bb17a740d01ba4fd3e3300f24cb715b", "best_bid": "0.67", "best_ask": "0.69"}, {"asset_id": "91609514063242777856043730063938310894548353925882406409927495687846407164056", "price": "0.84", "size": "200", "side": "SELL", "hash": "2675bb59f6cf3ea904820baa57fde6feb5fcf5d1", "best_bid": "0.31", "best_ask": "0.33"}], "timestamp": "1769384746490", "event_type": "price_change"}}
{"_local_timestamp": "2026-01-25T23:45:48.556551+00:00", "data": {"market": "0xa9c0c820fd79b4339ed4711288ce15236196a6015234350f42b37341e9094398", "price_changes": [{"asset_id": "78438315737001038193507108078052969359305687599144926740526502005681502958823", "price": "0.17", "size": "200", "side": "BUY", "hash": "4e84cf4b5d5bdc02ad7075d3c57fdf537f0ea939", "best_bid": "0.67", "best_ask": "0.69"}, {"asset_id": "91609514063242777856043730063938310894548353925882406409927495687846407164056", "price": "0.83", "size": "200", "side": "SELL", "hash": "7e658df1283773c89162cec0e71df8630585fb11", "best_bid": "0.31", "best_ask": "0.33"}], "timestamp": "1769384748494", "event_type": "price_change"}}
{"_local_timestamp": "2026-01-25T23:45:50.542295+00:00", "data": {"market": "0xa9c0c820fd79b4339ed4711288ce15236196a6015234350f42b37341e9094398", "price_changes": [{"asset_id": "78438315737001038193507108078052969359305687599144926740526502005681502958823", "price": "0.17", "size": "0", "side": "BUY", "hash": "d06bdbcf5e1d5074df971fcf6ab713da0beae473", "best_bid": "0.67", "best_ask": "0.69"}, {"asset_id": "91609514063242777856043730063938310894548353925882406409927495687846407164056", "price": "0.83", "size": "0", "side": "SELL", "hash": "ac442985d1cb82981bb2c7e323aa92ab5cd7381c", "best_bid": "0.31", "best_ask": "0.33"}], "timestamp": "1769384750479", "event_type": "price_change"}}
{"_local_timestamp": "2026-01-25T23:45:57.441114+00:00", "data": {"market": "0xa9c0c820fd79b4339ed4711288ce15236196a6015234350f42b37341e9094398", "price_changes": [{"asset_id": "78438315737001038193507108078052969359305687599144926740526502005681502958823", "price": "0.15", "size": "0", "side": "BUY", "hash": "bf0eaad3cbb882c72c52a00f42e98c0e86a8b8ae", "best_bid": "0.67", "best_ask": "0.69"}, {"asset_id": "91609514063242777856043730063938310894548353925882406409927495687846407164056", "price": "0.85", "size": "0", "side": "SELL", "hash": "7d5ce9b93b2fe4fa6dbf3689dbc1266b8f56d822", "best_bid": "0.31", "best_ask": "0.33"}], "timestamp": "1769384757124", "event_type": "price_change"}}
{"_local_timestamp": "2026-01-25T23:45:57.452821+00:00", "data": {"market": "0xa9c0c820fd79b4339ed4711288ce15236196a6015234350f42b37341e9094398", "price_changes": [{"asset_id": "78438315737001038193507108078052969359305687599144926740526502005681502958823", "price": "0.16", "size": "0", "side": "BUY", "hash": "e548774e217485cb46d0e3e665fc2b6175dfda09", "best_bid": "0.67", "best_ask": "0.69"}, {"asset_id": "91609514063242777856043730063938310894548353925882406409927495687846407164056", "price": "0.84", "size": "0", "side": "SELL", "hash": "93bfb91b350537658f3b3d5d9e746a2c3f61ae3b", "best_bid": "0.31", "best_ask": "0.33"}], "timestamp": "1769384757309", "event_type": "price_change"}}
{"_local_timestamp": "2026-01-25T23:45:57.453837+00:00", "data": {"market": "0xa9c0c820fd79b4339ed4711288ce15236196a6015234350f42b37341e9094398", "price_changes": [{"asset_id": "78438315737001038193507108078052969359305687599144926740526502005681502958823", "price": "0.14", "size": "250", "side": "BUY", "hash": "9dea80e9b98e4ab9395da7ff50f325b0441d831c", "best_bid": "0.67", "best_ask": "0.69"}, {"asset_id": "91609514063242777856043730063938310894548353925882406409927495687846407164056", "price": "0.86", "size": "250", "side": "SELL", "hash": "302a76d5824531a6f73983d99ab19ee5a0f9b6d1", "best_bid": "0.31", "best_ask": "0.33"}], "timestamp": "1769384757312", "event_type": "price_change"}}
{"_local_timestamp": "2026-01-25T23:45:57.474469+00:00", "data": {"market": "0xa9c0c820fd79b4339ed4711288ce15236196a6015234350f42b37341e9094398", "price_changes": [{"asset_id": "78438315737001038193507108078052969359305687599144926740526502005681502958823", "price": "0.11", "size": "200", "side": "BUY", "hash": "bf8446bd64ffda621355738971aa468d5cb02ab3", "best_bid": "0.67", "best_ask": "0.69"}, {"asset_id": "91609514063242777856043730063938310894548353925882406409927495687846407164056", "price": "0.89", "size": "200", "side": "SELL", "hash": "061be3d0b7bc190870a5faf32fcfe357ff003484", "best_bid": "0.31", "best_ask": "0.33"}], "timestamp": "1769384757397", "event_type": "price_change"}}
{"_local_timestamp": "2026-01-25T23:46:04.650822+00:00", "data": {"market": "0xa9c0c820fd79b4339ed4711288ce15236196a6015234350f42b37341e9094398", "price_changes": [{"asset_id": "91609514063242777856043730063938310894548353925882406409927495687846407164056", "price": "0.01", "size": "15275.55", "side": "BUY", "hash": "8b34d4aeb3a2d9d42a900570074878f2ded7d7cd", "best_bid": "0.31", "best_ask": "0.33"}, {"asset_id": "78438315737001038193507108078052969359305687599144926740526502005681502958823", "price": "0.99", "size": "15275.55", "side": "SELL", "hash": "22fd2aa7e9466e11e7e8836f8cc8cd7cb5fe05b1", "best_bid": "0.67", "best_ask": "0.69"}], "timestamp": "1769384764572", "event_type": "price_change"}}
{"_local_timestamp": "2026-01-25T23:46:04.732529+00:00", "data": {"market": "0xa9c0c820fd79b4339ed4711288ce15236196a6015234350f42b37341e9094398", "price_changes": [{"asset_id": "91609514063242777856043730063938310894548353925882406409927495687846407164056", "price": "0.02", "size": "3255.32", "side": "BUY", "hash": "be62304d6e2cc1c9d79b9a3dc2b8941afc6e9564", "best_bid": "0.31", "best_ask": "0.33"}, {"asset_id": "78438315737001038193507108078052969359305687599144926740526502005681502958823", "price": "0.98", "size": "3255.32", "side": "SELL", "hash": "66f98cee404fcfbf7b39e22756d53028e9b299cf", "best_bid": "0.67", "best_ask": "0.69"}], "timestamp": "1769384764654", "event_type": "price_change"}}
{"_local_timestamp": "2026-01-25T23:46:08.629301+00:00", "data": {"market": "0xa9c0c820fd79b4339ed4711288ce15236196a6015234350f42b37341e9094398", "price_changes": [{"asset_id": "78438315737001038193507108078052969359305687599144926740526502005681502958823", "price": "0.11", "size": "0", "side": "BUY", "hash": "0cd30d82074eae4f9b9627d55293257b7922163c", "best_bid": "0.67", "best_ask": "0.69"}, {"asset_id": "91609514063242777856043730063938310894548353925882406409927495687846407164056", "price": "0.89", "size": "0", "side": "SELL", "hash": "3cabc2cc16b9aaa8df9d17ea0627d10213aee389", "best_bid": "0.31", "best_ask": "0.33"}], "timestamp": "1769384768556", "event_type": "price_change"}}
{"_local_timestamp": "2026-01-25T23:46:08.917551+00:00", "data": {"market": "0xa9c0c820fd79b4339ed4711288ce15236196a6015234350f42b37341e9094398", "price_changes": [{"asset_id": "78438315737001038193507108078052969359305687599144926740526502005681502958823", "price": "0.14", "size": "450", "side": "BUY", "hash": "811b6dbcc1fc0fd7e129a2de8c078646cc076bc9", "best_bid": "0.67", "best_ask": "0.69"}, {"asset_id": "91609514063242777856043730063938310894548353925882406409927495687846407164056", "price": "0.86", "size": "450", "side": "SELL", "hash": "2043301a69f103efe4570836f6ca0429d8339ba4", "best_bid": "0.31", "best_ask": "0.33"}], "timestamp": "1769384768837", "event_type": "price_change"}}
{"_local_timestamp": "2026-01-25T23:46:08.969969+00:00", "data": {"market": "0xa9c0c820fd79b4339ed4711288ce15236196a6015234350f42b37341e9094398", "price_changes": [{"asset_id": "78438315737001038193507108078052969359305687599144926740526502005681502958823", "price": "0.14", "size": "250", "side": "BUY", "hash": "e898a90e78d722c89251232166dce40e39387eb8", "best_bid": "0.67", "best_ask": "0.69"}, {"asset_id": "91609514063242777856043730063938310894548353925882406409927495687846407164056", "price": "0.86", "size": "250", "side": "SELL", "hash": "1bf8d47a815513cccb8b51165a91b83138d9d304", "best_bid": "0.31", "best_ask": "0.33"}], "timestamp": "1769384768904", "event_type": "price_change"}}
{"_local_timestamp": "2026-01-25T23:46:08.989562+00:00", "data": {"market": "0xa9c0c820fd79b4339ed4711288ce15236196a6015234350f42b37341e9094398", "price_changes": [{"asset_id": "78438315737001038193507108078052969359305687599144926740526502005681502958823", "price": "0.15", "size": "200", "side": "BUY", "hash": "2c6519049c3630defd7c7ae371814ae85de3a360", "best_bid": "0.67", "best_ask": "0.69"}, {"asset_id": "91609514063242777856043730063938310894548353925882406409927495687846407164056", "price": "0.85", "size": "200", "side": "SELL", "hash": "b45cc792a06775f709df0e49eeed53856046d7e5", "best_bid": "0.31", "best_ask": "0.33"}], "timestamp": "1769384768906", "event_type": "price_change"}}
{"_local_timestamp": "2026-01-25T23:46:20.809530+00:00", "data": {"market": "0xa9c0c820fd79b4339ed4711288ce15236196a6015234350f42b37341e9094398", "price_changes": [{"asset_id": "78438315737001038193507108078052969359305687599144926740526502005681502958823", "price": "0.14", "size": "50", "side": "BUY", "hash": "b26034253926ae4957ebe06115866ffddd2833d0", "best_bid": "0.67", "best_ask": "0.69"}, {"asset_id": "91609514063242777856043730063938310894548353925882406409927495687846407164056", "price": "0.86", "size": "50", "side": "SELL", "hash": "cf5b8a25f2cd5a5afc851e9cca03d4ba3fba548b", "best_bid": "0.31", "best_ask": "0.33"}], "timestamp": "1769384780745", "event_type": "price_change"}}
{"_local_timestamp": "2026-01-25T23:46:20.853585+00:00", "data": {"market": "0xa9c0c820fd79b4339ed4711288ce15236196a6015234350f42b37341e9094398", "price_changes": [{"asset_id": "78438315737001038193507108078052969359305687599144926740526502005681502958823", "price": "0.15", "size": "0", "side": "BUY", "hash": "7e755d030450b841031245dbf1debdbeeed5dccd", "best_bid": "0.67", "best_ask": "0.69"}, {"asset_id": "91609514063242777856043730063938310894548353925882406409927495687846407164056", "price": "0.85", "size": "0", "side": "SELL", "hash": "1213c582e0740b253abdf820266f07752a17df31", "best_bid": "0.31", "best_ask": "0.33"}], "timestamp": "1769384780783", "event_type": "price_change"}}
{"_local_timestamp": "2026-01-25T23:46:20.854865+00:00", "data": {"market": "0xa9c0c820fd79b4339ed4711288ce15236196a6015234350f42b37341e9094398", "price_changes": [{"asset_id": "78438315737001038193507108078052969359305687599144926740526502005681502958823", "price": "0.14", "size": "250", "side": "BUY", "hash": "8acb6d96604ef105b2b115b8d0062387f4a7c96a", "best_bid": "0.67", "best_ask": "0.69"}, {"asset_id": "91609514063242777856043730063938310894548353925882406409927495687846407164056", "price": "0.86", "size": "250", "side": "SELL", "hash": "4a655d9db0083a781978498a47f8877efd76fdd9", "best_bid": "0.31", "best_ask": "0.33"}], "timestamp": "1769384780789", "event_type": "price_change"}}
{"_local_timestamp": "2026-01-25T23:46:21.182765+00:00", "data": {"market": "0xa9c0c820fd79b4339ed4711288ce15236196a6015234350f42b37341e9094398", "price_changes": [{"asset_id": "78438315737001038193507108078052969359305687599144926740526502005681502958823", "price": "0.15", "size": "200", "side": "BUY", "hash": "d073230d291d1af7cc53cb761c165e6d3638ba40", "best_bid": "0.67", "best_ask": "0.69"}, {"asset_id": "91609514063242777856043730063938310894548353925882406409927495687846407164056", "price": "0.85", "size": "200", "side": "SELL", "hash": "7f60fa5519c32467f46e4091e5c80e90c500f59f", "best_bid": "0.31", "best_ask": "0.33"}], "timestamp": "1769384781026", "event_type": "price_change"}}
{"_local_timestamp": "2026-01-25T23:46:22.847560+00:00", "data": {"market": "0xa9c0c820fd79b4339ed4711288ce15236196a6015234350f42b37341e9094398", "price_changes": [{"asset_id": "78438315737001038193507108078052969359305687599144926740526502005681502958823", "price": "0.16", "size": "200", "side": "BUY", "hash": "e46c181982b6dd2ebc2b715a3f222eb0898262e5", "best_bid": "0.67", "best_ask": "0.69"}, {"asset_id": "91609514063242777856043730063938310894548353925882406409927495687846407164056", "price": "0.84", "size": "200", "side": "SELL", "hash": "15abd1e9bb4349925c8273eba65fc7fafc664e6b", "best_bid": "0.31", "best_ask": "0.33"}], "timestamp": "1769384782786", "event_type": "price_change"}}
{"_local_timestamp": "2026-01-25T23:46:22.853088+00:00", "data": {"market": "0xa9c0c820fd79b4339ed4711288ce15236196a6015234350f42b37341e9094398", "price_changes": [{"asset_id": "78438315737001038193507108078052969359305687599144926740526502005681502958823", "price": "0.14", "size": "50", "side": "BUY", "hash": "6db8286d6fb56a6480068118a95781a77329559f", "best_bid": "0.67", "best_ask": "0.69"}, {"asset_id": "91609514063242777856043730063938310894548353925882406409927495687846407164056", "price": "0.86", "size": "50", "side": "SELL", "hash": "a7ecc3d80e59f2f78f8ef96b0ba444408234239e", "best_bid": "0.31", "best_ask": "0.33"}], "timestamp": "1769384782787", "event_type": "price_change"}}
{"_local_timestamp": "2026-01-25T23:46:33.013343+00:00", "data": {"market": "0xa9c0c820fd79b4339ed4711288ce15236196a6015234350f42b37341e9094398", "price_changes": [{"asset_id": "78438315737001038193507108078052969359305687599144926740526502005681502958823", "price": "0.15", "size": "0", "side": "BUY", "hash": "81451ac42e8c98c96e39ddda939137413a802719", "best_bid": "0.67", "best_ask": "0.69"}, {"asset_id": "91609514063242777856043730063938310894548353925882406409927495687846407164056", "price": "0.85", "size": "0", "side": "SELL", "hash": "d8b975abcee929d97bf61d5053894fbb27137891", "best_bid": "0.31", "best_ask": "0.33"}], "timestamp": "1769384792933", "event_type": "price_change"}}
{"_local_timestamp": "2026-01-25T23:46:33.047090+00:00", "data": {"market": "0xa9c0c820fd79b4339ed4711288ce15236196a6015234350f42b37341e9094398", "price_changes": [{"asset_id": "78438315737001038193507108078052969359305687599144926740526502005681502958823", "price": "0.16", "size": "0", "side": "BUY", "hash": "5486b3b70d97ab4368c4a6f253745b636ff47894", "best_bid": "0.67", "best_ask": "0.69"}, {"asset_id": "91609514063242777856043730063938310894548353925882406409927495687846407164056", "price": "0.84", "size": "0", "side": "SELL", "hash": "58b19b545188014903eaff43fe3150fcb3570cee", "best_bid": "0.31", "best_ask": "0.33"}], "timestamp": "1769384792976", "event_type": "price_change"}}
{"_local_timestamp": "2026-01-25T23:46:33.055953+00:00", "data": {"market": "0xa9c0c820fd79b4339ed4711288ce15236196a6015234350f42b37341e9094398", "price_changes": [{"asset_id": "78438315737001038193507108078052969359305687599144926740526502005681502958823", "price": "0.14", "size": "250", "side": "BUY", "hash": "ad28e64142acec43eef6fea3af2201b507d3f103", "best_bid": "0.67", "best_ask": "0.69"}, {"asset_id": "91609514063242777856043730063938310894548353925882406409927495687846407164056", "price": "0.86", "size": "250", "side": "SELL", "hash": "073197399282d1a9ed98151317471ea10d0b3027", "best_bid": "0.31", "best_ask": "0.33"}], "timestamp": "1769384792976", "event_type": "price_change"}}
{"_local_timestamp": "2026-01-25T23:46:33.270661+00:00", "data": {"market": "0xa9c0c820fd79b4339ed4711288ce15236196a6015234350f42b37341e9094398", "price_changes": [{"asset_id": "78438315737001038193507108078052969359305687599144926740526502005681502958823", "price": "0.11", "size": "200", "side": "BUY", "hash": "4a76c48facbf5a4690402770ad3120eb52d72436", "best_bid": "0.67", "best_ask": "0.69"}, {"asset_id": "91609514063242777856043730063938310894548353925882406409927495687846407164056", "price": "0.89", "size": "200", "side": "SELL", "hash": "f2eb69c6a951fbcd00dc8b9a4566f64b9447ebeb", "best_bid": "0.31", "best_ask": "0.33"}], "timestamp": "1769384793186", "event_type": "price_change"}}
{"_local_timestamp": "2026-01-25T23:46:43.502192+00:00", "data": {"market": "0xa9c0c820fd79b4339ed4711288ce15236196a6015234350f42b37341e9094398", "price_changes": [{"asset_id": "78438315737001038193507108078052969359305687599144926740526502005681502958823", "price": "0.11", "size": "0", "side": "BUY", "hash": "92ef1ecbc3077d99c714e9501730f4cb6be238df", "best_bid": "0.67", "best_ask": "0.69"}, {"asset_id": "91609514063242777856043730063938310894548353925882406409927495687846407164056", "price": "0.89", "size": "0", "side": "SELL", "hash": "98210e8be8b35b2d7dfe932059a94f1d5edda844", "best_bid": "0.31", "best_ask": "0.33"}], "timestamp": "1769384803330", "event_type": "price_change"}}
{"_local_timestamp": "2026-01-25T23:46:43.730476+00:00", "data": {"market": "0xa9c0c820fd79b4339ed4711288ce15236196a6015234350f42b37341e9094398", "price_changes": [{"asset_id": "78438315737001038193507108078052969359305687599144926740526502005681502958823", "price": "0.14", "size": "450", "side": "BUY", "hash": "80e031755aa53c3c212e6104d8066b14eeb3fce0", "best_bid": "0.67", "best_ask": "0.69"}, {"asset_id": "91609514063242777856043730063938310894548353925882406409927495687846407164056", "price": "0.86", "size": "450", "side": "SELL", "hash": "bd2de50edd49490622da00930f4138dc69e849b3", "best_bid": "0.31", "best_ask": "0.33"}], "timestamp": "1769384803585", "event_type": "price_change"}}
{"_local_timestamp": "2026-01-25T23:46:43.785526+00:00", "data": {"market": "0xa9c0c820fd79b4339ed4711288ce15236196a6015234350f42b37341e9094398", "price_changes": [{"asset_id": "78438315737001038193507108078052969359305687599144926740526502005681502958823", "price": "0.15", "size": "200", "side": "BUY", "hash": "2e0100726c3c6f724a6c6b931a26f444b93998ef", "best_bid": "0.67", "best_ask": "0.69"}, {"asset_id": "91609514063242777856043730063938310894548353925882406409927495687846407164056", "price": "0.85", "size": "200", "side": "SELL", "hash": "e4cbcaf4a3c3b72ecd4a5077a25f2ab7fbd39b74", "best_bid": "0.31", "best_ask": "0.33"}], "timestamp": "1769384803694", "event_type": "price_change"}}
{"_local_timestamp": "2026-01-25T23:46:43.786876+00:00", "data": {"market": "0xa9c0c820fd79b4339ed4711288ce15236196a6015234350f42b37341e9094398", "price_changes": [{"asset_id": "78438315737001038193507108078052969359305687599144926740526502005681502958823", "price": "0.14", "size": "250", "side": "BUY", "hash": "7518f0ce3c9e69cb0981e618e834643c83df736e", "best_bid": "0.67", "best_ask": "0.69"}, {"asset_id": "91609514063242777856043730063938310894548353925882406409927495687846407164056", "price": "0.86", "size": "250", "side": "SELL", "hash": "98dd4772909c7305f8c5b24161826c6d9e9b084d", "best_bid": "0.31", "best_ask": "0.33"}], "timestamp": "1769384803695", "event_type": "price_change"}}
{"_local_timestamp": "2026-01-25T23:46:54.085503+00:00", "data": {"market": "0xa9c0c820fd79b4339ed4711288ce15236196a6015234350f42b37341e9094398", "price_changes": [{"asset_id": "78438315737001038193507108078052969359305687599144926740526502005681502958823", "price": "0.14", "size": "50", "side": "BUY", "hash": "4be77bfc0c134fac61536e6d84d5542eee72043b", "best_bid": "0.67", "best_ask": "0.69"}, {"asset_id": "91609514063242777856043730063938310894548353925882406409927495687846407164056", "price": "0.86", "size": "50", "side": "SELL", "hash": "a205aec7b60ff675f3f4849bc7a555b7eb5a6671", "best_bid": "0.31", "best_ask": "0.33"}], "timestamp": "1769384814022", "event_type": "price_change"}}
{"_local_timestamp": "2026-01-25T23:46:54.142745+00:00", "data": {"market": "0xa9c0c820fd79b4339ed4711288ce15236196a6015234350f42b37341e9094398", "price_changes": [{"asset_id": "78438315737001038193507108078052969359305687599144926740526502005681502958823", "price": "0.14", "size": "250", "side": "BUY", "hash": "aebf99f4a931e025105ccabb837321bcf0c98f34", "best_bid": "0.67", "best_ask": "0.69"}, {"asset_id": "91609514063242777856043730063938310894548353925882406409927495687846407164056", "price": "0.86", "size": "250", "side": "SELL", "hash": "cc7747063cd85c3693f567ffa7abf681718e80fe", "best_bid": "0.31", "best_ask": "0.33"}], "timestamp": "1769384814059", "event_type": "price_change"}}
{"_local_timestamp": "2026-01-25T23:46:54.143866+00:00", "data": {"market": "0xa9c0c820fd79b4339ed4711288ce15236196a6015234350f42b37341e9094398", "price_changes": [{"asset_id": "78438315737001038193507108078052969359305687599144926740526502005681502958823", "price": "0.15", "size": "0", "side": "BUY", "hash": "18809eabea5a301bbeeea786ee6448af9ca831b6", "best_bid": "0.67", "best_ask": "0.69"}, {"asset_id": "91609514063242777856043730063938310894548353925882406409927495687846407164056", "price": "0.85", "size": "0", "side": "SELL", "hash": "a7f15a610eed6ecab274efb65986cede424f1a42", "best_bid": "0.31", "best_ask": "0.33"}], "timestamp": "1769384814060", "event_type": "price_change"}}
{"_local_timestamp": "2026-01-25T23:46:54.347703+00:00", "data": {"market": "0xa9c0c820fd79b4339ed4711288ce15236196a6015234350f42b37341e9094398", "price_changes": [{"asset_id": "78438315737001038193507108078052969359305687599144926740526502005681502958823", "price": "0.15", "size": "200", "side": "BUY", "hash": "f5186f2e19e688cd8640f6dded6a300e1b9dbec1", "best_bid": "0.67", "best_ask": "0.69"}, {"asset_id": "91609514063242777856043730063938310894548353925882406409927495687846407164056", "price": "0.85", "size": "200", "side": "SELL", "hash": "eae9811e0fde2a8ae78a2fb7c7709d06b409e77e", "best_bid": "0.31", "best_ask": "0.33"}], "timestamp": "1769384814275", "event_type": "price_change"}}
{"_local_timestamp": "2026-01-25T23:46:56.124005+00:00", "data": {"market": "0xa9c0c820fd79b4339ed4711288ce15236196a6015234350f42b37341e9094398", "price_changes": [{"asset_id": "78438315737001038193507108078052969359305687599144926740526502005681502958823", "price": "0.16", "size": "200", "side": "BUY", "hash": "ba0d4544206cacac38547bc2b0dbf83bb62564e3", "best_bid": "0.67", "best_ask": "0.69"}, {"asset_id": "91609514063242777856043730063938310894548353925882406409927495687846407164056", "price": "0.84", "size": "200", "side": "SELL", "hash": "e756c92caddf243bf5d973dacc2d61098521fc9b", "best_bid": "0.31", "best_ask": "0.33"}], "timestamp": "1769384816059", "event_type": "price_change"}}
{"_local_timestamp": "2026-01-25T23:46:56.128014+00:00", "data": {"market": "0xa9c0c820fd79b4339ed4711288ce15236196a6015234350f42b37341e9094398", "price_changes": [{"asset_id": "78438315737001038193507108078052969359305687599144926740526502005681502958823", "price": "0.14", "size": "50", "side": "BUY", "hash": "1bc210ef0b1eda2bbe0af34b94453ec184ac942f", "best_bid": "0.67", "best_ask": "0.69"}, {"asset_id": "91609514063242777856043730063938310894548353925882406409927495687846407164056", "price": "0.86", "size": "50", "side": "SELL", "hash": "78169ac31705399f29ad78ab8641bb7f96e55dc0", "best_bid": "0.31", "best_ask": "0.33"}], "timestamp": "1769384816061", "event_type": "price_change"}}
{"_local_timestamp": "2026-01-25T23:47:05.538942+00:00", "data": {"market": "0xa9c0c820fd79b4339ed4711288ce15236196a6015234350f42b37341e9094398", "price_changes": [{"asset_id": "78438315737001038193507108078052969359305687599144926740526502005681502958823", "price": "0.15", "size": "0", "side": "BUY", "hash": "4ee810825eee9411fa36ccdaf9c068f244fbbeb3", "best_bid": "0.67", "best_ask": "0.69"}, {"asset_id": "91609514063242777856043730063938310894548353925882406409927495687846407164056", "price": "0.85", "size": "0", "side": "SELL", "hash": "324fc818bae737bf98065b09835e8e41e01fd300", "best_bid": "0.31", "best_ask": "0.33"}], "timestamp": "1769384825463", "event_type": "price_change"}}
{"_local_timestamp": "2026-01-25T23:47:05.571832+00:00", "data": {"market": "0xa9c0c820fd79b4339ed4711288ce15236196a6015234350f42b37341e9094398", "price_changes": [{"asset_id": "78438315737001038193507108078052969359305687599144926740526502005681502958823", "price": "0.16", "size": "0", "side": "BUY", "hash": "889951d9009aedf2bb2f2ac2562c75cab2524625", "best_bid": "0.67", "best_ask": "0.69"}, {"asset_id": "91609514063242777856043730063938310894548353925882406409927495687846407164056", "price": "0.84", "size": "0", "side": "SELL", "hash": "a016efa175c8ccca7a88cdd91fbe6701348fccd6", "best_bid": "0.31", "best_ask": "0.33"}], "timestamp": "1769384825500", "event_type": "price_change"}}
{"_local_timestamp": "2026-01-25T23:47:05.577605+00:00", "data": {"market": "0xa9c0c820fd79b4339ed4711288ce15236196a6015234350f42b37341e9094398", "price_changes": [{"asset_id": "78438315737001038193507108078052969359305687599144926740526502005681502958823", "price": "0.14", "size": "250", "side": "BUY", "hash": "892408850b3d643065061d68b4dc1e7ed08dd2f3", "best_bid": "0.67", "best_ask": "0.69"}, {"asset_id": "91609514063242777856043730063938310894548353925882406409927495687846407164056", "price": "0.86", "size": "250", "side": "SELL", "hash": "1c7b30bdd80cbeb4adc1fbcf3b87600f95b13e0e", "best_bid": "0.31", "best_ask": "0.33"}], "timestamp": "1769384825506", "event_type": "price_change"}}
{"_local_timestamp": "2026-01-25T23:47:05.810398+00:00", "data": {"market": "0xa9c0c820fd79b4339ed4711288ce15236196a6015234350f42b37341e9094398", "price_changes": [{"asset_id": "78438315737001038193507108078052969359305687599144926740526502005681502958823", "price": "0.11", "size": "200", "side": "BUY", "hash": "4ec52bdae4eb0a6c889d73915569ea4be4950cb5", "best_bid": "0.67", "best_ask": "0.69"}, {"asset_id": "91609514063242777856043730063938310894548353925882406409927495687846407164056", "price": "0.89", "size": "200", "side": "SELL", "hash": "9ec7627dad62f91a9c756c6cd4e8f3cf56264e23", "best_bid": "0.31", "best_ask": "0.33"}], "timestamp": "1769384825733", "event_type": "price_change"}}
{"_local_timestamp": "2026-01-25T23:47:17.146044+00:00", "data": {"market": "0xa9c0c820fd79b4339ed4711288ce15236196a6015234350f42b37341e9094398", "price_changes": [{"asset_id": "78438315737001038193507108078052969359305687599144926740526502005681502958823", "price": "0.11", "size": "0", "side": "BUY", "hash": "e88861c8cc358a7e9af2823b5150f0ba4f002164", "best_bid": "0.67", "best_ask": "0.69"}, {"asset_id": "91609514063242777856043730063938310894548353925882406409927495687846407164056", "price": "0.89", "size": "0", "side": "SELL", "hash": "65a8c4cd19b797b4c29e3b10f4c6a218297f038c", "best_bid": "0.31", "best_ask": "0.33"}], "timestamp": "1769384837078", "event_type": "price_change"}}
{"_local_timestamp": "2026-01-25T23:47:17.433142+00:00", "data": {"market": "0xa9c0c820fd79b4339ed4711288ce15236196a6015234350f42b37341e9094398", "price_changes": [{"asset_id": "78438315737001038193507108078052969359305687599144926740526502005681502958823", "price": "0.14", "size": "450", "side": "BUY", "hash": "905672d86112a9f682641bddc4ea0253a31b4753", "best_bid": "0.67", "best_ask": "0.69"}, {"asset_id": "91609514063242777856043730063938310894548353925882406409927495687846407164056", "price": "0.86", "size": "450", "side": "SELL", "hash": "5dcc38047d0f42ff1d7163101ab0a25b76c8d987", "best_bid": "0.31", "best_ask": "0.33"}], "timestamp": "1769384837363", "event_type": "price_change"}}
{"_local_timestamp": "2026-01-25T23:47:17.467109+00:00", "data": {"market": "0xa9c0c820fd79b4339ed4711288ce15236196a6015234350f42b37341e9094398", "price_changes": [{"asset_id": "78438315737001038193507108078052969359305687599144926740526502005681502958823", "price": "0.15", "size": "200", "side": "BUY", "hash": "a022cbf15e4d659d168a28ac0ec5751c74495f30", "best_bid": "0.67", "best_ask": "0.69"}, {"asset_id": "91609514063242777856043730063938310894548353925882406409927495687846407164056", "price": "0.85", "size": "200", "side": "SELL", "hash": "df84c264f642c2e459dbeaf6c421f20cc44fb99c", "best_bid": "0.31", "best_ask": "0.33"}], "timestamp": "1769384837404", "event_type": "price_change"}}
{"_local_timestamp": "2026-01-25T23:47:17.468299+00:00", "data": {"market": "0xa9c0c820fd79b4339ed4711288ce15236196a6015234350f42b37341e9094398", "price_changes": [{"asset_id": "78438315737001038193507108078052969359305687599144926740526502005681502958823", "price": "0.14", "size": "250", "side": "BUY", "hash": "0ec1250c7ba4493c5b2e291174455cc68effd467", "best_bid": "0.67", "best_ask": "0.69"}, {"asset_id": "91609514063242777856043730063938310894548353925882406409927495687846407164056", "price": "0.86", "size": "250", "side": "SELL", "hash": "e864d0755303200cea851eecd3f9decc4744d5fe", "best_bid": "0.31", "best_ask": "0.33"}], "timestamp": "1769384837405", "event_type": "price_change"}}
{"_local_timestamp": "2026-01-25T23:47:17.912639+00:00", "data": {"market": "0xa9c0c820fd79b4339ed4711288ce15236196a6015234350f42b37341e9094398", "price_changes": [{"asset_id": "91609514063242777856043730063938310894548353925882406409927495687846407164056", "price": "0.34", "size": "0", "side": "SELL", "hash": "90ac6341104db606432a340c08bd920b0494137e", "best_bid": "0.31", "best_ask": "0.33"}, {"asset_id": "78438315737001038193507108078052969359305687599144926740526502005681502958823", "price": "0.66", "size": "0", "side": "BUY", "hash": "28e47643ab1f69b91fc2eeb4d796e59ff29aff9e", "best_bid": "0.67", "best_ask": "0.69"}], "timestamp": "1769384837830", "event_type": "price_change"}}
{"_local_timestamp": "2026-01-25T23:47:19.365635+00:00", "data": {"market": "0xa9c0c820fd79b4339ed4711288ce15236196a6015234350f42b37341e9094398", "price_changes": [{"asset_id": "91609514063242777856043730063938310894548353925882406409927495687846407164056", "price": "0.34", "size": "6.8", "side": "SELL", "hash": "9eab8f7c057df1480be8724f37b0cfbd8ec34c28", "best_bid": "0.31", "best_ask": "0.33"}, {"asset_id": "78438315737001038193507108078052969359305687599144926740526502005681502958823", "price": "0.66", "size": "6.8", "side": "BUY", "hash": "8d33fc1804fc1ba4895f2a86117f3b3b23799573", "best_bid": "0.67", "best_ask": "0.69"}], "timestamp": "1769384839150", "event_type": "price_change"}}
{"_local_timestamp": "2026-01-25T23:47:23.240269+00:00", "data": {"market": "0xa9c0c820fd79b4339ed4711288ce15236196a6015234350f42b37341e9094398", "price_changes": [{"asset_id": "91609514063242777856043730063938310894548353925882406409927495687846407164056", "price": "0.02", "size": "2255.32", "side": "BUY", "hash": "2c99130dffada33099946699a84ce87fd4864874", "best_bid": "0.31", "best_ask": "0.33"}, {"asset_id": "78438315737001038193507108078052969359305687599144926740526502005681502958823", "price": "0.98", "size": "2255.32", "side": "SELL", "hash": "3b7585ed0c05ce8ee753f627fe7ecff82e3e48a2", "best_bid": "0.67", "best_ask": "0.69"}], "timestamp": "1769384843174", "event_type": "price_change"}}
{"_local_timestamp": "2026-01-25T23:47:28.770130+00:00", "data": {"market": "0xa9c0c820fd79b4339ed4711288ce15236196a6015234350f42b37341e9094398", "price_changes": [{"asset_id": "78438315737001038193507108078052969359305687599144926740526502005681502958823", "price": "0.14", "size": "50", "side": "BUY", "hash": "c11646d61d34c59a98b91144b16665989cb1bcff", "best_bid": "0.67", "best_ask": "0.69"}, {"asset_id": "91609514063242777856043730063938310894548353925882406409927495687846407164056", "price": "0.86", "size": "50", "side": "SELL", "hash": "d3d6e02402451d7bb64028b6da2c8097448ef588", "best_bid": "0.31", "best_ask": "0.33"}], "timestamp": "1769384848703", "event_type": "price_change"}}
{"_local_timestamp": "2026-01-25T23:47:28.806339+00:00", "data": {"market": "0xa9c0c820fd79b4339ed4711288ce15236196a6015234350f42b37341e9094398", "price_changes": [{"asset_id": "78438315737001038193507108078052969359305687599144926740526502005681502958823", "price": "0.15", "size": "0", "side": "BUY", "hash": "065e39f60ffe4f89ee4768d225238e35c718252b", "best_bid": "0.67", "best_ask": "0.69"}, {"asset_id": "91609514063242777856043730063938310894548353925882406409927495687846407164056", "price": "0.85", "size": "0", "side": "SELL", "hash": "96cb6658012a0eec1fc399a331f4dd0979cf7475", "best_bid": "0.31", "best_ask": "0.33"}], "timestamp": "1769384848738", "event_type": "price_change"}}
{"_local_timestamp": "2026-01-25T23:47:28.807453+00:00", "data": {"market": "0xa9c0c820fd79b4339ed4711288ce15236196a6015234350f42b37341e9094398", "price_changes": [{"asset_id": "78438315737001038193507108078052969359305687599144926740526502005681502958823", "price": "0.14", "size": "250", "side": "BUY", "hash": "4b5248e69d4598ad8f03124e3354c4447b909057", "best_bid": "0.67", "best_ask": "0.69"}, {"asset_id": "91609514063242777856043730063938310894548353925882406409927495687846407164056", "price": "0.86", "size": "250", "side": "SELL", "hash": "1739b7f9b873f87ada9818bc50bd1c12c46702c6", "best_bid": "0.31", "best_ask": "0.33"}], "timestamp": "1769384848742", "event_type": "price_change"}}
{"_local_timestamp": "2026-01-25T23:47:29.047120+00:00", "data": {"market": "0xa9c0c820fd79b4339ed4711288ce15236196a6015234350f42b37341e9094398", "price_changes": [{"asset_id": "78438315737001038193507108078052969359305687599144926740526502005681502958823", "price": "0.15", "size": "200", "side": "BUY", "hash": "b35d015cd54720a82107cf8afef6d789e0393a06", "best_bid": "0.67", "best_ask": "0.69"}, {"asset_id": "91609514063242777856043730063938310894548353925882406409927495687846407164056", "price": "0.85", "size": "200", "side": "SELL", "hash": "d24fc7e0147948eb3229bd3fd00363ef49858adf", "best_bid": "0.31", "best_ask": "0.33"}], "timestamp": "1769384848964", "event_type": "price_change"}}
{"_local_timestamp": "2026-01-25T23:47:30.811340+00:00", "data": {"market": "0xa9c0c820fd79b4339ed4711288ce15236196a6015234350f42b37341e9094398", "price_changes": [{"asset_id": "78438315737001038193507108078052969359305687599144926740526502005681502958823", "price": "0.14", "size": "50", "side": "BUY", "hash": "794779d23e80281bb4164fc3ffb9a6de988da1b6", "best_bid": "0.67", "best_ask": "0.69"}, {"asset_id": "91609514063242777856043730063938310894548353925882406409927495687846407164056", "price": "0.86", "size": "50", "side": "SELL", "hash": "7451e60f120a3eef0edfa196097e2766f097acf9", "best_bid": "0.31", "best_ask": "0.33"}], "timestamp": "1769384850740", "event_type": "price_change"}}
{"_local_timestamp": "2026-01-25T23:47:30.812497+00:00", "data": {"market": "0xa9c0c820fd79b4339ed4711288ce15236196a6015234350f42b37341e9094398", "price_changes": [{"asset_id": "78438315737001038193507108078052969359305687599144926740526502005681502958823", "price": "0.16", "size": "200", "side": "BUY", "hash": "9502fcbf056ebc182a3a1d85e7b925c27ad5034d", "best_bid": "0.67", "best_ask": "0.69"}, {"asset_id": "91609514063242777856043730063938310894548353925882406409927495687846407164056", "price": "0.84", "size": "200", "side": "SELL", "hash": "3a1694f0322cde2cdacec0000052be7c241cc2ae", "best_bid": "0.31", "best_ask": "0.33"}], "timestamp": "1769384850743", "event_type": "price_change"}}
{"_local_timestamp": "2026-01-25T23:47:39.682692+00:00", "data": {"market": "0xa9c0c820fd79b4339ed4711288ce15236196a6015234350f42b37341e9094398", "price_changes": [{"asset_id": "78438315737001038193507108078052969359305687599144926740526502005681502958823", "price": "0.07", "size": "3799.11", "side": "BUY", "hash": "95e672db68c5b5ac8a1e25b2fa33fe3f3d6eb3ea", "best_bid": "0.67", "best_ask": "0.69"}, {"asset_id": "91609514063242777856043730063938310894548353925882406409927495687846407164056", "price": "0.93", "size": "3799.11", "side": "SELL", "hash": "78f4a958fd6765d0b87848cec5b131d6d9c5465c", "best_bid": "0.31", "best_ask": "0.33"}], "timestamp": "1769384859608", "event_type": "price_change"}}
{"_local_timestamp": "2026-01-25T23:47:39.683817+00:00", "data": {"market": "0xa9c0c820fd79b4339ed4711288ce15236196a6015234350f42b37341e9094398", "price_changes": [{"asset_id": "78438315737001038193507108078052969359305687599144926740526502005681502958823", "price": "0.15", "size": "0", "side": "BUY", "hash": "95e672db68c5b5ac8a1e25b2fa33fe3f3d6eb3ea", "best_bid": "0.67", "best_ask": "0.69"}, {"asset_id": "91609514063242777856043730063938310894548353925882406409927495687846407164056", "price": "0.85", "size": "0", "side": "SELL", "hash": "78f4a958fd6765d0b87848cec5b131d6d9c5465c", "best_bid": "0.31", "best_ask": "0.33"}], "timestamp": "1769384859608", "event_type": "price_change"}}
{"_local_timestamp": "2026-01-25T23:47:39.727407+00:00", "data": {"market": "0xa9c0c820fd79b4339ed4711288ce15236196a6015234350f42b37341e9094398", "price_changes": [{"asset_id": "78438315737001038193507108078052969359305687599144926740526502005681502958823", "price": "0.16", "size": "0", "side": "BUY", "hash": "752cd80f86a855ad8b80d046dcde05534f4247de", "best_bid": "0.67", "best_ask": "0.69"}, {"asset_id": "91609514063242777856043730063938310894548353925882406409927495687846407164056", "price": "0.84", "size": "0", "side": "SELL", "hash": "cef993741027a1dbc245de9fe6ccd3049c46323b", "best_bid": "0.31", "best_ask": "0.33"}], "timestamp": "1769384859657", "event_type": "price_change"}}
{"_local_timestamp": "2026-01-25T23:47:39.728543+00:00", "data": {"market": "0xa9c0c820fd79b4339ed4711288ce15236196a6015234350f42b37341e9094398", "price_changes": [{"asset_id": "78438315737001038193507108078052969359305687599144926740526502005681502958823", "price": "0.14", "size": "250", "side": "BUY", "hash": "6712eb0a30ef322083ca76579a40028db6878fff", "best_bid": "0.67", "best_ask": "0.69"}, {"asset_id": "91609514063242777856043730063938310894548353925882406409927495687846407164056", "price": "0.86", "size": "250", "side": "SELL", "hash": "194f6437f95654c2ae5c1411df7217ec32e9a76e", "best_bid": "0.31", "best_ask": "0.33"}], "timestamp": "1769384859661", "event_type": "price_change"}}
{"_local_timestamp": "2026-01-25T23:47:39.922682+00:00", "data": {"market": "0xa9c0c820fd79b4339ed4711288ce15236196a6015234350f42b37341e9094398", "price_changes": [{"asset_id": "78438315737001038193507108078052969359305687599144926740526502005681502958823", "price": "0.09", "size": "450", "side": "BUY", "hash": "69fec7655403555343e998446a228abe189836f2", "best_bid": "0.67", "best_ask": "0.69"}, {"asset_id": "91609514063242777856043730063938310894548353925882406409927495687846407164056", "price": "0.91", "size": "450", "side": "SELL", "hash": "d3983b2c8a1afb705526596bc1952cd9aa6fee2e", "best_bid": "0.31", "best_ask": "0.33"}], "timestamp": "1769384859856", "event_type": "price_change"}}
{"_local_timestamp": "2026-01-25T23:47:39.923841+00:00", "data": {"market": "0xa9c0c820fd79b4339ed4711288ce15236196a6015234350f42b37341e9094398", "price_changes": [{"asset_id": "78438315737001038193507108078052969359305687599144926740526502005681502958823", "price": "0.11", "size": "200", "side": "BUY", "hash": "fb21a666d8d351f77bba8b3af5fa1ecad4cc939d", "best_bid": "0.67", "best_ask": "0.69"}, {"asset_id": "91609514063242777856043730063938310894548353925882406409927495687846407164056", "price": "0.89", "size": "200", "side": "SELL", "hash": "b33d2644c0b39e9f46d1482f585411dbf1b68e89", "best_bid": "0.31", "best_ask": "0.33"}], "timestamp": "1769384859857", "event_type": "price_change"}}
{"_local_timestamp": "2026-01-25T23:47:50.041909+00:00", "data": {"market": "0xa9c0c820fd79b4339ed4711288ce15236196a6015234350f42b37341e9094398", "price_changes": [{"asset_id": "78438315737001038193507108078052969359305687599144926740526502005681502958823", "price": "0.09", "size": "250", "side": "BUY", "hash": "bfd0c989fabf3ca8cc810191115fa1e2406d07e9", "best_bid": "0.67", "best_ask": "0.69"}, {"asset_id": "91609514063242777856043730063938310894548353925882406409927495687846407164056", "price": "0.91", "size": "250", "side": "SELL", "hash": "e00d78516250160e3a9da8c9ee408f6fed78d6e0", "best_bid": "0.31", "best_ask": "0.33"}], "timestamp": "1769384869975", "event_type": "price_change"}}
{"_local_timestamp": "2026-01-25T23:47:50.043144+00:00", "data": {"market": "0xa9c0c820fd79b4339ed4711288ce15236196a6015234350f42b37341e9094398", "price_changes": [{"asset_id": "78438315737001038193507108078052969359305687599144926740526502005681502958823", "price": "0.11", "size": "0", "side": "BUY", "hash": "bfd0c989fabf3ca8cc810191115fa1e2406d07e9", "best_bid": "0.67", "best_ask": "0.69"}, {"asset_id": "91609514063242777856043730063938310894548353925882406409927495687846407164056", "price": "0.89", "size": "0", "side": "SELL", "hash": "e00d78516250160e3a9da8c9ee408f6fed78d6e0", "best_bid": "0.31", "best_ask": "0.33"}], "timestamp": "1769384869975", "event_type": "price_change"}}
{"_local_timestamp": "2026-01-25T23:47:50.307818+00:00", "data": {"market": "0xa9c0c820fd79b4339ed4711288ce15236196a6015234350f42b37341e9094398", "price_changes": [{"asset_id": "78438315737001038193507108078052969359305687599144926740526502005681502958823", "price": "0.14", "size": "450", "side": "BUY", "hash": "18e207c803b1cc8fe0daf4cac1b169ae75215c47", "best_bid": "0.67", "best_ask": "0.69"}, {"asset_id": "91609514063242777856043730063938310894548353925882406409927495687846407164056", "price": "0.86", "size": "450", "side": "SELL", "hash": "a7804ea11a1513c551639643e7dcad319c686e94", "best_bid": "0.31", "best_ask": "0.33"}], "timestamp": "1769384870243", "event_type": "price_change"}}
{"_local_timestamp": "2026-01-25T23:47:50.313556+00:00", "data": {"market": "0xa9c0c820fd79b4339ed4711288ce15236196a6015234350f42b37341e9094398", "price_changes": [{"asset_id": "78438315737001038193507108078052969359305687599144926740526502005681502958823", "price": "0.07", "size": "3999.11", "side": "BUY", "hash": "8a6e066a7acfab9d9a77f9271c1db201a4bc046a", "best_bid": "0.67", "best_ask": "0.69"}, {"asset_id": "91609514063242777856043730063938310894548353925882406409927495687846407164056", "price": "0.93", "size": "3999.11", "side": "SELL", "hash": "4e513ee1f0a15a865b9915df37b9dd65657415d4", "best_bid": "0.31", "best_ask": "0.33"}], "timestamp": "1769384870244", "event_type": "price_change"}}
{"_local_timestamp": "2026-01-25T23:47:50.346838+00:00", "data": {"market": "0xa9c0c820fd79b4339ed4711288ce15236196a6015234350f42b37341e9094398", "price_changes": [{"asset_id": "78438315737001038193507108078052969359305687599144926740526502005681502958823", "price": "0.14", "size": "250", "side": "BUY", "hash": "b493beeb5d1e977772d8581562d74172fd15599c", "best_bid": "0.67", "best_ask": "0.69"}, {"asset_id": "91609514063242777856043730063938310894548353925882406409927495687846407164056", "price": "0.86", "size": "250", "side": "SELL", "hash": "7184056415ddfc283abab00121cf158349b5b7d1", "best_bid": "0.31", "best_ask": "0.33"}], "timestamp": "1769384870278", "event_type": "price_change"}}
{"_local_timestamp": "2026-01-25T23:47:50.353782+00:00", "data": {"market": "0xa9c0c820fd79b4339ed4711288ce15236196a6015234350f42b37341e9094398", "price_changes": [{"asset_id": "78438315737001038193507108078052969359305687599144926740526502005681502958823", "price": "0.15", "size": "200", "side": "BUY", "hash": "aa4b5cd81dbfd5d1a282e526ef38e6758f0baf2f", "best_bid": "0.67", "best_ask": "0.69"}, {"asset_id": "91609514063242777856043730063938310894548353925882406409927495687846407164056", "price": "0.85", "size": "200", "side": "SELL", "hash": "be35fe2964bb25ed37bcc9be8341865cc3b067ef", "best_bid": "0.31", "best_ask": "0.33"}], "timestamp": "1769384870283", "event_type": "price_change"}}
{"_local_timestamp": "2026-01-25T23:48:01.873938+00:00", "data": {"market": "0xa9c0c820fd79b4339ed4711288ce15236196a6015234350f42b37341e9094398", "price_changes": [{"asset_id": "78438315737001038193507108078052969359305687599144926740526502005681502958823", "price": "0.14", "size": "50", "side": "BUY", "hash": "dd30cafea9dfd76f9ac2ba0dab329f790581ba82", "best_bid": "0.67", "best_ask": "0.69"}, {"asset_id": "91609514063242777856043730063938310894548353925882406409927495687846407164056", "price": "0.86", "size": "50", "side": "SELL", "hash": "08e692fa03cecc5d08e5d2d6347edc51a6021cd5", "best_bid": "0.31", "best_ask": "0.33"}], "timestamp": "1769384881804", "event_type": "price_change"}}
{"_local_timestamp": "2026-01-25T23:48:01.910515+00:00", "data": {"market": "0xa9c0c820fd79b4339ed4711288ce15236196a6015234350f42b37341e9094398", "price_changes": [{"asset_id": "78438315737001038193507108078052969359305687599144926740526502005681502958823", "price": "0.15", "size": "0", "side": "BUY", "hash": "64fcbf2869579d71be5bc616b4368b8851462d60", "best_bid": "0.67", "best_ask": "0.69"}, {"asset_id": "91609514063242777856043730063938310894548353925882406409927495687846407164056", "price": "0.85", "size": "0", "side": "SELL", "hash": "ba13f9cd2193a0920ef6e5b8b639294eb91e2227", "best_bid": "0.31", "best_ask": "0.33"}], "timestamp": "1769384881843", "event_type": "price_change"}}
{"_local_timestamp": "2026-01-25T23:48:01.911692+00:00", "data": {"market": "0xa9c0c820fd79b4339ed4711288ce15236196a6015234350f42b37341e9094398", "price_changes": [{"asset_id": "78438315737001038193507108078052969359305687599144926740526502005681502958823", "price": "0.14", "size": "250", "side": "BUY", "hash": "c6e810404bb3a023212b27b1c72010ac86b6c725", "best_bid": "0.67", "best_ask": "0.69"}, {"asset_id": "91609514063242777856043730063938310894548353925882406409927495687846407164056", "price": "0.86", "size": "250", "side": "SELL", "hash": "bb1f3bd494dd5550895c1fa226d2942d21de7c3d", "best_bid": "0.31", "best_ask": "0.33"}], "timestamp": "1769384881844", "event_type": "price_change"}}
{"_local_timestamp": "2026-01-25T23:48:02.146345+00:00", "data": {"market": "0xa9c0c820fd79b4339ed4711288ce15236196a6015234350f42b37341e9094398", "price_changes": [{"asset_id": "78438315737001038193507108078052969359305687599144926740526502005681502958823", "price": "0.15", "size": "200", "side": "BUY", "hash": "1a7f58a355c067bf29f7887489c521cb7d6fe059", "best_bid": "0.67", "best_ask": "0.69"}, {"asset_id": "91609514063242777856043730063938310894548353925882406409927495687846407164056", "price": "0.85", "size": "200", "side": "SELL", "hash": "f53bc92d18533580250bdfc80df63fa694c2dceb", "best_bid": "0.31", "best_ask": "0.33"}], "timestamp": "1769384882076", "event_type": "price_change"}}
{"_local_timestamp": "2026-01-25T23:48:03.918712+00:00", "data": {"market": "0xa9c0c820fd79b4339ed4711288ce15236196a6015234350f42b37341e9094398", "price_changes": [{"asset_id": "78438315737001038193507108078052969359305687599144926740526502005681502958823", "price": "0.16", "size": "200", "side": "BUY", "hash": "f682acaa29558a96459fd38bbe8974d113c0a375", "best_bid": "0.67", "best_ask": "0.69"}, {"asset_id": "91609514063242777856043730063938310894548353925882406409927495687846407164056", "price": "0.84", "size": "200", "side": "SELL", "hash": "6aa4c93672b5061bebb3b4baf4d37cf8772836b5", "best_bid": "0.31", "best_ask": "0.33"}], "timestamp": "1769384883846", "event_type": "price_change"}}
{"_local_timestamp": "2026-01-25T23:48:03.919836+00:00", "data": {"market": "0xa9c0c820fd79b4339ed4711288ce15236196a6015234350f42b37341e9094398", "price_changes": [{"asset_id": "78438315737001038193507108078052969359305687599144926740526502005681502958823", "price": "0.14", "size": "50", "side": "BUY", "hash": "561ea016b7351100a5f8e208a9dc78bf3d056584", "best_bid": "0.67", "best_ask": "0.69"}, {"asset_id": "91609514063242777856043730063938310894548353925882406409927495687846407164056", "price": "0.86", "size": "50", "side": "SELL", "hash": "d10366f077c5f71a22805c5924b17f3fa4e137a2", "best_bid": "0.31", "best_ask": "0.33"}], "timestamp": "1769384883846", "event_type": "price_change"}}
{"_local_timestamp": "2026-01-25T23:48:13.273538+00:00", "data": {"market": "0xa9c0c820fd79b4339ed4711288ce15236196a6015234350f42b37341e9094398", "price_changes": [{"asset_id": "78438315737001038193507108078052969359305687599144926740526502005681502958823", "price": "0.15", "size": "0", "side": "BUY", "hash": "0b2224dcaa78847097afa58883d73af29cb330bb", "best_bid": "0.67", "best_ask": "0.69"}, {"asset_id": "91609514063242777856043730063938310894548353925882406409927495687846407164056", "price": "0.85", "size": "0", "side": "SELL", "hash": "3f5ccb1134c156de39172316425961bfc226abc8", "best_bid": "0.31", "best_ask": "0.33"}], "timestamp": "1769384893209", "event_type": "price_change"}}
{"_local_timestamp": "2026-01-25T23:48:13.309465+00:00", "data": {"market": "0xa9c0c820fd79b4339ed4711288ce15236196a6015234350f42b37341e9094398", "price_changes": [{"asset_id": "78438315737001038193507108078052969359305687599144926740526502005681502958823", "price": "0.16", "size": "0", "side": "BUY", "hash": "31306159fd9a592272c68cf01eb01b3c4d27c30e", "best_bid": "0.67", "best_ask": "0.69"}, {"asset_id": "91609514063242777856043730063938310894548353925882406409927495687846407164056", "price": "0.84", "size": "0", "side": "SELL", "hash": "63f2ecbb702071b4df33004e9b4eafd004b24edb", "best_bid": "0.31", "best_ask": "0.33"}], "timestamp": "1769384893246", "event_type": "price_change"}}
{"_local_timestamp": "2026-01-25T23:48:13.316134+00:00", "data": {"market": "0xa9c0c820fd79b4339ed4711288ce15236196a6015234350f42b37341e9094398", "price_changes": [{"asset_id": "78438315737001038193507108078052969359305687599144926740526502005681502958823", "price": "0.14", "size": "250", "side": "BUY", "hash": "36d146a17d2deb301ad0210781096fce9f6ed91c", "best_bid": "0.67", "best_ask": "0.69"}, {"asset_id": "91609514063242777856043730063938310894548353925882406409927495687846407164056", "price": "0.86", "size": "250", "side": "SELL", "hash": "9dd5cce40febc18028eead0b47f4ef1c0e07dec5", "best_bid": "0.31", "best_ask": "0.33"}], "timestamp": "1769384893248", "event_type": "price_change"}}
{"_local_timestamp": "2026-01-25T23:48:13.545177+00:00", "data": {"market": "0xa9c0c820fd79b4339ed4711288ce15236196a6015234350f42b37341e9094398", "price_changes": [{"asset_id": "78438315737001038193507108078052969359305687599144926740526502005681502958823", "price": "0.11", "size": "200", "side": "BUY", "hash": "f6b259634d1d3d65e73404a41550dc548f6a724f", "best_bid": "0.67", "best_ask": "0.69"}, {"asset_id": "91609514063242777856043730063938310894548353925882406409927495687846407164056", "price": "0.89", "size": "200", "side": "SELL", "hash": "8d31ef9b18112e2b57bee92d1700292ecd270aad", "best_bid": "0.31", "best_ask": "0.33"}], "timestamp": "1769384893476", "event_type": "price_change"}}
{"_local_timestamp": "2026-01-25T23:48:17.988638+00:00", "data": {"market": "0xa9c0c820fd79b4339ed4711288ce15236196a6015234350f42b37341e9094398", "price_changes": [{"asset_id": "91609514063242777856043730063938310894548353925882406409927495687846407164056", "price": "0.34", "size": "0", "side": "SELL", "hash": "22bd6b283789c1396fa18552d29230685f5db694", "best_bid": "0.31", "best_ask": "0.33"}, {"asset_id": "78438315737001038193507108078052969359305687599144926740526502005681502958823", "price": "0.66", "size": "0", "side": "BUY", "hash": "34df1e5379ba0135303eef4d46642859e6e0637e", "best_bid": "0.67", "best_ask": "0.69"}], "timestamp": "1769384897910", "event_type": "price_change"}}
{"_local_timestamp": "2026-01-25T23:48:19.095144+00:00", "data": {"market": "0xa9c0c820fd79b4339ed4711288ce15236196a6015234350f42b37341e9094398", "price_changes": [{"asset_id": "91609514063242777856043730063938310894548353925882406409927495687846407164056", "price": "0.34", "size": "6.8", "side": "SELL", "hash": "4e62edb74232cbe17ca2775a6426524693e743c3", "best_bid": "0.31", "best_ask": "0.33"}, {"asset_id": "78438315737001038193507108078052969359305687599144926740526502005681502958823", "price": "0.66", "size": "6.8", "side": "BUY", "hash": "d61109e3e61f2f58a01c6721c09c154137823882", "best_bid": "0.67", "best_ask": "0.69"}], "timestamp": "1769384899008", "event_type": "price_change"}}
{"_local_timestamp": "2026-01-25T23:48:24.625137+00:00", "data": {"market": "0xa9c0c820fd79b4339ed4711288ce15236196a6015234350f42b37341e9094398", "price_changes": [{"asset_id": "78438315737001038193507108078052969359305687599144926740526502005681502958823", "price": "0.11", "size": "0", "side": "BUY", "hash": "12619186ec893f9018993fc14d62cdbbedde93b3", "best_bid": "0.67", "best_ask": "0.69"}, {"asset_id": "91609514063242777856043730063938310894548353925882406409927495687846407164056", "price": "0.89", "size": "0", "side": "SELL", "hash": "938bc92fa8a0a58a070a54cbbca1294b15dfa62f", "best_bid": "0.31", "best_ask": "0.33"}], "timestamp": "1769384904561", "event_type": "price_change"}}
{"_local_timestamp": "2026-01-25T23:48:24.878957+00:00", "data": {"market": "0xa9c0c820fd79b4339ed4711288ce15236196a6015234350f42b37341e9094398", "price_changes": [{"asset_id": "78438315737001038193507108078052969359305687599144926740526502005681502958823", "price": "0.14", "size": "450", "side": "BUY", "hash": "da5dc4cf115f60cb3552a5e39986fa38aa02857b", "best_bid": "0.67", "best_ask": "0.69"}, {"asset_id": "91609514063242777856043730063938310894548353925882406409927495687846407164056", "price": "0.86", "size": "450", "side": "SELL", "hash": "800f3f05c2f552ef77413ac82410ed685552b4ab", "best_bid": "0.31", "best_ask": "0.33"}], "timestamp": "1769384904811", "event_type": "price_change"}}
{"_local_timestamp": "2026-01-25T23:48:24.922592+00:00", "data": {"market": "0xa9c0c820fd79b4339ed4711288ce15236196a6015234350f42b37341e9094398", "price_changes": [{"asset_id": "78438315737001038193507108078052969359305687599144926740526502005681502958823", "price": "0.15", "size": "200", "side": "BUY", "hash": "91b8acb8160dbe099cd886d07a803078241fd319", "best_bid": "0.67", "best_ask": "0.69"}, {"asset_id": "91609514063242777856043730063938310894548353925882406409927495687846407164056", "price": "0.85", "size": "200", "side": "SELL", "hash": "9dcd5816165b64905ab83c5d622bce81a4bc3c11", "best_bid": "0.31", "best_ask": "0.33"}], "timestamp": "1769384904860", "event_type": "price_change"}}
{"_local_timestamp": "2026-01-25T23:48:24.923757+00:00", "data": {"market": "0xa9c0c820fd79b4339ed4711288ce15236196a6015234350f42b37341e9094398", "price_changes": [{"asset_id": "78438315737001038193507108078052969359305687599144926740526502005681502958823", "price": "0.14", "size": "250", "side": "BUY", "hash": "8bb206f9e6b9c1424f3dc8f48953490007e24ab4", "best_bid": "0.67", "best_ask": "0.69"}, {"asset_id": "91609514063242777856043730063938310894548353925882406409927495687846407164056", "price": "0.86", "size": "250", "side": "SELL", "hash": "dc7b26661372b20836bd3c05b7e173b01d057251", "best_bid": "0.31", "best_ask": "0.33"}], "timestamp": "1769384904861", "event_type": "price_change"}}
{"_local_timestamp": "2026-01-25T23:48:35.125187+00:00", "data": {"market": "0xa9c0c820fd79b4339ed4711288ce15236196a6015234350f42b37341e9094398", "price_changes": [{"asset_id": "78438315737001038193507108078052969359305687599144926740526502005681502958823", "price": "0.14", "size": "50", "side": "BUY", "hash": "ebfedd60ea9655d3bcf86c31bce6291b253fb2e1", "best_bid": "0.67", "best_ask": "0.69"}, {"asset_id": "91609514063242777856043730063938310894548353925882406409927495687846407164056", "price": "0.86", "size": "50", "side": "SELL", "hash": "40beb68db33af009641b6fd14203c879d43ceed6", "best_bid": "0.31", "best_ask": "0.33"}], "timestamp": "1769384915015", "event_type": "price_change"}}
{"_local_timestamp": "2026-01-25T23:48:35.181751+00:00", "data": {"market": "0xa9c0c820fd79b4339ed4711288ce15236196a6015234350f42b37341e9094398", "price_changes": [{"asset_id": "78438315737001038193507108078052969359305687599144926740526502005681502958823", "price": "0.15", "size": "0", "side": "BUY", "hash": "b7f37f5e4f4a3a77e77f8a2daedb302465c94623", "best_bid": "0.67", "best_ask": "0.69"}, {"asset_id": "91609514063242777856043730063938310894548353925882406409927495687846407164056", "price": "0.85", "size": "0", "side": "SELL", "hash": "32209ba9b92f983f1b5c54a2fc0cb25b3b0d35b7", "best_bid": "0.31", "best_ask": "0.33"}], "timestamp": "1769384915102", "event_type": "price_change"}}
{"_local_timestamp": "2026-01-25T23:48:35.182926+00:00", "data": {"market": "0xa9c0c820fd79b4339ed4711288ce15236196a6015234350f42b37341e9094398", "price_changes": [{"asset_id": "78438315737001038193507108078052969359305687599144926740526502005681502958823", "price": "0.14", "size": "250", "side": "BUY", "hash": "423077084d90958cfbe3d58391eeca563ae51f07", "best_bid": "0.67", "best_ask": "0.69"}, {"asset_id": "91609514063242777856043730063938310894548353925882406409927495687846407164056", "price": "0.86", "size": "250", "side": "SELL", "hash": "36b864613c74fb199f24da3efff479dacaa03ac9", "best_bid": "0.31", "best_ask": "0.33"}], "timestamp": "1769384915103", "event_type": "price_change"}}
{"_local_timestamp": "2026-01-25T23:48:35.364326+00:00", "data": {"market": "0xa9c0c820fd79b4339ed4711288ce15236196a6015234350f42b37341e9094398", "price_changes": [{"asset_id": "78438315737001038193507108078052969359305687599144926740526502005681502958823", "price": "0.15", "size": "200", "side": "BUY", "hash": "64c880de7644dcb85f7668351aa8a96f638ae079", "best_bid": "0.67", "best_ask": "0.69"}, {"asset_id": "91609514063242777856043730063938310894548353925882406409927495687846407164056", "price": "0.85", "size": "200", "side": "SELL", "hash": "905b3735aa4494d3457631e1471284eb4ea6a75a", "best_bid": "0.31", "best_ask": "0.33"}], "timestamp": "1769384915285", "event_type": "price_change"}}
{"_local_timestamp": "2026-01-25T23:48:37.168379+00:00", "data": {"market": "0xa9c0c820fd79b4339ed4711288ce15236196a6015234350f42b37341e9094398", "price_changes": [{"asset_id": "78438315737001038193507108078052969359305687599144926740526502005681502958823", "price": "0.14", "size": "50", "side": "BUY", "hash": "1bbf7d110bf8523b6057b5f49aa311349e96d390", "best_bid": "0.67", "best_ask": "0.69"}, {"asset_id": "91609514063242777856043730063938310894548353925882406409927495687846407164056", "price": "0.86", "size": "50", "side": "SELL", "hash": "71f31ca273a7a56b599861e70c210c4f1b713d0a", "best_bid": "0.31", "best_ask": "0.33"}], "timestamp": "1769384917085", "event_type": "price_change"}}
{"_local_timestamp": "2026-01-25T23:48:37.169569+00:00", "data": {"market": "0xa9c0c820fd79b4339ed4711288ce15236196a6015234350f42b37341e9094398", "price_changes": [{"asset_id": "78438315737001038193507108078052969359305687599144926740526502005681502958823", "price": "0.16", "size": "200", "side": "BUY", "hash": "b3043a7564ea0472ae323b244d6566752c15c201", "best_bid": "0.67", "best_ask": "0.69"}, {"asset_id": "91609514063242777856043730063938310894548353925882406409927495687846407164056", "price": "0.84", "size": "200", "side": "SELL", "hash": "ccd983dcf36f8097b6f8f921d6fc904c4d162fd2", "best_bid": "0.31", "best_ask": "0.33"}], "timestamp": "1769384917089", "event_type": "price_change"}}
{"_local_timestamp": "2026-01-25T23:48:46.767630+00:00", "data": {"market": "0xa9c0c820fd79b4339ed4711288ce15236196a6015234350f42b37341e9094398", "price_changes": [{"asset_id": "78438315737001038193507108078052969359305687599144926740526502005681502958823", "price": "0.15", "size": "0", "side": "BUY", "hash": "5e0567cdf463d8cee5b4a752dd86e8da29fd77ef", "best_bid": "0.67", "best_ask": "0.69"}, {"asset_id": "91609514063242777856043730063938310894548353925882406409927495687846407164056", "price": "0.85", "size": "0", "side": "SELL", "hash": "8b988adf97b7fa3041a93621cf22f8a45ac65824", "best_bid": "0.31", "best_ask": "0.33"}], "timestamp": "1769384926696", "event_type": "price_change"}}
{"_local_timestamp": "2026-01-25T23:48:46.816205+00:00", "data": {"market": "0xa9c0c820fd79b4339ed4711288ce15236196a6015234350f42b37341e9094398", "price_changes": [{"asset_id": "78438315737001038193507108078052969359305687599144926740526502005681502958823", "price": "0.16", "size": "0", "side": "BUY", "hash": "c4bc9cedccc1073b70177737760ad158c678f247", "best_bid": "0.67", "best_ask": "0.69"}, {"asset_id": "91609514063242777856043730063938310894548353925882406409927495687846407164056", "price": "0.84", "size": "0", "side": "SELL", "hash": "cba175b25546391caaeeff002c019a04dd7c86f6", "best_bid": "0.31", "best_ask": "0.33"}], "timestamp": "1769384926739", "event_type": "price_change"}}
{"_local_timestamp": "2026-01-25T23:48:46.817614+00:00", "data": {"market": "0xa9c0c820fd79b4339ed4711288ce15236196a6015234350f42b37341e9094398", "price_changes": [{"asset_id": "78438315737001038193507108078052969359305687599144926740526502005681502958823", "price": "0.14", "size": "250", "side": "BUY", "hash": "877c94ddf4ab3c164730ff5c2ff3397206c97bfa", "best_bid": "0.67", "best_ask": "0.69"}, {"asset_id": "91609514063242777856043730063938310894548353925882406409927495687846407164056", "price": "0.86", "size": "250", "side": "SELL", "hash": "39842449606036bb1a4366745c0d812dca775636", "best_bid": "0.31", "best_ask": "0.33"}], "timestamp": "1769384926741", "event_type": "price_change"}}
{"_local_timestamp": "2026-01-25T23:48:47.033665+00:00", "data": {"market": "0xa9c0c820fd79b4339ed4711288ce15236196a6015234350f42b37341e9094398", "price_changes": [{"asset_id": "78438315737001038193507108078052969359305687599144926740526502005681502958823", "price": "0.11", "size": "200", "side": "BUY", "hash": "70496d9b154f0c4a79c5fa1f1cdafb00aebe8f37", "best_bid": "0.67", "best_ask": "0.69"}, {"asset_id": "91609514063242777856043730063938310894548353925882406409927495687846407164056", "price": "0.89", "size": "200", "side": "SELL", "hash": "0b083fc62cec5cde3d191ab5d4d01f7ca3f4d147", "best_bid": "0.31", "best_ask": "0.33"}], "timestamp": "1769384926960", "event_type": "price_change"}}
{"_local_timestamp": "2026-01-25T23:48:59.711917+00:00", "data": {"market": "0xa9c0c820fd79b4339ed4711288ce15236196a6015234350f42b37341e9094398", "price_changes": [{"asset_id": "78438315737001038193507108078052969359305687599144926740526502005681502958823", "price": "0.11", "size": "0", "side": "BUY", "hash": "b186f17e644af3ff5dbb5b34b0ee0a505a044a3a", "best_bid": "0.67", "best_ask": "0.69"}, {"asset_id": "91609514063242777856043730063938310894548353925882406409927495687846407164056", "price": "0.89", "size": "0", "side": "SELL", "hash": "db3ca48ba7e914c3d4db7956668ccec65dc37005", "best_bid": "0.31", "best_ask": "0.33"}], "timestamp": "1769384939630", "event_type": "price_change"}}
{"_local_timestamp": "2026-01-25T23:48:59.966701+00:00", "data": {"market": "0xa9c0c820fd79b4339ed4711288ce15236196a6015234350f42b37341e9094398", "price_changes": [{"asset_id": "78438315737001038193507108078052969359305687599144926740526502005681502958823", "price": "0.14", "size": "450", "side": "BUY", "hash": "7c72d5127b5246ab30c45882380b625b60865ebe", "best_bid": "0.67", "best_ask": "0.69"}, {"asset_id": "91609514063242777856043730063938310894548353925882406409927495687846407164056", "price": "0.86", "size": "450", "side": "SELL", "hash": "5ed726ac77971a8bf851376286ad770ae680c7ef", "best_bid": "0.31", "best_ask": "0.33"}], "timestamp": "1769384939898", "event_type": "price_change"}}
{"_local_timestamp": "2026-01-25T23:49:00.007853+00:00", "data": {"market": "0xa9c0c820fd79b4339ed4711288ce15236196a6015234350f42b37341e9094398", "price_changes": [{"asset_id": "78438315737001038193507108078052969359305687599144926740526502005681502958823", "price": "0.14", "size": "250", "side": "BUY", "hash": "3355e0ee9642fb0d3f89d80c14a5fc9ed5bae02a", "best_bid": "0.67", "best_ask": "0.69"}, {"asset_id": "91609514063242777856043730063938310894548353925882406409927495687846407164056", "price": "0.86", "size": "250", "side": "SELL", "hash": "dc7f191b72aaabcb78c9de0a1a662c7ccecaf2f5", "best_bid": "0.31", "best_ask": "0.33"}], "timestamp": "1769384939934", "event_type": "price_change"}}
{"_local_timestamp": "2026-01-25T23:49:00.010472+00:00", "data": {"market": "0xa9c0c820fd79b4339ed4711288ce15236196a6015234350f42b37341e9094398", "price_changes": [{"asset_id": "78438315737001038193507108078052969359305687599144926740526502005681502958823", "price": "0.15", "size": "200", "side": "BUY", "hash": "58e473f99bc6d07dbca5943729e4c43c0ee0246f", "best_bid": "0.67", "best_ask": "0.69"}, {"asset_id": "91609514063242777856043730063938310894548353925882406409927495687846407164056", "price": "0.85", "size": "200", "side": "SELL", "hash": "a9c5aaecef9a339f44d31d28ac910d721493840f", "best_bid": "0.31", "best_ask": "0.33"}], "timestamp": "1769384939937", "event_type": "price_change"}}
{"_local_timestamp": "2026-01-25T23:49:10.704257+00:00", "data": {"market": "0xa9c0c820fd79b4339ed4711288ce15236196a6015234350f42b37341e9094398", "price_changes": [{"asset_id": "78438315737001038193507108078052969359305687599144926740526502005681502958823", "price": "0.14", "size": "50", "side": "BUY", "hash": "0fe669eddb06a2f6794f6a695bd9a17b823f0c10", "best_bid": "0.67", "best_ask": "0.69"}, {"asset_id": "91609514063242777856043730063938310894548353925882406409927495687846407164056", "price": "0.86", "size": "50", "side": "SELL", "hash": "7d593591c61f8b05aac46f19bdd385e25aa6ef37", "best_bid": "0.31", "best_ask": "0.33"}], "timestamp": "1769384950631", "event_type": "price_change"}}
{"_local_timestamp": "2026-01-25T23:49:10.736105+00:00", "data": {"market": "0xa9c0c820fd79b4339ed4711288ce15236196a6015234350f42b37341e9094398", "price_changes": [{"asset_id": "78438315737001038193507108078052969359305687599144926740526502005681502958823", "price": "0.15", "size": "0", "side": "BUY", "hash": "dad66bde993e1cc0301d61f082e30e6176245726", "best_bid": "0.67", "best_ask": "0.69"}, {"asset_id": "91609514063242777856043730063938310894548353925882406409927495687846407164056", "price": "0.85", "size": "0", "side": "SELL", "hash": "17ed0b0ed95e400956b2fe77d0d51aa6b121d979", "best_bid": "0.31", "best_ask": "0.33"}], "timestamp": "1769384950667", "event_type": "price_change"}}
{"_local_timestamp": "2026-01-25T23:49:10.737297+00:00", "data": {"market": "0xa9c0c820fd79b4339ed4711288ce15236196a6015234350f42b37341e9094398", "price_changes": [{"asset_id": "78438315737001038193507108078052969359305687599144926740526502005681502958823", "price": "0.14", "size": "250", "side": "BUY", "hash": "8bc4008b9b12a33fa0dc9cf1a026f966e442e63a", "best_bid": "0.67", "best_ask": "0.69"}, {"asset_id": "91609514063242777856043730063938310894548353925882406409927495687846407164056", "price": "0.86", "size": "250", "side": "SELL", "hash": "df3c7893082c9ddd0be0c827b619c60de4e2d7e3", "best_bid": "0.31", "best_ask": "0.33"}], "timestamp": "1769384950669", "event_type": "price_change"}}
{"_local_timestamp": "2026-01-25T23:49:10.948945+00:00", "data": {"market": "0xa9c0c820fd79b4339ed4711288ce15236196a6015234350f42b37341e9094398", "price_changes": [{"asset_id": "78438315737001038193507108078052969359305687599144926740526502005681502958823", "price": "0.15", "size": "200", "side": "BUY", "hash": "94247449ce285d3b690f793cea113a3ef0e40e08", "best_bid": "0.67", "best_ask": "0.69"}, {"asset_id": "91609514063242777856043730063938310894548353925882406409927495687846407164056", "price": "0.85", "size": "200", "side": "SELL", "hash": "806664b00e2b1f549d70f1343a48e7f1766f40ba", "best_bid": "0.31", "best_ask": "0.33"}], "timestamp": "1769384950873", "event_type": "price_change"}}
{"_local_timestamp": "2026-01-25T23:49:12.738302+00:00", "data": {"market": "0xa9c0c820fd79b4339ed4711288ce15236196a6015234350f42b37341e9094398", "price_changes": [{"asset_id": "78438315737001038193507108078052969359305687599144926740526502005681502958823", "price": "0.16", "size": "200", "side": "BUY", "hash": "532984271dc3a4743eb530ef7662f024d1c828e9", "best_bid": "0.67", "best_ask": "0.69"}, {"asset_id": "91609514063242777856043730063938310894548353925882406409927495687846407164056", "price": "0.84", "size": "200", "side": "SELL", "hash": "116b5570c8f0405e06715013b4736e3967a3f8ac", "best_bid": "0.31", "best_ask": "0.33"}], "timestamp": "1769384952666", "event_type": "price_change"}}
{"_local_timestamp": "2026-01-25T23:49:12.739563+00:00", "data": {"market": "0xa9c0c820fd79b4339ed4711288ce15236196a6015234350f42b37341e9094398", "price_changes": [{"asset_id": "78438315737001038193507108078052969359305687599144926740526502005681502958823", "price": "0.14", "size": "50", "side": "BUY", "hash": "8c6acf2c44d60ad4e04fea72c156ed62c05c2c61", "best_bid": "0.67", "best_ask": "0.69"}, {"asset_id": "91609514063242777856043730063938310894548353925882406409927495687846407164056", "price": "0.86", "size": "50", "side": "SELL", "hash": "efe1a5f26ac6fcd4e3ea8693a0116d2f70bbc819", "best_bid": "0.31", "best_ask": "0.33"}], "timestamp": "1769384952672", "event_type": "price_change"}}
{"_local_timestamp": "2026-01-25T23:49:22.938908+00:00", "data": {"market": "0xa9c0c820fd79b4339ed4711288ce15236196a6015234350f42b37341e9094398", "price_changes": [{"asset_id": "78438315737001038193507108078052969359305687599144926740526502005681502958823", "price": "0.15", "size": "0", "side": "BUY", "hash": "b18c5e15639f16c238daa6cebbe5e72d0199476f", "best_bid": "0.67", "best_ask": "0.69"}, {"asset_id": "91609514063242777856043730063938310894548353925882406409927495687846407164056", "price": "0.85", "size": "0", "side": "SELL", "hash": "a5876bbde93a24082d9f52daf8b923b9fd4a04b5", "best_bid": "0.31", "best_ask": "0.33"}], "timestamp": "1769384962867", "event_type": "price_change"}}
{"_local_timestamp": "2026-01-25T23:49:22.977528+00:00", "data": {"market": "0xa9c0c820fd79b4339ed4711288ce15236196a6015234350f42b37341e9094398", "price_changes": [{"asset_id": "78438315737001038193507108078052969359305687599144926740526502005681502958823", "price": "0.16", "size": "0", "side": "BUY", "hash": "3016d19fb1369d124a5fd1cc7f3f826fed0efe23", "best_bid": "0.67", "best_ask": "0.69"}, {"asset_id": "91609514063242777856043730063938310894548353925882406409927495687846407164056", "price": "0.84", "size": "0", "side": "SELL", "hash": "4bd0572a2f4f3271341d3a0e1ae7b38079536e19", "best_bid": "0.31", "best_ask": "0.33"}], "timestamp": "1769384962910", "event_type": "price_change"}}
{"_local_timestamp": "2026-01-25T23:49:22.988407+00:00", "data": {"market": "0xa9c0c820fd79b4339ed4711288ce15236196a6015234350f42b37341e9094398", "price_changes": [{"asset_id": "78438315737001038193507108078052969359305687599144926740526502005681502958823", "price": "0.14", "size": "250", "side": "BUY", "hash": "2ce5479312b05e8609f2a7e986a1033d7adf440a", "best_bid": "0.67", "best_ask": "0.69"}, {"asset_id": "91609514063242777856043730063938310894548353925882406409927495687846407164056", "price": "0.86", "size": "250", "side": "SELL", "hash": "dbf954e8516ce6b2f214789051314956da6550c8", "best_bid": "0.31", "best_ask": "0.33"}], "timestamp": "1769384962912", "event_type": "price_change"}}
{"_local_timestamp": "2026-01-25T23:49:23.199691+00:00", "data": {"market": "0xa9c0c820fd79b4339ed4711288ce15236196a6015234350f42b37341e9094398", "price_changes": [{"asset_id": "78438315737001038193507108078052969359305687599144926740526502005681502958823", "price": "0.11", "size": "200", "side": "BUY", "hash": "2d5fa5eb8e14358a41d7784e4e661452049efe06", "best_bid": "0.67", "best_ask": "0.69"}, {"asset_id": "91609514063242777856043730063938310894548353925882406409927495687846407164056", "price": "0.89", "size": "200", "side": "SELL", "hash": "f40d4d1d81f573689f1a96908ae419b25bad6127", "best_bid": "0.31", "best_ask": "0.33"}], "timestamp": "1769384963128", "event_type": "price_change"}}
{"_local_timestamp": "2026-01-25T23:49:33.524001+00:00", "data": {"market": "0xa9c0c820fd79b4339ed4711288ce15236196a6015234350f42b37341e9094398", "price_changes": [{"asset_id": "78438315737001038193507108078052969359305687599144926740526502005681502958823", "price": "0.11", "size": "0", "side": "BUY", "hash": "00bd3714316b301767ef7630959b910f30b9d529", "best_bid": "0.67", "best_ask": "0.69"}, {"asset_id": "91609514063242777856043730063938310894548353925882406409927495687846407164056", "price": "0.89", "size": "0", "side": "SELL", "hash": "9f57106bc4871e694e1d6be1977ffa9d3a77e0b6", "best_bid": "0.31", "best_ask": "0.33"}], "timestamp": "1769384973454", "event_type": "price_change"}}
{"_local_timestamp": "2026-01-25T23:49:33.771712+00:00", "data": {"market": "0xa9c0c820fd79b4339ed4711288ce15236196a6015234350f42b37341e9094398", "price_changes": [{"asset_id": "78438315737001038193507108078052969359305687599144926740526502005681502958823", "price": "0.14", "size": "450", "side": "BUY", "hash": "23c21b698e59cb5f797b4b3f0e4d0e43c405a735", "best_bid": "0.67", "best_ask": "0.69"}, {"asset_id": "91609514063242777856043730063938310894548353925882406409927495687846407164056", "price": "0.86", "size": "450", "side": "SELL", "hash": "7ea0d2320f6afda25b15403bc4b06a8ac8954c22", "best_bid": "0.31", "best_ask": "0.33"}], "timestamp": "1769384973704", "event_type": "price_change"}}
{"_local_timestamp": "2026-01-25T23:49:33.808029+00:00", "data": {"market": "0xa9c0c820fd79b4339ed4711288ce15236196a6015234350f42b37341e9094398", "price_changes": [{"asset_id": "78438315737001038193507108078052969359305687599144926740526502005681502958823", "price": "0.14", "size": "250", "side": "BUY", "hash": "5d603e24caa6dd580ef3fcfdd3ac1b9efe3dd782", "best_bid": "0.67", "best_ask": "0.69"}, {"asset_id": "91609514063242777856043730063938310894548353925882406409927495687846407164056", "price": "0.86", "size": "250", "side": "SELL", "hash": "d09ad1cbf8ebf8d23c5f97cf2dbf814fd95f539f", "best_bid": "0.31", "best_ask": "0.33"}], "timestamp": "1769384973746", "event_type": "price_change"}}
{"_local_timestamp": "2026-01-25T23:49:33.812225+00:00", "data": {"market": "0xa9c0c820fd79b4339ed4711288ce15236196a6015234350f42b37341e9094398", "price_changes": [{"asset_id": "78438315737001038193507108078052969359305687599144926740526502005681502958823", "price": "0.15", "size": "200", "side": "BUY", "hash": "8362ac81bfd8640e13b89a5488e78e7231d7ed8b", "best_bid": "0.67", "best_ask": "0.69"}, {"asset_id": "91609514063242777856043730063938310894548353925882406409927495687846407164056", "price": "0.85", "size": "200", "side": "SELL", "hash": "111e8acd94beed110c1e95d3f640320dead5c18b", "best_bid": "0.31", "best_ask": "0.33"}], "timestamp": "1769384973748", "event_type": "price_change"}}
{"_local_timestamp": "2026-01-25T23:49:43.893557+00:00", "data": {"market": "0xa9c0c820fd79b4339ed4711288ce15236196a6015234350f42b37341e9094398", "price_changes": [{"asset_id": "78438315737001038193507108078052969359305687599144926740526502005681502958823", "price": "0.14", "size": "50", "side": "BUY", "hash": "51b21461807a78ab895e454f381b279513d38802", "best_bid": "0.67", "best_ask": "0.69"}, {"asset_id": "91609514063242777856043730063938310894548353925882406409927495687846407164056", "price": "0.86", "size": "50", "side": "SELL", "hash": "15abb112f424025436596e40b55f3a1a941bc623", "best_bid": "0.31", "best_ask": "0.33"}], "timestamp": "1769384983826", "event_type": "price_change"}}
{"_local_timestamp": "2026-01-25T23:49:43.936359+00:00", "data": {"market": "0xa9c0c820fd79b4339ed4711288ce15236196a6015234350f42b37341e9094398", "price_changes": [{"asset_id": "78438315737001038193507108078052969359305687599144926740526502005681502958823", "price": "0.14", "size": "250", "side": "BUY", "hash": "2583b49e2dbf2f4e1a12ad6d279c78b5a7b5f3f2", "best_bid": "0.67", "best_ask": "0.69"}, {"asset_id": "91609514063242777856043730063938310894548353925882406409927495687846407164056", "price": "0.86", "size": "250", "side": "SELL", "hash": "aef4085b0100cbac45d0e4c196f44a709515d76a", "best_bid": "0.31", "best_ask": "0.33"}], "timestamp": "1769384983868", "event_type": "price_change"}}
{"_local_timestamp": "2026-01-25T23:49:43.937658+00:00", "data": {"market": "0xa9c0c820fd79b4339ed4711288ce15236196a6015234350f42b37341e9094398", "price_changes": [{"asset_id": "78438315737001038193507108078052969359305687599144926740526502005681502958823", "price": "0.15", "size": "0", "side": "BUY", "hash": "5d2041197962b557604b456bee864bdbd930ab60", "best_bid": "0.67", "best_ask": "0.69"}, {"asset_id": "91609514063242777856043730063938310894548353925882406409927495687846407164056", "price": "0.85", "size": "0", "side": "SELL", "hash": "b8aca86b8022d9101acf76c22878920dead0d3a9", "best_bid": "0.31", "best_ask": "0.33"}], "timestamp": "1769384983868", "event_type": "price_change"}}
{"_local_timestamp": "2026-01-25T23:49:44.150056+00:00", "data": {"market": "0xa9c0c820fd79b4339ed4711288ce15236196a6015234350f42b37341e9094398", "price_changes": [{"asset_id": "78438315737001038193507108078052969359305687599144926740526502005681502958823", "price": "0.15", "size": "200", "side": "BUY", "hash": "af22c6564ce19a55a99c724c0500b4048089acf4", "best_bid": "0.67", "best_ask": "0.69"}, {"asset_id": "91609514063242777856043730063938310894548353925882406409927495687846407164056", "price": "0.85", "size": "200", "side": "SELL", "hash": "4955edaff8344f27e5b74c0d4c3c3b40053af3f9", "best_bid": "0.31", "best_ask": "0.33"}], "timestamp": "1769384984079", "event_type": "price_change"}}
{"_local_timestamp": "2026-01-25T23:49:45.933688+00:00", "data": {"market": "0xa9c0c820fd79b4339ed4711288ce15236196a6015234350f42b37341e9094398", "price_changes": [{"asset_id": "78438315737001038193507108078052969359305687599144926740526502005681502958823", "price": "0.14", "size": "50", "side": "BUY", "hash": "71916364e31bc2af6dc9664387cf5762334f7fcf", "best_bid": "0.67", "best_ask": "0.69"}, {"asset_id": "91609514063242777856043730063938310894548353925882406409927495687846407164056", "price": "0.86", "size": "50", "side": "SELL", "hash": "72d3534286a32e180caf7101edf6866a537fb1ee", "best_bid": "0.31", "best_ask": "0.33"}], "timestamp": "1769384985863", "event_type": "price_change"}}
{"_local_timestamp": "2026-01-25T23:49:45.935031+00:00", "data": {"market": "0xa9c0c820fd79b4339ed4711288ce15236196a6015234350f42b37341e9094398", "price_changes": [{"asset_id": "78438315737001038193507108078052969359305687599144926740526502005681502958823", "price": "0.16", "size": "200", "side": "BUY", "hash": "59aa915f88c61eb389d2423e9e4ca8ad974d64f7", "best_bid": "0.67", "best_ask": "0.69"}, {"asset_id": "91609514063242777856043730063938310894548353925882406409927495687846407164056", "price": "0.84", "size": "200", "side": "SELL", "hash": "30aa7e56020af253ed91cf253d840ff2d44f87bf", "best_bid": "0.31", "best_ask": "0.33"}], "timestamp": "1769384985869", "event_type": "price_change"}}
{"_local_timestamp": "2026-01-25T23:49:56.605623+00:00", "data": {"market": "0xa9c0c820fd79b4339ed4711288ce15236196a6015234350f42b37341e9094398", "price_changes": [{"asset_id": "78438315737001038193507108078052969359305687599144926740526502005681502958823", "price": "0.15", "size": "0", "side": "BUY", "hash": "153b90d9517f0f0743e02a4cf2404683d2589e12", "best_bid": "0.67", "best_ask": "0.69"}, {"asset_id": "91609514063242777856043730063938310894548353925882406409927495687846407164056", "price": "0.85", "size": "0", "side": "SELL", "hash": "173be8d22a745ca7c2e8048db9df529b4a7497be", "best_bid": "0.31", "best_ask": "0.33"}], "timestamp": "1769384996540", "event_type": "price_change"}}
{"_local_timestamp": "2026-01-25T23:49:56.650182+00:00", "data": {"market": "0xa9c0c820fd79b4339ed4711288ce15236196a6015234350f42b37341e9094398", "price_changes": [{"asset_id": "78438315737001038193507108078052969359305687599144926740526502005681502958823", "price": "0.16", "size": "0", "side": "BUY", "hash": "79be861ebe0b3cd4649aa564b26d8f3998d200b1", "best_bid": "0.67", "best_ask": "0.69"}, {"asset_id": "91609514063242777856043730063938310894548353925882406409927495687846407164056", "price": "0.84", "size": "0", "side": "SELL", "hash": "33a07a9591b481423a99c00748ff354becb4693e", "best_bid": "0.31", "best_ask": "0.33"}], "timestamp": "1769384996575", "event_type": "price_change"}}
{"_local_timestamp": "2026-01-25T23:49:56.651508+00:00", "data": {"market": "0xa9c0c820fd79b4339ed4711288ce15236196a6015234350f42b37341e9094398", "price_changes": [{"asset_id": "78438315737001038193507108078052969359305687599144926740526502005681502958823", "price": "0.14", "size": "250", "side": "BUY", "hash": "d9c5cfef607fd032c89647b147eb2cfcd6bd150e", "best_bid": "0.67", "best_ask": "0.69"}, {"asset_id": "91609514063242777856043730063938310894548353925882406409927495687846407164056", "price": "0.86", "size": "250", "side": "SELL", "hash": "de54735fd553a0de07e4ec50d9090c319ab2a394", "best_bid": "0.31", "best_ask": "0.33"}], "timestamp": "1769384996584", "event_type": "price_change"}}
{"_local_timestamp": "2026-01-25T23:49:56.893859+00:00", "data": {"market": "0xa9c0c820fd79b4339ed4711288ce15236196a6015234350f42b37341e9094398", "price_changes": [{"asset_id": "78438315737001038193507108078052969359305687599144926740526502005681502958823", "price": "0.11", "size": "200", "side": "BUY", "hash": "1f9298e914f891927136e307f6a039e55a206a09", "best_bid": "0.67", "best_ask": "0.69"}, {"asset_id": "91609514063242777856043730063938310894548353925882406409927495687846407164056", "price": "0.89", "size": "200", "side": "SELL", "hash": "b4a9a2c791d9b7985d1870943f35459ad3dadc7a", "best_bid": "0.31", "best_ask": "0.33"}], "timestamp": "1769384996828", "event_type": "price_change"}}
{"_local_timestamp": "2026-01-25T23:50:08.012756+00:00", "data": {"market": "0xa9c0c820fd79b4339ed4711288ce15236196a6015234350f42b37341e9094398", "price_changes": [{"asset_id": "78438315737001038193507108078052969359305687599144926740526502005681502958823", "price": "0.11", "size": "0", "side": "BUY", "hash": "2c7cd261c12437d868e071e676e8e48c2835a320", "best_bid": "0.67", "best_ask": "0.69"}, {"asset_id": "91609514063242777856043730063938310894548353925882406409927495687846407164056", "price": "0.89", "size": "0", "side": "SELL", "hash": "fc8e3191094498bbb7ce89f737ae1fe30c21b4e5", "best_bid": "0.31", "best_ask": "0.33"}], "timestamp": "1769385007934", "event_type": "price_change"}}
{"_local_timestamp": "2026-01-25T23:50:08.284698+00:00", "data": {"market": "0xa9c0c820fd79b4339ed4711288ce15236196a6015234350f42b37341e9094398", "price_changes": [{"asset_id": "78438315737001038193507108078052969359305687599144926740526502005681502958823", "price": "0.14", "size": "450", "side": "BUY", "hash": "4e89f1c1c39478e0259b65254a3bc01f7660a4d2", "best_bid": "0.67", "best_ask": "0.69"}, {"asset_id": "91609514063242777856043730063938310894548353925882406409927495687846407164056", "price": "0.86", "size": "450", "side": "SELL", "hash": "135da95d9c3d2703c02b066f52269a8e51468b65", "best_bid": "0.31", "best_ask": "0.33"}], "timestamp": "1769385008212", "event_type": "price_change"}}
{"_local_timestamp": "2026-01-25T23:50:08.329260+00:00", "data": {"market": "0xa9c0c820fd79b4339ed4711288ce15236196a6015234350f42b37341e9094398", "price_changes": [{"asset_id": "78438315737001038193507108078052969359305687599144926740526502005681502958823", "price": "0.14", "size": "250", "side": "BUY", "hash": "4f69abee6c81fdc13dda4157f4f57169ede6990a", "best_bid": "0.67", "best_ask": "0.69"}, {"asset_id": "91609514063242777856043730063938310894548353925882406409927495687846407164056", "price": "0.86", "size": "250", "side": "SELL", "hash": "7672a7a6e66e5c43882465ab8871832863ce1e59", "best_bid": "0.31", "best_ask": "0.33"}], "timestamp": "1769385008255", "event_type": "price_change"}}
{"_local_timestamp": "2026-01-25T23:50:08.330532+00:00", "data": {"market": "0xa9c0c820fd79b4339ed4711288ce15236196a6015234350f42b37341e9094398", "price_changes": [{"asset_id": "78438315737001038193507108078052969359305687599144926740526502005681502958823", "price": "0.15", "size": "200", "side": "BUY", "hash": "c64545d98ba0904cbbeb17280d030a9f4fe980b0", "best_bid": "0.67", "best_ask": "0.69"}, {"asset_id": "91609514063242777856043730063938310894548353925882406409927495687846407164056", "price": "0.85", "size": "200", "side": "SELL", "hash": "0fa364ae053e48bd81bd9645950c894a23e99ec7", "best_bid": "0.31", "best_ask": "0.33"}], "timestamp": "1769385008255", "event_type": "price_change"}}
{"_local_timestamp": "2026-01-25T23:50:11.169407+00:00", "data": {"market": "0xa9c0c820fd79b4339ed4711288ce15236196a6015234350f42b37341e9094398", "price_changes": [{"asset_id": "91609514063242777856043730063938310894548353925882406409927495687846407164056", "price": "0.01", "size": "14275.55", "side": "BUY", "hash": "c701a04e72566b04b4ada140d2efd82f18d97764", "best_bid": "0.31", "best_ask": "0.33"}, {"asset_id": "78438315737001038193507108078052969359305687599144926740526502005681502958823", "price": "0.99", "size": "14275.55", "side": "SELL", "hash": "07c1f1981a52190e71f336b425fb26647c4ea46b", "best_bid": "0.67", "best_ask": "0.69"}], "timestamp": "1769385011088", "event_type": "price_change"}}
{"_local_timestamp": "2026-01-25T23:50:18.031875+00:00", "data": {"market": "0xa9c0c820fd79b4339ed4711288ce15236196a6015234350f42b37341e9094398", "price_changes": [{"asset_id": "91609514063242777856043730063938310894548353925882406409927495687846407164056", "price": "0.34", "size": "0", "side": "SELL", "hash": "b6da36ea845abd1a2d963ddf35bc4a745f43c4c0", "best_bid": "0.31", "best_ask": "0.33"}, {"asset_id": "78438315737001038193507108078052969359305687599144926740526502005681502958823", "price": "0.66", "size": "0", "side": "BUY", "hash": "24fca510ea66c81d84257c37407a723734b81abb", "best_bid": "0.67", "best_ask": "0.69"}], "timestamp": "1769385017926", "event_type": "price_change"}}
{"_local_timestamp": "2026-01-25T23:50:18.153095+00:00", "data": {"market": "0xa9c0c820fd79b4339ed4711288ce15236196a6015234350f42b37341e9094398", "price_changes": [{"asset_id": "91609514063242777856043730063938310894548353925882406409927495687846407164056", "price": "0.02", "size": "256.21", "side": "BUY", "hash": "6b1afa9d16256b6a313600a13c1a8f6e7062fc30", "best_bid": "0.31", "best_ask": "0.33"}, {"asset_id": "78438315737001038193507108078052969359305687599144926740526502005681502958823", "price": "0.98", "size": "256.21", "side": "SELL", "hash": "907392fc0b86f7cc2b99822991d29c86126799d8", "best_bid": "0.67", "best_ask": "0.69"}], "timestamp": "1769385018010", "event_type": "price_change"}}
{"_local_timestamp": "2026-01-25T23:50:19.152245+00:00", "data": {"market": "0xa9c0c820fd79b4339ed4711288ce15236196a6015234350f42b37341e9094398", "price_changes": [{"asset_id": "78438315737001038193507108078052969359305687599144926740526502005681502958823", "price": "0.14", "size": "50", "side": "BUY", "hash": "db9edba59bb7ad50c35dd904d06d79be610b4cde", "best_bid": "0.67", "best_ask": "0.69"}, {"asset_id": "91609514063242777856043730063938310894548353925882406409927495687846407164056", "price": "0.86", "size": "50", "side": "SELL", "hash": "72b817826a44f23b78d89c7ee059d05dc6e2d86d", "best_bid": "0.31", "best_ask": "0.33"}], "timestamp": "1769385019062", "event_type": "price_change"}}
{"_local_timestamp": "2026-01-25T23:50:19.182356+00:00", "data": {"market": "0xa9c0c820fd79b4339ed4711288ce15236196a6015234350f42b37341e9094398", "price_changes": [{"asset_id": "78438315737001038193507108078052969359305687599144926740526502005681502958823", "price": "0.15", "size": "0", "side": "BUY", "hash": "056e92878a536e711d8eddb3463d6fce58b2e1c8", "best_bid": "0.67", "best_ask": "0.69"}, {"asset_id": "91609514063242777856043730063938310894548353925882406409927495687846407164056", "price": "0.85", "size": "0", "side": "SELL", "hash": "6a6d81f8dfec347f25349d324ea608b0316c0617", "best_bid": "0.31", "best_ask": "0.33"}], "timestamp": "1769385019095", "event_type": "price_change"}}
{"_local_timestamp": "2026-01-25T23:50:19.183647+00:00", "data": {"market": "0xa9c0c820fd79b4339ed4711288ce15236196a6015234350f42b37341e9094398", "price_changes": [{"asset_id": "78438315737001038193507108078052969359305687599144926740526502005681502958823", "price": "0.14", "size": "250", "side": "BUY", "hash": "439786f782112bbab2c9d34d237d7e5d9272e012", "best_bid": "0.67", "best_ask": "0.69"}, {"asset_id": "91609514063242777856043730063938310894548353925882406409927495687846407164056", "price": "0.86", "size": "250", "side": "SELL", "hash": "23700a9140b30c7bdc8886f2437ea9069933f1f8", "best_bid": "0.31", "best_ask": "0.33"}], "timestamp": "1769385019097", "event_type": "price_change"}}
{"_local_timestamp": "2026-01-25T23:50:19.212584+00:00", "data": {"market": "0xa9c0c820fd79b4339ed4711288ce15236196a6015234350f42b37341e9094398", "price_changes": [{"asset_id": "91609514063242777856043730063938310894548353925882406409927495687846407164056", "price": "0.34", "size": "6.8", "side": "SELL", "hash": "1eb756a8990682ff7769c997821923e37f6bb072", "best_bid": "0.31", "best_ask": "0.33"}, {"asset_id": "78438315737001038193507108078052969359305687599144926740526502005681502958823", "price": "0.66", "size": "6.8", "side": "BUY", "hash": "1769e8b33a504bc80ffc517036ea289229c7d354", "best_bid": "0.67", "best_ask": "0.69"}], "timestamp": "1769385019126", "event_type": "price_change"}}
{"_local_timestamp": "2026-01-25T23:50:19.422819+00:00", "data": {"market": "0xa9c0c820fd79b4339ed4711288ce15236196a6015234350f42b37341e9094398", "price_changes": [{"asset_id": "78438315737001038193507108078052969359305687599144926740526502005681502958823", "price": "0.15", "size": "200", "side": "BUY", "hash": "2c4876980afb5fb65becec3e2ab158ea1147e2d3", "best_bid": "0.67", "best_ask": "0.69"}, {"asset_id": "91609514063242777856043730063938310894548353925882406409927495687846407164056", "price": "0.85", "size": "200", "side": "SELL", "hash": "21030e0d505cb0a1cfbe6cd1cb9eec1a6612bac9", "best_bid": "0.31", "best_ask": "0.33"}], "timestamp": "1769385019317", "event_type": "price_change"}}
{"_local_timestamp": "2026-01-25T23:50:21.207547+00:00", "data": {"market": "0xa9c0c820fd79b4339ed4711288ce15236196a6015234350f42b37341e9094398", "price_changes": [{"asset_id": "78438315737001038193507108078052969359305687599144926740526502005681502958823", "price": "0.14", "size": "50", "side": "BUY", "hash": "0ae78e3c6b7caad5c49ebb2af534766529cc7ee7", "best_bid": "0.67", "best_ask": "0.69"}, {"asset_id": "91609514063242777856043730063938310894548353925882406409927495687846407164056", "price": "0.86", "size": "50", "side": "SELL", "hash": "42ee2922d89e391eaa42d9805cfc339636770b74", "best_bid": "0.31", "best_ask": "0.33"}], "timestamp": "1769385021096", "event_type": "price_change"}}
{"_local_timestamp": "2026-01-25T23:50:21.208856+00:00", "data": {"market": "0xa9c0c820fd79b4339ed4711288ce15236196a6015234350f42b37341e9094398", "price_changes": [{"asset_id": "78438315737001038193507108078052969359305687599144926740526502005681502958823", "price": "0.16", "size": "200", "side": "BUY", "hash": "1e75e33d3702abcf5e9447f0901b4401477f3901", "best_bid": "0.67", "best_ask": "0.69"}, {"asset_id": "91609514063242777856043730063938310894548353925882406409927495687846407164056", "price": "0.84", "size": "200", "side": "SELL", "hash": "dda3b72247bb55d1016415f3e8909e90c57fc95c", "best_bid": "0.31", "best_ask": "0.33"}], "timestamp": "1769385021098", "event_type": "price_change"}}
{"_local_timestamp": "2026-01-25T23:50:30.415698+00:00", "data": {"market": "0xa9c0c820fd79b4339ed4711288ce15236196a6015234350f42b37341e9094398", "price_changes": [{"asset_id": "78438315737001038193507108078052969359305687599144926740526502005681502958823", "price": "0.15", "size": "0", "side": "BUY", "hash": "bd543f498632be6753627599c6935a475ffa9564", "best_bid": "0.67", "best_ask": "0.69"}, {"asset_id": "91609514063242777856043730063938310894548353925882406409927495687846407164056", "price": "0.85", "size": "0", "side": "SELL", "hash": "8cf371cded891b01fcab22c02d73c3d7954894b7", "best_bid": "0.31", "best_ask": "0.33"}], "timestamp": "1769385030254", "event_type": "price_change"}}
{"_local_timestamp": "2026-01-25T23:50:30.449169+00:00", "data": {"market": "0xa9c0c820fd79b4339ed4711288ce15236196a6015234350f42b37341e9094398", "price_changes": [{"asset_id": "78438315737001038193507108078052969359305687599144926740526502005681502958823", "price": "0.16", "size": "0", "side": "BUY", "hash": "c923f39d806c3dde65710ca6c0defc4ee2e85dfd", "best_bid": "0.67", "best_ask": "0.69"}, {"asset_id": "91609514063242777856043730063938310894548353925882406409927495687846407164056", "price": "0.84", "size": "0", "side": "SELL", "hash": "5cf92837e76320332b7306df02a06a67e36ffae2", "best_bid": "0.31", "best_ask": "0.33"}], "timestamp": "1769385030295", "event_type": "price_change"}}
{"_local_timestamp": "2026-01-25T23:50:30.454218+00:00", "data": {"market": "0xa9c0c820fd79b4339ed4711288ce15236196a6015234350f42b37341e9094398", "price_changes": [{"asset_id": "78438315737001038193507108078052969359305687599144926740526502005681502958823", "price": "0.14", "size": "250", "side": "BUY", "hash": "c6371302bf0297897555ac11d6b61e24e263ed77", "best_bid": "0.67", "best_ask": "0.69"}, {"asset_id": "91609514063242777856043730063938310894548353925882406409927495687846407164056", "price": "0.86", "size": "250", "side": "SELL", "hash": "326ee11a8c6ade9887bff489ccb72021b294242c", "best_bid": "0.31", "best_ask": "0.33"}], "timestamp": "1769385030296", "event_type": "price_change"}}
{"_local_timestamp": "2026-01-25T23:50:30.685510+00:00", "data": {"market": "0xa9c0c820fd79b4339ed4711288ce15236196a6015234350f42b37341e9094398", "price_changes": [{"asset_id": "78438315737001038193507108078052969359305687599144926740526502005681502958823", "price": "0.11", "size": "200", "side": "BUY", "hash": "a7927a175911db32882531e4f82a36e794c11b1a", "best_bid": "0.67", "best_ask": "0.69"}, {"asset_id": "91609514063242777856043730063938310894548353925882406409927495687846407164056", "price": "0.89", "size": "200", "side": "SELL", "hash": "bee6fd50c76003b66632e75779ae129f85863f2f", "best_bid": "0.31", "best_ask": "0.33"}], "timestamp": "1769385030522", "event_type": "price_change"}}
{"_local_timestamp": "2026-01-25T23:50:35.941481+00:00", "data": {"market": "0xa9c0c820fd79b4339ed4711288ce15236196a6015234350f42b37341e9094398", "price_changes": [{"asset_id": "91609514063242777856043730063938310894548353925882406409927495687846407164056", "price": "0.02", "size": "156.21", "side": "BUY", "hash": "5b46d7cac87ce7545d56e5380fe252a410830999", "best_bid": "0.31", "best_ask": "0.33"}, {"asset_id": "78438315737001038193507108078052969359305687599144926740526502005681502958823", "price": "0.98", "size": "156.21", "side": "SELL", "hash": "3d37ddbfe6f0368f2d9e6c12fd9ed69e0379bc29", "best_bid": "0.67", "best_ask": "0.69"}], "timestamp": "1769385035736", "event_type": "price_change"}}
{"_local_timestamp": "2026-01-25T23:50:36.299319+00:00", "data": {"market": "0xa9c0c820fd79b4339ed4711288ce15236196a6015234350f42b37341e9094398", "price_changes": [{"asset_id": "91609514063242777856043730063938310894548353925882406409927495687846407164056", "price": "0.01", "size": "14375.55", "side": "BUY", "hash": "7702de9d931d42cbc73465d67551dc61a944c09d", "best_bid": "0.31", "best_ask": "0.33"}, {"asset_id": "78438315737001038193507108078052969359305687599144926740526502005681502958823", "price": "0.99", "size": "14375.55", "side": "SELL", "hash": "5e06d9a731ac2e5715e319bf603ef91e2152ed9c", "best_bid": "0.67", "best_ask": "0.69"}], "timestamp": "1769385036114", "event_type": "price_change"}}
{"_local_timestamp": "2026-01-25T23:50:40.974023+00:00", "data": {"market": "0xa9c0c820fd79b4339ed4711288ce15236196a6015234350f42b37341e9094398", "price_changes": [{"asset_id": "78438315737001038193507108078052969359305687599144926740526502005681502958823", "price": "0.11", "size": "0", "side": "BUY", "hash": "47b8e9615ba26149a335cecc740c8f2acabec77c", "best_bid": "0.67", "best_ask": "0.69"}, {"asset_id": "91609514063242777856043730063938310894548353925882406409927495687846407164056", "price": "0.89", "size": "0", "side": "SELL", "hash": "3768c86c07ead34011ac15afac6350fa0147ae38", "best_bid": "0.31", "best_ask": "0.33"}], "timestamp": "1769385040777", "event_type": "price_change"}}
{"_local_timestamp": "2026-01-25T23:50:41.245115+00:00", "data": {"market": "0xa9c0c820fd79b4339ed4711288ce15236196a6015234350f42b37341e9094398", "price_changes": [{"asset_id": "78438315737001038193507108078052969359305687599144926740526502005681502958823", "price": "0.14", "size": "450", "side": "BUY", "hash": "18c4d12f4e187f5d8f44130059037253736755d3", "best_bid": "0.67", "best_ask": "0.69"}, {"asset_id": "91609514063242777856043730063938310894548353925882406409927495687846407164056", "price": "0.86", "size": "450", "side": "SELL", "hash": "b83d751daade0221d0cbc317c12a29a5e48e6b86", "best_bid": "0.31", "best_ask": "0.33"}], "timestamp": "1769385041032", "event_type": "price_change"}}
{"_local_timestamp": "2026-01-25T23:50:41.277316+00:00", "data": {"market": "0xa9c0c820fd79b4339ed4711288ce15236196a6015234350f42b37341e9094398", "price_changes": [{"asset_id": "78438315737001038193507108078052969359305687599144926740526502005681502958823", "price": "0.14", "size": "250", "side": "BUY", "hash": "6bf8a8b77e248fc5091e0dcc9f7fba9fc920cd4b", "best_bid": "0.67", "best_ask": "0.69"}, {"asset_id": "91609514063242777856043730063938310894548353925882406409927495687846407164056", "price": "0.86", "size": "250", "side": "SELL", "hash": "9c95f26e0e20232d8f59688227367026486d2f3c", "best_bid": "0.31", "best_ask": "0.33"}], "timestamp": "1769385041093", "event_type": "price_change"}}
{"_local_timestamp": "2026-01-25T23:50:41.288354+00:00", "data": {"market": "0xa9c0c820fd79b4339ed4711288ce15236196a6015234350f42b37341e9094398", "price_changes": [{"asset_id": "78438315737001038193507108078052969359305687599144926740526502005681502958823", "price": "0.15", "size": "200", "side": "BUY", "hash": "c674cf030badb9d993ec77e907a5c53ab5907dc5", "best_bid": "0.67", "best_ask": "0.69"}, {"asset_id": "91609514063242777856043730063938310894548353925882406409927495687846407164056", "price": "0.85", "size": "200", "side": "SELL", "hash": "ed693277e176f4e6419aada9e51d03d00fdc7678", "best_bid": "0.31", "best_ask": "0.33"}], "timestamp": "1769385041102", "event_type": "price_change"}}
{"_local_timestamp": "2026-01-25T23:50:51.551445+00:00", "data": {"market": "0xa9c0c820fd79b4339ed4711288ce15236196a6015234350f42b37341e9094398", "price_changes": [{"asset_id": "78438315737001038193507108078052969359305687599144926740526502005681502958823", "price": "0.14", "size": "50", "side": "BUY", "hash": "3fee005ad5f2cbddec4c52b003ec59548866bb66", "best_bid": "0.67", "best_ask": "0.69"}, {"asset_id": "91609514063242777856043730063938310894548353925882406409927495687846407164056", "price": "0.86", "size": "50", "side": "SELL", "hash": "fe9ec6e4257c794d8711aa594f2b82c2bb220c5a", "best_bid": "0.31", "best_ask": "0.33"}], "timestamp": "1769385051476", "event_type": "price_change"}}
{"_local_timestamp": "2026-01-25T23:50:51.584907+00:00", "data": {"market": "0xa9c0c820fd79b4339ed4711288ce15236196a6015234350f42b37341e9094398", "price_changes": [{"asset_id": "78438315737001038193507108078052969359305687599144926740526502005681502958823", "price": "0.15", "size": "0", "side": "BUY", "hash": "dc08d93977d13b6b0fcbe8a29f8f39ca65c53977", "best_bid": "0.67", "best_ask": "0.69"}, {"asset_id": "91609514063242777856043730063938310894548353925882406409927495687846407164056", "price": "0.85", "size": "0", "side": "SELL", "hash": "858ad9fa096ff229e723cad49be2b01ffa51a4a8", "best_bid": "0.31", "best_ask": "0.33"}], "timestamp": "1769385051517", "event_type": "price_change"}}
{"_local_timestamp": "2026-01-25T23:50:51.586239+00:00", "data": {"market": "0xa9c0c820fd79b4339ed4711288ce15236196a6015234350f42b37341e9094398", "price_changes": [{"asset_id": "78438315737001038193507108078052969359305687599144926740526502005681502958823", "price": "0.14", "size": "250", "side": "BUY", "hash": "36b9ea364ca63cf00cd01288132a52e3f9629399", "best_bid": "0.67", "best_ask": "0.69"}, {"asset_id": "91609514063242777856043730063938310894548353925882406409927495687846407164056", "price": "0.86", "size": "250", "side": "SELL", "hash": "2d65348f401583fab23b968602f7d8935a275d47", "best_bid": "0.31", "best_ask": "0.33"}], "timestamp": "1769385051519", "event_type": "price_change"}}
{"_local_timestamp": "2026-01-25T23:50:51.807476+00:00", "data": {"market": "0xa9c0c820fd79b4339ed4711288ce15236196a6015234350f42b37341e9094398", "price_changes": [{"asset_id": "78438315737001038193507108078052969359305687599144926740526502005681502958823", "price": "0.15", "size": "200", "side": "BUY", "hash": "30f8c42fc4bbefa9bdac9d9fb965ff64ebbaa1cb", "best_bid": "0.67", "best_ask": "0.69"}, {"asset_id": "91609514063242777856043730063938310894548353925882406409927495687846407164056", "price": "0.85", "size": "200", "side": "SELL", "hash": "1ea054efc33aa85c173095b1d65983255c20faef", "best_bid": "0.31", "best_ask": "0.33"}], "timestamp": "1769385051742", "event_type": "price_change"}}
