{"_local_timestamp": "2026-01-25T23:33:46.588372+00:00", "data": [{"market": "0x17aa2a7b47add5eb5866ab5cb4d73fa9fbd57c756fabaa94dc37e8f38d497edd", "asset_id": "36807728890327710559603862263987214098176146352243963377959711142197687028836", "timestamp": "1769384025807", "hash": "f0d0fc363d245933ff5345606491ad34cf6edb1d", "bids": [], "asks": [{"price": "0.999", "size": "99999"}, {"price": "0.998", "size": "55000"}, {"price": "0.992", "size": "155"}, {"price": "0.99", "size": "27125.5"}, {"price": "0.989", "size": "55710"}, {"price": "0.92", "size": "155"}, {"price": "0.903", "size": "100"}, {"price": "0.901", "size": "100"}, {"price": "0.9", "size": "3500"}, {"price": "0.899", "size": "10000"}, {"price": "0.53", "size": "100"}, {"price": "0.51", "size": "100"}, {"price": "0.503", "size": "200"}, {"price": "0.501", "size": "100"}, {"price": "0.5", "size": "176"}, {"price": "0.25", "size": "60"}, {"price": "0.233", "size": "60"}, {"price": "0.232", "size": "777"}, {"price": "0.231", "size": "60"}, {"price": "0.23", "size": "60"}, {"price": "0.229", "size": "53"}, {"price": "0.228", "size": "5.51"}, {"price": "0.009", "size": "500"}, {"price": "0.008", "size": "182.43"}, {"price": "0.001", "size": "100009.58"}], "event_type": "book", "last_trade_price": ""}, {"market": "0x0158388d5142d4e9b565f2da3c6ce69b2756682b78fb0a9cab8840203a1a7a97", "asset_id": "61239095484488036374794236590506380508392866879329338142519253844360838103055", "timestamp": "1769384025808", "hash": "8cecbb58056ddf8062cf5a2ac0bed1d80a47abfb", "bids": [{"price": "0.001", "size": "99999"}, {"price": "0.002", "size": "55000"}, {"price": "0.008", "size": "155"}, {"price": "0.01", "size": "27125.5"}, {"price": "0.011", "size": "55710"}, {"price": "0.08", "size": "155"}, {"price": "0.097", "size": "100"}, {"price": "0.099", "size": "100"}, {"price": "0.1", "size": "3500"}, {"price": "0.101", "size": "10000"}, {"price": "0.47", "size": "100"}, {"price": "0.49", "size": "100"}, {"price": "0.497", "size": "200"}, {"price": "0.499", "size": "100"}, {"price": "0.5", "size": "176"}, {"price": "0.75", "size": "60"}, {"price": "0.767", "size": "60"}, {"price": "0.768", "size": "348"}, {"price": "0.769", "size": "60"}, {"price": "0.77", "size": "60"}, {"price": "0.771", "size": "53"}, {"price": "0.772", "size": "8.44"}, {"price": "0.991", "size": "500"}, {"price": "0.992", "size": "42.53"}, {"price": "0.999", "size": "100005.1"}], "asks": [], "event_type": "book", "last_trade_price": ""}, {"market": "0x17aa2a7b47add5eb5866ab5cb4d73fa9fbd57c756fabaa94dc37e8f38d497edd", "asset_id": "33315863711622601322794791550568071116800577811624103081392589319514271651144", "timestamp": "1769384025807", "hash": "37a21ddcb4adaee8f67600e018d2c2e98c3cb69a", "bids": [{"price": "0.001", "size": "99999"}, {"price": "0.002", "size": "55000"}, {"price": "0.008", "size": "155"}, {"price": "0.01", "size": "27125.5"}, {"price": "0.011", "size": "55710"}, {"price": "0.08", "size": "155"}, {"price": "0.097", "size": "100"}, {"price": "0.099", "size": "100"}, {"price": "0.1", "size": "3500"}, {"price": "0.101", "size": "10000"}, {"price": "0.47", "size": "100"}, {"price": "0.49", "size": "100"}, {"price": "0.497", "size": "200"}, {"price": "0.499", "size": "100"}, {"price": "0.5", "size": "176"}, {"price": "0.75", "size": "60"}, {"price": "0.767", "size": "60"}, {"price": "0.768", "size": "777"}, {"price": "0.769", "size": "60"}, {"price": "0.77", "size": "60"}, {"price": "0.771", "size": "53"}, {"price": "0.772", "size": "5.51"}, {"price": "0.991", "size": "500"}, {"price": "0.992", "size": "182.43"}, {"price": "0.999", "size": "100009.58"}], "asks": [], "event_type": "book", "last_trade_price": ""}, {"market": "0x0158388d5142d4e9b565f2da3c6ce69b2756682b78fb0a9cab8840203a1a7a97", "asset_id": "75227449954700285684044979609243838936234590419670661782079639952375897552885", "timestamp": "1769384025808", "hash": "6cb741bd8aac8f8b13e8fb7515760398ee23245e", "bids": [], "asks": [{"price": "0.999", "size": "99999"}, {"price": "0.998", "size": "55000"}, {"price": "0.992", "size": "155"}, {"price": "0.99", "size": "27125.5"}, {"price": "0.989", "size": "55710"}, {"price": "0.92", "size": "155"}, {"price": "0.903", "size": "100"}, {"price": "0.901", "size": "100"}, {"price": "0.9", "size": "3500"}, {"price": "0.899", "size": "10000"}, {"price": "0.53", "size": "100"}, {"price": "0.51", "size": "100"}, {"price": "0.503", "size": "200"}, {"price": "0.501", "size": "100"}, {"price": "0.5", "size": "176"}, {"price": "0.25", "size": "60"}, {"price": "0.233", "size": "60"}, {"price": "0.232", "size": "348"}, {"price": "0.231", "size": "60"}, {"price": "0.23", "size": "60"}, {"price": "0.229", "size": "53"}, {"price": "0.228", "size": "8.44"}, {"price": "0.009", "size": "500"}, {"price": "0.008", "size": "42.53"}, {"price": "0.001", "size": "100005.1"}], "event_type": "book", "last_trade_price": ""}, {"market": "0xe58a3bfab1a749e30d75907ef5b61a3092da48602ed1431054292efc86a541b5", "asset_id": "30945955821645377043120581432385562305707272746509870032635711882219904769766", "timestamp": "1769384025807", "hash": "1aa63165b9b9e08a939976cdd8fc18002413baec", "bids": [{"price": "0.001", "size": "99999"}, {"price": "0.002", "size": "55000"}, {"price": "0.008", "size": "155"}, {"price": "0.01", "size": "27125.5"}, {"price": "0.011", "size": "55710"}, {"price": "0.08", "size": "155"}, {"price": "0.097", "size": "100"}, {"price": "0.099", "size": "100"}, {"price": "0.1", "size": "3500"}, {"price": "0.101", "size": "10000"}, {"price": "0.2", "size": "125"}, {"price": "0.201", "size": "110"}, {"price": "0.22", "size": "68.75"}, {"price": "0.4", "size": "25"}, {"price": "0.47", "size": "100"}, {"price": "0.49", "size": "100"}, {"price": "0.497", "size": "200"}, {"price": "0.499", "size": "100"}, {"price": "0.5", "size": "70"}, {"price": "0.501", "size": "176"}, {"price": "0.52", "size": "55.62"}, {"price": "0.75", "size": "87.81"}, {"price": "0.767", "size": "60"}, {"price": "0.768", "size": "386"}, {"price": "0.769", "size": "60"}, {"price": "0.77", "size": "60"}, {"price": "0.771", "size": "53"}, {"price": "0.772", "size": "5.51"}, {"price": "0.991", "size": "500"}, {"price": "0.992", "size": "48.83"}, {"price": "0.999", "size": "100005.1"}], "asks": [], "event_type": "book", "last_trade_price": ""}, {"market": "0xbe2b566c0abcd3fe4336f9cbe88a75a87a78673f7a39d31d4a1462d4b3a50888", "asset_id": "588547079469173719335200872670318735548084093624857812256307179730394747376", "timestamp": "1769384025808", "hash": "c441d88b84affefeb7d7198420b9e9848498c97c", "bids": [{"price": "0.001", "size": "99999"}, {"price": "0.002", "size": "55000"}, {"price": "0.008", "size": "155"}, {"price": "0.01", "size": "27125.5"}, {"price": "0.011", "size": "55710"}, {"price": "0.08", "size": "155"}, {"price": "0.097", "size": "100"}, {"price": "0.099", "size": "100"}, {"price": "0.1", "size": "3500"}, {"price": "0.101", "size": "10000"}, {"price": "0.47", "size": "100"}, {"price": "0.49", "size": "100"}, {"price": "0.497", "size": "200"}, {"price": "0.499", "size": "100"}, {"price": "0.5", "size": "176"}, {"price": "0.75", "size": "60"}, {"price": "0.767", "size": "60"}, {"price": "0.768", "size": "572"}, {"price": "0.769", "size": "60"}, {"price": "0.77", "size": "60"}, {"price": "0.771", "size": "53"}, {"price": "0.991", "size": "500"}, {"price": "0.992", "size": "8.26"}, {"price": "0.993", "size": "5.51"}, {"price": "0.998", "size": "8.68"}, {"price": "0.999", "size": "100005.1"}], "asks": [], "event_type": "book", "last_trade_price": ""}, {"market": "0xe58a3bfab1a749e30d75907ef5b61a3092da48602ed1431054292efc86a541b5", "asset_id": "75715544777874521912630047471213807609822733955542285127781965528868344383311", "timestamp": "1769384025807", "hash": "264fe10e33dcc502594589dd26108c338480e030", "bids": [], "asks": [{"price": "0.999", "size": "99999"}, {"price": "0.998", "size": "55000"}, {"price": "0.992", "size": "155"}, {"price": "0.99", "size": "27125.5"}, {"price": "0.989", "size": "55710"}, {"price": "0.92", "size": "155"}, {"price": "0.903", "size": "100"}, {"price": "0.901", "size": "100"}, {"price": "0.9", "size": "3500"}, {"price": "0.899", "size": "10000"}, {"price": "0.8", "size": "125"}, {"price": "0.799", "size": "110"}, {"price": "0.78", "size": "68.75"}, {"price": "0.6", "size": "25"}, {"price": "0.53", "size": "100"}, {"price": "0.51", "size": "100"}, {"price": "0.503", "size": "200"}, {"price": "0.501", "size": "100"}, {"price": "0.5", "size": "70"}, {"price": "0.499", "size": "176"}, {"price": "0.48", "size": "55.62"}, {"price": "0.25", "size": "87.81"}, {"price": "0.233", "size": "60"}, {"price": "0.232", "size": "386"}, {"price": "0.231", "size": "60"}, {"price": "0.23", "size": "60"}, {"price": "0.229", "size": "53"}, {"price": "0.228", "size": "5.51"}, {"price": "0.009", "size": "500"}, {"price": "0.008", "size": "48.83"}, {"price": "0.001", "size": "100005.1"}], "event_type": "book", "last_trade_price": ""}, {"market": "0xbe2b566c0abcd3fe4336f9cbe88a75a87a78673f7a39d31d4a1462d4b3a50888", "asset_id": "102561262047601806822226924855483392449010925057820256596841768139789198414780", "timestamp": "1769384025808", "hash": "216389d188505c4730eaec667790617695398351", "bids": [], "asks": [{"price": "0.999", "size": "99999"}, {"price": "0.998", "size": "55000"}, {"price": "0.992", "size": "155"}, {"price": "0.99", "size": "27125.5"}, {"price": "0.989", "size": "55710"}, {"price": "0.92", "size": "155"}, {"price": "0.903", "size": "100"}, {"price": "0.901", "size": "100"}, {"price": "0.9", "size": "3500"}, {"price": "0.899", "size": "10000"}, {"price": "0.53", "size": "100"}, {"price": "0.51", "size": "100"}, {"price": "0.503", "size": "200"}, {"price": "0.501", "size": "100"}, {"price": "0.5", "size": "176"}, {"price": "0.25", "size": "60"}, {"price": "0.233", "size": "60"}, {"price": "0.232", "size": "572"}, {"price": "0.231", "size": "60"}, {"price": "0.23", "size": "60"}, {"price": "0.229", "size": "53"}, {"price": "0.009", "size": "500"}, {"price": "0.008", "size": "8.26"}, {"price": "0.007", "size": "5.51"}, {"price": "0.002", "size": "8.68"}, {"price": "0.001", "size": "100005.1"}], "event_type": "book", "last_trade_price": ""}]}
{"_local_timestamp": "2026-01-25T23:33:47.599664+00:00", "data": {"market": "0xbe2b566c0abcd3fe4336f9cbe88a75a87a78673f7a39d31d4a1462d4b3a50888", "price_changes": [{"asset_id": "588547079469173719335200872670318735548084093624857812256307179730394747376", "price": "0.999", "size": "102502.1", "side": "BUY", "hash": "aefbbc38ff4e17b21f39934e4fbb1a07e959a9cb", "best_bid": "0.999", "best_ask": "1"}, {"asset_id": "102561262047601806822226924855483392449010925057820256596841768139789198414780", "price": "0.001", "size": "102502.1", "side": "SELL", "hash": "164a8844ee1b599465da90bb98eb974a8604c8a7", "best_bid": "0", "best_ask": "0.001"}], "timestamp": "1769384027512", "event_type": "price_change"}}
{"_local_timestamp": "2026-01-25T23:33:47.603015+00:00", "data": {"market": "0x17aa2a7b47add5eb5866ab5cb4d73fa9fbd57c756fabaa94dc37e8f38d497edd", "price_changes": [{"asset_id": "33315863711622601322794791550568071116800577811624103081392589319514271651144", "price": "0.999", "size": "102506.58", "side": "BUY", "hash": "1c7ce85aad4927e8b3867b9c1a9a3ef5593b0f6e", "best_bid": "0.999", "best_ask": "1"}, {"asset_id": "36807728890327710559603862263987214098176146352243963377959711142197687028836", "price": "0.001", "size": "102506.58", "side": "SELL", "hash": "350c9c6978c721380a446fa1bd0baa5faac2a918", "best_bid": "0", "best_ask": "0.001"}], "timestamp": "1769384027512", "event_type": "price_change"}}
{"_local_timestamp": "2026-01-25T23:33:47.603798+00:00", "data": {"market": "0xe58a3bfab1a749e30d75907ef5b61a3092da48602ed1431054292efc86a541b5", "price_changes": [{"asset_id": "30945955821645377043120581432385562305707272746509870032635711882219904769766", "price": "0.999", "size": "102502.1", "side": "BUY", "hash": "4df1172fceffc88f85a08715e1f10de6d1cfc692", "best_bid": "0.999", "best_ask": "1"}, {"asset_id": "75715544777874521912630047471213807609822733955542285127781965528868344383311", "price": "0.001", "size": "102502.1", "side": "SELL", "hash": "9373aebb9a192e91bf513dd57d8b6316d400847c", "best_bid": "0", "best_ask": "0.001"}], "timestamp": "1769384027512", "event_type": "price_change"}}
{"_local_timestamp": "2026-01-25T23:33:47.610892+00:00", "data": {"market": "0x0158388d5142d4e9b565f2da3c6ce69b2756682b78fb0a9cab8840203a1a7a97", "price_changes": [{"asset_id": "61239095484488036374794236590506380508392866879329338142519253844360838103055", "price": "0.999", "size": "102502.1", "side": "BUY", "hash": "24b62a229e6100b2cdb5e4df7357e2d51c4a1704", "best_bid": "0.999", "best_ask": "1"}, {"asset_id": "75227449954700285684044979609243838936234590419670661782079639952375897552885", "price": "0.001", "size": "102502.1", "side": "SELL", "hash": "f86e45af5af7057bd8748c059b94cf1d9281d82b", "best_bid": "0", "best_ask": "0.001"}], "timestamp": "1769384027513", "event_type": "price_change"}}
{"_local_timestamp": "2026-01-25T23:33:48.024229+00:00", "data": {"market": "0xe58a3bfab1a749e30d75907ef5b61a3092da48602ed1431054292efc86a541b5", "price_changes": [{"asset_id": "30945955821645377043120581432385562305707272746509870032635711882219904769766", "price": "0.999", "size": "104998.1", "side": "BUY", "hash": "a203e0742f5c7f4601b13423d7a43bd17886b9f7", "best_bid": "0.999", "best_ask": "1"}, {"asset_id": "75715544777874521912630047471213807609822733955542285127781965528868344383311", "price": "0.001", "size": "104998.1", "side": "SELL", "hash": "0adf27ce5abe1b1c5dbdc7a98d2a23225562d492", "best_bid": "0", "best_ask": "0.001"}], "timestamp": "1769384027928", "event_type": "price_change"}}
{"_local_timestamp": "2026-01-25T23:33:48.031021+00:00", "data": {"market": "0xbe2b566c0abcd3fe4336f9cbe88a75a87a78673f7a39d31d4a1462d4b3a50888", "price_changes": [{"asset_id": "588547079469173719335200872670318735548084093624857812256307179730394747376", "price": "0.999", "size": "104998.1", "side": "BUY", "hash": "4e52dcf271851cbba85c4d36ace4d9a73d42ebd5", "best_bid": "0.999", "best_ask": "1"}, {"asset_id": "102561262047601806822226924855483392449010925057820256596841768139789198414780", "price": "0.001", "size": "104998.1", "side": "SELL", "hash": "ce21cfa37fab3b97bd6b6149434bf847be59d823", "best_bid": "0", "best_ask": "0.001"}], "timestamp": "1769384027928", "event_type": "price_change"}}
{"_local_timestamp": "2026-01-25T23:33:48.031445+00:00", "data": {"market": "0x0158388d5142d4e9b565f2da3c6ce69b2756682b78fb0a9cab8840203a1a7a97", "price_changes": [{"asset_id": "61239095484488036374794236590506380508392866879329338142519253844360838103055", "price": "0.999", "size": "104998.1", "side": "BUY", "hash": "f9c68df4c17e02f50018e5c4c2beff573f9db103", "best_bid": "0.999", "best_ask": "1"}, {"asset_id": "75227449954700285684044979609243838936234590419670661782079639952375897552885", "price": "0.001", "size": "104998.1", "side": "SELL", "hash": "93cf3d203e3f77dff3dd3e339d1d96bd3fe7e252", "best_bid": "0", "best_ask": "0.001"}], "timestamp": "1769384027928", "event_type": "price_change"}}
{"_local_timestamp": "2026-01-25T23:33:48.031730+00:00", "data": {"market": "0x17aa2a7b47add5eb5866ab5cb4d73fa9fbd57c756fabaa94dc37e8f38d497edd", "price_changes": [{"asset_id": "33315863711622601322794791550568071116800577811624103081392589319514271651144", "price": "0.999", "size": "105002.58", "side": "BUY", "hash": "c4f644ee4605353408fd9dac809d55b3dc847b7a", "best_bid": "0.999", "best_ask": "1"}, {"asset_id": "36807728890327710559603862263987214098176146352243963377959711142197687028836", "price": "0.001", "size": "105002.58", "side": "SELL", "hash": "dfdc9706fe58bd7f845e14eb19a7b5c36dea27d3", "best_bid": "0", "best_ask": "0.001"}], "timestamp": "1769384027928", "event_type": "price_change"}}
{"_local_timestamp": "2026-01-25T23:33:48.524121+00:00", "data": {"market": "0xbe2b566c0abcd3fe4336f9cbe88a75a87a78673f7a39d31d4a1462d4b3a50888", "price_changes": [{"asset_id": "588547079469173719335200872670318735548084093624857812256307179730394747376", "price": "0.999", "size": "107493.1", "side": "BUY", "hash": "0f8811ed8072ad6914abe39c3b2a88b1de5e058e", "best_bid": "0.999", "best_ask": "1"}, {"asset_id": "102561262047601806822226924855483392449010925057820256596841768139789198414780", "price": "0.001", "size": "107493.1", "side": "SELL", "hash": "d9905374f9915961d6ec5497db72e620ab0d7624", "best_bid": "0", "best_ask": "0.001"}], "timestamp": "1769384028434", "event_type": "price_change"}}
{"_local_timestamp": "2026-01-25T23:33:48.526873+00:00", "data": {"market": "0x0158388d5142d4e9b565f2da3c6ce69b2756682b78fb0a9cab8840203a1a7a97", "price_changes": [{"asset_id": "61239095484488036374794236590506380508392866879329338142519253844360838103055", "price": "0.999", "size": "107493.1", "side": "BUY", "hash": "97aaf0ebb34ef2f5488fa920b41d2ee3c91f24d4", "best_bid": "0.999", "best_ask": "1"}, {"asset_id": "75227449954700285684044979609243838936234590419670661782079639952375897552885", "price": "0.001", "size": "107493.1", "side": "SELL", "hash": "a477d053c9def519faf592dbca1a1cb7f58e0ac3", "best_bid": "0", "best_ask": "0.001"}], "timestamp": "1769384028434", "event_type": "price_change"}}
{"_local_timestamp": "2026-01-25T23:33:48.527585+00:00", "data": {"market": "0xe58a3bfab1a749e30d75907ef5b61a3092da48602ed1431054292efc86a541b5", "price_changes": [{"asset_id": "30945955821645377043120581432385562305707272746509870032635711882219904769766", "price": "0.999", "size": "107493.1", "side": "BUY", "hash": "d38b7da1ee3efe2c53f11dfef9d599d17ce4cded", "best_bid": "0.999", "best_ask": "1"}, {"asset_id": "75715544777874521912630047471213807609822733955542285127781965528868344383311", "price": "0.001", "size": "107493.1", "side": "SELL", "hash": "d983377c90fddfed06d81bc52142ac2f79477dcd", "best_bid": "0", "best_ask": "0.001"}], "timestamp": "1769384028434", "event_type": "price_change"}}
{"_local_timestamp": "2026-01-25T23:33:48.531174+00:00", "data": {"market": "0x17aa2a7b47add5eb5866ab5cb4d73fa9fbd57c756fabaa94dc37e8f38d497edd", "price_changes": [{"asset_id": "33315863711622601322794791550568071116800577811624103081392589319514271651144", "price": "0.999", "size": "107497.58", "side": "BUY", "hash": "c0ba98f22dd3f7048ddce376268d23b8e3bf8a65", "best_bid": "0.999", "best_ask": "1"}, {"asset_id": "36807728890327710559603862263987214098176146352243963377959711142197687028836", "price": "0.001", "size": "107497.58", "side": "SELL", "hash": "7aaa4782270371150e72c2f541692608a078a1e6", "best_bid": "0", "best_ask": "0.001"}], "timestamp": "1769384028435", "event_type": "price_change"}}
{"_local_timestamp": "2026-01-25T23:33:49.327982+00:00", "data": {"market": "0xbe2b566c0abcd3fe4336f9cbe88a75a87a78673f7a39d31d4a1462d4b3a50888", "price_changes": [{"asset_id": "588547079469173719335200872670318735548084093624857812256307179730394747376", "price": "0.999", "size": "108116.1", "side": "BUY", "hash": "b182e6992f73a092bb22da7a2ffa18f1b9c65ccb", "best_bid": "0.999", "best_ask": "1"}, {"asset_id": "102561262047601806822226924855483392449010925057820256596841768139789198414780", "price": "0.001", "size": "108116.1", "side": "SELL", "hash": "66becda7afb271c93547895d34e684626d924efc", "best_bid": "0", "best_ask": "0.001"}], "timestamp": "1769384029240", "event_type": "price_change"}}
{"_local_timestamp": "2026-01-25T23:33:49.328438+00:00", "data": {"market": "0x17aa2a7b47add5eb5866ab5cb4d73fa9fbd57c756fabaa94dc37e8f38d497edd", "price_changes": [{"asset_id": "33315863711622601322794791550568071116800577811624103081392589319514271651144", "price": "0.999", "size": "108120.58", "side": "BUY", "hash": "7f33540d8b431f5eda85f7098f4003abd59c1efc", "best_bid": "0.999", "best_ask": "1"}, {"asset_id": "36807728890327710559603862263987214098176146352243963377959711142197687028836", "price": "0.001", "size": "108120.58", "side": "SELL", "hash": "637c3ed6d16c7f7f87e26ae7813dbd7ae2c688d7", "best_bid": "0", "best_ask": "0.001"}], "timestamp": "1769384029240", "event_type": "price_change"}}
{"_local_timestamp": "2026-01-25T23:33:49.328760+00:00", "data": {"market": "0x0158388d5142d4e9b565f2da3c6ce69b2756682b78fb0a9cab8840203a1a7a97", "price_changes": [{"asset_id": "61239095484488036374794236590506380508392866879329338142519253844360838103055", "price": "0.999", "size": "108116.1", "side": "BUY", "hash": "37b169527eeb0149903f249266bdd0f39f242bcf", "best_bid": "0.999", "best_ask": "1"}, {"asset_id": "75227449954700285684044979609243838936234590419670661782079639952375897552885", "price": "0.001", "size": "108116.1", "side": "SELL", "hash": "53334418bc98bbee54c90e21853c778161d681f7", "best_bid": "0", "best_ask": "0.001"}], "timestamp": "1769384029240", "event_type": "price_change"}}
{"_local_timestamp": "2026-01-25T23:33:49.330343+00:00", "data": {"market": "0xe58a3bfab1a749e30d75907ef5b61a3092da48602ed1431054292efc86a541b5", "price_changes": [{"asset_id": "30945955821645377043120581432385562305707272746509870032635711882219904769766", "price": "0.999", "size": "108116.1", "side": "BUY", "hash": "428117a2015c9d76533da16eccae9e3e2d979eeb", "best_bid": "0.999", "best_ask": "1"}, {"asset_id": "75715544777874521912630047471213807609822733955542285127781965528868344383311", "price": "0.001", "size": "108116.1", "side": "SELL", "hash": "eb6e3dc1590b86a5954745d6cdc844f57eeba198", "best_bid": "0", "best_ask": "0.001"}], "timestamp": "1769384029240", "event_type": "price_change"}}
{"_local_timestamp": "2026-01-25T23:33:49.794715+00:00", "data": {"market": "0xbe2b566c0abcd3fe4336f9cbe88a75a87a78673f7a39d31d4a1462d4b3a50888", "price_changes": [{"asset_id": "588547079469173719335200872670318735548084093624857812256307179730394747376", "price": "0.999", "size": "108738.1", "side": "BUY", "hash": "906d6804169dec5df0dd9fdd249bdc5d3d8049cd", "best_bid": "0.999", "best_ask": "1"}, {"asset_id": "102561262047601806822226924855483392449010925057820256596841768139789198414780", "price": "0.001", "size": "108738.1", "side": "SELL", "hash": "c29c3441bc57f528325ecdce582164e528056e23", "best_bid": "0", "best_ask": "0.001"}], "timestamp": "1769384029720", "event_type": "price_change"}}
{"_local_timestamp": "2026-01-25T23:33:49.795053+00:00", "data": {"market": "0xe58a3bfab1a749e30d75907ef5b61a3092da48602ed1431054292efc86a541b5", "price_changes": [{"asset_id": "30945955821645377043120581432385562305707272746509870032635711882219904769766", "price": "0.999", "size": "108738.1", "side": "BUY", "hash": "f1aa37c4a784b80942904daf6f13299727f48b4f", "best_bid": "0.999", "best_ask": "1"}, {"asset_id": "75715544777874521912630047471213807609822733955542285127781965528868344383311", "price": "0.001", "size": "108738.1", "side": "SELL", "hash": "5e54019e18caf92cc721ac2e0d0d7cc9d24baaa6", "best_bid": "0", "best_ask": "0.001"}], "timestamp": "1769384029722", "event_type": "price_change"}}
{"_local_timestamp": "2026-01-25T23:33:49.805436+00:00", "data": {"market": "0x17aa2a7b47add5eb5866ab5cb4d73fa9fbd57c756fabaa94dc37e8f38d497edd", "price_changes": [{"asset_id": "33315863711622601322794791550568071116800577811624103081392589319514271651144", "price": "0.999", "size": "108742.58", "side": "BUY", "hash": "56399082531d57023504ef532189d8fa41dfbae9", "best_bid": "0.999", "best_ask": "1"}, {"asset_id": "36807728890327710559603862263987214098176146352243963377959711142197687028836", "price": "0.001", "size": "108742.58", "side": "SELL", "hash": "a7e33dcfb397bbb6400b3f46801e863376863237", "best_bid": "0", "best_ask": "0.001"}], "timestamp": "1769384029720", "event_type": "price_change"}}
{"_local_timestamp": "2026-01-25T23:33:49.805775+00:00", "data": {"market": "0x0158388d5142d4e9b565f2da3c6ce69b2756682b78fb0a9cab8840203a1a7a97", "price_changes": [{"asset_id": "61239095484488036374794236590506380508392866879329338142519253844360838103055", "price": "0.999", "size": "108738.1", "side": "BUY", "hash": "6272a1bf26e3ed81e6ec95f33998a63f5d550d02", "best_bid": "0.999", "best_ask": "1"}, {"asset_id": "75227449954700285684044979609243838936234590419670661782079639952375897552885", "price": "0.001", "size": "108738.1", "side": "SELL", "hash": "4a8ba89fc6f3fe0cb090cd9a91b4411c937bb7a2", "best_bid": "0", "best_ask": "0.001"}], "timestamp": "1769384029721", "event_type": "price_change"}}
{"_local_timestamp": "2026-01-25T23:33:51.610448+00:00", "data": {"market": "0xbe2b566c0abcd3fe4336f9cbe88a75a87a78673f7a39d31d4a1462d4b3a50888", "price_changes": [{"asset_id": "588547079469173719335200872670318735548084093624857812256307179730394747376", "price": "0.999", "size": "108893.1", "side": "BUY", "hash": "6f6ed2bfa2605d1c2f6a9b60186ac8db8664fca3", "best_bid": "0.999", "best_ask": "1"}, {"asset_id": "102561262047601806822226924855483392449010925057820256596841768139789198414780", "price": "0.001", "size": "108893.1", "side": "SELL", "hash": "34bb1c808a63430b46997393bde4713309f123c2", "best_bid": "0", "best_ask": "0.001"}], "timestamp": "1769384031545", "event_type": "price_change"}}
{"_local_timestamp": "2026-01-25T23:33:51.610906+00:00", "data": {"market": "0xe58a3bfab1a749e30d75907ef5b61a3092da48602ed1431054292efc86a541b5", "price_changes": [{"asset_id": "30945955821645377043120581432385562305707272746509870032635711882219904769766", "price": "0.999", "size": "108893.1", "side": "BUY", "hash": "33178c2626ac6a99b4a6e9b0b72c1aeeab58b0f4", "best_bid": "0.999", "best_ask": "1"}, {"asset_id": "75715544777874521912630047471213807609822733955542285127781965528868344383311", "price": "0.001", "size": "108893.1", "side": "SELL", "hash": "10321a196bbb9f84dcc9e523e4cb60ebfaf6c0ad", "best_bid": "0", "best_ask": "0.001"}], "timestamp": "1769384031545", "event_type": "price_change"}}
{"_local_timestamp": "2026-01-25T23:33:51.611201+00:00", "data": {"market": "0x0158388d5142d4e9b565f2da3c6ce69b2756682b78fb0a9cab8840203a1a7a97", "price_changes": [{"asset_id": "61239095484488036374794236590506380508392866879329338142519253844360838103055", "price": "0.999", "size": "108893.1", "side": "BUY", "hash": "18578220e84a21cb39ce741efa1405002249e650", "best_bid": "0.999", "best_ask": "1"}, {"asset_id": "75227449954700285684044979609243838936234590419670661782079639952375897552885", "price": "0.001", "size": "108893.1", "side": "SELL", "hash": "93227a80edb79eec20b9a1437bda80d4caf5e3d4", "best_bid": "0", "best_ask": "0.001"}], "timestamp": "1769384031545", "event_type": "price_change"}}
{"_local_timestamp": "2026-01-25T23:33:51.611523+00:00", "data": {"market": "0x17aa2a7b47add5eb5866ab5cb4d73fa9fbd57c756fabaa94dc37e8f38d497edd", "price_changes": [{"asset_id": "33315863711622601322794791550568071116800577811624103081392589319514271651144", "price": "0.999", "size": "108897.58", "side": "BUY", "hash": "cc7ba5dd055a2e7595972da98841acf2eefeefbd", "best_bid": "0.999", "best_ask": "1"}, {"asset_id": "36807728890327710559603862263987214098176146352243963377959711142197687028836", "price": "0.001", "size": "108897.58", "side": "SELL", "hash": "69db7db7bc83b163315a39612a628981a86e1164", "best_bid": "0", "best_ask": "0.001"}], "timestamp": "1769384031545", "event_type": "price_change"}}
{"_local_timestamp": "2026-01-25T23:33:52.595392+00:00", "data": {"market": "0xe58a3bfab1a749e30d75907ef5b61a3092da48602ed1431054292efc86a541b5", "price_changes": [{"asset_id": "30945955821645377043120581432385562305707272746509870032635711882219904769766", "price": "0.999", "size": "109047.1", "side": "BUY", "hash": "365ba63ed0e886d612061d5d2d009db29260ef28", "best_bid": "0.999", "best_ask": "1"}, {"asset_id": "75715544777874521912630047471213807609822733955542285127781965528868344383311", "price": "0.001", "size": "109047.1", "side": "SELL", "hash": "58316a6024000cee5152716cb1f224ef3bd823f4", "best_bid": "0", "best_ask": "0.001"}], "timestamp": "1769384032528", "event_type": "price_change"}}
{"_local_timestamp": "2026-01-25T23:33:52.596719+00:00", "data": {"market": "0x0158388d5142d4e9b565f2da3c6ce69b2756682b78fb0a9cab8840203a1a7a97", "price_changes": [{"asset_id": "61239095484488036374794236590506380508392866879329338142519253844360838103055", "price": "0.999", "size": "109047.1", "side": "BUY", "hash": "9e6791a8da0165b788ba2f3b34ec056a889cef1b", "best_bid": "0.999", "best_ask": "1"}, {"asset_id": "75227449954700285684044979609243838936234590419670661782079639952375897552885", "price": "0.001", "size": "109047.1", "side": "SELL", "hash": "e450b59ce78909a0627ec9bf9950ed4884e8228a", "best_bid": "0", "best_ask": "0.001"}], "timestamp": "1769384032528", "event_type": "price_change"}}
{"_local_timestamp": "2026-01-25T23:33:52.597112+00:00", "data": {"market": "0x17aa2a7b47add5eb5866ab5cb4d73fa9fbd57c756fabaa94dc37e8f38d497edd", "price_changes": [{"asset_id": "33315863711622601322794791550568071116800577811624103081392589319514271651144", "price": "0.999", "size": "109051.58", "side": "BUY", "hash": "73b9fa6682edd8dffce9211bb5dc7c1a41f980e0", "best_bid": "0.999", "best_ask": "1"}, {"asset_id": "36807728890327710559603862263987214098176146352243963377959711142197687028836", "price": "0.001", "size": "109051.58", "side": "SELL", "hash": "8c07992b6d35439a58307654ae0cfedc2865f3e1", "best_bid": "0", "best_ask": "0.001"}], "timestamp": "1769384032528", "event_type": "price_change"}}
{"_local_timestamp": "2026-01-25T23:33:52.597547+00:00", "data": {"market": "0xbe2b566c0abcd3fe4336f9cbe88a75a87a78673f7a39d31d4a1462d4b3a50888", "price_changes": [{"asset_id": "588547079469173719335200872670318735548084093624857812256307179730394747376", "price": "0.999", "size": "109047.1", "side": "BUY", "hash": "17730e1bec2981d875eabb7bc8a5436133c26e04", "best_bid": "0.999", "best_ask": "1"}, {"asset_id": "102561262047601806822226924855483392449010925057820256596841768139789198414780", "price": "0.001", "size": "109047.1", "side": "SELL", "hash": "66dc727463f36002f6c014626eb2aaec0874bda2", "best_bid": "0", "best_ask": "0.001"}], "timestamp": "1769384032528", "event_type": "price_change"}}
{"_local_timestamp": "2026-01-25T23:33:52.972142+00:00", "data": {"market": "0xbe2b566c0abcd3fe4336f9cbe88a75a87a78673f7a39d31d4a1462d4b3a50888", "price_changes": [{"asset_id": "588547079469173719335200872670318735548084093624857812256307179730394747376", "price": "0.999", "size": "109200.1", "side": "BUY", "hash": "5af595cf47d9f65393b1e870b9f01e916104c626", "best_bid": "0.999", "best_ask": "1"}, {"asset_id": "102561262047601806822226924855483392449010925057820256596841768139789198414780", "price": "0.001", "size": "109200.1", "side": "SELL", "hash": "3f708f074b302c24418ce86a75d05e2b5f5b5b20", "best_bid": "0", "best_ask": "0.001"}], "timestamp": "1769384032895", "event_type": "price_change"}}
{"_local_timestamp": "2026-01-25T23:33:52.972549+00:00", "data": {"market": "0x0158388d5142d4e9b565f2da3c6ce69b2756682b78fb0a9cab8840203a1a7a97", "price_changes": [{"asset_id": "61239095484488036374794236590506380508392866879329338142519253844360838103055", "price": "0.999", "size": "109200.1", "side": "BUY", "hash": "8ad853494ffc878e205abb3631625fabf41d7354", "best_bid": "0.999", "best_ask": "1"}, {"asset_id": "75227449954700285684044979609243838936234590419670661782079639952375897552885", "price": "0.001", "size": "109200.1", "side": "SELL", "hash": "64e0e65cbb2e7fc31515f8aef039477d796d10db", "best_bid": "0", "best_ask": "0.001"}], "timestamp": "1769384032895", "event_type": "price_change"}}
{"_local_timestamp": "2026-01-25T23:33:52.973011+00:00", "data": {"market": "0xe58a3bfab1a749e30d75907ef5b61a3092da48602ed1431054292efc86a541b5", "price_changes": [{"asset_id": "30945955821645377043120581432385562305707272746509870032635711882219904769766", "price": "0.999", "size": "109200.1", "side": "BUY", "hash": "c1913d97fa540a8643a65340139269547ff645c5", "best_bid": "0.999", "best_ask": "1"}, {"asset_id": "75715544777874521912630047471213807609822733955542285127781965528868344383311", "price": "0.001", "size": "109200.1", "side": "SELL", "hash": "024299a666d14d5d6403267cac61a98be770d975", "best_bid": "0", "best_ask": "0.001"}], "timestamp": "1769384032894", "event_type": "price_change"}}
{"_local_timestamp": "2026-01-25T23:33:52.973364+00:00", "data": {"market": "0x17aa2a7b47add5eb5866ab5cb4d73fa9fbd57c756fabaa94dc37e8f38d497edd", "price_changes": [{"asset_id": "33315863711622601322794791550568071116800577811624103081392589319514271651144", "price": "0.999", "size": "109204.58", "side": "BUY", "hash": "a692210c0944bb8991c8f0443d0cc5185dda6dcb", "best_bid": "0.999", "best_ask": "1"}, {"asset_id": "36807728890327710559603862263987214098176146352243963377959711142197687028836", "price": "0.001", "size": "109204.58", "side": "SELL", "hash": "30ef2c534c04eb83d110f486ef8f754ee95e8a16", "best_bid": "0", "best_ask": "0.001"}], "timestamp": "1769384032895", "event_type": "price_change"}}
{"_local_timestamp": "2026-01-25T23:33:54.567184+00:00", "data": {"market": "0xbe2b566c0abcd3fe4336f9cbe88a75a87a78673f7a39d31d4a1462d4b3a50888", "price_changes": [{"asset_id": "588547079469173719335200872670318735548084093624857812256307179730394747376", "price": "0.999", "size": "109237.1", "side": "BUY", "hash": "d8d693cc5b2d221afb0540dafaa2d35fde434433", "best_bid": "0.999", "best_ask": "1"}, {"asset_id": "102561262047601806822226924855483392449010925057820256596841768139789198414780", "price": "0.001", "size": "109237.1", "side": "SELL", "hash": "191aa649b70c4a607d91e3b4731bd3ee6526cc46", "best_bid": "0", "best_ask": "0.001"}], "timestamp": "1769384034491", "event_type": "price_change"}}
{"_local_timestamp": "2026-01-25T23:33:54.581795+00:00", "data": {"market": "0xe58a3bfab1a749e30d75907ef5b61a3092da48602ed1431054292efc86a541b5", "price_changes": [{"asset_id": "30945955821645377043120581432385562305707272746509870032635711882219904769766", "price": "0.999", "size": "109237.1", "side": "BUY", "hash": "d03ca945659748d4d2bbbbefd94aa4ad98558300", "best_bid": "0.999", "best_ask": "1"}, {"asset_id": "75715544777874521912630047471213807609822733955542285127781965528868344383311", "price": "0.001", "size": "109237.1", "side": "SELL", "hash": "94ad5df452c4c42f5c6d79e3f11790e639ae7a73", "best_bid": "0", "best_ask": "0.001"}], "timestamp": "1769384034491", "event_type": "price_change"}}
{"_local_timestamp": "2026-01-25T23:33:54.582127+00:00", "data": {"market": "0x0158388d5142d4e9b565f2da3c6ce69b2756682b78fb0a9cab8840203a1a7a97", "price_changes": [{"asset_id": "61239095484488036374794236590506380508392866879329338142519253844360838103055", "price": "0.999", "size": "109237.1", "side": "BUY", "hash": "ec81e36cb177ec9ea582a892c1f2d2bcd059be77", "best_bid": "0.999", "best_ask": "1"}, {"asset_id": "75227449954700285684044979609243838936234590419670661782079639952375897552885", "price": "0.001", "size": "109237.1", "side": "SELL", "hash": "8666ffbe987ffab30faa396d021621f099ea0e2e", "best_bid": "0", "best_ask": "0.001"}], "timestamp": "1769384034491", "event_type": "price_change"}}
{"_local_timestamp": "2026-01-25T23:33:54.582391+00:00", "data": {"market": "0x17aa2a7b47add5eb5866ab5cb4d73fa9fbd57c756fabaa94dc37e8f38d497edd", "price_changes": [{"asset_id": "33315863711622601322794791550568071116800577811624103081392589319514271651144", "price": "0.999", "size": "109241.58", "side": "BUY", "hash": "b08fa380154932a57dc023c91d1e6fe2308507ec", "best_bid": "0.999", "best_ask": "1"}, {"asset_id": "36807728890327710559603862263987214098176146352243963377959711142197687028836", "price": "0.001", "size": "109241.58", "side": "SELL", "hash": "2651f944221ee1a0468a46b02e52ad013d6b7241", "best_bid": "0", "best_ask": "0.001"}], "timestamp": "1769384034491", "event_type": "price_change"}}
{"_local_timestamp": "2026-01-25T23:33:55.138522+00:00", "data": {"market": "0xbe2b566c0abcd3fe4336f9cbe88a75a87a78673f7a39d31d4a1462d4b3a50888", "price_changes": [{"asset_id": "588547079469173719335200872670318735548084093624857812256307179730394747376", "price": "0.999", "size": "109273.1", "side": "BUY", "hash": "0c1eb1d5744810e4cb37b34c7dc5a7b25a4690af", "best_bid": "0.999", "best_ask": "1"}, {"asset_id": "102561262047601806822226924855483392449010925057820256596841768139789198414780", "price": "0.001", "size": "109273.1", "side": "SELL", "hash": "ef0e367a8acc434092939913354aeb4d323319c3", "best_bid": "0", "best_ask": "0.001"}], "timestamp": "1769384035072", "event_type": "price_change"}}
{"_local_timestamp": "2026-01-25T23:33:55.139005+00:00", "data": {"market": "0xe58a3bfab1a749e30d75907ef5b61a3092da48602ed1431054292efc86a541b5", "price_changes": [{"asset_id": "30945955821645377043120581432385562305707272746509870032635711882219904769766", "price": "0.999", "size": "109273.1", "side": "BUY", "hash": "c6a7d405281b11afd4a0c9f2c7f01ab97a414c85", "best_bid": "0.999", "best_ask": "1"}, {"asset_id": "75715544777874521912630047471213807609822733955542285127781965528868344383311", "price": "0.001", "size": "109273.1", "side": "SELL", "hash": "a3838a33f37e4d38c6656f1a162c2cd602c1f4a2", "best_bid": "0", "best_ask": "0.001"}], "timestamp": "1769384035072", "event_type": "price_change"}}
{"_local_timestamp": "2026-01-25T23:33:55.139405+00:00", "data": {"market": "0x0158388d5142d4e9b565f2da3c6ce69b2756682b78fb0a9cab8840203a1a7a97", "price_changes": [{"asset_id": "61239095484488036374794236590506380508392866879329338142519253844360838103055", "price": "0.999", "size": "109273.1", "side": "BUY", "hash": "c3522a37e44138b055b1a5469141fc00f0c02e35", "best_bid": "0.999", "best_ask": "1"}, {"asset_id": "75227449954700285684044979609243838936234590419670661782079639952375897552885", "price": "0.001", "size": "109273.1", "side": "SELL", "hash": "fa9f9eeecdbf9dbc52c89dd6331bc61ec8b3adc6", "best_bid": "0", "best_ask": "0.001"}], "timestamp": "1769384035072", "event_type": "price_change"}}
{"_local_timestamp": "2026-01-25T23:33:55.139711+00:00", "data": {"market": "0x17aa2a7b47add5eb5866ab5cb4d73fa9fbd57c756fabaa94dc37e8f38d497edd", "price_changes": [{"asset_id": "33315863711622601322794791550568071116800577811624103081392589319514271651144", "price": "0.999", "size": "109277.58", "side": "BUY", "hash": "a1730acc6108a7c6d90e4a57d49d0e43036e0bf9", "best_bid": "0.999", "best_ask": "1"}, {"asset_id": "36807728890327710559603862263987214098176146352243963377959711142197687028836", "price": "0.001", "size": "109277.58", "side": "SELL", "hash": "61c57ee7ae1be5612c7e49fcd745873df9b360d2", "best_bid": "0", "best_ask": "0.001"}], "timestamp": "1769384035072", "event_type": "price_change"}}
{"_local_timestamp": "2026-01-25T23:33:55.607622+00:00", "data": {"market": "0xe58a3bfab1a749e30d75907ef5b61a3092da48602ed1431054292efc86a541b5", "price_changes": [{"asset_id": "30945955821645377043120581432385562305707272746509870032635711882219904769766", "price": "0.999", "size": "109308.1", "side": "BUY", "hash": "7b978ec9b7f78b330fc40953c68f2643c17a944f", "best_bid": "0.999", "best_ask": "1"}, {"asset_id": "75715544777874521912630047471213807609822733955542285127781965528868344383311", "price": "0.001", "size": "109308.1", "side": "SELL", "hash": "433ab94b3c4d7b04f6182a130daeb418ddbb1b64", "best_bid": "0", "best_ask": "0.001"}], "timestamp": "1769384035528", "event_type": "price_change"}}
{"_local_timestamp": "2026-01-25T23:33:55.609926+00:00", "data": {"market": "0xbe2b566c0abcd3fe4336f9cbe88a75a87a78673f7a39d31d4a1462d4b3a50888", "price_changes": [{"asset_id": "588547079469173719335200872670318735548084093624857812256307179730394747376", "price": "0.999", "size": "109308.1", "side": "BUY", "hash": "c713e834561f7a82487938ace081493a61639c16", "best_bid": "0.999", "best_ask": "1"}, {"asset_id": "102561262047601806822226924855483392449010925057820256596841768139789198414780", "price": "0.001", "size": "109308.1", "side": "SELL", "hash": "a6f78f82f0428c97559983efd2b0a9b9d82a37a1", "best_bid": "0", "best_ask": "0.001"}], "timestamp": "1769384035529", "event_type": "price_change"}}
{"_local_timestamp": "2026-01-25T23:33:55.611580+00:00", "data": {"market": "0x17aa2a7b47add5eb5866ab5cb4d73fa9fbd57c756fabaa94dc37e8f38d497edd", "price_changes": [{"asset_id": "33315863711622601322794791550568071116800577811624103081392589319514271651144", "price": "0.999", "size": "109312.58", "side": "BUY", "hash": "cf6c14d10275dcf0d3e0f551375b6b62eabefae2", "best_bid": "0.999", "best_ask": "1"}, {"asset_id": "36807728890327710559603862263987214098176146352243963377959711142197687028836", "price": "0.001", "size": "109312.58", "side": "SELL", "hash": "7d8fb36dc5a7121197c56e49213b28615e45fc13", "best_bid": "0", "best_ask": "0.001"}], "timestamp": "1769384035528", "event_type": "price_change"}}
{"_local_timestamp": "2026-01-25T23:33:55.615599+00:00", "data": {"market": "0x0158388d5142d4e9b565f2da3c6ce69b2756682b78fb0a9cab8840203a1a7a97", "price_changes": [{"asset_id": "61239095484488036374794236590506380508392866879329338142519253844360838103055", "price": "0.999", "size": "109308.1", "side": "BUY", "hash": "f75e35083e7ef77be0bbf04ea9a34e12da28f306", "best_bid": "0.999", "best_ask": "1"}, {"asset_id": "75227449954700285684044979609243838936234590419670661782079639952375897552885", "price": "0.001", "size": "109308.1", "side": "SELL", "hash": "89e7ede8ad9e31d72c75e58258a4f127e31d7920", "best_bid": "0", "best_ask": "0.001"}], "timestamp": "1769384035529", "event_type": "price_change"}}
{"_local_timestamp": "2026-01-25T23:34:07.984886+00:00", "data": {"market": "0xbe2b566c0abcd3fe4336f9cbe88a75a87a78673f7a39d31d4a1462d4b3a50888", "price_changes": [{"asset_id": "588547079469173719335200872670318735548084093624857812256307179730394747376", "price": "0.999", "size": "104998.1", "side": "BUY", "hash": "cfedd0e9400948da067ec1f9a2821a60a24597ef", "best_bid": "0.999", "best_ask": "1"}, {"asset_id": "102561262047601806822226924855483392449010925057820256596841768139789198414780", "price": "0.001", "size": "104998.1", "side": "SELL", "hash": "2a8b97b25ab048c20cfd61b7cb9b03b8a70c5dee", "best_bid": "0", "best_ask": "0.001"}], "timestamp": "1769384047890", "event_type": "price_change"}}
{"_local_timestamp": "2026-01-25T23:34:08.007246+00:00", "data": {"market": "0xe58a3bfab1a749e30d75907ef5b61a3092da48602ed1431054292efc86a541b5", "price_changes": [{"asset_id": "30945955821645377043120581432385562305707272746509870032635711882219904769766", "price": "0.999", "size": "104998.1", "side": "BUY", "hash": "455a29161bfb6d7645abe13ed7cab7e7e0e58379", "best_bid": "0.999", "best_ask": "1"}, {"asset_id": "75715544777874521912630047471213807609822733955542285127781965528868344383311", "price": "0.001", "size": "104998.1", "side": "SELL", "hash": "0a534796a93ba560269c70fdcfaca53583708bf2", "best_bid": "0", "best_ask": "0.001"}], "timestamp": "1769384047891", "event_type": "price_change"}}
{"_local_timestamp": "2026-01-25T23:34:08.009438+00:00", "data": {"market": "0x0158388d5142d4e9b565f2da3c6ce69b2756682b78fb0a9cab8840203a1a7a97", "price_changes": [{"asset_id": "61239095484488036374794236590506380508392866879329338142519253844360838103055", "price": "0.999", "size": "104998.1", "side": "BUY", "hash": "e4808cd00bdeeac8968890b2642914ea0a78322a", "best_bid": "0.999", "best_ask": "1"}, {"asset_id": "75227449954700285684044979609243838936234590419670661782079639952375897552885", "price": "0.001", "size": "104998.1", "side": "SELL", "hash": "6e63cae7d926ef64862aff6434576945073708b5", "best_bid": "0", "best_ask": "0.001"}], "timestamp": "1769384047890", "event_type": "price_change"}}
{"_local_timestamp": "2026-01-25T23:34:08.010277+00:00", "data": {"market": "0x17aa2a7b47add5eb5866ab5cb4d73fa9fbd57c756fabaa94dc37e8f38d497edd", "price_changes": [{"asset_id": "33315863711622601322794791550568071116800577811624103081392589319514271651144", "price": "0.999", "size": "105002.58", "side": "BUY", "hash": "65158496bf0beba257ed592f486575a45f63f512", "best_bid": "0.999", "best_ask": "1"}, {"asset_id": "36807728890327710559603862263987214098176146352243963377959711142197687028836", "price": "0.001", "size": "105002.58", "side": "SELL", "hash": "e25fe50efe575ea5439430bd255870916bf4be60", "best_bid": "0", "best_ask": "0.001"}], "timestamp": "1769384047890", "event_type": "price_change"}}
{"_local_timestamp": "2026-01-25T23:34:08.628062+00:00", "data": {"market": "0x17aa2a7b47add5eb5866ab5cb4d73fa9fbd57c756fabaa94dc37e8f38d497edd", "price_changes": [{"asset_id": "33315863711622601322794791550568071116800577811624103081392589319514271651144", "price": "0.999", "size": "100009.58", "side": "BUY", "hash": "55a1ddb665ee267efaf2b671293d0df58df11295", "best_bid": "0.999", "best_ask": "1"}, {"asset_id": "36807728890327710559603862263987214098176146352243963377959711142197687028836", "price": "0.001", "size": "100009.58", "side": "SELL", "hash": "4fed3dfcf68c8657a6544d69e75bd20b1d3e93c7", "best_bid": "0", "best_ask": "0.001"}], "timestamp": "1769384048562", "event_type": "price_change"}}
{"_local_timestamp": "2026-01-25T23:34:08.643662+00:00", "data": {"market": "0x0158388d5142d4e9b565f2da3c6ce69b2756682b78fb0a9cab8840203a1a7a97", "price_changes": [{"asset_id": "61239095484488036374794236590506380508392866879329338142519253844360838103055", "price": "0.999", "size": "100005.1", "side": "BUY", "hash": "7dfa6cff26b3da16af4053bb8aca3bbf2bb2978f", "best_bid": "0.999", "best_ask": "1"}, {"asset_id": "75227449954700285684044979609243838936234590419670661782079639952375897552885", "price": "0.001", "size": "100005.1", "side": "SELL", "hash": "c587e42cf8de7819b2e1091235dad60f95e214b9", "best_bid": "0", "best_ask": "0.001"}], "timestamp": "1769384048562", "event_type": "price_change"}}
{"_local_timestamp": "2026-01-25T23:34:08.649952+00:00", "data": {"market": "0xbe2b566c0abcd3fe4336f9cbe88a75a87a78673f7a39d31d4a1462d4b3a50888", "price_changes": [{"asset_id": "588547079469173719335200872670318735548084093624857812256307179730394747376", "price": "0.999", "size": "100005.1", "side": "BUY", "hash": "1a89b5a41203da8c6a2f29626245fafafba7ec5f", "best_bid": "0.999", "best_ask": "1"}, {"asset_id": "102561262047601806822226924855483392449010925057820256596841768139789198414780", "price": "0.001", "size": "100005.1", "side": "SELL", "hash": "a5326edd1e0fc36bee09483828f23f0876091057", "best_bid": "0", "best_ask": "0.001"}], "timestamp": "1769384048562", "event_type": "price_change"}}
{"_local_timestamp": "2026-01-25T23:34:08.659365+00:00", "data": {"market": "0xe58a3bfab1a749e30d75907ef5b61a3092da48602ed1431054292efc86a541b5", "price_changes": [{"asset_id": "30945955821645377043120581432385562305707272746509870032635711882219904769766", "price": "0.999", "size": "100005.1", "side": "BUY", "hash": "64824d8f05c9edc06a70c916d8fe4da0cff727e2", "best_bid": "0.999", "best_ask": "1"}, {"asset_id": "75715544777874521912630047471213807609822733955542285127781965528868344383311", "price": "0.001", "size": "100005.1", "side": "SELL", "hash": "8c8a29ace1ebc545d7e02f4904b65d995fc4cd88", "best_bid": "0", "best_ask": "0.001"}], "timestamp": "1769384048564", "event_type": "price_change"}}
{"_local_timestamp": "2026-01-25T23:34:09.287419+00:00", "data": {"market": "0xe58a3bfab1a749e30d75907ef5b61a3092da48602ed1431054292efc86a541b5", "price_changes": [{"asset_id": "30945955821645377043120581432385562305707272746509870032635711882219904769766", "price": "0.999", "size": "90005.1", "side": "BUY", "hash": "95abf3079e10c5649cde80cb74f574290848a1b6", "best_bid": "0.999", "best_ask": "1"}, {"asset_id": "75715544777874521912630047471213807609822733955542285127781965528868344383311", "price": "0.001", "size": "90005.1", "side": "SELL", "hash": "919cdf49d9160033ba72042e516faadc3250665a", "best_bid": "0", "best_ask": "0.001"}], "timestamp": "1769384049208", "event_type": "price_change"}}
{"_local_timestamp": "2026-01-25T23:34:09.289598+00:00", "data": {"market": "0x0158388d5142d4e9b565f2da3c6ce69b2756682b78fb0a9cab8840203a1a7a97", "price_changes": [{"asset_id": "61239095484488036374794236590506380508392866879329338142519253844360838103055", "price": "0.999", "size": "90005.1", "side": "BUY", "hash": "6bc15e6cc1f2119ccd707da428f261f713642665", "best_bid": "0.999", "best_ask": "1"}, {"asset_id": "75227449954700285684044979609243838936234590419670661782079639952375897552885", "price": "0.001", "size": "90005.1", "side": "SELL", "hash": "b3f152b1278479fbb687b177b6c2fb735c23a2f8", "best_bid": "0", "best_ask": "0.001"}], "timestamp": "1769384049209", "event_type": "price_change"}}
{"_local_timestamp": "2026-01-25T23:34:09.295439+00:00", "data": {"market": "0xbe2b566c0abcd3fe4336f9cbe88a75a87a78673f7a39d31d4a1462d4b3a50888", "price_changes": [{"asset_id": "588547079469173719335200872670318735548084093624857812256307179730394747376", "price": "0.999", "size": "90005.1", "side": "BUY", "hash": "87fd525321021f1de53f886d4045124d078e600b", "best_bid": "0.999", "best_ask": "1"}, {"asset_id": "102561262047601806822226924855483392449010925057820256596841768139789198414780", "price": "0.001", "size": "90005.1", "side": "SELL", "hash": "1308e5377ca6beba9e3e0ade334a7774eccdeb20", "best_bid": "0", "best_ask": "0.001"}], "timestamp": "1769384049208", "event_type": "price_change"}}
{"_local_timestamp": "2026-01-25T23:34:09.309100+00:00", "data": {"market": "0x17aa2a7b47add5eb5866ab5cb4d73fa9fbd57c756fabaa94dc37e8f38d497edd", "price_changes": [{"asset_id": "33315863711622601322794791550568071116800577811624103081392589319514271651144", "price": "0.999", "size": "90009.58", "side": "BUY", "hash": "7d676d8d34c0978bd57e6e7a3df224f028f0bfca", "best_bid": "0.999", "best_ask": "1"}, {"asset_id": "36807728890327710559603862263987214098176146352243963377959711142197687028836", "price": "0.001", "size": "90009.58", "side": "SELL", "hash": "5bc90fd90e50adb9b5d8e7a79bb662d03eb31a7b", "best_bid": "0", "best_ask": "0.001"}], "timestamp": "1769384049211", "event_type": "price_change"}}
{"_local_timestamp": "2026-01-25T23:34:11.215357+00:00", "data": {"market": "0xbe2b566c0abcd3fe4336f9cbe88a75a87a78673f7a39d31d4a1462d4b3a50888", "price_changes": [{"asset_id": "588547079469173719335200872670318735548084093624857812256307179730394747376", "price": "0.999", "size": "92505.1", "side": "BUY", "hash": "dbcabd89b6ef8ce984d5e1998d041e8e77fbe44d", "best_bid": "0.999", "best_ask": "1"}, {"asset_id": "102561262047601806822226924855483392449010925057820256596841768139789198414780", "price": "0.001", "size": "92505.1", "side": "SELL", "hash": "d8b3b41b6dd8f4ebdf99a8c9e634836d0e79a812", "best_bid": "0", "best_ask": "0.001"}], "timestamp": "1769384051128", "event_type": "price_change"}}
{"_local_timestamp": "2026-01-25T23:34:11.219547+00:00", "data": {"market": "0x17aa2a7b47add5eb5866ab5cb4d73fa9fbd57c756fabaa94dc37e8f38d497edd", "price_changes": [{"asset_id": "33315863711622601322794791550568071116800577811624103081392589319514271651144", "price": "0.999", "size": "92509.58", "side": "BUY", "hash": "38e215ad39ea28a79bbb1e6f27c5e6f815c853af", "best_bid": "0.999", "best_ask": "1"}, {"asset_id": "36807728890327710559603862263987214098176146352243963377959711142197687028836", "price": "0.001", "size": "92509.58", "side": "SELL", "hash": "1b9eed64039c910c5f5899e1124a45e257693717", "best_bid": "0", "best_ask": "0.001"}], "timestamp": "1769384051128", "event_type": "price_change"}}
{"_local_timestamp": "2026-01-25T23:34:11.221459+00:00", "data": {"market": "0x0158388d5142d4e9b565f2da3c6ce69b2756682b78fb0a9cab8840203a1a7a97", "price_changes": [{"asset_id": "61239095484488036374794236590506380508392866879329338142519253844360838103055", "price": "0.999", "size": "92505.1", "side": "BUY", "hash": "567884e33b3b867b0e054982a59c19aa27fb7049", "best_bid": "0.999", "best_ask": "1"}, {"asset_id": "75227449954700285684044979609243838936234590419670661782079639952375897552885", "price": "0.001", "size": "92505.1", "side": "SELL", "hash": "35e79f46cddbc7fc18dcc6642b0e50be36ba5813", "best_bid": "0", "best_ask": "0.001"}], "timestamp": "1769384051129", "event_type": "price_change"}}
{"_local_timestamp": "2026-01-25T23:34:11.225907+00:00", "data": {"market": "0xe58a3bfab1a749e30d75907ef5b61a3092da48602ed1431054292efc86a541b5", "price_changes": [{"asset_id": "30945955821645377043120581432385562305707272746509870032635711882219904769766", "price": "0.999", "size": "92505.1", "side": "BUY", "hash": "805aa6de9e32c0f2ffe268f207a3e3ecde8d1e00", "best_bid": "0.999", "best_ask": "1"}, {"asset_id": "75715544777874521912630047471213807609822733955542285127781965528868344383311", "price": "0.001", "size": "92505.1", "side": "SELL", "hash": "92cc0216106d9d2668da9e345ff0c28354aa8921", "best_bid": "0", "best_ask": "0.001"}], "timestamp": "1769384051130", "event_type": "price_change"}}
{"_local_timestamp": "2026-01-25T23:34:12.462301+00:00", "data": {"market": "0xe58a3bfab1a749e30d75907ef5b61a3092da48602ed1431054292efc86a541b5", "price_changes": [{"asset_id": "30945955821645377043120581432385562305707272746509870032635711882219904769766", "price": "0.999", "size": "93129.1", "side": "BUY", "hash": "7aec9b4bc0f4c29f9947ba8241deea31d9481f05", "best_bid": "0.999", "best_ask": "1"}, {"asset_id": "75715544777874521912630047471213807609822733955542285127781965528868344383311", "price": "0.001", "size": "93129.1", "side": "SELL", "hash": "05805f1172fff6a2d7036287c89071f1704fcc93", "best_bid": "0", "best_ask": "0.001"}], "timestamp": "1769384052367", "event_type": "price_change"}}
{"_local_timestamp": "2026-01-25T23:34:12.472630+00:00", "data": {"market": "0xbe2b566c0abcd3fe4336f9cbe88a75a87a78673f7a39d31d4a1462d4b3a50888", "price_changes": [{"asset_id": "588547079469173719335200872670318735548084093624857812256307179730394747376", "price": "0.999", "size": "93129.1", "side": "BUY", "hash": "484c4b02c2c905efef7073e6fdf10e6037d96090", "best_bid": "0.999", "best_ask": "1"}, {"asset_id": "102561262047601806822226924855483392449010925057820256596841768139789198414780", "price": "0.001", "size": "93129.1", "side": "SELL", "hash": "c85fe4b2cf9f558390038802fef301b47e5a8e09", "best_bid": "0", "best_ask": "0.001"}], "timestamp": "1769384052367", "event_type": "price_change"}}
{"_local_timestamp": "2026-01-25T23:34:12.473429+00:00", "data": {"market": "0x17aa2a7b47add5eb5866ab5cb4d73fa9fbd57c756fabaa94dc37e8f38d497edd", "price_changes": [{"asset_id": "33315863711622601322794791550568071116800577811624103081392589319514271651144", "price": "0.999", "size": "93133.58", "side": "BUY", "hash": "ae1e2ecda244b3690194a32b1034be6945ed7b9e", "best_bid": "0.999", "best_ask": "1"}, {"asset_id": "36807728890327710559603862263987214098176146352243963377959711142197687028836", "price": "0.001", "size": "93133.58", "side": "SELL", "hash": "cf4e1629fce8a916d954faca26241d323a001dd6", "best_bid": "0", "best_ask": "0.001"}], "timestamp": "1769384052367", "event_type": "price_change"}}
{"_local_timestamp": "2026-01-25T23:34:12.478546+00:00", "data": {"market": "0x0158388d5142d4e9b565f2da3c6ce69b2756682b78fb0a9cab8840203a1a7a97", "price_changes": [{"asset_id": "61239095484488036374794236590506380508392866879329338142519253844360838103055", "price": "0.999", "size": "93129.1", "side": "BUY", "hash": "32bd6fec0f5c59007b8656ef472c161017127b40", "best_bid": "0.999", "best_ask": "1"}, {"asset_id": "75227449954700285684044979609243838936234590419670661782079639952375897552885", "price": "0.001", "size": "93129.1", "side": "SELL", "hash": "940195c17fe192b8b07cf5ea2c21ccf839b1ea06", "best_bid": "0", "best_ask": "0.001"}], "timestamp": "1769384052368", "event_type": "price_change"}}
{"_local_timestamp": "2026-01-25T23:34:13.605474+00:00", "data": {"market": "0x17aa2a7b47add5eb5866ab5cb4d73fa9fbd57c756fabaa94dc37e8f38d497edd", "price_changes": [{"asset_id": "33315863711622601322794791550568071116800577811624103081392589319514271651144", "price": "0.999", "size": "93288.58", "side": "BUY", "hash": "c610e14c4cb0ed8175a0a5b74e951cef79fc9508", "best_bid": "0.999", "best_ask": "1"}, {"asset_id": "36807728890327710559603862263987214098176146352243963377959711142197687028836", "price": "0.001", "size": "93288.58", "side": "SELL", "hash": "97e045893e6e23803ed2b88b9e3b85101cdbcb3b", "best_bid": "0", "best_ask": "0.001"}], "timestamp": "1769384053428", "event_type": "price_change"}}
{"_local_timestamp": "2026-01-25T23:34:13.607057+00:00", "data": {"market": "0xbe2b566c0abcd3fe4336f9cbe88a75a87a78673f7a39d31d4a1462d4b3a50888", "price_changes": [{"asset_id": "588547079469173719335200872670318735548084093624857812256307179730394747376", "price": "0.999", "size": "93284.1", "side": "BUY", "hash": "7f26eeaeb05e165da5c088507432855a0f96912d", "best_bid": "0.999", "best_ask": "1"}, {"asset_id": "102561262047601806822226924855483392449010925057820256596841768139789198414780", "price": "0.001", "size": "93284.1", "side": "SELL", "hash": "cec4d02f352e4eb8aec5588aa56175d2ac4c6084", "best_bid": "0", "best_ask": "0.001"}], "timestamp": "1769384053428", "event_type": "price_change"}}
{"_local_timestamp": "2026-01-25T23:34:13.609268+00:00", "data": {"market": "0xe58a3bfab1a749e30d75907ef5b61a3092da48602ed1431054292efc86a541b5", "price_changes": [{"asset_id": "30945955821645377043120581432385562305707272746509870032635711882219904769766", "price": "0.999", "size": "93284.1", "side": "BUY", "hash": "4fbe6b6cbc65c1ce8b0cdb0a95a9e5a8bdc4fe18", "best_bid": "0.999", "best_ask": "1"}, {"asset_id": "75715544777874521912630047471213807609822733955542285127781965528868344383311", "price": "0.001", "size": "93284.1", "side": "SELL", "hash": "509550f6ca687fed323a6cac193cff07a66e4a65", "best_bid": "0", "best_ask": "0.001"}], "timestamp": "1769384053428", "event_type": "price_change"}}
{"_local_timestamp": "2026-01-25T23:34:13.611820+00:00", "data": {"market": "0x0158388d5142d4e9b565f2da3c6ce69b2756682b78fb0a9cab8840203a1a7a97", "price_changes": [{"asset_id": "61239095484488036374794236590506380508392866879329338142519253844360838103055", "price": "0.999", "size": "93284.1", "side": "BUY", "hash": "d5311dd81ed4b3ce30c93e7177fd20e747a16bb0", "best_bid": "0.999", "best_ask": "1"}, {"asset_id": "75227449954700285684044979609243838936234590419670661782079639952375897552885", "price": "0.001", "size": "93284.1", "side": "SELL", "hash": "090e4f604cdc187b776ab36107917981e3823063", "best_bid": "0", "best_ask": "0.001"}], "timestamp": "1769384053429", "event_type": "price_change"}}
{"_local_timestamp": "2026-01-25T23:34:25.446782+00:00", "data": {"market": "0xe58a3bfab1a749e30d75907ef5b61a3092da48602ed1431054292efc86a541b5", "price_changes": [{"asset_id": "30945955821645377043120581432385562305707272746509870032635711882219904769766", "price": "0.999", "size": "80005.1", "side": "BUY", "hash": "a0fd88f2fca7211629ba765cde03e65bc84d403b", "best_bid": "0.999", "best_ask": "1"}, {"asset_id": "75715544777874521912630047471213807609822733955542285127781965528868344383311", "price": "0.001", "size": "80005.1", "side": "SELL", "hash": "919785dcdccd85b7477eff8aeadd877712873062", "best_bid": "0", "best_ask": "0.001"}], "timestamp": "1769384065336", "event_type": "price_change"}}
{"_local_timestamp": "2026-01-25T23:34:25.462828+00:00", "data": {"market": "0xbe2b566c0abcd3fe4336f9cbe88a75a87a78673f7a39d31d4a1462d4b3a50888", "price_changes": [{"asset_id": "588547079469173719335200872670318735548084093624857812256307179730394747376", "price": "0.999", "size": "80005.1", "side": "BUY", "hash": "5e1e9660791359431e641cf7eaab6323e9b6a0a5", "best_bid": "0.999", "best_ask": "1"}, {"asset_id": "102561262047601806822226924855483392449010925057820256596841768139789198414780", "price": "0.001", "size": "80005.1", "side": "SELL", "hash": "cec5c6fedde2528619357f3bd61ca5be23a47a80", "best_bid": "0", "best_ask": "0.001"}], "timestamp": "1769384065337", "event_type": "price_change"}}
{"_local_timestamp": "2026-01-25T23:34:25.465125+00:00", "data": {"market": "0x0158388d5142d4e9b565f2da3c6ce69b2756682b78fb0a9cab8840203a1a7a97", "price_changes": [{"asset_id": "61239095484488036374794236590506380508392866879329338142519253844360838103055", "price": "0.999", "size": "80005.1", "side": "BUY", "hash": "e1cac714801100382646c67aafeba4a71936daa4", "best_bid": "0.999", "best_ask": "1"}, {"asset_id": "75227449954700285684044979609243838936234590419670661782079639952375897552885", "price": "0.001", "size": "80005.1", "side": "SELL", "hash": "d073fbb0f6035bb60cea63775d245075913e4951", "best_bid": "0", "best_ask": "0.001"}], "timestamp": "1769384065337", "event_type": "price_change"}}
{"_local_timestamp": "2026-01-25T23:34:25.465540+00:00", "data": {"market": "0x17aa2a7b47add5eb5866ab5cb4d73fa9fbd57c756fabaa94dc37e8f38d497edd", "price_changes": [{"asset_id": "33315863711622601322794791550568071116800577811624103081392589319514271651144", "price": "0.999", "size": "80009.58", "side": "BUY", "hash": "496c0c35153962255acbcf1e0402000dac69e83c", "best_bid": "0.999", "best_ask": "1"}, {"asset_id": "36807728890327710559603862263987214098176146352243963377959711142197687028836", "price": "0.001", "size": "80009.58", "side": "SELL", "hash": "400d1cc465fa00d966077e30c533b7483fb065a9", "best_bid": "0", "best_ask": "0.001"}], "timestamp": "1769384065336", "event_type": "price_change"}}
{"_local_timestamp": "2026-01-25T23:34:26.321322+00:00", "data": {"market": "0xe58a3bfab1a749e30d75907ef5b61a3092da48602ed1431054292efc86a541b5", "price_changes": [{"asset_id": "30945955821645377043120581432385562305707272746509870032635711882219904769766", "price": "0.999", "size": "80630.1", "side": "BUY", "hash": "235f4ac9fc1a4450c50a7e9a19a815a9c24d94a2", "best_bid": "0.999", "best_ask": "1"}, {"asset_id": "75715544777874521912630047471213807609822733955542285127781965528868344383311", "price": "0.001", "size": "80630.1", "side": "SELL", "hash": "327d3caae24b0c79ecb7dad2cb5b871f06397539", "best_bid": "0", "best_ask": "0.001"}], "timestamp": "1769384066215", "event_type": "price_change"}}
{"_local_timestamp": "2026-01-25T23:34:26.345819+00:00", "data": {"market": "0x17aa2a7b47add5eb5866ab5cb4d73fa9fbd57c756fabaa94dc37e8f38d497edd", "price_changes": [{"asset_id": "33315863711622601322794791550568071116800577811624103081392589319514271651144", "price": "0.999", "size": "80634.58", "side": "BUY", "hash": "2b345fea64f983ef6a8f0d1f4a3339ce549f4d87", "best_bid": "0.999", "best_ask": "1"}, {"asset_id": "36807728890327710559603862263987214098176146352243963377959711142197687028836", "price": "0.001", "size": "80634.58", "side": "SELL", "hash": "1152099704226194b159573302fb6dfdd37cec67", "best_bid": "0", "best_ask": "0.001"}], "timestamp": "1769384066216", "event_type": "price_change"}}
{"_local_timestamp": "2026-01-25T23:34:26.347682+00:00", "data": {"market": "0xbe2b566c0abcd3fe4336f9cbe88a75a87a78673f7a39d31d4a1462d4b3a50888", "price_changes": [{"asset_id": "588547079469173719335200872670318735548084093624857812256307179730394747376", "price": "0.999", "size": "80630.1", "side": "BUY", "hash": "24656bbe4eff737a5d98486c7370716c789d5560", "best_bid": "0.999", "best_ask": "1"}, {"asset_id": "102561262047601806822226924855483392449010925057820256596841768139789198414780", "price": "0.001", "size": "80630.1", "side": "SELL", "hash": "8bd63d0ac4006cf8ad36b1470b91b1a3b5bf9f92", "best_bid": "0", "best_ask": "0.001"}], "timestamp": "1769384066215", "event_type": "price_change"}}
{"_local_timestamp": "2026-01-25T23:34:26.348510+00:00", "data": {"market": "0x0158388d5142d4e9b565f2da3c6ce69b2756682b78fb0a9cab8840203a1a7a97", "price_changes": [{"asset_id": "61239095484488036374794236590506380508392866879329338142519253844360838103055", "price": "0.999", "size": "80630.1", "side": "BUY", "hash": "2fe40bd0ff3a7e799745460df72d706065f0a713", "best_bid": "0.999", "best_ask": "1"}, {"asset_id": "75227449954700285684044979609243838936234590419670661782079639952375897552885", "price": "0.001", "size": "80630.1", "side": "SELL", "hash": "626dc3e8d8d506cdc645e9cb018724b4fd1c1baa", "best_bid": "0", "best_ask": "0.001"}], "timestamp": "1769384066216", "event_type": "price_change"}}
{"_local_timestamp": "2026-01-25T23:34:26.646679+00:00", "data": {"market": "0x0158388d5142d4e9b565f2da3c6ce69b2756682b78fb0a9cab8840203a1a7a97", "price_changes": [{"asset_id": "61239095484488036374794236590506380508392866879329338142519253844360838103055", "price": "0.999", "size": "81254.1", "side": "BUY", "hash": "5c26552a33fec05f15f138c0637f2b71aa921088", "best_bid": "0.999", "best_ask": "1"}, {"asset_id": "75227449954700285684044979609243838936234590419670661782079639952375897552885", "price": "0.001", "size": "81254.1", "side": "SELL", "hash": "e4b6f97cbaf321e23dc83110e3b146d6d8153270", "best_bid": "0", "best_ask": "0.001"}], "timestamp": "1769384066574", "event_type": "price_change"}}
{"_local_timestamp": "2026-01-25T23:34:26.672501+00:00", "data": {"market": "0xe58a3bfab1a749e30d75907ef5b61a3092da48602ed1431054292efc86a541b5", "price_changes": [{"asset_id": "30945955821645377043120581432385562305707272746509870032635711882219904769766", "price": "0.999", "size": "81254.1", "side": "BUY", "hash": "f44da6fe19b56a449b75003af874c5224fc6db43", "best_bid": "0.999", "best_ask": "1"}, {"asset_id": "75715544777874521912630047471213807609822733955542285127781965528868344383311", "price": "0.001", "size": "81254.1", "side": "SELL", "hash": "afae8b563d2925cc071aacbda2728705d610a2e3", "best_bid": "0", "best_ask": "0.001"}], "timestamp": "1769384066574", "event_type": "price_change"}}
{"_local_timestamp": "2026-01-25T23:34:26.673287+00:00", "data": {"market": "0x17aa2a7b47add5eb5866ab5cb4d73fa9fbd57c756fabaa94dc37e8f38d497edd", "price_changes": [{"asset_id": "33315863711622601322794791550568071116800577811624103081392589319514271651144", "price": "0.999", "size": "81258.58", "side": "BUY", "hash": "981e1408350b182c7daec4bf23e02c3cf20463e9", "best_bid": "0.999", "best_ask": "1"}, {"asset_id": "36807728890327710559603862263987214098176146352243963377959711142197687028836", "price": "0.001", "size": "81258.58", "side": "SELL", "hash": "1dce6d1e070221825bbcdd83b453a9d926e92adb", "best_bid": "0", "best_ask": "0.001"}], "timestamp": "1769384066574", "event_type": "price_change"}}
{"_local_timestamp": "2026-01-25T23:34:26.673731+00:00", "data": {"market": "0xbe2b566c0abcd3fe4336f9cbe88a75a87a78673f7a39d31d4a1462d4b3a50888", "price_changes": [{"asset_id": "588547079469173719335200872670318735548084093624857812256307179730394747376", "price": "0.999", "size": "81254.1", "side": "BUY", "hash": "b84eb17f1b8aca4ceae918d9caa6afda1668d4bd", "best_bid": "0.999", "best_ask": "1"}, {"asset_id": "102561262047601806822226924855483392449010925057820256596841768139789198414780", "price": "0.001", "size": "81254.1", "side": "SELL", "hash": "f57185563b9a6ae2863265e24cd1c2b90143967d", "best_bid": "0", "best_ask": "0.001"}], "timestamp": "1769384066574", "event_type": "price_change"}}
{"_local_timestamp": "2026-01-25T23:34:27.943353+00:00", "data": {"market": "0x17aa2a7b47add5eb5866ab5cb4d73fa9fbd57c756fabaa94dc37e8f38d497edd", "price_changes": [{"asset_id": "33315863711622601322794791550568071116800577811624103081392589319514271651144", "price": "0.999", "size": "81413.58", "side": "BUY", "hash": "ba5ba5c824ebc993aef72b8fe3fe9098663f5cc6", "best_bid": "0.999", "best_ask": "1"}, {"asset_id": "36807728890327710559603862263987214098176146352243963377959711142197687028836", "price": "0.001", "size": "81413.58", "side": "SELL", "hash": "a3c5952cbbe0cc6e25b4000372bed6efacf593df", "best_bid": "0", "best_ask": "0.001"}], "timestamp": "1769384067737", "event_type": "price_change"}}
{"_local_timestamp": "2026-01-25T23:34:27.968865+00:00", "data": {"market": "0xe58a3bfab1a749e30d75907ef5b61a3092da48602ed1431054292efc86a541b5", "price_changes": [{"asset_id": "30945955821645377043120581432385562305707272746509870032635711882219904769766", "price": "0.999", "size": "81409.1", "side": "BUY", "hash": "27e57f19750a5c15b1c8f1c3dc1fac91bd5c8719", "best_bid": "0.999", "best_ask": "1"}, {"asset_id": "75715544777874521912630047471213807609822733955542285127781965528868344383311", "price": "0.001", "size": "81409.1", "side": "SELL", "hash": "ac5e4b8d2117339f95986898600626e6458f0f7a", "best_bid": "0", "best_ask": "0.001"}], "timestamp": "1769384067737", "event_type": "price_change"}}
{"_local_timestamp": "2026-01-25T23:34:27.975150+00:00", "data": {"market": "0xbe2b566c0abcd3fe4336f9cbe88a75a87a78673f7a39d31d4a1462d4b3a50888", "price_changes": [{"asset_id": "588547079469173719335200872670318735548084093624857812256307179730394747376", "price": "0.999", "size": "81409.1", "side": "BUY", "hash": "40346f32a9a3ea31a7375cdb4e52ce5edbf40d09", "best_bid": "0.999", "best_ask": "1"}, {"asset_id": "102561262047601806822226924855483392449010925057820256596841768139789198414780", "price": "0.001", "size": "81409.1", "side": "SELL", "hash": "693972e17cbe69d0e53340625762a955c9187222", "best_bid": "0", "best_ask": "0.001"}], "timestamp": "1769384067738", "event_type": "price_change"}}
{"_local_timestamp": "2026-01-25T23:34:27.977813+00:00", "data": {"market": "0x0158388d5142d4e9b565f2da3c6ce69b2756682b78fb0a9cab8840203a1a7a97", "price_changes": [{"asset_id": "61239095484488036374794236590506380508392866879329338142519253844360838103055", "price": "0.999", "size": "81409.1", "side": "BUY", "hash": "bd6af86b95ee5c1498306d00dc5ef5c9d920aa5c", "best_bid": "0.999", "best_ask": "1"}, {"asset_id": "75227449954700285684044979609243838936234590419670661782079639952375897552885", "price": "0.001", "size": "81409.1", "side": "SELL", "hash": "62f29b2e2fc8a788615e459b0ab2ef6b03db8f44", "best_bid": "0", "best_ask": "0.001"}], "timestamp": "1769384067737", "event_type": "price_change"}}
{"_local_timestamp": "2026-01-25T23:34:28.254581+00:00", "data": {"market": "0xbe2b566c0abcd3fe4336f9cbe88a75a87a78673f7a39d31d4a1462d4b3a50888", "price_changes": [{"asset_id": "588547079469173719335200872670318735548084093624857812256307179730394747376", "price": "0.999", "size": "81563.1", "side": "BUY", "hash": "a26daaf0401ddf348e4de3d283426a589c4c0707", "best_bid": "0.999", "best_ask": "1"}, {"asset_id": "102561262047601806822226924855483392449010925057820256596841768139789198414780", "price": "0.001", "size": "81563.1", "side": "SELL", "hash": "a9a6e916f1e5ef836f91a9f6b012b18f5aaeda6f", "best_bid": "0", "best_ask": "0.001"}], "timestamp": "1769384068167", "event_type": "price_change"}}
{"_local_timestamp": "2026-01-25T23:34:28.269586+00:00", "data": {"market": "0xe58a3bfab1a749e30d75907ef5b61a3092da48602ed1431054292efc86a541b5", "price_changes": [{"asset_id": "30945955821645377043120581432385562305707272746509870032635711882219904769766", "price": "0.999", "size": "81563.1", "side": "BUY", "hash": "087b142832ae1931efe6e2562635be5fa32474e7", "best_bid": "0.999", "best_ask": "1"}, {"asset_id": "75715544777874521912630047471213807609822733955542285127781965528868344383311", "price": "0.001", "size": "81563.1", "side": "SELL", "hash": "5fc7ad8b45f330f1236203e7daacc46d5bd21f4e", "best_bid": "0", "best_ask": "0.001"}], "timestamp": "1769384068172", "event_type": "price_change"}}
{"_local_timestamp": "2026-01-25T23:34:28.270320+00:00", "data": {"market": "0x0158388d5142d4e9b565f2da3c6ce69b2756682b78fb0a9cab8840203a1a7a97", "price_changes": [{"asset_id": "61239095484488036374794236590506380508392866879329338142519253844360838103055", "price": "0.999", "size": "81563.1", "side": "BUY", "hash": "53bfb2a6ba461f45e9ce0fa74e58afa521be3aa1", "best_bid": "0.999", "best_ask": "1"}, {"asset_id": "75227449954700285684044979609243838936234590419670661782079639952375897552885", "price": "0.001", "size": "81563.1", "side": "SELL", "hash": "fe4d240f96f87b01d4b04929c0fddabe2d677e16", "best_bid": "0", "best_ask": "0.001"}], "timestamp": "1769384068176", "event_type": "price_change"}}
{"_local_timestamp": "2026-01-25T23:34:28.270640+00:00", "data": {"market": "0x17aa2a7b47add5eb5866ab5cb4d73fa9fbd57c756fabaa94dc37e8f38d497edd", "price_changes": [{"asset_id": "33315863711622601322794791550568071116800577811624103081392589319514271651144", "price": "0.999", "size": "81567.58", "side": "BUY", "hash": "81784c515d73035d58d2e81ee2f46d1f6b0a5445", "best_bid": "0.999", "best_ask": "1"}, {"asset_id": "36807728890327710559603862263987214098176146352243963377959711142197687028836", "price": "0.001", "size": "81567.58", "side": "SELL", "hash": "5fe48ca67111fc1dafb30f0f06d239577c58c10b", "best_bid": "0", "best_ask": "0.001"}], "timestamp": "1769384068174", "event_type": "price_change"}}
{"_local_timestamp": "2026-01-25T23:34:29.342992+00:00", "data": {"market": "0xe58a3bfab1a749e30d75907ef5b61a3092da48602ed1431054292efc86a541b5", "price_changes": [{"asset_id": "30945955821645377043120581432385562305707272746509870032635711882219904769766", "price": "0.999", "size": "81716.1", "side": "BUY", "hash": "8313ef664c8eceff9a00985bd51d727e25d7f8c7", "best_bid": "0.999", "best_ask": "1"}, {"asset_id": "75715544777874521912630047471213807609822733955542285127781965528868344383311", "price": "0.001", "size": "81716.1", "side": "SELL", "hash": "ef093ebd8c2e19b1575a922f9ee6c5440f415d54", "best_bid": "0", "best_ask": "0.001"}], "timestamp": "1769384069279", "event_type": "price_change"}}
{"_local_timestamp": "2026-01-25T23:34:29.352689+00:00", "data": {"market": "0xbe2b566c0abcd3fe4336f9cbe88a75a87a78673f7a39d31d4a1462d4b3a50888", "price_changes": [{"asset_id": "588547079469173719335200872670318735548084093624857812256307179730394747376", "price": "0.999", "size": "81716.1", "side": "BUY", "hash": "484afdaeff56798d16f105c078fdbf2650188ef3", "best_bid": "0.999", "best_ask": "1"}, {"asset_id": "102561262047601806822226924855483392449010925057820256596841768139789198414780", "price": "0.001", "size": "81716.1", "side": "SELL", "hash": "a53095bf4096dddca51c0b37b1073138d6b73695", "best_bid": "0", "best_ask": "0.001"}], "timestamp": "1769384069279", "event_type": "price_change"}}
{"_local_timestamp": "2026-01-25T23:34:29.353316+00:00", "data": {"market": "0x17aa2a7b47add5eb5866ab5cb4d73fa9fbd57c756fabaa94dc37e8f38d497edd", "price_changes": [{"asset_id": "33315863711622601322794791550568071116800577811624103081392589319514271651144", "price": "0.999", "size": "81720.58", "side": "BUY", "hash": "3379f177d725b0a3a052c5eeeb6d342b2a49c012", "best_bid": "0.999", "best_ask": "1"}, {"asset_id": "36807728890327710559603862263987214098176146352243963377959711142197687028836", "price": "0.001", "size": "81720.58", "side": "SELL", "hash": "1be1f4d0b84131acbc458b6e2a90f0444e7be270", "best_bid": "0", "best_ask": "0.001"}], "timestamp": "1769384069279", "event_type": "price_change"}}
{"_local_timestamp": "2026-01-25T23:34:29.358146+00:00", "data": {"market": "0x0158388d5142d4e9b565f2da3c6ce69b2756682b78fb0a9cab8840203a1a7a97", "price_changes": [{"asset_id": "61239095484488036374794236590506380508392866879329338142519253844360838103055", "price": "0.999", "size": "81716.1", "side": "BUY", "hash": "cb4ac7652c2f42f77610c53312a9d33144a033a8", "best_bid": "0.999", "best_ask": "1"}, {"asset_id": "75227449954700285684044979609243838936234590419670661782079639952375897552885", "price": "0.001", "size": "81716.1", "side": "SELL", "hash": "2ae04bb26ad3430423ef0eb28f1ee96f01134e3c", "best_bid": "0", "best_ask": "0.001"}], "timestamp": "1769384069279", "event_type": "price_change"}}
{"_local_timestamp": "2026-01-25T23:34:29.808109+00:00", "data": {"market": "0x0158388d5142d4e9b565f2da3c6ce69b2756682b78fb0a9cab8840203a1a7a97", "price_changes": [{"asset_id": "61239095484488036374794236590506380508392866879329338142519253844360838103055", "price": "0.999", "size": "81868.1", "side": "BUY", "hash": "2b93c4b384d3abb7d28f829be54fa8baefc81aa6", "best_bid": "0.999", "best_ask": "1"}, {"asset_id": "75227449954700285684044979609243838936234590419670661782079639952375897552885", "price": "0.001", "size": "81868.1", "side": "SELL", "hash": "8b432ba0181207000cd1bfdad8a9e3eb86bcbe7f", "best_bid": "0", "best_ask": "0.001"}], "timestamp": "1769384069655", "event_type": "price_change"}}
{"_local_timestamp": "2026-01-25T23:34:29.809931+00:00", "data": {"market": "0xe58a3bfab1a749e30d75907ef5b61a3092da48602ed1431054292efc86a541b5", "price_changes": [{"asset_id": "30945955821645377043120581432385562305707272746509870032635711882219904769766", "price": "0.999", "size": "81868.1", "side": "BUY", "hash": "457d1b4c63704d4fe757ee32c435bdf46c97cd96", "best_bid": "0.999", "best_ask": "1"}, {"asset_id": "75715544777874521912630047471213807609822733955542285127781965528868344383311", "price": "0.001", "size": "81868.1", "side": "SELL", "hash": "a3339a7658d4b054421b1dbf1a47a0da0657caf5", "best_bid": "0", "best_ask": "0.001"}], "timestamp": "1769384069655", "event_type": "price_change"}}
{"_local_timestamp": "2026-01-25T23:34:29.810260+00:00", "data": {"market": "0x17aa2a7b47add5eb5866ab5cb4d73fa9fbd57c756fabaa94dc37e8f38d497edd", "price_changes": [{"asset_id": "33315863711622601322794791550568071116800577811624103081392589319514271651144", "price": "0.999", "size": "81872.58", "side": "BUY", "hash": "b665bf83095a3a9b458331b1704ab95196271704", "best_bid": "0.999", "best_ask": "1"}, {"asset_id": "36807728890327710559603862263987214098176146352243963377959711142197687028836", "price": "0.001", "size": "81872.58", "side": "SELL", "hash": "dfc3486607dacbfc52d5872377049c9d7f85a05a", "best_bid": "0", "best_ask": "0.001"}], "timestamp": "1769384069655", "event_type": "price_change"}}
{"_local_timestamp": "2026-01-25T23:34:29.810509+00:00", "data": {"market": "0xbe2b566c0abcd3fe4336f9cbe88a75a87a78673f7a39d31d4a1462d4b3a50888", "price_changes": [{"asset_id": "588547079469173719335200872670318735548084093624857812256307179730394747376", "price": "0.999", "size": "81868.1", "side": "BUY", "hash": "cae5ccb9079241eeac879ba27fb28a5671ac2b07", "best_bid": "0.999", "best_ask": "1"}, {"asset_id": "102561262047601806822226924855483392449010925057820256596841768139789198414780", "price": "0.001", "size": "81868.1", "side": "SELL", "hash": "88582a0ed7ddc3eb9cc1cfdb5fcfac7f6f1c305d", "best_bid": "0", "best_ask": "0.001"}], "timestamp": "1769384069655", "event_type": "price_change"}}
{"_local_timestamp": "2026-01-25T23:34:30.360945+00:00", "data": {"market": "0x0158388d5142d4e9b565f2da3c6ce69b2756682b78fb0a9cab8840203a1a7a97", "price_changes": [{"asset_id": "61239095484488036374794236590506380508392866879329338142519253844360838103055", "price": "0.999", "size": "82019.1", "side": "BUY", "hash": "b6f350204b0f4d2c5690b9aac9ff9cd3562498d7", "best_bid": "0.999", "best_ask": "1"}, {"asset_id": "75227449954700285684044979609243838936234590419670661782079639952375897552885", "price": "0.001", "size": "82019.1", "side": "SELL", "hash": "5d5f9ce42bf6fe290b87ec31cb9707011aad2052", "best_bid": "0", "best_ask": "0.001"}], "timestamp": "1769384070199", "event_type": "price_change"}}
{"_local_timestamp": "2026-01-25T23:34:30.361930+00:00", "data": {"market": "0x17aa2a7b47add5eb5866ab5cb4d73fa9fbd57c756fabaa94dc37e8f38d497edd", "price_changes": [{"asset_id": "33315863711622601322794791550568071116800577811624103081392589319514271651144", "price": "0.999", "size": "82023.58", "side": "BUY", "hash": "1dfadd2d65e652fc9b3f1c9b2faf310b8fd60ffb", "best_bid": "0.999", "best_ask": "1"}, {"asset_id": "36807728890327710559603862263987214098176146352243963377959711142197687028836", "price": "0.001", "size": "82023.58", "side": "SELL", "hash": "ee7fc5f84c0128714986b968cff971e89357f9c3", "best_bid": "0", "best_ask": "0.001"}], "timestamp": "1769384070199", "event_type": "price_change"}}
{"_local_timestamp": "2026-01-25T23:34:30.362691+00:00", "data": {"market": "0xbe2b566c0abcd3fe4336f9cbe88a75a87a78673f7a39d31d4a1462d4b3a50888", "price_changes": [{"asset_id": "588547079469173719335200872670318735548084093624857812256307179730394747376", "price": "0.999", "size": "82019.1", "side": "BUY", "hash": "68afc4a2cb26dc0579e2adba66f398c9b34589a1", "best_bid": "0.999", "best_ask": "1"}, {"asset_id": "102561262047601806822226924855483392449010925057820256596841768139789198414780", "price": "0.001", "size": "82019.1", "side": "SELL", "hash": "41fe833923aa77b61da41c059fc339d51b462692", "best_bid": "0", "best_ask": "0.001"}], "timestamp": "1769384070199", "event_type": "price_change"}}
{"_local_timestamp": "2026-01-25T23:34:30.363942+00:00", "data": {"market": "0xe58a3bfab1a749e30d75907ef5b61a3092da48602ed1431054292efc86a541b5", "price_changes": [{"asset_id": "30945955821645377043120581432385562305707272746509870032635711882219904769766", "price": "0.999", "size": "82019.1", "side": "BUY", "hash": "a32083b1cb85e6d2237cdfc6101e56cba3262d56", "best_bid": "0.999", "best_ask": "1"}, {"asset_id": "75715544777874521912630047471213807609822733955542285127781965528868344383311", "price": "0.001", "size": "82019.1", "side": "SELL", "hash": "8865c590cc5af9af33751a352f8933001994a25b", "best_bid": "0", "best_ask": "0.001"}], "timestamp": "1769384070199", "event_type": "price_change"}}
{"_local_timestamp": "2026-01-25T23:34:30.729900+00:00", "data": {"market": "0x0158388d5142d4e9b565f2da3c6ce69b2756682b78fb0a9cab8840203a1a7a97", "price_changes": [{"asset_id": "61239095484488036374794236590506380508392866879329338142519253844360838103055", "price": "0.999", "size": "82056.1", "side": "BUY", "hash": "b54fed213b7c67cea316922fbd384c8c165a5622", "best_bid": "0.999", "best_ask": "1"}, {"asset_id": "75227449954700285684044979609243838936234590419670661782079639952375897552885", "price": "0.001", "size": "82056.1", "side": "SELL", "hash": "0b2675c4c37d144b2452f6778806e7b029b6d1be", "best_bid": "0", "best_ask": "0.001"}], "timestamp": "1769384070574", "event_type": "price_change"}}
{"_local_timestamp": "2026-01-25T23:34:30.732419+00:00", "data": {"market": "0xe58a3bfab1a749e30d75907ef5b61a3092da48602ed1431054292efc86a541b5", "price_changes": [{"asset_id": "30945955821645377043120581432385562305707272746509870032635711882219904769766", "price": "0.999", "size": "82056.1", "side": "BUY", "hash": "ca318f783cf690cc8b8eebacc61927c4b14f2d7d", "best_bid": "0.999", "best_ask": "1"}, {"asset_id": "75715544777874521912630047471213807609822733955542285127781965528868344383311", "price": "0.001", "size": "82056.1", "side": "SELL", "hash": "2339df783b8c11212cbf1628bb2fcd5d5b540b40", "best_bid": "0", "best_ask": "0.001"}], "timestamp": "1769384070574", "event_type": "price_change"}}
{"_local_timestamp": "2026-01-25T23:34:30.734207+00:00", "data": {"market": "0x17aa2a7b47add5eb5866ab5cb4d73fa9fbd57c756fabaa94dc37e8f38d497edd", "price_changes": [{"asset_id": "33315863711622601322794791550568071116800577811624103081392589319514271651144", "price": "0.999", "size": "82060.58", "side": "BUY", "hash": "211c79f4e26c780e6517e97e4f59a956f4b1c8f8", "best_bid": "0.999", "best_ask": "1"}, {"asset_id": "36807728890327710559603862263987214098176146352243963377959711142197687028836", "price": "0.001", "size": "82060.58", "side": "SELL", "hash": "665662db149d128be05a7f0a34dce44746b3d0c2", "best_bid": "0", "best_ask": "0.001"}], "timestamp": "1769384070573", "event_type": "price_change"}}
{"_local_timestamp": "2026-01-25T23:34:30.734590+00:00", "data": {"market": "0xbe2b566c0abcd3fe4336f9cbe88a75a87a78673f7a39d31d4a1462d4b3a50888", "price_changes": [{"asset_id": "588547079469173719335200872670318735548084093624857812256307179730394747376", "price": "0.999", "size": "82056.1", "side": "BUY", "hash": "4c99ac52b306059af2fc84fd180495907704bb7c", "best_bid": "0.999", "best_ask": "1"}, {"asset_id": "102561262047601806822226924855483392449010925057820256596841768139789198414780", "price": "0.001", "size": "82056.1", "side": "SELL", "hash": "8be9cadf38faa2d7564a099b93155bc5970611d2", "best_bid": "0", "best_ask": "0.001"}], "timestamp": "1769384070574", "event_type": "price_change"}}
{"_local_timestamp": "2026-01-25T23:34:30.982949+00:00", "data": {"market": "0xbe2b566c0abcd3fe4336f9cbe88a75a87a78673f7a39d31d4a1462d4b3a50888", "price_changes": [{"asset_id": "588547079469173719335200872670318735548084093624857812256307179730394747376", "price": "0.999", "size": "82092.1", "side": "BUY", "hash": "2e6281dfb47ae68a35b046642a433b9cbe9a275d", "best_bid": "0.999", "best_ask": "1"}, {"asset_id": "102561262047601806822226924855483392449010925057820256596841768139789198414780", "price": "0.001", "size": "82092.1", "side": "SELL", "hash": "4660af39a830716ccc2c0f6f26fe83775ca46343", "best_bid": "0", "best_ask": "0.001"}], "timestamp": "1769384070918", "event_type": "price_change"}}
{"_local_timestamp": "2026-01-25T23:34:30.984912+00:00", "data": {"market": "0x0158388d5142d4e9b565f2da3c6ce69b2756682b78fb0a9cab8840203a1a7a97", "price_changes": [{"asset_id": "61239095484488036374794236590506380508392866879329338142519253844360838103055", "price": "0.999", "size": "82092.1", "side": "BUY", "hash": "4e80d2d8365681e0659c520a7cbf32d32863ecf1", "best_bid": "0.999", "best_ask": "1"}, {"asset_id": "75227449954700285684044979609243838936234590419670661782079639952375897552885", "price": "0.001", "size": "82092.1", "side": "SELL", "hash": "29035bfa5dd33d0522569297225f41bca560b96a", "best_bid": "0", "best_ask": "0.001"}], "timestamp": "1769384070918", "event_type": "price_change"}}
{"_local_timestamp": "2026-01-25T23:34:30.987146+00:00", "data": {"market": "0xe58a3bfab1a749e30d75907ef5b61a3092da48602ed1431054292efc86a541b5", "price_changes": [{"asset_id": "30945955821645377043120581432385562305707272746509870032635711882219904769766", "price": "0.999", "size": "82092.1", "side": "BUY", "hash": "8013ea9925ca34eeb774dcba46982f3b4f5ab0b5", "best_bid": "0.999", "best_ask": "1"}, {"asset_id": "75715544777874521912630047471213807609822733955542285127781965528868344383311", "price": "0.001", "size": "82092.1", "side": "SELL", "hash": "72ad72073f8251a3ee146a0d80c7f69b866f1f08", "best_bid": "0", "best_ask": "0.001"}], "timestamp": "1769384070918", "event_type": "price_change"}}
{"_local_timestamp": "2026-01-25T23:34:30.987525+00:00", "data": {"market": "0x17aa2a7b47add5eb5866ab5cb4d73fa9fbd57c756fabaa94dc37e8f38d497edd", "price_changes": [{"asset_id": "33315863711622601322794791550568071116800577811624103081392589319514271651144", "price": "0.999", "size": "82096.58", "side": "BUY", "hash": "fb45a601b102d4bd43689c7410199521bf3f69e6", "best_bid": "0.999", "best_ask": "1"}, {"asset_id": "36807728890327710559603862263987214098176146352243963377959711142197687028836", "price": "0.001", "size": "82096.58", "side": "SELL", "hash": "b369a2257ae45c56449e94396fdff3854fdef93d", "best_bid": "0", "best_ask": "0.001"}], "timestamp": "1769384070918", "event_type": "price_change"}}
{"_local_timestamp": "2026-01-25T23:34:32.207514+00:00", "data": {"market": "0xe58a3bfab1a749e30d75907ef5b61a3092da48602ed1431054292efc86a541b5", "price_changes": [{"asset_id": "30945955821645377043120581432385562305707272746509870032635711882219904769766", "price": "0.999", "size": "82127.1", "side": "BUY", "hash": "cab285c553b057edcdb59e68883fa0b44104bb68", "best_bid": "0.999", "best_ask": "1"}, {"asset_id": "75715544777874521912630047471213807609822733955542285127781965528868344383311", "price": "0.001", "size": "82127.1", "side": "SELL", "hash": "2c326df2d953150f6fbcf4048ce1e3171dbbf0df", "best_bid": "0", "best_ask": "0.001"}], "timestamp": "1769384072104", "event_type": "price_change"}}
{"_local_timestamp": "2026-01-25T23:34:32.242758+00:00", "data": {"market": "0x0158388d5142d4e9b565f2da3c6ce69b2756682b78fb0a9cab8840203a1a7a97", "price_changes": [{"asset_id": "61239095484488036374794236590506380508392866879329338142519253844360838103055", "price": "0.999", "size": "82127.1", "side": "BUY", "hash": "85de89e9095a4c8854744f3dab44dcfe19ff15d2", "best_bid": "0.999", "best_ask": "1"}, {"asset_id": "75227449954700285684044979609243838936234590419670661782079639952375897552885", "price": "0.001", "size": "82127.1", "side": "SELL", "hash": "945534fa7bb82b7c226f140ef6a92222171717d0", "best_bid": "0", "best_ask": "0.001"}], "timestamp": "1769384072104", "event_type": "price_change"}}
{"_local_timestamp": "2026-01-25T23:34:32.243210+00:00", "data": {"market": "0x17aa2a7b47add5eb5866ab5cb4d73fa9fbd57c756fabaa94dc37e8f38d497edd", "price_changes": [{"asset_id": "33315863711622601322794791550568071116800577811624103081392589319514271651144", "price": "0.999", "size": "82131.58", "side": "BUY", "hash": "f2468cdc1008cebd9816f51cdb786c67082dae2f", "best_bid": "0.999", "best_ask": "1"}, {"asset_id": "36807728890327710559603862263987214098176146352243963377959711142197687028836", "price": "0.001", "size": "82131.58", "side": "SELL", "hash": "1fc79e64444a94109e566a83266a340aa9ba3b43", "best_bid": "0", "best_ask": "0.001"}], "timestamp": "1769384072105", "event_type": "price_change"}}
{"_local_timestamp": "2026-01-25T23:34:32.262835+00:00", "data": {"market": "0xbe2b566c0abcd3fe4336f9cbe88a75a87a78673f7a39d31d4a1462d4b3a50888", "price_changes": [{"asset_id": "588547079469173719335200872670318735548084093624857812256307179730394747376", "price": "0.999", "size": "82127.1", "side": "BUY", "hash": "6c890d0e2a16df5da53c0f7582bf519278b980db", "best_bid": "0.999", "best_ask": "1"}, {"asset_id": "102561262047601806822226924855483392449010925057820256596841768139789198414780", "price": "0.001", "size": "82127.1", "side": "SELL", "hash": "ae6bee7bf8949a32e731227479756bdd81f75635", "best_bid": "0", "best_ask": "0.001"}], "timestamp": "1769384072107", "event_type": "price_change"}}
{"_local_timestamp": "2026-01-25T23:34:32.664592+00:00", "data": {"market": "0x17aa2a7b47add5eb5866ab5cb4d73fa9fbd57c756fabaa94dc37e8f38d497edd", "price_changes": [{"asset_id": "33315863711622601322794791550568071116800577811624103081392589319514271651144", "price": "0.999", "size": "82165.58", "side": "BUY", "hash": "4dc34e4657fb2ab660d4be84d2e13572de251f41", "best_bid": "0.999", "best_ask": "1"}, {"asset_id": "36807728890327710559603862263987214098176146352243963377959711142197687028836", "price": "0.001", "size": "82165.58", "side": "SELL", "hash": "f1d68358fdee5263aeae3a3267ed36a3927dbc27", "best_bid": "0", "best_ask": "0.001"}], "timestamp": "1769384072577", "event_type": "price_change"}}
{"_local_timestamp": "2026-01-25T23:34:32.665614+00:00", "data": {"market": "0xbe2b566c0abcd3fe4336f9cbe88a75a87a78673f7a39d31d4a1462d4b3a50888", "price_changes": [{"asset_id": "588547079469173719335200872670318735548084093624857812256307179730394747376", "price": "0.999", "size": "82161.1", "side": "BUY", "hash": "c317cd72850e756152b49fb355421813e4a4b584", "best_bid": "0.999", "best_ask": "1"}, {"asset_id": "102561262047601806822226924855483392449010925057820256596841768139789198414780", "price": "0.001", "size": "82161.1", "side": "SELL", "hash": "40bacccbbdabd38f17b752b69643d8443c7adb5b", "best_bid": "0", "best_ask": "0.001"}], "timestamp": "1769384072574", "event_type": "price_change"}}
{"_local_timestamp": "2026-01-25T23:34:32.672001+00:00", "data": {"market": "0x0158388d5142d4e9b565f2da3c6ce69b2756682b78fb0a9cab8840203a1a7a97", "price_changes": [{"asset_id": "61239095484488036374794236590506380508392866879329338142519253844360838103055", "price": "0.999", "size": "82161.1", "side": "BUY", "hash": "db1075f5fd47940e1cd63c0d02f108106ed5502d", "best_bid": "0.999", "best_ask": "1"}, {"asset_id": "75227449954700285684044979609243838936234590419670661782079639952375897552885", "price": "0.001", "size": "82161.1", "side": "SELL", "hash": "c1dddeca10c0e59232625312d3451329e0ccffdb", "best_bid": "0", "best_ask": "0.001"}], "timestamp": "1769384072579", "event_type": "price_change"}}
{"_local_timestamp": "2026-01-25T23:34:32.672718+00:00", "data": {"market": "0xe58a3bfab1a749e30d75907ef5b61a3092da48602ed1431054292efc86a541b5", "price_changes": [{"asset_id": "30945955821645377043120581432385562305707272746509870032635711882219904769766", "price": "0.999", "size": "82161.1", "side": "BUY", "hash": "94951e7bf93cd5eea5f5efd851a7b10e0a3dc4c0", "best_bid": "0.999", "best_ask": "1"}, {"asset_id": "75715544777874521912630047471213807609822733955542285127781965528868344383311", "price": "0.001", "size": "82161.1", "side": "SELL", "hash": "039c17145b2b729aa5eade467b8ccef134f9e3ea", "best_bid": "0", "best_ask": "0.001"}], "timestamp": "1769384072578", "event_type": "price_change"}}
{"_local_timestamp": "2026-01-25T23:34:33.433052+00:00", "data": {"market": "0x0158388d5142d4e9b565f2da3c6ce69b2756682b78fb0a9cab8840203a1a7a97", "price_changes": [{"asset_id": "61239095484488036374794236590506380508392866879329338142519253844360838103055", "price": "0.999", "size": "82194.1", "side": "BUY", "hash": "6843cc0709dd13c57e4786cdc8f406f91e888bb2", "best_bid": "0.999", "best_ask": "1"}, {"asset_id": "75227449954700285684044979609243838936234590419670661782079639952375897552885", "price": "0.001", "size": "82194.1", "side": "SELL", "hash": "d7866f9606d716e25f995aa4766dd3aae58b7029", "best_bid": "0", "best_ask": "0.001"}], "timestamp": "1769384073350", "event_type": "price_change"}}
{"_local_timestamp": "2026-01-25T23:34:33.433394+00:00", "data": {"market": "0x17aa2a7b47add5eb5866ab5cb4d73fa9fbd57c756fabaa94dc37e8f38d497edd", "price_changes": [{"asset_id": "33315863711622601322794791550568071116800577811624103081392589319514271651144", "price": "0.999", "size": "82198.58", "side": "BUY", "hash": "385a2431858a621c3a4a91daf16074c564934cc4", "best_bid": "0.999", "best_ask": "1"}, {"asset_id": "36807728890327710559603862263987214098176146352243963377959711142197687028836", "price": "0.001", "size": "82198.58", "side": "SELL", "hash": "95d8da2a9b33bdec968eabb4321a2a0e4415a3e1", "best_bid": "0", "best_ask": "0.001"}], "timestamp": "1769384073350", "event_type": "price_change"}}
{"_local_timestamp": "2026-01-25T23:34:33.433740+00:00", "data": {"market": "0xbe2b566c0abcd3fe4336f9cbe88a75a87a78673f7a39d31d4a1462d4b3a50888", "price_changes": [{"asset_id": "588547079469173719335200872670318735548084093624857812256307179730394747376", "price": "0.999", "size": "82194.1", "side": "BUY", "hash": "1a3c23de52f58429eaa9ce62c7bfe56661889b2a", "best_bid": "0.999", "best_ask": "1"}, {"asset_id": "102561262047601806822226924855483392449010925057820256596841768139789198414780", "price": "0.001", "size": "82194.1", "side": "SELL", "hash": "5f5b4236d12bdf306635ba8f3743bb27f3959581", "best_bid": "0", "best_ask": "0.001"}], "timestamp": "1769384073351", "event_type": "price_change"}}
{"_local_timestamp": "2026-01-25T23:34:33.441568+00:00", "data": {"market": "0xe58a3bfab1a749e30d75907ef5b61a3092da48602ed1431054292efc86a541b5", "price_changes": [{"asset_id": "30945955821645377043120581432385562305707272746509870032635711882219904769766", "price": "0.999", "size": "82194.1", "side": "BUY", "hash": "4a0540a18589b33ebf0c66b9d47420f6ad2b74ae", "best_bid": "0.999", "best_ask": "1"}, {"asset_id": "75715544777874521912630047471213807609822733955542285127781965528868344383311", "price": "0.001", "size": "82194.1", "side": "SELL", "hash": "628c3e571b3a3d77c8189bf90f4044f8856fe331", "best_bid": "0", "best_ask": "0.001"}], "timestamp": "1769384073354", "event_type": "price_change"}}
{"_local_timestamp": "2026-01-25T23:34:36.134586+00:00", "data": {"market": "0xbe2b566c0abcd3fe4336f9cbe88a75a87a78673f7a39d31d4a1462d4b3a50888", "price_changes": [{"asset_id": "588547079469173719335200872670318735548084093624857812256307179730394747376", "price": "0.999", "size": "84694.1", "side": "BUY", "hash": "3c56af9c6153753e92a5f60e237910b2e1eebd7a", "best_bid": "0.999", "best_ask": "1"}, {"asset_id": "102561262047601806822226924855483392449010925057820256596841768139789198414780", "price": "0.001", "size": "84694.1", "side": "SELL", "hash": "e8fa11577cfade6a07b2c1b09e459fce99c5acaa", "best_bid": "0", "best_ask": "0.001"}], "timestamp": "1769384076055", "event_type": "price_change"}}
{"_local_timestamp": "2026-01-25T23:34:36.135509+00:00", "data": {"market": "0xe58a3bfab1a749e30d75907ef5b61a3092da48602ed1431054292efc86a541b5", "price_changes": [{"asset_id": "30945955821645377043120581432385562305707272746509870032635711882219904769766", "price": "0.999", "size": "84694.1", "side": "BUY", "hash": "bb382f01758d4f5f3d1063c24d7cb3dd652486b9", "best_bid": "0.999", "best_ask": "1"}, {"asset_id": "75715544777874521912630047471213807609822733955542285127781965528868344383311", "price": "0.001", "size": "84694.1", "side": "SELL", "hash": "12e77ceebf23cdc4481532f65577a670844d8d67", "best_bid": "0", "best_ask": "0.001"}], "timestamp": "1769384076055", "event_type": "price_change"}}
{"_local_timestamp": "2026-01-25T23:34:36.136563+00:00", "data": {"market": "0x17aa2a7b47add5eb5866ab5cb4d73fa9fbd57c756fabaa94dc37e8f38d497edd", "price_changes": [{"asset_id": "33315863711622601322794791550568071116800577811624103081392589319514271651144", "price": "0.999", "size": "84698.58", "side": "BUY", "hash": "443a30f3b88e161e71db14c2dedda168b4a268c0", "best_bid": "0.999", "best_ask": "1"}, {"asset_id": "36807728890327710559603862263987214098176146352243963377959711142197687028836", "price": "0.001", "size": "84698.58", "side": "SELL", "hash": "542136a0fd21bd94b29c7e8b04bd7d8acfc2e20d", "best_bid": "0", "best_ask": "0.001"}], "timestamp": "1769384076055", "event_type": "price_change"}}
{"_local_timestamp": "2026-01-25T23:34:36.159351+00:00", "data": {"market": "0x0158388d5142d4e9b565f2da3c6ce69b2756682b78fb0a9cab8840203a1a7a97", "price_changes": [{"asset_id": "61239095484488036374794236590506380508392866879329338142519253844360838103055", "price": "0.999", "size": "84694.1", "side": "BUY", "hash": "f8a1b29323828890e15979970bbe907ad362b6ce", "best_bid": "0.999", "best_ask": "1"}, {"asset_id": "75227449954700285684044979609243838936234590419670661782079639952375897552885", "price": "0.001", "size": "84694.1", "side": "SELL", "hash": "4f1373e73900bf4aba7ee25abb466aff9626dddc", "best_bid": "0", "best_ask": "0.001"}], "timestamp": "1769384076055", "event_type": "price_change"}}
{"_local_timestamp": "2026-01-25T23:34:38.493952+00:00", "data": {"market": "0xbe2b566c0abcd3fe4336f9cbe88a75a87a78673f7a39d31d4a1462d4b3a50888", "price_changes": [{"asset_id": "588547079469173719335200872670318735548084093624857812256307179730394747376", "price": "0.999", "size": "84849.1", "side": "BUY", "hash": "06ae0f21a521f7619cafd2dbf02beac571573a06", "best_bid": "0.999", "best_ask": "1"}, {"asset_id": "102561262047601806822226924855483392449010925057820256596841768139789198414780", "price": "0.001", "size": "84849.1", "side": "SELL", "hash": "bf21cfa854620c259c681c914dcfa0b8b6b186bb", "best_bid": "0", "best_ask": "0.001"}], "timestamp": "1769384078430", "event_type": "price_change"}}
{"_local_timestamp": "2026-01-25T23:34:38.501334+00:00", "data": {"market": "0x17aa2a7b47add5eb5866ab5cb4d73fa9fbd57c756fabaa94dc37e8f38d497edd", "price_changes": [{"asset_id": "33315863711622601322794791550568071116800577811624103081392589319514271651144", "price": "0.999", "size": "84853.58", "side": "BUY", "hash": "cfec3b965a1ef822328d8ee8aef2861394d71356", "best_bid": "0.999", "best_ask": "1"}, {"asset_id": "36807728890327710559603862263987214098176146352243963377959711142197687028836", "price": "0.001", "size": "84853.58", "side": "SELL", "hash": "557b8acabe5dfb2903f91bbb9e7ce02c79feb5b6", "best_bid": "0", "best_ask": "0.001"}], "timestamp": "1769384078430", "event_type": "price_change"}}
{"_local_timestamp": "2026-01-25T23:34:38.501746+00:00", "data": {"market": "0xe58a3bfab1a749e30d75907ef5b61a3092da48602ed1431054292efc86a541b5", "price_changes": [{"asset_id": "30945955821645377043120581432385562305707272746509870032635711882219904769766", "price": "0.999", "size": "84849.1", "side": "BUY", "hash": "bdbf2fe9161a1d124c8b25edd35f75f1ce1a86b9", "best_bid": "0.999", "best_ask": "1"}, {"asset_id": "75715544777874521912630047471213807609822733955542285127781965528868344383311", "price": "0.001", "size": "84849.1", "side": "SELL", "hash": "49afc9db9d9e9e6e99e7fe2d4bb7bfe426b50d65", "best_bid": "0", "best_ask": "0.001"}], "timestamp": "1769384078430", "event_type": "price_change"}}
{"_local_timestamp": "2026-01-25T23:34:38.505693+00:00", "data": {"market": "0x0158388d5142d4e9b565f2da3c6ce69b2756682b78fb0a9cab8840203a1a7a97", "price_changes": [{"asset_id": "61239095484488036374794236590506380508392866879329338142519253844360838103055", "price": "0.999", "size": "84849.1", "side": "BUY", "hash": "554b5cd6482198913fb259f03cb3441ce2a9e3dc", "best_bid": "0.999", "best_ask": "1"}, {"asset_id": "75227449954700285684044979609243838936234590419670661782079639952375897552885", "price": "0.001", "size": "84849.1", "side": "SELL", "hash": "3561bdfa3733c91c43f2235c8c1ea60d0a0701ac", "best_bid": "0", "best_ask": "0.001"}], "timestamp": "1769384078430", "event_type": "price_change"}}
{"_local_timestamp": "2026-01-25T23:34:38.858844+00:00", "data": {"market": "0xbe2b566c0abcd3fe4336f9cbe88a75a87a78673f7a39d31d4a1462d4b3a50888", "price_changes": [{"asset_id": "588547079469173719335200872670318735548084093624857812256307179730394747376", "price": "0.999", "size": "85003.1", "side": "BUY", "hash": "b29aadb7a0f5c5bbbb1caeb7e4f5cd3984b07fcf", "best_bid": "0.999", "best_ask": "1"}, {"asset_id": "102561262047601806822226924855483392449010925057820256596841768139789198414780", "price": "0.001", "size": "85003.1", "side": "SELL", "hash": "fe767f5cbeaf8b45a82f20370fcc995111ac7b8b", "best_bid": "0", "best_ask": "0.001"}], "timestamp": "1769384078791", "event_type": "price_change"}}
{"_local_timestamp": "2026-01-25T23:34:38.859194+00:00", "data": {"market": "0x17aa2a7b47add5eb5866ab5cb4d73fa9fbd57c756fabaa94dc37e8f38d497edd", "price_changes": [{"asset_id": "33315863711622601322794791550568071116800577811624103081392589319514271651144", "price": "0.999", "size": "85007.58", "side": "BUY", "hash": "8a48b554eb65226199ae50bd4110af5191e0182e", "best_bid": "0.999", "best_ask": "1"}, {"asset_id": "36807728890327710559603862263987214098176146352243963377959711142197687028836", "price": "0.001", "size": "85007.58", "side": "SELL", "hash": "4c4ab0338ad28a4b1dece4f28a35c6222f6d64ed", "best_bid": "0", "best_ask": "0.001"}], "timestamp": "1769384078792", "event_type": "price_change"}}
{"_local_timestamp": "2026-01-25T23:34:38.859507+00:00", "data": {"market": "0x0158388d5142d4e9b565f2da3c6ce69b2756682b78fb0a9cab8840203a1a7a97", "price_changes": [{"asset_id": "61239095484488036374794236590506380508392866879329338142519253844360838103055", "price": "0.999", "size": "85003.1", "side": "BUY", "hash": "837d50f0e4143eb4ee8bcc42aace2452ba3496ab", "best_bid": "0.999", "best_ask": "1"}, {"asset_id": "75227449954700285684044979609243838936234590419670661782079639952375897552885", "price": "0.001", "size": "85003.1", "side": "SELL", "hash": "270a5da37927f0b2d4d80042c759c650698ae266", "best_bid": "0", "best_ask": "0.001"}], "timestamp": "1769384078792", "event_type": "price_change"}}
{"_local_timestamp": "2026-01-25T23:34:38.869396+00:00", "data": {"market": "0xe58a3bfab1a749e30d75907ef5b61a3092da48602ed1431054292efc86a541b5", "price_changes": [{"asset_id": "30945955821645377043120581432385562305707272746509870032635711882219904769766", "price": "0.999", "size": "85003.1", "side": "BUY", "hash": "33a6c3bd007893a89be49d8786bea31c959c0596", "best_bid": "0.999", "best_ask": "1"}, {"asset_id": "75715544777874521912630047471213807609822733955542285127781965528868344383311", "price": "0.001", "size": "85003.1", "side": "SELL", "hash": "8b44c1a9a80f6e4e5968dd04f61ee942c3dd80c0", "best_bid": "0", "best_ask": "0.001"}], "timestamp": "1769384078791", "event_type": "price_change"}}
{"_local_timestamp": "2026-01-25T23:34:40.173750+00:00", "data": {"market": "0x17aa2a7b47add5eb5866ab5cb4d73fa9fbd57c756fabaa94dc37e8f38d497edd", "price_changes": [{"asset_id": "33315863711622601322794791550568071116800577811624103081392589319514271651144", "price": "0.999", "size": "85160.58", "side": "BUY", "hash": "2ad3e788bf9b814c6bd64198e68a88276b9ba388", "best_bid": "0.999", "best_ask": "1"}, {"asset_id": "36807728890327710559603862263987214098176146352243963377959711142197687028836", "price": "0.001", "size": "85160.58", "side": "SELL", "hash": "7ca4ab63b4c45e248e48f7352a7b32506f71a5f5", "best_bid": "0", "best_ask": "0.001"}], "timestamp": "1769384080002", "event_type": "price_change"}}
{"_local_timestamp": "2026-01-25T23:34:40.174240+00:00", "data": {"market": "0xbe2b566c0abcd3fe4336f9cbe88a75a87a78673f7a39d31d4a1462d4b3a50888", "price_changes": [{"asset_id": "588547079469173719335200872670318735548084093624857812256307179730394747376", "price": "0.999", "size": "85156.1", "side": "BUY", "hash": "5600ca40d4f7758017e27027912e3251dc9b7c60", "best_bid": "0.999", "best_ask": "1"}, {"asset_id": "102561262047601806822226924855483392449010925057820256596841768139789198414780", "price": "0.001", "size": "85156.1", "side": "SELL", "hash": "f0503db6a205ac513c7bc8146ab5f895b32857f2", "best_bid": "0", "best_ask": "0.001"}], "timestamp": "1769384080002", "event_type": "price_change"}}
{"_local_timestamp": "2026-01-25T23:34:40.183570+00:00", "data": {"market": "0x0158388d5142d4e9b565f2da3c6ce69b2756682b78fb0a9cab8840203a1a7a97", "price_changes": [{"asset_id": "61239095484488036374794236590506380508392866879329338142519253844360838103055", "price": "0.999", "size": "85156.1", "side": "BUY", "hash": "75a46eeeb9aff39d551532fe80f4edb6d04fe115", "best_bid": "0.999", "best_ask": "1"}, {"asset_id": "75227449954700285684044979609243838936234590419670661782079639952375897552885", "price": "0.001", "size": "85156.1", "side": "SELL", "hash": "844a089613726f48f8a39c205af91de04c82ec44", "best_bid": "0", "best_ask": "0.001"}], "timestamp": "1769384080005", "event_type": "price_change"}}
{"_local_timestamp": "2026-01-25T23:34:40.192195+00:00", "data": {"market": "0xe58a3bfab1a749e30d75907ef5b61a3092da48602ed1431054292efc86a541b5", "price_changes": [{"asset_id": "30945955821645377043120581432385562305707272746509870032635711882219904769766", "price": "0.999", "size": "85156.1", "side": "BUY", "hash": "09bdd19570256a7e440f2951d9c3134f749dd90a", "best_bid": "0.999", "best_ask": "1"}, {"asset_id": "75715544777874521912630047471213807609822733955542285127781965528868344383311", "price": "0.001", "size": "85156.1", "side": "SELL", "hash": "9e296dae04ad4fc03b3bb0fcde2cc6269a6b3d61", "best_bid": "0", "best_ask": "0.001"}], "timestamp": "1769384080005", "event_type": "price_change"}}
{"_local_timestamp": "2026-01-25T23:34:40.657362+00:00", "data": {"market": "0x0158388d5142d4e9b565f2da3c6ce69b2756682b78fb0a9cab8840203a1a7a97", "price_changes": [{"asset_id": "61239095484488036374794236590506380508392866879329338142519253844360838103055", "price": "0.999", "size": "85308.1", "side": "BUY", "hash": "0748f8370e0f1672717c68aa4b9639510b600405", "best_bid": "0.999", "best_ask": "1"}, {"asset_id": "75227449954700285684044979609243838936234590419670661782079639952375897552885", "price": "0.001", "size": "85308.1", "side": "SELL", "hash": "99d735b173e2baf5b42f52bf7d9452127e89e331", "best_bid": "0", "best_ask": "0.001"}], "timestamp": "1769384080494", "event_type": "price_change"}}
{"_local_timestamp": "2026-01-25T23:34:40.682666+00:00", "data": {"market": "0x17aa2a7b47add5eb5866ab5cb4d73fa9fbd57c756fabaa94dc37e8f38d497edd", "price_changes": [{"asset_id": "33315863711622601322794791550568071116800577811624103081392589319514271651144", "price": "0.999", "size": "85312.58", "side": "BUY", "hash": "d4d8dbdddd7440dfcc8018cd6ba1a91e4a8fd10a", "best_bid": "0.999", "best_ask": "1"}, {"asset_id": "36807728890327710559603862263987214098176146352243963377959711142197687028836", "price": "0.001", "size": "85312.58", "side": "SELL", "hash": "f241cc3dc9f3b706bd327edfda0346bb6b185e80", "best_bid": "0", "best_ask": "0.001"}], "timestamp": "1769384080494", "event_type": "price_change"}}
{"_local_timestamp": "2026-01-25T23:34:40.683956+00:00", "data": {"market": "0xe58a3bfab1a749e30d75907ef5b61a3092da48602ed1431054292efc86a541b5", "price_changes": [{"asset_id": "30945955821645377043120581432385562305707272746509870032635711882219904769766", "price": "0.999", "size": "85308.1", "side": "BUY", "hash": "21ec7c5f3cc0851f88a936dce4e746a5d5dd4397", "best_bid": "0.999", "best_ask": "1"}, {"asset_id": "75715544777874521912630047471213807609822733955542285127781965528868344383311", "price": "0.001", "size": "85308.1", "side": "SELL", "hash": "3bd2e1a01390638d124eafa5895b3820b226c471", "best_bid": "0", "best_ask": "0.001"}], "timestamp": "1769384080493", "event_type": "price_change"}}
{"_local_timestamp": "2026-01-25T23:34:40.684358+00:00", "data": {"market": "0xbe2b566c0abcd3fe4336f9cbe88a75a87a78673f7a39d31d4a1462d4b3a50888", "price_changes": [{"asset_id": "588547079469173719335200872670318735548084093624857812256307179730394747376", "price": "0.999", "size": "85308.1", "side": "BUY", "hash": "4dab9498205ac2180e3209f955412e4f21ea9738", "best_bid": "0.999", "best_ask": "1"}, {"asset_id": "102561262047601806822226924855483392449010925057820256596841768139789198414780", "price": "0.001", "size": "85308.1", "side": "SELL", "hash": "180739532b8d771ac0c2117cfe61b629bd7f754d", "best_bid": "0", "best_ask": "0.001"}], "timestamp": "1769384080495", "event_type": "price_change"}}
{"_local_timestamp": "2026-01-25T23:35:02.100469+00:00", "data": {"market": "0xbe2b566c0abcd3fe4336f9cbe88a75a87a78673f7a39d31d4a1462d4b3a50888", "price_changes": [{"asset_id": "102561262047601806822226924855483392449010925057820256596841768139789198414780", "price": "0.002", "size": "0", "side": "SELL", "hash": "2d85cd1eaafb2147d2e6e0712fadc49391b68d73", "best_bid": "0", "best_ask": "0.001"}, {"asset_id": "588547079469173719335200872670318735548084093624857812256307179730394747376", "price": "0.998", "size": "0", "side": "BUY", "hash": "bdf7da495c44123e604eb5f5d8896e9416a8b0e7", "best_bid": "0.999", "best_ask": "1"}], "timestamp": "1769384102012", "event_type": "price_change"}}
{"_local_timestamp": "2026-01-25T23:35:03.793727+00:00", "data": {"market": "0xbe2b566c0abcd3fe4336f9cbe88a75a87a78673f7a39d31d4a1462d4b3a50888", "price_changes": [{"asset_id": "102561262047601806822226924855483392449010925057820256596841768139789198414780", "price": "0.001", "size": "85316.78", "side": "SELL", "hash": "558e22f2d64675e4ff8a44893b27fbe94c7523cf", "best_bid": "0", "best_ask": "0.001"}, {"asset_id": "588547079469173719335200872670318735548084093624857812256307179730394747376", "price": "0.999", "size": "85316.78", "side": "BUY", "hash": "0deaa6162705885ab394f4a62878e9b13373d6b8", "best_bid": "0.999", "best_ask": "1"}], "timestamp": "1769384103725", "event_type": "price_change"}}
{"_local_timestamp": "2026-01-25T23:35:07.474088+00:00", "data": {"market": "0xbe2b566c0abcd3fe4336f9cbe88a75a87a78673f7a39d31d4a1462d4b3a50888", "price_changes": [{"asset_id": "588547079469173719335200872670318735548084093624857812256307179730394747376", "price": "0.999", "size": "80013.78", "side": "BUY", "hash": "eb3ef0f6ada2d94e48c64c96ad4ec3159e9d7c4b", "best_bid": "0.999", "best_ask": "1"}, {"asset_id": "102561262047601806822226924855483392449010925057820256596841768139789198414780", "price": "0.001", "size": "80013.78", "side": "SELL", "hash": "b4fb7358cf12eb245ceef4aff197e7b5ec871bfb", "best_bid": "0", "best_ask": "0.001"}], "timestamp": "1769384107390", "event_type": "price_change"}}
{"_local_timestamp": "2026-01-25T23:35:07.488579+00:00", "data": {"market": "0xe58a3bfab1a749e30d75907ef5b61a3092da48602ed1431054292efc86a541b5", "price_changes": [{"asset_id": "30945955821645377043120581432385562305707272746509870032635711882219904769766", "price": "0.999", "size": "80005.1", "side": "BUY", "hash": "7f5107a52fd8a882574861cf19b2dbeedefcfd6d", "best_bid": "0.999", "best_ask": "1"}, {"asset_id": "75715544777874521912630047471213807609822733955542285127781965528868344383311", "price": "0.001", "size": "80005.1", "side": "SELL", "hash": "a98f56122cad8d28d4c63d8813a37e77e680fb8a", "best_bid": "0", "best_ask": "0.001"}], "timestamp": "1769384107391", "event_type": "price_change"}}
{"_local_timestamp": "2026-01-25T23:35:07.493105+00:00", "data": {"market": "0x0158388d5142d4e9b565f2da3c6ce69b2756682b78fb0a9cab8840203a1a7a97", "price_changes": [{"asset_id": "61239095484488036374794236590506380508392866879329338142519253844360838103055", "price": "0.999", "size": "80005.1", "side": "BUY", "hash": "ac80c8451932afa9266ebc560ce90198d2f50d2c", "best_bid": "0.999", "best_ask": "1"}, {"asset_id": "75227449954700285684044979609243838936234590419670661782079639952375897552885", "price": "0.001", "size": "80005.1", "side": "SELL", "hash": "d7d6608d8293eaec223402f3e3549862be10b98f", "best_bid": "0", "best_ask": "0.001"}], "timestamp": "1769384107401", "event_type": "price_change"}}
{"_local_timestamp": "2026-01-25T23:35:07.504104+00:00", "data": {"market": "0x17aa2a7b47add5eb5866ab5cb4d73fa9fbd57c756fabaa94dc37e8f38d497edd", "price_changes": [{"asset_id": "33315863711622601322794791550568071116800577811624103081392589319514271651144", "price": "0.999", "size": "80009.58", "side": "BUY", "hash": "53a0979e5c985326ab643a9c13a6e62824da62c8", "best_bid": "0.999", "best_ask": "1"}, {"asset_id": "36807728890327710559603862263987214098176146352243963377959711142197687028836", "price": "0.001", "size": "80009.58", "side": "SELL", "hash": "98a9f3beb50f16647342b578c2d611d5733ab957", "best_bid": "0", "best_ask": "0.001"}], "timestamp": "1769384107397", "event_type": "price_change"}}
{"_local_timestamp": "2026-01-25T23:35:07.703837+00:00", "data": {"market": "0x0158388d5142d4e9b565f2da3c6ce69b2756682b78fb0a9cab8840203a1a7a97", "price_changes": [{"asset_id": "61239095484488036374794236590506380508392866879329338142519253844360838103055", "price": "0.999", "size": "80044.1", "side": "BUY", "hash": "dcb87a4382264e01a4af2fae5430bfcfd12cde55", "best_bid": "0.999", "best_ask": "1"}, {"asset_id": "75227449954700285684044979609243838936234590419670661782079639952375897552885", "price": "0.001", "size": "80044.1", "side": "SELL", "hash": "9817118286eea2e305f27a28a3fcb2167e241b8f", "best_bid": "0", "best_ask": "0.001"}], "timestamp": "1769384107613", "event_type": "price_change"}}
{"_local_timestamp": "2026-01-25T23:35:07.704194+00:00", "data": {"market": "0x17aa2a7b47add5eb5866ab5cb4d73fa9fbd57c756fabaa94dc37e8f38d497edd", "price_changes": [{"asset_id": "33315863711622601322794791550568071116800577811624103081392589319514271651144", "price": "0.999", "size": "80048.58", "side": "BUY", "hash": "4745043571c3fa7e041689fbde6a0c0bd2eca842", "best_bid": "0.999", "best_ask": "1"}, {"asset_id": "36807728890327710559603862263987214098176146352243963377959711142197687028836", "price": "0.001", "size": "80048.58", "side": "SELL", "hash": "9bbd40bb99f399f1fa438a35a441cf93f2ceb763", "best_bid": "0", "best_ask": "0.001"}], "timestamp": "1769384107613", "event_type": "price_change"}}
{"_local_timestamp": "2026-01-25T23:35:07.704467+00:00", "data": {"market": "0xe58a3bfab1a749e30d75907ef5b61a3092da48602ed1431054292efc86a541b5", "price_changes": [{"asset_id": "30945955821645377043120581432385562305707272746509870032635711882219904769766", "price": "0.999", "size": "80044.1", "side": "BUY", "hash": "3c0bf0b6a79f028cabc8b159ef467cafd0b7b4c6", "best_bid": "0.999", "best_ask": "1"}, {"asset_id": "75715544777874521912630047471213807609822733955542285127781965528868344383311", "price": "0.001", "size": "80044.1", "side": "SELL", "hash": "70f11a5bda2efbc8527de87fc0161267fb938803", "best_bid": "0", "best_ask": "0.001"}], "timestamp": "1769384107613", "event_type": "price_change"}}
{"_local_timestamp": "2026-01-25T23:35:07.704705+00:00", "data": {"market": "0xbe2b566c0abcd3fe4336f9cbe88a75a87a78673f7a39d31d4a1462d4b3a50888", "price_changes": [{"asset_id": "588547079469173719335200872670318735548084093624857812256307179730394747376", "price": "0.999", "size": "80052.78", "side": "BUY", "hash": "04a092fb89def87837231b538aa5d124fc218306", "best_bid": "0.999", "best_ask": "1"}, {"asset_id": "102561262047601806822226924855483392449010925057820256596841768139789198414780", "price": "0.001", "size": "80052.78", "side": "SELL", "hash": "be987630b037de0f0b11d17bde8db367eefa382d", "best_bid": "0", "best_ask": "0.001"}], "timestamp": "1769384107613", "event_type": "price_change"}}
{"_local_timestamp": "2026-01-25T23:35:08.024597+00:00", "data": {"market": "0x0158388d5142d4e9b565f2da3c6ce69b2756682b78fb0a9cab8840203a1a7a97", "price_changes": [{"asset_id": "61239095484488036374794236590506380508392866879329338142519253844360838103055", "price": "0.999", "size": "80082.1", "side": "BUY", "hash": "cb4001a9be23f492b9632fb255dd7a79a73518da", "best_bid": "0.999", "best_ask": "1"}, {"asset_id": "75227449954700285684044979609243838936234590419670661782079639952375897552885", "price": "0.001", "size": "80082.1", "side": "SELL", "hash": "e5cc500d4876a5a98c6b3f612f34ca13e4b8a118", "best_bid": "0", "best_ask": "0.001"}], "timestamp": "1769384107945", "event_type": "price_change"}}
{"_local_timestamp": "2026-01-25T23:35:08.024919+00:00", "data": {"market": "0x17aa2a7b47add5eb5866ab5cb4d73fa9fbd57c756fabaa94dc37e8f38d497edd", "price_changes": [{"asset_id": "33315863711622601322794791550568071116800577811624103081392589319514271651144", "price": "0.999", "size": "80086.58", "side": "BUY", "hash": "be2d57eb39505766ef7451f6e7584abbbd46447b", "best_bid": "0.999", "best_ask": "1"}, {"asset_id": "36807728890327710559603862263987214098176146352243963377959711142197687028836", "price": "0.001", "size": "80086.58", "side": "SELL", "hash": "f04015b8ad13e15ef34bd5b9aa9c434fb0ac59ba", "best_bid": "0", "best_ask": "0.001"}], "timestamp": "1769384107945", "event_type": "price_change"}}
{"_local_timestamp": "2026-01-25T23:35:08.025175+00:00", "data": {"market": "0xe58a3bfab1a749e30d75907ef5b61a3092da48602ed1431054292efc86a541b5", "price_changes": [{"asset_id": "30945955821645377043120581432385562305707272746509870032635711882219904769766", "price": "0.999", "size": "80082.1", "side": "BUY", "hash": "fd932015375139dd75f0ea7a6f3c9e1ccd549f1e", "best_bid": "0.999", "best_ask": "1"}, {"asset_id": "75715544777874521912630047471213807609822733955542285127781965528868344383311", "price": "0.001", "size": "80082.1", "side": "SELL", "hash": "4277c8f7cbaf0be3d1971fb0eeaa159719bc30eb", "best_bid": "0", "best_ask": "0.001"}], "timestamp": "1769384107945", "event_type": "price_change"}}
{"_local_timestamp": "2026-01-25T23:35:08.033735+00:00", "data": {"market": "0xbe2b566c0abcd3fe4336f9cbe88a75a87a78673f7a39d31d4a1462d4b3a50888", "price_changes": [{"asset_id": "588547079469173719335200872670318735548084093624857812256307179730394747376", "price": "0.999", "size": "80090.78", "side": "BUY", "hash": "db40281f4c4d0412f8fa56740802871662830320", "best_bid": "0.999", "best_ask": "1"}, {"asset_id": "102561262047601806822226924855483392449010925057820256596841768139789198414780", "price": "0.001", "size": "80090.78", "side": "SELL", "hash": "4c84ad427c9a81556c2b8659346294959985bd06", "best_bid": "0", "best_ask": "0.001"}], "timestamp": "1769384107945", "event_type": "price_change"}}
{"_local_timestamp": "2026-01-25T23:35:08.437417+00:00", "data": {"market": "0x0158388d5142d4e9b565f2da3c6ce69b2756682b78fb0a9cab8840203a1a7a97", "price_changes": [{"asset_id": "61239095484488036374794236590506380508392866879329338142519253844360838103055", "price": "0.999", "size": "80119.1", "side": "BUY", "hash": "2925b856f720b0cef1deb3229ca27d3088b376a7", "best_bid": "0.999", "best_ask": "1"}, {"asset_id": "75227449954700285684044979609243838936234590419670661782079639952375897552885", "price": "0.001", "size": "80119.1", "side": "SELL", "hash": "bf63362fed0b3dc766f70435410b19f47adc2b41", "best_bid": "0", "best_ask": "0.001"}], "timestamp": "1769384108362", "event_type": "price_change"}}
{"_local_timestamp": "2026-01-25T23:35:08.437761+00:00", "data": {"market": "0x17aa2a7b47add5eb5866ab5cb4d73fa9fbd57c756fabaa94dc37e8f38d497edd", "price_changes": [{"asset_id": "33315863711622601322794791550568071116800577811624103081392589319514271651144", "price": "0.999", "size": "80123.58", "side": "BUY", "hash": "5e492c07a4f430d1a15e7dcec5875c374b00da17", "best_bid": "0.999", "best_ask": "1"}, {"asset_id": "36807728890327710559603862263987214098176146352243963377959711142197687028836", "price": "0.001", "size": "80123.58", "side": "SELL", "hash": "04e7f2bacf01c1c1cf1a8897dd37c48d7bf15dab", "best_bid": "0", "best_ask": "0.001"}], "timestamp": "1769384108362", "event_type": "price_change"}}
{"_local_timestamp": "2026-01-25T23:35:08.445229+00:00", "data": {"market": "0xe58a3bfab1a749e30d75907ef5b61a3092da48602ed1431054292efc86a541b5", "price_changes": [{"asset_id": "30945955821645377043120581432385562305707272746509870032635711882219904769766", "price": "0.999", "size": "80119.1", "side": "BUY", "hash": "b627ea348d877042e4b16672df18ec43e68abb18", "best_bid": "0.999", "best_ask": "1"}, {"asset_id": "75715544777874521912630047471213807609822733955542285127781965528868344383311", "price": "0.001", "size": "80119.1", "side": "SELL", "hash": "ebe5f6160783c673dd0081be6c3586b3ff475ab7", "best_bid": "0", "best_ask": "0.001"}], "timestamp": "1769384108362", "event_type": "price_change"}}
{"_local_timestamp": "2026-01-25T23:35:08.445659+00:00", "data": {"market": "0xbe2b566c0abcd3fe4336f9cbe88a75a87a78673f7a39d31d4a1462d4b3a50888", "price_changes": [{"asset_id": "588547079469173719335200872670318735548084093624857812256307179730394747376", "price": "0.999", "size": "80127.78", "side": "BUY", "hash": "fa6c212119418d70ad2b2c8f514e3a0f0730e621", "best_bid": "0.999", "best_ask": "1"}, {"asset_id": "102561262047601806822226924855483392449010925057820256596841768139789198414780", "price": "0.001", "size": "80127.78", "side": "SELL", "hash": "fce60eccc913058bf163b42287b417e743168775", "best_bid": "0", "best_ask": "0.001"}], "timestamp": "1769384108362", "event_type": "price_change"}}
{"_local_timestamp": "2026-01-25T23:35:08.886800+00:00", "data": {"market": "0x17aa2a7b47add5eb5866ab5cb4d73fa9fbd57c756fabaa94dc37e8f38d497edd", "price_changes": [{"asset_id": "33315863711622601322794791550568071116800577811624103081392589319514271651144", "price": "0.999", "size": "80159.58", "side": "BUY", "hash": "47a87f6d3e9a357ef69abe82d5bccade5b41be2e", "best_bid": "0.999", "best_ask": "1"}, {"asset_id": "36807728890327710559603862263987214098176146352243963377959711142197687028836", "price": "0.001", "size": "80159.58", "side": "SELL", "hash": "f70210770a229e809945e1fd3b86de99cc710caa", "best_bid": "0", "best_ask": "0.001"}], "timestamp": "1769384108812", "event_type": "price_change"}}
{"_local_timestamp": "2026-01-25T23:35:08.887218+00:00", "data": {"market": "0xbe2b566c0abcd3fe4336f9cbe88a75a87a78673f7a39d31d4a1462d4b3a50888", "price_changes": [{"asset_id": "588547079469173719335200872670318735548084093624857812256307179730394747376", "price": "0.999", "size": "80163.78", "side": "BUY", "hash": "438498912af1dc82c4d23d1d00ada33c6f1d473d", "best_bid": "0.999", "best_ask": "1"}, {"asset_id": "102561262047601806822226924855483392449010925057820256596841768139789198414780", "price": "0.001", "size": "80163.78", "side": "SELL", "hash": "c113d4459284a4c50a1648dd1f384a715d32e432", "best_bid": "0", "best_ask": "0.001"}], "timestamp": "1769384108813", "event_type": "price_change"}}
{"_local_timestamp": "2026-01-25T23:35:08.887612+00:00", "data": {"market": "0x0158388d5142d4e9b565f2da3c6ce69b2756682b78fb0a9cab8840203a1a7a97", "price_changes": [{"asset_id": "61239095484488036374794236590506380508392866879329338142519253844360838103055", "price": "0.999", "size": "80155.1", "side": "BUY", "hash": "62a5d531eddbafa529ea09c1de8e9058460a653d", "best_bid": "0.999", "best_ask": "1"}, {"asset_id": "75227449954700285684044979609243838936234590419670661782079639952375897552885", "price": "0.001", "size": "80155.1", "side": "SELL", "hash": "c3b04467b829deb1ef8fdbaf9579d70b83900b4e", "best_bid": "0", "best_ask": "0.001"}], "timestamp": "1769384108813", "event_type": "price_change"}}
{"_local_timestamp": "2026-01-25T23:35:08.888020+00:00", "data": {"market": "0xe58a3bfab1a749e30d75907ef5b61a3092da48602ed1431054292efc86a541b5", "price_changes": [{"asset_id": "30945955821645377043120581432385562305707272746509870032635711882219904769766", "price": "0.999", "size": "80155.1", "side": "BUY", "hash": "7cb754f1cde6ff7d93f643e9ef8dadad53f04a71", "best_bid": "0.999", "best_ask": "1"}, {"asset_id": "75715544777874521912630047471213807609822733955542285127781965528868344383311", "price": "0.001", "size": "80155.1", "side": "SELL", "hash": "bc04f1a83253f6c71b2068ead3590ba05805637e", "best_bid": "0", "best_ask": "0.001"}], "timestamp": "1769384108813", "event_type": "price_change"}}
{"_local_timestamp": "2026-01-25T23:35:09.237732+00:00", "data": {"market": "0x0158388d5142d4e9b565f2da3c6ce69b2756682b78fb0a9cab8840203a1a7a97", "price_changes": [{"asset_id": "61239095484488036374794236590506380508392866879329338142519253844360838103055", "price": "0.999", "size": "80190.1", "side": "BUY", "hash": "ddab4fa4a6804269f9ba7902c8d1e1c452269947", "best_bid": "0.999", "best_ask": "1"}, {"asset_id": "75227449954700285684044979609243838936234590419670661782079639952375897552885", "price": "0.001", "size": "80190.1", "side": "SELL", "hash": "89ced2ad7c894b6677bf07f1e9e85ac2a8560d97", "best_bid": "0", "best_ask": "0.001"}], "timestamp": "1769384109162", "event_type": "price_change"}}
{"_local_timestamp": "2026-01-25T23:35:09.243178+00:00", "data": {"market": "0xbe2b566c0abcd3fe4336f9cbe88a75a87a78673f7a39d31d4a1462d4b3a50888", "price_changes": [{"asset_id": "588547079469173719335200872670318735548084093624857812256307179730394747376", "price": "0.999", "size": "80198.78", "side": "BUY", "hash": "d79feb0bbccf300ed50a9ad7152d766c25365034", "best_bid": "0.999", "best_ask": "1"}, {"asset_id": "102561262047601806822226924855483392449010925057820256596841768139789198414780", "price": "0.001", "size": "80198.78", "side": "SELL", "hash": "6f9ff1e2191a26710e417d846043e4a417b96ed6", "best_bid": "0", "best_ask": "0.001"}], "timestamp": "1769384109162", "event_type": "price_change"}}
{"_local_timestamp": "2026-01-25T23:35:09.243694+00:00", "data": {"market": "0xe58a3bfab1a749e30d75907ef5b61a3092da48602ed1431054292efc86a541b5", "price_changes": [{"asset_id": "30945955821645377043120581432385562305707272746509870032635711882219904769766", "price": "0.999", "size": "80190.1", "side": "BUY", "hash": "229d827838fcd4444e3bfcef9271407a0c47b623", "best_bid": "0.999", "best_ask": "1"}, {"asset_id": "75715544777874521912630047471213807609822733955542285127781965528868344383311", "price": "0.001", "size": "80190.1", "side": "SELL", "hash": "c482fa8e6f7424f466386cd2c62e6d4898f55f8c", "best_bid": "0", "best_ask": "0.001"}], "timestamp": "1769384109162", "event_type": "price_change"}}
{"_local_timestamp": "2026-01-25T23:35:09.244016+00:00", "data": {"market": "0x17aa2a7b47add5eb5866ab5cb4d73fa9fbd57c756fabaa94dc37e8f38d497edd", "price_changes": [{"asset_id": "33315863711622601322794791550568071116800577811624103081392589319514271651144", "price": "0.999", "size": "80194.58", "side": "BUY", "hash": "0b71da71f13c34d964bd0e216333e339211c0bf6", "best_bid": "0.999", "best_ask": "1"}, {"asset_id": "36807728890327710559603862263987214098176146352243963377959711142197687028836", "price": "0.001", "size": "80194.58", "side": "SELL", "hash": "8bddd257a91c01687428d368174bfe16fbdeaa6a", "best_bid": "0", "best_ask": "0.001"}], "timestamp": "1769384109162", "event_type": "price_change"}}
{"_local_timestamp": "2026-01-25T23:35:12.142421+00:00", "data": {"market": "0xe58a3bfab1a749e30d75907ef5b61a3092da48602ed1431054292efc86a541b5", "price_changes": [{"asset_id": "30945955821645377043120581432385562305707272746509870032635711882219904769766", "price": "0.999", "size": "80814.1", "side": "BUY", "hash": "fe5206645bf12218bb5509504dcf45565f261455", "best_bid": "0.999", "best_ask": "1"}, {"asset_id": "75715544777874521912630047471213807609822733955542285127781965528868344383311", "price": "0.001", "size": "80814.1", "side": "SELL", "hash": "181583bb1d4ae3b8a866c0a7e52a3c27a2907556", "best_bid": "0", "best_ask": "0.001"}], "timestamp": "1769384112047", "event_type": "price_change"}}
{"_local_timestamp": "2026-01-25T23:35:12.143998+00:00", "data": {"market": "0x17aa2a7b47add5eb5866ab5cb4d73fa9fbd57c756fabaa94dc37e8f38d497edd", "price_changes": [{"asset_id": "33315863711622601322794791550568071116800577811624103081392589319514271651144", "price": "0.999", "size": "80818.58", "side": "BUY", "hash": "800aff959c899d3201988fadc58ccccccf32e3eb", "best_bid": "0.999", "best_ask": "1"}, {"asset_id": "36807728890327710559603862263987214098176146352243963377959711142197687028836", "price": "0.001", "size": "80818.58", "side": "SELL", "hash": "622bb6e7d305198a15fe2d3927a03ca5d6b65bea", "best_bid": "0", "best_ask": "0.001"}], "timestamp": "1769384112047", "event_type": "price_change"}}
{"_local_timestamp": "2026-01-25T23:35:12.144296+00:00", "data": {"market": "0x0158388d5142d4e9b565f2da3c6ce69b2756682b78fb0a9cab8840203a1a7a97", "price_changes": [{"asset_id": "61239095484488036374794236590506380508392866879329338142519253844360838103055", "price": "0.999", "size": "80814.1", "side": "BUY", "hash": "d3914796344fb7268a4181413e957a13ba9783b4", "best_bid": "0.999", "best_ask": "1"}, {"asset_id": "75227449954700285684044979609243838936234590419670661782079639952375897552885", "price": "0.001", "size": "80814.1", "side": "SELL", "hash": "3b43fb246f4461aa82e8670fa61b3cf28f092a79", "best_bid": "0", "best_ask": "0.001"}], "timestamp": "1769384112047", "event_type": "price_change"}}
{"_local_timestamp": "2026-01-25T23:35:12.144538+00:00", "data": {"market": "0xbe2b566c0abcd3fe4336f9cbe88a75a87a78673f7a39d31d4a1462d4b3a50888", "price_changes": [{"asset_id": "588547079469173719335200872670318735548084093624857812256307179730394747376", "price": "0.999", "size": "80822.78", "side": "BUY", "hash": "7145c0acc12dc9b2b710431efec639f23d9393e1", "best_bid": "0.999", "best_ask": "1"}, {"asset_id": "102561262047601806822226924855483392449010925057820256596841768139789198414780", "price": "0.001", "size": "80822.78", "side": "SELL", "hash": "23c0c885913ca21bcbed2f00811c315856fb696b", "best_bid": "0", "best_ask": "0.001"}], "timestamp": "1769384112047", "event_type": "price_change"}}
{"_local_timestamp": "2026-01-25T23:35:14.136138+00:00", "data": {"market": "0xbe2b566c0abcd3fe4336f9cbe88a75a87a78673f7a39d31d4a1462d4b3a50888", "price_changes": [{"asset_id": "588547079469173719335200872670318735548084093624857812256307179730394747376", "price": "0.999", "size": "80977.78", "side": "BUY", "hash": "5303489e50947f845d41a3fc46563b95d02cd1b4", "best_bid": "0.999", "best_ask": "1"}, {"asset_id": "102561262047601806822226924855483392449010925057820256596841768139789198414780", "price": "0.001", "size": "80977.78", "side": "SELL", "hash": "720c38f263bdc94accb154d3d615199dae15100c", "best_bid": "0", "best_ask": "0.001"}], "timestamp": "1769384114062", "event_type": "price_change"}}
{"_local_timestamp": "2026-01-25T23:35:14.147181+00:00", "data": {"market": "0xe58a3bfab1a749e30d75907ef5b61a3092da48602ed1431054292efc86a541b5", "price_changes": [{"asset_id": "30945955821645377043120581432385562305707272746509870032635711882219904769766", "price": "0.999", "size": "80969.1", "side": "BUY", "hash": "847d4654aaae82c2c28c6cf39e5299f45995df9b", "best_bid": "0.999", "best_ask": "1"}, {"asset_id": "75715544777874521912630047471213807609822733955542285127781965528868344383311", "price": "0.001", "size": "80969.1", "side": "SELL", "hash": "bec7a700d5b516aa03005baccd566b217360e685", "best_bid": "0", "best_ask": "0.001"}], "timestamp": "1769384114061", "event_type": "price_change"}}
{"_local_timestamp": "2026-01-25T23:35:14.163783+00:00", "data": {"market": "0x17aa2a7b47add5eb5866ab5cb4d73fa9fbd57c756fabaa94dc37e8f38d497edd", "price_changes": [{"asset_id": "33315863711622601322794791550568071116800577811624103081392589319514271651144", "price": "0.999", "size": "80973.58", "side": "BUY", "hash": "eead9e5c143a195850abff88f7a7ad811044c1b5", "best_bid": "0.999", "best_ask": "1"}, {"asset_id": "36807728890327710559603862263987214098176146352243963377959711142197687028836", "price": "0.001", "size": "80973.58", "side": "SELL", "hash": "735af1592800869ceeb7cb19b693293e479db097", "best_bid": "0", "best_ask": "0.001"}], "timestamp": "1769384114061", "event_type": "price_change"}}
{"_local_timestamp": "2026-01-25T23:35:14.164320+00:00", "data": {"market": "0x0158388d5142d4e9b565f2da3c6ce69b2756682b78fb0a9cab8840203a1a7a97", "price_changes": [{"asset_id": "61239095484488036374794236590506380508392866879329338142519253844360838103055", "price": "0.999", "size": "80969.1", "side": "BUY", "hash": "46e5a1d1c0363860d3b59360a66a3228b76b35ef", "best_bid": "0.999", "best_ask": "1"}, {"asset_id": "75227449954700285684044979609243838936234590419670661782079639952375897552885", "price": "0.001", "size": "80969.1", "side": "SELL", "hash": "210a6dcf4eb52f1e3d563a08fab29a1d29dad316", "best_bid": "0", "best_ask": "0.001"}], "timestamp": "1769384114061", "event_type": "price_change"}}
{"_local_timestamp": "2026-01-25T23:35:14.611680+00:00", "data": {"market": "0x17aa2a7b47add5eb5866ab5cb4d73fa9fbd57c756fabaa94dc37e8f38d497edd", "price_changes": [{"asset_id": "33315863711622601322794791550568071116800577811624103081392589319514271651144", "price": "0.999", "size": "81127.58", "side": "BUY", "hash": "e88948336fa34b16544944dc865207f9a0cfc8cc", "best_bid": "0.999", "best_ask": "1"}, {"asset_id": "36807728890327710559603862263987214098176146352243963377959711142197687028836", "price": "0.001", "size": "81127.58", "side": "SELL", "hash": "f438f75d44ec652f8d0ea4fbcc77271e24828538", "best_bid": "0", "best_ask": "0.001"}], "timestamp": "1769384114542", "event_type": "price_change"}}
{"_local_timestamp": "2026-01-25T23:35:14.612098+00:00", "data": {"market": "0xe58a3bfab1a749e30d75907ef5b61a3092da48602ed1431054292efc86a541b5", "price_changes": [{"asset_id": "30945955821645377043120581432385562305707272746509870032635711882219904769766", "price": "0.999", "size": "81123.1", "side": "BUY", "hash": "463a3fa3c2a4e48b896f4dd02ecf5389d1554627", "best_bid": "0.999", "best_ask": "1"}, {"asset_id": "75715544777874521912630047471213807609822733955542285127781965528868344383311", "price": "0.001", "size": "81123.1", "side": "SELL", "hash": "4cd4921d8f1c933a9cb2474de8e100ccc95a9d4e", "best_bid": "0", "best_ask": "0.001"}], "timestamp": "1769384114542", "event_type": "price_change"}}
{"_local_timestamp": "2026-01-25T23:35:14.612350+00:00", "data": {"market": "0xbe2b566c0abcd3fe4336f9cbe88a75a87a78673f7a39d31d4a1462d4b3a50888", "price_changes": [{"asset_id": "588547079469173719335200872670318735548084093624857812256307179730394747376", "price": "0.999", "size": "81131.78", "side": "BUY", "hash": "3306250ae8f073d16b9652fea9e1fee36c5ae895", "best_bid": "0.999", "best_ask": "1"}, {"asset_id": "102561262047601806822226924855483392449010925057820256596841768139789198414780", "price": "0.001", "size": "81131.78", "side": "SELL", "hash": "961918ca096c9af79a50be8f251a751725b6ba9b", "best_bid": "0", "best_ask": "0.001"}], "timestamp": "1769384114542", "event_type": "price_change"}}
{"_local_timestamp": "2026-01-25T23:35:14.612578+00:00", "data": {"market": "0x0158388d5142d4e9b565f2da3c6ce69b2756682b78fb0a9cab8840203a1a7a97", "price_changes": [{"asset_id": "61239095484488036374794236590506380508392866879329338142519253844360838103055", "price": "0.999", "size": "81123.1", "side": "BUY", "hash": "b6319a9eb8f590451b8c94eae275b78c1e2b7cd8", "best_bid": "0.999", "best_ask": "1"}, {"asset_id": "75227449954700285684044979609243838936234590419670661782079639952375897552885", "price": "0.001", "size": "81123.1", "side": "SELL", "hash": "e11d0c837688964b4651eb9526013b54c5bf1942", "best_bid": "0", "best_ask": "0.001"}], "timestamp": "1769384114542", "event_type": "price_change"}}
{"_local_timestamp": "2026-01-25T23:35:15.181521+00:00", "data": {"market": "0xe58a3bfab1a749e30d75907ef5b61a3092da48602ed1431054292efc86a541b5", "price_changes": [{"asset_id": "30945955821645377043120581432385562305707272746509870032635711882219904769766", "price": "0.999", "size": "81276.1", "side": "BUY", "hash": "7de7d495097dbc4756449618d52cc952dec8d1a7", "best_bid": "0.999", "best_ask": "1"}, {"asset_id": "75715544777874521912630047471213807609822733955542285127781965528868344383311", "price": "0.001", "size": "81276.1", "side": "SELL", "hash": "ddacf6811840236137d62950fa73923208f19de4", "best_bid": "0", "best_ask": "0.001"}], "timestamp": "1769384115110", "event_type": "price_change"}}
{"_local_timestamp": "2026-01-25T23:35:15.185457+00:00", "data": {"market": "0xbe2b566c0abcd3fe4336f9cbe88a75a87a78673f7a39d31d4a1462d4b3a50888", "price_changes": [{"asset_id": "588547079469173719335200872670318735548084093624857812256307179730394747376", "price": "0.999", "size": "81284.78", "side": "BUY", "hash": "41ed6bf2334ef0ab85632b972ff193d9be132e2f", "best_bid": "0.999", "best_ask": "1"}, {"asset_id": "102561262047601806822226924855483392449010925057820256596841768139789198414780", "price": "0.001", "size": "81284.78", "side": "SELL", "hash": "b049f5bafe090038ef16afa84f2aabe15b8157e2", "best_bid": "0", "best_ask": "0.001"}], "timestamp": "1769384115110", "event_type": "price_change"}}
{"_local_timestamp": "2026-01-25T23:35:15.197345+00:00", "data": {"market": "0x0158388d5142d4e9b565f2da3c6ce69b2756682b78fb0a9cab8840203a1a7a97", "price_changes": [{"asset_id": "61239095484488036374794236590506380508392866879329338142519253844360838103055", "price": "0.999", "size": "81276.1", "side": "BUY", "hash": "2c2a7af4b432d93e74e217163350310205e91f25", "best_bid": "0.999", "best_ask": "1"}, {"asset_id": "75227449954700285684044979609243838936234590419670661782079639952375897552885", "price": "0.001", "size": "81276.1", "side": "SELL", "hash": "8bbbfe31604f7c1a12c1309b5f300cb133af3323", "best_bid": "0", "best_ask": "0.001"}], "timestamp": "1769384115113", "event_type": "price_change"}}
{"_local_timestamp": "2026-01-25T23:35:15.197682+00:00", "data": {"market": "0x17aa2a7b47add5eb5866ab5cb4d73fa9fbd57c756fabaa94dc37e8f38d497edd", "price_changes": [{"asset_id": "33315863711622601322794791550568071116800577811624103081392589319514271651144", "price": "0.999", "size": "81280.58", "side": "BUY", "hash": "3023b3f431f1c70a2d35ee0278d8939b8c019113", "best_bid": "0.999", "best_ask": "1"}, {"asset_id": "36807728890327710559603862263987214098176146352243963377959711142197687028836", "price": "0.001", "size": "81280.58", "side": "SELL", "hash": "a9028e82807d88a9af7e9dd5cc9116bae744d23d", "best_bid": "0", "best_ask": "0.001"}], "timestamp": "1769384115114", "event_type": "price_change"}}
{"_local_timestamp": "2026-01-25T23:35:17.919277+00:00", "data": {"market": "0x17aa2a7b47add5eb5866ab5cb4d73fa9fbd57c756fabaa94dc37e8f38d497edd", "price_changes": [{"asset_id": "33315863711622601322794791550568071116800577811624103081392589319514271651144", "price": "0.999", "size": "81314.58", "side": "BUY", "hash": "ecd5be7696a568eb4cd2d14ddadff5480f2d020d", "best_bid": "0.999", "best_ask": "1"}, {"asset_id": "36807728890327710559603862263987214098176146352243963377959711142197687028836", "price": "0.001", "size": "81314.58", "side": "SELL", "hash": "0065a4634f7c3e11d814f99c342d08ade86245e5", "best_bid": "0", "best_ask": "0.001"}], "timestamp": "1769384117844", "event_type": "price_change"}}
{"_local_timestamp": "2026-01-25T23:35:17.925033+00:00", "data": {"market": "0xbe2b566c0abcd3fe4336f9cbe88a75a87a78673f7a39d31d4a1462d4b3a50888", "price_changes": [{"asset_id": "588547079469173719335200872670318735548084093624857812256307179730394747376", "price": "0.999", "size": "81318.78", "side": "BUY", "hash": "a49e1e362a3dcbbd340d36eeb8163616d57a41d0", "best_bid": "0.999", "best_ask": "1"}, {"asset_id": "102561262047601806822226924855483392449010925057820256596841768139789198414780", "price": "0.001", "size": "81318.78", "side": "SELL", "hash": "1f494750827bbf7213b777439fe08188dcd10d46", "best_bid": "0", "best_ask": "0.001"}], "timestamp": "1769384117844", "event_type": "price_change"}}
{"_local_timestamp": "2026-01-25T23:35:17.925372+00:00", "data": {"market": "0x0158388d5142d4e9b565f2da3c6ce69b2756682b78fb0a9cab8840203a1a7a97", "price_changes": [{"asset_id": "61239095484488036374794236590506380508392866879329338142519253844360838103055", "price": "0.999", "size": "81310.1", "side": "BUY", "hash": "5a55202ca6812c6352efca785bc1d341158b90d2", "best_bid": "0.999", "best_ask": "1"}, {"asset_id": "75227449954700285684044979609243838936234590419670661782079639952375897552885", "price": "0.001", "size": "81310.1", "side": "SELL", "hash": "5786909cddfda2d99666c65a73dcb74b68dbb84f", "best_bid": "0", "best_ask": "0.001"}], "timestamp": "1769384117844", "event_type": "price_change"}}
{"_local_timestamp": "2026-01-25T23:35:17.925621+00:00", "data": {"market": "0xe58a3bfab1a749e30d75907ef5b61a3092da48602ed1431054292efc86a541b5", "price_changes": [{"asset_id": "30945955821645377043120581432385562305707272746509870032635711882219904769766", "price": "0.999", "size": "81310.1", "side": "BUY", "hash": "ee937f4c6cc97af7cfe5f0d93dfa4ec9668c7028", "best_bid": "0.999", "best_ask": "1"}, {"asset_id": "75715544777874521912630047471213807609822733955542285127781965528868344383311", "price": "0.001", "size": "81310.1", "side": "SELL", "hash": "b0e0ba49f0985c3f86afcb40366f56fd055fac4f", "best_bid": "0", "best_ask": "0.001"}], "timestamp": "1769384117844", "event_type": "price_change"}}
