{"_local_timestamp": "2026-01-25T23:40:30.409702+00:00", "data": [{"market": "0x5c5d898595b3445dd3809896302889cd512411fa8306de609d9d8aa34e257ba8", "asset_id": "45014676111572901552217363692090679327003594688155466306257909550735876308571", "timestamp": "1769384425843", "hash": "bd01b39c7255c7b8d87613d55c068c74f20b23ac", "bids": [], "asks": [{"price": "0.999", "size": "8105561.01"}, {"price": "0.998", "size": "250"}, {"price": "0.997", "size": "400"}, {"price": "0.996", "size": "8.66"}, {"price": "0.994", "size": "1000200"}, {"price": "0.993", "size": "500000"}, {"price": "0.99", "size": "6760"}, {"price": "0.989", "size": "5.3"}, {"price": "0.98", "size": "3875"}, {"price": "0.979", "size": "21400"}, {"price": "0.978", "size": "250"}, {"price": "0.977", "size": "7.63"}, {"price": "0.96", "size": "2200"}, {"price": "0.95", "size": "30"}, {"price": "0.949", "size": "39"}, {"price": "0.94", "size": "975"}, {"price": "0.939", "size": "8.9"}, {"price": "0.9", "size": "1500"}, {"price": "0.85", "size": "700"}, {"price": "0.849", "size": "6250"}, {"price": "0.8", "size": "200"}, {"price": "0.799", "size": "5.83"}, {"price": "0.777", "size": "57"}, {"price": "0.69", "size": "3061.6"}, {"price": "0.64", "size": "3600"}, {"price": "0.622", "size": "4544"}, {"price": "0.595", "size": "5000"}, {"price": "0.594", "size": "6000"}, {"price": "0.593", "size": "5855"}, {"price": "0.592", "size": "5"}, {"price": "0.477", "size": "136"}, {"price": "0.3", "size": "5"}, {"price": "0.277", "size": "119"}, {"price": "0.276", "size": "30"}, {"price": "0.2", "size": "2000"}, {"price": "0.199", "size": "20"}, {"price": "0.198", "size": "20"}, {"price": "0.177", "size": "110"}, {"price": "0.143", "size": "413.43"}, {"price": "0.129", "size": "413.7"}, {"price": "0.127", "size": "1614.74"}, {"price": "0.1", "size": "40"}, {"price": "0.099", "size": "413.42"}, {"price": "0.09", "size": "413.7"}, {"price": "0.085", "size": "17.12"}, {"price": "0.078", "size": "1063.02"}, {"price": "0.077", "size": "379"}, {"price": "0.076", "size": "5"}, {"price": "0.071", "size": "1063.02"}, {"price": "0.07", "size": "444"}, {"price": "0.058", "size": "985.81"}, {"price": "0.049", "size": "136.73"}, {"price": "0.048", "size": "20"}, {"price": "0.045", "size": "647.85"}, {"price": "0.036", "size": "1614.73"}, {"price": "0.032", "size": "3965.01"}, {"price": "0.026", "size": "8384"}, {"price": "0.024", "size": "1740.3"}, {"price": "0.02", "size": "2636.61"}, {"price": "0.019", "size": "3965"}, {"price": "0.015", "size": "3950.19"}, {"price": "0.014", "size": "2381.07"}, {"price": "0.013", "size": "4383.62"}, {"price": "0.012", "size": "4395.73"}, {"price": "0.011", "size": "2030.8"}, {"price": "0.01", "size": "4762.17"}, {"price": "0.009", "size": "2710.91"}, {"price": "0.008", "size": "2942.05"}, {"price": "0.005", "size": "200"}, {"price": "0.004", "size": "270"}, {"price": "0.003", "size": "2702.55"}, {"price": "0.002", "size": "22641.52"}, {"price": "0.001", "size": "4743.55"}], "event_type": "book", "last_trade_price": "0.001"}, {"market": "0x12817d6a15f0fb839157bc5e61f8a3e5b4c1b78da852aceb490a04f70866b2d8", "asset_id": "5140781455716909563776111637536865083352312125872611479651831996330931913942", "timestamp": "1769384415667", "hash": "fd28306e2183b1c26b3a7514d55af194470a9a42", "bids": [], "asks": [{"price": "0.999", "size": "3102607"}, {"price": "0.998", "size": "2001450"}, {"price": "0.997", "size": "406.62"}, {"price": "0.994", "size": "200"}, {"price": "0.993", "size": "9.76"}, {"price": "0.99", "size": "6960"}, {"price": "0.98", "size": "5275"}, {"price": "0.96", "size": "2200"}, {"price": "0.95", "size": "10"}, {"price": "0.94", "size": "975"}, {"price": "0.9", "size": "1200"}, {"price": "0.857", "size": "20700"}, {"price": "0.856", "size": "5050"}, {"price": "0.85", "size": "500"}, {"price": "0.849", "size": "8.94"}, {"price": "0.777", "size": "143"}, {"price": "0.74", "size": "2800"}, {"price": "0.739", "size": "10000"}, {"price": "0.738", "size": "250"}, {"price": "0.67", "size": "3033.71"}, {"price": "0.66", "size": "100"}, {"price": "0.477", "size": "135"}, {"price": "0.423", "size": "5000"}, {"price": "0.422", "size": "4146"}, {"price": "0.421", "size": "5"}, {"price": "0.277", "size": "280"}, {"price": "0.177", "size": "644"}, {"price": "0.1", "size": "5"}, {"price": "0.093", "size": "200"}, {"price": "0.077", "size": "718"}, {"price": "0.076", "size": "500"}, {"price": "0.075", "size": "108"}, {"price": "0.065", "size": "20"}, {"price": "0.064", "size": "20"}, {"price": "0.063", "size": "30"}, {"price": "0.033", "size": "500"}, {"price": "0.009", "size": "333.33"}, {"price": "0.008", "size": "500"}, {"price": "0.005", "size": "294.01"}, {"price": "0.004", "size": "500"}, {"price": "0.003", "size": "15.78"}, {"price": "0.002", "size": "2889.49"}, {"price": "0.001", "size": "41517.65"}], "event_type": "book", "last_trade_price": "0.001"}, {"market": "0xe9215ac1b5d18ecd3bdc4e91942674146385871bdd14ff0578acd126c9b5a083", "asset_id": "50506784840746014472165828748986922256603852018037221896235814226504255159103", "timestamp": "1769384403047", "hash": "5eb7b656b0179fe8629c2a453f469d484a258f58", "bids": [{"price": "0.001", "size": "3102803"}, {"price": "0.002", "size": "250"}, {"price": "0.003", "size": "406.63"}, {"price": "0.005", "size": "200000"}, {"price": "0.006", "size": "1001400"}, {"price": "0.007", "size": "9.76"}, {"price": "0.01", "size": "6760"}, {"price": "0.02", "size": "5275"}, {"price": "0.021", "size": "8.81"}, {"price": "0.04", "size": "2200"}, {"price": "0.041", "size": "250"}, {"price": "0.05", "size": "30"}, {"price": "0.051", "size": "39"}, {"price": "0.06", "size": "975"}, {"price": "0.061", "size": "8.89"}, {"price": "0.1", "size": "1200"}, {"price": "0.14", "size": "5314"}, {"price": "0.15", "size": "500"}, {"price": "0.2", "size": "200"}, {"price": "0.201", "size": "5.83"}, {"price": "0.223", "size": "143"}, {"price": "0.27", "size": "200"}, {"price": "0.37", "size": "2933.71"}, {"price": "0.51", "size": "1600"}, {"price": "0.523", "size": "567"}, {"price": "0.601", "size": "20000"}, {"price": "0.602", "size": "3184"}, {"price": "0.631", "size": "700"}, {"price": "0.632", "size": "5"}, {"price": "0.723", "size": "280"}, {"price": "0.823", "size": "158"}, {"price": "0.837", "size": "20"}, {"price": "0.839", "size": "20"}, {"price": "0.841", "size": "30"}, {"price": "0.842", "size": "20"}, {"price": "0.923", "size": "387"}, {"price": "0.94", "size": "1666.21"}, {"price": "0.941", "size": "500"}, {"price": "0.943", "size": "300"}, {"price": "0.948", "size": "611.17"}, {"price": "0.949", "size": "500"}, {"price": "0.95", "size": "300"}, {"price": "0.951", "size": "400"}, {"price": "0.964", "size": "300"}, {"price": "0.967", "size": "132.6"}, {"price": "0.969", "size": "200"}, {"price": "0.973", "size": "100"}, {"price": "0.976", "size": "125"}, {"price": "0.983", "size": "244.2"}, {"price": "0.984", "size": "980"}, {"price": "0.985", "size": "278.79"}, {"price": "0.986", "size": "13.2"}], "asks": [{"price": "0.999", "size": "81114.48"}, {"price": "0.998", "size": "12838.76"}, {"price": "0.997", "size": "250"}, {"price": "0.995", "size": "100"}, {"price": "0.99", "size": "50"}, {"price": "0.989", "size": "6069.23"}, {"price": "0.988", "size": "769.23"}, {"price": "0.987", "size": "18974.8"}], "event_type": "book", "last_trade_price": "0.013"}, {"market": "0xf2fb4784ceb4d41ce23703da426700f710320ec5b711b6e3784bdaac24d94c23", "asset_id": "88794755386871079853762415286654635832909423950620116774027006364873482091563", "timestamp": "1769384429915", "hash": "8313786ac13474558981d9584338fd54d620af28", "bids": [{"price": "0.001", "size": "2155.13"}, {"price": "0.002", "size": "250"}, {"price": "0.003", "size": "29.82"}, {"price": "0.01", "size": "1007960"}, {"price": "0.02", "size": "3875"}, {"price": "0.021", "size": "8.92"}, {"price": "0.03", "size": "100000"}, {"price": "0.04", "size": "103600"}, {"price": "0.041", "size": "250"}, {"price": "0.05", "size": "30"}, {"price": "0.051", "size": "39"}, {"price": "0.06", "size": "1175"}, {"price": "0.061", "size": "8.95"}, {"price": "0.1", "size": "500"}, {"price": "0.13", "size": "6000"}, {"price": "0.14", "size": "50"}, {"price": "0.15", "size": "700"}, {"price": "0.201", "size": "796"}, {"price": "0.202", "size": "5.77"}, {"price": "0.222", "size": "2090"}, {"price": "0.23", "size": "6"}, {"price": "0.27", "size": "200"}, {"price": "0.34", "size": "3600"}, {"price": "0.35", "size": "2500"}, {"price": "0.36", "size": "2000"}, {"price": "0.367", "size": "594"}, {"price": "0.377", "size": "773"}, {"price": "0.427", "size": "45"}, {"price": "0.447", "size": "829"}, {"price": "0.448", "size": "3097"}, {"price": "0.467", "size": "22"}, {"price": "0.5", "size": "20"}, {"price": "0.587", "size": "10"}, {"price": "0.599", "size": "1800"}, {"price": "0.609", "size": "802"}, {"price": "0.619", "size": "720"}, {"price": "0.62", "size": "326.14"}, {"price": "0.629", "size": "117"}, {"price": "0.639", "size": "301"}, {"price": "0.65", "size": "284"}, {"price": "0.66", "size": "251"}, {"price": "0.67", "size": "234"}, {"price": "0.681", "size": "351"}, {"price": "0.691", "size": "174"}, {"price": "0.701", "size": "87"}, {"price": "0.712", "size": "920"}, {"price": "0.722", "size": "1026"}, {"price": "0.732", "size": "107"}, {"price": "0.75", "size": "10000"}, {"price": "0.751", "size": "700"}, {"price": "0.752", "size": "30"}, {"price": "0.795", "size": "247"}, {"price": "0.796", "size": "20"}, {"price": "0.8", "size": "5"}, {"price": "0.81", "size": "860.95"}, {"price": "0.816", "size": "358"}, {"price": "0.82", "size": "912.35"}, {"price": "0.821", "size": "200"}, {"price": "0.824", "size": "20"}, {"price": "0.825", "size": "20"}, {"price": "0.841", "size": "1000"}, {"price": "0.843", "size": "36"}, {"price": "0.851", "size": "1598"}, {"price": "0.858", "size": "25"}, {"price": "0.859", "size": "200"}, {"price": "0.864", "size": "60"}, {"price": "0.865", "size": "50"}], "asks": [{"price": "0.999", "size": "88188.99"}, {"price": "0.998", "size": "666"}, {"price": "0.99", "size": "7230"}, {"price": "0.989", "size": "8.26"}, {"price": "0.982", "size": "800"}, {"price": "0.981", "size": "3200"}, {"price": "0.98", "size": "1800"}, {"price": "0.967", "size": "400"}, {"price": "0.966", "size": "852.96"}, {"price": "0.965", "size": "1000"}, {"price": "0.964", "size": "1252.5"}, {"price": "0.963", "size": "250"}, {"price": "0.954", "size": "21"}, {"price": "0.953", "size": "76.41"}, {"price": "0.952", "size": "100"}, {"price": "0.95", "size": "73.24"}, {"price": "0.948", "size": "172"}, {"price": "0.947", "size": "16"}, {"price": "0.945", "size": "64.06"}, {"price": "0.94", "size": "16"}, {"price": "0.931", "size": "119.99"}, {"price": "0.93", "size": "5"}, {"price": "0.924", "size": "30"}, {"price": "0.915", "size": "13.65"}, {"price": "0.912", "size": "16.59"}, {"price": "0.907", "size": "64.67"}, {"price": "0.905", "size": "66.32"}, {"price": "0.903", "size": "28"}, {"price": "0.902", "size": "411"}, {"price": "0.895", "size": "18.73"}, {"price": "0.889", "size": "42.16"}, {"price": "0.882", "size": "450"}, {"price": "0.88", "size": "200.01"}, {"price": "0.879", "size": "183.75"}, {"price": "0.877", "size": "125"}], "event_type": "book", "last_trade_price": "0.124"}, {"market": "0x2e51ed86458e0a53ef3a2e882d2f857683dfe41822c2c26176c971e25a5a8db2", "asset_id": "35860392242789677660843128633880273047999536228481481169784265672448106307688", "timestamp": "1769384398149", "hash": "e5cc90e36830d6f1da10c960a5dba48627c57da9", "bids": [], "asks": [{"price": "0.999", "size": "3102414"}, {"price": "0.998", "size": "3001200"}, {"price": "0.997", "size": "406.62"}, {"price": "0.994", "size": "200"}, {"price": "0.993", "size": "9.76"}, {"price": "0.99", "size": "6810"}, {"price": "0.98", "size": "4875"}, {"price": "0.979", "size": "8.81"}, {"price": "0.96", "size": "1500"}, {"price": "0.95", "size": "10"}, {"price": "0.94", "size": "2175"}, {"price": "0.939", "size": "8.89"}, {"price": "0.9", "size": "500"}, {"price": "0.887", "size": "25000"}, {"price": "0.885", "size": "50900"}, {"price": "0.88", "size": "18100"}, {"price": "0.879", "size": "250"}, {"price": "0.86", "size": "50"}, {"price": "0.85", "size": "700"}, {"price": "0.8", "size": "200"}, {"price": "0.799", "size": "5.84"}, {"price": "0.73", "size": "200"}, {"price": "0.66", "size": "100"}, {"price": "0.58", "size": "2833.71"}, {"price": "0.477", "size": "136"}, {"price": "0.381", "size": "3845"}, {"price": "0.38", "size": "644"}, {"price": "0.1", "size": "63"}, {"price": "0.077", "size": "20"}, {"price": "0.065", "size": "555"}, {"price": "0.06", "size": "641"}, {"price": "0.057", "size": "30"}, {"price": "0.056", "size": "20"}, {"price": "0.055", "size": "20"}, {"price": "0.035", "size": "60.76"}, {"price": "0.004", "size": "253.77"}, {"price": "0.003", "size": "15.17"}, {"price": "0.002", "size": "2954.11"}, {"price": "0.001", "size": "10607.64"}], "event_type": "book", "last_trade_price": ""}, {"market": "0xbe1c736f56cade44537b90c07edb9209eba1ab044fa57b6f3900b8fd26570c61", "asset_id": "3966533862466247704344244549971560368457045062860350677311447732853769253405", "timestamp": "1769384396334", "hash": "409de0c9aa9dfaac8b1833047911eb26dae8cbe4", "bids": [], "asks": [{"price": "0.999", "size": "3100713"}, {"price": "0.998", "size": "3001200"}, {"price": "0.997", "size": "6.62"}, {"price": "0.994", "size": "83"}, {"price": "0.993", "size": "9.76"}, {"price": "0.99", "size": "7214.01"}, {"price": "0.98", "size": "4875"}, {"price": "0.979", "size": "9.02"}, {"price": "0.96", "size": "1500"}, {"price": "0.95", "size": "30"}, {"price": "0.945", "size": "60000"}, {"price": "0.944", "size": "71600"}, {"price": "0.94", "size": "375"}, {"price": "0.939", "size": "187"}, {"price": "0.938", "size": "8.68"}, {"price": "0.9", "size": "1200"}, {"price": "0.85", "size": "1250"}, {"price": "0.8", "size": "200"}, {"price": "0.799", "size": "5.84"}, {"price": "0.777", "size": "65"}, {"price": "0.73", "size": "200"}, {"price": "0.65", "size": "2933.71"}, {"price": "0.596", "size": "4444"}, {"price": "0.477", "size": "136"}, {"price": "0.399", "size": "500"}, {"price": "0.324", "size": "3542"}, {"price": "0.323", "size": "595"}, {"price": "0.322", "size": "147"}, {"price": "0.1", "size": "5"}, {"price": "0.075", "size": "30"}, {"price": "0.074", "size": "20"}, {"price": "0.073", "size": "20"}, {"price": "0.072", "size": "20"}, {"price": "0.017", "size": "100"}, {"price": "0.011", "size": "105"}, {"price": "0.007", "size": "444.55"}, {"price": "0.006", "size": "1200"}, {"price": "0.005", "size": "300"}, {"price": "0.003", "size": "48.63"}, {"price": "0.002", "size": "2080.49"}, {"price": "0.001", "size": "24547.64"}], "event_type": "book", "last_trade_price": ""}, {"market": "0x2e51ed86458e0a53ef3a2e882d2f857683dfe41822c2c26176c971e25a5a8db2", "asset_id": "104136471953275707571448642325206840852839877417604434112982860785920924591128", "timestamp": "1769384398149", "hash": "e5f5150f7bcb75759685054654efff6fff3f858d", "bids": [{"price": "0.001", "size": "3102414"}, {"price": "0.002", "size": "3001200"}, {"price": "0.003", "size": "406.62"}, {"price": "0.006", "size": "200"}, {"price": "0.007", "size": "9.76"}, {"price": "0.01", "size": "6810"}, {"price": "0.02", "size": "4875"}, {"price": "0.021", "size": "8.81"}, {"price": "0.04", "size": "1500"}, {"price": "0.05", "size": "10"}, {"price": "0.06", "size": "2175"}, {"price": "0.061", "size": "8.89"}, {"price": "0.1", "size": "500"}, {"price": "0.113", "size": "25000"}, {"price": "0.115", "size": "50900"}, {"price": "0.12", "size": "18100"}, {"price": "0.121", "size": "250"}, {"price": "0.14", "size": "50"}, {"price": "0.15", "size": "700"}, {"price": "0.2", "size": "200"}, {"price": "0.201", "size": "5.84"}, {"price": "0.27", "size": "200"}, {"price": "0.34", "size": "100"}, {"price": "0.42", "size": "2833.71"}, {"price": "0.523", "size": "136"}, {"price": "0.619", "size": "3845"}, {"price": "0.62", "size": "644"}, {"price": "0.9", "size": "63"}, {"price": "0.923", "size": "20"}, {"price": "0.935", "size": "555"}, {"price": "0.94", "size": "641"}, {"price": "0.943", "size": "30"}, {"price": "0.944", "size": "20"}, {"price": "0.945", "size": "20"}, {"price": "0.965", "size": "60.76"}, {"price": "0.996", "size": "253.77"}, {"price": "0.997", "size": "15.17"}, {"price": "0.998", "size": "2954.11"}, {"price": "0.999", "size": "10607.64"}], "asks": [], "event_type": "book", "last_trade_price": ""}, {"market": "0x19bcc01e456986aca8b3997c493970643e151a9d575ed18b809e7a5c67f113ce", "asset_id": "21674752237383605176783726837446532993113843275797631471973922465490315447086", "timestamp": "1769384410858", "hash": "689836a40b55cbfff8f19db25cbd46ffefb888f9", "bids": [], "asks": [{"price": "0.999", "size": "2020"}, {"price": "0.998", "size": "250"}, {"price": "0.997", "size": "406.62"}, {"price": "0.996", "size": "3001200"}, {"price": "0.995", "size": "500000"}, {"price": "0.994", "size": "200"}, {"price": "0.993", "size": "9.76"}, {"price": "0.99", "size": "6869.32"}, {"price": "0.98", "size": "3895"}, {"price": "0.979", "size": "8.81"}, {"price": "0.96", "size": "3600"}, {"price": "0.95", "size": "10"}, {"price": "0.94", "size": "975"}, {"price": "0.939", "size": "8.89"}, {"price": "0.901", "size": "80000"}, {"price": "0.9", "size": "201500"}, {"price": "0.899", "size": "250"}, {"price": "0.86", "size": "50"}, {"price": "0.85", "size": "900"}, {"price": "0.8", "size": "200"}, {"price": "0.799", "size": "5.84"}, {"price": "0.777", "size": "143"}, {"price": "0.768", "size": "538.03"}, {"price": "0.767", "size": "8"}, {"price": "0.73", "size": "200"}, {"price": "0.66", "size": "100"}, {"price": "0.477", "size": "432"}, {"price": "0.472", "size": "1076.06"}, {"price": "0.277", "size": "280"}, {"price": "0.248", "size": "803.64"}, {"price": "0.247", "size": "3179"}, {"price": "0.242", "size": "20"}, {"price": "0.241", "size": "20"}, {"price": "0.24", "size": "30"}, {"price": "0.177", "size": "158"}, {"price": "0.139", "size": "803.64"}, {"price": "0.1", "size": "45"}, {"price": "0.099", "size": "4092.58"}, {"price": "0.077", "size": "1282"}, {"price": "0.076", "size": "958.58"}, {"price": "0.075", "size": "777"}, {"price": "0.069", "size": "500.35"}, {"price": "0.048", "size": "2803.16"}, {"price": "0.047", "size": "20"}, {"price": "0.035", "size": "2510.22"}, {"price": "0.033", "size": "1305.36"}, {"price": "0.029", "size": "3583.2"}, {"price": "0.028", "size": "377.4"}, {"price": "0.025", "size": "1713.86"}, {"price": "0.022", "size": "3203.54"}, {"price": "0.021", "size": "901.63"}, {"price": "0.019", "size": "2438.96"}, {"price": "0.018", "size": "2468.9"}, {"price": "0.016", "size": "2227.43"}, {"price": "0.012", "size": "6919.91"}, {"price": "0.011", "size": "3193.16"}, {"price": "0.01", "size": "5322"}, {"price": "0.007", "size": "3171.68"}, {"price": "0.006", "size": "2393.26"}, {"price": "0.005", "size": "1841.32"}, {"price": "0.003", "size": "2717.92"}, {"price": "0.002", "size": "2531.15"}, {"price": "0.001", "size": "9170.77"}], "event_type": "book", "last_trade_price": ""}, {"market": "0x3f66a8da2209397d024c9b4748e4d9477f79e640f0e74384d1be1139c86e0297", "asset_id": "109261013108194241662895111134512910749567991941703212408386673929274785073992", "timestamp": "1769384393453", "hash": "bafe78ee94e4d228bda0bfcac3b95ff5fb2ec871", "bids": [], "asks": [{"price": "0.999", "size": "3102859"}, {"price": "0.998", "size": "5001450"}, {"price": "0.997", "size": "2000406.63"}, {"price": "0.994", "size": "200"}, {"price": "0.993", "size": "9.76"}, {"price": "0.99", "size": "6760"}, {"price": "0.98", "size": "5295"}, {"price": "0.979", "size": "12.96"}, {"price": "0.96", "size": "2200"}, {"price": "0.95", "size": "10"}, {"price": "0.94", "size": "975"}, {"price": "0.928", "size": "50000"}, {"price": "0.927", "size": "90200"}, {"price": "0.926", "size": "250"}, {"price": "0.92", "size": "100"}, {"price": "0.919", "size": "5.62"}, {"price": "0.9", "size": "900"}, {"price": "0.88", "size": "130.29"}, {"price": "0.85", "size": "1250"}, {"price": "0.849", "size": "13"}, {"price": "0.8", "size": "200"}, {"price": "0.799", "size": "5.83"}, {"price": "0.777", "size": "143"}, {"price": "0.73", "size": "200"}, {"price": "0.66", "size": "100"}, {"price": "0.477", "size": "432"}, {"price": "0.285", "size": "777"}, {"price": "0.282", "size": "3320"}, {"price": "0.281", "size": "138"}, {"price": "0.277", "size": "243"}, {"price": "0.276", "size": "30"}, {"price": "0.177", "size": "179"}, {"price": "0.1", "size": "5"}, {"price": "0.077", "size": "388"}, {"price": "0.075", "size": "20"}, {"price": "0.074", "size": "20"}, {"price": "0.06", "size": "427"}, {"price": "0.049", "size": "20"}, {"price": "0.039", "size": "1109.09"}, {"price": "0.029", "size": "684.44"}, {"price": "0.025", "size": "5000"}, {"price": "0.024", "size": "1687.85"}, {"price": "0.019", "size": "1453.27"}, {"price": "0.015", "size": "1298.92"}, {"price": "0.014", "size": "1569.06"}, {"price": "0.013", "size": "1762.94"}, {"price": "0.011", "size": "4312.31"}, {"price": "0.01", "size": "288.73"}, {"price": "0.008", "size": "4312.31"}, {"price": "0.005", "size": "600"}, {"price": "0.004", "size": "5411.09"}, {"price": "0.003", "size": "9534"}, {"price": "0.002", "size": "1445.85"}], "event_type": "book", "last_trade_price": ""}, {"market": "0x33882fdaa147a31a1231293615b6e249ee8cf790fce9d8dc14f312f7b3cc0e30", "asset_id": "37530499493117195782451233735171313136269148305511339352740697906918439679769", "timestamp": "1769384420775", "hash": "d62aa9a71d2491dc7b4b7501d6e303660e115dbe", "bids": [{"price": "0.001", "size": "77154.69"}, {"price": "0.002", "size": "3588.33"}, {"price": "0.003", "size": "27801.71"}, {"price": "0.004", "size": "10457.06"}], "asks": [{"price": "0.999", "size": "3102803.01"}, {"price": "0.998", "size": "5001450"}, {"price": "0.997", "size": "2000406.63"}, {"price": "0.996", "size": "1000000"}, {"price": "0.994", "size": "200"}, {"price": "0.993", "size": "9.77"}, {"price": "0.99", "size": "6760"}, {"price": "0.988", "size": "50900"}, {"price": "0.98", "size": "5275"}, {"price": "0.979", "size": "8.82"}, {"price": "0.96", "size": "2200"}, {"price": "0.959", "size": "250"}, {"price": "0.95", "size": "30"}, {"price": "0.949", "size": "39"}, {"price": "0.94", "size": "975"}, {"price": "0.939", "size": "8.9"}, {"price": "0.9", "size": "1500"}, {"price": "0.85", "size": "700"}, {"price": "0.849", "size": "3250"}, {"price": "0.8", "size": "200"}, {"price": "0.799", "size": "5.83"}, {"price": "0.777", "size": "142"}, {"price": "0.73", "size": "200"}, {"price": "0.607", "size": "3941"}, {"price": "0.605", "size": "6100"}, {"price": "0.575", "size": "1000"}, {"price": "0.573", "size": "2000"}, {"price": "0.572", "size": "5"}, {"price": "0.477", "size": "336"}, {"price": "0.277", "size": "249"}, {"price": "0.275", "size": "1000"}, {"price": "0.274", "size": "3275"}, {"price": "0.273", "size": "30"}, {"price": "0.272", "size": "40"}, {"price": "0.177", "size": "157"}, {"price": "0.175", "size": "1000"}, {"price": "0.125", "size": "476.81"}, {"price": "0.099", "size": "392.03"}, {"price": "0.095", "size": "1000"}, {"price": "0.088", "size": "409.42"}, {"price": "0.087", "size": "444"}, {"price": "0.086", "size": "20"}, {"price": "0.078", "size": "566.9"}, {"price": "0.069", "size": "566.91"}, {"price": "0.064", "size": "440.31"}, {"price": "0.06", "size": "100"}, {"price": "0.059", "size": "89.13"}, {"price": "0.053", "size": "1039"}, {"price": "0.052", "size": "20"}, {"price": "0.05", "size": "3000"}, {"price": "0.049", "size": "108.86"}, {"price": "0.048", "size": "200"}, {"price": "0.043", "size": "246.05"}, {"price": "0.04", "size": "300"}, {"price": "0.033", "size": "1588.18"}, {"price": "0.032", "size": "1166.85"}, {"price": "0.03", "size": "402.17"}, {"price": "0.024", "size": "314.77"}, {"price": "0.02", "size": "1208.79"}, {"price": "0.019", "size": "800"}, {"price": "0.018", "size": "4006"}, {"price": "0.015", "size": "6"}, {"price": "0.013", "size": "40.79"}, {"price": "0.012", "size": "1576.83"}, {"price": "0.011", "size": "341.24"}, {"price": "0.01", "size": "2000"}, {"price": "0.009", "size": "4406"}, {"price": "0.008", "size": "11037.54"}, {"price": "0.007", "size": "5314.5"}, {"price": "0.006", "size": "1146.79"}, {"price": "0.005", "size": "1418.87"}], "event_type": "book", "last_trade_price": "0.004"}, {"market": "0x73f7620da1d4a2ec2283ad55d72f5ff4666e8732ec04458f88dff6773d6be2c6", "asset_id": "47252200832793247423089215877857667425039333476763845614656878203768571431091", "timestamp": "1769384429940", "hash": "12a017795085a16d5a4439bbcab5e8d01f910d39", "bids": [{"price": "0.001", "size": "72402.69"}, {"price": "0.002", "size": "3565"}, {"price": "0.003", "size": "2101.34"}], "asks": [{"price": "0.999", "size": "5002808"}, {"price": "0.998", "size": "3001457.48"}, {"price": "0.997", "size": "500400"}, {"price": "0.996", "size": "900000"}, {"price": "0.995", "size": "5.93"}, {"price": "0.994", "size": "200"}, {"price": "0.99", "size": "7294.72"}, {"price": "0.989", "size": "5.29"}, {"price": "0.988", "size": "300000"}, {"price": "0.98", "size": "3875"}, {"price": "0.979", "size": "50000"}, {"price": "0.978", "size": "91400"}, {"price": "0.977", "size": "10.29"}, {"price": "0.96", "size": "2200"}, {"price": "0.95", "size": "30"}, {"price": "0.949", "size": "39"}, {"price": "0.94", "size": "975"}, {"price": "0.929", "size": "50000"}, {"price": "0.927", "size": "20000"}, {"price": "0.926", "size": "90200"}, {"price": "0.925", "size": "6.41"}, {"price": "0.91", "size": "5800"}, {"price": "0.9", "size": "855.78"}, {"price": "0.899", "size": "250"}, {"price": "0.86", "size": "50"}, {"price": "0.85", "size": "900"}, {"price": "0.8", "size": "472.84"}, {"price": "0.799", "size": "5.84"}, {"price": "0.706", "size": "4644"}, {"price": "0.7", "size": "181.89"}, {"price": "0.638", "size": "2600"}, {"price": "0.607", "size": "2000"}, {"price": "0.605", "size": "2100"}, {"price": "0.6", "size": "242.52"}, {"price": "0.599", "size": "5"}, {"price": "0.5", "size": "67.27"}, {"price": "0.4", "size": "100"}, {"price": "0.39", "size": "1886.25"}, {"price": "0.3", "size": "100"}, {"price": "0.25", "size": "94.99"}, {"price": "0.249", "size": "500"}, {"price": "0.248", "size": "3180"}, {"price": "0.24", "size": "33.21"}, {"price": "0.239", "size": "30"}, {"price": "0.23", "size": "10"}, {"price": "0.22", "size": "20.31"}, {"price": "0.21", "size": "17.73"}, {"price": "0.2", "size": "174.09"}, {"price": "0.195", "size": "41.67"}, {"price": "0.191", "size": "20"}, {"price": "0.19", "size": "20"}, {"price": "0.175", "size": "217.66"}, {"price": "0.15", "size": "68.21"}, {"price": "0.149", "size": "217.66"}, {"price": "0.138", "size": "899.16"}, {"price": "0.137", "size": "317.29"}, {"price": "0.126", "size": "722"}, {"price": "0.1", "size": "213.79"}, {"price": "0.099", "size": "785.02"}, {"price": "0.098", "size": "500"}, {"price": "0.084", "size": "1305.98"}, {"price": "0.083", "size": "20"}, {"price": "0.079", "size": "822.79"}, {"price": "0.066", "size": "1004.04"}, {"price": "0.064", "size": "1379.88"}, {"price": "0.061", "size": "612.71"}, {"price": "0.056", "size": "844.04"}, {"price": "0.052", "size": "1097.05"}, {"price": "0.05", "size": "945.65"}, {"price": "0.048", "size": "2233"}, {"price": "0.045", "size": "70.04"}, {"price": "0.042", "size": "2416.47"}, {"price": "0.04", "size": "62.76"}, {"price": "0.039", "size": "339.02"}, {"price": "0.035", "size": "712.04"}, {"price": "0.032", "size": "1050.94"}, {"price": "0.026", "size": "1926"}, {"price": "0.025", "size": "1000"}, {"price": "0.02", "size": "74.15"}, {"price": "0.019", "size": "630.32"}, {"price": "0.018", "size": "400"}, {"price": "0.015", "size": "77.83"}, {"price": "0.013", "size": "132.6"}, {"price": "0.007", "size": "200.91"}, {"price": "0.006", "size": "1020"}, {"price": "0.005", "size": "2228.18"}], "event_type": "book", "last_trade_price": "0.995"}, {"market": "0xad7b71c3cd4c95712735a04e28e44276b3fb1f117a5aaf1602a8944ccc813a0f", "asset_id": "4594564467899088477510786865304307754121480801570884531496874735386344332422", "timestamp": "1769384420775", "hash": "a49ce0c11e2b7d7e87831f162583c90b8a530efd", "bids": [{"price": "0.001", "size": "3102904"}, {"price": "0.002", "size": "2001450"}, {"price": "0.003", "size": "406.63"}, {"price": "0.006", "size": "200"}, {"price": "0.007", "size": "9.76"}, {"price": "0.01", "size": "6760"}, {"price": "0.02", "size": "4875"}, {"price": "0.021", "size": "12.35"}, {"price": "0.04", "size": "1500"}, {"price": "0.05", "size": "30"}, {"price": "0.051", "size": "39"}, {"price": "0.06", "size": "375"}, {"price": "0.069", "size": "31600"}, {"price": "0.077", "size": "7777"}, {"price": "0.078", "size": "6"}, {"price": "0.098", "size": "51000"}, {"price": "0.1", "size": "500"}, {"price": "0.101", "size": "250"}, {"price": "0.14", "size": "50"}, {"price": "0.15", "size": "900"}, {"price": "0.151", "size": "13"}, {"price": "0.2", "size": "200"}, {"price": "0.201", "size": "5.83"}, {"price": "0.223", "size": "143"}, {"price": "0.27", "size": "200"}, {"price": "0.34", "size": "100"}, {"price": "0.523", "size": "432"}, {"price": "0.723", "size": "280"}, {"price": "0.76", "size": "670"}, {"price": "0.777", "size": "3000"}, {"price": "0.778", "size": "3078"}, {"price": "0.823", "size": "158"}, {"price": "0.824", "size": "30"}, {"price": "0.825", "size": "20"}, {"price": "0.9", "size": "5"}, {"price": "0.923", "size": "388"}, {"price": "0.945", "size": "2918.81"}, {"price": "0.947", "size": "777"}, {"price": "0.948", "size": "40"}, {"price": "0.95", "size": "20"}, {"price": "0.974", "size": "1666.03"}, {"price": "0.976", "size": "2188.33"}, {"price": "0.977", "size": "2000"}, {"price": "0.988", "size": "3018.8"}, {"price": "0.989", "size": "2000"}, {"price": "0.991", "size": "2188.33"}, {"price": "0.993", "size": "3589.4"}, {"price": "0.994", "size": "2976.21"}, {"price": "0.995", "size": "10217.94"}, {"price": "0.996", "size": "9495.8"}, {"price": "0.997", "size": "1263.1"}], "asks": [{"price": "0.999", "size": "62699.35"}, {"price": "0.998", "size": "2545.66"}], "event_type": "book", "last_trade_price": "0.002"}, {"market": "0x434f5226d48f9b140a0cb8f12d066bc0bf2aabe8ac672bf2c91ec5906e86480e", "asset_id": "10551240476958456127678383810235284060911827428072452020915423608326929483609", "timestamp": "1769384429940", "hash": "06e572a5d7c69a2323562107b60373d4f4efe47f", "bids": [{"price": "0.001", "size": "60979.63"}], "asks": [{"price": "0.999", "size": "3102819"}, {"price": "0.998", "size": "5001450"}, {"price": "0.997", "size": "1000400"}, {"price": "0.996", "size": "8.66"}, {"price": "0.994", "size": "200"}, {"price": "0.99", "size": "6760"}, {"price": "0.989", "size": "6.17"}, {"price": "0.98", "size": "3875"}, {"price": "0.977", "size": "200000"}, {"price": "0.976", "size": "201400"}, {"price": "0.975", "size": "6.64"}, {"price": "0.96", "size": "1500"}, {"price": "0.95", "size": "30"}, {"price": "0.949", "size": "39"}, {"price": "0.94", "size": "1875"}, {"price": "0.939", "size": "8.9"}, {"price": "0.9", "size": "500"}, {"price": "0.89", "size": "3675"}, {"price": "0.889", "size": "10000"}, {"price": "0.85", "size": "500"}, {"price": "0.849", "size": "6250"}, {"price": "0.848", "size": "250"}, {"price": "0.8", "size": "200"}, {"price": "0.799", "size": "5.83"}, {"price": "0.69", "size": "2833.71"}, {"price": "0.689", "size": "4200"}, {"price": "0.66", "size": "100"}, {"price": "0.48", "size": "1564"}, {"price": "0.479", "size": "5"}, {"price": "0.234", "size": "5000"}, {"price": "0.233", "size": "3130"}, {"price": "0.207", "size": "2000"}, {"price": "0.203", "size": "2000"}, {"price": "0.2", "size": "500"}, {"price": "0.199", "size": "30"}, {"price": "0.185", "size": "20"}, {"price": "0.184", "size": "20"}, {"price": "0.183", "size": "20"}, {"price": "0.077", "size": "35"}, {"price": "0.07", "size": "55"}, {"price": "0.049", "size": "2433.09"}, {"price": "0.048", "size": "20"}, {"price": "0.047", "size": "200"}, {"price": "0.035", "size": "844.95"}, {"price": "0.025", "size": "3697.29"}, {"price": "0.024", "size": "1005"}, {"price": "0.022", "size": "1568.21"}, {"price": "0.018", "size": "1275.3"}, {"price": "0.015", "size": "3230.23"}, {"price": "0.011", "size": "1791.25"}, {"price": "0.01", "size": "2886.68"}, {"price": "0.009", "size": "2571.49"}, {"price": "0.008", "size": "2021.74"}, {"price": "0.007", "size": "2041.59"}, {"price": "0.006", "size": "1152.14"}, {"price": "0.005", "size": "1577.34"}, {"price": "0.004", "size": "2074.32"}, {"price": "0.003", "size": "4825.87"}, {"price": "0.002", "size": "3526.26"}], "event_type": "book", "last_trade_price": "0.001"}, {"market": "0x4018190670d804b326e5950dfba1087458d996c82b69a75832d1936f70b95de9", "asset_id": "58929016337506161720363416833742533235950903585527977383885355262628287822950", "timestamp": "1769384421988", "hash": "cf09acdd8ef281f600979a13715515d3e869ae7e", "bids": [{"price": "0.001", "size": "8209.48"}], "asks": [{"price": "0.999", "size": "2102803"}, {"price": "0.998", "size": "2000250"}, {"price": "0.997", "size": "406.62"}, {"price": "0.994", "size": "200"}, {"price": "0.993", "size": "10.45"}, {"price": "0.99", "size": "507960"}, {"price": "0.989", "size": "300000"}, {"price": "0.98", "size": "5275"}, {"price": "0.979", "size": "250"}, {"price": "0.978", "size": "8.19"}, {"price": "0.96", "size": "2200"}, {"price": "0.95", "size": "30"}, {"price": "0.949", "size": "39"}, {"price": "0.94", "size": "975"}, {"price": "0.939", "size": "8.89"}, {"price": "0.9", "size": "1200"}, {"price": "0.85", "size": "1250"}, {"price": "0.8", "size": "200"}, {"price": "0.799", "size": "5.84"}, {"price": "0.777", "size": "142"}, {"price": "0.73", "size": "200"}, {"price": "0.66", "size": "100"}, {"price": "0.55", "size": "2833.71"}, {"price": "0.477", "size": "369"}, {"price": "0.45", "size": "1555"}, {"price": "0.449", "size": "4309"}, {"price": "0.448", "size": "5"}, {"price": "0.277", "size": "242"}, {"price": "0.253", "size": "30"}, {"price": "0.252", "size": "20"}, {"price": "0.251", "size": "20"}, {"price": "0.1", "size": "5"}, {"price": "0.085", "size": "1571.37"}, {"price": "0.084", "size": "20"}, {"price": "0.05", "size": "5000"}, {"price": "0.049", "size": "10"}, {"price": "0.048", "size": "423.62"}, {"price": "0.045", "size": "543.33"}, {"price": "0.038", "size": "1571.37"}, {"price": "0.034", "size": "157.87"}, {"price": "0.033", "size": "817.67"}, {"price": "0.03", "size": "5000"}, {"price": "0.029", "size": "752.81"}, {"price": "0.027", "size": "881.37"}, {"price": "0.024", "size": "886.19"}, {"price": "0.02", "size": "2521.45"}, {"price": "0.019", "size": "2313.72"}, {"price": "0.017", "size": "2000"}, {"price": "0.015", "size": "2000"}, {"price": "0.014", "size": "3109.75"}, {"price": "0.013", "size": "2378.12"}, {"price": "0.012", "size": "2000"}, {"price": "0.007", "size": "3482.56"}, {"price": "0.006", "size": "3891.8"}, {"price": "0.005", "size": "1591.88"}, {"price": "0.004", "size": "500"}, {"price": "0.003", "size": "1745.41"}], "event_type": "book", "last_trade_price": "0.001"}, {"market": "0x3f66a8da2209397d024c9b4748e4d9477f79e640f0e74384d1be1139c86e0297", "asset_id": "54097460444768552387864439997267151054168497947975835479468673375780008192089", "timestamp": "1769384393453", "hash": "3227d8b6bae6d468577e1a55a7ce12224763300b", "bids": [{"price": "0.001", "size": "3102859"}, {"price": "0.002", "size": "5001450"}, {"price": "0.003", "size": "2000406.63"}, {"price": "0.006", "size": "200"}, {"price": "0.007", "size": "9.76"}, {"price": "0.01", "size": "6760"}, {"price": "0.02", "size": "5295"}, {"price": "0.021", "size": "12.96"}, {"price": "0.04", "size": "2200"}, {"price": "0.05", "size": "10"}, {"price": "0.06", "size": "975"}, {"price": "0.072", "size": "50000"}, {"price": "0.073", "size": "90200"}, {"price": "0.074", "size": "250"}, {"price": "0.08", "size": "100"}, {"price": "0.081", "size": "5.62"}, {"price": "0.1", "size": "900"}, {"price": "0.12", "size": "130.29"}, {"price": "0.15", "size": "1250"}, {"price": "0.151", "size": "13"}, {"price": "0.2", "size": "200"}, {"price": "0.201", "size": "5.83"}, {"price": "0.223", "size": "143"}, {"price": "0.27", "size": "200"}, {"price": "0.34", "size": "100"}, {"price": "0.523", "size": "432"}, {"price": "0.715", "size": "777"}, {"price": "0.718", "size": "3320"}, {"price": "0.719", "size": "138"}, {"price": "0.723", "size": "243"}, {"price": "0.724", "size": "30"}, {"price": "0.823", "size": "179"}, {"price": "0.9", "size": "5"}, {"price": "0.923", "size": "388"}, {"price": "0.925", "size": "20"}, {"price": "0.926", "size": "20"}, {"price": "0.94", "size": "427"}, {"price": "0.951", "size": "20"}, {"price": "0.961", "size": "1109.09"}, {"price": "0.971", "size": "684.44"}, {"price": "0.975", "size": "5000"}, {"price": "0.976", "size": "1687.85"}, {"price": "0.981", "size": "1453.27"}, {"price": "0.985", "size": "1298.92"}, {"price": "0.986", "size": "1569.06"}, {"price": "0.987", "size": "1762.94"}, {"price": "0.989", "size": "4312.31"}, {"price": "0.99", "size": "288.73"}, {"price": "0.992", "size": "4312.31"}, {"price": "0.995", "size": "600"}, {"price": "0.996", "size": "5411.09"}, {"price": "0.997", "size": "9534"}, {"price": "0.998", "size": "1445.85"}], "asks": [], "event_type": "book", "last_trade_price": ""}, {"market": "0x074bf4833158a5c77b80bdb914517263395b06a8d03fe8f1ffa8ce27f3dc7eae", "asset_id": "101833342127640601972442120820328386836304438892907405471464839024767281342006", "timestamp": "1769384429940", "hash": "78f0120fbf430539c4f70d251e4d1d14f78e0a09", "bids": [{"price": "0.001", "size": "118280.68"}], "asks": [{"price": "0.999", "size": "3102835.3"}, {"price": "0.998", "size": "2001450"}, {"price": "0.997", "size": "406.63"}, {"price": "0.994", "size": "200"}, {"price": "0.993", "size": "9.76"}, {"price": "0.99", "size": "6760"}, {"price": "0.98", "size": "4695"}, {"price": "0.979", "size": "8.81"}, {"price": "0.96", "size": "1500"}, {"price": "0.951", "size": "30000"}, {"price": "0.95", "size": "71830"}, {"price": "0.949", "size": "289"}, {"price": "0.94", "size": "375"}, {"price": "0.939", "size": "8.89"}, {"price": "0.9", "size": "1200"}, {"price": "0.858", "size": "7214"}, {"price": "0.85", "size": "500"}, {"price": "0.8", "size": "200"}, {"price": "0.799", "size": "5.83"}, {"price": "0.777", "size": "143"}, {"price": "0.73", "size": "200"}, {"price": "0.66", "size": "100"}, {"price": "0.477", "size": "432"}, {"price": "0.466", "size": "4482"}, {"price": "0.465", "size": "700"}, {"price": "0.277", "size": "280"}, {"price": "0.276", "size": "30"}, {"price": "0.177", "size": "158"}, {"price": "0.168", "size": "20"}, {"price": "0.167", "size": "20"}, {"price": "0.1", "size": "5"}, {"price": "0.087", "size": "1239.15"}, {"price": "0.086", "size": "20"}, {"price": "0.077", "size": "536"}, {"price": "0.065", "size": "602.35"}, {"price": "0.049", "size": "243.51"}, {"price": "0.039", "size": "1592.41"}, {"price": "0.038", "size": "1549.97"}, {"price": "0.029", "size": "1393.04"}, {"price": "0.024", "size": "783.69"}, {"price": "0.015", "size": "2339.46"}, {"price": "0.009", "size": "10361.23"}, {"price": "0.008", "size": "1996.7"}, {"price": "0.007", "size": "5358.06"}, {"price": "0.006", "size": "6335.48"}, {"price": "0.005", "size": "5937.92"}, {"price": "0.003", "size": "10276.48"}, {"price": "0.002", "size": "628.55"}], "event_type": "book", "last_trade_price": "0.001"}, {"market": "0xad7b71c3cd4c95712735a04e28e44276b3fb1f117a5aaf1602a8944ccc813a0f", "asset_id": "12006241990405507280592337983535539660132924687587738349269354063097180427564", "timestamp": "1769384420775", "hash": "f2761efafdabda0305e6b081732be1c11217e676", "bids": [{"price": "0.001", "size": "62699.35"}, {"price": "0.002", "size": "2545.66"}], "asks": [{"price": "0.999", "size": "3102904"}, {"price": "0.998", "size": "2001450"}, {"price": "0.997", "size": "406.63"}, {"price": "0.994", "size": "200"}, {"price": "0.993", "size": "9.76"}, {"price": "0.99", "size": "6760"}, {"price": "0.98", "size": "4875"}, {"price": "0.979", "size": "12.35"}, {"price": "0.96", "size": "1500"}, {"price": "0.95", "size": "30"}, {"price": "0.949", "size": "39"}, {"price": "0.94", "size": "375"}, {"price": "0.931", "size": "31600"}, {"price": "0.923", "size": "7777"}, {"price": "0.922", "size": "6"}, {"price": "0.902", "size": "51000"}, {"price": "0.9", "size": "500"}, {"price": "0.899", "size": "250"}, {"price": "0.86", "size": "50"}, {"price": "0.85", "size": "900"}, {"price": "0.849", "size": "13"}, {"price": "0.8", "size": "200"}, {"price": "0.799", "size": "5.83"}, {"price": "0.777", "size": "143"}, {"price": "0.73", "size": "200"}, {"price": "0.66", "size": "100"}, {"price": "0.477", "size": "432"}, {"price": "0.277", "size": "280"}, {"price": "0.24", "size": "670"}, {"price": "0.223", "size": "3000"}, {"price": "0.222", "size": "3078"}, {"price": "0.177", "size": "158"}, {"price": "0.176", "size": "30"}, {"price": "0.175", "size": "20"}, {"price": "0.1", "size": "5"}, {"price": "0.077", "size": "388"}, {"price": "0.055", "size": "2918.81"}, {"price": "0.053", "size": "777"}, {"price": "0.052", "size": "40"}, {"price": "0.05", "size": "20"}, {"price": "0.026", "size": "1666.03"}, {"price": "0.024", "size": "2188.33"}, {"price": "0.023", "size": "2000"}, {"price": "0.012", "size": "3018.8"}, {"price": "0.011", "size": "2000"}, {"price": "0.009", "size": "2188.33"}, {"price": "0.007", "size": "3589.4"}, {"price": "0.006", "size": "2976.21"}, {"price": "0.005", "size": "10217.94"}, {"price": "0.004", "size": "9495.8"}, {"price": "0.003", "size": "1263.1"}], "event_type": "book", "last_trade_price": "0.002"}, {"market": "0x434f5226d48f9b140a0cb8f12d066bc0bf2aabe8ac672bf2c91ec5906e86480e", "asset_id": "97752185707588108897656274135716080958882466579462181395491402254325392508452", "timestamp": "1769384429940", "hash": "1b6944bf394f4f89c95d8757376bb158fe6e82be", "bids": [{"price": "0.001", "size": "3102819"}, {"price": "0.002", "size": "5001450"}, {"price": "0.003", "size": "1000400"}, {"price": "0.004", "size": "8.66"}, {"price": "0.006", "size": "200"}, {"price": "0.01", "size": "6760"}, {"price": "0.011", "size": "6.17"}, {"price": "0.02", "size": "3875"}, {"price": "0.023", "size": "200000"}, {"price": "0.024", "size": "201400"}, {"price": "0.025", "size": "6.64"}, {"price": "0.04", "size": "1500"}, {"price": "0.05", "size": "30"}, {"price": "0.051", "size": "39"}, {"price": "0.06", "size": "1875"}, {"price": "0.061", "size": "8.9"}, {"price": "0.1", "size": "500"}, {"price": "0.11", "size": "3675"}, {"price": "0.111", "size": "10000"}, {"price": "0.15", "size": "500"}, {"price": "0.151", "size": "6250"}, {"price": "0.152", "size": "250"}, {"price": "0.2", "size": "200"}, {"price": "0.201", "size": "5.83"}, {"price": "0.31", "size": "2833.71"}, {"price": "0.311", "size": "4200"}, {"price": "0.34", "size": "100"}, {"price": "0.52", "size": "1564"}, {"price": "0.521", "size": "5"}, {"price": "0.766", "size": "5000"}, {"price": "0.767", "size": "3130"}, {"price": "0.793", "size": "2000"}, {"price": "0.797", "size": "2000"}, {"price": "0.8", "size": "500"}, {"price": "0.801", "size": "30"}, {"price": "0.815", "size": "20"}, {"price": "0.816", "size": "20"}, {"price": "0.817", "size": "20"}, {"price": "0.923", "size": "35"}, {"price": "0.93", "size": "55"}, {"price": "0.951", "size": "2433.09"}, {"price": "0.952", "size": "20"}, {"price": "0.953", "size": "200"}, {"price": "0.965", "size": "844.95"}, {"price": "0.975", "size": "3697.29"}, {"price": "0.976", "size": "1005"}, {"price": "0.978", "size": "1568.21"}, {"price": "0.982", "size": "1275.3"}, {"price": "0.985", "size": "3230.23"}, {"price": "0.989", "size": "1791.25"}, {"price": "0.99", "size": "2886.68"}, {"price": "0.991", "size": "2571.49"}, {"price": "0.992", "size": "2021.74"}, {"price": "0.993", "size": "2041.59"}, {"price": "0.994", "size": "1152.14"}, {"price": "0.995", "size": "1577.34"}, {"price": "0.996", "size": "2074.32"}, {"price": "0.997", "size": "4825.87"}, {"price": "0.998", "size": "3526.26"}], "asks": [{"price": "0.999", "size": "60979.63"}], "event_type": "book", "last_trade_price": "0.001"}, {"market": "0x12817d6a15f0fb839157bc5e61f8a3e5b4c1b78da852aceb490a04f70866b2d8", "asset_id": "81819134475192751850244767853940338256678046543134780375943253123997657598247", "timestamp": "1769384415667", "hash": "338cb7296ba80a5152657c052fe98202b123e5ad", "bids": [{"price": "0.001", "size": "3102607"}, {"price": "0.002", "size": "2001450"}, {"price": "0.003", "size": "406.62"}, {"price": "0.006", "size": "200"}, {"price": "0.007", "size": "9.76"}, {"price": "0.01", "size": "6960"}, {"price": "0.02", "size": "5275"}, {"price": "0.04", "size": "2200"}, {"price": "0.05", "size": "10"}, {"price": "0.06", "size": "975"}, {"price": "0.1", "size": "1200"}, {"price": "0.143", "size": "20700"}, {"price": "0.144", "size": "5050"}, {"price": "0.15", "size": "500"}, {"price": "0.151", "size": "8.94"}, {"price": "0.223", "size": "143"}, {"price": "0.26", "size": "2800"}, {"price": "0.261", "size": "10000"}, {"price": "0.262", "size": "250"}, {"price": "0.33", "size": "3033.71"}, {"price": "0.34", "size": "100"}, {"price": "0.523", "size": "135"}, {"price": "0.577", "size": "5000"}, {"price": "0.578", "size": "4146"}, {"price": "0.579", "size": "5"}, {"price": "0.723", "size": "280"}, {"price": "0.823", "size": "644"}, {"price": "0.9", "size": "5"}, {"price": "0.907", "size": "200"}, {"price": "0.923", "size": "718"}, {"price": "0.924", "size": "500"}, {"price": "0.925", "size": "108"}, {"price": "0.935", "size": "20"}, {"price": "0.936", "size": "20"}, {"price": "0.937", "size": "30"}, {"price": "0.967", "size": "500"}, {"price": "0.991", "size": "333.33"}, {"price": "0.992", "size": "500"}, {"price": "0.995", "size": "294.01"}, {"price": "0.996", "size": "500"}, {"price": "0.997", "size": "15.78"}, {"price": "0.998", "size": "2889.49"}, {"price": "0.999", "size": "41517.65"}], "asks": [], "event_type": "book", "last_trade_price": "0.001"}, {"market": "0x19bcc01e456986aca8b3997c493970643e151a9d575ed18b809e7a5c67f113ce", "asset_id": "10759399929116134478857263055055714686288459881388112754056719470109447748188", "timestamp": "1769384410858", "hash": "44b0b9171e79828cd22c0bc4463804e88c629d64", "bids": [{"price": "0.001", "size": "2020"}, {"price": "0.002", "size": "250"}, {"price": "0.003", "size": "406.62"}, {"price": "0.004", "size": "3001200"}, {"price": "0.005", "size": "500000"}, {"price": "0.006", "size": "200"}, {"price": "0.007", "size": "9.76"}, {"price": "0.01", "size": "6869.32"}, {"price": "0.02", "size": "3895"}, {"price": "0.021", "size": "8.81"}, {"price": "0.04", "size": "3600"}, {"price": "0.05", "size": "10"}, {"price": "0.06", "size": "975"}, {"price": "0.061", "size": "8.89"}, {"price": "0.099", "size": "80000"}, {"price": "0.1", "size": "201500"}, {"price": "0.101", "size": "250"}, {"price": "0.14", "size": "50"}, {"price": "0.15", "size": "900"}, {"price": "0.2", "size": "200"}, {"price": "0.201", "size": "5.84"}, {"price": "0.223", "size": "143"}, {"price": "0.232", "size": "538.03"}, {"price": "0.233", "size": "8"}, {"price": "0.27", "size": "200"}, {"price": "0.34", "size": "100"}, {"price": "0.523", "size": "432"}, {"price": "0.528", "size": "1076.06"}, {"price": "0.723", "size": "280"}, {"price": "0.752", "size": "803.64"}, {"price": "0.753", "size": "3179"}, {"price": "0.758", "size": "20"}, {"price": "0.759", "size": "20"}, {"price": "0.76", "size": "30"}, {"price": "0.823", "size": "158"}, {"price": "0.861", "size": "803.64"}, {"price": "0.9", "size": "45"}, {"price": "0.901", "size": "4092.58"}, {"price": "0.923", "size": "1282"}, {"price": "0.924", "size": "958.58"}, {"price": "0.925", "size": "777"}, {"price": "0.931", "size": "500.35"}, {"price": "0.952", "size": "2803.16"}, {"price": "0.953", "size": "20"}, {"price": "0.965", "size": "2510.22"}, {"price": "0.967", "size": "1305.36"}, {"price": "0.971", "size": "3583.2"}, {"price": "0.972", "size": "377.4"}, {"price": "0.975", "size": "1713.86"}, {"price": "0.978", "size": "3203.54"}, {"price": "0.979", "size": "901.63"}, {"price": "0.981", "size": "2438.96"}, {"price": "0.982", "size": "2468.9"}, {"price": "0.984", "size": "2227.43"}, {"price": "0.988", "size": "6919.91"}, {"price": "0.989", "size": "3193.16"}, {"price": "0.99", "size": "5322"}, {"price": "0.993", "size": "3171.68"}, {"price": "0.994", "size": "2393.26"}, {"price": "0.995", "size": "1841.32"}, {"price": "0.997", "size": "2717.92"}, {"price": "0.998", "size": "2531.15"}, {"price": "0.999", "size": "9170.77"}], "asks": [], "event_type": "book", "last_trade_price": ""}, {"market": "0x277a7364c4d2c69d1cbf073440f674efb215471e444b0f52e65a49c5d38e195c", "asset_id": "36826726069067234056175494565775503022721478093395304372916973271229509135349", "timestamp": "1769384416406", "hash": "b99baed2bdb41e9399fe2d341a0c9fbdf09ac8df", "bids": [{"price": "0.001", "size": "3100609"}, {"price": "0.002", "size": "2001200"}, {"price": "0.003", "size": "29.41"}, {"price": "0.01", "size": "6760"}, {"price": "0.02", "size": "4875"}, {"price": "0.021", "size": "8.81"}, {"price": "0.04", "size": "1500"}, {"price": "0.06", "size": "2175"}, {"price": "0.061", "size": "8.89"}, {"price": "0.1", "size": "500"}, {"price": "0.121", "size": "20900"}, {"price": "0.125", "size": "4900"}, {"price": "0.126", "size": "250"}, {"price": "0.14", "size": "50"}, {"price": "0.15", "size": "700"}, {"price": "0.2", "size": "200"}, {"price": "0.201", "size": "5.84"}, {"price": "0.223", "size": "57"}, {"price": "0.27", "size": "200"}, {"price": "0.34", "size": "100"}, {"price": "0.45", "size": "2833.71"}, {"price": "0.51", "size": "1564"}, {"price": "0.523", "size": "136"}, {"price": "0.525", "size": "5000"}, {"price": "0.723", "size": "110"}, {"price": "0.736", "size": "3229"}, {"price": "0.737", "size": "542"}, {"price": "0.9", "size": "5"}, {"price": "0.923", "size": "717"}, {"price": "0.924", "size": "108"}, {"price": "0.944", "size": "20"}, {"price": "0.945", "size": "20"}, {"price": "0.946", "size": "30"}, {"price": "0.993", "size": "1000"}, {"price": "0.994", "size": "282.29"}, {"price": "0.997", "size": "1018.2"}, {"price": "0.998", "size": "2303.18"}, {"price": "0.999", "size": "18717.64"}], "asks": [], "event_type": "book", "last_trade_price": ""}, {"market": "0x074bf4833158a5c77b80bdb914517263395b06a8d03fe8f1ffa8ce27f3dc7eae", "asset_id": "98666729447126053679630876822625630372153860455568945814377128076095114477178", "timestamp": "1769384429940", "hash": "2059cb98f0ac47dcfab4a0ca348414cce99038a7", "bids": [{"price": "0.001", "size": "3102835.3"}, {"price": "0.002", "size": "2001450"}, {"price": "0.003", "size": "406.63"}, {"price": "0.006", "size": "200"}, {"price": "0.007", "size": "9.76"}, {"price": "0.01", "size": "6760"}, {"price": "0.02", "size": "4695"}, {"price": "0.021", "size": "8.81"}, {"price": "0.04", "size": "1500"}, {"price": "0.049", "size": "30000"}, {"price": "0.05", "size": "71830"}, {"price": "0.051", "size": "289"}, {"price": "0.06", "size": "375"}, {"price": "0.061", "size": "8.89"}, {"price": "0.1", "size": "1200"}, {"price": "0.142", "size": "7214"}, {"price": "0.15", "size": "500"}, {"price": "0.2", "size": "200"}, {"price": "0.201", "size": "5.83"}, {"price": "0.223", "size": "143"}, {"price": "0.27", "size": "200"}, {"price": "0.34", "size": "100"}, {"price": "0.523", "size": "432"}, {"price": "0.534", "size": "4482"}, {"price": "0.535", "size": "700"}, {"price": "0.723", "size": "280"}, {"price": "0.724", "size": "30"}, {"price": "0.823", "size": "158"}, {"price": "0.832", "size": "20"}, {"price": "0.833", "size": "20"}, {"price": "0.9", "size": "5"}, {"price": "0.913", "size": "1239.15"}, {"price": "0.914", "size": "20"}, {"price": "0.923", "size": "536"}, {"price": "0.935", "size": "602.35"}, {"price": "0.951", "size": "243.51"}, {"price": "0.961", "size": "1592.41"}, {"price": "0.962", "size": "1549.97"}, {"price": "0.971", "size": "1393.04"}, {"price": "0.976", "size": "783.69"}, {"price": "0.985", "size": "2339.46"}, {"price": "0.991", "size": "10361.23"}, {"price": "0.992", "size": "1996.7"}, {"price": "0.993", "size": "5358.06"}, {"price": "0.994", "size": "6335.48"}, {"price": "0.995", "size": "5937.92"}, {"price": "0.997", "size": "10276.48"}, {"price": "0.998", "size": "628.55"}], "asks": [{"price": "0.999", "size": "118280.68"}], "event_type": "book", "last_trade_price": "0.001"}, {"market": "0xb207031da5ef9cbded418e6b5b3c5eee24a3a7b22c6ec10053cbaaa67d793796", "asset_id": "101506943049053276934626391886226570064171431948041761918666910024462041911155", "timestamp": "1769384426880", "hash": "6d28df4db8aaf11caf927f74ec50d56707335358", "bids": [{"price": "0.001", "size": "502934.82"}, {"price": "0.002", "size": "257.52"}, {"price": "0.003", "size": "400"}, {"price": "0.004", "size": "1001200"}, {"price": "0.005", "size": "5.96"}, {"price": "0.006", "size": "200"}, {"price": "0.01", "size": "6760"}, {"price": "0.011", "size": "5.32"}, {"price": "0.013", "size": "200000"}, {"price": "0.014", "size": "300000"}, {"price": "0.02", "size": "3875"}, {"price": "0.021", "size": "50000"}, {"price": "0.022", "size": "90800"}, {"price": "0.023", "size": "7.66"}, {"price": "0.04", "size": "1500"}, {"price": "0.041", "size": "60000"}, {"price": "0.042", "size": "91200"}, {"price": "0.05", "size": "50630"}, {"price": "0.051", "size": "39"}, {"price": "0.06", "size": "375"}, {"price": "0.061", "size": "8.98"}, {"price": "0.1", "size": "1500"}, {"price": "0.15", "size": "700"}, {"price": "0.151", "size": "12250"}, {"price": "0.152", "size": "250"}, {"price": "0.2", "size": "200"}, {"price": "0.201", "size": "796"}, {"price": "0.202", "size": "5.78"}, {"price": "0.28", "size": "4311"}, {"price": "0.282", "size": "3000"}, {"price": "0.283", "size": "1484"}, {"price": "0.36", "size": "1600"}, {"price": "0.368", "size": "3790.97"}, {"price": "0.437", "size": "1372"}, {"price": "0.438", "size": "3717"}, {"price": "0.5", "size": "20"}, {"price": "0.7", "size": "5"}, {"price": "0.73", "size": "166.51"}, {"price": "0.731", "size": "30"}, {"price": "0.76", "size": "999.99"}, {"price": "0.762", "size": "4266.86"}, {"price": "0.8", "size": "36.84"}, {"price": "0.801", "size": "20"}, {"price": "0.802", "size": "20"}, {"price": "0.85", "size": "394.56"}, {"price": "0.86", "size": "174.56"}, {"price": "0.861", "size": "20"}, {"price": "0.885", "size": "125"}, {"price": "0.886", "size": "20"}, {"price": "0.9", "size": "9159"}, {"price": "0.901", "size": "2099.99"}, {"price": "0.903", "size": "745.46"}, {"price": "0.904", "size": "198.74"}, {"price": "0.905", "size": "220"}, {"price": "0.911", "size": "20"}, {"price": "0.912", "size": "116.88"}, {"price": "0.913", "size": "30"}, {"price": "0.921", "size": "28.18"}, {"price": "0.928", "size": "47.66"}, {"price": "0.931", "size": "183"}, {"price": "0.933", "size": "190.07"}, {"price": "0.935", "size": "6.73"}, {"price": "0.936", "size": "7.15"}], "asks": [{"price": "0.999", "size": "71256.96"}, {"price": "0.998", "size": "20812"}, {"price": "0.997", "size": "5.03"}, {"price": "0.99", "size": "610"}, {"price": "0.989", "size": "6.89"}, {"price": "0.98", "size": "10000"}, {"price": "0.979", "size": "3000"}, {"price": "0.978", "size": "250"}, {"price": "0.95", "size": "893"}, {"price": "0.949", "size": "13203.91"}, {"price": "0.948", "size": "54"}, {"price": "0.945", "size": "136.02"}, {"price": "0.944", "size": "39.49"}, {"price": "0.943", "size": "44"}, {"price": "0.937", "size": "12.22"}], "event_type": "book", "last_trade_price": "0.937"}, {"market": "0xc24a7efb9a05be7e3579112dcc54492dc3af966602088aa93c7f233a190f79d5", "asset_id": "34119601935291220616728117106690337057964105103638371147174952394298971933530", "timestamp": "1769384403046", "hash": "e0e2c447156e335f44598a382b379f6925723cae", "bids": [{"price": "0.001", "size": "42610.31"}, {"price": "0.002", "size": "12021.08"}, {"price": "0.003", "size": "8503.18"}, {"price": "0.005", "size": "350"}, {"price": "0.01", "size": "100"}, {"price": "0.011", "size": "720"}, {"price": "0.015", "size": "909.09"}, {"price": "0.016", "size": "1045.96"}, {"price": "0.017", "size": "1284.96"}, {"price": "0.018", "size": "909.09"}, {"price": "0.019", "size": "227.95"}], "asks": [{"price": "0.999", "size": "3103093.79"}, {"price": "0.998", "size": "3001455"}, {"price": "0.997", "size": "1000400"}, {"price": "0.996", "size": "1000007.44"}, {"price": "0.994", "size": "200"}, {"price": "0.991", "size": "18000"}, {"price": "0.99", "size": "96765.36"}, {"price": "0.984", "size": "50000"}, {"price": "0.98", "size": "3875"}, {"price": "0.979", "size": "8.83"}, {"price": "0.97", "size": "298"}, {"price": "0.96", "size": "3600"}, {"price": "0.95", "size": "323"}, {"price": "0.949", "size": "39"}, {"price": "0.94", "size": "975"}, {"price": "0.939", "size": "8.91"}, {"price": "0.9", "size": "1200"}, {"price": "0.899", "size": "250"}, {"price": "0.85", "size": "1250"}, {"price": "0.8", "size": "200"}, {"price": "0.799", "size": "5.83"}, {"price": "0.73", "size": "200"}, {"price": "0.579", "size": "395"}, {"price": "0.577", "size": "1574"}, {"price": "0.403", "size": "777"}, {"price": "0.402", "size": "3182"}, {"price": "0.392", "size": "149"}, {"price": "0.361", "size": "391"}, {"price": "0.36", "size": "624"}, {"price": "0.359", "size": "5"}, {"price": "0.105", "size": "200"}, {"price": "0.104", "size": "20"}, {"price": "0.079", "size": "444"}, {"price": "0.076", "size": "400"}, {"price": "0.075", "size": "30"}, {"price": "0.072", "size": "20"}, {"price": "0.071", "size": "20"}, {"price": "0.055", "size": "200"}, {"price": "0.045", "size": "435.5"}, {"price": "0.044", "size": "100"}, {"price": "0.043", "size": "400"}, {"price": "0.033", "size": "300"}, {"price": "0.028", "size": "30"}, {"price": "0.027", "size": "53.44"}, {"price": "0.025", "size": "46.14"}, {"price": "0.024", "size": "83.55"}, {"price": "0.022", "size": "44.42"}, {"price": "0.021", "size": "35.49"}, {"price": "0.02", "size": "73.38"}], "event_type": "book", "last_trade_price": "0.020"}, {"market": "0x1c9539feef274e52bfd0f3fcccfc8bcf8d99360b736d88b86a8e416216d46cbf", "asset_id": "27969399532345239513597418907099096530761028415307848414064076448689159111425", "timestamp": "1769384427120", "hash": "6c5dc5d5bbf244709e842f0ddeabcf97d3ebaf7e", "bids": [{"price": "0.001", "size": "3102312.99"}, {"price": "0.002", "size": "3001450"}, {"price": "0.003", "size": "172.62"}, {"price": "0.006", "size": "83"}, {"price": "0.007", "size": "9.76"}, {"price": "0.01", "size": "6760"}, {"price": "0.02", "size": "4695"}, {"price": "0.021", "size": "8.81"}, {"price": "0.04", "size": "1500"}, {"price": "0.044", "size": "50000"}, {"price": "0.045", "size": "101200"}, {"price": "0.046", "size": "250"}, {"price": "0.05", "size": "10"}, {"price": "0.06", "size": "975"}, {"price": "0.061", "size": "6"}, {"price": "0.1", "size": "2166.66"}, {"price": "0.14", "size": "50"}, {"price": "0.15", "size": "900"}, {"price": "0.151", "size": "8.94"}, {"price": "0.223", "size": "142"}, {"price": "0.24", "size": "6600"}, {"price": "0.27", "size": "200"}, {"price": "0.34", "size": "100"}, {"price": "0.45", "size": "2833.71"}, {"price": "0.462", "size": "20000"}, {"price": "0.523", "size": "136"}, {"price": "0.723", "size": "279"}, {"price": "0.781", "size": "10000"}, {"price": "0.782", "size": "3052"}, {"price": "0.823", "size": "158"}, {"price": "0.825", "size": "6000"}, {"price": "0.826", "size": "484"}, {"price": "0.9", "size": "5"}, {"price": "0.923", "size": "500"}, {"price": "0.924", "size": "108"}, {"price": "0.929", "size": "20"}, {"price": "0.93", "size": "20"}, {"price": "0.931", "size": "30"}, {"price": "0.951", "size": "20"}, {"price": "0.957", "size": "500"}, {"price": "0.992", "size": "666.66"}, {"price": "0.993", "size": "137.73"}, {"price": "0.995", "size": "1082.53"}, {"price": "0.996", "size": "2000"}, {"price": "0.998", "size": "1271.56"}], "asks": [], "event_type": "book", "last_trade_price": ""}, {"market": "0x4018190670d804b326e5950dfba1087458d996c82b69a75832d1936f70b95de9", "asset_id": "38148294033630859133044614979854322111918497048405340500315132686438467706915", "timestamp": "1769384421988", "hash": "c3ccd540eaef11783154be8aba7a58ffba567389", "bids": [{"price": "0.001", "size": "2102803"}, {"price": "0.002", "size": "2000250"}, {"price": "0.003", "size": "406.62"}, {"price": "0.006", "size": "200"}, {"price": "0.007", "size": "10.45"}, {"price": "0.01", "size": "507960"}, {"price": "0.011", "size": "300000"}, {"price": "0.02", "size": "5275"}, {"price": "0.021", "size": "250"}, {"price": "0.022", "size": "8.19"}, {"price": "0.04", "size": "2200"}, {"price": "0.05", "size": "30"}, {"price": "0.051", "size": "39"}, {"price": "0.06", "size": "975"}, {"price": "0.061", "size": "8.89"}, {"price": "0.1", "size": "1200"}, {"price": "0.15", "size": "1250"}, {"price": "0.2", "size": "200"}, {"price": "0.201", "size": "5.84"}, {"price": "0.223", "size": "142"}, {"price": "0.27", "size": "200"}, {"price": "0.34", "size": "100"}, {"price": "0.45", "size": "2833.71"}, {"price": "0.523", "size": "369"}, {"price": "0.55", "size": "1555"}, {"price": "0.551", "size": "4309"}, {"price": "0.552", "size": "5"}, {"price": "0.723", "size": "242"}, {"price": "0.747", "size": "30"}, {"price": "0.748", "size": "20"}, {"price": "0.749", "size": "20"}, {"price": "0.9", "size": "5"}, {"price": "0.915", "size": "1571.37"}, {"price": "0.916", "size": "20"}, {"price": "0.95", "size": "5000"}, {"price": "0.951", "size": "10"}, {"price": "0.952", "size": "423.62"}, {"price": "0.955", "size": "543.33"}, {"price": "0.962", "size": "1571.37"}, {"price": "0.966", "size": "157.87"}, {"price": "0.967", "size": "817.67"}, {"price": "0.97", "size": "5000"}, {"price": "0.971", "size": "752.81"}, {"price": "0.973", "size": "881.37"}, {"price": "0.976", "size": "886.19"}, {"price": "0.98", "size": "2521.45"}, {"price": "0.981", "size": "2313.72"}, {"price": "0.983", "size": "2000"}, {"price": "0.985", "size": "2000"}, {"price": "0.986", "size": "3109.75"}, {"price": "0.987", "size": "2378.12"}, {"price": "0.988", "size": "2000"}, {"price": "0.993", "size": "3482.56"}, {"price": "0.994", "size": "3891.8"}, {"price": "0.995", "size": "1591.88"}, {"price": "0.996", "size": "500"}, {"price": "0.997", "size": "1745.41"}], "asks": [{"price": "0.999", "size": "8209.48"}], "event_type": "book", "last_trade_price": "0.001"}, {"market": "0xb207031da5ef9cbded418e6b5b3c5eee24a3a7b22c6ec10053cbaaa67d793796", "asset_id": "89110596788673536475065853727140488937259064164063660201050220270400840228269", "timestamp": "1769384426880", "hash": "0913ef8d777305bc16ecb3bce07a32232ef3779c", "bids": [{"price": "0.001", "size": "71256.96"}, {"price": "0.002", "size": "20812"}, {"price": "0.003", "size": "5.03"}, {"price": "0.01", "size": "610"}, {"price": "0.011", "size": "6.89"}, {"price": "0.02", "size": "10000"}, {"price": "0.021", "size": "3000"}, {"price": "0.022", "size": "250"}, {"price": "0.05", "size": "893"}, {"price": "0.051", "size": "13203.91"}, {"price": "0.052", "size": "54"}, {"price": "0.055", "size": "136.02"}, {"price": "0.056", "size": "39.49"}, {"price": "0.057", "size": "44"}, {"price": "0.063", "size": "12.22"}], "asks": [{"price": "0.999", "size": "502934.82"}, {"price": "0.998", "size": "257.52"}, {"price": "0.997", "size": "400"}, {"price": "0.996", "size": "1001200"}, {"price": "0.995", "size": "5.96"}, {"price": "0.994", "size": "200"}, {"price": "0.99", "size": "6760"}, {"price": "0.989", "size": "5.32"}, {"price": "0.987", "size": "200000"}, {"price": "0.986", "size": "300000"}, {"price": "0.98", "size": "3875"}, {"price": "0.979", "size": "50000"}, {"price": "0.978", "size": "90800"}, {"price": "0.977", "size": "7.66"}, {"price": "0.96", "size": "1500"}, {"price": "0.959", "size": "60000"}, {"price": "0.958", "size": "91200"}, {"price": "0.95", "size": "50630"}, {"price": "0.949", "size": "39"}, {"price": "0.94", "size": "375"}, {"price": "0.939", "size": "8.98"}, {"price": "0.9", "size": "1500"}, {"price": "0.85", "size": "700"}, {"price": "0.849", "size": "12250"}, {"price": "0.848", "size": "250"}, {"price": "0.8", "size": "200"}, {"price": "0.799", "size": "796"}, {"price": "0.798", "size": "5.78"}, {"price": "0.72", "size": "4311"}, {"price": "0.718", "size": "3000"}, {"price": "0.717", "size": "1484"}, {"price": "0.64", "size": "1600"}, {"price": "0.632", "size": "3790.97"}, {"price": "0.563", "size": "1372"}, {"price": "0.562", "size": "3717"}, {"price": "0.5", "size": "20"}, {"price": "0.3", "size": "5"}, {"price": "0.27", "size": "166.51"}, {"price": "0.269", "size": "30"}, {"price": "0.24", "size": "999.99"}, {"price": "0.238", "size": "4266.86"}, {"price": "0.2", "size": "36.84"}, {"price": "0.199", "size": "20"}, {"price": "0.198", "size": "20"}, {"price": "0.15", "size": "394.56"}, {"price": "0.14", "size": "174.56"}, {"price": "0.139", "size": "20"}, {"price": "0.115", "size": "125"}, {"price": "0.114", "size": "20"}, {"price": "0.1", "size": "9159"}, {"price": "0.099", "size": "2099.99"}, {"price": "0.097", "size": "745.46"}, {"price": "0.096", "size": "198.74"}, {"price": "0.095", "size": "220"}, {"price": "0.089", "size": "20"}, {"price": "0.088", "size": "116.88"}, {"price": "0.087", "size": "30"}, {"price": "0.079", "size": "28.18"}, {"price": "0.072", "size": "47.66"}, {"price": "0.069", "size": "183"}, {"price": "0.067", "size": "190.07"}, {"price": "0.065", "size": "6.73"}, {"price": "0.064", "size": "7.15"}], "event_type": "book", "last_trade_price": "0.937"}, {"market": "0xf2fb4784ceb4d41ce23703da426700f710320ec5b711b6e3784bdaac24d94c23", "asset_id": "73768610008619570600930429495180540710817177537162503586781057110775077618432", "timestamp": "1769384429915", "hash": "73ef16b36202a6aada23be44f54b5def3b76b5d4", "bids": [{"price": "0.001", "size": "88188.99"}, {"price": "0.002", "size": "666"}, {"price": "0.01", "size": "7230"}, {"price": "0.011", "size": "8.26"}, {"price": "0.018", "size": "800"}, {"price": "0.019", "size": "3200"}, {"price": "0.02", "size": "1800"}, {"price": "0.033", "size": "400"}, {"price": "0.034", "size": "852.96"}, {"price": "0.035", "size": "1000"}, {"price": "0.036", "size": "1252.5"}, {"price": "0.037", "size": "250"}, {"price": "0.046", "size": "21"}, {"price": "0.047", "size": "76.41"}, {"price": "0.048", "size": "100"}, {"price": "0.05", "size": "73.24"}, {"price": "0.052", "size": "172"}, {"price": "0.053", "size": "16"}, {"price": "0.055", "size": "64.06"}, {"price": "0.06", "size": "16"}, {"price": "0.069", "size": "119.99"}, {"price": "0.07", "size": "5"}, {"price": "0.076", "size": "30"}, {"price": "0.085", "size": "13.65"}, {"price": "0.088", "size": "16.59"}, {"price": "0.093", "size": "64.67"}, {"price": "0.095", "size": "66.32"}, {"price": "0.097", "size": "28"}, {"price": "0.098", "size": "411"}, {"price": "0.105", "size": "18.73"}, {"price": "0.111", "size": "42.16"}, {"price": "0.118", "size": "450"}, {"price": "0.12", "size": "200.01"}, {"price": "0.121", "size": "183.75"}, {"price": "0.123", "size": "125"}], "asks": [{"price": "0.999", "size": "2155.13"}, {"price": "0.998", "size": "250"}, {"price": "0.997", "size": "29.82"}, {"price": "0.99", "size": "1007960"}, {"price": "0.98", "size": "3875"}, {"price": "0.979", "size": "8.92"}, {"price": "0.97", "size": "100000"}, {"price": "0.96", "size": "103600"}, {"price": "0.959", "size": "250"}, {"price": "0.95", "size": "30"}, {"price": "0.949", "size": "39"}, {"price": "0.94", "size": "1175"}, {"price": "0.939", "size": "8.95"}, {"price": "0.9", "size": "500"}, {"price": "0.87", "size": "6000"}, {"price": "0.86", "size": "50"}, {"price": "0.85", "size": "700"}, {"price": "0.799", "size": "796"}, {"price": "0.798", "size": "5.77"}, {"price": "0.778", "size": "2090"}, {"price": "0.77", "size": "6"}, {"price": "0.73", "size": "200"}, {"price": "0.66", "size": "3600"}, {"price": "0.65", "size": "2500"}, {"price": "0.64", "size": "2000"}, {"price": "0.633", "size": "594"}, {"price": "0.623", "size": "773"}, {"price": "0.573", "size": "45"}, {"price": "0.553", "size": "829"}, {"price": "0.552", "size": "3097"}, {"price": "0.533", "size": "22"}, {"price": "0.5", "size": "20"}, {"price": "0.413", "size": "10"}, {"price": "0.401", "size": "1800"}, {"price": "0.391", "size": "802"}, {"price": "0.381", "size": "720"}, {"price": "0.38", "size": "326.14"}, {"price": "0.371", "size": "117"}, {"price": "0.361", "size": "301"}, {"price": "0.35", "size": "284"}, {"price": "0.34", "size": "251"}, {"price": "0.33", "size": "234"}, {"price": "0.319", "size": "351"}, {"price": "0.309", "size": "174"}, {"price": "0.299", "size": "87"}, {"price": "0.288", "size": "920"}, {"price": "0.278", "size": "1026"}, {"price": "0.268", "size": "107"}, {"price": "0.25", "size": "10000"}, {"price": "0.249", "size": "700"}, {"price": "0.248", "size": "30"}, {"price": "0.205", "size": "247"}, {"price": "0.204", "size": "20"}, {"price": "0.2", "size": "5"}, {"price": "0.19", "size": "860.95"}, {"price": "0.184", "size": "358"}, {"price": "0.18", "size": "912.35"}, {"price": "0.179", "size": "200"}, {"price": "0.176", "size": "20"}, {"price": "0.175", "size": "20"}, {"price": "0.159", "size": "1000"}, {"price": "0.157", "size": "36"}, {"price": "0.149", "size": "1598"}, {"price": "0.142", "size": "25"}, {"price": "0.141", "size": "200"}, {"price": "0.136", "size": "60"}, {"price": "0.135", "size": "50"}], "event_type": "book", "last_trade_price": "0.124"}, {"market": "0x8a1b1234126ead9d4a1ac3f8e776c4f11103492fbde6ed962dcf93b9290a4661", "asset_id": "32488483420540914681648834589082676490375370987663356617041618702457653421046", "timestamp": "1769384429940", "hash": "669fd5b61e5f329964aa9e7b6408df1a5dd56ccf", "bids": [{"price": "0.001", "size": "18363.49"}], "asks": [{"price": "0.999", "size": "3102813.01"}, {"price": "0.998", "size": "5001450"}, {"price": "0.997", "size": "406.63"}, {"price": "0.994", "size": "200"}, {"price": "0.993", "size": "10.46"}, {"price": "0.99", "size": "6760"}, {"price": "0.98", "size": "3875"}, {"price": "0.979", "size": "5000"}, {"price": "0.978", "size": "8.2"}, {"price": "0.963", "size": "15000"}, {"price": "0.962", "size": "52100"}, {"price": "0.96", "size": "1500"}, {"price": "0.959", "size": "250"}, {"price": "0.95", "size": "30"}, {"price": "0.949", "size": "39"}, {"price": "0.94", "size": "975"}, {"price": "0.939", "size": "8.9"}, {"price": "0.9", "size": "1200"}, {"price": "0.85", "size": "1250"}, {"price": "0.8", "size": "200"}, {"price": "0.799", "size": "5.83"}, {"price": "0.777", "size": "57"}, {"price": "0.73", "size": "200"}, {"price": "0.66", "size": "2933.71"}, {"price": "0.477", "size": "135"}, {"price": "0.468", "size": "5000"}, {"price": "0.463", "size": "5000"}, {"price": "0.388", "size": "4000"}, {"price": "0.387", "size": "3898"}, {"price": "0.378", "size": "243"}, {"price": "0.377", "size": "5"}, {"price": "0.277", "size": "110"}, {"price": "0.177", "size": "158"}, {"price": "0.172", "size": "30"}, {"price": "0.171", "size": "40"}, {"price": "0.17", "size": "20"}, {"price": "0.077", "size": "718"}, {"price": "0.075", "size": "555"}, {"price": "0.049", "size": "10"}, {"price": "0.03", "size": "3721.56"}, {"price": "0.029", "size": "1000"}, {"price": "0.024", "size": "5"}, {"price": "0.02", "size": "260.98"}, {"price": "0.01", "size": "300"}, {"price": "0.007", "size": "500"}, {"price": "0.006", "size": "1095.5"}, {"price": "0.004", "size": "887.32"}, {"price": "0.003", "size": "3717"}, {"price": "0.002", "size": "1902.51"}], "event_type": "book", "last_trade_price": "0.001"}, {"market": "0xbf5c661a6d8c348adb83d13626a52799ac68e11b8497aa1bf0189d85eeb5099c", "asset_id": "113032982619525852115420277512821190062380704297670231304441009678288132478177", "timestamp": "1769384418544", "hash": "6b2eefa35131489354b7270bf6b2a291310a98c7", "bids": [{"price": "0.001", "size": "97736.78"}, {"price": "0.002", "size": "11709.2"}, {"price": "0.003", "size": "210071.66"}, {"price": "0.004", "size": "7831.14"}], "asks": [{"price": "0.999", "size": "5002815"}, {"price": "0.998", "size": "3001450"}, {"price": "0.997", "size": "1000406.63"}, {"price": "0.994", "size": "200"}, {"price": "0.993", "size": "9.76"}, {"price": "0.99", "size": "6760"}, {"price": "0.98", "size": "3875"}, {"price": "0.979", "size": "8.81"}, {"price": "0.961", "size": "14000"}, {"price": "0.96", "size": "62300"}, {"price": "0.959", "size": "501200"}, {"price": "0.958", "size": "250"}, {"price": "0.95", "size": "30"}, {"price": "0.949", "size": "39"}, {"price": "0.94", "size": "975"}, {"price": "0.939", "size": "8.89"}, {"price": "0.9", "size": "1200"}, {"price": "0.85", "size": "1250"}, {"price": "0.849", "size": "13"}, {"price": "0.8", "size": "200"}, {"price": "0.799", "size": "5.83"}, {"price": "0.777", "size": "143"}, {"price": "0.73", "size": "200"}, {"price": "0.66", "size": "100"}, {"price": "0.477", "size": "432"}, {"price": "0.277", "size": "140"}, {"price": "0.276", "size": "30"}, {"price": "0.2", "size": "1000"}, {"price": "0.199", "size": "40"}, {"price": "0.177", "size": "110"}, {"price": "0.174", "size": "559.69"}, {"price": "0.1", "size": "5"}, {"price": "0.099", "size": "263.58"}, {"price": "0.098", "size": "20"}, {"price": "0.077", "size": "388"}, {"price": "0.067", "size": "698.9"}, {"price": "0.065", "size": "525"}, {"price": "0.059", "size": "601.63"}, {"price": "0.058", "size": "20"}, {"price": "0.05", "size": "1000"}, {"price": "0.049", "size": "1917.13"}, {"price": "0.04", "size": "2000"}, {"price": "0.039", "size": "1291.23"}, {"price": "0.037", "size": "1276.22"}, {"price": "0.033", "size": "1939.68"}, {"price": "0.03", "size": "1000"}, {"price": "0.029", "size": "1456.59"}, {"price": "0.028", "size": "675.85"}, {"price": "0.025", "size": "1000"}, {"price": "0.024", "size": "1081.63"}, {"price": "0.023", "size": "1072.62"}, {"price": "0.022", "size": "2112.47"}, {"price": "0.021", "size": "2442.13"}, {"price": "0.02", "size": "2406.51"}, {"price": "0.019", "size": "6016.84"}, {"price": "0.018", "size": "1959.55"}, {"price": "0.017", "size": "1203.25"}, {"price": "0.016", "size": "1195.79"}, {"price": "0.013", "size": "4530.43"}, {"price": "0.012", "size": "3855.53"}, {"price": "0.011", "size": "3284.93"}, {"price": "0.01", "size": "2866.46"}, {"price": "0.009", "size": "2650.54"}, {"price": "0.008", "size": "1686.78"}, {"price": "0.007", "size": "1164.26"}, {"price": "0.006", "size": "3045.15"}, {"price": "0.005", "size": "997.64"}], "event_type": "book", "last_trade_price": "0.004"}, {"market": "0xa6050f84ffa7c10ffb852ddf9fbf772da0080d004f029d07f28fc587c9ae8366", "asset_id": "2147660263457192660132398739748503328733480407014661001671321286651996306795", "timestamp": "1769384429940", "hash": "0b032833eaf871a93d08c6ed8046236af9eedd89", "bids": [{"price": "0.001", "size": "478507.64"}], "asks": [{"price": "0.999", "size": "3102868"}, {"price": "0.998", "size": "5001450"}, {"price": "0.997", "size": "406.63"}, {"price": "0.994", "size": "200"}, {"price": "0.993", "size": "9.76"}, {"price": "0.99", "size": "6760"}, {"price": "0.98", "size": "4695"}, {"price": "0.979", "size": "8.81"}, {"price": "0.96", "size": "1500"}, {"price": "0.959", "size": "31200"}, {"price": "0.95", "size": "30"}, {"price": "0.949", "size": "39"}, {"price": "0.94", "size": "975"}, {"price": "0.939", "size": "8.89"}, {"price": "0.9", "size": "1200"}, {"price": "0.86", "size": "8400"}, {"price": "0.856", "size": "20750"}, {"price": "0.855", "size": "250"}, {"price": "0.85", "size": "500"}, {"price": "0.8", "size": "600"}, {"price": "0.799", "size": "5.83"}, {"price": "0.777", "size": "143"}, {"price": "0.71", "size": "2833.71"}, {"price": "0.691", "size": "3000"}, {"price": "0.681", "size": "7641"}, {"price": "0.66", "size": "100"}, {"price": "0.477", "size": "135"}, {"price": "0.277", "size": "243"}, {"price": "0.2", "size": "10000"}, {"price": "0.199", "size": "624"}, {"price": "0.177", "size": "180"}, {"price": "0.176", "size": "20"}, {"price": "0.1", "size": "5"}, {"price": "0.077", "size": "388"}, {"price": "0.07", "size": "20"}, {"price": "0.069", "size": "20"}, {"price": "0.049", "size": "5"}, {"price": "0.048", "size": "30"}, {"price": "0.013", "size": "5000"}, {"price": "0.01", "size": "7000"}, {"price": "0.009", "size": "6353.73"}, {"price": "0.008", "size": "4500"}, {"price": "0.007", "size": "2977.65"}, {"price": "0.006", "size": "7084.28"}, {"price": "0.005", "size": "379.84"}, {"price": "0.004", "size": "300"}, {"price": "0.003", "size": "1477.72"}, {"price": "0.002", "size": "1365.47"}], "event_type": "book", "last_trade_price": "0.001"}, {"market": "0x281565cae359040475640be8bc20f4efe15245fe0251805fd338fb1a3e45ffae", "asset_id": "114528627098181527180076013437205839368323282497361602702800503052375432480589", "timestamp": "1769384428779", "hash": "9d7c4174963f86a710d33dd07c9b869fb1faa989", "bids": [{"price": "0.01", "size": "1216165.75"}, {"price": "0.02", "size": "58885.48"}, {"price": "0.03", "size": "200000"}, {"price": "0.04", "size": "112618.77"}, {"price": "0.05", "size": "53006"}, {"price": "0.06", "size": "3825"}, {"price": "0.07", "size": "7.18"}, {"price": "0.1", "size": "510"}, {"price": "0.11", "size": "2240"}, {"price": "0.13", "size": "268"}, {"price": "0.14", "size": "4418.56"}, {"price": "0.15", "size": "2005"}, {"price": "0.16", "size": "11112"}, {"price": "0.17", "size": "3452"}, {"price": "0.18", "size": "289"}, {"price": "0.19", "size": "693"}, {"price": "0.2", "size": "3292.7"}, {"price": "0.21", "size": "1436"}, {"price": "0.22", "size": "1616.46"}, {"price": "0.23", "size": "2055.15"}, {"price": "0.24", "size": "337.67"}], "asks": [{"price": "0.99", "size": "122242.5"}, {"price": "0.98", "size": "31000"}, {"price": "0.96", "size": "32100"}, {"price": "0.95", "size": "2600"}, {"price": "0.94", "size": "250"}, {"price": "0.92", "size": "2000"}, {"price": "0.9", "size": "500"}, {"price": "0.88", "size": "400"}, {"price": "0.82", "size": "1138"}, {"price": "0.78", "size": "2108"}, {"price": "0.71", "size": "4069"}, {"price": "0.7", "size": "10"}, {"price": "0.61", "size": "2100"}, {"price": "0.6", "size": "10"}, {"price": "0.52", "size": "1024"}, {"price": "0.51", "size": "169"}, {"price": "0.5", "size": "626"}, {"price": "0.49", "size": "2116"}, {"price": "0.48", "size": "127"}, {"price": "0.47", "size": "757"}, {"price": "0.45", "size": "223.81"}, {"price": "0.44", "size": "46"}, {"price": "0.43", "size": "48"}, {"price": "0.42", "size": "1000"}, {"price": "0.41", "size": "1605"}, {"price": "0.4", "size": "306"}, {"price": "0.39", "size": "600"}, {"price": "0.38", "size": "6"}, {"price": "0.36", "size": "406"}, {"price": "0.35", "size": "170"}, {"price": "0.34", "size": "284.1"}, {"price": "0.33", "size": "1225"}, {"price": "0.32", "size": "13679.46"}, {"price": "0.31", "size": "2343.4"}, {"price": "0.3", "size": "780"}, {"price": "0.29", "size": "381.04"}, {"price": "0.28", "size": "917.91"}, {"price": "0.27", "size": "617.68"}, {"price": "0.26", "size": "1121.3"}], "event_type": "book", "last_trade_price": "0.240"}, {"market": "0xa6050f84ffa7c10ffb852ddf9fbf772da0080d004f029d07f28fc587c9ae8366", "asset_id": "113233159598514523082947372045085757605133191614758750839883612662140036761879", "timestamp": "1769384429940", "hash": "b20ea7776e51df665b26604041820a50b2ed68cb", "bids": [{"price": "0.001", "size": "3102868"}, {"price": "0.002", "size": "5001450"}, {"price": "0.003", "size": "406.63"}, {"price": "0.006", "size": "200"}, {"price": "0.007", "size": "9.76"}, {"price": "0.01", "size": "6760"}, {"price": "0.02", "size": "4695"}, {"price": "0.021", "size": "8.81"}, {"price": "0.04", "size": "1500"}, {"price": "0.041", "size": "31200"}, {"price": "0.05", "size": "30"}, {"price": "0.051", "size": "39"}, {"price": "0.06", "size": "975"}, {"price": "0.061", "size": "8.89"}, {"price": "0.1", "size": "1200"}, {"price": "0.14", "size": "8400"}, {"price": "0.144", "size": "20750"}, {"price": "0.145", "size": "250"}, {"price": "0.15", "size": "500"}, {"price": "0.2", "size": "600"}, {"price": "0.201", "size": "5.83"}, {"price": "0.223", "size": "143"}, {"price": "0.29", "size": "2833.71"}, {"price": "0.309", "size": "3000"}, {"price": "0.319", "size": "7641"}, {"price": "0.34", "size": "100"}, {"price": "0.523", "size": "135"}, {"price": "0.723", "size": "243"}, {"price": "0.8", "size": "10000"}, {"price": "0.801", "size": "624"}, {"price": "0.823", "size": "180"}, {"price": "0.824", "size": "20"}, {"price": "0.9", "size": "5"}, {"price": "0.923", "size": "388"}, {"price": "0.93", "size": "20"}, {"price": "0.931", "size": "20"}, {"price": "0.951", "size": "5"}, {"price": "0.952", "size": "30"}, {"price": "0.987", "size": "5000"}, {"price": "0.99", "size": "7000"}, {"price": "0.991", "size": "6353.73"}, {"price": "0.992", "size": "4500"}, {"price": "0.993", "size": "2977.65"}, {"price": "0.994", "size": "7084.28"}, {"price": "0.995", "size": "379.84"}, {"price": "0.996", "size": "300"}, {"price": "0.997", "size": "1477.72"}, {"price": "0.998", "size": "1365.47"}], "asks": [{"price": "0.999", "size": "478507.64"}], "event_type": "book", "last_trade_price": "0.001"}, {"market": "0xbf5c661a6d8c348adb83d13626a52799ac68e11b8497aa1bf0189d85eeb5099c", "asset_id": "8118085990587694807693817803326435897709013287182004022853934387792139356974", "timestamp": "1769384418544", "hash": "bd986b15638eff5a7e4195f40a2532ea67fe0045", "bids": [{"price": "0.001", "size": "5002815"}, {"price": "0.002", "size": "3001450"}, {"price": "0.003", "size": "1000406.63"}, {"price": "0.006", "size": "200"}, {"price": "0.007", "size": "9.76"}, {"price": "0.01", "size": "6760"}, {"price": "0.02", "size": "3875"}, {"price": "0.021", "size": "8.81"}, {"price": "0.039", "size": "14000"}, {"price": "0.04", "size": "62300"}, {"price": "0.041", "size": "501200"}, {"price": "0.042", "size": "250"}, {"price": "0.05", "size": "30"}, {"price": "0.051", "size": "39"}, {"price": "0.06", "size": "975"}, {"price": "0.061", "size": "8.89"}, {"price": "0.1", "size": "1200"}, {"price": "0.15", "size": "1250"}, {"price": "0.151", "size": "13"}, {"price": "0.2", "size": "200"}, {"price": "0.201", "size": "5.83"}, {"price": "0.223", "size": "143"}, {"price": "0.27", "size": "200"}, {"price": "0.34", "size": "100"}, {"price": "0.523", "size": "432"}, {"price": "0.723", "size": "140"}, {"price": "0.724", "size": "30"}, {"price": "0.8", "size": "1000"}, {"price": "0.801", "size": "40"}, {"price": "0.823", "size": "110"}, {"price": "0.826", "size": "559.69"}, {"price": "0.9", "size": "5"}, {"price": "0.901", "size": "263.58"}, {"price": "0.902", "size": "20"}, {"price": "0.923", "size": "388"}, {"price": "0.933", "size": "698.9"}, {"price": "0.935", "size": "525"}, {"price": "0.941", "size": "601.63"}, {"price": "0.942", "size": "20"}, {"price": "0.95", "size": "1000"}, {"price": "0.951", "size": "1917.13"}, {"price": "0.96", "size": "2000"}, {"price": "0.961", "size": "1291.23"}, {"price": "0.963", "size": "1276.22"}, {"price": "0.967", "size": "1939.68"}, {"price": "0.97", "size": "1000"}, {"price": "0.971", "size": "1456.59"}, {"price": "0.972", "size": "675.85"}, {"price": "0.975", "size": "1000"}, {"price": "0.976", "size": "1081.63"}, {"price": "0.977", "size": "1072.62"}, {"price": "0.978", "size": "2112.47"}, {"price": "0.979", "size": "2442.13"}, {"price": "0.98", "size": "2406.51"}, {"price": "0.981", "size": "6016.84"}, {"price": "0.982", "size": "1959.55"}, {"price": "0.983", "size": "1203.25"}, {"price": "0.984", "size": "1195.79"}, {"price": "0.987", "size": "4530.43"}, {"price": "0.988", "size": "3855.53"}, {"price": "0.989", "size": "3284.93"}, {"price": "0.99", "size": "2866.46"}, {"price": "0.991", "size": "2650.54"}, {"price": "0.992", "size": "1686.78"}, {"price": "0.993", "size": "1164.26"}, {"price": "0.994", "size": "3045.15"}, {"price": "0.995", "size": "997.64"}], "asks": [{"price": "0.999", "size": "97736.78"}, {"price": "0.998", "size": "11709.2"}, {"price": "0.997", "size": "210071.66"}, {"price": "0.996", "size": "7831.14"}], "event_type": "book", "last_trade_price": "0.004"}, {"market": "0xc24a7efb9a05be7e3579112dcc54492dc3af966602088aa93c7f233a190f79d5", "asset_id": "23637695676589567801908162966008599210388633138867275717354437429702726087534", "timestamp": "1769384403046", "hash": "1f180178a9e4ac3936499bb07ec661a0f11e3506", "bids": [{"price": "0.001", "size": "3103093.79"}, {"price": "0.002", "size": "3001455"}, {"price": "0.003", "size": "1000400"}, {"price": "0.004", "size": "1000007.44"}, {"price": "0.006", "size": "200"}, {"price": "0.009", "size": "18000"}, {"price": "0.01", "size": "96765.36"}, {"price": "0.016", "size": "50000"}, {"price": "0.02", "size": "3875"}, {"price": "0.021", "size": "8.83"}, {"price": "0.03", "size": "298"}, {"price": "0.04", "size": "3600"}, {"price": "0.05", "size": "323"}, {"price": "0.051", "size": "39"}, {"price": "0.06", "size": "975"}, {"price": "0.061", "size": "8.91"}, {"price": "0.1", "size": "1200"}, {"price": "0.101", "size": "250"}, {"price": "0.15", "size": "1250"}, {"price": "0.2", "size": "200"}, {"price": "0.201", "size": "5.83"}, {"price": "0.27", "size": "200"}, {"price": "0.421", "size": "395"}, {"price": "0.423", "size": "1574"}, {"price": "0.597", "size": "777"}, {"price": "0.598", "size": "3182"}, {"price": "0.608", "size": "149"}, {"price": "0.639", "size": "391"}, {"price": "0.64", "size": "624"}, {"price": "0.641", "size": "5"}, {"price": "0.895", "size": "200"}, {"price": "0.896", "size": "20"}, {"price": "0.921", "size": "444"}, {"price": "0.924", "size": "400"}, {"price": "0.925", "size": "30"}, {"price": "0.928", "size": "20"}, {"price": "0.929", "size": "20"}, {"price": "0.945", "size": "200"}, {"price": "0.955", "size": "435.5"}, {"price": "0.956", "size": "100"}, {"price": "0.957", "size": "400"}, {"price": "0.967", "size": "300"}, {"price": "0.972", "size": "30"}, {"price": "0.973", "size": "53.44"}, {"price": "0.975", "size": "46.14"}, {"price": "0.976", "size": "83.55"}, {"price": "0.978", "size": "44.42"}, {"price": "0.979", "size": "35.49"}, {"price": "0.98", "size": "73.38"}], "asks": [{"price": "0.999", "size": "42610.31"}, {"price": "0.998", "size": "12021.08"}, {"price": "0.997", "size": "8503.18"}, {"price": "0.995", "size": "350"}, {"price": "0.99", "size": "100"}, {"price": "0.989", "size": "720"}, {"price": "0.985", "size": "909.09"}, {"price": "0.984", "size": "1045.96"}, {"price": "0.983", "size": "1284.96"}, {"price": "0.982", "size": "909.09"}, {"price": "0.981", "size": "227.95"}], "event_type": "book", "last_trade_price": "0.020"}, {"market": "0x1c9539feef274e52bfd0f3fcccfc8bcf8d99360b736d88b86a8e416216d46cbf", "asset_id": "18899537314561698545023534510661332727248432186400997110997496784446895116927", "timestamp": "1769384427120", "hash": "661f3b9f9166702e20b1b4c4144ffb6a63d91785", "bids": [], "asks": [{"price": "0.999", "size": "3102312.99"}, {"price": "0.998", "size": "3001450"}, {"price": "0.997", "size": "172.62"}, {"price": "0.994", "size": "83"}, {"price": "0.993", "size": "9.76"}, {"price": "0.99", "size": "6760"}, {"price": "0.98", "size": "4695"}, {"price": "0.979", "size": "8.81"}, {"price": "0.96", "size": "1500"}, {"price": "0.956", "size": "50000"}, {"price": "0.955", "size": "101200"}, {"price": "0.954", "size": "250"}, {"price": "0.95", "size": "10"}, {"price": "0.94", "size": "975"}, {"price": "0.939", "size": "6"}, {"price": "0.9", "size": "2166.66"}, {"price": "0.86", "size": "50"}, {"price": "0.85", "size": "900"}, {"price": "0.849", "size": "8.94"}, {"price": "0.777", "size": "142"}, {"price": "0.76", "size": "6600"}, {"price": "0.73", "size": "200"}, {"price": "0.66", "size": "100"}, {"price": "0.55", "size": "2833.71"}, {"price": "0.538", "size": "20000"}, {"price": "0.477", "size": "136"}, {"price": "0.277", "size": "279"}, {"price": "0.219", "size": "10000"}, {"price": "0.218", "size": "3052"}, {"price": "0.177", "size": "158"}, {"price": "0.175", "size": "6000"}, {"price": "0.174", "size": "484"}, {"price": "0.1", "size": "5"}, {"price": "0.077", "size": "500"}, {"price": "0.076", "size": "108"}, {"price": "0.071", "size": "20"}, {"price": "0.07", "size": "20"}, {"price": "0.069", "size": "30"}, {"price": "0.049", "size": "20"}, {"price": "0.043", "size": "500"}, {"price": "0.008", "size": "666.66"}, {"price": "0.007", "size": "137.73"}, {"price": "0.005", "size": "1082.53"}, {"price": "0.004", "size": "2000"}, {"price": "0.002", "size": "1271.56"}], "event_type": "book", "last_trade_price": ""}, {"market": "0x8a1b1234126ead9d4a1ac3f8e776c4f11103492fbde6ed962dcf93b9290a4661", "asset_id": "72926001215817423769403263536281172811553635603354011661132170213047062409663", "timestamp": "1769384429940", "hash": "2629a7f6b632d96973c5a659ea74155cb16cd3b5", "bids": [{"price": "0.001", "size": "3102813.01"}, {"price": "0.002", "size": "5001450"}, {"price": "0.003", "size": "406.63"}, {"price": "0.006", "size": "200"}, {"price": "0.007", "size": "10.46"}, {"price": "0.01", "size": "6760"}, {"price": "0.02", "size": "3875"}, {"price": "0.021", "size": "5000"}, {"price": "0.022", "size": "8.2"}, {"price": "0.037", "size": "15000"}, {"price": "0.038", "size": "52100"}, {"price": "0.04", "size": "1500"}, {"price": "0.041", "size": "250"}, {"price": "0.05", "size": "30"}, {"price": "0.051", "size": "39"}, {"price": "0.06", "size": "975"}, {"price": "0.061", "size": "8.9"}, {"price": "0.1", "size": "1200"}, {"price": "0.15", "size": "1250"}, {"price": "0.2", "size": "200"}, {"price": "0.201", "size": "5.83"}, {"price": "0.223", "size": "57"}, {"price": "0.27", "size": "200"}, {"price": "0.34", "size": "2933.71"}, {"price": "0.523", "size": "135"}, {"price": "0.532", "size": "5000"}, {"price": "0.537", "size": "5000"}, {"price": "0.612", "size": "4000"}, {"price": "0.613", "size": "3898"}, {"price": "0.622", "size": "243"}, {"price": "0.623", "size": "5"}, {"price": "0.723", "size": "110"}, {"price": "0.823", "size": "158"}, {"price": "0.828", "size": "30"}, {"price": "0.829", "size": "40"}, {"price": "0.83", "size": "20"}, {"price": "0.923", "size": "718"}, {"price": "0.925", "size": "555"}, {"price": "0.951", "size": "10"}, {"price": "0.97", "size": "3721.56"}, {"price": "0.971", "size": "1000"}, {"price": "0.976", "size": "5"}, {"price": "0.98", "size": "260.98"}, {"price": "0.99", "size": "300"}, {"price": "0.993", "size": "500"}, {"price": "0.994", "size": "1095.5"}, {"price": "0.996", "size": "887.32"}, {"price": "0.997", "size": "3717"}, {"price": "0.998", "size": "1902.51"}], "asks": [{"price": "0.999", "size": "18363.49"}], "event_type": "book", "last_trade_price": "0.001"}, {"market": "0x5c5d898595b3445dd3809896302889cd512411fa8306de609d9d8aa34e257ba8", "asset_id": "31339843398803147748606287378592227516750208753666943060502579333204198045040", "timestamp": "1769384425843", "hash": "db523fbb342ceb6f993fa3ae571026fd6f9279f3", "bids": [{"price": "0.001", "size": "8105561.01"}, {"price": "0.002", "size": "250"}, {"price": "0.003", "size": "400"}, {"price": "0.004", "size": "8.66"}, {"price": "0.006", "size": "1000200"}, {"price": "0.007", "size": "500000"}, {"price": "0.01", "size": "6760"}, {"price": "0.011", "size": "5.3"}, {"price": "0.02", "size": "3875"}, {"price": "0.021", "size": "21400"}, {"price": "0.022", "size": "250"}, {"price": "0.023", "size": "7.63"}, {"price": "0.04", "size": "2200"}, {"price": "0.05", "size": "30"}, {"price": "0.051", "size": "39"}, {"price": "0.06", "size": "975"}, {"price": "0.061", "size": "8.9"}, {"price": "0.1", "size": "1500"}, {"price": "0.15", "size": "700"}, {"price": "0.151", "size": "6250"}, {"price": "0.2", "size": "200"}, {"price": "0.201", "size": "5.83"}, {"price": "0.223", "size": "57"}, {"price": "0.31", "size": "3061.6"}, {"price": "0.36", "size": "3600"}, {"price": "0.378", "size": "4544"}, {"price": "0.405", "size": "5000"}, {"price": "0.406", "size": "6000"}, {"price": "0.407", "size": "5855"}, {"price": "0.408", "size": "5"}, {"price": "0.523", "size": "136"}, {"price": "0.7", "size": "5"}, {"price": "0.723", "size": "119"}, {"price": "0.724", "size": "30"}, {"price": "0.8", "size": "2000"}, {"price": "0.801", "size": "20"}, {"price": "0.802", "size": "20"}, {"price": "0.823", "size": "110"}, {"price": "0.857", "size": "413.43"}, {"price": "0.871", "size": "413.7"}, {"price": "0.873", "size": "1614.74"}, {"price": "0.9", "size": "40"}, {"price": "0.901", "size": "413.42"}, {"price": "0.91", "size": "413.7"}, {"price": "0.915", "size": "17.12"}, {"price": "0.922", "size": "1063.02"}, {"price": "0.923", "size": "379"}, {"price": "0.924", "size": "5"}, {"price": "0.929", "size": "1063.02"}, {"price": "0.93", "size": "444"}, {"price": "0.942", "size": "985.81"}, {"price": "0.951", "size": "136.73"}, {"price": "0.952", "size": "20"}, {"price": "0.955", "size": "647.85"}, {"price": "0.964", "size": "1614.73"}, {"price": "0.968", "size": "3965.01"}, {"price": "0.974", "size": "8384"}, {"price": "0.976", "size": "1740.3"}, {"price": "0.98", "size": "2636.61"}, {"price": "0.981", "size": "3965"}, {"price": "0.985", "size": "3950.19"}, {"price": "0.986", "size": "2381.07"}, {"price": "0.987", "size": "4383.62"}, {"price": "0.988", "size": "4395.73"}, {"price": "0.989", "size": "2030.8"}, {"price": "0.99", "size": "4762.17"}, {"price": "0.991", "size": "2710.91"}, {"price": "0.992", "size": "2942.05"}, {"price": "0.995", "size": "200"}, {"price": "0.996", "size": "270"}, {"price": "0.997", "size": "2702.55"}, {"price": "0.998", "size": "22641.52"}, {"price": "0.999", "size": "4743.55"}], "asks": [], "event_type": "book", "last_trade_price": "0.001"}, {"market": "0x73f7620da1d4a2ec2283ad55d72f5ff4666e8732ec04458f88dff6773d6be2c6", "asset_id": "100099833370943743015005579369281544702202348703727349862861252866217580509705", "timestamp": "1769384429940", "hash": "78936456e84832820e43e7390bca331e2191e062", "bids": [{"price": "0.001", "size": "5002808"}, {"price": "0.002", "size": "3001457.48"}, {"price": "0.003", "size": "500400"}, {"price": "0.004", "size": "900000"}, {"price": "0.005", "size": "5.93"}, {"price": "0.006", "size": "200"}, {"price": "0.01", "size": "7294.72"}, {"price": "0.011", "size": "5.29"}, {"price": "0.012", "size": "300000"}, {"price": "0.02", "size": "3875"}, {"price": "0.021", "size": "50000"}, {"price": "0.022", "size": "91400"}, {"price": "0.023", "size": "10.29"}, {"price": "0.04", "size": "2200"}, {"price": "0.05", "size": "30"}, {"price": "0.051", "size": "39"}, {"price": "0.06", "size": "975"}, {"price": "0.071", "size": "50000"}, {"price": "0.073", "size": "20000"}, {"price": "0.074", "size": "90200"}, {"price": "0.075", "size": "6.41"}, {"price": "0.09", "size": "5800"}, {"price": "0.1", "size": "855.78"}, {"price": "0.101", "size": "250"}, {"price": "0.14", "size": "50"}, {"price": "0.15", "size": "900"}, {"price": "0.2", "size": "472.84"}, {"price": "0.201", "size": "5.84"}, {"price": "0.294", "size": "4644"}, {"price": "0.3", "size": "181.89"}, {"price": "0.362", "size": "2600"}, {"price": "0.393", "size": "2000"}, {"price": "0.395", "size": "2100"}, {"price": "0.4", "size": "242.52"}, {"price": "0.401", "size": "5"}, {"price": "0.5", "size": "67.27"}, {"price": "0.6", "size": "100"}, {"price": "0.61", "size": "1886.25"}, {"price": "0.7", "size": "100"}, {"price": "0.75", "size": "94.99"}, {"price": "0.751", "size": "500"}, {"price": "0.752", "size": "3180"}, {"price": "0.76", "size": "33.21"}, {"price": "0.761", "size": "30"}, {"price": "0.77", "size": "10"}, {"price": "0.78", "size": "20.31"}, {"price": "0.79", "size": "17.73"}, {"price": "0.8", "size": "174.09"}, {"price": "0.805", "size": "41.67"}, {"price": "0.809", "size": "20"}, {"price": "0.81", "size": "20"}, {"price": "0.825", "size": "217.66"}, {"price": "0.85", "size": "68.21"}, {"price": "0.851", "size": "217.66"}, {"price": "0.862", "size": "899.16"}, {"price": "0.863", "size": "317.29"}, {"price": "0.874", "size": "722"}, {"price": "0.9", "size": "213.79"}, {"price": "0.901", "size": "785.02"}, {"price": "0.902", "size": "500"}, {"price": "0.916", "size": "1305.98"}, {"price": "0.917", "size": "20"}, {"price": "0.921", "size": "822.79"}, {"price": "0.934", "size": "1004.04"}, {"price": "0.936", "size": "1379.88"}, {"price": "0.939", "size": "612.71"}, {"price": "0.944", "size": "844.04"}, {"price": "0.948", "size": "1097.05"}, {"price": "0.95", "size": "945.65"}, {"price": "0.952", "size": "2233"}, {"price": "0.955", "size": "70.04"}, {"price": "0.958", "size": "2416.47"}, {"price": "0.96", "size": "62.76"}, {"price": "0.961", "size": "339.02"}, {"price": "0.965", "size": "712.04"}, {"price": "0.968", "size": "1050.94"}, {"price": "0.974", "size": "1926"}, {"price": "0.975", "size": "1000"}, {"price": "0.98", "size": "74.15"}, {"price": "0.981", "size": "630.32"}, {"price": "0.982", "size": "400"}, {"price": "0.985", "size": "77.83"}, {"price": "0.987", "size": "132.6"}, {"price": "0.993", "size": "200.91"}, {"price": "0.994", "size": "1020"}, {"price": "0.995", "size": "2228.18"}], "asks": [{"price": "0.999", "size": "72402.69"}, {"price": "0.998", "size": "3565"}, {"price": "0.997", "size": "2101.34"}], "event_type": "book", "last_trade_price": "0.995"}, {"market": "0x277a7364c4d2c69d1cbf073440f674efb215471e444b0f52e65a49c5d38e195c", "asset_id": "43052638939805111253042708876810364217320058918650838730114107320970504078348", "timestamp": "1769384416406", "hash": "c129165f3fbcd7d2cd84c86c3a3f93234c38bff4", "bids": [], "asks": [{"price": "0.999", "size": "3100609"}, {"price": "0.998", "size": "2001200"}, {"price": "0.997", "size": "29.41"}, {"price": "0.99", "size": "6760"}, {"price": "0.98", "size": "4875"}, {"price": "0.979", "size": "8.81"}, {"price": "0.96", "size": "1500"}, {"price": "0.94", "size": "2175"}, {"price": "0.939", "size": "8.89"}, {"price": "0.9", "size": "500"}, {"price": "0.879", "size": "20900"}, {"price": "0.875", "size": "4900"}, {"price": "0.874", "size": "250"}, {"price": "0.86", "size": "50"}, {"price": "0.85", "size": "700"}, {"price": "0.8", "size": "200"}, {"price": "0.799", "size": "5.84"}, {"price": "0.777", "size": "57"}, {"price": "0.73", "size": "200"}, {"price": "0.66", "size": "100"}, {"price": "0.55", "size": "2833.71"}, {"price": "0.49", "size": "1564"}, {"price": "0.477", "size": "136"}, {"price": "0.475", "size": "5000"}, {"price": "0.277", "size": "110"}, {"price": "0.264", "size": "3229"}, {"price": "0.263", "size": "542"}, {"price": "0.1", "size": "5"}, {"price": "0.077", "size": "717"}, {"price": "0.076", "size": "108"}, {"price": "0.056", "size": "20"}, {"price": "0.055", "size": "20"}, {"price": "0.054", "size": "30"}, {"price": "0.007", "size": "1000"}, {"price": "0.006", "size": "282.29"}, {"price": "0.003", "size": "1018.2"}, {"price": "0.002", "size": "2303.18"}, {"price": "0.001", "size": "18717.64"}], "event_type": "book", "last_trade_price": ""}, {"market": "0x33882fdaa147a31a1231293615b6e249ee8cf790fce9d8dc14f312f7b3cc0e30", "asset_id": "78479552665098816655928352883908122960617168323933482475119854343373488178805", "timestamp": "1769384420775", "hash": "aefcc4f0cdb2cee1f3f851d4960a5d78e6cda81f", "bids": [{"price": "0.001", "size": "3102803.01"}, {"price": "0.002", "size": "5001450"}, {"price": "0.003", "size": "2000406.63"}, {"price": "0.004", "size": "1000000"}, {"price": "0.006", "size": "200"}, {"price": "0.007", "size": "9.77"}, {"price": "0.01", "size": "6760"}, {"price": "0.012", "size": "50900"}, {"price": "0.02", "size": "5275"}, {"price": "0.021", "size": "8.82"}, {"price": "0.04", "size": "2200"}, {"price": "0.041", "size": "250"}, {"price": "0.05", "size": "30"}, {"price": "0.051", "size": "39"}, {"price": "0.06", "size": "975"}, {"price": "0.061", "size": "8.9"}, {"price": "0.1", "size": "1500"}, {"price": "0.15", "size": "700"}, {"price": "0.151", "size": "3250"}, {"price": "0.2", "size": "200"}, {"price": "0.201", "size": "5.83"}, {"price": "0.223", "size": "142"}, {"price": "0.27", "size": "200"}, {"price": "0.393", "size": "3941"}, {"price": "0.395", "size": "6100"}, {"price": "0.425", "size": "1000"}, {"price": "0.427", "size": "2000"}, {"price": "0.428", "size": "5"}, {"price": "0.523", "size": "336"}, {"price": "0.723", "size": "249"}, {"price": "0.725", "size": "1000"}, {"price": "0.726", "size": "3275"}, {"price": "0.727", "size": "30"}, {"price": "0.728", "size": "40"}, {"price": "0.823", "size": "157"}, {"price": "0.825", "size": "1000"}, {"price": "0.875", "size": "476.81"}, {"price": "0.901", "size": "392.03"}, {"price": "0.905", "size": "1000"}, {"price": "0.912", "size": "409.42"}, {"price": "0.913", "size": "444"}, {"price": "0.914", "size": "20"}, {"price": "0.922", "size": "566.9"}, {"price": "0.931", "size": "566.91"}, {"price": "0.936", "size": "440.31"}, {"price": "0.94", "size": "100"}, {"price": "0.941", "size": "89.13"}, {"price": "0.947", "size": "1039"}, {"price": "0.948", "size": "20"}, {"price": "0.95", "size": "3000"}, {"price": "0.951", "size": "108.86"}, {"price": "0.952", "size": "200"}, {"price": "0.957", "size": "246.05"}, {"price": "0.96", "size": "300"}, {"price": "0.967", "size": "1588.18"}, {"price": "0.968", "size": "1166.85"}, {"price": "0.97", "size": "402.17"}, {"price": "0.976", "size": "314.77"}, {"price": "0.98", "size": "1208.79"}, {"price": "0.981", "size": "800"}, {"price": "0.982", "size": "4006"}, {"price": "0.985", "size": "6"}, {"price": "0.987", "size": "40.79"}, {"price": "0.988", "size": "1576.83"}, {"price": "0.989", "size": "341.24"}, {"price": "0.99", "size": "2000"}, {"price": "0.991", "size": "4406"}, {"price": "0.992", "size": "11037.54"}, {"price": "0.993", "size": "5314.5"}, {"price": "0.994", "size": "1146.79"}, {"price": "0.995", "size": "1418.87"}], "asks": [{"price": "0.999", "size": "77154.69"}, {"price": "0.998", "size": "3588.33"}, {"price": "0.997", "size": "27801.71"}, {"price": "0.996", "size": "10457.06"}], "event_type": "book", "last_trade_price": "0.004"}, {"market": "0xbe1c736f56cade44537b90c07edb9209eba1ab044fa57b6f3900b8fd26570c61", "asset_id": "59999675311137587840491907461104965146991785998223820408543351474300723555438", "timestamp": "1769384396334", "hash": "af8e087f8d2a07c0de2060c1a516917425ca334b", "bids": [{"price": "0.001", "size": "3100713"}, {"price": "0.002", "size": "3001200"}, {"price": "0.003", "size": "6.62"}, {"price": "0.006", "size": "83"}, {"price": "0.007", "size": "9.76"}, {"price": "0.01", "size": "7214.01"}, {"price": "0.02", "size": "4875"}, {"price": "0.021", "size": "9.02"}, {"price": "0.04", "size": "1500"}, {"price": "0.05", "size": "30"}, {"price": "0.055", "size": "60000"}, {"price": "0.056", "size": "71600"}, {"price": "0.06", "size": "375"}, {"price": "0.061", "size": "187"}, {"price": "0.062", "size": "8.68"}, {"price": "0.1", "size": "1200"}, {"price": "0.15", "size": "1250"}, {"price": "0.2", "size": "200"}, {"price": "0.201", "size": "5.84"}, {"price": "0.223", "size": "65"}, {"price": "0.27", "size": "200"}, {"price": "0.35", "size": "2933.71"}, {"price": "0.404", "size": "4444"}, {"price": "0.523", "size": "136"}, {"price": "0.601", "size": "500"}, {"price": "0.676", "size": "3542"}, {"price": "0.677", "size": "595"}, {"price": "0.678", "size": "147"}, {"price": "0.9", "size": "5"}, {"price": "0.925", "size": "30"}, {"price": "0.926", "size": "20"}, {"price": "0.927", "size": "20"}, {"price": "0.928", "size": "20"}, {"price": "0.983", "size": "100"}, {"price": "0.989", "size": "105"}, {"price": "0.993", "size": "444.55"}, {"price": "0.994", "size": "1200"}, {"price": "0.995", "size": "300"}, {"price": "0.997", "size": "48.63"}, {"price": "0.998", "size": "2080.49"}, {"price": "0.999", "size": "24547.64"}], "asks": [], "event_type": "book", "last_trade_price": ""}, {"market": "0x281565cae359040475640be8bc20f4efe15245fe0251805fd338fb1a3e45ffae", "asset_id": "29048360022556021389805670398008888482908398853670829781367251641936311260707", "timestamp": "1769384428779", "hash": "566b93bd88ca999eb4567e0ccf8ede27215ce6bd", "bids": [{"price": "0.01", "size": "122242.5"}, {"price": "0.02", "size": "31000"}, {"price": "0.04", "size": "32100"}, {"price": "0.05", "size": "2600"}, {"price": "0.06", "size": "250"}, {"price": "0.08", "size": "2000"}, {"price": "0.1", "size": "500"}, {"price": "0.12", "size": "400"}, {"price": "0.18", "size": "1138"}, {"price": "0.22", "size": "2108"}, {"price": "0.29", "size": "4069"}, {"price": "0.3", "size": "10"}, {"price": "0.39", "size": "2100"}, {"price": "0.4", "size": "10"}, {"price": "0.48", "size": "1024"}, {"price": "0.49", "size": "169"}, {"price": "0.5", "size": "626"}, {"price": "0.51", "size": "2116"}, {"price": "0.52", "size": "127"}, {"price": "0.53", "size": "757"}, {"price": "0.55", "size": "223.81"}, {"price": "0.56", "size": "46"}, {"price": "0.57", "size": "48"}, {"price": "0.58", "size": "1000"}, {"price": "0.59", "size": "1605"}, {"price": "0.6", "size": "306"}, {"price": "0.61", "size": "600"}, {"price": "0.62", "size": "6"}, {"price": "0.64", "size": "406"}, {"price": "0.65", "size": "170"}, {"price": "0.66", "size": "284.1"}, {"price": "0.67", "size": "1225"}, {"price": "0.68", "size": "13679.46"}, {"price": "0.69", "size": "2343.4"}, {"price": "0.7", "size": "780"}, {"price": "0.71", "size": "381.04"}, {"price": "0.72", "size": "917.91"}, {"price": "0.73", "size": "617.68"}, {"price": "0.74", "size": "1121.3"}], "asks": [{"price": "0.99", "size": "1216165.75"}, {"price": "0.98", "size": "58885.48"}, {"price": "0.97", "size": "200000"}, {"price": "0.96", "size": "112618.77"}, {"price": "0.95", "size": "53006"}, {"price": "0.94", "size": "3825"}, {"price": "0.93", "size": "7.18"}, {"price": "0.9", "size": "510"}, {"price": "0.89", "size": "2240"}, {"price": "0.87", "size": "268"}, {"price": "0.86", "size": "4418.56"}, {"price": "0.85", "size": "2005"}, {"price": "0.84", "size": "11112"}, {"price": "0.83", "size": "3452"}, {"price": "0.82", "size": "289"}, {"price": "0.81", "size": "693"}, {"price": "0.8", "size": "3292.7"}, {"price": "0.79", "size": "1436"}, {"price": "0.78", "size": "1616.46"}, {"price": "0.77", "size": "2055.15"}, {"price": "0.76", "size": "337.67"}], "event_type": "book", "last_trade_price": "0.240"}, {"market": "0xe9215ac1b5d18ecd3bdc4e91942674146385871bdd14ff0578acd126c9b5a083", "asset_id": "27317805083324305657153029216706373718348619238641707186673635855142895952316", "timestamp": "1769384403047", "hash": "02c26877df69d7c831a12fb6851b548694d4d0d2", "bids": [{"price": "0.001", "size": "81114.48"}, {"price": "0.002", "size": "12838.76"}, {"price": "0.003", "size": "250"}, {"price": "0.005", "size": "100"}, {"price": "0.01", "size": "50"}, {"price": "0.011", "size": "6069.23"}, {"price": "0.012", "size": "769.23"}, {"price": "0.013", "size": "18974.8"}], "asks": [{"price": "0.999", "size": "3102803"}, {"price": "0.998", "size": "250"}, {"price": "0.997", "size": "406.63"}, {"price": "0.995", "size": "200000"}, {"price": "0.994", "size": "1001400"}, {"price": "0.993", "size": "9.76"}, {"price": "0.99", "size": "6760"}, {"price": "0.98", "size": "5275"}, {"price": "0.979", "size": "8.81"}, {"price": "0.96", "size": "2200"}, {"price": "0.959", "size": "250"}, {"price": "0.95", "size": "30"}, {"price": "0.949", "size": "39"}, {"price": "0.94", "size": "975"}, {"price": "0.939", "size": "8.89"}, {"price": "0.9", "size": "1200"}, {"price": "0.86", "size": "5314"}, {"price": "0.85", "size": "500"}, {"price": "0.8", "size": "200"}, {"price": "0.799", "size": "5.83"}, {"price": "0.777", "size": "143"}, {"price": "0.73", "size": "200"}, {"price": "0.63", "size": "2933.71"}, {"price": "0.49", "size": "1600"}, {"price": "0.477", "size": "567"}, {"price": "0.399", "size": "20000"}, {"price": "0.398", "size": "3184"}, {"price": "0.369", "size": "700"}, {"price": "0.368", "size": "5"}, {"price": "0.277", "size": "280"}, {"price": "0.177", "size": "158"}, {"price": "0.163", "size": "20"}, {"price": "0.161", "size": "20"}, {"price": "0.159", "size": "30"}, {"price": "0.158", "size": "20"}, {"price": "0.077", "size": "387"}, {"price": "0.06", "size": "1666.21"}, {"price": "0.059", "size": "500"}, {"price": "0.057", "size": "300"}, {"price": "0.052", "size": "611.17"}, {"price": "0.051", "size": "500"}, {"price": "0.05", "size": "300"}, {"price": "0.049", "size": "400"}, {"price": "0.036", "size": "300"}, {"price": "0.033", "size": "132.6"}, {"price": "0.031", "size": "200"}, {"price": "0.027", "size": "100"}, {"price": "0.024", "size": "125"}, {"price": "0.017", "size": "244.2"}, {"price": "0.016", "size": "980"}, {"price": "0.015", "size": "278.79"}, {"price": "0.014", "size": "13.2"}], "event_type": "book", "last_trade_price": "0.013"}]}
{"_local_timestamp": "2026-01-25T23:40:30.416620+00:00", "data": {"market": "0xf2fb4784ceb4d41ce23703da426700f710320ec5b711b6e3784bdaac24d94c23", "price_changes": [{"asset_id": "88794755386871079853762415286654635832909423950620116774027006364873482091563", "price": "0.221", "size": "417", "side": "BUY", "hash": "d7ebc9630e383aa2a1f3a77585a89cc23680c7a1", "best_bid": "0.865", "best_ask": "0.877"}, {"asset_id": "73768610008619570600930429495180540710817177537162503586781057110775077618432", "price": "0.779", "size": "417", "side": "SELL", "hash": "5a255978f7e0e0189b83e17598aff1af5cf76bfb", "best_bid": "0.123", "best_ask": "0.135"}], "timestamp": "1769384430164", "event_type": "price_change"}}
{"_local_timestamp": "2026-01-25T23:40:30.422545+00:00", "data": {"market": "0xf2fb4784ceb4d41ce23703da426700f710320ec5b711b6e3784bdaac24d94c23", "price_changes": [{"asset_id": "88794755386871079853762415286654635832909423950620116774027006364873482091563", "price": "0.806", "size": "2096", "side": "BUY", "hash": "18816152bf68d831caabf5d110672f00c4620564", "best_bid": "0.865", "best_ask": "0.877"}, {"asset_id": "73768610008619570600930429495180540710817177537162503586781057110775077618432", "price": "0.194", "size": "2096", "side": "SELL", "hash": "82b4784deddb2c51af43bf420d124f162ff9fad4", "best_bid": "0.123", "best_ask": "0.135"}], "timestamp": "1769384430165", "event_type": "price_change"}}
{"_local_timestamp": "2026-01-25T23:40:30.482625+00:00", "data": {"market": "0xf2fb4784ceb4d41ce23703da426700f710320ec5b711b6e3784bdaac24d94c23", "price_changes": [{"asset_id": "88794755386871079853762415286654635832909423950620116774027006364873482091563", "price": "0.221", "size": "0", "side": "BUY", "hash": "3ced895d652ca22ad45292b5b3a69dbdc816ec38", "best_bid": "0.865", "best_ask": "0.877"}, {"asset_id": "73768610008619570600930429495180540710817177537162503586781057110775077618432", "price": "0.779", "size": "0", "side": "SELL", "hash": "603ae5e1ce0a88cb23bf0d5db094611540e2de79", "best_bid": "0.123", "best_ask": "0.135"}], "timestamp": "1769384430403", "event_type": "price_change"}}
{"_local_timestamp": "2026-01-25T23:40:30.488706+00:00", "data": {"market": "0xf2fb4784ceb4d41ce23703da426700f710320ec5b711b6e3784bdaac24d94c23", "price_changes": [{"asset_id": "88794755386871079853762415286654635832909423950620116774027006364873482091563", "price": "0.795", "size": "0", "side": "BUY", "hash": "3ced895d652ca22ad45292b5b3a69dbdc816ec38", "best_bid": "0.865", "best_ask": "0.877"}, {"asset_id": "73768610008619570600930429495180540710817177537162503586781057110775077618432", "price": "0.205", "size": "0", "side": "SELL", "hash": "603ae5e1ce0a88cb23bf0d5db094611540e2de79", "best_bid": "0.123", "best_ask": "0.135"}], "timestamp": "1769384430403", "event_type": "price_change"}}
{"_local_timestamp": "2026-01-25T23:40:30.708093+00:00", "data": {"market": "0xf2fb4784ceb4d41ce23703da426700f710320ec5b711b6e3784bdaac24d94c23", "price_changes": [{"asset_id": "88794755386871079853762415286654635832909423950620116774027006364873482091563", "price": "0.795", "size": "292", "side": "BUY", "hash": "eef358a467f95347070803e28546ea65379c9e1a", "best_bid": "0.865", "best_ask": "0.877"}, {"asset_id": "73768610008619570600930429495180540710817177537162503586781057110775077618432", "price": "0.205", "size": "292", "side": "SELL", "hash": "42f1ff25aff7f9addb63b0065b25f1cac4d9d7a9", "best_bid": "0.123", "best_ask": "0.135"}], "timestamp": "1769384430623", "event_type": "price_change"}}
{"_local_timestamp": "2026-01-25T23:40:30.720917+00:00", "data": {"market": "0xf2fb4784ceb4d41ce23703da426700f710320ec5b711b6e3784bdaac24d94c23", "price_changes": [{"asset_id": "88794755386871079853762415286654635832909423950620116774027006364873482091563", "price": "0.221", "size": "372", "side": "BUY", "hash": "cc7a5798eda71b31721d67581c49f9a17cfa486e", "best_bid": "0.865", "best_ask": "0.877"}, {"asset_id": "73768610008619570600930429495180540710817177537162503586781057110775077618432", "price": "0.779", "size": "372", "side": "SELL", "hash": "d714b446dd1c5a4586f2547dc0e82e8fd1f14f54", "best_bid": "0.123", "best_ask": "0.135"}], "timestamp": "1769384430624", "event_type": "price_change"}}
{"_local_timestamp": "2026-01-25T23:40:32.973784+00:00", "data": {"market": "0xf2fb4784ceb4d41ce23703da426700f710320ec5b711b6e3784bdaac24d94c23", "price_changes": [{"asset_id": "73768610008619570600930429495180540710817177537162503586781057110775077618432", "price": "0.12", "size": "400.01", "side": "BUY", "hash": "bbb28036ca1c880c74123d0f97068366aca889ee", "best_bid": "0.123", "best_ask": "0.135"}, {"asset_id": "88794755386871079853762415286654635832909423950620116774027006364873482091563", "price": "0.88", "size": "400.01", "side": "SELL", "hash": "21cc1754375d19e5e65544cc1389de2b82f0d707", "best_bid": "0.865", "best_ask": "0.877"}], "timestamp": "1769384432908", "event_type": "price_change"}}
{"_local_timestamp": "2026-01-25T23:40:33.735706+00:00", "data": {"market": "0xf2fb4784ceb4d41ce23703da426700f710320ec5b711b6e3784bdaac24d94c23", "price_changes": [{"asset_id": "73768610008619570600930429495180540710817177537162503586781057110775077618432", "price": "0.14", "size": "26.6", "side": "SELL", "hash": "688fe0aae9c55af311de870d65a344a761c01591", "best_bid": "0.123", "best_ask": "0.135"}, {"asset_id": "88794755386871079853762415286654635832909423950620116774027006364873482091563", "price": "0.86", "size": "26.6", "side": "BUY", "hash": "f55d0ae9d75095c82da98bbb69a51943a6dad0fb", "best_bid": "0.865", "best_ask": "0.877"}], "timestamp": "1769384433654", "event_type": "price_change"}}
{"_local_timestamp": "2026-01-25T23:40:33.743778+00:00", "data": {"market": "0xf2fb4784ceb4d41ce23703da426700f710320ec5b711b6e3784bdaac24d94c23", "price_changes": [{"asset_id": "73768610008619570600930429495180540710817177537162503586781057110775077618432", "price": "0.14", "size": "53.2", "side": "SELL", "hash": "a3b87fe0e6b68f85641930191b21cc5eadf13faa", "best_bid": "0.123", "best_ask": "0.135"}, {"asset_id": "88794755386871079853762415286654635832909423950620116774027006364873482091563", "price": "0.86", "size": "53.2", "side": "BUY", "hash": "840598528ee6124045a29730f8e6aa6276c7ff13", "best_bid": "0.865", "best_ask": "0.877"}], "timestamp": "1769384433655", "event_type": "price_change"}}
{"_local_timestamp": "2026-01-25T23:40:33.749892+00:00", "data": {"market": "0xf2fb4784ceb4d41ce23703da426700f710320ec5b711b6e3784bdaac24d94c23", "price_changes": [{"asset_id": "73768610008619570600930429495180540710817177537162503586781057110775077618432", "price": "0.14", "size": "79.8", "side": "SELL", "hash": "938776a3bebe56eadd9bde71476491f6f7217ddc", "best_bid": "0.123", "best_ask": "0.135"}, {"asset_id": "88794755386871079853762415286654635832909423950620116774027006364873482091563", "price": "0.86", "size": "79.8", "side": "BUY", "hash": "02dea7c3be4ffd333959d4309eaf7013aabfc6a0", "best_bid": "0.865", "best_ask": "0.877"}], "timestamp": "1769384433655", "event_type": "price_change"}}
{"_local_timestamp": "2026-01-25T23:40:33.755826+00:00", "data": {"market": "0xf2fb4784ceb4d41ce23703da426700f710320ec5b711b6e3784bdaac24d94c23", "price_changes": [{"asset_id": "73768610008619570600930429495180540710817177537162503586781057110775077618432", "price": "0.14", "size": "106.4", "side": "SELL", "hash": "69c2c846c79388c07af9cf3b975afd1e2b5ef8a3", "best_bid": "0.123", "best_ask": "0.135"}, {"asset_id": "88794755386871079853762415286654635832909423950620116774027006364873482091563", "price": "0.86", "size": "106.4", "side": "BUY", "hash": "741698adcf4fc546743aacd8de7170511b4ce109", "best_bid": "0.865", "best_ask": "0.877"}], "timestamp": "1769384433656", "event_type": "price_change"}}
{"_local_timestamp": "2026-01-25T23:40:36.582575+00:00", "data": {"market": "0xf2fb4784ceb4d41ce23703da426700f710320ec5b711b6e3784bdaac24d94c23", "price_changes": [{"asset_id": "88794755386871079853762415286654635832909423950620116774027006364873482091563", "price": "0.859", "size": "0", "side": "BUY", "hash": "0a723a30a765ee690288b3d8e693d023e77f3b67", "best_bid": "0.865", "best_ask": "0.877"}, {"asset_id": "73768610008619570600930429495180540710817177537162503586781057110775077618432", "price": "0.141", "size": "0", "side": "SELL", "hash": "7f079e2fb1fd1c65f3a01050cc0203f90665f787", "best_bid": "0.123", "best_ask": "0.135"}], "timestamp": "1769384436518", "event_type": "price_change"}}
{"_local_timestamp": "2026-01-25T23:40:40.534608+00:00", "data": {"market": "0xf2fb4784ceb4d41ce23703da426700f710320ec5b711b6e3784bdaac24d94c23", "price_changes": [{"asset_id": "88794755386871079853762415286654635832909423950620116774027006364873482091563", "price": "0.86", "size": "306.4", "side": "BUY", "hash": "198230c6ae9a4585990f6c819d3494b3a199dce9", "best_bid": "0.865", "best_ask": "0.877"}, {"asset_id": "73768610008619570600930429495180540710817177537162503586781057110775077618432", "price": "0.14", "size": "306.4", "side": "SELL", "hash": "066a74bb6876c26fba6f896df196851e73d3fc59", "best_bid": "0.123", "best_ask": "0.135"}], "timestamp": "1769384440376", "event_type": "price_change"}}
{"_local_timestamp": "2026-01-25T23:40:45.658077+00:00", "data": {"market": "0x281565cae359040475640be8bc20f4efe15245fe0251805fd338fb1a3e45ffae", "price_changes": [{"asset_id": "114528627098181527180076013437205839368323282497361602702800503052375432480589", "price": "0.18", "size": "20", "side": "BUY", "hash": "d995c683baa76812a45f9ff8e16dd2b408745ea3", "best_bid": "0.24", "best_ask": "0.26"}, {"asset_id": "29048360022556021389805670398008888482908398853670829781367251641936311260707", "price": "0.82", "size": "20", "side": "SELL", "hash": "951dce211d78dbf4cf6f3c8e4abcc1ab73d06de5", "best_bid": "0.74", "best_ask": "0.76"}], "timestamp": "1769384445588", "event_type": "price_change"}}
{"_local_timestamp": "2026-01-25T23:40:45.665851+00:00", "data": {"market": "0x281565cae359040475640be8bc20f4efe15245fe0251805fd338fb1a3e45ffae", "price_changes": [{"asset_id": "29048360022556021389805670398008888482908398853670829781367251641936311260707", "price": "0.52", "size": "0", "side": "BUY", "hash": "aa01940f4a8eae8b478c7fb3373676485f637675", "best_bid": "0.74", "best_ask": "0.76"}, {"asset_id": "114528627098181527180076013437205839368323282497361602702800503052375432480589", "price": "0.48", "size": "0", "side": "SELL", "hash": "a5b389355b9f8cf49dce817d7df5647bf2f48642", "best_bid": "0.24", "best_ask": "0.26"}], "timestamp": "1769384445588", "event_type": "price_change"}}
{"_local_timestamp": "2026-01-25T23:40:45.672468+00:00", "data": {"market": "0x281565cae359040475640be8bc20f4efe15245fe0251805fd338fb1a3e45ffae", "price_changes": [{"asset_id": "29048360022556021389805670398008888482908398853670829781367251641936311260707", "price": "0.65", "size": "5", "side": "BUY", "hash": "aa01940f4a8eae8b478c7fb3373676485f637675", "best_bid": "0.74", "best_ask": "0.76"}, {"asset_id": "114528627098181527180076013437205839368323282497361602702800503052375432480589", "price": "0.35", "size": "5", "side": "SELL", "hash": "a5b389355b9f8cf49dce817d7df5647bf2f48642", "best_bid": "0.24", "best_ask": "0.26"}], "timestamp": "1769384445588", "event_type": "price_change"}}
{"_local_timestamp": "2026-01-25T23:40:45.679465+00:00", "data": {"market": "0x281565cae359040475640be8bc20f4efe15245fe0251805fd338fb1a3e45ffae", "price_changes": [{"asset_id": "29048360022556021389805670398008888482908398853670829781367251641936311260707", "price": "0.6", "size": "300", "side": "BUY", "hash": "aa01940f4a8eae8b478c7fb3373676485f637675", "best_bid": "0.74", "best_ask": "0.76"}, {"asset_id": "114528627098181527180076013437205839368323282497361602702800503052375432480589", "price": "0.4", "size": "300", "side": "SELL", "hash": "a5b389355b9f8cf49dce817d7df5647bf2f48642", "best_bid": "0.24", "best_ask": "0.26"}], "timestamp": "1769384445588", "event_type": "price_change"}}
{"_local_timestamp": "2026-01-25T23:40:45.685800+00:00", "data": {"market": "0x281565cae359040475640be8bc20f4efe15245fe0251805fd338fb1a3e45ffae", "price_changes": [{"asset_id": "29048360022556021389805670398008888482908398853670829781367251641936311260707", "price": "0.59", "size": "805", "side": "BUY", "hash": "aa01940f4a8eae8b478c7fb3373676485f637675", "best_bid": "0.74", "best_ask": "0.76"}, {"asset_id": "114528627098181527180076013437205839368323282497361602702800503052375432480589", "price": "0.41", "size": "805", "side": "SELL", "hash": "a5b389355b9f8cf49dce817d7df5647bf2f48642", "best_bid": "0.24", "best_ask": "0.26"}], "timestamp": "1769384445588", "event_type": "price_change"}}
{"_local_timestamp": "2026-01-25T23:40:45.692663+00:00", "data": {"market": "0x281565cae359040475640be8bc20f4efe15245fe0251805fd338fb1a3e45ffae", "price_changes": [{"asset_id": "29048360022556021389805670398008888482908398853670829781367251641936311260707", "price": "0.55", "size": "94.81", "side": "BUY", "hash": "aa01940f4a8eae8b478c7fb3373676485f637675", "best_bid": "0.74", "best_ask": "0.76"}, {"asset_id": "114528627098181527180076013437205839368323282497361602702800503052375432480589", "price": "0.45", "size": "94.81", "side": "SELL", "hash": "a5b389355b9f8cf49dce817d7df5647bf2f48642", "best_bid": "0.24", "best_ask": "0.26"}], "timestamp": "1769384445588", "event_type": "price_change"}}
{"_local_timestamp": "2026-01-25T23:40:45.701810+00:00", "data": {"market": "0x281565cae359040475640be8bc20f4efe15245fe0251805fd338fb1a3e45ffae", "price_changes": [{"asset_id": "29048360022556021389805670398008888482908398853670829781367251641936311260707", "price": "0.64", "size": "0", "side": "BUY", "hash": "aa01940f4a8eae8b478c7fb3373676485f637675", "best_bid": "0.74", "best_ask": "0.76"}, {"asset_id": "114528627098181527180076013437205839368323282497361602702800503052375432480589", "price": "0.36", "size": "0", "side": "SELL", "hash": "a5b389355b9f8cf49dce817d7df5647bf2f48642", "best_bid": "0.24", "best_ask": "0.26"}], "timestamp": "1769384445588", "event_type": "price_change"}}
{"_local_timestamp": "2026-01-25T23:40:45.713693+00:00", "data": {"market": "0x281565cae359040475640be8bc20f4efe15245fe0251805fd338fb1a3e45ffae", "price_changes": [{"asset_id": "29048360022556021389805670398008888482908398853670829781367251641936311260707", "price": "0.67", "size": "110", "side": "BUY", "hash": "aa01940f4a8eae8b478c7fb3373676485f637675", "best_bid": "0.74", "best_ask": "0.76"}, {"asset_id": "114528627098181527180076013437205839368323282497361602702800503052375432480589", "price": "0.33", "size": "110", "side": "SELL", "hash": "a5b389355b9f8cf49dce817d7df5647bf2f48642", "best_bid": "0.24", "best_ask": "0.26"}], "timestamp": "1769384445588", "event_type": "price_change"}}
{"_local_timestamp": "2026-01-25T23:40:45.723556+00:00", "data": {"market": "0x281565cae359040475640be8bc20f4efe15245fe0251805fd338fb1a3e45ffae", "price_changes": [{"asset_id": "29048360022556021389805670398008888482908398853670829781367251641936311260707", "price": "0.53", "size": "0", "side": "BUY", "hash": "aa01940f4a8eae8b478c7fb3373676485f637675", "best_bid": "0.74", "best_ask": "0.76"}, {"asset_id": "114528627098181527180076013437205839368323282497361602702800503052375432480589", "price": "0.47", "size": "0", "side": "SELL", "hash": "a5b389355b9f8cf49dce817d7df5647bf2f48642", "best_bid": "0.24", "best_ask": "0.26"}], "timestamp": "1769384445588", "event_type": "price_change"}}
{"_local_timestamp": "2026-01-25T23:40:45.802038+00:00", "data": {"market": "0xf2fb4784ceb4d41ce23703da426700f710320ec5b711b6e3784bdaac24d94c23", "price_changes": [{"asset_id": "88794755386871079853762415286654635832909423950620116774027006364873482091563", "price": "0.221", "size": "0", "side": "BUY", "hash": "93c3a4523f747c05520f1a252b26fe8492a99bd1", "best_bid": "0.865", "best_ask": "0.877"}, {"asset_id": "73768610008619570600930429495180540710817177537162503586781057110775077618432", "price": "0.779", "size": "0", "side": "SELL", "hash": "3e3dc0a5a32901c9423251a8946f79f25b7af156", "best_bid": "0.123", "best_ask": "0.135"}], "timestamp": "1769384445733", "event_type": "price_change"}}
{"_local_timestamp": "2026-01-25T23:40:45.808639+00:00", "data": {"market": "0xf2fb4784ceb4d41ce23703da426700f710320ec5b711b6e3784bdaac24d94c23", "price_changes": [{"asset_id": "88794755386871079853762415286654635832909423950620116774027006364873482091563", "price": "0.795", "size": "0", "side": "BUY", "hash": "93c3a4523f747c05520f1a252b26fe8492a99bd1", "best_bid": "0.865", "best_ask": "0.877"}, {"asset_id": "73768610008619570600930429495180540710817177537162503586781057110775077618432", "price": "0.205", "size": "0", "side": "SELL", "hash": "3e3dc0a5a32901c9423251a8946f79f25b7af156", "best_bid": "0.123", "best_ask": "0.135"}], "timestamp": "1769384445733", "event_type": "price_change"}}
{"_local_timestamp": "2026-01-25T23:40:45.920923+00:00", "data": {"market": "0x5c5d898595b3445dd3809896302889cd512411fa8306de609d9d8aa34e257ba8", "price_changes": [{"asset_id": "31339843398803147748606287378592227516750208753666943060502579333204198045040", "price": "0.974", "size": "0", "side": "BUY", "hash": "51ce4735057f55820e4252fbc2602d9d0d933c08", "best_bid": "0.999", "best_ask": "1"}, {"asset_id": "45014676111572901552217363692090679327003594688155466306257909550735876308571", "price": "0.026", "size": "0", "side": "SELL", "hash": "548fe04a5acc54d8a512cc8757843f558ac910b9", "best_bid": "0", "best_ask": "0.001"}], "timestamp": "1769384445846", "event_type": "price_change"}}
{"_local_timestamp": "2026-01-25T23:40:45.930237+00:00", "data": {"market": "0x281565cae359040475640be8bc20f4efe15245fe0251805fd338fb1a3e45ffae", "price_changes": [{"asset_id": "29048360022556021389805670398008888482908398853670829781367251641936311260707", "price": "0.72", "size": "690.91", "side": "BUY", "hash": "e12c84b099691f6f3e20b04a1953651005881b53", "best_bid": "0.74", "best_ask": "0.76"}, {"asset_id": "114528627098181527180076013437205839368323282497361602702800503052375432480589", "price": "0.28", "size": "690.91", "side": "SELL", "hash": "57961dd2457c37f21ff07c864560c35a304105e6", "best_bid": "0.24", "best_ask": "0.26"}], "timestamp": "1769384445846", "event_type": "price_change"}}
{"_local_timestamp": "2026-01-25T23:40:45.939730+00:00", "data": {"market": "0x281565cae359040475640be8bc20f4efe15245fe0251805fd338fb1a3e45ffae", "price_changes": [{"asset_id": "29048360022556021389805670398008888482908398853670829781367251641936311260707", "price": "0.81", "size": "100", "side": "SELL", "hash": "e12c84b099691f6f3e20b04a1953651005881b53", "best_bid": "0.74", "best_ask": "0.76"}, {"asset_id": "114528627098181527180076013437205839368323282497361602702800503052375432480589", "price": "0.19", "size": "100", "side": "BUY", "hash": "57961dd2457c37f21ff07c864560c35a304105e6", "best_bid": "0.24", "best_ask": "0.26"}], "timestamp": "1769384445846", "event_type": "price_change"}}
{"_local_timestamp": "2026-01-25T23:40:45.949989+00:00", "data": {"market": "0xb207031da5ef9cbded418e6b5b3c5eee24a3a7b22c6ec10053cbaaa67d793796", "price_changes": [{"asset_id": "89110596788673536475065853727140488937259064164063660201050220270400840228269", "price": "0.05", "size": "0", "side": "BUY", "hash": "5666109f7ed7c570ea8a27477e3d7256bfb09589", "best_bid": "0.063", "best_ask": "0.064"}, {"asset_id": "101506943049053276934626391886226570064171431948041761918666910024462041911155", "price": "0.95", "size": "0", "side": "SELL", "hash": "7d0fe3a7459b888029feb057ca4e199e1386f5f1", "best_bid": "0.936", "best_ask": "0.937"}], "timestamp": "1769384445846", "event_type": "price_change"}}
{"_local_timestamp": "2026-01-25T23:40:45.957662+00:00", "data": {"market": "0xb207031da5ef9cbded418e6b5b3c5eee24a3a7b22c6ec10053cbaaa67d793796", "price_changes": [{"asset_id": "89110596788673536475065853727140488937259064164063660201050220270400840228269", "price": "0.1", "size": "9024", "side": "SELL", "hash": "5666109f7ed7c570ea8a27477e3d7256bfb09589", "best_bid": "0.063", "best_ask": "0.064"}, {"asset_id": "101506943049053276934626391886226570064171431948041761918666910024462041911155", "price": "0.9", "size": "9024", "side": "BUY", "hash": "7d0fe3a7459b888029feb057ca4e199e1386f5f1", "best_bid": "0.936", "best_ask": "0.937"}], "timestamp": "1769384445846", "event_type": "price_change"}}
{"_local_timestamp": "2026-01-25T23:40:45.964401+00:00", "data": {"market": "0xf2fb4784ceb4d41ce23703da426700f710320ec5b711b6e3784bdaac24d94c23", "price_changes": [{"asset_id": "73768610008619570600930429495180540710817177537162503586781057110775077618432", "price": "0.098", "size": "200", "side": "BUY", "hash": "ee173ecd91ca096725c13ea9d292fb4492ace38d", "best_bid": "0.123", "best_ask": "0.135"}, {"asset_id": "88794755386871079853762415286654635832909423950620116774027006364873482091563", "price": "0.902", "size": "200", "side": "SELL", "hash": "dc66ff145eb1fd9e1db559befb16405a365052f1", "best_bid": "0.865", "best_ask": "0.877"}], "timestamp": "1769384445846", "event_type": "price_change"}}
{"_local_timestamp": "2026-01-25T23:40:45.970871+00:00", "data": {"market": "0xf2fb4784ceb4d41ce23703da426700f710320ec5b711b6e3784bdaac24d94c23", "price_changes": [{"asset_id": "73768610008619570600930429495180540710817177537162503586781057110775077618432", "price": "0.149", "size": "1200", "side": "SELL", "hash": "ee173ecd91ca096725c13ea9d292fb4492ace38d", "best_bid": "0.123", "best_ask": "0.135"}, {"asset_id": "88794755386871079853762415286654635832909423950620116774027006364873482091563", "price": "0.851", "size": "1200", "side": "BUY", "hash": "dc66ff145eb1fd9e1db559befb16405a365052f1", "best_bid": "0.865", "best_ask": "0.877"}], "timestamp": "1769384445846", "event_type": "price_change"}}
{"_local_timestamp": "2026-01-25T23:40:45.977707+00:00", "data": {"market": "0xb207031da5ef9cbded418e6b5b3c5eee24a3a7b22c6ec10053cbaaa67d793796", "price_changes": [{"asset_id": "101506943049053276934626391886226570064171431948041761918666910024462041911155", "price": "0.9", "size": "0", "side": "BUY", "hash": "510be2e45b54af09b5b71fe34aa9d62cdc781d17", "best_bid": "0.936", "best_ask": "0.937"}, {"asset_id": "89110596788673536475065853727140488937259064164063660201050220270400840228269", "price": "0.1", "size": "0", "side": "SELL", "hash": "08f3294ee86224818378fe19ebc5cd49278e6eb3", "best_bid": "0.063", "best_ask": "0.064"}], "timestamp": "1769384445848", "event_type": "price_change"}}
{"_local_timestamp": "2026-01-25T23:40:45.983640+00:00", "data": {"market": "0xf2fb4784ceb4d41ce23703da426700f710320ec5b711b6e3784bdaac24d94c23", "price_changes": [{"asset_id": "88794755386871079853762415286654635832909423950620116774027006364873482091563", "price": "0.796", "size": "0", "side": "BUY", "hash": "2ee50a636860ae72b86916a048d769d9dd72b000", "best_bid": "0.865", "best_ask": "0.877"}, {"asset_id": "73768610008619570600930429495180540710817177537162503586781057110775077618432", "price": "0.204", "size": "0", "side": "SELL", "hash": "b3dcf79e4ff457dbcd6dbae3b1f720c169717dc7", "best_bid": "0.123", "best_ask": "0.135"}], "timestamp": "1769384445912", "event_type": "price_change"}}
{"_local_timestamp": "2026-01-25T23:40:46.011398+00:00", "data": {"market": "0xf2fb4784ceb4d41ce23703da426700f710320ec5b711b6e3784bdaac24d94c23", "price_changes": [{"asset_id": "88794755386871079853762415286654635832909423950620116774027006364873482091563", "price": "0.753", "size": "20", "side": "BUY", "hash": "d6b25d6a113e927bb1ed141c472e0896e1d833f2", "best_bid": "0.865", "best_ask": "0.877"}, {"asset_id": "73768610008619570600930429495180540710817177537162503586781057110775077618432", "price": "0.247", "size": "20", "side": "SELL", "hash": "658c266764562dba5b26e5090158eff2bad42818", "best_bid": "0.123", "best_ask": "0.135"}], "timestamp": "1769384445936", "event_type": "price_change"}}
{"_local_timestamp": "2026-01-25T23:40:46.021525+00:00", "data": {"market": "0xf2fb4784ceb4d41ce23703da426700f710320ec5b711b6e3784bdaac24d94c23", "price_changes": [{"asset_id": "88794755386871079853762415286654635832909423950620116774027006364873482091563", "price": "0.221", "size": "417", "side": "BUY", "hash": "cbc4b5ad068c49c1e243c9c6679e2672dd41ccec", "best_bid": "0.865", "best_ask": "0.877"}, {"asset_id": "73768610008619570600930429495180540710817177537162503586781057110775077618432", "price": "0.779", "size": "417", "side": "SELL", "hash": "0e898228b82caa4d9b1b35adbb372b1bf56aa32d", "best_bid": "0.123", "best_ask": "0.135"}], "timestamp": "1769384445942", "event_type": "price_change"}}
{"_local_timestamp": "2026-01-25T23:40:46.029307+00:00", "data": {"market": "0xf2fb4784ceb4d41ce23703da426700f710320ec5b711b6e3784bdaac24d94c23", "price_changes": [{"asset_id": "88794755386871079853762415286654635832909423950620116774027006364873482091563", "price": "0.795", "size": "247", "side": "BUY", "hash": "d4493923b0e2781ecf3660e9b0fdd9a8920e5bf4", "best_bid": "0.865", "best_ask": "0.877"}, {"asset_id": "73768610008619570600930429495180540710817177537162503586781057110775077618432", "price": "0.205", "size": "247", "side": "SELL", "hash": "aa0084e492a2594ccca8bb2e4dd4eb6b49bfe266", "best_bid": "0.123", "best_ask": "0.135"}], "timestamp": "1769384445942", "event_type": "price_change"}}
{"_local_timestamp": "2026-01-25T23:40:46.044302+00:00", "data": {"market": "0xb207031da5ef9cbded418e6b5b3c5eee24a3a7b22c6ec10053cbaaa67d793796", "price_changes": [{"asset_id": "101506943049053276934626391886226570064171431948041761918666910024462041911155", "price": "0.763", "size": "636", "side": "BUY", "hash": "c09c599aad4a6caa165580522314ee214b1856d8", "best_bid": "0.936", "best_ask": "0.937"}, {"asset_id": "89110596788673536475065853727140488937259064164063660201050220270400840228269", "price": "0.237", "size": "636", "side": "SELL", "hash": "5dd1dbc78b190af9576eb61bfee045f60e24f22e", "best_bid": "0.063", "best_ask": "0.064"}], "timestamp": "1769384445969", "event_type": "price_change"}}
{"_local_timestamp": "2026-01-25T23:40:46.166851+00:00", "data": {"market": "0x281565cae359040475640be8bc20f4efe15245fe0251805fd338fb1a3e45ffae", "price_changes": [{"asset_id": "29048360022556021389805670398008888482908398853670829781367251641936311260707", "price": "0.31", "size": "14", "side": "BUY", "hash": "cb60c70ffa40d2f008b238b90f594a64cde84560", "best_bid": "0.74", "best_ask": "0.76"}, {"asset_id": "114528627098181527180076013437205839368323282497361602702800503052375432480589", "price": "0.69", "size": "14", "side": "SELL", "hash": "a369e9a4d3195737a2ab42eafbfdcf8db7f1970f", "best_bid": "0.24", "best_ask": "0.26"}], "timestamp": "1769384446100", "event_type": "price_change"}}
{"_local_timestamp": "2026-01-25T23:40:46.177299+00:00", "data": {"market": "0x281565cae359040475640be8bc20f4efe15245fe0251805fd338fb1a3e45ffae", "price_changes": [{"asset_id": "29048360022556021389805670398008888482908398853670829781367251641936311260707", "price": "0.28", "size": "16", "side": "BUY", "hash": "ea43ce95f54498ca762901ce306b5f2a1f991e57", "best_bid": "0.74", "best_ask": "0.76"}, {"asset_id": "114528627098181527180076013437205839368323282497361602702800503052375432480589", "price": "0.72", "size": "16", "side": "SELL", "hash": "9ab63a5bebd700890cdd06f2c866df7c9121ba00", "best_bid": "0.24", "best_ask": "0.26"}], "timestamp": "1769384446101", "event_type": "price_change"}}
{"_local_timestamp": "2026-01-25T23:40:46.185130+00:00", "data": {"market": "0x281565cae359040475640be8bc20f4efe15245fe0251805fd338fb1a3e45ffae", "price_changes": [{"asset_id": "29048360022556021389805670398008888482908398853670829781367251641936311260707", "price": "0.53", "size": "12", "side": "BUY", "hash": "8c91420686b74ba1448f3ceae15d324749a20628", "best_bid": "0.74", "best_ask": "0.76"}, {"asset_id": "114528627098181527180076013437205839368323282497361602702800503052375432480589", "price": "0.47", "size": "12", "side": "SELL", "hash": "b8658ef6aef33f5de19764f4519fd9451bc6fe04", "best_bid": "0.24", "best_ask": "0.26"}], "timestamp": "1769384446101", "event_type": "price_change"}}
{"_local_timestamp": "2026-01-25T23:40:46.193352+00:00", "data": {"market": "0x281565cae359040475640be8bc20f4efe15245fe0251805fd338fb1a3e45ffae", "price_changes": [{"asset_id": "29048360022556021389805670398008888482908398853670829781367251641936311260707", "price": "0.15", "size": "29", "side": "BUY", "hash": "fe0eb57f0dfb524c3e58b5b556b588c848fc8959", "best_bid": "0.74", "best_ask": "0.76"}, {"asset_id": "114528627098181527180076013437205839368323282497361602702800503052375432480589", "price": "0.85", "size": "29", "side": "SELL", "hash": "c27de593c22576996a76962f10c08d73d3c4801c", "best_bid": "0.24", "best_ask": "0.26"}], "timestamp": "1769384446102", "event_type": "price_change"}}
{"_local_timestamp": "2026-01-25T23:40:46.209003+00:00", "data": {"market": "0x281565cae359040475640be8bc20f4efe15245fe0251805fd338fb1a3e45ffae", "price_changes": [{"asset_id": "29048360022556021389805670398008888482908398853670829781367251641936311260707", "price": "0.55", "size": "980.81", "side": "BUY", "hash": "b2af05130f1ce23ef51e4a4e8150816bf0b7e4d2", "best_bid": "0.74", "best_ask": "0.76"}, {"asset_id": "114528627098181527180076013437205839368323282497361602702800503052375432480589", "price": "0.45", "size": "980.81", "side": "SELL", "hash": "6df562ce317e3d90c1df38fdc765dd707561a5ba", "best_bid": "0.24", "best_ask": "0.26"}], "timestamp": "1769384446102", "event_type": "price_change"}}
{"_local_timestamp": "2026-01-25T23:40:46.226512+00:00", "data": {"market": "0x281565cae359040475640be8bc20f4efe15245fe0251805fd338fb1a3e45ffae", "price_changes": [{"asset_id": "29048360022556021389805670398008888482908398853670829781367251641936311260707", "price": "0.54", "size": "127", "side": "BUY", "hash": "adeb2bb1a384e041150679cf916e461833f0fb3a", "best_bid": "0.74", "best_ask": "0.76"}, {"asset_id": "114528627098181527180076013437205839368323282497361602702800503052375432480589", "price": "0.46", "size": "127", "side": "SELL", "hash": "11c35cf2be56c792ec9864f3e88153e7809a809f", "best_bid": "0.24", "best_ask": "0.26"}], "timestamp": "1769384446103", "event_type": "price_change"}}
{"_local_timestamp": "2026-01-25T23:40:46.233444+00:00", "data": {"market": "0x281565cae359040475640be8bc20f4efe15245fe0251805fd338fb1a3e45ffae", "price_changes": [{"asset_id": "29048360022556021389805670398008888482908398853670829781367251641936311260707", "price": "0.27", "size": "644", "side": "BUY", "hash": "3637045512ea2903ac9fbfeef9cde3538abf692e", "best_bid": "0.74", "best_ask": "0.76"}, {"asset_id": "114528627098181527180076013437205839368323282497361602702800503052375432480589", "price": "0.73", "size": "644", "side": "SELL", "hash": "f4903d12002194ea9179acc4eabc18ef5b2393e3", "best_bid": "0.24", "best_ask": "0.26"}], "timestamp": "1769384446103", "event_type": "price_change"}}
{"_local_timestamp": "2026-01-25T23:40:46.240793+00:00", "data": {"market": "0x281565cae359040475640be8bc20f4efe15245fe0251805fd338fb1a3e45ffae", "price_changes": [{"asset_id": "29048360022556021389805670398008888482908398853670829781367251641936311260707", "price": "0.61", "size": "839", "side": "BUY", "hash": "6b6cf50d5c7b3cec2c7bd06697301f5056148c37", "best_bid": "0.74", "best_ask": "0.76"}, {"asset_id": "114528627098181527180076013437205839368323282497361602702800503052375432480589", "price": "0.39", "size": "839", "side": "SELL", "hash": "16a157c55c4c3ec3de2127deb9258a7947e48b68", "best_bid": "0.24", "best_ask": "0.26"}], "timestamp": "1769384446104", "event_type": "price_change"}}
{"_local_timestamp": "2026-01-25T23:40:46.249714+00:00", "data": {"market": "0x281565cae359040475640be8bc20f4efe15245fe0251805fd338fb1a3e45ffae", "price_changes": [{"asset_id": "29048360022556021389805670398008888482908398853670829781367251641936311260707", "price": "0.64", "size": "80", "side": "BUY", "hash": "7a100faf1324ac13c28588658feee772acf656b0", "best_bid": "0.74", "best_ask": "0.76"}, {"asset_id": "114528627098181527180076013437205839368323282497361602702800503052375432480589", "price": "0.36", "size": "80", "side": "SELL", "hash": "64dc38b687f86f3e1c69e027e10e779b801c5623", "best_bid": "0.24", "best_ask": "0.26"}], "timestamp": "1769384446104", "event_type": "price_change"}}
{"_local_timestamp": "2026-01-25T23:40:46.259438+00:00", "data": {"market": "0x281565cae359040475640be8bc20f4efe15245fe0251805fd338fb1a3e45ffae", "price_changes": [{"asset_id": "29048360022556021389805670398008888482908398853670829781367251641936311260707", "price": "0.67", "size": "494", "side": "BUY", "hash": "f0bf8b0389bf3631b6ef4dd64b49f1ca6d6491bf", "best_bid": "0.74", "best_ask": "0.76"}, {"asset_id": "114528627098181527180076013437205839368323282497361602702800503052375432480589", "price": "0.33", "size": "494", "side": "SELL", "hash": "3789e18f1b1b5b1647a0bb3a0281f927bb027e5d", "best_bid": "0.24", "best_ask": "0.26"}], "timestamp": "1769384446105", "event_type": "price_change"}}
{"_local_timestamp": "2026-01-25T23:40:46.269416+00:00", "data": {"market": "0x281565cae359040475640be8bc20f4efe15245fe0251805fd338fb1a3e45ffae", "price_changes": [{"asset_id": "29048360022556021389805670398008888482908398853670829781367251641936311260707", "price": "0.26", "size": "8", "side": "BUY", "hash": "3142bb935ea9c6c838819662fc6582c20483c9b5", "best_bid": "0.74", "best_ask": "0.76"}, {"asset_id": "114528627098181527180076013437205839368323282497361602702800503052375432480589", "price": "0.74", "size": "8", "side": "SELL", "hash": "373f272431c37fa6e3094625ab89101670f3f981", "best_bid": "0.24", "best_ask": "0.26"}], "timestamp": "1769384446106", "event_type": "price_change"}}
{"_local_timestamp": "2026-01-25T23:40:46.281828+00:00", "data": {"market": "0x281565cae359040475640be8bc20f4efe15245fe0251805fd338fb1a3e45ffae", "price_changes": [{"asset_id": "29048360022556021389805670398008888482908398853670829781367251641936311260707", "price": "0.66", "size": "690.1", "side": "BUY", "hash": "5dcdc4e0020615c04c6d5c860e48e3896e9a3021", "best_bid": "0.74", "best_ask": "0.76"}, {"asset_id": "114528627098181527180076013437205839368323282497361602702800503052375432480589", "price": "0.34", "size": "690.1", "side": "SELL", "hash": "18e2349769783e40438a108c5938938a424f96d2", "best_bid": "0.24", "best_ask": "0.26"}], "timestamp": "1769384446106", "event_type": "price_change"}}
{"_local_timestamp": "2026-01-25T23:40:46.290827+00:00", "data": {"market": "0x281565cae359040475640be8bc20f4efe15245fe0251805fd338fb1a3e45ffae", "price_changes": [{"asset_id": "29048360022556021389805670398008888482908398853670829781367251641936311260707", "price": "0.29", "size": "4083", "side": "BUY", "hash": "f59cc8fc40127d15bce0cd7f3b8ae28a93d77d45", "best_bid": "0.74", "best_ask": "0.76"}, {"asset_id": "114528627098181527180076013437205839368323282497361602702800503052375432480589", "price": "0.71", "size": "4083", "side": "SELL", "hash": "206b78bd88a7f707156a63c9cab79486afe57b7a", "best_bid": "0.24", "best_ask": "0.26"}], "timestamp": "1769384446107", "event_type": "price_change"}}
{"_local_timestamp": "2026-01-25T23:40:46.300569+00:00", "data": {"market": "0x281565cae359040475640be8bc20f4efe15245fe0251805fd338fb1a3e45ffae", "price_changes": [{"asset_id": "29048360022556021389805670398008888482908398853670829781367251641936311260707", "price": "0.59", "size": "1366", "side": "BUY", "hash": "77c4886f8739b67a3fd922016af0abd3bff8a03c", "best_bid": "0.74", "best_ask": "0.76"}, {"asset_id": "114528627098181527180076013437205839368323282497361602702800503052375432480589", "price": "0.41", "size": "1366", "side": "SELL", "hash": "2afca826330505f6f7a87c6062060bb06841d8f5", "best_bid": "0.24", "best_ask": "0.26"}], "timestamp": "1769384446107", "event_type": "price_change"}}
{"_local_timestamp": "2026-01-25T23:40:46.877867+00:00", "data": {"market": "0xf2fb4784ceb4d41ce23703da426700f710320ec5b711b6e3784bdaac24d94c23", "price_changes": [{"asset_id": "88794755386871079853762415286654635832909423950620116774027006364873482091563", "price": "0.753", "size": "0", "side": "BUY", "hash": "9a1ad3bce071f235e7fc6c43d7fb29acbad155d3", "best_bid": "0.865", "best_ask": "0.877"}, {"asset_id": "73768610008619570600930429495180540710817177537162503586781057110775077618432", "price": "0.247", "size": "0", "side": "SELL", "hash": "1ff150b1e3fb113e8581e14535761e2f1e95b82f", "best_bid": "0.123", "best_ask": "0.135"}], "timestamp": "1769384446796", "event_type": "price_change"}}
{"_local_timestamp": "2026-01-25T23:40:46.888673+00:00", "data": {"market": "0xf2fb4784ceb4d41ce23703da426700f710320ec5b711b6e3784bdaac24d94c23", "price_changes": [{"asset_id": "88794755386871079853762415286654635832909423950620116774027006364873482091563", "price": "0.796", "size": "20", "side": "BUY", "hash": "4d74993d0370a5c9da8db64f0409a9307ed9b322", "best_bid": "0.865", "best_ask": "0.877"}, {"asset_id": "73768610008619570600930429495180540710817177537162503586781057110775077618432", "price": "0.204", "size": "20", "side": "SELL", "hash": "6337bf0d3fc7862b8ebaf4e0a6b800377ff641e6", "best_bid": "0.123", "best_ask": "0.135"}], "timestamp": "1769384446821", "event_type": "price_change"}}
{"_local_timestamp": "2026-01-25T23:40:47.157112+00:00", "data": {"market": "0x281565cae359040475640be8bc20f4efe15245fe0251805fd338fb1a3e45ffae", "price_changes": [{"asset_id": "29048360022556021389805670398008888482908398853670829781367251641936311260707", "price": "0.56", "size": "0", "side": "BUY", "hash": "9b9da93cffbe08d347c53b41ee9b87dbae800bd5", "best_bid": "0.74", "best_ask": "0.76"}, {"asset_id": "114528627098181527180076013437205839368323282497361602702800503052375432480589", "price": "0.44", "size": "0", "side": "SELL", "hash": "2923180524b4942e4f1a9331b98640645397aa1d", "best_bid": "0.24", "best_ask": "0.26"}], "timestamp": "1769384447084", "event_type": "price_change"}}
{"_local_timestamp": "2026-01-25T23:40:47.169425+00:00", "data": {"market": "0x281565cae359040475640be8bc20f4efe15245fe0251805fd338fb1a3e45ffae", "price_changes": [{"asset_id": "29048360022556021389805670398008888482908398853670829781367251641936311260707", "price": "0.62", "size": "0", "side": "BUY", "hash": "9b9da93cffbe08d347c53b41ee9b87dbae800bd5", "best_bid": "0.74", "best_ask": "0.76"}, {"asset_id": "114528627098181527180076013437205839368323282497361602702800503052375432480589", "price": "0.38", "size": "0", "side": "SELL", "hash": "2923180524b4942e4f1a9331b98640645397aa1d", "best_bid": "0.24", "best_ask": "0.26"}], "timestamp": "1769384447084", "event_type": "price_change"}}
{"_local_timestamp": "2026-01-25T23:40:47.175555+00:00", "data": {"market": "0x281565cae359040475640be8bc20f4efe15245fe0251805fd338fb1a3e45ffae", "price_changes": [{"asset_id": "29048360022556021389805670398008888482908398853670829781367251641936311260707", "price": "0.49", "size": "0", "side": "BUY", "hash": "9b9da93cffbe08d347c53b41ee9b87dbae800bd5", "best_bid": "0.74", "best_ask": "0.76"}, {"asset_id": "114528627098181527180076013437205839368323282497361602702800503052375432480589", "price": "0.51", "size": "0", "side": "SELL", "hash": "2923180524b4942e4f1a9331b98640645397aa1d", "best_bid": "0.24", "best_ask": "0.26"}], "timestamp": "1769384447084", "event_type": "price_change"}}
{"_local_timestamp": "2026-01-25T23:40:47.186682+00:00", "data": {"market": "0x281565cae359040475640be8bc20f4efe15245fe0251805fd338fb1a3e45ffae", "price_changes": [{"asset_id": "29048360022556021389805670398008888482908398853670829781367251641936311260707", "price": "0.59", "size": "805", "side": "BUY", "hash": "9b9da93cffbe08d347c53b41ee9b87dbae800bd5", "best_bid": "0.74", "best_ask": "0.76"}, {"asset_id": "114528627098181527180076013437205839368323282497361602702800503052375432480589", "price": "0.41", "size": "805", "side": "SELL", "hash": "2923180524b4942e4f1a9331b98640645397aa1d", "best_bid": "0.24", "best_ask": "0.26"}], "timestamp": "1769384447084", "event_type": "price_change"}}
{"_local_timestamp": "2026-01-25T23:40:47.192767+00:00", "data": {"market": "0x281565cae359040475640be8bc20f4efe15245fe0251805fd338fb1a3e45ffae", "price_changes": [{"asset_id": "29048360022556021389805670398008888482908398853670829781367251641936311260707", "price": "0.48", "size": "0", "side": "BUY", "hash": "9b9da93cffbe08d347c53b41ee9b87dbae800bd5", "best_bid": "0.74", "best_ask": "0.76"}, {"asset_id": "114528627098181527180076013437205839368323282497361602702800503052375432480589", "price": "0.52", "size": "0", "side": "SELL", "hash": "2923180524b4942e4f1a9331b98640645397aa1d", "best_bid": "0.24", "best_ask": "0.26"}], "timestamp": "1769384447084", "event_type": "price_change"}}
{"_local_timestamp": "2026-01-25T23:40:47.456611+00:00", "data": {"market": "0x281565cae359040475640be8bc20f4efe15245fe0251805fd338fb1a3e45ffae", "price_changes": [{"asset_id": "29048360022556021389805670398008888482908398853670829781367251641936311260707", "price": "0.48", "size": "820", "side": "BUY", "hash": "174ebb4bd339be9451eff3431cb2d48a7ceef4f9", "best_bid": "0.74", "best_ask": "0.76"}, {"asset_id": "114528627098181527180076013437205839368323282497361602702800503052375432480589", "price": "0.52", "size": "820", "side": "SELL", "hash": "125ad3c2e435e0035c94e374e44e88d08f84e09d", "best_bid": "0.24", "best_ask": "0.26"}], "timestamp": "1769384447388", "event_type": "price_change"}}
{"_local_timestamp": "2026-01-25T23:40:47.465487+00:00", "data": {"market": "0x281565cae359040475640be8bc20f4efe15245fe0251805fd338fb1a3e45ffae", "price_changes": [{"asset_id": "29048360022556021389805670398008888482908398853670829781367251641936311260707", "price": "0.58", "size": "1046", "side": "BUY", "hash": "bf29219855f6e12df41bbbefd0b97fb12cc291d1", "best_bid": "0.74", "best_ask": "0.76"}, {"asset_id": "114528627098181527180076013437205839368323282497361602702800503052375432480589", "price": "0.42", "size": "1046", "side": "SELL", "hash": "f86a851a624589746d669a5f1c0f7077128a00ed", "best_bid": "0.24", "best_ask": "0.26"}], "timestamp": "1769384447389", "event_type": "price_change"}}
{"_local_timestamp": "2026-01-25T23:40:47.471679+00:00", "data": {"market": "0x281565cae359040475640be8bc20f4efe15245fe0251805fd338fb1a3e45ffae", "price_changes": [{"asset_id": "29048360022556021389805670398008888482908398853670829781367251641936311260707", "price": "0.52", "size": "206", "side": "BUY", "hash": "a6e4e7ad0ca21a127a6172a5c50bd809e46c47fd", "best_bid": "0.74", "best_ask": "0.76"}, {"asset_id": "114528627098181527180076013437205839368323282497361602702800503052375432480589", "price": "0.48", "size": "206", "side": "SELL", "hash": "cdd29458d51307c481e8931a9911d801585d73df", "best_bid": "0.24", "best_ask": "0.26"}], "timestamp": "1769384447389", "event_type": "price_change"}}
{"_local_timestamp": "2026-01-25T23:40:47.482834+00:00", "data": {"market": "0x281565cae359040475640be8bc20f4efe15245fe0251805fd338fb1a3e45ffae", "price_changes": [{"asset_id": "29048360022556021389805670398008888482908398853670829781367251641936311260707", "price": "0.59", "size": "853", "side": "BUY", "hash": "23175aa2dd229d90c4011b4cb932de561c4db8c2", "best_bid": "0.74", "best_ask": "0.76"}, {"asset_id": "114528627098181527180076013437205839368323282497361602702800503052375432480589", "price": "0.41", "size": "853", "side": "SELL", "hash": "924a5c3f04f139acb937c110a0d6a7a6a6faec62", "best_bid": "0.24", "best_ask": "0.26"}], "timestamp": "1769384447390", "event_type": "price_change"}}
{"_local_timestamp": "2026-01-25T23:40:47.489228+00:00", "data": {"market": "0x281565cae359040475640be8bc20f4efe15245fe0251805fd338fb1a3e45ffae", "price_changes": [{"asset_id": "29048360022556021389805670398008888482908398853670829781367251641936311260707", "price": "0.07", "size": "240", "side": "BUY", "hash": "5b92644dd4cafe61eb9cd0d3b36609bb694d0cd3", "best_bid": "0.74", "best_ask": "0.76"}, {"asset_id": "114528627098181527180076013437205839368323282497361602702800503052375432480589", "price": "0.93", "size": "240", "side": "SELL", "hash": "183ade5cf34410cd755d05a380571bdaadbc527c", "best_bid": "0.24", "best_ask": "0.26"}], "timestamp": "1769384447390", "event_type": "price_change"}}
{"_local_timestamp": "2026-01-25T23:40:47.816451+00:00", "data": {"market": "0x281565cae359040475640be8bc20f4efe15245fe0251805fd338fb1a3e45ffae", "price_changes": [{"asset_id": "29048360022556021389805670398008888482908398853670829781367251641936311260707", "price": "0.62", "size": "6", "side": "BUY", "hash": "acde2c88e8d0e707315489e0f88a1924855d694a", "best_bid": "0.74", "best_ask": "0.76"}, {"asset_id": "114528627098181527180076013437205839368323282497361602702800503052375432480589", "price": "0.38", "size": "6", "side": "SELL", "hash": "0e89dbbbe01fca853c5ac877c9e8ea06ec666d2e", "best_bid": "0.24", "best_ask": "0.26"}], "timestamp": "1769384447747", "event_type": "price_change"}}
{"_local_timestamp": "2026-01-25T23:40:48.125679+00:00", "data": {"market": "0x281565cae359040475640be8bc20f4efe15245fe0251805fd338fb1a3e45ffae", "price_changes": [{"asset_id": "29048360022556021389805670398008888482908398853670829781367251641936311260707", "price": "0.52", "size": "0", "side": "BUY", "hash": "1eb63864accba5ed7b4ea90d09f936f24707b16b", "best_bid": "0.74", "best_ask": "0.76"}, {"asset_id": "114528627098181527180076013437205839368323282497361602702800503052375432480589", "price": "0.48", "size": "0", "side": "SELL", "hash": "ddc2fab5c991fbe869dd96ab654e8577639f774e", "best_bid": "0.24", "best_ask": "0.26"}], "timestamp": "1769384448053", "event_type": "price_change"}}
{"_local_timestamp": "2026-01-25T23:40:48.132385+00:00", "data": {"market": "0x281565cae359040475640be8bc20f4efe15245fe0251805fd338fb1a3e45ffae", "price_changes": [{"asset_id": "29048360022556021389805670398008888482908398853670829781367251641936311260707", "price": "0.07", "size": "0", "side": "BUY", "hash": "1eb63864accba5ed7b4ea90d09f936f24707b16b", "best_bid": "0.74", "best_ask": "0.76"}, {"asset_id": "114528627098181527180076013437205839368323282497361602702800503052375432480589", "price": "0.93", "size": "0", "side": "SELL", "hash": "ddc2fab5c991fbe869dd96ab654e8577639f774e", "best_bid": "0.24", "best_ask": "0.26"}], "timestamp": "1769384448053", "event_type": "price_change"}}
{"_local_timestamp": "2026-01-25T23:40:48.140334+00:00", "data": {"market": "0x281565cae359040475640be8bc20f4efe15245fe0251805fd338fb1a3e45ffae", "price_changes": [{"asset_id": "29048360022556021389805670398008888482908398853670829781367251641936311260707", "price": "0.58", "size": "1000", "side": "BUY", "hash": "1eb63864accba5ed7b4ea90d09f936f24707b16b", "best_bid": "0.74", "best_ask": "0.76"}, {"asset_id": "114528627098181527180076013437205839368323282497361602702800503052375432480589", "price": "0.42", "size": "1000", "side": "SELL", "hash": "ddc2fab5c991fbe869dd96ab654e8577639f774e", "best_bid": "0.24", "best_ask": "0.26"}], "timestamp": "1769384448053", "event_type": "price_change"}}
{"_local_timestamp": "2026-01-25T23:40:48.148420+00:00", "data": {"market": "0x281565cae359040475640be8bc20f4efe15245fe0251805fd338fb1a3e45ffae", "price_changes": [{"asset_id": "29048360022556021389805670398008888482908398853670829781367251641936311260707", "price": "0.59", "size": "805", "side": "BUY", "hash": "1eb63864accba5ed7b4ea90d09f936f24707b16b", "best_bid": "0.74", "best_ask": "0.76"}, {"asset_id": "114528627098181527180076013437205839368323282497361602702800503052375432480589", "price": "0.41", "size": "805", "side": "SELL", "hash": "ddc2fab5c991fbe869dd96ab654e8577639f774e", "best_bid": "0.24", "best_ask": "0.26"}], "timestamp": "1769384448053", "event_type": "price_change"}}
{"_local_timestamp": "2026-01-25T23:40:48.154676+00:00", "data": {"market": "0x281565cae359040475640be8bc20f4efe15245fe0251805fd338fb1a3e45ffae", "price_changes": [{"asset_id": "29048360022556021389805670398008888482908398853670829781367251641936311260707", "price": "0.48", "size": "0", "side": "BUY", "hash": "1eb63864accba5ed7b4ea90d09f936f24707b16b", "best_bid": "0.74", "best_ask": "0.76"}, {"asset_id": "114528627098181527180076013437205839368323282497361602702800503052375432480589", "price": "0.52", "size": "0", "side": "SELL", "hash": "ddc2fab5c991fbe869dd96ab654e8577639f774e", "best_bid": "0.24", "best_ask": "0.26"}], "timestamp": "1769384448053", "event_type": "price_change"}}
{"_local_timestamp": "2026-01-25T23:40:48.359201+00:00", "data": {"market": "0x281565cae359040475640be8bc20f4efe15245fe0251805fd338fb1a3e45ffae", "price_changes": [{"asset_id": "29048360022556021389805670398008888482908398853670829781367251641936311260707", "price": "0.49", "size": "169", "side": "BUY", "hash": "126995f7b2da32d3426dbc1f38df846564f59555", "best_bid": "0.74", "best_ask": "0.76"}, {"asset_id": "114528627098181527180076013437205839368323282497361602702800503052375432480589", "price": "0.51", "size": "169", "side": "SELL", "hash": "6100cd9e32410306e29ff6a05897d1291f1caafe", "best_bid": "0.24", "best_ask": "0.26"}], "timestamp": "1769384448288", "event_type": "price_change"}}
{"_local_timestamp": "2026-01-25T23:40:48.368760+00:00", "data": {"market": "0x281565cae359040475640be8bc20f4efe15245fe0251805fd338fb1a3e45ffae", "price_changes": [{"asset_id": "29048360022556021389805670398008888482908398853670829781367251641936311260707", "price": "0.59", "size": "1366", "side": "BUY", "hash": "132c0a1c3f7df6667104548e6594e5dda8abd17a", "best_bid": "0.74", "best_ask": "0.76"}, {"asset_id": "114528627098181527180076013437205839368323282497361602702800503052375432480589", "price": "0.41", "size": "1366", "side": "SELL", "hash": "475c829e4670e6747c5b10f603f2e68d729d48ae", "best_bid": "0.24", "best_ask": "0.26"}], "timestamp": "1769384448288", "event_type": "price_change"}}
{"_local_timestamp": "2026-01-25T23:40:48.374919+00:00", "data": {"market": "0x281565cae359040475640be8bc20f4efe15245fe0251805fd338fb1a3e45ffae", "price_changes": [{"asset_id": "29048360022556021389805670398008888482908398853670829781367251641936311260707", "price": "0.56", "size": "46", "side": "BUY", "hash": "c2a77a03b39866952b23dbb181ca30bf21cdf8d0", "best_bid": "0.74", "best_ask": "0.76"}, {"asset_id": "114528627098181527180076013437205839368323282497361602702800503052375432480589", "price": "0.44", "size": "46", "side": "SELL", "hash": "b31afa73ddfbcb61d7143c54175f11a70516bab0", "best_bid": "0.24", "best_ask": "0.26"}], "timestamp": "1769384448289", "event_type": "price_change"}}
{"_local_timestamp": "2026-01-25T23:40:48.382132+00:00", "data": {"market": "0x281565cae359040475640be8bc20f4efe15245fe0251805fd338fb1a3e45ffae", "price_changes": [{"asset_id": "29048360022556021389805670398008888482908398853670829781367251641936311260707", "price": "0.48", "size": "1024", "side": "BUY", "hash": "814e6886fcabb1dd032d644a3bd3d85fd33582e8", "best_bid": "0.74", "best_ask": "0.76"}, {"asset_id": "114528627098181527180076013437205839368323282497361602702800503052375432480589", "price": "0.52", "size": "1024", "side": "SELL", "hash": "f3dfa16551cbc4667835470b4cf00562d021d3b9", "best_bid": "0.24", "best_ask": "0.26"}], "timestamp": "1769384448290", "event_type": "price_change"}}
{"_local_timestamp": "2026-01-25T23:40:48.994352+00:00", "data": {"market": "0xf2fb4784ceb4d41ce23703da426700f710320ec5b711b6e3784bdaac24d94c23", "price_changes": [{"asset_id": "88794755386871079853762415286654635832909423950620116774027006364873482091563", "price": "0.221", "size": "0", "side": "BUY", "hash": "8add6240fdf73656b7488f90296cc13e2d3e3eaf", "best_bid": "0.865", "best_ask": "0.877"}, {"asset_id": "73768610008619570600930429495180540710817177537162503586781057110775077618432", "price": "0.779", "size": "0", "side": "SELL", "hash": "e3643db3025bb297a484b4778fac4c03165bdb7e", "best_bid": "0.123", "best_ask": "0.135"}], "timestamp": "1769384448926", "event_type": "price_change"}}
{"_local_timestamp": "2026-01-25T23:40:49.002190+00:00", "data": {"market": "0xf2fb4784ceb4d41ce23703da426700f710320ec5b711b6e3784bdaac24d94c23", "price_changes": [{"asset_id": "88794755386871079853762415286654635832909423950620116774027006364873482091563", "price": "0.795", "size": "0", "side": "BUY", "hash": "8add6240fdf73656b7488f90296cc13e2d3e3eaf", "best_bid": "0.865", "best_ask": "0.877"}, {"asset_id": "73768610008619570600930429495180540710817177537162503586781057110775077618432", "price": "0.205", "size": "0", "side": "SELL", "hash": "e3643db3025bb297a484b4778fac4c03165bdb7e", "best_bid": "0.123", "best_ask": "0.135"}], "timestamp": "1769384448926", "event_type": "price_change"}}
{"_local_timestamp": "2026-01-25T23:40:49.223439+00:00", "data": {"market": "0xf2fb4784ceb4d41ce23703da426700f710320ec5b711b6e3784bdaac24d94c23", "price_changes": [{"asset_id": "88794755386871079853762415286654635832909423950620116774027006364873482091563", "price": "0.221", "size": "372", "side": "BUY", "hash": "ba6bd9be304ed2ed5339b8c6ab376ffdcd8c7ed2", "best_bid": "0.865", "best_ask": "0.877"}, {"asset_id": "73768610008619570600930429495180540710817177537162503586781057110775077618432", "price": "0.779", "size": "372", "side": "SELL", "hash": "94dfe8f21a6cf322ab51a38038a1dddda3dc3b80", "best_bid": "0.123", "best_ask": "0.135"}], "timestamp": "1769384449149", "event_type": "price_change"}}
{"_local_timestamp": "2026-01-25T23:40:49.232056+00:00", "data": {"market": "0xf2fb4784ceb4d41ce23703da426700f710320ec5b711b6e3784bdaac24d94c23", "price_changes": [{"asset_id": "88794755386871079853762415286654635832909423950620116774027006364873482091563", "price": "0.795", "size": "292", "side": "BUY", "hash": "6cc44c37363d43d18a06926934eb4016af71bf40", "best_bid": "0.865", "best_ask": "0.877"}, {"asset_id": "73768610008619570600930429495180540710817177537162503586781057110775077618432", "price": "0.205", "size": "292", "side": "SELL", "hash": "a9810e5214f2ec10fd88c7e6d20c322272d80bb7", "best_bid": "0.123", "best_ask": "0.135"}], "timestamp": "1769384449150", "event_type": "price_change"}}
{"_local_timestamp": "2026-01-25T23:40:49.263550+00:00", "data": {"market": "0xf2fb4784ceb4d41ce23703da426700f710320ec5b711b6e3784bdaac24d94c23", "price_changes": [{"asset_id": "88794755386871079853762415286654635832909423950620116774027006364873482091563", "price": "0.796", "size": "0", "side": "BUY", "hash": "0b56b13960e1427aeb4f7d48d1815fdb1bdf8162", "best_bid": "0.865", "best_ask": "0.877"}, {"asset_id": "73768610008619570600930429495180540710817177537162503586781057110775077618432", "price": "0.204", "size": "0", "side": "SELL", "hash": "767967590b7aae7dc084709fb8bc0a7096e14b39", "best_bid": "0.123", "best_ask": "0.135"}], "timestamp": "1769384449193", "event_type": "price_change"}}
{"_local_timestamp": "2026-01-25T23:40:49.296740+00:00", "data": {"market": "0xf2fb4784ceb4d41ce23703da426700f710320ec5b711b6e3784bdaac24d94c23", "price_changes": [{"asset_id": "88794755386871079853762415286654635832909423950620116774027006364873482091563", "price": "0.753", "size": "20", "side": "BUY", "hash": "652831d20bb29a6643ab11bfae8b0804629f1b55", "best_bid": "0.865", "best_ask": "0.877"}, {"asset_id": "73768610008619570600930429495180540710817177537162503586781057110775077618432", "price": "0.247", "size": "20", "side": "SELL", "hash": "173016540a45af28303cb4bec3fb9f05c6ebeab8", "best_bid": "0.123", "best_ask": "0.135"}], "timestamp": "1769384449219", "event_type": "price_change"}}
{"_local_timestamp": "2026-01-25T23:40:51.349624+00:00", "data": {"market": "0xf2fb4784ceb4d41ce23703da426700f710320ec5b711b6e3784bdaac24d94c23", "price_changes": [{"asset_id": "88794755386871079853762415286654635832909423950620116774027006364873482091563", "price": "0.753", "size": "0", "side": "BUY", "hash": "74721cc9a9bce48c59a7e7fe8d3e28cd63b8d313", "best_bid": "0.865", "best_ask": "0.877"}, {"asset_id": "73768610008619570600930429495180540710817177537162503586781057110775077618432", "price": "0.247", "size": "0", "side": "SELL", "hash": "0444a74cfafa46b3568e8a97e6cc0892ceb4495b", "best_bid": "0.123", "best_ask": "0.135"}], "timestamp": "1769384451278", "event_type": "price_change"}}
{"_local_timestamp": "2026-01-25T23:40:51.371217+00:00", "data": {"market": "0xf2fb4784ceb4d41ce23703da426700f710320ec5b711b6e3784bdaac24d94c23", "price_changes": [{"asset_id": "88794755386871079853762415286654635832909423950620116774027006364873482091563", "price": "0.796", "size": "20", "side": "BUY", "hash": "a2c7cb62b0748bc990a6e44d13d02f3efa10da77", "best_bid": "0.865", "best_ask": "0.877"}, {"asset_id": "73768610008619570600930429495180540710817177537162503586781057110775077618432", "price": "0.204", "size": "20", "side": "SELL", "hash": "55678eac407fd474a50abd92803342fbbfef74b8", "best_bid": "0.123", "best_ask": "0.135"}], "timestamp": "1769384451307", "event_type": "price_change"}}
{"_local_timestamp": "2026-01-25T23:40:51.525166+00:00", "data": {"market": "0x281565cae359040475640be8bc20f4efe15245fe0251805fd338fb1a3e45ffae", "price_changes": [{"asset_id": "29048360022556021389805670398008888482908398853670829781367251641936311260707", "price": "0.72", "size": "917.91", "side": "BUY", "hash": "f18548bb2917d27420b700b8bd9578b87afabe17", "best_bid": "0.74", "best_ask": "0.76"}, {"asset_id": "114528627098181527180076013437205839368323282497361602702800503052375432480589", "price": "0.28", "size": "917.91", "side": "SELL", "hash": "ac0c7a8be3d6d0af6dd585b6721565717b2e05a9", "best_bid": "0.24", "best_ask": "0.26"}], "timestamp": "1769384451457", "event_type": "price_change"}}
{"_local_timestamp": "2026-01-25T23:40:51.532209+00:00", "data": {"market": "0x281565cae359040475640be8bc20f4efe15245fe0251805fd338fb1a3e45ffae", "price_changes": [{"asset_id": "29048360022556021389805670398008888482908398853670829781367251641936311260707", "price": "0.81", "size": "693", "side": "SELL", "hash": "b69f0d2b3975a62427226602595cb7ebab88812e", "best_bid": "0.74", "best_ask": "0.76"}, {"asset_id": "114528627098181527180076013437205839368323282497361602702800503052375432480589", "price": "0.19", "size": "693", "side": "BUY", "hash": "7081e83243507bd2bf9d3a3af1b8620c12e7541d", "best_bid": "0.24", "best_ask": "0.26"}], "timestamp": "1769384451459", "event_type": "price_change"}}
{"_local_timestamp": "2026-01-25T23:40:52.188376+00:00", "data": {"market": "0xf2fb4784ceb4d41ce23703da426700f710320ec5b711b6e3784bdaac24d94c23", "price_changes": [{"asset_id": "73768610008619570600930429495180540710817177537162503586781057110775077618432", "price": "0.098", "size": "411", "side": "BUY", "hash": "737929bdc1e957c5365c082bf2de9cb50e947485", "best_bid": "0.123", "best_ask": "0.135"}, {"asset_id": "88794755386871079853762415286654635832909423950620116774027006364873482091563", "price": "0.902", "size": "411", "side": "SELL", "hash": "b782dd915889b46ebdcbacece0076c3ba50c92dc", "best_bid": "0.865", "best_ask": "0.877"}], "timestamp": "1769384452120", "event_type": "price_change"}}
{"_local_timestamp": "2026-01-25T23:40:52.196136+00:00", "data": {"market": "0xf2fb4784ceb4d41ce23703da426700f710320ec5b711b6e3784bdaac24d94c23", "price_changes": [{"asset_id": "73768610008619570600930429495180540710817177537162503586781057110775077618432", "price": "0.149", "size": "1598", "side": "SELL", "hash": "3bbe838a54aaa949d6cb230ed3b16634ce36e6d7", "best_bid": "0.123", "best_ask": "0.135"}, {"asset_id": "88794755386871079853762415286654635832909423950620116774027006364873482091563", "price": "0.851", "size": "1598", "side": "BUY", "hash": "c83e561a9478b5853b21e322e77781b7df65ec26", "best_bid": "0.865", "best_ask": "0.877"}], "timestamp": "1769384452131", "event_type": "price_change"}}
{"_local_timestamp": "2026-01-25T23:40:52.269628+00:00", "data": {"market": "0x281565cae359040475640be8bc20f4efe15245fe0251805fd338fb1a3e45ffae", "price_changes": [{"asset_id": "29048360022556021389805670398008888482908398853670829781367251641936311260707", "price": "0.15", "size": "0", "side": "BUY", "hash": "e2211ec67e769108d13b5f9a8687fed0261267f0", "best_bid": "0.74", "best_ask": "0.76"}, {"asset_id": "114528627098181527180076013437205839368323282497361602702800503052375432480589", "price": "0.85", "size": "0", "side": "SELL", "hash": "7a39e078b3d6ef1d580ea4c1077063b89e58796b", "best_bid": "0.24", "best_ask": "0.26"}], "timestamp": "1769384452203", "event_type": "price_change"}}
{"_local_timestamp": "2026-01-25T23:40:52.276913+00:00", "data": {"market": "0x281565cae359040475640be8bc20f4efe15245fe0251805fd338fb1a3e45ffae", "price_changes": [{"asset_id": "29048360022556021389805670398008888482908398853670829781367251641936311260707", "price": "0.49", "size": "0", "side": "BUY", "hash": "e2211ec67e769108d13b5f9a8687fed0261267f0", "best_bid": "0.74", "best_ask": "0.76"}, {"asset_id": "114528627098181527180076013437205839368323282497361602702800503052375432480589", "price": "0.51", "size": "0", "side": "SELL", "hash": "7a39e078b3d6ef1d580ea4c1077063b89e58796b", "best_bid": "0.24", "best_ask": "0.26"}], "timestamp": "1769384452203", "event_type": "price_change"}}
{"_local_timestamp": "2026-01-25T23:40:52.283578+00:00", "data": {"market": "0x281565cae359040475640be8bc20f4efe15245fe0251805fd338fb1a3e45ffae", "price_changes": [{"asset_id": "29048360022556021389805670398008888482908398853670829781367251641936311260707", "price": "0.59", "size": "805", "side": "BUY", "hash": "e2211ec67e769108d13b5f9a8687fed0261267f0", "best_bid": "0.74", "best_ask": "0.76"}, {"asset_id": "114528627098181527180076013437205839368323282497361602702800503052375432480589", "price": "0.41", "size": "805", "side": "SELL", "hash": "7a39e078b3d6ef1d580ea4c1077063b89e58796b", "best_bid": "0.24", "best_ask": "0.26"}], "timestamp": "1769384452203", "event_type": "price_change"}}
{"_local_timestamp": "2026-01-25T23:40:52.289957+00:00", "data": {"market": "0x281565cae359040475640be8bc20f4efe15245fe0251805fd338fb1a3e45ffae", "price_changes": [{"asset_id": "29048360022556021389805670398008888482908398853670829781367251641936311260707", "price": "0.62", "size": "0", "side": "BUY", "hash": "e2211ec67e769108d13b5f9a8687fed0261267f0", "best_bid": "0.74", "best_ask": "0.76"}, {"asset_id": "114528627098181527180076013437205839368323282497361602702800503052375432480589", "price": "0.38", "size": "0", "side": "SELL", "hash": "7a39e078b3d6ef1d580ea4c1077063b89e58796b", "best_bid": "0.24", "best_ask": "0.26"}], "timestamp": "1769384452203", "event_type": "price_change"}}
{"_local_timestamp": "2026-01-25T23:40:52.296167+00:00", "data": {"market": "0x281565cae359040475640be8bc20f4efe15245fe0251805fd338fb1a3e45ffae", "price_changes": [{"asset_id": "29048360022556021389805670398008888482908398853670829781367251641936311260707", "price": "0.61", "size": "600", "side": "BUY", "hash": "e2211ec67e769108d13b5f9a8687fed0261267f0", "best_bid": "0.74", "best_ask": "0.76"}, {"asset_id": "114528627098181527180076013437205839368323282497361602702800503052375432480589", "price": "0.39", "size": "600", "side": "SELL", "hash": "7a39e078b3d6ef1d580ea4c1077063b89e58796b", "best_bid": "0.24", "best_ask": "0.26"}], "timestamp": "1769384452203", "event_type": "price_change"}}
{"_local_timestamp": "2026-01-25T23:40:52.302229+00:00", "data": {"market": "0x281565cae359040475640be8bc20f4efe15245fe0251805fd338fb1a3e45ffae", "price_changes": [{"asset_id": "29048360022556021389805670398008888482908398853670829781367251641936311260707", "price": "0.54", "size": "0", "side": "BUY", "hash": "e2211ec67e769108d13b5f9a8687fed0261267f0", "best_bid": "0.74", "best_ask": "0.76"}, {"asset_id": "114528627098181527180076013437205839368323282497361602702800503052375432480589", "price": "0.46", "size": "0", "side": "SELL", "hash": "7a39e078b3d6ef1d580ea4c1077063b89e58796b", "best_bid": "0.24", "best_ask": "0.26"}], "timestamp": "1769384452203", "event_type": "price_change"}}
{"_local_timestamp": "2026-01-25T23:40:52.308100+00:00", "data": {"market": "0x281565cae359040475640be8bc20f4efe15245fe0251805fd338fb1a3e45ffae", "price_changes": [{"asset_id": "29048360022556021389805670398008888482908398853670829781367251641936311260707", "price": "0.56", "size": "0", "side": "BUY", "hash": "e2211ec67e769108d13b5f9a8687fed0261267f0", "best_bid": "0.74", "best_ask": "0.76"}, {"asset_id": "114528627098181527180076013437205839368323282497361602702800503052375432480589", "price": "0.44", "size": "0", "side": "SELL", "hash": "7a39e078b3d6ef1d580ea4c1077063b89e58796b", "best_bid": "0.24", "best_ask": "0.26"}], "timestamp": "1769384452203", "event_type": "price_change"}}
{"_local_timestamp": "2026-01-25T23:40:52.314182+00:00", "data": {"market": "0x281565cae359040475640be8bc20f4efe15245fe0251805fd338fb1a3e45ffae", "price_changes": [{"asset_id": "29048360022556021389805670398008888482908398853670829781367251641936311260707", "price": "0.53", "size": "0", "side": "BUY", "hash": "e2211ec67e769108d13b5f9a8687fed0261267f0", "best_bid": "0.74", "best_ask": "0.76"}, {"asset_id": "114528627098181527180076013437205839368323282497361602702800503052375432480589", "price": "0.47", "size": "0", "side": "SELL", "hash": "7a39e078b3d6ef1d580ea4c1077063b89e58796b", "best_bid": "0.24", "best_ask": "0.26"}], "timestamp": "1769384452203", "event_type": "price_change"}}
{"_local_timestamp": "2026-01-25T23:40:52.320178+00:00", "data": {"market": "0x281565cae359040475640be8bc20f4efe15245fe0251805fd338fb1a3e45ffae", "price_changes": [{"asset_id": "29048360022556021389805670398008888482908398853670829781367251641936311260707", "price": "0.26", "size": "0", "side": "BUY", "hash": "e2211ec67e769108d13b5f9a8687fed0261267f0", "best_bid": "0.74", "best_ask": "0.76"}, {"asset_id": "114528627098181527180076013437205839368323282497361602702800503052375432480589", "price": "0.74", "size": "0", "side": "SELL", "hash": "7a39e078b3d6ef1d580ea4c1077063b89e58796b", "best_bid": "0.24", "best_ask": "0.26"}], "timestamp": "1769384452203", "event_type": "price_change"}}
{"_local_timestamp": "2026-01-25T23:40:52.326133+00:00", "data": {"market": "0x281565cae359040475640be8bc20f4efe15245fe0251805fd338fb1a3e45ffae", "price_changes": [{"asset_id": "29048360022556021389805670398008888482908398853670829781367251641936311260707", "price": "0.57", "size": "0", "side": "BUY", "hash": "e2211ec67e769108d13b5f9a8687fed0261267f0", "best_bid": "0.74", "best_ask": "0.76"}, {"asset_id": "114528627098181527180076013437205839368323282497361602702800503052375432480589", "price": "0.43", "size": "0", "side": "SELL", "hash": "7a39e078b3d6ef1d580ea4c1077063b89e58796b", "best_bid": "0.24", "best_ask": "0.26"}], "timestamp": "1769384452203", "event_type": "price_change"}}
{"_local_timestamp": "2026-01-25T23:40:52.332071+00:00", "data": {"market": "0x281565cae359040475640be8bc20f4efe15245fe0251805fd338fb1a3e45ffae", "price_changes": [{"asset_id": "29048360022556021389805670398008888482908398853670829781367251641936311260707", "price": "0.55", "size": "94.81", "side": "BUY", "hash": "e2211ec67e769108d13b5f9a8687fed0261267f0", "best_bid": "0.74", "best_ask": "0.76"}, {"asset_id": "114528627098181527180076013437205839368323282497361602702800503052375432480589", "price": "0.45", "size": "94.81", "side": "SELL", "hash": "7a39e078b3d6ef1d580ea4c1077063b89e58796b", "best_bid": "0.24", "best_ask": "0.26"}], "timestamp": "1769384452203", "event_type": "price_change"}}
{"_local_timestamp": "2026-01-25T23:40:52.337995+00:00", "data": {"market": "0x281565cae359040475640be8bc20f4efe15245fe0251805fd338fb1a3e45ffae", "price_changes": [{"asset_id": "29048360022556021389805670398008888482908398853670829781367251641936311260707", "price": "0.51", "size": "2000", "side": "BUY", "hash": "e2211ec67e769108d13b5f9a8687fed0261267f0", "best_bid": "0.74", "best_ask": "0.76"}, {"asset_id": "114528627098181527180076013437205839368323282497361602702800503052375432480589", "price": "0.49", "size": "2000", "side": "SELL", "hash": "7a39e078b3d6ef1d580ea4c1077063b89e58796b", "best_bid": "0.24", "best_ask": "0.26"}], "timestamp": "1769384452203", "event_type": "price_change"}}
{"_local_timestamp": "2026-01-25T23:40:52.343792+00:00", "data": {"market": "0x281565cae359040475640be8bc20f4efe15245fe0251805fd338fb1a3e45ffae", "price_changes": [{"asset_id": "29048360022556021389805670398008888482908398853670829781367251641936311260707", "price": "0.5", "size": "420", "side": "BUY", "hash": "e2211ec67e769108d13b5f9a8687fed0261267f0", "best_bid": "0.74", "best_ask": "0.76"}, {"asset_id": "114528627098181527180076013437205839368323282497361602702800503052375432480589", "price": "0.5", "size": "420", "side": "SELL", "hash": "7a39e078b3d6ef1d580ea4c1077063b89e58796b", "best_bid": "0.24", "best_ask": "0.26"}], "timestamp": "1769384452203", "event_type": "price_change"}}
{"_local_timestamp": "2026-01-25T23:40:52.349692+00:00", "data": {"market": "0x281565cae359040475640be8bc20f4efe15245fe0251805fd338fb1a3e45ffae", "price_changes": [{"asset_id": "29048360022556021389805670398008888482908398853670829781367251641936311260707", "price": "0.48", "size": "0", "side": "BUY", "hash": "e2211ec67e769108d13b5f9a8687fed0261267f0", "best_bid": "0.74", "best_ask": "0.76"}, {"asset_id": "114528627098181527180076013437205839368323282497361602702800503052375432480589", "price": "0.52", "size": "0", "side": "SELL", "hash": "7a39e078b3d6ef1d580ea4c1077063b89e58796b", "best_bid": "0.24", "best_ask": "0.26"}], "timestamp": "1769384452203", "event_type": "price_change"}}
{"_local_timestamp": "2026-01-25T23:40:52.355651+00:00", "data": {"market": "0x281565cae359040475640be8bc20f4efe15245fe0251805fd338fb1a3e45ffae", "price_changes": [{"asset_id": "29048360022556021389805670398008888482908398853670829781367251641936311260707", "price": "0.27", "size": "0", "side": "BUY", "hash": "e2211ec67e769108d13b5f9a8687fed0261267f0", "best_bid": "0.74", "best_ask": "0.76"}, {"asset_id": "114528627098181527180076013437205839368323282497361602702800503052375432480589", "price": "0.73", "size": "0", "side": "SELL", "hash": "7a39e078b3d6ef1d580ea4c1077063b89e58796b", "best_bid": "0.24", "best_ask": "0.26"}], "timestamp": "1769384452203", "event_type": "price_change"}}
{"_local_timestamp": "2026-01-25T23:40:52.361599+00:00", "data": {"market": "0x281565cae359040475640be8bc20f4efe15245fe0251805fd338fb1a3e45ffae", "price_changes": [{"asset_id": "29048360022556021389805670398008888482908398853670829781367251641936311260707", "price": "0.31", "size": "0", "side": "BUY", "hash": "e2211ec67e769108d13b5f9a8687fed0261267f0", "best_bid": "0.74", "best_ask": "0.76"}, {"asset_id": "114528627098181527180076013437205839368323282497361602702800503052375432480589", "price": "0.69", "size": "0", "side": "SELL", "hash": "7a39e078b3d6ef1d580ea4c1077063b89e58796b", "best_bid": "0.24", "best_ask": "0.26"}], "timestamp": "1769384452203", "event_type": "price_change"}}
{"_local_timestamp": "2026-01-25T23:40:52.367527+00:00", "data": {"market": "0x281565cae359040475640be8bc20f4efe15245fe0251805fd338fb1a3e45ffae", "price_changes": [{"asset_id": "29048360022556021389805670398008888482908398853670829781367251641936311260707", "price": "0.29", "size": "4069", "side": "BUY", "hash": "e2211ec67e769108d13b5f9a8687fed0261267f0", "best_bid": "0.74", "best_ask": "0.76"}, {"asset_id": "114528627098181527180076013437205839368323282497361602702800503052375432480589", "price": "0.71", "size": "4069", "side": "SELL", "hash": "7a39e078b3d6ef1d580ea4c1077063b89e58796b", "best_bid": "0.24", "best_ask": "0.26"}], "timestamp": "1769384452203", "event_type": "price_change"}}
{"_local_timestamp": "2026-01-25T23:40:52.674734+00:00", "data": {"market": "0x281565cae359040475640be8bc20f4efe15245fe0251805fd338fb1a3e45ffae", "price_changes": [{"asset_id": "29048360022556021389805670398008888482908398853670829781367251641936311260707", "price": "0.17", "size": "113", "side": "BUY", "hash": "8da44795505d8c221ef69f4991fe84bc3e5275ec", "best_bid": "0.74", "best_ask": "0.76"}, {"asset_id": "114528627098181527180076013437205839368323282497361602702800503052375432480589", "price": "0.83", "size": "113", "side": "SELL", "hash": "fb8f2c7032c153f66d7268c0a395d5309bd78400", "best_bid": "0.24", "best_ask": "0.26"}], "timestamp": "1769384452593", "event_type": "price_change"}}
{"_local_timestamp": "2026-01-25T23:40:52.687212+00:00", "data": {"market": "0x281565cae359040475640be8bc20f4efe15245fe0251805fd338fb1a3e45ffae", "price_changes": [{"asset_id": "29048360022556021389805670398008888482908398853670829781367251641936311260707", "price": "0.31", "size": "233", "side": "BUY", "hash": "a014f2c77f1ed8a58ffd2496396963fec5af38a5", "best_bid": "0.74", "best_ask": "0.76"}, {"asset_id": "114528627098181527180076013437205839368323282497361602702800503052375432480589", "price": "0.69", "size": "233", "side": "SELL", "hash": "8a83f4fda19ce0f74a4691c6c55def35220d4b98", "best_bid": "0.24", "best_ask": "0.26"}], "timestamp": "1769384452594", "event_type": "price_change"}}
{"_local_timestamp": "2026-01-25T23:40:52.696936+00:00", "data": {"market": "0x281565cae359040475640be8bc20f4efe15245fe0251805fd338fb1a3e45ffae", "price_changes": [{"asset_id": "29048360022556021389805670398008888482908398853670829781367251641936311260707", "price": "0.32", "size": "12", "side": "BUY", "hash": "f8d7a9679f9b919f0106af03800ef688f2b64dc9", "best_bid": "0.74", "best_ask": "0.76"}, {"asset_id": "114528627098181527180076013437205839368323282497361602702800503052375432480589", "price": "0.68", "size": "12", "side": "SELL", "hash": "816b5e53f5404ed1da6977416aae32e714fe4600", "best_bid": "0.24", "best_ask": "0.26"}], "timestamp": "1769384452594", "event_type": "price_change"}}
{"_local_timestamp": "2026-01-25T23:40:52.712949+00:00", "data": {"market": "0x281565cae359040475640be8bc20f4efe15245fe0251805fd338fb1a3e45ffae", "price_changes": [{"asset_id": "29048360022556021389805670398008888482908398853670829781367251641936311260707", "price": "0.09", "size": "240", "side": "BUY", "hash": "c5c2278b0060eac3958a49cfb8f6d4441eaf8837", "best_bid": "0.74", "best_ask": "0.76"}, {"asset_id": "114528627098181527180076013437205839368323282497361602702800503052375432480589", "price": "0.91", "size": "240", "side": "SELL", "hash": "054cdc397206cb5b05e66e43415f115f1414ad33", "best_bid": "0.24", "best_ask": "0.26"}], "timestamp": "1769384452595", "event_type": "price_change"}}
{"_local_timestamp": "2026-01-25T23:40:52.722525+00:00", "data": {"market": "0x281565cae359040475640be8bc20f4efe15245fe0251805fd338fb1a3e45ffae", "price_changes": [{"asset_id": "29048360022556021389805670398008888482908398853670829781367251641936311260707", "price": "0.01", "size": "123150.5", "side": "BUY", "hash": "932c45c16ceea99775ed96bc06c8bcb09fa36d8f", "best_bid": "0.74", "best_ask": "0.76"}, {"asset_id": "114528627098181527180076013437205839368323282497361602702800503052375432480589", "price": "0.99", "size": "123150.5", "side": "SELL", "hash": "f5475e4d4b7d930cf6faba6ca25b115136b76815", "best_bid": "0.24", "best_ask": "0.26"}], "timestamp": "1769384452595", "event_type": "price_change"}}
{"_local_timestamp": "2026-01-25T23:40:52.730968+00:00", "data": {"market": "0x281565cae359040475640be8bc20f4efe15245fe0251805fd338fb1a3e45ffae", "price_changes": [{"asset_id": "29048360022556021389805670398008888482908398853670829781367251641936311260707", "price": "0.29", "size": "4480", "side": "BUY", "hash": "a7f2cb9df063a0f9db8e378deaaa00c66cf584c4", "best_bid": "0.74", "best_ask": "0.76"}, {"asset_id": "114528627098181527180076013437205839368323282497361602702800503052375432480589", "price": "0.71", "size": "4480", "side": "SELL", "hash": "79b925bb13ae48f877b7918c92c8260025999fe7", "best_bid": "0.24", "best_ask": "0.26"}], "timestamp": "1769384452596", "event_type": "price_change"}}
{"_local_timestamp": "2026-01-25T23:40:53.136843+00:00", "data": {"market": "0x5c5d898595b3445dd3809896302889cd512411fa8306de609d9d8aa34e257ba8", "price_changes": [{"asset_id": "31339843398803147748606287378592227516750208753666943060502579333204198045040", "price": "0.974", "size": "8357", "side": "BUY", "hash": "3885ba8b798a8af7e3262855eed9791bcc2f58a3", "best_bid": "0.999", "best_ask": "1"}, {"asset_id": "45014676111572901552217363692090679327003594688155466306257909550735876308571", "price": "0.026", "size": "8357", "side": "SELL", "hash": "9121dce7288c4d219eb2d22866957523d7c0cf06", "best_bid": "0", "best_ask": "0.001"}], "timestamp": "1769384453063", "event_type": "price_change"}}
{"_local_timestamp": "2026-01-25T23:40:53.193507+00:00", "data": {"market": "0x281565cae359040475640be8bc20f4efe15245fe0251805fd338fb1a3e45ffae", "price_changes": [{"asset_id": "29048360022556021389805670398008888482908398853670829781367251641936311260707", "price": "0.01", "size": "122242.5", "side": "BUY", "hash": "9752ec364eae0a9f380e0075c6b0fdf2e13430a3", "best_bid": "0.74", "best_ask": "0.76"}, {"asset_id": "114528627098181527180076013437205839368323282497361602702800503052375432480589", "price": "0.99", "size": "122242.5", "side": "SELL", "hash": "bad7f5bf8db9a41d527e2e7104ecc1b0917921f2", "best_bid": "0.24", "best_ask": "0.26"}], "timestamp": "1769384453124", "event_type": "price_change"}}
{"_local_timestamp": "2026-01-25T23:40:53.202685+00:00", "data": {"market": "0x281565cae359040475640be8bc20f4efe15245fe0251805fd338fb1a3e45ffae", "price_changes": [{"asset_id": "29048360022556021389805670398008888482908398853670829781367251641936311260707", "price": "0.32", "size": "0", "side": "BUY", "hash": "9752ec364eae0a9f380e0075c6b0fdf2e13430a3", "best_bid": "0.74", "best_ask": "0.76"}, {"asset_id": "114528627098181527180076013437205839368323282497361602702800503052375432480589", "price": "0.68", "size": "0", "side": "SELL", "hash": "bad7f5bf8db9a41d527e2e7104ecc1b0917921f2", "best_bid": "0.24", "best_ask": "0.26"}], "timestamp": "1769384453124", "event_type": "price_change"}}
{"_local_timestamp": "2026-01-25T23:40:53.208998+00:00", "data": {"market": "0x281565cae359040475640be8bc20f4efe15245fe0251805fd338fb1a3e45ffae", "price_changes": [{"asset_id": "29048360022556021389805670398008888482908398853670829781367251641936311260707", "price": "0.09", "size": "0", "side": "BUY", "hash": "9752ec364eae0a9f380e0075c6b0fdf2e13430a3", "best_bid": "0.74", "best_ask": "0.76"}, {"asset_id": "114528627098181527180076013437205839368323282497361602702800503052375432480589", "price": "0.91", "size": "0", "side": "SELL", "hash": "bad7f5bf8db9a41d527e2e7104ecc1b0917921f2", "best_bid": "0.24", "best_ask": "0.26"}], "timestamp": "1769384453124", "event_type": "price_change"}}
{"_local_timestamp": "2026-01-25T23:40:53.219001+00:00", "data": {"market": "0x281565cae359040475640be8bc20f4efe15245fe0251805fd338fb1a3e45ffae", "price_changes": [{"asset_id": "29048360022556021389805670398008888482908398853670829781367251641936311260707", "price": "0.17", "size": "0", "side": "BUY", "hash": "9752ec364eae0a9f380e0075c6b0fdf2e13430a3", "best_bid": "0.74", "best_ask": "0.76"}, {"asset_id": "114528627098181527180076013437205839368323282497361602702800503052375432480589", "price": "0.83", "size": "0", "side": "SELL", "hash": "bad7f5bf8db9a41d527e2e7104ecc1b0917921f2", "best_bid": "0.24", "best_ask": "0.26"}], "timestamp": "1769384453124", "event_type": "price_change"}}
{"_local_timestamp": "2026-01-25T23:40:53.231326+00:00", "data": {"market": "0x281565cae359040475640be8bc20f4efe15245fe0251805fd338fb1a3e45ffae", "price_changes": [{"asset_id": "29048360022556021389805670398008888482908398853670829781367251641936311260707", "price": "0.31", "size": "0", "side": "BUY", "hash": "9752ec364eae0a9f380e0075c6b0fdf2e13430a3", "best_bid": "0.74", "best_ask": "0.76"}, {"asset_id": "114528627098181527180076013437205839368323282497361602702800503052375432480589", "price": "0.69", "size": "0", "side": "SELL", "hash": "bad7f5bf8db9a41d527e2e7104ecc1b0917921f2", "best_bid": "0.24", "best_ask": "0.26"}], "timestamp": "1769384453124", "event_type": "price_change"}}
{"_local_timestamp": "2026-01-25T23:40:53.238337+00:00", "data": {"market": "0x281565cae359040475640be8bc20f4efe15245fe0251805fd338fb1a3e45ffae", "price_changes": [{"asset_id": "29048360022556021389805670398008888482908398853670829781367251641936311260707", "price": "0.29", "size": "4069", "side": "BUY", "hash": "9752ec364eae0a9f380e0075c6b0fdf2e13430a3", "best_bid": "0.74", "best_ask": "0.76"}, {"asset_id": "114528627098181527180076013437205839368323282497361602702800503052375432480589", "price": "0.71", "size": "4069", "side": "SELL", "hash": "bad7f5bf8db9a41d527e2e7104ecc1b0917921f2", "best_bid": "0.24", "best_ask": "0.26"}], "timestamp": "1769384453124", "event_type": "price_change"}}
{"_local_timestamp": "2026-01-25T23:40:53.254113+00:00", "data": {"market": "0xb207031da5ef9cbded418e6b5b3c5eee24a3a7b22c6ec10053cbaaa67d793796", "price_changes": [{"asset_id": "89110596788673536475065853727140488937259064164063660201050220270400840228269", "price": "0.1", "size": "135", "side": "SELL", "hash": "401e1b7ac7025bcee63790c56b5d3c4cb8d38798", "best_bid": "0.063", "best_ask": "0.064"}, {"asset_id": "101506943049053276934626391886226570064171431948041761918666910024462041911155", "price": "0.9", "size": "135", "side": "BUY", "hash": "b4cdf4c0de6eec53b46299340e63d88ff2c01a0c", "best_bid": "0.936", "best_ask": "0.937"}], "timestamp": "1769384453182", "event_type": "price_change"}}
{"_local_timestamp": "2026-01-25T23:40:53.260443+00:00", "data": {"market": "0xb207031da5ef9cbded418e6b5b3c5eee24a3a7b22c6ec10053cbaaa67d793796", "price_changes": [{"asset_id": "101506943049053276934626391886226570064171431948041761918666910024462041911155", "price": "0.9", "size": "9129", "side": "BUY", "hash": "48986e718a67eee6018849aedba9d410ba210466", "best_bid": "0.936", "best_ask": "0.937"}, {"asset_id": "89110596788673536475065853727140488937259064164063660201050220270400840228269", "price": "0.1", "size": "9129", "side": "SELL", "hash": "34dbb25ebad3d0c93038f73423725d16b1d1921d", "best_bid": "0.063", "best_ask": "0.064"}], "timestamp": "1769384453185", "event_type": "price_change"}}
{"_local_timestamp": "2026-01-25T23:40:53.272024+00:00", "data": {"market": "0xb207031da5ef9cbded418e6b5b3c5eee24a3a7b22c6ec10053cbaaa67d793796", "price_changes": [{"asset_id": "89110596788673536475065853727140488937259064164063660201050220270400840228269", "price": "0.05", "size": "893", "side": "BUY", "hash": "248886d038b265ca0d42e320ee5eea901b2701c6", "best_bid": "0.063", "best_ask": "0.064"}, {"asset_id": "101506943049053276934626391886226570064171431948041761918666910024462041911155", "price": "0.95", "size": "893", "side": "SELL", "hash": "a26992fef02ed2023c5a94a95146d6747bccad7c", "best_bid": "0.936", "best_ask": "0.937"}], "timestamp": "1769384453186", "event_type": "price_change"}}
{"_local_timestamp": "2026-01-25T23:40:53.433447+00:00", "data": {"market": "0xb207031da5ef9cbded418e6b5b3c5eee24a3a7b22c6ec10053cbaaa67d793796", "price_changes": [{"asset_id": "101506943049053276934626391886226570064171431948041761918666910024462041911155", "price": "0.763", "size": "0", "side": "BUY", "hash": "c023d2c1adb2d79780ea7b7eab612145a156c812", "best_bid": "0.936", "best_ask": "0.937"}, {"asset_id": "89110596788673536475065853727140488937259064164063660201050220270400840228269", "price": "0.237", "size": "0", "side": "SELL", "hash": "f5e6bd9644dbdc7cee239e6c9827ad04c8fcabbc", "best_bid": "0.063", "best_ask": "0.064"}], "timestamp": "1769384453363", "event_type": "price_change"}}
{"_local_timestamp": "2026-01-25T23:40:53.668507+00:00", "data": {"market": "0x281565cae359040475640be8bc20f4efe15245fe0251805fd338fb1a3e45ffae", "price_changes": [{"asset_id": "29048360022556021389805670398008888482908398853670829781367251641936311260707", "price": "0.51", "size": "2116", "side": "BUY", "hash": "db324f560c70ad28ee83436aa615fa393fcd8fb8", "best_bid": "0.74", "best_ask": "0.76"}, {"asset_id": "114528627098181527180076013437205839368323282497361602702800503052375432480589", "price": "0.49", "size": "2116", "side": "SELL", "hash": "33ec104df926257fcbb44876ecb50a63109efc39", "best_bid": "0.24", "best_ask": "0.26"}], "timestamp": "1769384453593", "event_type": "price_change"}}
{"_local_timestamp": "2026-01-25T23:40:53.677050+00:00", "data": {"market": "0x281565cae359040475640be8bc20f4efe15245fe0251805fd338fb1a3e45ffae", "price_changes": [{"asset_id": "29048360022556021389805670398008888482908398853670829781367251641936311260707", "price": "0.61", "size": "839", "side": "BUY", "hash": "d68b9071e1bf676e5e4454957cc3cfb7d813d252", "best_bid": "0.74", "best_ask": "0.76"}, {"asset_id": "114528627098181527180076013437205839368323282497361602702800503052375432480589", "price": "0.39", "size": "839", "side": "SELL", "hash": "72fb90e9cfb44be6518860f72b9c8ee75845b0a3", "best_bid": "0.24", "best_ask": "0.26"}], "timestamp": "1769384453593", "event_type": "price_change"}}
{"_local_timestamp": "2026-01-25T23:40:53.684054+00:00", "data": {"market": "0x281565cae359040475640be8bc20f4efe15245fe0251805fd338fb1a3e45ffae", "price_changes": [{"asset_id": "29048360022556021389805670398008888482908398853670829781367251641936311260707", "price": "0.54", "size": "127", "side": "BUY", "hash": "4265cd6ba9e54840fb4a383416544c255aa292ca", "best_bid": "0.74", "best_ask": "0.76"}, {"asset_id": "114528627098181527180076013437205839368323282497361602702800503052375432480589", "price": "0.46", "size": "127", "side": "SELL", "hash": "1e633ab8d41313c5c8d367f68c0d5d23c5ddde13", "best_bid": "0.24", "best_ask": "0.26"}], "timestamp": "1769384453594", "event_type": "price_change"}}
{"_local_timestamp": "2026-01-25T23:40:53.694271+00:00", "data": {"market": "0x281565cae359040475640be8bc20f4efe15245fe0251805fd338fb1a3e45ffae", "price_changes": [{"asset_id": "29048360022556021389805670398008888482908398853670829781367251641936311260707", "price": "0.49", "size": "169", "side": "BUY", "hash": "38ff3947a6037c6bdd9d42fe14ebf8e6b406200e", "best_bid": "0.74", "best_ask": "0.76"}, {"asset_id": "114528627098181527180076013437205839368323282497361602702800503052375432480589", "price": "0.51", "size": "169", "side": "SELL", "hash": "3984f9f2ebc04058a93f2f9f3fa81e3d4ad05e85", "best_bid": "0.24", "best_ask": "0.26"}], "timestamp": "1769384453594", "event_type": "price_change"}}
{"_local_timestamp": "2026-01-25T23:40:53.702162+00:00", "data": {"market": "0x281565cae359040475640be8bc20f4efe15245fe0251805fd338fb1a3e45ffae", "price_changes": [{"asset_id": "29048360022556021389805670398008888482908398853670829781367251641936311260707", "price": "0.62", "size": "6", "side": "BUY", "hash": "e7be6fa3c1d3f26c66c0beee704bd7174de1b0ae", "best_bid": "0.74", "best_ask": "0.76"}, {"asset_id": "114528627098181527180076013437205839368323282497361602702800503052375432480589", "price": "0.38", "size": "6", "side": "SELL", "hash": "6dc8f2e7cd9505e8304aa8ae2373930ac68461e6", "best_bid": "0.24", "best_ask": "0.26"}], "timestamp": "1769384453595", "event_type": "price_change"}}
{"_local_timestamp": "2026-01-25T23:40:53.714423+00:00", "data": {"market": "0x281565cae359040475640be8bc20f4efe15245fe0251805fd338fb1a3e45ffae", "price_changes": [{"asset_id": "29048360022556021389805670398008888482908398853670829781367251641936311260707", "price": "0.48", "size": "1024", "side": "BUY", "hash": "8c9a5499d161544c100dd2e8c92dc036bce073d5", "best_bid": "0.74", "best_ask": "0.76"}, {"asset_id": "114528627098181527180076013437205839368323282497361602702800503052375432480589", "price": "0.52", "size": "1024", "side": "SELL", "hash": "59441861b6daef0f85f3a9a7e568f8064bbeb11e", "best_bid": "0.24", "best_ask": "0.26"}], "timestamp": "1769384453595", "event_type": "price_change"}}
{"_local_timestamp": "2026-01-25T23:40:53.740405+00:00", "data": {"market": "0x281565cae359040475640be8bc20f4efe15245fe0251805fd338fb1a3e45ffae", "price_changes": [{"asset_id": "29048360022556021389805670398008888482908398853670829781367251641936311260707", "price": "0.57", "size": "48", "side": "BUY", "hash": "54f9129e98b3704a294d5e80c104277dc320777f", "best_bid": "0.74", "best_ask": "0.76"}, {"asset_id": "114528627098181527180076013437205839368323282497361602702800503052375432480589", "price": "0.43", "size": "48", "side": "SELL", "hash": "a988dbfca8a7c2b8918c281a9581477722ea7492", "best_bid": "0.24", "best_ask": "0.26"}], "timestamp": "1769384453596", "event_type": "price_change"}}
{"_local_timestamp": "2026-01-25T23:40:53.746958+00:00", "data": {"market": "0x281565cae359040475640be8bc20f4efe15245fe0251805fd338fb1a3e45ffae", "price_changes": [{"asset_id": "29048360022556021389805670398008888482908398853670829781367251641936311260707", "price": "0.27", "size": "644", "side": "BUY", "hash": "0afaebe205afad24ec1df845b736945bf8d5d154", "best_bid": "0.74", "best_ask": "0.76"}, {"asset_id": "114528627098181527180076013437205839368323282497361602702800503052375432480589", "price": "0.73", "size": "644", "side": "SELL", "hash": "27ec965220e3f21abd81ddc354f09f87783b2468", "best_bid": "0.24", "best_ask": "0.26"}], "timestamp": "1769384453596", "event_type": "price_change"}}
{"_local_timestamp": "2026-01-25T23:40:53.753208+00:00", "data": {"market": "0x281565cae359040475640be8bc20f4efe15245fe0251805fd338fb1a3e45ffae", "price_changes": [{"asset_id": "29048360022556021389805670398008888482908398853670829781367251641936311260707", "price": "0.56", "size": "46", "side": "BUY", "hash": "f1db231cc887c693a94123834e1247f5aeddb23f", "best_bid": "0.74", "best_ask": "0.76"}, {"asset_id": "114528627098181527180076013437205839368323282497361602702800503052375432480589", "price": "0.44", "size": "46", "side": "SELL", "hash": "520aa16731f830fab444ff34663c0723367742ed", "best_bid": "0.24", "best_ask": "0.26"}], "timestamp": "1769384453597", "event_type": "price_change"}}
{"_local_timestamp": "2026-01-25T23:40:53.760230+00:00", "data": {"market": "0x281565cae359040475640be8bc20f4efe15245fe0251805fd338fb1a3e45ffae", "price_changes": [{"asset_id": "29048360022556021389805670398008888482908398853670829781367251641936311260707", "price": "0.15", "size": "29", "side": "BUY", "hash": "68adec63c68b8d3621eb93548ba851908a3306e1", "best_bid": "0.74", "best_ask": "0.76"}, {"asset_id": "114528627098181527180076013437205839368323282497361602702800503052375432480589", "price": "0.85", "size": "29", "side": "SELL", "hash": "698290458a160679d755c4863fc088946d849b2c", "best_bid": "0.24", "best_ask": "0.26"}], "timestamp": "1769384453598", "event_type": "price_change"}}
{"_local_timestamp": "2026-01-25T23:40:53.769542+00:00", "data": {"market": "0x281565cae359040475640be8bc20f4efe15245fe0251805fd338fb1a3e45ffae", "price_changes": [{"asset_id": "29048360022556021389805670398008888482908398853670829781367251641936311260707", "price": "0.55", "size": "980.81", "side": "BUY", "hash": "de895f2bb952f09ea54bd5c13608d7ca5ef62224", "best_bid": "0.74", "best_ask": "0.76"}, {"asset_id": "114528627098181527180076013437205839368323282497361602702800503052375432480589", "price": "0.45", "size": "980.81", "side": "SELL", "hash": "a9287ac798e7c5f5957a8e024f3e80b282d2b0df", "best_bid": "0.24", "best_ask": "0.26"}], "timestamp": "1769384453598", "event_type": "price_change"}}
{"_local_timestamp": "2026-01-25T23:40:53.777490+00:00", "data": {"market": "0x281565cae359040475640be8bc20f4efe15245fe0251805fd338fb1a3e45ffae", "price_changes": [{"asset_id": "29048360022556021389805670398008888482908398853670829781367251641936311260707", "price": "0.53", "size": "12", "side": "BUY", "hash": "9c23865613b036d321aa9739f50515fd180b8f91", "best_bid": "0.74", "best_ask": "0.76"}, {"asset_id": "114528627098181527180076013437205839368323282497361602702800503052375432480589", "price": "0.47", "size": "12", "side": "SELL", "hash": "83738cdcfa22c95cd8abfd33373ed68826989b21", "best_bid": "0.24", "best_ask": "0.26"}], "timestamp": "1769384453599", "event_type": "price_change"}}
