{"_local_timestamp": "2026-01-25T23:40:30.313876+00:00", "data": [{"market": "0x9954b4eef49a268b810bc260ee9278361e29a8f6f4ad816a804dd613ef73a968", "asset_id": "407336258606092316833789781486672854343361331985279263948001098476429338355", "timestamp": "1769384424995", "hash": "9e3058c99ac8ed83edce59bad9d40c55950c903b", "bids": [{"price": "0.001", "size": "6103873.16"}, {"price": "0.002", "size": "250"}, {"price": "0.003", "size": "406.73"}, {"price": "0.006", "size": "200"}, {"price": "0.007", "size": "10.61"}, {"price": "0.01", "size": "1210"}, {"price": "0.02", "size": "2002400"}, {"price": "0.021", "size": "500000"}, {"price": "0.022", "size": "6.15"}, {"price": "0.05", "size": "1230"}, {"price": "0.051", "size": "39"}, {"price": "0.052", "size": "10.2"}, {"price": "0.08", "size": "900"}, {"price": "0.11", "size": "200"}, {"price": "0.179", "size": "20200"}, {"price": "0.181", "size": "14444"}, {"price": "0.182", "size": "250"}, {"price": "0.183", "size": "4122"}, {"price": "0.184", "size": "6.68"}, {"price": "0.577", "size": "5"}, {"price": "0.579", "size": "400"}, {"price": "0.796", "size": "20"}, {"price": "0.797", "size": "20"}, {"price": "0.816", "size": "30"}, {"price": "0.84", "size": "100"}, {"price": "0.848", "size": "79.36"}], "asks": [{"price": "0.999", "size": "29672"}, {"price": "0.998", "size": "7.35"}, {"price": "0.99", "size": "110"}, {"price": "0.989", "size": "10.78"}, {"price": "0.98", "size": "100"}, {"price": "0.974", "size": "2000"}, {"price": "0.97", "size": "100"}, {"price": "0.96", "size": "50"}, {"price": "0.95", "size": "912.65"}, {"price": "0.946", "size": "151.75"}, {"price": "0.942", "size": "2000"}, {"price": "0.94", "size": "520"}, {"price": "0.939", "size": "513.1"}, {"price": "0.938", "size": "125"}, {"price": "0.887", "size": "8.84"}, {"price": "0.881", "size": "13.37"}], "event_type": "book", "last_trade_price": "0.881"}, {"market": "0x1c60f9adb1d786b6fe78d63fd9f82dbb293fa06241532fb5ba43f8d8411cde1e", "asset_id": "5252381880374485440665230178984721306055940128786215274896991682225319468348", "timestamp": "1769384428590", "hash": "b26d650adccdaaa8ac25ee829d6fb27b56de2a53", "bids": [{"price": "0.01", "size": "200110"}, {"price": "0.02", "size": "11211"}, {"price": "0.03", "size": "100"}, {"price": "0.04", "size": "300"}, {"price": "0.05", "size": "100"}, {"price": "0.13", "size": "200"}, {"price": "0.14", "size": "100"}, {"price": "0.15", "size": "100"}, {"price": "0.16", "size": "2100"}, {"price": "0.17", "size": "200"}, {"price": "0.18", "size": "1859.89"}], "asks": [{"price": "0.99", "size": "1002274.97"}, {"price": "0.98", "size": "802400"}, {"price": "0.97", "size": "500700"}, {"price": "0.96", "size": "255.74"}, {"price": "0.95", "size": "30"}, {"price": "0.94", "size": "800"}, {"price": "0.92", "size": "100"}, {"price": "0.91", "size": "5.15"}, {"price": "0.89", "size": "900"}, {"price": "0.86", "size": "50"}, {"price": "0.8", "size": "400"}, {"price": "0.79", "size": "5.5"}, {"price": "0.73", "size": "200"}, {"price": "0.64", "size": "6000"}, {"price": "0.63", "size": "3029"}, {"price": "0.62", "size": "7877"}, {"price": "0.61", "size": "5"}, {"price": "0.5", "size": "10"}, {"price": "0.49", "size": "20"}, {"price": "0.31", "size": "100"}, {"price": "0.3", "size": "100"}, {"price": "0.29", "size": "100"}, {"price": "0.27", "size": "20"}, {"price": "0.22", "size": "2000"}, {"price": "0.21", "size": "637"}, {"price": "0.2", "size": "73.48"}], "event_type": "book", "last_trade_price": "0.180"}, {"market": "0x00a9dd3c3174468e2cee6ffa418dbf9b7e95c09788c281f608e496b9fef7b895", "asset_id": "79336858132239037705158300268603413459637933572725439146100963281670148171735", "timestamp": "1769384408216", "hash": "2131d64436d4b972db6171f8e47215ebf1d28809", "bids": [{"price": "0.001", "size": "30676"}, {"price": "0.002", "size": "250"}, {"price": "0.008", "size": "1700"}, {"price": "0.009", "size": "124.99"}, {"price": "0.013", "size": "423.07"}, {"price": "0.015", "size": "366.66"}], "asks": [{"price": "0.999", "size": "11002803"}, {"price": "0.998", "size": "250"}, {"price": "0.997", "size": "406.63"}, {"price": "0.994", "size": "200"}, {"price": "0.993", "size": "10.45"}, {"price": "0.99", "size": "2002310"}, {"price": "0.98", "size": "902400"}, {"price": "0.979", "size": "500000"}, {"price": "0.978", "size": "12.16"}, {"price": "0.95", "size": "30"}, {"price": "0.949", "size": "39"}, {"price": "0.94", "size": "1500"}, {"price": "0.92", "size": "100"}, {"price": "0.919", "size": "5.62"}, {"price": "0.89", "size": "900"}, {"price": "0.822", "size": "20200"}, {"price": "0.82", "size": "12395"}, {"price": "0.8", "size": "200"}, {"price": "0.799", "size": "5.83"}, {"price": "0.696", "size": "250"}, {"price": "0.695", "size": "6419"}, {"price": "0.66", "size": "100"}, {"price": "0.33", "size": "500"}, {"price": "0.269", "size": "2000"}, {"price": "0.268", "size": "273"}, {"price": "0.267", "size": "400"}, {"price": "0.148", "size": "10"}, {"price": "0.146", "size": "20"}, {"price": "0.145", "size": "20"}, {"price": "0.045", "size": "8.66"}, {"price": "0.044", "size": "8"}, {"price": "0.043", "size": "13"}, {"price": "0.022", "size": "536.99"}, {"price": "0.016", "size": "1806.86"}], "event_type": "book", "last_trade_price": "0.016"}, {"market": "0x32a07fd7094020a30410fce27454c130af242cc6cfefa2f5e90ee41a6589e293", "asset_id": "89424984881398254282556793620001573263091602619032305500254820107144922379129", "timestamp": "1769384385020", "hash": "8fb7d09b935854c4050168d3e412266bf053ea93", "bids": [{"price": "0.001", "size": "11002807.99"}, {"price": "0.002", "size": "250"}, {"price": "0.003", "size": "400"}, {"price": "0.004", "size": "8.65"}, {"price": "0.006", "size": "200"}, {"price": "0.01", "size": "2002410"}, {"price": "0.011", "size": "5.29"}, {"price": "0.02", "size": "1002400"}, {"price": "0.021", "size": "500000"}, {"price": "0.022", "size": "250"}, {"price": "0.023", "size": "11.42"}, {"price": "0.05", "size": "30"}, {"price": "0.051", "size": "39"}, {"price": "0.06", "size": "1500"}, {"price": "0.08", "size": "100"}, {"price": "0.081", "size": "5.62"}, {"price": "0.11", "size": "900"}, {"price": "0.14", "size": "50"}, {"price": "0.2", "size": "400"}, {"price": "0.201", "size": "5.83"}, {"price": "0.27", "size": "200"}, {"price": "0.34", "size": "100"}, {"price": "0.566", "size": "9000"}, {"price": "0.567", "size": "4205"}, {"price": "0.6", "size": "100"}, {"price": "0.751", "size": "266"}, {"price": "0.797", "size": "20"}, {"price": "0.799", "size": "10"}, {"price": "0.8", "size": "20"}, {"price": "0.951", "size": "10"}, {"price": "0.971", "size": "13.33"}, {"price": "0.976", "size": "439.52"}, {"price": "0.995", "size": "3627.89"}, {"price": "0.996", "size": "8.66"}, {"price": "0.997", "size": "1055.24"}], "asks": [{"price": "0.999", "size": "7346.76"}], "event_type": "book", "last_trade_price": ""}, {"market": "0x1672bfe7ef6d85a4ecffa9faf1149ef1a1661dd919598ab46b04a6ae0a4ffab4", "asset_id": "47611238256675927046254833225025176882857384948614440601874808834644661735134", "timestamp": "1769384408216", "hash": "1dbd563cd61ae7f443c9df90be5f884b3f4503cd", "bids": [{"price": "0.001", "size": "5514.76"}], "asks": [{"price": "0.999", "size": "11005503"}, {"price": "0.998", "size": "2000250"}, {"price": "0.997", "size": "406.63"}, {"price": "0.994", "size": "200"}, {"price": "0.993", "size": "10.58"}, {"price": "0.99", "size": "1010"}, {"price": "0.98", "size": "1002400"}, {"price": "0.979", "size": "800000"}, {"price": "0.978", "size": "6.36"}, {"price": "0.96", "size": "2700"}, {"price": "0.95", "size": "630"}, {"price": "0.949", "size": "39"}, {"price": "0.948", "size": "7.09"}, {"price": "0.92", "size": "700"}, {"price": "0.86", "size": "750"}, {"price": "0.859", "size": "9.84"}, {"price": "0.777", "size": "154"}, {"price": "0.773", "size": "20200"}, {"price": "0.698", "size": "250"}, {"price": "0.697", "size": "8050"}, {"price": "0.66", "size": "100"}, {"price": "0.659", "size": "5"}, {"price": "0.477", "size": "170"}, {"price": "0.277", "size": "173"}, {"price": "0.275", "size": "275"}, {"price": "0.177", "size": "195"}, {"price": "0.176", "size": "20"}, {"price": "0.077", "size": "764"}, {"price": "0.076", "size": "10"}, {"price": "0.075", "size": "20"}, {"price": "0.005", "size": "644.17"}, {"price": "0.003", "size": "19.7"}, {"price": "0.002", "size": "2808.75"}], "event_type": "book", "last_trade_price": "0.001"}, {"market": "0xd6203f8805d1812e3b189da3f6036989940a415ae3a0fecf83555b455394fdb8", "asset_id": "605623486066352556192926094200873695162641786747341465075860641086561702714", "timestamp": "1769384383590", "hash": "88d19e7b0bc63062d35ba1c47a44ce4e6e842e9e", "bids": [{"price": "0.001", "size": "11002792.04"}, {"price": "0.002", "size": "255.05"}, {"price": "0.003", "size": "400"}, {"price": "0.004", "size": "8.76"}, {"price": "0.006", "size": "200"}, {"price": "0.01", "size": "2002410"}, {"price": "0.011", "size": "5.35"}, {"price": "0.02", "size": "1002400"}, {"price": "0.021", "size": "500000"}, {"price": "0.022", "size": "6841"}, {"price": "0.023", "size": "8.49"}, {"price": "0.05", "size": "30"}, {"price": "0.051", "size": "39"}, {"price": "0.064", "size": "1400"}, {"price": "0.065", "size": "7.1"}, {"price": "0.11", "size": "900"}, {"price": "0.18", "size": "20200"}, {"price": "0.181", "size": "11111"}, {"price": "0.182", "size": "6.78"}, {"price": "0.234", "size": "650"}, {"price": "0.235", "size": "8"}, {"price": "0.75", "size": "155.55"}, {"price": "0.795", "size": "20"}, {"price": "0.797", "size": "10"}, {"price": "0.798", "size": "20"}, {"price": "0.916", "size": "16.7"}, {"price": "0.938", "size": "17.6"}, {"price": "0.941", "size": "8"}, {"price": "0.944", "size": "13"}, {"price": "0.957", "size": "84.84"}, {"price": "0.965", "size": "20"}], "asks": [{"price": "0.999", "size": "29651"}, {"price": "0.998", "size": "9679.78"}, {"price": "0.997", "size": "250"}, {"price": "0.996", "size": "26.53"}, {"price": "0.99", "size": "110"}, {"price": "0.985", "size": "100"}, {"price": "0.983", "size": "10100"}, {"price": "0.981", "size": "2000"}, {"price": "0.98", "size": "100"}, {"price": "0.979", "size": "714.28"}, {"price": "0.978", "size": "814.28"}, {"price": "0.977", "size": "714.28"}, {"price": "0.976", "size": "2714.28"}, {"price": "0.975", "size": "550"}, {"price": "0.972", "size": "34.75"}], "event_type": "book", "last_trade_price": "0.028"}, {"market": "0x85f3e001ffe2a24f985b939460d0cc22041d47107ed8c681f75abb6a5bd1d1d7", "asset_id": "26510384225806040730267502985578081313836463589753281281933174278980674429194", "timestamp": "1769384425291", "hash": "d125e69e3ae3722e8c986e7ec81daa656f394eba", "bids": [{"price": "0.01", "size": "50010"}, {"price": "0.02", "size": "11111"}, {"price": "0.03", "size": "350"}, {"price": "0.04", "size": "50"}, {"price": "0.05", "size": "100"}, {"price": "0.06", "size": "20"}, {"price": "0.07", "size": "1040"}, {"price": "0.09", "size": "424.84"}, {"price": "0.1", "size": "7.08"}], "asks": [{"price": "0.99", "size": "3102224.71"}, {"price": "0.98", "size": "902400"}, {"price": "0.97", "size": "500700"}, {"price": "0.96", "size": "5.65"}, {"price": "0.95", "size": "640"}, {"price": "0.94", "size": "33"}, {"price": "0.92", "size": "700"}, {"price": "0.91", "size": "5.08"}, {"price": "0.86", "size": "750"}, {"price": "0.8", "size": "200"}, {"price": "0.79", "size": "5.56"}, {"price": "0.73", "size": "9200"}, {"price": "0.63", "size": "20211"}, {"price": "0.6", "size": "250"}, {"price": "0.59", "size": "3380"}, {"price": "0.54", "size": "10"}, {"price": "0.53", "size": "20"}, {"price": "0.2", "size": "499.99"}, {"price": "0.19", "size": "20"}, {"price": "0.15", "size": "2000"}, {"price": "0.14", "size": "1798.36"}, {"price": "0.13", "size": "547.37"}, {"price": "0.12", "size": "147.8"}], "event_type": "book", "last_trade_price": "0.100"}, {"market": "0x3d2a697437b1093ad06d6a74c6fb5a2a499b15d7e895500b5153f66bfaa0e602", "asset_id": "29378510610351498292793924336050369056882113454472455899117956728534280393801", "timestamp": "1769384381455", "hash": "52e8e84c0e3737946472922a4096436dc6aa28f3", "bids": [{"price": "0.001", "size": "26854.99"}, {"price": "0.002", "size": "316.66"}, {"price": "0.01", "size": "530.3"}, {"price": "0.012", "size": "2066.9"}, {"price": "0.013", "size": "100"}, {"price": "0.014", "size": "599.16"}, {"price": "0.015", "size": "132"}], "asks": [{"price": "0.999", "size": "6004088.97"}, {"price": "0.998", "size": "250"}, {"price": "0.997", "size": "172.66"}, {"price": "0.994", "size": "83"}, {"price": "0.993", "size": "10.5"}, {"price": "0.99", "size": "1000"}, {"price": "0.98", "size": "901000"}, {"price": "0.979", "size": "901400"}, {"price": "0.978", "size": "12.2"}, {"price": "0.95", "size": "30"}, {"price": "0.949", "size": "39"}, {"price": "0.939", "size": "4500"}, {"price": "0.938", "size": "250"}, {"price": "0.92", "size": "100"}, {"price": "0.919", "size": "5.64"}, {"price": "0.89", "size": "900"}, {"price": "0.86", "size": "50"}, {"price": "0.8", "size": "400"}, {"price": "0.799", "size": "5.82"}, {"price": "0.73", "size": "200"}, {"price": "0.66", "size": "100"}, {"price": "0.42", "size": "2222"}, {"price": "0.401", "size": "3170"}, {"price": "0.4", "size": "333"}, {"price": "0.137", "size": "20"}, {"price": "0.135", "size": "10"}, {"price": "0.134", "size": "20"}, {"price": "0.043", "size": "13.33"}, {"price": "0.034", "size": "2000"}, {"price": "0.033", "size": "258"}, {"price": "0.026", "size": "2000"}, {"price": "0.019", "size": "1350"}], "event_type": "book", "last_trade_price": ""}, {"market": "0x8b89ea6de714f69d3418f77614b1dd5f9204443d8bc8fca1cb3d4b5cb7d0a1f5", "asset_id": "91288830864405819371669895951357549933848133831456873504828139312461957559857", "timestamp": "1769384383182", "hash": "2afccae0c020bd0e1d2057f0a0b537ab3491e3f6", "bids": [{"price": "0.001", "size": "5500"}], "asks": [{"price": "0.999", "size": "11002807.99"}, {"price": "0.998", "size": "250"}, {"price": "0.997", "size": "400"}, {"price": "0.996", "size": "8.65"}, {"price": "0.994", "size": "200"}, {"price": "0.99", "size": "2002410"}, {"price": "0.989", "size": "5.73"}, {"price": "0.98", "size": "1002400"}, {"price": "0.979", "size": "830000"}, {"price": "0.977", "size": "100"}, {"price": "0.976", "size": "10.74"}, {"price": "0.95", "size": "30"}, {"price": "0.949", "size": "39"}, {"price": "0.94", "size": "1500"}, {"price": "0.92", "size": "100"}, {"price": "0.919", "size": "5.62"}, {"price": "0.89", "size": "900"}, {"price": "0.86", "size": "50"}, {"price": "0.8", "size": "400"}, {"price": "0.799", "size": "5.84"}, {"price": "0.777", "size": "164"}, {"price": "0.73", "size": "200"}, {"price": "0.66", "size": "100"}, {"price": "0.477", "size": "161"}, {"price": "0.277", "size": "172"}, {"price": "0.259", "size": "2000"}, {"price": "0.258", "size": "3242"}, {"price": "0.241", "size": "263"}, {"price": "0.177", "size": "196"}, {"price": "0.162", "size": "10"}, {"price": "0.161", "size": "20"}, {"price": "0.077", "size": "352"}, {"price": "0.067", "size": "174.44"}, {"price": "0.049", "size": "5"}, {"price": "0.048", "size": "20"}, {"price": "0.007", "size": "1071.18"}, {"price": "0.006", "size": "2000"}, {"price": "0.004", "size": "162.15"}, {"price": "0.003", "size": "643.69"}, {"price": "0.002", "size": "4491.85"}], "event_type": "book", "last_trade_price": ""}, {"market": "0x1c60f9adb1d786b6fe78d63fd9f82dbb293fa06241532fb5ba43f8d8411cde1e", "asset_id": "76633639806751295595699993448608387906622374020066717378577586177644656154703", "timestamp": "1769384428590", "hash": "8f1958b1dcdbb2b6a9b5a5019e4ffbdebd1142b0", "bids": [{"price": "0.01", "size": "1002274.97"}, {"price": "0.02", "size": "802400"}, {"price": "0.03", "size": "500700"}, {"price": "0.04", "size": "255.74"}, {"price": "0.05", "size": "30"}, {"price": "0.06", "size": "800"}, {"price": "0.08", "size": "100"}, {"price": "0.09", "size": "5.15"}, {"price": "0.11", "size": "900"}, {"price": "0.14", "size": "50"}, {"price": "0.2", "size": "400"}, {"price": "0.21", "size": "5.5"}, {"price": "0.27", "size": "200"}, {"price": "0.36", "size": "6000"}, {"price": "0.37", "size": "3029"}, {"price": "0.38", "size": "7877"}, {"price": "0.39", "size": "5"}, {"price": "0.5", "size": "10"}, {"price": "0.51", "size": "20"}, {"price": "0.69", "size": "100"}, {"price": "0.7", "size": "100"}, {"price": "0.71", "size": "100"}, {"price": "0.73", "size": "20"}, {"price": "0.78", "size": "2000"}, {"price": "0.79", "size": "637"}, {"price": "0.8", "size": "73.48"}], "asks": [{"price": "0.99", "size": "200110"}, {"price": "0.98", "size": "11211"}, {"price": "0.97", "size": "100"}, {"price": "0.96", "size": "300"}, {"price": "0.95", "size": "100"}, {"price": "0.87", "size": "200"}, {"price": "0.86", "size": "100"}, {"price": "0.85", "size": "100"}, {"price": "0.84", "size": "2100"}, {"price": "0.83", "size": "200"}, {"price": "0.82", "size": "1859.89"}], "event_type": "book", "last_trade_price": "0.180"}, {"market": "0x9954b4eef49a268b810bc260ee9278361e29a8f6f4ad816a804dd613ef73a968", "asset_id": "50692628443801018513325614545746863026982626993302787461752145605052144027838", "timestamp": "1769384424995", "hash": "3c567dab129384815d7792b289d1f347a315142d", "bids": [{"price": "0.001", "size": "29672"}, {"price": "0.002", "size": "7.35"}, {"price": "0.01", "size": "110"}, {"price": "0.011", "size": "10.78"}, {"price": "0.02", "size": "100"}, {"price": "0.026", "size": "2000"}, {"price": "0.03", "size": "100"}, {"price": "0.04", "size": "50"}, {"price": "0.05", "size": "912.65"}, {"price": "0.054", "size": "151.75"}, {"price": "0.058", "size": "2000"}, {"price": "0.06", "size": "520"}, {"price": "0.061", "size": "513.1"}, {"price": "0.062", "size": "125"}, {"price": "0.113", "size": "8.84"}, {"price": "0.119", "size": "13.37"}], "asks": [{"price": "0.999", "size": "6103873.16"}, {"price": "0.998", "size": "250"}, {"price": "0.997", "size": "406.73"}, {"price": "0.994", "size": "200"}, {"price": "0.993", "size": "10.61"}, {"price": "0.99", "size": "1210"}, {"price": "0.98", "size": "2002400"}, {"price": "0.979", "size": "500000"}, {"price": "0.978", "size": "6.15"}, {"price": "0.95", "size": "1230"}, {"price": "0.949", "size": "39"}, {"price": "0.948", "size": "10.2"}, {"price": "0.92", "size": "900"}, {"price": "0.89", "size": "200"}, {"price": "0.821", "size": "20200"}, {"price": "0.819", "size": "14444"}, {"price": "0.818", "size": "250"}, {"price": "0.817", "size": "4122"}, {"price": "0.816", "size": "6.68"}, {"price": "0.423", "size": "5"}, {"price": "0.421", "size": "400"}, {"price": "0.204", "size": "20"}, {"price": "0.203", "size": "20"}, {"price": "0.184", "size": "30"}, {"price": "0.16", "size": "100"}, {"price": "0.152", "size": "79.36"}], "event_type": "book", "last_trade_price": "0.881"}, {"market": "0x00ca3a4205ea548274f06891fd4b703160675842dd0120279ef5a40f1ddcfdaa", "asset_id": "13909020251670713171595533995503592798947815255807698496259636962541337133650", "timestamp": "1769384401124", "hash": "d065c510e6336a016ec4bea240d2ed8bf8ed443b", "bids": [{"price": "0.001", "size": "11002801.99"}, {"price": "0.002", "size": "250"}, {"price": "0.003", "size": "400"}, {"price": "0.004", "size": "8.65"}, {"price": "0.006", "size": "200"}, {"price": "0.01", "size": "2002310"}, {"price": "0.011", "size": "5.73"}, {"price": "0.02", "size": "1002500"}, {"price": "0.021", "size": "500000"}, {"price": "0.023", "size": "100"}, {"price": "0.024", "size": "10.74"}, {"price": "0.05", "size": "70"}, {"price": "0.051", "size": "39"}, {"price": "0.06", "size": "1500"}, {"price": "0.08", "size": "100"}, {"price": "0.081", "size": "5.62"}, {"price": "0.1", "size": "20"}, {"price": "0.11", "size": "900"}, {"price": "0.14", "size": "50"}, {"price": "0.2", "size": "410"}, {"price": "0.201", "size": "5.83"}, {"price": "0.27", "size": "200"}, {"price": "0.34", "size": "100"}, {"price": "0.471", "size": "6000"}, {"price": "0.472", "size": "4049"}, {"price": "0.631", "size": "316"}, {"price": "0.729", "size": "410"}, {"price": "0.733", "size": "20"}, {"price": "0.734", "size": "20"}, {"price": "0.951", "size": "10"}, {"price": "0.967", "size": "13.33"}, {"price": "0.986", "size": "435.16"}, {"price": "0.987", "size": "5.03"}, {"price": "0.989", "size": "2000"}, {"price": "0.99", "size": "28.55"}], "asks": [{"price": "0.999", "size": "6721"}, {"price": "0.998", "size": "2500"}, {"price": "0.997", "size": "3120"}, {"price": "0.995", "size": "293"}], "event_type": "book", "last_trade_price": "0.006"}, {"market": "0xa3186ffc28c45f336920279d5085529d530690a1623997819f3a3db05119dbaa", "asset_id": "100637244310881573755436157770787626078576925658681383187976739528804051076924", "timestamp": "1769384425452", "hash": "f1e95f3b4496accb015eb35200a99399e4160e05", "bids": [{"price": "0.001", "size": "11004498.22"}, {"price": "0.002", "size": "255.2"}, {"price": "0.003", "size": "400"}, {"price": "0.004", "size": "9.03"}, {"price": "0.006", "size": "200"}, {"price": "0.01", "size": "1010"}, {"price": "0.011", "size": "5.06"}, {"price": "0.02", "size": "1002400"}, {"price": "0.021", "size": "500000"}, {"price": "0.022", "size": "12.66"}, {"price": "0.068", "size": "1500"}, {"price": "0.08", "size": "100"}, {"price": "0.081", "size": "5.84"}, {"price": "0.11", "size": "900"}, {"price": "0.18", "size": "15200"}, {"price": "0.182", "size": "11161"}, {"price": "0.2", "size": "200"}, {"price": "0.201", "size": "5.67"}, {"price": "0.27", "size": "200"}, {"price": "0.36", "size": "300"}, {"price": "0.361", "size": "3212"}, {"price": "0.362", "size": "405"}, {"price": "0.376", "size": "10"}, {"price": "0.377", "size": "20"}, {"price": "0.69", "size": "9.38"}, {"price": "0.691", "size": "20"}, {"price": "0.741", "size": "45.63"}, {"price": "0.75", "size": "1000"}, {"price": "0.751", "size": "13"}, {"price": "0.765", "size": "113.54"}, {"price": "0.775", "size": "55"}, {"price": "0.776", "size": "245"}, {"price": "0.777", "size": "15"}], "asks": [{"price": "0.999", "size": "38545"}, {"price": "0.998", "size": "916"}, {"price": "0.997", "size": "6.13"}, {"price": "0.99", "size": "30410"}, {"price": "0.988", "size": "1000"}, {"price": "0.987", "size": "11211"}, {"price": "0.986", "size": "150"}, {"price": "0.98", "size": "194"}, {"price": "0.979", "size": "5.47"}, {"price": "0.97", "size": "100"}, {"price": "0.95", "size": "100"}, {"price": "0.93", "size": "40"}, {"price": "0.9", "size": "100"}, {"price": "0.875", "size": "200"}, {"price": "0.87", "size": "30"}, {"price": "0.85", "size": "100"}, {"price": "0.83", "size": "20"}, {"price": "0.81", "size": "20"}, {"price": "0.805", "size": "19585.39"}, {"price": "0.787", "size": "2000"}, {"price": "0.786", "size": "2000"}, {"price": "0.785", "size": "9946.21"}, {"price": "0.783", "size": "85.1"}, {"price": "0.782", "size": "85.1"}, {"price": "0.781", "size": "85.1"}, {"price": "0.78", "size": "546.59"}, {"price": "0.779", "size": "36"}], "event_type": "book", "last_trade_price": "0.221"}, {"market": "0x00a9dd3c3174468e2cee6ffa418dbf9b7e95c09788c281f608e496b9fef7b895", "asset_id": "52843058974175583048395589011180975724373233294387599507798784190922550307232", "timestamp": "1769384408216", "hash": "72ed7e767da5fde3fee7a2229a0daaebc91fb593", "bids": [{"price": "0.001", "size": "11002803"}, {"price": "0.002", "size": "250"}, {"price": "0.003", "size": "406.63"}, {"price": "0.006", "size": "200"}, {"price": "0.007", "size": "10.45"}, {"price": "0.01", "size": "2002310"}, {"price": "0.02", "size": "902400"}, {"price": "0.021", "size": "500000"}, {"price": "0.022", "size": "12.16"}, {"price": "0.05", "size": "30"}, {"price": "0.051", "size": "39"}, {"price": "0.06", "size": "1500"}, {"price": "0.08", "size": "100"}, {"price": "0.081", "size": "5.62"}, {"price": "0.11", "size": "900"}, {"price": "0.178", "size": "20200"}, {"price": "0.18", "size": "12395"}, {"price": "0.2", "size": "200"}, {"price": "0.201", "size": "5.83"}, {"price": "0.304", "size": "250"}, {"price": "0.305", "size": "6419"}, {"price": "0.34", "size": "100"}, {"price": "0.67", "size": "500"}, {"price": "0.731", "size": "2000"}, {"price": "0.732", "size": "273"}, {"price": "0.733", "size": "400"}, {"price": "0.852", "size": "10"}, {"price": "0.854", "size": "20"}, {"price": "0.855", "size": "20"}, {"price": "0.955", "size": "8.66"}, {"price": "0.956", "size": "8"}, {"price": "0.957", "size": "13"}, {"price": "0.978", "size": "536.99"}, {"price": "0.984", "size": "1806.86"}], "asks": [{"price": "0.999", "size": "30676"}, {"price": "0.998", "size": "250"}, {"price": "0.992", "size": "1700"}, {"price": "0.991", "size": "124.99"}, {"price": "0.987", "size": "423.07"}, {"price": "0.985", "size": "366.66"}], "event_type": "book", "last_trade_price": "0.016"}, {"market": "0x1672bfe7ef6d85a4ecffa9faf1149ef1a1661dd919598ab46b04a6ae0a4ffab4", "asset_id": "67406170302156428995276860611642329904770865734970239500712482048975306249694", "timestamp": "1769384408216", "hash": "d895c17be13957405d059ac0caa8aa1a5e3b5030", "bids": [{"price": "0.001", "size": "11005503"}, {"price": "0.002", "size": "2000250"}, {"price": "0.003", "size": "406.63"}, {"price": "0.006", "size": "200"}, {"price": "0.007", "size": "10.58"}, {"price": "0.01", "size": "1010"}, {"price": "0.02", "size": "1002400"}, {"price": "0.021", "size": "800000"}, {"price": "0.022", "size": "6.36"}, {"price": "0.04", "size": "2700"}, {"price": "0.05", "size": "630"}, {"price": "0.051", "size": "39"}, {"price": "0.052", "size": "7.09"}, {"price": "0.08", "size": "700"}, {"price": "0.14", "size": "750"}, {"price": "0.141", "size": "9.84"}, {"price": "0.223", "size": "154"}, {"price": "0.227", "size": "20200"}, {"price": "0.302", "size": "250"}, {"price": "0.303", "size": "8050"}, {"price": "0.34", "size": "100"}, {"price": "0.341", "size": "5"}, {"price": "0.523", "size": "170"}, {"price": "0.723", "size": "173"}, {"price": "0.725", "size": "275"}, {"price": "0.823", "size": "195"}, {"price": "0.824", "size": "20"}, {"price": "0.923", "size": "764"}, {"price": "0.924", "size": "10"}, {"price": "0.925", "size": "20"}, {"price": "0.995", "size": "644.17"}, {"price": "0.997", "size": "19.7"}, {"price": "0.998", "size": "2808.75"}], "asks": [{"price": "0.999", "size": "5514.76"}], "event_type": "book", "last_trade_price": "0.001"}, {"market": "0x00ca3a4205ea548274f06891fd4b703160675842dd0120279ef5a40f1ddcfdaa", "asset_id": "24829650463128704493019067953349695357276451577710397157073955025381074470438", "timestamp": "1769384401124", "hash": "45a3679afde67931a3a1f3de3029428ce453a9f3", "bids": [{"price": "0.001", "size": "6721"}, {"price": "0.002", "size": "2500"}, {"price": "0.003", "size": "3120"}, {"price": "0.005", "size": "293"}], "asks": [{"price": "0.999", "size": "11002801.99"}, {"price": "0.998", "size": "250"}, {"price": "0.997", "size": "400"}, {"price": "0.996", "size": "8.65"}, {"price": "0.994", "size": "200"}, {"price": "0.99", "size": "2002310"}, {"price": "0.989", "size": "5.73"}, {"price": "0.98", "size": "1002500"}, {"price": "0.979", "size": "500000"}, {"price": "0.977", "size": "100"}, {"price": "0.976", "size": "10.74"}, {"price": "0.95", "size": "70"}, {"price": "0.949", "size": "39"}, {"price": "0.94", "size": "1500"}, {"price": "0.92", "size": "100"}, {"price": "0.919", "size": "5.62"}, {"price": "0.9", "size": "20"}, {"price": "0.89", "size": "900"}, {"price": "0.86", "size": "50"}, {"price": "0.8", "size": "410"}, {"price": "0.799", "size": "5.83"}, {"price": "0.73", "size": "200"}, {"price": "0.66", "size": "100"}, {"price": "0.529", "size": "6000"}, {"price": "0.528", "size": "4049"}, {"price": "0.369", "size": "316"}, {"price": "0.271", "size": "410"}, {"price": "0.267", "size": "20"}, {"price": "0.266", "size": "20"}, {"price": "0.049", "size": "10"}, {"price": "0.033", "size": "13.33"}, {"price": "0.014", "size": "435.16"}, {"price": "0.013", "size": "5.03"}, {"price": "0.011", "size": "2000"}, {"price": "0.01", "size": "28.55"}], "event_type": "book", "last_trade_price": "0.006"}, {"market": "0x85f3e001ffe2a24f985b939460d0cc22041d47107ed8c681f75abb6a5bd1d1d7", "asset_id": "91490628576757362533849475709592129096879082569664806718559823554313287888164", "timestamp": "1769384425291", "hash": "c28d950623c3349a8f8982869507f69a508ad4af", "bids": [{"price": "0.01", "size": "3102224.71"}, {"price": "0.02", "size": "902400"}, {"price": "0.03", "size": "500700"}, {"price": "0.04", "size": "5.65"}, {"price": "0.05", "size": "640"}, {"price": "0.06", "size": "33"}, {"price": "0.08", "size": "700"}, {"price": "0.09", "size": "5.08"}, {"price": "0.14", "size": "750"}, {"price": "0.2", "size": "200"}, {"price": "0.21", "size": "5.56"}, {"price": "0.27", "size": "9200"}, {"price": "0.37", "size": "20211"}, {"price": "0.4", "size": "250"}, {"price": "0.41", "size": "3380"}, {"price": "0.46", "size": "10"}, {"price": "0.47", "size": "20"}, {"price": "0.8", "size": "499.99"}, {"price": "0.81", "size": "20"}, {"price": "0.85", "size": "2000"}, {"price": "0.86", "size": "1798.36"}, {"price": "0.87", "size": "547.37"}, {"price": "0.88", "size": "147.8"}], "asks": [{"price": "0.99", "size": "50010"}, {"price": "0.98", "size": "11111"}, {"price": "0.97", "size": "350"}, {"price": "0.96", "size": "50"}, {"price": "0.95", "size": "100"}, {"price": "0.94", "size": "20"}, {"price": "0.93", "size": "1040"}, {"price": "0.91", "size": "424.84"}, {"price": "0.9", "size": "7.08"}], "event_type": "book", "last_trade_price": "0.100"}, {"market": "0x3d2a697437b1093ad06d6a74c6fb5a2a499b15d7e895500b5153f66bfaa0e602", "asset_id": "88196724466506103782248946687236791868579928810145867200121613054260505717011", "timestamp": "1769384381455", "hash": "9a256940b0413077446f62fe4b5d548a0f87b38f", "bids": [{"price": "0.001", "size": "6004088.97"}, {"price": "0.002", "size": "250"}, {"price": "0.003", "size": "172.66"}, {"price": "0.006", "size": "83"}, {"price": "0.007", "size": "10.5"}, {"price": "0.01", "size": "1000"}, {"price": "0.02", "size": "901000"}, {"price": "0.021", "size": "901400"}, {"price": "0.022", "size": "12.2"}, {"price": "0.05", "size": "30"}, {"price": "0.051", "size": "39"}, {"price": "0.061", "size": "4500"}, {"price": "0.062", "size": "250"}, {"price": "0.08", "size": "100"}, {"price": "0.081", "size": "5.64"}, {"price": "0.11", "size": "900"}, {"price": "0.14", "size": "50"}, {"price": "0.2", "size": "400"}, {"price": "0.201", "size": "5.82"}, {"price": "0.27", "size": "200"}, {"price": "0.34", "size": "100"}, {"price": "0.58", "size": "2222"}, {"price": "0.599", "size": "3170"}, {"price": "0.6", "size": "333"}, {"price": "0.863", "size": "20"}, {"price": "0.865", "size": "10"}, {"price": "0.866", "size": "20"}, {"price": "0.957", "size": "13.33"}, {"price": "0.966", "size": "2000"}, {"price": "0.967", "size": "258"}, {"price": "0.974", "size": "2000"}, {"price": "0.981", "size": "1350"}], "asks": [{"price": "0.999", "size": "26854.99"}, {"price": "0.998", "size": "316.66"}, {"price": "0.99", "size": "530.3"}, {"price": "0.988", "size": "2066.9"}, {"price": "0.987", "size": "100"}, {"price": "0.986", "size": "599.16"}, {"price": "0.985", "size": "132"}], "event_type": "book", "last_trade_price": ""}, {"market": "0xe6120576744ed4a770a37a962e5e1f13eca78070b05575c9dc118cc64cf000ba", "asset_id": "88202144797456094004565715683071874971451541348187754361676449702242116892606", "timestamp": "1769384385657", "hash": "51e6417c023c553204bcd41136df6a3e65589288", "bids": [{"price": "0.001", "size": "13501.14"}, {"price": "0.002", "size": "4702.14"}, {"price": "0.003", "size": "5331.32"}, {"price": "0.004", "size": "5008.34"}, {"price": "0.005", "size": "100"}], "asks": [{"price": "0.999", "size": "11002843"}, {"price": "0.998", "size": "250"}, {"price": "0.997", "size": "406.63"}, {"price": "0.994", "size": "200"}, {"price": "0.993", "size": "10.45"}, {"price": "0.99", "size": "2002210"}, {"price": "0.98", "size": "1002400"}, {"price": "0.979", "size": "800000"}, {"price": "0.978", "size": "12.16"}, {"price": "0.95", "size": "30"}, {"price": "0.949", "size": "39"}, {"price": "0.94", "size": "1500"}, {"price": "0.92", "size": "500"}, {"price": "0.919", "size": "5.62"}, {"price": "0.864", "size": "3550"}, {"price": "0.863", "size": "250"}, {"price": "0.86", "size": "50"}, {"price": "0.8", "size": "400"}, {"price": "0.799", "size": "5.83"}, {"price": "0.73", "size": "200"}, {"price": "0.66", "size": "100"}, {"price": "0.383", "size": "5"}, {"price": "0.377", "size": "3850"}, {"price": "0.376", "size": "320"}, {"price": "0.187", "size": "10"}, {"price": "0.185", "size": "20"}, {"price": "0.184", "size": "20"}, {"price": "0.036", "size": "8.88"}, {"price": "0.033", "size": "13"}, {"price": "0.01", "size": "380.99"}, {"price": "0.008", "size": "2000"}, {"price": "0.007", "size": "28.2"}], "event_type": "book", "last_trade_price": ""}, {"market": "0x14dbdb6274de6bcc65ce2b628c6636ff210fd452d095b0f14fdb1d376b31cecf", "asset_id": "108446172107941165064806998519652737542801121226691431615334275432295450338136", "timestamp": "1769384381674", "hash": "10ecc7af2918213564ce0b11035db1dc8e225f21", "bids": [{"price": "0.01", "size": "20510"}, {"price": "0.02", "size": "11117.66"}, {"price": "0.03", "size": "350"}, {"price": "0.05", "size": "100"}, {"price": "0.07", "size": "50"}, {"price": "0.1", "size": "100"}, {"price": "0.13", "size": "84.05"}, {"price": "0.15", "size": "100"}, {"price": "0.16", "size": "35.85"}, {"price": "0.17", "size": "310"}, {"price": "0.18", "size": "1426.95"}, {"price": "0.19", "size": "2106.95"}, {"price": "0.2", "size": "86.95"}, {"price": "0.21", "size": "1062.95"}], "asks": [{"price": "0.99", "size": "3102415.15"}, {"price": "0.98", "size": "1002409.79"}, {"price": "0.97", "size": "500700"}, {"price": "0.95", "size": "600"}, {"price": "0.94", "size": "6.44"}, {"price": "0.92", "size": "700"}, {"price": "0.86", "size": "700"}, {"price": "0.85", "size": "9.1"}, {"price": "0.78", "size": "18000"}, {"price": "0.77", "size": "14214"}, {"price": "0.72", "size": "250"}, {"price": "0.71", "size": "3145"}, {"price": "0.6", "size": "1654.31"}, {"price": "0.59", "size": "400"}, {"price": "0.58", "size": "5"}, {"price": "0.4", "size": "322.43"}, {"price": "0.38", "size": "20"}, {"price": "0.37", "size": "10"}, {"price": "0.3", "size": "100"}, {"price": "0.29", "size": "20"}, {"price": "0.28", "size": "100"}, {"price": "0.26", "size": "100"}, {"price": "0.24", "size": "137.49"}, {"price": "0.23", "size": "339.7"}], "event_type": "book", "last_trade_price": "0.230"}, {"market": "0xe6120576744ed4a770a37a962e5e1f13eca78070b05575c9dc118cc64cf000ba", "asset_id": "61485373804686118235598970240104189606288982592130954871186471768147590870705", "timestamp": "1769384385657", "hash": "c3e4bf69db8b83eb263f187b697cfcf6883d1787", "bids": [{"price": "0.001", "size": "11002843"}, {"price": "0.002", "size": "250"}, {"price": "0.003", "size": "406.63"}, {"price": "0.006", "size": "200"}, {"price": "0.007", "size": "10.45"}, {"price": "0.01", "size": "2002210"}, {"price": "0.02", "size": "1002400"}, {"price": "0.021", "size": "800000"}, {"price": "0.022", "size": "12.16"}, {"price": "0.05", "size": "30"}, {"price": "0.051", "size": "39"}, {"price": "0.06", "size": "1500"}, {"price": "0.08", "size": "500"}, {"price": "0.081", "size": "5.62"}, {"price": "0.136", "size": "3550"}, {"price": "0.137", "size": "250"}, {"price": "0.14", "size": "50"}, {"price": "0.2", "size": "400"}, {"price": "0.201", "size": "5.83"}, {"price": "0.27", "size": "200"}, {"price": "0.34", "size": "100"}, {"price": "0.617", "size": "5"}, {"price": "0.623", "size": "3850"}, {"price": "0.624", "size": "320"}, {"price": "0.813", "size": "10"}, {"price": "0.815", "size": "20"}, {"price": "0.816", "size": "20"}, {"price": "0.964", "size": "8.88"}, {"price": "0.967", "size": "13"}, {"price": "0.99", "size": "380.99"}, {"price": "0.992", "size": "2000"}, {"price": "0.993", "size": "28.2"}], "asks": [{"price": "0.999", "size": "13501.14"}, {"price": "0.998", "size": "4702.14"}, {"price": "0.997", "size": "5331.32"}, {"price": "0.996", "size": "5008.34"}, {"price": "0.995", "size": "100"}], "event_type": "book", "last_trade_price": ""}, {"market": "0xd6203f8805d1812e3b189da3f6036989940a415ae3a0fecf83555b455394fdb8", "asset_id": "46948910926280539794385431325138940193666253674995635848222141296489362188849", "timestamp": "1769384383590", "hash": "4e6b1f937f3825ee42c621d1f8d3825c1769eec8", "bids": [{"price": "0.001", "size": "29651"}, {"price": "0.002", "size": "9679.78"}, {"price": "0.003", "size": "250"}, {"price": "0.004", "size": "26.53"}, {"price": "0.01", "size": "110"}, {"price": "0.015", "size": "100"}, {"price": "0.017", "size": "10100"}, {"price": "0.019", "size": "2000"}, {"price": "0.02", "size": "100"}, {"price": "0.021", "size": "714.28"}, {"price": "0.022", "size": "814.28"}, {"price": "0.023", "size": "714.28"}, {"price": "0.024", "size": "2714.28"}, {"price": "0.025", "size": "550"}, {"price": "0.028", "size": "34.75"}], "asks": [{"price": "0.999", "size": "11002792.04"}, {"price": "0.998", "size": "255.05"}, {"price": "0.997", "size": "400"}, {"price": "0.996", "size": "8.76"}, {"price": "0.994", "size": "200"}, {"price": "0.99", "size": "2002410"}, {"price": "0.989", "size": "5.35"}, {"price": "0.98", "size": "1002400"}, {"price": "0.979", "size": "500000"}, {"price": "0.978", "size": "6841"}, {"price": "0.977", "size": "8.49"}, {"price": "0.95", "size": "30"}, {"price": "0.949", "size": "39"}, {"price": "0.936", "size": "1400"}, {"price": "0.935", "size": "7.1"}, {"price": "0.89", "size": "900"}, {"price": "0.82", "size": "20200"}, {"price": "0.819", "size": "11111"}, {"price": "0.818", "size": "6.78"}, {"price": "0.766", "size": "650"}, {"price": "0.765", "size": "8"}, {"price": "0.25", "size": "155.55"}, {"price": "0.205", "size": "20"}, {"price": "0.203", "size": "10"}, {"price": "0.202", "size": "20"}, {"price": "0.084", "size": "16.7"}, {"price": "0.062", "size": "17.6"}, {"price": "0.059", "size": "8"}, {"price": "0.056", "size": "13"}, {"price": "0.043", "size": "84.84"}, {"price": "0.035", "size": "20"}], "event_type": "book", "last_trade_price": "0.028"}, {"market": "0x2bf6f2697e123f9bfb2c8788ed35741c67159ed19374886e6e7cb3f35e60f855", "asset_id": "49586088438166301401847652669972487503167459757949140750804630139416391309643", "timestamp": "1769384420194", "hash": "8df8970f58b05dbea7ff472041072187cf9082dd", "bids": [{"price": "0.001", "size": "2859.07"}, {"price": "0.002", "size": "250"}, {"price": "0.003", "size": "172.68"}, {"price": "0.006", "size": "83"}, {"price": "0.007", "size": "10.53"}, {"price": "0.01", "size": "2002410"}, {"price": "0.02", "size": "901000"}, {"price": "0.021", "size": "901400"}, {"price": "0.022", "size": "12.23"}, {"price": "0.05", "size": "30"}, {"price": "0.051", "size": "39"}, {"price": "0.06", "size": "1500"}, {"price": "0.08", "size": "100"}, {"price": "0.081", "size": "5.64"}, {"price": "0.11", "size": "900"}, {"price": "0.182", "size": "20250"}, {"price": "0.2", "size": "200"}, {"price": "0.201", "size": "5.81"}, {"price": "0.265", "size": "11311"}, {"price": "0.27", "size": "200"}, {"price": "0.271", "size": "100"}, {"price": "0.34", "size": "100"}, {"price": "0.469", "size": "5"}, {"price": "0.502", "size": "10"}, {"price": "0.519", "size": "3141"}, {"price": "0.52", "size": "185"}, {"price": "0.521", "size": "20"}, {"price": "0.85", "size": "60.75"}, {"price": "0.86", "size": "35.99"}, {"price": "0.861", "size": "20"}, {"price": "0.92", "size": "2000"}, {"price": "0.921", "size": "2000"}, {"price": "0.926", "size": "31"}, {"price": "0.941", "size": "33.67"}, {"price": "0.942", "size": "46.8"}, {"price": "0.943", "size": "11.67"}, {"price": "0.944", "size": "45"}], "asks": [{"price": "0.999", "size": "26783.99"}, {"price": "0.998", "size": "19.43"}, {"price": "0.99", "size": "20110"}, {"price": "0.989", "size": "300"}, {"price": "0.988", "size": "7.87"}, {"price": "0.965", "size": "30.48"}, {"price": "0.961", "size": "48"}, {"price": "0.959", "size": "16"}, {"price": "0.958", "size": "204"}, {"price": "0.957", "size": "748"}, {"price": "0.954", "size": "19.78"}], "event_type": "book", "last_trade_price": "0.943"}, {"market": "0x9e3973197f60e1614567ce57a3e6f8a4805d21f471d67b67a5ed5ecca1b8004b", "asset_id": "34161622438208629372218363980216155858361713198177495956358330769075997408090", "timestamp": "1769384428467", "hash": "6a3a3958f04ca4697f097f2f9109f24a2ae7cc67", "bids": [{"price": "0.001", "size": "11002908.25"}, {"price": "0.002", "size": "250"}, {"price": "0.003", "size": "406.63"}, {"price": "0.006", "size": "200"}, {"price": "0.007", "size": "10.46"}, {"price": "0.01", "size": "2002410"}, {"price": "0.02", "size": "1002400"}, {"price": "0.021", "size": "500000"}, {"price": "0.022", "size": "12.16"}, {"price": "0.05", "size": "30"}, {"price": "0.051", "size": "39"}, {"price": "0.06", "size": "1500"}, {"price": "0.08", "size": "500"}, {"price": "0.081", "size": "6.11"}, {"price": "0.14", "size": "750"}, {"price": "0.212", "size": "20200"}, {"price": "0.213", "size": "5.32"}, {"price": "0.225", "size": "11111"}, {"price": "0.288", "size": "250"}, {"price": "0.289", "size": "6783"}, {"price": "0.34", "size": "100"}, {"price": "0.341", "size": "5"}, {"price": "0.592", "size": "10"}, {"price": "0.594", "size": "20"}, {"price": "0.595", "size": "20"}, {"price": "0.936", "size": "2019"}, {"price": "0.937", "size": "13"}, {"price": "0.956", "size": "2000"}, {"price": "0.957", "size": "62.7"}], "asks": [{"price": "0.999", "size": "19657"}, {"price": "0.998", "size": "673.31"}, {"price": "0.997", "size": "250"}, {"price": "0.996", "size": "12.52"}, {"price": "0.99", "size": "110"}, {"price": "0.989", "size": "6.23"}, {"price": "0.98", "size": "100"}, {"price": "0.975", "size": "100"}, {"price": "0.97", "size": "100"}, {"price": "0.968", "size": "650.45"}, {"price": "0.967", "size": "279.16"}, {"price": "0.965", "size": "130"}], "event_type": "book", "last_trade_price": ""}, {"market": "0x9e3973197f60e1614567ce57a3e6f8a4805d21f471d67b67a5ed5ecca1b8004b", "asset_id": "91737308879086717078434227064834144626260031635826299637092532293769745981585", "timestamp": "1769384428467", "hash": "9e30ad529cf0aca0da6a8533862c2db88e88c888", "bids": [{"price": "0.001", "size": "19657"}, {"price": "0.002", "size": "673.31"}, {"price": "0.003", "size": "250"}, {"price": "0.004", "size": "12.52"}, {"price": "0.01", "size": "110"}, {"price": "0.011", "size": "6.23"}, {"price": "0.02", "size": "100"}, {"price": "0.025", "size": "100"}, {"price": "0.03", "size": "100"}, {"price": "0.032", "size": "650.45"}, {"price": "0.033", "size": "279.16"}, {"price": "0.035", "size": "130"}], "asks": [{"price": "0.999", "size": "11002908.25"}, {"price": "0.998", "size": "250"}, {"price": "0.997", "size": "406.63"}, {"price": "0.994", "size": "200"}, {"price": "0.993", "size": "10.46"}, {"price": "0.99", "size": "2002410"}, {"price": "0.98", "size": "1002400"}, {"price": "0.979", "size": "500000"}, {"price": "0.978", "size": "12.16"}, {"price": "0.95", "size": "30"}, {"price": "0.949", "size": "39"}, {"price": "0.94", "size": "1500"}, {"price": "0.92", "size": "500"}, {"price": "0.919", "size": "6.11"}, {"price": "0.86", "size": "750"}, {"price": "0.788", "size": "20200"}, {"price": "0.787", "size": "5.32"}, {"price": "0.775", "size": "11111"}, {"price": "0.712", "size": "250"}, {"price": "0.711", "size": "6783"}, {"price": "0.66", "size": "100"}, {"price": "0.659", "size": "5"}, {"price": "0.408", "size": "10"}, {"price": "0.406", "size": "20"}, {"price": "0.405", "size": "20"}, {"price": "0.064", "size": "2019"}, {"price": "0.063", "size": "13"}, {"price": "0.044", "size": "2000"}, {"price": "0.043", "size": "62.7"}], "event_type": "book", "last_trade_price": ""}, {"market": "0xa3186ffc28c45f336920279d5085529d530690a1623997819f3a3db05119dbaa", "asset_id": "76284775424209240264542352208573338636556198300439966875308967535434111103074", "timestamp": "1769384425452", "hash": "4caa19cdd38d0f2039c3f5ff7dc6ce08031f8ef8", "bids": [{"price": "0.001", "size": "38545"}, {"price": "0.002", "size": "916"}, {"price": "0.003", "size": "6.13"}, {"price": "0.01", "size": "30410"}, {"price": "0.012", "size": "1000"}, {"price": "0.013", "size": "11211"}, {"price": "0.014", "size": "150"}, {"price": "0.02", "size": "194"}, {"price": "0.021", "size": "5.47"}, {"price": "0.03", "size": "100"}, {"price": "0.05", "size": "100"}, {"price": "0.07", "size": "40"}, {"price": "0.1", "size": "100"}, {"price": "0.125", "size": "200"}, {"price": "0.13", "size": "30"}, {"price": "0.15", "size": "100"}, {"price": "0.17", "size": "20"}, {"price": "0.19", "size": "20"}, {"price": "0.195", "size": "19585.39"}, {"price": "0.213", "size": "2000"}, {"price": "0.214", "size": "2000"}, {"price": "0.215", "size": "9946.21"}, {"price": "0.217", "size": "85.1"}, {"price": "0.218", "size": "85.1"}, {"price": "0.219", "size": "85.1"}, {"price": "0.22", "size": "546.59"}, {"price": "0.221", "size": "36"}], "asks": [{"price": "0.999", "size": "11004498.22"}, {"price": "0.998", "size": "255.2"}, {"price": "0.997", "size": "400"}, {"price": "0.996", "size": "9.03"}, {"price": "0.994", "size": "200"}, {"price": "0.99", "size": "1010"}, {"price": "0.989", "size": "5.06"}, {"price": "0.98", "size": "1002400"}, {"price": "0.979", "size": "500000"}, {"price": "0.978", "size": "12.66"}, {"price": "0.932", "size": "1500"}, {"price": "0.92", "size": "100"}, {"price": "0.919", "size": "5.84"}, {"price": "0.89", "size": "900"}, {"price": "0.82", "size": "15200"}, {"price": "0.818", "size": "11161"}, {"price": "0.8", "size": "200"}, {"price": "0.799", "size": "5.67"}, {"price": "0.73", "size": "200"}, {"price": "0.64", "size": "300"}, {"price": "0.639", "size": "3212"}, {"price": "0.638", "size": "405"}, {"price": "0.624", "size": "10"}, {"price": "0.623", "size": "20"}, {"price": "0.31", "size": "9.38"}, {"price": "0.309", "size": "20"}, {"price": "0.259", "size": "45.63"}, {"price": "0.25", "size": "1000"}, {"price": "0.249", "size": "13"}, {"price": "0.235", "size": "113.54"}, {"price": "0.225", "size": "55"}, {"price": "0.224", "size": "245"}, {"price": "0.223", "size": "15"}], "event_type": "book", "last_trade_price": "0.221"}, {"market": "0x8b89ea6de714f69d3418f77614b1dd5f9204443d8bc8fca1cb3d4b5cb7d0a1f5", "asset_id": "15952689881952595538604299570791504336373523211007351100313552761527006627492", "timestamp": "1769384383182", "hash": "d0bed41b21020c8516af15ee1f908a017ade315d", "bids": [{"price": "0.001", "size": "11002807.99"}, {"price": "0.002", "size": "250"}, {"price": "0.003", "size": "400"}, {"price": "0.004", "size": "8.65"}, {"price": "0.006", "size": "200"}, {"price": "0.01", "size": "2002410"}, {"price": "0.011", "size": "5.73"}, {"price": "0.02", "size": "1002400"}, {"price": "0.021", "size": "830000"}, {"price": "0.023", "size": "100"}, {"price": "0.024", "size": "10.74"}, {"price": "0.05", "size": "30"}, {"price": "0.051", "size": "39"}, {"price": "0.06", "size": "1500"}, {"price": "0.08", "size": "100"}, {"price": "0.081", "size": "5.62"}, {"price": "0.11", "size": "900"}, {"price": "0.14", "size": "50"}, {"price": "0.2", "size": "400"}, {"price": "0.201", "size": "5.84"}, {"price": "0.223", "size": "164"}, {"price": "0.27", "size": "200"}, {"price": "0.34", "size": "100"}, {"price": "0.523", "size": "161"}, {"price": "0.723", "size": "172"}, {"price": "0.741", "size": "2000"}, {"price": "0.742", "size": "3242"}, {"price": "0.759", "size": "263"}, {"price": "0.823", "size": "196"}, {"price": "0.838", "size": "10"}, {"price": "0.839", "size": "20"}, {"price": "0.923", "size": "352"}, {"price": "0.933", "size": "174.44"}, {"price": "0.951", "size": "5"}, {"price": "0.952", "size": "20"}, {"price": "0.993", "size": "1071.18"}, {"price": "0.994", "size": "2000"}, {"price": "0.996", "size": "162.15"}, {"price": "0.997", "size": "643.69"}, {"price": "0.998", "size": "4491.85"}], "asks": [{"price": "0.999", "size": "5500"}], "event_type": "book", "last_trade_price": ""}, {"market": "0x2bf6f2697e123f9bfb2c8788ed35741c67159ed19374886e6e7cb3f35e60f855", "asset_id": "36378160072890559704966692763500079412567571381443166092461911736222412577030", "timestamp": "1769384420194", "hash": "2c2c0e1a779fedd00d767756b1878622fc7cbe72", "bids": [{"price": "0.001", "size": "26783.99"}, {"price": "0.002", "size": "19.43"}, {"price": "0.01", "size": "20110"}, {"price": "0.011", "size": "300"}, {"price": "0.012", "size": "7.87"}, {"price": "0.035", "size": "30.48"}, {"price": "0.039", "size": "48"}, {"price": "0.041", "size": "16"}, {"price": "0.042", "size": "204"}, {"price": "0.043", "size": "748"}, {"price": "0.046", "size": "19.78"}], "asks": [{"price": "0.999", "size": "2859.07"}, {"price": "0.998", "size": "250"}, {"price": "0.997", "size": "172.68"}, {"price": "0.994", "size": "83"}, {"price": "0.993", "size": "10.53"}, {"price": "0.99", "size": "2002410"}, {"price": "0.98", "size": "901000"}, {"price": "0.979", "size": "901400"}, {"price": "0.978", "size": "12.23"}, {"price": "0.95", "size": "30"}, {"price": "0.949", "size": "39"}, {"price": "0.94", "size": "1500"}, {"price": "0.92", "size": "100"}, {"price": "0.919", "size": "5.64"}, {"price": "0.89", "size": "900"}, {"price": "0.818", "size": "20250"}, {"price": "0.8", "size": "200"}, {"price": "0.799", "size": "5.81"}, {"price": "0.735", "size": "11311"}, {"price": "0.73", "size": "200"}, {"price": "0.729", "size": "100"}, {"price": "0.66", "size": "100"}, {"price": "0.531", "size": "5"}, {"price": "0.498", "size": "10"}, {"price": "0.481", "size": "3141"}, {"price": "0.48", "size": "185"}, {"price": "0.479", "size": "20"}, {"price": "0.15", "size": "60.75"}, {"price": "0.14", "size": "35.99"}, {"price": "0.139", "size": "20"}, {"price": "0.08", "size": "2000"}, {"price": "0.079", "size": "2000"}, {"price": "0.074", "size": "31"}, {"price": "0.059", "size": "33.67"}, {"price": "0.058", "size": "46.8"}, {"price": "0.057", "size": "11.67"}, {"price": "0.056", "size": "45"}], "event_type": "book", "last_trade_price": "0.943"}, {"market": "0x32a07fd7094020a30410fce27454c130af242cc6cfefa2f5e90ee41a6589e293", "asset_id": "24132107218985688345495143092191711317864585230638250910164859465577083999899", "timestamp": "1769384385020", "hash": "29b97addd103ff4440f23fe6b0c3480234efa69a", "bids": [{"price": "0.001", "size": "7346.76"}], "asks": [{"price": "0.999", "size": "11002807.99"}, {"price": "0.998", "size": "250"}, {"price": "0.997", "size": "400"}, {"price": "0.996", "size": "8.65"}, {"price": "0.994", "size": "200"}, {"price": "0.99", "size": "2002410"}, {"price": "0.989", "size": "5.29"}, {"price": "0.98", "size": "1002400"}, {"price": "0.979", "size": "500000"}, {"price": "0.978", "size": "250"}, {"price": "0.977", "size": "11.42"}, {"price": "0.95", "size": "30"}, {"price": "0.949", "size": "39"}, {"price": "0.94", "size": "1500"}, {"price": "0.92", "size": "100"}, {"price": "0.919", "size": "5.62"}, {"price": "0.89", "size": "900"}, {"price": "0.86", "size": "50"}, {"price": "0.8", "size": "400"}, {"price": "0.799", "size": "5.83"}, {"price": "0.73", "size": "200"}, {"price": "0.66", "size": "100"}, {"price": "0.434", "size": "9000"}, {"price": "0.433", "size": "4205"}, {"price": "0.4", "size": "100"}, {"price": "0.249", "size": "266"}, {"price": "0.203", "size": "20"}, {"price": "0.201", "size": "10"}, {"price": "0.2", "size": "20"}, {"price": "0.049", "size": "10"}, {"price": "0.029", "size": "13.33"}, {"price": "0.024", "size": "439.52"}, {"price": "0.005", "size": "3627.89"}, {"price": "0.004", "size": "8.66"}, {"price": "0.003", "size": "1055.24"}], "event_type": "book", "last_trade_price": ""}, {"market": "0x14dbdb6274de6bcc65ce2b628c6636ff210fd452d095b0f14fdb1d376b31cecf", "asset_id": "84001958871872382698065661000901363707704455879969183740457806718395695678527", "timestamp": "1769384381674", "hash": "a0a94f2955a3f9ec00ffa0bd46521ef3d03b906f", "bids": [{"price": "0.01", "size": "3102415.15"}, {"price": "0.02", "size": "1002409.79"}, {"price": "0.03", "size": "500700"}, {"price": "0.05", "size": "600"}, {"price": "0.06", "size": "6.44"}, {"price": "0.08", "size": "700"}, {"price": "0.14", "size": "700"}, {"price": "0.15", "size": "9.1"}, {"price": "0.22", "size": "18000"}, {"price": "0.23", "size": "14214"}, {"price": "0.28", "size": "250"}, {"price": "0.29", "size": "3145"}, {"price": "0.4", "size": "1654.31"}, {"price": "0.41", "size": "400"}, {"price": "0.42", "size": "5"}, {"price": "0.6", "size": "322.43"}, {"price": "0.62", "size": "20"}, {"price": "0.63", "size": "10"}, {"price": "0.7", "size": "100"}, {"price": "0.71", "size": "20"}, {"price": "0.72", "size": "100"}, {"price": "0.74", "size": "100"}, {"price": "0.76", "size": "137.49"}, {"price": "0.77", "size": "339.7"}], "asks": [{"price": "0.99", "size": "20510"}, {"price": "0.98", "size": "11117.66"}, {"price": "0.97", "size": "350"}, {"price": "0.95", "size": "100"}, {"price": "0.93", "size": "50"}, {"price": "0.9", "size": "100"}, {"price": "0.87", "size": "84.05"}, {"price": "0.85", "size": "100"}, {"price": "0.84", "size": "35.85"}, {"price": "0.83", "size": "310"}, {"price": "0.82", "size": "1426.95"}, {"price": "0.81", "size": "2106.95"}, {"price": "0.8", "size": "86.95"}, {"price": "0.79", "size": "1062.95"}], "event_type": "book", "last_trade_price": "0.230"}]}
{"_local_timestamp": "2026-01-25T23:40:33.215052+00:00", "data": {"market": "0x1c60f9adb1d786b6fe78d63fd9f82dbb293fa06241532fb5ba43f8d8411cde1e", "price_changes": [{"asset_id": "76633639806751295595699993448608387906622374020066717378577586177644656154703", "price": "0.73", "size": "0", "side": "BUY", "hash": "6076f3cf3e51383b6cf999182d2b7396f80c693d", "best_bid": "0.8", "best_ask": "0.82"}, {"asset_id": "5252381880374485440665230178984721306055940128786215274896991682225319468348", "price": "0.27", "size": "0", "side": "SELL", "hash": "d94395f1025c2ec445c7eef7929790f2c0a5f890", "best_bid": "0.18", "best_ask": "0.2"}], "timestamp": "1769384433144", "event_type": "price_change"}}
{"_local_timestamp": "2026-01-25T23:40:33.234414+00:00", "data": {"market": "0x1c60f9adb1d786b6fe78d63fd9f82dbb293fa06241532fb5ba43f8d8411cde1e", "price_changes": [{"asset_id": "76633639806751295595699993448608387906622374020066717378577586177644656154703", "price": "0.72", "size": "20", "side": "BUY", "hash": "e2d0eca382562fc242882d8c37924a1827d9603a", "best_bid": "0.8", "best_ask": "0.82"}, {"asset_id": "5252381880374485440665230178984721306055940128786215274896991682225319468348", "price": "0.28", "size": "20", "side": "SELL", "hash": "2bcc16d33eb7bccb91d0d7bad450c1765d4ecb42", "best_bid": "0.18", "best_ask": "0.2"}], "timestamp": "1769384433169", "event_type": "price_change"}}
{"_local_timestamp": "2026-01-25T23:40:33.354324+00:00", "data": {"market": "0x1c60f9adb1d786b6fe78d63fd9f82dbb293fa06241532fb5ba43f8d8411cde1e", "price_changes": [{"asset_id": "76633639806751295595699993448608387906622374020066717378577586177644656154703", "price": "0.72", "size": "70", "side": "BUY", "hash": "5cb85f97ae5e3423f7b9bda9572ea1494dbb8ed4", "best_bid": "0.8", "best_ask": "0.82"}, {"asset_id": "5252381880374485440665230178984721306055940128786215274896991682225319468348", "price": "0.28", "size": "70", "side": "SELL", "hash": "1ca6e5f96c821ebcc8ee7f2eb20a634896f8b66b", "best_bid": "0.18", "best_ask": "0.2"}], "timestamp": "1769384433284", "event_type": "price_change"}}
{"_local_timestamp": "2026-01-25T23:40:33.397801+00:00", "data": {"market": "0x1c60f9adb1d786b6fe78d63fd9f82dbb293fa06241532fb5ba43f8d8411cde1e", "price_changes": [{"asset_id": "76633639806751295595699993448608387906622374020066717378577586177644656154703", "price": "0.72", "size": "120", "side": "BUY", "hash": "490ed3d1cbbf387979c59854cfd53d44a9ce560d", "best_bid": "0.8", "best_ask": "0.82"}, {"asset_id": "5252381880374485440665230178984721306055940128786215274896991682225319468348", "price": "0.28", "size": "120", "side": "SELL", "hash": "9ae85af71d4909b018e1041f463b0e6601676e0f", "best_bid": "0.18", "best_ask": "0.2"}], "timestamp": "1769384433327", "event_type": "price_change"}}
{"_local_timestamp": "2026-01-25T23:40:34.022342+00:00", "data": {"market": "0x1c60f9adb1d786b6fe78d63fd9f82dbb293fa06241532fb5ba43f8d8411cde1e", "price_changes": [{"asset_id": "76633639806751295595699993448608387906622374020066717378577586177644656154703", "price": "0.72", "size": "100", "side": "BUY", "hash": "00206308c67b5e9a1813cd27d284e3c1395d899e", "best_bid": "0.8", "best_ask": "0.82"}, {"asset_id": "5252381880374485440665230178984721306055940128786215274896991682225319468348", "price": "0.28", "size": "100", "side": "SELL", "hash": "30fc944b25845d7000e940036a8055b693a168a4", "best_bid": "0.18", "best_ask": "0.2"}], "timestamp": "1769384433949", "event_type": "price_change"}}
{"_local_timestamp": "2026-01-25T23:40:34.042424+00:00", "data": {"market": "0x1c60f9adb1d786b6fe78d63fd9f82dbb293fa06241532fb5ba43f8d8411cde1e", "price_changes": [{"asset_id": "76633639806751295595699993448608387906622374020066717378577586177644656154703", "price": "0.73", "size": "20", "side": "BUY", "hash": "0d7918c1f8281f670e24fc4e8b152b17fa2c7b7b", "best_bid": "0.8", "best_ask": "0.82"}, {"asset_id": "5252381880374485440665230178984721306055940128786215274896991682225319468348", "price": "0.27", "size": "20", "side": "SELL", "hash": "eb842427383df0ba0919b353db42b8a076755d79", "best_bid": "0.18", "best_ask": "0.2"}], "timestamp": "1769384433975", "event_type": "price_change"}}
{"_local_timestamp": "2026-01-25T23:40:34.149993+00:00", "data": {"market": "0x1c60f9adb1d786b6fe78d63fd9f82dbb293fa06241532fb5ba43f8d8411cde1e", "price_changes": [{"asset_id": "76633639806751295595699993448608387906622374020066717378577586177644656154703", "price": "0.72", "size": "50", "side": "BUY", "hash": "fdbca2a864129cb97c18d8c9e3bd91a8d70954b6", "best_bid": "0.8", "best_ask": "0.82"}, {"asset_id": "5252381880374485440665230178984721306055940128786215274896991682225319468348", "price": "0.28", "size": "50", "side": "SELL", "hash": "a277859507ae38fe018a5bf70d24cd7e94920830", "best_bid": "0.18", "best_ask": "0.2"}], "timestamp": "1769384434080", "event_type": "price_change"}}
{"_local_timestamp": "2026-01-25T23:40:34.152094+00:00", "data": {"market": "0x1c60f9adb1d786b6fe78d63fd9f82dbb293fa06241532fb5ba43f8d8411cde1e", "price_changes": [{"asset_id": "76633639806751295595699993448608387906622374020066717378577586177644656154703", "price": "0.72", "size": "0", "side": "BUY", "hash": "336517eb574a718f36e33f2177e205f91650d476", "best_bid": "0.8", "best_ask": "0.82"}, {"asset_id": "5252381880374485440665230178984721306055940128786215274896991682225319468348", "price": "0.28", "size": "0", "side": "SELL", "hash": "e773a75292f94dfde5078b4b81a77200f13eaf0c", "best_bid": "0.18", "best_ask": "0.2"}], "timestamp": "1769384434081", "event_type": "price_change"}}
{"_local_timestamp": "2026-01-25T23:40:36.747321+00:00", "data": {"market": "0x1c60f9adb1d786b6fe78d63fd9f82dbb293fa06241532fb5ba43f8d8411cde1e", "price_changes": [{"asset_id": "76633639806751295595699993448608387906622374020066717378577586177644656154703", "price": "0.73", "size": "0", "side": "BUY", "hash": "5d46e24d9c8dffa96a5503b19314039e7f967729", "best_bid": "0.8", "best_ask": "0.82"}, {"asset_id": "5252381880374485440665230178984721306055940128786215274896991682225319468348", "price": "0.27", "size": "0", "side": "SELL", "hash": "8a4e753eecdfd8f6855306fb4ce4524a9737d65c", "best_bid": "0.18", "best_ask": "0.2"}], "timestamp": "1769384436680", "event_type": "price_change"}}
{"_local_timestamp": "2026-01-25T23:40:36.778604+00:00", "data": {"market": "0x1c60f9adb1d786b6fe78d63fd9f82dbb293fa06241532fb5ba43f8d8411cde1e", "price_changes": [{"asset_id": "76633639806751295595699993448608387906622374020066717378577586177644656154703", "price": "0.72", "size": "20", "side": "BUY", "hash": "55d9e7c8e336567641c31b3ec2519ca9f15ccb09", "best_bid": "0.8", "best_ask": "0.82"}, {"asset_id": "5252381880374485440665230178984721306055940128786215274896991682225319468348", "price": "0.28", "size": "20", "side": "SELL", "hash": "b775e5621bcec52b866fa3ef9cb20ae345e6b48b", "best_bid": "0.18", "best_ask": "0.2"}], "timestamp": "1769384436710", "event_type": "price_change"}}
{"_local_timestamp": "2026-01-25T23:40:36.916264+00:00", "data": {"market": "0x1c60f9adb1d786b6fe78d63fd9f82dbb293fa06241532fb5ba43f8d8411cde1e", "price_changes": [{"asset_id": "76633639806751295595699993448608387906622374020066717378577586177644656154703", "price": "0.72", "size": "70", "side": "BUY", "hash": "bd7165f85850f637216658aca5aa1f4354730732", "best_bid": "0.8", "best_ask": "0.82"}, {"asset_id": "5252381880374485440665230178984721306055940128786215274896991682225319468348", "price": "0.28", "size": "70", "side": "SELL", "hash": "1e37d4f728d72b4463e2aab07a0515924258b031", "best_bid": "0.18", "best_ask": "0.2"}], "timestamp": "1769384436846", "event_type": "price_change"}}
{"_local_timestamp": "2026-01-25T23:40:36.931779+00:00", "data": {"market": "0x1c60f9adb1d786b6fe78d63fd9f82dbb293fa06241532fb5ba43f8d8411cde1e", "price_changes": [{"asset_id": "76633639806751295595699993448608387906622374020066717378577586177644656154703", "price": "0.72", "size": "120", "side": "BUY", "hash": "0c981ceb8dad5c9792d6247a7d0f027d4aa11194", "best_bid": "0.8", "best_ask": "0.82"}, {"asset_id": "5252381880374485440665230178984721306055940128786215274896991682225319468348", "price": "0.28", "size": "120", "side": "SELL", "hash": "4a3ddcb54c76a1a2cdbd6bb59c38cc9d0ea65f5f", "best_bid": "0.18", "best_ask": "0.2"}], "timestamp": "1769384436854", "event_type": "price_change"}}
{"_local_timestamp": "2026-01-25T23:40:37.022778+00:00", "data": {"market": "0x1c60f9adb1d786b6fe78d63fd9f82dbb293fa06241532fb5ba43f8d8411cde1e", "price_changes": [{"asset_id": "76633639806751295595699993448608387906622374020066717378577586177644656154703", "price": "0.72", "size": "70", "side": "BUY", "hash": "ff071622b238d7dbb57b12d11d4700414599e997", "best_bid": "0.8", "best_ask": "0.82"}, {"asset_id": "5252381880374485440665230178984721306055940128786215274896991682225319468348", "price": "0.28", "size": "70", "side": "SELL", "hash": "bc6c7d75171434aa762566dccb080152ed127920", "best_bid": "0.18", "best_ask": "0.2"}], "timestamp": "1769384436953", "event_type": "price_change"}}
{"_local_timestamp": "2026-01-25T23:40:38.660808+00:00", "data": {"market": "0x1c60f9adb1d786b6fe78d63fd9f82dbb293fa06241532fb5ba43f8d8411cde1e", "price_changes": [{"asset_id": "76633639806751295595699993448608387906622374020066717378577586177644656154703", "price": "0.72", "size": "50", "side": "BUY", "hash": "a99d71fd96095c6cd3bd2e679457ca6708bb2f54", "best_bid": "0.8", "best_ask": "0.82"}, {"asset_id": "5252381880374485440665230178984721306055940128786215274896991682225319468348", "price": "0.28", "size": "50", "side": "SELL", "hash": "e2b65d0338a49a25337779d1228d03145e750758", "best_bid": "0.18", "best_ask": "0.2"}], "timestamp": "1769384438587", "event_type": "price_change"}}
{"_local_timestamp": "2026-01-25T23:40:38.683275+00:00", "data": {"market": "0x1c60f9adb1d786b6fe78d63fd9f82dbb293fa06241532fb5ba43f8d8411cde1e", "price_changes": [{"asset_id": "76633639806751295595699993448608387906622374020066717378577586177644656154703", "price": "0.73", "size": "20", "side": "BUY", "hash": "44878576d3479d6a14508fb7e1dcd8a0a5c92d37", "best_bid": "0.8", "best_ask": "0.82"}, {"asset_id": "5252381880374485440665230178984721306055940128786215274896991682225319468348", "price": "0.27", "size": "20", "side": "SELL", "hash": "5edfb275c330b6ad2b2f784ae6ad5d9333aedbf9", "best_bid": "0.18", "best_ask": "0.2"}], "timestamp": "1769384438617", "event_type": "price_change"}}
{"_local_timestamp": "2026-01-25T23:40:38.776887+00:00", "data": {"market": "0x1c60f9adb1d786b6fe78d63fd9f82dbb293fa06241532fb5ba43f8d8411cde1e", "price_changes": [{"asset_id": "76633639806751295595699993448608387906622374020066717378577586177644656154703", "price": "0.72", "size": "0", "side": "BUY", "hash": "d80150d54dc15423ccd40fc803735adf2c501794", "best_bid": "0.8", "best_ask": "0.82"}, {"asset_id": "5252381880374485440665230178984721306055940128786215274896991682225319468348", "price": "0.28", "size": "0", "side": "SELL", "hash": "f74aeadbd269e983d53abb9f2d1d667854b7759d", "best_bid": "0.18", "best_ask": "0.2"}], "timestamp": "1769384438704", "event_type": "price_change"}}
{"_local_timestamp": "2026-01-25T23:40:43.227880+00:00", "data": {"market": "0x1c60f9adb1d786b6fe78d63fd9f82dbb293fa06241532fb5ba43f8d8411cde1e", "price_changes": [{"asset_id": "76633639806751295595699993448608387906622374020066717378577586177644656154703", "price": "0.73", "size": "0", "side": "BUY", "hash": "dade1bcb4dd06e8455f93ff02ddefd46acdcea6e", "best_bid": "0.8", "best_ask": "0.82"}, {"asset_id": "5252381880374485440665230178984721306055940128786215274896991682225319468348", "price": "0.27", "size": "0", "side": "SELL", "hash": "c6497dca5e24e8f6e05c8d36d0580a7613fe44e9", "best_bid": "0.18", "best_ask": "0.2"}], "timestamp": "1769384443156", "event_type": "price_change"}}
{"_local_timestamp": "2026-01-25T23:40:43.254545+00:00", "data": {"market": "0x1c60f9adb1d786b6fe78d63fd9f82dbb293fa06241532fb5ba43f8d8411cde1e", "price_changes": [{"asset_id": "76633639806751295595699993448608387906622374020066717378577586177644656154703", "price": "0.72", "size": "20", "side": "BUY", "hash": "99c8d650f7be4d8b04e5f4da26d6f92bf29bedb5", "best_bid": "0.8", "best_ask": "0.82"}, {"asset_id": "5252381880374485440665230178984721306055940128786215274896991682225319468348", "price": "0.28", "size": "20", "side": "SELL", "hash": "09af431eb5f28824f4dc5efee133434777dd074d", "best_bid": "0.18", "best_ask": "0.2"}], "timestamp": "1769384443182", "event_type": "price_change"}}
{"_local_timestamp": "2026-01-25T23:40:43.365047+00:00", "data": {"market": "0x1c60f9adb1d786b6fe78d63fd9f82dbb293fa06241532fb5ba43f8d8411cde1e", "price_changes": [{"asset_id": "76633639806751295595699993448608387906622374020066717378577586177644656154703", "price": "0.72", "size": "70", "side": "BUY", "hash": "9fc91ac0466c46d8d67c413f3127455329c6cb12", "best_bid": "0.8", "best_ask": "0.82"}, {"asset_id": "5252381880374485440665230178984721306055940128786215274896991682225319468348", "price": "0.28", "size": "70", "side": "SELL", "hash": "f438bd0d9381c5e6c2cb5d51acc25d26fda95c87", "best_bid": "0.18", "best_ask": "0.2"}], "timestamp": "1769384443293", "event_type": "price_change"}}
{"_local_timestamp": "2026-01-25T23:40:43.376443+00:00", "data": {"market": "0x1c60f9adb1d786b6fe78d63fd9f82dbb293fa06241532fb5ba43f8d8411cde1e", "price_changes": [{"asset_id": "76633639806751295595699993448608387906622374020066717378577586177644656154703", "price": "0.72", "size": "120", "side": "BUY", "hash": "c4195c4d996a33630b1e24872b717e8b272bfcba", "best_bid": "0.8", "best_ask": "0.82"}, {"asset_id": "5252381880374485440665230178984721306055940128786215274896991682225319468348", "price": "0.28", "size": "120", "side": "SELL", "hash": "ef3d157100aee3aa25aa78f3be05f2e34b49b18c", "best_bid": "0.18", "best_ask": "0.2"}], "timestamp": "1769384443308", "event_type": "price_change"}}
{"_local_timestamp": "2026-01-25T23:40:45.087922+00:00", "data": {"market": "0x9954b4eef49a268b810bc260ee9278361e29a8f6f4ad816a804dd613ef73a968", "price_changes": [{"asset_id": "407336258606092316833789781486672854343361331985279263948001098476429338355", "price": "0.939", "size": "147", "side": "SELL", "hash": "9d5dd2866b0612644ef6aca4ba0cbf9ab356bcf4", "best_bid": "0.848", "best_ask": "0.881"}, {"asset_id": "50692628443801018513325614545746863026982626993302787461752145605052144027838", "price": "0.061", "size": "147", "side": "BUY", "hash": "d073f85ee7efd6def30ae6636c265a03c6f4ad19", "best_bid": "0.119", "best_ask": "0.152"}], "timestamp": "1769384445001", "event_type": "price_change"}}
{"_local_timestamp": "2026-01-25T23:40:47.253757+00:00", "data": {"market": "0x1c60f9adb1d786b6fe78d63fd9f82dbb293fa06241532fb5ba43f8d8411cde1e", "price_changes": [{"asset_id": "76633639806751295595699993448608387906622374020066717378577586177644656154703", "price": "0.72", "size": "100", "side": "BUY", "hash": "c8641e4ec18cbaa60011931e10fd534abb7899fc", "best_bid": "0.8", "best_ask": "0.82"}, {"asset_id": "5252381880374485440665230178984721306055940128786215274896991682225319468348", "price": "0.28", "size": "100", "side": "SELL", "hash": "0829165d4fbac31cf1da379897dd1eb9d927b7c6", "best_bid": "0.18", "best_ask": "0.2"}], "timestamp": "1769384447184", "event_type": "price_change"}}
{"_local_timestamp": "2026-01-25T23:40:47.281873+00:00", "data": {"market": "0x1c60f9adb1d786b6fe78d63fd9f82dbb293fa06241532fb5ba43f8d8411cde1e", "price_changes": [{"asset_id": "76633639806751295595699993448608387906622374020066717378577586177644656154703", "price": "0.73", "size": "20", "side": "BUY", "hash": "e52ee2a1e36369980de73c5b63eec32dd4c4533d", "best_bid": "0.8", "best_ask": "0.82"}, {"asset_id": "5252381880374485440665230178984721306055940128786215274896991682225319468348", "price": "0.27", "size": "20", "side": "SELL", "hash": "0a08824d3ecf04c113bf7c86c7ba98cfb90e0d98", "best_bid": "0.18", "best_ask": "0.2"}], "timestamp": "1769384447213", "event_type": "price_change"}}
{"_local_timestamp": "2026-01-25T23:40:47.389677+00:00", "data": {"market": "0x1c60f9adb1d786b6fe78d63fd9f82dbb293fa06241532fb5ba43f8d8411cde1e", "price_changes": [{"asset_id": "76633639806751295595699993448608387906622374020066717378577586177644656154703", "price": "0.72", "size": "50", "side": "BUY", "hash": "0ed4791c9b446ceb78a21dd132d0447ce643f7c1", "best_bid": "0.8", "best_ask": "0.82"}, {"asset_id": "5252381880374485440665230178984721306055940128786215274896991682225319468348", "price": "0.28", "size": "50", "side": "SELL", "hash": "f7012eb2bd38da894164a76136a6086139abfa6f", "best_bid": "0.18", "best_ask": "0.2"}], "timestamp": "1769384447320", "event_type": "price_change"}}
{"_local_timestamp": "2026-01-25T23:40:47.475743+00:00", "data": {"market": "0x1c60f9adb1d786b6fe78d63fd9f82dbb293fa06241532fb5ba43f8d8411cde1e", "price_changes": [{"asset_id": "76633639806751295595699993448608387906622374020066717378577586177644656154703", "price": "0.72", "size": "0", "side": "BUY", "hash": "a3b3dd25f1b8220e802ad4494459bf9aee46625c", "best_bid": "0.8", "best_ask": "0.82"}, {"asset_id": "5252381880374485440665230178984721306055940128786215274896991682225319468348", "price": "0.28", "size": "0", "side": "SELL", "hash": "65f205ae4f19eab358cae9160efbbe68987036fc", "best_bid": "0.18", "best_ask": "0.2"}], "timestamp": "1769384447407", "event_type": "price_change"}}
{"_local_timestamp": "2026-01-25T23:40:53.377626+00:00", "data": {"market": "0x1c60f9adb1d786b6fe78d63fd9f82dbb293fa06241532fb5ba43f8d8411cde1e", "price_changes": [{"asset_id": "76633639806751295595699993448608387906622374020066717378577586177644656154703", "price": "0.73", "size": "0", "side": "BUY", "hash": "23fc7156654cce58e4d2c9877a52a3d734c15320", "best_bid": "0.8", "best_ask": "0.82"}, {"asset_id": "5252381880374485440665230178984721306055940128786215274896991682225319468348", "price": "0.27", "size": "0", "side": "SELL", "hash": "af16c5e9d8aa4d696f2b08e2e70f86ccd78d6712", "best_bid": "0.18", "best_ask": "0.2"}], "timestamp": "1769384453304", "event_type": "price_change"}}
{"_local_timestamp": "2026-01-25T23:40:53.419618+00:00", "data": {"market": "0x1c60f9adb1d786b6fe78d63fd9f82dbb293fa06241532fb5ba43f8d8411cde1e", "price_changes": [{"asset_id": "76633639806751295595699993448608387906622374020066717378577586177644656154703", "price": "0.72", "size": "20", "side": "BUY", "hash": "431d09d00b2894d3ad5427491ce04b9783706d27", "best_bid": "0.8", "best_ask": "0.82"}, {"asset_id": "5252381880374485440665230178984721306055940128786215274896991682225319468348", "price": "0.28", "size": "20", "side": "SELL", "hash": "0c37fd02227fbff2ab0bf8767d7f6553403404dd", "best_bid": "0.18", "best_ask": "0.2"}], "timestamp": "1769384453336", "event_type": "price_change"}}
{"_local_timestamp": "2026-01-25T23:40:53.529160+00:00", "data": {"market": "0x1c60f9adb1d786b6fe78d63fd9f82dbb293fa06241532fb5ba43f8d8411cde1e", "price_changes": [{"asset_id": "76633639806751295595699993448608387906622374020066717378577586177644656154703", "price": "0.72", "size": "70", "side": "BUY", "hash": "9327d17f4695753a97005cff6dbf5585783b3e07", "best_bid": "0.8", "best_ask": "0.82"}, {"asset_id": "5252381880374485440665230178984721306055940128786215274896991682225319468348", "price": "0.28", "size": "70", "side": "SELL", "hash": "0e0ab1d07b181654eed473577fca1d3016e70528", "best_bid": "0.18", "best_ask": "0.2"}], "timestamp": "1769384453452", "event_type": "price_change"}}
{"_local_timestamp": "2026-01-25T23:40:53.585788+00:00", "data": {"market": "0x1c60f9adb1d786b6fe78d63fd9f82dbb293fa06241532fb5ba43f8d8411cde1e", "price_changes": [{"asset_id": "76633639806751295595699993448608387906622374020066717378577586177644656154703", "price": "0.72", "size": "120", "side": "BUY", "hash": "fe8129f996d7cd848a68c28df9026fdba10c6660", "best_bid": "0.8", "best_ask": "0.82"}, {"asset_id": "5252381880374485440665230178984721306055940128786215274896991682225319468348", "price": "0.28", "size": "120", "side": "SELL", "hash": "d69956e22e58c5594a40b15bdca4ef8080bc10e4", "best_bid": "0.18", "best_ask": "0.2"}], "timestamp": "1769384453507", "event_type": "price_change"}}
{"_local_timestamp": "2026-01-25T23:40:54.287609+00:00", "data": {"market": "0x1c60f9adb1d786b6fe78d63fd9f82dbb293fa06241532fb5ba43f8d8411cde1e", "price_changes": [{"asset_id": "76633639806751295595699993448608387906622374020066717378577586177644656154703", "price": "0.72", "size": "100", "side": "BUY", "hash": "0ee8543058f3fd121027d56bc67376163eb3f0e5", "best_bid": "0.8", "best_ask": "0.82"}, {"asset_id": "5252381880374485440665230178984721306055940128786215274896991682225319468348", "price": "0.28", "size": "100", "side": "SELL", "hash": "0e09a9a944f7c6b90376939ceb138bd7e57f3fe4", "best_bid": "0.18", "best_ask": "0.2"}], "timestamp": "1769384454219", "event_type": "price_change"}}
{"_local_timestamp": "2026-01-25T23:40:54.320517+00:00", "data": {"market": "0x1c60f9adb1d786b6fe78d63fd9f82dbb293fa06241532fb5ba43f8d8411cde1e", "price_changes": [{"asset_id": "76633639806751295595699993448608387906622374020066717378577586177644656154703", "price": "0.73", "size": "20", "side": "BUY", "hash": "ce5cf2f6fddb19e9a35af45223fac29c89daa97c", "best_bid": "0.8", "best_ask": "0.82"}, {"asset_id": "5252381880374485440665230178984721306055940128786215274896991682225319468348", "price": "0.27", "size": "20", "side": "SELL", "hash": "b8c1084c5d817c9b803e4028fe1129334b3ad359", "best_bid": "0.18", "best_ask": "0.2"}], "timestamp": "1769384454249", "event_type": "price_change"}}
{"_local_timestamp": "2026-01-25T23:40:54.435639+00:00", "data": {"market": "0x1c60f9adb1d786b6fe78d63fd9f82dbb293fa06241532fb5ba43f8d8411cde1e", "price_changes": [{"asset_id": "76633639806751295595699993448608387906622374020066717378577586177644656154703", "price": "0.72", "size": "50", "side": "BUY", "hash": "3c7af375345764c73c6c1239803edb76a839153c", "best_bid": "0.8", "best_ask": "0.82"}, {"asset_id": "5252381880374485440665230178984721306055940128786215274896991682225319468348", "price": "0.28", "size": "50", "side": "SELL", "hash": "c5c34629d2b68d7914b548ef171d05215dffc290", "best_bid": "0.18", "best_ask": "0.2"}], "timestamp": "1769384454368", "event_type": "price_change"}}
{"_local_timestamp": "2026-01-25T23:40:54.569350+00:00", "data": {"market": "0x1c60f9adb1d786b6fe78d63fd9f82dbb293fa06241532fb5ba43f8d8411cde1e", "price_changes": [{"asset_id": "76633639806751295595699993448608387906622374020066717378577586177644656154703", "price": "0.72", "size": "0", "side": "BUY", "hash": "342f9c5d7885d901c6c1616ba3b6c09023436fc2", "best_bid": "0.8", "best_ask": "0.82"}, {"asset_id": "5252381880374485440665230178984721306055940128786215274896991682225319468348", "price": "0.28", "size": "0", "side": "SELL", "hash": "1a957a02597bd263b0d7e078cfbadc4d844ce013", "best_bid": "0.18", "best_ask": "0.2"}], "timestamp": "1769384454479", "event_type": "price_change"}}
{"_local_timestamp": "2026-01-25T23:40:56.184556+00:00", "data": {"market": "0x9954b4eef49a268b810bc260ee9278361e29a8f6f4ad816a804dd613ef73a968", "price_changes": [{"asset_id": "50692628443801018513325614545746863026982626993302787461752145605052144027838", "price": "0.058", "size": "2810", "side": "BUY", "hash": "a1edf822d0d401274761ea477877700e54d2dbcb", "best_bid": "0.119", "best_ask": "0.152"}, {"asset_id": "407336258606092316833789781486672854343361331985279263948001098476429338355", "price": "0.942", "size": "2810", "side": "SELL", "hash": "431ab6d3dd45be8e8423b6b63d92313867edc40d", "best_bid": "0.848", "best_ask": "0.881"}], "timestamp": "1769384456114", "event_type": "price_change"}}
{"_local_timestamp": "2026-01-25T23:40:56.186481+00:00", "data": {"market": "0x9954b4eef49a268b810bc260ee9278361e29a8f6f4ad816a804dd613ef73a968", "price_changes": [{"asset_id": "50692628443801018513325614545746863026982626993302787461752145605052144027838", "price": "0.05", "size": "1852.65", "side": "BUY", "hash": "204483a3c2aaffa99c56ebc89ca73858c8be2aff", "best_bid": "0.119", "best_ask": "0.152"}, {"asset_id": "407336258606092316833789781486672854343361331985279263948001098476429338355", "price": "0.95", "size": "1852.65", "side": "SELL", "hash": "6a14a2e7b34a2752b17fec95739526219ef171a5", "best_bid": "0.848", "best_ask": "0.881"}], "timestamp": "1769384456114", "event_type": "price_change"}}
{"_local_timestamp": "2026-01-25T23:40:56.191084+00:00", "data": {"market": "0x9954b4eef49a268b810bc260ee9278361e29a8f6f4ad816a804dd613ef73a968", "price_changes": [{"asset_id": "50692628443801018513325614545746863026982626993302787461752145605052144027838", "price": "0.042", "size": "1119", "side": "BUY", "hash": "80630e77d7facde4eca1a13c7c241c62534973c0", "best_bid": "0.119", "best_ask": "0.152"}, {"asset_id": "407336258606092316833789781486672854343361331985279263948001098476429338355", "price": "0.958", "size": "1119", "side": "SELL", "hash": "485ca96dc9b6927f2dd257641d8f9394c9a18b3e", "best_bid": "0.848", "best_ask": "0.881"}], "timestamp": "1769384456115", "event_type": "price_change"}}
{"_local_timestamp": "2026-01-25T23:40:57.247519+00:00", "data": {"market": "0x1c60f9adb1d786b6fe78d63fd9f82dbb293fa06241532fb5ba43f8d8411cde1e", "price_changes": [{"asset_id": "76633639806751295595699993448608387906622374020066717378577586177644656154703", "price": "0.73", "size": "0", "side": "BUY", "hash": "f27e4d46bef81268552fbede7e3eba11428c6123", "best_bid": "0.8", "best_ask": "0.82"}, {"asset_id": "5252381880374485440665230178984721306055940128786215274896991682225319468348", "price": "0.27", "size": "0", "side": "SELL", "hash": "402bc21be48489745288a7f141c072a4b05df984", "best_bid": "0.18", "best_ask": "0.2"}], "timestamp": "1769384457178", "event_type": "price_change"}}
{"_local_timestamp": "2026-01-25T23:40:57.282709+00:00", "data": {"market": "0x1c60f9adb1d786b6fe78d63fd9f82dbb293fa06241532fb5ba43f8d8411cde1e", "price_changes": [{"asset_id": "76633639806751295595699993448608387906622374020066717378577586177644656154703", "price": "0.72", "size": "20", "side": "BUY", "hash": "218668a4cc50d907e795d582edc0c182c5089545", "best_bid": "0.8", "best_ask": "0.82"}, {"asset_id": "5252381880374485440665230178984721306055940128786215274896991682225319468348", "price": "0.28", "size": "20", "side": "SELL", "hash": "6fd73208660c3eade87b1ae02030298d4b6ec1fa", "best_bid": "0.18", "best_ask": "0.2"}], "timestamp": "1769384457206", "event_type": "price_change"}}
{"_local_timestamp": "2026-01-25T23:40:57.391403+00:00", "data": {"market": "0x1c60f9adb1d786b6fe78d63fd9f82dbb293fa06241532fb5ba43f8d8411cde1e", "price_changes": [{"asset_id": "76633639806751295595699993448608387906622374020066717378577586177644656154703", "price": "0.72", "size": "70", "side": "BUY", "hash": "dc0533db7b90c564e17397f7d01407fbf2850222", "best_bid": "0.8", "best_ask": "0.82"}, {"asset_id": "5252381880374485440665230178984721306055940128786215274896991682225319468348", "price": "0.28", "size": "70", "side": "SELL", "hash": "02802e2a5d25007d12de361c6c75467de2100a6a", "best_bid": "0.18", "best_ask": "0.2"}], "timestamp": "1769384457323", "event_type": "price_change"}}
{"_local_timestamp": "2026-01-25T23:40:57.419299+00:00", "data": {"market": "0x1c60f9adb1d786b6fe78d63fd9f82dbb293fa06241532fb5ba43f8d8411cde1e", "price_changes": [{"asset_id": "76633639806751295595699993448608387906622374020066717378577586177644656154703", "price": "0.72", "size": "120", "side": "BUY", "hash": "47b40ea93799d2108f0c7571f977b50341004908", "best_bid": "0.8", "best_ask": "0.82"}, {"asset_id": "5252381880374485440665230178984721306055940128786215274896991682225319468348", "price": "0.28", "size": "120", "side": "SELL", "hash": "a5d5558b16da1856914eb9e8312446a3766ad5c1", "best_bid": "0.18", "best_ask": "0.2"}], "timestamp": "1769384457351", "event_type": "price_change"}}
{"_local_timestamp": "2026-01-25T23:40:59.349355+00:00", "data": {"market": "0x1c60f9adb1d786b6fe78d63fd9f82dbb293fa06241532fb5ba43f8d8411cde1e", "price_changes": [{"asset_id": "76633639806751295595699993448608387906622374020066717378577586177644656154703", "price": "0.72", "size": "100", "side": "BUY", "hash": "f3d27886df754eea55720abe472b41cbf72aeaa8", "best_bid": "0.8", "best_ask": "0.82"}, {"asset_id": "5252381880374485440665230178984721306055940128786215274896991682225319468348", "price": "0.28", "size": "100", "side": "SELL", "hash": "439af2287f53de425f647e6d779e0547ad2e6c46", "best_bid": "0.18", "best_ask": "0.2"}], "timestamp": "1769384459280", "event_type": "price_change"}}
{"_local_timestamp": "2026-01-25T23:40:59.383969+00:00", "data": {"market": "0x1c60f9adb1d786b6fe78d63fd9f82dbb293fa06241532fb5ba43f8d8411cde1e", "price_changes": [{"asset_id": "76633639806751295595699993448608387906622374020066717378577586177644656154703", "price": "0.73", "size": "20", "side": "BUY", "hash": "146062c9f0408ea6df70716c04c74a42d5da47b3", "best_bid": "0.8", "best_ask": "0.82"}, {"asset_id": "5252381880374485440665230178984721306055940128786215274896991682225319468348", "price": "0.27", "size": "20", "side": "SELL", "hash": "20c4210df8959e6affe7f5568f21e6b04e993993", "best_bid": "0.18", "best_ask": "0.2"}], "timestamp": "1769384459308", "event_type": "price_change"}}
{"_local_timestamp": "2026-01-25T23:40:59.499598+00:00", "data": {"market": "0x1c60f9adb1d786b6fe78d63fd9f82dbb293fa06241532fb5ba43f8d8411cde1e", "price_changes": [{"asset_id": "76633639806751295595699993448608387906622374020066717378577586177644656154703", "price": "0.72", "size": "50", "side": "BUY", "hash": "23a7221874bdb1bb057b9c86332bbb09cb383fe4", "best_bid": "0.8", "best_ask": "0.82"}, {"asset_id": "5252381880374485440665230178984721306055940128786215274896991682225319468348", "price": "0.28", "size": "50", "side": "SELL", "hash": "3e25b4f710823d365c52ce83456172cfbaccf225", "best_bid": "0.18", "best_ask": "0.2"}], "timestamp": "1769384459424", "event_type": "price_change"}}
{"_local_timestamp": "2026-01-25T23:40:59.587199+00:00", "data": {"market": "0x1c60f9adb1d786b6fe78d63fd9f82dbb293fa06241532fb5ba43f8d8411cde1e", "price_changes": [{"asset_id": "76633639806751295595699993448608387906622374020066717378577586177644656154703", "price": "0.72", "size": "0", "side": "BUY", "hash": "9cebf03f9c67e8b794d7c6b2d65878969c513440", "best_bid": "0.8", "best_ask": "0.82"}, {"asset_id": "5252381880374485440665230178984721306055940128786215274896991682225319468348", "price": "0.28", "size": "0", "side": "SELL", "hash": "b6000fd5aea016caaedc76962d6368fa87580dab", "best_bid": "0.18", "best_ask": "0.2"}], "timestamp": "1769384459500", "event_type": "price_change"}}
{"_local_timestamp": "2026-01-25T23:41:00.630574+00:00", "data": {"market": "0x1c60f9adb1d786b6fe78d63fd9f82dbb293fa06241532fb5ba43f8d8411cde1e", "price_changes": [{"asset_id": "76633639806751295595699993448608387906622374020066717378577586177644656154703", "price": "0.73", "size": "0", "side": "BUY", "hash": "1315fd76bf729133555db7f6ed3ba775bcdaf489", "best_bid": "0.8", "best_ask": "0.82"}, {"asset_id": "5252381880374485440665230178984721306055940128786215274896991682225319468348", "price": "0.27", "size": "0", "side": "SELL", "hash": "cbc5b9f4b8af490670ce5f1f015ffaaf436b3fea", "best_bid": "0.18", "best_ask": "0.2"}], "timestamp": "1769384460555", "event_type": "price_change"}}
{"_local_timestamp": "2026-01-25T23:41:00.650503+00:00", "data": {"market": "0x1c60f9adb1d786b6fe78d63fd9f82dbb293fa06241532fb5ba43f8d8411cde1e", "price_changes": [{"asset_id": "76633639806751295595699993448608387906622374020066717378577586177644656154703", "price": "0.72", "size": "20", "side": "BUY", "hash": "789e6defdfeb22bc649bc155c7c5ffae5d16b978", "best_bid": "0.8", "best_ask": "0.82"}, {"asset_id": "5252381880374485440665230178984721306055940128786215274896991682225319468348", "price": "0.28", "size": "20", "side": "SELL", "hash": "34cfddc87de35f8c596a3be90b1a636f02b68d4d", "best_bid": "0.18", "best_ask": "0.2"}], "timestamp": "1769384460581", "event_type": "price_change"}}
{"_local_timestamp": "2026-01-25T23:41:17.950483+00:00", "data": {"market": "0x2bf6f2697e123f9bfb2c8788ed35741c67159ed19374886e6e7cb3f35e60f855", "price_changes": [{"asset_id": "36378160072890559704966692763500079412567571381443166092461911736222412577030", "price": "0.058", "size": "0", "side": "SELL", "hash": "5f80e55a35c50a2ffbe5272f49acff66303c34ac", "best_bid": "0.046", "best_ask": "0.056"}, {"asset_id": "49586088438166301401847652669972487503167459757949140750804630139416391309643", "price": "0.942", "size": "0", "side": "BUY", "hash": "68fa57ce76a448559a1545842cccc6618356314e", "best_bid": "0.944", "best_ask": "0.954"}], "timestamp": "1769384477840", "event_type": "price_change"}}
{"_local_timestamp": "2026-01-25T23:41:18.027790+00:00", "data": {"market": "0x2bf6f2697e123f9bfb2c8788ed35741c67159ed19374886e6e7cb3f35e60f855", "price_changes": [{"asset_id": "49586088438166301401847652669972487503167459757949140750804630139416391309643", "price": "0.926", "size": "254", "side": "BUY", "hash": "4ce18d7b0566e25ad49d29226df6154b8d16ad81", "best_bid": "0.944", "best_ask": "0.954"}, {"asset_id": "36378160072890559704966692763500079412567571381443166092461911736222412577030", "price": "0.074", "size": "254", "side": "SELL", "hash": "21af2b739d5736594d59c1472b43afd3ba54611f", "best_bid": "0.046", "best_ask": "0.056"}], "timestamp": "1769384477914", "event_type": "price_change"}}
{"_local_timestamp": "2026-01-25T23:41:18.103601+00:00", "data": {"market": "0x1c60f9adb1d786b6fe78d63fd9f82dbb293fa06241532fb5ba43f8d8411cde1e", "price_changes": [{"asset_id": "76633639806751295595699993448608387906622374020066717378577586177644656154703", "price": "0.72", "size": "70", "side": "BUY", "hash": "2e0eca0d5d1c13b38a493994715ec6e7d1c51ede", "best_bid": "0.8", "best_ask": "0.82"}, {"asset_id": "5252381880374485440665230178984721306055940128786215274896991682225319468348", "price": "0.28", "size": "70", "side": "SELL", "hash": "e0499c6bfa6266c84583bf8efe799d1e91623dfa", "best_bid": "0.18", "best_ask": "0.2"}], "timestamp": "1769384477997", "event_type": "price_change"}}
{"_local_timestamp": "2026-01-25T23:41:18.109575+00:00", "data": {"market": "0x1c60f9adb1d786b6fe78d63fd9f82dbb293fa06241532fb5ba43f8d8411cde1e", "price_changes": [{"asset_id": "76633639806751295595699993448608387906622374020066717378577586177644656154703", "price": "0.72", "size": "120", "side": "BUY", "hash": "32323e8ff4b1fb521b1139ab226784d45bee5fad", "best_bid": "0.8", "best_ask": "0.82"}, {"asset_id": "5252381880374485440665230178984721306055940128786215274896991682225319468348", "price": "0.28", "size": "120", "side": "SELL", "hash": "7e7ee2247fcc3cbeedcde62f611869b32f45a9a6", "best_bid": "0.18", "best_ask": "0.2"}], "timestamp": "1769384478001", "event_type": "price_change"}}
{"_local_timestamp": "2026-01-25T23:41:18.219273+00:00", "data": {"market": "0x1c60f9adb1d786b6fe78d63fd9f82dbb293fa06241532fb5ba43f8d8411cde1e", "price_changes": [{"asset_id": "76633639806751295595699993448608387906622374020066717378577586177644656154703", "price": "0.72", "size": "70", "side": "BUY", "hash": "0565dd01e11d31380377a183722131040d191432", "best_bid": "0.8", "best_ask": "0.82"}, {"asset_id": "5252381880374485440665230178984721306055940128786215274896991682225319468348", "price": "0.28", "size": "70", "side": "SELL", "hash": "37a570efa78932b6f9c79e9437f8c5b7918c05eb", "best_bid": "0.18", "best_ask": "0.2"}], "timestamp": "1769384478114", "event_type": "price_change"}}
{"_local_timestamp": "2026-01-25T23:41:23.202710+00:00", "data": {"market": "0x1c60f9adb1d786b6fe78d63fd9f82dbb293fa06241532fb5ba43f8d8411cde1e", "price_changes": [{"asset_id": "76633639806751295595699993448608387906622374020066717378577586177644656154703", "price": "0.72", "size": "50", "side": "BUY", "hash": "892153923115619f004f933325746ce448e6f5ff", "best_bid": "0.8", "best_ask": "0.82"}, {"asset_id": "5252381880374485440665230178984721306055940128786215274896991682225319468348", "price": "0.28", "size": "50", "side": "SELL", "hash": "7acca72dbf588a56f269d39521d2db5fa90572d5", "best_bid": "0.18", "best_ask": "0.2"}], "timestamp": "1769384483121", "event_type": "price_change"}}
{"_local_timestamp": "2026-01-25T23:41:23.226240+00:00", "data": {"market": "0x1c60f9adb1d786b6fe78d63fd9f82dbb293fa06241532fb5ba43f8d8411cde1e", "price_changes": [{"asset_id": "76633639806751295595699993448608387906622374020066717378577586177644656154703", "price": "0.73", "size": "20", "side": "BUY", "hash": "6555a5c08317d896ef109a6dd8dddaab69e9b3fa", "best_bid": "0.8", "best_ask": "0.82"}, {"asset_id": "5252381880374485440665230178984721306055940128786215274896991682225319468348", "price": "0.27", "size": "20", "side": "SELL", "hash": "ea34485a256160f3a56ad47b212099adaef9686a", "best_bid": "0.18", "best_ask": "0.2"}], "timestamp": "1769384483147", "event_type": "price_change"}}
{"_local_timestamp": "2026-01-25T23:41:23.311102+00:00", "data": {"market": "0x1c60f9adb1d786b6fe78d63fd9f82dbb293fa06241532fb5ba43f8d8411cde1e", "price_changes": [{"asset_id": "76633639806751295595699993448608387906622374020066717378577586177644656154703", "price": "0.72", "size": "100", "side": "BUY", "hash": "2fa314babca1e0045aba2448de89f66b7d7f1abe", "best_bid": "0.8", "best_ask": "0.82"}, {"asset_id": "5252381880374485440665230178984721306055940128786215274896991682225319468348", "price": "0.28", "size": "100", "side": "SELL", "hash": "8a506a9ff43c38d6eba2a4b04ddcd90d7c272def", "best_bid": "0.18", "best_ask": "0.2"}], "timestamp": "1769384483243", "event_type": "price_change"}}
{"_local_timestamp": "2026-01-25T23:41:23.329364+00:00", "data": {"market": "0x1c60f9adb1d786b6fe78d63fd9f82dbb293fa06241532fb5ba43f8d8411cde1e", "price_changes": [{"asset_id": "76633639806751295595699993448608387906622374020066717378577586177644656154703", "price": "0.72", "size": "50", "side": "BUY", "hash": "2bb50e61e629748d5166cb5effc95504e0b37cff", "best_bid": "0.8", "best_ask": "0.82"}, {"asset_id": "5252381880374485440665230178984721306055940128786215274896991682225319468348", "price": "0.28", "size": "50", "side": "SELL", "hash": "85de8b896c9fd3bc8a794abf7d5995473b390051", "best_bid": "0.18", "best_ask": "0.2"}], "timestamp": "1769384483262", "event_type": "price_change"}}
{"_local_timestamp": "2026-01-25T23:41:26.738299+00:00", "data": {"market": "0x3d2a697437b1093ad06d6a74c6fb5a2a499b15d7e895500b5153f66bfaa0e602", "price_changes": [{"asset_id": "29378510610351498292793924336050369056882113454472455899117956728534280393801", "price": "0.002", "size": "250", "side": "BUY", "hash": "abe0ab67a7faf8e1fa0e4fee75a9e86dc689f21e", "best_bid": "0.015", "best_ask": "0.019"}, {"asset_id": "88196724466506103782248946687236791868579928810145867200121613054260505717011", "price": "0.998", "size": "250", "side": "SELL", "hash": "30fc9f68b1542b7d67e9a2fd1a04ec5d3a33e2d3", "best_bid": "0.981", "best_ask": "0.985"}], "timestamp": "1769384486657", "event_type": "price_change"}}
{"_local_timestamp": "2026-01-25T23:41:26.746158+00:00", "data": {"market": "0xd6203f8805d1812e3b189da3f6036989940a415ae3a0fecf83555b455394fdb8", "price_changes": [{"asset_id": "46948910926280539794385431325138940193666253674995635848222141296489362188849", "price": "0.002", "size": "9666.18", "side": "BUY", "hash": "4f6a61e727626bcfd25a4666070da26b1759b69f", "best_bid": "0.028", "best_ask": "0.035"}, {"asset_id": "605623486066352556192926094200873695162641786747341465075860641086561702714", "price": "0.998", "size": "9666.18", "side": "SELL", "hash": "6e142bdcf5a9d87197800cd13d699e669c1c19f9", "best_bid": "0.965", "best_ask": "0.972"}], "timestamp": "1769384486657", "event_type": "price_change"}}
{"_local_timestamp": "2026-01-25T23:41:26.852287+00:00", "data": {"market": "0x1c60f9adb1d786b6fe78d63fd9f82dbb293fa06241532fb5ba43f8d8411cde1e", "price_changes": [{"asset_id": "76633639806751295595699993448608387906622374020066717378577586177644656154703", "price": "0.72", "size": "0", "side": "BUY", "hash": "444b451497a5d3802f840635733d137499b4b0b5", "best_bid": "0.8", "best_ask": "0.82"}, {"asset_id": "5252381880374485440665230178984721306055940128786215274896991682225319468348", "price": "0.28", "size": "0", "side": "SELL", "hash": "d548186a839306241d0b5a94e05c954cb71c483a", "best_bid": "0.18", "best_ask": "0.2"}], "timestamp": "1769384486780", "event_type": "price_change"}}
{"_local_timestamp": "2026-01-25T23:41:27.359712+00:00", "data": {"market": "0x1c60f9adb1d786b6fe78d63fd9f82dbb293fa06241532fb5ba43f8d8411cde1e", "price_changes": [{"asset_id": "76633639806751295595699993448608387906622374020066717378577586177644656154703", "price": "0.73", "size": "0", "side": "BUY", "hash": "214533301102979368870632728299afa4a5ac8e", "best_bid": "0.8", "best_ask": "0.82"}, {"asset_id": "5252381880374485440665230178984721306055940128786215274896991682225319468348", "price": "0.27", "size": "0", "side": "SELL", "hash": "6dba5e18daa0c128289a4e33d319f6667e96d4bc", "best_bid": "0.18", "best_ask": "0.2"}], "timestamp": "1769384487288", "event_type": "price_change"}}
{"_local_timestamp": "2026-01-25T23:41:27.390171+00:00", "data": {"market": "0x1c60f9adb1d786b6fe78d63fd9f82dbb293fa06241532fb5ba43f8d8411cde1e", "price_changes": [{"asset_id": "76633639806751295595699993448608387906622374020066717378577586177644656154703", "price": "0.72", "size": "20", "side": "BUY", "hash": "65da092005a37ddadcf116f847da372ffbfec227", "best_bid": "0.8", "best_ask": "0.82"}, {"asset_id": "5252381880374485440665230178984721306055940128786215274896991682225319468348", "price": "0.28", "size": "20", "side": "SELL", "hash": "763066d83e118b85d4d6cf9db7deff26425cb9ac", "best_bid": "0.18", "best_ask": "0.2"}], "timestamp": "1769384487315", "event_type": "price_change"}}
{"_local_timestamp": "2026-01-25T23:41:27.570811+00:00", "data": {"market": "0x1c60f9adb1d786b6fe78d63fd9f82dbb293fa06241532fb5ba43f8d8411cde1e", "price_changes": [{"asset_id": "76633639806751295595699993448608387906622374020066717378577586177644656154703", "price": "0.72", "size": "70", "side": "BUY", "hash": "a87546b8295ab922e69e5114f6f42886932e04fb", "best_bid": "0.8", "best_ask": "0.82"}, {"asset_id": "5252381880374485440665230178984721306055940128786215274896991682225319468348", "price": "0.28", "size": "70", "side": "SELL", "hash": "53a7d88789331cd58343772d6c3f98db6cfae0e3", "best_bid": "0.18", "best_ask": "0.2"}], "timestamp": "1769384487492", "event_type": "price_change"}}
{"_local_timestamp": "2026-01-25T23:41:27.671215+00:00", "data": {"market": "0x1c60f9adb1d786b6fe78d63fd9f82dbb293fa06241532fb5ba43f8d8411cde1e", "price_changes": [{"asset_id": "76633639806751295595699993448608387906622374020066717378577586177644656154703", "price": "0.72", "size": "120", "side": "BUY", "hash": "a91ce764efc253fe9ca2a66c226493129628167f", "best_bid": "0.8", "best_ask": "0.82"}, {"asset_id": "5252381880374485440665230178984721306055940128786215274896991682225319468348", "price": "0.28", "size": "120", "side": "SELL", "hash": "35711316201d0398317e18fbd6effbb74dd2c999", "best_bid": "0.18", "best_ask": "0.2"}], "timestamp": "1769384487599", "event_type": "price_change"}}
{"_local_timestamp": "2026-01-25T23:41:29.183679+00:00", "data": {"market": "0x1c60f9adb1d786b6fe78d63fd9f82dbb293fa06241532fb5ba43f8d8411cde1e", "price_changes": [{"asset_id": "76633639806751295595699993448608387906622374020066717378577586177644656154703", "price": "0.72", "size": "100", "side": "BUY", "hash": "84d4dc31fff50e47ea7833184636a120f36189cf", "best_bid": "0.8", "best_ask": "0.82"}, {"asset_id": "5252381880374485440665230178984721306055940128786215274896991682225319468348", "price": "0.28", "size": "100", "side": "SELL", "hash": "17b6c7b1cb83601ed2a1cd1b485abc36186cc93c", "best_bid": "0.18", "best_ask": "0.2"}], "timestamp": "1769384489105", "event_type": "price_change"}}
{"_local_timestamp": "2026-01-25T23:41:29.209948+00:00", "data": {"market": "0x1c60f9adb1d786b6fe78d63fd9f82dbb293fa06241532fb5ba43f8d8411cde1e", "price_changes": [{"asset_id": "76633639806751295595699993448608387906622374020066717378577586177644656154703", "price": "0.73", "size": "20", "side": "BUY", "hash": "ec39bbb8e7a7d6eba0781edab4ffeb3d0fa0ea07", "best_bid": "0.8", "best_ask": "0.82"}, {"asset_id": "5252381880374485440665230178984721306055940128786215274896991682225319468348", "price": "0.27", "size": "20", "side": "SELL", "hash": "012db1022c4ec3848aff30a9141cfcd88b2bf4c0", "best_bid": "0.18", "best_ask": "0.2"}], "timestamp": "1769384489131", "event_type": "price_change"}}
{"_local_timestamp": "2026-01-25T23:41:29.310020+00:00", "data": {"market": "0x1c60f9adb1d786b6fe78d63fd9f82dbb293fa06241532fb5ba43f8d8411cde1e", "price_changes": [{"asset_id": "76633639806751295595699993448608387906622374020066717378577586177644656154703", "price": "0.72", "size": "50", "side": "BUY", "hash": "4c073c487cfcfa9228fa97b9ca0903f2e514be29", "best_bid": "0.8", "best_ask": "0.82"}, {"asset_id": "5252381880374485440665230178984721306055940128786215274896991682225319468348", "price": "0.28", "size": "50", "side": "SELL", "hash": "d85158ffe48e6a74740c459a6b3ba857bb8b9ddb", "best_bid": "0.18", "best_ask": "0.2"}], "timestamp": "1769384489244", "event_type": "price_change"}}
{"_local_timestamp": "2026-01-25T23:41:29.360626+00:00", "data": {"market": "0x1c60f9adb1d786b6fe78d63fd9f82dbb293fa06241532fb5ba43f8d8411cde1e", "price_changes": [{"asset_id": "76633639806751295595699993448608387906622374020066717378577586177644656154703", "price": "0.72", "size": "0", "side": "BUY", "hash": "67c18d58e2814d2dacd2d840af5dd2dc443fff1b", "best_bid": "0.8", "best_ask": "0.82"}, {"asset_id": "5252381880374485440665230178984721306055940128786215274896991682225319468348", "price": "0.28", "size": "0", "side": "SELL", "hash": "a47bb20e7d4c2034352632d8ebf04d0bad27d9ee", "best_bid": "0.18", "best_ask": "0.2"}], "timestamp": "1769384489286", "event_type": "price_change"}}
{"_local_timestamp": "2026-01-25T23:41:29.404467+00:00", "data": {"market": "0xd6203f8805d1812e3b189da3f6036989940a415ae3a0fecf83555b455394fdb8", "price_changes": [{"asset_id": "46948910926280539794385431325138940193666253674995635848222141296489362188849", "price": "0.002", "size": "9679.78", "side": "BUY", "hash": "58040ba8837837cc2a4d812eb3779416b10d6745", "best_bid": "0.028", "best_ask": "0.035"}, {"asset_id": "605623486066352556192926094200873695162641786747341465075860641086561702714", "price": "0.998", "size": "9679.78", "side": "SELL", "hash": "5b5fa8511de6198b6f4886aada0d759b94fd0189", "best_bid": "0.965", "best_ask": "0.972"}], "timestamp": "1769384489329", "event_type": "price_change"}}
{"_local_timestamp": "2026-01-25T23:41:29.408983+00:00", "data": {"market": "0x3d2a697437b1093ad06d6a74c6fb5a2a499b15d7e895500b5153f66bfaa0e602", "price_changes": [{"asset_id": "29378510610351498292793924336050369056882113454472455899117956728534280393801", "price": "0.002", "size": "316.66", "side": "BUY", "hash": "80db8ad1bfc2f5a81edeaddc4d03d25b0400ad73", "best_bid": "0.015", "best_ask": "0.019"}, {"asset_id": "88196724466506103782248946687236791868579928810145867200121613054260505717011", "price": "0.998", "size": "316.66", "side": "SELL", "hash": "2a3bda763300732aba792f50c00f3d5fb94abc8c", "best_bid": "0.981", "best_ask": "0.985"}], "timestamp": "1769384489329", "event_type": "price_change"}}
{"_local_timestamp": "2026-01-25T23:41:30.331158+00:00", "data": {"market": "0x1c60f9adb1d786b6fe78d63fd9f82dbb293fa06241532fb5ba43f8d8411cde1e", "price_changes": [{"asset_id": "76633639806751295595699993448608387906622374020066717378577586177644656154703", "price": "0.73", "size": "0", "side": "BUY", "hash": "2920766f68f0419e2237f4db50d46829cdf8551e", "best_bid": "0.8", "best_ask": "0.82"}, {"asset_id": "5252381880374485440665230178984721306055940128786215274896991682225319468348", "price": "0.27", "size": "0", "side": "SELL", "hash": "1666db2022a1a9f1eb1c5dd5099783341c4fdb46", "best_bid": "0.18", "best_ask": "0.2"}], "timestamp": "1769384490259", "event_type": "price_change"}}
{"_local_timestamp": "2026-01-25T23:41:30.374204+00:00", "data": {"market": "0x1c60f9adb1d786b6fe78d63fd9f82dbb293fa06241532fb5ba43f8d8411cde1e", "price_changes": [{"asset_id": "76633639806751295595699993448608387906622374020066717378577586177644656154703", "price": "0.72", "size": "20", "side": "BUY", "hash": "aff62a7de8328655bf6c58d4da13fa66d84ffd4e", "best_bid": "0.8", "best_ask": "0.82"}, {"asset_id": "5252381880374485440665230178984721306055940128786215274896991682225319468348", "price": "0.28", "size": "20", "side": "SELL", "hash": "8c8c8af34589c40c7df5b39224f58b8e189cf46c", "best_bid": "0.18", "best_ask": "0.2"}], "timestamp": "1769384490286", "event_type": "price_change"}}
{"_local_timestamp": "2026-01-25T23:41:44.430139+00:00", "data": {"market": "0xe6120576744ed4a770a37a962e5e1f13eca78070b05575c9dc118cc64cf000ba", "price_changes": [{"asset_id": "61485373804686118235598970240104189606288982592130954871186471768147590870705", "price": "0.617", "size": "0", "side": "BUY", "hash": "2a3a7590bfe440713fb30a816525c8d8bb16cdc3", "best_bid": "0.993", "best_ask": "0.995"}, {"asset_id": "88202144797456094004565715683071874971451541348187754361676449702242116892606", "price": "0.383", "size": "0", "side": "SELL", "hash": "b53f1034c4ad9a2d33550c1f58d767b1040bf93c", "best_bid": "0.005", "best_ask": "0.007"}], "timestamp": "1769384504362", "event_type": "price_change"}}
{"_local_timestamp": "2026-01-25T23:41:44.485094+00:00", "data": {"market": "0xe6120576744ed4a770a37a962e5e1f13eca78070b05575c9dc118cc64cf000ba", "price_changes": [{"asset_id": "61485373804686118235598970240104189606288982592130954871186471768147590870705", "price": "0.625", "size": "5", "side": "BUY", "hash": "227900016f43910cc839948c054b798965b82eeb", "best_bid": "0.993", "best_ask": "0.995"}, {"asset_id": "88202144797456094004565715683071874971451541348187754361676449702242116892606", "price": "0.375", "size": "5", "side": "SELL", "hash": "f1419f8177318c5d4e7b786f949164da66820160", "best_bid": "0.005", "best_ask": "0.007"}], "timestamp": "1769384504409", "event_type": "price_change"}}
{"_local_timestamp": "2026-01-25T23:41:44.535273+00:00", "data": {"market": "0x1c60f9adb1d786b6fe78d63fd9f82dbb293fa06241532fb5ba43f8d8411cde1e", "price_changes": [{"asset_id": "76633639806751295595699993448608387906622374020066717378577586177644656154703", "price": "0.72", "size": "70", "side": "BUY", "hash": "00f609929dadc99a427bfc000db3f6154d449379", "best_bid": "0.8", "best_ask": "0.82"}, {"asset_id": "5252381880374485440665230178984721306055940128786215274896991682225319468348", "price": "0.28", "size": "70", "side": "SELL", "hash": "8a591717d24ffa413fe11c9080025ae8d6d63294", "best_bid": "0.18", "best_ask": "0.2"}], "timestamp": "1769384504466", "event_type": "price_change"}}
{"_local_timestamp": "2026-01-25T23:41:44.550335+00:00", "data": {"market": "0x1c60f9adb1d786b6fe78d63fd9f82dbb293fa06241532fb5ba43f8d8411cde1e", "price_changes": [{"asset_id": "76633639806751295595699993448608387906622374020066717378577586177644656154703", "price": "0.72", "size": "120", "side": "BUY", "hash": "f342153d336f49016f5130f2276aa41b7aa33546", "best_bid": "0.8", "best_ask": "0.82"}, {"asset_id": "5252381880374485440665230178984721306055940128786215274896991682225319468348", "price": "0.28", "size": "120", "side": "SELL", "hash": "9774e78468298fbbe9b111e16097352634a7ae9a", "best_bid": "0.18", "best_ask": "0.2"}], "timestamp": "1769384504481", "event_type": "price_change"}}
{"_local_timestamp": "2026-01-25T23:41:46.763636+00:00", "data": {"market": "0x1c60f9adb1d786b6fe78d63fd9f82dbb293fa06241532fb5ba43f8d8411cde1e", "price_changes": [{"asset_id": "76633639806751295595699993448608387906622374020066717378577586177644656154703", "price": "0.72", "size": "100", "side": "BUY", "hash": "5e05cd83ee6176b43341b22cdf63b2bab5178be3", "best_bid": "0.8", "best_ask": "0.82"}, {"asset_id": "5252381880374485440665230178984721306055940128786215274896991682225319468348", "price": "0.28", "size": "100", "side": "SELL", "hash": "ac6a013ba133d604ecb7d9ccd4dd7072dd46b2ce", "best_bid": "0.18", "best_ask": "0.2"}], "timestamp": "1769384506686", "event_type": "price_change"}}
{"_local_timestamp": "2026-01-25T23:41:46.785569+00:00", "data": {"market": "0x1c60f9adb1d786b6fe78d63fd9f82dbb293fa06241532fb5ba43f8d8411cde1e", "price_changes": [{"asset_id": "76633639806751295595699993448608387906622374020066717378577586177644656154703", "price": "0.73", "size": "20", "side": "BUY", "hash": "4fa0144cdd7c223b77ee7f572a20a7fe488dd2d4", "best_bid": "0.8", "best_ask": "0.82"}, {"asset_id": "5252381880374485440665230178984721306055940128786215274896991682225319468348", "price": "0.27", "size": "20", "side": "SELL", "hash": "fd363d15031dcf649f1d5ff20a2c77e437420e5f", "best_bid": "0.18", "best_ask": "0.2"}], "timestamp": "1769384506712", "event_type": "price_change"}}
{"_local_timestamp": "2026-01-25T23:41:46.890363+00:00", "data": {"market": "0x1c60f9adb1d786b6fe78d63fd9f82dbb293fa06241532fb5ba43f8d8411cde1e", "price_changes": [{"asset_id": "76633639806751295595699993448608387906622374020066717378577586177644656154703", "price": "0.72", "size": "50", "side": "BUY", "hash": "cb3d8dcf0951d28f358b9a93cdc342ce6240b02b", "best_bid": "0.8", "best_ask": "0.82"}, {"asset_id": "5252381880374485440665230178984721306055940128786215274896991682225319468348", "price": "0.28", "size": "50", "side": "SELL", "hash": "25823212e8a3c9cd98793ec69d52da8a722232d8", "best_bid": "0.18", "best_ask": "0.2"}], "timestamp": "1769384506823", "event_type": "price_change"}}
{"_local_timestamp": "2026-01-25T23:41:46.899334+00:00", "data": {"market": "0x1c60f9adb1d786b6fe78d63fd9f82dbb293fa06241532fb5ba43f8d8411cde1e", "price_changes": [{"asset_id": "76633639806751295595699993448608387906622374020066717378577586177644656154703", "price": "0.72", "size": "0", "side": "BUY", "hash": "a5a64f42f00d31abbd93ece0ecfcb91f2dcd2fe1", "best_bid": "0.8", "best_ask": "0.82"}, {"asset_id": "5252381880374485440665230178984721306055940128786215274896991682225319468348", "price": "0.28", "size": "0", "side": "SELL", "hash": "be57d54ae581cd2f71740f75d0caf18e31b57bd2", "best_bid": "0.18", "best_ask": "0.2"}], "timestamp": "1769384506824", "event_type": "price_change"}}
{"_local_timestamp": "2026-01-25T23:41:48.049703+00:00", "data": {"market": "0x1c60f9adb1d786b6fe78d63fd9f82dbb293fa06241532fb5ba43f8d8411cde1e", "price_changes": [{"asset_id": "76633639806751295595699993448608387906622374020066717378577586177644656154703", "price": "0.73", "size": "0", "side": "BUY", "hash": "eb8f158d10eada5cd3152fb4231207c605eb512d", "best_bid": "0.8", "best_ask": "0.82"}, {"asset_id": "5252381880374485440665230178984721306055940128786215274896991682225319468348", "price": "0.27", "size": "0", "side": "SELL", "hash": "bf8fc9cc35c3c31178d194da63aec2f46f2ef49a", "best_bid": "0.18", "best_ask": "0.2"}], "timestamp": "1769384507984", "event_type": "price_change"}}
{"_local_timestamp": "2026-01-25T23:41:48.146798+00:00", "data": {"market": "0x1c60f9adb1d786b6fe78d63fd9f82dbb293fa06241532fb5ba43f8d8411cde1e", "price_changes": [{"asset_id": "76633639806751295595699993448608387906622374020066717378577586177644656154703", "price": "0.72", "size": "20", "side": "BUY", "hash": "94da33d23626b172b5edea00812b30293a7d89af", "best_bid": "0.8", "best_ask": "0.82"}, {"asset_id": "5252381880374485440665230178984721306055940128786215274896991682225319468348", "price": "0.28", "size": "20", "side": "SELL", "hash": "38e410c5b9aaf0e0cb2cd76fc70c25a466c517df", "best_bid": "0.18", "best_ask": "0.2"}], "timestamp": "1769384508009", "event_type": "price_change"}}
{"_local_timestamp": "2026-01-25T23:41:55.103653+00:00", "data": {"market": "0x9954b4eef49a268b810bc260ee9278361e29a8f6f4ad816a804dd613ef73a968", "price_changes": [{"asset_id": "407336258606092316833789781486672854343361331985279263948001098476429338355", "price": "0.939", "size": "513.1", "side": "SELL", "hash": "952d25047813351f90fbfb2d408fe4305728e132", "best_bid": "0.848", "best_ask": "0.881"}, {"asset_id": "50692628443801018513325614545746863026982626993302787461752145605052144027838", "price": "0.061", "size": "513.1", "side": "BUY", "hash": "c861c4a6bcea0f3a69bf82ca8ffeec7be1da98d3", "best_bid": "0.119", "best_ask": "0.152"}], "timestamp": "1769384515021", "event_type": "price_change"}}
{"_local_timestamp": "2026-01-25T23:41:55.202097+00:00", "data": {"market": "0x1c60f9adb1d786b6fe78d63fd9f82dbb293fa06241532fb5ba43f8d8411cde1e", "price_changes": [{"asset_id": "76633639806751295595699993448608387906622374020066717378577586177644656154703", "price": "0.72", "size": "70", "side": "BUY", "hash": "195952b0098df419d3657ec24378783fdecf5794", "best_bid": "0.8", "best_ask": "0.82"}, {"asset_id": "5252381880374485440665230178984721306055940128786215274896991682225319468348", "price": "0.28", "size": "70", "side": "SELL", "hash": "517410cfb2979e16ed31d6e72f9d421d67ddc54f", "best_bid": "0.18", "best_ask": "0.2"}], "timestamp": "1769384515129", "event_type": "price_change"}}
{"_local_timestamp": "2026-01-25T23:41:55.204331+00:00", "data": {"market": "0x1c60f9adb1d786b6fe78d63fd9f82dbb293fa06241532fb5ba43f8d8411cde1e", "price_changes": [{"asset_id": "76633639806751295595699993448608387906622374020066717378577586177644656154703", "price": "0.72", "size": "120", "side": "BUY", "hash": "3eb1897d1b67878e925400dd0981d695c4b68a52", "best_bid": "0.8", "best_ask": "0.82"}, {"asset_id": "5252381880374485440665230178984721306055940128786215274896991682225319468348", "price": "0.28", "size": "120", "side": "SELL", "hash": "89dcd0e98aabf2862c4a1cea1961a1e8d5c421cb", "best_bid": "0.18", "best_ask": "0.2"}], "timestamp": "1769384515133", "event_type": "price_change"}}
{"_local_timestamp": "2026-01-25T23:42:00.412269+00:00", "data": {"market": "0x1c60f9adb1d786b6fe78d63fd9f82dbb293fa06241532fb5ba43f8d8411cde1e", "price_changes": [{"asset_id": "76633639806751295595699993448608387906622374020066717378577586177644656154703", "price": "0.72", "size": "100", "side": "BUY", "hash": "533dd8de34c4818b18759f4ffb03dc3b033d785f", "best_bid": "0.8", "best_ask": "0.82"}, {"asset_id": "5252381880374485440665230178984721306055940128786215274896991682225319468348", "price": "0.28", "size": "100", "side": "SELL", "hash": "2525a51489e7c4593192d9e780eb1edaa7f87b33", "best_bid": "0.18", "best_ask": "0.2"}], "timestamp": "1769384520345", "event_type": "price_change"}}
{"_local_timestamp": "2026-01-25T23:42:00.444510+00:00", "data": {"market": "0x1c60f9adb1d786b6fe78d63fd9f82dbb293fa06241532fb5ba43f8d8411cde1e", "price_changes": [{"asset_id": "76633639806751295595699993448608387906622374020066717378577586177644656154703", "price": "0.73", "size": "20", "side": "BUY", "hash": "5b7747c659f92ff3502b43c6c88862669bb5e096", "best_bid": "0.8", "best_ask": "0.82"}, {"asset_id": "5252381880374485440665230178984721306055940128786215274896991682225319468348", "price": "0.27", "size": "20", "side": "SELL", "hash": "06a51c65e9b65ae3e7ab005648800887979d877c", "best_bid": "0.18", "best_ask": "0.2"}], "timestamp": "1769384520373", "event_type": "price_change"}}
{"_local_timestamp": "2026-01-25T23:42:00.557305+00:00", "data": {"market": "0x1c60f9adb1d786b6fe78d63fd9f82dbb293fa06241532fb5ba43f8d8411cde1e", "price_changes": [{"asset_id": "76633639806751295595699993448608387906622374020066717378577586177644656154703", "price": "0.72", "size": "50", "side": "BUY", "hash": "eb2ce81557249117b7686a9b11ccb9b3cd3105df", "best_bid": "0.8", "best_ask": "0.82"}, {"asset_id": "5252381880374485440665230178984721306055940128786215274896991682225319468348", "price": "0.28", "size": "50", "side": "SELL", "hash": "4df9670de99ddccad7ef8627137c7ba5d968889c", "best_bid": "0.18", "best_ask": "0.2"}], "timestamp": "1769384520485", "event_type": "price_change"}}
{"_local_timestamp": "2026-01-25T23:42:00.559362+00:00", "data": {"market": "0x1c60f9adb1d786b6fe78d63fd9f82dbb293fa06241532fb5ba43f8d8411cde1e", "price_changes": [{"asset_id": "76633639806751295595699993448608387906622374020066717378577586177644656154703", "price": "0.72", "size": "0", "side": "BUY", "hash": "efcc2608253935cee65ec3333ade6223603e2ded", "best_bid": "0.8", "best_ask": "0.82"}, {"asset_id": "5252381880374485440665230178984721306055940128786215274896991682225319468348", "price": "0.28", "size": "0", "side": "SELL", "hash": "198cd1e286b42dc8b6ecce467b925d5250c1f57f", "best_bid": "0.18", "best_ask": "0.2"}], "timestamp": "1769384520486", "event_type": "price_change"}}
{"_local_timestamp": "2026-01-25T23:42:03.591145+00:00", "data": {"market": "0x1c60f9adb1d786b6fe78d63fd9f82dbb293fa06241532fb5ba43f8d8411cde1e", "price_changes": [{"asset_id": "76633639806751295595699993448608387906622374020066717378577586177644656154703", "price": "0.73", "size": "0", "side": "BUY", "hash": "a3580a1bab0ffe17a172c44d63f9ac3b722ba0c5", "best_bid": "0.8", "best_ask": "0.82"}, {"asset_id": "5252381880374485440665230178984721306055940128786215274896991682225319468348", "price": "0.27", "size": "0", "side": "SELL", "hash": "69d8064b9a33d3ba66ae8630cc4f16c510a49d46", "best_bid": "0.18", "best_ask": "0.2"}], "timestamp": "1769384523516", "event_type": "price_change"}}
{"_local_timestamp": "2026-01-25T23:42:03.610128+00:00", "data": {"market": "0x1c60f9adb1d786b6fe78d63fd9f82dbb293fa06241532fb5ba43f8d8411cde1e", "price_changes": [{"asset_id": "76633639806751295595699993448608387906622374020066717378577586177644656154703", "price": "0.72", "size": "20", "side": "BUY", "hash": "c2ada57c3df4531e3a2e078d8d4781c03e692d08", "best_bid": "0.8", "best_ask": "0.82"}, {"asset_id": "5252381880374485440665230178984721306055940128786215274896991682225319468348", "price": "0.28", "size": "20", "side": "SELL", "hash": "65ea5c5ca43e10454efbf9a0863aa0b3a67e7b50", "best_bid": "0.18", "best_ask": "0.2"}], "timestamp": "1769384523541", "event_type": "price_change"}}
{"_local_timestamp": "2026-01-25T23:42:03.729698+00:00", "data": {"market": "0x1c60f9adb1d786b6fe78d63fd9f82dbb293fa06241532fb5ba43f8d8411cde1e", "price_changes": [{"asset_id": "76633639806751295595699993448608387906622374020066717378577586177644656154703", "price": "0.72", "size": "70", "side": "BUY", "hash": "e90ee175dd83df9264fcabca5d1ff620a270aea8", "best_bid": "0.8", "best_ask": "0.82"}, {"asset_id": "5252381880374485440665230178984721306055940128786215274896991682225319468348", "price": "0.28", "size": "70", "side": "SELL", "hash": "c5562b66d9013a3afe893c2845b66133a7a51b9a", "best_bid": "0.18", "best_ask": "0.2"}], "timestamp": "1769384523658", "event_type": "price_change"}}
{"_local_timestamp": "2026-01-25T23:42:03.759794+00:00", "data": {"market": "0x1c60f9adb1d786b6fe78d63fd9f82dbb293fa06241532fb5ba43f8d8411cde1e", "price_changes": [{"asset_id": "76633639806751295595699993448608387906622374020066717378577586177644656154703", "price": "0.72", "size": "120", "side": "BUY", "hash": "f887aa4b4a43f6dbd87c4e2d2aa7e65d7a451de7", "best_bid": "0.8", "best_ask": "0.82"}, {"asset_id": "5252381880374485440665230178984721306055940128786215274896991682225319468348", "price": "0.28", "size": "120", "side": "SELL", "hash": "c0bb91419357e7c3e0659835b02a0fda0e468763", "best_bid": "0.18", "best_ask": "0.2"}], "timestamp": "1769384523660", "event_type": "price_change"}}
{"_local_timestamp": "2026-01-25T23:42:03.846812+00:00", "data": {"market": "0x1c60f9adb1d786b6fe78d63fd9f82dbb293fa06241532fb5ba43f8d8411cde1e", "price_changes": [{"asset_id": "76633639806751295595699993448608387906622374020066717378577586177644656154703", "price": "0.72", "size": "70", "side": "BUY", "hash": "8e2de278503cb67b35a6ddd7f5bb9cc7d4d9dff0", "best_bid": "0.8", "best_ask": "0.82"}, {"asset_id": "5252381880374485440665230178984721306055940128786215274896991682225319468348", "price": "0.28", "size": "70", "side": "SELL", "hash": "660ba382f62fc38d9425e236fc323044d1e2ee23", "best_bid": "0.18", "best_ask": "0.2"}], "timestamp": "1769384523775", "event_type": "price_change"}}
{"_local_timestamp": "2026-01-25T23:42:03.885470+00:00", "data": {"market": "0xa3186ffc28c45f336920279d5085529d530690a1623997819f3a3db05119dbaa", "price_changes": [{"asset_id": "100637244310881573755436157770787626078576925658681383187976739528804051076924", "price": "0.376", "size": "0", "side": "BUY", "hash": "29f078e03aa1dbaf1258292cad5b4869b46f2773", "best_bid": "0.777", "best_ask": "0.779"}, {"asset_id": "76284775424209240264542352208573338636556198300439966875308967535434111103074", "price": "0.624", "size": "0", "side": "SELL", "hash": "9a6cf1a5390d9c37d60ab7d44729fefb06cd3b08", "best_bid": "0.221", "best_ask": "0.223"}], "timestamp": "1769384523811", "event_type": "price_change"}}
{"_local_timestamp": "2026-01-25T23:42:04.203910+00:00", "data": {"market": "0xa3186ffc28c45f336920279d5085529d530690a1623997819f3a3db05119dbaa", "price_changes": [{"asset_id": "100637244310881573755436157770787626078576925658681383187976739528804051076924", "price": "0.75", "size": "500", "side": "BUY", "hash": "7499c4929705cb9f078c921f8228d3e3e4b1ac3f", "best_bid": "0.777", "best_ask": "0.779"}, {"asset_id": "76284775424209240264542352208573338636556198300439966875308967535434111103074", "price": "0.25", "size": "500", "side": "SELL", "hash": "f5a32bd69d2326a30a5f50f4c2c3e7354ae0ebcd", "best_bid": "0.221", "best_ask": "0.223"}], "timestamp": "1769384524135", "event_type": "price_change"}}
{"_local_timestamp": "2026-01-25T23:42:04.332482+00:00", "data": {"market": "0x1c60f9adb1d786b6fe78d63fd9f82dbb293fa06241532fb5ba43f8d8411cde1e", "price_changes": [{"asset_id": "76633639806751295595699993448608387906622374020066717378577586177644656154703", "price": "0.72", "size": "120", "side": "BUY", "hash": "d715c7a2ebd44fb3566b2b941cb0582775c20520", "best_bid": "0.8", "best_ask": "0.82"}, {"asset_id": "5252381880374485440665230178984721306055940128786215274896991682225319468348", "price": "0.28", "size": "120", "side": "SELL", "hash": "4b74a80f5abf93a28193d162750bd90eba2563ec", "best_bid": "0.18", "best_ask": "0.2"}], "timestamp": "1769384524261", "event_type": "price_change"}}
{"_local_timestamp": "2026-01-25T23:42:04.359572+00:00", "data": {"market": "0xa3186ffc28c45f336920279d5085529d530690a1623997819f3a3db05119dbaa", "price_changes": [{"asset_id": "100637244310881573755436157770787626078576925658681383187976739528804051076924", "price": "0.378", "size": "10", "side": "BUY", "hash": "9c3ff1f0f81872c5df206e5dd2d17432c277b3b9", "best_bid": "0.777", "best_ask": "0.779"}, {"asset_id": "76284775424209240264542352208573338636556198300439966875308967535434111103074", "price": "0.622", "size": "10", "side": "SELL", "hash": "f584755ef2d0ef47c0a8c7e0ed8c39a87eb1beb2", "best_bid": "0.221", "best_ask": "0.223"}], "timestamp": "1769384524290", "event_type": "price_change"}}
{"_local_timestamp": "2026-01-25T23:42:05.894113+00:00", "data": {"market": "0x1c60f9adb1d786b6fe78d63fd9f82dbb293fa06241532fb5ba43f8d8411cde1e", "price_changes": [{"asset_id": "76633639806751295595699993448608387906622374020066717378577586177644656154703", "price": "0.72", "size": "100", "side": "BUY", "hash": "8ad70e2667a6568162aa6e2f2b73869687eedb37", "best_bid": "0.8", "best_ask": "0.82"}, {"asset_id": "5252381880374485440665230178984721306055940128786215274896991682225319468348", "price": "0.28", "size": "100", "side": "SELL", "hash": "0b8c58785f4d54a8598a7930f206ae7d25fad498", "best_bid": "0.18", "best_ask": "0.2"}], "timestamp": "1769384525819", "event_type": "price_change"}}
{"_local_timestamp": "2026-01-25T23:42:05.923252+00:00", "data": {"market": "0x1c60f9adb1d786b6fe78d63fd9f82dbb293fa06241532fb5ba43f8d8411cde1e", "price_changes": [{"asset_id": "76633639806751295595699993448608387906622374020066717378577586177644656154703", "price": "0.73", "size": "20", "side": "BUY", "hash": "dc434cd19588dd8977a3c9ab64229c1d8989da32", "best_bid": "0.8", "best_ask": "0.82"}, {"asset_id": "5252381880374485440665230178984721306055940128786215274896991682225319468348", "price": "0.27", "size": "20", "side": "SELL", "hash": "0a014a25727791671465a646df6bbfb5c045118e", "best_bid": "0.18", "best_ask": "0.2"}], "timestamp": "1769384525848", "event_type": "price_change"}}
{"_local_timestamp": "2026-01-25T23:42:06.035403+00:00", "data": {"market": "0x1c60f9adb1d786b6fe78d63fd9f82dbb293fa06241532fb5ba43f8d8411cde1e", "price_changes": [{"asset_id": "76633639806751295595699993448608387906622374020066717378577586177644656154703", "price": "0.72", "size": "50", "side": "BUY", "hash": "5f374e86281ee2e11743272a7ff3b5fd269bfe72", "best_bid": "0.8", "best_ask": "0.82"}, {"asset_id": "5252381880374485440665230178984721306055940128786215274896991682225319468348", "price": "0.28", "size": "50", "side": "SELL", "hash": "332c2d2cec30a64669ab91ee0ac7b93a9efd8644", "best_bid": "0.18", "best_ask": "0.2"}], "timestamp": "1769384525969", "event_type": "price_change"}}
{"_local_timestamp": "2026-01-25T23:42:06.043260+00:00", "data": {"market": "0x1c60f9adb1d786b6fe78d63fd9f82dbb293fa06241532fb5ba43f8d8411cde1e", "price_changes": [{"asset_id": "76633639806751295595699993448608387906622374020066717378577586177644656154703", "price": "0.72", "size": "0", "side": "BUY", "hash": "b55c4ee4c887be5cb4d50db9037bb21ba5a23715", "best_bid": "0.8", "best_ask": "0.82"}, {"asset_id": "5252381880374485440665230178984721306055940128786215274896991682225319468348", "price": "0.28", "size": "0", "side": "SELL", "hash": "b2911c848d5d15fe5f8d91eba15fd5e18c7dbd8a", "best_bid": "0.18", "best_ask": "0.2"}], "timestamp": "1769384525972", "event_type": "price_change"}}
{"_local_timestamp": "2026-01-25T23:42:08.508840+00:00", "data": {"market": "0x1c60f9adb1d786b6fe78d63fd9f82dbb293fa06241532fb5ba43f8d8411cde1e", "price_changes": [{"asset_id": "76633639806751295595699993448608387906622374020066717378577586177644656154703", "price": "0.73", "size": "0", "side": "BUY", "hash": "3a881e97ebde11942c2f90731b989f1960ef050a", "best_bid": "0.8", "best_ask": "0.82"}, {"asset_id": "5252381880374485440665230178984721306055940128786215274896991682225319468348", "price": "0.27", "size": "0", "side": "SELL", "hash": "4776ec4bdf6b1f7634527b02680cf4f1dea1b871", "best_bid": "0.18", "best_ask": "0.2"}], "timestamp": "1769384528433", "event_type": "price_change"}}
{"_local_timestamp": "2026-01-25T23:42:08.549344+00:00", "data": {"market": "0x1c60f9adb1d786b6fe78d63fd9f82dbb293fa06241532fb5ba43f8d8411cde1e", "price_changes": [{"asset_id": "76633639806751295595699993448608387906622374020066717378577586177644656154703", "price": "0.72", "size": "20", "side": "BUY", "hash": "5dd35fbb8a066a2c21079de7ff9f76d6972b7c14", "best_bid": "0.8", "best_ask": "0.82"}, {"asset_id": "5252381880374485440665230178984721306055940128786215274896991682225319468348", "price": "0.28", "size": "20", "side": "SELL", "hash": "445252b9dba1904b2cd7a0710d991d33a6c0eb67", "best_bid": "0.18", "best_ask": "0.2"}], "timestamp": "1769384528472", "event_type": "price_change"}}
{"_local_timestamp": "2026-01-25T23:42:08.660633+00:00", "data": {"market": "0x1c60f9adb1d786b6fe78d63fd9f82dbb293fa06241532fb5ba43f8d8411cde1e", "price_changes": [{"asset_id": "76633639806751295595699993448608387906622374020066717378577586177644656154703", "price": "0.72", "size": "70", "side": "BUY", "hash": "34e959ace2b922641a189ce3b822c6bb239302bf", "best_bid": "0.8", "best_ask": "0.82"}, {"asset_id": "5252381880374485440665230178984721306055940128786215274896991682225319468348", "price": "0.28", "size": "70", "side": "SELL", "hash": "2b18feab567770ca810232938be8d5711a88cc60", "best_bid": "0.18", "best_ask": "0.2"}], "timestamp": "1769384528589", "event_type": "price_change"}}
{"_local_timestamp": "2026-01-25T23:42:08.692527+00:00", "data": {"market": "0x1c60f9adb1d786b6fe78d63fd9f82dbb293fa06241532fb5ba43f8d8411cde1e", "price_changes": [{"asset_id": "76633639806751295595699993448608387906622374020066717378577586177644656154703", "price": "0.72", "size": "120", "side": "BUY", "hash": "cec92ec92fe7c2b9b1d0bb841497a825da533c3d", "best_bid": "0.8", "best_ask": "0.82"}, {"asset_id": "5252381880374485440665230178984721306055940128786215274896991682225319468348", "price": "0.28", "size": "120", "side": "SELL", "hash": "9bce88b5de68fdec7500112d4b11ebe1f339ecb7", "best_bid": "0.18", "best_ask": "0.2"}], "timestamp": "1769384528618", "event_type": "price_change"}}
{"_local_timestamp": "2026-01-25T23:42:10.608787+00:00", "data": {"market": "0xa3186ffc28c45f336920279d5085529d530690a1623997819f3a3db05119dbaa", "price_changes": [{"asset_id": "100637244310881573755436157770787626078576925658681383187976739528804051076924", "price": "0.362", "size": "400", "side": "BUY", "hash": "c6abec3a8b26c1e4d3cb9233721ac9562a545319", "best_bid": "0.777", "best_ask": "0.779"}, {"asset_id": "76284775424209240264542352208573338636556198300439966875308967535434111103074", "price": "0.638", "size": "400", "side": "SELL", "hash": "fd1aaad6dd9acae661d78c18b2845c8a2bd2f79c", "best_bid": "0.221", "best_ask": "0.223"}], "timestamp": "1769384530532", "event_type": "price_change"}}
{"_local_timestamp": "2026-01-25T23:42:10.653051+00:00", "data": {"market": "0xa3186ffc28c45f336920279d5085529d530690a1623997819f3a3db05119dbaa", "price_changes": [{"asset_id": "100637244310881573755436157770787626078576925658681383187976739528804051076924", "price": "0.363", "size": "5", "side": "BUY", "hash": "e17546851283c93e026388d6516a705553a7e912", "best_bid": "0.777", "best_ask": "0.779"}, {"asset_id": "76284775424209240264542352208573338636556198300439966875308967535434111103074", "price": "0.637", "size": "5", "side": "SELL", "hash": "c99c4b74b14dc3566db74712da240e584c2d0386", "best_bid": "0.221", "best_ask": "0.223"}], "timestamp": "1769384530582", "event_type": "price_change"}}
{"_local_timestamp": "2026-01-25T23:42:10.991614+00:00", "data": {"market": "0x1c60f9adb1d786b6fe78d63fd9f82dbb293fa06241532fb5ba43f8d8411cde1e", "price_changes": [{"asset_id": "76633639806751295595699993448608387906622374020066717378577586177644656154703", "price": "0.72", "size": "100", "side": "BUY", "hash": "82cd8b6278bef1f9f394714e2b6be60b0cf91c73", "best_bid": "0.8", "best_ask": "0.82"}, {"asset_id": "5252381880374485440665230178984721306055940128786215274896991682225319468348", "price": "0.28", "size": "100", "side": "SELL", "hash": "057a13593d813ebf2c78ca6ab5074c4e7f2f1279", "best_bid": "0.18", "best_ask": "0.2"}], "timestamp": "1769384530925", "event_type": "price_change"}}
{"_local_timestamp": "2026-01-25T23:42:11.027234+00:00", "data": {"market": "0x1c60f9adb1d786b6fe78d63fd9f82dbb293fa06241532fb5ba43f8d8411cde1e", "price_changes": [{"asset_id": "76633639806751295595699993448608387906622374020066717378577586177644656154703", "price": "0.73", "size": "20", "side": "BUY", "hash": "d4493cb7a47b8910351dde9fbbd9d9aab3b77956", "best_bid": "0.8", "best_ask": "0.82"}, {"asset_id": "5252381880374485440665230178984721306055940128786215274896991682225319468348", "price": "0.27", "size": "20", "side": "SELL", "hash": "ff385e89080fb0aa0a1b39c8e222a1bc9d21af23", "best_bid": "0.18", "best_ask": "0.2"}], "timestamp": "1769384530956", "event_type": "price_change"}}
{"_local_timestamp": "2026-01-25T23:42:11.132658+00:00", "data": {"market": "0x1c60f9adb1d786b6fe78d63fd9f82dbb293fa06241532fb5ba43f8d8411cde1e", "price_changes": [{"asset_id": "76633639806751295595699993448608387906622374020066717378577586177644656154703", "price": "0.72", "size": "50", "side": "BUY", "hash": "d9a4967031f6073bdfdf83212f2c0ba6b7b54ec7", "best_bid": "0.8", "best_ask": "0.82"}, {"asset_id": "5252381880374485440665230178984721306055940128786215274896991682225319468348", "price": "0.28", "size": "50", "side": "SELL", "hash": "446489913feca824983bece2eb12d6e2757b36df", "best_bid": "0.18", "best_ask": "0.2"}], "timestamp": "1769384531058", "event_type": "price_change"}}
{"_local_timestamp": "2026-01-25T23:42:11.134874+00:00", "data": {"market": "0x1c60f9adb1d786b6fe78d63fd9f82dbb293fa06241532fb5ba43f8d8411cde1e", "price_changes": [{"asset_id": "76633639806751295595699993448608387906622374020066717378577586177644656154703", "price": "0.72", "size": "0", "side": "BUY", "hash": "88b26b4dca5a677bb80e0380788ba082de2c6d65", "best_bid": "0.8", "best_ask": "0.82"}, {"asset_id": "5252381880374485440665230178984721306055940128786215274896991682225319468348", "price": "0.28", "size": "0", "side": "SELL", "hash": "5243334447dc4bfadc244af9195105cc9de08d4f", "best_bid": "0.18", "best_ask": "0.2"}], "timestamp": "1769384531062", "event_type": "price_change"}}
{"_local_timestamp": "2026-01-25T23:42:13.476137+00:00", "data": {"market": "0x1c60f9adb1d786b6fe78d63fd9f82dbb293fa06241532fb5ba43f8d8411cde1e", "price_changes": [{"asset_id": "76633639806751295595699993448608387906622374020066717378577586177644656154703", "price": "0.73", "size": "0", "side": "BUY", "hash": "db65779c0c8169cec23e802cd409084f7050ca7a", "best_bid": "0.8", "best_ask": "0.82"}, {"asset_id": "5252381880374485440665230178984721306055940128786215274896991682225319468348", "price": "0.27", "size": "0", "side": "SELL", "hash": "99a17de56d66d909078cd5650e8aed736aef3f60", "best_bid": "0.18", "best_ask": "0.2"}], "timestamp": "1769384533405", "event_type": "price_change"}}
{"_local_timestamp": "2026-01-25T23:42:13.508607+00:00", "data": {"market": "0x1c60f9adb1d786b6fe78d63fd9f82dbb293fa06241532fb5ba43f8d8411cde1e", "price_changes": [{"asset_id": "76633639806751295595699993448608387906622374020066717378577586177644656154703", "price": "0.72", "size": "20", "side": "BUY", "hash": "c00d5bc2a12e0e6f47908f88e6b8cf2467fa44d5", "best_bid": "0.8", "best_ask": "0.82"}, {"asset_id": "5252381880374485440665230178984721306055940128786215274896991682225319468348", "price": "0.28", "size": "20", "side": "SELL", "hash": "d09718e330cb796ee1cf313ea299f63a3028cf5e", "best_bid": "0.18", "best_ask": "0.2"}], "timestamp": "1769384533434", "event_type": "price_change"}}
{"_local_timestamp": "2026-01-25T23:42:13.615951+00:00", "data": {"market": "0x1c60f9adb1d786b6fe78d63fd9f82dbb293fa06241532fb5ba43f8d8411cde1e", "price_changes": [{"asset_id": "76633639806751295595699993448608387906622374020066717378577586177644656154703", "price": "0.72", "size": "70", "side": "BUY", "hash": "42e3816b9102d05e472c9ee6a3ec35065daabbe8", "best_bid": "0.8", "best_ask": "0.82"}, {"asset_id": "5252381880374485440665230178984721306055940128786215274896991682225319468348", "price": "0.28", "size": "70", "side": "SELL", "hash": "e1be9e9d92b743fd4002c3e082ef2986721d1f5e", "best_bid": "0.18", "best_ask": "0.2"}], "timestamp": "1769384533543", "event_type": "price_change"}}
{"_local_timestamp": "2026-01-25T23:42:13.619579+00:00", "data": {"market": "0x1c60f9adb1d786b6fe78d63fd9f82dbb293fa06241532fb5ba43f8d8411cde1e", "price_changes": [{"asset_id": "76633639806751295595699993448608387906622374020066717378577586177644656154703", "price": "0.72", "size": "120", "side": "BUY", "hash": "36f3ebd4e7111bce5f0d090201b3ad4e6002d584", "best_bid": "0.8", "best_ask": "0.82"}, {"asset_id": "5252381880374485440665230178984721306055940128786215274896991682225319468348", "price": "0.28", "size": "120", "side": "SELL", "hash": "50960d4ebceec3e1bf1006abada7e350efe5c13e", "best_bid": "0.18", "best_ask": "0.2"}], "timestamp": "1769384533546", "event_type": "price_change"}}
{"_local_timestamp": "2026-01-25T23:42:13.732372+00:00", "data": {"market": "0x1c60f9adb1d786b6fe78d63fd9f82dbb293fa06241532fb5ba43f8d8411cde1e", "price_changes": [{"asset_id": "76633639806751295595699993448608387906622374020066717378577586177644656154703", "price": "0.72", "size": "70", "side": "BUY", "hash": "50a78f26a35912a42c039da3c0dfee2e1745cb89", "best_bid": "0.8", "best_ask": "0.82"}, {"asset_id": "5252381880374485440665230178984721306055940128786215274896991682225319468348", "price": "0.28", "size": "70", "side": "SELL", "hash": "0c8e4f285eef0d8ea382b09c257c46cec6222f4d", "best_bid": "0.18", "best_ask": "0.2"}], "timestamp": "1769384533663", "event_type": "price_change"}}
{"_local_timestamp": "2026-01-25T23:42:15.120110+00:00", "data": {"market": "0x9954b4eef49a268b810bc260ee9278361e29a8f6f4ad816a804dd613ef73a968", "price_changes": [{"asset_id": "407336258606092316833789781486672854343361331985279263948001098476429338355", "price": "0.939", "size": "147", "side": "SELL", "hash": "1cf4302a83943b09223411de8cd9da1b560dea9d", "best_bid": "0.848", "best_ask": "0.881"}, {"asset_id": "50692628443801018513325614545746863026982626993302787461752145605052144027838", "price": "0.061", "size": "147", "side": "BUY", "hash": "e7f2c08125e534034471567e7baef71b5a5c6ac9", "best_bid": "0.119", "best_ask": "0.152"}], "timestamp": "1769384535000", "event_type": "price_change"}}
{"_local_timestamp": "2026-01-25T23:42:15.291936+00:00", "data": {"market": "0x1c60f9adb1d786b6fe78d63fd9f82dbb293fa06241532fb5ba43f8d8411cde1e", "price_changes": [{"asset_id": "76633639806751295595699993448608387906622374020066717378577586177644656154703", "price": "0.72", "size": "120", "side": "BUY", "hash": "5bf1a70f83fecbd2a4f2aed2f297039bfbc5a8f7", "best_bid": "0.8", "best_ask": "0.82"}, {"asset_id": "5252381880374485440665230178984721306055940128786215274896991682225319468348", "price": "0.28", "size": "120", "side": "SELL", "hash": "b7cda8de2d28a0f5043c3865cbc5381cb7f3fee0", "best_bid": "0.18", "best_ask": "0.2"}], "timestamp": "1769384535178", "event_type": "price_change"}}
{"_local_timestamp": "2026-01-25T23:42:17.207953+00:00", "data": {"market": "0x1c60f9adb1d786b6fe78d63fd9f82dbb293fa06241532fb5ba43f8d8411cde1e", "price_changes": [{"asset_id": "5252381880374485440665230178984721306055940128786215274896991682225319468348", "price": "0.2", "size": "0", "side": "SELL", "hash": "5c5c90039a28c569d653b49994c270ed4d90c39c", "best_bid": "0.18", "best_ask": "0.21"}, {"asset_id": "76633639806751295595699993448608387906622374020066717378577586177644656154703", "price": "0.8", "size": "0", "side": "BUY", "hash": "e885d82ea5560507a445f07c2e53534c6c8222fa", "best_bid": "0.79", "best_ask": "0.82"}], "timestamp": "1769384537084", "event_type": "price_change"}}
{"_local_timestamp": "2026-01-25T23:42:17.588292+00:00", "data": {"market": "0x1c60f9adb1d786b6fe78d63fd9f82dbb293fa06241532fb5ba43f8d8411cde1e", "price_changes": [{"asset_id": "76633639806751295595699993448608387906622374020066717378577586177644656154703", "price": "0.72", "size": "100", "side": "BUY", "hash": "82de1842942ca8597010b6f1467017aeb0edbe6b", "best_bid": "0.79", "best_ask": "0.82"}, {"asset_id": "5252381880374485440665230178984721306055940128786215274896991682225319468348", "price": "0.28", "size": "100", "side": "SELL", "hash": "31495ea1430d60e064f325cfb457f218eb0c8d90", "best_bid": "0.18", "best_ask": "0.21"}], "timestamp": "1769384537481", "event_type": "price_change"}}
{"_local_timestamp": "2026-01-25T23:42:17.618305+00:00", "data": {"market": "0x1c60f9adb1d786b6fe78d63fd9f82dbb293fa06241532fb5ba43f8d8411cde1e", "price_changes": [{"asset_id": "76633639806751295595699993448608387906622374020066717378577586177644656154703", "price": "0.73", "size": "20", "side": "BUY", "hash": "5d74f6c171b39a328932415d1b1cf25b102dc460", "best_bid": "0.79", "best_ask": "0.82"}, {"asset_id": "5252381880374485440665230178984721306055940128786215274896991682225319468348", "price": "0.27", "size": "20", "side": "SELL", "hash": "979747f73d8427c5bace4016a739e7ea1e872633", "best_bid": "0.18", "best_ask": "0.21"}], "timestamp": "1769384537510", "event_type": "price_change"}}
{"_local_timestamp": "2026-01-25T23:42:22.535874+00:00", "data": {"market": "0xa3186ffc28c45f336920279d5085529d530690a1623997819f3a3db05119dbaa", "price_changes": [{"asset_id": "100637244310881573755436157770787626078576925658681383187976739528804051076924", "price": "0.2", "size": "0", "side": "BUY", "hash": "eca2453d642a44de53df12a80c7ff9139f17d129", "best_bid": "0.777", "best_ask": "0.779"}, {"asset_id": "76284775424209240264542352208573338636556198300439966875308967535434111103074", "price": "0.8", "size": "0", "side": "SELL", "hash": "ff899b6abd1aec116655bd208f028e3fa30ad91b", "best_bid": "0.221", "best_ask": "0.223"}], "timestamp": "1769384542350", "event_type": "price_change"}}
{"_local_timestamp": "2026-01-25T23:42:22.538136+00:00", "data": {"market": "0xa3186ffc28c45f336920279d5085529d530690a1623997819f3a3db05119dbaa", "price_changes": [{"asset_id": "100637244310881573755436157770787626078576925658681383187976739528804051076924", "price": "0.27", "size": "0", "side": "BUY", "hash": "eca2453d642a44de53df12a80c7ff9139f17d129", "best_bid": "0.777", "best_ask": "0.779"}, {"asset_id": "76284775424209240264542352208573338636556198300439966875308967535434111103074", "price": "0.73", "size": "0", "side": "SELL", "hash": "ff899b6abd1aec116655bd208f028e3fa30ad91b", "best_bid": "0.221", "best_ask": "0.223"}], "timestamp": "1769384542350", "event_type": "price_change"}}
{"_local_timestamp": "2026-01-25T23:42:22.540161+00:00", "data": {"market": "0xa3186ffc28c45f336920279d5085529d530690a1623997819f3a3db05119dbaa", "price_changes": [{"asset_id": "100637244310881573755436157770787626078576925658681383187976739528804051076924", "price": "0.361", "size": "3112", "side": "BUY", "hash": "eca2453d642a44de53df12a80c7ff9139f17d129", "best_bid": "0.777", "best_ask": "0.779"}, {"asset_id": "76284775424209240264542352208573338636556198300439966875308967535434111103074", "price": "0.639", "size": "3112", "side": "SELL", "hash": "ff899b6abd1aec116655bd208f028e3fa30ad91b", "best_bid": "0.221", "best_ask": "0.223"}], "timestamp": "1769384542350", "event_type": "price_change"}}
{"_local_timestamp": "2026-01-25T23:42:23.256442+00:00", "data": {"market": "0xa3186ffc28c45f336920279d5085529d530690a1623997819f3a3db05119dbaa", "price_changes": [{"asset_id": "100637244310881573755436157770787626078576925658681383187976739528804051076924", "price": "0.182", "size": "11111", "side": "BUY", "hash": "4952dcb1b897a6bab5cefe84906467e6eb591345", "best_bid": "0.777", "best_ask": "0.779"}, {"asset_id": "76284775424209240264542352208573338636556198300439966875308967535434111103074", "price": "0.818", "size": "11111", "side": "SELL", "hash": "d7dfbb0468e327383562de9e5dd8642445c366bb", "best_bid": "0.221", "best_ask": "0.223"}], "timestamp": "1769384543021", "event_type": "price_change"}}
{"_local_timestamp": "2026-01-25T23:42:23.258567+00:00", "data": {"market": "0xa3186ffc28c45f336920279d5085529d530690a1623997819f3a3db05119dbaa", "price_changes": [{"asset_id": "100637244310881573755436157770787626078576925658681383187976739528804051076924", "price": "0.08", "size": "0", "side": "BUY", "hash": "4952dcb1b897a6bab5cefe84906467e6eb591345", "best_bid": "0.777", "best_ask": "0.779"}, {"asset_id": "76284775424209240264542352208573338636556198300439966875308967535434111103074", "price": "0.92", "size": "0", "side": "SELL", "hash": "d7dfbb0468e327383562de9e5dd8642445c366bb", "best_bid": "0.221", "best_ask": "0.223"}], "timestamp": "1769384543021", "event_type": "price_change"}}
{"_local_timestamp": "2026-01-25T23:42:29.168353+00:00", "data": {"market": "0x1c60f9adb1d786b6fe78d63fd9f82dbb293fa06241532fb5ba43f8d8411cde1e", "price_changes": [{"asset_id": "5252381880374485440665230178984721306055940128786215274896991682225319468348", "price": "0.2", "size": "18.37", "side": "SELL", "hash": "b2445ce8786390a851cfcc98a5ce1b804309b6b7", "best_bid": "0.18", "best_ask": "0.2"}, {"asset_id": "76633639806751295595699993448608387906622374020066717378577586177644656154703", "price": "0.8", "size": "18.37", "side": "BUY", "hash": "86ed957ef76f21f5265d8133f74eb83b67a1d515", "best_bid": "0.8", "best_ask": "0.82"}], "timestamp": "1769384548937", "event_type": "price_change"}}
{"_local_timestamp": "2026-01-25T23:42:29.170375+00:00", "data": {"market": "0x1c60f9adb1d786b6fe78d63fd9f82dbb293fa06241532fb5ba43f8d8411cde1e", "price_changes": [{"asset_id": "5252381880374485440665230178984721306055940128786215274896991682225319468348", "price": "0.2", "size": "36.74", "side": "SELL", "hash": "d649d50045ba01331599a504f18397e2382b8d3e", "best_bid": "0.18", "best_ask": "0.2"}, {"asset_id": "76633639806751295595699993448608387906622374020066717378577586177644656154703", "price": "0.8", "size": "36.74", "side": "BUY", "hash": "c170be8b01659c51325c18343a1e88a130ea75e1", "best_bid": "0.8", "best_ask": "0.82"}], "timestamp": "1769384548937", "event_type": "price_change"}}
{"_local_timestamp": "2026-01-25T23:42:29.172212+00:00", "data": {"market": "0x1c60f9adb1d786b6fe78d63fd9f82dbb293fa06241532fb5ba43f8d8411cde1e", "price_changes": [{"asset_id": "5252381880374485440665230178984721306055940128786215274896991682225319468348", "price": "0.2", "size": "55.11", "side": "SELL", "hash": "1682b0355a3862acff8d9440acae8cdd97d89e3c", "best_bid": "0.18", "best_ask": "0.2"}, {"asset_id": "76633639806751295595699993448608387906622374020066717378577586177644656154703", "price": "0.8", "size": "55.11", "side": "BUY", "hash": "d04b446061b97b85b2731064c70ab3d3181d2ffe", "best_bid": "0.8", "best_ask": "0.82"}], "timestamp": "1769384548938", "event_type": "price_change"}}
{"_local_timestamp": "2026-01-25T23:42:29.174008+00:00", "data": {"market": "0x1c60f9adb1d786b6fe78d63fd9f82dbb293fa06241532fb5ba43f8d8411cde1e", "price_changes": [{"asset_id": "5252381880374485440665230178984721306055940128786215274896991682225319468348", "price": "0.2", "size": "73.48", "side": "SELL", "hash": "6cb747ff948557f21591521b3ccca4d580027152", "best_bid": "0.18", "best_ask": "0.2"}, {"asset_id": "76633639806751295595699993448608387906622374020066717378577586177644656154703", "price": "0.8", "size": "73.48", "side": "BUY", "hash": "ed2f71eda93225a99a283e097df682f97f5be686", "best_bid": "0.8", "best_ask": "0.82"}], "timestamp": "1769384548938", "event_type": "price_change"}}
{"_local_timestamp": "2026-01-25T23:42:29.277585+00:00", "data": {"market": "0x1c60f9adb1d786b6fe78d63fd9f82dbb293fa06241532fb5ba43f8d8411cde1e", "price_changes": [{"asset_id": "76633639806751295595699993448608387906622374020066717378577586177644656154703", "price": "0.72", "size": "50", "side": "BUY", "hash": "2c101dc200660f56d2af8eae20f915d789736429", "best_bid": "0.8", "best_ask": "0.82"}, {"asset_id": "5252381880374485440665230178984721306055940128786215274896991682225319468348", "price": "0.28", "size": "50", "side": "SELL", "hash": "bca39319520e6aea8ba49911e9093fe0fafdaf98", "best_bid": "0.18", "best_ask": "0.2"}], "timestamp": "1769384549056", "event_type": "price_change"}}
{"_local_timestamp": "2026-01-25T23:42:29.298407+00:00", "data": {"market": "0x1c60f9adb1d786b6fe78d63fd9f82dbb293fa06241532fb5ba43f8d8411cde1e", "price_changes": [{"asset_id": "76633639806751295595699993448608387906622374020066717378577586177644656154703", "price": "0.72", "size": "0", "side": "BUY", "hash": "cf4412da4d2444fec9b831589d23e2252e2d8e72", "best_bid": "0.8", "best_ask": "0.82"}, {"asset_id": "5252381880374485440665230178984721306055940128786215274896991682225319468348", "price": "0.28", "size": "0", "side": "SELL", "hash": "1ed41b6e93b966966a06323b02ded41ea53034e4", "best_bid": "0.18", "best_ask": "0.2"}], "timestamp": "1769384549074", "event_type": "price_change"}}
{"_local_timestamp": "2026-01-25T23:42:31.096886+00:00", "data": {"market": "0x1c60f9adb1d786b6fe78d63fd9f82dbb293fa06241532fb5ba43f8d8411cde1e", "price_changes": [{"asset_id": "76633639806751295595699993448608387906622374020066717378577586177644656154703", "price": "0.73", "size": "0", "side": "BUY", "hash": "70272f60788263eea28bef817b305d69782dc88f", "best_bid": "0.8", "best_ask": "0.82"}, {"asset_id": "5252381880374485440665230178984721306055940128786215274896991682225319468348", "price": "0.27", "size": "0", "side": "SELL", "hash": "4dadcbcbdbb54a99a6619aea80e5063f826226a2", "best_bid": "0.18", "best_ask": "0.2"}], "timestamp": "1769384550904", "event_type": "price_change"}}
{"_local_timestamp": "2026-01-25T23:42:31.134751+00:00", "data": {"market": "0x1c60f9adb1d786b6fe78d63fd9f82dbb293fa06241532fb5ba43f8d8411cde1e", "price_changes": [{"asset_id": "76633639806751295595699993448608387906622374020066717378577586177644656154703", "price": "0.72", "size": "20", "side": "BUY", "hash": "fa7a70d3a88abf92047470118ca66f2d10013413", "best_bid": "0.8", "best_ask": "0.82"}, {"asset_id": "5252381880374485440665230178984721306055940128786215274896991682225319468348", "price": "0.28", "size": "20", "side": "SELL", "hash": "adcb721eb97a3ea61862cbc3076a7615d38f62e1", "best_bid": "0.18", "best_ask": "0.2"}], "timestamp": "1769384550932", "event_type": "price_change"}}
{"_local_timestamp": "2026-01-25T23:42:44.715968+00:00", "data": {"market": "0x9e3973197f60e1614567ce57a3e6f8a4805d21f471d67b67a5ed5ecca1b8004b", "price_changes": [{"asset_id": "34161622438208629372218363980216155858361713198177495956358330769075997408090", "price": "0.341", "size": "0", "side": "BUY", "hash": "7fa1fd40561286c599c00dfbb85f7d2d2c756e48", "best_bid": "0.957", "best_ask": "0.965"}, {"asset_id": "91737308879086717078434227064834144626260031635826299637092532293769745981585", "price": "0.659", "size": "0", "side": "SELL", "hash": "f8df14edb15547d35acef83ec4ba606d1f9fff6d", "best_bid": "0.035", "best_ask": "0.043"}], "timestamp": "1769384564577", "event_type": "price_change"}}
{"_local_timestamp": "2026-01-25T23:42:44.767170+00:00", "data": {"market": "0x9e3973197f60e1614567ce57a3e6f8a4805d21f471d67b67a5ed5ecca1b8004b", "price_changes": [{"asset_id": "34161622438208629372218363980216155858361713198177495956358330769075997408090", "price": "0.341", "size": "5", "side": "BUY", "hash": "35a88300260fca56614224e868e5c793d2a8bf55", "best_bid": "0.957", "best_ask": "0.965"}, {"asset_id": "91737308879086717078434227064834144626260031635826299637092532293769745981585", "price": "0.659", "size": "5", "side": "SELL", "hash": "df28f6e9741e691738bdfdc600dfe7aca9d8a561", "best_bid": "0.035", "best_ask": "0.043"}], "timestamp": "1769384564629", "event_type": "price_change"}}
{"_local_timestamp": "2026-01-25T23:42:44.822091+00:00", "data": {"market": "0x1c60f9adb1d786b6fe78d63fd9f82dbb293fa06241532fb5ba43f8d8411cde1e", "price_changes": [{"asset_id": "76633639806751295595699993448608387906622374020066717378577586177644656154703", "price": "0.72", "size": "70", "side": "BUY", "hash": "369f910b7de49f19b59110331de8ec0b4206face", "best_bid": "0.8", "best_ask": "0.82"}, {"asset_id": "5252381880374485440665230178984721306055940128786215274896991682225319468348", "price": "0.28", "size": "70", "side": "SELL", "hash": "ee6059a88a16f009ca5562934cfe021a6eb83c94", "best_bid": "0.18", "best_ask": "0.2"}], "timestamp": "1769384564685", "event_type": "price_change"}}
{"_local_timestamp": "2026-01-25T23:42:44.834101+00:00", "data": {"market": "0x1c60f9adb1d786b6fe78d63fd9f82dbb293fa06241532fb5ba43f8d8411cde1e", "price_changes": [{"asset_id": "76633639806751295595699993448608387906622374020066717378577586177644656154703", "price": "0.72", "size": "120", "side": "BUY", "hash": "646f484b2dbdf63f1fa0e4edf2299225b761da5b", "best_bid": "0.8", "best_ask": "0.82"}, {"asset_id": "5252381880374485440665230178984721306055940128786215274896991682225319468348", "price": "0.28", "size": "120", "side": "SELL", "hash": "951e186cd99dafb92c3a541f1b8bbe21936ddbca", "best_bid": "0.18", "best_ask": "0.2"}], "timestamp": "1769384564700", "event_type": "price_change"}}
{"_local_timestamp": "2026-01-25T23:42:50.795683+00:00", "data": {"market": "0x1c60f9adb1d786b6fe78d63fd9f82dbb293fa06241532fb5ba43f8d8411cde1e", "price_changes": [{"asset_id": "76633639806751295595699993448608387906622374020066717378577586177644656154703", "price": "0.72", "size": "100", "side": "BUY", "hash": "c12c0b80654af4ec80aecf07400ae3c77e6d45ad", "best_bid": "0.8", "best_ask": "0.82"}, {"asset_id": "5252381880374485440665230178984721306055940128786215274896991682225319468348", "price": "0.28", "size": "100", "side": "SELL", "hash": "57cd21d05b68d6f0e29f970a48e97df833c5fff4", "best_bid": "0.18", "best_ask": "0.2"}], "timestamp": "1769384570659", "event_type": "price_change"}}
{"_local_timestamp": "2026-01-25T23:42:50.814395+00:00", "data": {"market": "0x1c60f9adb1d786b6fe78d63fd9f82dbb293fa06241532fb5ba43f8d8411cde1e", "price_changes": [{"asset_id": "76633639806751295595699993448608387906622374020066717378577586177644656154703", "price": "0.73", "size": "20", "side": "BUY", "hash": "c6b62f5dc8d2f9ca773b153663e9796b7cd0f302", "best_bid": "0.8", "best_ask": "0.82"}, {"asset_id": "5252381880374485440665230178984721306055940128786215274896991682225319468348", "price": "0.27", "size": "20", "side": "SELL", "hash": "768ce222a9670c911b5ede519dd23b440124525e", "best_bid": "0.18", "best_ask": "0.2"}], "timestamp": "1769384570684", "event_type": "price_change"}}
{"_local_timestamp": "2026-01-25T23:42:50.922443+00:00", "data": {"market": "0x1c60f9adb1d786b6fe78d63fd9f82dbb293fa06241532fb5ba43f8d8411cde1e", "price_changes": [{"asset_id": "76633639806751295595699993448608387906622374020066717378577586177644656154703", "price": "0.72", "size": "50", "side": "BUY", "hash": "86c6df9980bd0e7c3368876abd87c3d467fcfa96", "best_bid": "0.8", "best_ask": "0.82"}, {"asset_id": "5252381880374485440665230178984721306055940128786215274896991682225319468348", "price": "0.28", "size": "50", "side": "SELL", "hash": "1adca49cb81fd89635a64bd1a95a99eb00658562", "best_bid": "0.18", "best_ask": "0.2"}], "timestamp": "1769384570787", "event_type": "price_change"}}
{"_local_timestamp": "2026-01-25T23:42:50.924433+00:00", "data": {"market": "0x00a9dd3c3174468e2cee6ffa418dbf9b7e95c09788c281f608e496b9fef7b895", "price_changes": [{"asset_id": "52843058974175583048395589011180975724373233294387599507798784190922550307232", "price": "0.852", "size": "0", "side": "BUY", "hash": "65a98bd0a97b3cef50e68ae4e9ffad25fff73dcb", "best_bid": "0.984", "best_ask": "0.985"}, {"asset_id": "79336858132239037705158300268603413459637933572725439146100963281670148171735", "price": "0.148", "size": "0", "side": "SELL", "hash": "5ac6c95e835b1c9d1e4aff7d8534129d9781701a", "best_bid": "0.015", "best_ask": "0.016"}], "timestamp": "1769384570794", "event_type": "price_change"}}
{"_local_timestamp": "2026-01-25T23:42:50.951601+00:00", "data": {"market": "0x1c60f9adb1d786b6fe78d63fd9f82dbb293fa06241532fb5ba43f8d8411cde1e", "price_changes": [{"asset_id": "76633639806751295595699993448608387906622374020066717378577586177644656154703", "price": "0.72", "size": "0", "side": "BUY", "hash": "b30f03b5b38b33434bc4f76034ca238b97407e21", "best_bid": "0.8", "best_ask": "0.82"}, {"asset_id": "5252381880374485440665230178984721306055940128786215274896991682225319468348", "price": "0.28", "size": "0", "side": "SELL", "hash": "9a6eed1cb2fc1b91ae60e9571e8fd0ad7febe8ce", "best_bid": "0.18", "best_ask": "0.2"}], "timestamp": "1769384570804", "event_type": "price_change"}}
{"_local_timestamp": "2026-01-25T23:42:55.635191+00:00", "data": {"market": "0x1c60f9adb1d786b6fe78d63fd9f82dbb293fa06241532fb5ba43f8d8411cde1e", "price_changes": [{"asset_id": "76633639806751295595699993448608387906622374020066717378577586177644656154703", "price": "0.73", "size": "0", "side": "BUY", "hash": "2b06c58ba5d1ff2356f36901258fa19467be8fa7", "best_bid": "0.8", "best_ask": "0.82"}, {"asset_id": "5252381880374485440665230178984721306055940128786215274896991682225319468348", "price": "0.27", "size": "0", "side": "SELL", "hash": "ed001c43dd36a2decf44fc2935b2f3389c8d8d04", "best_bid": "0.18", "best_ask": "0.2"}], "timestamp": "1769384575494", "event_type": "price_change"}}
{"_local_timestamp": "2026-01-25T23:42:55.665682+00:00", "data": {"market": "0x1c60f9adb1d786b6fe78d63fd9f82dbb293fa06241532fb5ba43f8d8411cde1e", "price_changes": [{"asset_id": "76633639806751295595699993448608387906622374020066717378577586177644656154703", "price": "0.72", "size": "20", "side": "BUY", "hash": "4b9c3500af43c26a2a17af8fa2f854d1624ffaa8", "best_bid": "0.8", "best_ask": "0.82"}, {"asset_id": "5252381880374485440665230178984721306055940128786215274896991682225319468348", "price": "0.28", "size": "20", "side": "SELL", "hash": "bc9069f7dc6acf2ca38573843f68e572b5cdf212", "best_bid": "0.18", "best_ask": "0.2"}], "timestamp": "1769384575524", "event_type": "price_change"}}
{"_local_timestamp": "2026-01-25T23:42:55.778945+00:00", "data": {"market": "0x1c60f9adb1d786b6fe78d63fd9f82dbb293fa06241532fb5ba43f8d8411cde1e", "price_changes": [{"asset_id": "76633639806751295595699993448608387906622374020066717378577586177644656154703", "price": "0.72", "size": "70", "side": "BUY", "hash": "183d5b2cc8d7d81e86d6088ad74513732ad10a14", "best_bid": "0.8", "best_ask": "0.82"}, {"asset_id": "5252381880374485440665230178984721306055940128786215274896991682225319468348", "price": "0.28", "size": "70", "side": "SELL", "hash": "cd31c33a2d7a567e5f9b3538e667ce10f6bbce8b", "best_bid": "0.18", "best_ask": "0.2"}], "timestamp": "1769384575632", "event_type": "price_change"}}
{"_local_timestamp": "2026-01-25T23:42:55.781365+00:00", "data": {"market": "0x1c60f9adb1d786b6fe78d63fd9f82dbb293fa06241532fb5ba43f8d8411cde1e", "price_changes": [{"asset_id": "76633639806751295595699993448608387906622374020066717378577586177644656154703", "price": "0.72", "size": "120", "side": "BUY", "hash": "ae6f8a1a01f7643fad97f628308bc2df96f2812f", "best_bid": "0.8", "best_ask": "0.82"}, {"asset_id": "5252381880374485440665230178984721306055940128786215274896991682225319468348", "price": "0.28", "size": "120", "side": "SELL", "hash": "c8655635659cd9ddee77767592425346ce7b50fe", "best_bid": "0.18", "best_ask": "0.2"}], "timestamp": "1769384575634", "event_type": "price_change"}}
{"_local_timestamp": "2026-01-25T23:42:58.653643+00:00", "data": {"market": "0x1c60f9adb1d786b6fe78d63fd9f82dbb293fa06241532fb5ba43f8d8411cde1e", "price_changes": [{"asset_id": "76633639806751295595699993448608387906622374020066717378577586177644656154703", "price": "0.72", "size": "100", "side": "BUY", "hash": "7149db6ed3bfce17ad6dd8fdb00fbce66f7f7001", "best_bid": "0.8", "best_ask": "0.82"}, {"asset_id": "5252381880374485440665230178984721306055940128786215274896991682225319468348", "price": "0.28", "size": "100", "side": "SELL", "hash": "4a7c6c7cebca12f5b3f34f0016424517f9c5e8ed", "best_bid": "0.18", "best_ask": "0.2"}], "timestamp": "1769384578529", "event_type": "price_change"}}
{"_local_timestamp": "2026-01-25T23:42:58.681495+00:00", "data": {"market": "0x1c60f9adb1d786b6fe78d63fd9f82dbb293fa06241532fb5ba43f8d8411cde1e", "price_changes": [{"asset_id": "76633639806751295595699993448608387906622374020066717378577586177644656154703", "price": "0.73", "size": "20", "side": "BUY", "hash": "084f380ce085abc96fde136dcfbbe6d89ded67e7", "best_bid": "0.8", "best_ask": "0.82"}, {"asset_id": "5252381880374485440665230178984721306055940128786215274896991682225319468348", "price": "0.27", "size": "20", "side": "SELL", "hash": "1b20d3af1df5f5d546fae29f767d425449032ba8", "best_bid": "0.18", "best_ask": "0.2"}], "timestamp": "1769384578554", "event_type": "price_change"}}
{"_local_timestamp": "2026-01-25T23:42:58.786292+00:00", "data": {"market": "0x1c60f9adb1d786b6fe78d63fd9f82dbb293fa06241532fb5ba43f8d8411cde1e", "price_changes": [{"asset_id": "76633639806751295595699993448608387906622374020066717378577586177644656154703", "price": "0.72", "size": "50", "side": "BUY", "hash": "1e15eb70e7a29d5e09ba3ea68f86198f71a16c09", "best_bid": "0.8", "best_ask": "0.82"}, {"asset_id": "5252381880374485440665230178984721306055940128786215274896991682225319468348", "price": "0.28", "size": "50", "side": "SELL", "hash": "67c46c454006c7cfd10fc6f852e3aed88aa8af13", "best_bid": "0.18", "best_ask": "0.2"}], "timestamp": "1769384578664", "event_type": "price_change"}}
{"_local_timestamp": "2026-01-25T23:42:58.797750+00:00", "data": {"market": "0x1c60f9adb1d786b6fe78d63fd9f82dbb293fa06241532fb5ba43f8d8411cde1e", "price_changes": [{"asset_id": "76633639806751295595699993448608387906622374020066717378577586177644656154703", "price": "0.72", "size": "0", "side": "BUY", "hash": "c96f96ef819d5548cea1166d7f54ba6f89121fbd", "best_bid": "0.8", "best_ask": "0.82"}, {"asset_id": "5252381880374485440665230178984721306055940128786215274896991682225319468348", "price": "0.28", "size": "0", "side": "SELL", "hash": "c179181617733395d0bdf2fa047f9bec1f8229bd", "best_bid": "0.18", "best_ask": "0.2"}], "timestamp": "1769384578673", "event_type": "price_change"}}
{"_local_timestamp": "2026-01-25T23:43:00.477827+00:00", "data": {"market": "0x1c60f9adb1d786b6fe78d63fd9f82dbb293fa06241532fb5ba43f8d8411cde1e", "price_changes": [{"asset_id": "76633639806751295595699993448608387906622374020066717378577586177644656154703", "price": "0.73", "size": "0", "side": "BUY", "hash": "19628fd5e34c68d6989962b3fd59a09dc56eb7a6", "best_bid": "0.8", "best_ask": "0.82"}, {"asset_id": "5252381880374485440665230178984721306055940128786215274896991682225319468348", "price": "0.27", "size": "0", "side": "SELL", "hash": "ba291004efb8ad0f47beec3e9a8adb4996ca31a2", "best_bid": "0.18", "best_ask": "0.2"}], "timestamp": "1769384580343", "event_type": "price_change"}}
{"_local_timestamp": "2026-01-25T23:43:00.506714+00:00", "data": {"market": "0x1c60f9adb1d786b6fe78d63fd9f82dbb293fa06241532fb5ba43f8d8411cde1e", "price_changes": [{"asset_id": "76633639806751295595699993448608387906622374020066717378577586177644656154703", "price": "0.72", "size": "20", "side": "BUY", "hash": "7353087661d934299b8bd94201c41e3340250b39", "best_bid": "0.8", "best_ask": "0.82"}, {"asset_id": "5252381880374485440665230178984721306055940128786215274896991682225319468348", "price": "0.28", "size": "20", "side": "SELL", "hash": "4699a724213891e38a2d41840dbd3353ec101f1f", "best_bid": "0.18", "best_ask": "0.2"}], "timestamp": "1769384580370", "event_type": "price_change"}}
{"_local_timestamp": "2026-01-25T23:43:00.637666+00:00", "data": {"market": "0x85f3e001ffe2a24f985b939460d0cc22041d47107ed8c681f75abb6a5bd1d1d7", "price_changes": [{"asset_id": "91490628576757362533849475709592129096879082569664806718559823554313287888164", "price": "0.46", "size": "0", "side": "BUY", "hash": "4f91764d1d63b4669015354232576187f4abb9e4", "best_bid": "0.88", "best_ask": "0.9"}, {"asset_id": "26510384225806040730267502985578081313836463589753281281933174278980674429194", "price": "0.54", "size": "0", "side": "SELL", "hash": "67592e31109fc5871cad5627a3575099f2cb2e3b", "best_bid": "0.1", "best_ask": "0.12"}], "timestamp": "1769384580497", "event_type": "price_change"}}
{"_local_timestamp": "2026-01-25T23:43:00.864531+00:00", "data": {"market": "0x85f3e001ffe2a24f985b939460d0cc22041d47107ed8c681f75abb6a5bd1d1d7", "price_changes": [{"asset_id": "91490628576757362533849475709592129096879082569664806718559823554313287888164", "price": "0.48", "size": "10", "side": "BUY", "hash": "2f79a18cadf41754b9e88227c6e69f1258850079", "best_bid": "0.88", "best_ask": "0.9"}, {"asset_id": "26510384225806040730267502985578081313836463589753281281933174278980674429194", "price": "0.52", "size": "10", "side": "SELL", "hash": "550e91b26d37bb46deef103983434424fa1e1ec5", "best_bid": "0.1", "best_ask": "0.12"}], "timestamp": "1769384580729", "event_type": "price_change"}}
{"_local_timestamp": "2026-01-25T23:43:00.933470+00:00", "data": {"market": "0x85f3e001ffe2a24f985b939460d0cc22041d47107ed8c681f75abb6a5bd1d1d7", "price_changes": [{"asset_id": "91490628576757362533849475709592129096879082569664806718559823554313287888164", "price": "0.87", "size": "47.37", "side": "BUY", "hash": "017949525732affdec29bca72b7bc4f99a57aa9e", "best_bid": "0.88", "best_ask": "0.9"}, {"asset_id": "26510384225806040730267502985578081313836463589753281281933174278980674429194", "price": "0.13", "size": "47.37", "side": "SELL", "hash": "015861b0dc66af2c414204ec5310f15a6d8c5425", "best_bid": "0.1", "best_ask": "0.12"}], "timestamp": "1769384580795", "event_type": "price_change"}}
{"_local_timestamp": "2026-01-25T23:43:00.987364+00:00", "data": {"market": "0x1c60f9adb1d786b6fe78d63fd9f82dbb293fa06241532fb5ba43f8d8411cde1e", "price_changes": [{"asset_id": "76633639806751295595699993448608387906622374020066717378577586177644656154703", "price": "0.72", "size": "70", "side": "BUY", "hash": "e447e731375b6623056017088179c316d5450a1d", "best_bid": "0.8", "best_ask": "0.82"}, {"asset_id": "5252381880374485440665230178984721306055940128786215274896991682225319468348", "price": "0.28", "size": "70", "side": "SELL", "hash": "43cf1721ead01787370a6a0fc1526dca0ce82e52", "best_bid": "0.18", "best_ask": "0.2"}], "timestamp": "1769384580837", "event_type": "price_change"}}
{"_local_timestamp": "2026-01-25T23:43:00.989530+00:00", "data": {"market": "0x1c60f9adb1d786b6fe78d63fd9f82dbb293fa06241532fb5ba43f8d8411cde1e", "price_changes": [{"asset_id": "76633639806751295595699993448608387906622374020066717378577586177644656154703", "price": "0.72", "size": "120", "side": "BUY", "hash": "e8d86064e9629bd36063ffe29058efb5ff04ff3c", "best_bid": "0.8", "best_ask": "0.82"}, {"asset_id": "5252381880374485440665230178984721306055940128786215274896991682225319468348", "price": "0.28", "size": "120", "side": "SELL", "hash": "d8dafe8c1e4326266ba7d13417aab47a0eaefbe8", "best_bid": "0.18", "best_ask": "0.2"}], "timestamp": "1769384580843", "event_type": "price_change"}}
{"_local_timestamp": "2026-01-25T23:43:01.078601+00:00", "data": {"market": "0x1c60f9adb1d786b6fe78d63fd9f82dbb293fa06241532fb5ba43f8d8411cde1e", "price_changes": [{"asset_id": "76633639806751295595699993448608387906622374020066717378577586177644656154703", "price": "0.72", "size": "70", "side": "BUY", "hash": "57b12f921bd88628175a68854332718b09890aeb", "best_bid": "0.8", "best_ask": "0.82"}, {"asset_id": "5252381880374485440665230178984721306055940128786215274896991682225319468348", "price": "0.28", "size": "70", "side": "SELL", "hash": "e43ddf7c93cb4ed259a43138a1556820519ee925", "best_bid": "0.18", "best_ask": "0.2"}], "timestamp": "1769384580941", "event_type": "price_change"}}
{"_local_timestamp": "2026-01-25T23:43:02.312458+00:00", "data": {"market": "0x1c60f9adb1d786b6fe78d63fd9f82dbb293fa06241532fb5ba43f8d8411cde1e", "price_changes": [{"asset_id": "76633639806751295595699993448608387906622374020066717378577586177644656154703", "price": "0.72", "size": "50", "side": "BUY", "hash": "f2f0aabe45b148dd5191d36d4886dfbf2324ea03", "best_bid": "0.8", "best_ask": "0.82"}, {"asset_id": "5252381880374485440665230178984721306055940128786215274896991682225319468348", "price": "0.28", "size": "50", "side": "SELL", "hash": "c007bb96c67179dcce9fd0b04c7b1d763bd50b61", "best_bid": "0.18", "best_ask": "0.2"}], "timestamp": "1769384582132", "event_type": "price_change"}}
{"_local_timestamp": "2026-01-25T23:43:02.333169+00:00", "data": {"market": "0x1c60f9adb1d786b6fe78d63fd9f82dbb293fa06241532fb5ba43f8d8411cde1e", "price_changes": [{"asset_id": "76633639806751295595699993448608387906622374020066717378577586177644656154703", "price": "0.73", "size": "20", "side": "BUY", "hash": "ad187b51d1c19df928f2035d4d302494ed7165e1", "best_bid": "0.8", "best_ask": "0.82"}, {"asset_id": "5252381880374485440665230178984721306055940128786215274896991682225319468348", "price": "0.27", "size": "20", "side": "SELL", "hash": "aac8d68463257808c64029d9e0a001121bd69162", "best_bid": "0.18", "best_ask": "0.2"}], "timestamp": "1769384582160", "event_type": "price_change"}}
{"_local_timestamp": "2026-01-25T23:43:09.172469+00:00", "data": {"market": "0x1c60f9adb1d786b6fe78d63fd9f82dbb293fa06241532fb5ba43f8d8411cde1e", "price_changes": [{"asset_id": "76633639806751295595699993448608387906622374020066717378577586177644656154703", "price": "0.72", "size": "0", "side": "BUY", "hash": "9aeaf55115682ce8a30238affb3bf35fcf170b7f", "best_bid": "0.8", "best_ask": "0.82"}, {"asset_id": "5252381880374485440665230178984721306055940128786215274896991682225319468348", "price": "0.28", "size": "0", "side": "SELL", "hash": "12c63dce5b1b1db12910f879d793c40e69bec45e", "best_bid": "0.18", "best_ask": "0.2"}], "timestamp": "1769384589002", "event_type": "price_change"}}
{"_local_timestamp": "2026-01-25T23:43:09.498470+00:00", "data": {"market": "0x2bf6f2697e123f9bfb2c8788ed35741c67159ed19374886e6e7cb3f35e60f855", "price_changes": [{"asset_id": "49586088438166301401847652669972487503167459757949140750804630139416391309643", "price": "0.948", "size": "11.38", "side": "SELL", "hash": "4d784d205c959867fb06c88553acd77d9c677d7d", "best_bid": "0.944", "best_ask": "0.948"}, {"asset_id": "36378160072890559704966692763500079412567571381443166092461911736222412577030", "price": "0.052", "size": "11.38", "side": "BUY", "hash": "45ada16d5e7ce3be837cc59addf9ba1b842b70c9", "best_bid": "0.052", "best_ask": "0.056"}], "timestamp": "1769384589354", "event_type": "price_change"}}
{"_local_timestamp": "2026-01-25T23:43:09.521004+00:00", "data": {"market": "0x2bf6f2697e123f9bfb2c8788ed35741c67159ed19374886e6e7cb3f35e60f855", "price_changes": [{"asset_id": "49586088438166301401847652669972487503167459757949140750804630139416391309643", "price": "0.926", "size": "31", "side": "BUY", "hash": "1dd15e5c40df8368dd19c2f2908560820d60c010", "best_bid": "0.944", "best_ask": "0.948"}, {"asset_id": "36378160072890559704966692763500079412567571381443166092461911736222412577030", "price": "0.074", "size": "31", "side": "SELL", "hash": "a32be85d92819c87a1db7839cd643db10ce9ad22", "best_bid": "0.052", "best_ask": "0.056"}], "timestamp": "1769384589388", "event_type": "price_change"}}
{"_local_timestamp": "2026-01-25T23:43:09.523087+00:00", "data": {"market": "0x2bf6f2697e123f9bfb2c8788ed35741c67159ed19374886e6e7cb3f35e60f855", "price_changes": [{"asset_id": "36378160072890559704966692763500079412567571381443166092461911736222412577030", "price": "0.043", "size": "0", "side": "BUY", "hash": "e52ee541f81572241f8889d3fd210ebf3a7b0bda", "best_bid": "0.052", "best_ask": "0.056"}, {"asset_id": "49586088438166301401847652669972487503167459757949140750804630139416391309643", "price": "0.957", "size": "0", "side": "SELL", "hash": "ceadc4a5c12e1012da92952b99de85c6923b475f", "best_bid": "0.944", "best_ask": "0.948"}], "timestamp": "1769384589389", "event_type": "price_change"}}
{"_local_timestamp": "2026-01-25T23:43:09.620622+00:00", "data": {"market": "0x9954b4eef49a268b810bc260ee9278361e29a8f6f4ad816a804dd613ef73a968", "price_changes": [{"asset_id": "407336258606092316833789781486672854343361331985279263948001098476429338355", "price": "0.849", "size": "7.08", "side": "BUY", "hash": "fd65f4842d815bdc6bc9413e915be21a2da9319c", "best_bid": "0.849", "best_ask": "0.881"}, {"asset_id": "50692628443801018513325614545746863026982626993302787461752145605052144027838", "price": "0.151", "size": "7.08", "side": "SELL", "hash": "3c77f28b779c36d6db25871c468c525ba7b9ca39", "best_bid": "0.119", "best_ask": "0.151"}], "timestamp": "1769384589492", "event_type": "price_change"}}
{"_local_timestamp": "2026-01-25T23:43:09.624150+00:00", "data": {"market": "0x9954b4eef49a268b810bc260ee9278361e29a8f6f4ad816a804dd613ef73a968", "price_changes": [{"asset_id": "407336258606092316833789781486672854343361331985279263948001098476429338355", "price": "0.843", "size": "25", "side": "BUY", "hash": "b06ed79ed0c0a5049821a6f6af58ba02878ff18d", "best_bid": "0.849", "best_ask": "0.881"}, {"asset_id": "50692628443801018513325614545746863026982626993302787461752145605052144027838", "price": "0.157", "size": "25", "side": "SELL", "hash": "96c1ace8040b812aadca80a4ee6da3ffc7d35e40", "best_bid": "0.119", "best_ask": "0.151"}], "timestamp": "1769384589495", "event_type": "price_change"}}
{"_local_timestamp": "2026-01-25T23:43:09.628917+00:00", "data": {"market": "0x9954b4eef49a268b810bc260ee9278361e29a8f6f4ad816a804dd613ef73a968", "price_changes": [{"asset_id": "407336258606092316833789781486672854343361331985279263948001098476429338355", "price": "0.843", "size": "50", "side": "BUY", "hash": "5796aa99d811c94b3b81a7a594db5e2d9cc28eff", "best_bid": "0.849", "best_ask": "0.881"}, {"asset_id": "50692628443801018513325614545746863026982626993302787461752145605052144027838", "price": "0.157", "size": "50", "side": "SELL", "hash": "26068bfd55b3adb077ccd7a9408f7ff3e2e15ebd", "best_bid": "0.119", "best_ask": "0.151"}], "timestamp": "1769384589500", "event_type": "price_change"}}
{"_local_timestamp": "2026-01-25T23:43:09.631021+00:00", "data": {"market": "0x9954b4eef49a268b810bc260ee9278361e29a8f6f4ad816a804dd613ef73a968", "price_changes": [{"asset_id": "407336258606092316833789781486672854343361331985279263948001098476429338355", "price": "0.84", "size": "50", "side": "BUY", "hash": "1f20804c38cd2923d3405188714cc1ce402287a9", "best_bid": "0.849", "best_ask": "0.881"}, {"asset_id": "50692628443801018513325614545746863026982626993302787461752145605052144027838", "price": "0.16", "size": "50", "side": "SELL", "hash": "1b5290c1ba4e80740a2c356fae4b6e428a95eec9", "best_bid": "0.119", "best_ask": "0.151"}], "timestamp": "1769384589501", "event_type": "price_change"}}
{"_local_timestamp": "2026-01-25T23:43:09.642864+00:00", "data": {"market": "0x14dbdb6274de6bcc65ce2b628c6636ff210fd452d095b0f14fdb1d376b31cecf", "price_changes": [{"asset_id": "84001958871872382698065661000901363707704455879969183740457806718395695678527", "price": "0.63", "size": "0", "side": "BUY", "hash": "ec80e2597e507f010c672d8c2e6e2227a4e1d7c3", "best_bid": "0.77", "best_ask": "0.79"}, {"asset_id": "108446172107941165064806998519652737542801121226691431615334275432295450338136", "price": "0.37", "size": "0", "side": "SELL", "hash": "9a9ad6453b4d382989aea89f213a7f8b55bb5bdb", "best_bid": "0.21", "best_ask": "0.23"}], "timestamp": "1769384589512", "event_type": "price_change"}}
{"_local_timestamp": "2026-01-25T23:43:09.648426+00:00", "data": {"market": "0x9954b4eef49a268b810bc260ee9278361e29a8f6f4ad816a804dd613ef73a968", "price_changes": [{"asset_id": "407336258606092316833789781486672854343361331985279263948001098476429338355", "price": "0.816", "size": "0", "side": "BUY", "hash": "5644a6a9371b6cc611f8607b4796b36cb0ccec06", "best_bid": "0.849", "best_ask": "0.881"}, {"asset_id": "50692628443801018513325614545746863026982626993302787461752145605052144027838", "price": "0.184", "size": "0", "side": "SELL", "hash": "35a541cdb4feb2695c3067a154f3ebdb2221dc7e", "best_bid": "0.119", "best_ask": "0.151"}], "timestamp": "1769384589512", "event_type": "price_change"}}
{"_local_timestamp": "2026-01-25T23:43:09.650686+00:00", "data": {"market": "0x8b89ea6de714f69d3418f77614b1dd5f9204443d8bc8fca1cb3d4b5cb7d0a1f5", "price_changes": [{"asset_id": "15952689881952595538604299570791504336373523211007351100313552761527006627492", "price": "0.838", "size": "0", "side": "BUY", "hash": "2766c194f591c2ec006446f81584bb744f42e0d8", "best_bid": "0.998", "best_ask": "0.999"}, {"asset_id": "91288830864405819371669895951357549933848133831456873504828139312461957559857", "price": "0.162", "size": "0", "side": "SELL", "hash": "b76dd3c3eae5f88a6e369de299be9767a050bf66", "best_bid": "0.001", "best_ask": "0.002"}], "timestamp": "1769384589512", "event_type": "price_change"}}
{"_local_timestamp": "2026-01-25T23:43:09.690320+00:00", "data": {"market": "0x3d2a697437b1093ad06d6a74c6fb5a2a499b15d7e895500b5153f66bfaa0e602", "price_changes": [{"asset_id": "88196724466506103782248946687236791868579928810145867200121613054260505717011", "price": "0.865", "size": "0", "side": "BUY", "hash": "b16768c31fe460ada99de682f4746d0820ddcb47", "best_bid": "0.981", "best_ask": "0.985"}, {"asset_id": "29378510610351498292793924336050369056882113454472455899117956728534280393801", "price": "0.135", "size": "0", "side": "SELL", "hash": "305e761edccad5454a0044828aeb16d98b8f5779", "best_bid": "0.015", "best_ask": "0.019"}], "timestamp": "1769384589512", "event_type": "price_change"}}
{"_local_timestamp": "2026-01-25T23:43:09.692525+00:00", "data": {"market": "0x9954b4eef49a268b810bc260ee9278361e29a8f6f4ad816a804dd613ef73a968", "price_changes": [{"asset_id": "407336258606092316833789781486672854343361331985279263948001098476429338355", "price": "0.84", "size": "0", "side": "BUY", "hash": "c2572fe87154cd1c3e18bfc88cd39c012fc902d2", "best_bid": "0.849", "best_ask": "0.881"}, {"asset_id": "50692628443801018513325614545746863026982626993302787461752145605052144027838", "price": "0.16", "size": "0", "side": "SELL", "hash": "82d202874ec709fa96ee3b3815f9e287c17e2f4f", "best_bid": "0.119", "best_ask": "0.151"}], "timestamp": "1769384589529", "event_type": "price_change"}}
{"_local_timestamp": "2026-01-25T23:43:09.757713+00:00", "data": {"market": "0x9954b4eef49a268b810bc260ee9278361e29a8f6f4ad816a804dd613ef73a968", "price_changes": [{"asset_id": "407336258606092316833789781486672854343361331985279263948001098476429338355", "price": "0.798", "size": "20", "side": "BUY", "hash": "cf0eb9a6b74ea99458e3d96fb027ee69268b26c0", "best_bid": "0.849", "best_ask": "0.881"}, {"asset_id": "50692628443801018513325614545746863026982626993302787461752145605052144027838", "price": "0.202", "size": "20", "side": "SELL", "hash": "a052fe63ff03017e9c2a46d84a0283634578d020", "best_bid": "0.119", "best_ask": "0.151"}], "timestamp": "1769384589611", "event_type": "price_change"}}
{"_local_timestamp": "2026-01-25T23:43:09.760445+00:00", "data": {"market": "0x14dbdb6274de6bcc65ce2b628c6636ff210fd452d095b0f14fdb1d376b31cecf", "price_changes": [{"asset_id": "84001958871872382698065661000901363707704455879969183740457806718395695678527", "price": "0.43", "size": "10", "side": "BUY", "hash": "7eee5b501a467fe9a795e20e05590e4da95738e1", "best_bid": "0.77", "best_ask": "0.79"}, {"asset_id": "108446172107941165064806998519652737542801121226691431615334275432295450338136", "price": "0.57", "size": "10", "side": "SELL", "hash": "12f550999a3e32fd4bdcd3b338f8ddd60b5dcf12", "best_bid": "0.21", "best_ask": "0.23"}], "timestamp": "1769384589611", "event_type": "price_change"}}
{"_local_timestamp": "2026-01-25T23:43:09.767741+00:00", "data": {"market": "0x3d2a697437b1093ad06d6a74c6fb5a2a499b15d7e895500b5153f66bfaa0e602", "price_changes": [{"asset_id": "88196724466506103782248946687236791868579928810145867200121613054260505717011", "price": "0.601", "size": "10", "side": "BUY", "hash": "bf79d05327fe35852660b535242b84eb3dcd323e", "best_bid": "0.981", "best_ask": "0.985"}, {"asset_id": "29378510610351498292793924336050369056882113454472455899117956728534280393801", "price": "0.399", "size": "10", "side": "SELL", "hash": "8a9f6971967fa5266a4693bc862f070c41c79b39", "best_bid": "0.015", "best_ask": "0.019"}], "timestamp": "1769384589611", "event_type": "price_change"}}
{"_local_timestamp": "2026-01-25T23:43:09.770561+00:00", "data": {"market": "0x8b89ea6de714f69d3418f77614b1dd5f9204443d8bc8fca1cb3d4b5cb7d0a1f5", "price_changes": [{"asset_id": "15952689881952595538604299570791504336373523211007351100313552761527006627492", "price": "0.824", "size": "10", "side": "BUY", "hash": "be2043139883b3415d5a493942e66a422f030b45", "best_bid": "0.998", "best_ask": "0.999"}, {"asset_id": "91288830864405819371669895951357549933848133831456873504828139312461957559857", "price": "0.176", "size": "10", "side": "SELL", "hash": "0a2a8cf34b7e77d80d9b9b333f323e99e2da69fd", "best_bid": "0.001", "best_ask": "0.002"}], "timestamp": "1769384589611", "event_type": "price_change"}}
{"_local_timestamp": "2026-01-25T23:43:09.772947+00:00", "data": {"market": "0x9954b4eef49a268b810bc260ee9278361e29a8f6f4ad816a804dd613ef73a968", "price_changes": [{"asset_id": "407336258606092316833789781486672854343361331985279263948001098476429338355", "price": "0.58", "size": "400", "side": "BUY", "hash": "b700a1ad5fb9c53395252dbe8cf7dee647a6687c", "best_bid": "0.849", "best_ask": "0.881"}, {"asset_id": "50692628443801018513325614545746863026982626993302787461752145605052144027838", "price": "0.42", "size": "400", "side": "SELL", "hash": "65289fbdb9cf63d2575827e1c75d0c233416e867", "best_bid": "0.119", "best_ask": "0.151"}], "timestamp": "1769384589612", "event_type": "price_change"}}
{"_local_timestamp": "2026-01-25T23:43:09.818513+00:00", "data": {"market": "0x85f3e001ffe2a24f985b939460d0cc22041d47107ed8c681f75abb6a5bd1d1d7", "price_changes": [{"asset_id": "91490628576757362533849475709592129096879082569664806718559823554313287888164", "price": "0.87", "size": "34", "side": "BUY", "hash": "909ecbeeee8a62f1065c88308f486e05161fc3b3", "best_bid": "0.88", "best_ask": "0.9"}, {"asset_id": "26510384225806040730267502985578081313836463589753281281933174278980674429194", "price": "0.13", "size": "34", "side": "SELL", "hash": "febc5cb410f67378e495044ed5d1ca6258511349", "best_bid": "0.1", "best_ask": "0.12"}], "timestamp": "1769384589643", "event_type": "price_change"}}
{"_local_timestamp": "2026-01-25T23:43:11.635642+00:00", "data": {"market": "0x1c60f9adb1d786b6fe78d63fd9f82dbb293fa06241532fb5ba43f8d8411cde1e", "price_changes": [{"asset_id": "76633639806751295595699993448608387906622374020066717378577586177644656154703", "price": "0.73", "size": "0", "side": "BUY", "hash": "e9928edbba2037db921e6f2247c5fcc758ac3f93", "best_bid": "0.8", "best_ask": "0.82"}, {"asset_id": "5252381880374485440665230178984721306055940128786215274896991682225319468348", "price": "0.27", "size": "0", "side": "SELL", "hash": "01f1751c9e044a36c669df27a52f49aa18f01f2e", "best_bid": "0.18", "best_ask": "0.2"}], "timestamp": "1769384591492", "event_type": "price_change"}}
{"_local_timestamp": "2026-01-25T23:43:11.637748+00:00", "data": {"market": "0x9954b4eef49a268b810bc260ee9278361e29a8f6f4ad816a804dd613ef73a968", "price_changes": [{"asset_id": "407336258606092316833789781486672854343361331985279263948001098476429338355", "price": "0.797", "size": "0", "side": "BUY", "hash": "28ae43f4f9b4a366a4cd2e39d0001d6e90b1d76c", "best_bid": "0.849", "best_ask": "0.881"}, {"asset_id": "50692628443801018513325614545746863026982626993302787461752145605052144027838", "price": "0.203", "size": "0", "side": "SELL", "hash": "c4c3f826823638cc9c15015e9fdff6fa1b237a6f", "best_bid": "0.119", "best_ask": "0.151"}], "timestamp": "1769384591492", "event_type": "price_change"}}
{"_local_timestamp": "2026-01-25T23:43:11.639683+00:00", "data": {"market": "0x3d2a697437b1093ad06d6a74c6fb5a2a499b15d7e895500b5153f66bfaa0e602", "price_changes": [{"asset_id": "88196724466506103782248946687236791868579928810145867200121613054260505717011", "price": "0.866", "size": "0", "side": "BUY", "hash": "60ebbf915e3cf11d0055d5eca15e3a8a5f105d5c", "best_bid": "0.981", "best_ask": "0.985"}, {"asset_id": "29378510610351498292793924336050369056882113454472455899117956728534280393801", "price": "0.134", "size": "0", "side": "SELL", "hash": "509103d6a620cf45983c514eda289429a171a69e", "best_bid": "0.015", "best_ask": "0.019"}], "timestamp": "1769384591492", "event_type": "price_change"}}
{"_local_timestamp": "2026-01-25T23:43:11.641619+00:00", "data": {"market": "0x8b89ea6de714f69d3418f77614b1dd5f9204443d8bc8fca1cb3d4b5cb7d0a1f5", "price_changes": [{"asset_id": "15952689881952595538604299570791504336373523211007351100313552761527006627492", "price": "0.839", "size": "0", "side": "BUY", "hash": "862dc6951a1f25b7c3f7c274ee60fb9951e9efad", "best_bid": "0.998", "best_ask": "0.999"}, {"asset_id": "91288830864405819371669895951357549933848133831456873504828139312461957559857", "price": "0.161", "size": "0", "side": "SELL", "hash": "54ab95d26e57655daa2717da18c95f5c041f2a9a", "best_bid": "0.001", "best_ask": "0.002"}], "timestamp": "1769384591492", "event_type": "price_change"}}
{"_local_timestamp": "2026-01-25T23:43:11.643565+00:00", "data": {"market": "0x1672bfe7ef6d85a4ecffa9faf1149ef1a1661dd919598ab46b04a6ae0a4ffab4", "price_changes": [{"asset_id": "67406170302156428995276860611642329904770865734970239500712482048975306249694", "price": "0.824", "size": "0", "side": "BUY", "hash": "bccbdd7818dcd3c284b69a33cb9b1219ed3794b0", "best_bid": "0.998", "best_ask": "0.999"}, {"asset_id": "47611238256675927046254833225025176882857384948614440601874808834644661735134", "price": "0.176", "size": "0", "side": "SELL", "hash": "c97521ad24fed5eaae70ba05141426ee39633c0b", "best_bid": "0.001", "best_ask": "0.002"}], "timestamp": "1769384591492", "event_type": "price_change"}}
{"_local_timestamp": "2026-01-25T23:43:11.661581+00:00", "data": {"market": "0x9954b4eef49a268b810bc260ee9278361e29a8f6f4ad816a804dd613ef73a968", "price_changes": [{"asset_id": "407336258606092316833789781486672854343361331985279263948001098476429338355", "price": "0.799", "size": "20", "side": "BUY", "hash": "598badfc5f5ccf13f4f7fbdbe08163553e027d43", "best_bid": "0.849", "best_ask": "0.881"}, {"asset_id": "50692628443801018513325614545746863026982626993302787461752145605052144027838", "price": "0.201", "size": "20", "side": "SELL", "hash": "afa24063c455fd041b906e72cc004d8b0e5c8e01", "best_bid": "0.119", "best_ask": "0.151"}], "timestamp": "1769384591524", "event_type": "price_change"}}
{"_local_timestamp": "2026-01-25T23:43:11.663712+00:00", "data": {"market": "0x1672bfe7ef6d85a4ecffa9faf1149ef1a1661dd919598ab46b04a6ae0a4ffab4", "price_changes": [{"asset_id": "67406170302156428995276860611642329904770865734970239500712482048975306249694", "price": "0.925", "size": "40", "side": "BUY", "hash": "068f667839f859f86ef56b0bf971d3fe01efb437", "best_bid": "0.998", "best_ask": "0.999"}, {"asset_id": "47611238256675927046254833225025176882857384948614440601874808834644661735134", "price": "0.075", "size": "40", "side": "SELL", "hash": "3d384c8d413384e53d25b197dfac12932568b0fb", "best_bid": "0.001", "best_ask": "0.002"}], "timestamp": "1769384591524", "event_type": "price_change"}}
{"_local_timestamp": "2026-01-25T23:43:11.665757+00:00", "data": {"market": "0x8b89ea6de714f69d3418f77614b1dd5f9204443d8bc8fca1cb3d4b5cb7d0a1f5", "price_changes": [{"asset_id": "15952689881952595538604299570791504336373523211007351100313552761527006627492", "price": "0.924", "size": "20", "side": "BUY", "hash": "c69c29711d912717d2f48f2509c63be21baff37e", "best_bid": "0.998", "best_ask": "0.999"}, {"asset_id": "91288830864405819371669895951357549933848133831456873504828139312461957559857", "price": "0.076", "size": "20", "side": "SELL", "hash": "b4778f790644498cf6cc5c6929b93c45137efdd9", "best_bid": "0.001", "best_ask": "0.002"}], "timestamp": "1769384591524", "event_type": "price_change"}}
{"_local_timestamp": "2026-01-25T23:43:11.667808+00:00", "data": {"market": "0x3d2a697437b1093ad06d6a74c6fb5a2a499b15d7e895500b5153f66bfaa0e602", "price_changes": [{"asset_id": "88196724466506103782248946687236791868579928810145867200121613054260505717011", "price": "0.864", "size": "20", "side": "BUY", "hash": "4d2ef9eef87d423ec6a1428dd28b6dedf2b719fc", "best_bid": "0.981", "best_ask": "0.985"}, {"asset_id": "29378510610351498292793924336050369056882113454472455899117956728534280393801", "price": "0.136", "size": "20", "side": "SELL", "hash": "ef2e49b25abcd989be03a27d220ad9fbb72a6284", "best_bid": "0.015", "best_ask": "0.019"}], "timestamp": "1769384591524", "event_type": "price_change"}}
{"_local_timestamp": "2026-01-25T23:43:11.670017+00:00", "data": {"market": "0x1c60f9adb1d786b6fe78d63fd9f82dbb293fa06241532fb5ba43f8d8411cde1e", "price_changes": [{"asset_id": "76633639806751295595699993448608387906622374020066717378577586177644656154703", "price": "0.72", "size": "20", "side": "BUY", "hash": "ad51122d0f67e54e705385f21e2dbd7bdaac752e", "best_bid": "0.8", "best_ask": "0.82"}, {"asset_id": "5252381880374485440665230178984721306055940128786215274896991682225319468348", "price": "0.28", "size": "20", "side": "SELL", "hash": "4aba3bc72816259e4253fa5473945fcc177b7cc6", "best_bid": "0.18", "best_ask": "0.2"}], "timestamp": "1769384591524", "event_type": "price_change"}}
{"_local_timestamp": "2026-01-25T23:43:11.832180+00:00", "data": {"market": "0x9954b4eef49a268b810bc260ee9278361e29a8f6f4ad816a804dd613ef73a968", "price_changes": [{"asset_id": "407336258606092316833789781486672854343361331985279263948001098476429338355", "price": "0.839", "size": "50", "side": "BUY", "hash": "56a1ecc0e891950aaec89ff359f7242c3f7d156a", "best_bid": "0.849", "best_ask": "0.881"}, {"asset_id": "50692628443801018513325614545746863026982626993302787461752145605052144027838", "price": "0.161", "size": "50", "side": "SELL", "hash": "114c477fde5b27014bbd54b193f912f6c344b6cf", "best_bid": "0.119", "best_ask": "0.151"}], "timestamp": "1769384591604", "event_type": "price_change"}}
{"_local_timestamp": "2026-01-25T23:43:11.834312+00:00", "data": {"market": "0x1c60f9adb1d786b6fe78d63fd9f82dbb293fa06241532fb5ba43f8d8411cde1e", "price_changes": [{"asset_id": "76633639806751295595699993448608387906622374020066717378577586177644656154703", "price": "0.72", "size": "70", "side": "BUY", "hash": "9e79a5df4d823602b0bb147cc5c942b79cd397e3", "best_bid": "0.8", "best_ask": "0.82"}, {"asset_id": "5252381880374485440665230178984721306055940128786215274896991682225319468348", "price": "0.28", "size": "70", "side": "SELL", "hash": "55ba0653d9cb6ac91f4488e7b844ed4f641fce18", "best_bid": "0.18", "best_ask": "0.2"}], "timestamp": "1769384591634", "event_type": "price_change"}}
{"_local_timestamp": "2026-01-25T23:43:11.836417+00:00", "data": {"market": "0x9954b4eef49a268b810bc260ee9278361e29a8f6f4ad816a804dd613ef73a968", "price_changes": [{"asset_id": "407336258606092316833789781486672854343361331985279263948001098476429338355", "price": "0.839", "size": "100", "side": "BUY", "hash": "0576819199fac6c91b1ed89ff51cd997bad97b3f", "best_bid": "0.849", "best_ask": "0.881"}, {"asset_id": "50692628443801018513325614545746863026982626993302787461752145605052144027838", "price": "0.161", "size": "100", "side": "SELL", "hash": "176f005519b0be31ac826dde8d18fe8777581aed", "best_bid": "0.119", "best_ask": "0.151"}], "timestamp": "1769384591640", "event_type": "price_change"}}
{"_local_timestamp": "2026-01-25T23:43:11.838596+00:00", "data": {"market": "0x1c60f9adb1d786b6fe78d63fd9f82dbb293fa06241532fb5ba43f8d8411cde1e", "price_changes": [{"asset_id": "76633639806751295595699993448608387906622374020066717378577586177644656154703", "price": "0.72", "size": "120", "side": "BUY", "hash": "2430bcefcc175163ef73176ba004b5a2006433fe", "best_bid": "0.8", "best_ask": "0.82"}, {"asset_id": "5252381880374485440665230178984721306055940128786215274896991682225319468348", "price": "0.28", "size": "120", "side": "SELL", "hash": "4880c0e1e73acba691aed2b8452bfacd64a6d488", "best_bid": "0.18", "best_ask": "0.2"}], "timestamp": "1769384591642", "event_type": "price_change"}}
{"_local_timestamp": "2026-01-25T23:43:12.797048+00:00", "data": {"market": "0x1c60f9adb1d786b6fe78d63fd9f82dbb293fa06241532fb5ba43f8d8411cde1e", "price_changes": [{"asset_id": "76633639806751295595699993448608387906622374020066717378577586177644656154703", "price": "0.72", "size": "100", "side": "BUY", "hash": "48d99eb34403c4a8c3a8bc9a5b3432fba3c653b6", "best_bid": "0.8", "best_ask": "0.82"}, {"asset_id": "5252381880374485440665230178984721306055940128786215274896991682225319468348", "price": "0.28", "size": "100", "side": "SELL", "hash": "542bfae79aa49de26d85be7330542dd526d88828", "best_bid": "0.18", "best_ask": "0.2"}], "timestamp": "1769384592662", "event_type": "price_change"}}
{"_local_timestamp": "2026-01-25T23:43:12.807716+00:00", "data": {"market": "0x1c60f9adb1d786b6fe78d63fd9f82dbb293fa06241532fb5ba43f8d8411cde1e", "price_changes": [{"asset_id": "76633639806751295595699993448608387906622374020066717378577586177644656154703", "price": "0.73", "size": "20", "side": "BUY", "hash": "c66cbb3ae8d10daefd14a2d192f7589cc30e83fd", "best_bid": "0.8", "best_ask": "0.82"}, {"asset_id": "5252381880374485440665230178984721306055940128786215274896991682225319468348", "price": "0.27", "size": "20", "side": "SELL", "hash": "0e75d2f1d00c863c5e1ddad1b548709940ef1ec9", "best_bid": "0.18", "best_ask": "0.2"}], "timestamp": "1769384592688", "event_type": "price_change"}}
{"_local_timestamp": "2026-01-25T23:43:12.917663+00:00", "data": {"market": "0x1c60f9adb1d786b6fe78d63fd9f82dbb293fa06241532fb5ba43f8d8411cde1e", "price_changes": [{"asset_id": "76633639806751295595699993448608387906622374020066717378577586177644656154703", "price": "0.72", "size": "50", "side": "BUY", "hash": "488e3e4535fa781dae81870acf4f02e5e7c475ca", "best_bid": "0.8", "best_ask": "0.82"}, {"asset_id": "5252381880374485440665230178984721306055940128786215274896991682225319468348", "price": "0.28", "size": "50", "side": "SELL", "hash": "bb7b3482fdb31641d9423362e98e540e51f77080", "best_bid": "0.18", "best_ask": "0.2"}], "timestamp": "1769384592797", "event_type": "price_change"}}
{"_local_timestamp": "2026-01-25T23:43:12.925097+00:00", "data": {"market": "0x1c60f9adb1d786b6fe78d63fd9f82dbb293fa06241532fb5ba43f8d8411cde1e", "price_changes": [{"asset_id": "76633639806751295595699993448608387906622374020066717378577586177644656154703", "price": "0.72", "size": "0", "side": "BUY", "hash": "0f30cca11e281b1c1013a05db721b09ebd1f1dcc", "best_bid": "0.8", "best_ask": "0.82"}, {"asset_id": "5252381880374485440665230178984721306055940128786215274896991682225319468348", "price": "0.28", "size": "0", "side": "SELL", "hash": "9fe19d436032ebd0c96dfbeb31dd20a7a5ea6911", "best_bid": "0.18", "best_ask": "0.2"}], "timestamp": "1769384592800", "event_type": "price_change"}}
{"_local_timestamp": "2026-01-25T23:43:13.961658+00:00", "data": {"market": "0x1c60f9adb1d786b6fe78d63fd9f82dbb293fa06241532fb5ba43f8d8411cde1e", "price_changes": [{"asset_id": "76633639806751295595699993448608387906622374020066717378577586177644656154703", "price": "0.73", "size": "0", "side": "BUY", "hash": "42728e81a6ceef41f0518b23d7cc4e532704efd2", "best_bid": "0.8", "best_ask": "0.82"}, {"asset_id": "5252381880374485440665230178984721306055940128786215274896991682225319468348", "price": "0.27", "size": "0", "side": "SELL", "hash": "eed1bb94577677e73e54477e64939728136b11e8", "best_bid": "0.18", "best_ask": "0.2"}], "timestamp": "1769384593834", "event_type": "price_change"}}
{"_local_timestamp": "2026-01-25T23:43:13.992003+00:00", "data": {"market": "0x1c60f9adb1d786b6fe78d63fd9f82dbb293fa06241532fb5ba43f8d8411cde1e", "price_changes": [{"asset_id": "76633639806751295595699993448608387906622374020066717378577586177644656154703", "price": "0.72", "size": "20", "side": "BUY", "hash": "63352909e0f267d869f0c5687da9421c8322ff85", "best_bid": "0.8", "best_ask": "0.82"}, {"asset_id": "5252381880374485440665230178984721306055940128786215274896991682225319468348", "price": "0.28", "size": "20", "side": "SELL", "hash": "1cd0b8b8ebc9f1eaccd35f53d87371d4867098e5", "best_bid": "0.18", "best_ask": "0.2"}], "timestamp": "1769384593862", "event_type": "price_change"}}
{"_local_timestamp": "2026-01-25T23:43:25.126833+00:00", "data": {"market": "0x9954b4eef49a268b810bc260ee9278361e29a8f6f4ad816a804dd613ef73a968", "price_changes": [{"asset_id": "407336258606092316833789781486672854343361331985279263948001098476429338355", "price": "0.939", "size": "513.1", "side": "SELL", "hash": "23ac70bf79e14250c116af35b2c06dc183697140", "best_bid": "0.849", "best_ask": "0.881"}, {"asset_id": "50692628443801018513325614545746863026982626993302787461752145605052144027838", "price": "0.061", "size": "513.1", "side": "BUY", "hash": "c93f40871ce844011a1a82315e9f64b56c90fc5a", "best_bid": "0.119", "best_ask": "0.151"}], "timestamp": "1769384604976", "event_type": "price_change"}}
{"_local_timestamp": "2026-01-25T23:43:25.231618+00:00", "data": {"market": "0x1c60f9adb1d786b6fe78d63fd9f82dbb293fa06241532fb5ba43f8d8411cde1e", "price_changes": [{"asset_id": "76633639806751295595699993448608387906622374020066717378577586177644656154703", "price": "0.72", "size": "70", "side": "BUY", "hash": "5b2ca71af18d71fc305ad35f04138958fe0c5218", "best_bid": "0.8", "best_ask": "0.82"}, {"asset_id": "5252381880374485440665230178984721306055940128786215274896991682225319468348", "price": "0.28", "size": "70", "side": "SELL", "hash": "9f4dee79f53064b5d4b0702d37f56ff5dd62e773", "best_bid": "0.18", "best_ask": "0.2"}], "timestamp": "1769384605086", "event_type": "price_change"}}
{"_local_timestamp": "2026-01-25T23:43:25.319610+00:00", "data": {"market": "0x1c60f9adb1d786b6fe78d63fd9f82dbb293fa06241532fb5ba43f8d8411cde1e", "price_changes": [{"asset_id": "76633639806751295595699993448608387906622374020066717378577586177644656154703", "price": "0.72", "size": "120", "side": "BUY", "hash": "a1f395121abaec59fead007cf852a81bb50b93e8", "best_bid": "0.8", "best_ask": "0.82"}, {"asset_id": "5252381880374485440665230178984721306055940128786215274896991682225319468348", "price": "0.28", "size": "120", "side": "SELL", "hash": "b8456d7b8e1c546023199e6b2ebfae88134e4607", "best_bid": "0.18", "best_ask": "0.2"}], "timestamp": "1769384605172", "event_type": "price_change"}}
{"_local_timestamp": "2026-01-25T23:43:25.393029+00:00", "data": {"market": "0x3d2a697437b1093ad06d6a74c6fb5a2a499b15d7e895500b5153f66bfaa0e602", "price_changes": [{"asset_id": "88196724466506103782248946687236791868579928810145867200121613054260505717011", "price": "0.863", "size": "0", "side": "BUY", "hash": "079a718155e8f8413b6755bfbf67b55713b8c525", "best_bid": "0.981", "best_ask": "0.985"}, {"asset_id": "29378510610351498292793924336050369056882113454472455899117956728534280393801", "price": "0.137", "size": "0", "side": "SELL", "hash": "c624e7797844c60e8a54298dff0b23f4454b6506", "best_bid": "0.015", "best_ask": "0.019"}], "timestamp": "1769384605252", "event_type": "price_change"}}
{"_local_timestamp": "2026-01-25T23:43:25.628686+00:00", "data": {"market": "0x3d2a697437b1093ad06d6a74c6fb5a2a499b15d7e895500b5153f66bfaa0e602", "price_changes": [{"asset_id": "88196724466506103782248946687236791868579928810145867200121613054260505717011", "price": "0.602", "size": "20", "side": "BUY", "hash": "42a6ef7fbe43961eda85d937056aa26b319b63a0", "best_bid": "0.981", "best_ask": "0.985"}, {"asset_id": "29378510610351498292793924336050369056882113454472455899117956728534280393801", "price": "0.398", "size": "20", "side": "SELL", "hash": "53c1eafd61867d2cc9bf2de8a11802b070073fd7", "best_bid": "0.015", "best_ask": "0.019"}], "timestamp": "1769384605494", "event_type": "price_change"}}
{"_local_timestamp": "2026-01-25T23:43:27.031846+00:00", "data": {"market": "0x14dbdb6274de6bcc65ce2b628c6636ff210fd452d095b0f14fdb1d376b31cecf", "price_changes": [{"asset_id": "84001958871872382698065661000901363707704455879969183740457806718395695678527", "price": "0.82", "size": "1406.95", "side": "SELL", "hash": "385647530cc1eaba8f49a501d186f388c9152ad3", "best_bid": "0.77", "best_ask": "0.79"}, {"asset_id": "108446172107941165064806998519652737542801121226691431615334275432295450338136", "price": "0.18", "size": "1406.95", "side": "BUY", "hash": "49c02f99c2e52f69d26cd8cd9ec51e21fac49b8d", "best_bid": "0.21", "best_ask": "0.23"}], "timestamp": "1769384606826", "event_type": "price_change"}}
{"_local_timestamp": "2026-01-25T23:43:27.266696+00:00", "data": {"market": "0x1c60f9adb1d786b6fe78d63fd9f82dbb293fa06241532fb5ba43f8d8411cde1e", "price_changes": [{"asset_id": "76633639806751295595699993448608387906622374020066717378577586177644656154703", "price": "0.72", "size": "100", "side": "BUY", "hash": "5c0d4c2d3f1a31fab6f27ddaecf725aceef1c78b", "best_bid": "0.8", "best_ask": "0.82"}, {"asset_id": "5252381880374485440665230178984721306055940128786215274896991682225319468348", "price": "0.28", "size": "100", "side": "SELL", "hash": "91e38e918c05082dedb1684c3016f705a7945c3d", "best_bid": "0.18", "best_ask": "0.2"}], "timestamp": "1769384607117", "event_type": "price_change"}}
{"_local_timestamp": "2026-01-25T23:43:27.279666+00:00", "data": {"market": "0x3d2a697437b1093ad06d6a74c6fb5a2a499b15d7e895500b5153f66bfaa0e602", "price_changes": [{"asset_id": "88196724466506103782248946687236791868579928810145867200121613054260505717011", "price": "0.864", "size": "0", "side": "BUY", "hash": "3fd1a33855ffc72c1c6ef81490c851047b31a13a", "best_bid": "0.981", "best_ask": "0.985"}, {"asset_id": "29378510610351498292793924336050369056882113454472455899117956728534280393801", "price": "0.136", "size": "0", "side": "SELL", "hash": "0acf1e5aa4e5e041e4c51a07ce2201e0fc82730e", "best_bid": "0.015", "best_ask": "0.019"}], "timestamp": "1769384607117", "event_type": "price_change"}}
{"_local_timestamp": "2026-01-25T23:43:27.304383+00:00", "data": {"market": "0x1c60f9adb1d786b6fe78d63fd9f82dbb293fa06241532fb5ba43f8d8411cde1e", "price_changes": [{"asset_id": "76633639806751295595699993448608387906622374020066717378577586177644656154703", "price": "0.73", "size": "20", "side": "BUY", "hash": "01063d55bf4f12f17125b801fc1494cedf94998f", "best_bid": "0.8", "best_ask": "0.82"}, {"asset_id": "5252381880374485440665230178984721306055940128786215274896991682225319468348", "price": "0.27", "size": "20", "side": "SELL", "hash": "17d13e51ae24a7bcac16e07f1719fa3f8635cd35", "best_bid": "0.18", "best_ask": "0.2"}], "timestamp": "1769384607146", "event_type": "price_change"}}
{"_local_timestamp": "2026-01-25T23:43:27.306726+00:00", "data": {"market": "0x3d2a697437b1093ad06d6a74c6fb5a2a499b15d7e895500b5153f66bfaa0e602", "price_changes": [{"asset_id": "88196724466506103782248946687236791868579928810145867200121613054260505717011", "price": "0.603", "size": "20", "side": "BUY", "hash": "e95531b3d05536e871bdc490862a534f6e334ded", "best_bid": "0.981", "best_ask": "0.985"}, {"asset_id": "29378510610351498292793924336050369056882113454472455899117956728534280393801", "price": "0.397", "size": "20", "side": "SELL", "hash": "e6b714390851136e0c6b3cc0cff5a242f0be5967", "best_bid": "0.015", "best_ask": "0.019"}], "timestamp": "1769384607146", "event_type": "price_change"}}
{"_local_timestamp": "2026-01-25T23:43:27.404586+00:00", "data": {"market": "0x1c60f9adb1d786b6fe78d63fd9f82dbb293fa06241532fb5ba43f8d8411cde1e", "price_changes": [{"asset_id": "76633639806751295595699993448608387906622374020066717378577586177644656154703", "price": "0.72", "size": "50", "side": "BUY", "hash": "b25384e3843136441b5cefbcd0bb9f9d9539f652", "best_bid": "0.8", "best_ask": "0.82"}, {"asset_id": "5252381880374485440665230178984721306055940128786215274896991682225319468348", "price": "0.28", "size": "50", "side": "SELL", "hash": "5cc91868e20a67ef6ac91932551333097de0aae2", "best_bid": "0.18", "best_ask": "0.2"}], "timestamp": "1769384607263", "event_type": "price_change"}}
{"_local_timestamp": "2026-01-25T23:43:27.409050+00:00", "data": {"market": "0x1c60f9adb1d786b6fe78d63fd9f82dbb293fa06241532fb5ba43f8d8411cde1e", "price_changes": [{"asset_id": "76633639806751295595699993448608387906622374020066717378577586177644656154703", "price": "0.72", "size": "0", "side": "BUY", "hash": "c0e2632f64349d7b0c51a6722650712a5c231e4a", "best_bid": "0.8", "best_ask": "0.82"}, {"asset_id": "5252381880374485440665230178984721306055940128786215274896991682225319468348", "price": "0.28", "size": "0", "side": "SELL", "hash": "cdc74eba3e949ebc38188efbc4d781b081a5ed1c", "best_bid": "0.18", "best_ask": "0.2"}], "timestamp": "1769384607269", "event_type": "price_change"}}
