{"_local_timestamp": "2026-01-25T23:41:09.032654+00:00", "data": [{"market": "0x538be58810bd07707c1e849da9b4de12dc6617739c2e87043ea9b7fb2b6266c3", "asset_id": "41247652063966004401306857419416685235874842651432515489339067969075836389387", "timestamp": "1769384401586", "hash": "ed582b0ec520dbdd077ae9b2e4f8488c5f2390c1", "bids": [{"price": "0.01", "size": "14091.22"}, {"price": "0.02", "size": "2450"}, {"price": "0.03", "size": "8.03"}, {"price": "0.07", "size": "3999.11"}, {"price": "0.08", "size": "2799.11"}, {"price": "0.09", "size": "7.34"}, {"price": "0.12", "size": "450"}, {"price": "0.14", "size": "50"}, {"price": "0.2", "size": "400"}, {"price": "0.21", "size": "200"}, {"price": "0.27", "size": "200"}, {"price": "0.34", "size": "100"}, {"price": "0.37", "size": "300"}, {"price": "0.41", "size": "200"}, {"price": "0.45", "size": "125"}, {"price": "0.48", "size": "75"}, {"price": "0.5", "size": "933"}, {"price": "0.62", "size": "1000"}, {"price": "0.63", "size": "720.63"}, {"price": "0.64", "size": "17.18"}, {"price": "0.66", "size": "20"}, {"price": "0.67", "size": "436.21"}, {"price": "0.68", "size": "670.52"}, {"price": "0.69", "size": "198.93"}, {"price": "0.7", "size": "7108.37"}, {"price": "0.71", "size": "1250.5"}, {"price": "0.72", "size": "205"}], "asks": [{"price": "0.99", "size": "11289.46"}, {"price": "0.98", "size": "292"}, {"price": "0.97", "size": "30.65"}, {"price": "0.9", "size": "100"}, {"price": "0.89", "size": "833"}, {"price": "0.87", "size": "300"}, {"price": "0.86", "size": "200"}, {"price": "0.85", "size": "100"}, {"price": "0.84", "size": "325"}, {"price": "0.83", "size": "151.47"}, {"price": "0.82", "size": "261.11"}, {"price": "0.8", "size": "1200"}, {"price": "0.79", "size": "500"}, {"price": "0.77", "size": "100"}, {"price": "0.76", "size": "90"}, {"price": "0.75", "size": "20.7"}], "event_type": "book", "last_trade_price": "0.250"}, {"market": "0x538be58810bd07707c1e849da9b4de12dc6617739c2e87043ea9b7fb2b6266c3", "asset_id": "58617143502730239165118144708053321823503557172455753166265292779077877259718", "timestamp": "1769384401586", "hash": "fe4be63ea0c06e7f4956b124331a3c76cd84608a", "bids": [{"price": "0.01", "size": "11289.46"}, {"price": "0.02", "size": "292"}, {"price": "0.03", "size": "30.65"}, {"price": "0.1", "size": "100"}, {"price": "0.11", "size": "833"}, {"price": "0.13", "size": "300"}, {"price": "0.14", "size": "200"}, {"price": "0.15", "size": "100"}, {"price": "0.16", "size": "325"}, {"price": "0.17", "size": "151.47"}, {"price": "0.18", "size": "261.11"}, {"price": "0.2", "size": "1200"}, {"price": "0.21", "size": "500"}, {"price": "0.23", "size": "100"}, {"price": "0.24", "size": "90"}, {"price": "0.25", "size": "20.7"}], "asks": [{"price": "0.99", "size": "14091.22"}, {"price": "0.98", "size": "2450"}, {"price": "0.97", "size": "8.03"}, {"price": "0.93", "size": "3999.11"}, {"price": "0.92", "size": "2799.11"}, {"price": "0.91", "size": "7.34"}, {"price": "0.88", "size": "450"}, {"price": "0.86", "size": "50"}, {"price": "0.8", "size": "400"}, {"price": "0.79", "size": "200"}, {"price": "0.73", "size": "200"}, {"price": "0.66", "size": "100"}, {"price": "0.63", "size": "300"}, {"price": "0.59", "size": "200"}, {"price": "0.55", "size": "125"}, {"price": "0.52", "size": "75"}, {"price": "0.5", "size": "933"}, {"price": "0.38", "size": "1000"}, {"price": "0.37", "size": "720.63"}, {"price": "0.36", "size": "17.18"}, {"price": "0.34", "size": "20"}, {"price": "0.33", "size": "436.21"}, {"price": "0.32", "size": "670.52"}, {"price": "0.31", "size": "198.93"}, {"price": "0.3", "size": "7108.37"}, {"price": "0.29", "size": "1250.5"}, {"price": "0.28", "size": "205"}], "event_type": "book", "last_trade_price": "0.250"}]}
{"_local_timestamp": "2026-01-25T23:41:13.738535+00:00", "data": {"market": "0x538be58810bd07707c1e849da9b4de12dc6617739c2e87043ea9b7fb2b6266c3", "price_changes": [{"asset_id": "41247652063966004401306857419416685235874842651432515489339067969075836389387", "price": "0.72", "size": "5", "side": "BUY", "hash": "58d14de363fb4a5dc243888033d4916d0ed5486b", "best_bid": "0.72", "best_ask": "0.75"}, {"asset_id": "58617143502730239165118144708053321823503557172455753166265292779077877259718", "price": "0.28", "size": "5", "side": "SELL", "hash": "43cac785fed378dddfaab0d41ac0852ecb844ac4", "best_bid": "0.25", "best_ask": "0.28"}], "timestamp": "1769384473672", "event_type": "price_change"}}
{"_local_timestamp": "2026-01-25T23:41:13.747531+00:00", "data": {"market": "0x538be58810bd07707c1e849da9b4de12dc6617739c2e87043ea9b7fb2b6266c3", "price_changes": [{"asset_id": "41247652063966004401306857419416685235874842651432515489339067969075836389387", "price": "0.7", "size": "7308.37", "side": "BUY", "hash": "9d7ea0f7bbdabcff98d420dae6029518aaed085e", "best_bid": "0.72", "best_ask": "0.75"}, {"asset_id": "58617143502730239165118144708053321823503557172455753166265292779077877259718", "price": "0.3", "size": "7308.37", "side": "SELL", "hash": "88fecb33b0a05bb35e0ed87ec19851069142c6f3", "best_bid": "0.25", "best_ask": "0.28"}], "timestamp": "1769384473678", "event_type": "price_change"}}
{"_local_timestamp": "2026-01-25T23:41:15.764588+00:00", "data": {"market": "0x538be58810bd07707c1e849da9b4de12dc6617739c2e87043ea9b7fb2b6266c3", "price_changes": [{"asset_id": "41247652063966004401306857419416685235874842651432515489339067969075836389387", "price": "0.71", "size": "1450.5", "side": "BUY", "hash": "fde7b7320346c41d1509ef2bf049b8ee66ff80a1", "best_bid": "0.72", "best_ask": "0.75"}, {"asset_id": "58617143502730239165118144708053321823503557172455753166265292779077877259718", "price": "0.29", "size": "1450.5", "side": "SELL", "hash": "5a4041d8376c3133b3b104a2c886ab6a0f903c07", "best_bid": "0.25", "best_ask": "0.28"}], "timestamp": "1769384475675", "event_type": "price_change"}}
{"_local_timestamp": "2026-01-25T23:41:15.765341+00:00", "data": {"market": "0x538be58810bd07707c1e849da9b4de12dc6617739c2e87043ea9b7fb2b6266c3", "price_changes": [{"asset_id": "41247652063966004401306857419416685235874842651432515489339067969075836389387", "price": "0.7", "size": "7108.37", "side": "BUY", "hash": "f8321f63bfd4bee3a311eb1569988eb82ec29e4a", "best_bid": "0.72", "best_ask": "0.75"}, {"asset_id": "58617143502730239165118144708053321823503557172455753166265292779077877259718", "price": "0.3", "size": "7108.37", "side": "SELL", "hash": "81391220834ea0d98c6158558d4735d514a108ef", "best_bid": "0.25", "best_ask": "0.28"}], "timestamp": "1769384475679", "event_type": "price_change"}}
{"_local_timestamp": "2026-01-25T23:42:29.479323+00:00", "data": {"market": "0x538be58810bd07707c1e849da9b4de12dc6617739c2e87043ea9b7fb2b6266c3", "price_changes": [{"asset_id": "41247652063966004401306857419416685235874842651432515489339067969075836389387", "price": "0.71", "size": "1250.5", "side": "BUY", "hash": "96f7a65bcc44fcd47b51817a40c398e287e70f51", "best_bid": "0.72", "best_ask": "0.75"}, {"asset_id": "58617143502730239165118144708053321823503557172455753166265292779077877259718", "price": "0.29", "size": "1250.5", "side": "SELL", "hash": "7ba42201098369253eed910b6f20586195f951b4", "best_bid": "0.25", "best_ask": "0.28"}], "timestamp": "1769384549381", "event_type": "price_change"}}
{"_local_timestamp": "2026-01-25T23:42:29.480401+00:00", "data": {"market": "0x538be58810bd07707c1e849da9b4de12dc6617739c2e87043ea9b7fb2b6266c3", "price_changes": [{"asset_id": "41247652063966004401306857419416685235874842651432515489339067969075836389387", "price": "0.7", "size": "7308.37", "side": "BUY", "hash": "7ede4336a9ea1de92c234dd393155de5f84be5ac", "best_bid": "0.72", "best_ask": "0.75"}, {"asset_id": "58617143502730239165118144708053321823503557172455753166265292779077877259718", "price": "0.3", "size": "7308.37", "side": "SELL", "hash": "4f4115fcb0bf1ac07d827d0366fbabe44ea182ba", "best_bid": "0.25", "best_ask": "0.28"}], "timestamp": "1769384549382", "event_type": "price_change"}}
{"_local_timestamp": "2026-01-25T23:42:31.478107+00:00", "data": {"market": "0x538be58810bd07707c1e849da9b4de12dc6617739c2e87043ea9b7fb2b6266c3", "price_changes": [{"asset_id": "41247652063966004401306857419416685235874842651432515489339067969075836389387", "price": "0.7", "size": "7108.37", "side": "BUY", "hash": "60b831108524acdfed275f4c5c8054219cce6895", "best_bid": "0.72", "best_ask": "0.75"}, {"asset_id": "58617143502730239165118144708053321823503557172455753166265292779077877259718", "price": "0.3", "size": "7108.37", "side": "SELL", "hash": "6e4de08bc2d90f3592662363e7ffa87e024c81e8", "best_bid": "0.25", "best_ask": "0.28"}], "timestamp": "1769384551379", "event_type": "price_change"}}
{"_local_timestamp": "2026-01-25T23:42:31.482516+00:00", "data": {"market": "0x538be58810bd07707c1e849da9b4de12dc6617739c2e87043ea9b7fb2b6266c3", "price_changes": [{"asset_id": "41247652063966004401306857419416685235874842651432515489339067969075836389387", "price": "0.72", "size": "205", "side": "BUY", "hash": "ae8c07194b79ad2807c628772c5b4d7cf5b5141e", "best_bid": "0.72", "best_ask": "0.75"}, {"asset_id": "58617143502730239165118144708053321823503557172455753166265292779077877259718", "price": "0.28", "size": "205", "side": "SELL", "hash": "237d8468ee5986145b7e86a15d8250a75f5a11f6", "best_bid": "0.25", "best_ask": "0.28"}], "timestamp": "1769384551380", "event_type": "price_change"}}
{"_local_timestamp": "2026-01-25T23:43:41.023787+00:00", "data": {"market": "0x538be58810bd07707c1e849da9b4de12dc6617739c2e87043ea9b7fb2b6266c3", "price_changes": [{"asset_id": "41247652063966004401306857419416685235874842651432515489339067969075836389387", "price": "0.72", "size": "5", "side": "BUY", "hash": "3cdebbdaf400eb8bf0eadc786f1a9b29da13c48f", "best_bid": "0.72", "best_ask": "0.75"}, {"asset_id": "58617143502730239165118144708053321823503557172455753166265292779077877259718", "price": "0.28", "size": "5", "side": "SELL", "hash": "44d4414b1866665230bf11336e9abc0257df903b", "best_bid": "0.25", "best_ask": "0.28"}], "timestamp": "1769384620904", "event_type": "price_change"}}
{"_local_timestamp": "2026-01-25T23:43:41.032366+00:00", "data": {"market": "0x538be58810bd07707c1e849da9b4de12dc6617739c2e87043ea9b7fb2b6266c3", "price_changes": [{"asset_id": "41247652063966004401306857419416685235874842651432515489339067969075836389387", "price": "0.7", "size": "7308.37", "side": "BUY", "hash": "3063a951dab51dce5a8285ffe6c01a14d83ffcbd", "best_bid": "0.72", "best_ask": "0.75"}, {"asset_id": "58617143502730239165118144708053321823503557172455753166265292779077877259718", "price": "0.3", "size": "7308.37", "side": "SELL", "hash": "ab19ac7645635ac94103ab1459eeff634c748398", "best_bid": "0.25", "best_ask": "0.28"}], "timestamp": "1769384620908", "event_type": "price_change"}}
{"_local_timestamp": "2026-01-25T23:43:43.004872+00:00", "data": {"market": "0x538be58810bd07707c1e849da9b4de12dc6617739c2e87043ea9b7fb2b6266c3", "price_changes": [{"asset_id": "41247652063966004401306857419416685235874842651432515489339067969075836389387", "price": "0.7", "size": "7108.37", "side": "BUY", "hash": "ddb65553387688a70d77826cd7f7bfc9cc96483f", "best_bid": "0.72", "best_ask": "0.75"}, {"asset_id": "58617143502730239165118144708053321823503557172455753166265292779077877259718", "price": "0.3", "size": "7108.37", "side": "SELL", "hash": "be28830514b7e1c5d124679347ec78de95b7345a", "best_bid": "0.25", "best_ask": "0.28"}], "timestamp": "1769384622908", "event_type": "price_change"}}
{"_local_timestamp": "2026-01-25T23:43:43.007408+00:00", "data": {"market": "0x538be58810bd07707c1e849da9b4de12dc6617739c2e87043ea9b7fb2b6266c3", "price_changes": [{"asset_id": "41247652063966004401306857419416685235874842651432515489339067969075836389387", "price": "0.71", "size": "1450.5", "side": "BUY", "hash": "5cd6313d9ee65f5ec0e82d85b9d24ae0a232b729", "best_bid": "0.72", "best_ask": "0.75"}, {"asset_id": "58617143502730239165118144708053321823503557172455753166265292779077877259718", "price": "0.29", "size": "1450.5", "side": "SELL", "hash": "d9170dfca4f0fedab4c8798b1bb958cd79fb8e2b", "best_bid": "0.25", "best_ask": "0.28"}], "timestamp": "1769384622912", "event_type": "price_change"}}
{"_local_timestamp": "2026-01-25T23:44:47.790282+00:00", "data": {"market": "0x538be58810bd07707c1e849da9b4de12dc6617739c2e87043ea9b7fb2b6266c3", "price_changes": [{"asset_id": "41247652063966004401306857419416685235874842651432515489339067969075836389387", "price": "0.71", "size": "1250.5", "side": "BUY", "hash": "7db449eec59194ef5fa2018472c337964f97256a", "best_bid": "0.72", "best_ask": "0.75"}, {"asset_id": "58617143502730239165118144708053321823503557172455753166265292779077877259718", "price": "0.29", "size": "1250.5", "side": "SELL", "hash": "8d7a04cf4db58ce6e921bb465350f4efc63765af", "best_bid": "0.25", "best_ask": "0.28"}], "timestamp": "1769384687491", "event_type": "price_change"}}
{"_local_timestamp": "2026-01-25T23:44:47.792226+00:00", "data": {"market": "0x538be58810bd07707c1e849da9b4de12dc6617739c2e87043ea9b7fb2b6266c3", "price_changes": [{"asset_id": "41247652063966004401306857419416685235874842651432515489339067969075836389387", "price": "0.7", "size": "7308.37", "side": "BUY", "hash": "b8f0b155968e066b683e05a6313942c39fbc4b7a", "best_bid": "0.72", "best_ask": "0.75"}, {"asset_id": "58617143502730239165118144708053321823503557172455753166265292779077877259718", "price": "0.3", "size": "7308.37", "side": "SELL", "hash": "2000de025b1a8a8ef03664f12e4de513f27b0870", "best_bid": "0.25", "best_ask": "0.28"}], "timestamp": "1769384687496", "event_type": "price_change"}}
{"_local_timestamp": "2026-01-25T23:44:49.675173+00:00", "data": {"market": "0x538be58810bd07707c1e849da9b4de12dc6617739c2e87043ea9b7fb2b6266c3", "price_changes": [{"asset_id": "41247652063966004401306857419416685235874842651432515489339067969075836389387", "price": "0.7", "size": "7108.37", "side": "BUY", "hash": "cbdcddb84007ba49c4f48061c07e082fe246a2dc", "best_bid": "0.72", "best_ask": "0.75"}, {"asset_id": "58617143502730239165118144708053321823503557172455753166265292779077877259718", "price": "0.3", "size": "7108.37", "side": "SELL", "hash": "630dcf49e8ac2d76d3998b10c3fb843eba2f4edf", "best_bid": "0.25", "best_ask": "0.28"}], "timestamp": "1769384689495", "event_type": "price_change"}}
{"_local_timestamp": "2026-01-25T23:44:49.675554+00:00", "data": {"market": "0x538be58810bd07707c1e849da9b4de12dc6617739c2e87043ea9b7fb2b6266c3", "price_changes": [{"asset_id": "41247652063966004401306857419416685235874842651432515489339067969075836389387", "price": "0.72", "size": "205", "side": "BUY", "hash": "96ec23d0e1500790b2c8e6b8b2be217ed4014ebf", "best_bid": "0.72", "best_ask": "0.75"}, {"asset_id": "58617143502730239165118144708053321823503557172455753166265292779077877259718", "price": "0.28", "size": "205", "side": "SELL", "hash": "2e62a1f95b8c45144ad866a419d5796f9080000c", "best_bid": "0.25", "best_ask": "0.28"}], "timestamp": "1769384689495", "event_type": "price_change"}}
{"_local_timestamp": "2026-01-25T23:46:06.268421+00:00", "data": {"market": "0x538be58810bd07707c1e849da9b4de12dc6617739c2e87043ea9b7fb2b6266c3", "price_changes": [{"asset_id": "41247652063966004401306857419416685235874842651432515489339067969075836389387", "price": "0.72", "size": "5", "side": "BUY", "hash": "3a1ef8e96b3054a784b0614cd2fb01d9dba57ea2", "best_bid": "0.72", "best_ask": "0.75"}, {"asset_id": "58617143502730239165118144708053321823503557172455753166265292779077877259718", "price": "0.28", "size": "5", "side": "SELL", "hash": "e8c1bb1f243993b067f04885c4fcd503d69cfa09", "best_bid": "0.25", "best_ask": "0.28"}], "timestamp": "1769384766170", "event_type": "price_change"}}
{"_local_timestamp": "2026-01-25T23:46:06.269142+00:00", "data": {"market": "0x538be58810bd07707c1e849da9b4de12dc6617739c2e87043ea9b7fb2b6266c3", "price_changes": [{"asset_id": "41247652063966004401306857419416685235874842651432515489339067969075836389387", "price": "0.7", "size": "7308.37", "side": "BUY", "hash": "a35c87dc931a32fe9a22b501dc5357780dca7ff3", "best_bid": "0.72", "best_ask": "0.75"}, {"asset_id": "58617143502730239165118144708053321823503557172455753166265292779077877259718", "price": "0.3", "size": "7308.37", "side": "SELL", "hash": "9b47348e8c08b02823c7e9ef3c23e246d4e7a2fa", "best_bid": "0.25", "best_ask": "0.28"}], "timestamp": "1769384766173", "event_type": "price_change"}}
{"_local_timestamp": "2026-01-25T23:46:08.245550+00:00", "data": {"market": "0x538be58810bd07707c1e849da9b4de12dc6617739c2e87043ea9b7fb2b6266c3", "price_changes": [{"asset_id": "41247652063966004401306857419416685235874842651432515489339067969075836389387", "price": "0.7", "size": "7108.37", "side": "BUY", "hash": "07d0232f5648569ac50a0b898f63bfe38cf894c2", "best_bid": "0.72", "best_ask": "0.75"}, {"asset_id": "58617143502730239165118144708053321823503557172455753166265292779077877259718", "price": "0.3", "size": "7108.37", "side": "SELL", "hash": "760e6653801a3bc31080898218382807fa615aa1", "best_bid": "0.25", "best_ask": "0.28"}], "timestamp": "1769384768171", "event_type": "price_change"}}
{"_local_timestamp": "2026-01-25T23:46:08.246194+00:00", "data": {"market": "0x538be58810bd07707c1e849da9b4de12dc6617739c2e87043ea9b7fb2b6266c3", "price_changes": [{"asset_id": "41247652063966004401306857419416685235874842651432515489339067969075836389387", "price": "0.71", "size": "1450.5", "side": "BUY", "hash": "4455eac1d70f07b1e5fe396fe1fe40fb092cb82b", "best_bid": "0.72", "best_ask": "0.75"}, {"asset_id": "58617143502730239165118144708053321823503557172455753166265292779077877259718", "price": "0.29", "size": "1450.5", "side": "SELL", "hash": "83360a0397ea6ae24b9497583345c2839a7547e2", "best_bid": "0.25", "best_ask": "0.28"}], "timestamp": "1769384768173", "event_type": "price_change"}}
{"_local_timestamp": "2026-01-25T23:47:30.199532+00:00", "data": {"market": "0x538be58810bd07707c1e849da9b4de12dc6617739c2e87043ea9b7fb2b6266c3", "price_changes": [{"asset_id": "41247652063966004401306857419416685235874842651432515489339067969075836389387", "price": "0.71", "size": "1250.5", "side": "BUY", "hash": "dea325dc2ad24c9cfcde2e18443f7fc5388418e8", "best_bid": "0.72", "best_ask": "0.75"}, {"asset_id": "58617143502730239165118144708053321823503557172455753166265292779077877259718", "price": "0.29", "size": "1250.5", "side": "SELL", "hash": "09b8277ea311a24564152802b13d5f0d25fee01f", "best_bid": "0.25", "best_ask": "0.28"}], "timestamp": "1769384850110", "event_type": "price_change"}}
{"_local_timestamp": "2026-01-25T23:47:30.200385+00:00", "data": {"market": "0x538be58810bd07707c1e849da9b4de12dc6617739c2e87043ea9b7fb2b6266c3", "price_changes": [{"asset_id": "41247652063966004401306857419416685235874842651432515489339067969075836389387", "price": "0.7", "size": "7308.37", "side": "BUY", "hash": "ef3178257a134ba942cead796f996bdc943813c3", "best_bid": "0.72", "best_ask": "0.75"}, {"asset_id": "58617143502730239165118144708053321823503557172455753166265292779077877259718", "price": "0.3", "size": "7308.37", "side": "SELL", "hash": "e797a69f37c4c2d162a75087afda354bc6bdc5fb", "best_bid": "0.25", "best_ask": "0.28"}], "timestamp": "1769384850111", "event_type": "price_change"}}
{"_local_timestamp": "2026-01-25T23:47:32.202318+00:00", "data": {"market": "0x538be58810bd07707c1e849da9b4de12dc6617739c2e87043ea9b7fb2b6266c3", "price_changes": [{"asset_id": "41247652063966004401306857419416685235874842651432515489339067969075836389387", "price": "0.7", "size": "7108.37", "side": "BUY", "hash": "07240b785cce36b236e94d60636ec0b42de4fd66", "best_bid": "0.72", "best_ask": "0.75"}, {"asset_id": "58617143502730239165118144708053321823503557172455753166265292779077877259718", "price": "0.3", "size": "7108.37", "side": "SELL", "hash": "9309069ce7ebb9e4518aa1d4db5126d5f03a0c97", "best_bid": "0.25", "best_ask": "0.28"}], "timestamp": "1769384852114", "event_type": "price_change"}}
{"_local_timestamp": "2026-01-25T23:47:32.203445+00:00", "data": {"market": "0x538be58810bd07707c1e849da9b4de12dc6617739c2e87043ea9b7fb2b6266c3", "price_changes": [{"asset_id": "41247652063966004401306857419416685235874842651432515489339067969075836389387", "price": "0.72", "size": "205", "side": "BUY", "hash": "97d274d5a1c971c04230886f8cf05042d18d2b1a", "best_bid": "0.72", "best_ask": "0.75"}, {"asset_id": "58617143502730239165118144708053321823503557172455753166265292779077877259718", "price": "0.28", "size": "205", "side": "SELL", "hash": "6ba45bf726bb9eb20b2d3adec3852c7ff2ab09e8", "best_bid": "0.25", "best_ask": "0.28"}], "timestamp": "1769384852116", "event_type": "price_change"}}
{"_local_timestamp": "2026-01-25T23:48:43.002473+00:00", "data": {"market": "0x538be58810bd07707c1e849da9b4de12dc6617739c2e87043ea9b7fb2b6266c3", "price_changes": [{"asset_id": "41247652063966004401306857419416685235874842651432515489339067969075836389387", "price": "0.7", "size": "7308.37", "side": "BUY", "hash": "84c13505a75a39ca7ba435fb72d3bf49cb0539ff", "best_bid": "0.72", "best_ask": "0.75"}, {"asset_id": "58617143502730239165118144708053321823503557172455753166265292779077877259718", "price": "0.3", "size": "7308.37", "side": "SELL", "hash": "1d4000c1e8e951f7c64218ad3e373bffce01771a", "best_bid": "0.25", "best_ask": "0.28"}], "timestamp": "1769384922934", "event_type": "price_change"}}
{"_local_timestamp": "2026-01-25T23:48:43.009072+00:00", "data": {"market": "0x538be58810bd07707c1e849da9b4de12dc6617739c2e87043ea9b7fb2b6266c3", "price_changes": [{"asset_id": "41247652063966004401306857419416685235874842651432515489339067969075836389387", "price": "0.72", "size": "5", "side": "BUY", "hash": "0ee209a6ed0763294b4a62e0ab78efe7e5ae8334", "best_bid": "0.72", "best_ask": "0.75"}, {"asset_id": "58617143502730239165118144708053321823503557172455753166265292779077877259718", "price": "0.28", "size": "5", "side": "SELL", "hash": "be45df5903d2eb7e104ecf17c3a02629d3f5ae60", "best_bid": "0.25", "best_ask": "0.28"}], "timestamp": "1769384922938", "event_type": "price_change"}}
{"_local_timestamp": "2026-01-25T23:48:44.991994+00:00", "data": {"market": "0x538be58810bd07707c1e849da9b4de12dc6617739c2e87043ea9b7fb2b6266c3", "price_changes": [{"asset_id": "41247652063966004401306857419416685235874842651432515489339067969075836389387", "price": "0.71", "size": "1450.5", "side": "BUY", "hash": "dd626dfee888f7c23fc6d603566bb8501252d0ed", "best_bid": "0.72", "best_ask": "0.75"}, {"asset_id": "58617143502730239165118144708053321823503557172455753166265292779077877259718", "price": "0.29", "size": "1450.5", "side": "SELL", "hash": "fda2599f01dba44eac2b6ff9f62c8080ffd5651b", "best_bid": "0.25", "best_ask": "0.28"}], "timestamp": "1769384924926", "event_type": "price_change"}}
{"_local_timestamp": "2026-01-25T23:48:45.004029+00:00", "data": {"market": "0x538be58810bd07707c1e849da9b4de12dc6617739c2e87043ea9b7fb2b6266c3", "price_changes": [{"asset_id": "41247652063966004401306857419416685235874842651432515489339067969075836389387", "price": "0.7", "size": "7108.37", "side": "BUY", "hash": "555de2309f428ab7f26ffa51a6c6898708c8a1bc", "best_bid": "0.72", "best_ask": "0.75"}, {"asset_id": "58617143502730239165118144708053321823503557172455753166265292779077877259718", "price": "0.3", "size": "7108.37", "side": "SELL", "hash": "92598e98dcb6eb6eb63dbfc15276be07f3e6eae2", "best_bid": "0.25", "best_ask": "0.28"}], "timestamp": "1769384924940", "event_type": "price_change"}}
{"_local_timestamp": "2026-01-25T23:48:49.331470+00:00", "data": {"market": "0x538be58810bd07707c1e849da9b4de12dc6617739c2e87043ea9b7fb2b6266c3", "price_changes": [{"asset_id": "41247652063966004401306857419416685235874842651432515489339067969075836389387", "price": "0.71", "size": "1250.5", "side": "BUY", "hash": "fe53b56d971730bb7041041257a79988d82bfec5", "best_bid": "0.72", "best_ask": "0.75"}, {"asset_id": "58617143502730239165118144708053321823503557172455753166265292779077877259718", "price": "0.29", "size": "1250.5", "side": "SELL", "hash": "c6008b73d536da2fdcf396843a1675048a0c9988", "best_bid": "0.25", "best_ask": "0.28"}], "timestamp": "1769384929267", "event_type": "price_change"}}
{"_local_timestamp": "2026-01-25T23:48:49.343090+00:00", "data": {"market": "0x538be58810bd07707c1e849da9b4de12dc6617739c2e87043ea9b7fb2b6266c3", "price_changes": [{"asset_id": "41247652063966004401306857419416685235874842651432515489339067969075836389387", "price": "0.7", "size": "7308.37", "side": "BUY", "hash": "12941c80c80676e2a0735faf2529ef5b9a1ea905", "best_bid": "0.72", "best_ask": "0.75"}, {"asset_id": "58617143502730239165118144708053321823503557172455753166265292779077877259718", "price": "0.3", "size": "7308.37", "side": "SELL", "hash": "3ae71ff4ae251aa99ce849734bf772265247f1e4", "best_bid": "0.25", "best_ask": "0.28"}], "timestamp": "1769384929273", "event_type": "price_change"}}
{"_local_timestamp": "2026-01-25T23:48:51.336865+00:00", "data": {"market": "0x538be58810bd07707c1e849da9b4de12dc6617739c2e87043ea9b7fb2b6266c3", "price_changes": [{"asset_id": "58617143502730239165118144708053321823503557172455753166265292779077877259718", "price": "0.14", "size": "400", "side": "BUY", "hash": "4a819f639814cddcfc21c5aa158c4093f06dde36", "best_bid": "0.25", "best_ask": "0.28"}, {"asset_id": "41247652063966004401306857419416685235874842651432515489339067969075836389387", "price": "0.86", "size": "400", "side": "SELL", "hash": "d90499e938eff0154003c3baf6d3e0cddac18004", "best_bid": "0.72", "best_ask": "0.75"}], "timestamp": "1769384931264", "event_type": "price_change"}}
{"_local_timestamp": "2026-01-25T23:48:51.337293+00:00", "data": {"market": "0x538be58810bd07707c1e849da9b4de12dc6617739c2e87043ea9b7fb2b6266c3", "price_changes": [{"asset_id": "58617143502730239165118144708053321823503557172455753166265292779077877259718", "price": "0.2", "size": "1000", "side": "BUY", "hash": "50a4addccc38d62ff34e0d31e37ca5b4f2b12460", "best_bid": "0.25", "best_ask": "0.28"}, {"asset_id": "41247652063966004401306857419416685235874842651432515489339067969075836389387", "price": "0.8", "size": "1000", "side": "SELL", "hash": "05703825004cf7b256672149137033e15f415964", "best_bid": "0.72", "best_ask": "0.75"}], "timestamp": "1769384931267", "event_type": "price_change"}}
{"_local_timestamp": "2026-01-25T23:48:51.338096+00:00", "data": {"market": "0x538be58810bd07707c1e849da9b4de12dc6617739c2e87043ea9b7fb2b6266c3", "price_changes": [{"asset_id": "58617143502730239165118144708053321823503557172455753166265292779077877259718", "price": "0.16", "size": "125", "side": "BUY", "hash": "50a4addccc38d62ff34e0d31e37ca5b4f2b12460", "best_bid": "0.25", "best_ask": "0.28"}, {"asset_id": "41247652063966004401306857419416685235874842651432515489339067969075836389387", "price": "0.84", "size": "125", "side": "SELL", "hash": "05703825004cf7b256672149137033e15f415964", "best_bid": "0.72", "best_ask": "0.75"}], "timestamp": "1769384931267", "event_type": "price_change"}}
{"_local_timestamp": "2026-01-25T23:48:51.338456+00:00", "data": {"market": "0x538be58810bd07707c1e849da9b4de12dc6617739c2e87043ea9b7fb2b6266c3", "price_changes": [{"asset_id": "58617143502730239165118144708053321823503557172455753166265292779077877259718", "price": "0.18", "size": "61.11", "side": "BUY", "hash": "50a4addccc38d62ff34e0d31e37ca5b4f2b12460", "best_bid": "0.25", "best_ask": "0.28"}, {"asset_id": "41247652063966004401306857419416685235874842651432515489339067969075836389387", "price": "0.82", "size": "61.11", "side": "SELL", "hash": "05703825004cf7b256672149137033e15f415964", "best_bid": "0.72", "best_ask": "0.75"}], "timestamp": "1769384931267", "event_type": "price_change"}}
{"_local_timestamp": "2026-01-25T23:49:55.717063+00:00", "data": {"market": "0x538be58810bd07707c1e849da9b4de12dc6617739c2e87043ea9b7fb2b6266c3", "price_changes": [{"asset_id": "41247652063966004401306857419416685235874842651432515489339067969075836389387", "price": "0.7", "size": "7108.37", "side": "BUY", "hash": "10e0e8130a951dedb630ec48e5d52e925a0ec59d", "best_bid": "0.72", "best_ask": "0.75"}, {"asset_id": "58617143502730239165118144708053321823503557172455753166265292779077877259718", "price": "0.3", "size": "7108.37", "side": "SELL", "hash": "fa5badd4a1722455bd54f2b4c09e4726ed8c34e6", "best_bid": "0.25", "best_ask": "0.28"}], "timestamp": "1769384995341", "event_type": "price_change"}}
{"_local_timestamp": "2026-01-25T23:49:55.719975+00:00", "data": {"market": "0x538be58810bd07707c1e849da9b4de12dc6617739c2e87043ea9b7fb2b6266c3", "price_changes": [{"asset_id": "41247652063966004401306857419416685235874842651432515489339067969075836389387", "price": "0.69", "size": "398.93", "side": "BUY", "hash": "048ecbb3ed00f90f462ec23b157e704ee23d87cd", "best_bid": "0.72", "best_ask": "0.75"}, {"asset_id": "58617143502730239165118144708053321823503557172455753166265292779077877259718", "price": "0.31", "size": "398.93", "side": "SELL", "hash": "2dc800755b90ec42c46137b7a3663f880c2beda4", "best_bid": "0.25", "best_ask": "0.28"}], "timestamp": "1769384995344", "event_type": "price_change"}}
{"_local_timestamp": "2026-01-25T23:49:57.417958+00:00", "data": {"market": "0x538be58810bd07707c1e849da9b4de12dc6617739c2e87043ea9b7fb2b6266c3", "price_changes": [{"asset_id": "41247652063966004401306857419416685235874842651432515489339067969075836389387", "price": "0.7", "size": "7308.37", "side": "BUY", "hash": "ec2c235069251f711e442837db2c8585c4bcf1ab", "best_bid": "0.72", "best_ask": "0.75"}, {"asset_id": "58617143502730239165118144708053321823503557172455753166265292779077877259718", "price": "0.3", "size": "7308.37", "side": "SELL", "hash": "7188136a49a295d068ba24685eb38ca124ca634b", "best_bid": "0.25", "best_ask": "0.28"}], "timestamp": "1769384997347", "event_type": "price_change"}}
{"_local_timestamp": "2026-01-25T23:49:57.421945+00:00", "data": {"market": "0x538be58810bd07707c1e849da9b4de12dc6617739c2e87043ea9b7fb2b6266c3", "price_changes": [{"asset_id": "41247652063966004401306857419416685235874842651432515489339067969075836389387", "price": "0.69", "size": "198.93", "side": "BUY", "hash": "80a1f90ee448053d4b131ca2670e89698e0acb36", "best_bid": "0.72", "best_ask": "0.75"}, {"asset_id": "58617143502730239165118144708053321823503557172455753166265292779077877259718", "price": "0.31", "size": "198.93", "side": "SELL", "hash": "358444254e3db5a823ee39fec5e3537313c855be", "best_bid": "0.25", "best_ask": "0.28"}], "timestamp": "1769384997347", "event_type": "price_change"}}
{"_local_timestamp": "2026-01-25T23:51:06.799426+00:00", "data": {"market": "0x538be58810bd07707c1e849da9b4de12dc6617739c2e87043ea9b7fb2b6266c3", "price_changes": [{"asset_id": "41247652063966004401306857419416685235874842651432515489339067969075836389387", "price": "0.69", "size": "398.93", "side": "BUY", "hash": "4cc559bdcf2bcd28cb8778bd2941eb3ea9a558ef", "best_bid": "0.72", "best_ask": "0.75"}, {"asset_id": "58617143502730239165118144708053321823503557172455753166265292779077877259718", "price": "0.31", "size": "398.93", "side": "SELL", "hash": "6064ee718802fb08bfd4498d81edc31a299ab5f8", "best_bid": "0.25", "best_ask": "0.28"}], "timestamp": "1769385066729", "event_type": "price_change"}}
{"_local_timestamp": "2026-01-25T23:51:06.800282+00:00", "data": {"market": "0x538be58810bd07707c1e849da9b4de12dc6617739c2e87043ea9b7fb2b6266c3", "price_changes": [{"asset_id": "41247652063966004401306857419416685235874842651432515489339067969075836389387", "price": "0.7", "size": "7108.37", "side": "BUY", "hash": "57f5eeaea55f26a59e2cfd94f316c1a24f2ba4c5", "best_bid": "0.72", "best_ask": "0.75"}, {"asset_id": "58617143502730239165118144708053321823503557172455753166265292779077877259718", "price": "0.3", "size": "7108.37", "side": "SELL", "hash": "cbc7aa282aa45d36e541db23000b3da163a60b87", "best_bid": "0.25", "best_ask": "0.28"}], "timestamp": "1769385066735", "event_type": "price_change"}}
{"_local_timestamp": "2026-01-25T23:51:08.794654+00:00", "data": {"market": "0x538be58810bd07707c1e849da9b4de12dc6617739c2e87043ea9b7fb2b6266c3", "price_changes": [{"asset_id": "41247652063966004401306857419416685235874842651432515489339067969075836389387", "price": "0.69", "size": "198.93", "side": "BUY", "hash": "03b1fca043ace7d151185817a2740725a0f6fb82", "best_bid": "0.72", "best_ask": "0.75"}, {"asset_id": "58617143502730239165118144708053321823503557172455753166265292779077877259718", "price": "0.31", "size": "198.93", "side": "SELL", "hash": "15409b037985d1e5a5f15ae81afbf5dd70676832", "best_bid": "0.25", "best_ask": "0.28"}], "timestamp": "1769385068730", "event_type": "price_change"}}
{"_local_timestamp": "2026-01-25T23:51:08.802950+00:00", "data": {"market": "0x538be58810bd07707c1e849da9b4de12dc6617739c2e87043ea9b7fb2b6266c3", "price_changes": [{"asset_id": "41247652063966004401306857419416685235874842651432515489339067969075836389387", "price": "0.7", "size": "7308.37", "side": "BUY", "hash": "cbd3d7487e4b7ba3cdcb9dd405c924a3959a8d67", "best_bid": "0.72", "best_ask": "0.75"}, {"asset_id": "58617143502730239165118144708053321823503557172455753166265292779077877259718", "price": "0.3", "size": "7308.37", "side": "SELL", "hash": "d813e0f37a449ef5965912661943c15408c62fa2", "best_bid": "0.25", "best_ask": "0.28"}], "timestamp": "1769385068738", "event_type": "price_change"}}
