{"_local_timestamp": "2026-01-25T23:40:32.290457+00:00", "data": [{"market": "0xef62cae2f23eb9084db338cafc8ee88806bee54e3a92051689f70d6907b7f3cf", "asset_id": "86421436930838227408032705986280984822442451727936616356929369488596324752129", "timestamp": "1769384224917", "hash": "24b113d9fbdf200cd60281364edf73f680aa86d3", "bids": [{"price": "0.001", "size": "2790.58"}, {"price": "0.002", "size": "256.55"}, {"price": "0.003", "size": "400"}, {"price": "0.004", "size": "11.32"}, {"price": "0.006", "size": "200"}, {"price": "0.01", "size": "2210"}, {"price": "0.011", "size": "5.73"}, {"price": "0.02", "size": "2000"}, {"price": "0.021", "size": "11.15"}, {"price": "0.05", "size": "30"}, {"price": "0.051", "size": "39"}, {"price": "0.06", "size": "1700"}, {"price": "0.061", "size": "6.42"}, {"price": "0.08", "size": "400"}, {"price": "0.14", "size": "700"}, {"price": "0.141", "size": "8.83"}, {"price": "0.231", "size": "8"}, {"price": "0.233", "size": "8112"}, {"price": "0.236", "size": "700"}, {"price": "0.237", "size": "1600"}, {"price": "0.523", "size": "61"}, {"price": "0.723", "size": "126"}, {"price": "0.823", "size": "102"}, {"price": "0.824", "size": "20"}, {"price": "0.923", "size": "253"}, {"price": "0.924", "size": "128"}, {"price": "0.947", "size": "40"}, {"price": "0.95", "size": "30"}, {"price": "0.961", "size": "31"}, {"price": "0.988", "size": "908.55"}, {"price": "0.991", "size": "103.61"}, {"price": "0.992", "size": "13.6"}], "asks": [{"price": "0.999", "size": "338"}, {"price": "0.998", "size": "250"}, {"price": "0.996", "size": "2107.79"}, {"price": "0.995", "size": "49.99"}], "event_type": "book", "last_trade_price": ""}, {"market": "0x1b7e6de8efe5f6a2c1ca2470e747370be89fe96270ccee85430bf18ac705a4e1", "asset_id": "86084595121347108808129382127322373721009228528241692453665189127555334452646", "timestamp": "1769384218876", "hash": "2bb60f7e2f5cde179a863d1fcddc2700d0948529", "bids": [{"price": "0.001", "size": "1759"}, {"price": "0.002", "size": "1110"}], "asks": [{"price": "0.999", "size": "4290.58"}, {"price": "0.998", "size": "256.55"}, {"price": "0.997", "size": "400"}, {"price": "0.996", "size": "11.32"}, {"price": "0.994", "size": "200"}, {"price": "0.99", "size": "2210"}, {"price": "0.989", "size": "5.73"}, {"price": "0.98", "size": "2000"}, {"price": "0.979", "size": "16.24"}, {"price": "0.95", "size": "30"}, {"price": "0.949", "size": "39"}, {"price": "0.94", "size": "1800"}, {"price": "0.92", "size": "100"}, {"price": "0.919", "size": "6.45"}, {"price": "0.89", "size": "900"}, {"price": "0.86", "size": "50"}, {"price": "0.8", "size": "400"}, {"price": "0.799", "size": "5.01"}, {"price": "0.73", "size": "200"}, {"price": "0.655", "size": "5"}, {"price": "0.654", "size": "6965"}, {"price": "0.653", "size": "64"}, {"price": "0.652", "size": "206"}, {"price": "0.477", "size": "50"}, {"price": "0.177", "size": "44"}, {"price": "0.077", "size": "145"}, {"price": "0.076", "size": "20"}, {"price": "0.052", "size": "30"}, {"price": "0.05", "size": "40"}, {"price": "0.049", "size": "20"}, {"price": "0.037", "size": "31"}, {"price": "0.005", "size": "1286.04"}, {"price": "0.004", "size": "45.69"}], "event_type": "book", "last_trade_price": ""}, {"market": "0xda86314ac2dd0f78ab1fe5b746840abeeff5be4e74c6d5bd5a0aada5c695030e", "asset_id": "83273939204150973203361658145419377967478532826191206101882322765481122431127", "timestamp": "1769384360487", "hash": "67b9545a9d47aad20449f8bd08aed66b3187e10f", "bids": [{"price": "0.001", "size": "10051"}, {"price": "0.002", "size": "294.09"}, {"price": "0.003", "size": "99.94"}, {"price": "0.008", "size": "1851.5"}], "asks": [{"price": "0.999", "size": "4290.59"}, {"price": "0.998", "size": "256.56"}, {"price": "0.997", "size": "400"}, {"price": "0.996", "size": "11.34"}, {"price": "0.994", "size": "200"}, {"price": "0.99", "size": "2387.3"}, {"price": "0.989", "size": "5.74"}, {"price": "0.98", "size": "2000"}, {"price": "0.979", "size": "11.42"}, {"price": "0.95", "size": "30"}, {"price": "0.949", "size": "39"}, {"price": "0.939", "size": "1700"}, {"price": "0.938", "size": "6.79"}, {"price": "0.92", "size": "400"}, {"price": "0.9", "size": "96.38"}, {"price": "0.853", "size": "700"}, {"price": "0.852", "size": "8.18"}, {"price": "0.777", "size": "86"}, {"price": "0.754", "size": "8"}, {"price": "0.752", "size": "6561"}, {"price": "0.749", "size": "500"}, {"price": "0.748", "size": "250"}, {"price": "0.5", "size": "59.09"}, {"price": "0.477", "size": "167"}, {"price": "0.277", "size": "83"}, {"price": "0.177", "size": "101"}, {"price": "0.1", "size": "64.25"}, {"price": "0.099", "size": "20"}, {"price": "0.077", "size": "254"}, {"price": "0.076", "size": "20"}, {"price": "0.075", "size": "152"}, {"price": "0.061", "size": "20"}, {"price": "0.05", "size": "63.29"}, {"price": "0.049", "size": "20"}, {"price": "0.048", "size": "30"}, {"price": "0.042", "size": "31"}, {"price": "0.012", "size": "474.29"}, {"price": "0.011", "size": "25"}], "event_type": "book", "last_trade_price": ""}, {"market": "0x7d99e856ca49dcf748ff0072af624a65bafcb44a34b914b5a1466211674ae729", "asset_id": "17182810599901842221755643003911781322979812178264318853202692827838675256569", "timestamp": "1769384390057", "hash": "033bf4930cae04194248c18347a3af7182383d4c", "bids": [{"price": "0.001", "size": "2791.59"}, {"price": "0.002", "size": "256.56"}, {"price": "0.003", "size": "166"}, {"price": "0.004", "size": "11.32"}, {"price": "0.006", "size": "83"}, {"price": "0.01", "size": "2210"}, {"price": "0.011", "size": "5.73"}, {"price": "0.02", "size": "2000"}, {"price": "0.021", "size": "5.33"}, {"price": "0.022", "size": "9.82"}, {"price": "0.05", "size": "30"}, {"price": "0.051", "size": "39"}, {"price": "0.06", "size": "1800"}, {"price": "0.061", "size": "6.72"}, {"price": "0.08", "size": "400"}, {"price": "0.15", "size": "700"}, {"price": "0.151", "size": "7.51"}, {"price": "0.275", "size": "6881"}, {"price": "0.276", "size": "250"}, {"price": "0.627", "size": "5"}, {"price": "0.667", "size": "67"}, {"price": "0.671", "size": "20"}, {"price": "0.673", "size": "30"}, {"price": "0.674", "size": "473"}, {"price": "0.675", "size": "20"}, {"price": "0.975", "size": "931.8"}, {"price": "0.976", "size": "199.99"}, {"price": "0.98", "size": "38.2"}, {"price": "0.981", "size": "159.04"}], "asks": [{"price": "0.999", "size": "2993"}, {"price": "0.998", "size": "1133.76"}, {"price": "0.997", "size": "372.39"}, {"price": "0.996", "size": "116.7"}, {"price": "0.995", "size": "113.29"}, {"price": "0.994", "size": "111.03"}, {"price": "0.993", "size": "100"}, {"price": "0.992", "size": "156.34"}, {"price": "0.991", "size": "234"}, {"price": "0.99", "size": "5267"}], "event_type": "book", "last_trade_price": ""}, {"market": "0x1b7e6de8efe5f6a2c1ca2470e747370be89fe96270ccee85430bf18ac705a4e1", "asset_id": "94395860414009734926327544945762460944151569233112202400231598436537334220949", "timestamp": "1769384218876", "hash": "ab54c842c502c1b95347f5f00f2517bbfff16325", "bids": [{"price": "0.001", "size": "4290.58"}, {"price": "0.002", "size": "256.55"}, {"price": "0.003", "size": "400"}, {"price": "0.004", "size": "11.32"}, {"price": "0.006", "size": "200"}, {"price": "0.01", "size": "2210"}, {"price": "0.011", "size": "5.73"}, {"price": "0.02", "size": "2000"}, {"price": "0.021", "size": "16.24"}, {"price": "0.05", "size": "30"}, {"price": "0.051", "size": "39"}, {"price": "0.06", "size": "1800"}, {"price": "0.08", "size": "100"}, {"price": "0.081", "size": "6.45"}, {"price": "0.11", "size": "900"}, {"price": "0.14", "size": "50"}, {"price": "0.2", "size": "400"}, {"price": "0.201", "size": "5.01"}, {"price": "0.27", "size": "200"}, {"price": "0.345", "size": "5"}, {"price": "0.346", "size": "6965"}, {"price": "0.347", "size": "64"}, {"price": "0.348", "size": "206"}, {"price": "0.523", "size": "50"}, {"price": "0.823", "size": "44"}, {"price": "0.923", "size": "145"}, {"price": "0.924", "size": "20"}, {"price": "0.948", "size": "30"}, {"price": "0.95", "size": "40"}, {"price": "0.951", "size": "20"}, {"price": "0.963", "size": "31"}, {"price": "0.995", "size": "1286.04"}, {"price": "0.996", "size": "45.69"}], "asks": [{"price": "0.999", "size": "1759"}, {"price": "0.998", "size": "1110"}], "event_type": "book", "last_trade_price": ""}, {"market": "0xda86314ac2dd0f78ab1fe5b746840abeeff5be4e74c6d5bd5a0aada5c695030e", "asset_id": "66466375160121808081218865320764245347163437070476088335272741711627298513873", "timestamp": "1769384360487", "hash": "d2490827cd95f33425bb063495145b565d1ecac8", "bids": [{"price": "0.001", "size": "4290.59"}, {"price": "0.002", "size": "256.56"}, {"price": "0.003", "size": "400"}, {"price": "0.004", "size": "11.34"}, {"price": "0.006", "size": "200"}, {"price": "0.01", "size": "2387.3"}, {"price": "0.011", "size": "5.74"}, {"price": "0.02", "size": "2000"}, {"price": "0.021", "size": "11.42"}, {"price": "0.05", "size": "30"}, {"price": "0.051", "size": "39"}, {"price": "0.061", "size": "1700"}, {"price": "0.062", "size": "6.79"}, {"price": "0.08", "size": "400"}, {"price": "0.1", "size": "96.38"}, {"price": "0.147", "size": "700"}, {"price": "0.148", "size": "8.18"}, {"price": "0.223", "size": "86"}, {"price": "0.246", "size": "8"}, {"price": "0.248", "size": "6561"}, {"price": "0.251", "size": "500"}, {"price": "0.252", "size": "250"}, {"price": "0.5", "size": "59.09"}, {"price": "0.523", "size": "167"}, {"price": "0.723", "size": "83"}, {"price": "0.823", "size": "101"}, {"price": "0.9", "size": "64.25"}, {"price": "0.901", "size": "20"}, {"price": "0.923", "size": "254"}, {"price": "0.924", "size": "20"}, {"price": "0.925", "size": "152"}, {"price": "0.939", "size": "20"}, {"price": "0.95", "size": "63.29"}, {"price": "0.951", "size": "20"}, {"price": "0.952", "size": "30"}, {"price": "0.958", "size": "31"}, {"price": "0.988", "size": "474.29"}, {"price": "0.989", "size": "25"}], "asks": [{"price": "0.999", "size": "10051"}, {"price": "0.998", "size": "294.09"}, {"price": "0.997", "size": "99.94"}, {"price": "0.992", "size": "1851.5"}], "event_type": "book", "last_trade_price": ""}, {"market": "0xb7ba5d2b34c3f78d2b483daa97bc301f7296a5d8658ba2851f4c912a161e5158", "asset_id": "94207036547569786168949387588066196313734350858370522979598866565386642178169", "timestamp": "1769384379978", "hash": "735bb67ad3d83418a118675011617eff5ce842a8", "bids": [{"price": "0.001", "size": "1230"}, {"price": "0.002", "size": "1023.19"}, {"price": "0.003", "size": "120.17"}, {"price": "0.004", "size": "75.93"}, {"price": "0.01", "size": "110"}, {"price": "0.011", "size": "12.86"}, {"price": "0.013", "size": "38"}, {"price": "0.017", "size": "2654"}, {"price": "0.018", "size": "694"}, {"price": "0.019", "size": "206.74"}, {"price": "0.02", "size": "200"}, {"price": "0.021", "size": "108"}, {"price": "0.022", "size": "7.68"}, {"price": "0.025", "size": "202"}, {"price": "0.026", "size": "9.84"}, {"price": "0.027", "size": "100"}, {"price": "0.03", "size": "111"}, {"price": "0.031", "size": "5.39"}, {"price": "0.033", "size": "100"}, {"price": "0.034", "size": "30"}, {"price": "0.035", "size": "12.83"}, {"price": "0.045", "size": "22.2"}, {"price": "0.046", "size": "10"}], "asks": [{"price": "0.999", "size": "2746"}, {"price": "0.998", "size": "250"}, {"price": "0.997", "size": "171.33"}, {"price": "0.994", "size": "83"}, {"price": "0.99", "size": "2310"}, {"price": "0.989", "size": "6.6"}, {"price": "0.98", "size": "1000"}, {"price": "0.974", "size": "7178"}, {"price": "0.95", "size": "30"}, {"price": "0.949", "size": "39"}, {"price": "0.948", "size": "5.98"}, {"price": "0.937", "size": "1400"}, {"price": "0.9", "size": "100"}, {"price": "0.899", "size": "700"}, {"price": "0.858", "size": "400"}, {"price": "0.776", "size": "67"}, {"price": "0.764", "size": "3218"}, {"price": "0.76", "size": "300"}, {"price": "0.759", "size": "1742"}, {"price": "0.641", "size": "5"}, {"price": "0.5", "size": "10"}, {"price": "0.067", "size": "100"}, {"price": "0.063", "size": "119.02"}, {"price": "0.051", "size": "111"}, {"price": "0.049", "size": "227"}, {"price": "0.048", "size": "79.42"}], "event_type": "book", "last_trade_price": ""}, {"market": "0x7d99e856ca49dcf748ff0072af624a65bafcb44a34b914b5a1466211674ae729", "asset_id": "27250410806992141952257033810710803403327848453310007128861669762666286354528", "timestamp": "1769384390057", "hash": "3d59e65ccb78affa7689bcd134761173dd03de3f", "bids": [{"price": "0.001", "size": "2993"}, {"price": "0.002", "size": "1133.76"}, {"price": "0.003", "size": "372.39"}, {"price": "0.004", "size": "116.7"}, {"price": "0.005", "size": "113.29"}, {"price": "0.006", "size": "111.03"}, {"price": "0.007", "size": "100"}, {"price": "0.008", "size": "156.34"}, {"price": "0.009", "size": "234"}, {"price": "0.01", "size": "5267"}], "asks": [{"price": "0.999", "size": "2791.59"}, {"price": "0.998", "size": "256.56"}, {"price": "0.997", "size": "166"}, {"price": "0.996", "size": "11.32"}, {"price": "0.994", "size": "83"}, {"price": "0.99", "size": "2210"}, {"price": "0.989", "size": "5.73"}, {"price": "0.98", "size": "2000"}, {"price": "0.979", "size": "5.33"}, {"price": "0.978", "size": "9.82"}, {"price": "0.95", "size": "30"}, {"price": "0.949", "size": "39"}, {"price": "0.94", "size": "1800"}, {"price": "0.939", "size": "6.72"}, {"price": "0.92", "size": "400"}, {"price": "0.85", "size": "700"}, {"price": "0.849", "size": "7.51"}, {"price": "0.725", "size": "6881"}, {"price": "0.724", "size": "250"}, {"price": "0.373", "size": "5"}, {"price": "0.333", "size": "67"}, {"price": "0.329", "size": "20"}, {"price": "0.327", "size": "30"}, {"price": "0.326", "size": "473"}, {"price": "0.325", "size": "20"}, {"price": "0.025", "size": "931.8"}, {"price": "0.024", "size": "199.99"}, {"price": "0.02", "size": "38.2"}, {"price": "0.019", "size": "159.04"}], "event_type": "book", "last_trade_price": ""}, {"market": "0xb7ba5d2b34c3f78d2b483daa97bc301f7296a5d8658ba2851f4c912a161e5158", "asset_id": "32582994008069750117370770211161750379270178143252809024325448815129555714046", "timestamp": "1769384379978", "hash": "f40ec7d5defa78fecf0ccd3b2bf78df85d6f9415", "bids": [{"price": "0.001", "size": "2746"}, {"price": "0.002", "size": "250"}, {"price": "0.003", "size": "171.33"}, {"price": "0.006", "size": "83"}, {"price": "0.01", "size": "2310"}, {"price": "0.011", "size": "6.6"}, {"price": "0.02", "size": "1000"}, {"price": "0.026", "size": "7178"}, {"price": "0.05", "size": "30"}, {"price": "0.051", "size": "39"}, {"price": "0.052", "size": "5.98"}, {"price": "0.063", "size": "1400"}, {"price": "0.1", "size": "100"}, {"price": "0.101", "size": "700"}, {"price": "0.142", "size": "400"}, {"price": "0.224", "size": "67"}, {"price": "0.236", "size": "3218"}, {"price": "0.24", "size": "300"}, {"price": "0.241", "size": "1742"}, {"price": "0.359", "size": "5"}, {"price": "0.5", "size": "10"}, {"price": "0.933", "size": "100"}, {"price": "0.937", "size": "119.02"}, {"price": "0.949", "size": "111"}, {"price": "0.951", "size": "227"}, {"price": "0.952", "size": "79.42"}], "asks": [{"price": "0.999", "size": "1230"}, {"price": "0.998", "size": "1023.19"}, {"price": "0.997", "size": "120.17"}, {"price": "0.996", "size": "75.93"}, {"price": "0.99", "size": "110"}, {"price": "0.989", "size": "12.86"}, {"price": "0.987", "size": "38"}, {"price": "0.983", "size": "2654"}, {"price": "0.982", "size": "694"}, {"price": "0.981", "size": "206.74"}, {"price": "0.98", "size": "200"}, {"price": "0.979", "size": "108"}, {"price": "0.978", "size": "7.68"}, {"price": "0.975", "size": "202"}, {"price": "0.974", "size": "9.84"}, {"price": "0.973", "size": "100"}, {"price": "0.97", "size": "111"}, {"price": "0.969", "size": "5.39"}, {"price": "0.967", "size": "100"}, {"price": "0.966", "size": "30"}, {"price": "0.965", "size": "12.83"}, {"price": "0.955", "size": "22.2"}, {"price": "0.954", "size": "10"}], "event_type": "book", "last_trade_price": ""}, {"market": "0xef62cae2f23eb9084db338cafc8ee88806bee54e3a92051689f70d6907b7f3cf", "asset_id": "48832045779017406406240960364495829307085252456810565554978796786740596106550", "timestamp": "1769384224917", "hash": "670597db9f3a9e28674cfcb1d95dcb87d6652f7f", "bids": [{"price": "0.001", "size": "338"}, {"price": "0.002", "size": "250"}, {"price": "0.004", "size": "2107.79"}, {"price": "0.005", "size": "49.99"}], "asks": [{"price": "0.999", "size": "2790.58"}, {"price": "0.998", "size": "256.55"}, {"price": "0.997", "size": "400"}, {"price": "0.996", "size": "11.32"}, {"price": "0.994", "size": "200"}, {"price": "0.99", "size": "2210"}, {"price": "0.989", "size": "5.73"}, {"price": "0.98", "size": "2000"}, {"price": "0.979", "size": "11.15"}, {"price": "0.95", "size": "30"}, {"price": "0.949", "size": "39"}, {"price": "0.94", "size": "1700"}, {"price": "0.939", "size": "6.42"}, {"price": "0.92", "size": "400"}, {"price": "0.86", "size": "700"}, {"price": "0.859", "size": "8.83"}, {"price": "0.769", "size": "8"}, {"price": "0.767", "size": "8112"}, {"price": "0.764", "size": "700"}, {"price": "0.763", "size": "1600"}, {"price": "0.477", "size": "61"}, {"price": "0.277", "size": "126"}, {"price": "0.177", "size": "102"}, {"price": "0.176", "size": "20"}, {"price": "0.077", "size": "253"}, {"price": "0.076", "size": "128"}, {"price": "0.053", "size": "40"}, {"price": "0.05", "size": "30"}, {"price": "0.039", "size": "31"}, {"price": "0.012", "size": "908.55"}, {"price": "0.009", "size": "103.61"}, {"price": "0.008", "size": "13.6"}], "event_type": "book", "last_trade_price": ""}]}
{"_local_timestamp": "2026-01-25T23:41:19.296268+00:00", "data": {"market": "0xda86314ac2dd0f78ab1fe5b746840abeeff5be4e74c6d5bd5a0aada5c695030e", "price_changes": [{"asset_id": "83273939204150973203361658145419377967478532826191206101882322765481122431127", "price": "0.003", "size": "34.94", "side": "BUY", "hash": "242bc495b116a83aa3f64defa8848f7c5ca106c0", "best_bid": "0.008", "best_ask": "0.011"}, {"asset_id": "66466375160121808081218865320764245347163437070476088335272741711627298513873", "price": "0.997", "size": "34.94", "side": "SELL", "hash": "530168f0f96e805d68d530c825e2d69ff5aaa1c2", "best_bid": "0.989", "best_ask": "0.992"}], "timestamp": "1769384479180", "event_type": "price_change"}}
{"_local_timestamp": "2026-01-25T23:41:19.300732+00:00", "data": {"market": "0x1b7e6de8efe5f6a2c1ca2470e747370be89fe96270ccee85430bf18ac705a4e1", "price_changes": [{"asset_id": "94395860414009734926327544945762460944151569233112202400231598436537334220949", "price": "0.951", "size": "0", "side": "BUY", "hash": "3ea35c56503acdcc608f8ff4b9f40d9a2fdcdd0a", "best_bid": "0.996", "best_ask": "0.998"}, {"asset_id": "86084595121347108808129382127322373721009228528241692453665189127555334452646", "price": "0.049", "size": "0", "side": "SELL", "hash": "b309456d544fb5c8e7cad2f273ce2a9b25c9666f", "best_bid": "0.002", "best_ask": "0.004"}], "timestamp": "1769384479220", "event_type": "price_change"}}
{"_local_timestamp": "2026-01-25T23:41:20.195919+00:00", "data": {"market": "0xda86314ac2dd0f78ab1fe5b746840abeeff5be4e74c6d5bd5a0aada5c695030e", "price_changes": [{"asset_id": "83273939204150973203361658145419377967478532826191206101882322765481122431127", "price": "0.003", "size": "99.94", "side": "BUY", "hash": "e1140f1bf350d0e0062dc19a55989f5bbe914856", "best_bid": "0.008", "best_ask": "0.011"}, {"asset_id": "66466375160121808081218865320764245347163437070476088335272741711627298513873", "price": "0.997", "size": "99.94", "side": "SELL", "hash": "4b917ac065b1f80ac84f9f45e7a87db2d879db76", "best_bid": "0.989", "best_ask": "0.992"}], "timestamp": "1769384480117", "event_type": "price_change"}}
{"_local_timestamp": "2026-01-25T23:41:33.338639+00:00", "data": {"market": "0xb7ba5d2b34c3f78d2b483daa97bc301f7296a5d8658ba2851f4c912a161e5158", "price_changes": [{"asset_id": "94207036547569786168949387588066196313734350858370522979598866565386642178169", "price": "0.013", "size": "20", "side": "BUY", "hash": "45bf853a7644895d98d8fc7e47f03d2b3b0addf7", "best_bid": "0.046", "best_ask": "0.048"}, {"asset_id": "32582994008069750117370770211161750379270178143252809024325448815129555714046", "price": "0.987", "size": "20", "side": "SELL", "hash": "31fb47c6a9af5e6b220d1f14e41f35010cc76bb2", "best_bid": "0.952", "best_ask": "0.954"}], "timestamp": "1769384493257", "event_type": "price_change"}}
{"_local_timestamp": "2026-01-25T23:41:33.501172+00:00", "data": {"market": "0x7d99e856ca49dcf748ff0072af624a65bafcb44a34b914b5a1466211674ae729", "price_changes": [{"asset_id": "17182810599901842221755643003911781322979812178264318853202692827838675256569", "price": "0.671", "size": "0", "side": "BUY", "hash": "89365797369a1d0ec0c7b799af7745da1ff4bb6f", "best_bid": "0.981", "best_ask": "0.99"}, {"asset_id": "27250410806992141952257033810710803403327848453310007128861669762666286354528", "price": "0.329", "size": "0", "side": "SELL", "hash": "30b4c348f9e1e3056e20d118c5ed6bba4fa0e602", "best_bid": "0.01", "best_ask": "0.019"}], "timestamp": "1769384493424", "event_type": "price_change"}}
{"_local_timestamp": "2026-01-25T23:41:33.682360+00:00", "data": {"market": "0x7d99e856ca49dcf748ff0072af624a65bafcb44a34b914b5a1466211674ae729", "price_changes": [{"asset_id": "17182810599901842221755643003911781322979812178264318853202692827838675256569", "price": "0.676", "size": "20", "side": "BUY", "hash": "df6a1d583431ba233120d59f662adef95826894c", "best_bid": "0.981", "best_ask": "0.99"}, {"asset_id": "27250410806992141952257033810710803403327848453310007128861669762666286354528", "price": "0.324", "size": "20", "side": "SELL", "hash": "cbf5b7092619843904b8dceb033bf7aada94d78d", "best_bid": "0.01", "best_ask": "0.019"}], "timestamp": "1769384493614", "event_type": "price_change"}}
{"_local_timestamp": "2026-01-25T23:41:33.777306+00:00", "data": {"market": "0x7d99e856ca49dcf748ff0072af624a65bafcb44a34b914b5a1466211674ae729", "price_changes": [{"asset_id": "17182810599901842221755643003911781322979812178264318853202692827838675256569", "price": "0.674", "size": "453", "side": "BUY", "hash": "6733f3f170c742dec15acb25b752f89cd3f74d0a", "best_bid": "0.981", "best_ask": "0.99"}, {"asset_id": "27250410806992141952257033810710803403327848453310007128861669762666286354528", "price": "0.326", "size": "453", "side": "SELL", "hash": "8e6bc33a71e3fd1e04af73cb1203a09b51217c0f", "best_bid": "0.01", "best_ask": "0.019"}], "timestamp": "1769384493683", "event_type": "price_change"}}
{"_local_timestamp": "2026-01-25T23:41:33.970809+00:00", "data": {"market": "0xb7ba5d2b34c3f78d2b483daa97bc301f7296a5d8658ba2851f4c912a161e5158", "price_changes": [{"asset_id": "94207036547569786168949387588066196313734350858370522979598866565386642178169", "price": "0.014", "size": "16.71", "side": "BUY", "hash": "fe619318dd2df849080db9ec627d2d7ad664f8d4", "best_bid": "0.046", "best_ask": "0.048"}, {"asset_id": "32582994008069750117370770211161750379270178143252809024325448815129555714046", "price": "0.986", "size": "16.71", "side": "SELL", "hash": "974811d6a287e4f0bc9402b322ee68f73712c8e8", "best_bid": "0.952", "best_ask": "0.954"}], "timestamp": "1769384493906", "event_type": "price_change"}}
{"_local_timestamp": "2026-01-25T23:41:34.771158+00:00", "data": {"market": "0x7d99e856ca49dcf748ff0072af624a65bafcb44a34b914b5a1466211674ae729", "price_changes": [{"asset_id": "17182810599901842221755643003911781322979812178264318853202692827838675256569", "price": "0.675", "size": "0", "side": "BUY", "hash": "706241c32610c02649c41b761f4fddeb66bc61d6", "best_bid": "0.981", "best_ask": "0.99"}, {"asset_id": "27250410806992141952257033810710803403327848453310007128861669762666286354528", "price": "0.325", "size": "0", "side": "SELL", "hash": "56b2a92072d7dcee0e876d31e759de7fd7a017ac", "best_bid": "0.01", "best_ask": "0.019"}], "timestamp": "1769384494700", "event_type": "price_change"}}
{"_local_timestamp": "2026-01-25T23:41:34.787340+00:00", "data": {"market": "0x7d99e856ca49dcf748ff0072af624a65bafcb44a34b914b5a1466211674ae729", "price_changes": [{"asset_id": "17182810599901842221755643003911781322979812178264318853202692827838675256569", "price": "0.677", "size": "20", "side": "BUY", "hash": "ee32a8cf62d30b72713916674ea20a87fce0e950", "best_bid": "0.981", "best_ask": "0.99"}, {"asset_id": "27250410806992141952257033810710803403327848453310007128861669762666286354528", "price": "0.323", "size": "20", "side": "SELL", "hash": "1f35a87522d69193fef9df0f97f9b38b9280894c", "best_bid": "0.01", "best_ask": "0.019"}], "timestamp": "1769384494723", "event_type": "price_change"}}
{"_local_timestamp": "2026-01-25T23:41:39.067104+00:00", "data": {"market": "0xb7ba5d2b34c3f78d2b483daa97bc301f7296a5d8658ba2851f4c912a161e5158", "price_changes": [{"asset_id": "32582994008069750117370770211161750379270178143252809024325448815129555714046", "price": "0.359", "size": "0", "side": "BUY", "hash": "b0c0d5a9a5041ffce03a73d21bf6637d6fc5cd06", "best_bid": "0.952", "best_ask": "0.954"}, {"asset_id": "94207036547569786168949387588066196313734350858370522979598866565386642178169", "price": "0.641", "size": "0", "side": "SELL", "hash": "fd22ddf2233cca547eece4090b673e372d744be8", "best_bid": "0.046", "best_ask": "0.048"}], "timestamp": "1769384498980", "event_type": "price_change"}}
{"_local_timestamp": "2026-01-25T23:41:39.562193+00:00", "data": {"market": "0xb7ba5d2b34c3f78d2b483daa97bc301f7296a5d8658ba2851f4c912a161e5158", "price_changes": [{"asset_id": "32582994008069750117370770211161750379270178143252809024325448815129555714046", "price": "0.359", "size": "5", "side": "BUY", "hash": "8bb39d210416424db0f318be22298701dfd0d75b", "best_bid": "0.952", "best_ask": "0.954"}, {"asset_id": "94207036547569786168949387588066196313734350858370522979598866565386642178169", "price": "0.641", "size": "5", "side": "SELL", "hash": "b81086be587eb50407cf55f128b4ccd2de6333b8", "best_bid": "0.046", "best_ask": "0.048"}], "timestamp": "1769384499482", "event_type": "price_change"}}
{"_local_timestamp": "2026-01-25T23:41:45.349279+00:00", "data": {"market": "0xb7ba5d2b34c3f78d2b483daa97bc301f7296a5d8658ba2851f4c912a161e5158", "price_changes": [{"asset_id": "32582994008069750117370770211161750379270178143252809024325448815129555714046", "price": "0.026", "size": "1400", "side": "BUY", "hash": "168e04a7062b878dfb0ef097d28718f83945afe9", "best_bid": "0.952", "best_ask": "0.954"}, {"asset_id": "94207036547569786168949387588066196313734350858370522979598866565386642178169", "price": "0.974", "size": "1400", "side": "SELL", "hash": "1bb8f162e06cf735b2d78b64014759af266560b4", "best_bid": "0.046", "best_ask": "0.048"}], "timestamp": "1769384505280", "event_type": "price_change"}}
{"_local_timestamp": "2026-01-25T23:41:45.517873+00:00", "data": {"market": "0xb7ba5d2b34c3f78d2b483daa97bc301f7296a5d8658ba2851f4c912a161e5158", "price_changes": [{"asset_id": "32582994008069750117370770211161750379270178143252809024325448815129555714046", "price": "0.027", "size": "5599", "side": "BUY", "hash": "ef0a5ffef035ade4b250c1b63f9d83bb28fe5196", "best_bid": "0.952", "best_ask": "0.954"}, {"asset_id": "94207036547569786168949387588066196313734350858370522979598866565386642178169", "price": "0.973", "size": "5599", "side": "SELL", "hash": "c466f880a1bb5a776f132627b627d266c3ccf07a", "best_bid": "0.046", "best_ask": "0.048"}], "timestamp": "1769384505445", "event_type": "price_change"}}
{"_local_timestamp": "2026-01-25T23:41:45.706420+00:00", "data": {"market": "0x7d99e856ca49dcf748ff0072af624a65bafcb44a34b914b5a1466211674ae729", "price_changes": [{"asset_id": "17182810599901842221755643003911781322979812178264318853202692827838675256569", "price": "0.275", "size": "0", "side": "BUY", "hash": "22479f352f32f5b21483853097a4c01489c9bae2", "best_bid": "0.981", "best_ask": "0.99"}, {"asset_id": "27250410806992141952257033810710803403327848453310007128861669762666286354528", "price": "0.725", "size": "0", "side": "SELL", "hash": "69b1da8c1173ffd69928a20a9b10a025377bc511", "best_bid": "0.01", "best_ask": "0.019"}], "timestamp": "1769384505643", "event_type": "price_change"}}
{"_local_timestamp": "2026-01-25T23:41:45.866904+00:00", "data": {"market": "0x7d99e856ca49dcf748ff0072af624a65bafcb44a34b914b5a1466211674ae729", "price_changes": [{"asset_id": "17182810599901842221755643003911781322979812178264318853202692827838675256569", "price": "0.277", "size": "6864", "side": "BUY", "hash": "9fce1bde2ae72a1f7ad22c3f44081df5c5977195", "best_bid": "0.981", "best_ask": "0.99"}, {"asset_id": "27250410806992141952257033810710803403327848453310007128861669762666286354528", "price": "0.723", "size": "6864", "side": "SELL", "hash": "89de774d492eeb58d1e62c8c0b258c7042ca5160", "best_bid": "0.01", "best_ask": "0.019"}], "timestamp": "1769384505799", "event_type": "price_change"}}
{"_local_timestamp": "2026-01-25T23:41:46.067204+00:00", "data": {"market": "0xda86314ac2dd0f78ab1fe5b746840abeeff5be4e74c6d5bd5a0aada5c695030e", "price_changes": [{"asset_id": "66466375160121808081218865320764245347163437070476088335272741711627298513873", "price": "0.248", "size": "0", "side": "BUY", "hash": "eaa838a5ef6014e15792bd7eeb5237dce4e649d1", "best_bid": "0.989", "best_ask": "0.992"}, {"asset_id": "83273939204150973203361658145419377967478532826191206101882322765481122431127", "price": "0.752", "size": "0", "side": "SELL", "hash": "d18b0834b5202d3a5bf1bb7fd122943defd9a93b", "best_bid": "0.008", "best_ask": "0.011"}], "timestamp": "1769384505995", "event_type": "price_change"}}
{"_local_timestamp": "2026-01-25T23:41:46.270521+00:00", "data": {"market": "0xda86314ac2dd0f78ab1fe5b746840abeeff5be4e74c6d5bd5a0aada5c695030e", "price_changes": [{"asset_id": "66466375160121808081218865320764245347163437070476088335272741711627298513873", "price": "0.253", "size": "6448", "side": "BUY", "hash": "6504639ae907d08716b8495e3bb61760b575f06b", "best_bid": "0.989", "best_ask": "0.992"}, {"asset_id": "83273939204150973203361658145419377967478532826191206101882322765481122431127", "price": "0.747", "size": "6448", "side": "SELL", "hash": "02981707efbfd4554e0c8251b772be31835eb978", "best_bid": "0.008", "best_ask": "0.011"}], "timestamp": "1769384506199", "event_type": "price_change"}}
{"_local_timestamp": "2026-01-25T23:41:46.302708+00:00", "data": {"market": "0xda86314ac2dd0f78ab1fe5b746840abeeff5be4e74c6d5bd5a0aada5c695030e", "price_changes": [{"asset_id": "66466375160121808081218865320764245347163437070476088335272741711627298513873", "price": "0.251", "size": "0", "side": "BUY", "hash": "d48452bfe88c6eaf050276f13e7716d2d65f8dc9", "best_bid": "0.989", "best_ask": "0.992"}, {"asset_id": "83273939204150973203361658145419377967478532826191206101882322765481122431127", "price": "0.749", "size": "0", "side": "SELL", "hash": "7d1280087991da70dbbecfa1bc4f8fc4a08068aa", "best_bid": "0.008", "best_ask": "0.011"}], "timestamp": "1769384506233", "event_type": "price_change"}}
{"_local_timestamp": "2026-01-25T23:41:46.463630+00:00", "data": {"market": "0xef62cae2f23eb9084db338cafc8ee88806bee54e3a92051689f70d6907b7f3cf", "price_changes": [{"asset_id": "86421436930838227408032705986280984822442451727936616356929369488596324752129", "price": "0.233", "size": "0", "side": "BUY", "hash": "be765fc807e1b725d6cebf3ef5cf67a51cf5d4ef", "best_bid": "0.992", "best_ask": "0.995"}, {"asset_id": "48832045779017406406240960364495829307085252456810565554978796786740596106550", "price": "0.767", "size": "0", "side": "SELL", "hash": "332d61a00bc1607c335bea11582b9d66be429d8f", "best_bid": "0.005", "best_ask": "0.008"}], "timestamp": "1769384506393", "event_type": "price_change"}}
{"_local_timestamp": "2026-01-25T23:41:46.622758+00:00", "data": {"market": "0xef62cae2f23eb9084db338cafc8ee88806bee54e3a92051689f70d6907b7f3cf", "price_changes": [{"asset_id": "86421436930838227408032705986280984822442451727936616356929369488596324752129", "price": "0.238", "size": "7978", "side": "BUY", "hash": "45a247d9bd9ef0c53a33f2f18bb23f3b045a1f57", "best_bid": "0.992", "best_ask": "0.995"}, {"asset_id": "48832045779017406406240960364495829307085252456810565554978796786740596106550", "price": "0.762", "size": "7978", "side": "SELL", "hash": "30b04c1cf972447c588f077d18ca1378040a4124", "best_bid": "0.005", "best_ask": "0.008"}], "timestamp": "1769384506553", "event_type": "price_change"}}
{"_local_timestamp": "2026-01-25T23:41:46.682631+00:00", "data": {"market": "0xef62cae2f23eb9084db338cafc8ee88806bee54e3a92051689f70d6907b7f3cf", "price_changes": [{"asset_id": "86421436930838227408032705986280984822442451727936616356929369488596324752129", "price": "0.236", "size": "0", "side": "BUY", "hash": "440fe64b511f343897d0797c9f7ef7d053580ba5", "best_bid": "0.992", "best_ask": "0.995"}, {"asset_id": "48832045779017406406240960364495829307085252456810565554978796786740596106550", "price": "0.764", "size": "0", "side": "SELL", "hash": "6795daa082548ac868374d3bcabebd08ca723ce8", "best_bid": "0.005", "best_ask": "0.008"}], "timestamp": "1769384506610", "event_type": "price_change"}}
{"_local_timestamp": "2026-01-25T23:41:46.763557+00:00", "data": {"market": "0xef62cae2f23eb9084db338cafc8ee88806bee54e3a92051689f70d6907b7f3cf", "price_changes": [{"asset_id": "86421436930838227408032705986280984822442451727936616356929369488596324752129", "price": "0.237", "size": "800", "side": "BUY", "hash": "86fe5736aec405ef3c7676ede2b8d373efdf3ea8", "best_bid": "0.992", "best_ask": "0.995"}, {"asset_id": "48832045779017406406240960364495829307085252456810565554978796786740596106550", "price": "0.763", "size": "800", "side": "SELL", "hash": "c7fefae835b02fd9554330fc5dde1d9630ba2daa", "best_bid": "0.005", "best_ask": "0.008"}], "timestamp": "1769384506688", "event_type": "price_change"}}
{"_local_timestamp": "2026-01-25T23:41:46.811618+00:00", "data": {"market": "0xef62cae2f23eb9084db338cafc8ee88806bee54e3a92051689f70d6907b7f3cf", "price_changes": [{"asset_id": "86421436930838227408032705986280984822442451727936616356929369488596324752129", "price": "0.237", "size": "300", "side": "BUY", "hash": "67453c9e03f53540b80294d4d6d95eb67d5e5f63", "best_bid": "0.992", "best_ask": "0.995"}, {"asset_id": "48832045779017406406240960364495829307085252456810565554978796786740596106550", "price": "0.763", "size": "300", "side": "SELL", "hash": "978e693bb42f7ac9e15990463b45eeb605217552", "best_bid": "0.005", "best_ask": "0.008"}], "timestamp": "1769384506743", "event_type": "price_change"}}
{"_local_timestamp": "2026-01-25T23:41:46.827447+00:00", "data": {"market": "0x1b7e6de8efe5f6a2c1ca2470e747370be89fe96270ccee85430bf18ac705a4e1", "price_changes": [{"asset_id": "94395860414009734926327544945762460944151569233112202400231598436537334220949", "price": "0.346", "size": "100", "side": "BUY", "hash": "20d557a19fd39020fe617a17d33390db7a47e8bd", "best_bid": "0.996", "best_ask": "0.998"}, {"asset_id": "86084595121347108808129382127322373721009228528241692453665189127555334452646", "price": "0.654", "size": "100", "side": "SELL", "hash": "d7541021b48a1c90fd3894873edae186052d07a2", "best_bid": "0.002", "best_ask": "0.004"}], "timestamp": "1769384506758", "event_type": "price_change"}}
{"_local_timestamp": "2026-01-25T23:41:46.871852+00:00", "data": {"market": "0xef62cae2f23eb9084db338cafc8ee88806bee54e3a92051689f70d6907b7f3cf", "price_changes": [{"asset_id": "86421436930838227408032705986280984822442451727936616356929369488596324752129", "price": "0.239", "size": "700", "side": "BUY", "hash": "59a4a79c5745842f0718d186273a02b3e2ab6ee5", "best_bid": "0.992", "best_ask": "0.995"}, {"asset_id": "48832045779017406406240960364495829307085252456810565554978796786740596106550", "price": "0.761", "size": "700", "side": "SELL", "hash": "fd6ee2ee7f01241673e44765ccbc2bbfe2e71d1d", "best_bid": "0.005", "best_ask": "0.008"}], "timestamp": "1769384506807", "event_type": "price_change"}}
{"_local_timestamp": "2026-01-25T23:41:46.874075+00:00", "data": {"market": "0xef62cae2f23eb9084db338cafc8ee88806bee54e3a92051689f70d6907b7f3cf", "price_changes": [{"asset_id": "86421436930838227408032705986280984822442451727936616356929369488596324752129", "price": "0.951", "size": "20", "side": "BUY", "hash": "948474aa6c6bc1f46bbec324f2df008897a60f43", "best_bid": "0.992", "best_ask": "0.995"}, {"asset_id": "48832045779017406406240960364495829307085252456810565554978796786740596106550", "price": "0.049", "size": "20", "side": "SELL", "hash": "f68e9be7dd9308315065af29a5a82e4e036eb347", "best_bid": "0.005", "best_ask": "0.008"}], "timestamp": "1769384506808", "event_type": "price_change"}}
{"_local_timestamp": "2026-01-25T23:41:46.914803+00:00", "data": {"market": "0xef62cae2f23eb9084db338cafc8ee88806bee54e3a92051689f70d6907b7f3cf", "price_changes": [{"asset_id": "86421436930838227408032705986280984822442451727936616356929369488596324752129", "price": "0.239", "size": "1200", "side": "BUY", "hash": "9a91e9d72a97e8c993d0f2cd1d0b750713efad64", "best_bid": "0.992", "best_ask": "0.995"}, {"asset_id": "48832045779017406406240960364495829307085252456810565554978796786740596106550", "price": "0.761", "size": "1200", "side": "SELL", "hash": "0e9287214910d8d3349a28a6ea782ebe2075f4e5", "best_bid": "0.005", "best_ask": "0.008"}], "timestamp": "1769384506850", "event_type": "price_change"}}
{"_local_timestamp": "2026-01-25T23:41:46.950483+00:00", "data": {"market": "0xef62cae2f23eb9084db338cafc8ee88806bee54e3a92051689f70d6907b7f3cf", "price_changes": [{"asset_id": "86421436930838227408032705986280984822442451727936616356929369488596324752129", "price": "0.239", "size": "2000", "side": "BUY", "hash": "1f057c060e90f84140315c37b85655035d364b36", "best_bid": "0.992", "best_ask": "0.995"}, {"asset_id": "48832045779017406406240960364495829307085252456810565554978796786740596106550", "price": "0.761", "size": "2000", "side": "SELL", "hash": "2dea1e1357589a085c3b42179dd05c94c1a9ade7", "best_bid": "0.005", "best_ask": "0.008"}], "timestamp": "1769384506885", "event_type": "price_change"}}
{"_local_timestamp": "2026-01-25T23:41:47.006639+00:00", "data": {"market": "0x1b7e6de8efe5f6a2c1ca2470e747370be89fe96270ccee85430bf18ac705a4e1", "price_changes": [{"asset_id": "94395860414009734926327544945762460944151569233112202400231598436537334220949", "price": "0.349", "size": "6805", "side": "BUY", "hash": "4e912e4ac0a4fa13c2cd5fa7375b0b99e7a04e33", "best_bid": "0.996", "best_ask": "0.998"}, {"asset_id": "86084595121347108808129382127322373721009228528241692453665189127555334452646", "price": "0.651", "size": "6805", "side": "SELL", "hash": "cec2c4c95c3e060c819fae61cac7b36345495cbf", "best_bid": "0.002", "best_ask": "0.004"}], "timestamp": "1769384506937", "event_type": "price_change"}}
{"_local_timestamp": "2026-01-25T23:41:47.135302+00:00", "data": {"market": "0x1b7e6de8efe5f6a2c1ca2470e747370be89fe96270ccee85430bf18ac705a4e1", "price_changes": [{"asset_id": "94395860414009734926327544945762460944151569233112202400231598436537334220949", "price": "0.35", "size": "194", "side": "BUY", "hash": "3ab02c9b3d95c63ca208db21dd01b4c75be0f605", "best_bid": "0.996", "best_ask": "0.998"}, {"asset_id": "86084595121347108808129382127322373721009228528241692453665189127555334452646", "price": "0.65", "size": "194", "side": "SELL", "hash": "e1b34087fc9eb4fc058a691cdfba05c74ddab4c8", "best_bid": "0.002", "best_ask": "0.004"}], "timestamp": "1769384507041", "event_type": "price_change"}}
{"_local_timestamp": "2026-01-25T23:41:47.199751+00:00", "data": {"market": "0x1b7e6de8efe5f6a2c1ca2470e747370be89fe96270ccee85430bf18ac705a4e1", "price_changes": [{"asset_id": "94395860414009734926327544945762460944151569233112202400231598436537334220949", "price": "0.348", "size": "78", "side": "BUY", "hash": "d3268fca11817cb6e33c55cec0ea4039d02d150a", "best_bid": "0.996", "best_ask": "0.998"}, {"asset_id": "86084595121347108808129382127322373721009228528241692453665189127555334452646", "price": "0.652", "size": "78", "side": "SELL", "hash": "3895caa9ec1412fe98e7cab84b4c2a30c203e545", "best_bid": "0.002", "best_ask": "0.004"}], "timestamp": "1769384507134", "event_type": "price_change"}}
{"_local_timestamp": "2026-01-25T23:41:47.317795+00:00", "data": {"market": "0x1b7e6de8efe5f6a2c1ca2470e747370be89fe96270ccee85430bf18ac705a4e1", "price_changes": [{"asset_id": "94395860414009734926327544945762460944151569233112202400231598436537334220949", "price": "0.347", "size": "0", "side": "BUY", "hash": "c913971fdeff0faab2d11ce7ed2b65819300265c", "best_bid": "0.996", "best_ask": "0.998"}, {"asset_id": "86084595121347108808129382127322373721009228528241692453665189127555334452646", "price": "0.653", "size": "0", "side": "SELL", "hash": "979d95ed77ee126a7d4aeda97b84a8b32dcdb975", "best_bid": "0.002", "best_ask": "0.004"}], "timestamp": "1769384507256", "event_type": "price_change"}}
{"_local_timestamp": "2026-01-25T23:41:47.375599+00:00", "data": {"market": "0x1b7e6de8efe5f6a2c1ca2470e747370be89fe96270ccee85430bf18ac705a4e1", "price_changes": [{"asset_id": "94395860414009734926327544945762460944151569233112202400231598436537334220949", "price": "0.35", "size": "261", "side": "BUY", "hash": "5c9bf1097632bfc2d3afc910082f2a1b75b44d49", "best_bid": "0.996", "best_ask": "0.998"}, {"asset_id": "86084595121347108808129382127322373721009228528241692453665189127555334452646", "price": "0.65", "size": "261", "side": "SELL", "hash": "3379197219634f884b5781e9f9644f01aa911dbc", "best_bid": "0.002", "best_ask": "0.004"}], "timestamp": "1769384507299", "event_type": "price_change"}}
{"_local_timestamp": "2026-01-25T23:41:47.495034+00:00", "data": {"market": "0x1b7e6de8efe5f6a2c1ca2470e747370be89fe96270ccee85430bf18ac705a4e1", "price_changes": [{"asset_id": "94395860414009734926327544945762460944151569233112202400231598436537334220949", "price": "0.35", "size": "325", "side": "BUY", "hash": "5d5b772624dbb5567cf178a799b630836bd84a01", "best_bid": "0.996", "best_ask": "0.998"}, {"asset_id": "86084595121347108808129382127322373721009228528241692453665189127555334452646", "price": "0.65", "size": "325", "side": "SELL", "hash": "c0edb2aa2e0052582cbc1d82cf550189800bd757", "best_bid": "0.002", "best_ask": "0.004"}], "timestamp": "1769384507426", "event_type": "price_change"}}
{"_local_timestamp": "2026-01-25T23:41:47.501359+00:00", "data": {"market": "0x1b7e6de8efe5f6a2c1ca2470e747370be89fe96270ccee85430bf18ac705a4e1", "price_changes": [{"asset_id": "94395860414009734926327544945762460944151569233112202400231598436537334220949", "price": "0.951", "size": "20", "side": "BUY", "hash": "1b606928f6a85cd7c28dd34e1debb562fd4fd4fd", "best_bid": "0.996", "best_ask": "0.998"}, {"asset_id": "86084595121347108808129382127322373721009228528241692453665189127555334452646", "price": "0.049", "size": "20", "side": "SELL", "hash": "608cc1314af97fb77f2a17bfaf32a3a3c878a46a", "best_bid": "0.002", "best_ask": "0.004"}], "timestamp": "1769384507427", "event_type": "price_change"}}
{"_local_timestamp": "2026-01-25T23:41:54.461666+00:00", "data": {"market": "0x7d99e856ca49dcf748ff0072af624a65bafcb44a34b914b5a1466211674ae729", "price_changes": [{"asset_id": "17182810599901842221755643003911781322979812178264318853202692827838675256569", "price": "0.022", "size": "0", "side": "BUY", "hash": "b6f0b7e9d239ce0c5889254e7fceb9f32370bc41", "best_bid": "0.981", "best_ask": "0.99"}, {"asset_id": "27250410806992141952257033810710803403327848453310007128861669762666286354528", "price": "0.978", "size": "0", "side": "SELL", "hash": "f30b0b8b8e78bec60e594526f73eddebdf1ce8a0", "best_bid": "0.01", "best_ask": "0.019"}], "timestamp": "1769384514391", "event_type": "price_change"}}
{"_local_timestamp": "2026-01-25T23:41:54.872523+00:00", "data": {"market": "0x7d99e856ca49dcf748ff0072af624a65bafcb44a34b914b5a1466211674ae729", "price_changes": [{"asset_id": "17182810599901842221755643003911781322979812178264318853202692827838675256569", "price": "0.021", "size": "15.62", "side": "BUY", "hash": "54ee2d6f2c79c7ee98bc752068941c20e95e8c56", "best_bid": "0.981", "best_ask": "0.99"}, {"asset_id": "27250410806992141952257033810710803403327848453310007128861669762666286354528", "price": "0.979", "size": "15.62", "side": "SELL", "hash": "7f39e9718df860943f5a1bf7917a77d4b38c02de", "best_bid": "0.01", "best_ask": "0.019"}], "timestamp": "1769384514793", "event_type": "price_change"}}
{"_local_timestamp": "2026-01-25T23:41:54.887092+00:00", "data": {"market": "0xb7ba5d2b34c3f78d2b483daa97bc301f7296a5d8658ba2851f4c912a161e5158", "price_changes": [{"asset_id": "32582994008069750117370770211161750379270178143252809024325448815129555714046", "price": "0.026", "size": "1200", "side": "BUY", "hash": "faccf384f1989308302528f6c22b97fab191d16c", "best_bid": "0.952", "best_ask": "0.954"}, {"asset_id": "94207036547569786168949387588066196313734350858370522979598866565386642178169", "price": "0.974", "size": "1200", "side": "SELL", "hash": "ee549e2c4376d570877a362aeb2dbf80563226eb", "best_bid": "0.046", "best_ask": "0.048"}], "timestamp": "1769384514821", "event_type": "price_change"}}
{"_local_timestamp": "2026-01-25T23:41:55.147958+00:00", "data": {"market": "0xb7ba5d2b34c3f78d2b483daa97bc301f7296a5d8658ba2851f4c912a161e5158", "price_changes": [{"asset_id": "32582994008069750117370770211161750379270178143252809024325448815129555714046", "price": "0.027", "size": "5799", "side": "BUY", "hash": "ed4c4343cca75cc4bc411f9f535ab450359dd647", "best_bid": "0.952", "best_ask": "0.954"}, {"asset_id": "94207036547569786168949387588066196313734350858370522979598866565386642178169", "price": "0.973", "size": "5799", "side": "SELL", "hash": "e6c5e153ae140077aac916aaf4c69719f4908d10", "best_bid": "0.046", "best_ask": "0.048"}], "timestamp": "1769384515073", "event_type": "price_change"}}
{"_local_timestamp": "2026-01-25T23:42:10.155940+00:00", "data": {"market": "0xb7ba5d2b34c3f78d2b483daa97bc301f7296a5d8658ba2851f4c912a161e5158", "price_changes": [{"asset_id": "32582994008069750117370770211161750379270178143252809024325448815129555714046", "price": "0.026", "size": "800", "side": "BUY", "hash": "f6aecf2430a3bfc4b393f5f1157c50813985eea3", "best_bid": "0.952", "best_ask": "0.954"}, {"asset_id": "94207036547569786168949387588066196313734350858370522979598866565386642178169", "price": "0.974", "size": "800", "side": "SELL", "hash": "58e4ad3b73fbe41059410eb21ea16ed1c7d83306", "best_bid": "0.046", "best_ask": "0.048"}], "timestamp": "1769384530052", "event_type": "price_change"}}
{"_local_timestamp": "2026-01-25T23:42:10.191061+00:00", "data": {"market": "0x1b7e6de8efe5f6a2c1ca2470e747370be89fe96270ccee85430bf18ac705a4e1", "price_changes": [{"asset_id": "94395860414009734926327544945762460944151569233112202400231598436537334220949", "price": "0.973", "size": "49", "side": "BUY", "hash": "624304565ef872f1b2ede8f9215dd3ec21bca00b", "best_bid": "0.996", "best_ask": "0.998"}, {"asset_id": "86084595121347108808129382127322373721009228528241692453665189127555334452646", "price": "0.027", "size": "49", "side": "SELL", "hash": "61a964e4055e25fa5fb40f521daa9a89d3d68485", "best_bid": "0.002", "best_ask": "0.004"}], "timestamp": "1769384530111", "event_type": "price_change"}}
{"_local_timestamp": "2026-01-25T23:42:10.191573+00:00", "data": {"market": "0xb7ba5d2b34c3f78d2b483daa97bc301f7296a5d8658ba2851f4c912a161e5158", "price_changes": [{"asset_id": "94207036547569786168949387588066196313734350858370522979598866565386642178169", "price": "0.023", "size": "49", "side": "BUY", "hash": "d3fdb9482b603a433f7f4982297446d838659889", "best_bid": "0.046", "best_ask": "0.048"}, {"asset_id": "32582994008069750117370770211161750379270178143252809024325448815129555714046", "price": "0.977", "size": "49", "side": "SELL", "hash": "6fd64e56cbd1a1f6e241ca45c20cea0e25757b9b", "best_bid": "0.952", "best_ask": "0.954"}], "timestamp": "1769384530112", "event_type": "price_change"}}
{"_local_timestamp": "2026-01-25T23:42:10.192035+00:00", "data": {"market": "0xda86314ac2dd0f78ab1fe5b746840abeeff5be4e74c6d5bd5a0aada5c695030e", "price_changes": [{"asset_id": "66466375160121808081218865320764245347163437070476088335272741711627298513873", "price": "0.968", "size": "49", "side": "BUY", "hash": "3f3d872ae41a22a4caecb8e90daa8d4d74483cc5", "best_bid": "0.989", "best_ask": "0.992"}, {"asset_id": "83273939204150973203361658145419377967478532826191206101882322765481122431127", "price": "0.032", "size": "49", "side": "SELL", "hash": "ee3a4348d45ee7c2448af346247a70f7407c547c", "best_bid": "0.008", "best_ask": "0.011"}], "timestamp": "1769384530113", "event_type": "price_change"}}
{"_local_timestamp": "2026-01-25T23:42:10.195154+00:00", "data": {"market": "0x7d99e856ca49dcf748ff0072af624a65bafcb44a34b914b5a1466211674ae729", "price_changes": [{"asset_id": "17182810599901842221755643003911781322979812178264318853202692827838675256569", "price": "0.966", "size": "49", "side": "BUY", "hash": "4724fffddd55cc817b79e0002832547fb69ff241", "best_bid": "0.981", "best_ask": "0.99"}, {"asset_id": "27250410806992141952257033810710803403327848453310007128861669762666286354528", "price": "0.034", "size": "49", "side": "SELL", "hash": "61095c865ed18fa61d861a9fb229fea5dc5fe9d6", "best_bid": "0.01", "best_ask": "0.019"}], "timestamp": "1769384530116", "event_type": "price_change"}}
{"_local_timestamp": "2026-01-25T23:42:10.380346+00:00", "data": {"market": "0xb7ba5d2b34c3f78d2b483daa97bc301f7296a5d8658ba2851f4c912a161e5158", "price_changes": [{"asset_id": "32582994008069750117370770211161750379270178143252809024325448815129555714046", "price": "0.027", "size": "6199", "side": "BUY", "hash": "e6eb3c704fa405ba955008e8ac58c8fffd0610ac", "best_bid": "0.952", "best_ask": "0.954"}, {"asset_id": "94207036547569786168949387588066196313734350858370522979598866565386642178169", "price": "0.973", "size": "6199", "side": "SELL", "hash": "23f49ee1e4dae26483976b5d7fa11d5ebb1e076b", "best_bid": "0.046", "best_ask": "0.048"}], "timestamp": "1769384530314", "event_type": "price_change"}}
{"_local_timestamp": "2026-01-25T23:42:13.603680+00:00", "data": {"market": "0xb7ba5d2b34c3f78d2b483daa97bc301f7296a5d8658ba2851f4c912a161e5158", "price_changes": [{"asset_id": "32582994008069750117370770211161750379270178143252809024325448815129555714046", "price": "0.026", "size": "400", "side": "BUY", "hash": "9dba98513574d3449f498d8af178211fb194e591", "best_bid": "0.952", "best_ask": "0.954"}, {"asset_id": "94207036547569786168949387588066196313734350858370522979598866565386642178169", "price": "0.974", "size": "400", "side": "SELL", "hash": "49a3be186a25558afa81e2b4a749b4c388061e99", "best_bid": "0.046", "best_ask": "0.048"}], "timestamp": "1769384533515", "event_type": "price_change"}}
{"_local_timestamp": "2026-01-25T23:42:13.847239+00:00", "data": {"market": "0xb7ba5d2b34c3f78d2b483daa97bc301f7296a5d8658ba2851f4c912a161e5158", "price_changes": [{"asset_id": "32582994008069750117370770211161750379270178143252809024325448815129555714046", "price": "0.027", "size": "6599", "side": "BUY", "hash": "0329a6ad6ff16b4281164d51c30bd130d372ec39", "best_bid": "0.952", "best_ask": "0.954"}, {"asset_id": "94207036547569786168949387588066196313734350858370522979598866565386642178169", "price": "0.973", "size": "6599", "side": "SELL", "hash": "2a70d91cf2fa08fa95b70a736b10b45e4229b34c", "best_bid": "0.046", "best_ask": "0.048"}], "timestamp": "1769384533779", "event_type": "price_change"}}
{"_local_timestamp": "2026-01-25T23:42:15.550384+00:00", "data": {"market": "0x7d99e856ca49dcf748ff0072af624a65bafcb44a34b914b5a1466211674ae729", "price_changes": [{"asset_id": "27250410806992141952257033810710803403327848453310007128861669762666286354528", "price": "0.002", "size": "1100", "side": "BUY", "hash": "684a7b15f3ae690e33ddd20a3c86b82c348e7180", "best_bid": "0.01", "best_ask": "0.019"}, {"asset_id": "17182810599901842221755643003911781322979812178264318853202692827838675256569", "price": "0.998", "size": "1100", "side": "SELL", "hash": "0f8716ec983da112398017330ba01f1aa309d2bc", "best_bid": "0.981", "best_ask": "0.99"}], "timestamp": "1769384535463", "event_type": "price_change"}}
{"_local_timestamp": "2026-01-25T23:42:15.550978+00:00", "data": {"market": "0x7d99e856ca49dcf748ff0072af624a65bafcb44a34b914b5a1466211674ae729", "price_changes": [{"asset_id": "27250410806992141952257033810710803403327848453310007128861669762666286354528", "price": "0.003", "size": "350", "side": "BUY", "hash": "684a7b15f3ae690e33ddd20a3c86b82c348e7180", "best_bid": "0.01", "best_ask": "0.019"}, {"asset_id": "17182810599901842221755643003911781322979812178264318853202692827838675256569", "price": "0.997", "size": "350", "side": "SELL", "hash": "0f8716ec983da112398017330ba01f1aa309d2bc", "best_bid": "0.981", "best_ask": "0.99"}], "timestamp": "1769384535463", "event_type": "price_change"}}
{"_local_timestamp": "2026-01-25T23:42:16.275457+00:00", "data": {"market": "0x7d99e856ca49dcf748ff0072af624a65bafcb44a34b914b5a1466211674ae729", "price_changes": [{"asset_id": "27250410806992141952257033810710803403327848453310007128861669762666286354528", "price": "0.003", "size": "372.39", "side": "BUY", "hash": "6fd488b95b660cfc742fc1af39a9eba7e3a03f57", "best_bid": "0.01", "best_ask": "0.019"}, {"asset_id": "17182810599901842221755643003911781322979812178264318853202692827838675256569", "price": "0.997", "size": "372.39", "side": "SELL", "hash": "0c05e18bec2bbc55d7d44ef20a9091f41d884caf", "best_bid": "0.981", "best_ask": "0.99"}], "timestamp": "1769384536176", "event_type": "price_change"}}
{"_local_timestamp": "2026-01-25T23:42:16.275932+00:00", "data": {"market": "0x7d99e856ca49dcf748ff0072af624a65bafcb44a34b914b5a1466211674ae729", "price_changes": [{"asset_id": "27250410806992141952257033810710803403327848453310007128861669762666286354528", "price": "0.007", "size": "109.4", "side": "BUY", "hash": "e65f4a3a9be1fc36704d7ef411e9e8f6e7d0d98c", "best_bid": "0.01", "best_ask": "0.019"}, {"asset_id": "17182810599901842221755643003911781322979812178264318853202692827838675256569", "price": "0.993", "size": "109.4", "side": "SELL", "hash": "8655c4140a06f4bc9454bee7076b9b6bf6db76f7", "best_bid": "0.981", "best_ask": "0.99"}], "timestamp": "1769384536184", "event_type": "price_change"}}
{"_local_timestamp": "2026-01-25T23:42:16.283618+00:00", "data": {"market": "0x7d99e856ca49dcf748ff0072af624a65bafcb44a34b914b5a1466211674ae729", "price_changes": [{"asset_id": "27250410806992141952257033810710803403327848453310007128861669762666286354528", "price": "0.002", "size": "1133.76", "side": "BUY", "hash": "7c234eddeb105c77affdba7ed55b84e96573fe04", "best_bid": "0.01", "best_ask": "0.019"}, {"asset_id": "17182810599901842221755643003911781322979812178264318853202692827838675256569", "price": "0.998", "size": "1133.76", "side": "SELL", "hash": "8d3a4660603ac855749b303f1602772cc8619fab", "best_bid": "0.981", "best_ask": "0.99"}], "timestamp": "1769384536189", "event_type": "price_change"}}
{"_local_timestamp": "2026-01-25T23:42:22.479094+00:00", "data": {"market": "0x1b7e6de8efe5f6a2c1ca2470e747370be89fe96270ccee85430bf18ac705a4e1", "price_changes": [{"asset_id": "94395860414009734926327544945762460944151569233112202400231598436537334220949", "price": "0.346", "size": "0", "side": "BUY", "hash": "06ebb1b1e2772b42452baa51060ce3cccfe310b5", "best_bid": "0.996", "best_ask": "0.998"}, {"asset_id": "86084595121347108808129382127322373721009228528241692453665189127555334452646", "price": "0.654", "size": "0", "side": "SELL", "hash": "298cd7d62a8629df71f6bf8811d4f342eb721ff2", "best_bid": "0.002", "best_ask": "0.004"}], "timestamp": "1769384542349", "event_type": "price_change"}}
{"_local_timestamp": "2026-01-25T23:42:22.738556+00:00", "data": {"market": "0x1b7e6de8efe5f6a2c1ca2470e747370be89fe96270ccee85430bf18ac705a4e1", "price_changes": [{"asset_id": "94395860414009734926327544945762460944151569233112202400231598436537334220949", "price": "0.349", "size": "6905", "side": "BUY", "hash": "972211d480912b978eb27134920624b4ddbec304", "best_bid": "0.996", "best_ask": "0.998"}, {"asset_id": "86084595121347108808129382127322373721009228528241692453665189127555334452646", "price": "0.651", "size": "6905", "side": "SELL", "hash": "e80b186e48301a13c291ba79ceed2138e4289351", "best_bid": "0.002", "best_ask": "0.004"}], "timestamp": "1769384542615", "event_type": "price_change"}}
{"_local_timestamp": "2026-01-25T23:42:23.980495+00:00", "data": {"market": "0xb7ba5d2b34c3f78d2b483daa97bc301f7296a5d8658ba2851f4c912a161e5158", "price_changes": [{"asset_id": "32582994008069750117370770211161750379270178143252809024325448815129555714046", "price": "0.026", "size": "0", "side": "BUY", "hash": "2fad84669ea9830ac14cfab41dd5aba94af40b7e", "best_bid": "0.952", "best_ask": "0.954"}, {"asset_id": "94207036547569786168949387588066196313734350858370522979598866565386642178169", "price": "0.974", "size": "0", "side": "SELL", "hash": "70efa1f708e2c6e9120921be6e1b9dc18bac85b7", "best_bid": "0.046", "best_ask": "0.048"}], "timestamp": "1769384543832", "event_type": "price_change"}}
{"_local_timestamp": "2026-01-25T23:42:24.276880+00:00", "data": {"market": "0xb7ba5d2b34c3f78d2b483daa97bc301f7296a5d8658ba2851f4c912a161e5158", "price_changes": [{"asset_id": "32582994008069750117370770211161750379270178143252809024325448815129555714046", "price": "0.027", "size": "6999", "side": "BUY", "hash": "6500dde01db9764c3f5398aa475eca71492c56ac", "best_bid": "0.952", "best_ask": "0.954"}, {"asset_id": "94207036547569786168949387588066196313734350858370522979598866565386642178169", "price": "0.973", "size": "6999", "side": "SELL", "hash": "a7961777ac7f102f99c82f7e0a0b0764348aa242", "best_bid": "0.046", "best_ask": "0.048"}], "timestamp": "1769384544116", "event_type": "price_change"}}
{"_local_timestamp": "2026-01-25T23:42:25.991567+00:00", "data": {"market": "0x7d99e856ca49dcf748ff0072af624a65bafcb44a34b914b5a1466211674ae729", "price_changes": [{"asset_id": "17182810599901842221755643003911781322979812178264318853202692827838675256569", "price": "0.627", "size": "0", "side": "BUY", "hash": "7a4c77bf5a227ec99e19c27988dd9ade6300b9a8", "best_bid": "0.981", "best_ask": "0.99"}, {"asset_id": "27250410806992141952257033810710803403327848453310007128861669762666286354528", "price": "0.373", "size": "0", "side": "SELL", "hash": "efca08bbba6354f70c5a3f5f854fb2158ebf22c3", "best_bid": "0.01", "best_ask": "0.019"}], "timestamp": "1769384545860", "event_type": "price_change"}}
{"_local_timestamp": "2026-01-25T23:42:26.042557+00:00", "data": {"market": "0x7d99e856ca49dcf748ff0072af624a65bafcb44a34b914b5a1466211674ae729", "price_changes": [{"asset_id": "17182810599901842221755643003911781322979812178264318853202692827838675256569", "price": "0.678", "size": "5", "side": "BUY", "hash": "76cd6e789d42f83fe7880508ffd6f4c2b00e9b2e", "best_bid": "0.981", "best_ask": "0.99"}, {"asset_id": "27250410806992141952257033810710803403327848453310007128861669762666286354528", "price": "0.322", "size": "5", "side": "SELL", "hash": "3fbf2919c9b50c7cbf933bb2d25dfd935e04944d", "best_bid": "0.01", "best_ask": "0.019"}], "timestamp": "1769384545908", "event_type": "price_change"}}
{"_local_timestamp": "2026-01-25T23:42:37.203087+00:00", "data": {"market": "0xb7ba5d2b34c3f78d2b483daa97bc301f7296a5d8658ba2851f4c912a161e5158", "price_changes": [{"asset_id": "32582994008069750117370770211161750379270178143252809024325448815129555714046", "price": "0.359", "size": "0", "side": "BUY", "hash": "8a89059c2cd9d6d9270daffe4fab546c6ef29404", "best_bid": "0.952", "best_ask": "0.954"}, {"asset_id": "94207036547569786168949387588066196313734350858370522979598866565386642178169", "price": "0.641", "size": "0", "side": "SELL", "hash": "70bc00dc39694c1e598eac31b88861018b6916b4", "best_bid": "0.046", "best_ask": "0.048"}], "timestamp": "1769384557031", "event_type": "price_change"}}
{"_local_timestamp": "2026-01-25T23:42:37.519490+00:00", "data": {"market": "0xb7ba5d2b34c3f78d2b483daa97bc301f7296a5d8658ba2851f4c912a161e5158", "price_changes": [{"asset_id": "32582994008069750117370770211161750379270178143252809024325448815129555714046", "price": "0.359", "size": "5", "side": "BUY", "hash": "533ecce67e5eb8894ebb88414f51a01f6e2f63f0", "best_bid": "0.952", "best_ask": "0.954"}, {"asset_id": "94207036547569786168949387588066196313734350858370522979598866565386642178169", "price": "0.641", "size": "5", "side": "SELL", "hash": "169c19cf831405b210c473ec39145d4947172424", "best_bid": "0.046", "best_ask": "0.048"}], "timestamp": "1769384557391", "event_type": "price_change"}}
{"_local_timestamp": "2026-01-25T23:42:52.938779+00:00", "data": {"market": "0x7d99e856ca49dcf748ff0072af624a65bafcb44a34b914b5a1466211674ae729", "price_changes": [{"asset_id": "27250410806992141952257033810710803403327848453310007128861669762666286354528", "price": "0.007", "size": "100", "side": "BUY", "hash": "3961db6fc365913eb1c500cf965b2da446fb7bf2", "best_bid": "0.01", "best_ask": "0.019"}, {"asset_id": "17182810599901842221755643003911781322979812178264318853202692827838675256569", "price": "0.993", "size": "100", "side": "SELL", "hash": "227f33aea1599e3601ad43e64d48153b058bf316", "best_bid": "0.981", "best_ask": "0.99"}], "timestamp": "1769384572794", "event_type": "price_change"}}
{"_local_timestamp": "2026-01-25T23:43:04.167852+00:00", "data": {"market": "0xb7ba5d2b34c3f78d2b483daa97bc301f7296a5d8658ba2851f4c912a161e5158", "price_changes": [{"asset_id": "32582994008069750117370770211161750379270178143252809024325448815129555714046", "price": "0.933", "size": "0", "side": "BUY", "hash": "a74e5df6e90e6ad7cb824cda269b766fefc7ef9e", "best_bid": "0.952", "best_ask": "0.954"}, {"asset_id": "94207036547569786168949387588066196313734350858370522979598866565386642178169", "price": "0.067", "size": "0", "side": "SELL", "hash": "30434fcef21034b4b494739efc11299a66f4a27a", "best_bid": "0.046", "best_ask": "0.048"}], "timestamp": "1769384584005", "event_type": "price_change"}}
{"_local_timestamp": "2026-01-25T23:43:04.173106+00:00", "data": {"market": "0xb7ba5d2b34c3f78d2b483daa97bc301f7296a5d8658ba2851f4c912a161e5158", "price_changes": [{"asset_id": "94207036547569786168949387588066196313734350858370522979598866565386642178169", "price": "0.027", "size": "0", "side": "BUY", "hash": "62bbac9063356511f52926fb3eb781461ca17360", "best_bid": "0.046", "best_ask": "0.048"}, {"asset_id": "32582994008069750117370770211161750379270178143252809024325448815129555714046", "price": "0.973", "size": "0", "side": "SELL", "hash": "74303794fcadfca802d7c78f6a4d1597f2bd197b", "best_bid": "0.952", "best_ask": "0.954"}], "timestamp": "1769384584006", "event_type": "price_change"}}
{"_local_timestamp": "2026-01-25T23:43:04.228778+00:00", "data": {"market": "0x1b7e6de8efe5f6a2c1ca2470e747370be89fe96270ccee85430bf18ac705a4e1", "price_changes": [{"asset_id": "94395860414009734926327544945762460944151569233112202400231598436537334220949", "price": "0.35", "size": "131", "side": "BUY", "hash": "3cbae60c97b47796be5fa3e42720a7a351bdd47f", "best_bid": "0.996", "best_ask": "0.998"}, {"asset_id": "86084595121347108808129382127322373721009228528241692453665189127555334452646", "price": "0.65", "size": "131", "side": "SELL", "hash": "07f729e5887520cf64fe4cd00425598a423d3da6", "best_bid": "0.002", "best_ask": "0.004"}], "timestamp": "1769384584092", "event_type": "price_change"}}
{"_local_timestamp": "2026-01-25T23:43:04.232641+00:00", "data": {"market": "0xda86314ac2dd0f78ab1fe5b746840abeeff5be4e74c6d5bd5a0aada5c695030e", "price_changes": [{"asset_id": "66466375160121808081218865320764245347163437070476088335272741711627298513873", "price": "0.925", "size": "0", "side": "BUY", "hash": "f9128a7d44a4b05cf2d8886ecad0efb14651f69f", "best_bid": "0.989", "best_ask": "0.992"}, {"asset_id": "83273939204150973203361658145419377967478532826191206101882322765481122431127", "price": "0.075", "size": "0", "side": "SELL", "hash": "2dcb735d9db41b93fe5b0947d47025b6c3b4b39d", "best_bid": "0.008", "best_ask": "0.011"}], "timestamp": "1769384584096", "event_type": "price_change"}}
{"_local_timestamp": "2026-01-25T23:43:04.300614+00:00", "data": {"market": "0xda86314ac2dd0f78ab1fe5b746840abeeff5be4e74c6d5bd5a0aada5c695030e", "price_changes": [{"asset_id": "66466375160121808081218865320764245347163437070476088335272741711627298513873", "price": "0.254", "size": "500", "side": "BUY", "hash": "68fd08357318d3cf2bd68d2468ca08fc0e53d21d", "best_bid": "0.989", "best_ask": "0.992"}, {"asset_id": "83273939204150973203361658145419377967478532826191206101882322765481122431127", "price": "0.746", "size": "500", "side": "SELL", "hash": "b923cf41b3b88457060bc8f5d691a7650b7f8ffe", "best_bid": "0.008", "best_ask": "0.011"}], "timestamp": "1769384584163", "event_type": "price_change"}}
{"_local_timestamp": "2026-01-25T23:43:04.333243+00:00", "data": {"market": "0x7d99e856ca49dcf748ff0072af624a65bafcb44a34b914b5a1466211674ae729", "price_changes": [{"asset_id": "17182810599901842221755643003911781322979812178264318853202692827838675256569", "price": "0.674", "size": "433", "side": "BUY", "hash": "9bdd0f0941771c2f086e1c4099711056b420f3a9", "best_bid": "0.981", "best_ask": "0.99"}, {"asset_id": "27250410806992141952257033810710803403327848453310007128861669762666286354528", "price": "0.326", "size": "433", "side": "SELL", "hash": "6f64fd9e0a33a32c3c73a4986c8c0f3d202486cc", "best_bid": "0.01", "best_ask": "0.019"}], "timestamp": "1769384584188", "event_type": "price_change"}}
{"_local_timestamp": "2026-01-25T23:43:04.333813+00:00", "data": {"market": "0x7d99e856ca49dcf748ff0072af624a65bafcb44a34b914b5a1466211674ae729", "price_changes": [{"asset_id": "17182810599901842221755643003911781322979812178264318853202692827838675256569", "price": "0.667", "size": "0", "side": "BUY", "hash": "9bdd0f0941771c2f086e1c4099711056b420f3a9", "best_bid": "0.981", "best_ask": "0.99"}, {"asset_id": "27250410806992141952257033810710803403327848453310007128861669762666286354528", "price": "0.333", "size": "0", "side": "SELL", "hash": "6f64fd9e0a33a32c3c73a4986c8c0f3d202486cc", "best_bid": "0.01", "best_ask": "0.019"}], "timestamp": "1769384584188", "event_type": "price_change"}}
{"_local_timestamp": "2026-01-25T23:43:04.355729+00:00", "data": {"market": "0xda86314ac2dd0f78ab1fe5b746840abeeff5be4e74c6d5bd5a0aada5c695030e", "price_changes": [{"asset_id": "66466375160121808081218865320764245347163437070476088335272741711627298513873", "price": "0.254", "size": "1287", "side": "BUY", "hash": "dedbfb6dab47c4ad48100da8313b02d2ab785ab3", "best_bid": "0.989", "best_ask": "0.992"}, {"asset_id": "83273939204150973203361658145419377967478532826191206101882322765481122431127", "price": "0.746", "size": "1287", "side": "SELL", "hash": "37869a60a6e0f0ca958383648ed51bcd31323cdd", "best_bid": "0.008", "best_ask": "0.011"}], "timestamp": "1769384584209", "event_type": "price_change"}}
{"_local_timestamp": "2026-01-25T23:43:04.454141+00:00", "data": {"market": "0x7d99e856ca49dcf748ff0072af624a65bafcb44a34b914b5a1466211674ae729", "price_changes": [{"asset_id": "17182810599901842221755643003911781322979812178264318853202692827838675256569", "price": "0.679", "size": "20", "side": "BUY", "hash": "137550460370fbe738a6fc8fa915444f1114807f", "best_bid": "0.981", "best_ask": "0.99"}, {"asset_id": "27250410806992141952257033810710803403327848453310007128861669762666286354528", "price": "0.321", "size": "20", "side": "SELL", "hash": "97f8d50e3ffc4d369311be5b9254cd8253c52758", "best_bid": "0.01", "best_ask": "0.019"}], "timestamp": "1769384584317", "event_type": "price_change"}}
{"_local_timestamp": "2026-01-25T23:43:06.246104+00:00", "data": {"market": "0x7d99e856ca49dcf748ff0072af624a65bafcb44a34b914b5a1466211674ae729", "price_changes": [{"asset_id": "17182810599901842221755643003911781322979812178264318853202692827838675256569", "price": "0.677", "size": "0", "side": "BUY", "hash": "25964d19f57423d163c32472b867d83866ad4be1", "best_bid": "0.981", "best_ask": "0.99"}, {"asset_id": "27250410806992141952257033810710803403327848453310007128861669762666286354528", "price": "0.323", "size": "0", "side": "SELL", "hash": "02191fcd1acdafa9b32031fc1803b647eff59593", "best_bid": "0.01", "best_ask": "0.019"}], "timestamp": "1769384586105", "event_type": "price_change"}}
{"_local_timestamp": "2026-01-25T23:43:06.274244+00:00", "data": {"market": "0x7d99e856ca49dcf748ff0072af624a65bafcb44a34b914b5a1466211674ae729", "price_changes": [{"asset_id": "17182810599901842221755643003911781322979812178264318853202692827838675256569", "price": "0.68", "size": "20", "side": "BUY", "hash": "600323221023f7c503d8dad7d11090f4868ab11e", "best_bid": "0.981", "best_ask": "0.99"}, {"asset_id": "27250410806992141952257033810710803403327848453310007128861669762666286354528", "price": "0.32", "size": "20", "side": "SELL", "hash": "c4e4e26eea45ab7fc6dd1232c4b40054c1a9449c", "best_bid": "0.01", "best_ask": "0.019"}], "timestamp": "1769384586129", "event_type": "price_change"}}
{"_local_timestamp": "2026-01-25T23:43:29.762235+00:00", "data": {"market": "0xb7ba5d2b34c3f78d2b483daa97bc301f7296a5d8658ba2851f4c912a161e5158", "price_changes": [{"asset_id": "32582994008069750117370770211161750379270178143252809024325448815129555714046", "price": "0.359", "size": "0", "side": "BUY", "hash": "7d79e2e8dd66928c60ea4e7865503ed8069d4219", "best_bid": "0.952", "best_ask": "0.954"}, {"asset_id": "94207036547569786168949387588066196313734350858370522979598866565386642178169", "price": "0.641", "size": "0", "side": "SELL", "hash": "5c1c1eb678ab111c6d2e598d030f7578a6d3e4cd", "best_bid": "0.046", "best_ask": "0.048"}], "timestamp": "1769384609672", "event_type": "price_change"}}
{"_local_timestamp": "2026-01-25T23:43:29.785763+00:00", "data": {"market": "0x1b7e6de8efe5f6a2c1ca2470e747370be89fe96270ccee85430bf18ac705a4e1", "price_changes": [{"asset_id": "94395860414009734926327544945762460944151569233112202400231598436537334220949", "price": "0.973", "size": "0", "side": "BUY", "hash": "d46dec4743b55a870bf34d174ad0e4fce6c5b896", "best_bid": "0.996", "best_ask": "0.998"}, {"asset_id": "86084595121347108808129382127322373721009228528241692453665189127555334452646", "price": "0.027", "size": "0", "side": "SELL", "hash": "8a2872266d30f9ec88385aa7f2f8b632573adbcf", "best_bid": "0.002", "best_ask": "0.004"}], "timestamp": "1769384609696", "event_type": "price_change"}}
{"_local_timestamp": "2026-01-25T23:43:29.786567+00:00", "data": {"market": "0x7d99e856ca49dcf748ff0072af624a65bafcb44a34b914b5a1466211674ae729", "price_changes": [{"asset_id": "17182810599901842221755643003911781322979812178264318853202692827838675256569", "price": "0.966", "size": "0", "side": "BUY", "hash": "f5f31f3c483d6ca520a624eee4b7a590cd6833b5", "best_bid": "0.981", "best_ask": "0.99"}, {"asset_id": "27250410806992141952257033810710803403327848453310007128861669762666286354528", "price": "0.034", "size": "0", "side": "SELL", "hash": "29e0cae30b55cbde48eb72e1d2013cd2a03b1c87", "best_bid": "0.01", "best_ask": "0.019"}], "timestamp": "1769384609697", "event_type": "price_change"}}
{"_local_timestamp": "2026-01-25T23:43:29.789980+00:00", "data": {"market": "0xda86314ac2dd0f78ab1fe5b746840abeeff5be4e74c6d5bd5a0aada5c695030e", "price_changes": [{"asset_id": "66466375160121808081218865320764245347163437070476088335272741711627298513873", "price": "0.968", "size": "0", "side": "BUY", "hash": "735698bf9ecce85bfd1df7c155fb4a5e75359bac", "best_bid": "0.989", "best_ask": "0.992"}, {"asset_id": "83273939204150973203361658145419377967478532826191206101882322765481122431127", "price": "0.032", "size": "0", "side": "SELL", "hash": "a29d989d2f33a28d0684531831fb0a62b62ff11a", "best_bid": "0.008", "best_ask": "0.011"}], "timestamp": "1769384609698", "event_type": "price_change"}}
{"_local_timestamp": "2026-01-25T23:43:29.793538+00:00", "data": {"market": "0xb7ba5d2b34c3f78d2b483daa97bc301f7296a5d8658ba2851f4c912a161e5158", "price_changes": [{"asset_id": "94207036547569786168949387588066196313734350858370522979598866565386642178169", "price": "0.023", "size": "0", "side": "BUY", "hash": "8603d7dce9c95f30732b490f20f75e3f8864e45b", "best_bid": "0.046", "best_ask": "0.048"}, {"asset_id": "32582994008069750117370770211161750379270178143252809024325448815129555714046", "price": "0.977", "size": "0", "side": "SELL", "hash": "6010a8627d8961269b7fdc58a8bb2eab91b9cc78", "best_bid": "0.952", "best_ask": "0.954"}], "timestamp": "1769384609698", "event_type": "price_change"}}
{"_local_timestamp": "2026-01-25T23:43:29.858797+00:00", "data": {"market": "0x7d99e856ca49dcf748ff0072af624a65bafcb44a34b914b5a1466211674ae729", "price_changes": [{"asset_id": "17182810599901842221755643003911781322979812178264318853202692827838675256569", "price": "0.673", "size": "0", "side": "BUY", "hash": "32cc81c5ffe66b1fc9c939a290bfcae4fd3cc770", "best_bid": "0.981", "best_ask": "0.99"}, {"asset_id": "27250410806992141952257033810710803403327848453310007128861669762666286354528", "price": "0.327", "size": "0", "side": "SELL", "hash": "b94afcacaa28f3a2416e716ff5a70a888e9449f8", "best_bid": "0.01", "best_ask": "0.019"}], "timestamp": "1769384609758", "event_type": "price_change"}}
{"_local_timestamp": "2026-01-25T23:43:29.929274+00:00", "data": {"market": "0x7d99e856ca49dcf748ff0072af624a65bafcb44a34b914b5a1466211674ae729", "price_changes": [{"asset_id": "17182810599901842221755643003911781322979812178264318853202692827838675256569", "price": "0.278", "size": "33", "side": "BUY", "hash": "a6770659786c379d7474af3430629e5417dc1c91", "best_bid": "0.981", "best_ask": "0.99"}, {"asset_id": "27250410806992141952257033810710803403327848453310007128861669762666286354528", "price": "0.722", "size": "33", "side": "SELL", "hash": "442c44b8d5f7767446517ef7da331027691750e0", "best_bid": "0.01", "best_ask": "0.019"}], "timestamp": "1769384609833", "event_type": "price_change"}}
{"_local_timestamp": "2026-01-25T23:43:29.941696+00:00", "data": {"market": "0x1b7e6de8efe5f6a2c1ca2470e747370be89fe96270ccee85430bf18ac705a4e1", "price_changes": [{"asset_id": "94395860414009734926327544945762460944151569233112202400231598436537334220949", "price": "0.35", "size": "154", "side": "BUY", "hash": "5921eb467ed486ccccff351ba53902225aae7a70", "best_bid": "0.996", "best_ask": "0.998"}, {"asset_id": "86084595121347108808129382127322373721009228528241692453665189127555334452646", "price": "0.65", "size": "154", "side": "SELL", "hash": "255465329610e2a025db63806db11636b68647ce", "best_bid": "0.002", "best_ask": "0.004"}], "timestamp": "1769384609851", "event_type": "price_change"}}
{"_local_timestamp": "2026-01-25T23:43:29.967982+00:00", "data": {"market": "0x7d99e856ca49dcf748ff0072af624a65bafcb44a34b914b5a1466211674ae729", "price_changes": [{"asset_id": "17182810599901842221755643003911781322979812178264318853202692827838675256569", "price": "0.681", "size": "314", "side": "BUY", "hash": "419e95dc62e4b5a702edadb3d1ed64e056af75f5", "best_bid": "0.981", "best_ask": "0.99"}, {"asset_id": "27250410806992141952257033810710803403327848453310007128861669762666286354528", "price": "0.319", "size": "314", "side": "SELL", "hash": "6d8474c445b7c88db79bced1c2efa1328852be46", "best_bid": "0.01", "best_ask": "0.019"}], "timestamp": "1769384609873", "event_type": "price_change"}}
{"_local_timestamp": "2026-01-25T23:43:29.968915+00:00", "data": {"market": "0x7d99e856ca49dcf748ff0072af624a65bafcb44a34b914b5a1466211674ae729", "price_changes": [{"asset_id": "17182810599901842221755643003911781322979812178264318853202692827838675256569", "price": "0.681", "size": "344", "side": "BUY", "hash": "15912df573fcf7ec91314545252657bb8830f14e", "best_bid": "0.981", "best_ask": "0.99"}, {"asset_id": "27250410806992141952257033810710803403327848453310007128861669762666286354528", "price": "0.319", "size": "344", "side": "SELL", "hash": "ee7f3b3091617f6adbd6f762cce01eae25801779", "best_bid": "0.01", "best_ask": "0.019"}], "timestamp": "1769384609876", "event_type": "price_change"}}
{"_local_timestamp": "2026-01-25T23:43:30.019957+00:00", "data": {"market": "0x7d99e856ca49dcf748ff0072af624a65bafcb44a34b914b5a1466211674ae729", "price_changes": [{"asset_id": "17182810599901842221755643003911781322979812178264318853202692827838675256569", "price": "0.674", "size": "285", "side": "BUY", "hash": "99612ab3f8c0009991ba260a7395da91badb1144", "best_bid": "0.981", "best_ask": "0.99"}, {"asset_id": "27250410806992141952257033810710803403327848453310007128861669762666286354528", "price": "0.326", "size": "285", "side": "SELL", "hash": "ef72157f42c42e531a3b0b2d263575152e781668", "best_bid": "0.01", "best_ask": "0.019"}], "timestamp": "1769384609928", "event_type": "price_change"}}
{"_local_timestamp": "2026-01-25T23:43:30.258731+00:00", "data": {"market": "0x7d99e856ca49dcf748ff0072af624a65bafcb44a34b914b5a1466211674ae729", "price_changes": [{"asset_id": "17182810599901842221755643003911781322979812178264318853202692827838675256569", "price": "0.682", "size": "20", "side": "BUY", "hash": "b69e847a3b99a7f544d83daf36021e16e8577bfb", "best_bid": "0.981", "best_ask": "0.99"}, {"asset_id": "27250410806992141952257033810710803403327848453310007128861669762666286354528", "price": "0.318", "size": "20", "side": "SELL", "hash": "eda1e4cbf587c937e217bab3b3e94c5d3027adea", "best_bid": "0.01", "best_ask": "0.019"}], "timestamp": "1769384610158", "event_type": "price_change"}}
{"_local_timestamp": "2026-01-25T23:43:30.259307+00:00", "data": {"market": "0xb7ba5d2b34c3f78d2b483daa97bc301f7296a5d8658ba2851f4c912a161e5158", "price_changes": [{"asset_id": "32582994008069750117370770211161750379270178143252809024325448815129555714046", "price": "0.359", "size": "5", "side": "BUY", "hash": "56965c3469b7915f33f419d60dad03d5f16812c6", "best_bid": "0.952", "best_ask": "0.954"}, {"asset_id": "94207036547569786168949387588066196313734350858370522979598866565386642178169", "price": "0.641", "size": "5", "side": "SELL", "hash": "3e4cae26290c5fc2373701975f32c98e58c8f0b3", "best_bid": "0.046", "best_ask": "0.048"}], "timestamp": "1769384610155", "event_type": "price_change"}}
{"_local_timestamp": "2026-01-25T23:43:30.259786+00:00", "data": {"market": "0x7d99e856ca49dcf748ff0072af624a65bafcb44a34b914b5a1466211674ae729", "price_changes": [{"asset_id": "17182810599901842221755643003911781322979812178264318853202692827838675256569", "price": "0.682", "size": "166", "side": "BUY", "hash": "3a59cf61be8ade341230bb00cbff8c5b5a8c9e80", "best_bid": "0.981", "best_ask": "0.99"}, {"asset_id": "27250410806992141952257033810710803403327848453310007128861669762666286354528", "price": "0.318", "size": "166", "side": "SELL", "hash": "bb295930a645eda1af47515e4c3ba2aa58381df8", "best_bid": "0.01", "best_ask": "0.019"}], "timestamp": "1769384610161", "event_type": "price_change"}}
{"_local_timestamp": "2026-01-25T23:43:30.282523+00:00", "data": {"market": "0x7d99e856ca49dcf748ff0072af624a65bafcb44a34b914b5a1466211674ae729", "price_changes": [{"asset_id": "17182810599901842221755643003911781322979812178264318853202692827838675256569", "price": "0.674", "size": "0", "side": "BUY", "hash": "a694a98dd0399f5cbebcb198fd845de895127a45", "best_bid": "0.981", "best_ask": "0.99"}, {"asset_id": "27250410806992141952257033810710803403327848453310007128861669762666286354528", "price": "0.326", "size": "0", "side": "SELL", "hash": "4911e2b2b2b5bbac9a0db62c2be144c152fd5181", "best_bid": "0.01", "best_ask": "0.019"}], "timestamp": "1769384610184", "event_type": "price_change"}}
{"_local_timestamp": "2026-01-25T23:43:30.441997+00:00", "data": {"market": "0x7d99e856ca49dcf748ff0072af624a65bafcb44a34b914b5a1466211674ae729", "price_changes": [{"asset_id": "17182810599901842221755643003911781322979812178264318853202692827838675256569", "price": "0.278", "size": "0", "side": "BUY", "hash": "910ab1b1ed2ba5dda72a0a2c55e63cf7f4b29274", "best_bid": "0.981", "best_ask": "0.99"}, {"asset_id": "27250410806992141952257033810710803403327848453310007128861669762666286354528", "price": "0.722", "size": "0", "side": "SELL", "hash": "55c832dc6ac0380041e492b5d55ce9e54c714012", "best_bid": "0.01", "best_ask": "0.019"}], "timestamp": "1769384610354", "event_type": "price_change"}}
{"_local_timestamp": "2026-01-25T23:43:30.526848+00:00", "data": {"market": "0x7d99e856ca49dcf748ff0072af624a65bafcb44a34b914b5a1466211674ae729", "price_changes": [{"asset_id": "17182810599901842221755643003911781322979812178264318853202692827838675256569", "price": "0.681", "size": "30", "side": "BUY", "hash": "fd69d2ac38738ce5b35daeb0cc38a276fe822ba3", "best_bid": "0.981", "best_ask": "0.99"}, {"asset_id": "27250410806992141952257033810710803403327848453310007128861669762666286354528", "price": "0.319", "size": "30", "side": "SELL", "hash": "892d727d4b8a1a3bdd79edc15c2f1f2855309b88", "best_bid": "0.01", "best_ask": "0.019"}], "timestamp": "1769384610438", "event_type": "price_change"}}
{"_local_timestamp": "2026-01-25T23:43:30.642838+00:00", "data": {"market": "0x7d99e856ca49dcf748ff0072af624a65bafcb44a34b914b5a1466211674ae729", "price_changes": [{"asset_id": "17182810599901842221755643003911781322979812178264318853202692827838675256569", "price": "0.278", "size": "193", "side": "BUY", "hash": "be7de0e551ff70ced356e8ac531b308ff56eb8f9", "best_bid": "0.981", "best_ask": "0.99"}, {"asset_id": "27250410806992141952257033810710803403327848453310007128861669762666286354528", "price": "0.722", "size": "193", "side": "SELL", "hash": "1a3f6ec142fabaf9f7091e139e8ce71614f1669a", "best_bid": "0.01", "best_ask": "0.019"}], "timestamp": "1769384610546", "event_type": "price_change"}}
{"_local_timestamp": "2026-01-25T23:43:30.683093+00:00", "data": {"market": "0x7d99e856ca49dcf748ff0072af624a65bafcb44a34b914b5a1466211674ae729", "price_changes": [{"asset_id": "17182810599901842221755643003911781322979812178264318853202692827838675256569", "price": "0.278", "size": "393", "side": "BUY", "hash": "4afcb63fa02aa70e4c90be82a35d3dfa933fc4f6", "best_bid": "0.981", "best_ask": "0.99"}, {"asset_id": "27250410806992141952257033810710803403327848453310007128861669762666286354528", "price": "0.722", "size": "393", "side": "SELL", "hash": "8e403fad41054bf806df5a3897bb508feb8fdffa", "best_bid": "0.01", "best_ask": "0.019"}], "timestamp": "1769384610581", "event_type": "price_change"}}
{"_local_timestamp": "2026-01-25T23:43:31.631828+00:00", "data": {"market": "0x7d99e856ca49dcf748ff0072af624a65bafcb44a34b914b5a1466211674ae729", "price_changes": [{"asset_id": "17182810599901842221755643003911781322979812178264318853202692827838675256569", "price": "0.68", "size": "0", "side": "BUY", "hash": "708a8f459aab4bc97607f037a3e1e07bd4e6cbc4", "best_bid": "0.981", "best_ask": "0.99"}, {"asset_id": "27250410806992141952257033810710803403327848453310007128861669762666286354528", "price": "0.32", "size": "0", "side": "SELL", "hash": "12c74378c3126206b833250f35804e661c6d9350", "best_bid": "0.01", "best_ask": "0.019"}], "timestamp": "1769384611529", "event_type": "price_change"}}
{"_local_timestamp": "2026-01-25T23:43:31.648399+00:00", "data": {"market": "0x7d99e856ca49dcf748ff0072af624a65bafcb44a34b914b5a1466211674ae729", "price_changes": [{"asset_id": "17182810599901842221755643003911781322979812178264318853202692827838675256569", "price": "0.683", "size": "20", "side": "BUY", "hash": "309d8cc716b29ab70c0c35b6d05d37f048c7d92c", "best_bid": "0.981", "best_ask": "0.99"}, {"asset_id": "27250410806992141952257033810710803403327848453310007128861669762666286354528", "price": "0.317", "size": "20", "side": "SELL", "hash": "005318258b4ed56f6fefab55a00f80a74a19c4a4", "best_bid": "0.01", "best_ask": "0.019"}], "timestamp": "1769384611554", "event_type": "price_change"}}
{"_local_timestamp": "2026-01-25T23:44:12.973235+00:00", "data": {"market": "0xb7ba5d2b34c3f78d2b483daa97bc301f7296a5d8658ba2851f4c912a161e5158", "price_changes": [{"asset_id": "32582994008069750117370770211161750379270178143252809024325448815129555714046", "price": "0.359", "size": "0", "side": "BUY", "hash": "2beee509103b951c1398bcba6cd9842b46e00e51", "best_bid": "0.952", "best_ask": "0.954"}, {"asset_id": "94207036547569786168949387588066196313734350858370522979598866565386642178169", "price": "0.641", "size": "0", "side": "SELL", "hash": "1e61ca23e6f698317e13ba3515eac8b1b7da648d", "best_bid": "0.046", "best_ask": "0.048"}], "timestamp": "1769384652833", "event_type": "price_change"}}
{"_local_timestamp": "2026-01-25T23:44:13.357005+00:00", "data": {"market": "0xb7ba5d2b34c3f78d2b483daa97bc301f7296a5d8658ba2851f4c912a161e5158", "price_changes": [{"asset_id": "32582994008069750117370770211161750379270178143252809024325448815129555714046", "price": "0.359", "size": "5", "side": "BUY", "hash": "f2de2d21bc25a6d7971dcc14323ad97d817b78f3", "best_bid": "0.952", "best_ask": "0.954"}, {"asset_id": "94207036547569786168949387588066196313734350858370522979598866565386642178169", "price": "0.641", "size": "5", "side": "SELL", "hash": "e6757ce085ef065b238dd0c8c407385b194d4735", "best_bid": "0.046", "best_ask": "0.048"}], "timestamp": "1769384653214", "event_type": "price_change"}}
{"_local_timestamp": "2026-01-25T23:44:25.066497+00:00", "data": {"market": "0xb7ba5d2b34c3f78d2b483daa97bc301f7296a5d8658ba2851f4c912a161e5158", "price_changes": [{"asset_id": "32582994008069750117370770211161750379270178143252809024325448815129555714046", "price": "0.933", "size": "100", "side": "BUY", "hash": "cabec7de88cc7ef9bf3d6e0bafa0a9e475b0e09e", "best_bid": "0.952", "best_ask": "0.954"}, {"asset_id": "94207036547569786168949387588066196313734350858370522979598866565386642178169", "price": "0.067", "size": "100", "side": "SELL", "hash": "1d531b04cb61ba9d40d4f00ae0d0db6d4fba5f0b", "best_bid": "0.046", "best_ask": "0.048"}], "timestamp": "1769384664988", "event_type": "price_change"}}
{"_local_timestamp": "2026-01-25T23:44:25.067399+00:00", "data": {"market": "0xb7ba5d2b34c3f78d2b483daa97bc301f7296a5d8658ba2851f4c912a161e5158", "price_changes": [{"asset_id": "94207036547569786168949387588066196313734350858370522979598866565386642178169", "price": "0.027", "size": "100", "side": "BUY", "hash": "534bb8ef2cb604d9d3c214a74d177fcb47815ca7", "best_bid": "0.046", "best_ask": "0.048"}, {"asset_id": "32582994008069750117370770211161750379270178143252809024325448815129555714046", "price": "0.973", "size": "100", "side": "SELL", "hash": "7a4a451eeb874076e64a4015477ffa079f489483", "best_bid": "0.952", "best_ask": "0.954"}], "timestamp": "1769384664988", "event_type": "price_change"}}
{"_local_timestamp": "2026-01-25T23:44:57.877323+00:00", "data": {"market": "0xb7ba5d2b34c3f78d2b483daa97bc301f7296a5d8658ba2851f4c912a161e5158", "price_changes": [{"asset_id": "32582994008069750117370770211161750379270178143252809024325448815129555714046", "price": "0.359", "size": "0", "side": "BUY", "hash": "a66131743014c693858ba0697098fdfea1cf0faa", "best_bid": "0.952", "best_ask": "0.954"}, {"asset_id": "94207036547569786168949387588066196313734350858370522979598866565386642178169", "price": "0.641", "size": "0", "side": "SELL", "hash": "d8f17e97bbdd0c0ab86f2d2e091ac0e01c21573f", "best_bid": "0.046", "best_ask": "0.048"}], "timestamp": "1769384697777", "event_type": "price_change"}}
{"_local_timestamp": "2026-01-25T23:44:58.295442+00:00", "data": {"market": "0xb7ba5d2b34c3f78d2b483daa97bc301f7296a5d8658ba2851f4c912a161e5158", "price_changes": [{"asset_id": "32582994008069750117370770211161750379270178143252809024325448815129555714046", "price": "0.359", "size": "5", "side": "BUY", "hash": "67621664036e701f5550b1baab2f257409886c7a", "best_bid": "0.952", "best_ask": "0.954"}, {"asset_id": "94207036547569786168949387588066196313734350858370522979598866565386642178169", "price": "0.641", "size": "5", "side": "SELL", "hash": "9abe747aae5b488688530ec6662e8801668ab4be", "best_bid": "0.046", "best_ask": "0.048"}], "timestamp": "1769384698228", "event_type": "price_change"}}
{"_local_timestamp": "2026-01-25T23:45:28.310493+00:00", "data": {"market": "0xda86314ac2dd0f78ab1fe5b746840abeeff5be4e74c6d5bd5a0aada5c695030e", "price_changes": [{"asset_id": "83273939204150973203361658145419377967478532826191206101882322765481122431127", "price": "0.003", "size": "34.94", "side": "BUY", "hash": "0913110caab69d76e8f5754cb4ddcba2f1bde6c8", "best_bid": "0.008", "best_ask": "0.011"}, {"asset_id": "66466375160121808081218865320764245347163437070476088335272741711627298513873", "price": "0.997", "size": "34.94", "side": "SELL", "hash": "77beba1324a8c94cbae3a468a99a3597843a8e65", "best_bid": "0.989", "best_ask": "0.992"}], "timestamp": "1769384728247", "event_type": "price_change"}}
{"_local_timestamp": "2026-01-25T23:45:29.038819+00:00", "data": {"market": "0xda86314ac2dd0f78ab1fe5b746840abeeff5be4e74c6d5bd5a0aada5c695030e", "price_changes": [{"asset_id": "83273939204150973203361658145419377967478532826191206101882322765481122431127", "price": "0.004", "size": "48.75", "side": "BUY", "hash": "6d2237d882d273471aad0311ee66d012b0db6d66", "best_bid": "0.008", "best_ask": "0.011"}, {"asset_id": "66466375160121808081218865320764245347163437070476088335272741711627298513873", "price": "0.996", "size": "48.75", "side": "SELL", "hash": "ce4e977d4d0e94b17997b72e9c5ff2854feac3e3", "best_bid": "0.989", "best_ask": "0.992"}], "timestamp": "1769384728958", "event_type": "price_change"}}
{"_local_timestamp": "2026-01-25T23:45:33.050638+00:00", "data": {"market": "0x7d99e856ca49dcf748ff0072af624a65bafcb44a34b914b5a1466211674ae729", "price_changes": [{"asset_id": "27250410806992141952257033810710803403327848453310007128861669762666286354528", "price": "0.009", "size": "134", "side": "BUY", "hash": "4e47e95396b83173052ab5976a090823ce9afadf", "best_bid": "0.01", "best_ask": "0.019"}, {"asset_id": "17182810599901842221755643003911781322979812178264318853202692827838675256569", "price": "0.991", "size": "134", "side": "SELL", "hash": "18b137348fec699b1f8ff5607cefd8d929fa797d", "best_bid": "0.981", "best_ask": "0.99"}], "timestamp": "1769384732954", "event_type": "price_change"}}
{"_local_timestamp": "2026-01-25T23:45:33.335545+00:00", "data": {"market": "0x7d99e856ca49dcf748ff0072af624a65bafcb44a34b914b5a1466211674ae729", "price_changes": [{"asset_id": "27250410806992141952257033810710803403327848453310007128861669762666286354528", "price": "0.011", "size": "100", "side": "BUY", "hash": "c33616b10b6d6b3aeb24355e7365a027322e5968", "best_bid": "0.011", "best_ask": "0.019"}, {"asset_id": "17182810599901842221755643003911781322979812178264318853202692827838675256569", "price": "0.989", "size": "100", "side": "SELL", "hash": "6d3590ee8e40833cebf9ca3a081da7afddf75b60", "best_bid": "0.981", "best_ask": "0.989"}], "timestamp": "1769384733261", "event_type": "price_change"}}
{"_local_timestamp": "2026-01-25T23:45:33.546995+00:00", "data": {"market": "0xda86314ac2dd0f78ab1fe5b746840abeeff5be4e74c6d5bd5a0aada5c695030e", "price_changes": [{"asset_id": "66466375160121808081218865320764245347163437070476088335272741711627298513873", "price": "0.951", "size": "0", "side": "BUY", "hash": "c35b0f09b40ee694006fa281a1e695181b9dbfba", "best_bid": "0.989", "best_ask": "0.992"}, {"asset_id": "83273939204150973203361658145419377967478532826191206101882322765481122431127", "price": "0.049", "size": "0", "side": "SELL", "hash": "05ad81faee3de02af207869c288e41637d463cda", "best_bid": "0.008", "best_ask": "0.011"}], "timestamp": "1769384733477", "event_type": "price_change"}}
{"_local_timestamp": "2026-01-25T23:45:54.681634+00:00", "data": {"market": "0x1b7e6de8efe5f6a2c1ca2470e747370be89fe96270ccee85430bf18ac705a4e1", "price_changes": [{"asset_id": "94395860414009734926327544945762460944151569233112202400231598436537334220949", "price": "0.345", "size": "0", "side": "BUY", "hash": "e10a6a0c4bbe1f385f06c81d7aa7b011e78aa386", "best_bid": "0.996", "best_ask": "0.998"}, {"asset_id": "86084595121347108808129382127322373721009228528241692453665189127555334452646", "price": "0.655", "size": "0", "side": "SELL", "hash": "fd93268510ace412150b2343d5c5df3dba21b7ca", "best_bid": "0.002", "best_ask": "0.004"}], "timestamp": "1769384754615", "event_type": "price_change"}}
{"_local_timestamp": "2026-01-25T23:45:54.728329+00:00", "data": {"market": "0x1b7e6de8efe5f6a2c1ca2470e747370be89fe96270ccee85430bf18ac705a4e1", "price_changes": [{"asset_id": "94395860414009734926327544945762460944151569233112202400231598436537334220949", "price": "0.351", "size": "5", "side": "BUY", "hash": "ad47f7e3e507f4159524b372f536b4d1165ad1cb", "best_bid": "0.996", "best_ask": "0.998"}, {"asset_id": "86084595121347108808129382127322373721009228528241692453665189127555334452646", "price": "0.649", "size": "5", "side": "SELL", "hash": "e1964e1d495444e083d4e15f3acaf2f9bff0d370", "best_bid": "0.002", "best_ask": "0.004"}], "timestamp": "1769384754664", "event_type": "price_change"}}
{"_local_timestamp": "2026-01-25T23:45:54.810319+00:00", "data": {"market": "0xda86314ac2dd0f78ab1fe5b746840abeeff5be4e74c6d5bd5a0aada5c695030e", "price_changes": [{"asset_id": "66466375160121808081218865320764245347163437070476088335272741711627298513873", "price": "0.255", "size": "261", "side": "BUY", "hash": "62337860356f1cea1f3691edf60c32694577f0f2", "best_bid": "0.989", "best_ask": "0.992"}, {"asset_id": "83273939204150973203361658145419377967478532826191206101882322765481122431127", "price": "0.745", "size": "261", "side": "SELL", "hash": "6cfe1e475631ef1b8c2124468d13e0174aa10fb9", "best_bid": "0.008", "best_ask": "0.011"}], "timestamp": "1769384754749", "event_type": "price_change"}}
{"_local_timestamp": "2026-01-25T23:45:54.813075+00:00", "data": {"market": "0xda86314ac2dd0f78ab1fe5b746840abeeff5be4e74c6d5bd5a0aada5c695030e", "price_changes": [{"asset_id": "66466375160121808081218865320764245347163437070476088335272741711627298513873", "price": "0.951", "size": "20", "side": "BUY", "hash": "356b872c7bfa48b88a49e77fb4cdce20b9c796cb", "best_bid": "0.989", "best_ask": "0.992"}, {"asset_id": "83273939204150973203361658145419377967478532826191206101882322765481122431127", "price": "0.049", "size": "20", "side": "SELL", "hash": "48ddfc764779f350724e12877fb3c0ba09542787", "best_bid": "0.008", "best_ask": "0.011"}], "timestamp": "1769384754750", "event_type": "price_change"}}
{"_local_timestamp": "2026-01-25T23:45:54.836772+00:00", "data": {"market": "0xef62cae2f23eb9084db338cafc8ee88806bee54e3a92051689f70d6907b7f3cf", "price_changes": [{"asset_id": "86421436930838227408032705986280984822442451727936616356929369488596324752129", "price": "0.951", "size": "0", "side": "BUY", "hash": "6c7d6e6975c66b9034cf2ec643e91222f66fd8fb", "best_bid": "0.992", "best_ask": "0.995"}, {"asset_id": "48832045779017406406240960364495829307085252456810565554978796786740596106550", "price": "0.049", "size": "0", "side": "SELL", "hash": "cb95bd51de5fc4947984dca567a5ea4b6a40c937", "best_bid": "0.005", "best_ask": "0.008"}], "timestamp": "1769384754773", "event_type": "price_change"}}
{"_local_timestamp": "2026-01-25T23:45:54.980540+00:00", "data": {"market": "0x1b7e6de8efe5f6a2c1ca2470e747370be89fe96270ccee85430bf18ac705a4e1", "price_changes": [{"asset_id": "94395860414009734926327544945762460944151569233112202400231598436537334220949", "price": "0.951", "size": "0", "side": "BUY", "hash": "675eba37c3f549de3372461fb0a2f41f64092452", "best_bid": "0.996", "best_ask": "0.998"}, {"asset_id": "86084595121347108808129382127322373721009228528241692453665189127555334452646", "price": "0.049", "size": "0", "side": "SELL", "hash": "a93af0a1afd54d78e527f5b61d44df8496b8432e", "best_bid": "0.002", "best_ask": "0.004"}], "timestamp": "1769384754918", "event_type": "price_change"}}
{"_local_timestamp": "2026-01-25T23:45:56.484569+00:00", "data": {"market": "0x1b7e6de8efe5f6a2c1ca2470e747370be89fe96270ccee85430bf18ac705a4e1", "price_changes": [{"asset_id": "94395860414009734926327544945762460944151569233112202400231598436537334220949", "price": "0.348", "size": "0", "side": "BUY", "hash": "f61d2062525b7f49bd578ea13d428a6a106f4ade", "best_bid": "0.996", "best_ask": "0.998"}, {"asset_id": "86084595121347108808129382127322373721009228528241692453665189127555334452646", "price": "0.652", "size": "0", "side": "SELL", "hash": "7ce4c078ceb88fed1c2e0a5545736e2a5f04b63d", "best_bid": "0.002", "best_ask": "0.004"}], "timestamp": "1769384756081", "event_type": "price_change"}}
{"_local_timestamp": "2026-01-25T23:45:56.674019+00:00", "data": {"market": "0xb7ba5d2b34c3f78d2b483daa97bc301f7296a5d8658ba2851f4c912a161e5158", "price_changes": [{"asset_id": "32582994008069750117370770211161750379270178143252809024325448815129555714046", "price": "0.24", "size": "0", "side": "BUY", "hash": "f062fb032a2fc725f86982912b05fe7bf3f3d307", "best_bid": "0.952", "best_ask": "0.954"}, {"asset_id": "94207036547569786168949387588066196313734350858370522979598866565386642178169", "price": "0.76", "size": "0", "side": "SELL", "hash": "a1c7fca0e04ecaa133109e59b2c279d3825297e6", "best_bid": "0.046", "best_ask": "0.048"}], "timestamp": "1769384756083", "event_type": "price_change"}}
{"_local_timestamp": "2026-01-25T23:45:56.737357+00:00", "data": {"market": "0xda86314ac2dd0f78ab1fe5b746840abeeff5be4e74c6d5bd5a0aada5c695030e", "price_changes": [{"asset_id": "66466375160121808081218865320764245347163437070476088335272741711627298513873", "price": "0.252", "size": "0", "side": "BUY", "hash": "9c0e2f0dedd638041ef46219e6475d43354ae738", "best_bid": "0.989", "best_ask": "0.992"}, {"asset_id": "83273939204150973203361658145419377967478532826191206101882322765481122431127", "price": "0.748", "size": "0", "side": "SELL", "hash": "c4c45a706089737694ce5511efe2f9cad3ca1cd0", "best_bid": "0.008", "best_ask": "0.011"}], "timestamp": "1769384756075", "event_type": "price_change"}}
{"_local_timestamp": "2026-01-25T23:45:56.742685+00:00", "data": {"market": "0x7d99e856ca49dcf748ff0072af624a65bafcb44a34b914b5a1466211674ae729", "price_changes": [{"asset_id": "17182810599901842221755643003911781322979812178264318853202692827838675256569", "price": "0.276", "size": "0", "side": "BUY", "hash": "578ce44c2207fa151e94f3e3928e000c785fad15", "best_bid": "0.981", "best_ask": "0.989"}, {"asset_id": "27250410806992141952257033810710803403327848453310007128861669762666286354528", "price": "0.724", "size": "0", "side": "SELL", "hash": "3c5306bcc88a8f842d516887ed8872e60f034ba7", "best_bid": "0.011", "best_ask": "0.019"}], "timestamp": "1769384756093", "event_type": "price_change"}}
{"_local_timestamp": "2026-01-25T23:45:56.751368+00:00", "data": {"market": "0xef62cae2f23eb9084db338cafc8ee88806bee54e3a92051689f70d6907b7f3cf", "price_changes": [{"asset_id": "86421436930838227408032705986280984822442451727936616356929369488596324752129", "price": "0.237", "size": "0", "side": "BUY", "hash": "40793e41e6ee739e7c89aca1c474583b3658eec3", "best_bid": "0.992", "best_ask": "0.995"}, {"asset_id": "48832045779017406406240960364495829307085252456810565554978796786740596106550", "price": "0.763", "size": "0", "side": "SELL", "hash": "632298085146d3ec7d7e9352932edb3b75718832", "best_bid": "0.005", "best_ask": "0.008"}], "timestamp": "1769384756093", "event_type": "price_change"}}
{"_local_timestamp": "2026-01-25T23:45:57.262278+00:00", "data": {"market": "0xef62cae2f23eb9084db338cafc8ee88806bee54e3a92051689f70d6907b7f3cf", "price_changes": [{"asset_id": "86421436930838227408032705986280984822442451727936616356929369488596324752129", "price": "0.947", "size": "20", "side": "BUY", "hash": "e6b005058b9abab20e75e92baefcf7a58d702a32", "best_bid": "0.992", "best_ask": "0.995"}, {"asset_id": "48832045779017406406240960364495829307085252456810565554978796786740596106550", "price": "0.053", "size": "20", "side": "SELL", "hash": "f3f16832745895019473872819729ffc90af32b4", "best_bid": "0.005", "best_ask": "0.008"}], "timestamp": "1769384756856", "event_type": "price_change"}}
{"_local_timestamp": "2026-01-25T23:45:57.417450+00:00", "data": {"market": "0xef62cae2f23eb9084db338cafc8ee88806bee54e3a92051689f70d6907b7f3cf", "price_changes": [{"asset_id": "86421436930838227408032705986280984822442451727936616356929369488596324752129", "price": "0.948", "size": "20", "side": "BUY", "hash": "31b4a2cf4c416b152223cb24d2648a66c3ceb381", "best_bid": "0.992", "best_ask": "0.995"}, {"asset_id": "48832045779017406406240960364495829307085252456810565554978796786740596106550", "price": "0.052", "size": "20", "side": "SELL", "hash": "3cdfb7e8b7a7e38abdc4b9f8caf1b27437c64398", "best_bid": "0.005", "best_ask": "0.008"}], "timestamp": "1769384757292", "event_type": "price_change"}}
{"_local_timestamp": "2026-01-25T23:45:57.659076+00:00", "data": {"market": "0xef62cae2f23eb9084db338cafc8ee88806bee54e3a92051689f70d6907b7f3cf", "price_changes": [{"asset_id": "86421436930838227408032705986280984822442451727936616356929369488596324752129", "price": "0.947", "size": "0", "side": "BUY", "hash": "bdd711255d31170313c9f18313518f74a8bfeaef", "best_bid": "0.992", "best_ask": "0.995"}, {"asset_id": "48832045779017406406240960364495829307085252456810565554978796786740596106550", "price": "0.053", "size": "0", "side": "SELL", "hash": "4dc2ccfdbec72fd1a51beac12a392c1ca0829e5e", "best_bid": "0.005", "best_ask": "0.008"}], "timestamp": "1769384757593", "event_type": "price_change"}}
{"_local_timestamp": "2026-01-25T23:45:57.745998+00:00", "data": {"market": "0xef62cae2f23eb9084db338cafc8ee88806bee54e3a92051689f70d6907b7f3cf", "price_changes": [{"asset_id": "86421436930838227408032705986280984822442451727936616356929369488596324752129", "price": "0.948", "size": "40", "side": "BUY", "hash": "ea8ec69c7d5cbe78f705b45c374bba41ece9612b", "best_bid": "0.992", "best_ask": "0.995"}, {"asset_id": "48832045779017406406240960364495829307085252456810565554978796786740596106550", "price": "0.052", "size": "40", "side": "SELL", "hash": "4ebde16afab5f5bb96383b5e4c0af69f0bd0b6ce", "best_bid": "0.005", "best_ask": "0.008"}], "timestamp": "1769384757677", "event_type": "price_change"}}
{"_local_timestamp": "2026-01-25T23:45:58.148527+00:00", "data": {"market": "0xb7ba5d2b34c3f78d2b483daa97bc301f7296a5d8658ba2851f4c912a161e5158", "price_changes": [{"asset_id": "32582994008069750117370770211161750379270178143252809024325448815129555714046", "price": "0.359", "size": "0", "side": "BUY", "hash": "b88448800ae0140e2c2ce14ea1af9cf4ff0866dd", "best_bid": "0.952", "best_ask": "0.954"}, {"asset_id": "94207036547569786168949387588066196313734350858370522979598866565386642178169", "price": "0.641", "size": "0", "side": "SELL", "hash": "744f261d972bada563c8a04ef9b6499981e9add8", "best_bid": "0.046", "best_ask": "0.048"}], "timestamp": "1769384758074", "event_type": "price_change"}}
{"_local_timestamp": "2026-01-25T23:45:58.585354+00:00", "data": {"market": "0xb7ba5d2b34c3f78d2b483daa97bc301f7296a5d8658ba2851f4c912a161e5158", "price_changes": [{"asset_id": "32582994008069750117370770211161750379270178143252809024325448815129555714046", "price": "0.359", "size": "5", "side": "BUY", "hash": "14bd8970804fdace80dd96b3ee2c96464236ec8d", "best_bid": "0.952", "best_ask": "0.954"}, {"asset_id": "94207036547569786168949387588066196313734350858370522979598866565386642178169", "price": "0.641", "size": "5", "side": "SELL", "hash": "d2a6f7125bf4e183488b7eab8a0cf6ac12d5de0e", "best_bid": "0.046", "best_ask": "0.048"}], "timestamp": "1769384758510", "event_type": "price_change"}}
{"_local_timestamp": "2026-01-25T23:46:05.620091+00:00", "data": {"market": "0x7d99e856ca49dcf748ff0072af624a65bafcb44a34b914b5a1466211674ae729", "price_changes": [{"asset_id": "17182810599901842221755643003911781322979812178264318853202692827838675256569", "price": "0.279", "size": "196", "side": "BUY", "hash": "ffd13818101a0d47f5f148311f539e1d25135275", "best_bid": "0.981", "best_ask": "0.989"}, {"asset_id": "27250410806992141952257033810710803403327848453310007128861669762666286354528", "price": "0.721", "size": "196", "side": "SELL", "hash": "e28fdaa6c8cc5928086a5ae355742f2af82a7a5e", "best_bid": "0.011", "best_ask": "0.019"}], "timestamp": "1769384765548", "event_type": "price_change"}}
{"_local_timestamp": "2026-01-25T23:46:05.620877+00:00", "data": {"market": "0xda86314ac2dd0f78ab1fe5b746840abeeff5be4e74c6d5bd5a0aada5c695030e", "price_changes": [{"asset_id": "66466375160121808081218865320764245347163437070476088335272741711627298513873", "price": "0.255", "size": "561", "side": "BUY", "hash": "7c169edf2a16a203e7c7004d7bba5e51f73352ba", "best_bid": "0.989", "best_ask": "0.992"}, {"asset_id": "83273939204150973203361658145419377967478532826191206101882322765481122431127", "price": "0.745", "size": "561", "side": "SELL", "hash": "0f090137d1e7d50d0a77e94c8a3c24273641a4c2", "best_bid": "0.008", "best_ask": "0.011"}], "timestamp": "1769384765549", "event_type": "price_change"}}
{"_local_timestamp": "2026-01-25T23:46:05.621586+00:00", "data": {"market": "0xb7ba5d2b34c3f78d2b483daa97bc301f7296a5d8658ba2851f4c912a161e5158", "price_changes": [{"asset_id": "32582994008069750117370770211161750379270178143252809024325448815129555714046", "price": "0.242", "size": "300", "side": "BUY", "hash": "f7064d3ccd04289292466ea7c143f0f3a7c26cea", "best_bid": "0.952", "best_ask": "0.954"}, {"asset_id": "94207036547569786168949387588066196313734350858370522979598866565386642178169", "price": "0.758", "size": "300", "side": "SELL", "hash": "ac8f9f280c0da924d182821e73b210f524e60935", "best_bid": "0.046", "best_ask": "0.048"}], "timestamp": "1769384765549", "event_type": "price_change"}}
{"_local_timestamp": "2026-01-25T23:46:05.936995+00:00", "data": {"market": "0xef62cae2f23eb9084db338cafc8ee88806bee54e3a92051689f70d6907b7f3cf", "price_changes": [{"asset_id": "86421436930838227408032705986280984822442451727936616356929369488596324752129", "price": "0.24", "size": "300", "side": "BUY", "hash": "d055aa0ab7654287388ed8fadb4b90af07ee6f3e", "best_bid": "0.992", "best_ask": "0.995"}, {"asset_id": "48832045779017406406240960364495829307085252456810565554978796786740596106550", "price": "0.76", "size": "300", "side": "SELL", "hash": "9824731443878d886a0db2f8837bc4ab8e360c6f", "best_bid": "0.005", "best_ask": "0.008"}], "timestamp": "1769384765871", "event_type": "price_change"}}
{"_local_timestamp": "2026-01-25T23:46:05.941762+00:00", "data": {"market": "0x1b7e6de8efe5f6a2c1ca2470e747370be89fe96270ccee85430bf18ac705a4e1", "price_changes": [{"asset_id": "94395860414009734926327544945762460944151569233112202400231598436537334220949", "price": "0.351", "size": "82", "side": "BUY", "hash": "88abd7ec68f9546a362fb4d5d624d8b1f5397a75", "best_bid": "0.996", "best_ask": "0.998"}, {"asset_id": "86084595121347108808129382127322373721009228528241692453665189127555334452646", "price": "0.649", "size": "82", "side": "SELL", "hash": "d98f2fc08b834675f9b0dcc5e131f125371ed484", "best_bid": "0.002", "best_ask": "0.004"}], "timestamp": "1769384765872", "event_type": "price_change"}}
{"_local_timestamp": "2026-01-25T23:46:07.158301+00:00", "data": {"market": "0x7d99e856ca49dcf748ff0072af624a65bafcb44a34b914b5a1466211674ae729", "price_changes": [{"asset_id": "17182810599901842221755643003911781322979812178264318853202692827838675256569", "price": "0.021", "size": "5.33", "side": "BUY", "hash": "978e7deed2315723335cce99f2be26cd8b4e5ce4", "best_bid": "0.981", "best_ask": "0.989"}, {"asset_id": "27250410806992141952257033810710803403327848453310007128861669762666286354528", "price": "0.979", "size": "5.33", "side": "SELL", "hash": "aa890a740472a0252e2f145bbc7883cd7e27e849", "best_bid": "0.011", "best_ask": "0.019"}], "timestamp": "1769384767083", "event_type": "price_change"}}
{"_local_timestamp": "2026-01-25T23:46:07.558270+00:00", "data": {"market": "0x7d99e856ca49dcf748ff0072af624a65bafcb44a34b914b5a1466211674ae729", "price_changes": [{"asset_id": "17182810599901842221755643003911781322979812178264318853202692827838675256569", "price": "0.021", "size": "15.62", "side": "BUY", "hash": "de40ff291d50ba83f3863a3509b09506338f9948", "best_bid": "0.981", "best_ask": "0.989"}, {"asset_id": "27250410806992141952257033810710803403327848453310007128861669762666286354528", "price": "0.979", "size": "15.62", "side": "SELL", "hash": "866e6d7fcd4672270bdeda866c73544c5cff3bfb", "best_bid": "0.011", "best_ask": "0.019"}], "timestamp": "1769384767486", "event_type": "price_change"}}
{"_local_timestamp": "2026-01-25T23:46:08.455935+00:00", "data": {"market": "0x7d99e856ca49dcf748ff0072af624a65bafcb44a34b914b5a1466211674ae729", "price_changes": [{"asset_id": "17182810599901842221755643003911781322979812178264318853202692827838675256569", "price": "0.021", "size": "5.33", "side": "BUY", "hash": "da7624425c604b046b534fd297fb0414343de959", "best_bid": "0.981", "best_ask": "0.989"}, {"asset_id": "27250410806992141952257033810710803403327848453310007128861669762666286354528", "price": "0.979", "size": "5.33", "side": "SELL", "hash": "ba45c1473df2a6f46c519a03179d23e901a92837", "best_bid": "0.011", "best_ask": "0.019"}], "timestamp": "1769384768388", "event_type": "price_change"}}
{"_local_timestamp": "2026-01-25T23:46:08.819083+00:00", "data": {"market": "0x7d99e856ca49dcf748ff0072af624a65bafcb44a34b914b5a1466211674ae729", "price_changes": [{"asset_id": "17182810599901842221755643003911781322979812178264318853202692827838675256569", "price": "0.021", "size": "15.62", "side": "BUY", "hash": "a93864a6e48c205656d3c0e1fb325a9c81137b6e", "best_bid": "0.981", "best_ask": "0.989"}, {"asset_id": "27250410806992141952257033810710803403327848453310007128861669762666286354528", "price": "0.979", "size": "15.62", "side": "SELL", "hash": "912f0fe1150a6a8f77c7e9eb0916bea11f581f6c", "best_bid": "0.011", "best_ask": "0.019"}], "timestamp": "1769384768756", "event_type": "price_change"}}
{"_local_timestamp": "2026-01-25T23:46:34.728964+00:00", "data": {"market": "0x7d99e856ca49dcf748ff0072af624a65bafcb44a34b914b5a1466211674ae729", "price_changes": [{"asset_id": "27250410806992141952257033810710803403327848453310007128861669762666286354528", "price": "0.002", "size": "1100", "side": "BUY", "hash": "16c1c8d9a461320e72f23b7909c466a41d70d700", "best_bid": "0.011", "best_ask": "0.019"}, {"asset_id": "17182810599901842221755643003911781322979812178264318853202692827838675256569", "price": "0.998", "size": "1100", "side": "SELL", "hash": "41b93c20e4ed5cab2edfeb37b78a8c5707aa0ad8", "best_bid": "0.981", "best_ask": "0.989"}], "timestamp": "1769384794653", "event_type": "price_change"}}
{"_local_timestamp": "2026-01-25T23:46:34.729717+00:00", "data": {"market": "0x7d99e856ca49dcf748ff0072af624a65bafcb44a34b914b5a1466211674ae729", "price_changes": [{"asset_id": "27250410806992141952257033810710803403327848453310007128861669762666286354528", "price": "0.003", "size": "350", "side": "BUY", "hash": "16c1c8d9a461320e72f23b7909c466a41d70d700", "best_bid": "0.011", "best_ask": "0.019"}, {"asset_id": "17182810599901842221755643003911781322979812178264318853202692827838675256569", "price": "0.997", "size": "350", "side": "SELL", "hash": "41b93c20e4ed5cab2edfeb37b78a8c5707aa0ad8", "best_bid": "0.981", "best_ask": "0.989"}], "timestamp": "1769384794653", "event_type": "price_change"}}
{"_local_timestamp": "2026-01-25T23:46:34.730273+00:00", "data": {"market": "0x7d99e856ca49dcf748ff0072af624a65bafcb44a34b914b5a1466211674ae729", "price_changes": [{"asset_id": "27250410806992141952257033810710803403327848453310007128861669762666286354528", "price": "0.004", "size": "100", "side": "BUY", "hash": "16c1c8d9a461320e72f23b7909c466a41d70d700", "best_bid": "0.011", "best_ask": "0.019"}, {"asset_id": "17182810599901842221755643003911781322979812178264318853202692827838675256569", "price": "0.996", "size": "100", "side": "SELL", "hash": "41b93c20e4ed5cab2edfeb37b78a8c5707aa0ad8", "best_bid": "0.981", "best_ask": "0.989"}], "timestamp": "1769384794653", "event_type": "price_change"}}
{"_local_timestamp": "2026-01-25T23:46:34.730876+00:00", "data": {"market": "0x7d99e856ca49dcf748ff0072af624a65bafcb44a34b914b5a1466211674ae729", "price_changes": [{"asset_id": "27250410806992141952257033810710803403327848453310007128861669762666286354528", "price": "0.005", "size": "100", "side": "BUY", "hash": "16c1c8d9a461320e72f23b7909c466a41d70d700", "best_bid": "0.011", "best_ask": "0.019"}, {"asset_id": "17182810599901842221755643003911781322979812178264318853202692827838675256569", "price": "0.995", "size": "100", "side": "SELL", "hash": "41b93c20e4ed5cab2edfeb37b78a8c5707aa0ad8", "best_bid": "0.981", "best_ask": "0.989"}], "timestamp": "1769384794653", "event_type": "price_change"}}
{"_local_timestamp": "2026-01-25T23:46:34.743235+00:00", "data": {"market": "0x7d99e856ca49dcf748ff0072af624a65bafcb44a34b914b5a1466211674ae729", "price_changes": [{"asset_id": "27250410806992141952257033810710803403327848453310007128861669762666286354528", "price": "0.006", "size": "100", "side": "BUY", "hash": "16c1c8d9a461320e72f23b7909c466a41d70d700", "best_bid": "0.011", "best_ask": "0.019"}, {"asset_id": "17182810599901842221755643003911781322979812178264318853202692827838675256569", "price": "0.994", "size": "100", "side": "SELL", "hash": "41b93c20e4ed5cab2edfeb37b78a8c5707aa0ad8", "best_bid": "0.981", "best_ask": "0.989"}], "timestamp": "1769384794653", "event_type": "price_change"}}
{"_local_timestamp": "2026-01-25T23:46:34.823198+00:00", "data": {"market": "0x1b7e6de8efe5f6a2c1ca2470e747370be89fe96270ccee85430bf18ac705a4e1", "price_changes": [{"asset_id": "94395860414009734926327544945762460944151569233112202400231598436537334220949", "price": "0.948", "size": "0", "side": "BUY", "hash": "fd3c83d1870a1d80452aaa5f22ca0db13212b783", "best_bid": "0.996", "best_ask": "0.998"}, {"asset_id": "86084595121347108808129382127322373721009228528241692453665189127555334452646", "price": "0.052", "size": "0", "side": "SELL", "hash": "51c48be84b27009ea3bfc65b50ffca810ece3e3a", "best_bid": "0.002", "best_ask": "0.004"}], "timestamp": "1769384794749", "event_type": "price_change"}}
{"_local_timestamp": "2026-01-25T23:46:34.947604+00:00", "data": {"market": "0x1b7e6de8efe5f6a2c1ca2470e747370be89fe96270ccee85430bf18ac705a4e1", "price_changes": [{"asset_id": "94395860414009734926327544945762460944151569233112202400231598436537334220949", "price": "0.951", "size": "30", "side": "BUY", "hash": "04eae143fa9f1c3b9c7bfcfce6fa6986e4422cb5", "best_bid": "0.996", "best_ask": "0.998"}, {"asset_id": "86084595121347108808129382127322373721009228528241692453665189127555334452646", "price": "0.049", "size": "30", "side": "SELL", "hash": "259df82bce95d04551cae5685f99b3f3b1f5ab71", "best_bid": "0.002", "best_ask": "0.004"}], "timestamp": "1769384794867", "event_type": "price_change"}}
{"_local_timestamp": "2026-01-25T23:46:34.948249+00:00", "data": {"market": "0x1b7e6de8efe5f6a2c1ca2470e747370be89fe96270ccee85430bf18ac705a4e1", "price_changes": [{"asset_id": "94395860414009734926327544945762460944151569233112202400231598436537334220949", "price": "0.925", "size": "363", "side": "BUY", "hash": "9c816821cfa7aa455de47d97430b0d0cdc775685", "best_bid": "0.996", "best_ask": "0.998"}, {"asset_id": "86084595121347108808129382127322373721009228528241692453665189127555334452646", "price": "0.075", "size": "363", "side": "SELL", "hash": "dee4048e1e046d8acf8268cbbae6193374621fd7", "best_bid": "0.002", "best_ask": "0.004"}], "timestamp": "1769384794868", "event_type": "price_change"}}
{"_local_timestamp": "2026-01-25T23:46:34.982489+00:00", "data": {"market": "0x1b7e6de8efe5f6a2c1ca2470e747370be89fe96270ccee85430bf18ac705a4e1", "price_changes": [{"asset_id": "94395860414009734926327544945762460944151569233112202400231598436537334220949", "price": "0.35", "size": "90", "side": "BUY", "hash": "34cd39cf4e5458d6d9fc84645b65c079937169cc", "best_bid": "0.996", "best_ask": "0.998"}, {"asset_id": "86084595121347108808129382127322373721009228528241692453665189127555334452646", "price": "0.65", "size": "90", "side": "SELL", "hash": "75e822a4ea4635ad6d5d48644bdc139f5b606045", "best_bid": "0.002", "best_ask": "0.004"}], "timestamp": "1769384794907", "event_type": "price_change"}}
{"_local_timestamp": "2026-01-25T23:46:35.047108+00:00", "data": {"market": "0x1b7e6de8efe5f6a2c1ca2470e747370be89fe96270ccee85430bf18ac705a4e1", "price_changes": [{"asset_id": "94395860414009734926327544945762460944151569233112202400231598436537334220949", "price": "0.952", "size": "20", "side": "BUY", "hash": "78d112c2a56c1246ea60bbd2135701937bc8a0dc", "best_bid": "0.996", "best_ask": "0.998"}, {"asset_id": "86084595121347108808129382127322373721009228528241692453665189127555334452646", "price": "0.048", "size": "20", "side": "SELL", "hash": "f9a1e8b986df0a93b94da9eee57ab518415c7e22", "best_bid": "0.002", "best_ask": "0.004"}], "timestamp": "1769384794974", "event_type": "price_change"}}
{"_local_timestamp": "2026-01-25T23:46:35.052044+00:00", "data": {"market": "0x1b7e6de8efe5f6a2c1ca2470e747370be89fe96270ccee85430bf18ac705a4e1", "price_changes": [{"asset_id": "94395860414009734926327544945762460944151569233112202400231598436537334220949", "price": "0.35", "size": "23", "side": "BUY", "hash": "fbd65264b01b117e09fcb3459033c90e99e17699", "best_bid": "0.996", "best_ask": "0.998"}, {"asset_id": "86084595121347108808129382127322373721009228528241692453665189127555334452646", "price": "0.65", "size": "23", "side": "SELL", "hash": "c2b4ed0144bc0ef82c423b22df2fc8eb910b4add", "best_bid": "0.002", "best_ask": "0.004"}], "timestamp": "1769384794981", "event_type": "price_change"}}
{"_local_timestamp": "2026-01-25T23:46:35.159057+00:00", "data": {"market": "0x1b7e6de8efe5f6a2c1ca2470e747370be89fe96270ccee85430bf18ac705a4e1", "price_changes": [{"asset_id": "94395860414009734926327544945762460944151569233112202400231598436537334220949", "price": "0.35", "size": "0", "side": "BUY", "hash": "2f4b308ca3db8ce412d1d442d132ae2a40bc9846", "best_bid": "0.996", "best_ask": "0.998"}, {"asset_id": "86084595121347108808129382127322373721009228528241692453665189127555334452646", "price": "0.65", "size": "0", "side": "SELL", "hash": "2c2127f568443b1f8d45b39804d5fb010ce58e87", "best_bid": "0.002", "best_ask": "0.004"}], "timestamp": "1769384795086", "event_type": "price_change"}}
{"_local_timestamp": "2026-01-25T23:46:35.192710+00:00", "data": {"market": "0x7d99e856ca49dcf748ff0072af624a65bafcb44a34b914b5a1466211674ae729", "price_changes": [{"asset_id": "27250410806992141952257033810710803403327848453310007128861669762666286354528", "price": "0.003", "size": "369.23", "side": "BUY", "hash": "7b29265b07e033fcf7879e10c5aa369527faf0f7", "best_bid": "0.011", "best_ask": "0.019"}, {"asset_id": "17182810599901842221755643003911781322979812178264318853202692827838675256569", "price": "0.997", "size": "369.23", "side": "SELL", "hash": "f6d84ad650e59b312b7b5fc21d49cc6f898fec2d", "best_bid": "0.981", "best_ask": "0.989"}], "timestamp": "1769384795114", "event_type": "price_change"}}
{"_local_timestamp": "2026-01-25T23:46:35.193354+00:00", "data": {"market": "0x7d99e856ca49dcf748ff0072af624a65bafcb44a34b914b5a1466211674ae729", "price_changes": [{"asset_id": "27250410806992141952257033810710803403327848453310007128861669762666286354528", "price": "0.006", "size": "109.47", "side": "BUY", "hash": "69df1217fba4650f3f721a9b69f92a86d84c5428", "best_bid": "0.011", "best_ask": "0.019"}, {"asset_id": "17182810599901842221755643003911781322979812178264318853202692827838675256569", "price": "0.994", "size": "109.47", "side": "SELL", "hash": "a9b62ebe65a37bbd38a28870ae9d5ca6103ace27", "best_bid": "0.981", "best_ask": "0.989"}], "timestamp": "1769384795117", "event_type": "price_change"}}
{"_local_timestamp": "2026-01-25T23:46:35.193951+00:00", "data": {"market": "0x7d99e856ca49dcf748ff0072af624a65bafcb44a34b914b5a1466211674ae729", "price_changes": [{"asset_id": "27250410806992141952257033810710803403327848453310007128861669762666286354528", "price": "0.008", "size": "163.37", "side": "BUY", "hash": "0d5fcbfa3933b454001c2494efe060d9e810edd4", "best_bid": "0.011", "best_ask": "0.019"}, {"asset_id": "17182810599901842221755643003911781322979812178264318853202692827838675256569", "price": "0.992", "size": "163.37", "side": "SELL", "hash": "a13c5c20d5ab8440fab1b696be5009eda10991c4", "best_bid": "0.981", "best_ask": "0.989"}], "timestamp": "1769384795118", "event_type": "price_change"}}
{"_local_timestamp": "2026-01-25T23:46:35.194612+00:00", "data": {"market": "0x7d99e856ca49dcf748ff0072af624a65bafcb44a34b914b5a1466211674ae729", "price_changes": [{"asset_id": "27250410806992141952257033810710803403327848453310007128861669762666286354528", "price": "0.004", "size": "114.35", "side": "BUY", "hash": "d6ceef06d2a4ae31cf7cb482a74fd2308806e948", "best_bid": "0.011", "best_ask": "0.019"}, {"asset_id": "17182810599901842221755643003911781322979812178264318853202692827838675256569", "price": "0.996", "size": "114.35", "side": "SELL", "hash": "8c4e476323de785bdbda148b37dad64e1ac08e53", "best_bid": "0.981", "best_ask": "0.989"}], "timestamp": "1769384795119", "event_type": "price_change"}}
{"_local_timestamp": "2026-01-25T23:46:35.195189+00:00", "data": {"market": "0x7d99e856ca49dcf748ff0072af624a65bafcb44a34b914b5a1466211674ae729", "price_changes": [{"asset_id": "27250410806992141952257033810710803403327848453310007128861669762666286354528", "price": "0.002", "size": "1129", "side": "BUY", "hash": "e09072867894ca427a684d33da23963565dea4df", "best_bid": "0.011", "best_ask": "0.019"}, {"asset_id": "17182810599901842221755643003911781322979812178264318853202692827838675256569", "price": "0.998", "size": "1129", "side": "SELL", "hash": "5a6452c18ee9c0939f5bc5ffe8149f1477512e91", "best_bid": "0.981", "best_ask": "0.989"}], "timestamp": "1769384795120", "event_type": "price_change"}}
{"_local_timestamp": "2026-01-25T23:46:35.195801+00:00", "data": {"market": "0x7d99e856ca49dcf748ff0072af624a65bafcb44a34b914b5a1466211674ae729", "price_changes": [{"asset_id": "27250410806992141952257033810710803403327848453310007128861669762666286354528", "price": "0.007", "size": "108.08", "side": "BUY", "hash": "5daefc41393fcb87cc3224c57e1fbcfb239b30f5", "best_bid": "0.011", "best_ask": "0.019"}, {"asset_id": "17182810599901842221755643003911781322979812178264318853202692827838675256569", "price": "0.993", "size": "108.08", "side": "SELL", "hash": "7398d8f79faec8abed205cb30f66f71183dbf990", "best_bid": "0.981", "best_ask": "0.989"}], "timestamp": "1769384795122", "event_type": "price_change"}}
{"_local_timestamp": "2026-01-25T23:46:35.206982+00:00", "data": {"market": "0x7d99e856ca49dcf748ff0072af624a65bafcb44a34b914b5a1466211674ae729", "price_changes": [{"asset_id": "27250410806992141952257033810710803403327848453310007128861669762666286354528", "price": "0.005", "size": "111.42", "side": "BUY", "hash": "170930b059dd4e28bb0403128ec13f0ffc2fdbc5", "best_bid": "0.011", "best_ask": "0.019"}, {"asset_id": "17182810599901842221755643003911781322979812178264318853202692827838675256569", "price": "0.995", "size": "111.42", "side": "SELL", "hash": "894f6bd00014d18e48330701712c73251194024e", "best_bid": "0.981", "best_ask": "0.989"}], "timestamp": "1769384795123", "event_type": "price_change"}}
{"_local_timestamp": "2026-01-25T23:46:35.504829+00:00", "data": {"market": "0x1b7e6de8efe5f6a2c1ca2470e747370be89fe96270ccee85430bf18ac705a4e1", "price_changes": [{"asset_id": "94395860414009734926327544945762460944151569233112202400231598436537334220949", "price": "0.925", "size": "0", "side": "BUY", "hash": "8d9efb084fec42440095d8c8892c0040e666e72e", "best_bid": "0.996", "best_ask": "0.998"}, {"asset_id": "86084595121347108808129382127322373721009228528241692453665189127555334452646", "price": "0.075", "size": "0", "side": "SELL", "hash": "14b2e8bf2f919849985fb81e8b6d269df1e926c5", "best_bid": "0.002", "best_ask": "0.004"}], "timestamp": "1769384795433", "event_type": "price_change"}}
{"_local_timestamp": "2026-01-25T23:46:35.563019+00:00", "data": {"market": "0x1b7e6de8efe5f6a2c1ca2470e747370be89fe96270ccee85430bf18ac705a4e1", "price_changes": [{"asset_id": "94395860414009734926327544945762460944151569233112202400231598436537334220949", "price": "0.35", "size": "126", "side": "BUY", "hash": "6ad63d4f9aea0f37d077c1bc3c3a01ef5dd8eb3f", "best_bid": "0.996", "best_ask": "0.998"}, {"asset_id": "86084595121347108808129382127322373721009228528241692453665189127555334452646", "price": "0.65", "size": "126", "side": "SELL", "hash": "0efab629904b7b7595e00c792bddde28ad77d0a2", "best_bid": "0.002", "best_ask": "0.004"}], "timestamp": "1769384795486", "event_type": "price_change"}}
{"_local_timestamp": "2026-01-25T23:46:35.641078+00:00", "data": {"market": "0x1b7e6de8efe5f6a2c1ca2470e747370be89fe96270ccee85430bf18ac705a4e1", "price_changes": [{"asset_id": "94395860414009734926327544945762460944151569233112202400231598436537334220949", "price": "0.35", "size": "256", "side": "BUY", "hash": "8108984863396987212f86d2b0fb2feffa80b613", "best_bid": "0.996", "best_ask": "0.998"}, {"asset_id": "86084595121347108808129382127322373721009228528241692453665189127555334452646", "price": "0.65", "size": "256", "side": "SELL", "hash": "d7312891761ea7d71f86bbbf9f6ed49301a81b81", "best_bid": "0.002", "best_ask": "0.004"}], "timestamp": "1769384795561", "event_type": "price_change"}}
{"_local_timestamp": "2026-01-25T23:46:57.836779+00:00", "data": {"market": "0xb7ba5d2b34c3f78d2b483daa97bc301f7296a5d8658ba2851f4c912a161e5158", "price_changes": [{"asset_id": "32582994008069750117370770211161750379270178143252809024325448815129555714046", "price": "0.359", "size": "0", "side": "BUY", "hash": "446dc41840e628f61f889218529dd63e5f7a920c", "best_bid": "0.952", "best_ask": "0.954"}, {"asset_id": "94207036547569786168949387588066196313734350858370522979598866565386642178169", "price": "0.641", "size": "0", "side": "SELL", "hash": "504ff69a3b3aae33c6025564d0f2a33693296a5a", "best_bid": "0.046", "best_ask": "0.048"}], "timestamp": "1769384817769", "event_type": "price_change"}}
{"_local_timestamp": "2026-01-25T23:46:58.265787+00:00", "data": {"market": "0xb7ba5d2b34c3f78d2b483daa97bc301f7296a5d8658ba2851f4c912a161e5158", "price_changes": [{"asset_id": "32582994008069750117370770211161750379270178143252809024325448815129555714046", "price": "0.359", "size": "5", "side": "BUY", "hash": "0a45e52e6307ba8cdf22ef3bb66301783b24fff4", "best_bid": "0.952", "best_ask": "0.954"}, {"asset_id": "94207036547569786168949387588066196313734350858370522979598866565386642178169", "price": "0.641", "size": "5", "side": "SELL", "hash": "a5e20de9b4fca0a5d209ebc6c435d802d605ac99", "best_bid": "0.046", "best_ask": "0.048"}], "timestamp": "1769384818197", "event_type": "price_change"}}
{"_local_timestamp": "2026-01-25T23:47:55.609506+00:00", "data": {"market": "0xb7ba5d2b34c3f78d2b483daa97bc301f7296a5d8658ba2851f4c912a161e5158", "price_changes": [{"asset_id": "32582994008069750117370770211161750379270178143252809024325448815129555714046", "price": "0.241", "size": "0", "side": "BUY", "hash": "bbcb16676d0aeef5f2b30cca2540e22f8afb227a", "best_bid": "0.952", "best_ask": "0.954"}, {"asset_id": "94207036547569786168949387588066196313734350858370522979598866565386642178169", "price": "0.759", "size": "0", "side": "SELL", "hash": "272de81e6e20ed27ade62a8f47d371bf72afca08", "best_bid": "0.046", "best_ask": "0.048"}], "timestamp": "1769384875413", "event_type": "price_change"}}
{"_local_timestamp": "2026-01-25T23:47:55.775990+00:00", "data": {"market": "0xda86314ac2dd0f78ab1fe5b746840abeeff5be4e74c6d5bd5a0aada5c695030e", "price_changes": [{"asset_id": "66466375160121808081218865320764245347163437070476088335272741711627298513873", "price": "0.254", "size": "787", "side": "BUY", "hash": "c67b4d6ca341cbe9f4bd1b5742d3f5acb75bb14e", "best_bid": "0.989", "best_ask": "0.992"}, {"asset_id": "83273939204150973203361658145419377967478532826191206101882322765481122431127", "price": "0.746", "size": "787", "side": "SELL", "hash": "e9c92f92be10683b049c8c0b859da6776619fab9", "best_bid": "0.008", "best_ask": "0.011"}], "timestamp": "1769384875642", "event_type": "price_change"}}
{"_local_timestamp": "2026-01-25T23:47:55.837312+00:00", "data": {"market": "0xef62cae2f23eb9084db338cafc8ee88806bee54e3a92051689f70d6907b7f3cf", "price_changes": [{"asset_id": "86421436930838227408032705986280984822442451727936616356929369488596324752129", "price": "0.95", "size": "0", "side": "BUY", "hash": "3c6ea6e8e7314c70ffaf778b6cd2c401fd73a486", "best_bid": "0.992", "best_ask": "0.995"}, {"asset_id": "48832045779017406406240960364495829307085252456810565554978796786740596106550", "price": "0.05", "size": "0", "side": "SELL", "hash": "7f725d2bc412c885c6980d90d52c4dca66546afa", "best_bid": "0.005", "best_ask": "0.008"}], "timestamp": "1769384875731", "event_type": "price_change"}}
{"_local_timestamp": "2026-01-25T23:47:55.861326+00:00", "data": {"market": "0xda86314ac2dd0f78ab1fe5b746840abeeff5be4e74c6d5bd5a0aada5c695030e", "price_changes": [{"asset_id": "66466375160121808081218865320764245347163437070476088335272741711627298513873", "price": "0.255", "size": "300", "side": "BUY", "hash": "ed8f6190242e53f5ae1f5cb1a65efd773840826c", "best_bid": "0.989", "best_ask": "0.992"}, {"asset_id": "83273939204150973203361658145419377967478532826191206101882322765481122431127", "price": "0.745", "size": "300", "side": "SELL", "hash": "23cb6c95ad63fa17f65b69ad05c1e2f8bad858cb", "best_bid": "0.008", "best_ask": "0.011"}], "timestamp": "1769384875765", "event_type": "price_change"}}
{"_local_timestamp": "2026-01-25T23:47:56.005788+00:00", "data": {"market": "0x7d99e856ca49dcf748ff0072af624a65bafcb44a34b914b5a1466211674ae729", "price_changes": [{"asset_id": "17182810599901842221755643003911781322979812178264318853202692827838675256569", "price": "0.682", "size": "146", "side": "BUY", "hash": "4278c4de51b8d8b1bcff61bd8fa679069d7b93ce", "best_bid": "0.981", "best_ask": "0.989"}, {"asset_id": "27250410806992141952257033810710803403327848453310007128861669762666286354528", "price": "0.318", "size": "146", "side": "SELL", "hash": "4b37261252e6b447988a08c8a99385e0f8f2ccf3", "best_bid": "0.011", "best_ask": "0.019"}], "timestamp": "1769384875935", "event_type": "price_change"}}
{"_local_timestamp": "2026-01-25T23:47:56.707844+00:00", "data": {"market": "0x7d99e856ca49dcf748ff0072af624a65bafcb44a34b914b5a1466211674ae729", "price_changes": [{"asset_id": "17182810599901842221755643003911781322979812178264318853202692827838675256569", "price": "0.676", "size": "0", "side": "BUY", "hash": "6e9dee2f3b0e776356d78ae964f6bcdf43a879e7", "best_bid": "0.981", "best_ask": "0.989"}, {"asset_id": "27250410806992141952257033810710803403327848453310007128861669762666286354528", "price": "0.324", "size": "0", "side": "SELL", "hash": "28b98e62bfeb424f07b12ecd98e8f2e05c86d0da", "best_bid": "0.011", "best_ask": "0.019"}], "timestamp": "1769384876639", "event_type": "price_change"}}
{"_local_timestamp": "2026-01-25T23:47:56.708525+00:00", "data": {"market": "0xda86314ac2dd0f78ab1fe5b746840abeeff5be4e74c6d5bd5a0aada5c695030e", "price_changes": [{"asset_id": "66466375160121808081218865320764245347163437070476088335272741711627298513873", "price": "0.254", "size": "0", "side": "BUY", "hash": "bc139117912aeec00e1dbfc263251b7498674d91", "best_bid": "0.989", "best_ask": "0.992"}, {"asset_id": "83273939204150973203361658145419377967478532826191206101882322765481122431127", "price": "0.746", "size": "0", "side": "SELL", "hash": "7c04d440fa1a16d9f82e662f8955e8d007dfc6c9", "best_bid": "0.008", "best_ask": "0.011"}], "timestamp": "1769384876639", "event_type": "price_change"}}
{"_local_timestamp": "2026-01-25T23:47:57.234178+00:00", "data": {"market": "0x7d99e856ca49dcf748ff0072af624a65bafcb44a34b914b5a1466211674ae729", "price_changes": [{"asset_id": "17182810599901842221755643003911781322979812178264318853202692827838675256569", "price": "0.684", "size": "20", "side": "BUY", "hash": "0137d0c7d6300ba81b1212af5faf2d2bd9f598b1", "best_bid": "0.981", "best_ask": "0.989"}, {"asset_id": "27250410806992141952257033810710803403327848453310007128861669762666286354528", "price": "0.316", "size": "20", "side": "SELL", "hash": "b44fd503ac21c5fa28c146e65753d8c4026e885e", "best_bid": "0.011", "best_ask": "0.019"}], "timestamp": "1769384877096", "event_type": "price_change"}}
{"_local_timestamp": "2026-01-25T23:47:58.972711+00:00", "data": {"market": "0x7d99e856ca49dcf748ff0072af624a65bafcb44a34b914b5a1466211674ae729", "price_changes": [{"asset_id": "17182810599901842221755643003911781322979812178264318853202692827838675256569", "price": "0.683", "size": "0", "side": "BUY", "hash": "b7aff3a142ca2789512b33faa6ecd41b856faba9", "best_bid": "0.981", "best_ask": "0.989"}, {"asset_id": "27250410806992141952257033810710803403327848453310007128861669762666286354528", "price": "0.317", "size": "0", "side": "SELL", "hash": "6a5729c62dad030566f2402967b9e14865f55eb8", "best_bid": "0.011", "best_ask": "0.019"}], "timestamp": "1769384878909", "event_type": "price_change"}}
{"_local_timestamp": "2026-01-25T23:47:58.996479+00:00", "data": {"market": "0x7d99e856ca49dcf748ff0072af624a65bafcb44a34b914b5a1466211674ae729", "price_changes": [{"asset_id": "17182810599901842221755643003911781322979812178264318853202692827838675256569", "price": "0.685", "size": "20", "side": "BUY", "hash": "44d8ae2bb4e78945dd2629cb07be2fa793f56c7e", "best_bid": "0.981", "best_ask": "0.989"}, {"asset_id": "27250410806992141952257033810710803403327848453310007128861669762666286354528", "price": "0.315", "size": "20", "side": "SELL", "hash": "3da330fd9ed83a3f18d75bf814d5449a63a0056d", "best_bid": "0.011", "best_ask": "0.019"}], "timestamp": "1769384878936", "event_type": "price_change"}}
{"_local_timestamp": "2026-01-25T23:48:00.958278+00:00", "data": {"market": "0xb7ba5d2b34c3f78d2b483daa97bc301f7296a5d8658ba2851f4c912a161e5158", "price_changes": [{"asset_id": "32582994008069750117370770211161750379270178143252809024325448815129555714046", "price": "0.359", "size": "0", "side": "BUY", "hash": "c97bcad1c515db773ad8397c147da806cfb6e038", "best_bid": "0.952", "best_ask": "0.954"}, {"asset_id": "94207036547569786168949387588066196313734350858370522979598866565386642178169", "price": "0.641", "size": "0", "side": "SELL", "hash": "07c0a930387dec144acaca2b63d762dfdaceb150", "best_bid": "0.046", "best_ask": "0.048"}], "timestamp": "1769384880893", "event_type": "price_change"}}
{"_local_timestamp": "2026-01-25T23:48:01.382304+00:00", "data": {"market": "0xb7ba5d2b34c3f78d2b483daa97bc301f7296a5d8658ba2851f4c912a161e5158", "price_changes": [{"asset_id": "32582994008069750117370770211161750379270178143252809024325448815129555714046", "price": "0.359", "size": "5", "side": "BUY", "hash": "edde1ea0283ff81af6dd4acf67fabff1556c1e3c", "best_bid": "0.952", "best_ask": "0.954"}, {"asset_id": "94207036547569786168949387588066196313734350858370522979598866565386642178169", "price": "0.641", "size": "5", "side": "SELL", "hash": "dddae8e03a820cc5cea216d9738429db2e164e3b", "best_bid": "0.046", "best_ask": "0.048"}], "timestamp": "1769384881312", "event_type": "price_change"}}
{"_local_timestamp": "2026-01-25T23:48:24.213365+00:00", "data": {"market": "0xb7ba5d2b34c3f78d2b483daa97bc301f7296a5d8658ba2851f4c912a161e5158", "price_changes": [{"asset_id": "32582994008069750117370770211161750379270178143252809024325448815129555714046", "price": "0.243", "size": "1728", "side": "BUY", "hash": "0f019cb35c8b4246f8f9488c3ae3a4b33253d12c", "best_bid": "0.952", "best_ask": "0.954"}, {"asset_id": "94207036547569786168949387588066196313734350858370522979598866565386642178169", "price": "0.757", "size": "1728", "side": "SELL", "hash": "1e1acf4945aa6ca86e8b6b709c5552e33f52d7ea", "best_bid": "0.046", "best_ask": "0.048"}], "timestamp": "1769384904152", "event_type": "price_change"}}
{"_local_timestamp": "2026-01-25T23:48:24.324828+00:00", "data": {"market": "0xda86314ac2dd0f78ab1fe5b746840abeeff5be4e74c6d5bd5a0aada5c695030e", "price_changes": [{"asset_id": "66466375160121808081218865320764245347163437070476088335272741711627298513873", "price": "0.255", "size": "800", "side": "BUY", "hash": "cacde6aeeb036d70a232f5a3f9c5c33697cc4a5d", "best_bid": "0.989", "best_ask": "0.992"}, {"asset_id": "83273939204150973203361658145419377967478532826191206101882322765481122431127", "price": "0.745", "size": "800", "side": "SELL", "hash": "66fc410f09b9cf0e69f4c90849033b1dcfd7b24d", "best_bid": "0.008", "best_ask": "0.011"}], "timestamp": "1769384904261", "event_type": "price_change"}}
{"_local_timestamp": "2026-01-25T23:48:24.761252+00:00", "data": {"market": "0xda86314ac2dd0f78ab1fe5b746840abeeff5be4e74c6d5bd5a0aada5c695030e", "price_changes": [{"asset_id": "66466375160121808081218865320764245347163437070476088335272741711627298513873", "price": "0.256", "size": "781", "side": "BUY", "hash": "3435128224f57170bcd047c4724ecade42f59091", "best_bid": "0.989", "best_ask": "0.992"}, {"asset_id": "83273939204150973203361658145419377967478532826191206101882322765481122431127", "price": "0.744", "size": "781", "side": "SELL", "hash": "1f1b56735ddc2b9ef1e831cd10eb10d56d0660f7", "best_bid": "0.008", "best_ask": "0.011"}], "timestamp": "1769384904698", "event_type": "price_change"}}
{"_local_timestamp": "2026-01-25T23:48:37.479188+00:00", "data": {"market": "0xb7ba5d2b34c3f78d2b483daa97bc301f7296a5d8658ba2851f4c912a161e5158", "price_changes": [{"asset_id": "32582994008069750117370770211161750379270178143252809024325448815129555714046", "price": "0.359", "size": "0", "side": "BUY", "hash": "00a3e3af4f2d7507e91f0a6568052b166c883a22", "best_bid": "0.952", "best_ask": "0.954"}, {"asset_id": "94207036547569786168949387588066196313734350858370522979598866565386642178169", "price": "0.641", "size": "0", "side": "SELL", "hash": "d710bce2317752b6ddb97453a3ff77d89e48a792", "best_bid": "0.046", "best_ask": "0.048"}], "timestamp": "1769384917402", "event_type": "price_change"}}
{"_local_timestamp": "2026-01-25T23:48:38.036481+00:00", "data": {"market": "0xb7ba5d2b34c3f78d2b483daa97bc301f7296a5d8658ba2851f4c912a161e5158", "price_changes": [{"asset_id": "32582994008069750117370770211161750379270178143252809024325448815129555714046", "price": "0.359", "size": "5", "side": "BUY", "hash": "8fb78b7705821e17140d2c16d81ab6e7d02fba67", "best_bid": "0.952", "best_ask": "0.954"}, {"asset_id": "94207036547569786168949387588066196313734350858370522979598866565386642178169", "price": "0.641", "size": "5", "side": "SELL", "hash": "adc321f07fe42ed41f5f9625adb24e4ba320bdc1", "best_bid": "0.046", "best_ask": "0.048"}], "timestamp": "1769384917882", "event_type": "price_change"}}
{"_local_timestamp": "2026-01-25T23:49:08.206417+00:00", "data": {"market": "0xda86314ac2dd0f78ab1fe5b746840abeeff5be4e74c6d5bd5a0aada5c695030e", "price_changes": [{"asset_id": "66466375160121808081218865320764245347163437070476088335272741711627298513873", "price": "0.246", "size": "0", "side": "BUY", "hash": "f643c50dc08b93a58e1cfc186d5c9ff84c718072", "best_bid": "0.989", "best_ask": "0.992"}, {"asset_id": "83273939204150973203361658145419377967478532826191206101882322765481122431127", "price": "0.754", "size": "0", "side": "SELL", "hash": "b6049452bb1a73d8106bef2dccfb7f823c32ddcd", "best_bid": "0.008", "best_ask": "0.011"}], "timestamp": "1769384948140", "event_type": "price_change"}}
{"_local_timestamp": "2026-01-25T23:49:08.258262+00:00", "data": {"market": "0xda86314ac2dd0f78ab1fe5b746840abeeff5be4e74c6d5bd5a0aada5c695030e", "price_changes": [{"asset_id": "66466375160121808081218865320764245347163437070476088335272741711627298513873", "price": "0.257", "size": "7", "side": "BUY", "hash": "53fddf5c18aaae990be8acf56664eca851210838", "best_bid": "0.989", "best_ask": "0.992"}, {"asset_id": "83273939204150973203361658145419377967478532826191206101882322765481122431127", "price": "0.743", "size": "7", "side": "SELL", "hash": "39a7b75ea3bedb1752b408cf77c763dec972b5b2", "best_bid": "0.008", "best_ask": "0.011"}], "timestamp": "1769384948190", "event_type": "price_change"}}
{"_local_timestamp": "2026-01-25T23:49:08.407481+00:00", "data": {"market": "0x7d99e856ca49dcf748ff0072af624a65bafcb44a34b914b5a1466211674ae729", "price_changes": [{"asset_id": "17182810599901842221755643003911781322979812178264318853202692827838675256569", "price": "0.679", "size": "0", "side": "BUY", "hash": "2b40f4b040f50fe075eb6f848d8d95c9eb87e2f3", "best_bid": "0.981", "best_ask": "0.989"}, {"asset_id": "27250410806992141952257033810710803403327848453310007128861669762666286354528", "price": "0.321", "size": "0", "side": "SELL", "hash": "f0285a5b4fea744c37361e97f50b248e2cbda0dd", "best_bid": "0.011", "best_ask": "0.019"}], "timestamp": "1769384948341", "event_type": "price_change"}}
{"_local_timestamp": "2026-01-25T23:49:08.473723+00:00", "data": {"market": "0x7d99e856ca49dcf748ff0072af624a65bafcb44a34b914b5a1466211674ae729", "price_changes": [{"asset_id": "17182810599901842221755643003911781322979812178264318853202692827838675256569", "price": "0.686", "size": "20", "side": "BUY", "hash": "9e426962ea64f28e42de000fd927f942339648fb", "best_bid": "0.981", "best_ask": "0.989"}, {"asset_id": "27250410806992141952257033810710803403327848453310007128861669762666286354528", "price": "0.314", "size": "20", "side": "SELL", "hash": "67bbc903e61f91d713e2b998cc1876868b07928b", "best_bid": "0.011", "best_ask": "0.019"}], "timestamp": "1769384948410", "event_type": "price_change"}}
{"_local_timestamp": "2026-01-25T23:49:09.157312+00:00", "data": {"market": "0xb7ba5d2b34c3f78d2b483daa97bc301f7296a5d8658ba2851f4c912a161e5158", "price_changes": [{"asset_id": "32582994008069750117370770211161750379270178143252809024325448815129555714046", "price": "0.359", "size": "0", "side": "BUY", "hash": "491ef23635adb2fe66165effa87fdc652329511f", "best_bid": "0.952", "best_ask": "0.954"}, {"asset_id": "94207036547569786168949387588066196313734350858370522979598866565386642178169", "price": "0.641", "size": "0", "side": "SELL", "hash": "e3ec1f1e98be416c2a410b932e5c9155cc9939af", "best_bid": "0.046", "best_ask": "0.048"}], "timestamp": "1769384949089", "event_type": "price_change"}}
{"_local_timestamp": "2026-01-25T23:49:10.031379+00:00", "data": {"market": "0x7d99e856ca49dcf748ff0072af624a65bafcb44a34b914b5a1466211674ae729", "price_changes": [{"asset_id": "17182810599901842221755643003911781322979812178264318853202692827838675256569", "price": "0.685", "size": "0", "side": "BUY", "hash": "6d8982137a92029d1a455379f35e43f2c9de6555", "best_bid": "0.981", "best_ask": "0.989"}, {"asset_id": "27250410806992141952257033810710803403327848453310007128861669762666286354528", "price": "0.315", "size": "0", "side": "SELL", "hash": "da419b3fec48cdcfdad1ec50d96cb8cd60e95a87", "best_bid": "0.011", "best_ask": "0.019"}], "timestamp": "1769384949954", "event_type": "price_change"}}
{"_local_timestamp": "2026-01-25T23:49:10.053760+00:00", "data": {"market": "0x7d99e856ca49dcf748ff0072af624a65bafcb44a34b914b5a1466211674ae729", "price_changes": [{"asset_id": "17182810599901842221755643003911781322979812178264318853202692827838675256569", "price": "0.687", "size": "20", "side": "BUY", "hash": "5b33b365fd24a5a10739add8e25d477f805fdff4", "best_bid": "0.981", "best_ask": "0.989"}, {"asset_id": "27250410806992141952257033810710803403327848453310007128861669762666286354528", "price": "0.313", "size": "20", "side": "SELL", "hash": "8f47bd0bee2e4f9b4af196c988fae1cdb9105ebc", "best_bid": "0.011", "best_ask": "0.019"}], "timestamp": "1769384949979", "event_type": "price_change"}}
{"_local_timestamp": "2026-01-25T23:49:10.064149+00:00", "data": {"market": "0xb7ba5d2b34c3f78d2b483daa97bc301f7296a5d8658ba2851f4c912a161e5158", "price_changes": [{"asset_id": "32582994008069750117370770211161750379270178143252809024325448815129555714046", "price": "0.359", "size": "5", "side": "BUY", "hash": "364ac1c2d033c17a422ddd2a4884f8fbfd635824", "best_bid": "0.952", "best_ask": "0.954"}, {"asset_id": "94207036547569786168949387588066196313734350858370522979598866565386642178169", "price": "0.641", "size": "5", "side": "SELL", "hash": "24b89e92bbc8350cea29b9518ea9621aef46cb04", "best_bid": "0.046", "best_ask": "0.048"}], "timestamp": "1769384949990", "event_type": "price_change"}}
{"_local_timestamp": "2026-01-25T23:49:25.409864+00:00", "data": {"market": "0xda86314ac2dd0f78ab1fe5b746840abeeff5be4e74c6d5bd5a0aada5c695030e", "price_changes": [{"asset_id": "83273939204150973203361658145419377967478532826191206101882322765481122431127", "price": "0.004", "size": "0", "side": "BUY", "hash": "6aca4b388805a9a20bd2e67aa9fd8ed2a0de0ae9", "best_bid": "0.008", "best_ask": "0.011"}, {"asset_id": "66466375160121808081218865320764245347163437070476088335272741711627298513873", "price": "0.996", "size": "0", "side": "SELL", "hash": "90be8af35d31336d74c6a49c33fb85a318fc654e", "best_bid": "0.989", "best_ask": "0.992"}], "timestamp": "1769384965278", "event_type": "price_change"}}
{"_local_timestamp": "2026-01-25T23:49:25.517019+00:00", "data": {"market": "0xda86314ac2dd0f78ab1fe5b746840abeeff5be4e74c6d5bd5a0aada5c695030e", "price_changes": [{"asset_id": "66466375160121808081218865320764245347163437070476088335272741711627298513873", "price": "0.952", "size": "0", "side": "BUY", "hash": "b692ef48eacfea359bc8c0eabe52aa64c14195d6", "best_bid": "0.989", "best_ask": "0.992"}, {"asset_id": "83273939204150973203361658145419377967478532826191206101882322765481122431127", "price": "0.048", "size": "0", "side": "SELL", "hash": "7b26e10f3b7d8f737c831877f4532d230f16efe6", "best_bid": "0.008", "best_ask": "0.011"}], "timestamp": "1769384965439", "event_type": "price_change"}}
{"_local_timestamp": "2026-01-25T23:49:25.596037+00:00", "data": {"market": "0xda86314ac2dd0f78ab1fe5b746840abeeff5be4e74c6d5bd5a0aada5c695030e", "price_changes": [{"asset_id": "66466375160121808081218865320764245347163437070476088335272741711627298513873", "price": "0.925", "size": "152", "side": "BUY", "hash": "f433e78bbfa8701f693b6759a15c930b2403ae52", "best_bid": "0.989", "best_ask": "0.992"}, {"asset_id": "83273939204150973203361658145419377967478532826191206101882322765481122431127", "price": "0.075", "size": "152", "side": "SELL", "hash": "5236c61dcf5eae8dacb2546d4d38e7de64ada698", "best_bid": "0.008", "best_ask": "0.011"}], "timestamp": "1769384965516", "event_type": "price_change"}}
{"_local_timestamp": "2026-01-25T23:49:25.596957+00:00", "data": {"market": "0xda86314ac2dd0f78ab1fe5b746840abeeff5be4e74c6d5bd5a0aada5c695030e", "price_changes": [{"asset_id": "66466375160121808081218865320764245347163437070476088335272741711627298513873", "price": "0.952", "size": "30", "side": "BUY", "hash": "8874fbf23a28ebc9240e70e31cdba1d1868f649c", "best_bid": "0.989", "best_ask": "0.992"}, {"asset_id": "83273939204150973203361658145419377967478532826191206101882322765481122431127", "price": "0.048", "size": "30", "side": "SELL", "hash": "59711db33486b409685320e0c185f1d1bd40ddfc", "best_bid": "0.008", "best_ask": "0.011"}], "timestamp": "1769384965518", "event_type": "price_change"}}
{"_local_timestamp": "2026-01-25T23:49:25.741695+00:00", "data": {"market": "0xda86314ac2dd0f78ab1fe5b746840abeeff5be4e74c6d5bd5a0aada5c695030e", "price_changes": [{"asset_id": "83273939204150973203361658145419377967478532826191206101882322765481122431127", "price": "0.003", "size": "99.94", "side": "BUY", "hash": "480b87b0bc5cf16c3fe92b5a34c8bbaaa1792a23", "best_bid": "0.008", "best_ask": "0.011"}, {"asset_id": "66466375160121808081218865320764245347163437070476088335272741711627298513873", "price": "0.997", "size": "99.94", "side": "SELL", "hash": "63da5e159397eb571b78f832beb2a3b453407629", "best_bid": "0.989", "best_ask": "0.992"}], "timestamp": "1769384965662", "event_type": "price_change"}}
{"_local_timestamp": "2026-01-25T23:49:36.197415+00:00", "data": {"market": "0xb7ba5d2b34c3f78d2b483daa97bc301f7296a5d8658ba2851f4c912a161e5158", "price_changes": [{"asset_id": "94207036547569786168949387588066196313734350858370522979598866565386642178169", "price": "0.776", "size": "0", "side": "SELL", "hash": "77159ad518ca153be55b7ac73ea2aa695de7f362", "best_bid": "0.046", "best_ask": "0.048"}, {"asset_id": "32582994008069750117370770211161750379270178143252809024325448815129555714046", "price": "0.224", "size": "0", "side": "BUY", "hash": "30cf784871ba15b9229dfcb1feaae5db5555827e", "best_bid": "0.952", "best_ask": "0.954"}], "timestamp": "1769384976127", "event_type": "price_change"}}
{"_local_timestamp": "2026-01-25T23:49:36.465912+00:00", "data": {"market": "0xb7ba5d2b34c3f78d2b483daa97bc301f7296a5d8658ba2851f4c912a161e5158", "price_changes": [{"asset_id": "94207036547569786168949387588066196313734350858370522979598866565386642178169", "price": "0.758", "size": "367", "side": "SELL", "hash": "d9a9db70d0f17a0cd1819b9b426fb036203933f6", "best_bid": "0.046", "best_ask": "0.048"}, {"asset_id": "32582994008069750117370770211161750379270178143252809024325448815129555714046", "price": "0.242", "size": "367", "side": "BUY", "hash": "7fa7bfca21017927f98551ce500ca168e899000b", "best_bid": "0.952", "best_ask": "0.954"}], "timestamp": "1769384976384", "event_type": "price_change"}}
{"_local_timestamp": "2026-01-25T23:49:41.639576+00:00", "data": {"market": "0xb7ba5d2b34c3f78d2b483daa97bc301f7296a5d8658ba2851f4c912a161e5158", "price_changes": [{"asset_id": "32582994008069750117370770211161750379270178143252809024325448815129555714046", "price": "0.359", "size": "0", "side": "BUY", "hash": "7639bc45ba84d9e3d3949bbf9ceeafccac6c0712", "best_bid": "0.952", "best_ask": "0.954"}, {"asset_id": "94207036547569786168949387588066196313734350858370522979598866565386642178169", "price": "0.641", "size": "0", "side": "SELL", "hash": "89bbe8970309d6a78196a05aad91d58e87ac025b", "best_bid": "0.046", "best_ask": "0.048"}], "timestamp": "1769384981572", "event_type": "price_change"}}
{"_local_timestamp": "2026-01-25T23:49:59.348307+00:00", "data": {"market": "0x7d99e856ca49dcf748ff0072af624a65bafcb44a34b914b5a1466211674ae729", "price_changes": [{"asset_id": "17182810599901842221755643003911781322979812178264318853202692827838675256569", "price": "0.021", "size": "5.33", "side": "BUY", "hash": "aa5d660328d67ac4dbf0e4dec259428bb33d6cf2", "best_bid": "0.981", "best_ask": "0.989"}, {"asset_id": "27250410806992141952257033810710803403327848453310007128861669762666286354528", "price": "0.979", "size": "5.33", "side": "SELL", "hash": "e6d8f30d67654db96fd8800da483434db42ceca2", "best_bid": "0.011", "best_ask": "0.019"}], "timestamp": "1769384999268", "event_type": "price_change"}}
{"_local_timestamp": "2026-01-25T23:49:59.552521+00:00", "data": {"market": "0xef62cae2f23eb9084db338cafc8ee88806bee54e3a92051689f70d6907b7f3cf", "price_changes": [{"asset_id": "86421436930838227408032705986280984822442451727936616356929369488596324752129", "price": "0.924", "size": "0", "side": "BUY", "hash": "dd7373fd0feccbf51de508dab12add683560b5a4", "best_bid": "0.992", "best_ask": "0.995"}, {"asset_id": "48832045779017406406240960364495829307085252456810565554978796786740596106550", "price": "0.076", "size": "0", "side": "SELL", "hash": "f75a23f712aff387dc6bbb56db20e41c43eee62a", "best_bid": "0.005", "best_ask": "0.008"}], "timestamp": "1769384999480", "event_type": "price_change"}}
{"_local_timestamp": "2026-01-25T23:49:59.553369+00:00", "data": {"market": "0x7d99e856ca49dcf748ff0072af624a65bafcb44a34b914b5a1466211674ae729", "price_changes": [{"asset_id": "17182810599901842221755643003911781322979812178264318853202692827838675256569", "price": "0.681", "size": "0", "side": "BUY", "hash": "69290506adf2c36cfe9395b151abb11ed9204456", "best_bid": "0.981", "best_ask": "0.989"}, {"asset_id": "27250410806992141952257033810710803403327848453310007128861669762666286354528", "price": "0.319", "size": "0", "side": "SELL", "hash": "ef214e5e565473ff70c74329547276702c51d4a9", "best_bid": "0.011", "best_ask": "0.019"}], "timestamp": "1769384999480", "event_type": "price_change"}}
{"_local_timestamp": "2026-01-25T23:49:59.621551+00:00", "data": {"market": "0x7d99e856ca49dcf748ff0072af624a65bafcb44a34b914b5a1466211674ae729", "price_changes": [{"asset_id": "17182810599901842221755643003911781322979812178264318853202692827838675256569", "price": "0.021", "size": "15.62", "side": "BUY", "hash": "700ab55ac3d950a21b72e79c43e2e6ec0038a041", "best_bid": "0.981", "best_ask": "0.989"}, {"asset_id": "27250410806992141952257033810710803403327848453310007128861669762666286354528", "price": "0.979", "size": "15.62", "side": "SELL", "hash": "1fed575fa624cf73cf1a5ccbb31911aff023ed3e", "best_bid": "0.011", "best_ask": "0.019"}], "timestamp": "1769384999543", "event_type": "price_change"}}
{"_local_timestamp": "2026-01-25T23:49:59.823405+00:00", "data": {"market": "0xef62cae2f23eb9084db338cafc8ee88806bee54e3a92051689f70d6907b7f3cf", "price_changes": [{"asset_id": "86421436930838227408032705986280984822442451727936616356929369488596324752129", "price": "0.924", "size": "208", "side": "BUY", "hash": "76744844f7e7e42d733973f66611af044c58d622", "best_bid": "0.992", "best_ask": "0.995"}, {"asset_id": "48832045779017406406240960364495829307085252456810565554978796786740596106550", "price": "0.076", "size": "208", "side": "SELL", "hash": "0fa2cf626ebe7a85ec165b6629ab6732cdd99c17", "best_bid": "0.005", "best_ask": "0.008"}], "timestamp": "1769384999751", "event_type": "price_change"}}
{"_local_timestamp": "2026-01-25T23:49:59.824225+00:00", "data": {"market": "0x7d99e856ca49dcf748ff0072af624a65bafcb44a34b914b5a1466211674ae729", "price_changes": [{"asset_id": "17182810599901842221755643003911781322979812178264318853202692827838675256569", "price": "0.688", "size": "384", "side": "BUY", "hash": "db9dbcc8c6ab8db4beec6e25cfe119d9537e4271", "best_bid": "0.981", "best_ask": "0.989"}, {"asset_id": "27250410806992141952257033810710803403327848453310007128861669762666286354528", "price": "0.312", "size": "384", "side": "SELL", "hash": "f0868fb5c1e48c646e385a94441514c9d7b1fc11", "best_bid": "0.011", "best_ask": "0.019"}], "timestamp": "1769384999751", "event_type": "price_change"}}
{"_local_timestamp": "2026-01-25T23:49:59.824960+00:00", "data": {"market": "0x7d99e856ca49dcf748ff0072af624a65bafcb44a34b914b5a1466211674ae729", "price_changes": [{"asset_id": "17182810599901842221755643003911781322979812178264318853202692827838675256569", "price": "0.688", "size": "414", "side": "BUY", "hash": "e7d0afb44511d0a85d7c84f1401f12123c6a9026", "best_bid": "0.981", "best_ask": "0.989"}, {"asset_id": "27250410806992141952257033810710803403327848453310007128861669762666286354528", "price": "0.312", "size": "414", "side": "SELL", "hash": "654b7195bb3349b6ee6cc5be28f8fd48d3c33cf0", "best_bid": "0.011", "best_ask": "0.019"}], "timestamp": "1769384999752", "event_type": "price_change"}}
{"_local_timestamp": "2026-01-25T23:49:59.831172+00:00", "data": {"market": "0xef62cae2f23eb9084db338cafc8ee88806bee54e3a92051689f70d6907b7f3cf", "price_changes": [{"asset_id": "86421436930838227408032705986280984822442451727936616356929369488596324752129", "price": "0.949", "size": "30", "side": "BUY", "hash": "d901c9e819c099a0376b502206f578042b9959e8", "best_bid": "0.992", "best_ask": "0.995"}, {"asset_id": "48832045779017406406240960364495829307085252456810565554978796786740596106550", "price": "0.051", "size": "30", "side": "SELL", "hash": "10ab5475214275980747e6b984d9d0abcb443542", "best_bid": "0.005", "best_ask": "0.008"}], "timestamp": "1769384999753", "event_type": "price_change"}}
{"_local_timestamp": "2026-01-25T23:49:59.903811+00:00", "data": {"market": "0x7d99e856ca49dcf748ff0072af624a65bafcb44a34b914b5a1466211674ae729", "price_changes": [{"asset_id": "17182810599901842221755643003911781322979812178264318853202692827838675256569", "price": "0.278", "size": "193", "side": "BUY", "hash": "af8ba9f21969b3a5f01052bfa62010d17cc79aa7", "best_bid": "0.981", "best_ask": "0.989"}, {"asset_id": "27250410806992141952257033810710803403327848453310007128861669762666286354528", "price": "0.722", "size": "193", "side": "SELL", "hash": "07c5cd72160dddb6066016e05052cb7da1ed136b", "best_bid": "0.011", "best_ask": "0.019"}], "timestamp": "1769384999830", "event_type": "price_change"}}
{"_local_timestamp": "2026-01-25T23:50:00.008851+00:00", "data": {"market": "0x7d99e856ca49dcf748ff0072af624a65bafcb44a34b914b5a1466211674ae729", "price_changes": [{"asset_id": "17182810599901842221755643003911781322979812178264318853202692827838675256569", "price": "0.682", "size": "0", "side": "BUY", "hash": "6ce378ebab062e9a1f85f56e8b8a9c73e912c64e", "best_bid": "0.981", "best_ask": "0.989"}, {"asset_id": "27250410806992141952257033810710803403327848453310007128861669762666286354528", "price": "0.318", "size": "0", "side": "SELL", "hash": "fe50a77e3a16d3d54ed44ac19eff6e36368c5f04", "best_bid": "0.011", "best_ask": "0.019"}], "timestamp": "1769384999933", "event_type": "price_change"}}
{"_local_timestamp": "2026-01-25T23:50:00.031635+00:00", "data": {"market": "0x7d99e856ca49dcf748ff0072af624a65bafcb44a34b914b5a1466211674ae729", "price_changes": [{"asset_id": "17182810599901842221755643003911781322979812178264318853202692827838675256569", "price": "0.278", "size": "0", "side": "BUY", "hash": "57ce6fcc2ccf799f488110a7698b84d1fbc18a5e", "best_bid": "0.981", "best_ask": "0.989"}, {"asset_id": "27250410806992141952257033810710803403327848453310007128861669762666286354528", "price": "0.722", "size": "0", "side": "SELL", "hash": "d1012fdfeb7ec772dccb76eb58b50da627d0e101", "best_bid": "0.011", "best_ask": "0.019"}], "timestamp": "1769384999959", "event_type": "price_change"}}
{"_local_timestamp": "2026-01-25T23:50:00.140649+00:00", "data": {"market": "0x7d99e856ca49dcf748ff0072af624a65bafcb44a34b914b5a1466211674ae729", "price_changes": [{"asset_id": "17182810599901842221755643003911781322979812178264318853202692827838675256569", "price": "0.689", "size": "20", "side": "BUY", "hash": "3a26d5d475b7ed1eebbf2b422b4a1189e15b8822", "best_bid": "0.981", "best_ask": "0.989"}, {"asset_id": "27250410806992141952257033810710803403327848453310007128861669762666286354528", "price": "0.311", "size": "20", "side": "SELL", "hash": "5e9dd4ac87ed9635030faf86bbc30852aaa3321a", "best_bid": "0.011", "best_ask": "0.019"}], "timestamp": "1769385000069", "event_type": "price_change"}}
{"_local_timestamp": "2026-01-25T23:50:00.141528+00:00", "data": {"market": "0x7d99e856ca49dcf748ff0072af624a65bafcb44a34b914b5a1466211674ae729", "price_changes": [{"asset_id": "17182810599901842221755643003911781322979812178264318853202692827838675256569", "price": "0.689", "size": "165", "side": "BUY", "hash": "dfa58169b20a559f2f32aa56cf86b089f18a4ac8", "best_bid": "0.981", "best_ask": "0.989"}, {"asset_id": "27250410806992141952257033810710803403327848453310007128861669762666286354528", "price": "0.311", "size": "165", "side": "SELL", "hash": "5a836982edf99ba9709286ff4a05b4f7938391bc", "best_bid": "0.011", "best_ask": "0.019"}], "timestamp": "1769385000070", "event_type": "price_change"}}
{"_local_timestamp": "2026-01-25T23:50:00.295979+00:00", "data": {"market": "0x7d99e856ca49dcf748ff0072af624a65bafcb44a34b914b5a1466211674ae729", "price_changes": [{"asset_id": "17182810599901842221755643003911781322979812178264318853202692827838675256569", "price": "0.689", "size": "455", "side": "BUY", "hash": "5a366f0e74fce57b3c0f9743ca18659f2726ff9a", "best_bid": "0.981", "best_ask": "0.989"}, {"asset_id": "27250410806992141952257033810710803403327848453310007128861669762666286354528", "price": "0.311", "size": "455", "side": "SELL", "hash": "6a1b624e59062130cf266d1420b24c87b8e4949e", "best_bid": "0.011", "best_ask": "0.019"}], "timestamp": "1769385000224", "event_type": "price_change"}}
{"_local_timestamp": "2026-01-25T23:50:00.306086+00:00", "data": {"market": "0x7d99e856ca49dcf748ff0072af624a65bafcb44a34b914b5a1466211674ae729", "price_changes": [{"asset_id": "17182810599901842221755643003911781322979812178264318853202692827838675256569", "price": "0.689", "size": "745", "side": "BUY", "hash": "db18edce97cf90d748ba72a19f86e66a23545f85", "best_bid": "0.981", "best_ask": "0.989"}, {"asset_id": "27250410806992141952257033810710803403327848453310007128861669762666286354528", "price": "0.311", "size": "745", "side": "SELL", "hash": "e279fbd4fd38f52253487059048f4bbb3545aa72", "best_bid": "0.011", "best_ask": "0.019"}], "timestamp": "1769385000234", "event_type": "price_change"}}
{"_local_timestamp": "2026-01-25T23:50:00.406944+00:00", "data": {"market": "0x7d99e856ca49dcf748ff0072af624a65bafcb44a34b914b5a1466211674ae729", "price_changes": [{"asset_id": "17182810599901842221755643003911781322979812178264318853202692827838675256569", "price": "0.688", "size": "30", "side": "BUY", "hash": "e5588f6273a75c9663a215aa66f43192f9beb34d", "best_bid": "0.981", "best_ask": "0.989"}, {"asset_id": "27250410806992141952257033810710803403327848453310007128861669762666286354528", "price": "0.312", "size": "30", "side": "SELL", "hash": "ffca7d32bd0d2475f226fba8efad99488b9e79a5", "best_bid": "0.011", "best_ask": "0.019"}], "timestamp": "1769385000331", "event_type": "price_change"}}
{"_local_timestamp": "2026-01-25T23:50:00.896946+00:00", "data": {"market": "0x7d99e856ca49dcf748ff0072af624a65bafcb44a34b914b5a1466211674ae729", "price_changes": [{"asset_id": "17182810599901842221755643003911781322979812178264318853202692827838675256569", "price": "0.687", "size": "0", "side": "BUY", "hash": "dc571856ba259bbdaafadcbac85f2de0e0bbacec", "best_bid": "0.981", "best_ask": "0.989"}, {"asset_id": "27250410806992141952257033810710803403327848453310007128861669762666286354528", "price": "0.313", "size": "0", "side": "SELL", "hash": "b00d3eaeb8acdf00027bf1289b8f5ec51d81ea83", "best_bid": "0.011", "best_ask": "0.019"}], "timestamp": "1769385000821", "event_type": "price_change"}}
{"_local_timestamp": "2026-01-25T23:50:00.922916+00:00", "data": {"market": "0x7d99e856ca49dcf748ff0072af624a65bafcb44a34b914b5a1466211674ae729", "price_changes": [{"asset_id": "17182810599901842221755643003911781322979812178264318853202692827838675256569", "price": "0.689", "size": "765", "side": "BUY", "hash": "aa4b6b16b02b5dcff9f2fdca4188093b4e3b7429", "best_bid": "0.981", "best_ask": "0.989"}, {"asset_id": "27250410806992141952257033810710803403327848453310007128861669762666286354528", "price": "0.311", "size": "765", "side": "SELL", "hash": "0d7f82676a2445ed22bc4843410f5f55f6a4b24b", "best_bid": "0.011", "best_ask": "0.019"}], "timestamp": "1769385000845", "event_type": "price_change"}}
{"_local_timestamp": "2026-01-25T23:50:02.021586+00:00", "data": {"market": "0x7d99e856ca49dcf748ff0072af624a65bafcb44a34b914b5a1466211674ae729", "price_changes": [{"asset_id": "17182810599901842221755643003911781322979812178264318853202692827838675256569", "price": "0.689", "size": "745", "side": "BUY", "hash": "1b7b70c5d82cb707a8e8e7235b1b7a5956d7564f", "best_bid": "0.981", "best_ask": "0.989"}, {"asset_id": "27250410806992141952257033810710803403327848453310007128861669762666286354528", "price": "0.311", "size": "745", "side": "SELL", "hash": "e032fc93884dac4bc6b18d4d0771fa3f49132dd5", "best_bid": "0.011", "best_ask": "0.019"}], "timestamp": "1769385001947", "event_type": "price_change"}}
{"_local_timestamp": "2026-01-25T23:50:02.045915+00:00", "data": {"market": "0x7d99e856ca49dcf748ff0072af624a65bafcb44a34b914b5a1466211674ae729", "price_changes": [{"asset_id": "17182810599901842221755643003911781322979812178264318853202692827838675256569", "price": "0.69", "size": "20", "side": "BUY", "hash": "288de4541f81629da79b88b25f516e841134276e", "best_bid": "0.981", "best_ask": "0.989"}, {"asset_id": "27250410806992141952257033810710803403327848453310007128861669762666286354528", "price": "0.31", "size": "20", "side": "SELL", "hash": "b16d233a97590e82fbeb2b3cddb5c3f6443ded3d", "best_bid": "0.011", "best_ask": "0.019"}], "timestamp": "1769385001971", "event_type": "price_change"}}
{"_local_timestamp": "2026-01-25T23:50:02.630441+00:00", "data": {"market": "0xb7ba5d2b34c3f78d2b483daa97bc301f7296a5d8658ba2851f4c912a161e5158", "price_changes": [{"asset_id": "32582994008069750117370770211161750379270178143252809024325448815129555714046", "price": "0.236", "size": "2542", "side": "BUY", "hash": "fec07abe7127c1b52612664adfaca43b71e01c23", "best_bid": "0.952", "best_ask": "0.954"}, {"asset_id": "94207036547569786168949387588066196313734350858370522979598866565386642178169", "price": "0.764", "size": "2542", "side": "SELL", "hash": "f091c207d88d60eb4a5bdd40bbc02f32418f9855", "best_bid": "0.046", "best_ask": "0.048"}], "timestamp": "1769385002268", "event_type": "price_change"}}
{"_local_timestamp": "2026-01-25T23:50:02.936298+00:00", "data": {"market": "0xb7ba5d2b34c3f78d2b483daa97bc301f7296a5d8658ba2851f4c912a161e5158", "price_changes": [{"asset_id": "32582994008069750117370770211161750379270178143252809024325448815129555714046", "price": "0.236", "size": "0", "side": "BUY", "hash": "0b62f699a095825803b7b672d08f5e5140a4d781", "best_bid": "0.952", "best_ask": "0.954"}, {"asset_id": "94207036547569786168949387588066196313734350858370522979598866565386642178169", "price": "0.764", "size": "0", "side": "SELL", "hash": "636a7f4055baa5fc0023e276d2fc7e714a43f62a", "best_bid": "0.046", "best_ask": "0.048"}], "timestamp": "1769385002364", "event_type": "price_change"}}
{"_local_timestamp": "2026-01-25T23:50:19.087016+00:00", "data": {"market": "0xb7ba5d2b34c3f78d2b483daa97bc301f7296a5d8658ba2851f4c912a161e5158", "price_changes": [{"asset_id": "32582994008069750117370770211161750379270178143252809024325448815129555714046", "price": "0.143", "size": "1118", "side": "BUY", "hash": "d9a061b94fc5a1b7c08de0c37914cb6e1e6dac19", "best_bid": "0.952", "best_ask": "0.954"}, {"asset_id": "94207036547569786168949387588066196313734350858370522979598866565386642178169", "price": "0.857", "size": "1118", "side": "SELL", "hash": "841b95574a2aaa100e82d6b616f4e71c32aa31c3", "best_bid": "0.046", "best_ask": "0.048"}], "timestamp": "1769385018964", "event_type": "price_change"}}
{"_local_timestamp": "2026-01-25T23:50:30.423634+00:00", "data": {"market": "0xb7ba5d2b34c3f78d2b483daa97bc301f7296a5d8658ba2851f4c912a161e5158", "price_changes": [{"asset_id": "32582994008069750117370770211161750379270178143252809024325448815129555714046", "price": "0.142", "size": "200", "side": "BUY", "hash": "e93cf767b00aad563db40cce1fcc73e2aa76d538", "best_bid": "0.952", "best_ask": "0.954"}, {"asset_id": "94207036547569786168949387588066196313734350858370522979598866565386642178169", "price": "0.858", "size": "200", "side": "SELL", "hash": "0151f7a264e490ceac51d606e25946bf6b8c39e2", "best_bid": "0.046", "best_ask": "0.048"}], "timestamp": "1769385030254", "event_type": "price_change"}}
{"_local_timestamp": "2026-01-25T23:50:30.707062+00:00", "data": {"market": "0xb7ba5d2b34c3f78d2b483daa97bc301f7296a5d8658ba2851f4c912a161e5158", "price_changes": [{"asset_id": "32582994008069750117370770211161750379270178143252809024325448815129555714046", "price": "0.143", "size": "1318", "side": "BUY", "hash": "061b8eb4e9bd54f0408d290e6024c4d3d6cb34f4", "best_bid": "0.952", "best_ask": "0.954"}, {"asset_id": "94207036547569786168949387588066196313734350858370522979598866565386642178169", "price": "0.857", "size": "1318", "side": "SELL", "hash": "cc4d3d5ef08d8bb405b33a23dec050a49658571b", "best_bid": "0.046", "best_ask": "0.048"}], "timestamp": "1769385030522", "event_type": "price_change"}}
{"_local_timestamp": "2026-01-25T23:50:36.237437+00:00", "data": {"market": "0x7d99e856ca49dcf748ff0072af624a65bafcb44a34b914b5a1466211674ae729", "price_changes": [{"asset_id": "27250410806992141952257033810710803403327848453310007128861669762666286354528", "price": "0.002", "size": "1100", "side": "BUY", "hash": "47b5c7f3109fcfe8ade7c5a0e3ae755b8a436099", "best_bid": "0.011", "best_ask": "0.019"}, {"asset_id": "17182810599901842221755643003911781322979812178264318853202692827838675256569", "price": "0.998", "size": "1100", "side": "SELL", "hash": "86b67862c26f56ead205ffe989f17993192febdf", "best_bid": "0.981", "best_ask": "0.989"}], "timestamp": "1769385036041", "event_type": "price_change"}}
{"_local_timestamp": "2026-01-25T23:50:36.564558+00:00", "data": {"market": "0x7d99e856ca49dcf748ff0072af624a65bafcb44a34b914b5a1466211674ae729", "price_changes": [{"asset_id": "27250410806992141952257033810710803403327848453310007128861669762666286354528", "price": "0.002", "size": "1129.09", "side": "BUY", "hash": "a686056547ed02fe8f0ca4c3373e736d65855f66", "best_bid": "0.011", "best_ask": "0.019"}, {"asset_id": "17182810599901842221755643003911781322979812178264318853202692827838675256569", "price": "0.998", "size": "1129.09", "side": "SELL", "hash": "83829801eafca796e94805f2d2c2fc29a7f2a8c8", "best_bid": "0.981", "best_ask": "0.989"}], "timestamp": "1769385036354", "event_type": "price_change"}}
{"_local_timestamp": "2026-01-25T23:50:38.817329+00:00", "data": {"market": "0xb7ba5d2b34c3f78d2b483daa97bc301f7296a5d8658ba2851f4c912a161e5158", "price_changes": [{"asset_id": "32582994008069750117370770211161750379270178143252809024325448815129555714046", "price": "0.142", "size": "0", "side": "BUY", "hash": "1ef5487337804c71493ac167dda5863f8eaf4f55", "best_bid": "0.952", "best_ask": "0.954"}, {"asset_id": "94207036547569786168949387588066196313734350858370522979598866565386642178169", "price": "0.858", "size": "0", "side": "SELL", "hash": "0f712efb216b8890799a7b87c08bd001cdc713a1", "best_bid": "0.046", "best_ask": "0.048"}], "timestamp": "1769385038613", "event_type": "price_change"}}
{"_local_timestamp": "2026-01-25T23:50:38.947809+00:00", "data": {"market": "0x1b7e6de8efe5f6a2c1ca2470e747370be89fe96270ccee85430bf18ac705a4e1", "price_changes": [{"asset_id": "94395860414009734926327544945762460944151569233112202400231598436537334220949", "price": "0.952", "size": "0", "side": "BUY", "hash": "58b2e853ae2c3c4d3914282e8f1f82332578c7e3", "best_bid": "0.996", "best_ask": "0.998"}, {"asset_id": "86084595121347108808129382127322373721009228528241692453665189127555334452646", "price": "0.048", "size": "0", "side": "SELL", "hash": "18052953f8af0ae35215b494d50536e55d53f44b", "best_bid": "0.002", "best_ask": "0.004"}], "timestamp": "1769385038746", "event_type": "price_change"}}
{"_local_timestamp": "2026-01-25T23:50:39.006432+00:00", "data": {"market": "0x1b7e6de8efe5f6a2c1ca2470e747370be89fe96270ccee85430bf18ac705a4e1", "price_changes": [{"asset_id": "94395860414009734926327544945762460944151569233112202400231598436537334220949", "price": "0.952", "size": "20", "side": "BUY", "hash": "d4f82829ff3a66aeeece4383cc9093167ba9dc51", "best_bid": "0.996", "best_ask": "0.998"}, {"asset_id": "86084595121347108808129382127322373721009228528241692453665189127555334452646", "price": "0.048", "size": "20", "side": "SELL", "hash": "439732eb335b0e8db678339369eb7def20c9877b", "best_bid": "0.002", "best_ask": "0.004"}], "timestamp": "1769385038801", "event_type": "price_change"}}
{"_local_timestamp": "2026-01-25T23:50:39.007392+00:00", "data": {"market": "0x1b7e6de8efe5f6a2c1ca2470e747370be89fe96270ccee85430bf18ac705a4e1", "price_changes": [{"asset_id": "94395860414009734926327544945762460944151569233112202400231598436537334220949", "price": "0.351", "size": "218", "side": "BUY", "hash": "9016a19af6942da87f1a3927c4aa6d6a94c29fad", "best_bid": "0.996", "best_ask": "0.998"}, {"asset_id": "86084595121347108808129382127322373721009228528241692453665189127555334452646", "price": "0.649", "size": "218", "side": "SELL", "hash": "e4f8da62cc70d09c994b6c3229739452a9bd1999", "best_bid": "0.002", "best_ask": "0.004"}], "timestamp": "1769385038803", "event_type": "price_change"}}
{"_local_timestamp": "2026-01-25T23:50:39.084669+00:00", "data": {"market": "0x1b7e6de8efe5f6a2c1ca2470e747370be89fe96270ccee85430bf18ac705a4e1", "price_changes": [{"asset_id": "94395860414009734926327544945762460944151569233112202400231598436537334220949", "price": "0.35", "size": "130", "side": "BUY", "hash": "cbed0e518ceb029e27b2db745b5a7d7d4c25dabd", "best_bid": "0.996", "best_ask": "0.998"}, {"asset_id": "86084595121347108808129382127322373721009228528241692453665189127555334452646", "price": "0.65", "size": "130", "side": "SELL", "hash": "eafe9fbe73f3c9d48ed6cb288ad5a523d3638ba0", "best_bid": "0.002", "best_ask": "0.004"}], "timestamp": "1769385038869", "event_type": "price_change"}}
{"_local_timestamp": "2026-01-25T23:50:39.127727+00:00", "data": {"market": "0xda86314ac2dd0f78ab1fe5b746840abeeff5be4e74c6d5bd5a0aada5c695030e", "price_changes": [{"asset_id": "66466375160121808081218865320764245347163437070476088335272741711627298513873", "price": "0.951", "size": "0", "side": "BUY", "hash": "f64ac9e9d87fc366f48a31e3f662be3c58c9441c", "best_bid": "0.989", "best_ask": "0.992"}, {"asset_id": "83273939204150973203361658145419377967478532826191206101882322765481122431127", "price": "0.049", "size": "0", "side": "SELL", "hash": "8d218c28e2c45bc36e470ef17cf9b6350781a994", "best_bid": "0.008", "best_ask": "0.011"}], "timestamp": "1769385038912", "event_type": "price_change"}}
{"_local_timestamp": "2026-01-25T23:50:39.153080+00:00", "data": {"market": "0xb7ba5d2b34c3f78d2b483daa97bc301f7296a5d8658ba2851f4c912a161e5158", "price_changes": [{"asset_id": "32582994008069750117370770211161750379270178143252809024325448815129555714046", "price": "0.143", "size": "1518", "side": "BUY", "hash": "3c8a7190fa40a2e45dcc8edc31aa6beebd8f9f25", "best_bid": "0.952", "best_ask": "0.954"}, {"asset_id": "94207036547569786168949387588066196313734350858370522979598866565386642178169", "price": "0.857", "size": "1518", "side": "SELL", "hash": "09b5cb5b6307f751f3f8cd0162dd003c92491fbb", "best_bid": "0.046", "best_ask": "0.048"}], "timestamp": "1769385038939", "event_type": "price_change"}}
{"_local_timestamp": "2026-01-25T23:50:39.165490+00:00", "data": {"market": "0xda86314ac2dd0f78ab1fe5b746840abeeff5be4e74c6d5bd5a0aada5c695030e", "price_changes": [{"asset_id": "66466375160121808081218865320764245347163437070476088335272741711627298513873", "price": "0.257", "size": "60", "side": "BUY", "hash": "284363dc45f85ab6c63a10f44cd5ae1b2970e847", "best_bid": "0.989", "best_ask": "0.992"}, {"asset_id": "83273939204150973203361658145419377967478532826191206101882322765481122431127", "price": "0.743", "size": "60", "side": "SELL", "hash": "346ef39b58391f56321f922741feb2fe9b443e25", "best_bid": "0.008", "best_ask": "0.011"}], "timestamp": "1769385038953", "event_type": "price_change"}}
{"_local_timestamp": "2026-01-25T23:50:39.166379+00:00", "data": {"market": "0xda86314ac2dd0f78ab1fe5b746840abeeff5be4e74c6d5bd5a0aada5c695030e", "price_changes": [{"asset_id": "66466375160121808081218865320764245347163437070476088335272741711627298513873", "price": "0.951", "size": "20", "side": "BUY", "hash": "b7d47cb7c6009b150fb84a5104f65a60967f39ce", "best_bid": "0.989", "best_ask": "0.992"}, {"asset_id": "83273939204150973203361658145419377967478532826191206101882322765481122431127", "price": "0.049", "size": "20", "side": "SELL", "hash": "d41f25c566cd8292f2a643137051590c6f3226e6", "best_bid": "0.008", "best_ask": "0.011"}], "timestamp": "1769385038954", "event_type": "price_change"}}
{"_local_timestamp": "2026-01-25T23:50:39.197080+00:00", "data": {"market": "0x1b7e6de8efe5f6a2c1ca2470e747370be89fe96270ccee85430bf18ac705a4e1", "price_changes": [{"asset_id": "94395860414009734926327544945762460944151569233112202400231598436537334220949", "price": "0.35", "size": "0", "side": "BUY", "hash": "5031ce063e762a348faaca639a3e7ec3a5594e0c", "best_bid": "0.996", "best_ask": "0.998"}, {"asset_id": "86084595121347108808129382127322373721009228528241692453665189127555334452646", "price": "0.65", "size": "0", "side": "SELL", "hash": "adb3ad46d2823829265c69040a71ce53d2da05e2", "best_bid": "0.002", "best_ask": "0.004"}], "timestamp": "1769385038985", "event_type": "price_change"}}
{"_local_timestamp": "2026-01-25T23:50:39.319203+00:00", "data": {"market": "0x1b7e6de8efe5f6a2c1ca2470e747370be89fe96270ccee85430bf18ac705a4e1", "price_changes": [{"asset_id": "94395860414009734926327544945762460944151569233112202400231598436537334220949", "price": "0.35", "size": "33", "side": "BUY", "hash": "5f11988e70b9bc7801b08c5699e168b8df5af0d2", "best_bid": "0.996", "best_ask": "0.998"}, {"asset_id": "86084595121347108808129382127322373721009228528241692453665189127555334452646", "price": "0.65", "size": "33", "side": "SELL", "hash": "634f98c0cc44eb6a7f0f8bf4475488b70ef43613", "best_bid": "0.002", "best_ask": "0.004"}], "timestamp": "1769385039115", "event_type": "price_change"}}
{"_local_timestamp": "2026-01-25T23:50:39.458434+00:00", "data": {"market": "0x1b7e6de8efe5f6a2c1ca2470e747370be89fe96270ccee85430bf18ac705a4e1", "price_changes": [{"asset_id": "94395860414009734926327544945762460944151569233112202400231598436537334220949", "price": "0.35", "size": "65", "side": "BUY", "hash": "6d5c5c1aeca8d698c42557d2607160dc325fc5c4", "best_bid": "0.996", "best_ask": "0.998"}, {"asset_id": "86084595121347108808129382127322373721009228528241692453665189127555334452646", "price": "0.65", "size": "65", "side": "SELL", "hash": "22c3c8ebee53c4e1a8f376dcb0961c3158d8a905", "best_bid": "0.002", "best_ask": "0.004"}], "timestamp": "1769385039240", "event_type": "price_change"}}
{"_local_timestamp": "2026-01-25T23:50:59.455173+00:00", "data": {"market": "0xb7ba5d2b34c3f78d2b483daa97bc301f7296a5d8658ba2851f4c912a161e5158", "price_changes": [{"asset_id": "32582994008069750117370770211161750379270178143252809024325448815129555714046", "price": "0.101", "size": "600", "side": "BUY", "hash": "4c690395e3aba328ba788f5eac7d597749bd229d", "best_bid": "0.952", "best_ask": "0.954"}, {"asset_id": "94207036547569786168949387588066196313734350858370522979598866565386642178169", "price": "0.899", "size": "600", "side": "SELL", "hash": "32d875ab5b87b12e66524465d7465c982b53b7e5", "best_bid": "0.046", "best_ask": "0.048"}], "timestamp": "1769385059388", "event_type": "price_change"}}
{"_local_timestamp": "2026-01-25T23:50:59.731659+00:00", "data": {"market": "0xb7ba5d2b34c3f78d2b483daa97bc301f7296a5d8658ba2851f4c912a161e5158", "price_changes": [{"asset_id": "32582994008069750117370770211161750379270178143252809024325448815129555714046", "price": "0.143", "size": "1618", "side": "BUY", "hash": "a08c80acbe58f3528e4b13626fd0e2ae72a89360", "best_bid": "0.952", "best_ask": "0.954"}, {"asset_id": "94207036547569786168949387588066196313734350858370522979598866565386642178169", "price": "0.857", "size": "1618", "side": "SELL", "hash": "47fe14b99e5b41a67947f6d9772ba36bc6f9658f", "best_bid": "0.046", "best_ask": "0.048"}], "timestamp": "1769385059666", "event_type": "price_change"}}
{"_local_timestamp": "2026-01-25T23:51:03.160644+00:00", "data": {"market": "0xb7ba5d2b34c3f78d2b483daa97bc301f7296a5d8658ba2851f4c912a161e5158", "price_changes": [{"asset_id": "32582994008069750117370770211161750379270178143252809024325448815129555714046", "price": "0.101", "size": "500", "side": "BUY", "hash": "6a9efeaa9c1c65a949f669214ca75528fb7c3c6f", "best_bid": "0.952", "best_ask": "0.954"}, {"asset_id": "94207036547569786168949387588066196313734350858370522979598866565386642178169", "price": "0.899", "size": "500", "side": "SELL", "hash": "19a8b126d61a144b28e3221a5abe0c916ce74dee", "best_bid": "0.046", "best_ask": "0.048"}], "timestamp": "1769385063071", "event_type": "price_change"}}
{"_local_timestamp": "2026-01-25T23:51:03.416086+00:00", "data": {"market": "0xb7ba5d2b34c3f78d2b483daa97bc301f7296a5d8658ba2851f4c912a161e5158", "price_changes": [{"asset_id": "32582994008069750117370770211161750379270178143252809024325448815129555714046", "price": "0.143", "size": "1718", "side": "BUY", "hash": "3d38fd053fee42e55685aa44a6a06af9ed82a9d1", "best_bid": "0.952", "best_ask": "0.954"}, {"asset_id": "94207036547569786168949387588066196313734350858370522979598866565386642178169", "price": "0.857", "size": "1718", "side": "SELL", "hash": "6995b60da97186166d5de4dfc40bd966216d28fe", "best_bid": "0.046", "best_ask": "0.048"}], "timestamp": "1769385063338", "event_type": "price_change"}}
{"_local_timestamp": "2026-01-25T23:51:10.991465+00:00", "data": {"market": "0xb7ba5d2b34c3f78d2b483daa97bc301f7296a5d8658ba2851f4c912a161e5158", "price_changes": [{"asset_id": "32582994008069750117370770211161750379270178143252809024325448815129555714046", "price": "0.101", "size": "400", "side": "BUY", "hash": "70bfc091cb90a7578761c48e19cf5aade5b272e2", "best_bid": "0.952", "best_ask": "0.954"}, {"asset_id": "94207036547569786168949387588066196313734350858370522979598866565386642178169", "price": "0.899", "size": "400", "side": "SELL", "hash": "fba8cd8486d1e935c9339aed0173e04a7d81ce89", "best_bid": "0.046", "best_ask": "0.048"}], "timestamp": "1769385070926", "event_type": "price_change"}}
{"_local_timestamp": "2026-01-25T23:51:11.258684+00:00", "data": {"market": "0xb7ba5d2b34c3f78d2b483daa97bc301f7296a5d8658ba2851f4c912a161e5158", "price_changes": [{"asset_id": "32582994008069750117370770211161750379270178143252809024325448815129555714046", "price": "0.143", "size": "1818", "side": "BUY", "hash": "73cddd6964ccf3f766b088fff33f4d19084e6b7d", "best_bid": "0.952", "best_ask": "0.954"}, {"asset_id": "94207036547569786168949387588066196313734350858370522979598866565386642178169", "price": "0.857", "size": "1818", "side": "SELL", "hash": "ff3cbc33e8ad09c0b19c6450cb68bb7a3b2b00db", "best_bid": "0.046", "best_ask": "0.048"}], "timestamp": "1769385071192", "event_type": "price_change"}}
{"_local_timestamp": "2026-01-25T23:51:12.538507+00:00", "data": {"market": "0xb7ba5d2b34c3f78d2b483daa97bc301f7296a5d8658ba2851f4c912a161e5158", "price_changes": [{"asset_id": "32582994008069750117370770211161750379270178143252809024325448815129555714046", "price": "0.244", "size": "2458", "side": "BUY", "hash": "cca1c2bd0a4a79fefb1704ceeb3dbe6756b29e0a", "best_bid": "0.952", "best_ask": "0.954"}, {"asset_id": "94207036547569786168949387588066196313734350858370522979598866565386642178169", "price": "0.756", "size": "2458", "side": "SELL", "hash": "6b0044f69e9dc4c8a481b784c62c5a41b2db0490", "best_bid": "0.046", "best_ask": "0.048"}], "timestamp": "1769385072476", "event_type": "price_change"}}
{"_local_timestamp": "2026-01-25T23:51:14.538815+00:00", "data": {"market": "0xb7ba5d2b34c3f78d2b483daa97bc301f7296a5d8658ba2851f4c912a161e5158", "price_changes": [{"asset_id": "94207036547569786168949387588066196313734350858370522979598866565386642178169", "price": "0.018", "size": "499", "side": "BUY", "hash": "9ee33482c14b03910436d298efd4fb0e3a511c9d", "best_bid": "0.046", "best_ask": "0.048"}, {"asset_id": "32582994008069750117370770211161750379270178143252809024325448815129555714046", "price": "0.982", "size": "499", "side": "SELL", "hash": "4c9957df5c7ba0553af1e1fffc565c85e80611ac", "best_bid": "0.952", "best_ask": "0.954"}], "timestamp": "1769385074459", "event_type": "price_change"}}
