{"_local_timestamp": "2026-01-25T23:40:50.654087+00:00", "data": [{"market": "0x25025db13d5868308eb2f1f57beaf7cbea76c4014201800853a4c1aaad3046ee", "asset_id": "15113128431693879081528076048684622701923990563320934711420493231791911133880", "timestamp": "1769384339061", "hash": "0b5a0114eac14403c89d6c405f77b268ff4cfca4", "bids": [{"price": "0.01", "size": "110.65"}, {"price": "0.02", "size": "108"}, {"price": "0.03", "size": "47.98"}], "asks": [{"price": "0.99", "size": "241.51"}, {"price": "0.98", "size": "31.75"}, {"price": "0.96", "size": "12"}, {"price": "0.95", "size": "20"}, {"price": "0.94", "size": "43"}, {"price": "0.93", "size": "5.92"}, {"price": "0.91", "size": "85"}, {"price": "0.89", "size": "18"}, {"price": "0.86", "size": "30"}, {"price": "0.85", "size": "20"}, {"price": "0.28", "size": "20"}], "event_type": "book", "last_trade_price": ""}, {"market": "0x93f28d0ad9d5906fee37296a8a70a57c9e4ed4b3b9aa09029c2d9589ce7ce832", "asset_id": "72776331054793272806940188908180904666024448478022907801009755847830868970904", "timestamp": "1769384353304", "hash": "99b02c42454a8825b284a407a6593c8f1a984282", "bids": [{"price": "0.01", "size": "121.79"}, {"price": "0.02", "size": "22.34"}, {"price": "0.03", "size": "11.13"}, {"price": "0.05", "size": "36.1"}, {"price": "0.06", "size": "43"}, {"price": "0.08", "size": "47"}, {"price": "0.1", "size": "6.7"}, {"price": "0.13", "size": "30"}, {"price": "0.15", "size": "60"}], "asks": [{"price": "0.99", "size": "150.59"}, {"price": "0.98", "size": "95"}, {"price": "0.97", "size": "39.99"}], "event_type": "book", "last_trade_price": ""}, {"market": "0xa3476e8efbbc5557ff9f58978bcf85b7c2bc0c14d2f2c5891f1861a0e95c71c7", "asset_id": "49075166570883369230840079099601560361862864964529664437077360133815011449025", "timestamp": "1769384353303", "hash": "0fe59932bb2f0023ce25ba884f4744f131e1602c", "bids": [{"price": "0.01", "size": "150.58"}, {"price": "0.02", "size": "100"}, {"price": "0.03", "size": "39.99"}], "asks": [{"price": "0.99", "size": "171.68"}, {"price": "0.98", "size": "48.75"}, {"price": "0.95", "size": "30"}, {"price": "0.94", "size": "33"}, {"price": "0.93", "size": "16"}, {"price": "0.92", "size": "9.4"}, {"price": "0.9", "size": "70"}, {"price": "0.88", "size": "118.75"}, {"price": "0.87", "size": "10"}, {"price": "0.86", "size": "20"}], "event_type": "book", "last_trade_price": ""}, {"market": "0xfe76f366b01cffc5f3c2551ca2fafd3626551f8e67c45e90bcb9980fadefb1d9", "asset_id": "91464103984107757678948958563250156809345102931554507444370450055330522832734", "timestamp": "1769384353303", "hash": "7cdd5acdd97422d9549ef1eb5d2589e300ad7f4b", "bids": [{"price": "0.01", "size": "183.81"}, {"price": "0.02", "size": "17.67"}, {"price": "0.03", "size": "10"}, {"price": "0.04", "size": "8.04"}, {"price": "0.05", "size": "30"}, {"price": "0.06", "size": "38.58"}, {"price": "0.07", "size": "24"}, {"price": "0.08", "size": "8.95"}, {"price": "0.1", "size": "70"}, {"price": "0.12", "size": "118.75"}, {"price": "0.13", "size": "20"}], "asks": [{"price": "0.99", "size": "150.58"}, {"price": "0.98", "size": "100"}, {"price": "0.97", "size": "39.99"}], "event_type": "book", "last_trade_price": ""}, {"market": "0xf69b405cb72c495b47f14d4581ec5f4fdc32c7c783c0b05c5d350af99f74fb57", "asset_id": "111483763262460809812427616008076634438113457835729033090496924816271676966924", "timestamp": "1769384353303", "hash": "80772ff58b71624e95f2bda2548bd21083957315", "bids": [{"price": "0.01", "size": "159.98"}, {"price": "0.02", "size": "15.89"}, {"price": "0.03", "size": "18"}, {"price": "0.04", "size": "8.65"}, {"price": "0.05", "size": "30"}, {"price": "0.06", "size": "33"}, {"price": "0.07", "size": "5.74"}, {"price": "0.1", "size": "76.58"}, {"price": "0.13", "size": "10"}, {"price": "0.14", "size": "20"}], "asks": [{"price": "0.99", "size": "150.58"}, {"price": "0.98", "size": "95"}, {"price": "0.97", "size": "39.99"}], "event_type": "book", "last_trade_price": ""}, {"market": "0x25025db13d5868308eb2f1f57beaf7cbea76c4014201800853a4c1aaad3046ee", "asset_id": "69171629149106323292749070292707293928031973221371003911300207535275094378436", "timestamp": "1769384339061", "hash": "0fcbe5eff926da9511d7e06dace5b3de0166a992", "bids": [{"price": "0.01", "size": "241.51"}, {"price": "0.02", "size": "31.75"}, {"price": "0.04", "size": "12"}, {"price": "0.05", "size": "20"}, {"price": "0.06", "size": "43"}, {"price": "0.07", "size": "5.92"}, {"price": "0.09", "size": "85"}, {"price": "0.11", "size": "18"}, {"price": "0.14", "size": "30"}, {"price": "0.15", "size": "20"}, {"price": "0.72", "size": "20"}], "asks": [{"price": "0.99", "size": "110.65"}, {"price": "0.98", "size": "108"}, {"price": "0.97", "size": "47.98"}], "event_type": "book", "last_trade_price": ""}, {"market": "0xb9d3c208d8eb2f3403144092d0e55a4ecf7a6493e33890b35140197a63148d14", "asset_id": "70717802646694382009573815278721437797667570104667888155891561185095387198938", "timestamp": "1769384329509", "hash": "9ffefe89d3d232245944330f32fc6c77b5ff14df", "bids": [{"price": "0.01", "size": "172.06"}, {"price": "0.02", "size": "17.5"}, {"price": "0.03", "size": "10"}, {"price": "0.04", "size": "7.08"}, {"price": "0.05", "size": "30"}, {"price": "0.06", "size": "39.33"}, {"price": "0.08", "size": "17"}, {"price": "0.09", "size": "37.89"}, {"price": "0.1", "size": "40"}, {"price": "0.12", "size": "118.75"}, {"price": "0.13", "size": "20"}], "asks": [{"price": "0.99", "size": "150.58"}, {"price": "0.98", "size": "95"}, {"price": "0.97", "size": "39.99"}], "event_type": "book", "last_trade_price": ""}, {"market": "0xf69b405cb72c495b47f14d4581ec5f4fdc32c7c783c0b05c5d350af99f74fb57", "asset_id": "77871459748036421242663925334747383360075298582158881700736355568100463986230", "timestamp": "1769384353303", "hash": "7b80e1fbb305feba7ead857bd109f8c0aa056f48", "bids": [{"price": "0.01", "size": "150.58"}, {"price": "0.02", "size": "95"}, {"price": "0.03", "size": "39.99"}], "asks": [{"price": "0.99", "size": "159.98"}, {"price": "0.98", "size": "15.89"}, {"price": "0.97", "size": "18"}, {"price": "0.96", "size": "8.65"}, {"price": "0.95", "size": "30"}, {"price": "0.94", "size": "33"}, {"price": "0.93", "size": "5.74"}, {"price": "0.9", "size": "76.58"}, {"price": "0.87", "size": "10"}, {"price": "0.86", "size": "20"}], "event_type": "book", "last_trade_price": ""}, {"market": "0x93f28d0ad9d5906fee37296a8a70a57c9e4ed4b3b9aa09029c2d9589ce7ce832", "asset_id": "100955895305218895610069502472760899905214942330703669753760270178117749789092", "timestamp": "1769384353304", "hash": "d20b7f5487f448afdcf2fb85153fe850ead0c895", "bids": [{"price": "0.01", "size": "150.59"}, {"price": "0.02", "size": "95"}, {"price": "0.03", "size": "39.99"}], "asks": [{"price": "0.99", "size": "121.79"}, {"price": "0.98", "size": "22.34"}, {"price": "0.97", "size": "11.13"}, {"price": "0.95", "size": "36.1"}, {"price": "0.94", "size": "43"}, {"price": "0.92", "size": "47"}, {"price": "0.9", "size": "6.7"}, {"price": "0.87", "size": "30"}, {"price": "0.85", "size": "60"}], "event_type": "book", "last_trade_price": ""}, {"market": "0xe0a32dbfe006ba8c5031351f5243c5cd9a58cf3c37b566cc82a9f7d41f8302c7", "asset_id": "65815064799788774655435771148232734980061574308316816581700167067698511121921", "timestamp": "1769384353303", "hash": "14e3ab21dad78b71565d976f20e0f8e229c246c5", "bids": [{"price": "0.01", "size": "161.97"}, {"price": "0.02", "size": "43.72"}, {"price": "0.05", "size": "30"}, {"price": "0.06", "size": "43"}, {"price": "0.07", "size": "11.71"}, {"price": "0.1", "size": "70"}, {"price": "0.11", "size": "35"}, {"price": "0.12", "size": "118.75"}, {"price": "0.13", "size": "20"}], "asks": [{"price": "0.99", "size": "92.27"}, {"price": "0.98", "size": "100"}, {"price": "0.97", "size": "39.99"}], "event_type": "book", "last_trade_price": ""}, {"market": "0xb9d3c208d8eb2f3403144092d0e55a4ecf7a6493e33890b35140197a63148d14", "asset_id": "63581074489545967013426062325864715209547016020665245565255381968385916667995", "timestamp": "1769384329509", "hash": "614cf812a14315b52d46edcdb27ba674093ffbaa", "bids": [{"price": "0.01", "size": "150.58"}, {"price": "0.02", "size": "95"}, {"price": "0.03", "size": "39.99"}], "asks": [{"price": "0.99", "size": "172.06"}, {"price": "0.98", "size": "17.5"}, {"price": "0.97", "size": "10"}, {"price": "0.96", "size": "7.08"}, {"price": "0.95", "size": "30"}, {"price": "0.94", "size": "39.33"}, {"price": "0.92", "size": "17"}, {"price": "0.91", "size": "37.89"}, {"price": "0.9", "size": "40"}, {"price": "0.88", "size": "118.75"}, {"price": "0.87", "size": "20"}], "event_type": "book", "last_trade_price": ""}, {"market": "0xe0a32dbfe006ba8c5031351f5243c5cd9a58cf3c37b566cc82a9f7d41f8302c7", "asset_id": "4885632818167351187788551933410416061445761831692101146500029904141404303906", "timestamp": "1769384353303", "hash": "51c7c73f55dcaae86545632d36ab40bbc709c5b1", "bids": [{"price": "0.01", "size": "92.27"}, {"price": "0.02", "size": "100"}, {"price": "0.03", "size": "39.99"}], "asks": [{"price": "0.99", "size": "161.97"}, {"price": "0.98", "size": "43.72"}, {"price": "0.95", "size": "30"}, {"price": "0.94", "size": "43"}, {"price": "0.93", "size": "11.71"}, {"price": "0.9", "size": "70"}, {"price": "0.89", "size": "35"}, {"price": "0.88", "size": "118.75"}, {"price": "0.87", "size": "20"}], "event_type": "book", "last_trade_price": ""}, {"market": "0xfe76f366b01cffc5f3c2551ca2fafd3626551f8e67c45e90bcb9980fadefb1d9", "asset_id": "113047842163343397942154658230859519377162790695920966272941515248645143857449", "timestamp": "1769384353303", "hash": "7a0f8db1ddb595dba625faccf82a1ab05b9cf1a0", "bids": [{"price": "0.01", "size": "150.58"}, {"price": "0.02", "size": "100"}, {"price": "0.03", "size": "39.99"}], "asks": [{"price": "0.99", "size": "183.81"}, {"price": "0.98", "size": "17.67"}, {"price": "0.97", "size": "10"}, {"price": "0.96", "size": "8.04"}, {"price": "0.95", "size": "30"}, {"price": "0.94", "size": "38.58"}, {"price": "0.93", "size": "24"}, {"price": "0.92", "size": "8.95"}, {"price": "0.9", "size": "70"}, {"price": "0.88", "size": "118.75"}, {"price": "0.87", "size": "20"}], "event_type": "book", "last_trade_price": ""}, {"market": "0xa3476e8efbbc5557ff9f58978bcf85b7c2bc0c14d2f2c5891f1861a0e95c71c7", "asset_id": "77616069079544766632313130435803131534837904050680582581189964299844607679338", "timestamp": "1769384353303", "hash": "91bfbe46bd46ad1e6b9b23eccb675ed47f001040", "bids": [{"price": "0.01", "size": "171.68"}, {"price": "0.02", "size": "48.75"}, {"price": "0.05", "size": "30"}, {"price": "0.06", "size": "33"}, {"price": "0.07", "size": "16"}, {"price": "0.08", "size": "9.4"}, {"price": "0.1", "size": "70"}, {"price": "0.12", "size": "118.75"}, {"price": "0.13", "size": "10"}, {"price": "0.14", "size": "20"}], "asks": [{"price": "0.99", "size": "150.58"}, {"price": "0.98", "size": "100"}, {"price": "0.97", "size": "39.99"}], "event_type": "book", "last_trade_price": ""}, {"market": "0x225e0fdd1dbcf8d4ed569658e9fcdadc106fe4df8f3eebab6de3179594e69cae", "asset_id": "100614172146851019022930506261540059414109250163382945560610650412918760163014", "timestamp": "1769384321835", "hash": "0272e4dd9848f7c8b619807b1c3ce823ed01b212", "bids": [{"price": "0.001", "size": "14333.94"}, {"price": "0.002", "size": "262.98"}, {"price": "0.003", "size": "66.47"}, {"price": "0.004", "size": "55.22"}, {"price": "0.01", "size": "50"}, {"price": "0.011", "size": "210.77"}, {"price": "0.012", "size": "155.1"}, {"price": "0.013", "size": "39.75"}, {"price": "0.014", "size": "6.17"}, {"price": "0.02", "size": "25"}, {"price": "0.022", "size": "65.44"}], "asks": [{"price": "0.999", "size": "5006.85"}, {"price": "0.998", "size": "457.29"}, {"price": "0.997", "size": "43.36"}, {"price": "0.99", "size": "55"}, {"price": "0.989", "size": "200"}, {"price": "0.988", "size": "43.66"}, {"price": "0.984", "size": "9"}, {"price": "0.95", "size": "30"}, {"price": "0.94", "size": "33"}, {"price": "0.938", "size": "40"}, {"price": "0.936", "size": "30"}, {"price": "0.935", "size": "6.57"}, {"price": "0.893", "size": "5.98"}, {"price": "0.872", "size": "15"}, {"price": "0.87", "size": "59"}, {"price": "0.869", "size": "10"}, {"price": "0.868", "size": "20"}, {"price": "0.08", "size": "20"}], "event_type": "book", "last_trade_price": ""}, {"market": "0x225e0fdd1dbcf8d4ed569658e9fcdadc106fe4df8f3eebab6de3179594e69cae", "asset_id": "45764625730845095130147096446415799271154137683585606059451270337639906719390", "timestamp": "1769384321835", "hash": "2d8cbcab4268e02e21a7307f7327c5611e9bd1fa", "bids": [{"price": "0.001", "size": "5006.85"}, {"price": "0.002", "size": "457.29"}, {"price": "0.003", "size": "43.36"}, {"price": "0.01", "size": "55"}, {"price": "0.011", "size": "200"}, {"price": "0.012", "size": "43.66"}, {"price": "0.016", "size": "9"}, {"price": "0.05", "size": "30"}, {"price": "0.06", "size": "33"}, {"price": "0.062", "size": "40"}, {"price": "0.064", "size": "30"}, {"price": "0.065", "size": "6.57"}, {"price": "0.107", "size": "5.98"}, {"price": "0.128", "size": "15"}, {"price": "0.13", "size": "59"}, {"price": "0.131", "size": "10"}, {"price": "0.132", "size": "20"}, {"price": "0.92", "size": "20"}], "asks": [{"price": "0.999", "size": "14333.94"}, {"price": "0.998", "size": "262.98"}, {"price": "0.997", "size": "66.47"}, {"price": "0.996", "size": "55.22"}, {"price": "0.99", "size": "50"}, {"price": "0.989", "size": "210.77"}, {"price": "0.988", "size": "155.1"}, {"price": "0.987", "size": "39.75"}, {"price": "0.986", "size": "6.17"}, {"price": "0.98", "size": "25"}, {"price": "0.978", "size": "65.44"}], "event_type": "book", "last_trade_price": ""}]}
{"_local_timestamp": "2026-01-25T23:40:52.894386+00:00", "data": {"market": "0xb9d3c208d8eb2f3403144092d0e55a4ecf7a6493e33890b35140197a63148d14", "price_changes": [{"asset_id": "70717802646694382009573815278721437797667570104667888155891561185095387198938", "price": "0.17", "size": "20", "side": "BUY", "hash": "fac5ab3639780c48015335d0727d8692323a51c8", "best_bid": "0.17", "best_ask": "0.97"}, {"asset_id": "63581074489545967013426062325864715209547016020665245565255381968385916667995", "price": "0.83", "size": "20", "side": "SELL", "hash": "8dba3ee48cff315ae2983c3316982ca7a4a8f836", "best_bid": "0.03", "best_ask": "0.83"}], "timestamp": "1769384452828", "event_type": "price_change"}}
{"_local_timestamp": "2026-01-25T23:41:02.924071+00:00", "data": {"market": "0xfe76f366b01cffc5f3c2551ca2fafd3626551f8e67c45e90bcb9980fadefb1d9", "price_changes": [{"asset_id": "91464103984107757678948958563250156809345102931554507444370450055330522832734", "price": "0.17", "size": "20", "side": "BUY", "hash": "4da8ffab82953ffae1d5bfe3471654b0ef6d5b6d", "best_bid": "0.17", "best_ask": "0.97"}, {"asset_id": "113047842163343397942154658230859519377162790695920966272941515248645143857449", "price": "0.83", "size": "20", "side": "SELL", "hash": "27691fecf2fc3e41ddfb9586d77b47ccf2187efd", "best_bid": "0.03", "best_ask": "0.83"}], "timestamp": "1769384462840", "event_type": "price_change"}}
{"_local_timestamp": "2026-01-25T23:41:06.790384+00:00", "data": {"market": "0x225e0fdd1dbcf8d4ed569658e9fcdadc106fe4df8f3eebab6de3179594e69cae", "price_changes": [{"asset_id": "45764625730845095130147096446415799271154137683585606059451270337639906719390", "price": "0.002", "size": "357.29", "side": "BUY", "hash": "5ef217eb1e015c69e0f1b31ff3e0203a9f29abd6", "best_bid": "0.92", "best_ask": "0.978"}, {"asset_id": "100614172146851019022930506261540059414109250163382945560610650412918760163014", "price": "0.998", "size": "357.29", "side": "SELL", "hash": "45ddb4eecb9e0c4ae5330a1bf55fae9b26b92898", "best_bid": "0.022", "best_ask": "0.08"}], "timestamp": "1769384466639", "event_type": "price_change"}}
{"_local_timestamp": "2026-01-25T23:41:06.810089+00:00", "data": {"market": "0x225e0fdd1dbcf8d4ed569658e9fcdadc106fe4df8f3eebab6de3179594e69cae", "price_changes": [{"asset_id": "100614172146851019022930506261540059414109250163382945560610650412918760163014", "price": "0.002", "size": "162.98", "side": "BUY", "hash": "d28900679f6dd689924471ecbaf9b9f66d53463c", "best_bid": "0.022", "best_ask": "0.08"}, {"asset_id": "45764625730845095130147096446415799271154137683585606059451270337639906719390", "price": "0.998", "size": "162.98", "side": "SELL", "hash": "c8b3f9a6e312b5ccab76b9d0c50a267cfadf1cc8", "best_bid": "0.92", "best_ask": "0.978"}], "timestamp": "1769384466647", "event_type": "price_change"}}
{"_local_timestamp": "2026-01-25T23:41:17.992529+00:00", "data": {"market": "0xe0a32dbfe006ba8c5031351f5243c5cd9a58cf3c37b566cc82a9f7d41f8302c7", "price_changes": [{"asset_id": "65815064799788774655435771148232734980061574308316816581700167067698511121921", "price": "0.18", "size": "20", "side": "BUY", "hash": "7232434dc323b1647787e4d10372ec6fa107cc24", "best_bid": "0.18", "best_ask": "0.97"}, {"asset_id": "4885632818167351187788551933410416061445761831692101146500029904141404303906", "price": "0.82", "size": "20", "side": "SELL", "hash": "871fd9a67d4f7b8fd2c29f570f208cfd33f74bbd", "best_bid": "0.03", "best_ask": "0.82"}], "timestamp": "1769384477868", "event_type": "price_change"}}
{"_local_timestamp": "2026-01-25T23:41:22.902426+00:00", "data": {"market": "0xf69b405cb72c495b47f14d4581ec5f4fdc32c7c783c0b05c5d350af99f74fb57", "price_changes": [{"asset_id": "111483763262460809812427616008076634438113457835729033090496924816271676966924", "price": "0.2", "size": "20", "side": "BUY", "hash": "c23cb3cbb6390f3f4f40c109b832b93aeebf3b2f", "best_bid": "0.2", "best_ask": "0.97"}, {"asset_id": "77871459748036421242663925334747383360075298582158881700736355568100463986230", "price": "0.8", "size": "20", "side": "SELL", "hash": "84ce7c55fb6dba3b25511aa3108015b17500d93e", "best_bid": "0.03", "best_ask": "0.8"}], "timestamp": "1769384482830", "event_type": "price_change"}}
{"_local_timestamp": "2026-01-25T23:41:32.960047+00:00", "data": {"market": "0xa3476e8efbbc5557ff9f58978bcf85b7c2bc0c14d2f2c5891f1861a0e95c71c7", "price_changes": [{"asset_id": "77616069079544766632313130435803131534837904050680582581189964299844607679338", "price": "0.2", "size": "20", "side": "BUY", "hash": "b44a880514b558bd324ef4fcc345d90aa2abc2c7", "best_bid": "0.2", "best_ask": "0.97"}, {"asset_id": "49075166570883369230840079099601560361862864964529664437077360133815011449025", "price": "0.8", "size": "20", "side": "SELL", "hash": "c29b42cf5b5d28e6e4d9eb4866b49693ad0457a8", "best_bid": "0.03", "best_ask": "0.8"}], "timestamp": "1769384492859", "event_type": "price_change"}}
{"_local_timestamp": "2026-01-25T23:41:37.903235+00:00", "data": {"market": "0x93f28d0ad9d5906fee37296a8a70a57c9e4ed4b3b9aa09029c2d9589ce7ce832", "price_changes": [{"asset_id": "72776331054793272806940188908180904666024448478022907801009755847830868970904", "price": "0.19", "size": "20", "side": "BUY", "hash": "0987d1829bc987217f9497434ef74d792b226325", "best_bid": "0.19", "best_ask": "0.97"}, {"asset_id": "100955895305218895610069502472760899905214942330703669753760270178117749789092", "price": "0.81", "size": "20", "side": "SELL", "hash": "238272a876fa27f44097487fd7a462fcb1504e2d", "best_bid": "0.03", "best_ask": "0.81"}], "timestamp": "1769384497834", "event_type": "price_change"}}
{"_local_timestamp": "2026-01-25T23:41:49.052427+00:00", "data": {"market": "0xa3476e8efbbc5557ff9f58978bcf85b7c2bc0c14d2f2c5891f1861a0e95c71c7", "price_changes": [{"asset_id": "77616069079544766632313130435803131534837904050680582581189964299844607679338", "price": "0.12", "size": "0", "side": "BUY", "hash": "caf3c3cdf14e50a3248598438b6216674698b086", "best_bid": "0.2", "best_ask": "0.97"}, {"asset_id": "49075166570883369230840079099601560361862864964529664437077360133815011449025", "price": "0.88", "size": "0", "side": "SELL", "hash": "5770cee2f1f0917921c4cb34c9445ed3406bd423", "best_bid": "0.03", "best_ask": "0.8"}], "timestamp": "1769384508969", "event_type": "price_change"}}
{"_local_timestamp": "2026-01-25T23:42:26.772705+00:00", "data": {"market": "0xa3476e8efbbc5557ff9f58978bcf85b7c2bc0c14d2f2c5891f1861a0e95c71c7", "price_changes": [{"asset_id": "77616069079544766632313130435803131534837904050680582581189964299844607679338", "price": "0.02", "size": "28.67", "side": "BUY", "hash": "9650900c015f577bb5f517ab8d133d77602989d6", "best_bid": "0.2", "best_ask": "0.97"}, {"asset_id": "49075166570883369230840079099601560361862864964529664437077360133815011449025", "price": "0.98", "size": "28.67", "side": "SELL", "hash": "52559fcbafc947e3f5cadaa8c3cd620a5036c49d", "best_bid": "0.03", "best_ask": "0.8"}], "timestamp": "1769384546663", "event_type": "price_change"}}
{"_local_timestamp": "2026-01-25T23:42:26.774737+00:00", "data": {"market": "0xa3476e8efbbc5557ff9f58978bcf85b7c2bc0c14d2f2c5891f1861a0e95c71c7", "price_changes": [{"asset_id": "77616069079544766632313130435803131534837904050680582581189964299844607679338", "price": "0.08", "size": "0", "side": "BUY", "hash": "9650900c015f577bb5f517ab8d133d77602989d6", "best_bid": "0.2", "best_ask": "0.97"}, {"asset_id": "49075166570883369230840079099601560361862864964529664437077360133815011449025", "price": "0.92", "size": "0", "side": "SELL", "hash": "52559fcbafc947e3f5cadaa8c3cd620a5036c49d", "best_bid": "0.03", "best_ask": "0.8"}], "timestamp": "1769384546663", "event_type": "price_change"}}
{"_local_timestamp": "2026-01-25T23:42:26.775069+00:00", "data": {"market": "0x225e0fdd1dbcf8d4ed569658e9fcdadc106fe4df8f3eebab6de3179594e69cae", "price_changes": [{"asset_id": "45764625730845095130147096446415799271154137683585606059451270337639906719390", "price": "0.016", "size": "0", "side": "BUY", "hash": "4938a57d171655b7dab0748009d88b3a4f14a82c", "best_bid": "0.92", "best_ask": "0.978"}, {"asset_id": "100614172146851019022930506261540059414109250163382945560610650412918760163014", "price": "0.984", "size": "0", "side": "SELL", "hash": "a8a3dca57273b2efa00d07fde05ac1d20e4cfc88", "best_bid": "0.022", "best_ask": "0.08"}], "timestamp": "1769384546662", "event_type": "price_change"}}
{"_local_timestamp": "2026-01-25T23:42:26.775348+00:00", "data": {"market": "0x225e0fdd1dbcf8d4ed569658e9fcdadc106fe4df8f3eebab6de3179594e69cae", "price_changes": [{"asset_id": "45764625730845095130147096446415799271154137683585606059451270337639906719390", "price": "0.107", "size": "0", "side": "BUY", "hash": "4938a57d171655b7dab0748009d88b3a4f14a82c", "best_bid": "0.92", "best_ask": "0.978"}, {"asset_id": "100614172146851019022930506261540059414109250163382945560610650412918760163014", "price": "0.893", "size": "0", "side": "SELL", "hash": "a8a3dca57273b2efa00d07fde05ac1d20e4cfc88", "best_bid": "0.022", "best_ask": "0.08"}], "timestamp": "1769384546662", "event_type": "price_change"}}
{"_local_timestamp": "2026-01-25T23:42:28.459293+00:00", "data": {"market": "0xa3476e8efbbc5557ff9f58978bcf85b7c2bc0c14d2f2c5891f1861a0e95c71c7", "price_changes": [{"asset_id": "77616069079544766632313130435803131534837904050680582581189964299844607679338", "price": "0.07", "size": "22.13", "side": "BUY", "hash": "8e1dcabd31d5dab775e58a48a1f40aceb365640a", "best_bid": "0.2", "best_ask": "0.97"}, {"asset_id": "49075166570883369230840079099601560361862864964529664437077360133815011449025", "price": "0.93", "size": "22.13", "side": "SELL", "hash": "dc5093c990a25305d766dd148bee6d6c1b98b03e", "best_bid": "0.03", "best_ask": "0.8"}], "timestamp": "1769384548368", "event_type": "price_change"}}
{"_local_timestamp": "2026-01-25T23:42:28.459688+00:00", "data": {"market": "0x225e0fdd1dbcf8d4ed569658e9fcdadc106fe4df8f3eebab6de3179594e69cae", "price_changes": [{"asset_id": "45764625730845095130147096446415799271154137683585606059451270337639906719390", "price": "0.065", "size": "16.41", "side": "BUY", "hash": "289470a8c654b570860c2406bb6f65914abe3529", "best_bid": "0.92", "best_ask": "0.978"}, {"asset_id": "100614172146851019022930506261540059414109250163382945560610650412918760163014", "price": "0.935", "size": "16.41", "side": "SELL", "hash": "dcba6faf0926f80302e9f771c5063fb944818735", "best_bid": "0.022", "best_ask": "0.08"}], "timestamp": "1769384548368", "event_type": "price_change"}}
{"_local_timestamp": "2026-01-25T23:42:28.459998+00:00", "data": {"market": "0x225e0fdd1dbcf8d4ed569658e9fcdadc106fe4df8f3eebab6de3179594e69cae", "price_changes": [{"asset_id": "45764625730845095130147096446415799271154137683585606059451270337639906719390", "price": "0.012", "size": "55.66", "side": "BUY", "hash": "aa34c5586a0c47d2346512b486d70f1ae522bfad", "best_bid": "0.92", "best_ask": "0.978"}, {"asset_id": "100614172146851019022930506261540059414109250163382945560610650412918760163014", "price": "0.988", "size": "55.66", "side": "SELL", "hash": "fbc2732dc5c74270adde5e57d31553b980a6a218", "best_bid": "0.022", "best_ask": "0.08"}], "timestamp": "1769384548369", "event_type": "price_change"}}
{"_local_timestamp": "2026-01-25T23:42:28.460290+00:00", "data": {"market": "0xa3476e8efbbc5557ff9f58978bcf85b7c2bc0c14d2f2c5891f1861a0e95c71c7", "price_changes": [{"asset_id": "77616069079544766632313130435803131534837904050680582581189964299844607679338", "price": "0.11", "size": "6.59", "side": "BUY", "hash": "f4d69aa976fd7a35bd25c4093a9fe4f6671d35ba", "best_bid": "0.2", "best_ask": "0.97"}, {"asset_id": "49075166570883369230840079099601560361862864964529664437077360133815011449025", "price": "0.89", "size": "6.59", "side": "SELL", "hash": "2989640922cff188edf080703c3b3c6fe1284c00", "best_bid": "0.03", "best_ask": "0.8"}], "timestamp": "1769384548369", "event_type": "price_change"}}
{"_local_timestamp": "2026-01-25T23:42:28.601789+00:00", "data": {"market": "0xf69b405cb72c495b47f14d4581ec5f4fdc32c7c783c0b05c5d350af99f74fb57", "price_changes": [{"asset_id": "111483763262460809812427616008076634438113457835729033090496924816271676966924", "price": "0.1", "size": "70", "side": "BUY", "hash": "8b841156e44ab57d6768c93d56c97db46eea7980", "best_bid": "0.2", "best_ask": "0.97"}, {"asset_id": "77871459748036421242663925334747383360075298582158881700736355568100463986230", "price": "0.9", "size": "70", "side": "SELL", "hash": "a024bb61a2e68289457e24f87272f88537301065", "best_bid": "0.03", "best_ask": "0.8"}], "timestamp": "1769384548503", "event_type": "price_change"}}
{"_local_timestamp": "2026-01-25T23:42:28.602166+00:00", "data": {"market": "0x93f28d0ad9d5906fee37296a8a70a57c9e4ed4b3b9aa09029c2d9589ce7ce832", "price_changes": [{"asset_id": "72776331054793272806940188908180904666024448478022907801009755847830868970904", "price": "0.03", "size": "0", "side": "BUY", "hash": "6176d6c31c2fd5731a739f539ed439e0a53742b1", "best_bid": "0.19", "best_ask": "0.97"}, {"asset_id": "100955895305218895610069502472760899905214942330703669753760270178117749789092", "price": "0.97", "size": "0", "side": "SELL", "hash": "76ef2ce8e365194123ebd3b5cec3d69f39d1aff9", "best_bid": "0.03", "best_ask": "0.81"}], "timestamp": "1769384548503", "event_type": "price_change"}}
{"_local_timestamp": "2026-01-25T23:42:28.602462+00:00", "data": {"market": "0x93f28d0ad9d5906fee37296a8a70a57c9e4ed4b3b9aa09029c2d9589ce7ce832", "price_changes": [{"asset_id": "72776331054793272806940188908180904666024448478022907801009755847830868970904", "price": "0.05", "size": "30", "side": "BUY", "hash": "6176d6c31c2fd5731a739f539ed439e0a53742b1", "best_bid": "0.19", "best_ask": "0.97"}, {"asset_id": "100955895305218895610069502472760899905214942330703669753760270178117749789092", "price": "0.95", "size": "30", "side": "SELL", "hash": "76ef2ce8e365194123ebd3b5cec3d69f39d1aff9", "best_bid": "0.03", "best_ask": "0.81"}], "timestamp": "1769384548503", "event_type": "price_change"}}
{"_local_timestamp": "2026-01-25T23:42:28.602772+00:00", "data": {"market": "0x93f28d0ad9d5906fee37296a8a70a57c9e4ed4b3b9aa09029c2d9589ce7ce832", "price_changes": [{"asset_id": "72776331054793272806940188908180904666024448478022907801009755847830868970904", "price": "0.1", "size": "0", "side": "BUY", "hash": "6176d6c31c2fd5731a739f539ed439e0a53742b1", "best_bid": "0.19", "best_ask": "0.97"}, {"asset_id": "100955895305218895610069502472760899905214942330703669753760270178117749789092", "price": "0.9", "size": "0", "side": "SELL", "hash": "76ef2ce8e365194123ebd3b5cec3d69f39d1aff9", "best_bid": "0.03", "best_ask": "0.81"}], "timestamp": "1769384548503", "event_type": "price_change"}}
{"_local_timestamp": "2026-01-25T23:42:29.059467+00:00", "data": {"market": "0xb9d3c208d8eb2f3403144092d0e55a4ecf7a6493e33890b35140197a63148d14", "price_changes": [{"asset_id": "70717802646694382009573815278721437797667570104667888155891561185095387198938", "price": "0.06", "size": "33", "side": "BUY", "hash": "7c67765a853edea00987093737f191ad315061bc", "best_bid": "0.17", "best_ask": "0.97"}, {"asset_id": "63581074489545967013426062325864715209547016020665245565255381968385916667995", "price": "0.94", "size": "33", "side": "SELL", "hash": "4b06edb659b9a301e13d293b876df499e25cb248", "best_bid": "0.03", "best_ask": "0.83"}], "timestamp": "1769384548948", "event_type": "price_change"}}
{"_local_timestamp": "2026-01-25T23:42:29.059889+00:00", "data": {"market": "0xfe76f366b01cffc5f3c2551ca2fafd3626551f8e67c45e90bcb9980fadefb1d9", "price_changes": [{"asset_id": "91464103984107757678948958563250156809345102931554507444370450055330522832734", "price": "0.06", "size": "33", "side": "BUY", "hash": "d53c03d7a9848fd8bf27dab9bf19b4dbce4352c5", "best_bid": "0.17", "best_ask": "0.97"}, {"asset_id": "113047842163343397942154658230859519377162790695920966272941515248645143857449", "price": "0.94", "size": "33", "side": "SELL", "hash": "5efaddce49b5b107c7b014977762dabe9fced6f3", "best_bid": "0.03", "best_ask": "0.83"}], "timestamp": "1769384548947", "event_type": "price_change"}}
{"_local_timestamp": "2026-01-25T23:42:29.060227+00:00", "data": {"market": "0xb9d3c208d8eb2f3403144092d0e55a4ecf7a6493e33890b35140197a63148d14", "price_changes": [{"asset_id": "70717802646694382009573815278721437797667570104667888155891561185095387198938", "price": "0.09", "size": "30", "side": "BUY", "hash": "7c67765a853edea00987093737f191ad315061bc", "best_bid": "0.17", "best_ask": "0.97"}, {"asset_id": "63581074489545967013426062325864715209547016020665245565255381968385916667995", "price": "0.91", "size": "30", "side": "SELL", "hash": "4b06edb659b9a301e13d293b876df499e25cb248", "best_bid": "0.03", "best_ask": "0.83"}], "timestamp": "1769384548948", "event_type": "price_change"}}
{"_local_timestamp": "2026-01-25T23:42:29.060563+00:00", "data": {"market": "0xfe76f366b01cffc5f3c2551ca2fafd3626551f8e67c45e90bcb9980fadefb1d9", "price_changes": [{"asset_id": "91464103984107757678948958563250156809345102931554507444370450055330522832734", "price": "0.08", "size": "0", "side": "BUY", "hash": "d53c03d7a9848fd8bf27dab9bf19b4dbce4352c5", "best_bid": "0.17", "best_ask": "0.97"}, {"asset_id": "113047842163343397942154658230859519377162790695920966272941515248645143857449", "price": "0.92", "size": "0", "side": "SELL", "hash": "5efaddce49b5b107c7b014977762dabe9fced6f3", "best_bid": "0.03", "best_ask": "0.83"}], "timestamp": "1769384548947", "event_type": "price_change"}}
{"_local_timestamp": "2026-01-25T23:42:29.060882+00:00", "data": {"market": "0xe0a32dbfe006ba8c5031351f5243c5cd9a58cf3c37b566cc82a9f7d41f8302c7", "price_changes": [{"asset_id": "65815064799788774655435771148232734980061574308316816581700167067698511121921", "price": "0.01", "size": "154.31", "side": "BUY", "hash": "65ff320e3e3510e5c1852c5be5acf666c9077a07", "best_bid": "0.18", "best_ask": "0.97"}, {"asset_id": "4885632818167351187788551933410416061445761831692101146500029904141404303906", "price": "0.99", "size": "154.31", "side": "SELL", "hash": "1b7b753ab6a23e7433e689b48c70521ca800208d", "best_bid": "0.03", "best_ask": "0.82"}], "timestamp": "1769384548948", "event_type": "price_change"}}
{"_local_timestamp": "2026-01-25T23:42:29.061206+00:00", "data": {"market": "0xe0a32dbfe006ba8c5031351f5243c5cd9a58cf3c37b566cc82a9f7d41f8302c7", "price_changes": [{"asset_id": "65815064799788774655435771148232734980061574308316816581700167067698511121921", "price": "0.02", "size": "29", "side": "BUY", "hash": "65ff320e3e3510e5c1852c5be5acf666c9077a07", "best_bid": "0.18", "best_ask": "0.97"}, {"asset_id": "4885632818167351187788551933410416061445761831692101146500029904141404303906", "price": "0.98", "size": "29", "side": "SELL", "hash": "1b7b753ab6a23e7433e689b48c70521ca800208d", "best_bid": "0.03", "best_ask": "0.82"}], "timestamp": "1769384548948", "event_type": "price_change"}}
{"_local_timestamp": "2026-01-25T23:42:29.061570+00:00", "data": {"market": "0xe0a32dbfe006ba8c5031351f5243c5cd9a58cf3c37b566cc82a9f7d41f8302c7", "price_changes": [{"asset_id": "65815064799788774655435771148232734980061574308316816581700167067698511121921", "price": "0.07", "size": "0", "side": "BUY", "hash": "65ff320e3e3510e5c1852c5be5acf666c9077a07", "best_bid": "0.18", "best_ask": "0.97"}, {"asset_id": "4885632818167351187788551933410416061445761831692101146500029904141404303906", "price": "0.93", "size": "0", "side": "SELL", "hash": "1b7b753ab6a23e7433e689b48c70521ca800208d", "best_bid": "0.03", "best_ask": "0.82"}], "timestamp": "1769384548948", "event_type": "price_change"}}
{"_local_timestamp": "2026-01-25T23:42:29.204810+00:00", "data": {"market": "0x25025db13d5868308eb2f1f57beaf7cbea76c4014201800853a4c1aaad3046ee", "price_changes": [{"asset_id": "69171629149106323292749070292707293928031973221371003911300207535275094378436", "price": "0.12", "size": "5.83", "side": "BUY", "hash": "9d070908329cd5042f6441002a4afa74a2a79a30", "best_bid": "0.72", "best_ask": "0.97"}, {"asset_id": "15113128431693879081528076048684622701923990563320934711420493231791911133880", "price": "0.88", "size": "5.83", "side": "SELL", "hash": "d878c97b815859a43fc42563c13fd1c451132fa3", "best_bid": "0.03", "best_ask": "0.28"}], "timestamp": "1769384549103", "event_type": "price_change"}}
{"_local_timestamp": "2026-01-25T23:42:29.674742+00:00", "data": {"market": "0xf69b405cb72c495b47f14d4581ec5f4fdc32c7c783c0b05c5d350af99f74fb57", "price_changes": [{"asset_id": "111483763262460809812427616008076634438113457835729033090496924816271676966924", "price": "0.11", "size": "5.99", "side": "BUY", "hash": "8d92581e10be7fe886349943cf611513dd2c5b08", "best_bid": "0.2", "best_ask": "0.97"}, {"asset_id": "77871459748036421242663925334747383360075298582158881700736355568100463986230", "price": "0.89", "size": "5.99", "side": "SELL", "hash": "b32a177b9cb0f67da9cf49e6bd7da3845882ff24", "best_bid": "0.03", "best_ask": "0.8"}], "timestamp": "1769384549584", "event_type": "price_change"}}
{"_local_timestamp": "2026-01-25T23:42:29.675247+00:00", "data": {"market": "0x93f28d0ad9d5906fee37296a8a70a57c9e4ed4b3b9aa09029c2d9589ce7ce832", "price_changes": [{"asset_id": "72776331054793272806940188908180904666024448478022907801009755847830868970904", "price": "0.11", "size": "5.51", "side": "BUY", "hash": "07197b171df8f9b8d73ff2d6c7fa1f535c0b6e93", "best_bid": "0.19", "best_ask": "0.97"}, {"asset_id": "100955895305218895610069502472760899905214942330703669753760270178117749789092", "price": "0.89", "size": "5.51", "side": "SELL", "hash": "9ab282316c2ec40ecfb381e1b16c92751fedb1da", "best_bid": "0.03", "best_ask": "0.81"}], "timestamp": "1769384549584", "event_type": "price_change"}}
{"_local_timestamp": "2026-01-25T23:42:29.676133+00:00", "data": {"market": "0x93f28d0ad9d5906fee37296a8a70a57c9e4ed4b3b9aa09029c2d9589ce7ce832", "price_changes": [{"asset_id": "72776331054793272806940188908180904666024448478022907801009755847830868970904", "price": "0.07", "size": "5.65", "side": "BUY", "hash": "15c49cfad8d9cd0f9a4c271692cda9bb971f597f", "best_bid": "0.19", "best_ask": "0.97"}, {"asset_id": "100955895305218895610069502472760899905214942330703669753760270178117749789092", "price": "0.93", "size": "5.65", "side": "SELL", "hash": "2c80fd010ae95912b5f340f8a91b5cb04d9cfcc8", "best_bid": "0.03", "best_ask": "0.81"}], "timestamp": "1769384549585", "event_type": "price_change"}}
{"_local_timestamp": "2026-01-25T23:42:29.676488+00:00", "data": {"market": "0x93f28d0ad9d5906fee37296a8a70a57c9e4ed4b3b9aa09029c2d9589ce7ce832", "price_changes": [{"asset_id": "72776331054793272806940188908180904666024448478022907801009755847830868970904", "price": "0.04", "size": "7.69", "side": "BUY", "hash": "d9708915df94787fd8d077750483cb241783d172", "best_bid": "0.19", "best_ask": "0.97"}, {"asset_id": "100955895305218895610069502472760899905214942330703669753760270178117749789092", "price": "0.96", "size": "7.69", "side": "SELL", "hash": "afbd3d94429ab328482a426685d6b22fe7dbe740", "best_bid": "0.03", "best_ask": "0.81"}], "timestamp": "1769384549586", "event_type": "price_change"}}
{"_local_timestamp": "2026-01-25T23:42:32.427992+00:00", "data": {"market": "0xe0a32dbfe006ba8c5031351f5243c5cd9a58cf3c37b566cc82a9f7d41f8302c7", "price_changes": [{"asset_id": "65815064799788774655435771148232734980061574308316816581700167067698511121921", "price": "0.07", "size": "6.54", "side": "BUY", "hash": "9cfc25902a6970d0ff1ea667fbb886b103bc0ca4", "best_bid": "0.18", "best_ask": "0.97"}, {"asset_id": "4885632818167351187788551933410416061445761831692101146500029904141404303906", "price": "0.93", "size": "6.54", "side": "SELL", "hash": "04f26f75c6862cdf624af97e2d7140653397d88a", "best_bid": "0.03", "best_ask": "0.82"}], "timestamp": "1769384552306", "event_type": "price_change"}}
{"_local_timestamp": "2026-01-25T23:42:32.428558+00:00", "data": {"market": "0xfe76f366b01cffc5f3c2551ca2fafd3626551f8e67c45e90bcb9980fadefb1d9", "price_changes": [{"asset_id": "91464103984107757678948958563250156809345102931554507444370450055330522832734", "price": "0.07", "size": "37.36", "side": "BUY", "hash": "ab538aca65e0697448b34403496382ef2a710f72", "best_bid": "0.17", "best_ask": "0.97"}, {"asset_id": "113047842163343397942154658230859519377162790695920966272941515248645143857449", "price": "0.93", "size": "37.36", "side": "SELL", "hash": "fb82e007d405ca4314feb3d3b1296c217d8adcde", "best_bid": "0.03", "best_ask": "0.83"}], "timestamp": "1769384552306", "event_type": "price_change"}}
{"_local_timestamp": "2026-01-25T23:42:32.428997+00:00", "data": {"market": "0xb9d3c208d8eb2f3403144092d0e55a4ecf7a6493e33890b35140197a63148d14", "price_changes": [{"asset_id": "70717802646694382009573815278721437797667570104667888155891561185095387198938", "price": "0.11", "size": "5.4", "side": "BUY", "hash": "4cd6ff9efbe6a404686208e553fff77c4c048856", "best_bid": "0.17", "best_ask": "0.97"}, {"asset_id": "63581074489545967013426062325864715209547016020665245565255381968385916667995", "price": "0.89", "size": "5.4", "side": "SELL", "hash": "289b984f85efb6c2ef16d9fede9adfdb08460033", "best_bid": "0.03", "best_ask": "0.83"}], "timestamp": "1769384552306", "event_type": "price_change"}}
{"_local_timestamp": "2026-01-25T23:42:32.430101+00:00", "data": {"market": "0xe0a32dbfe006ba8c5031351f5243c5cd9a58cf3c37b566cc82a9f7d41f8302c7", "price_changes": [{"asset_id": "65815064799788774655435771148232734980061574308316816581700167067698511121921", "price": "0.02", "size": "34.27", "side": "BUY", "hash": "acbeb7013cb9678294ff26706f1a09032d10d1e2", "best_bid": "0.18", "best_ask": "0.97"}, {"asset_id": "4885632818167351187788551933410416061445761831692101146500029904141404303906", "price": "0.98", "size": "34.27", "side": "SELL", "hash": "49ba974f259215673fe3aed8e366fac1d9d2fbe5", "best_bid": "0.03", "best_ask": "0.82"}], "timestamp": "1769384552307", "event_type": "price_change"}}
{"_local_timestamp": "2026-01-25T23:42:32.430524+00:00", "data": {"market": "0xb9d3c208d8eb2f3403144092d0e55a4ecf7a6493e33890b35140197a63148d14", "price_changes": [{"asset_id": "70717802646694382009573815278721437797667570104667888155891561185095387198938", "price": "0.07", "size": "7.08", "side": "BUY", "hash": "0c4c6717ac4b96973cd6bdc13965c3904ef50dd1", "best_bid": "0.17", "best_ask": "0.97"}, {"asset_id": "63581074489545967013426062325864715209547016020665245565255381968385916667995", "price": "0.93", "size": "7.08", "side": "SELL", "hash": "032175720dcbbd5c558e057925805278495e90f3", "best_bid": "0.03", "best_ask": "0.83"}], "timestamp": "1769384552307", "event_type": "price_change"}}
{"_local_timestamp": "2026-01-25T23:42:32.431883+00:00", "data": {"market": "0xfe76f366b01cffc5f3c2551ca2fafd3626551f8e67c45e90bcb9980fadefb1d9", "price_changes": [{"asset_id": "91464103984107757678948958563250156809345102931554507444370450055330522832734", "price": "0.02", "size": "23.47", "side": "BUY", "hash": "a52ddc0df7177c5046ae939a0160e8f0bce6dbcc", "best_bid": "0.17", "best_ask": "0.97"}, {"asset_id": "113047842163343397942154658230859519377162790695920966272941515248645143857449", "price": "0.98", "size": "23.47", "side": "SELL", "hash": "8a676c75bb65b1f3f4a040dc5968e60038741ae7", "best_bid": "0.03", "best_ask": "0.83"}], "timestamp": "1769384552307", "event_type": "price_change"}}
{"_local_timestamp": "2026-01-25T23:42:32.433557+00:00", "data": {"market": "0xe0a32dbfe006ba8c5031351f5243c5cd9a58cf3c37b566cc82a9f7d41f8302c7", "price_changes": [{"asset_id": "65815064799788774655435771148232734980061574308316816581700167067698511121921", "price": "0.11", "size": "40.7", "side": "BUY", "hash": "765d5ea9ac43f7a2b9c8bdd8384ececc8e9f7230", "best_bid": "0.18", "best_ask": "0.97"}, {"asset_id": "4885632818167351187788551933410416061445761831692101146500029904141404303906", "price": "0.89", "size": "40.7", "side": "SELL", "hash": "8c18e2957b82ea4f1312eb85bf1853ebd208019a", "best_bid": "0.03", "best_ask": "0.82"}], "timestamp": "1769384552308", "event_type": "price_change"}}
{"_local_timestamp": "2026-01-25T23:43:00.186203+00:00", "data": {"market": "0xa3476e8efbbc5557ff9f58978bcf85b7c2bc0c14d2f2c5891f1861a0e95c71c7", "price_changes": [{"asset_id": "49075166570883369230840079099601560361862864964529664437077360133815011449025", "price": "0.02", "size": "125", "side": "BUY", "hash": "eab581d97b1b3588272e5fe3f4328543341f293a", "best_bid": "0.03", "best_ask": "0.8"}, {"asset_id": "77616069079544766632313130435803131534837904050680582581189964299844607679338", "price": "0.98", "size": "125", "side": "SELL", "hash": "c57b0ca42d44b2fe61075b33b08222fc0ba06fe6", "best_bid": "0.2", "best_ask": "0.97"}], "timestamp": "1769384580070", "event_type": "price_change"}}
{"_local_timestamp": "2026-01-25T23:43:01.204403+00:00", "data": {"market": "0xf69b405cb72c495b47f14d4581ec5f4fdc32c7c783c0b05c5d350af99f74fb57", "price_changes": [{"asset_id": "77871459748036421242663925334747383360075298582158881700736355568100463986230", "price": "0.02", "size": "120", "side": "BUY", "hash": "6961a36476de5383a73be42597d27c7de1a9ba1a", "best_bid": "0.03", "best_ask": "0.8"}, {"asset_id": "111483763262460809812427616008076634438113457835729033090496924816271676966924", "price": "0.98", "size": "120", "side": "SELL", "hash": "bdc6669ccad484bea5a0c2bbad3c0f42e4b49bf6", "best_bid": "0.2", "best_ask": "0.97"}], "timestamp": "1769384581082", "event_type": "price_change"}}
{"_local_timestamp": "2026-01-25T23:43:01.206137+00:00", "data": {"market": "0xfe76f366b01cffc5f3c2551ca2fafd3626551f8e67c45e90bcb9980fadefb1d9", "price_changes": [{"asset_id": "113047842163343397942154658230859519377162790695920966272941515248645143857449", "price": "0.02", "size": "125", "side": "BUY", "hash": "956ca28ab5081aa2ed389e0c0ad96a601ee6e5d3", "best_bid": "0.03", "best_ask": "0.83"}, {"asset_id": "91464103984107757678948958563250156809345102931554507444370450055330522832734", "price": "0.98", "size": "125", "side": "SELL", "hash": "443ebb4cdaa5031c8c974fcc98de1cc27ec87d29", "best_bid": "0.17", "best_ask": "0.97"}], "timestamp": "1769384581082", "event_type": "price_change"}}
{"_local_timestamp": "2026-01-25T23:43:01.206494+00:00", "data": {"market": "0x93f28d0ad9d5906fee37296a8a70a57c9e4ed4b3b9aa09029c2d9589ce7ce832", "price_changes": [{"asset_id": "100955895305218895610069502472760899905214942330703669753760270178117749789092", "price": "0.02", "size": "119.99", "side": "BUY", "hash": "934aaef21987d4e01d6741d1514c2047011b29c2", "best_bid": "0.03", "best_ask": "0.81"}, {"asset_id": "72776331054793272806940188908180904666024448478022907801009755847830868970904", "price": "0.98", "size": "119.99", "side": "SELL", "hash": "e5301a9b887975e5a41eba7a1601fcff894425a4", "best_bid": "0.19", "best_ask": "0.97"}], "timestamp": "1769384581082", "event_type": "price_change"}}
{"_local_timestamp": "2026-01-25T23:43:01.338734+00:00", "data": {"market": "0x93f28d0ad9d5906fee37296a8a70a57c9e4ed4b3b9aa09029c2d9589ce7ce832", "price_changes": [{"asset_id": "72776331054793272806940188908180904666024448478022907801009755847830868970904", "price": "0.15", "size": "20", "side": "BUY", "hash": "10a745e8f24e4024ff42e7101e251dd5f48fa3c4", "best_bid": "0.19", "best_ask": "0.97"}, {"asset_id": "100955895305218895610069502472760899905214942330703669753760270178117749789092", "price": "0.85", "size": "20", "side": "SELL", "hash": "dc61f74d0ef52aac5fe5cebf6b4e9f2df9a53c32", "best_bid": "0.03", "best_ask": "0.81"}], "timestamp": "1769384581213", "event_type": "price_change"}}
{"_local_timestamp": "2026-01-25T23:43:01.548641+00:00", "data": {"market": "0x93f28d0ad9d5906fee37296a8a70a57c9e4ed4b3b9aa09029c2d9589ce7ce832", "price_changes": [{"asset_id": "72776331054793272806940188908180904666024448478022907801009755847830868970904", "price": "0.14", "size": "40", "side": "BUY", "hash": "07aad86a092b16626e6cd46e5fc22056b1480e40", "best_bid": "0.19", "best_ask": "0.97"}, {"asset_id": "100955895305218895610069502472760899905214942330703669753760270178117749789092", "price": "0.86", "size": "40", "side": "SELL", "hash": "f748deba9512eb375c6ddf0348477963303385ba", "best_bid": "0.03", "best_ask": "0.81"}], "timestamp": "1769384581445", "event_type": "price_change"}}
{"_local_timestamp": "2026-01-25T23:43:02.624443+00:00", "data": {"market": "0x93f28d0ad9d5906fee37296a8a70a57c9e4ed4b3b9aa09029c2d9589ce7ce832", "price_changes": [{"asset_id": "72776331054793272806940188908180904666024448478022907801009755847830868970904", "price": "0.15", "size": "0", "side": "BUY", "hash": "cd193bb9c43e1cbf0dd80de4221781203fd2d0b6", "best_bid": "0.19", "best_ask": "0.97"}, {"asset_id": "100955895305218895610069502472760899905214942330703669753760270178117749789092", "price": "0.85", "size": "0", "side": "SELL", "hash": "d491c50b7eebc85fbea0b962bbc935b017dbff0b", "best_bid": "0.03", "best_ask": "0.81"}], "timestamp": "1769384582525", "event_type": "price_change"}}
{"_local_timestamp": "2026-01-25T23:43:02.650212+00:00", "data": {"market": "0x93f28d0ad9d5906fee37296a8a70a57c9e4ed4b3b9aa09029c2d9589ce7ce832", "price_changes": [{"asset_id": "72776331054793272806940188908180904666024448478022907801009755847830868970904", "price": "0.14", "size": "60", "side": "BUY", "hash": "7204e2f5ccc65c5cfdde9c7ed116694cf4debaee", "best_bid": "0.19", "best_ask": "0.97"}, {"asset_id": "100955895305218895610069502472760899905214942330703669753760270178117749789092", "price": "0.86", "size": "60", "side": "SELL", "hash": "3c095d56033b7c700045428079d0b7c872e8ba56", "best_bid": "0.03", "best_ask": "0.81"}], "timestamp": "1769384582551", "event_type": "price_change"}}
{"_local_timestamp": "2026-01-25T23:43:02.770330+00:00", "data": {"market": "0xe0a32dbfe006ba8c5031351f5243c5cd9a58cf3c37b566cc82a9f7d41f8302c7", "price_changes": [{"asset_id": "4885632818167351187788551933410416061445761831692101146500029904141404303906", "price": "0.02", "size": "127.49", "side": "BUY", "hash": "8d8e785212039f8845226d0082c33cb50a89d9bc", "best_bid": "0.03", "best_ask": "0.82"}, {"asset_id": "65815064799788774655435771148232734980061574308316816581700167067698511121921", "price": "0.98", "size": "127.49", "side": "SELL", "hash": "cc0f9d136ef259a55e986854ff6b04da6a474a1e", "best_bid": "0.18", "best_ask": "0.97"}], "timestamp": "1769384582666", "event_type": "price_change"}}
{"_local_timestamp": "2026-01-25T23:43:02.770776+00:00", "data": {"market": "0xb9d3c208d8eb2f3403144092d0e55a4ecf7a6493e33890b35140197a63148d14", "price_changes": [{"asset_id": "63581074489545967013426062325864715209547016020665245565255381968385916667995", "price": "0.02", "size": "120", "side": "BUY", "hash": "c2ae1afd89df207586facabbe97a803049fe420c", "best_bid": "0.03", "best_ask": "0.83"}, {"asset_id": "70717802646694382009573815278721437797667570104667888155891561185095387198938", "price": "0.98", "size": "120", "side": "SELL", "hash": "d4df04f32adc7857d6401507e328e5530e86e5ab", "best_bid": "0.17", "best_ask": "0.97"}], "timestamp": "1769384582666", "event_type": "price_change"}}
{"_local_timestamp": "2026-01-25T23:43:02.771165+00:00", "data": {"market": "0x25025db13d5868308eb2f1f57beaf7cbea76c4014201800853a4c1aaad3046ee", "price_changes": [{"asset_id": "15113128431693879081528076048684622701923990563320934711420493231791911133880", "price": "0.02", "size": "155.46", "side": "BUY", "hash": "1eab4d28ce79aaddf5c6fb5c832b3f17180e4b09", "best_bid": "0.03", "best_ask": "0.28"}, {"asset_id": "69171629149106323292749070292707293928031973221371003911300207535275094378436", "price": "0.98", "size": "155.46", "side": "SELL", "hash": "ecd33b03ac1d85f7c8671ead354384a2dd64f200", "best_bid": "0.72", "best_ask": "0.97"}], "timestamp": "1769384582666", "event_type": "price_change"}}
{"_local_timestamp": "2026-01-25T23:43:02.771554+00:00", "data": {"market": "0xe0a32dbfe006ba8c5031351f5243c5cd9a58cf3c37b566cc82a9f7d41f8302c7", "price_changes": [{"asset_id": "4885632818167351187788551933410416061445761831692101146500029904141404303906", "price": "0.01", "size": "150.58", "side": "BUY", "hash": "f4c37cffb5ec69042b9cf1d4b87ec54f0107d1fc", "best_bid": "0.03", "best_ask": "0.82"}, {"asset_id": "65815064799788774655435771148232734980061574308316816581700167067698511121921", "price": "0.99", "size": "150.58", "side": "SELL", "hash": "b6b0004c3a8cb494d15da27d7be3bbd80c107ba3", "best_bid": "0.18", "best_ask": "0.97"}], "timestamp": "1769384582667", "event_type": "price_change"}}
{"_local_timestamp": "2026-01-25T23:43:03.241486+00:00", "data": {"market": "0x93f28d0ad9d5906fee37296a8a70a57c9e4ed4b3b9aa09029c2d9589ce7ce832", "price_changes": [{"asset_id": "72776331054793272806940188908180904666024448478022907801009755847830868970904", "price": "0.14", "size": "40", "side": "BUY", "hash": "f4a767d00d1a694e0a284ee29a744311cc4f75c4", "best_bid": "0.19", "best_ask": "0.97"}, {"asset_id": "100955895305218895610069502472760899905214942330703669753760270178117749789092", "price": "0.86", "size": "40", "side": "SELL", "hash": "095b9b5922cccbe2d35819dc2dea3e155594ecbe", "best_bid": "0.03", "best_ask": "0.81"}], "timestamp": "1769384583144", "event_type": "price_change"}}
{"_local_timestamp": "2026-01-25T23:43:03.273062+00:00", "data": {"market": "0x93f28d0ad9d5906fee37296a8a70a57c9e4ed4b3b9aa09029c2d9589ce7ce832", "price_changes": [{"asset_id": "72776331054793272806940188908180904666024448478022907801009755847830868970904", "price": "0.15", "size": "20", "side": "BUY", "hash": "b5330e9a67f68fdf5f48f363affb82b3684caffa", "best_bid": "0.19", "best_ask": "0.97"}, {"asset_id": "100955895305218895610069502472760899905214942330703669753760270178117749789092", "price": "0.85", "size": "20", "side": "SELL", "hash": "2e53e60234f62d4252f5b377266a6737e7b5f9f9", "best_bid": "0.03", "best_ask": "0.81"}], "timestamp": "1769384583181", "event_type": "price_change"}}
{"_local_timestamp": "2026-01-25T23:43:03.965945+00:00", "data": {"market": "0x225e0fdd1dbcf8d4ed569658e9fcdadc106fe4df8f3eebab6de3179594e69cae", "price_changes": [{"asset_id": "100614172146851019022930506261540059414109250163382945560610650412918760163014", "price": "0.004", "size": "0", "side": "BUY", "hash": "65c6d4121c4450a1aac61c3c34037dd3cf143b56", "best_bid": "0.022", "best_ask": "0.08"}, {"asset_id": "45764625730845095130147096446415799271154137683585606059451270337639906719390", "price": "0.996", "size": "0", "side": "SELL", "hash": "4fbd1b453e8d488b50e59989ccb46de00263e669", "best_bid": "0.92", "best_ask": "0.978"}], "timestamp": "1769384583859", "event_type": "price_change"}}
{"_local_timestamp": "2026-01-25T23:43:05.808825+00:00", "data": {"market": "0x225e0fdd1dbcf8d4ed569658e9fcdadc106fe4df8f3eebab6de3179594e69cae", "price_changes": [{"asset_id": "100614172146851019022930506261540059414109250163382945560610650412918760163014", "price": "0.002", "size": "273.41", "side": "BUY", "hash": "d12375a7410357485f145f82b5cafc68e92570f6", "best_bid": "0.022", "best_ask": "0.08"}, {"asset_id": "45764625730845095130147096446415799271154137683585606059451270337639906719390", "price": "0.998", "size": "273.41", "side": "SELL", "hash": "78d80a16239cf18fb8f322d82b60f6c8494d936a", "best_bid": "0.92", "best_ask": "0.978"}], "timestamp": "1769384585703", "event_type": "price_change"}}
{"_local_timestamp": "2026-01-25T23:43:24.763905+00:00", "data": {"market": "0xe0a32dbfe006ba8c5031351f5243c5cd9a58cf3c37b566cc82a9f7d41f8302c7", "price_changes": [{"asset_id": "65815064799788774655435771148232734980061574308316816581700167067698511121921", "price": "0.14", "size": "118.75", "side": "BUY", "hash": "11db41dcbea0d38a3342cf92c5eb26f93921d70f", "best_bid": "0.18", "best_ask": "0.97"}, {"asset_id": "4885632818167351187788551933410416061445761831692101146500029904141404303906", "price": "0.86", "size": "118.75", "side": "SELL", "hash": "9ffe24c06c32f4a4ef1a4224cfaa2c9cac4061f4", "best_bid": "0.03", "best_ask": "0.82"}], "timestamp": "1769384604635", "event_type": "price_change"}}
{"_local_timestamp": "2026-01-25T23:43:24.764436+00:00", "data": {"market": "0x93f28d0ad9d5906fee37296a8a70a57c9e4ed4b3b9aa09029c2d9589ce7ce832", "price_changes": [{"asset_id": "72776331054793272806940188908180904666024448478022907801009755847830868970904", "price": "0.16", "size": "29", "side": "BUY", "hash": "4afcd242b38b3284ecdd7a1b663c8f6996016d50", "best_bid": "0.19", "best_ask": "0.97"}, {"asset_id": "100955895305218895610069502472760899905214942330703669753760270178117749789092", "price": "0.84", "size": "29", "side": "SELL", "hash": "7d6d7382b41e316facb623c2180ccaa052b59b37", "best_bid": "0.03", "best_ask": "0.81"}], "timestamp": "1769384604635", "event_type": "price_change"}}
{"_local_timestamp": "2026-01-25T23:43:24.764962+00:00", "data": {"market": "0xfe76f366b01cffc5f3c2551ca2fafd3626551f8e67c45e90bcb9980fadefb1d9", "price_changes": [{"asset_id": "91464103984107757678948958563250156809345102931554507444370450055330522832734", "price": "0.17", "size": "49", "side": "BUY", "hash": "7739f670aabd7b80cf44d3d5ed984fd861c3c905", "best_bid": "0.17", "best_ask": "0.97"}, {"asset_id": "113047842163343397942154658230859519377162790695920966272941515248645143857449", "price": "0.83", "size": "49", "side": "SELL", "hash": "ca35c2725f226be8e1c735eaf8c86bce5a64f004", "best_bid": "0.03", "best_ask": "0.83"}], "timestamp": "1769384604635", "event_type": "price_change"}}
{"_local_timestamp": "2026-01-25T23:43:24.765378+00:00", "data": {"market": "0xa3476e8efbbc5557ff9f58978bcf85b7c2bc0c14d2f2c5891f1861a0e95c71c7", "price_changes": [{"asset_id": "77616069079544766632313130435803131534837904050680582581189964299844607679338", "price": "0.15", "size": "59", "side": "BUY", "hash": "421d61d74c75e6259256fd980eead68c2e9ae35e", "best_bid": "0.2", "best_ask": "0.97"}, {"asset_id": "49075166570883369230840079099601560361862864964529664437077360133815011449025", "price": "0.85", "size": "59", "side": "SELL", "hash": "268bbcebcbc35b97b9b12e53cb5f0ac5bd81922f", "best_bid": "0.03", "best_ask": "0.8"}], "timestamp": "1769384604635", "event_type": "price_change"}}
{"_local_timestamp": "2026-01-25T23:43:24.775576+00:00", "data": {"market": "0xb9d3c208d8eb2f3403144092d0e55a4ecf7a6493e33890b35140197a63148d14", "price_changes": [{"asset_id": "70717802646694382009573815278721437797667570104667888155891561185095387198938", "price": "0.17", "size": "49", "side": "BUY", "hash": "d1f01722fd69afdf0bde9c7188158025c4860451", "best_bid": "0.17", "best_ask": "0.97"}, {"asset_id": "63581074489545967013426062325864715209547016020665245565255381968385916667995", "price": "0.83", "size": "49", "side": "SELL", "hash": "656b8c6ab0ea10a93ddc491022596124fe1da7a1", "best_bid": "0.03", "best_ask": "0.83"}], "timestamp": "1769384604635", "event_type": "price_change"}}
{"_local_timestamp": "2026-01-25T23:43:24.776084+00:00", "data": {"market": "0x25025db13d5868308eb2f1f57beaf7cbea76c4014201800853a4c1aaad3046ee", "price_changes": [{"asset_id": "69171629149106323292749070292707293928031973221371003911300207535275094378436", "price": "0.16", "size": "29", "side": "BUY", "hash": "73b2928862573189ccfa1949175bdbf2da35a4a8", "best_bid": "0.72", "best_ask": "0.97"}, {"asset_id": "15113128431693879081528076048684622701923990563320934711420493231791911133880", "price": "0.84", "size": "29", "side": "SELL", "hash": "818eab2d4a5529bee2b1b340e6463f91a5dbcd9f", "best_bid": "0.03", "best_ask": "0.28"}], "timestamp": "1769384604635", "event_type": "price_change"}}
{"_local_timestamp": "2026-01-25T23:43:24.776607+00:00", "data": {"market": "0x225e0fdd1dbcf8d4ed569658e9fcdadc106fe4df8f3eebab6de3179594e69cae", "price_changes": [{"asset_id": "45764625730845095130147096446415799271154137683585606059451270337639906719390", "price": "0.133", "size": "118.75", "side": "BUY", "hash": "f1cadc59bed303af2a1fb2d21a751e0678d6c2de", "best_bid": "0.92", "best_ask": "0.978"}, {"asset_id": "100614172146851019022930506261540059414109250163382945560610650412918760163014", "price": "0.867", "size": "118.75", "side": "SELL", "hash": "a5d8c99d4de4f56ca2a4c85f2289135c92536736", "best_bid": "0.022", "best_ask": "0.08"}], "timestamp": "1769384604635", "event_type": "price_change"}}
{"_local_timestamp": "2026-01-25T23:43:24.777039+00:00", "data": {"market": "0xf69b405cb72c495b47f14d4581ec5f4fdc32c7c783c0b05c5d350af99f74fb57", "price_changes": [{"asset_id": "111483763262460809812427616008076634438113457835729033090496924816271676966924", "price": "0.15", "size": "59", "side": "BUY", "hash": "4a6f797bf635f85ef6592380d89e6ac6c4bd9b9b", "best_bid": "0.2", "best_ask": "0.97"}, {"asset_id": "77871459748036421242663925334747383360075298582158881700736355568100463986230", "price": "0.85", "size": "59", "side": "SELL", "hash": "c233bf7117af55285ab7a2868b06c183308f242a", "best_bid": "0.03", "best_ask": "0.8"}], "timestamp": "1769384604635", "event_type": "price_change"}}
{"_local_timestamp": "2026-01-25T23:43:24.777473+00:00", "data": {"market": "0x225e0fdd1dbcf8d4ed569658e9fcdadc106fe4df8f3eebab6de3179594e69cae", "price_changes": [{"asset_id": "45764625730845095130147096446415799271154137683585606059451270337639906719390", "price": "0.132", "size": "138.75", "side": "BUY", "hash": "136e91f71a344d09366826356b4ca9c44655ac28", "best_bid": "0.92", "best_ask": "0.978"}, {"asset_id": "100614172146851019022930506261540059414109250163382945560610650412918760163014", "price": "0.868", "size": "138.75", "side": "SELL", "hash": "2cf0bbcc9dc8b52c743a04e6bca6fe2303b28560", "best_bid": "0.022", "best_ask": "0.08"}], "timestamp": "1769384604636", "event_type": "price_change"}}
{"_local_timestamp": "2026-01-25T23:43:24.777874+00:00", "data": {"market": "0xfe76f366b01cffc5f3c2551ca2fafd3626551f8e67c45e90bcb9980fadefb1d9", "price_changes": [{"asset_id": "91464103984107757678948958563250156809345102931554507444370450055330522832734", "price": "0.18", "size": "29", "side": "BUY", "hash": "a866a29b13f1a9cd188b158e90d209971fb25f49", "best_bid": "0.18", "best_ask": "0.97"}, {"asset_id": "113047842163343397942154658230859519377162790695920966272941515248645143857449", "price": "0.82", "size": "29", "side": "SELL", "hash": "99cd75f0967e62c2e1242d449d2b10c5bb67e68d", "best_bid": "0.03", "best_ask": "0.82"}], "timestamp": "1769384604636", "event_type": "price_change"}}
{"_local_timestamp": "2026-01-25T23:43:24.778352+00:00", "data": {"market": "0xe0a32dbfe006ba8c5031351f5243c5cd9a58cf3c37b566cc82a9f7d41f8302c7", "price_changes": [{"asset_id": "65815064799788774655435771148232734980061574308316816581700167067698511121921", "price": "0.19", "size": "29", "side": "BUY", "hash": "51f0d94af7ed4d8116d9d198dcadbb204b91c964", "best_bid": "0.19", "best_ask": "0.97"}, {"asset_id": "4885632818167351187788551933410416061445761831692101146500029904141404303906", "price": "0.81", "size": "29", "side": "SELL", "hash": "0f3acb881c280717ad1c551e1f05a88f82591647", "best_bid": "0.03", "best_ask": "0.81"}], "timestamp": "1769384604636", "event_type": "price_change"}}
{"_local_timestamp": "2026-01-25T23:43:24.981301+00:00", "data": {"market": "0xb9d3c208d8eb2f3403144092d0e55a4ecf7a6493e33890b35140197a63148d14", "price_changes": [{"asset_id": "70717802646694382009573815278721437797667570104667888155891561185095387198938", "price": "0.18", "size": "29", "side": "BUY", "hash": "61fc638138faf74e5768c05d68bca66cf8f4fd8e", "best_bid": "0.18", "best_ask": "0.97"}, {"asset_id": "63581074489545967013426062325864715209547016020665245565255381968385916667995", "price": "0.82", "size": "29", "side": "SELL", "hash": "446d73b9773d9b29eb66f01cdaf85a499399d799", "best_bid": "0.03", "best_ask": "0.82"}], "timestamp": "1769384604636", "event_type": "price_change"}}
{"_local_timestamp": "2026-01-25T23:43:24.982975+00:00", "data": {"market": "0xe0a32dbfe006ba8c5031351f5243c5cd9a58cf3c37b566cc82a9f7d41f8302c7", "price_changes": [{"asset_id": "65815064799788774655435771148232734980061574308316816581700167067698511121921", "price": "0.18", "size": "0", "side": "BUY", "hash": "22f66b166c5ee63f46a351a8b543a8eae394279e", "best_bid": "0.19", "best_ask": "0.97"}, {"asset_id": "4885632818167351187788551933410416061445761831692101146500029904141404303906", "price": "0.82", "size": "0", "side": "SELL", "hash": "31b0f3a32687e6418cd5b09f07c89dda46bbf687", "best_bid": "0.03", "best_ask": "0.81"}], "timestamp": "1769384604663", "event_type": "price_change"}}
{"_local_timestamp": "2026-01-25T23:43:24.983488+00:00", "data": {"market": "0xfe76f366b01cffc5f3c2551ca2fafd3626551f8e67c45e90bcb9980fadefb1d9", "price_changes": [{"asset_id": "91464103984107757678948958563250156809345102931554507444370450055330522832734", "price": "0.17", "size": "29", "side": "BUY", "hash": "5d51f65e1939d871c735797369f05836304a1962", "best_bid": "0.18", "best_ask": "0.97"}, {"asset_id": "113047842163343397942154658230859519377162790695920966272941515248645143857449", "price": "0.83", "size": "29", "side": "SELL", "hash": "c5b560baa9bcde2c988ed899a8c57dcf48a48a0a", "best_bid": "0.03", "best_ask": "0.82"}], "timestamp": "1769384604663", "event_type": "price_change"}}
{"_local_timestamp": "2026-01-25T23:43:24.983949+00:00", "data": {"market": "0xb9d3c208d8eb2f3403144092d0e55a4ecf7a6493e33890b35140197a63148d14", "price_changes": [{"asset_id": "70717802646694382009573815278721437797667570104667888155891561185095387198938", "price": "0.17", "size": "29", "side": "BUY", "hash": "b624c7cb7708f6f2df8f2c3a68137b437245c69b", "best_bid": "0.18", "best_ask": "0.97"}, {"asset_id": "63581074489545967013426062325864715209547016020665245565255381968385916667995", "price": "0.83", "size": "29", "side": "SELL", "hash": "4f0807226c13dfd64d11b018efa97866dd2f031e", "best_bid": "0.03", "best_ask": "0.82"}], "timestamp": "1769384604663", "event_type": "price_change"}}
{"_local_timestamp": "2026-01-25T23:43:24.984513+00:00", "data": {"market": "0xb9d3c208d8eb2f3403144092d0e55a4ecf7a6493e33890b35140197a63148d14", "price_changes": [{"asset_id": "70717802646694382009573815278721437797667570104667888155891561185095387198938", "price": "0.2", "size": "20", "side": "BUY", "hash": "73f93fb6a70c20bb1c892300598063e58b26432c", "best_bid": "0.2", "best_ask": "0.97"}, {"asset_id": "63581074489545967013426062325864715209547016020665245565255381968385916667995", "price": "0.8", "size": "20", "side": "SELL", "hash": "4bfeee1ea82926d42452c278b7680bfdb74f5dc9", "best_bid": "0.03", "best_ask": "0.8"}], "timestamp": "1769384604687", "event_type": "price_change"}}
{"_local_timestamp": "2026-01-25T23:43:24.985113+00:00", "data": {"market": "0xfe76f366b01cffc5f3c2551ca2fafd3626551f8e67c45e90bcb9980fadefb1d9", "price_changes": [{"asset_id": "91464103984107757678948958563250156809345102931554507444370450055330522832734", "price": "0.2", "size": "20", "side": "BUY", "hash": "10ca28a0ebcec7b7bd94cd2f2f86fbd5ee744eef", "best_bid": "0.2", "best_ask": "0.97"}, {"asset_id": "113047842163343397942154658230859519377162790695920966272941515248645143857449", "price": "0.8", "size": "20", "side": "SELL", "hash": "96031acc0d349d8eac636b38dbdcde9933506592", "best_bid": "0.03", "best_ask": "0.8"}], "timestamp": "1769384604708", "event_type": "price_change"}}
{"_local_timestamp": "2026-01-25T23:43:24.985611+00:00", "data": {"market": "0xe0a32dbfe006ba8c5031351f5243c5cd9a58cf3c37b566cc82a9f7d41f8302c7", "price_changes": [{"asset_id": "65815064799788774655435771148232734980061574308316816581700167067698511121921", "price": "0.2", "size": "20", "side": "BUY", "hash": "0c21bf332893293f553bc9b06bdc8d95dcff6996", "best_bid": "0.2", "best_ask": "0.97"}, {"asset_id": "4885632818167351187788551933410416061445761831692101146500029904141404303906", "price": "0.8", "size": "20", "side": "SELL", "hash": "b2477a0a1adef1e9499560b6fac0d26d5e252b0b", "best_bid": "0.03", "best_ask": "0.8"}], "timestamp": "1769384604728", "event_type": "price_change"}}
{"_local_timestamp": "2026-01-25T23:43:24.986062+00:00", "data": {"market": "0xe0a32dbfe006ba8c5031351f5243c5cd9a58cf3c37b566cc82a9f7d41f8302c7", "price_changes": [{"asset_id": "65815064799788774655435771148232734980061574308316816581700167067698511121921", "price": "0.01", "size": "88.31", "side": "BUY", "hash": "d19f4559c4429b115b8b9128cad5d875263878b1", "best_bid": "0.2", "best_ask": "0.97"}, {"asset_id": "4885632818167351187788551933410416061445761831692101146500029904141404303906", "price": "0.99", "size": "88.31", "side": "SELL", "hash": "2859af4dab23d70f84ef9fd114642b2d920a194e", "best_bid": "0.03", "best_ask": "0.8"}], "timestamp": "1769384604749", "event_type": "price_change"}}
{"_local_timestamp": "2026-01-25T23:43:24.986521+00:00", "data": {"market": "0xe0a32dbfe006ba8c5031351f5243c5cd9a58cf3c37b566cc82a9f7d41f8302c7", "price_changes": [{"asset_id": "65815064799788774655435771148232734980061574308316816581700167067698511121921", "price": "0.06", "size": "33", "side": "BUY", "hash": "d2def19fe965af65b9c2571f3120ca017c5de2b3", "best_bid": "0.2", "best_ask": "0.97"}, {"asset_id": "4885632818167351187788551933410416061445761831692101146500029904141404303906", "price": "0.94", "size": "33", "side": "SELL", "hash": "078668b8435d5c416ac6cbbbf94066f5f7ab0671", "best_bid": "0.03", "best_ask": "0.8"}], "timestamp": "1769384604825", "event_type": "price_change"}}
{"_local_timestamp": "2026-01-25T23:43:25.068642+00:00", "data": {"market": "0xe0a32dbfe006ba8c5031351f5243c5cd9a58cf3c37b566cc82a9f7d41f8302c7", "price_changes": [{"asset_id": "65815064799788774655435771148232734980061574308316816581700167067698511121921", "price": "0.15", "size": "10", "side": "BUY", "hash": "cc225c39d5cc47ec9f804e1db5e6dcf701c55fc7", "best_bid": "0.2", "best_ask": "0.97"}, {"asset_id": "4885632818167351187788551933410416061445761831692101146500029904141404303906", "price": "0.85", "size": "10", "side": "SELL", "hash": "20a575cda2baf2c401bd0435a3f72491a3e9248c", "best_bid": "0.03", "best_ask": "0.8"}], "timestamp": "1769384604919", "event_type": "price_change"}}
{"_local_timestamp": "2026-01-25T23:43:25.126421+00:00", "data": {"market": "0xe0a32dbfe006ba8c5031351f5243c5cd9a58cf3c37b566cc82a9f7d41f8302c7", "price_changes": [{"asset_id": "65815064799788774655435771148232734980061574308316816581700167067698511121921", "price": "0.13", "size": "0", "side": "BUY", "hash": "fa88e1487626fa98e908d9b2c4f531de6f4e4ca7", "best_bid": "0.2", "best_ask": "0.97"}, {"asset_id": "4885632818167351187788551933410416061445761831692101146500029904141404303906", "price": "0.87", "size": "0", "side": "SELL", "hash": "595eb2d32860a6e99b2265d594a11992457e9960", "best_bid": "0.03", "best_ask": "0.8"}], "timestamp": "1769384604985", "event_type": "price_change"}}
{"_local_timestamp": "2026-01-25T23:43:25.127087+00:00", "data": {"market": "0xf69b405cb72c495b47f14d4581ec5f4fdc32c7c783c0b05c5d350af99f74fb57", "price_changes": [{"asset_id": "111483763262460809812427616008076634438113457835729033090496924816271676966924", "price": "0.14", "size": "0", "side": "BUY", "hash": "43ad2b392825f26fa222a0c2cc5c8468f788d1be", "best_bid": "0.2", "best_ask": "0.97"}, {"asset_id": "77871459748036421242663925334747383360075298582158881700736355568100463986230", "price": "0.86", "size": "0", "side": "SELL", "hash": "83133edaccb722075914a59c44940fced1d1a044", "best_bid": "0.03", "best_ask": "0.8"}], "timestamp": "1769384604985", "event_type": "price_change"}}
{"_local_timestamp": "2026-01-25T23:43:25.127572+00:00", "data": {"market": "0x225e0fdd1dbcf8d4ed569658e9fcdadc106fe4df8f3eebab6de3179594e69cae", "price_changes": [{"asset_id": "45764625730845095130147096446415799271154137683585606059451270337639906719390", "price": "0.132", "size": "118.75", "side": "BUY", "hash": "f65652e0491181195e123479bd32c53a2c9e5ed9", "best_bid": "0.92", "best_ask": "0.978"}, {"asset_id": "100614172146851019022930506261540059414109250163382945560610650412918760163014", "price": "0.868", "size": "118.75", "side": "SELL", "hash": "69837dc36cbbeb8eae71ac5dba48a3f0fced4715", "best_bid": "0.022", "best_ask": "0.08"}], "timestamp": "1769384604985", "event_type": "price_change"}}
{"_local_timestamp": "2026-01-25T23:43:25.128086+00:00", "data": {"market": "0xa3476e8efbbc5557ff9f58978bcf85b7c2bc0c14d2f2c5891f1861a0e95c71c7", "price_changes": [{"asset_id": "77616069079544766632313130435803131534837904050680582581189964299844607679338", "price": "0.14", "size": "0", "side": "BUY", "hash": "812bf900aba964cd09c664ed5174450314df03e9", "best_bid": "0.2", "best_ask": "0.97"}, {"asset_id": "49075166570883369230840079099601560361862864964529664437077360133815011449025", "price": "0.86", "size": "0", "side": "SELL", "hash": "ee04bf132b60f28a1358cb360cbbae6dbd28ee85", "best_bid": "0.03", "best_ask": "0.8"}], "timestamp": "1769384604985", "event_type": "price_change"}}
{"_local_timestamp": "2026-01-25T23:43:25.177704+00:00", "data": {"market": "0x225e0fdd1dbcf8d4ed569658e9fcdadc106fe4df8f3eebab6de3179594e69cae", "price_changes": [{"asset_id": "45764625730845095130147096446415799271154137683585606059451270337639906719390", "price": "0.134", "size": "20", "side": "BUY", "hash": "32a555c7b3c1f9ea940367a2f08bb56094bba249", "best_bid": "0.92", "best_ask": "0.978"}, {"asset_id": "100614172146851019022930506261540059414109250163382945560610650412918760163014", "price": "0.866", "size": "20", "side": "SELL", "hash": "f5b508223bc3887373599151967287f5b90ebcb6", "best_bid": "0.022", "best_ask": "0.08"}], "timestamp": "1769384605016", "event_type": "price_change"}}
{"_local_timestamp": "2026-01-25T23:43:25.178269+00:00", "data": {"market": "0xe0a32dbfe006ba8c5031351f5243c5cd9a58cf3c37b566cc82a9f7d41f8302c7", "price_changes": [{"asset_id": "65815064799788774655435771148232734980061574308316816581700167067698511121921", "price": "0.15", "size": "30", "side": "BUY", "hash": "acd78ef2e1dce77c9010d6f79358675a6588f1ef", "best_bid": "0.2", "best_ask": "0.97"}, {"asset_id": "4885632818167351187788551933410416061445761831692101146500029904141404303906", "price": "0.85", "size": "30", "side": "SELL", "hash": "21ee6e1d5368773ec72d0dccbe40f63fe199aaa7", "best_bid": "0.03", "best_ask": "0.8"}], "timestamp": "1769384605016", "event_type": "price_change"}}
{"_local_timestamp": "2026-01-25T23:43:25.178731+00:00", "data": {"market": "0xa3476e8efbbc5557ff9f58978bcf85b7c2bc0c14d2f2c5891f1861a0e95c71c7", "price_changes": [{"asset_id": "77616069079544766632313130435803131534837904050680582581189964299844607679338", "price": "0.15", "size": "79", "side": "BUY", "hash": "043e185a2d2a66e2747d53c5e017dc915f5da588", "best_bid": "0.2", "best_ask": "0.97"}, {"asset_id": "49075166570883369230840079099601560361862864964529664437077360133815011449025", "price": "0.85", "size": "79", "side": "SELL", "hash": "1d107aebf0913b24ae01088ecc8b2555527c1371", "best_bid": "0.03", "best_ask": "0.8"}], "timestamp": "1769384605016", "event_type": "price_change"}}
{"_local_timestamp": "2026-01-25T23:43:25.179206+00:00", "data": {"market": "0xf69b405cb72c495b47f14d4581ec5f4fdc32c7c783c0b05c5d350af99f74fb57", "price_changes": [{"asset_id": "111483763262460809812427616008076634438113457835729033090496924816271676966924", "price": "0.15", "size": "79", "side": "BUY", "hash": "f3bdfe67b3b0ce5d35e6f10a2ca7c3fcdfe251de", "best_bid": "0.2", "best_ask": "0.97"}, {"asset_id": "77871459748036421242663925334747383360075298582158881700736355568100463986230", "price": "0.85", "size": "79", "side": "SELL", "hash": "0707848b81afb7bc9556297eb1e4ca05e0d4a1c8", "best_bid": "0.03", "best_ask": "0.8"}], "timestamp": "1769384605016", "event_type": "price_change"}}
{"_local_timestamp": "2026-01-25T23:43:26.824800+00:00", "data": {"market": "0xa3476e8efbbc5557ff9f58978bcf85b7c2bc0c14d2f2c5891f1861a0e95c71c7", "price_changes": [{"asset_id": "49075166570883369230840079099601560361862864964529664437077360133815011449025", "price": "0.02", "size": "100", "side": "BUY", "hash": "f8686b4231fd962bc2d85394663991de67011971", "best_bid": "0.03", "best_ask": "0.8"}, {"asset_id": "77616069079544766632313130435803131534837904050680582581189964299844607679338", "price": "0.98", "size": "100", "side": "SELL", "hash": "acd08ac7bd810c60f221b841fd7da18da8f89bfe", "best_bid": "0.2", "best_ask": "0.97"}], "timestamp": "1769384606682", "event_type": "price_change"}}
{"_local_timestamp": "2026-01-25T23:43:26.825420+00:00", "data": {"market": "0xe0a32dbfe006ba8c5031351f5243c5cd9a58cf3c37b566cc82a9f7d41f8302c7", "price_changes": [{"asset_id": "4885632818167351187788551933410416061445761831692101146500029904141404303906", "price": "0.02", "size": "100", "side": "BUY", "hash": "6d3e4e094caf16c97810a25898b5397b3f3abe0b", "best_bid": "0.03", "best_ask": "0.8"}, {"asset_id": "65815064799788774655435771148232734980061574308316816581700167067698511121921", "price": "0.98", "size": "100", "side": "SELL", "hash": "b31d005a00a2f68b4512a3bdbc54f075e54c2a80", "best_bid": "0.2", "best_ask": "0.97"}], "timestamp": "1769384606682", "event_type": "price_change"}}
{"_local_timestamp": "2026-01-25T23:43:26.825898+00:00", "data": {"market": "0xfe76f366b01cffc5f3c2551ca2fafd3626551f8e67c45e90bcb9980fadefb1d9", "price_changes": [{"asset_id": "113047842163343397942154658230859519377162790695920966272941515248645143857449", "price": "0.02", "size": "100", "side": "BUY", "hash": "7d41246274cf49d8b12059343d3f3bd70590dd2f", "best_bid": "0.03", "best_ask": "0.8"}, {"asset_id": "91464103984107757678948958563250156809345102931554507444370450055330522832734", "price": "0.98", "size": "100", "side": "SELL", "hash": "e6d2bdff2c3ed727cb13ddef7490ccc86b645484", "best_bid": "0.2", "best_ask": "0.97"}], "timestamp": "1769384606682", "event_type": "price_change"}}
{"_local_timestamp": "2026-01-25T23:43:26.826417+00:00", "data": {"market": "0xf69b405cb72c495b47f14d4581ec5f4fdc32c7c783c0b05c5d350af99f74fb57", "price_changes": [{"asset_id": "77871459748036421242663925334747383360075298582158881700736355568100463986230", "price": "0.02", "size": "95", "side": "BUY", "hash": "41d3cfe3a6122747f6938e7ef36bd11e717c772c", "best_bid": "0.03", "best_ask": "0.8"}, {"asset_id": "111483763262460809812427616008076634438113457835729033090496924816271676966924", "price": "0.98", "size": "95", "side": "SELL", "hash": "21a846f94aa29780c6f3b15c9441b0a2b2eaee77", "best_bid": "0.2", "best_ask": "0.97"}], "timestamp": "1769384606682", "event_type": "price_change"}}
{"_local_timestamp": "2026-01-25T23:43:26.833026+00:00", "data": {"market": "0x25025db13d5868308eb2f1f57beaf7cbea76c4014201800853a4c1aaad3046ee", "price_changes": [{"asset_id": "15113128431693879081528076048684622701923990563320934711420493231791911133880", "price": "0.02", "size": "108", "side": "BUY", "hash": "ec19aa4570e76590ef4db1773b9ee0ad08233f7d", "best_bid": "0.03", "best_ask": "0.28"}, {"asset_id": "69171629149106323292749070292707293928031973221371003911300207535275094378436", "price": "0.98", "size": "108", "side": "SELL", "hash": "2fe5409c06570538dca8e16cace2bfa57e182019", "best_bid": "0.72", "best_ask": "0.97"}], "timestamp": "1769384606682", "event_type": "price_change"}}
{"_local_timestamp": "2026-01-25T23:43:26.833610+00:00", "data": {"market": "0xb9d3c208d8eb2f3403144092d0e55a4ecf7a6493e33890b35140197a63148d14", "price_changes": [{"asset_id": "63581074489545967013426062325864715209547016020665245565255381968385916667995", "price": "0.02", "size": "95", "side": "BUY", "hash": "d1a02ab7a648e6ca7b3e1e5def285ce3177e660f", "best_bid": "0.03", "best_ask": "0.8"}, {"asset_id": "70717802646694382009573815278721437797667570104667888155891561185095387198938", "price": "0.98", "size": "95", "side": "SELL", "hash": "97fc9112856d47b35511ee9c5ccab6b8adaa0ab0", "best_bid": "0.2", "best_ask": "0.97"}], "timestamp": "1769384606682", "event_type": "price_change"}}
{"_local_timestamp": "2026-01-25T23:43:26.834120+00:00", "data": {"market": "0x93f28d0ad9d5906fee37296a8a70a57c9e4ed4b3b9aa09029c2d9589ce7ce832", "price_changes": [{"asset_id": "100955895305218895610069502472760899905214942330703669753760270178117749789092", "price": "0.02", "size": "95", "side": "BUY", "hash": "0e36dec749580349062317887b70b0e32b5ede26", "best_bid": "0.03", "best_ask": "0.81"}, {"asset_id": "72776331054793272806940188908180904666024448478022907801009755847830868970904", "price": "0.98", "size": "95", "side": "SELL", "hash": "07423141fa788adf45f556fca72391b23ded22bc", "best_bid": "0.19", "best_ask": "0.97"}], "timestamp": "1769384606682", "event_type": "price_change"}}
{"_local_timestamp": "2026-01-25T23:43:27.036554+00:00", "data": {"market": "0xfe76f366b01cffc5f3c2551ca2fafd3626551f8e67c45e90bcb9980fadefb1d9", "price_changes": [{"asset_id": "91464103984107757678948958563250156809345102931554507444370450055330522832734", "price": "0.03", "size": "0", "side": "BUY", "hash": "5188d6be829a55660a3f514719cceb27dd290616", "best_bid": "0.2", "best_ask": "0.97"}, {"asset_id": "113047842163343397942154658230859519377162790695920966272941515248645143857449", "price": "0.97", "size": "0", "side": "SELL", "hash": "9073e7857571395b09e0134d21d9f4d96c6c3f6e", "best_bid": "0.03", "best_ask": "0.8"}], "timestamp": "1769384606865", "event_type": "price_change"}}
{"_local_timestamp": "2026-01-25T23:43:34.846458+00:00", "data": {"market": "0x93f28d0ad9d5906fee37296a8a70a57c9e4ed4b3b9aa09029c2d9589ce7ce832", "price_changes": [{"asset_id": "100955895305218895610069502472760899905214942330703669753760270178117749789092", "price": "0.03", "size": "0", "side": "BUY", "hash": "6a68b51659748eb5810fc8e3e5f38bac7aa356f8", "best_bid": "0.02", "best_ask": "0.81"}, {"asset_id": "72776331054793272806940188908180904666024448478022907801009755847830868970904", "price": "0.97", "size": "0", "side": "SELL", "hash": "b190723b5f0067e9afab8339f2fccb4ff005f47d", "best_bid": "0.19", "best_ask": "0.98"}], "timestamp": "1769384614719", "event_type": "price_change"}}
{"_local_timestamp": "2026-01-25T23:43:34.885862+00:00", "data": {"market": "0xf69b405cb72c495b47f14d4581ec5f4fdc32c7c783c0b05c5d350af99f74fb57", "price_changes": [{"asset_id": "111483763262460809812427616008076634438113457835729033090496924816271676966924", "price": "0.2", "size": "0", "side": "BUY", "hash": "957b7933136181572d7be6ff0b7dc6a5369b33d5", "best_bid": "0.15", "best_ask": "0.97"}, {"asset_id": "77871459748036421242663925334747383360075298582158881700736355568100463986230", "price": "0.8", "size": "0", "side": "SELL", "hash": "4606809fb9ee7b695baab892b17664425c63349c", "best_bid": "0.03", "best_ask": "0.85"}], "timestamp": "1769384614748", "event_type": "price_change"}}
{"_local_timestamp": "2026-01-25T23:43:34.886600+00:00", "data": {"market": "0xfe76f366b01cffc5f3c2551ca2fafd3626551f8e67c45e90bcb9980fadefb1d9", "price_changes": [{"asset_id": "91464103984107757678948958563250156809345102931554507444370450055330522832734", "price": "0.2", "size": "0", "side": "BUY", "hash": "ff3d5e7c287e9f7688dee3d0df5ee54fea4032cc", "best_bid": "0.18", "best_ask": "0.97"}, {"asset_id": "113047842163343397942154658230859519377162790695920966272941515248645143857449", "price": "0.8", "size": "0", "side": "SELL", "hash": "0a67f0a6382a5df68fdcda4ec72b61edf6246f22", "best_bid": "0.03", "best_ask": "0.82"}], "timestamp": "1769384614748", "event_type": "price_change"}}
{"_local_timestamp": "2026-01-25T23:43:34.887358+00:00", "data": {"market": "0xa3476e8efbbc5557ff9f58978bcf85b7c2bc0c14d2f2c5891f1861a0e95c71c7", "price_changes": [{"asset_id": "77616069079544766632313130435803131534837904050680582581189964299844607679338", "price": "0.2", "size": "0", "side": "BUY", "hash": "1c738ac7d197d849556d2665312c2d1b75b784ff", "best_bid": "0.15", "best_ask": "0.97"}, {"asset_id": "49075166570883369230840079099601560361862864964529664437077360133815011449025", "price": "0.8", "size": "0", "side": "SELL", "hash": "285e9f9133c3040760b757eac2d4b6f1408db67f", "best_bid": "0.03", "best_ask": "0.85"}], "timestamp": "1769384614748", "event_type": "price_change"}}
{"_local_timestamp": "2026-01-25T23:43:34.887871+00:00", "data": {"market": "0xb9d3c208d8eb2f3403144092d0e55a4ecf7a6493e33890b35140197a63148d14", "price_changes": [{"asset_id": "70717802646694382009573815278721437797667570104667888155891561185095387198938", "price": "0.2", "size": "0", "side": "BUY", "hash": "41c1368994d30b4d32a91b2b89129f9bad007793", "best_bid": "0.18", "best_ask": "0.97"}, {"asset_id": "63581074489545967013426062325864715209547016020665245565255381968385916667995", "price": "0.8", "size": "0", "side": "SELL", "hash": "7fdabaf3a711a5fe495ace88d72baffc0a7267f5", "best_bid": "0.03", "best_ask": "0.82"}], "timestamp": "1769384614748", "event_type": "price_change"}}
{"_local_timestamp": "2026-01-25T23:43:34.888380+00:00", "data": {"market": "0xe0a32dbfe006ba8c5031351f5243c5cd9a58cf3c37b566cc82a9f7d41f8302c7", "price_changes": [{"asset_id": "65815064799788774655435771148232734980061574308316816581700167067698511121921", "price": "0.2", "size": "0", "side": "BUY", "hash": "a7afb703d62170ab7e94c7855d9f3a3157567c89", "best_bid": "0.19", "best_ask": "0.97"}, {"asset_id": "4885632818167351187788551933410416061445761831692101146500029904141404303906", "price": "0.8", "size": "0", "side": "SELL", "hash": "1148a9f9b552744ab017752d8eb0c48a9b605df1", "best_bid": "0.03", "best_ask": "0.81"}], "timestamp": "1769384614748", "event_type": "price_change"}}
{"_local_timestamp": "2026-01-25T23:43:34.901998+00:00", "data": {"market": "0xf69b405cb72c495b47f14d4581ec5f4fdc32c7c783c0b05c5d350af99f74fb57", "price_changes": [{"asset_id": "111483763262460809812427616008076634438113457835729033090496924816271676966924", "price": "0.19", "size": "20", "side": "BUY", "hash": "017da3a77847a11d50a42b120652ea70888b83ad", "best_bid": "0.19", "best_ask": "0.97"}, {"asset_id": "77871459748036421242663925334747383360075298582158881700736355568100463986230", "price": "0.81", "size": "20", "side": "SELL", "hash": "7e85abb65395b4546eea57c6accb58d3a27a7d3d", "best_bid": "0.03", "best_ask": "0.81"}], "timestamp": "1769384614783", "event_type": "price_change"}}
{"_local_timestamp": "2026-01-25T23:43:34.926390+00:00", "data": {"market": "0xf69b405cb72c495b47f14d4581ec5f4fdc32c7c783c0b05c5d350af99f74fb57", "price_changes": [{"asset_id": "111483763262460809812427616008076634438113457835729033090496924816271676966924", "price": "0.15", "size": "59", "side": "BUY", "hash": "cb87e49aaef787dbcea5b2ab451952223653b203", "best_bid": "0.19", "best_ask": "0.97"}, {"asset_id": "77871459748036421242663925334747383360075298582158881700736355568100463986230", "price": "0.85", "size": "59", "side": "SELL", "hash": "c35a2cefed4166d26eec3c87ce9361276e1ac37b", "best_bid": "0.03", "best_ask": "0.81"}], "timestamp": "1769384614803", "event_type": "price_change"}}
{"_local_timestamp": "2026-01-25T23:43:34.927317+00:00", "data": {"market": "0xa3476e8efbbc5557ff9f58978bcf85b7c2bc0c14d2f2c5891f1861a0e95c71c7", "price_changes": [{"asset_id": "77616069079544766632313130435803131534837904050680582581189964299844607679338", "price": "0.16", "size": "20", "side": "BUY", "hash": "07454bbd324a857027bf53c1fdac2c6f339d0250", "best_bid": "0.16", "best_ask": "0.97"}, {"asset_id": "49075166570883369230840079099601560361862864964529664437077360133815011449025", "price": "0.84", "size": "20", "side": "SELL", "hash": "d67e06bb4ab29898338d5cd0c4ba648b1eb9d589", "best_bid": "0.03", "best_ask": "0.84"}], "timestamp": "1769384614803", "event_type": "price_change"}}
{"_local_timestamp": "2026-01-25T23:43:34.927915+00:00", "data": {"market": "0xe0a32dbfe006ba8c5031351f5243c5cd9a58cf3c37b566cc82a9f7d41f8302c7", "price_changes": [{"asset_id": "65815064799788774655435771148232734980061574308316816581700167067698511121921", "price": "0.15", "size": "10", "side": "BUY", "hash": "6273fcefd08accbfd47be4dc770ce291b862aba5", "best_bid": "0.19", "best_ask": "0.97"}, {"asset_id": "4885632818167351187788551933410416061445761831692101146500029904141404303906", "price": "0.85", "size": "10", "side": "SELL", "hash": "44668693b374fef0bf09695b167c1cdfb3493227", "best_bid": "0.03", "best_ask": "0.81"}], "timestamp": "1769384614803", "event_type": "price_change"}}
{"_local_timestamp": "2026-01-25T23:43:35.026234+00:00", "data": {"market": "0x25025db13d5868308eb2f1f57beaf7cbea76c4014201800853a4c1aaad3046ee", "price_changes": [{"asset_id": "69171629149106323292749070292707293928031973221371003911300207535275094378436", "price": "0.15", "size": "0", "side": "BUY", "hash": "b4031119e204fc5f0d118b8694e1040f359fb958", "best_bid": "0.72", "best_ask": "0.97"}, {"asset_id": "15113128431693879081528076048684622701923990563320934711420493231791911133880", "price": "0.85", "size": "0", "side": "SELL", "hash": "5bcf321d4863c25d9b73476716298aecbed3ec1a", "best_bid": "0.03", "best_ask": "0.28"}], "timestamp": "1769384614803", "event_type": "price_change"}}
{"_local_timestamp": "2026-01-25T23:43:35.026930+00:00", "data": {"market": "0xa3476e8efbbc5557ff9f58978bcf85b7c2bc0c14d2f2c5891f1861a0e95c71c7", "price_changes": [{"asset_id": "77616069079544766632313130435803131534837904050680582581189964299844607679338", "price": "0.15", "size": "59", "side": "BUY", "hash": "c0a7ed52954202fc58a526c31314c3be0e4df2d4", "best_bid": "0.16", "best_ask": "0.97"}, {"asset_id": "49075166570883369230840079099601560361862864964529664437077360133815011449025", "price": "0.85", "size": "59", "side": "SELL", "hash": "3c8bdddcd71ab9af6fce3b99bf3d223247a0a0e2", "best_bid": "0.03", "best_ask": "0.84"}], "timestamp": "1769384614803", "event_type": "price_change"}}
{"_local_timestamp": "2026-01-25T23:43:35.027724+00:00", "data": {"market": "0xb9d3c208d8eb2f3403144092d0e55a4ecf7a6493e33890b35140197a63148d14", "price_changes": [{"asset_id": "70717802646694382009573815278721437797667570104667888155891561185095387198938", "price": "0.19", "size": "20", "side": "BUY", "hash": "521bed25000774ef779a68e0fb0c34fac1d35f75", "best_bid": "0.19", "best_ask": "0.97"}, {"asset_id": "63581074489545967013426062325864715209547016020665245565255381968385916667995", "price": "0.81", "size": "20", "side": "SELL", "hash": "3c4fd797f70987d8289b001213bce1dabc0df8ce", "best_bid": "0.03", "best_ask": "0.81"}], "timestamp": "1769384614826", "event_type": "price_change"}}
{"_local_timestamp": "2026-01-25T23:43:35.028407+00:00", "data": {"market": "0xe0a32dbfe006ba8c5031351f5243c5cd9a58cf3c37b566cc82a9f7d41f8302c7", "price_changes": [{"asset_id": "65815064799788774655435771148232734980061574308316816581700167067698511121921", "price": "0.14", "size": "138.75", "side": "BUY", "hash": "ef72dc89eb75461fe1642e8e1fb2c546da3a41d8", "best_bid": "0.19", "best_ask": "0.97"}, {"asset_id": "4885632818167351187788551933410416061445761831692101146500029904141404303906", "price": "0.86", "size": "138.75", "side": "SELL", "hash": "d163b8ccafa6e097406e5123b3397c40591b2542", "best_bid": "0.03", "best_ask": "0.81"}], "timestamp": "1769384614833", "event_type": "price_change"}}
{"_local_timestamp": "2026-01-25T23:43:35.054921+00:00", "data": {"market": "0x25025db13d5868308eb2f1f57beaf7cbea76c4014201800853a4c1aaad3046ee", "price_changes": [{"asset_id": "69171629149106323292749070292707293928031973221371003911300207535275094378436", "price": "0.14", "size": "50", "side": "BUY", "hash": "f477f34f081df2a5bbc757e45de29ee04f6eba03", "best_bid": "0.72", "best_ask": "0.97"}, {"asset_id": "15113128431693879081528076048684622701923990563320934711420493231791911133880", "price": "0.86", "size": "50", "side": "SELL", "hash": "842445a6db64a2b24cffa441b2b243253abbb5b0", "best_bid": "0.03", "best_ask": "0.28"}], "timestamp": "1769384614833", "event_type": "price_change"}}
{"_local_timestamp": "2026-01-25T23:43:35.056757+00:00", "data": {"market": "0xf69b405cb72c495b47f14d4581ec5f4fdc32c7c783c0b05c5d350af99f74fb57", "price_changes": [{"asset_id": "111483763262460809812427616008076634438113457835729033090496924816271676966924", "price": "0.14", "size": "20", "side": "BUY", "hash": "4a10b857e8a527e5acbad1922084e092a409f115", "best_bid": "0.19", "best_ask": "0.97"}, {"asset_id": "77871459748036421242663925334747383360075298582158881700736355568100463986230", "price": "0.86", "size": "20", "side": "SELL", "hash": "a3262403a0bf80c5df049c7b8355e53ec94fd5da", "best_bid": "0.03", "best_ask": "0.81"}], "timestamp": "1769384614833", "event_type": "price_change"}}
{"_local_timestamp": "2026-01-25T23:43:35.057328+00:00", "data": {"market": "0xa3476e8efbbc5557ff9f58978bcf85b7c2bc0c14d2f2c5891f1861a0e95c71c7", "price_changes": [{"asset_id": "77616069079544766632313130435803131534837904050680582581189964299844607679338", "price": "0.14", "size": "20", "side": "BUY", "hash": "446bc7609876d8a9be034f72b076f87f5427ae46", "best_bid": "0.16", "best_ask": "0.97"}, {"asset_id": "49075166570883369230840079099601560361862864964529664437077360133815011449025", "price": "0.86", "size": "20", "side": "SELL", "hash": "25bd7847a67c82f3d15827b2476b7a54a75a757b", "best_bid": "0.03", "best_ask": "0.84"}], "timestamp": "1769384614833", "event_type": "price_change"}}
{"_local_timestamp": "2026-01-25T23:43:35.057846+00:00", "data": {"market": "0xfe76f366b01cffc5f3c2551ca2fafd3626551f8e67c45e90bcb9980fadefb1d9", "price_changes": [{"asset_id": "91464103984107757678948958563250156809345102931554507444370450055330522832734", "price": "0.19", "size": "20", "side": "BUY", "hash": "dd3ec845fe0ab91008962ac680478effa4b9d778", "best_bid": "0.19", "best_ask": "0.97"}, {"asset_id": "113047842163343397942154658230859519377162790695920966272941515248645143857449", "price": "0.81", "size": "20", "side": "SELL", "hash": "1cd6a41b3a14d79b76e9b498dcb82764df755db0", "best_bid": "0.03", "best_ask": "0.81"}], "timestamp": "1769384614850", "event_type": "price_change"}}
{"_local_timestamp": "2026-01-25T23:43:35.059080+00:00", "data": {"market": "0xb9d3c208d8eb2f3403144092d0e55a4ecf7a6493e33890b35140197a63148d14", "price_changes": [{"asset_id": "70717802646694382009573815278721437797667570104667888155891561185095387198938", "price": "0.03", "size": "0", "side": "BUY", "hash": "a97a41ede56b5cf04750061150b906ff345a67e7", "best_bid": "0.19", "best_ask": "0.97"}, {"asset_id": "63581074489545967013426062325864715209547016020665245565255381968385916667995", "price": "0.97", "size": "0", "side": "SELL", "hash": "b6069d89ecb24592d22a0c90b15a2c599c9bfe38", "best_bid": "0.03", "best_ask": "0.81"}], "timestamp": "1769384614863", "event_type": "price_change"}}
{"_local_timestamp": "2026-01-25T23:43:35.059907+00:00", "data": {"market": "0xe0a32dbfe006ba8c5031351f5243c5cd9a58cf3c37b566cc82a9f7d41f8302c7", "price_changes": [{"asset_id": "65815064799788774655435771148232734980061574308316816581700167067698511121921", "price": "0.15", "size": "0", "side": "BUY", "hash": "9ad6be695ceb125bbb86c7a0e736fddd0f4022ad", "best_bid": "0.19", "best_ask": "0.97"}, {"asset_id": "4885632818167351187788551933410416061445761831692101146500029904141404303906", "price": "0.85", "size": "0", "side": "SELL", "hash": "c46961a7830d9ce077c1decbd7a20dbe78ff33d2", "best_bid": "0.03", "best_ask": "0.81"}], "timestamp": "1769384614863", "event_type": "price_change"}}
{"_local_timestamp": "2026-01-25T23:43:35.060553+00:00", "data": {"market": "0xf69b405cb72c495b47f14d4581ec5f4fdc32c7c783c0b05c5d350af99f74fb57", "price_changes": [{"asset_id": "111483763262460809812427616008076634438113457835729033090496924816271676966924", "price": "0.13", "size": "0", "side": "BUY", "hash": "bf7e2c170e35de83def2ecabd10aa34a44290747", "best_bid": "0.19", "best_ask": "0.97"}, {"asset_id": "77871459748036421242663925334747383360075298582158881700736355568100463986230", "price": "0.87", "size": "0", "side": "SELL", "hash": "2e0fd62bf6d36cf4b9838163c56826083f039c97", "best_bid": "0.03", "best_ask": "0.81"}], "timestamp": "1769384614863", "event_type": "price_change"}}
{"_local_timestamp": "2026-01-25T23:43:35.061443+00:00", "data": {"market": "0xa3476e8efbbc5557ff9f58978bcf85b7c2bc0c14d2f2c5891f1861a0e95c71c7", "price_changes": [{"asset_id": "77616069079544766632313130435803131534837904050680582581189964299844607679338", "price": "0.13", "size": "0", "side": "BUY", "hash": "d326b56afe4a8b23e4b988056ad181b66331b3a5", "best_bid": "0.16", "best_ask": "0.97"}, {"asset_id": "49075166570883369230840079099601560361862864964529664437077360133815011449025", "price": "0.87", "size": "0", "side": "SELL", "hash": "1add0a8c81f9940afd9b7103e9a52e97593ecfb0", "best_bid": "0.03", "best_ask": "0.84"}], "timestamp": "1769384614863", "event_type": "price_change"}}
{"_local_timestamp": "2026-01-25T23:43:35.062088+00:00", "data": {"market": "0xe0a32dbfe006ba8c5031351f5243c5cd9a58cf3c37b566cc82a9f7d41f8302c7", "price_changes": [{"asset_id": "65815064799788774655435771148232734980061574308316816581700167067698511121921", "price": "0.19", "size": "49", "side": "BUY", "hash": "4ad2b9d782aa3d31ad4fe99bfaeafc5fb2bcadc2", "best_bid": "0.19", "best_ask": "0.97"}, {"asset_id": "4885632818167351187788551933410416061445761831692101146500029904141404303906", "price": "0.81", "size": "49", "side": "SELL", "hash": "429d10330287a217fdffc6d98a2690692897975f", "best_bid": "0.03", "best_ask": "0.81"}], "timestamp": "1769384614871", "event_type": "price_change"}}
{"_local_timestamp": "2026-01-25T23:43:35.096601+00:00", "data": {"market": "0xe0a32dbfe006ba8c5031351f5243c5cd9a58cf3c37b566cc82a9f7d41f8302c7", "price_changes": [{"asset_id": "65815064799788774655435771148232734980061574308316816581700167067698511121921", "price": "0.13", "size": "10", "side": "BUY", "hash": "e12555f891be535dfabf473074c4ca4c298bef24", "best_bid": "0.19", "best_ask": "0.97"}, {"asset_id": "4885632818167351187788551933410416061445761831692101146500029904141404303906", "price": "0.87", "size": "10", "side": "SELL", "hash": "e034b6484b9d4d1953174210a4d43ea8ec8eba57", "best_bid": "0.03", "best_ask": "0.81"}], "timestamp": "1769384614975", "event_type": "price_change"}}
{"_local_timestamp": "2026-01-25T23:43:35.098145+00:00", "data": {"market": "0xf69b405cb72c495b47f14d4581ec5f4fdc32c7c783c0b05c5d350af99f74fb57", "price_changes": [{"asset_id": "111483763262460809812427616008076634438113457835729033090496924816271676966924", "price": "0.11", "size": "15.99", "side": "BUY", "hash": "ee99be7bd4ca576ed1c93f8aac2c8e8c2b38791b", "best_bid": "0.19", "best_ask": "0.97"}, {"asset_id": "77871459748036421242663925334747383360075298582158881700736355568100463986230", "price": "0.89", "size": "15.99", "side": "SELL", "hash": "7deb7f70e16794628f4176bd7e36f780744215d1", "best_bid": "0.03", "best_ask": "0.81"}], "timestamp": "1769384614975", "event_type": "price_change"}}
{"_local_timestamp": "2026-01-25T23:43:35.104586+00:00", "data": {"market": "0xa3476e8efbbc5557ff9f58978bcf85b7c2bc0c14d2f2c5891f1861a0e95c71c7", "price_changes": [{"asset_id": "77616069079544766632313130435803131534837904050680582581189964299844607679338", "price": "0.11", "size": "16.59", "side": "BUY", "hash": "ad5a6bcafbff8f1a214f52a1b8ec97bc0d99f57c", "best_bid": "0.16", "best_ask": "0.97"}, {"asset_id": "49075166570883369230840079099601560361862864964529664437077360133815011449025", "price": "0.89", "size": "16.59", "side": "SELL", "hash": "0f33887a69fc874ce341d135b5a7b5ad736923a8", "best_bid": "0.03", "best_ask": "0.84"}], "timestamp": "1769384614975", "event_type": "price_change"}}
{"_local_timestamp": "2026-01-25T23:43:36.089680+00:00", "data": {"market": "0xf69b405cb72c495b47f14d4581ec5f4fdc32c7c783c0b05c5d350af99f74fb57", "price_changes": [{"asset_id": "111483763262460809812427616008076634438113457835729033090496924816271676966924", "price": "0.14", "size": "0", "side": "BUY", "hash": "d6081aca343298737c4c129c781739c5ff247509", "best_bid": "0.19", "best_ask": "0.97"}, {"asset_id": "77871459748036421242663925334747383360075298582158881700736355568100463986230", "price": "0.86", "size": "0", "side": "SELL", "hash": "1093d6e422c9f3b19a95fbd6a9fd50ee1e04598f", "best_bid": "0.03", "best_ask": "0.81"}], "timestamp": "1769384615959", "event_type": "price_change"}}
{"_local_timestamp": "2026-01-25T23:43:36.090302+00:00", "data": {"market": "0xa3476e8efbbc5557ff9f58978bcf85b7c2bc0c14d2f2c5891f1861a0e95c71c7", "price_changes": [{"asset_id": "77616069079544766632313130435803131534837904050680582581189964299844607679338", "price": "0.14", "size": "0", "side": "BUY", "hash": "bed071188343b18bf3cea246614daddc8907f6ed", "best_bid": "0.16", "best_ask": "0.97"}, {"asset_id": "49075166570883369230840079099601560361862864964529664437077360133815011449025", "price": "0.86", "size": "0", "side": "SELL", "hash": "6a2fe0a8babd8d6f9533b09a7a3d6ccf4e8e7491", "best_bid": "0.03", "best_ask": "0.84"}], "timestamp": "1769384615959", "event_type": "price_change"}}
{"_local_timestamp": "2026-01-25T23:43:36.120187+00:00", "data": {"market": "0xf69b405cb72c495b47f14d4581ec5f4fdc32c7c783c0b05c5d350af99f74fb57", "price_changes": [{"asset_id": "111483763262460809812427616008076634438113457835729033090496924816271676966924", "price": "0.12", "size": "20", "side": "BUY", "hash": "a4f9c8f02a487210eaeed4951df99d13d9c61330", "best_bid": "0.19", "best_ask": "0.97"}, {"asset_id": "77871459748036421242663925334747383360075298582158881700736355568100463986230", "price": "0.88", "size": "20", "side": "SELL", "hash": "a4d0c0c3155f32047f588044e88882465dbcd0f7", "best_bid": "0.03", "best_ask": "0.81"}], "timestamp": "1769384615985", "event_type": "price_change"}}
{"_local_timestamp": "2026-01-25T23:43:36.120865+00:00", "data": {"market": "0xa3476e8efbbc5557ff9f58978bcf85b7c2bc0c14d2f2c5891f1861a0e95c71c7", "price_changes": [{"asset_id": "77616069079544766632313130435803131534837904050680582581189964299844607679338", "price": "0.12", "size": "20", "side": "BUY", "hash": "4187e18f42bc4c8845288defff4e6d832818445b", "best_bid": "0.16", "best_ask": "0.97"}, {"asset_id": "49075166570883369230840079099601560361862864964529664437077360133815011449025", "price": "0.88", "size": "20", "side": "SELL", "hash": "c907d5a6a6b36bcb64d370c38aa60d16949e4628", "best_bid": "0.03", "best_ask": "0.84"}], "timestamp": "1769384615985", "event_type": "price_change"}}
{"_local_timestamp": "2026-01-25T23:43:36.882281+00:00", "data": {"market": "0xfe76f366b01cffc5f3c2551ca2fafd3626551f8e67c45e90bcb9980fadefb1d9", "price_changes": [{"asset_id": "91464103984107757678948958563250156809345102931554507444370450055330522832734", "price": "0.12", "size": "0", "side": "BUY", "hash": "252c60ac3b45d56c0bce973e60ce886ca5545c76", "best_bid": "0.19", "best_ask": "0.97"}, {"asset_id": "113047842163343397942154658230859519377162790695920966272941515248645143857449", "price": "0.88", "size": "0", "side": "SELL", "hash": "cc65aabcec0040346c8679d2c244bf66a7029ecd", "best_bid": "0.03", "best_ask": "0.81"}], "timestamp": "1769384616740", "event_type": "price_change"}}
{"_local_timestamp": "2026-01-25T23:43:36.898015+00:00", "data": {"market": "0xb9d3c208d8eb2f3403144092d0e55a4ecf7a6493e33890b35140197a63148d14", "price_changes": [{"asset_id": "70717802646694382009573815278721437797667570104667888155891561185095387198938", "price": "0.12", "size": "0", "side": "BUY", "hash": "a5e5af73e79ce181da8011dbdc6068f2978f9626", "best_bid": "0.19", "best_ask": "0.97"}, {"asset_id": "63581074489545967013426062325864715209547016020665245565255381968385916667995", "price": "0.88", "size": "0", "side": "SELL", "hash": "f2893c0e8eb65c6fab423a033635e9633841f5dd", "best_bid": "0.03", "best_ask": "0.81"}], "timestamp": "1769384616741", "event_type": "price_change"}}
{"_local_timestamp": "2026-01-25T23:43:37.132734+00:00", "data": {"market": "0xe0a32dbfe006ba8c5031351f5243c5cd9a58cf3c37b566cc82a9f7d41f8302c7", "price_changes": [{"asset_id": "65815064799788774655435771148232734980061574308316816581700167067698511121921", "price": "0.12", "size": "0", "side": "BUY", "hash": "275002ded59933e1f8cda1d8e7d3b7099c22a6cf", "best_bid": "0.19", "best_ask": "0.97"}, {"asset_id": "4885632818167351187788551933410416061445761831692101146500029904141404303906", "price": "0.88", "size": "0", "side": "SELL", "hash": "5c987a63c7aa05fe394d555ae79d50e6226594fd", "best_bid": "0.03", "best_ask": "0.81"}], "timestamp": "1769384616741", "event_type": "price_change"}}
{"_local_timestamp": "2026-01-25T23:43:37.133464+00:00", "data": {"market": "0xe0a32dbfe006ba8c5031351f5243c5cd9a58cf3c37b566cc82a9f7d41f8302c7", "price_changes": [{"asset_id": "65815064799788774655435771148232734980061574308316816581700167067698511121921", "price": "0.14", "size": "20", "side": "BUY", "hash": "275002ded59933e1f8cda1d8e7d3b7099c22a6cf", "best_bid": "0.19", "best_ask": "0.97"}, {"asset_id": "4885632818167351187788551933410416061445761831692101146500029904141404303906", "price": "0.86", "size": "20", "side": "SELL", "hash": "5c987a63c7aa05fe394d555ae79d50e6226594fd", "best_bid": "0.03", "best_ask": "0.81"}], "timestamp": "1769384616741", "event_type": "price_change"}}
{"_local_timestamp": "2026-01-25T23:43:37.134025+00:00", "data": {"market": "0x225e0fdd1dbcf8d4ed569658e9fcdadc106fe4df8f3eebab6de3179594e69cae", "price_changes": [{"asset_id": "45764625730845095130147096446415799271154137683585606059451270337639906719390", "price": "0.132", "size": "0", "side": "BUY", "hash": "5b44f92f492008b553f4a457054e63042560d9ca", "best_bid": "0.92", "best_ask": "0.978"}, {"asset_id": "100614172146851019022930506261540059414109250163382945560610650412918760163014", "price": "0.868", "size": "0", "side": "SELL", "hash": "b78e14fe5213973392defeebab4a193e423d74c5", "best_bid": "0.022", "best_ask": "0.08"}], "timestamp": "1769384616741", "event_type": "price_change"}}
{"_local_timestamp": "2026-01-25T23:43:37.134599+00:00", "data": {"market": "0xfe76f366b01cffc5f3c2551ca2fafd3626551f8e67c45e90bcb9980fadefb1d9", "price_changes": [{"asset_id": "91464103984107757678948958563250156809345102931554507444370450055330522832734", "price": "0.11", "size": "10", "side": "BUY", "hash": "787979b0abc0f68915cbc6c1a775dd267c60683a", "best_bid": "0.19", "best_ask": "0.97"}, {"asset_id": "113047842163343397942154658230859519377162790695920966272941515248645143857449", "price": "0.89", "size": "10", "side": "SELL", "hash": "06307ce11bf55d55875747c09d132299cb8b3160", "best_bid": "0.03", "best_ask": "0.81"}], "timestamp": "1769384616775", "event_type": "price_change"}}
{"_local_timestamp": "2026-01-25T23:43:37.135137+00:00", "data": {"market": "0xe0a32dbfe006ba8c5031351f5243c5cd9a58cf3c37b566cc82a9f7d41f8302c7", "price_changes": [{"asset_id": "65815064799788774655435771148232734980061574308316816581700167067698511121921", "price": "0.01", "size": "123.31", "side": "BUY", "hash": "11d63b55a6ac9b506bb79dc41f655db74d069004", "best_bid": "0.19", "best_ask": "0.97"}, {"asset_id": "4885632818167351187788551933410416061445761831692101146500029904141404303906", "price": "0.99", "size": "123.31", "side": "SELL", "hash": "0b7be72f25264b9c7516a22a2df20473ea8922c3", "best_bid": "0.03", "best_ask": "0.81"}], "timestamp": "1769384616883", "event_type": "price_change"}}
{"_local_timestamp": "2026-01-25T23:43:37.135668+00:00", "data": {"market": "0xb9d3c208d8eb2f3403144092d0e55a4ecf7a6493e33890b35140197a63148d14", "price_changes": [{"asset_id": "70717802646694382009573815278721437797667570104667888155891561185095387198938", "price": "0.11", "size": "15.4", "side": "BUY", "hash": "7b52728fa77cb2184283fc98ecc528073343e24a", "best_bid": "0.19", "best_ask": "0.97"}, {"asset_id": "63581074489545967013426062325864715209547016020665245565255381968385916667995", "price": "0.89", "size": "15.4", "side": "SELL", "hash": "e29f8e02f14b8d6fe183b1217d19477ff9d7a469", "best_bid": "0.03", "best_ask": "0.81"}], "timestamp": "1769384616928", "event_type": "price_change"}}
{"_local_timestamp": "2026-01-25T23:43:38.406596+00:00", "data": {"market": "0xfe76f366b01cffc5f3c2551ca2fafd3626551f8e67c45e90bcb9980fadefb1d9", "price_changes": [{"asset_id": "91464103984107757678948958563250156809345102931554507444370450055330522832734", "price": "0.13", "size": "0", "side": "BUY", "hash": "1ad7f468bd68c55eb1b8080dcd3f0dcf6cf04ef2", "best_bid": "0.19", "best_ask": "0.97"}, {"asset_id": "113047842163343397942154658230859519377162790695920966272941515248645143857449", "price": "0.87", "size": "0", "side": "SELL", "hash": "eea829417679239d9615e09b74487c9104d5bf2f", "best_bid": "0.03", "best_ask": "0.81"}], "timestamp": "1769384618282", "event_type": "price_change"}}
{"_local_timestamp": "2026-01-25T23:43:38.407459+00:00", "data": {"market": "0xb9d3c208d8eb2f3403144092d0e55a4ecf7a6493e33890b35140197a63148d14", "price_changes": [{"asset_id": "70717802646694382009573815278721437797667570104667888155891561185095387198938", "price": "0.13", "size": "0", "side": "BUY", "hash": "a05fb31d97c6910c27db889a09efbec7423f326e", "best_bid": "0.19", "best_ask": "0.97"}, {"asset_id": "63581074489545967013426062325864715209547016020665245565255381968385916667995", "price": "0.87", "size": "0", "side": "SELL", "hash": "ade724e1d622314810074826ef168c441dbe8ec5", "best_bid": "0.03", "best_ask": "0.81"}], "timestamp": "1769384618282", "event_type": "price_change"}}
{"_local_timestamp": "2026-01-25T23:43:38.433073+00:00", "data": {"market": "0xfe76f366b01cffc5f3c2551ca2fafd3626551f8e67c45e90bcb9980fadefb1d9", "price_changes": [{"asset_id": "91464103984107757678948958563250156809345102931554507444370450055330522832734", "price": "0.12", "size": "20", "side": "BUY", "hash": "f38faa654eae8a76c0fdb511697f1dc9dc15e36d", "best_bid": "0.19", "best_ask": "0.97"}, {"asset_id": "113047842163343397942154658230859519377162790695920966272941515248645143857449", "price": "0.88", "size": "20", "side": "SELL", "hash": "0bff097b435c8d0a4c1e82a6f1eec8b756106663", "best_bid": "0.03", "best_ask": "0.81"}], "timestamp": "1769384618311", "event_type": "price_change"}}
{"_local_timestamp": "2026-01-25T23:43:38.433740+00:00", "data": {"market": "0xb9d3c208d8eb2f3403144092d0e55a4ecf7a6493e33890b35140197a63148d14", "price_changes": [{"asset_id": "70717802646694382009573815278721437797667570104667888155891561185095387198938", "price": "0.12", "size": "20", "side": "BUY", "hash": "0a897360f85d05a2662f4764a3205d7aa412a962", "best_bid": "0.19", "best_ask": "0.97"}, {"asset_id": "63581074489545967013426062325864715209547016020665245565255381968385916667995", "price": "0.88", "size": "20", "side": "SELL", "hash": "9207ef3536af39704f95f5703ad43fc804ae61d6", "best_bid": "0.03", "best_ask": "0.81"}], "timestamp": "1769384618311", "event_type": "price_change"}}
{"_local_timestamp": "2026-01-25T23:43:39.762505+00:00", "data": {"market": "0xe0a32dbfe006ba8c5031351f5243c5cd9a58cf3c37b566cc82a9f7d41f8302c7", "price_changes": [{"asset_id": "65815064799788774655435771148232734980061574308316816581700167067698511121921", "price": "0.19", "size": "20", "side": "BUY", "hash": "31983f450669ed5dc6102c5b217b212bb5b08c84", "best_bid": "0.19", "best_ask": "0.97"}, {"asset_id": "4885632818167351187788551933410416061445761831692101146500029904141404303906", "price": "0.81", "size": "20", "side": "SELL", "hash": "c2175d3bf0d7b6727d7fde18ff7947aa1af29441", "best_bid": "0.03", "best_ask": "0.81"}], "timestamp": "1769384619643", "event_type": "price_change"}}
{"_local_timestamp": "2026-01-25T23:43:39.764477+00:00", "data": {"market": "0xfe76f366b01cffc5f3c2551ca2fafd3626551f8e67c45e90bcb9980fadefb1d9", "price_changes": [{"asset_id": "91464103984107757678948958563250156809345102931554507444370450055330522832734", "price": "0.18", "size": "0", "side": "BUY", "hash": "8626d59bc887840a2b1f5d557a2d6d97536c8dda", "best_bid": "0.19", "best_ask": "0.97"}, {"asset_id": "113047842163343397942154658230859519377162790695920966272941515248645143857449", "price": "0.82", "size": "0", "side": "SELL", "hash": "60c2592ebd84f4eb6a8dd7f74c2e86d7d443d22d", "best_bid": "0.03", "best_ask": "0.81"}], "timestamp": "1769384619643", "event_type": "price_change"}}
{"_local_timestamp": "2026-01-25T23:43:39.765103+00:00", "data": {"market": "0xfe76f366b01cffc5f3c2551ca2fafd3626551f8e67c45e90bcb9980fadefb1d9", "price_changes": [{"asset_id": "91464103984107757678948958563250156809345102931554507444370450055330522832734", "price": "0.17", "size": "0", "side": "BUY", "hash": "8626d59bc887840a2b1f5d557a2d6d97536c8dda", "best_bid": "0.19", "best_ask": "0.97"}, {"asset_id": "113047842163343397942154658230859519377162790695920966272941515248645143857449", "price": "0.83", "size": "0", "side": "SELL", "hash": "60c2592ebd84f4eb6a8dd7f74c2e86d7d443d22d", "best_bid": "0.03", "best_ask": "0.81"}], "timestamp": "1769384619643", "event_type": "price_change"}}
{"_local_timestamp": "2026-01-25T23:43:39.767252+00:00", "data": {"market": "0xb9d3c208d8eb2f3403144092d0e55a4ecf7a6493e33890b35140197a63148d14", "price_changes": [{"asset_id": "70717802646694382009573815278721437797667570104667888155891561185095387198938", "price": "0.18", "size": "0", "side": "BUY", "hash": "2eb50f53fe5700a1e9720c05b5e96a0673ec1518", "best_bid": "0.19", "best_ask": "0.97"}, {"asset_id": "63581074489545967013426062325864715209547016020665245565255381968385916667995", "price": "0.82", "size": "0", "side": "SELL", "hash": "d76af265f9c222bda4d72be70b9cd5fd25bf74a9", "best_bid": "0.03", "best_ask": "0.81"}], "timestamp": "1769384619643", "event_type": "price_change"}}
{"_local_timestamp": "2026-01-25T23:43:39.767953+00:00", "data": {"market": "0xb9d3c208d8eb2f3403144092d0e55a4ecf7a6493e33890b35140197a63148d14", "price_changes": [{"asset_id": "70717802646694382009573815278721437797667570104667888155891561185095387198938", "price": "0.17", "size": "0", "side": "BUY", "hash": "2eb50f53fe5700a1e9720c05b5e96a0673ec1518", "best_bid": "0.19", "best_ask": "0.97"}, {"asset_id": "63581074489545967013426062325864715209547016020665245565255381968385916667995", "price": "0.83", "size": "0", "side": "SELL", "hash": "d76af265f9c222bda4d72be70b9cd5fd25bf74a9", "best_bid": "0.03", "best_ask": "0.81"}], "timestamp": "1769384619643", "event_type": "price_change"}}
{"_local_timestamp": "2026-01-25T23:43:51.476753+00:00", "data": {"market": "0x225e0fdd1dbcf8d4ed569658e9fcdadc106fe4df8f3eebab6de3179594e69cae", "price_changes": [{"asset_id": "45764625730845095130147096446415799271154137683585606059451270337639906719390", "price": "0.133", "size": "0", "side": "BUY", "hash": "e68ccd4a5ca7218d2ed6edf9924728c393689b0b", "best_bid": "0.92", "best_ask": "0.978"}, {"asset_id": "100614172146851019022930506261540059414109250163382945560610650412918760163014", "price": "0.867", "size": "0", "side": "SELL", "hash": "ae49d63dabb5eeb86c8659d0966e14ffb92df645", "best_bid": "0.022", "best_ask": "0.08"}], "timestamp": "1769384631332", "event_type": "price_change"}}
{"_local_timestamp": "2026-01-25T23:43:53.759617+00:00", "data": {"market": "0x225e0fdd1dbcf8d4ed569658e9fcdadc106fe4df8f3eebab6de3179594e69cae", "price_changes": [{"asset_id": "45764625730845095130147096446415799271154137683585606059451270337639906719390", "price": "0.134", "size": "0", "side": "BUY", "hash": "ae8ddf5d352828e97b001181cfb9cfcfcaeb261c", "best_bid": "0.92", "best_ask": "0.978"}, {"asset_id": "100614172146851019022930506261540059414109250163382945560610650412918760163014", "price": "0.866", "size": "0", "side": "SELL", "hash": "475df6d53c7b4740c67de918699c250dad90fca9", "best_bid": "0.022", "best_ask": "0.08"}], "timestamp": "1769384633626", "event_type": "price_change"}}
{"_local_timestamp": "2026-01-25T23:43:53.788414+00:00", "data": {"market": "0x225e0fdd1dbcf8d4ed569658e9fcdadc106fe4df8f3eebab6de3179594e69cae", "price_changes": [{"asset_id": "45764625730845095130147096446415799271154137683585606059451270337639906719390", "price": "0.132", "size": "20", "side": "BUY", "hash": "a2ece3d4d8b63a885aa523170e8c72651ab9fef0", "best_bid": "0.92", "best_ask": "0.978"}, {"asset_id": "100614172146851019022930506261540059414109250163382945560610650412918760163014", "price": "0.868", "size": "20", "side": "SELL", "hash": "7fb53144957f9548e926e406577b07e64d8faf0d", "best_bid": "0.022", "best_ask": "0.08"}], "timestamp": "1769384633654", "event_type": "price_change"}}
{"_local_timestamp": "2026-01-25T23:45:11.516472+00:00", "data": {"market": "0x225e0fdd1dbcf8d4ed569658e9fcdadc106fe4df8f3eebab6de3179594e69cae", "price_changes": [{"asset_id": "100614172146851019022930506261540059414109250163382945560610650412918760163014", "price": "0.002", "size": "373.41", "side": "BUY", "hash": "8ff05cd2669d4aa77e37996a8df50ee7be77b441", "best_bid": "0.022", "best_ask": "0.08"}, {"asset_id": "45764625730845095130147096446415799271154137683585606059451270337639906719390", "price": "0.998", "size": "373.41", "side": "SELL", "hash": "eca5c4529989560977733db22a7342e188b56f16", "best_bid": "0.92", "best_ask": "0.978"}], "timestamp": "1769384711418", "event_type": "price_change"}}
{"_local_timestamp": "2026-01-25T23:45:11.635472+00:00", "data": {"market": "0x93f28d0ad9d5906fee37296a8a70a57c9e4ed4b3b9aa09029c2d9589ce7ce832", "price_changes": [{"asset_id": "72776331054793272806940188908180904666024448478022907801009755847830868970904", "price": "0.06", "size": "33", "side": "BUY", "hash": "e5ea34a409ba170763ba55b145c8931126c6a322", "best_bid": "0.19", "best_ask": "0.98"}, {"asset_id": "100955895305218895610069502472760899905214942330703669753760270178117749789092", "price": "0.94", "size": "33", "side": "SELL", "hash": "bd7cae21a79dea854d34306034c97bff1afd2397", "best_bid": "0.02", "best_ask": "0.81"}], "timestamp": "1769384711568", "event_type": "price_change"}}
{"_local_timestamp": "2026-01-25T23:45:11.777397+00:00", "data": {"market": "0x93f28d0ad9d5906fee37296a8a70a57c9e4ed4b3b9aa09029c2d9589ce7ce832", "price_changes": [{"asset_id": "72776331054793272806940188908180904666024448478022907801009755847830868970904", "price": "0.09", "size": "10", "side": "BUY", "hash": "e1ea03d399b50e21835248d23e834a899e0e4caf", "best_bid": "0.19", "best_ask": "0.98"}, {"asset_id": "100955895305218895610069502472760899905214942330703669753760270178117749789092", "price": "0.91", "size": "10", "side": "SELL", "hash": "c4fcc839ce87ef7e6b00bd859a48bc17a55aac90", "best_bid": "0.02", "best_ask": "0.81"}], "timestamp": "1769384711675", "event_type": "price_change"}}
{"_local_timestamp": "2026-01-25T23:45:56.229417+00:00", "data": {"market": "0xf69b405cb72c495b47f14d4581ec5f4fdc32c7c783c0b05c5d350af99f74fb57", "price_changes": [{"asset_id": "111483763262460809812427616008076634438113457835729033090496924816271676966924", "price": "0.03", "size": "0", "side": "BUY", "hash": "42a2008bdb5d22092c3f70c75241fe42e0027c99", "best_bid": "0.19", "best_ask": "0.97"}, {"asset_id": "77871459748036421242663925334747383360075298582158881700736355568100463986230", "price": "0.97", "size": "0", "side": "SELL", "hash": "bd9f9e0be3b25dc07bbc09dbb8d89f04d3d0713a", "best_bid": "0.03", "best_ask": "0.81"}], "timestamp": "1769384756077", "event_type": "price_change"}}
{"_local_timestamp": "2026-01-25T23:45:56.466353+00:00", "data": {"market": "0xe0a32dbfe006ba8c5031351f5243c5cd9a58cf3c37b566cc82a9f7d41f8302c7", "price_changes": [{"asset_id": "65815064799788774655435771148232734980061574308316816581700167067698511121921", "price": "0.11", "size": "5.7", "side": "BUY", "hash": "5058809c06ba114e8bd8131bdac992617f09dba8", "best_bid": "0.19", "best_ask": "0.97"}, {"asset_id": "4885632818167351187788551933410416061445761831692101146500029904141404303906", "price": "0.89", "size": "5.7", "side": "SELL", "hash": "10688f917757150623e9aff77aa5b64d47722974", "best_bid": "0.03", "best_ask": "0.81"}], "timestamp": "1769384756083", "event_type": "price_change"}}
{"_local_timestamp": "2026-01-25T23:46:12.950622+00:00", "data": {"market": "0xfe76f366b01cffc5f3c2551ca2fafd3626551f8e67c45e90bcb9980fadefb1d9", "price_changes": [{"asset_id": "91464103984107757678948958563250156809345102931554507444370450055330522832734", "price": "0.04", "size": "0", "side": "BUY", "hash": "db0d4f2ec18ed1b51f56f3b98a19ce1d397ca2a8", "best_bid": "0.19", "best_ask": "0.97"}, {"asset_id": "113047842163343397942154658230859519377162790695920966272941515248645143857449", "price": "0.96", "size": "0", "side": "SELL", "hash": "5715a950050813328144ba634662ad492bd2ec60", "best_bid": "0.03", "best_ask": "0.81"}], "timestamp": "1769384772879", "event_type": "price_change"}}
{"_local_timestamp": "2026-01-25T23:46:12.951331+00:00", "data": {"market": "0xfe76f366b01cffc5f3c2551ca2fafd3626551f8e67c45e90bcb9980fadefb1d9", "price_changes": [{"asset_id": "91464103984107757678948958563250156809345102931554507444370450055330522832734", "price": "0.07", "size": "24", "side": "BUY", "hash": "db0d4f2ec18ed1b51f56f3b98a19ce1d397ca2a8", "best_bid": "0.19", "best_ask": "0.97"}, {"asset_id": "113047842163343397942154658230859519377162790695920966272941515248645143857449", "price": "0.93", "size": "24", "side": "SELL", "hash": "5715a950050813328144ba634662ad492bd2ec60", "best_bid": "0.03", "best_ask": "0.81"}], "timestamp": "1769384772879", "event_type": "price_change"}}
{"_local_timestamp": "2026-01-25T23:46:12.961175+00:00", "data": {"market": "0xf69b405cb72c495b47f14d4581ec5f4fdc32c7c783c0b05c5d350af99f74fb57", "price_changes": [{"asset_id": "111483763262460809812427616008076634438113457835729033090496924816271676966924", "price": "0.04", "size": "0", "side": "BUY", "hash": "9ac566311e94dc160a67a1b9f6d2394d5c37db7a", "best_bid": "0.19", "best_ask": "0.97"}, {"asset_id": "77871459748036421242663925334747383360075298582158881700736355568100463986230", "price": "0.96", "size": "0", "side": "SELL", "hash": "a6037e324dbfd42e40a74e6734b409dcdfb28030", "best_bid": "0.03", "best_ask": "0.81"}], "timestamp": "1769384772880", "event_type": "price_change"}}
{"_local_timestamp": "2026-01-25T23:46:12.961779+00:00", "data": {"market": "0xa3476e8efbbc5557ff9f58978bcf85b7c2bc0c14d2f2c5891f1861a0e95c71c7", "price_changes": [{"asset_id": "77616069079544766632313130435803131534837904050680582581189964299844607679338", "price": "0.07", "size": "16", "side": "BUY", "hash": "c74e019894cb4c216eabc48b5a80c7b5ee14c8db", "best_bid": "0.16", "best_ask": "0.97"}, {"asset_id": "49075166570883369230840079099601560361862864964529664437077360133815011449025", "price": "0.93", "size": "16", "side": "SELL", "hash": "278b92227eda61c7427790ef5d43252facdf24a8", "best_bid": "0.03", "best_ask": "0.84"}], "timestamp": "1769384772879", "event_type": "price_change"}}
{"_local_timestamp": "2026-01-25T23:46:12.962393+00:00", "data": {"market": "0xa3476e8efbbc5557ff9f58978bcf85b7c2bc0c14d2f2c5891f1861a0e95c71c7", "price_changes": [{"asset_id": "77616069079544766632313130435803131534837904050680582581189964299844607679338", "price": "0.11", "size": "10", "side": "BUY", "hash": "c74e019894cb4c216eabc48b5a80c7b5ee14c8db", "best_bid": "0.16", "best_ask": "0.97"}, {"asset_id": "49075166570883369230840079099601560361862864964529664437077360133815011449025", "price": "0.89", "size": "10", "side": "SELL", "hash": "278b92227eda61c7427790ef5d43252facdf24a8", "best_bid": "0.03", "best_ask": "0.84"}], "timestamp": "1769384772879", "event_type": "price_change"}}
{"_local_timestamp": "2026-01-25T23:46:12.962963+00:00", "data": {"market": "0x93f28d0ad9d5906fee37296a8a70a57c9e4ed4b3b9aa09029c2d9589ce7ce832", "price_changes": [{"asset_id": "72776331054793272806940188908180904666024448478022907801009755847830868970904", "price": "0.04", "size": "0", "side": "BUY", "hash": "c4d70b572d77f83a5ac8be680b66ef101f6a8760", "best_bid": "0.19", "best_ask": "0.98"}, {"asset_id": "100955895305218895610069502472760899905214942330703669753760270178117749789092", "price": "0.96", "size": "0", "side": "SELL", "hash": "829f113fa32d958e293fa23d06d69348537ebcb7", "best_bid": "0.02", "best_ask": "0.81"}], "timestamp": "1769384772879", "event_type": "price_change"}}
{"_local_timestamp": "2026-01-25T23:46:12.963537+00:00", "data": {"market": "0x93f28d0ad9d5906fee37296a8a70a57c9e4ed4b3b9aa09029c2d9589ce7ce832", "price_changes": [{"asset_id": "72776331054793272806940188908180904666024448478022907801009755847830868970904", "price": "0.07", "size": "0", "side": "BUY", "hash": "c4d70b572d77f83a5ac8be680b66ef101f6a8760", "best_bid": "0.19", "best_ask": "0.98"}, {"asset_id": "100955895305218895610069502472760899905214942330703669753760270178117749789092", "price": "0.93", "size": "0", "side": "SELL", "hash": "829f113fa32d958e293fa23d06d69348537ebcb7", "best_bid": "0.02", "best_ask": "0.81"}], "timestamp": "1769384772879", "event_type": "price_change"}}
{"_local_timestamp": "2026-01-25T23:46:12.964155+00:00", "data": {"market": "0x93f28d0ad9d5906fee37296a8a70a57c9e4ed4b3b9aa09029c2d9589ce7ce832", "price_changes": [{"asset_id": "72776331054793272806940188908180904666024448478022907801009755847830868970904", "price": "0.11", "size": "0", "side": "BUY", "hash": "c4d70b572d77f83a5ac8be680b66ef101f6a8760", "best_bid": "0.19", "best_ask": "0.98"}, {"asset_id": "100955895305218895610069502472760899905214942330703669753760270178117749789092", "price": "0.89", "size": "0", "side": "SELL", "hash": "829f113fa32d958e293fa23d06d69348537ebcb7", "best_bid": "0.02", "best_ask": "0.81"}], "timestamp": "1769384772879", "event_type": "price_change"}}
{"_local_timestamp": "2026-01-25T23:46:13.141307+00:00", "data": {"market": "0xf69b405cb72c495b47f14d4581ec5f4fdc32c7c783c0b05c5d350af99f74fb57", "price_changes": [{"asset_id": "111483763262460809812427616008076634438113457835729033090496924816271676966924", "price": "0.02", "size": "33.19", "side": "BUY", "hash": "1436021c297ae3284461f338ca608f7c07ca5939", "best_bid": "0.19", "best_ask": "0.97"}, {"asset_id": "77871459748036421242663925334747383360075298582158881700736355568100463986230", "price": "0.98", "size": "33.19", "side": "SELL", "hash": "f08fc9fd42c7f582a4c349193beb7c0767744910", "best_bid": "0.03", "best_ask": "0.81"}], "timestamp": "1769384773073", "event_type": "price_change"}}
{"_local_timestamp": "2026-01-25T23:46:13.232929+00:00", "data": {"market": "0xfe76f366b01cffc5f3c2551ca2fafd3626551f8e67c45e90bcb9980fadefb1d9", "price_changes": [{"asset_id": "91464103984107757678948958563250156809345102931554507444370450055330522832734", "price": "0.02", "size": "32.73", "side": "BUY", "hash": "621744f3fde0a350f3fb23ef446ce54d7bd4c434", "best_bid": "0.19", "best_ask": "0.97"}, {"asset_id": "113047842163343397942154658230859519377162790695920966272941515248645143857449", "price": "0.98", "size": "32.73", "side": "SELL", "hash": "b2325b321ac21046412f80b5b816dfdd69db5799", "best_bid": "0.03", "best_ask": "0.81"}], "timestamp": "1769384773163", "event_type": "price_change"}}
{"_local_timestamp": "2026-01-25T23:46:13.243707+00:00", "data": {"market": "0xfe76f366b01cffc5f3c2551ca2fafd3626551f8e67c45e90bcb9980fadefb1d9", "price_changes": [{"asset_id": "91464103984107757678948958563250156809345102931554507444370450055330522832734", "price": "0.07", "size": "30.04", "side": "BUY", "hash": "095752aecbbd0cd96efbddfe8ef4d24f2fde3bf9", "best_bid": "0.19", "best_ask": "0.97"}, {"asset_id": "113047842163343397942154658230859519377162790695920966272941515248645143857449", "price": "0.93", "size": "30.04", "side": "SELL", "hash": "015526b679cf22c9675ce4076b082177a6cddbb5", "best_bid": "0.03", "best_ask": "0.81"}], "timestamp": "1769384773169", "event_type": "price_change"}}
{"_local_timestamp": "2026-01-25T23:46:13.245214+00:00", "data": {"market": "0xfe76f366b01cffc5f3c2551ca2fafd3626551f8e67c45e90bcb9980fadefb1d9", "price_changes": [{"asset_id": "91464103984107757678948958563250156809345102931554507444370450055330522832734", "price": "0.11", "size": "15.89", "side": "BUY", "hash": "e8b92b45fdced6179fc7e9fc6a42068875aec82f", "best_bid": "0.19", "best_ask": "0.97"}, {"asset_id": "113047842163343397942154658230859519377162790695920966272941515248645143857449", "price": "0.89", "size": "15.89", "side": "SELL", "hash": "62afdf5fd3bd0edadaa0e8117a794ff1fe21e253", "best_bid": "0.03", "best_ask": "0.81"}], "timestamp": "1769384773175", "event_type": "price_change"}}
{"_local_timestamp": "2026-01-25T23:46:13.587232+00:00", "data": {"market": "0x93f28d0ad9d5906fee37296a8a70a57c9e4ed4b3b9aa09029c2d9589ce7ce832", "price_changes": [{"asset_id": "72776331054793272806940188908180904666024448478022907801009755847830868970904", "price": "0.1", "size": "8.22", "side": "BUY", "hash": "1cfcefb058eed8a0875ccc471693d7454abe4ee1", "best_bid": "0.19", "best_ask": "0.98"}, {"asset_id": "100955895305218895610069502472760899905214942330703669753760270178117749789092", "price": "0.9", "size": "8.22", "side": "SELL", "hash": "f4fcfaf9268643f48870efb0066e4fc5f46fd0fb", "best_bid": "0.02", "best_ask": "0.81"}], "timestamp": "1769384773522", "event_type": "price_change"}}
{"_local_timestamp": "2026-01-25T23:46:13.599266+00:00", "data": {"market": "0xa3476e8efbbc5557ff9f58978bcf85b7c2bc0c14d2f2c5891f1861a0e95c71c7", "price_changes": [{"asset_id": "77616069079544766632313130435803131534837904050680582581189964299844607679338", "price": "0.02", "size": "43.69", "side": "BUY", "hash": "e7884b7f009c140656f4c7911ab31778c414bca9", "best_bid": "0.16", "best_ask": "0.97"}, {"asset_id": "49075166570883369230840079099601560361862864964529664437077360133815011449025", "price": "0.98", "size": "43.69", "side": "SELL", "hash": "a25be9f11baa2f76a523555c05df84c004fa255d", "best_bid": "0.03", "best_ask": "0.84"}], "timestamp": "1769384773524", "event_type": "price_change"}}
{"_local_timestamp": "2026-01-25T23:46:13.600830+00:00", "data": {"market": "0x93f28d0ad9d5906fee37296a8a70a57c9e4ed4b3b9aa09029c2d9589ce7ce832", "price_changes": [{"asset_id": "72776331054793272806940188908180904666024448478022907801009755847830868970904", "price": "0.06", "size": "41.11", "side": "BUY", "hash": "c62b9a2ea51ba2e87cd227896c27e016839b6aad", "best_bid": "0.19", "best_ask": "0.98"}, {"asset_id": "100955895305218895610069502472760899905214942330703669753760270178117749789092", "price": "0.94", "size": "41.11", "side": "SELL", "hash": "2bec0f80ae9d716da581897b132bf16a21ea460e", "best_bid": "0.02", "best_ask": "0.81"}], "timestamp": "1769384773527", "event_type": "price_change"}}
{"_local_timestamp": "2026-01-25T23:46:13.602258+00:00", "data": {"market": "0xa3476e8efbbc5557ff9f58978bcf85b7c2bc0c14d2f2c5891f1861a0e95c71c7", "price_changes": [{"asset_id": "77616069079544766632313130435803131534837904050680582581189964299844607679338", "price": "0.08", "size": "10.67", "side": "BUY", "hash": "cfb694f63643c66f9ee3b48fbf2291e07c4683a1", "best_bid": "0.16", "best_ask": "0.97"}, {"asset_id": "49075166570883369230840079099601560361862864964529664437077360133815011449025", "price": "0.92", "size": "10.67", "side": "SELL", "hash": "fb3f55156fe4e9a7dfea96ad0beb236bf2a57591", "best_bid": "0.03", "best_ask": "0.84"}], "timestamp": "1769384773533", "event_type": "price_change"}}
{"_local_timestamp": "2026-01-25T23:46:13.729192+00:00", "data": {"market": "0x25025db13d5868308eb2f1f57beaf7cbea76c4014201800853a4c1aaad3046ee", "price_changes": [{"asset_id": "69171629149106323292749070292707293928031973221371003911300207535275094378436", "price": "0.12", "size": "0", "side": "BUY", "hash": "5540b207e67e9500c75e93d84ee799bf882b7158", "best_bid": "0.72", "best_ask": "0.97"}, {"asset_id": "15113128431693879081528076048684622701923990563320934711420493231791911133880", "price": "0.88", "size": "0", "side": "SELL", "hash": "413b8f9c77efd4e4dc5e23a04770875e1f66277f", "best_bid": "0.03", "best_ask": "0.28"}], "timestamp": "1769384773658", "event_type": "price_change"}}
{"_local_timestamp": "2026-01-25T23:46:13.730855+00:00", "data": {"market": "0xb9d3c208d8eb2f3403144092d0e55a4ecf7a6493e33890b35140197a63148d14", "price_changes": [{"asset_id": "70717802646694382009573815278721437797667570104667888155891561185095387198938", "price": "0.04", "size": "0", "side": "BUY", "hash": "b6cc6c10fc6a8495dc3c7ffb08854945675501bd", "best_bid": "0.19", "best_ask": "0.97"}, {"asset_id": "63581074489545967013426062325864715209547016020665245565255381968385916667995", "price": "0.96", "size": "0", "side": "SELL", "hash": "6d0f1f28b1de3b0fbf1274fae8695234e8db8479", "best_bid": "0.03", "best_ask": "0.81"}], "timestamp": "1769384773658", "event_type": "price_change"}}
{"_local_timestamp": "2026-01-25T23:46:13.954874+00:00", "data": {"market": "0x25025db13d5868308eb2f1f57beaf7cbea76c4014201800853a4c1aaad3046ee", "price_changes": [{"asset_id": "69171629149106323292749070292707293928031973221371003911300207535275094378436", "price": "0.12", "size": "5.83", "side": "BUY", "hash": "b7cbd400b27b5f6cf8a528d297fd5fc6d8c67e08", "best_bid": "0.72", "best_ask": "0.97"}, {"asset_id": "15113128431693879081528076048684622701923990563320934711420493231791911133880", "price": "0.88", "size": "5.83", "side": "SELL", "hash": "11c284808689063749f7103b3a88fbe1e7d92688", "best_bid": "0.03", "best_ask": "0.28"}], "timestamp": "1769384773883", "event_type": "price_change"}}
{"_local_timestamp": "2026-01-25T23:46:13.956488+00:00", "data": {"market": "0xb9d3c208d8eb2f3403144092d0e55a4ecf7a6493e33890b35140197a63148d14", "price_changes": [{"asset_id": "70717802646694382009573815278721437797667570104667888155891561185095387198938", "price": "0.02", "size": "31.71", "side": "BUY", "hash": "b1a4e4d346ff773003f11d0deb5c2a8139a363d3", "best_bid": "0.19", "best_ask": "0.97"}, {"asset_id": "63581074489545967013426062325864715209547016020665245565255381968385916667995", "price": "0.98", "size": "31.71", "side": "SELL", "hash": "5b27ae58f09f42af03d3a8d13e8757e09036a923", "best_bid": "0.03", "best_ask": "0.81"}], "timestamp": "1769384773883", "event_type": "price_change"}}
{"_local_timestamp": "2026-01-25T23:46:26.298573+00:00", "data": {"market": "0xe0a32dbfe006ba8c5031351f5243c5cd9a58cf3c37b566cc82a9f7d41f8302c7", "price_changes": [{"asset_id": "65815064799788774655435771148232734980061574308316816581700167067698511121921", "price": "0.06", "size": "48", "side": "BUY", "hash": "f4f5ede92482df8612260913c77f0b29734b48bb", "best_bid": "0.19", "best_ask": "0.97"}, {"asset_id": "4885632818167351187788551933410416061445761831692101146500029904141404303906", "price": "0.94", "size": "48", "side": "SELL", "hash": "6e19e649494b80faac09043e541e3ba4cb060677", "best_bid": "0.03", "best_ask": "0.81"}], "timestamp": "1769384786218", "event_type": "price_change"}}
{"_local_timestamp": "2026-01-25T23:46:26.299319+00:00", "data": {"market": "0xf69b405cb72c495b47f14d4581ec5f4fdc32c7c783c0b05c5d350af99f74fb57", "price_changes": [{"asset_id": "111483763262460809812427616008076634438113457835729033090496924816271676966924", "price": "0.07", "size": "21.74", "side": "BUY", "hash": "dec9da8d9721b56c02ff70a2a6d352abf351e10f", "best_bid": "0.19", "best_ask": "0.97"}, {"asset_id": "77871459748036421242663925334747383360075298582158881700736355568100463986230", "price": "0.93", "size": "21.74", "side": "SELL", "hash": "2746af732f2fbce44aa272d6470024d4e58cc90c", "best_bid": "0.03", "best_ask": "0.81"}], "timestamp": "1769384786219", "event_type": "price_change"}}
{"_local_timestamp": "2026-01-25T23:46:32.980085+00:00", "data": {"market": "0xa3476e8efbbc5557ff9f58978bcf85b7c2bc0c14d2f2c5891f1861a0e95c71c7", "price_changes": [{"asset_id": "49075166570883369230840079099601560361862864964529664437077360133815011449025", "price": "0.02", "size": "125", "side": "BUY", "hash": "c0c74fcbf5d9e80eafb7bcfb5518619f5a579a76", "best_bid": "0.03", "best_ask": "0.84"}, {"asset_id": "77616069079544766632313130435803131534837904050680582581189964299844607679338", "price": "0.98", "size": "125", "side": "SELL", "hash": "ddaae4ac99052b090de78094431c009601dbb549", "best_bid": "0.16", "best_ask": "0.97"}], "timestamp": "1769384792898", "event_type": "price_change"}}
{"_local_timestamp": "2026-01-25T23:46:34.320316+00:00", "data": {"market": "0xf69b405cb72c495b47f14d4581ec5f4fdc32c7c783c0b05c5d350af99f74fb57", "price_changes": [{"asset_id": "77871459748036421242663925334747383360075298582158881700736355568100463986230", "price": "0.02", "size": "120", "side": "BUY", "hash": "50c4c9857e00dfb678faeabdbe96e479fca87568", "best_bid": "0.03", "best_ask": "0.81"}, {"asset_id": "111483763262460809812427616008076634438113457835729033090496924816271676966924", "price": "0.98", "size": "120", "side": "SELL", "hash": "b2a7993110e32d7304cfcc1477c67683ce94aad5", "best_bid": "0.19", "best_ask": "0.97"}], "timestamp": "1769384794242", "event_type": "price_change"}}
{"_local_timestamp": "2026-01-25T23:46:34.321094+00:00", "data": {"market": "0xfe76f366b01cffc5f3c2551ca2fafd3626551f8e67c45e90bcb9980fadefb1d9", "price_changes": [{"asset_id": "113047842163343397942154658230859519377162790695920966272941515248645143857449", "price": "0.02", "size": "125", "side": "BUY", "hash": "ff502a3ee1e80764fb63bf3dde051a08f6200a41", "best_bid": "0.03", "best_ask": "0.81"}, {"asset_id": "91464103984107757678948958563250156809345102931554507444370450055330522832734", "price": "0.98", "size": "125", "side": "SELL", "hash": "ba5d47f456d9575f3fc76630c473707c0376018f", "best_bid": "0.19", "best_ask": "0.97"}], "timestamp": "1769384794243", "event_type": "price_change"}}
{"_local_timestamp": "2026-01-25T23:46:34.592666+00:00", "data": {"market": "0xe0a32dbfe006ba8c5031351f5243c5cd9a58cf3c37b566cc82a9f7d41f8302c7", "price_changes": [{"asset_id": "4885632818167351187788551933410416061445761831692101146500029904141404303906", "price": "0.02", "size": "127.5", "side": "BUY", "hash": "c9fcde494b32777909d4c327699e0508982b3c7c", "best_bid": "0.03", "best_ask": "0.81"}, {"asset_id": "65815064799788774655435771148232734980061574308316816581700167067698511121921", "price": "0.98", "size": "127.5", "side": "SELL", "hash": "23ae35cb953d15149f25fdeb3eb8ed4e9b2e0934", "best_bid": "0.19", "best_ask": "0.97"}], "timestamp": "1769384794520", "event_type": "price_change"}}
{"_local_timestamp": "2026-01-25T23:46:34.593558+00:00", "data": {"market": "0xb9d3c208d8eb2f3403144092d0e55a4ecf7a6493e33890b35140197a63148d14", "price_changes": [{"asset_id": "63581074489545967013426062325864715209547016020665245565255381968385916667995", "price": "0.02", "size": "120", "side": "BUY", "hash": "27e9f148e4f7f4f261f38a495946622eb017b5ea", "best_bid": "0.03", "best_ask": "0.81"}, {"asset_id": "70717802646694382009573815278721437797667570104667888155891561185095387198938", "price": "0.98", "size": "120", "side": "SELL", "hash": "68c356615321f4bbf9668f25c020f47ce82f8774", "best_bid": "0.19", "best_ask": "0.97"}], "timestamp": "1769384794521", "event_type": "price_change"}}
{"_local_timestamp": "2026-01-25T23:46:34.663086+00:00", "data": {"market": "0xf69b405cb72c495b47f14d4581ec5f4fdc32c7c783c0b05c5d350af99f74fb57", "price_changes": [{"asset_id": "111483763262460809812427616008076634438113457835729033090496924816271676966924", "price": "0.11", "size": "5.99", "side": "BUY", "hash": "e9fb027bac9598a62df9bb25f5b6def4c7ec3814", "best_bid": "0.19", "best_ask": "0.97"}, {"asset_id": "77871459748036421242663925334747383360075298582158881700736355568100463986230", "price": "0.89", "size": "5.99", "side": "SELL", "hash": "1876d9e45469ec67aacfe262baebb0cbb6d05f0b", "best_bid": "0.03", "best_ask": "0.81"}], "timestamp": "1769384794577", "event_type": "price_change"}}
{"_local_timestamp": "2026-01-25T23:46:34.663802+00:00", "data": {"market": "0xa3476e8efbbc5557ff9f58978bcf85b7c2bc0c14d2f2c5891f1861a0e95c71c7", "price_changes": [{"asset_id": "77616069079544766632313130435803131534837904050680582581189964299844607679338", "price": "0.11", "size": "0", "side": "BUY", "hash": "27a89762b459e34a3d663a41e46790f26ffc559d", "best_bid": "0.16", "best_ask": "0.97"}, {"asset_id": "49075166570883369230840079099601560361862864964529664437077360133815011449025", "price": "0.89", "size": "0", "side": "SELL", "hash": "0daf475b8749a69524813892b979d8f36b272bd1", "best_bid": "0.03", "best_ask": "0.84"}], "timestamp": "1769384794577", "event_type": "price_change"}}
{"_local_timestamp": "2026-01-25T23:46:34.784492+00:00", "data": {"market": "0xf69b405cb72c495b47f14d4581ec5f4fdc32c7c783c0b05c5d350af99f74fb57", "price_changes": [{"asset_id": "111483763262460809812427616008076634438113457835729033090496924816271676966924", "price": "0.08", "size": "10", "side": "BUY", "hash": "3dc9e809e5fb8d9c421adf6a8c30be33773adcba", "best_bid": "0.19", "best_ask": "0.97"}, {"asset_id": "77871459748036421242663925334747383360075298582158881700736355568100463986230", "price": "0.92", "size": "10", "side": "SELL", "hash": "b73638358936d3a65908eb9144a6001f5adf2b61", "best_bid": "0.03", "best_ask": "0.81"}], "timestamp": "1769384794711", "event_type": "price_change"}}
{"_local_timestamp": "2026-01-25T23:46:34.785246+00:00", "data": {"market": "0xa3476e8efbbc5557ff9f58978bcf85b7c2bc0c14d2f2c5891f1861a0e95c71c7", "price_changes": [{"asset_id": "77616069079544766632313130435803131534837904050680582581189964299844607679338", "price": "0.09", "size": "10", "side": "BUY", "hash": "a0b75b90d8f373113b6af2ef18a75aadc04d6dd2", "best_bid": "0.16", "best_ask": "0.97"}, {"asset_id": "49075166570883369230840079099601560361862864964529664437077360133815011449025", "price": "0.91", "size": "10", "side": "SELL", "hash": "e300952361cb6b1762fa2b9644908939aa4fc3ac", "best_bid": "0.03", "best_ask": "0.84"}], "timestamp": "1769384794711", "event_type": "price_change"}}
{"_local_timestamp": "2026-01-25T23:46:35.124459+00:00", "data": {"market": "0xf69b405cb72c495b47f14d4581ec5f4fdc32c7c783c0b05c5d350af99f74fb57", "price_changes": [{"asset_id": "111483763262460809812427616008076634438113457835729033090496924816271676966924", "price": "0.12", "size": "0", "side": "BUY", "hash": "f8fbcd76e470b560700d3e3862e282540147aa23", "best_bid": "0.19", "best_ask": "0.97"}, {"asset_id": "77871459748036421242663925334747383360075298582158881700736355568100463986230", "price": "0.88", "size": "0", "side": "SELL", "hash": "a4b00d3e8b31af83112cd2a55bd4a6cf6615a0d2", "best_bid": "0.03", "best_ask": "0.81"}], "timestamp": "1769384795045", "event_type": "price_change"}}
{"_local_timestamp": "2026-01-25T23:46:35.125207+00:00", "data": {"market": "0xa3476e8efbbc5557ff9f58978bcf85b7c2bc0c14d2f2c5891f1861a0e95c71c7", "price_changes": [{"asset_id": "77616069079544766632313130435803131534837904050680582581189964299844607679338", "price": "0.12", "size": "0", "side": "BUY", "hash": "734a756be6aab89918cd20b3def83fe7110b4001", "best_bid": "0.16", "best_ask": "0.97"}, {"asset_id": "49075166570883369230840079099601560361862864964529664437077360133815011449025", "price": "0.88", "size": "0", "side": "SELL", "hash": "4005008c6e79be687f8ebd133fe4bddc0fb5dfce", "best_bid": "0.03", "best_ask": "0.84"}], "timestamp": "1769384795045", "event_type": "price_change"}}
{"_local_timestamp": "2026-01-25T23:46:35.147075+00:00", "data": {"market": "0xf69b405cb72c495b47f14d4581ec5f4fdc32c7c783c0b05c5d350af99f74fb57", "price_changes": [{"asset_id": "111483763262460809812427616008076634438113457835729033090496924816271676966924", "price": "0.11", "size": "25.99", "side": "BUY", "hash": "fdd56fd71e148f12959972ddfd6e16e766516465", "best_bid": "0.19", "best_ask": "0.97"}, {"asset_id": "77871459748036421242663925334747383360075298582158881700736355568100463986230", "price": "0.89", "size": "25.99", "side": "SELL", "hash": "0e569ec8416ed626d86871dd17033fc24c1745e3", "best_bid": "0.03", "best_ask": "0.81"}], "timestamp": "1769384795075", "event_type": "price_change"}}
{"_local_timestamp": "2026-01-25T23:46:35.153013+00:00", "data": {"market": "0xa3476e8efbbc5557ff9f58978bcf85b7c2bc0c14d2f2c5891f1861a0e95c71c7", "price_changes": [{"asset_id": "77616069079544766632313130435803131534837904050680582581189964299844607679338", "price": "0.11", "size": "20", "side": "BUY", "hash": "d13d64506c2f8654e4a852fc5516ad78f4c6c66a", "best_bid": "0.16", "best_ask": "0.97"}, {"asset_id": "49075166570883369230840079099601560361862864964529664437077360133815011449025", "price": "0.89", "size": "20", "side": "SELL", "hash": "f170bb68b6138f60b8bb6616e397a9e2ebbfebd3", "best_bid": "0.03", "best_ask": "0.84"}], "timestamp": "1769384795075", "event_type": "price_change"}}
{"_local_timestamp": "2026-01-25T23:46:35.219282+00:00", "data": {"market": "0x25025db13d5868308eb2f1f57beaf7cbea76c4014201800853a4c1aaad3046ee", "price_changes": [{"asset_id": "15113128431693879081528076048684622701923990563320934711420493231791911133880", "price": "0.02", "size": "155.46", "side": "BUY", "hash": "dd6dad933bfdf52ee0ae7afecdc09b98609ec34b", "best_bid": "0.03", "best_ask": "0.28"}, {"asset_id": "69171629149106323292749070292707293928031973221371003911300207535275094378436", "price": "0.98", "size": "155.46", "side": "SELL", "hash": "e2b1e57a3c9378195caabcb9434920dd33127fff", "best_bid": "0.72", "best_ask": "0.97"}], "timestamp": "1769384795146", "event_type": "price_change"}}
{"_local_timestamp": "2026-01-25T23:46:35.759851+00:00", "data": {"market": "0x93f28d0ad9d5906fee37296a8a70a57c9e4ed4b3b9aa09029c2d9589ce7ce832", "price_changes": [{"asset_id": "100955895305218895610069502472760899905214942330703669753760270178117749789092", "price": "0.01", "size": "73.6", "side": "BUY", "hash": "445c28c29ea5b126b70217f04894a4c2edad037f", "best_bid": "0.02", "best_ask": "0.81"}, {"asset_id": "72776331054793272806940188908180904666024448478022907801009755847830868970904", "price": "0.99", "size": "73.6", "side": "SELL", "hash": "fb906976f9785b0ff051212d69b1212ebdf1a052", "best_bid": "0.19", "best_ask": "0.98"}], "timestamp": "1769384795688", "event_type": "price_change"}}
{"_local_timestamp": "2026-01-25T23:46:36.149818+00:00", "data": {"market": "0x93f28d0ad9d5906fee37296a8a70a57c9e4ed4b3b9aa09029c2d9589ce7ce832", "price_changes": [{"asset_id": "100955895305218895610069502472760899905214942330703669753760270178117749789092", "price": "0.01", "size": "161.72", "side": "BUY", "hash": "f14a0a1922c81a0b1d59f8cba8fff1644e0c8f59", "best_bid": "0.02", "best_ask": "0.81"}, {"asset_id": "72776331054793272806940188908180904666024448478022907801009755847830868970904", "price": "0.99", "size": "161.72", "side": "SELL", "hash": "b8d3b4bd2dbdccb52f5528af5721938b171abc45", "best_bid": "0.19", "best_ask": "0.98"}], "timestamp": "1769384796017", "event_type": "price_change"}}
{"_local_timestamp": "2026-01-25T23:46:38.057786+00:00", "data": {"market": "0x225e0fdd1dbcf8d4ed569658e9fcdadc106fe4df8f3eebab6de3179594e69cae", "price_changes": [{"asset_id": "100614172146851019022930506261540059414109250163382945560610650412918760163014", "price": "0.002", "size": "262.98", "side": "BUY", "hash": "4c102d715aa93ac7b5a28af516c9b57b34b5f841", "best_bid": "0.022", "best_ask": "0.08"}, {"asset_id": "45764625730845095130147096446415799271154137683585606059451270337639906719390", "price": "0.998", "size": "262.98", "side": "SELL", "hash": "1f37b65e9d5ae3ac38f7974adf81111476417383", "best_bid": "0.92", "best_ask": "0.978"}], "timestamp": "1769384797982", "event_type": "price_change"}}
{"_local_timestamp": "2026-01-25T23:46:38.800059+00:00", "data": {"market": "0x225e0fdd1dbcf8d4ed569658e9fcdadc106fe4df8f3eebab6de3179594e69cae", "price_changes": [{"asset_id": "100614172146851019022930506261540059414109250163382945560610650412918760163014", "price": "0.003", "size": "140.09", "side": "BUY", "hash": "4dd887e94ee85853d5fd2f065e08e5cd58205b72", "best_bid": "0.022", "best_ask": "0.08"}, {"asset_id": "45764625730845095130147096446415799271154137683585606059451270337639906719390", "price": "0.997", "size": "140.09", "side": "SELL", "hash": "ce7e08585d72348f58e0db5131f696a6896e9f79", "best_bid": "0.92", "best_ask": "0.978"}], "timestamp": "1769384798726", "event_type": "price_change"}}
{"_local_timestamp": "2026-01-25T23:47:27.865826+00:00", "data": {"market": "0xa3476e8efbbc5557ff9f58978bcf85b7c2bc0c14d2f2c5891f1861a0e95c71c7", "price_changes": [{"asset_id": "49075166570883369230840079099601560361862864964529664437077360133815011449025", "price": "0.02", "size": "100", "side": "BUY", "hash": "593a09cb816d0e899bcaf91c030ba8464d60ee54", "best_bid": "0.03", "best_ask": "0.84"}, {"asset_id": "77616069079544766632313130435803131534837904050680582581189964299844607679338", "price": "0.98", "size": "100", "side": "SELL", "hash": "b842ff00cfc33c2fa4597e24c4f974e36296f3c4", "best_bid": "0.16", "best_ask": "0.97"}], "timestamp": "1769384847801", "event_type": "price_change"}}
{"_local_timestamp": "2026-01-25T23:47:27.870448+00:00", "data": {"market": "0xf69b405cb72c495b47f14d4581ec5f4fdc32c7c783c0b05c5d350af99f74fb57", "price_changes": [{"asset_id": "77871459748036421242663925334747383360075298582158881700736355568100463986230", "price": "0.02", "size": "95", "side": "BUY", "hash": "a38e750eff7809f879c8b5130c82c1ca678797af", "best_bid": "0.03", "best_ask": "0.81"}, {"asset_id": "111483763262460809812427616008076634438113457835729033090496924816271676966924", "price": "0.98", "size": "95", "side": "SELL", "hash": "e39fe67f61d8c2e316a7033e214c45634af59362", "best_bid": "0.19", "best_ask": "0.97"}], "timestamp": "1769384847801", "event_type": "price_change"}}
{"_local_timestamp": "2026-01-25T23:47:27.879002+00:00", "data": {"market": "0x25025db13d5868308eb2f1f57beaf7cbea76c4014201800853a4c1aaad3046ee", "price_changes": [{"asset_id": "15113128431693879081528076048684622701923990563320934711420493231791911133880", "price": "0.02", "size": "108", "side": "BUY", "hash": "3d2b07c555923b92eb53f6b0e40dd7e27a70b376", "best_bid": "0.03", "best_ask": "0.28"}, {"asset_id": "69171629149106323292749070292707293928031973221371003911300207535275094378436", "price": "0.98", "size": "108", "side": "SELL", "hash": "2d5cb8f275a1c54206ca8f45f855ee707ed4d213", "best_bid": "0.72", "best_ask": "0.97"}], "timestamp": "1769384847801", "event_type": "price_change"}}
{"_local_timestamp": "2026-01-25T23:47:27.879777+00:00", "data": {"market": "0xe0a32dbfe006ba8c5031351f5243c5cd9a58cf3c37b566cc82a9f7d41f8302c7", "price_changes": [{"asset_id": "4885632818167351187788551933410416061445761831692101146500029904141404303906", "price": "0.02", "size": "100", "side": "BUY", "hash": "b19b9a58d401960cc7026a7388278db97d355c2d", "best_bid": "0.03", "best_ask": "0.81"}, {"asset_id": "65815064799788774655435771148232734980061574308316816581700167067698511121921", "price": "0.98", "size": "100", "side": "SELL", "hash": "071da650dca2b39a719a4cf47afe40f29f6f9090", "best_bid": "0.19", "best_ask": "0.97"}], "timestamp": "1769384847801", "event_type": "price_change"}}
{"_local_timestamp": "2026-01-25T23:47:27.880484+00:00", "data": {"market": "0xb9d3c208d8eb2f3403144092d0e55a4ecf7a6493e33890b35140197a63148d14", "price_changes": [{"asset_id": "63581074489545967013426062325864715209547016020665245565255381968385916667995", "price": "0.02", "size": "95", "side": "BUY", "hash": "985ef28fd26c8d0d5246fd08f466b8f5bc0d1b3a", "best_bid": "0.03", "best_ask": "0.81"}, {"asset_id": "70717802646694382009573815278721437797667570104667888155891561185095387198938", "price": "0.98", "size": "95", "side": "SELL", "hash": "b519f81eb0af635974b46a69b499e99ad5b2e6fb", "best_bid": "0.19", "best_ask": "0.97"}], "timestamp": "1769384847801", "event_type": "price_change"}}
{"_local_timestamp": "2026-01-25T23:47:27.881208+00:00", "data": {"market": "0xfe76f366b01cffc5f3c2551ca2fafd3626551f8e67c45e90bcb9980fadefb1d9", "price_changes": [{"asset_id": "113047842163343397942154658230859519377162790695920966272941515248645143857449", "price": "0.02", "size": "100", "side": "BUY", "hash": "f678b3dbd3bed947d305045e79e594a5b8b37713", "best_bid": "0.03", "best_ask": "0.81"}, {"asset_id": "91464103984107757678948958563250156809345102931554507444370450055330522832734", "price": "0.98", "size": "100", "side": "SELL", "hash": "70d47bf334e84f4f691c9ef85edf503d5dcf7d51", "best_bid": "0.19", "best_ask": "0.97"}], "timestamp": "1769384847801", "event_type": "price_change"}}
{"_local_timestamp": "2026-01-25T23:48:57.118284+00:00", "data": {"market": "0x93f28d0ad9d5906fee37296a8a70a57c9e4ed4b3b9aa09029c2d9589ce7ce832", "price_changes": [{"asset_id": "72776331054793272806940188908180904666024448478022907801009755847830868970904", "price": "0.19", "size": "0", "side": "BUY", "hash": "5d397b259586e9dd33b5466990297a23f017acd4", "best_bid": "0.16", "best_ask": "0.98"}, {"asset_id": "100955895305218895610069502472760899905214942330703669753760270178117749789092", "price": "0.81", "size": "0", "side": "SELL", "hash": "1e08ab3fd598f58f480e08eb982bb4d6f6c497d9", "best_bid": "0.02", "best_ask": "0.84"}], "timestamp": "1769384937002", "event_type": "price_change"}}
{"_local_timestamp": "2026-01-25T23:48:57.145432+00:00", "data": {"market": "0x93f28d0ad9d5906fee37296a8a70a57c9e4ed4b3b9aa09029c2d9589ce7ce832", "price_changes": [{"asset_id": "72776331054793272806940188908180904666024448478022907801009755847830868970904", "price": "0.18", "size": "20", "side": "BUY", "hash": "a15665b22eb3ae22bd52f0554230be1ea9f05eb0", "best_bid": "0.18", "best_ask": "0.98"}, {"asset_id": "100955895305218895610069502472760899905214942330703669753760270178117749789092", "price": "0.82", "size": "20", "side": "SELL", "hash": "c0ad92ddc23971253456c31fd1b32f7d22c4a89d", "best_bid": "0.02", "best_ask": "0.82"}], "timestamp": "1769384937040", "event_type": "price_change"}}
{"_local_timestamp": "2026-01-25T23:48:57.262592+00:00", "data": {"market": "0x225e0fdd1dbcf8d4ed569658e9fcdadc106fe4df8f3eebab6de3179594e69cae", "price_changes": [{"asset_id": "45764625730845095130147096446415799271154137683585606059451270337639906719390", "price": "0.131", "size": "0", "side": "BUY", "hash": "1d4eb52a76597fa0436a2212143b541ee3daa174", "best_bid": "0.92", "best_ask": "0.978"}, {"asset_id": "100614172146851019022930506261540059414109250163382945560610650412918760163014", "price": "0.869", "size": "0", "side": "SELL", "hash": "3c5b7ab41aaf45925de686a57156ea9299a1e30d", "best_bid": "0.022", "best_ask": "0.08"}], "timestamp": "1769384937191", "event_type": "price_change"}}
{"_local_timestamp": "2026-01-25T23:48:57.263415+00:00", "data": {"market": "0x25025db13d5868308eb2f1f57beaf7cbea76c4014201800853a4c1aaad3046ee", "price_changes": [{"asset_id": "69171629149106323292749070292707293928031973221371003911300207535275094378436", "price": "0.06", "size": "33", "side": "BUY", "hash": "6ee6c5ccf6e32beda3d969eebf35471fb94603c3", "best_bid": "0.72", "best_ask": "0.97"}, {"asset_id": "15113128431693879081528076048684622701923990563320934711420493231791911133880", "price": "0.94", "size": "33", "side": "SELL", "hash": "d189769dd7db0e7ed68b214c9fefb54c111650ae", "best_bid": "0.03", "best_ask": "0.28"}], "timestamp": "1769384937191", "event_type": "price_change"}}
{"_local_timestamp": "2026-01-25T23:48:57.294611+00:00", "data": {"market": "0x25025db13d5868308eb2f1f57beaf7cbea76c4014201800853a4c1aaad3046ee", "price_changes": [{"asset_id": "69171629149106323292749070292707293928031973221371003911300207535275094378436", "price": "0.14", "size": "20", "side": "BUY", "hash": "93f2c21f41790f7f646486d36de59b20bce0637d", "best_bid": "0.72", "best_ask": "0.97"}, {"asset_id": "15113128431693879081528076048684622701923990563320934711420493231791911133880", "price": "0.86", "size": "20", "side": "SELL", "hash": "40e30a0735dd33fc61dd434b65a4628f1ca32bcb", "best_bid": "0.03", "best_ask": "0.28"}], "timestamp": "1769384937222", "event_type": "price_change"}}
{"_local_timestamp": "2026-01-25T23:48:57.332784+00:00", "data": {"market": "0x225e0fdd1dbcf8d4ed569658e9fcdadc106fe4df8f3eebab6de3179594e69cae", "price_changes": [{"asset_id": "45764625730845095130147096446415799271154137683585606059451270337639906719390", "price": "0.133", "size": "10", "side": "BUY", "hash": "34f5e2edade81c0f9740c0876d69d72f648a9d97", "best_bid": "0.92", "best_ask": "0.978"}, {"asset_id": "100614172146851019022930506261540059414109250163382945560610650412918760163014", "price": "0.867", "size": "10", "side": "SELL", "hash": "a7699746be1d7f012b44aed255d910da36acaafc", "best_bid": "0.022", "best_ask": "0.08"}], "timestamp": "1769384937254", "event_type": "price_change"}}
{"_local_timestamp": "2026-01-25T23:48:57.333691+00:00", "data": {"market": "0x25025db13d5868308eb2f1f57beaf7cbea76c4014201800853a4c1aaad3046ee", "price_changes": [{"asset_id": "69171629149106323292749070292707293928031973221371003911300207535275094378436", "price": "0.13", "size": "10", "side": "BUY", "hash": "98dcf68f5a1560cdaed28b2c848463f6f735f5ab", "best_bid": "0.72", "best_ask": "0.97"}, {"asset_id": "15113128431693879081528076048684622701923990563320934711420493231791911133880", "price": "0.87", "size": "10", "side": "SELL", "hash": "1872c4a09adf6bf5a25d67555e6476534d5f9f47", "best_bid": "0.03", "best_ask": "0.28"}], "timestamp": "1769384937254", "event_type": "price_change"}}
{"_local_timestamp": "2026-01-25T23:48:57.504372+00:00", "data": {"market": "0x25025db13d5868308eb2f1f57beaf7cbea76c4014201800853a4c1aaad3046ee", "price_changes": [{"asset_id": "69171629149106323292749070292707293928031973221371003911300207535275094378436", "price": "0.13", "size": "40", "side": "BUY", "hash": "0a5721ef43ff6a9b78d2102927a025351f485ef7", "best_bid": "0.72", "best_ask": "0.97"}, {"asset_id": "15113128431693879081528076048684622701923990563320934711420493231791911133880", "price": "0.87", "size": "40", "side": "SELL", "hash": "030409d3751916e5f1e4f3ebdaed95dd6bda2a2b", "best_bid": "0.03", "best_ask": "0.28"}], "timestamp": "1769384937432", "event_type": "price_change"}}
{"_local_timestamp": "2026-01-25T23:48:58.319525+00:00", "data": {"market": "0x225e0fdd1dbcf8d4ed569658e9fcdadc106fe4df8f3eebab6de3179594e69cae", "price_changes": [{"asset_id": "45764625730845095130147096446415799271154137683585606059451270337639906719390", "price": "0.132", "size": "0", "side": "BUY", "hash": "2a60ec33ef445599e9f118215317c48cc15a2816", "best_bid": "0.92", "best_ask": "0.978"}, {"asset_id": "100614172146851019022930506261540059414109250163382945560610650412918760163014", "price": "0.868", "size": "0", "side": "SELL", "hash": "7ac8a2f385b36e8c2687821af6b16a801863acee", "best_bid": "0.022", "best_ask": "0.08"}], "timestamp": "1769384938253", "event_type": "price_change"}}
{"_local_timestamp": "2026-01-25T23:48:58.363695+00:00", "data": {"market": "0x225e0fdd1dbcf8d4ed569658e9fcdadc106fe4df8f3eebab6de3179594e69cae", "price_changes": [{"asset_id": "45764625730845095130147096446415799271154137683585606059451270337639906719390", "price": "0.134", "size": "20", "side": "BUY", "hash": "5598417e23b4274cca5f1513d0dc395b6033844f", "best_bid": "0.92", "best_ask": "0.978"}, {"asset_id": "100614172146851019022930506261540059414109250163382945560610650412918760163014", "price": "0.866", "size": "20", "side": "SELL", "hash": "c4e1b528ea1968d5b6998fd4c48982480e8f0153", "best_bid": "0.022", "best_ask": "0.08"}], "timestamp": "1769384938286", "event_type": "price_change"}}
{"_local_timestamp": "2026-01-25T23:50:36.193297+00:00", "data": {"market": "0xe0a32dbfe006ba8c5031351f5243c5cd9a58cf3c37b566cc82a9f7d41f8302c7", "price_changes": [{"asset_id": "65815064799788774655435771148232734980061574308316816581700167067698511121921", "price": "0.19", "size": "0", "side": "BUY", "hash": "210aeb30227c2f30b3daeb41b5c61d8d309e09dc", "best_bid": "0.14", "best_ask": "0.97"}, {"asset_id": "4885632818167351187788551933410416061445761831692101146500029904141404303906", "price": "0.81", "size": "0", "side": "SELL", "hash": "16b60e33304adab24cb37be60141b383f6b302b8", "best_bid": "0.03", "best_ask": "0.86"}], "timestamp": "1769385036000", "event_type": "price_change"}}
{"_local_timestamp": "2026-01-25T23:50:36.216022+00:00", "data": {"market": "0xe0a32dbfe006ba8c5031351f5243c5cd9a58cf3c37b566cc82a9f7d41f8302c7", "price_changes": [{"asset_id": "65815064799788774655435771148232734980061574308316816581700167067698511121921", "price": "0.16", "size": "20", "side": "BUY", "hash": "c25dd591c080cf6fa7206f3a56f9a34bb98d68ef", "best_bid": "0.16", "best_ask": "0.97"}, {"asset_id": "4885632818167351187788551933410416061445761831692101146500029904141404303906", "price": "0.84", "size": "20", "side": "SELL", "hash": "6df988a18d561cfc5f98bab7f85d6ceb372ccb8f", "best_bid": "0.03", "best_ask": "0.84"}], "timestamp": "1769385036025", "event_type": "price_change"}}
{"_local_timestamp": "2026-01-25T23:50:44.122903+00:00", "data": {"market": "0xf69b405cb72c495b47f14d4581ec5f4fdc32c7c783c0b05c5d350af99f74fb57", "price_changes": [{"asset_id": "111483763262460809812427616008076634438113457835729033090496924816271676966924", "price": "0.19", "size": "0", "side": "BUY", "hash": "7c443de1c247f3cf7bcedde54441f8d2953bb5ff", "best_bid": "0.15", "best_ask": "0.97"}, {"asset_id": "77871459748036421242663925334747383360075298582158881700736355568100463986230", "price": "0.81", "size": "0", "side": "SELL", "hash": "afd791ca408eb39d10e0214aacfd67dc5b5aa09d", "best_bid": "0.03", "best_ask": "0.85"}], "timestamp": "1769385044001", "event_type": "price_change"}}
{"_local_timestamp": "2026-01-25T23:50:44.175953+00:00", "data": {"market": "0xf69b405cb72c495b47f14d4581ec5f4fdc32c7c783c0b05c5d350af99f74fb57", "price_changes": [{"asset_id": "111483763262460809812427616008076634438113457835729033090496924816271676966924", "price": "0.18", "size": "20", "side": "BUY", "hash": "6c2d8fdde1becd9e71cd0eff056bf052a27afbdb", "best_bid": "0.18", "best_ask": "0.97"}, {"asset_id": "77871459748036421242663925334747383360075298582158881700736355568100463986230", "price": "0.82", "size": "20", "side": "SELL", "hash": "ebac9082e33faac289fb34b2e96224b01a980d13", "best_bid": "0.03", "best_ask": "0.82"}], "timestamp": "1769385044035", "event_type": "price_change"}}
{"_local_timestamp": "2026-01-25T23:50:57.731028+00:00", "data": {"market": "0x25025db13d5868308eb2f1f57beaf7cbea76c4014201800853a4c1aaad3046ee", "price_changes": [{"asset_id": "69171629149106323292749070292707293928031973221371003911300207535275094378436", "price": "0.11", "size": "0", "side": "BUY", "hash": "388999a9278f090bfe0ade72b5f79b2ea222f228", "best_bid": "0.72", "best_ask": "0.97"}, {"asset_id": "15113128431693879081528076048684622701923990563320934711420493231791911133880", "price": "0.89", "size": "0", "side": "SELL", "hash": "3e6e1318add3a8257302860a81d3102e83cbc184", "best_bid": "0.03", "best_ask": "0.28"}], "timestamp": "1769385057663", "event_type": "price_change"}}
{"_local_timestamp": "2026-01-25T23:50:57.779152+00:00", "data": {"market": "0x25025db13d5868308eb2f1f57beaf7cbea76c4014201800853a4c1aaad3046ee", "price_changes": [{"asset_id": "69171629149106323292749070292707293928031973221371003911300207535275094378436", "price": "0.17", "size": "11", "side": "BUY", "hash": "6dc01d59c166bf0017567f561b53c3e376796813", "best_bid": "0.72", "best_ask": "0.97"}, {"asset_id": "15113128431693879081528076048684622701923990563320934711420493231791911133880", "price": "0.83", "size": "11", "side": "SELL", "hash": "858cc56ba7388a6d248cb242cb37ee2f563c5602", "best_bid": "0.03", "best_ask": "0.28"}], "timestamp": "1769385057708", "event_type": "price_change"}}
{"_local_timestamp": "2026-01-25T23:51:13.493161+00:00", "data": {"market": "0x25025db13d5868308eb2f1f57beaf7cbea76c4014201800853a4c1aaad3046ee", "price_changes": [{"asset_id": "69171629149106323292749070292707293928031973221371003911300207535275094378436", "price": "0.16", "size": "0", "side": "BUY", "hash": "167410a365c42160f4bdc4b449e598132c57fcc9", "best_bid": "0.72", "best_ask": "0.97"}, {"asset_id": "15113128431693879081528076048684622701923990563320934711420493231791911133880", "price": "0.84", "size": "0", "side": "SELL", "hash": "e0e30c596de1c29faf0c707abce58d16bcede5d3", "best_bid": "0.03", "best_ask": "0.28"}], "timestamp": "1769385073419", "event_type": "price_change"}}
{"_local_timestamp": "2026-01-25T23:51:18.070554+00:00", "data": {"market": "0xfe76f366b01cffc5f3c2551ca2fafd3626551f8e67c45e90bcb9980fadefb1d9", "price_changes": [{"asset_id": "91464103984107757678948958563250156809345102931554507444370450055330522832734", "price": "0.19", "size": "0", "side": "BUY", "hash": "4a277159091fe7ecd01d72467dc2d5c5221afcad", "best_bid": "0.12", "best_ask": "0.97"}, {"asset_id": "113047842163343397942154658230859519377162790695920966272941515248645143857449", "price": "0.81", "size": "0", "side": "SELL", "hash": "5a695dd98cc62f907ab7fc095d55b04fb66a03ec", "best_bid": "0.03", "best_ask": "0.88"}], "timestamp": "1769385078000", "event_type": "price_change"}}
{"_local_timestamp": "2026-01-25T23:51:20.082443+00:00", "data": {"market": "0xb9d3c208d8eb2f3403144092d0e55a4ecf7a6493e33890b35140197a63148d14", "price_changes": [{"asset_id": "70717802646694382009573815278721437797667570104667888155891561185095387198938", "price": "0.19", "size": "0", "side": "BUY", "hash": "fc6e7b807e05e4414708e2941cf9fcdeb3f11019", "best_bid": "0.12", "best_ask": "0.97"}, {"asset_id": "63581074489545967013426062325864715209547016020665245565255381968385916667995", "price": "0.81", "size": "0", "side": "SELL", "hash": "64f62cda892d44ee51e4a780a26c9904eec36b44", "best_bid": "0.03", "best_ask": "0.88"}], "timestamp": "1769385080001", "event_type": "price_change"}}
{"_local_timestamp": "2026-01-25T23:51:20.124315+00:00", "data": {"market": "0xb9d3c208d8eb2f3403144092d0e55a4ecf7a6493e33890b35140197a63148d14", "price_changes": [{"asset_id": "70717802646694382009573815278721437797667570104667888155891561185095387198938", "price": "0.15", "size": "20", "side": "BUY", "hash": "2bc772e2c492921d0a26b4a2f523ec9b5262b0f7", "best_bid": "0.15", "best_ask": "0.97"}, {"asset_id": "63581074489545967013426062325864715209547016020665245565255381968385916667995", "price": "0.85", "size": "20", "side": "SELL", "hash": "3c1354e2e6915a8d3d2087621f703d1d6c69743f", "best_bid": "0.03", "best_ask": "0.85"}], "timestamp": "1769385080029", "event_type": "price_change"}}
{"_local_timestamp": "2026-01-25T23:51:20.130771+00:00", "data": {"market": "0xfe76f366b01cffc5f3c2551ca2fafd3626551f8e67c45e90bcb9980fadefb1d9", "price_changes": [{"asset_id": "91464103984107757678948958563250156809345102931554507444370450055330522832734", "price": "0.17", "size": "20", "side": "BUY", "hash": "0865167c58022905dad9be010628effabf679301", "best_bid": "0.17", "best_ask": "0.97"}, {"asset_id": "113047842163343397942154658230859519377162790695920966272941515248645143857449", "price": "0.83", "size": "20", "side": "SELL", "hash": "12a762948879dbaeeddcfd66f440a1659606f7bb", "best_bid": "0.03", "best_ask": "0.83"}], "timestamp": "1769385080063", "event_type": "price_change"}}
