{"_local_timestamp": "2026-01-25T23:40:31.185453+00:00", "data": [{"market": "0x754113d4aefc74db7c1266dc5f03e89e3f597deda15b19c19b3ca16cc85b8c33", "asset_id": "16018186278713893766129270377649855044679233002578361062022208432086696077104", "timestamp": "1769384429806", "hash": "f65c66cf921a50780206add228741de3cd0260a7", "bids": [], "asks": [{"price": "0.999", "size": "1104969.93"}, {"price": "0.998", "size": "61250"}, {"price": "0.997", "size": "1405.01"}, {"price": "0.996", "size": "21000"}, {"price": "0.995", "size": "8.89"}, {"price": "0.994", "size": "200"}, {"price": "0.99", "size": "1000"}, {"price": "0.989", "size": "7.83"}, {"price": "0.98", "size": "4000"}, {"price": "0.979", "size": "30400"}, {"price": "0.978", "size": "250"}, {"price": "0.977", "size": "8.41"}, {"price": "0.95", "size": "30"}, {"price": "0.949", "size": "39"}, {"price": "0.948", "size": "10.14"}, {"price": "0.9", "size": "560"}, {"price": "0.85", "size": "551.66"}, {"price": "0.849", "size": "7.4"}, {"price": "0.8", "size": "460"}, {"price": "0.777", "size": "295"}, {"price": "0.75", "size": "112"}, {"price": "0.73", "size": "50"}, {"price": "0.7", "size": "86.66"}, {"price": "0.699", "size": "6"}, {"price": "0.659", "size": "5"}, {"price": "0.65", "size": "68.57"}, {"price": "0.6", "size": "175"}, {"price": "0.477", "size": "316"}, {"price": "0.277", "size": "170"}, {"price": "0.276", "size": "552"}, {"price": "0.177", "size": "207"}, {"price": "0.176", "size": "121"}, {"price": "0.077", "size": "254"}, {"price": "0.039", "size": "25"}, {"price": "0.038", "size": "15"}, {"price": "0.037", "size": "100"}, {"price": "0.016", "size": "17"}, {"price": "0.015", "size": "13"}, {"price": "0.008", "size": "22"}, {"price": "0.005", "size": "1231.76"}, {"price": "0.003", "size": "1794.67"}], "event_type": "book", "last_trade_price": "0.003"}, {"market": "0x83db787ed2cb00d225178e66bc6ae4d22e8029f19390d2b78ded5aed978eead6", "asset_id": "81906419701908530974011339985097627770048267181648886108185004759027261509242", "timestamp": "1769384429806", "hash": "8aac66317e36c6f3497b5ff60c778776c78beaa8", "bids": [{"price": "0.001", "size": "521989.99"}, {"price": "0.002", "size": "62658.44"}, {"price": "0.003", "size": "555.76"}, {"price": "0.004", "size": "191.42"}, {"price": "0.005", "size": "2249.99"}, {"price": "0.006", "size": "2568.65"}, {"price": "0.007", "size": "19.79"}, {"price": "0.008", "size": "24.16"}], "asks": [{"price": "0.999", "size": "11015924.66"}, {"price": "0.998", "size": "61250"}, {"price": "0.997", "size": "1166"}, {"price": "0.996", "size": "7005.78"}, {"price": "0.994", "size": "83"}, {"price": "0.99", "size": "1060"}, {"price": "0.989", "size": "10.93"}, {"price": "0.98", "size": "1000"}, {"price": "0.97", "size": "1000"}, {"price": "0.969", "size": "6400"}, {"price": "0.95", "size": "530"}, {"price": "0.949", "size": "2039"}, {"price": "0.948", "size": "9.86"}, {"price": "0.9", "size": "735"}, {"price": "0.85", "size": "551.66"}, {"price": "0.82", "size": "5"}, {"price": "0.8", "size": "585"}, {"price": "0.775", "size": "6200"}, {"price": "0.758", "size": "2000"}, {"price": "0.757", "size": "250"}, {"price": "0.75", "size": "112"}, {"price": "0.73", "size": "50"}, {"price": "0.7", "size": "86.66"}, {"price": "0.66", "size": "50"}, {"price": "0.65", "size": "68.57"}, {"price": "0.6", "size": "50"}, {"price": "0.59", "size": "110"}, {"price": "0.31", "size": "5"}, {"price": "0.3", "size": "188.35"}, {"price": "0.27", "size": "275"}, {"price": "0.19", "size": "86.09"}, {"price": "0.16", "size": "96"}, {"price": "0.078", "size": "500"}, {"price": "0.059", "size": "400"}, {"price": "0.05", "size": "89.12"}, {"price": "0.049", "size": "300"}, {"price": "0.02", "size": "10394.66"}, {"price": "0.019", "size": "1100"}, {"price": "0.018", "size": "100"}, {"price": "0.017", "size": "500"}, {"price": "0.016", "size": "6.25"}, {"price": "0.015", "size": "100"}, {"price": "0.014", "size": "100"}, {"price": "0.013", "size": "100"}, {"price": "0.012", "size": "100"}, {"price": "0.011", "size": "20"}, {"price": "0.01", "size": "22.97"}], "event_type": "book", "last_trade_price": "0.990"}, {"market": "0x754113d4aefc74db7c1266dc5f03e89e3f597deda15b19c19b3ca16cc85b8c33", "asset_id": "48827723684529991552849237252156781311984893775886188249280006578488168779709", "timestamp": "1769384429806", "hash": "7da49bcefd897fcf82acbd3af2a07d7b48bbe569", "bids": [{"price": "0.001", "size": "1104969.93"}, {"price": "0.002", "size": "61250"}, {"price": "0.003", "size": "1405.01"}, {"price": "0.004", "size": "21000"}, {"price": "0.005", "size": "8.89"}, {"price": "0.006", "size": "200"}, {"price": "0.01", "size": "1000"}, {"price": "0.011", "size": "7.83"}, {"price": "0.02", "size": "4000"}, {"price": "0.021", "size": "30400"}, {"price": "0.022", "size": "250"}, {"price": "0.023", "size": "8.41"}, {"price": "0.05", "size": "30"}, {"price": "0.051", "size": "39"}, {"price": "0.052", "size": "10.14"}, {"price": "0.1", "size": "560"}, {"price": "0.15", "size": "551.66"}, {"price": "0.151", "size": "7.4"}, {"price": "0.2", "size": "460"}, {"price": "0.223", "size": "295"}, {"price": "0.25", "size": "112"}, {"price": "0.27", "size": "50"}, {"price": "0.3", "size": "86.66"}, {"price": "0.301", "size": "6"}, {"price": "0.341", "size": "5"}, {"price": "0.35", "size": "68.57"}, {"price": "0.4", "size": "175"}, {"price": "0.523", "size": "316"}, {"price": "0.723", "size": "170"}, {"price": "0.724", "size": "552"}, {"price": "0.823", "size": "207"}, {"price": "0.824", "size": "121"}, {"price": "0.923", "size": "254"}, {"price": "0.961", "size": "25"}, {"price": "0.962", "size": "15"}, {"price": "0.963", "size": "100"}, {"price": "0.984", "size": "17"}, {"price": "0.985", "size": "13"}, {"price": "0.992", "size": "22"}, {"price": "0.995", "size": "1231.76"}, {"price": "0.997", "size": "1794.67"}], "asks": [], "event_type": "book", "last_trade_price": "0.003"}, {"market": "0xbfcc34365517ac4978e76ecd8287e37fd92e68b22a3db9b31129c5c37669c293", "asset_id": "95417221270011105499568468828531867453865533932484364685389046548264041887861", "timestamp": "1769384429805", "hash": "7443161c8efa3e1bd87bf66a096a3a6332565c7d", "bids": [{"price": "0.001", "size": "6286.99"}, {"price": "0.002", "size": "1150"}, {"price": "0.003", "size": "76.46"}], "asks": [{"price": "0.999", "size": "11008605.26"}, {"price": "0.998", "size": "61250"}, {"price": "0.997", "size": "1171.05"}, {"price": "0.996", "size": "7000"}, {"price": "0.995", "size": "8.96"}, {"price": "0.994", "size": "83"}, {"price": "0.99", "size": "1000"}, {"price": "0.989", "size": "7.24"}, {"price": "0.98", "size": "1400"}, {"price": "0.979", "size": "250"}, {"price": "0.978", "size": "9.17"}, {"price": "0.95", "size": "30"}, {"price": "0.949", "size": "39"}, {"price": "0.948", "size": "10.19"}, {"price": "0.9", "size": "560"}, {"price": "0.85", "size": "551.66"}, {"price": "0.849", "size": "7.37"}, {"price": "0.8", "size": "410"}, {"price": "0.772", "size": "6200"}, {"price": "0.75", "size": "112"}, {"price": "0.73", "size": "50"}, {"price": "0.7", "size": "86.66"}, {"price": "0.65", "size": "68.57"}, {"price": "0.6", "size": "175"}, {"price": "0.599", "size": "5"}, {"price": "0.33", "size": "50"}, {"price": "0.075", "size": "500"}, {"price": "0.074", "size": "20"}, {"price": "0.049", "size": "300"}, {"price": "0.048", "size": "25"}, {"price": "0.041", "size": "24.99"}, {"price": "0.039", "size": "25"}, {"price": "0.038", "size": "15"}, {"price": "0.031", "size": "92.74"}, {"price": "0.03", "size": "100"}, {"price": "0.029", "size": "20"}, {"price": "0.024", "size": "74.8"}, {"price": "0.02", "size": "10250"}, {"price": "0.018", "size": "84.85"}, {"price": "0.013", "size": "1000"}, {"price": "0.011", "size": "22"}, {"price": "0.01", "size": "100"}, {"price": "0.008", "size": "9254.23"}, {"price": "0.007", "size": "876.1"}, {"price": "0.006", "size": "124.25"}], "event_type": "book", "last_trade_price": "0.006"}, {"market": "0x83db787ed2cb00d225178e66bc6ae4d22e8029f19390d2b78ded5aed978eead6", "asset_id": "113401754986342384261044700457165882158632153698445535217371023842472815025478", "timestamp": "1769384429806", "hash": "19398e66cc659e9372be3b6a645df7d5f983f7e4", "bids": [{"price": "0.001", "size": "11015924.66"}, {"price": "0.002", "size": "61250"}, {"price": "0.003", "size": "1166"}, {"price": "0.004", "size": "7005.78"}, {"price": "0.006", "size": "83"}, {"price": "0.01", "size": "1060"}, {"price": "0.011", "size": "10.93"}, {"price": "0.02", "size": "1000"}, {"price": "0.03", "size": "1000"}, {"price": "0.031", "size": "6400"}, {"price": "0.05", "size": "530"}, {"price": "0.051", "size": "2039"}, {"price": "0.052", "size": "9.86"}, {"price": "0.1", "size": "735"}, {"price": "0.15", "size": "551.66"}, {"price": "0.18", "size": "5"}, {"price": "0.2", "size": "585"}, {"price": "0.225", "size": "6200"}, {"price": "0.242", "size": "2000"}, {"price": "0.243", "size": "250"}, {"price": "0.25", "size": "112"}, {"price": "0.27", "size": "50"}, {"price": "0.3", "size": "86.66"}, {"price": "0.34", "size": "50"}, {"price": "0.35", "size": "68.57"}, {"price": "0.4", "size": "50"}, {"price": "0.41", "size": "110"}, {"price": "0.69", "size": "5"}, {"price": "0.7", "size": "188.35"}, {"price": "0.73", "size": "275"}, {"price": "0.81", "size": "86.09"}, {"price": "0.84", "size": "96"}, {"price": "0.922", "size": "500"}, {"price": "0.941", "size": "400"}, {"price": "0.95", "size": "89.12"}, {"price": "0.951", "size": "300"}, {"price": "0.98", "size": "10394.66"}, {"price": "0.981", "size": "1100"}, {"price": "0.982", "size": "100"}, {"price": "0.983", "size": "500"}, {"price": "0.984", "size": "6.25"}, {"price": "0.985", "size": "100"}, {"price": "0.986", "size": "100"}, {"price": "0.987", "size": "100"}, {"price": "0.988", "size": "100"}, {"price": "0.989", "size": "20"}, {"price": "0.99", "size": "22.97"}], "asks": [{"price": "0.999", "size": "521989.99"}, {"price": "0.998", "size": "62658.44"}, {"price": "0.997", "size": "555.76"}, {"price": "0.996", "size": "191.42"}, {"price": "0.995", "size": "2249.99"}, {"price": "0.994", "size": "2568.65"}, {"price": "0.993", "size": "19.79"}, {"price": "0.992", "size": "24.16"}], "event_type": "book", "last_trade_price": "0.990"}, {"market": "0xbfcc34365517ac4978e76ecd8287e37fd92e68b22a3db9b31129c5c37669c293", "asset_id": "101322769768415942646735830228475566436146317671120615766292718518675772773223", "timestamp": "1769384429805", "hash": "ae6fbadc9e7d366937b92da2a8d9421cea5c46c9", "bids": [{"price": "0.001", "size": "11008605.26"}, {"price": "0.002", "size": "61250"}, {"price": "0.003", "size": "1171.05"}, {"price": "0.004", "size": "7000"}, {"price": "0.005", "size": "8.96"}, {"price": "0.006", "size": "83"}, {"price": "0.01", "size": "1000"}, {"price": "0.011", "size": "7.24"}, {"price": "0.02", "size": "1400"}, {"price": "0.021", "size": "250"}, {"price": "0.022", "size": "9.17"}, {"price": "0.05", "size": "30"}, {"price": "0.051", "size": "39"}, {"price": "0.052", "size": "10.19"}, {"price": "0.1", "size": "560"}, {"price": "0.15", "size": "551.66"}, {"price": "0.151", "size": "7.37"}, {"price": "0.2", "size": "410"}, {"price": "0.228", "size": "6200"}, {"price": "0.25", "size": "112"}, {"price": "0.27", "size": "50"}, {"price": "0.3", "size": "86.66"}, {"price": "0.35", "size": "68.57"}, {"price": "0.4", "size": "175"}, {"price": "0.401", "size": "5"}, {"price": "0.67", "size": "50"}, {"price": "0.925", "size": "500"}, {"price": "0.926", "size": "20"}, {"price": "0.951", "size": "300"}, {"price": "0.952", "size": "25"}, {"price": "0.959", "size": "24.99"}, {"price": "0.961", "size": "25"}, {"price": "0.962", "size": "15"}, {"price": "0.969", "size": "92.74"}, {"price": "0.97", "size": "100"}, {"price": "0.971", "size": "20"}, {"price": "0.976", "size": "74.8"}, {"price": "0.98", "size": "10250"}, {"price": "0.982", "size": "84.85"}, {"price": "0.987", "size": "1000"}, {"price": "0.989", "size": "22"}, {"price": "0.99", "size": "100"}, {"price": "0.992", "size": "9254.23"}, {"price": "0.993", "size": "876.1"}, {"price": "0.994", "size": "124.25"}], "asks": [{"price": "0.999", "size": "6286.99"}, {"price": "0.998", "size": "1150"}, {"price": "0.997", "size": "76.46"}], "event_type": "book", "last_trade_price": "0.006"}]}
{"_local_timestamp": "2026-01-25T23:40:31.932840+00:00", "data": {"market": "0x754113d4aefc74db7c1266dc5f03e89e3f597deda15b19c19b3ca16cc85b8c33", "price_changes": [{"asset_id": "48827723684529991552849237252156781311984893775886188249280006578488168779709", "price": "0.995", "size": "2138.57", "side": "BUY", "hash": "2e9a6e6c03521fa795050d4cc8e3c5fcd2f0a156", "best_bid": "0.997", "best_ask": "1"}, {"asset_id": "16018186278713893766129270377649855044679233002578361062022208432086696077104", "price": "0.005", "size": "2138.57", "side": "SELL", "hash": "0a1b61e085072f889d17ebf86f9d10f57bc8f404", "best_bid": "0", "best_ask": "0.003"}], "timestamp": "1769384431863", "event_type": "price_change"}}
{"_local_timestamp": "2026-01-25T23:40:32.882508+00:00", "data": {"market": "0xbfcc34365517ac4978e76ecd8287e37fd92e68b22a3db9b31129c5c37669c293", "price_changes": [{"asset_id": "95417221270011105499568468828531867453865533932484364685389046548264041887861", "price": "0.004", "size": "98", "side": "BUY", "hash": "ea7abe01ce41a2719dc0de245a9368772ca77eff", "best_bid": "0.004", "best_ask": "0.006"}, {"asset_id": "101322769768415942646735830228475566436146317671120615766292718518675772773223", "price": "0.996", "size": "98", "side": "SELL", "hash": "41d725a02f4a6cefcecdc7dee71e5382343a81d0", "best_bid": "0.994", "best_ask": "0.996"}], "timestamp": "1769384432813", "event_type": "price_change"}}
{"_local_timestamp": "2026-01-25T23:40:32.902651+00:00", "data": {"market": "0x83db787ed2cb00d225178e66bc6ae4d22e8029f19390d2b78ded5aed978eead6", "price_changes": [{"asset_id": "81906419701908530974011339985097627770048267181648886108185004759027261509242", "price": "0.002", "size": "62582.44", "side": "BUY", "hash": "026a3d4239b49de7c0388a68a71b7f2535a1623b", "best_bid": "0.008", "best_ask": "0.01"}, {"asset_id": "113401754986342384261044700457165882158632153698445535217371023842472815025478", "price": "0.998", "size": "62582.44", "side": "SELL", "hash": "d900817e935ff1569067cd8e4ca12c9d082cfd20", "best_bid": "0.99", "best_ask": "0.992"}], "timestamp": "1769384432837", "event_type": "price_change"}}
{"_local_timestamp": "2026-01-25T23:40:32.913868+00:00", "data": {"market": "0x754113d4aefc74db7c1266dc5f03e89e3f597deda15b19c19b3ca16cc85b8c33", "price_changes": [{"asset_id": "48827723684529991552849237252156781311984893775886188249280006578488168779709", "price": "0.992", "size": "0", "side": "BUY", "hash": "378346573157d6f8e860c865666d38ce5370e066", "best_bid": "0.997", "best_ask": "1"}, {"asset_id": "16018186278713893766129270377649855044679233002578361062022208432086696077104", "price": "0.008", "size": "0", "side": "SELL", "hash": "e2eb9b38487a186425401bfbefceb1b1917bd419", "best_bid": "0", "best_ask": "0.003"}], "timestamp": "1769384432839", "event_type": "price_change"}}
{"_local_timestamp": "2026-01-25T23:40:33.032546+00:00", "data": {"market": "0x83db787ed2cb00d225178e66bc6ae4d22e8029f19390d2b78ded5aed978eead6", "price_changes": [{"asset_id": "81906419701908530974011339985097627770048267181648886108185004759027261509242", "price": "0.003", "size": "653.76", "side": "BUY", "hash": "5304f6a7f05706e18bbcc21d02ac3b78bfdb7201", "best_bid": "0.008", "best_ask": "0.01"}, {"asset_id": "113401754986342384261044700457165882158632153698445535217371023842472815025478", "price": "0.997", "size": "653.76", "side": "SELL", "hash": "3040660bbcaeb931aa219b0c2d9eae9586fc378d", "best_bid": "0.99", "best_ask": "0.992"}], "timestamp": "1769384432961", "event_type": "price_change"}}
{"_local_timestamp": "2026-01-25T23:40:33.037619+00:00", "data": {"market": "0x754113d4aefc74db7c1266dc5f03e89e3f597deda15b19c19b3ca16cc85b8c33", "price_changes": [{"asset_id": "48827723684529991552849237252156781311984893775886188249280006578488168779709", "price": "0.993", "size": "22", "side": "BUY", "hash": "89cf32450bd2c9cb229a0b9a4050c22d68fee91d", "best_bid": "0.997", "best_ask": "1"}, {"asset_id": "16018186278713893766129270377649855044679233002578361062022208432086696077104", "price": "0.007", "size": "22", "side": "SELL", "hash": "d0c65f4ddca97ab77192345a2cf43327d5a272c2", "best_bid": "0", "best_ask": "0.003"}], "timestamp": "1769384432964", "event_type": "price_change"}}
{"_local_timestamp": "2026-01-25T23:40:33.283749+00:00", "data": {"market": "0xbfcc34365517ac4978e76ecd8287e37fd92e68b22a3db9b31129c5c37669c293", "price_changes": [{"asset_id": "95417221270011105499568468828531867453865533932484364685389046548264041887861", "price": "0.011", "size": "2668.88", "side": "SELL", "hash": "61c41b028e15912ef2e5a127faf9d67f24fcb483", "best_bid": "0.004", "best_ask": "0.006"}, {"asset_id": "101322769768415942646735830228475566436146317671120615766292718518675772773223", "price": "0.989", "size": "2668.88", "side": "BUY", "hash": "811da26330eaa1600a5b3a5e69c63f820f0edb1d", "best_bid": "0.994", "best_ask": "0.996"}], "timestamp": "1769384433210", "event_type": "price_change"}}
{"_local_timestamp": "2026-01-25T23:40:33.673879+00:00", "data": {"market": "0x83db787ed2cb00d225178e66bc6ae4d22e8029f19390d2b78ded5aed978eead6", "price_changes": [{"asset_id": "113401754986342384261044700457165882158632153698445535217371023842472815025478", "price": "0.986", "size": "1006.81", "side": "BUY", "hash": "ad0c8b83a06567ba643601baac7957367549a01c", "best_bid": "0.99", "best_ask": "0.992"}, {"asset_id": "81906419701908530974011339985097627770048267181648886108185004759027261509242", "price": "0.014", "size": "1006.81", "side": "SELL", "hash": "27779889aff610e21fd3bd355049966171e955d3", "best_bid": "0.008", "best_ask": "0.01"}], "timestamp": "1769384433608", "event_type": "price_change"}}
{"_local_timestamp": "2026-01-25T23:40:34.094088+00:00", "data": {"market": "0x83db787ed2cb00d225178e66bc6ae4d22e8029f19390d2b78ded5aed978eead6", "price_changes": [{"asset_id": "113401754986342384261044700457165882158632153698445535217371023842472815025478", "price": "0.991", "size": "946.66", "side": "SELL", "hash": "969399c8882950c89d53cfba22bbcdd0954b082e", "best_bid": "0.99", "best_ask": "0.991"}, {"asset_id": "81906419701908530974011339985097627770048267181648886108185004759027261509242", "price": "0.009", "size": "946.66", "side": "BUY", "hash": "e7037260288536e30adb3262599ccc9eb6c192ac", "best_bid": "0.009", "best_ask": "0.01"}], "timestamp": "1769384434004", "event_type": "price_change"}}
{"_local_timestamp": "2026-01-25T23:40:34.530869+00:00", "data": {"market": "0x754113d4aefc74db7c1266dc5f03e89e3f597deda15b19c19b3ca16cc85b8c33", "price_changes": [{"asset_id": "48827723684529991552849237252156781311984893775886188249280006578488168779709", "price": "0.995", "size": "1231.76", "side": "BUY", "hash": "49f7359e6d15b13a3dfdc3e2ac55961530a54f5d", "best_bid": "0.997", "best_ask": "1"}, {"asset_id": "16018186278713893766129270377649855044679233002578361062022208432086696077104", "price": "0.005", "size": "1231.76", "side": "SELL", "hash": "89c8ba18f17d12f780c0e62da87d2e2728d5317a", "best_bid": "0", "best_ask": "0.003"}], "timestamp": "1769384434457", "event_type": "price_change"}}
{"_local_timestamp": "2026-01-25T23:40:34.534041+00:00", "data": {"market": "0xbfcc34365517ac4978e76ecd8287e37fd92e68b22a3db9b31129c5c37669c293", "price_changes": [{"asset_id": "95417221270011105499568468828531867453865533932484364685389046548264041887861", "price": "0.011", "size": "22", "side": "SELL", "hash": "e15a8d223a7088107a87edb3cc6991930eb81727", "best_bid": "0.003", "best_ask": "0.006"}, {"asset_id": "101322769768415942646735830228475566436146317671120615766292718518675772773223", "price": "0.989", "size": "22", "side": "BUY", "hash": "da5e46febd36fd8de916ece1d956e5fa486f5385", "best_bid": "0.994", "best_ask": "0.997"}], "timestamp": "1769384434457", "event_type": "price_change"}}
{"_local_timestamp": "2026-01-25T23:40:34.536937+00:00", "data": {"market": "0xbfcc34365517ac4978e76ecd8287e37fd92e68b22a3db9b31129c5c37669c293", "price_changes": [{"asset_id": "95417221270011105499568468828531867453865533932484364685389046548264041887861", "price": "0.004", "size": "0", "side": "BUY", "hash": "e15a8d223a7088107a87edb3cc6991930eb81727", "best_bid": "0.003", "best_ask": "0.006"}, {"asset_id": "101322769768415942646735830228475566436146317671120615766292718518675772773223", "price": "0.996", "size": "0", "side": "SELL", "hash": "da5e46febd36fd8de916ece1d956e5fa486f5385", "best_bid": "0.994", "best_ask": "0.997"}], "timestamp": "1769384434457", "event_type": "price_change"}}
{"_local_timestamp": "2026-01-25T23:40:34.539825+00:00", "data": {"market": "0x83db787ed2cb00d225178e66bc6ae4d22e8029f19390d2b78ded5aed978eead6", "price_changes": [{"asset_id": "113401754986342384261044700457165882158632153698445535217371023842472815025478", "price": "0.991", "size": "0", "side": "SELL", "hash": "fa4f89b04981d8e9e88e3548da58fada23cacbcd", "best_bid": "0.99", "best_ask": "0.992"}, {"asset_id": "81906419701908530974011339985097627770048267181648886108185004759027261509242", "price": "0.009", "size": "0", "side": "BUY", "hash": "53223785e0ce5c01ae8c3a01049caddb9c932614", "best_bid": "0.008", "best_ask": "0.01"}], "timestamp": "1769384434457", "event_type": "price_change"}}
{"_local_timestamp": "2026-01-25T23:40:34.542890+00:00", "data": {"market": "0x83db787ed2cb00d225178e66bc6ae4d22e8029f19390d2b78ded5aed978eead6", "price_changes": [{"asset_id": "113401754986342384261044700457165882158632153698445535217371023842472815025478", "price": "0.986", "size": "100", "side": "BUY", "hash": "fa4f89b04981d8e9e88e3548da58fada23cacbcd", "best_bid": "0.99", "best_ask": "0.992"}, {"asset_id": "81906419701908530974011339985097627770048267181648886108185004759027261509242", "price": "0.014", "size": "100", "side": "SELL", "hash": "53223785e0ce5c01ae8c3a01049caddb9c932614", "best_bid": "0.008", "best_ask": "0.01"}], "timestamp": "1769384434457", "event_type": "price_change"}}
{"_local_timestamp": "2026-01-25T23:40:34.549846+00:00", "data": {"market": "0x83db787ed2cb00d225178e66bc6ae4d22e8029f19390d2b78ded5aed978eead6", "price_changes": [{"asset_id": "81906419701908530974011339985097627770048267181648886108185004759027261509242", "price": "0.003", "size": "555.76", "side": "BUY", "hash": "c3118724a811ca6b10fa3c11796a2ef2d58f13d6", "best_bid": "0.008", "best_ask": "0.01"}, {"asset_id": "113401754986342384261044700457165882158632153698445535217371023842472815025478", "price": "0.997", "size": "555.76", "side": "SELL", "hash": "972ad585d130c1bd6ea6170b4b3c52c334a2df23", "best_bid": "0.99", "best_ask": "0.992"}], "timestamp": "1769384434480", "event_type": "price_change"}}
{"_local_timestamp": "2026-01-25T23:40:34.563016+00:00", "data": {"market": "0x754113d4aefc74db7c1266dc5f03e89e3f597deda15b19c19b3ca16cc85b8c33", "price_changes": [{"asset_id": "48827723684529991552849237252156781311984893775886188249280006578488168779709", "price": "0.993", "size": "0", "side": "BUY", "hash": "bf3f0777c3bd10dd49bc906d498c533227a94bf4", "best_bid": "0.997", "best_ask": "1"}, {"asset_id": "16018186278713893766129270377649855044679233002578361062022208432086696077104", "price": "0.007", "size": "0", "side": "SELL", "hash": "83666e850da0d022ae15f01ce8096e7834928aae", "best_bid": "0", "best_ask": "0.003"}], "timestamp": "1769384434480", "event_type": "price_change"}}
{"_local_timestamp": "2026-01-25T23:40:34.674798+00:00", "data": {"market": "0x754113d4aefc74db7c1266dc5f03e89e3f597deda15b19c19b3ca16cc85b8c33", "price_changes": [{"asset_id": "48827723684529991552849237252156781311984893775886188249280006578488168779709", "price": "0.992", "size": "22", "side": "BUY", "hash": "da77477c8462f79f01b2651af4906b2c7b2ec618", "best_bid": "0.997", "best_ask": "1"}, {"asset_id": "16018186278713893766129270377649855044679233002578361062022208432086696077104", "price": "0.008", "size": "22", "side": "SELL", "hash": "137bc641c9ee95e0e51d234dcde7aef87605d1e5", "best_bid": "0", "best_ask": "0.003"}], "timestamp": "1769384434605", "event_type": "price_change"}}
{"_local_timestamp": "2026-01-25T23:40:34.677919+00:00", "data": {"market": "0x83db787ed2cb00d225178e66bc6ae4d22e8029f19390d2b78ded5aed978eead6", "price_changes": [{"asset_id": "81906419701908530974011339985097627770048267181648886108185004759027261509242", "price": "0.002", "size": "62658.44", "side": "BUY", "hash": "b896f1702f564ff38a77f46b69b8da9ee9c83b26", "best_bid": "0.008", "best_ask": "0.01"}, {"asset_id": "113401754986342384261044700457165882158632153698445535217371023842472815025478", "price": "0.998", "size": "62658.44", "side": "SELL", "hash": "15f485cd9af736b6387ea408e676c1d3980726a0", "best_bid": "0.99", "best_ask": "0.992"}], "timestamp": "1769384434607", "event_type": "price_change"}}
{"_local_timestamp": "2026-01-25T23:40:36.667025+00:00", "data": {"market": "0x754113d4aefc74db7c1266dc5f03e89e3f597deda15b19c19b3ca16cc85b8c33", "price_changes": [{"asset_id": "48827723684529991552849237252156781311984893775886188249280006578488168779709", "price": "0.995", "size": "2138.57", "side": "BUY", "hash": "95ce6c914d76e88326021ef71fe63a50f1c76ba9", "best_bid": "0.997", "best_ask": "1"}, {"asset_id": "16018186278713893766129270377649855044679233002578361062022208432086696077104", "price": "0.005", "size": "2138.57", "side": "SELL", "hash": "3d58d694455060cabdf749b370990461cd7759e2", "best_bid": "0", "best_ask": "0.003"}], "timestamp": "1769384436591", "event_type": "price_change"}}
{"_local_timestamp": "2026-01-25T23:40:37.445005+00:00", "data": {"market": "0xbfcc34365517ac4978e76ecd8287e37fd92e68b22a3db9b31129c5c37669c293", "price_changes": [{"asset_id": "95417221270011105499568468828531867453865533932484364685389046548264041887861", "price": "0.004", "size": "98", "side": "BUY", "hash": "7a1df3dca123941edb27011493eede5011ac5f41", "best_bid": "0.004", "best_ask": "0.006"}, {"asset_id": "101322769768415942646735830228475566436146317671120615766292718518675772773223", "price": "0.996", "size": "98", "side": "SELL", "hash": "eac8aa073d504d3176e5833a717ce81085c56e45", "best_bid": "0.994", "best_ask": "0.996"}], "timestamp": "1769384437374", "event_type": "price_change"}}
{"_local_timestamp": "2026-01-25T23:40:37.863444+00:00", "data": {"market": "0xbfcc34365517ac4978e76ecd8287e37fd92e68b22a3db9b31129c5c37669c293", "price_changes": [{"asset_id": "95417221270011105499568468828531867453865533932484364685389046548264041887861", "price": "0.011", "size": "2668.88", "side": "SELL", "hash": "6add57b0f9b007c3620c0132baebf9b6754ea34a", "best_bid": "0.004", "best_ask": "0.006"}, {"asset_id": "101322769768415942646735830228475566436146317671120615766292718518675772773223", "price": "0.989", "size": "2668.88", "side": "BUY", "hash": "7f501fdbf23de381b3dd50a0345bf1a23846b120", "best_bid": "0.994", "best_ask": "0.996"}], "timestamp": "1769384437792", "event_type": "price_change"}}
{"_local_timestamp": "2026-01-25T23:40:38.268987+00:00", "data": {"market": "0x83db787ed2cb00d225178e66bc6ae4d22e8029f19390d2b78ded5aed978eead6", "price_changes": [{"asset_id": "113401754986342384261044700457165882158632153698445535217371023842472815025478", "price": "0.986", "size": "1006.81", "side": "BUY", "hash": "50079ad1817eab676f76eb08139dd84c80445380", "best_bid": "0.99", "best_ask": "0.992"}, {"asset_id": "81906419701908530974011339985097627770048267181648886108185004759027261509242", "price": "0.014", "size": "1006.81", "side": "SELL", "hash": "498b7e7f9c98428cb9f688459d4cc373388d6a59", "best_bid": "0.008", "best_ask": "0.01"}], "timestamp": "1769384438194", "event_type": "price_change"}}
{"_local_timestamp": "2026-01-25T23:40:38.669216+00:00", "data": {"market": "0x83db787ed2cb00d225178e66bc6ae4d22e8029f19390d2b78ded5aed978eead6", "price_changes": [{"asset_id": "113401754986342384261044700457165882158632153698445535217371023842472815025478", "price": "0.991", "size": "946.66", "side": "SELL", "hash": "ee1f7310757dadcc8580e3dc20be5239c8ab83b7", "best_bid": "0.99", "best_ask": "0.991"}, {"asset_id": "81906419701908530974011339985097627770048267181648886108185004759027261509242", "price": "0.009", "size": "946.66", "side": "BUY", "hash": "5ff4661d443310b9759b46b7b59c2d0c9fd5f0fd", "best_bid": "0.009", "best_ask": "0.01"}], "timestamp": "1769384438597", "event_type": "price_change"}}
{"_local_timestamp": "2026-01-25T23:40:39.041531+00:00", "data": {"market": "0x754113d4aefc74db7c1266dc5f03e89e3f597deda15b19c19b3ca16cc85b8c33", "price_changes": [{"asset_id": "48827723684529991552849237252156781311984893775886188249280006578488168779709", "price": "0.995", "size": "1231.76", "side": "BUY", "hash": "c0241ddbc13fd7980c1c53e72e3e19318f00c937", "best_bid": "0.997", "best_ask": "1"}, {"asset_id": "16018186278713893766129270377649855044679233002578361062022208432086696077104", "price": "0.005", "size": "1231.76", "side": "SELL", "hash": "fa3c1c227781440a37b4d3c3688196d004d51a42", "best_bid": "0", "best_ask": "0.003"}], "timestamp": "1769384438970", "event_type": "price_change"}}
{"_local_timestamp": "2026-01-25T23:40:39.044844+00:00", "data": {"market": "0xbfcc34365517ac4978e76ecd8287e37fd92e68b22a3db9b31129c5c37669c293", "price_changes": [{"asset_id": "95417221270011105499568468828531867453865533932484364685389046548264041887861", "price": "0.004", "size": "0", "side": "BUY", "hash": "f10266e720489831ddcaca1ed4f8f9feb55a28f9", "best_bid": "0.003", "best_ask": "0.006"}, {"asset_id": "101322769768415942646735830228475566436146317671120615766292718518675772773223", "price": "0.996", "size": "0", "side": "SELL", "hash": "0e9b26db6e913779213f283dd52bea70ce764875", "best_bid": "0.994", "best_ask": "0.997"}], "timestamp": "1769384438971", "event_type": "price_change"}}
{"_local_timestamp": "2026-01-25T23:40:39.049060+00:00", "data": {"market": "0xbfcc34365517ac4978e76ecd8287e37fd92e68b22a3db9b31129c5c37669c293", "price_changes": [{"asset_id": "95417221270011105499568468828531867453865533932484364685389046548264041887861", "price": "0.011", "size": "22", "side": "SELL", "hash": "f10266e720489831ddcaca1ed4f8f9feb55a28f9", "best_bid": "0.003", "best_ask": "0.006"}, {"asset_id": "101322769768415942646735830228475566436146317671120615766292718518675772773223", "price": "0.989", "size": "22", "side": "BUY", "hash": "0e9b26db6e913779213f283dd52bea70ce764875", "best_bid": "0.994", "best_ask": "0.997"}], "timestamp": "1769384438971", "event_type": "price_change"}}
{"_local_timestamp": "2026-01-25T23:40:39.061191+00:00", "data": {"market": "0x83db787ed2cb00d225178e66bc6ae4d22e8029f19390d2b78ded5aed978eead6", "price_changes": [{"asset_id": "113401754986342384261044700457165882158632153698445535217371023842472815025478", "price": "0.991", "size": "0", "side": "SELL", "hash": "0f11f01a7cc207d925cc74186f72a29483e785ca", "best_bid": "0.99", "best_ask": "0.992"}, {"asset_id": "81906419701908530974011339985097627770048267181648886108185004759027261509242", "price": "0.009", "size": "0", "side": "BUY", "hash": "e136a702a0b68bc8143fcddfd727c4c09f0717a6", "best_bid": "0.008", "best_ask": "0.01"}], "timestamp": "1769384438971", "event_type": "price_change"}}
{"_local_timestamp": "2026-01-25T23:40:39.065406+00:00", "data": {"market": "0x83db787ed2cb00d225178e66bc6ae4d22e8029f19390d2b78ded5aed978eead6", "price_changes": [{"asset_id": "113401754986342384261044700457165882158632153698445535217371023842472815025478", "price": "0.986", "size": "100", "side": "BUY", "hash": "0f11f01a7cc207d925cc74186f72a29483e785ca", "best_bid": "0.99", "best_ask": "0.992"}, {"asset_id": "81906419701908530974011339985097627770048267181648886108185004759027261509242", "price": "0.014", "size": "100", "side": "SELL", "hash": "e136a702a0b68bc8143fcddfd727c4c09f0717a6", "best_bid": "0.008", "best_ask": "0.01"}], "timestamp": "1769384438971", "event_type": "price_change"}}
{"_local_timestamp": "2026-01-25T23:40:41.141784+00:00", "data": {"market": "0x754113d4aefc74db7c1266dc5f03e89e3f597deda15b19c19b3ca16cc85b8c33", "price_changes": [{"asset_id": "48827723684529991552849237252156781311984893775886188249280006578488168779709", "price": "0.995", "size": "2138.57", "side": "BUY", "hash": "d25044adfeca3e525d69fbbad041129659cbde2f", "best_bid": "0.997", "best_ask": "1"}, {"asset_id": "16018186278713893766129270377649855044679233002578361062022208432086696077104", "price": "0.005", "size": "2138.57", "side": "SELL", "hash": "9e8e76f66f01a8caad127579ecf5435d2141dc2f", "best_bid": "0", "best_ask": "0.003"}], "timestamp": "1769384441040", "event_type": "price_change"}}
{"_local_timestamp": "2026-01-25T23:40:41.911801+00:00", "data": {"market": "0xbfcc34365517ac4978e76ecd8287e37fd92e68b22a3db9b31129c5c37669c293", "price_changes": [{"asset_id": "95417221270011105499568468828531867453865533932484364685389046548264041887861", "price": "0.004", "size": "98", "side": "BUY", "hash": "94ad39aae9ddcaab52005a326712ddd9acdf0059", "best_bid": "0.004", "best_ask": "0.006"}, {"asset_id": "101322769768415942646735830228475566436146317671120615766292718518675772773223", "price": "0.996", "size": "98", "side": "SELL", "hash": "95e043a5b18614ecf3619ba67fc28bb6784354ed", "best_bid": "0.994", "best_ask": "0.996"}], "timestamp": "1769384441846", "event_type": "price_change"}}
{"_local_timestamp": "2026-01-25T23:40:42.319531+00:00", "data": {"market": "0xbfcc34365517ac4978e76ecd8287e37fd92e68b22a3db9b31129c5c37669c293", "price_changes": [{"asset_id": "95417221270011105499568468828531867453865533932484364685389046548264041887861", "price": "0.011", "size": "2668.88", "side": "SELL", "hash": "86147589ae20a4dc9bfb94d4c7408a7c3c52c7e8", "best_bid": "0.004", "best_ask": "0.006"}, {"asset_id": "101322769768415942646735830228475566436146317671120615766292718518675772773223", "price": "0.989", "size": "2668.88", "side": "BUY", "hash": "3de1803b63cabcfcb8a7d9efb0337125a4262cde", "best_bid": "0.994", "best_ask": "0.996"}], "timestamp": "1769384442248", "event_type": "price_change"}}
{"_local_timestamp": "2026-01-25T23:40:42.702111+00:00", "data": {"market": "0x83db787ed2cb00d225178e66bc6ae4d22e8029f19390d2b78ded5aed978eead6", "price_changes": [{"asset_id": "113401754986342384261044700457165882158632153698445535217371023842472815025478", "price": "0.986", "size": "1006.81", "side": "BUY", "hash": "55226daf66ad63451175636e8d761b8f8c662fd1", "best_bid": "0.99", "best_ask": "0.992"}, {"asset_id": "81906419701908530974011339985097627770048267181648886108185004759027261509242", "price": "0.014", "size": "1006.81", "side": "SELL", "hash": "9b1be7a8dc4540e6b52e63f0091263d0405ec72e", "best_bid": "0.008", "best_ask": "0.01"}], "timestamp": "1769384442631", "event_type": "price_change"}}
{"_local_timestamp": "2026-01-25T23:40:42.882382+00:00", "data": {"market": "0xbfcc34365517ac4978e76ecd8287e37fd92e68b22a3db9b31129c5c37669c293", "price_changes": [{"asset_id": "101322769768415942646735830228475566436146317671120615766292718518675772773223", "price": "0.971", "size": "0", "side": "BUY", "hash": "e28f00ef201484bb6a7ff20eb3c9c5e7cae2d11e", "best_bid": "0.994", "best_ask": "0.996"}, {"asset_id": "95417221270011105499568468828531867453865533932484364685389046548264041887861", "price": "0.029", "size": "0", "side": "SELL", "hash": "f0b3a81ce9fa8a9f169ba9d2d9ff01634c27b0c3", "best_bid": "0.004", "best_ask": "0.006"}], "timestamp": "1769384442809", "event_type": "price_change"}}
{"_local_timestamp": "2026-01-25T23:40:43.093345+00:00", "data": {"market": "0xbfcc34365517ac4978e76ecd8287e37fd92e68b22a3db9b31129c5c37669c293", "price_changes": [{"asset_id": "101322769768415942646735830228475566436146317671120615766292718518675772773223", "price": "0.971", "size": "20", "side": "BUY", "hash": "53ab7af032182e521179ca6ee11c5768588bb405", "best_bid": "0.994", "best_ask": "0.996"}, {"asset_id": "95417221270011105499568468828531867453865533932484364685389046548264041887861", "price": "0.029", "size": "20", "side": "SELL", "hash": "e862e5b7971724b87bbf6701d4d52acf62faa456", "best_bid": "0.004", "best_ask": "0.006"}], "timestamp": "1769384443009", "event_type": "price_change"}}
{"_local_timestamp": "2026-01-25T23:40:43.111754+00:00", "data": {"market": "0x83db787ed2cb00d225178e66bc6ae4d22e8029f19390d2b78ded5aed978eead6", "price_changes": [{"asset_id": "113401754986342384261044700457165882158632153698445535217371023842472815025478", "price": "0.991", "size": "946.66", "side": "SELL", "hash": "82bd08e3dc2f365c7ec79a5c065a6fd21ddb8120", "best_bid": "0.99", "best_ask": "0.991"}, {"asset_id": "81906419701908530974011339985097627770048267181648886108185004759027261509242", "price": "0.009", "size": "946.66", "side": "BUY", "hash": "d00da5d33e96196ddbef6e65172e7ca313bb9756", "best_bid": "0.009", "best_ask": "0.01"}], "timestamp": "1769384443039", "event_type": "price_change"}}
{"_local_timestamp": "2026-01-25T23:40:43.502610+00:00", "data": {"market": "0x754113d4aefc74db7c1266dc5f03e89e3f597deda15b19c19b3ca16cc85b8c33", "price_changes": [{"asset_id": "48827723684529991552849237252156781311984893775886188249280006578488168779709", "price": "0.995", "size": "1231.76", "side": "BUY", "hash": "9fb5b35e478a750fcebd544ecaf8b3ee50d22340", "best_bid": "0.997", "best_ask": "1"}, {"asset_id": "16018186278713893766129270377649855044679233002578361062022208432086696077104", "price": "0.005", "size": "1231.76", "side": "SELL", "hash": "95d9d99013ca3af9d4dbd30d48cf67cb9b84ba64", "best_bid": "0", "best_ask": "0.003"}], "timestamp": "1769384443428", "event_type": "price_change"}}
{"_local_timestamp": "2026-01-25T23:40:43.507767+00:00", "data": {"market": "0xbfcc34365517ac4978e76ecd8287e37fd92e68b22a3db9b31129c5c37669c293", "price_changes": [{"asset_id": "95417221270011105499568468828531867453865533932484364685389046548264041887861", "price": "0.004", "size": "0", "side": "BUY", "hash": "4e9cb7ae1844057dc065034622b3ef912aeb5878", "best_bid": "0.003", "best_ask": "0.006"}, {"asset_id": "101322769768415942646735830228475566436146317671120615766292718518675772773223", "price": "0.996", "size": "0", "side": "SELL", "hash": "b22eb87c992b4e4b2e900ea9165c82b0013c8d2f", "best_bid": "0.994", "best_ask": "0.997"}], "timestamp": "1769384443428", "event_type": "price_change"}}
{"_local_timestamp": "2026-01-25T23:40:43.515607+00:00", "data": {"market": "0xbfcc34365517ac4978e76ecd8287e37fd92e68b22a3db9b31129c5c37669c293", "price_changes": [{"asset_id": "95417221270011105499568468828531867453865533932484364685389046548264041887861", "price": "0.011", "size": "22", "side": "SELL", "hash": "4e9cb7ae1844057dc065034622b3ef912aeb5878", "best_bid": "0.003", "best_ask": "0.006"}, {"asset_id": "101322769768415942646735830228475566436146317671120615766292718518675772773223", "price": "0.989", "size": "22", "side": "BUY", "hash": "b22eb87c992b4e4b2e900ea9165c82b0013c8d2f", "best_bid": "0.994", "best_ask": "0.997"}], "timestamp": "1769384443428", "event_type": "price_change"}}
{"_local_timestamp": "2026-01-25T23:40:43.520965+00:00", "data": {"market": "0x83db787ed2cb00d225178e66bc6ae4d22e8029f19390d2b78ded5aed978eead6", "price_changes": [{"asset_id": "113401754986342384261044700457165882158632153698445535217371023842472815025478", "price": "0.986", "size": "100", "side": "BUY", "hash": "c40c363d2b3bf63cf146b86648297fd15b5adf43", "best_bid": "0.99", "best_ask": "0.992"}, {"asset_id": "81906419701908530974011339985097627770048267181648886108185004759027261509242", "price": "0.014", "size": "100", "side": "SELL", "hash": "31f26cc5949a37ab08a016b6cd592a36320c5088", "best_bid": "0.008", "best_ask": "0.01"}], "timestamp": "1769384443428", "event_type": "price_change"}}
{"_local_timestamp": "2026-01-25T23:40:43.527521+00:00", "data": {"market": "0x83db787ed2cb00d225178e66bc6ae4d22e8029f19390d2b78ded5aed978eead6", "price_changes": [{"asset_id": "113401754986342384261044700457165882158632153698445535217371023842472815025478", "price": "0.991", "size": "0", "side": "SELL", "hash": "c40c363d2b3bf63cf146b86648297fd15b5adf43", "best_bid": "0.99", "best_ask": "0.992"}, {"asset_id": "81906419701908530974011339985097627770048267181648886108185004759027261509242", "price": "0.009", "size": "0", "side": "BUY", "hash": "31f26cc5949a37ab08a016b6cd592a36320c5088", "best_bid": "0.008", "best_ask": "0.01"}], "timestamp": "1769384443428", "event_type": "price_change"}}
{"_local_timestamp": "2026-01-25T23:40:45.579901+00:00", "data": {"market": "0x754113d4aefc74db7c1266dc5f03e89e3f597deda15b19c19b3ca16cc85b8c33", "price_changes": [{"asset_id": "48827723684529991552849237252156781311984893775886188249280006578488168779709", "price": "0.995", "size": "2138.57", "side": "BUY", "hash": "021d06e55d717ea2d42884f690c4cfc307246a83", "best_bid": "0.997", "best_ask": "1"}, {"asset_id": "16018186278713893766129270377649855044679233002578361062022208432086696077104", "price": "0.005", "size": "2138.57", "side": "SELL", "hash": "8f46ccefc2ab5b1d28f2ba73e0912e65ad35717c", "best_bid": "0", "best_ask": "0.003"}], "timestamp": "1769384445513", "event_type": "price_change"}}
{"_local_timestamp": "2026-01-25T23:40:46.381193+00:00", "data": {"market": "0xbfcc34365517ac4978e76ecd8287e37fd92e68b22a3db9b31129c5c37669c293", "price_changes": [{"asset_id": "95417221270011105499568468828531867453865533932484364685389046548264041887861", "price": "0.004", "size": "98", "side": "BUY", "hash": "0fff022e7d9fdb77f63f984d95821fed2a5c5fd5", "best_bid": "0.004", "best_ask": "0.006"}, {"asset_id": "101322769768415942646735830228475566436146317671120615766292718518675772773223", "price": "0.996", "size": "98", "side": "SELL", "hash": "aa1cd58e3f1ec1c5af8c44b20218da89d1137c73", "best_bid": "0.994", "best_ask": "0.996"}], "timestamp": "1769384446309", "event_type": "price_change"}}
{"_local_timestamp": "2026-01-25T23:40:46.400616+00:00", "data": {"market": "0x754113d4aefc74db7c1266dc5f03e89e3f597deda15b19c19b3ca16cc85b8c33", "price_changes": [{"asset_id": "48827723684529991552849237252156781311984893775886188249280006578488168779709", "price": "0.992", "size": "0", "side": "BUY", "hash": "52d220b156e76887f8bef71754eee02cc01e6b15", "best_bid": "0.997", "best_ask": "1"}, {"asset_id": "16018186278713893766129270377649855044679233002578361062022208432086696077104", "price": "0.008", "size": "0", "side": "SELL", "hash": "59da01f8604e2953616bdd3c35c9f660c8af9579", "best_bid": "0", "best_ask": "0.003"}], "timestamp": "1769384446333", "event_type": "price_change"}}
{"_local_timestamp": "2026-01-25T23:40:46.411192+00:00", "data": {"market": "0x83db787ed2cb00d225178e66bc6ae4d22e8029f19390d2b78ded5aed978eead6", "price_changes": [{"asset_id": "81906419701908530974011339985097627770048267181648886108185004759027261509242", "price": "0.002", "size": "62582.44", "side": "BUY", "hash": "6902d322bff2178133405325d8e7fcceb65b2906", "best_bid": "0.008", "best_ask": "0.01"}, {"asset_id": "113401754986342384261044700457165882158632153698445535217371023842472815025478", "price": "0.998", "size": "62582.44", "side": "SELL", "hash": "e47cf20354a5f0b6b12e5198a78b31368cef6287", "best_bid": "0.99", "best_ask": "0.992"}], "timestamp": "1769384446339", "event_type": "price_change"}}
{"_local_timestamp": "2026-01-25T23:40:46.535452+00:00", "data": {"market": "0x83db787ed2cb00d225178e66bc6ae4d22e8029f19390d2b78ded5aed978eead6", "price_changes": [{"asset_id": "81906419701908530974011339985097627770048267181648886108185004759027261509242", "price": "0.003", "size": "653.76", "side": "BUY", "hash": "3856bbc81d829de5723cc986f894407d0f032c28", "best_bid": "0.008", "best_ask": "0.01"}, {"asset_id": "113401754986342384261044700457165882158632153698445535217371023842472815025478", "price": "0.997", "size": "653.76", "side": "SELL", "hash": "d32e1b2a717ff557694d9273dc020e201ce88e7c", "best_bid": "0.99", "best_ask": "0.992"}], "timestamp": "1769384446463", "event_type": "price_change"}}
{"_local_timestamp": "2026-01-25T23:40:46.540083+00:00", "data": {"market": "0x754113d4aefc74db7c1266dc5f03e89e3f597deda15b19c19b3ca16cc85b8c33", "price_changes": [{"asset_id": "48827723684529991552849237252156781311984893775886188249280006578488168779709", "price": "0.993", "size": "22", "side": "BUY", "hash": "2a218ed8983dd31dcd785a89d869831daff7feee", "best_bid": "0.997", "best_ask": "1"}, {"asset_id": "16018186278713893766129270377649855044679233002578361062022208432086696077104", "price": "0.007", "size": "22", "side": "SELL", "hash": "bb095094b4b9b0355a158ab06610ce318aa37881", "best_bid": "0", "best_ask": "0.003"}], "timestamp": "1769384446463", "event_type": "price_change"}}
{"_local_timestamp": "2026-01-25T23:40:46.777743+00:00", "data": {"market": "0xbfcc34365517ac4978e76ecd8287e37fd92e68b22a3db9b31129c5c37669c293", "price_changes": [{"asset_id": "95417221270011105499568468828531867453865533932484364685389046548264041887861", "price": "0.011", "size": "2668.88", "side": "SELL", "hash": "19526b8e4fc10f0dc5714a99d7d94d068363c7de", "best_bid": "0.004", "best_ask": "0.006"}, {"asset_id": "101322769768415942646735830228475566436146317671120615766292718518675772773223", "price": "0.989", "size": "2668.88", "side": "BUY", "hash": "5ed8a06b75e13762c20f34221c7e64fb7193288d", "best_bid": "0.994", "best_ask": "0.996"}], "timestamp": "1769384446707", "event_type": "price_change"}}
{"_local_timestamp": "2026-01-25T23:40:47.191265+00:00", "data": {"market": "0x83db787ed2cb00d225178e66bc6ae4d22e8029f19390d2b78ded5aed978eead6", "price_changes": [{"asset_id": "113401754986342384261044700457165882158632153698445535217371023842472815025478", "price": "0.986", "size": "1006.81", "side": "BUY", "hash": "64686c6e0af68ec90a7910178f3add43122f063e", "best_bid": "0.99", "best_ask": "0.992"}, {"asset_id": "81906419701908530974011339985097627770048267181648886108185004759027261509242", "price": "0.014", "size": "1006.81", "side": "SELL", "hash": "1eb5868c765dae5d3f62191d864d509e5dc7b86d", "best_bid": "0.008", "best_ask": "0.01"}], "timestamp": "1769384447117", "event_type": "price_change"}}
{"_local_timestamp": "2026-01-25T23:40:47.622659+00:00", "data": {"market": "0x83db787ed2cb00d225178e66bc6ae4d22e8029f19390d2b78ded5aed978eead6", "price_changes": [{"asset_id": "113401754986342384261044700457165882158632153698445535217371023842472815025478", "price": "0.991", "size": "946.66", "side": "SELL", "hash": "bfb11a3a0cf8c752cdf31b4cfac4c86ae963d8a7", "best_bid": "0.99", "best_ask": "0.991"}, {"asset_id": "81906419701908530974011339985097627770048267181648886108185004759027261509242", "price": "0.009", "size": "946.66", "side": "BUY", "hash": "531d6c17aa9da6c3eb57efc76ded216545d8a7b5", "best_bid": "0.009", "best_ask": "0.01"}], "timestamp": "1769384447548", "event_type": "price_change"}}
{"_local_timestamp": "2026-01-25T23:40:47.996051+00:00", "data": {"market": "0x754113d4aefc74db7c1266dc5f03e89e3f597deda15b19c19b3ca16cc85b8c33", "price_changes": [{"asset_id": "48827723684529991552849237252156781311984893775886188249280006578488168779709", "price": "0.995", "size": "1231.76", "side": "BUY", "hash": "aa7fefe70f1337c18809ebaafb3110f03ff60aaa", "best_bid": "0.997", "best_ask": "1"}, {"asset_id": "16018186278713893766129270377649855044679233002578361062022208432086696077104", "price": "0.005", "size": "1231.76", "side": "SELL", "hash": "dd186f9aac9c83277b2bc79cc2e8c2b0c4474807", "best_bid": "0", "best_ask": "0.003"}], "timestamp": "1769384447931", "event_type": "price_change"}}
{"_local_timestamp": "2026-01-25T23:40:48.000734+00:00", "data": {"market": "0xbfcc34365517ac4978e76ecd8287e37fd92e68b22a3db9b31129c5c37669c293", "price_changes": [{"asset_id": "95417221270011105499568468828531867453865533932484364685389046548264041887861", "price": "0.004", "size": "0", "side": "BUY", "hash": "bef3f1edd9a745dc6cce0bd756830ab54a579305", "best_bid": "0.003", "best_ask": "0.006"}, {"asset_id": "101322769768415942646735830228475566436146317671120615766292718518675772773223", "price": "0.996", "size": "0", "side": "SELL", "hash": "9dbf78ea296d820c504291812c5b9bdc3aa10953", "best_bid": "0.994", "best_ask": "0.997"}], "timestamp": "1769384447931", "event_type": "price_change"}}
{"_local_timestamp": "2026-01-25T23:40:48.005146+00:00", "data": {"market": "0xbfcc34365517ac4978e76ecd8287e37fd92e68b22a3db9b31129c5c37669c293", "price_changes": [{"asset_id": "95417221270011105499568468828531867453865533932484364685389046548264041887861", "price": "0.011", "size": "22", "side": "SELL", "hash": "bef3f1edd9a745dc6cce0bd756830ab54a579305", "best_bid": "0.003", "best_ask": "0.006"}, {"asset_id": "101322769768415942646735830228475566436146317671120615766292718518675772773223", "price": "0.989", "size": "22", "side": "BUY", "hash": "9dbf78ea296d820c504291812c5b9bdc3aa10953", "best_bid": "0.994", "best_ask": "0.997"}], "timestamp": "1769384447931", "event_type": "price_change"}}
{"_local_timestamp": "2026-01-25T23:40:48.008064+00:00", "data": {"market": "0x83db787ed2cb00d225178e66bc6ae4d22e8029f19390d2b78ded5aed978eead6", "price_changes": [{"asset_id": "113401754986342384261044700457165882158632153698445535217371023842472815025478", "price": "0.991", "size": "0", "side": "SELL", "hash": "f0ddcfa9550f9e1893bc80ff0e16d337629c8d56", "best_bid": "0.99", "best_ask": "0.992"}, {"asset_id": "81906419701908530974011339985097627770048267181648886108185004759027261509242", "price": "0.009", "size": "0", "side": "BUY", "hash": "5afcdbbd6f85452e405ef3cfc55168ff8c33c18c", "best_bid": "0.008", "best_ask": "0.01"}], "timestamp": "1769384447931", "event_type": "price_change"}}
{"_local_timestamp": "2026-01-25T23:40:48.011064+00:00", "data": {"market": "0x83db787ed2cb00d225178e66bc6ae4d22e8029f19390d2b78ded5aed978eead6", "price_changes": [{"asset_id": "113401754986342384261044700457165882158632153698445535217371023842472815025478", "price": "0.986", "size": "100", "side": "BUY", "hash": "f0ddcfa9550f9e1893bc80ff0e16d337629c8d56", "best_bid": "0.99", "best_ask": "0.992"}, {"asset_id": "81906419701908530974011339985097627770048267181648886108185004759027261509242", "price": "0.014", "size": "100", "side": "SELL", "hash": "5afcdbbd6f85452e405ef3cfc55168ff8c33c18c", "best_bid": "0.008", "best_ask": "0.01"}], "timestamp": "1769384447931", "event_type": "price_change"}}
{"_local_timestamp": "2026-01-25T23:40:48.031070+00:00", "data": {"market": "0x754113d4aefc74db7c1266dc5f03e89e3f597deda15b19c19b3ca16cc85b8c33", "price_changes": [{"asset_id": "48827723684529991552849237252156781311984893775886188249280006578488168779709", "price": "0.993", "size": "0", "side": "BUY", "hash": "8a91987cf19120bb5a56763e0bee5b3beaa591b7", "best_bid": "0.997", "best_ask": "1"}, {"asset_id": "16018186278713893766129270377649855044679233002578361062022208432086696077104", "price": "0.007", "size": "0", "side": "SELL", "hash": "f782aee823cc8c7df306902d465408999a20c18b", "best_bid": "0", "best_ask": "0.003"}], "timestamp": "1769384447955", "event_type": "price_change"}}
{"_local_timestamp": "2026-01-25T23:40:48.053012+00:00", "data": {"market": "0x83db787ed2cb00d225178e66bc6ae4d22e8029f19390d2b78ded5aed978eead6", "price_changes": [{"asset_id": "81906419701908530974011339985097627770048267181648886108185004759027261509242", "price": "0.003", "size": "555.76", "side": "BUY", "hash": "d9faff423f9d7e63bc7796bc3322622962c4b13a", "best_bid": "0.008", "best_ask": "0.01"}, {"asset_id": "113401754986342384261044700457165882158632153698445535217371023842472815025478", "price": "0.997", "size": "555.76", "side": "SELL", "hash": "ca8c12a64ffc2579763ccda9c9be719945944600", "best_bid": "0.99", "best_ask": "0.992"}], "timestamp": "1769384447982", "event_type": "price_change"}}
{"_local_timestamp": "2026-01-25T23:40:48.161640+00:00", "data": {"market": "0x754113d4aefc74db7c1266dc5f03e89e3f597deda15b19c19b3ca16cc85b8c33", "price_changes": [{"asset_id": "48827723684529991552849237252156781311984893775886188249280006578488168779709", "price": "0.992", "size": "22", "side": "BUY", "hash": "bc3d3030a455d7dfa9a494797b14680605d23c43", "best_bid": "0.997", "best_ask": "1"}, {"asset_id": "16018186278713893766129270377649855044679233002578361062022208432086696077104", "price": "0.008", "size": "22", "side": "SELL", "hash": "a1844df9114ecac9b101af42f9e5f31310850528", "best_bid": "0", "best_ask": "0.003"}], "timestamp": "1769384448085", "event_type": "price_change"}}
{"_local_timestamp": "2026-01-25T23:40:48.184853+00:00", "data": {"market": "0x83db787ed2cb00d225178e66bc6ae4d22e8029f19390d2b78ded5aed978eead6", "price_changes": [{"asset_id": "81906419701908530974011339985097627770048267181648886108185004759027261509242", "price": "0.002", "size": "62658.44", "side": "BUY", "hash": "5bfa3f760fbff1b2073454d9971bcf19f0502dda", "best_bid": "0.008", "best_ask": "0.01"}, {"asset_id": "113401754986342384261044700457165882158632153698445535217371023842472815025478", "price": "0.998", "size": "62658.44", "side": "SELL", "hash": "4324e6e366fa5225a79d68ed5163dc516a25b85e", "best_bid": "0.99", "best_ask": "0.992"}], "timestamp": "1769384448106", "event_type": "price_change"}}
{"_local_timestamp": "2026-01-25T23:40:50.178050+00:00", "data": {"market": "0x754113d4aefc74db7c1266dc5f03e89e3f597deda15b19c19b3ca16cc85b8c33", "price_changes": [{"asset_id": "48827723684529991552849237252156781311984893775886188249280006578488168779709", "price": "0.995", "size": "2138.57", "side": "BUY", "hash": "8d5c1d5d9e4b45c906885a9b4c798cd4d3c0564b", "best_bid": "0.997", "best_ask": "1"}, {"asset_id": "16018186278713893766129270377649855044679233002578361062022208432086696077104", "price": "0.005", "size": "2138.57", "side": "SELL", "hash": "1ef05e94f4224b7840b35b292160fa564c93433b", "best_bid": "0", "best_ask": "0.003"}], "timestamp": "1769384450041", "event_type": "price_change"}}
{"_local_timestamp": "2026-01-25T23:40:50.917154+00:00", "data": {"market": "0xbfcc34365517ac4978e76ecd8287e37fd92e68b22a3db9b31129c5c37669c293", "price_changes": [{"asset_id": "95417221270011105499568468828531867453865533932484364685389046548264041887861", "price": "0.004", "size": "98", "side": "BUY", "hash": "aa5d1bd642d3afd3dbc5420682f53bd502bda090", "best_bid": "0.004", "best_ask": "0.006"}, {"asset_id": "101322769768415942646735830228475566436146317671120615766292718518675772773223", "price": "0.996", "size": "98", "side": "SELL", "hash": "fea38fde1ede6a32ab414a2ff072e33068a0c6e7", "best_bid": "0.994", "best_ask": "0.996"}], "timestamp": "1769384450848", "event_type": "price_change"}}
{"_local_timestamp": "2026-01-25T23:40:51.345138+00:00", "data": {"market": "0xbfcc34365517ac4978e76ecd8287e37fd92e68b22a3db9b31129c5c37669c293", "price_changes": [{"asset_id": "95417221270011105499568468828531867453865533932484364685389046548264041887861", "price": "0.011", "size": "2668.88", "side": "SELL", "hash": "59e6fd987b3adfd903358b53d70c1a123d5d4a2b", "best_bid": "0.004", "best_ask": "0.006"}, {"asset_id": "101322769768415942646735830228475566436146317671120615766292718518675772773223", "price": "0.989", "size": "2668.88", "side": "BUY", "hash": "546cbf39887708ea5359f1fb70a3a4e6775e8b84", "best_bid": "0.994", "best_ask": "0.996"}], "timestamp": "1769384451261", "event_type": "price_change"}}
{"_local_timestamp": "2026-01-25T23:40:51.752841+00:00", "data": {"market": "0x83db787ed2cb00d225178e66bc6ae4d22e8029f19390d2b78ded5aed978eead6", "price_changes": [{"asset_id": "113401754986342384261044700457165882158632153698445535217371023842472815025478", "price": "0.986", "size": "1006.81", "side": "BUY", "hash": "5a9fc57953b39611ade5e0c8883d1e1ff278d9fb", "best_bid": "0.99", "best_ask": "0.992"}, {"asset_id": "81906419701908530974011339985097627770048267181648886108185004759027261509242", "price": "0.014", "size": "1006.81", "side": "SELL", "hash": "0f1f9b129d76f1f06ed62cce6a6d8edf625728e1", "best_bid": "0.008", "best_ask": "0.01"}], "timestamp": "1769384451683", "event_type": "price_change"}}
{"_local_timestamp": "2026-01-25T23:40:52.166646+00:00", "data": {"market": "0x83db787ed2cb00d225178e66bc6ae4d22e8029f19390d2b78ded5aed978eead6", "price_changes": [{"asset_id": "113401754986342384261044700457165882158632153698445535217371023842472815025478", "price": "0.991", "size": "946.66", "side": "SELL", "hash": "1e97093a17013d3f5f5eb6801781a963b2e5548c", "best_bid": "0.99", "best_ask": "0.991"}, {"asset_id": "81906419701908530974011339985097627770048267181648886108185004759027261509242", "price": "0.009", "size": "946.66", "side": "BUY", "hash": "38545ffa189f25d7c441cfa5a60f004eef978b18", "best_bid": "0.009", "best_ask": "0.01"}], "timestamp": "1769384452083", "event_type": "price_change"}}
{"_local_timestamp": "2026-01-25T23:40:52.573102+00:00", "data": {"market": "0x754113d4aefc74db7c1266dc5f03e89e3f597deda15b19c19b3ca16cc85b8c33", "price_changes": [{"asset_id": "48827723684529991552849237252156781311984893775886188249280006578488168779709", "price": "0.995", "size": "1231.76", "side": "BUY", "hash": "7800d87fda0f4b336a11382f72ad7e5ad403dbbc", "best_bid": "0.997", "best_ask": "1"}, {"asset_id": "16018186278713893766129270377649855044679233002578361062022208432086696077104", "price": "0.005", "size": "1231.76", "side": "SELL", "hash": "df81ccae0b5b1aa50d7055cc1120b544ce359923", "best_bid": "0", "best_ask": "0.003"}], "timestamp": "1769384452491", "event_type": "price_change"}}
{"_local_timestamp": "2026-01-25T23:40:52.576890+00:00", "data": {"market": "0xbfcc34365517ac4978e76ecd8287e37fd92e68b22a3db9b31129c5c37669c293", "price_changes": [{"asset_id": "95417221270011105499568468828531867453865533932484364685389046548264041887861", "price": "0.004", "size": "0", "side": "BUY", "hash": "6ce99eeca3834a28e428a70cf6cdfc943f955e42", "best_bid": "0.003", "best_ask": "0.006"}, {"asset_id": "101322769768415942646735830228475566436146317671120615766292718518675772773223", "price": "0.996", "size": "0", "side": "SELL", "hash": "06d31c687bd94ac2cadfa8be37481405cfc2e028", "best_bid": "0.994", "best_ask": "0.997"}], "timestamp": "1769384452491", "event_type": "price_change"}}
{"_local_timestamp": "2026-01-25T23:40:52.581167+00:00", "data": {"market": "0x83db787ed2cb00d225178e66bc6ae4d22e8029f19390d2b78ded5aed978eead6", "price_changes": [{"asset_id": "113401754986342384261044700457165882158632153698445535217371023842472815025478", "price": "0.986", "size": "100", "side": "BUY", "hash": "6b902c1d2142395235243b27ef396912444e38a7", "best_bid": "0.99", "best_ask": "0.992"}, {"asset_id": "81906419701908530974011339985097627770048267181648886108185004759027261509242", "price": "0.014", "size": "100", "side": "SELL", "hash": "af5d11a85464f33b8b03a8165a9b92bb9ddc552d", "best_bid": "0.008", "best_ask": "0.01"}], "timestamp": "1769384452491", "event_type": "price_change"}}
{"_local_timestamp": "2026-01-25T23:40:52.584829+00:00", "data": {"market": "0xbfcc34365517ac4978e76ecd8287e37fd92e68b22a3db9b31129c5c37669c293", "price_changes": [{"asset_id": "95417221270011105499568468828531867453865533932484364685389046548264041887861", "price": "0.011", "size": "22", "side": "SELL", "hash": "6ce99eeca3834a28e428a70cf6cdfc943f955e42", "best_bid": "0.003", "best_ask": "0.006"}, {"asset_id": "101322769768415942646735830228475566436146317671120615766292718518675772773223", "price": "0.989", "size": "22", "side": "BUY", "hash": "06d31c687bd94ac2cadfa8be37481405cfc2e028", "best_bid": "0.994", "best_ask": "0.997"}], "timestamp": "1769384452491", "event_type": "price_change"}}
{"_local_timestamp": "2026-01-25T23:40:52.589726+00:00", "data": {"market": "0x83db787ed2cb00d225178e66bc6ae4d22e8029f19390d2b78ded5aed978eead6", "price_changes": [{"asset_id": "113401754986342384261044700457165882158632153698445535217371023842472815025478", "price": "0.991", "size": "0", "side": "SELL", "hash": "6b902c1d2142395235243b27ef396912444e38a7", "best_bid": "0.99", "best_ask": "0.992"}, {"asset_id": "81906419701908530974011339985097627770048267181648886108185004759027261509242", "price": "0.009", "size": "0", "side": "BUY", "hash": "af5d11a85464f33b8b03a8165a9b92bb9ddc552d", "best_bid": "0.008", "best_ask": "0.01"}], "timestamp": "1769384452491", "event_type": "price_change"}}
{"_local_timestamp": "2026-01-25T23:40:52.834859+00:00", "data": {"market": "0x83db787ed2cb00d225178e66bc6ae4d22e8029f19390d2b78ded5aed978eead6", "price_changes": [{"asset_id": "81906419701908530974011339985097627770048267181648886108185004759027261509242", "price": "0.002", "size": "62599.87", "side": "BUY", "hash": "1791756cfbce9ec0d219f74fbb102b04850b12a6", "best_bid": "0.008", "best_ask": "0.01"}, {"asset_id": "113401754986342384261044700457165882158632153698445535217371023842472815025478", "price": "0.998", "size": "62599.87", "side": "SELL", "hash": "d1afd4c24839ca5118f2b0a4dbbdb98e95a6d353", "best_bid": "0.99", "best_ask": "0.992"}], "timestamp": "1769384452762", "event_type": "price_change"}}
{"_local_timestamp": "2026-01-25T23:40:52.837887+00:00", "data": {"market": "0x83db787ed2cb00d225178e66bc6ae4d22e8029f19390d2b78ded5aed978eead6", "price_changes": [{"asset_id": "81906419701908530974011339985097627770048267181648886108185004759027261509242", "price": "0.007", "size": "9.18", "side": "BUY", "hash": "1791756cfbce9ec0d219f74fbb102b04850b12a6", "best_bid": "0.008", "best_ask": "0.01"}, {"asset_id": "113401754986342384261044700457165882158632153698445535217371023842472815025478", "price": "0.993", "size": "9.18", "side": "SELL", "hash": "d1afd4c24839ca5118f2b0a4dbbdb98e95a6d353", "best_bid": "0.99", "best_ask": "0.992"}], "timestamp": "1769384452762", "event_type": "price_change"}}
{"_local_timestamp": "2026-01-25T23:40:54.624714+00:00", "data": {"market": "0x754113d4aefc74db7c1266dc5f03e89e3f597deda15b19c19b3ca16cc85b8c33", "price_changes": [{"asset_id": "48827723684529991552849237252156781311984893775886188249280006578488168779709", "price": "0.995", "size": "2138.57", "side": "BUY", "hash": "7be8f7d7575d7915cc24649f074550abb6b00a29", "best_bid": "0.997", "best_ask": "1"}, {"asset_id": "16018186278713893766129270377649855044679233002578361062022208432086696077104", "price": "0.005", "size": "2138.57", "side": "SELL", "hash": "eb7749e4c3870c656bc7be58705c3337b751effd", "best_bid": "0", "best_ask": "0.003"}], "timestamp": "1769384454548", "event_type": "price_change"}}
{"_local_timestamp": "2026-01-25T23:40:55.429579+00:00", "data": {"market": "0xbfcc34365517ac4978e76ecd8287e37fd92e68b22a3db9b31129c5c37669c293", "price_changes": [{"asset_id": "95417221270011105499568468828531867453865533932484364685389046548264041887861", "price": "0.004", "size": "98", "side": "BUY", "hash": "fb1f4e1b42d2a6db744b1cc9c165f34a31513428", "best_bid": "0.004", "best_ask": "0.006"}, {"asset_id": "101322769768415942646735830228475566436146317671120615766292718518675772773223", "price": "0.996", "size": "98", "side": "SELL", "hash": "e7a725b9d5dc397f949ce648ca0bbaf97a97c75a", "best_bid": "0.994", "best_ask": "0.996"}], "timestamp": "1769384455354", "event_type": "price_change"}}
{"_local_timestamp": "2026-01-25T23:40:55.523576+00:00", "data": {"market": "0x83db787ed2cb00d225178e66bc6ae4d22e8029f19390d2b78ded5aed978eead6", "price_changes": [{"asset_id": "81906419701908530974011339985097627770048267181648886108185004759027261509242", "price": "0.007", "size": "19.79", "side": "BUY", "hash": "bf856397b2a622ee2901c342921ff8b43453c9cb", "best_bid": "0.008", "best_ask": "0.01"}, {"asset_id": "113401754986342384261044700457165882158632153698445535217371023842472815025478", "price": "0.993", "size": "19.79", "side": "SELL", "hash": "c87b0017881e6b20ae8d7c790d8344063318043c", "best_bid": "0.99", "best_ask": "0.992"}], "timestamp": "1769384455450", "event_type": "price_change"}}
{"_local_timestamp": "2026-01-25T23:40:55.526712+00:00", "data": {"market": "0x83db787ed2cb00d225178e66bc6ae4d22e8029f19390d2b78ded5aed978eead6", "price_changes": [{"asset_id": "81906419701908530974011339985097627770048267181648886108185004759027261509242", "price": "0.002", "size": "62658.44", "side": "BUY", "hash": "73b5b04a1a09aab3f838190d51913bcfe7e81c11", "best_bid": "0.008", "best_ask": "0.01"}, {"asset_id": "113401754986342384261044700457165882158632153698445535217371023842472815025478", "price": "0.998", "size": "62658.44", "side": "SELL", "hash": "6adaf77084d87bd59bbc2925e661b87db0b5c025", "best_bid": "0.99", "best_ask": "0.992"}], "timestamp": "1769384455451", "event_type": "price_change"}}
{"_local_timestamp": "2026-01-25T23:40:55.564048+00:00", "data": {"market": "0xbfcc34365517ac4978e76ecd8287e37fd92e68b22a3db9b31129c5c37669c293", "price_changes": [{"asset_id": "101322769768415942646735830228475566436146317671120615766292718518675772773223", "price": "0.976", "size": "0", "side": "BUY", "hash": "49f39ec186fd940703335c7bfeb6a82191776721", "best_bid": "0.994", "best_ask": "0.996"}, {"asset_id": "95417221270011105499568468828531867453865533932484364685389046548264041887861", "price": "0.024", "size": "0", "side": "SELL", "hash": "940921de0dda3913af7262afc27e0b81a431ab3c", "best_bid": "0.004", "best_ask": "0.006"}], "timestamp": "1769384455494", "event_type": "price_change"}}
{"_local_timestamp": "2026-01-25T23:40:55.833155+00:00", "data": {"market": "0xbfcc34365517ac4978e76ecd8287e37fd92e68b22a3db9b31129c5c37669c293", "price_changes": [{"asset_id": "95417221270011105499568468828531867453865533932484364685389046548264041887861", "price": "0.011", "size": "2668.88", "side": "SELL", "hash": "009968d9b56f72519d3efe9d99ead8ff5d61be9d", "best_bid": "0.004", "best_ask": "0.006"}, {"asset_id": "101322769768415942646735830228475566436146317671120615766292718518675772773223", "price": "0.989", "size": "2668.88", "side": "BUY", "hash": "2d77ca4b16dc95926938224cb3bbceefaba31931", "best_bid": "0.994", "best_ask": "0.996"}], "timestamp": "1769384455762", "event_type": "price_change"}}
{"_local_timestamp": "2026-01-25T23:40:56.188531+00:00", "data": {"market": "0xbfcc34365517ac4978e76ecd8287e37fd92e68b22a3db9b31129c5c37669c293", "price_changes": [{"asset_id": "101322769768415942646735830228475566436146317671120615766292718518675772773223", "price": "0.993", "size": "950.9", "side": "BUY", "hash": "b000ab1ece199ed22b0ec1cb781b701ad1b98df0", "best_bid": "0.994", "best_ask": "0.996"}, {"asset_id": "95417221270011105499568468828531867453865533932484364685389046548264041887861", "price": "0.007", "size": "950.9", "side": "SELL", "hash": "612d9d11f58dafd7f5af4130999467464c64fda7", "best_bid": "0.004", "best_ask": "0.006"}], "timestamp": "1769384456112", "event_type": "price_change"}}
{"_local_timestamp": "2026-01-25T23:40:56.263949+00:00", "data": {"market": "0x83db787ed2cb00d225178e66bc6ae4d22e8029f19390d2b78ded5aed978eead6", "price_changes": [{"asset_id": "113401754986342384261044700457165882158632153698445535217371023842472815025478", "price": "0.986", "size": "1006.81", "side": "BUY", "hash": "013da0c3c4dcea42b974cb68e9c814c5f99c7636", "best_bid": "0.99", "best_ask": "0.992"}, {"asset_id": "81906419701908530974011339985097627770048267181648886108185004759027261509242", "price": "0.014", "size": "1006.81", "side": "SELL", "hash": "8a4a81fad79cc404461cee3d95ed34ca7a8c2162", "best_bid": "0.008", "best_ask": "0.01"}], "timestamp": "1769384456185", "event_type": "price_change"}}
{"_local_timestamp": "2026-01-25T23:40:56.651323+00:00", "data": {"market": "0x83db787ed2cb00d225178e66bc6ae4d22e8029f19390d2b78ded5aed978eead6", "price_changes": [{"asset_id": "113401754986342384261044700457165882158632153698445535217371023842472815025478", "price": "0.991", "size": "946.66", "side": "SELL", "hash": "5170eb736e9a7b26a3df84c7290e4c37ff0b888c", "best_bid": "0.99", "best_ask": "0.991"}, {"asset_id": "81906419701908530974011339985097627770048267181648886108185004759027261509242", "price": "0.009", "size": "946.66", "side": "BUY", "hash": "e118c3da9f0847524d9670e9d08825608c2a0c57", "best_bid": "0.009", "best_ask": "0.01"}], "timestamp": "1769384456579", "event_type": "price_change"}}
{"_local_timestamp": "2026-01-25T23:40:57.034210+00:00", "data": {"market": "0x754113d4aefc74db7c1266dc5f03e89e3f597deda15b19c19b3ca16cc85b8c33", "price_changes": [{"asset_id": "48827723684529991552849237252156781311984893775886188249280006578488168779709", "price": "0.995", "size": "1231.76", "side": "BUY", "hash": "6989741453a6e05851d914309d01ca8d5eb32982", "best_bid": "0.997", "best_ask": "1"}, {"asset_id": "16018186278713893766129270377649855044679233002578361062022208432086696077104", "price": "0.005", "size": "1231.76", "side": "SELL", "hash": "9a443de31248d085344cdf90dfc9c0ff8aaaaa62", "best_bid": "0", "best_ask": "0.003"}], "timestamp": "1769384456954", "event_type": "price_change"}}
{"_local_timestamp": "2026-01-25T23:40:57.037395+00:00", "data": {"market": "0xbfcc34365517ac4978e76ecd8287e37fd92e68b22a3db9b31129c5c37669c293", "price_changes": [{"asset_id": "95417221270011105499568468828531867453865533932484364685389046548264041887861", "price": "0.004", "size": "0", "side": "BUY", "hash": "d77a3c3009b39fadbb603cb790566005a7c45cf2", "best_bid": "0.003", "best_ask": "0.006"}, {"asset_id": "101322769768415942646735830228475566436146317671120615766292718518675772773223", "price": "0.996", "size": "0", "side": "SELL", "hash": "f3b56932c8db58f37710fe3d6d4d2abf18b706e2", "best_bid": "0.994", "best_ask": "0.997"}], "timestamp": "1769384456954", "event_type": "price_change"}}
{"_local_timestamp": "2026-01-25T23:40:57.040485+00:00", "data": {"market": "0xbfcc34365517ac4978e76ecd8287e37fd92e68b22a3db9b31129c5c37669c293", "price_changes": [{"asset_id": "95417221270011105499568468828531867453865533932484364685389046548264041887861", "price": "0.011", "size": "22", "side": "SELL", "hash": "d77a3c3009b39fadbb603cb790566005a7c45cf2", "best_bid": "0.003", "best_ask": "0.006"}, {"asset_id": "101322769768415942646735830228475566436146317671120615766292718518675772773223", "price": "0.989", "size": "22", "side": "BUY", "hash": "f3b56932c8db58f37710fe3d6d4d2abf18b706e2", "best_bid": "0.994", "best_ask": "0.997"}], "timestamp": "1769384456954", "event_type": "price_change"}}
{"_local_timestamp": "2026-01-25T23:40:57.043562+00:00", "data": {"market": "0x83db787ed2cb00d225178e66bc6ae4d22e8029f19390d2b78ded5aed978eead6", "price_changes": [{"asset_id": "113401754986342384261044700457165882158632153698445535217371023842472815025478", "price": "0.986", "size": "100", "side": "BUY", "hash": "52535c52892c02b59e18bc76249fa55957e26b40", "best_bid": "0.99", "best_ask": "0.992"}, {"asset_id": "81906419701908530974011339985097627770048267181648886108185004759027261509242", "price": "0.014", "size": "100", "side": "SELL", "hash": "bbbff964a6c6d146bc1cf652e0e46931a2387192", "best_bid": "0.008", "best_ask": "0.01"}], "timestamp": "1769384456954", "event_type": "price_change"}}
{"_local_timestamp": "2026-01-25T23:40:57.046791+00:00", "data": {"market": "0x83db787ed2cb00d225178e66bc6ae4d22e8029f19390d2b78ded5aed978eead6", "price_changes": [{"asset_id": "113401754986342384261044700457165882158632153698445535217371023842472815025478", "price": "0.991", "size": "0", "side": "SELL", "hash": "52535c52892c02b59e18bc76249fa55957e26b40", "best_bid": "0.99", "best_ask": "0.992"}, {"asset_id": "81906419701908530974011339985097627770048267181648886108185004759027261509242", "price": "0.009", "size": "0", "side": "BUY", "hash": "bbbff964a6c6d146bc1cf652e0e46931a2387192", "best_bid": "0.008", "best_ask": "0.01"}], "timestamp": "1769384456954", "event_type": "price_change"}}
{"_local_timestamp": "2026-01-25T23:40:59.203078+00:00", "data": {"market": "0x754113d4aefc74db7c1266dc5f03e89e3f597deda15b19c19b3ca16cc85b8c33", "price_changes": [{"asset_id": "48827723684529991552849237252156781311984893775886188249280006578488168779709", "price": "0.995", "size": "2138.57", "side": "BUY", "hash": "0733e7617447d810a8d9b5555532dbc10922f797", "best_bid": "0.997", "best_ask": "1"}, {"asset_id": "16018186278713893766129270377649855044679233002578361062022208432086696077104", "price": "0.005", "size": "2138.57", "side": "SELL", "hash": "f3e58ada12736d027e092748f8c0df4f3895a0ce", "best_bid": "0", "best_ask": "0.003"}], "timestamp": "1769384459102", "event_type": "price_change"}}
{"_local_timestamp": "2026-01-25T23:40:59.971181+00:00", "data": {"market": "0xbfcc34365517ac4978e76ecd8287e37fd92e68b22a3db9b31129c5c37669c293", "price_changes": [{"asset_id": "95417221270011105499568468828531867453865533932484364685389046548264041887861", "price": "0.004", "size": "98", "side": "BUY", "hash": "cd7ee7ecad4d3c003ab657f8026e47433a90a989", "best_bid": "0.004", "best_ask": "0.006"}, {"asset_id": "101322769768415942646735830228475566436146317671120615766292718518675772773223", "price": "0.996", "size": "98", "side": "SELL", "hash": "21605f69c4ef9e651d9255249a6c8e5975f2ae21", "best_bid": "0.994", "best_ask": "0.996"}], "timestamp": "1769384459904", "event_type": "price_change"}}
{"_local_timestamp": "2026-01-25T23:41:00.002289+00:00", "data": {"market": "0x754113d4aefc74db7c1266dc5f03e89e3f597deda15b19c19b3ca16cc85b8c33", "price_changes": [{"asset_id": "48827723684529991552849237252156781311984893775886188249280006578488168779709", "price": "0.992", "size": "0", "side": "BUY", "hash": "90e8232c2df9130a48a1526f68a3fb727b2bc793", "best_bid": "0.997", "best_ask": "1"}, {"asset_id": "16018186278713893766129270377649855044679233002578361062022208432086696077104", "price": "0.008", "size": "0", "side": "SELL", "hash": "267305d700ad85f2b0508c688097dae98a89dd5e", "best_bid": "0", "best_ask": "0.003"}], "timestamp": "1769384459926", "event_type": "price_change"}}
{"_local_timestamp": "2026-01-25T23:41:00.009179+00:00", "data": {"market": "0x83db787ed2cb00d225178e66bc6ae4d22e8029f19390d2b78ded5aed978eead6", "price_changes": [{"asset_id": "81906419701908530974011339985097627770048267181648886108185004759027261509242", "price": "0.002", "size": "62582.44", "side": "BUY", "hash": "198c7b0e2f8bd19ec325ce5fc1ea348a7412a536", "best_bid": "0.008", "best_ask": "0.01"}, {"asset_id": "113401754986342384261044700457165882158632153698445535217371023842472815025478", "price": "0.998", "size": "62582.44", "side": "SELL", "hash": "9b00ae6b1ec84300cb3e204d45fe9ee57fea529e", "best_bid": "0.99", "best_ask": "0.992"}], "timestamp": "1769384459929", "event_type": "price_change"}}
{"_local_timestamp": "2026-01-25T23:41:00.121078+00:00", "data": {"market": "0x754113d4aefc74db7c1266dc5f03e89e3f597deda15b19c19b3ca16cc85b8c33", "price_changes": [{"asset_id": "48827723684529991552849237252156781311984893775886188249280006578488168779709", "price": "0.993", "size": "22", "side": "BUY", "hash": "4c47e7b81a44ef1d33a7a2c7c3cb915a3bd210d6", "best_bid": "0.997", "best_ask": "1"}, {"asset_id": "16018186278713893766129270377649855044679233002578361062022208432086696077104", "price": "0.007", "size": "22", "side": "SELL", "hash": "c61b1a52023476aef5483d3db0d629c4b072a953", "best_bid": "0", "best_ask": "0.003"}], "timestamp": "1769384460054", "event_type": "price_change"}}
{"_local_timestamp": "2026-01-25T23:41:00.126965+00:00", "data": {"market": "0x83db787ed2cb00d225178e66bc6ae4d22e8029f19390d2b78ded5aed978eead6", "price_changes": [{"asset_id": "81906419701908530974011339985097627770048267181648886108185004759027261509242", "price": "0.003", "size": "653.76", "side": "BUY", "hash": "7987f4bd9fefd9898a7632e72caa29f0cb1fc065", "best_bid": "0.008", "best_ask": "0.01"}, {"asset_id": "113401754986342384261044700457165882158632153698445535217371023842472815025478", "price": "0.997", "size": "653.76", "side": "SELL", "hash": "2074d923d797c297efb33c696db089bb6d669cec", "best_bid": "0.99", "best_ask": "0.992"}], "timestamp": "1769384460056", "event_type": "price_change"}}
{"_local_timestamp": "2026-01-25T23:41:00.385676+00:00", "data": {"market": "0xbfcc34365517ac4978e76ecd8287e37fd92e68b22a3db9b31129c5c37669c293", "price_changes": [{"asset_id": "95417221270011105499568468828531867453865533932484364685389046548264041887861", "price": "0.011", "size": "2668.88", "side": "SELL", "hash": "b15f1cb194e7021a41231b6f392510d5a2f3cfae", "best_bid": "0.004", "best_ask": "0.006"}, {"asset_id": "101322769768415942646735830228475566436146317671120615766292718518675772773223", "price": "0.989", "size": "2668.88", "side": "BUY", "hash": "25c6bf02ee4315e56173a5e891b46a6846a57848", "best_bid": "0.994", "best_ask": "0.996"}], "timestamp": "1769384460317", "event_type": "price_change"}}
{"_local_timestamp": "2026-01-25T23:41:00.771593+00:00", "data": {"market": "0x83db787ed2cb00d225178e66bc6ae4d22e8029f19390d2b78ded5aed978eead6", "price_changes": [{"asset_id": "113401754986342384261044700457165882158632153698445535217371023842472815025478", "price": "0.986", "size": "1006.81", "side": "BUY", "hash": "0441e794fc2ae6f66ecf6c6b95141607851a2c50", "best_bid": "0.99", "best_ask": "0.992"}, {"asset_id": "81906419701908530974011339985097627770048267181648886108185004759027261509242", "price": "0.014", "size": "1006.81", "side": "SELL", "hash": "4dcc65cce05821adf0fbaf91f114d231a476783c", "best_bid": "0.008", "best_ask": "0.01"}], "timestamp": "1769384460705", "event_type": "price_change"}}
{"_local_timestamp": "2026-01-25T23:41:01.170192+00:00", "data": {"market": "0x83db787ed2cb00d225178e66bc6ae4d22e8029f19390d2b78ded5aed978eead6", "price_changes": [{"asset_id": "113401754986342384261044700457165882158632153698445535217371023842472815025478", "price": "0.991", "size": "946.66", "side": "SELL", "hash": "e9816a62630af766ab7f48f9253a1b3a0b15fb20", "best_bid": "0.99", "best_ask": "0.991"}, {"asset_id": "81906419701908530974011339985097627770048267181648886108185004759027261509242", "price": "0.009", "size": "946.66", "side": "BUY", "hash": "c4a2164bd8264bdcc3ec4d6d71f2b2be03a1bfac", "best_bid": "0.009", "best_ask": "0.01"}], "timestamp": "1769384461101", "event_type": "price_change"}}
{"_local_timestamp": "2026-01-25T23:41:01.565644+00:00", "data": {"market": "0x754113d4aefc74db7c1266dc5f03e89e3f597deda15b19c19b3ca16cc85b8c33", "price_changes": [{"asset_id": "48827723684529991552849237252156781311984893775886188249280006578488168779709", "price": "0.995", "size": "1231.76", "side": "BUY", "hash": "22b223a73a54f1c6d82eb172fea8e760b5223ad8", "best_bid": "0.997", "best_ask": "1"}, {"asset_id": "16018186278713893766129270377649855044679233002578361062022208432086696077104", "price": "0.005", "size": "1231.76", "side": "SELL", "hash": "e3a46df0485399ef9c8721bc1b794d92f5b18438", "best_bid": "0", "best_ask": "0.003"}], "timestamp": "1769384461477", "event_type": "price_change"}}
{"_local_timestamp": "2026-01-25T23:41:01.570340+00:00", "data": {"market": "0xbfcc34365517ac4978e76ecd8287e37fd92e68b22a3db9b31129c5c37669c293", "price_changes": [{"asset_id": "95417221270011105499568468828531867453865533932484364685389046548264041887861", "price": "0.004", "size": "0", "side": "BUY", "hash": "14ded30afd9793fd9db8a48c4138fb227506d5d7", "best_bid": "0.003", "best_ask": "0.006"}, {"asset_id": "101322769768415942646735830228475566436146317671120615766292718518675772773223", "price": "0.996", "size": "0", "side": "SELL", "hash": "3be874b9f1ec627f212ff20843dfdd11ad18fdd2", "best_bid": "0.994", "best_ask": "0.997"}], "timestamp": "1769384461477", "event_type": "price_change"}}
{"_local_timestamp": "2026-01-25T23:41:01.574257+00:00", "data": {"market": "0xbfcc34365517ac4978e76ecd8287e37fd92e68b22a3db9b31129c5c37669c293", "price_changes": [{"asset_id": "95417221270011105499568468828531867453865533932484364685389046548264041887861", "price": "0.011", "size": "22", "side": "SELL", "hash": "14ded30afd9793fd9db8a48c4138fb227506d5d7", "best_bid": "0.003", "best_ask": "0.006"}, {"asset_id": "101322769768415942646735830228475566436146317671120615766292718518675772773223", "price": "0.989", "size": "22", "side": "BUY", "hash": "3be874b9f1ec627f212ff20843dfdd11ad18fdd2", "best_bid": "0.994", "best_ask": "0.997"}], "timestamp": "1769384461477", "event_type": "price_change"}}
{"_local_timestamp": "2026-01-25T23:41:01.579291+00:00", "data": {"market": "0x83db787ed2cb00d225178e66bc6ae4d22e8029f19390d2b78ded5aed978eead6", "price_changes": [{"asset_id": "113401754986342384261044700457165882158632153698445535217371023842472815025478", "price": "0.986", "size": "100", "side": "BUY", "hash": "40d6d516340e46fe94abde90653778bec8765dce", "best_bid": "0.99", "best_ask": "0.992"}, {"asset_id": "81906419701908530974011339985097627770048267181648886108185004759027261509242", "price": "0.014", "size": "100", "side": "SELL", "hash": "df4614a9f11c06fc07098335d48d58da5a01c1b6", "best_bid": "0.008", "best_ask": "0.01"}], "timestamp": "1769384461477", "event_type": "price_change"}}
{"_local_timestamp": "2026-01-25T23:41:01.582685+00:00", "data": {"market": "0x83db787ed2cb00d225178e66bc6ae4d22e8029f19390d2b78ded5aed978eead6", "price_changes": [{"asset_id": "113401754986342384261044700457165882158632153698445535217371023842472815025478", "price": "0.991", "size": "0", "side": "SELL", "hash": "40d6d516340e46fe94abde90653778bec8765dce", "best_bid": "0.99", "best_ask": "0.992"}, {"asset_id": "81906419701908530974011339985097627770048267181648886108185004759027261509242", "price": "0.009", "size": "0", "side": "BUY", "hash": "df4614a9f11c06fc07098335d48d58da5a01c1b6", "best_bid": "0.008", "best_ask": "0.01"}], "timestamp": "1769384461477", "event_type": "price_change"}}
{"_local_timestamp": "2026-01-25T23:41:01.585680+00:00", "data": {"market": "0x83db787ed2cb00d225178e66bc6ae4d22e8029f19390d2b78ded5aed978eead6", "price_changes": [{"asset_id": "81906419701908530974011339985097627770048267181648886108185004759027261509242", "price": "0.003", "size": "555.76", "side": "BUY", "hash": "a0eb5fd275b2f286f20e3869d30804f283f8808a", "best_bid": "0.008", "best_ask": "0.01"}, {"asset_id": "113401754986342384261044700457165882158632153698445535217371023842472815025478", "price": "0.997", "size": "555.76", "side": "SELL", "hash": "44b0210e5fbed20fc492d06c533436089a573550", "best_bid": "0.99", "best_ask": "0.992"}], "timestamp": "1769384461501", "event_type": "price_change"}}
{"_local_timestamp": "2026-01-25T23:41:01.590820+00:00", "data": {"market": "0x754113d4aefc74db7c1266dc5f03e89e3f597deda15b19c19b3ca16cc85b8c33", "price_changes": [{"asset_id": "48827723684529991552849237252156781311984893775886188249280006578488168779709", "price": "0.993", "size": "0", "side": "BUY", "hash": "9a725b0ed294137bc27faff07901de2c31e8cfa8", "best_bid": "0.997", "best_ask": "1"}, {"asset_id": "16018186278713893766129270377649855044679233002578361062022208432086696077104", "price": "0.007", "size": "0", "side": "SELL", "hash": "75d6c7b0922a600caaaf3ef336b3cfedeedde476", "best_bid": "0", "best_ask": "0.003"}], "timestamp": "1769384461502", "event_type": "price_change"}}
{"_local_timestamp": "2026-01-25T23:41:01.705461+00:00", "data": {"market": "0x754113d4aefc74db7c1266dc5f03e89e3f597deda15b19c19b3ca16cc85b8c33", "price_changes": [{"asset_id": "48827723684529991552849237252156781311984893775886188249280006578488168779709", "price": "0.992", "size": "22", "side": "BUY", "hash": "73a86413530f7c4a9339edf6c643b373be6ffc55", "best_bid": "0.997", "best_ask": "1"}, {"asset_id": "16018186278713893766129270377649855044679233002578361062022208432086696077104", "price": "0.008", "size": "22", "side": "SELL", "hash": "37eb6c16bdf705eb9167254dec61fe91a1ffa54d", "best_bid": "0", "best_ask": "0.003"}], "timestamp": "1769384461628", "event_type": "price_change"}}
{"_local_timestamp": "2026-01-25T23:41:01.713413+00:00", "data": {"market": "0x83db787ed2cb00d225178e66bc6ae4d22e8029f19390d2b78ded5aed978eead6", "price_changes": [{"asset_id": "81906419701908530974011339985097627770048267181648886108185004759027261509242", "price": "0.002", "size": "62658.44", "side": "BUY", "hash": "0164045baf60e73eb7e10fc7e5472ecd2d876bb7", "best_bid": "0.008", "best_ask": "0.01"}, {"asset_id": "113401754986342384261044700457165882158632153698445535217371023842472815025478", "price": "0.998", "size": "62658.44", "side": "SELL", "hash": "4d115226945a6ad596c1d017ee7d493bcc92f883", "best_bid": "0.99", "best_ask": "0.992"}], "timestamp": "1769384461628", "event_type": "price_change"}}
{"_local_timestamp": "2026-01-25T23:41:02.150506+00:00", "data": {"market": "0x83db787ed2cb00d225178e66bc6ae4d22e8029f19390d2b78ded5aed978eead6", "price_changes": [{"asset_id": "113401754986342384261044700457165882158632153698445535217371023842472815025478", "price": "0.18", "size": "0", "side": "BUY", "hash": "1a4b5b3fc9bd3b42ebac1631d1d3f3ffeb9d7707", "best_bid": "0.99", "best_ask": "0.992"}, {"asset_id": "81906419701908530974011339985097627770048267181648886108185004759027261509242", "price": "0.82", "size": "0", "side": "SELL", "hash": "34975cb5d715970b79aa0e262a4039a0690b97a0", "best_bid": "0.008", "best_ask": "0.01"}], "timestamp": "1769384462081", "event_type": "price_change"}}
{"_local_timestamp": "2026-01-25T23:41:03.652044+00:00", "data": {"market": "0x754113d4aefc74db7c1266dc5f03e89e3f597deda15b19c19b3ca16cc85b8c33", "price_changes": [{"asset_id": "48827723684529991552849237252156781311984893775886188249280006578488168779709", "price": "0.995", "size": "2138.57", "side": "BUY", "hash": "fd3988d6cf66e9bb517fd3d246907ca6338eb82c", "best_bid": "0.997", "best_ask": "1"}, {"asset_id": "16018186278713893766129270377649855044679233002578361062022208432086696077104", "price": "0.005", "size": "2138.57", "side": "SELL", "hash": "be6c5ce9e026c0b2cc2f94080dd7182c0701e88c", "best_bid": "0", "best_ask": "0.003"}], "timestamp": "1769384463558", "event_type": "price_change"}}
{"_local_timestamp": "2026-01-25T23:41:03.980423+00:00", "data": {"market": "0x83db787ed2cb00d225178e66bc6ae4d22e8029f19390d2b78ded5aed978eead6", "price_changes": [{"asset_id": "113401754986342384261044700457165882158632153698445535217371023842472815025478", "price": "0.18", "size": "5", "side": "BUY", "hash": "39f8e827b9341b2fc2c67e1054b702df57f74a8c", "best_bid": "0.99", "best_ask": "0.992"}, {"asset_id": "81906419701908530974011339985097627770048267181648886108185004759027261509242", "price": "0.82", "size": "5", "side": "SELL", "hash": "f8b46e7955e702a79634319e7f554a310e3316e7", "best_bid": "0.008", "best_ask": "0.01"}], "timestamp": "1769384463908", "event_type": "price_change"}}
{"_local_timestamp": "2026-01-25T23:41:04.416159+00:00", "data": {"market": "0xbfcc34365517ac4978e76ecd8287e37fd92e68b22a3db9b31129c5c37669c293", "price_changes": [{"asset_id": "95417221270011105499568468828531867453865533932484364685389046548264041887861", "price": "0.004", "size": "98", "side": "BUY", "hash": "2c622380a119921660f55491124bad923ed9af42", "best_bid": "0.004", "best_ask": "0.006"}, {"asset_id": "101322769768415942646735830228475566436146317671120615766292718518675772773223", "price": "0.996", "size": "98", "side": "SELL", "hash": "3886b3e808492dcfe53cd08a22bdebf11f2a9f5a", "best_bid": "0.994", "best_ask": "0.996"}], "timestamp": "1769384464344", "event_type": "price_change"}}
{"_local_timestamp": "2026-01-25T23:41:04.809568+00:00", "data": {"market": "0xbfcc34365517ac4978e76ecd8287e37fd92e68b22a3db9b31129c5c37669c293", "price_changes": [{"asset_id": "95417221270011105499568468828531867453865533932484364685389046548264041887861", "price": "0.011", "size": "2668.88", "side": "SELL", "hash": "56bd6959a7532382311f2161c890f2fec3ddfa8d", "best_bid": "0.004", "best_ask": "0.006"}, {"asset_id": "101322769768415942646735830228475566436146317671120615766292718518675772773223", "price": "0.989", "size": "2668.88", "side": "BUY", "hash": "0cafd28878caf47f85f5079fbdd56d69126f1b42", "best_bid": "0.994", "best_ask": "0.996"}], "timestamp": "1769384464733", "event_type": "price_change"}}
{"_local_timestamp": "2026-01-25T23:41:05.237576+00:00", "data": {"market": "0x83db787ed2cb00d225178e66bc6ae4d22e8029f19390d2b78ded5aed978eead6", "price_changes": [{"asset_id": "113401754986342384261044700457165882158632153698445535217371023842472815025478", "price": "0.986", "size": "1006.81", "side": "BUY", "hash": "0d81ec1bcf9bb0bc8a0fdc6a1f85b1c81fb35c7e", "best_bid": "0.99", "best_ask": "0.992"}, {"asset_id": "81906419701908530974011339985097627770048267181648886108185004759027261509242", "price": "0.014", "size": "1006.81", "side": "SELL", "hash": "e9e22d665515bb318eed2a16af00f75ea5e32ad1", "best_bid": "0.008", "best_ask": "0.01"}], "timestamp": "1769384465162", "event_type": "price_change"}}
{"_local_timestamp": "2026-01-25T23:41:05.626604+00:00", "data": {"market": "0x83db787ed2cb00d225178e66bc6ae4d22e8029f19390d2b78ded5aed978eead6", "price_changes": [{"asset_id": "113401754986342384261044700457165882158632153698445535217371023842472815025478", "price": "0.991", "size": "946.66", "side": "SELL", "hash": "75818ba745035ab4de6eb782716b1d4652298a80", "best_bid": "0.99", "best_ask": "0.991"}, {"asset_id": "81906419701908530974011339985097627770048267181648886108185004759027261509242", "price": "0.009", "size": "946.66", "side": "BUY", "hash": "034d41956434a1c7733ef477ab1a80f46b989f45", "best_bid": "0.009", "best_ask": "0.01"}], "timestamp": "1769384465553", "event_type": "price_change"}}
{"_local_timestamp": "2026-01-25T23:41:06.033392+00:00", "data": {"market": "0x754113d4aefc74db7c1266dc5f03e89e3f597deda15b19c19b3ca16cc85b8c33", "price_changes": [{"asset_id": "48827723684529991552849237252156781311984893775886188249280006578488168779709", "price": "0.995", "size": "1231.76", "side": "BUY", "hash": "3e941162a19cda59bd1173500508c7a0cd5704c9", "best_bid": "0.997", "best_ask": "1"}, {"asset_id": "16018186278713893766129270377649855044679233002578361062022208432086696077104", "price": "0.005", "size": "1231.76", "side": "SELL", "hash": "edcf35145ebd15182d3c588b025cc14bec628129", "best_bid": "0", "best_ask": "0.003"}], "timestamp": "1769384465942", "event_type": "price_change"}}
{"_local_timestamp": "2026-01-25T23:41:06.072305+00:00", "data": {"market": "0xbfcc34365517ac4978e76ecd8287e37fd92e68b22a3db9b31129c5c37669c293", "price_changes": [{"asset_id": "95417221270011105499568468828531867453865533932484364685389046548264041887861", "price": "0.011", "size": "22", "side": "SELL", "hash": "dbf21718fd04ff954fdd197b2bda48c256a3055d", "best_bid": "0.003", "best_ask": "0.006"}, {"asset_id": "101322769768415942646735830228475566436146317671120615766292718518675772773223", "price": "0.989", "size": "22", "side": "BUY", "hash": "17c3ef7dff8406594112fc6caa7a2980f138c61b", "best_bid": "0.994", "best_ask": "0.997"}], "timestamp": "1769384465942", "event_type": "price_change"}}
{"_local_timestamp": "2026-01-25T23:41:06.075379+00:00", "data": {"market": "0xbfcc34365517ac4978e76ecd8287e37fd92e68b22a3db9b31129c5c37669c293", "price_changes": [{"asset_id": "95417221270011105499568468828531867453865533932484364685389046548264041887861", "price": "0.004", "size": "0", "side": "BUY", "hash": "dbf21718fd04ff954fdd197b2bda48c256a3055d", "best_bid": "0.003", "best_ask": "0.006"}, {"asset_id": "101322769768415942646735830228475566436146317671120615766292718518675772773223", "price": "0.996", "size": "0", "side": "SELL", "hash": "17c3ef7dff8406594112fc6caa7a2980f138c61b", "best_bid": "0.994", "best_ask": "0.997"}], "timestamp": "1769384465942", "event_type": "price_change"}}
{"_local_timestamp": "2026-01-25T23:41:06.081188+00:00", "data": {"market": "0x83db787ed2cb00d225178e66bc6ae4d22e8029f19390d2b78ded5aed978eead6", "price_changes": [{"asset_id": "113401754986342384261044700457165882158632153698445535217371023842472815025478", "price": "0.986", "size": "100", "side": "BUY", "hash": "3a6b55ebe8f9056d256b6878f46a7506f39fe162", "best_bid": "0.99", "best_ask": "0.992"}, {"asset_id": "81906419701908530974011339985097627770048267181648886108185004759027261509242", "price": "0.014", "size": "100", "side": "SELL", "hash": "532b9196404c3e79d2c3a9e1ad0e117d60afb2bf", "best_bid": "0.008", "best_ask": "0.01"}], "timestamp": "1769384465942", "event_type": "price_change"}}
{"_local_timestamp": "2026-01-25T23:41:06.124143+00:00", "data": {"market": "0x83db787ed2cb00d225178e66bc6ae4d22e8029f19390d2b78ded5aed978eead6", "price_changes": [{"asset_id": "113401754986342384261044700457165882158632153698445535217371023842472815025478", "price": "0.991", "size": "0", "side": "SELL", "hash": "3a6b55ebe8f9056d256b6878f46a7506f39fe162", "best_bid": "0.99", "best_ask": "0.992"}, {"asset_id": "81906419701908530974011339985097627770048267181648886108185004759027261509242", "price": "0.009", "size": "0", "side": "BUY", "hash": "532b9196404c3e79d2c3a9e1ad0e117d60afb2bf", "best_bid": "0.008", "best_ask": "0.01"}], "timestamp": "1769384465942", "event_type": "price_change"}}
{"_local_timestamp": "2026-01-25T23:41:06.827880+00:00", "data": {"market": "0xbfcc34365517ac4978e76ecd8287e37fd92e68b22a3db9b31129c5c37669c293", "price_changes": [{"asset_id": "95417221270011105499568468828531867453865533932484364685389046548264041887861", "price": "0.002", "size": "1050", "side": "BUY", "hash": "39bf7a97e57ab7baeb4a11e18707bc920966065d", "best_bid": "0.003", "best_ask": "0.006"}, {"asset_id": "101322769768415942646735830228475566436146317671120615766292718518675772773223", "price": "0.998", "size": "1050", "side": "SELL", "hash": "e0f122a45279299f0dee649aab988c41fecd0496", "best_bid": "0.994", "best_ask": "0.997"}], "timestamp": "1769384466643", "event_type": "price_change"}}
{"_local_timestamp": "2026-01-25T23:41:08.141307+00:00", "data": {"market": "0x754113d4aefc74db7c1266dc5f03e89e3f597deda15b19c19b3ca16cc85b8c33", "price_changes": [{"asset_id": "48827723684529991552849237252156781311984893775886188249280006578488168779709", "price": "0.995", "size": "2138.57", "side": "BUY", "hash": "4916ef5aa74ab5b0fe18cfabfa0f0f88d9923de3", "best_bid": "0.997", "best_ask": "1"}, {"asset_id": "16018186278713893766129270377649855044679233002578361062022208432086696077104", "price": "0.005", "size": "2138.57", "side": "SELL", "hash": "a48142f256807f450b22a9941b488a75c6070e68", "best_bid": "0", "best_ask": "0.003"}], "timestamp": "1769384468073", "event_type": "price_change"}}
{"_local_timestamp": "2026-01-25T23:41:08.927517+00:00", "data": {"market": "0xbfcc34365517ac4978e76ecd8287e37fd92e68b22a3db9b31129c5c37669c293", "price_changes": [{"asset_id": "95417221270011105499568468828531867453865533932484364685389046548264041887861", "price": "0.004", "size": "98", "side": "BUY", "hash": "0f09e8cdf8063619b1a182c0e1baec8da8005c97", "best_bid": "0.004", "best_ask": "0.006"}, {"asset_id": "101322769768415942646735830228475566436146317671120615766292718518675772773223", "price": "0.996", "size": "98", "side": "SELL", "hash": "48e65d98cba7455517ca814a5dc1803630a2aa73", "best_bid": "0.994", "best_ask": "0.996"}], "timestamp": "1769384468861", "event_type": "price_change"}}
{"_local_timestamp": "2026-01-25T23:41:09.339163+00:00", "data": {"market": "0xbfcc34365517ac4978e76ecd8287e37fd92e68b22a3db9b31129c5c37669c293", "price_changes": [{"asset_id": "95417221270011105499568468828531867453865533932484364685389046548264041887861", "price": "0.011", "size": "2668.88", "side": "SELL", "hash": "259a9eb41aea71ff64b9fad7502fd452e4cc8a8d", "best_bid": "0.004", "best_ask": "0.006"}, {"asset_id": "101322769768415942646735830228475566436146317671120615766292718518675772773223", "price": "0.989", "size": "2668.88", "side": "BUY", "hash": "eecd435c461da1a14a05a6435595746da82487a7", "best_bid": "0.994", "best_ask": "0.996"}], "timestamp": "1769384469272", "event_type": "price_change"}}
{"_local_timestamp": "2026-01-25T23:41:09.798095+00:00", "data": {"market": "0x83db787ed2cb00d225178e66bc6ae4d22e8029f19390d2b78ded5aed978eead6", "price_changes": [{"asset_id": "113401754986342384261044700457165882158632153698445535217371023842472815025478", "price": "0.986", "size": "1006.81", "side": "BUY", "hash": "a08d692a8a0e67edadc96a92fb157b6d5eec884d", "best_bid": "0.99", "best_ask": "0.992"}, {"asset_id": "81906419701908530974011339985097627770048267181648886108185004759027261509242", "price": "0.014", "size": "1006.81", "side": "SELL", "hash": "18cab43170b96b417ef56d42830933bf772a95d3", "best_bid": "0.008", "best_ask": "0.01"}], "timestamp": "1769384469710", "event_type": "price_change"}}
{"_local_timestamp": "2026-01-25T23:41:10.204361+00:00", "data": {"market": "0x83db787ed2cb00d225178e66bc6ae4d22e8029f19390d2b78ded5aed978eead6", "price_changes": [{"asset_id": "113401754986342384261044700457165882158632153698445535217371023842472815025478", "price": "0.991", "size": "946.66", "side": "SELL", "hash": "9d787d98b8bcfe83d7f57ecdd6f33cbaf6ceb26a", "best_bid": "0.99", "best_ask": "0.991"}, {"asset_id": "81906419701908530974011339985097627770048267181648886108185004759027261509242", "price": "0.009", "size": "946.66", "side": "BUY", "hash": "b5c365cc26aa2d5850c061f94996d69a26eaf4f4", "best_bid": "0.009", "best_ask": "0.01"}], "timestamp": "1769384470121", "event_type": "price_change"}}
{"_local_timestamp": "2026-01-25T23:41:10.579982+00:00", "data": {"market": "0x754113d4aefc74db7c1266dc5f03e89e3f597deda15b19c19b3ca16cc85b8c33", "price_changes": [{"asset_id": "48827723684529991552849237252156781311984893775886188249280006578488168779709", "price": "0.995", "size": "1231.76", "side": "BUY", "hash": "46708591eae46aa5a41444cffb7f878147ce4a42", "best_bid": "0.997", "best_ask": "1"}, {"asset_id": "16018186278713893766129270377649855044679233002578361062022208432086696077104", "price": "0.005", "size": "1231.76", "side": "SELL", "hash": "1c458eab43336f737392530e488197fa2184ad6d", "best_bid": "0", "best_ask": "0.003"}], "timestamp": "1769384470510", "event_type": "price_change"}}
{"_local_timestamp": "2026-01-25T23:41:10.584024+00:00", "data": {"market": "0xbfcc34365517ac4978e76ecd8287e37fd92e68b22a3db9b31129c5c37669c293", "price_changes": [{"asset_id": "95417221270011105499568468828531867453865533932484364685389046548264041887861", "price": "0.004", "size": "0", "side": "BUY", "hash": "2cabbb04f4ac710dea064262c694c4ddc645010c", "best_bid": "0.003", "best_ask": "0.006"}, {"asset_id": "101322769768415942646735830228475566436146317671120615766292718518675772773223", "price": "0.996", "size": "0", "side": "SELL", "hash": "706a522c2484ad279ec723b2c62b80d0ad2eb67b", "best_bid": "0.994", "best_ask": "0.997"}], "timestamp": "1769384470510", "event_type": "price_change"}}
{"_local_timestamp": "2026-01-25T23:41:10.589724+00:00", "data": {"market": "0xbfcc34365517ac4978e76ecd8287e37fd92e68b22a3db9b31129c5c37669c293", "price_changes": [{"asset_id": "95417221270011105499568468828531867453865533932484364685389046548264041887861", "price": "0.011", "size": "22", "side": "SELL", "hash": "2cabbb04f4ac710dea064262c694c4ddc645010c", "best_bid": "0.003", "best_ask": "0.006"}, {"asset_id": "101322769768415942646735830228475566436146317671120615766292718518675772773223", "price": "0.989", "size": "22", "side": "BUY", "hash": "706a522c2484ad279ec723b2c62b80d0ad2eb67b", "best_bid": "0.994", "best_ask": "0.997"}], "timestamp": "1769384470510", "event_type": "price_change"}}
{"_local_timestamp": "2026-01-25T23:41:10.595592+00:00", "data": {"market": "0x83db787ed2cb00d225178e66bc6ae4d22e8029f19390d2b78ded5aed978eead6", "price_changes": [{"asset_id": "113401754986342384261044700457165882158632153698445535217371023842472815025478", "price": "0.991", "size": "0", "side": "SELL", "hash": "e75054cdccfbdd6074681a870718886663e6adf0", "best_bid": "0.99", "best_ask": "0.992"}, {"asset_id": "81906419701908530974011339985097627770048267181648886108185004759027261509242", "price": "0.009", "size": "0", "side": "BUY", "hash": "6061d57359267bfbb27df49c04273be2921f6545", "best_bid": "0.008", "best_ask": "0.01"}], "timestamp": "1769384470511", "event_type": "price_change"}}
{"_local_timestamp": "2026-01-25T23:41:10.601668+00:00", "data": {"market": "0x83db787ed2cb00d225178e66bc6ae4d22e8029f19390d2b78ded5aed978eead6", "price_changes": [{"asset_id": "113401754986342384261044700457165882158632153698445535217371023842472815025478", "price": "0.986", "size": "100", "side": "BUY", "hash": "e75054cdccfbdd6074681a870718886663e6adf0", "best_bid": "0.99", "best_ask": "0.992"}, {"asset_id": "81906419701908530974011339985097627770048267181648886108185004759027261509242", "price": "0.014", "size": "100", "side": "SELL", "hash": "6061d57359267bfbb27df49c04273be2921f6545", "best_bid": "0.008", "best_ask": "0.01"}], "timestamp": "1769384470511", "event_type": "price_change"}}
{"_local_timestamp": "2026-01-25T23:41:12.671055+00:00", "data": {"market": "0x754113d4aefc74db7c1266dc5f03e89e3f597deda15b19c19b3ca16cc85b8c33", "price_changes": [{"asset_id": "48827723684529991552849237252156781311984893775886188249280006578488168779709", "price": "0.995", "size": "2138.57", "side": "BUY", "hash": "065c6240838cc68633972c0b452b630e0a67b9b9", "best_bid": "0.997", "best_ask": "1"}, {"asset_id": "16018186278713893766129270377649855044679233002578361062022208432086696077104", "price": "0.005", "size": "2138.57", "side": "SELL", "hash": "a8e1bcade6e59c35710ccf7dd74f2bf9e143a5e3", "best_bid": "0", "best_ask": "0.003"}], "timestamp": "1769384472594", "event_type": "price_change"}}
{"_local_timestamp": "2026-01-25T23:41:13.586076+00:00", "data": {"market": "0xbfcc34365517ac4978e76ecd8287e37fd92e68b22a3db9b31129c5c37669c293", "price_changes": [{"asset_id": "95417221270011105499568468828531867453865533932484364685389046548264041887861", "price": "0.004", "size": "98", "side": "BUY", "hash": "9ca136a5d1920130ba493db5970ed1f166724900", "best_bid": "0.004", "best_ask": "0.006"}, {"asset_id": "101322769768415942646735830228475566436146317671120615766292718518675772773223", "price": "0.996", "size": "98", "side": "SELL", "hash": "a22621458ce44e55e52e38d4c2d73cd28fcc5238", "best_bid": "0.994", "best_ask": "0.996"}], "timestamp": "1769384473510", "event_type": "price_change"}}
{"_local_timestamp": "2026-01-25T23:41:13.612943+00:00", "data": {"market": "0x83db787ed2cb00d225178e66bc6ae4d22e8029f19390d2b78ded5aed978eead6", "price_changes": [{"asset_id": "81906419701908530974011339985097627770048267181648886108185004759027261509242", "price": "0.002", "size": "62582.44", "side": "BUY", "hash": "a164367b3fa3361c832041c968986d7fac303934", "best_bid": "0.008", "best_ask": "0.01"}, {"asset_id": "113401754986342384261044700457165882158632153698445535217371023842472815025478", "price": "0.998", "size": "62582.44", "side": "SELL", "hash": "f4898408d99fc6573615e0a4cdd1745f26f7386c", "best_bid": "0.99", "best_ask": "0.992"}], "timestamp": "1769384473536", "event_type": "price_change"}}
{"_local_timestamp": "2026-01-25T23:41:13.615997+00:00", "data": {"market": "0x754113d4aefc74db7c1266dc5f03e89e3f597deda15b19c19b3ca16cc85b8c33", "price_changes": [{"asset_id": "48827723684529991552849237252156781311984893775886188249280006578488168779709", "price": "0.992", "size": "0", "side": "BUY", "hash": "da95c98834eeddeca3f7d46e479a141582bde7ee", "best_bid": "0.997", "best_ask": "1"}, {"asset_id": "16018186278713893766129270377649855044679233002578361062022208432086696077104", "price": "0.008", "size": "0", "side": "SELL", "hash": "11a862f307e20ecd0c62d31d58aff0df12c932ff", "best_bid": "0", "best_ask": "0.003"}], "timestamp": "1769384473536", "event_type": "price_change"}}
{"_local_timestamp": "2026-01-25T23:41:13.728123+00:00", "data": {"market": "0x754113d4aefc74db7c1266dc5f03e89e3f597deda15b19c19b3ca16cc85b8c33", "price_changes": [{"asset_id": "48827723684529991552849237252156781311984893775886188249280006578488168779709", "price": "0.993", "size": "22", "side": "BUY", "hash": "c64a0840322379f079fd1ac9924351d336a1ed3f", "best_bid": "0.997", "best_ask": "1"}, {"asset_id": "16018186278713893766129270377649855044679233002578361062022208432086696077104", "price": "0.007", "size": "22", "side": "SELL", "hash": "d2a05168fac3246df2adbc078546aa9570ed66c7", "best_bid": "0", "best_ask": "0.003"}], "timestamp": "1769384473662", "event_type": "price_change"}}
{"_local_timestamp": "2026-01-25T23:41:13.733396+00:00", "data": {"market": "0x83db787ed2cb00d225178e66bc6ae4d22e8029f19390d2b78ded5aed978eead6", "price_changes": [{"asset_id": "81906419701908530974011339985097627770048267181648886108185004759027261509242", "price": "0.003", "size": "653.76", "side": "BUY", "hash": "f1d07c2b9fce4696b61c58861d2e30b2dca5a7d4", "best_bid": "0.008", "best_ask": "0.01"}, {"asset_id": "113401754986342384261044700457165882158632153698445535217371023842472815025478", "price": "0.997", "size": "653.76", "side": "SELL", "hash": "dba717ee7e8435e4de7553bee4d2f8f85880f1f4", "best_bid": "0.99", "best_ask": "0.992"}], "timestamp": "1769384473662", "event_type": "price_change"}}
{"_local_timestamp": "2026-01-25T23:41:14.001281+00:00", "data": {"market": "0xbfcc34365517ac4978e76ecd8287e37fd92e68b22a3db9b31129c5c37669c293", "price_changes": [{"asset_id": "95417221270011105499568468828531867453865533932484364685389046548264041887861", "price": "0.011", "size": "2668.88", "side": "SELL", "hash": "385799a91521db4c6c1ec7255a5cfbf98b727843", "best_bid": "0.004", "best_ask": "0.006"}, {"asset_id": "101322769768415942646735830228475566436146317671120615766292718518675772773223", "price": "0.989", "size": "2668.88", "side": "BUY", "hash": "b1e80510d5c0aa4c44832abb12004b2600328708", "best_bid": "0.994", "best_ask": "0.996"}], "timestamp": "1769384473927", "event_type": "price_change"}}
{"_local_timestamp": "2026-01-25T23:41:14.431455+00:00", "data": {"market": "0x83db787ed2cb00d225178e66bc6ae4d22e8029f19390d2b78ded5aed978eead6", "price_changes": [{"asset_id": "113401754986342384261044700457165882158632153698445535217371023842472815025478", "price": "0.986", "size": "1006.81", "side": "BUY", "hash": "09a7b037516bd857f33a3a65ea21183c2fc747ee", "best_bid": "0.99", "best_ask": "0.992"}, {"asset_id": "81906419701908530974011339985097627770048267181648886108185004759027261509242", "price": "0.014", "size": "1006.81", "side": "SELL", "hash": "70cf2b95a739399ff7a739d425e0586eb201210f", "best_bid": "0.008", "best_ask": "0.01"}], "timestamp": "1769384474351", "event_type": "price_change"}}
{"_local_timestamp": "2026-01-25T23:41:14.885838+00:00", "data": {"market": "0x83db787ed2cb00d225178e66bc6ae4d22e8029f19390d2b78ded5aed978eead6", "price_changes": [{"asset_id": "113401754986342384261044700457165882158632153698445535217371023842472815025478", "price": "0.991", "size": "946.66", "side": "SELL", "hash": "dec69976f16c7f67e0936aae2306b619b451065a", "best_bid": "0.99", "best_ask": "0.991"}, {"asset_id": "81906419701908530974011339985097627770048267181648886108185004759027261509242", "price": "0.009", "size": "946.66", "side": "BUY", "hash": "5b080c794dc232690e13fff92add970711a58148", "best_bid": "0.009", "best_ask": "0.01"}], "timestamp": "1769384474756", "event_type": "price_change"}}
{"_local_timestamp": "2026-01-25T23:41:15.214438+00:00", "data": {"market": "0x754113d4aefc74db7c1266dc5f03e89e3f597deda15b19c19b3ca16cc85b8c33", "price_changes": [{"asset_id": "48827723684529991552849237252156781311984893775886188249280006578488168779709", "price": "0.995", "size": "1231.76", "side": "BUY", "hash": "9de72a896e512c09fe90474f05f9ab280367d70d", "best_bid": "0.997", "best_ask": "1"}, {"asset_id": "16018186278713893766129270377649855044679233002578361062022208432086696077104", "price": "0.005", "size": "1231.76", "side": "SELL", "hash": "c349b3fa089b5814b6796eb3cf3cadd2424f88f1", "best_bid": "0", "best_ask": "0.003"}], "timestamp": "1769384475143", "event_type": "price_change"}}
{"_local_timestamp": "2026-01-25T23:41:15.218931+00:00", "data": {"market": "0xbfcc34365517ac4978e76ecd8287e37fd92e68b22a3db9b31129c5c37669c293", "price_changes": [{"asset_id": "95417221270011105499568468828531867453865533932484364685389046548264041887861", "price": "0.004", "size": "0", "side": "BUY", "hash": "8c639cc360ec409665b4179249ecf9e9c3c05872", "best_bid": "0.003", "best_ask": "0.006"}, {"asset_id": "101322769768415942646735830228475566436146317671120615766292718518675772773223", "price": "0.996", "size": "0", "side": "SELL", "hash": "7db55d4bea991d5b48d3ca4eb17d8cf1cac38d6c", "best_bid": "0.994", "best_ask": "0.997"}], "timestamp": "1769384475143", "event_type": "price_change"}}
{"_local_timestamp": "2026-01-25T23:41:15.223141+00:00", "data": {"market": "0xbfcc34365517ac4978e76ecd8287e37fd92e68b22a3db9b31129c5c37669c293", "price_changes": [{"asset_id": "95417221270011105499568468828531867453865533932484364685389046548264041887861", "price": "0.011", "size": "22", "side": "SELL", "hash": "8c639cc360ec409665b4179249ecf9e9c3c05872", "best_bid": "0.003", "best_ask": "0.006"}, {"asset_id": "101322769768415942646735830228475566436146317671120615766292718518675772773223", "price": "0.989", "size": "22", "side": "BUY", "hash": "7db55d4bea991d5b48d3ca4eb17d8cf1cac38d6c", "best_bid": "0.994", "best_ask": "0.997"}], "timestamp": "1769384475143", "event_type": "price_change"}}
{"_local_timestamp": "2026-01-25T23:41:15.227124+00:00", "data": {"market": "0x83db787ed2cb00d225178e66bc6ae4d22e8029f19390d2b78ded5aed978eead6", "price_changes": [{"asset_id": "113401754986342384261044700457165882158632153698445535217371023842472815025478", "price": "0.991", "size": "0", "side": "SELL", "hash": "345fe6028c6a125cc158c2f1a4560686bf845423", "best_bid": "0.99", "best_ask": "0.992"}, {"asset_id": "81906419701908530974011339985097627770048267181648886108185004759027261509242", "price": "0.009", "size": "0", "side": "BUY", "hash": "8a2e9d36951caadf2a5bd4a03b68e4883835ffeb", "best_bid": "0.008", "best_ask": "0.01"}], "timestamp": "1769384475143", "event_type": "price_change"}}
{"_local_timestamp": "2026-01-25T23:41:15.231965+00:00", "data": {"market": "0x83db787ed2cb00d225178e66bc6ae4d22e8029f19390d2b78ded5aed978eead6", "price_changes": [{"asset_id": "113401754986342384261044700457165882158632153698445535217371023842472815025478", "price": "0.986", "size": "100", "side": "BUY", "hash": "345fe6028c6a125cc158c2f1a4560686bf845423", "best_bid": "0.99", "best_ask": "0.992"}, {"asset_id": "81906419701908530974011339985097627770048267181648886108185004759027261509242", "price": "0.014", "size": "100", "side": "SELL", "hash": "8a2e9d36951caadf2a5bd4a03b68e4883835ffeb", "best_bid": "0.008", "best_ask": "0.01"}], "timestamp": "1769384475143", "event_type": "price_change"}}
{"_local_timestamp": "2026-01-25T23:41:15.240417+00:00", "data": {"market": "0x83db787ed2cb00d225178e66bc6ae4d22e8029f19390d2b78ded5aed978eead6", "price_changes": [{"asset_id": "81906419701908530974011339985097627770048267181648886108185004759027261509242", "price": "0.003", "size": "555.76", "side": "BUY", "hash": "6a6c77c67f175bf5383c1412322f4cfa61f5d4f0", "best_bid": "0.008", "best_ask": "0.01"}, {"asset_id": "113401754986342384261044700457165882158632153698445535217371023842472815025478", "price": "0.997", "size": "555.76", "side": "SELL", "hash": "a485c91342c903432637ffa82d8293dc3c633c84", "best_bid": "0.99", "best_ask": "0.992"}], "timestamp": "1769384475169", "event_type": "price_change"}}
{"_local_timestamp": "2026-01-25T23:41:15.246266+00:00", "data": {"market": "0x754113d4aefc74db7c1266dc5f03e89e3f597deda15b19c19b3ca16cc85b8c33", "price_changes": [{"asset_id": "48827723684529991552849237252156781311984893775886188249280006578488168779709", "price": "0.993", "size": "0", "side": "BUY", "hash": "a71f20a61573e30ee6abcfd4d753d254f3fa6356", "best_bid": "0.997", "best_ask": "1"}, {"asset_id": "16018186278713893766129270377649855044679233002578361062022208432086696077104", "price": "0.007", "size": "0", "side": "SELL", "hash": "9f03ef924d239984af0807441f1d12d730c41e53", "best_bid": "0", "best_ask": "0.003"}], "timestamp": "1769384475170", "event_type": "price_change"}}
{"_local_timestamp": "2026-01-25T23:41:15.364247+00:00", "data": {"market": "0x754113d4aefc74db7c1266dc5f03e89e3f597deda15b19c19b3ca16cc85b8c33", "price_changes": [{"asset_id": "48827723684529991552849237252156781311984893775886188249280006578488168779709", "price": "0.992", "size": "22", "side": "BUY", "hash": "10529bb2f167c93f26aeeda955821d2eda678f3b", "best_bid": "0.997", "best_ask": "1"}, {"asset_id": "16018186278713893766129270377649855044679233002578361062022208432086696077104", "price": "0.008", "size": "22", "side": "SELL", "hash": "8eab0022149019f643de15d0cccacc28b03b3ef7", "best_bid": "0", "best_ask": "0.003"}], "timestamp": "1769384475295", "event_type": "price_change"}}
{"_local_timestamp": "2026-01-25T23:41:15.371532+00:00", "data": {"market": "0x83db787ed2cb00d225178e66bc6ae4d22e8029f19390d2b78ded5aed978eead6", "price_changes": [{"asset_id": "81906419701908530974011339985097627770048267181648886108185004759027261509242", "price": "0.002", "size": "62658.44", "side": "BUY", "hash": "ad6975f657fb823dc312b9dbdaa501a01c929756", "best_bid": "0.008", "best_ask": "0.01"}, {"asset_id": "113401754986342384261044700457165882158632153698445535217371023842472815025478", "price": "0.998", "size": "62658.44", "side": "SELL", "hash": "80b09a2d93d55e188834b96c7d4920fad7e0547f", "best_bid": "0.99", "best_ask": "0.992"}], "timestamp": "1769384475299", "event_type": "price_change"}}
{"_local_timestamp": "2026-01-25T23:41:17.285606+00:00", "data": {"market": "0x754113d4aefc74db7c1266dc5f03e89e3f597deda15b19c19b3ca16cc85b8c33", "price_changes": [{"asset_id": "48827723684529991552849237252156781311984893775886188249280006578488168779709", "price": "0.995", "size": "2138.57", "side": "BUY", "hash": "c6ece77ac7367fcce757c79ffdbc42b5d834680c", "best_bid": "0.997", "best_ask": "1"}, {"asset_id": "16018186278713893766129270377649855044679233002578361062022208432086696077104", "price": "0.005", "size": "2138.57", "side": "SELL", "hash": "dd909c6fc97125805c506b743fcc092fad9c8775", "best_bid": "0", "best_ask": "0.003"}], "timestamp": "1769384477218", "event_type": "price_change"}}
{"_local_timestamp": "2026-01-25T23:41:18.157936+00:00", "data": {"market": "0xbfcc34365517ac4978e76ecd8287e37fd92e68b22a3db9b31129c5c37669c293", "price_changes": [{"asset_id": "95417221270011105499568468828531867453865533932484364685389046548264041887861", "price": "0.004", "size": "98", "side": "BUY", "hash": "28890ff0c3f67885cb31395d6924d907fe1e3570", "best_bid": "0.004", "best_ask": "0.006"}, {"asset_id": "101322769768415942646735830228475566436146317671120615766292718518675772773223", "price": "0.996", "size": "98", "side": "SELL", "hash": "1255c98afe8cd563be48f85788cbb85ce250e178", "best_bid": "0.994", "best_ask": "0.996"}], "timestamp": "1769384478048", "event_type": "price_change"}}
{"_local_timestamp": "2026-01-25T23:41:18.549309+00:00", "data": {"market": "0xbfcc34365517ac4978e76ecd8287e37fd92e68b22a3db9b31129c5c37669c293", "price_changes": [{"asset_id": "95417221270011105499568468828531867453865533932484364685389046548264041887861", "price": "0.011", "size": "2668.88", "side": "SELL", "hash": "188e8366d1875a5991e38a15c6ca0233e83c9ad2", "best_bid": "0.004", "best_ask": "0.006"}, {"asset_id": "101322769768415942646735830228475566436146317671120615766292718518675772773223", "price": "0.989", "size": "2668.88", "side": "BUY", "hash": "db83ae5ff0db1cc8fed3b9433f4f603f9a4e4aff", "best_bid": "0.994", "best_ask": "0.996"}], "timestamp": "1769384478459", "event_type": "price_change"}}
{"_local_timestamp": "2026-01-25T23:41:18.926172+00:00", "data": {"market": "0x83db787ed2cb00d225178e66bc6ae4d22e8029f19390d2b78ded5aed978eead6", "price_changes": [{"asset_id": "113401754986342384261044700457165882158632153698445535217371023842472815025478", "price": "0.986", "size": "1006.81", "side": "BUY", "hash": "e68cb0978ff18a4be5251befcb28cade66db28d9", "best_bid": "0.99", "best_ask": "0.992"}, {"asset_id": "81906419701908530974011339985097627770048267181648886108185004759027261509242", "price": "0.014", "size": "1006.81", "side": "SELL", "hash": "ba4b5b9e2df194ec0bd8313b133937fe634e0c00", "best_bid": "0.008", "best_ask": "0.01"}], "timestamp": "1769384478852", "event_type": "price_change"}}
{"_local_timestamp": "2026-01-25T23:41:19.352621+00:00", "data": {"market": "0x83db787ed2cb00d225178e66bc6ae4d22e8029f19390d2b78ded5aed978eead6", "price_changes": [{"asset_id": "113401754986342384261044700457165882158632153698445535217371023842472815025478", "price": "0.991", "size": "946.66", "side": "SELL", "hash": "4f73413b1a332cd0250d3f88723579e60e1c8a5f", "best_bid": "0.99", "best_ask": "0.991"}, {"asset_id": "81906419701908530974011339985097627770048267181648886108185004759027261509242", "price": "0.009", "size": "946.66", "side": "BUY", "hash": "adcd709193585304fa44f3f2d001c270c4d1c9c7", "best_bid": "0.009", "best_ask": "0.01"}], "timestamp": "1769384479274", "event_type": "price_change"}}
{"_local_timestamp": "2026-01-25T23:41:19.852984+00:00", "data": {"market": "0x754113d4aefc74db7c1266dc5f03e89e3f597deda15b19c19b3ca16cc85b8c33", "price_changes": [{"asset_id": "48827723684529991552849237252156781311984893775886188249280006578488168779709", "price": "0.995", "size": "1231.76", "side": "BUY", "hash": "5303641c32b4cf2da9b6de4203935628df0d2601", "best_bid": "0.997", "best_ask": "1"}, {"asset_id": "16018186278713893766129270377649855044679233002578361062022208432086696077104", "price": "0.005", "size": "1231.76", "side": "SELL", "hash": "b5ffc2cb9c736aac79766d237ca62293b0667def", "best_bid": "0", "best_ask": "0.003"}], "timestamp": "1769384479769", "event_type": "price_change"}}
{"_local_timestamp": "2026-01-25T23:41:19.859020+00:00", "data": {"market": "0xbfcc34365517ac4978e76ecd8287e37fd92e68b22a3db9b31129c5c37669c293", "price_changes": [{"asset_id": "95417221270011105499568468828531867453865533932484364685389046548264041887861", "price": "0.011", "size": "22", "side": "SELL", "hash": "3d7304c6fd04fe49cb1381ee66027ea1ec01baca", "best_bid": "0.003", "best_ask": "0.006"}, {"asset_id": "101322769768415942646735830228475566436146317671120615766292718518675772773223", "price": "0.989", "size": "22", "side": "BUY", "hash": "d9bb23ff838f62c0eab22f83d0050a6c47352ed6", "best_bid": "0.994", "best_ask": "0.997"}], "timestamp": "1769384479769", "event_type": "price_change"}}
{"_local_timestamp": "2026-01-25T23:41:19.865910+00:00", "data": {"market": "0x83db787ed2cb00d225178e66bc6ae4d22e8029f19390d2b78ded5aed978eead6", "price_changes": [{"asset_id": "113401754986342384261044700457165882158632153698445535217371023842472815025478", "price": "0.986", "size": "100", "side": "BUY", "hash": "2e2dc62dc142b9ff739febcc5d79d0c47a32e44b", "best_bid": "0.99", "best_ask": "0.992"}, {"asset_id": "81906419701908530974011339985097627770048267181648886108185004759027261509242", "price": "0.014", "size": "100", "side": "SELL", "hash": "01e860bd2606da920a0e1d95628d7c613936eed3", "best_bid": "0.008", "best_ask": "0.01"}], "timestamp": "1769384479769", "event_type": "price_change"}}
{"_local_timestamp": "2026-01-25T23:41:19.870449+00:00", "data": {"market": "0xbfcc34365517ac4978e76ecd8287e37fd92e68b22a3db9b31129c5c37669c293", "price_changes": [{"asset_id": "95417221270011105499568468828531867453865533932484364685389046548264041887861", "price": "0.004", "size": "0", "side": "BUY", "hash": "3d7304c6fd04fe49cb1381ee66027ea1ec01baca", "best_bid": "0.003", "best_ask": "0.006"}, {"asset_id": "101322769768415942646735830228475566436146317671120615766292718518675772773223", "price": "0.996", "size": "0", "side": "SELL", "hash": "d9bb23ff838f62c0eab22f83d0050a6c47352ed6", "best_bid": "0.994", "best_ask": "0.997"}], "timestamp": "1769384479769", "event_type": "price_change"}}
{"_local_timestamp": "2026-01-25T23:41:19.891365+00:00", "data": {"market": "0x83db787ed2cb00d225178e66bc6ae4d22e8029f19390d2b78ded5aed978eead6", "price_changes": [{"asset_id": "113401754986342384261044700457165882158632153698445535217371023842472815025478", "price": "0.991", "size": "0", "side": "SELL", "hash": "2e2dc62dc142b9ff739febcc5d79d0c47a32e44b", "best_bid": "0.99", "best_ask": "0.992"}, {"asset_id": "81906419701908530974011339985097627770048267181648886108185004759027261509242", "price": "0.009", "size": "0", "side": "BUY", "hash": "01e860bd2606da920a0e1d95628d7c613936eed3", "best_bid": "0.008", "best_ask": "0.01"}], "timestamp": "1769384479769", "event_type": "price_change"}}
{"_local_timestamp": "2026-01-25T23:41:21.977807+00:00", "data": {"market": "0x754113d4aefc74db7c1266dc5f03e89e3f597deda15b19c19b3ca16cc85b8c33", "price_changes": [{"asset_id": "48827723684529991552849237252156781311984893775886188249280006578488168779709", "price": "0.995", "size": "2138.57", "side": "BUY", "hash": "c37490165b4a3f0b0080781ba342bdb7c5958c5d", "best_bid": "0.997", "best_ask": "1"}, {"asset_id": "16018186278713893766129270377649855044679233002578361062022208432086696077104", "price": "0.005", "size": "2138.57", "side": "SELL", "hash": "47389bf7c91619a2c07f33cbaf6093676ce73311", "best_bid": "0", "best_ask": "0.003"}], "timestamp": "1769384481900", "event_type": "price_change"}}
{"_local_timestamp": "2026-01-25T23:41:22.899713+00:00", "data": {"market": "0xbfcc34365517ac4978e76ecd8287e37fd92e68b22a3db9b31129c5c37669c293", "price_changes": [{"asset_id": "95417221270011105499568468828531867453865533932484364685389046548264041887861", "price": "0.004", "size": "98", "side": "BUY", "hash": "1b119a1d349e4583bec910abf781cfe3a561cc26", "best_bid": "0.004", "best_ask": "0.006"}, {"asset_id": "101322769768415942646735830228475566436146317671120615766292718518675772773223", "price": "0.996", "size": "98", "side": "SELL", "hash": "a63ec567089b2f50b813f07b049f403d750cd629", "best_bid": "0.994", "best_ask": "0.996"}], "timestamp": "1769384482825", "event_type": "price_change"}}
{"_local_timestamp": "2026-01-25T23:41:23.297522+00:00", "data": {"market": "0xbfcc34365517ac4978e76ecd8287e37fd92e68b22a3db9b31129c5c37669c293", "price_changes": [{"asset_id": "95417221270011105499568468828531867453865533932484364685389046548264041887861", "price": "0.011", "size": "2668.88", "side": "SELL", "hash": "34b9ad4b2138d12e81318782d136c53e833b3dcb", "best_bid": "0.004", "best_ask": "0.006"}, {"asset_id": "101322769768415942646735830228475566436146317671120615766292718518675772773223", "price": "0.989", "size": "2668.88", "side": "BUY", "hash": "b640dbbccad1d395e1f1cd392f2b6b50b5faa593", "best_bid": "0.994", "best_ask": "0.996"}], "timestamp": "1769384483218", "event_type": "price_change"}}
{"_local_timestamp": "2026-01-25T23:41:23.720021+00:00", "data": {"market": "0x83db787ed2cb00d225178e66bc6ae4d22e8029f19390d2b78ded5aed978eead6", "price_changes": [{"asset_id": "113401754986342384261044700457165882158632153698445535217371023842472815025478", "price": "0.986", "size": "1006.81", "side": "BUY", "hash": "c455a8d5021163a4e785f5a5eaf3d548ab8e9eee", "best_bid": "0.99", "best_ask": "0.992"}, {"asset_id": "81906419701908530974011339985097627770048267181648886108185004759027261509242", "price": "0.014", "size": "1006.81", "side": "SELL", "hash": "3768683b44db1583b71e1cca947fca562c735c19", "best_bid": "0.008", "best_ask": "0.01"}], "timestamp": "1769384483648", "event_type": "price_change"}}
{"_local_timestamp": "2026-01-25T23:41:24.143444+00:00", "data": {"market": "0x83db787ed2cb00d225178e66bc6ae4d22e8029f19390d2b78ded5aed978eead6", "price_changes": [{"asset_id": "113401754986342384261044700457165882158632153698445535217371023842472815025478", "price": "0.991", "size": "946.66", "side": "SELL", "hash": "9616e7b0ba26d4133135d1a755bd2606513c3c0f", "best_bid": "0.99", "best_ask": "0.991"}, {"asset_id": "81906419701908530974011339985097627770048267181648886108185004759027261509242", "price": "0.009", "size": "946.66", "side": "BUY", "hash": "679b208ffc20d9266290bd149a5166aa25870821", "best_bid": "0.009", "best_ask": "0.01"}], "timestamp": "1769384484071", "event_type": "price_change"}}
{"_local_timestamp": "2026-01-25T23:41:24.589174+00:00", "data": {"market": "0x754113d4aefc74db7c1266dc5f03e89e3f597deda15b19c19b3ca16cc85b8c33", "price_changes": [{"asset_id": "48827723684529991552849237252156781311984893775886188249280006578488168779709", "price": "0.995", "size": "1231.76", "side": "BUY", "hash": "dba471484debef64319c174b64f07ecb4b2df7f4", "best_bid": "0.997", "best_ask": "1"}, {"asset_id": "16018186278713893766129270377649855044679233002578361062022208432086696077104", "price": "0.005", "size": "1231.76", "side": "SELL", "hash": "ed441f7e004a2132eee866ced1cf85d1012545df", "best_bid": "0", "best_ask": "0.003"}], "timestamp": "1769384484512", "event_type": "price_change"}}
{"_local_timestamp": "2026-01-25T23:41:24.592088+00:00", "data": {"market": "0xbfcc34365517ac4978e76ecd8287e37fd92e68b22a3db9b31129c5c37669c293", "price_changes": [{"asset_id": "95417221270011105499568468828531867453865533932484364685389046548264041887861", "price": "0.004", "size": "0", "side": "BUY", "hash": "2694a8a5f13c49459a5e9a85b1a7ec14cb605c7a", "best_bid": "0.003", "best_ask": "0.006"}, {"asset_id": "101322769768415942646735830228475566436146317671120615766292718518675772773223", "price": "0.996", "size": "0", "side": "SELL", "hash": "e38549d7d3932e672184be7e59e010d789476ffb", "best_bid": "0.994", "best_ask": "0.997"}], "timestamp": "1769384484512", "event_type": "price_change"}}
{"_local_timestamp": "2026-01-25T23:41:24.594916+00:00", "data": {"market": "0xbfcc34365517ac4978e76ecd8287e37fd92e68b22a3db9b31129c5c37669c293", "price_changes": [{"asset_id": "95417221270011105499568468828531867453865533932484364685389046548264041887861", "price": "0.011", "size": "22", "side": "SELL", "hash": "2694a8a5f13c49459a5e9a85b1a7ec14cb605c7a", "best_bid": "0.003", "best_ask": "0.006"}, {"asset_id": "101322769768415942646735830228475566436146317671120615766292718518675772773223", "price": "0.989", "size": "22", "side": "BUY", "hash": "e38549d7d3932e672184be7e59e010d789476ffb", "best_bid": "0.994", "best_ask": "0.997"}], "timestamp": "1769384484512", "event_type": "price_change"}}
{"_local_timestamp": "2026-01-25T23:41:24.597793+00:00", "data": {"market": "0x83db787ed2cb00d225178e66bc6ae4d22e8029f19390d2b78ded5aed978eead6", "price_changes": [{"asset_id": "113401754986342384261044700457165882158632153698445535217371023842472815025478", "price": "0.991", "size": "0", "side": "SELL", "hash": "884f0cbd627cfca92c41bbab02a4f617b3d29ea0", "best_bid": "0.99", "best_ask": "0.992"}, {"asset_id": "81906419701908530974011339985097627770048267181648886108185004759027261509242", "price": "0.009", "size": "0", "side": "BUY", "hash": "c2ac46dd1a4ff3910c26b74f146abc45578dba77", "best_bid": "0.008", "best_ask": "0.01"}], "timestamp": "1769384484512", "event_type": "price_change"}}
{"_local_timestamp": "2026-01-25T23:41:24.600695+00:00", "data": {"market": "0x83db787ed2cb00d225178e66bc6ae4d22e8029f19390d2b78ded5aed978eead6", "price_changes": [{"asset_id": "113401754986342384261044700457165882158632153698445535217371023842472815025478", "price": "0.986", "size": "100", "side": "BUY", "hash": "884f0cbd627cfca92c41bbab02a4f617b3d29ea0", "best_bid": "0.99", "best_ask": "0.992"}, {"asset_id": "81906419701908530974011339985097627770048267181648886108185004759027261509242", "price": "0.014", "size": "100", "side": "SELL", "hash": "c2ac46dd1a4ff3910c26b74f146abc45578dba77", "best_bid": "0.008", "best_ask": "0.01"}], "timestamp": "1769384484512", "event_type": "price_change"}}
{"_local_timestamp": "2026-01-25T23:41:26.742974+00:00", "data": {"market": "0x754113d4aefc74db7c1266dc5f03e89e3f597deda15b19c19b3ca16cc85b8c33", "price_changes": [{"asset_id": "48827723684529991552849237252156781311984893775886188249280006578488168779709", "price": "0.995", "size": "2138.57", "side": "BUY", "hash": "a3df1c93fe9a188cedfb24e2b4bb69bb5e603b46", "best_bid": "0.997", "best_ask": "1"}, {"asset_id": "16018186278713893766129270377649855044679233002578361062022208432086696077104", "price": "0.005", "size": "2138.57", "side": "SELL", "hash": "61a6ebce6a31c488ab12f3413836d30509b9253d", "best_bid": "0", "best_ask": "0.003"}], "timestamp": "1769384486676", "event_type": "price_change"}}
{"_local_timestamp": "2026-01-25T23:41:27.522846+00:00", "data": {"market": "0xbfcc34365517ac4978e76ecd8287e37fd92e68b22a3db9b31129c5c37669c293", "price_changes": [{"asset_id": "95417221270011105499568468828531867453865533932484364685389046548264041887861", "price": "0.004", "size": "98", "side": "BUY", "hash": "1376292137eed7d2856d010659f169938eef909c", "best_bid": "0.004", "best_ask": "0.006"}, {"asset_id": "101322769768415942646735830228475566436146317671120615766292718518675772773223", "price": "0.996", "size": "98", "side": "SELL", "hash": "8fa1cf367cbafdaf463caa7c1e30943febaf1f03", "best_bid": "0.994", "best_ask": "0.996"}], "timestamp": "1769384487454", "event_type": "price_change"}}
{"_local_timestamp": "2026-01-25T23:41:27.555302+00:00", "data": {"market": "0x83db787ed2cb00d225178e66bc6ae4d22e8029f19390d2b78ded5aed978eead6", "price_changes": [{"asset_id": "81906419701908530974011339985097627770048267181648886108185004759027261509242", "price": "0.002", "size": "62582.44", "side": "BUY", "hash": "b74a40a7357247d0102924321261bc55244cec1e", "best_bid": "0.008", "best_ask": "0.01"}, {"asset_id": "113401754986342384261044700457165882158632153698445535217371023842472815025478", "price": "0.998", "size": "62582.44", "side": "SELL", "hash": "9d8b2946c50208d6614c5a956d477f9019494aab", "best_bid": "0.99", "best_ask": "0.992"}], "timestamp": "1769384487480", "event_type": "price_change"}}
{"_local_timestamp": "2026-01-25T23:41:27.558525+00:00", "data": {"market": "0x754113d4aefc74db7c1266dc5f03e89e3f597deda15b19c19b3ca16cc85b8c33", "price_changes": [{"asset_id": "48827723684529991552849237252156781311984893775886188249280006578488168779709", "price": "0.992", "size": "0", "side": "BUY", "hash": "8c6b56aa1d23b02157d35146218f9da5e154a4db", "best_bid": "0.997", "best_ask": "1"}, {"asset_id": "16018186278713893766129270377649855044679233002578361062022208432086696077104", "price": "0.008", "size": "0", "side": "SELL", "hash": "43c52901f71a19019b2d0c8426f63418a44d1a30", "best_bid": "0", "best_ask": "0.003"}], "timestamp": "1769384487483", "event_type": "price_change"}}
{"_local_timestamp": "2026-01-25T23:41:27.680391+00:00", "data": {"market": "0x83db787ed2cb00d225178e66bc6ae4d22e8029f19390d2b78ded5aed978eead6", "price_changes": [{"asset_id": "81906419701908530974011339985097627770048267181648886108185004759027261509242", "price": "0.003", "size": "653.76", "side": "BUY", "hash": "9d9d8378ca17a5ce7ed9a9392d7c96edde7a0846", "best_bid": "0.008", "best_ask": "0.01"}, {"asset_id": "113401754986342384261044700457165882158632153698445535217371023842472815025478", "price": "0.997", "size": "653.76", "side": "SELL", "hash": "58b3d9a7e0fb6e774f8323bc75a28dd0877352aa", "best_bid": "0.99", "best_ask": "0.992"}], "timestamp": "1769384487606", "event_type": "price_change"}}
{"_local_timestamp": "2026-01-25T23:41:27.685010+00:00", "data": {"market": "0x754113d4aefc74db7c1266dc5f03e89e3f597deda15b19c19b3ca16cc85b8c33", "price_changes": [{"asset_id": "48827723684529991552849237252156781311984893775886188249280006578488168779709", "price": "0.993", "size": "22", "side": "BUY", "hash": "27de7c21b2f0e0b3d658776fd9a0a5de1226a807", "best_bid": "0.997", "best_ask": "1"}, {"asset_id": "16018186278713893766129270377649855044679233002578361062022208432086696077104", "price": "0.007", "size": "22", "side": "SELL", "hash": "669dcb069c691e9b174d91e1ba79b907f85596e0", "best_bid": "0", "best_ask": "0.003"}], "timestamp": "1769384487617", "event_type": "price_change"}}
{"_local_timestamp": "2026-01-25T23:41:27.940789+00:00", "data": {"market": "0xbfcc34365517ac4978e76ecd8287e37fd92e68b22a3db9b31129c5c37669c293", "price_changes": [{"asset_id": "95417221270011105499568468828531867453865533932484364685389046548264041887861", "price": "0.011", "size": "2668.88", "side": "SELL", "hash": "5ebb9acedda5953fbe4c5e5b73ee589a0464f9e7", "best_bid": "0.004", "best_ask": "0.006"}, {"asset_id": "101322769768415942646735830228475566436146317671120615766292718518675772773223", "price": "0.989", "size": "2668.88", "side": "BUY", "hash": "87a67a253f31ca1df2a67f1f6feacf5e1b59984b", "best_bid": "0.994", "best_ask": "0.996"}], "timestamp": "1769384487867", "event_type": "price_change"}}
{"_local_timestamp": "2026-01-25T23:41:28.338678+00:00", "data": {"market": "0x83db787ed2cb00d225178e66bc6ae4d22e8029f19390d2b78ded5aed978eead6", "price_changes": [{"asset_id": "113401754986342384261044700457165882158632153698445535217371023842472815025478", "price": "0.986", "size": "1006.81", "side": "BUY", "hash": "bdb31846bb3139a1cd76e038fe40674b70e27236", "best_bid": "0.99", "best_ask": "0.992"}, {"asset_id": "81906419701908530974011339985097627770048267181648886108185004759027261509242", "price": "0.014", "size": "1006.81", "side": "SELL", "hash": "03cf5bc1b8051cab735f7354217eb1dca6b2f750", "best_bid": "0.008", "best_ask": "0.01"}], "timestamp": "1769384488268", "event_type": "price_change"}}
{"_local_timestamp": "2026-01-25T23:41:28.726764+00:00", "data": {"market": "0x83db787ed2cb00d225178e66bc6ae4d22e8029f19390d2b78ded5aed978eead6", "price_changes": [{"asset_id": "113401754986342384261044700457165882158632153698445535217371023842472815025478", "price": "0.991", "size": "946.66", "side": "SELL", "hash": "09506a61ad32336832cc7150f4619d0c348fadc9", "best_bid": "0.99", "best_ask": "0.991"}, {"asset_id": "81906419701908530974011339985097627770048267181648886108185004759027261509242", "price": "0.009", "size": "946.66", "side": "BUY", "hash": "377fd9ed44e07c6d0e690a236f1d8dfe76ced297", "best_bid": "0.009", "best_ask": "0.01"}], "timestamp": "1769384488653", "event_type": "price_change"}}
{"_local_timestamp": "2026-01-25T23:41:29.121842+00:00", "data": {"market": "0x754113d4aefc74db7c1266dc5f03e89e3f597deda15b19c19b3ca16cc85b8c33", "price_changes": [{"asset_id": "48827723684529991552849237252156781311984893775886188249280006578488168779709", "price": "0.995", "size": "1231.76", "side": "BUY", "hash": "1c61c736d38ae4c204524d33310aacbdcf28b35c", "best_bid": "0.997", "best_ask": "1"}, {"asset_id": "16018186278713893766129270377649855044679233002578361062022208432086696077104", "price": "0.005", "size": "1231.76", "side": "SELL", "hash": "b38db91cf818b9cee4d28260d4e1da4a0515d401", "best_bid": "0", "best_ask": "0.003"}], "timestamp": "1769384489042", "event_type": "price_change"}}
{"_local_timestamp": "2026-01-25T23:41:29.126866+00:00", "data": {"market": "0xbfcc34365517ac4978e76ecd8287e37fd92e68b22a3db9b31129c5c37669c293", "price_changes": [{"asset_id": "95417221270011105499568468828531867453865533932484364685389046548264041887861", "price": "0.004", "size": "0", "side": "BUY", "hash": "84d6b1d1fb9883d60ab95854fb2284630b64588e", "best_bid": "0.003", "best_ask": "0.006"}, {"asset_id": "101322769768415942646735830228475566436146317671120615766292718518675772773223", "price": "0.996", "size": "0", "side": "SELL", "hash": "38873e1a032e7bf25cccc172bf15c308fc963afe", "best_bid": "0.994", "best_ask": "0.997"}], "timestamp": "1769384489041", "event_type": "price_change"}}
{"_local_timestamp": "2026-01-25T23:41:29.130683+00:00", "data": {"market": "0xbfcc34365517ac4978e76ecd8287e37fd92e68b22a3db9b31129c5c37669c293", "price_changes": [{"asset_id": "95417221270011105499568468828531867453865533932484364685389046548264041887861", "price": "0.011", "size": "22", "side": "SELL", "hash": "84d6b1d1fb9883d60ab95854fb2284630b64588e", "best_bid": "0.003", "best_ask": "0.006"}, {"asset_id": "101322769768415942646735830228475566436146317671120615766292718518675772773223", "price": "0.989", "size": "22", "side": "BUY", "hash": "38873e1a032e7bf25cccc172bf15c308fc963afe", "best_bid": "0.994", "best_ask": "0.997"}], "timestamp": "1769384489041", "event_type": "price_change"}}
{"_local_timestamp": "2026-01-25T23:41:29.138495+00:00", "data": {"market": "0x83db787ed2cb00d225178e66bc6ae4d22e8029f19390d2b78ded5aed978eead6", "price_changes": [{"asset_id": "113401754986342384261044700457165882158632153698445535217371023842472815025478", "price": "0.991", "size": "0", "side": "SELL", "hash": "f92b6769138e4755daf9caf2a278bab4c6473873", "best_bid": "0.99", "best_ask": "0.992"}, {"asset_id": "81906419701908530974011339985097627770048267181648886108185004759027261509242", "price": "0.009", "size": "0", "side": "BUY", "hash": "d72eee85453e46c03d27f76250b30aa79d6d0a98", "best_bid": "0.008", "best_ask": "0.01"}], "timestamp": "1769384489042", "event_type": "price_change"}}
{"_local_timestamp": "2026-01-25T23:41:29.149697+00:00", "data": {"market": "0x83db787ed2cb00d225178e66bc6ae4d22e8029f19390d2b78ded5aed978eead6", "price_changes": [{"asset_id": "113401754986342384261044700457165882158632153698445535217371023842472815025478", "price": "0.986", "size": "100", "side": "BUY", "hash": "f92b6769138e4755daf9caf2a278bab4c6473873", "best_bid": "0.99", "best_ask": "0.992"}, {"asset_id": "81906419701908530974011339985097627770048267181648886108185004759027261509242", "price": "0.014", "size": "100", "side": "SELL", "hash": "d72eee85453e46c03d27f76250b30aa79d6d0a98", "best_bid": "0.008", "best_ask": "0.01"}], "timestamp": "1769384489042", "event_type": "price_change"}}
{"_local_timestamp": "2026-01-25T23:41:29.157215+00:00", "data": {"market": "0x754113d4aefc74db7c1266dc5f03e89e3f597deda15b19c19b3ca16cc85b8c33", "price_changes": [{"asset_id": "48827723684529991552849237252156781311984893775886188249280006578488168779709", "price": "0.993", "size": "0", "side": "BUY", "hash": "42dae73aed6043be76343ccb972f7aa46aa2c9a6", "best_bid": "0.997", "best_ask": "1"}, {"asset_id": "16018186278713893766129270377649855044679233002578361062022208432086696077104", "price": "0.007", "size": "0", "side": "SELL", "hash": "1487e6fd982faa8b6acfbdad7450c3016e89e647", "best_bid": "0", "best_ask": "0.003"}], "timestamp": "1769384489067", "event_type": "price_change"}}
{"_local_timestamp": "2026-01-25T23:41:29.162052+00:00", "data": {"market": "0x83db787ed2cb00d225178e66bc6ae4d22e8029f19390d2b78ded5aed978eead6", "price_changes": [{"asset_id": "81906419701908530974011339985097627770048267181648886108185004759027261509242", "price": "0.003", "size": "555.76", "side": "BUY", "hash": "2654a9d736cee56ce7a6565e410e544ed346fc9a", "best_bid": "0.008", "best_ask": "0.01"}, {"asset_id": "113401754986342384261044700457165882158632153698445535217371023842472815025478", "price": "0.997", "size": "555.76", "side": "SELL", "hash": "d2f0557c9bcfa31659b7ed9e43d7535056b39d7f", "best_bid": "0.99", "best_ask": "0.992"}], "timestamp": "1769384489072", "event_type": "price_change"}}
{"_local_timestamp": "2026-01-25T23:41:29.277563+00:00", "data": {"market": "0x83db787ed2cb00d225178e66bc6ae4d22e8029f19390d2b78ded5aed978eead6", "price_changes": [{"asset_id": "81906419701908530974011339985097627770048267181648886108185004759027261509242", "price": "0.002", "size": "62658.44", "side": "BUY", "hash": "f1e1ca551c11977dd457e50849d33d523b84655d", "best_bid": "0.008", "best_ask": "0.01"}, {"asset_id": "113401754986342384261044700457165882158632153698445535217371023842472815025478", "price": "0.998", "size": "62658.44", "side": "SELL", "hash": "340d3ae398b6f893a8fc82c1aef1225ed54264c2", "best_bid": "0.99", "best_ask": "0.992"}], "timestamp": "1769384489195", "event_type": "price_change"}}
{"_local_timestamp": "2026-01-25T23:41:29.288499+00:00", "data": {"market": "0x754113d4aefc74db7c1266dc5f03e89e3f597deda15b19c19b3ca16cc85b8c33", "price_changes": [{"asset_id": "48827723684529991552849237252156781311984893775886188249280006578488168779709", "price": "0.992", "size": "22", "side": "BUY", "hash": "5cdc2cc1073e706205549c86711e87244c5bff6b", "best_bid": "0.997", "best_ask": "1"}, {"asset_id": "16018186278713893766129270377649855044679233002578361062022208432086696077104", "price": "0.008", "size": "22", "side": "SELL", "hash": "7d99ea52cb1e506751685a1ed6cad26ec7ba8c27", "best_bid": "0", "best_ask": "0.003"}], "timestamp": "1769384489197", "event_type": "price_change"}}
{"_local_timestamp": "2026-01-25T23:41:31.146593+00:00", "data": {"market": "0x754113d4aefc74db7c1266dc5f03e89e3f597deda15b19c19b3ca16cc85b8c33", "price_changes": [{"asset_id": "48827723684529991552849237252156781311984893775886188249280006578488168779709", "price": "0.995", "size": "2138.57", "side": "BUY", "hash": "f1a66f60841ad716807e3ac91aa060d04459053f", "best_bid": "0.997", "best_ask": "1"}, {"asset_id": "16018186278713893766129270377649855044679233002578361062022208432086696077104", "price": "0.005", "size": "2138.57", "side": "SELL", "hash": "ee393aeeac0df4ec17fdcb70994046a69351ff68", "best_bid": "0", "best_ask": "0.003"}], "timestamp": "1769384491077", "event_type": "price_change"}}
{"_local_timestamp": "2026-01-25T23:41:32.157132+00:00", "data": {"market": "0xbfcc34365517ac4978e76ecd8287e37fd92e68b22a3db9b31129c5c37669c293", "price_changes": [{"asset_id": "95417221270011105499568468828531867453865533932484364685389046548264041887861", "price": "0.004", "size": "98", "side": "BUY", "hash": "38465e7212cf9f4b6ee2ca07a1d13284015b0f00", "best_bid": "0.004", "best_ask": "0.006"}, {"asset_id": "101322769768415942646735830228475566436146317671120615766292718518675772773223", "price": "0.996", "size": "98", "side": "SELL", "hash": "94c8983538a01c34199a6f676c015f8fd697f9ef", "best_bid": "0.994", "best_ask": "0.996"}], "timestamp": "1769384492086", "event_type": "price_change"}}
{"_local_timestamp": "2026-01-25T23:41:32.578712+00:00", "data": {"market": "0xbfcc34365517ac4978e76ecd8287e37fd92e68b22a3db9b31129c5c37669c293", "price_changes": [{"asset_id": "95417221270011105499568468828531867453865533932484364685389046548264041887861", "price": "0.011", "size": "2668.88", "side": "SELL", "hash": "f5b2fba55b62536c4ae1a74a8aa43ec623a69c80", "best_bid": "0.004", "best_ask": "0.006"}, {"asset_id": "101322769768415942646735830228475566436146317671120615766292718518675772773223", "price": "0.989", "size": "2668.88", "side": "BUY", "hash": "960785efb3208e905633e93a9d1c1e6470370974", "best_bid": "0.994", "best_ask": "0.996"}], "timestamp": "1769384492502", "event_type": "price_change"}}
{"_local_timestamp": "2026-01-25T23:41:33.049963+00:00", "data": {"market": "0x83db787ed2cb00d225178e66bc6ae4d22e8029f19390d2b78ded5aed978eead6", "price_changes": [{"asset_id": "113401754986342384261044700457165882158632153698445535217371023842472815025478", "price": "0.986", "size": "1006.81", "side": "BUY", "hash": "cf3837f1d1efcc1e117da5536139982f8b5d0fe2", "best_bid": "0.99", "best_ask": "0.992"}, {"asset_id": "81906419701908530974011339985097627770048267181648886108185004759027261509242", "price": "0.014", "size": "1006.81", "side": "SELL", "hash": "93a2cf00672fabb0913134d11095c396332318e2", "best_bid": "0.008", "best_ask": "0.01"}], "timestamp": "1769384492978", "event_type": "price_change"}}
{"_local_timestamp": "2026-01-25T23:41:33.439232+00:00", "data": {"market": "0x83db787ed2cb00d225178e66bc6ae4d22e8029f19390d2b78ded5aed978eead6", "price_changes": [{"asset_id": "113401754986342384261044700457165882158632153698445535217371023842472815025478", "price": "0.991", "size": "946.66", "side": "SELL", "hash": "9633e39f6261514e5c18971716b93e4379e3bf09", "best_bid": "0.99", "best_ask": "0.991"}, {"asset_id": "81906419701908530974011339985097627770048267181648886108185004759027261509242", "price": "0.009", "size": "946.66", "side": "BUY", "hash": "21f03bb53b6a41fc1576b1b8af0b6e9016d6522c", "best_bid": "0.009", "best_ask": "0.01"}], "timestamp": "1769384493363", "event_type": "price_change"}}
{"_local_timestamp": "2026-01-25T23:41:33.823849+00:00", "data": {"market": "0x754113d4aefc74db7c1266dc5f03e89e3f597deda15b19c19b3ca16cc85b8c33", "price_changes": [{"asset_id": "48827723684529991552849237252156781311984893775886188249280006578488168779709", "price": "0.995", "size": "1231.76", "side": "BUY", "hash": "8f47fdb6ae0d31c1b1356b9d8c641ec169141d56", "best_bid": "0.997", "best_ask": "1"}, {"asset_id": "16018186278713893766129270377649855044679233002578361062022208432086696077104", "price": "0.005", "size": "1231.76", "side": "SELL", "hash": "655fc869f326cc3d35e68807c74f366f05236385", "best_bid": "0", "best_ask": "0.003"}], "timestamp": "1769384493741", "event_type": "price_change"}}
{"_local_timestamp": "2026-01-25T23:41:33.830352+00:00", "data": {"market": "0xbfcc34365517ac4978e76ecd8287e37fd92e68b22a3db9b31129c5c37669c293", "price_changes": [{"asset_id": "95417221270011105499568468828531867453865533932484364685389046548264041887861", "price": "0.004", "size": "0", "side": "BUY", "hash": "f5e2833cf1283cd6d804a712598add241c516052", "best_bid": "0.003", "best_ask": "0.006"}, {"asset_id": "101322769768415942646735830228475566436146317671120615766292718518675772773223", "price": "0.996", "size": "0", "side": "SELL", "hash": "46f20c33670b191bca7b8607c50577f622568e89", "best_bid": "0.994", "best_ask": "0.997"}], "timestamp": "1769384493741", "event_type": "price_change"}}
{"_local_timestamp": "2026-01-25T23:41:33.833268+00:00", "data": {"market": "0xbfcc34365517ac4978e76ecd8287e37fd92e68b22a3db9b31129c5c37669c293", "price_changes": [{"asset_id": "95417221270011105499568468828531867453865533932484364685389046548264041887861", "price": "0.011", "size": "22", "side": "SELL", "hash": "f5e2833cf1283cd6d804a712598add241c516052", "best_bid": "0.003", "best_ask": "0.006"}, {"asset_id": "101322769768415942646735830228475566436146317671120615766292718518675772773223", "price": "0.989", "size": "22", "side": "BUY", "hash": "46f20c33670b191bca7b8607c50577f622568e89", "best_bid": "0.994", "best_ask": "0.997"}], "timestamp": "1769384493741", "event_type": "price_change"}}
{"_local_timestamp": "2026-01-25T23:41:33.836167+00:00", "data": {"market": "0x83db787ed2cb00d225178e66bc6ae4d22e8029f19390d2b78ded5aed978eead6", "price_changes": [{"asset_id": "113401754986342384261044700457165882158632153698445535217371023842472815025478", "price": "0.986", "size": "100", "side": "BUY", "hash": "b8bddbf6d9dda779886900d799edc03de2f230e3", "best_bid": "0.99", "best_ask": "0.992"}, {"asset_id": "81906419701908530974011339985097627770048267181648886108185004759027261509242", "price": "0.014", "size": "100", "side": "SELL", "hash": "d46f201b4fd9ea7f016b9f8ff297adfb65042ded", "best_bid": "0.008", "best_ask": "0.01"}], "timestamp": "1769384493741", "event_type": "price_change"}}
{"_local_timestamp": "2026-01-25T23:41:33.851501+00:00", "data": {"market": "0x83db787ed2cb00d225178e66bc6ae4d22e8029f19390d2b78ded5aed978eead6", "price_changes": [{"asset_id": "113401754986342384261044700457165882158632153698445535217371023842472815025478", "price": "0.991", "size": "0", "side": "SELL", "hash": "b8bddbf6d9dda779886900d799edc03de2f230e3", "best_bid": "0.99", "best_ask": "0.992"}, {"asset_id": "81906419701908530974011339985097627770048267181648886108185004759027261509242", "price": "0.009", "size": "0", "side": "BUY", "hash": "d46f201b4fd9ea7f016b9f8ff297adfb65042ded", "best_bid": "0.008", "best_ask": "0.01"}], "timestamp": "1769384493741", "event_type": "price_change"}}
{"_local_timestamp": "2026-01-25T23:41:35.892696+00:00", "data": {"market": "0x754113d4aefc74db7c1266dc5f03e89e3f597deda15b19c19b3ca16cc85b8c33", "price_changes": [{"asset_id": "48827723684529991552849237252156781311984893775886188249280006578488168779709", "price": "0.995", "size": "2138.57", "side": "BUY", "hash": "3591866da9ef0adb78dfe17b92cabd1c1449e24a", "best_bid": "0.997", "best_ask": "1"}, {"asset_id": "16018186278713893766129270377649855044679233002578361062022208432086696077104", "price": "0.005", "size": "2138.57", "side": "SELL", "hash": "e2d8e31d486e087bef9e9122e36e314b88d4e52e", "best_bid": "0", "best_ask": "0.003"}], "timestamp": "1769384495810", "event_type": "price_change"}}
{"_local_timestamp": "2026-01-25T23:41:36.644786+00:00", "data": {"market": "0xbfcc34365517ac4978e76ecd8287e37fd92e68b22a3db9b31129c5c37669c293", "price_changes": [{"asset_id": "95417221270011105499568468828531867453865533932484364685389046548264041887861", "price": "0.004", "size": "98", "side": "BUY", "hash": "1ae4e5a669c3c672f4332222d7a685dd0cb90f03", "best_bid": "0.004", "best_ask": "0.006"}, {"asset_id": "101322769768415942646735830228475566436146317671120615766292718518675772773223", "price": "0.996", "size": "98", "side": "SELL", "hash": "f6e786425d73693647ab5fd9bb1a381e1ea28337", "best_bid": "0.994", "best_ask": "0.996"}], "timestamp": "1769384496572", "event_type": "price_change"}}
{"_local_timestamp": "2026-01-25T23:41:37.045283+00:00", "data": {"market": "0xbfcc34365517ac4978e76ecd8287e37fd92e68b22a3db9b31129c5c37669c293", "price_changes": [{"asset_id": "95417221270011105499568468828531867453865533932484364685389046548264041887861", "price": "0.011", "size": "2668.88", "side": "SELL", "hash": "ec60f7a2c4bcea937e9da13e606440a9169bf4d9", "best_bid": "0.004", "best_ask": "0.006"}, {"asset_id": "101322769768415942646735830228475566436146317671120615766292718518675772773223", "price": "0.989", "size": "2668.88", "side": "BUY", "hash": "3aff5c97aae7694cacb20fa1c74fcee56e6a703f", "best_bid": "0.994", "best_ask": "0.996"}], "timestamp": "1769384496963", "event_type": "price_change"}}
{"_local_timestamp": "2026-01-25T23:41:37.451443+00:00", "data": {"market": "0x83db787ed2cb00d225178e66bc6ae4d22e8029f19390d2b78ded5aed978eead6", "price_changes": [{"asset_id": "113401754986342384261044700457165882158632153698445535217371023842472815025478", "price": "0.986", "size": "1006.81", "side": "BUY", "hash": "5395101f5b8caf7d604da83ff89dacbd7ace34af", "best_bid": "0.99", "best_ask": "0.992"}, {"asset_id": "81906419701908530974011339985097627770048267181648886108185004759027261509242", "price": "0.014", "size": "1006.81", "side": "SELL", "hash": "b2de2baca94fd2f886e11aab7508eb5fc61c6495", "best_bid": "0.008", "best_ask": "0.01"}], "timestamp": "1769384497365", "event_type": "price_change"}}
{"_local_timestamp": "2026-01-25T23:41:37.839844+00:00", "data": {"market": "0x83db787ed2cb00d225178e66bc6ae4d22e8029f19390d2b78ded5aed978eead6", "price_changes": [{"asset_id": "113401754986342384261044700457165882158632153698445535217371023842472815025478", "price": "0.991", "size": "946.66", "side": "SELL", "hash": "cbaefd7e9995cb5d98637712eb20ae73657e9978", "best_bid": "0.99", "best_ask": "0.991"}, {"asset_id": "81906419701908530974011339985097627770048267181648886108185004759027261509242", "price": "0.009", "size": "946.66", "side": "BUY", "hash": "00805433557bd8184852d300de7e37e7fe0ece69", "best_bid": "0.009", "best_ask": "0.01"}], "timestamp": "1769384497765", "event_type": "price_change"}}
{"_local_timestamp": "2026-01-25T23:41:38.239374+00:00", "data": {"market": "0x754113d4aefc74db7c1266dc5f03e89e3f597deda15b19c19b3ca16cc85b8c33", "price_changes": [{"asset_id": "48827723684529991552849237252156781311984893775886188249280006578488168779709", "price": "0.995", "size": "1231.76", "side": "BUY", "hash": "ae7dfecf1460d84669a8b15d0b9770428cc14e46", "best_bid": "0.997", "best_ask": "1"}, {"asset_id": "16018186278713893766129270377649855044679233002578361062022208432086696077104", "price": "0.005", "size": "1231.76", "side": "SELL", "hash": "d01f2b9023f533e4c10e167a67cb73b3eab164d5", "best_bid": "0", "best_ask": "0.003"}], "timestamp": "1769384498164", "event_type": "price_change"}}
{"_local_timestamp": "2026-01-25T23:41:38.242403+00:00", "data": {"market": "0x83db787ed2cb00d225178e66bc6ae4d22e8029f19390d2b78ded5aed978eead6", "price_changes": [{"asset_id": "113401754986342384261044700457165882158632153698445535217371023842472815025478", "price": "0.986", "size": "100", "side": "BUY", "hash": "3b5ba2b0bc74d21ebbc1d3ef42070cbdd2916e3a", "best_bid": "0.99", "best_ask": "0.992"}, {"asset_id": "81906419701908530974011339985097627770048267181648886108185004759027261509242", "price": "0.014", "size": "100", "side": "SELL", "hash": "d5f4e9a2bd6fe74378fbf1b508b26cf972034bb6", "best_bid": "0.008", "best_ask": "0.01"}], "timestamp": "1769384498164", "event_type": "price_change"}}
{"_local_timestamp": "2026-01-25T23:41:38.245525+00:00", "data": {"market": "0x83db787ed2cb00d225178e66bc6ae4d22e8029f19390d2b78ded5aed978eead6", "price_changes": [{"asset_id": "113401754986342384261044700457165882158632153698445535217371023842472815025478", "price": "0.991", "size": "0", "side": "SELL", "hash": "3b5ba2b0bc74d21ebbc1d3ef42070cbdd2916e3a", "best_bid": "0.99", "best_ask": "0.992"}, {"asset_id": "81906419701908530974011339985097627770048267181648886108185004759027261509242", "price": "0.009", "size": "0", "side": "BUY", "hash": "d5f4e9a2bd6fe74378fbf1b508b26cf972034bb6", "best_bid": "0.008", "best_ask": "0.01"}], "timestamp": "1769384498164", "event_type": "price_change"}}
{"_local_timestamp": "2026-01-25T23:41:38.250685+00:00", "data": {"market": "0xbfcc34365517ac4978e76ecd8287e37fd92e68b22a3db9b31129c5c37669c293", "price_changes": [{"asset_id": "95417221270011105499568468828531867453865533932484364685389046548264041887861", "price": "0.004", "size": "0", "side": "BUY", "hash": "d9735f1baf28d123e98110edc9b2daecfb97617b", "best_bid": "0.003", "best_ask": "0.006"}, {"asset_id": "101322769768415942646735830228475566436146317671120615766292718518675772773223", "price": "0.996", "size": "0", "side": "SELL", "hash": "8b30c03e8e4b9a2947e8bcb681422db974bb73cc", "best_bid": "0.994", "best_ask": "0.997"}], "timestamp": "1769384498164", "event_type": "price_change"}}
{"_local_timestamp": "2026-01-25T23:41:38.255142+00:00", "data": {"market": "0xbfcc34365517ac4978e76ecd8287e37fd92e68b22a3db9b31129c5c37669c293", "price_changes": [{"asset_id": "95417221270011105499568468828531867453865533932484364685389046548264041887861", "price": "0.011", "size": "22", "side": "SELL", "hash": "d9735f1baf28d123e98110edc9b2daecfb97617b", "best_bid": "0.003", "best_ask": "0.006"}, {"asset_id": "101322769768415942646735830228475566436146317671120615766292718518675772773223", "price": "0.989", "size": "22", "side": "BUY", "hash": "8b30c03e8e4b9a2947e8bcb681422db974bb73cc", "best_bid": "0.994", "best_ask": "0.997"}], "timestamp": "1769384498164", "event_type": "price_change"}}
{"_local_timestamp": "2026-01-25T23:41:40.370196+00:00", "data": {"market": "0x754113d4aefc74db7c1266dc5f03e89e3f597deda15b19c19b3ca16cc85b8c33", "price_changes": [{"asset_id": "48827723684529991552849237252156781311984893775886188249280006578488168779709", "price": "0.995", "size": "2138.57", "side": "BUY", "hash": "7709e1ca5295aa741983800e5a858321fd310d81", "best_bid": "0.997", "best_ask": "1"}, {"asset_id": "16018186278713893766129270377649855044679233002578361062022208432086696077104", "price": "0.005", "size": "2138.57", "side": "SELL", "hash": "72ddde88ae80689f901360f4be2950861b5b3389", "best_bid": "0", "best_ask": "0.003"}], "timestamp": "1769384500244", "event_type": "price_change"}}
{"_local_timestamp": "2026-01-25T23:41:41.267284+00:00", "data": {"market": "0xbfcc34365517ac4978e76ecd8287e37fd92e68b22a3db9b31129c5c37669c293", "price_changes": [{"asset_id": "95417221270011105499568468828531867453865533932484364685389046548264041887861", "price": "0.004", "size": "98", "side": "BUY", "hash": "ebe09aa1ce26aae5148ae53d5114bca856b52d46", "best_bid": "0.004", "best_ask": "0.006"}, {"asset_id": "101322769768415942646735830228475566436146317671120615766292718518675772773223", "price": "0.996", "size": "98", "side": "SELL", "hash": "16dbe7f4c12b269f4e33e963ef252105c7c2d955", "best_bid": "0.994", "best_ask": "0.996"}], "timestamp": "1769384501189", "event_type": "price_change"}}
{"_local_timestamp": "2026-01-25T23:41:41.284842+00:00", "data": {"market": "0x83db787ed2cb00d225178e66bc6ae4d22e8029f19390d2b78ded5aed978eead6", "price_changes": [{"asset_id": "81906419701908530974011339985097627770048267181648886108185004759027261509242", "price": "0.002", "size": "62582.44", "side": "BUY", "hash": "abb8c34f0e447c0d644e9738d45b5e3a25e8c624", "best_bid": "0.008", "best_ask": "0.01"}, {"asset_id": "113401754986342384261044700457165882158632153698445535217371023842472815025478", "price": "0.998", "size": "62582.44", "side": "SELL", "hash": "712ba4cb882eff72507842291adea0341567ced3", "best_bid": "0.99", "best_ask": "0.992"}], "timestamp": "1769384501213", "event_type": "price_change"}}
{"_local_timestamp": "2026-01-25T23:41:41.288381+00:00", "data": {"market": "0x754113d4aefc74db7c1266dc5f03e89e3f597deda15b19c19b3ca16cc85b8c33", "price_changes": [{"asset_id": "48827723684529991552849237252156781311984893775886188249280006578488168779709", "price": "0.992", "size": "0", "side": "BUY", "hash": "b81bb36ce902ed40b9c5d25d7c4a578dbde47ce0", "best_bid": "0.997", "best_ask": "1"}, {"asset_id": "16018186278713893766129270377649855044679233002578361062022208432086696077104", "price": "0.008", "size": "0", "side": "SELL", "hash": "1a7ec27cafda7866d389f37ec62422a9eed891e2", "best_bid": "0", "best_ask": "0.003"}], "timestamp": "1769384501219", "event_type": "price_change"}}
{"_local_timestamp": "2026-01-25T23:41:41.416232+00:00", "data": {"market": "0x83db787ed2cb00d225178e66bc6ae4d22e8029f19390d2b78ded5aed978eead6", "price_changes": [{"asset_id": "81906419701908530974011339985097627770048267181648886108185004759027261509242", "price": "0.003", "size": "653.76", "side": "BUY", "hash": "72239b9846c05aa7d0a9aab6cbcacbbd86746e77", "best_bid": "0.008", "best_ask": "0.01"}, {"asset_id": "113401754986342384261044700457165882158632153698445535217371023842472815025478", "price": "0.997", "size": "653.76", "side": "SELL", "hash": "75ec16503d85dd80a07b6fa983306be9cc8b4c87", "best_bid": "0.99", "best_ask": "0.992"}], "timestamp": "1769384501337", "event_type": "price_change"}}
{"_local_timestamp": "2026-01-25T23:41:41.420894+00:00", "data": {"market": "0x754113d4aefc74db7c1266dc5f03e89e3f597deda15b19c19b3ca16cc85b8c33", "price_changes": [{"asset_id": "48827723684529991552849237252156781311984893775886188249280006578488168779709", "price": "0.993", "size": "22", "side": "BUY", "hash": "370e5d228eb4bced8cd2837103463e83e89b2ccf", "best_bid": "0.997", "best_ask": "1"}, {"asset_id": "16018186278713893766129270377649855044679233002578361062022208432086696077104", "price": "0.007", "size": "22", "side": "SELL", "hash": "4c702074d7047a792933682ed27a3a49c89ac2c0", "best_bid": "0", "best_ask": "0.003"}], "timestamp": "1769384501343", "event_type": "price_change"}}
{"_local_timestamp": "2026-01-25T23:41:41.658775+00:00", "data": {"market": "0xbfcc34365517ac4978e76ecd8287e37fd92e68b22a3db9b31129c5c37669c293", "price_changes": [{"asset_id": "95417221270011105499568468828531867453865533932484364685389046548264041887861", "price": "0.011", "size": "2668.88", "side": "SELL", "hash": "97955188d56cd1542c72a9a488a5860cce3dafb2", "best_bid": "0.004", "best_ask": "0.006"}, {"asset_id": "101322769768415942646735830228475566436146317671120615766292718518675772773223", "price": "0.989", "size": "2668.88", "side": "BUY", "hash": "e0f62caeb5c4abb595d05e8a341820f9243fd0ed", "best_bid": "0.994", "best_ask": "0.996"}], "timestamp": "1769384501588", "event_type": "price_change"}}
{"_local_timestamp": "2026-01-25T23:41:42.056464+00:00", "data": {"market": "0x83db787ed2cb00d225178e66bc6ae4d22e8029f19390d2b78ded5aed978eead6", "price_changes": [{"asset_id": "113401754986342384261044700457165882158632153698445535217371023842472815025478", "price": "0.986", "size": "1006.81", "side": "BUY", "hash": "6ac6278d9f41c86ba1e5cb240ce73d5d94587f22", "best_bid": "0.99", "best_ask": "0.992"}, {"asset_id": "81906419701908530974011339985097627770048267181648886108185004759027261509242", "price": "0.014", "size": "1006.81", "side": "SELL", "hash": "85061ba0c044df6435c866a2d1d6055fb2e9160b", "best_bid": "0.008", "best_ask": "0.01"}], "timestamp": "1769384501991", "event_type": "price_change"}}
{"_local_timestamp": "2026-01-25T23:41:42.494789+00:00", "data": {"market": "0x83db787ed2cb00d225178e66bc6ae4d22e8029f19390d2b78ded5aed978eead6", "price_changes": [{"asset_id": "113401754986342384261044700457165882158632153698445535217371023842472815025478", "price": "0.991", "size": "946.66", "side": "SELL", "hash": "683ba696c396ff74f80b52c1d3cd76583326bdd7", "best_bid": "0.99", "best_ask": "0.991"}, {"asset_id": "81906419701908530974011339985097627770048267181648886108185004759027261509242", "price": "0.009", "size": "946.66", "side": "BUY", "hash": "98a7bf602034adaa50e26fc571eed064437ee497", "best_bid": "0.009", "best_ask": "0.01"}], "timestamp": "1769384502414", "event_type": "price_change"}}
{"_local_timestamp": "2026-01-25T23:41:42.878052+00:00", "data": {"market": "0x754113d4aefc74db7c1266dc5f03e89e3f597deda15b19c19b3ca16cc85b8c33", "price_changes": [{"asset_id": "48827723684529991552849237252156781311984893775886188249280006578488168779709", "price": "0.995", "size": "1231.76", "side": "BUY", "hash": "497cf24ce14ea98cfd4dede5b6e0c74d8b9b5071", "best_bid": "0.997", "best_ask": "1"}, {"asset_id": "16018186278713893766129270377649855044679233002578361062022208432086696077104", "price": "0.005", "size": "1231.76", "side": "SELL", "hash": "c0d645f0d1d3f9205d72e253c503f44071e304ea", "best_bid": "0", "best_ask": "0.003"}], "timestamp": "1769384502804", "event_type": "price_change"}}
{"_local_timestamp": "2026-01-25T23:41:42.880956+00:00", "data": {"market": "0xbfcc34365517ac4978e76ecd8287e37fd92e68b22a3db9b31129c5c37669c293", "price_changes": [{"asset_id": "95417221270011105499568468828531867453865533932484364685389046548264041887861", "price": "0.004", "size": "0", "side": "BUY", "hash": "a99750e17d12067409c94f2bc5263620175209ec", "best_bid": "0.003", "best_ask": "0.006"}, {"asset_id": "101322769768415942646735830228475566436146317671120615766292718518675772773223", "price": "0.996", "size": "0", "side": "SELL", "hash": "d9037c33a7e45b45cd600f23b697266b2b6730db", "best_bid": "0.994", "best_ask": "0.997"}], "timestamp": "1769384502803", "event_type": "price_change"}}
{"_local_timestamp": "2026-01-25T23:41:42.883723+00:00", "data": {"market": "0xbfcc34365517ac4978e76ecd8287e37fd92e68b22a3db9b31129c5c37669c293", "price_changes": [{"asset_id": "95417221270011105499568468828531867453865533932484364685389046548264041887861", "price": "0.011", "size": "22", "side": "SELL", "hash": "a99750e17d12067409c94f2bc5263620175209ec", "best_bid": "0.003", "best_ask": "0.006"}, {"asset_id": "101322769768415942646735830228475566436146317671120615766292718518675772773223", "price": "0.989", "size": "22", "side": "BUY", "hash": "d9037c33a7e45b45cd600f23b697266b2b6730db", "best_bid": "0.994", "best_ask": "0.997"}], "timestamp": "1769384502803", "event_type": "price_change"}}
{"_local_timestamp": "2026-01-25T23:41:42.886449+00:00", "data": {"market": "0x83db787ed2cb00d225178e66bc6ae4d22e8029f19390d2b78ded5aed978eead6", "price_changes": [{"asset_id": "113401754986342384261044700457165882158632153698445535217371023842472815025478", "price": "0.986", "size": "100", "side": "BUY", "hash": "a4e97b26faaca6b09ad503fe52895fc447bfca8b", "best_bid": "0.99", "best_ask": "0.992"}, {"asset_id": "81906419701908530974011339985097627770048267181648886108185004759027261509242", "price": "0.014", "size": "100", "side": "SELL", "hash": "9672690b5d9a49fe82a2fa20087d904974e1eff4", "best_bid": "0.008", "best_ask": "0.01"}], "timestamp": "1769384502804", "event_type": "price_change"}}
{"_local_timestamp": "2026-01-25T23:41:42.889426+00:00", "data": {"market": "0x83db787ed2cb00d225178e66bc6ae4d22e8029f19390d2b78ded5aed978eead6", "price_changes": [{"asset_id": "113401754986342384261044700457165882158632153698445535217371023842472815025478", "price": "0.991", "size": "0", "side": "SELL", "hash": "a4e97b26faaca6b09ad503fe52895fc447bfca8b", "best_bid": "0.99", "best_ask": "0.992"}, {"asset_id": "81906419701908530974011339985097627770048267181648886108185004759027261509242", "price": "0.009", "size": "0", "side": "BUY", "hash": "9672690b5d9a49fe82a2fa20087d904974e1eff4", "best_bid": "0.008", "best_ask": "0.01"}], "timestamp": "1769384502804", "event_type": "price_change"}}
{"_local_timestamp": "2026-01-25T23:41:42.892740+00:00", "data": {"market": "0x83db787ed2cb00d225178e66bc6ae4d22e8029f19390d2b78ded5aed978eead6", "price_changes": [{"asset_id": "81906419701908530974011339985097627770048267181648886108185004759027261509242", "price": "0.003", "size": "555.76", "side": "BUY", "hash": "6c756accd972d4443c37f81c0d2ceb51ace536d6", "best_bid": "0.008", "best_ask": "0.01"}, {"asset_id": "113401754986342384261044700457165882158632153698445535217371023842472815025478", "price": "0.997", "size": "555.76", "side": "SELL", "hash": "c09dcb723c5e5aaae6534723cc7d9fc8824565bd", "best_bid": "0.99", "best_ask": "0.992"}], "timestamp": "1769384502827", "event_type": "price_change"}}
{"_local_timestamp": "2026-01-25T23:41:42.895708+00:00", "data": {"market": "0x754113d4aefc74db7c1266dc5f03e89e3f597deda15b19c19b3ca16cc85b8c33", "price_changes": [{"asset_id": "48827723684529991552849237252156781311984893775886188249280006578488168779709", "price": "0.993", "size": "0", "side": "BUY", "hash": "56daefba58b33a4164e235fd6bd983ae9093ad42", "best_bid": "0.997", "best_ask": "1"}, {"asset_id": "16018186278713893766129270377649855044679233002578361062022208432086696077104", "price": "0.007", "size": "0", "side": "SELL", "hash": "463f1b386db6e043adff2a67aba3035048493ef1", "best_bid": "0", "best_ask": "0.003"}], "timestamp": "1769384502827", "event_type": "price_change"}}
{"_local_timestamp": "2026-01-25T23:41:43.022265+00:00", "data": {"market": "0x83db787ed2cb00d225178e66bc6ae4d22e8029f19390d2b78ded5aed978eead6", "price_changes": [{"asset_id": "81906419701908530974011339985097627770048267181648886108185004759027261509242", "price": "0.002", "size": "62658.44", "side": "BUY", "hash": "9cfcf7915ccbbc32765f3950670f7bd632197c3f", "best_bid": "0.008", "best_ask": "0.01"}, {"asset_id": "113401754986342384261044700457165882158632153698445535217371023842472815025478", "price": "0.998", "size": "62658.44", "side": "SELL", "hash": "26ff7dc24c3645c0eb45896e2c9e118895e954cd", "best_bid": "0.99", "best_ask": "0.992"}], "timestamp": "1769384502951", "event_type": "price_change"}}
{"_local_timestamp": "2026-01-25T23:41:43.025421+00:00", "data": {"market": "0x754113d4aefc74db7c1266dc5f03e89e3f597deda15b19c19b3ca16cc85b8c33", "price_changes": [{"asset_id": "48827723684529991552849237252156781311984893775886188249280006578488168779709", "price": "0.992", "size": "22", "side": "BUY", "hash": "71984211ebba042720b23c025c0ac3e13ba7d411", "best_bid": "0.997", "best_ask": "1"}, {"asset_id": "16018186278713893766129270377649855044679233002578361062022208432086696077104", "price": "0.008", "size": "22", "side": "SELL", "hash": "61090afca4fc79506db9f41922bbdfca835ab038", "best_bid": "0", "best_ask": "0.003"}], "timestamp": "1769384502954", "event_type": "price_change"}}
{"_local_timestamp": "2026-01-25T23:41:44.958507+00:00", "data": {"market": "0x754113d4aefc74db7c1266dc5f03e89e3f597deda15b19c19b3ca16cc85b8c33", "price_changes": [{"asset_id": "48827723684529991552849237252156781311984893775886188249280006578488168779709", "price": "0.995", "size": "2138.57", "side": "BUY", "hash": "5a788caf148b34da3125a6acac66801e5798430c", "best_bid": "0.997", "best_ask": "1"}, {"asset_id": "16018186278713893766129270377649855044679233002578361062022208432086696077104", "price": "0.005", "size": "2138.57", "side": "SELL", "hash": "6f3ead1aea76977b2b4b3ae851f1cab31fbde768", "best_bid": "0", "best_ask": "0.003"}], "timestamp": "1769384504892", "event_type": "price_change"}}
{"_local_timestamp": "2026-01-25T23:41:45.789310+00:00", "data": {"market": "0xbfcc34365517ac4978e76ecd8287e37fd92e68b22a3db9b31129c5c37669c293", "price_changes": [{"asset_id": "95417221270011105499568468828531867453865533932484364685389046548264041887861", "price": "0.004", "size": "98", "side": "BUY", "hash": "40443a5f7695fb46e889dce60069c053a05769b3", "best_bid": "0.004", "best_ask": "0.006"}, {"asset_id": "101322769768415942646735830228475566436146317671120615766292718518675772773223", "price": "0.996", "size": "98", "side": "SELL", "hash": "9db6a5c301d12119fa9b2719e7592b3ce7dcd9bc", "best_bid": "0.994", "best_ask": "0.996"}], "timestamp": "1769384505714", "event_type": "price_change"}}
{"_local_timestamp": "2026-01-25T23:41:46.199001+00:00", "data": {"market": "0xbfcc34365517ac4978e76ecd8287e37fd92e68b22a3db9b31129c5c37669c293", "price_changes": [{"asset_id": "95417221270011105499568468828531867453865533932484364685389046548264041887861", "price": "0.011", "size": "2668.88", "side": "SELL", "hash": "1439841ac5b6564b7973d7dc2f8306560ab9cdd9", "best_bid": "0.004", "best_ask": "0.006"}, {"asset_id": "101322769768415942646735830228475566436146317671120615766292718518675772773223", "price": "0.989", "size": "2668.88", "side": "BUY", "hash": "18621a9e065e72de97c0f3d20d6c249eef6e0a96", "best_bid": "0.994", "best_ask": "0.996"}], "timestamp": "1769384506131", "event_type": "price_change"}}
{"_local_timestamp": "2026-01-25T23:41:46.599136+00:00", "data": {"market": "0x83db787ed2cb00d225178e66bc6ae4d22e8029f19390d2b78ded5aed978eead6", "price_changes": [{"asset_id": "113401754986342384261044700457165882158632153698445535217371023842472815025478", "price": "0.986", "size": "1006.81", "side": "BUY", "hash": "7a3680d52171acc23b0273d35e886f762369fe91", "best_bid": "0.99", "best_ask": "0.992"}, {"asset_id": "81906419701908530974011339985097627770048267181648886108185004759027261509242", "price": "0.014", "size": "1006.81", "side": "SELL", "hash": "21c1eaf2118e7ffb192bd4753bca879937599b51", "best_bid": "0.008", "best_ask": "0.01"}], "timestamp": "1769384506525", "event_type": "price_change"}}
{"_local_timestamp": "2026-01-25T23:41:47.006685+00:00", "data": {"market": "0x83db787ed2cb00d225178e66bc6ae4d22e8029f19390d2b78ded5aed978eead6", "price_changes": [{"asset_id": "113401754986342384261044700457165882158632153698445535217371023842472815025478", "price": "0.991", "size": "946.66", "side": "SELL", "hash": "5ff3343fd231cf30f92c02aceee2b49c4c7d9fa6", "best_bid": "0.99", "best_ask": "0.991"}, {"asset_id": "81906419701908530974011339985097627770048267181648886108185004759027261509242", "price": "0.009", "size": "946.66", "side": "BUY", "hash": "85ebd26bc75eb7c135b19f92927f0e2f5d09b156", "best_bid": "0.009", "best_ask": "0.01"}], "timestamp": "1769384506936", "event_type": "price_change"}}
{"_local_timestamp": "2026-01-25T23:41:47.392567+00:00", "data": {"market": "0x754113d4aefc74db7c1266dc5f03e89e3f597deda15b19c19b3ca16cc85b8c33", "price_changes": [{"asset_id": "48827723684529991552849237252156781311984893775886188249280006578488168779709", "price": "0.995", "size": "1231.76", "side": "BUY", "hash": "16049571ad62c15f4794fd06159116c6caf6b6cd", "best_bid": "0.997", "best_ask": "1"}, {"asset_id": "16018186278713893766129270377649855044679233002578361062022208432086696077104", "price": "0.005", "size": "1231.76", "side": "SELL", "hash": "6cbc92428237cf87d364136aaab3cfcaa696ed96", "best_bid": "0", "best_ask": "0.003"}], "timestamp": "1769384507314", "event_type": "price_change"}}
{"_local_timestamp": "2026-01-25T23:41:47.395421+00:00", "data": {"market": "0xbfcc34365517ac4978e76ecd8287e37fd92e68b22a3db9b31129c5c37669c293", "price_changes": [{"asset_id": "95417221270011105499568468828531867453865533932484364685389046548264041887861", "price": "0.011", "size": "22", "side": "SELL", "hash": "305b549041b9afbeb50c3eb769aa14a3bb17f1bb", "best_bid": "0.003", "best_ask": "0.006"}, {"asset_id": "101322769768415942646735830228475566436146317671120615766292718518675772773223", "price": "0.989", "size": "22", "side": "BUY", "hash": "219278f91d3ddaab7a57dde3f9c23d696a11ab28", "best_bid": "0.994", "best_ask": "0.997"}], "timestamp": "1769384507314", "event_type": "price_change"}}
{"_local_timestamp": "2026-01-25T23:41:47.398076+00:00", "data": {"market": "0xbfcc34365517ac4978e76ecd8287e37fd92e68b22a3db9b31129c5c37669c293", "price_changes": [{"asset_id": "95417221270011105499568468828531867453865533932484364685389046548264041887861", "price": "0.004", "size": "0", "side": "BUY", "hash": "305b549041b9afbeb50c3eb769aa14a3bb17f1bb", "best_bid": "0.003", "best_ask": "0.006"}, {"asset_id": "101322769768415942646735830228475566436146317671120615766292718518675772773223", "price": "0.996", "size": "0", "side": "SELL", "hash": "219278f91d3ddaab7a57dde3f9c23d696a11ab28", "best_bid": "0.994", "best_ask": "0.997"}], "timestamp": "1769384507314", "event_type": "price_change"}}
{"_local_timestamp": "2026-01-25T23:41:47.400754+00:00", "data": {"market": "0x83db787ed2cb00d225178e66bc6ae4d22e8029f19390d2b78ded5aed978eead6", "price_changes": [{"asset_id": "113401754986342384261044700457165882158632153698445535217371023842472815025478", "price": "0.986", "size": "100", "side": "BUY", "hash": "9857126021c57bbccb5e907cc1427aec7092500b", "best_bid": "0.99", "best_ask": "0.992"}, {"asset_id": "81906419701908530974011339985097627770048267181648886108185004759027261509242", "price": "0.014", "size": "100", "side": "SELL", "hash": "ebeeb5224c554bfcc97d201dfe86ce6dd110a588", "best_bid": "0.008", "best_ask": "0.01"}], "timestamp": "1769384507314", "event_type": "price_change"}}
{"_local_timestamp": "2026-01-25T23:41:47.403597+00:00", "data": {"market": "0x83db787ed2cb00d225178e66bc6ae4d22e8029f19390d2b78ded5aed978eead6", "price_changes": [{"asset_id": "113401754986342384261044700457165882158632153698445535217371023842472815025478", "price": "0.991", "size": "0", "side": "SELL", "hash": "9857126021c57bbccb5e907cc1427aec7092500b", "best_bid": "0.99", "best_ask": "0.992"}, {"asset_id": "81906419701908530974011339985097627770048267181648886108185004759027261509242", "price": "0.009", "size": "0", "side": "BUY", "hash": "ebeeb5224c554bfcc97d201dfe86ce6dd110a588", "best_bid": "0.008", "best_ask": "0.01"}], "timestamp": "1769384507314", "event_type": "price_change"}}
{"_local_timestamp": "2026-01-25T23:41:49.495889+00:00", "data": {"market": "0x754113d4aefc74db7c1266dc5f03e89e3f597deda15b19c19b3ca16cc85b8c33", "price_changes": [{"asset_id": "48827723684529991552849237252156781311984893775886188249280006578488168779709", "price": "0.995", "size": "2138.57", "side": "BUY", "hash": "b9d3adcde2a2febcc7e907fd6a1e4336d84edd05", "best_bid": "0.997", "best_ask": "1"}, {"asset_id": "16018186278713893766129270377649855044679233002578361062022208432086696077104", "price": "0.005", "size": "2138.57", "side": "SELL", "hash": "2ea8bdb24e5bb49a473b5ec62d7fd166e64fc0c4", "best_bid": "0", "best_ask": "0.003"}], "timestamp": "1769384509414", "event_type": "price_change"}}
{"_local_timestamp": "2026-01-25T23:41:50.269575+00:00", "data": {"market": "0xbfcc34365517ac4978e76ecd8287e37fd92e68b22a3db9b31129c5c37669c293", "price_changes": [{"asset_id": "95417221270011105499568468828531867453865533932484364685389046548264041887861", "price": "0.004", "size": "98", "side": "BUY", "hash": "05875c95b172b549ac5b0f7d23506fc6ab2ba7a0", "best_bid": "0.004", "best_ask": "0.006"}, {"asset_id": "101322769768415942646735830228475566436146317671120615766292718518675772773223", "price": "0.996", "size": "98", "side": "SELL", "hash": "3c2164a65938300c7dfe40d81a4c0caad1e0e5f2", "best_bid": "0.994", "best_ask": "0.996"}], "timestamp": "1769384510194", "event_type": "price_change"}}
{"_local_timestamp": "2026-01-25T23:41:50.666166+00:00", "data": {"market": "0xbfcc34365517ac4978e76ecd8287e37fd92e68b22a3db9b31129c5c37669c293", "price_changes": [{"asset_id": "95417221270011105499568468828531867453865533932484364685389046548264041887861", "price": "0.011", "size": "2668.88", "side": "SELL", "hash": "8bca68031515edbce5497a0c1a76ec4848e2486e", "best_bid": "0.004", "best_ask": "0.006"}, {"asset_id": "101322769768415942646735830228475566436146317671120615766292718518675772773223", "price": "0.989", "size": "2668.88", "side": "BUY", "hash": "79d9ab1983462fe86b219c882906dda6cd2e315f", "best_bid": "0.994", "best_ask": "0.996"}], "timestamp": "1769384510587", "event_type": "price_change"}}
{"_local_timestamp": "2026-01-25T23:41:51.096994+00:00", "data": {"market": "0x83db787ed2cb00d225178e66bc6ae4d22e8029f19390d2b78ded5aed978eead6", "price_changes": [{"asset_id": "113401754986342384261044700457165882158632153698445535217371023842472815025478", "price": "0.986", "size": "1006.81", "side": "BUY", "hash": "6d17ef0aa9a862e31fa1b2472d5eae5ee907a943", "best_bid": "0.99", "best_ask": "0.992"}, {"asset_id": "81906419701908530974011339985097627770048267181648886108185004759027261509242", "price": "0.014", "size": "1006.81", "side": "SELL", "hash": "eab49c171571cd078647abc62ec05a99ee932983", "best_bid": "0.008", "best_ask": "0.01"}], "timestamp": "1769384511012", "event_type": "price_change"}}
{"_local_timestamp": "2026-01-25T23:41:51.477578+00:00", "data": {"market": "0x83db787ed2cb00d225178e66bc6ae4d22e8029f19390d2b78ded5aed978eead6", "price_changes": [{"asset_id": "113401754986342384261044700457165882158632153698445535217371023842472815025478", "price": "0.991", "size": "946.66", "side": "SELL", "hash": "2f9b5c7fb063e70ec6737fe00c8628a1ed3a3e03", "best_bid": "0.99", "best_ask": "0.991"}, {"asset_id": "81906419701908530974011339985097627770048267181648886108185004759027261509242", "price": "0.009", "size": "946.66", "side": "BUY", "hash": "4f6827371bbf1a3a0d3422f0c1d75191b0a7d06b", "best_bid": "0.009", "best_ask": "0.01"}], "timestamp": "1769384511411", "event_type": "price_change"}}
{"_local_timestamp": "2026-01-25T23:41:51.928635+00:00", "data": {"market": "0x83db787ed2cb00d225178e66bc6ae4d22e8029f19390d2b78ded5aed978eead6", "price_changes": [{"asset_id": "113401754986342384261044700457165882158632153698445535217371023842472815025478", "price": "0.991", "size": "0", "side": "SELL", "hash": "da9db3f1b4c9fd17d20a86af1b38028f3d0ce5a4", "best_bid": "0.99", "best_ask": "0.992"}, {"asset_id": "81906419701908530974011339985097627770048267181648886108185004759027261509242", "price": "0.009", "size": "0", "side": "BUY", "hash": "0cc30f226b62bed749e23e9ea0da38090cc4f8c1", "best_bid": "0.008", "best_ask": "0.01"}], "timestamp": "1769384511818", "event_type": "price_change"}}
{"_local_timestamp": "2026-01-25T23:41:51.931718+00:00", "data": {"market": "0x83db787ed2cb00d225178e66bc6ae4d22e8029f19390d2b78ded5aed978eead6", "price_changes": [{"asset_id": "113401754986342384261044700457165882158632153698445535217371023842472815025478", "price": "0.986", "size": "100", "side": "BUY", "hash": "da9db3f1b4c9fd17d20a86af1b38028f3d0ce5a4", "best_bid": "0.99", "best_ask": "0.992"}, {"asset_id": "81906419701908530974011339985097627770048267181648886108185004759027261509242", "price": "0.014", "size": "100", "side": "SELL", "hash": "0cc30f226b62bed749e23e9ea0da38090cc4f8c1", "best_bid": "0.008", "best_ask": "0.01"}], "timestamp": "1769384511818", "event_type": "price_change"}}
{"_local_timestamp": "2026-01-25T23:41:51.935274+00:00", "data": {"market": "0x754113d4aefc74db7c1266dc5f03e89e3f597deda15b19c19b3ca16cc85b8c33", "price_changes": [{"asset_id": "48827723684529991552849237252156781311984893775886188249280006578488168779709", "price": "0.995", "size": "1231.76", "side": "BUY", "hash": "7b99809c8f2b233048f77bf848a1ea4642f10252", "best_bid": "0.997", "best_ask": "1"}, {"asset_id": "16018186278713893766129270377649855044679233002578361062022208432086696077104", "price": "0.005", "size": "1231.76", "side": "SELL", "hash": "a19ae4b167fae8ef1c98e6d56a22240ce72176df", "best_bid": "0", "best_ask": "0.003"}], "timestamp": "1769384511822", "event_type": "price_change"}}
{"_local_timestamp": "2026-01-25T23:41:51.938187+00:00", "data": {"market": "0xbfcc34365517ac4978e76ecd8287e37fd92e68b22a3db9b31129c5c37669c293", "price_changes": [{"asset_id": "95417221270011105499568468828531867453865533932484364685389046548264041887861", "price": "0.004", "size": "0", "side": "BUY", "hash": "77f2ee5528f072026098ccc44365c0f8f1d6d83e", "best_bid": "0.003", "best_ask": "0.006"}, {"asset_id": "101322769768415942646735830228475566436146317671120615766292718518675772773223", "price": "0.996", "size": "0", "side": "SELL", "hash": "44f6162cb4b6193d0846bd30a833d075953a0ba5", "best_bid": "0.994", "best_ask": "0.997"}], "timestamp": "1769384511829", "event_type": "price_change"}}
{"_local_timestamp": "2026-01-25T23:41:52.190853+00:00", "data": {"market": "0xbfcc34365517ac4978e76ecd8287e37fd92e68b22a3db9b31129c5c37669c293", "price_changes": [{"asset_id": "95417221270011105499568468828531867453865533932484364685389046548264041887861", "price": "0.011", "size": "22", "side": "SELL", "hash": "77f2ee5528f072026098ccc44365c0f8f1d6d83e", "best_bid": "0.003", "best_ask": "0.006"}, {"asset_id": "101322769768415942646735830228475566436146317671120615766292718518675772773223", "price": "0.989", "size": "22", "side": "BUY", "hash": "44f6162cb4b6193d0846bd30a833d075953a0ba5", "best_bid": "0.994", "best_ask": "0.997"}], "timestamp": "1769384511829", "event_type": "price_change"}}
{"_local_timestamp": "2026-01-25T23:41:53.955012+00:00", "data": {"market": "0x754113d4aefc74db7c1266dc5f03e89e3f597deda15b19c19b3ca16cc85b8c33", "price_changes": [{"asset_id": "48827723684529991552849237252156781311984893775886188249280006578488168779709", "price": "0.995", "size": "2138.57", "side": "BUY", "hash": "27f7f59d366a060e2cd0ea0b07891a481eb1348d", "best_bid": "0.997", "best_ask": "1"}, {"asset_id": "16018186278713893766129270377649855044679233002578361062022208432086696077104", "price": "0.005", "size": "2138.57", "side": "SELL", "hash": "17b8af80e303dae8d26a262455293c9e9ef9eeb5", "best_bid": "0", "best_ask": "0.003"}], "timestamp": "1769384513881", "event_type": "price_change"}}
{"_local_timestamp": "2026-01-25T23:41:54.719270+00:00", "data": {"market": "0xbfcc34365517ac4978e76ecd8287e37fd92e68b22a3db9b31129c5c37669c293", "price_changes": [{"asset_id": "95417221270011105499568468828531867453865533932484364685389046548264041887861", "price": "0.004", "size": "98", "side": "BUY", "hash": "78fc1c094af1cedcd31df8399ff60b31d80284cb", "best_bid": "0.004", "best_ask": "0.006"}, {"asset_id": "101322769768415942646735830228475566436146317671120615766292718518675772773223", "price": "0.996", "size": "98", "side": "SELL", "hash": "36cb98b2faa9e50231ea2a55e3af1af0d04d1f72", "best_bid": "0.994", "best_ask": "0.996"}], "timestamp": "1769384514645", "event_type": "price_change"}}
{"_local_timestamp": "2026-01-25T23:41:54.745299+00:00", "data": {"market": "0x754113d4aefc74db7c1266dc5f03e89e3f597deda15b19c19b3ca16cc85b8c33", "price_changes": [{"asset_id": "48827723684529991552849237252156781311984893775886188249280006578488168779709", "price": "0.992", "size": "0", "side": "BUY", "hash": "f417981fa40ae03b1024136ff12b6e307492ae92", "best_bid": "0.997", "best_ask": "1"}, {"asset_id": "16018186278713893766129270377649855044679233002578361062022208432086696077104", "price": "0.008", "size": "0", "side": "SELL", "hash": "db9c220496c517200a9aa7d941a1c54a43f46bd8", "best_bid": "0", "best_ask": "0.003"}], "timestamp": "1769384514670", "event_type": "price_change"}}
{"_local_timestamp": "2026-01-25T23:41:54.748845+00:00", "data": {"market": "0x83db787ed2cb00d225178e66bc6ae4d22e8029f19390d2b78ded5aed978eead6", "price_changes": [{"asset_id": "81906419701908530974011339985097627770048267181648886108185004759027261509242", "price": "0.002", "size": "62582.44", "side": "BUY", "hash": "5e919e25235bd7816dc095b72ada190d7bab73ba", "best_bid": "0.008", "best_ask": "0.01"}, {"asset_id": "113401754986342384261044700457165882158632153698445535217371023842472815025478", "price": "0.998", "size": "62582.44", "side": "SELL", "hash": "6e4a63c5d6a1968c3aadea57053eaa55d31f2c80", "best_bid": "0.99", "best_ask": "0.992"}], "timestamp": "1769384514671", "event_type": "price_change"}}
{"_local_timestamp": "2026-01-25T23:41:54.864498+00:00", "data": {"market": "0x83db787ed2cb00d225178e66bc6ae4d22e8029f19390d2b78ded5aed978eead6", "price_changes": [{"asset_id": "81906419701908530974011339985097627770048267181648886108185004759027261509242", "price": "0.003", "size": "653.76", "side": "BUY", "hash": "ae7c149646eb550f58e74454ba9057fb57b072e8", "best_bid": "0.008", "best_ask": "0.01"}, {"asset_id": "113401754986342384261044700457165882158632153698445535217371023842472815025478", "price": "0.997", "size": "653.76", "side": "SELL", "hash": "0c9f7bec0cd8cf3dc0e66b288bd749c66c49b491", "best_bid": "0.99", "best_ask": "0.992"}], "timestamp": "1769384514795", "event_type": "price_change"}}
{"_local_timestamp": "2026-01-25T23:41:54.871585+00:00", "data": {"market": "0x754113d4aefc74db7c1266dc5f03e89e3f597deda15b19c19b3ca16cc85b8c33", "price_changes": [{"asset_id": "48827723684529991552849237252156781311984893775886188249280006578488168779709", "price": "0.993", "size": "22", "side": "BUY", "hash": "1c081ad930b38d65147e27c9489e6da42e183753", "best_bid": "0.997", "best_ask": "1"}, {"asset_id": "16018186278713893766129270377649855044679233002578361062022208432086696077104", "price": "0.007", "size": "22", "side": "SELL", "hash": "33b02932a3bbef86100b07d187ec7d9c94ff659c", "best_bid": "0", "best_ask": "0.003"}], "timestamp": "1769384514798", "event_type": "price_change"}}
{"_local_timestamp": "2026-01-25T23:41:55.110655+00:00", "data": {"market": "0xbfcc34365517ac4978e76ecd8287e37fd92e68b22a3db9b31129c5c37669c293", "price_changes": [{"asset_id": "95417221270011105499568468828531867453865533932484364685389046548264041887861", "price": "0.011", "size": "2668.88", "side": "SELL", "hash": "9ac5e5e3e8d23d65bf313b0c819ce751173eabb8", "best_bid": "0.004", "best_ask": "0.006"}, {"asset_id": "101322769768415942646735830228475566436146317671120615766292718518675772773223", "price": "0.989", "size": "2668.88", "side": "BUY", "hash": "07c11b5eca9ff5ad5434e9de36841ca63c2c673c", "best_bid": "0.994", "best_ask": "0.996"}], "timestamp": "1769384515041", "event_type": "price_change"}}
{"_local_timestamp": "2026-01-25T23:41:55.500175+00:00", "data": {"market": "0x83db787ed2cb00d225178e66bc6ae4d22e8029f19390d2b78ded5aed978eead6", "price_changes": [{"asset_id": "113401754986342384261044700457165882158632153698445535217371023842472815025478", "price": "0.986", "size": "1006.81", "side": "BUY", "hash": "d8a222ead22a1e6323fe67996b022705daef22a1", "best_bid": "0.99", "best_ask": "0.992"}, {"asset_id": "81906419701908530974011339985097627770048267181648886108185004759027261509242", "price": "0.014", "size": "1006.81", "side": "SELL", "hash": "c1f35da9bcd8bb449f8a64938f16efa4b4732366", "best_bid": "0.008", "best_ask": "0.01"}], "timestamp": "1769384515432", "event_type": "price_change"}}
{"_local_timestamp": "2026-01-25T23:41:55.915043+00:00", "data": {"market": "0x83db787ed2cb00d225178e66bc6ae4d22e8029f19390d2b78ded5aed978eead6", "price_changes": [{"asset_id": "113401754986342384261044700457165882158632153698445535217371023842472815025478", "price": "0.991", "size": "946.66", "side": "SELL", "hash": "7a0500869aa30213eb35ff12710cfd7866f93d61", "best_bid": "0.99", "best_ask": "0.991"}, {"asset_id": "81906419701908530974011339985097627770048267181648886108185004759027261509242", "price": "0.009", "size": "946.66", "side": "BUY", "hash": "98a556dcbee0f72abe8efff6b834ede6c0401402", "best_bid": "0.009", "best_ask": "0.01"}], "timestamp": "1769384515845", "event_type": "price_change"}}
{"_local_timestamp": "2026-01-25T23:41:56.315174+00:00", "data": {"market": "0x754113d4aefc74db7c1266dc5f03e89e3f597deda15b19c19b3ca16cc85b8c33", "price_changes": [{"asset_id": "48827723684529991552849237252156781311984893775886188249280006578488168779709", "price": "0.995", "size": "1231.76", "side": "BUY", "hash": "9f84aec6f4af52bd0acc5938503bd7a78787ca34", "best_bid": "0.997", "best_ask": "1"}, {"asset_id": "16018186278713893766129270377649855044679233002578361062022208432086696077104", "price": "0.005", "size": "1231.76", "side": "SELL", "hash": "d3a055cc295a616ae08291b264f94771bdb7047a", "best_bid": "0", "best_ask": "0.003"}], "timestamp": "1769384516239", "event_type": "price_change"}}
{"_local_timestamp": "2026-01-25T23:41:56.318158+00:00", "data": {"market": "0xbfcc34365517ac4978e76ecd8287e37fd92e68b22a3db9b31129c5c37669c293", "price_changes": [{"asset_id": "95417221270011105499568468828531867453865533932484364685389046548264041887861", "price": "0.004", "size": "0", "side": "BUY", "hash": "6afa45f221c1665db9dc3e6c13d2af739005c68a", "best_bid": "0.003", "best_ask": "0.006"}, {"asset_id": "101322769768415942646735830228475566436146317671120615766292718518675772773223", "price": "0.996", "size": "0", "side": "SELL", "hash": "98eb956180d16be826b23b103c211bbc84d3723c", "best_bid": "0.994", "best_ask": "0.997"}], "timestamp": "1769384516239", "event_type": "price_change"}}
{"_local_timestamp": "2026-01-25T23:41:56.321011+00:00", "data": {"market": "0x83db787ed2cb00d225178e66bc6ae4d22e8029f19390d2b78ded5aed978eead6", "price_changes": [{"asset_id": "113401754986342384261044700457165882158632153698445535217371023842472815025478", "price": "0.986", "size": "100", "side": "BUY", "hash": "9f53d92d80053a1b91429ffa8d5aad4d9c50b5d3", "best_bid": "0.99", "best_ask": "0.992"}, {"asset_id": "81906419701908530974011339985097627770048267181648886108185004759027261509242", "price": "0.014", "size": "100", "side": "SELL", "hash": "dcd61cbad42c3dd711027b0c86ae70a69b30bf84", "best_bid": "0.008", "best_ask": "0.01"}], "timestamp": "1769384516239", "event_type": "price_change"}}
{"_local_timestamp": "2026-01-25T23:41:56.323792+00:00", "data": {"market": "0xbfcc34365517ac4978e76ecd8287e37fd92e68b22a3db9b31129c5c37669c293", "price_changes": [{"asset_id": "95417221270011105499568468828531867453865533932484364685389046548264041887861", "price": "0.011", "size": "22", "side": "SELL", "hash": "6afa45f221c1665db9dc3e6c13d2af739005c68a", "best_bid": "0.003", "best_ask": "0.006"}, {"asset_id": "101322769768415942646735830228475566436146317671120615766292718518675772773223", "price": "0.989", "size": "22", "side": "BUY", "hash": "98eb956180d16be826b23b103c211bbc84d3723c", "best_bid": "0.994", "best_ask": "0.997"}], "timestamp": "1769384516239", "event_type": "price_change"}}
{"_local_timestamp": "2026-01-25T23:41:56.326596+00:00", "data": {"market": "0x83db787ed2cb00d225178e66bc6ae4d22e8029f19390d2b78ded5aed978eead6", "price_changes": [{"asset_id": "113401754986342384261044700457165882158632153698445535217371023842472815025478", "price": "0.991", "size": "0", "side": "SELL", "hash": "9f53d92d80053a1b91429ffa8d5aad4d9c50b5d3", "best_bid": "0.99", "best_ask": "0.992"}, {"asset_id": "81906419701908530974011339985097627770048267181648886108185004759027261509242", "price": "0.009", "size": "0", "side": "BUY", "hash": "dcd61cbad42c3dd711027b0c86ae70a69b30bf84", "best_bid": "0.008", "best_ask": "0.01"}], "timestamp": "1769384516239", "event_type": "price_change"}}
{"_local_timestamp": "2026-01-25T23:41:56.339440+00:00", "data": {"market": "0x754113d4aefc74db7c1266dc5f03e89e3f597deda15b19c19b3ca16cc85b8c33", "price_changes": [{"asset_id": "48827723684529991552849237252156781311984893775886188249280006578488168779709", "price": "0.993", "size": "0", "side": "BUY", "hash": "feabb9834cf6767a92b5169e0b40372c5c2c0c33", "best_bid": "0.997", "best_ask": "1"}, {"asset_id": "16018186278713893766129270377649855044679233002578361062022208432086696077104", "price": "0.007", "size": "0", "side": "SELL", "hash": "f5963867af17dc28f4742671907b5b9943af856d", "best_bid": "0", "best_ask": "0.003"}], "timestamp": "1769384516262", "event_type": "price_change"}}
{"_local_timestamp": "2026-01-25T23:41:56.346983+00:00", "data": {"market": "0x83db787ed2cb00d225178e66bc6ae4d22e8029f19390d2b78ded5aed978eead6", "price_changes": [{"asset_id": "81906419701908530974011339985097627770048267181648886108185004759027261509242", "price": "0.003", "size": "555.76", "side": "BUY", "hash": "0c7640edb04bc20c43f1f2ab26939fc5d49864f7", "best_bid": "0.008", "best_ask": "0.01"}, {"asset_id": "113401754986342384261044700457165882158632153698445535217371023842472815025478", "price": "0.997", "size": "555.76", "side": "SELL", "hash": "620f13e40354ceab826be0b1a325664b2f5e3f42", "best_bid": "0.99", "best_ask": "0.992"}], "timestamp": "1769384516267", "event_type": "price_change"}}
{"_local_timestamp": "2026-01-25T23:41:56.464737+00:00", "data": {"market": "0x754113d4aefc74db7c1266dc5f03e89e3f597deda15b19c19b3ca16cc85b8c33", "price_changes": [{"asset_id": "48827723684529991552849237252156781311984893775886188249280006578488168779709", "price": "0.992", "size": "22", "side": "BUY", "hash": "d1f7e756bd2ef35608ad77a72666b4612c2f0e00", "best_bid": "0.997", "best_ask": "1"}, {"asset_id": "16018186278713893766129270377649855044679233002578361062022208432086696077104", "price": "0.008", "size": "22", "side": "SELL", "hash": "9934a817a708b3948a9e1f961016982e614237c0", "best_bid": "0", "best_ask": "0.003"}], "timestamp": "1769384516390", "event_type": "price_change"}}
{"_local_timestamp": "2026-01-25T23:41:56.467659+00:00", "data": {"market": "0x83db787ed2cb00d225178e66bc6ae4d22e8029f19390d2b78ded5aed978eead6", "price_changes": [{"asset_id": "81906419701908530974011339985097627770048267181648886108185004759027261509242", "price": "0.002", "size": "62658.44", "side": "BUY", "hash": "5c0a523ea7a78543355381fda106e923729b2140", "best_bid": "0.008", "best_ask": "0.01"}, {"asset_id": "113401754986342384261044700457165882158632153698445535217371023842472815025478", "price": "0.998", "size": "62658.44", "side": "SELL", "hash": "c567b9705a8eb9ea2cac2efb62975916f74c708a", "best_bid": "0.99", "best_ask": "0.992"}], "timestamp": "1769384516392", "event_type": "price_change"}}
{"_local_timestamp": "2026-01-25T23:41:58.370845+00:00", "data": {"market": "0x754113d4aefc74db7c1266dc5f03e89e3f597deda15b19c19b3ca16cc85b8c33", "price_changes": [{"asset_id": "48827723684529991552849237252156781311984893775886188249280006578488168779709", "price": "0.995", "size": "2138.57", "side": "BUY", "hash": "8ceb0ab8de7924a4df4e44a37758914d72289b36", "best_bid": "0.997", "best_ask": "1"}, {"asset_id": "16018186278713893766129270377649855044679233002578361062022208432086696077104", "price": "0.005", "size": "2138.57", "side": "SELL", "hash": "5857d12766830a8219a47838e48ca2ba8c05bfa4", "best_bid": "0", "best_ask": "0.003"}], "timestamp": "1769384518304", "event_type": "price_change"}}
{"_local_timestamp": "2026-01-25T23:41:59.313272+00:00", "data": {"market": "0xbfcc34365517ac4978e76ecd8287e37fd92e68b22a3db9b31129c5c37669c293", "price_changes": [{"asset_id": "95417221270011105499568468828531867453865533932484364685389046548264041887861", "price": "0.004", "size": "98", "side": "BUY", "hash": "ace3939f448745d00979afd276198feb6096c197", "best_bid": "0.004", "best_ask": "0.006"}, {"asset_id": "101322769768415942646735830228475566436146317671120615766292718518675772773223", "price": "0.996", "size": "98", "side": "SELL", "hash": "028c51d2cadf10252242df8ae5a01afa30b1149e", "best_bid": "0.994", "best_ask": "0.996"}], "timestamp": "1769384519244", "event_type": "price_change"}}
{"_local_timestamp": "2026-01-25T23:41:59.716491+00:00", "data": {"market": "0xbfcc34365517ac4978e76ecd8287e37fd92e68b22a3db9b31129c5c37669c293", "price_changes": [{"asset_id": "95417221270011105499568468828531867453865533932484364685389046548264041887861", "price": "0.011", "size": "2668.88", "side": "SELL", "hash": "fb909eb070d4afcf0599647293501dbe335ab95f", "best_bid": "0.004", "best_ask": "0.006"}, {"asset_id": "101322769768415942646735830228475566436146317671120615766292718518675772773223", "price": "0.989", "size": "2668.88", "side": "BUY", "hash": "d63d094d61c091e77b63e724cbe7cf95441fd2c8", "best_bid": "0.994", "best_ask": "0.996"}], "timestamp": "1769384519645", "event_type": "price_change"}}
{"_local_timestamp": "2026-01-25T23:42:00.140185+00:00", "data": {"market": "0x83db787ed2cb00d225178e66bc6ae4d22e8029f19390d2b78ded5aed978eead6", "price_changes": [{"asset_id": "113401754986342384261044700457165882158632153698445535217371023842472815025478", "price": "0.986", "size": "1006.81", "side": "BUY", "hash": "d5305ee16fba8f846abe95bdf916cbf17293b2fa", "best_bid": "0.99", "best_ask": "0.992"}, {"asset_id": "81906419701908530974011339985097627770048267181648886108185004759027261509242", "price": "0.014", "size": "1006.81", "side": "SELL", "hash": "0a53abc4b2d93ebc012b88e5d08c2fe82d90cb69", "best_bid": "0.008", "best_ask": "0.01"}], "timestamp": "1769384520054", "event_type": "price_change"}}
{"_local_timestamp": "2026-01-25T23:42:00.557206+00:00", "data": {"market": "0x83db787ed2cb00d225178e66bc6ae4d22e8029f19390d2b78ded5aed978eead6", "price_changes": [{"asset_id": "113401754986342384261044700457165882158632153698445535217371023842472815025478", "price": "0.991", "size": "946.66", "side": "SELL", "hash": "67685cbb88dda544d31e6ce093add9611e5d282b", "best_bid": "0.99", "best_ask": "0.991"}, {"asset_id": "81906419701908530974011339985097627770048267181648886108185004759027261509242", "price": "0.009", "size": "946.66", "side": "BUY", "hash": "88f00490ba57de0494a7bee8c47d96f4b38b6036", "best_bid": "0.009", "best_ask": "0.01"}], "timestamp": "1769384520483", "event_type": "price_change"}}
{"_local_timestamp": "2026-01-25T23:42:00.784082+00:00", "data": {"market": "0xbfcc34365517ac4978e76ecd8287e37fd92e68b22a3db9b31129c5c37669c293", "price_changes": [{"asset_id": "101322769768415942646735830228475566436146317671120615766292718518675772773223", "price": "0.993", "size": "876.1", "side": "BUY", "hash": "0b605dc91e365fd21c74f7e45ea02afd4a0eec61", "best_bid": "0.994", "best_ask": "0.996"}, {"asset_id": "95417221270011105499568468828531867453865533932484364685389046548264041887861", "price": "0.007", "size": "876.1", "side": "SELL", "hash": "279a5de67d0198256227a8c95842601f532d2387", "best_bid": "0.004", "best_ask": "0.006"}], "timestamp": "1769384520716", "event_type": "price_change"}}
{"_local_timestamp": "2026-01-25T23:42:00.932783+00:00", "data": {"market": "0x754113d4aefc74db7c1266dc5f03e89e3f597deda15b19c19b3ca16cc85b8c33", "price_changes": [{"asset_id": "48827723684529991552849237252156781311984893775886188249280006578488168779709", "price": "0.995", "size": "1231.76", "side": "BUY", "hash": "1813678d426de7c4b4212f1749238afa257f43ce", "best_bid": "0.997", "best_ask": "1"}, {"asset_id": "16018186278713893766129270377649855044679233002578361062022208432086696077104", "price": "0.005", "size": "1231.76", "side": "SELL", "hash": "2dbb80427c0b704cc0fec258741058e64022fba3", "best_bid": "0", "best_ask": "0.003"}], "timestamp": "1769384520860", "event_type": "price_change"}}
{"_local_timestamp": "2026-01-25T23:42:00.935786+00:00", "data": {"market": "0xbfcc34365517ac4978e76ecd8287e37fd92e68b22a3db9b31129c5c37669c293", "price_changes": [{"asset_id": "95417221270011105499568468828531867453865533932484364685389046548264041887861", "price": "0.011", "size": "22", "side": "SELL", "hash": "e39a2bb57cab4e0fa8ab0a11a036a9a4ef318627", "best_bid": "0.003", "best_ask": "0.006"}, {"asset_id": "101322769768415942646735830228475566436146317671120615766292718518675772773223", "price": "0.989", "size": "22", "side": "BUY", "hash": "d52f9e8db45e3ec968e0fd119e6121b57c18a94a", "best_bid": "0.994", "best_ask": "0.997"}], "timestamp": "1769384520860", "event_type": "price_change"}}
{"_local_timestamp": "2026-01-25T23:42:00.938693+00:00", "data": {"market": "0xbfcc34365517ac4978e76ecd8287e37fd92e68b22a3db9b31129c5c37669c293", "price_changes": [{"asset_id": "95417221270011105499568468828531867453865533932484364685389046548264041887861", "price": "0.004", "size": "0", "side": "BUY", "hash": "e39a2bb57cab4e0fa8ab0a11a036a9a4ef318627", "best_bid": "0.003", "best_ask": "0.006"}, {"asset_id": "101322769768415942646735830228475566436146317671120615766292718518675772773223", "price": "0.996", "size": "0", "side": "SELL", "hash": "d52f9e8db45e3ec968e0fd119e6121b57c18a94a", "best_bid": "0.994", "best_ask": "0.997"}], "timestamp": "1769384520860", "event_type": "price_change"}}
{"_local_timestamp": "2026-01-25T23:42:00.941514+00:00", "data": {"market": "0x83db787ed2cb00d225178e66bc6ae4d22e8029f19390d2b78ded5aed978eead6", "price_changes": [{"asset_id": "113401754986342384261044700457165882158632153698445535217371023842472815025478", "price": "0.986", "size": "100", "side": "BUY", "hash": "d21d36fa2f1b57f85f19877299519e8befdca045", "best_bid": "0.99", "best_ask": "0.992"}, {"asset_id": "81906419701908530974011339985097627770048267181648886108185004759027261509242", "price": "0.014", "size": "100", "side": "SELL", "hash": "e75514ab23d4d7b50f003f6b16ad8934074029e8", "best_bid": "0.008", "best_ask": "0.01"}], "timestamp": "1769384520860", "event_type": "price_change"}}
