{"_local_timestamp": "2026-01-25T23:41:08.314126+00:00", "data": [{"market": "0x2a74a7cd29971c3a320eec0595c20a07d9a2cbc501c99694d34963e38a196682", "asset_id": "40042411695863369998216770625571070530892534611209558876495072542089465066752", "timestamp": "1769384461014", "hash": "51e46305fbb81ba9c60fef3c75a409f197c1edc4", "bids": [{"price": "0.001", "size": "4681.53"}, {"price": "0.002", "size": "1256.17"}, {"price": "0.003", "size": "1166"}, {"price": "0.004", "size": "10.67"}, {"price": "0.006", "size": "83"}, {"price": "0.01", "size": "4212.17"}, {"price": "0.011", "size": "5.41"}, {"price": "0.02", "size": "1800"}, {"price": "0.021", "size": "10.59"}, {"price": "0.05", "size": "30"}, {"price": "0.06", "size": "400"}, {"price": "0.061", "size": "10"}, {"price": "0.1", "size": "560"}, {"price": "0.15", "size": "226.66"}, {"price": "0.2", "size": "160"}, {"price": "0.201", "size": "5.2"}, {"price": "0.223", "size": "47"}, {"price": "0.25", "size": "112"}, {"price": "0.3", "size": "86.66"}, {"price": "0.35", "size": "68.57"}, {"price": "0.4", "size": "50"}, {"price": "0.5", "size": "15000"}, {"price": "0.501", "size": "7449.62"}, {"price": "0.523", "size": "130"}, {"price": "0.524", "size": "5"}, {"price": "0.723", "size": "50"}, {"price": "0.823", "size": "44"}, {"price": "0.923", "size": "129"}, {"price": "0.93", "size": "777.12"}, {"price": "0.931", "size": "20"}, {"price": "0.937", "size": "30"}, {"price": "0.938", "size": "40"}, {"price": "0.95", "size": "3501.75"}, {"price": "0.951", "size": "60"}, {"price": "0.97", "size": "1070"}, {"price": "0.98", "size": "875.62"}, {"price": "0.99", "size": "627.46"}, {"price": "0.993", "size": "660.69"}, {"price": "0.994", "size": "525.94"}, {"price": "0.995", "size": "738.91"}, {"price": "0.996", "size": "738.91"}, {"price": "0.997", "size": "1634.76"}, {"price": "0.998", "size": "2285"}], "asks": [{"price": "0.999", "size": "23709.47"}], "event_type": "book", "last_trade_price": "0.001"}, {"market": "0x0e34316a55bc233e7a3413a93c42c66072b7ac502d76e2bc66884b3816ee6e07", "asset_id": "107862542344757352141146430276434917083046632354992038304792604470800981194112", "timestamp": "1769384461014", "hash": "c6394bb6b35b9837881da0f426e9d2404f327d63", "bids": [{"price": "0.001", "size": "4817.53"}, {"price": "0.002", "size": "1256.17"}, {"price": "0.003", "size": "1166"}, {"price": "0.004", "size": "10.67"}, {"price": "0.006", "size": "83"}, {"price": "0.01", "size": "4123"}, {"price": "0.011", "size": "5.41"}, {"price": "0.02", "size": "2110.66"}, {"price": "0.021", "size": "10.59"}, {"price": "0.05", "size": "30"}, {"price": "0.06", "size": "400"}, {"price": "0.061", "size": "10"}, {"price": "0.1", "size": "1310"}, {"price": "0.15", "size": "226.66"}, {"price": "0.2", "size": "160"}, {"price": "0.201", "size": "5.2"}, {"price": "0.223", "size": "46"}, {"price": "0.25", "size": "112"}, {"price": "0.3", "size": "86.66"}, {"price": "0.35", "size": "68.57"}, {"price": "0.4", "size": "50"}, {"price": "0.5", "size": "15000"}, {"price": "0.523", "size": "203"}, {"price": "0.524", "size": "5"}, {"price": "0.723", "size": "48"}, {"price": "0.8", "size": "595.57"}, {"price": "0.823", "size": "121"}, {"price": "0.86", "size": "2000"}, {"price": "0.91", "size": "750"}, {"price": "0.92", "size": "595.56"}, {"price": "0.923", "size": "172"}, {"price": "0.924", "size": "20"}, {"price": "0.935", "size": "30"}, {"price": "0.936", "size": "40"}, {"price": "0.95", "size": "1897.04"}, {"price": "0.951", "size": "90"}, {"price": "0.96", "size": "9"}, {"price": "0.961", "size": "60"}, {"price": "0.968", "size": "60"}, {"price": "0.97", "size": "154"}, {"price": "0.975", "size": "1000"}, {"price": "0.98", "size": "529.38"}, {"price": "0.985", "size": "705.85"}, {"price": "0.988", "size": "1000"}, {"price": "0.989", "size": "500"}, {"price": "0.99", "size": "1262.82"}, {"price": "0.992", "size": "500"}, {"price": "0.993", "size": "19.04"}, {"price": "0.994", "size": "1000"}, {"price": "0.995", "size": "300"}, {"price": "0.996", "size": "833.51"}, {"price": "0.997", "size": "2715.29"}, {"price": "0.998", "size": "5"}], "asks": [{"price": "0.999", "size": "26942.16"}], "event_type": "book", "last_trade_price": "0.001"}, {"market": "0xf2995999537ed00a9e1ed196dac5a34c8362b9e454200968eb123c60d21530d2", "asset_id": "105244305087066947375390379713039474916834963808658829713388931041101255731949", "timestamp": "1769384460719", "hash": "f32a1b6e9360d29427e8cc80fd3920b62395028e", "bids": [{"price": "0.001", "size": "54244.63"}, {"price": "0.002", "size": "236.67"}, {"price": "0.005", "size": "66.33"}, {"price": "0.006", "size": "50.66"}, {"price": "0.007", "size": "16"}, {"price": "0.008", "size": "13.56"}, {"price": "0.01", "size": "2020"}, {"price": "0.011", "size": "17.29"}, {"price": "0.012", "size": "5387.03"}, {"price": "0.013", "size": "1829.41"}, {"price": "0.014", "size": "9.38"}, {"price": "0.015", "size": "25.97"}, {"price": "0.016", "size": "611.65"}, {"price": "0.017", "size": "12.14"}, {"price": "0.018", "size": "26.2"}, {"price": "0.019", "size": "11.87"}], "asks": [{"price": "0.999", "size": "27846.99"}, {"price": "0.998", "size": "1257.47"}, {"price": "0.997", "size": "1000"}, {"price": "0.99", "size": "2078"}, {"price": "0.989", "size": "5.34"}, {"price": "0.98", "size": "1805"}, {"price": "0.97", "size": "5"}, {"price": "0.95", "size": "30"}, {"price": "0.949", "size": "5.08"}, {"price": "0.94", "size": "433"}, {"price": "0.9", "size": "560"}, {"price": "0.85", "size": "226.66"}, {"price": "0.8", "size": "165"}, {"price": "0.75", "size": "117"}, {"price": "0.7", "size": "86.66"}, {"price": "0.65", "size": "68.57"}, {"price": "0.61", "size": "51.28"}, {"price": "0.522", "size": "5"}, {"price": "0.5", "size": "16.22"}, {"price": "0.35", "size": "178.08"}, {"price": "0.2", "size": "112.02"}, {"price": "0.141", "size": "5"}, {"price": "0.05", "size": "137.98"}, {"price": "0.04", "size": "500"}, {"price": "0.039", "size": "1000"}, {"price": "0.036", "size": "230"}, {"price": "0.035", "size": "500"}, {"price": "0.027", "size": "500"}, {"price": "0.026", "size": "500"}, {"price": "0.025", "size": "1399.66"}, {"price": "0.024", "size": "137.87"}, {"price": "0.023", "size": "28.59"}], "event_type": "book", "last_trade_price": "0.023"}, {"market": "0x2a74a7cd29971c3a320eec0595c20a07d9a2cbc501c99694d34963e38a196682", "asset_id": "35311691331065078920223858384826797458646117898089239758404119138722819634257", "timestamp": "1769384461014", "hash": "0c9096e54dd54aa96b76fcc2a4e13dc2468b2df6", "bids": [{"price": "0.001", "size": "23709.47"}], "asks": [{"price": "0.999", "size": "4681.53"}, {"price": "0.998", "size": "1256.17"}, {"price": "0.997", "size": "1166"}, {"price": "0.996", "size": "10.67"}, {"price": "0.994", "size": "83"}, {"price": "0.99", "size": "4212.17"}, {"price": "0.989", "size": "5.41"}, {"price": "0.98", "size": "1800"}, {"price": "0.979", "size": "10.59"}, {"price": "0.95", "size": "30"}, {"price": "0.94", "size": "400"}, {"price": "0.939", "size": "10"}, {"price": "0.9", "size": "560"}, {"price": "0.85", "size": "226.66"}, {"price": "0.8", "size": "160"}, {"price": "0.799", "size": "5.2"}, {"price": "0.777", "size": "47"}, {"price": "0.75", "size": "112"}, {"price": "0.7", "size": "86.66"}, {"price": "0.65", "size": "68.57"}, {"price": "0.6", "size": "50"}, {"price": "0.5", "size": "15000"}, {"price": "0.499", "size": "7449.62"}, {"price": "0.477", "size": "130"}, {"price": "0.476", "size": "5"}, {"price": "0.277", "size": "50"}, {"price": "0.177", "size": "44"}, {"price": "0.077", "size": "129"}, {"price": "0.07", "size": "777.12"}, {"price": "0.069", "size": "20"}, {"price": "0.063", "size": "30"}, {"price": "0.062", "size": "40"}, {"price": "0.05", "size": "3501.75"}, {"price": "0.049", "size": "60"}, {"price": "0.03", "size": "1070"}, {"price": "0.02", "size": "875.62"}, {"price": "0.01", "size": "627.46"}, {"price": "0.007", "size": "660.69"}, {"price": "0.006", "size": "525.94"}, {"price": "0.005", "size": "738.91"}, {"price": "0.004", "size": "738.91"}, {"price": "0.003", "size": "1634.76"}, {"price": "0.002", "size": "2285"}], "event_type": "book", "last_trade_price": "0.001"}, {"market": "0x4a00aea8c3beebfbd78428ed9794389a6064031b3b4498ecee8f1e2567960c52", "asset_id": "25647280398479894832229021619345962565230978912320531311978302103412384666485", "timestamp": "1769384461014", "hash": "0a9a99784f1fdefbf88d3be5999c006928465a27", "bids": [{"price": "0.001", "size": "5850.61"}, {"price": "0.002", "size": "1256.59"}, {"price": "0.003", "size": "1000"}, {"price": "0.004", "size": "11.4"}, {"price": "0.01", "size": "4073"}, {"price": "0.011", "size": "5.78"}, {"price": "0.02", "size": "1800"}, {"price": "0.021", "size": "11.31"}, {"price": "0.05", "size": "30"}, {"price": "0.06", "size": "400"}, {"price": "0.061", "size": "9.87"}, {"price": "0.1", "size": "360"}, {"price": "0.14", "size": "5"}, {"price": "0.15", "size": "226.66"}, {"price": "0.2", "size": "260"}, {"price": "0.201", "size": "5.13"}, {"price": "0.223", "size": "44"}, {"price": "0.23", "size": "5"}, {"price": "0.25", "size": "112"}, {"price": "0.3", "size": "86.66"}, {"price": "0.35", "size": "68.57"}, {"price": "0.4", "size": "50"}, {"price": "0.5", "size": "15000"}, {"price": "0.523", "size": "418"}, {"price": "0.524", "size": "5"}, {"price": "0.65", "size": "105.76"}, {"price": "0.723", "size": "31"}, {"price": "0.78", "size": "9.74"}, {"price": "0.823", "size": "220"}, {"price": "0.923", "size": "371"}, {"price": "0.93", "size": "1750.15"}, {"price": "0.931", "size": "20"}, {"price": "0.936", "size": "30"}, {"price": "0.937", "size": "40"}, {"price": "0.95", "size": "100"}, {"price": "0.951", "size": "60"}, {"price": "0.952", "size": "150"}, {"price": "0.97", "size": "3686.65"}, {"price": "0.98", "size": "1500"}, {"price": "0.981", "size": "1121.01"}, {"price": "0.99", "size": "20.2"}, {"price": "0.991", "size": "60.59"}, {"price": "0.994", "size": "3000"}, {"price": "0.995", "size": "1797.69"}], "asks": [{"price": "0.999", "size": "31756.82"}, {"price": "0.998", "size": "163.31"}], "event_type": "book", "last_trade_price": "0.999"}, {"market": "0xe0e842b31506fda8023595ae777aa10df28ecd9c22c1f1409a7f8712eda7e879", "asset_id": "109396302302451946277463128776199432259939419558255720043997107356989321269700", "timestamp": "1769384461014", "hash": "27bca0f6b1e70e380349d7671caa7d67b080652d", "bids": [{"price": "0.001", "size": "4668.56"}, {"price": "0.002", "size": "1250"}, {"price": "0.003", "size": "1166"}, {"price": "0.006", "size": "83"}, {"price": "0.01", "size": "4123"}, {"price": "0.011", "size": "6.3"}, {"price": "0.02", "size": "2234.91"}, {"price": "0.021", "size": "10.54"}, {"price": "0.05", "size": "30"}, {"price": "0.06", "size": "400"}, {"price": "0.061", "size": "9.96"}, {"price": "0.1", "size": "560"}, {"price": "0.15", "size": "226.66"}, {"price": "0.2", "size": "160"}, {"price": "0.201", "size": "5.17"}, {"price": "0.223", "size": "46"}, {"price": "0.25", "size": "112"}, {"price": "0.3", "size": "86.66"}, {"price": "0.35", "size": "68.57"}, {"price": "0.4", "size": "50"}, {"price": "0.5", "size": "10000"}, {"price": "0.501", "size": "5"}, {"price": "0.523", "size": "10"}, {"price": "0.723", "size": "48"}, {"price": "0.823", "size": "434"}, {"price": "0.923", "size": "33"}, {"price": "0.924", "size": "20"}, {"price": "0.936", "size": "40"}, {"price": "0.937", "size": "30"}, {"price": "0.95", "size": "2661.93"}, {"price": "0.951", "size": "60"}, {"price": "0.97", "size": "10"}, {"price": "0.986", "size": "1509.29"}, {"price": "0.987", "size": "2691.01"}, {"price": "0.99", "size": "840.51"}, {"price": "0.991", "size": "135.99"}, {"price": "0.994", "size": "800"}, {"price": "0.995", "size": "1159.73"}, {"price": "0.996", "size": "2079.61"}, {"price": "0.997", "size": "2881.69"}], "asks": [{"price": "0.999", "size": "30848.44"}], "event_type": "book", "last_trade_price": "0.001"}, {"market": "0x4a00aea8c3beebfbd78428ed9794389a6064031b3b4498ecee8f1e2567960c52", "asset_id": "28282613628199947618108198992841847089900837455551648546884564075036732056803", "timestamp": "1769384461014", "hash": "695207003d9489eb225ec3a2c522ebd5c67bc7a0", "bids": [{"price": "0.001", "size": "31756.82"}, {"price": "0.002", "size": "163.31"}], "asks": [{"price": "0.999", "size": "5850.61"}, {"price": "0.998", "size": "1256.59"}, {"price": "0.997", "size": "1000"}, {"price": "0.996", "size": "11.4"}, {"price": "0.99", "size": "4073"}, {"price": "0.989", "size": "5.78"}, {"price": "0.98", "size": "1800"}, {"price": "0.979", "size": "11.31"}, {"price": "0.95", "size": "30"}, {"price": "0.94", "size": "400"}, {"price": "0.939", "size": "9.87"}, {"price": "0.9", "size": "360"}, {"price": "0.86", "size": "5"}, {"price": "0.85", "size": "226.66"}, {"price": "0.8", "size": "260"}, {"price": "0.799", "size": "5.13"}, {"price": "0.777", "size": "44"}, {"price": "0.77", "size": "5"}, {"price": "0.75", "size": "112"}, {"price": "0.7", "size": "86.66"}, {"price": "0.65", "size": "68.57"}, {"price": "0.6", "size": "50"}, {"price": "0.5", "size": "15000"}, {"price": "0.477", "size": "418"}, {"price": "0.476", "size": "5"}, {"price": "0.35", "size": "105.76"}, {"price": "0.277", "size": "31"}, {"price": "0.22", "size": "9.74"}, {"price": "0.177", "size": "220"}, {"price": "0.077", "size": "371"}, {"price": "0.07", "size": "1750.15"}, {"price": "0.069", "size": "20"}, {"price": "0.064", "size": "30"}, {"price": "0.063", "size": "40"}, {"price": "0.05", "size": "100"}, {"price": "0.049", "size": "60"}, {"price": "0.048", "size": "150"}, {"price": "0.03", "size": "3686.65"}, {"price": "0.02", "size": "1500"}, {"price": "0.019", "size": "1121.01"}, {"price": "0.01", "size": "20.2"}, {"price": "0.009", "size": "60.59"}, {"price": "0.006", "size": "3000"}, {"price": "0.005", "size": "1797.69"}], "event_type": "book", "last_trade_price": "0.999"}, {"market": "0xf2995999537ed00a9e1ed196dac5a34c8362b9e454200968eb123c60d21530d2", "asset_id": "106415214145522966179186096977094978918005217851026867362814745409109043718965", "timestamp": "1769384460719", "hash": "dc4fa276b33008c0b5f3fdb02152af6fc8d9d1cb", "bids": [{"price": "0.001", "size": "27846.99"}, {"price": "0.002", "size": "1257.47"}, {"price": "0.003", "size": "1000"}, {"price": "0.01", "size": "2078"}, {"price": "0.011", "size": "5.34"}, {"price": "0.02", "size": "1805"}, {"price": "0.03", "size": "5"}, {"price": "0.05", "size": "30"}, {"price": "0.051", "size": "5.08"}, {"price": "0.06", "size": "433"}, {"price": "0.1", "size": "560"}, {"price": "0.15", "size": "226.66"}, {"price": "0.2", "size": "165"}, {"price": "0.25", "size": "117"}, {"price": "0.3", "size": "86.66"}, {"price": "0.35", "size": "68.57"}, {"price": "0.39", "size": "51.28"}, {"price": "0.478", "size": "5"}, {"price": "0.5", "size": "16.22"}, {"price": "0.65", "size": "178.08"}, {"price": "0.8", "size": "112.02"}, {"price": "0.859", "size": "5"}, {"price": "0.95", "size": "137.98"}, {"price": "0.96", "size": "500"}, {"price": "0.961", "size": "1000"}, {"price": "0.964", "size": "230"}, {"price": "0.965", "size": "500"}, {"price": "0.973", "size": "500"}, {"price": "0.974", "size": "500"}, {"price": "0.975", "size": "1399.66"}, {"price": "0.976", "size": "137.87"}, {"price": "0.977", "size": "28.59"}], "asks": [{"price": "0.999", "size": "54244.63"}, {"price": "0.998", "size": "236.67"}, {"price": "0.995", "size": "66.33"}, {"price": "0.994", "size": "50.66"}, {"price": "0.993", "size": "16"}, {"price": "0.992", "size": "13.56"}, {"price": "0.99", "size": "2020"}, {"price": "0.989", "size": "17.29"}, {"price": "0.988", "size": "5387.03"}, {"price": "0.987", "size": "1829.41"}, {"price": "0.986", "size": "9.38"}, {"price": "0.985", "size": "25.97"}, {"price": "0.984", "size": "611.65"}, {"price": "0.983", "size": "12.14"}, {"price": "0.982", "size": "26.2"}, {"price": "0.981", "size": "11.87"}], "event_type": "book", "last_trade_price": "0.023"}, {"market": "0x0e34316a55bc233e7a3413a93c42c66072b7ac502d76e2bc66884b3816ee6e07", "asset_id": "76761029218476112031409759115795427470125890678375395683863252655472602921499", "timestamp": "1769384461014", "hash": "94487c82b388745f99313000afa26cc141d2b70e", "bids": [{"price": "0.001", "size": "26942.16"}], "asks": [{"price": "0.999", "size": "4817.53"}, {"price": "0.998", "size": "1256.17"}, {"price": "0.997", "size": "1166"}, {"price": "0.996", "size": "10.67"}, {"price": "0.994", "size": "83"}, {"price": "0.99", "size": "4123"}, {"price": "0.989", "size": "5.41"}, {"price": "0.98", "size": "2110.66"}, {"price": "0.979", "size": "10.59"}, {"price": "0.95", "size": "30"}, {"price": "0.94", "size": "400"}, {"price": "0.939", "size": "10"}, {"price": "0.9", "size": "1310"}, {"price": "0.85", "size": "226.66"}, {"price": "0.8", "size": "160"}, {"price": "0.799", "size": "5.2"}, {"price": "0.777", "size": "46"}, {"price": "0.75", "size": "112"}, {"price": "0.7", "size": "86.66"}, {"price": "0.65", "size": "68.57"}, {"price": "0.6", "size": "50"}, {"price": "0.5", "size": "15000"}, {"price": "0.477", "size": "203"}, {"price": "0.476", "size": "5"}, {"price": "0.277", "size": "48"}, {"price": "0.2", "size": "595.57"}, {"price": "0.177", "size": "121"}, {"price": "0.14", "size": "2000"}, {"price": "0.09", "size": "750"}, {"price": "0.08", "size": "595.56"}, {"price": "0.077", "size": "172"}, {"price": "0.076", "size": "20"}, {"price": "0.065", "size": "30"}, {"price": "0.064", "size": "40"}, {"price": "0.05", "size": "1897.04"}, {"price": "0.049", "size": "90"}, {"price": "0.04", "size": "9"}, {"price": "0.039", "size": "60"}, {"price": "0.032", "size": "60"}, {"price": "0.03", "size": "154"}, {"price": "0.025", "size": "1000"}, {"price": "0.02", "size": "529.38"}, {"price": "0.015", "size": "705.85"}, {"price": "0.012", "size": "1000"}, {"price": "0.011", "size": "500"}, {"price": "0.01", "size": "1262.82"}, {"price": "0.008", "size": "500"}, {"price": "0.007", "size": "19.04"}, {"price": "0.006", "size": "1000"}, {"price": "0.005", "size": "300"}, {"price": "0.004", "size": "833.51"}, {"price": "0.003", "size": "2715.29"}, {"price": "0.002", "size": "5"}], "event_type": "book", "last_trade_price": "0.001"}, {"market": "0x8298fb2a176db2e46ceb5aff2ddff61aca1fdac933c02a4a9e1643bd12c1c7a5", "asset_id": "35897551024644058529519358120193216211748306981601166224061602740309627186051", "timestamp": "1769384461014", "hash": "b908b8634594ef2d655b8227253138a966cccdf8", "bids": [{"price": "0.001", "size": "4815.21"}, {"price": "0.002", "size": "1256.37"}, {"price": "0.003", "size": "1166"}, {"price": "0.004", "size": "11.02"}, {"price": "0.006", "size": "83"}, {"price": "0.01", "size": "4123"}, {"price": "0.02", "size": "1800"}, {"price": "0.05", "size": "30"}, {"price": "0.06", "size": "400"}, {"price": "0.1", "size": "560"}, {"price": "0.15", "size": "226.66"}, {"price": "0.2", "size": "160"}, {"price": "0.201", "size": "5.06"}, {"price": "0.223", "size": "45"}, {"price": "0.25", "size": "112"}, {"price": "0.3", "size": "86.66"}, {"price": "0.35", "size": "68.57"}, {"price": "0.4", "size": "50"}, {"price": "0.5", "size": "15000"}, {"price": "0.523", "size": "198"}, {"price": "0.524", "size": "5"}, {"price": "0.723", "size": "48"}, {"price": "0.823", "size": "121"}, {"price": "0.88", "size": "500"}, {"price": "0.9", "size": "200"}, {"price": "0.923", "size": "171"}, {"price": "0.924", "size": "20"}, {"price": "0.936", "size": "40"}, {"price": "0.937", "size": "30"}, {"price": "0.95", "size": "2887.58"}, {"price": "0.953", "size": "59.99"}, {"price": "0.954", "size": "90"}, {"price": "0.955", "size": "60"}, {"price": "0.97", "size": "5"}, {"price": "0.985", "size": "500"}, {"price": "0.986", "size": "918.79"}, {"price": "0.99", "size": "320.2"}, {"price": "0.991", "size": "374.95"}, {"price": "0.994", "size": "2157.96"}, {"price": "0.995", "size": "1225.05"}, {"price": "0.996", "size": "832.82"}, {"price": "0.997", "size": "2151.34"}], "asks": [{"price": "0.999", "size": "12897.09"}], "event_type": "book", "last_trade_price": "0.001"}, {"market": "0xe0e842b31506fda8023595ae777aa10df28ecd9c22c1f1409a7f8712eda7e879", "asset_id": "108109838300131904793645757730015721729233228300378400579897924202651980716760", "timestamp": "1769384461014", "hash": "89df3bea4351802376fa2cef5e5a0c6e62145eee", "bids": [{"price": "0.001", "size": "30848.44"}], "asks": [{"price": "0.999", "size": "4668.56"}, {"price": "0.998", "size": "1250"}, {"price": "0.997", "size": "1166"}, {"price": "0.994", "size": "83"}, {"price": "0.99", "size": "4123"}, {"price": "0.989", "size": "6.3"}, {"price": "0.98", "size": "2234.91"}, {"price": "0.979", "size": "10.54"}, {"price": "0.95", "size": "30"}, {"price": "0.94", "size": "400"}, {"price": "0.939", "size": "9.96"}, {"price": "0.9", "size": "560"}, {"price": "0.85", "size": "226.66"}, {"price": "0.8", "size": "160"}, {"price": "0.799", "size": "5.17"}, {"price": "0.777", "size": "46"}, {"price": "0.75", "size": "112"}, {"price": "0.7", "size": "86.66"}, {"price": "0.65", "size": "68.57"}, {"price": "0.6", "size": "50"}, {"price": "0.5", "size": "10000"}, {"price": "0.499", "size": "5"}, {"price": "0.477", "size": "10"}, {"price": "0.277", "size": "48"}, {"price": "0.177", "size": "434"}, {"price": "0.077", "size": "33"}, {"price": "0.076", "size": "20"}, {"price": "0.064", "size": "40"}, {"price": "0.063", "size": "30"}, {"price": "0.05", "size": "2661.93"}, {"price": "0.049", "size": "60"}, {"price": "0.03", "size": "10"}, {"price": "0.014", "size": "1509.29"}, {"price": "0.013", "size": "2691.01"}, {"price": "0.01", "size": "840.51"}, {"price": "0.009", "size": "135.99"}, {"price": "0.006", "size": "800"}, {"price": "0.005", "size": "1159.73"}, {"price": "0.004", "size": "2079.61"}, {"price": "0.003", "size": "2881.69"}], "event_type": "book", "last_trade_price": "0.001"}, {"market": "0x8298fb2a176db2e46ceb5aff2ddff61aca1fdac933c02a4a9e1643bd12c1c7a5", "asset_id": "7993116773810665385123830809052135747764218356289251597248975813552433650614", "timestamp": "1769384461014", "hash": "3c213e9d1c51d9872da0f3322f8d02c41e48922c", "bids": [{"price": "0.001", "size": "12897.09"}], "asks": [{"price": "0.999", "size": "4815.21"}, {"price": "0.998", "size": "1256.37"}, {"price": "0.997", "size": "1166"}, {"price": "0.996", "size": "11.02"}, {"price": "0.994", "size": "83"}, {"price": "0.99", "size": "4123"}, {"price": "0.98", "size": "1800"}, {"price": "0.95", "size": "30"}, {"price": "0.94", "size": "400"}, {"price": "0.9", "size": "560"}, {"price": "0.85", "size": "226.66"}, {"price": "0.8", "size": "160"}, {"price": "0.799", "size": "5.06"}, {"price": "0.777", "size": "45"}, {"price": "0.75", "size": "112"}, {"price": "0.7", "size": "86.66"}, {"price": "0.65", "size": "68.57"}, {"price": "0.6", "size": "50"}, {"price": "0.5", "size": "15000"}, {"price": "0.477", "size": "198"}, {"price": "0.476", "size": "5"}, {"price": "0.277", "size": "48"}, {"price": "0.177", "size": "121"}, {"price": "0.12", "size": "500"}, {"price": "0.1", "size": "200"}, {"price": "0.077", "size": "171"}, {"price": "0.076", "size": "20"}, {"price": "0.064", "size": "40"}, {"price": "0.063", "size": "30"}, {"price": "0.05", "size": "2887.58"}, {"price": "0.047", "size": "59.99"}, {"price": "0.046", "size": "90"}, {"price": "0.045", "size": "60"}, {"price": "0.03", "size": "5"}, {"price": "0.015", "size": "500"}, {"price": "0.014", "size": "918.79"}, {"price": "0.01", "size": "320.2"}, {"price": "0.009", "size": "374.95"}, {"price": "0.006", "size": "2157.96"}, {"price": "0.005", "size": "1225.05"}, {"price": "0.004", "size": "832.82"}, {"price": "0.003", "size": "2151.34"}], "event_type": "book", "last_trade_price": "0.001"}]}
{"_local_timestamp": "2026-01-25T23:41:17.196646+00:00", "data": {"market": "0xf2995999537ed00a9e1ed196dac5a34c8362b9e454200968eb123c60d21530d2", "price_changes": [{"asset_id": "105244305087066947375390379713039474916834963808658829713388931041101255731949", "price": "0.023", "size": "55.39", "side": "SELL", "hash": "2784c1beafc16bc23e48d99551abd64673b8f9f5", "best_bid": "0.019", "best_ask": "0.023"}, {"asset_id": "106415214145522966179186096977094978918005217851026867362814745409109043718965", "price": "0.977", "size": "55.39", "side": "BUY", "hash": "846e0822c33d7eaf1e6952d81311e37728f5373b", "best_bid": "0.977", "best_ask": "0.981"}], "timestamp": "1769384477126", "event_type": "price_change"}}
{"_local_timestamp": "2026-01-25T23:41:19.748032+00:00", "data": {"market": "0xf2995999537ed00a9e1ed196dac5a34c8362b9e454200968eb123c60d21530d2", "price_changes": [{"asset_id": "105244305087066947375390379713039474916834963808658829713388931041101255731949", "price": "0.024", "size": "263.63", "side": "SELL", "hash": "1460550f429f52be7de7534c48d46fd70dc49b40", "best_bid": "0.019", "best_ask": "0.023"}, {"asset_id": "106415214145522966179186096977094978918005217851026867362814745409109043718965", "price": "0.976", "size": "263.63", "side": "BUY", "hash": "2738e94f149fbc6d99e88fc883ab97d7589086bb", "best_bid": "0.977", "best_ask": "0.981"}], "timestamp": "1769384479674", "event_type": "price_change"}}
{"_local_timestamp": "2026-01-25T23:41:19.960588+00:00", "data": {"market": "0x4a00aea8c3beebfbd78428ed9794389a6064031b3b4498ecee8f1e2567960c52", "price_changes": [{"asset_id": "25647280398479894832229021619345962565230978912320531311978302103412384666485", "price": "0.951", "size": "0", "side": "BUY", "hash": "ceb4522cd938204bfd968c9d2b3f7555b4b4d111", "best_bid": "0.995", "best_ask": "0.998"}, {"asset_id": "28282613628199947618108198992841847089900837455551648546884564075036732056803", "price": "0.049", "size": "0", "side": "SELL", "hash": "95d56a53ad92b010dc456f47eb33705a9b9f000e", "best_bid": "0.002", "best_ask": "0.005"}], "timestamp": "1769384479887", "event_type": "price_change"}}
{"_local_timestamp": "2026-01-25T23:41:20.070313+00:00", "data": {"market": "0x4a00aea8c3beebfbd78428ed9794389a6064031b3b4498ecee8f1e2567960c52", "price_changes": [{"asset_id": "25647280398479894832229021619345962565230978912320531311978302103412384666485", "price": "0.953", "size": "60", "side": "BUY", "hash": "2d49b611a47b794fb7a9d69f9f95836fce216a19", "best_bid": "0.995", "best_ask": "0.998"}, {"asset_id": "28282613628199947618108198992841847089900837455551648546884564075036732056803", "price": "0.047", "size": "60", "side": "SELL", "hash": "65fdb200829d9dbf7cf4794a2cff9a4f6a712735", "best_bid": "0.002", "best_ask": "0.005"}], "timestamp": "1769384479998", "event_type": "price_change"}}
{"_local_timestamp": "2026-01-25T23:41:25.700412+00:00", "data": {"market": "0xf2995999537ed00a9e1ed196dac5a34c8362b9e454200968eb123c60d21530d2", "price_changes": [{"asset_id": "105244305087066947375390379713039474916834963808658829713388931041101255731949", "price": "0.024", "size": "110.56", "side": "SELL", "hash": "5ff834adc1ea972a1d96e90ee789efc5d53873c2", "best_bid": "0.019", "best_ask": "0.023"}, {"asset_id": "106415214145522966179186096977094978918005217851026867362814745409109043718965", "price": "0.976", "size": "110.56", "side": "BUY", "hash": "610d446ee9cfb95c98b12a9fc48cc5c145a0aad0", "best_bid": "0.977", "best_ask": "0.981"}], "timestamp": "1769384485613", "event_type": "price_change"}}
{"_local_timestamp": "2026-01-25T23:41:25.702461+00:00", "data": {"market": "0xf2995999537ed00a9e1ed196dac5a34c8362b9e454200968eb123c60d21530d2", "price_changes": [{"asset_id": "105244305087066947375390379713039474916834963808658829713388931041101255731949", "price": "0.023", "size": "28.59", "side": "SELL", "hash": "5ff834adc1ea972a1d96e90ee789efc5d53873c2", "best_bid": "0.019", "best_ask": "0.023"}, {"asset_id": "106415214145522966179186096977094978918005217851026867362814745409109043718965", "price": "0.977", "size": "28.59", "side": "BUY", "hash": "610d446ee9cfb95c98b12a9fc48cc5c145a0aad0", "best_bid": "0.977", "best_ask": "0.981"}], "timestamp": "1769384485613", "event_type": "price_change"}}
{"_local_timestamp": "2026-01-25T23:41:37.372421+00:00", "data": {"market": "0x8298fb2a176db2e46ceb5aff2ddff61aca1fdac933c02a4a9e1643bd12c1c7a5", "price_changes": [{"asset_id": "35897551024644058529519358120193216211748306981601166224061602740309627186051", "price": "0.011", "size": "5.58", "side": "BUY", "hash": "ad3e4f4d51f410bbce784d805cddd4d7032c4237", "best_bid": "0.997", "best_ask": "0.999"}, {"asset_id": "7993116773810665385123830809052135747764218356289251597248975813552433650614", "price": "0.989", "size": "5.58", "side": "SELL", "hash": "fb406da864be9b26e4b29228ce82141998d4974a", "best_bid": "0.001", "best_ask": "0.003"}], "timestamp": "1769384497304", "event_type": "price_change"}}
{"_local_timestamp": "2026-01-25T23:41:37.373283+00:00", "data": {"market": "0x8298fb2a176db2e46ceb5aff2ddff61aca1fdac933c02a4a9e1643bd12c1c7a5", "price_changes": [{"asset_id": "35897551024644058529519358120193216211748306981601166224061602740309627186051", "price": "0.061", "size": "10.31", "side": "BUY", "hash": "c76ca0eb871bcb97c1aed1bb291a9e24422243d3", "best_bid": "0.997", "best_ask": "0.999"}, {"asset_id": "7993116773810665385123830809052135747764218356289251597248975813552433650614", "price": "0.939", "size": "10.31", "side": "SELL", "hash": "607615e99bb4cffe03ce493688fcc1b5014a1af5", "best_bid": "0.001", "best_ask": "0.003"}], "timestamp": "1769384497305", "event_type": "price_change"}}
{"_local_timestamp": "2026-01-25T23:41:37.373772+00:00", "data": {"market": "0x8298fb2a176db2e46ceb5aff2ddff61aca1fdac933c02a4a9e1643bd12c1c7a5", "price_changes": [{"asset_id": "35897551024644058529519358120193216211748306981601166224061602740309627186051", "price": "0.021", "size": "10.92", "side": "BUY", "hash": "c923092b5e2ea3734ce30e18735f4923998676a1", "best_bid": "0.997", "best_ask": "0.999"}, {"asset_id": "7993116773810665385123830809052135747764218356289251597248975813552433650614", "price": "0.979", "size": "10.92", "side": "SELL", "hash": "ce2b83676c2ed5bfa3e3e00bee9ed764ca9ce2c2", "best_bid": "0.001", "best_ask": "0.003"}], "timestamp": "1769384497306", "event_type": "price_change"}}
{"_local_timestamp": "2026-01-25T23:42:37.981198+00:00", "data": {"market": "0x4a00aea8c3beebfbd78428ed9794389a6064031b3b4498ecee8f1e2567960c52", "price_changes": [{"asset_id": "28282613628199947618108198992841847089900837455551648546884564075036732056803", "price": "0.005", "size": "1597.69", "side": "SELL", "hash": "fd525b0c55881a3a3c8f7d7656c80aec72e1a957", "best_bid": "0.002", "best_ask": "0.005"}, {"asset_id": "25647280398479894832229021619345962565230978912320531311978302103412384666485", "price": "0.995", "size": "1597.69", "side": "BUY", "hash": "a815088e27e979fcccbb196692c1d089f4369e93", "best_bid": "0.995", "best_ask": "0.998"}], "timestamp": "1769384557862", "event_type": "price_change"}}
{"_local_timestamp": "2026-01-25T23:42:37.982163+00:00", "data": {"market": "0x4a00aea8c3beebfbd78428ed9794389a6064031b3b4498ecee8f1e2567960c52", "asset_id": "28282613628199947618108198992841847089900837455551648546884564075036732056803", "bids": [{"price": "0.001", "size": "31756.82"}, {"price": "0.002", "size": "163.31"}], "asks": [{"price": "0.999", "size": "5850.61"}, {"price": "0.998", "size": "1256.59"}, {"price": "0.997", "size": "1000"}, {"price": "0.996", "size": "11.4"}, {"price": "0.99", "size": "4073"}, {"price": "0.989", "size": "5.78"}, {"price": "0.98", "size": "1800"}, {"price": "0.979", "size": "11.31"}, {"price": "0.95", "size": "30"}, {"price": "0.94", "size": "400"}, {"price": "0.939", "size": "9.87"}, {"price": "0.9", "size": "360"}, {"price": "0.86", "size": "5"}, {"price": "0.85", "size": "226.66"}, {"price": "0.8", "size": "260"}, {"price": "0.799", "size": "5.13"}, {"price": "0.777", "size": "44"}, {"price": "0.77", "size": "5"}, {"price": "0.75", "size": "112"}, {"price": "0.7", "size": "86.66"}, {"price": "0.65", "size": "68.57"}, {"price": "0.6", "size": "50"}, {"price": "0.5", "size": "15000"}, {"price": "0.477", "size": "418"}, {"price": "0.476", "size": "5"}, {"price": "0.35", "size": "105.76"}, {"price": "0.277", "size": "31"}, {"price": "0.22", "size": "9.74"}, {"price": "0.177", "size": "220"}, {"price": "0.077", "size": "371"}, {"price": "0.07", "size": "1750.15"}, {"price": "0.069", "size": "20"}, {"price": "0.064", "size": "30"}, {"price": "0.063", "size": "40"}, {"price": "0.05", "size": "100"}, {"price": "0.048", "size": "150"}, {"price": "0.047", "size": "60"}, {"price": "0.03", "size": "3686.65"}, {"price": "0.02", "size": "1500"}, {"price": "0.019", "size": "1121.01"}, {"price": "0.01", "size": "20.2"}, {"price": "0.009", "size": "60.59"}, {"price": "0.006", "size": "3000"}, {"price": "0.005", "size": "1597.69"}], "hash": "fd525b0c55881a3a3c8f7d7656c80aec72e1a957", "timestamp": "1769384557862", "event_type": "book"}}
{"_local_timestamp": "2026-01-25T23:42:37.982652+00:00", "data": {"market": "0x4a00aea8c3beebfbd78428ed9794389a6064031b3b4498ecee8f1e2567960c52", "asset_id": "25647280398479894832229021619345962565230978912320531311978302103412384666485", "bids": [{"price": "0.001", "size": "5850.61"}, {"price": "0.002", "size": "1256.59"}, {"price": "0.003", "size": "1000"}, {"price": "0.004", "size": "11.4"}, {"price": "0.01", "size": "4073"}, {"price": "0.011", "size": "5.78"}, {"price": "0.02", "size": "1800"}, {"price": "0.021", "size": "11.31"}, {"price": "0.05", "size": "30"}, {"price": "0.06", "size": "400"}, {"price": "0.061", "size": "9.87"}, {"price": "0.1", "size": "360"}, {"price": "0.14", "size": "5"}, {"price": "0.15", "size": "226.66"}, {"price": "0.2", "size": "260"}, {"price": "0.201", "size": "5.13"}, {"price": "0.223", "size": "44"}, {"price": "0.23", "size": "5"}, {"price": "0.25", "size": "112"}, {"price": "0.3", "size": "86.66"}, {"price": "0.35", "size": "68.57"}, {"price": "0.4", "size": "50"}, {"price": "0.5", "size": "15000"}, {"price": "0.523", "size": "418"}, {"price": "0.524", "size": "5"}, {"price": "0.65", "size": "105.76"}, {"price": "0.723", "size": "31"}, {"price": "0.78", "size": "9.74"}, {"price": "0.823", "size": "220"}, {"price": "0.923", "size": "371"}, {"price": "0.93", "size": "1750.15"}, {"price": "0.931", "size": "20"}, {"price": "0.936", "size": "30"}, {"price": "0.937", "size": "40"}, {"price": "0.95", "size": "100"}, {"price": "0.952", "size": "150"}, {"price": "0.953", "size": "60"}, {"price": "0.97", "size": "3686.65"}, {"price": "0.98", "size": "1500"}, {"price": "0.981", "size": "1121.01"}, {"price": "0.99", "size": "20.2"}, {"price": "0.991", "size": "60.59"}, {"price": "0.994", "size": "3000"}, {"price": "0.995", "size": "1597.69"}], "asks": [{"price": "0.999", "size": "31756.82"}, {"price": "0.998", "size": "163.31"}], "hash": "a815088e27e979fcccbb196692c1d089f4369e93", "timestamp": "1769384557862", "event_type": "book"}}
{"_local_timestamp": "2026-01-25T23:42:38.005081+00:00", "data": {"market": "0x4a00aea8c3beebfbd78428ed9794389a6064031b3b4498ecee8f1e2567960c52", "asset_id": "28282613628199947618108198992841847089900837455551648546884564075036732056803", "price": "0.005", "size": "200", "fee_rate_bps": "0", "side": "BUY", "timestamp": "1769384557891", "event_type": "last_trade_price", "transaction_hash": "0x203ff6e071b876090f825031a81e64452c73f561e8fbd027b4fd23345d19388e"}}
{"_local_timestamp": "2026-01-25T23:42:47.265105+00:00", "data": {"market": "0xf2995999537ed00a9e1ed196dac5a34c8362b9e454200968eb123c60d21530d2", "price_changes": [{"asset_id": "105244305087066947375390379713039474916834963808658829713388931041101255731949", "price": "0.019", "size": "6.25", "side": "BUY", "hash": "7f3aaf06a1a05697464e662ef6f871026521e95c", "best_bid": "0.019", "best_ask": "0.023"}, {"asset_id": "106415214145522966179186096977094978918005217851026867362814745409109043718965", "price": "0.981", "size": "6.25", "side": "SELL", "hash": "0d3fcc9c4fffa5238bb5525463511ce19a32ff7b", "best_bid": "0.977", "best_ask": "0.981"}], "timestamp": "1769384567000", "event_type": "price_change"}}
{"_local_timestamp": "2026-01-25T23:42:47.371550+00:00", "data": {"market": "0x4a00aea8c3beebfbd78428ed9794389a6064031b3b4498ecee8f1e2567960c52", "price_changes": [{"asset_id": "25647280398479894832229021619345962565230978912320531311978302103412384666485", "price": "0.952", "size": "60", "side": "BUY", "hash": "33f9e919f754fce53768b1d09bbe50a0035d8bfd", "best_bid": "0.995", "best_ask": "0.998"}, {"asset_id": "28282613628199947618108198992841847089900837455551648546884564075036732056803", "price": "0.048", "size": "60", "side": "SELL", "hash": "8bbb6f45978aaf6b280fbacf64a9aded947be400", "best_bid": "0.002", "best_ask": "0.005"}], "timestamp": "1769384567217", "event_type": "price_change"}}
{"_local_timestamp": "2026-01-25T23:44:29.588233+00:00", "data": {"market": "0x4a00aea8c3beebfbd78428ed9794389a6064031b3b4498ecee8f1e2567960c52", "price_changes": [{"asset_id": "25647280398479894832229021619345962565230978912320531311978302103412384666485", "price": "0.524", "size": "0", "side": "BUY", "hash": "b8265b6ef929a970d7f618417c67c417297c88d5", "best_bid": "0.995", "best_ask": "0.998"}, {"asset_id": "28282613628199947618108198992841847089900837455551648546884564075036732056803", "price": "0.476", "size": "0", "side": "SELL", "hash": "13ac3fe71c0bb1101587d1420fd92370ca893ace", "best_bid": "0.002", "best_ask": "0.005"}], "timestamp": "1769384669326", "event_type": "price_change"}}
{"_local_timestamp": "2026-01-25T23:44:29.648998+00:00", "data": {"market": "0x4a00aea8c3beebfbd78428ed9794389a6064031b3b4498ecee8f1e2567960c52", "price_changes": [{"asset_id": "25647280398479894832229021619345962565230978912320531311978302103412384666485", "price": "0.524", "size": "5", "side": "BUY", "hash": "ce7d5fabf0a2636ad33b82ddaa4cecbcfd248f41", "best_bid": "0.995", "best_ask": "0.998"}, {"asset_id": "28282613628199947618108198992841847089900837455551648546884564075036732056803", "price": "0.476", "size": "5", "side": "SELL", "hash": "ce2505ee4d2182507edcf41b7ab5ad9776a94bf3", "best_bid": "0.002", "best_ask": "0.005"}], "timestamp": "1769384669378", "event_type": "price_change"}}
{"_local_timestamp": "2026-01-25T23:44:29.768395+00:00", "data": {"market": "0x4a00aea8c3beebfbd78428ed9794389a6064031b3b4498ecee8f1e2567960c52", "price_changes": [{"asset_id": "25647280398479894832229021619345962565230978912320531311978302103412384666485", "price": "0.952", "size": "0", "side": "BUY", "hash": "c5012d8a0bb4e860b3a5a4e8a8a8d3bf0c57c779", "best_bid": "0.995", "best_ask": "0.998"}, {"asset_id": "28282613628199947618108198992841847089900837455551648546884564075036732056803", "price": "0.048", "size": "0", "side": "SELL", "hash": "fb6a5cf0db4bc629de026f0084ec413fd34972c9", "best_bid": "0.002", "best_ask": "0.005"}], "timestamp": "1769384669504", "event_type": "price_change"}}
{"_local_timestamp": "2026-01-25T23:44:29.768776+00:00", "data": {"market": "0x0e34316a55bc233e7a3413a93c42c66072b7ac502d76e2bc66884b3816ee6e07", "price_changes": [{"asset_id": "107862542344757352141146430276434917083046632354992038304792604470800981194112", "price": "0.961", "size": "0", "side": "BUY", "hash": "2ffb58fae52d2b2e5ea13e1f260ec0411835c875", "best_bid": "0.998", "best_ask": "0.999"}, {"asset_id": "76761029218476112031409759115795427470125890678375395683863252655472602921499", "price": "0.039", "size": "0", "side": "SELL", "hash": "012c3e3eb5756a14bc9facc4e07d89c601ea8040", "best_bid": "0.001", "best_ask": "0.002"}], "timestamp": "1769384669504", "event_type": "price_change"}}
{"_local_timestamp": "2026-01-25T23:44:29.904486+00:00", "data": {"market": "0x4a00aea8c3beebfbd78428ed9794389a6064031b3b4498ecee8f1e2567960c52", "price_changes": [{"asset_id": "25647280398479894832229021619345962565230978912320531311978302103412384666485", "price": "0.951", "size": "90", "side": "BUY", "hash": "237d9a6eefb1fb7fd6a5900b44c480df35e8a954", "best_bid": "0.995", "best_ask": "0.998"}, {"asset_id": "28282613628199947618108198992841847089900837455551648546884564075036732056803", "price": "0.049", "size": "90", "side": "SELL", "hash": "7ad4e4606876c00cf1a526f02848f410fc09b8ed", "best_bid": "0.002", "best_ask": "0.005"}], "timestamp": "1769384669635", "event_type": "price_change"}}
{"_local_timestamp": "2026-01-25T23:44:29.904817+00:00", "data": {"market": "0x4a00aea8c3beebfbd78428ed9794389a6064031b3b4498ecee8f1e2567960c52", "price_changes": [{"asset_id": "25647280398479894832229021619345962565230978912320531311978302103412384666485", "price": "0.954", "size": "60", "side": "BUY", "hash": "317602640e76e0aa4ad58d282ff51e653358689f", "best_bid": "0.995", "best_ask": "0.998"}, {"asset_id": "28282613628199947618108198992841847089900837455551648546884564075036732056803", "price": "0.046", "size": "60", "side": "SELL", "hash": "438e8e72fbe7a81a15b1a08da6cdbfc88b080837", "best_bid": "0.002", "best_ask": "0.005"}], "timestamp": "1769384669638", "event_type": "price_change"}}
{"_local_timestamp": "2026-01-25T23:44:29.928783+00:00", "data": {"market": "0x0e34316a55bc233e7a3413a93c42c66072b7ac502d76e2bc66884b3816ee6e07", "price_changes": [{"asset_id": "107862542344757352141146430276434917083046632354992038304792604470800981194112", "price": "0.951", "size": "0", "side": "BUY", "hash": "53a7d3e3628e034bf4208f668e435308b6a047f0", "best_bid": "0.998", "best_ask": "0.999"}, {"asset_id": "76761029218476112031409759115795427470125890678375395683863252655472602921499", "price": "0.049", "size": "0", "side": "SELL", "hash": "ba2db9222765f562204b16aa922a27983191845e", "best_bid": "0.001", "best_ask": "0.002"}], "timestamp": "1769384669666", "event_type": "price_change"}}
{"_local_timestamp": "2026-01-25T23:44:30.069789+00:00", "data": {"market": "0x0e34316a55bc233e7a3413a93c42c66072b7ac502d76e2bc66884b3816ee6e07", "price_changes": [{"asset_id": "107862542344757352141146430276434917083046632354992038304792604470800981194112", "price": "0.961", "size": "60", "side": "BUY", "hash": "3cff229b5076e5ed64699714efe197ad5987f740", "best_bid": "0.998", "best_ask": "0.999"}, {"asset_id": "76761029218476112031409759115795427470125890678375395683863252655472602921499", "price": "0.039", "size": "60", "side": "SELL", "hash": "233ee3eb7ebad7da2332a248a5aa41609922c9fe", "best_bid": "0.001", "best_ask": "0.002"}], "timestamp": "1769384669785", "event_type": "price_change"}}
{"_local_timestamp": "2026-01-25T23:44:30.074607+00:00", "data": {"market": "0x0e34316a55bc233e7a3413a93c42c66072b7ac502d76e2bc66884b3816ee6e07", "price_changes": [{"asset_id": "107862542344757352141146430276434917083046632354992038304792604470800981194112", "price": "0.951", "size": "90", "side": "BUY", "hash": "03bcf1f93edf0588589c214ba115ea2b3b927f3e", "best_bid": "0.998", "best_ask": "0.999"}, {"asset_id": "76761029218476112031409759115795427470125890678375395683863252655472602921499", "price": "0.049", "size": "90", "side": "SELL", "hash": "5c36ec3d2f1f44eb2b15a446c6ece79539b9b6e6", "best_bid": "0.001", "best_ask": "0.002"}], "timestamp": "1769384669789", "event_type": "price_change"}}
{"_local_timestamp": "2026-01-25T23:44:43.155710+00:00", "data": {"market": "0xf2995999537ed00a9e1ed196dac5a34c8362b9e454200968eb123c60d21530d2", "price_changes": [{"asset_id": "105244305087066947375390379713039474916834963808658829713388931041101255731949", "price": "0.017", "size": "6.98", "side": "BUY", "hash": "03308c30bef950ad5860a27d5693ac61c6f6bef8", "best_bid": "0.019", "best_ask": "0.023"}, {"asset_id": "106415214145522966179186096977094978918005217851026867362814745409109043718965", "price": "0.983", "size": "6.98", "side": "SELL", "hash": "107a171a6b3d612014e427ad45cf1fb74a20e3d2", "best_bid": "0.977", "best_ask": "0.981"}], "timestamp": "1769384683000", "event_type": "price_change"}}
{"_local_timestamp": "2026-01-25T23:44:43.251835+00:00", "data": {"market": "0x8298fb2a176db2e46ceb5aff2ddff61aca1fdac933c02a4a9e1643bd12c1c7a5", "price_changes": [{"asset_id": "35897551024644058529519358120193216211748306981601166224061602740309627186051", "price": "0.955", "size": "0", "side": "BUY", "hash": "69f65b868682c7075830a3f409463deeda1ff341", "best_bid": "0.997", "best_ask": "0.999"}, {"asset_id": "7993116773810665385123830809052135747764218356289251597248975813552433650614", "price": "0.045", "size": "0", "side": "SELL", "hash": "3ef2993c95ec78fe67e8934d8819dc5de9ede72b", "best_bid": "0.001", "best_ask": "0.003"}], "timestamp": "1769384683099", "event_type": "price_change"}}
{"_local_timestamp": "2026-01-25T23:44:43.252334+00:00", "data": {"market": "0xe0e842b31506fda8023595ae777aa10df28ecd9c22c1f1409a7f8712eda7e879", "price_changes": [{"asset_id": "109396302302451946277463128776199432259939419558255720043997107356989321269700", "price": "0.951", "size": "0", "side": "BUY", "hash": "cfaccec6ded90501d7870962601115fb10ca2320", "best_bid": "0.997", "best_ask": "0.999"}, {"asset_id": "108109838300131904793645757730015721729233228300378400579897924202651980716760", "price": "0.049", "size": "0", "side": "SELL", "hash": "64bf37e42c5643dd70176f0571092222373a3cad", "best_bid": "0.001", "best_ask": "0.003"}], "timestamp": "1769384683099", "event_type": "price_change"}}
{"_local_timestamp": "2026-01-25T23:44:43.285393+00:00", "data": {"market": "0xe0e842b31506fda8023595ae777aa10df28ecd9c22c1f1409a7f8712eda7e879", "price_changes": [{"asset_id": "109396302302451946277463128776199432259939419558255720043997107356989321269700", "price": "0.952", "size": "60", "side": "BUY", "hash": "4ffb4ccd0ee579ff2cd3027cf3ecafd2caa258c5", "best_bid": "0.997", "best_ask": "0.999"}, {"asset_id": "108109838300131904793645757730015721729233228300378400579897924202651980716760", "price": "0.048", "size": "60", "side": "SELL", "hash": "84b3e8011145bb2206acabd49974555344049183", "best_bid": "0.001", "best_ask": "0.003"}], "timestamp": "1769384683130", "event_type": "price_change"}}
{"_local_timestamp": "2026-01-25T23:44:43.285777+00:00", "data": {"market": "0x8298fb2a176db2e46ceb5aff2ddff61aca1fdac933c02a4a9e1643bd12c1c7a5", "price_changes": [{"asset_id": "35897551024644058529519358120193216211748306981601166224061602740309627186051", "price": "0.955", "size": "60", "side": "BUY", "hash": "4b0f6f4dcffa448f735724ba03cf9afa2dcbbaaf", "best_bid": "0.997", "best_ask": "0.999"}, {"asset_id": "7993116773810665385123830809052135747764218356289251597248975813552433650614", "price": "0.045", "size": "60", "side": "SELL", "hash": "a3d0b4dac13f597bb8ea48066655f473cc32bb9d", "best_bid": "0.001", "best_ask": "0.003"}], "timestamp": "1769384683130", "event_type": "price_change"}}
{"_local_timestamp": "2026-01-25T23:44:43.286019+00:00", "data": {"market": "0xe0e842b31506fda8023595ae777aa10df28ecd9c22c1f1409a7f8712eda7e879", "price_changes": [{"asset_id": "109396302302451946277463128776199432259939419558255720043997107356989321269700", "price": "0.938", "size": "500", "side": "BUY", "hash": "2e302e5c5172f2c2ed1740da5171bd66988f770d", "best_bid": "0.997", "best_ask": "0.999"}, {"asset_id": "108109838300131904793645757730015721729233228300378400579897924202651980716760", "price": "0.062", "size": "500", "side": "SELL", "hash": "36f3f63b741cfd3961f8fa7a2d2f2e4fe2c0cc4d", "best_bid": "0.001", "best_ask": "0.003"}], "timestamp": "1769384683131", "event_type": "price_change"}}
{"_local_timestamp": "2026-01-25T23:44:43.777771+00:00", "data": {"market": "0xe0e842b31506fda8023595ae777aa10df28ecd9c22c1f1409a7f8712eda7e879", "price_changes": [{"asset_id": "109396302302451946277463128776199432259939419558255720043997107356989321269700", "price": "0.938", "size": "0", "side": "BUY", "hash": "da32ecc5f4f5a9007cb0e1ec5d5c5322273e9d2a", "best_bid": "0.997", "best_ask": "0.999"}, {"asset_id": "108109838300131904793645757730015721729233228300378400579897924202651980716760", "price": "0.062", "size": "0", "side": "SELL", "hash": "c9add41f0f7e486209bb22d51bd0f45824615bd0", "best_bid": "0.001", "best_ask": "0.003"}], "timestamp": "1769384683612", "event_type": "price_change"}}
{"_local_timestamp": "2026-01-25T23:44:44.220330+00:00", "data": {"market": "0xf2995999537ed00a9e1ed196dac5a34c8362b9e454200968eb123c60d21530d2", "price_changes": [{"asset_id": "105244305087066947375390379713039474916834963808658829713388931041101255731949", "price": "0.002", "size": "219.53", "side": "BUY", "hash": "354c875295d15c4bf6ac60dd275d49ce0c3f97e6", "best_bid": "0.019", "best_ask": "0.023"}, {"asset_id": "106415214145522966179186096977094978918005217851026867362814745409109043718965", "price": "0.998", "size": "219.53", "side": "SELL", "hash": "d4a2aa7a352aca7c11c0221a6edd6452c4ff34d7", "best_bid": "0.977", "best_ask": "0.981"}], "timestamp": "1769384684044", "event_type": "price_change"}}
{"_local_timestamp": "2026-01-25T23:44:44.979869+00:00", "data": {"market": "0xf2995999537ed00a9e1ed196dac5a34c8362b9e454200968eb123c60d21530d2", "price_changes": [{"asset_id": "105244305087066947375390379713039474916834963808658829713388931041101255731949", "price": "0.017", "size": "15.02", "side": "BUY", "hash": "e7ee31ad871759e22361986590571ba0b10de0ca", "best_bid": "0.019", "best_ask": "0.023"}, {"asset_id": "106415214145522966179186096977094978918005217851026867362814745409109043718965", "price": "0.983", "size": "15.02", "side": "SELL", "hash": "4d5f4e8bde45d89a4d08102a18a81a2786c1cc30", "best_bid": "0.977", "best_ask": "0.981"}], "timestamp": "1769384684795", "event_type": "price_change"}}
{"_local_timestamp": "2026-01-25T23:44:44.980323+00:00", "data": {"market": "0xf2995999537ed00a9e1ed196dac5a34c8362b9e454200968eb123c60d21530d2", "price_changes": [{"asset_id": "105244305087066947375390379713039474916834963808658829713388931041101255731949", "price": "0.006", "size": "59.37", "side": "BUY", "hash": "790548e99cf3c9cd206147470ecee5566d9e8d0f", "best_bid": "0.019", "best_ask": "0.023"}, {"asset_id": "106415214145522966179186096977094978918005217851026867362814745409109043718965", "price": "0.994", "size": "59.37", "side": "SELL", "hash": "24df1ebfe01bb1fa7522da2255d0283f77c83121", "best_bid": "0.977", "best_ask": "0.981"}], "timestamp": "1769384684797", "event_type": "price_change"}}
{"_local_timestamp": "2026-01-25T23:44:44.980601+00:00", "data": {"market": "0xf2995999537ed00a9e1ed196dac5a34c8362b9e454200968eb123c60d21530d2", "price_changes": [{"asset_id": "105244305087066947375390379713039474916834963808658829713388931041101255731949", "price": "0.014", "size": "17.66", "side": "BUY", "hash": "9ffee34b2cefe2e4662e02fd7506dc09c1766a90", "best_bid": "0.019", "best_ask": "0.023"}, {"asset_id": "106415214145522966179186096977094978918005217851026867362814745409109043718965", "price": "0.986", "size": "17.66", "side": "SELL", "hash": "88c5b7a42ae6fa884b29a4b97aad1d8c86480cdc", "best_bid": "0.977", "best_ask": "0.981"}], "timestamp": "1769384684798", "event_type": "price_change"}}
{"_local_timestamp": "2026-01-25T23:44:49.655947+00:00", "data": {"market": "0xf2995999537ed00a9e1ed196dac5a34c8362b9e454200968eb123c60d21530d2", "price_changes": [{"asset_id": "106415214145522966179186096977094978918005217851026867362814745409109043718965", "price": "0.478", "size": "0", "side": "BUY", "hash": "3ed9700754ed0988e2991b3892cd95e20ee98da9", "best_bid": "0.977", "best_ask": "0.981"}, {"asset_id": "105244305087066947375390379713039474916834963808658829713388931041101255731949", "price": "0.522", "size": "0", "side": "SELL", "hash": "c1716ef8b29053348d65a7c764c06237b8553fb2", "best_bid": "0.019", "best_ask": "0.023"}], "timestamp": "1769384689481", "event_type": "price_change"}}
{"_local_timestamp": "2026-01-25T23:44:49.961960+00:00", "data": {"market": "0xf2995999537ed00a9e1ed196dac5a34c8362b9e454200968eb123c60d21530d2", "price_changes": [{"asset_id": "106415214145522966179186096977094978918005217851026867362814745409109043718965", "price": "0.478", "size": "5", "side": "BUY", "hash": "18f5a3f067587f0f6a32857e0e2da91d71613b0c", "best_bid": "0.977", "best_ask": "0.981"}, {"asset_id": "105244305087066947375390379713039474916834963808658829713388931041101255731949", "price": "0.522", "size": "5", "side": "SELL", "hash": "6586d5e908cf26719ba3eeb4feed7453fa14f6ba", "best_bid": "0.019", "best_ask": "0.023"}], "timestamp": "1769384689799", "event_type": "price_change"}}
{"_local_timestamp": "2026-01-25T23:44:54.796714+00:00", "data": {"market": "0xf2995999537ed00a9e1ed196dac5a34c8362b9e454200968eb123c60d21530d2", "price_changes": [{"asset_id": "105244305087066947375390379713039474916834963808658829713388931041101255731949", "price": "0.006", "size": "49.43", "side": "BUY", "hash": "2b6167446e5321caa7835c581c2eb73a91b85983", "best_bid": "0.019", "best_ask": "0.023"}, {"asset_id": "106415214145522966179186096977094978918005217851026867362814745409109043718965", "price": "0.994", "size": "49.43", "side": "SELL", "hash": "f52eb5fc1353d347d81a02f223cdfd20c4363169", "best_bid": "0.977", "best_ask": "0.981"}], "timestamp": "1769384694686", "event_type": "price_change"}}
{"_local_timestamp": "2026-01-25T23:44:54.797219+00:00", "data": {"market": "0xf2995999537ed00a9e1ed196dac5a34c8362b9e454200968eb123c60d21530d2", "price_changes": [{"asset_id": "105244305087066947375390379713039474916834963808658829713388931041101255731949", "price": "0.014", "size": "8.28", "side": "BUY", "hash": "2b6167446e5321caa7835c581c2eb73a91b85983", "best_bid": "0.019", "best_ask": "0.023"}, {"asset_id": "106415214145522966179186096977094978918005217851026867362814745409109043718965", "price": "0.986", "size": "8.28", "side": "SELL", "hash": "f52eb5fc1353d347d81a02f223cdfd20c4363169", "best_bid": "0.977", "best_ask": "0.981"}], "timestamp": "1769384694686", "event_type": "price_change"}}
{"_local_timestamp": "2026-01-25T23:44:54.797529+00:00", "data": {"market": "0xf2995999537ed00a9e1ed196dac5a34c8362b9e454200968eb123c60d21530d2", "price_changes": [{"asset_id": "105244305087066947375390379713039474916834963808658829713388931041101255731949", "price": "0.017", "size": "6.98", "side": "BUY", "hash": "2b6167446e5321caa7835c581c2eb73a91b85983", "best_bid": "0.019", "best_ask": "0.023"}, {"asset_id": "106415214145522966179186096977094978918005217851026867362814745409109043718965", "price": "0.983", "size": "6.98", "side": "SELL", "hash": "f52eb5fc1353d347d81a02f223cdfd20c4363169", "best_bid": "0.977", "best_ask": "0.981"}], "timestamp": "1769384694686", "event_type": "price_change"}}
{"_local_timestamp": "2026-01-25T23:44:55.573425+00:00", "data": {"market": "0xf2995999537ed00a9e1ed196dac5a34c8362b9e454200968eb123c60d21530d2", "price_changes": [{"asset_id": "105244305087066947375390379713039474916834963808658829713388931041101255731949", "price": "0.006", "size": "59.83", "side": "BUY", "hash": "13f0803b98fc1bc638cf42d9f1367a5ed11c06d5", "best_bid": "0.019", "best_ask": "0.023"}, {"asset_id": "106415214145522966179186096977094978918005217851026867362814745409109043718965", "price": "0.994", "size": "59.83", "side": "SELL", "hash": "8b8b596d7e1a1cf57f180f5b07193c397ce46000", "best_bid": "0.977", "best_ask": "0.981"}], "timestamp": "1769384695450", "event_type": "price_change"}}
{"_local_timestamp": "2026-01-25T23:44:55.573825+00:00", "data": {"market": "0xf2995999537ed00a9e1ed196dac5a34c8362b9e454200968eb123c60d21530d2", "price_changes": [{"asset_id": "105244305087066947375390379713039474916834963808658829713388931041101255731949", "price": "0.017", "size": "14.56", "side": "BUY", "hash": "537094858a7fe21ac0ba080052675e98018dda48", "best_bid": "0.019", "best_ask": "0.023"}, {"asset_id": "106415214145522966179186096977094978918005217851026867362814745409109043718965", "price": "0.983", "size": "14.56", "side": "SELL", "hash": "d9fe08a721b8b8e06fd96f7f792254f6c8797630", "best_bid": "0.977", "best_ask": "0.981"}], "timestamp": "1769384695457", "event_type": "price_change"}}
{"_local_timestamp": "2026-01-25T23:44:55.579072+00:00", "data": {"market": "0xf2995999537ed00a9e1ed196dac5a34c8362b9e454200968eb123c60d21530d2", "price_changes": [{"asset_id": "105244305087066947375390379713039474916834963808658829713388931041101255731949", "price": "0.014", "size": "18.03", "side": "BUY", "hash": "7e5118fdb1ab48e8a668839dc70091c7e1b08acf", "best_bid": "0.019", "best_ask": "0.023"}, {"asset_id": "106415214145522966179186096977094978918005217851026867362814745409109043718965", "price": "0.986", "size": "18.03", "side": "SELL", "hash": "dd880f504b354629d5f772ff68af7d6dd08ece39", "best_bid": "0.977", "best_ask": "0.981"}], "timestamp": "1769384695466", "event_type": "price_change"}}
{"_local_timestamp": "2026-01-25T23:44:56.723650+00:00", "data": {"market": "0xf2995999537ed00a9e1ed196dac5a34c8362b9e454200968eb123c60d21530d2", "price_changes": [{"asset_id": "105244305087066947375390379713039474916834963808658829713388931041101255731949", "price": "0.006", "size": "49.43", "side": "BUY", "hash": "af5449dcf467abeb155529605b5a40827ecd3f16", "best_bid": "0.019", "best_ask": "0.023"}, {"asset_id": "106415214145522966179186096977094978918005217851026867362814745409109043718965", "price": "0.994", "size": "49.43", "side": "SELL", "hash": "5a4e099500037047cc1bc317e17fdeb8f3d364b7", "best_bid": "0.977", "best_ask": "0.981"}], "timestamp": "1769384696644", "event_type": "price_change"}}
{"_local_timestamp": "2026-01-25T23:44:56.724054+00:00", "data": {"market": "0xf2995999537ed00a9e1ed196dac5a34c8362b9e454200968eb123c60d21530d2", "price_changes": [{"asset_id": "105244305087066947375390379713039474916834963808658829713388931041101255731949", "price": "0.014", "size": "8.28", "side": "BUY", "hash": "af5449dcf467abeb155529605b5a40827ecd3f16", "best_bid": "0.019", "best_ask": "0.023"}, {"asset_id": "106415214145522966179186096977094978918005217851026867362814745409109043718965", "price": "0.986", "size": "8.28", "side": "SELL", "hash": "5a4e099500037047cc1bc317e17fdeb8f3d364b7", "best_bid": "0.977", "best_ask": "0.981"}], "timestamp": "1769384696644", "event_type": "price_change"}}
{"_local_timestamp": "2026-01-25T23:44:56.724389+00:00", "data": {"market": "0xf2995999537ed00a9e1ed196dac5a34c8362b9e454200968eb123c60d21530d2", "price_changes": [{"asset_id": "105244305087066947375390379713039474916834963808658829713388931041101255731949", "price": "0.017", "size": "6.98", "side": "BUY", "hash": "af5449dcf467abeb155529605b5a40827ecd3f16", "best_bid": "0.019", "best_ask": "0.023"}, {"asset_id": "106415214145522966179186096977094978918005217851026867362814745409109043718965", "price": "0.983", "size": "6.98", "side": "SELL", "hash": "5a4e099500037047cc1bc317e17fdeb8f3d364b7", "best_bid": "0.977", "best_ask": "0.981"}], "timestamp": "1769384696644", "event_type": "price_change"}}
{"_local_timestamp": "2026-01-25T23:44:57.168734+00:00", "data": {"market": "0xf2995999537ed00a9e1ed196dac5a34c8362b9e454200968eb123c60d21530d2", "price_changes": [{"asset_id": "105244305087066947375390379713039474916834963808658829713388931041101255731949", "price": "0.006", "size": "59.83", "side": "BUY", "hash": "9bd424ba26e2ef91017342a8a7b5e4a3638517f0", "best_bid": "0.019", "best_ask": "0.023"}, {"asset_id": "106415214145522966179186096977094978918005217851026867362814745409109043718965", "price": "0.994", "size": "59.83", "side": "SELL", "hash": "17afdb3f23a3549ca229a8b7d434f8a856138441", "best_bid": "0.977", "best_ask": "0.981"}], "timestamp": "1769384697082", "event_type": "price_change"}}
{"_local_timestamp": "2026-01-25T23:44:57.169132+00:00", "data": {"market": "0xf2995999537ed00a9e1ed196dac5a34c8362b9e454200968eb123c60d21530d2", "price_changes": [{"asset_id": "105244305087066947375390379713039474916834963808658829713388931041101255731949", "price": "0.017", "size": "14.56", "side": "BUY", "hash": "7a782ced62ae1c00b160aafb2093857abb56e408", "best_bid": "0.019", "best_ask": "0.023"}, {"asset_id": "106415214145522966179186096977094978918005217851026867362814745409109043718965", "price": "0.983", "size": "14.56", "side": "SELL", "hash": "bfa642cce2b9981b45772bba5545c38f8a025476", "best_bid": "0.977", "best_ask": "0.981"}], "timestamp": "1769384697083", "event_type": "price_change"}}
{"_local_timestamp": "2026-01-25T23:44:57.171496+00:00", "data": {"market": "0xf2995999537ed00a9e1ed196dac5a34c8362b9e454200968eb123c60d21530d2", "price_changes": [{"asset_id": "105244305087066947375390379713039474916834963808658829713388931041101255731949", "price": "0.014", "size": "18.03", "side": "BUY", "hash": "4663e197b59de54c11ec0ab6a0f8cdd757ab9487", "best_bid": "0.019", "best_ask": "0.023"}, {"asset_id": "106415214145522966179186096977094978918005217851026867362814745409109043718965", "price": "0.986", "size": "18.03", "side": "SELL", "hash": "f48d710565a4abf9263d9b5b6d137f62dfde2fd3", "best_bid": "0.977", "best_ask": "0.981"}], "timestamp": "1769384697084", "event_type": "price_change"}}
{"_local_timestamp": "2026-01-25T23:44:59.060227+00:00", "data": {"market": "0x0e34316a55bc233e7a3413a93c42c66072b7ac502d76e2bc66884b3816ee6e07", "price_changes": [{"asset_id": "107862542344757352141146430276434917083046632354992038304792604470800981194112", "price": "0.99", "size": "1242.62", "side": "BUY", "hash": "1ce45fbe74a57609e70762a5f5c17813b30d2941", "best_bid": "0.998", "best_ask": "0.999"}, {"asset_id": "76761029218476112031409759115795427470125890678375395683863252655472602921499", "price": "0.01", "size": "1242.62", "side": "SELL", "hash": "a49bc59c1f42b8b215a99140cfb28e0e8a859c02", "best_bid": "0.001", "best_ask": "0.002"}], "timestamp": "1769384698976", "event_type": "price_change"}}
{"_local_timestamp": "2026-01-25T23:44:59.060544+00:00", "data": {"market": "0x8298fb2a176db2e46ceb5aff2ddff61aca1fdac933c02a4a9e1643bd12c1c7a5", "price_changes": [{"asset_id": "35897551024644058529519358120193216211748306981601166224061602740309627186051", "price": "0.99", "size": "300", "side": "BUY", "hash": "06b38ea54ef44746f5fc9a11f41a6f1460745849", "best_bid": "0.997", "best_ask": "0.999"}, {"asset_id": "7993116773810665385123830809052135747764218356289251597248975813552433650614", "price": "0.01", "size": "300", "side": "SELL", "hash": "f847ca6e627d3824f3725251dd8227a0e3d159cc", "best_bid": "0.001", "best_ask": "0.003"}], "timestamp": "1769384698976", "event_type": "price_change"}}
{"_local_timestamp": "2026-01-25T23:44:59.060791+00:00", "data": {"market": "0x4a00aea8c3beebfbd78428ed9794389a6064031b3b4498ecee8f1e2567960c52", "price_changes": [{"asset_id": "25647280398479894832229021619345962565230978912320531311978302103412384666485", "price": "0.99", "size": "0", "side": "BUY", "hash": "7bfd59417b7083ff045fe99c3628a7216f8baa66", "best_bid": "0.995", "best_ask": "0.998"}, {"asset_id": "28282613628199947618108198992841847089900837455551648546884564075036732056803", "price": "0.01", "size": "0", "side": "SELL", "hash": "6db4b7c5a45862af910dbd77aa9d878c62bea476", "best_bid": "0.002", "best_ask": "0.005"}], "timestamp": "1769384698976", "event_type": "price_change"}}
{"_local_timestamp": "2026-01-25T23:44:59.061023+00:00", "data": {"market": "0x2a74a7cd29971c3a320eec0595c20a07d9a2cbc501c99694d34963e38a196682", "price_changes": [{"asset_id": "40042411695863369998216770625571070530892534611209558876495072542089465066752", "price": "0.99", "size": "607.26", "side": "BUY", "hash": "7e010af1ae7b4b8ff2e6954dc1e8ccf64052920c", "best_bid": "0.998", "best_ask": "0.999"}, {"asset_id": "35311691331065078920223858384826797458646117898089239758404119138722819634257", "price": "0.01", "size": "607.26", "side": "SELL", "hash": "2fb1b2e546933afbc4aa87978f0258c0fa203be7", "best_bid": "0.001", "best_ask": "0.002"}], "timestamp": "1769384698976", "event_type": "price_change"}}
{"_local_timestamp": "2026-01-25T23:44:59.061250+00:00", "data": {"market": "0xe0e842b31506fda8023595ae777aa10df28ecd9c22c1f1409a7f8712eda7e879", "price_changes": [{"asset_id": "109396302302451946277463128776199432259939419558255720043997107356989321269700", "price": "0.99", "size": "820.31", "side": "BUY", "hash": "9d84b89226a5758c6338dff558059c58152502bf", "best_bid": "0.997", "best_ask": "0.999"}, {"asset_id": "108109838300131904793645757730015721729233228300378400579897924202651980716760", "price": "0.01", "size": "820.31", "side": "SELL", "hash": "7c52a03f32ed85e853016570d7bbb0e90be2e3b5", "best_bid": "0.001", "best_ask": "0.003"}], "timestamp": "1769384698976", "event_type": "price_change"}}
{"_local_timestamp": "2026-01-25T23:44:59.361335+00:00", "data": {"market": "0xf2995999537ed00a9e1ed196dac5a34c8362b9e454200968eb123c60d21530d2", "price_changes": [{"asset_id": "105244305087066947375390379713039474916834963808658829713388931041101255731949", "price": "0.006", "size": "49.43", "side": "BUY", "hash": "8b13b130a34942cb33032141849e0c8b38c5db11", "best_bid": "0.019", "best_ask": "0.023"}, {"asset_id": "106415214145522966179186096977094978918005217851026867362814745409109043718965", "price": "0.994", "size": "49.43", "side": "SELL", "hash": "97c40656e3e945156cd10021710dc3dcc04bfe53", "best_bid": "0.977", "best_ask": "0.981"}], "timestamp": "1769384699280", "event_type": "price_change"}}
{"_local_timestamp": "2026-01-25T23:44:59.361786+00:00", "data": {"market": "0xf2995999537ed00a9e1ed196dac5a34c8362b9e454200968eb123c60d21530d2", "price_changes": [{"asset_id": "105244305087066947375390379713039474916834963808658829713388931041101255731949", "price": "0.014", "size": "8.28", "side": "BUY", "hash": "8b13b130a34942cb33032141849e0c8b38c5db11", "best_bid": "0.019", "best_ask": "0.023"}, {"asset_id": "106415214145522966179186096977094978918005217851026867362814745409109043718965", "price": "0.986", "size": "8.28", "side": "SELL", "hash": "97c40656e3e945156cd10021710dc3dcc04bfe53", "best_bid": "0.977", "best_ask": "0.981"}], "timestamp": "1769384699280", "event_type": "price_change"}}
{"_local_timestamp": "2026-01-25T23:44:59.362163+00:00", "data": {"market": "0xf2995999537ed00a9e1ed196dac5a34c8362b9e454200968eb123c60d21530d2", "price_changes": [{"asset_id": "105244305087066947375390379713039474916834963808658829713388931041101255731949", "price": "0.017", "size": "6.98", "side": "BUY", "hash": "8b13b130a34942cb33032141849e0c8b38c5db11", "best_bid": "0.019", "best_ask": "0.023"}, {"asset_id": "106415214145522966179186096977094978918005217851026867362814745409109043718965", "price": "0.983", "size": "6.98", "side": "SELL", "hash": "97c40656e3e945156cd10021710dc3dcc04bfe53", "best_bid": "0.977", "best_ask": "0.981"}], "timestamp": "1769384699280", "event_type": "price_change"}}
{"_local_timestamp": "2026-01-25T23:45:00.372714+00:00", "data": {"market": "0xf2995999537ed00a9e1ed196dac5a34c8362b9e454200968eb123c60d21530d2", "price_changes": [{"asset_id": "105244305087066947375390379713039474916834963808658829713388931041101255731949", "price": "0.015", "size": "34.24", "side": "BUY", "hash": "90632b1078656ace40a09caea2ec59261c46b56d", "best_bid": "0.019", "best_ask": "0.023"}, {"asset_id": "106415214145522966179186096977094978918005217851026867362814745409109043718965", "price": "0.985", "size": "34.24", "side": "SELL", "hash": "5e963f05668996756d959fbeecad4e20dbcc5e07", "best_bid": "0.977", "best_ask": "0.981"}], "timestamp": "1769384700306", "event_type": "price_change"}}
{"_local_timestamp": "2026-01-25T23:45:00.373149+00:00", "data": {"market": "0xf2995999537ed00a9e1ed196dac5a34c8362b9e454200968eb123c60d21530d2", "price_changes": [{"asset_id": "105244305087066947375390379713039474916834963808658829713388931041101255731949", "price": "0.007", "size": "27.5", "side": "BUY", "hash": "80f05479148892614e88f747ea4e3698bc7e73c8", "best_bid": "0.019", "best_ask": "0.023"}, {"asset_id": "106415214145522966179186096977094978918005217851026867362814745409109043718965", "price": "0.993", "size": "27.5", "side": "SELL", "hash": "8e8009e9de19e5c41327e8ec447a115d928c2e9f", "best_bid": "0.977", "best_ask": "0.981"}], "timestamp": "1769384700307", "event_type": "price_change"}}
{"_local_timestamp": "2026-01-25T23:45:00.389960+00:00", "data": {"market": "0xf2995999537ed00a9e1ed196dac5a34c8362b9e454200968eb123c60d21530d2", "price_changes": [{"asset_id": "105244305087066947375390379713039474916834963808658829713388931041101255731949", "price": "0.018", "size": "33.04", "side": "BUY", "hash": "e09f9b595445d6fa4fd55a42e67302d128b297b5", "best_bid": "0.019", "best_ask": "0.023"}, {"asset_id": "106415214145522966179186096977094978918005217851026867362814745409109043718965", "price": "0.982", "size": "33.04", "side": "SELL", "hash": "020cfa938c48ca8d741b3a4af1ad4c746ee27705", "best_bid": "0.977", "best_ask": "0.981"}], "timestamp": "1769384700308", "event_type": "price_change"}}
{"_local_timestamp": "2026-01-25T23:45:02.740119+00:00", "data": {"market": "0xf2995999537ed00a9e1ed196dac5a34c8362b9e454200968eb123c60d21530d2", "price_changes": [{"asset_id": "105244305087066947375390379713039474916834963808658829713388931041101255731949", "price": "0.007", "size": "16", "side": "BUY", "hash": "772d7230a87a6d1423e15372a775117b99721d2b", "best_bid": "0.019", "best_ask": "0.023"}, {"asset_id": "106415214145522966179186096977094978918005217851026867362814745409109043718965", "price": "0.993", "size": "16", "side": "SELL", "hash": "a41e335f224af41a65ade02b0bd65e2a61e27d63", "best_bid": "0.977", "best_ask": "0.981"}], "timestamp": "1769384702671", "event_type": "price_change"}}
{"_local_timestamp": "2026-01-25T23:45:02.740469+00:00", "data": {"market": "0xf2995999537ed00a9e1ed196dac5a34c8362b9e454200968eb123c60d21530d2", "price_changes": [{"asset_id": "105244305087066947375390379713039474916834963808658829713388931041101255731949", "price": "0.015", "size": "25.97", "side": "BUY", "hash": "772d7230a87a6d1423e15372a775117b99721d2b", "best_bid": "0.019", "best_ask": "0.023"}, {"asset_id": "106415214145522966179186096977094978918005217851026867362814745409109043718965", "price": "0.985", "size": "25.97", "side": "SELL", "hash": "a41e335f224af41a65ade02b0bd65e2a61e27d63", "best_bid": "0.977", "best_ask": "0.981"}], "timestamp": "1769384702671", "event_type": "price_change"}}
{"_local_timestamp": "2026-01-25T23:45:02.740736+00:00", "data": {"market": "0xf2995999537ed00a9e1ed196dac5a34c8362b9e454200968eb123c60d21530d2", "price_changes": [{"asset_id": "105244305087066947375390379713039474916834963808658829713388931041101255731949", "price": "0.018", "size": "26.2", "side": "BUY", "hash": "772d7230a87a6d1423e15372a775117b99721d2b", "best_bid": "0.019", "best_ask": "0.023"}, {"asset_id": "106415214145522966179186096977094978918005217851026867362814745409109043718965", "price": "0.982", "size": "26.2", "side": "SELL", "hash": "a41e335f224af41a65ade02b0bd65e2a61e27d63", "best_bid": "0.977", "best_ask": "0.981"}], "timestamp": "1769384702671", "event_type": "price_change"}}
{"_local_timestamp": "2026-01-25T23:45:03.254865+00:00", "data": {"market": "0xf2995999537ed00a9e1ed196dac5a34c8362b9e454200968eb123c60d21530d2", "price_changes": [{"asset_id": "105244305087066947375390379713039474916834963808658829713388931041101255731949", "price": "0.008", "size": "28.32", "side": "BUY", "hash": "846f6f88034badc84e6c84d13a88182c0dfe8a48", "best_bid": "0.019", "best_ask": "0.023"}, {"asset_id": "106415214145522966179186096977094978918005217851026867362814745409109043718965", "price": "0.992", "size": "28.32", "side": "SELL", "hash": "63e893d90058fa400efc0cdd1cd4e560e804c814", "best_bid": "0.977", "best_ask": "0.981"}], "timestamp": "1769384703174", "event_type": "price_change"}}
{"_local_timestamp": "2026-01-25T23:45:03.255259+00:00", "data": {"market": "0xf2995999537ed00a9e1ed196dac5a34c8362b9e454200968eb123c60d21530d2", "price_changes": [{"asset_id": "105244305087066947375390379713039474916834963808658829713388931041101255731949", "price": "0.017", "size": "12.97", "side": "BUY", "hash": "4b7cd2d21fc7f074e4e858dae342682cf35d6dec", "best_bid": "0.019", "best_ask": "0.023"}, {"asset_id": "106415214145522966179186096977094978918005217851026867362814745409109043718965", "price": "0.983", "size": "12.97", "side": "SELL", "hash": "6e222f1ce1bc415fabed5c6fb23872b0c9d67ecb", "best_bid": "0.977", "best_ask": "0.981"}], "timestamp": "1769384703176", "event_type": "price_change"}}
{"_local_timestamp": "2026-01-25T23:45:03.255540+00:00", "data": {"market": "0xf2995999537ed00a9e1ed196dac5a34c8362b9e454200968eb123c60d21530d2", "price_changes": [{"asset_id": "105244305087066947375390379713039474916834963808658829713388931041101255731949", "price": "0.014", "size": "15.98", "side": "BUY", "hash": "b338e294fee16a726dde865ea9fa83487ed24ad8", "best_bid": "0.019", "best_ask": "0.023"}, {"asset_id": "106415214145522966179186096977094978918005217851026867362814745409109043718965", "price": "0.986", "size": "15.98", "side": "SELL", "hash": "077dd39a05e80d7d5ec067a7a7c3b12eb48b4826", "best_bid": "0.977", "best_ask": "0.981"}], "timestamp": "1769384703177", "event_type": "price_change"}}
{"_local_timestamp": "2026-01-25T23:45:04.010683+00:00", "data": {"market": "0xf2995999537ed00a9e1ed196dac5a34c8362b9e454200968eb123c60d21530d2", "price_changes": [{"asset_id": "105244305087066947375390379713039474916834963808658829713388931041101255731949", "price": "0.008", "size": "13.56", "side": "BUY", "hash": "f8a24d26e6b81867f5519505b5ffb3907809d5b7", "best_bid": "0.019", "best_ask": "0.023"}, {"asset_id": "106415214145522966179186096977094978918005217851026867362814745409109043718965", "price": "0.992", "size": "13.56", "side": "SELL", "hash": "12e3c029c4323e9e7a38d429b27fc7ddd84046b6", "best_bid": "0.977", "best_ask": "0.981"}], "timestamp": "1769384703944", "event_type": "price_change"}}
{"_local_timestamp": "2026-01-25T23:45:04.495925+00:00", "data": {"market": "0xf2995999537ed00a9e1ed196dac5a34c8362b9e454200968eb123c60d21530d2", "price_changes": [{"asset_id": "105244305087066947375390379713039474916834963808658829713388931041101255731949", "price": "0.006", "size": "66.67", "side": "BUY", "hash": "33b37730fcbefe078b57ebbbd3daf44d27b1b276", "best_bid": "0.019", "best_ask": "0.023"}, {"asset_id": "106415214145522966179186096977094978918005217851026867362814745409109043718965", "price": "0.994", "size": "66.67", "side": "SELL", "hash": "6f8bd4aeb6e8974c088a1ad2939f232675bc0bca", "best_bid": "0.977", "best_ask": "0.981"}], "timestamp": "1769384704419", "event_type": "price_change"}}
{"_local_timestamp": "2026-01-25T23:45:04.496304+00:00", "data": {"market": "0xf2995999537ed00a9e1ed196dac5a34c8362b9e454200968eb123c60d21530d2", "price_changes": [{"asset_id": "105244305087066947375390379713039474916834963808658829713388931041101255731949", "price": "0.002", "size": "226.9", "side": "BUY", "hash": "ee126901453e880454b6d8808d8756b6e370444d", "best_bid": "0.019", "best_ask": "0.023"}, {"asset_id": "106415214145522966179186096977094978918005217851026867362814745409109043718965", "price": "0.998", "size": "226.9", "side": "SELL", "hash": "178c85adb298ad2394e4c7532589af40d8e9e1ac", "best_bid": "0.977", "best_ask": "0.981"}], "timestamp": "1769384704420", "event_type": "price_change"}}
{"_local_timestamp": "2026-01-25T23:45:06.363176+00:00", "data": {"market": "0xf2995999537ed00a9e1ed196dac5a34c8362b9e454200968eb123c60d21530d2", "price_changes": [{"asset_id": "105244305087066947375390379713039474916834963808658829713388931041101255731949", "price": "0.002", "size": "219.53", "side": "BUY", "hash": "effad8f7662e48d3356007172ce23a33e3eb388e", "best_bid": "0.019", "best_ask": "0.023"}, {"asset_id": "106415214145522966179186096977094978918005217851026867362814745409109043718965", "price": "0.998", "size": "219.53", "side": "SELL", "hash": "cc6dd995b32f9f616fc5509718b35bf023edbc27", "best_bid": "0.977", "best_ask": "0.981"}], "timestamp": "1769384706281", "event_type": "price_change"}}
{"_local_timestamp": "2026-01-25T23:45:06.363538+00:00", "data": {"market": "0xf2995999537ed00a9e1ed196dac5a34c8362b9e454200968eb123c60d21530d2", "price_changes": [{"asset_id": "105244305087066947375390379713039474916834963808658829713388931041101255731949", "price": "0.006", "size": "49.43", "side": "BUY", "hash": "effad8f7662e48d3356007172ce23a33e3eb388e", "best_bid": "0.019", "best_ask": "0.023"}, {"asset_id": "106415214145522966179186096977094978918005217851026867362814745409109043718965", "price": "0.994", "size": "49.43", "side": "SELL", "hash": "cc6dd995b32f9f616fc5509718b35bf023edbc27", "best_bid": "0.977", "best_ask": "0.981"}], "timestamp": "1769384706281", "event_type": "price_change"}}
{"_local_timestamp": "2026-01-25T23:45:06.788779+00:00", "data": {"market": "0xf2995999537ed00a9e1ed196dac5a34c8362b9e454200968eb123c60d21530d2", "price_changes": [{"asset_id": "105244305087066947375390379713039474916834963808658829713388931041101255731949", "price": "0.007", "size": "32.89", "side": "BUY", "hash": "c9d016d661940eb0afff23f1ba30405d13bf1dc4", "best_bid": "0.019", "best_ask": "0.023"}, {"asset_id": "106415214145522966179186096977094978918005217851026867362814745409109043718965", "price": "0.993", "size": "32.89", "side": "SELL", "hash": "abfa4ab3b8326120663a1836c23be111b6c05117", "best_bid": "0.977", "best_ask": "0.981"}], "timestamp": "1769384706719", "event_type": "price_change"}}
{"_local_timestamp": "2026-01-25T23:45:07.741448+00:00", "data": {"market": "0xf2995999537ed00a9e1ed196dac5a34c8362b9e454200968eb123c60d21530d2", "price_changes": [{"asset_id": "105244305087066947375390379713039474916834963808658829713388931041101255731949", "price": "0.007", "size": "16", "side": "BUY", "hash": "c6bf364c3d43d7ad2c8b903cea7871884527f60a", "best_bid": "0.019", "best_ask": "0.023"}, {"asset_id": "106415214145522966179186096977094978918005217851026867362814745409109043718965", "price": "0.993", "size": "16", "side": "SELL", "hash": "81a8d5b57a8887f9d5db12a2b3da314bd93325d6", "best_bid": "0.977", "best_ask": "0.981"}], "timestamp": "1769384707670", "event_type": "price_change"}}
{"_local_timestamp": "2026-01-25T23:45:08.212661+00:00", "data": {"market": "0xf2995999537ed00a9e1ed196dac5a34c8362b9e454200968eb123c60d21530d2", "price_changes": [{"asset_id": "105244305087066947375390379713039474916834963808658829713388931041101255731949", "price": "0.002", "size": "226.9", "side": "BUY", "hash": "f389bae060a754d4a651d3670934fcb88efb2022", "best_bid": "0.019", "best_ask": "0.023"}, {"asset_id": "106415214145522966179186096977094978918005217851026867362814745409109043718965", "price": "0.998", "size": "226.9", "side": "SELL", "hash": "483e1294d8d07e22b56eaf806fa874ada183f02c", "best_bid": "0.977", "best_ask": "0.981"}], "timestamp": "1769384708148", "event_type": "price_change"}}
{"_local_timestamp": "2026-01-25T23:45:08.220505+00:00", "data": {"market": "0xf2995999537ed00a9e1ed196dac5a34c8362b9e454200968eb123c60d21530d2", "price_changes": [{"asset_id": "105244305087066947375390379713039474916834963808658829713388931041101255731949", "price": "0.006", "size": "66.67", "side": "BUY", "hash": "d322e6b63f117e89c4570740fe301293ab4df2bb", "best_bid": "0.019", "best_ask": "0.023"}, {"asset_id": "106415214145522966179186096977094978918005217851026867362814745409109043718965", "price": "0.994", "size": "66.67", "side": "SELL", "hash": "950b99e92d7ef352adca93e3c9ec8d1832e41c4e", "best_bid": "0.977", "best_ask": "0.981"}], "timestamp": "1769384708149", "event_type": "price_change"}}
{"_local_timestamp": "2026-01-25T23:45:09.624287+00:00", "data": {"market": "0xf2995999537ed00a9e1ed196dac5a34c8362b9e454200968eb123c60d21530d2", "price_changes": [{"asset_id": "105244305087066947375390379713039474916834963808658829713388931041101255731949", "price": "0.002", "size": "219.53", "side": "BUY", "hash": "023d5166a611b70816b7da3789269de82cab1776", "best_bid": "0.019", "best_ask": "0.023"}, {"asset_id": "106415214145522966179186096977094978918005217851026867362814745409109043718965", "price": "0.998", "size": "219.53", "side": "SELL", "hash": "1c26b55afdaa3ac2e1f49d2fcf171474a972c9d3", "best_bid": "0.977", "best_ask": "0.981"}], "timestamp": "1769384709550", "event_type": "price_change"}}
{"_local_timestamp": "2026-01-25T23:45:09.624658+00:00", "data": {"market": "0xf2995999537ed00a9e1ed196dac5a34c8362b9e454200968eb123c60d21530d2", "price_changes": [{"asset_id": "105244305087066947375390379713039474916834963808658829713388931041101255731949", "price": "0.006", "size": "49.43", "side": "BUY", "hash": "023d5166a611b70816b7da3789269de82cab1776", "best_bid": "0.019", "best_ask": "0.023"}, {"asset_id": "106415214145522966179186096977094978918005217851026867362814745409109043718965", "price": "0.994", "size": "49.43", "side": "SELL", "hash": "1c26b55afdaa3ac2e1f49d2fcf171474a972c9d3", "best_bid": "0.977", "best_ask": "0.981"}], "timestamp": "1769384709550", "event_type": "price_change"}}
{"_local_timestamp": "2026-01-25T23:45:10.052004+00:00", "data": {"market": "0xf2995999537ed00a9e1ed196dac5a34c8362b9e454200968eb123c60d21530d2", "price_changes": [{"asset_id": "105244305087066947375390379713039474916834963808658829713388931041101255731949", "price": "0.007", "size": "32.89", "side": "BUY", "hash": "ae35f45f190c1e006d5892188cedb3cb412170eb", "best_bid": "0.019", "best_ask": "0.023"}, {"asset_id": "106415214145522966179186096977094978918005217851026867362814745409109043718965", "price": "0.993", "size": "32.89", "side": "SELL", "hash": "77191119b318a7270d5b96b7b75f6a45d2cb17a4", "best_bid": "0.977", "best_ask": "0.981"}], "timestamp": "1769384709983", "event_type": "price_change"}}
{"_local_timestamp": "2026-01-25T23:45:10.528025+00:00", "data": {"market": "0xf2995999537ed00a9e1ed196dac5a34c8362b9e454200968eb123c60d21530d2", "price_changes": [{"asset_id": "105244305087066947375390379713039474916834963808658829713388931041101255731949", "price": "0.007", "size": "16", "side": "BUY", "hash": "827f75898e7488e2ea586b2285689269895ac081", "best_bid": "0.019", "best_ask": "0.023"}, {"asset_id": "106415214145522966179186096977094978918005217851026867362814745409109043718965", "price": "0.993", "size": "16", "side": "SELL", "hash": "0b0809e87361deebfd6146a3499760f60f6b9c74", "best_bid": "0.977", "best_ask": "0.981"}], "timestamp": "1769384710454", "event_type": "price_change"}}
{"_local_timestamp": "2026-01-25T23:45:11.005194+00:00", "data": {"market": "0xf2995999537ed00a9e1ed196dac5a34c8362b9e454200968eb123c60d21530d2", "price_changes": [{"asset_id": "105244305087066947375390379713039474916834963808658829713388931041101255731949", "price": "0.002", "size": "226.9", "side": "BUY", "hash": "010f4c55bf8d6e4baf3bfe9e79c2a6011e5050f4", "best_bid": "0.019", "best_ask": "0.023"}, {"asset_id": "106415214145522966179186096977094978918005217851026867362814745409109043718965", "price": "0.998", "size": "226.9", "side": "SELL", "hash": "60159a434636805b514aae9599a6259c140149fe", "best_bid": "0.977", "best_ask": "0.981"}], "timestamp": "1769384710936", "event_type": "price_change"}}
{"_local_timestamp": "2026-01-25T23:45:11.005518+00:00", "data": {"market": "0xf2995999537ed00a9e1ed196dac5a34c8362b9e454200968eb123c60d21530d2", "price_changes": [{"asset_id": "105244305087066947375390379713039474916834963808658829713388931041101255731949", "price": "0.006", "size": "66.67", "side": "BUY", "hash": "d0fb755f6c7c45fe7a5be77418511eb6121dfc11", "best_bid": "0.019", "best_ask": "0.023"}, {"asset_id": "106415214145522966179186096977094978918005217851026867362814745409109043718965", "price": "0.994", "size": "66.67", "side": "SELL", "hash": "dd76d06da78f50323c47a8ec3fe471c5ed551bd2", "best_bid": "0.977", "best_ask": "0.981"}], "timestamp": "1769384710937", "event_type": "price_change"}}
{"_local_timestamp": "2026-01-25T23:45:12.081331+00:00", "data": {"market": "0xf2995999537ed00a9e1ed196dac5a34c8362b9e454200968eb123c60d21530d2", "price_changes": [{"asset_id": "105244305087066947375390379713039474916834963808658829713388931041101255731949", "price": "0.002", "size": "219.53", "side": "BUY", "hash": "13d44dd386d25ac70ecf3f2970aae2d6c8cef15b", "best_bid": "0.019", "best_ask": "0.023"}, {"asset_id": "106415214145522966179186096977094978918005217851026867362814745409109043718965", "price": "0.998", "size": "219.53", "side": "SELL", "hash": "0562a69eae40585a1d8423abd5072afd5bac6a4a", "best_bid": "0.977", "best_ask": "0.981"}], "timestamp": "1769384711910", "event_type": "price_change"}}
{"_local_timestamp": "2026-01-25T23:45:12.081684+00:00", "data": {"market": "0xf2995999537ed00a9e1ed196dac5a34c8362b9e454200968eb123c60d21530d2", "price_changes": [{"asset_id": "105244305087066947375390379713039474916834963808658829713388931041101255731949", "price": "0.006", "size": "49.43", "side": "BUY", "hash": "13d44dd386d25ac70ecf3f2970aae2d6c8cef15b", "best_bid": "0.019", "best_ask": "0.023"}, {"asset_id": "106415214145522966179186096977094978918005217851026867362814745409109043718965", "price": "0.994", "size": "49.43", "side": "SELL", "hash": "0562a69eae40585a1d8423abd5072afd5bac6a4a", "best_bid": "0.977", "best_ask": "0.981"}], "timestamp": "1769384711910", "event_type": "price_change"}}
{"_local_timestamp": "2026-01-25T23:45:12.316605+00:00", "data": {"market": "0xf2995999537ed00a9e1ed196dac5a34c8362b9e454200968eb123c60d21530d2", "price_changes": [{"asset_id": "105244305087066947375390379713039474916834963808658829713388931041101255731949", "price": "0.007", "size": "32.89", "side": "BUY", "hash": "9b42ce143cf61e9e0abd8b56c4c76cd8b2f3c7b1", "best_bid": "0.019", "best_ask": "0.023"}, {"asset_id": "106415214145522966179186096977094978918005217851026867362814745409109043718965", "price": "0.993", "size": "32.89", "side": "SELL", "hash": "a04e8594bd575a96752f678e92585e7925110069", "best_bid": "0.977", "best_ask": "0.981"}], "timestamp": "1769384712252", "event_type": "price_change"}}
{"_local_timestamp": "2026-01-25T23:45:14.337832+00:00", "data": {"market": "0xf2995999537ed00a9e1ed196dac5a34c8362b9e454200968eb123c60d21530d2", "price_changes": [{"asset_id": "105244305087066947375390379713039474916834963808658829713388931041101255731949", "price": "0.007", "size": "16", "side": "BUY", "hash": "d7b9406b3f2140b8e4e4fb5035a2acdf385ee58a", "best_bid": "0.019", "best_ask": "0.023"}, {"asset_id": "106415214145522966179186096977094978918005217851026867362814745409109043718965", "price": "0.993", "size": "16", "side": "SELL", "hash": "63637e14482555d32a8e7364ffc160d72a455684", "best_bid": "0.977", "best_ask": "0.981"}], "timestamp": "1769384714267", "event_type": "price_change"}}
{"_local_timestamp": "2026-01-25T23:45:14.722745+00:00", "data": {"market": "0xf2995999537ed00a9e1ed196dac5a34c8362b9e454200968eb123c60d21530d2", "price_changes": [{"asset_id": "105244305087066947375390379713039474916834963808658829713388931041101255731949", "price": "0.008", "size": "28.34", "side": "BUY", "hash": "7890e419e94b46d3df80b2d5f00afd40fe2a2013", "best_bid": "0.019", "best_ask": "0.023"}, {"asset_id": "106415214145522966179186096977094978918005217851026867362814745409109043718965", "price": "0.992", "size": "28.34", "side": "SELL", "hash": "f4db68c260afbf21e05485f0d9f2c20bce99880f", "best_bid": "0.977", "best_ask": "0.981"}], "timestamp": "1769384714648", "event_type": "price_change"}}
{"_local_timestamp": "2026-01-25T23:45:17.289321+00:00", "data": {"market": "0xf2995999537ed00a9e1ed196dac5a34c8362b9e454200968eb123c60d21530d2", "price_changes": [{"asset_id": "105244305087066947375390379713039474916834963808658829713388931041101255731949", "price": "0.008", "size": "13.56", "side": "BUY", "hash": "f20906daf74ae13472452238e9fc9fb7aabc9680", "best_bid": "0.019", "best_ask": "0.023"}, {"asset_id": "106415214145522966179186096977094978918005217851026867362814745409109043718965", "price": "0.992", "size": "13.56", "side": "SELL", "hash": "18886db5d58c3c7655f384d5febe02c186ac1bbe", "best_bid": "0.977", "best_ask": "0.981"}], "timestamp": "1769384717208", "event_type": "price_change"}}
{"_local_timestamp": "2026-01-25T23:45:17.817882+00:00", "data": {"market": "0xf2995999537ed00a9e1ed196dac5a34c8362b9e454200968eb123c60d21530d2", "price_changes": [{"asset_id": "105244305087066947375390379713039474916834963808658829713388931041101255731949", "price": "0.006", "size": "66.67", "side": "BUY", "hash": "e14a0c8a10a71d69eacbaf3ede7293caaef6150a", "best_bid": "0.019", "best_ask": "0.023"}, {"asset_id": "106415214145522966179186096977094978918005217851026867362814745409109043718965", "price": "0.994", "size": "66.67", "side": "SELL", "hash": "cc25ef3b4fe7dcd4eb495636e12f01a2f3136e10", "best_bid": "0.977", "best_ask": "0.981"}], "timestamp": "1769384717755", "event_type": "price_change"}}
{"_local_timestamp": "2026-01-25T23:45:17.824447+00:00", "data": {"market": "0xf2995999537ed00a9e1ed196dac5a34c8362b9e454200968eb123c60d21530d2", "price_changes": [{"asset_id": "105244305087066947375390379713039474916834963808658829713388931041101255731949", "price": "0.002", "size": "226.9", "side": "BUY", "hash": "1605d0c7a07e2a5f6a4c68345fb62298ea09f9ef", "best_bid": "0.019", "best_ask": "0.023"}, {"asset_id": "106415214145522966179186096977094978918005217851026867362814745409109043718965", "price": "0.998", "size": "226.9", "side": "SELL", "hash": "6bbc7086f94ad36fe76051527455b0bfc46257b9", "best_bid": "0.977", "best_ask": "0.981"}], "timestamp": "1769384717756", "event_type": "price_change"}}
{"_local_timestamp": "2026-01-25T23:45:18.533354+00:00", "data": {"market": "0xf2995999537ed00a9e1ed196dac5a34c8362b9e454200968eb123c60d21530d2", "price_changes": [{"asset_id": "105244305087066947375390379713039474916834963808658829713388931041101255731949", "price": "0.002", "size": "219.53", "side": "BUY", "hash": "8e794ea90f0a98c144690dbaae9e65af31be3f66", "best_bid": "0.019", "best_ask": "0.023"}, {"asset_id": "106415214145522966179186096977094978918005217851026867362814745409109043718965", "price": "0.998", "size": "219.53", "side": "SELL", "hash": "982cdfc605937c4dc6bffeffb072cb3af6c654f6", "best_bid": "0.977", "best_ask": "0.981"}], "timestamp": "1769384718450", "event_type": "price_change"}}
{"_local_timestamp": "2026-01-25T23:45:18.533676+00:00", "data": {"market": "0xf2995999537ed00a9e1ed196dac5a34c8362b9e454200968eb123c60d21530d2", "price_changes": [{"asset_id": "105244305087066947375390379713039474916834963808658829713388931041101255731949", "price": "0.006", "size": "49.43", "side": "BUY", "hash": "8e794ea90f0a98c144690dbaae9e65af31be3f66", "best_bid": "0.019", "best_ask": "0.023"}, {"asset_id": "106415214145522966179186096977094978918005217851026867362814745409109043718965", "price": "0.994", "size": "49.43", "side": "SELL", "hash": "982cdfc605937c4dc6bffeffb072cb3af6c654f6", "best_bid": "0.977", "best_ask": "0.981"}], "timestamp": "1769384718450", "event_type": "price_change"}}
{"_local_timestamp": "2026-01-25T23:45:18.945182+00:00", "data": {"market": "0xf2995999537ed00a9e1ed196dac5a34c8362b9e454200968eb123c60d21530d2", "price_changes": [{"asset_id": "105244305087066947375390379713039474916834963808658829713388931041101255731949", "price": "0.007", "size": "32.89", "side": "BUY", "hash": "aa0d2b8f524e1cd9d869b1c1d067a3e6cc1ec564", "best_bid": "0.019", "best_ask": "0.023"}, {"asset_id": "106415214145522966179186096977094978918005217851026867362814745409109043718965", "price": "0.993", "size": "32.89", "side": "SELL", "hash": "8d502f91a3de648d48f94845d5a7dec3c4a9cca1", "best_bid": "0.977", "best_ask": "0.981"}], "timestamp": "1769384718846", "event_type": "price_change"}}
{"_local_timestamp": "2026-01-25T23:45:19.886755+00:00", "data": {"market": "0xf2995999537ed00a9e1ed196dac5a34c8362b9e454200968eb123c60d21530d2", "price_changes": [{"asset_id": "105244305087066947375390379713039474916834963808658829713388931041101255731949", "price": "0.007", "size": "16", "side": "BUY", "hash": "d3446630ea1d3fd59eeb0f5bf348262dd4bb514d", "best_bid": "0.019", "best_ask": "0.023"}, {"asset_id": "106415214145522966179186096977094978918005217851026867362814745409109043718965", "price": "0.993", "size": "16", "side": "SELL", "hash": "c4e091b591e703351b08ae00a305fcb9e26b4ac5", "best_bid": "0.977", "best_ask": "0.981"}], "timestamp": "1769384719815", "event_type": "price_change"}}
{"_local_timestamp": "2026-01-25T23:45:19.887102+00:00", "data": {"market": "0xf2995999537ed00a9e1ed196dac5a34c8362b9e454200968eb123c60d21530d2", "price_changes": [{"asset_id": "105244305087066947375390379713039474916834963808658829713388931041101255731949", "price": "0.008", "size": "0", "side": "BUY", "hash": "d3446630ea1d3fd59eeb0f5bf348262dd4bb514d", "best_bid": "0.019", "best_ask": "0.023"}, {"asset_id": "106415214145522966179186096977094978918005217851026867362814745409109043718965", "price": "0.992", "size": "0", "side": "SELL", "hash": "c4e091b591e703351b08ae00a305fcb9e26b4ac5", "best_bid": "0.977", "best_ask": "0.981"}], "timestamp": "1769384719815", "event_type": "price_change"}}
{"_local_timestamp": "2026-01-25T23:45:20.317635+00:00", "data": {"market": "0xf2995999537ed00a9e1ed196dac5a34c8362b9e454200968eb123c60d21530d2", "price_changes": [{"asset_id": "105244305087066947375390379713039474916834963808658829713388931041101255731949", "price": "0.009", "size": "9.31", "side": "BUY", "hash": "c79482bbb0fa8b5aea55b7b1dbc78d98bd0315ff", "best_bid": "0.019", "best_ask": "0.023"}, {"asset_id": "106415214145522966179186096977094978918005217851026867362814745409109043718965", "price": "0.991", "size": "9.31", "side": "SELL", "hash": "e6487152f42e94658e6e35a0b095b02bc7647273", "best_bid": "0.977", "best_ask": "0.981"}], "timestamp": "1769384720246", "event_type": "price_change"}}
{"_local_timestamp": "2026-01-25T23:45:20.317960+00:00", "data": {"market": "0xf2995999537ed00a9e1ed196dac5a34c8362b9e454200968eb123c60d21530d2", "price_changes": [{"asset_id": "105244305087066947375390379713039474916834963808658829713388931041101255731949", "price": "0.008", "size": "17.86", "side": "BUY", "hash": "855c0126f5ce61153b7ddb642323f36a76b08e2c", "best_bid": "0.019", "best_ask": "0.023"}, {"asset_id": "106415214145522966179186096977094978918005217851026867362814745409109043718965", "price": "0.992", "size": "17.86", "side": "SELL", "hash": "a6f2d76e0c37dca7ada6bc8b80131331916dd510", "best_bid": "0.977", "best_ask": "0.981"}], "timestamp": "1769384720247", "event_type": "price_change"}}
{"_local_timestamp": "2026-01-25T23:45:21.737800+00:00", "data": {"market": "0xf2995999537ed00a9e1ed196dac5a34c8362b9e454200968eb123c60d21530d2", "price_changes": [{"asset_id": "105244305087066947375390379713039474916834963808658829713388931041101255731949", "price": "0.008", "size": "0", "side": "BUY", "hash": "e5505bd0655ed94987ed429418de6a6577a287e7", "best_bid": "0.019", "best_ask": "0.023"}, {"asset_id": "106415214145522966179186096977094978918005217851026867362814745409109043718965", "price": "0.992", "size": "0", "side": "SELL", "hash": "6c6a1156cf61749f96eb931434407024fa124494", "best_bid": "0.977", "best_ask": "0.981"}], "timestamp": "1769384721674", "event_type": "price_change"}}
{"_local_timestamp": "2026-01-25T23:45:21.740548+00:00", "data": {"market": "0xf2995999537ed00a9e1ed196dac5a34c8362b9e454200968eb123c60d21530d2", "price_changes": [{"asset_id": "105244305087066947375390379713039474916834963808658829713388931041101255731949", "price": "0.009", "size": "0", "side": "BUY", "hash": "e5505bd0655ed94987ed429418de6a6577a287e7", "best_bid": "0.019", "best_ask": "0.023"}, {"asset_id": "106415214145522966179186096977094978918005217851026867362814745409109043718965", "price": "0.991", "size": "0", "side": "SELL", "hash": "6c6a1156cf61749f96eb931434407024fa124494", "best_bid": "0.977", "best_ask": "0.981"}], "timestamp": "1769384721674", "event_type": "price_change"}}
{"_local_timestamp": "2026-01-25T23:45:22.074816+00:00", "data": {"market": "0xf2995999537ed00a9e1ed196dac5a34c8362b9e454200968eb123c60d21530d2", "price_changes": [{"asset_id": "105244305087066947375390379713039474916834963808658829713388931041101255731949", "price": "0.006", "size": "58.44", "side": "BUY", "hash": "15afa66b07d8b6b76a4b18e0bf31de83073cea47", "best_bid": "0.019", "best_ask": "0.023"}, {"asset_id": "106415214145522966179186096977094978918005217851026867362814745409109043718965", "price": "0.994", "size": "58.44", "side": "SELL", "hash": "8c2fef9e7ebe5363b674f95aa5e6e7b64b4be9b3", "best_bid": "0.977", "best_ask": "0.981"}], "timestamp": "1769384721999", "event_type": "price_change"}}
{"_local_timestamp": "2026-01-25T23:45:22.097087+00:00", "data": {"market": "0xf2995999537ed00a9e1ed196dac5a34c8362b9e454200968eb123c60d21530d2", "price_changes": [{"asset_id": "105244305087066947375390379713039474916834963808658829713388931041101255731949", "price": "0.008", "size": "21.58", "side": "BUY", "hash": "3332a25b7ca0a1008d0ca4ac6334504feccf91f2", "best_bid": "0.019", "best_ask": "0.023"}, {"asset_id": "106415214145522966179186096977094978918005217851026867362814745409109043718965", "price": "0.992", "size": "21.58", "side": "SELL", "hash": "6d223b4c17bd6a7f62a906461d8f4e3402e37fee", "best_bid": "0.977", "best_ask": "0.981"}], "timestamp": "1769384722003", "event_type": "price_change"}}
{"_local_timestamp": "2026-01-25T23:45:23.322819+00:00", "data": {"market": "0xf2995999537ed00a9e1ed196dac5a34c8362b9e454200968eb123c60d21530d2", "price_changes": [{"asset_id": "105244305087066947375390379713039474916834963808658829713388931041101255731949", "price": "0.006", "size": "49.19", "side": "BUY", "hash": "bfbbf90bd5328da3723e1b5b23a47711db5d1bc1", "best_bid": "0.019", "best_ask": "0.023"}, {"asset_id": "106415214145522966179186096977094978918005217851026867362814745409109043718965", "price": "0.994", "size": "49.19", "side": "SELL", "hash": "49aa81747cb05a9979c1f603f381a3e242ea66fb", "best_bid": "0.977", "best_ask": "0.981"}], "timestamp": "1769384723236", "event_type": "price_change"}}
{"_local_timestamp": "2026-01-25T23:45:23.323124+00:00", "data": {"market": "0xf2995999537ed00a9e1ed196dac5a34c8362b9e454200968eb123c60d21530d2", "price_changes": [{"asset_id": "105244305087066947375390379713039474916834963808658829713388931041101255731949", "price": "0.008", "size": "0", "side": "BUY", "hash": "bfbbf90bd5328da3723e1b5b23a47711db5d1bc1", "best_bid": "0.019", "best_ask": "0.023"}, {"asset_id": "106415214145522966179186096977094978918005217851026867362814745409109043718965", "price": "0.992", "size": "0", "side": "SELL", "hash": "49aa81747cb05a9979c1f603f381a3e242ea66fb", "best_bid": "0.977", "best_ask": "0.981"}], "timestamp": "1769384723236", "event_type": "price_change"}}
{"_local_timestamp": "2026-01-25T23:45:23.731978+00:00", "data": {"market": "0xf2995999537ed00a9e1ed196dac5a34c8362b9e454200968eb123c60d21530d2", "price_changes": [{"asset_id": "105244305087066947375390379713039474916834963808658829713388931041101255731949", "price": "0.008", "size": "21.5", "side": "BUY", "hash": "d6ee7452713cc6a06f7381350b8a054df22ecd09", "best_bid": "0.019", "best_ask": "0.023"}, {"asset_id": "106415214145522966179186096977094978918005217851026867362814745409109043718965", "price": "0.992", "size": "21.5", "side": "SELL", "hash": "2f06c487c18f694efad2739963b8c79eca207e70", "best_bid": "0.977", "best_ask": "0.981"}], "timestamp": "1769384723659", "event_type": "price_change"}}
{"_local_timestamp": "2026-01-25T23:45:23.738905+00:00", "data": {"market": "0xf2995999537ed00a9e1ed196dac5a34c8362b9e454200968eb123c60d21530d2", "price_changes": [{"asset_id": "105244305087066947375390379713039474916834963808658829713388931041101255731949", "price": "0.006", "size": "58.53", "side": "BUY", "hash": "2f6a66fce784a5b794f7797ea5d9b01d2dbdf4a1", "best_bid": "0.019", "best_ask": "0.023"}, {"asset_id": "106415214145522966179186096977094978918005217851026867362814745409109043718965", "price": "0.994", "size": "58.53", "side": "SELL", "hash": "1b56224dac27fe908e912dc7382b5b3a9de9b0bf", "best_bid": "0.977", "best_ask": "0.981"}], "timestamp": "1769384723668", "event_type": "price_change"}}
{"_local_timestamp": "2026-01-25T23:45:24.294318+00:00", "data": {"market": "0xf2995999537ed00a9e1ed196dac5a34c8362b9e454200968eb123c60d21530d2", "price_changes": [{"asset_id": "105244305087066947375390379713039474916834963808658829713388931041101255731949", "price": "0.006", "size": "49.19", "side": "BUY", "hash": "6a709b38a8c9638703c75c7512556d88e9036b58", "best_bid": "0.019", "best_ask": "0.023"}, {"asset_id": "106415214145522966179186096977094978918005217851026867362814745409109043718965", "price": "0.994", "size": "49.19", "side": "SELL", "hash": "639990e1c455210564817257717cc123a64f4728", "best_bid": "0.977", "best_ask": "0.981"}], "timestamp": "1769384724217", "event_type": "price_change"}}
{"_local_timestamp": "2026-01-25T23:45:24.294714+00:00", "data": {"market": "0xf2995999537ed00a9e1ed196dac5a34c8362b9e454200968eb123c60d21530d2", "price_changes": [{"asset_id": "105244305087066947375390379713039474916834963808658829713388931041101255731949", "price": "0.008", "size": "0", "side": "BUY", "hash": "6a709b38a8c9638703c75c7512556d88e9036b58", "best_bid": "0.019", "best_ask": "0.023"}, {"asset_id": "106415214145522966179186096977094978918005217851026867362814745409109043718965", "price": "0.992", "size": "0", "side": "SELL", "hash": "639990e1c455210564817257717cc123a64f4728", "best_bid": "0.977", "best_ask": "0.981"}], "timestamp": "1769384724217", "event_type": "price_change"}}
{"_local_timestamp": "2026-01-25T23:45:24.793829+00:00", "data": {"market": "0xf2995999537ed00a9e1ed196dac5a34c8362b9e454200968eb123c60d21530d2", "price_changes": [{"asset_id": "105244305087066947375390379713039474916834963808658829713388931041101255731949", "price": "0.007", "size": "21.37", "side": "BUY", "hash": "9a3eb7814c625db220a27e5ea93b4cd1444581b3", "best_bid": "0.019", "best_ask": "0.023"}, {"asset_id": "106415214145522966179186096977094978918005217851026867362814745409109043718965", "price": "0.993", "size": "21.37", "side": "SELL", "hash": "ef7413be385708324f8c3b90155a1880782df831", "best_bid": "0.977", "best_ask": "0.981"}], "timestamp": "1769384724729", "event_type": "price_change"}}
{"_local_timestamp": "2026-01-25T23:45:24.801020+00:00", "data": {"market": "0xf2995999537ed00a9e1ed196dac5a34c8362b9e454200968eb123c60d21530d2", "price_changes": [{"asset_id": "105244305087066947375390379713039474916834963808658829713388931041101255731949", "price": "0.009", "size": "12.82", "side": "BUY", "hash": "963904762aa65e831a467258648bc9ae7cd214a5", "best_bid": "0.019", "best_ask": "0.023"}, {"asset_id": "106415214145522966179186096977094978918005217851026867362814745409109043718965", "price": "0.991", "size": "12.82", "side": "SELL", "hash": "85571da1ccf35ae1ca921e7cc948ad52eb5218b5", "best_bid": "0.977", "best_ask": "0.981"}], "timestamp": "1769384724731", "event_type": "price_change"}}
{"_local_timestamp": "2026-01-25T23:45:24.801405+00:00", "data": {"market": "0xf2995999537ed00a9e1ed196dac5a34c8362b9e454200968eb123c60d21530d2", "price_changes": [{"asset_id": "105244305087066947375390379713039474916834963808658829713388931041101255731949", "price": "0.008", "size": "9.39", "side": "BUY", "hash": "4c088cc51af486bf83a272259536ae58ba15c8fa", "best_bid": "0.019", "best_ask": "0.023"}, {"asset_id": "106415214145522966179186096977094978918005217851026867362814745409109043718965", "price": "0.992", "size": "9.39", "side": "SELL", "hash": "f2ed5c8dc284a8edd94cfdd9658609e37d39f771", "best_bid": "0.977", "best_ask": "0.981"}], "timestamp": "1769384724732", "event_type": "price_change"}}
{"_local_timestamp": "2026-01-25T23:45:25.891083+00:00", "data": {"market": "0xf2995999537ed00a9e1ed196dac5a34c8362b9e454200968eb123c60d21530d2", "price_changes": [{"asset_id": "105244305087066947375390379713039474916834963808658829713388931041101255731949", "price": "0.007", "size": "16", "side": "BUY", "hash": "2a407e123ca754f1846227c88aa2e04b96000a38", "best_bid": "0.019", "best_ask": "0.023"}, {"asset_id": "106415214145522966179186096977094978918005217851026867362814745409109043718965", "price": "0.993", "size": "16", "side": "SELL", "hash": "28d193ab103be8427bafe31688115446b03cc198", "best_bid": "0.977", "best_ask": "0.981"}], "timestamp": "1769384725820", "event_type": "price_change"}}
{"_local_timestamp": "2026-01-25T23:45:25.894049+00:00", "data": {"market": "0xf2995999537ed00a9e1ed196dac5a34c8362b9e454200968eb123c60d21530d2", "price_changes": [{"asset_id": "105244305087066947375390379713039474916834963808658829713388931041101255731949", "price": "0.009", "size": "0", "side": "BUY", "hash": "2a407e123ca754f1846227c88aa2e04b96000a38", "best_bid": "0.019", "best_ask": "0.023"}, {"asset_id": "106415214145522966179186096977094978918005217851026867362814745409109043718965", "price": "0.991", "size": "0", "side": "SELL", "hash": "28d193ab103be8427bafe31688115446b03cc198", "best_bid": "0.977", "best_ask": "0.981"}], "timestamp": "1769384725820", "event_type": "price_change"}}
{"_local_timestamp": "2026-01-25T23:45:26.254345+00:00", "data": {"market": "0xf2995999537ed00a9e1ed196dac5a34c8362b9e454200968eb123c60d21530d2", "price_changes": [{"asset_id": "105244305087066947375390379713039474916834963808658829713388931041101255731949", "price": "0.008", "size": "17.67", "side": "BUY", "hash": "0c91a188b4408ffb93a939ccea3a024b45782dfc", "best_bid": "0.019", "best_ask": "0.023"}, {"asset_id": "106415214145522966179186096977094978918005217851026867362814745409109043718965", "price": "0.992", "size": "17.67", "side": "SELL", "hash": "30a31654693434d1ce3a922abcbdc5c73c0ba23e", "best_bid": "0.977", "best_ask": "0.981"}], "timestamp": "1769384726182", "event_type": "price_change"}}
{"_local_timestamp": "2026-01-25T23:45:26.254650+00:00", "data": {"market": "0xf2995999537ed00a9e1ed196dac5a34c8362b9e454200968eb123c60d21530d2", "price_changes": [{"asset_id": "105244305087066947375390379713039474916834963808658829713388931041101255731949", "price": "0.01", "size": "2028.67", "side": "BUY", "hash": "4b4598fed66f0780f34abb5fd81112e1d1e499a0", "best_bid": "0.019", "best_ask": "0.023"}, {"asset_id": "106415214145522966179186096977094978918005217851026867362814745409109043718965", "price": "0.99", "size": "2028.67", "side": "SELL", "hash": "08b99f146f7be4ad2e9c750822beb5c45a7ddf70", "best_bid": "0.977", "best_ask": "0.981"}], "timestamp": "1769384726183", "event_type": "price_change"}}
{"_local_timestamp": "2026-01-25T23:45:26.945873+00:00", "data": {"market": "0xf2995999537ed00a9e1ed196dac5a34c8362b9e454200968eb123c60d21530d2", "price_changes": [{"asset_id": "105244305087066947375390379713039474916834963808658829713388931041101255731949", "price": "0.008", "size": "8.28", "side": "BUY", "hash": "199c28a286c51e456aeabce8ba03aa0121ef2293", "best_bid": "0.019", "best_ask": "0.023"}, {"asset_id": "106415214145522966179186096977094978918005217851026867362814745409109043718965", "price": "0.992", "size": "8.28", "side": "SELL", "hash": "39981e9dd444249d440062b72e1e023c15dd3fc5", "best_bid": "0.977", "best_ask": "0.981"}], "timestamp": "1769384726877", "event_type": "price_change"}}
{"_local_timestamp": "2026-01-25T23:45:26.946223+00:00", "data": {"market": "0xf2995999537ed00a9e1ed196dac5a34c8362b9e454200968eb123c60d21530d2", "price_changes": [{"asset_id": "105244305087066947375390379713039474916834963808658829713388931041101255731949", "price": "0.01", "size": "2020", "side": "BUY", "hash": "199c28a286c51e456aeabce8ba03aa0121ef2293", "best_bid": "0.019", "best_ask": "0.023"}, {"asset_id": "106415214145522966179186096977094978918005217851026867362814745409109043718965", "price": "0.99", "size": "2020", "side": "SELL", "hash": "39981e9dd444249d440062b72e1e023c15dd3fc5", "best_bid": "0.977", "best_ask": "0.981"}], "timestamp": "1769384726877", "event_type": "price_change"}}
{"_local_timestamp": "2026-01-25T23:45:27.490199+00:00", "data": {"market": "0xf2995999537ed00a9e1ed196dac5a34c8362b9e454200968eb123c60d21530d2", "price_changes": [{"asset_id": "105244305087066947375390379713039474916834963808658829713388931041101255731949", "price": "0.006", "size": "61.16", "side": "BUY", "hash": "71eb0113a5a5af2a10c89baef02bef71e0672561", "best_bid": "0.019", "best_ask": "0.023"}, {"asset_id": "106415214145522966179186096977094978918005217851026867362814745409109043718965", "price": "0.994", "size": "61.16", "side": "SELL", "hash": "f325703c1523b1d11db072eacd6e589601a5e350", "best_bid": "0.977", "best_ask": "0.981"}], "timestamp": "1769384727422", "event_type": "price_change"}}
{"_local_timestamp": "2026-01-25T23:45:27.490502+00:00", "data": {"market": "0xf2995999537ed00a9e1ed196dac5a34c8362b9e454200968eb123c60d21530d2", "price_changes": [{"asset_id": "105244305087066947375390379713039474916834963808658829713388931041101255731949", "price": "0.008", "size": "19.53", "side": "BUY", "hash": "1afa223b2e8529c8214602e9ed641a3a354db7fe", "best_bid": "0.019", "best_ask": "0.023"}, {"asset_id": "106415214145522966179186096977094978918005217851026867362814745409109043718965", "price": "0.992", "size": "19.53", "side": "SELL", "hash": "6153475e43f6cd489bb884c695e5a2426505e597", "best_bid": "0.977", "best_ask": "0.981"}], "timestamp": "1769384727423", "event_type": "price_change"}}
{"_local_timestamp": "2026-01-25T23:45:28.100809+00:00", "data": {"market": "0xf2995999537ed00a9e1ed196dac5a34c8362b9e454200968eb123c60d21530d2", "price_changes": [{"asset_id": "105244305087066947375390379713039474916834963808658829713388931041101255731949", "price": "0.006", "size": "49.19", "side": "BUY", "hash": "b459438ce515c5765cbad3e2c4a7ee1e2f8b225f", "best_bid": "0.019", "best_ask": "0.023"}, {"asset_id": "106415214145522966179186096977094978918005217851026867362814745409109043718965", "price": "0.994", "size": "49.19", "side": "SELL", "hash": "c522a3b4006e99641d69a547c195464d9e47a2d3", "best_bid": "0.977", "best_ask": "0.981"}], "timestamp": "1769384728004", "event_type": "price_change"}}
{"_local_timestamp": "2026-01-25T23:45:28.101120+00:00", "data": {"market": "0xf2995999537ed00a9e1ed196dac5a34c8362b9e454200968eb123c60d21530d2", "price_changes": [{"asset_id": "105244305087066947375390379713039474916834963808658829713388931041101255731949", "price": "0.008", "size": "8.28", "side": "BUY", "hash": "b459438ce515c5765cbad3e2c4a7ee1e2f8b225f", "best_bid": "0.019", "best_ask": "0.023"}, {"asset_id": "106415214145522966179186096977094978918005217851026867362814745409109043718965", "price": "0.992", "size": "8.28", "side": "SELL", "hash": "c522a3b4006e99641d69a547c195464d9e47a2d3", "best_bid": "0.977", "best_ask": "0.981"}], "timestamp": "1769384728004", "event_type": "price_change"}}
{"_local_timestamp": "2026-01-25T23:45:28.459380+00:00", "data": {"market": "0xf2995999537ed00a9e1ed196dac5a34c8362b9e454200968eb123c60d21530d2", "price_changes": [{"asset_id": "105244305087066947375390379713039474916834963808658829713388931041101255731949", "price": "0.009", "size": "10", "side": "BUY", "hash": "c42d9450facef3f3d51f3cf2a1fe1bd32759ec82", "best_bid": "0.019", "best_ask": "0.023"}, {"asset_id": "106415214145522966179186096977094978918005217851026867362814745409109043718965", "price": "0.991", "size": "10", "side": "SELL", "hash": "67656e086c2391388b900e0548e2304a9c271cf0", "best_bid": "0.977", "best_ask": "0.981"}], "timestamp": "1769384728389", "event_type": "price_change"}}
{"_local_timestamp": "2026-01-25T23:45:28.459728+00:00", "data": {"market": "0xf2995999537ed00a9e1ed196dac5a34c8362b9e454200968eb123c60d21530d2", "price_changes": [{"asset_id": "105244305087066947375390379713039474916834963808658829713388931041101255731949", "price": "0.007", "size": "26.26", "side": "BUY", "hash": "c3c04cd4d40d6406cfe8686de1b065fe09e0b2d8", "best_bid": "0.019", "best_ask": "0.023"}, {"asset_id": "106415214145522966179186096977094978918005217851026867362814745409109043718965", "price": "0.993", "size": "26.26", "side": "SELL", "hash": "cfaa0958b14ad6e025974f3d6c6fa59c8d50a7f3", "best_bid": "0.977", "best_ask": "0.981"}], "timestamp": "1769384728390", "event_type": "price_change"}}
{"_local_timestamp": "2026-01-25T23:45:29.007236+00:00", "data": {"market": "0xf2995999537ed00a9e1ed196dac5a34c8362b9e454200968eb123c60d21530d2", "price_changes": [{"asset_id": "105244305087066947375390379713039474916834963808658829713388931041101255731949", "price": "0.007", "size": "16", "side": "BUY", "hash": "b6c450ff363408718b658fa83ebb9abcdc9406e8", "best_bid": "0.019", "best_ask": "0.023"}, {"asset_id": "106415214145522966179186096977094978918005217851026867362814745409109043718965", "price": "0.993", "size": "16", "side": "SELL", "hash": "11bd1e3e09c3ea013652a8399b189a259af82776", "best_bid": "0.977", "best_ask": "0.981"}], "timestamp": "1769384728939", "event_type": "price_change"}}
{"_local_timestamp": "2026-01-25T23:45:29.007553+00:00", "data": {"market": "0xf2995999537ed00a9e1ed196dac5a34c8362b9e454200968eb123c60d21530d2", "price_changes": [{"asset_id": "105244305087066947375390379713039474916834963808658829713388931041101255731949", "price": "0.009", "size": "0", "side": "BUY", "hash": "b6c450ff363408718b658fa83ebb9abcdc9406e8", "best_bid": "0.019", "best_ask": "0.023"}, {"asset_id": "106415214145522966179186096977094978918005217851026867362814745409109043718965", "price": "0.991", "size": "0", "side": "SELL", "hash": "11bd1e3e09c3ea013652a8399b189a259af82776", "best_bid": "0.977", "best_ask": "0.981"}], "timestamp": "1769384728939", "event_type": "price_change"}}
{"_local_timestamp": "2026-01-25T23:45:29.897058+00:00", "data": {"market": "0xf2995999537ed00a9e1ed196dac5a34c8362b9e454200968eb123c60d21530d2", "price_changes": [{"asset_id": "105244305087066947375390379713039474916834963808658829713388931041101255731949", "price": "0.01", "size": "2030.73", "side": "BUY", "hash": "53a50506f6b1370838634c8001f5881754cac5b7", "best_bid": "0.019", "best_ask": "0.023"}, {"asset_id": "106415214145522966179186096977094978918005217851026867362814745409109043718965", "price": "0.99", "size": "2030.73", "side": "SELL", "hash": "e635f4afc24ec5ec9bc1516aef1a1d8725e2bd78", "best_bid": "0.977", "best_ask": "0.981"}], "timestamp": "1769384729835", "event_type": "price_change"}}
{"_local_timestamp": "2026-01-25T23:45:29.901191+00:00", "data": {"market": "0xf2995999537ed00a9e1ed196dac5a34c8362b9e454200968eb123c60d21530d2", "price_changes": [{"asset_id": "105244305087066947375390379713039474916834963808658829713388931041101255731949", "price": "0.008", "size": "15.1", "side": "BUY", "hash": "e7098980d2573c9ba6f46b0dcd62d72eb7af35be", "best_bid": "0.019", "best_ask": "0.023"}, {"asset_id": "106415214145522966179186096977094978918005217851026867362814745409109043718965", "price": "0.992", "size": "15.1", "side": "SELL", "hash": "4fa53ae05ecd076cacf2d138bef90d7c22a0c066", "best_bid": "0.977", "best_ask": "0.981"}], "timestamp": "1769384729836", "event_type": "price_change"}}
{"_local_timestamp": "2026-01-25T23:45:30.284370+00:00", "data": {"market": "0xf2995999537ed00a9e1ed196dac5a34c8362b9e454200968eb123c60d21530d2", "price_changes": [{"asset_id": "105244305087066947375390379713039474916834963808658829713388931041101255731949", "price": "0.01", "size": "2020", "side": "BUY", "hash": "e3539e3415dc5fc31edbc780be2f47b5b7b85e6b", "best_bid": "0.019", "best_ask": "0.023"}, {"asset_id": "106415214145522966179186096977094978918005217851026867362814745409109043718965", "price": "0.99", "size": "2020", "side": "SELL", "hash": "90a0506098c806e8d02221b66ab3fab16e6deb29", "best_bid": "0.977", "best_ask": "0.981"}], "timestamp": "1769384730213", "event_type": "price_change"}}
{"_local_timestamp": "2026-01-25T23:45:30.757355+00:00", "data": {"market": "0xf2995999537ed00a9e1ed196dac5a34c8362b9e454200968eb123c60d21530d2", "price_changes": [{"asset_id": "105244305087066947375390379713039474916834963808658829713388931041101255731949", "price": "0.002", "size": "225.99", "side": "BUY", "hash": "e127d7bd9cae3cf1abf2e761032ce6f04bfeff7f", "best_bid": "0.019", "best_ask": "0.023"}, {"asset_id": "106415214145522966179186096977094978918005217851026867362814745409109043718965", "price": "0.998", "size": "225.99", "side": "SELL", "hash": "af2f0aa0de928d45f4c23c9cdf19d8b1e3c6f33e", "best_bid": "0.977", "best_ask": "0.981"}], "timestamp": "1769384730693", "event_type": "price_change"}}
{"_local_timestamp": "2026-01-25T23:45:30.757743+00:00", "data": {"market": "0xf2995999537ed00a9e1ed196dac5a34c8362b9e454200968eb123c60d21530d2", "price_changes": [{"asset_id": "105244305087066947375390379713039474916834963808658829713388931041101255731949", "price": "0.006", "size": "64.93", "side": "BUY", "hash": "9b1e2c426da259e48d22449682dbfdd772ea6a37", "best_bid": "0.019", "best_ask": "0.023"}, {"asset_id": "106415214145522966179186096977094978918005217851026867362814745409109043718965", "price": "0.994", "size": "64.93", "side": "SELL", "hash": "b012b3b74f6b4fc0581be4e53984c8010121255e", "best_bid": "0.977", "best_ask": "0.981"}], "timestamp": "1769384730694", "event_type": "price_change"}}
{"_local_timestamp": "2026-01-25T23:45:32.867658+00:00", "data": {"market": "0xf2995999537ed00a9e1ed196dac5a34c8362b9e454200968eb123c60d21530d2", "price_changes": [{"asset_id": "105244305087066947375390379713039474916834963808658829713388931041101255731949", "price": "0.002", "size": "219.53", "side": "BUY", "hash": "dd3760ccf9bb95ed17d029348131c8081ed34cd9", "best_bid": "0.019", "best_ask": "0.023"}, {"asset_id": "106415214145522966179186096977094978918005217851026867362814745409109043718965", "price": "0.998", "size": "219.53", "side": "SELL", "hash": "2635fca1598b97b348496dbaf314563bf3f7bc28", "best_bid": "0.977", "best_ask": "0.981"}], "timestamp": "1769384732800", "event_type": "price_change"}}
{"_local_timestamp": "2026-01-25T23:45:32.868021+00:00", "data": {"market": "0xf2995999537ed00a9e1ed196dac5a34c8362b9e454200968eb123c60d21530d2", "price_changes": [{"asset_id": "105244305087066947375390379713039474916834963808658829713388931041101255731949", "price": "0.006", "size": "49.19", "side": "BUY", "hash": "dd3760ccf9bb95ed17d029348131c8081ed34cd9", "best_bid": "0.019", "best_ask": "0.023"}, {"asset_id": "106415214145522966179186096977094978918005217851026867362814745409109043718965", "price": "0.994", "size": "49.19", "side": "SELL", "hash": "2635fca1598b97b348496dbaf314563bf3f7bc28", "best_bid": "0.977", "best_ask": "0.981"}], "timestamp": "1769384732800", "event_type": "price_change"}}
{"_local_timestamp": "2026-01-25T23:45:33.163262+00:00", "data": {"market": "0xf2995999537ed00a9e1ed196dac5a34c8362b9e454200968eb123c60d21530d2", "price_changes": [{"asset_id": "105244305087066947375390379713039474916834963808658829713388931041101255731949", "price": "0.006", "size": "64.93", "side": "BUY", "hash": "561ed7df4c7a33b2e6d292bedae7cd4977ca5cd7", "best_bid": "0.019", "best_ask": "0.023"}, {"asset_id": "106415214145522966179186096977094978918005217851026867362814745409109043718965", "price": "0.994", "size": "64.93", "side": "SELL", "hash": "ae391cba5b310ff58bc39dd685c5f732063f47ca", "best_bid": "0.977", "best_ask": "0.981"}], "timestamp": "1769384733093", "event_type": "price_change"}}
{"_local_timestamp": "2026-01-25T23:45:33.163608+00:00", "data": {"market": "0xf2995999537ed00a9e1ed196dac5a34c8362b9e454200968eb123c60d21530d2", "price_changes": [{"asset_id": "105244305087066947375390379713039474916834963808658829713388931041101255731949", "price": "0.002", "size": "225.99", "side": "BUY", "hash": "450bb579dcb3f4e3e3e1c478ecdc62a8b571bc91", "best_bid": "0.019", "best_ask": "0.023"}, {"asset_id": "106415214145522966179186096977094978918005217851026867362814745409109043718965", "price": "0.998", "size": "225.99", "side": "SELL", "hash": "efb2c915a00218571e1b3eee49f70021a787d5bf", "best_bid": "0.977", "best_ask": "0.981"}], "timestamp": "1769384733094", "event_type": "price_change"}}
{"_local_timestamp": "2026-01-25T23:45:33.610377+00:00", "data": {"market": "0xf2995999537ed00a9e1ed196dac5a34c8362b9e454200968eb123c60d21530d2", "price_changes": [{"asset_id": "105244305087066947375390379713039474916834963808658829713388931041101255731949", "price": "0.002", "size": "219.53", "side": "BUY", "hash": "9a7f0713bdebee926996589d64a24979133012df", "best_bid": "0.019", "best_ask": "0.023"}, {"asset_id": "106415214145522966179186096977094978918005217851026867362814745409109043718965", "price": "0.998", "size": "219.53", "side": "SELL", "hash": "2da87e0482afde4a1925fd1ef01000bb80967d36", "best_bid": "0.977", "best_ask": "0.981"}], "timestamp": "1769384733546", "event_type": "price_change"}}
{"_local_timestamp": "2026-01-25T23:45:33.610739+00:00", "data": {"market": "0xf2995999537ed00a9e1ed196dac5a34c8362b9e454200968eb123c60d21530d2", "price_changes": [{"asset_id": "105244305087066947375390379713039474916834963808658829713388931041101255731949", "price": "0.006", "size": "49.19", "side": "BUY", "hash": "9a7f0713bdebee926996589d64a24979133012df", "best_bid": "0.019", "best_ask": "0.023"}, {"asset_id": "106415214145522966179186096977094978918005217851026867362814745409109043718965", "price": "0.994", "size": "49.19", "side": "SELL", "hash": "2da87e0482afde4a1925fd1ef01000bb80967d36", "best_bid": "0.977", "best_ask": "0.981"}], "timestamp": "1769384733546", "event_type": "price_change"}}
{"_local_timestamp": "2026-01-25T23:45:34.418515+00:00", "data": {"market": "0xf2995999537ed00a9e1ed196dac5a34c8362b9e454200968eb123c60d21530d2", "price_changes": [{"asset_id": "105244305087066947375390379713039474916834963808658829713388931041101255731949", "price": "0.007", "size": "31.33", "side": "BUY", "hash": "7f7e9f227109dc49fc9e7764df525bea1cb07d3e", "best_bid": "0.019", "best_ask": "0.023"}, {"asset_id": "106415214145522966179186096977094978918005217851026867362814745409109043718965", "price": "0.993", "size": "31.33", "side": "SELL", "hash": "d75c5e94696175b4bfe6b6b6b23027d403ec5571", "best_bid": "0.977", "best_ask": "0.981"}], "timestamp": "1769384734336", "event_type": "price_change"}}
{"_local_timestamp": "2026-01-25T23:45:35.063023+00:00", "data": {"market": "0xf2995999537ed00a9e1ed196dac5a34c8362b9e454200968eb123c60d21530d2", "price_changes": [{"asset_id": "105244305087066947375390379713039474916834963808658829713388931041101255731949", "price": "0.007", "size": "16", "side": "BUY", "hash": "ebe305ff925ec0451d8f1f25bf639c78fe07174a", "best_bid": "0.019", "best_ask": "0.023"}, {"asset_id": "106415214145522966179186096977094978918005217851026867362814745409109043718965", "price": "0.993", "size": "16", "side": "SELL", "hash": "655e902f1aa6d32469876713c2a42b95a1bea04e", "best_bid": "0.977", "best_ask": "0.981"}], "timestamp": "1769384734996", "event_type": "price_change"}}
{"_local_timestamp": "2026-01-25T23:45:35.486173+00:00", "data": {"market": "0xf2995999537ed00a9e1ed196dac5a34c8362b9e454200968eb123c60d21530d2", "price_changes": [{"asset_id": "105244305087066947375390379713039474916834963808658829713388931041101255731949", "price": "0.002", "size": "225.99", "side": "BUY", "hash": "02e500d4d713cb1de4ae8d0fca8c03f61c199c8e", "best_bid": "0.019", "best_ask": "0.023"}, {"asset_id": "106415214145522966179186096977094978918005217851026867362814745409109043718965", "price": "0.998", "size": "225.99", "side": "SELL", "hash": "8d71cc2ed7bc83c23a8f5804c557b7c2384960a6", "best_bid": "0.977", "best_ask": "0.981"}], "timestamp": "1769384735417", "event_type": "price_change"}}
{"_local_timestamp": "2026-01-25T23:45:35.498656+00:00", "data": {"market": "0xf2995999537ed00a9e1ed196dac5a34c8362b9e454200968eb123c60d21530d2", "price_changes": [{"asset_id": "105244305087066947375390379713039474916834963808658829713388931041101255731949", "price": "0.006", "size": "64.93", "side": "BUY", "hash": "4e590ff083d612dad3f00db747249638ed2cb7cb", "best_bid": "0.019", "best_ask": "0.023"}, {"asset_id": "106415214145522966179186096977094978918005217851026867362814745409109043718965", "price": "0.994", "size": "64.93", "side": "SELL", "hash": "7ff6e26ed4fbbca31ea40110cc064aca9ca34da8", "best_bid": "0.977", "best_ask": "0.981"}], "timestamp": "1769384735422", "event_type": "price_change"}}
{"_local_timestamp": "2026-01-25T23:45:37.305750+00:00", "data": {"market": "0xf2995999537ed00a9e1ed196dac5a34c8362b9e454200968eb123c60d21530d2", "price_changes": [{"asset_id": "105244305087066947375390379713039474916834963808658829713388931041101255731949", "price": "0.002", "size": "219.53", "side": "BUY", "hash": "9b19fec40d04c53d13e84ab3323b824348261e8c", "best_bid": "0.019", "best_ask": "0.023"}, {"asset_id": "106415214145522966179186096977094978918005217851026867362814745409109043718965", "price": "0.998", "size": "219.53", "side": "SELL", "hash": "70fa3dfdc2bd6c76a0abc42a6b303c1bff9744c2", "best_bid": "0.977", "best_ask": "0.981"}], "timestamp": "1769384737235", "event_type": "price_change"}}
{"_local_timestamp": "2026-01-25T23:45:37.306156+00:00", "data": {"market": "0xf2995999537ed00a9e1ed196dac5a34c8362b9e454200968eb123c60d21530d2", "price_changes": [{"asset_id": "105244305087066947375390379713039474916834963808658829713388931041101255731949", "price": "0.006", "size": "49.19", "side": "BUY", "hash": "9b19fec40d04c53d13e84ab3323b824348261e8c", "best_bid": "0.019", "best_ask": "0.023"}, {"asset_id": "106415214145522966179186096977094978918005217851026867362814745409109043718965", "price": "0.994", "size": "49.19", "side": "SELL", "hash": "70fa3dfdc2bd6c76a0abc42a6b303c1bff9744c2", "best_bid": "0.977", "best_ask": "0.981"}], "timestamp": "1769384737235", "event_type": "price_change"}}
{"_local_timestamp": "2026-01-25T23:45:37.839248+00:00", "data": {"market": "0xf2995999537ed00a9e1ed196dac5a34c8362b9e454200968eb123c60d21530d2", "price_changes": [{"asset_id": "105244305087066947375390379713039474916834963808658829713388931041101255731949", "price": "0.007", "size": "31.33", "side": "BUY", "hash": "051eaa1cf7664e2c775d5ac728801f23b3d29387", "best_bid": "0.019", "best_ask": "0.023"}, {"asset_id": "106415214145522966179186096977094978918005217851026867362814745409109043718965", "price": "0.993", "size": "31.33", "side": "SELL", "hash": "83f1a66d4aaabb2c5f9ec503fc3a2245c6504ef2", "best_bid": "0.977", "best_ask": "0.981"}], "timestamp": "1769384737768", "event_type": "price_change"}}
{"_local_timestamp": "2026-01-25T23:45:39.500976+00:00", "data": {"market": "0xf2995999537ed00a9e1ed196dac5a34c8362b9e454200968eb123c60d21530d2", "price_changes": [{"asset_id": "105244305087066947375390379713039474916834963808658829713388931041101255731949", "price": "0.007", "size": "16", "side": "BUY", "hash": "02fc6765254bd7afb3a329fbf9b32faecd4c6bd2", "best_bid": "0.019", "best_ask": "0.023"}, {"asset_id": "106415214145522966179186096977094978918005217851026867362814745409109043718965", "price": "0.993", "size": "16", "side": "SELL", "hash": "551ea89cb990dcafa9ac73abbedf5b6927020f80", "best_bid": "0.977", "best_ask": "0.981"}], "timestamp": "1769384739429", "event_type": "price_change"}}
{"_local_timestamp": "2026-01-25T23:45:40.463040+00:00", "data": {"market": "0xf2995999537ed00a9e1ed196dac5a34c8362b9e454200968eb123c60d21530d2", "price_changes": [{"asset_id": "105244305087066947375390379713039474916834963808658829713388931041101255731949", "price": "0.008", "size": "28.52", "side": "BUY", "hash": "71680279a1550761a880dea2ea2f771412104d93", "best_bid": "0.019", "best_ask": "0.023"}, {"asset_id": "106415214145522966179186096977094978918005217851026867362814745409109043718965", "price": "0.992", "size": "28.52", "side": "SELL", "hash": "1e2e83de5f274e1f1dd267d2e544466c7cf8994e", "best_bid": "0.977", "best_ask": "0.981"}], "timestamp": "1769384740394", "event_type": "price_change"}}
{"_local_timestamp": "2026-01-25T23:45:40.919246+00:00", "data": {"market": "0xf2995999537ed00a9e1ed196dac5a34c8362b9e454200968eb123c60d21530d2", "price_changes": [{"asset_id": "105244305087066947375390379713039474916834963808658829713388931041101255731949", "price": "0.008", "size": "15.1", "side": "BUY", "hash": "1b78fedf33cae443a45c416c4ede89a846774e13", "best_bid": "0.019", "best_ask": "0.023"}, {"asset_id": "106415214145522966179186096977094978918005217851026867362814745409109043718965", "price": "0.992", "size": "15.1", "side": "SELL", "hash": "4cac70d60b47b6dec68314caa2526e01f4d865e9", "best_bid": "0.977", "best_ask": "0.981"}], "timestamp": "1769384740852", "event_type": "price_change"}}
{"_local_timestamp": "2026-01-25T23:45:41.374606+00:00", "data": {"market": "0xf2995999537ed00a9e1ed196dac5a34c8362b9e454200968eb123c60d21530d2", "price_changes": [{"asset_id": "105244305087066947375390379713039474916834963808658829713388931041101255731949", "price": "0.009", "size": "11.92", "side": "BUY", "hash": "fcf6b9c0e05da7c7c0ac4f723fe31affd9dd5730", "best_bid": "0.019", "best_ask": "0.023"}, {"asset_id": "106415214145522966179186096977094978918005217851026867362814745409109043718965", "price": "0.991", "size": "11.92", "side": "SELL", "hash": "916c3c267d5af13fa6ae225caadd0875091daf66", "best_bid": "0.977", "best_ask": "0.981"}], "timestamp": "1769384741310", "event_type": "price_change"}}
{"_local_timestamp": "2026-01-25T23:45:42.147959+00:00", "data": {"market": "0xf2995999537ed00a9e1ed196dac5a34c8362b9e454200968eb123c60d21530d2", "price_changes": [{"asset_id": "105244305087066947375390379713039474916834963808658829713388931041101255731949", "price": "0.009", "size": "0", "side": "BUY", "hash": "0e16e1c8dff78cd211fdcd9cbfe0b619d576c071", "best_bid": "0.019", "best_ask": "0.023"}, {"asset_id": "106415214145522966179186096977094978918005217851026867362814745409109043718965", "price": "0.991", "size": "0", "side": "SELL", "hash": "664ce68345bd12691a616a6b6dcd244b0c135499", "best_bid": "0.977", "best_ask": "0.981"}], "timestamp": "1769384742073", "event_type": "price_change"}}
{"_local_timestamp": "2026-01-25T23:45:42.526799+00:00", "data": {"market": "0xf2995999537ed00a9e1ed196dac5a34c8362b9e454200968eb123c60d21530d2", "price_changes": [{"asset_id": "105244305087066947375390379713039474916834963808658829713388931041101255731949", "price": "0.006", "size": "64.93", "side": "BUY", "hash": "a54c7b89f10dd9fe4a0f707b2691b493dbaf8166", "best_bid": "0.019", "best_ask": "0.023"}, {"asset_id": "106415214145522966179186096977094978918005217851026867362814745409109043718965", "price": "0.994", "size": "64.93", "side": "SELL", "hash": "56316f5523ec62b576006e75c6a3ce4cabf54ceb", "best_bid": "0.977", "best_ask": "0.981"}], "timestamp": "1769384742462", "event_type": "price_change"}}
{"_local_timestamp": "2026-01-25T23:45:42.527149+00:00", "data": {"market": "0xf2995999537ed00a9e1ed196dac5a34c8362b9e454200968eb123c60d21530d2", "price_changes": [{"asset_id": "105244305087066947375390379713039474916834963808658829713388931041101255731949", "price": "0.002", "size": "225.99", "side": "BUY", "hash": "c3d906472bb4127219f61e28d6cb2911b3e50fd4", "best_bid": "0.019", "best_ask": "0.023"}, {"asset_id": "106415214145522966179186096977094978918005217851026867362814745409109043718965", "price": "0.998", "size": "225.99", "side": "SELL", "hash": "fa064794d17624371a55d7ee0c84c1598e878eee", "best_bid": "0.977", "best_ask": "0.981"}], "timestamp": "1769384742464", "event_type": "price_change"}}
{"_local_timestamp": "2026-01-25T23:45:43.393690+00:00", "data": {"market": "0xf2995999537ed00a9e1ed196dac5a34c8362b9e454200968eb123c60d21530d2", "price_changes": [{"asset_id": "105244305087066947375390379713039474916834963808658829713388931041101255731949", "price": "0.002", "size": "219.53", "side": "BUY", "hash": "d9cc4646503285032b673462e3973f1813e84760", "best_bid": "0.019", "best_ask": "0.023"}, {"asset_id": "106415214145522966179186096977094978918005217851026867362814745409109043718965", "price": "0.998", "size": "219.53", "side": "SELL", "hash": "ef637e28928cb3aed1151674f7605c5afa6ea375", "best_bid": "0.977", "best_ask": "0.981"}], "timestamp": "1769384743328", "event_type": "price_change"}}
{"_local_timestamp": "2026-01-25T23:45:43.394112+00:00", "data": {"market": "0xf2995999537ed00a9e1ed196dac5a34c8362b9e454200968eb123c60d21530d2", "price_changes": [{"asset_id": "105244305087066947375390379713039474916834963808658829713388931041101255731949", "price": "0.006", "size": "49.19", "side": "BUY", "hash": "d9cc4646503285032b673462e3973f1813e84760", "best_bid": "0.019", "best_ask": "0.023"}, {"asset_id": "106415214145522966179186096977094978918005217851026867362814745409109043718965", "price": "0.994", "size": "49.19", "side": "SELL", "hash": "ef637e28928cb3aed1151674f7605c5afa6ea375", "best_bid": "0.977", "best_ask": "0.981"}], "timestamp": "1769384743328", "event_type": "price_change"}}
{"_local_timestamp": "2026-01-25T23:45:43.830880+00:00", "data": {"market": "0xf2995999537ed00a9e1ed196dac5a34c8362b9e454200968eb123c60d21530d2", "price_changes": [{"asset_id": "105244305087066947375390379713039474916834963808658829713388931041101255731949", "price": "0.002", "size": "225.99", "side": "BUY", "hash": "ffa60ad5b7c999d1c04947115d66912c78074be4", "best_bid": "0.019", "best_ask": "0.023"}, {"asset_id": "106415214145522966179186096977094978918005217851026867362814745409109043718965", "price": "0.998", "size": "225.99", "side": "SELL", "hash": "802b85cdc8b3555515775e52c71ba01e7b10b408", "best_bid": "0.977", "best_ask": "0.981"}], "timestamp": "1769384743766", "event_type": "price_change"}}
{"_local_timestamp": "2026-01-25T23:45:43.831210+00:00", "data": {"market": "0xf2995999537ed00a9e1ed196dac5a34c8362b9e454200968eb123c60d21530d2", "price_changes": [{"asset_id": "105244305087066947375390379713039474916834963808658829713388931041101255731949", "price": "0.006", "size": "64.93", "side": "BUY", "hash": "22bf5fd94ec9ce4f44e0ddf94e0c080aff2b1efe", "best_bid": "0.019", "best_ask": "0.023"}, {"asset_id": "106415214145522966179186096977094978918005217851026867362814745409109043718965", "price": "0.994", "size": "64.93", "side": "SELL", "hash": "8efdcef6c3f74815d7c3809b92e5b6677c1061c5", "best_bid": "0.977", "best_ask": "0.981"}], "timestamp": "1769384743768", "event_type": "price_change"}}
{"_local_timestamp": "2026-01-25T23:45:44.283905+00:00", "data": {"market": "0xf2995999537ed00a9e1ed196dac5a34c8362b9e454200968eb123c60d21530d2", "price_changes": [{"asset_id": "105244305087066947375390379713039474916834963808658829713388931041101255731949", "price": "0.002", "size": "219.53", "side": "BUY", "hash": "3db8ebfb88be5d8a36ff3cbfc4d97ff5afbea59c", "best_bid": "0.019", "best_ask": "0.023"}, {"asset_id": "106415214145522966179186096977094978918005217851026867362814745409109043718965", "price": "0.998", "size": "219.53", "side": "SELL", "hash": "0912f74dace73371f444d67e2551745c0604ac5a", "best_bid": "0.977", "best_ask": "0.981"}], "timestamp": "1769384744213", "event_type": "price_change"}}
{"_local_timestamp": "2026-01-25T23:45:44.284208+00:00", "data": {"market": "0xf2995999537ed00a9e1ed196dac5a34c8362b9e454200968eb123c60d21530d2", "price_changes": [{"asset_id": "105244305087066947375390379713039474916834963808658829713388931041101255731949", "price": "0.006", "size": "49.19", "side": "BUY", "hash": "3db8ebfb88be5d8a36ff3cbfc4d97ff5afbea59c", "best_bid": "0.019", "best_ask": "0.023"}, {"asset_id": "106415214145522966179186096977094978918005217851026867362814745409109043718965", "price": "0.994", "size": "49.19", "side": "SELL", "hash": "0912f74dace73371f444d67e2551745c0604ac5a", "best_bid": "0.977", "best_ask": "0.981"}], "timestamp": "1769384744213", "event_type": "price_change"}}
{"_local_timestamp": "2026-01-25T23:45:45.137085+00:00", "data": {"market": "0xf2995999537ed00a9e1ed196dac5a34c8362b9e454200968eb123c60d21530d2", "price_changes": [{"asset_id": "105244305087066947375390379713039474916834963808658829713388931041101255731949", "price": "0.007", "size": "31.33", "side": "BUY", "hash": "3165e1b2e5908dbe85062df1ee39bd7fa34830ae", "best_bid": "0.019", "best_ask": "0.023"}, {"asset_id": "106415214145522966179186096977094978918005217851026867362814745409109043718965", "price": "0.993", "size": "31.33", "side": "SELL", "hash": "46654edd887c5c87139276998aedf230f77fcfab", "best_bid": "0.977", "best_ask": "0.981"}], "timestamp": "1769384745072", "event_type": "price_change"}}
{"_local_timestamp": "2026-01-25T23:45:45.661672+00:00", "data": {"market": "0xf2995999537ed00a9e1ed196dac5a34c8362b9e454200968eb123c60d21530d2", "price_changes": [{"asset_id": "105244305087066947375390379713039474916834963808658829713388931041101255731949", "price": "0.007", "size": "16", "side": "BUY", "hash": "36bfe5c2e114d0af0789f2aac25b835345fccfad", "best_bid": "0.019", "best_ask": "0.023"}, {"asset_id": "106415214145522966179186096977094978918005217851026867362814745409109043718965", "price": "0.993", "size": "16", "side": "SELL", "hash": "a97689aac77ab9158db272586393f9bb3d958a59", "best_bid": "0.977", "best_ask": "0.981"}], "timestamp": "1769384745597", "event_type": "price_change"}}
{"_local_timestamp": "2026-01-25T23:45:45.972810+00:00", "data": {"market": "0xf2995999537ed00a9e1ed196dac5a34c8362b9e454200968eb123c60d21530d2", "price_changes": [{"asset_id": "105244305087066947375390379713039474916834963808658829713388931041101255731949", "price": "0.002", "size": "225.99", "side": "BUY", "hash": "653d974070750bcd1f332ccdd4ccf3b8b6b82eb0", "best_bid": "0.019", "best_ask": "0.023"}, {"asset_id": "106415214145522966179186096977094978918005217851026867362814745409109043718965", "price": "0.998", "size": "225.99", "side": "SELL", "hash": "d2876663990e4800b21354ecaa7b30fff7e14237", "best_bid": "0.977", "best_ask": "0.981"}], "timestamp": "1769384745911", "event_type": "price_change"}}
{"_local_timestamp": "2026-01-25T23:45:45.973126+00:00", "data": {"market": "0xf2995999537ed00a9e1ed196dac5a34c8362b9e454200968eb123c60d21530d2", "price_changes": [{"asset_id": "105244305087066947375390379713039474916834963808658829713388931041101255731949", "price": "0.006", "size": "64.93", "side": "BUY", "hash": "50b234d905be37570d39ef15c89b72f7fd174431", "best_bid": "0.019", "best_ask": "0.023"}, {"asset_id": "106415214145522966179186096977094978918005217851026867362814745409109043718965", "price": "0.994", "size": "64.93", "side": "SELL", "hash": "1a432319178b35ac3cc42012701054c49f13a19b", "best_bid": "0.977", "best_ask": "0.981"}], "timestamp": "1769384745912", "event_type": "price_change"}}
{"_local_timestamp": "2026-01-25T23:45:47.577499+00:00", "data": {"market": "0xf2995999537ed00a9e1ed196dac5a34c8362b9e454200968eb123c60d21530d2", "price_changes": [{"asset_id": "105244305087066947375390379713039474916834963808658829713388931041101255731949", "price": "0.002", "size": "219.53", "side": "BUY", "hash": "ee878009b318c522f323f99cfbf21d5d41c1b365", "best_bid": "0.019", "best_ask": "0.023"}, {"asset_id": "106415214145522966179186096977094978918005217851026867362814745409109043718965", "price": "0.998", "size": "219.53", "side": "SELL", "hash": "4df489b093a7ce2efab90dff534ad19fe43a48ca", "best_bid": "0.977", "best_ask": "0.981"}], "timestamp": "1769384747508", "event_type": "price_change"}}
{"_local_timestamp": "2026-01-25T23:45:47.577842+00:00", "data": {"market": "0xf2995999537ed00a9e1ed196dac5a34c8362b9e454200968eb123c60d21530d2", "price_changes": [{"asset_id": "105244305087066947375390379713039474916834963808658829713388931041101255731949", "price": "0.006", "size": "49.19", "side": "BUY", "hash": "ee878009b318c522f323f99cfbf21d5d41c1b365", "best_bid": "0.019", "best_ask": "0.023"}, {"asset_id": "106415214145522966179186096977094978918005217851026867362814745409109043718965", "price": "0.994", "size": "49.19", "side": "SELL", "hash": "4df489b093a7ce2efab90dff534ad19fe43a48ca", "best_bid": "0.977", "best_ask": "0.981"}], "timestamp": "1769384747508", "event_type": "price_change"}}
{"_local_timestamp": "2026-01-25T23:45:48.085290+00:00", "data": {"market": "0xf2995999537ed00a9e1ed196dac5a34c8362b9e454200968eb123c60d21530d2", "price_changes": [{"asset_id": "105244305087066947375390379713039474916834963808658829713388931041101255731949", "price": "0.007", "size": "31.33", "side": "BUY", "hash": "f6157a9aa29b2d4df901b040719254545b1558ea", "best_bid": "0.019", "best_ask": "0.023"}, {"asset_id": "106415214145522966179186096977094978918005217851026867362814745409109043718965", "price": "0.993", "size": "31.33", "side": "SELL", "hash": "9106800fe0ee57a5cc59ce3c58d10a0d3ec23ca1", "best_bid": "0.977", "best_ask": "0.981"}], "timestamp": "1769384748015", "event_type": "price_change"}}
{"_local_timestamp": "2026-01-25T23:45:49.336808+00:00", "data": {"market": "0xf2995999537ed00a9e1ed196dac5a34c8362b9e454200968eb123c60d21530d2", "price_changes": [{"asset_id": "105244305087066947375390379713039474916834963808658829713388931041101255731949", "price": "0.007", "size": "16", "side": "BUY", "hash": "b3bcef70102b25bda42f5a759a38ba4007826a32", "best_bid": "0.019", "best_ask": "0.023"}, {"asset_id": "106415214145522966179186096977094978918005217851026867362814745409109043718965", "price": "0.993", "size": "16", "side": "SELL", "hash": "64d73669b5e84967054338627d02e23fa4638cf6", "best_bid": "0.977", "best_ask": "0.981"}], "timestamp": "1769384749272", "event_type": "price_change"}}
{"_local_timestamp": "2026-01-25T23:45:49.748220+00:00", "data": {"market": "0xf2995999537ed00a9e1ed196dac5a34c8362b9e454200968eb123c60d21530d2", "price_changes": [{"asset_id": "105244305087066947375390379713039474916834963808658829713388931041101255731949", "price": "0.008", "size": "28.52", "side": "BUY", "hash": "e827122cd533c8d3f60db27d4693b8ddd8fdf1bf", "best_bid": "0.019", "best_ask": "0.023"}, {"asset_id": "106415214145522966179186096977094978918005217851026867362814745409109043718965", "price": "0.992", "size": "28.52", "side": "SELL", "hash": "fac44f6d9c82efc15d7cbc4dc60557f2a60260b9", "best_bid": "0.977", "best_ask": "0.981"}], "timestamp": "1769384749681", "event_type": "price_change"}}
{"_local_timestamp": "2026-01-25T23:45:50.711672+00:00", "data": {"market": "0xf2995999537ed00a9e1ed196dac5a34c8362b9e454200968eb123c60d21530d2", "price_changes": [{"asset_id": "105244305087066947375390379713039474916834963808658829713388931041101255731949", "price": "0.008", "size": "15.1", "side": "BUY", "hash": "d876e5efcc14be85a4f52c47dc98f05fbd77e32d", "best_bid": "0.019", "best_ask": "0.023"}, {"asset_id": "106415214145522966179186096977094978918005217851026867362814745409109043718965", "price": "0.992", "size": "15.1", "side": "SELL", "hash": "1a095fa457012846640202fe68d25de87516959f", "best_bid": "0.977", "best_ask": "0.981"}], "timestamp": "1769384750646", "event_type": "price_change"}}
{"_local_timestamp": "2026-01-25T23:45:51.196925+00:00", "data": {"market": "0xf2995999537ed00a9e1ed196dac5a34c8362b9e454200968eb123c60d21530d2", "price_changes": [{"asset_id": "105244305087066947375390379713039474916834963808658829713388931041101255731949", "price": "0.002", "size": "225.99", "side": "BUY", "hash": "74aa737097cbb83aa04f9a0774f8e0b595269540", "best_bid": "0.019", "best_ask": "0.023"}, {"asset_id": "106415214145522966179186096977094978918005217851026867362814745409109043718965", "price": "0.998", "size": "225.99", "side": "SELL", "hash": "1148e45c064bdad57e08f72c8c3d84775b189836", "best_bid": "0.977", "best_ask": "0.981"}], "timestamp": "1769384751136", "event_type": "price_change"}}
{"_local_timestamp": "2026-01-25T23:45:51.201829+00:00", "data": {"market": "0xf2995999537ed00a9e1ed196dac5a34c8362b9e454200968eb123c60d21530d2", "price_changes": [{"asset_id": "105244305087066947375390379713039474916834963808658829713388931041101255731949", "price": "0.006", "size": "64.93", "side": "BUY", "hash": "045729287c846db96b9f715478a515ab26d0f8da", "best_bid": "0.019", "best_ask": "0.023"}, {"asset_id": "106415214145522966179186096977094978918005217851026867362814745409109043718965", "price": "0.994", "size": "64.93", "side": "SELL", "hash": "6ce2d9066bc471b78fae4d070bcf4752cceecc4b", "best_bid": "0.977", "best_ask": "0.981"}], "timestamp": "1769384751137", "event_type": "price_change"}}
{"_local_timestamp": "2026-01-25T23:45:52.243847+00:00", "data": {"market": "0xf2995999537ed00a9e1ed196dac5a34c8362b9e454200968eb123c60d21530d2", "price_changes": [{"asset_id": "105244305087066947375390379713039474916834963808658829713388931041101255731949", "price": "0.002", "size": "219.53", "side": "BUY", "hash": "c01275c44a4ef08a444c0d70f4a5797633817494", "best_bid": "0.019", "best_ask": "0.023"}, {"asset_id": "106415214145522966179186096977094978918005217851026867362814745409109043718965", "price": "0.998", "size": "219.53", "side": "SELL", "hash": "6a0c2169359cd3ab1f179df359593cd9f58d52c0", "best_bid": "0.977", "best_ask": "0.981"}], "timestamp": "1769384752176", "event_type": "price_change"}}
{"_local_timestamp": "2026-01-25T23:45:52.244301+00:00", "data": {"market": "0xf2995999537ed00a9e1ed196dac5a34c8362b9e454200968eb123c60d21530d2", "price_changes": [{"asset_id": "105244305087066947375390379713039474916834963808658829713388931041101255731949", "price": "0.006", "size": "49.19", "side": "BUY", "hash": "c01275c44a4ef08a444c0d70f4a5797633817494", "best_bid": "0.019", "best_ask": "0.023"}, {"asset_id": "106415214145522966179186096977094978918005217851026867362814745409109043718965", "price": "0.994", "size": "49.19", "side": "SELL", "hash": "6a0c2169359cd3ab1f179df359593cd9f58d52c0", "best_bid": "0.977", "best_ask": "0.981"}], "timestamp": "1769384752176", "event_type": "price_change"}}
{"_local_timestamp": "2026-01-25T23:45:52.734676+00:00", "data": {"market": "0xf2995999537ed00a9e1ed196dac5a34c8362b9e454200968eb123c60d21530d2", "price_changes": [{"asset_id": "105244305087066947375390379713039474916834963808658829713388931041101255731949", "price": "0.007", "size": "31.33", "side": "BUY", "hash": "210f2532c5266ebb6a2bd1f042fd553a288d5d3b", "best_bid": "0.019", "best_ask": "0.023"}, {"asset_id": "106415214145522966179186096977094978918005217851026867362814745409109043718965", "price": "0.993", "size": "31.33", "side": "SELL", "hash": "079549609ed716d8f545536cf547faadbea82a81", "best_bid": "0.977", "best_ask": "0.981"}], "timestamp": "1769384752665", "event_type": "price_change"}}
{"_local_timestamp": "2026-01-25T23:45:53.758458+00:00", "data": {"market": "0xf2995999537ed00a9e1ed196dac5a34c8362b9e454200968eb123c60d21530d2", "price_changes": [{"asset_id": "105244305087066947375390379713039474916834963808658829713388931041101255731949", "price": "0.007", "size": "16", "side": "BUY", "hash": "5ece0015e9ccb00c55746ddaaddd4d3a3fecc284", "best_bid": "0.019", "best_ask": "0.023"}, {"asset_id": "106415214145522966179186096977094978918005217851026867362814745409109043718965", "price": "0.993", "size": "16", "side": "SELL", "hash": "ce88ecb8a13b662c23bab36e7dc5e72c97580365", "best_bid": "0.977", "best_ask": "0.981"}], "timestamp": "1769384753571", "event_type": "price_change"}}
{"_local_timestamp": "2026-01-25T23:45:54.379606+00:00", "data": {"market": "0xf2995999537ed00a9e1ed196dac5a34c8362b9e454200968eb123c60d21530d2", "price_changes": [{"asset_id": "105244305087066947375390379713039474916834963808658829713388931041101255731949", "price": "0.008", "size": "28.52", "side": "BUY", "hash": "a3ed0b8ef8606e8dc272ae3355198bffdff55769", "best_bid": "0.019", "best_ask": "0.023"}, {"asset_id": "106415214145522966179186096977094978918005217851026867362814745409109043718965", "price": "0.992", "size": "28.52", "side": "SELL", "hash": "56193a41498ab005678cad4cabdabcd10ff7c5c6", "best_bid": "0.977", "best_ask": "0.981"}], "timestamp": "1769384754305", "event_type": "price_change"}}
{"_local_timestamp": "2026-01-25T23:45:55.168495+00:00", "data": {"market": "0xf2995999537ed00a9e1ed196dac5a34c8362b9e454200968eb123c60d21530d2", "price_changes": [{"asset_id": "105244305087066947375390379713039474916834963808658829713388931041101255731949", "price": "0.008", "size": "15.1", "side": "BUY", "hash": "2ceaab729a221f5a43893c31349102df646a6e9f", "best_bid": "0.019", "best_ask": "0.023"}, {"asset_id": "106415214145522966179186096977094978918005217851026867362814745409109043718965", "price": "0.992", "size": "15.1", "side": "SELL", "hash": "0ea1c0d4eba8d4c72e1d0e9a68fd8447e2c77479", "best_bid": "0.977", "best_ask": "0.981"}], "timestamp": "1769384755100", "event_type": "price_change"}}
{"_local_timestamp": "2026-01-25T23:45:55.680330+00:00", "data": {"market": "0xf2995999537ed00a9e1ed196dac5a34c8362b9e454200968eb123c60d21530d2", "price_changes": [{"asset_id": "105244305087066947375390379713039474916834963808658829713388931041101255731949", "price": "0.006", "size": "64.93", "side": "BUY", "hash": "4f336e57f9668bcbd55e0de8ac8d00478af3285a", "best_bid": "0.019", "best_ask": "0.023"}, {"asset_id": "106415214145522966179186096977094978918005217851026867362814745409109043718965", "price": "0.994", "size": "64.93", "side": "SELL", "hash": "db6c5d1adaebc45a612724a8cfa46c75d1d1d823", "best_bid": "0.977", "best_ask": "0.981"}], "timestamp": "1769384755607", "event_type": "price_change"}}
{"_local_timestamp": "2026-01-25T23:45:55.681105+00:00", "data": {"market": "0xf2995999537ed00a9e1ed196dac5a34c8362b9e454200968eb123c60d21530d2", "price_changes": [{"asset_id": "105244305087066947375390379713039474916834963808658829713388931041101255731949", "price": "0.002", "size": "225.99", "side": "BUY", "hash": "36eab2911d0a820e7def0dd0364e5df5c8261ef2", "best_bid": "0.019", "best_ask": "0.023"}, {"asset_id": "106415214145522966179186096977094978918005217851026867362814745409109043718965", "price": "0.998", "size": "225.99", "side": "SELL", "hash": "669bf817e9e87744eb80c0507f8823ad307f5815", "best_bid": "0.977", "best_ask": "0.981"}], "timestamp": "1769384755615", "event_type": "price_change"}}
{"_local_timestamp": "2026-01-25T23:45:57.162940+00:00", "data": {"market": "0xf2995999537ed00a9e1ed196dac5a34c8362b9e454200968eb123c60d21530d2", "price_changes": [{"asset_id": "105244305087066947375390379713039474916834963808658829713388931041101255731949", "price": "0.002", "size": "219.53", "side": "BUY", "hash": "217c9277f545d37e78fcb5dd416e828394593189", "best_bid": "0.019", "best_ask": "0.023"}, {"asset_id": "106415214145522966179186096977094978918005217851026867362814745409109043718965", "price": "0.998", "size": "219.53", "side": "SELL", "hash": "2ff3113ade13e5a75e2630e7f38aa3ff116597c7", "best_bid": "0.977", "best_ask": "0.981"}], "timestamp": "1769384756682", "event_type": "price_change"}}
{"_local_timestamp": "2026-01-25T23:45:57.163346+00:00", "data": {"market": "0xf2995999537ed00a9e1ed196dac5a34c8362b9e454200968eb123c60d21530d2", "price_changes": [{"asset_id": "105244305087066947375390379713039474916834963808658829713388931041101255731949", "price": "0.006", "size": "49.19", "side": "BUY", "hash": "217c9277f545d37e78fcb5dd416e828394593189", "best_bid": "0.019", "best_ask": "0.023"}, {"asset_id": "106415214145522966179186096977094978918005217851026867362814745409109043718965", "price": "0.994", "size": "49.19", "side": "SELL", "hash": "2ff3113ade13e5a75e2630e7f38aa3ff116597c7", "best_bid": "0.977", "best_ask": "0.981"}], "timestamp": "1769384756682", "event_type": "price_change"}}
{"_local_timestamp": "2026-01-25T23:45:57.361453+00:00", "data": {"market": "0xf2995999537ed00a9e1ed196dac5a34c8362b9e454200968eb123c60d21530d2", "price_changes": [{"asset_id": "105244305087066947375390379713039474916834963808658829713388931041101255731949", "price": "0.007", "size": "31.33", "side": "BUY", "hash": "22675bf92bdfb0b4b477e8a1e7e1ef1801ca57c7", "best_bid": "0.019", "best_ask": "0.023"}, {"asset_id": "106415214145522966179186096977094978918005217851026867362814745409109043718965", "price": "0.993", "size": "31.33", "side": "SELL", "hash": "08ade164edff101a9b6dd62c5aaa614151958cd2", "best_bid": "0.977", "best_ask": "0.981"}], "timestamp": "1769384757148", "event_type": "price_change"}}
{"_local_timestamp": "2026-01-25T23:45:58.138812+00:00", "data": {"market": "0xf2995999537ed00a9e1ed196dac5a34c8362b9e454200968eb123c60d21530d2", "price_changes": [{"asset_id": "105244305087066947375390379713039474916834963808658829713388931041101255731949", "price": "0.023", "size": "188.64", "side": "SELL", "hash": "7da6952034b30844563175c2f8cd18afeb5cb660", "best_bid": "0.019", "best_ask": "0.023"}, {"asset_id": "106415214145522966179186096977094978918005217851026867362814745409109043718965", "price": "0.977", "size": "188.64", "side": "BUY", "hash": "34cb5272fb116a0c3f90f35ec766a8a72561e933", "best_bid": "0.977", "best_ask": "0.981"}], "timestamp": "1769384758060", "event_type": "price_change"}}
{"_local_timestamp": "2026-01-25T23:45:59.372373+00:00", "data": {"market": "0xf2995999537ed00a9e1ed196dac5a34c8362b9e454200968eb123c60d21530d2", "price_changes": [{"asset_id": "105244305087066947375390379713039474916834963808658829713388931041101255731949", "price": "0.007", "size": "16", "side": "BUY", "hash": "f99e0977b5098dcafbe7143c1c7d00868bc4074e", "best_bid": "0.019", "best_ask": "0.023"}, {"asset_id": "106415214145522966179186096977094978918005217851026867362814745409109043718965", "price": "0.993", "size": "16", "side": "SELL", "hash": "e53c6978ca3af8b844f51caa4413183fe07ddb19", "best_bid": "0.977", "best_ask": "0.981"}], "timestamp": "1769384759296", "event_type": "price_change"}}
{"_local_timestamp": "2026-01-25T23:45:59.734240+00:00", "data": {"market": "0xf2995999537ed00a9e1ed196dac5a34c8362b9e454200968eb123c60d21530d2", "price_changes": [{"asset_id": "105244305087066947375390379713039474916834963808658829713388931041101255731949", "price": "0.002", "size": "225.99", "side": "BUY", "hash": "30c8732c9dec1a47005f100e81aaf4ab060bb0e0", "best_bid": "0.019", "best_ask": "0.023"}, {"asset_id": "106415214145522966179186096977094978918005217851026867362814745409109043718965", "price": "0.998", "size": "225.99", "side": "SELL", "hash": "d2328ddf181ea5c86832cf242051ad5ec165dd79", "best_bid": "0.977", "best_ask": "0.981"}], "timestamp": "1769384759663", "event_type": "price_change"}}
{"_local_timestamp": "2026-01-25T23:45:59.744683+00:00", "data": {"market": "0xf2995999537ed00a9e1ed196dac5a34c8362b9e454200968eb123c60d21530d2", "price_changes": [{"asset_id": "105244305087066947375390379713039474916834963808658829713388931041101255731949", "price": "0.006", "size": "64.93", "side": "BUY", "hash": "c4d64861d7cc4f91733e35683a7f3b28146fe3ea", "best_bid": "0.019", "best_ask": "0.023"}, {"asset_id": "106415214145522966179186096977094978918005217851026867362814745409109043718965", "price": "0.994", "size": "64.93", "side": "SELL", "hash": "7021eb898a46233b9e21eb95dfb639fe37cb138c", "best_bid": "0.977", "best_ask": "0.981"}], "timestamp": "1769384759665", "event_type": "price_change"}}
{"_local_timestamp": "2026-01-25T23:46:02.107084+00:00", "data": {"market": "0xf2995999537ed00a9e1ed196dac5a34c8362b9e454200968eb123c60d21530d2", "price_changes": [{"asset_id": "105244305087066947375390379713039474916834963808658829713388931041101255731949", "price": "0.002", "size": "219.53", "side": "BUY", "hash": "3fb252aa1dd6cddea7a61c1b612bd33f0dba5480", "best_bid": "0.019", "best_ask": "0.023"}, {"asset_id": "106415214145522966179186096977094978918005217851026867362814745409109043718965", "price": "0.998", "size": "219.53", "side": "SELL", "hash": "e4ead7939a5fcaf8e445cb7eb25c32eae884d282", "best_bid": "0.977", "best_ask": "0.981"}], "timestamp": "1769384762009", "event_type": "price_change"}}
{"_local_timestamp": "2026-01-25T23:46:02.107445+00:00", "data": {"market": "0xf2995999537ed00a9e1ed196dac5a34c8362b9e454200968eb123c60d21530d2", "price_changes": [{"asset_id": "105244305087066947375390379713039474916834963808658829713388931041101255731949", "price": "0.006", "size": "49.19", "side": "BUY", "hash": "3fb252aa1dd6cddea7a61c1b612bd33f0dba5480", "best_bid": "0.019", "best_ask": "0.023"}, {"asset_id": "106415214145522966179186096977094978918005217851026867362814745409109043718965", "price": "0.994", "size": "49.19", "side": "SELL", "hash": "e4ead7939a5fcaf8e445cb7eb25c32eae884d282", "best_bid": "0.977", "best_ask": "0.981"}], "timestamp": "1769384762009", "event_type": "price_change"}}
{"_local_timestamp": "2026-01-25T23:46:02.514103+00:00", "data": {"market": "0xf2995999537ed00a9e1ed196dac5a34c8362b9e454200968eb123c60d21530d2", "price_changes": [{"asset_id": "105244305087066947375390379713039474916834963808658829713388931041101255731949", "price": "0.007", "size": "31.33", "side": "BUY", "hash": "69bf8e236fa5acf38ac976c88fb3dcf140ae249b", "best_bid": "0.019", "best_ask": "0.023"}, {"asset_id": "106415214145522966179186096977094978918005217851026867362814745409109043718965", "price": "0.993", "size": "31.33", "side": "SELL", "hash": "e930747ae88c636188aa8cd1c1c50fcf4cd0d21a", "best_bid": "0.977", "best_ask": "0.981"}], "timestamp": "1769384762448", "event_type": "price_change"}}
{"_local_timestamp": "2026-01-25T23:46:02.995051+00:00", "data": {"market": "0xf2995999537ed00a9e1ed196dac5a34c8362b9e454200968eb123c60d21530d2", "price_changes": [{"asset_id": "105244305087066947375390379713039474916834963808658829713388931041101255731949", "price": "0.007", "size": "16", "side": "BUY", "hash": "b7c4de44187e85cb2fc1d673d858856ba404103b", "best_bid": "0.019", "best_ask": "0.023"}, {"asset_id": "106415214145522966179186096977094978918005217851026867362814745409109043718965", "price": "0.993", "size": "16", "side": "SELL", "hash": "3695c4ec41def86de6be5fb126de48e25af14c22", "best_bid": "0.977", "best_ask": "0.981"}], "timestamp": "1769384762925", "event_type": "price_change"}}
{"_local_timestamp": "2026-01-25T23:46:03.802527+00:00", "data": {"market": "0xf2995999537ed00a9e1ed196dac5a34c8362b9e454200968eb123c60d21530d2", "price_changes": [{"asset_id": "105244305087066947375390379713039474916834963808658829713388931041101255731949", "price": "0.006", "size": "64.93", "side": "BUY", "hash": "b2ab4eb033720ac38b28c85965c2e9c2ac53fe55", "best_bid": "0.019", "best_ask": "0.023"}, {"asset_id": "106415214145522966179186096977094978918005217851026867362814745409109043718965", "price": "0.994", "size": "64.93", "side": "SELL", "hash": "44221b6730c78355a47d38eb6ab367bff247edb4", "best_bid": "0.977", "best_ask": "0.981"}], "timestamp": "1769384763730", "event_type": "price_change"}}
{"_local_timestamp": "2026-01-25T23:46:03.811185+00:00", "data": {"market": "0xf2995999537ed00a9e1ed196dac5a34c8362b9e454200968eb123c60d21530d2", "price_changes": [{"asset_id": "105244305087066947375390379713039474916834963808658829713388931041101255731949", "price": "0.002", "size": "225.99", "side": "BUY", "hash": "f68f8bb5335a32246b2c82f8be50a528388acc86", "best_bid": "0.019", "best_ask": "0.023"}, {"asset_id": "106415214145522966179186096977094978918005217851026867362814745409109043718965", "price": "0.998", "size": "225.99", "side": "SELL", "hash": "228c560d7abeae9261410ea6c135f5e3c9f28fa2", "best_bid": "0.977", "best_ask": "0.981"}], "timestamp": "1769384763732", "event_type": "price_change"}}
{"_local_timestamp": "2026-01-25T23:46:04.145986+00:00", "data": {"market": "0xf2995999537ed00a9e1ed196dac5a34c8362b9e454200968eb123c60d21530d2", "price_changes": [{"asset_id": "105244305087066947375390379713039474916834963808658829713388931041101255731949", "price": "0.024", "size": "130.38", "side": "SELL", "hash": "c8c5357bad2483d7277c8c9bd75cdb258158afce", "best_bid": "0.019", "best_ask": "0.023"}, {"asset_id": "106415214145522966179186096977094978918005217851026867362814745409109043718965", "price": "0.976", "size": "130.38", "side": "BUY", "hash": "1ab9f1730ce01b76b8d81db5aab7ebbede047365", "best_bid": "0.977", "best_ask": "0.981"}], "timestamp": "1769384764059", "event_type": "price_change"}}
{"_local_timestamp": "2026-01-25T23:46:04.339985+00:00", "data": {"market": "0xf2995999537ed00a9e1ed196dac5a34c8362b9e454200968eb123c60d21530d2", "price_changes": [{"asset_id": "105244305087066947375390379713039474916834963808658829713388931041101255731949", "price": "0.002", "size": "219.53", "side": "BUY", "hash": "de26512f78bb17021065d53fbf3f7f7eaae2c0d6", "best_bid": "0.019", "best_ask": "0.023"}, {"asset_id": "106415214145522966179186096977094978918005217851026867362814745409109043718965", "price": "0.998", "size": "219.53", "side": "SELL", "hash": "a3064b5ec2c4f5ccdacac273d369a6f703ec952e", "best_bid": "0.977", "best_ask": "0.981"}], "timestamp": "1769384764266", "event_type": "price_change"}}
{"_local_timestamp": "2026-01-25T23:46:04.340302+00:00", "data": {"market": "0xf2995999537ed00a9e1ed196dac5a34c8362b9e454200968eb123c60d21530d2", "price_changes": [{"asset_id": "105244305087066947375390379713039474916834963808658829713388931041101255731949", "price": "0.006", "size": "49.19", "side": "BUY", "hash": "de26512f78bb17021065d53fbf3f7f7eaae2c0d6", "best_bid": "0.019", "best_ask": "0.023"}, {"asset_id": "106415214145522966179186096977094978918005217851026867362814745409109043718965", "price": "0.994", "size": "49.19", "side": "SELL", "hash": "a3064b5ec2c4f5ccdacac273d369a6f703ec952e", "best_bid": "0.977", "best_ask": "0.981"}], "timestamp": "1769384764266", "event_type": "price_change"}}
{"_local_timestamp": "2026-01-25T23:46:04.720446+00:00", "data": {"market": "0xf2995999537ed00a9e1ed196dac5a34c8362b9e454200968eb123c60d21530d2", "price_changes": [{"asset_id": "105244305087066947375390379713039474916834963808658829713388931041101255731949", "price": "0.007", "size": "31.33", "side": "BUY", "hash": "4a6372e6c236340393af9be26fea998e5e48adf4", "best_bid": "0.019", "best_ask": "0.023"}, {"asset_id": "106415214145522966179186096977094978918005217851026867362814745409109043718965", "price": "0.993", "size": "31.33", "side": "SELL", "hash": "6338566eb0091560dd05a4c5d6de50f2f893a135", "best_bid": "0.977", "best_ask": "0.981"}], "timestamp": "1769384764647", "event_type": "price_change"}}
{"_local_timestamp": "2026-01-25T23:46:06.547414+00:00", "data": {"market": "0xf2995999537ed00a9e1ed196dac5a34c8362b9e454200968eb123c60d21530d2", "price_changes": [{"asset_id": "105244305087066947375390379713039474916834963808658829713388931041101255731949", "price": "0.007", "size": "16", "side": "BUY", "hash": "6320768cf2800c63cf9651bd23ebc8969a9bdd7c", "best_bid": "0.019", "best_ask": "0.023"}, {"asset_id": "106415214145522966179186096977094978918005217851026867362814745409109043718965", "price": "0.993", "size": "16", "side": "SELL", "hash": "b5a39fa3b990b3aadc7b9c04822a716d44f340cb", "best_bid": "0.977", "best_ask": "0.981"}], "timestamp": "1769384766473", "event_type": "price_change"}}
{"_local_timestamp": "2026-01-25T23:46:06.885373+00:00", "data": {"market": "0xf2995999537ed00a9e1ed196dac5a34c8362b9e454200968eb123c60d21530d2", "price_changes": [{"asset_id": "105244305087066947375390379713039474916834963808658829713388931041101255731949", "price": "0.008", "size": "28.52", "side": "BUY", "hash": "8b57c42fe48a2b99b777fcdf25327684cdcafb4b", "best_bid": "0.019", "best_ask": "0.023"}, {"asset_id": "106415214145522966179186096977094978918005217851026867362814745409109043718965", "price": "0.992", "size": "28.52", "side": "SELL", "hash": "dde7dd955190202b791dd20f8f1118fb62dda314", "best_bid": "0.977", "best_ask": "0.981"}], "timestamp": "1769384766819", "event_type": "price_change"}}
{"_local_timestamp": "2026-01-25T23:46:07.509966+00:00", "data": {"market": "0xf2995999537ed00a9e1ed196dac5a34c8362b9e454200968eb123c60d21530d2", "price_changes": [{"asset_id": "106415214145522966179186096977094978918005217851026867362814745409109043718965", "price": "0.478", "size": "0", "side": "BUY", "hash": "88e340ec26294d40694a73fbb8946718bd16fe68", "best_bid": "0.977", "best_ask": "0.981"}, {"asset_id": "105244305087066947375390379713039474916834963808658829713388931041101255731949", "price": "0.522", "size": "0", "side": "SELL", "hash": "1d85ccb101fba33fa29a7f1ecf5c686ecefe68eb", "best_bid": "0.019", "best_ask": "0.023"}], "timestamp": "1769384767435", "event_type": "price_change"}}
{"_local_timestamp": "2026-01-25T23:46:08.100361+00:00", "data": {"market": "0xf2995999537ed00a9e1ed196dac5a34c8362b9e454200968eb123c60d21530d2", "price_changes": [{"asset_id": "106415214145522966179186096977094978918005217851026867362814745409109043718965", "price": "0.478", "size": "5", "side": "BUY", "hash": "5275a3eedced198782814d6a109e9385183918eb", "best_bid": "0.977", "best_ask": "0.981"}, {"asset_id": "105244305087066947375390379713039474916834963808658829713388931041101255731949", "price": "0.522", "size": "5", "side": "SELL", "hash": "75ee8316f20befd3f72db0d2f8b5eb578cc93a11", "best_bid": "0.019", "best_ask": "0.023"}], "timestamp": "1769384768008", "event_type": "price_change"}}
{"_local_timestamp": "2026-01-25T23:46:08.497230+00:00", "data": {"market": "0xf2995999537ed00a9e1ed196dac5a34c8362b9e454200968eb123c60d21530d2", "price_changes": [{"asset_id": "105244305087066947375390379713039474916834963808658829713388931041101255731949", "price": "0.008", "size": "15.1", "side": "BUY", "hash": "943997d5b1c4792a4cce2b8dd1385630d05568d5", "best_bid": "0.019", "best_ask": "0.023"}, {"asset_id": "106415214145522966179186096977094978918005217851026867362814745409109043718965", "price": "0.992", "size": "15.1", "side": "SELL", "hash": "88197daba2705d62a971ebd3148afce754f676a8", "best_bid": "0.977", "best_ask": "0.981"}], "timestamp": "1769384768421", "event_type": "price_change"}}
{"_local_timestamp": "2026-01-25T23:46:08.912731+00:00", "data": {"market": "0xf2995999537ed00a9e1ed196dac5a34c8362b9e454200968eb123c60d21530d2", "price_changes": [{"asset_id": "105244305087066947375390379713039474916834963808658829713388931041101255731949", "price": "0.009", "size": "11.92", "side": "BUY", "hash": "5fb335bae0e2ba5733224e9fd5e5f427ed835200", "best_bid": "0.019", "best_ask": "0.023"}, {"asset_id": "106415214145522966179186096977094978918005217851026867362814745409109043718965", "price": "0.991", "size": "11.92", "side": "SELL", "hash": "db934084b353d2519e5f331b27dc9c1e8c41b35e", "best_bid": "0.977", "best_ask": "0.981"}], "timestamp": "1769384768836", "event_type": "price_change"}}
{"_local_timestamp": "2026-01-25T23:46:09.373709+00:00", "data": {"market": "0xf2995999537ed00a9e1ed196dac5a34c8362b9e454200968eb123c60d21530d2", "price_changes": [{"asset_id": "105244305087066947375390379713039474916834963808658829713388931041101255731949", "price": "0.009", "size": "0", "side": "BUY", "hash": "3de8dc837126f3f2e60f58d84bc79e1b7950ee1d", "best_bid": "0.019", "best_ask": "0.023"}, {"asset_id": "106415214145522966179186096977094978918005217851026867362814745409109043718965", "price": "0.991", "size": "0", "side": "SELL", "hash": "c12e0c3826ae1c416f78a31eac163bfe7c3e8ccd", "best_bid": "0.977", "best_ask": "0.981"}], "timestamp": "1769384769306", "event_type": "price_change"}}
{"_local_timestamp": "2026-01-25T23:46:10.753904+00:00", "data": {"market": "0xf2995999537ed00a9e1ed196dac5a34c8362b9e454200968eb123c60d21530d2", "price_changes": [{"asset_id": "105244305087066947375390379713039474916834963808658829713388931041101255731949", "price": "0.006", "size": "64.93", "side": "BUY", "hash": "8a6cf46ae81cb82c053fc4b909848dbcbfc5da97", "best_bid": "0.019", "best_ask": "0.023"}, {"asset_id": "106415214145522966179186096977094978918005217851026867362814745409109043718965", "price": "0.994", "size": "64.93", "side": "SELL", "hash": "a96aaf24027db796408d3b5be04eae2bccd8960d", "best_bid": "0.977", "best_ask": "0.981"}], "timestamp": "1769384770563", "event_type": "price_change"}}
{"_local_timestamp": "2026-01-25T23:46:10.754238+00:00", "data": {"market": "0xf2995999537ed00a9e1ed196dac5a34c8362b9e454200968eb123c60d21530d2", "price_changes": [{"asset_id": "105244305087066947375390379713039474916834963808658829713388931041101255731949", "price": "0.002", "size": "225.99", "side": "BUY", "hash": "782d6c1247002142a79b330d0e9a4e327c0119ee", "best_bid": "0.019", "best_ask": "0.023"}, {"asset_id": "106415214145522966179186096977094978918005217851026867362814745409109043718965", "price": "0.998", "size": "225.99", "side": "SELL", "hash": "3ce0afb75f92b49f401246f233247a0e4d29f000", "best_bid": "0.977", "best_ask": "0.981"}], "timestamp": "1769384770564", "event_type": "price_change"}}
{"_local_timestamp": "2026-01-25T23:46:11.184680+00:00", "data": {"market": "0xf2995999537ed00a9e1ed196dac5a34c8362b9e454200968eb123c60d21530d2", "price_changes": [{"asset_id": "105244305087066947375390379713039474916834963808658829713388931041101255731949", "price": "0.002", "size": "219.53", "side": "BUY", "hash": "b226a5e91b895ba809b5038148359f1e16c10636", "best_bid": "0.019", "best_ask": "0.023"}, {"asset_id": "106415214145522966179186096977094978918005217851026867362814745409109043718965", "price": "0.998", "size": "219.53", "side": "SELL", "hash": "124fa5e98376a6d0af77334075166012c6a70ff5", "best_bid": "0.977", "best_ask": "0.981"}], "timestamp": "1769384771060", "event_type": "price_change"}}
{"_local_timestamp": "2026-01-25T23:46:11.185287+00:00", "data": {"market": "0xf2995999537ed00a9e1ed196dac5a34c8362b9e454200968eb123c60d21530d2", "price_changes": [{"asset_id": "105244305087066947375390379713039474916834963808658829713388931041101255731949", "price": "0.006", "size": "49.19", "side": "BUY", "hash": "b226a5e91b895ba809b5038148359f1e16c10636", "best_bid": "0.019", "best_ask": "0.023"}, {"asset_id": "106415214145522966179186096977094978918005217851026867362814745409109043718965", "price": "0.994", "size": "49.19", "side": "SELL", "hash": "124fa5e98376a6d0af77334075166012c6a70ff5", "best_bid": "0.977", "best_ask": "0.981"}], "timestamp": "1769384771060", "event_type": "price_change"}}
{"_local_timestamp": "2026-01-25T23:46:11.929246+00:00", "data": {"market": "0xf2995999537ed00a9e1ed196dac5a34c8362b9e454200968eb123c60d21530d2", "price_changes": [{"asset_id": "105244305087066947375390379713039474916834963808658829713388931041101255731949", "price": "0.007", "size": "31.33", "side": "BUY", "hash": "bd88bbbffa0a883f2f59209be969451684c64011", "best_bid": "0.019", "best_ask": "0.023"}, {"asset_id": "106415214145522966179186096977094978918005217851026867362814745409109043718965", "price": "0.993", "size": "31.33", "side": "SELL", "hash": "65e28a2b1abd77490db65cf0b1b9254c3a1a8b30", "best_bid": "0.977", "best_ask": "0.981"}], "timestamp": "1769384771855", "event_type": "price_change"}}
{"_local_timestamp": "2026-01-25T23:46:13.187185+00:00", "data": {"market": "0xf2995999537ed00a9e1ed196dac5a34c8362b9e454200968eb123c60d21530d2", "price_changes": [{"asset_id": "105244305087066947375390379713039474916834963808658829713388931041101255731949", "price": "0.007", "size": "16", "side": "BUY", "hash": "b5163c77225b496b8757a57ed73c2fe50b0e9370", "best_bid": "0.019", "best_ask": "0.023"}, {"asset_id": "106415214145522966179186096977094978918005217851026867362814745409109043718965", "price": "0.993", "size": "16", "side": "SELL", "hash": "d3e8b5b0f69e024d6ae024456e1d7a757c60cb0f", "best_bid": "0.977", "best_ask": "0.981"}], "timestamp": "1769384773111", "event_type": "price_change"}}
{"_local_timestamp": "2026-01-25T23:46:13.832677+00:00", "data": {"market": "0xf2995999537ed00a9e1ed196dac5a34c8362b9e454200968eb123c60d21530d2", "price_changes": [{"asset_id": "105244305087066947375390379713039474916834963808658829713388931041101255731949", "price": "0.008", "size": "28.52", "side": "BUY", "hash": "c2b1810b15a0dc40961714df5851e49698d75a66", "best_bid": "0.019", "best_ask": "0.023"}, {"asset_id": "106415214145522966179186096977094978918005217851026867362814745409109043718965", "price": "0.992", "size": "28.52", "side": "SELL", "hash": "b6d2240fcfd2682ef558e5e703119cb4aba30d10", "best_bid": "0.977", "best_ask": "0.981"}], "timestamp": "1769384773756", "event_type": "price_change"}}
{"_local_timestamp": "2026-01-25T23:46:14.788235+00:00", "data": {"market": "0xf2995999537ed00a9e1ed196dac5a34c8362b9e454200968eb123c60d21530d2", "price_changes": [{"asset_id": "105244305087066947375390379713039474916834963808658829713388931041101255731949", "price": "0.008", "size": "15.1", "side": "BUY", "hash": "2b1481f4369c48b65dc265d21649ea77e218bff7", "best_bid": "0.019", "best_ask": "0.023"}, {"asset_id": "106415214145522966179186096977094978918005217851026867362814745409109043718965", "price": "0.992", "size": "15.1", "side": "SELL", "hash": "3b899e37222b1c08d910ff295ad16ea95370066e", "best_bid": "0.977", "best_ask": "0.981"}], "timestamp": "1769384774717", "event_type": "price_change"}}
{"_local_timestamp": "2026-01-25T23:46:15.229485+00:00", "data": {"market": "0xf2995999537ed00a9e1ed196dac5a34c8362b9e454200968eb123c60d21530d2", "price_changes": [{"asset_id": "105244305087066947375390379713039474916834963808658829713388931041101255731949", "price": "0.002", "size": "225.99", "side": "BUY", "hash": "704a7984576dbbecf5026a40ac13140ad944f1ba", "best_bid": "0.019", "best_ask": "0.023"}, {"asset_id": "106415214145522966179186096977094978918005217851026867362814745409109043718965", "price": "0.998", "size": "225.99", "side": "SELL", "hash": "81e9279ecea3588ec5d7ff962692a9c607026778", "best_bid": "0.977", "best_ask": "0.981"}], "timestamp": "1769384775162", "event_type": "price_change"}}
{"_local_timestamp": "2026-01-25T23:46:15.240104+00:00", "data": {"market": "0xf2995999537ed00a9e1ed196dac5a34c8362b9e454200968eb123c60d21530d2", "price_changes": [{"asset_id": "105244305087066947375390379713039474916834963808658829713388931041101255731949", "price": "0.006", "size": "64.93", "side": "BUY", "hash": "b14ed783a679331a0254538f079bf8404a69ff50", "best_bid": "0.019", "best_ask": "0.023"}, {"asset_id": "106415214145522966179186096977094978918005217851026867362814745409109043718965", "price": "0.994", "size": "64.93", "side": "SELL", "hash": "008d5f08c83b5d3869d8e18de91724413f0b3bd7", "best_bid": "0.977", "best_ask": "0.981"}], "timestamp": "1769384775163", "event_type": "price_change"}}
{"_local_timestamp": "2026-01-25T23:46:16.842776+00:00", "data": {"market": "0xf2995999537ed00a9e1ed196dac5a34c8362b9e454200968eb123c60d21530d2", "price_changes": [{"asset_id": "105244305087066947375390379713039474916834963808658829713388931041101255731949", "price": "0.002", "size": "219.53", "side": "BUY", "hash": "fb86aad3c780636d442be2da54b33ffca4a9e8dc", "best_bid": "0.019", "best_ask": "0.023"}, {"asset_id": "106415214145522966179186096977094978918005217851026867362814745409109043718965", "price": "0.998", "size": "219.53", "side": "SELL", "hash": "3a8ffaa1953332823a98660ce653be9bc69f8f64", "best_bid": "0.977", "best_ask": "0.981"}], "timestamp": "1769384776774", "event_type": "price_change"}}
{"_local_timestamp": "2026-01-25T23:46:16.843098+00:00", "data": {"market": "0xf2995999537ed00a9e1ed196dac5a34c8362b9e454200968eb123c60d21530d2", "price_changes": [{"asset_id": "105244305087066947375390379713039474916834963808658829713388931041101255731949", "price": "0.006", "size": "49.19", "side": "BUY", "hash": "fb86aad3c780636d442be2da54b33ffca4a9e8dc", "best_bid": "0.019", "best_ask": "0.023"}, {"asset_id": "106415214145522966179186096977094978918005217851026867362814745409109043718965", "price": "0.994", "size": "49.19", "side": "SELL", "hash": "3a8ffaa1953332823a98660ce653be9bc69f8f64", "best_bid": "0.977", "best_ask": "0.981"}], "timestamp": "1769384776774", "event_type": "price_change"}}
{"_local_timestamp": "2026-01-25T23:46:17.140955+00:00", "data": {"market": "0xf2995999537ed00a9e1ed196dac5a34c8362b9e454200968eb123c60d21530d2", "price_changes": [{"asset_id": "105244305087066947375390379713039474916834963808658829713388931041101255731949", "price": "0.007", "size": "31.33", "side": "BUY", "hash": "1758c27647734d0987cb514f7b4546efb83e5dec", "best_bid": "0.019", "best_ask": "0.023"}, {"asset_id": "106415214145522966179186096977094978918005217851026867362814745409109043718965", "price": "0.993", "size": "31.33", "side": "SELL", "hash": "94bda822a2e45259992eeedcebc5cda8d227487b", "best_bid": "0.977", "best_ask": "0.981"}], "timestamp": "1769384777028", "event_type": "price_change"}}
{"_local_timestamp": "2026-01-25T23:46:18.827123+00:00", "data": {"market": "0xf2995999537ed00a9e1ed196dac5a34c8362b9e454200968eb123c60d21530d2", "price_changes": [{"asset_id": "105244305087066947375390379713039474916834963808658829713388931041101255731949", "price": "0.007", "size": "16", "side": "BUY", "hash": "279a80099165375d31260f7234aba5586f88cdb6", "best_bid": "0.019", "best_ask": "0.023"}, {"asset_id": "106415214145522966179186096977094978918005217851026867362814745409109043718965", "price": "0.993", "size": "16", "side": "SELL", "hash": "482c4e74bf536cfbeb6cd1c725180f498f8254b4", "best_bid": "0.977", "best_ask": "0.981"}], "timestamp": "1769384778754", "event_type": "price_change"}}
{"_local_timestamp": "2026-01-25T23:46:19.153032+00:00", "data": {"market": "0xf2995999537ed00a9e1ed196dac5a34c8362b9e454200968eb123c60d21530d2", "price_changes": [{"asset_id": "105244305087066947375390379713039474916834963808658829713388931041101255731949", "price": "0.008", "size": "28.52", "side": "BUY", "hash": "60ae2b7af7c505bea8f79c25e6ccd26802bf623d", "best_bid": "0.019", "best_ask": "0.023"}, {"asset_id": "106415214145522966179186096977094978918005217851026867362814745409109043718965", "price": "0.992", "size": "28.52", "side": "SELL", "hash": "0a6111c47e7a9c73c5541c08f71dfd646f939b4b", "best_bid": "0.977", "best_ask": "0.981"}], "timestamp": "1769384779089", "event_type": "price_change"}}
{"_local_timestamp": "2026-01-25T23:46:19.696716+00:00", "data": {"market": "0xf2995999537ed00a9e1ed196dac5a34c8362b9e454200968eb123c60d21530d2", "price_changes": [{"asset_id": "105244305087066947375390379713039474916834963808658829713388931041101255731949", "price": "0.008", "size": "15.1", "side": "BUY", "hash": "677c5dbfec03d56e51fe28988fe60b9903c22116", "best_bid": "0.019", "best_ask": "0.023"}, {"asset_id": "106415214145522966179186096977094978918005217851026867362814745409109043718965", "price": "0.992", "size": "15.1", "side": "SELL", "hash": "fa38a0f1d11f1a26cd239961a6c3000e5226dd99", "best_bid": "0.977", "best_ask": "0.981"}], "timestamp": "1769384779632", "event_type": "price_change"}}
{"_local_timestamp": "2026-01-25T23:46:20.994826+00:00", "data": {"market": "0xf2995999537ed00a9e1ed196dac5a34c8362b9e454200968eb123c60d21530d2", "price_changes": [{"asset_id": "105244305087066947375390379713039474916834963808658829713388931041101255731949", "price": "0.002", "size": "225.99", "side": "BUY", "hash": "d671c600311e170b2a9c4f2a83f6db1195ec9cd8", "best_bid": "0.019", "best_ask": "0.023"}, {"asset_id": "106415214145522966179186096977094978918005217851026867362814745409109043718965", "price": "0.998", "size": "225.99", "side": "SELL", "hash": "af7c409f6acb3590d162522d283f75a7a7642894", "best_bid": "0.977", "best_ask": "0.981"}], "timestamp": "1769384780930", "event_type": "price_change"}}
{"_local_timestamp": "2026-01-25T23:46:21.028602+00:00", "data": {"market": "0xf2995999537ed00a9e1ed196dac5a34c8362b9e454200968eb123c60d21530d2", "price_changes": [{"asset_id": "105244305087066947375390379713039474916834963808658829713388931041101255731949", "price": "0.006", "size": "57.06", "side": "BUY", "hash": "874ac249ed58a9244c79fbc8fcba2fe0928c3aab", "best_bid": "0.019", "best_ask": "0.023"}, {"asset_id": "106415214145522966179186096977094978918005217851026867362814745409109043718965", "price": "0.994", "size": "57.06", "side": "SELL", "hash": "8785826f1d3e6024275db762c4af4d3e0c1a4c41", "best_bid": "0.977", "best_ask": "0.981"}], "timestamp": "1769384780935", "event_type": "price_change"}}
{"_local_timestamp": "2026-01-25T23:46:21.028897+00:00", "data": {"market": "0xf2995999537ed00a9e1ed196dac5a34c8362b9e454200968eb123c60d21530d2", "price_changes": [{"asset_id": "105244305087066947375390379713039474916834963808658829713388931041101255731949", "price": "0.006", "size": "64.93", "side": "BUY", "hash": "b35ec4442510106bab2157284134105310e50a46", "best_bid": "0.019", "best_ask": "0.023"}, {"asset_id": "106415214145522966179186096977094978918005217851026867362814745409109043718965", "price": "0.994", "size": "64.93", "side": "SELL", "hash": "6a20228c811993866cb7c1cbbde8b32472a53584", "best_bid": "0.977", "best_ask": "0.981"}], "timestamp": "1769384780965", "event_type": "price_change"}}
{"_local_timestamp": "2026-01-25T23:46:22.314295+00:00", "data": {"market": "0xf2995999537ed00a9e1ed196dac5a34c8362b9e454200968eb123c60d21530d2", "price_changes": [{"asset_id": "105244305087066947375390379713039474916834963808658829713388931041101255731949", "price": "0.002", "size": "219.53", "side": "BUY", "hash": "1a3d9544a3e067ebd4d6cf26bdd84098810ec511", "best_bid": "0.019", "best_ask": "0.023"}, {"asset_id": "106415214145522966179186096977094978918005217851026867362814745409109043718965", "price": "0.998", "size": "219.53", "side": "SELL", "hash": "19a1de5d2a14e76d47f5cb7f91116c084e21934e", "best_bid": "0.977", "best_ask": "0.981"}], "timestamp": "1769384782248", "event_type": "price_change"}}
{"_local_timestamp": "2026-01-25T23:46:22.315287+00:00", "data": {"market": "0xf2995999537ed00a9e1ed196dac5a34c8362b9e454200968eb123c60d21530d2", "price_changes": [{"asset_id": "105244305087066947375390379713039474916834963808658829713388931041101255731949", "price": "0.006", "size": "55.92", "side": "BUY", "hash": "1a3d9544a3e067ebd4d6cf26bdd84098810ec511", "best_bid": "0.019", "best_ask": "0.023"}, {"asset_id": "106415214145522966179186096977094978918005217851026867362814745409109043718965", "price": "0.994", "size": "55.92", "side": "SELL", "hash": "19a1de5d2a14e76d47f5cb7f91116c084e21934e", "best_bid": "0.977", "best_ask": "0.981"}], "timestamp": "1769384782248", "event_type": "price_change"}}
{"_local_timestamp": "2026-01-25T23:46:22.685242+00:00", "data": {"market": "0xf2995999537ed00a9e1ed196dac5a34c8362b9e454200968eb123c60d21530d2", "price_changes": [{"asset_id": "105244305087066947375390379713039474916834963808658829713388931041101255731949", "price": "0.007", "size": "25.56", "side": "BUY", "hash": "897a66edc8a950155c53938432dbcf423117d349", "best_bid": "0.019", "best_ask": "0.023"}, {"asset_id": "106415214145522966179186096977094978918005217851026867362814745409109043718965", "price": "0.993", "size": "25.56", "side": "SELL", "hash": "c61f81a253a77ce55480b80b9d7099fb63d46a82", "best_bid": "0.977", "best_ask": "0.981"}], "timestamp": "1769384782617", "event_type": "price_change"}}
{"_local_timestamp": "2026-01-25T23:46:22.968609+00:00", "data": {"market": "0x2a74a7cd29971c3a320eec0595c20a07d9a2cbc501c99694d34963e38a196682", "price_changes": [{"asset_id": "40042411695863369998216770625571070530892534611209558876495072542089465066752", "price": "0.981", "size": "19.83", "side": "BUY", "hash": "7254d01c4553ca5e40b7510eb9a9fb92cf132608", "best_bid": "0.998", "best_ask": "0.999"}, {"asset_id": "35311691331065078920223858384826797458646117898089239758404119138722819634257", "price": "0.019", "size": "19.83", "side": "SELL", "hash": "d2751681b3053cf5d9130ddaf70470b2f242471d", "best_bid": "0.001", "best_ask": "0.002"}], "timestamp": "1769384782900", "event_type": "price_change"}}
{"_local_timestamp": "2026-01-25T23:46:22.983647+00:00", "data": {"market": "0x4a00aea8c3beebfbd78428ed9794389a6064031b3b4498ecee8f1e2567960c52", "price_changes": [{"asset_id": "25647280398479894832229021619345962565230978912320531311978302103412384666485", "price": "0.98", "size": "1519.83", "side": "BUY", "hash": "c50f1fc61328e300dd133ad2cfdaaf6bb12ed9cb", "best_bid": "0.995", "best_ask": "0.998"}, {"asset_id": "28282613628199947618108198992841847089900837455551648546884564075036732056803", "price": "0.02", "size": "1519.83", "side": "SELL", "hash": "f3e76e178034ad6eef03c192979d9a08ef5a13fd", "best_bid": "0.002", "best_ask": "0.005"}], "timestamp": "1769384782914", "event_type": "price_change"}}
{"_local_timestamp": "2026-01-25T23:46:23.006591+00:00", "data": {"market": "0xe0e842b31506fda8023595ae777aa10df28ecd9c22c1f1409a7f8712eda7e879", "price_changes": [{"asset_id": "109396302302451946277463128776199432259939419558255720043997107356989321269700", "price": "0.981", "size": "19.83", "side": "BUY", "hash": "a5bbbc12c03367f33e62527a6c8782d99f04e08b", "best_bid": "0.997", "best_ask": "0.999"}, {"asset_id": "108109838300131904793645757730015721729233228300378400579897924202651980716760", "price": "0.019", "size": "19.83", "side": "SELL", "hash": "205ea7dec3cd27347ee569671e80c707ef0fa772", "best_bid": "0.001", "best_ask": "0.003"}], "timestamp": "1769384782933", "event_type": "price_change"}}
{"_local_timestamp": "2026-01-25T23:46:23.006965+00:00", "data": {"market": "0x8298fb2a176db2e46ceb5aff2ddff61aca1fdac933c02a4a9e1643bd12c1c7a5", "price_changes": [{"asset_id": "35897551024644058529519358120193216211748306981601166224061602740309627186051", "price": "0.981", "size": "19.83", "side": "BUY", "hash": "c69cf9bb28df4883f4c4e00176017781e0d226d1", "best_bid": "0.997", "best_ask": "0.999"}, {"asset_id": "7993116773810665385123830809052135747764218356289251597248975813552433650614", "price": "0.019", "size": "19.83", "side": "SELL", "hash": "868be8de515e1f694571265f2722d8485be1f091", "best_bid": "0.001", "best_ask": "0.003"}], "timestamp": "1769384782937", "event_type": "price_change"}}
{"_local_timestamp": "2026-01-25T23:46:23.007232+00:00", "data": {"market": "0x0e34316a55bc233e7a3413a93c42c66072b7ac502d76e2bc66884b3816ee6e07", "price_changes": [{"asset_id": "107862542344757352141146430276434917083046632354992038304792604470800981194112", "price": "0.981", "size": "19.83", "side": "BUY", "hash": "1b5672c491222855afb294cd7ac88a22960dfcc6", "best_bid": "0.998", "best_ask": "0.999"}, {"asset_id": "76761029218476112031409759115795427470125890678375395683863252655472602921499", "price": "0.019", "size": "19.83", "side": "SELL", "hash": "60453e057468cdde041022712caa2a1304b1e76d", "best_bid": "0.001", "best_ask": "0.002"}], "timestamp": "1769384782936", "event_type": "price_change"}}
{"_local_timestamp": "2026-01-25T23:46:24.219153+00:00", "data": {"market": "0xf2995999537ed00a9e1ed196dac5a34c8362b9e454200968eb123c60d21530d2", "price_changes": [{"asset_id": "105244305087066947375390379713039474916834963808658829713388931041101255731949", "price": "0.007", "size": "16", "side": "BUY", "hash": "28d414bb7b762857da786041c76e340b96a91837", "best_bid": "0.019", "best_ask": "0.023"}, {"asset_id": "106415214145522966179186096977094978918005217851026867362814745409109043718965", "price": "0.993", "size": "16", "side": "SELL", "hash": "6a281ce01faa5761df858bbee2a9b9ad313b0927", "best_bid": "0.977", "best_ask": "0.981"}], "timestamp": "1769384784154", "event_type": "price_change"}}
{"_local_timestamp": "2026-01-25T23:46:24.274298+00:00", "data": {"market": "0xe0e842b31506fda8023595ae777aa10df28ecd9c22c1f1409a7f8712eda7e879", "price_changes": [{"asset_id": "109396302302451946277463128776199432259939419558255720043997107356989321269700", "price": "0.981", "size": "0", "side": "BUY", "hash": "6f9031f292943351ff49422c60ac687181ec9a13", "best_bid": "0.997", "best_ask": "0.999"}, {"asset_id": "108109838300131904793645757730015721729233228300378400579897924202651980716760", "price": "0.019", "size": "0", "side": "SELL", "hash": "6c51885c984d56b1960162e3888489e5b2389a5d", "best_bid": "0.001", "best_ask": "0.003"}], "timestamp": "1769384784190", "event_type": "price_change"}}
{"_local_timestamp": "2026-01-25T23:46:24.274601+00:00", "data": {"market": "0x0e34316a55bc233e7a3413a93c42c66072b7ac502d76e2bc66884b3816ee6e07", "price_changes": [{"asset_id": "107862542344757352141146430276434917083046632354992038304792604470800981194112", "price": "0.981", "size": "0", "side": "BUY", "hash": "df8c7b836e27170b0c4c84f3330b0647d4aabcb6", "best_bid": "0.998", "best_ask": "0.999"}, {"asset_id": "76761029218476112031409759115795427470125890678375395683863252655472602921499", "price": "0.019", "size": "0", "side": "SELL", "hash": "4a296b37e9a2deb93ce1216996247e45c1122330", "best_bid": "0.001", "best_ask": "0.002"}], "timestamp": "1769384784190", "event_type": "price_change"}}
{"_local_timestamp": "2026-01-25T23:46:24.274855+00:00", "data": {"market": "0x4a00aea8c3beebfbd78428ed9794389a6064031b3b4498ecee8f1e2567960c52", "price_changes": [{"asset_id": "25647280398479894832229021619345962565230978912320531311978302103412384666485", "price": "0.98", "size": "1500", "side": "BUY", "hash": "9a01307429980c429732b3fa3a3dfcf301670bae", "best_bid": "0.995", "best_ask": "0.998"}, {"asset_id": "28282613628199947618108198992841847089900837455551648546884564075036732056803", "price": "0.02", "size": "1500", "side": "SELL", "hash": "aa36766f99296a74f92284e3d4bb19cec3af5399", "best_bid": "0.002", "best_ask": "0.005"}], "timestamp": "1769384784190", "event_type": "price_change"}}
{"_local_timestamp": "2026-01-25T23:46:24.275111+00:00", "data": {"market": "0x2a74a7cd29971c3a320eec0595c20a07d9a2cbc501c99694d34963e38a196682", "price_changes": [{"asset_id": "40042411695863369998216770625571070530892534611209558876495072542089465066752", "price": "0.981", "size": "0", "side": "BUY", "hash": "32fff6a5d424d49a256f0fdfa51fb8cfdb4008e8", "best_bid": "0.998", "best_ask": "0.999"}, {"asset_id": "35311691331065078920223858384826797458646117898089239758404119138722819634257", "price": "0.019", "size": "0", "side": "SELL", "hash": "465894f8debf6f71dbfa98ead7766d91fbc4e054", "best_bid": "0.001", "best_ask": "0.002"}], "timestamp": "1769384784190", "event_type": "price_change"}}
{"_local_timestamp": "2026-01-25T23:46:24.275330+00:00", "data": {"market": "0x8298fb2a176db2e46ceb5aff2ddff61aca1fdac933c02a4a9e1643bd12c1c7a5", "price_changes": [{"asset_id": "35897551024644058529519358120193216211748306981601166224061602740309627186051", "price": "0.981", "size": "0", "side": "BUY", "hash": "3ab99a6dcd2c831134cd65d9399b2db808a8ae19", "best_bid": "0.997", "best_ask": "0.999"}, {"asset_id": "7993116773810665385123830809052135747764218356289251597248975813552433650614", "price": "0.019", "size": "0", "side": "SELL", "hash": "7cf09807b606958756b1f06aa5fdbab83b85bdb6", "best_bid": "0.001", "best_ask": "0.003"}], "timestamp": "1769384784190", "event_type": "price_change"}}
{"_local_timestamp": "2026-01-25T23:46:25.095100+00:00", "data": {"market": "0xf2995999537ed00a9e1ed196dac5a34c8362b9e454200968eb123c60d21530d2", "price_changes": [{"asset_id": "105244305087066947375390379713039474916834963808658829713388931041101255731949", "price": "0.008", "size": "23.47", "side": "BUY", "hash": "7c5b8f89c3a5600c3b8813891e1c3439dc300fcd", "best_bid": "0.019", "best_ask": "0.023"}, {"asset_id": "106415214145522966179186096977094978918005217851026867362814745409109043718965", "price": "0.992", "size": "23.47", "side": "SELL", "hash": "0c6a9cfea4e9d742875e72be6cfbf1c0d725afc8", "best_bid": "0.977", "best_ask": "0.981"}], "timestamp": "1769384785025", "event_type": "price_change"}}
{"_local_timestamp": "2026-01-25T23:46:26.597261+00:00", "data": {"market": "0xf2995999537ed00a9e1ed196dac5a34c8362b9e454200968eb123c60d21530d2", "price_changes": [{"asset_id": "105244305087066947375390379713039474916834963808658829713388931041101255731949", "price": "0.008", "size": "15.1", "side": "BUY", "hash": "d218413626778cb0477c805265f784a0b4bb4b5f", "best_bid": "0.019", "best_ask": "0.023"}, {"asset_id": "106415214145522966179186096977094978918005217851026867362814745409109043718965", "price": "0.992", "size": "15.1", "side": "SELL", "hash": "3035a6c0347dc55a8142cd43a836ef8a8a057d3f", "best_bid": "0.977", "best_ask": "0.981"}], "timestamp": "1769384786524", "event_type": "price_change"}}
{"_local_timestamp": "2026-01-25T23:46:27.518927+00:00", "data": {"market": "0xf2995999537ed00a9e1ed196dac5a34c8362b9e454200968eb123c60d21530d2", "price_changes": [{"asset_id": "105244305087066947375390379713039474916834963808658829713388931041101255731949", "price": "0.002", "size": "236.27", "side": "BUY", "hash": "ca4c09cd5ef8625db628bc9676d0e92b848dbbd8", "best_bid": "0.019", "best_ask": "0.023"}, {"asset_id": "106415214145522966179186096977094978918005217851026867362814745409109043718965", "price": "0.998", "size": "236.27", "side": "SELL", "hash": "52260810efb524b8035f25d28b135667c1a1a499", "best_bid": "0.977", "best_ask": "0.981"}], "timestamp": "1769384787438", "event_type": "price_change"}}
{"_local_timestamp": "2026-01-25T23:46:27.519358+00:00", "data": {"market": "0xf2995999537ed00a9e1ed196dac5a34c8362b9e454200968eb123c60d21530d2", "price_changes": [{"asset_id": "105244305087066947375390379713039474916834963808658829713388931041101255731949", "price": "0.002", "size": "253.01", "side": "BUY", "hash": "5007b0fa931ae50636b5d02192ea0aa7005bf09d", "best_bid": "0.019", "best_ask": "0.023"}, {"asset_id": "106415214145522966179186096977094978918005217851026867362814745409109043718965", "price": "0.998", "size": "253.01", "side": "SELL", "hash": "f633b9360342c0ec5c5ca6775488ba6d99bddbcd", "best_bid": "0.977", "best_ask": "0.981"}], "timestamp": "1769384787441", "event_type": "price_change"}}
{"_local_timestamp": "2026-01-25T23:46:27.950960+00:00", "data": {"market": "0x4a00aea8c3beebfbd78428ed9794389a6064031b3b4498ecee8f1e2567960c52", "price_changes": [{"asset_id": "25647280398479894832229021619345962565230978912320531311978302103412384666485", "price": "0.98", "size": "1519.83", "side": "BUY", "hash": "aa247f81c16b48242791e01c297f20f5ae66e242", "best_bid": "0.995", "best_ask": "0.998"}, {"asset_id": "28282613628199947618108198992841847089900837455551648546884564075036732056803", "price": "0.02", "size": "1519.83", "side": "SELL", "hash": "8b277887733c3618be4a27f857764624586980e8", "best_bid": "0.002", "best_ask": "0.005"}], "timestamp": "1769384787869", "event_type": "price_change"}}
{"_local_timestamp": "2026-01-25T23:46:27.964651+00:00", "data": {"market": "0x2a74a7cd29971c3a320eec0595c20a07d9a2cbc501c99694d34963e38a196682", "price_changes": [{"asset_id": "40042411695863369998216770625571070530892534611209558876495072542089465066752", "price": "0.981", "size": "19.83", "side": "BUY", "hash": "a6b1b6c11243d2e0079906018acc424c3c7174a0", "best_bid": "0.998", "best_ask": "0.999"}, {"asset_id": "35311691331065078920223858384826797458646117898089239758404119138722819634257", "price": "0.019", "size": "19.83", "side": "SELL", "hash": "044efabfa64248dae3e023286571e1e17399055c", "best_bid": "0.001", "best_ask": "0.002"}], "timestamp": "1769384787888", "event_type": "price_change"}}
{"_local_timestamp": "2026-01-25T23:46:27.971420+00:00", "data": {"market": "0xe0e842b31506fda8023595ae777aa10df28ecd9c22c1f1409a7f8712eda7e879", "price_changes": [{"asset_id": "109396302302451946277463128776199432259939419558255720043997107356989321269700", "price": "0.981", "size": "19.83", "side": "BUY", "hash": "f5fda2711ecf72fb88757814a334680ab36eb7b7", "best_bid": "0.997", "best_ask": "0.999"}, {"asset_id": "108109838300131904793645757730015721729233228300378400579897924202651980716760", "price": "0.019", "size": "19.83", "side": "SELL", "hash": "ad61643716ce01b787b812e3b550f8a91e271ee2", "best_bid": "0.001", "best_ask": "0.003"}], "timestamp": "1769384787899", "event_type": "price_change"}}
{"_local_timestamp": "2026-01-25T23:46:27.980065+00:00", "data": {"market": "0x8298fb2a176db2e46ceb5aff2ddff61aca1fdac933c02a4a9e1643bd12c1c7a5", "price_changes": [{"asset_id": "35897551024644058529519358120193216211748306981601166224061602740309627186051", "price": "0.981", "size": "19.83", "side": "BUY", "hash": "de114aeaa5d1da8fa381c9bbd41da8bf137a5837", "best_bid": "0.997", "best_ask": "0.999"}, {"asset_id": "7993116773810665385123830809052135747764218356289251597248975813552433650614", "price": "0.019", "size": "19.83", "side": "SELL", "hash": "6b79665c69cf3922b454a33e707fc7153556d2aa", "best_bid": "0.001", "best_ask": "0.003"}], "timestamp": "1769384787909", "event_type": "price_change"}}
{"_local_timestamp": "2026-01-25T23:46:27.982705+00:00", "data": {"market": "0x0e34316a55bc233e7a3413a93c42c66072b7ac502d76e2bc66884b3816ee6e07", "price_changes": [{"asset_id": "107862542344757352141146430276434917083046632354992038304792604470800981194112", "price": "0.981", "size": "19.83", "side": "BUY", "hash": "aa5c03054c72ac1d469ff5affcedfd77f675ff71", "best_bid": "0.998", "best_ask": "0.999"}, {"asset_id": "76761029218476112031409759115795427470125890678375395683863252655472602921499", "price": "0.019", "size": "19.83", "side": "SELL", "hash": "7ec726169ee73719f3d0d586ef04488e56f378b3", "best_bid": "0.001", "best_ask": "0.002"}], "timestamp": "1769384787911", "event_type": "price_change"}}
{"_local_timestamp": "2026-01-25T23:46:28.655539+00:00", "data": {"market": "0xf2995999537ed00a9e1ed196dac5a34c8362b9e454200968eb123c60d21530d2", "price_changes": [{"asset_id": "105244305087066947375390379713039474916834963808658829713388931041101255731949", "price": "0.002", "size": "236.27", "side": "BUY", "hash": "670d4a33f90c765e64e94521996fad160a5f33c0", "best_bid": "0.019", "best_ask": "0.023"}, {"asset_id": "106415214145522966179186096977094978918005217851026867362814745409109043718965", "price": "0.998", "size": "236.27", "side": "SELL", "hash": "e86c47231ab31157ce51c805385e9c19c1ebeacb", "best_bid": "0.977", "best_ask": "0.981"}], "timestamp": "1769384788579", "event_type": "price_change"}}
{"_local_timestamp": "2026-01-25T23:46:28.922291+00:00", "data": {"market": "0x4a00aea8c3beebfbd78428ed9794389a6064031b3b4498ecee8f1e2567960c52", "price_changes": [{"asset_id": "25647280398479894832229021619345962565230978912320531311978302103412384666485", "price": "0.98", "size": "1500", "side": "BUY", "hash": "f7ec1e4d10f0600af0410eee394dba3bd1eb688c", "best_bid": "0.995", "best_ask": "0.998"}, {"asset_id": "28282613628199947618108198992841847089900837455551648546884564075036732056803", "price": "0.02", "size": "1500", "side": "SELL", "hash": "9d313584f8fb5204bd8a355f5f5c3dac44e8ee10", "best_bid": "0.002", "best_ask": "0.005"}], "timestamp": "1769384788770", "event_type": "price_change"}}
{"_local_timestamp": "2026-01-25T23:46:28.922575+00:00", "data": {"market": "0x2a74a7cd29971c3a320eec0595c20a07d9a2cbc501c99694d34963e38a196682", "price_changes": [{"asset_id": "40042411695863369998216770625571070530892534611209558876495072542089465066752", "price": "0.981", "size": "0", "side": "BUY", "hash": "41dc9f580d9b027cb8c76d8629d09c08c7d2fa69", "best_bid": "0.998", "best_ask": "0.999"}, {"asset_id": "35311691331065078920223858384826797458646117898089239758404119138722819634257", "price": "0.019", "size": "0", "side": "SELL", "hash": "9a688218a42be41213ad90f89e417543287eb026", "best_bid": "0.001", "best_ask": "0.002"}], "timestamp": "1769384788770", "event_type": "price_change"}}
{"_local_timestamp": "2026-01-25T23:46:28.922811+00:00", "data": {"market": "0x8298fb2a176db2e46ceb5aff2ddff61aca1fdac933c02a4a9e1643bd12c1c7a5", "price_changes": [{"asset_id": "35897551024644058529519358120193216211748306981601166224061602740309627186051", "price": "0.981", "size": "0", "side": "BUY", "hash": "d334bc883915e1dd4a3e2b4fab0dacf138cbe355", "best_bid": "0.997", "best_ask": "0.999"}, {"asset_id": "7993116773810665385123830809052135747764218356289251597248975813552433650614", "price": "0.019", "size": "0", "side": "SELL", "hash": "7863ac23e68a4a7268e9406a3739410da986863b", "best_bid": "0.001", "best_ask": "0.003"}], "timestamp": "1769384788770", "event_type": "price_change"}}
{"_local_timestamp": "2026-01-25T23:46:28.923026+00:00", "data": {"market": "0xe0e842b31506fda8023595ae777aa10df28ecd9c22c1f1409a7f8712eda7e879", "price_changes": [{"asset_id": "109396302302451946277463128776199432259939419558255720043997107356989321269700", "price": "0.981", "size": "0", "side": "BUY", "hash": "56332092f992b77a8dd6abdfd374b693326fdecd", "best_bid": "0.997", "best_ask": "0.999"}, {"asset_id": "108109838300131904793645757730015721729233228300378400579897924202651980716760", "price": "0.019", "size": "0", "side": "SELL", "hash": "f13ef9ef917f9add150842a73cff8382614bd059", "best_bid": "0.001", "best_ask": "0.003"}], "timestamp": "1769384788770", "event_type": "price_change"}}
{"_local_timestamp": "2026-01-25T23:46:28.923238+00:00", "data": {"market": "0x0e34316a55bc233e7a3413a93c42c66072b7ac502d76e2bc66884b3816ee6e07", "price_changes": [{"asset_id": "107862542344757352141146430276434917083046632354992038304792604470800981194112", "price": "0.981", "size": "0", "side": "BUY", "hash": "27fcb99a5ae900efcb6425a155787def3bcd67a2", "best_bid": "0.998", "best_ask": "0.999"}, {"asset_id": "76761029218476112031409759115795427470125890678375395683863252655472602921499", "price": "0.019", "size": "0", "side": "SELL", "hash": "2ce115348839890c7c73f2421268543cbab36b01", "best_bid": "0.001", "best_ask": "0.002"}], "timestamp": "1769384788770", "event_type": "price_change"}}
