{"_local_timestamp": "2026-01-25T23:40:29.665888+00:00", "data": [{"market": "0x0e34be3ee9cb4203fae20b289dfc9a9370f0045ab3fb2e1fa4e6fb82596c678f", "asset_id": "115183429975003994986742111804963130302445062562951748575181862773257927283380", "timestamp": "1769384426656", "hash": "2ca39059f2b0646ef0cf4d3cd8b347961f190850", "bids": [{"price": "0.01", "size": "3238.15"}, {"price": "0.02", "size": "1805.31"}, {"price": "0.03", "size": "100"}, {"price": "0.04", "size": "5.56"}, {"price": "0.07", "size": "900"}, {"price": "0.08", "size": "7650"}, {"price": "0.09", "size": "6.88"}, {"price": "0.36", "size": "3850"}, {"price": "0.39", "size": "674"}, {"price": "0.4", "size": "704"}, {"price": "0.41", "size": "9733"}, {"price": "0.42", "size": "2100"}, {"price": "0.43", "size": "103"}], "asks": [{"price": "0.99", "size": "3251.81"}, {"price": "0.98", "size": "1808.8"}, {"price": "0.97", "size": "100"}, {"price": "0.96", "size": "7.78"}, {"price": "0.95", "size": "10"}, {"price": "0.93", "size": "900"}, {"price": "0.92", "size": "2005.89"}, {"price": "0.88", "size": "1332"}, {"price": "0.87", "size": "3630"}, {"price": "0.86", "size": "50"}, {"price": "0.85", "size": "6.34"}, {"price": "0.8", "size": "209.84"}, {"price": "0.7", "size": "19.69"}, {"price": "0.6", "size": "13.12"}, {"price": "0.53", "size": "3870"}, {"price": "0.51", "size": "60"}, {"price": "0.5", "size": "726.5"}, {"price": "0.49", "size": "654"}, {"price": "0.48", "size": "9417"}, {"price": "0.47", "size": "742"}, {"price": "0.45", "size": "200"}], "event_type": "book", "last_trade_price": "0.560"}, {"market": "0xcda8a657998ef072e1d9edd83ce60ada3e75fc4d9113bc3f32a343a93fb1c927", "asset_id": "7064893400396467616058037848568819292052255869002775709074859726119346714372", "timestamp": "1769384426630", "hash": "24bf7648945d9d737496893483971bf83eeb8e87", "bids": [{"price": "0.001", "size": "3344.64"}, {"price": "0.002", "size": "255.47"}, {"price": "0.003", "size": "1000"}, {"price": "0.004", "size": "9.35"}, {"price": "0.01", "size": "3233"}, {"price": "0.011", "size": "8.91"}, {"price": "0.02", "size": "2200"}, {"price": "0.03", "size": "100"}, {"price": "0.031", "size": "6.98"}, {"price": "0.053", "size": "600"}, {"price": "0.102", "size": "3136"}, {"price": "0.103", "size": "4476"}, {"price": "0.104", "size": "6.07"}, {"price": "0.14", "size": "50"}, {"price": "0.2", "size": "200"}, {"price": "0.5", "size": "644"}, {"price": "0.506", "size": "10"}, {"price": "0.51", "size": "644"}, {"price": "0.52", "size": "110"}, {"price": "0.527", "size": "10611"}, {"price": "0.528", "size": "60"}], "asks": [{"price": "0.999", "size": "1610.74"}, {"price": "0.998", "size": "259.85"}, {"price": "0.997", "size": "400"}, {"price": "0.996", "size": "7.31"}, {"price": "0.994", "size": "200"}, {"price": "0.993", "size": "5.49"}, {"price": "0.99", "size": "3233"}, {"price": "0.989", "size": "16.48"}, {"price": "0.98", "size": "1800"}, {"price": "0.97", "size": "100"}, {"price": "0.969", "size": "9.16"}, {"price": "0.95", "size": "10"}, {"price": "0.935", "size": "900"}, {"price": "0.934", "size": "7.85"}, {"price": "0.91", "size": "1776"}, {"price": "0.909", "size": "5014"}, {"price": "0.907", "size": "9.89"}, {"price": "0.69", "size": "9.9"}, {"price": "0.689", "size": "20"}, {"price": "0.629", "size": "5"}, {"price": "0.61", "size": "652"}, {"price": "0.609", "size": "10"}, {"price": "0.6", "size": "909"}, {"price": "0.59", "size": "160"}, {"price": "0.588", "size": "50"}, {"price": "0.583", "size": "11260"}, {"price": "0.579", "size": "47.5"}, {"price": "0.572", "size": "103"}, {"price": "0.571", "size": "133"}, {"price": "0.569", "size": "25"}, {"price": "0.56", "size": "11.12"}, {"price": "0.559", "size": "0.78"}], "event_type": "book", "last_trade_price": "0.441"}, {"market": "0xcda8a657998ef072e1d9edd83ce60ada3e75fc4d9113bc3f32a343a93fb1c927", "asset_id": "79200508610612497735268197792255474784890164267460369534045305976733489576200", "timestamp": "1769384426630", "hash": "b3e3af58ba6aa9e03864fc85bbba825e01ce12cd", "bids": [{"price": "0.001", "size": "1610.74"}, {"price": "0.002", "size": "259.85"}, {"price": "0.003", "size": "400"}, {"price": "0.004", "size": "7.31"}, {"price": "0.006", "size": "200"}, {"price": "0.007", "size": "5.49"}, {"price": "0.01", "size": "3233"}, {"price": "0.011", "size": "16.48"}, {"price": "0.02", "size": "1800"}, {"price": "0.03", "size": "100"}, {"price": "0.031", "size": "9.16"}, {"price": "0.05", "size": "10"}, {"price": "0.065", "size": "900"}, {"price": "0.066", "size": "7.85"}, {"price": "0.09", "size": "1776"}, {"price": "0.091", "size": "5014"}, {"price": "0.093", "size": "9.89"}, {"price": "0.31", "size": "9.9"}, {"price": "0.311", "size": "20"}, {"price": "0.371", "size": "5"}, {"price": "0.39", "size": "652"}, {"price": "0.391", "size": "10"}, {"price": "0.4", "size": "909"}, {"price": "0.41", "size": "160"}, {"price": "0.412", "size": "50"}, {"price": "0.417", "size": "11260"}, {"price": "0.421", "size": "47.5"}, {"price": "0.428", "size": "103"}, {"price": "0.429", "size": "133"}, {"price": "0.431", "size": "25"}, {"price": "0.44", "size": "11.12"}, {"price": "0.441", "size": "0.78"}], "asks": [{"price": "0.999", "size": "3344.64"}, {"price": "0.998", "size": "255.47"}, {"price": "0.997", "size": "1000"}, {"price": "0.996", "size": "9.35"}, {"price": "0.99", "size": "3233"}, {"price": "0.989", "size": "8.91"}, {"price": "0.98", "size": "2200"}, {"price": "0.97", "size": "100"}, {"price": "0.969", "size": "6.98"}, {"price": "0.947", "size": "600"}, {"price": "0.898", "size": "3136"}, {"price": "0.897", "size": "4476"}, {"price": "0.896", "size": "6.07"}, {"price": "0.86", "size": "50"}, {"price": "0.8", "size": "200"}, {"price": "0.5", "size": "644"}, {"price": "0.494", "size": "10"}, {"price": "0.49", "size": "644"}, {"price": "0.48", "size": "110"}, {"price": "0.473", "size": "10611"}, {"price": "0.472", "size": "60"}], "event_type": "book", "last_trade_price": "0.441"}, {"market": "0x0e34be3ee9cb4203fae20b289dfc9a9370f0045ab3fb2e1fa4e6fb82596c678f", "asset_id": "12727775089212363162508241557815769734691893483170358591167365904671830747608", "timestamp": "1769384426656", "hash": "c5f3b70ab45ead68fc833c25cf9567b31fc95435", "bids": [{"price": "0.01", "size": "3251.81"}, {"price": "0.02", "size": "1808.8"}, {"price": "0.03", "size": "100"}, {"price": "0.04", "size": "7.78"}, {"price": "0.05", "size": "10"}, {"price": "0.07", "size": "900"}, {"price": "0.08", "size": "2005.89"}, {"price": "0.12", "size": "1332"}, {"price": "0.13", "size": "3630"}, {"price": "0.14", "size": "50"}, {"price": "0.15", "size": "6.34"}, {"price": "0.2", "size": "209.84"}, {"price": "0.3", "size": "19.69"}, {"price": "0.4", "size": "13.12"}, {"price": "0.47", "size": "3870"}, {"price": "0.49", "size": "60"}, {"price": "0.5", "size": "726.5"}, {"price": "0.51", "size": "654"}, {"price": "0.52", "size": "9417"}, {"price": "0.53", "size": "742"}, {"price": "0.55", "size": "200"}], "asks": [{"price": "0.99", "size": "3238.15"}, {"price": "0.98", "size": "1805.31"}, {"price": "0.97", "size": "100"}, {"price": "0.96", "size": "5.56"}, {"price": "0.93", "size": "900"}, {"price": "0.92", "size": "7650"}, {"price": "0.91", "size": "6.88"}, {"price": "0.64", "size": "3850"}, {"price": "0.61", "size": "674"}, {"price": "0.6", "size": "704"}, {"price": "0.59", "size": "9733"}, {"price": "0.58", "size": "2100"}, {"price": "0.57", "size": "103"}], "event_type": "book", "last_trade_price": "0.560"}]}
{"_local_timestamp": "2026-01-25T23:40:32.096539+00:00", "data": {"market": "0xcda8a657998ef072e1d9edd83ce60ada3e75fc4d9113bc3f32a343a93fb1c927", "price_changes": [{"asset_id": "7064893400396467616058037848568819292052255869002775709074859726119346714372", "price": "0.57", "size": "163.1", "side": "BUY", "hash": "0ee11d5f2543f375f67d8c6787aaf61dbf652443", "best_bid": "0.57", "best_ask": "0.571"}, {"asset_id": "79200508610612497735268197792255474784890164267460369534045305976733489576200", "price": "0.43", "size": "163.1", "side": "SELL", "hash": "8a19ff976f7d8166b276d729c6ee914bfadd2d78", "best_bid": "0.429", "best_ask": "0.43"}], "timestamp": "1769384432014", "event_type": "price_change"}}
{"_local_timestamp": "2026-01-25T23:40:32.097160+00:00", "data": {"market": "0xcda8a657998ef072e1d9edd83ce60ada3e75fc4d9113bc3f32a343a93fb1c927", "price_changes": [{"asset_id": "79200508610612497735268197792255474784890164267460369534045305976733489576200", "price": "0.441", "size": "0", "side": "BUY", "hash": "8a19ff976f7d8166b276d729c6ee914bfadd2d78", "best_bid": "0.429", "best_ask": "0.43"}, {"asset_id": "7064893400396467616058037848568819292052255869002775709074859726119346714372", "price": "0.559", "size": "0", "side": "SELL", "hash": "0ee11d5f2543f375f67d8c6787aaf61dbf652443", "best_bid": "0.57", "best_ask": "0.571"}], "timestamp": "1769384432014", "event_type": "price_change"}}
{"_local_timestamp": "2026-01-25T23:40:32.098893+00:00", "data": {"market": "0xcda8a657998ef072e1d9edd83ce60ada3e75fc4d9113bc3f32a343a93fb1c927", "price_changes": [{"asset_id": "79200508610612497735268197792255474784890164267460369534045305976733489576200", "price": "0.44", "size": "0", "side": "BUY", "hash": "8a19ff976f7d8166b276d729c6ee914bfadd2d78", "best_bid": "0.429", "best_ask": "0.43"}, {"asset_id": "7064893400396467616058037848568819292052255869002775709074859726119346714372", "price": "0.56", "size": "0", "side": "SELL", "hash": "0ee11d5f2543f375f67d8c6787aaf61dbf652443", "best_bid": "0.57", "best_ask": "0.571"}], "timestamp": "1769384432014", "event_type": "price_change"}}
{"_local_timestamp": "2026-01-25T23:40:32.100439+00:00", "data": {"market": "0xcda8a657998ef072e1d9edd83ce60ada3e75fc4d9113bc3f32a343a93fb1c927", "price_changes": [{"asset_id": "79200508610612497735268197792255474784890164267460369534045305976733489576200", "price": "0.431", "size": "0", "side": "BUY", "hash": "8a19ff976f7d8166b276d729c6ee914bfadd2d78", "best_bid": "0.429", "best_ask": "0.43"}, {"asset_id": "7064893400396467616058037848568819292052255869002775709074859726119346714372", "price": "0.569", "size": "0", "side": "SELL", "hash": "0ee11d5f2543f375f67d8c6787aaf61dbf652443", "best_bid": "0.57", "best_ask": "0.571"}], "timestamp": "1769384432014", "event_type": "price_change"}}
{"_local_timestamp": "2026-01-25T23:40:32.101391+00:00", "data": {"market": "0xcda8a657998ef072e1d9edd83ce60ada3e75fc4d9113bc3f32a343a93fb1c927", "asset_id": "7064893400396467616058037848568819292052255869002775709074859726119346714372", "bids": [{"price": "0.001", "size": "3344.64"}, {"price": "0.002", "size": "255.47"}, {"price": "0.003", "size": "1000"}, {"price": "0.004", "size": "9.35"}, {"price": "0.01", "size": "3233"}, {"price": "0.011", "size": "8.91"}, {"price": "0.02", "size": "2200"}, {"price": "0.03", "size": "100"}, {"price": "0.031", "size": "6.98"}, {"price": "0.053", "size": "600"}, {"price": "0.102", "size": "3136"}, {"price": "0.103", "size": "4476"}, {"price": "0.104", "size": "6.07"}, {"price": "0.14", "size": "50"}, {"price": "0.2", "size": "200"}, {"price": "0.5", "size": "644"}, {"price": "0.506", "size": "10"}, {"price": "0.51", "size": "644"}, {"price": "0.52", "size": "110"}, {"price": "0.527", "size": "10611"}, {"price": "0.528", "size": "60"}, {"price": "0.57", "size": "163.1"}], "asks": [{"price": "0.999", "size": "1610.74"}, {"price": "0.998", "size": "259.85"}, {"price": "0.997", "size": "400"}, {"price": "0.996", "size": "7.31"}, {"price": "0.994", "size": "200"}, {"price": "0.993", "size": "5.49"}, {"price": "0.99", "size": "3233"}, {"price": "0.989", "size": "16.48"}, {"price": "0.98", "size": "1800"}, {"price": "0.97", "size": "100"}, {"price": "0.969", "size": "9.16"}, {"price": "0.95", "size": "10"}, {"price": "0.935", "size": "900"}, {"price": "0.934", "size": "7.85"}, {"price": "0.91", "size": "1776"}, {"price": "0.909", "size": "5014"}, {"price": "0.907", "size": "9.89"}, {"price": "0.69", "size": "9.9"}, {"price": "0.689", "size": "20"}, {"price": "0.629", "size": "5"}, {"price": "0.61", "size": "652"}, {"price": "0.609", "size": "10"}, {"price": "0.6", "size": "909"}, {"price": "0.59", "size": "160"}, {"price": "0.588", "size": "50"}, {"price": "0.583", "size": "11260"}, {"price": "0.579", "size": "47.5"}, {"price": "0.572", "size": "103"}, {"price": "0.571", "size": "133"}], "hash": "0ee11d5f2543f375f67d8c6787aaf61dbf652443", "timestamp": "1769384432014", "event_type": "book"}}
{"_local_timestamp": "2026-01-25T23:40:32.103327+00:00", "data": {"market": "0xcda8a657998ef072e1d9edd83ce60ada3e75fc4d9113bc3f32a343a93fb1c927", "asset_id": "79200508610612497735268197792255474784890164267460369534045305976733489576200", "bids": [{"price": "0.001", "size": "1610.74"}, {"price": "0.002", "size": "259.85"}, {"price": "0.003", "size": "400"}, {"price": "0.004", "size": "7.31"}, {"price": "0.006", "size": "200"}, {"price": "0.007", "size": "5.49"}, {"price": "0.01", "size": "3233"}, {"price": "0.011", "size": "16.48"}, {"price": "0.02", "size": "1800"}, {"price": "0.03", "size": "100"}, {"price": "0.031", "size": "9.16"}, {"price": "0.05", "size": "10"}, {"price": "0.065", "size": "900"}, {"price": "0.066", "size": "7.85"}, {"price": "0.09", "size": "1776"}, {"price": "0.091", "size": "5014"}, {"price": "0.093", "size": "9.89"}, {"price": "0.31", "size": "9.9"}, {"price": "0.311", "size": "20"}, {"price": "0.371", "size": "5"}, {"price": "0.39", "size": "652"}, {"price": "0.391", "size": "10"}, {"price": "0.4", "size": "909"}, {"price": "0.41", "size": "160"}, {"price": "0.412", "size": "50"}, {"price": "0.417", "size": "11260"}, {"price": "0.421", "size": "47.5"}, {"price": "0.428", "size": "103"}, {"price": "0.429", "size": "133"}], "asks": [{"price": "0.999", "size": "3344.64"}, {"price": "0.998", "size": "255.47"}, {"price": "0.997", "size": "1000"}, {"price": "0.996", "size": "9.35"}, {"price": "0.99", "size": "3233"}, {"price": "0.989", "size": "8.91"}, {"price": "0.98", "size": "2200"}, {"price": "0.97", "size": "100"}, {"price": "0.969", "size": "6.98"}, {"price": "0.947", "size": "600"}, {"price": "0.898", "size": "3136"}, {"price": "0.897", "size": "4476"}, {"price": "0.896", "size": "6.07"}, {"price": "0.86", "size": "50"}, {"price": "0.8", "size": "200"}, {"price": "0.5", "size": "644"}, {"price": "0.494", "size": "10"}, {"price": "0.49", "size": "644"}, {"price": "0.48", "size": "110"}, {"price": "0.473", "size": "10611"}, {"price": "0.472", "size": "60"}, {"price": "0.43", "size": "163.1"}], "hash": "8a19ff976f7d8166b276d729c6ee914bfadd2d78", "timestamp": "1769384432014", "event_type": "book"}}
{"_local_timestamp": "2026-01-25T23:40:32.110680+00:00", "data": {"market": "0xcda8a657998ef072e1d9edd83ce60ada3e75fc4d9113bc3f32a343a93fb1c927", "asset_id": "7064893400396467616058037848568819292052255869002775709074859726119346714372", "price": "0.566", "size": "36.9", "fee_rate_bps": "0", "side": "BUY", "timestamp": "1769384432045", "event_type": "last_trade_price", "transaction_hash": "0x991f5f6e71c3c08865275d76cf75a2d1b949b3f733806634a01ef59db1be44d9"}}
{"_local_timestamp": "2026-01-25T23:40:32.122572+00:00", "data": {"market": "0xcda8a657998ef072e1d9edd83ce60ada3e75fc4d9113bc3f32a343a93fb1c927", "price_changes": [{"asset_id": "79200508610612497735268197792255474784890164267460369534045305976733489576200", "price": "0.428", "size": "0", "side": "BUY", "hash": "70800cf7b92575a0008cd0466f4e46a6c08cec22", "best_bid": "0.429", "best_ask": "0.43"}, {"asset_id": "7064893400396467616058037848568819292052255869002775709074859726119346714372", "price": "0.572", "size": "0", "side": "SELL", "hash": "6bc23ffda11b0e695954364f1f6568bd86223aad", "best_bid": "0.57", "best_ask": "0.571"}], "timestamp": "1769384432056", "event_type": "price_change"}}
{"_local_timestamp": "2026-01-25T23:40:32.227845+00:00", "data": {"market": "0x0e34be3ee9cb4203fae20b289dfc9a9370f0045ab3fb2e1fa4e6fb82596c678f", "price_changes": [{"asset_id": "12727775089212363162508241557815769734691893483170358591167365904671830747608", "price": "0.52", "size": "9317", "side": "BUY", "hash": "f9dd969cf706fa3ede3fba6889c6ce90adfe003c", "best_bid": "0.55", "best_ask": "0.57"}, {"asset_id": "115183429975003994986742111804963130302445062562951748575181862773257927283380", "price": "0.48", "size": "9317", "side": "SELL", "hash": "dc38cf38e021899dcf17e190faf189efcedb2411", "best_bid": "0.43", "best_ask": "0.45"}], "timestamp": "1769384432060", "event_type": "price_change"}}
{"_local_timestamp": "2026-01-25T23:40:32.228310+00:00", "data": {"market": "0x0e34be3ee9cb4203fae20b289dfc9a9370f0045ab3fb2e1fa4e6fb82596c678f", "price_changes": [{"asset_id": "12727775089212363162508241557815769734691893483170358591167365904671830747608", "price": "0.56", "size": "163.1", "side": "BUY", "hash": "b048d53ddbff13c4d96c33967cbaaba7503bd655", "best_bid": "0.56", "best_ask": "0.57"}, {"asset_id": "115183429975003994986742111804963130302445062562951748575181862773257927283380", "price": "0.44", "size": "163.1", "side": "SELL", "hash": "f5c814ca5026dc1027e65a236a4cddd1f635c63f", "best_bid": "0.43", "best_ask": "0.44"}], "timestamp": "1769384432068", "event_type": "price_change"}}
{"_local_timestamp": "2026-01-25T23:40:32.229049+00:00", "data": {"market": "0xcda8a657998ef072e1d9edd83ce60ada3e75fc4d9113bc3f32a343a93fb1c927", "price_changes": [{"asset_id": "79200508610612497735268197792255474784890164267460369534045305976733489576200", "price": "0.4", "size": "709", "side": "BUY", "hash": "17a9ddfb3c43ac0e7279fb8c00347a4e7af7016d", "best_bid": "0.429", "best_ask": "0.43"}, {"asset_id": "7064893400396467616058037848568819292052255869002775709074859726119346714372", "price": "0.6", "size": "709", "side": "SELL", "hash": "6ccead61b59ea1bfd86598f56da7634e5bf7fdca", "best_bid": "0.57", "best_ask": "0.571"}], "timestamp": "1769384432073", "event_type": "price_change"}}
{"_local_timestamp": "2026-01-25T23:40:32.229572+00:00", "data": {"market": "0xcda8a657998ef072e1d9edd83ce60ada3e75fc4d9113bc3f32a343a93fb1c927", "price_changes": [{"asset_id": "79200508610612497735268197792255474784890164267460369534045305976733489576200", "price": "0.417", "size": "4897", "side": "BUY", "hash": "a413fa86b0ca8f57a7a04235c883ace6b416bbe4", "best_bid": "0.429", "best_ask": "0.43"}, {"asset_id": "7064893400396467616058037848568819292052255869002775709074859726119346714372", "price": "0.583", "size": "4897", "side": "SELL", "hash": "529b1561a54e9ce6567dec9b56dcfd47fa6caf3d", "best_bid": "0.57", "best_ask": "0.571"}], "timestamp": "1769384432076", "event_type": "price_change"}}
{"_local_timestamp": "2026-01-25T23:40:32.234072+00:00", "data": {"market": "0xcda8a657998ef072e1d9edd83ce60ada3e75fc4d9113bc3f32a343a93fb1c927", "price_changes": [{"asset_id": "7064893400396467616058037848568819292052255869002775709074859726119346714372", "price": "0.583", "size": "0", "side": "SELL", "hash": "fca329cd0a694c49056063de1735dc3117cdc7f7", "best_bid": "0.57", "best_ask": "0.571"}, {"asset_id": "79200508610612497735268197792255474784890164267460369534045305976733489576200", "price": "0.417", "size": "0", "side": "BUY", "hash": "7238a6bce0c9af50f11e1a5a452ed28d881a5610", "best_bid": "0.429", "best_ask": "0.43"}], "timestamp": "1769384432077", "event_type": "price_change"}}
{"_local_timestamp": "2026-01-25T23:40:32.236793+00:00", "data": {"market": "0xcda8a657998ef072e1d9edd83ce60ada3e75fc4d9113bc3f32a343a93fb1c927", "price_changes": [{"asset_id": "7064893400396467616058037848568819292052255869002775709074859726119346714372", "price": "0.527", "size": "150", "side": "BUY", "hash": "fca329cd0a694c49056063de1735dc3117cdc7f7", "best_bid": "0.57", "best_ask": "0.571"}, {"asset_id": "79200508610612497735268197792255474784890164267460369534045305976733489576200", "price": "0.473", "size": "150", "side": "SELL", "hash": "7238a6bce0c9af50f11e1a5a452ed28d881a5610", "best_bid": "0.429", "best_ask": "0.43"}], "timestamp": "1769384432077", "event_type": "price_change"}}
{"_local_timestamp": "2026-01-25T23:40:32.237393+00:00", "data": {"market": "0xcda8a657998ef072e1d9edd83ce60ada3e75fc4d9113bc3f32a343a93fb1c927", "price_changes": [{"asset_id": "79200508610612497735268197792255474784890164267460369534045305976733489576200", "price": "0.4", "size": "909", "side": "BUY", "hash": "99402436a01173186832032755b979ca308dd56d", "best_bid": "0.429", "best_ask": "0.43"}, {"asset_id": "7064893400396467616058037848568819292052255869002775709074859726119346714372", "price": "0.6", "size": "909", "side": "SELL", "hash": "998d11dffd443b9cb19fb1e54c1be3efd4ee2206", "best_bid": "0.57", "best_ask": "0.571"}], "timestamp": "1769384432106", "event_type": "price_change"}}
{"_local_timestamp": "2026-01-25T23:40:32.237736+00:00", "data": {"market": "0x0e34be3ee9cb4203fae20b289dfc9a9370f0045ab3fb2e1fa4e6fb82596c678f", "price_changes": [{"asset_id": "12727775089212363162508241557815769734691893483170358591167365904671830747608", "price": "0.52", "size": "9267", "side": "BUY", "hash": "8a92cd679291433b5fbbf81f9e87b2ca0d9ae669", "best_bid": "0.56", "best_ask": "0.57"}, {"asset_id": "115183429975003994986742111804963130302445062562951748575181862773257927283380", "price": "0.48", "size": "9267", "side": "SELL", "hash": "b8e30fe8c70fe54f4fc866a71c51b9561979d34c", "best_bid": "0.43", "best_ask": "0.44"}], "timestamp": "1769384432140", "event_type": "price_change"}}
{"_local_timestamp": "2026-01-25T23:40:32.237994+00:00", "data": {"market": "0xcda8a657998ef072e1d9edd83ce60ada3e75fc4d9113bc3f32a343a93fb1c927", "price_changes": [{"asset_id": "79200508610612497735268197792255474784890164267460369534045305976733489576200", "price": "0.428", "size": "25", "side": "BUY", "hash": "1d6e315fa6cb227c05742d42de19bfc73ebf10e0", "best_bid": "0.429", "best_ask": "0.43"}, {"asset_id": "7064893400396467616058037848568819292052255869002775709074859726119346714372", "price": "0.572", "size": "25", "side": "SELL", "hash": "8faba1b0181bb1086f5e12b7874f5e7b5165784b", "best_bid": "0.57", "best_ask": "0.571"}], "timestamp": "1769384432143", "event_type": "price_change"}}
{"_local_timestamp": "2026-01-25T23:40:32.238232+00:00", "data": {"market": "0x0e34be3ee9cb4203fae20b289dfc9a9370f0045ab3fb2e1fa4e6fb82596c678f", "price_changes": [{"asset_id": "12727775089212363162508241557815769734691893483170358591167365904671830747608", "price": "0.52", "size": "9217", "side": "BUY", "hash": "a62544f69fe58d43b89449cad96c3e389ee03450", "best_bid": "0.56", "best_ask": "0.57"}, {"asset_id": "115183429975003994986742111804963130302445062562951748575181862773257927283380", "price": "0.48", "size": "9217", "side": "SELL", "hash": "027eece5b6647b95c242beab65da640853089f41", "best_bid": "0.43", "best_ask": "0.44"}], "timestamp": "1769384432144", "event_type": "price_change"}}
{"_local_timestamp": "2026-01-25T23:40:32.238557+00:00", "data": {"market": "0xcda8a657998ef072e1d9edd83ce60ada3e75fc4d9113bc3f32a343a93fb1c927", "price_changes": [{"asset_id": "79200508610612497735268197792255474784890164267460369534045305976733489576200", "price": "0.428", "size": "50", "side": "BUY", "hash": "a9d561cf6fdbf39badf876ce0ba1ed194d7cf5ac", "best_bid": "0.429", "best_ask": "0.43"}, {"asset_id": "7064893400396467616058037848568819292052255869002775709074859726119346714372", "price": "0.572", "size": "50", "side": "SELL", "hash": "cd574cf9632284114c9b00e758e87dc45e0a44eb", "best_bid": "0.57", "best_ask": "0.571"}], "timestamp": "1769384432144", "event_type": "price_change"}}
{"_local_timestamp": "2026-01-25T23:40:32.238998+00:00", "data": {"market": "0xcda8a657998ef072e1d9edd83ce60ada3e75fc4d9113bc3f32a343a93fb1c927", "price_changes": [{"asset_id": "79200508610612497735268197792255474784890164267460369534045305976733489576200", "price": "0.428", "size": "90", "side": "BUY", "hash": "3a237b0daad59b3560e0386b7e856ae2fc0bc4e7", "best_bid": "0.429", "best_ask": "0.43"}, {"asset_id": "7064893400396467616058037848568819292052255869002775709074859726119346714372", "price": "0.572", "size": "90", "side": "SELL", "hash": "b9d5bf72e77fe770ff6be8f9b4084d2eb8eb04a3", "best_bid": "0.57", "best_ask": "0.571"}], "timestamp": "1769384432145", "event_type": "price_change"}}
{"_local_timestamp": "2026-01-25T23:40:32.239324+00:00", "data": {"market": "0x0e34be3ee9cb4203fae20b289dfc9a9370f0045ab3fb2e1fa4e6fb82596c678f", "price_changes": [{"asset_id": "12727775089212363162508241557815769734691893483170358591167365904671830747608", "price": "0.56", "size": "168.1", "side": "BUY", "hash": "6a853666aba96d9a50fa01fff8103eb25a0e87ac", "best_bid": "0.56", "best_ask": "0.57"}, {"asset_id": "115183429975003994986742111804963130302445062562951748575181862773257927283380", "price": "0.44", "size": "168.1", "side": "SELL", "hash": "d43bfefb04398ffb688bbc4b6ad3f059c38ba774", "best_bid": "0.43", "best_ask": "0.44"}], "timestamp": "1769384432147", "event_type": "price_change"}}
{"_local_timestamp": "2026-01-25T23:40:32.239631+00:00", "data": {"market": "0x0e34be3ee9cb4203fae20b289dfc9a9370f0045ab3fb2e1fa4e6fb82596c678f", "price_changes": [{"asset_id": "12727775089212363162508241557815769734691893483170358591167365904671830747608", "price": "0.56", "size": "218.1", "side": "BUY", "hash": "70f446bc6284ca5b805d59154b1f3a4cd1c3904a", "best_bid": "0.56", "best_ask": "0.57"}, {"asset_id": "115183429975003994986742111804963130302445062562951748575181862773257927283380", "price": "0.44", "size": "218.1", "side": "SELL", "hash": "5a6ed5aaa4a6b1d444c28120ac93abf32495ae94", "best_bid": "0.43", "best_ask": "0.44"}], "timestamp": "1769384432151", "event_type": "price_change"}}
{"_local_timestamp": "2026-01-25T23:40:32.239881+00:00", "data": {"market": "0x0e34be3ee9cb4203fae20b289dfc9a9370f0045ab3fb2e1fa4e6fb82596c678f", "price_changes": [{"asset_id": "12727775089212363162508241557815769734691893483170358591167365904671830747608", "price": "0.56", "size": "268.1", "side": "BUY", "hash": "655d923b16f418c11e09a98f71977fab3d70117e", "best_bid": "0.56", "best_ask": "0.57"}, {"asset_id": "115183429975003994986742111804963130302445062562951748575181862773257927283380", "price": "0.44", "size": "268.1", "side": "SELL", "hash": "aae804ba268304a7500fefa338f83298842084c8", "best_bid": "0.43", "best_ask": "0.44"}], "timestamp": "1769384432153", "event_type": "price_change"}}
{"_local_timestamp": "2026-01-25T23:40:32.249177+00:00", "data": {"market": "0xcda8a657998ef072e1d9edd83ce60ada3e75fc4d9113bc3f32a343a93fb1c927", "price_changes": [{"asset_id": "79200508610612497735268197792255474784890164267460369534045305976733489576200", "price": "0.429", "size": "236", "side": "BUY", "hash": "57090b13f6ec797bda4c4bf276a1c2d5780f0584", "best_bid": "0.429", "best_ask": "0.43"}, {"asset_id": "7064893400396467616058037848568819292052255869002775709074859726119346714372", "price": "0.571", "size": "236", "side": "SELL", "hash": "44bdacf6f811694b74f3f5ff5a0ddd876dca5e1d", "best_bid": "0.57", "best_ask": "0.571"}], "timestamp": "1769384432180", "event_type": "price_change"}}
{"_local_timestamp": "2026-01-25T23:40:32.292875+00:00", "data": {"market": "0x0e34be3ee9cb4203fae20b289dfc9a9370f0045ab3fb2e1fa4e6fb82596c678f", "price_changes": [{"asset_id": "12727775089212363162508241557815769734691893483170358591167365904671830747608", "price": "0.52", "size": "9212", "side": "BUY", "hash": "add40592f6092914a4da2cdd331b01f9d37f6d5c", "best_bid": "0.56", "best_ask": "0.57"}, {"asset_id": "115183429975003994986742111804963130302445062562951748575181862773257927283380", "price": "0.48", "size": "9212", "side": "SELL", "hash": "970e80e835debb0087a969f1f5853661e26799ab", "best_bid": "0.43", "best_ask": "0.44"}], "timestamp": "1769384432228", "event_type": "price_change"}}
{"_local_timestamp": "2026-01-25T23:40:32.331308+00:00", "data": {"market": "0x0e34be3ee9cb4203fae20b289dfc9a9370f0045ab3fb2e1fa4e6fb82596c678f", "price_changes": [{"asset_id": "12727775089212363162508241557815769734691893483170358591167365904671830747608", "price": "0.05", "size": "0", "side": "BUY", "hash": "f280b9ac6b8380289ee075217a0b9bcd4db9dc89", "best_bid": "0.56", "best_ask": "0.57"}, {"asset_id": "115183429975003994986742111804963130302445062562951748575181862773257927283380", "price": "0.95", "size": "0", "side": "SELL", "hash": "4970e58765ce5de0348cc386f1b84188276ac795", "best_bid": "0.43", "best_ask": "0.44"}], "timestamp": "1769384432258", "event_type": "price_change"}}
{"_local_timestamp": "2026-01-25T23:40:32.502662+00:00", "data": {"market": "0xcda8a657998ef072e1d9edd83ce60ada3e75fc4d9113bc3f32a343a93fb1c927", "price_changes": [{"asset_id": "79200508610612497735268197792255474784890164267460369534045305976733489576200", "price": "0.4", "size": "1409", "side": "BUY", "hash": "77541453b5f9bf59e7918e70b13ed4ddf79bb265", "best_bid": "0.429", "best_ask": "0.43"}, {"asset_id": "7064893400396467616058037848568819292052255869002775709074859726119346714372", "price": "0.6", "size": "1409", "side": "SELL", "hash": "c50ab9f728b99c053f2687e6005c0087eb704999", "best_bid": "0.57", "best_ask": "0.571"}], "timestamp": "1769384432433", "event_type": "price_change"}}
{"_local_timestamp": "2026-01-25T23:40:33.091080+00:00", "data": {"market": "0xcda8a657998ef072e1d9edd83ce60ada3e75fc4d9113bc3f32a343a93fb1c927", "price_changes": [{"asset_id": "7064893400396467616058037848568819292052255869002775709074859726119346714372", "price": "0.527", "size": "10611", "side": "BUY", "hash": "6bb4daea67c96b27997524b64d7f2be2c4dad1be", "best_bid": "0.57", "best_ask": "0.571"}, {"asset_id": "79200508610612497735268197792255474784890164267460369534045305976733489576200", "price": "0.473", "size": "10611", "side": "SELL", "hash": "36cd859cc35aad6132799665794ecfb361359c48", "best_bid": "0.429", "best_ask": "0.43"}], "timestamp": "1769384433000", "event_type": "price_change"}}
{"_local_timestamp": "2026-01-25T23:40:33.094730+00:00", "data": {"market": "0xcda8a657998ef072e1d9edd83ce60ada3e75fc4d9113bc3f32a343a93fb1c927", "price_changes": [{"asset_id": "79200508610612497735268197792255474784890164267460369534045305976733489576200", "price": "0.417", "size": "6363", "side": "BUY", "hash": "83906f84a49dd33bf50dc4a15af4cafb9e6e6cfe", "best_bid": "0.429", "best_ask": "0.43"}, {"asset_id": "7064893400396467616058037848568819292052255869002775709074859726119346714372", "price": "0.583", "size": "6363", "side": "SELL", "hash": "3e8a30dc2ed6c8532e26c5f3549ba392da159793", "best_bid": "0.57", "best_ask": "0.571"}], "timestamp": "1769384433004", "event_type": "price_change"}}
{"_local_timestamp": "2026-01-25T23:40:33.098285+00:00", "data": {"market": "0xcda8a657998ef072e1d9edd83ce60ada3e75fc4d9113bc3f32a343a93fb1c927", "price_changes": [{"asset_id": "7064893400396467616058037848568819292052255869002775709074859726119346714372", "price": "0.583", "size": "11260", "side": "SELL", "hash": "69417a023da442591be8bac0db3bdf88935bd107", "best_bid": "0.57", "best_ask": "0.571"}, {"asset_id": "79200508610612497735268197792255474784890164267460369534045305976733489576200", "price": "0.417", "size": "11260", "side": "BUY", "hash": "4853689fa1e6fedbfededfc94175a64c999a06cf", "best_bid": "0.429", "best_ask": "0.43"}], "timestamp": "1769384433005", "event_type": "price_change"}}
{"_local_timestamp": "2026-01-25T23:40:33.102753+00:00", "data": {"market": "0x0e34be3ee9cb4203fae20b289dfc9a9370f0045ab3fb2e1fa4e6fb82596c678f", "price_changes": [{"asset_id": "12727775089212363162508241557815769734691893483170358591167365904671830747608", "price": "0.47", "size": "3850", "side": "BUY", "hash": "2d4741713cf152f241f6e89350e38f9aca2bee69", "best_bid": "0.56", "best_ask": "0.57"}, {"asset_id": "115183429975003994986742111804963130302445062562951748575181862773257927283380", "price": "0.53", "size": "3850", "side": "SELL", "hash": "dc06b274806af0b975965743f346c868b30baa05", "best_bid": "0.43", "best_ask": "0.44"}], "timestamp": "1769384433017", "event_type": "price_change"}}
{"_local_timestamp": "2026-01-25T23:40:33.121318+00:00", "data": {"market": "0x0e34be3ee9cb4203fae20b289dfc9a9370f0045ab3fb2e1fa4e6fb82596c678f", "price_changes": [{"asset_id": "12727775089212363162508241557815769734691893483170358591167365904671830747608", "price": "0.52", "size": "9232", "side": "BUY", "hash": "aaf6ce29c3c8190e9235dc327e5a9919f842b941", "best_bid": "0.56", "best_ask": "0.57"}, {"asset_id": "115183429975003994986742111804963130302445062562951748575181862773257927283380", "price": "0.48", "size": "9232", "side": "SELL", "hash": "81822cd67bf9e7639f7fc3a9e6011e31ba5d7532", "best_bid": "0.43", "best_ask": "0.44"}], "timestamp": "1769384433046", "event_type": "price_change"}}
{"_local_timestamp": "2026-01-25T23:40:33.197647+00:00", "data": {"market": "0x0e34be3ee9cb4203fae20b289dfc9a9370f0045ab3fb2e1fa4e6fb82596c678f", "price_changes": [{"asset_id": "12727775089212363162508241557815769734691893483170358591167365904671830747608", "price": "0.07", "size": "910", "side": "BUY", "hash": "dddbbe66a3d7bc8a2661ce72ef1454a854db10ce", "best_bid": "0.56", "best_ask": "0.57"}, {"asset_id": "115183429975003994986742111804963130302445062562951748575181862773257927283380", "price": "0.93", "size": "910", "side": "SELL", "hash": "2a8e6697c79875284187258107066b4dee27a993", "best_bid": "0.43", "best_ask": "0.44"}], "timestamp": "1769384433126", "event_type": "price_change"}}
{"_local_timestamp": "2026-01-25T23:40:33.204336+00:00", "data": {"market": "0x0e34be3ee9cb4203fae20b289dfc9a9370f0045ab3fb2e1fa4e6fb82596c678f", "price_changes": [{"asset_id": "12727775089212363162508241557815769734691893483170358591167365904671830747608", "price": "0.52", "size": "9237", "side": "BUY", "hash": "4dadeb8e2c94658c962e1cddf240a1e5fe0f571d", "best_bid": "0.56", "best_ask": "0.57"}, {"asset_id": "115183429975003994986742111804963130302445062562951748575181862773257927283380", "price": "0.48", "size": "9237", "side": "SELL", "hash": "ddf375612e91a27ce96d84ecd49350b7fe139877", "best_bid": "0.43", "best_ask": "0.44"}], "timestamp": "1769384433136", "event_type": "price_change"}}
{"_local_timestamp": "2026-01-25T23:40:33.204787+00:00", "data": {"market": "0xcda8a657998ef072e1d9edd83ce60ada3e75fc4d9113bc3f32a343a93fb1c927", "price_changes": [{"asset_id": "79200508610612497735268197792255474784890164267460369534045305976733489576200", "price": "0.418", "size": "400", "side": "BUY", "hash": "b2d4ae8830424806ef2f633d57aa90933c8652e9", "best_bid": "0.429", "best_ask": "0.43"}, {"asset_id": "7064893400396467616058037848568819292052255869002775709074859726119346714372", "price": "0.582", "size": "400", "side": "SELL", "hash": "71ed108a8204e78ccae75fd98bba936e9ec1e449", "best_bid": "0.57", "best_ask": "0.571"}], "timestamp": "1769384433138", "event_type": "price_change"}}
{"_local_timestamp": "2026-01-25T23:40:33.224941+00:00", "data": {"market": "0xcda8a657998ef072e1d9edd83ce60ada3e75fc4d9113bc3f32a343a93fb1c927", "price_changes": [{"asset_id": "79200508610612497735268197792255474784890164267460369534045305976733489576200", "price": "0.418", "size": "450", "side": "BUY", "hash": "ae6e3b52f9ccecd11cb94d10619265067fa66a44", "best_bid": "0.429", "best_ask": "0.43"}, {"asset_id": "7064893400396467616058037848568819292052255869002775709074859726119346714372", "price": "0.582", "size": "450", "side": "SELL", "hash": "419b4fc037091498543db9c6571e42e6d7178d89", "best_bid": "0.57", "best_ask": "0.571"}], "timestamp": "1769384433150", "event_type": "price_change"}}
{"_local_timestamp": "2026-01-25T23:40:33.240777+00:00", "data": {"market": "0xcda8a657998ef072e1d9edd83ce60ada3e75fc4d9113bc3f32a343a93fb1c927", "price_changes": [{"asset_id": "79200508610612497735268197792255474784890164267460369534045305976733489576200", "price": "0.418", "size": "500", "side": "BUY", "hash": "2b702c6f4b9161f69150436613eb4e2097fa7f86", "best_bid": "0.429", "best_ask": "0.43"}, {"asset_id": "7064893400396467616058037848568819292052255869002775709074859726119346714372", "price": "0.582", "size": "500", "side": "SELL", "hash": "10b94c10128bb807c8b6e129c86544a7b6420485", "best_bid": "0.57", "best_ask": "0.571"}], "timestamp": "1769384433176", "event_type": "price_change"}}
{"_local_timestamp": "2026-01-25T23:40:34.304772+00:00", "data": {"market": "0xcda8a657998ef072e1d9edd83ce60ada3e75fc4d9113bc3f32a343a93fb1c927", "price_changes": [{"asset_id": "79200508610612497735268197792255474784890164267460369534045305976733489576200", "price": "0.031", "size": "0", "side": "BUY", "hash": "354a13a9882ea71b0e0bbee0b583abfd95e82cca", "best_bid": "0.429", "best_ask": "0.43"}, {"asset_id": "7064893400396467616058037848568819292052255869002775709074859726119346714372", "price": "0.969", "size": "0", "side": "SELL", "hash": "1efad9982883de348bc55b2269c85c278d28db0e", "best_bid": "0.57", "best_ask": "0.571"}], "timestamp": "1769384434236", "event_type": "price_change"}}
{"_local_timestamp": "2026-01-25T23:40:34.305181+00:00", "data": {"market": "0xcda8a657998ef072e1d9edd83ce60ada3e75fc4d9113bc3f32a343a93fb1c927", "price_changes": [{"asset_id": "79200508610612497735268197792255474784890164267460369534045305976733489576200", "price": "0.066", "size": "0", "side": "BUY", "hash": "354a13a9882ea71b0e0bbee0b583abfd95e82cca", "best_bid": "0.429", "best_ask": "0.43"}, {"asset_id": "7064893400396467616058037848568819292052255869002775709074859726119346714372", "price": "0.934", "size": "0", "side": "SELL", "hash": "1efad9982883de348bc55b2269c85c278d28db0e", "best_bid": "0.57", "best_ask": "0.571"}], "timestamp": "1769384434236", "event_type": "price_change"}}
{"_local_timestamp": "2026-01-25T23:40:34.305551+00:00", "data": {"market": "0xcda8a657998ef072e1d9edd83ce60ada3e75fc4d9113bc3f32a343a93fb1c927", "price_changes": [{"asset_id": "79200508610612497735268197792255474784890164267460369534045305976733489576200", "price": "0.093", "size": "0", "side": "BUY", "hash": "354a13a9882ea71b0e0bbee0b583abfd95e82cca", "best_bid": "0.429", "best_ask": "0.43"}, {"asset_id": "7064893400396467616058037848568819292052255869002775709074859726119346714372", "price": "0.907", "size": "0", "side": "SELL", "hash": "1efad9982883de348bc55b2269c85c278d28db0e", "best_bid": "0.57", "best_ask": "0.571"}], "timestamp": "1769384434236", "event_type": "price_change"}}
{"_local_timestamp": "2026-01-25T23:40:34.310013+00:00", "data": {"market": "0xcda8a657998ef072e1d9edd83ce60ada3e75fc4d9113bc3f32a343a93fb1c927", "price_changes": [{"asset_id": "79200508610612497735268197792255474784890164267460369534045305976733489576200", "price": "0.429", "size": "206", "side": "BUY", "hash": "c18608373acdd27cc09213674df05ba0611d1464", "best_bid": "0.429", "best_ask": "0.43"}, {"asset_id": "7064893400396467616058037848568819292052255869002775709074859726119346714372", "price": "0.571", "size": "206", "side": "SELL", "hash": "154c49d864f98ccebc93b085412355dbec6d604d", "best_bid": "0.57", "best_ask": "0.571"}], "timestamp": "1769384434248", "event_type": "price_change"}}
{"_local_timestamp": "2026-01-25T23:40:35.805180+00:00", "data": {"market": "0xcda8a657998ef072e1d9edd83ce60ada3e75fc4d9113bc3f32a343a93fb1c927", "price_changes": [{"asset_id": "7064893400396467616058037848568819292052255869002775709074859726119346714372", "price": "0.527", "size": "10571", "side": "BUY", "hash": "c317a588528fc02a80b808b62979b0793e4fd8a1", "best_bid": "0.57", "best_ask": "0.571"}, {"asset_id": "79200508610612497735268197792255474784890164267460369534045305976733489576200", "price": "0.473", "size": "10571", "side": "SELL", "hash": "50790e1d395e720a7548fe56f4ad467914ce80c6", "best_bid": "0.429", "best_ask": "0.43"}], "timestamp": "1769384435735", "event_type": "price_change"}}
{"_local_timestamp": "2026-01-25T23:40:35.805765+00:00", "data": {"market": "0x0e34be3ee9cb4203fae20b289dfc9a9370f0045ab3fb2e1fa4e6fb82596c678f", "price_changes": [{"asset_id": "12727775089212363162508241557815769734691893483170358591167365904671830747608", "price": "0.5", "size": "686.5", "side": "BUY", "hash": "bdbc75a6efbaae3c05e367f3491eff12ecc9e4be", "best_bid": "0.56", "best_ask": "0.57"}, {"asset_id": "115183429975003994986742111804963130302445062562951748575181862773257927283380", "price": "0.5", "size": "686.5", "side": "SELL", "hash": "d46b1bf1eb9965bb931d4a8fbb2b51d1875ebc44", "best_bid": "0.43", "best_ask": "0.44"}], "timestamp": "1769384435735", "event_type": "price_change"}}
{"_local_timestamp": "2026-01-25T23:40:35.806105+00:00", "data": {"market": "0x0e34be3ee9cb4203fae20b289dfc9a9370f0045ab3fb2e1fa4e6fb82596c678f", "price_changes": [{"asset_id": "12727775089212363162508241557815769734691893483170358591167365904671830747608", "price": "0.49", "size": "0", "side": "BUY", "hash": "bdbc75a6efbaae3c05e367f3491eff12ecc9e4be", "best_bid": "0.56", "best_ask": "0.57"}, {"asset_id": "115183429975003994986742111804963130302445062562951748575181862773257927283380", "price": "0.51", "size": "0", "side": "SELL", "hash": "d46b1bf1eb9965bb931d4a8fbb2b51d1875ebc44", "best_bid": "0.43", "best_ask": "0.44"}], "timestamp": "1769384435735", "event_type": "price_change"}}
{"_local_timestamp": "2026-01-25T23:40:35.835723+00:00", "data": {"market": "0x0e34be3ee9cb4203fae20b289dfc9a9370f0045ab3fb2e1fa4e6fb82596c678f", "price_changes": [{"asset_id": "12727775089212363162508241557815769734691893483170358591167365904671830747608", "price": "0.55", "size": "260", "side": "BUY", "hash": "8eb7215beacb4b954f9207c5019eb5652e4c1446", "best_bid": "0.56", "best_ask": "0.57"}, {"asset_id": "115183429975003994986742111804963130302445062562951748575181862773257927283380", "price": "0.45", "size": "260", "side": "SELL", "hash": "7f2600ffb96b155b801717fd9d3160b6ff51a417", "best_bid": "0.43", "best_ask": "0.44"}], "timestamp": "1769384435766", "event_type": "price_change"}}
{"_local_timestamp": "2026-01-25T23:40:35.836207+00:00", "data": {"market": "0xcda8a657998ef072e1d9edd83ce60ada3e75fc4d9113bc3f32a343a93fb1c927", "price_changes": [{"asset_id": "7064893400396467616058037848568819292052255869002775709074859726119346714372", "price": "0.55", "size": "40", "side": "BUY", "hash": "b9ac3f78ac3a4b5632815ed008377eb292ac4062", "best_bid": "0.57", "best_ask": "0.571"}, {"asset_id": "79200508610612497735268197792255474784890164267460369534045305976733489576200", "price": "0.45", "size": "40", "side": "SELL", "hash": "7daeaee2c9e43ac6c35dadce96ec96ef21396e7e", "best_bid": "0.429", "best_ask": "0.43"}], "timestamp": "1769384435766", "event_type": "price_change"}}
{"_local_timestamp": "2026-01-25T23:40:35.836516+00:00", "data": {"market": "0x0e34be3ee9cb4203fae20b289dfc9a9370f0045ab3fb2e1fa4e6fb82596c678f", "price_changes": [{"asset_id": "12727775089212363162508241557815769734691893483170358591167365904671830747608", "price": "0.56", "size": "308.1", "side": "BUY", "hash": "a68f0d8db032b5bb4321fa014a9b2d87438e5fdd", "best_bid": "0.56", "best_ask": "0.57"}, {"asset_id": "115183429975003994986742111804963130302445062562951748575181862773257927283380", "price": "0.44", "size": "308.1", "side": "SELL", "hash": "17e1afaea76eb13d66ca6e27855b0673461e47d5", "best_bid": "0.43", "best_ask": "0.44"}], "timestamp": "1769384435766", "event_type": "price_change"}}
{"_local_timestamp": "2026-01-25T23:40:37.236327+00:00", "data": {"market": "0xcda8a657998ef072e1d9edd83ce60ada3e75fc4d9113bc3f32a343a93fb1c927", "price_changes": [{"asset_id": "79200508610612497735268197792255474784890164267460369534045305976733489576200", "price": "0.031", "size": "5.39", "side": "BUY", "hash": "f33294215d45dede6e63801e904e19054d321760", "best_bid": "0.429", "best_ask": "0.43"}, {"asset_id": "7064893400396467616058037848568819292052255869002775709074859726119346714372", "price": "0.969", "size": "5.39", "side": "SELL", "hash": "3a9a93f127af6ae34c2f8c4707835d12b53c0c36", "best_bid": "0.57", "best_ask": "0.571"}], "timestamp": "1769384437168", "event_type": "price_change"}}
{"_local_timestamp": "2026-01-25T23:40:37.236725+00:00", "data": {"market": "0xcda8a657998ef072e1d9edd83ce60ada3e75fc4d9113bc3f32a343a93fb1c927", "price_changes": [{"asset_id": "79200508610612497735268197792255474784890164267460369534045305976733489576200", "price": "0.051", "size": "5.94", "side": "BUY", "hash": "bbbf01c36e90772c8db14f5728f79e249e35d52b", "best_bid": "0.429", "best_ask": "0.43"}, {"asset_id": "7064893400396467616058037848568819292052255869002775709074859726119346714372", "price": "0.949", "size": "5.94", "side": "SELL", "hash": "6365838d834f1b4d596b1d2f106ab72f6e2a162f", "best_bid": "0.57", "best_ask": "0.571"}], "timestamp": "1769384437169", "event_type": "price_change"}}
{"_local_timestamp": "2026-01-25T23:40:37.237180+00:00", "data": {"market": "0xcda8a657998ef072e1d9edd83ce60ada3e75fc4d9113bc3f32a343a93fb1c927", "price_changes": [{"asset_id": "79200508610612497735268197792255474784890164267460369534045305976733489576200", "price": "0.092", "size": "13.6", "side": "BUY", "hash": "4a905c704de39b1b7c8c1c95b559be891bb2c27a", "best_bid": "0.429", "best_ask": "0.43"}, {"asset_id": "7064893400396467616058037848568819292052255869002775709074859726119346714372", "price": "0.908", "size": "13.6", "side": "SELL", "hash": "cf41a63b466773ace169d727ed2cdc3dd7ad38ad", "best_bid": "0.57", "best_ask": "0.571"}], "timestamp": "1769384437171", "event_type": "price_change"}}
{"_local_timestamp": "2026-01-25T23:40:40.530482+00:00", "data": {"market": "0x0e34be3ee9cb4203fae20b289dfc9a9370f0045ab3fb2e1fa4e6fb82596c678f", "price_changes": [{"asset_id": "12727775089212363162508241557815769734691893483170358591167365904671830747608", "price": "0.53", "size": "842", "side": "BUY", "hash": "877a030a8f4c08c19473120b2e5019e2864ec32e", "best_bid": "0.56", "best_ask": "0.57"}, {"asset_id": "115183429975003994986742111804963130302445062562951748575181862773257927283380", "price": "0.47", "size": "842", "side": "SELL", "hash": "8fcecced22a834d8cd52e676b7c3751231bd9ee6", "best_bid": "0.43", "best_ask": "0.44"}], "timestamp": "1769384440376", "event_type": "price_change"}}
{"_local_timestamp": "2026-01-25T23:40:45.915221+00:00", "data": {"market": "0x0e34be3ee9cb4203fae20b289dfc9a9370f0045ab3fb2e1fa4e6fb82596c678f", "price_changes": [{"asset_id": "12727775089212363162508241557815769734691893483170358591167365904671830747608", "price": "0.52", "size": "605", "side": "BUY", "hash": "1e3d281d62dfe790c13ddb8e42f3a30883ee9204", "best_bid": "0.56", "best_ask": "0.57"}, {"asset_id": "115183429975003994986742111804963130302445062562951748575181862773257927283380", "price": "0.48", "size": "605", "side": "SELL", "hash": "9c3dacb1e2b89061daf67e26f92a03deb92e2572", "best_bid": "0.43", "best_ask": "0.44"}], "timestamp": "1769384445846", "event_type": "price_change"}}
{"_local_timestamp": "2026-01-25T23:40:45.921238+00:00", "data": {"market": "0xcda8a657998ef072e1d9edd83ce60ada3e75fc4d9113bc3f32a343a93fb1c927", "price_changes": [{"asset_id": "79200508610612497735268197792255474784890164267460369534045305976733489576200", "price": "0.417", "size": "4897", "side": "BUY", "hash": "4da139b4b1320ea30d8a2662f01ee0a27c8b7ef7", "best_bid": "0.429", "best_ask": "0.43"}, {"asset_id": "7064893400396467616058037848568819292052255869002775709074859726119346714372", "price": "0.583", "size": "4897", "side": "SELL", "hash": "c7d0caef42480aa2d6f8cfa8d4836fe503b17606", "best_bid": "0.57", "best_ask": "0.571"}], "timestamp": "1769384445846", "event_type": "price_change"}}
{"_local_timestamp": "2026-01-25T23:40:45.922072+00:00", "data": {"market": "0x0e34be3ee9cb4203fae20b289dfc9a9370f0045ab3fb2e1fa4e6fb82596c678f", "price_changes": [{"asset_id": "115183429975003994986742111804963130302445062562951748575181862773257927283380", "price": "0.48", "size": "135", "side": "SELL", "hash": "9411e74cf35f1e8342f3fe37d8cd070dae346c3e", "best_bid": "0.43", "best_ask": "0.44"}, {"asset_id": "12727775089212363162508241557815769734691893483170358591167365904671830747608", "price": "0.52", "size": "135", "side": "BUY", "hash": "0b437685111000c6a872b886e1269652062e6439", "best_bid": "0.56", "best_ask": "0.57"}], "timestamp": "1769384445847", "event_type": "price_change"}}
{"_local_timestamp": "2026-01-25T23:40:45.924526+00:00", "data": {"market": "0x0e34be3ee9cb4203fae20b289dfc9a9370f0045ab3fb2e1fa4e6fb82596c678f", "price_changes": [{"asset_id": "115183429975003994986742111804963130302445062562951748575181862773257927283380", "price": "0.41", "size": "763", "side": "BUY", "hash": "9411e74cf35f1e8342f3fe37d8cd070dae346c3e", "best_bid": "0.43", "best_ask": "0.44"}, {"asset_id": "12727775089212363162508241557815769734691893483170358591167365904671830747608", "price": "0.59", "size": "763", "side": "SELL", "hash": "0b437685111000c6a872b886e1269652062e6439", "best_bid": "0.56", "best_ask": "0.57"}], "timestamp": "1769384445847", "event_type": "price_change"}}
{"_local_timestamp": "2026-01-25T23:40:45.930501+00:00", "data": {"market": "0xcda8a657998ef072e1d9edd83ce60ada3e75fc4d9113bc3f32a343a93fb1c927", "price_changes": [{"asset_id": "7064893400396467616058037848568819292052255869002775709074859726119346714372", "price": "0.583", "size": "0", "side": "SELL", "hash": "c0fbdc5fd600fe30232dcb618488cd66140af65a", "best_bid": "0.57", "best_ask": "0.571"}, {"asset_id": "79200508610612497735268197792255474784890164267460369534045305976733489576200", "price": "0.417", "size": "0", "side": "BUY", "hash": "88286ca38124db27f2272fd7a85665fad970e4b0", "best_bid": "0.429", "best_ask": "0.43"}], "timestamp": "1769384445847", "event_type": "price_change"}}
{"_local_timestamp": "2026-01-25T23:40:45.931020+00:00", "data": {"market": "0xcda8a657998ef072e1d9edd83ce60ada3e75fc4d9113bc3f32a343a93fb1c927", "price_changes": [{"asset_id": "7064893400396467616058037848568819292052255869002775709074859726119346714372", "price": "0.527", "size": "110", "side": "BUY", "hash": "c0fbdc5fd600fe30232dcb618488cd66140af65a", "best_bid": "0.57", "best_ask": "0.571"}, {"asset_id": "79200508610612497735268197792255474784890164267460369534045305976733489576200", "price": "0.473", "size": "110", "side": "SELL", "hash": "88286ca38124db27f2272fd7a85665fad970e4b0", "best_bid": "0.429", "best_ask": "0.43"}], "timestamp": "1769384445847", "event_type": "price_change"}}
{"_local_timestamp": "2026-01-25T23:40:46.040659+00:00", "data": {"market": "0x0e34be3ee9cb4203fae20b289dfc9a9370f0045ab3fb2e1fa4e6fb82596c678f", "price_changes": [{"asset_id": "12727775089212363162508241557815769734691893483170358591167365904671830747608", "price": "0.52", "size": "130", "side": "BUY", "hash": "af77100c5a31afa3e348c9f9f5fb4c15be34c4cf", "best_bid": "0.56", "best_ask": "0.57"}, {"asset_id": "115183429975003994986742111804963130302445062562951748575181862773257927283380", "price": "0.48", "size": "130", "side": "SELL", "hash": "18de4163ea856ee16a0a569909ef6d5fc0553129", "best_bid": "0.43", "best_ask": "0.44"}], "timestamp": "1769384445966", "event_type": "price_change"}}
{"_local_timestamp": "2026-01-25T23:40:47.955045+00:00", "data": {"market": "0xcda8a657998ef072e1d9edd83ce60ada3e75fc4d9113bc3f32a343a93fb1c927", "price_changes": [{"asset_id": "79200508610612497735268197792255474784890164267460369534045305976733489576200", "price": "0.43", "size": "336.9", "side": "BUY", "hash": "f0561d6dcce6e9dcba8e3681c40f0564a6fdd0ff", "best_bid": "0.43", "best_ask": "0.45"}, {"asset_id": "7064893400396467616058037848568819292052255869002775709074859726119346714372", "price": "0.57", "size": "336.9", "side": "SELL", "hash": "f4777867064c2da74e611a11857fd11a2f06a57b", "best_bid": "0.55", "best_ask": "0.57"}], "timestamp": "1769384447878", "event_type": "price_change"}}
{"_local_timestamp": "2026-01-25T23:40:47.956440+00:00", "data": {"market": "0xcda8a657998ef072e1d9edd83ce60ada3e75fc4d9113bc3f32a343a93fb1c927", "price_changes": [{"asset_id": "7064893400396467616058037848568819292052255869002775709074859726119346714372", "price": "0.57", "size": "0", "side": "BUY", "hash": "f4777867064c2da74e611a11857fd11a2f06a57b", "best_bid": "0.55", "best_ask": "0.57"}, {"asset_id": "79200508610612497735268197792255474784890164267460369534045305976733489576200", "price": "0.43", "size": "0", "side": "SELL", "hash": "f0561d6dcce6e9dcba8e3681c40f0564a6fdd0ff", "best_bid": "0.43", "best_ask": "0.45"}], "timestamp": "1769384447878", "event_type": "price_change"}}
{"_local_timestamp": "2026-01-25T23:40:47.957003+00:00", "data": {"market": "0xcda8a657998ef072e1d9edd83ce60ada3e75fc4d9113bc3f32a343a93fb1c927", "asset_id": "7064893400396467616058037848568819292052255869002775709074859726119346714372", "bids": [{"price": "0.001", "size": "3344.64"}, {"price": "0.002", "size": "255.47"}, {"price": "0.003", "size": "1000"}, {"price": "0.004", "size": "9.35"}, {"price": "0.01", "size": "3233"}, {"price": "0.011", "size": "8.91"}, {"price": "0.02", "size": "2200"}, {"price": "0.03", "size": "100"}, {"price": "0.031", "size": "6.98"}, {"price": "0.053", "size": "600"}, {"price": "0.102", "size": "3136"}, {"price": "0.103", "size": "4476"}, {"price": "0.104", "size": "6.07"}, {"price": "0.14", "size": "50"}, {"price": "0.2", "size": "200"}, {"price": "0.5", "size": "644"}, {"price": "0.506", "size": "10"}, {"price": "0.51", "size": "644"}, {"price": "0.52", "size": "110"}, {"price": "0.527", "size": "110"}, {"price": "0.528", "size": "60"}, {"price": "0.55", "size": "40"}], "asks": [{"price": "0.999", "size": "1610.74"}, {"price": "0.998", "size": "259.85"}, {"price": "0.997", "size": "400"}, {"price": "0.996", "size": "7.31"}, {"price": "0.994", "size": "200"}, {"price": "0.993", "size": "5.49"}, {"price": "0.99", "size": "3233"}, {"price": "0.989", "size": "16.48"}, {"price": "0.98", "size": "1800"}, {"price": "0.97", "size": "100"}, {"price": "0.969", "size": "5.39"}, {"price": "0.95", "size": "10"}, {"price": "0.949", "size": "5.94"}, {"price": "0.935", "size": "900"}, {"price": "0.91", "size": "1776"}, {"price": "0.909", "size": "5014"}, {"price": "0.908", "size": "13.6"}, {"price": "0.69", "size": "9.9"}, {"price": "0.689", "size": "20"}, {"price": "0.629", "size": "5"}, {"price": "0.61", "size": "652"}, {"price": "0.609", "size": "10"}, {"price": "0.6", "size": "1409"}, {"price": "0.59", "size": "160"}, {"price": "0.588", "size": "50"}, {"price": "0.582", "size": "500"}, {"price": "0.579", "size": "47.5"}, {"price": "0.572", "size": "90"}, {"price": "0.571", "size": "206"}, {"price": "0.57", "size": "336.9"}], "hash": "f4777867064c2da74e611a11857fd11a2f06a57b", "timestamp": "1769384447878", "event_type": "book"}}
{"_local_timestamp": "2026-01-25T23:40:47.957553+00:00", "data": {"market": "0xcda8a657998ef072e1d9edd83ce60ada3e75fc4d9113bc3f32a343a93fb1c927", "asset_id": "79200508610612497735268197792255474784890164267460369534045305976733489576200", "bids": [{"price": "0.001", "size": "1610.74"}, {"price": "0.002", "size": "259.85"}, {"price": "0.003", "size": "400"}, {"price": "0.004", "size": "7.31"}, {"price": "0.006", "size": "200"}, {"price": "0.007", "size": "5.49"}, {"price": "0.01", "size": "3233"}, {"price": "0.011", "size": "16.48"}, {"price": "0.02", "size": "1800"}, {"price": "0.03", "size": "100"}, {"price": "0.031", "size": "5.39"}, {"price": "0.05", "size": "10"}, {"price": "0.051", "size": "5.94"}, {"price": "0.065", "size": "900"}, {"price": "0.09", "size": "1776"}, {"price": "0.091", "size": "5014"}, {"price": "0.092", "size": "13.6"}, {"price": "0.31", "size": "9.9"}, {"price": "0.311", "size": "20"}, {"price": "0.371", "size": "5"}, {"price": "0.39", "size": "652"}, {"price": "0.391", "size": "10"}, {"price": "0.4", "size": "1409"}, {"price": "0.41", "size": "160"}, {"price": "0.412", "size": "50"}, {"price": "0.418", "size": "500"}, {"price": "0.421", "size": "47.5"}, {"price": "0.428", "size": "90"}, {"price": "0.429", "size": "206"}, {"price": "0.43", "size": "336.9"}], "asks": [{"price": "0.999", "size": "3344.64"}, {"price": "0.998", "size": "255.47"}, {"price": "0.997", "size": "1000"}, {"price": "0.996", "size": "9.35"}, {"price": "0.99", "size": "3233"}, {"price": "0.989", "size": "8.91"}, {"price": "0.98", "size": "2200"}, {"price": "0.97", "size": "100"}, {"price": "0.969", "size": "6.98"}, {"price": "0.947", "size": "600"}, {"price": "0.898", "size": "3136"}, {"price": "0.897", "size": "4476"}, {"price": "0.896", "size": "6.07"}, {"price": "0.86", "size": "50"}, {"price": "0.8", "size": "200"}, {"price": "0.5", "size": "644"}, {"price": "0.494", "size": "10"}, {"price": "0.49", "size": "644"}, {"price": "0.48", "size": "110"}, {"price": "0.473", "size": "110"}, {"price": "0.472", "size": "60"}, {"price": "0.45", "size": "40"}], "hash": "f0561d6dcce6e9dcba8e3681c40f0564a6fdd0ff", "timestamp": "1769384447878", "event_type": "book"}}
{"_local_timestamp": "2026-01-25T23:40:47.970281+00:00", "data": {"market": "0x0e34be3ee9cb4203fae20b289dfc9a9370f0045ab3fb2e1fa4e6fb82596c678f", "price_changes": [{"asset_id": "12727775089212363162508241557815769734691893483170358591167365904671830747608", "price": "0.53", "size": "942", "side": "BUY", "hash": "dcaf744cb610152d2cef4783f2e6c5da46abd476", "best_bid": "0.56", "best_ask": "0.57"}, {"asset_id": "115183429975003994986742111804963130302445062562951748575181862773257927283380", "price": "0.47", "size": "942", "side": "SELL", "hash": "c3593da4d8ae9ab42bef6a95331cb73699608061", "best_bid": "0.43", "best_ask": "0.44"}], "timestamp": "1769384447903", "event_type": "price_change"}}
{"_local_timestamp": "2026-01-25T23:40:47.971724+00:00", "data": {"market": "0xcda8a657998ef072e1d9edd83ce60ada3e75fc4d9113bc3f32a343a93fb1c927", "price_changes": [{"asset_id": "79200508610612497735268197792255474784890164267460369534045305976733489576200", "price": "0.471", "size": "320", "side": "SELL", "hash": "b0dd24ea36bd15f85ba444d346c0d0130a5be5f2", "best_bid": "0.43", "best_ask": "0.45"}, {"asset_id": "7064893400396467616058037848568819292052255869002775709074859726119346714372", "price": "0.529", "size": "320", "side": "BUY", "hash": "ae60784cacf426663260a83bc2ec7fb3ab105325", "best_bid": "0.55", "best_ask": "0.57"}], "timestamp": "1769384447904", "event_type": "price_change"}}
{"_local_timestamp": "2026-01-25T23:40:47.980393+00:00", "data": {"market": "0xcda8a657998ef072e1d9edd83ce60ada3e75fc4d9113bc3f32a343a93fb1c927", "price_changes": [{"asset_id": "79200508610612497735268197792255474784890164267460369534045305976733489576200", "price": "0.421", "size": "60.5", "side": "BUY", "hash": "8383b98217b3354ea2f53acd504362e2246f872f", "best_bid": "0.43", "best_ask": "0.45"}, {"asset_id": "7064893400396467616058037848568819292052255869002775709074859726119346714372", "price": "0.579", "size": "60.5", "side": "SELL", "hash": "64f349e918537442d0585f211c31d3faaddf4590", "best_bid": "0.55", "best_ask": "0.57"}], "timestamp": "1769384447905", "event_type": "price_change"}}
{"_local_timestamp": "2026-01-25T23:40:47.981380+00:00", "data": {"market": "0x0e34be3ee9cb4203fae20b289dfc9a9370f0045ab3fb2e1fa4e6fb82596c678f", "price_changes": [{"asset_id": "12727775089212363162508241557815769734691893483170358591167365904671830747608", "price": "0.55", "size": "200", "side": "BUY", "hash": "7bccf0e29af08478fcd183f06ff18cdb8dfcbaad", "best_bid": "0.56", "best_ask": "0.57"}, {"asset_id": "115183429975003994986742111804963130302445062562951748575181862773257927283380", "price": "0.45", "size": "200", "side": "SELL", "hash": "6b530f1bb2bfa686a684c343390c034f14b25f89", "best_bid": "0.43", "best_ask": "0.44"}], "timestamp": "1769384447906", "event_type": "price_change"}}
{"_local_timestamp": "2026-01-25T23:40:48.071556+00:00", "data": {"market": "0x0e34be3ee9cb4203fae20b289dfc9a9370f0045ab3fb2e1fa4e6fb82596c678f", "price_changes": [{"asset_id": "12727775089212363162508241557815769734691893483170358591167365904671830747608", "price": "0.56", "size": "268.1", "side": "BUY", "hash": "79a34dc8409008817381d61b6652972e2fdf3959", "best_bid": "0.56", "best_ask": "0.57"}, {"asset_id": "115183429975003994986742111804963130302445062562951748575181862773257927283380", "price": "0.44", "size": "268.1", "side": "SELL", "hash": "c421c36753994aa9d5a4e918b63445a2db2a9e42", "best_bid": "0.43", "best_ask": "0.44"}], "timestamp": "1769384447907", "event_type": "price_change"}}
{"_local_timestamp": "2026-01-25T23:40:48.072273+00:00", "data": {"market": "0xcda8a657998ef072e1d9edd83ce60ada3e75fc4d9113bc3f32a343a93fb1c927", "asset_id": "79200508610612497735268197792255474784890164267460369534045305976733489576200", "price": "0.43", "size": "163.1", "fee_rate_bps": "0", "side": "BUY", "timestamp": "1769384447909", "event_type": "last_trade_price", "transaction_hash": "0x3d458767f5f4cd18e313bbe4bf7f43d74bc5b4ee640a960a4f831d6dbd028a20"}}
{"_local_timestamp": "2026-01-25T23:40:48.072602+00:00", "data": {"market": "0xcda8a657998ef072e1d9edd83ce60ada3e75fc4d9113bc3f32a343a93fb1c927", "price_changes": [{"asset_id": "79200508610612497735268197792255474784890164267460369534045305976733489576200", "price": "0.418", "size": "450", "side": "BUY", "hash": "ff377b2476cd897d40319a4635066e3f8d58e7f0", "best_bid": "0.43", "best_ask": "0.45"}, {"asset_id": "7064893400396467616058037848568819292052255869002775709074859726119346714372", "price": "0.582", "size": "450", "side": "SELL", "hash": "7dc568aff9f47ae14b082a2b7ed185a395d57cfb", "best_bid": "0.55", "best_ask": "0.57"}], "timestamp": "1769384447985", "event_type": "price_change"}}
{"_local_timestamp": "2026-01-25T23:40:48.072887+00:00", "data": {"market": "0xcda8a657998ef072e1d9edd83ce60ada3e75fc4d9113bc3f32a343a93fb1c927", "price_changes": [{"asset_id": "79200508610612497735268197792255474784890164267460369534045305976733489576200", "price": "0.418", "size": "400", "side": "BUY", "hash": "782b7a3523cafdf522ec0e2a06e4d10918adf11c", "best_bid": "0.43", "best_ask": "0.45"}, {"asset_id": "7064893400396467616058037848568819292052255869002775709074859726119346714372", "price": "0.582", "size": "400", "side": "SELL", "hash": "ee68485ef06e6146c0100131ec257c69113df4ad", "best_bid": "0.55", "best_ask": "0.57"}], "timestamp": "1769384447988", "event_type": "price_change"}}
{"_local_timestamp": "2026-01-25T23:40:48.073161+00:00", "data": {"market": "0x0e34be3ee9cb4203fae20b289dfc9a9370f0045ab3fb2e1fa4e6fb82596c678f", "price_changes": [{"asset_id": "12727775089212363162508241557815769734691893483170358591167365904671830747608", "price": "0.52", "size": "180", "side": "BUY", "hash": "3ca3a308150647e69c3c0c1f35a8cdeb04236030", "best_bid": "0.56", "best_ask": "0.57"}, {"asset_id": "115183429975003994986742111804963130302445062562951748575181862773257927283380", "price": "0.48", "size": "180", "side": "SELL", "hash": "3938b74b4b91b8dff034202da1c0f6497fde90e6", "best_bid": "0.43", "best_ask": "0.44"}], "timestamp": "1769384447990", "event_type": "price_change"}}
{"_local_timestamp": "2026-01-25T23:40:48.073432+00:00", "data": {"market": "0x0e34be3ee9cb4203fae20b289dfc9a9370f0045ab3fb2e1fa4e6fb82596c678f", "price_changes": [{"asset_id": "12727775089212363162508241557815769734691893483170358591167365904671830747608", "price": "0.56", "size": "218.1", "side": "BUY", "hash": "2d165eec0a4466b574694a08e31012298cefaa42", "best_bid": "0.56", "best_ask": "0.57"}, {"asset_id": "115183429975003994986742111804963130302445062562951748575181862773257927283380", "price": "0.44", "size": "218.1", "side": "SELL", "hash": "02f0221e17e520f66cba7301665026254672d8f1", "best_bid": "0.43", "best_ask": "0.44"}], "timestamp": "1769384447996", "event_type": "price_change"}}
{"_local_timestamp": "2026-01-25T23:40:48.073671+00:00", "data": {"market": "0x0e34be3ee9cb4203fae20b289dfc9a9370f0045ab3fb2e1fa4e6fb82596c678f", "price_changes": [{"asset_id": "12727775089212363162508241557815769734691893483170358591167365904671830747608", "price": "0.52", "size": "230", "side": "BUY", "hash": "9d33b0376c5a92a173777ac55f1ef683f4274872", "best_bid": "0.56", "best_ask": "0.57"}, {"asset_id": "115183429975003994986742111804963130302445062562951748575181862773257927283380", "price": "0.48", "size": "230", "side": "SELL", "hash": "c0581b4e8225a43ef77710e5399d1ebb85cb3929", "best_bid": "0.43", "best_ask": "0.44"}], "timestamp": "1769384447997", "event_type": "price_change"}}
{"_local_timestamp": "2026-01-25T23:40:48.073914+00:00", "data": {"market": "0x0e34be3ee9cb4203fae20b289dfc9a9370f0045ab3fb2e1fa4e6fb82596c678f", "price_changes": [{"asset_id": "12727775089212363162508241557815769734691893483170358591167365904671830747608", "price": "0.56", "size": "213.1", "side": "BUY", "hash": "880c1d46944e8172e4d274f238cf5ca94cd1cec0", "best_bid": "0.56", "best_ask": "0.57"}, {"asset_id": "115183429975003994986742111804963130302445062562951748575181862773257927283380", "price": "0.44", "size": "213.1", "side": "SELL", "hash": "8b4b31e5e5b04faa436d5132716ca99502ebb24c", "best_bid": "0.43", "best_ask": "0.44"}], "timestamp": "1769384447997", "event_type": "price_change"}}
{"_local_timestamp": "2026-01-25T23:40:48.074148+00:00", "data": {"market": "0xcda8a657998ef072e1d9edd83ce60ada3e75fc4d9113bc3f32a343a93fb1c927", "price_changes": [{"asset_id": "79200508610612497735268197792255474784890164267460369534045305976733489576200", "price": "0.418", "size": "0", "side": "BUY", "hash": "f417be0f66b242e29629445a0ead5735c98486f9", "best_bid": "0.43", "best_ask": "0.45"}, {"asset_id": "7064893400396467616058037848568819292052255869002775709074859726119346714372", "price": "0.582", "size": "0", "side": "SELL", "hash": "6d56d6f788973f304fc2cf8bb0e9242cc7ad4c1e", "best_bid": "0.55", "best_ask": "0.57"}], "timestamp": "1769384447997", "event_type": "price_change"}}
{"_local_timestamp": "2026-01-25T23:40:48.080623+00:00", "data": {"market": "0xcda8a657998ef072e1d9edd83ce60ada3e75fc4d9113bc3f32a343a93fb1c927", "price_changes": [{"asset_id": "7064893400396467616058037848568819292052255869002775709074859726119346714372", "price": "0.56", "size": "200", "side": "BUY", "hash": "d466cb63f7dc0d7361488cb23ab110159d73986e", "best_bid": "0.56", "best_ask": "0.57"}, {"asset_id": "79200508610612497735268197792255474784890164267460369534045305976733489576200", "price": "0.44", "size": "200", "side": "SELL", "hash": "795c2eac540feac0b42a5cd922dccade1990b776", "best_bid": "0.43", "best_ask": "0.44"}], "timestamp": "1769384448003", "event_type": "price_change"}}
{"_local_timestamp": "2026-01-25T23:40:48.084110+00:00", "data": {"market": "0x0e34be3ee9cb4203fae20b289dfc9a9370f0045ab3fb2e1fa4e6fb82596c678f", "price_changes": [{"asset_id": "12727775089212363162508241557815769734691893483170358591167365904671830747608", "price": "0.52", "size": "235", "side": "BUY", "hash": "c4da935404b5df24f8f8bf014ecfaabd2b204203", "best_bid": "0.56", "best_ask": "0.57"}, {"asset_id": "115183429975003994986742111804963130302445062562951748575181862773257927283380", "price": "0.48", "size": "235", "side": "SELL", "hash": "37acc22c0325679a707827e4a2ad97e875d5ca30", "best_bid": "0.43", "best_ask": "0.44"}], "timestamp": "1769384448006", "event_type": "price_change"}}
{"_local_timestamp": "2026-01-25T23:40:48.084525+00:00", "data": {"market": "0x0e34be3ee9cb4203fae20b289dfc9a9370f0045ab3fb2e1fa4e6fb82596c678f", "price_changes": [{"asset_id": "12727775089212363162508241557815769734691893483170358591167365904671830747608", "price": "0.56", "size": "163.1", "side": "BUY", "hash": "e557586f43de8fdbeea4d77274ce854aef96d219", "best_bid": "0.56", "best_ask": "0.57"}, {"asset_id": "115183429975003994986742111804963130302445062562951748575181862773257927283380", "price": "0.44", "size": "163.1", "side": "SELL", "hash": "4325e8fbf6266760f0c68f1265487ad8e1c7a3be", "best_bid": "0.43", "best_ask": "0.44"}], "timestamp": "1769384448010", "event_type": "price_change"}}
{"_local_timestamp": "2026-01-25T23:40:48.157665+00:00", "data": {"market": "0x0e34be3ee9cb4203fae20b289dfc9a9370f0045ab3fb2e1fa4e6fb82596c678f", "price_changes": [{"asset_id": "12727775089212363162508241557815769734691893483170358591167365904671830747608", "price": "0.56", "size": "0", "side": "BUY", "hash": "1f49d8c4d85698e94a836ec40c3b9ac05c021560", "best_bid": "0.55", "best_ask": "0.57"}, {"asset_id": "115183429975003994986742111804963130302445062562951748575181862773257927283380", "price": "0.44", "size": "0", "side": "SELL", "hash": "92090b1958b145d89f7e0185c53bbed8ed0026b3", "best_bid": "0.43", "best_ask": "0.45"}], "timestamp": "1769384448093", "event_type": "price_change"}}
{"_local_timestamp": "2026-01-25T23:40:48.185036+00:00", "data": {"market": "0xcda8a657998ef072e1d9edd83ce60ada3e75fc4d9113bc3f32a343a93fb1c927", "price_changes": [{"asset_id": "7064893400396467616058037848568819292052255869002775709074859726119346714372", "price": "0.55", "size": "0", "side": "BUY", "hash": "00d60053d2567ea971c8677592b1166f4afbad22", "best_bid": "0.56", "best_ask": "0.57"}, {"asset_id": "79200508610612497735268197792255474784890164267460369534045305976733489576200", "price": "0.45", "size": "0", "side": "SELL", "hash": "af4574fd5ae1805202cc4486838fa37720deb1e6", "best_bid": "0.43", "best_ask": "0.44"}], "timestamp": "1769384448115", "event_type": "price_change"}}
{"_local_timestamp": "2026-01-25T23:40:48.202431+00:00", "data": {"market": "0x0e34be3ee9cb4203fae20b289dfc9a9370f0045ab3fb2e1fa4e6fb82596c678f", "price_changes": [{"asset_id": "12727775089212363162508241557815769734691893483170358591167365904671830747608", "price": "0.52", "size": "185", "side": "BUY", "hash": "2f066bec28bcf71b07f6d4e296c72f2fff8ea3dd", "best_bid": "0.55", "best_ask": "0.57"}, {"asset_id": "115183429975003994986742111804963130302445062562951748575181862773257927283380", "price": "0.48", "size": "185", "side": "SELL", "hash": "defa8c9a5087367cf743f14213881a03d4e89ac3", "best_bid": "0.43", "best_ask": "0.45"}], "timestamp": "1769384448131", "event_type": "price_change"}}
{"_local_timestamp": "2026-01-25T23:40:48.228268+00:00", "data": {"market": "0x0e34be3ee9cb4203fae20b289dfc9a9370f0045ab3fb2e1fa4e6fb82596c678f", "price_changes": [{"asset_id": "12727775089212363162508241557815769734691893483170358591167365904671830747608", "price": "0.52", "size": "135", "side": "BUY", "hash": "94feb513aeb62a7a4c55be6f7f083541875840ca", "best_bid": "0.55", "best_ask": "0.57"}, {"asset_id": "115183429975003994986742111804963130302445062562951748575181862773257927283380", "price": "0.48", "size": "135", "side": "SELL", "hash": "88d3365c3e4d92c12c4c1b3ffe2063742883533b", "best_bid": "0.43", "best_ask": "0.45"}], "timestamp": "1769384448166", "event_type": "price_change"}}
{"_local_timestamp": "2026-01-25T23:40:48.320337+00:00", "data": {"market": "0x0e34be3ee9cb4203fae20b289dfc9a9370f0045ab3fb2e1fa4e6fb82596c678f", "price_changes": [{"asset_id": "12727775089212363162508241557815769734691893483170358591167365904671830747608", "price": "0.54", "size": "40", "side": "BUY", "hash": "bc796e0d8161896d93d2aea016371354febad7a3", "best_bid": "0.55", "best_ask": "0.57"}, {"asset_id": "115183429975003994986742111804963130302445062562951748575181862773257927283380", "price": "0.46", "size": "40", "side": "SELL", "hash": "24e94caeb644a01ee6f9ceb9e061b1ac1ba21546", "best_bid": "0.43", "best_ask": "0.45"}], "timestamp": "1769384448243", "event_type": "price_change"}}
{"_local_timestamp": "2026-01-25T23:40:48.489660+00:00", "data": {"market": "0x0e34be3ee9cb4203fae20b289dfc9a9370f0045ab3fb2e1fa4e6fb82596c678f", "price_changes": [{"asset_id": "12727775089212363162508241557815769734691893483170358591167365904671830747608", "price": "0.54", "size": "0", "side": "BUY", "hash": "b6552b0eb4bbd488c4fd0a31fecf3e74a7c722f8", "best_bid": "0.55", "best_ask": "0.57"}, {"asset_id": "115183429975003994986742111804963130302445062562951748575181862773257927283380", "price": "0.46", "size": "0", "side": "SELL", "hash": "7920493f99a4068ce98b887f694395a954c70860", "best_bid": "0.43", "best_ask": "0.45"}], "timestamp": "1769384448416", "event_type": "price_change"}}
{"_local_timestamp": "2026-01-25T23:40:48.595046+00:00", "data": {"market": "0x0e34be3ee9cb4203fae20b289dfc9a9370f0045ab3fb2e1fa4e6fb82596c678f", "price_changes": [{"asset_id": "12727775089212363162508241557815769734691893483170358591167365904671830747608", "price": "0.55", "size": "205", "side": "BUY", "hash": "f4af243147adffcbd0db2b797cdbd88d288da478", "best_bid": "0.55", "best_ask": "0.57"}, {"asset_id": "115183429975003994986742111804963130302445062562951748575181862773257927283380", "price": "0.45", "size": "205", "side": "SELL", "hash": "5c9e065df537e0544f65ee4a0b00d3164581e42c", "best_bid": "0.43", "best_ask": "0.45"}], "timestamp": "1769384448524", "event_type": "price_change"}}
{"_local_timestamp": "2026-01-25T23:40:48.667200+00:00", "data": {"market": "0x0e34be3ee9cb4203fae20b289dfc9a9370f0045ab3fb2e1fa4e6fb82596c678f", "price_changes": [{"asset_id": "12727775089212363162508241557815769734691893483170358591167365904671830747608", "price": "0.55", "size": "405", "side": "BUY", "hash": "85744ec805c40d4e13578e86eb11303546af50b6", "best_bid": "0.55", "best_ask": "0.57"}, {"asset_id": "115183429975003994986742111804963130302445062562951748575181862773257927283380", "price": "0.45", "size": "405", "side": "SELL", "hash": "9f58f00f8f7a951ee84d797a84f2fd5609e957cd", "best_bid": "0.43", "best_ask": "0.45"}], "timestamp": "1769384448601", "event_type": "price_change"}}
{"_local_timestamp": "2026-01-25T23:40:48.969852+00:00", "data": {"market": "0x0e34be3ee9cb4203fae20b289dfc9a9370f0045ab3fb2e1fa4e6fb82596c678f", "price_changes": [{"asset_id": "12727775089212363162508241557815769734691893483170358591167365904671830747608", "price": "0.53", "size": "842", "side": "BUY", "hash": "0733a36c684cbca810a6843e504f7a7c591fe7d9", "best_bid": "0.55", "best_ask": "0.57"}, {"asset_id": "115183429975003994986742111804963130302445062562951748575181862773257927283380", "price": "0.47", "size": "842", "side": "SELL", "hash": "dcf8c98c90b98398ad7b919f5afddc6ff0ab9cff", "best_bid": "0.43", "best_ask": "0.45"}], "timestamp": "1769384448903", "event_type": "price_change"}}
{"_local_timestamp": "2026-01-25T23:40:49.015292+00:00", "data": {"market": "0x0e34be3ee9cb4203fae20b289dfc9a9370f0045ab3fb2e1fa4e6fb82596c678f", "price_changes": [{"asset_id": "12727775089212363162508241557815769734691893483170358591167365904671830747608", "price": "0.52", "size": "115", "side": "BUY", "hash": "4ca38f2e293b9b5c6687ad410e4e43b461ec1094", "best_bid": "0.55", "best_ask": "0.57"}, {"asset_id": "115183429975003994986742111804963130302445062562951748575181862773257927283380", "price": "0.48", "size": "115", "side": "SELL", "hash": "14a53dbd38561ffdac3c40b69f1fdcd2f2fcdf58", "best_bid": "0.43", "best_ask": "0.45"}], "timestamp": "1769384448949", "event_type": "price_change"}}
{"_local_timestamp": "2026-01-25T23:40:49.050408+00:00", "data": {"market": "0x0e34be3ee9cb4203fae20b289dfc9a9370f0045ab3fb2e1fa4e6fb82596c678f", "price_changes": [{"asset_id": "12727775089212363162508241557815769734691893483170358591167365904671830747608", "price": "0.51", "size": "674", "side": "BUY", "hash": "b508e051d770bf7f28f570889eeb6e863a124181", "best_bid": "0.55", "best_ask": "0.57"}, {"asset_id": "115183429975003994986742111804963130302445062562951748575181862773257927283380", "price": "0.49", "size": "674", "side": "SELL", "hash": "4f174202cdb448c7ab2f26ae9052d9b190d6e802", "best_bid": "0.43", "best_ask": "0.45"}], "timestamp": "1769384448979", "event_type": "price_change"}}
{"_local_timestamp": "2026-01-25T23:40:49.087949+00:00", "data": {"market": "0x0e34be3ee9cb4203fae20b289dfc9a9370f0045ab3fb2e1fa4e6fb82596c678f", "price_changes": [{"asset_id": "12727775089212363162508241557815769734691893483170358591167365904671830747608", "price": "0.55", "size": "455", "side": "BUY", "hash": "893acda13d6d54f45bc945223b745e9fc1cdb019", "best_bid": "0.55", "best_ask": "0.57"}, {"asset_id": "115183429975003994986742111804963130302445062562951748575181862773257927283380", "price": "0.45", "size": "455", "side": "SELL", "hash": "b50d5650d8e62e71e29d24141c80ae5b412dce21", "best_bid": "0.43", "best_ask": "0.45"}], "timestamp": "1769384449007", "event_type": "price_change"}}
{"_local_timestamp": "2026-01-25T23:40:49.088332+00:00", "data": {"market": "0x0e34be3ee9cb4203fae20b289dfc9a9370f0045ab3fb2e1fa4e6fb82596c678f", "price_changes": [{"asset_id": "12727775089212363162508241557815769734691893483170358591167365904671830747608", "price": "0.55", "size": "505", "side": "BUY", "hash": "175e2e9897c404f8aba144134ce3ea971c4eab1b", "best_bid": "0.55", "best_ask": "0.57"}, {"asset_id": "115183429975003994986742111804963130302445062562951748575181862773257927283380", "price": "0.45", "size": "505", "side": "SELL", "hash": "1ff1bab6d7d7bbb3bd9f707d335ca9777e4707f7", "best_bid": "0.43", "best_ask": "0.45"}], "timestamp": "1769384449017", "event_type": "price_change"}}
{"_local_timestamp": "2026-01-25T23:40:49.218519+00:00", "data": {"market": "0xcda8a657998ef072e1d9edd83ce60ada3e75fc4d9113bc3f32a343a93fb1c927", "price_changes": [{"asset_id": "79200508610612497735268197792255474784890164267460369534045305976733489576200", "price": "0.471", "size": "0", "side": "SELL", "hash": "5e6ae4b406d6d6b383a060566e638128cdf94acf", "best_bid": "0.43", "best_ask": "0.44"}, {"asset_id": "7064893400396467616058037848568819292052255869002775709074859726119346714372", "price": "0.529", "size": "0", "side": "BUY", "hash": "b45aa7235a06207dcfc346eab7b31fe9e79d260c", "best_bid": "0.56", "best_ask": "0.57"}], "timestamp": "1769384449151", "event_type": "price_change"}}
{"_local_timestamp": "2026-01-25T23:40:49.220226+00:00", "data": {"market": "0xcda8a657998ef072e1d9edd83ce60ada3e75fc4d9113bc3f32a343a93fb1c927", "price_changes": [{"asset_id": "79200508610612497735268197792255474784890164267460369534045305976733489576200", "price": "0.421", "size": "47.5", "side": "BUY", "hash": "5e6ae4b406d6d6b383a060566e638128cdf94acf", "best_bid": "0.43", "best_ask": "0.44"}, {"asset_id": "7064893400396467616058037848568819292052255869002775709074859726119346714372", "price": "0.579", "size": "47.5", "side": "SELL", "hash": "b45aa7235a06207dcfc346eab7b31fe9e79d260c", "best_bid": "0.56", "best_ask": "0.57"}], "timestamp": "1769384449151", "event_type": "price_change"}}
{"_local_timestamp": "2026-01-25T23:40:49.333756+00:00", "data": {"market": "0x0e34be3ee9cb4203fae20b289dfc9a9370f0045ab3fb2e1fa4e6fb82596c678f", "price_changes": [{"asset_id": "12727775089212363162508241557815769734691893483170358591167365904671830747608", "price": "0.52", "size": "110", "side": "BUY", "hash": "d934e66eea33713e4f5c64f514080cd1650ad62f", "best_bid": "0.55", "best_ask": "0.57"}, {"asset_id": "115183429975003994986742111804963130302445062562951748575181862773257927283380", "price": "0.48", "size": "110", "side": "SELL", "hash": "4fcf17e74406d5640ddd26e589c56662eba4691b", "best_bid": "0.43", "best_ask": "0.45"}], "timestamp": "1769384449264", "event_type": "price_change"}}
{"_local_timestamp": "2026-01-25T23:40:49.890647+00:00", "data": {"market": "0x0e34be3ee9cb4203fae20b289dfc9a9370f0045ab3fb2e1fa4e6fb82596c678f", "price_changes": [{"asset_id": "12727775089212363162508241557815769734691893483170358591167365904671830747608", "price": "0.53", "size": "742", "side": "BUY", "hash": "067136e638c6458fb5b3ce4379159ef2e48159b4", "best_bid": "0.55", "best_ask": "0.57"}, {"asset_id": "115183429975003994986742111804963130302445062562951748575181862773257927283380", "price": "0.47", "size": "742", "side": "SELL", "hash": "51b205b10e10cf3613623896e30cda46559b09d2", "best_bid": "0.43", "best_ask": "0.45"}], "timestamp": "1769384449813", "event_type": "price_change"}}
{"_local_timestamp": "2026-01-25T23:40:50.780203+00:00", "data": {"market": "0x0e34be3ee9cb4203fae20b289dfc9a9370f0045ab3fb2e1fa4e6fb82596c678f", "price_changes": [{"asset_id": "12727775089212363162508241557815769734691893483170358591167365904671830747608", "price": "0.55", "size": "545", "side": "BUY", "hash": "9bb46e224da0a8ef273376952ab1f8ac0d23647d", "best_bid": "0.55", "best_ask": "0.57"}, {"asset_id": "115183429975003994986742111804963130302445062562951748575181862773257927283380", "price": "0.45", "size": "545", "side": "SELL", "hash": "f27fafa40dced65684ce17fa0a98ec06f95f14db", "best_bid": "0.43", "best_ask": "0.45"}], "timestamp": "1769384450708", "event_type": "price_change"}}
{"_local_timestamp": "2026-01-25T23:40:50.780597+00:00", "data": {"market": "0xcda8a657998ef072e1d9edd83ce60ada3e75fc4d9113bc3f32a343a93fb1c927", "price_changes": [{"asset_id": "7064893400396467616058037848568819292052255869002775709074859726119346714372", "price": "0.54", "size": "40", "side": "BUY", "hash": "42b602773aeb6c6937d102cd2ac2669e4a5f786d", "best_bid": "0.56", "best_ask": "0.57"}, {"asset_id": "79200508610612497735268197792255474784890164267460369534045305976733489576200", "price": "0.46", "size": "40", "side": "SELL", "hash": "2d6706c87717e00b8f5465c784f54614274ec1bb", "best_bid": "0.43", "best_ask": "0.44"}], "timestamp": "1769384450708", "event_type": "price_change"}}
{"_local_timestamp": "2026-01-25T23:40:50.780906+00:00", "data": {"market": "0x0e34be3ee9cb4203fae20b289dfc9a9370f0045ab3fb2e1fa4e6fb82596c678f", "price_changes": [{"asset_id": "12727775089212363162508241557815769734691893483170358591167365904671830747608", "price": "0.54", "size": "60", "side": "BUY", "hash": "1e01f0255ae755d861222a57f1891719b50bb50d", "best_bid": "0.55", "best_ask": "0.57"}, {"asset_id": "115183429975003994986742111804963130302445062562951748575181862773257927283380", "price": "0.46", "size": "60", "side": "SELL", "hash": "f4fa16c176f9ba8ba96ab9a3b94c261f56606c98", "best_bid": "0.43", "best_ask": "0.45"}], "timestamp": "1769384450709", "event_type": "price_change"}}
{"_local_timestamp": "2026-01-25T23:40:53.070896+00:00", "data": {"market": "0x0e34be3ee9cb4203fae20b289dfc9a9370f0045ab3fb2e1fa4e6fb82596c678f", "price_changes": [{"asset_id": "12727775089212363162508241557815769734691893483170358591167365904671830747608", "price": "0.52", "size": "8714", "side": "BUY", "hash": "9a93b01c1dd085f9b58dc23009cc3e8af75a347f", "best_bid": "0.55", "best_ask": "0.57"}, {"asset_id": "115183429975003994986742111804963130302445062562951748575181862773257927283380", "price": "0.48", "size": "8714", "side": "SELL", "hash": "528693966f22c8c94aeffb473d10c1e958c11120", "best_bid": "0.43", "best_ask": "0.45"}], "timestamp": "1769384452992", "event_type": "price_change"}}
{"_local_timestamp": "2026-01-25T23:40:53.071770+00:00", "data": {"market": "0x0e34be3ee9cb4203fae20b289dfc9a9370f0045ab3fb2e1fa4e6fb82596c678f", "price_changes": [{"asset_id": "115183429975003994986742111804963130302445062562951748575181862773257927283380", "price": "0.41", "size": "9703", "side": "BUY", "hash": "8e87e0c23b2eee81579e40e281a52c2686eb7d67", "best_bid": "0.43", "best_ask": "0.45"}, {"asset_id": "12727775089212363162508241557815769734691893483170358591167365904671830747608", "price": "0.59", "size": "9703", "side": "SELL", "hash": "cb1adcdd685f8750cc5a7ed5e71097e7829d5a91", "best_bid": "0.55", "best_ask": "0.57"}], "timestamp": "1769384452996", "event_type": "price_change"}}
{"_local_timestamp": "2026-01-25T23:40:53.072541+00:00", "data": {"market": "0x0e34be3ee9cb4203fae20b289dfc9a9370f0045ab3fb2e1fa4e6fb82596c678f", "price_changes": [{"asset_id": "115183429975003994986742111804963130302445062562951748575181862773257927283380", "price": "0.48", "size": "9184", "side": "SELL", "hash": "7dec1300f54d5dcdddd9ab3bcc581f61b058e49c", "best_bid": "0.43", "best_ask": "0.45"}, {"asset_id": "12727775089212363162508241557815769734691893483170358591167365904671830747608", "price": "0.52", "size": "9184", "side": "BUY", "hash": "230080728f43c083a24616f8ec8c85eec424a3ca", "best_bid": "0.55", "best_ask": "0.57"}], "timestamp": "1769384452996", "event_type": "price_change"}}
{"_local_timestamp": "2026-01-25T23:40:53.107553+00:00", "data": {"market": "0x0e34be3ee9cb4203fae20b289dfc9a9370f0045ab3fb2e1fa4e6fb82596c678f", "price_changes": [{"asset_id": "12727775089212363162508241557815769734691893483170358591167365904671830747608", "price": "0.57", "size": "118", "side": "SELL", "hash": "43624cffb254e31274dad2a881cc14965a8e6140", "best_bid": "0.55", "best_ask": "0.57"}, {"asset_id": "115183429975003994986742111804963130302445062562951748575181862773257927283380", "price": "0.43", "size": "118", "side": "BUY", "hash": "60f53dd89c612750375e35203168bd41f9a203b6", "best_bid": "0.43", "best_ask": "0.45"}], "timestamp": "1769384453036", "event_type": "price_change"}}
{"_local_timestamp": "2026-01-25T23:40:53.171229+00:00", "data": {"market": "0xcda8a657998ef072e1d9edd83ce60ada3e75fc4d9113bc3f32a343a93fb1c927", "price_changes": [{"asset_id": "79200508610612497735268197792255474784890164267460369534045305976733489576200", "price": "0.429", "size": "103", "side": "BUY", "hash": "adc2c4b124ae4777b18cab90814310490af6bae9", "best_bid": "0.43", "best_ask": "0.44"}, {"asset_id": "7064893400396467616058037848568819292052255869002775709074859726119346714372", "price": "0.571", "size": "103", "side": "SELL", "hash": "f330397d8a2c2316ae9f0172eaa4e2f6077ca398", "best_bid": "0.56", "best_ask": "0.57"}], "timestamp": "1769384453064", "event_type": "price_change"}}
{"_local_timestamp": "2026-01-25T23:40:53.239029+00:00", "data": {"market": "0x0e34be3ee9cb4203fae20b289dfc9a9370f0045ab3fb2e1fa4e6fb82596c678f", "price_changes": [{"asset_id": "12727775089212363162508241557815769734691893483170358591167365904671830747608", "price": "0.07", "size": "900", "side": "BUY", "hash": "b4b2a55c1aaf4c7a2779c97ff9237f964ebb96a7", "best_bid": "0.55", "best_ask": "0.57"}, {"asset_id": "115183429975003994986742111804963130302445062562951748575181862773257927283380", "price": "0.93", "size": "900", "side": "SELL", "hash": "69fc037e9ba11a909199091b2a4e0b14cabbd9b3", "best_bid": "0.43", "best_ask": "0.45"}], "timestamp": "1769384453164", "event_type": "price_change"}}
{"_local_timestamp": "2026-01-25T23:40:53.263083+00:00", "data": {"market": "0xcda8a657998ef072e1d9edd83ce60ada3e75fc4d9113bc3f32a343a93fb1c927", "price_changes": [{"asset_id": "79200508610612497735268197792255474784890164267460369534045305976733489576200", "price": "0.429", "size": "0", "side": "BUY", "hash": "3956ea9009d67f3ed0f0a0d50158348b81522be5", "best_bid": "0.43", "best_ask": "0.44"}, {"asset_id": "7064893400396467616058037848568819292052255869002775709074859726119346714372", "price": "0.571", "size": "0", "side": "SELL", "hash": "87b09a6659c2318d4406de2503ea9d50fa149621", "best_bid": "0.56", "best_ask": "0.57"}], "timestamp": "1769384453194", "event_type": "price_change"}}
{"_local_timestamp": "2026-01-25T23:40:53.399839+00:00", "data": {"market": "0xcda8a657998ef072e1d9edd83ce60ada3e75fc4d9113bc3f32a343a93fb1c927", "price_changes": [{"asset_id": "79200508610612497735268197792255474784890164267460369534045305976733489576200", "price": "0.429", "size": "118", "side": "BUY", "hash": "9a55374ed5ef2c66d412307c54914959b146e982", "best_bid": "0.43", "best_ask": "0.44"}, {"asset_id": "7064893400396467616058037848568819292052255869002775709074859726119346714372", "price": "0.571", "size": "118", "side": "SELL", "hash": "0d0fc3f83d5c17f8b783974869d32d4a9c7e13dc", "best_bid": "0.56", "best_ask": "0.57"}], "timestamp": "1769384453330", "event_type": "price_change"}}
{"_local_timestamp": "2026-01-25T23:40:53.686202+00:00", "data": {"market": "0x0e34be3ee9cb4203fae20b289dfc9a9370f0045ab3fb2e1fa4e6fb82596c678f", "price_changes": [{"asset_id": "12727775089212363162508241557815769734691893483170358591167365904671830747608", "price": "0.53", "size": "642", "side": "BUY", "hash": "ef43edb23090cccaa51b242b6bf02ed7156e65ff", "best_bid": "0.55", "best_ask": "0.57"}, {"asset_id": "115183429975003994986742111804963130302445062562951748575181862773257927283380", "price": "0.47", "size": "642", "side": "SELL", "hash": "83b0feaca4e45bb9e005b66c5b816f9c5bd30ca9", "best_bid": "0.43", "best_ask": "0.45"}], "timestamp": "1769384453620", "event_type": "price_change"}}
{"_local_timestamp": "2026-01-25T23:40:53.762187+00:00", "data": {"market": "0x0e34be3ee9cb4203fae20b289dfc9a9370f0045ab3fb2e1fa4e6fb82596c678f", "price_changes": [{"asset_id": "12727775089212363162508241557815769734691893483170358591167365904671830747608", "price": "0.54", "size": "160", "side": "BUY", "hash": "a26e7e9ab5a51752d6ffcb2d60f4521975346dc7", "best_bid": "0.55", "best_ask": "0.57"}, {"asset_id": "115183429975003994986742111804963130302445062562951748575181862773257927283380", "price": "0.46", "size": "160", "side": "SELL", "hash": "edb57cfa79d85819bcaa6626037b518121680e4b", "best_bid": "0.43", "best_ask": "0.45"}], "timestamp": "1769384453695", "event_type": "price_change"}}
{"_local_timestamp": "2026-01-25T23:40:55.118080+00:00", "data": {"market": "0xcda8a657998ef072e1d9edd83ce60ada3e75fc4d9113bc3f32a343a93fb1c927", "price_changes": [{"asset_id": "7064893400396467616058037848568819292052255869002775709074859726119346714372", "price": "0.527", "size": "10537", "side": "BUY", "hash": "2ec9237fab78df51a317b418e46970683ad042a6", "best_bid": "0.56", "best_ask": "0.57"}, {"asset_id": "79200508610612497735268197792255474784890164267460369534045305976733489576200", "price": "0.473", "size": "10537", "side": "SELL", "hash": "5709db3530fc1936381364942a04072666c8c78c", "best_bid": "0.43", "best_ask": "0.44"}], "timestamp": "1769384455027", "event_type": "price_change"}}
{"_local_timestamp": "2026-01-25T23:40:55.118555+00:00", "data": {"market": "0xcda8a657998ef072e1d9edd83ce60ada3e75fc4d9113bc3f32a343a93fb1c927", "price_changes": [{"asset_id": "79200508610612497735268197792255474784890164267460369534045305976733489576200", "price": "0.417", "size": "6342", "side": "BUY", "hash": "73b34944d3279cde314bcde8a86555616cdc1f41", "best_bid": "0.43", "best_ask": "0.44"}, {"asset_id": "7064893400396467616058037848568819292052255869002775709074859726119346714372", "price": "0.583", "size": "6342", "side": "SELL", "hash": "5c48ae47c6f82b15dc4360b6695c8c54eb9221ff", "best_bid": "0.56", "best_ask": "0.57"}], "timestamp": "1769384455033", "event_type": "price_change"}}
{"_local_timestamp": "2026-01-25T23:40:55.118831+00:00", "data": {"market": "0xcda8a657998ef072e1d9edd83ce60ada3e75fc4d9113bc3f32a343a93fb1c927", "price_changes": [{"asset_id": "7064893400396467616058037848568819292052255869002775709074859726119346714372", "price": "0.583", "size": "11239", "side": "SELL", "hash": "b21f17f04ad29184b9ddca892f4b472c0520116f", "best_bid": "0.56", "best_ask": "0.57"}, {"asset_id": "79200508610612497735268197792255474784890164267460369534045305976733489576200", "price": "0.417", "size": "11239", "side": "BUY", "hash": "dca1d8cf66dc5c14f1f567e982364089b01deb91", "best_bid": "0.43", "best_ask": "0.44"}], "timestamp": "1769384455036", "event_type": "price_change"}}
{"_local_timestamp": "2026-01-25T23:40:55.218562+00:00", "data": {"market": "0x0e34be3ee9cb4203fae20b289dfc9a9370f0045ab3fb2e1fa4e6fb82596c678f", "price_changes": [{"asset_id": "12727775089212363162508241557815769734691893483170358591167365904671830747608", "price": "0.52", "size": "9189", "side": "BUY", "hash": "2cf6352c884ed6095f14dde4c6269f5882da6eeb", "best_bid": "0.55", "best_ask": "0.57"}, {"asset_id": "115183429975003994986742111804963130302445062562951748575181862773257927283380", "price": "0.48", "size": "9189", "side": "SELL", "hash": "1b6d96438be8ea9b0797b3879a47372577880081", "best_bid": "0.43", "best_ask": "0.45"}], "timestamp": "1769384455153", "event_type": "price_change"}}
{"_local_timestamp": "2026-01-25T23:40:55.302297+00:00", "data": {"market": "0x0e34be3ee9cb4203fae20b289dfc9a9370f0045ab3fb2e1fa4e6fb82596c678f", "price_changes": [{"asset_id": "12727775089212363162508241557815769734691893483170358591167365904671830747608", "price": "0.07", "size": "910", "side": "BUY", "hash": "6812c44a2621ee45c8892c5dfafcf25c58374b64", "best_bid": "0.55", "best_ask": "0.57"}, {"asset_id": "115183429975003994986742111804963130302445062562951748575181862773257927283380", "price": "0.93", "size": "910", "side": "SELL", "hash": "cf54d9e39bbf0da3824d17e928c69c515f93b143", "best_bid": "0.43", "best_ask": "0.45"}], "timestamp": "1769384455230", "event_type": "price_change"}}
{"_local_timestamp": "2026-01-25T23:40:55.345677+00:00", "data": {"market": "0xcda8a657998ef072e1d9edd83ce60ada3e75fc4d9113bc3f32a343a93fb1c927", "price_changes": [{"asset_id": "79200508610612497735268197792255474784890164267460369534045305976733489576200", "price": "0.431", "size": "30", "side": "BUY", "hash": "afe6ce3071b7516111fe2e3379b9fd8e714be618", "best_bid": "0.431", "best_ask": "0.44"}, {"asset_id": "7064893400396467616058037848568819292052255869002775709074859726119346714372", "price": "0.569", "size": "30", "side": "SELL", "hash": "492b53fecfb5320fa5d1bf88fad9fff8594d6325", "best_bid": "0.56", "best_ask": "0.569"}], "timestamp": "1769384455273", "event_type": "price_change"}}
{"_local_timestamp": "2026-01-25T23:40:55.743031+00:00", "data": {"market": "0xcda8a657998ef072e1d9edd83ce60ada3e75fc4d9113bc3f32a343a93fb1c927", "price_changes": [{"asset_id": "79200508610612497735268197792255474784890164267460369534045305976733489576200", "price": "0.421", "size": "0", "side": "BUY", "hash": "632708e06fed611901536c92d71614d8f628a115", "best_bid": "0.431", "best_ask": "0.44"}, {"asset_id": "7064893400396467616058037848568819292052255869002775709074859726119346714372", "price": "0.579", "size": "0", "side": "SELL", "hash": "ba8a332ed54d2599d3f3514caece606e0a6c4ebb", "best_bid": "0.56", "best_ask": "0.569"}], "timestamp": "1769384455670", "event_type": "price_change"}}
{"_local_timestamp": "2026-01-25T23:40:56.246128+00:00", "data": {"market": "0x0e34be3ee9cb4203fae20b289dfc9a9370f0045ab3fb2e1fa4e6fb82596c678f", "price_changes": [{"asset_id": "115183429975003994986742111804963130302445062562951748575181862773257927283380", "price": "0.42", "size": "2147.61", "side": "BUY", "hash": "66bc2df4647b80b4565c1d3aa79290d25cac61e0", "best_bid": "0.43", "best_ask": "0.45"}, {"asset_id": "12727775089212363162508241557815769734691893483170358591167365904671830747608", "price": "0.58", "size": "2147.61", "side": "SELL", "hash": "b9d996ef6348fa3cf94b590d30dceeae97f839db", "best_bid": "0.55", "best_ask": "0.57"}], "timestamp": "1769384456175", "event_type": "price_change"}}
{"_local_timestamp": "2026-01-25T23:40:58.933217+00:00", "data": {"market": "0x0e34be3ee9cb4203fae20b289dfc9a9370f0045ab3fb2e1fa4e6fb82596c678f", "price_changes": [{"asset_id": "115183429975003994986742111804963130302445062562951748575181862773257927283380", "price": "0.41", "size": "9503", "side": "BUY", "hash": "d922aca52a220a905357d083d6dcd58577351036", "best_bid": "0.43", "best_ask": "0.45"}, {"asset_id": "12727775089212363162508241557815769734691893483170358591167365904671830747608", "price": "0.59", "size": "9503", "side": "SELL", "hash": "8d1fd2d4a081f3dbe47d966da2ce994f27fb8b56", "best_bid": "0.55", "best_ask": "0.57"}], "timestamp": "1769384458857", "event_type": "price_change"}}
{"_local_timestamp": "2026-01-25T23:40:58.960339+00:00", "data": {"market": "0x0e34be3ee9cb4203fae20b289dfc9a9370f0045ab3fb2e1fa4e6fb82596c678f", "price_changes": [{"asset_id": "115183429975003994986742111804963130302445062562951748575181862773257927283380", "price": "0.41", "size": "9703", "side": "BUY", "hash": "89f9e40334d8c38cc9606254d372c7ebac114bad", "best_bid": "0.43", "best_ask": "0.45"}, {"asset_id": "12727775089212363162508241557815769734691893483170358591167365904671830747608", "price": "0.59", "size": "9703", "side": "SELL", "hash": "18cb8e78e13779666c3f7076c6d47b0fd84cd357", "best_bid": "0.55", "best_ask": "0.57"}], "timestamp": "1769384458893", "event_type": "price_change"}}
{"_local_timestamp": "2026-01-25T23:40:59.611764+00:00", "data": {"market": "0x0e34be3ee9cb4203fae20b289dfc9a9370f0045ab3fb2e1fa4e6fb82596c678f", "price_changes": [{"asset_id": "12727775089212363162508241557815769734691893483170358591167365904671830747608", "price": "0.55", "size": "345", "side": "BUY", "hash": "1bc3b2e526f6188a928db0c2082a22d7cabe89ba", "best_bid": "0.55", "best_ask": "0.57"}, {"asset_id": "115183429975003994986742111804963130302445062562951748575181862773257927283380", "price": "0.45", "size": "345", "side": "SELL", "hash": "80a0af555be97414434a5779a7db954e08264224", "best_bid": "0.43", "best_ask": "0.45"}], "timestamp": "1769384459546", "event_type": "price_change"}}
{"_local_timestamp": "2026-01-25T23:40:59.649434+00:00", "data": {"market": "0x0e34be3ee9cb4203fae20b289dfc9a9370f0045ab3fb2e1fa4e6fb82596c678f", "price_changes": [{"asset_id": "12727775089212363162508241557815769734691893483170358591167365904671830747608", "price": "0.55", "size": "545", "side": "BUY", "hash": "8079d554670b5720f22149c42f7c90d06d24b996", "best_bid": "0.55", "best_ask": "0.57"}, {"asset_id": "115183429975003994986742111804963130302445062562951748575181862773257927283380", "price": "0.45", "size": "545", "side": "SELL", "hash": "e45b6eca4f1fb0433e6b0928dc1fbcb1cdc3bbd2", "best_bid": "0.43", "best_ask": "0.45"}], "timestamp": "1769384459580", "event_type": "price_change"}}
{"_local_timestamp": "2026-01-25T23:41:02.860770+00:00", "data": {"market": "0x0e34be3ee9cb4203fae20b289dfc9a9370f0045ab3fb2e1fa4e6fb82596c678f", "price_changes": [{"asset_id": "12727775089212363162508241557815769734691893483170358591167365904671830747608", "price": "0.53", "size": "742", "side": "BUY", "hash": "f3496067236c55cfdb5d19b97d4852bcc05ea32b", "best_bid": "0.55", "best_ask": "0.57"}, {"asset_id": "115183429975003994986742111804963130302445062562951748575181862773257927283380", "price": "0.47", "size": "742", "side": "SELL", "hash": "6e7caebdf2e398c2dbca20ab314c57abfd311c0b", "best_bid": "0.43", "best_ask": "0.45"}], "timestamp": "1769384462780", "event_type": "price_change"}}
{"_local_timestamp": "2026-01-25T23:41:06.346228+00:00", "data": {"market": "0xcda8a657998ef072e1d9edd83ce60ada3e75fc4d9113bc3f32a343a93fb1c927", "price_changes": [{"asset_id": "7064893400396467616058037848568819292052255869002775709074859726119346714372", "price": "0.14", "size": "0", "side": "BUY", "hash": "7ee8f1b171f522c3b293cfd03fa1ea6e0bd22ecf", "best_bid": "0.56", "best_ask": "0.569"}, {"asset_id": "79200508610612497735268197792255474784890164267460369534045305976733489576200", "price": "0.86", "size": "0", "side": "SELL", "hash": "e7a9269aac055fdd318a3b2e4a784d28967f02f6", "best_bid": "0.431", "best_ask": "0.44"}], "timestamp": "1769384466258", "event_type": "price_change"}}
{"_local_timestamp": "2026-01-25T23:41:06.347219+00:00", "data": {"market": "0xcda8a657998ef072e1d9edd83ce60ada3e75fc4d9113bc3f32a343a93fb1c927", "price_changes": [{"asset_id": "7064893400396467616058037848568819292052255869002775709074859726119346714372", "price": "0.03", "size": "0", "side": "BUY", "hash": "7ee8f1b171f522c3b293cfd03fa1ea6e0bd22ecf", "best_bid": "0.56", "best_ask": "0.569"}, {"asset_id": "79200508610612497735268197792255474784890164267460369534045305976733489576200", "price": "0.97", "size": "0", "side": "SELL", "hash": "e7a9269aac055fdd318a3b2e4a784d28967f02f6", "best_bid": "0.431", "best_ask": "0.44"}], "timestamp": "1769384466258", "event_type": "price_change"}}
{"_local_timestamp": "2026-01-25T23:41:06.354942+00:00", "data": {"market": "0xcda8a657998ef072e1d9edd83ce60ada3e75fc4d9113bc3f32a343a93fb1c927", "price_changes": [{"asset_id": "7064893400396467616058037848568819292052255869002775709074859726119346714372", "price": "0.103", "size": "4376", "side": "BUY", "hash": "7ee8f1b171f522c3b293cfd03fa1ea6e0bd22ecf", "best_bid": "0.56", "best_ask": "0.569"}, {"asset_id": "79200508610612497735268197792255474784890164267460369534045305976733489576200", "price": "0.897", "size": "4376", "side": "SELL", "hash": "e7a9269aac055fdd318a3b2e4a784d28967f02f6", "best_bid": "0.431", "best_ask": "0.44"}], "timestamp": "1769384466258", "event_type": "price_change"}}
{"_local_timestamp": "2026-01-25T23:41:07.865351+00:00", "data": {"market": "0xcda8a657998ef072e1d9edd83ce60ada3e75fc4d9113bc3f32a343a93fb1c927", "price_changes": [{"asset_id": "7064893400396467616058037848568819292052255869002775709074859726119346714372", "price": "0.011", "size": "0", "side": "BUY", "hash": "957a357bf8a913b192db56d10a7696d667546992", "best_bid": "0.56", "best_ask": "0.569"}, {"asset_id": "79200508610612497735268197792255474784890164267460369534045305976733489576200", "price": "0.989", "size": "0", "side": "SELL", "hash": "d08a53843d4331355e22479e9da8be14bd1e903e", "best_bid": "0.431", "best_ask": "0.44"}], "timestamp": "1769384467793", "event_type": "price_change"}}
{"_local_timestamp": "2026-01-25T23:41:07.866997+00:00", "data": {"market": "0xcda8a657998ef072e1d9edd83ce60ada3e75fc4d9113bc3f32a343a93fb1c927", "price_changes": [{"asset_id": "7064893400396467616058037848568819292052255869002775709074859726119346714372", "price": "0.031", "size": "0", "side": "BUY", "hash": "957a357bf8a913b192db56d10a7696d667546992", "best_bid": "0.56", "best_ask": "0.569"}, {"asset_id": "79200508610612497735268197792255474784890164267460369534045305976733489576200", "price": "0.969", "size": "0", "side": "SELL", "hash": "d08a53843d4331355e22479e9da8be14bd1e903e", "best_bid": "0.431", "best_ask": "0.44"}], "timestamp": "1769384467793", "event_type": "price_change"}}
{"_local_timestamp": "2026-01-25T23:41:11.191900+00:00", "data": {"market": "0xcda8a657998ef072e1d9edd83ce60ada3e75fc4d9113bc3f32a343a93fb1c927", "price_changes": [{"asset_id": "7064893400396467616058037848568819292052255869002775709074859726119346714372", "price": "0.004", "size": "23.9", "side": "BUY", "hash": "c9e5e87de665dbb50738ab314a7ab6ad22f72e29", "best_bid": "0.56", "best_ask": "0.569"}, {"asset_id": "79200508610612497735268197792255474784890164267460369534045305976733489576200", "price": "0.996", "size": "23.9", "side": "SELL", "hash": "4ddbbc95a4567dd4239c462a7fc484ae39d4a242", "best_bid": "0.431", "best_ask": "0.44"}], "timestamp": "1769384471039", "event_type": "price_change"}}
{"_local_timestamp": "2026-01-25T23:41:11.192837+00:00", "data": {"market": "0xcda8a657998ef072e1d9edd83ce60ada3e75fc4d9113bc3f32a343a93fb1c927", "price_changes": [{"asset_id": "7064893400396467616058037848568819292052255869002775709074859726119346714372", "price": "0.032", "size": "8.02", "side": "BUY", "hash": "4a0b093880c5845026e99505b63b37d1b4409a61", "best_bid": "0.56", "best_ask": "0.569"}, {"asset_id": "79200508610612497735268197792255474784890164267460369534045305976733489576200", "price": "0.968", "size": "8.02", "side": "SELL", "hash": "39a36a416d623568142fa3861eb53985b07738bf", "best_bid": "0.431", "best_ask": "0.44"}], "timestamp": "1769384471045", "event_type": "price_change"}}
{"_local_timestamp": "2026-01-25T23:41:14.857674+00:00", "data": {"market": "0xcda8a657998ef072e1d9edd83ce60ada3e75fc4d9113bc3f32a343a93fb1c927", "price_changes": [{"asset_id": "79200508610612497735268197792255474784890164267460369534045305976733489576200", "price": "0.439", "size": "25", "side": "SELL", "hash": "9dfde2c1342288118883995d4b6030635dac8a37", "best_bid": "0.431", "best_ask": "0.439"}, {"asset_id": "7064893400396467616058037848568819292052255869002775709074859726119346714372", "price": "0.561", "size": "25", "side": "BUY", "hash": "dcaf59ead2b792c6229f306882eba4a9a9452063", "best_bid": "0.561", "best_ask": "0.569"}], "timestamp": "1769384474698", "event_type": "price_change"}}
{"_local_timestamp": "2026-01-25T23:41:14.924627+00:00", "data": {"market": "0x0e34be3ee9cb4203fae20b289dfc9a9370f0045ab3fb2e1fa4e6fb82596c678f", "price_changes": [{"asset_id": "12727775089212363162508241557815769734691893483170358591167365904671830747608", "price": "0.55", "size": "645", "side": "BUY", "hash": "7adaeaea47d97eca00c2d0ad0f61917ca9d25c83", "best_bid": "0.55", "best_ask": "0.57"}, {"asset_id": "115183429975003994986742111804963130302445062562951748575181862773257927283380", "price": "0.45", "size": "645", "side": "SELL", "hash": "b5e2d7fd0c110eca7a5de5d3f1cc24c3a1561f61", "best_bid": "0.43", "best_ask": "0.45"}], "timestamp": "1769384474785", "event_type": "price_change"}}
{"_local_timestamp": "2026-01-25T23:41:14.949136+00:00", "data": {"market": "0x0e34be3ee9cb4203fae20b289dfc9a9370f0045ab3fb2e1fa4e6fb82596c678f", "price_changes": [{"asset_id": "12727775089212363162508241557815769734691893483170358591167365904671830747608", "price": "0.55", "size": "445", "side": "BUY", "hash": "b8d09edd219106b9193236100a99a576b839faa2", "best_bid": "0.55", "best_ask": "0.57"}, {"asset_id": "115183429975003994986742111804963130302445062562951748575181862773257927283380", "price": "0.45", "size": "445", "side": "SELL", "hash": "9015abfc3b01407bc77ee25079622ef5825e134e", "best_bid": "0.43", "best_ask": "0.45"}], "timestamp": "1769384474830", "event_type": "price_change"}}
{"_local_timestamp": "2026-01-25T23:41:15.021397+00:00", "data": {"market": "0x0e34be3ee9cb4203fae20b289dfc9a9370f0045ab3fb2e1fa4e6fb82596c678f", "price_changes": [{"asset_id": "12727775089212363162508241557815769734691893483170358591167365904671830747608", "price": "0.55", "size": "470", "side": "BUY", "hash": "ce62084d6b41a8bd70474bedf4f5bf798c15c87b", "best_bid": "0.55", "best_ask": "0.57"}, {"asset_id": "115183429975003994986742111804963130302445062562951748575181862773257927283380", "price": "0.45", "size": "470", "side": "SELL", "hash": "8a03f68739bba2ab3620438ad77180367d6f4bc1", "best_bid": "0.43", "best_ask": "0.45"}], "timestamp": "1769384474930", "event_type": "price_change"}}
{"_local_timestamp": "2026-01-25T23:41:17.011160+00:00", "data": {"market": "0x0e34be3ee9cb4203fae20b289dfc9a9370f0045ab3fb2e1fa4e6fb82596c678f", "price_changes": [{"asset_id": "115183429975003994986742111804963130302445062562951748575181862773257927283380", "price": "0.47", "size": "787.45", "side": "SELL", "hash": "bc09b786ebb615df972982d10a31cb60185327f5", "best_bid": "0.43", "best_ask": "0.45"}, {"asset_id": "12727775089212363162508241557815769734691893483170358591167365904671830747608", "price": "0.53", "size": "787.45", "side": "BUY", "hash": "474b80fabb19dfa43b54c96ef41627932e8a3c7e", "best_bid": "0.55", "best_ask": "0.57"}], "timestamp": "1769384476886", "event_type": "price_change"}}
{"_local_timestamp": "2026-01-25T23:41:17.140168+00:00", "data": {"market": "0xcda8a657998ef072e1d9edd83ce60ada3e75fc4d9113bc3f32a343a93fb1c927", "price_changes": [{"asset_id": "79200508610612497735268197792255474784890164267460369534045305976733489576200", "price": "0.421", "size": "47.5", "side": "BUY", "hash": "08b4dd05cf469fee79bc20a1cc6b6ee119986b53", "best_bid": "0.431", "best_ask": "0.439"}, {"asset_id": "7064893400396467616058037848568819292052255869002775709074859726119346714372", "price": "0.579", "size": "47.5", "side": "SELL", "hash": "5b930f9fbbaa98df734ac0af95cc9080a012918a", "best_bid": "0.561", "best_ask": "0.569"}], "timestamp": "1769384477006", "event_type": "price_change"}}
{"_local_timestamp": "2026-01-25T23:41:17.241446+00:00", "data": {"market": "0xcda8a657998ef072e1d9edd83ce60ada3e75fc4d9113bc3f32a343a93fb1c927", "price_changes": [{"asset_id": "79200508610612497735268197792255474784890164267460369534045305976733489576200", "price": "0.4", "size": "1209", "side": "BUY", "hash": "414242259da6f26f542738ad13da4a2f90f5f86e", "best_bid": "0.431", "best_ask": "0.439"}, {"asset_id": "7064893400396467616058037848568819292052255869002775709074859726119346714372", "price": "0.6", "size": "1209", "side": "SELL", "hash": "1814b857ef41849d9c3722cb0a3c5d442ff7bcdc", "best_bid": "0.561", "best_ask": "0.569"}], "timestamp": "1769384477118", "event_type": "price_change"}}
{"_local_timestamp": "2026-01-25T23:41:17.269142+00:00", "data": {"market": "0xcda8a657998ef072e1d9edd83ce60ada3e75fc4d9113bc3f32a343a93fb1c927", "price_changes": [{"asset_id": "79200508610612497735268197792255474784890164267460369534045305976733489576200", "price": "0.4", "size": "1409", "side": "BUY", "hash": "2d24bf516bc744eba14ad9de3e665c1864e5cce5", "best_bid": "0.431", "best_ask": "0.439"}, {"asset_id": "7064893400396467616058037848568819292052255869002775709074859726119346714372", "price": "0.6", "size": "1409", "side": "SELL", "hash": "3d54dc2377dc60fdb8cda469b1a0d6195c4d7ebd", "best_bid": "0.561", "best_ask": "0.569"}], "timestamp": "1769384477150", "event_type": "price_change"}}
{"_local_timestamp": "2026-01-25T23:41:18.215707+00:00", "data": {"market": "0xcda8a657998ef072e1d9edd83ce60ada3e75fc4d9113bc3f32a343a93fb1c927", "price_changes": [{"asset_id": "79200508610612497735268197792255474784890164267460369534045305976733489576200", "price": "0.4", "size": "909", "side": "BUY", "hash": "204ddd9b774ea1488e033685737f0647629a63eb", "best_bid": "0.431", "best_ask": "0.439"}, {"asset_id": "7064893400396467616058037848568819292052255869002775709074859726119346714372", "price": "0.6", "size": "909", "side": "SELL", "hash": "f2e252948ca063960b9e5214c78d0a0bf0e81067", "best_bid": "0.561", "best_ask": "0.569"}], "timestamp": "1769384478072", "event_type": "price_change"}}
{"_local_timestamp": "2026-01-25T23:41:18.365464+00:00", "data": {"market": "0x0e34be3ee9cb4203fae20b289dfc9a9370f0045ab3fb2e1fa4e6fb82596c678f", "price_changes": [{"asset_id": "115183429975003994986742111804963130302445062562951748575181862773257927283380", "price": "0.42", "size": "1147.61", "side": "BUY", "hash": "ab6078cfe8f0a55a665f9869c2ff83d0faf9531e", "best_bid": "0.43", "best_ask": "0.45"}, {"asset_id": "12727775089212363162508241557815769734691893483170358591167365904671830747608", "price": "0.58", "size": "1147.61", "side": "SELL", "hash": "c5913770db634581bd05901c81a75bf5b9eab8ea", "best_bid": "0.55", "best_ask": "0.57"}], "timestamp": "1769384478215", "event_type": "price_change"}}
{"_local_timestamp": "2026-01-25T23:41:25.544424+00:00", "data": {"market": "0xcda8a657998ef072e1d9edd83ce60ada3e75fc4d9113bc3f32a343a93fb1c927", "price_changes": [{"asset_id": "79200508610612497735268197792255474784890164267460369534045305976733489576200", "price": "0.421", "size": "0", "side": "BUY", "hash": "b08472f4aed7240203067c5731633d8cd9ecd023", "best_bid": "0.431", "best_ask": "0.439"}, {"asset_id": "7064893400396467616058037848568819292052255869002775709074859726119346714372", "price": "0.579", "size": "0", "side": "SELL", "hash": "32c5a2c4fc0a8b85f5b20e9864f0c01ec3420d2b", "best_bid": "0.561", "best_ask": "0.569"}], "timestamp": "1769384485437", "event_type": "price_change"}}
{"_local_timestamp": "2026-01-25T23:41:25.635639+00:00", "data": {"market": "0xcda8a657998ef072e1d9edd83ce60ada3e75fc4d9113bc3f32a343a93fb1c927", "price_changes": [{"asset_id": "7064893400396467616058037848568819292052255869002775709074859726119346714372", "price": "0.14", "size": "50", "side": "BUY", "hash": "2757f9a79362d0bfbf5f305ccacdf74d36e93ac8", "best_bid": "0.561", "best_ask": "0.569"}, {"asset_id": "79200508610612497735268197792255474784890164267460369534045305976733489576200", "price": "0.86", "size": "50", "side": "SELL", "hash": "342fcbf44f3115c422882a530f20431266751f54", "best_bid": "0.431", "best_ask": "0.439"}], "timestamp": "1769384485539", "event_type": "price_change"}}
{"_local_timestamp": "2026-01-25T23:41:25.636529+00:00", "data": {"market": "0xcda8a657998ef072e1d9edd83ce60ada3e75fc4d9113bc3f32a343a93fb1c927", "price_changes": [{"asset_id": "7064893400396467616058037848568819292052255869002775709074859726119346714372", "price": "0.103", "size": "4476", "side": "BUY", "hash": "0eacd9bbcd888340cf432752de4c77e156f3a1ed", "best_bid": "0.561", "best_ask": "0.569"}, {"asset_id": "79200508610612497735268197792255474784890164267460369534045305976733489576200", "price": "0.897", "size": "4476", "side": "SELL", "hash": "17bca31b2e4cef36d91d2763c25731801d3fff1c", "best_bid": "0.431", "best_ask": "0.439"}], "timestamp": "1769384485540", "event_type": "price_change"}}
{"_local_timestamp": "2026-01-25T23:41:25.637542+00:00", "data": {"market": "0xcda8a657998ef072e1d9edd83ce60ada3e75fc4d9113bc3f32a343a93fb1c927", "price_changes": [{"asset_id": "7064893400396467616058037848568819292052255869002775709074859726119346714372", "price": "0.03", "size": "100", "side": "BUY", "hash": "de64102a002052a255aa3a3bfc87c7f206152ddd", "best_bid": "0.561", "best_ask": "0.569"}, {"asset_id": "79200508610612497735268197792255474784890164267460369534045305976733489576200", "price": "0.97", "size": "100", "side": "SELL", "hash": "3de8ffb4cea95a8c1d423a286ac9b0f5e64fec5b", "best_bid": "0.431", "best_ask": "0.439"}], "timestamp": "1769384485540", "event_type": "price_change"}}
{"_local_timestamp": "2026-01-25T23:41:26.245585+00:00", "data": {"market": "0x0e34be3ee9cb4203fae20b289dfc9a9370f0045ab3fb2e1fa4e6fb82596c678f", "price_changes": [{"asset_id": "115183429975003994986742111804963130302445062562951748575181862773257927283380", "price": "0.47", "size": "742", "side": "SELL", "hash": "314cc026b2d867aeea4f1fe35f8566d3e968977d", "best_bid": "0.43", "best_ask": "0.45"}, {"asset_id": "12727775089212363162508241557815769734691893483170358591167365904671830747608", "price": "0.53", "size": "742", "side": "BUY", "hash": "e6d9d214a7a65c2e90bd934124ea8abd2f31e6b6", "best_bid": "0.55", "best_ask": "0.57"}], "timestamp": "1769384486149", "event_type": "price_change"}}
{"_local_timestamp": "2026-01-25T23:41:33.134446+00:00", "data": {"market": "0xcda8a657998ef072e1d9edd83ce60ada3e75fc4d9113bc3f32a343a93fb1c927", "price_changes": [{"asset_id": "7064893400396467616058037848568819292052255869002775709074859726119346714372", "price": "0.56", "size": "0", "side": "BUY", "hash": "f9a5dfbe591d96f1fc60ea9ada1864681fd01bfa", "best_bid": "0.561", "best_ask": "0.569"}, {"asset_id": "79200508610612497735268197792255474784890164267460369534045305976733489576200", "price": "0.44", "size": "0", "side": "SELL", "hash": "a3a38defae3fa1ac48c2043460389ba246f587fe", "best_bid": "0.431", "best_ask": "0.439"}], "timestamp": "1769384492979", "event_type": "price_change"}}
{"_local_timestamp": "2026-01-25T23:41:33.183349+00:00", "data": {"market": "0x0e34be3ee9cb4203fae20b289dfc9a9370f0045ab3fb2e1fa4e6fb82596c678f", "price_changes": [{"asset_id": "12727775089212363162508241557815769734691893483170358591167365904671830747608", "price": "0.55", "size": "430", "side": "BUY", "hash": "a48b6447f9a7c24e8a1175ee4e78b505cc1ce2b1", "best_bid": "0.55", "best_ask": "0.57"}, {"asset_id": "115183429975003994986742111804963130302445062562951748575181862773257927283380", "price": "0.45", "size": "430", "side": "SELL", "hash": "9f196c62da22ed74b2983be5da26ca935b442315", "best_bid": "0.43", "best_ask": "0.45"}], "timestamp": "1769384493002", "event_type": "price_change"}}
{"_local_timestamp": "2026-01-25T23:41:33.188605+00:00", "data": {"market": "0x0e34be3ee9cb4203fae20b289dfc9a9370f0045ab3fb2e1fa4e6fb82596c678f", "price_changes": [{"asset_id": "12727775089212363162508241557815769734691893483170358591167365904671830747608", "price": "0.54", "size": "100", "side": "BUY", "hash": "02e64ce1a42a843b59ce080257abdde77fcf0c3a", "best_bid": "0.55", "best_ask": "0.57"}, {"asset_id": "115183429975003994986742111804963130302445062562951748575181862773257927283380", "price": "0.46", "size": "100", "side": "SELL", "hash": "efb265441341c9875fb19d3fb9b4a7b7d6b5dfe6", "best_bid": "0.43", "best_ask": "0.45"}], "timestamp": "1769384493004", "event_type": "price_change"}}
{"_local_timestamp": "2026-01-25T23:41:33.194070+00:00", "data": {"market": "0x0e34be3ee9cb4203fae20b289dfc9a9370f0045ab3fb2e1fa4e6fb82596c678f", "price_changes": [{"asset_id": "12727775089212363162508241557815769734691893483170358591167365904671830747608", "price": "0.55", "size": "330", "side": "BUY", "hash": "47d22ab3f92210cc8903090ecf4b087681f81d67", "best_bid": "0.55", "best_ask": "0.57"}, {"asset_id": "115183429975003994986742111804963130302445062562951748575181862773257927283380", "price": "0.45", "size": "330", "side": "SELL", "hash": "760b2152842e40f96096efa7348e14635d12dc30", "best_bid": "0.43", "best_ask": "0.45"}], "timestamp": "1769384493005", "event_type": "price_change"}}
{"_local_timestamp": "2026-01-25T23:41:33.195779+00:00", "data": {"market": "0xcda8a657998ef072e1d9edd83ce60ada3e75fc4d9113bc3f32a343a93fb1c927", "price_changes": [{"asset_id": "7064893400396467616058037848568819292052255869002775709074859726119346714372", "price": "0.56", "size": "200", "side": "BUY", "hash": "d177034dc9eb237bc63473f936f2494ad3e92b09", "best_bid": "0.561", "best_ask": "0.569"}, {"asset_id": "79200508610612497735268197792255474784890164267460369534045305976733489576200", "price": "0.44", "size": "200", "side": "SELL", "hash": "04dde91bcf7c99031817addeffb6af78db281289", "best_bid": "0.431", "best_ask": "0.439"}], "timestamp": "1769384493011", "event_type": "price_change"}}
{"_local_timestamp": "2026-01-25T23:41:33.234001+00:00", "data": {"market": "0x0e34be3ee9cb4203fae20b289dfc9a9370f0045ab3fb2e1fa4e6fb82596c678f", "price_changes": [{"asset_id": "12727775089212363162508241557815769734691893483170358591167365904671830747608", "price": "0.55", "size": "280", "side": "BUY", "hash": "1a8deecf7f44025f5a2c368c3c79875bf4e3bce0", "best_bid": "0.55", "best_ask": "0.57"}, {"asset_id": "115183429975003994986742111804963130302445062562951748575181862773257927283380", "price": "0.45", "size": "280", "side": "SELL", "hash": "2b58b0ce5f5afe72eec70223d1b3957082ce5797", "best_bid": "0.43", "best_ask": "0.45"}], "timestamp": "1769384493085", "event_type": "price_change"}}
{"_local_timestamp": "2026-01-25T23:41:33.234458+00:00", "data": {"market": "0x0e34be3ee9cb4203fae20b289dfc9a9370f0045ab3fb2e1fa4e6fb82596c678f", "price_changes": [{"asset_id": "12727775089212363162508241557815769734691893483170358591167365904671830747608", "price": "0.52", "size": "9239", "side": "BUY", "hash": "a62fe4dd39a716345f65a85c7d204401c071635d", "best_bid": "0.55", "best_ask": "0.57"}, {"asset_id": "115183429975003994986742111804963130302445062562951748575181862773257927283380", "price": "0.48", "size": "9239", "side": "SELL", "hash": "c6d27fe75a86473acd09eb1061fcce9b7a8d3edb", "best_bid": "0.43", "best_ask": "0.45"}], "timestamp": "1769384493090", "event_type": "price_change"}}
{"_local_timestamp": "2026-01-25T23:41:33.237105+00:00", "data": {"market": "0x0e34be3ee9cb4203fae20b289dfc9a9370f0045ab3fb2e1fa4e6fb82596c678f", "price_changes": [{"asset_id": "12727775089212363162508241557815769734691893483170358591167365904671830747608", "price": "0.52", "size": "9289", "side": "BUY", "hash": "3e8175668641b9dec96a645b0f6ab5483af1edb4", "best_bid": "0.55", "best_ask": "0.57"}, {"asset_id": "115183429975003994986742111804963130302445062562951748575181862773257927283380", "price": "0.48", "size": "9289", "side": "SELL", "hash": "babbec1169cb673b5cb7b0a931280e53d49937c1", "best_bid": "0.43", "best_ask": "0.45"}], "timestamp": "1769384493092", "event_type": "price_change"}}
{"_local_timestamp": "2026-01-25T23:41:33.237615+00:00", "data": {"market": "0x0e34be3ee9cb4203fae20b289dfc9a9370f0045ab3fb2e1fa4e6fb82596c678f", "price_changes": [{"asset_id": "12727775089212363162508241557815769734691893483170358591167365904671830747608", "price": "0.55", "size": "230", "side": "BUY", "hash": "4fb16a72f8fd33189ae09bbf44305a444ce52640", "best_bid": "0.55", "best_ask": "0.57"}, {"asset_id": "115183429975003994986742111804963130302445062562951748575181862773257927283380", "price": "0.45", "size": "230", "side": "SELL", "hash": "c5ac8fcee4649a98e2c3ffe8a8d459baa0dd69cd", "best_bid": "0.43", "best_ask": "0.45"}], "timestamp": "1769384493092", "event_type": "price_change"}}
{"_local_timestamp": "2026-01-25T23:41:33.285486+00:00", "data": {"market": "0x0e34be3ee9cb4203fae20b289dfc9a9370f0045ab3fb2e1fa4e6fb82596c678f", "price_changes": [{"asset_id": "12727775089212363162508241557815769734691893483170358591167365904671830747608", "price": "0.55", "size": "330", "side": "BUY", "hash": "29b33f61224108eac1a85d7721394258b99375f7", "best_bid": "0.55", "best_ask": "0.57"}, {"asset_id": "115183429975003994986742111804963130302445062562951748575181862773257927283380", "price": "0.45", "size": "330", "side": "SELL", "hash": "b747fc49feb6f76448fb1ccce6202fb786e19217", "best_bid": "0.43", "best_ask": "0.45"}], "timestamp": "1769384493136", "event_type": "price_change"}}
{"_local_timestamp": "2026-01-25T23:41:33.335948+00:00", "data": {"market": "0x0e34be3ee9cb4203fae20b289dfc9a9370f0045ab3fb2e1fa4e6fb82596c678f", "price_changes": [{"asset_id": "12727775089212363162508241557815769734691893483170358591167365904671830747608", "price": "0.54", "size": "0", "side": "BUY", "hash": "a3c88a692806dec5075b2927ba9f6cd9c6424ce3", "best_bid": "0.55", "best_ask": "0.57"}, {"asset_id": "115183429975003994986742111804963130302445062562951748575181862773257927283380", "price": "0.46", "size": "0", "side": "SELL", "hash": "19f7d320e32905c6a5e06a65e9aac383ac8f2e1b", "best_bid": "0.43", "best_ask": "0.45"}], "timestamp": "1769384493171", "event_type": "price_change"}}
{"_local_timestamp": "2026-01-25T23:41:33.336631+00:00", "data": {"market": "0x0e34be3ee9cb4203fae20b289dfc9a9370f0045ab3fb2e1fa4e6fb82596c678f", "price_changes": [{"asset_id": "12727775089212363162508241557815769734691893483170358591167365904671830747608", "price": "0.55", "size": "325", "side": "BUY", "hash": "ea7967d7500d0d72bce47e8078774895d8b77b6c", "best_bid": "0.55", "best_ask": "0.57"}, {"asset_id": "115183429975003994986742111804963130302445062562951748575181862773257927283380", "price": "0.45", "size": "325", "side": "SELL", "hash": "d092ed9b4f2da9b2ae9423e58dfcb27c4dd86140", "best_bid": "0.43", "best_ask": "0.45"}], "timestamp": "1769384493178", "event_type": "price_change"}}
{"_local_timestamp": "2026-01-25T23:41:33.374636+00:00", "data": {"market": "0x0e34be3ee9cb4203fae20b289dfc9a9370f0045ab3fb2e1fa4e6fb82596c678f", "price_changes": [{"asset_id": "12727775089212363162508241557815769734691893483170358591167365904671830747608", "price": "0.53", "size": "842", "side": "BUY", "hash": "ec77fea8e1927f378a4e6a499dce9a88ab2415d0", "best_bid": "0.55", "best_ask": "0.57"}, {"asset_id": "115183429975003994986742111804963130302445062562951748575181862773257927283380", "price": "0.47", "size": "842", "side": "SELL", "hash": "85681d9574e9f273f9bce09d0c843baab50ad2e1", "best_bid": "0.43", "best_ask": "0.45"}], "timestamp": "1769384493217", "event_type": "price_change"}}
{"_local_timestamp": "2026-01-25T23:41:33.447657+00:00", "data": {"market": "0x0e34be3ee9cb4203fae20b289dfc9a9370f0045ab3fb2e1fa4e6fb82596c678f", "price_changes": [{"asset_id": "12727775089212363162508241557815769734691893483170358591167365904671830747608", "price": "0.55", "size": "330", "side": "BUY", "hash": "93ca090ce3683755327f85a936b5e3fb16fb4268", "best_bid": "0.55", "best_ask": "0.57"}, {"asset_id": "115183429975003994986742111804963130302445062562951748575181862773257927283380", "price": "0.45", "size": "330", "side": "SELL", "hash": "b0a0863c0b74c8db99a0ee81f50063bfc42264d2", "best_bid": "0.43", "best_ask": "0.45"}], "timestamp": "1769384493293", "event_type": "price_change"}}
{"_local_timestamp": "2026-01-25T23:41:35.832276+00:00", "data": {"market": "0x0e34be3ee9cb4203fae20b289dfc9a9370f0045ab3fb2e1fa4e6fb82596c678f", "price_changes": [{"asset_id": "12727775089212363162508241557815769734691893483170358591167365904671830747608", "price": "0.55", "size": "370", "side": "BUY", "hash": "edfa8acd05d1264c2e64d914028a7de39607f541", "best_bid": "0.55", "best_ask": "0.57"}, {"asset_id": "115183429975003994986742111804963130302445062562951748575181862773257927283380", "price": "0.45", "size": "370", "side": "SELL", "hash": "865fb152ff0b227e563ba136f8b249ca349489bc", "best_bid": "0.43", "best_ask": "0.45"}], "timestamp": "1769384495702", "event_type": "price_change"}}
{"_local_timestamp": "2026-01-25T23:41:35.833390+00:00", "data": {"market": "0x0e34be3ee9cb4203fae20b289dfc9a9370f0045ab3fb2e1fa4e6fb82596c678f", "price_changes": [{"asset_id": "12727775089212363162508241557815769734691893483170358591167365904671830747608", "price": "0.54", "size": "60", "side": "BUY", "hash": "900c9e846eeed362e44b0c65dc5786f8e07bf092", "best_bid": "0.55", "best_ask": "0.57"}, {"asset_id": "115183429975003994986742111804963130302445062562951748575181862773257927283380", "price": "0.46", "size": "60", "side": "SELL", "hash": "a3c21a05f9c447f14f75877b7c976087394f3b9a", "best_bid": "0.43", "best_ask": "0.45"}], "timestamp": "1769384495702", "event_type": "price_change"}}
{"_local_timestamp": "2026-01-25T23:41:35.931215+00:00", "data": {"market": "0x0e34be3ee9cb4203fae20b289dfc9a9370f0045ab3fb2e1fa4e6fb82596c678f", "price_changes": [{"asset_id": "12727775089212363162508241557815769734691893483170358591167365904671830747608", "price": "0.52", "size": "9239", "side": "BUY", "hash": "53728c43109e0deb02cf30405d8988deb663fa73", "best_bid": "0.55", "best_ask": "0.57"}, {"asset_id": "115183429975003994986742111804963130302445062562951748575181862773257927283380", "price": "0.48", "size": "9239", "side": "SELL", "hash": "fc583729314bd16c9a42699a2421050737f3f6fe", "best_bid": "0.43", "best_ask": "0.45"}], "timestamp": "1769384495811", "event_type": "price_change"}}
{"_local_timestamp": "2026-01-25T23:41:35.937213+00:00", "data": {"market": "0x0e34be3ee9cb4203fae20b289dfc9a9370f0045ab3fb2e1fa4e6fb82596c678f", "price_changes": [{"asset_id": "12727775089212363162508241557815769734691893483170358591167365904671830747608", "price": "0.52", "size": "9189", "side": "BUY", "hash": "20b09c03be11262dc7f1c6f3e56f9f6a100b74eb", "best_bid": "0.55", "best_ask": "0.57"}, {"asset_id": "115183429975003994986742111804963130302445062562951748575181862773257927283380", "price": "0.48", "size": "9189", "side": "SELL", "hash": "aab6686cf931c5a0b996569113c128b9e779e132", "best_bid": "0.43", "best_ask": "0.45"}], "timestamp": "1769384495812", "event_type": "price_change"}}
{"_local_timestamp": "2026-01-25T23:41:35.940030+00:00", "data": {"market": "0x0e34be3ee9cb4203fae20b289dfc9a9370f0045ab3fb2e1fa4e6fb82596c678f", "price_changes": [{"asset_id": "12727775089212363162508241557815769734691893483170358591167365904671830747608", "price": "0.55", "size": "420", "side": "BUY", "hash": "e3c75b0befe779863b59dc83a0afed7f8493ef03", "best_bid": "0.55", "best_ask": "0.57"}, {"asset_id": "115183429975003994986742111804963130302445062562951748575181862773257927283380", "price": "0.45", "size": "420", "side": "SELL", "hash": "01d5ac64f62692e82404fcf73a421e04fc549019", "best_bid": "0.43", "best_ask": "0.45"}], "timestamp": "1769384495813", "event_type": "price_change"}}
{"_local_timestamp": "2026-01-25T23:41:35.940586+00:00", "data": {"market": "0x0e34be3ee9cb4203fae20b289dfc9a9370f0045ab3fb2e1fa4e6fb82596c678f", "price_changes": [{"asset_id": "12727775089212363162508241557815769734691893483170358591167365904671830747608", "price": "0.55", "size": "470", "side": "BUY", "hash": "ebc3c236ed9c0a5a0f9ba94c95c98672bc900348", "best_bid": "0.55", "best_ask": "0.57"}, {"asset_id": "115183429975003994986742111804963130302445062562951748575181862773257927283380", "price": "0.45", "size": "470", "side": "SELL", "hash": "1651c1bf22ae5e0dee614c549aa8b40c56ff8e49", "best_bid": "0.43", "best_ask": "0.45"}], "timestamp": "1769384495820", "event_type": "price_change"}}
{"_local_timestamp": "2026-01-25T23:41:43.826063+00:00", "data": {"market": "0xcda8a657998ef072e1d9edd83ce60ada3e75fc4d9113bc3f32a343a93fb1c927", "price_changes": [{"asset_id": "79200508610612497735268197792255474784890164267460369534045305976733489576200", "price": "0.472", "size": "0", "side": "SELL", "hash": "e03f2c35a1c9d27f2c2fdc4f2ecacf909fabc55f", "best_bid": "0.431", "best_ask": "0.439"}, {"asset_id": "7064893400396467616058037848568819292052255869002775709074859726119346714372", "price": "0.528", "size": "0", "side": "BUY", "hash": "8d61c4973134e48c4d425d02a30d5fe1d1857aa1", "best_bid": "0.561", "best_ask": "0.569"}], "timestamp": "1769384503759", "event_type": "price_change"}}
{"_local_timestamp": "2026-01-25T23:41:44.006183+00:00", "data": {"market": "0x0e34be3ee9cb4203fae20b289dfc9a9370f0045ab3fb2e1fa4e6fb82596c678f", "price_changes": [{"asset_id": "115183429975003994986742111804963130302445062562951748575181862773257927283380", "price": "0.41", "size": "9503", "side": "BUY", "hash": "cbce72d6c626321fd7e62ee8fff3bfd1b687f4cc", "best_bid": "0.43", "best_ask": "0.45"}, {"asset_id": "12727775089212363162508241557815769734691893483170358591167365904671830747608", "price": "0.59", "size": "9503", "side": "SELL", "hash": "b84c19154e70ddbc3429cfd62c186d7f814c6593", "best_bid": "0.55", "best_ask": "0.57"}], "timestamp": "1769384503933", "event_type": "price_change"}}
{"_local_timestamp": "2026-01-25T23:41:44.030718+00:00", "data": {"market": "0x0e34be3ee9cb4203fae20b289dfc9a9370f0045ab3fb2e1fa4e6fb82596c678f", "price_changes": [{"asset_id": "115183429975003994986742111804963130302445062562951748575181862773257927283380", "price": "0.41", "size": "9703", "side": "BUY", "hash": "d3f9f8e7ada06666bfe24899e3b4bea48729edb7", "best_bid": "0.43", "best_ask": "0.45"}, {"asset_id": "12727775089212363162508241557815769734691893483170358591167365904671830747608", "price": "0.59", "size": "9703", "side": "SELL", "hash": "48d10b486c4bb0b6ec532594fc37d936d5eb2106", "best_bid": "0.55", "best_ask": "0.57"}], "timestamp": "1769384503965", "event_type": "price_change"}}
{"_local_timestamp": "2026-01-25T23:41:44.712110+00:00", "data": {"market": "0x0e34be3ee9cb4203fae20b289dfc9a9370f0045ab3fb2e1fa4e6fb82596c678f", "price_changes": [{"asset_id": "12727775089212363162508241557815769734691893483170358591167365904671830747608", "price": "0.55", "size": "270", "side": "BUY", "hash": "bc4d4a3433791aa86d350edd62bac7eddc46be5c", "best_bid": "0.55", "best_ask": "0.57"}, {"asset_id": "115183429975003994986742111804963130302445062562951748575181862773257927283380", "price": "0.45", "size": "270", "side": "SELL", "hash": "389291afd6d348336b1e5de26d07b6432bef42e3", "best_bid": "0.43", "best_ask": "0.45"}], "timestamp": "1769384504640", "event_type": "price_change"}}
{"_local_timestamp": "2026-01-25T23:41:44.738457+00:00", "data": {"market": "0x0e34be3ee9cb4203fae20b289dfc9a9370f0045ab3fb2e1fa4e6fb82596c678f", "price_changes": [{"asset_id": "12727775089212363162508241557815769734691893483170358591167365904671830747608", "price": "0.55", "size": "470", "side": "BUY", "hash": "ec8f5fa70ce172c3cf9fd5849a00e60f9310e2c3", "best_bid": "0.55", "best_ask": "0.57"}, {"asset_id": "115183429975003994986742111804963130302445062562951748575181862773257927283380", "price": "0.45", "size": "470", "side": "SELL", "hash": "eb3df92ec6a0834a526408b815f09cc68286b07e", "best_bid": "0.43", "best_ask": "0.45"}], "timestamp": "1769384504671", "event_type": "price_change"}}
{"_local_timestamp": "2026-01-25T23:41:46.214936+00:00", "data": {"market": "0xcda8a657998ef072e1d9edd83ce60ada3e75fc4d9113bc3f32a343a93fb1c927", "price_changes": [{"asset_id": "79200508610612497735268197792255474784890164267460369534045305976733489576200", "price": "0.418", "size": "400", "side": "BUY", "hash": "fee1db1b61e07e00527c27733a65fe5c09426f28", "best_bid": "0.431", "best_ask": "0.439"}, {"asset_id": "7064893400396467616058037848568819292052255869002775709074859726119346714372", "price": "0.582", "size": "400", "side": "SELL", "hash": "d4d4e667d3753dc979968a50bb93af90fd5e1224", "best_bid": "0.561", "best_ask": "0.569"}], "timestamp": "1769384506149", "event_type": "price_change"}}
{"_local_timestamp": "2026-01-25T23:41:46.215369+00:00", "data": {"market": "0x0e34be3ee9cb4203fae20b289dfc9a9370f0045ab3fb2e1fa4e6fb82596c678f", "price_changes": [{"asset_id": "12727775089212363162508241557815769734691893483170358591167365904671830747608", "price": "0.53", "size": "1242", "side": "BUY", "hash": "5ee26918034c36a6dba5f84931d553a60c71886c", "best_bid": "0.55", "best_ask": "0.57"}, {"asset_id": "115183429975003994986742111804963130302445062562951748575181862773257927283380", "price": "0.47", "size": "1242", "side": "SELL", "hash": "95cbd85302f17b8645d1dab3916eff9742b84fde", "best_bid": "0.43", "best_ask": "0.45"}], "timestamp": "1769384506149", "event_type": "price_change"}}
{"_local_timestamp": "2026-01-25T23:41:46.215727+00:00", "data": {"market": "0x0e34be3ee9cb4203fae20b289dfc9a9370f0045ab3fb2e1fa4e6fb82596c678f", "price_changes": [{"asset_id": "12727775089212363162508241557815769734691893483170358591167365904671830747608", "price": "0.56", "size": "200", "side": "BUY", "hash": "1c54fc0ac3aef72cd4c90a87ce1f9ac092d4d20b", "best_bid": "0.56", "best_ask": "0.57"}, {"asset_id": "115183429975003994986742111804963130302445062562951748575181862773257927283380", "price": "0.44", "size": "200", "side": "SELL", "hash": "f903d8bfb687da047261506925102f5b29bc43e9", "best_bid": "0.43", "best_ask": "0.44"}], "timestamp": "1769384506149", "event_type": "price_change"}}
{"_local_timestamp": "2026-01-25T23:41:46.318222+00:00", "data": {"market": "0x0e34be3ee9cb4203fae20b289dfc9a9370f0045ab3fb2e1fa4e6fb82596c678f", "price_changes": [{"asset_id": "12727775089212363162508241557815769734691893483170358591167365904671830747608", "price": "0.52", "size": "9184", "side": "BUY", "hash": "3454a3351366ed90cf75e241cffb637b16313528", "best_bid": "0.56", "best_ask": "0.57"}, {"asset_id": "115183429975003994986742111804963130302445062562951748575181862773257927283380", "price": "0.48", "size": "9184", "side": "SELL", "hash": "eaa25a74d3059f1b2e9f58bdb22d7f2e0fc55583", "best_bid": "0.43", "best_ask": "0.44"}], "timestamp": "1769384506255", "event_type": "price_change"}}
{"_local_timestamp": "2026-01-25T23:41:48.523558+00:00", "data": {"market": "0x0e34be3ee9cb4203fae20b289dfc9a9370f0045ab3fb2e1fa4e6fb82596c678f", "price_changes": [{"asset_id": "12727775089212363162508241557815769734691893483170358591167365904671830747608", "price": "0.53", "size": "1142", "side": "BUY", "hash": "2e67eb33c8bac6590228f11b85914fa59a006ccd", "best_bid": "0.56", "best_ask": "0.57"}, {"asset_id": "115183429975003994986742111804963130302445062562951748575181862773257927283380", "price": "0.47", "size": "1142", "side": "SELL", "hash": "7d2eb4241a84cf314af57234371198dc43cffa47", "best_bid": "0.43", "best_ask": "0.44"}], "timestamp": "1769384508453", "event_type": "price_change"}}
{"_local_timestamp": "2026-01-25T23:41:49.042603+00:00", "data": {"market": "0xcda8a657998ef072e1d9edd83ce60ada3e75fc4d9113bc3f32a343a93fb1c927", "price_changes": [{"asset_id": "79200508610612497735268197792255474784890164267460369534045305976733489576200", "price": "0.418", "size": "0", "side": "BUY", "hash": "06224be2ebc433ee6cb95c2ee20b0f1ae95bb7aa", "best_bid": "0.431", "best_ask": "0.439"}, {"asset_id": "7064893400396467616058037848568819292052255869002775709074859726119346714372", "price": "0.582", "size": "0", "side": "SELL", "hash": "a176cf77ac343571a0263321719ec92d5c21f558", "best_bid": "0.561", "best_ask": "0.569"}], "timestamp": "1769384508968", "event_type": "price_change"}}
{"_local_timestamp": "2026-01-25T23:41:49.062315+00:00", "data": {"market": "0x0e34be3ee9cb4203fae20b289dfc9a9370f0045ab3fb2e1fa4e6fb82596c678f", "price_changes": [{"asset_id": "12727775089212363162508241557815769734691893483170358591167365904671830747608", "price": "0.56", "size": "0", "side": "BUY", "hash": "c89da1fc6205358b54c90cb75a4a6c7004f6cdb1", "best_bid": "0.55", "best_ask": "0.57"}, {"asset_id": "115183429975003994986742111804963130302445062562951748575181862773257927283380", "price": "0.44", "size": "0", "side": "SELL", "hash": "df0e9e2c16c4786086fab98a49079031f908c944", "best_bid": "0.43", "best_ask": "0.45"}], "timestamp": "1769384508970", "event_type": "price_change"}}
{"_local_timestamp": "2026-01-25T23:41:49.067320+00:00", "data": {"market": "0x0e34be3ee9cb4203fae20b289dfc9a9370f0045ab3fb2e1fa4e6fb82596c678f", "price_changes": [{"asset_id": "12727775089212363162508241557815769734691893483170358591167365904671830747608", "price": "0.53", "size": "742", "side": "BUY", "hash": "c89da1fc6205358b54c90cb75a4a6c7004f6cdb1", "best_bid": "0.55", "best_ask": "0.57"}, {"asset_id": "115183429975003994986742111804963130302445062562951748575181862773257927283380", "price": "0.47", "size": "742", "side": "SELL", "hash": "df0e9e2c16c4786086fab98a49079031f908c944", "best_bid": "0.43", "best_ask": "0.45"}], "timestamp": "1769384508970", "event_type": "price_change"}}
{"_local_timestamp": "2026-01-25T23:41:49.200017+00:00", "data": {"market": "0x0e34be3ee9cb4203fae20b289dfc9a9370f0045ab3fb2e1fa4e6fb82596c678f", "price_changes": [{"asset_id": "12727775089212363162508241557815769734691893483170358591167365904671830747608", "price": "0.52", "size": "9189", "side": "BUY", "hash": "ba40a2c16dad957c37b579d0d238cf9d27c4fd51", "best_bid": "0.55", "best_ask": "0.57"}, {"asset_id": "115183429975003994986742111804963130302445062562951748575181862773257927283380", "price": "0.48", "size": "9189", "side": "SELL", "hash": "4a3b6f206c262939041f54d01d368f345e071478", "best_bid": "0.43", "best_ask": "0.45"}], "timestamp": "1769384509132", "event_type": "price_change"}}
{"_local_timestamp": "2026-01-25T23:41:51.684148+00:00", "data": {"market": "0x0e34be3ee9cb4203fae20b289dfc9a9370f0045ab3fb2e1fa4e6fb82596c678f", "price_changes": [{"asset_id": "12727775089212363162508241557815769734691893483170358591167365904671830747608", "price": "0.53", "size": "842", "side": "BUY", "hash": "a9a14162c95822d0444c0c02c90c8974b5d5fcec", "best_bid": "0.55", "best_ask": "0.57"}, {"asset_id": "115183429975003994986742111804963130302445062562951748575181862773257927283380", "price": "0.47", "size": "842", "side": "SELL", "hash": "8a362b7b557e34adf98a0320e1a9db5028b72132", "best_bid": "0.43", "best_ask": "0.45"}], "timestamp": "1769384511593", "event_type": "price_change"}}
{"_local_timestamp": "2026-01-25T23:41:54.589034+00:00", "data": {"market": "0xcda8a657998ef072e1d9edd83ce60ada3e75fc4d9113bc3f32a343a93fb1c927", "price_changes": [{"asset_id": "79200508610612497735268197792255474784890164267460369534045305976733489576200", "price": "0.429", "size": "164.62", "side": "BUY", "hash": "6cfadc87be49306f00960355e5634282f298eb6f", "best_bid": "0.431", "best_ask": "0.439"}, {"asset_id": "7064893400396467616058037848568819292052255869002775709074859726119346714372", "price": "0.571", "size": "164.62", "side": "SELL", "hash": "4a5cb255a68357e1ceee91211d31caf9e44542ab", "best_bid": "0.561", "best_ask": "0.569"}], "timestamp": "1769384514513", "event_type": "price_change"}}
{"_local_timestamp": "2026-01-25T23:41:56.918586+00:00", "data": {"market": "0xcda8a657998ef072e1d9edd83ce60ada3e75fc4d9113bc3f32a343a93fb1c927", "price_changes": [{"asset_id": "79200508610612497735268197792255474784890164267460369534045305976733489576200", "price": "0.438", "size": "163.1", "side": "SELL", "hash": "8fd591a7cda7022c1fe0133168691a7766d59c71", "best_bid": "0.431", "best_ask": "0.438"}, {"asset_id": "7064893400396467616058037848568819292052255869002775709074859726119346714372", "price": "0.562", "size": "163.1", "side": "BUY", "hash": "e66b3f2f735007440ed77734fbff7e9742e55fe3", "best_bid": "0.562", "best_ask": "0.569"}], "timestamp": "1769384516855", "event_type": "price_change"}}
{"_local_timestamp": "2026-01-25T23:41:56.952101+00:00", "data": {"market": "0x0e34be3ee9cb4203fae20b289dfc9a9370f0045ab3fb2e1fa4e6fb82596c678f", "price_changes": [{"asset_id": "12727775089212363162508241557815769734691893483170358591167365904671830747608", "price": "0.55", "size": "370", "side": "BUY", "hash": "e8bcb6846d86ebd347186304aed46f888e7c9015", "best_bid": "0.55", "best_ask": "0.57"}, {"asset_id": "115183429975003994986742111804963130302445062562951748575181862773257927283380", "price": "0.45", "size": "370", "side": "SELL", "hash": "dbd78632b37aac1bfcdff00914708a62c39963d0", "best_bid": "0.43", "best_ask": "0.45"}], "timestamp": "1769384516878", "event_type": "price_change"}}
{"_local_timestamp": "2026-01-25T23:41:57.040657+00:00", "data": {"market": "0x0e34be3ee9cb4203fae20b289dfc9a9370f0045ab3fb2e1fa4e6fb82596c678f", "price_changes": [{"asset_id": "12727775089212363162508241557815769734691893483170358591167365904671830747608", "price": "0.55", "size": "365", "side": "BUY", "hash": "4502bce304f8fb5baaadeb6b601fe7254c301427", "best_bid": "0.55", "best_ask": "0.57"}, {"asset_id": "115183429975003994986742111804963130302445062562951748575181862773257927283380", "price": "0.45", "size": "365", "side": "SELL", "hash": "c0b211945bf18cbf567f9dd8a46e4902155acfb9", "best_bid": "0.43", "best_ask": "0.45"}], "timestamp": "1769384516960", "event_type": "price_change"}}
{"_local_timestamp": "2026-01-25T23:41:57.045424+00:00", "data": {"market": "0x0e34be3ee9cb4203fae20b289dfc9a9370f0045ab3fb2e1fa4e6fb82596c678f", "price_changes": [{"asset_id": "12727775089212363162508241557815769734691893483170358591167365904671830747608", "price": "0.56", "size": "5", "side": "BUY", "hash": "5f8ca38586f072ca5db970ff8209c4f30c8e2492", "best_bid": "0.56", "best_ask": "0.57"}, {"asset_id": "115183429975003994986742111804963130302445062562951748575181862773257927283380", "price": "0.44", "size": "5", "side": "SELL", "hash": "2ec5b64ddc2447bd3bf3693aeb345da464eb0c50", "best_bid": "0.43", "best_ask": "0.44"}], "timestamp": "1769384516964", "event_type": "price_change"}}
{"_local_timestamp": "2026-01-25T23:41:57.156368+00:00", "data": {"market": "0x0e34be3ee9cb4203fae20b289dfc9a9370f0045ab3fb2e1fa4e6fb82596c678f", "price_changes": [{"asset_id": "12727775089212363162508241557815769734691893483170358591167365904671830747608", "price": "0.56", "size": "30", "side": "BUY", "hash": "22095ac1d32069d3272ab7645e490b4006e25ceb", "best_bid": "0.56", "best_ask": "0.57"}, {"asset_id": "115183429975003994986742111804963130302445062562951748575181862773257927283380", "price": "0.44", "size": "30", "side": "SELL", "hash": "eae2ba28743e41fb55a8dee4c5844fb9b346002b", "best_bid": "0.43", "best_ask": "0.44"}], "timestamp": "1769384517070", "event_type": "price_change"}}
{"_local_timestamp": "2026-01-25T23:41:57.251428+00:00", "data": {"market": "0x0e34be3ee9cb4203fae20b289dfc9a9370f0045ab3fb2e1fa4e6fb82596c678f", "price_changes": [{"asset_id": "12727775089212363162508241557815769734691893483170358591167365904671830747608", "price": "0.55", "size": "340", "side": "BUY", "hash": "bef4919644c0fbce4ddc87a89d54f1dcba96deac", "best_bid": "0.56", "best_ask": "0.57"}, {"asset_id": "115183429975003994986742111804963130302445062562951748575181862773257927283380", "price": "0.45", "size": "340", "side": "SELL", "hash": "63037dc42390d6d59b0154c29dcbcb44530a086a", "best_bid": "0.43", "best_ask": "0.44"}], "timestamp": "1769384517137", "event_type": "price_change"}}
{"_local_timestamp": "2026-01-25T23:41:57.258988+00:00", "data": {"market": "0x0e34be3ee9cb4203fae20b289dfc9a9370f0045ab3fb2e1fa4e6fb82596c678f", "price_changes": [{"asset_id": "12727775089212363162508241557815769734691893483170358591167365904671830747608", "price": "0.52", "size": "9184", "side": "BUY", "hash": "c1aecf4a5c9c6d6ead371e9a7c0132182fc12cf2", "best_bid": "0.56", "best_ask": "0.57"}, {"asset_id": "115183429975003994986742111804963130302445062562951748575181862773257927283380", "price": "0.48", "size": "9184", "side": "SELL", "hash": "c4f60f3a7e29951deba7499bb2aed98c61fe580c", "best_bid": "0.43", "best_ask": "0.44"}], "timestamp": "1769384517190", "event_type": "price_change"}}
{"_local_timestamp": "2026-01-25T23:41:57.352814+00:00", "data": {"market": "0x0e34be3ee9cb4203fae20b289dfc9a9370f0045ab3fb2e1fa4e6fb82596c678f", "price_changes": [{"asset_id": "12727775089212363162508241557815769734691893483170358591167365904671830747608", "price": "0.55", "size": "503.1", "side": "BUY", "hash": "12f867b84d439a4393a38627893953287c9b6171", "best_bid": "0.56", "best_ask": "0.57"}, {"asset_id": "115183429975003994986742111804963130302445062562951748575181862773257927283380", "price": "0.45", "size": "503.1", "side": "SELL", "hash": "993700f0dc50377dad65707ce4f4f130e906d832", "best_bid": "0.43", "best_ask": "0.44"}], "timestamp": "1769384517288", "event_type": "price_change"}}
{"_local_timestamp": "2026-01-25T23:41:59.199258+00:00", "data": {"market": "0xcda8a657998ef072e1d9edd83ce60ada3e75fc4d9113bc3f32a343a93fb1c927", "price_changes": [{"asset_id": "79200508610612497735268197792255474784890164267460369534045305976733489576200", "price": "0.431", "size": "0", "side": "BUY", "hash": "0a42723a9123a77452f27da1c945574a04c3ab14", "best_bid": "0.43", "best_ask": "0.438"}, {"asset_id": "7064893400396467616058037848568819292052255869002775709074859726119346714372", "price": "0.569", "size": "0", "side": "SELL", "hash": "07a905ebfeb424d957005170605203489cf1f22c", "best_bid": "0.562", "best_ask": "0.57"}], "timestamp": "1769384519128", "event_type": "price_change"}}
{"_local_timestamp": "2026-01-25T23:41:59.313132+00:00", "data": {"market": "0x0e34be3ee9cb4203fae20b289dfc9a9370f0045ab3fb2e1fa4e6fb82596c678f", "price_changes": [{"asset_id": "12727775089212363162508241557815769734691893483170358591167365904671830747608", "price": "0.56", "size": "5", "side": "BUY", "hash": "dfe0d75021463e55943bb8a6fdfd466e3bd49e3d", "best_bid": "0.56", "best_ask": "0.57"}, {"asset_id": "115183429975003994986742111804963130302445062562951748575181862773257927283380", "price": "0.44", "size": "5", "side": "SELL", "hash": "79bb932240938a71645fac2fc2e4e23aefd06d40", "best_bid": "0.43", "best_ask": "0.44"}], "timestamp": "1769384519243", "event_type": "price_change"}}
{"_local_timestamp": "2026-01-25T23:41:59.420180+00:00", "data": {"market": "0x0e34be3ee9cb4203fae20b289dfc9a9370f0045ab3fb2e1fa4e6fb82596c678f", "price_changes": [{"asset_id": "12727775089212363162508241557815769734691893483170358591167365904671830747608", "price": "0.52", "size": "9189", "side": "BUY", "hash": "413ddf6603bf9da1d2cc967276c0b11e947b98fb", "best_bid": "0.56", "best_ask": "0.57"}, {"asset_id": "115183429975003994986742111804963130302445062562951748575181862773257927283380", "price": "0.48", "size": "9189", "side": "SELL", "hash": "ae9d3ec79f4162925cfd92f43dbf87b41d4e6e97", "best_bid": "0.43", "best_ask": "0.44"}], "timestamp": "1769384519355", "event_type": "price_change"}}
{"_local_timestamp": "2026-01-25T23:42:01.976499+00:00", "data": {"market": "0x0e34be3ee9cb4203fae20b289dfc9a9370f0045ab3fb2e1fa4e6fb82596c678f", "price_changes": [{"asset_id": "12727775089212363162508241557815769734691893483170358591167365904671830747608", "price": "0.53", "size": "742", "side": "BUY", "hash": "03b5c95c79053270986a6aecadec8373fb97e5dc", "best_bid": "0.56", "best_ask": "0.57"}, {"asset_id": "115183429975003994986742111804963130302445062562951748575181862773257927283380", "price": "0.47", "size": "742", "side": "SELL", "hash": "44753db50d9e0f655082ab2c7b5dd251115c918c", "best_bid": "0.43", "best_ask": "0.44"}], "timestamp": "1769384521907", "event_type": "price_change"}}
{"_local_timestamp": "2026-01-25T23:42:02.092651+00:00", "data": {"market": "0x0e34be3ee9cb4203fae20b289dfc9a9370f0045ab3fb2e1fa4e6fb82596c678f", "price_changes": [{"asset_id": "12727775089212363162508241557815769734691893483170358591167365904671830747608", "price": "0.56", "size": "30", "side": "BUY", "hash": "e851b1d82863529e764e42010c8a1a59d729223a", "best_bid": "0.56", "best_ask": "0.57"}, {"asset_id": "115183429975003994986742111804963130302445062562951748575181862773257927283380", "price": "0.44", "size": "30", "side": "SELL", "hash": "9928451f7d98cc4d4ff7109ccdb67efbadd00e00", "best_bid": "0.43", "best_ask": "0.44"}], "timestamp": "1769384522019", "event_type": "price_change"}}
{"_local_timestamp": "2026-01-25T23:42:02.240285+00:00", "data": {"market": "0x0e34be3ee9cb4203fae20b289dfc9a9370f0045ab3fb2e1fa4e6fb82596c678f", "price_changes": [{"asset_id": "12727775089212363162508241557815769734691893483170358591167365904671830747608", "price": "0.52", "size": "9184", "side": "BUY", "hash": "67b4c89f7953f66afaae2807e3dded29e86d197c", "best_bid": "0.56", "best_ask": "0.57"}, {"asset_id": "115183429975003994986742111804963130302445062562951748575181862773257927283380", "price": "0.48", "size": "9184", "side": "SELL", "hash": "4d94b2581e7b9222ee2070b8cb935046edec8015", "best_bid": "0.43", "best_ask": "0.44"}], "timestamp": "1769384522174", "event_type": "price_change"}}
{"_local_timestamp": "2026-01-25T23:42:02.241946+00:00", "data": {"market": "0xcda8a657998ef072e1d9edd83ce60ada3e75fc4d9113bc3f32a343a93fb1c927", "price_changes": [{"asset_id": "79200508610612497735268197792255474784890164267460369534045305976733489576200", "price": "0.4", "size": "709", "side": "BUY", "hash": "e8eb9c5fe9cb03161831d7c618e93b74a011474f", "best_bid": "0.43", "best_ask": "0.438"}, {"asset_id": "7064893400396467616058037848568819292052255869002775709074859726119346714372", "price": "0.6", "size": "709", "side": "SELL", "hash": "3ffe8ef2e556bdaaf29c27b61917ebc8eb99f387", "best_bid": "0.562", "best_ask": "0.57"}], "timestamp": "1769384522178", "event_type": "price_change"}}
{"_local_timestamp": "2026-01-25T23:42:02.284259+00:00", "data": {"market": "0xcda8a657998ef072e1d9edd83ce60ada3e75fc4d9113bc3f32a343a93fb1c927", "price_changes": [{"asset_id": "79200508610612497735268197792255474784890164267460369534045305976733489576200", "price": "0.4", "size": "909", "side": "BUY", "hash": "3a13080dd4d8f892009a96bca4b2bc3dd475c191", "best_bid": "0.43", "best_ask": "0.438"}, {"asset_id": "7064893400396467616058037848568819292052255869002775709074859726119346714372", "price": "0.6", "size": "909", "side": "SELL", "hash": "0d75d4b8ca4c8de4bb4ccf8f02aa3bf3507d45a1", "best_bid": "0.562", "best_ask": "0.57"}], "timestamp": "1769384522216", "event_type": "price_change"}}
{"_local_timestamp": "2026-01-25T23:42:02.367232+00:00", "data": {"market": "0xcda8a657998ef072e1d9edd83ce60ada3e75fc4d9113bc3f32a343a93fb1c927", "price_changes": [{"asset_id": "79200508610612497735268197792255474784890164267460369534045305976733489576200", "price": "0.418", "size": "50", "side": "BUY", "hash": "06d30fb5831b8e32e2bbff14b40f6321165a80c8", "best_bid": "0.43", "best_ask": "0.438"}, {"asset_id": "7064893400396467616058037848568819292052255869002775709074859726119346714372", "price": "0.582", "size": "50", "side": "SELL", "hash": "634c40963bf25dbd5036a368584e4609ec52b825", "best_bid": "0.562", "best_ask": "0.57"}], "timestamp": "1769384522298", "event_type": "price_change"}}
{"_local_timestamp": "2026-01-25T23:42:02.409287+00:00", "data": {"market": "0xcda8a657998ef072e1d9edd83ce60ada3e75fc4d9113bc3f32a343a93fb1c927", "price_changes": [{"asset_id": "79200508610612497735268197792255474784890164267460369534045305976733489576200", "price": "0.408", "size": "800", "side": "BUY", "hash": "4325b8a12392dd0c782ad7f4d083c4d6fc431e14", "best_bid": "0.43", "best_ask": "0.438"}, {"asset_id": "7064893400396467616058037848568819292052255869002775709074859726119346714372", "price": "0.592", "size": "800", "side": "SELL", "hash": "7c005c3c9084ab3b8d01d2f2d0c838782030948a", "best_bid": "0.562", "best_ask": "0.57"}], "timestamp": "1769384522341", "event_type": "price_change"}}
{"_local_timestamp": "2026-01-25T23:42:02.439956+00:00", "data": {"market": "0xcda8a657998ef072e1d9edd83ce60ada3e75fc4d9113bc3f32a343a93fb1c927", "price_changes": [{"asset_id": "79200508610612497735268197792255474784890164267460369534045305976733489576200", "price": "0.418", "size": "100", "side": "BUY", "hash": "be3db84c3099ee944963dcc948023dbbb21e28b3", "best_bid": "0.43", "best_ask": "0.438"}, {"asset_id": "7064893400396467616058037848568819292052255869002775709074859726119346714372", "price": "0.582", "size": "100", "side": "SELL", "hash": "ec03f95855947b373e1d9835dee8d83b2e16f992", "best_bid": "0.562", "best_ask": "0.57"}], "timestamp": "1769384522364", "event_type": "price_change"}}
{"_local_timestamp": "2026-01-25T23:42:02.956976+00:00", "data": {"market": "0x0e34be3ee9cb4203fae20b289dfc9a9370f0045ab3fb2e1fa4e6fb82596c678f", "price_changes": [{"asset_id": "12727775089212363162508241557815769734691893483170358591167365904671830747608", "price": "0.52", "size": "11176", "side": "BUY", "hash": "4527bc4c5ab51b497c221f0a955efb535ffeeae8", "best_bid": "0.56", "best_ask": "0.57"}, {"asset_id": "115183429975003994986742111804963130302445062562951748575181862773257927283380", "price": "0.48", "size": "11176", "side": "SELL", "hash": "2ac589e2dffb3488f44ec2d2f6d9beba8827cf9d", "best_bid": "0.43", "best_ask": "0.44"}], "timestamp": "1769384522893", "event_type": "price_change"}}
{"_local_timestamp": "2026-01-25T23:42:02.966963+00:00", "data": {"market": "0x0e34be3ee9cb4203fae20b289dfc9a9370f0045ab3fb2e1fa4e6fb82596c678f", "price_changes": [{"asset_id": "115183429975003994986742111804963130302445062562951748575181862773257927283380", "price": "0.43", "size": "2162", "side": "BUY", "hash": "418298b4740e5f03696d0cd882d53bf9f8190ae5", "best_bid": "0.43", "best_ask": "0.44"}, {"asset_id": "12727775089212363162508241557815769734691893483170358591167365904671830747608", "price": "0.57", "size": "2162", "side": "SELL", "hash": "a311c6b62702d1c80b70d370475508d59406a6a2", "best_bid": "0.56", "best_ask": "0.57"}], "timestamp": "1769384522894", "event_type": "price_change"}}
{"_local_timestamp": "2026-01-25T23:42:02.967320+00:00", "data": {"market": "0xcda8a657998ef072e1d9edd83ce60ada3e75fc4d9113bc3f32a343a93fb1c927", "price_changes": [{"asset_id": "79200508610612497735268197792255474784890164267460369534045305976733489576200", "price": "0.41", "size": "2222", "side": "BUY", "hash": "cd6dc2b5c65f6b66062edb9b66d46d0e0be40c8a", "best_bid": "0.43", "best_ask": "0.438"}, {"asset_id": "7064893400396467616058037848568819292052255869002775709074859726119346714372", "price": "0.59", "size": "2222", "side": "SELL", "hash": "4d499d60089c6e65f6bc9895aa6fe8989a6c3ba7", "best_bid": "0.562", "best_ask": "0.57"}], "timestamp": "1769384522895", "event_type": "price_change"}}
{"_local_timestamp": "2026-01-25T23:42:02.967625+00:00", "data": {"market": "0xcda8a657998ef072e1d9edd83ce60ada3e75fc4d9113bc3f32a343a93fb1c927", "price_changes": [{"asset_id": "79200508610612497735268197792255474784890164267460369534045305976733489576200", "price": "0.47", "size": "1157.93", "side": "SELL", "hash": "1f605d2b630f56131aeee64f0628409e81cd5ca4", "best_bid": "0.43", "best_ask": "0.438"}, {"asset_id": "7064893400396467616058037848568819292052255869002775709074859726119346714372", "price": "0.53", "size": "1157.93", "side": "BUY", "hash": "89f75d9dc08e79757a03a4da0344ee42b9bad94a", "best_bid": "0.562", "best_ask": "0.57"}], "timestamp": "1769384522896", "event_type": "price_change"}}
{"_local_timestamp": "2026-01-25T23:42:02.967939+00:00", "data": {"market": "0x0e34be3ee9cb4203fae20b289dfc9a9370f0045ab3fb2e1fa4e6fb82596c678f", "price_changes": [{"asset_id": "12727775089212363162508241557815769734691893483170358591167365904671830747608", "price": "0.53", "size": "2730", "side": "BUY", "hash": "1e6972db777076bcc0eea0804b6da36e2ff5694f", "best_bid": "0.56", "best_ask": "0.57"}, {"asset_id": "115183429975003994986742111804963130302445062562951748575181862773257927283380", "price": "0.47", "size": "2730", "side": "SELL", "hash": "63f633915ecc74c46dc8d0ba792eec3422ae0fce", "best_bid": "0.43", "best_ask": "0.44"}], "timestamp": "1769384522897", "event_type": "price_change"}}
{"_local_timestamp": "2026-01-25T23:42:02.968264+00:00", "data": {"market": "0x0e34be3ee9cb4203fae20b289dfc9a9370f0045ab3fb2e1fa4e6fb82596c678f", "price_changes": [{"asset_id": "115183429975003994986742111804963130302445062562951748575181862773257927283380", "price": "0.42", "size": "3201.61", "side": "BUY", "hash": "e622eb06b0cc9248239e135eacd6aa406be47acb", "best_bid": "0.43", "best_ask": "0.44"}, {"asset_id": "12727775089212363162508241557815769734691893483170358591167365904671830747608", "price": "0.58", "size": "3201.61", "side": "SELL", "hash": "1f4c6758cb514077acdba483e464c11504863c32", "best_bid": "0.56", "best_ask": "0.57"}], "timestamp": "1769384522898", "event_type": "price_change"}}
{"_local_timestamp": "2026-01-25T23:42:02.988959+00:00", "data": {"market": "0xcda8a657998ef072e1d9edd83ce60ada3e75fc4d9113bc3f32a343a93fb1c927", "price_changes": [{"asset_id": "7064893400396467616058037848568819292052255869002775709074859726119346714372", "price": "0.51", "size": "2640", "side": "BUY", "hash": "46ad56774542dd011ab4edc31c058360a6997b06", "best_bid": "0.562", "best_ask": "0.57"}, {"asset_id": "79200508610612497735268197792255474784890164267460369534045305976733489576200", "price": "0.49", "size": "2640", "side": "SELL", "hash": "0faee7440f2e2b7cccfc442b0d7065973d09e299", "best_bid": "0.43", "best_ask": "0.438"}], "timestamp": "1769384522905", "event_type": "price_change"}}
{"_local_timestamp": "2026-01-25T23:42:02.989324+00:00", "data": {"market": "0xcda8a657998ef072e1d9edd83ce60ada3e75fc4d9113bc3f32a343a93fb1c927", "price_changes": [{"asset_id": "7064893400396467616058037848568819292052255869002775709074859726119346714372", "price": "0.52", "size": "2102", "side": "BUY", "hash": "f70fd238c671095d4525fb1a1cc763526a216023", "best_bid": "0.562", "best_ask": "0.57"}, {"asset_id": "79200508610612497735268197792255474784890164267460369534045305976733489576200", "price": "0.48", "size": "2102", "side": "SELL", "hash": "3270cd307d1144e921ee06384a428748ced07bea", "best_bid": "0.43", "best_ask": "0.438"}], "timestamp": "1769384522908", "event_type": "price_change"}}
{"_local_timestamp": "2026-01-25T23:42:03.030165+00:00", "data": {"market": "0xcda8a657998ef072e1d9edd83ce60ada3e75fc4d9113bc3f32a343a93fb1c927", "price_changes": [{"asset_id": "7064893400396467616058037848568819292052255869002775709074859726119346714372", "price": "0.53", "size": "3145.93", "side": "BUY", "hash": "0344cda8f2a018d9568c68430d0d60e9227c29d4", "best_bid": "0.562", "best_ask": "0.57"}, {"asset_id": "79200508610612497735268197792255474784890164267460369534045305976733489576200", "price": "0.47", "size": "3145.93", "side": "SELL", "hash": "c9e0bf6e292c5271638ec68e93e88c5fda47bf94", "best_bid": "0.43", "best_ask": "0.438"}], "timestamp": "1769384522958", "event_type": "price_change"}}
{"_local_timestamp": "2026-01-25T23:42:03.030455+00:00", "data": {"market": "0xcda8a657998ef072e1d9edd83ce60ada3e75fc4d9113bc3f32a343a93fb1c927", "price_changes": [{"asset_id": "79200508610612497735268197792255474784890164267460369534045305976733489576200", "price": "0.43", "size": "2380.9", "side": "BUY", "hash": "1e64b265252f77f104c8d564cc1cf87cf7b3494d", "best_bid": "0.43", "best_ask": "0.438"}, {"asset_id": "7064893400396467616058037848568819292052255869002775709074859726119346714372", "price": "0.57", "size": "2380.9", "side": "SELL", "hash": "ca7a58924e8649fc4228b19a9b2b277e8e85a6e4", "best_bid": "0.562", "best_ask": "0.57"}], "timestamp": "1769384522960", "event_type": "price_change"}}
{"_local_timestamp": "2026-01-25T23:42:03.030679+00:00", "data": {"market": "0x0e34be3ee9cb4203fae20b289dfc9a9370f0045ab3fb2e1fa4e6fb82596c678f", "price_changes": [{"asset_id": "115183429975003994986742111804963130302445062562951748575181862773257927283380", "price": "0.41", "size": "11765", "side": "BUY", "hash": "742ad07449edd00e4a7065c53c4dcfeef3660099", "best_bid": "0.43", "best_ask": "0.44"}, {"asset_id": "12727775089212363162508241557815769734691893483170358591167365904671830747608", "price": "0.59", "size": "11765", "side": "SELL", "hash": "626ac3d6076849300701460088e9fde2958423af", "best_bid": "0.56", "best_ask": "0.57"}], "timestamp": "1769384522960", "event_type": "price_change"}}
{"_local_timestamp": "2026-01-25T23:42:03.089803+00:00", "data": {"market": "0x0e34be3ee9cb4203fae20b289dfc9a9370f0045ab3fb2e1fa4e6fb82596c678f", "price_changes": [{"asset_id": "115183429975003994986742111804963130302445062562951748575181862773257927283380", "price": "0.47", "size": "2752.99", "side": "SELL", "hash": "78e19e8846e8405eeb0baf24dc6994c2c691d935", "best_bid": "0.43", "best_ask": "0.44"}, {"asset_id": "12727775089212363162508241557815769734691893483170358591167365904671830747608", "price": "0.53", "size": "2752.99", "side": "BUY", "hash": "7a92ae4b8ca0900f1cdb2f76c2620e9c1cfbdc82", "best_bid": "0.56", "best_ask": "0.57"}], "timestamp": "1769384522962", "event_type": "price_change"}}
{"_local_timestamp": "2026-01-25T23:42:03.090081+00:00", "data": {"market": "0xcda8a657998ef072e1d9edd83ce60ada3e75fc4d9113bc3f32a343a93fb1c927", "price_changes": [{"asset_id": "79200508610612497735268197792255474784890164267460369534045305976733489576200", "price": "0.42", "size": "2054", "side": "BUY", "hash": "b9b3f4605694b4b2036a29915bb20d67c30e69df", "best_bid": "0.43", "best_ask": "0.438"}, {"asset_id": "7064893400396467616058037848568819292052255869002775709074859726119346714372", "price": "0.58", "size": "2054", "side": "SELL", "hash": "17f1258a6cce82f1fa746ad5904faffb7347b4a6", "best_bid": "0.562", "best_ask": "0.57"}], "timestamp": "1769384522963", "event_type": "price_change"}}
{"_local_timestamp": "2026-01-25T23:42:03.090336+00:00", "data": {"market": "0x0e34be3ee9cb4203fae20b289dfc9a9370f0045ab3fb2e1fa4e6fb82596c678f", "price_changes": [{"asset_id": "12727775089212363162508241557815769734691893483170358591167365904671830747608", "price": "0.51", "size": "2670", "side": "BUY", "hash": "c0e12f13242e1a7e06b1fd0a75b0c59a33d159f0", "best_bid": "0.56", "best_ask": "0.57"}, {"asset_id": "115183429975003994986742111804963130302445062562951748575181862773257927283380", "price": "0.49", "size": "2670", "side": "SELL", "hash": "7425758d0770701abd0b5226a5f6db083bc6b0c8", "best_bid": "0.43", "best_ask": "0.44"}], "timestamp": "1769384522963", "event_type": "price_change"}}
{"_local_timestamp": "2026-01-25T23:42:03.090562+00:00", "data": {"market": "0x0e34be3ee9cb4203fae20b289dfc9a9370f0045ab3fb2e1fa4e6fb82596c678f", "price_changes": [{"asset_id": "115183429975003994986742111804963130302445062562951748575181862773257927283380", "price": "0.42", "size": "3101.61", "side": "BUY", "hash": "8bdb57d62d466fdd0a0b61033e2845b9d6b5b3b8", "best_bid": "0.43", "best_ask": "0.44"}, {"asset_id": "12727775089212363162508241557815769734691893483170358591167365904671830747608", "price": "0.58", "size": "3101.61", "side": "SELL", "hash": "8896bda9a9023ce60203f72678e4e6f098ff70b6", "best_bid": "0.56", "best_ask": "0.57"}], "timestamp": "1769384522971", "event_type": "price_change"}}
{"_local_timestamp": "2026-01-25T23:42:03.096004+00:00", "data": {"market": "0xcda8a657998ef072e1d9edd83ce60ada3e75fc4d9113bc3f32a343a93fb1c927", "price_changes": [{"asset_id": "79200508610612497735268197792255474784890164267460369534045305976733489576200", "price": "0.418", "size": "500", "side": "BUY", "hash": "2ee6c5df3a07e1254193536cb500268ac0d7204f", "best_bid": "0.43", "best_ask": "0.438"}, {"asset_id": "7064893400396467616058037848568819292052255869002775709074859726119346714372", "price": "0.582", "size": "500", "side": "SELL", "hash": "b4eacaeaba12a0aa69904ac4d4f35c5532c564bc", "best_bid": "0.562", "best_ask": "0.57"}], "timestamp": "1769384523003", "event_type": "price_change"}}
{"_local_timestamp": "2026-01-25T23:42:03.096263+00:00", "data": {"market": "0x0e34be3ee9cb4203fae20b289dfc9a9370f0045ab3fb2e1fa4e6fb82596c678f", "price_changes": [{"asset_id": "12727775089212363162508241557815769734691893483170358591167365904671830747608", "price": "0.56", "size": "5", "side": "BUY", "hash": "748a0e5e1f9762703b9848db385268876e9d42cc", "best_bid": "0.56", "best_ask": "0.57"}, {"asset_id": "115183429975003994986742111804963130302445062562951748575181862773257927283380", "price": "0.44", "size": "5", "side": "SELL", "hash": "1e5b6bde881ce32fbfefe38453ae460818573614", "best_bid": "0.43", "best_ask": "0.44"}], "timestamp": "1769384523004", "event_type": "price_change"}}
{"_local_timestamp": "2026-01-25T23:42:03.096478+00:00", "data": {"market": "0xcda8a657998ef072e1d9edd83ce60ada3e75fc4d9113bc3f32a343a93fb1c927", "price_changes": [{"asset_id": "79200508610612497735268197792255474784890164267460369534045305976733489576200", "price": "0.418", "size": "450", "side": "BUY", "hash": "f8cbd2ed9a336301981d473cb88c4e3427408e1d", "best_bid": "0.43", "best_ask": "0.438"}, {"asset_id": "7064893400396467616058037848568819292052255869002775709074859726119346714372", "price": "0.582", "size": "450", "side": "SELL", "hash": "93c84cfe611b75dc08f919c3170169f53811e299", "best_bid": "0.562", "best_ask": "0.57"}], "timestamp": "1769384523004", "event_type": "price_change"}}
{"_local_timestamp": "2026-01-25T23:42:03.103028+00:00", "data": {"market": "0xcda8a657998ef072e1d9edd83ce60ada3e75fc4d9113bc3f32a343a93fb1c927", "price_changes": [{"asset_id": "79200508610612497735268197792255474784890164267460369534045305976733489576200", "price": "0.408", "size": "0", "side": "BUY", "hash": "23e059fbf3642a36587a2869af97e535404b9acd", "best_bid": "0.43", "best_ask": "0.438"}, {"asset_id": "7064893400396467616058037848568819292052255869002775709074859726119346714372", "price": "0.592", "size": "0", "side": "SELL", "hash": "d6c5524b25d5f1ce906c308fb438bf5924ec11ee", "best_bid": "0.562", "best_ask": "0.57"}], "timestamp": "1769384523016", "event_type": "price_change"}}
{"_local_timestamp": "2026-01-25T23:42:03.103290+00:00", "data": {"market": "0xcda8a657998ef072e1d9edd83ce60ada3e75fc4d9113bc3f32a343a93fb1c927", "price_changes": [{"asset_id": "79200508610612497735268197792255474784890164267460369534045305976733489576200", "price": "0.418", "size": "400", "side": "BUY", "hash": "9390634e761d8c09f24ca34afff18a38fe8a55db", "best_bid": "0.43", "best_ask": "0.438"}, {"asset_id": "7064893400396467616058037848568819292052255869002775709074859726119346714372", "price": "0.582", "size": "400", "side": "SELL", "hash": "f3b146b9e3849aee6843d2e5be87f0f4592e3ad8", "best_bid": "0.562", "best_ask": "0.57"}], "timestamp": "1769384523021", "event_type": "price_change"}}
{"_local_timestamp": "2026-01-25T23:42:03.212452+00:00", "data": {"market": "0xcda8a657998ef072e1d9edd83ce60ada3e75fc4d9113bc3f32a343a93fb1c927", "price_changes": [{"asset_id": "79200508610612497735268197792255474784890164267460369534045305976733489576200", "price": "0.429", "size": "46.62", "side": "BUY", "hash": "a1f429a8a72f7ba159ce35d0fd8d607b05511c09", "best_bid": "0.43", "best_ask": "0.438"}, {"asset_id": "7064893400396467616058037848568819292052255869002775709074859726119346714372", "price": "0.571", "size": "46.62", "side": "SELL", "hash": "739a1111e52e61e63a0f2d1e76d8f367ae75a96e", "best_bid": "0.562", "best_ask": "0.57"}], "timestamp": "1769384523127", "event_type": "price_change"}}
{"_local_timestamp": "2026-01-25T23:42:03.212810+00:00", "data": {"market": "0x0e34be3ee9cb4203fae20b289dfc9a9370f0045ab3fb2e1fa4e6fb82596c678f", "price_changes": [{"asset_id": "12727775089212363162508241557815769734691893483170358591167365904671830747608", "price": "0.52", "size": "11181", "side": "BUY", "hash": "9c93675a23382a0451ccf9da2bec065d9b98b361", "best_bid": "0.56", "best_ask": "0.57"}, {"asset_id": "115183429975003994986742111804963130302445062562951748575181862773257927283380", "price": "0.48", "size": "11181", "side": "SELL", "hash": "95b7dbf7c2e0f3496f56970042353d0813b5a849", "best_bid": "0.43", "best_ask": "0.44"}], "timestamp": "1769384523137", "event_type": "price_change"}}
{"_local_timestamp": "2026-01-25T23:42:03.213064+00:00", "data": {"market": "0x0e34be3ee9cb4203fae20b289dfc9a9370f0045ab3fb2e1fa4e6fb82596c678f", "price_changes": [{"asset_id": "12727775089212363162508241557815769734691893483170358591167365904671830747608", "price": "0.56", "size": "30", "side": "BUY", "hash": "728b1dda1d557914b00cd33ab30dd2947ec13294", "best_bid": "0.56", "best_ask": "0.57"}, {"asset_id": "115183429975003994986742111804963130302445062562951748575181862773257927283380", "price": "0.44", "size": "30", "side": "SELL", "hash": "3b93302896de88f855fe86e635f300b3c5ba2323", "best_bid": "0.43", "best_ask": "0.44"}], "timestamp": "1769384523139", "event_type": "price_change"}}
{"_local_timestamp": "2026-01-25T23:42:03.667566+00:00", "data": {"market": "0x0e34be3ee9cb4203fae20b289dfc9a9370f0045ab3fb2e1fa4e6fb82596c678f", "price_changes": [{"asset_id": "115183429975003994986742111804963130302445062562951748575181862773257927283380", "price": "0.41", "size": "11865", "side": "BUY", "hash": "acfcb82a5e68e95b22a6cf40ef08ac2eb6e5bb32", "best_bid": "0.43", "best_ask": "0.44"}, {"asset_id": "12727775089212363162508241557815769734691893483170358591167365904671830747608", "price": "0.59", "size": "11865", "side": "SELL", "hash": "e4b6dad4f647fb8d8ed3ea28cd622ece87562653", "best_bid": "0.56", "best_ask": "0.57"}], "timestamp": "1769384523602", "event_type": "price_change"}}
{"_local_timestamp": "2026-01-25T23:42:03.791460+00:00", "data": {"market": "0x0e34be3ee9cb4203fae20b289dfc9a9370f0045ab3fb2e1fa4e6fb82596c678f", "price_changes": [{"asset_id": "12727775089212363162508241557815769734691893483170358591167365904671830747608", "price": "0.52", "size": "11176", "side": "BUY", "hash": "03abb3315302c72a10fd6ad3a93380bf7ae2920c", "best_bid": "0.56", "best_ask": "0.57"}, {"asset_id": "115183429975003994986742111804963130302445062562951748575181862773257927283380", "price": "0.48", "size": "11176", "side": "SELL", "hash": "d29246a4b0bee83eb312b778e2f14f7eadeaa22b", "best_bid": "0.43", "best_ask": "0.44"}], "timestamp": "1769384523709", "event_type": "price_change"}}
{"_local_timestamp": "2026-01-25T23:42:03.791817+00:00", "data": {"market": "0xcda8a657998ef072e1d9edd83ce60ada3e75fc4d9113bc3f32a343a93fb1c927", "price_changes": [{"asset_id": "79200508610612497735268197792255474784890164267460369534045305976733489576200", "price": "0.418", "size": "0", "side": "BUY", "hash": "f44ad5253d4e7381bfe37725cc8180d6f435a5a2", "best_bid": "0.43", "best_ask": "0.438"}, {"asset_id": "7064893400396467616058037848568819292052255869002775709074859726119346714372", "price": "0.582", "size": "0", "side": "SELL", "hash": "8111fa467b212b5ffd0ae888775ad0b8c5195ff2", "best_bid": "0.562", "best_ask": "0.57"}], "timestamp": "1769384523713", "event_type": "price_change"}}
{"_local_timestamp": "2026-01-25T23:42:03.825267+00:00", "data": {"market": "0xcda8a657998ef072e1d9edd83ce60ada3e75fc4d9113bc3f32a343a93fb1c927", "price_changes": [{"asset_id": "7064893400396467616058037848568819292052255869002775709074859726119346714372", "price": "0.5", "size": "2644", "side": "BUY", "hash": "3f6830ab0b7a712223112db2a74029bf76c522c5", "best_bid": "0.562", "best_ask": "0.57"}, {"asset_id": "79200508610612497735268197792255474784890164267460369534045305976733489576200", "price": "0.5", "size": "2644", "side": "SELL", "hash": "b12fe2a88daf093da712dc31832d55e89003bfeb", "best_bid": "0.43", "best_ask": "0.438"}], "timestamp": "1769384523755", "event_type": "price_change"}}
{"_local_timestamp": "2026-01-25T23:42:03.825679+00:00", "data": {"market": "0x0e34be3ee9cb4203fae20b289dfc9a9370f0045ab3fb2e1fa4e6fb82596c678f", "price_changes": [{"asset_id": "12727775089212363162508241557815769734691893483170358591167365904671830747608", "price": "0.5", "size": "2686.5", "side": "BUY", "hash": "9908e3baea43e921a7921476b59baccc64064516", "best_bid": "0.56", "best_ask": "0.57"}, {"asset_id": "115183429975003994986742111804963130302445062562951748575181862773257927283380", "price": "0.5", "size": "2686.5", "side": "SELL", "hash": "fb1c4f589ce7d128a7927676253876ddf5e57668", "best_bid": "0.43", "best_ask": "0.44"}], "timestamp": "1769384523756", "event_type": "price_change"}}
{"_local_timestamp": "2026-01-25T23:42:03.825932+00:00", "data": {"market": "0x0e34be3ee9cb4203fae20b289dfc9a9370f0045ab3fb2e1fa4e6fb82596c678f", "price_changes": [{"asset_id": "115183429975003994986742111804963130302445062562951748575181862773257927283380", "price": "0.47", "size": "2730", "side": "SELL", "hash": "6d8aee6342da97cdc238f776dbb524a5f1c250e3", "best_bid": "0.43", "best_ask": "0.44"}, {"asset_id": "12727775089212363162508241557815769734691893483170358591167365904671830747608", "price": "0.53", "size": "2730", "side": "BUY", "hash": "e1afd619ce9d199fdc72eec17e351b343f222514", "best_bid": "0.56", "best_ask": "0.57"}], "timestamp": "1769384523757", "event_type": "price_change"}}
{"_local_timestamp": "2026-01-25T23:42:03.826181+00:00", "data": {"market": "0xcda8a657998ef072e1d9edd83ce60ada3e75fc4d9113bc3f32a343a93fb1c927", "price_changes": [{"asset_id": "79200508610612497735268197792255474784890164267460369534045305976733489576200", "price": "0.47", "size": "1988", "side": "SELL", "hash": "36fca9946cdd4920a814bd1ca82680f2685a38bf", "best_bid": "0.43", "best_ask": "0.438"}, {"asset_id": "7064893400396467616058037848568819292052255869002775709074859726119346714372", "price": "0.53", "size": "1988", "side": "BUY", "hash": "fdf583afa76cf5e3a771e85ee14957cfa752f61b", "best_bid": "0.562", "best_ask": "0.57"}], "timestamp": "1769384523758", "event_type": "price_change"}}
{"_local_timestamp": "2026-01-25T23:42:03.826425+00:00", "data": {"market": "0x0e34be3ee9cb4203fae20b289dfc9a9370f0045ab3fb2e1fa4e6fb82596c678f", "price_changes": [{"asset_id": "12727775089212363162508241557815769734691893483170358591167365904671830747608", "price": "0.53", "size": "742", "side": "BUY", "hash": "ec77bd92cd35a1d01f377608b4314c251374ffd3", "best_bid": "0.56", "best_ask": "0.57"}, {"asset_id": "115183429975003994986742111804963130302445062562951748575181862773257927283380", "price": "0.47", "size": "742", "side": "SELL", "hash": "e7360883beba72faca32a3dd54c8ff8abc9a9fe1", "best_bid": "0.43", "best_ask": "0.44"}], "timestamp": "1769384523758", "event_type": "price_change"}}
{"_local_timestamp": "2026-01-25T23:42:03.826701+00:00", "data": {"market": "0xcda8a657998ef072e1d9edd83ce60ada3e75fc4d9113bc3f32a343a93fb1c927", "price_changes": [{"asset_id": "79200508610612497735268197792255474784890164267460369534045305976733489576200", "price": "0.48", "size": "3259.93", "side": "SELL", "hash": "8f6dcc9103e75e3d7110ab5dd43fd281b62a4e81", "best_bid": "0.43", "best_ask": "0.438"}, {"asset_id": "7064893400396467616058037848568819292052255869002775709074859726119346714372", "price": "0.52", "size": "3259.93", "side": "BUY", "hash": "4bb9d8a07fae196d3bd7c1ee7d54bc52f4a7d21f", "best_bid": "0.562", "best_ask": "0.57"}], "timestamp": "1769384523760", "event_type": "price_change"}}
{"_local_timestamp": "2026-01-25T23:42:03.831748+00:00", "data": {"market": "0xcda8a657998ef072e1d9edd83ce60ada3e75fc4d9113bc3f32a343a93fb1c927", "price_changes": [{"asset_id": "7064893400396467616058037848568819292052255869002775709074859726119346714372", "price": "0.53", "size": "0", "side": "BUY", "hash": "29b9f28fc46aa566e04284b1e21d0d6c99b77bf6", "best_bid": "0.562", "best_ask": "0.57"}, {"asset_id": "79200508610612497735268197792255474784890164267460369534045305976733489576200", "price": "0.47", "size": "0", "side": "SELL", "hash": "5fd80d63f02765c3015ca8f97bff1268200a6a5a", "best_bid": "0.43", "best_ask": "0.438"}], "timestamp": "1769384523761", "event_type": "price_change"}}
{"_local_timestamp": "2026-01-25T23:42:03.853231+00:00", "data": {"market": "0x0e34be3ee9cb4203fae20b289dfc9a9370f0045ab3fb2e1fa4e6fb82596c678f", "price_changes": [{"asset_id": "115183429975003994986742111804963130302445062562951748575181862773257927283380", "price": "0.41", "size": "9803", "side": "BUY", "hash": "00a46178e2a219ef756426091c5f4da7179a85f9", "best_bid": "0.43", "best_ask": "0.44"}, {"asset_id": "12727775089212363162508241557815769734691893483170358591167365904671830747608", "price": "0.59", "size": "9803", "side": "SELL", "hash": "169c2662e3d604767e5e62270872982577018f4b", "best_bid": "0.56", "best_ask": "0.57"}], "timestamp": "1769384523787", "event_type": "price_change"}}
{"_local_timestamp": "2026-01-25T23:42:03.853519+00:00", "data": {"market": "0x0e34be3ee9cb4203fae20b289dfc9a9370f0045ab3fb2e1fa4e6fb82596c678f", "price_changes": [{"asset_id": "115183429975003994986742111804963130302445062562951748575181862773257927283380", "price": "0.42", "size": "1047.61", "side": "BUY", "hash": "00a46178e2a219ef756426091c5f4da7179a85f9", "best_bid": "0.43", "best_ask": "0.44"}, {"asset_id": "12727775089212363162508241557815769734691893483170358591167365904671830747608", "price": "0.58", "size": "1047.61", "side": "SELL", "hash": "169c2662e3d604767e5e62270872982577018f4b", "best_bid": "0.56", "best_ask": "0.57"}], "timestamp": "1769384523787", "event_type": "price_change"}}
{"_local_timestamp": "2026-01-25T23:42:03.853746+00:00", "data": {"market": "0x0e34be3ee9cb4203fae20b289dfc9a9370f0045ab3fb2e1fa4e6fb82596c678f", "price_changes": [{"asset_id": "115183429975003994986742111804963130302445062562951748575181862773257927283380", "price": "0.43", "size": "118", "side": "BUY", "hash": "00a46178e2a219ef756426091c5f4da7179a85f9", "best_bid": "0.43", "best_ask": "0.44"}, {"asset_id": "12727775089212363162508241557815769734691893483170358591167365904671830747608", "price": "0.57", "size": "118", "side": "SELL", "hash": "169c2662e3d604767e5e62270872982577018f4b", "best_bid": "0.56", "best_ask": "0.57"}], "timestamp": "1769384523787", "event_type": "price_change"}}
{"_local_timestamp": "2026-01-25T23:42:03.853960+00:00", "data": {"market": "0x0e34be3ee9cb4203fae20b289dfc9a9370f0045ab3fb2e1fa4e6fb82596c678f", "price_changes": [{"asset_id": "12727775089212363162508241557815769734691893483170358591167365904671830747608", "price": "0.51", "size": "674", "side": "BUY", "hash": "02bf27f2e1a4bda50b9551b947d795abad4a0c84", "best_bid": "0.56", "best_ask": "0.57"}, {"asset_id": "115183429975003994986742111804963130302445062562951748575181862773257927283380", "price": "0.49", "size": "674", "side": "SELL", "hash": "dc254b2bf456fd5502fe7c5ab2ae4f45eb6ed790", "best_bid": "0.43", "best_ask": "0.44"}], "timestamp": "1769384523789", "event_type": "price_change"}}
{"_local_timestamp": "2026-01-25T23:42:03.854211+00:00", "data": {"market": "0x0e34be3ee9cb4203fae20b289dfc9a9370f0045ab3fb2e1fa4e6fb82596c678f", "price_changes": [{"asset_id": "12727775089212363162508241557815769734691893483170358591167365904671830747608", "price": "0.5", "size": "686.5", "side": "BUY", "hash": "02bf27f2e1a4bda50b9551b947d795abad4a0c84", "best_bid": "0.56", "best_ask": "0.57"}, {"asset_id": "115183429975003994986742111804963130302445062562951748575181862773257927283380", "price": "0.5", "size": "686.5", "side": "SELL", "hash": "dc254b2bf456fd5502fe7c5ab2ae4f45eb6ed790", "best_bid": "0.43", "best_ask": "0.44"}], "timestamp": "1769384523789", "event_type": "price_change"}}
{"_local_timestamp": "2026-01-25T23:42:03.865913+00:00", "data": {"market": "0xcda8a657998ef072e1d9edd83ce60ada3e75fc4d9113bc3f32a343a93fb1c927", "price_changes": [{"asset_id": "7064893400396467616058037848568819292052255869002775709074859726119346714372", "price": "0.52", "size": "1267.93", "side": "BUY", "hash": "9fd9220b171c1891f418247022bbe1193114b8b4", "best_bid": "0.562", "best_ask": "0.57"}, {"asset_id": "79200508610612497735268197792255474784890164267460369534045305976733489576200", "price": "0.48", "size": "1267.93", "side": "SELL", "hash": "0255f0dbd6ef5a6e6e92706cb3a717529e301621", "best_bid": "0.43", "best_ask": "0.438"}], "timestamp": "1769384523789", "event_type": "price_change"}}
{"_local_timestamp": "2026-01-25T23:42:03.908561+00:00", "data": {"market": "0xcda8a657998ef072e1d9edd83ce60ada3e75fc4d9113bc3f32a343a93fb1c927", "price_changes": [{"asset_id": "7064893400396467616058037848568819292052255869002775709074859726119346714372", "price": "0.51", "size": "644", "side": "BUY", "hash": "9fd9220b171c1891f418247022bbe1193114b8b4", "best_bid": "0.562", "best_ask": "0.57"}, {"asset_id": "79200508610612497735268197792255474784890164267460369534045305976733489576200", "price": "0.49", "size": "644", "side": "SELL", "hash": "0255f0dbd6ef5a6e6e92706cb3a717529e301621", "best_bid": "0.43", "best_ask": "0.438"}], "timestamp": "1769384523789", "event_type": "price_change"}}
{"_local_timestamp": "2026-01-25T23:42:03.908874+00:00", "data": {"market": "0x0e34be3ee9cb4203fae20b289dfc9a9370f0045ab3fb2e1fa4e6fb82596c678f", "price_changes": [{"asset_id": "12727775089212363162508241557815769734691893483170358591167365904671830747608", "price": "0.52", "size": "9184", "side": "BUY", "hash": "02bf27f2e1a4bda50b9551b947d795abad4a0c84", "best_bid": "0.56", "best_ask": "0.57"}, {"asset_id": "115183429975003994986742111804963130302445062562951748575181862773257927283380", "price": "0.48", "size": "9184", "side": "SELL", "hash": "dc254b2bf456fd5502fe7c5ab2ae4f45eb6ed790", "best_bid": "0.43", "best_ask": "0.44"}], "timestamp": "1769384523789", "event_type": "price_change"}}
{"_local_timestamp": "2026-01-25T23:42:03.909101+00:00", "data": {"market": "0xcda8a657998ef072e1d9edd83ce60ada3e75fc4d9113bc3f32a343a93fb1c927", "price_changes": [{"asset_id": "7064893400396467616058037848568819292052255869002775709074859726119346714372", "price": "0.5", "size": "644", "side": "BUY", "hash": "9fd9220b171c1891f418247022bbe1193114b8b4", "best_bid": "0.562", "best_ask": "0.57"}, {"asset_id": "79200508610612497735268197792255474784890164267460369534045305976733489576200", "price": "0.5", "size": "644", "side": "SELL", "hash": "0255f0dbd6ef5a6e6e92706cb3a717529e301621", "best_bid": "0.43", "best_ask": "0.438"}], "timestamp": "1769384523789", "event_type": "price_change"}}
{"_local_timestamp": "2026-01-25T23:42:03.909321+00:00", "data": {"market": "0xcda8a657998ef072e1d9edd83ce60ada3e75fc4d9113bc3f32a343a93fb1c927", "price_changes": [{"asset_id": "79200508610612497735268197792255474784890164267460369534045305976733489576200", "price": "0.41", "size": "160", "side": "BUY", "hash": "fbc04a9b6215cd4dc811c4ca2eb9bd1c73bfcf05", "best_bid": "0.43", "best_ask": "0.438"}, {"asset_id": "7064893400396467616058037848568819292052255869002775709074859726119346714372", "price": "0.59", "size": "160", "side": "SELL", "hash": "e2302f99023e04100270914fad1d8e5c8c3657ba", "best_bid": "0.562", "best_ask": "0.57"}], "timestamp": "1769384523794", "event_type": "price_change"}}
{"_local_timestamp": "2026-01-25T23:42:03.909547+00:00", "data": {"market": "0xcda8a657998ef072e1d9edd83ce60ada3e75fc4d9113bc3f32a343a93fb1c927", "price_changes": [{"asset_id": "79200508610612497735268197792255474784890164267460369534045305976733489576200", "price": "0.43", "size": "336.9", "side": "BUY", "hash": "fbc04a9b6215cd4dc811c4ca2eb9bd1c73bfcf05", "best_bid": "0.43", "best_ask": "0.438"}, {"asset_id": "7064893400396467616058037848568819292052255869002775709074859726119346714372", "price": "0.57", "size": "336.9", "side": "SELL", "hash": "e2302f99023e04100270914fad1d8e5c8c3657ba", "best_bid": "0.562", "best_ask": "0.57"}], "timestamp": "1769384523794", "event_type": "price_change"}}
{"_local_timestamp": "2026-01-25T23:42:03.909913+00:00", "data": {"market": "0xcda8a657998ef072e1d9edd83ce60ada3e75fc4d9113bc3f32a343a93fb1c927", "price_changes": [{"asset_id": "79200508610612497735268197792255474784890164267460369534045305976733489576200", "price": "0.48", "size": "110", "side": "SELL", "hash": "fbc04a9b6215cd4dc811c4ca2eb9bd1c73bfcf05", "best_bid": "0.43", "best_ask": "0.438"}, {"asset_id": "7064893400396467616058037848568819292052255869002775709074859726119346714372", "price": "0.52", "size": "110", "side": "BUY", "hash": "e2302f99023e04100270914fad1d8e5c8c3657ba", "best_bid": "0.562", "best_ask": "0.57"}], "timestamp": "1769384523794", "event_type": "price_change"}}
{"_local_timestamp": "2026-01-25T23:42:03.910150+00:00", "data": {"market": "0xcda8a657998ef072e1d9edd83ce60ada3e75fc4d9113bc3f32a343a93fb1c927", "price_changes": [{"asset_id": "79200508610612497735268197792255474784890164267460369534045305976733489576200", "price": "0.42", "size": "0", "side": "BUY", "hash": "fbc04a9b6215cd4dc811c4ca2eb9bd1c73bfcf05", "best_bid": "0.43", "best_ask": "0.438"}, {"asset_id": "7064893400396467616058037848568819292052255869002775709074859726119346714372", "price": "0.58", "size": "0", "side": "SELL", "hash": "e2302f99023e04100270914fad1d8e5c8c3657ba", "best_bid": "0.562", "best_ask": "0.57"}], "timestamp": "1769384523794", "event_type": "price_change"}}
{"_local_timestamp": "2026-01-25T23:42:03.947825+00:00", "data": {"market": "0xcda8a657998ef072e1d9edd83ce60ada3e75fc4d9113bc3f32a343a93fb1c927", "price_changes": [{"asset_id": "79200508610612497735268197792255474784890164267460369534045305976733489576200", "price": "0.429", "size": "1977.54", "side": "BUY", "hash": "cfd523009a20d467b115555e27e58f3c82c2ba26", "best_bid": "0.43", "best_ask": "0.438"}, {"asset_id": "7064893400396467616058037848568819292052255869002775709074859726119346714372", "price": "0.571", "size": "1977.54", "side": "SELL", "hash": "b0a987b7e08b955600c7b62133fe736c417a012e", "best_bid": "0.562", "best_ask": "0.57"}], "timestamp": "1769384523878", "event_type": "price_change"}}
{"_local_timestamp": "2026-01-25T23:42:04.025052+00:00", "data": {"market": "0xcda8a657998ef072e1d9edd83ce60ada3e75fc4d9113bc3f32a343a93fb1c927", "price_changes": [{"asset_id": "79200508610612497735268197792255474784890164267460369534045305976733489576200", "price": "0.418", "size": "150", "side": "BUY", "hash": "a7a0f7a85ba333f42a9d43356e0268974ffe92a2", "best_bid": "0.43", "best_ask": "0.438"}, {"asset_id": "7064893400396467616058037848568819292052255869002775709074859726119346714372", "price": "0.582", "size": "150", "side": "SELL", "hash": "e93bc574010fec252f84febc9643cda67ef5838d", "best_bid": "0.562", "best_ask": "0.57"}], "timestamp": "1769384523951", "event_type": "price_change"}}
{"_local_timestamp": "2026-01-25T23:42:04.025422+00:00", "data": {"market": "0xcda8a657998ef072e1d9edd83ce60ada3e75fc4d9113bc3f32a343a93fb1c927", "price_changes": [{"asset_id": "79200508610612497735268197792255474784890164267460369534045305976733489576200", "price": "0.418", "size": "200", "side": "BUY", "hash": "d9855668ecb28bffdafa04de1b679f2ce056e8b5", "best_bid": "0.43", "best_ask": "0.438"}, {"asset_id": "7064893400396467616058037848568819292052255869002775709074859726119346714372", "price": "0.582", "size": "200", "side": "SELL", "hash": "105f1977752132ded4d1fd5988426f2fe0c171ad", "best_bid": "0.562", "best_ask": "0.57"}], "timestamp": "1769384523956", "event_type": "price_change"}}
{"_local_timestamp": "2026-01-25T23:42:04.048828+00:00", "data": {"market": "0x0e34be3ee9cb4203fae20b289dfc9a9370f0045ab3fb2e1fa4e6fb82596c678f", "price_changes": [{"asset_id": "12727775089212363162508241557815769734691893483170358591167365904671830747608", "price": "0.56", "size": "5", "side": "BUY", "hash": "b14f9d106a1a4652f36d6f369851fe9c09596588", "best_bid": "0.56", "best_ask": "0.57"}, {"asset_id": "115183429975003994986742111804963130302445062562951748575181862773257927283380", "price": "0.44", "size": "5", "side": "SELL", "hash": "466486e465ac52df844cedf6b5159da21a3b63be", "best_bid": "0.43", "best_ask": "0.44"}], "timestamp": "1769384523974", "event_type": "price_change"}}
{"_local_timestamp": "2026-01-25T23:42:04.051501+00:00", "data": {"market": "0xcda8a657998ef072e1d9edd83ce60ada3e75fc4d9113bc3f32a343a93fb1c927", "price_changes": [{"asset_id": "79200508610612497735268197792255474784890164267460369534045305976733489576200", "price": "0.418", "size": "250", "side": "BUY", "hash": "57b79affc33be506e721ba1e95776d5f139a13d3", "best_bid": "0.43", "best_ask": "0.438"}, {"asset_id": "7064893400396467616058037848568819292052255869002775709074859726119346714372", "price": "0.582", "size": "250", "side": "SELL", "hash": "8e0bfb4a77e11c7cbc46ae97153ff2cfe6373518", "best_bid": "0.562", "best_ask": "0.57"}], "timestamp": "1769384523980", "event_type": "price_change"}}
{"_local_timestamp": "2026-01-25T23:42:04.051802+00:00", "data": {"market": "0xcda8a657998ef072e1d9edd83ce60ada3e75fc4d9113bc3f32a343a93fb1c927", "price_changes": [{"asset_id": "79200508610612497735268197792255474784890164267460369534045305976733489576200", "price": "0.391", "size": "0", "side": "BUY", "hash": "24bbf9cfedfaf261193d762a8336a870fb866a69", "best_bid": "0.43", "best_ask": "0.438"}, {"asset_id": "7064893400396467616058037848568819292052255869002775709074859726119346714372", "price": "0.609", "size": "0", "side": "SELL", "hash": "5da8d5dca5998b29fe298ea3c2f6422f4a8c32bf", "best_bid": "0.562", "best_ask": "0.57"}], "timestamp": "1769384523985", "event_type": "price_change"}}
{"_local_timestamp": "2026-01-25T23:42:04.129627+00:00", "data": {"market": "0xcda8a657998ef072e1d9edd83ce60ada3e75fc4d9113bc3f32a343a93fb1c927", "price_changes": [{"asset_id": "79200508610612497735268197792255474784890164267460369534045305976733489576200", "price": "0.429", "size": "46.62", "side": "BUY", "hash": "26150daef6dbe9c3bead20a700bac6594a27302b", "best_bid": "0.43", "best_ask": "0.438"}, {"asset_id": "7064893400396467616058037848568819292052255869002775709074859726119346714372", "price": "0.571", "size": "46.62", "side": "SELL", "hash": "d042f7228b935bb1ea43b4a3f2a7fc1a91d8df0c", "best_bid": "0.562", "best_ask": "0.57"}], "timestamp": "1769384524062", "event_type": "price_change"}}
{"_local_timestamp": "2026-01-25T23:42:04.171727+00:00", "data": {"market": "0xcda8a657998ef072e1d9edd83ce60ada3e75fc4d9113bc3f32a343a93fb1c927", "price_changes": [{"asset_id": "79200508610612497735268197792255474784890164267460369534045305976733489576200", "price": "0.429", "size": "164.62", "side": "BUY", "hash": "582aee28a53b72ce9a224f41b93a3318f194b2a2", "best_bid": "0.43", "best_ask": "0.438"}, {"asset_id": "7064893400396467616058037848568819292052255869002775709074859726119346714372", "price": "0.571", "size": "164.62", "side": "SELL", "hash": "36de4b55cc019a0e5bd091dc456f73a37297b0f5", "best_bid": "0.562", "best_ask": "0.57"}], "timestamp": "1769384524102", "event_type": "price_change"}}
{"_local_timestamp": "2026-01-25T23:42:04.211465+00:00", "data": {"market": "0xcda8a657998ef072e1d9edd83ce60ada3e75fc4d9113bc3f32a343a93fb1c927", "price_changes": [{"asset_id": "79200508610612497735268197792255474784890164267460369534045305976733489576200", "price": "0.372", "size": "10", "side": "BUY", "hash": "c3ed7a291c4fa1ca795636840db0caaf51806018", "best_bid": "0.43", "best_ask": "0.438"}, {"asset_id": "7064893400396467616058037848568819292052255869002775709074859726119346714372", "price": "0.628", "size": "10", "side": "SELL", "hash": "761f81d738d1e0e9896ecffc15855aabe8605294", "best_bid": "0.562", "best_ask": "0.57"}], "timestamp": "1769384524136", "event_type": "price_change"}}
{"_local_timestamp": "2026-01-25T23:42:04.685664+00:00", "data": {"market": "0xcda8a657998ef072e1d9edd83ce60ada3e75fc4d9113bc3f32a343a93fb1c927", "price_changes": [{"asset_id": "79200508610612497735268197792255474784890164267460369534045305976733489576200", "price": "0.311", "size": "0", "side": "BUY", "hash": "8bfb88d71ff73f2755f21b043a1faf99b963f94c", "best_bid": "0.43", "best_ask": "0.438"}, {"asset_id": "7064893400396467616058037848568819292052255869002775709074859726119346714372", "price": "0.689", "size": "0", "side": "SELL", "hash": "4a244a1075348ac4d7ed7fa9a12b7408e330a11d", "best_bid": "0.562", "best_ask": "0.57"}], "timestamp": "1769384524617", "event_type": "price_change"}}
{"_local_timestamp": "2026-01-25T23:42:04.716741+00:00", "data": {"market": "0xcda8a657998ef072e1d9edd83ce60ada3e75fc4d9113bc3f32a343a93fb1c927", "price_changes": [{"asset_id": "79200508610612497735268197792255474784890164267460369534045305976733489576200", "price": "0.373", "size": "20", "side": "BUY", "hash": "e0f90cd40a06e640a9ed88acee04b755eb2d8cef", "best_bid": "0.43", "best_ask": "0.438"}, {"asset_id": "7064893400396467616058037848568819292052255869002775709074859726119346714372", "price": "0.627", "size": "20", "side": "SELL", "hash": "4bcc441be57da343ee36e3e4bbe5360ea731fdd1", "best_bid": "0.562", "best_ask": "0.57"}], "timestamp": "1769384524651", "event_type": "price_change"}}
{"_local_timestamp": "2026-01-25T23:42:05.596296+00:00", "data": {"market": "0x0e34be3ee9cb4203fae20b289dfc9a9370f0045ab3fb2e1fa4e6fb82596c678f", "price_changes": [{"asset_id": "12727775089212363162508241557815769734691893483170358591167365904671830747608", "price": "0.54", "size": "160", "side": "BUY", "hash": "bbb04c20af074c0724c7ba14841c6832a7352bd0", "best_bid": "0.56", "best_ask": "0.57"}, {"asset_id": "115183429975003994986742111804963130302445062562951748575181862773257927283380", "price": "0.46", "size": "160", "side": "SELL", "hash": "8ca08c5cb01c0cefc723cd4aaf4f6b1d3ea6f1eb", "best_bid": "0.43", "best_ask": "0.44"}], "timestamp": "1769384525531", "event_type": "price_change"}}
{"_local_timestamp": "2026-01-25T23:42:06.937355+00:00", "data": {"market": "0x0e34be3ee9cb4203fae20b289dfc9a9370f0045ab3fb2e1fa4e6fb82596c678f", "price_changes": [{"asset_id": "115183429975003994986742111804963130302445062562951748575181862773257927283380", "price": "0.41", "size": "863", "side": "BUY", "hash": "4c892f63be4a6a34e597e7ce7f8d10b03c5482eb", "best_bid": "0.43", "best_ask": "0.44"}, {"asset_id": "12727775089212363162508241557815769734691893483170358591167365904671830747608", "price": "0.59", "size": "863", "side": "SELL", "hash": "3199ba05b3a35d68a6ec3f39a0f90f1e346fe68e", "best_bid": "0.56", "best_ask": "0.57"}], "timestamp": "1769384526864", "event_type": "price_change"}}
{"_local_timestamp": "2026-01-25T23:42:06.937772+00:00", "data": {"market": "0x0e34be3ee9cb4203fae20b289dfc9a9370f0045ab3fb2e1fa4e6fb82596c678f", "price_changes": [{"asset_id": "115183429975003994986742111804963130302445062562951748575181862773257927283380", "price": "0.48", "size": "8714", "side": "SELL", "hash": "4c892f63be4a6a34e597e7ce7f8d10b03c5482eb", "best_bid": "0.43", "best_ask": "0.44"}, {"asset_id": "12727775089212363162508241557815769734691893483170358591167365904671830747608", "price": "0.52", "size": "8714", "side": "BUY", "hash": "3199ba05b3a35d68a6ec3f39a0f90f1e346fe68e", "best_bid": "0.56", "best_ask": "0.57"}], "timestamp": "1769384526864", "event_type": "price_change"}}
{"_local_timestamp": "2026-01-25T23:42:06.938144+00:00", "data": {"market": "0x0e34be3ee9cb4203fae20b289dfc9a9370f0045ab3fb2e1fa4e6fb82596c678f", "price_changes": [{"asset_id": "12727775089212363162508241557815769734691893483170358591167365904671830747608", "price": "0.52", "size": "110", "side": "BUY", "hash": "16ee329056c229cd5b98edff61b892fdf5ea3461", "best_bid": "0.56", "best_ask": "0.57"}, {"asset_id": "115183429975003994986742111804963130302445062562951748575181862773257927283380", "price": "0.48", "size": "110", "side": "SELL", "hash": "75a9cf7c7412b2a391ca6c86065bdac45bb1450a", "best_bid": "0.43", "best_ask": "0.44"}], "timestamp": "1769384526865", "event_type": "price_change"}}
{"_local_timestamp": "2026-01-25T23:42:06.944454+00:00", "data": {"market": "0x0e34be3ee9cb4203fae20b289dfc9a9370f0045ab3fb2e1fa4e6fb82596c678f", "price_changes": [{"asset_id": "115183429975003994986742111804963130302445062562951748575181862773257927283380", "price": "0.48", "size": "580", "side": "SELL", "hash": "99e3cdd3b0ca7e200b4e5c01fca552c4e294411b", "best_bid": "0.43", "best_ask": "0.44"}, {"asset_id": "12727775089212363162508241557815769734691893483170358591167365904671830747608", "price": "0.52", "size": "580", "side": "BUY", "hash": "e1168d1b2eedee6a2c1da1bf6a25f877c71c9f8e", "best_bid": "0.56", "best_ask": "0.57"}], "timestamp": "1769384526867", "event_type": "price_change"}}
{"_local_timestamp": "2026-01-25T23:42:06.944793+00:00", "data": {"market": "0x0e34be3ee9cb4203fae20b289dfc9a9370f0045ab3fb2e1fa4e6fb82596c678f", "price_changes": [{"asset_id": "12727775089212363162508241557815769734691893483170358591167365904671830747608", "price": "0.52", "size": "9903", "side": "BUY", "hash": "60620dbb1947fb94f53ab24ee4632e4c35f1e648", "best_bid": "0.56", "best_ask": "0.57"}, {"asset_id": "115183429975003994986742111804963130302445062562951748575181862773257927283380", "price": "0.48", "size": "9903", "side": "SELL", "hash": "0302c0f5582a03ddf20ff4bd6076d4abe44650a7", "best_bid": "0.43", "best_ask": "0.44"}], "timestamp": "1769384526869", "event_type": "price_change"}}
{"_local_timestamp": "2026-01-25T23:42:06.959884+00:00", "data": {"market": "0x0e34be3ee9cb4203fae20b289dfc9a9370f0045ab3fb2e1fa4e6fb82596c678f", "price_changes": [{"asset_id": "115183429975003994986742111804963130302445062562951748575181862773257927283380", "price": "0.47", "size": "150", "side": "SELL", "hash": "b20ff494633a02e4d24960dd97bee70b7610fe44", "best_bid": "0.43", "best_ask": "0.44"}, {"asset_id": "12727775089212363162508241557815769734691893483170358591167365904671830747608", "price": "0.53", "size": "150", "side": "BUY", "hash": "ce9e0fd7a995e9f848558c4649f9276b81cb29c8", "best_bid": "0.56", "best_ask": "0.57"}], "timestamp": "1769384526889", "event_type": "price_change"}}
{"_local_timestamp": "2026-01-25T23:42:06.979213+00:00", "data": {"market": "0x0e34be3ee9cb4203fae20b289dfc9a9370f0045ab3fb2e1fa4e6fb82596c678f", "price_changes": [{"asset_id": "115183429975003994986742111804963130302445062562951748575181862773257927283380", "price": "0.45", "size": "1166.1", "side": "SELL", "hash": "161d946b941ad49f83734537d30e5ab2f6cb4509", "best_bid": "0.43", "best_ask": "0.44"}, {"asset_id": "12727775089212363162508241557815769734691893483170358591167365904671830747608", "price": "0.55", "size": "1166.1", "side": "BUY", "hash": "e36fcba5c2bf9db11ec5b61d1268ed1b92f8e684", "best_bid": "0.56", "best_ask": "0.57"}], "timestamp": "1769384526914", "event_type": "price_change"}}
{"_local_timestamp": "2026-01-25T23:42:07.040831+00:00", "data": {"market": "0x0e34be3ee9cb4203fae20b289dfc9a9370f0045ab3fb2e1fa4e6fb82596c678f", "price_changes": [{"asset_id": "12727775089212363162508241557815769734691893483170358591167365904671830747608", "price": "0.53", "size": "50", "side": "BUY", "hash": "d5ca71acaf4b51fa396d45903ddf50d99f4d7d1d", "best_bid": "0.56", "best_ask": "0.57"}, {"asset_id": "115183429975003994986742111804963130302445062562951748575181862773257927283380", "price": "0.47", "size": "50", "side": "SELL", "hash": "4f51e50b23cfb5d5bc68cfe7bea07da18e50a066", "best_bid": "0.43", "best_ask": "0.44"}], "timestamp": "1769384526977", "event_type": "price_change"}}
{"_local_timestamp": "2026-01-25T23:42:07.050411+00:00", "data": {"market": "0x0e34be3ee9cb4203fae20b289dfc9a9370f0045ab3fb2e1fa4e6fb82596c678f", "price_changes": [{"asset_id": "12727775089212363162508241557815769734691893483170358591167365904671830747608", "price": "0.56", "size": "30", "side": "BUY", "hash": "d5d2522711aa20722a78dc8e8b771dc78f57b34f", "best_bid": "0.56", "best_ask": "0.57"}, {"asset_id": "115183429975003994986742111804963130302445062562951748575181862773257927283380", "price": "0.44", "size": "30", "side": "SELL", "hash": "4a0123e1b819982d0a3fb589e384a1f77459ab3e", "best_bid": "0.43", "best_ask": "0.44"}], "timestamp": "1769384526986", "event_type": "price_change"}}
{"_local_timestamp": "2026-01-25T23:42:07.050762+00:00", "data": {"market": "0x0e34be3ee9cb4203fae20b289dfc9a9370f0045ab3fb2e1fa4e6fb82596c678f", "price_changes": [{"asset_id": "115183429975003994986742111804963130302445062562951748575181862773257927283380", "price": "0.41", "size": "8891", "side": "BUY", "hash": "2ca9223303ec597893d11e536d013a116d422cb6", "best_bid": "0.43", "best_ask": "0.44"}, {"asset_id": "12727775089212363162508241557815769734691893483170358591167365904671830747608", "price": "0.59", "size": "8891", "side": "SELL", "hash": "e4aba54034e6a81d8ceb268bcb8ddf87753547c8", "best_bid": "0.56", "best_ask": "0.57"}], "timestamp": "1769384526988", "event_type": "price_change"}}
{"_local_timestamp": "2026-01-25T23:42:07.100618+00:00", "data": {"market": "0xcda8a657998ef072e1d9edd83ce60ada3e75fc4d9113bc3f32a343a93fb1c927", "price_changes": [{"asset_id": "79200508610612497735268197792255474784890164267460369534045305976733489576200", "price": "0.4", "size": "709", "side": "BUY", "hash": "3c16d99a8119cffd2d1e6f74e86869782c6f7f13", "best_bid": "0.43", "best_ask": "0.438"}, {"asset_id": "7064893400396467616058037848568819292052255869002775709074859726119346714372", "price": "0.6", "size": "709", "side": "SELL", "hash": "ca6cf84f15cd9b13cd9f4ae783ed575c8199f8ec", "best_bid": "0.562", "best_ask": "0.57"}], "timestamp": "1769384527035", "event_type": "price_change"}}
{"_local_timestamp": "2026-01-25T23:42:07.140586+00:00", "data": {"market": "0xcda8a657998ef072e1d9edd83ce60ada3e75fc4d9113bc3f32a343a93fb1c927", "price_changes": [{"asset_id": "79200508610612497735268197792255474784890164267460369534045305976733489576200", "price": "0.38", "size": "200", "side": "BUY", "hash": "2edabc7c86e56147b14f01cdb48611779f2f9a46", "best_bid": "0.43", "best_ask": "0.438"}, {"asset_id": "7064893400396467616058037848568819292052255869002775709074859726119346714372", "price": "0.62", "size": "200", "side": "SELL", "hash": "f0e13d25531d201857d0e737eafe7f833195237a", "best_bid": "0.562", "best_ask": "0.57"}], "timestamp": "1769384527065", "event_type": "price_change"}}
