{"_local_timestamp": "2026-01-25T23:40:30.783749+00:00", "data": [{"market": "0xf9489fd8943a211e64a5f8cc4ad876e8e21454ede9b5a8ad9acf0296b6b04702", "asset_id": "87363809360614939616802255755511451786609322228971360593781048078652109810907", "timestamp": "1769384297852", "hash": "62951b81fd927dc15a48fc3ce46994ecb930bf52", "bids": [{"price": "0.001", "size": "2805"}, {"price": "0.002", "size": "201450"}, {"price": "0.003", "size": "406.63"}, {"price": "0.006", "size": "200"}, {"price": "0.007", "size": "9.76"}, {"price": "0.01", "size": "2010"}, {"price": "0.02", "size": "2300"}, {"price": "0.021", "size": "14.98"}, {"price": "0.05", "size": "630"}, {"price": "0.051", "size": "39"}, {"price": "0.09", "size": "300"}, {"price": "0.091", "size": "17.44"}, {"price": "0.244", "size": "250"}, {"price": "0.245", "size": "3673.46"}, {"price": "0.523", "size": "201"}, {"price": "0.537", "size": "744"}, {"price": "0.538", "size": "148.59"}, {"price": "0.539", "size": "5"}, {"price": "0.823", "size": "141"}, {"price": "0.826", "size": "121"}, {"price": "0.856", "size": "40"}, {"price": "0.858", "size": "10"}, {"price": "0.859", "size": "20"}, {"price": "0.951", "size": "5"}, {"price": "0.953", "size": "25"}, {"price": "0.971", "size": "11"}, {"price": "0.972", "size": "20"}, {"price": "0.994", "size": "144.45"}, {"price": "0.995", "size": "145.64"}], "asks": [{"price": "0.999", "size": "309026.9"}, {"price": "0.998", "size": "10047.28"}], "event_type": "book", "last_trade_price": "0.002"}, {"market": "0x0c473519a0fd7d7dc49f4dde9420e439a96a279147262d94d94440c7bb0c3d1a", "asset_id": "75542494425322153297720389520749706755259470813001035748631847230682534703546", "timestamp": "1769384319342", "hash": "99921a3e9157726021f015b21933600ad2825f08", "bids": [{"price": "0.001", "size": "641.94"}], "asks": [{"price": "0.999", "size": "2761.99"}, {"price": "0.998", "size": "301450"}, {"price": "0.997", "size": "400"}, {"price": "0.996", "size": "8.65"}, {"price": "0.994", "size": "200"}, {"price": "0.99", "size": "2010"}, {"price": "0.989", "size": "8.75"}, {"price": "0.98", "size": "2300"}, {"price": "0.97", "size": "100"}, {"price": "0.969", "size": "8.74"}, {"price": "0.95", "size": "630"}, {"price": "0.949", "size": "39"}, {"price": "0.909", "size": "300"}, {"price": "0.908", "size": "5.16"}, {"price": "0.78", "size": "3000"}, {"price": "0.779", "size": "5.01"}, {"price": "0.661", "size": "5"}, {"price": "0.657", "size": "250"}, {"price": "0.656", "size": "2616.27"}, {"price": "0.2", "size": "700"}, {"price": "0.177", "size": "397"}, {"price": "0.16", "size": "150"}, {"price": "0.159", "size": "355"}, {"price": "0.158", "size": "10"}, {"price": "0.157", "size": "20"}, {"price": "0.06", "size": "25"}, {"price": "0.059", "size": "40"}, {"price": "0.036", "size": "16"}, {"price": "0.019", "size": "7.89"}, {"price": "0.018", "size": "168.19"}, {"price": "0.002", "size": "777.69"}], "event_type": "book", "last_trade_price": "0.001"}, {"market": "0x922e4b06aa5b4f1c10789e4d1bceb3b23a23a111d3a04b2a54d75230a790d1b4", "asset_id": "62643557617577355943605983554546603980679897744241679695433453599898130140289", "timestamp": "1769384290198", "hash": "9d62aca91eb32c21163fce06f6b96e0ce77115c6", "bids": [{"price": "0.001", "size": "4348.33"}, {"price": "0.002", "size": "301450"}, {"price": "0.003", "size": "406.63"}, {"price": "0.006", "size": "200"}, {"price": "0.007", "size": "9.76"}, {"price": "0.01", "size": "2010"}, {"price": "0.02", "size": "2300"}, {"price": "0.021", "size": "12.94"}, {"price": "0.05", "size": "630"}, {"price": "0.051", "size": "39"}, {"price": "0.09", "size": "300"}, {"price": "0.091", "size": "17.95"}, {"price": "0.304", "size": "6"}, {"price": "0.305", "size": "250"}, {"price": "0.306", "size": "2941.17"}, {"price": "0.49", "size": "700"}, {"price": "0.491", "size": "206"}, {"price": "0.777", "size": "128"}, {"price": "0.779", "size": "40"}, {"price": "0.781", "size": "10"}, {"price": "0.782", "size": "20"}, {"price": "0.951", "size": "10"}, {"price": "0.96", "size": "739.04"}, {"price": "0.961", "size": "38.19"}, {"price": "0.963", "size": "25"}, {"price": "0.976", "size": "31"}, {"price": "0.988", "size": "5.97"}, {"price": "0.991", "size": "33.86"}, {"price": "0.996", "size": "265.24"}], "asks": [{"price": "0.999", "size": "1358.03"}], "event_type": "book", "last_trade_price": "0.001"}, {"market": "0x76c29af7fdae5e892d4e4a07c561d9369f26bcea68c8cf74446b7721f36f45c0", "asset_id": "70920736873132577919043852770207478180247569812569419374051281724093244013193", "timestamp": "1769384410389", "hash": "d6f29d7c69a3a66a86f56ce7ebe7134309b4d2b1", "bids": [{"price": "0.001", "size": "1059.28"}], "asks": [{"price": "0.999", "size": "4308.99"}, {"price": "0.998", "size": "301450"}, {"price": "0.997", "size": "400"}, {"price": "0.996", "size": "8.65"}, {"price": "0.994", "size": "200"}, {"price": "0.99", "size": "2010"}, {"price": "0.989", "size": "8.75"}, {"price": "0.98", "size": "2300"}, {"price": "0.97", "size": "100"}, {"price": "0.969", "size": "7.24"}, {"price": "0.95", "size": "630"}, {"price": "0.949", "size": "39"}, {"price": "0.92", "size": "100"}, {"price": "0.919", "size": "5.62"}, {"price": "0.908", "size": "300"}, {"price": "0.86", "size": "50"}, {"price": "0.8", "size": "200"}, {"price": "0.799", "size": "5.84"}, {"price": "0.777", "size": "87"}, {"price": "0.72", "size": "250"}, {"price": "0.719", "size": "3402.84"}, {"price": "0.717", "size": "30"}, {"price": "0.66", "size": "100"}, {"price": "0.659", "size": "5"}, {"price": "0.177", "size": "172"}, {"price": "0.176", "size": "10"}, {"price": "0.15", "size": "40"}, {"price": "0.08", "size": "150"}, {"price": "0.079", "size": "15"}, {"price": "0.078", "size": "20"}, {"price": "0.05", "size": "1000"}, {"price": "0.044", "size": "5"}, {"price": "0.043", "size": "10"}, {"price": "0.042", "size": "16"}, {"price": "0.041", "size": "25"}, {"price": "0.003", "size": "12.75"}, {"price": "0.002", "size": "880.2"}], "event_type": "book", "last_trade_price": "0.001"}, {"market": "0x7bc69219ef0d98cf1052e760908aa227fdc2b45e70e0469c53457266ee4f555b", "asset_id": "18584298671564073928388576844101198739042674309692107459010136899299606833542", "timestamp": "1769384324511", "hash": "4d08bf86d16ec6fdc2fbcc8a17f6a086dae9c4ed", "bids": [{"price": "0.001", "size": "786.59"}], "asks": [{"price": "0.999", "size": "4304"}, {"price": "0.998", "size": "301450"}, {"price": "0.997", "size": "406.62"}, {"price": "0.994", "size": "200"}, {"price": "0.993", "size": "9.76"}, {"price": "0.99", "size": "2010"}, {"price": "0.98", "size": "2200"}, {"price": "0.979", "size": "6.89"}, {"price": "0.95", "size": "630"}, {"price": "0.949", "size": "39"}, {"price": "0.947", "size": "10.43"}, {"price": "0.884", "size": "300"}, {"price": "0.809", "size": "250"}, {"price": "0.808", "size": "4687.5"}, {"price": "0.807", "size": "6.23"}, {"price": "0.777", "size": "73"}, {"price": "0.776", "size": "8"}, {"price": "0.189", "size": "492"}, {"price": "0.177", "size": "185"}, {"price": "0.14", "size": "150"}, {"price": "0.139", "size": "116"}, {"price": "0.077", "size": "224"}, {"price": "0.076", "size": "20"}, {"price": "0.057", "size": "10"}, {"price": "0.054", "size": "56"}, {"price": "0.053", "size": "16"}, {"price": "0.052", "size": "25"}, {"price": "0.007", "size": "8"}, {"price": "0.003", "size": "17.54"}, {"price": "0.002", "size": "804.9"}], "event_type": "book", "last_trade_price": "0.001"}, {"market": "0x003478da73863b7555a88a4a240042edbdfa9ce2afbab32f34ec97dbd80c5ab7", "asset_id": "15388846204487952420250024653778730612452760958783811368620029058645994602122", "timestamp": "1769384409797", "hash": "275eb4e26fae6dd45995f997129f835ecdd71545", "bids": [{"price": "0.001", "size": "3249"}, {"price": "0.002", "size": "250"}, {"price": "0.003", "size": "172.62"}, {"price": "0.006", "size": "83"}, {"price": "0.007", "size": "9.76"}, {"price": "0.01", "size": "53210"}, {"price": "0.02", "size": "2200"}, {"price": "0.021", "size": "14.97"}, {"price": "0.05", "size": "630"}, {"price": "0.051", "size": "39"}, {"price": "0.09", "size": "300"}, {"price": "0.091", "size": "17.44"}, {"price": "0.299", "size": "6"}, {"price": "0.306", "size": "300"}, {"price": "0.308", "size": "746"}, {"price": "0.92", "size": "202"}, {"price": "0.925", "size": "15"}, {"price": "0.926", "size": "20"}, {"price": "0.942", "size": "10"}, {"price": "0.946", "size": "46"}, {"price": "0.947", "size": "10"}, {"price": "0.948", "size": "16"}, {"price": "0.949", "size": "25"}, {"price": "0.997", "size": "258.54"}, {"price": "0.998", "size": "667.44"}], "asks": [{"price": "0.999", "size": "1638.41"}], "event_type": "book", "last_trade_price": "0.001"}, {"market": "0x73ad1ccf984fe936e2d38bfe6f9e0479d9780b07290d01495cfc0fe6e889665a", "asset_id": "106144597899636887285661247566617521480303783850130038753142172360623351151116", "timestamp": "1769384410125", "hash": "a21d52f2e2f76df6fcbd4d1592ca3ccdd76a1f4b", "bids": [{"price": "0.001", "size": "5015.56"}], "asks": [{"price": "0.999", "size": "4305.04"}, {"price": "0.998", "size": "201450"}, {"price": "0.997", "size": "400"}, {"price": "0.996", "size": "8.71"}, {"price": "0.994", "size": "200"}, {"price": "0.99", "size": "2010"}, {"price": "0.989", "size": "8.8"}, {"price": "0.98", "size": "2300"}, {"price": "0.97", "size": "100"}, {"price": "0.969", "size": "7.28"}, {"price": "0.95", "size": "630"}, {"price": "0.949", "size": "39"}, {"price": "0.92", "size": "100"}, {"price": "0.919", "size": "5.65"}, {"price": "0.91", "size": "300"}, {"price": "0.86", "size": "50"}, {"price": "0.8", "size": "200"}, {"price": "0.799", "size": "5.84"}, {"price": "0.777", "size": "73"}, {"price": "0.724", "size": "250"}, {"price": "0.723", "size": "3449.09"}, {"price": "0.66", "size": "100"}, {"price": "0.51", "size": "700"}, {"price": "0.477", "size": "201"}, {"price": "0.476", "size": "5"}, {"price": "0.177", "size": "185"}, {"price": "0.175", "size": "10"}, {"price": "0.174", "size": "40"}, {"price": "0.09", "size": "150"}, {"price": "0.084", "size": "15"}, {"price": "0.083", "size": "20"}, {"price": "0.05", "size": "1000"}, {"price": "0.048", "size": "16.66"}, {"price": "0.047", "size": "25"}, {"price": "0.005", "size": "8.59"}, {"price": "0.004", "size": "48.7"}, {"price": "0.003", "size": "159.65"}, {"price": "0.002", "size": "491.36"}], "event_type": "book", "last_trade_price": "0.001"}, {"market": "0x88298e294408106c07c49520e9bf10c7dc469afe13e834be34d95e82bc36542e", "asset_id": "28970242768597401097961438832075151737962074789968575309469772733732578617699", "timestamp": "1769384398647", "hash": "9525060408412ec147851efc376bc42059d7bf6e", "bids": [{"price": "0.001", "size": "535546.79"}, {"price": "0.002", "size": "59999.54"}, {"price": "0.003", "size": "10255"}, {"price": "0.004", "size": "2250"}, {"price": "0.005", "size": "98.56"}], "asks": [{"price": "0.999", "size": "203955"}, {"price": "0.998", "size": "250"}, {"price": "0.997", "size": "406.63"}, {"price": "0.994", "size": "200"}, {"price": "0.993", "size": "9.76"}, {"price": "0.99", "size": "2010"}, {"price": "0.98", "size": "2200"}, {"price": "0.979", "size": "6.89"}, {"price": "0.95", "size": "630"}, {"price": "0.949", "size": "39"}, {"price": "0.948", "size": "5.96"}, {"price": "0.85", "size": "300"}, {"price": "0.849", "size": "5960.26"}, {"price": "0.836", "size": "6"}, {"price": "0.833", "size": "8.66"}, {"price": "0.832", "size": "11"}, {"price": "0.477", "size": "201"}, {"price": "0.476", "size": "10"}, {"price": "0.177", "size": "185"}, {"price": "0.09", "size": "850"}, {"price": "0.084", "size": "400"}, {"price": "0.083", "size": "207.93"}, {"price": "0.081", "size": "15"}, {"price": "0.075", "size": "40"}, {"price": "0.073", "size": "10"}, {"price": "0.072", "size": "20"}, {"price": "0.047", "size": "50"}, {"price": "0.045", "size": "25"}, {"price": "0.025", "size": "60"}, {"price": "0.016", "size": "97.6"}, {"price": "0.012", "size": "6.88"}, {"price": "0.011", "size": "0.11"}, {"price": "0.01", "size": "87.68"}, {"price": "0.009", "size": "14"}], "event_type": "book", "last_trade_price": "0.005"}, {"market": "0x9ff5cedb966c4ce0c5f0da7dd827f769ef3d9fb4c662fd1a13dce3cfdb5f6e5e", "asset_id": "38503258109330545049739643067830963325321354481872200149686592473366119549035", "timestamp": "1769384334065", "hash": "991fcef4676e7de6202698fa5573824986cc362c", "bids": [{"price": "0.001", "size": "505503"}, {"price": "0.002", "size": "20250"}, {"price": "0.003", "size": "406.62"}, {"price": "0.006", "size": "200"}, {"price": "0.007", "size": "9.76"}, {"price": "0.01", "size": "2010"}, {"price": "0.02", "size": "2200"}, {"price": "0.021", "size": "6.89"}, {"price": "0.05", "size": "630"}, {"price": "0.051", "size": "39"}, {"price": "0.052", "size": "7.6"}, {"price": "0.15", "size": "6300"}, {"price": "0.151", "size": "9.01"}, {"price": "0.39", "size": "151.21"}, {"price": "0.417", "size": "5"}, {"price": "0.438", "size": "100"}, {"price": "0.443", "size": "10"}, {"price": "0.453", "size": "10"}, {"price": "0.454", "size": "674"}, {"price": "0.455", "size": "219"}, {"price": "0.456", "size": "25"}, {"price": "0.458", "size": "25"}, {"price": "0.46", "size": "40"}, {"price": "0.461", "size": "20"}, {"price": "0.951", "size": "5"}, {"price": "0.955", "size": "169"}, {"price": "0.966", "size": "51.24"}, {"price": "0.97", "size": "23.33"}, {"price": "0.979", "size": "87.41"}, {"price": "0.986", "size": "24.34"}, {"price": "0.992", "size": "60.08"}, {"price": "0.994", "size": "5"}], "asks": [{"price": "0.999", "size": "2491.24"}, {"price": "0.998", "size": "197.28"}], "event_type": "book", "last_trade_price": "0.002"}, {"market": "0x9ff5cedb966c4ce0c5f0da7dd827f769ef3d9fb4c662fd1a13dce3cfdb5f6e5e", "asset_id": "33926193055016677000725490855297544366307667383544420005648237701850394575691", "timestamp": "1769384334065", "hash": "af9a314c70b72d652bcffde4a7a7d4fb46b05c5f", "bids": [{"price": "0.001", "size": "2491.24"}, {"price": "0.002", "size": "197.28"}], "asks": [{"price": "0.999", "size": "505503"}, {"price": "0.998", "size": "20250"}, {"price": "0.997", "size": "406.62"}, {"price": "0.994", "size": "200"}, {"price": "0.993", "size": "9.76"}, {"price": "0.99", "size": "2010"}, {"price": "0.98", "size": "2200"}, {"price": "0.979", "size": "6.89"}, {"price": "0.95", "size": "630"}, {"price": "0.949", "size": "39"}, {"price": "0.948", "size": "7.6"}, {"price": "0.85", "size": "6300"}, {"price": "0.849", "size": "9.01"}, {"price": "0.61", "size": "151.21"}, {"price": "0.583", "size": "5"}, {"price": "0.562", "size": "100"}, {"price": "0.557", "size": "10"}, {"price": "0.547", "size": "10"}, {"price": "0.546", "size": "674"}, {"price": "0.545", "size": "219"}, {"price": "0.544", "size": "25"}, {"price": "0.542", "size": "25"}, {"price": "0.54", "size": "40"}, {"price": "0.539", "size": "20"}, {"price": "0.049", "size": "5"}, {"price": "0.045", "size": "169"}, {"price": "0.034", "size": "51.24"}, {"price": "0.03", "size": "23.33"}, {"price": "0.021", "size": "87.41"}, {"price": "0.014", "size": "24.34"}, {"price": "0.008", "size": "60.08"}, {"price": "0.006", "size": "5"}], "event_type": "book", "last_trade_price": "0.002"}, {"market": "0xc07928d93d2e9ae459edba5b537bcdcb4f59abcdca19ee1d4dc88c7474cfd5e0", "asset_id": "15596315259806586303408002371753656561550066663906359186784326959810935330986", "timestamp": "1769384409797", "hash": "a3368332acf7a12be7addaa810b1b45dff75fb23", "bids": [{"price": "0.001", "size": "2704.99"}, {"price": "0.002", "size": "201450"}, {"price": "0.003", "size": "400"}, {"price": "0.004", "size": "8.65"}, {"price": "0.006", "size": "200"}, {"price": "0.01", "size": "2010"}, {"price": "0.011", "size": "8.75"}, {"price": "0.02", "size": "2300"}, {"price": "0.03", "size": "100"}, {"price": "0.031", "size": "7.24"}, {"price": "0.05", "size": "630"}, {"price": "0.051", "size": "39"}, {"price": "0.08", "size": "400"}, {"price": "0.081", "size": "5.62"}, {"price": "0.14", "size": "50"}, {"price": "0.2", "size": "200"}, {"price": "0.201", "size": "5.84"}, {"price": "0.223", "size": "73"}, {"price": "0.27", "size": "200"}, {"price": "0.272", "size": "250"}, {"price": "0.341", "size": "2739.29"}, {"price": "0.523", "size": "201"}, {"price": "0.539", "size": "5"}, {"price": "0.823", "size": "185"}, {"price": "0.824", "size": "10"}, {"price": "0.854", "size": "40"}, {"price": "0.858", "size": "25"}, {"price": "0.859", "size": "20"}, {"price": "0.95", "size": "1000"}, {"price": "0.951", "size": "25"}, {"price": "0.991", "size": "12.34"}, {"price": "0.993", "size": "69.95"}, {"price": "0.995", "size": "136.6"}, {"price": "0.996", "size": "28.57"}, {"price": "0.997", "size": "5.46"}, {"price": "0.998", "size": "410.47"}], "asks": [{"price": "0.999", "size": "1478.4"}], "event_type": "book", "last_trade_price": "0.001"}, {"market": "0xa4dad4202b71fcd1387651e9eae72cb138c9b61c4194f93f5e8da4a3d534269c", "asset_id": "80457400145229493285131901610968168953953012727977795272540798397863492712492", "timestamp": "1769384375495", "hash": "5859001ee837b287058278146f6a9f99798d5147", "bids": [{"price": "0.001", "size": "2823"}, {"price": "0.002", "size": "201450"}, {"price": "0.003", "size": "406.62"}, {"price": "0.006", "size": "200"}, {"price": "0.007", "size": "9.76"}, {"price": "0.01", "size": "2010"}, {"price": "0.02", "size": "1800"}, {"price": "0.021", "size": "12.96"}, {"price": "0.05", "size": "30"}, {"price": "0.051", "size": "39"}, {"price": "0.052", "size": "2000"}, {"price": "0.08", "size": "100"}, {"price": "0.081", "size": "5.62"}, {"price": "0.09", "size": "300"}, {"price": "0.14", "size": "50"}, {"price": "0.2", "size": "200"}, {"price": "0.201", "size": "5.84"}, {"price": "0.27", "size": "200"}, {"price": "0.348", "size": "250"}, {"price": "0.349", "size": "2678.79"}, {"price": "0.35", "size": "40"}, {"price": "0.351", "size": "10"}, {"price": "0.352", "size": "5"}, {"price": "0.698", "size": "25"}, {"price": "0.699", "size": "20"}, {"price": "0.95", "size": "1174.56"}, {"price": "0.951", "size": "500"}, {"price": "0.952", "size": "252.53"}, {"price": "0.954", "size": "25"}, {"price": "0.962", "size": "20"}, {"price": "0.978", "size": "98.4"}, {"price": "0.981", "size": "34.96"}, {"price": "0.987", "size": "41.1"}, {"price": "0.988", "size": "64"}], "asks": [{"price": "0.999", "size": "506417"}, {"price": "0.998", "size": "250889.21"}, {"price": "0.997", "size": "150000"}, {"price": "0.996", "size": "5000"}, {"price": "0.995", "size": "250"}, {"price": "0.99", "size": "917.18"}], "event_type": "book", "last_trade_price": "0.010"}, {"market": "0x922e4b06aa5b4f1c10789e4d1bceb3b23a23a111d3a04b2a54d75230a790d1b4", "asset_id": "67461470194930786130315916571100744094933697359761375026443878409128440673645", "timestamp": "1769384290198", "hash": "819122709b798fb55b0aff7035537bb84e320f8f", "bids": [{"price": "0.001", "size": "1358.03"}], "asks": [{"price": "0.999", "size": "4348.33"}, {"price": "0.998", "size": "301450"}, {"price": "0.997", "size": "406.63"}, {"price": "0.994", "size": "200"}, {"price": "0.993", "size": "9.76"}, {"price": "0.99", "size": "2010"}, {"price": "0.98", "size": "2300"}, {"price": "0.979", "size": "12.94"}, {"price": "0.95", "size": "630"}, {"price": "0.949", "size": "39"}, {"price": "0.91", "size": "300"}, {"price": "0.909", "size": "17.95"}, {"price": "0.696", "size": "6"}, {"price": "0.695", "size": "250"}, {"price": "0.694", "size": "2941.17"}, {"price": "0.51", "size": "700"}, {"price": "0.509", "size": "206"}, {"price": "0.223", "size": "128"}, {"price": "0.221", "size": "40"}, {"price": "0.219", "size": "10"}, {"price": "0.218", "size": "20"}, {"price": "0.049", "size": "10"}, {"price": "0.04", "size": "739.04"}, {"price": "0.039", "size": "38.19"}, {"price": "0.037", "size": "25"}, {"price": "0.024", "size": "31"}, {"price": "0.012", "size": "5.97"}, {"price": "0.009", "size": "33.86"}, {"price": "0.004", "size": "265.24"}], "event_type": "book", "last_trade_price": "0.001"}, {"market": "0x64e049eddd2da2ea85d3e7dd529efabb83e52bb9f10e78ca5e06c0e4c5ef0e02", "asset_id": "96688790171056136704679313409054589073276180181982810079705385951588572412760", "timestamp": "1769384393086", "hash": "9045629b477a6dacc864d2078988bdfc71646212", "bids": [{"price": "0.001", "size": "4314.32"}, {"price": "0.002", "size": "250"}, {"price": "0.003", "size": "302606.64"}, {"price": "0.006", "size": "200"}, {"price": "0.007", "size": "9.79"}, {"price": "0.01", "size": "1010"}, {"price": "0.02", "size": "2200"}, {"price": "0.021", "size": "13.04"}, {"price": "0.05", "size": "630"}, {"price": "0.051", "size": "39"}, {"price": "0.08", "size": "3300"}, {"price": "0.081", "size": "20.09"}, {"price": "0.276", "size": "250"}, {"price": "0.277", "size": "3256.09"}, {"price": "0.771", "size": "185"}, {"price": "0.813", "size": "123"}, {"price": "0.814", "size": "10"}, {"price": "0.815", "size": "40"}, {"price": "0.816", "size": "25"}, {"price": "0.9", "size": "150"}, {"price": "0.901", "size": "20"}, {"price": "0.953", "size": "87.41"}, {"price": "0.96", "size": "500"}, {"price": "0.961", "size": "70.57"}, {"price": "0.968", "size": "10"}, {"price": "0.982", "size": "6.91"}, {"price": "0.983", "size": "19.78"}, {"price": "0.984", "size": "25"}], "asks": [{"price": "0.999", "size": "8760"}, {"price": "0.998", "size": "10124.21"}, {"price": "0.997", "size": "250"}, {"price": "0.99", "size": "1099.86"}], "event_type": "book", "last_trade_price": "0.010"}, {"market": "0x4f40e41d6ba58848f8d01d4b291f54c693e3a2e7ee490800459af35f8b1b9038", "asset_id": "73853268877233301425516175263410875167064672110922243604576539593244418639141", "timestamp": "1769384316871", "hash": "eccbcb84df3d1b0197e0c75c929d1a06f7ef425e", "bids": [{"price": "0.001", "size": "2748"}, {"price": "0.002", "size": "201450"}, {"price": "0.003", "size": "406.62"}, {"price": "0.006", "size": "200"}, {"price": "0.007", "size": "10.45"}, {"price": "0.01", "size": "2010"}, {"price": "0.02", "size": "1000"}, {"price": "0.021", "size": "2800"}, {"price": "0.022", "size": "6.36"}, {"price": "0.05", "size": "30"}, {"price": "0.051", "size": "3039"}, {"price": "0.052", "size": "6.87"}, {"price": "0.137", "size": "300"}, {"price": "0.138", "size": "10.14"}, {"price": "0.223", "size": "87"}, {"price": "0.309", "size": "306"}, {"price": "0.31", "size": "2903.22"}, {"price": "0.311", "size": "381"}, {"price": "0.823", "size": "185"}, {"price": "0.824", "size": "10"}, {"price": "0.853", "size": "117"}, {"price": "0.879", "size": "40"}, {"price": "0.88", "size": "20"}, {"price": "0.95", "size": "713"}, {"price": "0.957", "size": "5"}, {"price": "0.958", "size": "10"}, {"price": "0.959", "size": "16"}, {"price": "0.96", "size": "25"}, {"price": "0.997", "size": "12.75"}, {"price": "0.998", "size": "715.22"}], "asks": [{"price": "0.999", "size": "4632.29"}], "event_type": "book", "last_trade_price": "0.001"}, {"market": "0x949c9ec867ff713ee52ab749498e761b737139dbcf3cee2fce4fb97fcddc8332", "asset_id": "14388290902643650435293090680587869555316527818926326372933718414371708858517", "timestamp": "1769384316806", "hash": "7c0d6be4277e93b0f540448872f5c35a686dc9cd", "bids": [{"price": "0.001", "size": "503952.13"}, {"price": "0.002", "size": "250"}, {"price": "0.003", "size": "400"}, {"price": "0.004", "size": "8.67"}, {"price": "0.006", "size": "200"}, {"price": "0.01", "size": "2010"}, {"price": "0.011", "size": "8.77"}, {"price": "0.02", "size": "2300"}, {"price": "0.03", "size": "100"}, {"price": "0.031", "size": "7.26"}, {"price": "0.05", "size": "630"}, {"price": "0.051", "size": "39"}, {"price": "0.08", "size": "100"}, {"price": "0.081", "size": "5.63"}, {"price": "0.096", "size": "300"}, {"price": "0.14", "size": "50"}, {"price": "0.2", "size": "200"}, {"price": "0.201", "size": "5.83"}, {"price": "0.271", "size": "3521.03"}, {"price": "0.34", "size": "100"}, {"price": "0.35", "size": "5"}, {"price": "0.351", "size": "247"}, {"price": "0.92", "size": "882.17"}, {"price": "0.924", "size": "25"}, {"price": "0.925", "size": "20"}, {"price": "0.942", "size": "10"}, {"price": "0.946", "size": "72"}, {"price": "0.947", "size": "25"}, {"price": "0.989", "size": "10"}, {"price": "0.995", "size": "18.41"}, {"price": "0.997", "size": "127.09"}, {"price": "0.998", "size": "1022.63"}], "asks": [{"price": "0.999", "size": "1375.23"}], "event_type": "book", "last_trade_price": "0.001"}, {"market": "0xe8aa6e2e78b148ade04614fb635df30b6e7101bb356ae0d049e8f17fad3df4f7", "asset_id": "82381608296304959049355559600146889289834297440752377216630323877678083558940", "timestamp": "1769384322656", "hash": "a0d59b60454bdd70f831f84ca8a307041a7b5062", "bids": [{"price": "0.001", "size": "4182"}, {"price": "0.002", "size": "301450"}, {"price": "0.003", "size": "406.62"}, {"price": "0.006", "size": "200"}, {"price": "0.007", "size": "9.76"}, {"price": "0.01", "size": "2010"}, {"price": "0.02", "size": "2300"}, {"price": "0.021", "size": "6.89"}, {"price": "0.05", "size": "630"}, {"price": "0.051", "size": "39"}, {"price": "0.052", "size": "10.56"}, {"price": "0.094", "size": "300"}, {"price": "0.19", "size": "3000"}, {"price": "0.191", "size": "6.32"}, {"price": "0.222", "size": "300"}, {"price": "0.223", "size": "4035.87"}, {"price": "0.341", "size": "5"}, {"price": "0.823", "size": "179"}, {"price": "0.83", "size": "700"}, {"price": "0.831", "size": "240"}, {"price": "0.861", "size": "116"}, {"price": "0.92", "size": "150"}, {"price": "0.921", "size": "20"}, {"price": "0.943", "size": "10"}, {"price": "0.946", "size": "40"}, {"price": "0.947", "size": "25"}, {"price": "0.991", "size": "8.43"}, {"price": "0.993", "size": "47.77"}, {"price": "0.995", "size": "302.5"}, {"price": "0.996", "size": "298.53"}, {"price": "0.998", "size": "382.28"}], "asks": [{"price": "0.999", "size": "1606.29"}], "event_type": "book", "last_trade_price": "0.001"}, {"market": "0x6bc389514aeed2d49f77818df91931b8f47bca741b922b5aa581bcd285898ecf", "asset_id": "62692103489206718495616938107149784138085199695151413614837109358489160284585", "timestamp": "1769384316806", "hash": "a7693b24e79fa4df1b6d3883fcb115831cfdb252", "bids": [{"price": "0.001", "size": "2246.97"}], "asks": [{"price": "0.999", "size": "2808.99"}, {"price": "0.998", "size": "301450"}, {"price": "0.997", "size": "400"}, {"price": "0.996", "size": "8.65"}, {"price": "0.994", "size": "200"}, {"price": "0.99", "size": "2010"}, {"price": "0.989", "size": "8.75"}, {"price": "0.98", "size": "2300"}, {"price": "0.975", "size": "9"}, {"price": "0.97", "size": "100"}, {"price": "0.969", "size": "7.24"}, {"price": "0.95", "size": "630"}, {"price": "0.949", "size": "39"}, {"price": "0.92", "size": "400"}, {"price": "0.919", "size": "5.62"}, {"price": "0.86", "size": "50"}, {"price": "0.8", "size": "200"}, {"price": "0.799", "size": "5.84"}, {"price": "0.728", "size": "250"}, {"price": "0.727", "size": "3496.7"}, {"price": "0.66", "size": "100"}, {"price": "0.515", "size": "5"}, {"price": "0.473", "size": "25"}, {"price": "0.471", "size": "10"}, {"price": "0.469", "size": "40"}, {"price": "0.468", "size": "20"}, {"price": "0.05", "size": "1200"}, {"price": "0.049", "size": "15.15"}, {"price": "0.047", "size": "157.99"}, {"price": "0.046", "size": "25"}, {"price": "0.022", "size": "20"}, {"price": "0.004", "size": "5.66"}, {"price": "0.003", "size": "24.61"}], "event_type": "book", "last_trade_price": "0.001"}, {"market": "0x091010f5fa0aed8218a8f2ef38ca6f75a04b86207e9d9a3464c76acedae5ff71", "asset_id": "30914129377008299105825712463210268035742945099105633197958126446720250780230", "timestamp": "1769384407583", "hash": "4afb319f30f2aa7e9d70482b703a50742a5ce07d", "bids": [{"price": "0.001", "size": "5697.28"}], "asks": [{"price": "0.999", "size": "2690"}, {"price": "0.998", "size": "201450"}, {"price": "0.997", "size": "406.62"}, {"price": "0.994", "size": "200"}, {"price": "0.993", "size": "9.76"}, {"price": "0.99", "size": "2010"}, {"price": "0.98", "size": "2200"}, {"price": "0.979", "size": "15.17"}, {"price": "0.95", "size": "630"}, {"price": "0.949", "size": "39"}, {"price": "0.905", "size": "9773.68"}, {"price": "0.904", "size": "16.49"}, {"price": "0.557", "size": "5"}, {"price": "0.554", "size": "400"}, {"price": "0.552", "size": "446"}, {"price": "0.551", "size": "622"}, {"price": "0.55", "size": "13.33"}, {"price": "0.546", "size": "25"}, {"price": "0.544", "size": "10"}, {"price": "0.542", "size": "40"}, {"price": "0.54", "size": "25"}, {"price": "0.539", "size": "20"}, {"price": "0.012", "size": "5.69"}, {"price": "0.009", "size": "32.28"}, {"price": "0.003", "size": "12.67"}, {"price": "0.002", "size": "207.38"}], "event_type": "book", "last_trade_price": "0.001"}, {"market": "0x1786c149f32f75fa909fbfab4f7b273975b6da5b76ad6d43200f927a1690f1e8", "asset_id": "25541691838497877440175161707261211792942265656882782730327118132070277416890", "timestamp": "1769384391979", "hash": "01fb3899294644fd455626a7612653dfbe811020", "bids": [{"price": "0.01", "size": "168083.07"}, {"price": "0.02", "size": "63869.19"}, {"price": "0.03", "size": "32206.72"}, {"price": "0.04", "size": "1036.87"}, {"price": "0.05", "size": "765.99"}, {"price": "0.06", "size": "30"}], "asks": [{"price": "0.99", "size": "8210"}, {"price": "0.98", "size": "3300"}, {"price": "0.97", "size": "100"}, {"price": "0.95", "size": "620"}, {"price": "0.94", "size": "33"}, {"price": "0.87", "size": "3400"}, {"price": "0.86", "size": "50"}, {"price": "0.81", "size": "600"}, {"price": "0.8", "size": "200"}, {"price": "0.79", "size": "100"}, {"price": "0.73", "size": "200"}, {"price": "0.66", "size": "100"}, {"price": "0.17", "size": "1020.02"}, {"price": "0.14", "size": "150"}, {"price": "0.12", "size": "48.59"}, {"price": "0.08", "size": "104"}], "event_type": "book", "last_trade_price": "0.060"}, {"market": "0x438bd0f5ff930f040bc63ed2dc0585f93ef5cbd871b50efe502d703bba96654d", "asset_id": "53925808913836840946371550342430470487372041989648351858443846988581594567500", "timestamp": "1769384344961", "hash": "cfd9492c7c6f90ac355402e21971372f8e3dc321", "bids": [{"price": "0.001", "size": "83961.99"}, {"price": "0.002", "size": "4255"}, {"price": "0.003", "size": "8174"}, {"price": "0.004", "size": "6254.78"}], "asks": [{"price": "0.999", "size": "705002.99"}, {"price": "0.998", "size": "250"}, {"price": "0.997", "size": "29.42"}, {"price": "0.99", "size": "2010"}, {"price": "0.98", "size": "1800"}, {"price": "0.979", "size": "12.96"}, {"price": "0.95", "size": "30"}, {"price": "0.949", "size": "39"}, {"price": "0.948", "size": "5000"}, {"price": "0.946", "size": "50"}, {"price": "0.945", "size": "10"}, {"price": "0.92", "size": "100"}, {"price": "0.919", "size": "5.79"}, {"price": "0.91", "size": "300"}, {"price": "0.909", "size": "21"}, {"price": "0.86", "size": "50"}, {"price": "0.8", "size": "200"}, {"price": "0.795", "size": "5.66"}, {"price": "0.73", "size": "200"}, {"price": "0.729", "size": "25"}, {"price": "0.66", "size": "100"}, {"price": "0.22", "size": "117.21"}, {"price": "0.11", "size": "40"}, {"price": "0.088", "size": "5000"}, {"price": "0.08", "size": "850"}, {"price": "0.078", "size": "15"}, {"price": "0.077", "size": "20"}, {"price": "0.046", "size": "5000"}, {"price": "0.029", "size": "2099.22"}, {"price": "0.027", "size": "3000"}, {"price": "0.025", "size": "30"}, {"price": "0.009", "size": "99"}, {"price": "0.006", "size": "882.5"}, {"price": "0.005", "size": "127.92"}], "event_type": "book", "last_trade_price": "0.004"}, {"market": "0x1786c149f32f75fa909fbfab4f7b273975b6da5b76ad6d43200f927a1690f1e8", "asset_id": "69860370569560842073228065523569617122621124551318423120774348883993531485193", "timestamp": "1769384391979", "hash": "3280e2b16c43171e8ee6825996ad483d42e5bb31", "bids": [{"price": "0.01", "size": "8210"}, {"price": "0.02", "size": "3300"}, {"price": "0.03", "size": "100"}, {"price": "0.05", "size": "620"}, {"price": "0.06", "size": "33"}, {"price": "0.13", "size": "3400"}, {"price": "0.14", "size": "50"}, {"price": "0.19", "size": "600"}, {"price": "0.2", "size": "200"}, {"price": "0.21", "size": "100"}, {"price": "0.27", "size": "200"}, {"price": "0.34", "size": "100"}, {"price": "0.83", "size": "1020.02"}, {"price": "0.86", "size": "150"}, {"price": "0.88", "size": "48.59"}, {"price": "0.92", "size": "104"}], "asks": [{"price": "0.99", "size": "168083.07"}, {"price": "0.98", "size": "63869.19"}, {"price": "0.97", "size": "32206.72"}, {"price": "0.96", "size": "1036.87"}, {"price": "0.95", "size": "765.99"}, {"price": "0.94", "size": "30"}], "event_type": "book", "last_trade_price": "0.060"}, {"market": "0x3590d080b030a479d32cfdc39eb16d5666c70b32326bee61076cfa3372d0e145", "asset_id": "102717039453623659974177091352103016643954726486882538879796504216481619498182", "timestamp": "1769384316806", "hash": "312f911534ee252bc18af1a22deb9f16af8eb5ba", "bids": [{"price": "0.001", "size": "6096.01"}, {"price": "0.002", "size": "448.56"}], "asks": [{"price": "0.999", "size": "604008.19"}, {"price": "0.998", "size": "250"}, {"price": "0.997", "size": "400"}, {"price": "0.996", "size": "8.82"}, {"price": "0.994", "size": "200"}, {"price": "0.99", "size": "2010"}, {"price": "0.989", "size": "8.92"}, {"price": "0.98", "size": "2200"}, {"price": "0.97", "size": "100"}, {"price": "0.969", "size": "7.66"}, {"price": "0.95", "size": "630"}, {"price": "0.949", "size": "39"}, {"price": "0.918", "size": "7000"}, {"price": "0.917", "size": "5.06"}, {"price": "0.892", "size": "20400"}, {"price": "0.86", "size": "50"}, {"price": "0.859", "size": "10"}, {"price": "0.8", "size": "200"}, {"price": "0.799", "size": "5.94"}, {"price": "0.724", "size": "250"}, {"price": "0.723", "size": "3449.09"}, {"price": "0.66", "size": "100"}, {"price": "0.659", "size": "5"}, {"price": "0.27", "size": "150"}, {"price": "0.177", "size": "185"}, {"price": "0.175", "size": "40"}, {"price": "0.087", "size": "800"}, {"price": "0.076", "size": "15"}, {"price": "0.064", "size": "25"}, {"price": "0.063", "size": "20"}, {"price": "0.039", "size": "1000"}, {"price": "0.018", "size": "193.63"}, {"price": "0.017", "size": "400"}, {"price": "0.016", "size": "29.9"}, {"price": "0.01", "size": "148.76"}, {"price": "0.009", "size": "26"}], "event_type": "book", "last_trade_price": "0.002"}, {"market": "0x091010f5fa0aed8218a8f2ef38ca6f75a04b86207e9d9a3464c76acedae5ff71", "asset_id": "18543401226963683485470982595403517845090555185510389603436997425977517302982", "timestamp": "1769384407583", "hash": "24dd2940a6c13c44f58c5aa019681861ce186a3e", "bids": [{"price": "0.001", "size": "2690"}, {"price": "0.002", "size": "201450"}, {"price": "0.003", "size": "406.62"}, {"price": "0.006", "size": "200"}, {"price": "0.007", "size": "9.76"}, {"price": "0.01", "size": "2010"}, {"price": "0.02", "size": "2200"}, {"price": "0.021", "size": "15.17"}, {"price": "0.05", "size": "630"}, {"price": "0.051", "size": "39"}, {"price": "0.095", "size": "9773.68"}, {"price": "0.096", "size": "16.49"}, {"price": "0.443", "size": "5"}, {"price": "0.446", "size": "400"}, {"price": "0.448", "size": "446"}, {"price": "0.449", "size": "622"}, {"price": "0.45", "size": "13.33"}, {"price": "0.454", "size": "25"}, {"price": "0.456", "size": "10"}, {"price": "0.458", "size": "40"}, {"price": "0.46", "size": "25"}, {"price": "0.461", "size": "20"}, {"price": "0.988", "size": "5.69"}, {"price": "0.991", "size": "32.28"}, {"price": "0.997", "size": "12.67"}, {"price": "0.998", "size": "207.38"}], "asks": [{"price": "0.999", "size": "5697.28"}], "event_type": "book", "last_trade_price": "0.001"}, {"market": "0xaad7429c6e56ba07ab9642b66edd365ba97442042e010cc8fce27d59a08f2da5", "asset_id": "46443102387865875618199309137574651890271593500189004156516763187381128187486", "timestamp": "1769384319341", "hash": "b97386baec07deebdeb1fd7d598bc45a9741dee5", "bids": [{"price": "0.001", "size": "2686.99"}, {"price": "0.002", "size": "301450"}, {"price": "0.003", "size": "400"}, {"price": "0.004", "size": "8.65"}, {"price": "0.006", "size": "200"}, {"price": "0.01", "size": "2010"}, {"price": "0.011", "size": "8.75"}, {"price": "0.02", "size": "2300"}, {"price": "0.03", "size": "100"}, {"price": "0.031", "size": "7.24"}, {"price": "0.05", "size": "630"}, {"price": "0.051", "size": "39"}, {"price": "0.08", "size": "400"}, {"price": "0.081", "size": "6.43"}, {"price": "0.14", "size": "50"}, {"price": "0.2", "size": "200"}, {"price": "0.202", "size": "10"}, {"price": "0.203", "size": "5.46"}, {"price": "0.272", "size": "400"}, {"price": "0.32", "size": "250"}, {"price": "0.321", "size": "3003.73"}, {"price": "0.34", "size": "100"}, {"price": "0.341", "size": "5"}, {"price": "0.523", "size": "201"}, {"price": "0.672", "size": "643"}, {"price": "0.823", "size": "186"}, {"price": "0.824", "size": "40"}, {"price": "0.92", "size": "850"}, {"price": "0.925", "size": "15"}, {"price": "0.926", "size": "20"}, {"price": "0.95", "size": "1000"}, {"price": "0.954", "size": "16.66"}, {"price": "0.955", "size": "25"}, {"price": "0.99", "size": "8.51"}, {"price": "0.992", "size": "48.23"}, {"price": "0.995", "size": "30.01"}, {"price": "0.998", "size": "746.31"}], "asks": [{"price": "0.999", "size": "1378.99"}], "event_type": "book", "last_trade_price": "0.001"}, {"market": "0xd12252318b547e004af2773f4b6d11c6cca2c3708c9648b7ce976f6be394913b", "asset_id": "114015390382366870083382365854653616663197240917052981101117141643069661733868", "timestamp": "1769384319341", "hash": "b8a03754683755ff995b2edf288d78e608177671", "bids": [{"price": "0.001", "size": "2682.04"}, {"price": "0.002", "size": "301450"}, {"price": "0.003", "size": "406.64"}, {"price": "0.006", "size": "200"}, {"price": "0.007", "size": "9.79"}, {"price": "0.01", "size": "2010"}, {"price": "0.02", "size": "2300"}, {"price": "0.021", "size": "6.9"}, {"price": "0.05", "size": "630"}, {"price": "0.051", "size": "39"}, {"price": "0.052", "size": "10.58"}, {"price": "0.098", "size": "300"}, {"price": "0.199", "size": "300"}, {"price": "0.2", "size": "10"}, {"price": "0.22", "size": "3000"}, {"price": "0.221", "size": "4077.84"}, {"price": "0.523", "size": "201"}, {"price": "0.77", "size": "700"}, {"price": "0.801", "size": "281"}, {"price": "0.823", "size": "186"}, {"price": "0.83", "size": "150"}, {"price": "0.831", "size": "120"}, {"price": "0.867", "size": "13.33"}, {"price": "0.869", "size": "25"}, {"price": "0.87", "size": "40"}, {"price": "0.872", "size": "410"}, {"price": "0.873", "size": "20"}, {"price": "0.99", "size": "8.22"}, {"price": "0.992", "size": "46.61"}, {"price": "0.994", "size": "30.01"}, {"price": "0.998", "size": "601.4"}], "asks": [{"price": "0.999", "size": "1528.94"}], "event_type": "book", "last_trade_price": "0.001"}, {"market": "0x1407cc4f937c9f1bf80b8519e8e74a43f4670e3d9e51344e03b67cf1b1dcc17b", "asset_id": "89401287443133133504894623881628605711209932174008254640939999447570721516033", "timestamp": "1769384411932", "hash": "834cd6e647327d1ed59aec6bf0a76a7cb9d294e9", "bids": [{"price": "0.001", "size": "403902.82"}, {"price": "0.002", "size": "250"}, {"price": "0.003", "size": "400"}, {"price": "0.004", "size": "8.73"}, {"price": "0.006", "size": "200"}, {"price": "0.01", "size": "2010"}, {"price": "0.011", "size": "8.83"}, {"price": "0.02", "size": "2200"}, {"price": "0.03", "size": "100"}, {"price": "0.031", "size": "7.3"}, {"price": "0.05", "size": "630"}, {"price": "0.051", "size": "39"}, {"price": "0.052", "size": "10"}, {"price": "0.081", "size": "5.67"}, {"price": "0.09", "size": "3400"}, {"price": "0.091", "size": "300"}, {"price": "0.14", "size": "50"}, {"price": "0.2", "size": "200"}, {"price": "0.201", "size": "5.83"}, {"price": "0.223", "size": "87"}, {"price": "0.294", "size": "3261.22"}, {"price": "0.295", "size": "25"}, {"price": "0.34", "size": "100"}, {"price": "0.341", "size": "40"}, {"price": "0.523", "size": "201"}, {"price": "0.54", "size": "700"}, {"price": "0.541", "size": "5"}, {"price": "0.65", "size": "150"}, {"price": "0.823", "size": "185"}, {"price": "0.834", "size": "25"}, {"price": "0.835", "size": "20"}, {"price": "0.95", "size": "168.15"}, {"price": "0.951", "size": "10"}, {"price": "0.971", "size": "4000"}, {"price": "0.974", "size": "260"}, {"price": "0.992", "size": "31.45"}, {"price": "0.995", "size": "371.02"}], "asks": [{"price": "0.999", "size": "1122.97"}, {"price": "0.998", "size": "192.28"}], "event_type": "book", "last_trade_price": "0.002"}, {"market": "0xc07928d93d2e9ae459edba5b537bcdcb4f59abcdca19ee1d4dc88c7474cfd5e0", "asset_id": "102789355367893125922194040490556243357965914304236215712028923179316736754233", "timestamp": "1769384409797", "hash": "c6b14cb57e7009b6b2e921e22ae40b7ec404acd2", "bids": [{"price": "0.001", "size": "1478.4"}], "asks": [{"price": "0.999", "size": "2704.99"}, {"price": "0.998", "size": "201450"}, {"price": "0.997", "size": "400"}, {"price": "0.996", "size": "8.65"}, {"price": "0.994", "size": "200"}, {"price": "0.99", "size": "2010"}, {"price": "0.989", "size": "8.75"}, {"price": "0.98", "size": "2300"}, {"price": "0.97", "size": "100"}, {"price": "0.969", "size": "7.24"}, {"price": "0.95", "size": "630"}, {"price": "0.949", "size": "39"}, {"price": "0.92", "size": "400"}, {"price": "0.919", "size": "5.62"}, {"price": "0.86", "size": "50"}, {"price": "0.8", "size": "200"}, {"price": "0.799", "size": "5.84"}, {"price": "0.777", "size": "73"}, {"price": "0.73", "size": "200"}, {"price": "0.728", "size": "250"}, {"price": "0.659", "size": "2739.29"}, {"price": "0.477", "size": "201"}, {"price": "0.461", "size": "5"}, {"price": "0.177", "size": "185"}, {"price": "0.176", "size": "10"}, {"price": "0.146", "size": "40"}, {"price": "0.142", "size": "25"}, {"price": "0.141", "size": "20"}, {"price": "0.05", "size": "1000"}, {"price": "0.049", "size": "25"}, {"price": "0.009", "size": "12.34"}, {"price": "0.007", "size": "69.95"}, {"price": "0.005", "size": "136.6"}, {"price": "0.004", "size": "28.57"}, {"price": "0.003", "size": "5.46"}, {"price": "0.002", "size": "410.47"}], "event_type": "book", "last_trade_price": "0.001"}, {"market": "0x88298e294408106c07c49520e9bf10c7dc469afe13e834be34d95e82bc36542e", "asset_id": "110927174810108466705078650135127005951257798916789146270595008049405408818734", "timestamp": "1769384398647", "hash": "51ffec3720f7163ff0cd69235e749461e3bfcc3e", "bids": [{"price": "0.001", "size": "203955"}, {"price": "0.002", "size": "250"}, {"price": "0.003", "size": "406.63"}, {"price": "0.006", "size": "200"}, {"price": "0.007", "size": "9.76"}, {"price": "0.01", "size": "2010"}, {"price": "0.02", "size": "2200"}, {"price": "0.021", "size": "6.89"}, {"price": "0.05", "size": "630"}, {"price": "0.051", "size": "39"}, {"price": "0.052", "size": "5.96"}, {"price": "0.15", "size": "300"}, {"price": "0.151", "size": "5960.26"}, {"price": "0.164", "size": "6"}, {"price": "0.167", "size": "8.66"}, {"price": "0.168", "size": "11"}, {"price": "0.523", "size": "201"}, {"price": "0.524", "size": "10"}, {"price": "0.823", "size": "185"}, {"price": "0.91", "size": "850"}, {"price": "0.916", "size": "400"}, {"price": "0.917", "size": "207.93"}, {"price": "0.919", "size": "15"}, {"price": "0.925", "size": "40"}, {"price": "0.927", "size": "10"}, {"price": "0.928", "size": "20"}, {"price": "0.953", "size": "50"}, {"price": "0.955", "size": "25"}, {"price": "0.975", "size": "60"}, {"price": "0.984", "size": "97.6"}, {"price": "0.988", "size": "6.88"}, {"price": "0.989", "size": "0.11"}, {"price": "0.99", "size": "87.68"}, {"price": "0.991", "size": "14"}], "asks": [{"price": "0.999", "size": "535546.79"}, {"price": "0.998", "size": "59999.54"}, {"price": "0.997", "size": "10255"}, {"price": "0.996", "size": "2250"}, {"price": "0.995", "size": "98.56"}], "event_type": "book", "last_trade_price": "0.005"}, {"market": "0x0c473519a0fd7d7dc49f4dde9420e439a96a279147262d94d94440c7bb0c3d1a", "asset_id": "33850995040817642028610750949028268753079036233754982280349900373513025092341", "timestamp": "1769384319342", "hash": "a4035a179f4e1047dc76ac9f524eb055f45aa8e4", "bids": [{"price": "0.001", "size": "2761.99"}, {"price": "0.002", "size": "301450"}, {"price": "0.003", "size": "400"}, {"price": "0.004", "size": "8.65"}, {"price": "0.006", "size": "200"}, {"price": "0.01", "size": "2010"}, {"price": "0.011", "size": "8.75"}, {"price": "0.02", "size": "2300"}, {"price": "0.03", "size": "100"}, {"price": "0.031", "size": "8.74"}, {"price": "0.05", "size": "630"}, {"price": "0.051", "size": "39"}, {"price": "0.091", "size": "300"}, {"price": "0.092", "size": "5.16"}, {"price": "0.22", "size": "3000"}, {"price": "0.221", "size": "5.01"}, {"price": "0.339", "size": "5"}, {"price": "0.343", "size": "250"}, {"price": "0.344", "size": "2616.27"}, {"price": "0.8", "size": "700"}, {"price": "0.823", "size": "397"}, {"price": "0.84", "size": "150"}, {"price": "0.841", "size": "355"}, {"price": "0.842", "size": "10"}, {"price": "0.843", "size": "20"}, {"price": "0.94", "size": "25"}, {"price": "0.941", "size": "40"}, {"price": "0.964", "size": "16"}, {"price": "0.981", "size": "7.89"}, {"price": "0.982", "size": "168.19"}, {"price": "0.998", "size": "777.69"}], "asks": [{"price": "0.999", "size": "641.94"}], "event_type": "book", "last_trade_price": "0.001"}, {"market": "0x27d3b228eb7a01bf021f86dd9255f32f01a386b64577ff44f97b2bf720edb078", "asset_id": "70987153717494175881665090780043286768976439451887172951225255552771040459447", "timestamp": "1769384361308", "hash": "10375369222b5e23c1ce14287147e7fc83e1347f", "bids": [{"price": "0.001", "size": "1274.27"}], "asks": [{"price": "0.999", "size": "2804"}, {"price": "0.998", "size": "201450"}, {"price": "0.997", "size": "400"}, {"price": "0.996", "size": "8.67"}, {"price": "0.994", "size": "200"}, {"price": "0.99", "size": "2010"}, {"price": "0.989", "size": "8.77"}, {"price": "0.98", "size": "2300"}, {"price": "0.97", "size": "100"}, {"price": "0.969", "size": "8.63"}, {"price": "0.95", "size": "630"}, {"price": "0.949", "size": "39"}, {"price": "0.91", "size": "300"}, {"price": "0.909", "size": "17.48"}, {"price": "0.84", "size": "3000"}, {"price": "0.668", "size": "250"}, {"price": "0.667", "size": "2702.7"}, {"price": "0.477", "size": "201"}, {"price": "0.35", "size": "150"}, {"price": "0.323", "size": "590"}, {"price": "0.237", "size": "131"}, {"price": "0.177", "size": "100"}, {"price": "0.174", "size": "10"}, {"price": "0.173", "size": "20"}, {"price": "0.054", "size": "40"}, {"price": "0.052", "size": "11.1"}, {"price": "0.051", "size": "16"}, {"price": "0.05", "size": "25"}, {"price": "0.004", "size": "7.84"}, {"price": "0.003", "size": "44.45"}, {"price": "0.002", "size": "672.1"}], "event_type": "book", "last_trade_price": "0.001"}, {"market": "0xba0328d6ad5ab81ba51d27e32b2bc5db92c24b54fb96d9efba3b3e56d7f5de95", "asset_id": "32224453635036431353149279508385871867136661091803541589020076501121714777202", "timestamp": "1769384322664", "hash": "da47762fa30e7408614a83dbebff395faf7e6eba", "bids": [{"price": "0.001", "size": "1417.38"}], "asks": [{"price": "0.999", "size": "4298.41"}, {"price": "0.998", "size": "201450"}, {"price": "0.997", "size": "408.29"}, {"price": "0.994", "size": "200"}, {"price": "0.993", "size": "9.76"}, {"price": "0.99", "size": "2010"}, {"price": "0.98", "size": "2200"}, {"price": "0.979", "size": "6.67"}, {"price": "0.97", "size": "100"}, {"price": "0.95", "size": "630"}, {"price": "0.949", "size": "39"}, {"price": "0.948", "size": "5.09"}, {"price": "0.887", "size": "8370.6"}, {"price": "0.886", "size": "13.12"}, {"price": "0.777", "size": "118"}, {"price": "0.775", "size": "8"}, {"price": "0.62", "size": "3000"}, {"price": "0.19", "size": "700"}, {"price": "0.177", "size": "142"}, {"price": "0.169", "size": "240"}, {"price": "0.159", "size": "237"}, {"price": "0.158", "size": "118"}, {"price": "0.15", "size": "150"}, {"price": "0.134", "size": "10"}, {"price": "0.132", "size": "40"}, {"price": "0.131", "size": "20"}, {"price": "0.049", "size": "20"}, {"price": "0.048", "size": "25"}, {"price": "0.026", "size": "20"}, {"price": "0.004", "size": "16"}, {"price": "0.003", "size": "402.89"}, {"price": "0.002", "size": "725.39"}], "event_type": "book", "last_trade_price": "0.001"}, {"market": "0x68220e1323e36bfbc2fa63af9c62976e759eb46049af631e56b7fb9c130ff5cb", "asset_id": "41829131859319827462125137692733846658456852401422197145743414010522852953327", "timestamp": "1769384322656", "hash": "d84965377f2074b52271e8daa91bfaf840079fce", "bids": [{"price": "0.001", "size": "116.65"}], "asks": [{"price": "0.999", "size": "4304"}, {"price": "0.998", "size": "301450"}, {"price": "0.997", "size": "405.05"}, {"price": "0.994", "size": "200"}, {"price": "0.993", "size": "9.79"}, {"price": "0.99", "size": "2010"}, {"price": "0.98", "size": "2300"}, {"price": "0.979", "size": "6.55"}, {"price": "0.97", "size": "100"}, {"price": "0.95", "size": "630"}, {"price": "0.949", "size": "44.2"}, {"price": "0.888", "size": "300"}, {"price": "0.887", "size": "13.3"}, {"price": "0.777", "size": "82"}, {"price": "0.654", "size": "255"}, {"price": "0.653", "size": "2593.65"}, {"price": "0.477", "size": "41"}, {"price": "0.21", "size": "700"}, {"price": "0.189", "size": "492"}, {"price": "0.177", "size": "146"}, {"price": "0.168", "size": "120"}, {"price": "0.08", "size": "150"}, {"price": "0.077", "size": "346"}, {"price": "0.076", "size": "16.81"}, {"price": "0.074", "size": "10"}, {"price": "0.073", "size": "20"}, {"price": "0.054", "size": "46"}, {"price": "0.053", "size": "10"}, {"price": "0.052", "size": "16"}, {"price": "0.051", "size": "25"}, {"price": "0.02", "size": "32.51"}, {"price": "0.002", "size": "102.89"}], "event_type": "book", "last_trade_price": "0.001"}, {"market": "0xd80e46775331928bde30cc8ff482f42823b74115677a4ec15779d45a25f47fc1", "asset_id": "98461653036081390149693407208637821266204790775472074887403914584572668702865", "timestamp": "1769384320216", "hash": "1128d21ac0bdbe056e3cac0901d5e707e08a6122", "bids": [], "asks": [{"price": "0.999", "size": "4304"}, {"price": "0.998", "size": "301450"}, {"price": "0.997", "size": "406.63"}, {"price": "0.994", "size": "200"}, {"price": "0.993", "size": "9.76"}, {"price": "0.99", "size": "2010"}, {"price": "0.98", "size": "2300"}, {"price": "0.979", "size": "14.98"}, {"price": "0.95", "size": "630"}, {"price": "0.949", "size": "39"}, {"price": "0.91", "size": "300"}, {"price": "0.909", "size": "17.44"}, {"price": "0.685", "size": "6"}, {"price": "0.679", "size": "2803.73"}, {"price": "0.678", "size": "1009"}, {"price": "0.177", "size": "142"}, {"price": "0.077", "size": "372"}, {"price": "0.076", "size": "98.99"}, {"price": "0.074", "size": "15"}, {"price": "0.063", "size": "10"}, {"price": "0.062", "size": "40"}, {"price": "0.049", "size": "5"}, {"price": "0.046", "size": "25"}, {"price": "0.012", "size": "114.86"}, {"price": "0.011", "size": "20"}, {"price": "0.004", "size": "30.01"}, {"price": "0.003", "size": "13.46"}, {"price": "0.002", "size": "233.83"}], "event_type": "book", "last_trade_price": "0.001"}, {"market": "0xf9489fd8943a211e64a5f8cc4ad876e8e21454ede9b5a8ad9acf0296b6b04702", "asset_id": "115659415493993067186522617098547228925162442224581115188185764894045972353794", "timestamp": "1769384297852", "hash": "bcf2089db5f8fc4daeda09c41bc57f62f55ebae8", "bids": [{"price": "0.001", "size": "309026.9"}, {"price": "0.002", "size": "10047.28"}], "asks": [{"price": "0.999", "size": "2805"}, {"price": "0.998", "size": "201450"}, {"price": "0.997", "size": "406.63"}, {"price": "0.994", "size": "200"}, {"price": "0.993", "size": "9.76"}, {"price": "0.99", "size": "2010"}, {"price": "0.98", "size": "2300"}, {"price": "0.979", "size": "14.98"}, {"price": "0.95", "size": "630"}, {"price": "0.949", "size": "39"}, {"price": "0.91", "size": "300"}, {"price": "0.909", "size": "17.44"}, {"price": "0.756", "size": "250"}, {"price": "0.755", "size": "3673.46"}, {"price": "0.477", "size": "201"}, {"price": "0.463", "size": "744"}, {"price": "0.462", "size": "148.59"}, {"price": "0.461", "size": "5"}, {"price": "0.177", "size": "141"}, {"price": "0.174", "size": "121"}, {"price": "0.144", "size": "40"}, {"price": "0.142", "size": "10"}, {"price": "0.141", "size": "20"}, {"price": "0.049", "size": "5"}, {"price": "0.047", "size": "25"}, {"price": "0.029", "size": "11"}, {"price": "0.028", "size": "20"}, {"price": "0.006", "size": "144.45"}, {"price": "0.005", "size": "145.64"}], "event_type": "book", "last_trade_price": "0.002"}, {"market": "0x6bc389514aeed2d49f77818df91931b8f47bca741b922b5aa581bcd285898ecf", "asset_id": "16489262565579695131848767429570049041149464887984576468765279262944286152030", "timestamp": "1769384316806", "hash": "a091e942978cf39f611cf0cf1a6a879d9b9de4cc", "bids": [{"price": "0.001", "size": "2808.99"}, {"price": "0.002", "size": "301450"}, {"price": "0.003", "size": "400"}, {"price": "0.004", "size": "8.65"}, {"price": "0.006", "size": "200"}, {"price": "0.01", "size": "2010"}, {"price": "0.011", "size": "8.75"}, {"price": "0.02", "size": "2300"}, {"price": "0.025", "size": "9"}, {"price": "0.03", "size": "100"}, {"price": "0.031", "size": "7.24"}, {"price": "0.05", "size": "630"}, {"price": "0.051", "size": "39"}, {"price": "0.08", "size": "400"}, {"price": "0.081", "size": "5.62"}, {"price": "0.14", "size": "50"}, {"price": "0.2", "size": "200"}, {"price": "0.201", "size": "5.84"}, {"price": "0.272", "size": "250"}, {"price": "0.273", "size": "3496.7"}, {"price": "0.34", "size": "100"}, {"price": "0.485", "size": "5"}, {"price": "0.527", "size": "25"}, {"price": "0.529", "size": "10"}, {"price": "0.531", "size": "40"}, {"price": "0.532", "size": "20"}, {"price": "0.95", "size": "1200"}, {"price": "0.951", "size": "15.15"}, {"price": "0.953", "size": "157.99"}, {"price": "0.954", "size": "25"}, {"price": "0.978", "size": "20"}, {"price": "0.996", "size": "5.66"}, {"price": "0.997", "size": "24.61"}], "asks": [{"price": "0.999", "size": "2246.97"}], "event_type": "book", "last_trade_price": "0.001"}, {"market": "0x53f51083a4b4fee058bfcda4d8752e4178ff99d5cf414ca40586ff46d4b98830", "asset_id": "98958728694271140216248695359897335966039366127035047208434501596396634451257", "timestamp": "1769384322672", "hash": "5cbd21722515ba1445720179a4f556ebc777b437", "bids": [{"price": "0.001", "size": "487.77"}], "asks": [{"price": "0.999", "size": "305791.25"}, {"price": "0.998", "size": "257.48"}, {"price": "0.997", "size": "400"}, {"price": "0.996", "size": "6000"}, {"price": "0.995", "size": "5.93"}, {"price": "0.994", "size": "200"}, {"price": "0.992", "size": "9"}, {"price": "0.99", "size": "1010"}, {"price": "0.989", "size": "8.75"}, {"price": "0.98", "size": "2300"}, {"price": "0.97", "size": "100"}, {"price": "0.969", "size": "8.61"}, {"price": "0.95", "size": "630"}, {"price": "0.949", "size": "39"}, {"price": "0.91", "size": "300"}, {"price": "0.909", "size": "17.44"}, {"price": "0.671", "size": "6"}, {"price": "0.67", "size": "250"}, {"price": "0.669", "size": "2719.03"}, {"price": "0.35", "size": "578"}, {"price": "0.22", "size": "69.99"}, {"price": "0.18", "size": "123.33"}, {"price": "0.177", "size": "185"}, {"price": "0.176", "size": "121"}, {"price": "0.077", "size": "97"}, {"price": "0.076", "size": "20"}, {"price": "0.058", "size": "10"}, {"price": "0.057", "size": "40"}, {"price": "0.049", "size": "10"}, {"price": "0.048", "size": "25"}, {"price": "0.027", "size": "20"}, {"price": "0.011", "size": "47.18"}, {"price": "0.005", "size": "158.43"}, {"price": "0.004", "size": "219.24"}], "event_type": "book", "last_trade_price": "0.001"}, {"market": "0xf2c1d8073d365d0a6ca005c37e2250efb4625d5247f1f8db7f7edd194f235ca6", "asset_id": "59922854145177028632667171179632806422139858373409305746732269435780452237751", "timestamp": "1769384316871", "hash": "7f84206b4856f67858feb30e963af849e7dfe60f", "bids": [{"price": "0.001", "size": "7527.3"}, {"price": "0.002", "size": "223.66"}], "asks": [{"price": "0.999", "size": "4304.06"}, {"price": "0.998", "size": "201450"}, {"price": "0.997", "size": "406.64"}, {"price": "0.994", "size": "200"}, {"price": "0.993", "size": "10.03"}, {"price": "0.99", "size": "2010"}, {"price": "0.98", "size": "2300"}, {"price": "0.979", "size": "5.06"}, {"price": "0.95", "size": "630"}, {"price": "0.949", "size": "39"}, {"price": "0.948", "size": "5.24"}, {"price": "0.886", "size": "300"}, {"price": "0.885", "size": "13.22"}, {"price": "0.777", "size": "73"}, {"price": "0.764", "size": "250"}, {"price": "0.763", "size": "3805.46"}, {"price": "0.762", "size": "336"}, {"price": "0.477", "size": "201"}, {"price": "0.177", "size": "185"}, {"price": "0.159", "size": "118"}, {"price": "0.158", "size": "10"}, {"price": "0.157", "size": "40"}, {"price": "0.102", "size": "25"}, {"price": "0.101", "size": "20"}, {"price": "0.049", "size": "5"}, {"price": "0.022", "size": "89.22"}, {"price": "0.021", "size": "369.28"}, {"price": "0.02", "size": "215.64"}, {"price": "0.019", "size": "111.28"}, {"price": "0.01", "size": "5"}, {"price": "0.009", "size": "58.16"}, {"price": "0.006", "size": "22"}], "event_type": "book", "last_trade_price": "0.002"}, {"market": "0x8932cec511d09e4922b72842626d444f4b9c7cfda6d8fab78cf5e70edcce1ad3", "asset_id": "79302611148486703587078109319753536512866118261052167146822125856737883623057", "timestamp": "1769384322653", "hash": "27dda1864fb0935572376d517fadb31558531a64", "bids": [{"price": "0.001", "size": "503986"}, {"price": "0.002", "size": "250"}, {"price": "0.003", "size": "406.62"}, {"price": "0.006", "size": "200"}, {"price": "0.007", "size": "9.76"}, {"price": "0.01", "size": "2010"}, {"price": "0.02", "size": "2220.53"}, {"price": "0.021", "size": "16.16"}, {"price": "0.05", "size": "630"}, {"price": "0.051", "size": "39"}, {"price": "0.096", "size": "300"}, {"price": "0.097", "size": "9578.35"}, {"price": "0.098", "size": "15.94"}, {"price": "0.354", "size": "5"}, {"price": "0.79", "size": "700"}, {"price": "0.831", "size": "240"}, {"price": "0.841", "size": "355"}, {"price": "0.842", "size": "10"}, {"price": "0.91", "size": "111.5"}, {"price": "0.92", "size": "150"}, {"price": "0.932", "size": "40"}, {"price": "0.933", "size": "20"}, {"price": "0.962", "size": "100"}, {"price": "0.963", "size": "41.66"}, {"price": "0.981", "size": "8.18"}, {"price": "0.992", "size": "10"}, {"price": "0.997", "size": "771.75"}, {"price": "0.998", "size": "400.29"}], "asks": [{"price": "0.999", "size": "1070.29"}], "event_type": "book", "last_trade_price": "0.001"}, {"market": "0x09ac5925691713ff142bab96413fd34ad1113bd18bb0a090d8284fd6ccb27d8f", "asset_id": "95861053919171993512697190106673713355541727588409736217989846113692847198678", "timestamp": "1769384316871", "hash": "39d247d7c214195f00a65328280d6f10dbc61889", "bids": [{"price": "0.001", "size": "2807.99"}, {"price": "0.002", "size": "201450"}, {"price": "0.003", "size": "400"}, {"price": "0.004", "size": "8.65"}, {"price": "0.006", "size": "200"}, {"price": "0.01", "size": "2010"}, {"price": "0.011", "size": "8.75"}, {"price": "0.02", "size": "2300"}, {"price": "0.03", "size": "100"}, {"price": "0.031", "size": "7.24"}, {"price": "0.05", "size": "630"}, {"price": "0.051", "size": "39"}, {"price": "0.08", "size": "100"}, {"price": "0.081", "size": "5.62"}, {"price": "0.09", "size": "300"}, {"price": "0.14", "size": "50"}, {"price": "0.2", "size": "200"}, {"price": "0.201", "size": "5.84"}, {"price": "0.223", "size": "87"}, {"price": "0.281", "size": "250"}, {"price": "0.282", "size": "3391.48"}, {"price": "0.283", "size": "246"}, {"price": "0.34", "size": "100"}, {"price": "0.341", "size": "5"}, {"price": "0.823", "size": "185"}, {"price": "0.824", "size": "10"}, {"price": "0.852", "size": "40"}, {"price": "0.856", "size": "25"}, {"price": "0.857", "size": "20"}, {"price": "0.95", "size": "1000"}, {"price": "0.958", "size": "5"}, {"price": "0.959", "size": "10"}, {"price": "0.96", "size": "16"}, {"price": "0.961", "size": "25"}, {"price": "0.997", "size": "12.75"}, {"price": "0.998", "size": "900.49"}], "asks": [{"price": "0.999", "size": "1220.29"}], "event_type": "book", "last_trade_price": "0.001"}, {"market": "0xbb9ebd08fe1834e60ee5d40b0f5b564478de30519bc8dd6d6d023539a39cd51f", "asset_id": "89553061197618390623760390657385664748681901228299157936065698474602382096708", "timestamp": "1769384399412", "hash": "bd33a24eda6530cd22a046d3b3f8a5f337acefbc", "bids": [{"price": "0.001", "size": "505301.07"}, {"price": "0.002", "size": "20005"}, {"price": "0.003", "size": "300"}, {"price": "0.004", "size": "170.4"}, {"price": "0.005", "size": "113.88"}], "asks": [{"price": "0.999", "size": "502861.81"}, {"price": "0.998", "size": "250"}, {"price": "0.997", "size": "13.27"}, {"price": "0.994", "size": "83"}, {"price": "0.99", "size": "53210"}, {"price": "0.989", "size": "8.79"}, {"price": "0.98", "size": "2300"}, {"price": "0.97", "size": "100"}, {"price": "0.969", "size": "7.27"}, {"price": "0.95", "size": "630"}, {"price": "0.949", "size": "39"}, {"price": "0.92", "size": "100"}, {"price": "0.919", "size": "5.64"}, {"price": "0.906", "size": "300"}, {"price": "0.86", "size": "50"}, {"price": "0.839", "size": "250"}, {"price": "0.8", "size": "200"}, {"price": "0.799", "size": "5.82"}, {"price": "0.73", "size": "200"}, {"price": "0.66", "size": "100"}, {"price": "0.659", "size": "5"}, {"price": "0.658", "size": "10"}, {"price": "0.186", "size": "25"}, {"price": "0.185", "size": "40"}, {"price": "0.09", "size": "150"}, {"price": "0.089", "size": "15"}, {"price": "0.07", "size": "1000"}, {"price": "0.068", "size": "10"}, {"price": "0.067", "size": "20"}, {"price": "0.049", "size": "5"}, {"price": "0.042", "size": "20.1"}, {"price": "0.03", "size": "500"}, {"price": "0.029", "size": "354.38"}, {"price": "0.027", "size": "87.41"}, {"price": "0.026", "size": "188.4"}, {"price": "0.011", "size": "57"}], "event_type": "book", "last_trade_price": "0.005"}, {"market": "0x8932cec511d09e4922b72842626d444f4b9c7cfda6d8fab78cf5e70edcce1ad3", "asset_id": "67412626609038893259917867132982247771702111359601014529897364049627602663970", "timestamp": "1769384322653", "hash": "a39df1f987364eb57143668d597ed06481b08cd6", "bids": [{"price": "0.001", "size": "1070.29"}], "asks": [{"price": "0.999", "size": "503986"}, {"price": "0.998", "size": "250"}, {"price": "0.997", "size": "406.62"}, {"price": "0.994", "size": "200"}, {"price": "0.993", "size": "9.76"}, {"price": "0.99", "size": "2010"}, {"price": "0.98", "size": "2220.53"}, {"price": "0.979", "size": "16.16"}, {"price": "0.95", "size": "630"}, {"price": "0.949", "size": "39"}, {"price": "0.904", "size": "300"}, {"price": "0.903", "size": "9578.35"}, {"price": "0.902", "size": "15.94"}, {"price": "0.646", "size": "5"}, {"price": "0.21", "size": "700"}, {"price": "0.169", "size": "240"}, {"price": "0.159", "size": "355"}, {"price": "0.158", "size": "10"}, {"price": "0.09", "size": "111.5"}, {"price": "0.08", "size": "150"}, {"price": "0.068", "size": "40"}, {"price": "0.067", "size": "20"}, {"price": "0.038", "size": "100"}, {"price": "0.037", "size": "41.66"}, {"price": "0.019", "size": "8.18"}, {"price": "0.008", "size": "10"}, {"price": "0.003", "size": "771.75"}, {"price": "0.002", "size": "400.29"}], "event_type": "book", "last_trade_price": "0.001"}, {"market": "0x949c9ec867ff713ee52ab749498e761b737139dbcf3cee2fce4fb97fcddc8332", "asset_id": "57579576028532911954666940251041611742032623764462509111730085124509956613210", "timestamp": "1769384316806", "hash": "fa31fc4ef8d6706655beea360c9013f7afd16199", "bids": [{"price": "0.001", "size": "1375.23"}], "asks": [{"price": "0.999", "size": "503952.13"}, {"price": "0.998", "size": "250"}, {"price": "0.997", "size": "400"}, {"price": "0.996", "size": "8.67"}, {"price": "0.994", "size": "200"}, {"price": "0.99", "size": "2010"}, {"price": "0.989", "size": "8.77"}, {"price": "0.98", "size": "2300"}, {"price": "0.97", "size": "100"}, {"price": "0.969", "size": "7.26"}, {"price": "0.95", "size": "630"}, {"price": "0.949", "size": "39"}, {"price": "0.92", "size": "100"}, {"price": "0.919", "size": "5.63"}, {"price": "0.904", "size": "300"}, {"price": "0.86", "size": "50"}, {"price": "0.8", "size": "200"}, {"price": "0.799", "size": "5.83"}, {"price": "0.729", "size": "3521.03"}, {"price": "0.66", "size": "100"}, {"price": "0.65", "size": "5"}, {"price": "0.649", "size": "247"}, {"price": "0.08", "size": "882.17"}, {"price": "0.076", "size": "25"}, {"price": "0.075", "size": "20"}, {"price": "0.058", "size": "10"}, {"price": "0.054", "size": "72"}, {"price": "0.053", "size": "25"}, {"price": "0.011", "size": "10"}, {"price": "0.005", "size": "18.41"}, {"price": "0.003", "size": "127.09"}, {"price": "0.002", "size": "1022.63"}], "event_type": "book", "last_trade_price": "0.001"}, {"market": "0xa4dad4202b71fcd1387651e9eae72cb138c9b61c4194f93f5e8da4a3d534269c", "asset_id": "82555109203307099745725321482723908789076391198733120428808326995300770905860", "timestamp": "1769384375495", "hash": "6b755322fff0a674e526bef4ece3ac9c043744b2", "bids": [{"price": "0.001", "size": "506417"}, {"price": "0.002", "size": "250889.21"}, {"price": "0.003", "size": "150000"}, {"price": "0.004", "size": "5000"}, {"price": "0.005", "size": "250"}, {"price": "0.01", "size": "917.18"}], "asks": [{"price": "0.999", "size": "2823"}, {"price": "0.998", "size": "201450"}, {"price": "0.997", "size": "406.62"}, {"price": "0.994", "size": "200"}, {"price": "0.993", "size": "9.76"}, {"price": "0.99", "size": "2010"}, {"price": "0.98", "size": "1800"}, {"price": "0.979", "size": "12.96"}, {"price": "0.95", "size": "30"}, {"price": "0.949", "size": "39"}, {"price": "0.948", "size": "2000"}, {"price": "0.92", "size": "100"}, {"price": "0.919", "size": "5.62"}, {"price": "0.91", "size": "300"}, {"price": "0.86", "size": "50"}, {"price": "0.8", "size": "200"}, {"price": "0.799", "size": "5.84"}, {"price": "0.73", "size": "200"}, {"price": "0.652", "size": "250"}, {"price": "0.651", "size": "2678.79"}, {"price": "0.65", "size": "40"}, {"price": "0.649", "size": "10"}, {"price": "0.648", "size": "5"}, {"price": "0.302", "size": "25"}, {"price": "0.301", "size": "20"}, {"price": "0.05", "size": "1174.56"}, {"price": "0.049", "size": "500"}, {"price": "0.048", "size": "252.53"}, {"price": "0.046", "size": "25"}, {"price": "0.038", "size": "20"}, {"price": "0.022", "size": "98.4"}, {"price": "0.019", "size": "34.96"}, {"price": "0.013", "size": "41.1"}, {"price": "0.012", "size": "64"}], "event_type": "book", "last_trade_price": "0.010"}, {"market": "0xd1cb6a36c0eaafd15fbb30e15d210b6ea3ca6b4beacd5506a4e18c0b3c9f0c14", "asset_id": "35745608736303685712191378174068870840106833352597804268446172117129985633950", "timestamp": "1769384355796", "hash": "54e5616d32b40166f99686839e8a93e45314fa78", "bids": [{"price": "0.001", "size": "4308.99"}, {"price": "0.002", "size": "201450"}, {"price": "0.003", "size": "400"}, {"price": "0.004", "size": "8.65"}, {"price": "0.006", "size": "200"}, {"price": "0.01", "size": "2010"}, {"price": "0.011", "size": "8.75"}, {"price": "0.02", "size": "2300"}, {"price": "0.03", "size": "100"}, {"price": "0.031", "size": "7.24"}, {"price": "0.05", "size": "630"}, {"price": "0.051", "size": "39"}, {"price": "0.08", "size": "400"}, {"price": "0.081", "size": "5.62"}, {"price": "0.14", "size": "50"}, {"price": "0.2", "size": "200"}, {"price": "0.201", "size": "5.83"}, {"price": "0.299", "size": "250"}, {"price": "0.3", "size": "3200"}, {"price": "0.34", "size": "100"}, {"price": "0.391", "size": "5"}, {"price": "0.392", "size": "10"}, {"price": "0.92", "size": "1200"}, {"price": "0.921", "size": "16.81"}, {"price": "0.922", "size": "15"}, {"price": "0.93", "size": "10"}, {"price": "0.931", "size": "20"}, {"price": "0.944", "size": "40"}, {"price": "0.951", "size": "5"}, {"price": "0.952", "size": "25"}, {"price": "0.976", "size": "53.7"}, {"price": "0.977", "size": "24.1"}, {"price": "0.996", "size": "5.66"}, {"price": "0.997", "size": "20.61"}], "asks": [{"price": "0.999", "size": "2401.01"}], "event_type": "book", "last_trade_price": "0.001"}, {"market": "0x45a92c8b378085a254cf1678e006bc1046a60e04be1952f118239a45bc1ff2d4", "asset_id": "42699425594771854466147311473473124935952259123609260877052089014568462114821", "timestamp": "1769384289017", "hash": "ee4729216036893304c2d38f1d00373b86f98b39", "bids": [{"price": "0.001", "size": "2708"}, {"price": "0.002", "size": "250"}, {"price": "0.003", "size": "302606.62"}, {"price": "0.006", "size": "200"}, {"price": "0.007", "size": "9.76"}, {"price": "0.01", "size": "1010"}, {"price": "0.02", "size": "2300"}, {"price": "0.021", "size": "14.97"}, {"price": "0.05", "size": "630"}, {"price": "0.051", "size": "39"}, {"price": "0.09", "size": "300"}, {"price": "0.091", "size": "17.44"}, {"price": "0.239", "size": "8"}, {"price": "0.244", "size": "294"}, {"price": "0.245", "size": "3673.46"}, {"price": "0.246", "size": "1213"}, {"price": "0.823", "size": "147"}, {"price": "0.824", "size": "121"}, {"price": "0.856", "size": "40"}, {"price": "0.858", "size": "410"}, {"price": "0.859", "size": "20"}, {"price": "0.953", "size": "11.1"}, {"price": "0.954", "size": "16"}, {"price": "0.955", "size": "25"}, {"price": "0.996", "size": "5.66"}, {"price": "0.997", "size": "750.19"}, {"price": "0.998", "size": "369.62"}], "asks": [{"price": "0.999", "size": "993.56"}], "event_type": "book", "last_trade_price": "0.001"}, {"market": "0xba0328d6ad5ab81ba51d27e32b2bc5db92c24b54fb96d9efba3b3e56d7f5de95", "asset_id": "43531991381212233715650019655708331015011640780166908574527077093404380004577", "timestamp": "1769384322664", "hash": "e35158f4bd081964f99f34105e0fd0fda5ec01e6", "bids": [{"price": "0.001", "size": "4298.41"}, {"price": "0.002", "size": "201450"}, {"price": "0.003", "size": "408.29"}, {"price": "0.006", "size": "200"}, {"price": "0.007", "size": "9.76"}, {"price": "0.01", "size": "2010"}, {"price": "0.02", "size": "2200"}, {"price": "0.021", "size": "6.67"}, {"price": "0.03", "size": "100"}, {"price": "0.05", "size": "630"}, {"price": "0.051", "size": "39"}, {"price": "0.052", "size": "5.09"}, {"price": "0.113", "size": "8370.6"}, {"price": "0.114", "size": "13.12"}, {"price": "0.223", "size": "118"}, {"price": "0.225", "size": "8"}, {"price": "0.38", "size": "3000"}, {"price": "0.81", "size": "700"}, {"price": "0.823", "size": "142"}, {"price": "0.831", "size": "240"}, {"price": "0.841", "size": "237"}, {"price": "0.842", "size": "118"}, {"price": "0.85", "size": "150"}, {"price": "0.866", "size": "10"}, {"price": "0.868", "size": "40"}, {"price": "0.869", "size": "20"}, {"price": "0.951", "size": "20"}, {"price": "0.952", "size": "25"}, {"price": "0.974", "size": "20"}, {"price": "0.996", "size": "16"}, {"price": "0.997", "size": "402.89"}, {"price": "0.998", "size": "725.39"}], "asks": [{"price": "0.999", "size": "1417.38"}], "event_type": "book", "last_trade_price": "0.001"}, {"market": "0x53f51083a4b4fee058bfcda4d8752e4178ff99d5cf414ca40586ff46d4b98830", "asset_id": "59667302053889267080300457945986198764614482947834944120284388591968595691250", "timestamp": "1769384322672", "hash": "31006b94cf6e10cf9206f3bd71856d43e42208fb", "bids": [{"price": "0.001", "size": "305791.25"}, {"price": "0.002", "size": "257.48"}, {"price": "0.003", "size": "400"}, {"price": "0.004", "size": "6000"}, {"price": "0.005", "size": "5.93"}, {"price": "0.006", "size": "200"}, {"price": "0.008", "size": "9"}, {"price": "0.01", "size": "1010"}, {"price": "0.011", "size": "8.75"}, {"price": "0.02", "size": "2300"}, {"price": "0.03", "size": "100"}, {"price": "0.031", "size": "8.61"}, {"price": "0.05", "size": "630"}, {"price": "0.051", "size": "39"}, {"price": "0.09", "size": "300"}, {"price": "0.091", "size": "17.44"}, {"price": "0.329", "size": "6"}, {"price": "0.33", "size": "250"}, {"price": "0.331", "size": "2719.03"}, {"price": "0.65", "size": "578"}, {"price": "0.78", "size": "69.99"}, {"price": "0.82", "size": "123.33"}, {"price": "0.823", "size": "185"}, {"price": "0.824", "size": "121"}, {"price": "0.923", "size": "97"}, {"price": "0.924", "size": "20"}, {"price": "0.942", "size": "10"}, {"price": "0.943", "size": "40"}, {"price": "0.951", "size": "10"}, {"price": "0.952", "size": "25"}, {"price": "0.973", "size": "20"}, {"price": "0.989", "size": "47.18"}, {"price": "0.995", "size": "158.43"}, {"price": "0.996", "size": "219.24"}], "asks": [{"price": "0.999", "size": "487.77"}], "event_type": "book", "last_trade_price": "0.001"}, {"market": "0x09ac5925691713ff142bab96413fd34ad1113bd18bb0a090d8284fd6ccb27d8f", "asset_id": "79706026068944835262224079232154067921292858426362398176248100716599909254344", "timestamp": "1769384316871", "hash": "20d6c1da474f25b04690b0a5da889dfb40136cc2", "bids": [{"price": "0.001", "size": "1220.29"}], "asks": [{"price": "0.999", "size": "2807.99"}, {"price": "0.998", "size": "201450"}, {"price": "0.997", "size": "400"}, {"price": "0.996", "size": "8.65"}, {"price": "0.994", "size": "200"}, {"price": "0.99", "size": "2010"}, {"price": "0.989", "size": "8.75"}, {"price": "0.98", "size": "2300"}, {"price": "0.97", "size": "100"}, {"price": "0.969", "size": "7.24"}, {"price": "0.95", "size": "630"}, {"price": "0.949", "size": "39"}, {"price": "0.92", "size": "100"}, {"price": "0.919", "size": "5.62"}, {"price": "0.91", "size": "300"}, {"price": "0.86", "size": "50"}, {"price": "0.8", "size": "200"}, {"price": "0.799", "size": "5.84"}, {"price": "0.777", "size": "87"}, {"price": "0.719", "size": "250"}, {"price": "0.718", "size": "3391.48"}, {"price": "0.717", "size": "246"}, {"price": "0.66", "size": "100"}, {"price": "0.659", "size": "5"}, {"price": "0.177", "size": "185"}, {"price": "0.176", "size": "10"}, {"price": "0.148", "size": "40"}, {"price": "0.144", "size": "25"}, {"price": "0.143", "size": "20"}, {"price": "0.05", "size": "1000"}, {"price": "0.042", "size": "5"}, {"price": "0.041", "size": "10"}, {"price": "0.04", "size": "16"}, {"price": "0.039", "size": "25"}, {"price": "0.003", "size": "12.75"}, {"price": "0.002", "size": "900.49"}], "event_type": "book", "last_trade_price": "0.001"}, {"market": "0xbb9ebd08fe1834e60ee5d40b0f5b564478de30519bc8dd6d6d023539a39cd51f", "asset_id": "14039941832212049659335286897830341252093775527829576530596212959467785519299", "timestamp": "1769384399412", "hash": "5c096b687339a273555b0867a9678807d93f4558", "bids": [{"price": "0.001", "size": "502861.81"}, {"price": "0.002", "size": "250"}, {"price": "0.003", "size": "13.27"}, {"price": "0.006", "size": "83"}, {"price": "0.01", "size": "53210"}, {"price": "0.011", "size": "8.79"}, {"price": "0.02", "size": "2300"}, {"price": "0.03", "size": "100"}, {"price": "0.031", "size": "7.27"}, {"price": "0.05", "size": "630"}, {"price": "0.051", "size": "39"}, {"price": "0.08", "size": "100"}, {"price": "0.081", "size": "5.64"}, {"price": "0.094", "size": "300"}, {"price": "0.14", "size": "50"}, {"price": "0.161", "size": "250"}, {"price": "0.2", "size": "200"}, {"price": "0.201", "size": "5.82"}, {"price": "0.27", "size": "200"}, {"price": "0.34", "size": "100"}, {"price": "0.341", "size": "5"}, {"price": "0.342", "size": "10"}, {"price": "0.814", "size": "25"}, {"price": "0.815", "size": "40"}, {"price": "0.91", "size": "150"}, {"price": "0.911", "size": "15"}, {"price": "0.93", "size": "1000"}, {"price": "0.932", "size": "10"}, {"price": "0.933", "size": "20"}, {"price": "0.951", "size": "5"}, {"price": "0.958", "size": "20.1"}, {"price": "0.97", "size": "500"}, {"price": "0.971", "size": "354.38"}, {"price": "0.973", "size": "87.41"}, {"price": "0.974", "size": "188.4"}, {"price": "0.989", "size": "57"}], "asks": [{"price": "0.999", "size": "505301.07"}, {"price": "0.998", "size": "20005"}, {"price": "0.997", "size": "300"}, {"price": "0.996", "size": "170.4"}, {"price": "0.995", "size": "113.88"}], "event_type": "book", "last_trade_price": "0.005"}, {"market": "0x45a92c8b378085a254cf1678e006bc1046a60e04be1952f118239a45bc1ff2d4", "asset_id": "47914900509987469662657224450044519296684025204210693945111618026781521243443", "timestamp": "1769384289017", "hash": "96332d30ab9409e9272f845655eb5259a37c66f5", "bids": [{"price": "0.001", "size": "993.56"}], "asks": [{"price": "0.999", "size": "2708"}, {"price": "0.998", "size": "250"}, {"price": "0.997", "size": "302606.62"}, {"price": "0.994", "size": "200"}, {"price": "0.993", "size": "9.76"}, {"price": "0.99", "size": "1010"}, {"price": "0.98", "size": "2300"}, {"price": "0.979", "size": "14.97"}, {"price": "0.95", "size": "630"}, {"price": "0.949", "size": "39"}, {"price": "0.91", "size": "300"}, {"price": "0.909", "size": "17.44"}, {"price": "0.761", "size": "8"}, {"price": "0.756", "size": "294"}, {"price": "0.755", "size": "3673.46"}, {"price": "0.754", "size": "1213"}, {"price": "0.177", "size": "147"}, {"price": "0.176", "size": "121"}, {"price": "0.144", "size": "40"}, {"price": "0.142", "size": "410"}, {"price": "0.141", "size": "20"}, {"price": "0.047", "size": "11.1"}, {"price": "0.046", "size": "16"}, {"price": "0.045", "size": "25"}, {"price": "0.004", "size": "5.66"}, {"price": "0.003", "size": "750.19"}, {"price": "0.002", "size": "369.62"}], "event_type": "book", "last_trade_price": "0.001"}, {"market": "0x68220e1323e36bfbc2fa63af9c62976e759eb46049af631e56b7fb9c130ff5cb", "asset_id": "61093916433786111931785179828144353066415901600627307428882566063311322263898", "timestamp": "1769384322656", "hash": "9fc1fcabdccc880800b9b31129be47be4769205c", "bids": [{"price": "0.001", "size": "4304"}, {"price": "0.002", "size": "301450"}, {"price": "0.003", "size": "405.05"}, {"price": "0.006", "size": "200"}, {"price": "0.007", "size": "9.79"}, {"price": "0.01", "size": "2010"}, {"price": "0.02", "size": "2300"}, {"price": "0.021", "size": "6.55"}, {"price": "0.03", "size": "100"}, {"price": "0.05", "size": "630"}, {"price": "0.051", "size": "44.2"}, {"price": "0.112", "size": "300"}, {"price": "0.113", "size": "13.3"}, {"price": "0.223", "size": "82"}, {"price": "0.346", "size": "255"}, {"price": "0.347", "size": "2593.65"}, {"price": "0.523", "size": "41"}, {"price": "0.79", "size": "700"}, {"price": "0.811", "size": "492"}, {"price": "0.823", "size": "146"}, {"price": "0.832", "size": "120"}, {"price": "0.92", "size": "150"}, {"price": "0.923", "size": "346"}, {"price": "0.924", "size": "16.81"}, {"price": "0.926", "size": "10"}, {"price": "0.927", "size": "20"}, {"price": "0.946", "size": "46"}, {"price": "0.947", "size": "10"}, {"price": "0.948", "size": "16"}, {"price": "0.949", "size": "25"}, {"price": "0.98", "size": "32.51"}, {"price": "0.998", "size": "102.89"}], "asks": [{"price": "0.999", "size": "116.65"}], "event_type": "book", "last_trade_price": "0.001"}, {"market": "0x64e049eddd2da2ea85d3e7dd529efabb83e52bb9f10e78ca5e06c0e4c5ef0e02", "asset_id": "109840811354893313734425044059254590430891323754942496129100706519726473429600", "timestamp": "1769384393086", "hash": "4f03a376545d75a8f63b4958cc7d6f09ec99c2fe", "bids": [{"price": "0.001", "size": "8760"}, {"price": "0.002", "size": "10124.21"}, {"price": "0.003", "size": "250"}, {"price": "0.01", "size": "1099.86"}], "asks": [{"price": "0.999", "size": "4314.32"}, {"price": "0.998", "size": "250"}, {"price": "0.997", "size": "302606.64"}, {"price": "0.994", "size": "200"}, {"price": "0.993", "size": "9.79"}, {"price": "0.99", "size": "1010"}, {"price": "0.98", "size": "2200"}, {"price": "0.979", "size": "13.04"}, {"price": "0.95", "size": "630"}, {"price": "0.949", "size": "39"}, {"price": "0.92", "size": "3300"}, {"price": "0.919", "size": "20.09"}, {"price": "0.724", "size": "250"}, {"price": "0.723", "size": "3256.09"}, {"price": "0.229", "size": "185"}, {"price": "0.187", "size": "123"}, {"price": "0.186", "size": "10"}, {"price": "0.185", "size": "40"}, {"price": "0.184", "size": "25"}, {"price": "0.1", "size": "150"}, {"price": "0.099", "size": "20"}, {"price": "0.047", "size": "87.41"}, {"price": "0.04", "size": "500"}, {"price": "0.039", "size": "70.57"}, {"price": "0.032", "size": "10"}, {"price": "0.018", "size": "6.91"}, {"price": "0.017", "size": "19.78"}, {"price": "0.016", "size": "25"}], "event_type": "book", "last_trade_price": "0.010"}, {"market": "0xe8aa6e2e78b148ade04614fb635df30b6e7101bb356ae0d049e8f17fad3df4f7", "asset_id": "7415398757579829371388746916782351900338601049827707938782174312340133977353", "timestamp": "1769384322656", "hash": "5bc21a22640d9bec267ddf1903b7dc60be9d3a9f", "bids": [{"price": "0.001", "size": "1606.29"}], "asks": [{"price": "0.999", "size": "4182"}, {"price": "0.998", "size": "301450"}, {"price": "0.997", "size": "406.62"}, {"price": "0.994", "size": "200"}, {"price": "0.993", "size": "9.76"}, {"price": "0.99", "size": "2010"}, {"price": "0.98", "size": "2300"}, {"price": "0.979", "size": "6.89"}, {"price": "0.95", "size": "630"}, {"price": "0.949", "size": "39"}, {"price": "0.948", "size": "10.56"}, {"price": "0.906", "size": "300"}, {"price": "0.81", "size": "3000"}, {"price": "0.809", "size": "6.32"}, {"price": "0.778", "size": "300"}, {"price": "0.777", "size": "4035.87"}, {"price": "0.659", "size": "5"}, {"price": "0.177", "size": "179"}, {"price": "0.17", "size": "700"}, {"price": "0.169", "size": "240"}, {"price": "0.139", "size": "116"}, {"price": "0.08", "size": "150"}, {"price": "0.079", "size": "20"}, {"price": "0.057", "size": "10"}, {"price": "0.054", "size": "40"}, {"price": "0.053", "size": "25"}, {"price": "0.009", "size": "8.43"}, {"price": "0.007", "size": "47.77"}, {"price": "0.005", "size": "302.5"}, {"price": "0.004", "size": "298.53"}, {"price": "0.002", "size": "382.28"}], "event_type": "book", "last_trade_price": "0.001"}, {"market": "0x003478da73863b7555a88a4a240042edbdfa9ce2afbab32f34ec97dbd80c5ab7", "asset_id": "19849499173481000650143487020210206007032192502412659368242470292955038260110", "timestamp": "1769384409797", "hash": "a55c40532f86f3d7edbacc68b31c67f4864473de", "bids": [{"price": "0.001", "size": "1638.41"}], "asks": [{"price": "0.999", "size": "3249"}, {"price": "0.998", "size": "250"}, {"price": "0.997", "size": "172.62"}, {"price": "0.994", "size": "83"}, {"price": "0.993", "size": "9.76"}, {"price": "0.99", "size": "53210"}, {"price": "0.98", "size": "2200"}, {"price": "0.979", "size": "14.97"}, {"price": "0.95", "size": "630"}, {"price": "0.949", "size": "39"}, {"price": "0.91", "size": "300"}, {"price": "0.909", "size": "17.44"}, {"price": "0.701", "size": "6"}, {"price": "0.694", "size": "300"}, {"price": "0.692", "size": "746"}, {"price": "0.08", "size": "202"}, {"price": "0.075", "size": "15"}, {"price": "0.074", "size": "20"}, {"price": "0.058", "size": "10"}, {"price": "0.054", "size": "46"}, {"price": "0.053", "size": "10"}, {"price": "0.052", "size": "16"}, {"price": "0.051", "size": "25"}, {"price": "0.003", "size": "258.54"}, {"price": "0.002", "size": "667.44"}], "event_type": "book", "last_trade_price": "0.001"}, {"market": "0x438bd0f5ff930f040bc63ed2dc0585f93ef5cbd871b50efe502d703bba96654d", "asset_id": "8739167718638980235687942123866249649168680031256814828170525657956217651887", "timestamp": "1769384344961", "hash": "f81c7cd8a889b8d4aef0d8dc35c6c26222741054", "bids": [{"price": "0.001", "size": "705002.99"}, {"price": "0.002", "size": "250"}, {"price": "0.003", "size": "29.42"}, {"price": "0.01", "size": "2010"}, {"price": "0.02", "size": "1800"}, {"price": "0.021", "size": "12.96"}, {"price": "0.05", "size": "30"}, {"price": "0.051", "size": "39"}, {"price": "0.052", "size": "5000"}, {"price": "0.054", "size": "50"}, {"price": "0.055", "size": "10"}, {"price": "0.08", "size": "100"}, {"price": "0.081", "size": "5.79"}, {"price": "0.09", "size": "300"}, {"price": "0.091", "size": "21"}, {"price": "0.14", "size": "50"}, {"price": "0.2", "size": "200"}, {"price": "0.205", "size": "5.66"}, {"price": "0.27", "size": "200"}, {"price": "0.271", "size": "25"}, {"price": "0.34", "size": "100"}, {"price": "0.78", "size": "117.21"}, {"price": "0.89", "size": "40"}, {"price": "0.912", "size": "5000"}, {"price": "0.92", "size": "850"}, {"price": "0.922", "size": "15"}, {"price": "0.923", "size": "20"}, {"price": "0.954", "size": "5000"}, {"price": "0.971", "size": "2099.22"}, {"price": "0.973", "size": "3000"}, {"price": "0.975", "size": "30"}, {"price": "0.991", "size": "99"}, {"price": "0.994", "size": "882.5"}, {"price": "0.995", "size": "127.92"}], "asks": [{"price": "0.999", "size": "83961.99"}, {"price": "0.998", "size": "4255"}, {"price": "0.997", "size": "8174"}, {"price": "0.996", "size": "6254.78"}], "event_type": "book", "last_trade_price": "0.004"}, {"market": "0x73ad1ccf984fe936e2d38bfe6f9e0479d9780b07290d01495cfc0fe6e889665a", "asset_id": "8721859781630956031480953029967309557134082262242417882183208730280192682035", "timestamp": "1769384410125", "hash": "8b1b3b67aefb197020c2cd5c3d5213de4a0738d0", "bids": [{"price": "0.001", "size": "4305.04"}, {"price": "0.002", "size": "201450"}, {"price": "0.003", "size": "400"}, {"price": "0.004", "size": "8.71"}, {"price": "0.006", "size": "200"}, {"price": "0.01", "size": "2010"}, {"price": "0.011", "size": "8.8"}, {"price": "0.02", "size": "2300"}, {"price": "0.03", "size": "100"}, {"price": "0.031", "size": "7.28"}, {"price": "0.05", "size": "630"}, {"price": "0.051", "size": "39"}, {"price": "0.08", "size": "100"}, {"price": "0.081", "size": "5.65"}, {"price": "0.09", "size": "300"}, {"price": "0.14", "size": "50"}, {"price": "0.2", "size": "200"}, {"price": "0.201", "size": "5.84"}, {"price": "0.223", "size": "73"}, {"price": "0.276", "size": "250"}, {"price": "0.277", "size": "3449.09"}, {"price": "0.34", "size": "100"}, {"price": "0.49", "size": "700"}, {"price": "0.523", "size": "201"}, {"price": "0.524", "size": "5"}, {"price": "0.823", "size": "185"}, {"price": "0.825", "size": "10"}, {"price": "0.826", "size": "40"}, {"price": "0.91", "size": "150"}, {"price": "0.916", "size": "15"}, {"price": "0.917", "size": "20"}, {"price": "0.95", "size": "1000"}, {"price": "0.952", "size": "16.66"}, {"price": "0.953", "size": "25"}, {"price": "0.995", "size": "8.59"}, {"price": "0.996", "size": "48.7"}, {"price": "0.997", "size": "159.65"}, {"price": "0.998", "size": "491.36"}], "asks": [{"price": "0.999", "size": "5015.56"}], "event_type": "book", "last_trade_price": "0.001"}, {"market": "0xd1cb6a36c0eaafd15fbb30e15d210b6ea3ca6b4beacd5506a4e18c0b3c9f0c14", "asset_id": "95741946556861642865192415995078391397421392763870884030463136567133794215973", "timestamp": "1769384355796", "hash": "4d9b48fa8c0d3ce39c2577e19244a7627f3a5a51", "bids": [{"price": "0.001", "size": "2401.01"}], "asks": [{"price": "0.999", "size": "4308.99"}, {"price": "0.998", "size": "201450"}, {"price": "0.997", "size": "400"}, {"price": "0.996", "size": "8.65"}, {"price": "0.994", "size": "200"}, {"price": "0.99", "size": "2010"}, {"price": "0.989", "size": "8.75"}, {"price": "0.98", "size": "2300"}, {"price": "0.97", "size": "100"}, {"price": "0.969", "size": "7.24"}, {"price": "0.95", "size": "630"}, {"price": "0.949", "size": "39"}, {"price": "0.92", "size": "400"}, {"price": "0.919", "size": "5.62"}, {"price": "0.86", "size": "50"}, {"price": "0.8", "size": "200"}, {"price": "0.799", "size": "5.83"}, {"price": "0.701", "size": "250"}, {"price": "0.7", "size": "3200"}, {"price": "0.66", "size": "100"}, {"price": "0.609", "size": "5"}, {"price": "0.608", "size": "10"}, {"price": "0.08", "size": "1200"}, {"price": "0.079", "size": "16.81"}, {"price": "0.078", "size": "15"}, {"price": "0.07", "size": "10"}, {"price": "0.069", "size": "20"}, {"price": "0.056", "size": "40"}, {"price": "0.049", "size": "5"}, {"price": "0.048", "size": "25"}, {"price": "0.024", "size": "53.7"}, {"price": "0.023", "size": "24.1"}, {"price": "0.004", "size": "5.66"}, {"price": "0.003", "size": "20.61"}], "event_type": "book", "last_trade_price": "0.001"}, {"market": "0x4f40e41d6ba58848f8d01d4b291f54c693e3a2e7ee490800459af35f8b1b9038", "asset_id": "40404326304601432341146088950317537343596762067162777068335332534014469652791", "timestamp": "1769384316871", "hash": "877f497dc906fa041e8b84305c753964ad490b68", "bids": [{"price": "0.001", "size": "4632.29"}], "asks": [{"price": "0.999", "size": "2748"}, {"price": "0.998", "size": "201450"}, {"price": "0.997", "size": "406.62"}, {"price": "0.994", "size": "200"}, {"price": "0.993", "size": "10.45"}, {"price": "0.99", "size": "2010"}, {"price": "0.98", "size": "1000"}, {"price": "0.979", "size": "2800"}, {"price": "0.978", "size": "6.36"}, {"price": "0.95", "size": "30"}, {"price": "0.949", "size": "3039"}, {"price": "0.948", "size": "6.87"}, {"price": "0.863", "size": "300"}, {"price": "0.862", "size": "10.14"}, {"price": "0.777", "size": "87"}, {"price": "0.691", "size": "306"}, {"price": "0.69", "size": "2903.22"}, {"price": "0.689", "size": "381"}, {"price": "0.177", "size": "185"}, {"price": "0.176", "size": "10"}, {"price": "0.147", "size": "117"}, {"price": "0.121", "size": "40"}, {"price": "0.12", "size": "20"}, {"price": "0.05", "size": "713"}, {"price": "0.043", "size": "5"}, {"price": "0.042", "size": "10"}, {"price": "0.041", "size": "16"}, {"price": "0.04", "size": "25"}, {"price": "0.003", "size": "12.75"}, {"price": "0.002", "size": "715.22"}], "event_type": "book", "last_trade_price": "0.001"}, {"market": "0xaad7429c6e56ba07ab9642b66edd365ba97442042e010cc8fce27d59a08f2da5", "asset_id": "70435272270000303444232595121425292735616760933087659375750995553393761504892", "timestamp": "1769384319341", "hash": "03c8578ce9ee0b39580793509238591d0723ab0e", "bids": [{"price": "0.001", "size": "1378.99"}], "asks": [{"price": "0.999", "size": "2686.99"}, {"price": "0.998", "size": "301450"}, {"price": "0.997", "size": "400"}, {"price": "0.996", "size": "8.65"}, {"price": "0.994", "size": "200"}, {"price": "0.99", "size": "2010"}, {"price": "0.989", "size": "8.75"}, {"price": "0.98", "size": "2300"}, {"price": "0.97", "size": "100"}, {"price": "0.969", "size": "7.24"}, {"price": "0.95", "size": "630"}, {"price": "0.949", "size": "39"}, {"price": "0.92", "size": "400"}, {"price": "0.919", "size": "6.43"}, {"price": "0.86", "size": "50"}, {"price": "0.8", "size": "200"}, {"price": "0.798", "size": "10"}, {"price": "0.797", "size": "5.46"}, {"price": "0.728", "size": "400"}, {"price": "0.68", "size": "250"}, {"price": "0.679", "size": "3003.73"}, {"price": "0.66", "size": "100"}, {"price": "0.659", "size": "5"}, {"price": "0.477", "size": "201"}, {"price": "0.328", "size": "643"}, {"price": "0.177", "size": "186"}, {"price": "0.176", "size": "40"}, {"price": "0.08", "size": "850"}, {"price": "0.075", "size": "15"}, {"price": "0.074", "size": "20"}, {"price": "0.05", "size": "1000"}, {"price": "0.046", "size": "16.66"}, {"price": "0.045", "size": "25"}, {"price": "0.01", "size": "8.51"}, {"price": "0.008", "size": "48.23"}, {"price": "0.005", "size": "30.01"}, {"price": "0.002", "size": "746.31"}], "event_type": "book", "last_trade_price": "0.001"}, {"market": "0x7bc69219ef0d98cf1052e760908aa227fdc2b45e70e0469c53457266ee4f555b", "asset_id": "2941777413221672007568670508449151565377511293585698138529107990360114774959", "timestamp": "1769384324511", "hash": "66eaeccbcb403a83fbac468b60250282842658a1", "bids": [{"price": "0.001", "size": "4304"}, {"price": "0.002", "size": "301450"}, {"price": "0.003", "size": "406.62"}, {"price": "0.006", "size": "200"}, {"price": "0.007", "size": "9.76"}, {"price": "0.01", "size": "2010"}, {"price": "0.02", "size": "2200"}, {"price": "0.021", "size": "6.89"}, {"price": "0.05", "size": "630"}, {"price": "0.051", "size": "39"}, {"price": "0.053", "size": "10.43"}, {"price": "0.116", "size": "300"}, {"price": "0.191", "size": "250"}, {"price": "0.192", "size": "4687.5"}, {"price": "0.193", "size": "6.23"}, {"price": "0.223", "size": "73"}, {"price": "0.224", "size": "8"}, {"price": "0.811", "size": "492"}, {"price": "0.823", "size": "185"}, {"price": "0.86", "size": "150"}, {"price": "0.861", "size": "116"}, {"price": "0.923", "size": "224"}, {"price": "0.924", "size": "20"}, {"price": "0.943", "size": "10"}, {"price": "0.946", "size": "56"}, {"price": "0.947", "size": "16"}, {"price": "0.948", "size": "25"}, {"price": "0.993", "size": "8"}, {"price": "0.997", "size": "17.54"}, {"price": "0.998", "size": "804.9"}], "asks": [{"price": "0.999", "size": "786.59"}], "event_type": "book", "last_trade_price": "0.001"}, {"market": "0x1407cc4f937c9f1bf80b8519e8e74a43f4670e3d9e51344e03b67cf1b1dcc17b", "asset_id": "61333438224991090029549325331522226961828740049006775405883405120037322223568", "timestamp": "1769384411932", "hash": "b7bebfc5e7c0173dd254542757a6c39038c1d634", "bids": [{"price": "0.001", "size": "1122.97"}, {"price": "0.002", "size": "192.28"}], "asks": [{"price": "0.999", "size": "403902.82"}, {"price": "0.998", "size": "250"}, {"price": "0.997", "size": "400"}, {"price": "0.996", "size": "8.73"}, {"price": "0.994", "size": "200"}, {"price": "0.99", "size": "2010"}, {"price": "0.989", "size": "8.83"}, {"price": "0.98", "size": "2200"}, {"price": "0.97", "size": "100"}, {"price": "0.969", "size": "7.3"}, {"price": "0.95", "size": "630"}, {"price": "0.949", "size": "39"}, {"price": "0.948", "size": "10"}, {"price": "0.919", "size": "5.67"}, {"price": "0.91", "size": "3400"}, {"price": "0.909", "size": "300"}, {"price": "0.86", "size": "50"}, {"price": "0.8", "size": "200"}, {"price": "0.799", "size": "5.83"}, {"price": "0.777", "size": "87"}, {"price": "0.706", "size": "3261.22"}, {"price": "0.705", "size": "25"}, {"price": "0.66", "size": "100"}, {"price": "0.659", "size": "40"}, {"price": "0.477", "size": "201"}, {"price": "0.46", "size": "700"}, {"price": "0.459", "size": "5"}, {"price": "0.35", "size": "150"}, {"price": "0.177", "size": "185"}, {"price": "0.166", "size": "25"}, {"price": "0.165", "size": "20"}, {"price": "0.05", "size": "168.15"}, {"price": "0.049", "size": "10"}, {"price": "0.029", "size": "4000"}, {"price": "0.026", "size": "260"}, {"price": "0.008", "size": "31.45"}, {"price": "0.005", "size": "371.02"}], "event_type": "book", "last_trade_price": "0.002"}, {"market": "0x76c29af7fdae5e892d4e4a07c561d9369f26bcea68c8cf74446b7721f36f45c0", "asset_id": "54031257762448920866070382525869450987772451934273228136657254025477075623594", "timestamp": "1769384410389", "hash": "cc57f02e8e4079b40fd845a0edfcff28e55375cf", "bids": [{"price": "0.001", "size": "4308.99"}, {"price": "0.002", "size": "301450"}, {"price": "0.003", "size": "400"}, {"price": "0.004", "size": "8.65"}, {"price": "0.006", "size": "200"}, {"price": "0.01", "size": "2010"}, {"price": "0.011", "size": "8.75"}, {"price": "0.02", "size": "2300"}, {"price": "0.03", "size": "100"}, {"price": "0.031", "size": "7.24"}, {"price": "0.05", "size": "630"}, {"price": "0.051", "size": "39"}, {"price": "0.08", "size": "100"}, {"price": "0.081", "size": "5.62"}, {"price": "0.092", "size": "300"}, {"price": "0.14", "size": "50"}, {"price": "0.2", "size": "200"}, {"price": "0.201", "size": "5.84"}, {"price": "0.223", "size": "87"}, {"price": "0.28", "size": "250"}, {"price": "0.281", "size": "3402.84"}, {"price": "0.283", "size": "30"}, {"price": "0.34", "size": "100"}, {"price": "0.341", "size": "5"}, {"price": "0.823", "size": "172"}, {"price": "0.824", "size": "10"}, {"price": "0.85", "size": "40"}, {"price": "0.92", "size": "150"}, {"price": "0.921", "size": "15"}, {"price": "0.922", "size": "20"}, {"price": "0.95", "size": "1000"}, {"price": "0.956", "size": "5"}, {"price": "0.957", "size": "10"}, {"price": "0.958", "size": "16"}, {"price": "0.959", "size": "25"}, {"price": "0.997", "size": "12.75"}, {"price": "0.998", "size": "880.2"}], "asks": [{"price": "0.999", "size": "1059.28"}], "event_type": "book", "last_trade_price": "0.001"}, {"market": "0x7bc0c2a607e267892269961a911a0b666f29594433a7d95c0dd56babdc29f308", "asset_id": "13373402356576882724938800858000537994853003539200086787602846320764306199642", "timestamp": "1769384295685", "hash": "9c652b095446d5034d6ba01bc06d91141e478e60", "bids": [{"price": "0.001", "size": "7379.18"}, {"price": "0.002", "size": "2755"}, {"price": "0.003", "size": "103.56"}], "asks": [{"price": "0.999", "size": "302695"}, {"price": "0.998", "size": "250"}, {"price": "0.997", "size": "202606.63"}, {"price": "0.994", "size": "200"}, {"price": "0.993", "size": "9.76"}, {"price": "0.99", "size": "1010"}, {"price": "0.98", "size": "1800"}, {"price": "0.979", "size": "14.98"}, {"price": "0.95", "size": "30"}, {"price": "0.949", "size": "39"}, {"price": "0.948", "size": "21000"}, {"price": "0.947", "size": "10"}, {"price": "0.91", "size": "300"}, {"price": "0.909", "size": "17.44"}, {"price": "0.708", "size": "5000"}, {"price": "0.707", "size": "3071.67"}, {"price": "0.65", "size": "5"}, {"price": "0.649", "size": "250"}, {"price": "0.5", "size": "20"}, {"price": "0.19", "size": "700"}, {"price": "0.177", "size": "168"}, {"price": "0.176", "size": "40"}, {"price": "0.13", "size": "150"}, {"price": "0.124", "size": "25"}, {"price": "0.08", "size": "736"}, {"price": "0.077", "size": "15"}, {"price": "0.076", "size": "20"}, {"price": "0.025", "size": "510.25"}, {"price": "0.023", "size": "500"}, {"price": "0.022", "size": "189.75"}, {"price": "0.012", "size": "38.1"}, {"price": "0.01", "size": "8.38"}, {"price": "0.009", "size": "130.23"}, {"price": "0.007", "size": "147.6"}], "event_type": "book", "last_trade_price": "0.003"}, {"market": "0x7bc0c2a607e267892269961a911a0b666f29594433a7d95c0dd56babdc29f308", "asset_id": "105586204831827806415544690970027356427067426133583910562372754475220137027200", "timestamp": "1769384295685", "hash": "3efc0cf6b4bb3995edc6016d8f1f04871fdaae0f", "bids": [{"price": "0.001", "size": "302695"}, {"price": "0.002", "size": "250"}, {"price": "0.003", "size": "202606.63"}, {"price": "0.006", "size": "200"}, {"price": "0.007", "size": "9.76"}, {"price": "0.01", "size": "1010"}, {"price": "0.02", "size": "1800"}, {"price": "0.021", "size": "14.98"}, {"price": "0.05", "size": "30"}, {"price": "0.051", "size": "39"}, {"price": "0.052", "size": "21000"}, {"price": "0.053", "size": "10"}, {"price": "0.09", "size": "300"}, {"price": "0.091", "size": "17.44"}, {"price": "0.292", "size": "5000"}, {"price": "0.293", "size": "3071.67"}, {"price": "0.35", "size": "5"}, {"price": "0.351", "size": "250"}, {"price": "0.5", "size": "20"}, {"price": "0.81", "size": "700"}, {"price": "0.823", "size": "168"}, {"price": "0.824", "size": "40"}, {"price": "0.87", "size": "150"}, {"price": "0.876", "size": "25"}, {"price": "0.92", "size": "736"}, {"price": "0.923", "size": "15"}, {"price": "0.924", "size": "20"}, {"price": "0.975", "size": "510.25"}, {"price": "0.977", "size": "500"}, {"price": "0.978", "size": "189.75"}, {"price": "0.988", "size": "38.1"}, {"price": "0.99", "size": "8.38"}, {"price": "0.991", "size": "130.23"}, {"price": "0.993", "size": "147.6"}], "asks": [{"price": "0.999", "size": "7379.18"}, {"price": "0.998", "size": "2755"}, {"price": "0.997", "size": "103.56"}], "event_type": "book", "last_trade_price": "0.003"}, {"market": "0x53139e5393daa3be90f7a06a12915345edbec881b618042c4a067a2d5c5e2a12", "asset_id": "42936122567428135552688640317579851311197787192394235773027440258132035376520", "timestamp": "1769384329111", "hash": "43b7322df5c749ba3b8461415f288e4e9e0c2860", "bids": [], "asks": [{"price": "0.999", "size": "2750"}, {"price": "0.998", "size": "301450"}, {"price": "0.997", "size": "406.63"}, {"price": "0.994", "size": "200"}, {"price": "0.993", "size": "9.76"}, {"price": "0.99", "size": "2010"}, {"price": "0.98", "size": "2200"}, {"price": "0.979", "size": "6.89"}, {"price": "0.95", "size": "630"}, {"price": "0.949", "size": "39"}, {"price": "0.948", "size": "10.62"}, {"price": "0.9", "size": "300"}, {"price": "0.899", "size": "19"}, {"price": "0.81", "size": "3000"}, {"price": "0.809", "size": "4712.04"}, {"price": "0.808", "size": "6.27"}, {"price": "0.629", "size": "300"}, {"price": "0.5", "size": "10"}, {"price": "0.189", "size": "246"}, {"price": "0.179", "size": "243"}, {"price": "0.169", "size": "120"}, {"price": "0.08", "size": "150"}, {"price": "0.07", "size": "40"}, {"price": "0.069", "size": "10"}, {"price": "0.049", "size": "5"}, {"price": "0.047", "size": "16.66"}, {"price": "0.046", "size": "25"}, {"price": "0.011", "size": "23.36"}, {"price": "0.004", "size": "5.46"}, {"price": "0.003", "size": "158.09"}, {"price": "0.002", "size": "563.46"}], "event_type": "book", "last_trade_price": ""}, {"market": "0xf2c1d8073d365d0a6ca005c37e2250efb4625d5247f1f8db7f7edd194f235ca6", "asset_id": "79626073716122806247747146996983459766280740135190159206018393840044111275887", "timestamp": "1769384316871", "hash": "7c37433d8c01b996529f796b1edd217c331a9f95", "bids": [{"price": "0.001", "size": "4304.06"}, {"price": "0.002", "size": "201450"}, {"price": "0.003", "size": "406.64"}, {"price": "0.006", "size": "200"}, {"price": "0.007", "size": "10.03"}, {"price": "0.01", "size": "2010"}, {"price": "0.02", "size": "2300"}, {"price": "0.021", "size": "5.06"}, {"price": "0.05", "size": "630"}, {"price": "0.051", "size": "39"}, {"price": "0.052", "size": "5.24"}, {"price": "0.114", "size": "300"}, {"price": "0.115", "size": "13.22"}, {"price": "0.223", "size": "73"}, {"price": "0.236", "size": "250"}, {"price": "0.237", "size": "3805.46"}, {"price": "0.238", "size": "336"}, {"price": "0.523", "size": "201"}, {"price": "0.823", "size": "185"}, {"price": "0.841", "size": "118"}, {"price": "0.842", "size": "10"}, {"price": "0.843", "size": "40"}, {"price": "0.898", "size": "25"}, {"price": "0.899", "size": "20"}, {"price": "0.951", "size": "5"}, {"price": "0.978", "size": "89.22"}, {"price": "0.979", "size": "369.28"}, {"price": "0.98", "size": "215.64"}, {"price": "0.981", "size": "111.28"}, {"price": "0.99", "size": "5"}, {"price": "0.991", "size": "58.16"}, {"price": "0.994", "size": "22"}], "asks": [{"price": "0.999", "size": "7527.3"}, {"price": "0.998", "size": "223.66"}], "event_type": "book", "last_trade_price": "0.002"}, {"market": "0x27d3b228eb7a01bf021f86dd9255f32f01a386b64577ff44f97b2bf720edb078", "asset_id": "106093880903038709632538183024596068620470661192596344740386929058766343990013", "timestamp": "1769384361308", "hash": "fe71c92230b5a5cf6b449a3ef0a9f317a334b2fb", "bids": [{"price": "0.001", "size": "2804"}, {"price": "0.002", "size": "201450"}, {"price": "0.003", "size": "400"}, {"price": "0.004", "size": "8.67"}, {"price": "0.006", "size": "200"}, {"price": "0.01", "size": "2010"}, {"price": "0.011", "size": "8.77"}, {"price": "0.02", "size": "2300"}, {"price": "0.03", "size": "100"}, {"price": "0.031", "size": "8.63"}, {"price": "0.05", "size": "630"}, {"price": "0.051", "size": "39"}, {"price": "0.09", "size": "300"}, {"price": "0.091", "size": "17.48"}, {"price": "0.16", "size": "3000"}, {"price": "0.332", "size": "250"}, {"price": "0.333", "size": "2702.7"}, {"price": "0.523", "size": "201"}, {"price": "0.65", "size": "150"}, {"price": "0.677", "size": "590"}, {"price": "0.763", "size": "131"}, {"price": "0.823", "size": "100"}, {"price": "0.826", "size": "10"}, {"price": "0.827", "size": "20"}, {"price": "0.946", "size": "40"}, {"price": "0.948", "size": "11.1"}, {"price": "0.949", "size": "16"}, {"price": "0.95", "size": "25"}, {"price": "0.996", "size": "7.84"}, {"price": "0.997", "size": "44.45"}, {"price": "0.998", "size": "672.1"}], "asks": [{"price": "0.999", "size": "1274.27"}], "event_type": "book", "last_trade_price": "0.001"}, {"market": "0x53139e5393daa3be90f7a06a12915345edbec881b618042c4a067a2d5c5e2a12", "asset_id": "37545743105054357675350349016261948572964975442151011777359623561010737340634", "timestamp": "1769384329111", "hash": "96923e3ee43687d86e34f768f8bce35b0933d975", "bids": [{"price": "0.001", "size": "2750"}, {"price": "0.002", "size": "301450"}, {"price": "0.003", "size": "406.63"}, {"price": "0.006", "size": "200"}, {"price": "0.007", "size": "9.76"}, {"price": "0.01", "size": "2010"}, {"price": "0.02", "size": "2200"}, {"price": "0.021", "size": "6.89"}, {"price": "0.05", "size": "630"}, {"price": "0.051", "size": "39"}, {"price": "0.052", "size": "10.62"}, {"price": "0.1", "size": "300"}, {"price": "0.101", "size": "19"}, {"price": "0.19", "size": "3000"}, {"price": "0.191", "size": "4712.04"}, {"price": "0.192", "size": "6.27"}, {"price": "0.371", "size": "300"}, {"price": "0.5", "size": "10"}, {"price": "0.811", "size": "246"}, {"price": "0.821", "size": "243"}, {"price": "0.831", "size": "120"}, {"price": "0.92", "size": "150"}, {"price": "0.93", "size": "40"}, {"price": "0.931", "size": "10"}, {"price": "0.951", "size": "5"}, {"price": "0.953", "size": "16.66"}, {"price": "0.954", "size": "25"}, {"price": "0.989", "size": "23.36"}, {"price": "0.996", "size": "5.46"}, {"price": "0.997", "size": "158.09"}, {"price": "0.998", "size": "563.46"}], "asks": [], "event_type": "book", "last_trade_price": ""}, {"market": "0xd80e46775331928bde30cc8ff482f42823b74115677a4ec15779d45a25f47fc1", "asset_id": "94147980495506523061285599391654217252672465986872966229183455459770874471291", "timestamp": "1769384320216", "hash": "2f6289a29cfde0192393b5da6c9dc0c6e766cf0c", "bids": [{"price": "0.001", "size": "4304"}, {"price": "0.002", "size": "301450"}, {"price": "0.003", "size": "406.63"}, {"price": "0.006", "size": "200"}, {"price": "0.007", "size": "9.76"}, {"price": "0.01", "size": "2010"}, {"price": "0.02", "size": "2300"}, {"price": "0.021", "size": "14.98"}, {"price": "0.05", "size": "630"}, {"price": "0.051", "size": "39"}, {"price": "0.09", "size": "300"}, {"price": "0.091", "size": "17.44"}, {"price": "0.315", "size": "6"}, {"price": "0.321", "size": "2803.73"}, {"price": "0.322", "size": "1009"}, {"price": "0.823", "size": "142"}, {"price": "0.923", "size": "372"}, {"price": "0.924", "size": "98.99"}, {"price": "0.926", "size": "15"}, {"price": "0.937", "size": "10"}, {"price": "0.938", "size": "40"}, {"price": "0.951", "size": "5"}, {"price": "0.954", "size": "25"}, {"price": "0.988", "size": "114.86"}, {"price": "0.989", "size": "20"}, {"price": "0.996", "size": "30.01"}, {"price": "0.997", "size": "13.46"}, {"price": "0.998", "size": "233.83"}], "asks": [], "event_type": "book", "last_trade_price": "0.001"}, {"market": "0x3590d080b030a479d32cfdc39eb16d5666c70b32326bee61076cfa3372d0e145", "asset_id": "105986652731971281617915617408962849670669850444959910165813420329566758424999", "timestamp": "1769384316806", "hash": "ca320592793b52d2f4ad5cac2ffa30bf8d8b55e0", "bids": [{"price": "0.001", "size": "604008.19"}, {"price": "0.002", "size": "250"}, {"price": "0.003", "size": "400"}, {"price": "0.004", "size": "8.82"}, {"price": "0.006", "size": "200"}, {"price": "0.01", "size": "2010"}, {"price": "0.011", "size": "8.92"}, {"price": "0.02", "size": "2200"}, {"price": "0.03", "size": "100"}, {"price": "0.031", "size": "7.66"}, {"price": "0.05", "size": "630"}, {"price": "0.051", "size": "39"}, {"price": "0.082", "size": "7000"}, {"price": "0.083", "size": "5.06"}, {"price": "0.108", "size": "20400"}, {"price": "0.14", "size": "50"}, {"price": "0.141", "size": "10"}, {"price": "0.2", "size": "200"}, {"price": "0.201", "size": "5.94"}, {"price": "0.276", "size": "250"}, {"price": "0.277", "size": "3449.09"}, {"price": "0.34", "size": "100"}, {"price": "0.341", "size": "5"}, {"price": "0.73", "size": "150"}, {"price": "0.823", "size": "185"}, {"price": "0.825", "size": "40"}, {"price": "0.913", "size": "800"}, {"price": "0.924", "size": "15"}, {"price": "0.936", "size": "25"}, {"price": "0.937", "size": "20"}, {"price": "0.961", "size": "1000"}, {"price": "0.982", "size": "193.63"}, {"price": "0.983", "size": "400"}, {"price": "0.984", "size": "29.9"}, {"price": "0.99", "size": "148.76"}, {"price": "0.991", "size": "26"}], "asks": [{"price": "0.999", "size": "6096.01"}, {"price": "0.998", "size": "448.56"}], "event_type": "book", "last_trade_price": "0.002"}, {"market": "0xd12252318b547e004af2773f4b6d11c6cca2c3708c9648b7ce976f6be394913b", "asset_id": "58692710125244578295801513269064116127644889610624817969032949228424472175600", "timestamp": "1769384319341", "hash": "9a66fd255a894f1df5dbcfa2187aed66589498be", "bids": [{"price": "0.001", "size": "1528.94"}], "asks": [{"price": "0.999", "size": "2682.04"}, {"price": "0.998", "size": "301450"}, {"price": "0.997", "size": "406.64"}, {"price": "0.994", "size": "200"}, {"price": "0.993", "size": "9.79"}, {"price": "0.99", "size": "2010"}, {"price": "0.98", "size": "2300"}, {"price": "0.979", "size": "6.9"}, {"price": "0.95", "size": "630"}, {"price": "0.949", "size": "39"}, {"price": "0.948", "size": "10.58"}, {"price": "0.902", "size": "300"}, {"price": "0.801", "size": "300"}, {"price": "0.8", "size": "10"}, {"price": "0.78", "size": "3000"}, {"price": "0.779", "size": "4077.84"}, {"price": "0.477", "size": "201"}, {"price": "0.23", "size": "700"}, {"price": "0.199", "size": "281"}, {"price": "0.177", "size": "186"}, {"price": "0.17", "size": "150"}, {"price": "0.169", "size": "120"}, {"price": "0.133", "size": "13.33"}, {"price": "0.131", "size": "25"}, {"price": "0.13", "size": "40"}, {"price": "0.128", "size": "410"}, {"price": "0.127", "size": "20"}, {"price": "0.01", "size": "8.22"}, {"price": "0.008", "size": "46.61"}, {"price": "0.006", "size": "30.01"}, {"price": "0.002", "size": "601.4"}], "event_type": "book", "last_trade_price": "0.001"}]}
{"_local_timestamp": "2026-01-25T23:40:40.898902+00:00", "data": {"market": "0xd80e46775331928bde30cc8ff482f42823b74115677a4ec15779d45a25f47fc1", "price_changes": [{"asset_id": "94147980495506523061285599391654217252672465986872966229183455459770874471291", "price": "0.315", "size": "0", "side": "BUY", "hash": "a19e116478e827ba5651dc4d02c0902c0c7838a2", "best_bid": "0.998", "best_ask": "1"}, {"asset_id": "98461653036081390149693407208637821266204790775472074887403914584572668702865", "price": "0.685", "size": "0", "side": "SELL", "hash": "0c50ed59be69f4c390087fb6ed62acaf422bc990", "best_bid": "0", "best_ask": "0.002"}], "timestamp": "1769384440786", "event_type": "price_change"}}
{"_local_timestamp": "2026-01-25T23:40:40.939460+00:00", "data": {"market": "0xd80e46775331928bde30cc8ff482f42823b74115677a4ec15779d45a25f47fc1", "price_changes": [{"asset_id": "94147980495506523061285599391654217252672465986872966229183455459770874471291", "price": "0.323", "size": "6", "side": "BUY", "hash": "d162515b5d971abd9d014b81211d1237c6a316fd", "best_bid": "0.998", "best_ask": "1"}, {"asset_id": "98461653036081390149693407208637821266204790775472074887403914584572668702865", "price": "0.677", "size": "6", "side": "SELL", "hash": "7fc4af0492fa630d2b8a50d4d7cdee0bbfb5693a", "best_bid": "0", "best_ask": "0.002"}], "timestamp": "1769384440871", "event_type": "price_change"}}
{"_local_timestamp": "2026-01-25T23:40:41.142486+00:00", "data": {"market": "0xa4dad4202b71fcd1387651e9eae72cb138c9b61c4194f93f5e8da4a3d534269c", "price_changes": [{"asset_id": "80457400145229493285131901610968168953953012727977795272540798397863492712492", "price": "0.35", "size": "0", "side": "BUY", "hash": "878156be8328791bdcdbf8fade87c8e66fa6156f", "best_bid": "0.988", "best_ask": "0.99"}, {"asset_id": "82555109203307099745725321482723908789076391198733120428808326995300770905860", "price": "0.65", "size": "0", "side": "SELL", "hash": "b4984de5320ee5e0f9301a2d071be4a76f7bc908", "best_bid": "0.01", "best_ask": "0.012"}], "timestamp": "1769384441051", "event_type": "price_change"}}
{"_local_timestamp": "2026-01-25T23:40:41.192203+00:00", "data": {"market": "0x438bd0f5ff930f040bc63ed2dc0585f93ef5cbd871b50efe502d703bba96654d", "price_changes": [{"asset_id": "8739167718638980235687942123866249649168680031256814828170525657956217651887", "price": "0.092", "size": "40", "side": "BUY", "hash": "2e36afa6b58791e34474902c7ff08daebc7c0672", "best_bid": "0.995", "best_ask": "0.996"}, {"asset_id": "53925808913836840946371550342430470487372041989648351858443846988581594567500", "price": "0.908", "size": "40", "side": "SELL", "hash": "05874e32c091a2ba2484b1f68d07ccf7dd90009b", "best_bid": "0.004", "best_ask": "0.005"}], "timestamp": "1769384441109", "event_type": "price_change"}}
{"_local_timestamp": "2026-01-25T23:40:41.195881+00:00", "data": {"market": "0x6bc389514aeed2d49f77818df91931b8f47bca741b922b5aa581bcd285898ecf", "price_changes": [{"asset_id": "16489262565579695131848767429570049041149464887984576468765279262944286152030", "price": "0.527", "size": "15", "side": "BUY", "hash": "09be4a2bd3d3d3f864a28fdc7aa37736cf71c96b", "best_bid": "0.997", "best_ask": "0.999"}, {"asset_id": "62692103489206718495616938107149784138085199695151413614837109358489160284585", "price": "0.473", "size": "15", "side": "SELL", "hash": "db639f95f82b4574b0234622194ecb89e7a36392", "best_bid": "0.001", "best_ask": "0.003"}], "timestamp": "1769384441111", "event_type": "price_change"}}
{"_local_timestamp": "2026-01-25T23:40:41.198916+00:00", "data": {"market": "0x88298e294408106c07c49520e9bf10c7dc469afe13e834be34d95e82bc36542e", "price_changes": [{"asset_id": "110927174810108466705078650135127005951257798916789146270595008049405408818734", "price": "0.919", "size": "0", "side": "BUY", "hash": "47cde8e7f20f9496438b26ff1c60dfd51a89bc3f", "best_bid": "0.991", "best_ask": "0.995"}, {"asset_id": "28970242768597401097961438832075151737962074789968575309469772733732578617699", "price": "0.081", "size": "0", "side": "SELL", "hash": "5bb6a266191ddbd3170bb411fd598950b1dc29d7", "best_bid": "0.005", "best_ask": "0.009"}], "timestamp": "1769384441111", "event_type": "price_change"}}
{"_local_timestamp": "2026-01-25T23:40:41.357130+00:00", "data": {"market": "0x88298e294408106c07c49520e9bf10c7dc469afe13e834be34d95e82bc36542e", "price_changes": [{"asset_id": "110927174810108466705078650135127005951257798916789146270595008049405408818734", "price": "0.927", "size": "0", "side": "BUY", "hash": "15e9181861b704bdc6386ecea22cb07eacd71c53", "best_bid": "0.991", "best_ask": "0.995"}, {"asset_id": "28970242768597401097961438832075151737962074789968575309469772733732578617699", "price": "0.073", "size": "0", "side": "SELL", "hash": "b0a4a0e491c893a339d52c2e9b6e231c6537d321", "best_bid": "0.005", "best_ask": "0.009"}], "timestamp": "1769384441284", "event_type": "price_change"}}
{"_local_timestamp": "2026-01-25T23:40:41.360396+00:00", "data": {"market": "0x73ad1ccf984fe936e2d38bfe6f9e0479d9780b07290d01495cfc0fe6e889665a", "price_changes": [{"asset_id": "8721859781630956031480953029967309557134082262242417882183208730280192682035", "price": "0.916", "size": "0", "side": "BUY", "hash": "aa2be2e8bd888c42acc8cabe054f40860c20844d", "best_bid": "0.998", "best_ask": "0.999"}, {"asset_id": "106144597899636887285661247566617521480303783850130038753142172360623351151116", "price": "0.084", "size": "0", "side": "SELL", "hash": "222afebef3b3ed5f4a162cbb49872488cdc2d912", "best_bid": "0.001", "best_ask": "0.002"}], "timestamp": "1769384441285", "event_type": "price_change"}}
{"_local_timestamp": "2026-01-25T23:40:41.362986+00:00", "data": {"market": "0xbb9ebd08fe1834e60ee5d40b0f5b564478de30519bc8dd6d6d023539a39cd51f", "price_changes": [{"asset_id": "14039941832212049659335286897830341252093775527829576530596212959467785519299", "price": "0.932", "size": "0", "side": "BUY", "hash": "3f9b666e845db438762bf75636e728f401b68751", "best_bid": "0.989", "best_ask": "0.995"}, {"asset_id": "89553061197618390623760390657385664748681901228299157936065698474602382096708", "price": "0.068", "size": "0", "side": "SELL", "hash": "34338a1a6bc385739b9c1d082901607fc4e6f628", "best_bid": "0.005", "best_ask": "0.011"}], "timestamp": "1769384441285", "event_type": "price_change"}}
{"_local_timestamp": "2026-01-25T23:40:41.427800+00:00", "data": {"market": "0x88298e294408106c07c49520e9bf10c7dc469afe13e834be34d95e82bc36542e", "price_changes": [{"asset_id": "110927174810108466705078650135127005951257798916789146270595008049405408818734", "price": "0.918", "size": "15", "side": "BUY", "hash": "40ca07037b2a9708284436cb0bbb6125ae5bcdcd", "best_bid": "0.991", "best_ask": "0.995"}, {"asset_id": "28970242768597401097961438832075151737962074789968575309469772733732578617699", "price": "0.082", "size": "15", "side": "SELL", "hash": "8427e4e1b88d5a4218330f20860d4fe58f1396be", "best_bid": "0.005", "best_ask": "0.009"}], "timestamp": "1769384441364", "event_type": "price_change"}}
{"_local_timestamp": "2026-01-25T23:40:41.432816+00:00", "data": {"market": "0x88298e294408106c07c49520e9bf10c7dc469afe13e834be34d95e82bc36542e", "price_changes": [{"asset_id": "110927174810108466705078650135127005951257798916789146270595008049405408818734", "price": "0.929", "size": "10", "side": "BUY", "hash": "27f203124a73a0015db7ebc97ceab3dec5cb74ba", "best_bid": "0.991", "best_ask": "0.995"}, {"asset_id": "28970242768597401097961438832075151737962074789968575309469772733732578617699", "price": "0.071", "size": "10", "side": "SELL", "hash": "bf3af4fafe93a90f27db516d85729e235580b56c", "best_bid": "0.005", "best_ask": "0.009"}], "timestamp": "1769384441365", "event_type": "price_change"}}
{"_local_timestamp": "2026-01-25T23:40:41.435165+00:00", "data": {"market": "0x73ad1ccf984fe936e2d38bfe6f9e0479d9780b07290d01495cfc0fe6e889665a", "price_changes": [{"asset_id": "8721859781630956031480953029967309557134082262242417882183208730280192682035", "price": "0.918", "size": "10", "side": "BUY", "hash": "78a044fa3b2ea45eb8d8626c13aabd5f7b80048b", "best_bid": "0.998", "best_ask": "0.999"}, {"asset_id": "106144597899636887285661247566617521480303783850130038753142172360623351151116", "price": "0.082", "size": "10", "side": "SELL", "hash": "1890dc95b5cfe525c904bb6a91baa1d44f9b65aa", "best_bid": "0.001", "best_ask": "0.002"}], "timestamp": "1769384441366", "event_type": "price_change"}}
{"_local_timestamp": "2026-01-25T23:40:41.437438+00:00", "data": {"market": "0x73ad1ccf984fe936e2d38bfe6f9e0479d9780b07290d01495cfc0fe6e889665a", "price_changes": [{"asset_id": "8721859781630956031480953029967309557134082262242417882183208730280192682035", "price": "0.824", "size": "27", "side": "BUY", "hash": "b1536ff11de3d528b52a84be869d99088c61cdc9", "best_bid": "0.998", "best_ask": "0.999"}, {"asset_id": "106144597899636887285661247566617521480303783850130038753142172360623351151116", "price": "0.176", "size": "27", "side": "SELL", "hash": "525136f92860527906fcf6b766121ec4d601aede", "best_bid": "0.001", "best_ask": "0.002"}], "timestamp": "1769384441367", "event_type": "price_change"}}
{"_local_timestamp": "2026-01-25T23:40:41.443009+00:00", "data": {"market": "0x73ad1ccf984fe936e2d38bfe6f9e0479d9780b07290d01495cfc0fe6e889665a", "price_changes": [{"asset_id": "8721859781630956031480953029967309557134082262242417882183208730280192682035", "price": "0.918", "size": "25", "side": "BUY", "hash": "1d5deb901baa380a7e8152da12cf9c0ac249b9f8", "best_bid": "0.998", "best_ask": "0.999"}, {"asset_id": "106144597899636887285661247566617521480303783850130038753142172360623351151116", "price": "0.082", "size": "25", "side": "SELL", "hash": "5f904ac7718806b85bf0a48a00b237c79589f4d0", "best_bid": "0.001", "best_ask": "0.002"}], "timestamp": "1769384441367", "event_type": "price_change"}}
{"_local_timestamp": "2026-01-25T23:40:41.528894+00:00", "data": {"market": "0x6bc389514aeed2d49f77818df91931b8f47bca741b922b5aa581bcd285898ecf", "price_changes": [{"asset_id": "16489262565579695131848767429570049041149464887984576468765279262944286152030", "price": "0.527", "size": "0", "side": "BUY", "hash": "eacd569416011532fd46b9d10a6cd518daad62b2", "best_bid": "0.997", "best_ask": "0.999"}, {"asset_id": "62692103489206718495616938107149784138085199695151413614837109358489160284585", "price": "0.473", "size": "0", "side": "SELL", "hash": "f8e162473f0f4e5846c1270e638b2c29e5c7d847", "best_bid": "0.001", "best_ask": "0.003"}], "timestamp": "1769384441447", "event_type": "price_change"}}
{"_local_timestamp": "2026-01-25T23:40:41.531551+00:00", "data": {"market": "0x003478da73863b7555a88a4a240042edbdfa9ce2afbab32f34ec97dbd80c5ab7", "price_changes": [{"asset_id": "15388846204487952420250024653778730612452760958783811368620029058645994602122", "price": "0.925", "size": "0", "side": "BUY", "hash": "0a87ca97fa518f6374c9a93195b4517d7b009cdd", "best_bid": "0.998", "best_ask": "0.999"}, {"asset_id": "19849499173481000650143487020210206007032192502412659368242470292955038260110", "price": "0.075", "size": "0", "side": "SELL", "hash": "e66f25bbbf4e7b6c6f1eea533ae3c89b086fe2f4", "best_bid": "0.001", "best_ask": "0.002"}], "timestamp": "1769384441447", "event_type": "price_change"}}
{"_local_timestamp": "2026-01-25T23:40:41.533803+00:00", "data": {"market": "0xbb9ebd08fe1834e60ee5d40b0f5b564478de30519bc8dd6d6d023539a39cd51f", "price_changes": [{"asset_id": "14039941832212049659335286897830341252093775527829576530596212959467785519299", "price": "0.911", "size": "0", "side": "BUY", "hash": "5e097c4862466ae396c7d0fcc1cef807fab2af31", "best_bid": "0.989", "best_ask": "0.995"}, {"asset_id": "89553061197618390623760390657385664748681901228299157936065698474602382096708", "price": "0.089", "size": "0", "side": "SELL", "hash": "7350054373bc20e46b5596206bf14448a377228a", "best_bid": "0.005", "best_ask": "0.011"}], "timestamp": "1769384441447", "event_type": "price_change"}}
{"_local_timestamp": "2026-01-25T23:40:41.580166+00:00", "data": {"market": "0x003478da73863b7555a88a4a240042edbdfa9ce2afbab32f34ec97dbd80c5ab7", "price_changes": [{"asset_id": "15388846204487952420250024653778730612452760958783811368620029058645994602122", "price": "0.927", "size": "10", "side": "BUY", "hash": "4d0d25604f77c96674772a4a2fa831a6ef153edc", "best_bid": "0.998", "best_ask": "0.999"}, {"asset_id": "19849499173481000650143487020210206007032192502412659368242470292955038260110", "price": "0.073", "size": "10", "side": "SELL", "hash": "c4b47ea909502df9a1a23c4cd5ce10ad2f3bd25e", "best_bid": "0.001", "best_ask": "0.002"}], "timestamp": "1769384441515", "event_type": "price_change"}}
{"_local_timestamp": "2026-01-25T23:40:41.582513+00:00", "data": {"market": "0xbb9ebd08fe1834e60ee5d40b0f5b564478de30519bc8dd6d6d023539a39cd51f", "price_changes": [{"asset_id": "14039941832212049659335286897830341252093775527829576530596212959467785519299", "price": "0.934", "size": "10", "side": "BUY", "hash": "839bbe29205787ff8a1b51d5d873c80ac01af558", "best_bid": "0.989", "best_ask": "0.995"}, {"asset_id": "89553061197618390623760390657385664748681901228299157936065698474602382096708", "price": "0.066", "size": "10", "side": "SELL", "hash": "79e953fc78d1cdf436367a296b84e2393a20b354", "best_bid": "0.005", "best_ask": "0.011"}], "timestamp": "1769384441515", "event_type": "price_change"}}
{"_local_timestamp": "2026-01-25T23:40:41.584716+00:00", "data": {"market": "0x6bc389514aeed2d49f77818df91931b8f47bca741b922b5aa581bcd285898ecf", "price_changes": [{"asset_id": "16489262565579695131848767429570049041149464887984576468765279262944286152030", "price": "0.533", "size": "10", "side": "BUY", "hash": "62fc5b58450b87e036491310815fc291b7f10eb0", "best_bid": "0.997", "best_ask": "0.999"}, {"asset_id": "62692103489206718495616938107149784138085199695151413614837109358489160284585", "price": "0.467", "size": "10", "side": "SELL", "hash": "2ad9c6d1adf4b2407083e45e36e3870f112ce288", "best_bid": "0.001", "best_ask": "0.003"}], "timestamp": "1769384441515", "event_type": "price_change"}}
{"_local_timestamp": "2026-01-25T23:40:41.586966+00:00", "data": {"market": "0x003478da73863b7555a88a4a240042edbdfa9ce2afbab32f34ec97dbd80c5ab7", "price_changes": [{"asset_id": "15388846204487952420250024653778730612452760958783811368620029058645994602122", "price": "0.309", "size": "323", "side": "BUY", "hash": "80af8f5d545032905d6e167349b636a05aa43f3c", "best_bid": "0.998", "best_ask": "0.999"}, {"asset_id": "19849499173481000650143487020210206007032192502412659368242470292955038260110", "price": "0.691", "size": "323", "side": "SELL", "hash": "85b98f0517edb8198c9f3c45de3326121295ca66", "best_bid": "0.001", "best_ask": "0.002"}], "timestamp": "1769384441516", "event_type": "price_change"}}
{"_local_timestamp": "2026-01-25T23:40:41.589194+00:00", "data": {"market": "0x6bc389514aeed2d49f77818df91931b8f47bca741b922b5aa581bcd285898ecf", "price_changes": [{"asset_id": "16489262565579695131848767429570049041149464887984576468765279262944286152030", "price": "0.533", "size": "25", "side": "BUY", "hash": "b30a971c09ae138430c68154f5666a37fbcaccb8", "best_bid": "0.997", "best_ask": "0.999"}, {"asset_id": "62692103489206718495616938107149784138085199695151413614837109358489160284585", "price": "0.467", "size": "25", "side": "SELL", "hash": "be96aac4384adc5a1fa9db8d6673b5feedf9e507", "best_bid": "0.001", "best_ask": "0.003"}], "timestamp": "1769384441516", "event_type": "price_change"}}
{"_local_timestamp": "2026-01-25T23:40:41.591359+00:00", "data": {"market": "0xbb9ebd08fe1834e60ee5d40b0f5b564478de30519bc8dd6d6d023539a39cd51f", "price_changes": [{"asset_id": "14039941832212049659335286897830341252093775527829576530596212959467785519299", "price": "0.911", "size": "15", "side": "BUY", "hash": "5306a10be7b647d9c73fc9fa92d135af33ff7e52", "best_bid": "0.989", "best_ask": "0.995"}, {"asset_id": "89553061197618390623760390657385664748681901228299157936065698474602382096708", "price": "0.089", "size": "15", "side": "SELL", "hash": "1e4c8f657b9d7e26ef7d80b408f46b6245eb6d62", "best_bid": "0.005", "best_ask": "0.011"}], "timestamp": "1769384441516", "event_type": "price_change"}}
{"_local_timestamp": "2026-01-25T23:40:41.602455+00:00", "data": {"market": "0x003478da73863b7555a88a4a240042edbdfa9ce2afbab32f34ec97dbd80c5ab7", "price_changes": [{"asset_id": "15388846204487952420250024653778730612452760958783811368620029058645994602122", "price": "0.921", "size": "15", "side": "BUY", "hash": "694e8455259cafeeb26b1014a49b2b5642d343fb", "best_bid": "0.998", "best_ask": "0.999"}, {"asset_id": "19849499173481000650143487020210206007032192502412659368242470292955038260110", "price": "0.079", "size": "15", "side": "SELL", "hash": "da521d0e7345dc92054bda74ef1d5d9f48fb8617", "best_bid": "0.001", "best_ask": "0.002"}], "timestamp": "1769384441517", "event_type": "price_change"}}
{"_local_timestamp": "2026-01-25T23:40:41.615963+00:00", "data": {"market": "0x6bc389514aeed2d49f77818df91931b8f47bca741b922b5aa581bcd285898ecf", "price_changes": [{"asset_id": "16489262565579695131848767429570049041149464887984576468765279262944286152030", "price": "0.274", "size": "20", "side": "BUY", "hash": "5e4b4b58f084ee8b452cb6d97bda8badbd27050a", "best_bid": "0.997", "best_ask": "0.999"}, {"asset_id": "62692103489206718495616938107149784138085199695151413614837109358489160284585", "price": "0.726", "size": "20", "side": "SELL", "hash": "0d4b102e13622e9d28abf78b72a8375715c59c18", "best_bid": "0.001", "best_ask": "0.003"}], "timestamp": "1769384441547", "event_type": "price_change"}}
{"_local_timestamp": "2026-01-25T23:40:41.855314+00:00", "data": {"market": "0x9ff5cedb966c4ce0c5f0da7dd827f769ef3d9fb4c662fd1a13dce3cfdb5f6e5e", "price_changes": [{"asset_id": "38503258109330545049739643067830963325321354481872200149686592473366119549035", "price": "0.458", "size": "15", "side": "BUY", "hash": "ef51fb42cb9a62cc557e1d03c50cf96eb8e77607", "best_bid": "0.994", "best_ask": "0.998"}, {"asset_id": "33926193055016677000725490855297544366307667383544420005648237701850394575691", "price": "0.542", "size": "15", "side": "SELL", "hash": "fb0cc9bc57457aed30537b0574c0ac163870e091", "best_bid": "0.002", "best_ask": "0.006"}], "timestamp": "1769384441787", "event_type": "price_change"}}
{"_local_timestamp": "2026-01-25T23:40:41.860390+00:00", "data": {"market": "0x73ad1ccf984fe936e2d38bfe6f9e0479d9780b07290d01495cfc0fe6e889665a", "price_changes": [{"asset_id": "8721859781630956031480953029967309557134082262242417882183208730280192682035", "price": "0.824", "size": "0", "side": "BUY", "hash": "94a6399eca2ebf150593e15735e7048027f7fdc6", "best_bid": "0.998", "best_ask": "0.999"}, {"asset_id": "106144597899636887285661247566617521480303783850130038753142172360623351151116", "price": "0.176", "size": "0", "side": "SELL", "hash": "d4f01bb5b2f4c0d636b59e102a3d1beeff83fd9d", "best_bid": "0.001", "best_ask": "0.002"}], "timestamp": "1769384441787", "event_type": "price_change"}}
{"_local_timestamp": "2026-01-25T23:40:42.174147+00:00", "data": {"market": "0x6bc389514aeed2d49f77818df91931b8f47bca741b922b5aa581bcd285898ecf", "price_changes": [{"asset_id": "16489262565579695131848767429570049041149464887984576468765279262944286152030", "price": "0.274", "size": "0", "side": "BUY", "hash": "b4338627d966588fc70598ac088a7c3ebe018bde", "best_bid": "0.997", "best_ask": "0.999"}, {"asset_id": "62692103489206718495616938107149784138085199695151413614837109358489160284585", "price": "0.726", "size": "0", "side": "SELL", "hash": "b23b7550290dd69111a9f02f2766a8f5b9ba08e9", "best_bid": "0.001", "best_ask": "0.003"}], "timestamp": "1769384442098", "event_type": "price_change"}}
{"_local_timestamp": "2026-01-25T23:40:43.312237+00:00", "data": {"market": "0xbb9ebd08fe1834e60ee5d40b0f5b564478de30519bc8dd6d6d023539a39cd51f", "price_changes": [{"asset_id": "14039941832212049659335286897830341252093775527829576530596212959467785519299", "price": "0.933", "size": "0", "side": "BUY", "hash": "ddafd4e4b48134c541a4ff4453e8c15a913d28b5", "best_bid": "0.989", "best_ask": "0.995"}, {"asset_id": "89553061197618390623760390657385664748681901228299157936065698474602382096708", "price": "0.067", "size": "0", "side": "SELL", "hash": "3d54026695c1f984c89071f55b9b6dbc3008b9af", "best_bid": "0.005", "best_ask": "0.011"}], "timestamp": "1769384443248", "event_type": "price_change"}}
{"_local_timestamp": "2026-01-25T23:40:43.316197+00:00", "data": {"market": "0x003478da73863b7555a88a4a240042edbdfa9ce2afbab32f34ec97dbd80c5ab7", "price_changes": [{"asset_id": "15388846204487952420250024653778730612452760958783811368620029058645994602122", "price": "0.926", "size": "0", "side": "BUY", "hash": "cc0030ab11f987350a85984510fa7de6d27212f2", "best_bid": "0.998", "best_ask": "0.999"}, {"asset_id": "19849499173481000650143487020210206007032192502412659368242470292955038260110", "price": "0.074", "size": "0", "side": "SELL", "hash": "f525f8dd99dd412c16f195910a6b67a82c042ffd", "best_bid": "0.001", "best_ask": "0.002"}], "timestamp": "1769384443248", "event_type": "price_change"}}
{"_local_timestamp": "2026-01-25T23:40:43.318870+00:00", "data": {"market": "0x73ad1ccf984fe936e2d38bfe6f9e0479d9780b07290d01495cfc0fe6e889665a", "price_changes": [{"asset_id": "8721859781630956031480953029967309557134082262242417882183208730280192682035", "price": "0.917", "size": "0", "side": "BUY", "hash": "fd7e3c130616b4da7f01151037966c2ee563a3a7", "best_bid": "0.998", "best_ask": "0.999"}, {"asset_id": "106144597899636887285661247566617521480303783850130038753142172360623351151116", "price": "0.083", "size": "0", "side": "SELL", "hash": "e50218d4de67ce657cf68cd0e9ed3d8542a6f91c", "best_bid": "0.001", "best_ask": "0.002"}], "timestamp": "1769384443248", "event_type": "price_change"}}
{"_local_timestamp": "2026-01-25T23:40:43.321706+00:00", "data": {"market": "0x6bc389514aeed2d49f77818df91931b8f47bca741b922b5aa581bcd285898ecf", "price_changes": [{"asset_id": "16489262565579695131848767429570049041149464887984576468765279262944286152030", "price": "0.532", "size": "0", "side": "BUY", "hash": "da084e9362de0b2613cc96de2c1dddca21ffc8ba", "best_bid": "0.997", "best_ask": "0.999"}, {"asset_id": "62692103489206718495616938107149784138085199695151413614837109358489160284585", "price": "0.468", "size": "0", "side": "SELL", "hash": "11db8dd9d058bc8c1db77f9a194224488332102b", "best_bid": "0.001", "best_ask": "0.003"}], "timestamp": "1769384443248", "event_type": "price_change"}}
{"_local_timestamp": "2026-01-25T23:40:43.325652+00:00", "data": {"market": "0x88298e294408106c07c49520e9bf10c7dc469afe13e834be34d95e82bc36542e", "price_changes": [{"asset_id": "110927174810108466705078650135127005951257798916789146270595008049405408818734", "price": "0.928", "size": "0", "side": "BUY", "hash": "b10a9e7f4a8293dcbefe7b2de20982d8ba0cd281", "best_bid": "0.991", "best_ask": "0.995"}, {"asset_id": "28970242768597401097961438832075151737962074789968575309469772733732578617699", "price": "0.072", "size": "0", "side": "SELL", "hash": "58d37f167e2411a0c192f8fe870f79efcac37852", "best_bid": "0.005", "best_ask": "0.009"}], "timestamp": "1769384443248", "event_type": "price_change"}}
{"_local_timestamp": "2026-01-25T23:40:43.353022+00:00", "data": {"market": "0x73ad1ccf984fe936e2d38bfe6f9e0479d9780b07290d01495cfc0fe6e889665a", "price_changes": [{"asset_id": "8721859781630956031480953029967309557134082262242417882183208730280192682035", "price": "0.919", "size": "20", "side": "BUY", "hash": "14e74c9834d170f51ed62168a2eee074a6f137c9", "best_bid": "0.998", "best_ask": "0.999"}, {"asset_id": "106144597899636887285661247566617521480303783850130038753142172360623351151116", "price": "0.081", "size": "20", "side": "SELL", "hash": "fc89745ae6e552447f314ad4c422cc232b14f30d", "best_bid": "0.001", "best_ask": "0.002"}], "timestamp": "1769384443283", "event_type": "price_change"}}
{"_local_timestamp": "2026-01-25T23:40:43.355987+00:00", "data": {"market": "0x6bc389514aeed2d49f77818df91931b8f47bca741b922b5aa581bcd285898ecf", "price_changes": [{"asset_id": "16489262565579695131848767429570049041149464887984576468765279262944286152030", "price": "0.534", "size": "20", "side": "BUY", "hash": "ae704d842faee1345d98ea8bff78629a3b323c4d", "best_bid": "0.997", "best_ask": "0.999"}, {"asset_id": "62692103489206718495616938107149784138085199695151413614837109358489160284585", "price": "0.466", "size": "20", "side": "SELL", "hash": "b4e24a42c9b7736d8c4781933ea7dcc33a210a21", "best_bid": "0.001", "best_ask": "0.003"}], "timestamp": "1769384443283", "event_type": "price_change"}}
{"_local_timestamp": "2026-01-25T23:40:43.358485+00:00", "data": {"market": "0x003478da73863b7555a88a4a240042edbdfa9ce2afbab32f34ec97dbd80c5ab7", "price_changes": [{"asset_id": "15388846204487952420250024653778730612452760958783811368620029058645994602122", "price": "0.928", "size": "20", "side": "BUY", "hash": "5427f7722eec14a6d057ee096c70722d6b6337c6", "best_bid": "0.998", "best_ask": "0.999"}, {"asset_id": "19849499173481000650143487020210206007032192502412659368242470292955038260110", "price": "0.072", "size": "20", "side": "SELL", "hash": "2abf3855ee8ec123147ac4e9dc0fd401d22a9969", "best_bid": "0.001", "best_ask": "0.002"}], "timestamp": "1769384443283", "event_type": "price_change"}}
{"_local_timestamp": "2026-01-25T23:40:43.360795+00:00", "data": {"market": "0xbb9ebd08fe1834e60ee5d40b0f5b564478de30519bc8dd6d6d023539a39cd51f", "price_changes": [{"asset_id": "14039941832212049659335286897830341252093775527829576530596212959467785519299", "price": "0.931", "size": "20", "side": "BUY", "hash": "d600c993790d1edb4a0e486b9e0fdbea693ad464", "best_bid": "0.989", "best_ask": "0.995"}, {"asset_id": "89553061197618390623760390657385664748681901228299157936065698474602382096708", "price": "0.069", "size": "20", "side": "SELL", "hash": "0f157babe490e381e43e37fea16c11a3897bca9f", "best_bid": "0.005", "best_ask": "0.011"}], "timestamp": "1769384443284", "event_type": "price_change"}}
{"_local_timestamp": "2026-01-25T23:40:43.363021+00:00", "data": {"market": "0x88298e294408106c07c49520e9bf10c7dc469afe13e834be34d95e82bc36542e", "price_changes": [{"asset_id": "110927174810108466705078650135127005951257798916789146270595008049405408818734", "price": "0.93", "size": "20", "side": "BUY", "hash": "e6f3164272c61aa2cd4f9e10318f94a17bf6c27c", "best_bid": "0.991", "best_ask": "0.995"}, {"asset_id": "28970242768597401097961438832075151737962074789968575309469772733732578617699", "price": "0.07", "size": "20", "side": "SELL", "hash": "ce53900ae3eb2ed99d4024f554b6f72b2b8c812a", "best_bid": "0.005", "best_ask": "0.009"}], "timestamp": "1769384443283", "event_type": "price_change"}}
{"_local_timestamp": "2026-01-25T23:40:43.443329+00:00", "data": {"market": "0x9ff5cedb966c4ce0c5f0da7dd827f769ef3d9fb4c662fd1a13dce3cfdb5f6e5e", "price_changes": [{"asset_id": "38503258109330545049739643067830963325321354481872200149686592473366119549035", "price": "0.453", "size": "0", "side": "BUY", "hash": "60e0e1111b9d975fe1b1309cfdd2f205836f6576", "best_bid": "0.994", "best_ask": "0.998"}, {"asset_id": "33926193055016677000725490855297544366307667383544420005648237701850394575691", "price": "0.547", "size": "0", "side": "SELL", "hash": "6d2b21872307d7589fab580a30288d243c45697f", "best_bid": "0.002", "best_ask": "0.006"}], "timestamp": "1769384443294", "event_type": "price_change"}}
{"_local_timestamp": "2026-01-25T23:40:43.445836+00:00", "data": {"market": "0x9ff5cedb966c4ce0c5f0da7dd827f769ef3d9fb4c662fd1a13dce3cfdb5f6e5e", "price_changes": [{"asset_id": "38503258109330545049739643067830963325321354481872200149686592473366119549035", "price": "0.462", "size": "400", "side": "BUY", "hash": "380acbbd6a2c863a02f3bf3f78d978defc191d1c", "best_bid": "0.994", "best_ask": "0.998"}, {"asset_id": "33926193055016677000725490855297544366307667383544420005648237701850394575691", "price": "0.538", "size": "400", "side": "SELL", "hash": "ff9629d2b03aebbe8bbf1879849b22ddd5747a03", "best_bid": "0.002", "best_ask": "0.006"}], "timestamp": "1769384443341", "event_type": "price_change"}}
{"_local_timestamp": "2026-01-25T23:40:43.448120+00:00", "data": {"market": "0x9ff5cedb966c4ce0c5f0da7dd827f769ef3d9fb4c662fd1a13dce3cfdb5f6e5e", "price_changes": [{"asset_id": "38503258109330545049739643067830963325321354481872200149686592473366119549035", "price": "0.462", "size": "410", "side": "BUY", "hash": "d5d9d32249e6e28e12939c6779354be24bfb5909", "best_bid": "0.994", "best_ask": "0.998"}, {"asset_id": "33926193055016677000725490855297544366307667383544420005648237701850394575691", "price": "0.538", "size": "410", "side": "SELL", "hash": "7c433a403911e64e26ee08d6ad72a69ba611890a", "best_bid": "0.002", "best_ask": "0.006"}], "timestamp": "1769384443342", "event_type": "price_change"}}
{"_local_timestamp": "2026-01-25T23:40:43.509874+00:00", "data": {"market": "0x9ff5cedb966c4ce0c5f0da7dd827f769ef3d9fb4c662fd1a13dce3cfdb5f6e5e", "price_changes": [{"asset_id": "38503258109330545049739643067830963325321354481872200149686592473366119549035", "price": "0.454", "size": "400", "side": "BUY", "hash": "de0cf445aacf058905a496b444b66a411c005432", "best_bid": "0.994", "best_ask": "0.998"}, {"asset_id": "33926193055016677000725490855297544366307667383544420005648237701850394575691", "price": "0.546", "size": "400", "side": "SELL", "hash": "b3e245829dc9bc98bca246ca6ee187d2171ebd7c", "best_bid": "0.002", "best_ask": "0.006"}], "timestamp": "1769384443441", "event_type": "price_change"}}
{"_local_timestamp": "2026-01-25T23:40:43.532411+00:00", "data": {"market": "0x9ff5cedb966c4ce0c5f0da7dd827f769ef3d9fb4c662fd1a13dce3cfdb5f6e5e", "price_changes": [{"asset_id": "38503258109330545049739643067830963325321354481872200149686592473366119549035", "price": "0.454", "size": "0", "side": "BUY", "hash": "007e1e1dc723e18eba6026baa85e918d3afda120", "best_bid": "0.994", "best_ask": "0.998"}, {"asset_id": "33926193055016677000725490855297544366307667383544420005648237701850394575691", "price": "0.546", "size": "0", "side": "SELL", "hash": "841c691517c4d9cbd774b0f4a0e62f9fa9290cfb", "best_bid": "0.002", "best_ask": "0.006"}], "timestamp": "1769384443459", "event_type": "price_change"}}
{"_local_timestamp": "2026-01-25T23:40:43.567568+00:00", "data": {"market": "0xd1cb6a36c0eaafd15fbb30e15d210b6ea3ca6b4beacd5506a4e18c0b3c9f0c14", "price_changes": [{"asset_id": "35745608736303685712191378174068870840106833352597804268446172117129985633950", "price": "0.93", "size": "0", "side": "BUY", "hash": "fe3c8dea1ac71e4312f522bf969848567b07aad4", "best_bid": "0.997", "best_ask": "0.999"}, {"asset_id": "95741946556861642865192415995078391397421392763870884030463136567133794215973", "price": "0.07", "size": "0", "side": "SELL", "hash": "fa504601c7a82af132bcb216276e8ebc83786b97", "best_bid": "0.001", "best_ask": "0.003"}], "timestamp": "1769384443489", "event_type": "price_change"}}
{"_local_timestamp": "2026-01-25T23:40:43.599497+00:00", "data": {"market": "0x9ff5cedb966c4ce0c5f0da7dd827f769ef3d9fb4c662fd1a13dce3cfdb5f6e5e", "price_changes": [{"asset_id": "38503258109330545049739643067830963325321354481872200149686592473366119549035", "price": "0.463", "size": "400", "side": "BUY", "hash": "81d01c7417c6e886c580babbdfbb4c737176eca5", "best_bid": "0.994", "best_ask": "0.998"}, {"asset_id": "33926193055016677000725490855297544366307667383544420005648237701850394575691", "price": "0.537", "size": "400", "side": "SELL", "hash": "da403f05fa0ac7900743cd23988105910a054f33", "best_bid": "0.002", "best_ask": "0.006"}], "timestamp": "1769384443495", "event_type": "price_change"}}
{"_local_timestamp": "2026-01-25T23:40:43.614601+00:00", "data": {"market": "0x9ff5cedb966c4ce0c5f0da7dd827f769ef3d9fb4c662fd1a13dce3cfdb5f6e5e", "price_changes": [{"asset_id": "38503258109330545049739643067830963325321354481872200149686592473366119549035", "price": "0.462", "size": "778", "side": "BUY", "hash": "308a33debe66af2a2cd28a1e0448cef4f33df422", "best_bid": "0.994", "best_ask": "0.998"}, {"asset_id": "33926193055016677000725490855297544366307667383544420005648237701850394575691", "price": "0.538", "size": "778", "side": "SELL", "hash": "1316e35ff791dd9b45d731e89f48032c6d3d7954", "best_bid": "0.002", "best_ask": "0.006"}], "timestamp": "1769384443550", "event_type": "price_change"}}
{"_local_timestamp": "2026-01-25T23:40:43.732553+00:00", "data": {"market": "0x9ff5cedb966c4ce0c5f0da7dd827f769ef3d9fb4c662fd1a13dce3cfdb5f6e5e", "price_changes": [{"asset_id": "38503258109330545049739643067830963325321354481872200149686592473366119549035", "price": "0.455", "size": "0", "side": "BUY", "hash": "d3b3ae7ffd10248a743da8112e16d308c08cc544", "best_bid": "0.994", "best_ask": "0.998"}, {"asset_id": "33926193055016677000725490855297544366307667383544420005648237701850394575691", "price": "0.545", "size": "0", "side": "SELL", "hash": "954d578563bcf00b0765f872036c307fb7f991b0", "best_bid": "0.002", "best_ask": "0.006"}], "timestamp": "1769384443658", "event_type": "price_change"}}
{"_local_timestamp": "2026-01-25T23:40:43.885248+00:00", "data": {"market": "0x9ff5cedb966c4ce0c5f0da7dd827f769ef3d9fb4c662fd1a13dce3cfdb5f6e5e", "price_changes": [{"asset_id": "38503258109330545049739643067830963325321354481872200149686592473366119549035", "price": "0.462", "size": "378", "side": "BUY", "hash": "8ba275b23dc634411cf9d3501fe55f2ed62a348a", "best_bid": "0.994", "best_ask": "0.998"}, {"asset_id": "33926193055016677000725490855297544366307667383544420005648237701850394575691", "price": "0.538", "size": "378", "side": "SELL", "hash": "4d73a9b7fb1ae6b384978cb1a6fc875aac5dbd04", "best_bid": "0.002", "best_ask": "0.006"}], "timestamp": "1769384443814", "event_type": "price_change"}}
{"_local_timestamp": "2026-01-25T23:40:44.071942+00:00", "data": {"market": "0xd1cb6a36c0eaafd15fbb30e15d210b6ea3ca6b4beacd5506a4e18c0b3c9f0c14", "price_changes": [{"asset_id": "35745608736303685712191378174068870840106833352597804268446172117129985633950", "price": "0.922", "size": "0", "side": "BUY", "hash": "9ecfe75cbd33dc88984ecca06f08e0a56ca01605", "best_bid": "0.997", "best_ask": "0.999"}, {"asset_id": "95741946556861642865192415995078391397421392763870884030463136567133794215973", "price": "0.078", "size": "0", "side": "SELL", "hash": "ac2313f49b3a59907f04be2b25bb30628876c692", "best_bid": "0.001", "best_ask": "0.003"}], "timestamp": "1769384443999", "event_type": "price_change"}}
{"_local_timestamp": "2026-01-25T23:40:44.146874+00:00", "data": {"market": "0xd1cb6a36c0eaafd15fbb30e15d210b6ea3ca6b4beacd5506a4e18c0b3c9f0c14", "price_changes": [{"asset_id": "35745608736303685712191378174068870840106833352597804268446172117129985633950", "price": "0.932", "size": "10", "side": "BUY", "hash": "c068570f04bda8a8439596ecc04234c218524491", "best_bid": "0.997", "best_ask": "0.999"}, {"asset_id": "95741946556861642865192415995078391397421392763870884030463136567133794215973", "price": "0.068", "size": "10", "side": "SELL", "hash": "3433c599158245cdb79a49e1a04d4fb2d6d79ad5", "best_bid": "0.001", "best_ask": "0.003"}], "timestamp": "1769384444062", "event_type": "price_change"}}
{"_local_timestamp": "2026-01-25T23:40:44.150047+00:00", "data": {"market": "0xd1cb6a36c0eaafd15fbb30e15d210b6ea3ca6b4beacd5506a4e18c0b3c9f0c14", "price_changes": [{"asset_id": "35745608736303685712191378174068870840106833352597804268446172117129985633950", "price": "0.922", "size": "15", "side": "BUY", "hash": "60b4bd8a3758807beeca3f9087584466fd4c124a", "best_bid": "0.997", "best_ask": "0.999"}, {"asset_id": "95741946556861642865192415995078391397421392763870884030463136567133794215973", "price": "0.078", "size": "15", "side": "SELL", "hash": "0bc47c329554dfa331282f89d2535ad5eff93a50", "best_bid": "0.001", "best_ask": "0.003"}], "timestamp": "1769384444062", "event_type": "price_change"}}
{"_local_timestamp": "2026-01-25T23:40:44.322914+00:00", "data": {"market": "0xd1cb6a36c0eaafd15fbb30e15d210b6ea3ca6b4beacd5506a4e18c0b3c9f0c14", "price_changes": [{"asset_id": "35745608736303685712191378174068870840106833352597804268446172117129985633950", "price": "0.931", "size": "0", "side": "BUY", "hash": "f8d10c2c01731838cdbe7a12a298536726a952ec", "best_bid": "0.997", "best_ask": "0.999"}, {"asset_id": "95741946556861642865192415995078391397421392763870884030463136567133794215973", "price": "0.069", "size": "0", "side": "SELL", "hash": "d7573e825c6b05ab0ae2d68d6be529fd5fedbb22", "best_bid": "0.001", "best_ask": "0.003"}], "timestamp": "1769384444256", "event_type": "price_change"}}
{"_local_timestamp": "2026-01-25T23:40:44.326242+00:00", "data": {"market": "0x9ff5cedb966c4ce0c5f0da7dd827f769ef3d9fb4c662fd1a13dce3cfdb5f6e5e", "price_changes": [{"asset_id": "38503258109330545049739643067830963325321354481872200149686592473366119549035", "price": "0.461", "size": "0", "side": "BUY", "hash": "a33d3ae44d965d887552963d6751f369dec77ea0", "best_bid": "0.994", "best_ask": "0.998"}, {"asset_id": "33926193055016677000725490855297544366307667383544420005648237701850394575691", "price": "0.539", "size": "0", "side": "SELL", "hash": "f4fc8aff98df7d67ce02507e7b43d3d62fa1dc7e", "best_bid": "0.002", "best_ask": "0.006"}], "timestamp": "1769384444256", "event_type": "price_change"}}
{"_local_timestamp": "2026-01-25T23:40:44.357364+00:00", "data": {"market": "0x9ff5cedb966c4ce0c5f0da7dd827f769ef3d9fb4c662fd1a13dce3cfdb5f6e5e", "price_changes": [{"asset_id": "38503258109330545049739643067830963325321354481872200149686592473366119549035", "price": "0.464", "size": "20", "side": "BUY", "hash": "a9d2d18e9bfb13c8afd10aa01d50ced07c6b3919", "best_bid": "0.994", "best_ask": "0.998"}, {"asset_id": "33926193055016677000725490855297544366307667383544420005648237701850394575691", "price": "0.536", "size": "20", "side": "SELL", "hash": "cc29a27174c32258d06b6584f96d0747811c7847", "best_bid": "0.002", "best_ask": "0.006"}], "timestamp": "1769384444290", "event_type": "price_change"}}
{"_local_timestamp": "2026-01-25T23:40:44.360681+00:00", "data": {"market": "0xd1cb6a36c0eaafd15fbb30e15d210b6ea3ca6b4beacd5506a4e18c0b3c9f0c14", "price_changes": [{"asset_id": "35745608736303685712191378174068870840106833352597804268446172117129985633950", "price": "0.923", "size": "20", "side": "BUY", "hash": "67d4142e4aadcea878042e158621235c37c1a44e", "best_bid": "0.997", "best_ask": "0.999"}, {"asset_id": "95741946556861642865192415995078391397421392763870884030463136567133794215973", "price": "0.077", "size": "20", "side": "SELL", "hash": "6799918783c0428d677f783550e4f00e30a666bd", "best_bid": "0.001", "best_ask": "0.003"}], "timestamp": "1769384444290", "event_type": "price_change"}}
{"_local_timestamp": "2026-01-25T23:40:47.142837+00:00", "data": {"market": "0xd1cb6a36c0eaafd15fbb30e15d210b6ea3ca6b4beacd5506a4e18c0b3c9f0c14", "price_changes": [{"asset_id": "35745608736303685712191378174068870840106833352597804268446172117129985633950", "price": "0.923", "size": "0", "side": "BUY", "hash": "7a3fc65ea3d7c373f47dca86481e88407c3b7c5b", "best_bid": "0.997", "best_ask": "0.999"}, {"asset_id": "95741946556861642865192415995078391397421392763870884030463136567133794215973", "price": "0.077", "size": "0", "side": "SELL", "hash": "01c8d7f9d82d6741702065349efbb08915ce3890", "best_bid": "0.001", "best_ask": "0.003"}], "timestamp": "1769384447069", "event_type": "price_change"}}
{"_local_timestamp": "2026-01-25T23:40:47.161679+00:00", "data": {"market": "0xd1cb6a36c0eaafd15fbb30e15d210b6ea3ca6b4beacd5506a4e18c0b3c9f0c14", "price_changes": [{"asset_id": "35745608736303685712191378174068870840106833352597804268446172117129985633950", "price": "0.933", "size": "20", "side": "BUY", "hash": "2cdf3211f32a064c75ff14e9c9f5513d224fbae7", "best_bid": "0.997", "best_ask": "0.999"}, {"asset_id": "95741946556861642865192415995078391397421392763870884030463136567133794215973", "price": "0.067", "size": "20", "side": "SELL", "hash": "2b3e708234a356bcedeadcc3ef91ebcfe945eb21", "best_bid": "0.001", "best_ask": "0.003"}], "timestamp": "1769384447098", "event_type": "price_change"}}
{"_local_timestamp": "2026-01-25T23:40:56.139022+00:00", "data": {"market": "0x3590d080b030a479d32cfdc39eb16d5666c70b32326bee61076cfa3372d0e145", "price_changes": [{"asset_id": "105986652731971281617915617408962849670669850444959910165813420329566758424999", "price": "0.73", "size": "0", "side": "BUY", "hash": "9bc29a96fffe99223595880db884f10a5cfb4ad3", "best_bid": "0.991", "best_ask": "0.998"}, {"asset_id": "102717039453623659974177091352103016643954726486882538879796504216481619498182", "price": "0.27", "size": "0", "side": "SELL", "hash": "c8df5c3400923d8bba0392391a2bea7a9c6e5f48", "best_bid": "0.002", "best_ask": "0.009"}], "timestamp": "1769384456041", "event_type": "price_change"}}
{"_local_timestamp": "2026-01-25T23:40:56.325820+00:00", "data": {"market": "0x76c29af7fdae5e892d4e4a07c561d9369f26bcea68c8cf74446b7721f36f45c0", "price_changes": [{"asset_id": "54031257762448920866070382525869450987772451934273228136657254025477075623594", "price": "0.921", "size": "0", "side": "BUY", "hash": "fef821a8cecf5a53f65d5f002d047dd0140e81e6", "best_bid": "0.998", "best_ask": "0.999"}, {"asset_id": "70920736873132577919043852770207478180247569812569419374051281724093244013193", "price": "0.079", "size": "0", "side": "SELL", "hash": "9c44cffed0e4ebd82b4c4439ad20a484729a0ea5", "best_bid": "0.001", "best_ask": "0.002"}], "timestamp": "1769384456254", "event_type": "price_change"}}
{"_local_timestamp": "2026-01-25T23:40:56.432460+00:00", "data": {"market": "0x76c29af7fdae5e892d4e4a07c561d9369f26bcea68c8cf74446b7721f36f45c0", "price_changes": [{"asset_id": "54031257762448920866070382525869450987772451934273228136657254025477075623594", "price": "0.923", "size": "10", "side": "BUY", "hash": "e93ce461fe553bb244559a884b08651a72d090c5", "best_bid": "0.998", "best_ask": "0.999"}, {"asset_id": "70920736873132577919043852770207478180247569812569419374051281724093244013193", "price": "0.077", "size": "10", "side": "SELL", "hash": "084d03170638e6f7f84d1ad4170386c50375a881", "best_bid": "0.001", "best_ask": "0.002"}], "timestamp": "1769384456371", "event_type": "price_change"}}
{"_local_timestamp": "2026-01-25T23:40:56.437698+00:00", "data": {"market": "0x76c29af7fdae5e892d4e4a07c561d9369f26bcea68c8cf74446b7721f36f45c0", "price_changes": [{"asset_id": "54031257762448920866070382525869450987772451934273228136657254025477075623594", "price": "0.824", "size": "38", "side": "BUY", "hash": "c4cc4e8fc3a5d313dba84a117d41caaa01fcda86", "best_bid": "0.998", "best_ask": "0.999"}, {"asset_id": "70920736873132577919043852770207478180247569812569419374051281724093244013193", "price": "0.176", "size": "38", "side": "SELL", "hash": "a847b4fd9f148401657c43a0cc80f598f1ec19ca", "best_bid": "0.001", "best_ask": "0.002"}], "timestamp": "1769384456371", "event_type": "price_change"}}
{"_local_timestamp": "2026-01-25T23:40:56.440107+00:00", "data": {"market": "0x76c29af7fdae5e892d4e4a07c561d9369f26bcea68c8cf74446b7721f36f45c0", "price_changes": [{"asset_id": "54031257762448920866070382525869450987772451934273228136657254025477075623594", "price": "0.923", "size": "25", "side": "BUY", "hash": "0526274ea520f4e19334330f7ebfef05bd7132b9", "best_bid": "0.998", "best_ask": "0.999"}, {"asset_id": "70920736873132577919043852770207478180247569812569419374051281724093244013193", "price": "0.077", "size": "25", "side": "SELL", "hash": "1812994a8458e65677bd6628985957e0ac01fc23", "best_bid": "0.001", "best_ask": "0.002"}], "timestamp": "1769384456373", "event_type": "price_change"}}
{"_local_timestamp": "2026-01-25T23:40:56.471779+00:00", "data": {"market": "0x76c29af7fdae5e892d4e4a07c561d9369f26bcea68c8cf74446b7721f36f45c0", "price_changes": [{"asset_id": "54031257762448920866070382525869450987772451934273228136657254025477075623594", "price": "0.282", "size": "26", "side": "BUY", "hash": "71f37ad86f29b2da72f511e87ec3d1b7d6854e7e", "best_bid": "0.998", "best_ask": "0.999"}, {"asset_id": "70920736873132577919043852770207478180247569812569419374051281724093244013193", "price": "0.718", "size": "26", "side": "SELL", "hash": "7040774a977fd019a117653f2ec61cd75162442c", "best_bid": "0.001", "best_ask": "0.002"}], "timestamp": "1769384456395", "event_type": "price_change"}}
{"_local_timestamp": "2026-01-25T23:40:56.474135+00:00", "data": {"market": "0xa4dad4202b71fcd1387651e9eae72cb138c9b61c4194f93f5e8da4a3d534269c", "price_changes": [{"asset_id": "80457400145229493285131901610968168953953012727977795272540798397863492712492", "price": "0.351", "size": "0", "side": "BUY", "hash": "67fcc5b09028e3892071e7c75b446cf6ccecca17", "best_bid": "0.988", "best_ask": "0.99"}, {"asset_id": "82555109203307099745725321482723908789076391198733120428808326995300770905860", "price": "0.649", "size": "0", "side": "SELL", "hash": "b418ab29b78f1e4d780edf609ab0474cd4848ef7", "best_bid": "0.01", "best_ask": "0.012"}], "timestamp": "1769384456397", "event_type": "price_change"}}
{"_local_timestamp": "2026-01-25T23:40:56.506263+00:00", "data": {"market": "0x9ff5cedb966c4ce0c5f0da7dd827f769ef3d9fb4c662fd1a13dce3cfdb5f6e5e", "price_changes": [{"asset_id": "38503258109330545049739643067830963325321354481872200149686592473366119549035", "price": "0.458", "size": "0", "side": "BUY", "hash": "238b04273a7275a222fb02f0d087984fffec5225", "best_bid": "0.994", "best_ask": "0.998"}, {"asset_id": "33926193055016677000725490855297544366307667383544420005648237701850394575691", "price": "0.542", "size": "0", "side": "SELL", "hash": "566f48704a93271d7f40e52b6f789d5fa68ed05a", "best_bid": "0.002", "best_ask": "0.006"}], "timestamp": "1769384456428", "event_type": "price_change"}}
{"_local_timestamp": "2026-01-25T23:40:56.589540+00:00", "data": {"market": "0x9ff5cedb966c4ce0c5f0da7dd827f769ef3d9fb4c662fd1a13dce3cfdb5f6e5e", "price_changes": [{"asset_id": "38503258109330545049739643067830963325321354481872200149686592473366119549035", "price": "0.465", "size": "10", "side": "BUY", "hash": "0621e5457820b206cc08d2f370b48a1872cda5bb", "best_bid": "0.994", "best_ask": "0.998"}, {"asset_id": "33926193055016677000725490855297544366307667383544420005648237701850394575691", "price": "0.535", "size": "10", "side": "SELL", "hash": "3e00e800892201d4c6407412ad96a6d6ce3593bb", "best_bid": "0.002", "best_ask": "0.006"}], "timestamp": "1769384456521", "event_type": "price_change"}}
{"_local_timestamp": "2026-01-25T23:40:56.594169+00:00", "data": {"market": "0x9ff5cedb966c4ce0c5f0da7dd827f769ef3d9fb4c662fd1a13dce3cfdb5f6e5e", "price_changes": [{"asset_id": "38503258109330545049739643067830963325321354481872200149686592473366119549035", "price": "0.464", "size": "235", "side": "BUY", "hash": "d0ad2b36756921676681ad6b8d13b569dcc0780f", "best_bid": "0.994", "best_ask": "0.998"}, {"asset_id": "33926193055016677000725490855297544366307667383544420005648237701850394575691", "price": "0.536", "size": "235", "side": "SELL", "hash": "614c74faaa2423c14a5b82eed7d1b0a5bff2345e", "best_bid": "0.002", "best_ask": "0.006"}], "timestamp": "1769384456522", "event_type": "price_change"}}
{"_local_timestamp": "2026-01-25T23:40:56.599590+00:00", "data": {"market": "0x9ff5cedb966c4ce0c5f0da7dd827f769ef3d9fb4c662fd1a13dce3cfdb5f6e5e", "price_changes": [{"asset_id": "38503258109330545049739643067830963325321354481872200149686592473366119549035", "price": "0.465", "size": "25", "side": "BUY", "hash": "678624986324a864612b2d49f4770826dc382221", "best_bid": "0.994", "best_ask": "0.998"}, {"asset_id": "33926193055016677000725490855297544366307667383544420005648237701850394575691", "price": "0.535", "size": "25", "side": "SELL", "hash": "a2d0c5674feaecbac5c397e5abf846c05f75e8f3", "best_bid": "0.002", "best_ask": "0.006"}], "timestamp": "1769384456523", "event_type": "price_change"}}
{"_local_timestamp": "2026-01-25T23:40:56.625622+00:00", "data": {"market": "0xa4dad4202b71fcd1387651e9eae72cb138c9b61c4194f93f5e8da4a3d534269c", "price_changes": [{"asset_id": "80457400145229493285131901610968168953953012727977795272540798397863492712492", "price": "0.353", "size": "10", "side": "BUY", "hash": "9b406be8e32da1c71384c3e217262d181b00feb6", "best_bid": "0.988", "best_ask": "0.99"}, {"asset_id": "82555109203307099745725321482723908789076391198733120428808326995300770905860", "price": "0.647", "size": "10", "side": "SELL", "hash": "224093d2a3884a1b6b5d7098303eefc8af8fc272", "best_bid": "0.01", "best_ask": "0.012"}], "timestamp": "1769384456557", "event_type": "price_change"}}
{"_local_timestamp": "2026-01-25T23:40:56.651312+00:00", "data": {"market": "0x76c29af7fdae5e892d4e4a07c561d9369f26bcea68c8cf74446b7721f36f45c0", "price_changes": [{"asset_id": "54031257762448920866070382525869450987772451934273228136657254025477075623594", "price": "0.283", "size": "0", "side": "BUY", "hash": "2ccf09666bcec9d2fd16dd832a3e3c3bbdac5969", "best_bid": "0.998", "best_ask": "0.999"}, {"asset_id": "70920736873132577919043852770207478180247569812569419374051281724093244013193", "price": "0.717", "size": "0", "side": "SELL", "hash": "8da4dee0766f650e6f287620d7c7981f73fb2f1f", "best_bid": "0.001", "best_ask": "0.002"}], "timestamp": "1769384456584", "event_type": "price_change"}}
{"_local_timestamp": "2026-01-25T23:40:56.777411+00:00", "data": {"market": "0x9ff5cedb966c4ce0c5f0da7dd827f769ef3d9fb4c662fd1a13dce3cfdb5f6e5e", "price_changes": [{"asset_id": "38503258109330545049739643067830963325321354481872200149686592473366119549035", "price": "0.462", "size": "10", "side": "BUY", "hash": "235473c5e1dbd58ced63123261064359f91e1fea", "best_bid": "0.994", "best_ask": "0.998"}, {"asset_id": "33926193055016677000725490855297544366307667383544420005648237701850394575691", "price": "0.538", "size": "10", "side": "SELL", "hash": "d4619e3db871adb34db35dd8cea985bdcbb9a56e", "best_bid": "0.002", "best_ask": "0.006"}], "timestamp": "1769384456707", "event_type": "price_change"}}
{"_local_timestamp": "2026-01-25T23:40:56.933299+00:00", "data": {"market": "0x9ff5cedb966c4ce0c5f0da7dd827f769ef3d9fb4c662fd1a13dce3cfdb5f6e5e", "price_changes": [{"asset_id": "38503258109330545049739643067830963325321354481872200149686592473366119549035", "price": "0.463", "size": "601", "side": "BUY", "hash": "05556029c2c8107a9af8a7783fb3afe260cf10a0", "best_bid": "0.994", "best_ask": "0.998"}, {"asset_id": "33926193055016677000725490855297544366307667383544420005648237701850394575691", "price": "0.537", "size": "601", "side": "SELL", "hash": "352adcc2d60b0fec75088dbbb6ab1f994f378d13", "best_bid": "0.002", "best_ask": "0.006"}], "timestamp": "1769384456869", "event_type": "price_change"}}
{"_local_timestamp": "2026-01-25T23:40:56.964916+00:00", "data": {"market": "0x76c29af7fdae5e892d4e4a07c561d9369f26bcea68c8cf74446b7721f36f45c0", "price_changes": [{"asset_id": "54031257762448920866070382525869450987772451934273228136657254025477075623594", "price": "0.282", "size": "0", "side": "BUY", "hash": "1b1b23cbfdecc35f62ce5e0202e11ba4d880be44", "best_bid": "0.998", "best_ask": "0.999"}, {"asset_id": "70920736873132577919043852770207478180247569812569419374051281724093244013193", "price": "0.718", "size": "0", "side": "SELL", "hash": "63544b70c3d78d7acaa5708be5575bb0cab7a619", "best_bid": "0.001", "best_ask": "0.002"}], "timestamp": "1769384456896", "event_type": "price_change"}}
{"_local_timestamp": "2026-01-25T23:40:57.033912+00:00", "data": {"market": "0x76c29af7fdae5e892d4e4a07c561d9369f26bcea68c8cf74446b7721f36f45c0", "price_changes": [{"asset_id": "54031257762448920866070382525869450987772451934273228136657254025477075623594", "price": "0.824", "size": "10", "side": "BUY", "hash": "f5a71220f887df302aaa49781637f30d9e2e53be", "best_bid": "0.998", "best_ask": "0.999"}, {"asset_id": "70920736873132577919043852770207478180247569812569419374051281724093244013193", "price": "0.176", "size": "10", "side": "SELL", "hash": "737f2eb69a47aacc4713f390259824b17977e300", "best_bid": "0.001", "best_ask": "0.002"}], "timestamp": "1769384456932", "event_type": "price_change"}}
{"_local_timestamp": "2026-01-25T23:40:57.138763+00:00", "data": {"market": "0x76c29af7fdae5e892d4e4a07c561d9369f26bcea68c8cf74446b7721f36f45c0", "price_changes": [{"asset_id": "54031257762448920866070382525869450987772451934273228136657254025477075623594", "price": "0.282", "size": "30", "side": "BUY", "hash": "75bf72da7746e6e1fb30e5d142eae6e2673c3e60", "best_bid": "0.998", "best_ask": "0.999"}, {"asset_id": "70920736873132577919043852770207478180247569812569419374051281724093244013193", "price": "0.718", "size": "30", "side": "SELL", "hash": "8d369ad69aa2b1e178e16a340debd20e9288c5ad", "best_bid": "0.001", "best_ask": "0.002"}], "timestamp": "1769384457008", "event_type": "price_change"}}
{"_local_timestamp": "2026-01-25T23:40:57.147690+00:00", "data": {"market": "0x76c29af7fdae5e892d4e4a07c561d9369f26bcea68c8cf74446b7721f36f45c0", "price_changes": [{"asset_id": "54031257762448920866070382525869450987772451934273228136657254025477075623594", "price": "0.282", "size": "59", "side": "BUY", "hash": "c7b8a8b6aad73bf853ab3191be6cc2bdd006ab42", "best_bid": "0.998", "best_ask": "0.999"}, {"asset_id": "70920736873132577919043852770207478180247569812569419374051281724093244013193", "price": "0.718", "size": "59", "side": "SELL", "hash": "71e63d23ccd1b60169e83fc0e206aa310f2dbfe2", "best_bid": "0.001", "best_ask": "0.002"}], "timestamp": "1769384457044", "event_type": "price_change"}}
{"_local_timestamp": "2026-01-25T23:40:58.634812+00:00", "data": {"market": "0x9ff5cedb966c4ce0c5f0da7dd827f769ef3d9fb4c662fd1a13dce3cfdb5f6e5e", "price_changes": [{"asset_id": "38503258109330545049739643067830963325321354481872200149686592473366119549035", "price": "0.464", "size": "215", "side": "BUY", "hash": "cb7967abbaeea0216c2f381c1846c1003101563f", "best_bid": "0.994", "best_ask": "0.998"}, {"asset_id": "33926193055016677000725490855297544366307667383544420005648237701850394575691", "price": "0.536", "size": "215", "side": "SELL", "hash": "0e351fe404da7595932815af9483b698ddb41c3f", "best_bid": "0.002", "best_ask": "0.006"}], "timestamp": "1769384458050", "event_type": "price_change"}}
{"_local_timestamp": "2026-01-25T23:40:58.636954+00:00", "data": {"market": "0x76c29af7fdae5e892d4e4a07c561d9369f26bcea68c8cf74446b7721f36f45c0", "price_changes": [{"asset_id": "54031257762448920866070382525869450987772451934273228136657254025477075623594", "price": "0.922", "size": "0", "side": "BUY", "hash": "f9cdbc95c0fc28bd101126a2d5bcf939e2536a23", "best_bid": "0.998", "best_ask": "0.999"}, {"asset_id": "70920736873132577919043852770207478180247569812569419374051281724093244013193", "price": "0.078", "size": "0", "side": "SELL", "hash": "d8bde942447cb4d12f2ce088ff9a8755c976d717", "best_bid": "0.001", "best_ask": "0.002"}], "timestamp": "1769384458050", "event_type": "price_change"}}
{"_local_timestamp": "2026-01-25T23:40:58.639204+00:00", "data": {"market": "0x9ff5cedb966c4ce0c5f0da7dd827f769ef3d9fb4c662fd1a13dce3cfdb5f6e5e", "price_changes": [{"asset_id": "38503258109330545049739643067830963325321354481872200149686592473366119549035", "price": "0.466", "size": "20", "side": "BUY", "hash": "c75d20fe8e2875d6cd4fd71c537809996d346676", "best_bid": "0.994", "best_ask": "0.998"}, {"asset_id": "33926193055016677000725490855297544366307667383544420005648237701850394575691", "price": "0.534", "size": "20", "side": "SELL", "hash": "c2124d6701ed210f09cc5a5b9b189862e26cb982", "best_bid": "0.002", "best_ask": "0.006"}], "timestamp": "1769384458097", "event_type": "price_change"}}
{"_local_timestamp": "2026-01-25T23:40:58.641349+00:00", "data": {"market": "0x76c29af7fdae5e892d4e4a07c561d9369f26bcea68c8cf74446b7721f36f45c0", "price_changes": [{"asset_id": "54031257762448920866070382525869450987772451934273228136657254025477075623594", "price": "0.924", "size": "20", "side": "BUY", "hash": "facdb8f6a2f7de363e9675a88b962171ee2749a2", "best_bid": "0.998", "best_ask": "0.999"}, {"asset_id": "70920736873132577919043852770207478180247569812569419374051281724093244013193", "price": "0.076", "size": "20", "side": "SELL", "hash": "ca456bc176e9ef54534282cdc393c523e83bdb5e", "best_bid": "0.001", "best_ask": "0.002"}], "timestamp": "1769384458097", "event_type": "price_change"}}
{"_local_timestamp": "2026-01-25T23:41:02.043360+00:00", "data": {"market": "0xc07928d93d2e9ae459edba5b537bcdcb4f59abcdca19ee1d4dc88c7474cfd5e0", "price_changes": [{"asset_id": "15596315259806586303408002371753656561550066663906359186784326959810935330986", "price": "0.539", "size": "0", "side": "BUY", "hash": "c5e87bed03911b522261aed0be0d521b6be27a4c", "best_bid": "0.998", "best_ask": "0.999"}, {"asset_id": "102789355367893125922194040490556243357965914304236215712028923179316736754233", "price": "0.461", "size": "0", "side": "SELL", "hash": "2667d0ab847a1eb461f169180b0b76564c86f99d", "best_bid": "0.001", "best_ask": "0.002"}], "timestamp": "1769384461964", "event_type": "price_change"}}
{"_local_timestamp": "2026-01-25T23:41:02.112242+00:00", "data": {"market": "0xc07928d93d2e9ae459edba5b537bcdcb4f59abcdca19ee1d4dc88c7474cfd5e0", "price_changes": [{"asset_id": "15596315259806586303408002371753656561550066663906359186784326959810935330986", "price": "0.524", "size": "5", "side": "BUY", "hash": "5e073868ae09f54cd94d7327756383c2313c26a7", "best_bid": "0.998", "best_ask": "0.999"}, {"asset_id": "102789355367893125922194040490556243357965914304236215712028923179316736754233", "price": "0.476", "size": "5", "side": "SELL", "hash": "89e6ce224c2576531a7750bf37aaa8292dee07f6", "best_bid": "0.001", "best_ask": "0.002"}], "timestamp": "1769384462013", "event_type": "price_change"}}
{"_local_timestamp": "2026-01-25T23:41:02.116359+00:00", "data": {"market": "0x949c9ec867ff713ee52ab749498e761b737139dbcf3cee2fce4fb97fcddc8332", "price_changes": [{"asset_id": "14388290902643650435293090680587869555316527818926326372933718414371708858517", "price": "0.924", "size": "15", "side": "BUY", "hash": "476fabc4a732285d2b30f743cab057a40fb4393f", "best_bid": "0.998", "best_ask": "0.999"}, {"asset_id": "57579576028532911954666940251041611742032623764462509111730085124509956613210", "price": "0.076", "size": "15", "side": "SELL", "hash": "cbe4e28a79efb9668a8a7e9ba526c8b6f6fb1a65", "best_bid": "0.001", "best_ask": "0.002"}], "timestamp": "1769384462037", "event_type": "price_change"}}
{"_local_timestamp": "2026-01-25T23:41:02.243028+00:00", "data": {"market": "0x0c473519a0fd7d7dc49f4dde9420e439a96a279147262d94d94440c7bb0c3d1a", "price_changes": [{"asset_id": "33850995040817642028610750949028268753079036233754982280349900373513025092341", "price": "0.842", "size": "0", "side": "BUY", "hash": "ee6b80779869b1b7e119c074783512b023b09ee5", "best_bid": "0.998", "best_ask": "0.999"}, {"asset_id": "75542494425322153297720389520749706755259470813001035748631847230682534703546", "price": "0.158", "size": "0", "side": "SELL", "hash": "a5a83f50d4827e91afdc770f643941638cb018b3", "best_bid": "0.001", "best_ask": "0.002"}], "timestamp": "1769384462181", "event_type": "price_change"}}
{"_local_timestamp": "2026-01-25T23:41:02.275128+00:00", "data": {"market": "0x09ac5925691713ff142bab96413fd34ad1113bd18bb0a090d8284fd6ccb27d8f", "price_changes": [{"asset_id": "95861053919171993512697190106673713355541727588409736217989846113692847198678", "price": "0.856", "size": "15", "side": "BUY", "hash": "653fea0b2257bf9b41e4a60bd8b885b0dfe9bca5", "best_bid": "0.998", "best_ask": "0.999"}, {"asset_id": "79706026068944835262224079232154067921292858426362398176248100716599909254344", "price": "0.144", "size": "15", "side": "SELL", "hash": "222901fc6b9aa27e575eab6b49fb232ae1419f34", "best_bid": "0.001", "best_ask": "0.002"}], "timestamp": "1769384462204", "event_type": "price_change"}}
{"_local_timestamp": "2026-01-25T23:41:02.338031+00:00", "data": {"market": "0x0c473519a0fd7d7dc49f4dde9420e439a96a279147262d94d94440c7bb0c3d1a", "price_changes": [{"asset_id": "33850995040817642028610750949028268753079036233754982280349900373513025092341", "price": "0.844", "size": "10", "side": "BUY", "hash": "844fe198774e5dc7e8a746e289b01281a49de0c6", "best_bid": "0.998", "best_ask": "0.999"}, {"asset_id": "75542494425322153297720389520749706755259470813001035748631847230682534703546", "price": "0.156", "size": "10", "side": "SELL", "hash": "e3c2ba0e51500227a9dec66db1bc55addf4dd92d", "best_bid": "0.001", "best_ask": "0.002"}], "timestamp": "1769384462264", "event_type": "price_change"}}
{"_local_timestamp": "2026-01-25T23:41:05.182125+00:00", "data": {"market": "0x0c473519a0fd7d7dc49f4dde9420e439a96a279147262d94d94440c7bb0c3d1a", "price_changes": [{"asset_id": "33850995040817642028610750949028268753079036233754982280349900373513025092341", "price": "0.843", "size": "0", "side": "BUY", "hash": "a38e787e2ef78a437f1cd3b72002d957649cab31", "best_bid": "0.998", "best_ask": "0.999"}, {"asset_id": "75542494425322153297720389520749706755259470813001035748631847230682534703546", "price": "0.157", "size": "0", "side": "SELL", "hash": "ef72fa57f446bbc97d56e25c33d9c104b6c093d1", "best_bid": "0.001", "best_ask": "0.002"}], "timestamp": "1769384465108", "event_type": "price_change"}}
{"_local_timestamp": "2026-01-25T23:41:05.208568+00:00", "data": {"market": "0x0c473519a0fd7d7dc49f4dde9420e439a96a279147262d94d94440c7bb0c3d1a", "price_changes": [{"asset_id": "33850995040817642028610750949028268753079036233754982280349900373513025092341", "price": "0.845", "size": "20", "side": "BUY", "hash": "32733af2cd59501b93a671fa207e517325b836b7", "best_bid": "0.998", "best_ask": "0.999"}, {"asset_id": "75542494425322153297720389520749706755259470813001035748631847230682534703546", "price": "0.155", "size": "20", "side": "SELL", "hash": "4b6197240fe5cf630c3471a55c6d85f411b739bf", "best_bid": "0.001", "best_ask": "0.002"}], "timestamp": "1769384465137", "event_type": "price_change"}}
{"_local_timestamp": "2026-01-25T23:41:17.850170+00:00", "data": {"market": "0x1786c149f32f75fa909fbfab4f7b273975b6da5b76ad6d43200f927a1690f1e8", "price_changes": [{"asset_id": "69860370569560842073228065523569617122621124551318423120774348883993531485193", "price": "0.13", "size": "400", "side": "BUY", "hash": "cb988e43dfdfbbb9b76e59a6032f9c799ac82858", "best_bid": "0.92", "best_ask": "0.94"}, {"asset_id": "25541691838497877440175161707261211792942265656882782730327118132070277416890", "price": "0.87", "size": "400", "side": "SELL", "hash": "fcd8ef6aca467058855fbf5fa3f56d8d28bb4cd4", "best_bid": "0.06", "best_ask": "0.08"}], "timestamp": "1769384477707", "event_type": "price_change"}}
{"_local_timestamp": "2026-01-25T23:41:18.144796+00:00", "data": {"market": "0x438bd0f5ff930f040bc63ed2dc0585f93ef5cbd871b50efe502d703bba96654d", "price_changes": [{"asset_id": "8739167718638980235687942123866249649168680031256814828170525657956217651887", "price": "0.055", "size": "0", "side": "BUY", "hash": "c75e120db5a51bcf0ae2926faa22b18f0d3fe155", "best_bid": "0.995", "best_ask": "0.996"}, {"asset_id": "53925808913836840946371550342430470487372041989648351858443846988581594567500", "price": "0.945", "size": "0", "side": "SELL", "hash": "0b778cfe2c2887a2890c0f6d8ac3b7ef3c44df28", "best_bid": "0.004", "best_ask": "0.005"}], "timestamp": "1769384478013", "event_type": "price_change"}}
{"_local_timestamp": "2026-01-25T23:41:18.149241+00:00", "data": {"market": "0xaad7429c6e56ba07ab9642b66edd365ba97442042e010cc8fce27d59a08f2da5", "price_changes": [{"asset_id": "46443102387865875618199309137574651890271593500189004156516763187381128187486", "price": "0.202", "size": "0", "side": "BUY", "hash": "60d72b6f64007c8e5d66a82301e3731d48c5ac7c", "best_bid": "0.998", "best_ask": "0.999"}, {"asset_id": "70435272270000303444232595121425292735616760933087659375750995553393761504892", "price": "0.798", "size": "0", "side": "SELL", "hash": "9d03fda15be0a1c6fc23961075f4da4628e217dc", "best_bid": "0.001", "best_ask": "0.002"}], "timestamp": "1769384478014", "event_type": "price_change"}}
{"_local_timestamp": "2026-01-25T23:41:18.383675+00:00", "data": {"market": "0xaad7429c6e56ba07ab9642b66edd365ba97442042e010cc8fce27d59a08f2da5", "price_changes": [{"asset_id": "46443102387865875618199309137574651890271593500189004156516763187381128187486", "price": "0.342", "size": "10", "side": "BUY", "hash": "83983d54b092a125686a508cdfcf293d31001062", "best_bid": "0.998", "best_ask": "0.999"}, {"asset_id": "70435272270000303444232595121425292735616760933087659375750995553393761504892", "price": "0.658", "size": "10", "side": "SELL", "hash": "3533d331a10380fa9aced574c014fe2e130716ab", "best_bid": "0.001", "best_ask": "0.002"}], "timestamp": "1769384478225", "event_type": "price_change"}}
{"_local_timestamp": "2026-01-25T23:41:18.750612+00:00", "data": {"market": "0x3590d080b030a479d32cfdc39eb16d5666c70b32326bee61076cfa3372d0e145", "price_changes": [{"asset_id": "105986652731971281617915617408962849670669850444959910165813420329566758424999", "price": "0.69", "size": "700", "side": "BUY", "hash": "e92c6405cee605c542cbc91bec4395bf1bffa57d", "best_bid": "0.991", "best_ask": "0.998"}, {"asset_id": "102717039453623659974177091352103016643954726486882538879796504216481619498182", "price": "0.31", "size": "700", "side": "SELL", "hash": "f1fff357b3e705d306afac5f001e9243c75934ad", "best_bid": "0.002", "best_ask": "0.009"}], "timestamp": "1769384478642", "event_type": "price_change"}}
{"_local_timestamp": "2026-01-25T23:41:18.755384+00:00", "data": {"market": "0x3590d080b030a479d32cfdc39eb16d5666c70b32326bee61076cfa3372d0e145", "price_changes": [{"asset_id": "105986652731971281617915617408962849670669850444959910165813420329566758424999", "price": "0.34", "size": "3100", "side": "BUY", "hash": "ad147fc012746d4ea60d75b0e27dca24fdfe87e2", "best_bid": "0.991", "best_ask": "0.998"}, {"asset_id": "102717039453623659974177091352103016643954726486882538879796504216481619498182", "price": "0.66", "size": "3100", "side": "SELL", "hash": "026f9204445c640a829fb9b11373284ef8382a35", "best_bid": "0.002", "best_ask": "0.009"}], "timestamp": "1769384478644", "event_type": "price_change"}}
{"_local_timestamp": "2026-01-25T23:41:20.863967+00:00", "data": {"market": "0xbb9ebd08fe1834e60ee5d40b0f5b564478de30519bc8dd6d6d023539a39cd51f", "price_changes": [{"asset_id": "14039941832212049659335286897830341252093775527829576530596212959467785519299", "price": "0.22", "size": "3000", "side": "BUY", "hash": "1b87fa361636521281e368e4ea3cf259d541ab48", "best_bid": "0.989", "best_ask": "0.995"}, {"asset_id": "89553061197618390623760390657385664748681901228299157936065698474602382096708", "price": "0.78", "size": "3000", "side": "SELL", "hash": "259148d254edf618d30db2d5e56587a54d7535c6", "best_bid": "0.005", "best_ask": "0.011"}], "timestamp": "1769384480735", "event_type": "price_change"}}
{"_local_timestamp": "2026-01-25T23:41:21.008003+00:00", "data": {"market": "0x091010f5fa0aed8218a8f2ef38ca6f75a04b86207e9d9a3464c76acedae5ff71", "price_changes": [{"asset_id": "18543401226963683485470982595403517845090555185510389603436997425977517302982", "price": "0.454", "size": "0", "side": "BUY", "hash": "be4c09d837cc1da17b8e44c1058605c6bb4a8799", "best_bid": "0.998", "best_ask": "0.999"}, {"asset_id": "30914129377008299105825712463210268035742945099105633197958126446720250780230", "price": "0.546", "size": "0", "side": "SELL", "hash": "be538dda0f0abe8b15cb37f8f0ee1074918bff5e", "best_bid": "0.001", "best_ask": "0.002"}], "timestamp": "1769384480890", "event_type": "price_change"}}
{"_local_timestamp": "2026-01-25T23:41:21.011377+00:00", "data": {"market": "0x9ff5cedb966c4ce0c5f0da7dd827f769ef3d9fb4c662fd1a13dce3cfdb5f6e5e", "price_changes": [{"asset_id": "38503258109330545049739643067830963325321354481872200149686592473366119549035", "price": "0.456", "size": "0", "side": "BUY", "hash": "e0f7d6f0d8f4223b15f63394c479beb721509475", "best_bid": "0.994", "best_ask": "0.998"}, {"asset_id": "33926193055016677000725490855297544366307667383544420005648237701850394575691", "price": "0.544", "size": "0", "side": "SELL", "hash": "de9aae77ccea28d01281a3dc6745d3040a27a78e", "best_bid": "0.002", "best_ask": "0.006"}], "timestamp": "1769384480890", "event_type": "price_change"}}
{"_local_timestamp": "2026-01-25T23:41:21.165540+00:00", "data": {"market": "0x9ff5cedb966c4ce0c5f0da7dd827f769ef3d9fb4c662fd1a13dce3cfdb5f6e5e", "price_changes": [{"asset_id": "38503258109330545049739643067830963325321354481872200149686592473366119549035", "price": "0.467", "size": "25", "side": "BUY", "hash": "88d43b1c356fac4cc601994a5ee457393c8875f2", "best_bid": "0.994", "best_ask": "0.998"}, {"asset_id": "33926193055016677000725490855297544366307667383544420005648237701850394575691", "price": "0.533", "size": "25", "side": "SELL", "hash": "2ba5c960108cd145f1bf24e9b2235ce4ce100385", "best_bid": "0.002", "best_ask": "0.006"}], "timestamp": "1769384481021", "event_type": "price_change"}}
{"_local_timestamp": "2026-01-25T23:41:21.196625+00:00", "data": {"market": "0x091010f5fa0aed8218a8f2ef38ca6f75a04b86207e9d9a3464c76acedae5ff71", "price_changes": [{"asset_id": "18543401226963683485470982595403517845090555185510389603436997425977517302982", "price": "0.462", "size": "25", "side": "BUY", "hash": "e2b4bb28d71add279acaeae5f39dafb89a60d614", "best_bid": "0.998", "best_ask": "0.999"}, {"asset_id": "30914129377008299105825712463210268035742945099105633197958126446720250780230", "price": "0.538", "size": "25", "side": "SELL", "hash": "4aad3d416cbca44ccd369a0e6e802ae68b283718", "best_bid": "0.001", "best_ask": "0.002"}], "timestamp": "1769384481021", "event_type": "price_change"}}
{"_local_timestamp": "2026-01-25T23:41:22.172726+00:00", "data": {"market": "0x1786c149f32f75fa909fbfab4f7b273975b6da5b76ad6d43200f927a1690f1e8", "price_changes": [{"asset_id": "69860370569560842073228065523569617122621124551318423120774348883993531485193", "price": "0.81", "size": "700", "side": "BUY", "hash": "f16cc206cae104aac49c527877f7100b3269d277", "best_bid": "0.92", "best_ask": "0.94"}, {"asset_id": "25541691838497877440175161707261211792942265656882782730327118132070277416890", "price": "0.19", "size": "700", "side": "SELL", "hash": "3970033576cd0e34ef66379bd6c3b6f36e0811de", "best_bid": "0.06", "best_ask": "0.08"}], "timestamp": "1769384482015", "event_type": "price_change"}}
{"_local_timestamp": "2026-01-25T23:41:22.214570+00:00", "data": {"market": "0x949c9ec867ff713ee52ab749498e761b737139dbcf3cee2fce4fb97fcddc8332", "price_changes": [{"asset_id": "14388290902643650435293090680587869555316527818926326372933718414371708858517", "price": "0.924", "size": "0", "side": "BUY", "hash": "02f984c10b919f5cbbf90038b03b909ca14b9218", "best_bid": "0.998", "best_ask": "0.999"}, {"asset_id": "57579576028532911954666940251041611742032623764462509111730085124509956613210", "price": "0.076", "size": "0", "side": "SELL", "hash": "9d59f80fe04ccf28900eacd3343acae5d3aef73a", "best_bid": "0.001", "best_ask": "0.002"}], "timestamp": "1769384482113", "event_type": "price_change"}}
{"_local_timestamp": "2026-01-25T23:41:22.312509+00:00", "data": {"market": "0xd1cb6a36c0eaafd15fbb30e15d210b6ea3ca6b4beacd5506a4e18c0b3c9f0c14", "price_changes": [{"asset_id": "35745608736303685712191378174068870840106833352597804268446172117129985633950", "price": "0.301", "size": "398", "side": "BUY", "hash": "273a4297dff026ed4093be40f0c71e5f93275858", "best_bid": "0.997", "best_ask": "0.999"}, {"asset_id": "95741946556861642865192415995078391397421392763870884030463136567133794215973", "price": "0.699", "size": "398", "side": "SELL", "hash": "d5efa4eeb8fdb4d4312526e88bf1b7df6119ce1b", "best_bid": "0.001", "best_ask": "0.003"}], "timestamp": "1769384482189", "event_type": "price_change"}}
{"_local_timestamp": "2026-01-25T23:41:22.341051+00:00", "data": {"market": "0x091010f5fa0aed8218a8f2ef38ca6f75a04b86207e9d9a3464c76acedae5ff71", "price_changes": [{"asset_id": "18543401226963683485470982595403517845090555185510389603436997425977517302982", "price": "0.461", "size": "0", "side": "BUY", "hash": "005090c71124e8c1bf85c8bd0d2c9601cf0593ef", "best_bid": "0.998", "best_ask": "0.999"}, {"asset_id": "30914129377008299105825712463210268035742945099105633197958126446720250780230", "price": "0.539", "size": "0", "side": "SELL", "hash": "5bf7f0d933b5417a0776540f6f09dbff131e8f26", "best_bid": "0.001", "best_ask": "0.002"}], "timestamp": "1769384482222", "event_type": "price_change"}}
{"_local_timestamp": "2026-01-25T23:41:22.352051+00:00", "data": {"market": "0x9ff5cedb966c4ce0c5f0da7dd827f769ef3d9fb4c662fd1a13dce3cfdb5f6e5e", "price_changes": [{"asset_id": "38503258109330545049739643067830963325321354481872200149686592473366119549035", "price": "0.466", "size": "0", "side": "BUY", "hash": "70967cea257c73faaa5a55b512315e3d59ac8a0e", "best_bid": "0.994", "best_ask": "0.998"}, {"asset_id": "33926193055016677000725490855297544366307667383544420005648237701850394575691", "price": "0.534", "size": "0", "side": "SELL", "hash": "355364a773196a6aa88bc234892979499926a428", "best_bid": "0.002", "best_ask": "0.006"}], "timestamp": "1769384482222", "event_type": "price_change"}}
{"_local_timestamp": "2026-01-25T23:41:22.354420+00:00", "data": {"market": "0xc07928d93d2e9ae459edba5b537bcdcb4f59abcdca19ee1d4dc88c7474cfd5e0", "price_changes": [{"asset_id": "15596315259806586303408002371753656561550066663906359186784326959810935330986", "price": "0.342", "size": "400", "side": "BUY", "hash": "163ec5305eb70337dcba11d09a94497189bcd873", "best_bid": "0.998", "best_ask": "0.999"}, {"asset_id": "102789355367893125922194040490556243357965914304236215712028923179316736754233", "price": "0.658", "size": "400", "side": "SELL", "hash": "9c2554f46e63cb4a0a5aa1bc68654f0f86dbccf5", "best_bid": "0.001", "best_ask": "0.002"}], "timestamp": "1769384482225", "event_type": "price_change"}}
{"_local_timestamp": "2026-01-25T23:41:22.357002+00:00", "data": {"market": "0x6bc389514aeed2d49f77818df91931b8f47bca741b922b5aa581bcd285898ecf", "price_changes": [{"asset_id": "16489262565579695131848767429570049041149464887984576468765279262944286152030", "price": "0.274", "size": "400", "side": "BUY", "hash": "47baeb2e0a9bda2d02b1a3cf8cfd3884090d8d14", "best_bid": "0.997", "best_ask": "0.999"}, {"asset_id": "62692103489206718495616938107149784138085199695151413614837109358489160284585", "price": "0.726", "size": "400", "side": "SELL", "hash": "22810cdd4befad4f18f1af6cf6764c1fbed23c34", "best_bid": "0.001", "best_ask": "0.003"}], "timestamp": "1769384482225", "event_type": "price_change"}}
{"_local_timestamp": "2026-01-25T23:41:22.361611+00:00", "data": {"market": "0x73ad1ccf984fe936e2d38bfe6f9e0479d9780b07290d01495cfc0fe6e889665a", "price_changes": [{"asset_id": "8721859781630956031480953029967309557134082262242417882183208730280192682035", "price": "0.523", "size": "438", "side": "BUY", "hash": "e0a618c1b48f09a19fd80e5a6ccee4266a6dc6cb", "best_bid": "0.998", "best_ask": "0.999"}, {"asset_id": "106144597899636887285661247566617521480303783850130038753142172360623351151116", "price": "0.477", "size": "438", "side": "SELL", "hash": "434f18e504ea5016cae8bcb6e767da5cecf6da35", "best_bid": "0.001", "best_ask": "0.002"}], "timestamp": "1769384482225", "event_type": "price_change"}}
{"_local_timestamp": "2026-01-25T23:41:22.364137+00:00", "data": {"market": "0xd1cb6a36c0eaafd15fbb30e15d210b6ea3ca6b4beacd5506a4e18c0b3c9f0c14", "price_changes": [{"asset_id": "35745608736303685712191378174068870840106833352597804268446172117129985633950", "price": "0.301", "size": "798", "side": "BUY", "hash": "1b9cb124dc4a8eb8cad0e2cbc96de30dda6fa679", "best_bid": "0.997", "best_ask": "0.999"}, {"asset_id": "95741946556861642865192415995078391397421392763870884030463136567133794215973", "price": "0.699", "size": "798", "side": "SELL", "hash": "d03627b01d23eb91fa6439a0267b8c5a4e069d1a", "best_bid": "0.001", "best_ask": "0.003"}], "timestamp": "1769384482225", "event_type": "price_change"}}
{"_local_timestamp": "2026-01-25T23:41:22.366402+00:00", "data": {"market": "0x091010f5fa0aed8218a8f2ef38ca6f75a04b86207e9d9a3464c76acedae5ff71", "price_changes": [{"asset_id": "18543401226963683485470982595403517845090555185510389603436997425977517302982", "price": "0.463", "size": "20", "side": "BUY", "hash": "ff78d7cfb4f3d125cbe0a77de8bfc99e2b9b0669", "best_bid": "0.998", "best_ask": "0.999"}, {"asset_id": "30914129377008299105825712463210268035742945099105633197958126446720250780230", "price": "0.537", "size": "20", "side": "SELL", "hash": "c1069ad5a96a5b7a19ff2db3170ff4787662fe82", "best_bid": "0.001", "best_ask": "0.002"}], "timestamp": "1769384482252", "event_type": "price_change"}}
{"_local_timestamp": "2026-01-25T23:41:22.370749+00:00", "data": {"market": "0x9ff5cedb966c4ce0c5f0da7dd827f769ef3d9fb4c662fd1a13dce3cfdb5f6e5e", "price_changes": [{"asset_id": "38503258109330545049739643067830963325321354481872200149686592473366119549035", "price": "0.468", "size": "20", "side": "BUY", "hash": "cb3d316c1df1602f16951bf1b5030701507d056c", "best_bid": "0.994", "best_ask": "0.998"}, {"asset_id": "33926193055016677000725490855297544366307667383544420005648237701850394575691", "price": "0.532", "size": "20", "side": "SELL", "hash": "b3df8b401ba3d8a7ca2ac0d563905e69e57e96ee", "best_bid": "0.002", "best_ask": "0.006"}], "timestamp": "1769384482252", "event_type": "price_change"}}
{"_local_timestamp": "2026-01-25T23:41:22.373411+00:00", "data": {"market": "0x438bd0f5ff930f040bc63ed2dc0585f93ef5cbd871b50efe502d703bba96654d", "price_changes": [{"asset_id": "8739167718638980235687942123866249649168680031256814828170525657956217651887", "price": "0.093", "size": "10", "side": "BUY", "hash": "f7d29313bc5db588523b8695f055be67edbc039b", "best_bid": "0.995", "best_ask": "0.996"}, {"asset_id": "53925808913836840946371550342430470487372041989648351858443846988581594567500", "price": "0.907", "size": "10", "side": "SELL", "hash": "49d63fb877edf3ccf3aa0a48b28521c196102d84", "best_bid": "0.004", "best_ask": "0.005"}], "timestamp": "1769384482254", "event_type": "price_change"}}
{"_local_timestamp": "2026-01-25T23:41:22.385136+00:00", "data": {"market": "0x88298e294408106c07c49520e9bf10c7dc469afe13e834be34d95e82bc36542e", "price_changes": [{"asset_id": "110927174810108466705078650135127005951257798916789146270595008049405408818734", "price": "0.524", "size": "0", "side": "BUY", "hash": "98c3e97397d48c0c653432d894e8c0e2abdf7e7a", "best_bid": "0.991", "best_ask": "0.995"}, {"asset_id": "28970242768597401097961438832075151737962074789968575309469772733732578617699", "price": "0.476", "size": "0", "side": "SELL", "hash": "c96a0714242fad3e7e601e4afdf56a4b8807ee9d", "best_bid": "0.005", "best_ask": "0.009"}], "timestamp": "1769384482281", "event_type": "price_change"}}
{"_local_timestamp": "2026-01-25T23:41:22.387490+00:00", "data": {"market": "0xbb9ebd08fe1834e60ee5d40b0f5b564478de30519bc8dd6d6d023539a39cd51f", "price_changes": [{"asset_id": "14039941832212049659335286897830341252093775527829576530596212959467785519299", "price": "0.342", "size": "0", "side": "BUY", "hash": "819728e51bd1483a1e105fa26cb57b229572eebb", "best_bid": "0.989", "best_ask": "0.995"}, {"asset_id": "89553061197618390623760390657385664748681901228299157936065698474602382096708", "price": "0.658", "size": "0", "side": "SELL", "hash": "b0cf4ab357cd3e1e9f04fba46ea569c971318a3c", "best_bid": "0.005", "best_ask": "0.011"}], "timestamp": "1769384482281", "event_type": "price_change"}}
{"_local_timestamp": "2026-01-25T23:41:22.457897+00:00", "data": {"market": "0x73ad1ccf984fe936e2d38bfe6f9e0479d9780b07290d01495cfc0fe6e889665a", "price_changes": [{"asset_id": "8721859781630956031480953029967309557134082262242417882183208730280192682035", "price": "0.825", "size": "0", "side": "BUY", "hash": "609ad82a47bc81242b27997ac11690280a52194b", "best_bid": "0.998", "best_ask": "0.999"}, {"asset_id": "106144597899636887285661247566617521480303783850130038753142172360623351151116", "price": "0.175", "size": "0", "side": "SELL", "hash": "fac28952ec28f499dd62680153aaf80e86b7b1c7", "best_bid": "0.001", "best_ask": "0.002"}], "timestamp": "1769384482281", "event_type": "price_change"}}
{"_local_timestamp": "2026-01-25T23:41:22.461458+00:00", "data": {"market": "0x7bc0c2a607e267892269961a911a0b666f29594433a7d95c0dd56babdc29f308", "price_changes": [{"asset_id": "105586204831827806415544690970027356427067426133583910562372754475220137027200", "price": "0.053", "size": "0", "side": "BUY", "hash": "68064c92ea629bb4bb0df375f406c486919ec94e", "best_bid": "0.993", "best_ask": "0.997"}, {"asset_id": "13373402356576882724938800858000537994853003539200086787602846320764306199642", "price": "0.947", "size": "0", "side": "SELL", "hash": "66817c3085af507bb15ed4ae2f4e6f6bbc190dc9", "best_bid": "0.003", "best_ask": "0.007"}], "timestamp": "1769384482281", "event_type": "price_change"}}
{"_local_timestamp": "2026-01-25T23:41:22.465821+00:00", "data": {"market": "0xe8aa6e2e78b148ade04614fb635df30b6e7101bb356ae0d049e8f17fad3df4f7", "price_changes": [{"asset_id": "82381608296304959049355559600146889289834297440752377216630323877678083558940", "price": "0.823", "size": "422", "side": "BUY", "hash": "026dbca30e8928d2f794d5348cb321630f9d0839", "best_bid": "0.998", "best_ask": "0.999"}, {"asset_id": "7415398757579829371388746916782351900338601049827707938782174312340133977353", "price": "0.177", "size": "422", "side": "SELL", "hash": "ae5bf41e91cf59d7b0309feac5be9640e1c2daf7", "best_bid": "0.001", "best_ask": "0.002"}], "timestamp": "1769384482347", "event_type": "price_change"}}
{"_local_timestamp": "2026-01-25T23:41:22.469845+00:00", "data": {"market": "0x73ad1ccf984fe936e2d38bfe6f9e0479d9780b07290d01495cfc0fe6e889665a", "price_changes": [{"asset_id": "8721859781630956031480953029967309557134082262242417882183208730280192682035", "price": "0.523", "size": "667", "side": "BUY", "hash": "5c186d92eb9cb6dfe143960501afbc8a0bff484f", "best_bid": "0.998", "best_ask": "0.999"}, {"asset_id": "106144597899636887285661247566617521480303783850130038753142172360623351151116", "price": "0.477", "size": "667", "side": "SELL", "hash": "2449a948b057aaddf6518ec5cfa3dae2b7195f00", "best_bid": "0.001", "best_ask": "0.002"}], "timestamp": "1769384482347", "event_type": "price_change"}}
{"_local_timestamp": "2026-01-25T23:41:22.502393+00:00", "data": {"market": "0x6bc389514aeed2d49f77818df91931b8f47bca741b922b5aa581bcd285898ecf", "price_changes": [{"asset_id": "16489262565579695131848767429570049041149464887984576468765279262944286152030", "price": "0.274", "size": "869", "side": "BUY", "hash": "1cac540cf2f408659c9349fe8a76fba8209f47db", "best_bid": "0.997", "best_ask": "0.999"}, {"asset_id": "62692103489206718495616938107149784138085199695151413614837109358489160284585", "price": "0.726", "size": "869", "side": "SELL", "hash": "1e700dcb3f68007db721c05eea86175e5d0a975e", "best_bid": "0.001", "best_ask": "0.003"}], "timestamp": "1769384482347", "event_type": "price_change"}}
{"_local_timestamp": "2026-01-25T23:41:22.505716+00:00", "data": {"market": "0xa4dad4202b71fcd1387651e9eae72cb138c9b61c4194f93f5e8da4a3d534269c", "price_changes": [{"asset_id": "80457400145229493285131901610968168953953012727977795272540798397863492712492", "price": "0.7", "size": "40", "side": "BUY", "hash": "b5bb742d0747708e44fb4df1fca28d41d928aca0", "best_bid": "0.988", "best_ask": "0.99"}, {"asset_id": "82555109203307099745725321482723908789076391198733120428808326995300770905860", "price": "0.3", "size": "40", "side": "SELL", "hash": "074f2e524ef04ac14696a684bb77434b27e51be5", "best_bid": "0.01", "best_ask": "0.012"}], "timestamp": "1769384482347", "event_type": "price_change"}}
{"_local_timestamp": "2026-01-25T23:41:22.509330+00:00", "data": {"market": "0xc07928d93d2e9ae459edba5b537bcdcb4f59abcdca19ee1d4dc88c7474cfd5e0", "price_changes": [{"asset_id": "15596315259806586303408002371753656561550066663906359186784326959810935330986", "price": "0.342", "size": "807", "side": "BUY", "hash": "ea28ca43cc14585cfa431761c3d3b6aaa97331bb", "best_bid": "0.998", "best_ask": "0.999"}, {"asset_id": "102789355367893125922194040490556243357965914304236215712028923179316736754233", "price": "0.658", "size": "807", "side": "SELL", "hash": "b3517e5ce2c5f7f5b6dd1465df75d3f5103d2c39", "best_bid": "0.001", "best_ask": "0.002"}], "timestamp": "1769384482347", "event_type": "price_change"}}
{"_local_timestamp": "2026-01-25T23:41:22.517625+00:00", "data": {"market": "0x88298e294408106c07c49520e9bf10c7dc469afe13e834be34d95e82bc36542e", "price_changes": [{"asset_id": "110927174810108466705078650135127005951257798916789146270595008049405408818734", "price": "0.524", "size": "10", "side": "BUY", "hash": "8a13978ef7b4e0d26fbceabaa327ee137a5031bd", "best_bid": "0.991", "best_ask": "0.995"}, {"asset_id": "28970242768597401097961438832075151737962074789968575309469772733732578617699", "price": "0.476", "size": "10", "side": "SELL", "hash": "b2c459f46236497e92b0198a22585bc6ee9ba629", "best_bid": "0.005", "best_ask": "0.009"}], "timestamp": "1769384482400", "event_type": "price_change"}}
{"_local_timestamp": "2026-01-25T23:41:22.521875+00:00", "data": {"market": "0x7bc0c2a607e267892269961a911a0b666f29594433a7d95c0dd56babdc29f308", "price_changes": [{"asset_id": "105586204831827806415544690970027356427067426133583910562372754475220137027200", "price": "0.501", "size": "10", "side": "BUY", "hash": "01867970bec95eb53f20a026747d857fcaca87e3", "best_bid": "0.993", "best_ask": "0.997"}, {"asset_id": "13373402356576882724938800858000537994853003539200086787602846320764306199642", "price": "0.499", "size": "10", "side": "SELL", "hash": "9b8c8b865c452f02b0a8962edca576595d4a1eaf", "best_bid": "0.003", "best_ask": "0.007"}], "timestamp": "1769384482400", "event_type": "price_change"}}
{"_local_timestamp": "2026-01-25T23:41:22.526021+00:00", "data": {"market": "0x73ad1ccf984fe936e2d38bfe6f9e0479d9780b07290d01495cfc0fe6e889665a", "price_changes": [{"asset_id": "8721859781630956031480953029967309557134082262242417882183208730280192682035", "price": "0.827", "size": "10", "side": "BUY", "hash": "894f29596974ff6fb6592e6647e555f8fca35216", "best_bid": "0.998", "best_ask": "0.999"}, {"asset_id": "106144597899636887285661247566617521480303783850130038753142172360623351151116", "price": "0.173", "size": "10", "side": "SELL", "hash": "85e22c53642429a96e4688d66c2fb45f981b0cb9", "best_bid": "0.001", "best_ask": "0.002"}], "timestamp": "1769384482400", "event_type": "price_change"}}
{"_local_timestamp": "2026-01-25T23:41:22.529114+00:00", "data": {"market": "0xbb9ebd08fe1834e60ee5d40b0f5b564478de30519bc8dd6d6d023539a39cd51f", "price_changes": [{"asset_id": "14039941832212049659335286897830341252093775527829576530596212959467785519299", "price": "0.342", "size": "10", "side": "BUY", "hash": "63a1737e8c68e666468395de11bf2acda20b9ad0", "best_bid": "0.989", "best_ask": "0.995"}, {"asset_id": "89553061197618390623760390657385664748681901228299157936065698474602382096708", "price": "0.658", "size": "10", "side": "SELL", "hash": "6b46c6d54309083867fa27d5d6793a6877693ec3", "best_bid": "0.005", "best_ask": "0.011"}], "timestamp": "1769384482400", "event_type": "price_change"}}
{"_local_timestamp": "2026-01-25T23:41:22.595792+00:00", "data": {"market": "0x09ac5925691713ff142bab96413fd34ad1113bd18bb0a090d8284fd6ccb27d8f", "price_changes": [{"asset_id": "95861053919171993512697190106673713355541727588409736217989846113692847198678", "price": "0.856", "size": "0", "side": "BUY", "hash": "1eeb2317c1a94bc586013c8a12d567bf7699887c", "best_bid": "0.998", "best_ask": "0.999"}, {"asset_id": "79706026068944835262224079232154067921292858426362398176248100716599909254344", "price": "0.144", "size": "0", "side": "SELL", "hash": "ea6dccbc8cb64a8a973cb9a4ead2702c6b37b5d5", "best_bid": "0.001", "best_ask": "0.002"}], "timestamp": "1769384482453", "event_type": "price_change"}}
{"_local_timestamp": "2026-01-25T23:41:22.853027+00:00", "data": {"market": "0x09ac5925691713ff142bab96413fd34ad1113bd18bb0a090d8284fd6ccb27d8f", "price_changes": [{"asset_id": "95861053919171993512697190106673713355541727588409736217989846113692847198678", "price": "0.858", "size": "10", "side": "BUY", "hash": "f92e27191776fef10bc7b59da583990979604538", "best_bid": "0.998", "best_ask": "0.999"}, {"asset_id": "79706026068944835262224079232154067921292858426362398176248100716599909254344", "price": "0.142", "size": "10", "side": "SELL", "hash": "5811a7dee6ca14a8c64f981c4c9ff7d321c88330", "best_bid": "0.001", "best_ask": "0.002"}], "timestamp": "1769384482737", "event_type": "price_change"}}
{"_local_timestamp": "2026-01-25T23:41:22.889076+00:00", "data": {"market": "0x09ac5925691713ff142bab96413fd34ad1113bd18bb0a090d8284fd6ccb27d8f", "price_changes": [{"asset_id": "95861053919171993512697190106673713355541727588409736217989846113692847198678", "price": "0.341", "size": "298", "side": "BUY", "hash": "8a06f722a9a32c8cdb67b3aa7e04532718131f54", "best_bid": "0.998", "best_ask": "0.999"}, {"asset_id": "79706026068944835262224079232154067921292858426362398176248100716599909254344", "price": "0.659", "size": "298", "side": "SELL", "hash": "c20734a61e7ee856f02253b809f7b35a9cb2f643", "best_bid": "0.001", "best_ask": "0.002"}], "timestamp": "1769384482738", "event_type": "price_change"}}
{"_local_timestamp": "2026-01-25T23:41:22.894745+00:00", "data": {"market": "0x09ac5925691713ff142bab96413fd34ad1113bd18bb0a090d8284fd6ccb27d8f", "price_changes": [{"asset_id": "95861053919171993512697190106673713355541727588409736217989846113692847198678", "price": "0.858", "size": "25", "side": "BUY", "hash": "fbf78fd1a6744ccba88f8846e14822fe6fbc9996", "best_bid": "0.998", "best_ask": "0.999"}, {"asset_id": "79706026068944835262224079232154067921292858426362398176248100716599909254344", "price": "0.142", "size": "25", "side": "SELL", "hash": "28c5b83c6f424f88e7e0acbbbc2235261bd209a1", "best_bid": "0.001", "best_ask": "0.002"}], "timestamp": "1769384482739", "event_type": "price_change"}}
{"_local_timestamp": "2026-01-25T23:41:23.088439+00:00", "data": {"market": "0x1786c149f32f75fa909fbfab4f7b273975b6da5b76ad6d43200f927a1690f1e8", "price_changes": [{"asset_id": "69860370569560842073228065523569617122621124551318423120774348883993531485193", "price": "0.81", "size": "0", "side": "BUY", "hash": "050567b0c4e58029d672b533dbf9deb95d5c24f6", "best_bid": "0.92", "best_ask": "0.94"}, {"asset_id": "25541691838497877440175161707261211792942265656882782730327118132070277416890", "price": "0.19", "size": "0", "side": "SELL", "hash": "b773f0cc90a311ff814a66222df83978fc017e3b", "best_bid": "0.06", "best_ask": "0.08"}], "timestamp": "1769384482969", "event_type": "price_change"}}
{"_local_timestamp": "2026-01-25T23:41:23.094929+00:00", "data": {"market": "0x1786c149f32f75fa909fbfab4f7b273975b6da5b76ad6d43200f927a1690f1e8", "price_changes": [{"asset_id": "69860370569560842073228065523569617122621124551318423120774348883993531485193", "price": "0.86", "size": "0", "side": "BUY", "hash": "050567b0c4e58029d672b533dbf9deb95d5c24f6", "best_bid": "0.92", "best_ask": "0.94"}, {"asset_id": "25541691838497877440175161707261211792942265656882782730327118132070277416890", "price": "0.14", "size": "0", "side": "SELL", "hash": "b773f0cc90a311ff814a66222df83978fc017e3b", "best_bid": "0.06", "best_ask": "0.08"}], "timestamp": "1769384482969", "event_type": "price_change"}}
