{"_local_timestamp": "2026-01-25T23:41:06.085454+00:00", "data": {"market": "0x1dde34de4ceb798933f85826a2879ff5676853144ea79f4c1ca89d4f8546ce73", "price_changes": [{"asset_id": "2989772230015894045729002380739794506754998903816202205758003265088876154235", "price": "0.5", "size": "440", "side": "BUY", "hash": "aa08a580bd961eda3b3932e42480629e0e63a28b", "best_bid": "0.999", "best_ask": "1"}, {"asset_id": "72299768080662854793831035989036195853606657997616618081658086993981448595143", "price": "0.5", "size": "440", "side": "SELL", "hash": "d59911fa24bf2d64dc7446be8eb70e8f3b1371f8", "best_bid": "0", "best_ask": "0.001"}], "timestamp": "1769384466000", "event_type": "price_change"}}
{"_local_timestamp": "2026-01-25T23:41:06.085743+00:00", "data": {"market": "0x453f8479a041419e8f794d9f7149e4d95a3d315effa5d754fa0e303c83257140", "price_changes": [{"asset_id": "39365936570984542827431489666856672933613556292100829681088739787833575189466", "price": "0.501", "size": "0", "side": "BUY", "hash": "65da5fd4c142d6017551f91debf2082bb0d99351", "best_bid": "0.996", "best_ask": "1"}, {"asset_id": "19192699567236935154412948133755984775559628536019255388694943247637117213140", "price": "0.499", "size": "0", "side": "SELL", "hash": "c98ef132dcdc1e4354b62fb58b915b338fd475e5", "best_bid": "0", "best_ask": "0.004"}], "timestamp": "1769384466000", "event_type": "price_change"}}
{"_local_timestamp": "2026-01-25T23:41:06.088229+00:00", "data": {"market": "0x4748aea08c7479f93888e3c88574cc22f470db27586dddc3c389443aec89ff59", "price_changes": [{"asset_id": "66589182701894097810798527186415708633655827134259434616730323536170342159606", "price": "0.011", "size": "0", "side": "BUY", "hash": "5f58db2dac7a0ba9bfb0d4db3b8aedd3865f1b43", "best_bid": "0.99", "best_ask": "0.999"}, {"asset_id": "83504158413192513722048719030445378881634624891122351294833041377392549555836", "price": "0.989", "size": "0", "side": "SELL", "hash": "a0dc3d623e31258a9748eccc6b2dcb5a62687063", "best_bid": "0.001", "best_ask": "0.01"}], "timestamp": "1769384466000", "event_type": "price_change"}}
{"_local_timestamp": "2026-01-25T23:41:06.219098+00:00", "data": {"market": "0xd9b0fc72f38c908a5a7141420c06da580d01ed86c2ec38705ea15f72cb5e5e19", "price_changes": [{"asset_id": "51572238815890626847563912025595017507148782163592329862076559798897854761860", "price": "0.011", "size": "0", "side": "BUY", "hash": "35688b4dd8b572fefcdcccd8dfadc6a7f0d72a3f", "best_bid": "0.999", "best_ask": "1"}, {"asset_id": "57098020481919035618128472838337976081009168137472950524968489896877203309629", "price": "0.989", "size": "0", "side": "SELL", "hash": "74e941ccbaba100273d324b1d73479bc0f833823", "best_bid": "0", "best_ask": "0.001"}], "timestamp": "1769384466000", "event_type": "price_change"}}
{"_local_timestamp": "2026-01-25T23:41:06.219535+00:00", "data": {"market": "0x462bb7daa3b0906569beaf26fe722dd2b742cdaaca0900c3aa710a9e8e418f15", "price_changes": [{"asset_id": "84426700624131057289025898608787752028694418359354475239466346481861071213446", "price": "0.32", "size": "0", "side": "BUY", "hash": "ee82233fca2a12d6ea827cc2c1959374d6a335ab", "best_bid": "0.49", "best_ask": "0.51"}, {"asset_id": "109631748687541424858485727517534723373639840024430532350488906491941213609965", "price": "0.68", "size": "0", "side": "SELL", "hash": "0f6459172896f06c6cf4e740585a261e4552d0a6", "best_bid": "0.49", "best_ask": "0.51"}], "timestamp": "1769384466000", "event_type": "price_change"}}
{"_local_timestamp": "2026-01-25T23:41:06.219832+00:00", "data": {"market": "0x41701e7ba16d4af257e01e112cff807143ef2d2ecb90cc481f11652e055d4c59", "price_changes": [{"asset_id": "10466278887690510175905331848661528762143716832637414322344895027265950979694", "price": "0.5", "size": "440", "side": "BUY", "hash": "34531587b53c4a0865258b287822b1996b8cc161", "best_bid": "0.999", "best_ask": "1"}, {"asset_id": "25335907832274451055949522033815474513838672679545890866843065752499213006185", "price": "0.5", "size": "440", "side": "SELL", "hash": "dbb178b6fc6508a8ca83971e42d3c1589af21bf4", "best_bid": "0", "best_ask": "0.001"}], "timestamp": "1769384466000", "event_type": "price_change"}}
{"_local_timestamp": "2026-01-25T23:41:06.220118+00:00", "data": {"market": "0x5a3fd19d87709f84b93d3a71af7adaeca3f99cdfa2e1ba4a3ad256a6ddfb481b", "price_changes": [{"asset_id": "58248314633586529362367123493139013590568973389535271143944925899040736147880", "price": "0.011", "size": "0", "side": "BUY", "hash": "59c1caee28719874e61394682bc135a644e5d7e0", "best_bid": "0.999", "best_ask": "1"}, {"asset_id": "65953037871248164391818099564886117125781149283903860674544296582421226617357", "price": "0.989", "size": "0", "side": "SELL", "hash": "16904dc58a4b09e41158a880ce4a2db004e6d859", "best_bid": "0", "best_ask": "0.001"}], "timestamp": "1769384466000", "event_type": "price_change"}}
{"_local_timestamp": "2026-01-25T23:41:06.220389+00:00", "data": {"market": "0xb396be1c57cb41ca2248f91ebde81d87102b4cdcfa4aa6908abb2e1ad4d71be6", "price_changes": [{"asset_id": "34419698228673649128953341658515616138601812429723644373431200193643709482989", "price": "0.5", "size": "440", "side": "BUY", "hash": "0ad483423871be01ffa22e80061c7be15030cc45", "best_bid": "0.999", "best_ask": "1"}, {"asset_id": "62435228944209279352438951651853891000763690834442926701361268157078928214358", "price": "0.5", "size": "440", "side": "SELL", "hash": "85f4ef5635ae2ceb77affef966c82048da658bf9", "best_bid": "0", "best_ask": "0.001"}], "timestamp": "1769384466000", "event_type": "price_change"}}
{"_local_timestamp": "2026-01-25T23:41:06.220684+00:00", "data": {"market": "0xfb0f4ac0b68e94aedc1214a03cbe9c723feebf9d3a55777fe2b05b8feb66a11c", "price_changes": [{"asset_id": "55426209889638974733753071618642569441373076860672244339538811630049825345670", "price": "0.01", "size": "1000", "side": "BUY", "hash": "87e6be1245b0aedab3401de52a75dc43f9a66d22", "best_bid": "0.99", "best_ask": "0.999"}, {"asset_id": "43959289417856840840427763184407307972480869140742194070396563955715812876628", "price": "0.99", "size": "1000", "side": "SELL", "hash": "94ab7b85b39415ae6e9bf2e5994a9726a1a43b44", "best_bid": "0.001", "best_ask": "0.01"}], "timestamp": "1769384466000", "event_type": "price_change"}}
{"_local_timestamp": "2026-01-25T23:41:06.220974+00:00", "data": {"market": "0x1b130b268df56e4802707e2ec9b5c2929b51222d2d0a19af03516e2b960de26a", "price_changes": [{"asset_id": "77018818557373862304084960921215808370283364442421773897574584607622496684030", "price": "0.5", "size": "440", "side": "BUY", "hash": "958499819c0cd5b8cc35b9f9ccd8906bef2f55e4", "best_bid": "0.999", "best_ask": "1"}, {"asset_id": "72797979972272034635860920395196865314139391915868888486424461493808639864972", "price": "0.5", "size": "440", "side": "SELL", "hash": "227b8c3b8de2b38a0a0279d48278273d4f127558", "best_bid": "0", "best_ask": "0.001"}], "timestamp": "1769384466000", "event_type": "price_change"}}
{"_local_timestamp": "2026-01-25T23:41:06.221250+00:00", "data": {"market": "0xc0d7f7796a0cac90cb70c79845db9d226ed35959bd0aa35af7fb418f3f2e22e5", "price_changes": [{"asset_id": "12543330728269567640220567011294079896273543850192586290021550850906815833169", "price": "0.501", "size": "0", "side": "BUY", "hash": "0f607ef74a7461a62c34d4351c2c16595dfbfe97", "best_bid": "0.999", "best_ask": "1"}, {"asset_id": "10008028422703392249749236854165253701939526137534166171302431408077717628002", "price": "0.499", "size": "0", "side": "SELL", "hash": "47fe81a0f0e20f4ee896faa93f91a09e0444da5f", "best_bid": "0", "best_ask": "0.001"}], "timestamp": "1769384466000", "event_type": "price_change"}}
{"_local_timestamp": "2026-01-25T23:41:06.221534+00:00", "data": {"market": "0x462bb7daa3b0906569beaf26fe722dd2b742cdaaca0900c3aa710a9e8e418f15", "price_changes": [{"asset_id": "109631748687541424858485727517534723373639840024430532350488906491941213609965", "price": "0.32", "size": "0", "side": "BUY", "hash": "d2fb60446ca947e406a4806f3abf98bf34c53cb8", "best_bid": "0.49", "best_ask": "0.51"}, {"asset_id": "84426700624131057289025898608787752028694418359354475239466346481861071213446", "price": "0.68", "size": "0", "side": "SELL", "hash": "0a3a38c34ace094b73fdea705462462601152743", "best_bid": "0.49", "best_ask": "0.51"}], "timestamp": "1769384466000", "event_type": "price_change"}}
{"_local_timestamp": "2026-01-25T23:41:06.221813+00:00", "data": {"market": "0x204b14f24297c06aaa199dc1d8844bd1becc80bc07f6fca3c5b60e7578c9c201", "price_changes": [{"asset_id": "102355609737505986959456016204459786144451240240244825770982312180145369373256", "price": "0.501", "size": "0", "side": "BUY", "hash": "66982f47fa324835d7470b104c1c87e68e1ac4c9", "best_bid": "0.999", "best_ask": "1"}, {"asset_id": "58553512085555920981275268565214845438113167009368856656814609879942308608483", "price": "0.499", "size": "0", "side": "SELL", "hash": "8ce70361de06b0796cacc896f7c99566d16b940e", "best_bid": "0", "best_ask": "0.001"}], "timestamp": "1769384466000", "event_type": "price_change"}}
{"_local_timestamp": "2026-01-25T23:41:06.222109+00:00", "data": {"market": "0xbcdc50ca134fca43e2ff92b1d4eb74d1370ee70226edaff6ed2e66eded7c4f17", "price_changes": [{"asset_id": "5574857600587711269700129730512235249359616543972163182547512086378810357379", "price": "0.011", "size": "0", "side": "BUY", "hash": "68e1d977ec8aec218c7ae6016060174a673eb700", "best_bid": "0.999", "best_ask": "1"}, {"asset_id": "34715175763796870678361611735891885650420703648689314817663953704466610666238", "price": "0.989", "size": "0", "side": "SELL", "hash": "46602c038b5d49d78bac2de3a0454f558979e995", "best_bid": "0", "best_ask": "0.001"}], "timestamp": "1769384466001", "event_type": "price_change"}}
{"_local_timestamp": "2026-01-25T23:41:06.222399+00:00", "data": {"market": "0xf6d24c742a3126a68c6b83264660beb058a1f82652c951d599af6bdfb7b391d4", "price_changes": [{"asset_id": "97482207647464260874772172680967961758321108174204964420696779227628091002379", "price": "0.013", "size": "8692", "side": "BUY", "hash": "89a9ae01fd22fa1f248a93d080b66c77808dd18e", "best_bid": "0.996", "best_ask": "1"}, {"asset_id": "113918115236977645637180997599109290964068777945588716077455921908247080428977", "price": "0.987", "size": "8692", "side": "SELL", "hash": "12962f4a603126f1d85c56aabf65599d4a248a84", "best_bid": "0", "best_ask": "0.004"}], "timestamp": "1769384466001", "event_type": "price_change"}}
{"_local_timestamp": "2026-01-25T23:41:06.222688+00:00", "data": {"market": "0x5c5933ee7d871e48d1a120122ffee0fd57f2a547109c226bf75d12a2d3905e1e", "price_changes": [{"asset_id": "39445779384581598316851917827889246832002643510245720484561264580818170018041", "price": "0.501", "size": "0", "side": "BUY", "hash": "ef8c8c1fda2cb18723c5d05b9e8d42748224eb72", "best_bid": "0.999", "best_ask": "1"}, {"asset_id": "31450040692827736276733070952336677024248005125940001939196013706836154165101", "price": "0.499", "size": "0", "side": "SELL", "hash": "11685ae11f439c1a8f04f7111a376597bf083947", "best_bid": "0", "best_ask": "0.001"}], "timestamp": "1769384466000", "event_type": "price_change"}}
{"_local_timestamp": "2026-01-25T23:41:06.222977+00:00", "data": {"market": "0x717fb00a39a3c4cec6cc728168c3fce6e3035d8ed930aecfc6f343564b16a788", "price_changes": [{"asset_id": "60119374126653128719260895844622062846381272599857895156246552575227623552241", "price": "0.01", "size": "1000", "side": "BUY", "hash": "06dabab6ebf314cbd6b19d36574e029a14d14636", "best_bid": "0.99", "best_ask": "0.999"}, {"asset_id": "49177293917175339908646266682490527167418532793156915271748070003785027932027", "price": "0.99", "size": "1000", "side": "SELL", "hash": "623215183b362da0dd029e9b0b64789f791df91e", "best_bid": "0.001", "best_ask": "0.01"}], "timestamp": "1769384466001", "event_type": "price_change"}}
{"_local_timestamp": "2026-01-25T23:41:06.223287+00:00", "data": {"market": "0xcba6d744bd14bb788690a3479acf192ed35f44241c30820efc642d6720703a01", "price_changes": [{"asset_id": "109228675712804150419254959603454060015458251960061436438701346753980946344788", "price": "0.55", "size": "50", "side": "BUY", "hash": "a1d00c642c65852102bd05f815ca28003f4ff4a7", "best_bid": "0.999", "best_ask": "1"}, {"asset_id": "64735823985571109441321290529333378978050160684601981636835688716014717666867", "price": "0.45", "size": "50", "side": "SELL", "hash": "a6dba1670550c74ee522a0939ea0aafddc9d9ef1", "best_bid": "0", "best_ask": "0.001"}], "timestamp": "1769384466001", "event_type": "price_change"}}
{"_local_timestamp": "2026-01-25T23:41:06.237226+00:00", "data": {"market": "0x76f7c3b2f193044a7891883f044da641b75b078197b3d214b1cef235c8b771e1", "price_changes": [{"asset_id": "56082532738175047478011286938051439618844073329646641418943392710720146125419", "price": "0.035", "size": "0", "side": "BUY", "hash": "dd04f886af4875d793b00eb26666f199b91a787b", "best_bid": "0.999", "best_ask": "1"}, {"asset_id": "83705947662071625507322075497208006707849354374430230873246504758105177021022", "price": "0.965", "size": "0", "side": "SELL", "hash": "c78f51e1d00244234c22bef06f0211ee96d37eb5", "best_bid": "0", "best_ask": "0.001"}], "timestamp": "1769384466001", "event_type": "price_change"}}
{"_local_timestamp": "2026-01-25T23:41:06.260659+00:00", "data": {"market": "0xc0b3638a969d1b4a2c2c8b9ff3dda8765f5e0dfb1f1669d3223a7d0764ba1808", "price_changes": [{"asset_id": "79078096109886043971078249449586427255424561324464046969686459745648521830395", "price": "0.501", "size": "0", "side": "BUY", "hash": "f7b48c7efa4e2c3578b2ad003a8f670d2324c5af", "best_bid": "0.999", "best_ask": "1"}, {"asset_id": "71287787540221311833143710317668754611438884018424897811637563407660610591090", "price": "0.499", "size": "0", "side": "SELL", "hash": "b8724199a2087366ae5fb046fe6cea06c4a2457f", "best_bid": "0", "best_ask": "0.001"}], "timestamp": "1769384466001", "event_type": "price_change"}}
{"_local_timestamp": "2026-01-25T23:41:06.275637+00:00", "data": {"market": "0xd4e29ae9220207efbb9a6b10fe79d09dc21e0e6b15d7095289a8ca046a4977aa", "price_changes": [{"asset_id": "50566369412855320406430637371866470227092223333450744138817186935756262630055", "price": "0.501", "size": "0", "side": "BUY", "hash": "80a39ffbc39188f9e923601b8631fb586c2d6ecc", "best_bid": "0.999", "best_ask": "1"}, {"asset_id": "54581162693071710130485903923254363489511874058356442244838298018744580572687", "price": "0.499", "size": "0", "side": "SELL", "hash": "9ff915b62eaa2c0c1f948646259bf352225d0bd7", "best_bid": "0", "best_ask": "0.001"}], "timestamp": "1769384466001", "event_type": "price_change"}}
{"_local_timestamp": "2026-01-25T23:41:06.290572+00:00", "data": {"market": "0x00f131408059e28efe44b6975a5eff6a626a50b1ea117987b2a777f0c28ea352", "price_changes": [{"asset_id": "97023203174986827040174699473138310071498195771105841874355416606377824157721", "price": "0.501", "size": "0", "side": "BUY", "hash": "a6e4f433520d11930e8b5f900a6c54966b78fbfb", "best_bid": "0.999", "best_ask": "1"}, {"asset_id": "61431819519869665528604747494974593341766773949138777450330672465387185609856", "price": "0.499", "size": "0", "side": "SELL", "hash": "f5410efb5fc57b8c78c49ff6be5f153c1755b9c6", "best_bid": "0", "best_ask": "0.001"}], "timestamp": "1769384466001", "event_type": "price_change"}}
{"_local_timestamp": "2026-01-25T23:41:06.321036+00:00", "data": {"market": "0x393557eaf4c3ec53cf4a341d12263914944220359b6f02b703109ce220257641", "price_changes": [{"asset_id": "93940441597806605185863489141137222482434084554690688125580295758685733000625", "price": "0.72", "size": "160.59", "side": "BUY", "hash": "6690afdd3c8fc01c952b90862c2ba3140a93ddfa", "best_bid": "0.999", "best_ask": "1"}, {"asset_id": "84067471748088275158649178487081940954142612413002471523992575056649818081482", "price": "0.28", "size": "160.59", "side": "SELL", "hash": "a5bee741315ac69b6a514768be4001f025d09c4e", "best_bid": "0", "best_ask": "0.001"}], "timestamp": "1769384466000", "event_type": "price_change"}}
{"_local_timestamp": "2026-01-25T23:41:06.332751+00:00", "data": {"market": "0x462bb7daa3b0906569beaf26fe722dd2b742cdaaca0900c3aa710a9e8e418f15", "price_changes": [{"asset_id": "84426700624131057289025898608787752028694418359354475239466346481861071213446", "price": "0.01", "size": "1020", "side": "BUY", "hash": "27636aa600d71c1534237d7990a203c910b87d3d", "best_bid": "0.49", "best_ask": "0.51"}, {"asset_id": "109631748687541424858485727517534723373639840024430532350488906491941213609965", "price": "0.99", "size": "1020", "side": "SELL", "hash": "2c39657df7d4ba812c66a9197a60086ee9f6fe9f", "best_bid": "0.49", "best_ask": "0.51"}], "timestamp": "1769384466258", "event_type": "price_change"}}
{"_local_timestamp": "2026-01-25T23:41:06.343385+00:00", "data": {"market": "0x462bb7daa3b0906569beaf26fe722dd2b742cdaaca0900c3aa710a9e8e418f15", "price_changes": [{"asset_id": "109631748687541424858485727517534723373639840024430532350488906491941213609965", "price": "0.08", "size": "0", "side": "BUY", "hash": "b880187150a8e1a82f779d178d4a9beb6db4681b", "best_bid": "0.49", "best_ask": "0.51"}, {"asset_id": "84426700624131057289025898608787752028694418359354475239466346481861071213446", "price": "0.92", "size": "0", "side": "SELL", "hash": "dacdd17099c51906489b4f18ad1ab2a311e71185", "best_bid": "0.49", "best_ask": "0.51"}], "timestamp": "1769384466266", "event_type": "price_change"}}
{"_local_timestamp": "2026-01-25T23:41:06.343771+00:00", "data": {"market": "0x462bb7daa3b0906569beaf26fe722dd2b742cdaaca0900c3aa710a9e8e418f15", "price_changes": [{"asset_id": "109631748687541424858485727517534723373639840024430532350488906491941213609965", "price": "0.01", "size": "1000", "side": "BUY", "hash": "b880187150a8e1a82f779d178d4a9beb6db4681b", "best_bid": "0.49", "best_ask": "0.51"}, {"asset_id": "84426700624131057289025898608787752028694418359354475239466346481861071213446", "price": "0.99", "size": "1000", "side": "SELL", "hash": "dacdd17099c51906489b4f18ad1ab2a311e71185", "best_bid": "0.49", "best_ask": "0.51"}], "timestamp": "1769384466266", "event_type": "price_change"}}
{"_local_timestamp": "2026-01-25T23:41:06.344112+00:00", "data": {"market": "0xafb15e731c59384c3d0cc49a5b10ca15478b5e1b3dc515ec78f90ce0c704d585", "price_changes": [{"asset_id": "27721477593921857597151286987191549878448898559962734579469006937396328767858", "price": "0.111", "size": "0", "side": "BUY", "hash": "cf288b88c77197e2ead3e110974fc805306b43db", "best_bid": "0.999", "best_ask": "1"}, {"asset_id": "19153094648738512033099285766555908783036763432962656196067038857357488238219", "price": "0.889", "size": "0", "side": "SELL", "hash": "ffe0ce239333fd70fc365204f38b7f4df86c533a", "best_bid": "0", "best_ask": "0.001"}], "timestamp": "1769384466266", "event_type": "price_change"}}
{"_local_timestamp": "2026-01-25T23:41:06.344436+00:00", "data": {"market": "0x462bb7daa3b0906569beaf26fe722dd2b742cdaaca0900c3aa710a9e8e418f15", "price_changes": [{"asset_id": "84426700624131057289025898608787752028694418359354475239466346481861071213446", "price": "0.08", "size": "0", "side": "BUY", "hash": "f37a94504b1614b282c2d8d2d957437a2a07ba83", "best_bid": "0.49", "best_ask": "0.51"}, {"asset_id": "109631748687541424858485727517534723373639840024430532350488906491941213609965", "price": "0.92", "size": "0", "side": "SELL", "hash": "14a22aa7beefb4aa10cc4284f3e3cfcf44e6e533", "best_bid": "0.49", "best_ask": "0.51"}], "timestamp": "1769384466266", "event_type": "price_change"}}
{"_local_timestamp": "2026-01-25T23:41:06.629574+00:00", "data": {"market": "0x462bb7daa3b0906569beaf26fe722dd2b742cdaaca0900c3aa710a9e8e418f15", "price_changes": [{"asset_id": "84426700624131057289025898608787752028694418359354475239466346481861071213446", "price": "0.09", "size": "1211", "side": "BUY", "hash": "f372bf994308110588980f793f8eb06887aa2740", "best_bid": "0.49", "best_ask": "0.51"}, {"asset_id": "109631748687541424858485727517534723373639840024430532350488906491941213609965", "price": "0.91", "size": "1211", "side": "SELL", "hash": "6ec7fcb0188aafddf30554f039061fe0a52a5288", "best_bid": "0.49", "best_ask": "0.51"}], "timestamp": "1769384466558", "event_type": "price_change"}}
{"_local_timestamp": "2026-01-25T23:41:06.638493+00:00", "data": {"market": "0xafb15e731c59384c3d0cc49a5b10ca15478b5e1b3dc515ec78f90ce0c704d585", "price_changes": [{"asset_id": "27721477593921857597151286987191549878448898559962734579469006937396328767858", "price": "0.101", "size": "10100", "side": "BUY", "hash": "fd7f29c1bf2194bd28af38570d42d0ec56a52662", "best_bid": "0.999", "best_ask": "1"}, {"asset_id": "19153094648738512033099285766555908783036763432962656196067038857357488238219", "price": "0.899", "size": "10100", "side": "SELL", "hash": "35e2db3443e6626b41b55be71f5111c936956f3a", "best_bid": "0", "best_ask": "0.001"}], "timestamp": "1769384466559", "event_type": "price_change"}}
{"_local_timestamp": "2026-01-25T23:41:06.638958+00:00", "data": {"market": "0x462bb7daa3b0906569beaf26fe722dd2b742cdaaca0900c3aa710a9e8e418f15", "price_changes": [{"asset_id": "109631748687541424858485727517534723373639840024430532350488906491941213609965", "price": "0.09", "size": "1211", "side": "BUY", "hash": "70d5cc2133764a8e004ed644a7ee8c570acdbf05", "best_bid": "0.49", "best_ask": "0.51"}, {"asset_id": "84426700624131057289025898608787752028694418359354475239466346481861071213446", "price": "0.91", "size": "1211", "side": "SELL", "hash": "c44b0d3bce790e5e53aac301e08764c8b8959a05", "best_bid": "0.49", "best_ask": "0.51"}], "timestamp": "1769384466560", "event_type": "price_change"}}
{"_local_timestamp": "2026-01-25T23:41:06.897450+00:00", "data": {"market": "0x95159c454bc60f97b3c36f83e82df65a1078a294341a0c1e5207c658f1677cff", "price_changes": [{"asset_id": "51622214577048818167956068950762172686195652496669777228341234316117474308234", "price": "0.05", "size": "1600", "side": "BUY", "hash": "a8d5a0f0d300e949e16a6ad1e567c12051405d2c", "best_bid": "0.56", "best_ask": "1"}, {"asset_id": "93983273693994158380547572404838271499508530443528488764618578435868300664163", "price": "0.95", "size": "1600", "side": "SELL", "hash": "e66cd7a660d51b8def5fef3f29a87b854a657758", "best_bid": "0", "best_ask": "0.44"}], "timestamp": "1769384466688", "event_type": "price_change"}}
{"_local_timestamp": "2026-01-25T23:41:06.909147+00:00", "data": {"market": "0x462bb7daa3b0906569beaf26fe722dd2b742cdaaca0900c3aa710a9e8e418f15", "price_changes": [{"asset_id": "84426700624131057289025898608787752028694418359354475239466346481861071213446", "price": "0.31", "size": "774", "side": "BUY", "hash": "2cdbccdca15117bf681a66b79cb7e69e675e2747", "best_bid": "0.49", "best_ask": "0.51"}, {"asset_id": "109631748687541424858485727517534723373639840024430532350488906491941213609965", "price": "0.69", "size": "774", "side": "SELL", "hash": "de0e5831245c69e85effdfccf716086f2f874973", "best_bid": "0.49", "best_ask": "0.51"}], "timestamp": "1769384466687", "event_type": "price_change"}}
{"_local_timestamp": "2026-01-25T23:41:06.913898+00:00", "data": {"market": "0x1b130b268df56e4802707e2ec9b5c2929b51222d2d0a19af03516e2b960de26a", "price_changes": [{"asset_id": "77018818557373862304084960921215808370283364442421773897574584607622496684030", "price": "0.77", "size": "369", "side": "BUY", "hash": "7c19df79a9f161774c2eb994c3d03a36e1c948d2", "best_bid": "0.999", "best_ask": "1"}, {"asset_id": "72797979972272034635860920395196865314139391915868888486424461493808639864972", "price": "0.23", "size": "369", "side": "SELL", "hash": "98dfd6ba38486f8f2a487f1e5708cb4428bae0b2", "best_bid": "0", "best_ask": "0.001"}], "timestamp": "1769384466688", "event_type": "price_change"}}
{"_local_timestamp": "2026-01-25T23:41:06.928141+00:00", "data": {"market": "0x3a95272be7d95e8145bd957fae244f214b60a62fd948062f776282c2d2bdb9c8", "price_changes": [{"asset_id": "94570884678709009503382566813899043832638397291612895561327288355956778233951", "price": "0.013", "size": "6153", "side": "BUY", "hash": "9a18bab9bd346489f93ead46c9274b9875d90a29", "best_bid": "0.999", "best_ask": "1"}, {"asset_id": "34429579477292779051220305424595648879239634505793752749749838360409422364039", "price": "0.987", "size": "6153", "side": "SELL", "hash": "82131b393a454ef715af0618c9e31ae3b3d1a04b", "best_bid": "0", "best_ask": "0.001"}], "timestamp": "1769384466688", "event_type": "price_change"}}
{"_local_timestamp": "2026-01-25T23:41:07.011666+00:00", "data": {"market": "0xd9b0fc72f38c908a5a7141420c06da580d01ed86c2ec38705ea15f72cb5e5e19", "price_changes": [{"asset_id": "51572238815890626847563912025595017507148782163592329862076559798897854761860", "price": "0.013", "size": "6158", "side": "BUY", "hash": "769471e30d89cc425d998a7679143dc136a7b90a", "best_bid": "0.999", "best_ask": "1"}, {"asset_id": "57098020481919035618128472838337976081009168137472950524968489896877203309629", "price": "0.987", "size": "6158", "side": "SELL", "hash": "404c254d6e69da10d158de7801b0cd8d451c8110", "best_bid": "0", "best_ask": "0.001"}], "timestamp": "1769384466688", "event_type": "price_change"}}
{"_local_timestamp": "2026-01-25T23:41:07.012266+00:00", "data": {"market": "0xfd4c8249183b221b97b519bbbc40ccad67df85fdf5accd82b5776a795e437c6b", "price_changes": [{"asset_id": "17874277896927531123551458106581405508715609873461214308237688268056733842058", "price": "0.06", "size": "1333", "side": "BUY", "hash": "ba345d7364cf6aa8c9bbbcfb8a745637f895b0d0", "best_bid": "0.61", "best_ask": "1"}, {"asset_id": "8963298533671687804870085262130769994356887438237727171798917958022949375208", "price": "0.94", "size": "1333", "side": "SELL", "hash": "1a6a010a16343caed6ab671acc531ef9a3968eaa", "best_bid": "0", "best_ask": "0.39"}], "timestamp": "1769384466688", "event_type": "price_change"}}
{"_local_timestamp": "2026-01-25T23:41:07.016289+00:00", "data": {"market": "0x4748aea08c7479f93888e3c88574cc22f470db27586dddc3c389443aec89ff59", "price_changes": [{"asset_id": "66589182701894097810798527186415708633655827134259434616730323536170342159606", "price": "0.013", "size": "6158.47", "side": "BUY", "hash": "4022d4ba92586de4d060e881bc8488d40405a411", "best_bid": "0.99", "best_ask": "0.999"}, {"asset_id": "83504158413192513722048719030445378881634624891122351294833041377392549555836", "price": "0.987", "size": "6158.47", "side": "SELL", "hash": "15864070e58835867937621d5b74632200cfbb2f", "best_bid": "0.001", "best_ask": "0.01"}], "timestamp": "1769384466688", "event_type": "price_change"}}
{"_local_timestamp": "2026-01-25T23:41:07.021965+00:00", "data": {"market": "0xf6d24c742a3126a68c6b83264660beb058a1f82652c951d599af6bdfb7b391d4", "price_changes": [{"asset_id": "97482207647464260874772172680967961758321108174204964420696779227628091002379", "price": "0.013", "size": "14845", "side": "BUY", "hash": "61a4b9f323f318de6e3d8c4cbe5620ad7eae46bf", "best_bid": "0.996", "best_ask": "1"}, {"asset_id": "113918115236977645637180997599109290964068777945588716077455921908247080428977", "price": "0.987", "size": "14845", "side": "SELL", "hash": "a50426a50e5df77499089ef85442dbd22ff1e715", "best_bid": "0", "best_ask": "0.004"}], "timestamp": "1769384466688", "event_type": "price_change"}}
{"_local_timestamp": "2026-01-25T23:41:07.028771+00:00", "data": {"market": "0xd4e29ae9220207efbb9a6b10fe79d09dc21e0e6b15d7095289a8ca046a4977aa", "price_changes": [{"asset_id": "50566369412855320406430637371866470227092223333450744138817186935756262630055", "price": "0.771", "size": "314.47", "side": "BUY", "hash": "c61c18c7fe1ac2a7284184a148a7551668e7d183", "best_bid": "0.999", "best_ask": "1"}, {"asset_id": "54581162693071710130485903923254363489511874058356442244838298018744580572687", "price": "0.229", "size": "314.47", "side": "SELL", "hash": "1eb3fa36b7ebe5de8d184703bdcd9562bfc6e305", "best_bid": "0", "best_ask": "0.001"}], "timestamp": "1769384466688", "event_type": "price_change"}}
{"_local_timestamp": "2026-01-25T23:41:07.034622+00:00", "data": {"market": "0x5c5933ee7d871e48d1a120122ffee0fd57f2a547109c226bf75d12a2d3905e1e", "price_changes": [{"asset_id": "39445779384581598316851917827889246832002643510245720484561264580818170018041", "price": "0.771", "size": "309", "side": "BUY", "hash": "517c0ea6230dad0ac7d35a0e53f2e21bfa1affd5", "best_bid": "0.999", "best_ask": "1"}, {"asset_id": "31450040692827736276733070952336677024248005125940001939196013706836154165101", "price": "0.229", "size": "309", "side": "SELL", "hash": "6b18b37757c91369c9e8b4fa13106d12b6313a17", "best_bid": "0", "best_ask": "0.001"}], "timestamp": "1769384466688", "event_type": "price_change"}}
{"_local_timestamp": "2026-01-25T23:41:07.042681+00:00", "data": {"market": "0xec0af11a54f5f6205317897289e191394795cd7f35b76a1cb902006e4a505352", "price_changes": [{"asset_id": "88403256582890565589272354714319570649971420555579995262370758371602376328234", "price": "0.77", "size": "369", "side": "BUY", "hash": "46aa8e04bef4518e7c83c043ca49e8766e874dec", "best_bid": "0.999", "best_ask": "1"}, {"asset_id": "83902666523488757660408005544769162912726010224373037612352316388014236164604", "price": "0.23", "size": "369", "side": "SELL", "hash": "2335fcf8641a6add420fb480cd8b13ea84461250", "best_bid": "0", "best_ask": "0.001"}], "timestamp": "1769384466688", "event_type": "price_change"}}
{"_local_timestamp": "2026-01-25T23:41:07.043442+00:00", "data": {"market": "0xcba6d744bd14bb788690a3479acf192ed35f44241c30820efc642d6720703a01", "price_changes": [{"asset_id": "109228675712804150419254959603454060015458251960061436438701346753980946344788", "price": "0.77", "size": "369", "side": "BUY", "hash": "07358ab3812a82ceb18c765bd151e425cbd8517f", "best_bid": "0.999", "best_ask": "1"}, {"asset_id": "64735823985571109441321290529333378978050160684601981636835688716014717666867", "price": "0.23", "size": "369", "side": "SELL", "hash": "397035d886c75a923a196d71b79c8b2106a7ed51", "best_bid": "0", "best_ask": "0.001"}], "timestamp": "1769384466688", "event_type": "price_change"}}
{"_local_timestamp": "2026-01-25T23:41:07.043859+00:00", "data": {"market": "0xf1ce664701af71aac63156b3b4fa25a67eb79c29810953512e9724d577053bb2", "price_changes": [{"asset_id": "39778100528521559320073842412769877439422950815300994587540677860951543138758", "price": "0.77", "size": "369", "side": "BUY", "hash": "afda862a26b86e891ee5b3a620ced46e25f2fbc2", "best_bid": "0.995", "best_ask": "1"}, {"asset_id": "74880017248043009869759184047952705769556168918768905724786540599437534359659", "price": "0.23", "size": "369", "side": "SELL", "hash": "217c21e38d609ff4e4bf68450d335ad2c1bca99e", "best_bid": "0", "best_ask": "0.005"}], "timestamp": "1769384466688", "event_type": "price_change"}}
{"_local_timestamp": "2026-01-25T23:41:07.044288+00:00", "data": {"market": "0x204b14f24297c06aaa199dc1d8844bd1becc80bc07f6fca3c5b60e7578c9c201", "price_changes": [{"asset_id": "102355609737505986959456016204459786144451240240244825770982312180145369373256", "price": "0.771", "size": "314.47", "side": "BUY", "hash": "90ef5c18143dbe2888406e56db4e9fb66904cda5", "best_bid": "0.999", "best_ask": "1"}, {"asset_id": "58553512085555920981275268565214845438113167009368856656814609879942308608483", "price": "0.229", "size": "314.47", "side": "SELL", "hash": "77d81af818d47444079bced2fb4405f9ebf3ee47", "best_bid": "0", "best_ask": "0.001"}], "timestamp": "1769384466688", "event_type": "price_change"}}
{"_local_timestamp": "2026-01-25T23:41:07.059751+00:00", "data": {"market": "0x393557eaf4c3ec53cf4a341d12263914944220359b6f02b703109ce220257641", "price_changes": [{"asset_id": "93940441597806605185863489141137222482434084554690688125580295758685733000625", "price": "0.77", "size": "369", "side": "BUY", "hash": "b5d7add2f047094446c900881c1535de7ab765cd", "best_bid": "0.999", "best_ask": "1"}, {"asset_id": "84067471748088275158649178487081940954142612413002471523992575056649818081482", "price": "0.23", "size": "369", "side": "SELL", "hash": "bd9fb3008e876112ec637fc458ab63854571ca34", "best_bid": "0", "best_ask": "0.001"}], "timestamp": "1769384466688", "event_type": "price_change"}}
{"_local_timestamp": "2026-01-25T23:41:07.062767+00:00", "data": {"market": "0xbcdc50ca134fca43e2ff92b1d4eb74d1370ee70226edaff6ed2e66eded7c4f17", "price_changes": [{"asset_id": "5574857600587711269700129730512235249359616543972163182547512086378810357379", "price": "0.013", "size": "6153", "side": "BUY", "hash": "0e44025e7736543754327529b48e1b6418aa80eb", "best_bid": "0.999", "best_ask": "1"}, {"asset_id": "34715175763796870678361611735891885650420703648689314817663953704466610666238", "price": "0.987", "size": "6153", "side": "SELL", "hash": "ddb620c7b1e4f56a8adf8df391929f080cd4eb3f", "best_bid": "0", "best_ask": "0.001"}], "timestamp": "1769384466912", "event_type": "price_change"}}
{"_local_timestamp": "2026-01-25T23:41:07.064196+00:00", "data": {"market": "0xfb0f4ac0b68e94aedc1214a03cbe9c723feebf9d3a55777fe2b05b8feb66a11c", "price_changes": [{"asset_id": "55426209889638974733753071618642569441373076860672244339538811630049825345670", "price": "0.01", "size": "7666", "side": "BUY", "hash": "e2ad9cef02d96c3bfa2c8cafddd8a5194ec59c0e", "best_bid": "0.99", "best_ask": "0.999"}, {"asset_id": "43959289417856840840427763184407307972480869140742194070396563955715812876628", "price": "0.99", "size": "7666", "side": "SELL", "hash": "7cdc27b1dc00052a2c3d224db3f56adcda5eae03", "best_bid": "0.001", "best_ask": "0.01"}], "timestamp": "1769384466912", "event_type": "price_change"}}
{"_local_timestamp": "2026-01-25T23:41:07.091609+00:00", "data": {"market": "0x462bb7daa3b0906569beaf26fe722dd2b742cdaaca0900c3aa710a9e8e418f15", "price_changes": [{"asset_id": "109631748687541424858485727517534723373639840024430532350488906491941213609965", "price": "0.31", "size": "774", "side": "BUY", "hash": "5aa2c4b4eba84bc3507f0221c35ceaccec8db64d", "best_bid": "0.49", "best_ask": "0.51"}, {"asset_id": "84426700624131057289025898608787752028694418359354475239466346481861071213446", "price": "0.69", "size": "774", "side": "SELL", "hash": "d8f5a0a7c1009b9f5446627cc173ff648380f87b", "best_bid": "0.49", "best_ask": "0.51"}], "timestamp": "1769384466912", "event_type": "price_change"}}
{"_local_timestamp": "2026-01-25T23:41:07.096934+00:00", "data": {"market": "0x1a20f34335d311c98347af3e47d637b5cbcb249f7dac1915d88c08d330e765d6", "price_changes": [{"asset_id": "51847501527474096557405943284662724691287223384062767234682532363137318024266", "price": "0.771", "size": "314.47", "side": "BUY", "hash": "a6fa2caf066172c1a5ddb8b40e063a522d5640ef", "best_bid": "0.999", "best_ask": "1"}, {"asset_id": "55127205459841014452783599440229813013711949511338579686361956191876234776667", "price": "0.229", "size": "314.47", "side": "SELL", "hash": "ab06b9a804f191b6e384b55bd391bab138a27a63", "best_bid": "0", "best_ask": "0.001"}], "timestamp": "1769384466912", "event_type": "price_change"}}
{"_local_timestamp": "2026-01-25T23:41:07.097369+00:00", "data": {"market": "0x717fb00a39a3c4cec6cc728168c3fce6e3035d8ed930aecfc6f343564b16a788", "price_changes": [{"asset_id": "60119374126653128719260895844622062846381272599857895156246552575227623552241", "price": "0.01", "size": "7666", "side": "BUY", "hash": "0e44368922a9a30d13f8465a7eada646a5b4f30d", "best_bid": "0.99", "best_ask": "0.999"}, {"asset_id": "49177293917175339908646266682490527167418532793156915271748070003785027932027", "price": "0.99", "size": "7666", "side": "SELL", "hash": "0d4fb4201d58ef82540088ad0c763687b0012e58", "best_bid": "0.001", "best_ask": "0.01"}], "timestamp": "1769384466912", "event_type": "price_change"}}
{"_local_timestamp": "2026-01-25T23:41:07.097781+00:00", "data": {"market": "0x5a3fd19d87709f84b93d3a71af7adaeca3f99cdfa2e1ba4a3ad256a6ddfb481b", "price_changes": [{"asset_id": "58248314633586529362367123493139013590568973389535271143944925899040736147880", "price": "0.013", "size": "6158.47", "side": "BUY", "hash": "0f74c0bafa0619e860c94226e50db166fd99c7b3", "best_bid": "0.999", "best_ask": "1"}, {"asset_id": "65953037871248164391818099564886117125781149283903860674544296582421226617357", "price": "0.987", "size": "6158.47", "side": "SELL", "hash": "8e2f54670a46661a181d37f078b791fa6027b048", "best_bid": "0", "best_ask": "0.001"}], "timestamp": "1769384466912", "event_type": "price_change"}}
{"_local_timestamp": "2026-01-25T23:41:07.102281+00:00", "data": {"market": "0x76f7c3b2f193044a7891883f044da641b75b078197b3d214b1cef235c8b771e1", "price_changes": [{"asset_id": "56082532738175047478011286938051439618844073329646641418943392710720146125419", "price": "0.037", "size": "2162", "side": "BUY", "hash": "f1273392be27b5495175b521e856ab25b2625525", "best_bid": "0.999", "best_ask": "1"}, {"asset_id": "83705947662071625507322075497208006707849354374430230873246504758105177021022", "price": "0.963", "size": "2162", "side": "SELL", "hash": "f33c43f55323fb43e1071898c4aa28949b368749", "best_bid": "0", "best_ask": "0.001"}], "timestamp": "1769384466912", "event_type": "price_change"}}
{"_local_timestamp": "2026-01-25T23:41:07.115495+00:00", "data": {"market": "0x4c2b7eeab37dc3dbf56fb2a58451e7bf82c554a22e56ed048637c270340bb082", "price_changes": [{"asset_id": "69173073876652300953776803396376322172775215646460032389913013787125429776220", "price": "0.772", "size": "314.47", "side": "BUY", "hash": "68972ca9a9a83e3e71b5670155b1337419aa83b5", "best_bid": "0.995", "best_ask": "1"}, {"asset_id": "73025139437582022870812618619686768740565683325010098372267219247119634794964", "price": "0.228", "size": "314.47", "side": "SELL", "hash": "5872e101f0c8f5aed197e266e3485f9590f1c499", "best_bid": "0", "best_ask": "0.005"}], "timestamp": "1769384466912", "event_type": "price_change"}}
{"_local_timestamp": "2026-01-25T23:41:07.127044+00:00", "data": {"market": "0xb396be1c57cb41ca2248f91ebde81d87102b4cdcfa4aa6908abb2e1ad4d71be6", "price_changes": [{"asset_id": "34419698228673649128953341658515616138601812429723644373431200193643709482989", "price": "0.77", "size": "369", "side": "BUY", "hash": "d1771a2900093a458b8306031f3cdb4855d33f50", "best_bid": "0.999", "best_ask": "1"}, {"asset_id": "62435228944209279352438951651853891000763690834442926701361268157078928214358", "price": "0.23", "size": "369", "side": "SELL", "hash": "90da96a51e8064c780403bdaef36706d9cce8bf7", "best_bid": "0", "best_ask": "0.001"}], "timestamp": "1769384466912", "event_type": "price_change"}}
{"_local_timestamp": "2026-01-25T23:41:07.127486+00:00", "data": {"market": "0x00f131408059e28efe44b6975a5eff6a626a50b1ea117987b2a777f0c28ea352", "price_changes": [{"asset_id": "97023203174986827040174699473138310071498195771105841874355416606377824157721", "price": "0.771", "size": "314.47", "side": "BUY", "hash": "6cef7b276b0981c68acee7f7cbdb3c9f0bd7187d", "best_bid": "0.999", "best_ask": "1"}, {"asset_id": "61431819519869665528604747494974593341766773949138777450330672465387185609856", "price": "0.229", "size": "314.47", "side": "SELL", "hash": "e15b12d39def6a58b731515260e206f63bef6fec", "best_bid": "0", "best_ask": "0.001"}], "timestamp": "1769384466912", "event_type": "price_change"}}
{"_local_timestamp": "2026-01-25T23:41:07.127891+00:00", "data": {"market": "0xc0d7f7796a0cac90cb70c79845db9d226ed35959bd0aa35af7fb418f3f2e22e5", "price_changes": [{"asset_id": "12543330728269567640220567011294079896273543850192586290021550850906815833169", "price": "0.771", "size": "309", "side": "BUY", "hash": "665180e6d6a762ab7139b275f461729e05666cd7", "best_bid": "0.999", "best_ask": "1"}, {"asset_id": "10008028422703392249749236854165253701939526137534166171302431408077717628002", "price": "0.229", "size": "309", "side": "SELL", "hash": "6ef81ee26dd0e0302ab0e748ccb1f3ccbd5fb602", "best_bid": "0", "best_ask": "0.001"}], "timestamp": "1769384466912", "event_type": "price_change"}}
{"_local_timestamp": "2026-01-25T23:41:07.128287+00:00", "data": {"market": "0xc0b3638a969d1b4a2c2c8b9ff3dda8765f5e0dfb1f1669d3223a7d0764ba1808", "price_changes": [{"asset_id": "79078096109886043971078249449586427255424561324464046969686459745648521830395", "price": "0.771", "size": "309", "side": "BUY", "hash": "3da7fbe3862eb9dd70a4c299b55bfb9ba0f70121", "best_bid": "0.999", "best_ask": "1"}, {"asset_id": "71287787540221311833143710317668754611438884018424897811637563407660610591090", "price": "0.229", "size": "309", "side": "SELL", "hash": "d5f56705274d15fce2d3334bfd4a135cec395788", "best_bid": "0", "best_ask": "0.001"}], "timestamp": "1769384466912", "event_type": "price_change"}}
{"_local_timestamp": "2026-01-25T23:41:07.138909+00:00", "data": {"market": "0x6de3a6fdb4423aefb3e842d82c7ac644a5fce68f0a8ccdd0b05b7bde6fe1149a", "price_changes": [{"asset_id": "22745855048729710799193712391689530895061901586126737668400722077572535398940", "price": "0.77", "size": "369", "side": "BUY", "hash": "5716d3900bf36bc9963849f4fef39adfd4e227c3", "best_bid": "0.991", "best_ask": "1"}, {"asset_id": "4049982343138716877211130425857197940994108677561153999944183574753980469925", "price": "0.23", "size": "369", "side": "SELL", "hash": "0efccf8abda49b3aa3987b3b38d5780acd83e8e0", "best_bid": "0", "best_ask": "0.009"}], "timestamp": "1769384466912", "event_type": "price_change"}}
{"_local_timestamp": "2026-01-25T23:41:07.152926+00:00", "data": {"market": "0x1dde34de4ceb798933f85826a2879ff5676853144ea79f4c1ca89d4f8546ce73", "price_changes": [{"asset_id": "2989772230015894045729002380739794506754998903816202205758003265088876154235", "price": "0.77", "size": "379", "side": "BUY", "hash": "1df588c5f3335ca8a8c38aeec63a2959b1c75d18", "best_bid": "0.999", "best_ask": "1"}, {"asset_id": "72299768080662854793831035989036195853606657997616618081658086993981448595143", "price": "0.23", "size": "379", "side": "SELL", "hash": "2e971334e3bbdfc11de3db45329096ed57c58692", "best_bid": "0", "best_ask": "0.001"}], "timestamp": "1769384466912", "event_type": "price_change"}}
{"_local_timestamp": "2026-01-25T23:41:07.155889+00:00", "data": {"market": "0x453f8479a041419e8f794d9f7149e4d95a3d315effa5d754fa0e303c83257140", "price_changes": [{"asset_id": "39365936570984542827431489666856672933613556292100829681088739787833575189466", "price": "0.772", "size": "314.47", "side": "BUY", "hash": "859b15d6d13504014b8650f0397a3e3efa0b9666", "best_bid": "0.996", "best_ask": "1"}, {"asset_id": "19192699567236935154412948133755984775559628536019255388694943247637117213140", "price": "0.228", "size": "314.47", "side": "SELL", "hash": "8d699cd42831f9c993bbf4ef558d66541748e9f5", "best_bid": "0", "best_ask": "0.004"}], "timestamp": "1769384466912", "event_type": "price_change"}}
{"_local_timestamp": "2026-01-25T23:41:07.160116+00:00", "data": {"market": "0x33cca535d0340264125e6d424c2b72a54fbf7bed77ea0e12618b2d2117fba8d2", "price_changes": [{"asset_id": "94933623159925613438322028509055338748965839910045279599576284066393667174618", "price": "0.5", "size": "440", "side": "BUY", "hash": "8d526b93c67fcc2a88c0764368f2742782e77e0a", "best_bid": "0.999", "best_ask": "1"}, {"asset_id": "66579638131066880161649101980342858689404800341486957072639169013202428010651", "price": "0.5", "size": "440", "side": "SELL", "hash": "1f33489f10012fa1dfe31f5cc2ed458b92b5648c", "best_bid": "0", "best_ask": "0.001"}], "timestamp": "1769384467000", "event_type": "price_change"}}
{"_local_timestamp": "2026-01-25T23:41:07.160939+00:00", "data": {"market": "0xdf8ea6f127a9d5ea8f14f53eed41b6b24390879f3e35823f9c601c4e775a9f6f", "price_changes": [{"asset_id": "57520827470961388297170993749766772989637717292522446798352861047363463676119", "price": "0.5", "size": "440", "side": "BUY", "hash": "c7774dbdd9c6e1099c7bb6fa26ddb1e286128bce", "best_bid": "0.999", "best_ask": "1"}, {"asset_id": "102951250765217183430323843256952868593235165640536923878565064766596049029095", "price": "0.5", "size": "440", "side": "SELL", "hash": "e606085c6681b04f6e6434ac4a19ecb34edc8ff6", "best_bid": "0", "best_ask": "0.001"}], "timestamp": "1769384467000", "event_type": "price_change"}}
{"_local_timestamp": "2026-01-25T23:41:07.164836+00:00", "data": {"market": "0x174f99617876ff89e3d88401a3e0bcb7e0ccc8f539f981603589b759ee1c986e", "price_changes": [{"asset_id": "8465468375968679168353185049278886271922501234385197733228896629886564398231", "price": "0.501", "size": "0", "side": "BUY", "hash": "284986aa0c82c26f62a8bee6076bc5c57daaf79a", "best_bid": "0.991", "best_ask": "1"}, {"asset_id": "48703479947195481706486691840615061336509417685157069361566374591350887277675", "price": "0.499", "size": "0", "side": "SELL", "hash": "1a95d52664cc78f219c41f26e6f4a78f01e319be", "best_bid": "0", "best_ask": "0.009"}], "timestamp": "1769384467000", "event_type": "price_change"}}
{"_local_timestamp": "2026-01-25T23:41:07.173994+00:00", "data": {"market": "0x5aac5eb8ab6580a07fefe1b4101c8e2d0dc7fe18f9f09073e20099844dbda100", "price_changes": [{"asset_id": "84728266476447611508256889651403922792366137388604704373227221268140494231791", "price": "0.5", "size": "440", "side": "BUY", "hash": "f5e89a0db0dd6f539ad060ffe8bc152284fca015", "best_bid": "0.999", "best_ask": "1"}, {"asset_id": "87637668678053836144289414976006902217669102557443391993849170637464055115930", "price": "0.5", "size": "440", "side": "SELL", "hash": "0ec7534927b5eb8db44ec07bd268dfa93f5b0093", "best_bid": "0", "best_ask": "0.001"}], "timestamp": "1769384467000", "event_type": "price_change"}}
{"_local_timestamp": "2026-01-25T23:41:07.175517+00:00", "data": {"market": "0xf2d6a296447b45978757a49d4b469c2de8f65911bcec656c46e61d79e5b0ec02", "price_changes": [{"asset_id": "7748216705460976435623561406129775099072355727261540349420629705624956570226", "price": "0.5", "size": "440", "side": "BUY", "hash": "6e1a0fea7a784e2701b52d69215237a091e7baf5", "best_bid": "0.991", "best_ask": "1"}, {"asset_id": "97497637738863159234810323045630267886627719917222933191405894986155355727361", "price": "0.5", "size": "440", "side": "SELL", "hash": "177e4d46cbf680e786deaa855afbaa14d6327217", "best_bid": "0", "best_ask": "0.009"}], "timestamp": "1769384467000", "event_type": "price_change"}}
{"_local_timestamp": "2026-01-25T23:41:07.176820+00:00", "data": {"market": "0x3d0844ce16b86e66a126cfc7b6860f06b7e1d89f7c46f2730679c97b311a6946", "price_changes": [{"asset_id": "64162699045912597255102549430256867196645669965426599877159267293140384494672", "price": "0.501", "size": "0", "side": "BUY", "hash": "38ec4929f435037770a7847fbb0bf53ef28a5618", "best_bid": "0.995", "best_ask": "1"}, {"asset_id": "30140424268001367103070307735535434752966197427345930967528797587498602312567", "price": "0.499", "size": "0", "side": "SELL", "hash": "7b6a63194ab91402a7a9b780da2fc69487464cbb", "best_bid": "0", "best_ask": "0.005"}], "timestamp": "1769384467000", "event_type": "price_change"}}
{"_local_timestamp": "2026-01-25T23:41:07.177713+00:00", "data": {"market": "0xf0bce5848ca6de05a661582b4cae5f6bf815fb1054db10a5ea50d0973c11f730", "price_changes": [{"asset_id": "26611711269986954238795968887055898455427225275079966863101216346291253473218", "price": "0.5", "size": "440", "side": "BUY", "hash": "0bd64f129d6724060746a211b950e2e234aac78c", "best_bid": "0.991", "best_ask": "1"}, {"asset_id": "101618041657621872578453287140987906509660472129196215861315765866542254604120", "price": "0.5", "size": "440", "side": "SELL", "hash": "12c61863cb8540b09568794cf3124d01ed4b061a", "best_bid": "0", "best_ask": "0.009"}], "timestamp": "1769384467000", "event_type": "price_change"}}
{"_local_timestamp": "2026-01-25T23:41:07.182984+00:00", "data": {"market": "0x8af89f7ab343c39305681165171c95c1574b12e60c5304f2dd239a0a1e7a24c1", "price_changes": [{"asset_id": "37692909475645550314459974353936567359636217295346972073722745661977094322515", "price": "0.5", "size": "440", "side": "BUY", "hash": "5bd06e7ac7b755a11d9f8d60eac26da387104249", "best_bid": "0.996", "best_ask": "1"}, {"asset_id": "89418472453463174537963554748272507537614203294881181516093278640962936694404", "price": "0.5", "size": "440", "side": "SELL", "hash": "c17cdfe54d2147d20fe8603e68e810b947a911c5", "best_bid": "0", "best_ask": "0.004"}], "timestamp": "1769384467000", "event_type": "price_change"}}
{"_local_timestamp": "2026-01-25T23:41:07.183513+00:00", "data": {"market": "0x46381d9f2cbc49b1570adac72897d7760074fde567f4eb41b9183f6647964909", "price_changes": [{"asset_id": "99297111031951279105369527231196692827634634378016245082110314557578319128154", "price": "0.5", "size": "440", "side": "BUY", "hash": "3c6e4efa085972d9f77642eba72b771d254a67b0", "best_bid": "0.999", "best_ask": "1"}, {"asset_id": "89174380733589776741557368884298749975045965515062114405574362559487645447506", "price": "0.5", "size": "440", "side": "SELL", "hash": "a731adbc4d83bbdad8f6d856c1608556a916b055", "best_bid": "0", "best_ask": "0.001"}], "timestamp": "1769384467000", "event_type": "price_change"}}
{"_local_timestamp": "2026-01-25T23:41:07.184928+00:00", "data": {"market": "0x95159c454bc60f97b3c36f83e82df65a1078a294341a0c1e5207c658f1677cff", "price_changes": [{"asset_id": "51622214577048818167956068950762172686195652496669777228341234316117474308234", "price": "0.03", "size": "0", "side": "BUY", "hash": "61ce387532c308d1ebcede0d68b114589588088a", "best_bid": "0.56", "best_ask": "1"}, {"asset_id": "93983273693994158380547572404838271499508530443528488764618578435868300664163", "price": "0.97", "size": "0", "side": "SELL", "hash": "f8ef925e69a7db2108b3dd0a82bc191803e02a1e", "best_bid": "0", "best_ask": "0.44"}], "timestamp": "1769384467001", "event_type": "price_change"}}
{"_local_timestamp": "2026-01-25T23:41:07.185399+00:00", "data": {"market": "0xce44cece516669135071d3bae72fc4f5f365322a1d5005949dfc86be9be420da", "price_changes": [{"asset_id": "53974558442829387376541849493942578943658081612178694724995455494917931103192", "price": "0.65", "size": "30", "side": "BUY", "hash": "270cb17091e94784c7d8b9b3153da5c105564994", "best_bid": "0.999", "best_ask": "1"}, {"asset_id": "76014602550800947248168109629242500597255611883184659688735188973598896781240", "price": "0.35", "size": "30", "side": "SELL", "hash": "6423151e24da28391f4e78cf6f26cd37a488b897", "best_bid": "0", "best_ask": "0.001"}], "timestamp": "1769384467001", "event_type": "price_change"}}
{"_local_timestamp": "2026-01-25T23:41:07.185817+00:00", "data": {"market": "0xb8b7c370c01d589e56de7431e78203839a6054489e2049c444b97a24cad3be11", "price_changes": [{"asset_id": "28849374540506943880982554114742096039302062713864319348646490583409276747173", "price": "0.5", "size": "440", "side": "BUY", "hash": "6d444f7d7e795b85521ae95d2efc9c90c52b7371", "best_bid": "0.999", "best_ask": "1"}, {"asset_id": "83592981020384399234305075593225008895851215579831739799641923332818184660225", "price": "0.5", "size": "440", "side": "SELL", "hash": "e7617f2f65c14cbeb808ff096a20a7bebdc615d2", "best_bid": "0", "best_ask": "0.001"}], "timestamp": "1769384467001", "event_type": "price_change"}}
{"_local_timestamp": "2026-01-25T23:41:07.186229+00:00", "data": {"market": "0xffc02802851ddf3857633aef0f1146e641f16279ef1a91de899500e3f1642956", "price_changes": [{"asset_id": "83868310274258098937534955108180906010340820748057057072512945569667612470884", "price": "0.5", "size": "0", "side": "BUY", "hash": "fce2e4627c69175489841311678db9ab94006bd1", "best_bid": "0.991", "best_ask": "1"}, {"asset_id": "58246546221470895651705696424054214777798759824740890223804348498573359454874", "price": "0.5", "size": "0", "side": "SELL", "hash": "0a57cc12eedd2a1a1cc2470145b44473e202afca", "best_bid": "0", "best_ask": "0.009"}], "timestamp": "1769384467001", "event_type": "price_change"}}
{"_local_timestamp": "2026-01-25T23:41:07.186677+00:00", "data": {"market": "0x0c93caec5803eac3e4b6571dc14eaf525d00985445b5f44c45c75adc541d949f", "price_changes": [{"asset_id": "42081513420746908832995752715611088031055183705260933435790788126688597030231", "price": "0.5", "size": "440", "side": "BUY", "hash": "fcb36af79e6781830d4e24de69e2a4f0606e6713", "best_bid": "0.991", "best_ask": "1"}, {"asset_id": "95262791531890285439592660554284242677180507171292465411471784850962207018875", "price": "0.5", "size": "440", "side": "SELL", "hash": "7cb4e149f6fe7d2734cb3c59b4c6f0f8ce25f6d4", "best_bid": "0", "best_ask": "0.009"}], "timestamp": "1769384467000", "event_type": "price_change"}}
{"_local_timestamp": "2026-01-25T23:41:07.187104+00:00", "data": {"market": "0x8e32c847d8e5fc101cf164fa70dfcce2ef19fc9f4bba82a8a063fb1c25be8f66", "price_changes": [{"asset_id": "85075037879085409153276428549450686728111630086931256613306885529883454175471", "price": "0.501", "size": "0", "side": "BUY", "hash": "224d224e51d8213e24e37017ac7becfbb346ed43", "best_bid": "0.999", "best_ask": "1"}, {"asset_id": "41617232520361893962087593588795705248847905449395592919411850737120322243726", "price": "0.499", "size": "0", "side": "SELL", "hash": "edac4e3383d2cb50dc35baf4b40ec67b315e8372", "best_bid": "0", "best_ask": "0.001"}], "timestamp": "1769384467001", "event_type": "price_change"}}
{"_local_timestamp": "2026-01-25T23:41:07.187539+00:00", "data": {"market": "0xd5fb790e70d3ad1769f40ef70f55233cc6098ac83423c160dcd16f0278199c0d", "price_changes": [{"asset_id": "38669595393479333756794564935772837388967649329391357690872871259908868669902", "price": "0.5", "size": "440", "side": "BUY", "hash": "b3a7730c960aa8a122db2518da13182cbd42a284", "best_bid": "0.991", "best_ask": "1"}, {"asset_id": "67683893917838442286608716085337607998088783731863722223710730122730169958578", "price": "0.5", "size": "440", "side": "SELL", "hash": "9b23a8146be723cc72dab67ad4aad23f937caa80", "best_bid": "0", "best_ask": "0.009"}], "timestamp": "1769384467001", "event_type": "price_change"}}
{"_local_timestamp": "2026-01-25T23:41:07.187961+00:00", "data": {"market": "0x24d4c6ac79205728202e8f7c87fce23e394fcd425e2442081f975c02e14c20be", "price_changes": [{"asset_id": "3416966364373630870081312389812029383875790961501880158985109393879810083440", "price": "0.5", "size": "440", "side": "BUY", "hash": "ab395cd42e075da548aa4ab39f400d80d36ceea5", "best_bid": "0.995", "best_ask": "1"}, {"asset_id": "111358084047172002584440472770888660450582020066278598324688081719481646394656", "price": "0.5", "size": "440", "side": "SELL", "hash": "233d0e8174d6fab7a8254ab57ef1ca447587605b", "best_bid": "0", "best_ask": "0.005"}], "timestamp": "1769384467001", "event_type": "price_change"}}
{"_local_timestamp": "2026-01-25T23:41:07.188398+00:00", "data": {"market": "0x1b77653abede480dbe48e76b6dab80958170679b2adf02bec54685c63ca9a546", "price_changes": [{"asset_id": "31235796366585584348784397652164243490901775984817980456949548138406439175277", "price": "0.5", "size": "440", "side": "BUY", "hash": "cfc1747a3b2d4483aa1e70e248aaa37625c45e9a", "best_bid": "0.991", "best_ask": "1"}, {"asset_id": "52947772514216127300593849158446775746944174907449498056310257714039867887602", "price": "0.5", "size": "440", "side": "SELL", "hash": "6ac155ee41f38f38852f8b1cda4b32539a2c9e71", "best_bid": "0", "best_ask": "0.009"}], "timestamp": "1769384467001", "event_type": "price_change"}}
{"_local_timestamp": "2026-01-25T23:41:07.188854+00:00", "data": {"market": "0x03ecd51a935b6bf98cc155606a07757f8df82f65813692051f4c72c9257d2b8a", "price_changes": [{"asset_id": "61150347572202179484542766533898569511105402829901319366793784265466052825309", "price": "0.5", "size": "440", "side": "BUY", "hash": "73aa2d9773a360c6b768ef7fe111659484ce68ce", "best_bid": "0.991", "best_ask": "1"}, {"asset_id": "70854033519000008495118885269721217276572546111465787503153647369190581264337", "price": "0.5", "size": "440", "side": "SELL", "hash": "8a694537675755524f6fc341ba3ec2ebc2f22731", "best_bid": "0", "best_ask": "0.009"}], "timestamp": "1769384467001", "event_type": "price_change"}}
{"_local_timestamp": "2026-01-25T23:41:07.205074+00:00", "data": {"market": "0xfb36b9f2ce0d23b0f82b4ecb696d8c837b70a33c185cacab2d01b03c008bdaa5", "price_changes": [{"asset_id": "81287387146750561505580355482640926212406745446474340005282467156958865823238", "price": "0.5", "size": "440", "side": "BUY", "hash": "bbafd5af0cc2ea312a0d67415a20c9a55d7ea2aa", "best_bid": "0.991", "best_ask": "1"}, {"asset_id": "32119105197847901346777680653737019062753278665429569684663596053648338847292", "price": "0.5", "size": "440", "side": "SELL", "hash": "b7033750aa3207af128c7402e6293f152d5aceff", "best_bid": "0", "best_ask": "0.009"}], "timestamp": "1769384467001", "event_type": "price_change"}}
{"_local_timestamp": "2026-01-25T23:41:07.282996+00:00", "data": {"market": "0xc9d50cd59883b78a7566c95c5c49540e627b99bdfdfdee9f38aa4d20a8965092", "price_changes": [{"asset_id": "80520293693063475541125700613267791349974838363391685088405449865305853523521", "price": "0.5", "size": "440", "side": "BUY", "hash": "a97c59d79a623a6c3eeb24782d02093f61250c74", "best_bid": "0.991", "best_ask": "1"}, {"asset_id": "93686631495592470915059577974351598851938202157000548036184210764800257229360", "price": "0.5", "size": "440", "side": "SELL", "hash": "cb0c2ea4c93d7328bf672a9be70a724c0d0476da", "best_bid": "0", "best_ask": "0.009"}], "timestamp": "1769384467001", "event_type": "price_change"}}
{"_local_timestamp": "2026-01-25T23:41:07.287754+00:00", "data": {"market": "0x88c159de04783ed9846a8dcb03fa330754e46e61564059cc81acb25932710b46", "price_changes": [{"asset_id": "26962425957446230275275597334954929477143782773021571348663069985031678553413", "price": "0.5", "size": "440", "side": "BUY", "hash": "f093d91ac516ce89cbd5eb0c79695490c72440aa", "best_bid": "0.991", "best_ask": "1"}, {"asset_id": "8459072361983769420511248215510567919570934744639447022627913477245830483592", "price": "0.5", "size": "440", "side": "SELL", "hash": "9384532f467c655f56b90a9ac91534a26a90f7c3", "best_bid": "0", "best_ask": "0.009"}], "timestamp": "1769384467001", "event_type": "price_change"}}
{"_local_timestamp": "2026-01-25T23:41:07.291079+00:00", "data": {"market": "0xdb8c52f913b49429f0c941680f913fe8b9f8170e1176c92c0d2ec6aa609116c5", "price_changes": [{"asset_id": "46803634135962229171825077703475690792137743454334214987347130776565965421012", "price": "0.5", "size": "440", "side": "BUY", "hash": "a5ee90e30b17aa624f0722e8fed815fa7c68b6db", "best_bid": "0.999", "best_ask": "1"}, {"asset_id": "79771878395953822320782565470392821820625919272515479990943961908567355595301", "price": "0.5", "size": "440", "side": "SELL", "hash": "971c4ece0f5f8a05a0783d786504dcf72975369e", "best_bid": "0", "best_ask": "0.001"}], "timestamp": "1769384467001", "event_type": "price_change"}}
{"_local_timestamp": "2026-01-25T23:41:07.294981+00:00", "data": {"market": "0x1484fa631b6b04bcbb37d85c786d498fedebc9678858ce17b48ba0e3f9519b45", "price_changes": [{"asset_id": "18402099481226334869165686605666466356593385080959681184650513853894363863316", "price": "0.5", "size": "440", "side": "BUY", "hash": "89e6ddd4c0308d99883f4c8bf6ee25e284c819a2", "best_bid": "0.991", "best_ask": "1"}, {"asset_id": "24068598186203113951404786672050843911242288735982794500931518548143205695626", "price": "0.5", "size": "440", "side": "SELL", "hash": "9eba9d8ba694a1981fa7394a4fc7062ce4cf6cd7", "best_bid": "0", "best_ask": "0.009"}], "timestamp": "1769384467002", "event_type": "price_change"}}
{"_local_timestamp": "2026-01-25T23:41:07.300833+00:00", "data": {"market": "0x9350615e9b70df65499ed381a555426151aa578b80c9755c1f516fc4e1c6f235", "price_changes": [{"asset_id": "75560298592976643246574401702633222451038371118414162908867835243856309708656", "price": "0.501", "size": "0", "side": "BUY", "hash": "a8b1c4a911afdc0ac63e578acc9945318a9cbc67", "best_bid": "0.992", "best_ask": "1"}, {"asset_id": "11663191844619895104021077879042630369854320198358238010806010814420259499799", "price": "0.499", "size": "0", "side": "SELL", "hash": "9b6a79d6bb60986dfbfdfb2145618074832f9e7e", "best_bid": "0", "best_ask": "0.008"}], "timestamp": "1769384467001", "event_type": "price_change"}}
{"_local_timestamp": "2026-01-25T23:41:07.304923+00:00", "data": {"market": "0x84e5a3986fbc3fee389ed87a4f070df7478c78953a4e0ac8fcefb9cf1f7d4a90", "price_changes": [{"asset_id": "1834143411676190819902614191475506377009972301852369769871635548739845748032", "price": "0.5", "size": "440", "side": "BUY", "hash": "3008c9aed8dd45856a4583f24f7ec9c28e85eef9", "best_bid": "0.991", "best_ask": "1"}, {"asset_id": "29432070850069872970940163971322046452677105415473389882122736983204650720097", "price": "0.5", "size": "440", "side": "SELL", "hash": "6977040ddd7e89147645b7c937e95bddbcdb6a23", "best_bid": "0", "best_ask": "0.009"}], "timestamp": "1769384467001", "event_type": "price_change"}}
{"_local_timestamp": "2026-01-25T23:41:07.305502+00:00", "data": {"market": "0x082b1d3d49530a5c4b1bdfe6616af419e3c5d378bcde74f7a7ed60cfeeecf543", "price_changes": [{"asset_id": "62900695194310488026262854028149955278817013330532204834877233861501581391062", "price": "0.5", "size": "440", "side": "BUY", "hash": "f080e996f52e66c43a99369fe3cee80c54e79588", "best_bid": "0.991", "best_ask": "1"}, {"asset_id": "94251180310671755511507309886350339223509449584552212021917442764720858939978", "price": "0.5", "size": "440", "side": "SELL", "hash": "2d3877fc432ec9522ca95ef1387fc409528e2f87", "best_bid": "0", "best_ask": "0.009"}], "timestamp": "1769384467002", "event_type": "price_change"}}
{"_local_timestamp": "2026-01-25T23:41:07.306967+00:00", "data": {"market": "0xeb02db955841608dd7b20177dcee991fe4f2ea565dff4c3bd4b84ec83b645f9a", "price_changes": [{"asset_id": "100018068008040261825170439668225153993196628728529816847778302576794454481108", "price": "0.5", "size": "0", "side": "BUY", "hash": "033f51653e0952b9adf0fdeefdd07fc27b525da3", "best_bid": "0.991", "best_ask": "1"}, {"asset_id": "58025251642493946196272668217217183996192324147426153302998300455299188048809", "price": "0.5", "size": "0", "side": "SELL", "hash": "5269e137025461e3e8ecd2d17ba04309586d048c", "best_bid": "0", "best_ask": "0.009"}], "timestamp": "1769384467002", "event_type": "price_change"}}
{"_local_timestamp": "2026-01-25T23:41:07.329997+00:00", "data": {"market": "0xafb15e731c59384c3d0cc49a5b10ca15478b5e1b3dc515ec78f90ce0c704d585", "price_changes": [{"asset_id": "27721477593921857597151286987191549878448898559962734579469006937396328767858", "price": "0.501", "size": "0", "side": "BUY", "hash": "5da69c39937c5b2de59dd540880b9bf527f1a166", "best_bid": "0.999", "best_ask": "1"}, {"asset_id": "19153094648738512033099285766555908783036763432962656196067038857357488238219", "price": "0.499", "size": "0", "side": "SELL", "hash": "d9754675b0e77c2acf6d0de5090a24d0795ff40c", "best_bid": "0", "best_ask": "0.001"}], "timestamp": "1769384467002", "event_type": "price_change"}}
{"_local_timestamp": "2026-01-25T23:41:07.468987+00:00", "data": {"market": "0xd3866b1b556fe5843dbf7a6517780211295ba024bb4a90a749531b1cfbf2ac20", "price_changes": [{"asset_id": "30947500130804640808249625202467513009782734777729829776701604345427228069664", "price": "0.501", "size": "0", "side": "BUY", "hash": "80794550691f0940e9e4cdad8d2383b9df777c89", "best_bid": "0.999", "best_ask": "1"}, {"asset_id": "112914448831136287961641635085213918544450861148980379546124511283573338657686", "price": "0.499", "size": "0", "side": "SELL", "hash": "4d360ae7b919ca8379b6d67ff91035cb74f12162", "best_bid": "0", "best_ask": "0.001"}], "timestamp": "1769384467002", "event_type": "price_change"}}
{"_local_timestamp": "2026-01-25T23:41:07.469584+00:00", "data": {"market": "0x2fb524a8bd4a9274a3347f130e97ec434f882cde9c72c6c39a478df8a037b6bc", "price_changes": [{"asset_id": "81676411729682572522209607657662370196428570636534278076571567552256536781076", "price": "0.501", "size": "0", "side": "BUY", "hash": "d9da55456341b345bc330a6268ca07eeb15ba0b0", "best_bid": "0.999", "best_ask": "1"}, {"asset_id": "88238876172066828223705449297653633223268017246368037214406599205862569277341", "price": "0.499", "size": "0", "side": "SELL", "hash": "a4d4decc7e67e1553fd915d324830b157ac3046d", "best_bid": "0", "best_ask": "0.001"}], "timestamp": "1769384467002", "event_type": "price_change"}}
{"_local_timestamp": "2026-01-25T23:41:07.470081+00:00", "data": {"market": "0xc509411ef133866e75fe61d20ea4ee7be70fcf00843fe605db1bb095a5862b15", "price_changes": [{"asset_id": "45555810545993612965430060201918590422740142498305025284246002991925909487625", "price": "0.501", "size": "0", "side": "BUY", "hash": "cfa22d02104dd6ba7153a9afd0d3bc8e911dfc18", "best_bid": "0.995", "best_ask": "1"}, {"asset_id": "11750347072954117414759862893422867351489364626761446082158388065590872281535", "price": "0.499", "size": "0", "side": "SELL", "hash": "1f22eb23c16adfb64e462811d5b3b70ecea4ccc1", "best_bid": "0", "best_ask": "0.005"}], "timestamp": "1769384467003", "event_type": "price_change"}}
{"_local_timestamp": "2026-01-25T23:41:07.470803+00:00", "data": {"market": "0xdc9d3b6adb4ec1d0bd24409bac6537f979720fd2d540e04ce9a5223bf42b9aa6", "price_changes": [{"asset_id": "69658209478973033181726587560985982613825739930726601099487874533280680791418", "price": "0.5", "size": "480", "side": "BUY", "hash": "9152ba61bddb768f2ee421207f8dfe6d4f81d51a", "best_bid": "0.999", "best_ask": "1"}, {"asset_id": "96910445513992308799227995027211940876785078628341868853241341912618720742656", "price": "0.5", "size": "480", "side": "SELL", "hash": "2e9d481f73fe349cdd8ea8efb45a79ba029bf6fb", "best_bid": "0", "best_ask": "0.001"}], "timestamp": "1769384467003", "event_type": "price_change"}}
{"_local_timestamp": "2026-01-25T23:41:07.471293+00:00", "data": {"market": "0x0ddecb3719cb794f5e7579e7d507b9ad43b923c937cfd2f5a986cf6a81dee110", "price_changes": [{"asset_id": "110102504010926247021349733674729068129771632709988877722712998580229970801235", "price": "0.5", "size": "440", "side": "BUY", "hash": "63259cdac66167899b536f3fc90ddf132bc89345", "best_bid": "0.991", "best_ask": "1"}, {"asset_id": "86378274955206497521039828168131476196819840033175972348144762576295741113618", "price": "0.5", "size": "440", "side": "SELL", "hash": "d607c9caf17463f50966dfcbb8ac0a5e5316ad76", "best_bid": "0", "best_ask": "0.009"}], "timestamp": "1769384467003", "event_type": "price_change"}}
{"_local_timestamp": "2026-01-25T23:41:07.471793+00:00", "data": {"market": "0xd5fb790e70d3ad1769f40ef70f55233cc6098ac83423c160dcd16f0278199c0d", "price_changes": [{"asset_id": "38669595393479333756794564935772837388967649329391357690872871259908868669902", "price": "0.77", "size": "369", "side": "BUY", "hash": "3a125bade87b7444976b42e5fda4633d788af5e3", "best_bid": "0.991", "best_ask": "1"}, {"asset_id": "67683893917838442286608716085337607998088783731863722223710730122730169958578", "price": "0.23", "size": "369", "side": "SELL", "hash": "33d779c8062db781d0e944c839448478bd7374a3", "best_bid": "0", "best_ask": "0.009"}], "timestamp": "1769384467144", "event_type": "price_change"}}
{"_local_timestamp": "2026-01-25T23:41:07.472281+00:00", "data": {"market": "0xc509411ef133866e75fe61d20ea4ee7be70fcf00843fe605db1bb095a5862b15", "price_changes": [{"asset_id": "45555810545993612965430060201918590422740142498305025284246002991925909487625", "price": "0.772", "size": "314.47", "side": "BUY", "hash": "08995f39be0d725d9dca4b4625ba95d21f52b652", "best_bid": "0.995", "best_ask": "1"}, {"asset_id": "11750347072954117414759862893422867351489364626761446082158388065590872281535", "price": "0.228", "size": "314.47", "side": "SELL", "hash": "3208ec0a182a783dc8333859b4463416eb901191", "best_bid": "0", "best_ask": "0.005"}], "timestamp": "1769384467144", "event_type": "price_change"}}
{"_local_timestamp": "2026-01-25T23:41:07.472863+00:00", "data": {"market": "0xdb8c52f913b49429f0c941680f913fe8b9f8170e1176c92c0d2ec6aa609116c5", "price_changes": [{"asset_id": "46803634135962229171825077703475690792137743454334214987347130776565965421012", "price": "0.77", "size": "369", "side": "BUY", "hash": "dc27b7c5f97b8f6264783265cd2e098f7e764f14", "best_bid": "0.999", "best_ask": "1"}, {"asset_id": "79771878395953822320782565470392821820625919272515479990943961908567355595301", "price": "0.23", "size": "369", "side": "SELL", "hash": "3e49a7bf2464c4b3d71837f990496a10e703b46c", "best_bid": "0", "best_ask": "0.001"}], "timestamp": "1769384467144", "event_type": "price_change"}}
{"_local_timestamp": "2026-01-25T23:41:07.474035+00:00", "data": {"market": "0xc9d50cd59883b78a7566c95c5c49540e627b99bdfdfdee9f38aa4d20a8965092", "price_changes": [{"asset_id": "80520293693063475541125700613267791349974838363391685088405449865305853523521", "price": "0.77", "size": "369", "side": "BUY", "hash": "91af2e67fa25326535019392a613e4427433b993", "best_bid": "0.991", "best_ask": "1"}, {"asset_id": "93686631495592470915059577974351598851938202157000548036184210764800257229360", "price": "0.23", "size": "369", "side": "SELL", "hash": "ac57675fc869696f73a29009632c219917061ec3", "best_bid": "0", "best_ask": "0.009"}], "timestamp": "1769384467144", "event_type": "price_change"}}
{"_local_timestamp": "2026-01-25T23:41:07.475137+00:00", "data": {"market": "0xdc9d3b6adb4ec1d0bd24409bac6537f979720fd2d540e04ce9a5223bf42b9aa6", "price_changes": [{"asset_id": "69658209478973033181726587560985982613825739930726601099487874533280680791418", "price": "0.77", "size": "369", "side": "BUY", "hash": "ea8523b0ad9e68cd7c2a2a1caf75c0e29970f54a", "best_bid": "0.999", "best_ask": "1"}, {"asset_id": "96910445513992308799227995027211940876785078628341868853241341912618720742656", "price": "0.23", "size": "369", "side": "SELL", "hash": "e85cbffe1d8fb5309036e2395e3d008e8fb438f1", "best_bid": "0", "best_ask": "0.001"}], "timestamp": "1769384467144", "event_type": "price_change"}}
{"_local_timestamp": "2026-01-25T23:41:07.477020+00:00", "data": {"market": "0xce44cece516669135071d3bae72fc4f5f365322a1d5005949dfc86be9be420da", "price_changes": [{"asset_id": "53974558442829387376541849493942578943658081612178694724995455494917931103192", "price": "0.77", "size": "369", "side": "BUY", "hash": "df5a27a34a746a2f04deaf0087b331d8d7ec8672", "best_bid": "0.999", "best_ask": "1"}, {"asset_id": "76014602550800947248168109629242500597255611883184659688735188973598896781240", "price": "0.23", "size": "369", "side": "SELL", "hash": "e4d54f3c171f5d24559937502ecc809c2098817c", "best_bid": "0", "best_ask": "0.001"}], "timestamp": "1769384467145", "event_type": "price_change"}}
{"_local_timestamp": "2026-01-25T23:41:07.478994+00:00", "data": {"market": "0x174f99617876ff89e3d88401a3e0bcb7e0ccc8f539f981603589b759ee1c986e", "price_changes": [{"asset_id": "8465468375968679168353185049278886271922501234385197733228896629886564398231", "price": "0.772", "size": "314.47", "side": "BUY", "hash": "34f6174c70569fd3883fb1e4a97635387320ed47", "best_bid": "0.991", "best_ask": "1"}, {"asset_id": "48703479947195481706486691840615061336509417685157069361566374591350887277675", "price": "0.228", "size": "314.47", "side": "SELL", "hash": "3a779dabe831d239cddd2e594942ca7052f5671b", "best_bid": "0", "best_ask": "0.009"}], "timestamp": "1769384467145", "event_type": "price_change"}}
{"_local_timestamp": "2026-01-25T23:41:07.479640+00:00", "data": {"market": "0x84e5a3986fbc3fee389ed87a4f070df7478c78953a4e0ac8fcefb9cf1f7d4a90", "price_changes": [{"asset_id": "1834143411676190819902614191475506377009972301852369769871635548739845748032", "price": "0.77", "size": "369", "side": "BUY", "hash": "29cfacd3db5d0e2d3e8b271ec314d9fe2a4baf8e", "best_bid": "0.991", "best_ask": "1"}, {"asset_id": "29432070850069872970940163971322046452677105415473389882122736983204650720097", "price": "0.23", "size": "369", "side": "SELL", "hash": "1b4b56e26787fa61b55a0c98dfa1c94565467cc1", "best_bid": "0", "best_ask": "0.009"}], "timestamp": "1769384467145", "event_type": "price_change"}}
{"_local_timestamp": "2026-01-25T23:41:07.480385+00:00", "data": {"market": "0x41701e7ba16d4af257e01e112cff807143ef2d2ecb90cc481f11652e055d4c59", "price_changes": [{"asset_id": "10466278887690510175905331848661528762143716832637414322344895027265950979694", "price": "0.77", "size": "369", "side": "BUY", "hash": "cfd2445f34145772a3a2b85dad5e69ae1c086a12", "best_bid": "0.999", "best_ask": "1"}, {"asset_id": "25335907832274451055949522033815474513838672679545890866843065752499213006185", "price": "0.23", "size": "369", "side": "SELL", "hash": "3561e903b5352e8403747c794dc338f8b1b0c722", "best_bid": "0", "best_ask": "0.001"}], "timestamp": "1769384467145", "event_type": "price_change"}}
{"_local_timestamp": "2026-01-25T23:41:07.481057+00:00", "data": {"market": "0xeb02db955841608dd7b20177dcee991fe4f2ea565dff4c3bd4b84ec83b645f9a", "price_changes": [{"asset_id": "100018068008040261825170439668225153993196628728529816847778302576794454481108", "price": "0.77", "size": "369", "side": "BUY", "hash": "fed4088106ab88e0e1c8b96c773f22a4b5a38c39", "best_bid": "0.991", "best_ask": "1"}, {"asset_id": "58025251642493946196272668217217183996192324147426153302998300455299188048809", "price": "0.23", "size": "369", "side": "SELL", "hash": "f204a2f6d6a17f74982c67f7b2368d2dd98ccb65", "best_bid": "0", "best_ask": "0.009"}], "timestamp": "1769384467145", "event_type": "price_change"}}
{"_local_timestamp": "2026-01-25T23:41:07.481587+00:00", "data": {"market": "0x3d0844ce16b86e66a126cfc7b6860f06b7e1d89f7c46f2730679c97b311a6946", "price_changes": [{"asset_id": "64162699045912597255102549430256867196645669965426599877159267293140384494672", "price": "0.772", "size": "314.47", "side": "BUY", "hash": "87e66f81f79e0ca737fa207424eedb514ea2fbbd", "best_bid": "0.995", "best_ask": "1"}, {"asset_id": "30140424268001367103070307735535434752966197427345930967528797587498602312567", "price": "0.228", "size": "314.47", "side": "SELL", "hash": "03bb200a1e089f7815a72406563a8d64184cefd6", "best_bid": "0", "best_ask": "0.005"}], "timestamp": "1769384467145", "event_type": "price_change"}}
{"_local_timestamp": "2026-01-25T23:41:07.484701+00:00", "data": {"market": "0xffc02802851ddf3857633aef0f1146e641f16279ef1a91de899500e3f1642956", "price_changes": [{"asset_id": "83868310274258098937534955108180906010340820748057057072512945569667612470884", "price": "0.77", "size": "369", "side": "BUY", "hash": "b8996c8d30160bc98024427d97cd89ac0aab1d85", "best_bid": "0.991", "best_ask": "1"}, {"asset_id": "58246546221470895651705696424054214777798759824740890223804348498573359454874", "price": "0.23", "size": "369", "side": "SELL", "hash": "34743b61a05bac706cc219dcee391aadd85926ed", "best_bid": "0", "best_ask": "0.009"}], "timestamp": "1769384467145", "event_type": "price_change"}}
{"_local_timestamp": "2026-01-25T23:41:07.485310+00:00", "data": {"market": "0x88c159de04783ed9846a8dcb03fa330754e46e61564059cc81acb25932710b46", "price_changes": [{"asset_id": "26962425957446230275275597334954929477143782773021571348663069985031678553413", "price": "0.117", "size": "4400", "side": "BUY", "hash": "76f7d02349b574e6187b3f9cae2adfdf5d537e50", "best_bid": "0.991", "best_ask": "1"}, {"asset_id": "8459072361983769420511248215510567919570934744639447022627913477245830483592", "price": "0.883", "size": "4400", "side": "SELL", "hash": "81e3655eea72de26a5bf7f1d8542b7a828e2b212", "best_bid": "0", "best_ask": "0.009"}], "timestamp": "1769384467332", "event_type": "price_change"}}
{"_local_timestamp": "2026-01-25T23:41:07.485834+00:00", "data": {"market": "0xb8b7c370c01d589e56de7431e78203839a6054489e2049c444b97a24cad3be11", "price_changes": [{"asset_id": "28849374540506943880982554114742096039302062713864319348646490583409276747173", "price": "0.77", "size": "369", "side": "BUY", "hash": "77e605abc69646821b340844caf473b29531eb59", "best_bid": "0.999", "best_ask": "1"}, {"asset_id": "83592981020384399234305075593225008895851215579831739799641923332818184660225", "price": "0.23", "size": "369", "side": "SELL", "hash": "11621e1f1959feb74d5c275cfb6bd9fc83a59713", "best_bid": "0", "best_ask": "0.001"}], "timestamp": "1769384467394", "event_type": "price_change"}}
{"_local_timestamp": "2026-01-25T23:41:07.486350+00:00", "data": {"market": "0xf2d6a296447b45978757a49d4b469c2de8f65911bcec656c46e61d79e5b0ec02", "price_changes": [{"asset_id": "7748216705460976435623561406129775099072355727261540349420629705624956570226", "price": "0.77", "size": "369", "side": "BUY", "hash": "68cfb2c45d4c705ae8f3d94404e25263b09e4426", "best_bid": "0.991", "best_ask": "1"}, {"asset_id": "97497637738863159234810323045630267886627719917222933191405894986155355727361", "price": "0.23", "size": "369", "side": "SELL", "hash": "bf68d883a456f3b77ed3c6e6871209375f655dad", "best_bid": "0", "best_ask": "0.009"}], "timestamp": "1769384467394", "event_type": "price_change"}}
{"_local_timestamp": "2026-01-25T23:41:07.486864+00:00", "data": {"market": "0x0c93caec5803eac3e4b6571dc14eaf525d00985445b5f44c45c75adc541d949f", "price_changes": [{"asset_id": "42081513420746908832995752715611088031055183705260933435790788126688597030231", "price": "0.77", "size": "369", "side": "BUY", "hash": "062b4100a9558df8aebb074bb26892218fcd83c8", "best_bid": "0.991", "best_ask": "1"}, {"asset_id": "95262791531890285439592660554284242677180507171292465411471784850962207018875", "price": "0.23", "size": "369", "side": "SELL", "hash": "e47355dd2b916819c59b5407a2bc4605c14d4526", "best_bid": "0", "best_ask": "0.009"}], "timestamp": "1769384467394", "event_type": "price_change"}}
{"_local_timestamp": "2026-01-25T23:41:07.487397+00:00", "data": {"market": "0x03ecd51a935b6bf98cc155606a07757f8df82f65813692051f4c72c9257d2b8a", "price_changes": [{"asset_id": "61150347572202179484542766533898569511105402829901319366793784265466052825309", "price": "0.77", "size": "489", "side": "BUY", "hash": "36256fbd27b7b7c3976521de4b7e5e6bb2e28966", "best_bid": "0.991", "best_ask": "1"}, {"asset_id": "70854033519000008495118885269721217276572546111465787503153647369190581264337", "price": "0.23", "size": "489", "side": "SELL", "hash": "8d57fbb2ed325d71e53ac3ce169574edc01be0f9", "best_bid": "0", "best_ask": "0.009"}], "timestamp": "1769384467394", "event_type": "price_change"}}
{"_local_timestamp": "2026-01-25T23:41:07.487978+00:00", "data": {"market": "0x9350615e9b70df65499ed381a555426151aa578b80c9755c1f516fc4e1c6f235", "price_changes": [{"asset_id": "75560298592976643246574401702633222451038371118414162908867835243856309708656", "price": "0.774", "size": "314.47", "side": "BUY", "hash": "c48ae8b33b259b03d57a557bce6480efacdbb5a8", "best_bid": "0.992", "best_ask": "1"}, {"asset_id": "11663191844619895104021077879042630369854320198358238010806010814420259499799", "price": "0.226", "size": "314.47", "side": "SELL", "hash": "03a5ba2b9bb2ae22f59eb52ef1abf652b5521d75", "best_bid": "0", "best_ask": "0.008"}], "timestamp": "1769384467394", "event_type": "price_change"}}
{"_local_timestamp": "2026-01-25T23:41:07.488533+00:00", "data": {"market": "0x082b1d3d49530a5c4b1bdfe6616af419e3c5d378bcde74f7a7ed60cfeeecf543", "price_changes": [{"asset_id": "62900695194310488026262854028149955278817013330532204834877233861501581391062", "price": "0.77", "size": "369", "side": "BUY", "hash": "43f58a449d2ca760f38710823cb9f3c5ad191196", "best_bid": "0.991", "best_ask": "1"}, {"asset_id": "94251180310671755511507309886350339223509449584552212021917442764720858939978", "price": "0.23", "size": "369", "side": "SELL", "hash": "19319a364ec8515c18cc52e5fc9b68e5ddba7dec", "best_bid": "0", "best_ask": "0.009"}], "timestamp": "1769384467394", "event_type": "price_change"}}
{"_local_timestamp": "2026-01-25T23:41:07.489078+00:00", "data": {"market": "0x1484fa631b6b04bcbb37d85c786d498fedebc9678858ce17b48ba0e3f9519b45", "price_changes": [{"asset_id": "18402099481226334869165686605666466356593385080959681184650513853894363863316", "price": "0.77", "size": "369", "side": "BUY", "hash": "cc1304bfff38ce992d5ff1a6da9a5e4a929af07f", "best_bid": "0.991", "best_ask": "1"}, {"asset_id": "24068598186203113951404786672050843911242288735982794500931518548143205695626", "price": "0.23", "size": "369", "side": "SELL", "hash": "98f90cf69d34c60842e26900dd88a0c8a8d0c918", "best_bid": "0", "best_ask": "0.009"}], "timestamp": "1769384467394", "event_type": "price_change"}}
{"_local_timestamp": "2026-01-25T23:41:07.489608+00:00", "data": {"market": "0x0ddecb3719cb794f5e7579e7d507b9ad43b923c937cfd2f5a986cf6a81dee110", "price_changes": [{"asset_id": "110102504010926247021349733674729068129771632709988877722712998580229970801235", "price": "0.77", "size": "369", "side": "BUY", "hash": "45b76bd9274e841a74311d20b3f36fef68eba164", "best_bid": "0.991", "best_ask": "1"}, {"asset_id": "86378274955206497521039828168131476196819840033175972348144762576295741113618", "price": "0.23", "size": "369", "side": "SELL", "hash": "2fa08e3e089501dc1a39c0ce30233021ae1a84e0", "best_bid": "0", "best_ask": "0.009"}], "timestamp": "1769384467394", "event_type": "price_change"}}
{"_local_timestamp": "2026-01-25T23:41:07.490133+00:00", "data": {"market": "0x5aac5eb8ab6580a07fefe1b4101c8e2d0dc7fe18f9f09073e20099844dbda100", "price_changes": [{"asset_id": "84728266476447611508256889651403922792366137388604704373227221268140494231791", "price": "0.77", "size": "369", "side": "BUY", "hash": "85a26ad2b48aa32a5bee38e247b24c93ab395d25", "best_bid": "0.999", "best_ask": "1"}, {"asset_id": "87637668678053836144289414976006902217669102557443391993849170637464055115930", "price": "0.23", "size": "369", "side": "SELL", "hash": "7b537742b19d4c52c6104b808ba7c25630505d97", "best_bid": "0", "best_ask": "0.001"}], "timestamp": "1769384467394", "event_type": "price_change"}}
{"_local_timestamp": "2026-01-25T23:41:07.490674+00:00", "data": {"market": "0x8e32c847d8e5fc101cf164fa70dfcce2ef19fc9f4bba82a8a063fb1c25be8f66", "price_changes": [{"asset_id": "85075037879085409153276428549450686728111630086931256613306885529883454175471", "price": "0.771", "size": "314.47", "side": "BUY", "hash": "338f4daff5ab148e7ccd17bba81affdbcafc30a3", "best_bid": "0.999", "best_ask": "1"}, {"asset_id": "41617232520361893962087593588795705248847905449395592919411850737120322243726", "price": "0.229", "size": "314.47", "side": "SELL", "hash": "ff9b368c8b7e2fa4fd3efa42e88a10d6dd3dcd26", "best_bid": "0", "best_ask": "0.001"}], "timestamp": "1769384467394", "event_type": "price_change"}}
{"_local_timestamp": "2026-01-25T23:41:07.491251+00:00", "data": {"market": "0xafb15e731c59384c3d0cc49a5b10ca15478b5e1b3dc515ec78f90ce0c704d585", "price_changes": [{"asset_id": "27721477593921857597151286987191549878448898559962734579469006937396328767858", "price": "0.771", "size": "314.47", "side": "BUY", "hash": "c6268a65803cbe9878687e71d8c5657451ee6687", "best_bid": "0.999", "best_ask": "1"}, {"asset_id": "19153094648738512033099285766555908783036763432962656196067038857357488238219", "price": "0.229", "size": "314.47", "side": "SELL", "hash": "bbd513e5c9740d1723dcdefc026869fc439786e1", "best_bid": "0", "best_ask": "0.001"}], "timestamp": "1769384467394", "event_type": "price_change"}}
{"_local_timestamp": "2026-01-25T23:41:07.725086+00:00", "data": {"market": "0x24d4c6ac79205728202e8f7c87fce23e394fcd425e2442081f975c02e14c20be", "price_changes": [{"asset_id": "3416966364373630870081312389812029383875790961501880158985109393879810083440", "price": "0.77", "size": "369", "side": "BUY", "hash": "dbca1fd075b976da160d1f6505d23e0f2412091f", "best_bid": "0.995", "best_ask": "1"}, {"asset_id": "111358084047172002584440472770888660450582020066278598324688081719481646394656", "price": "0.23", "size": "369", "side": "SELL", "hash": "ba1ede46978c9d6ebc393f37893b3977ca88a480", "best_bid": "0", "best_ask": "0.005"}], "timestamp": "1769384467643", "event_type": "price_change"}}
{"_local_timestamp": "2026-01-25T23:41:07.741508+00:00", "data": {"market": "0xdf8ea6f127a9d5ea8f14f53eed41b6b24390879f3e35823f9c601c4e775a9f6f", "price_changes": [{"asset_id": "57520827470961388297170993749766772989637717292522446798352861047363463676119", "price": "0.77", "size": "369", "side": "BUY", "hash": "4e1a975f3233ee69728fc9f7c47f29e83f6cc8b6", "best_bid": "0.999", "best_ask": "1"}, {"asset_id": "102951250765217183430323843256952868593235165640536923878565064766596049029095", "price": "0.23", "size": "369", "side": "SELL", "hash": "7961c7d6bce4709a1cfd37cd6426ac3e8082051a", "best_bid": "0", "best_ask": "0.001"}], "timestamp": "1769384467643", "event_type": "price_change"}}
{"_local_timestamp": "2026-01-25T23:41:07.742108+00:00", "data": {"market": "0xfb36b9f2ce0d23b0f82b4ecb696d8c837b70a33c185cacab2d01b03c008bdaa5", "price_changes": [{"asset_id": "81287387146750561505580355482640926212406745446474340005282467156958865823238", "price": "0.77", "size": "369", "side": "BUY", "hash": "73c1589f3e65eb8709449888f4e259d712f7c994", "best_bid": "0.991", "best_ask": "1"}, {"asset_id": "32119105197847901346777680653737019062753278665429569684663596053648338847292", "price": "0.23", "size": "369", "side": "SELL", "hash": "3f9f1cce78bb7f332b1b4ab04d1ebf66520c5c50", "best_bid": "0", "best_ask": "0.009"}], "timestamp": "1769384467643", "event_type": "price_change"}}
{"_local_timestamp": "2026-01-25T23:41:07.757523+00:00", "data": {"market": "0x1b77653abede480dbe48e76b6dab80958170679b2adf02bec54685c63ca9a546", "price_changes": [{"asset_id": "31235796366585584348784397652164243490901775984817980456949548138406439175277", "price": "0.77", "size": "369", "side": "BUY", "hash": "a3ea81b650dcf470b5c2d14e0424209d2f12a3c1", "best_bid": "0.991", "best_ask": "1"}, {"asset_id": "52947772514216127300593849158446775746944174907449498056310257714039867887602", "price": "0.23", "size": "369", "side": "SELL", "hash": "076380396fd177b655a2a221dc3841b206951c8d", "best_bid": "0", "best_ask": "0.009"}], "timestamp": "1769384467643", "event_type": "price_change"}}
{"_local_timestamp": "2026-01-25T23:41:07.758089+00:00", "data": {"market": "0x88c159de04783ed9846a8dcb03fa330754e46e61564059cc81acb25932710b46", "price_changes": [{"asset_id": "26962425957446230275275597334954929477143782773021571348663069985031678553413", "price": "0.77", "size": "369", "side": "BUY", "hash": "8c835aa45866b322fd222783b05dec127c497552", "best_bid": "0.991", "best_ask": "1"}, {"asset_id": "8459072361983769420511248215510567919570934744639447022627913477245830483592", "price": "0.23", "size": "369", "side": "SELL", "hash": "4a5d71fca746b5c13611dcbfc14be0f987406b04", "best_bid": "0", "best_ask": "0.009"}], "timestamp": "1769384467643", "event_type": "price_change"}}
{"_local_timestamp": "2026-01-25T23:41:07.758822+00:00", "data": {"market": "0x2fb524a8bd4a9274a3347f130e97ec434f882cde9c72c6c39a478df8a037b6bc", "price_changes": [{"asset_id": "81676411729682572522209607657662370196428570636534278076571567552256536781076", "price": "0.771", "size": "309", "side": "BUY", "hash": "72d9e5850ca79f0eb3892677382b984037787bcc", "best_bid": "0.999", "best_ask": "1"}, {"asset_id": "88238876172066828223705449297653633223268017246368037214406599205862569277341", "price": "0.229", "size": "309", "side": "SELL", "hash": "e859f6dfbadbc5f9b9d5adbe35597f89a84f02a3", "best_bid": "0", "best_ask": "0.001"}], "timestamp": "1769384467643", "event_type": "price_change"}}
{"_local_timestamp": "2026-01-25T23:41:07.760710+00:00", "data": {"market": "0xf0bce5848ca6de05a661582b4cae5f6bf815fb1054db10a5ea50d0973c11f730", "price_changes": [{"asset_id": "26611711269986954238795968887055898455427225275079966863101216346291253473218", "price": "0.77", "size": "369", "side": "BUY", "hash": "e54653b0ac34588a6b9c2c3439ee6a922993e985", "best_bid": "0.991", "best_ask": "1"}, {"asset_id": "101618041657621872578453287140987906509660472129196215861315765866542254604120", "price": "0.23", "size": "369", "side": "SELL", "hash": "94a204518074ce2afd99c03e4a3b35cddfc77512", "best_bid": "0", "best_ask": "0.009"}], "timestamp": "1769384467643", "event_type": "price_change"}}
{"_local_timestamp": "2026-01-25T23:41:07.761340+00:00", "data": {"market": "0x8af89f7ab343c39305681165171c95c1574b12e60c5304f2dd239a0a1e7a24c1", "price_changes": [{"asset_id": "37692909475645550314459974353936567359636217295346972073722745661977094322515", "price": "0.77", "size": "369", "side": "BUY", "hash": "1f8bd61911298c4ae9585f4c2ba5a8f00c45a722", "best_bid": "0.996", "best_ask": "1"}, {"asset_id": "89418472453463174537963554748272507537614203294881181516093278640962936694404", "price": "0.23", "size": "369", "side": "SELL", "hash": "cc352e5ff0b1cbe5c2a4a68be7a313110e2cbf97", "best_bid": "0", "best_ask": "0.004"}], "timestamp": "1769384467643", "event_type": "price_change"}}
{"_local_timestamp": "2026-01-25T23:41:07.761910+00:00", "data": {"market": "0x46381d9f2cbc49b1570adac72897d7760074fde567f4eb41b9183f6647964909", "price_changes": [{"asset_id": "99297111031951279105369527231196692827634634378016245082110314557578319128154", "price": "0.77", "size": "369", "side": "BUY", "hash": "0c4895fbc9d2857cc2e22f1b0396909c8a8947ab", "best_bid": "0.999", "best_ask": "1"}, {"asset_id": "89174380733589776741557368884298749975045965515062114405574362559487645447506", "price": "0.23", "size": "369", "side": "SELL", "hash": "824405895668fbf29a611da710692cc49ba616c6", "best_bid": "0", "best_ask": "0.001"}], "timestamp": "1769384467643", "event_type": "price_change"}}
{"_local_timestamp": "2026-01-25T23:41:07.762501+00:00", "data": {"market": "0x33cca535d0340264125e6d424c2b72a54fbf7bed77ea0e12618b2d2117fba8d2", "price_changes": [{"asset_id": "94933623159925613438322028509055338748965839910045279599576284066393667174618", "price": "0.77", "size": "369", "side": "BUY", "hash": "d7865a874bbd935d9cdcf2ee22721255dc680b74", "best_bid": "0.999", "best_ask": "1"}, {"asset_id": "66579638131066880161649101980342858689404800341486957072639169013202428010651", "price": "0.23", "size": "369", "side": "SELL", "hash": "506f803b0dd4fd46d2b2633faaf86bb15d93398c", "best_bid": "0", "best_ask": "0.001"}], "timestamp": "1769384467643", "event_type": "price_change"}}
{"_local_timestamp": "2026-01-25T23:41:07.763065+00:00", "data": {"market": "0xd3866b1b556fe5843dbf7a6517780211295ba024bb4a90a749531b1cfbf2ac20", "price_changes": [{"asset_id": "30947500130804640808249625202467513009782734777729829776701604345427228069664", "price": "0.771", "size": "309", "side": "BUY", "hash": "c030e894b5a76bcc34accf09b536644e18b9a02b", "best_bid": "0.999", "best_ask": "1"}, {"asset_id": "112914448831136287961641635085213918544450861148980379546124511283573338657686", "price": "0.229", "size": "309", "side": "SELL", "hash": "19c6d27dec1ac151d4d1194c5eb8d30941ce22bb", "best_bid": "0", "best_ask": "0.001"}], "timestamp": "1769384467643", "event_type": "price_change"}}
{"_local_timestamp": "2026-01-25T23:41:07.878202+00:00", "data": {"market": "0x5a3fd19d87709f84b93d3a71af7adaeca3f99cdfa2e1ba4a3ad256a6ddfb481b", "price_changes": [{"asset_id": "65953037871248164391818099564886117125781149283903860674544296582421226617357", "price": "0.987", "size": "6153", "side": "SELL", "hash": "47a836f6478d0a090f2ae9ad458edf4c9dc3f97a", "best_bid": "0", "best_ask": "0.001"}, {"asset_id": "58248314633586529362367123493139013590568973389535271143944925899040736147880", "price": "0.013", "size": "6153", "side": "BUY", "hash": "58814ab96e71d096c23e052dcbf0e3b5119ab3ec", "best_bid": "0.999", "best_ask": "1"}], "timestamp": "1769384467806", "event_type": "price_change"}}
{"_local_timestamp": "2026-01-25T23:41:07.897235+00:00", "data": {"market": "0x4748aea08c7479f93888e3c88574cc22f470db27586dddc3c389443aec89ff59", "price_changes": [{"asset_id": "83504158413192513722048719030445378881634624891122351294833041377392549555836", "price": "0.987", "size": "6153", "side": "SELL", "hash": "9e9503597779b796c845e13685b030340879073c", "best_bid": "0.001", "best_ask": "0.01"}, {"asset_id": "66589182701894097810798527186415708633655827134259434616730323536170342159606", "price": "0.013", "size": "6153", "side": "BUY", "hash": "6bceed115294f0ed5dcaeffa37cda29ac3b9bc5a", "best_bid": "0.99", "best_ask": "0.999"}], "timestamp": "1769384467806", "event_type": "price_change"}}
{"_local_timestamp": "2026-01-25T23:41:07.897987+00:00", "data": {"market": "0x1a20f34335d311c98347af3e47d637b5cbcb249f7dac1915d88c08d330e765d6", "price_changes": [{"asset_id": "55127205459841014452783599440229813013711949511338579686361956191876234776667", "price": "0.229", "size": "309", "side": "SELL", "hash": "a36e2866889d7e1469574ea4bbc1987a53809e57", "best_bid": "0", "best_ask": "0.001"}, {"asset_id": "51847501527474096557405943284662724691287223384062767234682532363137318024266", "price": "0.771", "size": "309", "side": "BUY", "hash": "ba1cdafdb7ef85fe88fd44be7fb692baca53a287", "best_bid": "0.999", "best_ask": "1"}], "timestamp": "1769384467806", "event_type": "price_change"}}
{"_local_timestamp": "2026-01-25T23:41:07.898623+00:00", "data": {"market": "0x204b14f24297c06aaa199dc1d8844bd1becc80bc07f6fca3c5b60e7578c9c201", "price_changes": [{"asset_id": "58553512085555920981275268565214845438113167009368856656814609879942308608483", "price": "0.229", "size": "309", "side": "SELL", "hash": "e63c7164018ade61ffd520d2fa39b9df06c6dbcb", "best_bid": "0", "best_ask": "0.001"}, {"asset_id": "102355609737505986959456016204459786144451240240244825770982312180145369373256", "price": "0.771", "size": "309", "side": "BUY", "hash": "f1c54ddde37fab6065922a9337b9d4a99dc3f84f", "best_bid": "0.999", "best_ask": "1"}], "timestamp": "1769384467806", "event_type": "price_change"}}
{"_local_timestamp": "2026-01-25T23:41:07.899185+00:00", "data": {"market": "0x8e32c847d8e5fc101cf164fa70dfcce2ef19fc9f4bba82a8a063fb1c25be8f66", "price_changes": [{"asset_id": "41617232520361893962087593588795705248847905449395592919411850737120322243726", "price": "0.229", "size": "309", "side": "SELL", "hash": "6910fd1bca8658b89c5fdde5069c36338763f760", "best_bid": "0", "best_ask": "0.001"}, {"asset_id": "85075037879085409153276428549450686728111630086931256613306885529883454175471", "price": "0.771", "size": "309", "side": "BUY", "hash": "481a301134a48946143ef5027d91dc7768c53cbc", "best_bid": "0.999", "best_ask": "1"}], "timestamp": "1769384467806", "event_type": "price_change"}}
{"_local_timestamp": "2026-01-25T23:41:07.899753+00:00", "data": {"market": "0x4c2b7eeab37dc3dbf56fb2a58451e7bf82c554a22e56ed048637c270340bb082", "price_changes": [{"asset_id": "73025139437582022870812618619686768740565683325010098372267219247119634794964", "price": "0.228", "size": "309", "side": "SELL", "hash": "4a22b87f3f6de6ae33985e09132acf57c8f15c12", "best_bid": "0", "best_ask": "0.005"}, {"asset_id": "69173073876652300953776803396376322172775215646460032389913013787125429776220", "price": "0.772", "size": "309", "side": "BUY", "hash": "59a348e75d0afc28a3e8c378105be8dfce0ec2f1", "best_bid": "0.995", "best_ask": "1"}], "timestamp": "1769384467806", "event_type": "price_change"}}
{"_local_timestamp": "2026-01-25T23:41:07.900338+00:00", "data": {"market": "0xd9b0fc72f38c908a5a7141420c06da580d01ed86c2ec38705ea15f72cb5e5e19", "price_changes": [{"asset_id": "57098020481919035618128472838337976081009168137472950524968489896877203309629", "price": "0.987", "size": "6153", "side": "SELL", "hash": "7ee20f8d2418eba8380ad807a8ed25ecab8200a6", "best_bid": "0", "best_ask": "0.001"}, {"asset_id": "51572238815890626847563912025595017507148782163592329862076559798897854761860", "price": "0.013", "size": "6153", "side": "BUY", "hash": "6ccb64218a714d2d32aeff6ecbb8d585a67b6ffd", "best_bid": "0.999", "best_ask": "1"}], "timestamp": "1769384467806", "event_type": "price_change"}}
{"_local_timestamp": "2026-01-25T23:41:07.900911+00:00", "data": {"market": "0xc509411ef133866e75fe61d20ea4ee7be70fcf00843fe605db1bb095a5862b15", "price_changes": [{"asset_id": "11750347072954117414759862893422867351489364626761446082158388065590872281535", "price": "0.228", "size": "309", "side": "SELL", "hash": "86d8ce8ae63b5227f54e8751d1812f20eb031f93", "best_bid": "0", "best_ask": "0.005"}, {"asset_id": "45555810545993612965430060201918590422740142498305025284246002991925909487625", "price": "0.772", "size": "309", "side": "BUY", "hash": "4830d2c3a783b1b87faab30409382c58bd5b9106", "best_bid": "0.995", "best_ask": "1"}], "timestamp": "1769384467806", "event_type": "price_change"}}
{"_local_timestamp": "2026-01-25T23:41:07.901468+00:00", "data": {"market": "0x3d0844ce16b86e66a126cfc7b6860f06b7e1d89f7c46f2730679c97b311a6946", "price_changes": [{"asset_id": "30140424268001367103070307735535434752966197427345930967528797587498602312567", "price": "0.228", "size": "309", "side": "SELL", "hash": "f1d3d350d4bb46e6c4a6d3bb288fd32c7899c236", "best_bid": "0", "best_ask": "0.005"}, {"asset_id": "64162699045912597255102549430256867196645669965426599877159267293140384494672", "price": "0.772", "size": "309", "side": "BUY", "hash": "fee5628cec41ea14e647e93de6516e8c86fd7331", "best_bid": "0.995", "best_ask": "1"}], "timestamp": "1769384467806", "event_type": "price_change"}}
{"_local_timestamp": "2026-01-25T23:41:07.902039+00:00", "data": {"market": "0x174f99617876ff89e3d88401a3e0bcb7e0ccc8f539f981603589b759ee1c986e", "price_changes": [{"asset_id": "48703479947195481706486691840615061336509417685157069361566374591350887277675", "price": "0.228", "size": "309", "side": "SELL", "hash": "6f3de3ccf5c54de999ea7a1772c88e8db96f99b8", "best_bid": "0", "best_ask": "0.009"}, {"asset_id": "8465468375968679168353185049278886271922501234385197733228896629886564398231", "price": "0.772", "size": "309", "side": "BUY", "hash": "adfe4736fda10da4bc9f1b01d031a1dead99aeaf", "best_bid": "0.991", "best_ask": "1"}], "timestamp": "1769384467806", "event_type": "price_change"}}
{"_local_timestamp": "2026-01-25T23:41:07.902611+00:00", "data": {"market": "0x9350615e9b70df65499ed381a555426151aa578b80c9755c1f516fc4e1c6f235", "price_changes": [{"asset_id": "11663191844619895104021077879042630369854320198358238010806010814420259499799", "price": "0.226", "size": "309", "side": "SELL", "hash": "d75def812ebc9d40651d2e1642508258220f4c6a", "best_bid": "0", "best_ask": "0.008"}, {"asset_id": "75560298592976643246574401702633222451038371118414162908867835243856309708656", "price": "0.774", "size": "309", "side": "BUY", "hash": "5fa6437afd0071611c49815c8e94005b2ea026b2", "best_bid": "0.992", "best_ask": "1"}], "timestamp": "1769384467806", "event_type": "price_change"}}
{"_local_timestamp": "2026-01-25T23:41:07.903325+00:00", "data": {"market": "0x00f131408059e28efe44b6975a5eff6a626a50b1ea117987b2a777f0c28ea352", "price_changes": [{"asset_id": "61431819519869665528604747494974593341766773949138777450330672465387185609856", "price": "0.229", "size": "309", "side": "SELL", "hash": "fa53eba7d9a540aadcb6e0787a7afb6365f51f78", "best_bid": "0", "best_ask": "0.001"}, {"asset_id": "97023203174986827040174699473138310071498195771105841874355416606377824157721", "price": "0.771", "size": "309", "side": "BUY", "hash": "8e851feff5d46ae884a2cc85bda6fcdeb4839215", "best_bid": "0.999", "best_ask": "1"}], "timestamp": "1769384467806", "event_type": "price_change"}}
{"_local_timestamp": "2026-01-25T23:41:07.903976+00:00", "data": {"market": "0x453f8479a041419e8f794d9f7149e4d95a3d315effa5d754fa0e303c83257140", "price_changes": [{"asset_id": "19192699567236935154412948133755984775559628536019255388694943247637117213140", "price": "0.228", "size": "309", "side": "SELL", "hash": "ccbe42be0bec4e78d8309accee5c5802547f972c", "best_bid": "0", "best_ask": "0.004"}, {"asset_id": "39365936570984542827431489666856672933613556292100829681088739787833575189466", "price": "0.772", "size": "309", "side": "BUY", "hash": "af746459ff68ba8c744b717649b2658100bb3edb", "best_bid": "0.996", "best_ask": "1"}], "timestamp": "1769384467806", "event_type": "price_change"}}
{"_local_timestamp": "2026-01-25T23:41:07.904965+00:00", "data": {"market": "0xd4e29ae9220207efbb9a6b10fe79d09dc21e0e6b15d7095289a8ca046a4977aa", "price_changes": [{"asset_id": "54581162693071710130485903923254363489511874058356442244838298018744580572687", "price": "0.229", "size": "309", "side": "SELL", "hash": "44b9146ddca3929af0e1f150ada858df39674788", "best_bid": "0", "best_ask": "0.001"}, {"asset_id": "50566369412855320406430637371866470227092223333450744138817186935756262630055", "price": "0.771", "size": "309", "side": "BUY", "hash": "0215b04e2f032a7fd20da7375e2821b5796f5c85", "best_bid": "0.999", "best_ask": "1"}], "timestamp": "1769384467806", "event_type": "price_change"}}
{"_local_timestamp": "2026-01-25T23:41:07.908180+00:00", "data": {"market": "0xafb15e731c59384c3d0cc49a5b10ca15478b5e1b3dc515ec78f90ce0c704d585", "price_changes": [{"asset_id": "19153094648738512033099285766555908783036763432962656196067038857357488238219", "price": "0.229", "size": "309", "side": "SELL", "hash": "0d04d4fb6b68ab61cd93d0e55c04bd76914fedde", "best_bid": "0", "best_ask": "0.001"}, {"asset_id": "27721477593921857597151286987191549878448898559962734579469006937396328767858", "price": "0.771", "size": "309", "side": "BUY", "hash": "540b37cfc7a2d1d55d46acc5fd1e741784e81eb2", "best_bid": "0.999", "best_ask": "1"}], "timestamp": "1769384467806", "event_type": "price_change"}}
{"_local_timestamp": "2026-01-25T23:41:07.945659+00:00", "data": {"market": "0x9350615e9b70df65499ed381a555426151aa578b80c9755c1f516fc4e1c6f235", "price_changes": [{"asset_id": "11663191844619895104021077879042630369854320198358238010806010814420259499799", "price": "0.225", "size": "5.47", "side": "SELL", "hash": "7ba689d10e96141381f2a57f8d8cc21613176e10", "best_bid": "0", "best_ask": "0.008"}, {"asset_id": "75560298592976643246574401702633222451038371118414162908867835243856309708656", "price": "0.775", "size": "5.47", "side": "BUY", "hash": "58ba96153698d3436398523818ab5a6d4e526168", "best_bid": "0.992", "best_ask": "1"}], "timestamp": "1769384467870", "event_type": "price_change"}}
{"_local_timestamp": "2026-01-25T23:41:07.946715+00:00", "data": {"market": "0xd4e29ae9220207efbb9a6b10fe79d09dc21e0e6b15d7095289a8ca046a4977aa", "price_changes": [{"asset_id": "54581162693071710130485903923254363489511874058356442244838298018744580572687", "price": "0.228", "size": "5.47", "side": "SELL", "hash": "c09efdcbc2f7e5d6ebbb8fe2b9f3293014ce5adb", "best_bid": "0", "best_ask": "0.001"}, {"asset_id": "50566369412855320406430637371866470227092223333450744138817186935756262630055", "price": "0.772", "size": "5.47", "side": "BUY", "hash": "5a7ec218d424728e5de80fffad54550494cb48c4", "best_bid": "0.999", "best_ask": "1"}], "timestamp": "1769384467871", "event_type": "price_change"}}
{"_local_timestamp": "2026-01-25T23:41:07.949704+00:00", "data": {"market": "0xc509411ef133866e75fe61d20ea4ee7be70fcf00843fe605db1bb095a5862b15", "price_changes": [{"asset_id": "11750347072954117414759862893422867351489364626761446082158388065590872281535", "price": "0.227", "size": "5.47", "side": "SELL", "hash": "4fc78c4f3605d7013b38d241be43c18bf0fd4987", "best_bid": "0", "best_ask": "0.005"}, {"asset_id": "45555810545993612965430060201918590422740142498305025284246002991925909487625", "price": "0.773", "size": "5.47", "side": "BUY", "hash": "117e4855576ae9e5cc125b12bacbd2c31c776c3a", "best_bid": "0.995", "best_ask": "1"}], "timestamp": "1769384467871", "event_type": "price_change"}}
{"_local_timestamp": "2026-01-25T23:41:07.978610+00:00", "data": {"market": "0x00f131408059e28efe44b6975a5eff6a626a50b1ea117987b2a777f0c28ea352", "price_changes": [{"asset_id": "61431819519869665528604747494974593341766773949138777450330672465387185609856", "price": "0.228", "size": "5.47", "side": "SELL", "hash": "f4c64aec96a2cde2837a4286be4652a4dde41793", "best_bid": "0", "best_ask": "0.001"}, {"asset_id": "97023203174986827040174699473138310071498195771105841874355416606377824157721", "price": "0.772", "size": "5.47", "side": "BUY", "hash": "21ac9c3da5c17900c2b5adcf3ff20d1209818e3e", "best_bid": "0.999", "best_ask": "1"}], "timestamp": "1769384467912", "event_type": "price_change"}}
{"_local_timestamp": "2026-01-25T23:41:07.979389+00:00", "data": {"market": "0x5a3fd19d87709f84b93d3a71af7adaeca3f99cdfa2e1ba4a3ad256a6ddfb481b", "price_changes": [{"asset_id": "65953037871248164391818099564886117125781149283903860674544296582421226617357", "price": "0.986", "size": "5.47", "side": "SELL", "hash": "3619b85db164d9106510e0c2b59bcc00cb6d81a3", "best_bid": "0", "best_ask": "0.001"}, {"asset_id": "58248314633586529362367123493139013590568973389535271143944925899040736147880", "price": "0.014", "size": "5.47", "side": "BUY", "hash": "24011282706b6214fd1d9cdfbef8446c0a6e0160", "best_bid": "0.999", "best_ask": "1"}], "timestamp": "1769384467912", "event_type": "price_change"}}
{"_local_timestamp": "2026-01-25T23:41:07.981681+00:00", "data": {"market": "0x174f99617876ff89e3d88401a3e0bcb7e0ccc8f539f981603589b759ee1c986e", "price_changes": [{"asset_id": "48703479947195481706486691840615061336509417685157069361566374591350887277675", "price": "0.227", "size": "5.47", "side": "SELL", "hash": "1c92dd3b868aac22d1618614c383597079c8da85", "best_bid": "0", "best_ask": "0.009"}, {"asset_id": "8465468375968679168353185049278886271922501234385197733228896629886564398231", "price": "0.773", "size": "5.47", "side": "BUY", "hash": "820c6bf65280d27c25879f25427564803289c3f6", "best_bid": "0.991", "best_ask": "1"}], "timestamp": "1769384467912", "event_type": "price_change"}}
{"_local_timestamp": "2026-01-25T23:41:07.982407+00:00", "data": {"market": "0xafb15e731c59384c3d0cc49a5b10ca15478b5e1b3dc515ec78f90ce0c704d585", "price_changes": [{"asset_id": "19153094648738512033099285766555908783036763432962656196067038857357488238219", "price": "0.228", "size": "5.47", "side": "SELL", "hash": "e7b73aadc5d6e1486e31204d2487c3bd10d52ab6", "best_bid": "0", "best_ask": "0.001"}, {"asset_id": "27721477593921857597151286987191549878448898559962734579469006937396328767858", "price": "0.772", "size": "5.47", "side": "BUY", "hash": "7a3ded0a58127b29f14c992e0c7adbf9c3606596", "best_bid": "0.999", "best_ask": "1"}], "timestamp": "1769384467912", "event_type": "price_change"}}
{"_local_timestamp": "2026-01-25T23:41:07.983022+00:00", "data": {"market": "0x4c2b7eeab37dc3dbf56fb2a58451e7bf82c554a22e56ed048637c270340bb082", "price_changes": [{"asset_id": "73025139437582022870812618619686768740565683325010098372267219247119634794964", "price": "0.227", "size": "5.47", "side": "SELL", "hash": "ba1089989fc73d5d09d367ded472b6f37d9d0970", "best_bid": "0", "best_ask": "0.005"}, {"asset_id": "69173073876652300953776803396376322172775215646460032389913013787125429776220", "price": "0.773", "size": "5.47", "side": "BUY", "hash": "538b4e2f3ad65a2cbbef980ab24e94dc0669ef6d", "best_bid": "0.995", "best_ask": "1"}], "timestamp": "1769384467912", "event_type": "price_change"}}
{"_local_timestamp": "2026-01-25T23:41:07.983637+00:00", "data": {"market": "0x453f8479a041419e8f794d9f7149e4d95a3d315effa5d754fa0e303c83257140", "price_changes": [{"asset_id": "19192699567236935154412948133755984775559628536019255388694943247637117213140", "price": "0.227", "size": "5.47", "side": "SELL", "hash": "9349af21be8e80a1c90244acfff85a942cd85f53", "best_bid": "0", "best_ask": "0.004"}, {"asset_id": "39365936570984542827431489666856672933613556292100829681088739787833575189466", "price": "0.773", "size": "5.47", "side": "BUY", "hash": "59c0473a098eaf2a40ae97b2213b18715cde9937", "best_bid": "0.996", "best_ask": "1"}], "timestamp": "1769384467912", "event_type": "price_change"}}
{"_local_timestamp": "2026-01-25T23:41:07.984252+00:00", "data": {"market": "0x3d0844ce16b86e66a126cfc7b6860f06b7e1d89f7c46f2730679c97b311a6946", "price_changes": [{"asset_id": "30140424268001367103070307735535434752966197427345930967528797587498602312567", "price": "0.227", "size": "5.47", "side": "SELL", "hash": "48b0adabb5b8ae8b8ddf3c5109ac8a2fc57aa4f2", "best_bid": "0", "best_ask": "0.005"}, {"asset_id": "64162699045912597255102549430256867196645669965426599877159267293140384494672", "price": "0.773", "size": "5.47", "side": "BUY", "hash": "eb64e8672dcdac78f2ea449b0f9a80eee161d4ae", "best_bid": "0.995", "best_ask": "1"}], "timestamp": "1769384467912", "event_type": "price_change"}}
{"_local_timestamp": "2026-01-25T23:41:07.984847+00:00", "data": {"market": "0x1a20f34335d311c98347af3e47d637b5cbcb249f7dac1915d88c08d330e765d6", "price_changes": [{"asset_id": "55127205459841014452783599440229813013711949511338579686361956191876234776667", "price": "0.228", "size": "5.47", "side": "SELL", "hash": "b1dcc10b11cbd7491cb47f0fdac0fdb89b0e725d", "best_bid": "0", "best_ask": "0.001"}, {"asset_id": "51847501527474096557405943284662724691287223384062767234682532363137318024266", "price": "0.772", "size": "5.47", "side": "BUY", "hash": "905f57e729f600f5b63390545ca1f8a6efa88d61", "best_bid": "0.999", "best_ask": "1"}], "timestamp": "1769384467912", "event_type": "price_change"}}
{"_local_timestamp": "2026-01-25T23:41:07.985918+00:00", "data": {"market": "0x204b14f24297c06aaa199dc1d8844bd1becc80bc07f6fca3c5b60e7578c9c201", "price_changes": [{"asset_id": "58553512085555920981275268565214845438113167009368856656814609879942308608483", "price": "0.228", "size": "5.47", "side": "SELL", "hash": "7708e0b226117b591f1bc86a8fa9d11e38a1025a", "best_bid": "0", "best_ask": "0.001"}, {"asset_id": "102355609737505986959456016204459786144451240240244825770982312180145369373256", "price": "0.772", "size": "5.47", "side": "BUY", "hash": "b2ce2581fba0e01268ff89ea61a86077a84b05a1", "best_bid": "0.999", "best_ask": "1"}], "timestamp": "1769384467912", "event_type": "price_change"}}
{"_local_timestamp": "2026-01-25T23:41:07.986628+00:00", "data": {"market": "0x8e32c847d8e5fc101cf164fa70dfcce2ef19fc9f4bba82a8a063fb1c25be8f66", "price_changes": [{"asset_id": "41617232520361893962087593588795705248847905449395592919411850737120322243726", "price": "0.228", "size": "5.47", "side": "SELL", "hash": "e75f29e5f068aa574ae982b2627b0b35cb845ca0", "best_bid": "0", "best_ask": "0.001"}, {"asset_id": "85075037879085409153276428549450686728111630086931256613306885529883454175471", "price": "0.772", "size": "5.47", "side": "BUY", "hash": "38dc73bcd090cc2564aebbc0e057ef3b7c5c134f", "best_bid": "0.999", "best_ask": "1"}], "timestamp": "1769384467912", "event_type": "price_change"}}
{"_local_timestamp": "2026-01-25T23:41:08.031260+00:00", "data": {"market": "0xd9b0fc72f38c908a5a7141420c06da580d01ed86c2ec38705ea15f72cb5e5e19", "price_changes": [{"asset_id": "57098020481919035618128472838337976081009168137472950524968489896877203309629", "price": "0.986", "size": "5", "side": "SELL", "hash": "e3a8275e4a58225bc8460bf646c48aa586d667f1", "best_bid": "0", "best_ask": "0.001"}, {"asset_id": "51572238815890626847563912025595017507148782163592329862076559798897854761860", "price": "0.014", "size": "5", "side": "BUY", "hash": "5b07d6f86bc8b804f6bb40b1c4f895392f3e3ba6", "best_bid": "0.999", "best_ask": "1"}], "timestamp": "1769384467960", "event_type": "price_change"}}
{"_local_timestamp": "2026-01-25T23:41:08.032087+00:00", "data": {"market": "0x4748aea08c7479f93888e3c88574cc22f470db27586dddc3c389443aec89ff59", "price_changes": [{"asset_id": "83504158413192513722048719030445378881634624891122351294833041377392549555836", "price": "0.986", "size": "5.47", "side": "SELL", "hash": "386dbf5807eea361a89f3622a42925929d90e173", "best_bid": "0.001", "best_ask": "0.01"}, {"asset_id": "66589182701894097810798527186415708633655827134259434616730323536170342159606", "price": "0.014", "size": "5.47", "side": "BUY", "hash": "9fc6d9db9dcb36f0db857973b411411ee1a11138", "best_bid": "0.99", "best_ask": "0.999"}], "timestamp": "1769384467960", "event_type": "price_change"}}
{"_local_timestamp": "2026-01-25T23:41:08.066893+00:00", "data": {"market": "0xfb0f4ac0b68e94aedc1214a03cbe9c723feebf9d3a55777fe2b05b8feb66a11c", "price_changes": [{"asset_id": "55426209889638974733753071618642569441373076860672244339538811630049825345670", "price": "0.011", "size": "0", "side": "BUY", "hash": "b3f835e23064b702897506eb74b3b4f366e47a39", "best_bid": "0.99", "best_ask": "0.999"}, {"asset_id": "43959289417856840840427763184407307972480869140742194070396563955715812876628", "price": "0.989", "size": "0", "side": "SELL", "hash": "e96fab79a917f2fc5d6461e8b4f3dc556b08efc7", "best_bid": "0.001", "best_ask": "0.01"}], "timestamp": "1769384468000", "event_type": "price_change"}}
{"_local_timestamp": "2026-01-25T23:41:08.067704+00:00", "data": {"market": "0xb8b7c370c01d589e56de7431e78203839a6054489e2049c444b97a24cad3be11", "price_changes": [{"asset_id": "28849374540506943880982554114742096039302062713864319348646490583409276747173", "price": "0.116", "size": "0", "side": "BUY", "hash": "adda8eb4bb1f7ef5570359e69829da9507264676", "best_bid": "0.999", "best_ask": "1"}, {"asset_id": "83592981020384399234305075593225008895851215579831739799641923332818184660225", "price": "0.884", "size": "0", "side": "SELL", "hash": "607f6c687707a3ce77fe166d7e27d05628fab081", "best_bid": "0", "best_ask": "0.001"}], "timestamp": "1769384468000", "event_type": "price_change"}}
{"_local_timestamp": "2026-01-25T23:41:08.068362+00:00", "data": {"market": "0xec0af11a54f5f6205317897289e191394795cd7f35b76a1cb902006e4a505352", "price_changes": [{"asset_id": "88403256582890565589272354714319570649971420555579995262370758371602376328234", "price": "0.141", "size": "0", "side": "BUY", "hash": "574f7a98be3b93649baac3c195bca65676358cf0", "best_bid": "0.999", "best_ask": "1"}, {"asset_id": "83902666523488757660408005544769162912726010224373037612352316388014236164604", "price": "0.859", "size": "0", "side": "SELL", "hash": "c148243f6716726dc4c6d855bca5db30005afa02", "best_bid": "0", "best_ask": "0.001"}], "timestamp": "1769384468000", "event_type": "price_change"}}
{"_local_timestamp": "2026-01-25T23:41:08.069006+00:00", "data": {"market": "0x24d4c6ac79205728202e8f7c87fce23e394fcd425e2442081f975c02e14c20be", "price_changes": [{"asset_id": "3416966364373630870081312389812029383875790961501880158985109393879810083440", "price": "0.142", "size": "50", "side": "BUY", "hash": "89cc1ebae875e347cf02f79a26c49772b9b462c0", "best_bid": "0.995", "best_ask": "1"}, {"asset_id": "111358084047172002584440472770888660450582020066278598324688081719481646394656", "price": "0.858", "size": "50", "side": "SELL", "hash": "6355551b13d6d11c9ac9144ca720c0c304583ec8", "best_bid": "0", "best_ask": "0.005"}], "timestamp": "1769384468000", "event_type": "price_change"}}
{"_local_timestamp": "2026-01-25T23:41:08.114574+00:00", "data": {"market": "0x9350615e9b70df65499ed381a555426151aa578b80c9755c1f516fc4e1c6f235", "price_changes": [{"asset_id": "75560298592976643246574401702633222451038371118414162908867835243856309708656", "price": "0.111", "size": "0", "side": "BUY", "hash": "36d2c319b36731c5c22532dbde365c9c3141c363", "best_bid": "0.992", "best_ask": "1"}, {"asset_id": "11663191844619895104021077879042630369854320198358238010806010814420259499799", "price": "0.889", "size": "0", "side": "SELL", "hash": "9adfa300072a0063dfb65f52e2a9e47ff4a7a689", "best_bid": "0", "best_ask": "0.008"}], "timestamp": "1769384468000", "event_type": "price_change"}}
{"_local_timestamp": "2026-01-25T23:41:08.139254+00:00", "data": {"market": "0xd9b0fc72f38c908a5a7141420c06da580d01ed86c2ec38705ea15f72cb5e5e19", "price_changes": [{"asset_id": "51572238815890626847563912025595017507148782163592329862076559798897854761860", "price": "0.012", "size": "0", "side": "BUY", "hash": "d1156b32f21c9b8baf8a8ad4d79253d9addb0a9b", "best_bid": "0.999", "best_ask": "1"}, {"asset_id": "57098020481919035618128472838337976081009168137472950524968489896877203309629", "price": "0.988", "size": "0", "side": "SELL", "hash": "9b3f718db317c3ed46edaafaa183209b0595d560", "best_bid": "0", "best_ask": "0.001"}], "timestamp": "1769384468000", "event_type": "price_change"}}
{"_local_timestamp": "2026-01-25T23:41:08.140125+00:00", "data": {"market": "0xce44cece516669135071d3bae72fc4f5f365322a1d5005949dfc86be9be420da", "price_changes": [{"asset_id": "53974558442829387376541849493942578943658081612178694724995455494917931103192", "price": "0.112", "size": "0", "side": "BUY", "hash": "2fed7d00a14fa0ed9dd2c0ed977f6696b9502306", "best_bid": "0.999", "best_ask": "1"}, {"asset_id": "76014602550800947248168109629242500597255611883184659688735188973598896781240", "price": "0.888", "size": "0", "side": "SELL", "hash": "4cbf1e8721e4f3f1b0fffd727f83897908f741fb", "best_bid": "0", "best_ask": "0.001"}], "timestamp": "1769384468000", "event_type": "price_change"}}
{"_local_timestamp": "2026-01-25T23:41:08.140798+00:00", "data": {"market": "0xbcdc50ca134fca43e2ff92b1d4eb74d1370ee70226edaff6ed2e66eded7c4f17", "price_changes": [{"asset_id": "5574857600587711269700129730512235249359616543972163182547512086378810357379", "price": "0.012", "size": "0", "side": "BUY", "hash": "11e6c819300025a21b5e83bcfde852d6518fa8b1", "best_bid": "0.999", "best_ask": "1"}, {"asset_id": "34715175763796870678361611735891885650420703648689314817663953704466610666238", "price": "0.988", "size": "0", "side": "SELL", "hash": "1bfcea8579d7be702f814732e6e90b3370127225", "best_bid": "0", "best_ask": "0.001"}], "timestamp": "1769384468000", "event_type": "price_change"}}
{"_local_timestamp": "2026-01-25T23:41:08.141450+00:00", "data": {"market": "0x4748aea08c7479f93888e3c88574cc22f470db27586dddc3c389443aec89ff59", "price_changes": [{"asset_id": "66589182701894097810798527186415708633655827134259434616730323536170342159606", "price": "0.012", "size": "0", "side": "BUY", "hash": "36765b84dfcca821663730d9671fff836cc2bf3b", "best_bid": "0.99", "best_ask": "0.999"}, {"asset_id": "83504158413192513722048719030445378881634624891122351294833041377392549555836", "price": "0.988", "size": "0", "side": "SELL", "hash": "c9f4636554bd48f6dc5c45778cda676f12861b80", "best_bid": "0.001", "best_ask": "0.01"}], "timestamp": "1769384468000", "event_type": "price_change"}}
{"_local_timestamp": "2026-01-25T23:41:08.142095+00:00", "data": {"market": "0x4c2b7eeab37dc3dbf56fb2a58451e7bf82c554a22e56ed048637c270340bb082", "price_changes": [{"asset_id": "69173073876652300953776803396376322172775215646460032389913013787125429776220", "price": "0.118", "size": "0", "side": "BUY", "hash": "dd7c78c67ed1444cb408c7b9c4217b0b12ae8eb9", "best_bid": "0.995", "best_ask": "1"}, {"asset_id": "73025139437582022870812618619686768740565683325010098372267219247119634794964", "price": "0.882", "size": "0", "side": "SELL", "hash": "ce66be54e8c22b183b89af133dfeb43cf8a1845f", "best_bid": "0", "best_ask": "0.005"}], "timestamp": "1769384468000", "event_type": "price_change"}}
{"_local_timestamp": "2026-01-25T23:41:08.142730+00:00", "data": {"market": "0x88c159de04783ed9846a8dcb03fa330754e46e61564059cc81acb25932710b46", "price_changes": [{"asset_id": "26962425957446230275275597334954929477143782773021571348663069985031678553413", "price": "0.116", "size": "0", "side": "BUY", "hash": "44a8c44e981ece683ca31ae13b7a140a111b4804", "best_bid": "0.991", "best_ask": "1"}, {"asset_id": "8459072361983769420511248215510567919570934744639447022627913477245830483592", "price": "0.884", "size": "0", "side": "SELL", "hash": "a4781595914914648fc2be5c617fe68716d2fa34", "best_bid": "0", "best_ask": "0.009"}], "timestamp": "1769384468000", "event_type": "price_change"}}
{"_local_timestamp": "2026-01-25T23:41:08.143370+00:00", "data": {"market": "0x717fb00a39a3c4cec6cc728168c3fce6e3035d8ed930aecfc6f343564b16a788", "price_changes": [{"asset_id": "60119374126653128719260895844622062846381272599857895156246552575227623552241", "price": "0.011", "size": "0", "side": "BUY", "hash": "03328fe518ccff482b898475b39933760f4a5fff", "best_bid": "0.99", "best_ask": "0.999"}, {"asset_id": "49177293917175339908646266682490527167418532793156915271748070003785027932027", "price": "0.989", "size": "0", "side": "SELL", "hash": "d3c7378f5b5401802a835b8a802a9d77c2f1e8c8", "best_bid": "0.001", "best_ask": "0.01"}], "timestamp": "1769384468000", "event_type": "price_change"}}
{"_local_timestamp": "2026-01-25T23:41:08.144009+00:00", "data": {"market": "0xf2d6a296447b45978757a49d4b469c2de8f65911bcec656c46e61d79e5b0ec02", "price_changes": [{"asset_id": "7748216705460976435623561406129775099072355727261540349420629705624956570226", "price": "0.114", "size": "0", "side": "BUY", "hash": "1eda84f4da03fb196e02432c50293bd99fb93f5e", "best_bid": "0.991", "best_ask": "1"}, {"asset_id": "97497637738863159234810323045630267886627719917222933191405894986155355727361", "price": "0.886", "size": "0", "side": "SELL", "hash": "2020633ba4e4acade439b289c6376b950c7459fa", "best_bid": "0", "best_ask": "0.009"}], "timestamp": "1769384468000", "event_type": "price_change"}}
{"_local_timestamp": "2026-01-25T23:41:08.144645+00:00", "data": {"market": "0xc0b3638a969d1b4a2c2c8b9ff3dda8765f5e0dfb1f1669d3223a7d0764ba1808", "price_changes": [{"asset_id": "79078096109886043971078249449586427255424561324464046969686459745648521830395", "price": "0.141", "size": "0", "side": "BUY", "hash": "48c9a421812317ff662ff22f3ce793b760337977", "best_bid": "0.999", "best_ask": "1"}, {"asset_id": "71287787540221311833143710317668754611438884018424897811637563407660610591090", "price": "0.859", "size": "0", "side": "SELL", "hash": "6613cfdffec842e49ab3bf5edf7497fda4e1f7ee", "best_bid": "0", "best_ask": "0.001"}], "timestamp": "1769384468000", "event_type": "price_change"}}
{"_local_timestamp": "2026-01-25T23:41:08.145286+00:00", "data": {"market": "0xfd4c8249183b221b97b519bbbc40ccad67df85fdf5accd82b5776a795e437c6b", "price_changes": [{"asset_id": "17874277896927531123551458106581405508715609873461214308237688268056733842058", "price": "0.05", "size": "0", "side": "BUY", "hash": "afc29f36a5ecb93e6b81f28220bcc514fe4a4ac8", "best_bid": "0.61", "best_ask": "1"}, {"asset_id": "8963298533671687804870085262130769994356887438237727171798917958022949375208", "price": "0.95", "size": "0", "side": "SELL", "hash": "69c83ee6895df04ea7111f322bfd57e5b64d2efe", "best_bid": "0", "best_ask": "0.39"}], "timestamp": "1769384468000", "event_type": "price_change"}}
{"_local_timestamp": "2026-01-25T23:41:08.145920+00:00", "data": {"market": "0xffc02802851ddf3857633aef0f1146e641f16279ef1a91de899500e3f1642956", "price_changes": [{"asset_id": "83868310274258098937534955108180906010340820748057057072512945569667612470884", "price": "0.111", "size": "0", "side": "BUY", "hash": "9bcf3032559f240f2d6ea8246d51e08f1c1479cc", "best_bid": "0.991", "best_ask": "1"}, {"asset_id": "58246546221470895651705696424054214777798759824740890223804348498573359454874", "price": "0.889", "size": "0", "side": "SELL", "hash": "f53c70f7e74f935b2ba5da4aa612ac4388f977ec", "best_bid": "0", "best_ask": "0.009"}], "timestamp": "1769384468000", "event_type": "price_change"}}
{"_local_timestamp": "2026-01-25T23:41:08.146566+00:00", "data": {"market": "0x3a95272be7d95e8145bd957fae244f214b60a62fd948062f776282c2d2bdb9c8", "price_changes": [{"asset_id": "94570884678709009503382566813899043832638397291612895561327288355956778233951", "price": "0.012", "size": "0", "side": "BUY", "hash": "9a2ef8042d8005b0803e50580eefacb494673e2d", "best_bid": "0.999", "best_ask": "1"}, {"asset_id": "34429579477292779051220305424595648879239634505793752749749838360409422364039", "price": "0.988", "size": "0", "side": "SELL", "hash": "4118d6c08c3ea91f62e6203ea064593b63ce4902", "best_bid": "0", "best_ask": "0.001"}], "timestamp": "1769384468001", "event_type": "price_change"}}
{"_local_timestamp": "2026-01-25T23:41:08.147217+00:00", "data": {"market": "0x76f7c3b2f193044a7891883f044da641b75b078197b3d214b1cef235c8b771e1", "price_changes": [{"asset_id": "56082532738175047478011286938051439618844073329646641418943392710720146125419", "price": "0.036", "size": "0", "side": "BUY", "hash": "24713138f0ecf64d000851350a1cc32fc03f3102", "best_bid": "0.999", "best_ask": "1"}, {"asset_id": "83705947662071625507322075497208006707849354374430230873246504758105177021022", "price": "0.964", "size": "0", "side": "SELL", "hash": "f96c96c3e65e292993611a26e3bf6a61d0acba49", "best_bid": "0", "best_ask": "0.001"}], "timestamp": "1769384468001", "event_type": "price_change"}}
{"_local_timestamp": "2026-01-25T23:41:08.147856+00:00", "data": {"market": "0x204b14f24297c06aaa199dc1d8844bd1becc80bc07f6fca3c5b60e7578c9c201", "price_changes": [{"asset_id": "102355609737505986959456016204459786144451240240244825770982312180145369373256", "price": "0.141", "size": "0", "side": "BUY", "hash": "803d2f990c86303c6e3208645a5fe2c4f0a7f544", "best_bid": "0.999", "best_ask": "1"}, {"asset_id": "58553512085555920981275268565214845438113167009368856656814609879942308608483", "price": "0.859", "size": "0", "side": "SELL", "hash": "c84bf43ae1bac46392a141f3806eb7dc6297a511", "best_bid": "0", "best_ask": "0.001"}], "timestamp": "1769384468000", "event_type": "price_change"}}
{"_local_timestamp": "2026-01-25T23:41:08.148513+00:00", "data": {"market": "0xf1ce664701af71aac63156b3b4fa25a67eb79c29810953512e9724d577053bb2", "price_changes": [{"asset_id": "39778100528521559320073842412769877439422950815300994587540677860951543138758", "price": "0.141", "size": "0", "side": "BUY", "hash": "ec91cfaa3ce21eb425cd461219166bba054869e0", "best_bid": "0.995", "best_ask": "1"}, {"asset_id": "74880017248043009869759184047952705769556168918768905724786540599437534359659", "price": "0.859", "size": "0", "side": "SELL", "hash": "35e079e95aabed6ed9bcef319ef9848cc2eb43dd", "best_bid": "0", "best_ask": "0.005"}], "timestamp": "1769384468001", "event_type": "price_change"}}
{"_local_timestamp": "2026-01-25T23:41:08.149164+00:00", "data": {"market": "0x462bb7daa3b0906569beaf26fe722dd2b742cdaaca0900c3aa710a9e8e418f15", "price_changes": [{"asset_id": "84426700624131057289025898608787752028694418359354475239466346481861071213446", "price": "0.09", "size": "100", "side": "BUY", "hash": "8d484ac1800887962e0d3c98e6510f84f9718b49", "best_bid": "0.49", "best_ask": "0.51"}, {"asset_id": "109631748687541424858485727517534723373639840024430532350488906491941213609965", "price": "0.91", "size": "100", "side": "SELL", "hash": "5fe61b148e240210993e34b3835f68fc128bd6da", "best_bid": "0.49", "best_ask": "0.51"}], "timestamp": "1769384468001", "event_type": "price_change"}}
{"_local_timestamp": "2026-01-25T23:41:08.149812+00:00", "data": {"market": "0x84e5a3986fbc3fee389ed87a4f070df7478c78953a4e0ac8fcefb9cf1f7d4a90", "price_changes": [{"asset_id": "1834143411676190819902614191475506377009972301852369769871635548739845748032", "price": "0.112", "size": "0", "side": "BUY", "hash": "0433e0aaa23c7b0e8816d9d3831db260ff2ab795", "best_bid": "0.991", "best_ask": "1"}, {"asset_id": "29432070850069872970940163971322046452677105415473389882122736983204650720097", "price": "0.888", "size": "0", "side": "SELL", "hash": "09ccdb0905474dafaea4ca401339ef46d71aaa54", "best_bid": "0", "best_ask": "0.009"}], "timestamp": "1769384468000", "event_type": "price_change"}}
{"_local_timestamp": "2026-01-25T23:41:08.150449+00:00", "data": {"market": "0x6c368d16e4ac2cdc06d087eb5e1678ea5440c4b42e02fd337fe63da0aeaf8f1e", "price_changes": [{"asset_id": "25574953065128994069638517886303382281906451104860620707001535186471690862311", "price": "0.011", "size": "0", "side": "BUY", "hash": "a07ea2ac2466315d4805de4a91d14aaa4989c913", "best_bid": "0.99", "best_ask": "0.999"}, {"asset_id": "82367807427516865349185391674760284005869010126029029189020727017640887348967", "price": "0.989", "size": "0", "side": "SELL", "hash": "a3639d88bf22beb13d9a83ad621124bae25274ee", "best_bid": "0.001", "best_ask": "0.01"}], "timestamp": "1769384468001", "event_type": "price_change"}}
{"_local_timestamp": "2026-01-25T23:41:08.151078+00:00", "data": {"market": "0xd5fb790e70d3ad1769f40ef70f55233cc6098ac83423c160dcd16f0278199c0d", "price_changes": [{"asset_id": "38669595393479333756794564935772837388967649329391357690872871259908868669902", "price": "0.112", "size": "0", "side": "BUY", "hash": "21e0af17835f9bfb37948949769e3b6147371e87", "best_bid": "0.991", "best_ask": "1"}, {"asset_id": "67683893917838442286608716085337607998088783731863722223710730122730169958578", "price": "0.888", "size": "0", "side": "SELL", "hash": "19646876e6ab84473a3b07ac88c2b2ae036356db", "best_bid": "0", "best_ask": "0.009"}], "timestamp": "1769384468000", "event_type": "price_change"}}
{"_local_timestamp": "2026-01-25T23:41:08.151736+00:00", "data": {"market": "0x00f131408059e28efe44b6975a5eff6a626a50b1ea117987b2a777f0c28ea352", "price_changes": [{"asset_id": "97023203174986827040174699473138310071498195771105841874355416606377824157721", "price": "0.112", "size": "0", "side": "BUY", "hash": "731bdfa762f18d59fcbd8d5904a35d33d85ba7f0", "best_bid": "0.999", "best_ask": "1"}, {"asset_id": "61431819519869665528604747494974593341766773949138777450330672465387185609856", "price": "0.888", "size": "0", "side": "SELL", "hash": "e1820a483240009c1c0b375fc041ea5d361747b7", "best_bid": "0", "best_ask": "0.001"}], "timestamp": "1769384468001", "event_type": "price_change"}}
{"_local_timestamp": "2026-01-25T23:41:08.152407+00:00", "data": {"market": "0xdc9d3b6adb4ec1d0bd24409bac6537f979720fd2d540e04ce9a5223bf42b9aa6", "price_changes": [{"asset_id": "69658209478973033181726587560985982613825739930726601099487874533280680791418", "price": "0.141", "size": "0", "side": "BUY", "hash": "cbe60414805cee154d0d515cc13abd595cee108f", "best_bid": "0.999", "best_ask": "1"}, {"asset_id": "96910445513992308799227995027211940876785078628341868853241341912618720742656", "price": "0.859", "size": "0", "side": "SELL", "hash": "d74f15f63049b9dd0f3984b7048c38956f704d23", "best_bid": "0", "best_ask": "0.001"}], "timestamp": "1769384468001", "event_type": "price_change"}}
{"_local_timestamp": "2026-01-25T23:41:08.153129+00:00", "data": {"market": "0x8e32c847d8e5fc101cf164fa70dfcce2ef19fc9f4bba82a8a063fb1c25be8f66", "price_changes": [{"asset_id": "85075037879085409153276428549450686728111630086931256613306885529883454175471", "price": "0.141", "size": "0", "side": "BUY", "hash": "e51db80fbb833ff0e6842571bb0d9398fce3409f", "best_bid": "0.999", "best_ask": "1"}, {"asset_id": "41617232520361893962087593588795705248847905449395592919411850737120322243726", "price": "0.859", "size": "0", "side": "SELL", "hash": "56113ea103a1ddac3778d47627471200e343c1c6", "best_bid": "0", "best_ask": "0.001"}], "timestamp": "1769384468001", "event_type": "price_change"}}
{"_local_timestamp": "2026-01-25T23:41:08.153835+00:00", "data": {"market": "0x1b130b268df56e4802707e2ec9b5c2929b51222d2d0a19af03516e2b960de26a", "price_changes": [{"asset_id": "77018818557373862304084960921215808370283364442421773897574584607622496684030", "price": "0.141", "size": "0", "side": "BUY", "hash": "cc96b38567452b3dee62a8254d28fdf5bd675667", "best_bid": "0.999", "best_ask": "1"}, {"asset_id": "72797979972272034635860920395196865314139391915868888486424461493808639864972", "price": "0.859", "size": "0", "side": "SELL", "hash": "cf2e3057d54b412fe2461a9e5d52dbb9815a6039", "best_bid": "0", "best_ask": "0.001"}], "timestamp": "1769384468001", "event_type": "price_change"}}
{"_local_timestamp": "2026-01-25T23:41:08.154550+00:00", "data": {"market": "0xfb36b9f2ce0d23b0f82b4ecb696d8c837b70a33c185cacab2d01b03c008bdaa5", "price_changes": [{"asset_id": "81287387146750561505580355482640926212406745446474340005282467156958865823238", "price": "0.118", "size": "0", "side": "BUY", "hash": "b7962cf4902ed2c150e655b77b2ea16dafa5b5f0", "best_bid": "0.991", "best_ask": "1"}, {"asset_id": "32119105197847901346777680653737019062753278665429569684663596053648338847292", "price": "0.882", "size": "0", "side": "SELL", "hash": "f22b7914afd17d99ba9d0c6f391c37f555e5db88", "best_bid": "0", "best_ask": "0.009"}], "timestamp": "1769384468001", "event_type": "price_change"}}
{"_local_timestamp": "2026-01-25T23:41:08.155436+00:00", "data": {"market": "0x174f99617876ff89e3d88401a3e0bcb7e0ccc8f539f981603589b759ee1c986e", "price_changes": [{"asset_id": "8465468375968679168353185049278886271922501234385197733228896629886564398231", "price": "0.112", "size": "0", "side": "BUY", "hash": "e00099c2db877bc50f19058331aa8133686dee7a", "best_bid": "0.991", "best_ask": "1"}, {"asset_id": "48703479947195481706486691840615061336509417685157069361566374591350887277675", "price": "0.888", "size": "0", "side": "SELL", "hash": "6f8706118efaf0a21801138cbc4c8c31246907cc", "best_bid": "0", "best_ask": "0.009"}], "timestamp": "1769384468001", "event_type": "price_change"}}
{"_local_timestamp": "2026-01-25T23:41:08.156144+00:00", "data": {"market": "0x5a3fd19d87709f84b93d3a71af7adaeca3f99cdfa2e1ba4a3ad256a6ddfb481b", "price_changes": [{"asset_id": "58248314633586529362367123493139013590568973389535271143944925899040736147880", "price": "0.012", "size": "0", "side": "BUY", "hash": "af78b4acd1f70400044b48265d2acb92e0ddd997", "best_bid": "0.999", "best_ask": "1"}, {"asset_id": "65953037871248164391818099564886117125781149283903860674544296582421226617357", "price": "0.988", "size": "0", "side": "SELL", "hash": "28ae6c68af19c78a211471d6020aef862d389e85", "best_bid": "0", "best_ask": "0.001"}], "timestamp": "1769384468002", "event_type": "price_change"}}
{"_local_timestamp": "2026-01-25T23:41:08.156843+00:00", "data": {"market": "0xcba6d744bd14bb788690a3479acf192ed35f44241c30820efc642d6720703a01", "price_changes": [{"asset_id": "109228675712804150419254959603454060015458251960061436438701346753980946344788", "price": "0.118", "size": "0", "side": "BUY", "hash": "724859e616e0f0ae3908b047e6be493115807d61", "best_bid": "0.999", "best_ask": "1"}, {"asset_id": "64735823985571109441321290529333378978050160684601981636835688716014717666867", "price": "0.882", "size": "0", "side": "SELL", "hash": "d4f57e896843d8ab03b8695e80db3be994fd631d", "best_bid": "0", "best_ask": "0.001"}], "timestamp": "1769384468001", "event_type": "price_change"}}
{"_local_timestamp": "2026-01-25T23:41:08.157554+00:00", "data": {"market": "0x462bb7daa3b0906569beaf26fe722dd2b742cdaaca0900c3aa710a9e8e418f15", "price_changes": [{"asset_id": "109631748687541424858485727517534723373639840024430532350488906491941213609965", "price": "0.09", "size": "100", "side": "BUY", "hash": "f90b8e19736f073dc1aba71b6b72781d927139c6", "best_bid": "0.49", "best_ask": "0.51"}, {"asset_id": "84426700624131057289025898608787752028694418359354475239466346481861071213446", "price": "0.91", "size": "100", "side": "SELL", "hash": "8121a8a2f6e285c55ec25f2fa24e63c2659e38ca", "best_bid": "0.49", "best_ask": "0.51"}], "timestamp": "1769384468002", "event_type": "price_change"}}
{"_local_timestamp": "2026-01-25T23:41:08.158241+00:00", "data": {"market": "0xc0d7f7796a0cac90cb70c79845db9d226ed35959bd0aa35af7fb418f3f2e22e5", "price_changes": [{"asset_id": "12543330728269567640220567011294079896273543850192586290021550850906815833169", "price": "0.141", "size": "0", "side": "BUY", "hash": "36b27431327438ccc619fe16071b5b7b596b8db0", "best_bid": "0.999", "best_ask": "1"}, {"asset_id": "10008028422703392249749236854165253701939526137534166171302431408077717628002", "price": "0.859", "size": "0", "side": "SELL", "hash": "36ce36dbe239dbce45c183ea26cd0c95b825e324", "best_bid": "0", "best_ask": "0.001"}], "timestamp": "1769384468000", "event_type": "price_change"}}
{"_local_timestamp": "2026-01-25T23:41:08.159206+00:00", "data": {"market": "0x5c5933ee7d871e48d1a120122ffee0fd57f2a547109c226bf75d12a2d3905e1e", "price_changes": [{"asset_id": "39445779384581598316851917827889246832002643510245720484561264580818170018041", "price": "0.141", "size": "0", "side": "BUY", "hash": "2e8d5b837b3f7d8c90610b48bba6c060147e40c4", "best_bid": "0.999", "best_ask": "1"}, {"asset_id": "31450040692827736276733070952336677024248005125940001939196013706836154165101", "price": "0.859", "size": "0", "side": "SELL", "hash": "3e13f6e18d054a9c2c44e0734e9f0bc4bf253146", "best_bid": "0", "best_ask": "0.001"}], "timestamp": "1769384468001", "event_type": "price_change"}}
{"_local_timestamp": "2026-01-25T23:41:08.159964+00:00", "data": {"market": "0x33cca535d0340264125e6d424c2b72a54fbf7bed77ea0e12618b2d2117fba8d2", "price_changes": [{"asset_id": "94933623159925613438322028509055338748965839910045279599576284066393667174618", "price": "0.116", "size": "0", "side": "BUY", "hash": "15a4a974019a04ea9a7e7e5ea6b988f512420640", "best_bid": "0.999", "best_ask": "1"}, {"asset_id": "66579638131066880161649101980342858689404800341486957072639169013202428010651", "price": "0.884", "size": "0", "side": "SELL", "hash": "822f1f56ea73c60648a3289150630d3c9f04c8c4", "best_bid": "0", "best_ask": "0.001"}], "timestamp": "1769384468002", "event_type": "price_change"}}
{"_local_timestamp": "2026-01-25T23:41:08.160672+00:00", "data": {"market": "0xd4e29ae9220207efbb9a6b10fe79d09dc21e0e6b15d7095289a8ca046a4977aa", "price_changes": [{"asset_id": "50566369412855320406430637371866470227092223333450744138817186935756262630055", "price": "0.141", "size": "0", "side": "BUY", "hash": "ac839dc1107cba1739b72aad98f9ac6ff3bb6ce4", "best_bid": "0.999", "best_ask": "1"}, {"asset_id": "54581162693071710130485903923254363489511874058356442244838298018744580572687", "price": "0.859", "size": "0", "side": "SELL", "hash": "c292eb1d6d7c1564a0977f528d4bbaa632451707", "best_bid": "0", "best_ask": "0.001"}], "timestamp": "1769384468001", "event_type": "price_change"}}
{"_local_timestamp": "2026-01-25T23:41:08.161607+00:00", "data": {"market": "0xdb8c52f913b49429f0c941680f913fe8b9f8170e1176c92c0d2ec6aa609116c5", "price_changes": [{"asset_id": "46803634135962229171825077703475690792137743454334214987347130776565965421012", "price": "0.141", "size": "0", "side": "BUY", "hash": "6705a87313c253f6f49d29022c22f965beb40971", "best_bid": "0.999", "best_ask": "1"}, {"asset_id": "79771878395953822320782565470392821820625919272515479990943961908567355595301", "price": "0.859", "size": "0", "side": "SELL", "hash": "456d4b1290dda77ebe539df84c27f604c3f20272", "best_bid": "0", "best_ask": "0.001"}], "timestamp": "1769384468000", "event_type": "price_change"}}
{"_local_timestamp": "2026-01-25T23:41:08.162379+00:00", "data": {"market": "0x453f8479a041419e8f794d9f7149e4d95a3d315effa5d754fa0e303c83257140", "price_changes": [{"asset_id": "39365936570984542827431489666856672933613556292100829681088739787833575189466", "price": "0.114", "size": "0", "side": "BUY", "hash": "b23af8b8078dd795c95cff0e28bb6c4a09bea6df", "best_bid": "0.996", "best_ask": "1"}, {"asset_id": "19192699567236935154412948133755984775559628536019255388694943247637117213140", "price": "0.886", "size": "0", "side": "SELL", "hash": "10ad1c08562581adb614e2da0cd4138b0d73b095", "best_bid": "0", "best_ask": "0.004"}], "timestamp": "1769384468002", "event_type": "price_change"}}
{"_local_timestamp": "2026-01-25T23:41:08.163346+00:00", "data": {"market": "0xb396be1c57cb41ca2248f91ebde81d87102b4cdcfa4aa6908abb2e1ad4d71be6", "price_changes": [{"asset_id": "34419698228673649128953341658515616138601812429723644373431200193643709482989", "price": "0.151", "size": "0", "side": "BUY", "hash": "2a982b21a8f40af1afce92cc7c305ca833e640f5", "best_bid": "0.999", "best_ask": "1"}, {"asset_id": "62435228944209279352438951651853891000763690834442926701361268157078928214358", "price": "0.849", "size": "0", "side": "SELL", "hash": "b1d84f859cba1ab7bcd9dd41b91de46e4cee52ef", "best_bid": "0", "best_ask": "0.001"}], "timestamp": "1769384468001", "event_type": "price_change"}}
{"_local_timestamp": "2026-01-25T23:41:08.164091+00:00", "data": {"market": "0x0ddecb3719cb794f5e7579e7d507b9ad43b923c937cfd2f5a986cf6a81dee110", "price_changes": [{"asset_id": "110102504010926247021349733674729068129771632709988877722712998580229970801235", "price": "0.112", "size": "0", "side": "BUY", "hash": "65513b893a6af7a87a6e62f62e1cb39c64def10e", "best_bid": "0.991", "best_ask": "1"}, {"asset_id": "86378274955206497521039828168131476196819840033175972348144762576295741113618", "price": "0.888", "size": "0", "side": "SELL", "hash": "53ca2080af9c37a14644e333922bc4728ca521a6", "best_bid": "0", "best_ask": "0.009"}], "timestamp": "1769384468002", "event_type": "price_change"}}
{"_local_timestamp": "2026-01-25T23:41:08.164808+00:00", "data": {"market": "0x95159c454bc60f97b3c36f83e82df65a1078a294341a0c1e5207c658f1677cff", "price_changes": [{"asset_id": "51622214577048818167956068950762172686195652496669777228341234316117474308234", "price": "0.04", "size": "0", "side": "BUY", "hash": "0d2878f27b2f7f076b0f24d7e71acf3e7e53606b", "best_bid": "0.56", "best_ask": "1"}, {"asset_id": "93983273693994158380547572404838271499508530443528488764618578435868300664163", "price": "0.96", "size": "0", "side": "SELL", "hash": "986d40cda6930f9044ec2352d649809e70b80d05", "best_bid": "0", "best_ask": "0.44"}], "timestamp": "1769384468002", "event_type": "price_change"}}
{"_local_timestamp": "2026-01-25T23:41:08.165480+00:00", "data": {"market": "0xf6d24c742a3126a68c6b83264660beb058a1f82652c951d599af6bdfb7b391d4", "price_changes": [{"asset_id": "97482207647464260874772172680967961758321108174204964420696779227628091002379", "price": "0.013", "size": "7153", "side": "BUY", "hash": "1698dc23a0d868d6b0bbc8259a996d1cca2eff83", "best_bid": "0.996", "best_ask": "1"}, {"asset_id": "113918115236977645637180997599109290964068777945588716077455921908247080428977", "price": "0.987", "size": "7153", "side": "SELL", "hash": "b38c439cc97c18e7fc0501ce18050cf235485fc4", "best_bid": "0", "best_ask": "0.004"}], "timestamp": "1769384468003", "event_type": "price_change"}}
{"_local_timestamp": "2026-01-25T23:41:08.166140+00:00", "data": {"market": "0x6de3a6fdb4423aefb3e842d82c7ac644a5fce68f0a8ccdd0b05b7bde6fe1149a", "price_changes": [{"asset_id": "22745855048729710799193712391689530895061901586126737668400722077572535398940", "price": "0.111", "size": "0", "side": "BUY", "hash": "b0fdd031167a43c8fc390e830bc54c79c940b86e", "best_bid": "0.991", "best_ask": "1"}, {"asset_id": "4049982343138716877211130425857197940994108677561153999944183574753980469925", "price": "0.889", "size": "0", "side": "SELL", "hash": "1fc633a346915ca681b85a717b76d8d0e58e6b9a", "best_bid": "0", "best_ask": "0.009"}], "timestamp": "1769384468001", "event_type": "price_change"}}
{"_local_timestamp": "2026-01-25T23:41:08.166820+00:00", "data": {"market": "0xc509411ef133866e75fe61d20ea4ee7be70fcf00843fe605db1bb095a5862b15", "price_changes": [{"asset_id": "45555810545993612965430060201918590422740142498305025284246002991925909487625", "price": "0.112", "size": "0", "side": "BUY", "hash": "ebc4abc05d4ce067a398e0f497c5c6d1b32a19fe", "best_bid": "0.995", "best_ask": "1"}, {"asset_id": "11750347072954117414759862893422867351489364626761446082158388065590872281535", "price": "0.888", "size": "0", "side": "SELL", "hash": "9069cfc598c4ac277b38e2b30cf8317c451eaad1", "best_bid": "0", "best_ask": "0.005"}], "timestamp": "1769384468002", "event_type": "price_change"}}
{"_local_timestamp": "2026-01-25T23:41:08.167490+00:00", "data": {"market": "0xf0bce5848ca6de05a661582b4cae5f6bf815fb1054db10a5ea50d0973c11f730", "price_changes": [{"asset_id": "26611711269986954238795968887055898455427225275079966863101216346291253473218", "price": "0.116", "size": "0", "side": "BUY", "hash": "f9b66bb7ffa9e6bbbd2902944c642d9088da040a", "best_bid": "0.991", "best_ask": "1"}, {"asset_id": "101618041657621872578453287140987906509660472129196215861315765866542254604120", "price": "0.884", "size": "0", "side": "SELL", "hash": "e017e91b8e4a1080724764dd66de2d35c63e3d8e", "best_bid": "0", "best_ask": "0.009"}], "timestamp": "1769384468002", "event_type": "price_change"}}
{"_local_timestamp": "2026-01-25T23:41:08.168167+00:00", "data": {"market": "0x1a20f34335d311c98347af3e47d637b5cbcb249f7dac1915d88c08d330e765d6", "price_changes": [{"asset_id": "51847501527474096557405943284662724691287223384062767234682532363137318024266", "price": "0.112", "size": "0", "side": "BUY", "hash": "927d3851f8f618dd9676cd36a2b72d5aa5b310b0", "best_bid": "0.999", "best_ask": "1"}, {"asset_id": "55127205459841014452783599440229813013711949511338579686361956191876234776667", "price": "0.888", "size": "0", "side": "SELL", "hash": "4aeccc0c0cd8aae876a0ee08cfe833bd4d6c4878", "best_bid": "0", "best_ask": "0.001"}], "timestamp": "1769384468001", "event_type": "price_change"}}
{"_local_timestamp": "2026-01-25T23:41:08.168861+00:00", "data": {"market": "0x393557eaf4c3ec53cf4a341d12263914944220359b6f02b703109ce220257641", "price_changes": [{"asset_id": "93940441597806605185863489141137222482434084554690688125580295758685733000625", "price": "0.141", "size": "0", "side": "BUY", "hash": "bf493d1534124551c6db91382258cd2d43f4ec7e", "best_bid": "0.999", "best_ask": "1"}, {"asset_id": "84067471748088275158649178487081940954142612413002471523992575056649818081482", "price": "0.859", "size": "0", "side": "SELL", "hash": "cd3b7aa54ff9cc6db54265de24393c27d9446d7e", "best_bid": "0", "best_ask": "0.001"}], "timestamp": "1769384468002", "event_type": "price_change"}}
{"_local_timestamp": "2026-01-25T23:41:08.169548+00:00", "data": {"market": "0xc9d50cd59883b78a7566c95c5c49540e627b99bdfdfdee9f38aa4d20a8965092", "price_changes": [{"asset_id": "80520293693063475541125700613267791349974838363391685088405449865305853523521", "price": "0.112", "size": "0", "side": "BUY", "hash": "a8176a6f00bf5eb997ce9835b8014e79daca027a", "best_bid": "0.991", "best_ask": "1"}, {"asset_id": "93686631495592470915059577974351598851938202157000548036184210764800257229360", "price": "0.888", "size": "0", "side": "SELL", "hash": "7d5ca586a4fd7ab352e96cc54ef3dcac94ba350d", "best_bid": "0", "best_ask": "0.009"}], "timestamp": "1769384468001", "event_type": "price_change"}}
{"_local_timestamp": "2026-01-25T23:41:08.170456+00:00", "data": {"market": "0xd3866b1b556fe5843dbf7a6517780211295ba024bb4a90a749531b1cfbf2ac20", "price_changes": [{"asset_id": "30947500130804640808249625202467513009782734777729829776701604345427228069664", "price": "0.141", "size": "0", "side": "BUY", "hash": "77730089186b753bed6c4ee4ae0e2f9447795bd0", "best_bid": "0.999", "best_ask": "1"}, {"asset_id": "112914448831136287961641635085213918544450861148980379546124511283573338657686", "price": "0.859", "size": "0", "side": "SELL", "hash": "f1ef6c21efff625ffba1b4c1ae2dd8e5a6903b60", "best_bid": "0", "best_ask": "0.001"}], "timestamp": "1769384468001", "event_type": "price_change"}}
{"_local_timestamp": "2026-01-25T23:41:08.171489+00:00", "data": {"market": "0x1dde34de4ceb798933f85826a2879ff5676853144ea79f4c1ca89d4f8546ce73", "price_changes": [{"asset_id": "2989772230015894045729002380739794506754998903816202205758003265088876154235", "price": "0.142", "size": "50", "side": "BUY", "hash": "0e6dbd4786e675acf7f46f0b34ccc9b455e9300a", "best_bid": "0.999", "best_ask": "1"}, {"asset_id": "72299768080662854793831035989036195853606657997616618081658086993981448595143", "price": "0.858", "size": "50", "side": "SELL", "hash": "1930e39cb492a9b0707bf424bf277a5bd59c1510", "best_bid": "0", "best_ask": "0.001"}], "timestamp": "1769384468001", "event_type": "price_change"}}
{"_local_timestamp": "2026-01-25T23:41:08.172230+00:00", "data": {"market": "0x41701e7ba16d4af257e01e112cff807143ef2d2ecb90cc481f11652e055d4c59", "price_changes": [{"asset_id": "10466278887690510175905331848661528762143716832637414322344895027265950979694", "price": "0.141", "size": "0", "side": "BUY", "hash": "30a50935078f1bda4483b023c2ca23ead8f3b9ab", "best_bid": "0.999", "best_ask": "1"}, {"asset_id": "25335907832274451055949522033815474513838672679545890866843065752499213006185", "price": "0.859", "size": "0", "side": "SELL", "hash": "68bf2f322774f15798c1ff24ca57164f0136e612", "best_bid": "0", "best_ask": "0.001"}], "timestamp": "1769384468001", "event_type": "price_change"}}
{"_local_timestamp": "2026-01-25T23:41:08.172949+00:00", "data": {"market": "0x8af89f7ab343c39305681165171c95c1574b12e60c5304f2dd239a0a1e7a24c1", "price_changes": [{"asset_id": "37692909475645550314459974353936567359636217295346972073722745661977094322515", "price": "0.112", "size": "0", "side": "BUY", "hash": "b45830eb833f781cb0d944ea9ca857339d503a1b", "best_bid": "0.996", "best_ask": "1"}, {"asset_id": "89418472453463174537963554748272507537614203294881181516093278640962936694404", "price": "0.888", "size": "0", "side": "SELL", "hash": "622094d4bd9549555975f411ff271005dc3f665c", "best_bid": "0", "best_ask": "0.004"}], "timestamp": "1769384468004", "event_type": "price_change"}}
{"_local_timestamp": "2026-01-25T23:41:08.752311+00:00", "data": {"market": "0x88c159de04783ed9846a8dcb03fa330754e46e61564059cc81acb25932710b46", "price_changes": [{"asset_id": "26962425957446230275275597334954929477143782773021571348663069985031678553413", "price": "0.115", "size": "0", "side": "BUY", "hash": "002f295851bf13cf7d4711ad370463f7a39978e6", "best_bid": "0.991", "best_ask": "1"}, {"asset_id": "8459072361983769420511248215510567919570934744639447022627913477245830483592", "price": "0.885", "size": "0", "side": "SELL", "hash": "9c38c9f798c6b3861e6ba9cc4e46ce7270105de7", "best_bid": "0", "best_ask": "0.009"}], "timestamp": "1769384468682", "event_type": "price_change"}}
{"_local_timestamp": "2026-01-25T23:41:09.071418+00:00", "data": {"market": "0x5aac5eb8ab6580a07fefe1b4101c8e2d0dc7fe18f9f09073e20099844dbda100", "price_changes": [{"asset_id": "84728266476447611508256889651403922792366137388604704373227221268140494231791", "price": "0.112", "size": "0", "side": "BUY", "hash": "04e8ee5cae988ca98d4d59013ac397f80262c35d", "best_bid": "0.999", "best_ask": "1"}, {"asset_id": "87637668678053836144289414976006902217669102557443391993849170637464055115930", "price": "0.888", "size": "0", "side": "SELL", "hash": "9f1de3e4479c62ed2804eb5c9016fdab62766a32", "best_bid": "0", "best_ask": "0.001"}], "timestamp": "1769384469000", "event_type": "price_change"}}
{"_local_timestamp": "2026-01-25T23:41:09.073936+00:00", "data": {"market": "0x03ecd51a935b6bf98cc155606a07757f8df82f65813692051f4c72c9257d2b8a", "price_changes": [{"asset_id": "61150347572202179484542766533898569511105402829901319366793784265466052825309", "price": "0.116", "size": "0", "side": "BUY", "hash": "27f0d4c30aad8a74ede43e08b4e4e8e2bccd3828", "best_bid": "0.991", "best_ask": "1"}, {"asset_id": "70854033519000008495118885269721217276572546111465787503153647369190581264337", "price": "0.884", "size": "0", "side": "SELL", "hash": "39a9ffa54f72672feabd0bdc61202c7e14c76faf", "best_bid": "0", "best_ask": "0.009"}], "timestamp": "1769384469000", "event_type": "price_change"}}
{"_local_timestamp": "2026-01-25T23:41:09.075070+00:00", "data": {"market": "0x082b1d3d49530a5c4b1bdfe6616af419e3c5d378bcde74f7a7ed60cfeeecf543", "price_changes": [{"asset_id": "62900695194310488026262854028149955278817013330532204834877233861501581391062", "price": "0.114", "size": "0", "side": "BUY", "hash": "7cdf2b6997fa903c8473bbe4f10cb47f1624f828", "best_bid": "0.991", "best_ask": "1"}, {"asset_id": "94251180310671755511507309886350339223509449584552212021917442764720858939978", "price": "0.886", "size": "0", "side": "SELL", "hash": "3c155e33ccc36fe0caaf06aa042ba041e91dcd16", "best_bid": "0", "best_ask": "0.009"}], "timestamp": "1769384469000", "event_type": "price_change"}}
{"_local_timestamp": "2026-01-25T23:41:09.080190+00:00", "data": {"market": "0x1484fa631b6b04bcbb37d85c786d498fedebc9678858ce17b48ba0e3f9519b45", "price_changes": [{"asset_id": "18402099481226334869165686605666466356593385080959681184650513853894363863316", "price": "0.114", "size": "0", "side": "BUY", "hash": "ea10ebd24525ca577a9bf3f4c4bc5b7b47ef7e4b", "best_bid": "0.991", "best_ask": "1"}, {"asset_id": "24068598186203113951404786672050843911242288735982794500931518548143205695626", "price": "0.886", "size": "0", "side": "SELL", "hash": "011017331cce38690d88c20cebd25b13139166c7", "best_bid": "0", "best_ask": "0.009"}], "timestamp": "1769384469001", "event_type": "price_change"}}
{"_local_timestamp": "2026-01-25T23:41:09.081110+00:00", "data": {"market": "0x46381d9f2cbc49b1570adac72897d7760074fde567f4eb41b9183f6647964909", "price_changes": [{"asset_id": "99297111031951279105369527231196692827634634378016245082110314557578319128154", "price": "0.112", "size": "0", "side": "BUY", "hash": "b800eb251e09702703b43607349841f5fd3bb659", "best_bid": "0.999", "best_ask": "1"}, {"asset_id": "89174380733589776741557368884298749975045965515062114405574362559487645447506", "price": "0.888", "size": "0", "side": "SELL", "hash": "9468a4d2bdf97df455e18c6be49c4ea3409c01af", "best_bid": "0", "best_ask": "0.001"}], "timestamp": "1769384469002", "event_type": "price_change"}}
{"_local_timestamp": "2026-01-25T23:41:09.081849+00:00", "data": {"market": "0x0c93caec5803eac3e4b6571dc14eaf525d00985445b5f44c45c75adc541d949f", "price_changes": [{"asset_id": "42081513420746908832995752715611088031055183705260933435790788126688597030231", "price": "0.118", "size": "0", "side": "BUY", "hash": "0d8f7532ef8cd35deb82d0f8adc7dba13cd5ba7b", "best_bid": "0.991", "best_ask": "1"}, {"asset_id": "95262791531890285439592660554284242677180507171292465411471784850962207018875", "price": "0.882", "size": "0", "side": "SELL", "hash": "5b78826939825e0f2e925b5d3d4269e45cc40c35", "best_bid": "0", "best_ask": "0.009"}], "timestamp": "1769384469002", "event_type": "price_change"}}
{"_local_timestamp": "2026-01-25T23:41:09.082564+00:00", "data": {"market": "0x2fb524a8bd4a9274a3347f130e97ec434f882cde9c72c6c39a478df8a037b6bc", "price_changes": [{"asset_id": "81676411729682572522209607657662370196428570636534278076571567552256536781076", "price": "0.141", "size": "0", "side": "BUY", "hash": "0c441f24ff6d04296597f577f87a44e66f013439", "best_bid": "0.999", "best_ask": "1"}, {"asset_id": "88238876172066828223705449297653633223268017246368037214406599205862569277341", "price": "0.859", "size": "0", "side": "SELL", "hash": "9b3ea314828a8097d36e3f1eb66c3061d33b8b38", "best_bid": "0", "best_ask": "0.001"}], "timestamp": "1769384469001", "event_type": "price_change"}}
{"_local_timestamp": "2026-01-25T23:41:09.083353+00:00", "data": {"market": "0xafb15e731c59384c3d0cc49a5b10ca15478b5e1b3dc515ec78f90ce0c704d585", "price_changes": [{"asset_id": "27721477593921857597151286987191549878448898559962734579469006937396328767858", "price": "0.141", "size": "0", "side": "BUY", "hash": "ae7a04ff865a4d2bed24c1d28c3ae00559b9be4e", "best_bid": "0.999", "best_ask": "1"}, {"asset_id": "19153094648738512033099285766555908783036763432962656196067038857357488238219", "price": "0.859", "size": "0", "side": "SELL", "hash": "ca79063d41fe476fb2978bf735e9c8cfa2b2814f", "best_bid": "0", "best_ask": "0.001"}], "timestamp": "1769384469002", "event_type": "price_change"}}
{"_local_timestamp": "2026-01-25T23:41:09.084070+00:00", "data": {"market": "0xeb02db955841608dd7b20177dcee991fe4f2ea565dff4c3bd4b84ec83b645f9a", "price_changes": [{"asset_id": "100018068008040261825170439668225153993196628728529816847778302576794454481108", "price": "0.111", "size": "0", "side": "BUY", "hash": "e2be72eb8c017423b4ada14d6c6197b87605f0b9", "best_bid": "0.991", "best_ask": "1"}, {"asset_id": "58025251642493946196272668217217183996192324147426153302998300455299188048809", "price": "0.889", "size": "0", "side": "SELL", "hash": "3c488a4a1ff51809763fba8af6f43c6f304779ca", "best_bid": "0", "best_ask": "0.009"}], "timestamp": "1769384469002", "event_type": "price_change"}}
{"_local_timestamp": "2026-01-25T23:41:09.086652+00:00", "data": {"market": "0x1b77653abede480dbe48e76b6dab80958170679b2adf02bec54685c63ca9a546", "price_changes": [{"asset_id": "31235796366585584348784397652164243490901775984817980456949548138406439175277", "price": "0.114", "size": "0", "side": "BUY", "hash": "0e7fd4e573aa3ed4dab3363f67d06d502eb76369", "best_bid": "0.991", "best_ask": "1"}, {"asset_id": "52947772514216127300593849158446775746944174907449498056310257714039867887602", "price": "0.886", "size": "0", "side": "SELL", "hash": "d4f696ebc125f6e40cffd7258fef64f407062761", "best_bid": "0", "best_ask": "0.009"}], "timestamp": "1769384469000", "event_type": "price_change"}}
{"_local_timestamp": "2026-01-25T23:41:09.087537+00:00", "data": {"market": "0x3d0844ce16b86e66a126cfc7b6860f06b7e1d89f7c46f2730679c97b311a6946", "price_changes": [{"asset_id": "64162699045912597255102549430256867196645669965426599877159267293140384494672", "price": "0.114", "size": "0", "side": "BUY", "hash": "e7958a1e4777e128178b7491da92a41d079e80e9", "best_bid": "0.995", "best_ask": "1"}, {"asset_id": "30140424268001367103070307735535434752966197427345930967528797587498602312567", "price": "0.886", "size": "0", "side": "SELL", "hash": "e7950f7baf484f9cb000271831470d32caaaf7b4", "best_bid": "0", "best_ask": "0.005"}], "timestamp": "1769384469001", "event_type": "price_change"}}
{"_local_timestamp": "2026-01-25T23:41:09.089075+00:00", "data": {"market": "0xdf8ea6f127a9d5ea8f14f53eed41b6b24390879f3e35823f9c601c4e775a9f6f", "price_changes": [{"asset_id": "57520827470961388297170993749766772989637717292522446798352861047363463676119", "price": "0.112", "size": "0", "side": "BUY", "hash": "7f815fba2c56a1ce3f2dbf0967a56ba60f3387ca", "best_bid": "0.999", "best_ask": "1"}, {"asset_id": "102951250765217183430323843256952868593235165640536923878565064766596049029095", "price": "0.888", "size": "0", "side": "SELL", "hash": "4806316aa688873f39a1c877b1f5b81f41a8830a", "best_bid": "0", "best_ask": "0.001"}], "timestamp": "1769384469002", "event_type": "price_change"}}
{"_local_timestamp": "2026-01-25T23:41:09.439192+00:00", "data": {"market": "0x717fb00a39a3c4cec6cc728168c3fce6e3035d8ed930aecfc6f343564b16a788", "price_changes": [{"asset_id": "49177293917175339908646266682490527167418532793156915271748070003785027932027", "price": "0.988", "size": "0", "side": "SELL", "hash": "4bf7db9eab35f1b6fa7ad2ec8227d890546f4c4f", "best_bid": "0.001", "best_ask": "0.01"}, {"asset_id": "60119374126653128719260895844622062846381272599857895156246552575227623552241", "price": "0.012", "size": "0", "side": "BUY", "hash": "a5f23c43718c874178103007a3ffc6c69ba11e6d", "best_bid": "0.99", "best_ask": "0.999"}], "timestamp": "1769384469369", "event_type": "price_change"}}
{"_local_timestamp": "2026-01-25T23:41:09.501346+00:00", "data": {"market": "0x717fb00a39a3c4cec6cc728168c3fce6e3035d8ed930aecfc6f343564b16a788", "price_changes": [{"asset_id": "49177293917175339908646266682490527167418532793156915271748070003785027932027", "price": "0.989", "size": "8.41", "side": "SELL", "hash": "91c09e6a43a4dd3d676959f97e642647249b0c91", "best_bid": "0.001", "best_ask": "0.01"}, {"asset_id": "60119374126653128719260895844622062846381272599857895156246552575227623552241", "price": "0.011", "size": "8.41", "side": "BUY", "hash": "2d748403c55ff8b190c76257f92c582d188e4cfe", "best_bid": "0.99", "best_ask": "0.999"}], "timestamp": "1769384469435", "event_type": "price_change"}}
{"_local_timestamp": "2026-01-25T23:41:09.604834+00:00", "data": {"market": "0x33cca535d0340264125e6d424c2b72a54fbf7bed77ea0e12618b2d2117fba8d2", "price_changes": [{"asset_id": "94933623159925613438322028509055338748965839910045279599576284066393667174618", "price": "0.117", "size": "4400", "side": "BUY", "hash": "54bc51a2484f7daf3d53f8a086854b15c534f091", "best_bid": "0.999", "best_ask": "1"}, {"asset_id": "66579638131066880161649101980342858689404800341486957072639169013202428010651", "price": "0.883", "size": "4400", "side": "SELL", "hash": "19369460a04426e1a35d35625fd5308886d6c3aa", "best_bid": "0", "best_ask": "0.001"}], "timestamp": "1769384469531", "event_type": "price_change"}}
{"_local_timestamp": "2026-01-25T23:41:10.068360+00:00", "data": {"market": "0xf6d24c742a3126a68c6b83264660beb058a1f82652c951d599af6bdfb7b391d4", "price_changes": [{"asset_id": "97482207647464260874772172680967961758321108174204964420696779227628091002379", "price": "0.013", "size": "1000", "side": "BUY", "hash": "e5a1c61a1afbb7deded635124aa2e391df11a310", "best_bid": "0.996", "best_ask": "1"}, {"asset_id": "113918115236977645637180997599109290964068777945588716077455921908247080428977", "price": "0.987", "size": "1000", "side": "SELL", "hash": "c53c98c201fa81ca8a4485234be50f2706860e3c", "best_bid": "0", "best_ask": "0.004"}], "timestamp": "1769384470000", "event_type": "price_change"}}
{"_local_timestamp": "2026-01-25T23:41:10.071134+00:00", "data": {"market": "0x174f99617876ff89e3d88401a3e0bcb7e0ccc8f539f981603589b759ee1c986e", "price_changes": [{"asset_id": "8465468375968679168353185049278886271922501234385197733228896629886564398231", "price": "0.772", "size": "0", "side": "BUY", "hash": "aa66d843b1114489f1f38cbb82648851bd39d559", "best_bid": "0.991", "best_ask": "1"}, {"asset_id": "48703479947195481706486691840615061336509417685157069361566374591350887277675", "price": "0.228", "size": "0", "side": "SELL", "hash": "70526512454f01a7da530d603dcfaa93b8663a21", "best_bid": "0", "best_ask": "0.009"}], "timestamp": "1769384470000", "event_type": "price_change"}}
{"_local_timestamp": "2026-01-25T23:41:10.080234+00:00", "data": {"market": "0xeb02db955841608dd7b20177dcee991fe4f2ea565dff4c3bd4b84ec83b645f9a", "price_changes": [{"asset_id": "100018068008040261825170439668225153993196628728529816847778302576794454481108", "price": "0.77", "size": "60", "side": "BUY", "hash": "3cf6724c72e43ac3473bc365d11a9e9473e109a8", "best_bid": "0.991", "best_ask": "1"}, {"asset_id": "58025251642493946196272668217217183996192324147426153302998300455299188048809", "price": "0.23", "size": "60", "side": "SELL", "hash": "bb1669838d76a6587d50a394998020c3613b01c0", "best_bid": "0", "best_ask": "0.009"}], "timestamp": "1769384470000", "event_type": "price_change"}}
{"_local_timestamp": "2026-01-25T23:41:10.082383+00:00", "data": {"market": "0x4748aea08c7479f93888e3c88574cc22f470db27586dddc3c389443aec89ff59", "price_changes": [{"asset_id": "66589182701894097810798527186415708633655827134259434616730323536170342159606", "price": "0.013", "size": "0", "side": "BUY", "hash": "31e8c4f8a78c0a0d1d12ce2c40070417f45d3805", "best_bid": "0.99", "best_ask": "0.999"}, {"asset_id": "83504158413192513722048719030445378881634624891122351294833041377392549555836", "price": "0.987", "size": "0", "side": "SELL", "hash": "0216cc865c4df94449db7edb0c73aed7eb5ccb24", "best_bid": "0.001", "best_ask": "0.01"}], "timestamp": "1769384470000", "event_type": "price_change"}}
{"_local_timestamp": "2026-01-25T23:41:10.084223+00:00", "data": {"market": "0x5a3fd19d87709f84b93d3a71af7adaeca3f99cdfa2e1ba4a3ad256a6ddfb481b", "price_changes": [{"asset_id": "58248314633586529362367123493139013590568973389535271143944925899040736147880", "price": "0.013", "size": "0", "side": "BUY", "hash": "e8d83ad8cce076be673d1e78e6ff0b69d70777d6", "best_bid": "0.999", "best_ask": "1"}, {"asset_id": "65953037871248164391818099564886117125781149283903860674544296582421226617357", "price": "0.987", "size": "0", "side": "SELL", "hash": "39f234ab89964c767ad4901b3a4e866cb0476d76", "best_bid": "0", "best_ask": "0.001"}], "timestamp": "1769384470000", "event_type": "price_change"}}
{"_local_timestamp": "2026-01-25T23:41:10.085033+00:00", "data": {"market": "0x00f131408059e28efe44b6975a5eff6a626a50b1ea117987b2a777f0c28ea352", "price_changes": [{"asset_id": "97023203174986827040174699473138310071498195771105841874355416606377824157721", "price": "0.771", "size": "0", "side": "BUY", "hash": "70ba0c1154a8037347f958821c37f7e1f9234173", "best_bid": "0.999", "best_ask": "1"}, {"asset_id": "61431819519869665528604747494974593341766773949138777450330672465387185609856", "price": "0.229", "size": "0", "side": "SELL", "hash": "d2561680471d5945787af2f5361c8bded276b04a", "best_bid": "0", "best_ask": "0.001"}], "timestamp": "1769384470001", "event_type": "price_change"}}
{"_local_timestamp": "2026-01-25T23:41:10.087577+00:00", "data": {"market": "0x3d0844ce16b86e66a126cfc7b6860f06b7e1d89f7c46f2730679c97b311a6946", "price_changes": [{"asset_id": "64162699045912597255102549430256867196645669965426599877159267293140384494672", "price": "0.772", "size": "0", "side": "BUY", "hash": "ad6706997fa8506eabac31a891dd4ebcbe4ea5cb", "best_bid": "0.995", "best_ask": "1"}, {"asset_id": "30140424268001367103070307735535434752966197427345930967528797587498602312567", "price": "0.228", "size": "0", "side": "SELL", "hash": "0331a14608f4d24e94378a62a4b3c9677ac73c6a", "best_bid": "0", "best_ask": "0.005"}], "timestamp": "1769384470000", "event_type": "price_change"}}
{"_local_timestamp": "2026-01-25T23:41:10.088483+00:00", "data": {"market": "0x1b130b268df56e4802707e2ec9b5c2929b51222d2d0a19af03516e2b960de26a", "price_changes": [{"asset_id": "77018818557373862304084960921215808370283364442421773897574584607622496684030", "price": "0.77", "size": "60", "side": "BUY", "hash": "b34a5da0749b0ebca822a5a46dda8184b87938a5", "best_bid": "0.999", "best_ask": "1"}, {"asset_id": "72797979972272034635860920395196865314139391915868888486424461493808639864972", "price": "0.23", "size": "60", "side": "SELL", "hash": "b8e644654f715e95bbd5796c6fa90750ed50966a", "best_bid": "0", "best_ask": "0.001"}], "timestamp": "1769384470001", "event_type": "price_change"}}
{"_local_timestamp": "2026-01-25T23:41:10.090990+00:00", "data": {"market": "0x76f7c3b2f193044a7891883f044da641b75b078197b3d214b1cef235c8b771e1", "price_changes": [{"asset_id": "56082532738175047478011286938051439618844073329646641418943392710720146125419", "price": "0.037", "size": "0", "side": "BUY", "hash": "63f95bce528c2caf5d0c13a9b22a561ecd2cf34e", "best_bid": "0.999", "best_ask": "1"}, {"asset_id": "83705947662071625507322075497208006707849354374430230873246504758105177021022", "price": "0.963", "size": "0", "side": "SELL", "hash": "b7946f0fa6b849eb7e3d25b379bfdfdfb4092763", "best_bid": "0", "best_ask": "0.001"}], "timestamp": "1769384470001", "event_type": "price_change"}}
{"_local_timestamp": "2026-01-25T23:41:10.091885+00:00", "data": {"market": "0xfb0f4ac0b68e94aedc1214a03cbe9c723feebf9d3a55777fe2b05b8feb66a11c", "price_changes": [{"asset_id": "55426209889638974733753071618642569441373076860672244339538811630049825345670", "price": "0.01", "size": "1000", "side": "BUY", "hash": "45516e25dd5b890334bce128fdc86e6e1789b408", "best_bid": "0.99", "best_ask": "0.999"}, {"asset_id": "43959289417856840840427763184407307972480869140742194070396563955715812876628", "price": "0.99", "size": "1000", "side": "SELL", "hash": "c199243147b988b30da8a6e3287d0da83b8e53ec", "best_bid": "0.001", "best_ask": "0.01"}], "timestamp": "1769384470001", "event_type": "price_change"}}
{"_local_timestamp": "2026-01-25T23:41:10.094162+00:00", "data": {"market": "0xffc02802851ddf3857633aef0f1146e641f16279ef1a91de899500e3f1642956", "price_changes": [{"asset_id": "83868310274258098937534955108180906010340820748057057072512945569667612470884", "price": "0.77", "size": "60", "side": "BUY", "hash": "2614013c25b9b4c06752549241738246dd7ce9ce", "best_bid": "0.991", "best_ask": "1"}, {"asset_id": "58246546221470895651705696424054214777798759824740890223804348498573359454874", "price": "0.23", "size": "60", "side": "SELL", "hash": "474d3d5c788b0c1822c114643b29b6e5d926239c", "best_bid": "0", "best_ask": "0.009"}], "timestamp": "1769384470002", "event_type": "price_change"}}
{"_local_timestamp": "2026-01-25T23:41:10.095245+00:00", "data": {"market": "0xfd4c8249183b221b97b519bbbc40ccad67df85fdf5accd82b5776a795e437c6b", "price_changes": [{"asset_id": "17874277896927531123551458106581405508715609873461214308237688268056733842058", "price": "0.06", "size": "0", "side": "BUY", "hash": "f444797d4ebc958bee4c0d5770ef26cfb588fbf1", "best_bid": "0.61", "best_ask": "1"}, {"asset_id": "8963298533671687804870085262130769994356887438237727171798917958022949375208", "price": "0.94", "size": "0", "side": "SELL", "hash": "e50689dc3668a675b5c57e19b9914b68f68f6be8", "best_bid": "0", "best_ask": "0.39"}], "timestamp": "1769384470003", "event_type": "price_change"}}
{"_local_timestamp": "2026-01-25T23:41:10.102719+00:00", "data": {"market": "0x462bb7daa3b0906569beaf26fe722dd2b742cdaaca0900c3aa710a9e8e418f15", "price_changes": [{"asset_id": "84426700624131057289025898608787752028694418359354475239466346481861071213446", "price": "0.31", "size": "0", "side": "BUY", "hash": "6423f4377cde1742fd1baa66aea14202c2199afd", "best_bid": "0.49", "best_ask": "0.51"}, {"asset_id": "109631748687541424858485727517534723373639840024430532350488906491941213609965", "price": "0.69", "size": "0", "side": "SELL", "hash": "46c2411924c4de5f544cbcfa9c6047df0ca7a518", "best_bid": "0.49", "best_ask": "0.51"}], "timestamp": "1769384470001", "event_type": "price_change"}}
{"_local_timestamp": "2026-01-25T23:41:10.103980+00:00", "data": {"market": "0x204b14f24297c06aaa199dc1d8844bd1becc80bc07f6fca3c5b60e7578c9c201", "price_changes": [{"asset_id": "102355609737505986959456016204459786144451240240244825770982312180145369373256", "price": "0.771", "size": "0", "side": "BUY", "hash": "6c7252d9d150043f6d818789ada86fdb0dd5ee91", "best_bid": "0.999", "best_ask": "1"}, {"asset_id": "58553512085555920981275268565214845438113167009368856656814609879942308608483", "price": "0.229", "size": "0", "side": "SELL", "hash": "c4557023522ce3b8b5a08b4fb44a058d9d74a5a2", "best_bid": "0", "best_ask": "0.001"}], "timestamp": "1769384470003", "event_type": "price_change"}}
{"_local_timestamp": "2026-01-25T23:41:10.104907+00:00", "data": {"market": "0xd5fb790e70d3ad1769f40ef70f55233cc6098ac83423c160dcd16f0278199c0d", "price_changes": [{"asset_id": "38669595393479333756794564935772837388967649329391357690872871259908868669902", "price": "0.77", "size": "60", "side": "BUY", "hash": "fe6154bfd520e839f8bb499725e45e34a4914e7f", "best_bid": "0.991", "best_ask": "1"}, {"asset_id": "67683893917838442286608716085337607998088783731863722223710730122730169958578", "price": "0.23", "size": "60", "side": "SELL", "hash": "0e909c3f7306f71b6b86f83d97fde3928436b7b8", "best_bid": "0", "best_ask": "0.009"}], "timestamp": "1769384470003", "event_type": "price_change"}}
{"_local_timestamp": "2026-01-25T23:41:10.206082+00:00", "data": {"market": "0x717fb00a39a3c4cec6cc728168c3fce6e3035d8ed930aecfc6f343564b16a788", "price_changes": [{"asset_id": "60119374126653128719260895844622062846381272599857895156246552575227623552241", "price": "0.01", "size": "1000", "side": "BUY", "hash": "9b53fbd1cfd40d7ca37c6bc7dacee847240b5e82", "best_bid": "0.99", "best_ask": "0.999"}, {"asset_id": "49177293917175339908646266682490527167418532793156915271748070003785027932027", "price": "0.99", "size": "1000", "side": "SELL", "hash": "4b209a5067237242c3d22961f932e1c4a3c4a4b0", "best_bid": "0.001", "best_ask": "0.01"}], "timestamp": "1769384470002", "event_type": "price_change"}}
{"_local_timestamp": "2026-01-25T23:41:10.208130+00:00", "data": {"market": "0xc0d7f7796a0cac90cb70c79845db9d226ed35959bd0aa35af7fb418f3f2e22e5", "price_changes": [{"asset_id": "12543330728269567640220567011294079896273543850192586290021550850906815833169", "price": "0.771", "size": "0", "side": "BUY", "hash": "80a2a000af68c9d9df66554a2e2961140217ce27", "best_bid": "0.999", "best_ask": "1"}, {"asset_id": "10008028422703392249749236854165253701939526137534166171302431408077717628002", "price": "0.229", "size": "0", "side": "SELL", "hash": "3ee8be74d2f90cd8347a1f5337235dc67ed8fe6b", "best_bid": "0", "best_ask": "0.001"}], "timestamp": "1769384470002", "event_type": "price_change"}}
{"_local_timestamp": "2026-01-25T23:41:10.209435+00:00", "data": {"market": "0x5c5933ee7d871e48d1a120122ffee0fd57f2a547109c226bf75d12a2d3905e1e", "price_changes": [{"asset_id": "39445779384581598316851917827889246832002643510245720484561264580818170018041", "price": "0.771", "size": "0", "side": "BUY", "hash": "cb9157c18527e09f72848fe2aeabd881071ceca3", "best_bid": "0.999", "best_ask": "1"}, {"asset_id": "31450040692827736276733070952336677024248005125940001939196013706836154165101", "price": "0.229", "size": "0", "side": "SELL", "hash": "c72eacff090a191eabb4dc8c8fa75d19c142d56f", "best_bid": "0", "best_ask": "0.001"}], "timestamp": "1769384470004", "event_type": "price_change"}}
{"_local_timestamp": "2026-01-25T23:41:10.210216+00:00", "data": {"market": "0xdb8c52f913b49429f0c941680f913fe8b9f8170e1176c92c0d2ec6aa609116c5", "price_changes": [{"asset_id": "46803634135962229171825077703475690792137743454334214987347130776565965421012", "price": "0.77", "size": "60", "side": "BUY", "hash": "e2b3ae8c97909e5633219eb5d19133c83fb26fe4", "best_bid": "0.999", "best_ask": "1"}, {"asset_id": "79771878395953822320782565470392821820625919272515479990943961908567355595301", "price": "0.23", "size": "60", "side": "SELL", "hash": "ddfd69a0a1cc6589cce88261b577c81dd2d80e74", "best_bid": "0", "best_ask": "0.001"}], "timestamp": "1769384470004", "event_type": "price_change"}}
{"_local_timestamp": "2026-01-25T23:41:10.211844+00:00", "data": {"market": "0x95159c454bc60f97b3c36f83e82df65a1078a294341a0c1e5207c658f1677cff", "price_changes": [{"asset_id": "51622214577048818167956068950762172686195652496669777228341234316117474308234", "price": "0.05", "size": "0", "side": "BUY", "hash": "0b6559fec3bc1e59c8fbb32406b68ddc69720e6f", "best_bid": "0.56", "best_ask": "1"}, {"asset_id": "93983273693994158380547572404838271499508530443528488764618578435868300664163", "price": "0.95", "size": "0", "side": "SELL", "hash": "139f3079db8e3e05ae57d58b156705a6652242f5", "best_bid": "0", "best_ask": "0.44"}], "timestamp": "1769384470002", "event_type": "price_change"}}
{"_local_timestamp": "2026-01-25T23:41:10.212722+00:00", "data": {"market": "0xc9d50cd59883b78a7566c95c5c49540e627b99bdfdfdee9f38aa4d20a8965092", "price_changes": [{"asset_id": "80520293693063475541125700613267791349974838363391685088405449865305853523521", "price": "0.77", "size": "60", "side": "BUY", "hash": "6b3a57447aef1ac94699dde3f404a7fae6dcaa01", "best_bid": "0.991", "best_ask": "1"}, {"asset_id": "93686631495592470915059577974351598851938202157000548036184210764800257229360", "price": "0.23", "size": "60", "side": "SELL", "hash": "1c4ad9f96b1e18373e9d14564749bef14a1d8e8c", "best_bid": "0", "best_ask": "0.009"}], "timestamp": "1769384470006", "event_type": "price_change"}}
{"_local_timestamp": "2026-01-25T23:41:10.213518+00:00", "data": {"market": "0x84e5a3986fbc3fee389ed87a4f070df7478c78953a4e0ac8fcefb9cf1f7d4a90", "price_changes": [{"asset_id": "1834143411676190819902614191475506377009972301852369769871635548739845748032", "price": "0.77", "size": "60", "side": "BUY", "hash": "3a334f80c03e1cbe7dee8c444ecbc9529722505a", "best_bid": "0.991", "best_ask": "1"}, {"asset_id": "29432070850069872970940163971322046452677105415473389882122736983204650720097", "price": "0.23", "size": "60", "side": "SELL", "hash": "63efe7f7e409dc0d91a83d1327f969f09cf43997", "best_bid": "0", "best_ask": "0.009"}], "timestamp": "1769384470002", "event_type": "price_change"}}
{"_local_timestamp": "2026-01-25T23:41:10.214285+00:00", "data": {"market": "0x453f8479a041419e8f794d9f7149e4d95a3d315effa5d754fa0e303c83257140", "price_changes": [{"asset_id": "39365936570984542827431489666856672933613556292100829681088739787833575189466", "price": "0.772", "size": "0", "side": "BUY", "hash": "2634071ad488d8a8162379a7f4c39a50913f3adc", "best_bid": "0.996", "best_ask": "1"}, {"asset_id": "19192699567236935154412948133755984775559628536019255388694943247637117213140", "price": "0.228", "size": "0", "side": "SELL", "hash": "5955e7335a41d8e6aacdbd7f2a74d7fa71fd3a86", "best_bid": "0", "best_ask": "0.004"}], "timestamp": "1769384470006", "event_type": "price_change"}}
{"_local_timestamp": "2026-01-25T23:41:10.215838+00:00", "data": {"market": "0xce44cece516669135071d3bae72fc4f5f365322a1d5005949dfc86be9be420da", "price_changes": [{"asset_id": "53974558442829387376541849493942578943658081612178694724995455494917931103192", "price": "0.77", "size": "60", "side": "BUY", "hash": "29fabb6f4c0df1216e0f217e3f92c102506376e4", "best_bid": "0.999", "best_ask": "1"}, {"asset_id": "76014602550800947248168109629242500597255611883184659688735188973598896781240", "price": "0.23", "size": "60", "side": "SELL", "hash": "2b2541ce698e2e0e57fb70ee2f7e96cf1bec2cc4", "best_bid": "0", "best_ask": "0.001"}], "timestamp": "1769384470005", "event_type": "price_change"}}
{"_local_timestamp": "2026-01-25T23:41:10.217167+00:00", "data": {"market": "0xd9b0fc72f38c908a5a7141420c06da580d01ed86c2ec38705ea15f72cb5e5e19", "price_changes": [{"asset_id": "51572238815890626847563912025595017507148782163592329862076559798897854761860", "price": "0.013", "size": "0", "side": "BUY", "hash": "f92cc1355f5fe4865625bfe9db5ede3ddd22d049", "best_bid": "0.999", "best_ask": "1"}, {"asset_id": "57098020481919035618128472838337976081009168137472950524968489896877203309629", "price": "0.987", "size": "0", "side": "SELL", "hash": "21da943317b32d9bebce89e17718069e8498df1a", "best_bid": "0", "best_ask": "0.001"}], "timestamp": "1769384470006", "event_type": "price_change"}}
{"_local_timestamp": "2026-01-25T23:41:10.218598+00:00", "data": {"market": "0x3a95272be7d95e8145bd957fae244f214b60a62fd948062f776282c2d2bdb9c8", "price_changes": [{"asset_id": "94570884678709009503382566813899043832638397291612895561327288355956778233951", "price": "0.013", "size": "0", "side": "BUY", "hash": "867fa550a966b7abea6af601e3395060dde068a7", "best_bid": "0.999", "best_ask": "1"}, {"asset_id": "34429579477292779051220305424595648879239634505793752749749838360409422364039", "price": "0.987", "size": "0", "side": "SELL", "hash": "88668276c8d337e2bdbef9b3e9a4a91392a44ec9", "best_bid": "0", "best_ask": "0.001"}], "timestamp": "1769384470003", "event_type": "price_change"}}
{"_local_timestamp": "2026-01-25T23:41:10.219536+00:00", "data": {"market": "0xf1ce664701af71aac63156b3b4fa25a67eb79c29810953512e9724d577053bb2", "price_changes": [{"asset_id": "39778100528521559320073842412769877439422950815300994587540677860951543138758", "price": "0.77", "size": "60", "side": "BUY", "hash": "394286afee5b8ccbc36b3d9db9611207f26b6589", "best_bid": "0.995", "best_ask": "1"}, {"asset_id": "74880017248043009869759184047952705769556168918768905724786540599437534359659", "price": "0.23", "size": "60", "side": "SELL", "hash": "93f9ab58796afc24e0ac1499d4e012eed248bd55", "best_bid": "0", "best_ask": "0.005"}], "timestamp": "1769384470006", "event_type": "price_change"}}
{"_local_timestamp": "2026-01-25T23:41:10.221039+00:00", "data": {"market": "0xec0af11a54f5f6205317897289e191394795cd7f35b76a1cb902006e4a505352", "price_changes": [{"asset_id": "88403256582890565589272354714319570649971420555579995262370758371602376328234", "price": "0.77", "size": "60", "side": "BUY", "hash": "0dda3e336d605c3e76e3152484ca35bd79dc1582", "best_bid": "0.999", "best_ask": "1"}, {"asset_id": "83902666523488757660408005544769162912726010224373037612352316388014236164604", "price": "0.23", "size": "60", "side": "SELL", "hash": "ed30068c016eee5ca68bc95b14826db9a048b4a2", "best_bid": "0", "best_ask": "0.001"}], "timestamp": "1769384470005", "event_type": "price_change"}}
{"_local_timestamp": "2026-01-25T23:41:10.223627+00:00", "data": {"market": "0x1a20f34335d311c98347af3e47d637b5cbcb249f7dac1915d88c08d330e765d6", "price_changes": [{"asset_id": "51847501527474096557405943284662724691287223384062767234682532363137318024266", "price": "0.771", "size": "0", "side": "BUY", "hash": "d95d5a496654e49730df548380bd48efed38f006", "best_bid": "0.999", "best_ask": "1"}, {"asset_id": "55127205459841014452783599440229813013711949511338579686361956191876234776667", "price": "0.229", "size": "0", "side": "SELL", "hash": "cb795633824fd6e859c83c80455557f32ad04646", "best_bid": "0", "best_ask": "0.001"}], "timestamp": "1769384470003", "event_type": "price_change"}}
{"_local_timestamp": "2026-01-25T23:41:10.225038+00:00", "data": {"market": "0x4c2b7eeab37dc3dbf56fb2a58451e7bf82c554a22e56ed048637c270340bb082", "price_changes": [{"asset_id": "69173073876652300953776803396376322172775215646460032389913013787125429776220", "price": "0.772", "size": "0", "side": "BUY", "hash": "a68da9d6ea1d627180f41e43298d8effb96d43fc", "best_bid": "0.995", "best_ask": "1"}, {"asset_id": "73025139437582022870812618619686768740565683325010098372267219247119634794964", "price": "0.228", "size": "0", "side": "SELL", "hash": "33d7a5580c545bf7de046bda69f52cdbe7f37436", "best_bid": "0", "best_ask": "0.005"}], "timestamp": "1769384470003", "event_type": "price_change"}}
{"_local_timestamp": "2026-01-25T23:41:10.225883+00:00", "data": {"market": "0xb396be1c57cb41ca2248f91ebde81d87102b4cdcfa4aa6908abb2e1ad4d71be6", "price_changes": [{"asset_id": "34419698228673649128953341658515616138601812429723644373431200193643709482989", "price": "0.77", "size": "60", "side": "BUY", "hash": "8d0ca246ef2f29ccfcfb5eaf72eee95b1cc10a8d", "best_bid": "0.999", "best_ask": "1"}, {"asset_id": "62435228944209279352438951651853891000763690834442926701361268157078928214358", "price": "0.23", "size": "60", "side": "SELL", "hash": "44baf6a9183a7f960aa825493f23ec8b1067cf44", "best_bid": "0", "best_ask": "0.001"}], "timestamp": "1769384470003", "event_type": "price_change"}}
{"_local_timestamp": "2026-01-25T23:41:10.269020+00:00", "data": {"market": "0x462bb7daa3b0906569beaf26fe722dd2b742cdaaca0900c3aa710a9e8e418f15", "price_changes": [{"asset_id": "109631748687541424858485727517534723373639840024430532350488906491941213609965", "price": "0.31", "size": "0", "side": "BUY", "hash": "efd9819abb0e8c4591ebe30aaa8a5068a006838a", "best_bid": "0.49", "best_ask": "0.51"}, {"asset_id": "84426700624131057289025898608787752028694418359354475239466346481861071213446", "price": "0.69", "size": "0", "side": "SELL", "hash": "27cf2f52aef37b2a1aff638e79de9d9bb364cecf", "best_bid": "0.49", "best_ask": "0.51"}], "timestamp": "1769384470007", "event_type": "price_change"}}
{"_local_timestamp": "2026-01-25T23:41:10.269968+00:00", "data": {"market": "0x41701e7ba16d4af257e01e112cff807143ef2d2ecb90cc481f11652e055d4c59", "price_changes": [{"asset_id": "10466278887690510175905331848661528762143716832637414322344895027265950979694", "price": "0.77", "size": "60", "side": "BUY", "hash": "ed85042a9aa902afd7bd98275356c27efdba1ccc", "best_bid": "0.999", "best_ask": "1"}, {"asset_id": "25335907832274451055949522033815474513838672679545890866843065752499213006185", "price": "0.23", "size": "60", "side": "SELL", "hash": "872ebebb5c3875410fcfd950ed2fe2957a7cf0b3", "best_bid": "0", "best_ask": "0.001"}], "timestamp": "1769384470006", "event_type": "price_change"}}
{"_local_timestamp": "2026-01-25T23:41:10.270788+00:00", "data": {"market": "0x6de3a6fdb4423aefb3e842d82c7ac644a5fce68f0a8ccdd0b05b7bde6fe1149a", "price_changes": [{"asset_id": "22745855048729710799193712391689530895061901586126737668400722077572535398940", "price": "0.77", "size": "60", "side": "BUY", "hash": "3632cd94c9fb9df9623d464bd9bfd2bb4df44870", "best_bid": "0.991", "best_ask": "1"}, {"asset_id": "4049982343138716877211130425857197940994108677561153999944183574753980469925", "price": "0.23", "size": "60", "side": "SELL", "hash": "f156a52797dd0e3cc34f28d6350f6be6916f04a4", "best_bid": "0", "best_ask": "0.009"}], "timestamp": "1769384470006", "event_type": "price_change"}}
{"_local_timestamp": "2026-01-25T23:41:10.271633+00:00", "data": {"market": "0xd4e29ae9220207efbb9a6b10fe79d09dc21e0e6b15d7095289a8ca046a4977aa", "price_changes": [{"asset_id": "50566369412855320406430637371866470227092223333450744138817186935756262630055", "price": "0.771", "size": "0", "side": "BUY", "hash": "08b790a0d31f5d913ce8ae665370514311f331a4", "best_bid": "0.999", "best_ask": "1"}, {"asset_id": "54581162693071710130485903923254363489511874058356442244838298018744580572687", "price": "0.229", "size": "0", "side": "SELL", "hash": "f923e930184292c5e0a773b9430f03b6de3c0e17", "best_bid": "0", "best_ask": "0.001"}], "timestamp": "1769384470004", "event_type": "price_change"}}
{"_local_timestamp": "2026-01-25T23:41:10.272454+00:00", "data": {"market": "0xcba6d744bd14bb788690a3479acf192ed35f44241c30820efc642d6720703a01", "price_changes": [{"asset_id": "109228675712804150419254959603454060015458251960061436438701346753980946344788", "price": "0.77", "size": "60", "side": "BUY", "hash": "fc01649d6a40e3e4edb43cb188c5c5495591671c", "best_bid": "0.999", "best_ask": "1"}, {"asset_id": "64735823985571109441321290529333378978050160684601981636835688716014717666867", "price": "0.23", "size": "60", "side": "SELL", "hash": "eb3832dbc3ac75aa11324ac31f891392ba059955", "best_bid": "0", "best_ask": "0.001"}], "timestamp": "1769384470005", "event_type": "price_change"}}
{"_local_timestamp": "2026-01-25T23:41:10.273307+00:00", "data": {"market": "0xbcdc50ca134fca43e2ff92b1d4eb74d1370ee70226edaff6ed2e66eded7c4f17", "price_changes": [{"asset_id": "5574857600587711269700129730512235249359616543972163182547512086378810357379", "price": "0.013", "size": "0", "side": "BUY", "hash": "5eb076955fdc3481ae63a06626c46b33acc335b7", "best_bid": "0.999", "best_ask": "1"}, {"asset_id": "34715175763796870678361611735891885650420703648689314817663953704466610666238", "price": "0.987", "size": "0", "side": "SELL", "hash": "9a85c5d8dc38b1a67b178433cee97d0fa27280af", "best_bid": "0", "best_ask": "0.001"}], "timestamp": "1769384470004", "event_type": "price_change"}}
{"_local_timestamp": "2026-01-25T23:41:10.274131+00:00", "data": {"market": "0x1dde34de4ceb798933f85826a2879ff5676853144ea79f4c1ca89d4f8546ce73", "price_changes": [{"asset_id": "2989772230015894045729002380739794506754998903816202205758003265088876154235", "price": "0.77", "size": "70", "side": "BUY", "hash": "52eee62b739767d7c2225a660e017ba88f12175b", "best_bid": "0.999", "best_ask": "1"}, {"asset_id": "72299768080662854793831035989036195853606657997616618081658086993981448595143", "price": "0.23", "size": "70", "side": "SELL", "hash": "6437f0f1d5d32287b4527ec2454e19cf09e42765", "best_bid": "0", "best_ask": "0.001"}], "timestamp": "1769384470002", "event_type": "price_change"}}
{"_local_timestamp": "2026-01-25T23:41:10.274993+00:00", "data": {"market": "0xdc9d3b6adb4ec1d0bd24409bac6537f979720fd2d540e04ce9a5223bf42b9aa6", "price_changes": [{"asset_id": "69658209478973033181726587560985982613825739930726601099487874533280680791418", "price": "0.77", "size": "60", "side": "BUY", "hash": "28c3265fd9e7afdbda87d389bf4685907572b078", "best_bid": "0.999", "best_ask": "1"}, {"asset_id": "96910445513992308799227995027211940876785078628341868853241341912618720742656", "price": "0.23", "size": "60", "side": "SELL", "hash": "40c78271ca3a2023fb92cf8834c19b4f9352973f", "best_bid": "0", "best_ask": "0.001"}], "timestamp": "1769384470006", "event_type": "price_change"}}
{"_local_timestamp": "2026-01-25T23:41:10.275809+00:00", "data": {"market": "0x393557eaf4c3ec53cf4a341d12263914944220359b6f02b703109ce220257641", "price_changes": [{"asset_id": "93940441597806605185863489141137222482434084554690688125580295758685733000625", "price": "0.77", "size": "60", "side": "BUY", "hash": "6bcf54ac26dec83f92fb5b78045b75b02e56e8cf", "best_bid": "0.999", "best_ask": "1"}, {"asset_id": "84067471748088275158649178487081940954142612413002471523992575056649818081482", "price": "0.23", "size": "60", "side": "SELL", "hash": "798be4807545f0d7755876970270289cbb71e66e", "best_bid": "0", "best_ask": "0.001"}], "timestamp": "1769384470000", "event_type": "price_change"}}
{"_local_timestamp": "2026-01-25T23:41:10.276618+00:00", "data": {"market": "0xc0b3638a969d1b4a2c2c8b9ff3dda8765f5e0dfb1f1669d3223a7d0764ba1808", "price_changes": [{"asset_id": "79078096109886043971078249449586427255424561324464046969686459745648521830395", "price": "0.771", "size": "0", "side": "BUY", "hash": "1ef0acbb833c0f9ec9c9ca5a007e1492ce523cc2", "best_bid": "0.999", "best_ask": "1"}, {"asset_id": "71287787540221311833143710317668754611438884018424897811637563407660610591090", "price": "0.229", "size": "0", "side": "SELL", "hash": "413abe35fdeaff09d49b409bf25aeec77d5595d5", "best_bid": "0", "best_ask": "0.001"}], "timestamp": "1769384470008", "event_type": "price_change"}}
{"_local_timestamp": "2026-01-25T23:41:10.277421+00:00", "data": {"market": "0xc509411ef133866e75fe61d20ea4ee7be70fcf00843fe605db1bb095a5862b15", "price_changes": [{"asset_id": "45555810545993612965430060201918590422740142498305025284246002991925909487625", "price": "0.772", "size": "0", "side": "BUY", "hash": "b3588d8bd89214a4ac749a2db51a1b60d6d1b589", "best_bid": "0.995", "best_ask": "1"}, {"asset_id": "11750347072954117414759862893422867351489364626761446082158388065590872281535", "price": "0.228", "size": "0", "side": "SELL", "hash": "68a2c3652c2311891c969d7a5556bca6a7c3e9b9", "best_bid": "0", "best_ask": "0.005"}], "timestamp": "1769384470006", "event_type": "price_change"}}
{"_local_timestamp": "2026-01-25T23:41:10.278245+00:00", "data": {"market": "0x174f99617876ff89e3d88401a3e0bcb7e0ccc8f539f981603589b759ee1c986e", "price_changes": [{"asset_id": "8465468375968679168353185049278886271922501234385197733228896629886564398231", "price": "0.113", "size": "4400", "side": "BUY", "hash": "a4f5ab9ef5b9c09cf536a178edb24e7b235ba146", "best_bid": "0.991", "best_ask": "1"}, {"asset_id": "48703479947195481706486691840615061336509417685157069361566374591350887277675", "price": "0.887", "size": "4400", "side": "SELL", "hash": "c86b464bfb6f8f7e370179c41fac53d0b3faed21", "best_bid": "0", "best_ask": "0.009"}], "timestamp": "1769384470066", "event_type": "price_change"}}
{"_local_timestamp": "2026-01-25T23:41:10.506522+00:00", "data": {"market": "0x33cca535d0340264125e6d424c2b72a54fbf7bed77ea0e12618b2d2117fba8d2", "price_changes": [{"asset_id": "94933623159925613438322028509055338748965839910045279599576284066393667174618", "price": "0.115", "size": "0", "side": "BUY", "hash": "207a117949629b0d0db2bfdc8dc1a6d9420e10e9", "best_bid": "0.999", "best_ask": "1"}, {"asset_id": "66579638131066880161649101980342858689404800341486957072639169013202428010651", "price": "0.885", "size": "0", "side": "SELL", "hash": "6161a50747042ed3aa2cbcc052c3e40f83dab3eb", "best_bid": "0", "best_ask": "0.001"}], "timestamp": "1769384470440", "event_type": "price_change"}}
{"_local_timestamp": "2026-01-25T23:41:10.886736+00:00", "data": {"market": "0x4748aea08c7479f93888e3c88574cc22f470db27586dddc3c389443aec89ff59", "price_changes": [{"asset_id": "83504158413192513722048719030445378881634624891122351294833041377392549555836", "price": "0.986", "size": "0", "side": "SELL", "hash": "c77d2b3eb42e233efa6d9fdda602d696be63c32c", "best_bid": "0.001", "best_ask": "0.01"}, {"asset_id": "66589182701894097810798527186415708633655827134259434616730323536170342159606", "price": "0.014", "size": "0", "side": "BUY", "hash": "c45cdee1022170ea578ede35cc2249cd70379da0", "best_bid": "0.99", "best_ask": "0.999"}], "timestamp": "1769384470820", "event_type": "price_change"}}
{"_local_timestamp": "2026-01-25T23:41:10.887784+00:00", "data": {"market": "0xd9b0fc72f38c908a5a7141420c06da580d01ed86c2ec38705ea15f72cb5e5e19", "price_changes": [{"asset_id": "57098020481919035618128472838337976081009168137472950524968489896877203309629", "price": "0.986", "size": "0", "side": "SELL", "hash": "fbbe7b3e3b638c765108b8db02fd00670a9fd691", "best_bid": "0", "best_ask": "0.001"}, {"asset_id": "51572238815890626847563912025595017507148782163592329862076559798897854761860", "price": "0.014", "size": "0", "side": "BUY", "hash": "1cf45fd67595154d2f10b10300eed6ca82334eb6", "best_bid": "0.999", "best_ask": "1"}], "timestamp": "1769384470820", "event_type": "price_change"}}
{"_local_timestamp": "2026-01-25T23:41:10.904853+00:00", "data": {"market": "0x5a3fd19d87709f84b93d3a71af7adaeca3f99cdfa2e1ba4a3ad256a6ddfb481b", "price_changes": [{"asset_id": "65953037871248164391818099564886117125781149283903860674544296582421226617357", "price": "0.986", "size": "0", "side": "SELL", "hash": "44b0ce2cff76c259a6ce9e06c69ca6e7a32adff2", "best_bid": "0", "best_ask": "0.001"}, {"asset_id": "58248314633586529362367123493139013590568973389535271143944925899040736147880", "price": "0.014", "size": "0", "side": "BUY", "hash": "3f4419212f540df12ef88dd6216f361c7b2755a1", "best_bid": "0.999", "best_ask": "1"}], "timestamp": "1769384470821", "event_type": "price_change"}}
{"_local_timestamp": "2026-01-25T23:41:10.905902+00:00", "data": {"market": "0x4c2b7eeab37dc3dbf56fb2a58451e7bf82c554a22e56ed048637c270340bb082", "price_changes": [{"asset_id": "73025139437582022870812618619686768740565683325010098372267219247119634794964", "price": "0.227", "size": "0", "side": "SELL", "hash": "bd49e081e4ed84cd220936c83946cf48151c1e1b", "best_bid": "0", "best_ask": "0.005"}, {"asset_id": "69173073876652300953776803396376322172775215646460032389913013787125429776220", "price": "0.773", "size": "0", "side": "BUY", "hash": "23c093bb50f6d14d17a9559b6e4f4a2ec915e654", "best_bid": "0.995", "best_ask": "1"}], "timestamp": "1769384470820", "event_type": "price_change"}}
{"_local_timestamp": "2026-01-25T23:41:10.906855+00:00", "data": {"market": "0xc509411ef133866e75fe61d20ea4ee7be70fcf00843fe605db1bb095a5862b15", "price_changes": [{"asset_id": "11750347072954117414759862893422867351489364626761446082158388065590872281535", "price": "0.227", "size": "0", "side": "SELL", "hash": "1e695c5be085c4d1f0ce0e08ba12bf055bbe63de", "best_bid": "0", "best_ask": "0.005"}, {"asset_id": "45555810545993612965430060201918590422740142498305025284246002991925909487625", "price": "0.773", "size": "0", "side": "BUY", "hash": "986d2f4a2af4a3b28505c51bc35908cfc3b72546", "best_bid": "0.995", "best_ask": "1"}], "timestamp": "1769384470820", "event_type": "price_change"}}
{"_local_timestamp": "2026-01-25T23:41:10.907706+00:00", "data": {"market": "0x00f131408059e28efe44b6975a5eff6a626a50b1ea117987b2a777f0c28ea352", "price_changes": [{"asset_id": "61431819519869665528604747494974593341766773949138777450330672465387185609856", "price": "0.228", "size": "0", "side": "SELL", "hash": "6c93f930ff2cdf96e8e0c649dffdb1833f522856", "best_bid": "0", "best_ask": "0.001"}, {"asset_id": "97023203174986827040174699473138310071498195771105841874355416606377824157721", "price": "0.772", "size": "0", "side": "BUY", "hash": "b7125e4097b121fd0c341b4b23dff709776905c2", "best_bid": "0.999", "best_ask": "1"}], "timestamp": "1769384470820", "event_type": "price_change"}}
{"_local_timestamp": "2026-01-25T23:41:10.908524+00:00", "data": {"market": "0xd4e29ae9220207efbb9a6b10fe79d09dc21e0e6b15d7095289a8ca046a4977aa", "price_changes": [{"asset_id": "54581162693071710130485903923254363489511874058356442244838298018744580572687", "price": "0.228", "size": "0", "side": "SELL", "hash": "4f2794d57d21449c4853c93c2175bcab7abcbcc3", "best_bid": "0", "best_ask": "0.001"}, {"asset_id": "50566369412855320406430637371866470227092223333450744138817186935756262630055", "price": "0.772", "size": "0", "side": "BUY", "hash": "e30b2c2f8ea03289bca9b638f680812cd18eef29", "best_bid": "0.999", "best_ask": "1"}], "timestamp": "1769384470820", "event_type": "price_change"}}
{"_local_timestamp": "2026-01-25T23:41:10.909323+00:00", "data": {"market": "0x453f8479a041419e8f794d9f7149e4d95a3d315effa5d754fa0e303c83257140", "price_changes": [{"asset_id": "19192699567236935154412948133755984775559628536019255388694943247637117213140", "price": "0.227", "size": "0", "side": "SELL", "hash": "b1d9e387f1ab8fb2a2bafd7e908df575d666f7df", "best_bid": "0", "best_ask": "0.004"}, {"asset_id": "39365936570984542827431489666856672933613556292100829681088739787833575189466", "price": "0.773", "size": "0", "side": "BUY", "hash": "44dd1b508e5b3a14e0afd0adf8560a328fcfa267", "best_bid": "0.996", "best_ask": "1"}], "timestamp": "1769384470821", "event_type": "price_change"}}
{"_local_timestamp": "2026-01-25T23:41:10.910145+00:00", "data": {"market": "0x174f99617876ff89e3d88401a3e0bcb7e0ccc8f539f981603589b759ee1c986e", "price_changes": [{"asset_id": "48703479947195481706486691840615061336509417685157069361566374591350887277675", "price": "0.227", "size": "0", "side": "SELL", "hash": "592c624cb9434ffdc813996921ad9639c6320f50", "best_bid": "0", "best_ask": "0.009"}, {"asset_id": "8465468375968679168353185049278886271922501234385197733228896629886564398231", "price": "0.773", "size": "0", "side": "BUY", "hash": "bb14b7136ba677dc59bc796636ea32ce996d35b6", "best_bid": "0.991", "best_ask": "1"}], "timestamp": "1769384470821", "event_type": "price_change"}}
{"_local_timestamp": "2026-01-25T23:41:10.910961+00:00", "data": {"market": "0x3d0844ce16b86e66a126cfc7b6860f06b7e1d89f7c46f2730679c97b311a6946", "price_changes": [{"asset_id": "30140424268001367103070307735535434752966197427345930967528797587498602312567", "price": "0.227", "size": "0", "side": "SELL", "hash": "fb4b27a10e8676aba274c0d8076720442aba4d85", "best_bid": "0", "best_ask": "0.005"}, {"asset_id": "64162699045912597255102549430256867196645669965426599877159267293140384494672", "price": "0.773", "size": "0", "side": "BUY", "hash": "718a4e6806979b9a99c1971180c9b25e21e3171e", "best_bid": "0.995", "best_ask": "1"}], "timestamp": "1769384470821", "event_type": "price_change"}}
{"_local_timestamp": "2026-01-25T23:41:10.911767+00:00", "data": {"market": "0x204b14f24297c06aaa199dc1d8844bd1becc80bc07f6fca3c5b60e7578c9c201", "price_changes": [{"asset_id": "58553512085555920981275268565214845438113167009368856656814609879942308608483", "price": "0.228", "size": "0", "side": "SELL", "hash": "482d9f4e65e22dbe82a761b483f69dd7a76666b4", "best_bid": "0", "best_ask": "0.001"}, {"asset_id": "102355609737505986959456016204459786144451240240244825770982312180145369373256", "price": "0.772", "size": "0", "side": "BUY", "hash": "9c031664dc623b3859539b8b4e2255fdaa06229a", "best_bid": "0.999", "best_ask": "1"}], "timestamp": "1769384470821", "event_type": "price_change"}}
{"_local_timestamp": "2026-01-25T23:41:10.912570+00:00", "data": {"market": "0x1a20f34335d311c98347af3e47d637b5cbcb249f7dac1915d88c08d330e765d6", "price_changes": [{"asset_id": "55127205459841014452783599440229813013711949511338579686361956191876234776667", "price": "0.228", "size": "0", "side": "SELL", "hash": "ab6422850b197fea05891773ba733c748c7c0ee8", "best_bid": "0", "best_ask": "0.001"}, {"asset_id": "51847501527474096557405943284662724691287223384062767234682532363137318024266", "price": "0.772", "size": "0", "side": "BUY", "hash": "2391d2a51986866ef82a94526e49bde6f2927e99", "best_bid": "0.999", "best_ask": "1"}], "timestamp": "1769384470821", "event_type": "price_change"}}
{"_local_timestamp": "2026-01-25T23:41:11.004828+00:00", "data": {"market": "0x3d0844ce16b86e66a126cfc7b6860f06b7e1d89f7c46f2730679c97b311a6946", "price_changes": [{"asset_id": "30140424268001367103070307735535434752966197427345930967528797587498602312567", "price": "0.228", "size": "5.47", "side": "SELL", "hash": "836710a92dc4782893811b89e3e5095e0c813167", "best_bid": "0", "best_ask": "0.005"}, {"asset_id": "64162699045912597255102549430256867196645669965426599877159267293140384494672", "price": "0.772", "size": "5.47", "side": "BUY", "hash": "b918d480b41b07985939e073264a257847dc92e3", "best_bid": "0.995", "best_ask": "1"}], "timestamp": "1769384470893", "event_type": "price_change"}}
{"_local_timestamp": "2026-01-25T23:41:11.007931+00:00", "data": {"market": "0xc509411ef133866e75fe61d20ea4ee7be70fcf00843fe605db1bb095a5862b15", "price_changes": [{"asset_id": "11750347072954117414759862893422867351489364626761446082158388065590872281535", "price": "0.228", "size": "5.47", "side": "SELL", "hash": "43fbf3690835fe68cfd314e572107549f278a1bd", "best_bid": "0", "best_ask": "0.005"}, {"asset_id": "45555810545993612965430060201918590422740142498305025284246002991925909487625", "price": "0.772", "size": "5.47", "side": "BUY", "hash": "00bb5fc47f417217a2be705c3808b9cb2633285c", "best_bid": "0.995", "best_ask": "1"}], "timestamp": "1769384470893", "event_type": "price_change"}}
{"_local_timestamp": "2026-01-25T23:41:11.008910+00:00", "data": {"market": "0x453f8479a041419e8f794d9f7149e4d95a3d315effa5d754fa0e303c83257140", "price_changes": [{"asset_id": "19192699567236935154412948133755984775559628536019255388694943247637117213140", "price": "0.228", "size": "5.47", "side": "SELL", "hash": "b424eb1d261bfa60d159fac951dde4b2a3916a4c", "best_bid": "0", "best_ask": "0.004"}, {"asset_id": "39365936570984542827431489666856672933613556292100829681088739787833575189466", "price": "0.772", "size": "5.47", "side": "BUY", "hash": "148ac405d1cec18a629e5435fb222a1fab57e853", "best_bid": "0.996", "best_ask": "1"}], "timestamp": "1769384470893", "event_type": "price_change"}}
{"_local_timestamp": "2026-01-25T23:41:11.016997+00:00", "data": {"market": "0xd4e29ae9220207efbb9a6b10fe79d09dc21e0e6b15d7095289a8ca046a4977aa", "price_changes": [{"asset_id": "54581162693071710130485903923254363489511874058356442244838298018744580572687", "price": "0.229", "size": "5.47", "side": "SELL", "hash": "dd0db427b1c87a3e7aeffbfb1b9981f64097eccc", "best_bid": "0", "best_ask": "0.001"}, {"asset_id": "50566369412855320406430637371866470227092223333450744138817186935756262630055", "price": "0.771", "size": "5.47", "side": "BUY", "hash": "565be6f59a4f6007bd4b1b6110f3636bd24203a5", "best_bid": "0.999", "best_ask": "1"}], "timestamp": "1769384470893", "event_type": "price_change"}}
