{"_local_timestamp": "2026-01-25T23:33:37.919005+00:00", "data": [{"market": "0xda92713dcfd1002a861dc7927afe82dbd81a0bcb45a8468e15cebc3adb455f2a", "asset_id": "61199962474262836932103113956187992633340535926439339471247709440883806095370", "timestamp": "1769383996532", "hash": "daaa049ca6de67743c66aeb2cd7158ed5e761fef", "bids": [{"price": "0.01", "size": "13337.35"}, {"price": "0.02", "size": "700"}, {"price": "0.03", "size": "12.11"}, {"price": "0.05", "size": "760"}, {"price": "0.09", "size": "61.11"}, {"price": "0.1", "size": "55.48"}, {"price": "0.25", "size": "150"}, {"price": "0.27", "size": "67.7"}, {"price": "0.28", "size": "86"}], "asks": [{"price": "0.99", "size": "14138.84"}, {"price": "0.98", "size": "700"}, {"price": "0.97", "size": "5.96"}, {"price": "0.95", "size": "500"}, {"price": "0.94", "size": "50"}, {"price": "0.92", "size": "58.97"}, {"price": "0.89", "size": "218.18"}, {"price": "0.88", "size": "50"}, {"price": "0.65", "size": "81.42"}, {"price": "0.35", "size": "150"}], "event_type": "book", "last_trade_price": ""}, {"market": "0xfa5b189b04818014e796a6978b1f1e4f842cec8fe4b0f2aa2daa4b2ab7cc59b3", "asset_id": "76097257249586503390123122659919039099107925379782923914081177262841936638457", "timestamp": "1769384016749", "hash": "281f59a5d86a2a3b779f0aab3176bdcd96f5bde3", "bids": [{"price": "0.01", "size": "743.48"}, {"price": "0.02", "size": "250"}, {"price": "0.03", "size": "8.59"}, {"price": "0.04", "size": "1100"}, {"price": "0.07", "size": "700"}, {"price": "0.08", "size": "500"}, {"price": "0.09", "size": "7.08"}, {"price": "0.18", "size": "20050"}, {"price": "0.2", "size": "200"}, {"price": "0.39", "size": "211"}, {"price": "0.42", "size": "64.52"}, {"price": "0.43", "size": "62.14"}, {"price": "0.44", "size": "40"}, {"price": "0.45", "size": "1010"}, {"price": "0.46", "size": "6760"}, {"price": "0.47", "size": "6055"}, {"price": "0.48", "size": "6649"}, {"price": "0.49", "size": "1946"}, {"price": "0.5", "size": "8490.3"}, {"price": "0.51", "size": "6650.25"}], "asks": [{"price": "0.99", "size": "738.35"}, {"price": "0.98", "size": "1355.06"}, {"price": "0.97", "size": "100"}, {"price": "0.96", "size": "5.31"}, {"price": "0.95", "size": "700"}, {"price": "0.92", "size": "500"}, {"price": "0.91", "size": "7.02"}, {"price": "0.82", "size": "20050"}, {"price": "0.66", "size": "210"}, {"price": "0.61", "size": "33.33"}, {"price": "0.6", "size": "42.5"}, {"price": "0.59", "size": "10"}, {"price": "0.58", "size": "20"}, {"price": "0.57", "size": "80"}, {"price": "0.56", "size": "1520"}, {"price": "0.55", "size": "515"}, {"price": "0.54", "size": "7654"}, {"price": "0.53", "size": "6798"}, {"price": "0.52", "size": "8463.5"}], "event_type": "book", "last_trade_price": "0.480"}, {"market": "0xfa5b189b04818014e796a6978b1f1e4f842cec8fe4b0f2aa2daa4b2ab7cc59b3", "asset_id": "15086968501686691607738632508897515530788413406991828817382775759887962883365", "timestamp": "1769384016749", "hash": "a110030f4fda1c6aa68b55f518ab8a2f750d5101", "bids": [{"price": "0.01", "size": "738.35"}, {"price": "0.02", "size": "1355.06"}, {"price": "0.03", "size": "100"}, {"price": "0.04", "size": "5.31"}, {"price": "0.05", "size": "700"}, {"price": "0.08", "size": "500"}, {"price": "0.09", "size": "7.02"}, {"price": "0.18", "size": "20050"}, {"price": "0.34", "size": "210"}, {"price": "0.39", "size": "33.33"}, {"price": "0.4", "size": "42.5"}, {"price": "0.41", "size": "10"}, {"price": "0.42", "size": "20"}, {"price": "0.43", "size": "80"}, {"price": "0.44", "size": "1520"}, {"price": "0.45", "size": "515"}, {"price": "0.46", "size": "7654"}, {"price": "0.47", "size": "6798"}, {"price": "0.48", "size": "8463.5"}], "asks": [{"price": "0.99", "size": "743.48"}, {"price": "0.98", "size": "250"}, {"price": "0.97", "size": "8.59"}, {"price": "0.96", "size": "1100"}, {"price": "0.93", "size": "700"}, {"price": "0.92", "size": "500"}, {"price": "0.91", "size": "7.08"}, {"price": "0.82", "size": "20050"}, {"price": "0.8", "size": "200"}, {"price": "0.61", "size": "211"}, {"price": "0.58", "size": "64.52"}, {"price": "0.57", "size": "62.14"}, {"price": "0.56", "size": "40"}, {"price": "0.55", "size": "1010"}, {"price": "0.54", "size": "6760"}, {"price": "0.53", "size": "6055"}, {"price": "0.52", "size": "6649"}, {"price": "0.51", "size": "1946"}, {"price": "0.5", "size": "8490.3"}, {"price": "0.49", "size": "6650.25"}], "event_type": "book", "last_trade_price": "0.480"}, {"market": "0xda92713dcfd1002a861dc7927afe82dbd81a0bcb45a8468e15cebc3adb455f2a", "asset_id": "67847413380699129626284788855443204194830281546928428292927803428848858907175", "timestamp": "1769383996532", "hash": "ceb34e098a1ca5b406ebb7f1f64ec0fb0ec2782e", "bids": [{"price": "0.01", "size": "14138.84"}, {"price": "0.02", "size": "700"}, {"price": "0.03", "size": "5.96"}, {"price": "0.05", "size": "500"}, {"price": "0.06", "size": "50"}, {"price": "0.08", "size": "58.97"}, {"price": "0.11", "size": "218.18"}, {"price": "0.12", "size": "50"}, {"price": "0.35", "size": "81.42"}, {"price": "0.65", "size": "150"}], "asks": [{"price": "0.99", "size": "13337.35"}, {"price": "0.98", "size": "700"}, {"price": "0.97", "size": "12.11"}, {"price": "0.95", "size": "760"}, {"price": "0.91", "size": "61.11"}, {"price": "0.9", "size": "55.48"}, {"price": "0.75", "size": "150"}, {"price": "0.73", "size": "67.7"}, {"price": "0.72", "size": "86"}], "event_type": "book", "last_trade_price": ""}, {"market": "0x900ecfb22add054072f36bc9c943bb05e02369cd1d55dce3ee5b8cf4ae2af764", "asset_id": "72955248379058153293084602651666522215407419096114442653795152349439056321315", "timestamp": "1769383994545", "hash": "2055365ae63c22d399d9bf651988be4cf59a337f", "bids": [{"price": "0.01", "size": "343.32"}, {"price": "0.02", "size": "750"}, {"price": "0.03", "size": "9.69"}, {"price": "0.05", "size": "500"}, {"price": "0.08", "size": "11542.29"}, {"price": "0.09", "size": "4269.41"}, {"price": "0.1", "size": "6.06"}, {"price": "0.12", "size": "89"}, {"price": "0.49", "size": "150"}], "asks": [{"price": "0.99", "size": "343.63"}, {"price": "0.98", "size": "700"}, {"price": "0.97", "size": "11.11"}, {"price": "0.95", "size": "500"}, {"price": "0.91", "size": "450"}, {"price": "0.89", "size": "55.09"}, {"price": "0.62", "size": "290.21"}, {"price": "0.61", "size": "246.32"}, {"price": "0.6", "size": "236.76"}, {"price": "0.59", "size": "296.05"}, {"price": "0.58", "size": "199.28"}, {"price": "0.57", "size": "210.77"}, {"price": "0.56", "size": "150.53"}], "event_type": "book", "last_trade_price": ""}, {"market": "0x900ecfb22add054072f36bc9c943bb05e02369cd1d55dce3ee5b8cf4ae2af764", "asset_id": "90499528413305425764851960350753110982866738119170371042863813719685571770922", "timestamp": "1769383994545", "hash": "77c5e275ab09528ba94f0290fe3b89aa16f5d6c6", "bids": [{"price": "0.01", "size": "343.63"}, {"price": "0.02", "size": "700"}, {"price": "0.03", "size": "11.11"}, {"price": "0.05", "size": "500"}, {"price": "0.09", "size": "450"}, {"price": "0.11", "size": "55.09"}, {"price": "0.38", "size": "290.21"}, {"price": "0.39", "size": "246.32"}, {"price": "0.4", "size": "236.76"}, {"price": "0.41", "size": "296.05"}, {"price": "0.42", "size": "199.28"}, {"price": "0.43", "size": "210.77"}, {"price": "0.44", "size": "150.53"}], "asks": [{"price": "0.99", "size": "343.32"}, {"price": "0.98", "size": "750"}, {"price": "0.97", "size": "9.69"}, {"price": "0.95", "size": "500"}, {"price": "0.92", "size": "11542.29"}, {"price": "0.91", "size": "4269.41"}, {"price": "0.9", "size": "6.06"}, {"price": "0.88", "size": "89"}, {"price": "0.51", "size": "150"}], "event_type": "book", "last_trade_price": ""}, {"market": "0xd5adfe406a67b13cc0a05117843523a69e8bfd4745fd20163f0576a45d7e7fbf", "asset_id": "9783783549835614458881326312946338430553875019865093562239304806617094760942", "timestamp": "1769383965905", "hash": "b0f7e2c74091de897df11b17d76241b43c8c30b0", "bids": [{"price": "0.01", "size": "343.29"}, {"price": "0.03", "size": "809.63"}, {"price": "0.05", "size": "550"}, {"price": "0.08", "size": "100"}, {"price": "0.09", "size": "150"}, {"price": "0.1", "size": "6.08"}, {"price": "0.14", "size": "242.85"}, {"price": "0.2", "size": "200"}, {"price": "0.22", "size": "100"}, {"price": "0.47", "size": "311.65"}, {"price": "0.48", "size": "293.51"}, {"price": "0.49", "size": "359.71"}, {"price": "0.5", "size": "237.57"}, {"price": "0.51", "size": "2275.94"}, {"price": "0.52", "size": "1012.88"}, {"price": "0.53", "size": "286.76"}], "asks": [{"price": "0.99", "size": "1138.38"}, {"price": "0.98", "size": "709.7"}, {"price": "0.95", "size": "500"}, {"price": "0.94", "size": "12.53"}, {"price": "0.89", "size": "218.18"}, {"price": "0.86", "size": "78.57"}, {"price": "0.84", "size": "75"}, {"price": "0.61", "size": "100"}, {"price": "0.58", "size": "6.88"}, {"price": "0.57", "size": "55"}], "event_type": "book", "last_trade_price": ""}, {"market": "0xd5adfe406a67b13cc0a05117843523a69e8bfd4745fd20163f0576a45d7e7fbf", "asset_id": "92942148598462030310311593687833911343746933382385610072160871418917000805183", "timestamp": "1769383965905", "hash": "bbbb9519f5fbdde0bac4f3544babe0c6a82ccf92", "bids": [{"price": "0.01", "size": "1138.38"}, {"price": "0.02", "size": "709.7"}, {"price": "0.05", "size": "500"}, {"price": "0.06", "size": "12.53"}, {"price": "0.11", "size": "218.18"}, {"price": "0.14", "size": "78.57"}, {"price": "0.16", "size": "75"}, {"price": "0.39", "size": "100"}, {"price": "0.42", "size": "6.88"}, {"price": "0.43", "size": "55"}], "asks": [{"price": "0.99", "size": "343.29"}, {"price": "0.97", "size": "809.63"}, {"price": "0.95", "size": "550"}, {"price": "0.92", "size": "100"}, {"price": "0.91", "size": "150"}, {"price": "0.9", "size": "6.08"}, {"price": "0.86", "size": "242.85"}, {"price": "0.8", "size": "200"}, {"price": "0.78", "size": "100"}, {"price": "0.53", "size": "311.65"}, {"price": "0.52", "size": "293.51"}, {"price": "0.51", "size": "359.71"}, {"price": "0.5", "size": "237.57"}, {"price": "0.49", "size": "2275.94"}, {"price": "0.48", "size": "1012.88"}, {"price": "0.47", "size": "286.76"}], "event_type": "book", "last_trade_price": ""}]}
{"_local_timestamp": "2026-01-25T23:33:38.294622+00:00", "data": {"market": "0xfa5b189b04818014e796a6978b1f1e4f842cec8fe4b0f2aa2daa4b2ab7cc59b3", "price_changes": [{"asset_id": "76097257249586503390123122659919039099107925379782923914081177262841936638457", "price": "0.53", "size": "6694", "side": "SELL", "hash": "d213981d1040bc5fdc511ee5e3ffe09f3af3cec1", "best_bid": "0.51", "best_ask": "0.52"}, {"asset_id": "15086968501686691607738632508897515530788413406991828817382775759887962883365", "price": "0.47", "size": "6694", "side": "BUY", "hash": "28e8f91686bb07c892d9d0d809b767e2f5b823f8", "best_bid": "0.48", "best_ask": "0.49"}], "timestamp": "1769384018224", "event_type": "price_change"}}
{"_local_timestamp": "2026-01-25T23:33:38.320592+00:00", "data": {"market": "0xfa5b189b04818014e796a6978b1f1e4f842cec8fe4b0f2aa2daa4b2ab7cc59b3", "price_changes": [{"asset_id": "76097257249586503390123122659919039099107925379782923914081177262841936638457", "price": "0.53", "size": "6798", "side": "SELL", "hash": "b0e996143db9502e236183d3d96775efa536c7ad", "best_bid": "0.51", "best_ask": "0.52"}, {"asset_id": "15086968501686691607738632508897515530788413406991828817382775759887962883365", "price": "0.47", "size": "6798", "side": "BUY", "hash": "4382abedb8983947e77f3280958876ea9d6caee6", "best_bid": "0.48", "best_ask": "0.49"}], "timestamp": "1769384018250", "event_type": "price_change"}}
{"_local_timestamp": "2026-01-25T23:33:39.793155+00:00", "data": {"market": "0xfa5b189b04818014e796a6978b1f1e4f842cec8fe4b0f2aa2daa4b2ab7cc59b3", "price_changes": [{"asset_id": "76097257249586503390123122659919039099107925379782923914081177262841936638457", "price": "0.53", "size": "6694", "side": "SELL", "hash": "1c181c49427a6d75216b9d17e1b3485aaf08c877", "best_bid": "0.51", "best_ask": "0.52"}, {"asset_id": "15086968501686691607738632508897515530788413406991828817382775759887962883365", "price": "0.47", "size": "6694", "side": "BUY", "hash": "407c8cc55cee161365cdf064da3bbaf9a0d17196", "best_bid": "0.48", "best_ask": "0.49"}], "timestamp": "1769384019723", "event_type": "price_change"}}
{"_local_timestamp": "2026-01-25T23:33:39.818448+00:00", "data": {"market": "0xfa5b189b04818014e796a6978b1f1e4f842cec8fe4b0f2aa2daa4b2ab7cc59b3", "price_changes": [{"asset_id": "76097257249586503390123122659919039099107925379782923914081177262841936638457", "price": "0.53", "size": "6798", "side": "SELL", "hash": "d572ea1a0f3b5fd577873cafe1a5d6c3833f1c59", "best_bid": "0.51", "best_ask": "0.52"}, {"asset_id": "15086968501686691607738632508897515530788413406991828817382775759887962883365", "price": "0.47", "size": "6798", "side": "BUY", "hash": "8b62a4d65419a179c487da49a8711edd5ef2a6cf", "best_bid": "0.48", "best_ask": "0.49"}], "timestamp": "1769384019749", "event_type": "price_change"}}
{"_local_timestamp": "2026-01-25T23:33:41.330512+00:00", "data": {"market": "0xfa5b189b04818014e796a6978b1f1e4f842cec8fe4b0f2aa2daa4b2ab7cc59b3", "price_changes": [{"asset_id": "76097257249586503390123122659919039099107925379782923914081177262841936638457", "price": "0.53", "size": "6694", "side": "SELL", "hash": "52027265fe1b03373d783b7cbed94e363b877138", "best_bid": "0.51", "best_ask": "0.52"}, {"asset_id": "15086968501686691607738632508897515530788413406991828817382775759887962883365", "price": "0.47", "size": "6694", "side": "BUY", "hash": "0991d440b4af6dbbea4dedb43d75be066218d7f7", "best_bid": "0.48", "best_ask": "0.49"}], "timestamp": "1769384021225", "event_type": "price_change"}}
{"_local_timestamp": "2026-01-25T23:33:41.346884+00:00", "data": {"market": "0xfa5b189b04818014e796a6978b1f1e4f842cec8fe4b0f2aa2daa4b2ab7cc59b3", "price_changes": [{"asset_id": "76097257249586503390123122659919039099107925379782923914081177262841936638457", "price": "0.53", "size": "6798", "side": "SELL", "hash": "023b8b0fad58acec791c88ba9ce445224908d801", "best_bid": "0.51", "best_ask": "0.52"}, {"asset_id": "15086968501686691607738632508897515530788413406991828817382775759887962883365", "price": "0.47", "size": "6798", "side": "BUY", "hash": "1affc7c2ba96353f3f031f62f3c70e183287cc62", "best_bid": "0.48", "best_ask": "0.49"}], "timestamp": "1769384021252", "event_type": "price_change"}}
{"_local_timestamp": "2026-01-25T23:33:42.789886+00:00", "data": {"market": "0xfa5b189b04818014e796a6978b1f1e4f842cec8fe4b0f2aa2daa4b2ab7cc59b3", "price_changes": [{"asset_id": "76097257249586503390123122659919039099107925379782923914081177262841936638457", "price": "0.53", "size": "6694", "side": "SELL", "hash": "0946877496d1447adbb30fc4f9cbc569fbf8b849", "best_bid": "0.51", "best_ask": "0.52"}, {"asset_id": "15086968501686691607738632508897515530788413406991828817382775759887962883365", "price": "0.47", "size": "6694", "side": "BUY", "hash": "288046eac3630d7585add4258ac23f90c93d2c2f", "best_bid": "0.48", "best_ask": "0.49"}], "timestamp": "1769384022723", "event_type": "price_change"}}
{"_local_timestamp": "2026-01-25T23:33:42.813611+00:00", "data": {"market": "0xfa5b189b04818014e796a6978b1f1e4f842cec8fe4b0f2aa2daa4b2ab7cc59b3", "price_changes": [{"asset_id": "76097257249586503390123122659919039099107925379782923914081177262841936638457", "price": "0.53", "size": "6798", "side": "SELL", "hash": "e5a2f68b4f16e347cbcda72cfb7121c59c994fe9", "best_bid": "0.51", "best_ask": "0.52"}, {"asset_id": "15086968501686691607738632508897515530788413406991828817382775759887962883365", "price": "0.47", "size": "6798", "side": "BUY", "hash": "a69d2ab2c87c1df77b1c5de76b257f09ac7d2aa6", "best_bid": "0.48", "best_ask": "0.49"}], "timestamp": "1769384022749", "event_type": "price_change"}}
{"_local_timestamp": "2026-01-25T23:33:44.297333+00:00", "data": {"market": "0xfa5b189b04818014e796a6978b1f1e4f842cec8fe4b0f2aa2daa4b2ab7cc59b3", "price_changes": [{"asset_id": "76097257249586503390123122659919039099107925379782923914081177262841936638457", "price": "0.53", "size": "6694", "side": "SELL", "hash": "76fa4e37dba530c64ac57b921dc290227ace3916", "best_bid": "0.51", "best_ask": "0.52"}, {"asset_id": "15086968501686691607738632508897515530788413406991828817382775759887962883365", "price": "0.47", "size": "6694", "side": "BUY", "hash": "56e4c39bf36de6c7a2f861ed40716aaaa99edceb", "best_bid": "0.48", "best_ask": "0.49"}], "timestamp": "1769384024228", "event_type": "price_change"}}
{"_local_timestamp": "2026-01-25T23:33:44.348048+00:00", "data": {"market": "0xfa5b189b04818014e796a6978b1f1e4f842cec8fe4b0f2aa2daa4b2ab7cc59b3", "price_changes": [{"asset_id": "76097257249586503390123122659919039099107925379782923914081177262841936638457", "price": "0.53", "size": "6798", "side": "SELL", "hash": "437a6ca5f870388e38adb9a960099c4780f874cd", "best_bid": "0.51", "best_ask": "0.52"}, {"asset_id": "15086968501686691607738632508897515530788413406991828817382775759887962883365", "price": "0.47", "size": "6798", "side": "BUY", "hash": "faba97cce1433d6f88a391553c6cf7b1ab3b153b", "best_bid": "0.48", "best_ask": "0.49"}], "timestamp": "1769384024265", "event_type": "price_change"}}
{"_local_timestamp": "2026-01-25T23:33:45.810787+00:00", "data": {"market": "0xfa5b189b04818014e796a6978b1f1e4f842cec8fe4b0f2aa2daa4b2ab7cc59b3", "price_changes": [{"asset_id": "76097257249586503390123122659919039099107925379782923914081177262841936638457", "price": "0.53", "size": "6694", "side": "SELL", "hash": "ff95abaff5d86191bce13b40f4967da9df3c8047", "best_bid": "0.51", "best_ask": "0.52"}, {"asset_id": "15086968501686691607738632508897515530788413406991828817382775759887962883365", "price": "0.47", "size": "6694", "side": "BUY", "hash": "6909f3cc5e32d7521a75d8b22f433911b4fcd2a6", "best_bid": "0.48", "best_ask": "0.49"}], "timestamp": "1769384025737", "event_type": "price_change"}}
{"_local_timestamp": "2026-01-25T23:33:45.833352+00:00", "data": {"market": "0xfa5b189b04818014e796a6978b1f1e4f842cec8fe4b0f2aa2daa4b2ab7cc59b3", "price_changes": [{"asset_id": "76097257249586503390123122659919039099107925379782923914081177262841936638457", "price": "0.53", "size": "6798", "side": "SELL", "hash": "334519be786d021b34b817efcd6b5d250ac15540", "best_bid": "0.51", "best_ask": "0.52"}, {"asset_id": "15086968501686691607738632508897515530788413406991828817382775759887962883365", "price": "0.47", "size": "6798", "side": "BUY", "hash": "60fddbbc6aeb0644c664c2c6ddda858f9fd04dd3", "best_bid": "0.48", "best_ask": "0.49"}], "timestamp": "1769384025766", "event_type": "price_change"}}
{"_local_timestamp": "2026-01-25T23:33:47.302242+00:00", "data": {"market": "0xfa5b189b04818014e796a6978b1f1e4f842cec8fe4b0f2aa2daa4b2ab7cc59b3", "price_changes": [{"asset_id": "76097257249586503390123122659919039099107925379782923914081177262841936638457", "price": "0.53", "size": "6694", "side": "SELL", "hash": "868b8203a7b4552089a56101e604df78602d9897", "best_bid": "0.51", "best_ask": "0.52"}, {"asset_id": "15086968501686691607738632508897515530788413406991828817382775759887962883365", "price": "0.47", "size": "6694", "side": "BUY", "hash": "5c6213f362016f107a5e9c61900f6960b3a76440", "best_bid": "0.48", "best_ask": "0.49"}], "timestamp": "1769384027223", "event_type": "price_change"}}
{"_local_timestamp": "2026-01-25T23:33:47.329062+00:00", "data": {"market": "0xfa5b189b04818014e796a6978b1f1e4f842cec8fe4b0f2aa2daa4b2ab7cc59b3", "price_changes": [{"asset_id": "76097257249586503390123122659919039099107925379782923914081177262841936638457", "price": "0.53", "size": "6798", "side": "SELL", "hash": "2ed95e7d2fed17ba4ddafc419bc2627d5d0082f3", "best_bid": "0.51", "best_ask": "0.52"}, {"asset_id": "15086968501686691607738632508897515530788413406991828817382775759887962883365", "price": "0.47", "size": "6798", "side": "BUY", "hash": "4c3934f387248e2ec89a4f2d912b77d79e5644af", "best_bid": "0.48", "best_ask": "0.49"}], "timestamp": "1769384027253", "event_type": "price_change"}}
{"_local_timestamp": "2026-01-25T23:33:48.790280+00:00", "data": {"market": "0xfa5b189b04818014e796a6978b1f1e4f842cec8fe4b0f2aa2daa4b2ab7cc59b3", "price_changes": [{"asset_id": "76097257249586503390123122659919039099107925379782923914081177262841936638457", "price": "0.53", "size": "6694", "side": "SELL", "hash": "138927a13afac7d3cd4f3e273a6730cf2c204c65", "best_bid": "0.51", "best_ask": "0.52"}, {"asset_id": "15086968501686691607738632508897515530788413406991828817382775759887962883365", "price": "0.47", "size": "6694", "side": "BUY", "hash": "c8f3dc84e5c9d3dc76ac77d9f01e53aec9b6b12e", "best_bid": "0.48", "best_ask": "0.49"}], "timestamp": "1769384028725", "event_type": "price_change"}}
{"_local_timestamp": "2026-01-25T23:33:48.822343+00:00", "data": {"market": "0xfa5b189b04818014e796a6978b1f1e4f842cec8fe4b0f2aa2daa4b2ab7cc59b3", "price_changes": [{"asset_id": "76097257249586503390123122659919039099107925379782923914081177262841936638457", "price": "0.53", "size": "6798", "side": "SELL", "hash": "68f3e085f22503c506af1fc47298b2cd57684ead", "best_bid": "0.51", "best_ask": "0.52"}, {"asset_id": "15086968501686691607738632508897515530788413406991828817382775759887962883365", "price": "0.47", "size": "6798", "side": "BUY", "hash": "8d0275091d1ab282f2967edc11a5f12b061dbf0e", "best_bid": "0.48", "best_ask": "0.49"}], "timestamp": "1769384028750", "event_type": "price_change"}}
{"_local_timestamp": "2026-01-25T23:33:50.295932+00:00", "data": {"market": "0xfa5b189b04818014e796a6978b1f1e4f842cec8fe4b0f2aa2daa4b2ab7cc59b3", "price_changes": [{"asset_id": "76097257249586503390123122659919039099107925379782923914081177262841936638457", "price": "0.53", "size": "6694", "side": "SELL", "hash": "7e095eaaaa1f49a3a29917e1e34e3e684b22ac10", "best_bid": "0.51", "best_ask": "0.52"}, {"asset_id": "15086968501686691607738632508897515530788413406991828817382775759887962883365", "price": "0.47", "size": "6694", "side": "BUY", "hash": "65741c41b1390e59bfc3225ad7807f9a63b4bc7f", "best_bid": "0.48", "best_ask": "0.49"}], "timestamp": "1769384030224", "event_type": "price_change"}}
{"_local_timestamp": "2026-01-25T23:33:50.324722+00:00", "data": {"market": "0xfa5b189b04818014e796a6978b1f1e4f842cec8fe4b0f2aa2daa4b2ab7cc59b3", "price_changes": [{"asset_id": "76097257249586503390123122659919039099107925379782923914081177262841936638457", "price": "0.53", "size": "6798", "side": "SELL", "hash": "7acbf0647714b676dfcb0fe5c96401d2746d12c9", "best_bid": "0.51", "best_ask": "0.52"}, {"asset_id": "15086968501686691607738632508897515530788413406991828817382775759887962883365", "price": "0.47", "size": "6798", "side": "BUY", "hash": "aa004551511f1404dba687549fc03d7c976288d6", "best_bid": "0.48", "best_ask": "0.49"}], "timestamp": "1769384030249", "event_type": "price_change"}}
{"_local_timestamp": "2026-01-25T23:33:51.793824+00:00", "data": {"market": "0xfa5b189b04818014e796a6978b1f1e4f842cec8fe4b0f2aa2daa4b2ab7cc59b3", "price_changes": [{"asset_id": "76097257249586503390123122659919039099107925379782923914081177262841936638457", "price": "0.53", "size": "6694", "side": "SELL", "hash": "64f0f3e773c3efc0a71b3483419aa774b44dc5f7", "best_bid": "0.51", "best_ask": "0.52"}, {"asset_id": "15086968501686691607738632508897515530788413406991828817382775759887962883365", "price": "0.47", "size": "6694", "side": "BUY", "hash": "13de42ce763e7d65db3e5e21c771e0bac185d321", "best_bid": "0.48", "best_ask": "0.49"}], "timestamp": "1769384031726", "event_type": "price_change"}}
{"_local_timestamp": "2026-01-25T23:33:51.834265+00:00", "data": {"market": "0xfa5b189b04818014e796a6978b1f1e4f842cec8fe4b0f2aa2daa4b2ab7cc59b3", "price_changes": [{"asset_id": "76097257249586503390123122659919039099107925379782923914081177262841936638457", "price": "0.53", "size": "6798", "side": "SELL", "hash": "730a246b259b2c658ae789476219b744ed9a8e07", "best_bid": "0.51", "best_ask": "0.52"}, {"asset_id": "15086968501686691607738632508897515530788413406991828817382775759887962883365", "price": "0.47", "size": "6798", "side": "BUY", "hash": "68010e4b3c3257af720148dff336d580d2ee55c9", "best_bid": "0.48", "best_ask": "0.49"}], "timestamp": "1769384031764", "event_type": "price_change"}}
{"_local_timestamp": "2026-01-25T23:33:53.291287+00:00", "data": {"market": "0xfa5b189b04818014e796a6978b1f1e4f842cec8fe4b0f2aa2daa4b2ab7cc59b3", "price_changes": [{"asset_id": "76097257249586503390123122659919039099107925379782923914081177262841936638457", "price": "0.53", "size": "6694", "side": "SELL", "hash": "e01b32c239e7c1ed159fdc1b62872ff79d294533", "best_bid": "0.51", "best_ask": "0.52"}, {"asset_id": "15086968501686691607738632508897515530788413406991828817382775759887962883365", "price": "0.47", "size": "6694", "side": "BUY", "hash": "a22643b37f15cbfd47ed8b01fc97c298df02a0e5", "best_bid": "0.48", "best_ask": "0.49"}], "timestamp": "1769384033223", "event_type": "price_change"}}
{"_local_timestamp": "2026-01-25T23:33:53.320574+00:00", "data": {"market": "0xfa5b189b04818014e796a6978b1f1e4f842cec8fe4b0f2aa2daa4b2ab7cc59b3", "price_changes": [{"asset_id": "76097257249586503390123122659919039099107925379782923914081177262841936638457", "price": "0.53", "size": "6798", "side": "SELL", "hash": "6a24fc888addaea9740adb763677b3dd13dd937c", "best_bid": "0.51", "best_ask": "0.52"}, {"asset_id": "15086968501686691607738632508897515530788413406991828817382775759887962883365", "price": "0.47", "size": "6798", "side": "BUY", "hash": "419660a60834240fba5ae850dab281d461b8d5c7", "best_bid": "0.48", "best_ask": "0.49"}], "timestamp": "1769384033250", "event_type": "price_change"}}
{"_local_timestamp": "2026-01-25T23:33:54.793533+00:00", "data": {"market": "0xfa5b189b04818014e796a6978b1f1e4f842cec8fe4b0f2aa2daa4b2ab7cc59b3", "price_changes": [{"asset_id": "76097257249586503390123122659919039099107925379782923914081177262841936638457", "price": "0.53", "size": "6694", "side": "SELL", "hash": "26618ff77c8c05c3a58f2d925d792aeb37d17128", "best_bid": "0.51", "best_ask": "0.52"}, {"asset_id": "15086968501686691607738632508897515530788413406991828817382775759887962883365", "price": "0.47", "size": "6694", "side": "BUY", "hash": "3e78f305c2e0f2e92d142f0537b3a8f7e721df08", "best_bid": "0.48", "best_ask": "0.49"}], "timestamp": "1769384034727", "event_type": "price_change"}}
{"_local_timestamp": "2026-01-25T23:33:54.831033+00:00", "data": {"market": "0xfa5b189b04818014e796a6978b1f1e4f842cec8fe4b0f2aa2daa4b2ab7cc59b3", "price_changes": [{"asset_id": "76097257249586503390123122659919039099107925379782923914081177262841936638457", "price": "0.53", "size": "6798", "side": "SELL", "hash": "87ef5e7f1be553b016d40e0a4304cf7f73410344", "best_bid": "0.51", "best_ask": "0.52"}, {"asset_id": "15086968501686691607738632508897515530788413406991828817382775759887962883365", "price": "0.47", "size": "6798", "side": "BUY", "hash": "e6cd81d980a1b28c713a5077400c3d372515bbf0", "best_bid": "0.48", "best_ask": "0.49"}], "timestamp": "1769384034756", "event_type": "price_change"}}
{"_local_timestamp": "2026-01-25T23:33:56.295327+00:00", "data": {"market": "0xfa5b189b04818014e796a6978b1f1e4f842cec8fe4b0f2aa2daa4b2ab7cc59b3", "price_changes": [{"asset_id": "76097257249586503390123122659919039099107925379782923914081177262841936638457", "price": "0.53", "size": "6694", "side": "SELL", "hash": "015dcd7b53b75d84a383335e508f1c00875ac0cb", "best_bid": "0.51", "best_ask": "0.52"}, {"asset_id": "15086968501686691607738632508897515530788413406991828817382775759887962883365", "price": "0.47", "size": "6694", "side": "BUY", "hash": "b284b7ac978aa99bdb70bd83fff7e0a290fd9bb1", "best_bid": "0.48", "best_ask": "0.49"}], "timestamp": "1769384036228", "event_type": "price_change"}}
{"_local_timestamp": "2026-01-25T23:33:56.322861+00:00", "data": {"market": "0xfa5b189b04818014e796a6978b1f1e4f842cec8fe4b0f2aa2daa4b2ab7cc59b3", "price_changes": [{"asset_id": "76097257249586503390123122659919039099107925379782923914081177262841936638457", "price": "0.53", "size": "6798", "side": "SELL", "hash": "35ddcdede2466bd3177060c2f10dc2fea63baa3a", "best_bid": "0.51", "best_ask": "0.52"}, {"asset_id": "15086968501686691607738632508897515530788413406991828817382775759887962883365", "price": "0.47", "size": "6798", "side": "BUY", "hash": "9e4bebf31e1982d6820c3f961f2e06210eb5c5f0", "best_bid": "0.48", "best_ask": "0.49"}], "timestamp": "1769384036255", "event_type": "price_change"}}
{"_local_timestamp": "2026-01-25T23:33:57.815444+00:00", "data": {"market": "0xfa5b189b04818014e796a6978b1f1e4f842cec8fe4b0f2aa2daa4b2ab7cc59b3", "price_changes": [{"asset_id": "76097257249586503390123122659919039099107925379782923914081177262841936638457", "price": "0.53", "size": "6694", "side": "SELL", "hash": "836ed630147c5bb5578577fd3b509952a9e76a15", "best_bid": "0.51", "best_ask": "0.52"}, {"asset_id": "15086968501686691607738632508897515530788413406991828817382775759887962883365", "price": "0.47", "size": "6694", "side": "BUY", "hash": "8802633dedac5e9a5045d711e2f80014c666ce71", "best_bid": "0.48", "best_ask": "0.49"}], "timestamp": "1769384037741", "event_type": "price_change"}}
{"_local_timestamp": "2026-01-25T23:33:57.842221+00:00", "data": {"market": "0xfa5b189b04818014e796a6978b1f1e4f842cec8fe4b0f2aa2daa4b2ab7cc59b3", "price_changes": [{"asset_id": "76097257249586503390123122659919039099107925379782923914081177262841936638457", "price": "0.53", "size": "6798", "side": "SELL", "hash": "14e139d263646958426a5631fddcf067eaef5214", "best_bid": "0.51", "best_ask": "0.52"}, {"asset_id": "15086968501686691607738632508897515530788413406991828817382775759887962883365", "price": "0.47", "size": "6798", "side": "BUY", "hash": "94cc92713dbeb2ededf8c850ab662dc64d4417ef", "best_bid": "0.48", "best_ask": "0.49"}], "timestamp": "1769384037769", "event_type": "price_change"}}
{"_local_timestamp": "2026-01-25T23:33:59.297431+00:00", "data": {"market": "0xfa5b189b04818014e796a6978b1f1e4f842cec8fe4b0f2aa2daa4b2ab7cc59b3", "price_changes": [{"asset_id": "76097257249586503390123122659919039099107925379782923914081177262841936638457", "price": "0.53", "size": "6694", "side": "SELL", "hash": "6ebaf17bd585ac6224fafcece4c672a88dcc5620", "best_bid": "0.51", "best_ask": "0.52"}, {"asset_id": "15086968501686691607738632508897515530788413406991828817382775759887962883365", "price": "0.47", "size": "6694", "side": "BUY", "hash": "25075b191f75475d06904cc2b13526d272bab898", "best_bid": "0.48", "best_ask": "0.49"}], "timestamp": "1769384039229", "event_type": "price_change"}}
{"_local_timestamp": "2026-01-25T23:33:59.324979+00:00", "data": {"market": "0xfa5b189b04818014e796a6978b1f1e4f842cec8fe4b0f2aa2daa4b2ab7cc59b3", "price_changes": [{"asset_id": "76097257249586503390123122659919039099107925379782923914081177262841936638457", "price": "0.53", "size": "6798", "side": "SELL", "hash": "444c9086c5032e25df893cdac58b74dc2f0bbb36", "best_bid": "0.51", "best_ask": "0.52"}, {"asset_id": "15086968501686691607738632508897515530788413406991828817382775759887962883365", "price": "0.47", "size": "6798", "side": "BUY", "hash": "5ca70be73ac75650ce734a6ce467b32cdf0b8dc7", "best_bid": "0.48", "best_ask": "0.49"}], "timestamp": "1769384039255", "event_type": "price_change"}}
{"_local_timestamp": "2026-01-25T23:34:00.798359+00:00", "data": {"market": "0xfa5b189b04818014e796a6978b1f1e4f842cec8fe4b0f2aa2daa4b2ab7cc59b3", "price_changes": [{"asset_id": "76097257249586503390123122659919039099107925379782923914081177262841936638457", "price": "0.53", "size": "6694", "side": "SELL", "hash": "3cd65945bd723802056d9f2c768850f49638c0e7", "best_bid": "0.51", "best_ask": "0.52"}, {"asset_id": "15086968501686691607738632508897515530788413406991828817382775759887962883365", "price": "0.47", "size": "6694", "side": "BUY", "hash": "1e7853622b7ca55e6a5b2822393fbeab16594027", "best_bid": "0.48", "best_ask": "0.49"}], "timestamp": "1769384040730", "event_type": "price_change"}}
{"_local_timestamp": "2026-01-25T23:34:00.827580+00:00", "data": {"market": "0xfa5b189b04818014e796a6978b1f1e4f842cec8fe4b0f2aa2daa4b2ab7cc59b3", "price_changes": [{"asset_id": "76097257249586503390123122659919039099107925379782923914081177262841936638457", "price": "0.53", "size": "6798", "side": "SELL", "hash": "92bef04da3f0cef26915d6bd25f226367acf4ecd", "best_bid": "0.51", "best_ask": "0.52"}, {"asset_id": "15086968501686691607738632508897515530788413406991828817382775759887962883365", "price": "0.47", "size": "6798", "side": "BUY", "hash": "22634204566f40337046c517b509fa3f0c03145a", "best_bid": "0.48", "best_ask": "0.49"}], "timestamp": "1769384040755", "event_type": "price_change"}}
{"_local_timestamp": "2026-01-25T23:34:02.297360+00:00", "data": {"market": "0xfa5b189b04818014e796a6978b1f1e4f842cec8fe4b0f2aa2daa4b2ab7cc59b3", "price_changes": [{"asset_id": "76097257249586503390123122659919039099107925379782923914081177262841936638457", "price": "0.53", "size": "6694", "side": "SELL", "hash": "e437a98750f713ce33ed8c6b097827470832fe5e", "best_bid": "0.51", "best_ask": "0.52"}, {"asset_id": "15086968501686691607738632508897515530788413406991828817382775759887962883365", "price": "0.47", "size": "6694", "side": "BUY", "hash": "6d4efecf04320913c762738336218c0cb6cadc92", "best_bid": "0.48", "best_ask": "0.49"}], "timestamp": "1769384042226", "event_type": "price_change"}}
{"_local_timestamp": "2026-01-25T23:34:02.323291+00:00", "data": {"market": "0xfa5b189b04818014e796a6978b1f1e4f842cec8fe4b0f2aa2daa4b2ab7cc59b3", "price_changes": [{"asset_id": "76097257249586503390123122659919039099107925379782923914081177262841936638457", "price": "0.53", "size": "6798", "side": "SELL", "hash": "e99b42a3a93ca4b733c98f8aeffa518685e1d7aa", "best_bid": "0.51", "best_ask": "0.52"}, {"asset_id": "15086968501686691607738632508897515530788413406991828817382775759887962883365", "price": "0.47", "size": "6798", "side": "BUY", "hash": "83a3d032797fe289f85aee33e45ef19cedd783ed", "best_bid": "0.48", "best_ask": "0.49"}], "timestamp": "1769384042252", "event_type": "price_change"}}
{"_local_timestamp": "2026-01-25T23:34:03.798679+00:00", "data": {"market": "0xfa5b189b04818014e796a6978b1f1e4f842cec8fe4b0f2aa2daa4b2ab7cc59b3", "price_changes": [{"asset_id": "76097257249586503390123122659919039099107925379782923914081177262841936638457", "price": "0.53", "size": "6694", "side": "SELL", "hash": "bfa30eb49fbe7b2660d9b4e37dfb62911eb21edc", "best_bid": "0.51", "best_ask": "0.52"}, {"asset_id": "15086968501686691607738632508897515530788413406991828817382775759887962883365", "price": "0.47", "size": "6694", "side": "BUY", "hash": "b2b82561a925f1db71fe881a4c35377240287a60", "best_bid": "0.48", "best_ask": "0.49"}], "timestamp": "1769384043729", "event_type": "price_change"}}
{"_local_timestamp": "2026-01-25T23:34:03.836097+00:00", "data": {"market": "0xfa5b189b04818014e796a6978b1f1e4f842cec8fe4b0f2aa2daa4b2ab7cc59b3", "price_changes": [{"asset_id": "76097257249586503390123122659919039099107925379782923914081177262841936638457", "price": "0.53", "size": "6798", "side": "SELL", "hash": "f0289ceded39657efa6e00ca2f969e25a0b5b835", "best_bid": "0.51", "best_ask": "0.52"}, {"asset_id": "15086968501686691607738632508897515530788413406991828817382775759887962883365", "price": "0.47", "size": "6798", "side": "BUY", "hash": "98dde1375a5c44e5f36ac44912fa3d0e34a48b1e", "best_bid": "0.48", "best_ask": "0.49"}], "timestamp": "1769384043766", "event_type": "price_change"}}
{"_local_timestamp": "2026-01-25T23:34:05.296878+00:00", "data": {"market": "0xfa5b189b04818014e796a6978b1f1e4f842cec8fe4b0f2aa2daa4b2ab7cc59b3", "price_changes": [{"asset_id": "76097257249586503390123122659919039099107925379782923914081177262841936638457", "price": "0.53", "size": "6694", "side": "SELL", "hash": "e69a728172efcb881d6390d9012c04ca4077d020", "best_bid": "0.51", "best_ask": "0.52"}, {"asset_id": "15086968501686691607738632508897515530788413406991828817382775759887962883365", "price": "0.47", "size": "6694", "side": "BUY", "hash": "eee1894384e8f6a31cf014a8cb8ec3f3e9cf0189", "best_bid": "0.48", "best_ask": "0.49"}], "timestamp": "1769384045223", "event_type": "price_change"}}
{"_local_timestamp": "2026-01-25T23:34:05.319995+00:00", "data": {"market": "0xfa5b189b04818014e796a6978b1f1e4f842cec8fe4b0f2aa2daa4b2ab7cc59b3", "price_changes": [{"asset_id": "76097257249586503390123122659919039099107925379782923914081177262841936638457", "price": "0.53", "size": "6798", "side": "SELL", "hash": "6ad67993581f6ce09d1060f748ebe77098c3fd22", "best_bid": "0.51", "best_ask": "0.52"}, {"asset_id": "15086968501686691607738632508897515530788413406991828817382775759887962883365", "price": "0.47", "size": "6798", "side": "BUY", "hash": "78ed98d5fd5fa8698b471ee5b39fbf9c9385c1b9", "best_bid": "0.48", "best_ask": "0.49"}], "timestamp": "1769384045250", "event_type": "price_change"}}
{"_local_timestamp": "2026-01-25T23:34:06.487776+00:00", "data": {"market": "0x900ecfb22add054072f36bc9c943bb05e02369cd1d55dce3ee5b8cf4ae2af764", "price_changes": [{"asset_id": "72955248379058153293084602651666522215407419096114442653795152349439056321315", "price": "0.52", "size": "306.99", "side": "BUY", "hash": "9bfebdff8ce474b49d8e16168eb777dbab561e60", "best_bid": "0.52", "best_ask": "0.56"}, {"asset_id": "90499528413305425764851960350753110982866738119170371042863813719685571770922", "price": "0.48", "size": "306.99", "side": "SELL", "hash": "85f9b3cc6c32b10699db988d7e8457304de03d81", "best_bid": "0.44", "best_ask": "0.48"}], "timestamp": "1769384046416", "event_type": "price_change"}}
{"_local_timestamp": "2026-01-25T23:34:06.534378+00:00", "data": {"market": "0x900ecfb22add054072f36bc9c943bb05e02369cd1d55dce3ee5b8cf4ae2af764", "price_changes": [{"asset_id": "72955248379058153293084602651666522215407419096114442653795152349439056321315", "price": "0.02", "size": "700", "side": "BUY", "hash": "04ca08b89d107f4f899e26f292f40e3ea4d48a5c", "best_bid": "0.52", "best_ask": "0.56"}, {"asset_id": "90499528413305425764851960350753110982866738119170371042863813719685571770922", "price": "0.98", "size": "700", "side": "SELL", "hash": "98e94084407e968decc270f57628e32fa8522c1f", "best_bid": "0.44", "best_ask": "0.48"}], "timestamp": "1769384046462", "event_type": "price_change"}}
{"_local_timestamp": "2026-01-25T23:34:06.535544+00:00", "data": {"market": "0x900ecfb22add054072f36bc9c943bb05e02369cd1d55dce3ee5b8cf4ae2af764", "price_changes": [{"asset_id": "72955248379058153293084602651666522215407419096114442653795152349439056321315", "price": "0.49", "size": "100", "side": "BUY", "hash": "04ca08b89d107f4f899e26f292f40e3ea4d48a5c", "best_bid": "0.52", "best_ask": "0.56"}, {"asset_id": "90499528413305425764851960350753110982866738119170371042863813719685571770922", "price": "0.51", "size": "100", "side": "SELL", "hash": "98e94084407e968decc270f57628e32fa8522c1f", "best_bid": "0.44", "best_ask": "0.48"}], "timestamp": "1769384046462", "event_type": "price_change"}}
{"_local_timestamp": "2026-01-25T23:34:06.536752+00:00", "data": {"market": "0x900ecfb22add054072f36bc9c943bb05e02369cd1d55dce3ee5b8cf4ae2af764", "price_changes": [{"asset_id": "72955248379058153293084602651666522215407419096114442653795152349439056321315", "price": "0.03", "size": "59.69", "side": "BUY", "hash": "880593a829d2bfebbfcd86742fb9d6c3f9d6503d", "best_bid": "0.52", "best_ask": "0.56"}, {"asset_id": "90499528413305425764851960350753110982866738119170371042863813719685571770922", "price": "0.97", "size": "59.69", "side": "SELL", "hash": "345c93459a32303f93186d894db2923ea7ae6ae0", "best_bid": "0.44", "best_ask": "0.48"}], "timestamp": "1769384046464", "event_type": "price_change"}}
{"_local_timestamp": "2026-01-25T23:34:06.537347+00:00", "data": {"market": "0x900ecfb22add054072f36bc9c943bb05e02369cd1d55dce3ee5b8cf4ae2af764", "price_changes": [{"asset_id": "72955248379058153293084602651666522215407419096114442653795152349439056321315", "price": "0.52", "size": "351.99", "side": "BUY", "hash": "97cb2b0dab05c70ea08578e380dc4c1a6e8b5703", "best_bid": "0.52", "best_ask": "0.56"}, {"asset_id": "90499528413305425764851960350753110982866738119170371042863813719685571770922", "price": "0.48", "size": "351.99", "side": "SELL", "hash": "01d59b91d42abaef7b6b0fd7d85eff4efb3eb975", "best_bid": "0.44", "best_ask": "0.48"}], "timestamp": "1769384046465", "event_type": "price_change"}}
{"_local_timestamp": "2026-01-25T23:34:06.795018+00:00", "data": {"market": "0xfa5b189b04818014e796a6978b1f1e4f842cec8fe4b0f2aa2daa4b2ab7cc59b3", "price_changes": [{"asset_id": "76097257249586503390123122659919039099107925379782923914081177262841936638457", "price": "0.53", "size": "6694", "side": "SELL", "hash": "e1f62003a3ec507fdbf308c9e80acaa596493f49", "best_bid": "0.51", "best_ask": "0.52"}, {"asset_id": "15086968501686691607738632508897515530788413406991828817382775759887962883365", "price": "0.47", "size": "6694", "side": "BUY", "hash": "1e156b242e14f0f811b760b721aee50065e0eb15", "best_bid": "0.48", "best_ask": "0.49"}], "timestamp": "1769384046726", "event_type": "price_change"}}
{"_local_timestamp": "2026-01-25T23:34:06.822066+00:00", "data": {"market": "0xfa5b189b04818014e796a6978b1f1e4f842cec8fe4b0f2aa2daa4b2ab7cc59b3", "price_changes": [{"asset_id": "76097257249586503390123122659919039099107925379782923914081177262841936638457", "price": "0.53", "size": "6798", "side": "SELL", "hash": "9f69f76f91a6f61bc21ce05210aab0c74f647be4", "best_bid": "0.51", "best_ask": "0.52"}, {"asset_id": "15086968501686691607738632508897515530788413406991828817382775759887962883365", "price": "0.47", "size": "6798", "side": "BUY", "hash": "ad05aaa369e4bdac060be0ddbf93579cf3cc45df", "best_bid": "0.48", "best_ask": "0.49"}], "timestamp": "1769384046754", "event_type": "price_change"}}
{"_local_timestamp": "2026-01-25T23:34:07.104039+00:00", "data": {"market": "0xda92713dcfd1002a861dc7927afe82dbd81a0bcb45a8468e15cebc3adb455f2a", "price_changes": [{"asset_id": "67847413380699129626284788855443204194830281546928428292927803428848858907175", "price": "0.69", "size": "380.14", "side": "BUY", "hash": "91a37c9c4e8884b77b49275d84498d33798694f4", "best_bid": "0.69", "best_ask": "0.72"}, {"asset_id": "61199962474262836932103113956187992633340535926439339471247709440883806095370", "price": "0.31", "size": "380.14", "side": "SELL", "hash": "83f8ea9c6f800a4f0e509a3d2c24cb00ae1087ab", "best_bid": "0.28", "best_ask": "0.31"}], "timestamp": "1769384047015", "event_type": "price_change"}}
{"_local_timestamp": "2026-01-25T23:34:08.298309+00:00", "data": {"market": "0xfa5b189b04818014e796a6978b1f1e4f842cec8fe4b0f2aa2daa4b2ab7cc59b3", "price_changes": [{"asset_id": "76097257249586503390123122659919039099107925379782923914081177262841936638457", "price": "0.53", "size": "6694", "side": "SELL", "hash": "1cf6ac58f4a50542ae694128957a5371855a768c", "best_bid": "0.51", "best_ask": "0.52"}, {"asset_id": "15086968501686691607738632508897515530788413406991828817382775759887962883365", "price": "0.47", "size": "6694", "side": "BUY", "hash": "c96fca0df809c6918d293a3a321f3cb160220cd9", "best_bid": "0.48", "best_ask": "0.49"}], "timestamp": "1769384048226", "event_type": "price_change"}}
{"_local_timestamp": "2026-01-25T23:34:08.328776+00:00", "data": {"market": "0xfa5b189b04818014e796a6978b1f1e4f842cec8fe4b0f2aa2daa4b2ab7cc59b3", "price_changes": [{"asset_id": "76097257249586503390123122659919039099107925379782923914081177262841936638457", "price": "0.53", "size": "6798", "side": "SELL", "hash": "00f7122445098f4eec990ff1e8152c5c00efd8b9", "best_bid": "0.51", "best_ask": "0.52"}, {"asset_id": "15086968501686691607738632508897515530788413406991828817382775759887962883365", "price": "0.47", "size": "6798", "side": "BUY", "hash": "d6dc40b0968e6f441151e5800d466dfbf0936a19", "best_bid": "0.48", "best_ask": "0.49"}], "timestamp": "1769384048257", "event_type": "price_change"}}
{"_local_timestamp": "2026-01-25T23:34:09.795006+00:00", "data": {"market": "0xfa5b189b04818014e796a6978b1f1e4f842cec8fe4b0f2aa2daa4b2ab7cc59b3", "price_changes": [{"asset_id": "76097257249586503390123122659919039099107925379782923914081177262841936638457", "price": "0.53", "size": "6694", "side": "SELL", "hash": "da159614d641e834cfd04cf4fd2a4a3680e103bb", "best_bid": "0.51", "best_ask": "0.52"}, {"asset_id": "15086968501686691607738632508897515530788413406991828817382775759887962883365", "price": "0.47", "size": "6694", "side": "BUY", "hash": "13fa667afd55ffaf58eef3e660bb9325ba993ddc", "best_bid": "0.48", "best_ask": "0.49"}], "timestamp": "1769384049727", "event_type": "price_change"}}
{"_local_timestamp": "2026-01-25T23:34:09.828085+00:00", "data": {"market": "0xfa5b189b04818014e796a6978b1f1e4f842cec8fe4b0f2aa2daa4b2ab7cc59b3", "price_changes": [{"asset_id": "76097257249586503390123122659919039099107925379782923914081177262841936638457", "price": "0.53", "size": "6798", "side": "SELL", "hash": "c88cf09663d43005b19c5a4f3daddaaf57de36bf", "best_bid": "0.51", "best_ask": "0.52"}, {"asset_id": "15086968501686691607738632508897515530788413406991828817382775759887962883365", "price": "0.47", "size": "6798", "side": "BUY", "hash": "e1cf29df5eec7597f0032c267f33ae7efc4fa54a", "best_bid": "0.48", "best_ask": "0.49"}], "timestamp": "1769384049757", "event_type": "price_change"}}
{"_local_timestamp": "2026-01-25T23:34:11.297132+00:00", "data": {"market": "0xfa5b189b04818014e796a6978b1f1e4f842cec8fe4b0f2aa2daa4b2ab7cc59b3", "price_changes": [{"asset_id": "76097257249586503390123122659919039099107925379782923914081177262841936638457", "price": "0.53", "size": "6694", "side": "SELL", "hash": "42218b2198e7c31a586e626bb926c1e64179cd34", "best_bid": "0.51", "best_ask": "0.52"}, {"asset_id": "15086968501686691607738632508897515530788413406991828817382775759887962883365", "price": "0.47", "size": "6694", "side": "BUY", "hash": "d6bcc2c3d28a54ba667e318e087286fbffdd45b0", "best_bid": "0.48", "best_ask": "0.49"}], "timestamp": "1769384051229", "event_type": "price_change"}}
{"_local_timestamp": "2026-01-25T23:34:11.329675+00:00", "data": {"market": "0xfa5b189b04818014e796a6978b1f1e4f842cec8fe4b0f2aa2daa4b2ab7cc59b3", "price_changes": [{"asset_id": "76097257249586503390123122659919039099107925379782923914081177262841936638457", "price": "0.53", "size": "6798", "side": "SELL", "hash": "5277aa962963f776c29124844ea7e55374aa5fab", "best_bid": "0.51", "best_ask": "0.52"}, {"asset_id": "15086968501686691607738632508897515530788413406991828817382775759887962883365", "price": "0.47", "size": "6798", "side": "BUY", "hash": "f16615c1656432054cc38be0d971bad9b2054807", "best_bid": "0.48", "best_ask": "0.49"}], "timestamp": "1769384051259", "event_type": "price_change"}}
{"_local_timestamp": "2026-01-25T23:34:12.793042+00:00", "data": {"market": "0xfa5b189b04818014e796a6978b1f1e4f842cec8fe4b0f2aa2daa4b2ab7cc59b3", "price_changes": [{"asset_id": "76097257249586503390123122659919039099107925379782923914081177262841936638457", "price": "0.53", "size": "6694", "side": "SELL", "hash": "8489720cb12de68ae9541d3402b07d5390b295b7", "best_bid": "0.51", "best_ask": "0.52"}, {"asset_id": "15086968501686691607738632508897515530788413406991828817382775759887962883365", "price": "0.47", "size": "6694", "side": "BUY", "hash": "3c00115a5f19b91dcf4746dea888341809525bd2", "best_bid": "0.48", "best_ask": "0.49"}], "timestamp": "1769384052725", "event_type": "price_change"}}
{"_local_timestamp": "2026-01-25T23:34:12.821820+00:00", "data": {"market": "0xfa5b189b04818014e796a6978b1f1e4f842cec8fe4b0f2aa2daa4b2ab7cc59b3", "price_changes": [{"asset_id": "76097257249586503390123122659919039099107925379782923914081177262841936638457", "price": "0.53", "size": "6798", "side": "SELL", "hash": "72de06660ce71127c8711be347c7aad09f370dd8", "best_bid": "0.51", "best_ask": "0.52"}, {"asset_id": "15086968501686691607738632508897515530788413406991828817382775759887962883365", "price": "0.47", "size": "6798", "side": "BUY", "hash": "600370c6d950b565b1b9ba5a976a765ec74d64ad", "best_bid": "0.48", "best_ask": "0.49"}], "timestamp": "1769384052751", "event_type": "price_change"}}
{"_local_timestamp": "2026-01-25T23:34:14.321206+00:00", "data": {"market": "0xfa5b189b04818014e796a6978b1f1e4f842cec8fe4b0f2aa2daa4b2ab7cc59b3", "price_changes": [{"asset_id": "76097257249586503390123122659919039099107925379782923914081177262841936638457", "price": "0.53", "size": "6694", "side": "SELL", "hash": "6c846390535c7f5540dca23c5b61557facedae41", "best_bid": "0.51", "best_ask": "0.52"}, {"asset_id": "15086968501686691607738632508897515530788413406991828817382775759887962883365", "price": "0.47", "size": "6694", "side": "BUY", "hash": "306b4625bd148c3f3c3ed18bff1e71ffaddccd4a", "best_bid": "0.48", "best_ask": "0.49"}], "timestamp": "1769384054230", "event_type": "price_change"}}
{"_local_timestamp": "2026-01-25T23:34:14.347060+00:00", "data": {"market": "0xfa5b189b04818014e796a6978b1f1e4f842cec8fe4b0f2aa2daa4b2ab7cc59b3", "price_changes": [{"asset_id": "76097257249586503390123122659919039099107925379782923914081177262841936638457", "price": "0.53", "size": "6798", "side": "SELL", "hash": "22b83a9ba9c1e62e7b7b3cf8cdad545e6bace94c", "best_bid": "0.51", "best_ask": "0.52"}, {"asset_id": "15086968501686691607738632508897515530788413406991828817382775759887962883365", "price": "0.47", "size": "6798", "side": "BUY", "hash": "aeb93470dcfc2b4fae1d04081363db7cd43ad019", "best_bid": "0.48", "best_ask": "0.49"}], "timestamp": "1769384054256", "event_type": "price_change"}}
{"_local_timestamp": "2026-01-25T23:34:14.486035+00:00", "data": {"market": "0x900ecfb22add054072f36bc9c943bb05e02369cd1d55dce3ee5b8cf4ae2af764", "price_changes": [{"asset_id": "72955248379058153293084602651666522215407419096114442653795152349439056321315", "price": "0.52", "size": "45", "side": "BUY", "hash": "d826b1189b43ab298b5e13f764f00684517f503c", "best_bid": "0.52", "best_ask": "0.56"}, {"asset_id": "90499528413305425764851960350753110982866738119170371042863813719685571770922", "price": "0.48", "size": "45", "side": "SELL", "hash": "12c35b13c5a8e1f90c0359df07d96f888758b19e", "best_bid": "0.44", "best_ask": "0.48"}], "timestamp": "1769384054411", "event_type": "price_change"}}
{"_local_timestamp": "2026-01-25T23:34:14.541625+00:00", "data": {"market": "0x900ecfb22add054072f36bc9c943bb05e02369cd1d55dce3ee5b8cf4ae2af764", "price_changes": [{"asset_id": "72955248379058153293084602651666522215407419096114442653795152349439056321315", "price": "0.03", "size": "9.69", "side": "BUY", "hash": "6a4dfdfafb8ea206fe959d648ae6a381f8294020", "best_bid": "0.49", "best_ask": "0.56"}, {"asset_id": "90499528413305425764851960350753110982866738119170371042863813719685571770922", "price": "0.97", "size": "9.69", "side": "SELL", "hash": "05b2248db136391fe70a683da26296cc76eda243", "best_bid": "0.44", "best_ask": "0.51"}], "timestamp": "1769384054461", "event_type": "price_change"}}
{"_local_timestamp": "2026-01-25T23:34:14.542413+00:00", "data": {"market": "0x900ecfb22add054072f36bc9c943bb05e02369cd1d55dce3ee5b8cf4ae2af764", "price_changes": [{"asset_id": "72955248379058153293084602651666522215407419096114442653795152349439056321315", "price": "0.52", "size": "0", "side": "BUY", "hash": "6a4dfdfafb8ea206fe959d648ae6a381f8294020", "best_bid": "0.49", "best_ask": "0.56"}, {"asset_id": "90499528413305425764851960350753110982866738119170371042863813719685571770922", "price": "0.48", "size": "0", "side": "SELL", "hash": "05b2248db136391fe70a683da26296cc76eda243", "best_bid": "0.44", "best_ask": "0.51"}], "timestamp": "1769384054461", "event_type": "price_change"}}
{"_local_timestamp": "2026-01-25T23:34:14.543565+00:00", "data": {"market": "0x900ecfb22add054072f36bc9c943bb05e02369cd1d55dce3ee5b8cf4ae2af764", "price_changes": [{"asset_id": "72955248379058153293084602651666522215407419096114442653795152349439056321315", "price": "0.02", "size": "750", "side": "BUY", "hash": "91cf3344413f532bd0d19c0ffcdf0f4861922f15", "best_bid": "0.49", "best_ask": "0.56"}, {"asset_id": "90499528413305425764851960350753110982866738119170371042863813719685571770922", "price": "0.98", "size": "750", "side": "SELL", "hash": "a4b77fb6a007c4e2fc140f16831a0b4345c62075", "best_bid": "0.44", "best_ask": "0.51"}], "timestamp": "1769384054465", "event_type": "price_change"}}
{"_local_timestamp": "2026-01-25T23:34:14.544022+00:00", "data": {"market": "0x900ecfb22add054072f36bc9c943bb05e02369cd1d55dce3ee5b8cf4ae2af764", "price_changes": [{"asset_id": "72955248379058153293084602651666522215407419096114442653795152349439056321315", "price": "0.49", "size": "150", "side": "BUY", "hash": "43f764bb375750a924259c38ee1a0ea7f9e7f05d", "best_bid": "0.49", "best_ask": "0.56"}, {"asset_id": "90499528413305425764851960350753110982866738119170371042863813719685571770922", "price": "0.51", "size": "150", "side": "SELL", "hash": "4893a98ddd918dce2b04660230cd39003c13dee2", "best_bid": "0.44", "best_ask": "0.51"}], "timestamp": "1769384054466", "event_type": "price_change"}}
{"_local_timestamp": "2026-01-25T23:34:15.821894+00:00", "data": {"market": "0xfa5b189b04818014e796a6978b1f1e4f842cec8fe4b0f2aa2daa4b2ab7cc59b3", "price_changes": [{"asset_id": "76097257249586503390123122659919039099107925379782923914081177262841936638457", "price": "0.53", "size": "6694", "side": "SELL", "hash": "fe699a9d804586b218d40bdd8da15e99d03dbabf", "best_bid": "0.51", "best_ask": "0.52"}, {"asset_id": "15086968501686691607738632508897515530788413406991828817382775759887962883365", "price": "0.47", "size": "6694", "side": "BUY", "hash": "d908eaba5a73f1ae1a6b4f44f895d2735137d70c", "best_bid": "0.48", "best_ask": "0.49"}], "timestamp": "1769384055740", "event_type": "price_change"}}
{"_local_timestamp": "2026-01-25T23:34:15.846118+00:00", "data": {"market": "0xfa5b189b04818014e796a6978b1f1e4f842cec8fe4b0f2aa2daa4b2ab7cc59b3", "price_changes": [{"asset_id": "76097257249586503390123122659919039099107925379782923914081177262841936638457", "price": "0.53", "size": "6798", "side": "SELL", "hash": "c13212b0784eb79a23ddce67a2dececdae0ca2e8", "best_bid": "0.51", "best_ask": "0.52"}, {"asset_id": "15086968501686691607738632508897515530788413406991828817382775759887962883365", "price": "0.47", "size": "6798", "side": "BUY", "hash": "5a40c15e1a443a7a6987023eb912ad45c4b2f11e", "best_bid": "0.48", "best_ask": "0.49"}], "timestamp": "1769384055772", "event_type": "price_change"}}
{"_local_timestamp": "2026-01-25T23:34:16.256560+00:00", "data": {"market": "0xda92713dcfd1002a861dc7927afe82dbd81a0bcb45a8468e15cebc3adb455f2a", "price_changes": [{"asset_id": "67847413380699129626284788855443204194830281546928428292927803428848858907175", "price": "0.69", "size": "0", "side": "BUY", "hash": "423112fcd601126249bbccf86e3f9d7d3d2ab11a", "best_bid": "0.65", "best_ask": "0.72"}, {"asset_id": "61199962474262836932103113956187992633340535926439339471247709440883806095370", "price": "0.31", "size": "0", "side": "SELL", "hash": "4f0da6f5ddb06dbd78e0a610ff2668a30bc2e83c", "best_bid": "0.28", "best_ask": "0.35"}], "timestamp": "1769384056187", "event_type": "price_change"}}
{"_local_timestamp": "2026-01-25T23:34:17.297642+00:00", "data": {"market": "0xfa5b189b04818014e796a6978b1f1e4f842cec8fe4b0f2aa2daa4b2ab7cc59b3", "price_changes": [{"asset_id": "76097257249586503390123122659919039099107925379782923914081177262841936638457", "price": "0.53", "size": "6694", "side": "SELL", "hash": "fc98c70258a85a213acab7fe86c04cf8deab356c", "best_bid": "0.51", "best_ask": "0.52"}, {"asset_id": "15086968501686691607738632508897515530788413406991828817382775759887962883365", "price": "0.47", "size": "6694", "side": "BUY", "hash": "91b1ce18e1b5832fe189d96e591a2fa6f5a55b87", "best_bid": "0.48", "best_ask": "0.49"}], "timestamp": "1769384057223", "event_type": "price_change"}}
{"_local_timestamp": "2026-01-25T23:34:17.317789+00:00", "data": {"market": "0xfa5b189b04818014e796a6978b1f1e4f842cec8fe4b0f2aa2daa4b2ab7cc59b3", "price_changes": [{"asset_id": "76097257249586503390123122659919039099107925379782923914081177262841936638457", "price": "0.53", "size": "6798", "side": "SELL", "hash": "e10d0f3c64999329d9c5f27e529f79fd875ae980", "best_bid": "0.51", "best_ask": "0.52"}, {"asset_id": "15086968501686691607738632508897515530788413406991828817382775759887962883365", "price": "0.47", "size": "6798", "side": "BUY", "hash": "6c87437bd28d8cc774d0f47409ef61249f991a70", "best_bid": "0.48", "best_ask": "0.49"}], "timestamp": "1769384057249", "event_type": "price_change"}}
{"_local_timestamp": "2026-01-25T23:34:18.789246+00:00", "data": {"market": "0xfa5b189b04818014e796a6978b1f1e4f842cec8fe4b0f2aa2daa4b2ab7cc59b3", "price_changes": [{"asset_id": "76097257249586503390123122659919039099107925379782923914081177262841936638457", "price": "0.53", "size": "6694", "side": "SELL", "hash": "58bb51c733b7a62fded455b7f1655dd39e4592be", "best_bid": "0.51", "best_ask": "0.52"}, {"asset_id": "15086968501686691607738632508897515530788413406991828817382775759887962883365", "price": "0.47", "size": "6694", "side": "BUY", "hash": "3c43a3cecb6b25afc358895befa544d43afec44a", "best_bid": "0.48", "best_ask": "0.49"}], "timestamp": "1769384058722", "event_type": "price_change"}}
{"_local_timestamp": "2026-01-25T23:34:18.832892+00:00", "data": {"market": "0xfa5b189b04818014e796a6978b1f1e4f842cec8fe4b0f2aa2daa4b2ab7cc59b3", "price_changes": [{"asset_id": "76097257249586503390123122659919039099107925379782923914081177262841936638457", "price": "0.53", "size": "6798", "side": "SELL", "hash": "eb44865b85d5def4226f357be0573bee06116c35", "best_bid": "0.51", "best_ask": "0.52"}, {"asset_id": "15086968501686691607738632508897515530788413406991828817382775759887962883365", "price": "0.47", "size": "6798", "side": "BUY", "hash": "de49edde135a8011f0e8efefe460675443f41035", "best_bid": "0.48", "best_ask": "0.49"}], "timestamp": "1769384058753", "event_type": "price_change"}}
{"_local_timestamp": "2026-01-25T23:34:20.297725+00:00", "data": {"market": "0xfa5b189b04818014e796a6978b1f1e4f842cec8fe4b0f2aa2daa4b2ab7cc59b3", "price_changes": [{"asset_id": "76097257249586503390123122659919039099107925379782923914081177262841936638457", "price": "0.53", "size": "6694", "side": "SELL", "hash": "1317657501ad87f0bd72d6506d13d78cd4046126", "best_bid": "0.51", "best_ask": "0.52"}, {"asset_id": "15086968501686691607738632508897515530788413406991828817382775759887962883365", "price": "0.47", "size": "6694", "side": "BUY", "hash": "4bc61329ccdc7bd8ebbb1b6baa7034288edcbf8e", "best_bid": "0.48", "best_ask": "0.49"}], "timestamp": "1769384060230", "event_type": "price_change"}}
{"_local_timestamp": "2026-01-25T23:34:20.328322+00:00", "data": {"market": "0xfa5b189b04818014e796a6978b1f1e4f842cec8fe4b0f2aa2daa4b2ab7cc59b3", "price_changes": [{"asset_id": "76097257249586503390123122659919039099107925379782923914081177262841936638457", "price": "0.53", "size": "6798", "side": "SELL", "hash": "75b7d7fcb73533c7e7479745a90ad31920280781", "best_bid": "0.51", "best_ask": "0.52"}, {"asset_id": "15086968501686691607738632508897515530788413406991828817382775759887962883365", "price": "0.47", "size": "6798", "side": "BUY", "hash": "fca24e60afe217e10cca0bc0b8489f36a32618ba", "best_bid": "0.48", "best_ask": "0.49"}], "timestamp": "1769384060255", "event_type": "price_change"}}
{"_local_timestamp": "2026-01-25T23:34:21.817660+00:00", "data": {"market": "0xfa5b189b04818014e796a6978b1f1e4f842cec8fe4b0f2aa2daa4b2ab7cc59b3", "price_changes": [{"asset_id": "76097257249586503390123122659919039099107925379782923914081177262841936638457", "price": "0.53", "size": "6694", "side": "SELL", "hash": "45c14c9728be678979d6df689fe3f9de410fa3e1", "best_bid": "0.51", "best_ask": "0.52"}, {"asset_id": "15086968501686691607738632508897515530788413406991828817382775759887962883365", "price": "0.47", "size": "6694", "side": "BUY", "hash": "0f06c1c51df0633ba742965aa216c4b32c57beb2", "best_bid": "0.48", "best_ask": "0.49"}], "timestamp": "1769384061732", "event_type": "price_change"}}
{"_local_timestamp": "2026-01-25T23:34:21.833236+00:00", "data": {"market": "0xfa5b189b04818014e796a6978b1f1e4f842cec8fe4b0f2aa2daa4b2ab7cc59b3", "price_changes": [{"asset_id": "76097257249586503390123122659919039099107925379782923914081177262841936638457", "price": "0.53", "size": "6798", "side": "SELL", "hash": "aebe40c9394a579a4436784db2b2f5a277cf14dd", "best_bid": "0.51", "best_ask": "0.52"}, {"asset_id": "15086968501686691607738632508897515530788413406991828817382775759887962883365", "price": "0.47", "size": "6798", "side": "BUY", "hash": "9813e3cf895d58f721393267ddd38a898488d840", "best_bid": "0.48", "best_ask": "0.49"}], "timestamp": "1769384061759", "event_type": "price_change"}}
{"_local_timestamp": "2026-01-25T23:34:23.299356+00:00", "data": {"market": "0xfa5b189b04818014e796a6978b1f1e4f842cec8fe4b0f2aa2daa4b2ab7cc59b3", "price_changes": [{"asset_id": "76097257249586503390123122659919039099107925379782923914081177262841936638457", "price": "0.53", "size": "6694", "side": "SELL", "hash": "1799797c18998fc038277315cfaf2e9fc26619ab", "best_bid": "0.51", "best_ask": "0.52"}, {"asset_id": "15086968501686691607738632508897515530788413406991828817382775759887962883365", "price": "0.47", "size": "6694", "side": "BUY", "hash": "41d1113c953f79ac83289106e4d78665bf82f66a", "best_bid": "0.48", "best_ask": "0.49"}], "timestamp": "1769384063230", "event_type": "price_change"}}
{"_local_timestamp": "2026-01-25T23:34:23.329637+00:00", "data": {"market": "0xfa5b189b04818014e796a6978b1f1e4f842cec8fe4b0f2aa2daa4b2ab7cc59b3", "price_changes": [{"asset_id": "76097257249586503390123122659919039099107925379782923914081177262841936638457", "price": "0.53", "size": "6798", "side": "SELL", "hash": "7fbb12de72b65aeb7208779ae4d4aa8cd7714c21", "best_bid": "0.51", "best_ask": "0.52"}, {"asset_id": "15086968501686691607738632508897515530788413406991828817382775759887962883365", "price": "0.47", "size": "6798", "side": "BUY", "hash": "e7b517956d4364cbefb79816e6343472a3c055a1", "best_bid": "0.48", "best_ask": "0.49"}], "timestamp": "1769384063259", "event_type": "price_change"}}
{"_local_timestamp": "2026-01-25T23:34:24.796715+00:00", "data": {"market": "0xfa5b189b04818014e796a6978b1f1e4f842cec8fe4b0f2aa2daa4b2ab7cc59b3", "price_changes": [{"asset_id": "76097257249586503390123122659919039099107925379782923914081177262841936638457", "price": "0.53", "size": "6694", "side": "SELL", "hash": "15a55a3c7fde487748772112eeea762606eae43b", "best_bid": "0.51", "best_ask": "0.52"}, {"asset_id": "15086968501686691607738632508897515530788413406991828817382775759887962883365", "price": "0.47", "size": "6694", "side": "BUY", "hash": "67365842cb99e84bd3fe0d390c5d2d9ffa22f05f", "best_bid": "0.48", "best_ask": "0.49"}], "timestamp": "1769384064729", "event_type": "price_change"}}
{"_local_timestamp": "2026-01-25T23:34:24.828995+00:00", "data": {"market": "0xfa5b189b04818014e796a6978b1f1e4f842cec8fe4b0f2aa2daa4b2ab7cc59b3", "price_changes": [{"asset_id": "76097257249586503390123122659919039099107925379782923914081177262841936638457", "price": "0.53", "size": "6798", "side": "SELL", "hash": "d9241a49171e75eb9c1b5e92662da70660f09aa2", "best_bid": "0.51", "best_ask": "0.52"}, {"asset_id": "15086968501686691607738632508897515530788413406991828817382775759887962883365", "price": "0.47", "size": "6798", "side": "BUY", "hash": "b8e67779951ec735159addd2130c310225c53507", "best_bid": "0.48", "best_ask": "0.49"}], "timestamp": "1769384064758", "event_type": "price_change"}}
{"_local_timestamp": "2026-01-25T23:34:26.334061+00:00", "data": {"market": "0xfa5b189b04818014e796a6978b1f1e4f842cec8fe4b0f2aa2daa4b2ab7cc59b3", "price_changes": [{"asset_id": "76097257249586503390123122659919039099107925379782923914081177262841936638457", "price": "0.53", "size": "6694", "side": "SELL", "hash": "f94bd801aed6941e6ba285f560beec77368a0220", "best_bid": "0.51", "best_ask": "0.52"}, {"asset_id": "15086968501686691607738632508897515530788413406991828817382775759887962883365", "price": "0.47", "size": "6694", "side": "BUY", "hash": "368a53863e8f0329772660251fa7499d5604e8a3", "best_bid": "0.48", "best_ask": "0.49"}], "timestamp": "1769384066226", "event_type": "price_change"}}
{"_local_timestamp": "2026-01-25T23:34:26.349695+00:00", "data": {"market": "0xfa5b189b04818014e796a6978b1f1e4f842cec8fe4b0f2aa2daa4b2ab7cc59b3", "price_changes": [{"asset_id": "76097257249586503390123122659919039099107925379782923914081177262841936638457", "price": "0.53", "size": "6798", "side": "SELL", "hash": "6316d64ddae78406bdfd78fbe95a9a024bbeeeb3", "best_bid": "0.51", "best_ask": "0.52"}, {"asset_id": "15086968501686691607738632508897515530788413406991828817382775759887962883365", "price": "0.47", "size": "6798", "side": "BUY", "hash": "5ccc19c74347dc4b2751dde83949cabf99ad9dd7", "best_bid": "0.48", "best_ask": "0.49"}], "timestamp": "1769384066259", "event_type": "price_change"}}
{"_local_timestamp": "2026-01-25T23:34:27.918801+00:00", "data": {"market": "0xfa5b189b04818014e796a6978b1f1e4f842cec8fe4b0f2aa2daa4b2ab7cc59b3", "price_changes": [{"asset_id": "76097257249586503390123122659919039099107925379782923914081177262841936638457", "price": "0.53", "size": "6694", "side": "SELL", "hash": "97970d06ba38d4c4bb8990f84b91a9f79fe66d32", "best_bid": "0.51", "best_ask": "0.52"}, {"asset_id": "15086968501686691607738632508897515530788413406991828817382775759887962883365", "price": "0.47", "size": "6694", "side": "BUY", "hash": "a96c05133c0f3301d9435171656d0e2621d54d2a", "best_bid": "0.48", "best_ask": "0.49"}], "timestamp": "1769384067723", "event_type": "price_change"}}
{"_local_timestamp": "2026-01-25T23:34:27.926868+00:00", "data": {"market": "0xfa5b189b04818014e796a6978b1f1e4f842cec8fe4b0f2aa2daa4b2ab7cc59b3", "price_changes": [{"asset_id": "76097257249586503390123122659919039099107925379782923914081177262841936638457", "price": "0.53", "size": "6798", "side": "SELL", "hash": "903d973046c4632a361a9d88eb70cefa5eaa5b7b", "best_bid": "0.51", "best_ask": "0.52"}, {"asset_id": "15086968501686691607738632508897515530788413406991828817382775759887962883365", "price": "0.47", "size": "6798", "side": "BUY", "hash": "058c64f9d7e803019cc6d01441cdb97abc4539e5", "best_bid": "0.48", "best_ask": "0.49"}], "timestamp": "1769384067750", "event_type": "price_change"}}
{"_local_timestamp": "2026-01-25T23:34:29.293456+00:00", "data": {"market": "0xfa5b189b04818014e796a6978b1f1e4f842cec8fe4b0f2aa2daa4b2ab7cc59b3", "price_changes": [{"asset_id": "76097257249586503390123122659919039099107925379782923914081177262841936638457", "price": "0.53", "size": "6694", "side": "SELL", "hash": "60b352b41a45019fd4d619cc87ac9564226bb650", "best_bid": "0.51", "best_ask": "0.52"}, {"asset_id": "15086968501686691607738632508897515530788413406991828817382775759887962883365", "price": "0.47", "size": "6694", "side": "BUY", "hash": "2e3a90e64cbef257f35b5b75323841bf99500ee3", "best_bid": "0.48", "best_ask": "0.49"}], "timestamp": "1769384069225", "event_type": "price_change"}}
{"_local_timestamp": "2026-01-25T23:34:29.319541+00:00", "data": {"market": "0xfa5b189b04818014e796a6978b1f1e4f842cec8fe4b0f2aa2daa4b2ab7cc59b3", "price_changes": [{"asset_id": "76097257249586503390123122659919039099107925379782923914081177262841936638457", "price": "0.53", "size": "6798", "side": "SELL", "hash": "f345e826354da7325145e86d07b99a87a0bfcc04", "best_bid": "0.51", "best_ask": "0.52"}, {"asset_id": "15086968501686691607738632508897515530788413406991828817382775759887962883365", "price": "0.47", "size": "6798", "side": "BUY", "hash": "ac79fa259cde43b3c6c9ec0883dc34efd9d71abc", "best_bid": "0.48", "best_ask": "0.49"}], "timestamp": "1769384069249", "event_type": "price_change"}}
{"_local_timestamp": "2026-01-25T23:34:30.792726+00:00", "data": {"market": "0xfa5b189b04818014e796a6978b1f1e4f842cec8fe4b0f2aa2daa4b2ab7cc59b3", "price_changes": [{"asset_id": "76097257249586503390123122659919039099107925379782923914081177262841936638457", "price": "0.53", "size": "6694", "side": "SELL", "hash": "b099d787f245793ae7119fac6fbe10a70f22cd2c", "best_bid": "0.51", "best_ask": "0.52"}, {"asset_id": "15086968501686691607738632508897515530788413406991828817382775759887962883365", "price": "0.47", "size": "6694", "side": "BUY", "hash": "664d6265efb706aa1ad0ba62a3a92ccc492d37ea", "best_bid": "0.48", "best_ask": "0.49"}], "timestamp": "1769384070722", "event_type": "price_change"}}
{"_local_timestamp": "2026-01-25T23:34:30.822642+00:00", "data": {"market": "0xfa5b189b04818014e796a6978b1f1e4f842cec8fe4b0f2aa2daa4b2ab7cc59b3", "price_changes": [{"asset_id": "76097257249586503390123122659919039099107925379782923914081177262841936638457", "price": "0.53", "size": "6798", "side": "SELL", "hash": "1dcd9ba95674aa7f3f5091efaf6a8d4b4f4b66c2", "best_bid": "0.51", "best_ask": "0.52"}, {"asset_id": "15086968501686691607738632508897515530788413406991828817382775759887962883365", "price": "0.47", "size": "6798", "side": "BUY", "hash": "02aa78cab7a535449cd519b2998e1e150d3de566", "best_bid": "0.48", "best_ask": "0.49"}], "timestamp": "1769384070752", "event_type": "price_change"}}
{"_local_timestamp": "2026-01-25T23:34:32.345813+00:00", "data": {"market": "0xfa5b189b04818014e796a6978b1f1e4f842cec8fe4b0f2aa2daa4b2ab7cc59b3", "price_changes": [{"asset_id": "76097257249586503390123122659919039099107925379782923914081177262841936638457", "price": "0.53", "size": "6694", "side": "SELL", "hash": "c8ce67339eb340b798a5de428bfdea2196cdc945", "best_bid": "0.51", "best_ask": "0.52"}, {"asset_id": "15086968501686691607738632508897515530788413406991828817382775759887962883365", "price": "0.47", "size": "6694", "side": "BUY", "hash": "bd5a71c6884c968788d593a4de7441233950d596", "best_bid": "0.48", "best_ask": "0.49"}], "timestamp": "1769384072222", "event_type": "price_change"}}
{"_local_timestamp": "2026-01-25T23:34:32.363832+00:00", "data": {"market": "0xfa5b189b04818014e796a6978b1f1e4f842cec8fe4b0f2aa2daa4b2ab7cc59b3", "price_changes": [{"asset_id": "76097257249586503390123122659919039099107925379782923914081177262841936638457", "price": "0.53", "size": "6798", "side": "SELL", "hash": "60753384a129bdc3f6add8ee428913a9f0844f3d", "best_bid": "0.51", "best_ask": "0.52"}, {"asset_id": "15086968501686691607738632508897515530788413406991828817382775759887962883365", "price": "0.47", "size": "6798", "side": "BUY", "hash": "7ab36d70cd08f5997bd00404917abd0e00cd330f", "best_bid": "0.48", "best_ask": "0.49"}], "timestamp": "1769384072250", "event_type": "price_change"}}
{"_local_timestamp": "2026-01-25T23:34:33.800800+00:00", "data": {"market": "0xfa5b189b04818014e796a6978b1f1e4f842cec8fe4b0f2aa2daa4b2ab7cc59b3", "price_changes": [{"asset_id": "76097257249586503390123122659919039099107925379782923914081177262841936638457", "price": "0.53", "size": "6694", "side": "SELL", "hash": "91ec4008bb0b42cfc9ff6320bdba4335f6863fe2", "best_bid": "0.51", "best_ask": "0.52"}, {"asset_id": "15086968501686691607738632508897515530788413406991828817382775759887962883365", "price": "0.47", "size": "6694", "side": "BUY", "hash": "d7082406296a373e0f3ec4e86b81c482433d5207", "best_bid": "0.48", "best_ask": "0.49"}], "timestamp": "1769384073724", "event_type": "price_change"}}
{"_local_timestamp": "2026-01-25T23:34:33.815004+00:00", "data": {"market": "0xfa5b189b04818014e796a6978b1f1e4f842cec8fe4b0f2aa2daa4b2ab7cc59b3", "price_changes": [{"asset_id": "76097257249586503390123122659919039099107925379782923914081177262841936638457", "price": "0.53", "size": "6798", "side": "SELL", "hash": "013ca4a2d5f714d738933f527ec3af310be9140c", "best_bid": "0.51", "best_ask": "0.52"}, {"asset_id": "15086968501686691607738632508897515530788413406991828817382775759887962883365", "price": "0.47", "size": "6798", "side": "BUY", "hash": "661de5bf0ca9d306e2405e2dcaa6f2702147c48e", "best_bid": "0.48", "best_ask": "0.49"}], "timestamp": "1769384073748", "event_type": "price_change"}}
{"_local_timestamp": "2026-01-25T23:34:35.299856+00:00", "data": {"market": "0xfa5b189b04818014e796a6978b1f1e4f842cec8fe4b0f2aa2daa4b2ab7cc59b3", "price_changes": [{"asset_id": "76097257249586503390123122659919039099107925379782923914081177262841936638457", "price": "0.53", "size": "6694", "side": "SELL", "hash": "6e2d5c13d233ea03ca52a7050b15cc853a19a093", "best_bid": "0.51", "best_ask": "0.52"}, {"asset_id": "15086968501686691607738632508897515530788413406991828817382775759887962883365", "price": "0.47", "size": "6694", "side": "BUY", "hash": "1bb68c3c3ba7820403d6639e6e28740134854d68", "best_bid": "0.48", "best_ask": "0.49"}], "timestamp": "1769384075227", "event_type": "price_change"}}
{"_local_timestamp": "2026-01-25T23:34:35.330940+00:00", "data": {"market": "0xfa5b189b04818014e796a6978b1f1e4f842cec8fe4b0f2aa2daa4b2ab7cc59b3", "price_changes": [{"asset_id": "76097257249586503390123122659919039099107925379782923914081177262841936638457", "price": "0.53", "size": "6798", "side": "SELL", "hash": "2cc1d73b6f8ca39353564f71106ffe26532503c3", "best_bid": "0.51", "best_ask": "0.52"}, {"asset_id": "15086968501686691607738632508897515530788413406991828817382775759887962883365", "price": "0.47", "size": "6798", "side": "BUY", "hash": "d8c386e75234b4a4e2b3624bea500c1a5d115a2b", "best_bid": "0.48", "best_ask": "0.49"}], "timestamp": "1769384075256", "event_type": "price_change"}}
{"_local_timestamp": "2026-01-25T23:34:36.800627+00:00", "data": {"market": "0xfa5b189b04818014e796a6978b1f1e4f842cec8fe4b0f2aa2daa4b2ab7cc59b3", "price_changes": [{"asset_id": "76097257249586503390123122659919039099107925379782923914081177262841936638457", "price": "0.53", "size": "6694", "side": "SELL", "hash": "59a38308d2c87e0b5d44ddb8e1ed4ba87fc0c181", "best_bid": "0.51", "best_ask": "0.52"}, {"asset_id": "15086968501686691607738632508897515530788413406991828817382775759887962883365", "price": "0.47", "size": "6694", "side": "BUY", "hash": "0682c190284dc011e5c49820bd96d33492e45d0f", "best_bid": "0.48", "best_ask": "0.49"}], "timestamp": "1769384076722", "event_type": "price_change"}}
{"_local_timestamp": "2026-01-25T23:34:36.843055+00:00", "data": {"market": "0xfa5b189b04818014e796a6978b1f1e4f842cec8fe4b0f2aa2daa4b2ab7cc59b3", "price_changes": [{"asset_id": "76097257249586503390123122659919039099107925379782923914081177262841936638457", "price": "0.53", "size": "6798", "side": "SELL", "hash": "66f7a9219745de063f41b66021db82d786c2424f", "best_bid": "0.51", "best_ask": "0.52"}, {"asset_id": "15086968501686691607738632508897515530788413406991828817382775759887962883365", "price": "0.47", "size": "6798", "side": "BUY", "hash": "282485d3ee2ab54a414f5471cf6d903fbef37c76", "best_bid": "0.48", "best_ask": "0.49"}], "timestamp": "1769384076763", "event_type": "price_change"}}
{"_local_timestamp": "2026-01-25T23:34:38.290034+00:00", "data": {"market": "0xfa5b189b04818014e796a6978b1f1e4f842cec8fe4b0f2aa2daa4b2ab7cc59b3", "price_changes": [{"asset_id": "76097257249586503390123122659919039099107925379782923914081177262841936638457", "price": "0.53", "size": "6694", "side": "SELL", "hash": "424d06c6fc8027c934dd047803754ec881bd1013", "best_bid": "0.51", "best_ask": "0.52"}, {"asset_id": "15086968501686691607738632508897515530788413406991828817382775759887962883365", "price": "0.47", "size": "6694", "side": "BUY", "hash": "a8af720d9917c06acb7c5e3027412cc51693cbf4", "best_bid": "0.48", "best_ask": "0.49"}], "timestamp": "1769384078222", "event_type": "price_change"}}
{"_local_timestamp": "2026-01-25T23:34:38.325483+00:00", "data": {"market": "0xfa5b189b04818014e796a6978b1f1e4f842cec8fe4b0f2aa2daa4b2ab7cc59b3", "price_changes": [{"asset_id": "76097257249586503390123122659919039099107925379782923914081177262841936638457", "price": "0.53", "size": "6798", "side": "SELL", "hash": "2f034029935586a535912d20cf33aa5fd4432698", "best_bid": "0.51", "best_ask": "0.52"}, {"asset_id": "15086968501686691607738632508897515530788413406991828817382775759887962883365", "price": "0.47", "size": "6798", "side": "BUY", "hash": "f43a4c3437549c6962d549624be26f22984712b8", "best_bid": "0.48", "best_ask": "0.49"}], "timestamp": "1769384078256", "event_type": "price_change"}}
{"_local_timestamp": "2026-01-25T23:34:39.802597+00:00", "data": {"market": "0xfa5b189b04818014e796a6978b1f1e4f842cec8fe4b0f2aa2daa4b2ab7cc59b3", "price_changes": [{"asset_id": "76097257249586503390123122659919039099107925379782923914081177262841936638457", "price": "0.53", "size": "6694", "side": "SELL", "hash": "f9d1b6e1a24a3fbec31947984e5a42fbbb3adadb", "best_bid": "0.51", "best_ask": "0.52"}, {"asset_id": "15086968501686691607738632508897515530788413406991828817382775759887962883365", "price": "0.47", "size": "6694", "side": "BUY", "hash": "494b03d6157a4642210c366a2ca40230050800a3", "best_bid": "0.48", "best_ask": "0.49"}], "timestamp": "1769384079729", "event_type": "price_change"}}
{"_local_timestamp": "2026-01-25T23:34:39.832557+00:00", "data": {"market": "0xfa5b189b04818014e796a6978b1f1e4f842cec8fe4b0f2aa2daa4b2ab7cc59b3", "price_changes": [{"asset_id": "76097257249586503390123122659919039099107925379782923914081177262841936638457", "price": "0.53", "size": "6798", "side": "SELL", "hash": "93ba3e2ca3643de2edd85fb8dc3d6f10986158dc", "best_bid": "0.51", "best_ask": "0.52"}, {"asset_id": "15086968501686691607738632508897515530788413406991828817382775759887962883365", "price": "0.47", "size": "6798", "side": "BUY", "hash": "fd748c14db81b3b6f934db35d2e7f3056ed557df", "best_bid": "0.48", "best_ask": "0.49"}], "timestamp": "1769384079761", "event_type": "price_change"}}
{"_local_timestamp": "2026-01-25T23:34:41.293366+00:00", "data": {"market": "0xfa5b189b04818014e796a6978b1f1e4f842cec8fe4b0f2aa2daa4b2ab7cc59b3", "price_changes": [{"asset_id": "76097257249586503390123122659919039099107925379782923914081177262841936638457", "price": "0.53", "size": "6694", "side": "SELL", "hash": "ea68de136aebae520809cb8991d19337ab48f9f1", "best_bid": "0.51", "best_ask": "0.52"}, {"asset_id": "15086968501686691607738632508897515530788413406991828817382775759887962883365", "price": "0.47", "size": "6694", "side": "BUY", "hash": "58c0f5282a5371fab86d491ed399a4e4b9eedbea", "best_bid": "0.48", "best_ask": "0.49"}], "timestamp": "1769384081225", "event_type": "price_change"}}
{"_local_timestamp": "2026-01-25T23:34:41.323128+00:00", "data": {"market": "0xfa5b189b04818014e796a6978b1f1e4f842cec8fe4b0f2aa2daa4b2ab7cc59b3", "price_changes": [{"asset_id": "76097257249586503390123122659919039099107925379782923914081177262841936638457", "price": "0.53", "size": "6798", "side": "SELL", "hash": "cfbd851c385ae188f866996ae23916e60f507996", "best_bid": "0.51", "best_ask": "0.52"}, {"asset_id": "15086968501686691607738632508897515530788413406991828817382775759887962883365", "price": "0.47", "size": "6798", "side": "BUY", "hash": "8ea44a3d4a98a668863453194d012182797b8383", "best_bid": "0.48", "best_ask": "0.49"}], "timestamp": "1769384081254", "event_type": "price_change"}}
{"_local_timestamp": "2026-01-25T23:34:42.791094+00:00", "data": {"market": "0xfa5b189b04818014e796a6978b1f1e4f842cec8fe4b0f2aa2daa4b2ab7cc59b3", "price_changes": [{"asset_id": "76097257249586503390123122659919039099107925379782923914081177262841936638457", "price": "0.53", "size": "6694", "side": "SELL", "hash": "342ab85fdb58b4c653a7b4d51485de1a62460ceb", "best_bid": "0.51", "best_ask": "0.52"}, {"asset_id": "15086968501686691607738632508897515530788413406991828817382775759887962883365", "price": "0.47", "size": "6694", "side": "BUY", "hash": "623b15026f20ae2f53141c07aa3e108b8b7289fa", "best_bid": "0.48", "best_ask": "0.49"}], "timestamp": "1769384082724", "event_type": "price_change"}}
{"_local_timestamp": "2026-01-25T23:34:42.822149+00:00", "data": {"market": "0xfa5b189b04818014e796a6978b1f1e4f842cec8fe4b0f2aa2daa4b2ab7cc59b3", "price_changes": [{"asset_id": "76097257249586503390123122659919039099107925379782923914081177262841936638457", "price": "0.53", "size": "6798", "side": "SELL", "hash": "39e8c85e2ecece6a7898359b706172bbc4f0325f", "best_bid": "0.51", "best_ask": "0.52"}, {"asset_id": "15086968501686691607738632508897515530788413406991828817382775759887962883365", "price": "0.47", "size": "6798", "side": "BUY", "hash": "e286c0f1d024ddab7ae21a6549d374204500e618", "best_bid": "0.48", "best_ask": "0.49"}], "timestamp": "1769384082750", "event_type": "price_change"}}
{"_local_timestamp": "2026-01-25T23:34:44.294335+00:00", "data": {"market": "0xfa5b189b04818014e796a6978b1f1e4f842cec8fe4b0f2aa2daa4b2ab7cc59b3", "price_changes": [{"asset_id": "76097257249586503390123122659919039099107925379782923914081177262841936638457", "price": "0.53", "size": "6694", "side": "SELL", "hash": "ceaf839989db588fc280ffa352b706416e86febe", "best_bid": "0.51", "best_ask": "0.52"}, {"asset_id": "15086968501686691607738632508897515530788413406991828817382775759887962883365", "price": "0.47", "size": "6694", "side": "BUY", "hash": "fd2023b204a41197da63e75a2da8539c5f8ca721", "best_bid": "0.48", "best_ask": "0.49"}], "timestamp": "1769384084224", "event_type": "price_change"}}
{"_local_timestamp": "2026-01-25T23:34:44.318062+00:00", "data": {"market": "0xfa5b189b04818014e796a6978b1f1e4f842cec8fe4b0f2aa2daa4b2ab7cc59b3", "price_changes": [{"asset_id": "76097257249586503390123122659919039099107925379782923914081177262841936638457", "price": "0.53", "size": "6798", "side": "SELL", "hash": "53aa07d87d5b21b3fc3de15897a5992ad54b0274", "best_bid": "0.51", "best_ask": "0.52"}, {"asset_id": "15086968501686691607738632508897515530788413406991828817382775759887962883365", "price": "0.47", "size": "6798", "side": "BUY", "hash": "7a338bd4e0e65eb4b1069d76e0e2c8dd7f3c546f", "best_bid": "0.48", "best_ask": "0.49"}], "timestamp": "1769384084249", "event_type": "price_change"}}
{"_local_timestamp": "2026-01-25T23:34:45.797924+00:00", "data": {"market": "0xfa5b189b04818014e796a6978b1f1e4f842cec8fe4b0f2aa2daa4b2ab7cc59b3", "price_changes": [{"asset_id": "76097257249586503390123122659919039099107925379782923914081177262841936638457", "price": "0.53", "size": "6694", "side": "SELL", "hash": "aa83b361a55887e84c3f34d5ca5eb8e1e48915fe", "best_bid": "0.51", "best_ask": "0.52"}, {"asset_id": "15086968501686691607738632508897515530788413406991828817382775759887962883365", "price": "0.47", "size": "6694", "side": "BUY", "hash": "fd415ad44769bc360398ca68ac34331adf71ce5b", "best_bid": "0.48", "best_ask": "0.49"}], "timestamp": "1769384085728", "event_type": "price_change"}}
{"_local_timestamp": "2026-01-25T23:34:45.826532+00:00", "data": {"market": "0xfa5b189b04818014e796a6978b1f1e4f842cec8fe4b0f2aa2daa4b2ab7cc59b3", "price_changes": [{"asset_id": "76097257249586503390123122659919039099107925379782923914081177262841936638457", "price": "0.53", "size": "6798", "side": "SELL", "hash": "22702316d8687c38457c15eedf6041b86cbd8d37", "best_bid": "0.51", "best_ask": "0.52"}, {"asset_id": "15086968501686691607738632508897515530788413406991828817382775759887962883365", "price": "0.47", "size": "6798", "side": "BUY", "hash": "cd16099074a6992bd184f2ede1989db45f5c9599", "best_bid": "0.48", "best_ask": "0.49"}], "timestamp": "1769384085756", "event_type": "price_change"}}
{"_local_timestamp": "2026-01-25T23:34:47.290091+00:00", "data": {"market": "0xfa5b189b04818014e796a6978b1f1e4f842cec8fe4b0f2aa2daa4b2ab7cc59b3", "price_changes": [{"asset_id": "76097257249586503390123122659919039099107925379782923914081177262841936638457", "price": "0.53", "size": "6694", "side": "SELL", "hash": "04266ff56e40fe414d77f4c0239c2768df4d68b8", "best_bid": "0.51", "best_ask": "0.52"}, {"asset_id": "15086968501686691607738632508897515530788413406991828817382775759887962883365", "price": "0.47", "size": "6694", "side": "BUY", "hash": "240241513e5bc96a1c505bdc14f0b6dab8ce4128", "best_bid": "0.48", "best_ask": "0.49"}], "timestamp": "1769384087222", "event_type": "price_change"}}
{"_local_timestamp": "2026-01-25T23:34:47.316532+00:00", "data": {"market": "0xfa5b189b04818014e796a6978b1f1e4f842cec8fe4b0f2aa2daa4b2ab7cc59b3", "price_changes": [{"asset_id": "76097257249586503390123122659919039099107925379782923914081177262841936638457", "price": "0.53", "size": "6798", "side": "SELL", "hash": "d959bb52c2fa83bbc57841f49334731bd4b5598f", "best_bid": "0.51", "best_ask": "0.52"}, {"asset_id": "15086968501686691607738632508897515530788413406991828817382775759887962883365", "price": "0.47", "size": "6798", "side": "BUY", "hash": "eef21456d07efed2e59189331922fbfe1d9a354c", "best_bid": "0.48", "best_ask": "0.49"}], "timestamp": "1769384087248", "event_type": "price_change"}}
{"_local_timestamp": "2026-01-25T23:34:48.796464+00:00", "data": {"market": "0xfa5b189b04818014e796a6978b1f1e4f842cec8fe4b0f2aa2daa4b2ab7cc59b3", "price_changes": [{"asset_id": "76097257249586503390123122659919039099107925379782923914081177262841936638457", "price": "0.53", "size": "6694", "side": "SELL", "hash": "980e876cd9839b4a16e55e291ada45d964609598", "best_bid": "0.51", "best_ask": "0.52"}, {"asset_id": "15086968501686691607738632508897515530788413406991828817382775759887962883365", "price": "0.47", "size": "6694", "side": "BUY", "hash": "05e6fc4ef7eba3028a56306a08e742ceec27ea94", "best_bid": "0.48", "best_ask": "0.49"}], "timestamp": "1769384088728", "event_type": "price_change"}}
{"_local_timestamp": "2026-01-25T23:34:48.824888+00:00", "data": {"market": "0xfa5b189b04818014e796a6978b1f1e4f842cec8fe4b0f2aa2daa4b2ab7cc59b3", "price_changes": [{"asset_id": "76097257249586503390123122659919039099107925379782923914081177262841936638457", "price": "0.53", "size": "6798", "side": "SELL", "hash": "3d6368885ac39380f182140816c0cbb8707db6bb", "best_bid": "0.51", "best_ask": "0.52"}, {"asset_id": "15086968501686691607738632508897515530788413406991828817382775759887962883365", "price": "0.47", "size": "6798", "side": "BUY", "hash": "50d4ad2734aa028be77b0fcd5a029648008362bd", "best_bid": "0.48", "best_ask": "0.49"}], "timestamp": "1769384088757", "event_type": "price_change"}}
{"_local_timestamp": "2026-01-25T23:34:50.298658+00:00", "data": {"market": "0xfa5b189b04818014e796a6978b1f1e4f842cec8fe4b0f2aa2daa4b2ab7cc59b3", "price_changes": [{"asset_id": "76097257249586503390123122659919039099107925379782923914081177262841936638457", "price": "0.53", "size": "6694", "side": "SELL", "hash": "ed210f93a31bbcebd6ad4aecdc3fb616fa5182db", "best_bid": "0.51", "best_ask": "0.52"}, {"asset_id": "15086968501686691607738632508897515530788413406991828817382775759887962883365", "price": "0.47", "size": "6694", "side": "BUY", "hash": "c9c7588bc0889245aec7972ff1c24fae16bfb0bd", "best_bid": "0.48", "best_ask": "0.49"}], "timestamp": "1769384090227", "event_type": "price_change"}}
{"_local_timestamp": "2026-01-25T23:34:50.781291+00:00", "data": {"market": "0xfa5b189b04818014e796a6978b1f1e4f842cec8fe4b0f2aa2daa4b2ab7cc59b3", "price_changes": [{"asset_id": "76097257249586503390123122659919039099107925379782923914081177262841936638457", "price": "0.53", "size": "6798", "side": "SELL", "hash": "bac83cd6f9e271bc695cb61e312f6562daad0f9a", "best_bid": "0.51", "best_ask": "0.52"}, {"asset_id": "15086968501686691607738632508897515530788413406991828817382775759887962883365", "price": "0.47", "size": "6798", "side": "BUY", "hash": "2443ad1d66f36ed47cdbbf0104232b5c0b83be9c", "best_bid": "0.48", "best_ask": "0.49"}], "timestamp": "1769384090255", "event_type": "price_change"}}
{"_local_timestamp": "2026-01-25T23:34:51.792794+00:00", "data": {"market": "0xfa5b189b04818014e796a6978b1f1e4f842cec8fe4b0f2aa2daa4b2ab7cc59b3", "price_changes": [{"asset_id": "76097257249586503390123122659919039099107925379782923914081177262841936638457", "price": "0.53", "size": "6694", "side": "SELL", "hash": "399f6ff6dd5b7aac00b8b3b5ae916248c107c0b5", "best_bid": "0.51", "best_ask": "0.52"}, {"asset_id": "15086968501686691607738632508897515530788413406991828817382775759887962883365", "price": "0.47", "size": "6694", "side": "BUY", "hash": "17103efa210142e5a9c9716d7bb8e63d60718256", "best_bid": "0.48", "best_ask": "0.49"}], "timestamp": "1769384091725", "event_type": "price_change"}}
{"_local_timestamp": "2026-01-25T23:34:51.820592+00:00", "data": {"market": "0xfa5b189b04818014e796a6978b1f1e4f842cec8fe4b0f2aa2daa4b2ab7cc59b3", "price_changes": [{"asset_id": "76097257249586503390123122659919039099107925379782923914081177262841936638457", "price": "0.53", "size": "6798", "side": "SELL", "hash": "9a6b5b0b104f80b108c603a9b85405e1d76d4e26", "best_bid": "0.51", "best_ask": "0.52"}, {"asset_id": "15086968501686691607738632508897515530788413406991828817382775759887962883365", "price": "0.47", "size": "6798", "side": "BUY", "hash": "11063d7ab0804413c75804d964048fbb42e4370a", "best_bid": "0.48", "best_ask": "0.49"}], "timestamp": "1769384091749", "event_type": "price_change"}}
{"_local_timestamp": "2026-01-25T23:34:53.298521+00:00", "data": {"market": "0xfa5b189b04818014e796a6978b1f1e4f842cec8fe4b0f2aa2daa4b2ab7cc59b3", "price_changes": [{"asset_id": "76097257249586503390123122659919039099107925379782923914081177262841936638457", "price": "0.53", "size": "6694", "side": "SELL", "hash": "91cf337cd2e474b14d56cad5c66225045085c943", "best_bid": "0.51", "best_ask": "0.52"}, {"asset_id": "15086968501686691607738632508897515530788413406991828817382775759887962883365", "price": "0.47", "size": "6694", "side": "BUY", "hash": "0b842232e1f16d89dd35b870602b4b43e68429f9", "best_bid": "0.48", "best_ask": "0.49"}], "timestamp": "1769384093229", "event_type": "price_change"}}
{"_local_timestamp": "2026-01-25T23:34:53.324588+00:00", "data": {"market": "0xfa5b189b04818014e796a6978b1f1e4f842cec8fe4b0f2aa2daa4b2ab7cc59b3", "price_changes": [{"asset_id": "76097257249586503390123122659919039099107925379782923914081177262841936638457", "price": "0.53", "size": "6798", "side": "SELL", "hash": "fef03ee558d6ea458c62200471ba68ae0f3088c8", "best_bid": "0.51", "best_ask": "0.52"}, {"asset_id": "15086968501686691607738632508897515530788413406991828817382775759887962883365", "price": "0.47", "size": "6798", "side": "BUY", "hash": "c07acb0bb46fcb0e6773b9f703a274ccd8322589", "best_bid": "0.48", "best_ask": "0.49"}], "timestamp": "1769384093257", "event_type": "price_change"}}
{"_local_timestamp": "2026-01-25T23:34:54.789566+00:00", "data": {"market": "0xfa5b189b04818014e796a6978b1f1e4f842cec8fe4b0f2aa2daa4b2ab7cc59b3", "price_changes": [{"asset_id": "76097257249586503390123122659919039099107925379782923914081177262841936638457", "price": "0.53", "size": "6694", "side": "SELL", "hash": "ec8542e117ac5f50530b90ff2c2f3ae15215c628", "best_bid": "0.51", "best_ask": "0.52"}, {"asset_id": "15086968501686691607738632508897515530788413406991828817382775759887962883365", "price": "0.47", "size": "6694", "side": "BUY", "hash": "455bab425c1bc7729f2ac11e29d8b1ea0f026891", "best_bid": "0.48", "best_ask": "0.49"}], "timestamp": "1769384094722", "event_type": "price_change"}}
{"_local_timestamp": "2026-01-25T23:34:54.821414+00:00", "data": {"market": "0xfa5b189b04818014e796a6978b1f1e4f842cec8fe4b0f2aa2daa4b2ab7cc59b3", "price_changes": [{"asset_id": "76097257249586503390123122659919039099107925379782923914081177262841936638457", "price": "0.53", "size": "6798", "side": "SELL", "hash": "4421d6bb719993db3367c9eb363786f7181d7487", "best_bid": "0.51", "best_ask": "0.52"}, {"asset_id": "15086968501686691607738632508897515530788413406991828817382775759887962883365", "price": "0.47", "size": "6798", "side": "BUY", "hash": "a6c29d343f0ef162304d2b9480bd03933b94b214", "best_bid": "0.48", "best_ask": "0.49"}], "timestamp": "1769384094750", "event_type": "price_change"}}
{"_local_timestamp": "2026-01-25T23:34:56.292636+00:00", "data": {"market": "0xfa5b189b04818014e796a6978b1f1e4f842cec8fe4b0f2aa2daa4b2ab7cc59b3", "price_changes": [{"asset_id": "76097257249586503390123122659919039099107925379782923914081177262841936638457", "price": "0.53", "size": "6694", "side": "SELL", "hash": "880a1e3ac6ac5c584f7f9348870b375061227593", "best_bid": "0.51", "best_ask": "0.52"}, {"asset_id": "15086968501686691607738632508897515530788413406991828817382775759887962883365", "price": "0.47", "size": "6694", "side": "BUY", "hash": "50e4e451a450e693efd097701921b75efca7404a", "best_bid": "0.48", "best_ask": "0.49"}], "timestamp": "1769384096223", "event_type": "price_change"}}
{"_local_timestamp": "2026-01-25T23:34:56.322751+00:00", "data": {"market": "0xfa5b189b04818014e796a6978b1f1e4f842cec8fe4b0f2aa2daa4b2ab7cc59b3", "price_changes": [{"asset_id": "76097257249586503390123122659919039099107925379782923914081177262841936638457", "price": "0.53", "size": "6798", "side": "SELL", "hash": "83aedb4babe19e02087e97ca2c38834b00c30187", "best_bid": "0.51", "best_ask": "0.52"}, {"asset_id": "15086968501686691607738632508897515530788413406991828817382775759887962883365", "price": "0.47", "size": "6798", "side": "BUY", "hash": "ec18784000f1e05b65a459617129efd6cae12fad", "best_bid": "0.48", "best_ask": "0.49"}], "timestamp": "1769384096250", "event_type": "price_change"}}
{"_local_timestamp": "2026-01-25T23:34:57.798670+00:00", "data": {"market": "0xfa5b189b04818014e796a6978b1f1e4f842cec8fe4b0f2aa2daa4b2ab7cc59b3", "price_changes": [{"asset_id": "76097257249586503390123122659919039099107925379782923914081177262841936638457", "price": "0.53", "size": "6694", "side": "SELL", "hash": "3181267487a344d4058db474c00fa85cf94c9248", "best_bid": "0.51", "best_ask": "0.52"}, {"asset_id": "15086968501686691607738632508897515530788413406991828817382775759887962883365", "price": "0.47", "size": "6694", "side": "BUY", "hash": "68b2e1db4a75ab8a0be22a084c9ec9507b34a86d", "best_bid": "0.48", "best_ask": "0.49"}], "timestamp": "1769384097724", "event_type": "price_change"}}
{"_local_timestamp": "2026-01-25T23:34:57.821558+00:00", "data": {"market": "0xfa5b189b04818014e796a6978b1f1e4f842cec8fe4b0f2aa2daa4b2ab7cc59b3", "price_changes": [{"asset_id": "76097257249586503390123122659919039099107925379782923914081177262841936638457", "price": "0.53", "size": "6798", "side": "SELL", "hash": "5ff166beb109cd7e5494855b28c28210030d0e35", "best_bid": "0.51", "best_ask": "0.52"}, {"asset_id": "15086968501686691607738632508897515530788413406991828817382775759887962883365", "price": "0.47", "size": "6798", "side": "BUY", "hash": "08bffc714d06b3c12fc93dd728f57e4a3dc2c3c8", "best_bid": "0.48", "best_ask": "0.49"}], "timestamp": "1769384097750", "event_type": "price_change"}}
{"_local_timestamp": "2026-01-25T23:34:59.291370+00:00", "data": {"market": "0xfa5b189b04818014e796a6978b1f1e4f842cec8fe4b0f2aa2daa4b2ab7cc59b3", "price_changes": [{"asset_id": "76097257249586503390123122659919039099107925379782923914081177262841936638457", "price": "0.53", "size": "6694", "side": "SELL", "hash": "bc3e95fb94dd4318234e8e5b31b91965fd48ab5b", "best_bid": "0.51", "best_ask": "0.52"}, {"asset_id": "15086968501686691607738632508897515530788413406991828817382775759887962883365", "price": "0.47", "size": "6694", "side": "BUY", "hash": "7441552f136a72c6d23e8be52348b52c93933fc5", "best_bid": "0.48", "best_ask": "0.49"}], "timestamp": "1769384099223", "event_type": "price_change"}}
{"_local_timestamp": "2026-01-25T23:34:59.325912+00:00", "data": {"market": "0xfa5b189b04818014e796a6978b1f1e4f842cec8fe4b0f2aa2daa4b2ab7cc59b3", "price_changes": [{"asset_id": "76097257249586503390123122659919039099107925379782923914081177262841936638457", "price": "0.53", "size": "6798", "side": "SELL", "hash": "69af0e097059b5817b72dc180ced251bed595448", "best_bid": "0.51", "best_ask": "0.52"}, {"asset_id": "15086968501686691607738632508897515530788413406991828817382775759887962883365", "price": "0.47", "size": "6798", "side": "BUY", "hash": "0b9a65b09845f0b178915375aea73dc2c244785e", "best_bid": "0.48", "best_ask": "0.49"}], "timestamp": "1769384099250", "event_type": "price_change"}}
{"_local_timestamp": "2026-01-25T23:35:00.809946+00:00", "data": {"market": "0xfa5b189b04818014e796a6978b1f1e4f842cec8fe4b0f2aa2daa4b2ab7cc59b3", "price_changes": [{"asset_id": "76097257249586503390123122659919039099107925379782923914081177262841936638457", "price": "0.53", "size": "6694", "side": "SELL", "hash": "deef2b638a5a91d318ab7b9f925b2ad3e27da1b0", "best_bid": "0.51", "best_ask": "0.52"}, {"asset_id": "15086968501686691607738632508897515530788413406991828817382775759887962883365", "price": "0.47", "size": "6694", "side": "BUY", "hash": "4d78389b3b896d2fcb74822229c63c2c693ee869", "best_bid": "0.48", "best_ask": "0.49"}], "timestamp": "1769384100727", "event_type": "price_change"}}
{"_local_timestamp": "2026-01-25T23:35:00.838503+00:00", "data": {"market": "0xfa5b189b04818014e796a6978b1f1e4f842cec8fe4b0f2aa2daa4b2ab7cc59b3", "price_changes": [{"asset_id": "76097257249586503390123122659919039099107925379782923914081177262841936638457", "price": "0.53", "size": "6798", "side": "SELL", "hash": "d147746322054cb6f2d2c272c0d197fae82bef30", "best_bid": "0.51", "best_ask": "0.52"}, {"asset_id": "15086968501686691607738632508897515530788413406991828817382775759887962883365", "price": "0.47", "size": "6798", "side": "BUY", "hash": "71943ef913a259e54aa6f92a0d5885faee2fe08f", "best_bid": "0.48", "best_ask": "0.49"}], "timestamp": "1769384100753", "event_type": "price_change"}}
{"_local_timestamp": "2026-01-25T23:35:02.461155+00:00", "data": {"market": "0xfa5b189b04818014e796a6978b1f1e4f842cec8fe4b0f2aa2daa4b2ab7cc59b3", "price_changes": [{"asset_id": "76097257249586503390123122659919039099107925379782923914081177262841936638457", "price": "0.53", "size": "6694", "side": "SELL", "hash": "3c6ccecf776ed7df1936b29565635fd5b4383c23", "best_bid": "0.51", "best_ask": "0.52"}, {"asset_id": "15086968501686691607738632508897515530788413406991828817382775759887962883365", "price": "0.47", "size": "6694", "side": "BUY", "hash": "55876a9c2e6e3086761cedc313f8f01072ee89f8", "best_bid": "0.48", "best_ask": "0.49"}], "timestamp": "1769384102315", "event_type": "price_change"}}
{"_local_timestamp": "2026-01-25T23:35:02.510322+00:00", "data": {"market": "0xfa5b189b04818014e796a6978b1f1e4f842cec8fe4b0f2aa2daa4b2ab7cc59b3", "price_changes": [{"asset_id": "76097257249586503390123122659919039099107925379782923914081177262841936638457", "price": "0.53", "size": "6798", "side": "SELL", "hash": "cfe46ffcc8128d263735a0df852fa995a8eb32af", "best_bid": "0.51", "best_ask": "0.52"}, {"asset_id": "15086968501686691607738632508897515530788413406991828817382775759887962883365", "price": "0.47", "size": "6798", "side": "BUY", "hash": "c9c8156aabfb299a45152fb3a058c14cef426c13", "best_bid": "0.48", "best_ask": "0.49"}], "timestamp": "1769384102357", "event_type": "price_change"}}
{"_local_timestamp": "2026-01-25T23:35:03.856930+00:00", "data": {"market": "0xfa5b189b04818014e796a6978b1f1e4f842cec8fe4b0f2aa2daa4b2ab7cc59b3", "price_changes": [{"asset_id": "76097257249586503390123122659919039099107925379782923914081177262841936638457", "price": "0.53", "size": "6694", "side": "SELL", "hash": "fbeac21587ed1bfc43043963a569be6dfd3d9c73", "best_bid": "0.51", "best_ask": "0.52"}, {"asset_id": "15086968501686691607738632508897515530788413406991828817382775759887962883365", "price": "0.47", "size": "6694", "side": "BUY", "hash": "6f5c01f69c307174956c40c95d0537def524d4e3", "best_bid": "0.48", "best_ask": "0.49"}], "timestamp": "1769384103726", "event_type": "price_change"}}
{"_local_timestamp": "2026-01-25T23:35:03.891245+00:00", "data": {"market": "0xfa5b189b04818014e796a6978b1f1e4f842cec8fe4b0f2aa2daa4b2ab7cc59b3", "price_changes": [{"asset_id": "76097257249586503390123122659919039099107925379782923914081177262841936638457", "price": "0.53", "size": "6798", "side": "SELL", "hash": "524ffe138f33b088fe3708317657f37c0ea89065", "best_bid": "0.51", "best_ask": "0.52"}, {"asset_id": "15086968501686691607738632508897515530788413406991828817382775759887962883365", "price": "0.47", "size": "6798", "side": "BUY", "hash": "d55d6d89b2fcfc2b90d0d4bbb516ebddf11965db", "best_bid": "0.48", "best_ask": "0.49"}], "timestamp": "1769384103756", "event_type": "price_change"}}
{"_local_timestamp": "2026-01-25T23:35:05.374143+00:00", "data": {"market": "0xfa5b189b04818014e796a6978b1f1e4f842cec8fe4b0f2aa2daa4b2ab7cc59b3", "price_changes": [{"asset_id": "76097257249586503390123122659919039099107925379782923914081177262841936638457", "price": "0.53", "size": "6694", "side": "SELL", "hash": "ed103dfd8fe71363ea1dded126a529d887e834d6", "best_bid": "0.51", "best_ask": "0.52"}, {"asset_id": "15086968501686691607738632508897515530788413406991828817382775759887962883365", "price": "0.47", "size": "6694", "side": "BUY", "hash": "5cb53ed73c6579e9cfd91e58e6a2af4f57d25585", "best_bid": "0.48", "best_ask": "0.49"}], "timestamp": "1769384105224", "event_type": "price_change"}}
{"_local_timestamp": "2026-01-25T23:35:05.412751+00:00", "data": {"market": "0xfa5b189b04818014e796a6978b1f1e4f842cec8fe4b0f2aa2daa4b2ab7cc59b3", "price_changes": [{"asset_id": "76097257249586503390123122659919039099107925379782923914081177262841936638457", "price": "0.53", "size": "6798", "side": "SELL", "hash": "918adbdd5a37a3970ac5a38026061022136ff52b", "best_bid": "0.51", "best_ask": "0.52"}, {"asset_id": "15086968501686691607738632508897515530788413406991828817382775759887962883365", "price": "0.47", "size": "6798", "side": "BUY", "hash": "331c7146bc8ed5076f08d21019294b8624b4fefb", "best_bid": "0.48", "best_ask": "0.49"}], "timestamp": "1769384105257", "event_type": "price_change"}}
{"_local_timestamp": "2026-01-25T23:35:06.637648+00:00", "data": {"market": "0x900ecfb22add054072f36bc9c943bb05e02369cd1d55dce3ee5b8cf4ae2af764", "price_changes": [{"asset_id": "72955248379058153293084602651666522215407419096114442653795152349439056321315", "price": "0.52", "size": "306.99", "side": "BUY", "hash": "a2a563e23183134860aa9723fb48f55747416b75", "best_bid": "0.52", "best_ask": "0.56"}, {"asset_id": "90499528413305425764851960350753110982866738119170371042863813719685571770922", "price": "0.48", "size": "306.99", "side": "SELL", "hash": "5b7cf68fd8121aff42737438e6920e2def8555e6", "best_bid": "0.44", "best_ask": "0.48"}], "timestamp": "1769384106453", "event_type": "price_change"}}
{"_local_timestamp": "2026-01-25T23:35:06.682352+00:00", "data": {"market": "0x900ecfb22add054072f36bc9c943bb05e02369cd1d55dce3ee5b8cf4ae2af764", "price_changes": [{"asset_id": "72955248379058153293084602651666522215407419096114442653795152349439056321315", "price": "0.02", "size": "700", "side": "BUY", "hash": "a960709a1371afe59e4f5f9993eff7d6af7cb114", "best_bid": "0.52", "best_ask": "0.56"}, {"asset_id": "90499528413305425764851960350753110982866738119170371042863813719685571770922", "price": "0.98", "size": "700", "side": "SELL", "hash": "3c22cd2f8d5618d8eb180aa7435b0a872549a965", "best_bid": "0.44", "best_ask": "0.48"}], "timestamp": "1769384106500", "event_type": "price_change"}}
{"_local_timestamp": "2026-01-25T23:35:06.683166+00:00", "data": {"market": "0x900ecfb22add054072f36bc9c943bb05e02369cd1d55dce3ee5b8cf4ae2af764", "price_changes": [{"asset_id": "72955248379058153293084602651666522215407419096114442653795152349439056321315", "price": "0.49", "size": "100", "side": "BUY", "hash": "a960709a1371afe59e4f5f9993eff7d6af7cb114", "best_bid": "0.52", "best_ask": "0.56"}, {"asset_id": "90499528413305425764851960350753110982866738119170371042863813719685571770922", "price": "0.51", "size": "100", "side": "SELL", "hash": "3c22cd2f8d5618d8eb180aa7435b0a872549a965", "best_bid": "0.44", "best_ask": "0.48"}], "timestamp": "1769384106500", "event_type": "price_change"}}
{"_local_timestamp": "2026-01-25T23:35:06.683766+00:00", "data": {"market": "0x900ecfb22add054072f36bc9c943bb05e02369cd1d55dce3ee5b8cf4ae2af764", "price_changes": [{"asset_id": "72955248379058153293084602651666522215407419096114442653795152349439056321315", "price": "0.03", "size": "59.69", "side": "BUY", "hash": "3625e6968a96c5a7ff7485324cad19513edcd087", "best_bid": "0.52", "best_ask": "0.56"}, {"asset_id": "90499528413305425764851960350753110982866738119170371042863813719685571770922", "price": "0.97", "size": "59.69", "side": "SELL", "hash": "382559d19483ee3dad53d9db456cd7dd978f50b0", "best_bid": "0.44", "best_ask": "0.48"}], "timestamp": "1769384106503", "event_type": "price_change"}}
{"_local_timestamp": "2026-01-25T23:35:06.688982+00:00", "data": {"market": "0x900ecfb22add054072f36bc9c943bb05e02369cd1d55dce3ee5b8cf4ae2af764", "price_changes": [{"asset_id": "72955248379058153293084602651666522215407419096114442653795152349439056321315", "price": "0.52", "size": "351.99", "side": "BUY", "hash": "99fda707cd2f9a0382ac9f62488a75ce35a39d64", "best_bid": "0.52", "best_ask": "0.56"}, {"asset_id": "90499528413305425764851960350753110982866738119170371042863813719685571770922", "price": "0.48", "size": "351.99", "side": "SELL", "hash": "0a3ccba054ad242db6b0986b47947b25f8655577", "best_bid": "0.44", "best_ask": "0.48"}], "timestamp": "1769384106504", "event_type": "price_change"}}
{"_local_timestamp": "2026-01-25T23:35:06.918116+00:00", "data": {"market": "0xfa5b189b04818014e796a6978b1f1e4f842cec8fe4b0f2aa2daa4b2ab7cc59b3", "price_changes": [{"asset_id": "76097257249586503390123122659919039099107925379782923914081177262841936638457", "price": "0.53", "size": "6694", "side": "SELL", "hash": "52f4add265945b4099395205b1edf33a465c5ced", "best_bid": "0.51", "best_ask": "0.52"}, {"asset_id": "15086968501686691607738632508897515530788413406991828817382775759887962883365", "price": "0.47", "size": "6694", "side": "BUY", "hash": "71975c9e599bd7100aa184d84af41df131e39374", "best_bid": "0.48", "best_ask": "0.49"}], "timestamp": "1769384106731", "event_type": "price_change"}}
{"_local_timestamp": "2026-01-25T23:35:06.944769+00:00", "data": {"market": "0xfa5b189b04818014e796a6978b1f1e4f842cec8fe4b0f2aa2daa4b2ab7cc59b3", "price_changes": [{"asset_id": "76097257249586503390123122659919039099107925379782923914081177262841936638457", "price": "0.53", "size": "6798", "side": "SELL", "hash": "d969e45143c9448cae2e1b27203b48aa16ec7ef4", "best_bid": "0.51", "best_ask": "0.52"}, {"asset_id": "15086968501686691607738632508897515530788413406991828817382775759887962883365", "price": "0.47", "size": "6798", "side": "BUY", "hash": "8dbb20d16276d02e63d9322397336a70e5277db6", "best_bid": "0.48", "best_ask": "0.49"}], "timestamp": "1769384106761", "event_type": "price_change"}}
{"_local_timestamp": "2026-01-25T23:35:07.278920+00:00", "data": {"market": "0xda92713dcfd1002a861dc7927afe82dbd81a0bcb45a8468e15cebc3adb455f2a", "price_changes": [{"asset_id": "67847413380699129626284788855443204194830281546928428292927803428848858907175", "price": "0.69", "size": "380.14", "side": "BUY", "hash": "c967abedf5e844f100cf8d46fbe7319b5de00c5f", "best_bid": "0.69", "best_ask": "0.72"}, {"asset_id": "61199962474262836932103113956187992633340535926439339471247709440883806095370", "price": "0.31", "size": "380.14", "side": "SELL", "hash": "5e4ad9cc57ba4cd773d700601142d23c91e867bb", "best_bid": "0.28", "best_ask": "0.31"}], "timestamp": "1769384107052", "event_type": "price_change"}}
{"_local_timestamp": "2026-01-25T23:35:08.429659+00:00", "data": {"market": "0xfa5b189b04818014e796a6978b1f1e4f842cec8fe4b0f2aa2daa4b2ab7cc59b3", "price_changes": [{"asset_id": "76097257249586503390123122659919039099107925379782923914081177262841936638457", "price": "0.53", "size": "6694", "side": "SELL", "hash": "a8a53c8d8a9c8c7d0525f4963b44500feaf606ea", "best_bid": "0.51", "best_ask": "0.52"}, {"asset_id": "15086968501686691607738632508897515530788413406991828817382775759887962883365", "price": "0.47", "size": "6694", "side": "BUY", "hash": "6c0eb4458e246751455f5cc3e5c6edf7260c3121", "best_bid": "0.48", "best_ask": "0.49"}], "timestamp": "1769384108227", "event_type": "price_change"}}
{"_local_timestamp": "2026-01-25T23:35:08.453392+00:00", "data": {"market": "0xfa5b189b04818014e796a6978b1f1e4f842cec8fe4b0f2aa2daa4b2ab7cc59b3", "price_changes": [{"asset_id": "76097257249586503390123122659919039099107925379782923914081177262841936638457", "price": "0.53", "size": "6798", "side": "SELL", "hash": "fbcc11ed61252cd5ae06c8cc023d8ff3792a1656", "best_bid": "0.51", "best_ask": "0.52"}, {"asset_id": "15086968501686691607738632508897515530788413406991828817382775759887962883365", "price": "0.47", "size": "6798", "side": "BUY", "hash": "9061a152a310509d3c3270ca6ea39e9f9bf4c5c9", "best_bid": "0.48", "best_ask": "0.49"}], "timestamp": "1769384108254", "event_type": "price_change"}}
{"_local_timestamp": "2026-01-25T23:35:09.946826+00:00", "data": {"market": "0xfa5b189b04818014e796a6978b1f1e4f842cec8fe4b0f2aa2daa4b2ab7cc59b3", "price_changes": [{"asset_id": "76097257249586503390123122659919039099107925379782923914081177262841936638457", "price": "0.53", "size": "6694", "side": "SELL", "hash": "49b17865d8019bd2a483b07c45457796e5f49930", "best_bid": "0.51", "best_ask": "0.52"}, {"asset_id": "15086968501686691607738632508897515530788413406991828817382775759887962883365", "price": "0.47", "size": "6694", "side": "BUY", "hash": "b2772fc3167bb76d537d03cdd034c5509d432e14", "best_bid": "0.48", "best_ask": "0.49"}], "timestamp": "1769384109746", "event_type": "price_change"}}
{"_local_timestamp": "2026-01-25T23:35:09.968916+00:00", "data": {"market": "0xfa5b189b04818014e796a6978b1f1e4f842cec8fe4b0f2aa2daa4b2ab7cc59b3", "price_changes": [{"asset_id": "76097257249586503390123122659919039099107925379782923914081177262841936638457", "price": "0.53", "size": "6798", "side": "SELL", "hash": "f118f165e2cf7e740be7b06f1e2defd34d29873a", "best_bid": "0.51", "best_ask": "0.52"}, {"asset_id": "15086968501686691607738632508897515530788413406991828817382775759887962883365", "price": "0.47", "size": "6798", "side": "BUY", "hash": "b906ef73f6208bc18d5ffada8e5062a809837967", "best_bid": "0.48", "best_ask": "0.49"}], "timestamp": "1769384109772", "event_type": "price_change"}}
{"_local_timestamp": "2026-01-25T23:35:11.426848+00:00", "data": {"market": "0xfa5b189b04818014e796a6978b1f1e4f842cec8fe4b0f2aa2daa4b2ab7cc59b3", "price_changes": [{"asset_id": "76097257249586503390123122659919039099107925379782923914081177262841936638457", "price": "0.53", "size": "6694", "side": "SELL", "hash": "94788cc0be37af8858c0ed25609b4b05813e855a", "best_bid": "0.51", "best_ask": "0.52"}, {"asset_id": "15086968501686691607738632508897515530788413406991828817382775759887962883365", "price": "0.47", "size": "6694", "side": "BUY", "hash": "8cd328ffab03d52d8c447531b582065536c7103a", "best_bid": "0.48", "best_ask": "0.49"}], "timestamp": "1769384111221", "event_type": "price_change"}}
{"_local_timestamp": "2026-01-25T23:35:11.448082+00:00", "data": {"market": "0xfa5b189b04818014e796a6978b1f1e4f842cec8fe4b0f2aa2daa4b2ab7cc59b3", "price_changes": [{"asset_id": "76097257249586503390123122659919039099107925379782923914081177262841936638457", "price": "0.53", "size": "6798", "side": "SELL", "hash": "def096968c4155cadebc94636d20d15353cdf5de", "best_bid": "0.51", "best_ask": "0.52"}, {"asset_id": "15086968501686691607738632508897515530788413406991828817382775759887962883365", "price": "0.47", "size": "6798", "side": "BUY", "hash": "d328d14cfbdfa2aef34f86ced0beadfe34a3c1a7", "best_bid": "0.48", "best_ask": "0.49"}], "timestamp": "1769384111247", "event_type": "price_change"}}
{"_local_timestamp": "2026-01-25T23:35:12.935468+00:00", "data": {"market": "0xfa5b189b04818014e796a6978b1f1e4f842cec8fe4b0f2aa2daa4b2ab7cc59b3", "price_changes": [{"asset_id": "76097257249586503390123122659919039099107925379782923914081177262841936638457", "price": "0.53", "size": "6694", "side": "SELL", "hash": "9d312472897e187a37a9e76eb0005805d175a7b5", "best_bid": "0.51", "best_ask": "0.52"}, {"asset_id": "15086968501686691607738632508897515530788413406991828817382775759887962883365", "price": "0.47", "size": "6694", "side": "BUY", "hash": "ff3309cacc7cde6c7065d353f3d4cb271d96d36a", "best_bid": "0.48", "best_ask": "0.49"}], "timestamp": "1769384112722", "event_type": "price_change"}}
{"_local_timestamp": "2026-01-25T23:35:12.958899+00:00", "data": {"market": "0xfa5b189b04818014e796a6978b1f1e4f842cec8fe4b0f2aa2daa4b2ab7cc59b3", "price_changes": [{"asset_id": "76097257249586503390123122659919039099107925379782923914081177262841936638457", "price": "0.53", "size": "6798", "side": "SELL", "hash": "43e83d0e678cc1f38eaea19b686c7937bf1527e5", "best_bid": "0.51", "best_ask": "0.52"}, {"asset_id": "15086968501686691607738632508897515530788413406991828817382775759887962883365", "price": "0.47", "size": "6798", "side": "BUY", "hash": "b2fe12fe45a8119d0b2829875b3b555168405ab0", "best_bid": "0.48", "best_ask": "0.49"}], "timestamp": "1769384112749", "event_type": "price_change"}}
{"_local_timestamp": "2026-01-25T23:35:14.422535+00:00", "data": {"market": "0xfa5b189b04818014e796a6978b1f1e4f842cec8fe4b0f2aa2daa4b2ab7cc59b3", "price_changes": [{"asset_id": "76097257249586503390123122659919039099107925379782923914081177262841936638457", "price": "0.53", "size": "6694", "side": "SELL", "hash": "fc28dade0a7dc0b6d80907a1765923d1ecb7e337", "best_bid": "0.51", "best_ask": "0.52"}, {"asset_id": "15086968501686691607738632508897515530788413406991828817382775759887962883365", "price": "0.47", "size": "6694", "side": "BUY", "hash": "7aa121d76e44fc1c0e949a3ceb449842beb076e1", "best_bid": "0.48", "best_ask": "0.49"}], "timestamp": "1769384114225", "event_type": "price_change"}}
{"_local_timestamp": "2026-01-25T23:35:14.453427+00:00", "data": {"market": "0xfa5b189b04818014e796a6978b1f1e4f842cec8fe4b0f2aa2daa4b2ab7cc59b3", "price_changes": [{"asset_id": "76097257249586503390123122659919039099107925379782923914081177262841936638457", "price": "0.53", "size": "6798", "side": "SELL", "hash": "027d21d5f24c2f149b58f404c62231ff2bc6bf00", "best_bid": "0.51", "best_ask": "0.52"}, {"asset_id": "15086968501686691607738632508897515530788413406991828817382775759887962883365", "price": "0.47", "size": "6798", "side": "BUY", "hash": "3f8eef326daf9f68e47ecd8f9c4de7da976a10e4", "best_bid": "0.48", "best_ask": "0.49"}], "timestamp": "1769384114252", "event_type": "price_change"}}
{"_local_timestamp": "2026-01-25T23:35:14.734879+00:00", "data": {"market": "0x900ecfb22add054072f36bc9c943bb05e02369cd1d55dce3ee5b8cf4ae2af764", "price_changes": [{"asset_id": "72955248379058153293084602651666522215407419096114442653795152349439056321315", "price": "0.52", "size": "45", "side": "BUY", "hash": "4b5c620d71fc96c41d6affca02a730fe0789bd46", "best_bid": "0.52", "best_ask": "0.56"}, {"asset_id": "90499528413305425764851960350753110982866738119170371042863813719685571770922", "price": "0.48", "size": "45", "side": "SELL", "hash": "fec8f4d40f3f13acdea47c1a0b2cfd733da21666", "best_bid": "0.44", "best_ask": "0.48"}], "timestamp": "1769384114539", "event_type": "price_change"}}
{"_local_timestamp": "2026-01-25T23:35:14.795133+00:00", "data": {"market": "0x900ecfb22add054072f36bc9c943bb05e02369cd1d55dce3ee5b8cf4ae2af764", "price_changes": [{"asset_id": "72955248379058153293084602651666522215407419096114442653795152349439056321315", "price": "0.52", "size": "0", "side": "BUY", "hash": "29a38260a34f712e531880cf48f7731b19e86db9", "best_bid": "0.49", "best_ask": "0.56"}, {"asset_id": "90499528413305425764851960350753110982866738119170371042863813719685571770922", "price": "0.48", "size": "0", "side": "SELL", "hash": "e86be85a190d6040002f25bee4cbabed69648345", "best_bid": "0.44", "best_ask": "0.51"}], "timestamp": "1769384114584", "event_type": "price_change"}}
{"_local_timestamp": "2026-01-25T23:35:14.795868+00:00", "data": {"market": "0x900ecfb22add054072f36bc9c943bb05e02369cd1d55dce3ee5b8cf4ae2af764", "price_changes": [{"asset_id": "72955248379058153293084602651666522215407419096114442653795152349439056321315", "price": "0.03", "size": "9.69", "side": "BUY", "hash": "29a38260a34f712e531880cf48f7731b19e86db9", "best_bid": "0.49", "best_ask": "0.56"}, {"asset_id": "90499528413305425764851960350753110982866738119170371042863813719685571770922", "price": "0.97", "size": "9.69", "side": "SELL", "hash": "e86be85a190d6040002f25bee4cbabed69648345", "best_bid": "0.44", "best_ask": "0.51"}], "timestamp": "1769384114584", "event_type": "price_change"}}
{"_local_timestamp": "2026-01-25T23:35:14.796485+00:00", "data": {"market": "0x900ecfb22add054072f36bc9c943bb05e02369cd1d55dce3ee5b8cf4ae2af764", "price_changes": [{"asset_id": "72955248379058153293084602651666522215407419096114442653795152349439056321315", "price": "0.02", "size": "750", "side": "BUY", "hash": "ef252f2dd10b96049a0046cc1223dd9e72771344", "best_bid": "0.49", "best_ask": "0.56"}, {"asset_id": "90499528413305425764851960350753110982866738119170371042863813719685571770922", "price": "0.98", "size": "750", "side": "SELL", "hash": "0667e48983aac238ff6f5f5dbff0da7cffba827d", "best_bid": "0.44", "best_ask": "0.51"}], "timestamp": "1769384114590", "event_type": "price_change"}}
{"_local_timestamp": "2026-01-25T23:35:14.797132+00:00", "data": {"market": "0x900ecfb22add054072f36bc9c943bb05e02369cd1d55dce3ee5b8cf4ae2af764", "price_changes": [{"asset_id": "72955248379058153293084602651666522215407419096114442653795152349439056321315", "price": "0.49", "size": "150", "side": "BUY", "hash": "ead27a5b4fb3f7bac561b7009d85594b30ba9e92", "best_bid": "0.49", "best_ask": "0.56"}, {"asset_id": "90499528413305425764851960350753110982866738119170371042863813719685571770922", "price": "0.51", "size": "150", "side": "SELL", "hash": "47971f89fc30c1fd4551851e1c2d589380ef80e7", "best_bid": "0.44", "best_ask": "0.51"}], "timestamp": "1769384114591", "event_type": "price_change"}}
{"_local_timestamp": "2026-01-25T23:35:15.946751+00:00", "data": {"market": "0xfa5b189b04818014e796a6978b1f1e4f842cec8fe4b0f2aa2daa4b2ab7cc59b3", "price_changes": [{"asset_id": "76097257249586503390123122659919039099107925379782923914081177262841936638457", "price": "0.53", "size": "6694", "side": "SELL", "hash": "566ea8d3c375e618fdad5448bc7aa3b88bea7abb", "best_bid": "0.51", "best_ask": "0.52"}, {"asset_id": "15086968501686691607738632508897515530788413406991828817382775759887962883365", "price": "0.47", "size": "6694", "side": "BUY", "hash": "e373aae82312184d7ba4af30be0754f541e32301", "best_bid": "0.48", "best_ask": "0.49"}], "timestamp": "1769384115726", "event_type": "price_change"}}
{"_local_timestamp": "2026-01-25T23:35:15.974025+00:00", "data": {"market": "0xfa5b189b04818014e796a6978b1f1e4f842cec8fe4b0f2aa2daa4b2ab7cc59b3", "price_changes": [{"asset_id": "76097257249586503390123122659919039099107925379782923914081177262841936638457", "price": "0.53", "size": "6798", "side": "SELL", "hash": "d14dda42ae2f8ecd1f269f335113248b2d451490", "best_bid": "0.51", "best_ask": "0.52"}, {"asset_id": "15086968501686691607738632508897515530788413406991828817382775759887962883365", "price": "0.47", "size": "6798", "side": "BUY", "hash": "3a6295c975d066449f4b4dd591675e39e7eec8fd", "best_bid": "0.48", "best_ask": "0.49"}], "timestamp": "1769384115754", "event_type": "price_change"}}
{"_local_timestamp": "2026-01-25T23:35:16.567118+00:00", "data": {"market": "0xda92713dcfd1002a861dc7927afe82dbd81a0bcb45a8468e15cebc3adb455f2a", "price_changes": [{"asset_id": "67847413380699129626284788855443204194830281546928428292927803428848858907175", "price": "0.69", "size": "0", "side": "BUY", "hash": "d133b54e28f05e5ee587fc8fd902f5e58106c681", "best_bid": "0.65", "best_ask": "0.72"}, {"asset_id": "61199962474262836932103113956187992633340535926439339471247709440883806095370", "price": "0.31", "size": "0", "side": "SELL", "hash": "16a639234726250204db8ae401e564c0f0765218", "best_bid": "0.28", "best_ask": "0.35"}], "timestamp": "1769384116349", "event_type": "price_change"}}
{"_local_timestamp": "2026-01-25T23:35:17.445694+00:00", "data": {"market": "0xfa5b189b04818014e796a6978b1f1e4f842cec8fe4b0f2aa2daa4b2ab7cc59b3", "price_changes": [{"asset_id": "76097257249586503390123122659919039099107925379782923914081177262841936638457", "price": "0.53", "size": "6694", "side": "SELL", "hash": "c90fb2501d64c162ff59a34f7d12f51a7a3a0b97", "best_bid": "0.51", "best_ask": "0.52"}, {"asset_id": "15086968501686691607738632508897515530788413406991828817382775759887962883365", "price": "0.47", "size": "6694", "side": "BUY", "hash": "d5211032f27ffb8847a9ca06e737afdf0c6282da", "best_bid": "0.48", "best_ask": "0.49"}], "timestamp": "1769384117223", "event_type": "price_change"}}
{"_local_timestamp": "2026-01-25T23:35:17.473332+00:00", "data": {"market": "0xfa5b189b04818014e796a6978b1f1e4f842cec8fe4b0f2aa2daa4b2ab7cc59b3", "price_changes": [{"asset_id": "76097257249586503390123122659919039099107925379782923914081177262841936638457", "price": "0.53", "size": "6798", "side": "SELL", "hash": "c1cc04dc5c55689154f5090e1b9ee693aec8e719", "best_bid": "0.51", "best_ask": "0.52"}, {"asset_id": "15086968501686691607738632508897515530788413406991828817382775759887962883365", "price": "0.47", "size": "6798", "side": "BUY", "hash": "568d11853f345b5bad4e389a615411029722982c", "best_bid": "0.48", "best_ask": "0.49"}], "timestamp": "1769384117256", "event_type": "price_change"}}
{"_local_timestamp": "2026-01-25T23:35:17.776195+00:00", "data": {"market": "0x900ecfb22add054072f36bc9c943bb05e02369cd1d55dce3ee5b8cf4ae2af764", "price_changes": [{"asset_id": "90499528413305425764851960350753110982866738119170371042863813719685571770922", "price": "0.11", "size": "50", "side": "BUY", "hash": "d12e6b843288044d6411568a65a0833e07342df0", "best_bid": "0.44", "best_ask": "0.51"}, {"asset_id": "72955248379058153293084602651666522215407419096114442653795152349439056321315", "price": "0.89", "size": "50", "side": "SELL", "hash": "4b4e55a2d9d1809c5c56b4cdb335e0e182c163da", "best_bid": "0.49", "best_ask": "0.56"}], "timestamp": "1769384117570", "event_type": "price_change"}}
{"_local_timestamp": "2026-01-25T23:35:18.795514+00:00", "data": {"market": "0x900ecfb22add054072f36bc9c943bb05e02369cd1d55dce3ee5b8cf4ae2af764", "price_changes": [{"asset_id": "90499528413305425764851960350753110982866738119170371042863813719685571770922", "price": "0.1", "size": "50", "side": "BUY", "hash": "2a02252d39642eb3f2bce789f144fece3c2d053f", "best_bid": "0.44", "best_ask": "0.51"}, {"asset_id": "72955248379058153293084602651666522215407419096114442653795152349439056321315", "price": "0.9", "size": "50", "side": "SELL", "hash": "c95a1be9169d0df1ec691ac13545a43f1038655e", "best_bid": "0.49", "best_ask": "0.56"}], "timestamp": "1769384118579", "event_type": "price_change"}}
{"_local_timestamp": "2026-01-25T23:35:18.796194+00:00", "data": {"market": "0x900ecfb22add054072f36bc9c943bb05e02369cd1d55dce3ee5b8cf4ae2af764", "price_changes": [{"asset_id": "90499528413305425764851960350753110982866738119170371042863813719685571770922", "price": "0.11", "size": "0", "side": "BUY", "hash": "850cf907402bc67b42ef84e2a04a166fafd891ee", "best_bid": "0.44", "best_ask": "0.51"}, {"asset_id": "72955248379058153293084602651666522215407419096114442653795152349439056321315", "price": "0.89", "size": "0", "side": "SELL", "hash": "fae271a2e62689d7ff7c49b3bbfd0b0384906487", "best_bid": "0.49", "best_ask": "0.56"}], "timestamp": "1769384118580", "event_type": "price_change"}}
{"_local_timestamp": "2026-01-25T23:35:18.957298+00:00", "data": {"market": "0xfa5b189b04818014e796a6978b1f1e4f842cec8fe4b0f2aa2daa4b2ab7cc59b3", "price_changes": [{"asset_id": "76097257249586503390123122659919039099107925379782923914081177262841936638457", "price": "0.53", "size": "6694", "side": "SELL", "hash": "d6e27131872ee408c7cf0fa32ce33a634f2b4899", "best_bid": "0.51", "best_ask": "0.52"}, {"asset_id": "15086968501686691607738632508897515530788413406991828817382775759887962883365", "price": "0.47", "size": "6694", "side": "BUY", "hash": "d81dbe67690283fb9c0959fef5e83b67c669a836", "best_bid": "0.48", "best_ask": "0.49"}], "timestamp": "1769384118723", "event_type": "price_change"}}
{"_local_timestamp": "2026-01-25T23:35:18.971160+00:00", "data": {"market": "0xfa5b189b04818014e796a6978b1f1e4f842cec8fe4b0f2aa2daa4b2ab7cc59b3", "price_changes": [{"asset_id": "76097257249586503390123122659919039099107925379782923914081177262841936638457", "price": "0.53", "size": "6798", "side": "SELL", "hash": "88540f1462a170e648b35e7dde448a90369c50d0", "best_bid": "0.51", "best_ask": "0.52"}, {"asset_id": "15086968501686691607738632508897515530788413406991828817382775759887962883365", "price": "0.47", "size": "6798", "side": "BUY", "hash": "e43c16025c2cbf8b957b3f5545f02fdc2e1d1106", "best_bid": "0.48", "best_ask": "0.49"}], "timestamp": "1769384118753", "event_type": "price_change"}}
{"_local_timestamp": "2026-01-25T23:35:19.608075+00:00", "data": {"market": "0x900ecfb22add054072f36bc9c943bb05e02369cd1d55dce3ee5b8cf4ae2af764", "price_changes": [{"asset_id": "90499528413305425764851960350753110982866738119170371042863813719685571770922", "price": "0.1", "size": "55.6", "side": "BUY", "hash": "79bcd90bcc5e0d533274a5de26de3ee8d70fc9b8", "best_bid": "0.44", "best_ask": "0.51"}, {"asset_id": "72955248379058153293084602651666522215407419096114442653795152349439056321315", "price": "0.9", "size": "55.6", "side": "SELL", "hash": "c81bd4016a7b4313307701c5b507aae1b3bfaaa6", "best_bid": "0.49", "best_ask": "0.56"}], "timestamp": "1769384119398", "event_type": "price_change"}}
{"_local_timestamp": "2026-01-25T23:35:20.141343+00:00", "data": {"market": "0xda92713dcfd1002a861dc7927afe82dbd81a0bcb45a8468e15cebc3adb455f2a", "price_changes": [{"asset_id": "67847413380699129626284788855443204194830281546928428292927803428848858907175", "price": "0.65", "size": "220", "side": "BUY", "hash": "a3308580bf17ae04d8cc300cd16dd613d59ccfa4", "best_bid": "0.65", "best_ask": "0.72"}, {"asset_id": "61199962474262836932103113956187992633340535926439339471247709440883806095370", "price": "0.35", "size": "220", "side": "SELL", "hash": "2647013bc81b075ddea3f4bc3952223ad6026fd2", "best_bid": "0.28", "best_ask": "0.35"}], "timestamp": "1769384119922", "event_type": "price_change"}}
{"_local_timestamp": "2026-01-25T23:35:20.347255+00:00", "data": {"market": "0x900ecfb22add054072f36bc9c943bb05e02369cd1d55dce3ee5b8cf4ae2af764", "price_changes": [{"asset_id": "72955248379058153293084602651666522215407419096114442653795152349439056321315", "price": "0.49", "size": "162.1", "side": "BUY", "hash": "b118343a1403c99187354504e5472cf0c81c5e30", "best_bid": "0.49", "best_ask": "0.56"}, {"asset_id": "90499528413305425764851960350753110982866738119170371042863813719685571770922", "price": "0.51", "size": "162.1", "side": "SELL", "hash": "170e94dbec06a4d8d87bd0c52b08f28c52d05827", "best_bid": "0.44", "best_ask": "0.51"}], "timestamp": "1769384120119", "event_type": "price_change"}}
{"_local_timestamp": "2026-01-25T23:35:20.447067+00:00", "data": {"market": "0xfa5b189b04818014e796a6978b1f1e4f842cec8fe4b0f2aa2daa4b2ab7cc59b3", "price_changes": [{"asset_id": "76097257249586503390123122659919039099107925379782923914081177262841936638457", "price": "0.53", "size": "6694", "side": "SELL", "hash": "aef83ffa55fa342fdd9fd9def559583fd37473a3", "best_bid": "0.51", "best_ask": "0.52"}, {"asset_id": "15086968501686691607738632508897515530788413406991828817382775759887962883365", "price": "0.47", "size": "6694", "side": "BUY", "hash": "911c67bd9dac5781ca67162802e5db5fbe38827c", "best_bid": "0.48", "best_ask": "0.49"}], "timestamp": "1769384120225", "event_type": "price_change"}}
{"_local_timestamp": "2026-01-25T23:35:20.479152+00:00", "data": {"market": "0xfa5b189b04818014e796a6978b1f1e4f842cec8fe4b0f2aa2daa4b2ab7cc59b3", "price_changes": [{"asset_id": "76097257249586503390123122659919039099107925379782923914081177262841936638457", "price": "0.53", "size": "6798", "side": "SELL", "hash": "a9836388987bf7b1070b66507e0fe533c5cdd126", "best_bid": "0.51", "best_ask": "0.52"}, {"asset_id": "15086968501686691607738632508897515530788413406991828817382775759887962883365", "price": "0.47", "size": "6798", "side": "BUY", "hash": "1b103bada3a38a053b88f1099365cd1da151f83e", "best_bid": "0.48", "best_ask": "0.49"}], "timestamp": "1769384120254", "event_type": "price_change"}}
{"_local_timestamp": "2026-01-25T23:35:21.945217+00:00", "data": {"market": "0xfa5b189b04818014e796a6978b1f1e4f842cec8fe4b0f2aa2daa4b2ab7cc59b3", "price_changes": [{"asset_id": "76097257249586503390123122659919039099107925379782923914081177262841936638457", "price": "0.53", "size": "6694", "side": "SELL", "hash": "0d698f82014a059ce23ffa82abd9ed2fd4828249", "best_bid": "0.51", "best_ask": "0.52"}, {"asset_id": "15086968501686691607738632508897515530788413406991828817382775759887962883365", "price": "0.47", "size": "6694", "side": "BUY", "hash": "609ff124ac634d1eedf6bb3c094475386ed8f322", "best_bid": "0.48", "best_ask": "0.49"}], "timestamp": "1769384121732", "event_type": "price_change"}}
{"_local_timestamp": "2026-01-25T23:35:21.973980+00:00", "data": {"market": "0xfa5b189b04818014e796a6978b1f1e4f842cec8fe4b0f2aa2daa4b2ab7cc59b3", "price_changes": [{"asset_id": "76097257249586503390123122659919039099107925379782923914081177262841936638457", "price": "0.53", "size": "6798", "side": "SELL", "hash": "d4fa89c25dcc5da3cda6848b8899480ae03da333", "best_bid": "0.51", "best_ask": "0.52"}, {"asset_id": "15086968501686691607738632508897515530788413406991828817382775759887962883365", "price": "0.47", "size": "6798", "side": "BUY", "hash": "e9a9f20e1ee73dbb5e9be842a49791af3e760b61", "best_bid": "0.48", "best_ask": "0.49"}], "timestamp": "1769384121767", "event_type": "price_change"}}
{"_local_timestamp": "2026-01-25T23:35:22.907725+00:00", "data": {"market": "0xd5adfe406a67b13cc0a05117843523a69e8bfd4745fd20163f0576a45d7e7fbf", "price_changes": [{"asset_id": "9783783549835614458881326312946338430553875019865093562239304806617094760942", "price": "0.03", "size": "800", "side": "BUY", "hash": "9ad665d0987babfa193917de9641722f6bf98af4", "best_bid": "0.53", "best_ask": "0.57"}, {"asset_id": "92942148598462030310311593687833911343746933382385610072160871418917000805183", "price": "0.97", "size": "800", "side": "SELL", "hash": "947a11cdf9e2609c766aa45c84ed408ffae65764", "best_bid": "0.43", "best_ask": "0.47"}], "timestamp": "1769384122696", "event_type": "price_change"}}
{"_local_timestamp": "2026-01-25T23:35:22.908549+00:00", "data": {"market": "0xda92713dcfd1002a861dc7927afe82dbd81a0bcb45a8468e15cebc3adb455f2a", "price_changes": [{"asset_id": "67847413380699129626284788855443204194830281546928428292927803428848858907175", "price": "0.08", "size": "50", "side": "BUY", "hash": "42b3c82e8ce4ceaf765f0113fb4f2f7cddf6eaba", "best_bid": "0.65", "best_ask": "0.72"}, {"asset_id": "61199962474262836932103113956187992633340535926439339471247709440883806095370", "price": "0.92", "size": "50", "side": "SELL", "hash": "d4e951b1eb4f21b1957204a37032eaf1e80e0dd9", "best_bid": "0.28", "best_ask": "0.35"}], "timestamp": "1769384122696", "event_type": "price_change"}}
{"_local_timestamp": "2026-01-25T23:35:23.422538+00:00", "data": {"market": "0xfa5b189b04818014e796a6978b1f1e4f842cec8fe4b0f2aa2daa4b2ab7cc59b3", "price_changes": [{"asset_id": "76097257249586503390123122659919039099107925379782923914081177262841936638457", "price": "0.53", "size": "6694", "side": "SELL", "hash": "552c823d3d1c20a13d644c729e312568cac00ce4", "best_bid": "0.51", "best_ask": "0.52"}, {"asset_id": "15086968501686691607738632508897515530788413406991828817382775759887962883365", "price": "0.47", "size": "6694", "side": "BUY", "hash": "85439c17dc4b4f127296d85c2dce72208bbc18d2", "best_bid": "0.48", "best_ask": "0.49"}], "timestamp": "1769384123223", "event_type": "price_change"}}
{"_local_timestamp": "2026-01-25T23:35:23.462518+00:00", "data": {"market": "0xfa5b189b04818014e796a6978b1f1e4f842cec8fe4b0f2aa2daa4b2ab7cc59b3", "price_changes": [{"asset_id": "76097257249586503390123122659919039099107925379782923914081177262841936638457", "price": "0.53", "size": "6798", "side": "SELL", "hash": "3edd53b29dd59f802ca9ac7d077f3844fc5241f1", "best_bid": "0.51", "best_ask": "0.52"}, {"asset_id": "15086968501686691607738632508897515530788413406991828817382775759887962883365", "price": "0.47", "size": "6798", "side": "BUY", "hash": "00ec9e5e68aaa086eb3c1508956c9eba1655590f", "best_bid": "0.48", "best_ask": "0.49"}], "timestamp": "1769384123251", "event_type": "price_change"}}
{"_local_timestamp": "2026-01-25T23:35:23.975763+00:00", "data": {"market": "0xd5adfe406a67b13cc0a05117843523a69e8bfd4745fd20163f0576a45d7e7fbf", "price_changes": [{"asset_id": "9783783549835614458881326312946338430553875019865093562239304806617094760942", "price": "0.04", "size": "7.22", "side": "BUY", "hash": "0fab61220b4e991dfc8b8f09fe4cc57ea3b6b7a9", "best_bid": "0.53", "best_ask": "0.57"}, {"asset_id": "92942148598462030310311593687833911343746933382385610072160871418917000805183", "price": "0.96", "size": "7.22", "side": "SELL", "hash": "5d7113878b005d216989717475bfb8cdecdde291", "best_bid": "0.43", "best_ask": "0.47"}], "timestamp": "1769384123739", "event_type": "price_change"}}
{"_local_timestamp": "2026-01-25T23:35:23.976535+00:00", "data": {"market": "0xda92713dcfd1002a861dc7927afe82dbd81a0bcb45a8468e15cebc3adb455f2a", "price_changes": [{"asset_id": "67847413380699129626284788855443204194830281546928428292927803428848858907175", "price": "0.09", "size": "7.98", "side": "BUY", "hash": "e2c03acbd02594ddf805f01bc50627356f63b10e", "best_bid": "0.65", "best_ask": "0.72"}, {"asset_id": "61199962474262836932103113956187992633340535926439339471247709440883806095370", "price": "0.91", "size": "7.98", "side": "SELL", "hash": "9349b168e460ffbfb0a297998621aa029e15a246", "best_bid": "0.28", "best_ask": "0.35"}], "timestamp": "1769384123739", "event_type": "price_change"}}
{"_local_timestamp": "2026-01-25T23:35:25.101207+00:00", "data": {"market": "0xda92713dcfd1002a861dc7927afe82dbd81a0bcb45a8468e15cebc3adb455f2a", "price_changes": [{"asset_id": "67847413380699129626284788855443204194830281546928428292927803428848858907175", "price": "0.08", "size": "0", "side": "BUY", "hash": "ffc1211c17aa3b48b8efaf524bb4367d6e04aa1f", "best_bid": "0.65", "best_ask": "0.72"}, {"asset_id": "61199962474262836932103113956187992633340535926439339471247709440883806095370", "price": "0.92", "size": "0", "side": "SELL", "hash": "e579390e4ea2af254a7f5b621c3e521be8b3ec9e", "best_bid": "0.28", "best_ask": "0.35"}], "timestamp": "1769384124739", "event_type": "price_change"}}
{"_local_timestamp": "2026-01-25T23:35:25.102017+00:00", "data": {"market": "0xda92713dcfd1002a861dc7927afe82dbd81a0bcb45a8468e15cebc3adb455f2a", "price_changes": [{"asset_id": "67847413380699129626284788855443204194830281546928428292927803428848858907175", "price": "0.65", "size": "170", "side": "BUY", "hash": "ffc1211c17aa3b48b8efaf524bb4367d6e04aa1f", "best_bid": "0.65", "best_ask": "0.72"}, {"asset_id": "61199962474262836932103113956187992633340535926439339471247709440883806095370", "price": "0.35", "size": "170", "side": "SELL", "hash": "e579390e4ea2af254a7f5b621c3e521be8b3ec9e", "best_bid": "0.28", "best_ask": "0.35"}], "timestamp": "1769384124739", "event_type": "price_change"}}
{"_local_timestamp": "2026-01-25T23:35:25.102689+00:00", "data": {"market": "0xda92713dcfd1002a861dc7927afe82dbd81a0bcb45a8468e15cebc3adb455f2a", "price_changes": [{"asset_id": "67847413380699129626284788855443204194830281546928428292927803428848858907175", "price": "0.66", "size": "50", "side": "BUY", "hash": "2940fc45ae28d255277f13e68dc769144aeb300e", "best_bid": "0.66", "best_ask": "0.72"}, {"asset_id": "61199962474262836932103113956187992633340535926439339471247709440883806095370", "price": "0.34", "size": "50", "side": "SELL", "hash": "3584df40fbd24916a639539a6d4b5f522d301591", "best_bid": "0.28", "best_ask": "0.34"}], "timestamp": "1769384124746", "event_type": "price_change"}}
{"_local_timestamp": "2026-01-25T23:35:25.103423+00:00", "data": {"market": "0xda92713dcfd1002a861dc7927afe82dbd81a0bcb45a8468e15cebc3adb455f2a", "price_changes": [{"asset_id": "67847413380699129626284788855443204194830281546928428292927803428848858907175", "price": "0.09", "size": "57.98", "side": "BUY", "hash": "a1659fcf7d9bd2076ebe1aadb7776008f7fe44c0", "best_bid": "0.66", "best_ask": "0.72"}, {"asset_id": "61199962474262836932103113956187992633340535926439339471247709440883806095370", "price": "0.91", "size": "57.98", "side": "SELL", "hash": "07349f86e49803bd12b220b918f8aae9cc6ed293", "best_bid": "0.28", "best_ask": "0.34"}], "timestamp": "1769384124747", "event_type": "price_change"}}
{"_local_timestamp": "2026-01-25T23:35:25.111996+00:00", "data": {"market": "0xfa5b189b04818014e796a6978b1f1e4f842cec8fe4b0f2aa2daa4b2ab7cc59b3", "price_changes": [{"asset_id": "76097257249586503390123122659919039099107925379782923914081177262841936638457", "price": "0.53", "size": "6694", "side": "SELL", "hash": "abc09b1f213e9f8726ec9ad4b24ab4cd415252f7", "best_bid": "0.51", "best_ask": "0.52"}, {"asset_id": "15086968501686691607738632508897515530788413406991828817382775759887962883365", "price": "0.47", "size": "6694", "side": "BUY", "hash": "37bfa4e60f09a149cfba8538a58bbf389b45b1f1", "best_bid": "0.48", "best_ask": "0.49"}], "timestamp": "1769384124762", "event_type": "price_change"}}
{"_local_timestamp": "2026-01-25T23:35:25.145620+00:00", "data": {"market": "0xfa5b189b04818014e796a6978b1f1e4f842cec8fe4b0f2aa2daa4b2ab7cc59b3", "price_changes": [{"asset_id": "76097257249586503390123122659919039099107925379782923914081177262841936638457", "price": "0.53", "size": "6798", "side": "SELL", "hash": "9b9f9e873b801289f8586ec5daf8197f9fccf82c", "best_bid": "0.51", "best_ask": "0.52"}, {"asset_id": "15086968501686691607738632508897515530788413406991828817382775759887962883365", "price": "0.47", "size": "6798", "side": "BUY", "hash": "3770d312d8046c99499ae458f83f2602a0094643", "best_bid": "0.48", "best_ask": "0.49"}], "timestamp": "1769384124800", "event_type": "price_change"}}
{"_local_timestamp": "2026-01-25T23:35:26.437975+00:00", "data": {"market": "0xfa5b189b04818014e796a6978b1f1e4f842cec8fe4b0f2aa2daa4b2ab7cc59b3", "price_changes": [{"asset_id": "76097257249586503390123122659919039099107925379782923914081177262841936638457", "price": "0.53", "size": "6694", "side": "SELL", "hash": "aef311123f75319edec2ff85c2373b013e805ee4", "best_bid": "0.51", "best_ask": "0.52"}, {"asset_id": "15086968501686691607738632508897515530788413406991828817382775759887962883365", "price": "0.47", "size": "6694", "side": "BUY", "hash": "5c77a958630b815b6dabec94f778eb661c79b888", "best_bid": "0.48", "best_ask": "0.49"}], "timestamp": "1769384126223", "event_type": "price_change"}}
{"_local_timestamp": "2026-01-25T23:35:26.461405+00:00", "data": {"market": "0xfa5b189b04818014e796a6978b1f1e4f842cec8fe4b0f2aa2daa4b2ab7cc59b3", "price_changes": [{"asset_id": "76097257249586503390123122659919039099107925379782923914081177262841936638457", "price": "0.53", "size": "6798", "side": "SELL", "hash": "29d787899982764866f6b1ab11c83ff6ad1874b1", "best_bid": "0.51", "best_ask": "0.52"}, {"asset_id": "15086968501686691607738632508897515530788413406991828817382775759887962883365", "price": "0.47", "size": "6798", "side": "BUY", "hash": "f340f60c4d444563901d93bb64eb37358d822354", "best_bid": "0.48", "best_ask": "0.49"}], "timestamp": "1769384126249", "event_type": "price_change"}}
{"_local_timestamp": "2026-01-25T23:35:27.958955+00:00", "data": {"market": "0xfa5b189b04818014e796a6978b1f1e4f842cec8fe4b0f2aa2daa4b2ab7cc59b3", "price_changes": [{"asset_id": "76097257249586503390123122659919039099107925379782923914081177262841936638457", "price": "0.53", "size": "6694", "side": "SELL", "hash": "f521e74ef930a522ef2b62ccf44c579c35193fc9", "best_bid": "0.51", "best_ask": "0.52"}, {"asset_id": "15086968501686691607738632508897515530788413406991828817382775759887962883365", "price": "0.47", "size": "6694", "side": "BUY", "hash": "79c6ae61f5f6765fb59c06b2474c0a1e9f0514cf", "best_bid": "0.48", "best_ask": "0.49"}], "timestamp": "1769384127724", "event_type": "price_change"}}
{"_local_timestamp": "2026-01-25T23:35:27.980994+00:00", "data": {"market": "0xfa5b189b04818014e796a6978b1f1e4f842cec8fe4b0f2aa2daa4b2ab7cc59b3", "price_changes": [{"asset_id": "76097257249586503390123122659919039099107925379782923914081177262841936638457", "price": "0.53", "size": "6798", "side": "SELL", "hash": "b06507b0cef1801378a6bbc9d11e82200e7c8fde", "best_bid": "0.51", "best_ask": "0.52"}, {"asset_id": "15086968501686691607738632508897515530788413406991828817382775759887962883365", "price": "0.47", "size": "6798", "side": "BUY", "hash": "be0704c0c1de4cfe8c02173da44eaf1eaa824063", "best_bid": "0.48", "best_ask": "0.49"}], "timestamp": "1769384127753", "event_type": "price_change"}}
{"_local_timestamp": "2026-01-25T23:35:29.442993+00:00", "data": {"market": "0xfa5b189b04818014e796a6978b1f1e4f842cec8fe4b0f2aa2daa4b2ab7cc59b3", "price_changes": [{"asset_id": "76097257249586503390123122659919039099107925379782923914081177262841936638457", "price": "0.53", "size": "6694", "side": "SELL", "hash": "d67437068623366cadf15180131cdfbc9882490a", "best_bid": "0.51", "best_ask": "0.52"}, {"asset_id": "15086968501686691607738632508897515530788413406991828817382775759887962883365", "price": "0.47", "size": "6694", "side": "BUY", "hash": "5b94bd6c003688b3fe5a12f2caa8978c5fa881b5", "best_bid": "0.48", "best_ask": "0.49"}], "timestamp": "1769384129222", "event_type": "price_change"}}
{"_local_timestamp": "2026-01-25T23:35:29.463395+00:00", "data": {"market": "0xfa5b189b04818014e796a6978b1f1e4f842cec8fe4b0f2aa2daa4b2ab7cc59b3", "price_changes": [{"asset_id": "76097257249586503390123122659919039099107925379782923914081177262841936638457", "price": "0.53", "size": "6798", "side": "SELL", "hash": "5532276341fd2c575926d25e9bf930bc2dbec3df", "best_bid": "0.51", "best_ask": "0.52"}, {"asset_id": "15086968501686691607738632508897515530788413406991828817382775759887962883365", "price": "0.47", "size": "6798", "side": "BUY", "hash": "42ced83cad2f61b75b1ddee27d37c9380552b1fa", "best_bid": "0.48", "best_ask": "0.49"}], "timestamp": "1769384129247", "event_type": "price_change"}}
{"_local_timestamp": "2026-01-25T23:35:30.986560+00:00", "data": {"market": "0xfa5b189b04818014e796a6978b1f1e4f842cec8fe4b0f2aa2daa4b2ab7cc59b3", "price_changes": [{"asset_id": "76097257249586503390123122659919039099107925379782923914081177262841936638457", "price": "0.53", "size": "6694", "side": "SELL", "hash": "f6bd04eacdce50b3701f3c73961c6455d6a834d0", "best_bid": "0.51", "best_ask": "0.52"}, {"asset_id": "15086968501686691607738632508897515530788413406991828817382775759887962883365", "price": "0.47", "size": "6694", "side": "BUY", "hash": "ae28a65c0b290d80bd55fa8438df1b3a75f90d85", "best_bid": "0.48", "best_ask": "0.49"}], "timestamp": "1769384130737", "event_type": "price_change"}}
{"_local_timestamp": "2026-01-25T23:35:31.012344+00:00", "data": {"market": "0xfa5b189b04818014e796a6978b1f1e4f842cec8fe4b0f2aa2daa4b2ab7cc59b3", "price_changes": [{"asset_id": "76097257249586503390123122659919039099107925379782923914081177262841936638457", "price": "0.53", "size": "6798", "side": "SELL", "hash": "49d63c89a36cbe89ae28ce63927b9edae55bec4f", "best_bid": "0.51", "best_ask": "0.52"}, {"asset_id": "15086968501686691607738632508897515530788413406991828817382775759887962883365", "price": "0.47", "size": "6798", "side": "BUY", "hash": "331020852396c0b2bf1498ad0a7a26ba7c232309", "best_bid": "0.48", "best_ask": "0.49"}], "timestamp": "1769384130769", "event_type": "price_change"}}
{"_local_timestamp": "2026-01-25T23:35:32.450174+00:00", "data": {"market": "0xfa5b189b04818014e796a6978b1f1e4f842cec8fe4b0f2aa2daa4b2ab7cc59b3", "price_changes": [{"asset_id": "76097257249586503390123122659919039099107925379782923914081177262841936638457", "price": "0.53", "size": "6694", "side": "SELL", "hash": "2472efcee444db7fdeffd8c6a07cf38c13c3b47b", "best_bid": "0.51", "best_ask": "0.52"}, {"asset_id": "15086968501686691607738632508897515530788413406991828817382775759887962883365", "price": "0.47", "size": "6694", "side": "BUY", "hash": "8e1788e8c90253102a4180f392fe8203e780f7be", "best_bid": "0.48", "best_ask": "0.49"}], "timestamp": "1769384132223", "event_type": "price_change"}}
{"_local_timestamp": "2026-01-25T23:35:32.499027+00:00", "data": {"market": "0xfa5b189b04818014e796a6978b1f1e4f842cec8fe4b0f2aa2daa4b2ab7cc59b3", "price_changes": [{"asset_id": "76097257249586503390123122659919039099107925379782923914081177262841936638457", "price": "0.53", "size": "6798", "side": "SELL", "hash": "bb94697c76268ace44246dd9cb5a6c65aeb9cc23", "best_bid": "0.51", "best_ask": "0.52"}, {"asset_id": "15086968501686691607738632508897515530788413406991828817382775759887962883365", "price": "0.47", "size": "6798", "side": "BUY", "hash": "8418c3f5dd9096630bdddbc860e133f99814d2e8", "best_bid": "0.48", "best_ask": "0.49"}], "timestamp": "1769384132248", "event_type": "price_change"}}
{"_local_timestamp": "2026-01-25T23:35:33.943998+00:00", "data": {"market": "0xfa5b189b04818014e796a6978b1f1e4f842cec8fe4b0f2aa2daa4b2ab7cc59b3", "price_changes": [{"asset_id": "76097257249586503390123122659919039099107925379782923914081177262841936638457", "price": "0.53", "size": "6694", "side": "SELL", "hash": "46280372a19a5c471807de601932c13955fa281e", "best_bid": "0.51", "best_ask": "0.52"}, {"asset_id": "15086968501686691607738632508897515530788413406991828817382775759887962883365", "price": "0.47", "size": "6694", "side": "BUY", "hash": "fc095659bced226e000cf7a365ebf520853ea906", "best_bid": "0.48", "best_ask": "0.49"}], "timestamp": "1769384133724", "event_type": "price_change"}}
{"_local_timestamp": "2026-01-25T23:35:33.954593+00:00", "data": {"market": "0xfa5b189b04818014e796a6978b1f1e4f842cec8fe4b0f2aa2daa4b2ab7cc59b3", "price_changes": [{"asset_id": "76097257249586503390123122659919039099107925379782923914081177262841936638457", "price": "0.53", "size": "6798", "side": "SELL", "hash": "79ced050bb074ba36104a9bf854da02cabe139da", "best_bid": "0.51", "best_ask": "0.52"}, {"asset_id": "15086968501686691607738632508897515530788413406991828817382775759887962883365", "price": "0.47", "size": "6798", "side": "BUY", "hash": "76eca9a774c39bc8948fdb7ec56492b35daa8d12", "best_bid": "0.48", "best_ask": "0.49"}], "timestamp": "1769384133758", "event_type": "price_change"}}
{"_local_timestamp": "2026-01-25T23:35:35.460990+00:00", "data": {"market": "0xfa5b189b04818014e796a6978b1f1e4f842cec8fe4b0f2aa2daa4b2ab7cc59b3", "price_changes": [{"asset_id": "76097257249586503390123122659919039099107925379782923914081177262841936638457", "price": "0.53", "size": "6694", "side": "SELL", "hash": "ce6166d3d2b15c8a63d24a7fbdc7677784d58a34", "best_bid": "0.51", "best_ask": "0.52"}, {"asset_id": "15086968501686691607738632508897515530788413406991828817382775759887962883365", "price": "0.47", "size": "6694", "side": "BUY", "hash": "002f29d76f0e6880676fae8661e7fcedf23683a7", "best_bid": "0.48", "best_ask": "0.49"}], "timestamp": "1769384135223", "event_type": "price_change"}}
{"_local_timestamp": "2026-01-25T23:35:35.479249+00:00", "data": {"market": "0xfa5b189b04818014e796a6978b1f1e4f842cec8fe4b0f2aa2daa4b2ab7cc59b3", "price_changes": [{"asset_id": "76097257249586503390123122659919039099107925379782923914081177262841936638457", "price": "0.53", "size": "6798", "side": "SELL", "hash": "3419c46cafa46319114640a4734d394f8dd40743", "best_bid": "0.51", "best_ask": "0.52"}, {"asset_id": "15086968501686691607738632508897515530788413406991828817382775759887962883365", "price": "0.47", "size": "6798", "side": "BUY", "hash": "24c1ee9ffd92db3653941b551c4dab1bab3f3d0d", "best_bid": "0.48", "best_ask": "0.49"}], "timestamp": "1769384135252", "event_type": "price_change"}}
{"_local_timestamp": "2026-01-25T23:35:36.941887+00:00", "data": {"market": "0xfa5b189b04818014e796a6978b1f1e4f842cec8fe4b0f2aa2daa4b2ab7cc59b3", "price_changes": [{"asset_id": "76097257249586503390123122659919039099107925379782923914081177262841936638457", "price": "0.53", "size": "6694", "side": "SELL", "hash": "21dee043598609d73d2356129a6e44c536413a27", "best_bid": "0.51", "best_ask": "0.52"}, {"asset_id": "15086968501686691607738632508897515530788413406991828817382775759887962883365", "price": "0.47", "size": "6694", "side": "BUY", "hash": "c723b9e6ffd05d8eff4d8b3bf27f601fa291945a", "best_bid": "0.48", "best_ask": "0.49"}], "timestamp": "1769384136728", "event_type": "price_change"}}
{"_local_timestamp": "2026-01-25T23:35:36.978371+00:00", "data": {"market": "0xfa5b189b04818014e796a6978b1f1e4f842cec8fe4b0f2aa2daa4b2ab7cc59b3", "price_changes": [{"asset_id": "76097257249586503390123122659919039099107925379782923914081177262841936638457", "price": "0.53", "size": "6798", "side": "SELL", "hash": "847f56c34f561c64a649f731ff0a934ac0d883bc", "best_bid": "0.51", "best_ask": "0.52"}, {"asset_id": "15086968501686691607738632508897515530788413406991828817382775759887962883365", "price": "0.47", "size": "6798", "side": "BUY", "hash": "b365163948ea636162f8e122ee2acfd8858c9133", "best_bid": "0.48", "best_ask": "0.49"}], "timestamp": "1769384136756", "event_type": "price_change"}}
{"_local_timestamp": "2026-01-25T23:35:38.311902+00:00", "data": {"market": "0xfa5b189b04818014e796a6978b1f1e4f842cec8fe4b0f2aa2daa4b2ab7cc59b3", "price_changes": [{"asset_id": "76097257249586503390123122659919039099107925379782923914081177262841936638457", "price": "0.53", "size": "6694", "side": "SELL", "hash": "2e59e248005a93f0651c30e07f65ea3db7db66ae", "best_bid": "0.51", "best_ask": "0.52"}, {"asset_id": "15086968501686691607738632508897515530788413406991828817382775759887962883365", "price": "0.47", "size": "6694", "side": "BUY", "hash": "7bf8998e545978735ea9ae05d70b913a7ca8cc29", "best_bid": "0.48", "best_ask": "0.49"}], "timestamp": "1769384138223", "event_type": "price_change"}}
{"_local_timestamp": "2026-01-25T23:35:38.334713+00:00", "data": {"market": "0xfa5b189b04818014e796a6978b1f1e4f842cec8fe4b0f2aa2daa4b2ab7cc59b3", "price_changes": [{"asset_id": "76097257249586503390123122659919039099107925379782923914081177262841936638457", "price": "0.53", "size": "6798", "side": "SELL", "hash": "3948ac4f1bfafa55683ca933089892ab4c32498e", "best_bid": "0.51", "best_ask": "0.52"}, {"asset_id": "15086968501686691607738632508897515530788413406991828817382775759887962883365", "price": "0.47", "size": "6798", "side": "BUY", "hash": "587a37f5a444626a49df76a21730727ebfe68f2f", "best_bid": "0.48", "best_ask": "0.49"}], "timestamp": "1769384138252", "event_type": "price_change"}}
{"_local_timestamp": "2026-01-25T23:35:39.506613+00:00", "data": {"market": "0x900ecfb22add054072f36bc9c943bb05e02369cd1d55dce3ee5b8cf4ae2af764", "price_changes": [{"asset_id": "72955248379058153293084602651666522215407419096114442653795152349439056321315", "price": "0.49", "size": "112.1", "side": "BUY", "hash": "c3f5b5082fbcab0476f6bea1a8f65eb79c07c7b1", "best_bid": "0.49", "best_ask": "0.56"}, {"asset_id": "90499528413305425764851960350753110982866738119170371042863813719685571770922", "price": "0.51", "size": "112.1", "side": "SELL", "hash": "ec7530883438c355d9b6a966b4b43d38aca51b79", "best_bid": "0.44", "best_ask": "0.51"}], "timestamp": "1769384139435", "event_type": "price_change"}}
{"_local_timestamp": "2026-01-25T23:35:39.507448+00:00", "data": {"market": "0x900ecfb22add054072f36bc9c943bb05e02369cd1d55dce3ee5b8cf4ae2af764", "price_changes": [{"asset_id": "72955248379058153293084602651666522215407419096114442653795152349439056321315", "price": "0.5", "size": "50", "side": "BUY", "hash": "08f45bb40cee84685c5e2fb7315c68b78ac7b5e3", "best_bid": "0.5", "best_ask": "0.56"}, {"asset_id": "90499528413305425764851960350753110982866738119170371042863813719685571770922", "price": "0.5", "size": "50", "side": "SELL", "hash": "8386f5fb07a3d269db8cd1fb41e7f69b85ac7f19", "best_bid": "0.44", "best_ask": "0.5"}], "timestamp": "1769384139439", "event_type": "price_change"}}
{"_local_timestamp": "2026-01-25T23:35:39.794843+00:00", "data": {"market": "0xfa5b189b04818014e796a6978b1f1e4f842cec8fe4b0f2aa2daa4b2ab7cc59b3", "price_changes": [{"asset_id": "76097257249586503390123122659919039099107925379782923914081177262841936638457", "price": "0.53", "size": "6694", "side": "SELL", "hash": "179520a4b52a6ac88a199c8d2e846dedeb7b5dad", "best_bid": "0.51", "best_ask": "0.52"}, {"asset_id": "15086968501686691607738632508897515530788413406991828817382775759887962883365", "price": "0.47", "size": "6694", "side": "BUY", "hash": "f2977e099fbad24c0e2bf8d01764529b8f21c7c8", "best_bid": "0.48", "best_ask": "0.49"}], "timestamp": "1769384139724", "event_type": "price_change"}}
{"_local_timestamp": "2026-01-25T23:35:39.819440+00:00", "data": {"market": "0xfa5b189b04818014e796a6978b1f1e4f842cec8fe4b0f2aa2daa4b2ab7cc59b3", "price_changes": [{"asset_id": "76097257249586503390123122659919039099107925379782923914081177262841936638457", "price": "0.53", "size": "6798", "side": "SELL", "hash": "c07f0a50d9cc5d9a49b7969d63885020f6186b92", "best_bid": "0.51", "best_ask": "0.52"}, {"asset_id": "15086968501686691607738632508897515530788413406991828817382775759887962883365", "price": "0.47", "size": "6798", "side": "BUY", "hash": "948a5180cb6a1c57c6bd4e6fb7382da8e067c6be", "best_bid": "0.48", "best_ask": "0.49"}], "timestamp": "1769384139750", "event_type": "price_change"}}
{"_local_timestamp": "2026-01-25T23:35:41.296924+00:00", "data": {"market": "0xfa5b189b04818014e796a6978b1f1e4f842cec8fe4b0f2aa2daa4b2ab7cc59b3", "price_changes": [{"asset_id": "76097257249586503390123122659919039099107925379782923914081177262841936638457", "price": "0.53", "size": "6694", "side": "SELL", "hash": "935ba190f47fae4edba82ff197b7cb64f4e9445c", "best_bid": "0.51", "best_ask": "0.52"}, {"asset_id": "15086968501686691607738632508897515530788413406991828817382775759887962883365", "price": "0.47", "size": "6694", "side": "BUY", "hash": "ca324f8705c73f02995a463b8216c61f11a6b246", "best_bid": "0.48", "best_ask": "0.49"}], "timestamp": "1769384141222", "event_type": "price_change"}}
{"_local_timestamp": "2026-01-25T23:35:41.315241+00:00", "data": {"market": "0xfa5b189b04818014e796a6978b1f1e4f842cec8fe4b0f2aa2daa4b2ab7cc59b3", "price_changes": [{"asset_id": "76097257249586503390123122659919039099107925379782923914081177262841936638457", "price": "0.53", "size": "6798", "side": "SELL", "hash": "bcfc9f2bccf4c6f0945054c3be3e041af3eb2f3e", "best_bid": "0.51", "best_ask": "0.52"}, {"asset_id": "15086968501686691607738632508897515530788413406991828817382775759887962883365", "price": "0.47", "size": "6798", "side": "BUY", "hash": "6fda20022093a21e6ce1390e5c2ba7c87ec84fe9", "best_bid": "0.48", "best_ask": "0.49"}], "timestamp": "1769384141248", "event_type": "price_change"}}
{"_local_timestamp": "2026-01-25T23:35:42.797424+00:00", "data": {"market": "0xfa5b189b04818014e796a6978b1f1e4f842cec8fe4b0f2aa2daa4b2ab7cc59b3", "price_changes": [{"asset_id": "76097257249586503390123122659919039099107925379782923914081177262841936638457", "price": "0.53", "size": "6694", "side": "SELL", "hash": "f56352367766f4526fa13ae28301ab7b9950b4f0", "best_bid": "0.51", "best_ask": "0.52"}, {"asset_id": "15086968501686691607738632508897515530788413406991828817382775759887962883365", "price": "0.47", "size": "6694", "side": "BUY", "hash": "f92b7c68f3100da777e2fd77c0dab3a7ea6b822f", "best_bid": "0.48", "best_ask": "0.49"}], "timestamp": "1769384142726", "event_type": "price_change"}}
{"_local_timestamp": "2026-01-25T23:35:42.819570+00:00", "data": {"market": "0xfa5b189b04818014e796a6978b1f1e4f842cec8fe4b0f2aa2daa4b2ab7cc59b3", "price_changes": [{"asset_id": "76097257249586503390123122659919039099107925379782923914081177262841936638457", "price": "0.53", "size": "6798", "side": "SELL", "hash": "da4732e24abcb88d19c9ae918d19fc38176e55d3", "best_bid": "0.51", "best_ask": "0.52"}, {"asset_id": "15086968501686691607738632508897515530788413406991828817382775759887962883365", "price": "0.47", "size": "6798", "side": "BUY", "hash": "0c6e60a75e4fb04e18cde755835274138eda3c25", "best_bid": "0.48", "best_ask": "0.49"}], "timestamp": "1769384142754", "event_type": "price_change"}}
{"_local_timestamp": "2026-01-25T23:35:44.298513+00:00", "data": {"market": "0xfa5b189b04818014e796a6978b1f1e4f842cec8fe4b0f2aa2daa4b2ab7cc59b3", "price_changes": [{"asset_id": "76097257249586503390123122659919039099107925379782923914081177262841936638457", "price": "0.53", "size": "6694", "side": "SELL", "hash": "32c824b1466222ec81b724c6e01106bfac9ff16f", "best_bid": "0.51", "best_ask": "0.52"}, {"asset_id": "15086968501686691607738632508897515530788413406991828817382775759887962883365", "price": "0.47", "size": "6694", "side": "BUY", "hash": "2b8c59788c20e04466499ac373726cced2feb577", "best_bid": "0.48", "best_ask": "0.49"}], "timestamp": "1769384144234", "event_type": "price_change"}}
{"_local_timestamp": "2026-01-25T23:35:44.332774+00:00", "data": {"market": "0xfa5b189b04818014e796a6978b1f1e4f842cec8fe4b0f2aa2daa4b2ab7cc59b3", "price_changes": [{"asset_id": "76097257249586503390123122659919039099107925379782923914081177262841936638457", "price": "0.53", "size": "6798", "side": "SELL", "hash": "229ae7422cfe78c09631430b9e0d2ad6c88365f4", "best_bid": "0.51", "best_ask": "0.52"}, {"asset_id": "15086968501686691607738632508897515530788413406991828817382775759887962883365", "price": "0.47", "size": "6798", "side": "BUY", "hash": "efd9093a4773ffa789f39591d02b8007be90be05", "best_bid": "0.48", "best_ask": "0.49"}], "timestamp": "1769384144265", "event_type": "price_change"}}
{"_local_timestamp": "2026-01-25T23:35:45.796895+00:00", "data": {"market": "0xfa5b189b04818014e796a6978b1f1e4f842cec8fe4b0f2aa2daa4b2ab7cc59b3", "price_changes": [{"asset_id": "76097257249586503390123122659919039099107925379782923914081177262841936638457", "price": "0.53", "size": "6694", "side": "SELL", "hash": "c03c981476218867e3afc9e79d02a4bfe2934536", "best_bid": "0.51", "best_ask": "0.52"}, {"asset_id": "15086968501686691607738632508897515530788413406991828817382775759887962883365", "price": "0.47", "size": "6694", "side": "BUY", "hash": "c59bb53fa1d9312376224ba4b1c5bc84aa6e5e8d", "best_bid": "0.48", "best_ask": "0.49"}], "timestamp": "1769384145725", "event_type": "price_change"}}
{"_local_timestamp": "2026-01-25T23:35:45.816212+00:00", "data": {"market": "0xfa5b189b04818014e796a6978b1f1e4f842cec8fe4b0f2aa2daa4b2ab7cc59b3", "price_changes": [{"asset_id": "76097257249586503390123122659919039099107925379782923914081177262841936638457", "price": "0.53", "size": "6798", "side": "SELL", "hash": "6994066e952973a1a616f17fdb2feb422c2c7f2b", "best_bid": "0.51", "best_ask": "0.52"}, {"asset_id": "15086968501686691607738632508897515530788413406991828817382775759887962883365", "price": "0.47", "size": "6798", "side": "BUY", "hash": "48d8a3ff8e92c3aa28dd27d21f932647d57141b8", "best_bid": "0.48", "best_ask": "0.49"}], "timestamp": "1769384145751", "event_type": "price_change"}}
{"_local_timestamp": "2026-01-25T23:35:47.299740+00:00", "data": {"market": "0xfa5b189b04818014e796a6978b1f1e4f842cec8fe4b0f2aa2daa4b2ab7cc59b3", "price_changes": [{"asset_id": "76097257249586503390123122659919039099107925379782923914081177262841936638457", "price": "0.53", "size": "6694", "side": "SELL", "hash": "aa24c7f73f1f6b523819b6a229ee172780abc75a", "best_bid": "0.51", "best_ask": "0.52"}, {"asset_id": "15086968501686691607738632508897515530788413406991828817382775759887962883365", "price": "0.47", "size": "6694", "side": "BUY", "hash": "a5d21af59f5c7138cb4bac86dbfb5623b2c0c621", "best_bid": "0.48", "best_ask": "0.49"}], "timestamp": "1769384147232", "event_type": "price_change"}}
{"_local_timestamp": "2026-01-25T23:35:47.327075+00:00", "data": {"market": "0xfa5b189b04818014e796a6978b1f1e4f842cec8fe4b0f2aa2daa4b2ab7cc59b3", "price_changes": [{"asset_id": "76097257249586503390123122659919039099107925379782923914081177262841936638457", "price": "0.53", "size": "6798", "side": "SELL", "hash": "291d7c4cbfe21731f4d9730aba64110c4188843d", "best_bid": "0.51", "best_ask": "0.52"}, {"asset_id": "15086968501686691607738632508897515530788413406991828817382775759887962883365", "price": "0.47", "size": "6798", "side": "BUY", "hash": "a4abfc12c99494d3af9f5e1c58230bdf9ab5bae7", "best_bid": "0.48", "best_ask": "0.49"}], "timestamp": "1769384147258", "event_type": "price_change"}}
{"_local_timestamp": "2026-01-25T23:35:48.790368+00:00", "data": {"market": "0xfa5b189b04818014e796a6978b1f1e4f842cec8fe4b0f2aa2daa4b2ab7cc59b3", "price_changes": [{"asset_id": "76097257249586503390123122659919039099107925379782923914081177262841936638457", "price": "0.53", "size": "6694", "side": "SELL", "hash": "6585308dc06d83a60dd6d4b32fcba924632398a4", "best_bid": "0.51", "best_ask": "0.52"}, {"asset_id": "15086968501686691607738632508897515530788413406991828817382775759887962883365", "price": "0.47", "size": "6694", "side": "BUY", "hash": "c19df56b24a5a1b4546370b347b0d89595463d70", "best_bid": "0.48", "best_ask": "0.49"}], "timestamp": "1769384148725", "event_type": "price_change"}}
{"_local_timestamp": "2026-01-25T23:35:48.820905+00:00", "data": {"market": "0xfa5b189b04818014e796a6978b1f1e4f842cec8fe4b0f2aa2daa4b2ab7cc59b3", "price_changes": [{"asset_id": "76097257249586503390123122659919039099107925379782923914081177262841936638457", "price": "0.53", "size": "6798", "side": "SELL", "hash": "4675096d43fb31fc4366f0fe2b15ce4a310b7057", "best_bid": "0.51", "best_ask": "0.52"}, {"asset_id": "15086968501686691607738632508897515530788413406991828817382775759887962883365", "price": "0.47", "size": "6798", "side": "BUY", "hash": "221ce3a081b71ecf505cad5853ccd7b7d5a1319d", "best_bid": "0.48", "best_ask": "0.49"}], "timestamp": "1769384148752", "event_type": "price_change"}}
{"_local_timestamp": "2026-01-25T23:35:50.322167+00:00", "data": {"market": "0xfa5b189b04818014e796a6978b1f1e4f842cec8fe4b0f2aa2daa4b2ab7cc59b3", "price_changes": [{"asset_id": "76097257249586503390123122659919039099107925379782923914081177262841936638457", "price": "0.53", "size": "6694", "side": "SELL", "hash": "1ef5fcc33da3fdc3cf007f9bbeb3c77bf087a5bc", "best_bid": "0.51", "best_ask": "0.52"}, {"asset_id": "15086968501686691607738632508897515530788413406991828817382775759887962883365", "price": "0.47", "size": "6694", "side": "BUY", "hash": "f776a9efd9b501254a8d51861d127e354db47efe", "best_bid": "0.48", "best_ask": "0.49"}], "timestamp": "1769384150247", "event_type": "price_change"}}
{"_local_timestamp": "2026-01-25T23:35:50.351215+00:00", "data": {"market": "0xfa5b189b04818014e796a6978b1f1e4f842cec8fe4b0f2aa2daa4b2ab7cc59b3", "price_changes": [{"asset_id": "76097257249586503390123122659919039099107925379782923914081177262841936638457", "price": "0.53", "size": "6798", "side": "SELL", "hash": "a7bf2922d5208d08a915c69e09dedca5b3b710bb", "best_bid": "0.51", "best_ask": "0.52"}, {"asset_id": "15086968501686691607738632508897515530788413406991828817382775759887962883365", "price": "0.47", "size": "6798", "side": "BUY", "hash": "ef032f3d071f7a68ce9e3cf153725773e2f02c7f", "best_bid": "0.48", "best_ask": "0.49"}], "timestamp": "1769384150275", "event_type": "price_change"}}
{"_local_timestamp": "2026-01-25T23:35:51.786982+00:00", "data": {"market": "0xfa5b189b04818014e796a6978b1f1e4f842cec8fe4b0f2aa2daa4b2ab7cc59b3", "price_changes": [{"asset_id": "76097257249586503390123122659919039099107925379782923914081177262841936638457", "price": "0.53", "size": "6694", "side": "SELL", "hash": "7c9e7da9baf03307bc37e12fbe3e75f3d92e6ab0", "best_bid": "0.51", "best_ask": "0.52"}, {"asset_id": "15086968501686691607738632508897515530788413406991828817382775759887962883365", "price": "0.47", "size": "6694", "side": "BUY", "hash": "5827ebe6290bda78bd13f18ff5234c0c7bc48388", "best_bid": "0.48", "best_ask": "0.49"}], "timestamp": "1769384151721", "event_type": "price_change"}}
{"_local_timestamp": "2026-01-25T23:35:51.818346+00:00", "data": {"market": "0xfa5b189b04818014e796a6978b1f1e4f842cec8fe4b0f2aa2daa4b2ab7cc59b3", "price_changes": [{"asset_id": "76097257249586503390123122659919039099107925379782923914081177262841936638457", "price": "0.53", "size": "6798", "side": "SELL", "hash": "8b0a0102db3c5dc4fd528ae52d2d62af1ea9d5d7", "best_bid": "0.51", "best_ask": "0.52"}, {"asset_id": "15086968501686691607738632508897515530788413406991828817382775759887962883365", "price": "0.47", "size": "6798", "side": "BUY", "hash": "ad06eaf8483805c504b65305d5e99572e7b7b9de", "best_bid": "0.48", "best_ask": "0.49"}], "timestamp": "1769384151749", "event_type": "price_change"}}
{"_local_timestamp": "2026-01-25T23:35:53.292905+00:00", "data": {"market": "0xfa5b189b04818014e796a6978b1f1e4f842cec8fe4b0f2aa2daa4b2ab7cc59b3", "price_changes": [{"asset_id": "76097257249586503390123122659919039099107925379782923914081177262841936638457", "price": "0.53", "size": "6694", "side": "SELL", "hash": "3f929c3b262c425834486a90fc2897cc667b6674", "best_bid": "0.51", "best_ask": "0.52"}, {"asset_id": "15086968501686691607738632508897515530788413406991828817382775759887962883365", "price": "0.47", "size": "6694", "side": "BUY", "hash": "78c1a7d7712e7714a7b9efa6fc759e0d18e8f072", "best_bid": "0.48", "best_ask": "0.49"}], "timestamp": "1769384153223", "event_type": "price_change"}}
{"_local_timestamp": "2026-01-25T23:35:53.320569+00:00", "data": {"market": "0xfa5b189b04818014e796a6978b1f1e4f842cec8fe4b0f2aa2daa4b2ab7cc59b3", "price_changes": [{"asset_id": "76097257249586503390123122659919039099107925379782923914081177262841936638457", "price": "0.53", "size": "6798", "side": "SELL", "hash": "73f3a0704f2ed53250495f3eb73431fbd1ba9427", "best_bid": "0.51", "best_ask": "0.52"}, {"asset_id": "15086968501686691607738632508897515530788413406991828817382775759887962883365", "price": "0.47", "size": "6798", "side": "BUY", "hash": "77a49d579eef07036ebfb96a354e93d69b015bd2", "best_bid": "0.48", "best_ask": "0.49"}], "timestamp": "1769384153254", "event_type": "price_change"}}
{"_local_timestamp": "2026-01-25T23:35:54.820897+00:00", "data": {"market": "0xfa5b189b04818014e796a6978b1f1e4f842cec8fe4b0f2aa2daa4b2ab7cc59b3", "price_changes": [{"asset_id": "76097257249586503390123122659919039099107925379782923914081177262841936638457", "price": "0.53", "size": "6694", "side": "SELL", "hash": "5f11fe188284c11dfd8a9e403a669d99d4f0e581", "best_bid": "0.51", "best_ask": "0.52"}, {"asset_id": "15086968501686691607738632508897515530788413406991828817382775759887962883365", "price": "0.47", "size": "6694", "side": "BUY", "hash": "05de21ecdfc498c1782dadcbc71de3e9c3445f29", "best_bid": "0.48", "best_ask": "0.49"}], "timestamp": "1769384154724", "event_type": "price_change"}}
{"_local_timestamp": "2026-01-25T23:35:54.828544+00:00", "data": {"market": "0xfa5b189b04818014e796a6978b1f1e4f842cec8fe4b0f2aa2daa4b2ab7cc59b3", "price_changes": [{"asset_id": "76097257249586503390123122659919039099107925379782923914081177262841936638457", "price": "0.53", "size": "6798", "side": "SELL", "hash": "c4e5b7ac94bdff1786e3866cdeb07f5378bcb9a8", "best_bid": "0.51", "best_ask": "0.52"}, {"asset_id": "15086968501686691607738632508897515530788413406991828817382775759887962883365", "price": "0.47", "size": "6798", "side": "BUY", "hash": "d32e85210764c088649ea47b32f42a3f440fc40b", "best_bid": "0.48", "best_ask": "0.49"}], "timestamp": "1769384154757", "event_type": "price_change"}}
{"_local_timestamp": "2026-01-25T23:35:56.299249+00:00", "data": {"market": "0xfa5b189b04818014e796a6978b1f1e4f842cec8fe4b0f2aa2daa4b2ab7cc59b3", "price_changes": [{"asset_id": "76097257249586503390123122659919039099107925379782923914081177262841936638457", "price": "0.53", "size": "6694", "side": "SELL", "hash": "5b45bb80752c99b39cbcc527225d1f4628c99dda", "best_bid": "0.51", "best_ask": "0.52"}, {"asset_id": "15086968501686691607738632508897515530788413406991828817382775759887962883365", "price": "0.47", "size": "6694", "side": "BUY", "hash": "21a40576240327a15d5d5469db154b35616eab11", "best_bid": "0.48", "best_ask": "0.49"}], "timestamp": "1769384156233", "event_type": "price_change"}}
{"_local_timestamp": "2026-01-25T23:35:56.376928+00:00", "data": {"market": "0xfa5b189b04818014e796a6978b1f1e4f842cec8fe4b0f2aa2daa4b2ab7cc59b3", "price_changes": [{"asset_id": "76097257249586503390123122659919039099107925379782923914081177262841936638457", "price": "0.53", "size": "6798", "side": "SELL", "hash": "ad9d6ae9275e59f6307fb64c34825cf5fc659697", "best_bid": "0.51", "best_ask": "0.52"}, {"asset_id": "15086968501686691607738632508897515530788413406991828817382775759887962883365", "price": "0.47", "size": "6798", "side": "BUY", "hash": "8b3e0839bc2060aed3637216a8ebb6351de30e5f", "best_bid": "0.48", "best_ask": "0.49"}], "timestamp": "1769384156279", "event_type": "price_change"}}
{"_local_timestamp": "2026-01-25T23:35:57.822486+00:00", "data": {"market": "0xfa5b189b04818014e796a6978b1f1e4f842cec8fe4b0f2aa2daa4b2ab7cc59b3", "price_changes": [{"asset_id": "76097257249586503390123122659919039099107925379782923914081177262841936638457", "price": "0.53", "size": "6694", "side": "SELL", "hash": "4c2c6f2d4a7fa405df015c4c3cab4a17d69299bc", "best_bid": "0.51", "best_ask": "0.52"}, {"asset_id": "15086968501686691607738632508897515530788413406991828817382775759887962883365", "price": "0.47", "size": "6694", "side": "BUY", "hash": "cd39082e830f4c690d7fc02ba8dcfa3089752ffe", "best_bid": "0.48", "best_ask": "0.49"}], "timestamp": "1769384157722", "event_type": "price_change"}}
{"_local_timestamp": "2026-01-25T23:35:57.841192+00:00", "data": {"market": "0xfa5b189b04818014e796a6978b1f1e4f842cec8fe4b0f2aa2daa4b2ab7cc59b3", "price_changes": [{"asset_id": "76097257249586503390123122659919039099107925379782923914081177262841936638457", "price": "0.53", "size": "6798", "side": "SELL", "hash": "3a699202f6ae6cee1ff39f65aae544c471251785", "best_bid": "0.51", "best_ask": "0.52"}, {"asset_id": "15086968501686691607738632508897515530788413406991828817382775759887962883365", "price": "0.47", "size": "6798", "side": "BUY", "hash": "da23829a23c64fc131bae20f50b461f30c883353", "best_bid": "0.48", "best_ask": "0.49"}], "timestamp": "1769384157750", "event_type": "price_change"}}
{"_local_timestamp": "2026-01-25T23:35:59.299248+00:00", "data": {"market": "0xfa5b189b04818014e796a6978b1f1e4f842cec8fe4b0f2aa2daa4b2ab7cc59b3", "price_changes": [{"asset_id": "76097257249586503390123122659919039099107925379782923914081177262841936638457", "price": "0.53", "size": "6694", "side": "SELL", "hash": "a7f9f81cd47197cbcbba44921e6b92b9c8fe95ab", "best_bid": "0.51", "best_ask": "0.52"}, {"asset_id": "15086968501686691607738632508897515530788413406991828817382775759887962883365", "price": "0.47", "size": "6694", "side": "BUY", "hash": "9104a3892b80fbfd354a3756f04b5c5b8da3c328", "best_bid": "0.48", "best_ask": "0.49"}], "timestamp": "1769384159224", "event_type": "price_change"}}
{"_local_timestamp": "2026-01-25T23:35:59.319103+00:00", "data": {"market": "0xfa5b189b04818014e796a6978b1f1e4f842cec8fe4b0f2aa2daa4b2ab7cc59b3", "price_changes": [{"asset_id": "76097257249586503390123122659919039099107925379782923914081177262841936638457", "price": "0.53", "size": "6798", "side": "SELL", "hash": "cbf9c2f45370df329c31f84ee8258da3b5e1040f", "best_bid": "0.51", "best_ask": "0.52"}, {"asset_id": "15086968501686691607738632508897515530788413406991828817382775759887962883365", "price": "0.47", "size": "6798", "side": "BUY", "hash": "fee734c1fcaa5d4fedb007d88b6968ff2236caae", "best_bid": "0.48", "best_ask": "0.49"}], "timestamp": "1769384159249", "event_type": "price_change"}}
{"_local_timestamp": "2026-01-25T23:36:00.813821+00:00", "data": {"market": "0xfa5b189b04818014e796a6978b1f1e4f842cec8fe4b0f2aa2daa4b2ab7cc59b3", "price_changes": [{"asset_id": "76097257249586503390123122659919039099107925379782923914081177262841936638457", "price": "0.53", "size": "6694", "side": "SELL", "hash": "36d7151756566b9de88dca602f18662165126eb6", "best_bid": "0.51", "best_ask": "0.52"}, {"asset_id": "15086968501686691607738632508897515530788413406991828817382775759887962883365", "price": "0.47", "size": "6694", "side": "BUY", "hash": "246f0444ddb6b4bba35361c902b37846cfc8b37e", "best_bid": "0.48", "best_ask": "0.49"}], "timestamp": "1769384160740", "event_type": "price_change"}}
{"_local_timestamp": "2026-01-25T23:36:00.837344+00:00", "data": {"market": "0xfa5b189b04818014e796a6978b1f1e4f842cec8fe4b0f2aa2daa4b2ab7cc59b3", "price_changes": [{"asset_id": "76097257249586503390123122659919039099107925379782923914081177262841936638457", "price": "0.53", "size": "6798", "side": "SELL", "hash": "be95592d73ca1c1c4d2139632fd05ffdb5b24d6a", "best_bid": "0.51", "best_ask": "0.52"}, {"asset_id": "15086968501686691607738632508897515530788413406991828817382775759887962883365", "price": "0.47", "size": "6798", "side": "BUY", "hash": "232e8df5d2d893c2d574d813d24e08b0b8fdf00d", "best_bid": "0.48", "best_ask": "0.49"}], "timestamp": "1769384160769", "event_type": "price_change"}}
{"_local_timestamp": "2026-01-25T23:36:02.337116+00:00", "data": {"market": "0xfa5b189b04818014e796a6978b1f1e4f842cec8fe4b0f2aa2daa4b2ab7cc59b3", "price_changes": [{"asset_id": "76097257249586503390123122659919039099107925379782923914081177262841936638457", "price": "0.53", "size": "6694", "side": "SELL", "hash": "071b70a3fa71d16ca765ebefa8d633a911367823", "best_bid": "0.51", "best_ask": "0.52"}, {"asset_id": "15086968501686691607738632508897515530788413406991828817382775759887962883365", "price": "0.47", "size": "6694", "side": "BUY", "hash": "0e4790a6369d41616fcce2d0185e3735e92154c0", "best_bid": "0.48", "best_ask": "0.49"}], "timestamp": "1769384162255", "event_type": "price_change"}}
{"_local_timestamp": "2026-01-25T23:36:02.410980+00:00", "data": {"market": "0xfa5b189b04818014e796a6978b1f1e4f842cec8fe4b0f2aa2daa4b2ab7cc59b3", "price_changes": [{"asset_id": "76097257249586503390123122659919039099107925379782923914081177262841936638457", "price": "0.53", "size": "6798", "side": "SELL", "hash": "fabc90233da5e01e39ee672f081f3f4c908bd2a9", "best_bid": "0.51", "best_ask": "0.52"}, {"asset_id": "15086968501686691607738632508897515530788413406991828817382775759887962883365", "price": "0.47", "size": "6798", "side": "BUY", "hash": "3d196fa95dd82844bd1c6dc931bef2462201b70d", "best_bid": "0.48", "best_ask": "0.49"}], "timestamp": "1769384162283", "event_type": "price_change"}}
{"_local_timestamp": "2026-01-25T23:36:03.810556+00:00", "data": {"market": "0xfa5b189b04818014e796a6978b1f1e4f842cec8fe4b0f2aa2daa4b2ab7cc59b3", "price_changes": [{"asset_id": "76097257249586503390123122659919039099107925379782923914081177262841936638457", "price": "0.53", "size": "6694", "side": "SELL", "hash": "5af63d14b4a0317777a1ec0751a4a868a9a19b25", "best_bid": "0.51", "best_ask": "0.52"}, {"asset_id": "15086968501686691607738632508897515530788413406991828817382775759887962883365", "price": "0.47", "size": "6694", "side": "BUY", "hash": "ed44fa5d58039a7838fa88798d723087bca7ad5d", "best_bid": "0.48", "best_ask": "0.49"}], "timestamp": "1769384163729", "event_type": "price_change"}}
{"_local_timestamp": "2026-01-25T23:36:03.825205+00:00", "data": {"market": "0xfa5b189b04818014e796a6978b1f1e4f842cec8fe4b0f2aa2daa4b2ab7cc59b3", "price_changes": [{"asset_id": "76097257249586503390123122659919039099107925379782923914081177262841936638457", "price": "0.53", "size": "6798", "side": "SELL", "hash": "f9d6d3db7eaaebb592d5394c3c92feeb1cc336b2", "best_bid": "0.51", "best_ask": "0.52"}, {"asset_id": "15086968501686691607738632508897515530788413406991828817382775759887962883365", "price": "0.47", "size": "6798", "side": "BUY", "hash": "63376d699296d83e8566deafa3ecb1fe29808896", "best_bid": "0.48", "best_ask": "0.49"}], "timestamp": "1769384163755", "event_type": "price_change"}}
{"_local_timestamp": "2026-01-25T23:36:05.288708+00:00", "data": {"market": "0xfa5b189b04818014e796a6978b1f1e4f842cec8fe4b0f2aa2daa4b2ab7cc59b3", "price_changes": [{"asset_id": "76097257249586503390123122659919039099107925379782923914081177262841936638457", "price": "0.53", "size": "6694", "side": "SELL", "hash": "7bf6c72af9ea72cfc83e6fea991320ed58389089", "best_bid": "0.51", "best_ask": "0.52"}, {"asset_id": "15086968501686691607738632508897515530788413406991828817382775759887962883365", "price": "0.47", "size": "6694", "side": "BUY", "hash": "bf7f5c26eee64f7ea823b9fb8ffebbb56f450a3f", "best_bid": "0.48", "best_ask": "0.49"}], "timestamp": "1769384165223", "event_type": "price_change"}}
{"_local_timestamp": "2026-01-25T23:36:05.313196+00:00", "data": {"market": "0xfa5b189b04818014e796a6978b1f1e4f842cec8fe4b0f2aa2daa4b2ab7cc59b3", "price_changes": [{"asset_id": "76097257249586503390123122659919039099107925379782923914081177262841936638457", "price": "0.53", "size": "6798", "side": "SELL", "hash": "eedcbbbd3413c18a77aabc92d694279803963276", "best_bid": "0.51", "best_ask": "0.52"}, {"asset_id": "15086968501686691607738632508897515530788413406991828817382775759887962883365", "price": "0.47", "size": "6798", "side": "BUY", "hash": "f541ccdd11adc4da390420c647e5ae8b8c15e0d9", "best_bid": "0.48", "best_ask": "0.49"}], "timestamp": "1769384165247", "event_type": "price_change"}}
{"_local_timestamp": "2026-01-25T23:36:06.792662+00:00", "data": {"market": "0xfa5b189b04818014e796a6978b1f1e4f842cec8fe4b0f2aa2daa4b2ab7cc59b3", "price_changes": [{"asset_id": "76097257249586503390123122659919039099107925379782923914081177262841936638457", "price": "0.53", "size": "6694", "side": "SELL", "hash": "926e70426d219d9d43c21bfd8d63fe76f7e8e4e4", "best_bid": "0.51", "best_ask": "0.52"}, {"asset_id": "15086968501686691607738632508897515530788413406991828817382775759887962883365", "price": "0.47", "size": "6694", "side": "BUY", "hash": "52a41e7c40a3033257926ef1b8d9aaaee5ee06dd", "best_bid": "0.48", "best_ask": "0.49"}], "timestamp": "1769384166722", "event_type": "price_change"}}
{"_local_timestamp": "2026-01-25T23:36:06.817015+00:00", "data": {"market": "0xfa5b189b04818014e796a6978b1f1e4f842cec8fe4b0f2aa2daa4b2ab7cc59b3", "price_changes": [{"asset_id": "76097257249586503390123122659919039099107925379782923914081177262841936638457", "price": "0.53", "size": "6798", "side": "SELL", "hash": "736480ff30c5ab2e24e64f669d35a7fb14b3192d", "best_bid": "0.51", "best_ask": "0.52"}, {"asset_id": "15086968501686691607738632508897515530788413406991828817382775759887962883365", "price": "0.47", "size": "6798", "side": "BUY", "hash": "a1ce22c14bda423d022cc968f8e8f23dad46eff4", "best_bid": "0.48", "best_ask": "0.49"}], "timestamp": "1769384166749", "event_type": "price_change"}}
{"_local_timestamp": "2026-01-25T23:36:07.086886+00:00", "data": {"market": "0x900ecfb22add054072f36bc9c943bb05e02369cd1d55dce3ee5b8cf4ae2af764", "price_changes": [{"asset_id": "72955248379058153293084602651666522215407419096114442653795152349439056321315", "price": "0.52", "size": "306.99", "side": "BUY", "hash": "28f472bee7c721ed76e269e93b0e11abbbad22f8", "best_bid": "0.52", "best_ask": "0.56"}, {"asset_id": "90499528413305425764851960350753110982866738119170371042863813719685571770922", "price": "0.48", "size": "306.99", "side": "SELL", "hash": "4b6539efd170fe178604ebb7ee86331b658e898f", "best_bid": "0.44", "best_ask": "0.48"}], "timestamp": "1769384167004", "event_type": "price_change"}}
{"_local_timestamp": "2026-01-25T23:36:07.131735+00:00", "data": {"market": "0x900ecfb22add054072f36bc9c943bb05e02369cd1d55dce3ee5b8cf4ae2af764", "price_changes": [{"asset_id": "72955248379058153293084602651666522215407419096114442653795152349439056321315", "price": "0.03", "size": "59.69", "side": "BUY", "hash": "70f781bc145ede5fa82f484e33a9927f66d8d131", "best_bid": "0.52", "best_ask": "0.56"}, {"asset_id": "90499528413305425764851960350753110982866738119170371042863813719685571770922", "price": "0.97", "size": "59.69", "side": "SELL", "hash": "76d3a049d80f6e9485d3e3bb2889d8fe912599a5", "best_bid": "0.44", "best_ask": "0.48"}], "timestamp": "1769384167063", "event_type": "price_change"}}
{"_local_timestamp": "2026-01-25T23:36:07.138646+00:00", "data": {"market": "0x900ecfb22add054072f36bc9c943bb05e02369cd1d55dce3ee5b8cf4ae2af764", "price_changes": [{"asset_id": "72955248379058153293084602651666522215407419096114442653795152349439056321315", "price": "0.52", "size": "351.99", "side": "BUY", "hash": "1dc093237cf76c49d6e6c8c35509fec8f26f2333", "best_bid": "0.52", "best_ask": "0.56"}, {"asset_id": "90499528413305425764851960350753110982866738119170371042863813719685571770922", "price": "0.48", "size": "351.99", "side": "SELL", "hash": "871e646bce3028fd9e1109036a0928b6a3579280", "best_bid": "0.44", "best_ask": "0.48"}], "timestamp": "1769384167064", "event_type": "price_change"}}
{"_local_timestamp": "2026-01-25T23:36:07.139728+00:00", "data": {"market": "0x900ecfb22add054072f36bc9c943bb05e02369cd1d55dce3ee5b8cf4ae2af764", "price_changes": [{"asset_id": "72955248379058153293084602651666522215407419096114442653795152349439056321315", "price": "0.02", "size": "700", "side": "BUY", "hash": "3ff3c508b9eb4788d146b7e0eca523093847b3ce", "best_bid": "0.52", "best_ask": "0.56"}, {"asset_id": "90499528413305425764851960350753110982866738119170371042863813719685571770922", "price": "0.98", "size": "700", "side": "SELL", "hash": "4a30f509717815f6963351502c23c2dbdb182551", "best_bid": "0.44", "best_ask": "0.48"}], "timestamp": "1769384167066", "event_type": "price_change"}}
{"_local_timestamp": "2026-01-25T23:36:07.140594+00:00", "data": {"market": "0x900ecfb22add054072f36bc9c943bb05e02369cd1d55dce3ee5b8cf4ae2af764", "price_changes": [{"asset_id": "72955248379058153293084602651666522215407419096114442653795152349439056321315", "price": "0.5", "size": "0", "side": "BUY", "hash": "3ff3c508b9eb4788d146b7e0eca523093847b3ce", "best_bid": "0.52", "best_ask": "0.56"}, {"asset_id": "90499528413305425764851960350753110982866738119170371042863813719685571770922", "price": "0.5", "size": "0", "side": "SELL", "hash": "4a30f509717815f6963351502c23c2dbdb182551", "best_bid": "0.44", "best_ask": "0.48"}], "timestamp": "1769384167066", "event_type": "price_change"}}
{"_local_timestamp": "2026-01-25T23:36:07.612688+00:00", "data": {"market": "0xda92713dcfd1002a861dc7927afe82dbd81a0bcb45a8468e15cebc3adb455f2a", "price_changes": [{"asset_id": "67847413380699129626284788855443204194830281546928428292927803428848858907175", "price": "0.69", "size": "380.14", "side": "BUY", "hash": "f9b35b6630591b0604b7aa7873367b920f79e7eb", "best_bid": "0.69", "best_ask": "0.72"}, {"asset_id": "61199962474262836932103113956187992633340535926439339471247709440883806095370", "price": "0.31", "size": "380.14", "side": "SELL", "hash": "84d55560986c2daabc579920adcdd3f27bbf64f0", "best_bid": "0.28", "best_ask": "0.31"}], "timestamp": "1769384167544", "event_type": "price_change"}}
{"_local_timestamp": "2026-01-25T23:36:08.294801+00:00", "data": {"market": "0xfa5b189b04818014e796a6978b1f1e4f842cec8fe4b0f2aa2daa4b2ab7cc59b3", "price_changes": [{"asset_id": "76097257249586503390123122659919039099107925379782923914081177262841936638457", "price": "0.53", "size": "6694", "side": "SELL", "hash": "bf7e2c9e1d3096c35248c3099efa423271186fa0", "best_bid": "0.51", "best_ask": "0.52"}, {"asset_id": "15086968501686691607738632508897515530788413406991828817382775759887962883365", "price": "0.47", "size": "6694", "side": "BUY", "hash": "cdab3d4f7712519fdbf5806a8948331c7c0969c7", "best_bid": "0.48", "best_ask": "0.49"}], "timestamp": "1769384168225", "event_type": "price_change"}}
{"_local_timestamp": "2026-01-25T23:36:08.338810+00:00", "data": {"market": "0xfa5b189b04818014e796a6978b1f1e4f842cec8fe4b0f2aa2daa4b2ab7cc59b3", "price_changes": [{"asset_id": "76097257249586503390123122659919039099107925379782923914081177262841936638457", "price": "0.53", "size": "6798", "side": "SELL", "hash": "442c7d1ac2603ff706b3f31492434eca4fcec364", "best_bid": "0.51", "best_ask": "0.52"}, {"asset_id": "15086968501686691607738632508897515530788413406991828817382775759887962883365", "price": "0.47", "size": "6798", "side": "BUY", "hash": "bf5a5e52623d26b547d3269a623c7e1717f5217f", "best_bid": "0.48", "best_ask": "0.49"}], "timestamp": "1769384168267", "event_type": "price_change"}}
{"_local_timestamp": "2026-01-25T23:36:09.806616+00:00", "data": {"market": "0xfa5b189b04818014e796a6978b1f1e4f842cec8fe4b0f2aa2daa4b2ab7cc59b3", "price_changes": [{"asset_id": "76097257249586503390123122659919039099107925379782923914081177262841936638457", "price": "0.53", "size": "6694", "side": "SELL", "hash": "02b951acff5f72f8afe3aeb57646c05e3ec97096", "best_bid": "0.51", "best_ask": "0.52"}, {"asset_id": "15086968501686691607738632508897515530788413406991828817382775759887962883365", "price": "0.47", "size": "6694", "side": "BUY", "hash": "0017af68a9b2991ff71401253869b9e3dd3d634e", "best_bid": "0.48", "best_ask": "0.49"}], "timestamp": "1769384169721", "event_type": "price_change"}}
{"_local_timestamp": "2026-01-25T23:36:09.831218+00:00", "data": {"market": "0xfa5b189b04818014e796a6978b1f1e4f842cec8fe4b0f2aa2daa4b2ab7cc59b3", "price_changes": [{"asset_id": "76097257249586503390123122659919039099107925379782923914081177262841936638457", "price": "0.53", "size": "6798", "side": "SELL", "hash": "d7264b39dbd7e76d3cc48c709d8b8a05c78a8de5", "best_bid": "0.51", "best_ask": "0.52"}, {"asset_id": "15086968501686691607738632508897515530788413406991828817382775759887962883365", "price": "0.47", "size": "6798", "side": "BUY", "hash": "33242d3b3f33fec45623cc6d198f063795f45951", "best_bid": "0.48", "best_ask": "0.49"}], "timestamp": "1769384169755", "event_type": "price_change"}}
{"_local_timestamp": "2026-01-25T23:36:11.293678+00:00", "data": {"market": "0xfa5b189b04818014e796a6978b1f1e4f842cec8fe4b0f2aa2daa4b2ab7cc59b3", "price_changes": [{"asset_id": "76097257249586503390123122659919039099107925379782923914081177262841936638457", "price": "0.53", "size": "6694", "side": "SELL", "hash": "11b69f43062e9a4e7c1dd7ad78acb15f7f1af2dd", "best_bid": "0.51", "best_ask": "0.52"}, {"asset_id": "15086968501686691607738632508897515530788413406991828817382775759887962883365", "price": "0.47", "size": "6694", "side": "BUY", "hash": "e34ac6db0a179d159854d475963000afc111e4b2", "best_bid": "0.48", "best_ask": "0.49"}], "timestamp": "1769384171227", "event_type": "price_change"}}
{"_local_timestamp": "2026-01-25T23:36:11.327279+00:00", "data": {"market": "0xfa5b189b04818014e796a6978b1f1e4f842cec8fe4b0f2aa2daa4b2ab7cc59b3", "price_changes": [{"asset_id": "76097257249586503390123122659919039099107925379782923914081177262841936638457", "price": "0.53", "size": "6798", "side": "SELL", "hash": "75b1f0c749fd7528aea43e7f4c79db95c2ea358e", "best_bid": "0.51", "best_ask": "0.52"}, {"asset_id": "15086968501686691607738632508897515530788413406991828817382775759887962883365", "price": "0.47", "size": "6798", "side": "BUY", "hash": "086011c6a2157855e26c00f53028e76fd0e2e32b", "best_bid": "0.48", "best_ask": "0.49"}], "timestamp": "1769384171254", "event_type": "price_change"}}
{"_local_timestamp": "2026-01-25T23:36:12.794376+00:00", "data": {"market": "0xfa5b189b04818014e796a6978b1f1e4f842cec8fe4b0f2aa2daa4b2ab7cc59b3", "price_changes": [{"asset_id": "76097257249586503390123122659919039099107925379782923914081177262841936638457", "price": "0.53", "size": "6694", "side": "SELL", "hash": "60c16fadf8196e2b16a68e628f0e331895192207", "best_bid": "0.51", "best_ask": "0.52"}, {"asset_id": "15086968501686691607738632508897515530788413406991828817382775759887962883365", "price": "0.47", "size": "6694", "side": "BUY", "hash": "2232b519e18a39ce46210da65a7198e377ceec7f", "best_bid": "0.48", "best_ask": "0.49"}], "timestamp": "1769384172728", "event_type": "price_change"}}
{"_local_timestamp": "2026-01-25T23:36:12.826918+00:00", "data": {"market": "0xfa5b189b04818014e796a6978b1f1e4f842cec8fe4b0f2aa2daa4b2ab7cc59b3", "price_changes": [{"asset_id": "76097257249586503390123122659919039099107925379782923914081177262841936638457", "price": "0.53", "size": "6798", "side": "SELL", "hash": "3d0c0d5cb1c98487d7058556746fd2d9a070d564", "best_bid": "0.51", "best_ask": "0.52"}, {"asset_id": "15086968501686691607738632508897515530788413406991828817382775759887962883365", "price": "0.47", "size": "6798", "side": "BUY", "hash": "31e7813e815e02da1a80504c9429d2f7b19fdb60", "best_bid": "0.48", "best_ask": "0.49"}], "timestamp": "1769384172757", "event_type": "price_change"}}
{"_local_timestamp": "2026-01-25T23:36:14.332000+00:00", "data": {"market": "0xfa5b189b04818014e796a6978b1f1e4f842cec8fe4b0f2aa2daa4b2ab7cc59b3", "price_changes": [{"asset_id": "76097257249586503390123122659919039099107925379782923914081177262841936638457", "price": "0.53", "size": "6694", "side": "SELL", "hash": "fd285276093931041dfd06e2ade6e27df47cc170", "best_bid": "0.51", "best_ask": "0.52"}, {"asset_id": "15086968501686691607738632508897515530788413406991828817382775759887962883365", "price": "0.47", "size": "6694", "side": "BUY", "hash": "a6aac41caa018170136b0be086ab8374be68f403", "best_bid": "0.48", "best_ask": "0.49"}], "timestamp": "1769384174222", "event_type": "price_change"}}
{"_local_timestamp": "2026-01-25T23:36:14.343938+00:00", "data": {"market": "0xfa5b189b04818014e796a6978b1f1e4f842cec8fe4b0f2aa2daa4b2ab7cc59b3", "price_changes": [{"asset_id": "76097257249586503390123122659919039099107925379782923914081177262841936638457", "price": "0.53", "size": "6798", "side": "SELL", "hash": "ba748206617b535c9fd75a1b3c039eb4dd52d731", "best_bid": "0.51", "best_ask": "0.52"}, {"asset_id": "15086968501686691607738632508897515530788413406991828817382775759887962883365", "price": "0.47", "size": "6798", "side": "BUY", "hash": "e7cdd052139364ee45ebb94fbc6e6225ab11e53a", "best_bid": "0.48", "best_ask": "0.49"}], "timestamp": "1769384174248", "event_type": "price_change"}}
{"_local_timestamp": "2026-01-25T23:36:15.040709+00:00", "data": {"market": "0x900ecfb22add054072f36bc9c943bb05e02369cd1d55dce3ee5b8cf4ae2af764", "price_changes": [{"asset_id": "72955248379058153293084602651666522215407419096114442653795152349439056321315", "price": "0.52", "size": "45", "side": "BUY", "hash": "118fabb1858cadfb2a862ed64e6445e44c3ffd1e", "best_bid": "0.52", "best_ask": "0.56"}, {"asset_id": "90499528413305425764851960350753110982866738119170371042863813719685571770922", "price": "0.48", "size": "45", "side": "SELL", "hash": "0b3a0cece8d3c44ff129830d304a4a5648ae018c", "best_bid": "0.44", "best_ask": "0.48"}], "timestamp": "1769384174972", "event_type": "price_change"}}
{"_local_timestamp": "2026-01-25T23:36:15.108312+00:00", "data": {"market": "0x900ecfb22add054072f36bc9c943bb05e02369cd1d55dce3ee5b8cf4ae2af764", "price_changes": [{"asset_id": "72955248379058153293084602651666522215407419096114442653795152349439056321315", "price": "0.03", "size": "9.69", "side": "BUY", "hash": "9cde350c61f7f46da6a4c996c63fd3801d6c0c8c", "best_bid": "0.49", "best_ask": "0.56"}, {"asset_id": "90499528413305425764851960350753110982866738119170371042863813719685571770922", "price": "0.97", "size": "9.69", "side": "SELL", "hash": "80148bab253b74a62441d6ba989b8c5d3058cf14", "best_bid": "0.44", "best_ask": "0.51"}], "timestamp": "1769384175015", "event_type": "price_change"}}
{"_local_timestamp": "2026-01-25T23:36:15.109343+00:00", "data": {"market": "0x900ecfb22add054072f36bc9c943bb05e02369cd1d55dce3ee5b8cf4ae2af764", "price_changes": [{"asset_id": "72955248379058153293084602651666522215407419096114442653795152349439056321315", "price": "0.52", "size": "0", "side": "BUY", "hash": "9cde350c61f7f46da6a4c996c63fd3801d6c0c8c", "best_bid": "0.49", "best_ask": "0.56"}, {"asset_id": "90499528413305425764851960350753110982866738119170371042863813719685571770922", "price": "0.48", "size": "0", "side": "SELL", "hash": "80148bab253b74a62441d6ba989b8c5d3058cf14", "best_bid": "0.44", "best_ask": "0.51"}], "timestamp": "1769384175015", "event_type": "price_change"}}
{"_local_timestamp": "2026-01-25T23:36:15.111685+00:00", "data": {"market": "0x900ecfb22add054072f36bc9c943bb05e02369cd1d55dce3ee5b8cf4ae2af764", "price_changes": [{"asset_id": "72955248379058153293084602651666522215407419096114442653795152349439056321315", "price": "0.02", "size": "750", "side": "BUY", "hash": "088d079b09a47173223817fece464b9d2e4b80f0", "best_bid": "0.49", "best_ask": "0.56"}, {"asset_id": "90499528413305425764851960350753110982866738119170371042863813719685571770922", "price": "0.98", "size": "750", "side": "SELL", "hash": "ab031d1eff2a7e50cda71b33d29b901758fcd811", "best_bid": "0.44", "best_ask": "0.51"}], "timestamp": "1769384175022", "event_type": "price_change"}}
{"_local_timestamp": "2026-01-25T23:36:15.114101+00:00", "data": {"market": "0x900ecfb22add054072f36bc9c943bb05e02369cd1d55dce3ee5b8cf4ae2af764", "price_changes": [{"asset_id": "72955248379058153293084602651666522215407419096114442653795152349439056321315", "price": "0.5", "size": "50", "side": "BUY", "hash": "abbc940954f1d3b1008328ef07ef762441fe82d2", "best_bid": "0.5", "best_ask": "0.56"}, {"asset_id": "90499528413305425764851960350753110982866738119170371042863813719685571770922", "price": "0.5", "size": "50", "side": "SELL", "hash": "c91322940c993cab3d26a661811aec319befd6b4", "best_bid": "0.44", "best_ask": "0.5"}], "timestamp": "1769384175023", "event_type": "price_change"}}
{"_local_timestamp": "2026-01-25T23:36:15.811597+00:00", "data": {"market": "0xfa5b189b04818014e796a6978b1f1e4f842cec8fe4b0f2aa2daa4b2ab7cc59b3", "price_changes": [{"asset_id": "76097257249586503390123122659919039099107925379782923914081177262841936638457", "price": "0.53", "size": "6694", "side": "SELL", "hash": "c009b97014ecd148feeb58ad5369f20ce2f03ee8", "best_bid": "0.51", "best_ask": "0.52"}, {"asset_id": "15086968501686691607738632508897515530788413406991828817382775759887962883365", "price": "0.47", "size": "6694", "side": "BUY", "hash": "04bfc2d81f4eeba634aeb7a5c0f5db7dffc67601", "best_bid": "0.48", "best_ask": "0.49"}], "timestamp": "1769384175733", "event_type": "price_change"}}
{"_local_timestamp": "2026-01-25T23:36:15.850899+00:00", "data": {"market": "0xfa5b189b04818014e796a6978b1f1e4f842cec8fe4b0f2aa2daa4b2ab7cc59b3", "price_changes": [{"asset_id": "76097257249586503390123122659919039099107925379782923914081177262841936638457", "price": "0.53", "size": "6798", "side": "SELL", "hash": "e68ccb9f31ef06f1b5aa939784d1da8446e46604", "best_bid": "0.51", "best_ask": "0.52"}, {"asset_id": "15086968501686691607738632508897515530788413406991828817382775759887962883365", "price": "0.47", "size": "6798", "side": "BUY", "hash": "e9a7ea3846974fdbf1cd5ddd4c9afe46fa98a54b", "best_bid": "0.48", "best_ask": "0.49"}], "timestamp": "1769384175769", "event_type": "price_change"}}
{"_local_timestamp": "2026-01-25T23:36:16.784379+00:00", "data": {"market": "0xda92713dcfd1002a861dc7927afe82dbd81a0bcb45a8468e15cebc3adb455f2a", "price_changes": [{"asset_id": "67847413380699129626284788855443204194830281546928428292927803428848858907175", "price": "0.69", "size": "0", "side": "BUY", "hash": "fd0df23ae39fdd725a865d50c699deaa7e496465", "best_bid": "0.66", "best_ask": "0.72"}, {"asset_id": "61199962474262836932103113956187992633340535926439339471247709440883806095370", "price": "0.31", "size": "0", "side": "SELL", "hash": "cb03f5c1f60e83df8af880f6eafd65ea529cc4aa", "best_bid": "0.28", "best_ask": "0.34"}], "timestamp": "1769384176713", "event_type": "price_change"}}
{"_local_timestamp": "2026-01-25T23:36:17.290460+00:00", "data": {"market": "0xfa5b189b04818014e796a6978b1f1e4f842cec8fe4b0f2aa2daa4b2ab7cc59b3", "price_changes": [{"asset_id": "76097257249586503390123122659919039099107925379782923914081177262841936638457", "price": "0.53", "size": "6694", "side": "SELL", "hash": "c9383c3b12e397b539fcdc8462a8f7cdec5001bf", "best_bid": "0.51", "best_ask": "0.52"}, {"asset_id": "15086968501686691607738632508897515530788413406991828817382775759887962883365", "price": "0.47", "size": "6694", "side": "BUY", "hash": "56fd3edee9b6a1817d4dcbc589ad5597eada686a", "best_bid": "0.48", "best_ask": "0.49"}], "timestamp": "1769384177223", "event_type": "price_change"}}
{"_local_timestamp": "2026-01-25T23:36:17.319601+00:00", "data": {"market": "0xfa5b189b04818014e796a6978b1f1e4f842cec8fe4b0f2aa2daa4b2ab7cc59b3", "price_changes": [{"asset_id": "76097257249586503390123122659919039099107925379782923914081177262841936638457", "price": "0.53", "size": "6798", "side": "SELL", "hash": "f27cae09d98428a1dca961cd135d07f95f747357", "best_bid": "0.51", "best_ask": "0.52"}, {"asset_id": "15086968501686691607738632508897515530788413406991828817382775759887962883365", "price": "0.47", "size": "6798", "side": "BUY", "hash": "a099d42ed948a014f7fb6c30f4333f178a41e465", "best_bid": "0.48", "best_ask": "0.49"}], "timestamp": "1769384177251", "event_type": "price_change"}}
{"_local_timestamp": "2026-01-25T23:36:18.796239+00:00", "data": {"market": "0xfa5b189b04818014e796a6978b1f1e4f842cec8fe4b0f2aa2daa4b2ab7cc59b3", "price_changes": [{"asset_id": "76097257249586503390123122659919039099107925379782923914081177262841936638457", "price": "0.53", "size": "6694", "side": "SELL", "hash": "ab7837f27843af2eb155d7d2378b06778d8e2fdb", "best_bid": "0.51", "best_ask": "0.52"}, {"asset_id": "15086968501686691607738632508897515530788413406991828817382775759887962883365", "price": "0.47", "size": "6694", "side": "BUY", "hash": "09f89e540dd35da5387dfa36491d014867604a55", "best_bid": "0.48", "best_ask": "0.49"}], "timestamp": "1769384178724", "event_type": "price_change"}}
{"_local_timestamp": "2026-01-25T23:36:18.827020+00:00", "data": {"market": "0xfa5b189b04818014e796a6978b1f1e4f842cec8fe4b0f2aa2daa4b2ab7cc59b3", "price_changes": [{"asset_id": "76097257249586503390123122659919039099107925379782923914081177262841936638457", "price": "0.53", "size": "6798", "side": "SELL", "hash": "5e5beeb258865fd19fe9b457993b0a6a7a1a7512", "best_bid": "0.51", "best_ask": "0.52"}, {"asset_id": "15086968501686691607738632508897515530788413406991828817382775759887962883365", "price": "0.47", "size": "6798", "side": "BUY", "hash": "4462f3b81c6b6679e9e94112580d6959c537d72a", "best_bid": "0.48", "best_ask": "0.49"}], "timestamp": "1769384178755", "event_type": "price_change"}}
{"_local_timestamp": "2026-01-25T23:36:20.295356+00:00", "data": {"market": "0xfa5b189b04818014e796a6978b1f1e4f842cec8fe4b0f2aa2daa4b2ab7cc59b3", "price_changes": [{"asset_id": "76097257249586503390123122659919039099107925379782923914081177262841936638457", "price": "0.53", "size": "6694", "side": "SELL", "hash": "fbf6e023a4c79ab365ffa43ebd75d279d8562ccd", "best_bid": "0.51", "best_ask": "0.52"}, {"asset_id": "15086968501686691607738632508897515530788413406991828817382775759887962883365", "price": "0.47", "size": "6694", "side": "BUY", "hash": "c40073b13b1f4ba335541093d89ff3449d156576", "best_bid": "0.48", "best_ask": "0.49"}], "timestamp": "1769384180223", "event_type": "price_change"}}
{"_local_timestamp": "2026-01-25T23:36:20.328202+00:00", "data": {"market": "0xfa5b189b04818014e796a6978b1f1e4f842cec8fe4b0f2aa2daa4b2ab7cc59b3", "price_changes": [{"asset_id": "76097257249586503390123122659919039099107925379782923914081177262841936638457", "price": "0.53", "size": "6798", "side": "SELL", "hash": "e8ffe404dba990cf15eb9ef37e6baca78374ce6f", "best_bid": "0.51", "best_ask": "0.52"}, {"asset_id": "15086968501686691607738632508897515530788413406991828817382775759887962883365", "price": "0.47", "size": "6798", "side": "BUY", "hash": "a22f586bb46fbc4b3ced604eb3ef77c46df6e4c5", "best_bid": "0.48", "best_ask": "0.49"}], "timestamp": "1769384180257", "event_type": "price_change"}}
{"_local_timestamp": "2026-01-25T23:36:21.795930+00:00", "data": {"market": "0xfa5b189b04818014e796a6978b1f1e4f842cec8fe4b0f2aa2daa4b2ab7cc59b3", "price_changes": [{"asset_id": "76097257249586503390123122659919039099107925379782923914081177262841936638457", "price": "0.53", "size": "6694", "side": "SELL", "hash": "d78f6a17f3aa2aa5a6f8058b4c238de9440564f6", "best_bid": "0.51", "best_ask": "0.52"}, {"asset_id": "15086968501686691607738632508897515530788413406991828817382775759887962883365", "price": "0.47", "size": "6694", "side": "BUY", "hash": "873e42c2b45f47bc55b7fdfefc622416ff02a29b", "best_bid": "0.48", "best_ask": "0.49"}], "timestamp": "1769384181724", "event_type": "price_change"}}
{"_local_timestamp": "2026-01-25T23:36:21.814524+00:00", "data": {"market": "0xfa5b189b04818014e796a6978b1f1e4f842cec8fe4b0f2aa2daa4b2ab7cc59b3", "price_changes": [{"asset_id": "76097257249586503390123122659919039099107925379782923914081177262841936638457", "price": "0.53", "size": "6798", "side": "SELL", "hash": "0e9ddda9446ba04927cb2aa416a4e38afdac43bd", "best_bid": "0.51", "best_ask": "0.52"}, {"asset_id": "15086968501686691607738632508897515530788413406991828817382775759887962883365", "price": "0.47", "size": "6798", "side": "BUY", "hash": "a97eb695125d0b6eba2a1c46316dfa4c92310de5", "best_bid": "0.48", "best_ask": "0.49"}], "timestamp": "1769384181748", "event_type": "price_change"}}
