{"_local_timestamp": "2026-01-25T23:33:46.349931+00:00", "data": [{"market": "0x1c90e1383b8664103731bacc42ba86dff9c1582b8982f0ec02ba6aa255540dec", "asset_id": "10824614737277384579120931547716737694062714916890575016613469671599992760641", "timestamp": "1769384025288", "hash": "570afcd24b2d438f0f9c245c4f38b9539a96d72d", "bids": [{"price": "0.01", "size": "13601.71"}, {"price": "0.02", "size": "4048"}, {"price": "0.03", "size": "9.09"}, {"price": "0.04", "size": "1262"}, {"price": "0.05", "size": "810"}, {"price": "0.06", "size": "33"}, {"price": "0.08", "size": "128"}, {"price": "0.09", "size": "700"}, {"price": "0.1", "size": "6.3"}, {"price": "0.13", "size": "586.53"}, {"price": "0.16", "size": "64"}, {"price": "0.18", "size": "427.77"}, {"price": "0.21", "size": "810"}, {"price": "0.22", "size": "127.27"}, {"price": "0.23", "size": "1876"}, {"price": "0.27", "size": "196.29"}, {"price": "0.28", "size": "300"}, {"price": "0.3", "size": "100"}, {"price": "0.31", "size": "77.41"}, {"price": "0.32", "size": "32"}, {"price": "0.34", "size": "100"}, {"price": "0.36", "size": "280.55"}, {"price": "0.37", "size": "5"}, {"price": "0.6", "size": "100"}, {"price": "0.64", "size": "16"}, {"price": "0.7", "size": "110"}, {"price": "0.74", "size": "12"}, {"price": "0.75", "size": "40"}, {"price": "0.76", "size": "17.1"}, {"price": "0.78", "size": "14.1"}, {"price": "0.79", "size": "10"}, {"price": "0.84", "size": "508"}, {"price": "0.85", "size": "507"}, {"price": "0.86", "size": "67.26"}], "asks": [{"price": "0.99", "size": "2250"}, {"price": "0.98", "size": "4006.2"}, {"price": "0.97", "size": "261.23"}, {"price": "0.96", "size": "325"}, {"price": "0.95", "size": "110"}, {"price": "0.94", "size": "8.98"}, {"price": "0.93", "size": "929.1"}, {"price": "0.91", "size": "333"}, {"price": "0.9", "size": "606.47"}, {"price": "0.89", "size": "701.35"}, {"price": "0.88", "size": "165.4"}], "event_type": "book", "last_trade_price": ""}, {"market": "0x1c90e1383b8664103731bacc42ba86dff9c1582b8982f0ec02ba6aa255540dec", "asset_id": "97961254854749379702593191658896132704622945558274415067651430934438719211772", "timestamp": "1769384025288", "hash": "f89b7dea73c71c2814541b4275ed4788344160bf", "bids": [{"price": "0.01", "size": "2250"}, {"price": "0.02", "size": "4006.2"}, {"price": "0.03", "size": "261.23"}, {"price": "0.04", "size": "325"}, {"price": "0.05", "size": "110"}, {"price": "0.06", "size": "8.98"}, {"price": "0.07", "size": "929.1"}, {"price": "0.09", "size": "333"}, {"price": "0.1", "size": "606.47"}, {"price": "0.11", "size": "701.35"}, {"price": "0.12", "size": "165.4"}], "asks": [{"price": "0.99", "size": "13601.71"}, {"price": "0.98", "size": "4048"}, {"price": "0.97", "size": "9.09"}, {"price": "0.96", "size": "1262"}, {"price": "0.95", "size": "810"}, {"price": "0.94", "size": "33"}, {"price": "0.92", "size": "128"}, {"price": "0.91", "size": "700"}, {"price": "0.9", "size": "6.3"}, {"price": "0.87", "size": "586.53"}, {"price": "0.84", "size": "64"}, {"price": "0.82", "size": "427.77"}, {"price": "0.79", "size": "810"}, {"price": "0.78", "size": "127.27"}, {"price": "0.77", "size": "1876"}, {"price": "0.73", "size": "196.29"}, {"price": "0.72", "size": "300"}, {"price": "0.7", "size": "100"}, {"price": "0.69", "size": "77.41"}, {"price": "0.68", "size": "32"}, {"price": "0.66", "size": "100"}, {"price": "0.64", "size": "280.55"}, {"price": "0.63", "size": "5"}, {"price": "0.4", "size": "100"}, {"price": "0.36", "size": "16"}, {"price": "0.3", "size": "110"}, {"price": "0.26", "size": "12"}, {"price": "0.25", "size": "40"}, {"price": "0.24", "size": "17.1"}, {"price": "0.22", "size": "14.1"}, {"price": "0.21", "size": "10"}, {"price": "0.16", "size": "508"}, {"price": "0.15", "size": "507"}, {"price": "0.14", "size": "67.26"}], "event_type": "book", "last_trade_price": ""}]}
{"_local_timestamp": "2026-01-25T23:33:48.238806+00:00", "data": {"market": "0x1c90e1383b8664103731bacc42ba86dff9c1582b8982f0ec02ba6aa255540dec", "price_changes": [{"asset_id": "97961254854749379702593191658896132704622945558274415067651430934438719211772", "price": "0.14", "size": "91.67", "side": "SELL", "hash": "0efce80b90c32faae6aacb21da772b615af0b880", "best_bid": "0.12", "best_ask": "0.14"}, {"asset_id": "10824614737277384579120931547716737694062714916890575016613469671599992760641", "price": "0.86", "size": "91.67", "side": "BUY", "hash": "2ae5c171a252f4e9a4cec4b27138af6c5a8b5f59", "best_bid": "0.86", "best_ask": "0.88"}], "timestamp": "1769384028167", "event_type": "price_change"}}
{"_local_timestamp": "2026-01-25T23:33:49.322416+00:00", "data": {"market": "0x1c90e1383b8664103731bacc42ba86dff9c1582b8982f0ec02ba6aa255540dec", "price_changes": [{"asset_id": "97961254854749379702593191658896132704622945558274415067651430934438719211772", "price": "0.14", "size": "67.26", "side": "SELL", "hash": "b54cd0d975683ab16813903e9e7f59766ea5209a", "best_bid": "0.12", "best_ask": "0.14"}, {"asset_id": "10824614737277384579120931547716737694062714916890575016613469671599992760641", "price": "0.86", "size": "67.26", "side": "BUY", "hash": "32ef673f107047526241becc146730fcf4c61dfe", "best_bid": "0.86", "best_ask": "0.88"}], "timestamp": "1769384029237", "event_type": "price_change"}}
{"_local_timestamp": "2026-01-25T23:33:50.189797+00:00", "data": {"market": "0x1c90e1383b8664103731bacc42ba86dff9c1582b8982f0ec02ba6aa255540dec", "price_changes": [{"asset_id": "97961254854749379702593191658896132704622945558274415067651430934438719211772", "price": "0.14", "size": "91.67", "side": "SELL", "hash": "fc2dbdc2ca0ca03dd0be8dfa780bd48fe06ac8a9", "best_bid": "0.12", "best_ask": "0.14"}, {"asset_id": "10824614737277384579120931547716737694062714916890575016613469671599992760641", "price": "0.86", "size": "91.67", "side": "BUY", "hash": "57c62bc3be40118cad3e38c9055baab462120d96", "best_bid": "0.86", "best_ask": "0.88"}], "timestamp": "1769384030122", "event_type": "price_change"}}
{"_local_timestamp": "2026-01-25T23:33:53.091116+00:00", "data": {"market": "0x1c90e1383b8664103731bacc42ba86dff9c1582b8982f0ec02ba6aa255540dec", "price_changes": [{"asset_id": "97961254854749379702593191658896132704622945558274415067651430934438719211772", "price": "0.14", "size": "67.26", "side": "SELL", "hash": "d1f24518e92d5f786d2acaf6601bb616cef316b7", "best_bid": "0.12", "best_ask": "0.14"}, {"asset_id": "10824614737277384579120931547716737694062714916890575016613469671599992760641", "price": "0.86", "size": "67.26", "side": "BUY", "hash": "3a081f4fc8489b1366120e646195a0740db28ef7", "best_bid": "0.86", "best_ask": "0.88"}], "timestamp": "1769384032998", "event_type": "price_change"}}
{"_local_timestamp": "2026-01-25T23:33:54.679273+00:00", "data": {"market": "0x1c90e1383b8664103731bacc42ba86dff9c1582b8982f0ec02ba6aa255540dec", "price_changes": [{"asset_id": "97961254854749379702593191658896132704622945558274415067651430934438719211772", "price": "0.14", "size": "91.67", "side": "SELL", "hash": "d86cc9cb0736706b477a34ddd4f468391c3ca23a", "best_bid": "0.12", "best_ask": "0.14"}, {"asset_id": "10824614737277384579120931547716737694062714916890575016613469671599992760641", "price": "0.86", "size": "91.67", "side": "BUY", "hash": "9e20766aea66e5c7349768990f5c7cacd10b07cf", "best_bid": "0.86", "best_ask": "0.88"}], "timestamp": "1769384034605", "event_type": "price_change"}}
{"_local_timestamp": "2026-01-25T23:33:56.626753+00:00", "data": {"market": "0x1c90e1383b8664103731bacc42ba86dff9c1582b8982f0ec02ba6aa255540dec", "price_changes": [{"asset_id": "97961254854749379702593191658896132704622945558274415067651430934438719211772", "price": "0.14", "size": "67.26", "side": "SELL", "hash": "c62ef0f9965f02b44f2303e245fb7c3874ba4f03", "best_bid": "0.12", "best_ask": "0.14"}, {"asset_id": "10824614737277384579120931547716737694062714916890575016613469671599992760641", "price": "0.86", "size": "67.26", "side": "BUY", "hash": "a2150d13a9a2da6bba9b974e58313b1e4759227b", "best_bid": "0.86", "best_ask": "0.88"}], "timestamp": "1769384036542", "event_type": "price_change"}}
{"_local_timestamp": "2026-01-25T23:33:59.301245+00:00", "data": {"market": "0x1c90e1383b8664103731bacc42ba86dff9c1582b8982f0ec02ba6aa255540dec", "price_changes": [{"asset_id": "97961254854749379702593191658896132704622945558274415067651430934438719211772", "price": "0.14", "size": "91.67", "side": "SELL", "hash": "6e3012198442a310d2777e8c0a21a17f3c91c05e", "best_bid": "0.12", "best_ask": "0.14"}, {"asset_id": "10824614737277384579120931547716737694062714916890575016613469671599992760641", "price": "0.86", "size": "91.67", "side": "BUY", "hash": "cac832041b6740454a7b810b37de695f37d578fe", "best_bid": "0.86", "best_ask": "0.88"}], "timestamp": "1769384039233", "event_type": "price_change"}}
{"_local_timestamp": "2026-01-25T23:33:59.957756+00:00", "data": {"market": "0x1c90e1383b8664103731bacc42ba86dff9c1582b8982f0ec02ba6aa255540dec", "price_changes": [{"asset_id": "97961254854749379702593191658896132704622945558274415067651430934438719211772", "price": "0.14", "size": "67.26", "side": "SELL", "hash": "b7171a3c842be85bbcef81ab8a2636112ce0ff46", "best_bid": "0.12", "best_ask": "0.14"}, {"asset_id": "10824614737277384579120931547716737694062714916890575016613469671599992760641", "price": "0.86", "size": "67.26", "side": "BUY", "hash": "4731349178301145073009ad509de6f641e94611", "best_bid": "0.86", "best_ask": "0.88"}], "timestamp": "1769384039891", "event_type": "price_change"}}
{"_local_timestamp": "2026-01-25T23:34:01.471563+00:00", "data": {"market": "0x1c90e1383b8664103731bacc42ba86dff9c1582b8982f0ec02ba6aa255540dec", "price_changes": [{"asset_id": "97961254854749379702593191658896132704622945558274415067651430934438719211772", "price": "0.14", "size": "91.67", "side": "SELL", "hash": "fcc72f8f04e4f76d45dc9e2361672544520e72ca", "best_bid": "0.12", "best_ask": "0.14"}, {"asset_id": "10824614737277384579120931547716737694062714916890575016613469671599992760641", "price": "0.86", "size": "91.67", "side": "BUY", "hash": "e879ab55e681ca1a0fa9079c952b4b613aef2bc0", "best_bid": "0.86", "best_ask": "0.88"}], "timestamp": "1769384041386", "event_type": "price_change"}}
{"_local_timestamp": "2026-01-25T23:34:03.262272+00:00", "data": {"market": "0x1c90e1383b8664103731bacc42ba86dff9c1582b8982f0ec02ba6aa255540dec", "price_changes": [{"asset_id": "97961254854749379702593191658896132704622945558274415067651430934438719211772", "price": "0.14", "size": "67.26", "side": "SELL", "hash": "25bfd1ff9f4dadb69cfe5b3c0b42b6c1355ec368", "best_bid": "0.12", "best_ask": "0.14"}, {"asset_id": "10824614737277384579120931547716737694062714916890575016613469671599992760641", "price": "0.86", "size": "67.26", "side": "BUY", "hash": "b62b29d95224857499b5447bc66047a02a704c52", "best_bid": "0.86", "best_ask": "0.88"}], "timestamp": "1769384043185", "event_type": "price_change"}}
{"_local_timestamp": "2026-01-25T23:34:06.450339+00:00", "data": {"market": "0x1c90e1383b8664103731bacc42ba86dff9c1582b8982f0ec02ba6aa255540dec", "price_changes": [{"asset_id": "97961254854749379702593191658896132704622945558274415067651430934438719211772", "price": "0.14", "size": "91.67", "side": "SELL", "hash": "1f7c42e3f6d98cddeffc32b001696871ce8a9c61", "best_bid": "0.12", "best_ask": "0.14"}, {"asset_id": "10824614737277384579120931547716737694062714916890575016613469671599992760641", "price": "0.86", "size": "91.67", "side": "BUY", "hash": "5814dd38a742908240c152e2a8445dcca8eb6506", "best_bid": "0.86", "best_ask": "0.88"}], "timestamp": "1769384046370", "event_type": "price_change"}}
{"_local_timestamp": "2026-01-25T23:34:07.129850+00:00", "data": {"market": "0x1c90e1383b8664103731bacc42ba86dff9c1582b8982f0ec02ba6aa255540dec", "price_changes": [{"asset_id": "97961254854749379702593191658896132704622945558274415067651430934438719211772", "price": "0.14", "size": "67.26", "side": "SELL", "hash": "5cb9b5b6aec456964eed43ab6adfd07f3fccb8cc", "best_bid": "0.12", "best_ask": "0.14"}, {"asset_id": "10824614737277384579120931547716737694062714916890575016613469671599992760641", "price": "0.86", "size": "67.26", "side": "BUY", "hash": "9fc130c6195ad47541a8f9e1e23cc03d51993498", "best_bid": "0.86", "best_ask": "0.88"}], "timestamp": "1769384047050", "event_type": "price_change"}}
{"_local_timestamp": "2026-01-25T23:34:09.020801+00:00", "data": {"market": "0x1c90e1383b8664103731bacc42ba86dff9c1582b8982f0ec02ba6aa255540dec", "price_changes": [{"asset_id": "97961254854749379702593191658896132704622945558274415067651430934438719211772", "price": "0.14", "size": "91.67", "side": "SELL", "hash": "e14888b104938d6dcc225284eb35e7299a9cde89", "best_bid": "0.12", "best_ask": "0.14"}, {"asset_id": "10824614737277384579120931547716737694062714916890575016613469671599992760641", "price": "0.86", "size": "91.67", "side": "BUY", "hash": "c0dfa11a6d410e2695e83532e0056f145ce9e759", "best_bid": "0.86", "best_ask": "0.88"}], "timestamp": "1769384048949", "event_type": "price_change"}}
{"_local_timestamp": "2026-01-25T23:34:10.259187+00:00", "data": {"market": "0x1c90e1383b8664103731bacc42ba86dff9c1582b8982f0ec02ba6aa255540dec", "price_changes": [{"asset_id": "97961254854749379702593191658896132704622945558274415067651430934438719211772", "price": "0.14", "size": "67.26", "side": "SELL", "hash": "3293e2456fcb6fa57edc9fb832ded6e353b6d134", "best_bid": "0.12", "best_ask": "0.14"}, {"asset_id": "10824614737277384579120931547716737694062714916890575016613469671599992760641", "price": "0.86", "size": "67.26", "side": "BUY", "hash": "b14b85c270b09b803bb0d69021bbf1878f68ffd1", "best_bid": "0.86", "best_ask": "0.88"}], "timestamp": "1769384050183", "event_type": "price_change"}}
{"_local_timestamp": "2026-01-25T23:34:11.313077+00:00", "data": {"market": "0x1c90e1383b8664103731bacc42ba86dff9c1582b8982f0ec02ba6aa255540dec", "price_changes": [{"asset_id": "97961254854749379702593191658896132704622945558274415067651430934438719211772", "price": "0.14", "size": "91.67", "side": "SELL", "hash": "fd5eb72f405e3a23dc3f92b6d10aededaa515714", "best_bid": "0.12", "best_ask": "0.14"}, {"asset_id": "10824614737277384579120931547716737694062714916890575016613469671599992760641", "price": "0.86", "size": "91.67", "side": "BUY", "hash": "48b90351d6ee5bd3b4eafe3485a5ea35c846e969", "best_bid": "0.86", "best_ask": "0.88"}], "timestamp": "1769384051246", "event_type": "price_change"}}
{"_local_timestamp": "2026-01-25T23:34:13.928828+00:00", "data": {"market": "0x1c90e1383b8664103731bacc42ba86dff9c1582b8982f0ec02ba6aa255540dec", "price_changes": [{"asset_id": "97961254854749379702593191658896132704622945558274415067651430934438719211772", "price": "0.14", "size": "67.26", "side": "SELL", "hash": "9764a29e94c52a9741738706f6f665ce6c26e731", "best_bid": "0.12", "best_ask": "0.14"}, {"asset_id": "10824614737277384579120931547716737694062714916890575016613469671599992760641", "price": "0.86", "size": "67.26", "side": "BUY", "hash": "f4103915e3028a20010ac97c3cf3f02b897a4455", "best_bid": "0.86", "best_ask": "0.88"}], "timestamp": "1769384053858", "event_type": "price_change"}}
{"_local_timestamp": "2026-01-25T23:34:16.186285+00:00", "data": {"market": "0x1c90e1383b8664103731bacc42ba86dff9c1582b8982f0ec02ba6aa255540dec", "price_changes": [{"asset_id": "97961254854749379702593191658896132704622945558274415067651430934438719211772", "price": "0.14", "size": "91.67", "side": "SELL", "hash": "4095c5388b05a9f77db1cf7ad14bc5148c8a5609", "best_bid": "0.12", "best_ask": "0.14"}, {"asset_id": "10824614737277384579120931547716737694062714916890575016613469671599992760641", "price": "0.86", "size": "91.67", "side": "BUY", "hash": "771c1d148e5bfd2bb9f04ea5bc3afc9b53fc1fa6", "best_bid": "0.86", "best_ask": "0.88"}], "timestamp": "1769384056111", "event_type": "price_change"}}
{"_local_timestamp": "2026-01-25T23:34:17.556594+00:00", "data": {"market": "0x1c90e1383b8664103731bacc42ba86dff9c1582b8982f0ec02ba6aa255540dec", "price_changes": [{"asset_id": "97961254854749379702593191658896132704622945558274415067651430934438719211772", "price": "0.14", "size": "67.26", "side": "SELL", "hash": "da31b8cc90893fe4ad50800ae0f2eb491e1f341f", "best_bid": "0.12", "best_ask": "0.14"}, {"asset_id": "10824614737277384579120931547716737694062714916890575016613469671599992760641", "price": "0.86", "size": "67.26", "side": "BUY", "hash": "c386fe3c01a75606fc61f22d3f3b1d7dc6cfeec1", "best_bid": "0.86", "best_ask": "0.88"}], "timestamp": "1769384057482", "event_type": "price_change"}}
{"_local_timestamp": "2026-01-25T23:34:18.513294+00:00", "data": {"market": "0x1c90e1383b8664103731bacc42ba86dff9c1582b8982f0ec02ba6aa255540dec", "price_changes": [{"asset_id": "97961254854749379702593191658896132704622945558274415067651430934438719211772", "price": "0.14", "size": "91.67", "side": "SELL", "hash": "b5caf516bef6fdf63bd2d47cd407693582b5b991", "best_bid": "0.12", "best_ask": "0.14"}, {"asset_id": "10824614737277384579120931547716737694062714916890575016613469671599992760641", "price": "0.86", "size": "91.67", "side": "BUY", "hash": "ff7df7382b2803f1df8893f696898ed88cb97aad", "best_bid": "0.86", "best_ask": "0.88"}], "timestamp": "1769384058422", "event_type": "price_change"}}
{"_local_timestamp": "2026-01-25T23:34:19.875965+00:00", "data": {"market": "0x1c90e1383b8664103731bacc42ba86dff9c1582b8982f0ec02ba6aa255540dec", "price_changes": [{"asset_id": "10824614737277384579120931547716737694062714916890575016613469671599992760641", "price": "0.23", "size": "50", "side": "BUY", "hash": "070667fc9cbb24a214b72beaacd1ab85e0d4df94", "best_bid": "0.86", "best_ask": "0.88"}, {"asset_id": "97961254854749379702593191658896132704622945558274415067651430934438719211772", "price": "0.77", "size": "50", "side": "SELL", "hash": "ee8ebbe764843a3f38b54e3cd8896110614dc40d", "best_bid": "0.12", "best_ask": "0.14"}], "timestamp": "1769384059755", "event_type": "price_change"}}
{"_local_timestamp": "2026-01-25T23:34:21.125810+00:00", "data": {"market": "0x1c90e1383b8664103731bacc42ba86dff9c1582b8982f0ec02ba6aa255540dec", "price_changes": [{"asset_id": "97961254854749379702593191658896132704622945558274415067651430934438719211772", "price": "0.14", "size": "67.26", "side": "SELL", "hash": "02368553db8f3dffbdd01c236156cfad5cdafb1f", "best_bid": "0.12", "best_ask": "0.14"}, {"asset_id": "10824614737277384579120931547716737694062714916890575016613469671599992760641", "price": "0.86", "size": "67.26", "side": "BUY", "hash": "9b129978736065e2386710df80ab93c2cd989d2c", "best_bid": "0.86", "best_ask": "0.88"}], "timestamp": "1769384061055", "event_type": "price_change"}}
{"_local_timestamp": "2026-01-25T23:34:23.358154+00:00", "data": {"market": "0x1c90e1383b8664103731bacc42ba86dff9c1582b8982f0ec02ba6aa255540dec", "price_changes": [{"asset_id": "97961254854749379702593191658896132704622945558274415067651430934438719211772", "price": "0.14", "size": "91.67", "side": "SELL", "hash": "3ef17fe161c510192cf7f56bc1d470fba0fc8268", "best_bid": "0.12", "best_ask": "0.14"}, {"asset_id": "10824614737277384579120931547716737694062714916890575016613469671599992760641", "price": "0.86", "size": "91.67", "side": "BUY", "hash": "db6b2b440af281694825aa106d9449bda33f5495", "best_bid": "0.86", "best_ask": "0.88"}], "timestamp": "1769384063281", "event_type": "price_change"}}
{"_local_timestamp": "2026-01-25T23:34:24.377075+00:00", "data": {"market": "0x1c90e1383b8664103731bacc42ba86dff9c1582b8982f0ec02ba6aa255540dec", "price_changes": [{"asset_id": "97961254854749379702593191658896132704622945558274415067651430934438719211772", "price": "0.14", "size": "67.26", "side": "SELL", "hash": "4a75632c5b80402ad1d8bff5f04d8c02832dd46e", "best_bid": "0.12", "best_ask": "0.14"}, {"asset_id": "10824614737277384579120931547716737694062714916890575016613469671599992760641", "price": "0.86", "size": "67.26", "side": "BUY", "hash": "cb5071ac282cdcddc0c893e95f0a9ba39cb34657", "best_bid": "0.86", "best_ask": "0.88"}], "timestamp": "1769384064299", "event_type": "price_change"}}
{"_local_timestamp": "2026-01-25T23:34:25.413629+00:00", "data": {"market": "0x1c90e1383b8664103731bacc42ba86dff9c1582b8982f0ec02ba6aa255540dec", "price_changes": [{"asset_id": "97961254854749379702593191658896132704622945558274415067651430934438719211772", "price": "0.14", "size": "91.67", "side": "SELL", "hash": "22ea1a635753a2e3e23ba5c4ee23f784a9ac2f6e", "best_bid": "0.12", "best_ask": "0.14"}, {"asset_id": "10824614737277384579120931547716737694062714916890575016613469671599992760641", "price": "0.86", "size": "91.67", "side": "BUY", "hash": "b0fe8ee05fea026108df3d2229b14b95662d299e", "best_bid": "0.86", "best_ask": "0.88"}], "timestamp": "1769384065319", "event_type": "price_change"}}
{"_local_timestamp": "2026-01-25T23:34:27.718654+00:00", "data": {"market": "0x1c90e1383b8664103731bacc42ba86dff9c1582b8982f0ec02ba6aa255540dec", "price_changes": [{"asset_id": "10824614737277384579120931547716737694062714916890575016613469671599992760641", "price": "0.27", "size": "96.29", "side": "BUY", "hash": "61410cb31f9cb89227f30b5a68aa8189968266f8", "best_bid": "0.86", "best_ask": "0.88"}, {"asset_id": "97961254854749379702593191658896132704622945558274415067651430934438719211772", "price": "0.73", "size": "96.29", "side": "SELL", "hash": "be0a2e22046e99b03c0dc4d6cc7e0953b752e313", "best_bid": "0.12", "best_ask": "0.14"}], "timestamp": "1769384067573", "event_type": "price_change"}}
{"_local_timestamp": "2026-01-25T23:34:27.917034+00:00", "data": {"market": "0x1c90e1383b8664103731bacc42ba86dff9c1582b8982f0ec02ba6aa255540dec", "price_changes": [{"asset_id": "97961254854749379702593191658896132704622945558274415067651430934438719211772", "price": "0.14", "size": "67.26", "side": "SELL", "hash": "0f0d988373b59ac84511354f454ec9fbd695dc3c", "best_bid": "0.12", "best_ask": "0.14"}, {"asset_id": "10824614737277384579120931547716737694062714916890575016613469671599992760641", "price": "0.86", "size": "67.26", "side": "BUY", "hash": "fd41ed3fdd5c4c898de0359827a91cb833480671", "best_bid": "0.86", "best_ask": "0.88"}], "timestamp": "1769384067679", "event_type": "price_change"}}
{"_local_timestamp": "2026-01-25T23:34:28.516971+00:00", "data": {"market": "0x1c90e1383b8664103731bacc42ba86dff9c1582b8982f0ec02ba6aa255540dec", "price_changes": [{"asset_id": "10824614737277384579120931547716737694062714916890575016613469671599992760641", "price": "0.23", "size": "150", "side": "BUY", "hash": "eecdb3c68a6029bd1015d5bc99994087371a4975", "best_bid": "0.86", "best_ask": "0.88"}, {"asset_id": "97961254854749379702593191658896132704622945558274415067651430934438719211772", "price": "0.77", "size": "150", "side": "SELL", "hash": "0cfa457f848d6c456ed68f7b6b364b55cc6e19fb", "best_bid": "0.12", "best_ask": "0.14"}], "timestamp": "1769384068147", "event_type": "price_change"}}
{"_local_timestamp": "2026-01-25T23:34:30.462327+00:00", "data": {"market": "0x1c90e1383b8664103731bacc42ba86dff9c1582b8982f0ec02ba6aa255540dec", "price_changes": [{"asset_id": "97961254854749379702593191658896132704622945558274415067651430934438719211772", "price": "0.14", "size": "91.67", "side": "SELL", "hash": "1c2fd1c8b5fd38abc1c4d74863f05b691228cdde", "best_bid": "0.12", "best_ask": "0.14"}, {"asset_id": "10824614737277384579120931547716737694062714916890575016613469671599992760641", "price": "0.86", "size": "91.67", "side": "BUY", "hash": "ec23fd27a9306e164ae6d4cc48dd86799d5cc27b", "best_bid": "0.86", "best_ask": "0.88"}], "timestamp": "1769384070286", "event_type": "price_change"}}
{"_local_timestamp": "2026-01-25T23:34:31.071126+00:00", "data": {"market": "0x1c90e1383b8664103731bacc42ba86dff9c1582b8982f0ec02ba6aa255540dec", "price_changes": [{"asset_id": "97961254854749379702593191658896132704622945558274415067651430934438719211772", "price": "0.14", "size": "67.26", "side": "SELL", "hash": "fad4d51ac4c18c0bb97c623555916c0297853781", "best_bid": "0.12", "best_ask": "0.14"}, {"asset_id": "10824614737277384579120931547716737694062714916890575016613469671599992760641", "price": "0.86", "size": "67.26", "side": "BUY", "hash": "2482e037894b40c911f150212f651e33ac5fcda4", "best_bid": "0.86", "best_ask": "0.88"}], "timestamp": "1769384070999", "event_type": "price_change"}}
{"_local_timestamp": "2026-01-25T23:34:33.153300+00:00", "data": {"market": "0x1c90e1383b8664103731bacc42ba86dff9c1582b8982f0ec02ba6aa255540dec", "price_changes": [{"asset_id": "97961254854749379702593191658896132704622945558274415067651430934438719211772", "price": "0.14", "size": "91.67", "side": "SELL", "hash": "7d3aa96ff8e0f45e42f51b3f827acd5f3db1be83", "best_bid": "0.12", "best_ask": "0.14"}, {"asset_id": "10824614737277384579120931547716737694062714916890575016613469671599992760641", "price": "0.86", "size": "91.67", "side": "BUY", "hash": "0a60149a56859e7dc1198751e88168f38fb47d47", "best_bid": "0.86", "best_ask": "0.88"}], "timestamp": "1769384073084", "event_type": "price_change"}}
{"_local_timestamp": "2026-01-25T23:34:34.329703+00:00", "data": {"market": "0x1c90e1383b8664103731bacc42ba86dff9c1582b8982f0ec02ba6aa255540dec", "price_changes": [{"asset_id": "97961254854749379702593191658896132704622945558274415067651430934438719211772", "price": "0.14", "size": "67.26", "side": "SELL", "hash": "2d7196c21f81b2d315a0ec01f94a035c66af8792", "best_bid": "0.12", "best_ask": "0.14"}, {"asset_id": "10824614737277384579120931547716737694062714916890575016613469671599992760641", "price": "0.86", "size": "67.26", "side": "BUY", "hash": "a9bd4b935a199ce62665f5eca2276ef023e9b327", "best_bid": "0.86", "best_ask": "0.88"}], "timestamp": "1769384074256", "event_type": "price_change"}}
{"_local_timestamp": "2026-01-25T23:34:35.023661+00:00", "data": {"market": "0x1c90e1383b8664103731bacc42ba86dff9c1582b8982f0ec02ba6aa255540dec", "price_changes": [{"asset_id": "97961254854749379702593191658896132704622945558274415067651430934438719211772", "price": "0.14", "size": "91.67", "side": "SELL", "hash": "bd8db730483518316b3d0f47cd5e93a55f1fd77b", "best_bid": "0.12", "best_ask": "0.14"}, {"asset_id": "10824614737277384579120931547716737694062714916890575016613469671599992760641", "price": "0.86", "size": "91.67", "side": "BUY", "hash": "94bc2d386f0a97b57905d6107f1f811283a19c88", "best_bid": "0.86", "best_ask": "0.88"}], "timestamp": "1769384074953", "event_type": "price_change"}}
{"_local_timestamp": "2026-01-25T23:34:38.163994+00:00", "data": {"market": "0x1c90e1383b8664103731bacc42ba86dff9c1582b8982f0ec02ba6aa255540dec", "price_changes": [{"asset_id": "97961254854749379702593191658896132704622945558274415067651430934438719211772", "price": "0.14", "size": "67.26", "side": "SELL", "hash": "f984c794f2b4235c11540e54f8841bd46d10ca2b", "best_bid": "0.12", "best_ask": "0.14"}, {"asset_id": "10824614737277384579120931547716737694062714916890575016613469671599992760641", "price": "0.86", "size": "67.26", "side": "BUY", "hash": "0b1c4fcff83a54de05b86738940978a12ec3ebb7", "best_bid": "0.86", "best_ask": "0.88"}], "timestamp": "1769384078090", "event_type": "price_change"}}
{"_local_timestamp": "2026-01-25T23:34:39.765849+00:00", "data": {"market": "0x1c90e1383b8664103731bacc42ba86dff9c1582b8982f0ec02ba6aa255540dec", "price_changes": [{"asset_id": "97961254854749379702593191658896132704622945558274415067651430934438719211772", "price": "0.14", "size": "91.67", "side": "SELL", "hash": "bfef5370fee72d816a589d8b67c071ce6c73c594", "best_bid": "0.12", "best_ask": "0.14"}, {"asset_id": "10824614737277384579120931547716737694062714916890575016613469671599992760641", "price": "0.86", "size": "91.67", "side": "BUY", "hash": "10e316dfb66209447b11b428cae23b63ed25063d", "best_bid": "0.86", "best_ask": "0.88"}], "timestamp": "1769384079699", "event_type": "price_change"}}
{"_local_timestamp": "2026-01-25T23:34:41.889789+00:00", "data": {"market": "0x1c90e1383b8664103731bacc42ba86dff9c1582b8982f0ec02ba6aa255540dec", "price_changes": [{"asset_id": "97961254854749379702593191658896132704622945558274415067651430934438719211772", "price": "0.14", "size": "67.26", "side": "SELL", "hash": "3d27f53c2963a956bdd9af5d81330d7f84a8ef2b", "best_bid": "0.12", "best_ask": "0.14"}, {"asset_id": "10824614737277384579120931547716737694062714916890575016613469671599992760641", "price": "0.86", "size": "67.26", "side": "BUY", "hash": "2af848c0c6f55b5e252f60a5e8b8c6348717e969", "best_bid": "0.86", "best_ask": "0.88"}], "timestamp": "1769384081819", "event_type": "price_change"}}
{"_local_timestamp": "2026-01-25T23:34:44.684816+00:00", "data": {"market": "0x1c90e1383b8664103731bacc42ba86dff9c1582b8982f0ec02ba6aa255540dec", "price_changes": [{"asset_id": "97961254854749379702593191658896132704622945558274415067651430934438719211772", "price": "0.14", "size": "91.67", "side": "SELL", "hash": "a9d8f96d5045c41c6ae2c346c0d1902561175db1", "best_bid": "0.12", "best_ask": "0.14"}, {"asset_id": "10824614737277384579120931547716737694062714916890575016613469671599992760641", "price": "0.86", "size": "91.67", "side": "BUY", "hash": "1f1a471f67447814f64a327df035ea30bf1cfcab", "best_bid": "0.86", "best_ask": "0.88"}], "timestamp": "1769384084619", "event_type": "price_change"}}
{"_local_timestamp": "2026-01-25T23:34:45.262477+00:00", "data": {"market": "0x1c90e1383b8664103731bacc42ba86dff9c1582b8982f0ec02ba6aa255540dec", "price_changes": [{"asset_id": "97961254854749379702593191658896132704622945558274415067651430934438719211772", "price": "0.14", "size": "67.26", "side": "SELL", "hash": "4215af97abac8d4c29b9e0da9f4293a47caa5bb3", "best_bid": "0.12", "best_ask": "0.14"}, {"asset_id": "10824614737277384579120931547716737694062714916890575016613469671599992760641", "price": "0.86", "size": "67.26", "side": "BUY", "hash": "78e329153b89c96077a9e24847a5b8cf0fa77a01", "best_bid": "0.86", "best_ask": "0.88"}], "timestamp": "1769384085179", "event_type": "price_change"}}
{"_local_timestamp": "2026-01-25T23:34:47.002609+00:00", "data": {"market": "0x1c90e1383b8664103731bacc42ba86dff9c1582b8982f0ec02ba6aa255540dec", "price_changes": [{"asset_id": "97961254854749379702593191658896132704622945558274415067651430934438719211772", "price": "0.14", "size": "91.67", "side": "SELL", "hash": "9a24f6c3a4de45605f6cd03c283e86ecb01da921", "best_bid": "0.12", "best_ask": "0.14"}, {"asset_id": "10824614737277384579120931547716737694062714916890575016613469671599992760641", "price": "0.86", "size": "91.67", "side": "BUY", "hash": "0f785948217ac1e5713dccfe6a6a9bf733898510", "best_bid": "0.86", "best_ask": "0.88"}], "timestamp": "1769384086931", "event_type": "price_change"}}
{"_local_timestamp": "2026-01-25T23:34:49.056458+00:00", "data": {"market": "0x1c90e1383b8664103731bacc42ba86dff9c1582b8982f0ec02ba6aa255540dec", "price_changes": [{"asset_id": "97961254854749379702593191658896132704622945558274415067651430934438719211772", "price": "0.14", "size": "67.26", "side": "SELL", "hash": "d163c84277749eedeb5755157d177da4e4e7e83b", "best_bid": "0.12", "best_ask": "0.14"}, {"asset_id": "10824614737277384579120931547716737694062714916890575016613469671599992760641", "price": "0.86", "size": "67.26", "side": "BUY", "hash": "3b9c98cfbf2d7eb793360bc1a00bb4be1c59aa3b", "best_bid": "0.86", "best_ask": "0.88"}], "timestamp": "1769384088986", "event_type": "price_change"}}
{"_local_timestamp": "2026-01-25T23:34:51.919418+00:00", "data": {"market": "0x1c90e1383b8664103731bacc42ba86dff9c1582b8982f0ec02ba6aa255540dec", "price_changes": [{"asset_id": "97961254854749379702593191658896132704622945558274415067651430934438719211772", "price": "0.14", "size": "91.67", "side": "SELL", "hash": "dcf8c641ccff4a3933f04641bb48a81c4f91ab4c", "best_bid": "0.12", "best_ask": "0.14"}, {"asset_id": "10824614737277384579120931547716737694062714916890575016613469671599992760641", "price": "0.86", "size": "91.67", "side": "BUY", "hash": "760f62d8b8d57e483801c5a59b2fe5ac66fb3c30", "best_bid": "0.86", "best_ask": "0.88"}], "timestamp": "1769384091841", "event_type": "price_change"}}
{"_local_timestamp": "2026-01-25T23:34:52.841285+00:00", "data": {"market": "0x1c90e1383b8664103731bacc42ba86dff9c1582b8982f0ec02ba6aa255540dec", "price_changes": [{"asset_id": "97961254854749379702593191658896132704622945558274415067651430934438719211772", "price": "0.14", "size": "67.26", "side": "SELL", "hash": "c92c165ba211acbe434fa026fac9bf3ea30b3508", "best_bid": "0.12", "best_ask": "0.14"}, {"asset_id": "10824614737277384579120931547716737694062714916890575016613469671599992760641", "price": "0.86", "size": "67.26", "side": "BUY", "hash": "12fbb11703e16c4469d7587fac848e2fd474a3d5", "best_bid": "0.86", "best_ask": "0.88"}], "timestamp": "1769384092770", "event_type": "price_change"}}
{"_local_timestamp": "2026-01-25T23:34:53.845929+00:00", "data": {"market": "0x1c90e1383b8664103731bacc42ba86dff9c1582b8982f0ec02ba6aa255540dec", "price_changes": [{"asset_id": "97961254854749379702593191658896132704622945558274415067651430934438719211772", "price": "0.14", "size": "91.67", "side": "SELL", "hash": "7a763055db57b3e62d4ae8ba69a45b94e1b8fcc9", "best_bid": "0.12", "best_ask": "0.14"}, {"asset_id": "10824614737277384579120931547716737694062714916890575016613469671599992760641", "price": "0.86", "size": "91.67", "side": "BUY", "hash": "ab148e80aa34a07fac3ad3f3035f439e249c393a", "best_bid": "0.86", "best_ask": "0.88"}], "timestamp": "1769384093765", "event_type": "price_change"}}
{"_local_timestamp": "2026-01-25T23:34:56.616698+00:00", "data": {"market": "0x1c90e1383b8664103731bacc42ba86dff9c1582b8982f0ec02ba6aa255540dec", "price_changes": [{"asset_id": "97961254854749379702593191658896132704622945558274415067651430934438719211772", "price": "0.14", "size": "67.26", "side": "SELL", "hash": "ccae9954bcd9df84b741a15cc44b47dbf4b39b9b", "best_bid": "0.12", "best_ask": "0.14"}, {"asset_id": "10824614737277384579120931547716737694062714916890575016613469671599992760641", "price": "0.86", "size": "67.26", "side": "BUY", "hash": "f55222c9e56257cb678341450696e8aaf2ab5e24", "best_bid": "0.86", "best_ask": "0.88"}], "timestamp": "1769384096540", "event_type": "price_change"}}
{"_local_timestamp": "2026-01-25T23:34:58.961590+00:00", "data": {"market": "0x1c90e1383b8664103731bacc42ba86dff9c1582b8982f0ec02ba6aa255540dec", "price_changes": [{"asset_id": "97961254854749379702593191658896132704622945558274415067651430934438719211772", "price": "0.14", "size": "91.67", "side": "SELL", "hash": "f0d8a7f03598739024fdccacb9ffc9cbff424e8e", "best_bid": "0.12", "best_ask": "0.14"}, {"asset_id": "10824614737277384579120931547716737694062714916890575016613469671599992760641", "price": "0.86", "size": "91.67", "side": "BUY", "hash": "86e4a03cb91c5ea63763c6dd280c58d767b97bde", "best_bid": "0.86", "best_ask": "0.88"}], "timestamp": "1769384098889", "event_type": "price_change"}}
{"_local_timestamp": "2026-01-25T23:34:59.926587+00:00", "data": {"market": "0x1c90e1383b8664103731bacc42ba86dff9c1582b8982f0ec02ba6aa255540dec", "price_changes": [{"asset_id": "10824614737277384579120931547716737694062714916890575016613469671599992760641", "price": "0.85", "size": "607", "side": "BUY", "hash": "9ed466729cd6933cf4db69e74961f1af45b96c26", "best_bid": "0.86", "best_ask": "0.88"}, {"asset_id": "97961254854749379702593191658896132704622945558274415067651430934438719211772", "price": "0.15", "size": "607", "side": "SELL", "hash": "aa86cb38eb961e5afaecc0a3f2b892e493904fb0", "best_bid": "0.12", "best_ask": "0.14"}], "timestamp": "1769384099858", "event_type": "price_change"}}
{"_local_timestamp": "2026-01-25T23:34:59.934638+00:00", "data": {"market": "0x1c90e1383b8664103731bacc42ba86dff9c1582b8982f0ec02ba6aa255540dec", "price_changes": [{"asset_id": "97961254854749379702593191658896132704622945558274415067651430934438719211772", "price": "0.11", "size": "801.35", "side": "BUY", "hash": "ce401f725caceca08dcc5fe7d41bd3ec7bd26fa3", "best_bid": "0.12", "best_ask": "0.14"}, {"asset_id": "10824614737277384579120931547716737694062714916890575016613469671599992760641", "price": "0.89", "size": "801.35", "side": "SELL", "hash": "378c54b222c25086a2d3b0ffbece278f15484f09", "best_bid": "0.86", "best_ask": "0.88"}], "timestamp": "1769384099858", "event_type": "price_change"}}
{"_local_timestamp": "2026-01-25T23:35:00.777191+00:00", "data": {"market": "0x1c90e1383b8664103731bacc42ba86dff9c1582b8982f0ec02ba6aa255540dec", "price_changes": [{"asset_id": "97961254854749379702593191658896132704622945558274415067651430934438719211772", "price": "0.14", "size": "67.26", "side": "SELL", "hash": "eb2cf6c4836e581f18dc352176a2bec746bdb5a1", "best_bid": "0.12", "best_ask": "0.14"}, {"asset_id": "10824614737277384579120931547716737694062714916890575016613469671599992760641", "price": "0.86", "size": "67.26", "side": "BUY", "hash": "5b3ec0cb196cd35d7b4e4b1c79b406f59f370872", "best_bid": "0.86", "best_ask": "0.88"}], "timestamp": "1769384100704", "event_type": "price_change"}}
{"_local_timestamp": "2026-01-25T23:35:04.153483+00:00", "data": {"market": "0x1c90e1383b8664103731bacc42ba86dff9c1582b8982f0ec02ba6aa255540dec", "price_changes": [{"asset_id": "97961254854749379702593191658896132704622945558274415067651430934438719211772", "price": "0.14", "size": "91.67", "side": "SELL", "hash": "f8c1697fbc40b600b1028624e9800a7486fef6af", "best_bid": "0.12", "best_ask": "0.14"}, {"asset_id": "10824614737277384579120931547716737694062714916890575016613469671599992760641", "price": "0.86", "size": "91.67", "side": "BUY", "hash": "0d98bc3fe277fd7648b351ea9ed80e3ab365740f", "best_bid": "0.86", "best_ask": "0.88"}], "timestamp": "1769384104085", "event_type": "price_change"}}
{"_local_timestamp": "2026-01-25T23:35:06.682345+00:00", "data": {"market": "0x1c90e1383b8664103731bacc42ba86dff9c1582b8982f0ec02ba6aa255540dec", "price_changes": [{"asset_id": "10824614737277384579120931547716737694062714916890575016613469671599992760641", "price": "0.22", "size": "2035.27", "side": "BUY", "hash": "61eed58f64248de6d95cd2aea6b67e6ac39c9eda", "best_bid": "0.86", "best_ask": "0.88"}, {"asset_id": "97961254854749379702593191658896132704622945558274415067651430934438719211772", "price": "0.78", "size": "2035.27", "side": "SELL", "hash": "005d4de648be6ca8eb30666cbb411479d5979236", "best_bid": "0.12", "best_ask": "0.14"}], "timestamp": "1769384106608", "event_type": "price_change"}}
{"_local_timestamp": "2026-01-25T23:35:08.064833+00:00", "data": {"market": "0x1c90e1383b8664103731bacc42ba86dff9c1582b8982f0ec02ba6aa255540dec", "price_changes": [{"asset_id": "97961254854749379702593191658896132704622945558274415067651430934438719211772", "price": "0.14", "size": "67.26", "side": "SELL", "hash": "dea904e09c54ffed272b8c7d2cbc73f3bc7a505d", "best_bid": "0.12", "best_ask": "0.14"}, {"asset_id": "10824614737277384579120931547716737694062714916890575016613469671599992760641", "price": "0.86", "size": "67.26", "side": "BUY", "hash": "204bab475563865a8557dd6561fb3d87babeca2a", "best_bid": "0.86", "best_ask": "0.88"}], "timestamp": "1769384107976", "event_type": "price_change"}}
{"_local_timestamp": "2026-01-25T23:35:09.198743+00:00", "data": {"market": "0x1c90e1383b8664103731bacc42ba86dff9c1582b8982f0ec02ba6aa255540dec", "price_changes": [{"asset_id": "97961254854749379702593191658896132704622945558274415067651430934438719211772", "price": "0.14", "size": "91.67", "side": "SELL", "hash": "b85e6f76986b25ce16353561d74200dfe19abb3f", "best_bid": "0.12", "best_ask": "0.14"}, {"asset_id": "10824614737277384579120931547716737694062714916890575016613469671599992760641", "price": "0.86", "size": "91.67", "side": "BUY", "hash": "000700de7faadf9e559e65821cfb854e037882c1", "best_bid": "0.86", "best_ask": "0.88"}], "timestamp": "1769384109117", "event_type": "price_change"}}
{"_local_timestamp": "2026-01-25T23:35:11.748720+00:00", "data": {"market": "0x1c90e1383b8664103731bacc42ba86dff9c1582b8982f0ec02ba6aa255540dec", "price_changes": [{"asset_id": "97961254854749379702593191658896132704622945558274415067651430934438719211772", "price": "0.14", "size": "67.26", "side": "SELL", "hash": "d8ea6a18399add03395cb3264c43e89c223d4b76", "best_bid": "0.12", "best_ask": "0.14"}, {"asset_id": "10824614737277384579120931547716737694062714916890575016613469671599992760641", "price": "0.86", "size": "67.26", "side": "BUY", "hash": "0704ddf99167457fcee2bd7f8168c9cc1e7be0a1", "best_bid": "0.86", "best_ask": "0.88"}], "timestamp": "1769384111681", "event_type": "price_change"}}
{"_local_timestamp": "2026-01-25T23:35:13.856158+00:00", "data": {"market": "0x1c90e1383b8664103731bacc42ba86dff9c1582b8982f0ec02ba6aa255540dec", "price_changes": [{"asset_id": "97961254854749379702593191658896132704622945558274415067651430934438719211772", "price": "0.14", "size": "91.67", "side": "SELL", "hash": "5dae77029bb1954bcee1b482904ed1e376f84c94", "best_bid": "0.12", "best_ask": "0.14"}, {"asset_id": "10824614737277384579120931547716737694062714916890575016613469671599992760641", "price": "0.86", "size": "91.67", "side": "BUY", "hash": "87e276e5ac82f5ede373545310f44db4e7e401b5", "best_bid": "0.86", "best_ask": "0.88"}], "timestamp": "1769384113766", "event_type": "price_change"}}
{"_local_timestamp": "2026-01-25T23:35:15.514850+00:00", "data": {"market": "0x1c90e1383b8664103731bacc42ba86dff9c1582b8982f0ec02ba6aa255540dec", "price_changes": [{"asset_id": "97961254854749379702593191658896132704622945558274415067651430934438719211772", "price": "0.14", "size": "67.26", "side": "SELL", "hash": "3d0daeae9691c8db877b4193b7acdee66828b4f4", "best_bid": "0.12", "best_ask": "0.14"}, {"asset_id": "10824614737277384579120931547716737694062714916890575016613469671599992760641", "price": "0.86", "size": "67.26", "side": "BUY", "hash": "5a083e8de5edfeb8e49855b54432ea6de55b124b", "best_bid": "0.86", "best_ask": "0.88"}], "timestamp": "1769384115441", "event_type": "price_change"}}
{"_local_timestamp": "2026-01-25T23:35:18.915304+00:00", "data": {"market": "0x1c90e1383b8664103731bacc42ba86dff9c1582b8982f0ec02ba6aa255540dec", "price_changes": [{"asset_id": "97961254854749379702593191658896132704622945558274415067651430934438719211772", "price": "0.14", "size": "91.67", "side": "SELL", "hash": "ffdbde0a7e0742b501e69fa8a357184f6f129dfd", "best_bid": "0.12", "best_ask": "0.14"}, {"asset_id": "10824614737277384579120931547716737694062714916890575016613469671599992760641", "price": "0.86", "size": "91.67", "side": "BUY", "hash": "e707649174e87a4a97d3f89e18f9aba401883f03", "best_bid": "0.86", "best_ask": "0.88"}], "timestamp": "1769384118843", "event_type": "price_change"}}
{"_local_timestamp": "2026-01-25T23:35:19.474242+00:00", "data": {"market": "0x1c90e1383b8664103731bacc42ba86dff9c1582b8982f0ec02ba6aa255540dec", "price_changes": [{"asset_id": "97961254854749379702593191658896132704622945558274415067651430934438719211772", "price": "0.14", "size": "67.26", "side": "SELL", "hash": "4df5663b72b75ee76f4992a2f956ce8fbb245ef1", "best_bid": "0.12", "best_ask": "0.14"}, {"asset_id": "10824614737277384579120931547716737694062714916890575016613469671599992760641", "price": "0.86", "size": "67.26", "side": "BUY", "hash": "cb8a9f2deec0612348126693076aead8159cfca8", "best_bid": "0.86", "best_ask": "0.88"}], "timestamp": "1769384119399", "event_type": "price_change"}}
{"_local_timestamp": "2026-01-25T23:35:20.944084+00:00", "data": {"market": "0x1c90e1383b8664103731bacc42ba86dff9c1582b8982f0ec02ba6aa255540dec", "price_changes": [{"asset_id": "97961254854749379702593191658896132704622945558274415067651430934438719211772", "price": "0.14", "size": "91.67", "side": "SELL", "hash": "2153b5afe8a696906ff27078622c0db58e910b99", "best_bid": "0.12", "best_ask": "0.14"}, {"asset_id": "10824614737277384579120931547716737694062714916890575016613469671599992760641", "price": "0.86", "size": "91.67", "side": "BUY", "hash": "5d57d2d0b1e03c4a93da96db57d7bc455a81e05a", "best_bid": "0.86", "best_ask": "0.88"}], "timestamp": "1769384120865", "event_type": "price_change"}}
{"_local_timestamp": "2026-01-25T23:35:23.718894+00:00", "data": {"market": "0x1c90e1383b8664103731bacc42ba86dff9c1582b8982f0ec02ba6aa255540dec", "price_changes": [{"asset_id": "97961254854749379702593191658896132704622945558274415067651430934438719211772", "price": "0.14", "size": "67.26", "side": "SELL", "hash": "883b4dda213023aeec6d83310f6d97f9ad42cac5", "best_bid": "0.12", "best_ask": "0.14"}, {"asset_id": "10824614737277384579120931547716737694062714916890575016613469671599992760641", "price": "0.86", "size": "67.26", "side": "BUY", "hash": "02ab496327a6e82394e1bddaaad3546651c06f10", "best_bid": "0.86", "best_ask": "0.88"}], "timestamp": "1769384123650", "event_type": "price_change"}}
{"_local_timestamp": "2026-01-25T23:35:26.046701+00:00", "data": {"market": "0x1c90e1383b8664103731bacc42ba86dff9c1582b8982f0ec02ba6aa255540dec", "price_changes": [{"asset_id": "97961254854749379702593191658896132704622945558274415067651430934438719211772", "price": "0.14", "size": "91.67", "side": "SELL", "hash": "21db2f17f258c10a8e9d135988a8f8afc9c2b2ad", "best_bid": "0.12", "best_ask": "0.14"}, {"asset_id": "10824614737277384579120931547716737694062714916890575016613469671599992760641", "price": "0.86", "size": "91.67", "side": "BUY", "hash": "e87ce85e24ba7de89fa7292ccc23a4c18de7e056", "best_bid": "0.86", "best_ask": "0.88"}], "timestamp": "1769384125974", "event_type": "price_change"}}
{"_local_timestamp": "2026-01-25T23:35:27.483780+00:00", "data": {"market": "0x1c90e1383b8664103731bacc42ba86dff9c1582b8982f0ec02ba6aa255540dec", "price_changes": [{"asset_id": "97961254854749379702593191658896132704622945558274415067651430934438719211772", "price": "0.14", "size": "67.26", "side": "SELL", "hash": "d7290d3ddc62ff69391db9ac8239f7b32746010a", "best_bid": "0.12", "best_ask": "0.14"}, {"asset_id": "10824614737277384579120931547716737694062714916890575016613469671599992760641", "price": "0.86", "size": "67.26", "side": "BUY", "hash": "69ba3c73f8bfd712a3b58ce386bcd4cc7698c658", "best_bid": "0.86", "best_ask": "0.88"}], "timestamp": "1769384127415", "event_type": "price_change"}}
{"_local_timestamp": "2026-01-25T23:35:28.540198+00:00", "data": {"market": "0x1c90e1383b8664103731bacc42ba86dff9c1582b8982f0ec02ba6aa255540dec", "price_changes": [{"asset_id": "97961254854749379702593191658896132704622945558274415067651430934438719211772", "price": "0.14", "size": "91.67", "side": "SELL", "hash": "829378bd24d4d3ad123d431d7cdc07a4307bf45b", "best_bid": "0.12", "best_ask": "0.14"}, {"asset_id": "10824614737277384579120931547716737694062714916890575016613469671599992760641", "price": "0.86", "size": "91.67", "side": "BUY", "hash": "8ad11baf387630538596a9623ad897be9130c891", "best_bid": "0.86", "best_ask": "0.88"}], "timestamp": "1769384128471", "event_type": "price_change"}}
{"_local_timestamp": "2026-01-25T23:35:30.938083+00:00", "data": {"market": "0x1c90e1383b8664103731bacc42ba86dff9c1582b8982f0ec02ba6aa255540dec", "price_changes": [{"asset_id": "97961254854749379702593191658896132704622945558274415067651430934438719211772", "price": "0.14", "size": "67.26", "side": "SELL", "hash": "38f608497ae9fe9da49597d7156c69afeba46204", "best_bid": "0.12", "best_ask": "0.14"}, {"asset_id": "10824614737277384579120931547716737694062714916890575016613469671599992760641", "price": "0.86", "size": "67.26", "side": "BUY", "hash": "29cba876232011a8cbfbc534b31354f1b33e5301", "best_bid": "0.86", "best_ask": "0.88"}], "timestamp": "1769384130864", "event_type": "price_change"}}
{"_local_timestamp": "2026-01-25T23:35:33.610228+00:00", "data": {"market": "0x1c90e1383b8664103731bacc42ba86dff9c1582b8982f0ec02ba6aa255540dec", "price_changes": [{"asset_id": "97961254854749379702593191658896132704622945558274415067651430934438719211772", "price": "0.14", "size": "91.67", "side": "SELL", "hash": "806785aa5c70353fce126f4e48dc4c4b9a4d05aa", "best_bid": "0.12", "best_ask": "0.14"}, {"asset_id": "10824614737277384579120931547716737694062714916890575016613469671599992760641", "price": "0.86", "size": "91.67", "side": "BUY", "hash": "39155c74bf28688dc688a6bb92c5c1387f293b94", "best_bid": "0.86", "best_ask": "0.88"}], "timestamp": "1769384133543", "event_type": "price_change"}}
{"_local_timestamp": "2026-01-25T23:35:34.659108+00:00", "data": {"market": "0x1c90e1383b8664103731bacc42ba86dff9c1582b8982f0ec02ba6aa255540dec", "price_changes": [{"asset_id": "97961254854749379702593191658896132704622945558274415067651430934438719211772", "price": "0.14", "size": "67.26", "side": "SELL", "hash": "c18bcdd8da4e8cb7b51beb37efab05ba4fd6eb3b", "best_bid": "0.12", "best_ask": "0.14"}, {"asset_id": "10824614737277384579120931547716737694062714916890575016613469671599992760641", "price": "0.86", "size": "67.26", "side": "BUY", "hash": "22c45a80c23439b7422475fc16d61253ced93463", "best_bid": "0.86", "best_ask": "0.88"}], "timestamp": "1769384134576", "event_type": "price_change"}}
{"_local_timestamp": "2026-01-25T23:35:35.974819+00:00", "data": {"market": "0x1c90e1383b8664103731bacc42ba86dff9c1582b8982f0ec02ba6aa255540dec", "price_changes": [{"asset_id": "97961254854749379702593191658896132704622945558274415067651430934438719211772", "price": "0.14", "size": "91.67", "side": "SELL", "hash": "b767803cba2fee5d111b18f62ecc9e75f9b4ff53", "best_bid": "0.12", "best_ask": "0.14"}, {"asset_id": "10824614737277384579120931547716737694062714916890575016613469671599992760641", "price": "0.86", "size": "91.67", "side": "BUY", "hash": "32d5b9043ae8c0aefd984d8e14af412955ea66ae", "best_bid": "0.86", "best_ask": "0.88"}], "timestamp": "1769384135908", "event_type": "price_change"}}
{"_local_timestamp": "2026-01-25T23:35:38.456097+00:00", "data": {"market": "0x1c90e1383b8664103731bacc42ba86dff9c1582b8982f0ec02ba6aa255540dec", "price_changes": [{"asset_id": "97961254854749379702593191658896132704622945558274415067651430934438719211772", "price": "0.14", "size": "67.26", "side": "SELL", "hash": "d0444278149d8d273854102a65b0a53734ab9182", "best_bid": "0.12", "best_ask": "0.14"}, {"asset_id": "10824614737277384579120931547716737694062714916890575016613469671599992760641", "price": "0.86", "size": "67.26", "side": "BUY", "hash": "50da47de3cc56c2f4d119ece3eb1b5d54acb3eda", "best_bid": "0.86", "best_ask": "0.88"}], "timestamp": "1769384138381", "event_type": "price_change"}}
{"_local_timestamp": "2026-01-25T23:35:40.578252+00:00", "data": {"market": "0x1c90e1383b8664103731bacc42ba86dff9c1582b8982f0ec02ba6aa255540dec", "price_changes": [{"asset_id": "97961254854749379702593191658896132704622945558274415067651430934438719211772", "price": "0.14", "size": "91.67", "side": "SELL", "hash": "2525ab8d1b443bd66e4ca101685431422532292d", "best_bid": "0.12", "best_ask": "0.14"}, {"asset_id": "10824614737277384579120931547716737694062714916890575016613469671599992760641", "price": "0.86", "size": "91.67", "side": "BUY", "hash": "81c857d631f460453291524c21511951b4ffe3c9", "best_bid": "0.86", "best_ask": "0.88"}], "timestamp": "1769384140497", "event_type": "price_change"}}
{"_local_timestamp": "2026-01-25T23:35:42.751023+00:00", "data": {"market": "0x1c90e1383b8664103731bacc42ba86dff9c1582b8982f0ec02ba6aa255540dec", "price_changes": [{"asset_id": "97961254854749379702593191658896132704622945558274415067651430934438719211772", "price": "0.14", "size": "67.26", "side": "SELL", "hash": "66c96e44309c6086095fc61433a5710536f9be4d", "best_bid": "0.12", "best_ask": "0.14"}, {"asset_id": "10824614737277384579120931547716737694062714916890575016613469671599992760641", "price": "0.86", "size": "67.26", "side": "BUY", "hash": "02dd97ce771156f810f2310468ca4a0dbb630d5b", "best_bid": "0.86", "best_ask": "0.88"}], "timestamp": "1769384142683", "event_type": "price_change"}}
{"_local_timestamp": "2026-01-25T23:35:45.488496+00:00", "data": {"market": "0x1c90e1383b8664103731bacc42ba86dff9c1582b8982f0ec02ba6aa255540dec", "price_changes": [{"asset_id": "97961254854749379702593191658896132704622945558274415067651430934438719211772", "price": "0.14", "size": "91.67", "side": "SELL", "hash": "0ad2b48a3165ecd347f05d754a8dc5b9bf30e451", "best_bid": "0.12", "best_ask": "0.14"}, {"asset_id": "10824614737277384579120931547716737694062714916890575016613469671599992760641", "price": "0.86", "size": "91.67", "side": "BUY", "hash": "126fc4592b0b6ca916c5cd6f79ccdd936a35f916", "best_bid": "0.86", "best_ask": "0.88"}], "timestamp": "1769384145417", "event_type": "price_change"}}
{"_local_timestamp": "2026-01-25T23:35:46.638591+00:00", "data": {"market": "0x1c90e1383b8664103731bacc42ba86dff9c1582b8982f0ec02ba6aa255540dec", "price_changes": [{"asset_id": "97961254854749379702593191658896132704622945558274415067651430934438719211772", "price": "0.14", "size": "67.26", "side": "SELL", "hash": "53ea648b7f5322927812be03f5e98a81c5d7863a", "best_bid": "0.12", "best_ask": "0.14"}, {"asset_id": "10824614737277384579120931547716737694062714916890575016613469671599992760641", "price": "0.86", "size": "67.26", "side": "BUY", "hash": "52960e78becc02ee8a3d5472a8e149707e684c79", "best_bid": "0.86", "best_ask": "0.88"}], "timestamp": "1769384146561", "event_type": "price_change"}}
{"_local_timestamp": "2026-01-25T23:35:47.651237+00:00", "data": {"market": "0x1c90e1383b8664103731bacc42ba86dff9c1582b8982f0ec02ba6aa255540dec", "price_changes": [{"asset_id": "97961254854749379702593191658896132704622945558274415067651430934438719211772", "price": "0.14", "size": "91.67", "side": "SELL", "hash": "2f6d80f9a669696d8eef98bf64f209d80f2d8b40", "best_bid": "0.12", "best_ask": "0.14"}, {"asset_id": "10824614737277384579120931547716737694062714916890575016613469671599992760641", "price": "0.86", "size": "91.67", "side": "BUY", "hash": "994e5f33ce30c98a83929503513e001a1d41a455", "best_bid": "0.86", "best_ask": "0.88"}], "timestamp": "1769384147582", "event_type": "price_change"}}
{"_local_timestamp": "2026-01-25T23:35:50.520926+00:00", "data": {"market": "0x1c90e1383b8664103731bacc42ba86dff9c1582b8982f0ec02ba6aa255540dec", "price_changes": [{"asset_id": "97961254854749379702593191658896132704622945558274415067651430934438719211772", "price": "0.14", "size": "67.26", "side": "SELL", "hash": "67c9b9786b268164b5ed971af9f9f741f62405eb", "best_bid": "0.12", "best_ask": "0.14"}, {"asset_id": "10824614737277384579120931547716737694062714916890575016613469671599992760641", "price": "0.86", "size": "67.26", "side": "BUY", "hash": "e599a9b4d80c707c0b19584512cf69ceb5cbeead", "best_bid": "0.86", "best_ask": "0.88"}], "timestamp": "1769384150447", "event_type": "price_change"}}
{"_local_timestamp": "2026-01-25T23:35:52.406314+00:00", "data": {"market": "0x1c90e1383b8664103731bacc42ba86dff9c1582b8982f0ec02ba6aa255540dec", "price_changes": [{"asset_id": "97961254854749379702593191658896132704622945558274415067651430934438719211772", "price": "0.14", "size": "91.67", "side": "SELL", "hash": "faa3fca2b17c76e29d2079876e59b757e5220c5d", "best_bid": "0.12", "best_ask": "0.14"}, {"asset_id": "10824614737277384579120931547716737694062714916890575016613469671599992760641", "price": "0.86", "size": "91.67", "side": "BUY", "hash": "40eef7054e7df2d74e5b7161ee90f734ded15c69", "best_bid": "0.86", "best_ask": "0.88"}], "timestamp": "1769384152324", "event_type": "price_change"}}
{"_local_timestamp": "2026-01-25T23:35:54.143775+00:00", "data": {"market": "0x1c90e1383b8664103731bacc42ba86dff9c1582b8982f0ec02ba6aa255540dec", "price_changes": [{"asset_id": "97961254854749379702593191658896132704622945558274415067651430934438719211772", "price": "0.14", "size": "67.26", "side": "SELL", "hash": "029004a071f7db24a704e3a8b294342665fef600", "best_bid": "0.12", "best_ask": "0.14"}, {"asset_id": "10824614737277384579120931547716737694062714916890575016613469671599992760641", "price": "0.86", "size": "67.26", "side": "BUY", "hash": "fbdfb424d39a5af1bb8b2b4a40abc59c2b7db13d", "best_bid": "0.86", "best_ask": "0.88"}], "timestamp": "1769384154069", "event_type": "price_change"}}
{"_local_timestamp": "2026-01-25T23:35:56.437793+00:00", "data": {"market": "0x1c90e1383b8664103731bacc42ba86dff9c1582b8982f0ec02ba6aa255540dec", "price_changes": [{"asset_id": "10824614737277384579120931547716737694062714916890575016613469671599992760641", "price": "0.21", "size": "760", "side": "BUY", "hash": "41fce1b75387d74ed8fa7fb782a6b4e26f68c540", "best_bid": "0.86", "best_ask": "0.88"}, {"asset_id": "97961254854749379702593191658896132704622945558274415067651430934438719211772", "price": "0.79", "size": "760", "side": "SELL", "hash": "71c881c4bb413d6f30e78aef3224de5d725e3934", "best_bid": "0.12", "best_ask": "0.14"}], "timestamp": "1769384156288", "event_type": "price_change"}}
{"_local_timestamp": "2026-01-25T23:35:56.848104+00:00", "data": {"market": "0x1c90e1383b8664103731bacc42ba86dff9c1582b8982f0ec02ba6aa255540dec", "price_changes": [{"asset_id": "10824614737277384579120931547716737694062714916890575016613469671599992760641", "price": "0.23", "size": "200", "side": "BUY", "hash": "41b1eb249b46576a124ffa2296be80bc3d00c52e", "best_bid": "0.86", "best_ask": "0.88"}, {"asset_id": "97961254854749379702593191658896132704622945558274415067651430934438719211772", "price": "0.77", "size": "200", "side": "SELL", "hash": "afef6b3b0596ff055249867fbc21b30f7eaf5f57", "best_bid": "0.12", "best_ask": "0.14"}], "timestamp": "1769384156718", "event_type": "price_change"}}
{"_local_timestamp": "2026-01-25T23:35:57.342408+00:00", "data": {"market": "0x1c90e1383b8664103731bacc42ba86dff9c1582b8982f0ec02ba6aa255540dec", "price_changes": [{"asset_id": "97961254854749379702593191658896132704622945558274415067651430934438719211772", "price": "0.14", "size": "91.67", "side": "SELL", "hash": "f78db23908fe7e9b4a4edb5438c082f08a3bb2a9", "best_bid": "0.12", "best_ask": "0.14"}, {"asset_id": "10824614737277384579120931547716737694062714916890575016613469671599992760641", "price": "0.86", "size": "91.67", "side": "BUY", "hash": "2c345c33626ac4c23fa71281dbfece13b8b6bae6", "best_bid": "0.86", "best_ask": "0.88"}], "timestamp": "1769384157258", "event_type": "price_change"}}
{"_local_timestamp": "2026-01-25T23:35:57.662921+00:00", "data": {"market": "0x1c90e1383b8664103731bacc42ba86dff9c1582b8982f0ec02ba6aa255540dec", "price_changes": [{"asset_id": "97961254854749379702593191658896132704622945558274415067651430934438719211772", "price": "0.14", "size": "67.26", "side": "SELL", "hash": "cd481c58892885a9695a7ebbe8c150038ca10501", "best_bid": "0.12", "best_ask": "0.14"}, {"asset_id": "10824614737277384579120931547716737694062714916890575016613469671599992760641", "price": "0.86", "size": "67.26", "side": "BUY", "hash": "ac17ae85854f10d830b75a7b1146eef6b83e3a8d", "best_bid": "0.86", "best_ask": "0.88"}], "timestamp": "1769384157595", "event_type": "price_change"}}
{"_local_timestamp": "2026-01-25T23:35:58.203893+00:00", "data": {"market": "0x1c90e1383b8664103731bacc42ba86dff9c1582b8982f0ec02ba6aa255540dec", "price_changes": [{"asset_id": "10824614737277384579120931547716737694062714916890575016613469671599992760641", "price": "0.22", "size": "127.27", "side": "BUY", "hash": "8c92f7f2e45c775e54711d2e695de193ca05ec01", "best_bid": "0.86", "best_ask": "0.88"}, {"asset_id": "97961254854749379702593191658896132704622945558274415067651430934438719211772", "price": "0.78", "size": "127.27", "side": "SELL", "hash": "be55ce1a746336366831ba13d33b82f1471dfa6b", "best_bid": "0.12", "best_ask": "0.14"}], "timestamp": "1769384158078", "event_type": "price_change"}}
{"_local_timestamp": "2026-01-25T23:35:59.893143+00:00", "data": {"market": "0x1c90e1383b8664103731bacc42ba86dff9c1582b8982f0ec02ba6aa255540dec", "price_changes": [{"asset_id": "97961254854749379702593191658896132704622945558274415067651430934438719211772", "price": "0.14", "size": "91.67", "side": "SELL", "hash": "f65650660df38be68fc93aab01880252ef2a1936", "best_bid": "0.12", "best_ask": "0.14"}, {"asset_id": "10824614737277384579120931547716737694062714916890575016613469671599992760641", "price": "0.86", "size": "91.67", "side": "BUY", "hash": "7530840649d1154eb22bf47c9e5fb6d30bc88e63", "best_bid": "0.86", "best_ask": "0.88"}], "timestamp": "1769384159823", "event_type": "price_change"}}
{"_local_timestamp": "2026-01-25T23:36:01.109375+00:00", "data": {"market": "0x1c90e1383b8664103731bacc42ba86dff9c1582b8982f0ec02ba6aa255540dec", "price_changes": [{"asset_id": "97961254854749379702593191658896132704622945558274415067651430934438719211772", "price": "0.14", "size": "67.26", "side": "SELL", "hash": "baabbef1a5d8d5af5152d00a7e0fba0ebb052a33", "best_bid": "0.12", "best_ask": "0.14"}, {"asset_id": "10824614737277384579120931547716737694062714916890575016613469671599992760641", "price": "0.86", "size": "67.26", "side": "BUY", "hash": "491cd826fe9578c59cf1aabd7e9529da0e6ed2dc", "best_bid": "0.86", "best_ask": "0.88"}], "timestamp": "1769384161017", "event_type": "price_change"}}
{"_local_timestamp": "2026-01-25T23:36:02.172303+00:00", "data": {"market": "0x1c90e1383b8664103731bacc42ba86dff9c1582b8982f0ec02ba6aa255540dec", "price_changes": [{"asset_id": "97961254854749379702593191658896132704622945558274415067651430934438719211772", "price": "0.14", "size": "91.67", "side": "SELL", "hash": "c580c2df9498679c495668d63c15ba63063b86de", "best_bid": "0.12", "best_ask": "0.14"}, {"asset_id": "10824614737277384579120931547716737694062714916890575016613469671599992760641", "price": "0.86", "size": "91.67", "side": "BUY", "hash": "562682270dc68d212c0e0fcfdbe89b2a1fb4cf7d", "best_bid": "0.86", "best_ask": "0.88"}], "timestamp": "1769384162101", "event_type": "price_change"}}
{"_local_timestamp": "2026-01-25T23:36:05.281399+00:00", "data": {"market": "0x1c90e1383b8664103731bacc42ba86dff9c1582b8982f0ec02ba6aa255540dec", "price_changes": [{"asset_id": "97961254854749379702593191658896132704622945558274415067651430934438719211772", "price": "0.14", "size": "67.26", "side": "SELL", "hash": "b35d7027c1352e7c69f42c39a10739c682e1de30", "best_bid": "0.12", "best_ask": "0.14"}, {"asset_id": "10824614737277384579120931547716737694062714916890575016613469671599992760641", "price": "0.86", "size": "67.26", "side": "BUY", "hash": "129d42bb63ea1c10d4524168b775293c526e542e", "best_bid": "0.86", "best_ask": "0.88"}], "timestamp": "1769384165214", "event_type": "price_change"}}
{"_local_timestamp": "2026-01-25T23:36:06.657161+00:00", "data": {"market": "0x1c90e1383b8664103731bacc42ba86dff9c1582b8982f0ec02ba6aa255540dec", "price_changes": [{"asset_id": "97961254854749379702593191658896132704622945558274415067651430934438719211772", "price": "0.14", "size": "91.67", "side": "SELL", "hash": "b22744cb3bc01be491d370679437460f384bb3a6", "best_bid": "0.12", "best_ask": "0.14"}, {"asset_id": "10824614737277384579120931547716737694062714916890575016613469671599992760641", "price": "0.86", "size": "91.67", "side": "BUY", "hash": "13d1158a2ce5bf3016c28fa74371c3a16d18f237", "best_bid": "0.86", "best_ask": "0.88"}], "timestamp": "1769384166590", "event_type": "price_change"}}
{"_local_timestamp": "2026-01-25T23:36:08.993099+00:00", "data": {"market": "0x1c90e1383b8664103731bacc42ba86dff9c1582b8982f0ec02ba6aa255540dec", "price_changes": [{"asset_id": "97961254854749379702593191658896132704622945558274415067651430934438719211772", "price": "0.14", "size": "67.26", "side": "SELL", "hash": "a8da3f3a8d45770e2e64d41907c38e4baf82404c", "best_bid": "0.12", "best_ask": "0.14"}, {"asset_id": "10824614737277384579120931547716737694062714916890575016613469671599992760641", "price": "0.86", "size": "67.26", "side": "BUY", "hash": "ecd174c9eea3715a8bfd56f1d32f4709772ef05d", "best_bid": "0.86", "best_ask": "0.88"}], "timestamp": "1769384168916", "event_type": "price_change"}}
{"_local_timestamp": "2026-01-25T23:36:11.145206+00:00", "data": {"market": "0x1c90e1383b8664103731bacc42ba86dff9c1582b8982f0ec02ba6aa255540dec", "price_changes": [{"asset_id": "97961254854749379702593191658896132704622945558274415067651430934438719211772", "price": "0.14", "size": "91.67", "side": "SELL", "hash": "5aee7b250568c561598ec9fdfff98428b13f446c", "best_bid": "0.12", "best_ask": "0.14"}, {"asset_id": "10824614737277384579120931547716737694062714916890575016613469671599992760641", "price": "0.86", "size": "91.67", "side": "BUY", "hash": "cca47f1c48c31bfa65915844e9c1f7808505a3ea", "best_bid": "0.86", "best_ask": "0.88"}], "timestamp": "1769384171067", "event_type": "price_change"}}
{"_local_timestamp": "2026-01-25T23:36:12.802249+00:00", "data": {"market": "0x1c90e1383b8664103731bacc42ba86dff9c1582b8982f0ec02ba6aa255540dec", "price_changes": [{"asset_id": "97961254854749379702593191658896132704622945558274415067651430934438719211772", "price": "0.14", "size": "67.26", "side": "SELL", "hash": "c8d08fac79f440996f7686699d9b9553ddf87422", "best_bid": "0.12", "best_ask": "0.14"}, {"asset_id": "10824614737277384579120931547716737694062714916890575016613469671599992760641", "price": "0.86", "size": "67.26", "side": "BUY", "hash": "b78f357b126447516a31e04b1541f2953e751611", "best_bid": "0.86", "best_ask": "0.88"}], "timestamp": "1769384172734", "event_type": "price_change"}}
{"_local_timestamp": "2026-01-25T23:36:13.655121+00:00", "data": {"market": "0x1c90e1383b8664103731bacc42ba86dff9c1582b8982f0ec02ba6aa255540dec", "price_changes": [{"asset_id": "97961254854749379702593191658896132704622945558274415067651430934438719211772", "price": "0.14", "size": "91.67", "side": "SELL", "hash": "0cbdf07282ed22d38f3fb384e84a2696d8dfc155", "best_bid": "0.12", "best_ask": "0.14"}, {"asset_id": "10824614737277384579120931547716737694062714916890575016613469671599992760641", "price": "0.86", "size": "91.67", "side": "BUY", "hash": "ab66ddd487d48d63e8108814b4037d16d2a60f71", "best_bid": "0.86", "best_ask": "0.88"}], "timestamp": "1769384173580", "event_type": "price_change"}}
{"_local_timestamp": "2026-01-25T23:36:16.546811+00:00", "data": {"market": "0x1c90e1383b8664103731bacc42ba86dff9c1582b8982f0ec02ba6aa255540dec", "price_changes": [{"asset_id": "97961254854749379702593191658896132704622945558274415067651430934438719211772", "price": "0.14", "size": "67.26", "side": "SELL", "hash": "9a17e1250f2af8e55793b50ff871186c9814735a", "best_bid": "0.12", "best_ask": "0.14"}, {"asset_id": "10824614737277384579120931547716737694062714916890575016613469671599992760641", "price": "0.86", "size": "67.26", "side": "BUY", "hash": "6975c83058255a73b24f9b38c8f80a19d5645bc0", "best_bid": "0.86", "best_ask": "0.88"}], "timestamp": "1769384176480", "event_type": "price_change"}}
{"_local_timestamp": "2026-01-25T23:36:18.070224+00:00", "data": {"market": "0x1c90e1383b8664103731bacc42ba86dff9c1582b8982f0ec02ba6aa255540dec", "price_changes": [{"asset_id": "97961254854749379702593191658896132704622945558274415067651430934438719211772", "price": "0.14", "size": "91.67", "side": "SELL", "hash": "b5f068d494022016c8c03aac868affaaca3aad39", "best_bid": "0.12", "best_ask": "0.14"}, {"asset_id": "10824614737277384579120931547716737694062714916890575016613469671599992760641", "price": "0.86", "size": "91.67", "side": "BUY", "hash": "732433d6fb2e88262ff9bcba995a80ec4adf86be", "best_bid": "0.86", "best_ask": "0.88"}], "timestamp": "1769384177998", "event_type": "price_change"}}
{"_local_timestamp": "2026-01-25T23:36:20.479558+00:00", "data": {"market": "0x1c90e1383b8664103731bacc42ba86dff9c1582b8982f0ec02ba6aa255540dec", "price_changes": [{"asset_id": "97961254854749379702593191658896132704622945558274415067651430934438719211772", "price": "0.14", "size": "67.26", "side": "SELL", "hash": "a1991947f8d420040c324ca6d87c5c2242b07ee2", "best_bid": "0.12", "best_ask": "0.14"}, {"asset_id": "10824614737277384579120931547716737694062714916890575016613469671599992760641", "price": "0.86", "size": "67.26", "side": "BUY", "hash": "9265b7c247bc62e78fa8098f9b0de5cf3536c7e6", "best_bid": "0.86", "best_ask": "0.88"}], "timestamp": "1769384180405", "event_type": "price_change"}}
{"_local_timestamp": "2026-01-25T23:36:22.857872+00:00", "data": {"market": "0x1c90e1383b8664103731bacc42ba86dff9c1582b8982f0ec02ba6aa255540dec", "price_changes": [{"asset_id": "97961254854749379702593191658896132704622945558274415067651430934438719211772", "price": "0.14", "size": "91.67", "side": "SELL", "hash": "d365a01640c97d8b779a8d7c88456af86de526ae", "best_bid": "0.12", "best_ask": "0.14"}, {"asset_id": "10824614737277384579120931547716737694062714916890575016613469671599992760641", "price": "0.86", "size": "91.67", "side": "BUY", "hash": "7600c81c926544203123f252cf074a7fa0d15cb0", "best_bid": "0.86", "best_ask": "0.88"}], "timestamp": "1769384182786", "event_type": "price_change"}}
{"_local_timestamp": "2026-01-25T23:36:24.311687+00:00", "data": {"market": "0x1c90e1383b8664103731bacc42ba86dff9c1582b8982f0ec02ba6aa255540dec", "price_changes": [{"asset_id": "97961254854749379702593191658896132704622945558274415067651430934438719211772", "price": "0.14", "size": "67.26", "side": "SELL", "hash": "7cbd11a1edc330053f0d09bb044747ad0decdc7a", "best_bid": "0.12", "best_ask": "0.14"}, {"asset_id": "10824614737277384579120931547716737694062714916890575016613469671599992760641", "price": "0.86", "size": "67.26", "side": "BUY", "hash": "172709432c595994c5f6900c5575151d9fc9f891", "best_bid": "0.86", "best_ask": "0.88"}], "timestamp": "1769384184227", "event_type": "price_change"}}
{"_local_timestamp": "2026-01-25T23:36:25.524102+00:00", "data": {"market": "0x1c90e1383b8664103731bacc42ba86dff9c1582b8982f0ec02ba6aa255540dec", "price_changes": [{"asset_id": "97961254854749379702593191658896132704622945558274415067651430934438719211772", "price": "0.14", "size": "91.67", "side": "SELL", "hash": "efb7c2ebcac6254c73a7ef3ec94f4172838b6b74", "best_bid": "0.12", "best_ask": "0.14"}, {"asset_id": "10824614737277384579120931547716737694062714916890575016613469671599992760641", "price": "0.86", "size": "91.67", "side": "BUY", "hash": "d98748d164ca6c54c295119ffebb707a44d748b7", "best_bid": "0.86", "best_ask": "0.88"}], "timestamp": "1769384185452", "event_type": "price_change"}}
{"_local_timestamp": "2026-01-25T23:36:28.433386+00:00", "data": {"market": "0x1c90e1383b8664103731bacc42ba86dff9c1582b8982f0ec02ba6aa255540dec", "price_changes": [{"asset_id": "97961254854749379702593191658896132704622945558274415067651430934438719211772", "price": "0.14", "size": "67.26", "side": "SELL", "hash": "8eab88b28a4e573b0e5ac25ab5a7f3349d27d72f", "best_bid": "0.12", "best_ask": "0.14"}, {"asset_id": "10824614737277384579120931547716737694062714916890575016613469671599992760641", "price": "0.86", "size": "67.26", "side": "BUY", "hash": "b374cbc413de2d637ea3c04e006ffe46c7b85d06", "best_bid": "0.86", "best_ask": "0.88"}], "timestamp": "1769384188357", "event_type": "price_change"}}
{"_local_timestamp": "2026-01-25T23:36:30.578369+00:00", "data": {"market": "0x1c90e1383b8664103731bacc42ba86dff9c1582b8982f0ec02ba6aa255540dec", "price_changes": [{"asset_id": "97961254854749379702593191658896132704622945558274415067651430934438719211772", "price": "0.14", "size": "91.67", "side": "SELL", "hash": "0ca3bbb0a16647e68678c042222ab01a94570da7", "best_bid": "0.12", "best_ask": "0.14"}, {"asset_id": "10824614737277384579120931547716737694062714916890575016613469671599992760641", "price": "0.86", "size": "91.67", "side": "BUY", "hash": "caca4c0fb16a1e33f204d7cb9a98dc3aec8f5636", "best_bid": "0.86", "best_ask": "0.88"}], "timestamp": "1769384190504", "event_type": "price_change"}}
{"_local_timestamp": "2026-01-25T23:36:32.330359+00:00", "data": {"market": "0x1c90e1383b8664103731bacc42ba86dff9c1582b8982f0ec02ba6aa255540dec", "price_changes": [{"asset_id": "97961254854749379702593191658896132704622945558274415067651430934438719211772", "price": "0.14", "size": "67.26", "side": "SELL", "hash": "7a16da801240ab8c82d1cd4fea6bcf028ea7d7c7", "best_bid": "0.12", "best_ask": "0.14"}, {"asset_id": "10824614737277384579120931547716737694062714916890575016613469671599992760641", "price": "0.86", "size": "67.26", "side": "BUY", "hash": "37be531541c5e01e4d516230024a6d7b8ce23dc8", "best_bid": "0.86", "best_ask": "0.88"}], "timestamp": "1769384192253", "event_type": "price_change"}}
{"_local_timestamp": "2026-01-25T23:36:35.889059+00:00", "data": {"market": "0x1c90e1383b8664103731bacc42ba86dff9c1582b8982f0ec02ba6aa255540dec", "price_changes": [{"asset_id": "97961254854749379702593191658896132704622945558274415067651430934438719211772", "price": "0.14", "size": "91.67", "side": "SELL", "hash": "550eda73b0d9544a014ea5e4376c4b7efb4a30e9", "best_bid": "0.12", "best_ask": "0.14"}, {"asset_id": "10824614737277384579120931547716737694062714916890575016613469671599992760641", "price": "0.86", "size": "91.67", "side": "BUY", "hash": "14e90420006fb240ec49ce9d8de84355bcce15a0", "best_bid": "0.86", "best_ask": "0.88"}], "timestamp": "1769384195818", "event_type": "price_change"}}
{"_local_timestamp": "2026-01-25T23:36:39.722917+00:00", "data": {"market": "0x1c90e1383b8664103731bacc42ba86dff9c1582b8982f0ec02ba6aa255540dec", "price_changes": [{"asset_id": "97961254854749379702593191658896132704622945558274415067651430934438719211772", "price": "0.14", "size": "67.26", "side": "SELL", "hash": "b990c4104f7c08bdec90b2eed2a20624d038b641", "best_bid": "0.12", "best_ask": "0.14"}, {"asset_id": "10824614737277384579120931547716737694062714916890575016613469671599992760641", "price": "0.86", "size": "67.26", "side": "BUY", "hash": "d6de0ee2866b59893944a10ff07476ec1f4d38d7", "best_bid": "0.86", "best_ask": "0.88"}], "timestamp": "1769384199654", "event_type": "price_change"}}
{"_local_timestamp": "2026-01-25T23:36:40.832656+00:00", "data": {"market": "0x1c90e1383b8664103731bacc42ba86dff9c1582b8982f0ec02ba6aa255540dec", "price_changes": [{"asset_id": "97961254854749379702593191658896132704622945558274415067651430934438719211772", "price": "0.14", "size": "91.67", "side": "SELL", "hash": "0fd0a194a8f543e4dc1d2f90b03198506c7bc391", "best_bid": "0.12", "best_ask": "0.14"}, {"asset_id": "10824614737277384579120931547716737694062714916890575016613469671599992760641", "price": "0.86", "size": "91.67", "side": "BUY", "hash": "b18541de3e799223aec227fca88fa75850a64d6c", "best_bid": "0.86", "best_ask": "0.88"}], "timestamp": "1769384200766", "event_type": "price_change"}}
{"_local_timestamp": "2026-01-25T23:36:43.583538+00:00", "data": {"market": "0x1c90e1383b8664103731bacc42ba86dff9c1582b8982f0ec02ba6aa255540dec", "price_changes": [{"asset_id": "97961254854749379702593191658896132704622945558274415067651430934438719211772", "price": "0.14", "size": "67.26", "side": "SELL", "hash": "d8bc4636fe5be92bb28ed06aac3fc3fec4bdddac", "best_bid": "0.12", "best_ask": "0.14"}, {"asset_id": "10824614737277384579120931547716737694062714916890575016613469671599992760641", "price": "0.86", "size": "67.26", "side": "BUY", "hash": "e8150d2f476e99f0c6b2a405ae4460a49ee27fea", "best_bid": "0.86", "best_ask": "0.88"}], "timestamp": "1769384203412", "event_type": "price_change"}}
{"_local_timestamp": "2026-01-25T23:36:45.454675+00:00", "data": {"market": "0x1c90e1383b8664103731bacc42ba86dff9c1582b8982f0ec02ba6aa255540dec", "price_changes": [{"asset_id": "97961254854749379702593191658896132704622945558274415067651430934438719211772", "price": "0.14", "size": "91.67", "side": "SELL", "hash": "ac652c932bbfdb723a41f4c571ae430d810284c4", "best_bid": "0.12", "best_ask": "0.14"}, {"asset_id": "10824614737277384579120931547716737694062714916890575016613469671599992760641", "price": "0.86", "size": "91.67", "side": "BUY", "hash": "34bd8579b9762cd73075c949b5791c955c9ef61d", "best_bid": "0.86", "best_ask": "0.88"}], "timestamp": "1769384205284", "event_type": "price_change"}}
{"_local_timestamp": "2026-01-25T23:36:47.413036+00:00", "data": {"market": "0x1c90e1383b8664103731bacc42ba86dff9c1582b8982f0ec02ba6aa255540dec", "price_changes": [{"asset_id": "97961254854749379702593191658896132704622945558274415067651430934438719211772", "price": "0.14", "size": "67.26", "side": "SELL", "hash": "669408f440cb352c80cd2ebacd4205e73a14a77e", "best_bid": "0.12", "best_ask": "0.14"}, {"asset_id": "10824614737277384579120931547716737694062714916890575016613469671599992760641", "price": "0.86", "size": "67.26", "side": "BUY", "hash": "66829f71aaba99369f9cb0f620d6e4099db8a378", "best_bid": "0.86", "best_ask": "0.88"}], "timestamp": "1769384207244", "event_type": "price_change"}}
{"_local_timestamp": "2026-01-25T23:36:50.760713+00:00", "data": {"market": "0x1c90e1383b8664103731bacc42ba86dff9c1582b8982f0ec02ba6aa255540dec", "price_changes": [{"asset_id": "97961254854749379702593191658896132704622945558274415067651430934438719211772", "price": "0.14", "size": "91.67", "side": "SELL", "hash": "931c7eb3dcd8efd2a5d68dd8a0fb8daeff6d540f", "best_bid": "0.12", "best_ask": "0.14"}, {"asset_id": "10824614737277384579120931547716737694062714916890575016613469671599992760641", "price": "0.86", "size": "91.67", "side": "BUY", "hash": "a001229cd4983c6489b07eef9092b88e46b39083", "best_bid": "0.86", "best_ask": "0.88"}], "timestamp": "1769384210614", "event_type": "price_change"}}
{"_local_timestamp": "2026-01-25T23:36:54.756976+00:00", "data": {"market": "0x1c90e1383b8664103731bacc42ba86dff9c1582b8982f0ec02ba6aa255540dec", "price_changes": [{"asset_id": "97961254854749379702593191658896132704622945558274415067651430934438719211772", "price": "0.14", "size": "67.26", "side": "SELL", "hash": "1a4c14350959fe7cd9a8111974901b8a6850a529", "best_bid": "0.12", "best_ask": "0.14"}, {"asset_id": "10824614737277384579120931547716737694062714916890575016613469671599992760641", "price": "0.86", "size": "67.26", "side": "BUY", "hash": "1f7c13fdf00da49118a6b08ebf86588ebbccf334", "best_bid": "0.86", "best_ask": "0.88"}], "timestamp": "1769384214551", "event_type": "price_change"}}
{"_local_timestamp": "2026-01-25T23:36:55.185798+00:00", "data": {"market": "0x1c90e1383b8664103731bacc42ba86dff9c1582b8982f0ec02ba6aa255540dec", "price_changes": [{"asset_id": "10824614737277384579120931547716737694062714916890575016613469671599992760641", "price": "0.23", "size": "100", "side": "BUY", "hash": "37c1ef279c534fbc0f10ec40c1745100bbe571b7", "best_bid": "0.86", "best_ask": "0.88"}, {"asset_id": "97961254854749379702593191658896132704622945558274415067651430934438719211772", "price": "0.77", "size": "100", "side": "SELL", "hash": "06c6ee9e7cc7c10d218a6a86d9131d1174ef670b", "best_bid": "0.12", "best_ask": "0.14"}], "timestamp": "1769384214955", "event_type": "price_change"}}
{"_local_timestamp": "2026-01-25T23:36:55.697069+00:00", "data": {"market": "0x1c90e1383b8664103731bacc42ba86dff9c1582b8982f0ec02ba6aa255540dec", "price_changes": [{"asset_id": "97961254854749379702593191658896132704622945558274415067651430934438719211772", "price": "0.14", "size": "91.67", "side": "SELL", "hash": "056c63e2c919b498912c65991b78031693a5136b", "best_bid": "0.12", "best_ask": "0.14"}, {"asset_id": "10824614737277384579120931547716737694062714916890575016613469671599992760641", "price": "0.86", "size": "91.67", "side": "BUY", "hash": "d0e106efa1c235fb1e41824dfcc91bc503277891", "best_bid": "0.86", "best_ask": "0.88"}], "timestamp": "1769384215483", "event_type": "price_change"}}
{"_local_timestamp": "2026-01-25T23:36:55.991000+00:00", "data": {"market": "0x1c90e1383b8664103731bacc42ba86dff9c1582b8982f0ec02ba6aa255540dec", "price_changes": [{"asset_id": "10824614737277384579120931547716737694062714916890575016613469671599992760641", "price": "0.21", "size": "860", "side": "BUY", "hash": "c96f7bfb44d21d8979f0d1af92f2e34565eea4da", "best_bid": "0.86", "best_ask": "0.88"}, {"asset_id": "97961254854749379702593191658896132704622945558274415067651430934438719211772", "price": "0.79", "size": "860", "side": "SELL", "hash": "33695ba4a24067a8e185698bc267be702a4e5cd0", "best_bid": "0.12", "best_ask": "0.14"}], "timestamp": "1769384215633", "event_type": "price_change"}}
{"_local_timestamp": "2026-01-25T23:36:58.135141+00:00", "data": {"market": "0x1c90e1383b8664103731bacc42ba86dff9c1582b8982f0ec02ba6aa255540dec", "price_changes": [{"asset_id": "97961254854749379702593191658896132704622945558274415067651430934438719211772", "price": "0.14", "size": "67.26", "side": "SELL", "hash": "394cececc41419e4bfa73044f054f0bc4497d685", "best_bid": "0.12", "best_ask": "0.14"}, {"asset_id": "10824614737277384579120931547716737694062714916890575016613469671599992760641", "price": "0.86", "size": "67.26", "side": "BUY", "hash": "88b0cc8d92f1dce49e6485d9dd6fd23c3d1fb3ee", "best_bid": "0.86", "best_ask": "0.88"}], "timestamp": "1769384217945", "event_type": "price_change"}}
{"_local_timestamp": "2026-01-25T23:36:58.767929+00:00", "data": {"market": "0x1c90e1383b8664103731bacc42ba86dff9c1582b8982f0ec02ba6aa255540dec", "price_changes": [{"asset_id": "10824614737277384579120931547716737694062714916890575016613469671599992760641", "price": "0.24", "size": "1748", "side": "BUY", "hash": "45e7688dd2710387228b2ad97eb86be5cef563f8", "best_bid": "0.86", "best_ask": "0.88"}, {"asset_id": "97961254854749379702593191658896132704622945558274415067651430934438719211772", "price": "0.76", "size": "1748", "side": "SELL", "hash": "3c25acae7adcb66f2f27e9aadef2a60d0aa5e3d4", "best_bid": "0.12", "best_ask": "0.14"}], "timestamp": "1769384218542", "event_type": "price_change"}}
{"_local_timestamp": "2026-01-25T23:37:00.820916+00:00", "data": {"market": "0x1c90e1383b8664103731bacc42ba86dff9c1582b8982f0ec02ba6aa255540dec", "price_changes": [{"asset_id": "97961254854749379702593191658896132704622945558274415067651430934438719211772", "price": "0.14", "size": "91.67", "side": "SELL", "hash": "1c503c2957d1a57af20dba8683ecc201c41cc3a6", "best_bid": "0.12", "best_ask": "0.14"}, {"asset_id": "10824614737277384579120931547716737694062714916890575016613469671599992760641", "price": "0.86", "size": "91.67", "side": "BUY", "hash": "ddbed166ffab51ceac38da608fd064ba352405f6", "best_bid": "0.86", "best_ask": "0.88"}], "timestamp": "1769384220614", "event_type": "price_change"}}
{"_local_timestamp": "2026-01-25T23:37:01.972473+00:00", "data": {"market": "0x1c90e1383b8664103731bacc42ba86dff9c1582b8982f0ec02ba6aa255540dec", "price_changes": [{"asset_id": "97961254854749379702593191658896132704622945558274415067651430934438719211772", "price": "0.14", "size": "67.26", "side": "SELL", "hash": "3b442d66b6844b94d6113b19e98a12aa9ba81b9e", "best_bid": "0.12", "best_ask": "0.14"}, {"asset_id": "10824614737277384579120931547716737694062714916890575016613469671599992760641", "price": "0.86", "size": "67.26", "side": "BUY", "hash": "4c6dce06ebe8ef57311fdab000ee133981f8105c", "best_bid": "0.86", "best_ask": "0.88"}], "timestamp": "1769384221791", "event_type": "price_change"}}
{"_local_timestamp": "2026-01-25T23:37:03.060274+00:00", "data": {"market": "0x1c90e1383b8664103731bacc42ba86dff9c1582b8982f0ec02ba6aa255540dec", "price_changes": [{"asset_id": "97961254854749379702593191658896132704622945558274415067651430934438719211772", "price": "0.14", "size": "91.67", "side": "SELL", "hash": "ed038e31094c6d17f21449ad8023b501dd3aa1c6", "best_bid": "0.12", "best_ask": "0.14"}, {"asset_id": "10824614737277384579120931547716737694062714916890575016613469671599992760641", "price": "0.86", "size": "91.67", "side": "BUY", "hash": "7539989c9621e065093c7100e4ca2b72149f254c", "best_bid": "0.86", "best_ask": "0.88"}], "timestamp": "1769384222861", "event_type": "price_change"}}
{"_local_timestamp": "2026-01-25T23:37:05.901189+00:00", "data": {"market": "0x1c90e1383b8664103731bacc42ba86dff9c1582b8982f0ec02ba6aa255540dec", "price_changes": [{"asset_id": "97961254854749379702593191658896132704622945558274415067651430934438719211772", "price": "0.14", "size": "67.26", "side": "SELL", "hash": "8c8d6475bc794c7a9d398e8e4dda181e3124cece", "best_bid": "0.12", "best_ask": "0.14"}, {"asset_id": "10824614737277384579120931547716737694062714916890575016613469671599992760641", "price": "0.86", "size": "67.26", "side": "BUY", "hash": "349e8f4b59ea24f08c7f8a60124d7e6391974bbe", "best_bid": "0.86", "best_ask": "0.88"}], "timestamp": "1769384225686", "event_type": "price_change"}}
{"_local_timestamp": "2026-01-25T23:37:08.218527+00:00", "data": {"market": "0x1c90e1383b8664103731bacc42ba86dff9c1582b8982f0ec02ba6aa255540dec", "price_changes": [{"asset_id": "97961254854749379702593191658896132704622945558274415067651430934438719211772", "price": "0.14", "size": "91.67", "side": "SELL", "hash": "fd96672aaaa8d627b24b431b4bc95baf146e62cd", "best_bid": "0.12", "best_ask": "0.14"}, {"asset_id": "10824614737277384579120931547716737694062714916890575016613469671599992760641", "price": "0.86", "size": "91.67", "side": "BUY", "hash": "d9a506ca12214215be7859b6d5eaa0f48e83432c", "best_bid": "0.86", "best_ask": "0.88"}], "timestamp": "1769384228038", "event_type": "price_change"}}
{"_local_timestamp": "2026-01-25T23:37:09.344365+00:00", "data": {"market": "0x1c90e1383b8664103731bacc42ba86dff9c1582b8982f0ec02ba6aa255540dec", "price_changes": [{"asset_id": "97961254854749379702593191658896132704622945558274415067651430934438719211772", "price": "0.14", "size": "67.26", "side": "SELL", "hash": "67b033c8aac4c90f25df760b18dd11973e29acfa", "best_bid": "0.12", "best_ask": "0.14"}, {"asset_id": "10824614737277384579120931547716737694062714916890575016613469671599992760641", "price": "0.86", "size": "67.26", "side": "BUY", "hash": "ad965a628eca6971e7afe69c98dbd2b98453c301", "best_bid": "0.86", "best_ask": "0.88"}], "timestamp": "1769384229263", "event_type": "price_change"}}
{"_local_timestamp": "2026-01-25T23:37:10.109206+00:00", "data": {"market": "0x1c90e1383b8664103731bacc42ba86dff9c1582b8982f0ec02ba6aa255540dec", "price_changes": [{"asset_id": "97961254854749379702593191658896132704622945558274415067651430934438719211772", "price": "0.14", "size": "91.67", "side": "SELL", "hash": "70e85c7b3a6f0a05b2716b2d8353d019bb3cd3c5", "best_bid": "0.12", "best_ask": "0.14"}, {"asset_id": "10824614737277384579120931547716737694062714916890575016613469671599992760641", "price": "0.86", "size": "91.67", "side": "BUY", "hash": "1355d25babece315fe3cb96258168bc229ee1bf6", "best_bid": "0.86", "best_ask": "0.88"}], "timestamp": "1769384230041", "event_type": "price_change"}}
{"_local_timestamp": "2026-01-25T23:37:13.052401+00:00", "data": {"market": "0x1c90e1383b8664103731bacc42ba86dff9c1582b8982f0ec02ba6aa255540dec", "price_changes": [{"asset_id": "97961254854749379702593191658896132704622945558274415067651430934438719211772", "price": "0.14", "size": "67.26", "side": "SELL", "hash": "dadbef16cb3c91c81cf7e535d5f71f1668abac32", "best_bid": "0.12", "best_ask": "0.14"}, {"asset_id": "10824614737277384579120931547716737694062714916890575016613469671599992760641", "price": "0.86", "size": "67.26", "side": "BUY", "hash": "8e2fcec62da01b957b5d99ecea184bcb0cd944c9", "best_bid": "0.86", "best_ask": "0.88"}], "timestamp": "1769384232984", "event_type": "price_change"}}
{"_local_timestamp": "2026-01-25T23:37:13.131781+00:00", "data": {"market": "0x1c90e1383b8664103731bacc42ba86dff9c1582b8982f0ec02ba6aa255540dec", "price_changes": [{"asset_id": "10824614737277384579120931547716737694062714916890575016613469671599992760641", "price": "0.23", "size": "50", "side": "BUY", "hash": "b023e304bf0a9dfe1aa3892149476dc16e6c45ec", "best_bid": "0.86", "best_ask": "0.88"}, {"asset_id": "97961254854749379702593191658896132704622945558274415067651430934438719211772", "price": "0.77", "size": "50", "side": "SELL", "hash": "5fe835025dfdbd0d7ce02baabdb01ca135d989b0", "best_bid": "0.12", "best_ask": "0.14"}], "timestamp": "1769384233012", "event_type": "price_change"}}
{"_local_timestamp": "2026-01-25T23:37:13.467808+00:00", "data": {"market": "0x1c90e1383b8664103731bacc42ba86dff9c1582b8982f0ec02ba6aa255540dec", "price_changes": [{"asset_id": "10824614737277384579120931547716737694062714916890575016613469671599992760641", "price": "0.22", "size": "177.27", "side": "BUY", "hash": "224e752045b03b41a5d5812aa7b36a9a3d329c7c", "best_bid": "0.86", "best_ask": "0.88"}, {"asset_id": "97961254854749379702593191658896132704622945558274415067651430934438719211772", "price": "0.78", "size": "177.27", "side": "SELL", "hash": "c8a847d15ca39b805024547159a8a9ce1c2f8532", "best_bid": "0.12", "best_ask": "0.14"}], "timestamp": "1769384233356", "event_type": "price_change"}}
{"_local_timestamp": "2026-01-25T23:37:14.869906+00:00", "data": {"market": "0x1c90e1383b8664103731bacc42ba86dff9c1582b8982f0ec02ba6aa255540dec", "price_changes": [{"asset_id": "97961254854749379702593191658896132704622945558274415067651430934438719211772", "price": "0.14", "size": "91.67", "side": "SELL", "hash": "0c1ac553fc16d551ae70bb4f5985495926144c36", "best_bid": "0.12", "best_ask": "0.14"}, {"asset_id": "10824614737277384579120931547716737694062714916890575016613469671599992760641", "price": "0.86", "size": "91.67", "side": "BUY", "hash": "af0809b3626df3b89644d3d1fa91def4da85c0c2", "best_bid": "0.86", "best_ask": "0.88"}], "timestamp": "1769384234793", "event_type": "price_change"}}
{"_local_timestamp": "2026-01-25T23:37:16.351473+00:00", "data": {"market": "0x1c90e1383b8664103731bacc42ba86dff9c1582b8982f0ec02ba6aa255540dec", "price_changes": [{"asset_id": "97961254854749379702593191658896132704622945558274415067651430934438719211772", "price": "0.14", "size": "67.26", "side": "SELL", "hash": "822ce4d1a4a8adcbf676cc65326305a2457bf99b", "best_bid": "0.12", "best_ask": "0.14"}, {"asset_id": "10824614737277384579120931547716737694062714916890575016613469671599992760641", "price": "0.86", "size": "67.26", "side": "BUY", "hash": "4e83d1903a1fa44347da47d5e654e98cd160ebda", "best_bid": "0.86", "best_ask": "0.88"}], "timestamp": "1769384236281", "event_type": "price_change"}}
{"_local_timestamp": "2026-01-25T23:37:17.048393+00:00", "data": {"market": "0x1c90e1383b8664103731bacc42ba86dff9c1582b8982f0ec02ba6aa255540dec", "price_changes": [{"asset_id": "97961254854749379702593191658896132704622945558274415067651430934438719211772", "price": "0.14", "size": "91.67", "side": "SELL", "hash": "8ff27fbcdd4e5dc3fdde054365fae8c4d7ff9fc3", "best_bid": "0.12", "best_ask": "0.14"}, {"asset_id": "10824614737277384579120931547716737694062714916890575016613469671599992760641", "price": "0.86", "size": "91.67", "side": "BUY", "hash": "dc8caf592668262b91596ef934cc0748ed4919d0", "best_bid": "0.86", "best_ask": "0.88"}], "timestamp": "1769384236979", "event_type": "price_change"}}
{"_local_timestamp": "2026-01-25T23:37:19.531010+00:00", "data": {"market": "0x1c90e1383b8664103731bacc42ba86dff9c1582b8982f0ec02ba6aa255540dec", "price_changes": [{"asset_id": "97961254854749379702593191658896132704622945558274415067651430934438719211772", "price": "0.14", "size": "67.26", "side": "SELL", "hash": "57fcc5a3c3f20c484a25aee0803a328d8f1698ef", "best_bid": "0.12", "best_ask": "0.14"}, {"asset_id": "10824614737277384579120931547716737694062714916890575016613469671599992760641", "price": "0.86", "size": "67.26", "side": "BUY", "hash": "27b6dc2b2d5628a8b524c171db7478bedd1f8a5b", "best_bid": "0.86", "best_ask": "0.88"}], "timestamp": "1769384239459", "event_type": "price_change"}}
{"_local_timestamp": "2026-01-25T23:37:21.548820+00:00", "data": {"market": "0x1c90e1383b8664103731bacc42ba86dff9c1582b8982f0ec02ba6aa255540dec", "price_changes": [{"asset_id": "97961254854749379702593191658896132704622945558274415067651430934438719211772", "price": "0.14", "size": "91.67", "side": "SELL", "hash": "b81192c67010c3c2fb8533f39e4eb34293c1aca6", "best_bid": "0.12", "best_ask": "0.14"}, {"asset_id": "10824614737277384579120931547716737694062714916890575016613469671599992760641", "price": "0.86", "size": "91.67", "side": "BUY", "hash": "a0ac4a32f4cbc3064ba7207eb0dde0d8c1562846", "best_bid": "0.86", "best_ask": "0.88"}], "timestamp": "1769384241480", "event_type": "price_change"}}
{"_local_timestamp": "2026-01-25T23:37:22.968654+00:00", "data": {"market": "0x1c90e1383b8664103731bacc42ba86dff9c1582b8982f0ec02ba6aa255540dec", "price_changes": [{"asset_id": "97961254854749379702593191658896132704622945558274415067651430934438719211772", "price": "0.14", "size": "67.26", "side": "SELL", "hash": "32148eecd47539ed7caded5262f8137d4840ca3e", "best_bid": "0.12", "best_ask": "0.14"}, {"asset_id": "10824614737277384579120931547716737694062714916890575016613469671599992760641", "price": "0.86", "size": "67.26", "side": "BUY", "hash": "d6a0755e98a63b23228c199b2474689c98d1e68b", "best_bid": "0.86", "best_ask": "0.88"}], "timestamp": "1769384242899", "event_type": "price_change"}}
{"_local_timestamp": "2026-01-25T23:37:23.730221+00:00", "data": {"market": "0x1c90e1383b8664103731bacc42ba86dff9c1582b8982f0ec02ba6aa255540dec", "price_changes": [{"asset_id": "97961254854749379702593191658896132704622945558274415067651430934438719211772", "price": "0.14", "size": "91.67", "side": "SELL", "hash": "2338066e28db5fac1e166344f3d313c9643d4f63", "best_bid": "0.12", "best_ask": "0.14"}, {"asset_id": "10824614737277384579120931547716737694062714916890575016613469671599992760641", "price": "0.86", "size": "91.67", "side": "BUY", "hash": "1d96cf9591df0887952888ce67672aad70f680a4", "best_bid": "0.86", "best_ask": "0.88"}], "timestamp": "1769384243656", "event_type": "price_change"}}
{"_local_timestamp": "2026-01-25T23:37:26.809580+00:00", "data": {"market": "0x1c90e1383b8664103731bacc42ba86dff9c1582b8982f0ec02ba6aa255540dec", "price_changes": [{"asset_id": "97961254854749379702593191658896132704622945558274415067651430934438719211772", "price": "0.14", "size": "67.26", "side": "SELL", "hash": "0a33f4d1a432ce91ac2d10b2a7c3d88b96cdbb9b", "best_bid": "0.12", "best_ask": "0.14"}, {"asset_id": "10824614737277384579120931547716737694062714916890575016613469671599992760641", "price": "0.86", "size": "67.26", "side": "BUY", "hash": "cc6ca2615a0c7e897d62af05e076855d22d2e332", "best_bid": "0.86", "best_ask": "0.88"}], "timestamp": "1769384246739", "event_type": "price_change"}}
{"_local_timestamp": "2026-01-25T23:37:28.107927+00:00", "data": {"market": "0x1c90e1383b8664103731bacc42ba86dff9c1582b8982f0ec02ba6aa255540dec", "price_changes": [{"asset_id": "97961254854749379702593191658896132704622945558274415067651430934438719211772", "price": "0.14", "size": "91.67", "side": "SELL", "hash": "e1bdcc8844cb6cca26e3eb3ab53c28a1f3e13e44", "best_bid": "0.12", "best_ask": "0.14"}, {"asset_id": "10824614737277384579120931547716737694062714916890575016613469671599992760641", "price": "0.86", "size": "91.67", "side": "BUY", "hash": "a085fe3ae566be05f250601e0b13b4b8bbc89753", "best_bid": "0.86", "best_ask": "0.88"}], "timestamp": "1769384248032", "event_type": "price_change"}}
{"_local_timestamp": "2026-01-25T23:37:30.113262+00:00", "data": {"market": "0x1c90e1383b8664103731bacc42ba86dff9c1582b8982f0ec02ba6aa255540dec", "price_changes": [{"asset_id": "97961254854749379702593191658896132704622945558274415067651430934438719211772", "price": "0.14", "size": "67.26", "side": "SELL", "hash": "cd3121a45c1e8262712518a3c6be016fc357f0bc", "best_bid": "0.12", "best_ask": "0.14"}, {"asset_id": "10824614737277384579120931547716737694062714916890575016613469671599992760641", "price": "0.86", "size": "67.26", "side": "BUY", "hash": "b84375d85ee1661a53a3113be4a0a844b6f99f39", "best_bid": "0.86", "best_ask": "0.88"}], "timestamp": "1769384250016", "event_type": "price_change"}}
{"_local_timestamp": "2026-01-25T23:37:32.887199+00:00", "data": {"market": "0x1c90e1383b8664103731bacc42ba86dff9c1582b8982f0ec02ba6aa255540dec", "price_changes": [{"asset_id": "97961254854749379702593191658896132704622945558274415067651430934438719211772", "price": "0.14", "size": "91.67", "side": "SELL", "hash": "c63b76e1b4cc8102f76cf782b18e0b05ada97bd9", "best_bid": "0.12", "best_ask": "0.14"}, {"asset_id": "10824614737277384579120931547716737694062714916890575016613469671599992760641", "price": "0.86", "size": "91.67", "side": "BUY", "hash": "9a5cc2e44b03ca6b451355338863ab1d882e5595", "best_bid": "0.86", "best_ask": "0.88"}], "timestamp": "1769384252816", "event_type": "price_change"}}
{"_local_timestamp": "2026-01-25T23:37:33.609413+00:00", "data": {"market": "0x1c90e1383b8664103731bacc42ba86dff9c1582b8982f0ec02ba6aa255540dec", "price_changes": [{"asset_id": "97961254854749379702593191658896132704622945558274415067651430934438719211772", "price": "0.14", "size": "67.26", "side": "SELL", "hash": "f06d608197302667c7546c3e04e18bf4cd714b0d", "best_bid": "0.12", "best_ask": "0.14"}, {"asset_id": "10824614737277384579120931547716737694062714916890575016613469671599992760641", "price": "0.86", "size": "67.26", "side": "BUY", "hash": "1e2c5678723e55b25c99902a5531c085802f8826", "best_bid": "0.86", "best_ask": "0.88"}], "timestamp": "1769384253529", "event_type": "price_change"}}
{"_local_timestamp": "2026-01-25T23:37:35.125615+00:00", "data": {"market": "0x1c90e1383b8664103731bacc42ba86dff9c1582b8982f0ec02ba6aa255540dec", "price_changes": [{"asset_id": "97961254854749379702593191658896132704622945558274415067651430934438719211772", "price": "0.14", "size": "91.67", "side": "SELL", "hash": "5683cc224fd55a85849367e6111a29942c6698b2", "best_bid": "0.12", "best_ask": "0.14"}, {"asset_id": "10824614737277384579120931547716737694062714916890575016613469671599992760641", "price": "0.86", "size": "91.67", "side": "BUY", "hash": "4526b9d7f53f978cc734e871bb67396be874c203", "best_bid": "0.86", "best_ask": "0.88"}], "timestamp": "1769384255054", "event_type": "price_change"}}
{"_local_timestamp": "2026-01-25T23:37:35.221352+00:00", "data": {"market": "0x1c90e1383b8664103731bacc42ba86dff9c1582b8982f0ec02ba6aa255540dec", "price_changes": [{"asset_id": "10824614737277384579120931547716737694062714916890575016613469671599992760641", "price": "0.24", "size": "0", "side": "BUY", "hash": "5b6abb8546e7d71d4b346069c40656d4e047d00c", "best_bid": "0.86", "best_ask": "0.88"}, {"asset_id": "97961254854749379702593191658896132704622945558274415067651430934438719211772", "price": "0.76", "size": "0", "side": "SELL", "hash": "3fca2f8ed2b6865fd410479f8542eefc836e7612", "best_bid": "0.12", "best_ask": "0.14"}], "timestamp": "1769384255117", "event_type": "price_change"}}
{"_local_timestamp": "2026-01-25T23:37:37.176688+00:00", "data": {"market": "0x1c90e1383b8664103731bacc42ba86dff9c1582b8982f0ec02ba6aa255540dec", "price_changes": [{"asset_id": "97961254854749379702593191658896132704622945558274415067651430934438719211772", "price": "0.14", "size": "67.26", "side": "SELL", "hash": "6ede28827607c4f3004ff00d1d5c49d0be7c053c", "best_bid": "0.12", "best_ask": "0.14"}, {"asset_id": "10824614737277384579120931547716737694062714916890575016613469671599992760641", "price": "0.86", "size": "67.26", "side": "BUY", "hash": "1c13350707dcfdb83e7821d66129811a622b0f16", "best_bid": "0.86", "best_ask": "0.88"}], "timestamp": "1769384257101", "event_type": "price_change"}}
{"_local_timestamp": "2026-01-25T23:37:39.599550+00:00", "data": {"market": "0x1c90e1383b8664103731bacc42ba86dff9c1582b8982f0ec02ba6aa255540dec", "price_changes": [{"asset_id": "97961254854749379702593191658896132704622945558274415067651430934438719211772", "price": "0.14", "size": "91.67", "side": "SELL", "hash": "3973f66b5cc260ba7e186886da00dbf16adb1c9c", "best_bid": "0.12", "best_ask": "0.14"}, {"asset_id": "10824614737277384579120931547716737694062714916890575016613469671599992760641", "price": "0.86", "size": "91.67", "side": "BUY", "hash": "976235c1dab8ab77880be484052b7d49589a6d4e", "best_bid": "0.86", "best_ask": "0.88"}], "timestamp": "1769384259523", "event_type": "price_change"}}
{"_local_timestamp": "2026-01-25T23:37:41.128635+00:00", "data": {"market": "0x1c90e1383b8664103731bacc42ba86dff9c1582b8982f0ec02ba6aa255540dec", "price_changes": [{"asset_id": "97961254854749379702593191658896132704622945558274415067651430934438719211772", "price": "0.14", "size": "67.26", "side": "SELL", "hash": "214c0882f18a130383ddff23f8ffd93b93fd6e9a", "best_bid": "0.12", "best_ask": "0.14"}, {"asset_id": "10824614737277384579120931547716737694062714916890575016613469671599992760641", "price": "0.86", "size": "67.26", "side": "BUY", "hash": "db726a30165dfd5dc8c2128c601f73b6a1aee75e", "best_bid": "0.86", "best_ask": "0.88"}], "timestamp": "1769384260987", "event_type": "price_change"}}
{"_local_timestamp": "2026-01-25T23:37:42.206677+00:00", "data": {"market": "0x1c90e1383b8664103731bacc42ba86dff9c1582b8982f0ec02ba6aa255540dec", "price_changes": [{"asset_id": "97961254854749379702593191658896132704622945558274415067651430934438719211772", "price": "0.14", "size": "91.67", "side": "SELL", "hash": "f5529f1a0f8dc044d2efc6a6ee6d7e2ceff7bdb9", "best_bid": "0.12", "best_ask": "0.14"}, {"asset_id": "10824614737277384579120931547716737694062714916890575016613469671599992760641", "price": "0.86", "size": "91.67", "side": "BUY", "hash": "a20791488899d685fe5b05f36bdd82a12908013b", "best_bid": "0.86", "best_ask": "0.88"}], "timestamp": "1769384262087", "event_type": "price_change"}}
{"_local_timestamp": "2026-01-25T23:37:45.226313+00:00", "data": {"market": "0x1c90e1383b8664103731bacc42ba86dff9c1582b8982f0ec02ba6aa255540dec", "price_changes": [{"asset_id": "97961254854749379702593191658896132704622945558274415067651430934438719211772", "price": "0.14", "size": "67.26", "side": "SELL", "hash": "4687d4edb7e135c7b576ceb50e5fe6062699b952", "best_bid": "0.12", "best_ask": "0.14"}, {"asset_id": "10824614737277384579120931547716737694062714916890575016613469671599992760641", "price": "0.86", "size": "67.26", "side": "BUY", "hash": "54cadf9d8717411e43aff3f43442b184b256b1b1", "best_bid": "0.86", "best_ask": "0.88"}], "timestamp": "1769384265112", "event_type": "price_change"}}
{"_local_timestamp": "2026-01-25T23:37:47.312235+00:00", "data": {"market": "0x1c90e1383b8664103731bacc42ba86dff9c1582b8982f0ec02ba6aa255540dec", "price_changes": [{"asset_id": "97961254854749379702593191658896132704622945558274415067651430934438719211772", "price": "0.14", "size": "91.67", "side": "SELL", "hash": "3567455453c65e752b98d60cd37b455257a38788", "best_bid": "0.12", "best_ask": "0.14"}, {"asset_id": "10824614737277384579120931547716737694062714916890575016613469671599992760641", "price": "0.86", "size": "91.67", "side": "BUY", "hash": "b4f32bb9556ae84c1f437033f9180396fb59ad81", "best_bid": "0.86", "best_ask": "0.88"}], "timestamp": "1769384267211", "event_type": "price_change"}}
{"_local_timestamp": "2026-01-25T23:37:48.555929+00:00", "data": {"market": "0x1c90e1383b8664103731bacc42ba86dff9c1582b8982f0ec02ba6aa255540dec", "price_changes": [{"asset_id": "97961254854749379702593191658896132704622945558274415067651430934438719211772", "price": "0.14", "size": "67.26", "side": "SELL", "hash": "eb4c6151dc3582721ce135a66ffd6a86de37c2c3", "best_bid": "0.12", "best_ask": "0.14"}, {"asset_id": "10824614737277384579120931547716737694062714916890575016613469671599992760641", "price": "0.86", "size": "67.26", "side": "BUY", "hash": "ade9769cf02cb2974afdb2e79d46dd3648199b09", "best_bid": "0.86", "best_ask": "0.88"}], "timestamp": "1769384268453", "event_type": "price_change"}}
{"_local_timestamp": "2026-01-25T23:37:49.487550+00:00", "data": {"market": "0x1c90e1383b8664103731bacc42ba86dff9c1582b8982f0ec02ba6aa255540dec", "price_changes": [{"asset_id": "97961254854749379702593191658896132704622945558274415067651430934438719211772", "price": "0.14", "size": "91.67", "side": "SELL", "hash": "2a3a5b7da1a9518f76c94b057b9681ccb192ebc5", "best_bid": "0.12", "best_ask": "0.14"}, {"asset_id": "10824614737277384579120931547716737694062714916890575016613469671599992760641", "price": "0.86", "size": "91.67", "side": "BUY", "hash": "a68b25742f94b1c66530bc018883c12e2f0aa395", "best_bid": "0.86", "best_ask": "0.88"}], "timestamp": "1769384269367", "event_type": "price_change"}}
{"_local_timestamp": "2026-01-25T23:37:52.450675+00:00", "data": {"market": "0x1c90e1383b8664103731bacc42ba86dff9c1582b8982f0ec02ba6aa255540dec", "price_changes": [{"asset_id": "97961254854749379702593191658896132704622945558274415067651430934438719211772", "price": "0.14", "size": "67.26", "side": "SELL", "hash": "2c964e0382a33a8fbda0258ea5bb8e9283aba04a", "best_bid": "0.12", "best_ask": "0.14"}, {"asset_id": "10824614737277384579120931547716737694062714916890575016613469671599992760641", "price": "0.86", "size": "67.26", "side": "BUY", "hash": "295cb91a30873d2cc9834d474f25d238d531b97d", "best_bid": "0.86", "best_ask": "0.88"}], "timestamp": "1769384272306", "event_type": "price_change"}}
{"_local_timestamp": "2026-01-25T23:37:54.118570+00:00", "data": {"market": "0x1c90e1383b8664103731bacc42ba86dff9c1582b8982f0ec02ba6aa255540dec", "price_changes": [{"asset_id": "97961254854749379702593191658896132704622945558274415067651430934438719211772", "price": "0.14", "size": "91.67", "side": "SELL", "hash": "9b20588c36e6e517a2ea380ee77d0889eb54896a", "best_bid": "0.12", "best_ask": "0.14"}, {"asset_id": "10824614737277384579120931547716737694062714916890575016613469671599992760641", "price": "0.86", "size": "91.67", "side": "BUY", "hash": "8733131557757aacf80ea79b50f62673bcf9624e", "best_bid": "0.86", "best_ask": "0.88"}], "timestamp": "1769384273979", "event_type": "price_change"}}
{"_local_timestamp": "2026-01-25T23:37:56.269831+00:00", "data": {"market": "0x1c90e1383b8664103731bacc42ba86dff9c1582b8982f0ec02ba6aa255540dec", "price_changes": [{"asset_id": "97961254854749379702593191658896132704622945558274415067651430934438719211772", "price": "0.14", "size": "67.26", "side": "SELL", "hash": "1b5b91f39f6dbce08057c47d935f2f1ad6828d87", "best_bid": "0.12", "best_ask": "0.14"}, {"asset_id": "10824614737277384579120931547716737694062714916890575016613469671599992760641", "price": "0.86", "size": "67.26", "side": "BUY", "hash": "d921afe660d87ab81cd3fcb47870b1e96cc2961d", "best_bid": "0.86", "best_ask": "0.88"}], "timestamp": "1769384276146", "event_type": "price_change"}}
{"_local_timestamp": "2026-01-25T23:37:59.157418+00:00", "data": {"market": "0x1c90e1383b8664103731bacc42ba86dff9c1582b8982f0ec02ba6aa255540dec", "price_changes": [{"asset_id": "97961254854749379702593191658896132704622945558274415067651430934438719211772", "price": "0.14", "size": "91.67", "side": "SELL", "hash": "6b6792a55484a6a1580771a4fb468220ae9efb0c", "best_bid": "0.12", "best_ask": "0.14"}, {"asset_id": "10824614737277384579120931547716737694062714916890575016613469671599992760641", "price": "0.86", "size": "91.67", "side": "BUY", "hash": "b1b4ec1c5116437b49b6f4aaad206b03416b6a38", "best_bid": "0.86", "best_ask": "0.88"}], "timestamp": "1769384279013", "event_type": "price_change"}}
{"_local_timestamp": "2026-01-25T23:38:00.548734+00:00", "data": {"market": "0x1c90e1383b8664103731bacc42ba86dff9c1582b8982f0ec02ba6aa255540dec", "price_changes": [{"asset_id": "97961254854749379702593191658896132704622945558274415067651430934438719211772", "price": "0.14", "size": "67.26", "side": "SELL", "hash": "1b93930c19894735440343fedd6092034edc7c52", "best_bid": "0.12", "best_ask": "0.14"}, {"asset_id": "10824614737277384579120931547716737694062714916890575016613469671599992760641", "price": "0.86", "size": "67.26", "side": "BUY", "hash": "ba2dc4787c9629067d288a1fd39dd2fa38255f5a", "best_bid": "0.86", "best_ask": "0.88"}], "timestamp": "1769384280431", "event_type": "price_change"}}
{"_local_timestamp": "2026-01-25T23:38:01.161513+00:00", "data": {"market": "0x1c90e1383b8664103731bacc42ba86dff9c1582b8982f0ec02ba6aa255540dec", "price_changes": [{"asset_id": "97961254854749379702593191658896132704622945558274415067651430934438719211772", "price": "0.14", "size": "91.67", "side": "SELL", "hash": "7533483cde372519e90b35109bf238c39457cf28", "best_bid": "0.12", "best_ask": "0.14"}, {"asset_id": "10824614737277384579120931547716737694062714916890575016613469671599992760641", "price": "0.86", "size": "91.67", "side": "BUY", "hash": "3422cf2bbe91f6aa1d49c4bba2574e71d853adb4", "best_bid": "0.86", "best_ask": "0.88"}], "timestamp": "1769384281036", "event_type": "price_change"}}
{"_local_timestamp": "2026-01-25T23:38:04.231530+00:00", "data": {"market": "0x1c90e1383b8664103731bacc42ba86dff9c1582b8982f0ec02ba6aa255540dec", "price_changes": [{"asset_id": "97961254854749379702593191658896132704622945558274415067651430934438719211772", "price": "0.14", "size": "67.26", "side": "SELL", "hash": "b9af63aaeaf2ce5ca0c65182e9b2d32b581ddf02", "best_bid": "0.12", "best_ask": "0.14"}, {"asset_id": "10824614737277384579120931547716737694062714916890575016613469671599992760641", "price": "0.86", "size": "67.26", "side": "BUY", "hash": "1ae25ebc9f4b62dbf2fcb384b308dce6a61908ac", "best_bid": "0.86", "best_ask": "0.88"}], "timestamp": "1769384284071", "event_type": "price_change"}}
{"_local_timestamp": "2026-01-25T23:38:05.512976+00:00", "data": {"market": "0x1c90e1383b8664103731bacc42ba86dff9c1582b8982f0ec02ba6aa255540dec", "price_changes": [{"asset_id": "97961254854749379702593191658896132704622945558274415067651430934438719211772", "price": "0.14", "size": "91.67", "side": "SELL", "hash": "5f24b8383258c84c01514ab61ae9453e9f3b3ae3", "best_bid": "0.12", "best_ask": "0.14"}, {"asset_id": "10824614737277384579120931547716737694062714916890575016613469671599992760641", "price": "0.86", "size": "91.67", "side": "BUY", "hash": "059410a7dd75cef90663ee832073119bb1c78b19", "best_bid": "0.86", "best_ask": "0.88"}], "timestamp": "1769384285363", "event_type": "price_change"}}
{"_local_timestamp": "2026-01-25T23:38:07.927850+00:00", "data": {"market": "0x1c90e1383b8664103731bacc42ba86dff9c1582b8982f0ec02ba6aa255540dec", "price_changes": [{"asset_id": "97961254854749379702593191658896132704622945558274415067651430934438719211772", "price": "0.14", "size": "67.26", "side": "SELL", "hash": "e0fadaa2d85e598963c35d7c91983adb22ceaef1", "best_bid": "0.12", "best_ask": "0.14"}, {"asset_id": "10824614737277384579120931547716737694062714916890575016613469671599992760641", "price": "0.86", "size": "67.26", "side": "BUY", "hash": "0c85549777c034b6cbffbcfb72f9eb62d04264a4", "best_bid": "0.86", "best_ask": "0.88"}], "timestamp": "1769384287816", "event_type": "price_change"}}
{"_local_timestamp": "2026-01-25T23:38:08.975408+00:00", "data": {"market": "0x1c90e1383b8664103731bacc42ba86dff9c1582b8982f0ec02ba6aa255540dec", "price_changes": [{"asset_id": "10824614737277384579120931547716737694062714916890575016613469671599992760641", "price": "0.37", "size": "0", "side": "BUY", "hash": "d05af4ea58af6bfff74f221d8e24972a65919f29", "best_bid": "0.86", "best_ask": "0.88"}, {"asset_id": "97961254854749379702593191658896132704622945558274415067651430934438719211772", "price": "0.63", "size": "0", "side": "SELL", "hash": "94265af4ca23120df84c6ff7a3209dede5f77f8e", "best_bid": "0.12", "best_ask": "0.14"}], "timestamp": "1769384288899", "event_type": "price_change"}}
{"_local_timestamp": "2026-01-25T23:38:09.022406+00:00", "data": {"market": "0x1c90e1383b8664103731bacc42ba86dff9c1582b8982f0ec02ba6aa255540dec", "price_changes": [{"asset_id": "10824614737277384579120931547716737694062714916890575016613469671599992760641", "price": "0.37", "size": "5", "side": "BUY", "hash": "3a569cdbb357c5c009fd26a9117bac728efaec73", "best_bid": "0.86", "best_ask": "0.88"}, {"asset_id": "97961254854749379702593191658896132704622945558274415067651430934438719211772", "price": "0.63", "size": "5", "side": "SELL", "hash": "cf3a4716667786e09fb2885a6094640929a95eab", "best_bid": "0.12", "best_ask": "0.14"}], "timestamp": "1769384288949", "event_type": "price_change"}}
{"_local_timestamp": "2026-01-25T23:38:09.713830+00:00", "data": {"market": "0x1c90e1383b8664103731bacc42ba86dff9c1582b8982f0ec02ba6aa255540dec", "price_changes": [{"asset_id": "10824614737277384579120931547716737694062714916890575016613469671599992760641", "price": "0.22", "size": "2085.27", "side": "BUY", "hash": "090f61a65df4b2db26b594d12af3d224ce937af1", "best_bid": "0.86", "best_ask": "0.88"}, {"asset_id": "97961254854749379702593191658896132704622945558274415067651430934438719211772", "price": "0.78", "size": "2085.27", "side": "SELL", "hash": "e5af83dcb3d0fb64c9d2dae93c6251788876a14c", "best_bid": "0.12", "best_ask": "0.14"}], "timestamp": "1769384289612", "event_type": "price_change"}}
{"_local_timestamp": "2026-01-25T23:38:10.661767+00:00", "data": {"market": "0x1c90e1383b8664103731bacc42ba86dff9c1582b8982f0ec02ba6aa255540dec", "price_changes": [{"asset_id": "97961254854749379702593191658896132704622945558274415067651430934438719211772", "price": "0.14", "size": "91.67", "side": "SELL", "hash": "e9e678219d434a85a05d172f804241ffdf404271", "best_bid": "0.12", "best_ask": "0.14"}, {"asset_id": "10824614737277384579120931547716737694062714916890575016613469671599992760641", "price": "0.86", "size": "91.67", "side": "BUY", "hash": "152c8b2e3ed2e21c8721e105947ee957fc9fff25", "best_bid": "0.86", "best_ask": "0.88"}], "timestamp": "1769384290588", "event_type": "price_change"}}
{"_local_timestamp": "2026-01-25T23:38:11.406047+00:00", "data": {"market": "0x1c90e1383b8664103731bacc42ba86dff9c1582b8982f0ec02ba6aa255540dec", "price_changes": [{"asset_id": "97961254854749379702593191658896132704622945558274415067651430934438719211772", "price": "0.14", "size": "67.26", "side": "SELL", "hash": "e0208b67c5103d79ac5e32f6a20368031e88e289", "best_bid": "0.12", "best_ask": "0.14"}, {"asset_id": "10824614737277384579120931547716737694062714916890575016613469671599992760641", "price": "0.86", "size": "67.26", "side": "BUY", "hash": "0b33180206c032148dab1e26c4606c9f23b5f57a", "best_bid": "0.86", "best_ask": "0.88"}], "timestamp": "1769384291332", "event_type": "price_change"}}
{"_local_timestamp": "2026-01-25T23:38:12.957507+00:00", "data": {"market": "0x1c90e1383b8664103731bacc42ba86dff9c1582b8982f0ec02ba6aa255540dec", "price_changes": [{"asset_id": "97961254854749379702593191658896132704622945558274415067651430934438719211772", "price": "0.14", "size": "91.67", "side": "SELL", "hash": "5d4fcaa6b3fe7fc5cfddc06b392485cea085d937", "best_bid": "0.12", "best_ask": "0.14"}, {"asset_id": "10824614737277384579120931547716737694062714916890575016613469671599992760641", "price": "0.86", "size": "91.67", "side": "BUY", "hash": "6726538647724bd4462d0b0c05eed67fd72a1526", "best_bid": "0.86", "best_ask": "0.88"}], "timestamp": "1769384292886", "event_type": "price_change"}}
{"_local_timestamp": "2026-01-25T23:38:14.576944+00:00", "data": {"market": "0x1c90e1383b8664103731bacc42ba86dff9c1582b8982f0ec02ba6aa255540dec", "price_changes": [{"asset_id": "97961254854749379702593191658896132704622945558274415067651430934438719211772", "price": "0.14", "size": "67.26", "side": "SELL", "hash": "d88641b11fe1d693f54475c0655563c966d6a7e4", "best_bid": "0.12", "best_ask": "0.14"}, {"asset_id": "10824614737277384579120931547716737694062714916890575016613469671599992760641", "price": "0.86", "size": "67.26", "side": "BUY", "hash": "c666ef841b01726d56e637015fe95f4da5906527", "best_bid": "0.86", "best_ask": "0.88"}], "timestamp": "1769384294508", "event_type": "price_change"}}
{"_local_timestamp": "2026-01-25T23:38:17.997431+00:00", "data": {"market": "0x1c90e1383b8664103731bacc42ba86dff9c1582b8982f0ec02ba6aa255540dec", "price_changes": [{"asset_id": "97961254854749379702593191658896132704622945558274415067651430934438719211772", "price": "0.14", "size": "91.67", "side": "SELL", "hash": "9458fea6e32e5066cda7e80cc2ed88174e17ff0c", "best_bid": "0.12", "best_ask": "0.14"}, {"asset_id": "10824614737277384579120931547716737694062714916890575016613469671599992760641", "price": "0.86", "size": "91.67", "side": "BUY", "hash": "c4879607f1e82123acc6510f81c4fe1980362c43", "best_bid": "0.86", "best_ask": "0.88"}], "timestamp": "1769384297921", "event_type": "price_change"}}
{"_local_timestamp": "2026-01-25T23:38:21.252827+00:00", "data": {"market": "0x1c90e1383b8664103731bacc42ba86dff9c1582b8982f0ec02ba6aa255540dec", "price_changes": [{"asset_id": "10824614737277384579120931547716737694062714916890575016613469671599992760641", "price": "0.23", "size": "0", "side": "BUY", "hash": "7c7657fdf58255dff64c862f8d35121b1b973c1d", "best_bid": "0.86", "best_ask": "0.88"}, {"asset_id": "97961254854749379702593191658896132704622945558274415067651430934438719211772", "price": "0.77", "size": "0", "side": "SELL", "hash": "585eac05a372cf4ef1d1c4c0724ab263fa073351", "best_bid": "0.12", "best_ask": "0.14"}], "timestamp": "1769384301118", "event_type": "price_change"}}
{"_local_timestamp": "2026-01-25T23:38:21.573988+00:00", "data": {"market": "0x1c90e1383b8664103731bacc42ba86dff9c1582b8982f0ec02ba6aa255540dec", "price_changes": [{"asset_id": "10824614737277384579120931547716737694062714916890575016613469671599992760641", "price": "0.21", "size": "910", "side": "BUY", "hash": "1bc501c0d8dbc93c3677a08830e1af80db40caa5", "best_bid": "0.86", "best_ask": "0.88"}, {"asset_id": "97961254854749379702593191658896132704622945558274415067651430934438719211772", "price": "0.79", "size": "910", "side": "SELL", "hash": "582edc7dff7979ae9fcb5f7401a90fcc22a7d88c", "best_bid": "0.12", "best_ask": "0.14"}], "timestamp": "1769384301447", "event_type": "price_change"}}
{"_local_timestamp": "2026-01-25T23:38:21.701058+00:00", "data": {"market": "0x1c90e1383b8664103731bacc42ba86dff9c1582b8982f0ec02ba6aa255540dec", "price_changes": [{"asset_id": "97961254854749379702593191658896132704622945558274415067651430934438719211772", "price": "0.14", "size": "67.26", "side": "SELL", "hash": "4a5056eba5753c2edf4e09397ca1054eb4004fac", "best_bid": "0.12", "best_ask": "0.14"}, {"asset_id": "10824614737277384579120931547716737694062714916890575016613469671599992760641", "price": "0.86", "size": "67.26", "side": "BUY", "hash": "9b4782438bd7941496ad37bb326a53d33c848da9", "best_bid": "0.86", "best_ask": "0.88"}], "timestamp": "1769384301543", "event_type": "price_change"}}
{"_local_timestamp": "2026-01-25T23:38:22.315384+00:00", "data": {"market": "0x1c90e1383b8664103731bacc42ba86dff9c1582b8982f0ec02ba6aa255540dec", "price_changes": [{"asset_id": "97961254854749379702593191658896132704622945558274415067651430934438719211772", "price": "0.14", "size": "91.67", "side": "SELL", "hash": "55e3ea8c65abf283514801db0c9d8bb94ba6f4f8", "best_bid": "0.12", "best_ask": "0.14"}, {"asset_id": "10824614737277384579120931547716737694062714916890575016613469671599992760641", "price": "0.86", "size": "91.67", "side": "BUY", "hash": "a698c8810ce5644a1e4e97bb67272b5c8e1dba76", "best_bid": "0.86", "best_ask": "0.88"}], "timestamp": "1769384302244", "event_type": "price_change"}}
{"_local_timestamp": "2026-01-25T23:38:25.045023+00:00", "data": {"market": "0x1c90e1383b8664103731bacc42ba86dff9c1582b8982f0ec02ba6aa255540dec", "price_changes": [{"asset_id": "97961254854749379702593191658896132704622945558274415067651430934438719211772", "price": "0.14", "size": "67.26", "side": "SELL", "hash": "b4e730c17ec78071ffa79f8caaa2e1d9efc54f95", "best_bid": "0.12", "best_ask": "0.14"}, {"asset_id": "10824614737277384579120931547716737694062714916890575016613469671599992760641", "price": "0.86", "size": "67.26", "side": "BUY", "hash": "c5c90681e63fd70280aae7930de93df6c3105d88", "best_bid": "0.86", "best_ask": "0.88"}], "timestamp": "1769384304961", "event_type": "price_change"}}
{"_local_timestamp": "2026-01-25T23:38:27.188657+00:00", "data": {"market": "0x1c90e1383b8664103731bacc42ba86dff9c1582b8982f0ec02ba6aa255540dec", "price_changes": [{"asset_id": "97961254854749379702593191658896132704622945558274415067651430934438719211772", "price": "0.14", "size": "91.67", "side": "SELL", "hash": "44f659ae994de70be515a2728343f482d849e17a", "best_bid": "0.12", "best_ask": "0.14"}, {"asset_id": "10824614737277384579120931547716737694062714916890575016613469671599992760641", "price": "0.86", "size": "91.67", "side": "BUY", "hash": "273e123cda7c97c5de107976db7f5be727d8f098", "best_bid": "0.86", "best_ask": "0.88"}], "timestamp": "1769384307105", "event_type": "price_change"}}
{"_local_timestamp": "2026-01-25T23:38:28.427312+00:00", "data": {"market": "0x1c90e1383b8664103731bacc42ba86dff9c1582b8982f0ec02ba6aa255540dec", "price_changes": [{"asset_id": "97961254854749379702593191658896132704622945558274415067651430934438719211772", "price": "0.14", "size": "67.26", "side": "SELL", "hash": "6c927ba77e4981acbf5321d6c2eaa81a4bab5e73", "best_bid": "0.12", "best_ask": "0.14"}, {"asset_id": "10824614737277384579120931547716737694062714916890575016613469671599992760641", "price": "0.86", "size": "67.26", "side": "BUY", "hash": "2f5e749231856ab6914039fbdd9616e40f1686b7", "best_bid": "0.86", "best_ask": "0.88"}], "timestamp": "1769384308353", "event_type": "price_change"}}
{"_local_timestamp": "2026-01-25T23:38:29.777676+00:00", "data": {"market": "0x1c90e1383b8664103731bacc42ba86dff9c1582b8982f0ec02ba6aa255540dec", "price_changes": [{"asset_id": "97961254854749379702593191658896132704622945558274415067651430934438719211772", "price": "0.14", "size": "91.67", "side": "SELL", "hash": "dcf86a3c1b9462f93a887408f9e7ac9e4536530f", "best_bid": "0.12", "best_ask": "0.14"}, {"asset_id": "10824614737277384579120931547716737694062714916890575016613469671599992760641", "price": "0.86", "size": "91.67", "side": "BUY", "hash": "2b86cf30adb0cd1c42f4d2488d3cbe95f7b11872", "best_bid": "0.86", "best_ask": "0.88"}], "timestamp": "1769384309705", "event_type": "price_change"}}
{"_local_timestamp": "2026-01-25T23:38:31.445942+00:00", "data": {"market": "0x1c90e1383b8664103731bacc42ba86dff9c1582b8982f0ec02ba6aa255540dec", "price_changes": [{"asset_id": "97961254854749379702593191658896132704622945558274415067651430934438719211772", "price": "0.14", "size": "67.26", "side": "SELL", "hash": "7c1b66f02ee57111e4e5c9e840f7f96131ed8aff", "best_bid": "0.12", "best_ask": "0.14"}, {"asset_id": "10824614737277384579120931547716737694062714916890575016613469671599992760641", "price": "0.86", "size": "67.26", "side": "BUY", "hash": "4071e85a09fd48db8e81b5920f64265cdcfbf3e3", "best_bid": "0.86", "best_ask": "0.88"}], "timestamp": "1769384311362", "event_type": "price_change"}}
{"_local_timestamp": "2026-01-25T23:38:34.374977+00:00", "data": {"market": "0x1c90e1383b8664103731bacc42ba86dff9c1582b8982f0ec02ba6aa255540dec", "price_changes": [{"asset_id": "97961254854749379702593191658896132704622945558274415067651430934438719211772", "price": "0.14", "size": "91.67", "side": "SELL", "hash": "a8c43089694bf4ce7623210d377b2c79a3c2f1e2", "best_bid": "0.12", "best_ask": "0.14"}, {"asset_id": "10824614737277384579120931547716737694062714916890575016613469671599992760641", "price": "0.86", "size": "91.67", "side": "BUY", "hash": "a74b4de7653e290b0140df1564ee745365be2122", "best_bid": "0.86", "best_ask": "0.88"}], "timestamp": "1769384314307", "event_type": "price_change"}}
{"_local_timestamp": "2026-01-25T23:38:38.063544+00:00", "data": {"market": "0x1c90e1383b8664103731bacc42ba86dff9c1582b8982f0ec02ba6aa255540dec", "price_changes": [{"asset_id": "97961254854749379702593191658896132704622945558274415067651430934438719211772", "price": "0.14", "size": "67.26", "side": "SELL", "hash": "c1d12d0143f62c9ef919867afb3d89a0bddddf5b", "best_bid": "0.12", "best_ask": "0.14"}, {"asset_id": "10824614737277384579120931547716737694062714916890575016613469671599992760641", "price": "0.86", "size": "67.26", "side": "BUY", "hash": "d8ac9fd61019e60acb98adf828c16babc46fcb2f", "best_bid": "0.86", "best_ask": "0.88"}], "timestamp": "1769384317985", "event_type": "price_change"}}
{"_local_timestamp": "2026-01-25T23:38:39.029039+00:00", "data": {"market": "0x1c90e1383b8664103731bacc42ba86dff9c1582b8982f0ec02ba6aa255540dec", "price_changes": [{"asset_id": "97961254854749379702593191658896132704622945558274415067651430934438719211772", "price": "0.14", "size": "91.67", "side": "SELL", "hash": "dc8524f698d4a48c80b8fe1966ce27950c1ba48e", "best_bid": "0.12", "best_ask": "0.14"}, {"asset_id": "10824614737277384579120931547716737694062714916890575016613469671599992760641", "price": "0.86", "size": "91.67", "side": "BUY", "hash": "20b621d9ac8970a12c17ba854ae1544ea2f00f23", "best_bid": "0.86", "best_ask": "0.88"}], "timestamp": "1769384318955", "event_type": "price_change"}}
{"_local_timestamp": "2026-01-25T23:38:41.635299+00:00", "data": {"market": "0x1c90e1383b8664103731bacc42ba86dff9c1582b8982f0ec02ba6aa255540dec", "price_changes": [{"asset_id": "97961254854749379702593191658896132704622945558274415067651430934438719211772", "price": "0.14", "size": "67.26", "side": "SELL", "hash": "fefa7dc53a5bb14134a4d8c207138bc529be131e", "best_bid": "0.12", "best_ask": "0.14"}, {"asset_id": "10824614737277384579120931547716737694062714916890575016613469671599992760641", "price": "0.86", "size": "67.26", "side": "BUY", "hash": "903f40afbc599789ec1f54a784737c3a57114501", "best_bid": "0.86", "best_ask": "0.88"}], "timestamp": "1769384321540", "event_type": "price_change"}}
{"_local_timestamp": "2026-01-25T23:38:44.425977+00:00", "data": {"market": "0x1c90e1383b8664103731bacc42ba86dff9c1582b8982f0ec02ba6aa255540dec", "price_changes": [{"asset_id": "97961254854749379702593191658896132704622945558274415067651430934438719211772", "price": "0.14", "size": "91.67", "side": "SELL", "hash": "241019b9b7e49ada68e4bbc3a9009a59577dffe9", "best_bid": "0.12", "best_ask": "0.14"}, {"asset_id": "10824614737277384579120931547716737694062714916890575016613469671599992760641", "price": "0.86", "size": "91.67", "side": "BUY", "hash": "501c6898f21ded69d7b36f7720ac3feb951ba9f2", "best_bid": "0.86", "best_ask": "0.88"}], "timestamp": "1769384324353", "event_type": "price_change"}}
{"_local_timestamp": "2026-01-25T23:38:45.156313+00:00", "data": {"market": "0x1c90e1383b8664103731bacc42ba86dff9c1582b8982f0ec02ba6aa255540dec", "price_changes": [{"asset_id": "97961254854749379702593191658896132704622945558274415067651430934438719211772", "price": "0.14", "size": "67.26", "side": "SELL", "hash": "b61cce8d4f56b8777376fbd39f650204057d7d96", "best_bid": "0.12", "best_ask": "0.14"}, {"asset_id": "10824614737277384579120931547716737694062714916890575016613469671599992760641", "price": "0.86", "size": "67.26", "side": "BUY", "hash": "25710c33aff217d3d26cfec84a8a77cf9205c2c9", "best_bid": "0.86", "best_ask": "0.88"}], "timestamp": "1769384325077", "event_type": "price_change"}}
{"_local_timestamp": "2026-01-25T23:38:46.482131+00:00", "data": {"market": "0x1c90e1383b8664103731bacc42ba86dff9c1582b8982f0ec02ba6aa255540dec", "price_changes": [{"asset_id": "97961254854749379702593191658896132704622945558274415067651430934438719211772", "price": "0.14", "size": "91.67", "side": "SELL", "hash": "b5393862c256951457a62e34b0fccac4b4d70a13", "best_bid": "0.12", "best_ask": "0.14"}, {"asset_id": "10824614737277384579120931547716737694062714916890575016613469671599992760641", "price": "0.86", "size": "91.67", "side": "BUY", "hash": "97fb236219c7d17b6bc44b7271e662a212472945", "best_bid": "0.86", "best_ask": "0.88"}], "timestamp": "1769384326415", "event_type": "price_change"}}
{"_local_timestamp": "2026-01-25T23:38:48.962611+00:00", "data": {"market": "0x1c90e1383b8664103731bacc42ba86dff9c1582b8982f0ec02ba6aa255540dec", "price_changes": [{"asset_id": "97961254854749379702593191658896132704622945558274415067651430934438719211772", "price": "0.14", "size": "67.26", "side": "SELL", "hash": "60ce863ab9c0a01fe3d0ed6023802b55c7fad0a1", "best_bid": "0.12", "best_ask": "0.14"}, {"asset_id": "10824614737277384579120931547716737694062714916890575016613469671599992760641", "price": "0.86", "size": "67.26", "side": "BUY", "hash": "e674cebf7e0694068517413e2cfb1b5694f2b6b6", "best_bid": "0.86", "best_ask": "0.88"}], "timestamp": "1769384328887", "event_type": "price_change"}}
{"_local_timestamp": "2026-01-25T23:38:51.725456+00:00", "data": {"market": "0x1c90e1383b8664103731bacc42ba86dff9c1582b8982f0ec02ba6aa255540dec", "price_changes": [{"asset_id": "97961254854749379702593191658896132704622945558274415067651430934438719211772", "price": "0.14", "size": "91.67", "side": "SELL", "hash": "0f2811287f293d116e9930ee16d9f9cdce12c10c", "best_bid": "0.12", "best_ask": "0.14"}, {"asset_id": "10824614737277384579120931547716737694062714916890575016613469671599992760641", "price": "0.86", "size": "91.67", "side": "BUY", "hash": "331c20d83a2be7539cd545dab032ba2ffd7e7a82", "best_bid": "0.86", "best_ask": "0.88"}], "timestamp": "1769384331656", "event_type": "price_change"}}
{"_local_timestamp": "2026-01-25T23:38:52.051794+00:00", "data": {"market": "0x1c90e1383b8664103731bacc42ba86dff9c1582b8982f0ec02ba6aa255540dec", "price_changes": [{"asset_id": "97961254854749379702593191658896132704622945558274415067651430934438719211772", "price": "0.14", "size": "67.26", "side": "SELL", "hash": "6929e9b533113634be9595dfc5104043af2bb4fa", "best_bid": "0.12", "best_ask": "0.14"}, {"asset_id": "10824614737277384579120931547716737694062714916890575016613469671599992760641", "price": "0.86", "size": "67.26", "side": "BUY", "hash": "14921d6816f45170e17661a110e86f721068aef5", "best_bid": "0.86", "best_ask": "0.88"}], "timestamp": "1769384331977", "event_type": "price_change"}}
{"_local_timestamp": "2026-01-25T23:38:54.674089+00:00", "data": {"market": "0x1c90e1383b8664103731bacc42ba86dff9c1582b8982f0ec02ba6aa255540dec", "price_changes": [{"asset_id": "97961254854749379702593191658896132704622945558274415067651430934438719211772", "price": "0.14", "size": "91.67", "side": "SELL", "hash": "3f4f51659689db32d748b1706c0e82015d1c0599", "best_bid": "0.12", "best_ask": "0.14"}, {"asset_id": "10824614737277384579120931547716737694062714916890575016613469671599992760641", "price": "0.86", "size": "91.67", "side": "BUY", "hash": "dfc6913ce3198bc89f82d0d96b4c2933706240e0", "best_bid": "0.86", "best_ask": "0.88"}], "timestamp": "1769384334606", "event_type": "price_change"}}
{"_local_timestamp": "2026-01-25T23:38:55.564681+00:00", "data": {"market": "0x1c90e1383b8664103731bacc42ba86dff9c1582b8982f0ec02ba6aa255540dec", "price_changes": [{"asset_id": "97961254854749379702593191658896132704622945558274415067651430934438719211772", "price": "0.14", "size": "67.26", "side": "SELL", "hash": "bebfd6fe69ade1722bfc53d04c65aeeb42a5d50f", "best_bid": "0.12", "best_ask": "0.14"}, {"asset_id": "10824614737277384579120931547716737694062714916890575016613469671599992760641", "price": "0.86", "size": "67.26", "side": "BUY", "hash": "d32cca95542398116c2fee1d7bb826e6b1908e33", "best_bid": "0.86", "best_ask": "0.88"}], "timestamp": "1769384335494", "event_type": "price_change"}}
{"_local_timestamp": "2026-01-25T23:38:56.466259+00:00", "data": {"market": "0x1c90e1383b8664103731bacc42ba86dff9c1582b8982f0ec02ba6aa255540dec", "price_changes": [{"asset_id": "97961254854749379702593191658896132704622945558274415067651430934438719211772", "price": "0.14", "size": "91.67", "side": "SELL", "hash": "cc20cb53954e46e563bc599f8a74d2ddb3c35828", "best_bid": "0.12", "best_ask": "0.14"}, {"asset_id": "10824614737277384579120931547716737694062714916890575016613469671599992760641", "price": "0.86", "size": "91.67", "side": "BUY", "hash": "c8bed5ffc11dd80b442e94cd07a1da37e9c33361", "best_bid": "0.86", "best_ask": "0.88"}], "timestamp": "1769384336391", "event_type": "price_change"}}
{"_local_timestamp": "2026-01-25T23:38:58.378949+00:00", "data": {"market": "0x1c90e1383b8664103731bacc42ba86dff9c1582b8982f0ec02ba6aa255540dec", "price_changes": [{"asset_id": "10824614737277384579120931547716737694062714916890575016613469671599992760641", "price": "0.22", "size": "2035.27", "side": "BUY", "hash": "1e4731b31a479e6c6f6c0efc05975e8fb9ce9e58", "best_bid": "0.86", "best_ask": "0.88"}, {"asset_id": "97961254854749379702593191658896132704622945558274415067651430934438719211772", "price": "0.78", "size": "2035.27", "side": "SELL", "hash": "f13a8c8f016f2b9a79124697e3483678c1cc9ca9", "best_bid": "0.12", "best_ask": "0.14"}], "timestamp": "1769384338216", "event_type": "price_change"}}
{"_local_timestamp": "2026-01-25T23:38:58.806443+00:00", "data": {"market": "0x1c90e1383b8664103731bacc42ba86dff9c1582b8982f0ec02ba6aa255540dec", "price_changes": [{"asset_id": "10824614737277384579120931547716737694062714916890575016613469671599992760641", "price": "0.24", "size": "50", "side": "BUY", "hash": "234f3903f5bb837ef7dbbce3082d3b7c16681b28", "best_bid": "0.86", "best_ask": "0.88"}, {"asset_id": "97961254854749379702593191658896132704622945558274415067651430934438719211772", "price": "0.76", "size": "50", "side": "SELL", "hash": "6bf0c54ac90574741f90fd78e05463b372d2ce98", "best_bid": "0.12", "best_ask": "0.14"}], "timestamp": "1769384338644", "event_type": "price_change"}}
{"_local_timestamp": "2026-01-25T23:38:59.481799+00:00", "data": {"market": "0x1c90e1383b8664103731bacc42ba86dff9c1582b8982f0ec02ba6aa255540dec", "price_changes": [{"asset_id": "97961254854749379702593191658896132704622945558274415067651430934438719211772", "price": "0.14", "size": "67.26", "side": "SELL", "hash": "32d19ebe56e11e146794fdd34cca3e10184aaca3", "best_bid": "0.12", "best_ask": "0.14"}, {"asset_id": "10824614737277384579120931547716737694062714916890575016613469671599992760641", "price": "0.86", "size": "67.26", "side": "BUY", "hash": "6a5161979e86c4a634edfa09a51dcc0f2c5a9642", "best_bid": "0.86", "best_ask": "0.88"}], "timestamp": "1769384339384", "event_type": "price_change"}}
{"_local_timestamp": "2026-01-25T23:39:01.985868+00:00", "data": {"market": "0x1c90e1383b8664103731bacc42ba86dff9c1582b8982f0ec02ba6aa255540dec", "price_changes": [{"asset_id": "97961254854749379702593191658896132704622945558274415067651430934438719211772", "price": "0.14", "size": "91.67", "side": "SELL", "hash": "237cc35094006ece13209c909e8c3082803f4396", "best_bid": "0.12", "best_ask": "0.14"}, {"asset_id": "10824614737277384579120931547716737694062714916890575016613469671599992760641", "price": "0.86", "size": "91.67", "side": "BUY", "hash": "b15446b1aa59a777f1b36dd678d6f957ccad7b6b", "best_bid": "0.86", "best_ask": "0.88"}], "timestamp": "1769384341912", "event_type": "price_change"}}
{"_local_timestamp": "2026-01-25T23:39:03.060469+00:00", "data": {"market": "0x1c90e1383b8664103731bacc42ba86dff9c1582b8982f0ec02ba6aa255540dec", "price_changes": [{"asset_id": "97961254854749379702593191658896132704622945558274415067651430934438719211772", "price": "0.14", "size": "67.26", "side": "SELL", "hash": "acdb07dfa27423853165e39b706189e8172ef01c", "best_bid": "0.12", "best_ask": "0.14"}, {"asset_id": "10824614737277384579120931547716737694062714916890575016613469671599992760641", "price": "0.86", "size": "67.26", "side": "BUY", "hash": "95d4b4602419ca5363f9aa4b03348b0f6a647a19", "best_bid": "0.86", "best_ask": "0.88"}], "timestamp": "1769384342981", "event_type": "price_change"}}
{"_local_timestamp": "2026-01-25T23:39:04.290113+00:00", "data": {"market": "0x1c90e1383b8664103731bacc42ba86dff9c1582b8982f0ec02ba6aa255540dec", "price_changes": [{"asset_id": "97961254854749379702593191658896132704622945558274415067651430934438719211772", "price": "0.14", "size": "91.67", "side": "SELL", "hash": "67c8553287937c39ff96eb803c41795cc07de8bc", "best_bid": "0.12", "best_ask": "0.14"}, {"asset_id": "10824614737277384579120931547716737694062714916890575016613469671599992760641", "price": "0.86", "size": "91.67", "side": "BUY", "hash": "a91b1210eab193c5f6c0df856a7ea705fca55aca", "best_bid": "0.86", "best_ask": "0.88"}], "timestamp": "1769384344222", "event_type": "price_change"}}
{"_local_timestamp": "2026-01-25T23:39:06.421435+00:00", "data": {"market": "0x1c90e1383b8664103731bacc42ba86dff9c1582b8982f0ec02ba6aa255540dec", "price_changes": [{"asset_id": "97961254854749379702593191658896132704622945558274415067651430934438719211772", "price": "0.14", "size": "67.26", "side": "SELL", "hash": "34b396f0ee692225cdb4b228d326c01c2dcd29cd", "best_bid": "0.12", "best_ask": "0.14"}, {"asset_id": "10824614737277384579120931547716737694062714916890575016613469671599992760641", "price": "0.86", "size": "67.26", "side": "BUY", "hash": "e324723d04a6153ea18a5b2704a9a6d47f30fd18", "best_bid": "0.86", "best_ask": "0.88"}], "timestamp": "1769384346349", "event_type": "price_change"}}
{"_local_timestamp": "2026-01-25T23:39:08.689154+00:00", "data": {"market": "0x1c90e1383b8664103731bacc42ba86dff9c1582b8982f0ec02ba6aa255540dec", "price_changes": [{"asset_id": "97961254854749379702593191658896132704622945558274415067651430934438719211772", "price": "0.14", "size": "91.67", "side": "SELL", "hash": "240477d5d08ab2fe76b4159a8a2c1ac24aa903ba", "best_bid": "0.12", "best_ask": "0.14"}, {"asset_id": "10824614737277384579120931547716737694062714916890575016613469671599992760641", "price": "0.86", "size": "91.67", "side": "BUY", "hash": "97b98313888bbca6eb6066b9b7959cbbf2914401", "best_bid": "0.86", "best_ask": "0.88"}], "timestamp": "1769384348616", "event_type": "price_change"}}
{"_local_timestamp": "2026-01-25T23:39:10.160367+00:00", "data": {"market": "0x1c90e1383b8664103731bacc42ba86dff9c1582b8982f0ec02ba6aa255540dec", "price_changes": [{"asset_id": "97961254854749379702593191658896132704622945558274415067651430934438719211772", "price": "0.14", "size": "67.26", "side": "SELL", "hash": "b36a011863f7234d6a69700f921b6db3c3317e06", "best_bid": "0.12", "best_ask": "0.14"}, {"asset_id": "10824614737277384579120931547716737694062714916890575016613469671599992760641", "price": "0.86", "size": "67.26", "side": "BUY", "hash": "34eb0f620d8d958ee806ad66ab9ea581d1ff5205", "best_bid": "0.86", "best_ask": "0.88"}], "timestamp": "1769384350091", "event_type": "price_change"}}
{"_local_timestamp": "2026-01-25T23:39:10.933757+00:00", "data": {"market": "0x1c90e1383b8664103731bacc42ba86dff9c1582b8982f0ec02ba6aa255540dec", "price_changes": [{"asset_id": "97961254854749379702593191658896132704622945558274415067651430934438719211772", "price": "0.14", "size": "91.67", "side": "SELL", "hash": "bc963f9caf4b86777b69d2a26a547481216c1e02", "best_bid": "0.12", "best_ask": "0.14"}, {"asset_id": "10824614737277384579120931547716737694062714916890575016613469671599992760641", "price": "0.86", "size": "91.67", "side": "BUY", "hash": "e14383235fe113c55206572536d6bf11806edcd3", "best_bid": "0.86", "best_ask": "0.88"}], "timestamp": "1769384350863", "event_type": "price_change"}}
{"_local_timestamp": "2026-01-25T23:39:14.172096+00:00", "data": {"market": "0x1c90e1383b8664103731bacc42ba86dff9c1582b8982f0ec02ba6aa255540dec", "price_changes": [{"asset_id": "97961254854749379702593191658896132704622945558274415067651430934438719211772", "price": "0.14", "size": "67.26", "side": "SELL", "hash": "184757f44616e05dc43c07b75c49b6c964481711", "best_bid": "0.12", "best_ask": "0.14"}, {"asset_id": "10824614737277384579120931547716737694062714916890575016613469671599992760641", "price": "0.86", "size": "67.26", "side": "BUY", "hash": "49a2a4aebc9fbe21d4537cbe15f3678b806fcace", "best_bid": "0.86", "best_ask": "0.88"}], "timestamp": "1769384354043", "event_type": "price_change"}}
{"_local_timestamp": "2026-01-25T23:39:15.927503+00:00", "data": {"market": "0x1c90e1383b8664103731bacc42ba86dff9c1582b8982f0ec02ba6aa255540dec", "price_changes": [{"asset_id": "97961254854749379702593191658896132704622945558274415067651430934438719211772", "price": "0.14", "size": "91.67", "side": "SELL", "hash": "12bf8bf54cfd90f107e6d341b4f158a69a883dda", "best_bid": "0.12", "best_ask": "0.14"}, {"asset_id": "10824614737277384579120931547716737694062714916890575016613469671599992760641", "price": "0.86", "size": "91.67", "side": "BUY", "hash": "d57835a2caa25a4e54c1524910c496ef8a83de39", "best_bid": "0.86", "best_ask": "0.88"}], "timestamp": "1769384355856", "event_type": "price_change"}}
{"_local_timestamp": "2026-01-25T23:39:17.617774+00:00", "data": {"market": "0x1c90e1383b8664103731bacc42ba86dff9c1582b8982f0ec02ba6aa255540dec", "price_changes": [{"asset_id": "97961254854749379702593191658896132704622945558274415067651430934438719211772", "price": "0.14", "size": "67.26", "side": "SELL", "hash": "911a4e2ec65eefa0ced98b9914f52ee5348e3484", "best_bid": "0.12", "best_ask": "0.14"}, {"asset_id": "10824614737277384579120931547716737694062714916890575016613469671599992760641", "price": "0.86", "size": "67.26", "side": "BUY", "hash": "4b77d247a5c16cee54021894de4ba0a8bb5eeda3", "best_bid": "0.86", "best_ask": "0.88"}], "timestamp": "1769384357544", "event_type": "price_change"}}
{"_local_timestamp": "2026-01-25T23:39:20.873130+00:00", "data": {"market": "0x1c90e1383b8664103731bacc42ba86dff9c1582b8982f0ec02ba6aa255540dec", "price_changes": [{"asset_id": "97961254854749379702593191658896132704622945558274415067651430934438719211772", "price": "0.14", "size": "91.67", "side": "SELL", "hash": "e4a01d5169000fb296974872fcd9bf5170a06525", "best_bid": "0.12", "best_ask": "0.14"}, {"asset_id": "10824614737277384579120931547716737694062714916890575016613469671599992760641", "price": "0.86", "size": "91.67", "side": "BUY", "hash": "f88611735e04c70c01b36130e2832e2e2b17d7b1", "best_bid": "0.86", "best_ask": "0.88"}], "timestamp": "1769384360800", "event_type": "price_change"}}
{"_local_timestamp": "2026-01-25T23:39:21.446763+00:00", "data": {"market": "0x1c90e1383b8664103731bacc42ba86dff9c1582b8982f0ec02ba6aa255540dec", "price_changes": [{"asset_id": "97961254854749379702593191658896132704622945558274415067651430934438719211772", "price": "0.14", "size": "67.26", "side": "SELL", "hash": "efe9fd4fb92d500e1a9024e1c6502fd7642f5fe9", "best_bid": "0.12", "best_ask": "0.14"}, {"asset_id": "10824614737277384579120931547716737694062714916890575016613469671599992760641", "price": "0.86", "size": "67.26", "side": "BUY", "hash": "198768829c4341df65c960aa26c6e03b13ff5654", "best_bid": "0.86", "best_ask": "0.88"}], "timestamp": "1769384361378", "event_type": "price_change"}}
{"_local_timestamp": "2026-01-25T23:39:22.396302+00:00", "data": {"market": "0x1c90e1383b8664103731bacc42ba86dff9c1582b8982f0ec02ba6aa255540dec", "price_changes": [{"asset_id": "10824614737277384579120931547716737694062714916890575016613469671599992760641", "price": "0.21", "size": "810", "side": "BUY", "hash": "44c2dc8ca31191163949174ae532ac45e67e3896", "best_bid": "0.86", "best_ask": "0.88"}, {"asset_id": "97961254854749379702593191658896132704622945558274415067651430934438719211772", "price": "0.79", "size": "810", "side": "SELL", "hash": "59c4e300bcefc0b6fd30be8b01c2cbbbd9e460d6", "best_bid": "0.12", "best_ask": "0.14"}], "timestamp": "1769384362205", "event_type": "price_change"}}
{"_local_timestamp": "2026-01-25T23:39:22.942512+00:00", "data": {"market": "0x1c90e1383b8664103731bacc42ba86dff9c1582b8982f0ec02ba6aa255540dec", "price_changes": [{"asset_id": "10824614737277384579120931547716737694062714916890575016613469671599992760641", "price": "0.24", "size": "150", "side": "BUY", "hash": "2ea49392fbb7a91b9c2e0272b3a21c88bcb38563", "best_bid": "0.86", "best_ask": "0.88"}, {"asset_id": "97961254854749379702593191658896132704622945558274415067651430934438719211772", "price": "0.76", "size": "150", "side": "SELL", "hash": "9ca0d08eb15c92f04624fcc7112b41335481d758", "best_bid": "0.12", "best_ask": "0.14"}], "timestamp": "1769384362723", "event_type": "price_change"}}
{"_local_timestamp": "2026-01-25T23:39:23.102603+00:00", "data": {"market": "0x1c90e1383b8664103731bacc42ba86dff9c1582b8982f0ec02ba6aa255540dec", "price_changes": [{"asset_id": "97961254854749379702593191658896132704622945558274415067651430934438719211772", "price": "0.14", "size": "91.67", "side": "SELL", "hash": "969fafbf3bacb4bbbe0d3a584a3c3c254844e6f5", "best_bid": "0.12", "best_ask": "0.14"}, {"asset_id": "10824614737277384579120931547716737694062714916890575016613469671599992760641", "price": "0.86", "size": "91.67", "side": "BUY", "hash": "a9a029f9379f276950333fee360900db03c11e3b", "best_bid": "0.86", "best_ask": "0.88"}], "timestamp": "1769384362971", "event_type": "price_change"}}
{"_local_timestamp": "2026-01-25T23:39:24.906191+00:00", "data": {"market": "0x1c90e1383b8664103731bacc42ba86dff9c1582b8982f0ec02ba6aa255540dec", "price_changes": [{"asset_id": "97961254854749379702593191658896132704622945558274415067651430934438719211772", "price": "0.14", "size": "67.26", "side": "SELL", "hash": "f67a032ef46c7b2d097674f3f1a29234a0fe1263", "best_bid": "0.12", "best_ask": "0.14"}, {"asset_id": "10824614737277384579120931547716737694062714916890575016613469671599992760641", "price": "0.86", "size": "67.26", "side": "BUY", "hash": "7a9869348b62eeba9e729a6f835ec59e6aac88a2", "best_bid": "0.86", "best_ask": "0.88"}], "timestamp": "1769384364835", "event_type": "price_change"}}
{"_local_timestamp": "2026-01-25T23:39:27.717031+00:00", "data": {"market": "0x1c90e1383b8664103731bacc42ba86dff9c1582b8982f0ec02ba6aa255540dec", "price_changes": [{"asset_id": "97961254854749379702593191658896132704622945558274415067651430934438719211772", "price": "0.14", "size": "91.67", "side": "SELL", "hash": "5d61fb69e2d8ab52f0fb98253db344f11fd8b1d0", "best_bid": "0.12", "best_ask": "0.14"}, {"asset_id": "10824614737277384579120931547716737694062714916890575016613469671599992760641", "price": "0.86", "size": "91.67", "side": "BUY", "hash": "7339a4c638d762c8e5d61f2e8f8a44a050da6ca5", "best_bid": "0.86", "best_ask": "0.88"}], "timestamp": "1769384367638", "event_type": "price_change"}}
{"_local_timestamp": "2026-01-25T23:39:28.586545+00:00", "data": {"market": "0x1c90e1383b8664103731bacc42ba86dff9c1582b8982f0ec02ba6aa255540dec", "price_changes": [{"asset_id": "97961254854749379702593191658896132704622945558274415067651430934438719211772", "price": "0.14", "size": "67.26", "side": "SELL", "hash": "805949cbe8dd1ab5f34bbe9bc946f52cb909a704", "best_bid": "0.12", "best_ask": "0.14"}, {"asset_id": "10824614737277384579120931547716737694062714916890575016613469671599992760641", "price": "0.86", "size": "67.26", "side": "BUY", "hash": "ed1cd0d9c77d00f4185c66cf8ed5eee0e1ad4d63", "best_bid": "0.86", "best_ask": "0.88"}], "timestamp": "1769384368501", "event_type": "price_change"}}
{"_local_timestamp": "2026-01-25T23:39:30.566568+00:00", "data": {"market": "0x1c90e1383b8664103731bacc42ba86dff9c1582b8982f0ec02ba6aa255540dec", "price_changes": [{"asset_id": "97961254854749379702593191658896132704622945558274415067651430934438719211772", "price": "0.14", "size": "91.67", "side": "SELL", "hash": "51640fb8d40ab93b69c0d50ee7bc548d8802cd57", "best_bid": "0.12", "best_ask": "0.14"}, {"asset_id": "10824614737277384579120931547716737694062714916890575016613469671599992760641", "price": "0.86", "size": "91.67", "side": "BUY", "hash": "a6680336dc2f9558cbd66ea1115a1fb5feb2f3ff", "best_bid": "0.86", "best_ask": "0.88"}], "timestamp": "1769384370489", "event_type": "price_change"}}
{"_local_timestamp": "2026-01-25T23:39:32.803462+00:00", "data": {"market": "0x1c90e1383b8664103731bacc42ba86dff9c1582b8982f0ec02ba6aa255540dec", "price_changes": [{"asset_id": "97961254854749379702593191658896132704622945558274415067651430934438719211772", "price": "0.14", "size": "67.26", "side": "SELL", "hash": "8f613420390165759126718e92c2f272ecae4cc0", "best_bid": "0.12", "best_ask": "0.14"}, {"asset_id": "10824614737277384579120931547716737694062714916890575016613469671599992760641", "price": "0.86", "size": "67.26", "side": "BUY", "hash": "5102f9ffb53ff671efc455dc877b718e8d660e75", "best_bid": "0.86", "best_ask": "0.88"}], "timestamp": "1769384372717", "event_type": "price_change"}}
{"_local_timestamp": "2026-01-25T23:39:35.320044+00:00", "data": {"market": "0x1c90e1383b8664103731bacc42ba86dff9c1582b8982f0ec02ba6aa255540dec", "price_changes": [{"asset_id": "97961254854749379702593191658896132704622945558274415067651430934438719211772", "price": "0.14", "size": "91.67", "side": "SELL", "hash": "a01f8dfef026b3a3611536f531c3866f2d16c337", "best_bid": "0.12", "best_ask": "0.14"}, {"asset_id": "10824614737277384579120931547716737694062714916890575016613469671599992760641", "price": "0.86", "size": "91.67", "side": "BUY", "hash": "c33575419ab6b1e1d17465c071b3743df0ea36ee", "best_bid": "0.86", "best_ask": "0.88"}], "timestamp": "1769384375235", "event_type": "price_change"}}
{"_local_timestamp": "2026-01-25T23:39:36.530610+00:00", "data": {"market": "0x1c90e1383b8664103731bacc42ba86dff9c1582b8982f0ec02ba6aa255540dec", "price_changes": [{"asset_id": "97961254854749379702593191658896132704622945558274415067651430934438719211772", "price": "0.14", "size": "67.26", "side": "SELL", "hash": "b54c86c7835404b46ceed46968cbe6d7fe5e9930", "best_bid": "0.12", "best_ask": "0.14"}, {"asset_id": "10824614737277384579120931547716737694062714916890575016613469671599992760641", "price": "0.86", "size": "67.26", "side": "BUY", "hash": "012d4b01a3a56fb17f094d2bef0f858a07644121", "best_bid": "0.86", "best_ask": "0.88"}], "timestamp": "1769384376452", "event_type": "price_change"}}
{"_local_timestamp": "2026-01-25T23:39:37.688235+00:00", "data": {"market": "0x1c90e1383b8664103731bacc42ba86dff9c1582b8982f0ec02ba6aa255540dec", "price_changes": [{"asset_id": "97961254854749379702593191658896132704622945558274415067651430934438719211772", "price": "0.14", "size": "91.67", "side": "SELL", "hash": "d690381ba2c8eff9e448c40c9c058ed408ba6caf", "best_bid": "0.12", "best_ask": "0.14"}, {"asset_id": "10824614737277384579120931547716737694062714916890575016613469671599992760641", "price": "0.86", "size": "91.67", "side": "BUY", "hash": "0bc4b840a401bdbb893bea5db8805b54387205a0", "best_bid": "0.86", "best_ask": "0.88"}], "timestamp": "1769384377617", "event_type": "price_change"}}
{"_local_timestamp": "2026-01-25T23:39:40.930740+00:00", "data": {"market": "0x1c90e1383b8664103731bacc42ba86dff9c1582b8982f0ec02ba6aa255540dec", "price_changes": [{"asset_id": "97961254854749379702593191658896132704622945558274415067651430934438719211772", "price": "0.14", "size": "67.26", "side": "SELL", "hash": "3f681da2420285fa8399cf6d04a7cb7a399a887e", "best_bid": "0.12", "best_ask": "0.14"}, {"asset_id": "10824614737277384579120931547716737694062714916890575016613469671599992760641", "price": "0.86", "size": "67.26", "side": "BUY", "hash": "151c1fb17bf1d24992a8a3052af8d850280b9828", "best_bid": "0.86", "best_ask": "0.88"}], "timestamp": "1769384380847", "event_type": "price_change"}}
{"_local_timestamp": "2026-01-25T23:39:42.223575+00:00", "data": {"market": "0x1c90e1383b8664103731bacc42ba86dff9c1582b8982f0ec02ba6aa255540dec", "price_changes": [{"asset_id": "97961254854749379702593191658896132704622945558274415067651430934438719211772", "price": "0.14", "size": "91.67", "side": "SELL", "hash": "6e78396b34fdd1728398bd923164d1210cfb32a2", "best_bid": "0.12", "best_ask": "0.14"}, {"asset_id": "10824614737277384579120931547716737694062714916890575016613469671599992760641", "price": "0.86", "size": "91.67", "side": "BUY", "hash": "109e9b40fd74b2106d972521d765c614c584b359", "best_bid": "0.86", "best_ask": "0.88"}], "timestamp": "1769384382155", "event_type": "price_change"}}
{"_local_timestamp": "2026-01-25T23:39:45.329894+00:00", "data": {"market": "0x1c90e1383b8664103731bacc42ba86dff9c1582b8982f0ec02ba6aa255540dec", "price_changes": [{"asset_id": "97961254854749379702593191658896132704622945558274415067651430934438719211772", "price": "0.14", "size": "67.26", "side": "SELL", "hash": "8432cf80e075520668fbb518454bc13cc11ef539", "best_bid": "0.12", "best_ask": "0.14"}, {"asset_id": "10824614737277384579120931547716737694062714916890575016613469671599992760641", "price": "0.86", "size": "67.26", "side": "BUY", "hash": "3adf9271121fd272940f5cfb01bff450dc4c6492", "best_bid": "0.86", "best_ask": "0.88"}], "timestamp": "1769384385254", "event_type": "price_change"}}
{"_local_timestamp": "2026-01-25T23:39:47.375177+00:00", "data": {"market": "0x1c90e1383b8664103731bacc42ba86dff9c1582b8982f0ec02ba6aa255540dec", "price_changes": [{"asset_id": "97961254854749379702593191658896132704622945558274415067651430934438719211772", "price": "0.14", "size": "91.67", "side": "SELL", "hash": "56b19cb5bbc88eea486e04b149d817e3472cfb32", "best_bid": "0.12", "best_ask": "0.14"}, {"asset_id": "10824614737277384579120931547716737694062714916890575016613469671599992760641", "price": "0.86", "size": "91.67", "side": "BUY", "hash": "3acc55c9e09e21ce20bed9dc9994991b59003476", "best_bid": "0.86", "best_ask": "0.88"}], "timestamp": "1769384387302", "event_type": "price_change"}}
{"_local_timestamp": "2026-01-25T23:39:49.226246+00:00", "data": {"market": "0x1c90e1383b8664103731bacc42ba86dff9c1582b8982f0ec02ba6aa255540dec", "price_changes": [{"asset_id": "97961254854749379702593191658896132704622945558274415067651430934438719211772", "price": "0.14", "size": "67.26", "side": "SELL", "hash": "5b12e47f8abe54966fd5e86b347cd4e7f714fcac", "best_bid": "0.12", "best_ask": "0.14"}, {"asset_id": "10824614737277384579120931547716737694062714916890575016613469671599992760641", "price": "0.86", "size": "67.26", "side": "BUY", "hash": "61a4b54fa92ddfe9ba8f8f0f91e283fcfe85a715", "best_bid": "0.86", "best_ask": "0.88"}], "timestamp": "1769384389158", "event_type": "price_change"}}
{"_local_timestamp": "2026-01-25T23:39:52.590154+00:00", "data": {"market": "0x1c90e1383b8664103731bacc42ba86dff9c1582b8982f0ec02ba6aa255540dec", "price_changes": [{"asset_id": "97961254854749379702593191658896132704622945558274415067651430934438719211772", "price": "0.14", "size": "91.67", "side": "SELL", "hash": "58185186ee1db0a29f6374a1a5580a0e62f8c225", "best_bid": "0.12", "best_ask": "0.14"}, {"asset_id": "10824614737277384579120931547716737694062714916890575016613469671599992760641", "price": "0.86", "size": "91.67", "side": "BUY", "hash": "53eee8d49a132a925b07b43e12c5b938ae8e2c7f", "best_bid": "0.86", "best_ask": "0.88"}], "timestamp": "1769384392521", "event_type": "price_change"}}
{"_local_timestamp": "2026-01-25T23:39:53.775699+00:00", "data": {"market": "0x1c90e1383b8664103731bacc42ba86dff9c1582b8982f0ec02ba6aa255540dec", "price_changes": [{"asset_id": "97961254854749379702593191658896132704622945558274415067651430934438719211772", "price": "0.14", "size": "67.26", "side": "SELL", "hash": "d30599c55e270e93e609a4425357fefa3ab1b0e6", "best_bid": "0.12", "best_ask": "0.14"}, {"asset_id": "10824614737277384579120931547716737694062714916890575016613469671599992760641", "price": "0.86", "size": "67.26", "side": "BUY", "hash": "5523cd2fe7c67623dde9ecd74a162cd2bfffdd37", "best_bid": "0.86", "best_ask": "0.88"}], "timestamp": "1769384393704", "event_type": "price_change"}}
{"_local_timestamp": "2026-01-25T23:39:54.747505+00:00", "data": {"market": "0x1c90e1383b8664103731bacc42ba86dff9c1582b8982f0ec02ba6aa255540dec", "price_changes": [{"asset_id": "97961254854749379702593191658896132704622945558274415067651430934438719211772", "price": "0.14", "size": "91.67", "side": "SELL", "hash": "6a33c11c9731f548f6f473bc1ba00dd3e471fe4b", "best_bid": "0.12", "best_ask": "0.14"}, {"asset_id": "10824614737277384579120931547716737694062714916890575016613469671599992760641", "price": "0.86", "size": "91.67", "side": "BUY", "hash": "84ae8007da1b2d0bacf92dd70d9dc5359649b3ee", "best_bid": "0.86", "best_ask": "0.88"}], "timestamp": "1769384394679", "event_type": "price_change"}}
{"_local_timestamp": "2026-01-25T23:39:58.100541+00:00", "data": {"market": "0x1c90e1383b8664103731bacc42ba86dff9c1582b8982f0ec02ba6aa255540dec", "price_changes": [{"asset_id": "97961254854749379702593191658896132704622945558274415067651430934438719211772", "price": "0.14", "size": "67.26", "side": "SELL", "hash": "831a12558bfe025eed989606fb4f8f1f0415529e", "best_bid": "0.12", "best_ask": "0.14"}, {"asset_id": "10824614737277384579120931547716737694062714916890575016613469671599992760641", "price": "0.86", "size": "67.26", "side": "BUY", "hash": "11c4189378580295d397473c1fb20fa9a9e9509b", "best_bid": "0.86", "best_ask": "0.88"}], "timestamp": "1769384397936", "event_type": "price_change"}}
{"_local_timestamp": "2026-01-25T23:40:00.299557+00:00", "data": {"market": "0x1c90e1383b8664103731bacc42ba86dff9c1582b8982f0ec02ba6aa255540dec", "price_changes": [{"asset_id": "97961254854749379702593191658896132704622945558274415067651430934438719211772", "price": "0.14", "size": "91.67", "side": "SELL", "hash": "9f0b8c59b3c723e86b9ce24932cde7f70a640812", "best_bid": "0.12", "best_ask": "0.14"}, {"asset_id": "10824614737277384579120931547716737694062714916890575016613469671599992760641", "price": "0.86", "size": "91.67", "side": "BUY", "hash": "f8533104cbdf59f2338b9ad853701dd30a97c655", "best_bid": "0.86", "best_ask": "0.88"}], "timestamp": "1769384400229", "event_type": "price_change"}}
{"_local_timestamp": "2026-01-25T23:40:01.760041+00:00", "data": {"market": "0x1c90e1383b8664103731bacc42ba86dff9c1582b8982f0ec02ba6aa255540dec", "price_changes": [{"asset_id": "97961254854749379702593191658896132704622945558274415067651430934438719211772", "price": "0.14", "size": "67.26", "side": "SELL", "hash": "fca3ee5df9f6a14ded706120326b919a969f4558", "best_bid": "0.12", "best_ask": "0.14"}, {"asset_id": "10824614737277384579120931547716737694062714916890575016613469671599992760641", "price": "0.86", "size": "67.26", "side": "BUY", "hash": "14cc851f2a8a8fd55005c2bdb00650582fd1c917", "best_bid": "0.86", "best_ask": "0.88"}], "timestamp": "1769384401683", "event_type": "price_change"}}
{"_local_timestamp": "2026-01-25T23:40:02.339685+00:00", "data": {"market": "0x1c90e1383b8664103731bacc42ba86dff9c1582b8982f0ec02ba6aa255540dec", "price_changes": [{"asset_id": "97961254854749379702593191658896132704622945558274415067651430934438719211772", "price": "0.14", "size": "91.67", "side": "SELL", "hash": "9d003579adfe8c0fb90abe2d9a2c104011eac5bd", "best_bid": "0.12", "best_ask": "0.14"}, {"asset_id": "10824614737277384579120931547716737694062714916890575016613469671599992760641", "price": "0.86", "size": "91.67", "side": "BUY", "hash": "647fb3bed571dbf2ca99a7b4b87162932d45f21e", "best_bid": "0.86", "best_ask": "0.88"}], "timestamp": "1769384402264", "event_type": "price_change"}}
{"_local_timestamp": "2026-01-25T23:40:05.676803+00:00", "data": {"market": "0x1c90e1383b8664103731bacc42ba86dff9c1582b8982f0ec02ba6aa255540dec", "price_changes": [{"asset_id": "97961254854749379702593191658896132704622945558274415067651430934438719211772", "price": "0.14", "size": "67.26", "side": "SELL", "hash": "eea4d18183b19c3db46df4f7df7341bbea1f28e0", "best_bid": "0.12", "best_ask": "0.14"}, {"asset_id": "10824614737277384579120931547716737694062714916890575016613469671599992760641", "price": "0.86", "size": "67.26", "side": "BUY", "hash": "9e22397006320882b004789245c4767c9f758a6f", "best_bid": "0.86", "best_ask": "0.88"}], "timestamp": "1769384405592", "event_type": "price_change"}}
{"_local_timestamp": "2026-01-25T23:40:06.872855+00:00", "data": {"market": "0x1c90e1383b8664103731bacc42ba86dff9c1582b8982f0ec02ba6aa255540dec", "price_changes": [{"asset_id": "97961254854749379702593191658896132704622945558274415067651430934438719211772", "price": "0.14", "size": "91.67", "side": "SELL", "hash": "d723a3a98af76355843fd1258f5fb007636fa07e", "best_bid": "0.12", "best_ask": "0.14"}, {"asset_id": "10824614737277384579120931547716737694062714916890575016613469671599992760641", "price": "0.86", "size": "91.67", "side": "BUY", "hash": "52af8415e975d6a1d1f8c0d545e9718175052ed5", "best_bid": "0.86", "best_ask": "0.88"}], "timestamp": "1769384406643", "event_type": "price_change"}}
{"_local_timestamp": "2026-01-25T23:40:08.075608+00:00", "data": {"market": "0x1c90e1383b8664103731bacc42ba86dff9c1582b8982f0ec02ba6aa255540dec", "price_changes": [{"asset_id": "97961254854749379702593191658896132704622945558274415067651430934438719211772", "price": "0.02", "size": "6.2", "side": "BUY", "hash": "af6a1641d84d10b40f40b19f04870bc40556ffef", "best_bid": "0.12", "best_ask": "0.14"}, {"asset_id": "10824614737277384579120931547716737694062714916890575016613469671599992760641", "price": "0.98", "size": "6.2", "side": "SELL", "hash": "a5461df093cba7808552f404c8a817b7c943de76", "best_bid": "0.86", "best_ask": "0.88"}], "timestamp": "1769384408000", "event_type": "price_change"}}
{"_local_timestamp": "2026-01-25T23:40:08.076478+00:00", "data": {"market": "0x1c90e1383b8664103731bacc42ba86dff9c1582b8982f0ec02ba6aa255540dec", "price_changes": [{"asset_id": "97961254854749379702593191658896132704622945558274415067651430934438719211772", "price": "0.09", "size": "110", "side": "BUY", "hash": "9781a86ccca70ef8482dbfc0c3eb7bfe0516ac3f", "best_bid": "0.12", "best_ask": "0.14"}, {"asset_id": "10824614737277384579120931547716737694062714916890575016613469671599992760641", "price": "0.91", "size": "110", "side": "SELL", "hash": "547a9634a708a03dcf71fa159fba969c97f392eb", "best_bid": "0.86", "best_ask": "0.88"}], "timestamp": "1769384408001", "event_type": "price_change"}}
{"_local_timestamp": "2026-01-25T23:40:08.083639+00:00", "data": {"market": "0x1c90e1383b8664103731bacc42ba86dff9c1582b8982f0ec02ba6aa255540dec", "price_changes": [{"asset_id": "97961254854749379702593191658896132704622945558274415067651430934438719211772", "price": "0.1", "size": "556.47", "side": "BUY", "hash": "33e136ed91e4631ab7eac1933eb39607124ba370", "best_bid": "0.12", "best_ask": "0.14"}, {"asset_id": "10824614737277384579120931547716737694062714916890575016613469671599992760641", "price": "0.9", "size": "556.47", "side": "SELL", "hash": "a371e289c0c226ac486363f480afdc27e8430bdf", "best_bid": "0.86", "best_ask": "0.88"}], "timestamp": "1769384408002", "event_type": "price_change"}}
{"_local_timestamp": "2026-01-25T23:40:08.102638+00:00", "data": {"market": "0x1c90e1383b8664103731bacc42ba86dff9c1582b8982f0ec02ba6aa255540dec", "price_changes": [{"asset_id": "97961254854749379702593191658896132704622945558274415067651430934438719211772", "price": "0.07", "size": "357.1", "side": "BUY", "hash": "8810d99eed18906d797c7e5ad25d65227b838499", "best_bid": "0.12", "best_ask": "0.14"}, {"asset_id": "10824614737277384579120931547716737694062714916890575016613469671599992760641", "price": "0.93", "size": "357.1", "side": "SELL", "hash": "629bc0432df40ac03b1350292bb0eda0981abd22", "best_bid": "0.86", "best_ask": "0.88"}], "timestamp": "1769384408005", "event_type": "price_change"}}
{"_local_timestamp": "2026-01-25T23:40:09.290154+00:00", "data": {"market": "0x1c90e1383b8664103731bacc42ba86dff9c1582b8982f0ec02ba6aa255540dec", "price_changes": [{"asset_id": "97961254854749379702593191658896132704622945558274415067651430934438719211772", "price": "0.14", "size": "67.26", "side": "SELL", "hash": "9f559e29c93281fe40bb615424f7bc45e5f1b653", "best_bid": "0.12", "best_ask": "0.14"}, {"asset_id": "10824614737277384579120931547716737694062714916890575016613469671599992760641", "price": "0.86", "size": "67.26", "side": "BUY", "hash": "2c6504d91d5f249bee740f86c513c8a35a49116a", "best_bid": "0.86", "best_ask": "0.88"}], "timestamp": "1769384409219", "event_type": "price_change"}}
{"_local_timestamp": "2026-01-25T23:40:11.580945+00:00", "data": {"market": "0x1c90e1383b8664103731bacc42ba86dff9c1582b8982f0ec02ba6aa255540dec", "price_changes": [{"asset_id": "97961254854749379702593191658896132704622945558274415067651430934438719211772", "price": "0.14", "size": "91.67", "side": "SELL", "hash": "5bc6afd256ba8079caad0fe42c52e738ad2db054", "best_bid": "0.12", "best_ask": "0.14"}, {"asset_id": "10824614737277384579120931547716737694062714916890575016613469671599992760641", "price": "0.86", "size": "91.67", "side": "BUY", "hash": "8fca180ad5500a733539ae6cc628b2a8e3c286fd", "best_bid": "0.86", "best_ask": "0.88"}], "timestamp": "1769384411511", "event_type": "price_change"}}
{"_local_timestamp": "2026-01-25T23:40:12.912266+00:00", "data": {"market": "0x1c90e1383b8664103731bacc42ba86dff9c1582b8982f0ec02ba6aa255540dec", "price_changes": [{"asset_id": "97961254854749379702593191658896132704622945558274415067651430934438719211772", "price": "0.14", "size": "67.26", "side": "SELL", "hash": "3b54afba3714aed01f653eb0ec19310f1a6786e3", "best_bid": "0.12", "best_ask": "0.14"}, {"asset_id": "10824614737277384579120931547716737694062714916890575016613469671599992760641", "price": "0.86", "size": "67.26", "side": "BUY", "hash": "2c5be7891b20cd23020ffea48d249997ba027053", "best_bid": "0.86", "best_ask": "0.88"}], "timestamp": "1769384412845", "event_type": "price_change"}}
{"_local_timestamp": "2026-01-25T23:40:13.818279+00:00", "data": {"market": "0x1c90e1383b8664103731bacc42ba86dff9c1582b8982f0ec02ba6aa255540dec", "price_changes": [{"asset_id": "97961254854749379702593191658896132704622945558274415067651430934438719211772", "price": "0.14", "size": "91.67", "side": "SELL", "hash": "c9a308ef5bf0422909669b2e9a0b784d3e92c7e9", "best_bid": "0.12", "best_ask": "0.14"}, {"asset_id": "10824614737277384579120931547716737694062714916890575016613469671599992760641", "price": "0.86", "size": "91.67", "side": "BUY", "hash": "7af69565ce91dba709448baf589d4a8950a26c2a", "best_bid": "0.86", "best_ask": "0.88"}], "timestamp": "1769384413749", "event_type": "price_change"}}
