{"_local_timestamp": "2026-01-25T23:33:27.857286+00:00", "data": [{"market": "0x765b8aa92705a707bef70a29afe26415334d89acdc4b39c6181cba487ce84c05", "asset_id": "7572089862132266277497190546594925217703296087729786738015583660130296798227", "timestamp": "1769383955499", "hash": "1125a5634e2455664b351a8b18724859429e1ccf", "bids": [{"price": "0.001", "size": "14439"}, {"price": "0.002", "size": "686.94"}, {"price": "0.003", "size": "213.75"}, {"price": "0.004", "size": "62.55"}, {"price": "0.011", "size": "100"}, {"price": "0.012", "size": "330.3"}, {"price": "0.013", "size": "466.66"}, {"price": "0.014", "size": "100"}, {"price": "0.015", "size": "53.33"}], "asks": [{"price": "0.999", "size": "3863.22"}, {"price": "0.998", "size": "1256.2"}, {"price": "0.997", "size": "1400"}, {"price": "0.996", "size": "10.71"}, {"price": "0.994", "size": "200"}, {"price": "0.99", "size": "9550"}, {"price": "0.989", "size": "5.43"}, {"price": "0.98", "size": "3700"}, {"price": "0.979", "size": "5.46"}, {"price": "0.96", "size": "625"}, {"price": "0.959", "size": "5.15"}, {"price": "0.95", "size": "30"}, {"price": "0.949", "size": "39"}, {"price": "0.92", "size": "425"}, {"price": "0.919", "size": "6.28"}, {"price": "0.9", "size": "560"}, {"price": "0.85", "size": "826.66"}, {"price": "0.84", "size": "400"}, {"price": "0.8", "size": "160"}, {"price": "0.799", "size": "5.19"}, {"price": "0.78", "size": "1000"}, {"price": "0.75", "size": "112"}, {"price": "0.7", "size": "186.66"}, {"price": "0.651", "size": "100"}, {"price": "0.65", "size": "68.57"}, {"price": "0.649", "size": "34"}, {"price": "0.6", "size": "175"}, {"price": "0.599", "size": "5"}, {"price": "0.355", "size": "100"}, {"price": "0.25", "size": "150"}, {"price": "0.249", "size": "20"}, {"price": "0.06", "size": "5"}, {"price": "0.059", "size": "57"}], "event_type": "book", "last_trade_price": ""}, {"market": "0x44140ac0504e812d05917c3214e38eef26a18ddcd64b2832a616c7cc0222c137", "asset_id": "24302570134861420001522487831207657461211578987386112721833748346595897717589", "timestamp": "1769383948369", "hash": "462755943ca9e2de09bdeb1aaedd562b5ae2bfbf", "bids": [{"price": "0.01", "size": "5510"}, {"price": "0.02", "size": "2200"}, {"price": "0.03", "size": "11.11"}, {"price": "0.05", "size": "20"}, {"price": "0.06", "size": "33"}, {"price": "0.09", "size": "1200"}, {"price": "0.14", "size": "842.85"}, {"price": "0.19", "size": "568.42"}, {"price": "0.24", "size": "266.66"}, {"price": "0.29", "size": "439.65"}, {"price": "0.33", "size": "72.72"}, {"price": "0.34", "size": "36"}, {"price": "0.38", "size": "127.63"}, {"price": "0.61", "size": "100"}, {"price": "0.63", "size": "108.28"}, {"price": "0.64", "size": "20"}, {"price": "0.83", "size": "50"}, {"price": "0.91", "size": "25"}, {"price": "0.94", "size": "4.55"}], "asks": [{"price": "0.99", "size": "3841.77"}, {"price": "0.98", "size": "1047.7"}, {"price": "0.97", "size": "30.93"}, {"price": "0.96", "size": "1023.94"}, {"price": "0.95", "size": "55"}], "event_type": "book", "last_trade_price": ""}, {"market": "0x44140ac0504e812d05917c3214e38eef26a18ddcd64b2832a616c7cc0222c137", "asset_id": "73574222258523377180162380054665411282462793585968406483594315204933879956564", "timestamp": "1769383948369", "hash": "f9ba4331341d85ba74f00cffa3fd3eb1b0bb308c", "bids": [{"price": "0.01", "size": "3841.77"}, {"price": "0.02", "size": "1047.7"}, {"price": "0.03", "size": "30.93"}, {"price": "0.04", "size": "1023.94"}, {"price": "0.05", "size": "55"}], "asks": [{"price": "0.99", "size": "5510"}, {"price": "0.98", "size": "2200"}, {"price": "0.97", "size": "11.11"}, {"price": "0.95", "size": "20"}, {"price": "0.94", "size": "33"}, {"price": "0.91", "size": "1200"}, {"price": "0.86", "size": "842.85"}, {"price": "0.81", "size": "568.42"}, {"price": "0.76", "size": "266.66"}, {"price": "0.71", "size": "439.65"}, {"price": "0.67", "size": "72.72"}, {"price": "0.66", "size": "36"}, {"price": "0.62", "size": "127.63"}, {"price": "0.39", "size": "100"}, {"price": "0.37", "size": "108.28"}, {"price": "0.36", "size": "20"}, {"price": "0.17", "size": "50"}, {"price": "0.09", "size": "25"}, {"price": "0.06", "size": "4.55"}], "event_type": "book", "last_trade_price": ""}, {"market": "0x4be208ebef12c4a31a44475ee6c50d16845918d56d9721af346e3075dbef197e", "asset_id": "40384302563834290793063484431892352880489425722482841375537167889452921217825", "timestamp": "1769383901921", "hash": "3557a82171e3b4010547d1a642984dc529e19ac0", "bids": [{"price": "0.001", "size": "14452.66"}, {"price": "0.002", "size": "706.76"}, {"price": "0.003", "size": "327.04"}, {"price": "0.004", "size": "382.57"}, {"price": "0.005", "size": "240"}, {"price": "0.006", "size": "75.93"}, {"price": "0.007", "size": "157.2"}, {"price": "0.008", "size": "126.66"}, {"price": "0.009", "size": "283"}], "asks": [{"price": "0.999", "size": "3863.22"}, {"price": "0.998", "size": "1256.19"}, {"price": "0.997", "size": "1400"}, {"price": "0.996", "size": "10.71"}, {"price": "0.994", "size": "200"}, {"price": "0.99", "size": "9550"}, {"price": "0.989", "size": "5.43"}, {"price": "0.98", "size": "3700"}, {"price": "0.979", "size": "5.46"}, {"price": "0.96", "size": "625"}, {"price": "0.959", "size": "5.15"}, {"price": "0.95", "size": "30"}, {"price": "0.949", "size": "39"}, {"price": "0.92", "size": "425"}, {"price": "0.919", "size": "6.28"}, {"price": "0.9", "size": "560"}, {"price": "0.85", "size": "776.66"}, {"price": "0.8", "size": "660"}, {"price": "0.799", "size": "5.19"}, {"price": "0.75", "size": "362"}, {"price": "0.7", "size": "186.66"}, {"price": "0.698", "size": "5"}, {"price": "0.65", "size": "68.57"}, {"price": "0.6", "size": "175"}, {"price": "0.599", "size": "25"}, {"price": "0.08", "size": "850"}, {"price": "0.06", "size": "5"}, {"price": "0.059", "size": "57"}], "event_type": "book", "last_trade_price": ""}, {"market": "0xf25a20da2ca057704975cd29bb742a97cfc089759d1c1161e1323a2cc98bb9f2", "asset_id": "53640757834467466216485370712527762791041006461643906643501013471745623378175", "timestamp": "1769383901926", "hash": "a6adf5845f01bc8734458020fb8dfff664e13794", "bids": [{"price": "0.001", "size": "3793.23"}, {"price": "0.002", "size": "1256.2"}, {"price": "0.003", "size": "1400"}, {"price": "0.004", "size": "10.72"}, {"price": "0.006", "size": "200"}, {"price": "0.01", "size": "9550"}, {"price": "0.011", "size": "5.44"}, {"price": "0.02", "size": "3700"}, {"price": "0.021", "size": "5.46"}, {"price": "0.04", "size": "625"}, {"price": "0.041", "size": "5.15"}, {"price": "0.05", "size": "30"}, {"price": "0.051", "size": "39"}, {"price": "0.08", "size": "425"}, {"price": "0.081", "size": "6.29"}, {"price": "0.1", "size": "560"}, {"price": "0.15", "size": "776.66"}, {"price": "0.2", "size": "660"}, {"price": "0.201", "size": "5.18"}, {"price": "0.25", "size": "362"}, {"price": "0.3", "size": "186.66"}, {"price": "0.349", "size": "150"}, {"price": "0.35", "size": "68.57"}, {"price": "0.4", "size": "50"}, {"price": "0.402", "size": "133"}, {"price": "0.403", "size": "5"}, {"price": "0.643", "size": "100"}, {"price": "0.644", "size": "20"}, {"price": "0.92", "size": "150"}, {"price": "0.937", "size": "52.72"}, {"price": "0.938", "size": "21"}], "asks": [{"price": "0.999", "size": "21347.86"}, {"price": "0.998", "size": "694.71"}, {"price": "0.997", "size": "301.87"}, {"price": "0.996", "size": "275"}, {"price": "0.995", "size": "373.51"}, {"price": "0.994", "size": "148.16"}, {"price": "0.993", "size": "7.67"}, {"price": "0.992", "size": "206.16"}, {"price": "0.99", "size": "10.5"}, {"price": "0.989", "size": "39.16"}], "event_type": "book", "last_trade_price": ""}, {"market": "0xf25a20da2ca057704975cd29bb742a97cfc089759d1c1161e1323a2cc98bb9f2", "asset_id": "46569543401181796902098192406569670746198909020178777906519890064700339458797", "timestamp": "1769383901926", "hash": "fa9577cfaea908c79ae339993eada441e42215ab", "bids": [{"price": "0.001", "size": "21347.86"}, {"price": "0.002", "size": "694.71"}, {"price": "0.003", "size": "301.87"}, {"price": "0.004", "size": "275"}, {"price": "0.005", "size": "373.51"}, {"price": "0.006", "size": "148.16"}, {"price": "0.007", "size": "7.67"}, {"price": "0.008", "size": "206.16"}, {"price": "0.01", "size": "10.5"}, {"price": "0.011", "size": "39.16"}], "asks": [{"price": "0.999", "size": "3793.23"}, {"price": "0.998", "size": "1256.2"}, {"price": "0.997", "size": "1400"}, {"price": "0.996", "size": "10.72"}, {"price": "0.994", "size": "200"}, {"price": "0.99", "size": "9550"}, {"price": "0.989", "size": "5.44"}, {"price": "0.98", "size": "3700"}, {"price": "0.979", "size": "5.46"}, {"price": "0.96", "size": "625"}, {"price": "0.959", "size": "5.15"}, {"price": "0.95", "size": "30"}, {"price": "0.949", "size": "39"}, {"price": "0.92", "size": "425"}, {"price": "0.919", "size": "6.29"}, {"price": "0.9", "size": "560"}, {"price": "0.85", "size": "776.66"}, {"price": "0.8", "size": "660"}, {"price": "0.799", "size": "5.18"}, {"price": "0.75", "size": "362"}, {"price": "0.7", "size": "186.66"}, {"price": "0.651", "size": "150"}, {"price": "0.65", "size": "68.57"}, {"price": "0.6", "size": "50"}, {"price": "0.598", "size": "133"}, {"price": "0.597", "size": "5"}, {"price": "0.357", "size": "100"}, {"price": "0.356", "size": "20"}, {"price": "0.08", "size": "150"}, {"price": "0.063", "size": "52.72"}, {"price": "0.062", "size": "21"}], "event_type": "book", "last_trade_price": ""}, {"market": "0x4be208ebef12c4a31a44475ee6c50d16845918d56d9721af346e3075dbef197e", "asset_id": "44624470937661180249911132691369304324365682396836759395211838560647467358745", "timestamp": "1769383901921", "hash": "91a334a411f594a221b6e54a76a3b7fc96270b34", "bids": [{"price": "0.001", "size": "3863.22"}, {"price": "0.002", "size": "1256.19"}, {"price": "0.003", "size": "1400"}, {"price": "0.004", "size": "10.71"}, {"price": "0.006", "size": "200"}, {"price": "0.01", "size": "9550"}, {"price": "0.011", "size": "5.43"}, {"price": "0.02", "size": "3700"}, {"price": "0.021", "size": "5.46"}, {"price": "0.04", "size": "625"}, {"price": "0.041", "size": "5.15"}, {"price": "0.05", "size": "30"}, {"price": "0.051", "size": "39"}, {"price": "0.08", "size": "425"}, {"price": "0.081", "size": "6.28"}, {"price": "0.1", "size": "560"}, {"price": "0.15", "size": "776.66"}, {"price": "0.2", "size": "660"}, {"price": "0.201", "size": "5.19"}, {"price": "0.25", "size": "362"}, {"price": "0.3", "size": "186.66"}, {"price": "0.302", "size": "5"}, {"price": "0.35", "size": "68.57"}, {"price": "0.4", "size": "175"}, {"price": "0.401", "size": "25"}, {"price": "0.92", "size": "850"}, {"price": "0.94", "size": "5"}, {"price": "0.941", "size": "57"}], "asks": [{"price": "0.999", "size": "14452.66"}, {"price": "0.998", "size": "706.76"}, {"price": "0.997", "size": "327.04"}, {"price": "0.996", "size": "382.57"}, {"price": "0.995", "size": "240"}, {"price": "0.994", "size": "75.93"}, {"price": "0.993", "size": "157.2"}, {"price": "0.992", "size": "126.66"}, {"price": "0.991", "size": "283"}], "event_type": "book", "last_trade_price": ""}, {"market": "0x928bccc135016fa2cafe8d4f0ba037d9a5a48f326dd1e30975dcb194586557a9", "asset_id": "27158678906746497110330606113923753280208777834993320994787156825009294890573", "timestamp": "1769383901917", "hash": "9138ceaaa62015222b51c35e8671e6b2c98b4af7", "bids": [{"price": "0.001", "size": "3828.19"}, {"price": "0.002", "size": "1256.17"}, {"price": "0.003", "size": "1400"}, {"price": "0.004", "size": "10.67"}, {"price": "0.006", "size": "200"}, {"price": "0.01", "size": "9550"}, {"price": "0.011", "size": "5.41"}, {"price": "0.02", "size": "3700"}, {"price": "0.021", "size": "5.44"}, {"price": "0.04", "size": "625"}, {"price": "0.041", "size": "5.13"}, {"price": "0.05", "size": "30"}, {"price": "0.051", "size": "39"}, {"price": "0.08", "size": "425"}, {"price": "0.081", "size": "6.27"}, {"price": "0.1", "size": "560"}, {"price": "0.15", "size": "776.66"}, {"price": "0.2", "size": "660"}, {"price": "0.201", "size": "5.2"}, {"price": "0.25", "size": "362"}, {"price": "0.251", "size": "181"}, {"price": "0.3", "size": "186.66"}, {"price": "0.35", "size": "68.57"}, {"price": "0.4", "size": "175"}, {"price": "0.401", "size": "20"}, {"price": "0.402", "size": "5"}, {"price": "0.91", "size": "855"}, {"price": "0.946", "size": "52.72"}, {"price": "0.992", "size": "24.36"}], "asks": [{"price": "0.999", "size": "20355"}, {"price": "0.998", "size": "916"}, {"price": "0.995", "size": "945.38"}, {"price": "0.994", "size": "172.84"}], "event_type": "book", "last_trade_price": ""}, {"market": "0xa56d5e2b4e7b2953924a056ef8dd06dc522cca07452b022c2709e7657c5e77d1", "asset_id": "4516212715150974646881863469118521294538792708256862394143608505284110964795", "timestamp": "1769383901917", "hash": "dae0d9196b82b428e3fd306b878584d7e8472b2b", "bids": [{"price": "0.001", "size": "15439"}, {"price": "0.002", "size": "721.83"}, {"price": "0.003", "size": "604.43"}, {"price": "0.004", "size": "313.15"}, {"price": "0.005", "size": "300"}, {"price": "0.006", "size": "166.66"}, {"price": "0.007", "size": "66.66"}, {"price": "0.008", "size": "66.66"}], "asks": [{"price": "0.999", "size": "3863.2"}, {"price": "0.998", "size": "1256.18"}, {"price": "0.997", "size": "1400"}, {"price": "0.996", "size": "10.68"}, {"price": "0.994", "size": "200"}, {"price": "0.99", "size": "9550"}, {"price": "0.989", "size": "5.42"}, {"price": "0.98", "size": "3700"}, {"price": "0.979", "size": "5.44"}, {"price": "0.96", "size": "625"}, {"price": "0.959", "size": "5.13"}, {"price": "0.95", "size": "30"}, {"price": "0.949", "size": "39"}, {"price": "0.92", "size": "425"}, {"price": "0.919", "size": "6.27"}, {"price": "0.9", "size": "560"}, {"price": "0.85", "size": "776.66"}, {"price": "0.8", "size": "660"}, {"price": "0.799", "size": "5.2"}, {"price": "0.75", "size": "362"}, {"price": "0.7", "size": "186.66"}, {"price": "0.66", "size": "50"}, {"price": "0.65", "size": "68.57"}, {"price": "0.6", "size": "50"}, {"price": "0.599", "size": "100"}, {"price": "0.597", "size": "130"}, {"price": "0.379", "size": "112.61"}, {"price": "0.307", "size": "100"}, {"price": "0.306", "size": "25"}, {"price": "0.08", "size": "150"}, {"price": "0.06", "size": "5"}, {"price": "0.014", "size": "57"}], "event_type": "book", "last_trade_price": ""}, {"market": "0x765b8aa92705a707bef70a29afe26415334d89acdc4b39c6181cba487ce84c05", "asset_id": "110736404220942753069497130589444118893575413943575478177477380332405665833000", "timestamp": "1769383955499", "hash": "03f76fb771f05f6d9e3bf3b10e6c85350aac0ca7", "bids": [{"price": "0.001", "size": "3863.22"}, {"price": "0.002", "size": "1256.2"}, {"price": "0.003", "size": "1400"}, {"price": "0.004", "size": "10.71"}, {"price": "0.006", "size": "200"}, {"price": "0.01", "size": "9550"}, {"price": "0.011", "size": "5.43"}, {"price": "0.02", "size": "3700"}, {"price": "0.021", "size": "5.46"}, {"price": "0.04", "size": "625"}, {"price": "0.041", "size": "5.15"}, {"price": "0.05", "size": "30"}, {"price": "0.051", "size": "39"}, {"price": "0.08", "size": "425"}, {"price": "0.081", "size": "6.28"}, {"price": "0.1", "size": "560"}, {"price": "0.15", "size": "826.66"}, {"price": "0.16", "size": "400"}, {"price": "0.2", "size": "160"}, {"price": "0.201", "size": "5.19"}, {"price": "0.22", "size": "1000"}, {"price": "0.25", "size": "112"}, {"price": "0.3", "size": "186.66"}, {"price": "0.349", "size": "100"}, {"price": "0.35", "size": "68.57"}, {"price": "0.351", "size": "34"}, {"price": "0.4", "size": "175"}, {"price": "0.401", "size": "5"}, {"price": "0.645", "size": "100"}, {"price": "0.75", "size": "150"}, {"price": "0.751", "size": "20"}, {"price": "0.94", "size": "5"}, {"price": "0.941", "size": "57"}], "asks": [{"price": "0.999", "size": "14439"}, {"price": "0.998", "size": "686.94"}, {"price": "0.997", "size": "213.75"}, {"price": "0.996", "size": "62.55"}, {"price": "0.989", "size": "100"}, {"price": "0.988", "size": "330.3"}, {"price": "0.987", "size": "466.66"}, {"price": "0.986", "size": "100"}, {"price": "0.985", "size": "53.33"}], "event_type": "book", "last_trade_price": ""}, {"market": "0x928bccc135016fa2cafe8d4f0ba037d9a5a48f326dd1e30975dcb194586557a9", "asset_id": "26824912620938254469767700654787050340700902693511625959763274813138255826963", "timestamp": "1769383901917", "hash": "20f3195a99a279f64058cca2a71c3588ae7011b9", "bids": [{"price": "0.001", "size": "20355"}, {"price": "0.002", "size": "916"}, {"price": "0.005", "size": "945.38"}, {"price": "0.006", "size": "172.84"}], "asks": [{"price": "0.999", "size": "3828.19"}, {"price": "0.998", "size": "1256.17"}, {"price": "0.997", "size": "1400"}, {"price": "0.996", "size": "10.67"}, {"price": "0.994", "size": "200"}, {"price": "0.99", "size": "9550"}, {"price": "0.989", "size": "5.41"}, {"price": "0.98", "size": "3700"}, {"price": "0.979", "size": "5.44"}, {"price": "0.96", "size": "625"}, {"price": "0.959", "size": "5.13"}, {"price": "0.95", "size": "30"}, {"price": "0.949", "size": "39"}, {"price": "0.92", "size": "425"}, {"price": "0.919", "size": "6.27"}, {"price": "0.9", "size": "560"}, {"price": "0.85", "size": "776.66"}, {"price": "0.8", "size": "660"}, {"price": "0.799", "size": "5.2"}, {"price": "0.75", "size": "362"}, {"price": "0.749", "size": "181"}, {"price": "0.7", "size": "186.66"}, {"price": "0.65", "size": "68.57"}, {"price": "0.6", "size": "175"}, {"price": "0.599", "size": "20"}, {"price": "0.598", "size": "5"}, {"price": "0.09", "size": "855"}, {"price": "0.054", "size": "52.72"}, {"price": "0.008", "size": "24.36"}], "event_type": "book", "last_trade_price": ""}, {"market": "0xa56d5e2b4e7b2953924a056ef8dd06dc522cca07452b022c2709e7657c5e77d1", "asset_id": "77556710504213316111448322484387351100527751215970755902181921805797849287503", "timestamp": "1769383901917", "hash": "127fb0131b059183f3b30ab5a3981d4c07a1bd2d", "bids": [{"price": "0.001", "size": "3863.2"}, {"price": "0.002", "size": "1256.18"}, {"price": "0.003", "size": "1400"}, {"price": "0.004", "size": "10.68"}, {"price": "0.006", "size": "200"}, {"price": "0.01", "size": "9550"}, {"price": "0.011", "size": "5.42"}, {"price": "0.02", "size": "3700"}, {"price": "0.021", "size": "5.44"}, {"price": "0.04", "size": "625"}, {"price": "0.041", "size": "5.13"}, {"price": "0.05", "size": "30"}, {"price": "0.051", "size": "39"}, {"price": "0.08", "size": "425"}, {"price": "0.081", "size": "6.27"}, {"price": "0.1", "size": "560"}, {"price": "0.15", "size": "776.66"}, {"price": "0.2", "size": "660"}, {"price": "0.201", "size": "5.2"}, {"price": "0.25", "size": "362"}, {"price": "0.3", "size": "186.66"}, {"price": "0.34", "size": "50"}, {"price": "0.35", "size": "68.57"}, {"price": "0.4", "size": "50"}, {"price": "0.401", "size": "100"}, {"price": "0.403", "size": "130"}, {"price": "0.621", "size": "112.61"}, {"price": "0.693", "size": "100"}, {"price": "0.694", "size": "25"}, {"price": "0.92", "size": "150"}, {"price": "0.94", "size": "5"}, {"price": "0.986", "size": "57"}], "asks": [{"price": "0.999", "size": "15439"}, {"price": "0.998", "size": "721.83"}, {"price": "0.997", "size": "604.43"}, {"price": "0.996", "size": "313.15"}, {"price": "0.995", "size": "300"}, {"price": "0.994", "size": "166.66"}, {"price": "0.993", "size": "66.66"}, {"price": "0.992", "size": "66.66"}], "event_type": "book", "last_trade_price": ""}]}
{"_local_timestamp": "2026-01-25T23:34:39.475435+00:00", "data": {"market": "0x765b8aa92705a707bef70a29afe26415334d89acdc4b39c6181cba487ce84c05", "price_changes": [{"asset_id": "7572089862132266277497190546594925217703296087729786738015583660130296798227", "price": "0.012", "size": "230.3", "side": "BUY", "hash": "a9aa6a4e429034327492d18a2b3b2bef51cbd1b0", "best_bid": "0.015", "best_ask": "0.059"}, {"asset_id": "110736404220942753069497130589444118893575413943575478177477380332405665833000", "price": "0.988", "size": "230.3", "side": "SELL", "hash": "c14864cb29fa64760e057fc5fcacb56ace6e5d5f", "best_bid": "0.941", "best_ask": "0.985"}], "timestamp": "1769384079397", "event_type": "price_change"}}
{"_local_timestamp": "2026-01-25T23:34:39.477629+00:00", "data": {"market": "0xf25a20da2ca057704975cd29bb742a97cfc089759d1c1161e1323a2cc98bb9f2", "price_changes": [{"asset_id": "46569543401181796902098192406569670746198909020178777906519890064700339458797", "price": "0.005", "size": "273.51", "side": "BUY", "hash": "c3334140e196ad8d297c4cdbfa3da8853c67a156", "best_bid": "0.011", "best_ask": "0.062"}, {"asset_id": "53640757834467466216485370712527762791041006461643906643501013471745623378175", "price": "0.995", "size": "273.51", "side": "SELL", "hash": "5f25e34b101bbedc08bacb684f997b07944d4c3d", "best_bid": "0.938", "best_ask": "0.989"}], "timestamp": "1769384079397", "event_type": "price_change"}}
{"_local_timestamp": "2026-01-25T23:34:39.750492+00:00", "data": {"market": "0x765b8aa92705a707bef70a29afe26415334d89acdc4b39c6181cba487ce84c05", "price_changes": [{"asset_id": "7572089862132266277497190546594925217703296087729786738015583660130296798227", "price": "0.014", "size": "200", "side": "BUY", "hash": "90f340c178e7f7f68cb268cb89b81df20615487e", "best_bid": "0.015", "best_ask": "0.059"}, {"asset_id": "110736404220942753069497130589444118893575413943575478177477380332405665833000", "price": "0.986", "size": "200", "side": "SELL", "hash": "cd7b94ce77d9dab12e307e5d6da176574882cc04", "best_bid": "0.941", "best_ask": "0.985"}], "timestamp": "1769384079681", "event_type": "price_change"}}
{"_local_timestamp": "2026-01-25T23:34:39.752272+00:00", "data": {"market": "0xf25a20da2ca057704975cd29bb742a97cfc089759d1c1161e1323a2cc98bb9f2", "price_changes": [{"asset_id": "46569543401181796902098192406569670746198909020178777906519890064700339458797", "price": "0.004", "size": "375", "side": "BUY", "hash": "c030cd6cfb390c897d18bf04ba9ed90b6e48fe76", "best_bid": "0.011", "best_ask": "0.062"}, {"asset_id": "53640757834467466216485370712527762791041006461643906643501013471745623378175", "price": "0.996", "size": "375", "side": "SELL", "hash": "7583b7ff38c4ea8680bc9591cccfa02dd548e056", "best_bid": "0.938", "best_ask": "0.989"}], "timestamp": "1769384079682", "event_type": "price_change"}}
{"_local_timestamp": "2026-01-25T23:35:15.904120+00:00", "data": {"market": "0x4be208ebef12c4a31a44475ee6c50d16845918d56d9721af346e3075dbef197e", "price_changes": [{"asset_id": "40384302563834290793063484431892352880489425722482841375537167889452921217825", "price": "0.002", "size": "666", "side": "BUY", "hash": "a1c30744702a8a1548299d6cbe44b6a529bf6f12", "best_bid": "0.009", "best_ask": "0.059"}, {"asset_id": "44624470937661180249911132691369304324365682396836759395211838560647467358745", "price": "0.998", "size": "666", "side": "SELL", "hash": "7f1290f7679e16fa143d7aa8f1d62f187c7e03a1", "best_bid": "0.941", "best_ask": "0.991"}], "timestamp": "1769384115832", "event_type": "price_change"}}
{"_local_timestamp": "2026-01-25T23:35:15.904996+00:00", "data": {"market": "0x4be208ebef12c4a31a44475ee6c50d16845918d56d9721af346e3075dbef197e", "price_changes": [{"asset_id": "40384302563834290793063484431892352880489425722482841375537167889452921217825", "price": "0.003", "size": "300", "side": "BUY", "hash": "a1c30744702a8a1548299d6cbe44b6a529bf6f12", "best_bid": "0.009", "best_ask": "0.059"}, {"asset_id": "44624470937661180249911132691369304324365682396836759395211838560647467358745", "price": "0.997", "size": "300", "side": "SELL", "hash": "7f1290f7679e16fa143d7aa8f1d62f187c7e03a1", "best_bid": "0.941", "best_ask": "0.991"}], "timestamp": "1769384115832", "event_type": "price_change"}}
{"_local_timestamp": "2026-01-25T23:35:15.905247+00:00", "data": {"market": "0x4be208ebef12c4a31a44475ee6c50d16845918d56d9721af346e3075dbef197e", "price_changes": [{"asset_id": "40384302563834290793063484431892352880489425722482841375537167889452921217825", "price": "0.004", "size": "362.4", "side": "BUY", "hash": "a1c30744702a8a1548299d6cbe44b6a529bf6f12", "best_bid": "0.009", "best_ask": "0.059"}, {"asset_id": "44624470937661180249911132691369304324365682396836759395211838560647467358745", "price": "0.996", "size": "362.4", "side": "SELL", "hash": "7f1290f7679e16fa143d7aa8f1d62f187c7e03a1", "best_bid": "0.941", "best_ask": "0.991"}], "timestamp": "1769384115832", "event_type": "price_change"}}
{"_local_timestamp": "2026-01-25T23:35:16.246711+00:00", "data": {"market": "0x4be208ebef12c4a31a44475ee6c50d16845918d56d9721af346e3075dbef197e", "price_changes": [{"asset_id": "40384302563834290793063484431892352880489425722482841375537167889452921217825", "price": "0.004", "size": "382.57", "side": "BUY", "hash": "736d94e8c643c1c7df111fc81c489c223fc15ead", "best_bid": "0.009", "best_ask": "0.059"}, {"asset_id": "44624470937661180249911132691369304324365682396836759395211838560647467358745", "price": "0.996", "size": "382.57", "side": "SELL", "hash": "4f609b4f66d904c11df2a681b6e2fb1c1da966f6", "best_bid": "0.941", "best_ask": "0.991"}], "timestamp": "1769384116169", "event_type": "price_change"}}
{"_local_timestamp": "2026-01-25T23:35:16.247107+00:00", "data": {"market": "0x4be208ebef12c4a31a44475ee6c50d16845918d56d9721af346e3075dbef197e", "price_changes": [{"asset_id": "40384302563834290793063484431892352880489425722482841375537167889452921217825", "price": "0.005", "size": "256.06", "side": "BUY", "hash": "1aa35060dff9f786c6f0d664e767f00234cee115", "best_bid": "0.009", "best_ask": "0.059"}, {"asset_id": "44624470937661180249911132691369304324365682396836759395211838560647467358745", "price": "0.995", "size": "256.06", "side": "SELL", "hash": "700295847b117d2ea88b1f12fcc1e80ac1a6b775", "best_bid": "0.941", "best_ask": "0.991"}], "timestamp": "1769384116170", "event_type": "price_change"}}
{"_local_timestamp": "2026-01-25T23:35:16.247813+00:00", "data": {"market": "0x4be208ebef12c4a31a44475ee6c50d16845918d56d9721af346e3075dbef197e", "price_changes": [{"asset_id": "40384302563834290793063484431892352880489425722482841375537167889452921217825", "price": "0.002", "size": "706.76", "side": "BUY", "hash": "ad03441e2f72c1f82f8c4d4e14a12912e9acb8aa", "best_bid": "0.009", "best_ask": "0.059"}, {"asset_id": "44624470937661180249911132691369304324365682396836759395211838560647467358745", "price": "0.998", "size": "706.76", "side": "SELL", "hash": "9c5c4d895b66c8e3e5ab123d8151fde141b10230", "best_bid": "0.941", "best_ask": "0.991"}], "timestamp": "1769384116172", "event_type": "price_change"}}
{"_local_timestamp": "2026-01-25T23:35:16.248192+00:00", "data": {"market": "0x4be208ebef12c4a31a44475ee6c50d16845918d56d9721af346e3075dbef197e", "price_changes": [{"asset_id": "40384302563834290793063484431892352880489425722482841375537167889452921217825", "price": "0.003", "size": "327.04", "side": "BUY", "hash": "99ffa038c80f271cca28d161a33a9597f69b3944", "best_bid": "0.009", "best_ask": "0.059"}, {"asset_id": "44624470937661180249911132691369304324365682396836759395211838560647467358745", "price": "0.997", "size": "327.04", "side": "SELL", "hash": "aaee165290300a6e60e5ebb2ac10b4707514e5bf", "best_bid": "0.941", "best_ask": "0.991"}], "timestamp": "1769384116173", "event_type": "price_change"}}
{"_local_timestamp": "2026-01-25T23:35:16.759015+00:00", "data": {"market": "0xf25a20da2ca057704975cd29bb742a97cfc089759d1c1161e1323a2cc98bb9f2", "price_changes": [{"asset_id": "46569543401181796902098192406569670746198909020178777906519890064700339458797", "price": "0.002", "size": "666", "side": "BUY", "hash": "5860c78c497b19afb124dd6526fda3aa9fc1ca41", "best_bid": "0.011", "best_ask": "0.062"}, {"asset_id": "53640757834467466216485370712527762791041006461643906643501013471745623378175", "price": "0.998", "size": "666", "side": "SELL", "hash": "ba80ba15e777074e09ac12f43d3f8c160d335c26", "best_bid": "0.938", "best_ask": "0.989"}], "timestamp": "1769384116695", "event_type": "price_change"}}
{"_local_timestamp": "2026-01-25T23:35:17.086174+00:00", "data": {"market": "0xf25a20da2ca057704975cd29bb742a97cfc089759d1c1161e1323a2cc98bb9f2", "price_changes": [{"asset_id": "46569543401181796902098192406569670746198909020178777906519890064700339458797", "price": "0.002", "size": "694.71", "side": "BUY", "hash": "c71e778f7c939c94e6655362534d1fa5c1164ad6", "best_bid": "0.011", "best_ask": "0.062"}, {"asset_id": "53640757834467466216485370712527762791041006461643906643501013471745623378175", "price": "0.998", "size": "694.71", "side": "SELL", "hash": "e7b633eff34219c37cf928765cb0f61cd98c650e", "best_bid": "0.938", "best_ask": "0.989"}], "timestamp": "1769384117014", "event_type": "price_change"}}
{"_local_timestamp": "2026-01-25T23:35:19.379077+00:00", "data": {"market": "0xa56d5e2b4e7b2953924a056ef8dd06dc522cca07452b022c2709e7657c5e77d1", "price_changes": [{"asset_id": "4516212715150974646881863469118521294538792708256862394143608505284110964795", "price": "0.002", "size": "666", "side": "BUY", "hash": "874f278080d07ed9cf9c461dcc5a02dad906d06a", "best_bid": "0.008", "best_ask": "0.014"}, {"asset_id": "77556710504213316111448322484387351100527751215970755902181921805797849287503", "price": "0.998", "size": "666", "side": "SELL", "hash": "4bdb7c5e4829d6d5c2d1264e7d753ee2523b73f1", "best_bid": "0.986", "best_ask": "0.992"}], "timestamp": "1769384119312", "event_type": "price_change"}}
{"_local_timestamp": "2026-01-25T23:35:19.380094+00:00", "data": {"market": "0xa56d5e2b4e7b2953924a056ef8dd06dc522cca07452b022c2709e7657c5e77d1", "price_changes": [{"asset_id": "4516212715150974646881863469118521294538792708256862394143608505284110964795", "price": "0.003", "size": "567.4", "side": "BUY", "hash": "874f278080d07ed9cf9c461dcc5a02dad906d06a", "best_bid": "0.008", "best_ask": "0.014"}, {"asset_id": "77556710504213316111448322484387351100527751215970755902181921805797849287503", "price": "0.997", "size": "567.4", "side": "SELL", "hash": "4bdb7c5e4829d6d5c2d1264e7d753ee2523b73f1", "best_bid": "0.986", "best_ask": "0.992"}], "timestamp": "1769384119312", "event_type": "price_change"}}
{"_local_timestamp": "2026-01-25T23:35:19.380414+00:00", "data": {"market": "0xa56d5e2b4e7b2953924a056ef8dd06dc522cca07452b022c2709e7657c5e77d1", "price_changes": [{"asset_id": "4516212715150974646881863469118521294538792708256862394143608505284110964795", "price": "0.004", "size": "285.52", "side": "BUY", "hash": "874f278080d07ed9cf9c461dcc5a02dad906d06a", "best_bid": "0.008", "best_ask": "0.014"}, {"asset_id": "77556710504213316111448322484387351100527751215970755902181921805797849287503", "price": "0.996", "size": "285.52", "side": "SELL", "hash": "4bdb7c5e4829d6d5c2d1264e7d753ee2523b73f1", "best_bid": "0.986", "best_ask": "0.992"}], "timestamp": "1769384119312", "event_type": "price_change"}}
{"_local_timestamp": "2026-01-25T23:35:19.749274+00:00", "data": {"market": "0xa56d5e2b4e7b2953924a056ef8dd06dc522cca07452b022c2709e7657c5e77d1", "price_changes": [{"asset_id": "4516212715150974646881863469118521294538792708256862394143608505284110964795", "price": "0.002", "size": "721.83", "side": "BUY", "hash": "bc61aa94b13719e663ba0a8bbda34b9535ff2c26", "best_bid": "0.008", "best_ask": "0.014"}, {"asset_id": "77556710504213316111448322484387351100527751215970755902181921805797849287503", "price": "0.998", "size": "721.83", "side": "SELL", "hash": "6aefe875fcddbe48840022c51819d545401ceeb8", "best_bid": "0.986", "best_ask": "0.992"}], "timestamp": "1769384119679", "event_type": "price_change"}}
{"_local_timestamp": "2026-01-25T23:35:19.749624+00:00", "data": {"market": "0xa56d5e2b4e7b2953924a056ef8dd06dc522cca07452b022c2709e7657c5e77d1", "price_changes": [{"asset_id": "4516212715150974646881863469118521294538792708256862394143608505284110964795", "price": "0.004", "size": "313.15", "side": "BUY", "hash": "74b240dc75a361e66f850e99477c44f4c537d993", "best_bid": "0.008", "best_ask": "0.014"}, {"asset_id": "77556710504213316111448322484387351100527751215970755902181921805797849287503", "price": "0.996", "size": "313.15", "side": "SELL", "hash": "6d07d6b77dd341a919d77f52c1a5a28493c7b93d", "best_bid": "0.986", "best_ask": "0.992"}], "timestamp": "1769384119680", "event_type": "price_change"}}
{"_local_timestamp": "2026-01-25T23:35:19.749917+00:00", "data": {"market": "0xa56d5e2b4e7b2953924a056ef8dd06dc522cca07452b022c2709e7657c5e77d1", "price_changes": [{"asset_id": "4516212715150974646881863469118521294538792708256862394143608505284110964795", "price": "0.003", "size": "604.43", "side": "BUY", "hash": "f9a4e5c5378fbd9ecfd54c025d1b7b30c8c85058", "best_bid": "0.008", "best_ask": "0.014"}, {"asset_id": "77556710504213316111448322484387351100527751215970755902181921805797849287503", "price": "0.997", "size": "604.43", "side": "SELL", "hash": "5d309b7d61b5f24bea7ee8b9c32f5d198fc789b9", "best_bid": "0.986", "best_ask": "0.992"}], "timestamp": "1769384119681", "event_type": "price_change"}}
{"_local_timestamp": "2026-01-25T23:35:19.829264+00:00", "data": {"market": "0x765b8aa92705a707bef70a29afe26415334d89acdc4b39c6181cba487ce84c05", "price_changes": [{"asset_id": "7572089862132266277497190546594925217703296087729786738015583660130296798227", "price": "0.002", "size": "676.42", "side": "BUY", "hash": "871b3a88f63623a3274034e909452f932d25af9f", "best_bid": "0.015", "best_ask": "0.059"}, {"asset_id": "110736404220942753069497130589444118893575413943575478177477380332405665833000", "price": "0.998", "size": "676.42", "side": "SELL", "hash": "5fdc73f1dbc4a9ac076c94903adb922daf7e2b44", "best_bid": "0.941", "best_ask": "0.985"}], "timestamp": "1769384119762", "event_type": "price_change"}}
{"_local_timestamp": "2026-01-25T23:35:19.829681+00:00", "data": {"market": "0x765b8aa92705a707bef70a29afe26415334d89acdc4b39c6181cba487ce84c05", "price_changes": [{"asset_id": "7572089862132266277497190546594925217703296087729786738015583660130296798227", "price": "0.003", "size": "206.22", "side": "BUY", "hash": "871b3a88f63623a3274034e909452f932d25af9f", "best_bid": "0.015", "best_ask": "0.059"}, {"asset_id": "110736404220942753069497130589444118893575413943575478177477380332405665833000", "price": "0.997", "size": "206.22", "side": "SELL", "hash": "5fdc73f1dbc4a9ac076c94903adb922daf7e2b44", "best_bid": "0.941", "best_ask": "0.985"}], "timestamp": "1769384119762", "event_type": "price_change"}}
{"_local_timestamp": "2026-01-25T23:35:20.230508+00:00", "data": {"market": "0x765b8aa92705a707bef70a29afe26415334d89acdc4b39c6181cba487ce84c05", "price_changes": [{"asset_id": "7572089862132266277497190546594925217703296087729786738015583660130296798227", "price": "0.002", "size": "686.33", "side": "BUY", "hash": "eb88b789f72b048d7dae7917d03979cdd01810c5", "best_bid": "0.015", "best_ask": "0.059"}, {"asset_id": "110736404220942753069497130589444118893575413943575478177477380332405665833000", "price": "0.998", "size": "686.33", "side": "SELL", "hash": "e6f3a1dbb8a9189981c035329903a183947530cb", "best_bid": "0.941", "best_ask": "0.985"}], "timestamp": "1769384120160", "event_type": "price_change"}}
{"_local_timestamp": "2026-01-25T23:35:20.230988+00:00", "data": {"market": "0x765b8aa92705a707bef70a29afe26415334d89acdc4b39c6181cba487ce84c05", "price_changes": [{"asset_id": "7572089862132266277497190546594925217703296087729786738015583660130296798227", "price": "0.003", "size": "214.15", "side": "BUY", "hash": "54f192169cf2cafdf0bd6db8fa00d457e7b9b22e", "best_bid": "0.015", "best_ask": "0.059"}, {"asset_id": "110736404220942753069497130589444118893575413943575478177477380332405665833000", "price": "0.997", "size": "214.15", "side": "SELL", "hash": "634494169ed88c090142a1fdb392c17efce66865", "best_bid": "0.941", "best_ask": "0.985"}], "timestamp": "1769384120162", "event_type": "price_change"}}
{"_local_timestamp": "2026-01-25T23:35:28.649270+00:00", "data": {"market": "0x4be208ebef12c4a31a44475ee6c50d16845918d56d9721af346e3075dbef197e", "price_changes": [{"asset_id": "40384302563834290793063484431892352880489425722482841375537167889452921217825", "price": "0.005", "size": "240", "side": "BUY", "hash": "9cce2d11ebfcbd566da7581c222158c18e55d687", "best_bid": "0.009", "best_ask": "0.059"}, {"asset_id": "44624470937661180249911132691369304324365682396836759395211838560647467358745", "price": "0.995", "size": "240", "side": "SELL", "hash": "97cf8c4ca42a9950ff1e8a79adf121bf7e35ae4f", "best_bid": "0.941", "best_ask": "0.991"}], "timestamp": "1769384128571", "event_type": "price_change"}}
{"_local_timestamp": "2026-01-25T23:36:13.283143+00:00", "data": {"market": "0x928bccc135016fa2cafe8d4f0ba037d9a5a48f326dd1e30975dcb194586557a9", "price_changes": [{"asset_id": "27158678906746497110330606113923753280208777834993320994787156825009294890573", "price": "0.402", "size": "0", "side": "BUY", "hash": "a5bedc46c301415c0bfcc6e52d46ce04ddb04750", "best_bid": "0.992", "best_ask": "0.994"}, {"asset_id": "26824912620938254469767700654787050340700902693511625959763274813138255826963", "price": "0.598", "size": "0", "side": "SELL", "hash": "bd97e415f21eb5c287cb953fa05237281f063b42", "best_bid": "0.006", "best_ask": "0.008"}], "timestamp": "1769384173217", "event_type": "price_change"}}
{"_local_timestamp": "2026-01-25T23:36:13.330591+00:00", "data": {"market": "0x928bccc135016fa2cafe8d4f0ba037d9a5a48f326dd1e30975dcb194586557a9", "price_changes": [{"asset_id": "27158678906746497110330606113923753280208777834993320994787156825009294890573", "price": "0.402", "size": "5", "side": "BUY", "hash": "8dcae4e842af7b0b30b8bd0563aebe704a27f0b7", "best_bid": "0.992", "best_ask": "0.994"}, {"asset_id": "26824912620938254469767700654787050340700902693511625959763274813138255826963", "price": "0.598", "size": "5", "side": "SELL", "hash": "4043d0562bf24b71b0fa547eca578ed09df3ec81", "best_bid": "0.006", "best_ask": "0.008"}], "timestamp": "1769384173263", "event_type": "price_change"}}
{"_local_timestamp": "2026-01-25T23:36:16.734523+00:00", "data": {"market": "0x44140ac0504e812d05917c3214e38eef26a18ddcd64b2832a616c7cc0222c137", "price_changes": [{"asset_id": "73574222258523377180162380054665411282462793585968406483594315204933879956564", "price": "0.01", "size": "3830", "side": "BUY", "hash": "cd2d07782759e3c46056b29ba938c1925b34fa66", "best_bid": "0.05", "best_ask": "0.06"}, {"asset_id": "24302570134861420001522487831207657461211578987386112721833748346595897717589", "price": "0.99", "size": "3830", "side": "SELL", "hash": "c7f7081a8f0e6f6ed439c99c46979fab89bb46f2", "best_bid": "0.94", "best_ask": "0.95"}], "timestamp": "1769384176669", "event_type": "price_change"}}
{"_local_timestamp": "2026-01-25T23:36:16.734937+00:00", "data": {"market": "0x44140ac0504e812d05917c3214e38eef26a18ddcd64b2832a616c7cc0222c137", "price_changes": [{"asset_id": "73574222258523377180162380054665411282462793585968406483594315204933879956564", "price": "0.02", "size": "1000", "side": "BUY", "hash": "cd2d07782759e3c46056b29ba938c1925b34fa66", "best_bid": "0.05", "best_ask": "0.06"}, {"asset_id": "24302570134861420001522487831207657461211578987386112721833748346595897717589", "price": "0.98", "size": "1000", "side": "SELL", "hash": "c7f7081a8f0e6f6ed439c99c46979fab89bb46f2", "best_bid": "0.94", "best_ask": "0.95"}], "timestamp": "1769384176669", "event_type": "price_change"}}
{"_local_timestamp": "2026-01-25T23:36:16.735200+00:00", "data": {"market": "0x44140ac0504e812d05917c3214e38eef26a18ddcd64b2832a616c7cc0222c137", "price_changes": [{"asset_id": "73574222258523377180162380054665411282462793585968406483594315204933879956564", "price": "0.03", "size": "0", "side": "BUY", "hash": "cd2d07782759e3c46056b29ba938c1925b34fa66", "best_bid": "0.05", "best_ask": "0.06"}, {"asset_id": "24302570134861420001522487831207657461211578987386112721833748346595897717589", "price": "0.97", "size": "0", "side": "SELL", "hash": "c7f7081a8f0e6f6ed439c99c46979fab89bb46f2", "best_bid": "0.94", "best_ask": "0.95"}], "timestamp": "1769384176669", "event_type": "price_change"}}
{"_local_timestamp": "2026-01-25T23:36:17.139083+00:00", "data": {"market": "0x44140ac0504e812d05917c3214e38eef26a18ddcd64b2832a616c7cc0222c137", "price_changes": [{"asset_id": "73574222258523377180162380054665411282462793585968406483594315204933879956564", "price": "0.03", "size": "30.93", "side": "BUY", "hash": "841432842f35f6a3251c606df7eb0751a5bb7829", "best_bid": "0.05", "best_ask": "0.06"}, {"asset_id": "24302570134861420001522487831207657461211578987386112721833748346595897717589", "price": "0.97", "size": "30.93", "side": "SELL", "hash": "d0c9ed31860afc6cc526c5c43d85a27524511262", "best_bid": "0.94", "best_ask": "0.95"}], "timestamp": "1769384177068", "event_type": "price_change"}}
{"_local_timestamp": "2026-01-25T23:36:17.139469+00:00", "data": {"market": "0x44140ac0504e812d05917c3214e38eef26a18ddcd64b2832a616c7cc0222c137", "price_changes": [{"asset_id": "73574222258523377180162380054665411282462793585968406483594315204933879956564", "price": "0.02", "size": "1047.7", "side": "BUY", "hash": "37b251f8fbc34c846acafad42fe63305446a6427", "best_bid": "0.05", "best_ask": "0.06"}, {"asset_id": "24302570134861420001522487831207657461211578987386112721833748346595897717589", "price": "0.98", "size": "1047.7", "side": "SELL", "hash": "4e61b860121ddf8bb1aed5012551b7994d473e27", "best_bid": "0.94", "best_ask": "0.95"}], "timestamp": "1769384177069", "event_type": "price_change"}}
{"_local_timestamp": "2026-01-25T23:36:17.139783+00:00", "data": {"market": "0x44140ac0504e812d05917c3214e38eef26a18ddcd64b2832a616c7cc0222c137", "price_changes": [{"asset_id": "73574222258523377180162380054665411282462793585968406483594315204933879956564", "price": "0.01", "size": "3841.77", "side": "BUY", "hash": "e949d96aa486fa8419e1cc52ff98890039023f63", "best_bid": "0.05", "best_ask": "0.06"}, {"asset_id": "24302570134861420001522487831207657461211578987386112721833748346595897717589", "price": "0.99", "size": "3841.77", "side": "SELL", "hash": "1f4af0b8b99def5fcc39bbe4c828c8bfc094ca48", "best_bid": "0.94", "best_ask": "0.95"}], "timestamp": "1769384177070", "event_type": "price_change"}}
{"_local_timestamp": "2026-01-25T23:36:57.756513+00:00", "data": {"market": "0x765b8aa92705a707bef70a29afe26415334d89acdc4b39c6181cba487ce84c05", "price_changes": [{"asset_id": "7572089862132266277497190546594925217703296087729786738015583660130296798227", "price": "0.012", "size": "18.3", "side": "BUY", "hash": "a60c1ae9b4aabe98f7fc4220d109535e935324eb", "best_bid": "0.015", "best_ask": "0.059"}, {"asset_id": "110736404220942753069497130589444118893575413943575478177477380332405665833000", "price": "0.988", "size": "18.3", "side": "SELL", "hash": "e2102e34af25b287233088efe3c7263b199b8d5a", "best_bid": "0.941", "best_ask": "0.985"}], "timestamp": "1769384217231", "event_type": "price_change"}}
{"_local_timestamp": "2026-01-25T23:36:58.881879+00:00", "data": {"market": "0xf25a20da2ca057704975cd29bb742a97cfc089759d1c1161e1323a2cc98bb9f2", "price_changes": [{"asset_id": "46569543401181796902098192406569670746198909020178777906519890064700339458797", "price": "0.003", "size": "401.87", "side": "BUY", "hash": "cc57dfbe6fb0cab4f22242ed0e31837b795cf3f4", "best_bid": "0.011", "best_ask": "0.062"}, {"asset_id": "53640757834467466216485370712527762791041006461643906643501013471745623378175", "price": "0.997", "size": "401.87", "side": "SELL", "hash": "b0b0af9f0160dfb4e4bfa232a155b1fd6b5ab49c", "best_bid": "0.938", "best_ask": "0.989"}], "timestamp": "1769384218489", "event_type": "price_change"}}
{"_local_timestamp": "2026-01-25T23:36:58.882220+00:00", "data": {"market": "0x928bccc135016fa2cafe8d4f0ba037d9a5a48f326dd1e30975dcb194586557a9", "price_changes": [{"asset_id": "26824912620938254469767700654787050340700902693511625959763274813138255826963", "price": "0.005", "size": "1045.38", "side": "BUY", "hash": "5bbd310cda2e3fe14c607a6fa65fee2c40e2c2d7", "best_bid": "0.006", "best_ask": "0.008"}, {"asset_id": "27158678906746497110330606113923753280208777834993320994787156825009294890573", "price": "0.995", "size": "1045.38", "side": "SELL", "hash": "e9f24f304af67c3a30b8432e0bff6ba08cf26d7b", "best_bid": "0.992", "best_ask": "0.994"}], "timestamp": "1769384218492", "event_type": "price_change"}}
{"_local_timestamp": "2026-01-25T23:36:58.930166+00:00", "data": {"market": "0x4be208ebef12c4a31a44475ee6c50d16845918d56d9721af346e3075dbef197e", "price_changes": [{"asset_id": "40384302563834290793063484431892352880489425722482841375537167889452921217825", "price": "0.003", "size": "427.04", "side": "BUY", "hash": "ca55ae782e4144f603660b2c517b9accfb5d88f7", "best_bid": "0.009", "best_ask": "0.059"}, {"asset_id": "44624470937661180249911132691369304324365682396836759395211838560647467358745", "price": "0.997", "size": "427.04", "side": "SELL", "hash": "2ddf90f4f8099063c7dcb74ae6228380c7c5f156", "best_bid": "0.941", "best_ask": "0.991"}], "timestamp": "1769384218507", "event_type": "price_change"}}
{"_local_timestamp": "2026-01-25T23:36:58.974088+00:00", "data": {"market": "0xa56d5e2b4e7b2953924a056ef8dd06dc522cca07452b022c2709e7657c5e77d1", "price_changes": [{"asset_id": "4516212715150974646881863469118521294538792708256862394143608505284110964795", "price": "0.003", "size": "704.43", "side": "BUY", "hash": "8258fee051ce358dd09785b95466b10991f3e015", "best_bid": "0.008", "best_ask": "0.014"}, {"asset_id": "77556710504213316111448322484387351100527751215970755902181921805797849287503", "price": "0.997", "size": "704.43", "side": "SELL", "hash": "45c9de63039ca994be41966465898f09ef95cb2f", "best_bid": "0.986", "best_ask": "0.992"}], "timestamp": "1769384218537", "event_type": "price_change"}}
{"_local_timestamp": "2026-01-25T23:36:59.002309+00:00", "data": {"market": "0x765b8aa92705a707bef70a29afe26415334d89acdc4b39c6181cba487ce84c05", "price_changes": [{"asset_id": "7572089862132266277497190546594925217703296087729786738015583660130296798227", "price": "0.003", "size": "314.15", "side": "BUY", "hash": "beb7f0241446f1dd0bbeba25db94a9f7140362b1", "best_bid": "0.015", "best_ask": "0.059"}, {"asset_id": "110736404220942753069497130589444118893575413943575478177477380332405665833000", "price": "0.997", "size": "314.15", "side": "SELL", "hash": "baa4f5388ceac3abea6f42fe9c2b2034cd2debd7", "best_bid": "0.941", "best_ask": "0.985"}], "timestamp": "1769384218536", "event_type": "price_change"}}
{"_local_timestamp": "2026-01-25T23:37:13.670708+00:00", "data": {"market": "0x765b8aa92705a707bef70a29afe26415334d89acdc4b39c6181cba487ce84c05", "price_changes": [{"asset_id": "7572089862132266277497190546594925217703296087729786738015583660130296798227", "price": "0.014", "size": "433", "side": "BUY", "hash": "5efe9f6a752ca31ad8c9db80cedd8e71b5ec6686", "best_bid": "0.015", "best_ask": "0.059"}, {"asset_id": "110736404220942753069497130589444118893575413943575478177477380332405665833000", "price": "0.986", "size": "433", "side": "SELL", "hash": "405de93fddda51b58aa24ced51423530cc47d32b", "best_bid": "0.941", "best_ask": "0.985"}], "timestamp": "1769384233604", "event_type": "price_change"}}
{"_local_timestamp": "2026-01-25T23:38:25.204870+00:00", "data": {"market": "0x765b8aa92705a707bef70a29afe26415334d89acdc4b39c6181cba487ce84c05", "price_changes": [{"asset_id": "7572089862132266277497190546594925217703296087729786738015583660130296798227", "price": "0.003", "size": "214.15", "side": "BUY", "hash": "f75e86d5c7c863f147f69f0e0df317fb76c1a710", "best_bid": "0.015", "best_ask": "0.059"}, {"asset_id": "110736404220942753069497130589444118893575413943575478177477380332405665833000", "price": "0.997", "size": "214.15", "side": "SELL", "hash": "d5f4d1c2a856a7f06f94e13891596d2c22b9ea85", "best_bid": "0.941", "best_ask": "0.985"}], "timestamp": "1769384305122", "event_type": "price_change"}}
{"_local_timestamp": "2026-01-25T23:38:25.493699+00:00", "data": {"market": "0x765b8aa92705a707bef70a29afe26415334d89acdc4b39c6181cba487ce84c05", "price_changes": [{"asset_id": "7572089862132266277497190546594925217703296087729786738015583660130296798227", "price": "0.014", "size": "533", "side": "BUY", "hash": "0eed63f7fa135da6880b428cdde9820582193495", "best_bid": "0.015", "best_ask": "0.059"}, {"asset_id": "110736404220942753069497130589444118893575413943575478177477380332405665833000", "price": "0.986", "size": "533", "side": "SELL", "hash": "d8b8ee89c63be9c10dca841e9aa0c9beed65afa2", "best_bid": "0.941", "best_ask": "0.985"}], "timestamp": "1769384305411", "event_type": "price_change"}}
{"_local_timestamp": "2026-01-25T23:39:44.992919+00:00", "data": {"market": "0x44140ac0504e812d05917c3214e38eef26a18ddcd64b2832a616c7cc0222c137", "price_changes": [{"asset_id": "73574222258523377180162380054665411282462793585968406483594315204933879956564", "price": "0.01", "size": "3830", "side": "BUY", "hash": "5786b9e298159f5731ad3dae034c168c031d03f4", "best_bid": "0.05", "best_ask": "0.06"}, {"asset_id": "24302570134861420001522487831207657461211578987386112721833748346595897717589", "price": "0.99", "size": "3830", "side": "SELL", "hash": "370fd1c75c5717e9c2bf190badfc92640aad3117", "best_bid": "0.94", "best_ask": "0.95"}], "timestamp": "1769384384918", "event_type": "price_change"}}
{"_local_timestamp": "2026-01-25T23:39:44.993813+00:00", "data": {"market": "0x44140ac0504e812d05917c3214e38eef26a18ddcd64b2832a616c7cc0222c137", "price_changes": [{"asset_id": "73574222258523377180162380054665411282462793585968406483594315204933879956564", "price": "0.02", "size": "1000", "side": "BUY", "hash": "5786b9e298159f5731ad3dae034c168c031d03f4", "best_bid": "0.05", "best_ask": "0.06"}, {"asset_id": "24302570134861420001522487831207657461211578987386112721833748346595897717589", "price": "0.98", "size": "1000", "side": "SELL", "hash": "370fd1c75c5717e9c2bf190badfc92640aad3117", "best_bid": "0.94", "best_ask": "0.95"}], "timestamp": "1769384384918", "event_type": "price_change"}}
{"_local_timestamp": "2026-01-25T23:39:44.994165+00:00", "data": {"market": "0x44140ac0504e812d05917c3214e38eef26a18ddcd64b2832a616c7cc0222c137", "price_changes": [{"asset_id": "73574222258523377180162380054665411282462793585968406483594315204933879956564", "price": "0.03", "size": "0", "side": "BUY", "hash": "5786b9e298159f5731ad3dae034c168c031d03f4", "best_bid": "0.05", "best_ask": "0.06"}, {"asset_id": "24302570134861420001522487831207657461211578987386112721833748346595897717589", "price": "0.97", "size": "0", "side": "SELL", "hash": "370fd1c75c5717e9c2bf190badfc92640aad3117", "best_bid": "0.94", "best_ask": "0.95"}], "timestamp": "1769384384918", "event_type": "price_change"}}
{"_local_timestamp": "2026-01-25T23:39:46.598582+00:00", "data": {"market": "0x44140ac0504e812d05917c3214e38eef26a18ddcd64b2832a616c7cc0222c137", "price_changes": [{"asset_id": "73574222258523377180162380054665411282462793585968406483594315204933879956564", "price": "0.02", "size": "1047.7", "side": "BUY", "hash": "e22d9f5842187b0cd8e23f63c4693118d7834ed4", "best_bid": "0.05", "best_ask": "0.06"}, {"asset_id": "24302570134861420001522487831207657461211578987386112721833748346595897717589", "price": "0.98", "size": "1047.7", "side": "SELL", "hash": "5e2c6001e3a3239668f0ac245461bb6a0fbf7d7f", "best_bid": "0.94", "best_ask": "0.95"}], "timestamp": "1769384386530", "event_type": "price_change"}}
{"_local_timestamp": "2026-01-25T23:39:46.614602+00:00", "data": {"market": "0x44140ac0504e812d05917c3214e38eef26a18ddcd64b2832a616c7cc0222c137", "price_changes": [{"asset_id": "73574222258523377180162380054665411282462793585968406483594315204933879956564", "price": "0.03", "size": "30.93", "side": "BUY", "hash": "be1d0a729df93ca2d039501594ee69c03b93c7f5", "best_bid": "0.05", "best_ask": "0.06"}, {"asset_id": "24302570134861420001522487831207657461211578987386112721833748346595897717589", "price": "0.97", "size": "30.93", "side": "SELL", "hash": "bbc6e3002d4058040607c713f4ce6fa168ce813e", "best_bid": "0.94", "best_ask": "0.95"}], "timestamp": "1769384386540", "event_type": "price_change"}}
{"_local_timestamp": "2026-01-25T23:39:47.237257+00:00", "data": {"market": "0x44140ac0504e812d05917c3214e38eef26a18ddcd64b2832a616c7cc0222c137", "price_changes": [{"asset_id": "73574222258523377180162380054665411282462793585968406483594315204933879956564", "price": "0.01", "size": "3841.77", "side": "BUY", "hash": "b2d20200e4847a6217737266e4fb55e43d90580d", "best_bid": "0.05", "best_ask": "0.06"}, {"asset_id": "24302570134861420001522487831207657461211578987386112721833748346595897717589", "price": "0.99", "size": "3841.77", "side": "SELL", "hash": "00ec5368cbcdacd17c5774bad04e2784dcd8cc30", "best_bid": "0.94", "best_ask": "0.95"}], "timestamp": "1769384387162", "event_type": "price_change"}}
{"_local_timestamp": "2026-01-25T23:39:47.859833+00:00", "data": {"market": "0x44140ac0504e812d05917c3214e38eef26a18ddcd64b2832a616c7cc0222c137", "price_changes": [{"asset_id": "73574222258523377180162380054665411282462793585968406483594315204933879956564", "price": "0.01", "size": "3830", "side": "BUY", "hash": "6082a33736a4b63db95ec66b07378699ef4b1ee5", "best_bid": "0.05", "best_ask": "0.06"}, {"asset_id": "24302570134861420001522487831207657461211578987386112721833748346595897717589", "price": "0.99", "size": "3830", "side": "SELL", "hash": "a63eb95d58796315403c3a1e06bb0945c4352df3", "best_bid": "0.94", "best_ask": "0.95"}], "timestamp": "1769384387779", "event_type": "price_change"}}
{"_local_timestamp": "2026-01-25T23:39:47.860225+00:00", "data": {"market": "0x44140ac0504e812d05917c3214e38eef26a18ddcd64b2832a616c7cc0222c137", "price_changes": [{"asset_id": "73574222258523377180162380054665411282462793585968406483594315204933879956564", "price": "0.02", "size": "1000", "side": "BUY", "hash": "6082a33736a4b63db95ec66b07378699ef4b1ee5", "best_bid": "0.05", "best_ask": "0.06"}, {"asset_id": "24302570134861420001522487831207657461211578987386112721833748346595897717589", "price": "0.98", "size": "1000", "side": "SELL", "hash": "a63eb95d58796315403c3a1e06bb0945c4352df3", "best_bid": "0.94", "best_ask": "0.95"}], "timestamp": "1769384387779", "event_type": "price_change"}}
{"_local_timestamp": "2026-01-25T23:39:47.860549+00:00", "data": {"market": "0x44140ac0504e812d05917c3214e38eef26a18ddcd64b2832a616c7cc0222c137", "price_changes": [{"asset_id": "73574222258523377180162380054665411282462793585968406483594315204933879956564", "price": "0.03", "size": "0", "side": "BUY", "hash": "6082a33736a4b63db95ec66b07378699ef4b1ee5", "best_bid": "0.05", "best_ask": "0.06"}, {"asset_id": "24302570134861420001522487831207657461211578987386112721833748346595897717589", "price": "0.97", "size": "0", "side": "SELL", "hash": "a63eb95d58796315403c3a1e06bb0945c4352df3", "best_bid": "0.94", "best_ask": "0.95"}], "timestamp": "1769384387779", "event_type": "price_change"}}
{"_local_timestamp": "2026-01-25T23:39:49.905066+00:00", "data": {"market": "0x44140ac0504e812d05917c3214e38eef26a18ddcd64b2832a616c7cc0222c137", "price_changes": [{"asset_id": "73574222258523377180162380054665411282462793585968406483594315204933879956564", "price": "0.03", "size": "30.93", "side": "BUY", "hash": "3dea21b55546d7a93a6104bd03bb561355f12815", "best_bid": "0.05", "best_ask": "0.06"}, {"asset_id": "24302570134861420001522487831207657461211578987386112721833748346595897717589", "price": "0.97", "size": "30.93", "side": "SELL", "hash": "dbbf944e8e771b1dab1e88fd9317e51c1a729830", "best_bid": "0.94", "best_ask": "0.95"}], "timestamp": "1769384389832", "event_type": "price_change"}}
{"_local_timestamp": "2026-01-25T23:39:49.910035+00:00", "data": {"market": "0x44140ac0504e812d05917c3214e38eef26a18ddcd64b2832a616c7cc0222c137", "price_changes": [{"asset_id": "73574222258523377180162380054665411282462793585968406483594315204933879956564", "price": "0.02", "size": "1047.7", "side": "BUY", "hash": "26bf3dcd2efaa0a7bc12a733c074bc466909974f", "best_bid": "0.05", "best_ask": "0.06"}, {"asset_id": "24302570134861420001522487831207657461211578987386112721833748346595897717589", "price": "0.98", "size": "1047.7", "side": "SELL", "hash": "1080245c36d72b7bc94c553bee9868a6325e9cb8", "best_bid": "0.94", "best_ask": "0.95"}], "timestamp": "1769384389834", "event_type": "price_change"}}
{"_local_timestamp": "2026-01-25T23:39:49.910386+00:00", "data": {"market": "0x44140ac0504e812d05917c3214e38eef26a18ddcd64b2832a616c7cc0222c137", "price_changes": [{"asset_id": "73574222258523377180162380054665411282462793585968406483594315204933879956564", "price": "0.01", "size": "3841.77", "side": "BUY", "hash": "9def73f1da2a012987ddbd711394aac4343df758", "best_bid": "0.05", "best_ask": "0.06"}, {"asset_id": "24302570134861420001522487831207657461211578987386112721833748346595897717589", "price": "0.99", "size": "3841.77", "side": "SELL", "hash": "ce1a546df08711d85de18bc3625dcc373bdc67dd", "best_bid": "0.94", "best_ask": "0.95"}], "timestamp": "1769384389835", "event_type": "price_change"}}
{"_local_timestamp": "2026-01-25T23:40:13.215452+00:00", "data": {"market": "0x765b8aa92705a707bef70a29afe26415334d89acdc4b39c6181cba487ce84c05", "price_changes": [{"asset_id": "7572089862132266277497190546594925217703296087729786738015583660130296798227", "price": "0.013", "size": "360", "side": "BUY", "hash": "ca515186b82e6d82b3d1776e9c29393d136eee69", "best_bid": "0.014", "best_ask": "0.059"}, {"asset_id": "110736404220942753069497130589444118893575413943575478177477380332405665833000", "price": "0.987", "size": "360", "side": "SELL", "hash": "3588fe639e7102fa3efcf716846f3054a55bd310", "best_bid": "0.941", "best_ask": "0.986"}], "timestamp": "1769384413148", "event_type": "price_change"}}
{"_local_timestamp": "2026-01-25T23:40:13.215854+00:00", "data": {"market": "0x765b8aa92705a707bef70a29afe26415334d89acdc4b39c6181cba487ce84c05", "price_changes": [{"asset_id": "7572089862132266277497190546594925217703296087729786738015583660130296798227", "price": "0.015", "size": "0", "side": "BUY", "hash": "ca515186b82e6d82b3d1776e9c29393d136eee69", "best_bid": "0.014", "best_ask": "0.059"}, {"asset_id": "110736404220942753069497130589444118893575413943575478177477380332405665833000", "price": "0.985", "size": "0", "side": "SELL", "hash": "3588fe639e7102fa3efcf716846f3054a55bd310", "best_bid": "0.941", "best_ask": "0.986"}], "timestamp": "1769384413148", "event_type": "price_change"}}
{"_local_timestamp": "2026-01-25T23:40:13.652218+00:00", "data": {"market": "0x765b8aa92705a707bef70a29afe26415334d89acdc4b39c6181cba487ce84c05", "price_changes": [{"asset_id": "7572089862132266277497190546594925217703296087729786738015583660130296798227", "price": "0.015", "size": "160", "side": "BUY", "hash": "ded82653579eaff3ca4cd30eac70412c3c6d860e", "best_bid": "0.015", "best_ask": "0.059"}, {"asset_id": "110736404220942753069497130589444118893575413943575478177477380332405665833000", "price": "0.985", "size": "160", "side": "SELL", "hash": "e448733fc50be9d6ba48497d5029c0b10da6e14a", "best_bid": "0.941", "best_ask": "0.985"}], "timestamp": "1769384413588", "event_type": "price_change"}}
{"_local_timestamp": "2026-01-25T23:40:13.720067+00:00", "data": {"market": "0x44140ac0504e812d05917c3214e38eef26a18ddcd64b2832a616c7cc0222c137", "price_changes": [{"asset_id": "73574222258523377180162380054665411282462793585968406483594315204933879956564", "price": "0.04", "size": "1043.94", "side": "BUY", "hash": "488bcdb632589df9d6348c09956f39ab3cda2a4f", "best_bid": "0.05", "best_ask": "0.06"}, {"asset_id": "24302570134861420001522487831207657461211578987386112721833748346595897717589", "price": "0.96", "size": "1043.94", "side": "SELL", "hash": "cafb0b3b2a2af0870517fc1855e07b79e16064af", "best_bid": "0.94", "best_ask": "0.95"}], "timestamp": "1769384413653", "event_type": "price_change"}}
