{"_local_timestamp": "2026-01-25T23:41:06.321014+00:00", "data": [{"market": "0xa5ea40ac631a40071430323150632a1555ad1687e00a8085139add2d911c9f34", "asset_id": "110173687573613171160959717033136753568422637870529083487941219617533969558974", "timestamp": "1769384273835", "hash": "a77cd2ed48312af728f9cf0cb5fd0097358f746b", "bids": [{"price": "0.001", "size": "1810.87"}], "asks": [{"price": "0.999", "size": "7231.18"}, {"price": "0.998", "size": "27.51"}, {"price": "0.99", "size": "123"}, {"price": "0.989", "size": "5.41"}, {"price": "0.98", "size": "800"}, {"price": "0.979", "size": "8.05"}, {"price": "0.95", "size": "30"}, {"price": "0.949", "size": "13.01"}, {"price": "0.9", "size": "360"}, {"price": "0.85", "size": "226.66"}, {"price": "0.8", "size": "160"}, {"price": "0.799", "size": "5.2"}, {"price": "0.75", "size": "112"}, {"price": "0.7", "size": "86.66"}, {"price": "0.65", "size": "68.57"}, {"price": "0.6", "size": "50"}, {"price": "0.599", "size": "20"}, {"price": "0.598", "size": "5"}, {"price": "0.08", "size": "90"}, {"price": "0.04", "size": "17.62"}, {"price": "0.03", "size": "7"}, {"price": "0.027", "size": "16.5"}, {"price": "0.025", "size": "7"}, {"price": "0.02", "size": "7"}, {"price": "0.016", "size": "7"}, {"price": "0.011", "size": "12"}], "event_type": "book", "last_trade_price": "0.001"}, {"market": "0x1cc98e3388b008a494448ef05c62bad301d61b1e73192ea563f646ef205209d1", "asset_id": "24208114257867316046741920450990596841932558836227302708830175610444235443186", "timestamp": "1769384417499", "hash": "ab2002f89ddb50edd759258a75e88362e15f5428", "bids": [{"price": "0.001", "size": "1065.73"}], "asks": [{"price": "0.999", "size": "4070.99"}, {"price": "0.99", "size": "123"}, {"price": "0.989", "size": "5.73"}, {"price": "0.95", "size": "30"}, {"price": "0.937", "size": "31"}, {"price": "0.936", "size": "25.63"}, {"price": "0.5", "size": "50"}, {"price": "0.499", "size": "20"}, {"price": "0.183", "size": "50"}, {"price": "0.18", "size": "34"}, {"price": "0.179", "size": "45"}, {"price": "0.168", "size": "30"}, {"price": "0.084", "size": "10"}], "event_type": "book", "last_trade_price": "0.902"}, {"market": "0xfd4d63b87d452451524c012b34422ce17d79a2ad8506dcd99630d20986cffc6c", "asset_id": "85706890002666730040133427101415019283931076549192427865944188977254431727460", "timestamp": "1769384400599", "hash": "83a1c3b01c8c6a4e783eeaf316357bcf5ca87aba", "bids": [{"price": "0.01", "size": "106.33"}, {"price": "0.05", "size": "47.76"}], "asks": [{"price": "0.99", "size": "4123"}, {"price": "0.98", "size": "1800"}, {"price": "0.95", "size": "30"}, {"price": "0.94", "size": "33"}, {"price": "0.92", "size": "650"}, {"price": "0.88", "size": "283.33"}, {"price": "0.84", "size": "200"}, {"price": "0.8", "size": "240"}, {"price": "0.76", "size": "108.33"}, {"price": "0.73", "size": "50"}, {"price": "0.72", "size": "85.71"}, {"price": "0.68", "size": "62.5"}, {"price": "0.66", "size": "50"}, {"price": "0.65", "size": "5"}, {"price": "0.5", "size": "58"}, {"price": "0.37", "size": "30"}, {"price": "0.3", "size": "100"}, {"price": "0.25", "size": "20"}], "event_type": "book", "last_trade_price": ""}, {"market": "0x5aed2428cc06418d09f2ce809ecb8f1e650f9810ca7ffa580d8198b2485b82a2", "asset_id": "74021919747762703818371920869032012091337884966295339545160428820529526807612", "timestamp": "1769384273839", "hash": "0c8b12a78cfac4879dc323063563320ffc13cda1", "bids": [{"price": "0.001", "size": "7204.18"}, {"price": "0.002", "size": "27.51"}, {"price": "0.01", "size": "123"}, {"price": "0.011", "size": "5.41"}, {"price": "0.02", "size": "800"}, {"price": "0.021", "size": "8.05"}, {"price": "0.05", "size": "30"}, {"price": "0.051", "size": "13.01"}, {"price": "0.1", "size": "360"}, {"price": "0.15", "size": "226.66"}, {"price": "0.2", "size": "160"}, {"price": "0.201", "size": "5.2"}, {"price": "0.25", "size": "112"}, {"price": "0.3", "size": "86.66"}, {"price": "0.35", "size": "68.57"}, {"price": "0.4", "size": "50"}, {"price": "0.5", "size": "50"}, {"price": "0.501", "size": "25"}, {"price": "0.888", "size": "35"}, {"price": "0.98", "size": "7"}, {"price": "0.99", "size": "7"}], "asks": [{"price": "0.999", "size": "1432.99"}], "event_type": "book", "last_trade_price": "0.010"}, {"market": "0x1cc98e3388b008a494448ef05c62bad301d61b1e73192ea563f646ef205209d1", "asset_id": "61587484925357220620822959423222817449642342451321057905286571851665076728447", "timestamp": "1769384417499", "hash": "8f96563b925a69ffcc7266aa4bb50e738ea6cf90", "bids": [{"price": "0.001", "size": "4070.99"}, {"price": "0.01", "size": "123"}, {"price": "0.011", "size": "5.73"}, {"price": "0.05", "size": "30"}, {"price": "0.063", "size": "31"}, {"price": "0.064", "size": "25.63"}, {"price": "0.5", "size": "50"}, {"price": "0.501", "size": "20"}, {"price": "0.817", "size": "50"}, {"price": "0.82", "size": "34"}, {"price": "0.821", "size": "45"}, {"price": "0.832", "size": "30"}, {"price": "0.916", "size": "10"}], "asks": [{"price": "0.999", "size": "1065.73"}], "event_type": "book", "last_trade_price": "0.902"}, {"market": "0xd77e17a14e200e8ba39628152afb9a10a650d7a4df78a5c0c32d2c0d00438497", "asset_id": "20646024614518848979253481451471247924363690492887737547762322712372601906082", "timestamp": "1769384424485", "hash": "04de4e9cef10b925835155fdf3c8deaa4cff59c6", "bids": [{"price": "0.01", "size": "80.34"}, {"price": "0.02", "size": "15.59"}, {"price": "0.05", "size": "47.76"}, {"price": "0.06", "size": "19.39"}, {"price": "0.21", "size": "80"}], "asks": [{"price": "0.99", "size": "4123"}, {"price": "0.98", "size": "1800"}, {"price": "0.97", "size": "11.11"}, {"price": "0.95", "size": "60"}, {"price": "0.94", "size": "433"}, {"price": "0.82", "size": "300"}, {"price": "0.81", "size": "150"}, {"price": "0.64", "size": "100"}, {"price": "0.5", "size": "8"}, {"price": "0.46", "size": "50"}, {"price": "0.44", "size": "6.88"}], "event_type": "book", "last_trade_price": "0.620"}, {"market": "0x4c2d754e7c24fb9d4023fea135b2d2fd6974e2b65bbabdf32ec54ab004e3094e", "asset_id": "94573874879413366791871863953905517346163874608980882390521603877946886896050", "timestamp": "1769384273841", "hash": "f16614f9ea3eedc5d3b607b07c375950b03ec2f3", "bids": [{"price": "0.001", "size": "6176.18"}, {"price": "0.002", "size": "1256.17"}, {"price": "0.003", "size": "1000"}, {"price": "0.004", "size": "10.67"}, {"price": "0.01", "size": "4123"}, {"price": "0.011", "size": "5.41"}, {"price": "0.02", "size": "1800"}, {"price": "0.021", "size": "10.59"}, {"price": "0.05", "size": "30"}, {"price": "0.06", "size": "400"}, {"price": "0.061", "size": "10"}, {"price": "0.1", "size": "360"}, {"price": "0.15", "size": "226.66"}, {"price": "0.2", "size": "260"}, {"price": "0.201", "size": "5.2"}, {"price": "0.25", "size": "112"}, {"price": "0.27", "size": "50"}, {"price": "0.3", "size": "86.66"}, {"price": "0.34", "size": "50"}, {"price": "0.35", "size": "68.57"}, {"price": "0.4", "size": "50"}, {"price": "0.401", "size": "20"}, {"price": "0.402", "size": "5"}, {"price": "0.889", "size": "5"}, {"price": "0.892", "size": "107.75"}, {"price": "0.945", "size": "50"}, {"price": "0.95", "size": "50"}, {"price": "0.976", "size": "33.75"}, {"price": "0.991", "size": "88.6"}], "asks": [{"price": "0.999", "size": "1969.99"}, {"price": "0.998", "size": "234.97"}], "event_type": "book", "last_trade_price": "0.002"}, {"market": "0x5aed2428cc06418d09f2ce809ecb8f1e650f9810ca7ffa580d8198b2485b82a2", "asset_id": "100021065579084940736063823889502644589195267758520773095016000368725874938342", "timestamp": "1769384273839", "hash": "25cf10a33166ef08d92edf1bd353eef54d52dc3c", "bids": [{"price": "0.001", "size": "1432.99"}], "asks": [{"price": "0.999", "size": "7204.18"}, {"price": "0.998", "size": "27.51"}, {"price": "0.99", "size": "123"}, {"price": "0.989", "size": "5.41"}, {"price": "0.98", "size": "800"}, {"price": "0.979", "size": "8.05"}, {"price": "0.95", "size": "30"}, {"price": "0.949", "size": "13.01"}, {"price": "0.9", "size": "360"}, {"price": "0.85", "size": "226.66"}, {"price": "0.8", "size": "160"}, {"price": "0.799", "size": "5.2"}, {"price": "0.75", "size": "112"}, {"price": "0.7", "size": "86.66"}, {"price": "0.65", "size": "68.57"}, {"price": "0.6", "size": "50"}, {"price": "0.5", "size": "50"}, {"price": "0.499", "size": "25"}, {"price": "0.112", "size": "35"}, {"price": "0.02", "size": "7"}, {"price": "0.01", "size": "7"}], "event_type": "book", "last_trade_price": "0.010"}, {"market": "0xd77e17a14e200e8ba39628152afb9a10a650d7a4df78a5c0c32d2c0d00438497", "asset_id": "112293333149300959260536867050041277128420756685297458675303614200002918687623", "timestamp": "1769384424485", "hash": "cccc948667ba2cf12cf9d72d2e9b929035a8e436", "bids": [{"price": "0.01", "size": "4123"}, {"price": "0.02", "size": "1800"}, {"price": "0.03", "size": "11.11"}, {"price": "0.05", "size": "60"}, {"price": "0.06", "size": "433"}, {"price": "0.18", "size": "300"}, {"price": "0.19", "size": "150"}, {"price": "0.36", "size": "100"}, {"price": "0.5", "size": "8"}, {"price": "0.54", "size": "50"}, {"price": "0.56", "size": "6.88"}], "asks": [{"price": "0.99", "size": "80.34"}, {"price": "0.98", "size": "15.59"}, {"price": "0.95", "size": "47.76"}, {"price": "0.94", "size": "19.39"}, {"price": "0.79", "size": "80"}], "event_type": "book", "last_trade_price": "0.620"}, {"market": "0xfd4d63b87d452451524c012b34422ce17d79a2ad8506dcd99630d20986cffc6c", "asset_id": "62495477629246824566352773417644552473546059979364789192618873139681745624169", "timestamp": "1769384400599", "hash": "71298cd0452c9a8994bf21d613b50fc1019f76ca", "bids": [{"price": "0.01", "size": "4123"}, {"price": "0.02", "size": "1800"}, {"price": "0.05", "size": "30"}, {"price": "0.06", "size": "33"}, {"price": "0.08", "size": "650"}, {"price": "0.12", "size": "283.33"}, {"price": "0.16", "size": "200"}, {"price": "0.2", "size": "240"}, {"price": "0.24", "size": "108.33"}, {"price": "0.27", "size": "50"}, {"price": "0.28", "size": "85.71"}, {"price": "0.32", "size": "62.5"}, {"price": "0.34", "size": "50"}, {"price": "0.35", "size": "5"}, {"price": "0.5", "size": "58"}, {"price": "0.63", "size": "30"}, {"price": "0.7", "size": "100"}, {"price": "0.75", "size": "20"}], "asks": [{"price": "0.99", "size": "106.33"}, {"price": "0.95", "size": "47.76"}], "event_type": "book", "last_trade_price": ""}, {"market": "0x4c2d754e7c24fb9d4023fea135b2d2fd6974e2b65bbabdf32ec54ab004e3094e", "asset_id": "39373623011212403172160377238273277794513317822013997037546842124128973842671", "timestamp": "1769384273841", "hash": "29b19e43b67624314728850806c3950f291d405b", "bids": [{"price": "0.001", "size": "1969.99"}, {"price": "0.002", "size": "234.97"}], "asks": [{"price": "0.999", "size": "6176.18"}, {"price": "0.998", "size": "1256.17"}, {"price": "0.997", "size": "1000"}, {"price": "0.996", "size": "10.67"}, {"price": "0.99", "size": "4123"}, {"price": "0.989", "size": "5.41"}, {"price": "0.98", "size": "1800"}, {"price": "0.979", "size": "10.59"}, {"price": "0.95", "size": "30"}, {"price": "0.94", "size": "400"}, {"price": "0.939", "size": "10"}, {"price": "0.9", "size": "360"}, {"price": "0.85", "size": "226.66"}, {"price": "0.8", "size": "260"}, {"price": "0.799", "size": "5.2"}, {"price": "0.75", "size": "112"}, {"price": "0.73", "size": "50"}, {"price": "0.7", "size": "86.66"}, {"price": "0.66", "size": "50"}, {"price": "0.65", "size": "68.57"}, {"price": "0.6", "size": "50"}, {"price": "0.599", "size": "20"}, {"price": "0.598", "size": "5"}, {"price": "0.111", "size": "5"}, {"price": "0.108", "size": "107.75"}, {"price": "0.055", "size": "50"}, {"price": "0.05", "size": "50"}, {"price": "0.024", "size": "33.75"}, {"price": "0.009", "size": "88.6"}], "event_type": "book", "last_trade_price": "0.002"}, {"market": "0xa5ea40ac631a40071430323150632a1555ad1687e00a8085139add2d911c9f34", "asset_id": "8685396856010324986284872647116218952058192899553342786948483493131886453135", "timestamp": "1769384273835", "hash": "6c96016e50da8437506405c53b29cf78c8e90faf", "bids": [{"price": "0.001", "size": "7231.18"}, {"price": "0.002", "size": "27.51"}, {"price": "0.01", "size": "123"}, {"price": "0.011", "size": "5.41"}, {"price": "0.02", "size": "800"}, {"price": "0.021", "size": "8.05"}, {"price": "0.05", "size": "30"}, {"price": "0.051", "size": "13.01"}, {"price": "0.1", "size": "360"}, {"price": "0.15", "size": "226.66"}, {"price": "0.2", "size": "160"}, {"price": "0.201", "size": "5.2"}, {"price": "0.25", "size": "112"}, {"price": "0.3", "size": "86.66"}, {"price": "0.35", "size": "68.57"}, {"price": "0.4", "size": "50"}, {"price": "0.401", "size": "20"}, {"price": "0.402", "size": "5"}, {"price": "0.92", "size": "90"}, {"price": "0.96", "size": "17.62"}, {"price": "0.97", "size": "7"}, {"price": "0.973", "size": "16.5"}, {"price": "0.975", "size": "7"}, {"price": "0.98", "size": "7"}, {"price": "0.984", "size": "7"}, {"price": "0.989", "size": "12"}], "asks": [{"price": "0.999", "size": "1810.87"}], "event_type": "book", "last_trade_price": "0.001"}]}
{"_local_timestamp": "2026-01-25T23:41:12.148394+00:00", "data": {"market": "0xd77e17a14e200e8ba39628152afb9a10a650d7a4df78a5c0c32d2c0d00438497", "price_changes": [{"asset_id": "20646024614518848979253481451471247924363690492887737547762322712372601906082", "price": "0.44", "size": "0", "side": "SELL", "hash": "4add99e9529717327e84e649c42903036711f5bb", "best_bid": "0.21", "best_ask": "0.46"}, {"asset_id": "112293333149300959260536867050041277128420756685297458675303614200002918687623", "price": "0.56", "size": "0", "side": "BUY", "hash": "4c66583b45b7f38cfb2249f2196166ffdf3b3fe7", "best_bid": "0.54", "best_ask": "0.79"}], "timestamp": "1769384472029", "event_type": "price_change"}}
{"_local_timestamp": "2026-01-25T23:41:13.955184+00:00", "data": {"market": "0xd77e17a14e200e8ba39628152afb9a10a650d7a4df78a5c0c32d2c0d00438497", "price_changes": [{"asset_id": "20646024614518848979253481451471247924363690492887737547762322712372601906082", "price": "0.43", "size": "6.88", "side": "SELL", "hash": "bfa5951f9fc39e40a5254686e7c8022bd6912887", "best_bid": "0.21", "best_ask": "0.43"}, {"asset_id": "112293333149300959260536867050041277128420756685297458675303614200002918687623", "price": "0.57", "size": "6.88", "side": "BUY", "hash": "5476025f3bdb24a3c0a25bf6d0e2052d14c38ea8", "best_bid": "0.57", "best_ask": "0.79"}], "timestamp": "1769384473888", "event_type": "price_change"}}
{"_local_timestamp": "2026-01-25T23:41:39.347744+00:00", "data": {"market": "0xd77e17a14e200e8ba39628152afb9a10a650d7a4df78a5c0c32d2c0d00438497", "price_changes": [{"asset_id": "112293333149300959260536867050041277128420756685297458675303614200002918687623", "price": "0.55", "size": "69.09", "side": "BUY", "hash": "ade461c35effdbbb9b71e7e4cc6c9e43862de298", "best_bid": "0.57", "best_ask": "0.79"}, {"asset_id": "20646024614518848979253481451471247924363690492887737547762322712372601906082", "price": "0.45", "size": "69.09", "side": "SELL", "hash": "2297f9a5248f92e4e6d931cef71bf7082e518207", "best_bid": "0.21", "best_ask": "0.43"}], "timestamp": "1769384499281", "event_type": "price_change"}}
{"_local_timestamp": "2026-01-25T23:41:41.309857+00:00", "data": {"market": "0xfd4d63b87d452451524c012b34422ce17d79a2ad8506dcd99630d20986cffc6c", "price_changes": [{"asset_id": "62495477629246824566352773417644552473546059979364789192618873139681745624169", "price": "0.5", "size": "38", "side": "BUY", "hash": "13091475b4c3aa81d287a344c1341622434fd014", "best_bid": "0.75", "best_ask": "0.95"}, {"asset_id": "85706890002666730040133427101415019283931076549192427865944188977254431727460", "price": "0.5", "size": "38", "side": "SELL", "hash": "6255db010610511b9af4dc1eea0547a17302f410", "best_bid": "0.05", "best_ask": "0.25"}], "timestamp": "1769384501241", "event_type": "price_change"}}
{"_local_timestamp": "2026-01-25T23:41:41.342728+00:00", "data": {"market": "0xfd4d63b87d452451524c012b34422ce17d79a2ad8506dcd99630d20986cffc6c", "price_changes": [{"asset_id": "62495477629246824566352773417644552473546059979364789192618873139681745624169", "price": "0.51", "size": "20", "side": "BUY", "hash": "78be5f16c22368e3fc51c91ca92a64712504e852", "best_bid": "0.75", "best_ask": "0.95"}, {"asset_id": "85706890002666730040133427101415019283931076549192427865944188977254431727460", "price": "0.49", "size": "20", "side": "SELL", "hash": "f74f52438e6a18663ce76c487f26b6d178844671", "best_bid": "0.05", "best_ask": "0.25"}], "timestamp": "1769384501271", "event_type": "price_change"}}
{"_local_timestamp": "2026-01-25T23:41:57.088367+00:00", "data": {"market": "0xd77e17a14e200e8ba39628152afb9a10a650d7a4df78a5c0c32d2c0d00438497", "price_changes": [{"asset_id": "112293333149300959260536867050041277128420756685297458675303614200002918687623", "price": "0.03", "size": "0", "side": "BUY", "hash": "de1af3dd58d9796cfe636601d5e3481dfe4c8ef5", "best_bid": "0.57", "best_ask": "0.79"}, {"asset_id": "20646024614518848979253481451471247924363690492887737547762322712372601906082", "price": "0.97", "size": "0", "side": "SELL", "hash": "47d3cc2e2915c3074b667646bf3d71f031c549e4", "best_bid": "0.21", "best_ask": "0.43"}], "timestamp": "1769384517003", "event_type": "price_change"}}
{"_local_timestamp": "2026-01-25T23:42:26.480701+00:00", "data": {"market": "0xfd4d63b87d452451524c012b34422ce17d79a2ad8506dcd99630d20986cffc6c", "price_changes": [{"asset_id": "62495477629246824566352773417644552473546059979364789192618873139681745624169", "price": "0.17", "size": "6.97", "side": "BUY", "hash": "755eafd6d8ffa959999dfa08a8ffca755f0f18a1", "best_bid": "0.75", "best_ask": "0.95"}, {"asset_id": "85706890002666730040133427101415019283931076549192427865944188977254431727460", "price": "0.83", "size": "6.97", "side": "SELL", "hash": "ff1b261f54fc27a2b6350370b736b7040d58e5ab", "best_bid": "0.05", "best_ask": "0.25"}], "timestamp": "1769384546336", "event_type": "price_change"}}
{"_local_timestamp": "2026-01-25T23:42:26.481681+00:00", "data": {"market": "0xfd4d63b87d452451524c012b34422ce17d79a2ad8506dcd99630d20986cffc6c", "price_changes": [{"asset_id": "62495477629246824566352773417644552473546059979364789192618873139681745624169", "price": "0.01", "size": "4135.25", "side": "BUY", "hash": "656e54bb42d0a1d28974a9b9dbc4a78685e300e8", "best_bid": "0.75", "best_ask": "0.95"}, {"asset_id": "85706890002666730040133427101415019283931076549192427865944188977254431727460", "price": "0.99", "size": "4135.25", "side": "SELL", "hash": "1b9861272a3dae22b219ee62f82c5e95e5b5ad66", "best_bid": "0.05", "best_ask": "0.25"}], "timestamp": "1769384546343", "event_type": "price_change"}}
{"_local_timestamp": "2026-01-25T23:42:26.488453+00:00", "data": {"market": "0xfd4d63b87d452451524c012b34422ce17d79a2ad8506dcd99630d20986cffc6c", "price_changes": [{"asset_id": "62495477629246824566352773417644552473546059979364789192618873139681745624169", "price": "0.03", "size": "7.52", "side": "BUY", "hash": "4420cb1a484d853b85ea53d6d44ffcf47f22b289", "best_bid": "0.75", "best_ask": "0.95"}, {"asset_id": "85706890002666730040133427101415019283931076549192427865944188977254431727460", "price": "0.97", "size": "7.52", "side": "SELL", "hash": "35fe6614b04432f652cdc5885d099152a46e199e", "best_bid": "0.05", "best_ask": "0.25"}], "timestamp": "1769384546347", "event_type": "price_change"}}
{"_local_timestamp": "2026-01-25T23:42:26.496865+00:00", "data": {"market": "0x1cc98e3388b008a494448ef05c62bad301d61b1e73192ea563f646ef205209d1", "price_changes": [{"asset_id": "61587484925357220620822959423222817449642342451321057905286571851665076728447", "price": "0.011", "size": "27.11", "side": "BUY", "hash": "b25f005880b8c9e4de9ed772a4d0d3cd2b758126", "best_bid": "0.916", "best_ask": "0.999"}, {"asset_id": "24208114257867316046741920450990596841932558836227302708830175610444235443186", "price": "0.989", "size": "27.11", "side": "SELL", "hash": "950f8470c728d333c83b3bc04f31cacb026ed967", "best_bid": "0.001", "best_ask": "0.084"}], "timestamp": "1769384546350", "event_type": "price_change"}}
{"_local_timestamp": "2026-01-25T23:42:26.497381+00:00", "data": {"market": "0x1cc98e3388b008a494448ef05c62bad301d61b1e73192ea563f646ef205209d1", "price_changes": [{"asset_id": "61587484925357220620822959423222817449642342451321057905286571851665076728447", "price": "0.001", "size": "4077.2", "side": "BUY", "hash": "092f471c6f6902b79bdf95aad883103e51569136", "best_bid": "0.916", "best_ask": "0.999"}, {"asset_id": "24208114257867316046741920450990596841932558836227302708830175610444235443186", "price": "0.999", "size": "4077.2", "side": "SELL", "hash": "5804d65eadcc24f59495a94db7a4ca501f284cfa", "best_bid": "0.001", "best_ask": "0.084"}], "timestamp": "1769384546354", "event_type": "price_change"}}
{"_local_timestamp": "2026-01-25T23:42:26.497996+00:00", "data": {"market": "0xfd4d63b87d452451524c012b34422ce17d79a2ad8506dcd99630d20986cffc6c", "price_changes": [{"asset_id": "62495477629246824566352773417644552473546059979364789192618873139681745624169", "price": "0.07", "size": "6.66", "side": "BUY", "hash": "76fe71a020c73aefd0cc2a0b7c23e10c0624f3ed", "best_bid": "0.75", "best_ask": "0.95"}, {"asset_id": "85706890002666730040133427101415019283931076549192427865944188977254431727460", "price": "0.93", "size": "6.66", "side": "SELL", "hash": "0c8d9baab3d67b356d01c5f24c68041c98fe93e7", "best_bid": "0.05", "best_ask": "0.25"}], "timestamp": "1769384546355", "event_type": "price_change"}}
{"_local_timestamp": "2026-01-25T23:42:26.498458+00:00", "data": {"market": "0x1cc98e3388b008a494448ef05c62bad301d61b1e73192ea563f646ef205209d1", "price_changes": [{"asset_id": "61587484925357220620822959423222817449642342451321057905286571851665076728447", "price": "0.002", "size": "27.58", "side": "BUY", "hash": "c4b0927b095319c837fb384cb758be99f8d6f5c2", "best_bid": "0.916", "best_ask": "0.999"}, {"asset_id": "24208114257867316046741920450990596841932558836227302708830175610444235443186", "price": "0.998", "size": "27.58", "side": "SELL", "hash": "3568dfe579361c64b62c4c1f9b1206e6d4c6a74d", "best_bid": "0.001", "best_ask": "0.084"}], "timestamp": "1769384546358", "event_type": "price_change"}}
{"_local_timestamp": "2026-01-25T23:43:18.284290+00:00", "data": {"market": "0xfd4d63b87d452451524c012b34422ce17d79a2ad8506dcd99630d20986cffc6c", "price_changes": [{"asset_id": "85706890002666730040133427101415019283931076549192427865944188977254431727460", "price": "0.01", "size": "73", "side": "BUY", "hash": "d24bcd6266075acef34ee9986a0afc075a36ca0d", "best_bid": "0.05", "best_ask": "0.25"}, {"asset_id": "62495477629246824566352773417644552473546059979364789192618873139681745624169", "price": "0.99", "size": "73", "side": "SELL", "hash": "4462389bad9ce3b70c01d65be2fffc207ed390b0", "best_bid": "0.75", "best_ask": "0.95"}], "timestamp": "1769384598172", "event_type": "price_change"}}
{"_local_timestamp": "2026-01-25T23:43:20.413582+00:00", "data": {"market": "0xfd4d63b87d452451524c012b34422ce17d79a2ad8506dcd99630d20986cffc6c", "price_changes": [{"asset_id": "85706890002666730040133427101415019283931076549192427865944188977254431727460", "price": "0.01", "size": "106.33", "side": "BUY", "hash": "0d7bbe0becfbdfdf89ff52afe987bca498bed94d", "best_bid": "0.05", "best_ask": "0.25"}, {"asset_id": "62495477629246824566352773417644552473546059979364789192618873139681745624169", "price": "0.99", "size": "106.33", "side": "SELL", "hash": "2c38097123cbc5e1068eb783c2a8065c422ec4c8", "best_bid": "0.75", "best_ask": "0.95"}], "timestamp": "1769384600294", "event_type": "price_change"}}
{"_local_timestamp": "2026-01-25T23:43:25.361245+00:00", "data": {"market": "0x1cc98e3388b008a494448ef05c62bad301d61b1e73192ea563f646ef205209d1", "price_changes": [{"asset_id": "61587484925357220620822959423222817449642342451321057905286571851665076728447", "price": "0.958", "size": "20.88", "side": "BUY", "hash": "d67322b0608b6ff176d258ec8ce0469ed40ecd34", "best_bid": "0.958", "best_ask": "0.999"}, {"asset_id": "24208114257867316046741920450990596841932558836227302708830175610444235443186", "price": "0.042", "size": "20.88", "side": "SELL", "hash": "2053f72091e9bc75f5ed9c081b72abf4426f3b66", "best_bid": "0.001", "best_ask": "0.042"}], "timestamp": "1769384605234", "event_type": "price_change"}}
{"_local_timestamp": "2026-01-25T23:43:31.105857+00:00", "data": {"market": "0xd77e17a14e200e8ba39628152afb9a10a650d7a4df78a5c0c32d2c0d00438497", "price_changes": [{"asset_id": "20646024614518848979253481451471247924363690492887737547762322712372601906082", "price": "0.01", "size": "73", "side": "BUY", "hash": "5581946be180f5e8a7afd1efc45128431360137b", "best_bid": "0.21", "best_ask": "0.43"}, {"asset_id": "112293333149300959260536867050041277128420756685297458675303614200002918687623", "price": "0.99", "size": "73", "side": "SELL", "hash": "5794979b4f838af2ce5820da0938fb5a832400a0", "best_bid": "0.57", "best_ask": "0.79"}], "timestamp": "1769384611001", "event_type": "price_change"}}
{"_local_timestamp": "2026-01-25T23:43:31.118852+00:00", "data": {"market": "0xd77e17a14e200e8ba39628152afb9a10a650d7a4df78a5c0c32d2c0d00438497", "price_changes": [{"asset_id": "20646024614518848979253481451471247924363690492887737547762322712372601906082", "price": "0.02", "size": "0", "side": "BUY", "hash": "ab968276014f9f44a4b19b0f1fa43bebc42d2ec6", "best_bid": "0.21", "best_ask": "0.43"}, {"asset_id": "112293333149300959260536867050041277128420756685297458675303614200002918687623", "price": "0.98", "size": "0", "side": "SELL", "hash": "d49ddc42d3922b25fe356056c642243221f114c8", "best_bid": "0.57", "best_ask": "0.79"}], "timestamp": "1769384611003", "event_type": "price_change"}}
{"_local_timestamp": "2026-01-25T23:43:46.669547+00:00", "data": {"market": "0xd77e17a14e200e8ba39628152afb9a10a650d7a4df78a5c0c32d2c0d00438497", "price_changes": [{"asset_id": "112293333149300959260536867050041277128420756685297458675303614200002918687623", "price": "0.55", "size": "0", "side": "BUY", "hash": "32b25f1a8a61f70955afb0fc6ea79bdb9ea82c3b", "best_bid": "0.57", "best_ask": "0.79"}, {"asset_id": "20646024614518848979253481451471247924363690492887737547762322712372601906082", "price": "0.45", "size": "0", "side": "SELL", "hash": "4c36a7140d805c3a13d2baf79e04ea0cd6a37f04", "best_bid": "0.21", "best_ask": "0.43"}], "timestamp": "1769384626603", "event_type": "price_change"}}
{"_local_timestamp": "2026-01-25T23:43:47.239151+00:00", "data": {"market": "0xfd4d63b87d452451524c012b34422ce17d79a2ad8506dcd99630d20986cffc6c", "price_changes": [{"asset_id": "62495477629246824566352773417644552473546059979364789192618873139681745624169", "price": "0.51", "size": "0", "side": "BUY", "hash": "2ff915c3cc39f4f8845ffcf66489415aa830a1e0", "best_bid": "0.75", "best_ask": "0.95"}, {"asset_id": "85706890002666730040133427101415019283931076549192427865944188977254431727460", "price": "0.49", "size": "0", "side": "SELL", "hash": "4a0b9a1d01b6afe1a4e54da79d3cd532bc7cdb9a", "best_bid": "0.05", "best_ask": "0.25"}], "timestamp": "1769384627175", "event_type": "price_change"}}
{"_local_timestamp": "2026-01-25T23:43:47.270217+00:00", "data": {"market": "0xfd4d63b87d452451524c012b34422ce17d79a2ad8506dcd99630d20986cffc6c", "price_changes": [{"asset_id": "62495477629246824566352773417644552473546059979364789192618873139681745624169", "price": "0.5", "size": "58", "side": "BUY", "hash": "0ecc94372cc058122d5fd429bd1444bc505874cc", "best_bid": "0.75", "best_ask": "0.95"}, {"asset_id": "85706890002666730040133427101415019283931076549192427865944188977254431727460", "price": "0.5", "size": "58", "side": "SELL", "hash": "7da516031cc76d97aca2f654a5b933c4e9f3cff0", "best_bid": "0.05", "best_ask": "0.25"}], "timestamp": "1769384627204", "event_type": "price_change"}}
{"_local_timestamp": "2026-01-25T23:43:57.333067+00:00", "data": {"market": "0x1cc98e3388b008a494448ef05c62bad301d61b1e73192ea563f646ef205209d1", "price_changes": [{"asset_id": "24208114257867316046741920450990596841932558836227302708830175610444235443186", "price": "0.084", "size": "5", "side": "SELL", "hash": "cbcddd1df1d837cb5036a70fa4ae5a5005752b27", "best_bid": "0.001", "best_ask": "0.042"}, {"asset_id": "61587484925357220620822959423222817449642342451321057905286571851665076728447", "price": "0.916", "size": "5", "side": "BUY", "hash": "6c70e5dc465cd4bb3f51a1e2b7c954a74b553dbc", "best_bid": "0.958", "best_ask": "0.999"}], "timestamp": "1769384637209", "event_type": "price_change"}}
{"_local_timestamp": "2026-01-25T23:44:34.010013+00:00", "data": {"market": "0x1cc98e3388b008a494448ef05c62bad301d61b1e73192ea563f646ef205209d1", "price_changes": [{"asset_id": "24208114257867316046741920450990596841932558836227302708830175610444235443186", "price": "0.042", "size": "25.88", "side": "SELL", "hash": "675fb843283894df1cffa04bf23b6ea5d19ce035", "best_bid": "0.001", "best_ask": "0.042"}, {"asset_id": "61587484925357220620822959423222817449642342451321057905286571851665076728447", "price": "0.958", "size": "25.88", "side": "BUY", "hash": "b0a9a92fc7f5842f40a90dc607bbdb68c7e3210b", "best_bid": "0.958", "best_ask": "0.999"}], "timestamp": "1769384673946", "event_type": "price_change"}}
{"_local_timestamp": "2026-01-25T23:44:39.345165+00:00", "data": {"market": "0x4c2d754e7c24fb9d4023fea135b2d2fd6974e2b65bbabdf32ec54ab004e3094e", "price_changes": [{"asset_id": "94573874879413366791871863953905517346163874608980882390521603877946886896050", "price": "0.402", "size": "0", "side": "BUY", "hash": "a4a48ee9fe309913a67942eb9beaf2376d092c5f", "best_bid": "0.991", "best_ask": "0.998"}, {"asset_id": "39373623011212403172160377238273277794513317822013997037546842124128973842671", "price": "0.598", "size": "0", "side": "SELL", "hash": "90bc88ef6e80f0642537ae5f67185d46eb5bc972", "best_bid": "0.002", "best_ask": "0.009"}], "timestamp": "1769384679278", "event_type": "price_change"}}
{"_local_timestamp": "2026-01-25T23:44:39.390962+00:00", "data": {"market": "0x4c2d754e7c24fb9d4023fea135b2d2fd6974e2b65bbabdf32ec54ab004e3094e", "price_changes": [{"asset_id": "94573874879413366791871863953905517346163874608980882390521603877946886896050", "price": "0.402", "size": "5", "side": "BUY", "hash": "6c6b14de3e6564834a4abd8109cc68a866086c0a", "best_bid": "0.991", "best_ask": "0.998"}, {"asset_id": "39373623011212403172160377238273277794513317822013997037546842124128973842671", "price": "0.598", "size": "5", "side": "SELL", "hash": "306366a69a6edfdf4be646ce99908aef629cfbcd", "best_bid": "0.002", "best_ask": "0.009"}], "timestamp": "1769384679325", "event_type": "price_change"}}
{"_local_timestamp": "2026-01-25T23:44:41.510411+00:00", "data": {"market": "0xd77e17a14e200e8ba39628152afb9a10a650d7a4df78a5c0c32d2c0d00438497", "price_changes": [{"asset_id": "20646024614518848979253481451471247924363690492887737547762322712372601906082", "price": "0.43", "size": "0", "side": "SELL", "hash": "4bf14833d80cf101dcd746935ef01d76cb9b070d", "best_bid": "0.21", "best_ask": "0.46"}, {"asset_id": "112293333149300959260536867050041277128420756685297458675303614200002918687623", "price": "0.57", "size": "0", "side": "BUY", "hash": "962a04b586aa6225d882f4810da34f2c9d77c34f", "best_bid": "0.54", "best_ask": "0.79"}], "timestamp": "1769384681444", "event_type": "price_change"}}
{"_local_timestamp": "2026-01-25T23:44:41.736117+00:00", "data": {"market": "0xd77e17a14e200e8ba39628152afb9a10a650d7a4df78a5c0c32d2c0d00438497", "price_changes": [{"asset_id": "20646024614518848979253481451471247924363690492887737547762322712372601906082", "price": "0.42", "size": "6.88", "side": "SELL", "hash": "9cba85619036dbd9601f1a3c7f0e49a8fcaa696d", "best_bid": "0.21", "best_ask": "0.42"}, {"asset_id": "112293333149300959260536867050041277128420756685297458675303614200002918687623", "price": "0.58", "size": "6.88", "side": "BUY", "hash": "23242c78021225280bc45bcb33d31de8cf7a79ac", "best_bid": "0.58", "best_ask": "0.79"}], "timestamp": "1769384681664", "event_type": "price_change"}}
{"_local_timestamp": "2026-01-25T23:44:42.032664+00:00", "data": {"market": "0xd77e17a14e200e8ba39628152afb9a10a650d7a4df78a5c0c32d2c0d00438497", "price_changes": [{"asset_id": "20646024614518848979253481451471247924363690492887737547762322712372601906082", "price": "0.02", "size": "15.73", "side": "BUY", "hash": "a3a870604f434c1bf4c3fa0107065f7a4b790c9c", "best_bid": "0.21", "best_ask": "0.42"}, {"asset_id": "112293333149300959260536867050041277128420756685297458675303614200002918687623", "price": "0.98", "size": "15.73", "side": "SELL", "hash": "8359c82613559beb6a1a9d73dc8329d53fd3dd1a", "best_bid": "0.58", "best_ask": "0.79"}], "timestamp": "1769384681936", "event_type": "price_change"}}
{"_local_timestamp": "2026-01-25T23:44:42.040486+00:00", "data": {"market": "0xd77e17a14e200e8ba39628152afb9a10a650d7a4df78a5c0c32d2c0d00438497", "price_changes": [{"asset_id": "20646024614518848979253481451471247924363690492887737547762322712372601906082", "price": "0.01", "size": "80.07", "side": "BUY", "hash": "d9eda427db94082f45e5ca8a660ad9732989ee1b", "best_bid": "0.21", "best_ask": "0.42"}, {"asset_id": "112293333149300959260536867050041277128420756685297458675303614200002918687623", "price": "0.99", "size": "80.07", "side": "SELL", "hash": "b51c8c289d441eaabbdc155b3a15c6105a45c752", "best_bid": "0.58", "best_ask": "0.79"}], "timestamp": "1769384681940", "event_type": "price_change"}}
{"_local_timestamp": "2026-01-25T23:44:47.604542+00:00", "data": {"market": "0x1cc98e3388b008a494448ef05c62bad301d61b1e73192ea563f646ef205209d1", "price_changes": [{"asset_id": "61587484925357220620822959423222817449642342451321057905286571851665076728447", "price": "0.821", "size": "0", "side": "BUY", "hash": "b1dac3cef13dc86e85c82f79d10673115e802424", "best_bid": "0.958", "best_ask": "0.999"}, {"asset_id": "24208114257867316046741920450990596841932558836227302708830175610444235443186", "price": "0.179", "size": "0", "side": "SELL", "hash": "a69a9f468614b6ad0a8082b284331ab43fa46a6a", "best_bid": "0.001", "best_ask": "0.042"}], "timestamp": "1769384687468", "event_type": "price_change"}}
{"_local_timestamp": "2026-01-25T23:44:59.896020+00:00", "data": {"market": "0xd77e17a14e200e8ba39628152afb9a10a650d7a4df78a5c0c32d2c0d00438497", "price_changes": [{"asset_id": "112293333149300959260536867050041277128420756685297458675303614200002918687623", "price": "0.55", "size": "69.09", "side": "BUY", "hash": "598ecf1b7893d2ced362a1f26d4966d2ab513c26", "best_bid": "0.58", "best_ask": "0.79"}, {"asset_id": "20646024614518848979253481451471247924363690492887737547762322712372601906082", "price": "0.45", "size": "69.09", "side": "SELL", "hash": "8523b429d45e377b1c233d4eb3f9e04939962254", "best_bid": "0.21", "best_ask": "0.42"}], "timestamp": "1769384699829", "event_type": "price_change"}}
{"_local_timestamp": "2026-01-25T23:45:01.263986+00:00", "data": {"market": "0xfd4d63b87d452451524c012b34422ce17d79a2ad8506dcd99630d20986cffc6c", "price_changes": [{"asset_id": "62495477629246824566352773417644552473546059979364789192618873139681745624169", "price": "0.5", "size": "38", "side": "BUY", "hash": "f2632f67bdd887ddac08cb858569ac0d0c3747cb", "best_bid": "0.75", "best_ask": "0.95"}, {"asset_id": "85706890002666730040133427101415019283931076549192427865944188977254431727460", "price": "0.5", "size": "38", "side": "SELL", "hash": "aa7c08c68ae35f6eaeca556182ed0d23c7e082cb", "best_bid": "0.05", "best_ask": "0.25"}], "timestamp": "1769384701194", "event_type": "price_change"}}
{"_local_timestamp": "2026-01-25T23:45:01.308378+00:00", "data": {"market": "0xfd4d63b87d452451524c012b34422ce17d79a2ad8506dcd99630d20986cffc6c", "price_changes": [{"asset_id": "62495477629246824566352773417644552473546059979364789192618873139681745624169", "price": "0.51", "size": "20", "side": "BUY", "hash": "bac29e6eba2a96d562e4c8a1bbcc3a012978abb3", "best_bid": "0.75", "best_ask": "0.95"}, {"asset_id": "85706890002666730040133427101415019283931076549192427865944188977254431727460", "price": "0.49", "size": "20", "side": "SELL", "hash": "79401ad81430c33df401e6f2c9edd8fc9a765795", "best_bid": "0.05", "best_ask": "0.25"}], "timestamp": "1769384701240", "event_type": "price_change"}}
{"_local_timestamp": "2026-01-25T23:45:19.470331+00:00", "data": {"market": "0x1cc98e3388b008a494448ef05c62bad301d61b1e73192ea563f646ef205209d1", "price_changes": [{"asset_id": "61587484925357220620822959423222817449642342451321057905286571851665076728447", "price": "0.821", "size": "45", "side": "BUY", "hash": "971a24f2c9d4b47d4f6bd957d3e376fee384d84f", "best_bid": "0.958", "best_ask": "0.999"}, {"asset_id": "24208114257867316046741920450990596841932558836227302708830175610444235443186", "price": "0.179", "size": "45", "side": "SELL", "hash": "62b46dd8078f295f4fabf0b56a238c91e91da322", "best_bid": "0.001", "best_ask": "0.042"}], "timestamp": "1769384719407", "event_type": "price_change"}}
{"_local_timestamp": "2026-01-25T23:45:24.811337+00:00", "data": {"market": "0x1cc98e3388b008a494448ef05c62bad301d61b1e73192ea563f646ef205209d1", "price_changes": [{"asset_id": "61587484925357220620822959423222817449642342451321057905286571851665076728447", "price": "0.95", "size": "5", "side": "BUY", "hash": "207d2cea3dc3f2237d302a7857ef3536f3261c8c", "best_bid": "0.958", "best_ask": "0.999"}, {"asset_id": "24208114257867316046741920450990596841932558836227302708830175610444235443186", "price": "0.05", "size": "5", "side": "SELL", "hash": "d5af3d250c57d0c2c2bed9dfe1d40cbaaff175de", "best_bid": "0.001", "best_ask": "0.042"}], "timestamp": "1769384724742", "event_type": "price_change"}}
{"_local_timestamp": "2026-01-25T23:46:05.095679+00:00", "data": {"market": "0xd77e17a14e200e8ba39628152afb9a10a650d7a4df78a5c0c32d2c0d00438497", "price_changes": [{"asset_id": "112293333149300959260536867050041277128420756685297458675303614200002918687623", "price": "0.03", "size": "11.11", "side": "BUY", "hash": "bf45d6c1192bd0eb02c8409f94c04282d8d24aa4", "best_bid": "0.58", "best_ask": "0.79"}, {"asset_id": "20646024614518848979253481451471247924363690492887737547762322712372601906082", "price": "0.97", "size": "11.11", "side": "SELL", "hash": "74592b3d7968467f64189fdc8e9a7bdac5a38f05", "best_bid": "0.21", "best_ask": "0.42"}], "timestamp": "1769384765012", "event_type": "price_change"}}
{"_local_timestamp": "2026-01-25T23:47:05.706978+00:00", "data": {"market": "0xd77e17a14e200e8ba39628152afb9a10a650d7a4df78a5c0c32d2c0d00438497", "price_changes": [{"asset_id": "112293333149300959260536867050041277128420756685297458675303614200002918687623", "price": "0.55", "size": "0", "side": "BUY", "hash": "6ab6b92aeaa36c419c2edf7bd77bc62e6e91486c", "best_bid": "0.58", "best_ask": "0.79"}, {"asset_id": "20646024614518848979253481451471247924363690492887737547762322712372601906082", "price": "0.45", "size": "0", "side": "SELL", "hash": "1cf8ad6e400010dfab088c7160f374b38d457f88", "best_bid": "0.21", "best_ask": "0.42"}], "timestamp": "1769384825634", "event_type": "price_change"}}
{"_local_timestamp": "2026-01-25T23:47:06.594922+00:00", "data": {"market": "0xfd4d63b87d452451524c012b34422ce17d79a2ad8506dcd99630d20986cffc6c", "price_changes": [{"asset_id": "62495477629246824566352773417644552473546059979364789192618873139681745624169", "price": "0.51", "size": "0", "side": "BUY", "hash": "40a3a1b6c49232b654177d64386e3cb2c931a1a1", "best_bid": "0.75", "best_ask": "0.95"}, {"asset_id": "85706890002666730040133427101415019283931076549192427865944188977254431727460", "price": "0.49", "size": "0", "side": "SELL", "hash": "27eefa908cdf08ca0c60765ef67543fbb93a94b2", "best_bid": "0.05", "best_ask": "0.25"}], "timestamp": "1769384826530", "event_type": "price_change"}}
{"_local_timestamp": "2026-01-25T23:47:06.626723+00:00", "data": {"market": "0xfd4d63b87d452451524c012b34422ce17d79a2ad8506dcd99630d20986cffc6c", "price_changes": [{"asset_id": "62495477629246824566352773417644552473546059979364789192618873139681745624169", "price": "0.5", "size": "58", "side": "BUY", "hash": "173b194256f3c0ad0fac55af26f416f091a46010", "best_bid": "0.75", "best_ask": "0.95"}, {"asset_id": "85706890002666730040133427101415019283931076549192427865944188977254431727460", "price": "0.5", "size": "58", "side": "SELL", "hash": "d776c26c1126906bf0c7ae4e5b4af7441e5b9668", "best_bid": "0.05", "best_ask": "0.25"}], "timestamp": "1769384826558", "event_type": "price_change"}}
{"_local_timestamp": "2026-01-25T23:47:08.967431+00:00", "data": {"market": "0x5aed2428cc06418d09f2ce809ecb8f1e650f9810ca7ffa580d8198b2485b82a2", "price_changes": [{"asset_id": "74021919747762703818371920869032012091337884966295339545160428820529526807612", "price": "0.501", "size": "20", "side": "BUY", "hash": "123fa76801f2787d3b081e1d6fdbd7d69072b556", "best_bid": "0.99", "best_ask": "0.999"}, {"asset_id": "100021065579084940736063823889502644589195267758520773095016000368725874938342", "price": "0.499", "size": "20", "side": "SELL", "hash": "f4cf71ac1c22038a665ca8bbca181041f8d9ddf4", "best_bid": "0.001", "best_ask": "0.01"}], "timestamp": "1769384828891", "event_type": "price_change"}}
{"_local_timestamp": "2026-01-25T23:47:09.011183+00:00", "data": {"market": "0x5aed2428cc06418d09f2ce809ecb8f1e650f9810ca7ffa580d8198b2485b82a2", "price_changes": [{"asset_id": "74021919747762703818371920869032012091337884966295339545160428820529526807612", "price": "0.501", "size": "25", "side": "BUY", "hash": "cfddc3e872786e23c4ddfc5f11514fc7c558a306", "best_bid": "0.99", "best_ask": "0.999"}, {"asset_id": "100021065579084940736063823889502644589195267758520773095016000368725874938342", "price": "0.499", "size": "25", "side": "SELL", "hash": "e713fba976e7436fa191708d0486f3cc5375655b", "best_bid": "0.001", "best_ask": "0.01"}], "timestamp": "1769384828947", "event_type": "price_change"}}
{"_local_timestamp": "2026-01-25T23:47:16.098950+00:00", "data": {"market": "0xd77e17a14e200e8ba39628152afb9a10a650d7a4df78a5c0c32d2c0d00438497", "price_changes": [{"asset_id": "20646024614518848979253481451471247924363690492887737547762322712372601906082", "price": "0.06", "size": "0", "side": "BUY", "hash": "306d18736b5a61901115a1f857bcdd90f596f03e", "best_bid": "0.21", "best_ask": "0.42"}, {"asset_id": "112293333149300959260536867050041277128420756685297458675303614200002918687623", "price": "0.94", "size": "0", "side": "SELL", "hash": "02ad48da8cde76a9d9bb87e72bd0a1b63543e09a", "best_bid": "0.58", "best_ask": "0.79"}], "timestamp": "1769384836005", "event_type": "price_change"}}
{"_local_timestamp": "2026-01-25T23:47:45.066067+00:00", "data": {"market": "0x1cc98e3388b008a494448ef05c62bad301d61b1e73192ea563f646ef205209d1", "price_changes": [{"asset_id": "61587484925357220620822959423222817449642342451321057905286571851665076728447", "price": "0.011", "size": "21.38", "side": "BUY", "hash": "ca4c652400c4c3ea7732913aace870d3a5c92bba", "best_bid": "0.958", "best_ask": "0.999"}, {"asset_id": "24208114257867316046741920450990596841932558836227302708830175610444235443186", "price": "0.989", "size": "21.38", "side": "SELL", "hash": "030e89d7d8c8b0fd59b2bc3719ffb9287e4b72e6", "best_bid": "0.001", "best_ask": "0.042"}], "timestamp": "1769384865000", "event_type": "price_change"}}
{"_local_timestamp": "2026-01-25T23:47:45.066663+00:00", "data": {"market": "0x1cc98e3388b008a494448ef05c62bad301d61b1e73192ea563f646ef205209d1", "price_changes": [{"asset_id": "61587484925357220620822959423222817449642342451321057905286571851665076728447", "price": "0.064", "size": "0", "side": "BUY", "hash": "8d50cd42b36fb46780444488186cbd5f6961662c", "best_bid": "0.958", "best_ask": "0.999"}, {"asset_id": "24208114257867316046741920450990596841932558836227302708830175610444235443186", "price": "0.936", "size": "0", "side": "SELL", "hash": "8a9731f7c4cd709dbced47de29c3de26491fc8c8", "best_bid": "0.001", "best_ask": "0.042"}], "timestamp": "1769384865001", "event_type": "price_change"}}
{"_local_timestamp": "2026-01-25T23:47:57.077989+00:00", "data": {"market": "0x5aed2428cc06418d09f2ce809ecb8f1e650f9810ca7ffa580d8198b2485b82a2", "price_changes": [{"asset_id": "74021919747762703818371920869032012091337884966295339545160428820529526807612", "price": "0.021", "size": "0", "side": "BUY", "hash": "90311098e26074d62d7789a3a09ff94ba5032b10", "best_bid": "0.99", "best_ask": "0.999"}, {"asset_id": "100021065579084940736063823889502644589195267758520773095016000368725874938342", "price": "0.979", "size": "0", "side": "SELL", "hash": "337731085fc95238b15ae85e64d44a8ce74d8a71", "best_bid": "0.001", "best_ask": "0.01"}], "timestamp": "1769384877000", "event_type": "price_change"}}
{"_local_timestamp": "2026-01-25T23:47:57.082889+00:00", "data": {"market": "0xa5ea40ac631a40071430323150632a1555ad1687e00a8085139add2d911c9f34", "price_changes": [{"asset_id": "8685396856010324986284872647116218952058192899553342786948483493131886453135", "price": "0.002", "size": "0", "side": "BUY", "hash": "a06db0c2e60d60a4317d0c92490b9ab50f77eeb5", "best_bid": "0.989", "best_ask": "0.999"}, {"asset_id": "110173687573613171160959717033136753568422637870529083487941219617533969558974", "price": "0.998", "size": "0", "side": "SELL", "hash": "2f0f70667c681ef33d1eabdf95358953d45bc626", "best_bid": "0.001", "best_ask": "0.011"}], "timestamp": "1769384877000", "event_type": "price_change"}}
{"_local_timestamp": "2026-01-25T23:47:57.089915+00:00", "data": {"market": "0x5aed2428cc06418d09f2ce809ecb8f1e650f9810ca7ffa580d8198b2485b82a2", "price_changes": [{"asset_id": "74021919747762703818371920869032012091337884966295339545160428820529526807612", "price": "0.001", "size": "7197.99", "side": "BUY", "hash": "e11af7e6280a99ef320463f5631964403287eb65", "best_bid": "0.99", "best_ask": "0.999"}, {"asset_id": "100021065579084940736063823889502644589195267758520773095016000368725874938342", "price": "0.999", "size": "7197.99", "side": "SELL", "hash": "69df624777d320a917242513f51435c3599af18f", "best_bid": "0.001", "best_ask": "0.01"}], "timestamp": "1769384877001", "event_type": "price_change"}}
{"_local_timestamp": "2026-01-25T23:47:57.090505+00:00", "data": {"market": "0x4c2d754e7c24fb9d4023fea135b2d2fd6974e2b65bbabdf32ec54ab004e3094e", "price_changes": [{"asset_id": "94573874879413366791871863953905517346163874608980882390521603877946886896050", "price": "0.021", "size": "0", "side": "BUY", "hash": "902ffc9fd821a452fe289a2174e6f735a8353689", "best_bid": "0.991", "best_ask": "0.998"}, {"asset_id": "39373623011212403172160377238273277794513317822013997037546842124128973842671", "price": "0.979", "size": "0", "side": "SELL", "hash": "a7d1ec319bc5bddf53ddc6bc0056e77f5a63dd9d", "best_bid": "0.002", "best_ask": "0.009"}], "timestamp": "1769384877001", "event_type": "price_change"}}
{"_local_timestamp": "2026-01-25T23:47:57.097053+00:00", "data": {"market": "0x4c2d754e7c24fb9d4023fea135b2d2fd6974e2b65bbabdf32ec54ab004e3094e", "price_changes": [{"asset_id": "94573874879413366791871863953905517346163874608980882390521603877946886896050", "price": "0.002", "size": "1250", "side": "BUY", "hash": "6fb7021c054457128bba38962f430c3ab2caaab4", "best_bid": "0.991", "best_ask": "0.998"}, {"asset_id": "39373623011212403172160377238273277794513317822013997037546842124128973842671", "price": "0.998", "size": "1250", "side": "SELL", "hash": "054aabb6bb09016029226f020328796b0d8a1c3e", "best_bid": "0.002", "best_ask": "0.009"}], "timestamp": "1769384877003", "event_type": "price_change"}}
{"_local_timestamp": "2026-01-25T23:47:57.105011+00:00", "data": {"market": "0xa5ea40ac631a40071430323150632a1555ad1687e00a8085139add2d911c9f34", "price_changes": [{"asset_id": "8685396856010324986284872647116218952058192899553342786948483493131886453135", "price": "0.051", "size": "0", "side": "BUY", "hash": "176f3d591faf62f4ac07a71eeb94228c6a987525", "best_bid": "0.989", "best_ask": "0.999"}, {"asset_id": "110173687573613171160959717033136753568422637870529083487941219617533969558974", "price": "0.949", "size": "0", "side": "SELL", "hash": "c7ce4d4285503870306f7ec895b95b0bb712ef98", "best_bid": "0.001", "best_ask": "0.011"}], "timestamp": "1769384877003", "event_type": "price_change"}}
{"_local_timestamp": "2026-01-25T23:47:57.117276+00:00", "data": {"market": "0xa5ea40ac631a40071430323150632a1555ad1687e00a8085139add2d911c9f34", "price_changes": [{"asset_id": "8685396856010324986284872647116218952058192899553342786948483493131886453135", "price": "0.001", "size": "7224.99", "side": "BUY", "hash": "343f9f0cdd4c4ae40484669b2c1938e9c5d03f2d", "best_bid": "0.989", "best_ask": "0.999"}, {"asset_id": "110173687573613171160959717033136753568422637870529083487941219617533969558974", "price": "0.999", "size": "7224.99", "side": "SELL", "hash": "9d857179e9efe784dfa999399a41d4d0da4ff617", "best_bid": "0.001", "best_ask": "0.011"}], "timestamp": "1769384877004", "event_type": "price_change"}}
{"_local_timestamp": "2026-01-25T23:47:57.117874+00:00", "data": {"market": "0xa5ea40ac631a40071430323150632a1555ad1687e00a8085139add2d911c9f34", "price_changes": [{"asset_id": "8685396856010324986284872647116218952058192899553342786948483493131886453135", "price": "0.201", "size": "0", "side": "BUY", "hash": "43bdedcbe1a837335b9ea8827084c2f2a059847f", "best_bid": "0.989", "best_ask": "0.999"}, {"asset_id": "110173687573613171160959717033136753568422637870529083487941219617533969558974", "price": "0.799", "size": "0", "side": "SELL", "hash": "2400fba5a708422d14dd114156b67e78703faa29", "best_bid": "0.001", "best_ask": "0.011"}], "timestamp": "1769384877005", "event_type": "price_change"}}
{"_local_timestamp": "2026-01-25T23:47:57.118442+00:00", "data": {"market": "0x4c2d754e7c24fb9d4023fea135b2d2fd6974e2b65bbabdf32ec54ab004e3094e", "price_changes": [{"asset_id": "94573874879413366791871863953905517346163874608980882390521603877946886896050", "price": "0.011", "size": "0", "side": "BUY", "hash": "1614d860ca83b5fca64025f6812e98172074b174", "best_bid": "0.991", "best_ask": "0.998"}, {"asset_id": "39373623011212403172160377238273277794513317822013997037546842124128973842671", "price": "0.989", "size": "0", "side": "SELL", "hash": "5ff8f319a27c7846f4bcdd22cc57c91cdd0e8fa7", "best_bid": "0.002", "best_ask": "0.009"}], "timestamp": "1769384877004", "event_type": "price_change"}}
{"_local_timestamp": "2026-01-25T23:47:57.118963+00:00", "data": {"market": "0xa5ea40ac631a40071430323150632a1555ad1687e00a8085139add2d911c9f34", "price_changes": [{"asset_id": "8685396856010324986284872647116218952058192899553342786948483493131886453135", "price": "0.011", "size": "0", "side": "BUY", "hash": "3e5efcaa4c322f537b3935765cc54a0bb1a64a1b", "best_bid": "0.989", "best_ask": "0.999"}, {"asset_id": "110173687573613171160959717033136753568422637870529083487941219617533969558974", "price": "0.989", "size": "0", "side": "SELL", "hash": "14724e20c5fd5208bdd29344f969239fe9cc9252", "best_bid": "0.001", "best_ask": "0.011"}], "timestamp": "1769384877006", "event_type": "price_change"}}
{"_local_timestamp": "2026-01-25T23:47:57.210734+00:00", "data": {"market": "0x5aed2428cc06418d09f2ce809ecb8f1e650f9810ca7ffa580d8198b2485b82a2", "price_changes": [{"asset_id": "74021919747762703818371920869032012091337884966295339545160428820529526807612", "price": "0.011", "size": "0", "side": "BUY", "hash": "2af567da318d0ad696116b52e4fdf8aa00af4770", "best_bid": "0.99", "best_ask": "0.999"}, {"asset_id": "100021065579084940736063823889502644589195267758520773095016000368725874938342", "price": "0.989", "size": "0", "side": "SELL", "hash": "f1dfefc8fd134c97f25509d11f27020e4e0cd8de", "best_bid": "0.001", "best_ask": "0.01"}], "timestamp": "1769384877004", "event_type": "price_change"}}
{"_local_timestamp": "2026-01-25T23:47:57.211329+00:00", "data": {"market": "0x4c2d754e7c24fb9d4023fea135b2d2fd6974e2b65bbabdf32ec54ab004e3094e", "price_changes": [{"asset_id": "94573874879413366791871863953905517346163874608980882390521603877946886896050", "price": "0.004", "size": "0", "side": "BUY", "hash": "6c410c4d977d4efa7788d943370c850b6f3f2c0f", "best_bid": "0.991", "best_ask": "0.998"}, {"asset_id": "39373623011212403172160377238273277794513317822013997037546842124128973842671", "price": "0.996", "size": "0", "side": "SELL", "hash": "51c69a906000a2cf72df2a741c1111163db4f953", "best_bid": "0.002", "best_ask": "0.009"}], "timestamp": "1769384877006", "event_type": "price_change"}}
{"_local_timestamp": "2026-01-25T23:47:57.211886+00:00", "data": {"market": "0xa5ea40ac631a40071430323150632a1555ad1687e00a8085139add2d911c9f34", "price_changes": [{"asset_id": "8685396856010324986284872647116218952058192899553342786948483493131886453135", "price": "0.021", "size": "0", "side": "BUY", "hash": "3e5efcaa4c322f537b3935765cc54a0bb1a64a1b", "best_bid": "0.989", "best_ask": "0.999"}, {"asset_id": "110173687573613171160959717033136753568422637870529083487941219617533969558974", "price": "0.979", "size": "0", "side": "SELL", "hash": "14724e20c5fd5208bdd29344f969239fe9cc9252", "best_bid": "0.001", "best_ask": "0.011"}], "timestamp": "1769384877006", "event_type": "price_change"}}
{"_local_timestamp": "2026-01-25T23:47:57.212453+00:00", "data": {"market": "0x4c2d754e7c24fb9d4023fea135b2d2fd6974e2b65bbabdf32ec54ab004e3094e", "price_changes": [{"asset_id": "94573874879413366791871863953905517346163874608980882390521603877946886896050", "price": "0.061", "size": "0", "side": "BUY", "hash": "16f902c7b24fb1cd6c598cdbb9d9d61f96f32ece", "best_bid": "0.991", "best_ask": "0.998"}, {"asset_id": "39373623011212403172160377238273277794513317822013997037546842124128973842671", "price": "0.939", "size": "0", "side": "SELL", "hash": "56766a85a26bc04b4108a0556ca5339a1c137a14", "best_bid": "0.002", "best_ask": "0.009"}], "timestamp": "1769384877008", "event_type": "price_change"}}
{"_local_timestamp": "2026-01-25T23:47:57.219655+00:00", "data": {"market": "0x5aed2428cc06418d09f2ce809ecb8f1e650f9810ca7ffa580d8198b2485b82a2", "price_changes": [{"asset_id": "74021919747762703818371920869032012091337884966295339545160428820529526807612", "price": "0.201", "size": "0", "side": "BUY", "hash": "85ca1e9e743a7276074eecef5a5b199c4eeee149", "best_bid": "0.99", "best_ask": "0.999"}, {"asset_id": "100021065579084940736063823889502644589195267758520773095016000368725874938342", "price": "0.799", "size": "0", "side": "SELL", "hash": "3941cc3fcce62a5370698b10aac9525295f0759f", "best_bid": "0.001", "best_ask": "0.01"}], "timestamp": "1769384877008", "event_type": "price_change"}}
{"_local_timestamp": "2026-01-25T23:47:57.220243+00:00", "data": {"market": "0x5aed2428cc06418d09f2ce809ecb8f1e650f9810ca7ffa580d8198b2485b82a2", "price_changes": [{"asset_id": "74021919747762703818371920869032012091337884966295339545160428820529526807612", "price": "0.002", "size": "0", "side": "BUY", "hash": "a9003d86b58e32ce36b3b3dec4c8f4cb562c055c", "best_bid": "0.99", "best_ask": "0.999"}, {"asset_id": "100021065579084940736063823889502644589195267758520773095016000368725874938342", "price": "0.998", "size": "0", "side": "SELL", "hash": "f0e749c465ea76cbb7b2d161c74840f5c74c8152", "best_bid": "0.001", "best_ask": "0.01"}], "timestamp": "1769384877009", "event_type": "price_change"}}
{"_local_timestamp": "2026-01-25T23:47:57.220809+00:00", "data": {"market": "0x5aed2428cc06418d09f2ce809ecb8f1e650f9810ca7ffa580d8198b2485b82a2", "price_changes": [{"asset_id": "74021919747762703818371920869032012091337884966295339545160428820529526807612", "price": "0.051", "size": "0", "side": "BUY", "hash": "4e6b6b40fb07339e9f0c130149d56158dff38361", "best_bid": "0.99", "best_ask": "0.999"}, {"asset_id": "100021065579084940736063823889502644589195267758520773095016000368725874938342", "price": "0.949", "size": "0", "side": "SELL", "hash": "6c61a635fc0c85ad6ac0f7df7d516bab26564038", "best_bid": "0.001", "best_ask": "0.01"}], "timestamp": "1769384877010", "event_type": "price_change"}}
{"_local_timestamp": "2026-01-25T23:47:57.221359+00:00", "data": {"market": "0x4c2d754e7c24fb9d4023fea135b2d2fd6974e2b65bbabdf32ec54ab004e3094e", "price_changes": [{"asset_id": "94573874879413366791871863953905517346163874608980882390521603877946886896050", "price": "0.201", "size": "0", "side": "BUY", "hash": "30b6364d8da5d39b10e18cd45c97690cb11111a1", "best_bid": "0.991", "best_ask": "0.998"}, {"asset_id": "39373623011212403172160377238273277794513317822013997037546842124128973842671", "price": "0.799", "size": "0", "side": "SELL", "hash": "9be53b865f977ada25be5f91a6cb4d41e8087048", "best_bid": "0.002", "best_ask": "0.009"}], "timestamp": "1769384877009", "event_type": "price_change"}}
{"_local_timestamp": "2026-01-25T23:47:57.221904+00:00", "data": {"market": "0x4c2d754e7c24fb9d4023fea135b2d2fd6974e2b65bbabdf32ec54ab004e3094e", "price_changes": [{"asset_id": "94573874879413366791871863953905517346163874608980882390521603877946886896050", "price": "0.001", "size": "6169.99", "side": "BUY", "hash": "be6679f7be5f49c722fd59b83786cd60b2669b82", "best_bid": "0.991", "best_ask": "0.998"}, {"asset_id": "39373623011212403172160377238273277794513317822013997037546842124128973842671", "price": "0.999", "size": "6169.99", "side": "SELL", "hash": "3fa9bc80bfcd99dfb5dd856e121683a3fd90c868", "best_bid": "0.002", "best_ask": "0.009"}], "timestamp": "1769384877011", "event_type": "price_change"}}
{"_local_timestamp": "2026-01-25T23:47:59.295063+00:00", "data": {"market": "0xa5ea40ac631a40071430323150632a1555ad1687e00a8085139add2d911c9f34", "price_changes": [{"asset_id": "8685396856010324986284872647116218952058192899553342786948483493131886453135", "price": "0.002", "size": "27.51", "side": "BUY", "hash": "fd3a266938eea97f777a8ba9b95d8bbed54dd5a1", "best_bid": "0.989", "best_ask": "0.999"}, {"asset_id": "110173687573613171160959717033136753568422637870529083487941219617533969558974", "price": "0.998", "size": "27.51", "side": "SELL", "hash": "67714ec39a513ba3afcb8c7ffec44e2551559420", "best_bid": "0.001", "best_ask": "0.011"}], "timestamp": "1769384879226", "event_type": "price_change"}}
{"_local_timestamp": "2026-01-25T23:47:59.298554+00:00", "data": {"market": "0xa5ea40ac631a40071430323150632a1555ad1687e00a8085139add2d911c9f34", "price_changes": [{"asset_id": "8685396856010324986284872647116218952058192899553342786948483493131886453135", "price": "0.001", "size": "7231.18", "side": "BUY", "hash": "33627341d74ae31d56246fe2763b43d638e5dc74", "best_bid": "0.989", "best_ask": "0.999"}, {"asset_id": "110173687573613171160959717033136753568422637870529083487941219617533969558974", "price": "0.999", "size": "7231.18", "side": "SELL", "hash": "7a50684a6edddc2d6ec7b4b608cf73da18839737", "best_bid": "0.001", "best_ask": "0.011"}], "timestamp": "1769384879228", "event_type": "price_change"}}
{"_local_timestamp": "2026-01-25T23:47:59.299232+00:00", "data": {"market": "0xa5ea40ac631a40071430323150632a1555ad1687e00a8085139add2d911c9f34", "price_changes": [{"asset_id": "8685396856010324986284872647116218952058192899553342786948483493131886453135", "price": "0.201", "size": "5.2", "side": "BUY", "hash": "bfb0a377bd4e22a93412a51246d8b8dc47f6791b", "best_bid": "0.989", "best_ask": "0.999"}, {"asset_id": "110173687573613171160959717033136753568422637870529083487941219617533969558974", "price": "0.799", "size": "5.2", "side": "SELL", "hash": "6e9e6704ade2a37f071e84cd005165a6850986be", "best_bid": "0.001", "best_ask": "0.011"}], "timestamp": "1769384879228", "event_type": "price_change"}}
{"_local_timestamp": "2026-01-25T23:47:59.299854+00:00", "data": {"market": "0xa5ea40ac631a40071430323150632a1555ad1687e00a8085139add2d911c9f34", "price_changes": [{"asset_id": "8685396856010324986284872647116218952058192899553342786948483493131886453135", "price": "0.011", "size": "5.41", "side": "BUY", "hash": "d093a351600f446a3db0ec05e34abd5160226491", "best_bid": "0.989", "best_ask": "0.999"}, {"asset_id": "110173687573613171160959717033136753568422637870529083487941219617533969558974", "price": "0.989", "size": "5.41", "side": "SELL", "hash": "342d5bb0ad0f10818d40e5b3d396edd209f6eb8c", "best_bid": "0.001", "best_ask": "0.011"}], "timestamp": "1769384879229", "event_type": "price_change"}}
{"_local_timestamp": "2026-01-25T23:47:59.300972+00:00", "data": {"market": "0xa5ea40ac631a40071430323150632a1555ad1687e00a8085139add2d911c9f34", "price_changes": [{"asset_id": "8685396856010324986284872647116218952058192899553342786948483493131886453135", "price": "0.051", "size": "13.01", "side": "BUY", "hash": "e7f8af614c24bc5019dd8d6607c9eed5f17c2667", "best_bid": "0.989", "best_ask": "0.999"}, {"asset_id": "110173687573613171160959717033136753568422637870529083487941219617533969558974", "price": "0.949", "size": "13.01", "side": "SELL", "hash": "669fcae0768d5f5cc3b0654a46625d87b340eb56", "best_bid": "0.001", "best_ask": "0.011"}], "timestamp": "1769384879230", "event_type": "price_change"}}
{"_local_timestamp": "2026-01-25T23:47:59.302250+00:00", "data": {"market": "0xa5ea40ac631a40071430323150632a1555ad1687e00a8085139add2d911c9f34", "price_changes": [{"asset_id": "8685396856010324986284872647116218952058192899553342786948483493131886453135", "price": "0.021", "size": "8.05", "side": "BUY", "hash": "375752e182f78a3ec24b8c20fa44991067c05dcd", "best_bid": "0.989", "best_ask": "0.999"}, {"asset_id": "110173687573613171160959717033136753568422637870529083487941219617533969558974", "price": "0.979", "size": "8.05", "side": "SELL", "hash": "85c0c9b38cf99408bbe5b5dd0632e4ac96d8701e", "best_bid": "0.001", "best_ask": "0.011"}], "timestamp": "1769384879231", "event_type": "price_change"}}
{"_local_timestamp": "2026-01-25T23:48:20.129928+00:00", "data": {"market": "0xd77e17a14e200e8ba39628152afb9a10a650d7a4df78a5c0c32d2c0d00438497", "price_changes": [{"asset_id": "112293333149300959260536867050041277128420756685297458675303614200002918687623", "price": "0.55", "size": "69.09", "side": "BUY", "hash": "132f4d0d290e6cfbf56fbf0b045b7f7a402114d5", "best_bid": "0.58", "best_ask": "0.79"}, {"asset_id": "20646024614518848979253481451471247924363690492887737547762322712372601906082", "price": "0.45", "size": "69.09", "side": "SELL", "hash": "b053b897dc036f14fac018cfc06088e6beeff2f2", "best_bid": "0.21", "best_ask": "0.42"}], "timestamp": "1769384900011", "event_type": "price_change"}}
{"_local_timestamp": "2026-01-25T23:48:22.699046+00:00", "data": {"market": "0xfd4d63b87d452451524c012b34422ce17d79a2ad8506dcd99630d20986cffc6c", "price_changes": [{"asset_id": "85706890002666730040133427101415019283931076549192427865944188977254431727460", "price": "0.01", "size": "73", "side": "BUY", "hash": "971f43423a20a3313c4a54a6981fb6bac6db6f83", "best_bid": "0.05", "best_ask": "0.25"}, {"asset_id": "62495477629246824566352773417644552473546059979364789192618873139681745624169", "price": "0.99", "size": "73", "side": "SELL", "hash": "45a400dab262053b266b5cb2038a57d208223205", "best_bid": "0.75", "best_ask": "0.95"}], "timestamp": "1769384902635", "event_type": "price_change"}}
{"_local_timestamp": "2026-01-25T23:48:23.064935+00:00", "data": {"market": "0xfd4d63b87d452451524c012b34422ce17d79a2ad8506dcd99630d20986cffc6c", "price_changes": [{"asset_id": "62495477629246824566352773417644552473546059979364789192618873139681745624169", "price": "0.5", "size": "38", "side": "BUY", "hash": "a4e51d80b70c0d0042c9fc70a2b04c2c3aa20724", "best_bid": "0.75", "best_ask": "0.95"}, {"asset_id": "85706890002666730040133427101415019283931076549192427865944188977254431727460", "price": "0.5", "size": "38", "side": "SELL", "hash": "00b4c53e05b94c156c1f2ef5256c8e9b4a269194", "best_bid": "0.05", "best_ask": "0.25"}], "timestamp": "1769384902999", "event_type": "price_change"}}
{"_local_timestamp": "2026-01-25T23:48:23.110444+00:00", "data": {"market": "0xfd4d63b87d452451524c012b34422ce17d79a2ad8506dcd99630d20986cffc6c", "price_changes": [{"asset_id": "62495477629246824566352773417644552473546059979364789192618873139681745624169", "price": "0.51", "size": "20", "side": "BUY", "hash": "7fb973930ddaf879108a2912dd5c9864f8cab5ba", "best_bid": "0.75", "best_ask": "0.95"}, {"asset_id": "85706890002666730040133427101415019283931076549192427865944188977254431727460", "price": "0.49", "size": "20", "side": "SELL", "hash": "6e77a10e6f3c653ae3f111d9cefb34e9011b4b69", "best_bid": "0.05", "best_ask": "0.25"}], "timestamp": "1769384903031", "event_type": "price_change"}}
{"_local_timestamp": "2026-01-25T23:48:23.176982+00:00", "data": {"market": "0xfd4d63b87d452451524c012b34422ce17d79a2ad8506dcd99630d20986cffc6c", "price_changes": [{"asset_id": "85706890002666730040133427101415019283931076549192427865944188977254431727460", "price": "0.01", "size": "106.33", "side": "BUY", "hash": "5eb0997aa9924f40e2fd2d606e3f43612a95df7c", "best_bid": "0.05", "best_ask": "0.25"}, {"asset_id": "62495477629246824566352773417644552473546059979364789192618873139681745624169", "price": "0.99", "size": "106.33", "side": "SELL", "hash": "72c2771da9dedd3e35013eaf86f5bcac4948c7da", "best_bid": "0.75", "best_ask": "0.95"}], "timestamp": "1769384903111", "event_type": "price_change"}}
{"_local_timestamp": "2026-01-25T23:49:06.855894+00:00", "data": {"market": "0xd77e17a14e200e8ba39628152afb9a10a650d7a4df78a5c0c32d2c0d00438497", "price_changes": [{"asset_id": "20646024614518848979253481451471247924363690492887737547762322712372601906082", "price": "0.42", "size": "0", "side": "SELL", "hash": "28873a4270db5fad07a2b4d2d1ce04267d51046b", "best_bid": "0.21", "best_ask": "0.45"}, {"asset_id": "112293333149300959260536867050041277128420756685297458675303614200002918687623", "price": "0.58", "size": "0", "side": "BUY", "hash": "0867dead82f2aaec785af8a5ddaf62cc7d62b0a8", "best_bid": "0.55", "best_ask": "0.79"}], "timestamp": "1769384946787", "event_type": "price_change"}}
{"_local_timestamp": "2026-01-25T23:49:07.251849+00:00", "data": {"market": "0xd77e17a14e200e8ba39628152afb9a10a650d7a4df78a5c0c32d2c0d00438497", "price_changes": [{"asset_id": "20646024614518848979253481451471247924363690492887737547762322712372601906082", "price": "0.44", "size": "6.88", "side": "SELL", "hash": "a93f9dd121369f84874c11330f1e5cc543f78436", "best_bid": "0.21", "best_ask": "0.44"}, {"asset_id": "112293333149300959260536867050041277128420756685297458675303614200002918687623", "price": "0.56", "size": "6.88", "side": "BUY", "hash": "ac218cb8e7587766b3553c86d36a3088cdcac46d", "best_bid": "0.56", "best_ask": "0.79"}], "timestamp": "1769384947180", "event_type": "price_change"}}
{"_local_timestamp": "2026-01-25T23:49:07.695840+00:00", "data": {"market": "0xd77e17a14e200e8ba39628152afb9a10a650d7a4df78a5c0c32d2c0d00438497", "price_changes": [{"asset_id": "20646024614518848979253481451471247924363690492887737547762322712372601906082", "price": "0.06", "size": "19.39", "side": "BUY", "hash": "a9eba50fde8a876524e6f6c66ba8c9dcf63512b3", "best_bid": "0.21", "best_ask": "0.44"}, {"asset_id": "112293333149300959260536867050041277128420756685297458675303614200002918687623", "price": "0.94", "size": "19.39", "side": "SELL", "hash": "c6985e8bb3300afe3e4a4918fb379adc42af2288", "best_bid": "0.56", "best_ask": "0.79"}], "timestamp": "1769384947628", "event_type": "price_change"}}
{"_local_timestamp": "2026-01-25T23:49:09.530489+00:00", "data": {"market": "0xfd4d63b87d452451524c012b34422ce17d79a2ad8506dcd99630d20986cffc6c", "price_changes": [{"asset_id": "62495477629246824566352773417644552473546059979364789192618873139681745624169", "price": "0.51", "size": "0", "side": "BUY", "hash": "13b74f6f5c97698e67f792d370ddcc372eaa6b61", "best_bid": "0.75", "best_ask": "0.95"}, {"asset_id": "85706890002666730040133427101415019283931076549192427865944188977254431727460", "price": "0.49", "size": "0", "side": "SELL", "hash": "0c1b55b3f4a3950c63a5fba0d425dd3cb8878661", "best_bid": "0.05", "best_ask": "0.25"}], "timestamp": "1769384949459", "event_type": "price_change"}}
{"_local_timestamp": "2026-01-25T23:49:09.556479+00:00", "data": {"market": "0xfd4d63b87d452451524c012b34422ce17d79a2ad8506dcd99630d20986cffc6c", "price_changes": [{"asset_id": "62495477629246824566352773417644552473546059979364789192618873139681745624169", "price": "0.5", "size": "58", "side": "BUY", "hash": "eb300b9ee7faac1edaa480e94cd992de50fcaccd", "best_bid": "0.75", "best_ask": "0.95"}, {"asset_id": "85706890002666730040133427101415019283931076549192427865944188977254431727460", "price": "0.5", "size": "58", "side": "SELL", "hash": "20dfbae3d3b907024919f2846ef4cd85d3ff3900", "best_bid": "0.05", "best_ask": "0.25"}], "timestamp": "1769384949489", "event_type": "price_change"}}
{"_local_timestamp": "2026-01-25T23:49:50.087047+00:00", "data": {"market": "0x1cc98e3388b008a494448ef05c62bad301d61b1e73192ea563f646ef205209d1", "price_changes": [{"asset_id": "61587484925357220620822959423222817449642342451321057905286571851665076728447", "price": "0.821", "size": "0", "side": "BUY", "hash": "8464b908e1c41ee2c63a737f93c9d1da3f9ae6cd", "best_bid": "0.958", "best_ask": "0.999"}, {"asset_id": "24208114257867316046741920450990596841932558836227302708830175610444235443186", "price": "0.179", "size": "0", "side": "SELL", "hash": "793e7de5dcd2f2fdb1f8cdf7187c5138d2dcb9cd", "best_bid": "0.001", "best_ask": "0.042"}], "timestamp": "1769384989966", "event_type": "price_change"}}
{"_local_timestamp": "2026-01-25T23:50:13.075030+00:00", "data": {"market": "0x1cc98e3388b008a494448ef05c62bad301d61b1e73192ea563f646ef205209d1", "price_changes": [{"asset_id": "61587484925357220620822959423222817449642342451321057905286571851665076728447", "price": "0.001", "size": "4070.99", "side": "BUY", "hash": "5f9f3e055f160141db582d804675fad0cbc1e3d6", "best_bid": "0.958", "best_ask": "0.999"}, {"asset_id": "24208114257867316046741920450990596841932558836227302708830175610444235443186", "price": "0.999", "size": "4070.99", "side": "SELL", "hash": "3f0e2958cf2a00c0b3c67387bd5c780fbf329141", "best_bid": "0.001", "best_ask": "0.042"}], "timestamp": "1769385013000", "event_type": "price_change"}}
{"_local_timestamp": "2026-01-25T23:50:13.086090+00:00", "data": {"market": "0x1cc98e3388b008a494448ef05c62bad301d61b1e73192ea563f646ef205209d1", "price_changes": [{"asset_id": "61587484925357220620822959423222817449642342451321057905286571851665076728447", "price": "0.002", "size": "0", "side": "BUY", "hash": "5f9f3e055f160141db582d804675fad0cbc1e3d6", "best_bid": "0.958", "best_ask": "0.999"}, {"asset_id": "24208114257867316046741920450990596841932558836227302708830175610444235443186", "price": "0.998", "size": "0", "side": "SELL", "hash": "3f0e2958cf2a00c0b3c67387bd5c780fbf329141", "best_bid": "0.001", "best_ask": "0.042"}], "timestamp": "1769385013000", "event_type": "price_change"}}
{"_local_timestamp": "2026-01-25T23:50:13.086788+00:00", "data": {"market": "0xfd4d63b87d452451524c012b34422ce17d79a2ad8506dcd99630d20986cffc6c", "price_changes": [{"asset_id": "62495477629246824566352773417644552473546059979364789192618873139681745624169", "price": "0.17", "size": "0", "side": "BUY", "hash": "101ae131dcd50ec5c5a5163f35f2979443f4c19e", "best_bid": "0.75", "best_ask": "0.95"}, {"asset_id": "85706890002666730040133427101415019283931076549192427865944188977254431727460", "price": "0.83", "size": "0", "side": "SELL", "hash": "3a6d98616182621f2f9220e9b882692640a68e0f", "best_bid": "0.05", "best_ask": "0.25"}], "timestamp": "1769385013000", "event_type": "price_change"}}
{"_local_timestamp": "2026-01-25T23:50:13.087485+00:00", "data": {"market": "0x1cc98e3388b008a494448ef05c62bad301d61b1e73192ea563f646ef205209d1", "price_changes": [{"asset_id": "61587484925357220620822959423222817449642342451321057905286571851665076728447", "price": "0.011", "size": "0", "side": "BUY", "hash": "fbe67f6e6d8074f05787ec48f6f4382bfce51297", "best_bid": "0.958", "best_ask": "0.999"}, {"asset_id": "24208114257867316046741920450990596841932558836227302708830175610444235443186", "price": "0.989", "size": "0", "side": "SELL", "hash": "7cb66de1d477cb2123ae0b378d8b622189e90186", "best_bid": "0.001", "best_ask": "0.042"}], "timestamp": "1769385013002", "event_type": "price_change"}}
{"_local_timestamp": "2026-01-25T23:50:13.088109+00:00", "data": {"market": "0xfd4d63b87d452451524c012b34422ce17d79a2ad8506dcd99630d20986cffc6c", "price_changes": [{"asset_id": "62495477629246824566352773417644552473546059979364789192618873139681745624169", "price": "0.07", "size": "0", "side": "BUY", "hash": "8763da8e2f7fa3225bb9e231bf87bb24289e58df", "best_bid": "0.75", "best_ask": "0.95"}, {"asset_id": "85706890002666730040133427101415019283931076549192427865944188977254431727460", "price": "0.93", "size": "0", "side": "SELL", "hash": "dc5c23f1eac1cf78c7c047eafb7d81879e5b64c2", "best_bid": "0.05", "best_ask": "0.25"}], "timestamp": "1769385013002", "event_type": "price_change"}}
{"_local_timestamp": "2026-01-25T23:50:13.095606+00:00", "data": {"market": "0xfd4d63b87d452451524c012b34422ce17d79a2ad8506dcd99630d20986cffc6c", "price_changes": [{"asset_id": "62495477629246824566352773417644552473546059979364789192618873139681745624169", "price": "0.01", "size": "4123", "side": "BUY", "hash": "8763da8e2f7fa3225bb9e231bf87bb24289e58df", "best_bid": "0.75", "best_ask": "0.95"}, {"asset_id": "85706890002666730040133427101415019283931076549192427865944188977254431727460", "price": "0.99", "size": "4123", "side": "SELL", "hash": "dc5c23f1eac1cf78c7c047eafb7d81879e5b64c2", "best_bid": "0.05", "best_ask": "0.25"}], "timestamp": "1769385013002", "event_type": "price_change"}}
{"_local_timestamp": "2026-01-25T23:50:13.096241+00:00", "data": {"market": "0xfd4d63b87d452451524c012b34422ce17d79a2ad8506dcd99630d20986cffc6c", "price_changes": [{"asset_id": "62495477629246824566352773417644552473546059979364789192618873139681745624169", "price": "0.03", "size": "0", "side": "BUY", "hash": "307c1105bdfc2d3b98cc36ed8f6bf2ceed7b13b8", "best_bid": "0.75", "best_ask": "0.95"}, {"asset_id": "85706890002666730040133427101415019283931076549192427865944188977254431727460", "price": "0.97", "size": "0", "side": "SELL", "hash": "5c3ebf1d453a43d892084e2846ae536943642399", "best_bid": "0.05", "best_ask": "0.25"}], "timestamp": "1769385013003", "event_type": "price_change"}}
{"_local_timestamp": "2026-01-25T23:50:23.261760+00:00", "data": {"market": "0xd77e17a14e200e8ba39628152afb9a10a650d7a4df78a5c0c32d2c0d00438497", "price_changes": [{"asset_id": "112293333149300959260536867050041277128420756685297458675303614200002918687623", "price": "0.55", "size": "0", "side": "BUY", "hash": "bdd3515ab0da84305fe6af220cb87480d90b5baa", "best_bid": "0.56", "best_ask": "0.79"}, {"asset_id": "20646024614518848979253481451471247924363690492887737547762322712372601906082", "price": "0.45", "size": "0", "side": "SELL", "hash": "49c1421ab7189cce0d9d0657c3c2783e0156cbf1", "best_bid": "0.21", "best_ask": "0.44"}], "timestamp": "1769385023094", "event_type": "price_change"}}
{"_local_timestamp": "2026-01-25T23:51:21.070353+00:00", "data": {"market": "0xd77e17a14e200e8ba39628152afb9a10a650d7a4df78a5c0c32d2c0d00438497", "price_changes": [{"asset_id": "20646024614518848979253481451471247924363690492887737547762322712372601906082", "price": "0.02", "size": "0", "side": "BUY", "hash": "71e1185e36a185e0019ee5dcde7f1b27bbbf65a4", "best_bid": "0.21", "best_ask": "0.44"}, {"asset_id": "112293333149300959260536867050041277128420756685297458675303614200002918687623", "price": "0.98", "size": "0", "side": "SELL", "hash": "cfd228f1ed92ecc94f8e0bd4b6ec9a6dd479a136", "best_bid": "0.56", "best_ask": "0.79"}], "timestamp": "1769385081000", "event_type": "price_change"}}
{"_local_timestamp": "2026-01-25T23:51:21.074827+00:00", "data": {"market": "0xd77e17a14e200e8ba39628152afb9a10a650d7a4df78a5c0c32d2c0d00438497", "price_changes": [{"asset_id": "20646024614518848979253481451471247924363690492887737547762322712372601906082", "price": "0.01", "size": "73", "side": "BUY", "hash": "54e7b19098de64cd13cf28064a2c4ef9fa83caa7", "best_bid": "0.21", "best_ask": "0.44"}, {"asset_id": "112293333149300959260536867050041277128420756685297458675303614200002918687623", "price": "0.99", "size": "73", "side": "SELL", "hash": "cd88da97e88f6af90d672b6e1b90187b30b11901", "best_bid": "0.56", "best_ask": "0.79"}], "timestamp": "1769385081001", "event_type": "price_change"}}
