{"_local_timestamp": "2026-01-25T23:33:34.001249+00:00", "data": [{"market": "0xe93e70dba8f12060ef544e9ef6b0accc90d4e134994cabf7ac7a13c519524f90", "asset_id": "17227676978076729603320200601284543089020583147504453146520617679632315947452", "timestamp": "1769382340970", "hash": "ee70caacac086b5b6b65b53d525e954440d92fa8", "bids": [{"price": "0.01", "size": "5910.84"}, {"price": "0.02", "size": "2200"}, {"price": "0.03", "size": "6.74"}, {"price": "0.05", "size": "30"}, {"price": "0.06", "size": "533"}, {"price": "0.07", "size": "7.71"}, {"price": "0.1", "size": "560"}, {"price": "0.14", "size": "842.85"}, {"price": "0.19", "size": "318.42"}, {"price": "0.2", "size": "5.74"}, {"price": "0.24", "size": "116.66"}, {"price": "0.29", "size": "89.65"}, {"price": "0.34", "size": "70.58"}, {"price": "0.38", "size": "52.63"}, {"price": "0.39", "size": "150"}, {"price": "0.41", "size": "62"}, {"price": "0.46", "size": "100"}, {"price": "0.47", "size": "30"}, {"price": "0.48", "size": "17"}, {"price": "0.49", "size": "5"}, {"price": "0.57", "size": "36"}, {"price": "0.91", "size": "5"}], "asks": [{"price": "0.99", "size": "5"}, {"price": "0.96", "size": "12"}], "event_type": "book", "last_trade_price": ""}, {"market": "0xa103fd29e21844a2c37dbae0ddd5abc05c9a899652f82b185b1cfd02d18e052e", "asset_id": "68251780522342786457624382430403984200536262465760434117810614118555332248086", "timestamp": "1769383901919", "hash": "77ba5839b022652f0b5ad5e007923a7c5dcd7dc8", "bids": [{"price": "0.001", "size": "3838.08"}, {"price": "0.002", "size": "1250"}, {"price": "0.003", "size": "1407.34"}, {"price": "0.006", "size": "200"}, {"price": "0.007", "size": "10.78"}, {"price": "0.01", "size": "5800"}, {"price": "0.02", "size": "2200"}, {"price": "0.021", "size": "9.63"}, {"price": "0.05", "size": "30"}, {"price": "0.051", "size": "39"}, {"price": "0.06", "size": "500"}, {"price": "0.061", "size": "9.48"}, {"price": "0.1", "size": "360"}, {"price": "0.15", "size": "451.66"}, {"price": "0.2", "size": "310"}, {"price": "0.201", "size": "16.66"}, {"price": "0.202", "size": "5.49"}, {"price": "0.25", "size": "112"}, {"price": "0.251", "size": "200"}, {"price": "0.3", "size": "86.66"}, {"price": "0.301", "size": "42.81"}, {"price": "0.35", "size": "68.57"}, {"price": "0.351", "size": "34"}, {"price": "0.4", "size": "200"}, {"price": "0.401", "size": "22"}, {"price": "0.972", "size": "28.57"}, {"price": "0.973", "size": "13.6"}], "asks": [{"price": "0.999", "size": "14439.86"}, {"price": "0.998", "size": "1034.56"}, {"price": "0.997", "size": "379.96"}, {"price": "0.996", "size": "360"}, {"price": "0.995", "size": "225.17"}, {"price": "0.994", "size": "187.17"}, {"price": "0.992", "size": "25.17"}], "event_type": "book", "last_trade_price": ""}, {"market": "0x09e25ccabb32e8d68fed95405ffe3975ffcb2af7de61b1de2f4eb22f1b375029", "asset_id": "91673509190321458869106560782565319947503739452675658246836850790481377708221", "timestamp": "1769383901923", "hash": "3649a075a6502046d38db61165bab752be966db7", "bids": [{"price": "0.01", "size": "33.33"}, {"price": "0.02", "size": "12.5"}, {"price": "0.03", "size": "150"}, {"price": "0.04", "size": "91"}, {"price": "0.09", "size": "28.33"}, {"price": "0.17", "size": "10"}, {"price": "0.18", "size": "58.88"}], "asks": [{"price": "0.99", "size": "4611.93"}, {"price": "0.98", "size": "1800"}, {"price": "0.97", "size": "307.41"}, {"price": "0.96", "size": "100"}, {"price": "0.95", "size": "130"}, {"price": "0.94", "size": "200"}, {"price": "0.93", "size": "106.76"}, {"price": "0.89", "size": "275"}, {"price": "0.84", "size": "75"}, {"price": "0.83", "size": "6.97"}, {"price": "0.68", "size": "100"}, {"price": "0.67", "size": "23"}, {"price": "0.45", "size": "6.8"}, {"price": "0.38", "size": "17"}], "event_type": "book", "last_trade_price": ""}, {"market": "0xc3a4cae673b27efa91532ddb90b398930318186e51e01ff0c8eb783a0dbcd4e7", "asset_id": "96741359658621321208991066620310092016019156810960175572658869255516755049336", "timestamp": "1769383783005", "hash": "3812b780b6324dc884d0b8c0adefd0906c4a4f0e", "bids": [{"price": "0.01", "size": "5910.86"}, {"price": "0.02", "size": "2200"}, {"price": "0.03", "size": "6.74"}, {"price": "0.05", "size": "30"}, {"price": "0.06", "size": "533"}, {"price": "0.07", "size": "7.71"}, {"price": "0.1", "size": "560"}, {"price": "0.14", "size": "842.85"}, {"price": "0.19", "size": "318.42"}, {"price": "0.2", "size": "5.74"}, {"price": "0.24", "size": "116.66"}, {"price": "0.29", "size": "89.65"}, {"price": "0.34", "size": "70.58"}, {"price": "0.38", "size": "52.63"}, {"price": "0.39", "size": "150"}, {"price": "0.4", "size": "125"}, {"price": "0.46", "size": "100"}, {"price": "0.47", "size": "47"}, {"price": "0.49", "size": "5"}, {"price": "0.54", "size": "48.97"}, {"price": "0.91", "size": "23.8"}], "asks": [{"price": "0.99", "size": "12.62"}, {"price": "0.97", "size": "7.62"}, {"price": "0.96", "size": "12"}, {"price": "0.95", "size": "7.62"}], "event_type": "book", "last_trade_price": ""}, {"market": "0x15dd98954f5a3d5bc21a6fe182d76bbde3e29af1465195df74a6f82c5be6fb2c", "asset_id": "103448363933352469180704380615499404975348483690550986365085327126347374707599", "timestamp": "1769383901917", "hash": "3d704e24ae2521bd9e1127f02c428d4d3c378a42", "bids": [{"price": "0.001", "size": "3082.36"}, {"price": "0.002", "size": "1256.35"}, {"price": "0.003", "size": "1000"}, {"price": "0.004", "size": "11"}, {"price": "0.01", "size": "5800"}, {"price": "0.011", "size": "5.6"}, {"price": "0.02", "size": "2200"}, {"price": "0.021", "size": "11.06"}, {"price": "0.05", "size": "30"}, {"price": "0.051", "size": "39"}, {"price": "0.06", "size": "700"}, {"price": "0.061", "size": "8.09"}, {"price": "0.11", "size": "600"}, {"price": "0.16", "size": "150"}, {"price": "0.161", "size": "7.13"}, {"price": "0.215", "size": "66.66"}, {"price": "0.217", "size": "317"}, {"price": "0.26", "size": "50"}, {"price": "0.261", "size": "7"}, {"price": "0.392", "size": "66.66"}, {"price": "0.4", "size": "150"}, {"price": "0.401", "size": "17"}, {"price": "0.568", "size": "102.66"}, {"price": "0.569", "size": "30.33"}], "asks": [{"price": "0.999", "size": "1108.07"}, {"price": "0.998", "size": "368.38"}, {"price": "0.997", "size": "333.79"}, {"price": "0.996", "size": "392.6"}, {"price": "0.995", "size": "107.14"}, {"price": "0.994", "size": "97.49"}, {"price": "0.993", "size": "191"}, {"price": "0.991", "size": "8.44"}, {"price": "0.99", "size": "5"}, {"price": "0.987", "size": "33.44"}], "event_type": "book", "last_trade_price": ""}, {"market": "0xba8526e4bf87c26c043d7048d364508d066117c173a91f2c56a82128fdc9102c", "asset_id": "32267317137576261468029282489488620944358875503578558321905938935435579396497", "timestamp": "1769383901928", "hash": "6a7b906d89e7703b30260321b90e568707a6a14d", "bids": [{"price": "0.01", "size": "64.41"}, {"price": "0.02", "size": "12.5"}, {"price": "0.03", "size": "16"}, {"price": "0.04", "size": "150"}, {"price": "0.05", "size": "75"}, {"price": "0.14", "size": "66.55"}, {"price": "0.27", "size": "15"}], "asks": [{"price": "0.99", "size": "3576.11"}, {"price": "0.98", "size": "17.81"}, {"price": "0.97", "size": "200"}, {"price": "0.96", "size": "250"}, {"price": "0.95", "size": "810"}, {"price": "0.94", "size": "325.82"}, {"price": "0.93", "size": "600"}, {"price": "0.83", "size": "66.66"}, {"price": "0.82", "size": "17"}, {"price": "0.73", "size": "111"}, {"price": "0.72", "size": "66.66"}], "event_type": "book", "last_trade_price": ""}, {"market": "0xa103fd29e21844a2c37dbae0ddd5abc05c9a899652f82b185b1cfd02d18e052e", "asset_id": "84850580000869621913865680797117970052468736368951185577800573275538604924241", "timestamp": "1769383901919", "hash": "b47ef2115bebe0d3c10d1709751e81241b40a13e", "bids": [{"price": "0.001", "size": "14439.86"}, {"price": "0.002", "size": "1034.56"}, {"price": "0.003", "size": "379.96"}, {"price": "0.004", "size": "360"}, {"price": "0.005", "size": "225.17"}, {"price": "0.006", "size": "187.17"}, {"price": "0.008", "size": "25.17"}], "asks": [{"price": "0.999", "size": "3838.08"}, {"price": "0.998", "size": "1250"}, {"price": "0.997", "size": "1407.34"}, {"price": "0.994", "size": "200"}, {"price": "0.993", "size": "10.78"}, {"price": "0.99", "size": "5800"}, {"price": "0.98", "size": "2200"}, {"price": "0.979", "size": "9.63"}, {"price": "0.95", "size": "30"}, {"price": "0.949", "size": "39"}, {"price": "0.94", "size": "500"}, {"price": "0.939", "size": "9.48"}, {"price": "0.9", "size": "360"}, {"price": "0.85", "size": "451.66"}, {"price": "0.8", "size": "310"}, {"price": "0.799", "size": "16.66"}, {"price": "0.798", "size": "5.49"}, {"price": "0.75", "size": "112"}, {"price": "0.749", "size": "200"}, {"price": "0.7", "size": "86.66"}, {"price": "0.699", "size": "42.81"}, {"price": "0.65", "size": "68.57"}, {"price": "0.649", "size": "34"}, {"price": "0.6", "size": "200"}, {"price": "0.599", "size": "22"}, {"price": "0.028", "size": "28.57"}, {"price": "0.027", "size": "13.6"}], "event_type": "book", "last_trade_price": ""}, {"market": "0xe93e70dba8f12060ef544e9ef6b0accc90d4e134994cabf7ac7a13c519524f90", "asset_id": "22923368263767590428987798075575909590223530155664669069971868689484297261500", "timestamp": "1769382340970", "hash": "21c60ced1673410afe0dbba20e120470c0a5b90b", "bids": [{"price": "0.01", "size": "5"}, {"price": "0.04", "size": "12"}], "asks": [{"price": "0.99", "size": "5910.84"}, {"price": "0.98", "size": "2200"}, {"price": "0.97", "size": "6.74"}, {"price": "0.95", "size": "30"}, {"price": "0.94", "size": "533"}, {"price": "0.93", "size": "7.71"}, {"price": "0.9", "size": "560"}, {"price": "0.86", "size": "842.85"}, {"price": "0.81", "size": "318.42"}, {"price": "0.8", "size": "5.74"}, {"price": "0.76", "size": "116.66"}, {"price": "0.71", "size": "89.65"}, {"price": "0.66", "size": "70.58"}, {"price": "0.62", "size": "52.63"}, {"price": "0.61", "size": "150"}, {"price": "0.59", "size": "62"}, {"price": "0.54", "size": "100"}, {"price": "0.53", "size": "30"}, {"price": "0.52", "size": "17"}, {"price": "0.51", "size": "5"}, {"price": "0.43", "size": "36"}, {"price": "0.09", "size": "5"}], "event_type": "book", "last_trade_price": ""}, {"market": "0xba8526e4bf87c26c043d7048d364508d066117c173a91f2c56a82128fdc9102c", "asset_id": "49259132375860726199054520213393805061519699612170190892474472339512233385785", "timestamp": "1769383901928", "hash": "345721befbea7a46acb2a48419bcbab581a0eb78", "bids": [{"price": "0.01", "size": "3576.11"}, {"price": "0.02", "size": "17.81"}, {"price": "0.03", "size": "200"}, {"price": "0.04", "size": "250"}, {"price": "0.05", "size": "810"}, {"price": "0.06", "size": "325.82"}, {"price": "0.07", "size": "600"}, {"price": "0.17", "size": "66.66"}, {"price": "0.18", "size": "17"}, {"price": "0.27", "size": "111"}, {"price": "0.28", "size": "66.66"}], "asks": [{"price": "0.99", "size": "64.41"}, {"price": "0.98", "size": "12.5"}, {"price": "0.97", "size": "16"}, {"price": "0.96", "size": "150"}, {"price": "0.95", "size": "75"}, {"price": "0.86", "size": "66.55"}, {"price": "0.73", "size": "15"}], "event_type": "book", "last_trade_price": ""}, {"market": "0x15dd98954f5a3d5bc21a6fe182d76bbde3e29af1465195df74a6f82c5be6fb2c", "asset_id": "50774184608010128165657683699294077924184178889265892143108921917710895798073", "timestamp": "1769383901917", "hash": "8c3efd1b3c6e2d7961043e283ab22ce5f3c91f1a", "bids": [{"price": "0.001", "size": "1108.07"}, {"price": "0.002", "size": "368.38"}, {"price": "0.003", "size": "333.79"}, {"price": "0.004", "size": "392.6"}, {"price": "0.005", "size": "107.14"}, {"price": "0.006", "size": "97.49"}, {"price": "0.007", "size": "191"}, {"price": "0.009", "size": "8.44"}, {"price": "0.01", "size": "5"}, {"price": "0.013", "size": "33.44"}], "asks": [{"price": "0.999", "size": "3082.36"}, {"price": "0.998", "size": "1256.35"}, {"price": "0.997", "size": "1000"}, {"price": "0.996", "size": "11"}, {"price": "0.99", "size": "5800"}, {"price": "0.989", "size": "5.6"}, {"price": "0.98", "size": "2200"}, {"price": "0.979", "size": "11.06"}, {"price": "0.95", "size": "30"}, {"price": "0.949", "size": "39"}, {"price": "0.94", "size": "700"}, {"price": "0.939", "size": "8.09"}, {"price": "0.89", "size": "600"}, {"price": "0.84", "size": "150"}, {"price": "0.839", "size": "7.13"}, {"price": "0.785", "size": "66.66"}, {"price": "0.783", "size": "317"}, {"price": "0.74", "size": "50"}, {"price": "0.739", "size": "7"}, {"price": "0.608", "size": "66.66"}, {"price": "0.6", "size": "150"}, {"price": "0.599", "size": "17"}, {"price": "0.432", "size": "102.66"}, {"price": "0.431", "size": "30.33"}], "event_type": "book", "last_trade_price": ""}, {"market": "0x422eecd1eec8d501c70508387d11b1ca7550da75002dcdc448d4d99236df53a9", "asset_id": "37786111380458799656608112817818264473709140890522870941671572177308421431721", "timestamp": "1769383963549", "hash": "cc3116cfb7c735b79aa01a2c71c44a6be641a254", "bids": [{"price": "0.001", "size": "1129.97"}, {"price": "0.002", "size": "475.7"}, {"price": "0.003", "size": "500.44"}, {"price": "0.004", "size": "117.66"}, {"price": "0.005", "size": "110.17"}, {"price": "0.007", "size": "5"}, {"price": "0.008", "size": "183"}, {"price": "0.01", "size": "5"}, {"price": "0.011", "size": "5"}], "asks": [{"price": "0.999", "size": "3089.03"}, {"price": "0.998", "size": "1250"}, {"price": "0.997", "size": "19.31"}, {"price": "0.99", "size": "5800"}, {"price": "0.988", "size": "6.29"}, {"price": "0.98", "size": "2200"}, {"price": "0.979", "size": "200"}, {"price": "0.978", "size": "100"}, {"price": "0.977", "size": "100"}, {"price": "0.976", "size": "7.62"}, {"price": "0.95", "size": "30"}, {"price": "0.949", "size": "39"}, {"price": "0.939", "size": "900"}, {"price": "0.938", "size": "8.15"}, {"price": "0.89", "size": "425"}, {"price": "0.889", "size": "125"}, {"price": "0.839", "size": "216.66"}, {"price": "0.838", "size": "7.19"}, {"price": "0.785", "size": "196"}, {"price": "0.74", "size": "50"}, {"price": "0.739", "size": "7"}, {"price": "0.638", "size": "66.66"}, {"price": "0.6", "size": "150"}, {"price": "0.599", "size": "17"}, {"price": "0.468", "size": "14.91"}, {"price": "0.439", "size": "66.66"}, {"price": "0.438", "size": "29.98"}], "event_type": "book", "last_trade_price": ""}, {"market": "0x09e25ccabb32e8d68fed95405ffe3975ffcb2af7de61b1de2f4eb22f1b375029", "asset_id": "89658892949676737922541358818208957757334253491716424169833323571160167352106", "timestamp": "1769383901923", "hash": "357a511527a0b6da745e06e4c1f441f77a89b3f1", "bids": [{"price": "0.01", "size": "4611.93"}, {"price": "0.02", "size": "1800"}, {"price": "0.03", "size": "307.41"}, {"price": "0.04", "size": "100"}, {"price": "0.05", "size": "130"}, {"price": "0.06", "size": "200"}, {"price": "0.07", "size": "106.76"}, {"price": "0.11", "size": "275"}, {"price": "0.16", "size": "75"}, {"price": "0.17", "size": "6.97"}, {"price": "0.32", "size": "100"}, {"price": "0.33", "size": "23"}, {"price": "0.55", "size": "6.8"}, {"price": "0.62", "size": "17"}], "asks": [{"price": "0.99", "size": "33.33"}, {"price": "0.98", "size": "12.5"}, {"price": "0.97", "size": "150"}, {"price": "0.96", "size": "91"}, {"price": "0.91", "size": "28.33"}, {"price": "0.83", "size": "10"}, {"price": "0.82", "size": "58.88"}], "event_type": "book", "last_trade_price": ""}, {"market": "0x422eecd1eec8d501c70508387d11b1ca7550da75002dcdc448d4d99236df53a9", "asset_id": "92095665890628866412192885284169451045487268875038936631172018308093854978979", "timestamp": "1769383963549", "hash": "c3088ce64e31ac246eada8ce7665620f1f4dd60a", "bids": [{"price": "0.001", "size": "3089.03"}, {"price": "0.002", "size": "1250"}, {"price": "0.003", "size": "19.31"}, {"price": "0.01", "size": "5800"}, {"price": "0.012", "size": "6.29"}, {"price": "0.02", "size": "2200"}, {"price": "0.021", "size": "200"}, {"price": "0.022", "size": "100"}, {"price": "0.023", "size": "100"}, {"price": "0.024", "size": "7.62"}, {"price": "0.05", "size": "30"}, {"price": "0.051", "size": "39"}, {"price": "0.061", "size": "900"}, {"price": "0.062", "size": "8.15"}, {"price": "0.11", "size": "425"}, {"price": "0.111", "size": "125"}, {"price": "0.161", "size": "216.66"}, {"price": "0.162", "size": "7.19"}, {"price": "0.215", "size": "196"}, {"price": "0.26", "size": "50"}, {"price": "0.261", "size": "7"}, {"price": "0.362", "size": "66.66"}, {"price": "0.4", "size": "150"}, {"price": "0.401", "size": "17"}, {"price": "0.532", "size": "14.91"}, {"price": "0.561", "size": "66.66"}, {"price": "0.562", "size": "29.98"}], "asks": [{"price": "0.999", "size": "1129.97"}, {"price": "0.998", "size": "475.7"}, {"price": "0.997", "size": "500.44"}, {"price": "0.996", "size": "117.66"}, {"price": "0.995", "size": "110.17"}, {"price": "0.993", "size": "5"}, {"price": "0.992", "size": "183"}, {"price": "0.99", "size": "5"}, {"price": "0.989", "size": "5"}], "event_type": "book", "last_trade_price": ""}, {"market": "0xc3a4cae673b27efa91532ddb90b398930318186e51e01ff0c8eb783a0dbcd4e7", "asset_id": "8608317574717919639592346411602668438605050919704951969833903607649299947045", "timestamp": "1769383783005", "hash": "812c903653b14487603c95db2d8ec5a0579b7f58", "bids": [{"price": "0.01", "size": "12.62"}, {"price": "0.03", "size": "7.62"}, {"price": "0.04", "size": "12"}, {"price": "0.05", "size": "7.62"}], "asks": [{"price": "0.99", "size": "5910.86"}, {"price": "0.98", "size": "2200"}, {"price": "0.97", "size": "6.74"}, {"price": "0.95", "size": "30"}, {"price": "0.94", "size": "533"}, {"price": "0.93", "size": "7.71"}, {"price": "0.9", "size": "560"}, {"price": "0.86", "size": "842.85"}, {"price": "0.81", "size": "318.42"}, {"price": "0.8", "size": "5.74"}, {"price": "0.76", "size": "116.66"}, {"price": "0.71", "size": "89.65"}, {"price": "0.66", "size": "70.58"}, {"price": "0.62", "size": "52.63"}, {"price": "0.61", "size": "150"}, {"price": "0.6", "size": "125"}, {"price": "0.54", "size": "100"}, {"price": "0.53", "size": "47"}, {"price": "0.51", "size": "5"}, {"price": "0.46", "size": "48.97"}, {"price": "0.09", "size": "23.8"}], "event_type": "book", "last_trade_price": ""}, {"market": "0x7406898e6ec1bfc478fb7c0b0ee2c425f651ad48700739caaa05d7ffada6c326", "asset_id": "5161312722139049791735600709163110113562284745776838565625720112539869142403", "timestamp": "1769383402268", "hash": "4f70e3b57f72c4a12a738ff3d577dc1c16b6f8ad", "bids": [{"price": "0.01", "size": "5"}, {"price": "0.04", "size": "12"}], "asks": [{"price": "0.99", "size": "5910.86"}, {"price": "0.98", "size": "2200"}, {"price": "0.97", "size": "6.74"}, {"price": "0.95", "size": "30"}, {"price": "0.94", "size": "533"}, {"price": "0.93", "size": "7.71"}, {"price": "0.9", "size": "560"}, {"price": "0.86", "size": "842.85"}, {"price": "0.81", "size": "318.42"}, {"price": "0.8", "size": "5.74"}, {"price": "0.76", "size": "116.66"}, {"price": "0.71", "size": "89.65"}, {"price": "0.66", "size": "70.58"}, {"price": "0.62", "size": "52.63"}, {"price": "0.61", "size": "150"}, {"price": "0.59", "size": "62"}, {"price": "0.53", "size": "100"}, {"price": "0.52", "size": "30"}, {"price": "0.51", "size": "17"}, {"price": "0.48", "size": "48.97"}, {"price": "0.47", "size": "5"}, {"price": "0.09", "size": "23.8"}], "event_type": "book", "last_trade_price": ""}, {"market": "0x7406898e6ec1bfc478fb7c0b0ee2c425f651ad48700739caaa05d7ffada6c326", "asset_id": "77177992782379277188834811026700688385399386837043471039260711341762751742573", "timestamp": "1769383402268", "hash": "4760d030f152ef86b9e4ff4fcf88dda748aad161", "bids": [{"price": "0.01", "size": "5910.86"}, {"price": "0.02", "size": "2200"}, {"price": "0.03", "size": "6.74"}, {"price": "0.05", "size": "30"}, {"price": "0.06", "size": "533"}, {"price": "0.07", "size": "7.71"}, {"price": "0.1", "size": "560"}, {"price": "0.14", "size": "842.85"}, {"price": "0.19", "size": "318.42"}, {"price": "0.2", "size": "5.74"}, {"price": "0.24", "size": "116.66"}, {"price": "0.29", "size": "89.65"}, {"price": "0.34", "size": "70.58"}, {"price": "0.38", "size": "52.63"}, {"price": "0.39", "size": "150"}, {"price": "0.41", "size": "62"}, {"price": "0.47", "size": "100"}, {"price": "0.48", "size": "30"}, {"price": "0.49", "size": "17"}, {"price": "0.52", "size": "48.97"}, {"price": "0.53", "size": "5"}, {"price": "0.91", "size": "23.8"}], "asks": [{"price": "0.99", "size": "5"}, {"price": "0.96", "size": "12"}], "event_type": "book", "last_trade_price": ""}]}
{"_local_timestamp": "2026-01-25T23:33:48.213572+00:00", "data": {"market": "0x09e25ccabb32e8d68fed95405ffe3975ffcb2af7de61b1de2f4eb22f1b375029", "price_changes": [{"asset_id": "91673509190321458869106560782565319947503739452675658246836850790481377708221", "price": "0.03", "size": "0", "side": "BUY", "hash": "52b62e2d0b86eb6e7e99ff374d5b60911267a96d", "best_bid": "0.18", "best_ask": "0.38"}, {"asset_id": "89658892949676737922541358818208957757334253491716424169833323571160167352106", "price": "0.97", "size": "0", "side": "SELL", "hash": "ed347b962774fd0cb0ebf36c9f6e0c9a3f553acb", "best_bid": "0.62", "best_ask": "0.82"}], "timestamp": "1769384028141", "event_type": "price_change"}}
{"_local_timestamp": "2026-01-25T23:34:00.614532+00:00", "data": {"market": "0x422eecd1eec8d501c70508387d11b1ca7550da75002dcdc448d4d99236df53a9", "price_changes": [{"asset_id": "92095665890628866412192885284169451045487268875038936631172018308093854978979", "price": "0.012", "size": "0", "side": "BUY", "hash": "221a1cbf5cd9b0cd89191af7939d29b586feed3d", "best_bid": "0.562", "best_ask": "0.989"}, {"asset_id": "37786111380458799656608112817818264473709140890522870941671572177308421431721", "price": "0.988", "size": "0", "side": "SELL", "hash": "381f65e648d7190b5ac66204dcb69cda9f116134", "best_bid": "0.011", "best_ask": "0.438"}], "timestamp": "1769384040542", "event_type": "price_change"}}
{"_local_timestamp": "2026-01-25T23:34:01.024797+00:00", "data": {"market": "0x422eecd1eec8d501c70508387d11b1ca7550da75002dcdc448d4d99236df53a9", "price_changes": [{"asset_id": "92095665890628866412192885284169451045487268875038936631172018308093854978979", "price": "0.011", "size": "6.91", "side": "BUY", "hash": "3f3274d5d96489842f673dcd7c5e33ca8a5f4213", "best_bid": "0.562", "best_ask": "0.989"}, {"asset_id": "37786111380458799656608112817818264473709140890522870941671572177308421431721", "price": "0.989", "size": "6.91", "side": "SELL", "hash": "2dd33db6fa0327227b41a279a9450fecc841651b", "best_bid": "0.011", "best_ask": "0.438"}], "timestamp": "1769384040950", "event_type": "price_change"}}
{"_local_timestamp": "2026-01-25T23:34:02.392301+00:00", "data": {"market": "0xba8526e4bf87c26c043d7048d364508d066117c173a91f2c56a82128fdc9102c", "price_changes": [{"asset_id": "49259132375860726199054520213393805061519699612170190892474472339512233385785", "price": "0.02", "size": "0", "side": "BUY", "hash": "7d6f8a4187508a32d632e0bbdd205d406ad971af", "best_bid": "0.28", "best_ask": "0.73"}, {"asset_id": "32267317137576261468029282489488620944358875503578558321905938935435579396497", "price": "0.98", "size": "0", "side": "SELL", "hash": "efb761106a540dd323ede039ab5d7b2a0a6526e2", "best_bid": "0.27", "best_ask": "0.72"}], "timestamp": "1769384042313", "event_type": "price_change"}}
{"_local_timestamp": "2026-01-25T23:34:02.392725+00:00", "data": {"market": "0xba8526e4bf87c26c043d7048d364508d066117c173a91f2c56a82128fdc9102c", "price_changes": [{"asset_id": "49259132375860726199054520213393805061519699612170190892474472339512233385785", "price": "0.06", "size": "300", "side": "BUY", "hash": "7d6f8a4187508a32d632e0bbdd205d406ad971af", "best_bid": "0.28", "best_ask": "0.73"}, {"asset_id": "32267317137576261468029282489488620944358875503578558321905938935435579396497", "price": "0.94", "size": "300", "side": "SELL", "hash": "efb761106a540dd323ede039ab5d7b2a0a6526e2", "best_bid": "0.27", "best_ask": "0.72"}], "timestamp": "1769384042313", "event_type": "price_change"}}
{"_local_timestamp": "2026-01-25T23:34:02.737424+00:00", "data": {"market": "0xba8526e4bf87c26c043d7048d364508d066117c173a91f2c56a82128fdc9102c", "price_changes": [{"asset_id": "49259132375860726199054520213393805061519699612170190892474472339512233385785", "price": "0.02", "size": "13.51", "side": "BUY", "hash": "009a429cc4cfafb070b1deee5b7a8259c534bea2", "best_bid": "0.28", "best_ask": "0.73"}, {"asset_id": "32267317137576261468029282489488620944358875503578558321905938935435579396497", "price": "0.98", "size": "13.51", "side": "SELL", "hash": "5bd5cedfa7b0dcdae60a9148de7c32a49da10efa", "best_bid": "0.27", "best_ask": "0.72"}], "timestamp": "1769384042672", "event_type": "price_change"}}
{"_local_timestamp": "2026-01-25T23:34:02.739194+00:00", "data": {"market": "0xba8526e4bf87c26c043d7048d364508d066117c173a91f2c56a82128fdc9102c", "price_changes": [{"asset_id": "49259132375860726199054520213393805061519699612170190892474472339512233385785", "price": "0.05", "size": "815.03", "side": "BUY", "hash": "99f1c6d897b53a6ad5f971a6b1b41a971211c737", "best_bid": "0.28", "best_ask": "0.73"}, {"asset_id": "32267317137576261468029282489488620944358875503578558321905938935435579396497", "price": "0.95", "size": "815.03", "side": "SELL", "hash": "577a4358407e72c1023c9cc06c09a993ad0afdd5", "best_bid": "0.27", "best_ask": "0.72"}], "timestamp": "1769384042673", "event_type": "price_change"}}
{"_local_timestamp": "2026-01-25T23:34:02.741048+00:00", "data": {"market": "0xba8526e4bf87c26c043d7048d364508d066117c173a91f2c56a82128fdc9102c", "price_changes": [{"asset_id": "49259132375860726199054520213393805061519699612170190892474472339512233385785", "price": "0.08", "size": "17.29", "side": "BUY", "hash": "c50fb0b0ae6918c86a27e5ada7cd7c02212c007e", "best_bid": "0.28", "best_ask": "0.73"}, {"asset_id": "32267317137576261468029282489488620944358875503578558321905938935435579396497", "price": "0.92", "size": "17.29", "side": "SELL", "hash": "cce8e82cc1d246b9b2c4da5f8485e3dd5aaf9c14", "best_bid": "0.27", "best_ask": "0.72"}], "timestamp": "1769384042675", "event_type": "price_change"}}
{"_local_timestamp": "2026-01-25T23:34:12.944631+00:00", "data": {"market": "0x422eecd1eec8d501c70508387d11b1ca7550da75002dcdc448d4d99236df53a9", "price_changes": [{"asset_id": "92095665890628866412192885284169451045487268875038936631172018308093854978979", "price": "0.023", "size": "0", "side": "BUY", "hash": "9ab5e813dd821369dc0fa8a606b83a4eaaa2bd16", "best_bid": "0.562", "best_ask": "0.989"}, {"asset_id": "37786111380458799656608112817818264473709140890522870941671572177308421431721", "price": "0.977", "size": "0", "side": "SELL", "hash": "dc86d2a4b4ca47c3d7b450b0e83e5be796a2cb8f", "best_bid": "0.011", "best_ask": "0.438"}], "timestamp": "1769384052806", "event_type": "price_change"}}
{"_local_timestamp": "2026-01-25T23:34:12.982233+00:00", "data": {"market": "0x422eecd1eec8d501c70508387d11b1ca7550da75002dcdc448d4d99236df53a9", "price_changes": [{"asset_id": "37786111380458799656608112817818264473709140890522870941671572177308421431721", "price": "0.005", "size": "10.17", "side": "BUY", "hash": "1d272ee09d64095de99e1677ef7cc6ae813b7070", "best_bid": "0.011", "best_ask": "0.438"}, {"asset_id": "92095665890628866412192885284169451045487268875038936631172018308093854978979", "price": "0.995", "size": "10.17", "side": "SELL", "hash": "22e3dd41950ca8e09524a997ce20253f2029ced4", "best_bid": "0.562", "best_ask": "0.989"}], "timestamp": "1769384052807", "event_type": "price_change"}}
{"_local_timestamp": "2026-01-25T23:34:12.985960+00:00", "data": {"market": "0x09e25ccabb32e8d68fed95405ffe3975ffcb2af7de61b1de2f4eb22f1b375029", "price_changes": [{"asset_id": "89658892949676737922541358818208957757334253491716424169833323571160167352106", "price": "0.05", "size": "30", "side": "BUY", "hash": "dc2e5187bc5c0a0c5a1531eb1a863c4cc72d592d", "best_bid": "0.62", "best_ask": "0.82"}, {"asset_id": "91673509190321458869106560782565319947503739452675658246836850790481377708221", "price": "0.95", "size": "30", "side": "SELL", "hash": "f10aad2dd1b6f2a295edd4c07d305f08276562f9", "best_bid": "0.18", "best_ask": "0.38"}], "timestamp": "1769384052815", "event_type": "price_change"}}
{"_local_timestamp": "2026-01-25T23:34:12.994647+00:00", "data": {"market": "0xba8526e4bf87c26c043d7048d364508d066117c173a91f2c56a82128fdc9102c", "price_changes": [{"asset_id": "49259132375860726199054520213393805061519699612170190892474472339512233385785", "price": "0.05", "size": "715.03", "side": "BUY", "hash": "e9275ddb3e202a4a34cbd05b2937f9f5b36637b0", "best_bid": "0.28", "best_ask": "0.73"}, {"asset_id": "32267317137576261468029282489488620944358875503578558321905938935435579396497", "price": "0.95", "size": "715.03", "side": "SELL", "hash": "7891d887fb00434b455824433dc1055134c4b39a", "best_bid": "0.27", "best_ask": "0.72"}], "timestamp": "1769384052816", "event_type": "price_change"}}
{"_local_timestamp": "2026-01-25T23:34:13.383782+00:00", "data": {"market": "0x422eecd1eec8d501c70508387d11b1ca7550da75002dcdc448d4d99236df53a9", "price_changes": [{"asset_id": "37786111380458799656608112817818264473709140890522870941671572177308421431721", "price": "0.004", "size": "217.66", "side": "BUY", "hash": "ec130235f659760c84607b194c6e0237f3f871d0", "best_bid": "0.011", "best_ask": "0.438"}, {"asset_id": "92095665890628866412192885284169451045487268875038936631172018308093854978979", "price": "0.996", "size": "217.66", "side": "SELL", "hash": "2cdc3c636bfe8a71a83b81948069bc14dc1196f0", "best_bid": "0.562", "best_ask": "0.989"}], "timestamp": "1769384053266", "event_type": "price_change"}}
{"_local_timestamp": "2026-01-25T23:34:13.393945+00:00", "data": {"market": "0x09e25ccabb32e8d68fed95405ffe3975ffcb2af7de61b1de2f4eb22f1b375029", "price_changes": [{"asset_id": "89658892949676737922541358818208957757334253491716424169833323571160167352106", "price": "0.04", "size": "200", "side": "BUY", "hash": "ecfcfc8e4d5fae50b99d7e09980bb4368ebcc16b", "best_bid": "0.62", "best_ask": "0.82"}, {"asset_id": "91673509190321458869106560782565319947503739452675658246836850790481377708221", "price": "0.96", "size": "200", "side": "SELL", "hash": "267f46afbf66fe68d1e16892d7c7fb534da1da1f", "best_bid": "0.18", "best_ask": "0.38"}], "timestamp": "1769384053269", "event_type": "price_change"}}
{"_local_timestamp": "2026-01-25T23:34:13.397667+00:00", "data": {"market": "0xba8526e4bf87c26c043d7048d364508d066117c173a91f2c56a82128fdc9102c", "price_changes": [{"asset_id": "49259132375860726199054520213393805061519699612170190892474472339512233385785", "price": "0.08", "size": "117.29", "side": "BUY", "hash": "a074c7c131e8f75fb4037bd826f95b84ee06d19b", "best_bid": "0.28", "best_ask": "0.73"}, {"asset_id": "32267317137576261468029282489488620944358875503578558321905938935435579396497", "price": "0.92", "size": "117.29", "side": "SELL", "hash": "cde2dc796fbd4f32ab650e7c5a785fff11d1de3d", "best_bid": "0.27", "best_ask": "0.72"}], "timestamp": "1769384053270", "event_type": "price_change"}}
{"_local_timestamp": "2026-01-25T23:34:18.032727+00:00", "data": {"market": "0x422eecd1eec8d501c70508387d11b1ca7550da75002dcdc448d4d99236df53a9", "price_changes": [{"asset_id": "92095665890628866412192885284169451045487268875038936631172018308093854978979", "price": "0.261", "size": "0", "side": "BUY", "hash": "c693f13de826228a0da92901c5298faf2b6aa69f", "best_bid": "0.562", "best_ask": "0.989"}, {"asset_id": "37786111380458799656608112817818264473709140890522870941671572177308421431721", "price": "0.739", "size": "0", "side": "SELL", "hash": "3cf24248697d1d0e869c9cc4e069c399643ddeba", "best_bid": "0.011", "best_ask": "0.438"}], "timestamp": "1769384057957", "event_type": "price_change"}}
{"_local_timestamp": "2026-01-25T23:34:18.087051+00:00", "data": {"market": "0x422eecd1eec8d501c70508387d11b1ca7550da75002dcdc448d4d99236df53a9", "price_changes": [{"asset_id": "92095665890628866412192885284169451045487268875038936631172018308093854978979", "price": "0.216", "size": "9", "side": "BUY", "hash": "143681c499142f9ec6c584fa236571cc46e8fd7e", "best_bid": "0.562", "best_ask": "0.989"}, {"asset_id": "37786111380458799656608112817818264473709140890522870941671572177308421431721", "price": "0.784", "size": "9", "side": "SELL", "hash": "0b4b69a3cb1295121748c8078190b6c9427436be", "best_bid": "0.011", "best_ask": "0.438"}], "timestamp": "1769384058009", "event_type": "price_change"}}
{"_local_timestamp": "2026-01-25T23:34:24.319111+00:00", "data": {"market": "0x09e25ccabb32e8d68fed95405ffe3975ffcb2af7de61b1de2f4eb22f1b375029", "price_changes": [{"asset_id": "89658892949676737922541358818208957757334253491716424169833323571160167352106", "price": "0.13", "size": "150", "side": "BUY", "hash": "deaff1f17e1d91a49798d09c1a729c621c2169d1", "best_bid": "0.62", "best_ask": "0.82"}, {"asset_id": "91673509190321458869106560782565319947503739452675658246836850790481377708221", "price": "0.87", "size": "150", "side": "SELL", "hash": "7a5605536aec6a79833df73f1a4c23bda6454619", "best_bid": "0.18", "best_ask": "0.38"}], "timestamp": "1769384064246", "event_type": "price_change"}}
{"_local_timestamp": "2026-01-25T23:34:26.018729+00:00", "data": {"market": "0x09e25ccabb32e8d68fed95405ffe3975ffcb2af7de61b1de2f4eb22f1b375029", "price_changes": [{"asset_id": "89658892949676737922541358818208957757334253491716424169833323571160167352106", "price": "0.01", "size": "4600", "side": "BUY", "hash": "849e91b27ca3678e1d21d1e4e88d448775daf2ab", "best_bid": "0.62", "best_ask": "0.82"}, {"asset_id": "91673509190321458869106560782565319947503739452675658246836850790481377708221", "price": "0.99", "size": "4600", "side": "SELL", "hash": "d8733bc0b3356f61169af6ce0a18b9e21ba1c291", "best_bid": "0.18", "best_ask": "0.38"}], "timestamp": "1769384065945", "event_type": "price_change"}}
{"_local_timestamp": "2026-01-25T23:34:26.020373+00:00", "data": {"market": "0x09e25ccabb32e8d68fed95405ffe3975ffcb2af7de61b1de2f4eb22f1b375029", "price_changes": [{"asset_id": "89658892949676737922541358818208957757334253491716424169833323571160167352106", "price": "0.03", "size": "300", "side": "BUY", "hash": "849e91b27ca3678e1d21d1e4e88d448775daf2ab", "best_bid": "0.62", "best_ask": "0.82"}, {"asset_id": "91673509190321458869106560782565319947503739452675658246836850790481377708221", "price": "0.97", "size": "300", "side": "SELL", "hash": "d8733bc0b3356f61169af6ce0a18b9e21ba1c291", "best_bid": "0.18", "best_ask": "0.38"}], "timestamp": "1769384065945", "event_type": "price_change"}}
{"_local_timestamp": "2026-01-25T23:34:26.021156+00:00", "data": {"market": "0x09e25ccabb32e8d68fed95405ffe3975ffcb2af7de61b1de2f4eb22f1b375029", "price_changes": [{"asset_id": "89658892949676737922541358818208957757334253491716424169833323571160167352106", "price": "0.07", "size": "100", "side": "BUY", "hash": "849e91b27ca3678e1d21d1e4e88d448775daf2ab", "best_bid": "0.62", "best_ask": "0.82"}, {"asset_id": "91673509190321458869106560782565319947503739452675658246836850790481377708221", "price": "0.93", "size": "100", "side": "SELL", "hash": "d8733bc0b3356f61169af6ce0a18b9e21ba1c291", "best_bid": "0.18", "best_ask": "0.38"}], "timestamp": "1769384065945", "event_type": "price_change"}}
{"_local_timestamp": "2026-01-25T23:34:26.281559+00:00", "data": {"market": "0x09e25ccabb32e8d68fed95405ffe3975ffcb2af7de61b1de2f4eb22f1b375029", "price_changes": [{"asset_id": "89658892949676737922541358818208957757334253491716424169833323571160167352106", "price": "0.04", "size": "205.43", "side": "BUY", "hash": "21676256d811a603a81e95a11721c882eb4a19b3", "best_bid": "0.62", "best_ask": "0.82"}, {"asset_id": "91673509190321458869106560782565319947503739452675658246836850790481377708221", "price": "0.96", "size": "205.43", "side": "SELL", "hash": "b17b30005eff168c71f45e5a211b882487c03b63", "best_bid": "0.18", "best_ask": "0.38"}], "timestamp": "1769384066201", "event_type": "price_change"}}
{"_local_timestamp": "2026-01-25T23:34:26.321403+00:00", "data": {"market": "0x09e25ccabb32e8d68fed95405ffe3975ffcb2af7de61b1de2f4eb22f1b375029", "price_changes": [{"asset_id": "89658892949676737922541358818208957757334253491716424169833323571160167352106", "price": "0.01", "size": "4606.04", "side": "BUY", "hash": "d3402fdbde216253764c119a20fcc221d63770eb", "best_bid": "0.62", "best_ask": "0.82"}, {"asset_id": "91673509190321458869106560782565319947503739452675658246836850790481377708221", "price": "0.99", "size": "4606.04", "side": "SELL", "hash": "83ba5066d12ee23ea334f0b7dcb31a66e53635c7", "best_bid": "0.18", "best_ask": "0.38"}], "timestamp": "1769384066215", "event_type": "price_change"}}
{"_local_timestamp": "2026-01-25T23:34:26.346082+00:00", "data": {"market": "0x09e25ccabb32e8d68fed95405ffe3975ffcb2af7de61b1de2f4eb22f1b375029", "price_changes": [{"asset_id": "89658892949676737922541358818208957757334253491716424169833323571160167352106", "price": "0.08", "size": "5.25", "side": "BUY", "hash": "681f6b4b3253630116f148b161bfbd6584395a21", "best_bid": "0.62", "best_ask": "0.82"}, {"asset_id": "91673509190321458869106560782565319947503739452675658246836850790481377708221", "price": "0.92", "size": "5.25", "side": "SELL", "hash": "6f1bf47256962ea93dc2c9ff851542a82641a0d8", "best_bid": "0.18", "best_ask": "0.38"}], "timestamp": "1769384066223", "event_type": "price_change"}}
{"_local_timestamp": "2026-01-25T23:34:26.347144+00:00", "data": {"market": "0x09e25ccabb32e8d68fed95405ffe3975ffcb2af7de61b1de2f4eb22f1b375029", "price_changes": [{"asset_id": "89658892949676737922541358818208957757334253491716424169833323571160167352106", "price": "0.02", "size": "1805.83", "side": "BUY", "hash": "e92f5e2ad83c8d0bf4f8aa25d66063abfc26fff4", "best_bid": "0.62", "best_ask": "0.82"}, {"asset_id": "91673509190321458869106560782565319947503739452675658246836850790481377708221", "price": "0.98", "size": "1805.83", "side": "SELL", "hash": "c588a202392191b30c0c9069f0fbea6b1ea642cb", "best_bid": "0.18", "best_ask": "0.38"}], "timestamp": "1769384066231", "event_type": "price_change"}}
{"_local_timestamp": "2026-01-25T23:34:27.698908+00:00", "data": {"market": "0x422eecd1eec8d501c70508387d11b1ca7550da75002dcdc448d4d99236df53a9", "price_changes": [{"asset_id": "92095665890628866412192885284169451045487268875038936631172018308093854978979", "price": "0.11", "size": "225", "side": "BUY", "hash": "66ce4208de123bccc5757f5e853cdbb284a9fc18", "best_bid": "0.562", "best_ask": "0.989"}, {"asset_id": "37786111380458799656608112817818264473709140890522870941671572177308421431721", "price": "0.89", "size": "225", "side": "SELL", "hash": "e9cbed6dcd1707437fdec473ced63536082702c1", "best_bid": "0.011", "best_ask": "0.438"}], "timestamp": "1769384067570", "event_type": "price_change"}}
{"_local_timestamp": "2026-01-25T23:34:28.348302+00:00", "data": {"market": "0x422eecd1eec8d501c70508387d11b1ca7550da75002dcdc448d4d99236df53a9", "price_changes": [{"asset_id": "92095665890628866412192885284169451045487268875038936631172018308093854978979", "price": "0.111", "size": "325", "side": "BUY", "hash": "2e016d4f8bae7746a45852b50df31d77461adc86", "best_bid": "0.562", "best_ask": "0.989"}, {"asset_id": "37786111380458799656608112817818264473709140890522870941671572177308421431721", "price": "0.889", "size": "325", "side": "SELL", "hash": "8c57804ad7ec6d66bc7d9aa7b820819fbf6c2fca", "best_bid": "0.011", "best_ask": "0.438"}], "timestamp": "1769384068096", "event_type": "price_change"}}
{"_local_timestamp": "2026-01-25T23:34:54.627756+00:00", "data": {"market": "0x422eecd1eec8d501c70508387d11b1ca7550da75002dcdc448d4d99236df53a9", "price_changes": [{"asset_id": "37786111380458799656608112817818264473709140890522870941671572177308421431721", "price": "0.003", "size": "400.44", "side": "BUY", "hash": "88cfd41e827015b015e6e3ba13ed86a350f3bb93", "best_bid": "0.011", "best_ask": "0.438"}, {"asset_id": "92095665890628866412192885284169451045487268875038936631172018308093854978979", "price": "0.997", "size": "400.44", "side": "SELL", "hash": "cee3c36523ee48756097f517d14d571503172cce", "best_bid": "0.562", "best_ask": "0.989"}], "timestamp": "1769384094546", "event_type": "price_change"}}
{"_local_timestamp": "2026-01-25T23:34:54.993073+00:00", "data": {"market": "0x422eecd1eec8d501c70508387d11b1ca7550da75002dcdc448d4d99236df53a9", "price_changes": [{"asset_id": "37786111380458799656608112817818264473709140890522870941671572177308421431721", "price": "0.004", "size": "317.66", "side": "BUY", "hash": "07ae66b3971642d1f0178db58e5c55b1436266b8", "best_bid": "0.011", "best_ask": "0.438"}, {"asset_id": "92095665890628866412192885284169451045487268875038936631172018308093854978979", "price": "0.996", "size": "317.66", "side": "SELL", "hash": "239dfd28a062826f13197dbfbe2de0ade7b36469", "best_bid": "0.562", "best_ask": "0.989"}], "timestamp": "1769384094891", "event_type": "price_change"}}
{"_local_timestamp": "2026-01-25T23:35:12.175174+00:00", "data": {"market": "0xba8526e4bf87c26c043d7048d364508d066117c173a91f2c56a82128fdc9102c", "price_changes": [{"asset_id": "32267317137576261468029282489488620944358875503578558321905938935435579396497", "price": "0.14", "size": "7.14", "side": "BUY", "hash": "d92f5c71eb80cf83f12dd5a07e54af4f571f26d8", "best_bid": "0.27", "best_ask": "0.72"}, {"asset_id": "49259132375860726199054520213393805061519699612170190892474472339512233385785", "price": "0.86", "size": "7.14", "side": "SELL", "hash": "76fdaf2209a8d03a12cb95861a3d4c08cdcf2391", "best_bid": "0.28", "best_ask": "0.73"}], "timestamp": "1769384112066", "event_type": "price_change"}}
{"_local_timestamp": "2026-01-25T23:35:12.176040+00:00", "data": {"market": "0xba8526e4bf87c26c043d7048d364508d066117c173a91f2c56a82128fdc9102c", "price_changes": [{"asset_id": "32267317137576261468029282489488620944358875503578558321905938935435579396497", "price": "0.01", "size": "5", "side": "BUY", "hash": "d92f5c71eb80cf83f12dd5a07e54af4f571f26d8", "best_bid": "0.27", "best_ask": "0.72"}, {"asset_id": "49259132375860726199054520213393805061519699612170190892474472339512233385785", "price": "0.99", "size": "5", "side": "SELL", "hash": "76fdaf2209a8d03a12cb95861a3d4c08cdcf2391", "best_bid": "0.28", "best_ask": "0.73"}], "timestamp": "1769384112066", "event_type": "price_change"}}
{"_local_timestamp": "2026-01-25T23:35:12.478454+00:00", "data": {"market": "0xba8526e4bf87c26c043d7048d364508d066117c173a91f2c56a82128fdc9102c", "price_changes": [{"asset_id": "32267317137576261468029282489488620944358875503578558321905938935435579396497", "price": "0.28", "size": "39.61", "side": "BUY", "hash": "2164298c7a580b79ef6a1efe05cc7fe774732f4f", "best_bid": "0.28", "best_ask": "0.72"}, {"asset_id": "49259132375860726199054520213393805061519699612170190892474472339512233385785", "price": "0.72", "size": "39.61", "side": "SELL", "hash": "8bf2fa51920afd17c2b040f07848aa93dc363f2b", "best_bid": "0.28", "best_ask": "0.72"}], "timestamp": "1769384112415", "event_type": "price_change"}}
{"_local_timestamp": "2026-01-25T23:35:12.536131+00:00", "data": {"market": "0xba8526e4bf87c26c043d7048d364508d066117c173a91f2c56a82128fdc9102c", "price_changes": [{"asset_id": "32267317137576261468029282489488620944358875503578558321905938935435579396497", "price": "0.01", "size": "44.61", "side": "BUY", "hash": "4e4c14d1ec33eda75fd0ad29ffdb2d7178a346d6", "best_bid": "0.28", "best_ask": "0.72"}, {"asset_id": "49259132375860726199054520213393805061519699612170190892474472339512233385785", "price": "0.99", "size": "44.61", "side": "SELL", "hash": "29c0021c86b50270578f12375abe142baaa4c9b0", "best_bid": "0.28", "best_ask": "0.72"}], "timestamp": "1769384112468", "event_type": "price_change"}}
{"_local_timestamp": "2026-01-25T23:35:12.573881+00:00", "data": {"market": "0xba8526e4bf87c26c043d7048d364508d066117c173a91f2c56a82128fdc9102c", "price_changes": [{"asset_id": "32267317137576261468029282489488620944358875503578558321905938935435579396497", "price": "0.14", "size": "46.75", "side": "BUY", "hash": "3986f3170283007ee2e2fabb6f0cdc4b2d9005ee", "best_bid": "0.28", "best_ask": "0.72"}, {"asset_id": "49259132375860726199054520213393805061519699612170190892474472339512233385785", "price": "0.86", "size": "46.75", "side": "SELL", "hash": "ced4c3802a8c6ad8f9e11f39c0ac610856e45679", "best_bid": "0.28", "best_ask": "0.72"}], "timestamp": "1769384112504", "event_type": "price_change"}}
{"_local_timestamp": "2026-01-25T23:35:12.826498+00:00", "data": {"market": "0xc3a4cae673b27efa91532ddb90b398930318186e51e01ff0c8eb783a0dbcd4e7", "price_changes": [{"asset_id": "96741359658621321208991066620310092016019156810960175572658869255516755049336", "price": "0.47", "size": "30", "side": "BUY", "hash": "f90b6e7ed433c7d9cf18eff1535c91f2895e9fbd", "best_bid": "0.91", "best_ask": "0.95"}, {"asset_id": "8608317574717919639592346411602668438605050919704951969833903607649299947045", "price": "0.53", "size": "30", "side": "SELL", "hash": "6efac0b814723b54a9194daa2788e6dab4e239e5", "best_bid": "0.05", "best_ask": "0.09"}], "timestamp": "1769384112760", "event_type": "price_change"}}
{"_local_timestamp": "2026-01-25T23:35:12.827104+00:00", "data": {"market": "0x422eecd1eec8d501c70508387d11b1ca7550da75002dcdc448d4d99236df53a9", "price_changes": [{"asset_id": "92095665890628866412192885284169451045487268875038936631172018308093854978979", "price": "0.401", "size": "0", "side": "BUY", "hash": "31ac056b66eba27c955b671885590958de879b31", "best_bid": "0.562", "best_ask": "0.989"}, {"asset_id": "37786111380458799656608112817818264473709140890522870941671572177308421431721", "price": "0.599", "size": "0", "side": "SELL", "hash": "28e0fde20cb0e6361c2bd4b1b3d05598fcdc80ab", "best_bid": "0.011", "best_ask": "0.438"}], "timestamp": "1769384112760", "event_type": "price_change"}}
{"_local_timestamp": "2026-01-25T23:35:12.858252+00:00", "data": {"market": "0x422eecd1eec8d501c70508387d11b1ca7550da75002dcdc448d4d99236df53a9", "price_changes": [{"asset_id": "92095665890628866412192885284169451045487268875038936631172018308093854978979", "price": "0.533", "size": "17", "side": "BUY", "hash": "26d92bca0b23f4410d5e64a810488f5e2d2485e7", "best_bid": "0.562", "best_ask": "0.989"}, {"asset_id": "37786111380458799656608112817818264473709140890522870941671572177308421431721", "price": "0.467", "size": "17", "side": "SELL", "hash": "e549b14b95242df36afec9d35a8aa178a27be692", "best_bid": "0.011", "best_ask": "0.438"}], "timestamp": "1769384112791", "event_type": "price_change"}}
{"_local_timestamp": "2026-01-25T23:35:12.858733+00:00", "data": {"market": "0xc3a4cae673b27efa91532ddb90b398930318186e51e01ff0c8eb783a0dbcd4e7", "price_changes": [{"asset_id": "96741359658621321208991066620310092016019156810960175572658869255516755049336", "price": "0.48", "size": "17", "side": "BUY", "hash": "2d0ad7e6b34bf82f8223c9ca53608b3055d61f4d", "best_bid": "0.91", "best_ask": "0.95"}, {"asset_id": "8608317574717919639592346411602668438605050919704951969833903607649299947045", "price": "0.52", "size": "17", "side": "SELL", "hash": "58bbdc771acffb741fd17f33d0379a9f05d0b3ce", "best_bid": "0.05", "best_ask": "0.09"}], "timestamp": "1769384112791", "event_type": "price_change"}}
{"_local_timestamp": "2026-01-25T23:35:23.786294+00:00", "data": {"market": "0x422eecd1eec8d501c70508387d11b1ca7550da75002dcdc448d4d99236df53a9", "price_changes": [{"asset_id": "92095665890628866412192885284169451045487268875038936631172018308093854978979", "price": "0.11", "size": "0", "side": "BUY", "hash": "adc5be3454de4faafa2ff796a13867ddd0680d2f", "best_bid": "0.562", "best_ask": "0.989"}, {"asset_id": "37786111380458799656608112817818264473709140890522870941671572177308421431721", "price": "0.89", "size": "0", "side": "SELL", "hash": "3ac3a3dae6135eca68b5f1295120ba4e69e1e249", "best_bid": "0.011", "best_ask": "0.438"}], "timestamp": "1769384123679", "event_type": "price_change"}}
{"_local_timestamp": "2026-01-25T23:35:23.786694+00:00", "data": {"market": "0x09e25ccabb32e8d68fed95405ffe3975ffcb2af7de61b1de2f4eb22f1b375029", "price_changes": [{"asset_id": "89658892949676737922541358818208957757334253491716424169833323571160167352106", "price": "0.11", "size": "50", "side": "BUY", "hash": "88825859a4dc8a76357a55a4c73b226983598207", "best_bid": "0.62", "best_ask": "0.82"}, {"asset_id": "91673509190321458869106560782565319947503739452675658246836850790481377708221", "price": "0.89", "size": "50", "side": "SELL", "hash": "1d4104e0321de615e8fb06bcd4dad713913a5ec9", "best_bid": "0.18", "best_ask": "0.38"}], "timestamp": "1769384123679", "event_type": "price_change"}}
{"_local_timestamp": "2026-01-25T23:35:24.231407+00:00", "data": {"market": "0x422eecd1eec8d501c70508387d11b1ca7550da75002dcdc448d4d99236df53a9", "price_changes": [{"asset_id": "92095665890628866412192885284169451045487268875038936631172018308093854978979", "price": "0.111", "size": "550", "side": "BUY", "hash": "1ee0c68ee3359fbd7d047e515d9600cdde1533b7", "best_bid": "0.562", "best_ask": "0.989"}, {"asset_id": "37786111380458799656608112817818264473709140890522870941671572177308421431721", "price": "0.889", "size": "550", "side": "SELL", "hash": "d86688a53c9b5a272e1fa41ace2fa53e65951b8e", "best_bid": "0.011", "best_ask": "0.438"}], "timestamp": "1769384123942", "event_type": "price_change"}}
{"_local_timestamp": "2026-01-25T23:35:26.651132+00:00", "data": {"market": "0x422eecd1eec8d501c70508387d11b1ca7550da75002dcdc448d4d99236df53a9", "price_changes": [{"asset_id": "92095665890628866412192885284169451045487268875038936631172018308093854978979", "price": "0.111", "size": "425", "side": "BUY", "hash": "d79493637b6a4570c97de708a533428ca122b25f", "best_bid": "0.562", "best_ask": "0.989"}, {"asset_id": "37786111380458799656608112817818264473709140890522870941671572177308421431721", "price": "0.889", "size": "425", "side": "SELL", "hash": "7dcbe46d3279bab25aee691f9e40ec5ceff16228", "best_bid": "0.011", "best_ask": "0.438"}], "timestamp": "1769384126560", "event_type": "price_change"}}
{"_local_timestamp": "2026-01-25T23:35:27.068575+00:00", "data": {"market": "0x422eecd1eec8d501c70508387d11b1ca7550da75002dcdc448d4d99236df53a9", "price_changes": [{"asset_id": "92095665890628866412192885284169451045487268875038936631172018308093854978979", "price": "0.11", "size": "125", "side": "BUY", "hash": "dd0880950779c2e64e607e0961c777cab1ce39e2", "best_bid": "0.562", "best_ask": "0.989"}, {"asset_id": "37786111380458799656608112817818264473709140890522870941671572177308421431721", "price": "0.89", "size": "125", "side": "SELL", "hash": "ce8378323bf4a04d23ee5a2f7e116a1f61980da5", "best_bid": "0.011", "best_ask": "0.438"}], "timestamp": "1769384126900", "event_type": "price_change"}}
{"_local_timestamp": "2026-01-25T23:35:30.795997+00:00", "data": {"market": "0x09e25ccabb32e8d68fed95405ffe3975ffcb2af7de61b1de2f4eb22f1b375029", "price_changes": [{"asset_id": "89658892949676737922541358818208957757334253491716424169833323571160167352106", "price": "0.11", "size": "0", "side": "BUY", "hash": "e7ce3caa5b6647a683ed76e8e29e3021a4366dfe", "best_bid": "0.62", "best_ask": "0.82"}, {"asset_id": "91673509190321458869106560782565319947503739452675658246836850790481377708221", "price": "0.89", "size": "0", "side": "SELL", "hash": "5e98279c29bfc23bca0e164639662f2831f1f913", "best_bid": "0.18", "best_ask": "0.38"}], "timestamp": "1769384130716", "event_type": "price_change"}}
{"_local_timestamp": "2026-01-25T23:35:30.796565+00:00", "data": {"market": "0xba8526e4bf87c26c043d7048d364508d066117c173a91f2c56a82128fdc9102c", "price_changes": [{"asset_id": "49259132375860726199054520213393805061519699612170190892474472339512233385785", "price": "0.07", "size": "100", "side": "BUY", "hash": "32a66e3dd5f636d200fe02f3b07cb76ebaed5e4c", "best_bid": "0.28", "best_ask": "0.72"}, {"asset_id": "32267317137576261468029282489488620944358875503578558321905938935435579396497", "price": "0.93", "size": "100", "side": "SELL", "hash": "2b0ddfc07d36588bc21dffd8f03fdbfa3683f5df", "best_bid": "0.28", "best_ask": "0.72"}], "timestamp": "1769384130716", "event_type": "price_change"}}
{"_local_timestamp": "2026-01-25T23:35:31.101122+00:00", "data": {"market": "0x09e25ccabb32e8d68fed95405ffe3975ffcb2af7de61b1de2f4eb22f1b375029", "price_changes": [{"asset_id": "89658892949676737922541358818208957757334253491716424169833323571160167352106", "price": "0.13", "size": "200", "side": "BUY", "hash": "8f66d6b5d29ed1da2962fd2c3070ac6297980bfa", "best_bid": "0.62", "best_ask": "0.82"}, {"asset_id": "91673509190321458869106560782565319947503739452675658246836850790481377708221", "price": "0.87", "size": "200", "side": "SELL", "hash": "9cb6076c7449907704c63312c34f682ecc8b50f4", "best_bid": "0.18", "best_ask": "0.38"}], "timestamp": "1769384131021", "event_type": "price_change"}}
{"_local_timestamp": "2026-01-25T23:35:31.101643+00:00", "data": {"market": "0xba8526e4bf87c26c043d7048d364508d066117c173a91f2c56a82128fdc9102c", "price_changes": [{"asset_id": "49259132375860726199054520213393805061519699612170190892474472339512233385785", "price": "0.08", "size": "417.29", "side": "BUY", "hash": "d3f89f15fbeddee6c06e47dff368d80075391622", "best_bid": "0.28", "best_ask": "0.72"}, {"asset_id": "32267317137576261468029282489488620944358875503578558321905938935435579396497", "price": "0.92", "size": "417.29", "side": "SELL", "hash": "ccfa9d2ad41ff35635608868733aaf90199b313c", "best_bid": "0.28", "best_ask": "0.72"}], "timestamp": "1769384131023", "event_type": "price_change"}}
{"_local_timestamp": "2026-01-25T23:35:33.850417+00:00", "data": {"market": "0x15dd98954f5a3d5bc21a6fe182d76bbde3e29af1465195df74a6f82c5be6fb2c", "price_changes": [{"asset_id": "50774184608010128165657683699294077924184178889265892143108921917710895798073", "price": "0.007", "size": "196.17", "side": "BUY", "hash": "e291ee15147e52368400bda80b891b21eb30be76", "best_bid": "0.013", "best_ask": "0.431"}, {"asset_id": "103448363933352469180704380615499404975348483690550986365085327126347374707599", "price": "0.993", "size": "196.17", "side": "SELL", "hash": "bb5505422d47a620c8ac6c03923d11f0b97874ef", "best_bid": "0.569", "best_ask": "0.987"}], "timestamp": "1769384133783", "event_type": "price_change"}}
{"_local_timestamp": "2026-01-25T23:35:34.626459+00:00", "data": {"market": "0xa103fd29e21844a2c37dbae0ddd5abc05c9a899652f82b185b1cfd02d18e052e", "price_changes": [{"asset_id": "84850580000869621913865680797117970052468736368951185577800573275538604924241", "price": "0.001", "size": "14427", "side": "BUY", "hash": "df2d12973f7ac1c96ec07631c540878bb31a0a3b", "best_bid": "0.008", "best_ask": "0.027"}, {"asset_id": "68251780522342786457624382430403984200536262465760434117810614118555332248086", "price": "0.999", "size": "14427", "side": "SELL", "hash": "b7cd7171f9577d91370ea08094539810dd4144d1", "best_bid": "0.973", "best_ask": "0.992"}], "timestamp": "1769384134558", "event_type": "price_change"}}
{"_local_timestamp": "2026-01-25T23:35:34.626964+00:00", "data": {"market": "0xa103fd29e21844a2c37dbae0ddd5abc05c9a899652f82b185b1cfd02d18e052e", "price_changes": [{"asset_id": "84850580000869621913865680797117970052468736368951185577800573275538604924241", "price": "0.002", "size": "916", "side": "BUY", "hash": "df2d12973f7ac1c96ec07631c540878bb31a0a3b", "best_bid": "0.008", "best_ask": "0.027"}, {"asset_id": "68251780522342786457624382430403984200536262465760434117810614118555332248086", "price": "0.998", "size": "916", "side": "SELL", "hash": "b7cd7171f9577d91370ea08094539810dd4144d1", "best_bid": "0.973", "best_ask": "0.992"}], "timestamp": "1769384134558", "event_type": "price_change"}}
{"_local_timestamp": "2026-01-25T23:35:34.907911+00:00", "data": {"market": "0xa103fd29e21844a2c37dbae0ddd5abc05c9a899652f82b185b1cfd02d18e052e", "price_changes": [{"asset_id": "84850580000869621913865680797117970052468736368951185577800573275538604924241", "price": "0.002", "size": "1034.56", "side": "BUY", "hash": "f15d754bee224aa47d4460fb846b2f4a6a7a2c4e", "best_bid": "0.008", "best_ask": "0.027"}, {"asset_id": "68251780522342786457624382430403984200536262465760434117810614118555332248086", "price": "0.998", "size": "1034.56", "side": "SELL", "hash": "699d5b8f77cc9d89e3d0cbc484bbfe4c5f625e6b", "best_bid": "0.973", "best_ask": "0.992"}], "timestamp": "1769384134836", "event_type": "price_change"}}
{"_local_timestamp": "2026-01-25T23:35:34.915480+00:00", "data": {"market": "0xa103fd29e21844a2c37dbae0ddd5abc05c9a899652f82b185b1cfd02d18e052e", "price_changes": [{"asset_id": "84850580000869621913865680797117970052468736368951185577800573275538604924241", "price": "0.001", "size": "14439.86", "side": "BUY", "hash": "59c8cba7b1c215b5fb4d089746c9709c5c00ae73", "best_bid": "0.008", "best_ask": "0.027"}, {"asset_id": "68251780522342786457624382430403984200536262465760434117810614118555332248086", "price": "0.999", "size": "14439.86", "side": "SELL", "hash": "089a4e882cea16b46914dd3421f517ae38005857", "best_bid": "0.973", "best_ask": "0.992"}], "timestamp": "1769384134844", "event_type": "price_change"}}
{"_local_timestamp": "2026-01-25T23:36:28.919570+00:00", "data": {"market": "0x15dd98954f5a3d5bc21a6fe182d76bbde3e29af1465195df74a6f82c5be6fb2c", "price_changes": [{"asset_id": "50774184608010128165657683699294077924184178889265892143108921917710895798073", "price": "0.007", "size": "191", "side": "BUY", "hash": "90c0d89ecc8a2c6a680b0aebc19104e0c73096e7", "best_bid": "0.013", "best_ask": "0.431"}, {"asset_id": "103448363933352469180704380615499404975348483690550986365085327126347374707599", "price": "0.993", "size": "191", "side": "SELL", "hash": "46141e963824dad52bf825ed70505ae4f7b076a4", "best_bid": "0.569", "best_ask": "0.987"}], "timestamp": "1769384188820", "event_type": "price_change"}}
{"_local_timestamp": "2026-01-25T23:36:55.213374+00:00", "data": {"market": "0x422eecd1eec8d501c70508387d11b1ca7550da75002dcdc448d4d99236df53a9", "price_changes": [{"asset_id": "92095665890628866412192885284169451045487268875038936631172018308093854978979", "price": "0.111", "size": "225", "side": "BUY", "hash": "68c522257d1e60f812c4c2d979ed26dda45a526b", "best_bid": "0.562", "best_ask": "0.989"}, {"asset_id": "37786111380458799656608112817818264473709140890522870941671572177308421431721", "price": "0.889", "size": "225", "side": "SELL", "hash": "e7932357809637b91597c4af8f60e89d5012118a", "best_bid": "0.011", "best_ask": "0.438"}], "timestamp": "1769384215020", "event_type": "price_change"}}
{"_local_timestamp": "2026-01-25T23:36:56.006778+00:00", "data": {"market": "0x422eecd1eec8d501c70508387d11b1ca7550da75002dcdc448d4d99236df53a9", "price_changes": [{"asset_id": "92095665890628866412192885284169451045487268875038936631172018308093854978979", "price": "0.11", "size": "325", "side": "BUY", "hash": "2531ad2e4045317df8420638ec67bf8865cf804c", "best_bid": "0.562", "best_ask": "0.989"}, {"asset_id": "37786111380458799656608112817818264473709140890522870941671572177308421431721", "price": "0.89", "size": "325", "side": "SELL", "hash": "405a97fe61abe617efa94b96ee24c29ff0cf904e", "best_bid": "0.011", "best_ask": "0.438"}], "timestamp": "1769384215641", "event_type": "price_change"}}
{"_local_timestamp": "2026-01-25T23:36:57.426939+00:00", "data": {"market": "0xba8526e4bf87c26c043d7048d364508d066117c173a91f2c56a82128fdc9102c", "price_changes": [{"asset_id": "49259132375860726199054520213393805061519699612170190892474472339512233385785", "price": "0.06", "size": "0", "side": "BUY", "hash": "150b0580c1cd730abda2a5124caf34444732aae0", "best_bid": "0.28", "best_ask": "0.72"}, {"asset_id": "32267317137576261468029282489488620944358875503578558321905938935435579396497", "price": "0.94", "size": "0", "side": "SELL", "hash": "70d3d41aa441e289c72e0d32bf838ab20e215365", "best_bid": "0.28", "best_ask": "0.72"}], "timestamp": "1769384217218", "event_type": "price_change"}}
{"_local_timestamp": "2026-01-25T23:36:57.571104+00:00", "data": {"market": "0x15dd98954f5a3d5bc21a6fe182d76bbde3e29af1465195df74a6f82c5be6fb2c", "price_changes": [{"asset_id": "103448363933352469180704380615499404975348483690550986365085327126347374707599", "price": "0.217", "size": "150", "side": "BUY", "hash": "5acd44b180893ded825794d004c8986d0899aa37", "best_bid": "0.569", "best_ask": "0.987"}, {"asset_id": "50774184608010128165657683699294077924184178889265892143108921917710895798073", "price": "0.783", "size": "150", "side": "SELL", "hash": "3f289a2373f29ea5138455f459bbc957930a694a", "best_bid": "0.013", "best_ask": "0.431"}], "timestamp": "1769384217222", "event_type": "price_change"}}
{"_local_timestamp": "2026-01-25T23:36:58.767932+00:00", "data": {"market": "0x422eecd1eec8d501c70508387d11b1ca7550da75002dcdc448d4d99236df53a9", "price_changes": [{"asset_id": "37786111380458799656608112817818264473709140890522870941671572177308421431721", "price": "0.002", "size": "575.7", "side": "BUY", "hash": "1299826acb6364cc5e720c96ab964fbada3f723f", "best_bid": "0.011", "best_ask": "0.438"}, {"asset_id": "92095665890628866412192885284169451045487268875038936631172018308093854978979", "price": "0.998", "size": "575.7", "side": "SELL", "hash": "f18ae66484f37633243ad9c11e9d1938f44634b1", "best_bid": "0.562", "best_ask": "0.989"}], "timestamp": "1769384218468", "event_type": "price_change"}}
{"_local_timestamp": "2026-01-25T23:36:58.788068+00:00", "data": {"market": "0x15dd98954f5a3d5bc21a6fe182d76bbde3e29af1465195df74a6f82c5be6fb2c", "price_changes": [{"asset_id": "50774184608010128165657683699294077924184178889265892143108921917710895798073", "price": "0.002", "size": "468.38", "side": "BUY", "hash": "7b522a356155f8f44b0c7e809567d9c252bdd559", "best_bid": "0.013", "best_ask": "0.431"}, {"asset_id": "103448363933352469180704380615499404975348483690550986365085327126347374707599", "price": "0.998", "size": "468.38", "side": "SELL", "hash": "b4a546b7bde6565738e9119941a24069e0238706", "best_bid": "0.569", "best_ask": "0.987"}], "timestamp": "1769384218471", "event_type": "price_change"}}
{"_local_timestamp": "2026-01-25T23:36:58.788477+00:00", "data": {"market": "0x422eecd1eec8d501c70508387d11b1ca7550da75002dcdc448d4d99236df53a9", "price_changes": [{"asset_id": "92095665890628866412192885284169451045487268875038936631172018308093854978979", "price": "0.011", "size": "106.91", "side": "BUY", "hash": "183e53b5fc35880be684ba2116857a27088533e6", "best_bid": "0.562", "best_ask": "0.989"}, {"asset_id": "37786111380458799656608112817818264473709140890522870941671572177308421431721", "price": "0.989", "size": "106.91", "side": "SELL", "hash": "cf30c37151d0719132bd8c396b85e037caead204", "best_bid": "0.011", "best_ask": "0.438"}], "timestamp": "1769384218552", "event_type": "price_change"}}
{"_local_timestamp": "2026-01-25T23:36:58.788730+00:00", "data": {"market": "0xa103fd29e21844a2c37dbae0ddd5abc05c9a899652f82b185b1cfd02d18e052e", "price_changes": [{"asset_id": "84850580000869621913865680797117970052468736368951185577800573275538604924241", "price": "0.003", "size": "479.96", "side": "BUY", "hash": "5cab713f4b56162a1d65b6e512a8cc461b6d5811", "best_bid": "0.008", "best_ask": "0.027"}, {"asset_id": "68251780522342786457624382430403984200536262465760434117810614118555332248086", "price": "0.997", "size": "479.96", "side": "SELL", "hash": "8415dbc774154e2d0a710150ccd2484e4797f805", "best_bid": "0.973", "best_ask": "0.992"}], "timestamp": "1769384218476", "event_type": "price_change"}}
{"_local_timestamp": "2026-01-25T23:37:13.167091+00:00", "data": {"market": "0x422eecd1eec8d501c70508387d11b1ca7550da75002dcdc448d4d99236df53a9", "price_changes": [{"asset_id": "92095665890628866412192885284169451045487268875038936631172018308093854978979", "price": "0.11", "size": "200", "side": "BUY", "hash": "5e895c9ff27badf4692081de7703ecd52b54ac89", "best_bid": "0.562", "best_ask": "0.989"}, {"asset_id": "37786111380458799656608112817818264473709140890522870941671572177308421431721", "price": "0.89", "size": "200", "side": "SELL", "hash": "c4c3e363967fbe9d35618a049151b7887d96511f", "best_bid": "0.011", "best_ask": "0.438"}], "timestamp": "1769384233019", "event_type": "price_change"}}
{"_local_timestamp": "2026-01-25T23:37:13.468001+00:00", "data": {"market": "0x422eecd1eec8d501c70508387d11b1ca7550da75002dcdc448d4d99236df53a9", "price_changes": [{"asset_id": "92095665890628866412192885284169451045487268875038936631172018308093854978979", "price": "0.111", "size": "350", "side": "BUY", "hash": "27f884a5b3f8217932e401b061a7b0b3ac473d4a", "best_bid": "0.562", "best_ask": "0.989"}, {"asset_id": "37786111380458799656608112817818264473709140890522870941671572177308421431721", "price": "0.889", "size": "350", "side": "SELL", "hash": "b45d39c5795d9079692d0e5b10de581f91691463", "best_bid": "0.011", "best_ask": "0.438"}], "timestamp": "1769384233361", "event_type": "price_change"}}
{"_local_timestamp": "2026-01-25T23:37:20.854211+00:00", "data": {"market": "0x15dd98954f5a3d5bc21a6fe182d76bbde3e29af1465195df74a6f82c5be6fb2c", "price_changes": [{"asset_id": "103448363933352469180704380615499404975348483690550986365085327126347374707599", "price": "0.218", "size": "158", "side": "BUY", "hash": "ccd18af07349b1ce89fb51d935f0656df0b8d2c2", "best_bid": "0.569", "best_ask": "0.987"}, {"asset_id": "50774184608010128165657683699294077924184178889265892143108921917710895798073", "price": "0.782", "size": "158", "side": "SELL", "hash": "5479a8de6901e85ba7c939d8d349d1739c2ebe00", "best_bid": "0.013", "best_ask": "0.431"}], "timestamp": "1769384240785", "event_type": "price_change"}}
{"_local_timestamp": "2026-01-25T23:37:20.854624+00:00", "data": {"market": "0xba8526e4bf87c26c043d7048d364508d066117c173a91f2c56a82128fdc9102c", "price_changes": [{"asset_id": "49259132375860726199054520213393805061519699612170190892474472339512233385785", "price": "0.09", "size": "208", "side": "BUY", "hash": "48a99a57eb3a6bff3d070d70acbb9bdd04ebd822", "best_bid": "0.28", "best_ask": "0.72"}, {"asset_id": "32267317137576261468029282489488620944358875503578558321905938935435579396497", "price": "0.91", "size": "208", "side": "SELL", "hash": "1014fc062b0aaf85f7659ebd1e09141f00e82e61", "best_bid": "0.28", "best_ask": "0.72"}], "timestamp": "1769384240786", "event_type": "price_change"}}
{"_local_timestamp": "2026-01-25T23:38:03.758280+00:00", "data": {"market": "0x15dd98954f5a3d5bc21a6fe182d76bbde3e29af1465195df74a6f82c5be6fb2c", "price_changes": [{"asset_id": "103448363933352469180704380615499404975348483690550986365085327126347374707599", "price": "0.217", "size": "50", "side": "BUY", "hash": "d378a79f573e72e45044670193b46544996ab9b9", "best_bid": "0.569", "best_ask": "0.987"}, {"asset_id": "50774184608010128165657683699294077924184178889265892143108921917710895798073", "price": "0.783", "size": "50", "side": "SELL", "hash": "b90bebbb2fdcf980740e4eb16e1b762d6e9dec81", "best_bid": "0.013", "best_ask": "0.431"}], "timestamp": "1769384283683", "event_type": "price_change"}}
{"_local_timestamp": "2026-01-25T23:38:03.758973+00:00", "data": {"market": "0x422eecd1eec8d501c70508387d11b1ca7550da75002dcdc448d4d99236df53a9", "price_changes": [{"asset_id": "92095665890628866412192885284169451045487268875038936631172018308093854978979", "price": "0.111", "size": "125", "side": "BUY", "hash": "66495df25f6ea53213fe2c58fb0e72ac6b84defe", "best_bid": "0.562", "best_ask": "0.989"}, {"asset_id": "37786111380458799656608112817818264473709140890522870941671572177308421431721", "price": "0.889", "size": "125", "side": "SELL", "hash": "9f1ed79f879e28d8610575e22ac0816023dd708b", "best_bid": "0.011", "best_ask": "0.438"}], "timestamp": "1769384283683", "event_type": "price_change"}}
{"_local_timestamp": "2026-01-25T23:38:04.029437+00:00", "data": {"market": "0x422eecd1eec8d501c70508387d11b1ca7550da75002dcdc448d4d99236df53a9", "price_changes": [{"asset_id": "92095665890628866412192885284169451045487268875038936631172018308093854978979", "price": "0.11", "size": "425", "side": "BUY", "hash": "407833bb020b0fa1548916748a30a59f1172622c", "best_bid": "0.562", "best_ask": "0.989"}, {"asset_id": "37786111380458799656608112817818264473709140890522870941671572177308421431721", "price": "0.89", "size": "425", "side": "SELL", "hash": "8eccb7d5024682bef5ffcec9415c870dc4b1331b", "best_bid": "0.011", "best_ask": "0.438"}], "timestamp": "1769384283940", "event_type": "price_change"}}
{"_local_timestamp": "2026-01-25T23:38:04.029800+00:00", "data": {"market": "0x15dd98954f5a3d5bc21a6fe182d76bbde3e29af1465195df74a6f82c5be6fb2c", "price_changes": [{"asset_id": "103448363933352469180704380615499404975348483690550986365085327126347374707599", "price": "0.218", "size": "258", "side": "BUY", "hash": "23e5ceb3fbdafaaaba3c88ea13aa1a42d5b6bbc2", "best_bid": "0.569", "best_ask": "0.987"}, {"asset_id": "50774184608010128165657683699294077924184178889265892143108921917710895798073", "price": "0.782", "size": "258", "side": "SELL", "hash": "c7c028fc137a0e3884420effb9bbeb9867a0e508", "best_bid": "0.013", "best_ask": "0.431"}], "timestamp": "1769384283940", "event_type": "price_change"}}
{"_local_timestamp": "2026-01-25T23:38:12.989007+00:00", "data": {"market": "0x422eecd1eec8d501c70508387d11b1ca7550da75002dcdc448d4d99236df53a9", "price_changes": [{"asset_id": "92095665890628866412192885284169451045487268875038936631172018308093854978979", "price": "0.011", "size": "100", "side": "BUY", "hash": "79cbc5e626284ec0138c671287f86c4e7affe0cd", "best_bid": "0.562", "best_ask": "0.989"}, {"asset_id": "37786111380458799656608112817818264473709140890522870941671572177308421431721", "price": "0.989", "size": "100", "side": "SELL", "hash": "65b5b1359eeb9850ce7dfb3c14598fe2fd97b23c", "best_bid": "0.011", "best_ask": "0.438"}], "timestamp": "1769384292921", "event_type": "price_change"}}
{"_local_timestamp": "2026-01-25T23:38:12.989472+00:00", "data": {"market": "0x422eecd1eec8d501c70508387d11b1ca7550da75002dcdc448d4d99236df53a9", "price_changes": [{"asset_id": "92095665890628866412192885284169451045487268875038936631172018308093854978979", "price": "0.024", "size": "0", "side": "BUY", "hash": "79cbc5e626284ec0138c671287f86c4e7affe0cd", "best_bid": "0.562", "best_ask": "0.989"}, {"asset_id": "37786111380458799656608112817818264473709140890522870941671572177308421431721", "price": "0.976", "size": "0", "side": "SELL", "hash": "65b5b1359eeb9850ce7dfb3c14598fe2fd97b23c", "best_bid": "0.011", "best_ask": "0.438"}], "timestamp": "1769384292921", "event_type": "price_change"}}
{"_local_timestamp": "2026-01-25T23:38:13.301912+00:00", "data": {"market": "0x422eecd1eec8d501c70508387d11b1ca7550da75002dcdc448d4d99236df53a9", "price_changes": [{"asset_id": "92095665890628866412192885284169451045487268875038936631172018308093854978979", "price": "0.025", "size": "6.42", "side": "BUY", "hash": "68ebe219abc31f7ef448bd6c246da374109240d6", "best_bid": "0.562", "best_ask": "0.989"}, {"asset_id": "37786111380458799656608112817818264473709140890522870941671572177308421431721", "price": "0.975", "size": "6.42", "side": "SELL", "hash": "c6369ccfb9622065132cca2ad0823a820b80d05b", "best_bid": "0.011", "best_ask": "0.438"}], "timestamp": "1769384293234", "event_type": "price_change"}}
{"_local_timestamp": "2026-01-25T23:38:13.302265+00:00", "data": {"market": "0x422eecd1eec8d501c70508387d11b1ca7550da75002dcdc448d4d99236df53a9", "price_changes": [{"asset_id": "92095665890628866412192885284169451045487268875038936631172018308093854978979", "price": "0.012", "size": "8.19", "side": "BUY", "hash": "3c38d4e1d836fbb86f5394d76b7afb2b66ff6a3d", "best_bid": "0.562", "best_ask": "0.989"}, {"asset_id": "37786111380458799656608112817818264473709140890522870941671572177308421431721", "price": "0.988", "size": "8.19", "side": "SELL", "hash": "7aa6cfbc04f630c4a023731679aba5c7c6d4a95c", "best_bid": "0.011", "best_ask": "0.438"}], "timestamp": "1769384293236", "event_type": "price_change"}}
{"_local_timestamp": "2026-01-25T23:38:15.237641+00:00", "data": {"market": "0xba8526e4bf87c26c043d7048d364508d066117c173a91f2c56a82128fdc9102c", "price_changes": [{"asset_id": "49259132375860726199054520213393805061519699612170190892474472339512233385785", "price": "0.05", "size": "710", "side": "BUY", "hash": "a6ec906d992c615b4e413dd3d211561e32187cb0", "best_bid": "0.28", "best_ask": "0.72"}, {"asset_id": "32267317137576261468029282489488620944358875503578558321905938935435579396497", "price": "0.95", "size": "710", "side": "SELL", "hash": "76be20c43b28edb0c1dcb78ca7dca0eba43efeb2", "best_bid": "0.28", "best_ask": "0.72"}], "timestamp": "1769384295166", "event_type": "price_change"}}
{"_local_timestamp": "2026-01-25T23:38:15.238051+00:00", "data": {"market": "0xba8526e4bf87c26c043d7048d364508d066117c173a91f2c56a82128fdc9102c", "price_changes": [{"asset_id": "49259132375860726199054520213393805061519699612170190892474472339512233385785", "price": "0.08", "size": "400", "side": "BUY", "hash": "a6ec906d992c615b4e413dd3d211561e32187cb0", "best_bid": "0.28", "best_ask": "0.72"}, {"asset_id": "32267317137576261468029282489488620944358875503578558321905938935435579396497", "price": "0.92", "size": "400", "side": "SELL", "hash": "76be20c43b28edb0c1dcb78ca7dca0eba43efeb2", "best_bid": "0.28", "best_ask": "0.72"}], "timestamp": "1769384295166", "event_type": "price_change"}}
{"_local_timestamp": "2026-01-25T23:38:15.652651+00:00", "data": {"market": "0xba8526e4bf87c26c043d7048d364508d066117c173a91f2c56a82128fdc9102c", "price_changes": [{"asset_id": "49259132375860726199054520213393805061519699612170190892474472339512233385785", "price": "0.06", "size": "5.69", "side": "BUY", "hash": "2c362e4b682c3d199eb9c8c7a8da701df5325080", "best_bid": "0.28", "best_ask": "0.72"}, {"asset_id": "32267317137576261468029282489488620944358875503578558321905938935435579396497", "price": "0.94", "size": "5.69", "side": "SELL", "hash": "92b33eb1a5ece711b88f5dee0fbb475cbde380ce", "best_bid": "0.28", "best_ask": "0.72"}], "timestamp": "1769384295578", "event_type": "price_change"}}
{"_local_timestamp": "2026-01-25T23:38:15.652992+00:00", "data": {"market": "0xba8526e4bf87c26c043d7048d364508d066117c173a91f2c56a82128fdc9102c", "price_changes": [{"asset_id": "49259132375860726199054520213393805061519699612170190892474472339512233385785", "price": "0.1", "size": "12.93", "side": "BUY", "hash": "08b15eb4c708671c538e4b5276779179628d2365", "best_bid": "0.28", "best_ask": "0.72"}, {"asset_id": "32267317137576261468029282489488620944358875503578558321905938935435579396497", "price": "0.9", "size": "12.93", "side": "SELL", "hash": "6d83d419254575a62f55e6fb533f36b411c77ee3", "best_bid": "0.28", "best_ask": "0.72"}], "timestamp": "1769384295580", "event_type": "price_change"}}
{"_local_timestamp": "2026-01-25T23:38:32.630421+00:00", "data": {"market": "0xba8526e4bf87c26c043d7048d364508d066117c173a91f2c56a82128fdc9102c", "price_changes": [{"asset_id": "49259132375860726199054520213393805061519699612170190892474472339512233385785", "price": "0.08", "size": "100", "side": "BUY", "hash": "774bf274f9c3d1d3be4b432aeae66bbfe8aa627b", "best_bid": "0.28", "best_ask": "0.72"}, {"asset_id": "32267317137576261468029282489488620944358875503578558321905938935435579396497", "price": "0.92", "size": "100", "side": "SELL", "hash": "7530427dcda060d8b9f3b91b53dceca3e08a9bf2", "best_bid": "0.28", "best_ask": "0.72"}], "timestamp": "1769384312542", "event_type": "price_change"}}
{"_local_timestamp": "2026-01-25T23:38:32.913695+00:00", "data": {"market": "0xba8526e4bf87c26c043d7048d364508d066117c173a91f2c56a82128fdc9102c", "price_changes": [{"asset_id": "49259132375860726199054520213393805061519699612170190892474472339512233385785", "price": "0.09", "size": "508", "side": "BUY", "hash": "ff9319388f0dd43176fa96181fa8ebdecf0dc045", "best_bid": "0.28", "best_ask": "0.72"}, {"asset_id": "32267317137576261468029282489488620944358875503578558321905938935435579396497", "price": "0.91", "size": "508", "side": "SELL", "hash": "847c8a3be5cf5964f9deeb5f2a97d835582061da", "best_bid": "0.28", "best_ask": "0.72"}], "timestamp": "1769384312837", "event_type": "price_change"}}
{"_local_timestamp": "2026-01-25T23:39:04.654479+00:00", "data": {"market": "0xba8526e4bf87c26c043d7048d364508d066117c173a91f2c56a82128fdc9102c", "price_changes": [{"asset_id": "49259132375860726199054520213393805061519699612170190892474472339512233385785", "price": "0.04", "size": "150", "side": "BUY", "hash": "e3af7cabc2546d799beb82d7e0ede7d771073928", "best_bid": "0.28", "best_ask": "0.72"}, {"asset_id": "32267317137576261468029282489488620944358875503578558321905938935435579396497", "price": "0.96", "size": "150", "side": "SELL", "hash": "6fb74d6868c84d745c9922fe791ffa25d6d0ceb1", "best_bid": "0.28", "best_ask": "0.72"}], "timestamp": "1769384344318", "event_type": "price_change"}}
{"_local_timestamp": "2026-01-25T23:39:04.749311+00:00", "data": {"market": "0xba8526e4bf87c26c043d7048d364508d066117c173a91f2c56a82128fdc9102c", "price_changes": [{"asset_id": "49259132375860726199054520213393805061519699612170190892474472339512233385785", "price": "0.08", "size": "200", "side": "BUY", "hash": "1cdd848536ec0f29ecedc3111dcab0d265585fc7", "best_bid": "0.28", "best_ask": "0.72"}, {"asset_id": "32267317137576261468029282489488620944358875503578558321905938935435579396497", "price": "0.92", "size": "200", "side": "SELL", "hash": "979c28954d93aed4f9b5d92d82d13f107b79636d", "best_bid": "0.28", "best_ask": "0.72"}], "timestamp": "1769384344625", "event_type": "price_change"}}
{"_local_timestamp": "2026-01-25T23:39:22.447766+00:00", "data": {"market": "0x422eecd1eec8d501c70508387d11b1ca7550da75002dcdc448d4d99236df53a9", "price_changes": [{"asset_id": "92095665890628866412192885284169451045487268875038936631172018308093854978979", "price": "0.11", "size": "225", "side": "BUY", "hash": "4a440c0f382de24139f0239b695c9a02cfb37f39", "best_bid": "0.562", "best_ask": "0.989"}, {"asset_id": "37786111380458799656608112817818264473709140890522870941671572177308421431721", "price": "0.89", "size": "225", "side": "SELL", "hash": "93aedb3579383a6205e1a9c21c89276243b0564a", "best_bid": "0.011", "best_ask": "0.438"}], "timestamp": "1769384362207", "event_type": "price_change"}}
{"_local_timestamp": "2026-01-25T23:39:22.839577+00:00", "data": {"market": "0x422eecd1eec8d501c70508387d11b1ca7550da75002dcdc448d4d99236df53a9", "price_changes": [{"asset_id": "92095665890628866412192885284169451045487268875038936631172018308093854978979", "price": "0.111", "size": "325", "side": "BUY", "hash": "0cd17d2396893db680a160861f0e942f168be290", "best_bid": "0.562", "best_ask": "0.989"}, {"asset_id": "37786111380458799656608112817818264473709140890522870941671572177308421431721", "price": "0.889", "size": "325", "side": "SELL", "hash": "6092bc74fa4bb498263af9225a6fe2d91069c3d6", "best_bid": "0.011", "best_ask": "0.438"}], "timestamp": "1769384362755", "event_type": "price_change"}}
{"_local_timestamp": "2026-01-25T23:39:22.922390+00:00", "data": {"market": "0xba8526e4bf87c26c043d7048d364508d066117c173a91f2c56a82128fdc9102c", "price_changes": [{"asset_id": "49259132375860726199054520213393805061519699612170190892474472339512233385785", "price": "0.01", "size": "3876.11", "side": "BUY", "hash": "18cdcbced659b81f624b7e0951d0bd394e705704", "best_bid": "0.28", "best_ask": "0.72"}, {"asset_id": "32267317137576261468029282489488620944358875503578558321905938935435579396497", "price": "0.99", "size": "3876.11", "side": "SELL", "hash": "804e1a0fa3c19e23106947c20395db0a29389ac7", "best_bid": "0.28", "best_ask": "0.72"}], "timestamp": "1769384362722", "event_type": "price_change"}}
{"_local_timestamp": "2026-01-25T23:39:56.431123+00:00", "data": {"market": "0x422eecd1eec8d501c70508387d11b1ca7550da75002dcdc448d4d99236df53a9", "price_changes": [{"asset_id": "92095665890628866412192885284169451045487268875038936631172018308093854978979", "price": "0.11", "size": "0", "side": "BUY", "hash": "37288c2fb5b9ae5f8d94af5a84794d16a68d543f", "best_bid": "0.562", "best_ask": "0.989"}, {"asset_id": "37786111380458799656608112817818264473709140890522870941671572177308421431721", "price": "0.89", "size": "0", "side": "SELL", "hash": "36e3151c92c48eb1354f01b6eed56f29678f5607", "best_bid": "0.011", "best_ask": "0.438"}], "timestamp": "1769384396332", "event_type": "price_change"}}
{"_local_timestamp": "2026-01-25T23:39:56.711234+00:00", "data": {"market": "0x422eecd1eec8d501c70508387d11b1ca7550da75002dcdc448d4d99236df53a9", "price_changes": [{"asset_id": "92095665890628866412192885284169451045487268875038936631172018308093854978979", "price": "0.111", "size": "550", "side": "BUY", "hash": "a8f3b99e8198c395da5705e9ca054750f7350503", "best_bid": "0.562", "best_ask": "0.989"}, {"asset_id": "37786111380458799656608112817818264473709140890522870941671572177308421431721", "price": "0.889", "size": "550", "side": "SELL", "hash": "0662857a2b0c11a376180114079d8ca4746f84c2", "best_bid": "0.011", "best_ask": "0.438"}], "timestamp": "1769384396610", "event_type": "price_change"}}
