{"_local_timestamp": "2026-01-25T23:33:51.406161+00:00", "data": [{"market": "0xd423a5d9202016fba92b69fcc65e64b652f7bd0a3ff90a467a3b9981c1ba40bf", "asset_id": "66326498088647961820902244163239082840805695724900141547875364666440398917609", "timestamp": "1769384018876", "hash": "038c60606c596727bddc9524e3a951e9d9dc1074", "bids": [{"price": "0.01", "size": "176.66"}, {"price": "0.02", "size": "9.28"}, {"price": "0.04", "size": "116.66"}, {"price": "0.08", "size": "12.5"}, {"price": "0.09", "size": "72.21"}], "asks": [{"price": "0.99", "size": "143.83"}, {"price": "0.98", "size": "26.36"}, {"price": "0.96", "size": "100"}, {"price": "0.95", "size": "130"}, {"price": "0.94", "size": "33"}, {"price": "0.93", "size": "6.64"}, {"price": "0.89", "size": "33.33"}, {"price": "0.88", "size": "7.51"}, {"price": "0.86", "size": "140"}, {"price": "0.85", "size": "13"}, {"price": "0.73", "size": "33.33"}, {"price": "0.72", "size": "25"}], "event_type": "book", "last_trade_price": ""}, {"market": "0x238e76ab8673302f69465f6276dc30397f2da6d45e256d1addb3727c52d426cf", "asset_id": "97242587671502984422385091919023155761644234345765358718238822411412771007696", "timestamp": "1769383874438", "hash": "5454e022e0302aa7c34a73bd411158bfb07ef9e4", "bids": [{"price": "0.01", "size": "6011.83"}, {"price": "0.02", "size": "2200"}, {"price": "0.03", "size": "7.3"}, {"price": "0.05", "size": "40"}, {"price": "0.06", "size": "733"}, {"price": "0.07", "size": "6.56"}, {"price": "0.11", "size": "550"}, {"price": "0.16", "size": "150"}, {"price": "0.17", "size": "7.07"}, {"price": "0.21", "size": "100"}, {"price": "0.26", "size": "50"}, {"price": "0.29", "size": "25"}, {"price": "0.36", "size": "100"}, {"price": "0.37", "size": "25"}, {"price": "0.71", "size": "95.7"}], "asks": [{"price": "0.99", "size": "153.7"}, {"price": "0.97", "size": "53.7"}, {"price": "0.96", "size": "93"}, {"price": "0.95", "size": "30"}, {"price": "0.94", "size": "53.7"}], "event_type": "book", "last_trade_price": ""}, {"market": "0xd423a5d9202016fba92b69fcc65e64b652f7bd0a3ff90a467a3b9981c1ba40bf", "asset_id": "94350465852216138354255274614877157805309416974679362811091088550032908691370", "timestamp": "1769384018876", "hash": "ad2329f46a8a983105250ef8a94335c5c76cb36d", "bids": [{"price": "0.01", "size": "143.83"}, {"price": "0.02", "size": "26.36"}, {"price": "0.04", "size": "100"}, {"price": "0.05", "size": "130"}, {"price": "0.06", "size": "33"}, {"price": "0.07", "size": "6.64"}, {"price": "0.11", "size": "33.33"}, {"price": "0.12", "size": "7.51"}, {"price": "0.14", "size": "140"}, {"price": "0.15", "size": "13"}, {"price": "0.27", "size": "33.33"}, {"price": "0.28", "size": "25"}], "asks": [{"price": "0.99", "size": "176.66"}, {"price": "0.98", "size": "9.28"}, {"price": "0.96", "size": "116.66"}, {"price": "0.92", "size": "12.5"}, {"price": "0.91", "size": "72.21"}], "event_type": "book", "last_trade_price": ""}, {"market": "0xcd24bf9e4312eff0c8e93716adf5f1507c802eb49940dc548686d3dd01f7dc80", "asset_id": "26250882338411993353025798873396196450213722200450121972167061161438889023462", "timestamp": "1769383901915", "hash": "65dacf3e7d216b74cdaae9e528e01a3e9e066c01", "bids": [{"price": "0.01", "size": "140.33"}, {"price": "0.02", "size": "70"}, {"price": "0.03", "size": "40.33"}, {"price": "0.06", "size": "56.99"}], "asks": [{"price": "0.99", "size": "4705.86"}, {"price": "0.98", "size": "1805.81"}, {"price": "0.97", "size": "300"}, {"price": "0.96", "size": "205.38"}, {"price": "0.95", "size": "30"}, {"price": "0.94", "size": "33"}, {"price": "0.93", "size": "100"}, {"price": "0.92", "size": "5.14"}, {"price": "0.89", "size": "225"}, {"price": "0.84", "size": "200"}, {"price": "0.83", "size": "7.05"}, {"price": "0.78", "size": "50"}, {"price": "0.64", "size": "100"}, {"price": "0.63", "size": "20"}, {"price": "0.62", "size": "5"}, {"price": "0.32", "size": "16"}, {"price": "0.31", "size": "9"}, {"price": "0.3", "size": "33"}], "event_type": "book", "last_trade_price": ""}, {"market": "0xda6d412db6123d081fc90f020d6a7cb9b19bf4a48888fd1884071d62e7543611", "asset_id": "112184512106281098337746048918245759041804395263732191740766735719601623879523", "timestamp": "1769383901915", "hash": "79bcc82b98ebe6527844460ada20baff63a53ae3", "bids": [{"price": "0.01", "size": "4705.22"}, {"price": "0.02", "size": "1805.65"}, {"price": "0.03", "size": "300"}, {"price": "0.04", "size": "205.24"}, {"price": "0.05", "size": "30"}, {"price": "0.06", "size": "33"}, {"price": "0.07", "size": "100"}, {"price": "0.08", "size": "6.43"}, {"price": "0.11", "size": "225"}, {"price": "0.16", "size": "200"}, {"price": "0.19", "size": "10"}, {"price": "0.2", "size": "5.55"}, {"price": "0.36", "size": "100"}, {"price": "0.37", "size": "20"}, {"price": "0.38", "size": "5"}, {"price": "0.68", "size": "16"}, {"price": "0.69", "size": "9"}, {"price": "0.7", "size": "33"}], "asks": [{"price": "0.99", "size": "140.33"}, {"price": "0.98", "size": "70"}, {"price": "0.97", "size": "40.33"}, {"price": "0.94", "size": "55.06"}], "event_type": "book", "last_trade_price": ""}, {"market": "0xda6d412db6123d081fc90f020d6a7cb9b19bf4a48888fd1884071d62e7543611", "asset_id": "80000332397245837596854182599697796366828301139631925465959846280975689186136", "timestamp": "1769383901915", "hash": "cf2584f4000ec99d866985dd9a93fb1bec0ce753", "bids": [{"price": "0.01", "size": "140.33"}, {"price": "0.02", "size": "70"}, {"price": "0.03", "size": "40.33"}, {"price": "0.06", "size": "55.06"}], "asks": [{"price": "0.99", "size": "4705.22"}, {"price": "0.98", "size": "1805.65"}, {"price": "0.97", "size": "300"}, {"price": "0.96", "size": "205.24"}, {"price": "0.95", "size": "30"}, {"price": "0.94", "size": "33"}, {"price": "0.93", "size": "100"}, {"price": "0.92", "size": "6.43"}, {"price": "0.89", "size": "225"}, {"price": "0.84", "size": "200"}, {"price": "0.81", "size": "10"}, {"price": "0.8", "size": "5.55"}, {"price": "0.64", "size": "100"}, {"price": "0.63", "size": "20"}, {"price": "0.62", "size": "5"}, {"price": "0.32", "size": "16"}, {"price": "0.31", "size": "9"}, {"price": "0.3", "size": "33"}], "event_type": "book", "last_trade_price": ""}, {"market": "0x60704bdb0d83d6f14581a1ebfe2a0f1f3c110b5b4d5e6644b4f526a0ef7d3001", "asset_id": "93030990064375513510189225885274415076490550330310701425495660148274214307425", "timestamp": "1769383874437", "hash": "6ba7f223d568e7e4c542d751a10bff97f9f9e727", "bids": [{"price": "0.01", "size": "6011.77"}, {"price": "0.02", "size": "2200"}, {"price": "0.03", "size": "7.27"}, {"price": "0.05", "size": "30"}, {"price": "0.06", "size": "733"}, {"price": "0.07", "size": "6.53"}, {"price": "0.12", "size": "550"}, {"price": "0.16", "size": "150"}, {"price": "0.17", "size": "7.09"}, {"price": "0.21", "size": "100"}, {"price": "0.29", "size": "100"}, {"price": "0.3", "size": "20"}, {"price": "0.37", "size": "100"}, {"price": "0.38", "size": "5"}, {"price": "0.72", "size": "58"}], "asks": [{"price": "0.99", "size": "140.33"}, {"price": "0.98", "size": "70"}, {"price": "0.97", "size": "40.33"}, {"price": "0.94", "size": "55.06"}], "event_type": "book", "last_trade_price": ""}, {"market": "0x897bf69800a1bdda4aedfb6514f3f5a50e3dd128e1e6f9d626978a1e6318e73b", "asset_id": "62293292317905300650991725392919669384770245915371865525007679676421368767515", "timestamp": "1769383901913", "hash": "2b2a2d8a6bafa8c6164a2b4b70adad93daac317d", "bids": [{"price": "0.01", "size": "140.33"}, {"price": "0.02", "size": "86"}, {"price": "0.03", "size": "40.33"}, {"price": "0.06", "size": "55.06"}], "asks": [{"price": "0.99", "size": "4705.87"}, {"price": "0.98", "size": "1806.12"}, {"price": "0.97", "size": "300"}, {"price": "0.96", "size": "205.67"}, {"price": "0.95", "size": "30"}, {"price": "0.94", "size": "33"}, {"price": "0.93", "size": "100"}, {"price": "0.92", "size": "5.42"}, {"price": "0.89", "size": "225"}, {"price": "0.84", "size": "200"}, {"price": "0.83", "size": "6.81"}, {"price": "0.8", "size": "12"}, {"price": "0.64", "size": "100"}, {"price": "0.63", "size": "20"}, {"price": "0.62", "size": "5"}, {"price": "0.32", "size": "16"}, {"price": "0.31", "size": "9"}, {"price": "0.3", "size": "33"}], "event_type": "book", "last_trade_price": ""}, {"market": "0xcd24bf9e4312eff0c8e93716adf5f1507c802eb49940dc548686d3dd01f7dc80", "asset_id": "5838306871037945340010006268256931296949052336165005624521859666744160071457", "timestamp": "1769383901915", "hash": "8beb58af8b7125d4767e556769effb2b4ea50b84", "bids": [{"price": "0.01", "size": "4705.86"}, {"price": "0.02", "size": "1805.81"}, {"price": "0.03", "size": "300"}, {"price": "0.04", "size": "205.38"}, {"price": "0.05", "size": "30"}, {"price": "0.06", "size": "33"}, {"price": "0.07", "size": "100"}, {"price": "0.08", "size": "5.14"}, {"price": "0.11", "size": "225"}, {"price": "0.16", "size": "200"}, {"price": "0.17", "size": "7.05"}, {"price": "0.22", "size": "50"}, {"price": "0.36", "size": "100"}, {"price": "0.37", "size": "20"}, {"price": "0.38", "size": "5"}, {"price": "0.68", "size": "16"}, {"price": "0.69", "size": "9"}, {"price": "0.7", "size": "33"}], "asks": [{"price": "0.99", "size": "140.33"}, {"price": "0.98", "size": "70"}, {"price": "0.97", "size": "40.33"}, {"price": "0.94", "size": "56.99"}], "event_type": "book", "last_trade_price": ""}, {"market": "0x897bf69800a1bdda4aedfb6514f3f5a50e3dd128e1e6f9d626978a1e6318e73b", "asset_id": "107315720365659808114604028527822042298641109513906619819239162323543505300877", "timestamp": "1769383901913", "hash": "d75429786ad529fa9b8af721f68439329bdae99c", "bids": [{"price": "0.01", "size": "4705.87"}, {"price": "0.02", "size": "1806.12"}, {"price": "0.03", "size": "300"}, {"price": "0.04", "size": "205.67"}, {"price": "0.05", "size": "30"}, {"price": "0.06", "size": "33"}, {"price": "0.07", "size": "100"}, {"price": "0.08", "size": "5.42"}, {"price": "0.11", "size": "225"}, {"price": "0.16", "size": "200"}, {"price": "0.17", "size": "6.81"}, {"price": "0.2", "size": "12"}, {"price": "0.36", "size": "100"}, {"price": "0.37", "size": "20"}, {"price": "0.38", "size": "5"}, {"price": "0.68", "size": "16"}, {"price": "0.69", "size": "9"}, {"price": "0.7", "size": "33"}], "asks": [{"price": "0.99", "size": "140.33"}, {"price": "0.98", "size": "86"}, {"price": "0.97", "size": "40.33"}, {"price": "0.94", "size": "55.06"}], "event_type": "book", "last_trade_price": ""}, {"market": "0x238e76ab8673302f69465f6276dc30397f2da6d45e256d1addb3727c52d426cf", "asset_id": "45416836285011613952203179410772546980719957661013072684949967687661326740901", "timestamp": "1769383874438", "hash": "15df93dcd91098e1e2a2aa2ebc4281aad5b637a9", "bids": [{"price": "0.01", "size": "153.7"}, {"price": "0.03", "size": "53.7"}, {"price": "0.04", "size": "93"}, {"price": "0.05", "size": "30"}, {"price": "0.06", "size": "53.7"}], "asks": [{"price": "0.99", "size": "6011.83"}, {"price": "0.98", "size": "2200"}, {"price": "0.97", "size": "7.3"}, {"price": "0.95", "size": "40"}, {"price": "0.94", "size": "733"}, {"price": "0.93", "size": "6.56"}, {"price": "0.89", "size": "550"}, {"price": "0.84", "size": "150"}, {"price": "0.83", "size": "7.07"}, {"price": "0.79", "size": "100"}, {"price": "0.74", "size": "50"}, {"price": "0.71", "size": "25"}, {"price": "0.64", "size": "100"}, {"price": "0.63", "size": "25"}, {"price": "0.29", "size": "95.7"}], "event_type": "book", "last_trade_price": ""}, {"market": "0xfb0453c8a45a74240fb53aa98969613fdeb93e4d3235849079d3517266a5d5c6", "asset_id": "80661299423809747898502345161492672838497575056642213047279133666465067326877", "timestamp": "1769383901914", "hash": "1760a81984e059c3aebf08f50aadf680f4ecaf3b", "bids": [{"price": "0.01", "size": "145.91"}, {"price": "0.02", "size": "101.49"}, {"price": "0.04", "size": "40.33"}, {"price": "0.09", "size": "51.44"}], "asks": [{"price": "0.99", "size": "4712.07"}, {"price": "0.98", "size": "1800"}, {"price": "0.97", "size": "305.66"}, {"price": "0.96", "size": "200"}, {"price": "0.95", "size": "130"}, {"price": "0.94", "size": "33"}, {"price": "0.93", "size": "6.3"}, {"price": "0.89", "size": "275"}, {"price": "0.87", "size": "5"}, {"price": "0.82", "size": "7.04"}, {"price": "0.81", "size": "20"}, {"price": "0.66", "size": "100"}, {"price": "0.65", "size": "5"}, {"price": "0.35", "size": "16"}, {"price": "0.34", "size": "9"}, {"price": "0.33", "size": "33"}], "event_type": "book", "last_trade_price": ""}, {"market": "0x60704bdb0d83d6f14581a1ebfe2a0f1f3c110b5b4d5e6644b4f526a0ef7d3001", "asset_id": "52795436891171139146570659596446975016064524845299806211429059129878692728045", "timestamp": "1769383874437", "hash": "6c3a54d8972e64ca0b80f49c2f7365e23b2e76cd", "bids": [{"price": "0.01", "size": "140.33"}, {"price": "0.02", "size": "70"}, {"price": "0.03", "size": "40.33"}, {"price": "0.06", "size": "55.06"}], "asks": [{"price": "0.99", "size": "6011.77"}, {"price": "0.98", "size": "2200"}, {"price": "0.97", "size": "7.27"}, {"price": "0.95", "size": "30"}, {"price": "0.94", "size": "733"}, {"price": "0.93", "size": "6.53"}, {"price": "0.88", "size": "550"}, {"price": "0.84", "size": "150"}, {"price": "0.83", "size": "7.09"}, {"price": "0.79", "size": "100"}, {"price": "0.71", "size": "100"}, {"price": "0.7", "size": "20"}, {"price": "0.63", "size": "100"}, {"price": "0.62", "size": "5"}, {"price": "0.28", "size": "58"}], "event_type": "book", "last_trade_price": ""}, {"market": "0xfb0453c8a45a74240fb53aa98969613fdeb93e4d3235849079d3517266a5d5c6", "asset_id": "16163104876449149619311464240366771564134586034188584457341092863175915998347", "timestamp": "1769383901914", "hash": "f4bd8487803a1116a75914deb23f77831ec31b26", "bids": [{"price": "0.01", "size": "4712.07"}, {"price": "0.02", "size": "1800"}, {"price": "0.03", "size": "305.66"}, {"price": "0.04", "size": "200"}, {"price": "0.05", "size": "130"}, {"price": "0.06", "size": "33"}, {"price": "0.07", "size": "6.3"}, {"price": "0.11", "size": "275"}, {"price": "0.13", "size": "5"}, {"price": "0.18", "size": "7.04"}, {"price": "0.19", "size": "20"}, {"price": "0.34", "size": "100"}, {"price": "0.35", "size": "5"}, {"price": "0.65", "size": "16"}, {"price": "0.66", "size": "9"}, {"price": "0.67", "size": "33"}], "asks": [{"price": "0.99", "size": "145.91"}, {"price": "0.98", "size": "101.49"}, {"price": "0.96", "size": "40.33"}, {"price": "0.91", "size": "51.44"}], "event_type": "book", "last_trade_price": ""}]}
{"_local_timestamp": "2026-01-25T23:33:53.498317+00:00", "data": {"market": "0xd423a5d9202016fba92b69fcc65e64b652f7bd0a3ff90a467a3b9981c1ba40bf", "price_changes": [{"asset_id": "94350465852216138354255274614877157805309416974679362811091088550032908691370", "price": "0.29", "size": "67", "side": "BUY", "hash": "24a697b12b62b64a7ca3a8ba6608869a1641c763", "best_bid": "0.29", "best_ask": "0.91"}, {"asset_id": "66326498088647961820902244163239082840805695724900141547875364666440398917609", "price": "0.71", "size": "67", "side": "SELL", "hash": "2a639a632ac0d306acdd15184c73356ec72d9d8b", "best_bid": "0.09", "best_ask": "0.71"}], "timestamp": "1769384033422", "event_type": "price_change"}}
{"_local_timestamp": "2026-01-25T23:33:53.498832+00:00", "data": {"market": "0xd423a5d9202016fba92b69fcc65e64b652f7bd0a3ff90a467a3b9981c1ba40bf", "price_changes": [{"asset_id": "94350465852216138354255274614877157805309416974679362811091088550032908691370", "price": "0.28", "size": "92", "side": "BUY", "hash": "094471c87c4503ee6bff266f3a9701c0495f2112", "best_bid": "0.29", "best_ask": "0.91"}, {"asset_id": "66326498088647961820902244163239082840805695724900141547875364666440398917609", "price": "0.72", "size": "92", "side": "SELL", "hash": "548e839441cfd4e7519ca2474f7c704290087866", "best_bid": "0.09", "best_ask": "0.71"}], "timestamp": "1769384033423", "event_type": "price_change"}}
{"_local_timestamp": "2026-01-25T23:33:54.007815+00:00", "data": {"market": "0xd423a5d9202016fba92b69fcc65e64b652f7bd0a3ff90a467a3b9981c1ba40bf", "price_changes": [{"asset_id": "94350465852216138354255274614877157805309416974679362811091088550032908691370", "price": "0.28", "size": "87", "side": "BUY", "hash": "380398221b9e0794177d10031fd5c075437d0153", "best_bid": "0.29", "best_ask": "0.91"}, {"asset_id": "66326498088647961820902244163239082840805695724900141547875364666440398917609", "price": "0.72", "size": "87", "side": "SELL", "hash": "36541b03ef0a3b4cb87aef14370650f1faa6c6ec", "best_bid": "0.09", "best_ask": "0.71"}], "timestamp": "1769384033936", "event_type": "price_change"}}
{"_local_timestamp": "2026-01-25T23:33:56.610486+00:00", "data": {"market": "0xd423a5d9202016fba92b69fcc65e64b652f7bd0a3ff90a467a3b9981c1ba40bf", "price_changes": [{"asset_id": "94350465852216138354255274614877157805309416974679362811091088550032908691370", "price": "0.29", "size": "72", "side": "BUY", "hash": "a1e5d44ff8f4256313a6080056d1755d4e7ba57f", "best_bid": "0.29", "best_ask": "0.91"}, {"asset_id": "66326498088647961820902244163239082840805695724900141547875364666440398917609", "price": "0.71", "size": "72", "side": "SELL", "hash": "3e40ad9b854989f28dd61412d94c035a0db444b7", "best_bid": "0.09", "best_ask": "0.71"}], "timestamp": "1769384036546", "event_type": "price_change"}}
{"_local_timestamp": "2026-01-25T23:33:57.599944+00:00", "data": {"market": "0xd423a5d9202016fba92b69fcc65e64b652f7bd0a3ff90a467a3b9981c1ba40bf", "price_changes": [{"asset_id": "94350465852216138354255274614877157805309416974679362811091088550032908691370", "price": "0.28", "size": "67", "side": "BUY", "hash": "c72a9dce4f68c36086cb8a281b2a3cd8b9b38177", "best_bid": "0.29", "best_ask": "0.91"}, {"asset_id": "66326498088647961820902244163239082840805695724900141547875364666440398917609", "price": "0.72", "size": "67", "side": "SELL", "hash": "c5acf9b133948bc68b4f832ac2610c249cfb60a6", "best_bid": "0.09", "best_ask": "0.71"}], "timestamp": "1769384037526", "event_type": "price_change"}}
{"_local_timestamp": "2026-01-25T23:33:57.621627+00:00", "data": {"market": "0xd423a5d9202016fba92b69fcc65e64b652f7bd0a3ff90a467a3b9981c1ba40bf", "price_changes": [{"asset_id": "94350465852216138354255274614877157805309416974679362811091088550032908691370", "price": "0.3", "size": "20", "side": "BUY", "hash": "116a40df75761e5dac1e358b27abbe2f10f28333", "best_bid": "0.3", "best_ask": "0.91"}, {"asset_id": "66326498088647961820902244163239082840805695724900141547875364666440398917609", "price": "0.7", "size": "20", "side": "SELL", "hash": "b0f4055c6dc0df48fceb3969b4795803528408e0", "best_bid": "0.09", "best_ask": "0.7"}], "timestamp": "1769384037554", "event_type": "price_change"}}
{"_local_timestamp": "2026-01-25T23:33:59.405166+00:00", "data": {"market": "0xd423a5d9202016fba92b69fcc65e64b652f7bd0a3ff90a467a3b9981c1ba40bf", "price_changes": [{"asset_id": "94350465852216138354255274614877157805309416974679362811091088550032908691370", "price": "0.29", "size": "67", "side": "BUY", "hash": "21e47433dee7176405f5bf6b1fe29f4fda029a72", "best_bid": "0.3", "best_ask": "0.91"}, {"asset_id": "66326498088647961820902244163239082840805695724900141547875364666440398917609", "price": "0.71", "size": "67", "side": "SELL", "hash": "017307fbdab44557035defa96a5c3e53943c921a", "best_bid": "0.09", "best_ask": "0.7"}], "timestamp": "1769384039328", "event_type": "price_change"}}
{"_local_timestamp": "2026-01-25T23:34:02.233481+00:00", "data": {"market": "0xd423a5d9202016fba92b69fcc65e64b652f7bd0a3ff90a467a3b9981c1ba40bf", "price_changes": [{"asset_id": "94350465852216138354255274614877157805309416974679362811091088550032908691370", "price": "0.3", "size": "25", "side": "BUY", "hash": "338fe83dbc85a374318e8f815109bda7adb684f7", "best_bid": "0.3", "best_ask": "0.91"}, {"asset_id": "66326498088647961820902244163239082840805695724900141547875364666440398917609", "price": "0.7", "size": "25", "side": "SELL", "hash": "fb113ca024d8fc76d16bc77345fe8b528bfed91f", "best_bid": "0.09", "best_ask": "0.7"}], "timestamp": "1769384042164", "event_type": "price_change"}}
{"_local_timestamp": "2026-01-25T23:34:03.691910+00:00", "data": {"market": "0xd423a5d9202016fba92b69fcc65e64b652f7bd0a3ff90a467a3b9981c1ba40bf", "price_changes": [{"asset_id": "94350465852216138354255274614877157805309416974679362811091088550032908691370", "price": "0.02", "size": "14.8", "side": "BUY", "hash": "0ab487b84434566f08713e672ffb0dcc017a0a01", "best_bid": "0.3", "best_ask": "0.91"}, {"asset_id": "66326498088647961820902244163239082840805695724900141547875364666440398917609", "price": "0.98", "size": "14.8", "side": "SELL", "hash": "cec0fc9ed75c77f16411a370fa450de2be1f3cf3", "best_bid": "0.09", "best_ask": "0.7"}], "timestamp": "1769384043617", "event_type": "price_change"}}
{"_local_timestamp": "2026-01-25T23:34:03.692559+00:00", "data": {"market": "0xd423a5d9202016fba92b69fcc65e64b652f7bd0a3ff90a467a3b9981c1ba40bf", "price_changes": [{"asset_id": "94350465852216138354255274614877157805309416974679362811091088550032908691370", "price": "0.12", "size": "0", "side": "BUY", "hash": "0ab487b84434566f08713e672ffb0dcc017a0a01", "best_bid": "0.3", "best_ask": "0.91"}, {"asset_id": "66326498088647961820902244163239082840805695724900141547875364666440398917609", "price": "0.88", "size": "0", "side": "SELL", "hash": "cec0fc9ed75c77f16411a370fa450de2be1f3cf3", "best_bid": "0.09", "best_ask": "0.7"}], "timestamp": "1769384043617", "event_type": "price_change"}}
{"_local_timestamp": "2026-01-25T23:34:03.927513+00:00", "data": {"market": "0xd423a5d9202016fba92b69fcc65e64b652f7bd0a3ff90a467a3b9981c1ba40bf", "price_changes": [{"asset_id": "94350465852216138354255274614877157805309416974679362811091088550032908691370", "price": "0.02", "size": "22.48", "side": "BUY", "hash": "098ad5fea951a293443a41f28ed6ff6517396265", "best_bid": "0.3", "best_ask": "0.91"}, {"asset_id": "66326498088647961820902244163239082840805695724900141547875364666440398917609", "price": "0.98", "size": "22.48", "side": "SELL", "hash": "1a4ae4f9886cfd94523d7d0e8ce4e70d737daf33", "best_bid": "0.09", "best_ask": "0.7"}], "timestamp": "1769384043861", "event_type": "price_change"}}
{"_local_timestamp": "2026-01-25T23:34:03.928014+00:00", "data": {"market": "0xd423a5d9202016fba92b69fcc65e64b652f7bd0a3ff90a467a3b9981c1ba40bf", "price_changes": [{"asset_id": "94350465852216138354255274614877157805309416974679362811091088550032908691370", "price": "0.16", "size": "6.12", "side": "BUY", "hash": "f294f4094ca90186929de8b9ab1364e970d6ffdc", "best_bid": "0.3", "best_ask": "0.91"}, {"asset_id": "66326498088647961820902244163239082840805695724900141547875364666440398917609", "price": "0.84", "size": "6.12", "side": "SELL", "hash": "66f9ef2988f5609c471939bd10051d1db073ce55", "best_bid": "0.09", "best_ask": "0.7"}], "timestamp": "1769384043862", "event_type": "price_change"}}
{"_local_timestamp": "2026-01-25T23:34:04.108887+00:00", "data": {"market": "0xfb0453c8a45a74240fb53aa98969613fdeb93e4d3235849079d3517266a5d5c6", "price_changes": [{"asset_id": "16163104876449149619311464240366771564134586034188584457341092863175915998347", "price": "0.18", "size": "0", "side": "BUY", "hash": "b64400d656ec46b194d07fe2f0cf5b5a1a6e4ef1", "best_bid": "0.67", "best_ask": "0.91"}, {"asset_id": "80661299423809747898502345161492672838497575056642213047279133666465067326877", "price": "0.82", "size": "0", "side": "SELL", "hash": "9e51d4b2717ab231381960dcab3b32c304380715", "best_bid": "0.09", "best_ask": "0.33"}], "timestamp": "1769384044047", "event_type": "price_change"}}
{"_local_timestamp": "2026-01-25T23:34:04.352928+00:00", "data": {"market": "0xfb0453c8a45a74240fb53aa98969613fdeb93e4d3235849079d3517266a5d5c6", "price_changes": [{"asset_id": "16163104876449149619311464240366771564134586034188584457341092863175915998347", "price": "0.2", "size": "6.34", "side": "BUY", "hash": "a5f0a5c01350bcdbdb253c21648550900a3a6834", "best_bid": "0.67", "best_ask": "0.91"}, {"asset_id": "80661299423809747898502345161492672838497575056642213047279133666465067326877", "price": "0.8", "size": "6.34", "side": "SELL", "hash": "d0d194accf32c24c476f6b9f055165849f21fc3a", "best_bid": "0.09", "best_ask": "0.33"}], "timestamp": "1769384044289", "event_type": "price_change"}}
{"_local_timestamp": "2026-01-25T23:34:04.969366+00:00", "data": {"market": "0xfb0453c8a45a74240fb53aa98969613fdeb93e4d3235849079d3517266a5d5c6", "price_changes": [{"asset_id": "16163104876449149619311464240366771564134586034188584457341092863175915998347", "price": "0.19", "size": "0", "side": "BUY", "hash": "5b17e822164f19059036db0b5f0743fce3a53721", "best_bid": "0.67", "best_ask": "0.91"}, {"asset_id": "80661299423809747898502345161492672838497575056642213047279133666465067326877", "price": "0.81", "size": "0", "side": "SELL", "hash": "49319d7affb327555e0a7121366205c32ab206ba", "best_bid": "0.09", "best_ask": "0.33"}], "timestamp": "1769384044863", "event_type": "price_change"}}
{"_local_timestamp": "2026-01-25T23:34:05.001465+00:00", "data": {"market": "0xfb0453c8a45a74240fb53aa98969613fdeb93e4d3235849079d3517266a5d5c6", "price_changes": [{"asset_id": "16163104876449149619311464240366771564134586034188584457341092863175915998347", "price": "0.21", "size": "20", "side": "BUY", "hash": "a6a63c6adfbac75a0182fb2fe70e44a55174d33e", "best_bid": "0.67", "best_ask": "0.91"}, {"asset_id": "80661299423809747898502345161492672838497575056642213047279133666465067326877", "price": "0.79", "size": "20", "side": "SELL", "hash": "b884132e086b64f851bd3112ee3e0176303fdeb6", "best_bid": "0.09", "best_ask": "0.33"}], "timestamp": "1769384044916", "event_type": "price_change"}}
{"_local_timestamp": "2026-01-25T23:34:11.246534+00:00", "data": {"market": "0xd423a5d9202016fba92b69fcc65e64b652f7bd0a3ff90a467a3b9981c1ba40bf", "price_changes": [{"asset_id": "94350465852216138354255274614877157805309416974679362811091088550032908691370", "price": "0.28", "size": "0", "side": "BUY", "hash": "e3a79e5fc42089b2ffedd1d97328802d82e6631e", "best_bid": "0.3", "best_ask": "0.91"}, {"asset_id": "66326498088647961820902244163239082840805695724900141547875364666440398917609", "price": "0.72", "size": "0", "side": "SELL", "hash": "218afc87f9b884eaf71b95053d7d423afcaab9c7", "best_bid": "0.09", "best_ask": "0.7"}], "timestamp": "1769384051172", "event_type": "price_change"}}
{"_local_timestamp": "2026-01-25T23:34:25.500494+00:00", "data": {"market": "0xd423a5d9202016fba92b69fcc65e64b652f7bd0a3ff90a467a3b9981c1ba40bf", "price_changes": [{"asset_id": "94350465852216138354255274614877157805309416974679362811091088550032908691370", "price": "0.29", "size": "0", "side": "BUY", "hash": "96c7f9875bf4cf032452ed18449dfbb6662c2167", "best_bid": "0.3", "best_ask": "0.91"}, {"asset_id": "66326498088647961820902244163239082840805695724900141547875364666440398917609", "price": "0.71", "size": "0", "side": "SELL", "hash": "babb03ebb82fa817c4f6df313cf3d90ed8e148aa", "best_bid": "0.09", "best_ask": "0.7"}], "timestamp": "1769384065368", "event_type": "price_change"}}
{"_local_timestamp": "2026-01-25T23:34:33.381900+00:00", "data": {"market": "0xd423a5d9202016fba92b69fcc65e64b652f7bd0a3ff90a467a3b9981c1ba40bf", "price_changes": [{"asset_id": "94350465852216138354255274614877157805309416974679362811091088550032908691370", "price": "0.3", "size": "5", "side": "BUY", "hash": "5b1c713db3b22c1054081b0815db67252d532d88", "best_bid": "0.3", "best_ask": "0.91"}, {"asset_id": "66326498088647961820902244163239082840805695724900141547875364666440398917609", "price": "0.7", "size": "5", "side": "SELL", "hash": "80207faca05826ffa469bf58330004740e37dba1", "best_bid": "0.09", "best_ask": "0.7"}], "timestamp": "1769384073306", "event_type": "price_change"}}
{"_local_timestamp": "2026-01-25T23:34:33.405558+00:00", "data": {"market": "0xd423a5d9202016fba92b69fcc65e64b652f7bd0a3ff90a467a3b9981c1ba40bf", "price_changes": [{"asset_id": "94350465852216138354255274614877157805309416974679362811091088550032908691370", "price": "0.28", "size": "20", "side": "BUY", "hash": "bf561ed2d97d467972461631152b921bf71a219c", "best_bid": "0.3", "best_ask": "0.91"}, {"asset_id": "66326498088647961820902244163239082840805695724900141547875364666440398917609", "price": "0.72", "size": "20", "side": "SELL", "hash": "54e3dd03fd66465cb77b357e8fad364829fd91dd", "best_bid": "0.09", "best_ask": "0.7"}], "timestamp": "1769384073335", "event_type": "price_change"}}
{"_local_timestamp": "2026-01-25T23:34:33.878974+00:00", "data": {"market": "0xd423a5d9202016fba92b69fcc65e64b652f7bd0a3ff90a467a3b9981c1ba40bf", "price_changes": [{"asset_id": "94350465852216138354255274614877157805309416974679362811091088550032908691370", "price": "0.3", "size": "0", "side": "BUY", "hash": "020656432c615a9b28f937bcfa715e32e3a0f565", "best_bid": "0.28", "best_ask": "0.91"}, {"asset_id": "66326498088647961820902244163239082840805695724900141547875364666440398917609", "price": "0.7", "size": "0", "side": "SELL", "hash": "a1e4b0abac40fcb3cd3acc83274104e2a7586ff8", "best_bid": "0.09", "best_ask": "0.72"}], "timestamp": "1769384073811", "event_type": "price_change"}}
{"_local_timestamp": "2026-01-25T23:34:36.557695+00:00", "data": {"market": "0xd423a5d9202016fba92b69fcc65e64b652f7bd0a3ff90a467a3b9981c1ba40bf", "price_changes": [{"asset_id": "94350465852216138354255274614877157805309416974679362811091088550032908691370", "price": "0.28", "size": "25", "side": "BUY", "hash": "eefac2bca8037a516b382d3a0b548e0e6d12ef51", "best_bid": "0.28", "best_ask": "0.91"}, {"asset_id": "66326498088647961820902244163239082840805695724900141547875364666440398917609", "price": "0.72", "size": "25", "side": "SELL", "hash": "f18f3e0bd76c3ac3ee90df1e994cedbd1ff98e16", "best_bid": "0.09", "best_ask": "0.72"}], "timestamp": "1769384076486", "event_type": "price_change"}}
{"_local_timestamp": "2026-01-25T23:35:17.425369+00:00", "data": {"market": "0xcd24bf9e4312eff0c8e93716adf5f1507c802eb49940dc548686d3dd01f7dc80", "price_changes": [{"asset_id": "26250882338411993353025798873396196450213722200450121972167061161438889023462", "price": "0.01", "size": "168.9", "side": "BUY", "hash": "3d6a300e29fe6159a54263f874b89c16ffa5206c", "best_bid": "0.06", "best_ask": "0.3"}, {"asset_id": "5838306871037945340010006268256931296949052336165005624521859666744160071457", "price": "0.99", "size": "168.9", "side": "SELL", "hash": "94d00d7daa862aa85e028dc2be3c95784fc3afaf", "best_bid": "0.7", "best_ask": "0.94"}], "timestamp": "1769384117357", "event_type": "price_change"}}
{"_local_timestamp": "2026-01-25T23:35:19.742275+00:00", "data": {"market": "0x238e76ab8673302f69465f6276dc30397f2da6d45e256d1addb3727c52d426cf", "price_changes": [{"asset_id": "45416836285011613952203179410772546980719957661013072684949967687661326740901", "price": "0.01", "size": "182.27", "side": "BUY", "hash": "b9a2d97593a1a122ae6e7c4cfb013541a6c07b52", "best_bid": "0.06", "best_ask": "0.29"}, {"asset_id": "97242587671502984422385091919023155761644234345765358718238822411412771007696", "price": "0.99", "size": "182.27", "side": "SELL", "hash": "94e0b62ecdea63c310d17364215404e2e12d6ccd", "best_bid": "0.71", "best_ask": "0.94"}], "timestamp": "1769384119679", "event_type": "price_change"}}
{"_local_timestamp": "2026-01-25T23:35:24.925781+00:00", "data": {"market": "0xda6d412db6123d081fc90f020d6a7cb9b19bf4a48888fd1884071d62e7543611", "price_changes": [{"asset_id": "80000332397245837596854182599697796366828301139631925465959846280975689186136", "price": "0.01", "size": "168.9", "side": "BUY", "hash": "7898e9544760e6ff7b2cab9302480d167cc034d1", "best_bid": "0.06", "best_ask": "0.3"}, {"asset_id": "112184512106281098337746048918245759041804395263732191740766735719601623879523", "price": "0.99", "size": "168.9", "side": "SELL", "hash": "1bf485b3578eaf6a6f94b381d6cd9916a20f9538", "best_bid": "0.7", "best_ask": "0.94"}], "timestamp": "1769384124730", "event_type": "price_change"}}
{"_local_timestamp": "2026-01-25T23:35:28.152075+00:00", "data": {"market": "0x897bf69800a1bdda4aedfb6514f3f5a50e3dd128e1e6f9d626978a1e6318e73b", "price_changes": [{"asset_id": "62293292317905300650991725392919669384770245915371865525007679676421368767515", "price": "0.01", "size": "168.9", "side": "BUY", "hash": "1f797878c416b1fd363f37fe3e9fa18fb437963f", "best_bid": "0.06", "best_ask": "0.3"}, {"asset_id": "107315720365659808114604028527822042298641109513906619819239162323543505300877", "price": "0.99", "size": "168.9", "side": "SELL", "hash": "158f89799090b170eead4e4b2122410a95c68222", "best_bid": "0.7", "best_ask": "0.94"}], "timestamp": "1769384128084", "event_type": "price_change"}}
{"_local_timestamp": "2026-01-25T23:35:28.649304+00:00", "data": {"market": "0x897bf69800a1bdda4aedfb6514f3f5a50e3dd128e1e6f9d626978a1e6318e73b", "price_changes": [{"asset_id": "62293292317905300650991725392919669384770245915371865525007679676421368767515", "price": "0.01", "size": "140.33", "side": "BUY", "hash": "f1d8ea188c826f3d9f3ae4df9faa99a99e8886b3", "best_bid": "0.06", "best_ask": "0.3"}, {"asset_id": "107315720365659808114604028527822042298641109513906619819239162323543505300877", "price": "0.99", "size": "140.33", "side": "SELL", "hash": "c8f1d5e527bddec27db9fa4fb73ba7fb450fa535", "best_bid": "0.7", "best_ask": "0.94"}], "timestamp": "1769384128571", "event_type": "price_change"}}
{"_local_timestamp": "2026-01-25T23:35:28.649800+00:00", "data": {"market": "0x238e76ab8673302f69465f6276dc30397f2da6d45e256d1addb3727c52d426cf", "price_changes": [{"asset_id": "45416836285011613952203179410772546980719957661013072684949967687661326740901", "price": "0.01", "size": "153.7", "side": "BUY", "hash": "0c3ead5662c886f88c1270e2dc4717c3ed201580", "best_bid": "0.06", "best_ask": "0.29"}, {"asset_id": "97242587671502984422385091919023155761644234345765358718238822411412771007696", "price": "0.99", "size": "153.7", "side": "SELL", "hash": "2d4fd137abc36800f5c0d587ef22e51a3cb2f6c6", "best_bid": "0.71", "best_ask": "0.94"}], "timestamp": "1769384128571", "event_type": "price_change"}}
{"_local_timestamp": "2026-01-25T23:35:28.650155+00:00", "data": {"market": "0xcd24bf9e4312eff0c8e93716adf5f1507c802eb49940dc548686d3dd01f7dc80", "price_changes": [{"asset_id": "26250882338411993353025798873396196450213722200450121972167061161438889023462", "price": "0.01", "size": "140.33", "side": "BUY", "hash": "887cf87ac685e7fb7d3466e72265234912566e9d", "best_bid": "0.06", "best_ask": "0.3"}, {"asset_id": "5838306871037945340010006268256931296949052336165005624521859666744160071457", "price": "0.99", "size": "140.33", "side": "SELL", "hash": "62722594662a87b568c555f6d85bedf56351b809", "best_bid": "0.7", "best_ask": "0.94"}], "timestamp": "1769384128571", "event_type": "price_change"}}
{"_local_timestamp": "2026-01-25T23:35:28.650490+00:00", "data": {"market": "0xda6d412db6123d081fc90f020d6a7cb9b19bf4a48888fd1884071d62e7543611", "price_changes": [{"asset_id": "80000332397245837596854182599697796366828301139631925465959846280975689186136", "price": "0.01", "size": "140.33", "side": "BUY", "hash": "d2043651f3790473c07fbab1059736d25cd73cc2", "best_bid": "0.06", "best_ask": "0.3"}, {"asset_id": "112184512106281098337746048918245759041804395263732191740766735719601623879523", "price": "0.99", "size": "140.33", "side": "SELL", "hash": "707ff842d9e4881eaa9c32973833b64d36a207c2", "best_bid": "0.7", "best_ask": "0.94"}], "timestamp": "1769384128571", "event_type": "price_change"}}
{"_local_timestamp": "2026-01-25T23:35:29.242829+00:00", "data": {"market": "0x60704bdb0d83d6f14581a1ebfe2a0f1f3c110b5b4d5e6644b4f526a0ef7d3001", "price_changes": [{"asset_id": "52795436891171139146570659596446975016064524845299806211429059129878692728045", "price": "0.01", "size": "168.9", "side": "BUY", "hash": "f91edecfd60de1e66e94227b6e9b728e4ee004b4", "best_bid": "0.06", "best_ask": "0.28"}, {"asset_id": "93030990064375513510189225885274415076490550330310701425495660148274214307425", "price": "0.99", "size": "168.9", "side": "SELL", "hash": "c942eb1312d5f341189438a858432cf5463fcb11", "best_bid": "0.72", "best_ask": "0.94"}], "timestamp": "1769384129171", "event_type": "price_change"}}
{"_local_timestamp": "2026-01-25T23:36:18.222604+00:00", "data": {"market": "0xd423a5d9202016fba92b69fcc65e64b652f7bd0a3ff90a467a3b9981c1ba40bf", "price_changes": [{"asset_id": "94350465852216138354255274614877157805309416974679362811091088550032908691370", "price": "0.11", "size": "0", "side": "BUY", "hash": "02bea4662b503475a9f7ee55e17c7f31538a4cbc", "best_bid": "0.28", "best_ask": "0.91"}, {"asset_id": "66326498088647961820902244163239082840805695724900141547875364666440398917609", "price": "0.89", "size": "0", "side": "SELL", "hash": "5ad8504532d8e72419f01ec1174175aa11f26099", "best_bid": "0.09", "best_ask": "0.72"}], "timestamp": "1769384178160", "event_type": "price_change"}}
{"_local_timestamp": "2026-01-25T23:36:18.935101+00:00", "data": {"market": "0xd423a5d9202016fba92b69fcc65e64b652f7bd0a3ff90a467a3b9981c1ba40bf", "price_changes": [{"asset_id": "94350465852216138354255274614877157805309416974679362811091088550032908691370", "price": "0.15", "size": "46.33", "side": "BUY", "hash": "102e7e0ff37c4572870cd9fc316f1f163ef8047b", "best_bid": "0.28", "best_ask": "0.91"}, {"asset_id": "66326498088647961820902244163239082840805695724900141547875364666440398917609", "price": "0.85", "size": "46.33", "side": "SELL", "hash": "dbc7fa55ce8cc114c39cd89d8f7842cc763b0221", "best_bid": "0.09", "best_ask": "0.72"}], "timestamp": "1769384178869", "event_type": "price_change"}}
{"_local_timestamp": "2026-01-25T23:36:28.918934+00:00", "data": {"market": "0x60704bdb0d83d6f14581a1ebfe2a0f1f3c110b5b4d5e6644b4f526a0ef7d3001", "price_changes": [{"asset_id": "52795436891171139146570659596446975016064524845299806211429059129878692728045", "price": "0.01", "size": "140.33", "side": "BUY", "hash": "26ccafc46a53084c92e0688e40cb9f293703c4d9", "best_bid": "0.06", "best_ask": "0.28"}, {"asset_id": "93030990064375513510189225885274415076490550330310701425495660148274214307425", "price": "0.99", "size": "140.33", "side": "SELL", "hash": "bcf2def91eca2313c7ba8a135b30d539db5090b1", "best_bid": "0.72", "best_ask": "0.94"}], "timestamp": "1769384188820", "event_type": "price_change"}}
{"_local_timestamp": "2026-01-25T23:38:18.031996+00:00", "data": {"market": "0xd423a5d9202016fba92b69fcc65e64b652f7bd0a3ff90a467a3b9981c1ba40bf", "price_changes": [{"asset_id": "94350465852216138354255274614877157805309416974679362811091088550032908691370", "price": "0.16", "size": "0", "side": "BUY", "hash": "a1e5e6b2655ba703a6d3e1a576d62b66eb9d56f8", "best_bid": "0.28", "best_ask": "0.91"}, {"asset_id": "66326498088647961820902244163239082840805695724900141547875364666440398917609", "price": "0.84", "size": "0", "side": "SELL", "hash": "7ef3a2044ca1ef66ec1abbaa0e4ffac21bcef35e", "best_bid": "0.09", "best_ask": "0.72"}], "timestamp": "1769384297966", "event_type": "price_change"}}
{"_local_timestamp": "2026-01-25T23:38:18.032599+00:00", "data": {"market": "0xfb0453c8a45a74240fb53aa98969613fdeb93e4d3235849079d3517266a5d5c6", "price_changes": [{"asset_id": "16163104876449149619311464240366771564134586034188584457341092863175915998347", "price": "0.07", "size": "0", "side": "BUY", "hash": "54b25367f7433bebe86e87451e715e93c56fc01e", "best_bid": "0.67", "best_ask": "0.91"}, {"asset_id": "80661299423809747898502345161492672838497575056642213047279133666465067326877", "price": "0.93", "size": "0", "side": "SELL", "hash": "a12d4b9e7f28aed5ca942e67d8305a63e968a894", "best_bid": "0.09", "best_ask": "0.33"}], "timestamp": "1769384297966", "event_type": "price_change"}}
{"_local_timestamp": "2026-01-25T23:38:18.034950+00:00", "data": {"market": "0xfb0453c8a45a74240fb53aa98969613fdeb93e4d3235849079d3517266a5d5c6", "price_changes": [{"asset_id": "16163104876449149619311464240366771564134586034188584457341092863175915998347", "price": "0.2", "size": "0", "side": "BUY", "hash": "54b25367f7433bebe86e87451e715e93c56fc01e", "best_bid": "0.67", "best_ask": "0.91"}, {"asset_id": "80661299423809747898502345161492672838497575056642213047279133666465067326877", "price": "0.8", "size": "0", "side": "SELL", "hash": "a12d4b9e7f28aed5ca942e67d8305a63e968a894", "best_bid": "0.09", "best_ask": "0.33"}], "timestamp": "1769384297966", "event_type": "price_change"}}
{"_local_timestamp": "2026-01-25T23:38:18.469641+00:00", "data": {"market": "0xd423a5d9202016fba92b69fcc65e64b652f7bd0a3ff90a467a3b9981c1ba40bf", "price_changes": [{"asset_id": "94350465852216138354255274614877157805309416974679362811091088550032908691370", "price": "0.28", "size": "92", "side": "BUY", "hash": "2412af506ec107ad91c7de521d8fb9f31022a93b", "best_bid": "0.28", "best_ask": "0.91"}, {"asset_id": "66326498088647961820902244163239082840805695724900141547875364666440398917609", "price": "0.72", "size": "92", "side": "SELL", "hash": "2e2bcf56a21f5475c1bdc95fd5274110723add4b", "best_bid": "0.09", "best_ask": "0.72"}], "timestamp": "1769384298396", "event_type": "price_change"}}
{"_local_timestamp": "2026-01-25T23:38:18.470067+00:00", "data": {"market": "0xd423a5d9202016fba92b69fcc65e64b652f7bd0a3ff90a467a3b9981c1ba40bf", "price_changes": [{"asset_id": "94350465852216138354255274614877157805309416974679362811091088550032908691370", "price": "0.29", "size": "67", "side": "BUY", "hash": "fece299b8af4fff2a533f568717d26ea3b30fd9b", "best_bid": "0.29", "best_ask": "0.91"}, {"asset_id": "66326498088647961820902244163239082840805695724900141547875364666440398917609", "price": "0.71", "size": "67", "side": "SELL", "hash": "11051995924efdc9f948cd40701d97e1c73917a3", "best_bid": "0.09", "best_ask": "0.71"}], "timestamp": "1769384298396", "event_type": "price_change"}}
{"_local_timestamp": "2026-01-25T23:38:18.493619+00:00", "data": {"market": "0xd423a5d9202016fba92b69fcc65e64b652f7bd0a3ff90a467a3b9981c1ba40bf", "price_changes": [{"asset_id": "94350465852216138354255274614877157805309416974679362811091088550032908691370", "price": "0.15", "size": "52.86", "side": "BUY", "hash": "ddece42f6674497dbd19d75cfd93f6b313d80217", "best_bid": "0.29", "best_ask": "0.91"}, {"asset_id": "66326498088647961820902244163239082840805695724900141547875364666440398917609", "price": "0.85", "size": "52.86", "side": "SELL", "hash": "3b3ff2302e7bf79365fda86b996ea1d823b3e4c2", "best_bid": "0.09", "best_ask": "0.71"}], "timestamp": "1769384298420", "event_type": "price_change"}}
{"_local_timestamp": "2026-01-25T23:38:18.494032+00:00", "data": {"market": "0xfb0453c8a45a74240fb53aa98969613fdeb93e4d3235849079d3517266a5d5c6", "price_changes": [{"asset_id": "16163104876449149619311464240366771564134586034188584457341092863175915998347", "price": "0.12", "size": "11.71", "side": "BUY", "hash": "efc0922b89969d9b8eec1472e5beabfc42e3a4f3", "best_bid": "0.67", "best_ask": "0.91"}, {"asset_id": "80661299423809747898502345161492672838497575056642213047279133666465067326877", "price": "0.88", "size": "11.71", "side": "SELL", "hash": "37542870788ca6afac8f05788bcf0ae90b1420f1", "best_bid": "0.09", "best_ask": "0.33"}], "timestamp": "1769384298420", "event_type": "price_change"}}
{"_local_timestamp": "2026-01-25T23:38:18.494391+00:00", "data": {"market": "0xfb0453c8a45a74240fb53aa98969613fdeb93e4d3235849079d3517266a5d5c6", "price_changes": [{"asset_id": "16163104876449149619311464240366771564134586034188584457341092863175915998347", "price": "0.06", "size": "38.05", "side": "BUY", "hash": "c7898b0650bd715dcd1cb846332cfbe7061cfab6", "best_bid": "0.67", "best_ask": "0.91"}, {"asset_id": "80661299423809747898502345161492672838497575056642213047279133666465067326877", "price": "0.94", "size": "38.05", "side": "SELL", "hash": "0573b3d0d14ba11f179b60b454573939f33d8dc5", "best_bid": "0.09", "best_ask": "0.33"}], "timestamp": "1769384298422", "event_type": "price_change"}}
{"_local_timestamp": "2026-01-25T23:38:18.723841+00:00", "data": {"market": "0xfb0453c8a45a74240fb53aa98969613fdeb93e4d3235849079d3517266a5d5c6", "price_changes": [{"asset_id": "16163104876449149619311464240366771564134586034188584457341092863175915998347", "price": "0.21", "size": "0", "side": "BUY", "hash": "5f8df931ae5832f4594200b42727a408d79f6e10", "best_bid": "0.67", "best_ask": "0.91"}, {"asset_id": "80661299423809747898502345161492672838497575056642213047279133666465067326877", "price": "0.79", "size": "0", "side": "SELL", "hash": "8438fcaed26db93281ad02fc06ae76ae6119c284", "best_bid": "0.09", "best_ask": "0.33"}], "timestamp": "1769384298652", "event_type": "price_change"}}
{"_local_timestamp": "2026-01-25T23:38:18.724258+00:00", "data": {"market": "0xd423a5d9202016fba92b69fcc65e64b652f7bd0a3ff90a467a3b9981c1ba40bf", "price_changes": [{"asset_id": "94350465852216138354255274614877157805309416974679362811091088550032908691370", "price": "0.28", "size": "72", "side": "BUY", "hash": "505c83221d601fd10cc09c6ecf27b873be8f0875", "best_bid": "0.29", "best_ask": "0.91"}, {"asset_id": "66326498088647961820902244163239082840805695724900141547875364666440398917609", "price": "0.72", "size": "72", "side": "SELL", "hash": "71e0dd5ee4cdb1a1edfbcdfb8bf52457d3cc0b08", "best_bid": "0.09", "best_ask": "0.71"}], "timestamp": "1769384298652", "event_type": "price_change"}}
{"_local_timestamp": "2026-01-25T23:38:18.749857+00:00", "data": {"market": "0xfb0453c8a45a74240fb53aa98969613fdeb93e4d3235849079d3517266a5d5c6", "price_changes": [{"asset_id": "16163104876449149619311464240366771564134586034188584457341092863175915998347", "price": "0.13", "size": "25", "side": "BUY", "hash": "8d638b3b6ccdc23532aae5c0a340dcee5f8ee1ec", "best_bid": "0.67", "best_ask": "0.91"}, {"asset_id": "80661299423809747898502345161492672838497575056642213047279133666465067326877", "price": "0.87", "size": "25", "side": "SELL", "hash": "e31bc988f384f79f0982c73f87c0437394494c99", "best_bid": "0.09", "best_ask": "0.33"}], "timestamp": "1769384298681", "event_type": "price_change"}}
{"_local_timestamp": "2026-01-25T23:38:18.757135+00:00", "data": {"market": "0xd423a5d9202016fba92b69fcc65e64b652f7bd0a3ff90a467a3b9981c1ba40bf", "price_changes": [{"asset_id": "94350465852216138354255274614877157805309416974679362811091088550032908691370", "price": "0.3", "size": "20", "side": "BUY", "hash": "cb0d84f3de92a886959d192f46d5d9fac863b9e0", "best_bid": "0.3", "best_ask": "0.91"}, {"asset_id": "66326498088647961820902244163239082840805695724900141547875364666440398917609", "price": "0.7", "size": "20", "side": "SELL", "hash": "b0182648701d06ccc7f580ec611b2cb9352cec8d", "best_bid": "0.09", "best_ask": "0.7"}], "timestamp": "1769384298682", "event_type": "price_change"}}
{"_local_timestamp": "2026-01-25T23:38:19.478564+00:00", "data": {"market": "0xd423a5d9202016fba92b69fcc65e64b652f7bd0a3ff90a467a3b9981c1ba40bf", "price_changes": [{"asset_id": "94350465852216138354255274614877157805309416974679362811091088550032908691370", "price": "0.28", "size": "67", "side": "BUY", "hash": "c7e17f5a06edc9f299787b64cea31c7ab920203e", "best_bid": "0.3", "best_ask": "0.91"}, {"asset_id": "66326498088647961820902244163239082840805695724900141547875364666440398917609", "price": "0.72", "size": "67", "side": "SELL", "hash": "2329f3c40210bd7ca49a2fdd87aa8ad1e201df6c", "best_bid": "0.09", "best_ask": "0.7"}], "timestamp": "1769384299410", "event_type": "price_change"}}
{"_local_timestamp": "2026-01-25T23:38:25.529839+00:00", "data": {"market": "0xd423a5d9202016fba92b69fcc65e64b652f7bd0a3ff90a467a3b9981c1ba40bf", "price_changes": [{"asset_id": "94350465852216138354255274614877157805309416974679362811091088550032908691370", "price": "0.3", "size": "25", "side": "BUY", "hash": "6579f95e23f68e2b4911b0b4ea720ef54596f988", "best_bid": "0.3", "best_ask": "0.91"}, {"asset_id": "66326498088647961820902244163239082840805695724900141547875364666440398917609", "price": "0.7", "size": "25", "side": "SELL", "hash": "375a4730d04281a8d5c5c7097054765a26882763", "best_bid": "0.09", "best_ask": "0.7"}], "timestamp": "1769384305432", "event_type": "price_change"}}
{"_local_timestamp": "2026-01-25T23:38:29.730189+00:00", "data": {"market": "0xd423a5d9202016fba92b69fcc65e64b652f7bd0a3ff90a467a3b9981c1ba40bf", "price_changes": [{"asset_id": "94350465852216138354255274614877157805309416974679362811091088550032908691370", "price": "0.29", "size": "0", "side": "BUY", "hash": "c025f2c444ee840a24e9190bc7a8d812df653990", "best_bid": "0.3", "best_ask": "0.91"}, {"asset_id": "66326498088647961820902244163239082840805695724900141547875364666440398917609", "price": "0.71", "size": "0", "side": "SELL", "hash": "35342a16fe9f62412fafb5214166f12df26854be", "best_bid": "0.09", "best_ask": "0.7"}], "timestamp": "1769384309619", "event_type": "price_change"}}
{"_local_timestamp": "2026-01-25T23:38:29.981779+00:00", "data": {"market": "0xd423a5d9202016fba92b69fcc65e64b652f7bd0a3ff90a467a3b9981c1ba40bf", "price_changes": [{"asset_id": "94350465852216138354255274614877157805309416974679362811091088550032908691370", "price": "0.3", "size": "5", "side": "BUY", "hash": "215039ae5e44eb04e85af0581860992d563ee2fd", "best_bid": "0.3", "best_ask": "0.91"}, {"asset_id": "66326498088647961820902244163239082840805695724900141547875364666440398917609", "price": "0.7", "size": "5", "side": "SELL", "hash": "11b8357bc2cb2e36214f14193bd427c779ed0ff3", "best_bid": "0.09", "best_ask": "0.7"}], "timestamp": "1769384309917", "event_type": "price_change"}}
{"_local_timestamp": "2026-01-25T23:38:30.010686+00:00", "data": {"market": "0xd423a5d9202016fba92b69fcc65e64b652f7bd0a3ff90a467a3b9981c1ba40bf", "price_changes": [{"asset_id": "94350465852216138354255274614877157805309416974679362811091088550032908691370", "price": "0.29", "size": "20", "side": "BUY", "hash": "e78cd3402dfc4d32e2e05af8a5e6dd0395336368", "best_bid": "0.3", "best_ask": "0.91"}, {"asset_id": "66326498088647961820902244163239082840805695724900141547875364666440398917609", "price": "0.71", "size": "20", "side": "SELL", "hash": "8b8ec3773d7c912dc18d725f4a2b412ba4bd6067", "best_bid": "0.09", "best_ask": "0.7"}], "timestamp": "1769384309946", "event_type": "price_change"}}
{"_local_timestamp": "2026-01-25T23:38:46.473209+00:00", "data": {"market": "0xd423a5d9202016fba92b69fcc65e64b652f7bd0a3ff90a467a3b9981c1ba40bf", "price_changes": [{"asset_id": "94350465852216138354255274614877157805309416974679362811091088550032908691370", "price": "0.28", "size": "0", "side": "BUY", "hash": "85af218653f45a8ce7be5c5de5e9ebfb2fb60712", "best_bid": "0.3", "best_ask": "0.91"}, {"asset_id": "66326498088647961820902244163239082840805695724900141547875364666440398917609", "price": "0.72", "size": "0", "side": "SELL", "hash": "999a3e25b6043db341fc2c72cc7722a8f973f283", "best_bid": "0.09", "best_ask": "0.7"}], "timestamp": "1769384326404", "event_type": "price_change"}}
{"_local_timestamp": "2026-01-25T23:38:53.161373+00:00", "data": {"market": "0xd423a5d9202016fba92b69fcc65e64b652f7bd0a3ff90a467a3b9981c1ba40bf", "price_changes": [{"asset_id": "94350465852216138354255274614877157805309416974679362811091088550032908691370", "price": "0.29", "size": "0", "side": "BUY", "hash": "867b186c1c7c9ebc0a3ae4168ee64506e4fb1478", "best_bid": "0.3", "best_ask": "0.91"}, {"asset_id": "66326498088647961820902244163239082840805695724900141547875364666440398917609", "price": "0.71", "size": "0", "side": "SELL", "hash": "5c0d21ee86b004d98ce11867a1a4221c1e6b55b3", "best_bid": "0.09", "best_ask": "0.7"}], "timestamp": "1769384333084", "event_type": "price_change"}}
{"_local_timestamp": "2026-01-25T23:38:53.192791+00:00", "data": {"market": "0xd423a5d9202016fba92b69fcc65e64b652f7bd0a3ff90a467a3b9981c1ba40bf", "price_changes": [{"asset_id": "94350465852216138354255274614877157805309416974679362811091088550032908691370", "price": "0.28", "size": "20", "side": "BUY", "hash": "80befdbf4ac1b27ca81eac180a99835a3f4afb51", "best_bid": "0.3", "best_ask": "0.91"}, {"asset_id": "66326498088647961820902244163239082840805695724900141547875364666440398917609", "price": "0.72", "size": "20", "side": "SELL", "hash": "a96128fa4ae568c924e83187906f667828c70c30", "best_bid": "0.09", "best_ask": "0.7"}], "timestamp": "1769384333112", "event_type": "price_change"}}
{"_local_timestamp": "2026-01-25T23:38:54.871431+00:00", "data": {"market": "0xd423a5d9202016fba92b69fcc65e64b652f7bd0a3ff90a467a3b9981c1ba40bf", "price_changes": [{"asset_id": "94350465852216138354255274614877157805309416974679362811091088550032908691370", "price": "0.3", "size": "0", "side": "BUY", "hash": "d7cbccc82ddbcf8256c3129e3f40b4d1e35c631d", "best_bid": "0.28", "best_ask": "0.91"}, {"asset_id": "66326498088647961820902244163239082840805695724900141547875364666440398917609", "price": "0.7", "size": "0", "side": "SELL", "hash": "3a74249f2b385df1c4fcc7156c5a8edf651f594e", "best_bid": "0.09", "best_ask": "0.72"}], "timestamp": "1769384334805", "event_type": "price_change"}}
{"_local_timestamp": "2026-01-25T23:38:57.469152+00:00", "data": {"market": "0xd423a5d9202016fba92b69fcc65e64b652f7bd0a3ff90a467a3b9981c1ba40bf", "price_changes": [{"asset_id": "94350465852216138354255274614877157805309416974679362811091088550032908691370", "price": "0.28", "size": "25", "side": "BUY", "hash": "a714298e9b0d6be412cbaa7d31b37d62338c62d8", "best_bid": "0.28", "best_ask": "0.91"}, {"asset_id": "66326498088647961820902244163239082840805695724900141547875364666440398917609", "price": "0.72", "size": "25", "side": "SELL", "hash": "12df2c003e7860e6a70e7246771c80434063ce25", "best_bid": "0.09", "best_ask": "0.72"}], "timestamp": "1769384337407", "event_type": "price_change"}}
{"_local_timestamp": "2026-01-25T23:40:13.106549+00:00", "data": {"market": "0x238e76ab8673302f69465f6276dc30397f2da6d45e256d1addb3727c52d426cf", "price_changes": [{"asset_id": "97242587671502984422385091919023155761644234345765358718238822411412771007696", "price": "0.37", "size": "20", "side": "BUY", "hash": "df2379c19eda114b17f72c3361204c0e4adc381f", "best_bid": "0.71", "best_ask": "0.94"}, {"asset_id": "45416836285011613952203179410772546980719957661013072684949967687661326740901", "price": "0.63", "size": "20", "side": "SELL", "hash": "a12845ecefb513ec9d1ab0f943832fe2a87711b5", "best_bid": "0.06", "best_ask": "0.29"}], "timestamp": "1769384413041", "event_type": "price_change"}}
{"_local_timestamp": "2026-01-25T23:40:13.155306+00:00", "data": {"market": "0x238e76ab8673302f69465f6276dc30397f2da6d45e256d1addb3727c52d426cf", "price_changes": [{"asset_id": "97242587671502984422385091919023155761644234345765358718238822411412771007696", "price": "0.38", "size": "5", "side": "BUY", "hash": "b80713ba3dd8e7a6a0283a333c5ecd3282f5199b", "best_bid": "0.71", "best_ask": "0.94"}, {"asset_id": "45416836285011613952203179410772546980719957661013072684949967687661326740901", "price": "0.62", "size": "5", "side": "SELL", "hash": "99e2a69510d8678fa03d58dee525cde2d9c4735d", "best_bid": "0.06", "best_ask": "0.29"}], "timestamp": "1769384413091", "event_type": "price_change"}}
