{"_local_timestamp": "2026-01-25T23:40:31.208216+00:00", "data": [{"market": "0xa281783fc73b1a6927a301ee34cd90795470dc64b500673e445ba5e54f697c09", "asset_id": "19224712151342060925250675326667957156597084749312967133447388236247487979547", "timestamp": "1769384430427", "hash": "34ded16bec9b40b86c9454f17aef3220d9cedcab", "bids": [{"price": "0.001", "size": "11007099.85"}, {"price": "0.002", "size": "91255.83"}, {"price": "0.003", "size": "1400"}, {"price": "0.004", "size": "10.09"}, {"price": "0.006", "size": "200"}, {"price": "0.01", "size": "2000"}, {"price": "0.011", "size": "7.14"}, {"price": "0.02", "size": "1000"}, {"price": "0.021", "size": "41000"}, {"price": "0.022", "size": "10"}, {"price": "0.024", "size": "33333"}, {"price": "0.025", "size": "5.61"}, {"price": "0.05", "size": "330"}, {"price": "0.051", "size": "39"}, {"price": "0.052", "size": "11.65"}, {"price": "0.09", "size": "700"}, {"price": "0.14", "size": "567.85"}, {"price": "0.19", "size": "418.42"}, {"price": "0.191", "size": "209"}, {"price": "0.192", "size": "5.82"}, {"price": "0.24", "size": "116.66"}, {"price": "0.253", "size": "5000"}, {"price": "0.259", "size": "5575"}, {"price": "0.26", "size": "1614"}, {"price": "0.261", "size": "300"}, {"price": "0.27", "size": "50"}, {"price": "0.28", "size": "92.85"}, {"price": "0.33", "size": "72.72"}, {"price": "0.38", "size": "177.63"}, {"price": "0.381", "size": "25"}, {"price": "0.513", "size": "2222"}, {"price": "0.514", "size": "5"}, {"price": "0.515", "size": "25"}, {"price": "0.516", "size": "20"}, {"price": "0.82", "size": "2072.3"}, {"price": "0.821", "size": "317.55"}, {"price": "0.822", "size": "222.23"}, {"price": "0.823", "size": "16.66"}, {"price": "0.824", "size": "25"}, {"price": "0.858", "size": "20"}, {"price": "0.912", "size": "75.85"}, {"price": "0.913", "size": "75"}, {"price": "0.914", "size": "6.32"}, {"price": "0.915", "size": "24.63"}], "asks": [{"price": "0.999", "size": "117628"}, {"price": "0.998", "size": "2166"}, {"price": "0.997", "size": "508.52"}, {"price": "0.995", "size": "150"}, {"price": "0.994", "size": "75"}, {"price": "0.993", "size": "6.22"}, {"price": "0.99", "size": "50"}, {"price": "0.989", "size": "50"}, {"price": "0.987", "size": "50"}, {"price": "0.986", "size": "15.47"}, {"price": "0.969", "size": "15"}, {"price": "0.965", "size": "555.79"}, {"price": "0.964", "size": "50"}, {"price": "0.95", "size": "50"}, {"price": "0.947", "size": "200"}, {"price": "0.946", "size": "10"}, {"price": "0.945", "size": "338.53"}, {"price": "0.943", "size": "416.14"}], "event_type": "book", "last_trade_price": "0.057"}, {"market": "0x3849e1d62e0807801913d3e2427e8caf3cc6dd1c8ef42d8d5c08c6f9c449dc5e", "asset_id": "56615676606297588259337956203332341775475048285080710344367729433788967812170", "timestamp": "1769384401977", "hash": "db0c870d94f7f9fda3bc601670d9b554dd73e523", "bids": [{"price": "0.01", "size": "55310"}, {"price": "0.02", "size": "22000"}, {"price": "0.03", "size": "9.52"}, {"price": "0.04", "size": "250"}, {"price": "0.05", "size": "3300"}, {"price": "0.07", "size": "514.28"}, {"price": "0.08", "size": "4061"}, {"price": "0.11", "size": "417.09"}, {"price": "0.14", "size": "228.57"}, {"price": "0.15", "size": "325"}, {"price": "0.17", "size": "649.7"}, {"price": "0.21", "size": "123.8"}, {"price": "0.24", "size": "750"}, {"price": "0.25", "size": "250"}, {"price": "0.28", "size": "71.42"}, {"price": "0.3", "size": "300"}, {"price": "0.31", "size": "100"}, {"price": "0.34", "size": "50"}, {"price": "0.5", "size": "43.27"}, {"price": "0.51", "size": "91.48"}, {"price": "0.52", "size": "160"}, {"price": "0.6", "size": "21.66"}, {"price": "0.61", "size": "46.21"}, {"price": "0.62", "size": "27.04"}, {"price": "0.64", "size": "29.99"}, {"price": "0.67", "size": "102"}], "asks": [{"price": "0.99", "size": "3012.72"}, {"price": "0.98", "size": "25700"}, {"price": "0.97", "size": "806.1"}, {"price": "0.96", "size": "850"}, {"price": "0.95", "size": "17.08"}, {"price": "0.9", "size": "69.73"}, {"price": "0.85", "size": "31"}, {"price": "0.84", "size": "25.22"}, {"price": "0.82", "size": "6"}, {"price": "0.8", "size": "68.51"}, {"price": "0.79", "size": "25"}, {"price": "0.78", "size": "89.09"}, {"price": "0.77", "size": "47.82"}, {"price": "0.76", "size": "20"}, {"price": "0.75", "size": "180"}, {"price": "0.73", "size": "491.92"}, {"price": "0.72", "size": "3853.99"}, {"price": "0.71", "size": "224.77"}, {"price": "0.7", "size": "884.12"}], "event_type": "book", "last_trade_price": "0.320"}, {"market": "0x3849e1d62e0807801913d3e2427e8caf3cc6dd1c8ef42d8d5c08c6f9c449dc5e", "asset_id": "8070607953656787024050950499598687532281829563384949938603247089607814583142", "timestamp": "1769384401977", "hash": "f17214d38dc8cd08f338f39d7a708086114af3ea", "bids": [{"price": "0.01", "size": "3012.72"}, {"price": "0.02", "size": "25700"}, {"price": "0.03", "size": "806.1"}, {"price": "0.04", "size": "850"}, {"price": "0.05", "size": "17.08"}, {"price": "0.1", "size": "69.73"}, {"price": "0.15", "size": "31"}, {"price": "0.16", "size": "25.22"}, {"price": "0.18", "size": "6"}, {"price": "0.2", "size": "68.51"}, {"price": "0.21", "size": "25"}, {"price": "0.22", "size": "89.09"}, {"price": "0.23", "size": "47.82"}, {"price": "0.24", "size": "20"}, {"price": "0.25", "size": "180"}, {"price": "0.27", "size": "491.92"}, {"price": "0.28", "size": "3853.99"}, {"price": "0.29", "size": "224.77"}, {"price": "0.3", "size": "884.12"}], "asks": [{"price": "0.99", "size": "55310"}, {"price": "0.98", "size": "22000"}, {"price": "0.97", "size": "9.52"}, {"price": "0.96", "size": "250"}, {"price": "0.95", "size": "3300"}, {"price": "0.93", "size": "514.28"}, {"price": "0.92", "size": "4061"}, {"price": "0.89", "size": "417.09"}, {"price": "0.86", "size": "228.57"}, {"price": "0.85", "size": "325"}, {"price": "0.83", "size": "649.7"}, {"price": "0.79", "size": "123.8"}, {"price": "0.76", "size": "750"}, {"price": "0.75", "size": "250"}, {"price": "0.72", "size": "71.42"}, {"price": "0.7", "size": "300"}, {"price": "0.69", "size": "100"}, {"price": "0.66", "size": "50"}, {"price": "0.5", "size": "43.27"}, {"price": "0.49", "size": "91.48"}, {"price": "0.48", "size": "160"}, {"price": "0.4", "size": "21.66"}, {"price": "0.39", "size": "46.21"}, {"price": "0.38", "size": "27.04"}, {"price": "0.36", "size": "29.99"}, {"price": "0.33", "size": "102"}], "event_type": "book", "last_trade_price": "0.320"}, {"market": "0x4a8005d19b41af72c1cd5c619640d9d51da548dd7c3544b12ae0c520d9e6805b", "asset_id": "57920006811393570084962107679227395634282382525602277724728836928684998641754", "timestamp": "1769384222189", "hash": "3c7f11f0f755dae969058229a2caec8f2d7f1326", "bids": [{"price": "0.001", "size": "6107099.86"}, {"price": "0.002", "size": "91255.84"}, {"price": "0.003", "size": "1400"}, {"price": "0.004", "size": "11.53"}, {"price": "0.006", "size": "200"}, {"price": "0.01", "size": "2000"}, {"price": "0.011", "size": "50000"}, {"price": "0.012", "size": "9.31"}, {"price": "0.02", "size": "1000"}, {"price": "0.021", "size": "9000"}, {"price": "0.03", "size": "1000"}, {"price": "0.031", "size": "3000"}, {"price": "0.032", "size": "6.32"}, {"price": "0.041", "size": "3000"}, {"price": "0.05", "size": "330"}, {"price": "0.051", "size": "39"}, {"price": "0.062", "size": "15755"}, {"price": "0.07", "size": "300"}, {"price": "0.071", "size": "7.19"}, {"price": "0.1", "size": "360"}, {"price": "0.15", "size": "551.66"}, {"price": "0.19", "size": "418.42"}, {"price": "0.191", "size": "209"}, {"price": "0.192", "size": "5.79"}, {"price": "0.24", "size": "116.66"}, {"price": "0.251", "size": "900"}, {"price": "0.253", "size": "2372"}, {"price": "0.254", "size": "1652"}, {"price": "0.27", "size": "50"}, {"price": "0.29", "size": "89.65"}, {"price": "0.337", "size": "6716"}, {"price": "0.338", "size": "4839"}, {"price": "0.34", "size": "120.58"}, {"price": "0.341", "size": "60"}, {"price": "0.39", "size": "51.28"}, {"price": "0.454", "size": "1380"}, {"price": "0.613", "size": "3333"}, {"price": "0.75", "size": "1911.57"}, {"price": "0.797", "size": "50"}, {"price": "0.799", "size": "25"}, {"price": "0.8", "size": "20"}, {"price": "0.851", "size": "324.98"}, {"price": "0.909", "size": "324.99"}, {"price": "0.91", "size": "100"}, {"price": "0.943", "size": "254.46"}, {"price": "0.944", "size": "242"}, {"price": "0.947", "size": "200"}, {"price": "0.954", "size": "200"}, {"price": "0.955", "size": "7.33"}, {"price": "0.956", "size": "214.65"}], "asks": [{"price": "0.999", "size": "117664"}, {"price": "0.998", "size": "2175.74"}, {"price": "0.997", "size": "500"}, {"price": "0.996", "size": "257.22"}, {"price": "0.995", "size": "150"}, {"price": "0.994", "size": "701.87"}, {"price": "0.993", "size": "13.31"}, {"price": "0.99", "size": "100"}, {"price": "0.985", "size": "1050"}, {"price": "0.984", "size": "50"}, {"price": "0.983", "size": "5.72"}, {"price": "0.982", "size": "50"}, {"price": "0.98", "size": "102"}, {"price": "0.979", "size": "450"}, {"price": "0.977", "size": "814.47"}, {"price": "0.974", "size": "200"}, {"price": "0.973", "size": "1175"}, {"price": "0.972", "size": "471"}, {"price": "0.969", "size": "2.18"}, {"price": "0.968", "size": "25"}], "event_type": "book", "last_trade_price": ""}, {"market": "0xb77424a53b7480164118374fb5e97b859bd12b696b1aea55d383ce798c060cf4", "asset_id": "74987521271361072746264224488245891269775371028979674431826416209897741154003", "timestamp": "1769384416929", "hash": "be5b7aac99694616b3f28667d256bdb852fc60e0", "bids": [{"price": "0.001", "size": "11007099.86"}, {"price": "0.002", "size": "91255.83"}, {"price": "0.003", "size": "1400"}, {"price": "0.004", "size": "10.1"}, {"price": "0.006", "size": "200"}, {"price": "0.01", "size": "2000"}, {"price": "0.011", "size": "6.64"}, {"price": "0.02", "size": "1000"}, {"price": "0.023", "size": "51000"}, {"price": "0.024", "size": "6.23"}, {"price": "0.05", "size": "330"}, {"price": "0.051", "size": "39"}, {"price": "0.052", "size": "11.73"}, {"price": "0.09", "size": "700"}, {"price": "0.14", "size": "567.85"}, {"price": "0.19", "size": "418.42"}, {"price": "0.2", "size": "200"}, {"price": "0.201", "size": "2138"}, {"price": "0.202", "size": "5.49"}, {"price": "0.24", "size": "116.66"}, {"price": "0.261", "size": "5000"}, {"price": "0.262", "size": "5705"}, {"price": "0.263", "size": "4254"}, {"price": "0.27", "size": "50"}, {"price": "0.28", "size": "92.85"}, {"price": "0.33", "size": "72.72"}, {"price": "0.34", "size": "50"}, {"price": "0.38", "size": "52.63"}, {"price": "0.412", "size": "5555"}, {"price": "0.413", "size": "310"}, {"price": "0.414", "size": "5"}, {"price": "0.75", "size": "3572.81"}, {"price": "0.751", "size": "318.12"}, {"price": "0.752", "size": "30"}, {"price": "0.753", "size": "15"}, {"price": "0.787", "size": "10"}, {"price": "0.789", "size": "10"}, {"price": "0.79", "size": "20"}, {"price": "0.817", "size": "25"}, {"price": "0.818", "size": "25"}, {"price": "0.857", "size": "20"}, {"price": "0.874", "size": "9.41"}, {"price": "0.911", "size": "50"}, {"price": "0.921", "size": "36.1"}, {"price": "0.922", "size": "23"}, {"price": "0.924", "size": "25"}, {"price": "0.933", "size": "60"}, {"price": "0.934", "size": "5.09"}], "asks": [{"price": "0.999", "size": "43441"}, {"price": "0.998", "size": "1675.29"}, {"price": "0.997", "size": "835"}, {"price": "0.996", "size": "150"}, {"price": "0.995", "size": "82.27"}, {"price": "0.99", "size": "100"}, {"price": "0.989", "size": "8.33"}, {"price": "0.974", "size": "50"}, {"price": "0.973", "size": "705.15"}, {"price": "0.972", "size": "50"}, {"price": "0.967", "size": "69.6"}, {"price": "0.96", "size": "1125"}, {"price": "0.959", "size": "50"}, {"price": "0.958", "size": "78"}, {"price": "0.945", "size": "469.3"}, {"price": "0.944", "size": "32"}, {"price": "0.943", "size": "210"}, {"price": "0.942", "size": "224.9"}], "event_type": "book", "last_trade_price": "0.066"}, {"market": "0x08b39100a4d3d6ad1099e076fb69f781313c5b16975adf189d63542bd1ecca04", "asset_id": "48451126471681390564675828610810240762308720916091458567360242927144088567337", "timestamp": "1769384390065", "hash": "cb1041151226e632f526302ac0f2a0d674565fd1", "bids": [{"price": "0.001", "size": "1106973.31"}, {"price": "0.002", "size": "1255.83"}, {"price": "0.003", "size": "1400"}, {"price": "0.004", "size": "11.52"}, {"price": "0.006", "size": "200"}, {"price": "0.01", "size": "2000"}, {"price": "0.011", "size": "30000"}, {"price": "0.012", "size": "9.72"}, {"price": "0.02", "size": "1000"}, {"price": "0.021", "size": "6000"}, {"price": "0.032", "size": "56855"}, {"price": "0.033", "size": "5.93"}, {"price": "0.05", "size": "330"}, {"price": "0.051", "size": "39"}, {"price": "0.07", "size": "300"}, {"price": "0.071", "size": "7.64"}, {"price": "0.1", "size": "560"}, {"price": "0.15", "size": "551.66"}, {"price": "0.2", "size": "460"}, {"price": "0.201", "size": "5.37"}, {"price": "0.25", "size": "112"}, {"price": "0.29", "size": "89.65"}, {"price": "0.3", "size": "500"}, {"price": "0.34", "size": "70.58"}, {"price": "0.372", "size": "6716"}, {"price": "0.373", "size": "5078"}, {"price": "0.39", "size": "51.28"}, {"price": "0.391", "size": "138"}, {"price": "0.392", "size": "5"}, {"price": "0.689", "size": "197.36"}, {"price": "0.75", "size": "297.81"}, {"price": "0.751", "size": "292.45"}, {"price": "0.752", "size": "10"}, {"price": "0.759", "size": "25"}, {"price": "0.76", "size": "20"}, {"price": "0.85", "size": "263.75"}, {"price": "0.857", "size": "25"}, {"price": "0.858", "size": "25"}, {"price": "0.9", "size": "245"}, {"price": "0.945", "size": "57.88"}, {"price": "0.956", "size": "45.45"}, {"price": "0.967", "size": "293.47"}, {"price": "0.97", "size": "368.59"}, {"price": "0.971", "size": "237.42"}, {"price": "0.978", "size": "1422.79"}], "asks": [{"price": "0.999", "size": "12801"}, {"price": "0.998", "size": "11362.53"}, {"price": "0.997", "size": "500"}, {"price": "0.996", "size": "256.63"}, {"price": "0.995", "size": "393.75"}, {"price": "0.994", "size": "17.24"}, {"price": "0.988", "size": "55.94"}, {"price": "0.983", "size": "2309.3"}, {"price": "0.982", "size": "1494.03"}], "event_type": "book", "last_trade_price": ""}, {"market": "0x602a7a6c7d65b55932e6cf8b6904cb7acdc728ca423ffd3ccb1988dd5501de13", "asset_id": "88770632741686298370270294037614812817595949782311984579833554458717957886356", "timestamp": "1769384286642", "hash": "1afbd4940277a02933e244136e62657f1d545d57", "bids": [{"price": "0.001", "size": "116664"}, {"price": "0.002", "size": "2552.91"}, {"price": "0.003", "size": "500"}, {"price": "0.004", "size": "23.26"}, {"price": "0.011", "size": "1000"}, {"price": "0.013", "size": "5115.08"}, {"price": "0.016", "size": "250"}, {"price": "0.017", "size": "294.11"}, {"price": "0.018", "size": "9.93"}, {"price": "0.026", "size": "192.3"}, {"price": "0.038", "size": "1110"}, {"price": "0.039", "size": "280"}, {"price": "0.04", "size": "125"}, {"price": "0.041", "size": "129.8"}, {"price": "0.042", "size": "10"}, {"price": "0.046", "size": "39.3"}, {"price": "0.047", "size": "117.3"}, {"price": "0.048", "size": "46.15"}], "asks": [{"price": "0.999", "size": "11007382.8"}, {"price": "0.998", "size": "91255.83"}, {"price": "0.997", "size": "1400"}, {"price": "0.996", "size": "10.09"}, {"price": "0.994", "size": "200"}, {"price": "0.99", "size": "2000"}, {"price": "0.989", "size": "5.13"}, {"price": "0.98", "size": "2000"}, {"price": "0.979", "size": "12.92"}, {"price": "0.95", "size": "330"}, {"price": "0.949", "size": "39"}, {"price": "0.93", "size": "300"}, {"price": "0.929", "size": "7.14"}, {"price": "0.9", "size": "560"}, {"price": "0.898", "size": "12000"}, {"price": "0.896", "size": "11111"}, {"price": "0.86", "size": "567.85"}, {"price": "0.81", "size": "418.42"}, {"price": "0.809", "size": "209"}, {"price": "0.808", "size": "5.76"}, {"price": "0.76", "size": "166.66"}, {"price": "0.71", "size": "89.65"}, {"price": "0.703", "size": "4150"}, {"price": "0.702", "size": "1408"}, {"price": "0.67", "size": "72.72"}, {"price": "0.65", "size": "4050"}, {"price": "0.649", "size": "4672"}, {"price": "0.648", "size": "300"}, {"price": "0.62", "size": "52.63"}, {"price": "0.571", "size": "1458"}, {"price": "0.57", "size": "5"}, {"price": "0.3", "size": "280"}, {"price": "0.25", "size": "3307.41"}, {"price": "0.249", "size": "110"}, {"price": "0.243", "size": "10"}, {"price": "0.241", "size": "25"}, {"price": "0.24", "size": "20"}, {"price": "0.174", "size": "25"}, {"price": "0.173", "size": "25"}, {"price": "0.098", "size": "424.7"}, {"price": "0.073", "size": "250"}, {"price": "0.068", "size": "35.7"}, {"price": "0.062", "size": "27.71"}, {"price": "0.06", "size": "237.71"}, {"price": "0.059", "size": "9"}], "event_type": "book", "last_trade_price": "0.052"}, {"market": "0x3f9f68feccc892303834833665bf204632438b028254fc2d5bceea757ff61ed3", "asset_id": "36088399593046466421453063228085042771351246231742717370399696243183381174466", "timestamp": "1769384417512", "hash": "96dbef58d4eac9630664ea4beae8b428f0ed5f7d", "bids": [{"price": "0.001", "size": "17774"}, {"price": "0.002", "size": "1675.54"}, {"price": "0.003", "size": "500"}, {"price": "0.004", "size": "18.61"}, {"price": "0.01", "size": "100"}, {"price": "0.011", "size": "1000"}, {"price": "0.012", "size": "13.08"}, {"price": "0.018", "size": "1822.44"}, {"price": "0.02", "size": "400"}, {"price": "0.021", "size": "200"}, {"price": "0.022", "size": "148.6"}, {"price": "0.03", "size": "45.95"}, {"price": "0.032", "size": "1000"}, {"price": "0.033", "size": "272"}, {"price": "0.034", "size": "151.46"}], "asks": [{"price": "0.999", "size": "3871.64"}, {"price": "0.998", "size": "1255.84"}, {"price": "0.997", "size": "1400"}, {"price": "0.996", "size": "10.11"}, {"price": "0.994", "size": "200"}, {"price": "0.99", "size": "515300"}, {"price": "0.989", "size": "11.63"}, {"price": "0.98", "size": "1000"}, {"price": "0.97", "size": "12000"}, {"price": "0.967", "size": "45444"}, {"price": "0.966", "size": "5.6"}, {"price": "0.95", "size": "330"}, {"price": "0.949", "size": "39"}, {"price": "0.93", "size": "300"}, {"price": "0.929", "size": "7.14"}, {"price": "0.9", "size": "560"}, {"price": "0.86", "size": "567.85"}, {"price": "0.81", "size": "418.42"}, {"price": "0.809", "size": "5.84"}, {"price": "0.76", "size": "116.66"}, {"price": "0.759", "size": "5755"}, {"price": "0.757", "size": "51.07"}, {"price": "0.73", "size": "50"}, {"price": "0.71", "size": "89.65"}, {"price": "0.66", "size": "70.58"}, {"price": "0.62", "size": "52.63"}, {"price": "0.601", "size": "3518"}, {"price": "0.6", "size": "134"}, {"price": "0.599", "size": "207"}, {"price": "0.593", "size": "5"}, {"price": "0.592", "size": "10"}, {"price": "0.232", "size": "161"}, {"price": "0.23", "size": "25"}, {"price": "0.229", "size": "15"}, {"price": "0.199", "size": "25"}, {"price": "0.197", "size": "10"}, {"price": "0.196", "size": "20"}, {"price": "0.149", "size": "246.11"}, {"price": "0.119", "size": "128.45"}, {"price": "0.118", "size": "250.45"}, {"price": "0.117", "size": "83.2"}, {"price": "0.116", "size": "30"}, {"price": "0.115", "size": "33.67"}, {"price": "0.113", "size": "31.57"}, {"price": "0.112", "size": "45"}], "event_type": "book", "last_trade_price": ""}, {"market": "0xa281783fc73b1a6927a301ee34cd90795470dc64b500673e445ba5e54f697c09", "asset_id": "19470872781622450446330627562106312915240544924539183504885686468325701819521", "timestamp": "1769384430427", "hash": "a421cc931299c2493a1845372cd1dff469e6da55", "bids": [{"price": "0.001", "size": "117628"}, {"price": "0.002", "size": "2166"}, {"price": "0.003", "size": "508.52"}, {"price": "0.005", "size": "150"}, {"price": "0.006", "size": "75"}, {"price": "0.007", "size": "6.22"}, {"price": "0.01", "size": "50"}, {"price": "0.011", "size": "50"}, {"price": "0.013", "size": "50"}, {"price": "0.014", "size": "15.47"}, {"price": "0.031", "size": "15"}, {"price": "0.035", "size": "555.79"}, {"price": "0.036", "size": "50"}, {"price": "0.05", "size": "50"}, {"price": "0.053", "size": "200"}, {"price": "0.054", "size": "10"}, {"price": "0.055", "size": "338.53"}, {"price": "0.057", "size": "416.14"}], "asks": [{"price": "0.999", "size": "11007099.85"}, {"price": "0.998", "size": "91255.83"}, {"price": "0.997", "size": "1400"}, {"price": "0.996", "size": "10.09"}, {"price": "0.994", "size": "200"}, {"price": "0.99", "size": "2000"}, {"price": "0.989", "size": "7.14"}, {"price": "0.98", "size": "1000"}, {"price": "0.979", "size": "41000"}, {"price": "0.978", "size": "10"}, {"price": "0.976", "size": "33333"}, {"price": "0.975", "size": "5.61"}, {"price": "0.95", "size": "330"}, {"price": "0.949", "size": "39"}, {"price": "0.948", "size": "11.65"}, {"price": "0.91", "size": "700"}, {"price": "0.86", "size": "567.85"}, {"price": "0.81", "size": "418.42"}, {"price": "0.809", "size": "209"}, {"price": "0.808", "size": "5.82"}, {"price": "0.76", "size": "116.66"}, {"price": "0.747", "size": "5000"}, {"price": "0.741", "size": "5575"}, {"price": "0.74", "size": "1614"}, {"price": "0.739", "size": "300"}, {"price": "0.73", "size": "50"}, {"price": "0.72", "size": "92.85"}, {"price": "0.67", "size": "72.72"}, {"price": "0.62", "size": "177.63"}, {"price": "0.619", "size": "25"}, {"price": "0.487", "size": "2222"}, {"price": "0.486", "size": "5"}, {"price": "0.485", "size": "25"}, {"price": "0.484", "size": "20"}, {"price": "0.18", "size": "2072.3"}, {"price": "0.179", "size": "317.55"}, {"price": "0.178", "size": "222.23"}, {"price": "0.177", "size": "16.66"}, {"price": "0.176", "size": "25"}, {"price": "0.142", "size": "20"}, {"price": "0.088", "size": "75.85"}, {"price": "0.087", "size": "75"}, {"price": "0.086", "size": "6.32"}, {"price": "0.085", "size": "24.63"}], "event_type": "book", "last_trade_price": "0.057"}, {"market": "0x08b39100a4d3d6ad1099e076fb69f781313c5b16975adf189d63542bd1ecca04", "asset_id": "6122912536415539457721068960901205060237919057489564846781206253065694717085", "timestamp": "1769384390065", "hash": "f3d8dc71dae9d590bbf08fecb408adb2077f099f", "bids": [{"price": "0.001", "size": "12801"}, {"price": "0.002", "size": "11362.53"}, {"price": "0.003", "size": "500"}, {"price": "0.004", "size": "256.63"}, {"price": "0.005", "size": "393.75"}, {"price": "0.006", "size": "17.24"}, {"price": "0.012", "size": "55.94"}, {"price": "0.017", "size": "2309.3"}, {"price": "0.018", "size": "1494.03"}], "asks": [{"price": "0.999", "size": "1106973.31"}, {"price": "0.998", "size": "1255.83"}, {"price": "0.997", "size": "1400"}, {"price": "0.996", "size": "11.52"}, {"price": "0.994", "size": "200"}, {"price": "0.99", "size": "2000"}, {"price": "0.989", "size": "30000"}, {"price": "0.988", "size": "9.72"}, {"price": "0.98", "size": "1000"}, {"price": "0.979", "size": "6000"}, {"price": "0.968", "size": "56855"}, {"price": "0.967", "size": "5.93"}, {"price": "0.95", "size": "330"}, {"price": "0.949", "size": "39"}, {"price": "0.93", "size": "300"}, {"price": "0.929", "size": "7.64"}, {"price": "0.9", "size": "560"}, {"price": "0.85", "size": "551.66"}, {"price": "0.8", "size": "460"}, {"price": "0.799", "size": "5.37"}, {"price": "0.75", "size": "112"}, {"price": "0.71", "size": "89.65"}, {"price": "0.7", "size": "500"}, {"price": "0.66", "size": "70.58"}, {"price": "0.628", "size": "6716"}, {"price": "0.627", "size": "5078"}, {"price": "0.61", "size": "51.28"}, {"price": "0.609", "size": "138"}, {"price": "0.608", "size": "5"}, {"price": "0.311", "size": "197.36"}, {"price": "0.25", "size": "297.81"}, {"price": "0.249", "size": "292.45"}, {"price": "0.248", "size": "10"}, {"price": "0.241", "size": "25"}, {"price": "0.24", "size": "20"}, {"price": "0.15", "size": "263.75"}, {"price": "0.143", "size": "25"}, {"price": "0.142", "size": "25"}, {"price": "0.1", "size": "245"}, {"price": "0.055", "size": "57.88"}, {"price": "0.044", "size": "45.45"}, {"price": "0.033", "size": "293.47"}, {"price": "0.03", "size": "368.59"}, {"price": "0.029", "size": "237.42"}, {"price": "0.022", "size": "1422.79"}], "event_type": "book", "last_trade_price": ""}, {"market": "0x3f9f68feccc892303834833665bf204632438b028254fc2d5bceea757ff61ed3", "asset_id": "11947171408899503371980811142475369274013053223377767646204433492871687017998", "timestamp": "1769384417512", "hash": "36e7309c831cc7d260f0eebe9c597c75e398fab8", "bids": [{"price": "0.001", "size": "3871.64"}, {"price": "0.002", "size": "1255.84"}, {"price": "0.003", "size": "1400"}, {"price": "0.004", "size": "10.11"}, {"price": "0.006", "size": "200"}, {"price": "0.01", "size": "515300"}, {"price": "0.011", "size": "11.63"}, {"price": "0.02", "size": "1000"}, {"price": "0.03", "size": "12000"}, {"price": "0.033", "size": "45444"}, {"price": "0.034", "size": "5.6"}, {"price": "0.05", "size": "330"}, {"price": "0.051", "size": "39"}, {"price": "0.07", "size": "300"}, {"price": "0.071", "size": "7.14"}, {"price": "0.1", "size": "560"}, {"price": "0.14", "size": "567.85"}, {"price": "0.19", "size": "418.42"}, {"price": "0.191", "size": "5.84"}, {"price": "0.24", "size": "116.66"}, {"price": "0.241", "size": "5755"}, {"price": "0.243", "size": "51.07"}, {"price": "0.27", "size": "50"}, {"price": "0.29", "size": "89.65"}, {"price": "0.34", "size": "70.58"}, {"price": "0.38", "size": "52.63"}, {"price": "0.399", "size": "3518"}, {"price": "0.4", "size": "134"}, {"price": "0.401", "size": "207"}, {"price": "0.407", "size": "5"}, {"price": "0.408", "size": "10"}, {"price": "0.768", "size": "161"}, {"price": "0.77", "size": "25"}, {"price": "0.771", "size": "15"}, {"price": "0.801", "size": "25"}, {"price": "0.803", "size": "10"}, {"price": "0.804", "size": "20"}, {"price": "0.851", "size": "246.11"}, {"price": "0.881", "size": "128.45"}, {"price": "0.882", "size": "250.45"}, {"price": "0.883", "size": "83.2"}, {"price": "0.884", "size": "30"}, {"price": "0.885", "size": "33.67"}, {"price": "0.887", "size": "31.57"}, {"price": "0.888", "size": "45"}], "asks": [{"price": "0.999", "size": "17774"}, {"price": "0.998", "size": "1675.54"}, {"price": "0.997", "size": "500"}, {"price": "0.996", "size": "18.61"}, {"price": "0.99", "size": "100"}, {"price": "0.989", "size": "1000"}, {"price": "0.988", "size": "13.08"}, {"price": "0.982", "size": "1822.44"}, {"price": "0.98", "size": "400"}, {"price": "0.979", "size": "200"}, {"price": "0.978", "size": "148.6"}, {"price": "0.97", "size": "45.95"}, {"price": "0.968", "size": "1000"}, {"price": "0.967", "size": "272"}, {"price": "0.966", "size": "151.46"}], "event_type": "book", "last_trade_price": ""}, {"market": "0x4a8005d19b41af72c1cd5c619640d9d51da548dd7c3544b12ae0c520d9e6805b", "asset_id": "42493289531592820306292191064557160874552640520793925047778017979799601355649", "timestamp": "1769384222189", "hash": "4b6b31da5a608e63eef78ad4846dbe1d98d8f8f7", "bids": [{"price": "0.001", "size": "117664"}, {"price": "0.002", "size": "2175.74"}, {"price": "0.003", "size": "500"}, {"price": "0.004", "size": "257.22"}, {"price": "0.005", "size": "150"}, {"price": "0.006", "size": "701.87"}, {"price": "0.007", "size": "13.31"}, {"price": "0.01", "size": "100"}, {"price": "0.015", "size": "1050"}, {"price": "0.016", "size": "50"}, {"price": "0.017", "size": "5.72"}, {"price": "0.018", "size": "50"}, {"price": "0.02", "size": "102"}, {"price": "0.021", "size": "450"}, {"price": "0.023", "size": "814.47"}, {"price": "0.026", "size": "200"}, {"price": "0.027", "size": "1175"}, {"price": "0.028", "size": "471"}, {"price": "0.031", "size": "2.18"}, {"price": "0.032", "size": "25"}], "asks": [{"price": "0.999", "size": "6107099.86"}, {"price": "0.998", "size": "91255.84"}, {"price": "0.997", "size": "1400"}, {"price": "0.996", "size": "11.53"}, {"price": "0.994", "size": "200"}, {"price": "0.99", "size": "2000"}, {"price": "0.989", "size": "50000"}, {"price": "0.988", "size": "9.31"}, {"price": "0.98", "size": "1000"}, {"price": "0.979", "size": "9000"}, {"price": "0.97", "size": "1000"}, {"price": "0.969", "size": "3000"}, {"price": "0.968", "size": "6.32"}, {"price": "0.959", "size": "3000"}, {"price": "0.95", "size": "330"}, {"price": "0.949", "size": "39"}, {"price": "0.938", "size": "15755"}, {"price": "0.93", "size": "300"}, {"price": "0.929", "size": "7.19"}, {"price": "0.9", "size": "360"}, {"price": "0.85", "size": "551.66"}, {"price": "0.81", "size": "418.42"}, {"price": "0.809", "size": "209"}, {"price": "0.808", "size": "5.79"}, {"price": "0.76", "size": "116.66"}, {"price": "0.749", "size": "900"}, {"price": "0.747", "size": "2372"}, {"price": "0.746", "size": "1652"}, {"price": "0.73", "size": "50"}, {"price": "0.71", "size": "89.65"}, {"price": "0.663", "size": "6716"}, {"price": "0.662", "size": "4839"}, {"price": "0.66", "size": "120.58"}, {"price": "0.659", "size": "60"}, {"price": "0.61", "size": "51.28"}, {"price": "0.546", "size": "1380"}, {"price": "0.387", "size": "3333"}, {"price": "0.25", "size": "1911.57"}, {"price": "0.203", "size": "50"}, {"price": "0.201", "size": "25"}, {"price": "0.2", "size": "20"}, {"price": "0.149", "size": "324.98"}, {"price": "0.091", "size": "324.99"}, {"price": "0.09", "size": "100"}, {"price": "0.057", "size": "254.46"}, {"price": "0.056", "size": "242"}, {"price": "0.053", "size": "200"}, {"price": "0.046", "size": "200"}, {"price": "0.045", "size": "7.33"}, {"price": "0.044", "size": "214.65"}], "event_type": "book", "last_trade_price": ""}, {"market": "0xb77424a53b7480164118374fb5e97b859bd12b696b1aea55d383ce798c060cf4", "asset_id": "86904220753614324927759730619985568200215013704321476651673438801320577270597", "timestamp": "1769384416929", "hash": "1eba4988f15bb0df5d777c7c53a705d678ee38c4", "bids": [{"price": "0.001", "size": "43441"}, {"price": "0.002", "size": "1675.29"}, {"price": "0.003", "size": "835"}, {"price": "0.004", "size": "150"}, {"price": "0.005", "size": "82.27"}, {"price": "0.01", "size": "100"}, {"price": "0.011", "size": "8.33"}, {"price": "0.026", "size": "50"}, {"price": "0.027", "size": "705.15"}, {"price": "0.028", "size": "50"}, {"price": "0.033", "size": "69.6"}, {"price": "0.04", "size": "1125"}, {"price": "0.041", "size": "50"}, {"price": "0.042", "size": "78"}, {"price": "0.055", "size": "469.3"}, {"price": "0.056", "size": "32"}, {"price": "0.057", "size": "210"}, {"price": "0.058", "size": "224.9"}], "asks": [{"price": "0.999", "size": "11007099.86"}, {"price": "0.998", "size": "91255.83"}, {"price": "0.997", "size": "1400"}, {"price": "0.996", "size": "10.1"}, {"price": "0.994", "size": "200"}, {"price": "0.99", "size": "2000"}, {"price": "0.989", "size": "6.64"}, {"price": "0.98", "size": "1000"}, {"price": "0.977", "size": "51000"}, {"price": "0.976", "size": "6.23"}, {"price": "0.95", "size": "330"}, {"price": "0.949", "size": "39"}, {"price": "0.948", "size": "11.73"}, {"price": "0.91", "size": "700"}, {"price": "0.86", "size": "567.85"}, {"price": "0.81", "size": "418.42"}, {"price": "0.8", "size": "200"}, {"price": "0.799", "size": "2138"}, {"price": "0.798", "size": "5.49"}, {"price": "0.76", "size": "116.66"}, {"price": "0.739", "size": "5000"}, {"price": "0.738", "size": "5705"}, {"price": "0.737", "size": "4254"}, {"price": "0.73", "size": "50"}, {"price": "0.72", "size": "92.85"}, {"price": "0.67", "size": "72.72"}, {"price": "0.66", "size": "50"}, {"price": "0.62", "size": "52.63"}, {"price": "0.588", "size": "5555"}, {"price": "0.587", "size": "310"}, {"price": "0.586", "size": "5"}, {"price": "0.25", "size": "3572.81"}, {"price": "0.249", "size": "318.12"}, {"price": "0.248", "size": "30"}, {"price": "0.247", "size": "15"}, {"price": "0.213", "size": "10"}, {"price": "0.211", "size": "10"}, {"price": "0.21", "size": "20"}, {"price": "0.183", "size": "25"}, {"price": "0.182", "size": "25"}, {"price": "0.143", "size": "20"}, {"price": "0.126", "size": "9.41"}, {"price": "0.089", "size": "50"}, {"price": "0.079", "size": "36.1"}, {"price": "0.078", "size": "23"}, {"price": "0.076", "size": "25"}, {"price": "0.067", "size": "60"}, {"price": "0.066", "size": "5.09"}], "event_type": "book", "last_trade_price": "0.066"}, {"market": "0x602a7a6c7d65b55932e6cf8b6904cb7acdc728ca423ffd3ccb1988dd5501de13", "asset_id": "18399565751068676179945656979762090460558422925963909399757895217338947077684", "timestamp": "1769384286642", "hash": "dbd4c4b2fdd62ae7aa6704c954434ded7093256b", "bids": [{"price": "0.001", "size": "11007382.8"}, {"price": "0.002", "size": "91255.83"}, {"price": "0.003", "size": "1400"}, {"price": "0.004", "size": "10.09"}, {"price": "0.006", "size": "200"}, {"price": "0.01", "size": "2000"}, {"price": "0.011", "size": "5.13"}, {"price": "0.02", "size": "2000"}, {"price": "0.021", "size": "12.92"}, {"price": "0.05", "size": "330"}, {"price": "0.051", "size": "39"}, {"price": "0.07", "size": "300"}, {"price": "0.071", "size": "7.14"}, {"price": "0.1", "size": "560"}, {"price": "0.102", "size": "12000"}, {"price": "0.104", "size": "11111"}, {"price": "0.14", "size": "567.85"}, {"price": "0.19", "size": "418.42"}, {"price": "0.191", "size": "209"}, {"price": "0.192", "size": "5.76"}, {"price": "0.24", "size": "166.66"}, {"price": "0.29", "size": "89.65"}, {"price": "0.297", "size": "4150"}, {"price": "0.298", "size": "1408"}, {"price": "0.33", "size": "72.72"}, {"price": "0.35", "size": "4050"}, {"price": "0.351", "size": "4672"}, {"price": "0.352", "size": "300"}, {"price": "0.38", "size": "52.63"}, {"price": "0.429", "size": "1458"}, {"price": "0.43", "size": "5"}, {"price": "0.7", "size": "280"}, {"price": "0.75", "size": "3307.41"}, {"price": "0.751", "size": "110"}, {"price": "0.757", "size": "10"}, {"price": "0.759", "size": "25"}, {"price": "0.76", "size": "20"}, {"price": "0.826", "size": "25"}, {"price": "0.827", "size": "25"}, {"price": "0.902", "size": "424.7"}, {"price": "0.927", "size": "250"}, {"price": "0.932", "size": "35.7"}, {"price": "0.938", "size": "27.71"}, {"price": "0.94", "size": "237.71"}, {"price": "0.941", "size": "9"}], "asks": [{"price": "0.999", "size": "116664"}, {"price": "0.998", "size": "2552.91"}, {"price": "0.997", "size": "500"}, {"price": "0.996", "size": "23.26"}, {"price": "0.989", "size": "1000"}, {"price": "0.987", "size": "5115.08"}, {"price": "0.984", "size": "250"}, {"price": "0.983", "size": "294.11"}, {"price": "0.982", "size": "9.93"}, {"price": "0.974", "size": "192.3"}, {"price": "0.962", "size": "1110"}, {"price": "0.961", "size": "280"}, {"price": "0.96", "size": "125"}, {"price": "0.959", "size": "129.8"}, {"price": "0.958", "size": "10"}, {"price": "0.954", "size": "39.3"}, {"price": "0.953", "size": "117.3"}, {"price": "0.952", "size": "46.15"}], "event_type": "book", "last_trade_price": "0.052"}]}
{"_local_timestamp": "2026-01-25T23:40:39.574719+00:00", "data": {"market": "0x3849e1d62e0807801913d3e2427e8caf3cc6dd1c8ef42d8d5c08c6f9c449dc5e", "price_changes": [{"asset_id": "56615676606297588259337956203332341775475048285080710344367729433788967812170", "price": "0.15", "size": "3123", "side": "BUY", "hash": "62ef53adf396c411d1bf22804b7ad84ef80a537b", "best_bid": "0.67", "best_ask": "0.7"}, {"asset_id": "8070607953656787024050950499598687532281829563384949938603247089607814583142", "price": "0.85", "size": "3123", "side": "SELL", "hash": "013fa63468caa306b7873f247c4c83fa7f1569e4", "best_bid": "0.3", "best_ask": "0.33"}], "timestamp": "1769384439508", "event_type": "price_change"}}
{"_local_timestamp": "2026-01-25T23:40:39.801885+00:00", "data": {"market": "0x3f9f68feccc892303834833665bf204632438b028254fc2d5bceea757ff61ed3", "price_changes": [{"asset_id": "11947171408899503371980811142475369274013053223377767646204433492871687017998", "price": "0.408", "size": "0", "side": "BUY", "hash": "c435e200c74121b3272f8913b6fd24584e649a4c", "best_bid": "0.888", "best_ask": "0.966"}, {"asset_id": "36088399593046466421453063228085042771351246231742717370399696243183381174466", "price": "0.592", "size": "0", "side": "SELL", "hash": "32832a1418eba2a4ccd0ad876ca8f22bb36bf347", "best_bid": "0.034", "best_ask": "0.112"}], "timestamp": "1769384439729", "event_type": "price_change"}}
{"_local_timestamp": "2026-01-25T23:40:40.102373+00:00", "data": {"market": "0x3f9f68feccc892303834833665bf204632438b028254fc2d5bceea757ff61ed3", "price_changes": [{"asset_id": "11947171408899503371980811142475369274013053223377767646204433492871687017998", "price": "0.408", "size": "10", "side": "BUY", "hash": "fc7044cb1140b8ac66fa277452a989efe34ac5cd", "best_bid": "0.888", "best_ask": "0.966"}, {"asset_id": "36088399593046466421453063228085042771351246231742717370399696243183381174466", "price": "0.592", "size": "10", "side": "SELL", "hash": "6f2a03917efd3c0b0eff368ca592c4445b330c69", "best_bid": "0.034", "best_ask": "0.112"}], "timestamp": "1769384440033", "event_type": "price_change"}}
{"_local_timestamp": "2026-01-25T23:40:40.433150+00:00", "data": {"market": "0x3849e1d62e0807801913d3e2427e8caf3cc6dd1c8ef42d8d5c08c6f9c449dc5e", "price_changes": [{"asset_id": "56615676606297588259337956203332341775475048285080710344367729433788967812170", "price": "0.15", "size": "2998", "side": "BUY", "hash": "62adb15ad2de365a538b2cbcfc43b85642e3228a", "best_bid": "0.67", "best_ask": "0.7"}, {"asset_id": "8070607953656787024050950499598687532281829563384949938603247089607814583142", "price": "0.85", "size": "2998", "side": "SELL", "hash": "a3681436572e6abbef88d6c539517082bc108d8f", "best_bid": "0.3", "best_ask": "0.33"}], "timestamp": "1769384440254", "event_type": "price_change"}}
{"_local_timestamp": "2026-01-25T23:40:40.484013+00:00", "data": {"market": "0x3849e1d62e0807801913d3e2427e8caf3cc6dd1c8ef42d8d5c08c6f9c449dc5e", "price_changes": [{"asset_id": "56615676606297588259337956203332341775475048285080710344367729433788967812170", "price": "0.17", "size": "549.7", "side": "BUY", "hash": "62adb15ad2de365a538b2cbcfc43b85642e3228a", "best_bid": "0.67", "best_ask": "0.7"}, {"asset_id": "8070607953656787024050950499598687532281829563384949938603247089607814583142", "price": "0.83", "size": "549.7", "side": "SELL", "hash": "a3681436572e6abbef88d6c539517082bc108d8f", "best_bid": "0.3", "best_ask": "0.33"}], "timestamp": "1769384440254", "event_type": "price_change"}}
{"_local_timestamp": "2026-01-25T23:40:40.770140+00:00", "data": {"market": "0x3849e1d62e0807801913d3e2427e8caf3cc6dd1c8ef42d8d5c08c6f9c449dc5e", "price_changes": [{"asset_id": "56615676606297588259337956203332341775475048285080710344367729433788967812170", "price": "0.11", "size": "542.09", "side": "BUY", "hash": "60173f52d0b32e5440831c36f5dbdf104efd4015", "best_bid": "0.67", "best_ask": "0.7"}, {"asset_id": "8070607953656787024050950499598687532281829563384949938603247089607814583142", "price": "0.89", "size": "542.09", "side": "SELL", "hash": "ebcd53c9c1ca01f4d7fd39ef6081487f8a4e3cf5", "best_bid": "0.3", "best_ask": "0.33"}], "timestamp": "1769384440574", "event_type": "price_change"}}
{"_local_timestamp": "2026-01-25T23:40:40.834339+00:00", "data": {"market": "0x3849e1d62e0807801913d3e2427e8caf3cc6dd1c8ef42d8d5c08c6f9c449dc5e", "price_changes": [{"asset_id": "56615676606297588259337956203332341775475048285080710344367729433788967812170", "price": "0.16", "size": "100", "side": "BUY", "hash": "a426d704971c0ef79213ded924593cba0370ef06", "best_bid": "0.67", "best_ask": "0.7"}, {"asset_id": "8070607953656787024050950499598687532281829563384949938603247089607814583142", "price": "0.84", "size": "100", "side": "SELL", "hash": "1ef37ddd7e8515fbff001a4315a4436ebc5d28cb", "best_bid": "0.3", "best_ask": "0.33"}], "timestamp": "1769384440632", "event_type": "price_change"}}
{"_local_timestamp": "2026-01-25T23:40:44.410357+00:00", "data": {"market": "0x3f9f68feccc892303834833665bf204632438b028254fc2d5bceea757ff61ed3", "price_changes": [{"asset_id": "36088399593046466421453063228085042771351246231742717370399696243183381174466", "price": "0.113", "size": "0", "side": "SELL", "hash": "8fdaf1969cad610e47cb27d171b4ccaad0b4a90f", "best_bid": "0.034", "best_ask": "0.112"}, {"asset_id": "11947171408899503371980811142475369274013053223377767646204433492871687017998", "price": "0.887", "size": "0", "side": "BUY", "hash": "784059e34c499fe278b5ca8d62c512b4725230cc", "best_bid": "0.888", "best_ask": "0.966"}], "timestamp": "1769384444341", "event_type": "price_change"}}
{"_local_timestamp": "2026-01-25T23:40:45.484124+00:00", "data": {"market": "0x3f9f68feccc892303834833665bf204632438b028254fc2d5bceea757ff61ed3", "price_changes": [{"asset_id": "36088399593046466421453063228085042771351246231742717370399696243183381174466", "price": "0.111", "size": "31.57", "side": "SELL", "hash": "7b7c4abe3549f94b657c31d38096af4a7016101c", "best_bid": "0.034", "best_ask": "0.111"}, {"asset_id": "11947171408899503371980811142475369274013053223377767646204433492871687017998", "price": "0.889", "size": "31.57", "side": "BUY", "hash": "1ec842b781d8e6d3f70e4f70a25a57582d757503", "best_bid": "0.889", "best_ask": "0.966"}], "timestamp": "1769384445413", "event_type": "price_change"}}
{"_local_timestamp": "2026-01-25T23:40:56.625612+00:00", "data": {"market": "0x3849e1d62e0807801913d3e2427e8caf3cc6dd1c8ef42d8d5c08c6f9c449dc5e", "price_changes": [{"asset_id": "8070607953656787024050950499598687532281829563384949938603247089607814583142", "price": "0.45", "size": "36.25", "side": "SELL", "hash": "c77d1faac9bb261ba842c6c62279db577a1e37c3", "best_bid": "0.3", "best_ask": "0.33"}, {"asset_id": "56615676606297588259337956203332341775475048285080710344367729433788967812170", "price": "0.55", "size": "36.25", "side": "BUY", "hash": "4916d057445030d82f0e83fbbd06e6a72e8ddfb9", "best_bid": "0.67", "best_ask": "0.7"}], "timestamp": "1769384456551", "event_type": "price_change"}}
{"_local_timestamp": "2026-01-25T23:40:56.933298+00:00", "data": {"market": "0x4a8005d19b41af72c1cd5c619640d9d51da548dd7c3544b12ae0c520d9e6805b", "price_changes": [{"asset_id": "57920006811393570084962107679227395634282382525602277724728836928684998641754", "price": "0.751", "size": "10", "side": "BUY", "hash": "8e8f6cae6cb4337a012c22f54db90374b26723a4", "best_bid": "0.956", "best_ask": "0.968"}, {"asset_id": "42493289531592820306292191064557160874552640520793925047778017979799601355649", "price": "0.249", "size": "10", "side": "SELL", "hash": "f5f73554882ca35e74856ec9ea95880f07b056b2", "best_bid": "0.032", "best_ask": "0.044"}], "timestamp": "1769384456859", "event_type": "price_change"}}
{"_local_timestamp": "2026-01-25T23:41:03.256435+00:00", "data": {"market": "0xb77424a53b7480164118374fb5e97b859bd12b696b1aea55d383ce798c060cf4", "price_changes": [{"asset_id": "86904220753614324927759730619985568200215013704321476651673438801320577270597", "price": "0.067", "size": "10", "side": "SELL", "hash": "a738e330bcca7780c89b9ca1143c41c3941b87b8", "best_bid": "0.058", "best_ask": "0.066"}, {"asset_id": "74987521271361072746264224488245891269775371028979674431826416209897741154003", "price": "0.933", "size": "10", "side": "BUY", "hash": "20707947fe2cf18dbe2e80f69fd7cd9fdd348b61", "best_bid": "0.934", "best_ask": "0.942"}], "timestamp": "1769384463188", "event_type": "price_change"}}
{"_local_timestamp": "2026-01-25T23:41:03.260659+00:00", "data": {"market": "0xb77424a53b7480164118374fb5e97b859bd12b696b1aea55d383ce798c060cf4", "price_changes": [{"asset_id": "86904220753614324927759730619985568200215013704321476651673438801320577270597", "price": "0.058", "size": "174.9", "side": "BUY", "hash": "a738e330bcca7780c89b9ca1143c41c3941b87b8", "best_bid": "0.058", "best_ask": "0.066"}, {"asset_id": "74987521271361072746264224488245891269775371028979674431826416209897741154003", "price": "0.942", "size": "174.9", "side": "SELL", "hash": "20707947fe2cf18dbe2e80f69fd7cd9fdd348b61", "best_bid": "0.934", "best_ask": "0.942"}], "timestamp": "1769384463188", "event_type": "price_change"}}
{"_local_timestamp": "2026-01-25T23:41:03.288388+00:00", "data": {"market": "0xb77424a53b7480164118374fb5e97b859bd12b696b1aea55d383ce798c060cf4", "price_changes": [{"asset_id": "86904220753614324927759730619985568200215013704321476651673438801320577270597", "price": "0.067", "size": "60", "side": "SELL", "hash": "d993864c39b59dbd1724f3808b362cd886a2afc9", "best_bid": "0.058", "best_ask": "0.066"}, {"asset_id": "74987521271361072746264224488245891269775371028979674431826416209897741154003", "price": "0.933", "size": "60", "side": "BUY", "hash": "75b0b3f5d1a439b717371494388caa876af8a442", "best_bid": "0.934", "best_ask": "0.942"}], "timestamp": "1769384463212", "event_type": "price_change"}}
{"_local_timestamp": "2026-01-25T23:41:03.299275+00:00", "data": {"market": "0xa281783fc73b1a6927a301ee34cd90795470dc64b500673e445ba5e54f697c09", "price_changes": [{"asset_id": "19224712151342060925250675326667957156597084749312967133447388236247487979547", "price": "0.515", "size": "15", "side": "BUY", "hash": "e8b447bdb28436ad141c737f12b8f8d70442a66a", "best_bid": "0.915", "best_ask": "0.943"}, {"asset_id": "19470872781622450446330627562106312915240544924539183504885686468325701819521", "price": "0.485", "size": "15", "side": "SELL", "hash": "bb29f0cf5fdfdd7b24614df4f0cb5731bdee0a8f", "best_bid": "0.057", "best_ask": "0.085"}], "timestamp": "1769384463230", "event_type": "price_change"}}
{"_local_timestamp": "2026-01-25T23:41:03.465329+00:00", "data": {"market": "0xa281783fc73b1a6927a301ee34cd90795470dc64b500673e445ba5e54f697c09", "price_changes": [{"asset_id": "19224712151342060925250675326667957156597084749312967133447388236247487979547", "price": "0.022", "size": "0", "side": "BUY", "hash": "432ec6747d40722f190cfa8fbd13e51994a73c52", "best_bid": "0.915", "best_ask": "0.943"}, {"asset_id": "19470872781622450446330627562106312915240544924539183504885686468325701819521", "price": "0.978", "size": "0", "side": "SELL", "hash": "00f3f19c47bd375ef8d9e611a8a148f3b632cb06", "best_bid": "0.057", "best_ask": "0.085"}], "timestamp": "1769384463373", "event_type": "price_change"}}
{"_local_timestamp": "2026-01-25T23:41:03.568435+00:00", "data": {"market": "0xa281783fc73b1a6927a301ee34cd90795470dc64b500673e445ba5e54f697c09", "price_changes": [{"asset_id": "19224712151342060925250675326667957156597084749312967133447388236247487979547", "price": "0.271", "size": "10", "side": "BUY", "hash": "bbe8f31862946113e6271bbc15aa448eb4c57f45", "best_bid": "0.915", "best_ask": "0.943"}, {"asset_id": "19470872781622450446330627562106312915240544924539183504885686468325701819521", "price": "0.729", "size": "10", "side": "SELL", "hash": "61e56b6da9691f8871709265fe9283552ba42e54", "best_bid": "0.057", "best_ask": "0.085"}], "timestamp": "1769384463466", "event_type": "price_change"}}
{"_local_timestamp": "2026-01-25T23:41:03.661297+00:00", "data": {"market": "0x3f9f68feccc892303834833665bf204632438b028254fc2d5bceea757ff61ed3", "price_changes": [{"asset_id": "11947171408899503371980811142475369274013053223377767646204433492871687017998", "price": "0.771", "size": "0", "side": "BUY", "hash": "f647df77e88135c4772388e8b620425c929111d0", "best_bid": "0.889", "best_ask": "0.966"}, {"asset_id": "36088399593046466421453063228085042771351246231742717370399696243183381174466", "price": "0.229", "size": "0", "side": "SELL", "hash": "41ce22db6d167ac223fe12d11b12bc8aa9429318", "best_bid": "0.034", "best_ask": "0.111"}], "timestamp": "1769384463566", "event_type": "price_change"}}
{"_local_timestamp": "2026-01-25T23:41:03.822422+00:00", "data": {"market": "0x4a8005d19b41af72c1cd5c619640d9d51da548dd7c3544b12ae0c520d9e6805b", "price_changes": [{"asset_id": "57920006811393570084962107679227395634282382525602277724728836928684998641754", "price": "0.799", "size": "10", "side": "BUY", "hash": "219a11d06f34e53b9e0208d62065cc88dd6555b2", "best_bid": "0.956", "best_ask": "0.968"}, {"asset_id": "42493289531592820306292191064557160874552640520793925047778017979799601355649", "price": "0.201", "size": "10", "side": "SELL", "hash": "31398fcc945d3fc53afe1f8b54d409d9baef1f5a", "best_bid": "0.032", "best_ask": "0.044"}], "timestamp": "1769384463739", "event_type": "price_change"}}
{"_local_timestamp": "2026-01-25T23:41:03.980551+00:00", "data": {"market": "0x3f9f68feccc892303834833665bf204632438b028254fc2d5bceea757ff61ed3", "price_changes": [{"asset_id": "11947171408899503371980811142475369274013053223377767646204433492871687017998", "price": "0.803", "size": "0", "side": "BUY", "hash": "461c372a57d57902f181c5788582c2391652582b", "best_bid": "0.889", "best_ask": "0.966"}, {"asset_id": "36088399593046466421453063228085042771351246231742717370399696243183381174466", "price": "0.197", "size": "0", "side": "SELL", "hash": "73e06b2ca0199a4076a203a1a1412b6b1ff02a9a", "best_bid": "0.034", "best_ask": "0.111"}], "timestamp": "1769384463908", "event_type": "price_change"}}
{"_local_timestamp": "2026-01-25T23:41:03.981806+00:00", "data": {"market": "0xb77424a53b7480164118374fb5e97b859bd12b696b1aea55d383ce798c060cf4", "price_changes": [{"asset_id": "74987521271361072746264224488245891269775371028979674431826416209897741154003", "price": "0.789", "size": "0", "side": "BUY", "hash": "345faed561f2a52502596210c0492b49d2165843", "best_bid": "0.934", "best_ask": "0.942"}, {"asset_id": "86904220753614324927759730619985568200215013704321476651673438801320577270597", "price": "0.211", "size": "0", "side": "SELL", "hash": "2656dcfdee4e70c38c1c7f28e4c077bb956049b5", "best_bid": "0.058", "best_ask": "0.066"}], "timestamp": "1769384463908", "event_type": "price_change"}}
{"_local_timestamp": "2026-01-25T23:41:04.108948+00:00", "data": {"market": "0x3f9f68feccc892303834833665bf204632438b028254fc2d5bceea757ff61ed3", "price_changes": [{"asset_id": "11947171408899503371980811142475369274013053223377767646204433492871687017998", "price": "0.771", "size": "15", "side": "BUY", "hash": "51b20475f8565cb98d8292b0ab0209035d90811b", "best_bid": "0.889", "best_ask": "0.966"}, {"asset_id": "36088399593046466421453063228085042771351246231742717370399696243183381174466", "price": "0.229", "size": "15", "side": "SELL", "hash": "176539485699108257f555b1fc772c3922f91284", "best_bid": "0.034", "best_ask": "0.111"}], "timestamp": "1769384464029", "event_type": "price_change"}}
{"_local_timestamp": "2026-01-25T23:41:04.109991+00:00", "data": {"market": "0x3f9f68feccc892303834833665bf204632438b028254fc2d5bceea757ff61ed3", "price_changes": [{"asset_id": "11947171408899503371980811142475369274013053223377767646204433492871687017998", "price": "0.805", "size": "10", "side": "BUY", "hash": "5ebcff380c6f7ba2f9326bda30236c12f476320e", "best_bid": "0.889", "best_ask": "0.966"}, {"asset_id": "36088399593046466421453063228085042771351246231742717370399696243183381174466", "price": "0.195", "size": "10", "side": "SELL", "hash": "aae91713204563209e238ca750c4b6ba3ead389f", "best_bid": "0.034", "best_ask": "0.111"}], "timestamp": "1769384464032", "event_type": "price_change"}}
{"_local_timestamp": "2026-01-25T23:41:04.781361+00:00", "data": {"market": "0x3f9f68feccc892303834833665bf204632438b028254fc2d5bceea757ff61ed3", "price_changes": [{"asset_id": "11947171408899503371980811142475369274013053223377767646204433492871687017998", "price": "0.804", "size": "0", "side": "BUY", "hash": "7e70b6ceb4078261149e75f28f590a6369833ad1", "best_bid": "0.889", "best_ask": "0.966"}, {"asset_id": "36088399593046466421453063228085042771351246231742717370399696243183381174466", "price": "0.196", "size": "0", "side": "SELL", "hash": "9f84532715302374b3fffe9e0a33e94e030e14e1", "best_bid": "0.034", "best_ask": "0.111"}], "timestamp": "1769384464712", "event_type": "price_change"}}
{"_local_timestamp": "2026-01-25T23:41:04.782415+00:00", "data": {"market": "0xb77424a53b7480164118374fb5e97b859bd12b696b1aea55d383ce798c060cf4", "price_changes": [{"asset_id": "74987521271361072746264224488245891269775371028979674431826416209897741154003", "price": "0.79", "size": "0", "side": "BUY", "hash": "2f646ae470f2d715a4bec9e71893fd1b91987268", "best_bid": "0.934", "best_ask": "0.942"}, {"asset_id": "86904220753614324927759730619985568200215013704321476651673438801320577270597", "price": "0.21", "size": "0", "side": "SELL", "hash": "f591f668ead51ee5d168b19dab473a7f2451e1ba", "best_bid": "0.058", "best_ask": "0.066"}], "timestamp": "1769384464712", "event_type": "price_change"}}
{"_local_timestamp": "2026-01-25T23:41:04.817022+00:00", "data": {"market": "0xb77424a53b7480164118374fb5e97b859bd12b696b1aea55d383ce798c060cf4", "price_changes": [{"asset_id": "74987521271361072746264224488245891269775371028979674431826416209897741154003", "price": "0.788", "size": "20", "side": "BUY", "hash": "f92b6593717e160af3faa4e39abf59302d8bfa57", "best_bid": "0.934", "best_ask": "0.942"}, {"asset_id": "86904220753614324927759730619985568200215013704321476651673438801320577270597", "price": "0.212", "size": "20", "side": "SELL", "hash": "9b269ccf93c85fe00f196c2570fcfde9625349f5", "best_bid": "0.058", "best_ask": "0.066"}], "timestamp": "1769384464742", "event_type": "price_change"}}
{"_local_timestamp": "2026-01-25T23:41:04.818225+00:00", "data": {"market": "0x3f9f68feccc892303834833665bf204632438b028254fc2d5bceea757ff61ed3", "price_changes": [{"asset_id": "11947171408899503371980811142475369274013053223377767646204433492871687017998", "price": "0.806", "size": "20", "side": "BUY", "hash": "b46b30df4bc19c345dd8d64f033c31164f202ad4", "best_bid": "0.889", "best_ask": "0.966"}, {"asset_id": "36088399593046466421453063228085042771351246231742717370399696243183381174466", "price": "0.194", "size": "20", "side": "SELL", "hash": "f660e545032d5dafe1a760fc0df1abef38326754", "best_bid": "0.034", "best_ask": "0.111"}], "timestamp": "1769384464742", "event_type": "price_change"}}
{"_local_timestamp": "2026-01-25T23:41:04.995290+00:00", "data": {"market": "0xa281783fc73b1a6927a301ee34cd90795470dc64b500673e445ba5e54f697c09", "price_changes": [{"asset_id": "19224712151342060925250675326667957156597084749312967133447388236247487979547", "price": "0.515", "size": "0", "side": "BUY", "hash": "a6ee1671e1cd85868716d1da6fd5a01187c5b835", "best_bid": "0.915", "best_ask": "0.943"}, {"asset_id": "19470872781622450446330627562106312915240544924539183504885686468325701819521", "price": "0.485", "size": "0", "side": "SELL", "hash": "06769daa854b20de002f15424eb468768c78e019", "best_bid": "0.057", "best_ask": "0.085"}], "timestamp": "1769384464929", "event_type": "price_change"}}
{"_local_timestamp": "2026-01-25T23:41:05.140180+00:00", "data": {"market": "0xa281783fc73b1a6927a301ee34cd90795470dc64b500673e445ba5e54f697c09", "price_changes": [{"asset_id": "19224712151342060925250675326667957156597084749312967133447388236247487979547", "price": "0.517", "size": "10", "side": "BUY", "hash": "350c812197c30c148921fea4d53c8dc6bb3a6f2f", "best_bid": "0.915", "best_ask": "0.943"}, {"asset_id": "19470872781622450446330627562106312915240544924539183504885686468325701819521", "price": "0.483", "size": "10", "side": "SELL", "hash": "facfd9db6f354d6721826a055943efe14f0a3f5b", "best_bid": "0.057", "best_ask": "0.085"}], "timestamp": "1769384465074", "event_type": "price_change"}}
{"_local_timestamp": "2026-01-25T23:41:05.141324+00:00", "data": {"market": "0xa281783fc73b1a6927a301ee34cd90795470dc64b500673e445ba5e54f697c09", "price_changes": [{"asset_id": "19224712151342060925250675326667957156597084749312967133447388236247487979547", "price": "0.517", "size": "25", "side": "BUY", "hash": "4cce6644121ee78e0972d06536d1a4db76c13be2", "best_bid": "0.915", "best_ask": "0.943"}, {"asset_id": "19470872781622450446330627562106312915240544924539183504885686468325701819521", "price": "0.483", "size": "25", "side": "SELL", "hash": "8cd65cc38546e098f833dd7f4c94ccdb1ba74833", "best_bid": "0.057", "best_ask": "0.085"}], "timestamp": "1769384465074", "event_type": "price_change"}}
{"_local_timestamp": "2026-01-25T23:41:05.602644+00:00", "data": {"market": "0xa281783fc73b1a6927a301ee34cd90795470dc64b500673e445ba5e54f697c09", "price_changes": [{"asset_id": "19224712151342060925250675326667957156597084749312967133447388236247487979547", "price": "0.516", "size": "0", "side": "BUY", "hash": "7a25bae69dfe377b9fc67a8fb42ad3bd2ab9dc76", "best_bid": "0.915", "best_ask": "0.943"}, {"asset_id": "19470872781622450446330627562106312915240544924539183504885686468325701819521", "price": "0.484", "size": "0", "side": "SELL", "hash": "ce09830aa5bbf71c870d6782a80467b997ac385c", "best_bid": "0.057", "best_ask": "0.085"}], "timestamp": "1769384465530", "event_type": "price_change"}}
{"_local_timestamp": "2026-01-25T23:41:05.636178+00:00", "data": {"market": "0xa281783fc73b1a6927a301ee34cd90795470dc64b500673e445ba5e54f697c09", "price_changes": [{"asset_id": "19224712151342060925250675326667957156597084749312967133447388236247487979547", "price": "0.518", "size": "20", "side": "BUY", "hash": "a742e48f836aa7f0b49832805cab3e19b0449baa", "best_bid": "0.915", "best_ask": "0.943"}, {"asset_id": "19470872781622450446330627562106312915240544924539183504885686468325701819521", "price": "0.482", "size": "20", "side": "SELL", "hash": "d8cc988a953d6088d38c534d12252c8807d56cbf", "best_bid": "0.057", "best_ask": "0.085"}], "timestamp": "1769384465558", "event_type": "price_change"}}
{"_local_timestamp": "2026-01-25T23:41:05.686939+00:00", "data": {"market": "0xb77424a53b7480164118374fb5e97b859bd12b696b1aea55d383ce798c060cf4", "price_changes": [{"asset_id": "74987521271361072746264224488245891269775371028979674431826416209897741154003", "price": "0.753", "size": "0", "side": "BUY", "hash": "954c4fff99714bc7c2c5b87399795df3f3b7bd5a", "best_bid": "0.934", "best_ask": "0.942"}, {"asset_id": "86904220753614324927759730619985568200215013704321476651673438801320577270597", "price": "0.247", "size": "0", "side": "SELL", "hash": "ddce5dc0faf3804fdf4d57e41e8fe5eb65da0583", "best_bid": "0.058", "best_ask": "0.066"}], "timestamp": "1769384465607", "event_type": "price_change"}}
{"_local_timestamp": "2026-01-25T23:41:05.692856+00:00", "data": {"market": "0x4a8005d19b41af72c1cd5c619640d9d51da548dd7c3544b12ae0c520d9e6805b", "price_changes": [{"asset_id": "57920006811393570084962107679227395634282382525602277724728836928684998641754", "price": "0.799", "size": "0", "side": "BUY", "hash": "a719536a89ef795178eee8582a0413fe77c67451", "best_bid": "0.956", "best_ask": "0.968"}, {"asset_id": "42493289531592820306292191064557160874552640520793925047778017979799601355649", "price": "0.201", "size": "0", "side": "SELL", "hash": "748f967688f4b3bd3191b3bce380b27578a539d2", "best_bid": "0.032", "best_ask": "0.044"}], "timestamp": "1769384465607", "event_type": "price_change"}}
{"_local_timestamp": "2026-01-25T23:41:05.763494+00:00", "data": {"market": "0xb77424a53b7480164118374fb5e97b859bd12b696b1aea55d383ce798c060cf4", "price_changes": [{"asset_id": "74987521271361072746264224488245891269775371028979674431826416209897741154003", "price": "0.753", "size": "15", "side": "BUY", "hash": "fd29332d62043c35dc403ca392818b41fae20b4a", "best_bid": "0.934", "best_ask": "0.942"}, {"asset_id": "86904220753614324927759730619985568200215013704321476651673438801320577270597", "price": "0.247", "size": "15", "side": "SELL", "hash": "b140507bd3a8d7366eb44858ac48377286f6f48a", "best_bid": "0.058", "best_ask": "0.066"}], "timestamp": "1769384465680", "event_type": "price_change"}}
{"_local_timestamp": "2026-01-25T23:41:05.764894+00:00", "data": {"market": "0x4a8005d19b41af72c1cd5c619640d9d51da548dd7c3544b12ae0c520d9e6805b", "price_changes": [{"asset_id": "57920006811393570084962107679227395634282382525602277724728836928684998641754", "price": "0.801", "size": "15", "side": "BUY", "hash": "270af34bfa85aad5f9a38c4360ae16251200eefd", "best_bid": "0.956", "best_ask": "0.968"}, {"asset_id": "42493289531592820306292191064557160874552640520793925047778017979799601355649", "price": "0.199", "size": "15", "side": "SELL", "hash": "2f25deed52b79c6262dd99ec0317ab3042c28171", "best_bid": "0.032", "best_ask": "0.044"}], "timestamp": "1769384465680", "event_type": "price_change"}}
{"_local_timestamp": "2026-01-25T23:41:05.782906+00:00", "data": {"market": "0xb77424a53b7480164118374fb5e97b859bd12b696b1aea55d383ce798c060cf4", "price_changes": [{"asset_id": "74987521271361072746264224488245891269775371028979674431826416209897741154003", "price": "0.789", "size": "10", "side": "BUY", "hash": "d60b70e03d2abd701a7441dbfd72c2bd51d4c696", "best_bid": "0.934", "best_ask": "0.942"}, {"asset_id": "86904220753614324927759730619985568200215013704321476651673438801320577270597", "price": "0.211", "size": "10", "side": "SELL", "hash": "4ef776ccd8cd77592a1e018b8a1a1be0fdcc4850", "best_bid": "0.058", "best_ask": "0.066"}], "timestamp": "1769384465681", "event_type": "price_change"}}
{"_local_timestamp": "2026-01-25T23:41:05.811670+00:00", "data": {"market": "0x4a8005d19b41af72c1cd5c619640d9d51da548dd7c3544b12ae0c520d9e6805b", "price_changes": [{"asset_id": "57920006811393570084962107679227395634282382525602277724728836928684998641754", "price": "0.801", "size": "25", "side": "BUY", "hash": "d61e9f441fabc28e69a18cf473b8269cae78baef", "best_bid": "0.956", "best_ask": "0.968"}, {"asset_id": "42493289531592820306292191064557160874552640520793925047778017979799601355649", "price": "0.199", "size": "25", "side": "SELL", "hash": "c1d14348973493f61b8211e614c6d21af0a4dbb9", "best_bid": "0.032", "best_ask": "0.044"}], "timestamp": "1769384465681", "event_type": "price_change"}}
{"_local_timestamp": "2026-01-25T23:41:06.564191+00:00", "data": {"market": "0xb77424a53b7480164118374fb5e97b859bd12b696b1aea55d383ce798c060cf4", "price_changes": [{"asset_id": "74987521271361072746264224488245891269775371028979674431826416209897741154003", "price": "0.788", "size": "0", "side": "BUY", "hash": "04d7e945c3ca340b70ce876116a9d68e9022ec39", "best_bid": "0.934", "best_ask": "0.942"}, {"asset_id": "86904220753614324927759730619985568200215013704321476651673438801320577270597", "price": "0.212", "size": "0", "side": "SELL", "hash": "d44c6b3ee6c1591326f9879b56dddae600bc1861", "best_bid": "0.058", "best_ask": "0.066"}], "timestamp": "1769384466491", "event_type": "price_change"}}
{"_local_timestamp": "2026-01-25T23:41:06.570938+00:00", "data": {"market": "0x4a8005d19b41af72c1cd5c619640d9d51da548dd7c3544b12ae0c520d9e6805b", "price_changes": [{"asset_id": "57920006811393570084962107679227395634282382525602277724728836928684998641754", "price": "0.8", "size": "0", "side": "BUY", "hash": "7f11350a649ae92e7a8cd6b94d353e0f90a8c1af", "best_bid": "0.956", "best_ask": "0.968"}, {"asset_id": "42493289531592820306292191064557160874552640520793925047778017979799601355649", "price": "0.2", "size": "0", "side": "SELL", "hash": "dd1746b8419289f98e1dd1893d52217fbb39c665", "best_bid": "0.032", "best_ask": "0.044"}], "timestamp": "1769384466491", "event_type": "price_change"}}
{"_local_timestamp": "2026-01-25T23:41:06.601019+00:00", "data": {"market": "0x4a8005d19b41af72c1cd5c619640d9d51da548dd7c3544b12ae0c520d9e6805b", "price_changes": [{"asset_id": "57920006811393570084962107679227395634282382525602277724728836928684998641754", "price": "0.802", "size": "20", "side": "BUY", "hash": "a9ca5ff6308852ec845d6a1fdc2f065c9c0ae699", "best_bid": "0.956", "best_ask": "0.968"}, {"asset_id": "42493289531592820306292191064557160874552640520793925047778017979799601355649", "price": "0.198", "size": "20", "side": "SELL", "hash": "ff9a1b4947cb9f941071afd5552a11e1fa2d3b42", "best_bid": "0.032", "best_ask": "0.044"}], "timestamp": "1769384466522", "event_type": "price_change"}}
{"_local_timestamp": "2026-01-25T23:41:06.602972+00:00", "data": {"market": "0xb77424a53b7480164118374fb5e97b859bd12b696b1aea55d383ce798c060cf4", "price_changes": [{"asset_id": "74987521271361072746264224488245891269775371028979674431826416209897741154003", "price": "0.79", "size": "20", "side": "BUY", "hash": "fb8ad04c2f73748582c547d0a5661d58610c3dd2", "best_bid": "0.934", "best_ask": "0.942"}, {"asset_id": "86904220753614324927759730619985568200215013704321476651673438801320577270597", "price": "0.21", "size": "20", "side": "SELL", "hash": "6aabd6029068268cc16a34d295b631edf35a2dfc", "best_bid": "0.058", "best_ask": "0.066"}], "timestamp": "1769384466522", "event_type": "price_change"}}
{"_local_timestamp": "2026-01-25T23:41:14.624891+00:00", "data": {"market": "0x3849e1d62e0807801913d3e2427e8caf3cc6dd1c8ef42d8d5c08c6f9c449dc5e", "price_changes": [{"asset_id": "56615676606297588259337956203332341775475048285080710344367729433788967812170", "price": "0.15", "size": "200", "side": "BUY", "hash": "5f28b200fe33bdfe533c744271da39306079de54", "best_bid": "0.67", "best_ask": "0.7"}, {"asset_id": "8070607953656787024050950499598687532281829563384949938603247089607814583142", "price": "0.85", "size": "200", "side": "SELL", "hash": "dd3f7abb37f2d6ea47b3ee3ef55615d94982e58f", "best_bid": "0.3", "best_ask": "0.33"}], "timestamp": "1769384474530", "event_type": "price_change"}}
{"_local_timestamp": "2026-01-25T23:41:14.783902+00:00", "data": {"market": "0xa281783fc73b1a6927a301ee34cd90795470dc64b500673e445ba5e54f697c09", "price_changes": [{"asset_id": "19224712151342060925250675326667957156597084749312967133447388236247487979547", "price": "0.271", "size": "0", "side": "BUY", "hash": "3ffe69cbb8802f739b4ba0fa6c207dd49228c936", "best_bid": "0.915", "best_ask": "0.943"}, {"asset_id": "19470872781622450446330627562106312915240544924539183504885686468325701819521", "price": "0.729", "size": "0", "side": "SELL", "hash": "467b8ffc18c3b9d9a79f3f4977e29ec200dd4592", "best_bid": "0.057", "best_ask": "0.085"}], "timestamp": "1769384474609", "event_type": "price_change"}}
{"_local_timestamp": "2026-01-25T23:41:14.955426+00:00", "data": {"market": "0xa281783fc73b1a6927a301ee34cd90795470dc64b500673e445ba5e54f697c09", "price_changes": [{"asset_id": "19224712151342060925250675326667957156597084749312967133447388236247487979547", "price": "0.026", "size": "10", "side": "BUY", "hash": "af36dac7d4d6f563168be31e71d9913dde53eea5", "best_bid": "0.915", "best_ask": "0.943"}, {"asset_id": "19470872781622450446330627562106312915240544924539183504885686468325701819521", "price": "0.974", "size": "10", "side": "SELL", "hash": "ea650907c7a59f14370c7198e621e0c6abdd20d3", "best_bid": "0.057", "best_ask": "0.085"}], "timestamp": "1769384474879", "event_type": "price_change"}}
{"_local_timestamp": "2026-01-25T23:41:15.279548+00:00", "data": {"market": "0x3849e1d62e0807801913d3e2427e8caf3cc6dd1c8ef42d8d5c08c6f9c449dc5e", "price_changes": [{"asset_id": "8070607953656787024050950499598687532281829563384949938603247089607814583142", "price": "0.38", "size": "0", "side": "SELL", "hash": "112258946fc20e785d3c3f04dd853525f9f5b164", "best_bid": "0.3", "best_ask": "0.33"}, {"asset_id": "56615676606297588259337956203332341775475048285080710344367729433788967812170", "price": "0.62", "size": "0", "side": "BUY", "hash": "f5572e88046584b8214b676c75e5cd996e96d31c", "best_bid": "0.67", "best_ask": "0.7"}], "timestamp": "1769384475212", "event_type": "price_change"}}
{"_local_timestamp": "2026-01-25T23:41:15.342590+00:00", "data": {"market": "0xb77424a53b7480164118374fb5e97b859bd12b696b1aea55d383ce798c060cf4", "price_changes": [{"asset_id": "74987521271361072746264224488245891269775371028979674431826416209897741154003", "price": "0.751", "size": "266.12", "side": "BUY", "hash": "63ee0381c934b36768b50c521b84d2c8e8012de6", "best_bid": "0.934", "best_ask": "0.942"}, {"asset_id": "86904220753614324927759730619985568200215013704321476651673438801320577270597", "price": "0.249", "size": "266.12", "side": "SELL", "hash": "7db26eb11c3eae30fb666b5bc408c3a8f89b5115", "best_bid": "0.058", "best_ask": "0.066"}], "timestamp": "1769384475266", "event_type": "price_change"}}
{"_local_timestamp": "2026-01-25T23:41:15.347082+00:00", "data": {"market": "0xb77424a53b7480164118374fb5e97b859bd12b696b1aea55d383ce798c060cf4", "price_changes": [{"asset_id": "74987521271361072746264224488245891269775371028979674431826416209897741154003", "price": "0.751", "size": "216.12", "side": "BUY", "hash": "68acac98367b9a9bd2f49849197088045f121fcf", "best_bid": "0.934", "best_ask": "0.942"}, {"asset_id": "86904220753614324927759730619985568200215013704321476651673438801320577270597", "price": "0.249", "size": "216.12", "side": "SELL", "hash": "98142987cf1cad1bd82e547e210465d53372af67", "best_bid": "0.058", "best_ask": "0.066"}], "timestamp": "1769384475274", "event_type": "price_change"}}
{"_local_timestamp": "2026-01-25T23:41:15.354335+00:00", "data": {"market": "0x4a8005d19b41af72c1cd5c619640d9d51da548dd7c3544b12ae0c520d9e6805b", "price_changes": [{"asset_id": "57920006811393570084962107679227395634282382525602277724728836928684998641754", "price": "0.751", "size": "0", "side": "BUY", "hash": "d3307aaa4137ff810105b2fb85e8de012267e69c", "best_bid": "0.956", "best_ask": "0.968"}, {"asset_id": "42493289531592820306292191064557160874552640520793925047778017979799601355649", "price": "0.249", "size": "0", "side": "SELL", "hash": "24d7340a109ac4ec0594b8b557932bde207d85ba", "best_bid": "0.032", "best_ask": "0.044"}], "timestamp": "1769384475288", "event_type": "price_change"}}
{"_local_timestamp": "2026-01-25T23:41:18.359463+00:00", "data": {"market": "0x3849e1d62e0807801913d3e2427e8caf3cc6dd1c8ef42d8d5c08c6f9c449dc5e", "price_changes": [{"asset_id": "8070607953656787024050950499598687532281829563384949938603247089607814583142", "price": "0.45", "size": "63.29", "side": "SELL", "hash": "38934daedb97696a5ac7ed13cbbc26bed7aae788", "best_bid": "0.3", "best_ask": "0.33"}, {"asset_id": "56615676606297588259337956203332341775475048285080710344367729433788967812170", "price": "0.55", "size": "63.29", "side": "BUY", "hash": "fed6ee6821a3a9727c30bed605ecd1f95a0d3a3a", "best_bid": "0.67", "best_ask": "0.7"}], "timestamp": "1769384478232", "event_type": "price_change"}}
{"_local_timestamp": "2026-01-25T23:41:24.765358+00:00", "data": {"market": "0x3f9f68feccc892303834833665bf204632438b028254fc2d5bceea757ff61ed3", "price_changes": [{"asset_id": "36088399593046466421453063228085042771351246231742717370399696243183381174466", "price": "0.757", "size": "0", "side": "SELL", "hash": "341d7143420dbced50f2043bde18dc42a605f9fe", "best_bid": "0.034", "best_ask": "0.111"}, {"asset_id": "11947171408899503371980811142475369274013053223377767646204433492871687017998", "price": "0.243", "size": "0", "side": "BUY", "hash": "dc95bce1ba27111086c56280577a850d80d1adbb", "best_bid": "0.889", "best_ask": "0.966"}], "timestamp": "1769384484692", "event_type": "price_change"}}
{"_local_timestamp": "2026-01-25T23:41:26.117756+00:00", "data": {"market": "0x3849e1d62e0807801913d3e2427e8caf3cc6dd1c8ef42d8d5c08c6f9c449dc5e", "price_changes": [{"asset_id": "8070607953656787024050950499598687532281829563384949938603247089607814583142", "price": "0.45", "size": "0", "side": "SELL", "hash": "ba45a9d858610736c638daab85829c6391cd6e64", "best_bid": "0.3", "best_ask": "0.33"}, {"asset_id": "56615676606297588259337956203332341775475048285080710344367729433788967812170", "price": "0.55", "size": "0", "side": "BUY", "hash": "e66dc1afc1950bdecf5dd0d4051b65578b549c3f", "best_bid": "0.67", "best_ask": "0.7"}], "timestamp": "1769384486050", "event_type": "price_change"}}
{"_local_timestamp": "2026-01-25T23:41:26.710095+00:00", "data": {"market": "0x3f9f68feccc892303834833665bf204632438b028254fc2d5bceea757ff61ed3", "price_changes": [{"asset_id": "36088399593046466421453063228085042771351246231742717370399696243183381174466", "price": "0.6", "size": "185.07", "side": "SELL", "hash": "2800ce6b63e8a670500d40faa64884ed40464291", "best_bid": "0.034", "best_ask": "0.111"}, {"asset_id": "11947171408899503371980811142475369274013053223377767646204433492871687017998", "price": "0.4", "size": "185.07", "side": "BUY", "hash": "be6a38370b5d4a3c237238af5a3f84783a146e31", "best_bid": "0.889", "best_ask": "0.966"}], "timestamp": "1769384486635", "event_type": "price_change"}}
{"_local_timestamp": "2026-01-25T23:41:28.838056+00:00", "data": {"market": "0xb77424a53b7480164118374fb5e97b859bd12b696b1aea55d383ce798c060cf4", "price_changes": [{"asset_id": "86904220753614324927759730619985568200215013704321476651673438801320577270597", "price": "0.058", "size": "224.9", "side": "BUY", "hash": "37ac21eaee2c22a3013f65002d6db753cbd96c87", "best_bid": "0.058", "best_ask": "0.066"}, {"asset_id": "74987521271361072746264224488245891269775371028979674431826416209897741154003", "price": "0.942", "size": "224.9", "side": "SELL", "hash": "f8074b0cfac8754781a1ac0540c8b0411ce2585c", "best_bid": "0.934", "best_ask": "0.942"}], "timestamp": "1769384488770", "event_type": "price_change"}}
{"_local_timestamp": "2026-01-25T23:41:50.957817+00:00", "data": {"market": "0x3849e1d62e0807801913d3e2427e8caf3cc6dd1c8ef42d8d5c08c6f9c449dc5e", "price_changes": [{"asset_id": "56615676606297588259337956203332341775475048285080710344367729433788967812170", "price": "0.15", "size": "0", "side": "BUY", "hash": "a910dd9ede47e06613e9f0747e19a7975ed2674a", "best_bid": "0.67", "best_ask": "0.7"}, {"asset_id": "8070607953656787024050950499598687532281829563384949938603247089607814583142", "price": "0.85", "size": "0", "side": "SELL", "hash": "461a9bc7cde5e79bad550faaf5391ae1c7deb2fd", "best_bid": "0.3", "best_ask": "0.33"}], "timestamp": "1769384510771", "event_type": "price_change"}}
{"_local_timestamp": "2026-01-25T23:41:52.854792+00:00", "data": {"market": "0x3849e1d62e0807801913d3e2427e8caf3cc6dd1c8ef42d8d5c08c6f9c449dc5e", "price_changes": [{"asset_id": "56615676606297588259337956203332341775475048285080710344367729433788967812170", "price": "0.11", "size": "742.09", "side": "BUY", "hash": "9a55a670237953f5d71d09b3df0b348c6ff1c202", "best_bid": "0.67", "best_ask": "0.7"}, {"asset_id": "8070607953656787024050950499598687532281829563384949938603247089607814583142", "price": "0.89", "size": "742.09", "side": "SELL", "hash": "8ffa7bc1c55f3e14614d17bf487d9df4c8632040", "best_bid": "0.3", "best_ask": "0.33"}], "timestamp": "1769384511824", "event_type": "price_change"}}
{"_local_timestamp": "2026-01-25T23:41:54.535495+00:00", "data": {"market": "0x3849e1d62e0807801913d3e2427e8caf3cc6dd1c8ef42d8d5c08c6f9c449dc5e", "price_changes": [{"asset_id": "8070607953656787024050950499598687532281829563384949938603247089607814583142", "price": "0.37", "size": "40.56", "side": "SELL", "hash": "ca0daba213cf2402daeecbbf77c8ec78f63f3372", "best_bid": "0.3", "best_ask": "0.33"}, {"asset_id": "56615676606297588259337956203332341775475048285080710344367729433788967812170", "price": "0.63", "size": "40.56", "side": "BUY", "hash": "5a4e1ad1ac5d85f007601a845ecde70c314385ab", "best_bid": "0.67", "best_ask": "0.7"}], "timestamp": "1769384514467", "event_type": "price_change"}}
{"_local_timestamp": "2026-01-25T23:41:54.605779+00:00", "data": {"market": "0x4a8005d19b41af72c1cd5c619640d9d51da548dd7c3544b12ae0c520d9e6805b", "price_changes": [{"asset_id": "57920006811393570084962107679227395634282382525602277724728836928684998641754", "price": "0.751", "size": "10", "side": "BUY", "hash": "f2e03fc95156d52633fbd7b2452ebcc57a775f3e", "best_bid": "0.956", "best_ask": "0.968"}, {"asset_id": "42493289531592820306292191064557160874552640520793925047778017979799601355649", "price": "0.249", "size": "10", "side": "SELL", "hash": "932f7d5300069e08cd6bfa6febafa4dcc7b2ac4a", "best_bid": "0.032", "best_ask": "0.044"}], "timestamp": "1769384514531", "event_type": "price_change"}}
{"_local_timestamp": "2026-01-25T23:41:56.816518+00:00", "data": {"market": "0x3849e1d62e0807801913d3e2427e8caf3cc6dd1c8ef42d8d5c08c6f9c449dc5e", "price_changes": [{"asset_id": "8070607953656787024050950499598687532281829563384949938603247089607814583142", "price": "0.48", "size": "0", "side": "SELL", "hash": "815866aa480670d4dfb68411b722b8e9173f3f47", "best_bid": "0.3", "best_ask": "0.33"}, {"asset_id": "56615676606297588259337956203332341775475048285080710344367729433788967812170", "price": "0.52", "size": "0", "side": "BUY", "hash": "2977d83c3d37427a771338d3a9d98f94282c9365", "best_bid": "0.67", "best_ask": "0.7"}], "timestamp": "1769384516744", "event_type": "price_change"}}
{"_local_timestamp": "2026-01-25T23:41:56.854328+00:00", "data": {"market": "0x3f9f68feccc892303834833665bf204632438b028254fc2d5bceea757ff61ed3", "price_changes": [{"asset_id": "11947171408899503371980811142475369274013053223377767646204433492871687017998", "price": "0.4", "size": "117.07", "side": "BUY", "hash": "96117f3b6f43f91e46c4fce0c1f8c7e8af461c01", "best_bid": "0.889", "best_ask": "0.966"}, {"asset_id": "36088399593046466421453063228085042771351246231742717370399696243183381174466", "price": "0.6", "size": "117.07", "side": "SELL", "hash": "31b6f0c037920808da3b745ba76b4fb9ae6bb975", "best_bid": "0.034", "best_ask": "0.111"}], "timestamp": "1769384516781", "event_type": "price_change"}}
{"_local_timestamp": "2026-01-25T23:41:56.885713+00:00", "data": {"market": "0x3f9f68feccc892303834833665bf204632438b028254fc2d5bceea757ff61ed3", "price_changes": [{"asset_id": "11947171408899503371980811142475369274013053223377767646204433492871687017998", "price": "0.4", "size": "51.07", "side": "BUY", "hash": "613bfab02a7cc06af82526814856c94d473247f3", "best_bid": "0.889", "best_ask": "0.966"}, {"asset_id": "36088399593046466421453063228085042771351246231742717370399696243183381174466", "price": "0.6", "size": "51.07", "side": "SELL", "hash": "5032ddf5ddac0b49ec10e7b4fd46d3c4c73d4eb6", "best_bid": "0.034", "best_ask": "0.111"}], "timestamp": "1769384516815", "event_type": "price_change"}}
{"_local_timestamp": "2026-01-25T23:41:56.905107+00:00", "data": {"market": "0x4a8005d19b41af72c1cd5c619640d9d51da548dd7c3544b12ae0c520d9e6805b", "price_changes": [{"asset_id": "57920006811393570084962107679227395634282382525602277724728836928684998641754", "price": "0.751", "size": "0", "side": "BUY", "hash": "e00c7c5c2b7da2c6cddc7f8facfe2a500e16e05c", "best_bid": "0.956", "best_ask": "0.968"}, {"asset_id": "42493289531592820306292191064557160874552640520793925047778017979799601355649", "price": "0.249", "size": "0", "side": "SELL", "hash": "9e7a69577ddb2d4d290c97fc1820b63025789575", "best_bid": "0.032", "best_ask": "0.044"}], "timestamp": "1769384516832", "event_type": "price_change"}}
{"_local_timestamp": "2026-01-25T23:41:57.122067+00:00", "data": {"market": "0x3849e1d62e0807801913d3e2427e8caf3cc6dd1c8ef42d8d5c08c6f9c449dc5e", "price_changes": [{"asset_id": "8070607953656787024050950499598687532281829563384949938603247089607814583142", "price": "0.47", "size": "22.73", "side": "SELL", "hash": "cbfb55f21d173172292302c1634e3bedd93facb2", "best_bid": "0.3", "best_ask": "0.33"}, {"asset_id": "56615676606297588259337956203332341775475048285080710344367729433788967812170", "price": "0.53", "size": "22.73", "side": "BUY", "hash": "17097a4bd920fc6bba1672ab122c860c0a28089c", "best_bid": "0.67", "best_ask": "0.7"}], "timestamp": "1769384517014", "event_type": "price_change"}}
{"_local_timestamp": "2026-01-25T23:41:57.267031+00:00", "data": {"market": "0x3849e1d62e0807801913d3e2427e8caf3cc6dd1c8ef42d8d5c08c6f9c449dc5e", "price_changes": [{"asset_id": "8070607953656787024050950499598687532281829563384949938603247089607814583142", "price": "0.36", "size": "189.99", "side": "SELL", "hash": "b90952ab4f812608bb3a7d4f5fec31fe20614808", "best_bid": "0.3", "best_ask": "0.33"}, {"asset_id": "56615676606297588259337956203332341775475048285080710344367729433788967812170", "price": "0.64", "size": "189.99", "side": "BUY", "hash": "c5a46d05f1500eddec121309db1cc0625e628850", "best_bid": "0.67", "best_ask": "0.7"}], "timestamp": "1769384517193", "event_type": "price_change"}}
{"_local_timestamp": "2026-01-25T23:41:57.309887+00:00", "data": {"market": "0x4a8005d19b41af72c1cd5c619640d9d51da548dd7c3544b12ae0c520d9e6805b", "price_changes": [{"asset_id": "57920006811393570084962107679227395634282382525602277724728836928684998641754", "price": "0.751", "size": "10", "side": "BUY", "hash": "bd6a550422bfd15defb4a53dac47241d980b93d1", "best_bid": "0.956", "best_ask": "0.968"}, {"asset_id": "42493289531592820306292191064557160874552640520793925047778017979799601355649", "price": "0.249", "size": "10", "side": "SELL", "hash": "42bfa722c37d9402f691edc2a9e6581ed0fb0861", "best_bid": "0.032", "best_ask": "0.044"}], "timestamp": "1769384517234", "event_type": "price_change"}}
{"_local_timestamp": "2026-01-25T23:41:57.399608+00:00", "data": {"market": "0x3f9f68feccc892303834833665bf204632438b028254fc2d5bceea757ff61ed3", "price_changes": [{"asset_id": "11947171408899503371980811142475369274013053223377767646204433492871687017998", "price": "0.4", "size": "112.07", "side": "BUY", "hash": "7ccf475df2574b62e107ac17350540ccb515cf99", "best_bid": "0.889", "best_ask": "0.966"}, {"asset_id": "36088399593046466421453063228085042771351246231742717370399696243183381174466", "price": "0.6", "size": "112.07", "side": "SELL", "hash": "e446170996256cc7d4fc7bcba401eba7149f623a", "best_bid": "0.034", "best_ask": "0.111"}], "timestamp": "1769384517329", "event_type": "price_change"}}
{"_local_timestamp": "2026-01-25T23:41:57.400589+00:00", "data": {"market": "0x08b39100a4d3d6ad1099e076fb69f781313c5b16975adf189d63542bd1ecca04", "price_changes": [{"asset_id": "48451126471681390564675828610810240762308720916091458567360242927144088567337", "price": "0.752", "size": "31", "side": "BUY", "hash": "b996122d648cb0299414bd5798512152ba45ef45", "best_bid": "0.978", "best_ask": "0.982"}, {"asset_id": "6122912536415539457721068960901205060237919057489564846781206253065694717085", "price": "0.248", "size": "31", "side": "SELL", "hash": "b1e4eaae9654399043d33a2398dab14fc36dc2e5", "best_bid": "0.018", "best_ask": "0.022"}], "timestamp": "1769384517329", "event_type": "price_change"}}
{"_local_timestamp": "2026-01-25T23:41:57.432532+00:00", "data": {"market": "0x3f9f68feccc892303834833665bf204632438b028254fc2d5bceea757ff61ed3", "price_changes": [{"asset_id": "11947171408899503371980811142475369274013053223377767646204433492871687017998", "price": "0.4", "size": "175.07", "side": "BUY", "hash": "50d9d7dc707f7613c69992faed027baa6bd9706c", "best_bid": "0.889", "best_ask": "0.966"}, {"asset_id": "36088399593046466421453063228085042771351246231742717370399696243183381174466", "price": "0.6", "size": "175.07", "side": "SELL", "hash": "e8dbec2570d4187cd07a32df1ecdd4c5227ab2ca", "best_bid": "0.034", "best_ask": "0.111"}], "timestamp": "1769384517363", "event_type": "price_change"}}
{"_local_timestamp": "2026-01-25T23:41:57.433654+00:00", "data": {"market": "0x08b39100a4d3d6ad1099e076fb69f781313c5b16975adf189d63542bd1ecca04", "price_changes": [{"asset_id": "48451126471681390564675828610810240762308720916091458567360242927144088567337", "price": "0.752", "size": "52", "side": "BUY", "hash": "a966f61858387cde464a09921e43a542d5b269cf", "best_bid": "0.978", "best_ask": "0.982"}, {"asset_id": "6122912536415539457721068960901205060237919057489564846781206253065694717085", "price": "0.248", "size": "52", "side": "SELL", "hash": "4fa20470cc47341c145a94551b3ed5d557b0d228", "best_bid": "0.018", "best_ask": "0.022"}], "timestamp": "1769384517363", "event_type": "price_change"}}
{"_local_timestamp": "2026-01-25T23:41:57.434655+00:00", "data": {"market": "0xb77424a53b7480164118374fb5e97b859bd12b696b1aea55d383ce798c060cf4", "price_changes": [{"asset_id": "74987521271361072746264224488245891269775371028979674431826416209897741154003", "price": "0.751", "size": "236.12", "side": "BUY", "hash": "deba8bc5840e11150b2140908594eb025c52b0c3", "best_bid": "0.934", "best_ask": "0.942"}, {"asset_id": "86904220753614324927759730619985568200215013704321476651673438801320577270597", "price": "0.249", "size": "236.12", "side": "SELL", "hash": "bb6bc596d803c692accafab3666c0627342832b7", "best_bid": "0.058", "best_ask": "0.066"}], "timestamp": "1769384517363", "event_type": "price_change"}}
{"_local_timestamp": "2026-01-25T23:41:57.569511+00:00", "data": {"market": "0x602a7a6c7d65b55932e6cf8b6904cb7acdc728ca423ffd3ccb1988dd5501de13", "price_changes": [{"asset_id": "18399565751068676179945656979762090460558422925963909399757895217338947077684", "price": "0.759", "size": "0", "side": "BUY", "hash": "595b508bf4707e6b28f0bebeecc2bc70168b7b24", "best_bid": "0.941", "best_ask": "0.952"}, {"asset_id": "88770632741686298370270294037614812817595949782311984579833554458717957886356", "price": "0.241", "size": "0", "side": "SELL", "hash": "8168924ca9eadd3bebf9c564e970dcf60474e021", "best_bid": "0.048", "best_ask": "0.059"}], "timestamp": "1769384517496", "event_type": "price_change"}}
{"_local_timestamp": "2026-01-25T23:41:57.684577+00:00", "data": {"market": "0x602a7a6c7d65b55932e6cf8b6904cb7acdc728ca423ffd3ccb1988dd5501de13", "price_changes": [{"asset_id": "18399565751068676179945656979762090460558422925963909399757895217338947077684", "price": "0.761", "size": "15", "side": "BUY", "hash": "ec10c784142914f9c9473996024ed152612d43dc", "best_bid": "0.941", "best_ask": "0.952"}, {"asset_id": "88770632741686298370270294037614812817595949782311984579833554458717957886356", "price": "0.239", "size": "15", "side": "SELL", "hash": "b8157d9e5e17792adf833d7a881e3b67f0c0db1c", "best_bid": "0.048", "best_ask": "0.059"}], "timestamp": "1769384517616", "event_type": "price_change"}}
{"_local_timestamp": "2026-01-25T23:41:57.694174+00:00", "data": {"market": "0x602a7a6c7d65b55932e6cf8b6904cb7acdc728ca423ffd3ccb1988dd5501de13", "price_changes": [{"asset_id": "18399565751068676179945656979762090460558422925963909399757895217338947077684", "price": "0.761", "size": "25", "side": "BUY", "hash": "cba182c555946f07874f17bf8926e73edc3394a0", "best_bid": "0.941", "best_ask": "0.952"}, {"asset_id": "88770632741686298370270294037614812817595949782311984579833554458717957886356", "price": "0.239", "size": "25", "side": "SELL", "hash": "ce3e45c5e3296e33c8c048be335b7ff435906a2e", "best_bid": "0.048", "best_ask": "0.059"}], "timestamp": "1769384517617", "event_type": "price_change"}}
{"_local_timestamp": "2026-01-25T23:41:58.368753+00:00", "data": {"market": "0x602a7a6c7d65b55932e6cf8b6904cb7acdc728ca423ffd3ccb1988dd5501de13", "price_changes": [{"asset_id": "18399565751068676179945656979762090460558422925963909399757895217338947077684", "price": "0.76", "size": "0", "side": "BUY", "hash": "5e3933abecc7f3115b2963c7489527f398e02d5c", "best_bid": "0.941", "best_ask": "0.952"}, {"asset_id": "88770632741686298370270294037614812817595949782311984579833554458717957886356", "price": "0.24", "size": "0", "side": "SELL", "hash": "8eb0631377b7c9832488851331aa28fbd8584b49", "best_bid": "0.048", "best_ask": "0.059"}], "timestamp": "1769384518299", "event_type": "price_change"}}
{"_local_timestamp": "2026-01-25T23:41:58.404303+00:00", "data": {"market": "0x602a7a6c7d65b55932e6cf8b6904cb7acdc728ca423ffd3ccb1988dd5501de13", "price_changes": [{"asset_id": "18399565751068676179945656979762090460558422925963909399757895217338947077684", "price": "0.762", "size": "20", "side": "BUY", "hash": "cc6ca1bfe2abe49b5639868156ee12ab0a6957bc", "best_bid": "0.941", "best_ask": "0.952"}, {"asset_id": "88770632741686298370270294037614812817595949782311984579833554458717957886356", "price": "0.238", "size": "20", "side": "SELL", "hash": "e62245f7500f955aa04b0981847a386877feba4b", "best_bid": "0.048", "best_ask": "0.059"}], "timestamp": "1769384518333", "event_type": "price_change"}}
{"_local_timestamp": "2026-01-25T23:42:18.545482+00:00", "data": {"market": "0x3849e1d62e0807801913d3e2427e8caf3cc6dd1c8ef42d8d5c08c6f9c449dc5e", "price_changes": [{"asset_id": "56615676606297588259337956203332341775475048285080710344367729433788967812170", "price": "0.17", "size": "3019.7", "side": "BUY", "hash": "00d29b2c842d75194d757ce4cf5671829bfe4b4d", "best_bid": "0.67", "best_ask": "0.7"}, {"asset_id": "8070607953656787024050950499598687532281829563384949938603247089607814583142", "price": "0.83", "size": "3019.7", "side": "SELL", "hash": "5a3d42d8adf28b7559c644b69818a946b054018d", "best_bid": "0.3", "best_ask": "0.33"}], "timestamp": "1769384538460", "event_type": "price_change"}}
{"_local_timestamp": "2026-01-25T23:42:18.564061+00:00", "data": {"market": "0x3f9f68feccc892303834833665bf204632438b028254fc2d5bceea757ff61ed3", "price_changes": [{"asset_id": "11947171408899503371980811142475369274013053223377767646204433492871687017998", "price": "0.882", "size": "275.45", "side": "BUY", "hash": "bea4b9c86bf3af14c61b0fbcc1785cac804fcfbf", "best_bid": "0.889", "best_ask": "0.966"}, {"asset_id": "36088399593046466421453063228085042771351246231742717370399696243183381174466", "price": "0.118", "size": "275.45", "side": "SELL", "hash": "54114b9f92e07dce5dda1d1f804026cd91aa152f", "best_bid": "0.034", "best_ask": "0.111"}], "timestamp": "1769384538486", "event_type": "price_change"}}
{"_local_timestamp": "2026-01-25T23:42:18.571164+00:00", "data": {"market": "0xa281783fc73b1a6927a301ee34cd90795470dc64b500673e445ba5e54f697c09", "price_changes": [{"asset_id": "19224712151342060925250675326667957156597084749312967133447388236247487979547", "price": "0.859", "size": "25", "side": "BUY", "hash": "964f48d6348fef94d5445da90c1f1a4abf7892c3", "best_bid": "0.915", "best_ask": "0.943"}, {"asset_id": "19470872781622450446330627562106312915240544924539183504885686468325701819521", "price": "0.141", "size": "25", "side": "SELL", "hash": "7461c61f06199a3d121b42d69de84495f30bdfb9", "best_bid": "0.057", "best_ask": "0.085"}], "timestamp": "1769384538495", "event_type": "price_change"}}
{"_local_timestamp": "2026-01-25T23:42:19.198889+00:00", "data": {"market": "0xa281783fc73b1a6927a301ee34cd90795470dc64b500673e445ba5e54f697c09", "price_changes": [{"asset_id": "19224712151342060925250675326667957156597084749312967133447388236247487979547", "price": "0.907", "size": "50", "side": "BUY", "hash": "c2dcda0a313494efae33d3cfa8d24dc490899989", "best_bid": "0.915", "best_ask": "0.943"}, {"asset_id": "19470872781622450446330627562106312915240544924539183504885686468325701819521", "price": "0.093", "size": "50", "side": "SELL", "hash": "994ce0fb10198b6d63d62a5349eaffad2a922465", "best_bid": "0.057", "best_ask": "0.085"}], "timestamp": "1769384539103", "event_type": "price_change"}}
{"_local_timestamp": "2026-01-25T23:42:19.380633+00:00", "data": {"market": "0xa281783fc73b1a6927a301ee34cd90795470dc64b500673e445ba5e54f697c09", "price_changes": [{"asset_id": "19224712151342060925250675326667957156597084749312967133447388236247487979547", "price": "0.912", "size": "105.85", "side": "BUY", "hash": "e22d5619f185adf88bf12161be5e969ec7575b9f", "best_bid": "0.915", "best_ask": "0.943"}, {"asset_id": "19470872781622450446330627562106312915240544924539183504885686468325701819521", "price": "0.088", "size": "105.85", "side": "SELL", "hash": "58a050335b202f2a13c6d70e40b8446fa4c6e027", "best_bid": "0.057", "best_ask": "0.085"}], "timestamp": "1769384539273", "event_type": "price_change"}}
{"_local_timestamp": "2026-01-25T23:42:19.523763+00:00", "data": {"market": "0xa281783fc73b1a6927a301ee34cd90795470dc64b500673e445ba5e54f697c09", "price_changes": [{"asset_id": "19224712151342060925250675326667957156597084749312967133447388236247487979547", "price": "0.913", "size": "25", "side": "BUY", "hash": "1b38daee1ddf8f2c95cafaf404000608094cbad6", "best_bid": "0.915", "best_ask": "0.943"}, {"asset_id": "19470872781622450446330627562106312915240544924539183504885686468325701819521", "price": "0.087", "size": "25", "side": "SELL", "hash": "bfb79db8ab592528fb15d84bdd2f7c68b75bcec2", "best_bid": "0.057", "best_ask": "0.085"}], "timestamp": "1769384539419", "event_type": "price_change"}}
{"_local_timestamp": "2026-01-25T23:42:19.524963+00:00", "data": {"market": "0xa281783fc73b1a6927a301ee34cd90795470dc64b500673e445ba5e54f697c09", "price_changes": [{"asset_id": "19470872781622450446330627562106312915240544924539183504885686468325701819521", "price": "0.055", "size": "288.53", "side": "BUY", "hash": "ce2cfc1b017816fb96efc85bd748a3132ae67329", "best_bid": "0.057", "best_ask": "0.085"}, {"asset_id": "19224712151342060925250675326667957156597084749312967133447388236247487979547", "price": "0.945", "size": "288.53", "side": "SELL", "hash": "dbdc02ec50d9fe2def2f21a735618374b06c0ded", "best_bid": "0.915", "best_ask": "0.943"}], "timestamp": "1769384539419", "event_type": "price_change"}}
{"_local_timestamp": "2026-01-25T23:42:19.712045+00:00", "data": {"market": "0xa281783fc73b1a6927a301ee34cd90795470dc64b500673e445ba5e54f697c09", "price_changes": [{"asset_id": "19224712151342060925250675326667957156597084749312967133447388236247487979547", "price": "0.907", "size": "100", "side": "BUY", "hash": "3566979e241f0aea526e7d21933a7a6316461f53", "best_bid": "0.915", "best_ask": "0.943"}, {"asset_id": "19470872781622450446330627562106312915240544924539183504885686468325701819521", "price": "0.093", "size": "100", "side": "SELL", "hash": "7be6d101ed5cd59e8302c642b69a5e6cb1c2b7d1", "best_bid": "0.057", "best_ask": "0.085"}], "timestamp": "1769384539609", "event_type": "price_change"}}
{"_local_timestamp": "2026-01-25T23:42:19.715144+00:00", "data": {"market": "0xa281783fc73b1a6927a301ee34cd90795470dc64b500673e445ba5e54f697c09", "price_changes": [{"asset_id": "19470872781622450446330627562106312915240544924539183504885686468325701819521", "price": "0.055", "size": "338.53", "side": "BUY", "hash": "5e42e8c84e7acc38cc70da89270ce27f5dd5dacd", "best_bid": "0.057", "best_ask": "0.085"}, {"asset_id": "19224712151342060925250675326667957156597084749312967133447388236247487979547", "price": "0.945", "size": "338.53", "side": "SELL", "hash": "c279bba7495991341129b096b2f6e7a192bdf5f8", "best_bid": "0.915", "best_ask": "0.943"}], "timestamp": "1769384539610", "event_type": "price_change"}}
{"_local_timestamp": "2026-01-25T23:42:24.573744+00:00", "data": {"market": "0x3849e1d62e0807801913d3e2427e8caf3cc6dd1c8ef42d8d5c08c6f9c449dc5e", "price_changes": [{"asset_id": "56615676606297588259337956203332341775475048285080710344367729433788967812170", "price": "0.11", "size": "617.09", "side": "BUY", "hash": "eb4a1843cc90c1dac90b945c0bf0f57a05a22eb6", "best_bid": "0.67", "best_ask": "0.7"}, {"asset_id": "8070607953656787024050950499598687532281829563384949938603247089607814583142", "price": "0.89", "size": "617.09", "side": "SELL", "hash": "a9ac60f7ec6eb49b5ea2cb4c3af9516470b9538e", "best_bid": "0.3", "best_ask": "0.33"}], "timestamp": "1769384544473", "event_type": "price_change"}}
{"_local_timestamp": "2026-01-25T23:42:24.574981+00:00", "data": {"market": "0x3849e1d62e0807801913d3e2427e8caf3cc6dd1c8ef42d8d5c08c6f9c449dc5e", "price_changes": [{"asset_id": "56615676606297588259337956203332341775475048285080710344367729433788967812170", "price": "0.16", "size": "0", "side": "BUY", "hash": "eb4a1843cc90c1dac90b945c0bf0f57a05a22eb6", "best_bid": "0.67", "best_ask": "0.7"}, {"asset_id": "8070607953656787024050950499598687532281829563384949938603247089607814583142", "price": "0.84", "size": "0", "side": "SELL", "hash": "a9ac60f7ec6eb49b5ea2cb4c3af9516470b9538e", "best_bid": "0.3", "best_ask": "0.33"}], "timestamp": "1769384544473", "event_type": "price_change"}}
{"_local_timestamp": "2026-01-25T23:42:25.068175+00:00", "data": {"market": "0x3849e1d62e0807801913d3e2427e8caf3cc6dd1c8ef42d8d5c08c6f9c449dc5e", "price_changes": [{"asset_id": "56615676606297588259337956203332341775475048285080710344367729433788967812170", "price": "0.17", "size": "3119.7", "side": "BUY", "hash": "986789be4d7028f0c3daf7468fcfa1e3200afdfa", "best_bid": "0.67", "best_ask": "0.7"}, {"asset_id": "8070607953656787024050950499598687532281829563384949938603247089607814583142", "price": "0.83", "size": "3119.7", "side": "SELL", "hash": "2e94fe3c39344ebd4fdde52e66ecbc7ee14ba3d1", "best_bid": "0.3", "best_ask": "0.33"}], "timestamp": "1769384544904", "event_type": "price_change"}}
{"_local_timestamp": "2026-01-25T23:42:25.147451+00:00", "data": {"market": "0x3849e1d62e0807801913d3e2427e8caf3cc6dd1c8ef42d8d5c08c6f9c449dc5e", "price_changes": [{"asset_id": "56615676606297588259337956203332341775475048285080710344367729433788967812170", "price": "0.15", "size": "125", "side": "BUY", "hash": "d94750e70a4893134e6935d12228263e38331c29", "best_bid": "0.67", "best_ask": "0.7"}, {"asset_id": "8070607953656787024050950499598687532281829563384949938603247089607814583142", "price": "0.85", "size": "125", "side": "SELL", "hash": "83db1ea5e952bf83543948030a01d3b276c79b22", "best_bid": "0.3", "best_ask": "0.33"}], "timestamp": "1769384544942", "event_type": "price_change"}}
{"_local_timestamp": "2026-01-25T23:42:37.146646+00:00", "data": {"market": "0x602a7a6c7d65b55932e6cf8b6904cb7acdc728ca423ffd3ccb1988dd5501de13", "price_changes": [{"asset_id": "88770632741686298370270294037614812817595949782311984579833554458717957886356", "price": "0.013", "size": "75", "side": "BUY", "hash": "085c43ac51a916ea9aa7e0c88889fd6ca05fd924", "best_bid": "0.048", "best_ask": "0.059"}, {"asset_id": "18399565751068676179945656979762090460558422925963909399757895217338947077684", "price": "0.987", "size": "75", "side": "SELL", "hash": "ad419fed884b74e810e19dbea72d8f50b598661a", "best_bid": "0.941", "best_ask": "0.952"}], "timestamp": "1769384557001", "event_type": "price_change"}}
{"_local_timestamp": "2026-01-25T23:42:37.172501+00:00", "data": {"market": "0x602a7a6c7d65b55932e6cf8b6904cb7acdc728ca423ffd3ccb1988dd5501de13", "price_changes": [{"asset_id": "18399565751068676179945656979762090460558422925963909399757895217338947077684", "price": "0.927", "size": "50", "side": "BUY", "hash": "62871f08a33be7e11d05f56ebb9f343f14a98eac", "best_bid": "0.941", "best_ask": "0.952"}, {"asset_id": "88770632741686298370270294037614812817595949782311984579833554458717957886356", "price": "0.073", "size": "50", "side": "SELL", "hash": "17e3e5bbf29720c97cceaf29873b923fdab71620", "best_bid": "0.048", "best_ask": "0.059"}], "timestamp": "1769384557005", "event_type": "price_change"}}
{"_local_timestamp": "2026-01-25T23:42:47.241505+00:00", "data": {"market": "0x3849e1d62e0807801913d3e2427e8caf3cc6dd1c8ef42d8d5c08c6f9c449dc5e", "price_changes": [{"asset_id": "56615676606297588259337956203332341775475048285080710344367729433788967812170", "price": "0.17", "size": "649.7", "side": "BUY", "hash": "33b46615d037ea9fd3162214ec1c07a5a43869b8", "best_bid": "0.67", "best_ask": "0.7"}, {"asset_id": "8070607953656787024050950499598687532281829563384949938603247089607814583142", "price": "0.83", "size": "649.7", "side": "SELL", "hash": "eba47e9855020f65e9fd7aa37759fabfefd10db6", "best_bid": "0.3", "best_ask": "0.33"}], "timestamp": "1769384566990", "event_type": "price_change"}}
{"_local_timestamp": "2026-01-25T23:42:56.067627+00:00", "data": {"market": "0xa281783fc73b1a6927a301ee34cd90795470dc64b500673e445ba5e54f697c09", "price_changes": [{"asset_id": "19224712151342060925250675326667957156597084749312967133447388236247487979547", "price": "0.907", "size": "50", "side": "BUY", "hash": "aecddbfacd7b2911deeb04eb6413305cfd76e631", "best_bid": "0.915", "best_ask": "0.943"}, {"asset_id": "19470872781622450446330627562106312915240544924539183504885686468325701819521", "price": "0.093", "size": "50", "side": "SELL", "hash": "23371ff1a0364da7d45b506ba8cbe74244ed17da", "best_bid": "0.057", "best_ask": "0.085"}], "timestamp": "1769384575966", "event_type": "price_change"}}
{"_local_timestamp": "2026-01-25T23:42:56.088180+00:00", "data": {"market": "0xa281783fc73b1a6927a301ee34cd90795470dc64b500673e445ba5e54f697c09", "price_changes": [{"asset_id": "19224712151342060925250675326667957156597084749312967133447388236247487979547", "price": "0.381", "size": "0", "side": "BUY", "hash": "c61a88fb125be3e97fc6ff362fd834f477c8920d", "best_bid": "0.915", "best_ask": "0.943"}, {"asset_id": "19470872781622450446330627562106312915240544924539183504885686468325701819521", "price": "0.619", "size": "0", "side": "SELL", "hash": "9e37e1392e6a125b9bad97beb7a89526bc896e09", "best_bid": "0.057", "best_ask": "0.085"}], "timestamp": "1769384575998", "event_type": "price_change"}}
{"_local_timestamp": "2026-01-25T23:42:56.199213+00:00", "data": {"market": "0xa281783fc73b1a6927a301ee34cd90795470dc64b500673e445ba5e54f697c09", "price_changes": [{"asset_id": "19470872781622450446330627562106312915240544924539183504885686468325701819521", "price": "0.055", "size": "288.53", "side": "BUY", "hash": "7b46bab350f5662788fd787cdb3a990471d67a75", "best_bid": "0.057", "best_ask": "0.085"}, {"asset_id": "19224712151342060925250675326667957156597084749312967133447388236247487979547", "price": "0.945", "size": "288.53", "side": "SELL", "hash": "78964bb1c0ea216df11ab57844fa6f20cf1b933f", "best_bid": "0.915", "best_ask": "0.943"}], "timestamp": "1769384576102", "event_type": "price_change"}}
{"_local_timestamp": "2026-01-25T23:42:56.200467+00:00", "data": {"market": "0xa281783fc73b1a6927a301ee34cd90795470dc64b500673e445ba5e54f697c09", "price_changes": [{"asset_id": "19224712151342060925250675326667957156597084749312967133447388236247487979547", "price": "0.907", "size": "0", "side": "BUY", "hash": "cbe42c55142e57642dde5db42abc8817902bd558", "best_bid": "0.915", "best_ask": "0.943"}, {"asset_id": "19470872781622450446330627562106312915240544924539183504885686468325701819521", "price": "0.093", "size": "0", "side": "SELL", "hash": "57b5a9fbb1fa34ed63290f1a365a26fab5ed7f04", "best_bid": "0.057", "best_ask": "0.085"}], "timestamp": "1769384576102", "event_type": "price_change"}}
{"_local_timestamp": "2026-01-25T23:42:56.335116+00:00", "data": {"market": "0x08b39100a4d3d6ad1099e076fb69f781313c5b16975adf189d63542bd1ecca04", "price_changes": [{"asset_id": "48451126471681390564675828610810240762308720916091458567360242927144088567337", "price": "0.759", "size": "15", "side": "BUY", "hash": "1827b9120b6dd0fc829b9d93b306857fa468ca47", "best_bid": "0.978", "best_ask": "0.982"}, {"asset_id": "6122912536415539457721068960901205060237919057489564846781206253065694717085", "price": "0.241", "size": "15", "side": "SELL", "hash": "58c847585df4ec5937a005eeb6aa5285a8b62a4a", "best_bid": "0.018", "best_ask": "0.022"}], "timestamp": "1769384576241", "event_type": "price_change"}}
{"_local_timestamp": "2026-01-25T23:42:56.343180+00:00", "data": {"market": "0xa281783fc73b1a6927a301ee34cd90795470dc64b500673e445ba5e54f697c09", "price_changes": [{"asset_id": "19470872781622450446330627562106312915240544924539183504885686468325701819521", "price": "0.055", "size": "338.53", "side": "BUY", "hash": "8c190d37960195bc8096ce2d7015135c2965a03c", "best_bid": "0.057", "best_ask": "0.085"}, {"asset_id": "19224712151342060925250675326667957156597084749312967133447388236247487979547", "price": "0.945", "size": "338.53", "side": "SELL", "hash": "eae68616d764ead1bed296261c480b9d00dbed99", "best_bid": "0.915", "best_ask": "0.943"}], "timestamp": "1769384576255", "event_type": "price_change"}}
{"_local_timestamp": "2026-01-25T23:42:56.350113+00:00", "data": {"market": "0xa281783fc73b1a6927a301ee34cd90795470dc64b500673e445ba5e54f697c09", "price_changes": [{"asset_id": "19224712151342060925250675326667957156597084749312967133447388236247487979547", "price": "0.913", "size": "75", "side": "BUY", "hash": "6bb7415638eda604cd98c3fb960a70d0d372f437", "best_bid": "0.915", "best_ask": "0.943"}, {"asset_id": "19470872781622450446330627562106312915240544924539183504885686468325701819521", "price": "0.087", "size": "75", "side": "SELL", "hash": "af3e5566df663d98b6daf40ae85e84f08c93c046", "best_bid": "0.057", "best_ask": "0.085"}], "timestamp": "1769384576255", "event_type": "price_change"}}
{"_local_timestamp": "2026-01-25T23:42:57.384376+00:00", "data": {"market": "0xa281783fc73b1a6927a301ee34cd90795470dc64b500673e445ba5e54f697c09", "price_changes": [{"asset_id": "19224712151342060925250675326667957156597084749312967133447388236247487979547", "price": "0.912", "size": "75.85", "side": "BUY", "hash": "913b8690654522fe3e235499563ec0029f9bfc70", "best_bid": "0.915", "best_ask": "0.943"}, {"asset_id": "19470872781622450446330627562106312915240544924539183504885686468325701819521", "price": "0.088", "size": "75.85", "side": "SELL", "hash": "a53f1cc298d8c9d223e43ec42c475e6a1ea96274", "best_bid": "0.057", "best_ask": "0.085"}], "timestamp": "1769384577294", "event_type": "price_change"}}
{"_local_timestamp": "2026-01-25T23:43:11.163833+00:00", "data": {"market": "0x3f9f68feccc892303834833665bf204632438b028254fc2d5bceea757ff61ed3", "price_changes": [{"asset_id": "36088399593046466421453063228085042771351246231742717370399696243183381174466", "price": "0.115", "size": "10.73", "side": "SELL", "hash": "df0e305bca96ca9f37d60f938afed938af3c27a4", "best_bid": "0.034", "best_ask": "0.111"}, {"asset_id": "11947171408899503371980811142475369274013053223377767646204433492871687017998", "price": "0.885", "size": "10.73", "side": "BUY", "hash": "b0f53555a392912b935b44892649d5b0f00b288c", "best_bid": "0.889", "best_ask": "0.966"}], "timestamp": "1769384591027", "event_type": "price_change"}}
{"_local_timestamp": "2026-01-25T23:43:11.247482+00:00", "data": {"market": "0x3f9f68feccc892303834833665bf204632438b028254fc2d5bceea757ff61ed3", "price_changes": [{"asset_id": "36088399593046466421453063228085042771351246231742717370399696243183381174466", "price": "0.034", "size": "32", "side": "BUY", "hash": "70e668873813bd9d92f5b313124cdb5a8d7805fa", "best_bid": "0.034", "best_ask": "0.111"}, {"asset_id": "11947171408899503371980811142475369274013053223377767646204433492871687017998", "price": "0.966", "size": "32", "side": "SELL", "hash": "48307dba81217e2fdde29ad9fd220a16afc747c5", "best_bid": "0.889", "best_ask": "0.966"}], "timestamp": "1769384591136", "event_type": "price_change"}}
{"_local_timestamp": "2026-01-25T23:43:11.254622+00:00", "data": {"market": "0x3f9f68feccc892303834833665bf204632438b028254fc2d5bceea757ff61ed3", "price_changes": [{"asset_id": "11947171408899503371980811142475369274013053223377767646204433492871687017998", "price": "0.885", "size": "0", "side": "BUY", "hash": "87aee101f7792583f06587887f4443a74962c009", "best_bid": "0.889", "best_ask": "0.966"}, {"asset_id": "36088399593046466421453063228085042771351246231742717370399696243183381174466", "price": "0.115", "size": "0", "side": "SELL", "hash": "d0e54ca98d592b82c52b0a06af3fd0e62b154edd", "best_bid": "0.034", "best_ask": "0.111"}], "timestamp": "1769384591149", "event_type": "price_change"}}
{"_local_timestamp": "2026-01-25T23:43:11.306805+00:00", "data": {"market": "0x08b39100a4d3d6ad1099e076fb69f781313c5b16975adf189d63542bd1ecca04", "price_changes": [{"asset_id": "6122912536415539457721068960901205060237919057489564846781206253065694717085", "price": "0.018", "size": "1196.2", "side": "BUY", "hash": "3ff33635402d45ee280a60e363eddc52bd8e6591", "best_bid": "0.018", "best_ask": "0.022"}, {"asset_id": "48451126471681390564675828610810240762308720916091458567360242927144088567337", "price": "0.982", "size": "1196.2", "side": "SELL", "hash": "875d7dfd8f2b14fc48fbd3ba18ffdb610d598d17", "best_bid": "0.978", "best_ask": "0.982"}], "timestamp": "1769384591196", "event_type": "price_change"}}
{"_local_timestamp": "2026-01-25T23:43:11.353146+00:00", "data": {"market": "0xa281783fc73b1a6927a301ee34cd90795470dc64b500673e445ba5e54f697c09", "price_changes": [{"asset_id": "19224712151342060925250675326667957156597084749312967133447388236247487979547", "price": "0.943", "size": "350.45", "side": "SELL", "hash": "af5736c09002ec2be3c75e78eaa99c5b5ed50db1", "best_bid": "0.915", "best_ask": "0.943"}, {"asset_id": "19470872781622450446330627562106312915240544924539183504885686468325701819521", "price": "0.057", "size": "350.45", "side": "BUY", "hash": "3c3ebe77cef7ebc3e9bcc556530f786c4c0ca7fa", "best_bid": "0.057", "best_ask": "0.085"}], "timestamp": "1769384591235", "event_type": "price_change"}}
{"_local_timestamp": "2026-01-25T23:43:45.605652+00:00", "data": {"market": "0x08b39100a4d3d6ad1099e076fb69f781313c5b16975adf189d63542bd1ecca04", "price_changes": [{"asset_id": "6122912536415539457721068960901205060237919057489564846781206253065694717085", "price": "0.018", "size": "1416.38", "side": "BUY", "hash": "51dd7d7c0cc8f0e04d43b1716ee96f0ee976dbd6", "best_bid": "0.018", "best_ask": "0.022"}, {"asset_id": "48451126471681390564675828610810240762308720916091458567360242927144088567337", "price": "0.982", "size": "1416.38", "side": "SELL", "hash": "1d1a899068e66abbd8f2e87cc63487444fe72e3c", "best_bid": "0.978", "best_ask": "0.982"}], "timestamp": "1769384625262", "event_type": "price_change"}}
{"_local_timestamp": "2026-01-25T23:43:49.268603+00:00", "data": {"market": "0x3f9f68feccc892303834833665bf204632438b028254fc2d5bceea757ff61ed3", "price_changes": [{"asset_id": "11947171408899503371980811142475369274013053223377767646204433492871687017998", "price": "0.889", "size": "41.87", "side": "BUY", "hash": "f18880e07cb1f92e0e4a76a8dbde44242ad83e67", "best_bid": "0.889", "best_ask": "0.966"}, {"asset_id": "36088399593046466421453063228085042771351246231742717370399696243183381174466", "price": "0.111", "size": "41.87", "side": "SELL", "hash": "7c5b9192e9439532aaadb0b496bb1291fe04eff3", "best_bid": "0.034", "best_ask": "0.111"}], "timestamp": "1769384629174", "event_type": "price_change"}}
{"_local_timestamp": "2026-01-25T23:43:49.423467+00:00", "data": {"market": "0x08b39100a4d3d6ad1099e076fb69f781313c5b16975adf189d63542bd1ecca04", "price_changes": [{"asset_id": "48451126471681390564675828610810240762308720916091458567360242927144088567337", "price": "0.759", "size": "0", "side": "BUY", "hash": "cb93db02f205c8afd8a0f8e650e5b514e890c49d", "best_bid": "0.978", "best_ask": "0.982"}, {"asset_id": "6122912536415539457721068960901205060237919057489564846781206253065694717085", "price": "0.241", "size": "0", "side": "SELL", "hash": "237e75e66f898c426a6721be0e5191b17471b146", "best_bid": "0.018", "best_ask": "0.022"}], "timestamp": "1769384629326", "event_type": "price_change"}}
{"_local_timestamp": "2026-01-25T23:43:49.471798+00:00", "data": {"market": "0x08b39100a4d3d6ad1099e076fb69f781313c5b16975adf189d63542bd1ecca04", "price_changes": [{"asset_id": "48451126471681390564675828610810240762308720916091458567360242927144088567337", "price": "0.761", "size": "15", "side": "BUY", "hash": "4d988ee9aaf85267ec89f828d123ebd53f5d6469", "best_bid": "0.978", "best_ask": "0.982"}, {"asset_id": "6122912536415539457721068960901205060237919057489564846781206253065694717085", "price": "0.239", "size": "15", "side": "SELL", "hash": "6b12a7a6f08d61ff6de6accab733f3201a388dd4", "best_bid": "0.018", "best_ask": "0.022"}], "timestamp": "1769384629372", "event_type": "price_change"}}
{"_local_timestamp": "2026-01-25T23:43:49.473247+00:00", "data": {"market": "0x08b39100a4d3d6ad1099e076fb69f781313c5b16975adf189d63542bd1ecca04", "price_changes": [{"asset_id": "48451126471681390564675828610810240762308720916091458567360242927144088567337", "price": "0.761", "size": "25", "side": "BUY", "hash": "a58da1637f764c260025a3c606c2c232e586094d", "best_bid": "0.978", "best_ask": "0.982"}, {"asset_id": "6122912536415539457721068960901205060237919057489564846781206253065694717085", "price": "0.239", "size": "25", "side": "SELL", "hash": "b4f9a786b0766532f6946ab5d39cd0304cd994e7", "best_bid": "0.018", "best_ask": "0.022"}], "timestamp": "1769384629373", "event_type": "price_change"}}
{"_local_timestamp": "2026-01-25T23:43:50.380238+00:00", "data": {"market": "0x08b39100a4d3d6ad1099e076fb69f781313c5b16975adf189d63542bd1ecca04", "price_changes": [{"asset_id": "48451126471681390564675828610810240762308720916091458567360242927144088567337", "price": "0.76", "size": "0", "side": "BUY", "hash": "5fe6d74d0c23eb357ea4519b7ec4bfcd138a21c6", "best_bid": "0.978", "best_ask": "0.982"}, {"asset_id": "6122912536415539457721068960901205060237919057489564846781206253065694717085", "price": "0.24", "size": "0", "side": "SELL", "hash": "485707ad75fd7d24e8dcf1cb1895b67d45b876cd", "best_bid": "0.018", "best_ask": "0.022"}], "timestamp": "1769384630205", "event_type": "price_change"}}
{"_local_timestamp": "2026-01-25T23:43:50.412548+00:00", "data": {"market": "0x08b39100a4d3d6ad1099e076fb69f781313c5b16975adf189d63542bd1ecca04", "price_changes": [{"asset_id": "48451126471681390564675828610810240762308720916091458567360242927144088567337", "price": "0.762", "size": "20", "side": "BUY", "hash": "a7fb4bdec68f4fa8615fb747a6c948335f1cafad", "best_bid": "0.978", "best_ask": "0.982"}, {"asset_id": "6122912536415539457721068960901205060237919057489564846781206253065694717085", "price": "0.238", "size": "20", "side": "SELL", "hash": "0f72e9474851fcc408168414544211553c16d35f", "best_bid": "0.018", "best_ask": "0.022"}], "timestamp": "1769384630233", "event_type": "price_change"}}
{"_local_timestamp": "2026-01-25T23:43:53.558369+00:00", "data": {"market": "0x3849e1d62e0807801913d3e2427e8caf3cc6dd1c8ef42d8d5c08c6f9c449dc5e", "price_changes": [{"asset_id": "56615676606297588259337956203332341775475048285080710344367729433788967812170", "price": "0.7", "size": "917.84", "side": "SELL", "hash": "1a84fd97c175a22cf78be8f54e76e3ba7a5e69d9", "best_bid": "0.67", "best_ask": "0.7"}, {"asset_id": "8070607953656787024050950499598687532281829563384949938603247089607814583142", "price": "0.3", "size": "917.84", "side": "BUY", "hash": "424a8b2d436398e4f2453ad6bbbad829a222cfed", "best_bid": "0.3", "best_ask": "0.33"}], "timestamp": "1769384633407", "event_type": "price_change"}}
{"_local_timestamp": "2026-01-25T23:43:54.586475+00:00", "data": {"market": "0xa281783fc73b1a6927a301ee34cd90795470dc64b500673e445ba5e54f697c09", "price_changes": [{"asset_id": "19224712151342060925250675326667957156597084749312967133447388236247487979547", "price": "0.943", "size": "416.14", "side": "SELL", "hash": "ab5fdc269ceefdb20626c63e7d5cdb95b458b4a9", "best_bid": "0.915", "best_ask": "0.943"}, {"asset_id": "19470872781622450446330627562106312915240544924539183504885686468325701819521", "price": "0.057", "size": "416.14", "side": "BUY", "hash": "74a5b69446fd7e075be2ed52918d6783e9662778", "best_bid": "0.057", "best_ask": "0.085"}], "timestamp": "1769384634435", "event_type": "price_change"}}
{"_local_timestamp": "2026-01-25T23:44:00.593393+00:00", "data": {"market": "0x3f9f68feccc892303834833665bf204632438b028254fc2d5bceea757ff61ed3", "price_changes": [{"asset_id": "36088399593046466421453063228085042771351246231742717370399696243183381174466", "price": "0.111", "size": "64.81", "side": "SELL", "hash": "cf16dd77d0de5ee5b6251f672c538e1d6f746778", "best_bid": "0.034", "best_ask": "0.111"}, {"asset_id": "11947171408899503371980811142475369274013053223377767646204433492871687017998", "price": "0.889", "size": "64.81", "side": "BUY", "hash": "3c12be68a462fe652fc8d34061aa87bc656b4895", "best_bid": "0.889", "best_ask": "0.966"}], "timestamp": "1769384640451", "event_type": "price_change"}}
{"_local_timestamp": "2026-01-25T23:44:01.503041+00:00", "data": {"market": "0x3f9f68feccc892303834833665bf204632438b028254fc2d5bceea757ff61ed3", "price_changes": [{"asset_id": "36088399593046466421453063228085042771351246231742717370399696243183381174466", "price": "0.116", "size": "0", "side": "SELL", "hash": "a22cf1ddbdf37aba689353bc00f2879bccffa033", "best_bid": "0.034", "best_ask": "0.111"}, {"asset_id": "11947171408899503371980811142475369274013053223377767646204433492871687017998", "price": "0.884", "size": "0", "side": "BUY", "hash": "b92ce432f0595618de730854b9058881f4ce7b55", "best_bid": "0.889", "best_ask": "0.966"}], "timestamp": "1769384641349", "event_type": "price_change"}}
{"_local_timestamp": "2026-01-25T23:44:01.556566+00:00", "data": {"market": "0x3f9f68feccc892303834833665bf204632438b028254fc2d5bceea757ff61ed3", "price_changes": [{"asset_id": "36088399593046466421453063228085042771351246231742717370399696243183381174466", "price": "0.11", "size": "30", "side": "SELL", "hash": "18538583cb4044e8b0e625f05c1f2f6d77242658", "best_bid": "0.034", "best_ask": "0.11"}, {"asset_id": "11947171408899503371980811142475369274013053223377767646204433492871687017998", "price": "0.89", "size": "30", "side": "BUY", "hash": "4e4c79f1d499da595f018d9b60c6db0103de13fc", "best_bid": "0.89", "best_ask": "0.966"}], "timestamp": "1769384641409", "event_type": "price_change"}}
{"_local_timestamp": "2026-01-25T23:44:01.943217+00:00", "data": {"market": "0xb77424a53b7480164118374fb5e97b859bd12b696b1aea55d383ce798c060cf4", "price_changes": [{"asset_id": "86904220753614324927759730619985568200215013704321476651673438801320577270597", "price": "0.058", "size": "174.9", "side": "BUY", "hash": "2c0aa19aede557886ae6cc1527b477b74d40288e", "best_bid": "0.058", "best_ask": "0.066"}, {"asset_id": "74987521271361072746264224488245891269775371028979674431826416209897741154003", "price": "0.942", "size": "174.9", "side": "SELL", "hash": "ccdb0e5602ba16fefea0596f564026fc4971a104", "best_bid": "0.934", "best_ask": "0.942"}], "timestamp": "1769384641796", "event_type": "price_change"}}
{"_local_timestamp": "2026-01-25T23:44:01.944396+00:00", "data": {"market": "0xb77424a53b7480164118374fb5e97b859bd12b696b1aea55d383ce798c060cf4", "price_changes": [{"asset_id": "86904220753614324927759730619985568200215013704321476651673438801320577270597", "price": "0.067", "size": "10", "side": "SELL", "hash": "2c0aa19aede557886ae6cc1527b477b74d40288e", "best_bid": "0.058", "best_ask": "0.066"}, {"asset_id": "74987521271361072746264224488245891269775371028979674431826416209897741154003", "price": "0.933", "size": "10", "side": "BUY", "hash": "ccdb0e5602ba16fefea0596f564026fc4971a104", "best_bid": "0.934", "best_ask": "0.942"}], "timestamp": "1769384641796", "event_type": "price_change"}}
{"_local_timestamp": "2026-01-25T23:44:01.969794+00:00", "data": {"market": "0xb77424a53b7480164118374fb5e97b859bd12b696b1aea55d383ce798c060cf4", "price_changes": [{"asset_id": "86904220753614324927759730619985568200215013704321476651673438801320577270597", "price": "0.067", "size": "60", "side": "SELL", "hash": "c472566a14ceaaa5dc48f8e8b97b818c611151c2", "best_bid": "0.058", "best_ask": "0.066"}, {"asset_id": "74987521271361072746264224488245891269775371028979674431826416209897741154003", "price": "0.933", "size": "60", "side": "BUY", "hash": "f76dd84b797d02ae3ea7ca95c5aaeac4e1742c65", "best_bid": "0.934", "best_ask": "0.942"}], "timestamp": "1769384641825", "event_type": "price_change"}}
{"_local_timestamp": "2026-01-25T23:44:02.223599+00:00", "data": {"market": "0x3f9f68feccc892303834833665bf204632438b028254fc2d5bceea757ff61ed3", "price_changes": [{"asset_id": "11947171408899503371980811142475369274013053223377767646204433492871687017998", "price": "0.883", "size": "53.2", "side": "BUY", "hash": "ff4391eea24265eaff17dfcee626df42a236310d", "best_bid": "0.89", "best_ask": "0.966"}, {"asset_id": "36088399593046466421453063228085042771351246231742717370399696243183381174466", "price": "0.117", "size": "53.2", "side": "SELL", "hash": "5fc9040ac1fcba20d3e28820095048ab83673f60", "best_bid": "0.034", "best_ask": "0.11"}], "timestamp": "1769384642080", "event_type": "price_change"}}
{"_local_timestamp": "2026-01-25T23:44:02.273833+00:00", "data": {"market": "0x3f9f68feccc892303834833665bf204632438b028254fc2d5bceea757ff61ed3", "price_changes": [{"asset_id": "11947171408899503371980811142475369274013053223377767646204433492871687017998", "price": "0.889", "size": "94.81", "side": "BUY", "hash": "5440544e5bf29206f5847d7505f7fc9afb0ed479", "best_bid": "0.89", "best_ask": "0.966"}, {"asset_id": "36088399593046466421453063228085042771351246231742717370399696243183381174466", "price": "0.111", "size": "94.81", "side": "SELL", "hash": "a7dd628ce555d9a381b0a30d09cc37492db9080b", "best_bid": "0.034", "best_ask": "0.11"}], "timestamp": "1769384642128", "event_type": "price_change"}}
{"_local_timestamp": "2026-01-25T23:44:04.797958+00:00", "data": {"market": "0x3849e1d62e0807801913d3e2427e8caf3cc6dd1c8ef42d8d5c08c6f9c449dc5e", "price_changes": [{"asset_id": "56615676606297588259337956203332341775475048285080710344367729433788967812170", "price": "0.16", "size": "2624", "side": "BUY", "hash": "c96e8129289529b6e293fc891c32afc1106e7e13", "best_bid": "0.67", "best_ask": "0.7"}, {"asset_id": "8070607953656787024050950499598687532281829563384949938603247089607814583142", "price": "0.84", "size": "2624", "side": "SELL", "hash": "b1ad4dd6ece971e51ce767bccb0c66022433445a", "best_bid": "0.3", "best_ask": "0.33"}], "timestamp": "1769384644655", "event_type": "price_change"}}
{"_local_timestamp": "2026-01-25T23:44:07.449485+00:00", "data": {"market": "0x602a7a6c7d65b55932e6cf8b6904cb7acdc728ca423ffd3ccb1988dd5501de13", "price_changes": [{"asset_id": "18399565751068676179945656979762090460558422925963909399757895217338947077684", "price": "0.927", "size": "250", "side": "BUY", "hash": "21f91fb49981c6f2b629f1c3e1fe09ff3792cd94", "best_bid": "0.941", "best_ask": "0.952"}, {"asset_id": "88770632741686298370270294037614812817595949782311984579833554458717957886356", "price": "0.073", "size": "250", "side": "SELL", "hash": "9401aa58f892c7dd148809c23c9fd20a4dac01b9", "best_bid": "0.048", "best_ask": "0.059"}], "timestamp": "1769384647293", "event_type": "price_change"}}
{"_local_timestamp": "2026-01-25T23:44:07.451879+00:00", "data": {"market": "0x602a7a6c7d65b55932e6cf8b6904cb7acdc728ca423ffd3ccb1988dd5501de13", "price_changes": [{"asset_id": "88770632741686298370270294037614812817595949782311984579833554458717957886356", "price": "0.013", "size": "5115.08", "side": "BUY", "hash": "6705e73c495d12d81044245a1697cb89adb6e296", "best_bid": "0.048", "best_ask": "0.059"}, {"asset_id": "18399565751068676179945656979762090460558422925963909399757895217338947077684", "price": "0.987", "size": "5115.08", "side": "SELL", "hash": "52fb108e3361d003000648b316dd85d3f6defca2", "best_bid": "0.941", "best_ask": "0.952"}], "timestamp": "1769384647294", "event_type": "price_change"}}
{"_local_timestamp": "2026-01-25T23:44:08.698270+00:00", "data": {"market": "0x3849e1d62e0807801913d3e2427e8caf3cc6dd1c8ef42d8d5c08c6f9c449dc5e", "price_changes": [{"asset_id": "56615676606297588259337956203332341775475048285080710344367729433788967812170", "price": "0.15", "size": "0", "side": "BUY", "hash": "8654469a84a27fa084a1b72cc081a0b413b51308", "best_bid": "0.67", "best_ask": "0.7"}, {"asset_id": "8070607953656787024050950499598687532281829563384949938603247089607814583142", "price": "0.85", "size": "0", "side": "SELL", "hash": "e461e5f08c38bc67fac02f0152eef195a5c996b0", "best_bid": "0.3", "best_ask": "0.33"}], "timestamp": "1769384648428", "event_type": "price_change"}}
{"_local_timestamp": "2026-01-25T23:44:09.067468+00:00", "data": {"market": "0x3849e1d62e0807801913d3e2427e8caf3cc6dd1c8ef42d8d5c08c6f9c449dc5e", "price_changes": [{"asset_id": "56615676606297588259337956203332341775475048285080710344367729433788967812170", "price": "0.11", "size": "742.09", "side": "BUY", "hash": "c73b92d09d174534402ba2a76dec188d3cfffa7d", "best_bid": "0.67", "best_ask": "0.7"}, {"asset_id": "8070607953656787024050950499598687532281829563384949938603247089607814583142", "price": "0.89", "size": "742.09", "side": "SELL", "hash": "eafb5d5253d11306a131f5c2b5d67f6454e4a94a", "best_bid": "0.3", "best_ask": "0.33"}], "timestamp": "1769384648753", "event_type": "price_change"}}
{"_local_timestamp": "2026-01-25T23:44:09.146613+00:00", "data": {"market": "0x3849e1d62e0807801913d3e2427e8caf3cc6dd1c8ef42d8d5c08c6f9c449dc5e", "price_changes": [{"asset_id": "56615676606297588259337956203332341775475048285080710344367729433788967812170", "price": "0.24", "size": "800", "side": "BUY", "hash": "6bcb8cadc4f7456a0244b94288a9aa2d9690d6f0", "best_bid": "0.67", "best_ask": "0.7"}, {"asset_id": "8070607953656787024050950499598687532281829563384949938603247089607814583142", "price": "0.76", "size": "800", "side": "SELL", "hash": "2f5e6602deea67fc8a7dbc8be18deaaa79f4fb24", "best_bid": "0.3", "best_ask": "0.33"}], "timestamp": "1769384648830", "event_type": "price_change"}}
{"_local_timestamp": "2026-01-25T23:44:21.090136+00:00", "data": {"market": "0xa281783fc73b1a6927a301ee34cd90795470dc64b500673e445ba5e54f697c09", "price_changes": [{"asset_id": "19224712151342060925250675326667957156597084749312967133447388236247487979547", "price": "0.909", "size": "50", "side": "BUY", "hash": "44b52f8bc43455983db88a15af00606178203d15", "best_bid": "0.915", "best_ask": "0.943"}, {"asset_id": "19470872781622450446330627562106312915240544924539183504885686468325701819521", "price": "0.091", "size": "50", "side": "SELL", "hash": "4fec8d6f68f9e65a87ee53ddf2b77ef30007f861", "best_bid": "0.057", "best_ask": "0.085"}], "timestamp": "1769384660632", "event_type": "price_change"}}
{"_local_timestamp": "2026-01-25T23:44:21.092172+00:00", "data": {"market": "0xa281783fc73b1a6927a301ee34cd90795470dc64b500673e445ba5e54f697c09", "price_changes": [{"asset_id": "19470872781622450446330627562106312915240544924539183504885686468325701819521", "price": "0.051", "size": "50", "side": "BUY", "hash": "b4e527f8fd1fe8869395ae678dd5d4d43a6c844c", "best_bid": "0.057", "best_ask": "0.085"}, {"asset_id": "19224712151342060925250675326667957156597084749312967133447388236247487979547", "price": "0.949", "size": "50", "side": "SELL", "hash": "fc6936bad6acae66d1f3feb3de0df93eb161798f", "best_bid": "0.915", "best_ask": "0.943"}], "timestamp": "1769384660633", "event_type": "price_change"}}
{"_local_timestamp": "2026-01-25T23:44:21.393262+00:00", "data": {"market": "0xa281783fc73b1a6927a301ee34cd90795470dc64b500673e445ba5e54f697c09", "price_changes": [{"asset_id": "19224712151342060925250675326667957156597084749312967133447388236247487979547", "price": "0.913", "size": "25", "side": "BUY", "hash": "d884654d2932357c301418be670ffae76cd2721b", "best_bid": "0.915", "best_ask": "0.943"}, {"asset_id": "19470872781622450446330627562106312915240544924539183504885686468325701819521", "price": "0.087", "size": "25", "side": "SELL", "hash": "aafbd1fed8d3ffb87ebfa31c489f5e7efdc67b98", "best_bid": "0.057", "best_ask": "0.085"}], "timestamp": "1769384660923", "event_type": "price_change"}}
{"_local_timestamp": "2026-01-25T23:44:21.513429+00:00", "data": {"market": "0xa281783fc73b1a6927a301ee34cd90795470dc64b500673e445ba5e54f697c09", "price_changes": [{"asset_id": "19470872781622450446330627562106312915240544924539183504885686468325701819521", "price": "0.055", "size": "288.53", "side": "BUY", "hash": "dc98f402cd0187f6e855210935144385cf0dd2b2", "best_bid": "0.057", "best_ask": "0.085"}, {"asset_id": "19224712151342060925250675326667957156597084749312967133447388236247487979547", "price": "0.945", "size": "288.53", "side": "SELL", "hash": "7a099a8c80f99c2fdedb86ec81e5a7f3ff422b1e", "best_bid": "0.915", "best_ask": "0.943"}], "timestamp": "1769384660924", "event_type": "price_change"}}
{"_local_timestamp": "2026-01-25T23:44:21.613212+00:00", "data": {"market": "0x3849e1d62e0807801913d3e2427e8caf3cc6dd1c8ef42d8d5c08c6f9c449dc5e", "price_changes": [{"asset_id": "56615676606297588259337956203332341775475048285080710344367729433788967812170", "price": "0.34", "size": "125", "side": "BUY", "hash": "800a7ff077ef5042e250e896df394e7131784799", "best_bid": "0.67", "best_ask": "0.7"}, {"asset_id": "8070607953656787024050950499598687532281829563384949938603247089607814583142", "price": "0.66", "size": "125", "side": "SELL", "hash": "c1ee13573fcf339bc7d201873147b08de6113dbe", "best_bid": "0.3", "best_ask": "0.33"}], "timestamp": "1769384660910", "event_type": "price_change"}}
{"_local_timestamp": "2026-01-25T23:44:21.812466+00:00", "data": {"market": "0xa281783fc73b1a6927a301ee34cd90795470dc64b500673e445ba5e54f697c09", "price_changes": [{"asset_id": "19224712151342060925250675326667957156597084749312967133447388236247487979547", "price": "0.909", "size": "100", "side": "BUY", "hash": "2f71627d42a5eeb9328e4343a0695c7b476eb62b", "best_bid": "0.915", "best_ask": "0.943"}, {"asset_id": "19470872781622450446330627562106312915240544924539183504885686468325701819521", "price": "0.091", "size": "100", "side": "SELL", "hash": "fd1ed7993b5366739e1ff3ada851464502464f4a", "best_bid": "0.057", "best_ask": "0.085"}], "timestamp": "1769384661103", "event_type": "price_change"}}
{"_local_timestamp": "2026-01-25T23:44:21.814950+00:00", "data": {"market": "0xa281783fc73b1a6927a301ee34cd90795470dc64b500673e445ba5e54f697c09", "price_changes": [{"asset_id": "19470872781622450446330627562106312915240544924539183504885686468325701819521", "price": "0.055", "size": "338.53", "side": "BUY", "hash": "326f6e8273faa369a3aa4c3907b5d0d0521e58fc", "best_bid": "0.057", "best_ask": "0.085"}, {"asset_id": "19224712151342060925250675326667957156597084749312967133447388236247487979547", "price": "0.945", "size": "338.53", "side": "SELL", "hash": "cee67ce28d5c50bec0a9edff3611ee8f74d90f73", "best_bid": "0.915", "best_ask": "0.943"}], "timestamp": "1769384661104", "event_type": "price_change"}}
{"_local_timestamp": "2026-01-25T23:44:21.816219+00:00", "data": {"market": "0xa281783fc73b1a6927a301ee34cd90795470dc64b500673e445ba5e54f697c09", "price_changes": [{"asset_id": "19224712151342060925250675326667957156597084749312967133447388236247487979547", "price": "0.912", "size": "105.85", "side": "BUY", "hash": "500c3d594db21a17168762718ccc42dccd6b7d7f", "best_bid": "0.915", "best_ask": "0.943"}, {"asset_id": "19470872781622450446330627562106312915240544924539183504885686468325701819521", "price": "0.088", "size": "105.85", "side": "SELL", "hash": "340e4d96f498febf823a75bbd54eb0c0101f478b", "best_bid": "0.057", "best_ask": "0.085"}], "timestamp": "1769384661324", "event_type": "price_change"}}
{"_local_timestamp": "2026-01-25T23:44:21.893763+00:00", "data": {"market": "0xa281783fc73b1a6927a301ee34cd90795470dc64b500673e445ba5e54f697c09", "price_changes": [{"asset_id": "19470872781622450446330627562106312915240544924539183504885686468325701819521", "price": "0.035", "size": "505.79", "side": "BUY", "hash": "bb3ccd6b9723e823aeb669b9a71b4b4a455f6c78", "best_bid": "0.057", "best_ask": "0.085"}, {"asset_id": "19224712151342060925250675326667957156597084749312967133447388236247487979547", "price": "0.965", "size": "505.79", "side": "SELL", "hash": "735e9b378f318002208b703f819067c5d45f1b63", "best_bid": "0.915", "best_ask": "0.943"}], "timestamp": "1769384661620", "event_type": "price_change"}}
{"_local_timestamp": "2026-01-25T23:44:25.379817+00:00", "data": {"market": "0xa281783fc73b1a6927a301ee34cd90795470dc64b500673e445ba5e54f697c09", "price_changes": [{"asset_id": "19470872781622450446330627562106312915240544924539183504885686468325701819521", "price": "0.036", "size": "100", "side": "BUY", "hash": "26a3d2336717c4fe8ffffe6c0aa56a53eadbf11e", "best_bid": "0.057", "best_ask": "0.085"}, {"asset_id": "19224712151342060925250675326667957156597084749312967133447388236247487979547", "price": "0.964", "size": "100", "side": "SELL", "hash": "5b775f6ec67a9c26a2ebb69afa90870a9ea6eec0", "best_bid": "0.915", "best_ask": "0.943"}], "timestamp": "1769384665126", "event_type": "price_change"}}
{"_local_timestamp": "2026-01-25T23:44:32.670024+00:00", "data": {"market": "0x3849e1d62e0807801913d3e2427e8caf3cc6dd1c8ef42d8d5c08c6f9c449dc5e", "price_changes": [{"asset_id": "56615676606297588259337956203332341775475048285080710344367729433788967812170", "price": "0.16", "size": "0", "side": "BUY", "hash": "e3053cd8d1e6844909f3621e46b4c98cadcff859", "best_bid": "0.67", "best_ask": "0.7"}, {"asset_id": "8070607953656787024050950499598687532281829563384949938603247089607814583142", "price": "0.84", "size": "0", "side": "SELL", "hash": "7550ba3fecff17955336ec03ff548d66e49a2df3", "best_bid": "0.3", "best_ask": "0.33"}], "timestamp": "1769384672298", "event_type": "price_change"}}
{"_local_timestamp": "2026-01-25T23:44:32.741676+00:00", "data": {"market": "0xa281783fc73b1a6927a301ee34cd90795470dc64b500673e445ba5e54f697c09", "price_changes": [{"asset_id": "19224712151342060925250675326667957156597084749312967133447388236247487979547", "price": "0.381", "size": "25", "side": "BUY", "hash": "0d88ae5967e4ed3fa5b4d683f56ecf1696cb0ebd", "best_bid": "0.915", "best_ask": "0.943"}, {"asset_id": "19470872781622450446330627562106312915240544924539183504885686468325701819521", "price": "0.619", "size": "25", "side": "SELL", "hash": "ce08d17e9ad19ab07c4d82561eda27ed06868e18", "best_bid": "0.057", "best_ask": "0.085"}], "timestamp": "1769384672460", "event_type": "price_change"}}
{"_local_timestamp": "2026-01-25T23:44:34.713345+00:00", "data": {"market": "0xa281783fc73b1a6927a301ee34cd90795470dc64b500673e445ba5e54f697c09", "price_changes": [{"asset_id": "19470872781622450446330627562106312915240544924539183504885686468325701819521", "price": "0.086", "size": "0", "side": "SELL", "hash": "06970ac06804ada5ea7c2d2331b50279a380acd7", "best_bid": "0.057", "best_ask": "0.085"}, {"asset_id": "19224712151342060925250675326667957156597084749312967133447388236247487979547", "price": "0.914", "size": "0", "side": "BUY", "hash": "58a79d60aeaf46b341d2d8f9e3f9c0a45e72211e", "best_bid": "0.915", "best_ask": "0.943"}], "timestamp": "1769384674443", "event_type": "price_change"}}
{"_local_timestamp": "2026-01-25T23:44:34.746626+00:00", "data": {"market": "0xa281783fc73b1a6927a301ee34cd90795470dc64b500673e445ba5e54f697c09", "price_changes": [{"asset_id": "19224712151342060925250675326667957156597084749312967133447388236247487979547", "price": "0.859", "size": "0", "side": "BUY", "hash": "5c1292d975bdb4fc6e965d686377a57a664abc85", "best_bid": "0.915", "best_ask": "0.943"}, {"asset_id": "19470872781622450446330627562106312915240544924539183504885686468325701819521", "price": "0.141", "size": "0", "side": "SELL", "hash": "57139d76446f2df3eee12b8965364b20f94f1c67", "best_bid": "0.057", "best_ask": "0.085"}], "timestamp": "1769384674467", "event_type": "price_change"}}
{"_local_timestamp": "2026-01-25T23:44:34.766783+00:00", "data": {"market": "0x3f9f68feccc892303834833665bf204632438b028254fc2d5bceea757ff61ed3", "price_changes": [{"asset_id": "11947171408899503371980811142475369274013053223377767646204433492871687017998", "price": "0.882", "size": "250.45", "side": "BUY", "hash": "1171dba8b235acda705320dc89c1b4fed9e2b2f0", "best_bid": "0.89", "best_ask": "0.966"}, {"asset_id": "36088399593046466421453063228085042771351246231742717370399696243183381174466", "price": "0.118", "size": "250.45", "side": "SELL", "hash": "acd93f5939239f61c196b8e6b5ac4be0b59a0179", "best_bid": "0.034", "best_ask": "0.11"}], "timestamp": "1769384674474", "event_type": "price_change"}}
{"_local_timestamp": "2026-01-25T23:44:34.998547+00:00", "data": {"market": "0xa281783fc73b1a6927a301ee34cd90795470dc64b500673e445ba5e54f697c09", "price_changes": [{"asset_id": "19470872781622450446330627562106312915240544924539183504885686468325701819521", "price": "0.087", "size": "31.32", "side": "SELL", "hash": "1c12ffb8f1d858620b07ca389e5e7451bf55a4ff", "best_bid": "0.057", "best_ask": "0.085"}, {"asset_id": "19224712151342060925250675326667957156597084749312967133447388236247487979547", "price": "0.913", "size": "31.32", "side": "BUY", "hash": "3a179895a1b342ab0a2b548dc8eaf1a21c047369", "best_bid": "0.915", "best_ask": "0.943"}], "timestamp": "1769384674718", "event_type": "price_change"}}
{"_local_timestamp": "2026-01-25T23:44:35.069031+00:00", "data": {"market": "0xb77424a53b7480164118374fb5e97b859bd12b696b1aea55d383ce798c060cf4", "price_changes": [{"asset_id": "86904220753614324927759730619985568200215013704321476651673438801320577270597", "price": "0.058", "size": "224.9", "side": "BUY", "hash": "f7453996efbbf9966cc7951e796f7cbfcc293705", "best_bid": "0.058", "best_ask": "0.066"}, {"asset_id": "74987521271361072746264224488245891269775371028979674431826416209897741154003", "price": "0.942", "size": "224.9", "side": "SELL", "hash": "a3bc65ca3d7c239351ecde8806d6063e31c8ef55", "best_bid": "0.934", "best_ask": "0.942"}], "timestamp": "1769384674800", "event_type": "price_change"}}
{"_local_timestamp": "2026-01-25T23:44:35.729716+00:00", "data": {"market": "0xa281783fc73b1a6927a301ee34cd90795470dc64b500673e445ba5e54f697c09", "price_changes": [{"asset_id": "19224712151342060925250675326667957156597084749312967133447388236247487979547", "price": "0.912", "size": "75.85", "side": "BUY", "hash": "28fafc01c1fb06105533d275ed0b342a61c7c848", "best_bid": "0.915", "best_ask": "0.943"}, {"asset_id": "19470872781622450446330627562106312915240544924539183504885686468325701819521", "price": "0.088", "size": "75.85", "side": "SELL", "hash": "008d8eae52c27ef31b22e8ab852154424ffd7fba", "best_bid": "0.057", "best_ask": "0.085"}], "timestamp": "1769384675439", "event_type": "price_change"}}
{"_local_timestamp": "2026-01-25T23:44:47.704737+00:00", "data": {"market": "0x3f9f68feccc892303834833665bf204632438b028254fc2d5bceea757ff61ed3", "price_changes": [{"asset_id": "11947171408899503371980811142475369274013053223377767646204433492871687017998", "price": "0.888", "size": "0", "side": "BUY", "hash": "ff5a24e8f654240c82913def6bc3be0d3dc818ed", "best_bid": "0.89", "best_ask": "0.966"}, {"asset_id": "36088399593046466421453063228085042771351246231742717370399696243183381174466", "price": "0.112", "size": "0", "side": "SELL", "hash": "ecd999f79e4c4d5fb40f9bab327bb0dd40a729a4", "best_bid": "0.034", "best_ask": "0.11"}], "timestamp": "1769384687466", "event_type": "price_change"}}
{"_local_timestamp": "2026-01-25T23:44:47.792385+00:00", "data": {"market": "0xa281783fc73b1a6927a301ee34cd90795470dc64b500673e445ba5e54f697c09", "price_changes": [{"asset_id": "19224712151342060925250675326667957156597084749312967133447388236247487979547", "price": "0.907", "size": "50", "side": "BUY", "hash": "5d3b290c66cc5a714912d8ab3e3a331fc1f45ca7", "best_bid": "0.915", "best_ask": "0.943"}, {"asset_id": "19470872781622450446330627562106312915240544924539183504885686468325701819521", "price": "0.093", "size": "50", "side": "SELL", "hash": "6ae3b74f04971843f301ccab56a64748b7c55375", "best_bid": "0.057", "best_ask": "0.085"}], "timestamp": "1769384687501", "event_type": "price_change"}}
{"_local_timestamp": "2026-01-25T23:44:48.203556+00:00", "data": {"market": "0x3f9f68feccc892303834833665bf204632438b028254fc2d5bceea757ff61ed3", "price_changes": [{"asset_id": "11947171408899503371980811142475369274013053223377767646204433492871687017998", "price": "0.889", "size": "64.81", "side": "BUY", "hash": "1f9229fdab8fcd8d4b6b99b05207d7617507f620", "best_bid": "0.89", "best_ask": "0.966"}, {"asset_id": "36088399593046466421453063228085042771351246231742717370399696243183381174466", "price": "0.111", "size": "64.81", "side": "SELL", "hash": "1437bed40d25a569b722f8065804fecd4c7e2ed7", "best_bid": "0.034", "best_ask": "0.11"}], "timestamp": "1769384688003", "event_type": "price_change"}}
{"_local_timestamp": "2026-01-25T23:44:48.246465+00:00", "data": {"market": "0xa281783fc73b1a6927a301ee34cd90795470dc64b500673e445ba5e54f697c09", "price_changes": [{"asset_id": "19224712151342060925250675326667957156597084749312967133447388236247487979547", "price": "0.912", "size": "105.85", "side": "BUY", "hash": "3b6ca82fb8a962d8b9e86108af3fe17e2ef7e984", "best_bid": "0.915", "best_ask": "0.943"}, {"asset_id": "19470872781622450446330627562106312915240544924539183504885686468325701819521", "price": "0.088", "size": "105.85", "side": "SELL", "hash": "407b63ded1203aeca61ae86b01e8ce2afcba7895", "best_bid": "0.057", "best_ask": "0.085"}], "timestamp": "1769384688071", "event_type": "price_change"}}
{"_local_timestamp": "2026-01-25T23:44:53.343561+00:00", "data": {"market": "0x3f9f68feccc892303834833665bf204632438b028254fc2d5bceea757ff61ed3", "price_changes": [{"asset_id": "11947171408899503371980811142475369274013053223377767646204433492871687017998", "price": "0.966", "size": "25", "side": "SELL", "hash": "468a07313fdb48c67b9b3b040955b6cc325770fe", "best_bid": "0.89", "best_ask": "0.966"}, {"asset_id": "36088399593046466421453063228085042771351246231742717370399696243183381174466", "price": "0.034", "size": "25", "side": "BUY", "hash": "944168308160eb9e62d71872e161f887d9cbb9c3", "best_bid": "0.034", "best_ask": "0.11"}], "timestamp": "1769384693263", "event_type": "price_change"}}
{"_local_timestamp": "2026-01-25T23:44:53.538738+00:00", "data": {"market": "0x3f9f68feccc892303834833665bf204632438b028254fc2d5bceea757ff61ed3", "price_changes": [{"asset_id": "11947171408899503371980811142475369274013053223377767646204433492871687017998", "price": "0.966", "size": "32", "side": "SELL", "hash": "7a33e0b431161243c24fd1f9c3ba8d3c5f437cd6", "best_bid": "0.89", "best_ask": "0.966"}, {"asset_id": "36088399593046466421453063228085042771351246231742717370399696243183381174466", "price": "0.034", "size": "32", "side": "BUY", "hash": "f920dbb078673f5972fab953316ef0a5375bfead", "best_bid": "0.034", "best_ask": "0.11"}], "timestamp": "1769384693458", "event_type": "price_change"}}
{"_local_timestamp": "2026-01-25T23:44:57.049718+00:00", "data": {"market": "0x3849e1d62e0807801913d3e2427e8caf3cc6dd1c8ef42d8d5c08c6f9c449dc5e", "price_changes": [{"asset_id": "8070607953656787024050950499598687532281829563384949938603247089607814583142", "price": "0.28", "size": "3803.99", "side": "BUY", "hash": "4989b30b05dcc0f1314deaf92086ea714ee806b1", "best_bid": "0.3", "best_ask": "0.33"}, {"asset_id": "56615676606297588259337956203332341775475048285080710344367729433788967812170", "price": "0.72", "size": "3803.99", "side": "SELL", "hash": "d34ac926cdb64f6e7807d28bd6f72428e0fc26bf", "best_bid": "0.67", "best_ask": "0.7"}], "timestamp": "1769384696918", "event_type": "price_change"}}
{"_local_timestamp": "2026-01-25T23:44:57.178974+00:00", "data": {"market": "0x4a8005d19b41af72c1cd5c619640d9d51da548dd7c3544b12ae0c520d9e6805b", "price_changes": [{"asset_id": "57920006811393570084962107679227395634282382525602277724728836928684998641754", "price": "0.801", "size": "15", "side": "BUY", "hash": "cf715a57e3f7dc984bbd4930fdba8be1acdc1041", "best_bid": "0.956", "best_ask": "0.968"}, {"asset_id": "42493289531592820306292191064557160874552640520793925047778017979799601355649", "price": "0.199", "size": "15", "side": "SELL", "hash": "805237c21551622c77e1f38e8c0b6aa94e015d2f", "best_bid": "0.032", "best_ask": "0.044"}], "timestamp": "1769384697076", "event_type": "price_change"}}
{"_local_timestamp": "2026-01-25T23:44:57.323102+00:00", "data": {"market": "0xa281783fc73b1a6927a301ee34cd90795470dc64b500673e445ba5e54f697c09", "price_changes": [{"asset_id": "19224712151342060925250675326667957156597084749312967133447388236247487979547", "price": "0.517", "size": "15", "side": "BUY", "hash": "7b3e264411897bfa0a572f9f8bf8a1aa505af04e", "best_bid": "0.915", "best_ask": "0.943"}, {"asset_id": "19470872781622450446330627562106312915240544924539183504885686468325701819521", "price": "0.483", "size": "15", "side": "SELL", "hash": "9e5bea8b2692dd7eb6c59382c1ce78bd8c1bab7e", "best_bid": "0.057", "best_ask": "0.085"}], "timestamp": "1769384697254", "event_type": "price_change"}}
{"_local_timestamp": "2026-01-25T23:44:58.641930+00:00", "data": {"market": "0x3849e1d62e0807801913d3e2427e8caf3cc6dd1c8ef42d8d5c08c6f9c449dc5e", "price_changes": [{"asset_id": "56615676606297588259337956203332341775475048285080710344367729433788967812170", "price": "0.18", "size": "2332", "side": "BUY", "hash": "f2c27a749b8ea362374d9270260611fdbb67088c", "best_bid": "0.67", "best_ask": "0.7"}, {"asset_id": "8070607953656787024050950499598687532281829563384949938603247089607814583142", "price": "0.82", "size": "2332", "side": "SELL", "hash": "f10f5b81869e630b66937ea56cf9abfec399853c", "best_bid": "0.3", "best_ask": "0.33"}], "timestamp": "1769384698573", "event_type": "price_change"}}
{"_local_timestamp": "2026-01-25T23:44:58.849874+00:00", "data": {"market": "0x3f9f68feccc892303834833665bf204632438b028254fc2d5bceea757ff61ed3", "price_changes": [{"asset_id": "11947171408899503371980811142475369274013053223377767646204433492871687017998", "price": "0.805", "size": "0", "side": "BUY", "hash": "37973eb2d856aba6e805c6803d13995496b6e1a4", "best_bid": "0.89", "best_ask": "0.966"}, {"asset_id": "36088399593046466421453063228085042771351246231742717370399696243183381174466", "price": "0.195", "size": "0", "side": "SELL", "hash": "5ba0baa3a5a7fa5de0d7bdb95d23de40e8b0bbe6", "best_bid": "0.034", "best_ask": "0.11"}], "timestamp": "1769384698775", "event_type": "price_change"}}
{"_local_timestamp": "2026-01-25T23:44:59.605305+00:00", "data": {"market": "0x3f9f68feccc892303834833665bf204632438b028254fc2d5bceea757ff61ed3", "price_changes": [{"asset_id": "11947171408899503371980811142475369274013053223377767646204433492871687017998", "price": "0.806", "size": "0", "side": "BUY", "hash": "80850b1457f8c1aa81f8f72cf41591eaa84ace17", "best_bid": "0.89", "best_ask": "0.966"}, {"asset_id": "36088399593046466421453063228085042771351246231742717370399696243183381174466", "price": "0.194", "size": "0", "side": "SELL", "hash": "d819b91846e2bcb5cb2e199075b3aa3768445b6f", "best_bid": "0.034", "best_ask": "0.11"}], "timestamp": "1769384699528", "event_type": "price_change"}}
{"_local_timestamp": "2026-01-25T23:44:59.623949+00:00", "data": {"market": "0x3f9f68feccc892303834833665bf204632438b028254fc2d5bceea757ff61ed3", "price_changes": [{"asset_id": "11947171408899503371980811142475369274013053223377767646204433492871687017998", "price": "0.802", "size": "20", "side": "BUY", "hash": "e6e367fa4c99923e8f8bfdc1fe353a4b462798d6", "best_bid": "0.89", "best_ask": "0.966"}, {"asset_id": "36088399593046466421453063228085042771351246231742717370399696243183381174466", "price": "0.198", "size": "20", "side": "SELL", "hash": "f552ffd105ebfad3304a9c854df3256d30ac7599", "best_bid": "0.034", "best_ask": "0.11"}], "timestamp": "1769384699555", "event_type": "price_change"}}
{"_local_timestamp": "2026-01-25T23:45:18.613518+00:00", "data": {"market": "0x3f9f68feccc892303834833665bf204632438b028254fc2d5bceea757ff61ed3", "price_changes": [{"asset_id": "36088399593046466421453063228085042771351246231742717370399696243183381174466", "price": "0.111", "size": "33.24", "side": "SELL", "hash": "4d42c7f11cd27302dcefa02fc8efe3a1282a7ea1", "best_bid": "0.034", "best_ask": "0.11"}, {"asset_id": "11947171408899503371980811142475369274013053223377767646204433492871687017998", "price": "0.889", "size": "33.24", "side": "BUY", "hash": "db0ff546f43a8fa0e98be5549578dee524f5277a", "best_bid": "0.89", "best_ask": "0.966"}], "timestamp": "1769384718543", "event_type": "price_change"}}
{"_local_timestamp": "2026-01-25T23:45:19.202720+00:00", "data": {"market": "0x3f9f68feccc892303834833665bf204632438b028254fc2d5bceea757ff61ed3", "price_changes": [{"asset_id": "11947171408899503371980811142475369274013053223377767646204433492871687017998", "price": "0.891", "size": "45", "side": "BUY", "hash": "2862c40bbd56ffbd4b1d3087c45891fd692b43c9", "best_bid": "0.891", "best_ask": "0.966"}, {"asset_id": "36088399593046466421453063228085042771351246231742717370399696243183381174466", "price": "0.109", "size": "45", "side": "SELL", "hash": "2da4c5150cb673a7477a62699e19f7d0b04b201e", "best_bid": "0.034", "best_ask": "0.109"}], "timestamp": "1769384719126", "event_type": "price_change"}}
{"_local_timestamp": "2026-01-25T23:45:19.623548+00:00", "data": {"market": "0x3f9f68feccc892303834833665bf204632438b028254fc2d5bceea757ff61ed3", "price_changes": [{"asset_id": "36088399593046466421453063228085042771351246231742717370399696243183381174466", "price": "0.109", "size": "76.57", "side": "SELL", "hash": "2151ec25849085d18edc4b2ddcf3ba1312f6ab49", "best_bid": "0.034", "best_ask": "0.109"}, {"asset_id": "11947171408899503371980811142475369274013053223377767646204433492871687017998", "price": "0.891", "size": "76.57", "side": "BUY", "hash": "cbffa8efdb6c9d6d02e6894e3f1d8689c960cdcc", "best_bid": "0.891", "best_ask": "0.966"}], "timestamp": "1769384719546", "event_type": "price_change"}}
{"_local_timestamp": "2026-01-25T23:45:19.624818+00:00", "data": {"market": "0x3f9f68feccc892303834833665bf204632438b028254fc2d5bceea757ff61ed3", "price_changes": [{"asset_id": "36088399593046466421453063228085042771351246231742717370399696243183381174466", "price": "0.11", "size": "0", "side": "SELL", "hash": "7041d9916262203b52c7f750cc54f872ebe5fd65", "best_bid": "0.034", "best_ask": "0.109"}, {"asset_id": "11947171408899503371980811142475369274013053223377767646204433492871687017998", "price": "0.89", "size": "0", "side": "BUY", "hash": "c88b251f37bc6e481808c6613e771964268a8cbc", "best_bid": "0.891", "best_ask": "0.966"}], "timestamp": "1769384719552", "event_type": "price_change"}}
{"_local_timestamp": "2026-01-25T23:45:19.695161+00:00", "data": {"market": "0x3f9f68feccc892303834833665bf204632438b028254fc2d5bceea757ff61ed3", "price_changes": [{"asset_id": "36088399593046466421453063228085042771351246231742717370399696243183381174466", "price": "0.116", "size": "30", "side": "SELL", "hash": "d2b4565c1afc9c44c6e2ec15a8e794c2943dd514", "best_bid": "0.034", "best_ask": "0.109"}, {"asset_id": "11947171408899503371980811142475369274013053223377767646204433492871687017998", "price": "0.884", "size": "30", "side": "BUY", "hash": "9d0d21352e19771d1102d2d08611277856e21ba0", "best_bid": "0.891", "best_ask": "0.966"}], "timestamp": "1769384719624", "event_type": "price_change"}}
{"_local_timestamp": "2026-01-25T23:45:19.771073+00:00", "data": {"market": "0x4a8005d19b41af72c1cd5c619640d9d51da548dd7c3544b12ae0c520d9e6805b", "price_changes": [{"asset_id": "57920006811393570084962107679227395634282382525602277724728836928684998641754", "price": "0.801", "size": "0", "side": "BUY", "hash": "9721164d0b8063d96eb0a669bdd1d028957d99f2", "best_bid": "0.956", "best_ask": "0.968"}, {"asset_id": "42493289531592820306292191064557160874552640520793925047778017979799601355649", "price": "0.199", "size": "0", "side": "SELL", "hash": "4af1b104b48920fca6e9cb6ad56783c33a9d8bd7", "best_bid": "0.032", "best_ask": "0.044"}], "timestamp": "1769384719701", "event_type": "price_change"}}
{"_local_timestamp": "2026-01-25T23:45:19.962372+00:00", "data": {"market": "0x3f9f68feccc892303834833665bf204632438b028254fc2d5bceea757ff61ed3", "price_changes": [{"asset_id": "11947171408899503371980811142475369274013053223377767646204433492871687017998", "price": "0.771", "size": "0", "side": "BUY", "hash": "c19342587ed5014bf31c197b3486247a5ec8d83f", "best_bid": "0.891", "best_ask": "0.966"}, {"asset_id": "36088399593046466421453063228085042771351246231742717370399696243183381174466", "price": "0.229", "size": "0", "side": "SELL", "hash": "ba87301004d4baef6b6aab42401d36183a238ad2", "best_bid": "0.034", "best_ask": "0.109"}], "timestamp": "1769384719873", "event_type": "price_change"}}
{"_local_timestamp": "2026-01-25T23:45:19.963667+00:00", "data": {"market": "0xa281783fc73b1a6927a301ee34cd90795470dc64b500673e445ba5e54f697c09", "price_changes": [{"asset_id": "19224712151342060925250675326667957156597084749312967133447388236247487979547", "price": "0.517", "size": "0", "side": "BUY", "hash": "4faae96e0f2db5d2219a8340a3a7e569edaea7af", "best_bid": "0.915", "best_ask": "0.943"}, {"asset_id": "19470872781622450446330627562106312915240544924539183504885686468325701819521", "price": "0.483", "size": "0", "side": "SELL", "hash": "56c7d98f960e0d9e55f163f3b5fcc3ed569beb81", "best_bid": "0.057", "best_ask": "0.085"}], "timestamp": "1769384719873", "event_type": "price_change"}}
{"_local_timestamp": "2026-01-25T23:45:19.985460+00:00", "data": {"market": "0x4a8005d19b41af72c1cd5c619640d9d51da548dd7c3544b12ae0c520d9e6805b", "price_changes": [{"asset_id": "57920006811393570084962107679227395634282382525602277724728836928684998641754", "price": "0.803", "size": "15", "side": "BUY", "hash": "cf5396b97523ddfc5390eabb84a7be80972af128", "best_bid": "0.956", "best_ask": "0.968"}, {"asset_id": "42493289531592820306292191064557160874552640520793925047778017979799601355649", "price": "0.197", "size": "15", "side": "SELL", "hash": "5a32ed96c3bb8618aad9626f4c889bfa0a8bdafe", "best_bid": "0.032", "best_ask": "0.044"}], "timestamp": "1769384719919", "event_type": "price_change"}}
{"_local_timestamp": "2026-01-25T23:45:19.990527+00:00", "data": {"market": "0x4a8005d19b41af72c1cd5c619640d9d51da548dd7c3544b12ae0c520d9e6805b", "price_changes": [{"asset_id": "57920006811393570084962107679227395634282382525602277724728836928684998641754", "price": "0.803", "size": "25", "side": "BUY", "hash": "38f5d33517bda5a6ba0f4b239ad60e8f3e7ceb0f", "best_bid": "0.956", "best_ask": "0.968"}, {"asset_id": "42493289531592820306292191064557160874552640520793925047778017979799601355649", "price": "0.197", "size": "25", "side": "SELL", "hash": "fc2439ec7cbb66689f32f03c793af360d34a0dc7", "best_bid": "0.032", "best_ask": "0.044"}], "timestamp": "1769384719920", "event_type": "price_change"}}
{"_local_timestamp": "2026-01-25T23:45:19.991808+00:00", "data": {"market": "0x3f9f68feccc892303834833665bf204632438b028254fc2d5bceea757ff61ed3", "price_changes": [{"asset_id": "11947171408899503371980811142475369274013053223377767646204433492871687017998", "price": "0.803", "size": "10", "side": "BUY", "hash": "37adc5ce4bd064fbb042eefdbcea2d444c289612", "best_bid": "0.891", "best_ask": "0.966"}, {"asset_id": "36088399593046466421453063228085042771351246231742717370399696243183381174466", "price": "0.197", "size": "10", "side": "SELL", "hash": "7d56af214d8cc4fa46fa330d6a689b0264532117", "best_bid": "0.034", "best_ask": "0.109"}], "timestamp": "1769384719919", "event_type": "price_change"}}
{"_local_timestamp": "2026-01-25T23:45:19.992942+00:00", "data": {"market": "0x3f9f68feccc892303834833665bf204632438b028254fc2d5bceea757ff61ed3", "price_changes": [{"asset_id": "11947171408899503371980811142475369274013053223377767646204433492871687017998", "price": "0.803", "size": "25", "side": "BUY", "hash": "386c68959071b1b37f212272e2aa8c6dd6e24755", "best_bid": "0.891", "best_ask": "0.966"}, {"asset_id": "36088399593046466421453063228085042771351246231742717370399696243183381174466", "price": "0.197", "size": "25", "side": "SELL", "hash": "5d6803745e171de1ca10d3aed29e16c38d4c458b", "best_bid": "0.034", "best_ask": "0.109"}], "timestamp": "1769384719920", "event_type": "price_change"}}
{"_local_timestamp": "2026-01-25T23:45:19.994063+00:00", "data": {"market": "0xa281783fc73b1a6927a301ee34cd90795470dc64b500673e445ba5e54f697c09", "price_changes": [{"asset_id": "19224712151342060925250675326667957156597084749312967133447388236247487979547", "price": "0.519", "size": "15", "side": "BUY", "hash": "380d3cd18db890fe5fa50f5fc1d69fc1ee979b0d", "best_bid": "0.915", "best_ask": "0.943"}, {"asset_id": "19470872781622450446330627562106312915240544924539183504885686468325701819521", "price": "0.481", "size": "15", "side": "SELL", "hash": "55f33b09fa74618262acdb71abf37b4c44d2989c", "best_bid": "0.057", "best_ask": "0.085"}], "timestamp": "1769384719919", "event_type": "price_change"}}
{"_local_timestamp": "2026-01-25T23:45:19.995195+00:00", "data": {"market": "0xa281783fc73b1a6927a301ee34cd90795470dc64b500673e445ba5e54f697c09", "price_changes": [{"asset_id": "19224712151342060925250675326667957156597084749312967133447388236247487979547", "price": "0.519", "size": "25", "side": "BUY", "hash": "3c047ae39a971624a73109bed225053bab91732b", "best_bid": "0.915", "best_ask": "0.943"}, {"asset_id": "19470872781622450446330627562106312915240544924539183504885686468325701819521", "price": "0.481", "size": "25", "side": "SELL", "hash": "684e06616a96704dfaac5efc71fc0d8e0653f7c7", "best_bid": "0.057", "best_ask": "0.085"}], "timestamp": "1769384719920", "event_type": "price_change"}}
{"_local_timestamp": "2026-01-25T23:45:20.128799+00:00", "data": {"market": "0xb77424a53b7480164118374fb5e97b859bd12b696b1aea55d383ce798c060cf4", "price_changes": [{"asset_id": "74987521271361072746264224488245891269775371028979674431826416209897741154003", "price": "0.753", "size": "0", "side": "BUY", "hash": "34c038c096650e952922ee9b22d97e47f859b748", "best_bid": "0.934", "best_ask": "0.942"}, {"asset_id": "86904220753614324927759730619985568200215013704321476651673438801320577270597", "price": "0.247", "size": "0", "side": "SELL", "hash": "0ac8352cbbf2c9cd8735c680e33baf6c00b428b5", "best_bid": "0.058", "best_ask": "0.066"}], "timestamp": "1769384720039", "event_type": "price_change"}}
{"_local_timestamp": "2026-01-25T23:45:21.024733+00:00", "data": {"market": "0x3f9f68feccc892303834833665bf204632438b028254fc2d5bceea757ff61ed3", "price_changes": [{"asset_id": "36088399593046466421453063228085042771351246231742717370399696243183381174466", "price": "0.116", "size": "0", "side": "SELL", "hash": "a347c55caa70cc5a7f15fef0c54f14f03e80588c", "best_bid": "0.034", "best_ask": "0.109"}, {"asset_id": "11947171408899503371980811142475369274013053223377767646204433492871687017998", "price": "0.884", "size": "0", "side": "BUY", "hash": "383c70a128e9bd20d5886427df044bbae6740efc", "best_bid": "0.891", "best_ask": "0.966"}], "timestamp": "1769384720953", "event_type": "price_change"}}
{"_local_timestamp": "2026-01-25T23:45:21.070319+00:00", "data": {"market": "0x3849e1d62e0807801913d3e2427e8caf3cc6dd1c8ef42d8d5c08c6f9c449dc5e", "price_changes": [{"asset_id": "8070607953656787024050950499598687532281829563384949938603247089607814583142", "price": "0.28", "size": "3853.99", "side": "BUY", "hash": "af6c45490fbfce2732a5429c4319d9d99472d773", "best_bid": "0.3", "best_ask": "0.33"}, {"asset_id": "56615676606297588259337956203332341775475048285080710344367729433788967812170", "price": "0.72", "size": "3853.99", "side": "SELL", "hash": "01afb6a937f950f40d1cb39f8d274ceb89145741", "best_bid": "0.67", "best_ask": "0.7"}], "timestamp": "1769384720995", "event_type": "price_change"}}
{"_local_timestamp": "2026-01-25T23:45:21.102558+00:00", "data": {"market": "0x3f9f68feccc892303834833665bf204632438b028254fc2d5bceea757ff61ed3", "price_changes": [{"asset_id": "36088399593046466421453063228085042771351246231742717370399696243183381174466", "price": "0.108", "size": "30", "side": "SELL", "hash": "a0a315b4db6734920f02ac856591a2d677162fec", "best_bid": "0.034", "best_ask": "0.108"}, {"asset_id": "11947171408899503371980811142475369274013053223377767646204433492871687017998", "price": "0.892", "size": "30", "side": "BUY", "hash": "caedf88afbd6ef78c5d5c392884be31261b7ed24", "best_bid": "0.892", "best_ask": "0.966"}], "timestamp": "1769384721007", "event_type": "price_change"}}
{"_local_timestamp": "2026-01-25T23:45:21.133096+00:00", "data": {"market": "0xb77424a53b7480164118374fb5e97b859bd12b696b1aea55d383ce798c060cf4", "price_changes": [{"asset_id": "74987521271361072746264224488245891269775371028979674431826416209897741154003", "price": "0.789", "size": "0", "side": "BUY", "hash": "98d28b9ffb1469d7b8460a65c81db205454e3652", "best_bid": "0.934", "best_ask": "0.942"}, {"asset_id": "86904220753614324927759730619985568200215013704321476651673438801320577270597", "price": "0.211", "size": "0", "side": "SELL", "hash": "5cec54763617e5cb6cfc5ae72e05d3663999c114", "best_bid": "0.058", "best_ask": "0.066"}], "timestamp": "1769384721062", "event_type": "price_change"}}
{"_local_timestamp": "2026-01-25T23:45:21.209448+00:00", "data": {"market": "0xb77424a53b7480164118374fb5e97b859bd12b696b1aea55d383ce798c060cf4", "price_changes": [{"asset_id": "74987521271361072746264224488245891269775371028979674431826416209897741154003", "price": "0.751", "size": "258.12", "side": "BUY", "hash": "4341f8a665bf6d553b8e4d5f9fcadc6d87dc29f9", "best_bid": "0.934", "best_ask": "0.942"}, {"asset_id": "86904220753614324927759730619985568200215013704321476651673438801320577270597", "price": "0.249", "size": "258.12", "side": "SELL", "hash": "13ccced02b90f2ea279ea72a19cafb60625b86b9", "best_bid": "0.058", "best_ask": "0.066"}], "timestamp": "1769384721139", "event_type": "price_change"}}
{"_local_timestamp": "2026-01-25T23:45:21.338052+00:00", "data": {"market": "0xb77424a53b7480164118374fb5e97b859bd12b696b1aea55d383ce798c060cf4", "price_changes": [{"asset_id": "74987521271361072746264224488245891269775371028979674431826416209897741154003", "price": "0.791", "size": "10", "side": "BUY", "hash": "eec7ae33734d32b29892413b587309cde74f9e18", "best_bid": "0.934", "best_ask": "0.942"}, {"asset_id": "86904220753614324927759730619985568200215013704321476651673438801320577270597", "price": "0.209", "size": "10", "side": "SELL", "hash": "6d6f7e6c04989a1da42fc4cb0ba0bc63e207b474", "best_bid": "0.058", "best_ask": "0.066"}], "timestamp": "1769384721266", "event_type": "price_change"}}
{"_local_timestamp": "2026-01-25T23:45:21.344780+00:00", "data": {"market": "0xb77424a53b7480164118374fb5e97b859bd12b696b1aea55d383ce798c060cf4", "price_changes": [{"asset_id": "74987521271361072746264224488245891269775371028979674431826416209897741154003", "price": "0.791", "size": "25", "side": "BUY", "hash": "3547d5a85190c66465e8a6a7dc107e3002960b80", "best_bid": "0.934", "best_ask": "0.942"}, {"asset_id": "86904220753614324927759730619985568200215013704321476651673438801320577270597", "price": "0.209", "size": "25", "side": "SELL", "hash": "eca18ab79e401ffaded6186f85105881c26bd6c3", "best_bid": "0.058", "best_ask": "0.066"}], "timestamp": "1769384721267", "event_type": "price_change"}}
{"_local_timestamp": "2026-01-25T23:45:22.050021+00:00", "data": {"market": "0x4a8005d19b41af72c1cd5c619640d9d51da548dd7c3544b12ae0c520d9e6805b", "price_changes": [{"asset_id": "57920006811393570084962107679227395634282382525602277724728836928684998641754", "price": "0.802", "size": "0", "side": "BUY", "hash": "718a068c9888171844cad7c66379b922711b1369", "best_bid": "0.956", "best_ask": "0.968"}, {"asset_id": "42493289531592820306292191064557160874552640520793925047778017979799601355649", "price": "0.198", "size": "0", "side": "SELL", "hash": "0da261281df3c04dafb05baca02433c349438047", "best_bid": "0.032", "best_ask": "0.044"}], "timestamp": "1769384721983", "event_type": "price_change"}}
{"_local_timestamp": "2026-01-25T23:45:22.051296+00:00", "data": {"market": "0x3f9f68feccc892303834833665bf204632438b028254fc2d5bceea757ff61ed3", "price_changes": [{"asset_id": "11947171408899503371980811142475369274013053223377767646204433492871687017998", "price": "0.802", "size": "0", "side": "BUY", "hash": "53c1e5449f493a1039f9d195220e73cd9196c572", "best_bid": "0.892", "best_ask": "0.966"}, {"asset_id": "36088399593046466421453063228085042771351246231742717370399696243183381174466", "price": "0.198", "size": "0", "side": "SELL", "hash": "c5119842fff2eae73641b5bf1bf042f52c52f7dc", "best_bid": "0.034", "best_ask": "0.108"}], "timestamp": "1769384721983", "event_type": "price_change"}}
{"_local_timestamp": "2026-01-25T23:45:22.052464+00:00", "data": {"market": "0xb77424a53b7480164118374fb5e97b859bd12b696b1aea55d383ce798c060cf4", "price_changes": [{"asset_id": "74987521271361072746264224488245891269775371028979674431826416209897741154003", "price": "0.79", "size": "0", "side": "BUY", "hash": "f6f701f47d1509825e43cab8b86e2af827553e41", "best_bid": "0.934", "best_ask": "0.942"}, {"asset_id": "86904220753614324927759730619985568200215013704321476651673438801320577270597", "price": "0.21", "size": "0", "side": "SELL", "hash": "47dc8100108be60bb934dfae249465f01e0238df", "best_bid": "0.058", "best_ask": "0.066"}], "timestamp": "1769384721983", "event_type": "price_change"}}
{"_local_timestamp": "2026-01-25T23:45:22.053644+00:00", "data": {"market": "0xa281783fc73b1a6927a301ee34cd90795470dc64b500673e445ba5e54f697c09", "price_changes": [{"asset_id": "19224712151342060925250675326667957156597084749312967133447388236247487979547", "price": "0.518", "size": "0", "side": "BUY", "hash": "fe7f59d2896157703188c939d77b95f0b17bce00", "best_bid": "0.915", "best_ask": "0.943"}, {"asset_id": "19470872781622450446330627562106312915240544924539183504885686468325701819521", "price": "0.482", "size": "0", "side": "SELL", "hash": "7a97bda98a84a609bc14dad87fd311667bbe6a65", "best_bid": "0.057", "best_ask": "0.085"}], "timestamp": "1769384721983", "event_type": "price_change"}}
{"_local_timestamp": "2026-01-25T23:45:22.127888+00:00", "data": {"market": "0x3f9f68feccc892303834833665bf204632438b028254fc2d5bceea757ff61ed3", "price_changes": [{"asset_id": "11947171408899503371980811142475369274013053223377767646204433492871687017998", "price": "0.804", "size": "20", "side": "BUY", "hash": "a02d1bbf7b1983ce9b53a050058f6c7ad4af8ecd", "best_bid": "0.892", "best_ask": "0.966"}, {"asset_id": "36088399593046466421453063228085042771351246231742717370399696243183381174466", "price": "0.196", "size": "20", "side": "SELL", "hash": "82fab4c6254e4a5d3d0c613b8c96d95870e6bac9", "best_bid": "0.034", "best_ask": "0.108"}], "timestamp": "1769384722019", "event_type": "price_change"}}
{"_local_timestamp": "2026-01-25T23:45:22.129174+00:00", "data": {"market": "0xb77424a53b7480164118374fb5e97b859bd12b696b1aea55d383ce798c060cf4", "price_changes": [{"asset_id": "74987521271361072746264224488245891269775371028979674431826416209897741154003", "price": "0.792", "size": "20", "side": "BUY", "hash": "1a28441ab3726bdc3c2d92a7750dfac638627a3c", "best_bid": "0.934", "best_ask": "0.942"}, {"asset_id": "86904220753614324927759730619985568200215013704321476651673438801320577270597", "price": "0.208", "size": "20", "side": "SELL", "hash": "49e53e27cc4fb3d21abeb975e4523ad7a3e0e79d", "best_bid": "0.058", "best_ask": "0.066"}], "timestamp": "1769384722019", "event_type": "price_change"}}
{"_local_timestamp": "2026-01-25T23:45:22.130400+00:00", "data": {"market": "0xa281783fc73b1a6927a301ee34cd90795470dc64b500673e445ba5e54f697c09", "price_changes": [{"asset_id": "19224712151342060925250675326667957156597084749312967133447388236247487979547", "price": "0.52", "size": "20", "side": "BUY", "hash": "a859139b74d0e64487ea673ce5e3b86e2e01bee8", "best_bid": "0.915", "best_ask": "0.943"}, {"asset_id": "19470872781622450446330627562106312915240544924539183504885686468325701819521", "price": "0.48", "size": "20", "side": "SELL", "hash": "88fc1f3a38c2ac1165999e47427ee05b0dd00d84", "best_bid": "0.057", "best_ask": "0.085"}], "timestamp": "1769384722019", "event_type": "price_change"}}
{"_local_timestamp": "2026-01-25T23:45:22.131604+00:00", "data": {"market": "0x4a8005d19b41af72c1cd5c619640d9d51da548dd7c3544b12ae0c520d9e6805b", "price_changes": [{"asset_id": "57920006811393570084962107679227395634282382525602277724728836928684998641754", "price": "0.804", "size": "20", "side": "BUY", "hash": "da0ce90784ef9f908e902780f3e33c792372d0ca", "best_bid": "0.956", "best_ask": "0.968"}, {"asset_id": "42493289531592820306292191064557160874552640520793925047778017979799601355649", "price": "0.196", "size": "20", "side": "SELL", "hash": "df279887fade7ba812cd91345bc093ddae1812ef", "best_bid": "0.032", "best_ask": "0.044"}], "timestamp": "1769384722019", "event_type": "price_change"}}
{"_local_timestamp": "2026-01-25T23:45:24.913082+00:00", "data": {"market": "0xa281783fc73b1a6927a301ee34cd90795470dc64b500673e445ba5e54f697c09", "price_changes": [{"asset_id": "19224712151342060925250675326667957156597084749312967133447388236247487979547", "price": "0.907", "size": "0", "side": "BUY", "hash": "323fd0c07514009ae606f6a448bb3a1b1c8c21d9", "best_bid": "0.915", "best_ask": "0.943"}, {"asset_id": "19470872781622450446330627562106312915240544924539183504885686468325701819521", "price": "0.093", "size": "0", "side": "SELL", "hash": "f1bb5a7a843de84771adab3ac1a19de382ce2c31", "best_bid": "0.057", "best_ask": "0.085"}], "timestamp": "1769384724838", "event_type": "price_change"}}
{"_local_timestamp": "2026-01-25T23:45:25.371063+00:00", "data": {"market": "0xa281783fc73b1a6927a301ee34cd90795470dc64b500673e445ba5e54f697c09", "price_changes": [{"asset_id": "19224712151342060925250675326667957156597084749312967133447388236247487979547", "price": "0.912", "size": "75.85", "side": "BUY", "hash": "e3e70f2850fdc621769361c94cdbcd4782bdf8d3", "best_bid": "0.915", "best_ask": "0.943"}, {"asset_id": "19470872781622450446330627562106312915240544924539183504885686468325701819521", "price": "0.088", "size": "75.85", "side": "SELL", "hash": "c3c4cc6903ad7a0c1486bae57612aa09a7df33c7", "best_bid": "0.057", "best_ask": "0.085"}], "timestamp": "1769384725299", "event_type": "price_change"}}
{"_local_timestamp": "2026-01-25T23:45:52.472350+00:00", "data": {"market": "0x08b39100a4d3d6ad1099e076fb69f781313c5b16975adf189d63542bd1ecca04", "price_changes": [{"asset_id": "48451126471681390564675828610810240762308720916091458567360242927144088567337", "price": "0.373", "size": "0", "side": "BUY", "hash": "4f15221ade35b995f60c92260b371be87c877378", "best_bid": "0.978", "best_ask": "0.982"}, {"asset_id": "6122912536415539457721068960901205060237919057489564846781206253065694717085", "price": "0.627", "size": "0", "side": "SELL", "hash": "1af1f2eeb8b36639c975bdb20442537112021466", "best_bid": "0.018", "best_ask": "0.022"}], "timestamp": "1769384752404", "event_type": "price_change"}}
{"_local_timestamp": "2026-01-25T23:45:52.609784+00:00", "data": {"market": "0x602a7a6c7d65b55932e6cf8b6904cb7acdc728ca423ffd3ccb1988dd5501de13", "price_changes": [{"asset_id": "18399565751068676179945656979762090460558422925963909399757895217338947077684", "price": "0.761", "size": "15", "side": "BUY", "hash": "99d62c88a20acf4642007bcf1365aba98db964c8", "best_bid": "0.941", "best_ask": "0.952"}, {"asset_id": "88770632741686298370270294037614812817595949782311984579833554458717957886356", "price": "0.239", "size": "15", "side": "SELL", "hash": "ede0540593e0407f2f3f24a83ae5ee1d9266ea80", "best_bid": "0.048", "best_ask": "0.059"}], "timestamp": "1769384752533", "event_type": "price_change"}}
{"_local_timestamp": "2026-01-25T23:45:52.644713+00:00", "data": {"market": "0x08b39100a4d3d6ad1099e076fb69f781313c5b16975adf189d63542bd1ecca04", "price_changes": [{"asset_id": "48451126471681390564675828610810240762308720916091458567360242927144088567337", "price": "0.373", "size": "5113", "side": "BUY", "hash": "cf82d209e59129d12afce1ba6ee949355d199d4b", "best_bid": "0.978", "best_ask": "0.982"}, {"asset_id": "6122912536415539457721068960901205060237919057489564846781206253065694717085", "price": "0.627", "size": "5113", "side": "SELL", "hash": "c05d88ea186857681aa605cc62a8cd8daf83246a", "best_bid": "0.018", "best_ask": "0.022"}], "timestamp": "1769384752579", "event_type": "price_change"}}
{"_local_timestamp": "2026-01-25T23:45:52.853002+00:00", "data": {"market": "0x3f9f68feccc892303834833665bf204632438b028254fc2d5bceea757ff61ed3", "price_changes": [{"asset_id": "11947171408899503371980811142475369274013053223377767646204433492871687017998", "price": "0.399", "size": "50", "side": "BUY", "hash": "a30e52b3fe1dd7f702ddd4acb4fc9e1fbc903ada", "best_bid": "0.892", "best_ask": "0.966"}, {"asset_id": "36088399593046466421453063228085042771351246231742717370399696243183381174466", "price": "0.601", "size": "50", "side": "SELL", "hash": "f074e26a32cfc13d77753b3317ac98c199d804ef", "best_bid": "0.034", "best_ask": "0.108"}], "timestamp": "1769384752784", "event_type": "price_change"}}
{"_local_timestamp": "2026-01-25T23:45:53.009303+00:00", "data": {"market": "0x3f9f68feccc892303834833665bf204632438b028254fc2d5bceea757ff61ed3", "price_changes": [{"asset_id": "11947171408899503371980811142475369274013053223377767646204433492871687017998", "price": "0.402", "size": "3433", "side": "BUY", "hash": "3acc8c4b7c3b880107f6149096711f496c708dcf", "best_bid": "0.892", "best_ask": "0.966"}, {"asset_id": "36088399593046466421453063228085042771351246231742717370399696243183381174466", "price": "0.598", "size": "3433", "side": "SELL", "hash": "1373571dcd40824f8fd5c81eee8e73f8516ca5d8", "best_bid": "0.034", "best_ask": "0.108"}], "timestamp": "1769384752941", "event_type": "price_change"}}
{"_local_timestamp": "2026-01-25T23:45:53.105835+00:00", "data": {"market": "0x3849e1d62e0807801913d3e2427e8caf3cc6dd1c8ef42d8d5c08c6f9c449dc5e", "price_changes": [{"asset_id": "56615676606297588259337956203332341775475048285080710344367729433788967812170", "price": "0.17", "size": "549.7", "side": "BUY", "hash": "4c0dd4f3b2d516d56b70b7287ad3870d0e2bd157", "best_bid": "0.67", "best_ask": "0.7"}, {"asset_id": "8070607953656787024050950499598687532281829563384949938603247089607814583142", "price": "0.83", "size": "549.7", "side": "SELL", "hash": "c3483dc14b1b8ea6a047623f5980a5d76a36b5e3", "best_bid": "0.3", "best_ask": "0.33"}], "timestamp": "1769384752999", "event_type": "price_change"}}
{"_local_timestamp": "2026-01-25T23:45:53.330315+00:00", "data": {"market": "0x3f9f68feccc892303834833665bf204632438b028254fc2d5bceea757ff61ed3", "price_changes": [{"asset_id": "11947171408899503371980811142475369274013053223377767646204433492871687017998", "price": "0.4", "size": "112.07", "side": "BUY", "hash": "5220806e120a06424f90132a56077dc7a3a61cb0", "best_bid": "0.892", "best_ask": "0.966"}, {"asset_id": "36088399593046466421453063228085042771351246231742717370399696243183381174466", "price": "0.6", "size": "112.07", "side": "SELL", "hash": "9b752859071adb8f496408862fe743f5230e147a", "best_bid": "0.034", "best_ask": "0.108"}], "timestamp": "1769384753113", "event_type": "price_change"}}
{"_local_timestamp": "2026-01-25T23:45:53.351788+00:00", "data": {"market": "0x3f9f68feccc892303834833665bf204632438b028254fc2d5bceea757ff61ed3", "price_changes": [{"asset_id": "11947171408899503371980811142475369274013053223377767646204433492871687017998", "price": "0.4", "size": "51.07", "side": "BUY", "hash": "ac771ef60c4f133707c4456020f305e199986df9", "best_bid": "0.892", "best_ask": "0.966"}, {"asset_id": "36088399593046466421453063228085042771351246231742717370399696243183381174466", "price": "0.6", "size": "51.07", "side": "SELL", "hash": "8fd9f9f31c02313d9116a5c92d0af9ae797c719b", "best_bid": "0.034", "best_ask": "0.108"}], "timestamp": "1769384753144", "event_type": "price_change"}}
{"_local_timestamp": "2026-01-25T23:45:53.354444+00:00", "data": {"market": "0xb77424a53b7480164118374fb5e97b859bd12b696b1aea55d383ce798c060cf4", "price_changes": [{"asset_id": "74987521271361072746264224488245891269775371028979674431826416209897741154003", "price": "0.263", "size": "0", "side": "BUY", "hash": "0861209fa6147bb2a508665d240a61ba6fca5453", "best_bid": "0.934", "best_ask": "0.942"}, {"asset_id": "86904220753614324927759730619985568200215013704321476651673438801320577270597", "price": "0.737", "size": "0", "side": "SELL", "hash": "8c21890827cf7d37557b6d8f69d56da12ef7ce01", "best_bid": "0.058", "best_ask": "0.066"}], "timestamp": "1769384753170", "event_type": "price_change"}}
{"_local_timestamp": "2026-01-25T23:45:53.441107+00:00", "data": {"market": "0xb77424a53b7480164118374fb5e97b859bd12b696b1aea55d383ce798c060cf4", "price_changes": [{"asset_id": "74987521271361072746264224488245891269775371028979674431826416209897741154003", "price": "0.263", "size": "4238", "side": "BUY", "hash": "f20b2c63093182b8c91e2b3bca35e5254479a25e", "best_bid": "0.934", "best_ask": "0.942"}, {"asset_id": "86904220753614324927759730619985568200215013704321476651673438801320577270597", "price": "0.737", "size": "4238", "side": "SELL", "hash": "56748d256284a8a81c40c2cf5a8c4c289e87ba0e", "best_bid": "0.058", "best_ask": "0.066"}], "timestamp": "1769384753332", "event_type": "price_change"}}
{"_local_timestamp": "2026-01-25T23:45:53.471206+00:00", "data": {"market": "0x3f9f68feccc892303834833665bf204632438b028254fc2d5bceea757ff61ed3", "price_changes": [{"asset_id": "11947171408899503371980811142475369274013053223377767646204433492871687017998", "price": "0.403", "size": "313", "side": "BUY", "hash": "daf5373efa8a689016794bf6479315737f0a5c70", "best_bid": "0.892", "best_ask": "0.966"}, {"asset_id": "36088399593046466421453063228085042771351246231742717370399696243183381174466", "price": "0.597", "size": "313", "side": "SELL", "hash": "756d2a8422e4635eb21c5edfbc58993a44e1cd6c", "best_bid": "0.034", "best_ask": "0.108"}], "timestamp": "1769384753390", "event_type": "price_change"}}
{"_local_timestamp": "2026-01-25T23:45:53.474380+00:00", "data": {"market": "0x3f9f68feccc892303834833665bf204632438b028254fc2d5bceea757ff61ed3", "price_changes": [{"asset_id": "11947171408899503371980811142475369274013053223377767646204433492871687017998", "price": "0.403", "size": "616", "side": "BUY", "hash": "95b6cb055ece23e06de5788317d5f9d991c34804", "best_bid": "0.892", "best_ask": "0.966"}, {"asset_id": "36088399593046466421453063228085042771351246231742717370399696243183381174466", "price": "0.597", "size": "616", "side": "SELL", "hash": "7db4ea90ba88c8899cc6c70c0bd618f8f0a81949", "best_bid": "0.034", "best_ask": "0.108"}], "timestamp": "1769384753405", "event_type": "price_change"}}
{"_local_timestamp": "2026-01-25T23:45:53.662759+00:00", "data": {"market": "0x3849e1d62e0807801913d3e2427e8caf3cc6dd1c8ef42d8d5c08c6f9c449dc5e", "price_changes": [{"asset_id": "56615676606297588259337956203332341775475048285080710344367729433788967812170", "price": "0.16", "size": "100", "side": "BUY", "hash": "c9e95859426c482bf0547c4c229b563c831881d6", "best_bid": "0.67", "best_ask": "0.7"}, {"asset_id": "8070607953656787024050950499598687532281829563384949938603247089607814583142", "price": "0.84", "size": "100", "side": "SELL", "hash": "b81d1595e92b42e6f4fec161dc8d1668c4e4a715", "best_bid": "0.3", "best_ask": "0.33"}], "timestamp": "1769384753520", "event_type": "price_change"}}
{"_local_timestamp": "2026-01-25T23:45:53.775073+00:00", "data": {"market": "0x602a7a6c7d65b55932e6cf8b6904cb7acdc728ca423ffd3ccb1988dd5501de13", "price_changes": [{"asset_id": "18399565751068676179945656979762090460558422925963909399757895217338947077684", "price": "0.351", "size": "50", "side": "BUY", "hash": "71f2ad824d7ac39671021b66b79fac87b8f27579", "best_bid": "0.941", "best_ask": "0.952"}, {"asset_id": "88770632741686298370270294037614812817595949782311984579833554458717957886356", "price": "0.649", "size": "50", "side": "SELL", "hash": "782ac944004afc96a40f5be1b327652d11c6fcfa", "best_bid": "0.048", "best_ask": "0.059"}], "timestamp": "1769384753628", "event_type": "price_change"}}
{"_local_timestamp": "2026-01-25T23:45:53.885371+00:00", "data": {"market": "0x602a7a6c7d65b55932e6cf8b6904cb7acdc728ca423ffd3ccb1988dd5501de13", "price_changes": [{"asset_id": "18399565751068676179945656979762090460558422925963909399757895217338947077684", "price": "0.43", "size": "3820", "side": "BUY", "hash": "1099e727ce771d91775be71f8c0082763718a171", "best_bid": "0.941", "best_ask": "0.952"}, {"asset_id": "88770632741686298370270294037614812817595949782311984579833554458717957886356", "price": "0.57", "size": "3820", "side": "SELL", "hash": "cbe50247850b029ad833575092e01c3b3bf6fb80", "best_bid": "0.048", "best_ask": "0.059"}], "timestamp": "1769384753820", "event_type": "price_change"}}
{"_local_timestamp": "2026-01-25T23:45:53.965471+00:00", "data": {"market": "0x602a7a6c7d65b55932e6cf8b6904cb7acdc728ca423ffd3ccb1988dd5501de13", "price_changes": [{"asset_id": "18399565751068676179945656979762090460558422925963909399757895217338947077684", "price": "0.761", "size": "0", "side": "BUY", "hash": "428990ee9a1e36e374d498561612e892c0fb625c", "best_bid": "0.941", "best_ask": "0.952"}, {"asset_id": "88770632741686298370270294037614812817595949782311984579833554458717957886356", "price": "0.239", "size": "0", "side": "SELL", "hash": "adb828a1e0d88d896a506d985495d0c0c6bc71fa", "best_bid": "0.048", "best_ask": "0.059"}], "timestamp": "1769384753897", "event_type": "price_change"}}
{"_local_timestamp": "2026-01-25T23:45:54.073676+00:00", "data": {"market": "0x602a7a6c7d65b55932e6cf8b6904cb7acdc728ca423ffd3ccb1988dd5501de13", "price_changes": [{"asset_id": "18399565751068676179945656979762090460558422925963909399757895217338947077684", "price": "0.763", "size": "15", "side": "BUY", "hash": "b37e8c386b6adb32e96251e17c0dfb66e362a57b", "best_bid": "0.941", "best_ask": "0.952"}, {"asset_id": "88770632741686298370270294037614812817595949782311984579833554458717957886356", "price": "0.237", "size": "15", "side": "SELL", "hash": "f5eb311738d7d1ac74293289f8405a99950e204b", "best_bid": "0.048", "best_ask": "0.059"}], "timestamp": "1769384754000", "event_type": "price_change"}}
{"_local_timestamp": "2026-01-25T23:45:54.097028+00:00", "data": {"market": "0x602a7a6c7d65b55932e6cf8b6904cb7acdc728ca423ffd3ccb1988dd5501de13", "price_changes": [{"asset_id": "18399565751068676179945656979762090460558422925963909399757895217338947077684", "price": "0.763", "size": "25", "side": "BUY", "hash": "338c0a3927f9aa85976bdd8f0db3b36409813458", "best_bid": "0.941", "best_ask": "0.952"}, {"asset_id": "88770632741686298370270294037614812817595949782311984579833554458717957886356", "price": "0.237", "size": "25", "side": "SELL", "hash": "8de4bcab1d6527671c02d4cad242a28e19892106", "best_bid": "0.048", "best_ask": "0.059"}], "timestamp": "1769384754002", "event_type": "price_change"}}
{"_local_timestamp": "2026-01-25T23:45:54.119355+00:00", "data": {"market": "0xa281783fc73b1a6927a301ee34cd90795470dc64b500673e445ba5e54f697c09", "price_changes": [{"asset_id": "19224712151342060925250675326667957156597084749312967133447388236247487979547", "price": "0.259", "size": "200", "side": "BUY", "hash": "3c520f9f7d9259d16779ad42419a40ec4749dca5", "best_bid": "0.915", "best_ask": "0.943"}, {"asset_id": "19470872781622450446330627562106312915240544924539183504885686468325701819521", "price": "0.741", "size": "200", "side": "SELL", "hash": "03eddd11b082b6559f6e15151705cd807a39d61d", "best_bid": "0.057", "best_ask": "0.085"}], "timestamp": "1769384754036", "event_type": "price_change"}}
{"_local_timestamp": "2026-01-25T23:45:54.303060+00:00", "data": {"market": "0xa281783fc73b1a6927a301ee34cd90795470dc64b500673e445ba5e54f697c09", "price_changes": [{"asset_id": "19224712151342060925250675326667957156597084749312967133447388236247487979547", "price": "0.381", "size": "3669", "side": "BUY", "hash": "98ced5985822cceedfc44b44977eed91e02a98f3", "best_bid": "0.915", "best_ask": "0.943"}, {"asset_id": "19470872781622450446330627562106312915240544924539183504885686468325701819521", "price": "0.619", "size": "3669", "side": "SELL", "hash": "6b18e0cf2a53437a0ae629b6fbbdb4dc27c8170d", "best_bid": "0.057", "best_ask": "0.085"}], "timestamp": "1769384754206", "event_type": "price_change"}}
{"_local_timestamp": "2026-01-25T23:45:54.462308+00:00", "data": {"market": "0x4a8005d19b41af72c1cd5c619640d9d51da548dd7c3544b12ae0c520d9e6805b", "price_changes": [{"asset_id": "57920006811393570084962107679227395634282382525602277724728836928684998641754", "price": "0.338", "size": "0", "side": "BUY", "hash": "84534a3214f6a104662e7cefe58e45f6ba7031ea", "best_bid": "0.956", "best_ask": "0.968"}, {"asset_id": "42493289531592820306292191064557160874552640520793925047778017979799601355649", "price": "0.662", "size": "0", "side": "SELL", "hash": "1638d8ca16c1bd8fd738fc35fb5baed7df728630", "best_bid": "0.032", "best_ask": "0.044"}], "timestamp": "1769384754395", "event_type": "price_change"}}
{"_local_timestamp": "2026-01-25T23:45:54.641482+00:00", "data": {"market": "0x4a8005d19b41af72c1cd5c619640d9d51da548dd7c3544b12ae0c520d9e6805b", "price_changes": [{"asset_id": "57920006811393570084962107679227395634282382525602277724728836928684998641754", "price": "0.455", "size": "3607", "side": "BUY", "hash": "f9e9a18596350624e2384e3e0541bd467fb67093", "best_bid": "0.956", "best_ask": "0.968"}, {"asset_id": "42493289531592820306292191064557160874552640520793925047778017979799601355649", "price": "0.545", "size": "3607", "side": "SELL", "hash": "6cb20dd0340e1e9a3535917778da59d85462537d", "best_bid": "0.032", "best_ask": "0.044"}], "timestamp": "1769384754567", "event_type": "price_change"}}
{"_local_timestamp": "2026-01-25T23:45:54.836821+00:00", "data": {"market": "0x3849e1d62e0807801913d3e2427e8caf3cc6dd1c8ef42d8d5c08c6f9c449dc5e", "price_changes": [{"asset_id": "56615676606297588259337956203332341775475048285080710344367729433788967812170", "price": "0.08", "size": "300", "side": "BUY", "hash": "b70cea42523e490540f1726181bbdfc8367f8c1f", "best_bid": "0.67", "best_ask": "0.7"}, {"asset_id": "8070607953656787024050950499598687532281829563384949938603247089607814583142", "price": "0.92", "size": "300", "side": "SELL", "hash": "4d6845fdf993a3b6cefb90e5fd3ec7240b704f98", "best_bid": "0.3", "best_ask": "0.33"}], "timestamp": "1769384754772", "event_type": "price_change"}}
{"_local_timestamp": "2026-01-25T23:45:55.016689+00:00", "data": {"market": "0x3849e1d62e0807801913d3e2427e8caf3cc6dd1c8ef42d8d5c08c6f9c449dc5e", "price_changes": [{"asset_id": "56615676606297588259337956203332341775475048285080710344367729433788967812170", "price": "0.09", "size": "3364", "side": "BUY", "hash": "9cbba9e7fd4ff17466a1085f53041e0e55086030", "best_bid": "0.67", "best_ask": "0.7"}, {"asset_id": "8070607953656787024050950499598687532281829563384949938603247089607814583142", "price": "0.91", "size": "3364", "side": "SELL", "hash": "f195fe4617b150cd5c34412363c1131569f7e0cb", "best_bid": "0.3", "best_ask": "0.33"}], "timestamp": "1769384754948", "event_type": "price_change"}}
{"_local_timestamp": "2026-01-25T23:45:55.105110+00:00", "data": {"market": "0x602a7a6c7d65b55932e6cf8b6904cb7acdc728ca423ffd3ccb1988dd5501de13", "price_changes": [{"asset_id": "18399565751068676179945656979762090460558422925963909399757895217338947077684", "price": "0.762", "size": "0", "side": "BUY", "hash": "a1dc7f040c36d88bda221ccb0d27e82508325fa9", "best_bid": "0.941", "best_ask": "0.952"}, {"asset_id": "88770632741686298370270294037614812817595949782311984579833554458717957886356", "price": "0.238", "size": "0", "side": "SELL", "hash": "824a772671aeccf6076704012c85f625c2f5cf67", "best_bid": "0.048", "best_ask": "0.059"}], "timestamp": "1769384755011", "event_type": "price_change"}}
{"_local_timestamp": "2026-01-25T23:45:55.117042+00:00", "data": {"market": "0x602a7a6c7d65b55932e6cf8b6904cb7acdc728ca423ffd3ccb1988dd5501de13", "price_changes": [{"asset_id": "18399565751068676179945656979762090460558422925963909399757895217338947077684", "price": "0.764", "size": "20", "side": "BUY", "hash": "7c868738914e79f7528bd592a947a9f8a44365d3", "best_bid": "0.941", "best_ask": "0.952"}, {"asset_id": "88770632741686298370270294037614812817595949782311984579833554458717957886356", "price": "0.236", "size": "20", "side": "SELL", "hash": "601726e7c33e4f35c3e1ae45349e7dc107d54515", "best_bid": "0.048", "best_ask": "0.059"}], "timestamp": "1769384755046", "event_type": "price_change"}}
{"_local_timestamp": "2026-01-25T23:45:55.689142+00:00", "data": {"market": "0x3849e1d62e0807801913d3e2427e8caf3cc6dd1c8ef42d8d5c08c6f9c449dc5e", "price_changes": [{"asset_id": "8070607953656787024050950499598687532281829563384949938603247089607814583142", "price": "0.47", "size": "0", "side": "SELL", "hash": "e2cdebaa1eb4a2b2ee836a417d933b89814120c3", "best_bid": "0.3", "best_ask": "0.33"}, {"asset_id": "56615676606297588259337956203332341775475048285080710344367729433788967812170", "price": "0.53", "size": "0", "side": "BUY", "hash": "e3cfb41aaf15d55317829a04f665b476a5321136", "best_bid": "0.67", "best_ask": "0.7"}], "timestamp": "1769384755621", "event_type": "price_change"}}
{"_local_timestamp": "2026-01-25T23:45:55.692536+00:00", "data": {"market": "0x3849e1d62e0807801913d3e2427e8caf3cc6dd1c8ef42d8d5c08c6f9c449dc5e", "price_changes": [{"asset_id": "8070607953656787024050950499598687532281829563384949938603247089607814583142", "price": "0.37", "size": "0", "side": "SELL", "hash": "e2cdebaa1eb4a2b2ee836a417d933b89814120c3", "best_bid": "0.3", "best_ask": "0.33"}, {"asset_id": "56615676606297588259337956203332341775475048285080710344367729433788967812170", "price": "0.63", "size": "0", "side": "BUY", "hash": "e3cfb41aaf15d55317829a04f665b476a5321136", "best_bid": "0.67", "best_ask": "0.7"}], "timestamp": "1769384755621", "event_type": "price_change"}}
{"_local_timestamp": "2026-01-25T23:45:55.725837+00:00", "data": {"market": "0x08b39100a4d3d6ad1099e076fb69f781313c5b16975adf189d63542bd1ecca04", "price_changes": [{"asset_id": "48451126471681390564675828610810240762308720916091458567360242927144088567337", "price": "0.752", "size": "31", "side": "BUY", "hash": "beb96004af49c2ff2e582a4a190ccbe13998d990", "best_bid": "0.978", "best_ask": "0.982"}, {"asset_id": "6122912536415539457721068960901205060237919057489564846781206253065694717085", "price": "0.248", "size": "31", "side": "SELL", "hash": "6be6555b008b4d90f21a0dbf8689b1272b2a3b84", "best_bid": "0.018", "best_ask": "0.022"}], "timestamp": "1769384755659", "event_type": "price_change"}}
{"_local_timestamp": "2026-01-25T23:45:55.875659+00:00", "data": {"market": "0x08b39100a4d3d6ad1099e076fb69f781313c5b16975adf189d63542bd1ecca04", "price_changes": [{"asset_id": "48451126471681390564675828610810240762308720916091458567360242927144088567337", "price": "0.752", "size": "10", "side": "BUY", "hash": "d77a899c02b09e8dc55cfb6031d4bef5b002f1a8", "best_bid": "0.978", "best_ask": "0.982"}, {"asset_id": "6122912536415539457721068960901205060237919057489564846781206253065694717085", "price": "0.248", "size": "10", "side": "SELL", "hash": "412767ba7c60a9b7440117072855027f1444429f", "best_bid": "0.018", "best_ask": "0.022"}], "timestamp": "1769384755808", "event_type": "price_change"}}
{"_local_timestamp": "2026-01-25T23:45:57.139857+00:00", "data": {"market": "0x3849e1d62e0807801913d3e2427e8caf3cc6dd1c8ef42d8d5c08c6f9c449dc5e", "price_changes": [{"asset_id": "8070607953656787024050950499598687532281829563384949938603247089607814583142", "price": "0.36", "size": "29.99", "side": "SELL", "hash": "2796bdbb02c927e59708047ffe4f436e6e02ad7e", "best_bid": "0.3", "best_ask": "0.33"}, {"asset_id": "56615676606297588259337956203332341775475048285080710344367729433788967812170", "price": "0.64", "size": "29.99", "side": "BUY", "hash": "22a00611bb450e5993c7f2d2773613100f0c2cf5", "best_bid": "0.67", "best_ask": "0.7"}], "timestamp": "1769384756622", "event_type": "price_change"}}
{"_local_timestamp": "2026-01-25T23:45:57.344717+00:00", "data": {"market": "0x3849e1d62e0807801913d3e2427e8caf3cc6dd1c8ef42d8d5c08c6f9c449dc5e", "price_changes": [{"asset_id": "8070607953656787024050950499598687532281829563384949938603247089607814583142", "price": "0.48", "size": "160", "side": "SELL", "hash": "2b57138fdd1c796fa374fb25a0a1991dafa4a21f", "best_bid": "0.3", "best_ask": "0.33"}, {"asset_id": "56615676606297588259337956203332341775475048285080710344367729433788967812170", "price": "0.52", "size": "160", "side": "BUY", "hash": "16b1456251ba15efeb01a2d36874361584535739", "best_bid": "0.67", "best_ask": "0.7"}], "timestamp": "1769384757073", "event_type": "price_change"}}
{"_local_timestamp": "2026-01-25T23:45:57.346476+00:00", "data": {"market": "0x3849e1d62e0807801913d3e2427e8caf3cc6dd1c8ef42d8d5c08c6f9c449dc5e", "price_changes": [{"asset_id": "8070607953656787024050950499598687532281829563384949938603247089607814583142", "price": "0.29", "size": "236.77", "side": "BUY", "hash": "8c2d298ee06ed8e460203d272809a159c7dd9a4b", "best_bid": "0.3", "best_ask": "0.33"}, {"asset_id": "56615676606297588259337956203332341775475048285080710344367729433788967812170", "price": "0.71", "size": "236.77", "side": "SELL", "hash": "9488d682cd21d64bc1c05b768c80b6819e57e378", "best_bid": "0.67", "best_ask": "0.7"}], "timestamp": "1769384757102", "event_type": "price_change"}}
{"_local_timestamp": "2026-01-25T23:45:57.347784+00:00", "data": {"market": "0x4a8005d19b41af72c1cd5c619640d9d51da548dd7c3544b12ae0c520d9e6805b", "price_changes": [{"asset_id": "57920006811393570084962107679227395634282382525602277724728836928684998641754", "price": "0.751", "size": "0", "side": "BUY", "hash": "9cb5516046f5671722308f24438c36f13aa38c4b", "best_bid": "0.956", "best_ask": "0.968"}, {"asset_id": "42493289531592820306292191064557160874552640520793925047778017979799601355649", "price": "0.249", "size": "0", "side": "SELL", "hash": "08c3b9475b474b2ef1bdde0c8e79017444268221", "best_bid": "0.032", "best_ask": "0.044"}], "timestamp": "1769384757132", "event_type": "price_change"}}
{"_local_timestamp": "2026-01-25T23:45:57.382406+00:00", "data": {"market": "0x4a8005d19b41af72c1cd5c619640d9d51da548dd7c3544b12ae0c520d9e6805b", "price_changes": [{"asset_id": "57920006811393570084962107679227395634282382525602277724728836928684998641754", "price": "0.797", "size": "25", "side": "BUY", "hash": "57c75c68593e165026d930d51bbb790697c16ac0", "best_bid": "0.956", "best_ask": "0.968"}, {"asset_id": "42493289531592820306292191064557160874552640520793925047778017979799601355649", "price": "0.203", "size": "25", "side": "SELL", "hash": "2f8ba186a9bf624a3a5742838b192a8c6568bc06", "best_bid": "0.032", "best_ask": "0.044"}], "timestamp": "1769384757197", "event_type": "price_change"}}
{"_local_timestamp": "2026-01-25T23:45:57.387155+00:00", "data": {"market": "0x3f9f68feccc892303834833665bf204632438b028254fc2d5bceea757ff61ed3", "price_changes": [{"asset_id": "11947171408899503371980811142475369274013053223377767646204433492871687017998", "price": "0.403", "size": "303", "side": "BUY", "hash": "4d330709596bbf5194bd013136b55882324579ed", "best_bid": "0.892", "best_ask": "0.966"}, {"asset_id": "36088399593046466421453063228085042771351246231742717370399696243183381174466", "price": "0.597", "size": "303", "side": "SELL", "hash": "782b9882adb532629f0746b5dc24e624b1d3fcd5", "best_bid": "0.034", "best_ask": "0.108"}], "timestamp": "1769384757197", "event_type": "price_change"}}
{"_local_timestamp": "2026-01-25T23:45:57.484847+00:00", "data": {"market": "0x4a8005d19b41af72c1cd5c619640d9d51da548dd7c3544b12ae0c520d9e6805b", "price_changes": [{"asset_id": "57920006811393570084962107679227395634282382525602277724728836928684998641754", "price": "0.752", "size": "25", "side": "BUY", "hash": "e7e4e566a41536bcf0ed8934d20bd807408d8140", "best_bid": "0.956", "best_ask": "0.968"}, {"asset_id": "42493289531592820306292191064557160874552640520793925047778017979799601355649", "price": "0.248", "size": "25", "side": "SELL", "hash": "55d3484e795fdfe221e49eaf90e4b6089e8e78dd", "best_bid": "0.032", "best_ask": "0.044"}], "timestamp": "1769384757292", "event_type": "price_change"}}
{"_local_timestamp": "2026-01-25T23:45:57.486513+00:00", "data": {"market": "0x3f9f68feccc892303834833665bf204632438b028254fc2d5bceea757ff61ed3", "price_changes": [{"asset_id": "11947171408899503371980811142475369274013053223377767646204433492871687017998", "price": "0.404", "size": "270", "side": "BUY", "hash": "3a9c5bd1586ea117abdae552451866dc733365a8", "best_bid": "0.892", "best_ask": "0.966"}, {"asset_id": "36088399593046466421453063228085042771351246231742717370399696243183381174466", "price": "0.596", "size": "270", "side": "SELL", "hash": "7a75ad8ac724901eb82fba06585349024f1cac80", "best_bid": "0.034", "best_ask": "0.108"}], "timestamp": "1769384757292", "event_type": "price_change"}}
{"_local_timestamp": "2026-01-25T23:45:57.664752+00:00", "data": {"market": "0x4a8005d19b41af72c1cd5c619640d9d51da548dd7c3544b12ae0c520d9e6805b", "price_changes": [{"asset_id": "57920006811393570084962107679227395634282382525602277724728836928684998641754", "price": "0.797", "size": "0", "side": "BUY", "hash": "7a73fd01c91d5d308d3465f30d21ad090cd2a942", "best_bid": "0.956", "best_ask": "0.968"}, {"asset_id": "42493289531592820306292191064557160874552640520793925047778017979799601355649", "price": "0.203", "size": "0", "side": "SELL", "hash": "d6f4209f970d4bbb47b429febe05bd95402e9689", "best_bid": "0.032", "best_ask": "0.044"}], "timestamp": "1769384757593", "event_type": "price_change"}}
{"_local_timestamp": "2026-01-25T23:45:57.666976+00:00", "data": {"market": "0x3f9f68feccc892303834833665bf204632438b028254fc2d5bceea757ff61ed3", "price_changes": [{"asset_id": "11947171408899503371980811142475369274013053223377767646204433492871687017998", "price": "0.403", "size": "0", "side": "BUY", "hash": "37dfd9c2d63d9136782f70f6bcc6098c094cf36c", "best_bid": "0.892", "best_ask": "0.966"}, {"asset_id": "36088399593046466421453063228085042771351246231742717370399696243183381174466", "price": "0.597", "size": "0", "side": "SELL", "hash": "7c5a5bcf4236bb1e487ac7a3e3a87a1864c1ab2c", "best_bid": "0.034", "best_ask": "0.108"}], "timestamp": "1769384757593", "event_type": "price_change"}}
{"_local_timestamp": "2026-01-25T23:45:57.668295+00:00", "data": {"market": "0x3f9f68feccc892303834833665bf204632438b028254fc2d5bceea757ff61ed3", "price_changes": [{"asset_id": "11947171408899503371980811142475369274013053223377767646204433492871687017998", "price": "0.801", "size": "0", "side": "BUY", "hash": "37dfd9c2d63d9136782f70f6bcc6098c094cf36c", "best_bid": "0.892", "best_ask": "0.966"}, {"asset_id": "36088399593046466421453063228085042771351246231742717370399696243183381174466", "price": "0.199", "size": "0", "side": "SELL", "hash": "7c5a5bcf4236bb1e487ac7a3e3a87a1864c1ab2c", "best_bid": "0.034", "best_ask": "0.108"}], "timestamp": "1769384757593", "event_type": "price_change"}}
{"_local_timestamp": "2026-01-25T23:45:57.697650+00:00", "data": {"market": "0x4a8005d19b41af72c1cd5c619640d9d51da548dd7c3544b12ae0c520d9e6805b", "price_changes": [{"asset_id": "57920006811393570084962107679227395634282382525602277724728836928684998641754", "price": "0.751", "size": "10", "side": "BUY", "hash": "4bea2646f256ea1b453b20993bf9c56aa9c28c04", "best_bid": "0.956", "best_ask": "0.968"}, {"asset_id": "42493289531592820306292191064557160874552640520793925047778017979799601355649", "price": "0.249", "size": "10", "side": "SELL", "hash": "1068eda03ee3d3999457599707f325e69f87d24f", "best_bid": "0.032", "best_ask": "0.044"}], "timestamp": "1769384757623", "event_type": "price_change"}}
{"_local_timestamp": "2026-01-25T23:45:57.745940+00:00", "data": {"market": "0x3f9f68feccc892303834833665bf204632438b028254fc2d5bceea757ff61ed3", "price_changes": [{"asset_id": "11947171408899503371980811142475369274013053223377767646204433492871687017998", "price": "0.771", "size": "25", "side": "BUY", "hash": "bccc39285e31e0f24207416a0cda0cbdcfe6dbf0", "best_bid": "0.892", "best_ask": "0.966"}, {"asset_id": "36088399593046466421453063228085042771351246231742717370399696243183381174466", "price": "0.229", "size": "25", "side": "SELL", "hash": "45768b3c7a83d5db076215350a297f2771eea5ae", "best_bid": "0.034", "best_ask": "0.108"}], "timestamp": "1769384757677", "event_type": "price_change"}}
{"_local_timestamp": "2026-01-25T23:45:57.747346+00:00", "data": {"market": "0x4a8005d19b41af72c1cd5c619640d9d51da548dd7c3544b12ae0c520d9e6805b", "price_changes": [{"asset_id": "57920006811393570084962107679227395634282382525602277724728836928684998641754", "price": "0.753", "size": "25", "side": "BUY", "hash": "2d5a5fd00843eb1c4a5cbd1369746ac83a2d62d9", "best_bid": "0.956", "best_ask": "0.968"}, {"asset_id": "42493289531592820306292191064557160874552640520793925047778017979799601355649", "price": "0.247", "size": "25", "side": "SELL", "hash": "f8ec69661c5df682fc375dc911e7a56b9116ba68", "best_bid": "0.032", "best_ask": "0.044"}], "timestamp": "1769384757677", "event_type": "price_change"}}
{"_local_timestamp": "2026-01-25T23:45:57.933811+00:00", "data": {"market": "0x3f9f68feccc892303834833665bf204632438b028254fc2d5bceea757ff61ed3", "price_changes": [{"asset_id": "11947171408899503371980811142475369274013053223377767646204433492871687017998", "price": "0.403", "size": "81", "side": "BUY", "hash": "9f0a0510c3611d9f92780d518695a0f019bb5846", "best_bid": "0.892", "best_ask": "0.966"}, {"asset_id": "36088399593046466421453063228085042771351246231742717370399696243183381174466", "price": "0.597", "size": "81", "side": "SELL", "hash": "0357e7dd35c50dd0d9c3b04910b08b1d581cf726", "best_bid": "0.034", "best_ask": "0.108"}], "timestamp": "1769384757848", "event_type": "price_change"}}
{"_local_timestamp": "2026-01-25T23:45:59.538962+00:00", "data": {"market": "0x3849e1d62e0807801913d3e2427e8caf3cc6dd1c8ef42d8d5c08c6f9c449dc5e", "price_changes": [{"asset_id": "8070607953656787024050950499598687532281829563384949938603247089607814583142", "price": "0.38", "size": "27.04", "side": "SELL", "hash": "8cff4fbf7e8a4fdd9e1e4a985f12bc7945f6ca9d", "best_bid": "0.3", "best_ask": "0.33"}, {"asset_id": "56615676606297588259337956203332341775475048285080710344367729433788967812170", "price": "0.62", "size": "27.04", "side": "BUY", "hash": "d5488708dcca9569a346afef3d4fe1396f1f1c73", "best_bid": "0.67", "best_ask": "0.7"}], "timestamp": "1769384759462", "event_type": "price_change"}}
