{"_local_timestamp": "2026-01-25T23:40:42.628724+00:00", "data": [{"market": "0x57d601622f7211f1bafc592e21baf81df8f44741e6ee708aee2449b49b58fc82", "asset_id": "12668390728546664562591096503585520540809771817912759179044387646050235405928", "timestamp": "1769384362726", "hash": "bf5834945218c44f1d451abc274a8510ee61cb1d", "bids": [{"price": "0.01", "size": "3872.22"}, {"price": "0.02", "size": "10.63"}, {"price": "0.04", "size": "200"}, {"price": "0.05", "size": "810"}, {"price": "0.06", "size": "200"}, {"price": "0.07", "size": "100"}, {"price": "0.08", "size": "9.14"}, {"price": "0.11", "size": "225"}, {"price": "0.13", "size": "7.69"}, {"price": "0.16", "size": "150"}, {"price": "0.21", "size": "100"}, {"price": "0.26", "size": "162.66"}, {"price": "0.5", "size": "40"}, {"price": "0.51", "size": "66.66"}], "asks": [{"price": "0.99", "size": "84.65"}, {"price": "0.98", "size": "46.03"}, {"price": "0.97", "size": "20"}, {"price": "0.96", "size": "5.98"}, {"price": "0.95", "size": "30"}, {"price": "0.94", "size": "40.86"}, {"price": "0.91", "size": "70.13"}, {"price": "0.9", "size": "8.83"}, {"price": "0.84", "size": "1.66"}, {"price": "0.83", "size": "5.88"}], "event_type": "book", "last_trade_price": ""}, {"market": "0x57d601622f7211f1bafc592e21baf81df8f44741e6ee708aee2449b49b58fc82", "asset_id": "97753848768374060999337901528962238014065821426341113231597534959461731339133", "timestamp": "1769384362726", "hash": "063bb0fd4655665631e639f1df597652d4b57a17", "bids": [{"price": "0.01", "size": "84.65"}, {"price": "0.02", "size": "46.03"}, {"price": "0.03", "size": "20"}, {"price": "0.04", "size": "5.98"}, {"price": "0.05", "size": "30"}, {"price": "0.06", "size": "40.86"}, {"price": "0.09", "size": "70.13"}, {"price": "0.1", "size": "8.83"}, {"price": "0.16", "size": "1.66"}, {"price": "0.17", "size": "5.88"}], "asks": [{"price": "0.99", "size": "3872.22"}, {"price": "0.98", "size": "10.63"}, {"price": "0.96", "size": "200"}, {"price": "0.95", "size": "810"}, {"price": "0.94", "size": "200"}, {"price": "0.93", "size": "100"}, {"price": "0.92", "size": "9.14"}, {"price": "0.89", "size": "225"}, {"price": "0.87", "size": "7.69"}, {"price": "0.84", "size": "150"}, {"price": "0.79", "size": "100"}, {"price": "0.74", "size": "162.66"}, {"price": "0.5", "size": "40"}, {"price": "0.49", "size": "66.66"}], "event_type": "book", "last_trade_price": ""}, {"market": "0x07db4ca35f28bc5ca53a161794ab7b6aad0f3f4b32786fd2c3ca3070cbd31d23", "asset_id": "89399296058082802849637265880462852921510982613019570700598879554887149139762", "timestamp": "1769384438862", "hash": "43e45247e0ad274f534815d613e1394573a94be7", "bids": [{"price": "0.01", "size": "76.23"}, {"price": "0.02", "size": "44.44"}, {"price": "0.03", "size": "7.94"}, {"price": "0.04", "size": "62.66"}, {"price": "0.05", "size": "9.94"}, {"price": "0.09", "size": "73.76"}], "asks": [{"price": "0.99", "size": "1375.21"}, {"price": "0.98", "size": "308.25"}, {"price": "0.97", "size": "100"}, {"price": "0.96", "size": "205.59"}, {"price": "0.95", "size": "230"}, {"price": "0.94", "size": "33"}, {"price": "0.93", "size": "8.22"}, {"price": "0.89", "size": "225"}, {"price": "0.84", "size": "66.66"}, {"price": "0.83", "size": "5.59"}, {"price": "0.74", "size": "96"}, {"price": "0.7", "size": "6"}, {"price": "0.67", "size": "200"}, {"price": "0.65", "size": "66.66"}, {"price": "0.64", "size": "20"}, {"price": "0.5", "size": "20"}], "event_type": "book", "last_trade_price": ""}, {"market": "0x07db4ca35f28bc5ca53a161794ab7b6aad0f3f4b32786fd2c3ca3070cbd31d23", "asset_id": "24363275266089775305424843015532890390275785659687191694023230547125544911803", "timestamp": "1769384438862", "hash": "54cb7ceabe469af9236dc79d95059e2d65a2bb10", "bids": [{"price": "0.01", "size": "1375.21"}, {"price": "0.02", "size": "308.25"}, {"price": "0.03", "size": "100"}, {"price": "0.04", "size": "205.59"}, {"price": "0.05", "size": "230"}, {"price": "0.06", "size": "33"}, {"price": "0.07", "size": "8.22"}, {"price": "0.11", "size": "225"}, {"price": "0.16", "size": "66.66"}, {"price": "0.17", "size": "5.59"}, {"price": "0.26", "size": "96"}, {"price": "0.3", "size": "6"}, {"price": "0.33", "size": "200"}, {"price": "0.35", "size": "66.66"}, {"price": "0.36", "size": "20"}, {"price": "0.5", "size": "20"}], "asks": [{"price": "0.99", "size": "76.23"}, {"price": "0.98", "size": "44.44"}, {"price": "0.97", "size": "7.94"}, {"price": "0.96", "size": "62.66"}, {"price": "0.95", "size": "9.94"}, {"price": "0.91", "size": "73.76"}], "event_type": "book", "last_trade_price": ""}]}
{"_local_timestamp": "2026-01-25T23:40:52.966061+00:00", "data": {"market": "0x07db4ca35f28bc5ca53a161794ab7b6aad0f3f4b32786fd2c3ca3070cbd31d23", "price_changes": [{"asset_id": "24363275266089775305424843015532890390275785659687191694023230547125544911803", "price": "0.33", "size": "0", "side": "BUY", "hash": "6d0d795f587cdcc09c6175fd9160b5b21fc16dad", "best_bid": "0.5", "best_ask": "0.91"}, {"asset_id": "89399296058082802849637265880462852921510982613019570700598879554887149139762", "price": "0.67", "size": "0", "side": "SELL", "hash": "8619e2830b05c80cbcc1323576f767a8c425cf00", "best_bid": "0.09", "best_ask": "0.5"}], "timestamp": "1769384452899", "event_type": "price_change"}}
{"_local_timestamp": "2026-01-25T23:40:53.560472+00:00", "data": {"market": "0x07db4ca35f28bc5ca53a161794ab7b6aad0f3f4b32786fd2c3ca3070cbd31d23", "price_changes": [{"asset_id": "24363275266089775305424843015532890390275785659687191694023230547125544911803", "price": "0.11", "size": "275", "side": "BUY", "hash": "4ec8c22986cc192825e2e1dc9dcef2b37f0a95bf", "best_bid": "0.5", "best_ask": "0.91"}, {"asset_id": "89399296058082802849637265880462852921510982613019570700598879554887149139762", "price": "0.89", "size": "275", "side": "SELL", "hash": "2716762201e1211a2f9bf8dfcdad22aefb743500", "best_bid": "0.09", "best_ask": "0.5"}], "timestamp": "1769384453488", "event_type": "price_change"}}
{"_local_timestamp": "2026-01-25T23:40:53.560893+00:00", "data": {"market": "0x07db4ca35f28bc5ca53a161794ab7b6aad0f3f4b32786fd2c3ca3070cbd31d23", "price_changes": [{"asset_id": "24363275266089775305424843015532890390275785659687191694023230547125544911803", "price": "0.05", "size": "730", "side": "BUY", "hash": "96bcb42f38d2449876f54bb9e4a4f68efaac23f1", "best_bid": "0.5", "best_ask": "0.91"}, {"asset_id": "89399296058082802849637265880462852921510982613019570700598879554887149139762", "price": "0.95", "size": "730", "side": "SELL", "hash": "07fb296319d69648cc0b840282abfb8436b32d10", "best_bid": "0.09", "best_ask": "0.5"}], "timestamp": "1769384453490", "event_type": "price_change"}}
{"_local_timestamp": "2026-01-25T23:40:53.561265+00:00", "data": {"market": "0x07db4ca35f28bc5ca53a161794ab7b6aad0f3f4b32786fd2c3ca3070cbd31d23", "price_changes": [{"asset_id": "24363275266089775305424843015532890390275785659687191694023230547125544911803", "price": "0.01", "size": "3875.21", "side": "BUY", "hash": "e7e34834f92e24578469038a34c4fd10e9f4149c", "best_bid": "0.5", "best_ask": "0.91"}, {"asset_id": "89399296058082802849637265880462852921510982613019570700598879554887149139762", "price": "0.99", "size": "3875.21", "side": "SELL", "hash": "f196f6f3f522a29accdfe702392a3bc8f8c23537", "best_bid": "0.09", "best_ask": "0.5"}], "timestamp": "1769384453491", "event_type": "price_change"}}
{"_local_timestamp": "2026-01-25T23:41:40.232280+00:00", "data": {"market": "0x07db4ca35f28bc5ca53a161794ab7b6aad0f3f4b32786fd2c3ca3070cbd31d23", "price_changes": [{"asset_id": "24363275266089775305424843015532890390275785659687191694023230547125544911803", "price": "0.11", "size": "225", "side": "BUY", "hash": "f53b097b94673f125581aef8cf629e94bd248664", "best_bid": "0.5", "best_ask": "0.91"}, {"asset_id": "89399296058082802849637265880462852921510982613019570700598879554887149139762", "price": "0.89", "size": "225", "side": "SELL", "hash": "e9041bb2740a250e6837c8ff82a8aacc115fb352", "best_bid": "0.09", "best_ask": "0.5"}], "timestamp": "1769384500155", "event_type": "price_change"}}
{"_local_timestamp": "2026-01-25T23:41:40.233649+00:00", "data": {"market": "0x07db4ca35f28bc5ca53a161794ab7b6aad0f3f4b32786fd2c3ca3070cbd31d23", "price_changes": [{"asset_id": "24363275266089775305424843015532890390275785659687191694023230547125544911803", "price": "0.05", "size": "230", "side": "BUY", "hash": "f53b097b94673f125581aef8cf629e94bd248664", "best_bid": "0.5", "best_ask": "0.91"}, {"asset_id": "89399296058082802849637265880462852921510982613019570700598879554887149139762", "price": "0.95", "size": "230", "side": "SELL", "hash": "e9041bb2740a250e6837c8ff82a8aacc115fb352", "best_bid": "0.09", "best_ask": "0.5"}], "timestamp": "1769384500155", "event_type": "price_change"}}
{"_local_timestamp": "2026-01-25T23:41:40.233944+00:00", "data": {"market": "0x07db4ca35f28bc5ca53a161794ab7b6aad0f3f4b32786fd2c3ca3070cbd31d23", "price_changes": [{"asset_id": "24363275266089775305424843015532890390275785659687191694023230547125544911803", "price": "0.01", "size": "1375.21", "side": "BUY", "hash": "f53b097b94673f125581aef8cf629e94bd248664", "best_bid": "0.5", "best_ask": "0.91"}, {"asset_id": "89399296058082802849637265880462852921510982613019570700598879554887149139762", "price": "0.99", "size": "1375.21", "side": "SELL", "hash": "e9041bb2740a250e6837c8ff82a8aacc115fb352", "best_bid": "0.09", "best_ask": "0.5"}], "timestamp": "1769384500155", "event_type": "price_change"}}
{"_local_timestamp": "2026-01-25T23:41:50.886240+00:00", "data": {"market": "0x57d601622f7211f1bafc592e21baf81df8f44741e6ee708aee2449b49b58fc82", "price_changes": [{"asset_id": "12668390728546664562591096503585520540809771817912759179044387646050235405928", "price": "0.01", "size": "3572.22", "side": "BUY", "hash": "8951f09add02d12e9a9c66e551ed1edf4c20a89b", "best_bid": "0.51", "best_ask": "0.83"}, {"asset_id": "97753848768374060999337901528962238014065821426341113231597534959461731339133", "price": "0.99", "size": "3572.22", "side": "SELL", "hash": "2b0186d626b68c556380c1ea18a2cf0655eb3a99", "best_bid": "0.17", "best_ask": "0.49"}], "timestamp": "1769384510748", "event_type": "price_change"}}
{"_local_timestamp": "2026-01-25T23:41:50.887095+00:00", "data": {"market": "0x07db4ca35f28bc5ca53a161794ab7b6aad0f3f4b32786fd2c3ca3070cbd31d23", "price_changes": [{"asset_id": "24363275266089775305424843015532890390275785659687191694023230547125544911803", "price": "0.01", "size": "1075.21", "side": "BUY", "hash": "917bb689627f1ee00f5b19c35f6fbe52dddb68ca", "best_bid": "0.5", "best_ask": "0.91"}, {"asset_id": "89399296058082802849637265880462852921510982613019570700598879554887149139762", "price": "0.99", "size": "1075.21", "side": "SELL", "hash": "79644ef0142664a432bc1c30a3e474240399b4f4", "best_bid": "0.09", "best_ask": "0.5"}], "timestamp": "1769384510748", "event_type": "price_change"}}
{"_local_timestamp": "2026-01-25T23:42:21.199446+00:00", "data": {"market": "0x07db4ca35f28bc5ca53a161794ab7b6aad0f3f4b32786fd2c3ca3070cbd31d23", "price_changes": [{"asset_id": "24363275266089775305424843015532890390275785659687191694023230547125544911803", "price": "0.01", "size": "2075.21", "side": "BUY", "hash": "dd638e52d1da111cc86251f89c1026e53c4acd74", "best_bid": "0.5", "best_ask": "0.91"}, {"asset_id": "89399296058082802849637265880462852921510982613019570700598879554887149139762", "price": "0.99", "size": "2075.21", "side": "SELL", "hash": "15ab101c3735731213dd8a7d1273e7c81bb414d5", "best_bid": "0.09", "best_ask": "0.5"}], "timestamp": "1769384541076", "event_type": "price_change"}}
{"_local_timestamp": "2026-01-25T23:43:12.033247+00:00", "data": {"market": "0x07db4ca35f28bc5ca53a161794ab7b6aad0f3f4b32786fd2c3ca3070cbd31d23", "price_changes": [{"asset_id": "24363275266089775305424843015532890390275785659687191694023230547125544911803", "price": "0.35", "size": "0", "side": "BUY", "hash": "11d0b7079b3ceb7e11af9f118f48945cb7a37111", "best_bid": "0.5", "best_ask": "0.91"}, {"asset_id": "89399296058082802849637265880462852921510982613019570700598879554887149139762", "price": "0.65", "size": "0", "side": "SELL", "hash": "fba61b3f246b0bb77264f99046b686ecbe388892", "best_bid": "0.09", "best_ask": "0.5"}], "timestamp": "1769384591881", "event_type": "price_change"}}
{"_local_timestamp": "2026-01-25T23:43:12.046209+00:00", "data": {"market": "0x07db4ca35f28bc5ca53a161794ab7b6aad0f3f4b32786fd2c3ca3070cbd31d23", "price_changes": [{"asset_id": "24363275266089775305424843015532890390275785659687191694023230547125544911803", "price": "0.16", "size": "0", "side": "BUY", "hash": "11d0b7079b3ceb7e11af9f118f48945cb7a37111", "best_bid": "0.5", "best_ask": "0.91"}, {"asset_id": "89399296058082802849637265880462852921510982613019570700598879554887149139762", "price": "0.84", "size": "0", "side": "SELL", "hash": "fba61b3f246b0bb77264f99046b686ecbe388892", "best_bid": "0.09", "best_ask": "0.5"}], "timestamp": "1769384591881", "event_type": "price_change"}}
{"_local_timestamp": "2026-01-25T23:43:12.515319+00:00", "data": {"market": "0x07db4ca35f28bc5ca53a161794ab7b6aad0f3f4b32786fd2c3ca3070cbd31d23", "price_changes": [{"asset_id": "24363275266089775305424843015532890390275785659687191694023230547125544911803", "price": "0.26", "size": "162.66", "side": "BUY", "hash": "3af6fd5674c079ce48f7839c6eb069862b79237c", "best_bid": "0.5", "best_ask": "0.91"}, {"asset_id": "89399296058082802849637265880462852921510982613019570700598879554887149139762", "price": "0.74", "size": "162.66", "side": "SELL", "hash": "b005ac13b3b139b85299fe625c662402c73fc1b6", "best_bid": "0.09", "best_ask": "0.5"}], "timestamp": "1769384592403", "event_type": "price_change"}}
{"_local_timestamp": "2026-01-25T23:43:12.553849+00:00", "data": {"market": "0x07db4ca35f28bc5ca53a161794ab7b6aad0f3f4b32786fd2c3ca3070cbd31d23", "price_changes": [{"asset_id": "24363275266089775305424843015532890390275785659687191694023230547125544911803", "price": "0.51", "size": "66.66", "side": "BUY", "hash": "e26caa0797b33fd2c26885fe516711e38d0fcb52", "best_bid": "0.51", "best_ask": "0.91"}, {"asset_id": "89399296058082802849637265880462852921510982613019570700598879554887149139762", "price": "0.49", "size": "66.66", "side": "SELL", "hash": "37e3f533e9c2d0fcfc5f94675833191e22fd075e", "best_bid": "0.09", "best_ask": "0.49"}], "timestamp": "1769384592438", "event_type": "price_change"}}
{"_local_timestamp": "2026-01-25T23:43:15.161126+00:00", "data": {"market": "0x07db4ca35f28bc5ca53a161794ab7b6aad0f3f4b32786fd2c3ca3070cbd31d23", "price_changes": [{"asset_id": "24363275266089775305424843015532890390275785659687191694023230547125544911803", "price": "0.36", "size": "0", "side": "BUY", "hash": "954166cb8a70c307f74017c9e2357e046ddfff62", "best_bid": "0.51", "best_ask": "0.91"}, {"asset_id": "89399296058082802849637265880462852921510982613019570700598879554887149139762", "price": "0.64", "size": "0", "side": "SELL", "hash": "d4b67dc30030abe8884c12866b2a6f025b86f1a1", "best_bid": "0.09", "best_ask": "0.49"}], "timestamp": "1769384595011", "event_type": "price_change"}}
{"_local_timestamp": "2026-01-25T23:43:15.163966+00:00", "data": {"market": "0x07db4ca35f28bc5ca53a161794ab7b6aad0f3f4b32786fd2c3ca3070cbd31d23", "price_changes": [{"asset_id": "24363275266089775305424843015532890390275785659687191694023230547125544911803", "price": "0.27", "size": "20", "side": "BUY", "hash": "cb9001d9b80a570280a889e1194cce7e7f03ddaa", "best_bid": "0.51", "best_ask": "0.91"}, {"asset_id": "89399296058082802849637265880462852921510982613019570700598879554887149139762", "price": "0.73", "size": "20", "side": "SELL", "hash": "6c3e9963587d7cbd4df3b7f8d02b499fff031c5a", "best_bid": "0.09", "best_ask": "0.49"}], "timestamp": "1769384595035", "event_type": "price_change"}}
{"_local_timestamp": "2026-01-25T23:43:48.633036+00:00", "data": {"market": "0x07db4ca35f28bc5ca53a161794ab7b6aad0f3f4b32786fd2c3ca3070cbd31d23", "price_changes": [{"asset_id": "24363275266089775305424843015532890390275785659687191694023230547125544911803", "price": "0.02", "size": "1308.25", "side": "BUY", "hash": "ca3854e8ee69ca280402766d04cf716441fe9df6", "best_bid": "0.51", "best_ask": "0.91"}, {"asset_id": "89399296058082802849637265880462852921510982613019570700598879554887149139762", "price": "0.98", "size": "1308.25", "side": "SELL", "hash": "90c844dc2497d2e516770267118964deb94a5135", "best_bid": "0.09", "best_ask": "0.49"}], "timestamp": "1769384628567", "event_type": "price_change"}}
{"_local_timestamp": "2026-01-25T23:43:52.811531+00:00", "data": {"market": "0x07db4ca35f28bc5ca53a161794ab7b6aad0f3f4b32786fd2c3ca3070cbd31d23", "price_changes": [{"asset_id": "24363275266089775305424843015532890390275785659687191694023230547125544911803", "price": "0.11", "size": "275", "side": "BUY", "hash": "996b70064ed6cdb27bd45cb4aa9bcbb075c65a20", "best_bid": "0.51", "best_ask": "0.91"}, {"asset_id": "89399296058082802849637265880462852921510982613019570700598879554887149139762", "price": "0.89", "size": "275", "side": "SELL", "hash": "5f7aa891b69ac93b784c9c573a96f919ef7680f4", "best_bid": "0.09", "best_ask": "0.49"}], "timestamp": "1769384632658", "event_type": "price_change"}}
{"_local_timestamp": "2026-01-25T23:43:52.811875+00:00", "data": {"market": "0x07db4ca35f28bc5ca53a161794ab7b6aad0f3f4b32786fd2c3ca3070cbd31d23", "price_changes": [{"asset_id": "24363275266089775305424843015532890390275785659687191694023230547125544911803", "price": "0.01", "size": "4575.21", "side": "BUY", "hash": "2252653309c980c6e654dcd6cafa3b954ba69ae3", "best_bid": "0.51", "best_ask": "0.91"}, {"asset_id": "89399296058082802849637265880462852921510982613019570700598879554887149139762", "price": "0.99", "size": "4575.21", "side": "SELL", "hash": "3b0cde53ba76ae2c07b953401c701f1e6aed9932", "best_bid": "0.09", "best_ask": "0.49"}], "timestamp": "1769384632660", "event_type": "price_change"}}
{"_local_timestamp": "2026-01-25T23:43:52.812120+00:00", "data": {"market": "0x07db4ca35f28bc5ca53a161794ab7b6aad0f3f4b32786fd2c3ca3070cbd31d23", "price_changes": [{"asset_id": "24363275266089775305424843015532890390275785659687191694023230547125544911803", "price": "0.05", "size": "730", "side": "BUY", "hash": "8aad10464d0fcab51f1146a4f0adb6c3ccf9ce5f", "best_bid": "0.51", "best_ask": "0.91"}, {"asset_id": "89399296058082802849637265880462852921510982613019570700598879554887149139762", "price": "0.95", "size": "730", "side": "SELL", "hash": "d6f939e0798d85909bf9916c115ddc7ff0699fe9", "best_bid": "0.09", "best_ask": "0.49"}], "timestamp": "1769384632661", "event_type": "price_change"}}
{"_local_timestamp": "2026-01-25T23:44:18.261015+00:00", "data": {"market": "0x07db4ca35f28bc5ca53a161794ab7b6aad0f3f4b32786fd2c3ca3070cbd31d23", "price_changes": [{"asset_id": "24363275266089775305424843015532890390275785659687191694023230547125544911803", "price": "0.21", "size": "100", "side": "BUY", "hash": "faa6473b2e5c38b11226fcf6af65df2d369bb936", "best_bid": "0.51", "best_ask": "0.91"}, {"asset_id": "89399296058082802849637265880462852921510982613019570700598879554887149139762", "price": "0.79", "size": "100", "side": "SELL", "hash": "2821667ea11959699bc2c4ea1da93d364c0a3b92", "best_bid": "0.09", "best_ask": "0.49"}], "timestamp": "1769384658177", "event_type": "price_change"}}
{"_local_timestamp": "2026-01-25T23:44:18.269059+00:00", "data": {"market": "0x07db4ca35f28bc5ca53a161794ab7b6aad0f3f4b32786fd2c3ca3070cbd31d23", "price_changes": [{"asset_id": "24363275266089775305424843015532890390275785659687191694023230547125544911803", "price": "0.16", "size": "150", "side": "BUY", "hash": "2dcf97a565202bbc79efd655e58c5cabc3b537e1", "best_bid": "0.51", "best_ask": "0.91"}, {"asset_id": "89399296058082802849637265880462852921510982613019570700598879554887149139762", "price": "0.84", "size": "150", "side": "SELL", "hash": "62184f2901c860f40f8a0d969e4eb2a4665919f1", "best_bid": "0.09", "best_ask": "0.49"}], "timestamp": "1769384658183", "event_type": "price_change"}}
{"_local_timestamp": "2026-01-25T23:44:37.483101+00:00", "data": {"market": "0x07db4ca35f28bc5ca53a161794ab7b6aad0f3f4b32786fd2c3ca3070cbd31d23", "price_changes": [{"asset_id": "24363275266089775305424843015532890390275785659687191694023230547125544911803", "price": "0.05", "size": "230", "side": "BUY", "hash": "5f942d0dbf2b74ccadf19ecf8fedde1c6b166a05", "best_bid": "0.51", "best_ask": "0.91"}, {"asset_id": "89399296058082802849637265880462852921510982613019570700598879554887149139762", "price": "0.95", "size": "230", "side": "SELL", "hash": "7f73b78967b0da4687075aee3590908180d3eb21", "best_bid": "0.09", "best_ask": "0.49"}], "timestamp": "1769384677409", "event_type": "price_change"}}
{"_local_timestamp": "2026-01-25T23:44:37.756830+00:00", "data": {"market": "0x07db4ca35f28bc5ca53a161794ab7b6aad0f3f4b32786fd2c3ca3070cbd31d23", "price_changes": [{"asset_id": "24363275266089775305424843015532890390275785659687191694023230547125544911803", "price": "0.02", "size": "2108.25", "side": "BUY", "hash": "4ca9adb2d074b9093e27680829062242dba59023", "best_bid": "0.51", "best_ask": "0.91"}, {"asset_id": "89399296058082802849637265880462852921510982613019570700598879554887149139762", "price": "0.98", "size": "2108.25", "side": "SELL", "hash": "fc83266863c2345b8305549b129e3492096263e1", "best_bid": "0.09", "best_ask": "0.49"}], "timestamp": "1769384677688", "event_type": "price_change"}}
{"_local_timestamp": "2026-01-25T23:44:55.981280+00:00", "data": {"market": "0x07db4ca35f28bc5ca53a161794ab7b6aad0f3f4b32786fd2c3ca3070cbd31d23", "price_changes": [{"asset_id": "24363275266089775305424843015532890390275785659687191694023230547125544911803", "price": "0.01", "size": "3575.21", "side": "BUY", "hash": "77354fad1de45ee8d95747b962bea6fcca558903", "best_bid": "0.51", "best_ask": "0.91"}, {"asset_id": "89399296058082802849637265880462852921510982613019570700598879554887149139762", "price": "0.99", "size": "3575.21", "side": "SELL", "hash": "8d2ac566004a04cedeef7fb51e0160ad12d0701b", "best_bid": "0.09", "best_ask": "0.49"}], "timestamp": "1769384695893", "event_type": "price_change"}}
{"_local_timestamp": "2026-01-25T23:45:23.843223+00:00", "data": {"market": "0x07db4ca35f28bc5ca53a161794ab7b6aad0f3f4b32786fd2c3ca3070cbd31d23", "price_changes": [{"asset_id": "24363275266089775305424843015532890390275785659687191694023230547125544911803", "price": "0.11", "size": "225", "side": "BUY", "hash": "6d4f32d7850c48b852ce2d4364395533c01e3d0c", "best_bid": "0.51", "best_ask": "0.91"}, {"asset_id": "89399296058082802849637265880462852921510982613019570700598879554887149139762", "price": "0.89", "size": "225", "side": "SELL", "hash": "599778027ca253feed7e174276e50dcb5a42e8dc", "best_bid": "0.09", "best_ask": "0.49"}], "timestamp": "1769384723761", "event_type": "price_change"}}
{"_local_timestamp": "2026-01-25T23:45:57.676798+00:00", "data": {"market": "0x07db4ca35f28bc5ca53a161794ab7b6aad0f3f4b32786fd2c3ca3070cbd31d23", "price_changes": [{"asset_id": "24363275266089775305424843015532890390275785659687191694023230547125544911803", "price": "0.51", "size": "0", "side": "BUY", "hash": "ea9a4efd14cfb795efbc5d61c19ec883bb6fd1cd", "best_bid": "0.5", "best_ask": "0.91"}, {"asset_id": "89399296058082802849637265880462852921510982613019570700598879554887149139762", "price": "0.49", "size": "0", "side": "SELL", "hash": "4ff2229bd937470f3226b92ae8443bd29059eba8", "best_bid": "0.09", "best_ask": "0.5"}], "timestamp": "1769384757605", "event_type": "price_change"}}
{"_local_timestamp": "2026-01-25T23:45:57.677456+00:00", "data": {"market": "0x07db4ca35f28bc5ca53a161794ab7b6aad0f3f4b32786fd2c3ca3070cbd31d23", "price_changes": [{"asset_id": "24363275266089775305424843015532890390275785659687191694023230547125544911803", "price": "0.26", "size": "96", "side": "BUY", "hash": "ea9a4efd14cfb795efbc5d61c19ec883bb6fd1cd", "best_bid": "0.5", "best_ask": "0.91"}, {"asset_id": "89399296058082802849637265880462852921510982613019570700598879554887149139762", "price": "0.74", "size": "96", "side": "SELL", "hash": "4ff2229bd937470f3226b92ae8443bd29059eba8", "best_bid": "0.09", "best_ask": "0.5"}], "timestamp": "1769384757605", "event_type": "price_change"}}
{"_local_timestamp": "2026-01-25T23:45:57.677829+00:00", "data": {"market": "0x07db4ca35f28bc5ca53a161794ab7b6aad0f3f4b32786fd2c3ca3070cbd31d23", "price_changes": [{"asset_id": "24363275266089775305424843015532890390275785659687191694023230547125544911803", "price": "0.01", "size": "3508.55", "side": "BUY", "hash": "ea9a4efd14cfb795efbc5d61c19ec883bb6fd1cd", "best_bid": "0.5", "best_ask": "0.91"}, {"asset_id": "89399296058082802849637265880462852921510982613019570700598879554887149139762", "price": "0.99", "size": "3508.55", "side": "SELL", "hash": "4ff2229bd937470f3226b92ae8443bd29059eba8", "best_bid": "0.09", "best_ask": "0.5"}], "timestamp": "1769384757605", "event_type": "price_change"}}
{"_local_timestamp": "2026-01-25T23:45:58.012771+00:00", "data": {"market": "0x07db4ca35f28bc5ca53a161794ab7b6aad0f3f4b32786fd2c3ca3070cbd31d23", "price_changes": [{"asset_id": "24363275266089775305424843015532890390275785659687191694023230547125544911803", "price": "0.26", "size": "196", "side": "BUY", "hash": "e77f375fb8492e136d514de163add2e1c4364899", "best_bid": "0.5", "best_ask": "0.91"}, {"asset_id": "89399296058082802849637265880462852921510982613019570700598879554887149139762", "price": "0.74", "size": "196", "side": "SELL", "hash": "15134449670c466bc6ead0afadfa12075d764b9e", "best_bid": "0.09", "best_ask": "0.5"}], "timestamp": "1769384757944", "event_type": "price_change"}}
{"_local_timestamp": "2026-01-25T23:45:58.182631+00:00", "data": {"market": "0x07db4ca35f28bc5ca53a161794ab7b6aad0f3f4b32786fd2c3ca3070cbd31d23", "price_changes": [{"asset_id": "24363275266089775305424843015532890390275785659687191694023230547125544911803", "price": "0.01", "size": "3608.55", "side": "BUY", "hash": "920ce81612c34b6496d24e1d46f7bf84e6919730", "best_bid": "0.5", "best_ask": "0.91"}, {"asset_id": "89399296058082802849637265880462852921510982613019570700598879554887149139762", "price": "0.99", "size": "3608.55", "side": "SELL", "hash": "bec670b893d5afe1e5b84a9387cb1337a14a224c", "best_bid": "0.09", "best_ask": "0.5"}], "timestamp": "1769384758095", "event_type": "price_change"}}
{"_local_timestamp": "2026-01-25T23:46:11.217090+00:00", "data": {"market": "0x07db4ca35f28bc5ca53a161794ab7b6aad0f3f4b32786fd2c3ca3070cbd31d23", "price_changes": [{"asset_id": "24363275266089775305424843015532890390275785659687191694023230547125544911803", "price": "0.04", "size": "105.59", "side": "BUY", "hash": "abbe95a73de5b22a306c8a6de144a1705f4a52fc", "best_bid": "0.5", "best_ask": "0.91"}, {"asset_id": "89399296058082802849637265880462852921510982613019570700598879554887149139762", "price": "0.96", "size": "105.59", "side": "SELL", "hash": "5250d6ad5ae0b0b77462d462b8b0dda0cafa2e7c", "best_bid": "0.09", "best_ask": "0.5"}], "timestamp": "1769384771119", "event_type": "price_change"}}
{"_local_timestamp": "2026-01-25T23:46:11.659610+00:00", "data": {"market": "0x07db4ca35f28bc5ca53a161794ab7b6aad0f3f4b32786fd2c3ca3070cbd31d23", "price_changes": [{"asset_id": "24363275266089775305424843015532890390275785659687191694023230547125544911803", "price": "0.03", "size": "200", "side": "BUY", "hash": "508892748528bba9cea9ca36b3d6e3fb6b5fde9c", "best_bid": "0.5", "best_ask": "0.91"}, {"asset_id": "89399296058082802849637265880462852921510982613019570700598879554887149139762", "price": "0.97", "size": "200", "side": "SELL", "hash": "0842db12275a065952974241d2be20d464516f42", "best_bid": "0.09", "best_ask": "0.5"}], "timestamp": "1769384771578", "event_type": "price_change"}}
{"_local_timestamp": "2026-01-25T23:46:51.521801+00:00", "data": {"market": "0x07db4ca35f28bc5ca53a161794ab7b6aad0f3f4b32786fd2c3ca3070cbd31d23", "price_changes": [{"asset_id": "24363275266089775305424843015532890390275785659687191694023230547125544911803", "price": "0.01", "size": "3908.55", "side": "BUY", "hash": "831295275827c8c0620f4bcfd0a8df837dae12dc", "best_bid": "0.5", "best_ask": "0.91"}, {"asset_id": "89399296058082802849637265880462852921510982613019570700598879554887149139762", "price": "0.99", "size": "3908.55", "side": "SELL", "hash": "922403e0463936b0759093a4d1965973aba5e940", "best_bid": "0.09", "best_ask": "0.5"}], "timestamp": "1769384811210", "event_type": "price_change"}}
{"_local_timestamp": "2026-01-25T23:46:58.987902+00:00", "data": {"market": "0x07db4ca35f28bc5ca53a161794ab7b6aad0f3f4b32786fd2c3ca3070cbd31d23", "price_changes": [{"asset_id": "24363275266089775305424843015532890390275785659687191694023230547125544911803", "price": "0.11", "size": "0", "side": "BUY", "hash": "1143af34717db9d5c28748881cb6fbb89c5e84dc", "best_bid": "0.5", "best_ask": "0.91"}, {"asset_id": "89399296058082802849637265880462852921510982613019570700598879554887149139762", "price": "0.89", "size": "0", "side": "SELL", "hash": "d649540263c0c1c7ea44455554aa9169858c5a40", "best_bid": "0.09", "best_ask": "0.5"}], "timestamp": "1769384818868", "event_type": "price_change"}}
{"_local_timestamp": "2026-01-25T23:46:58.988306+00:00", "data": {"market": "0x07db4ca35f28bc5ca53a161794ab7b6aad0f3f4b32786fd2c3ca3070cbd31d23", "price_changes": [{"asset_id": "24363275266089775305424843015532890390275785659687191694023230547125544911803", "price": "0.21", "size": "0", "side": "BUY", "hash": "1143af34717db9d5c28748881cb6fbb89c5e84dc", "best_bid": "0.5", "best_ask": "0.91"}, {"asset_id": "89399296058082802849637265880462852921510982613019570700598879554887149139762", "price": "0.79", "size": "0", "side": "SELL", "hash": "d649540263c0c1c7ea44455554aa9169858c5a40", "best_bid": "0.09", "best_ask": "0.5"}], "timestamp": "1769384818868", "event_type": "price_change"}}
{"_local_timestamp": "2026-01-25T23:46:58.988585+00:00", "data": {"market": "0x07db4ca35f28bc5ca53a161794ab7b6aad0f3f4b32786fd2c3ca3070cbd31d23", "price_changes": [{"asset_id": "24363275266089775305424843015532890390275785659687191694023230547125544911803", "price": "0.16", "size": "0", "side": "BUY", "hash": "1143af34717db9d5c28748881cb6fbb89c5e84dc", "best_bid": "0.5", "best_ask": "0.91"}, {"asset_id": "89399296058082802849637265880462852921510982613019570700598879554887149139762", "price": "0.84", "size": "0", "side": "SELL", "hash": "d649540263c0c1c7ea44455554aa9169858c5a40", "best_bid": "0.09", "best_ask": "0.5"}], "timestamp": "1769384818868", "event_type": "price_change"}}
{"_local_timestamp": "2026-01-25T23:47:23.260995+00:00", "data": {"market": "0x07db4ca35f28bc5ca53a161794ab7b6aad0f3f4b32786fd2c3ca3070cbd31d23", "price_changes": [{"asset_id": "24363275266089775305424843015532890390275785659687191694023230547125544911803", "price": "0.02", "size": "1108.25", "side": "BUY", "hash": "3ae8d9a01e6f1f08da004f5215ac8aa8040d73b5", "best_bid": "0.5", "best_ask": "0.91"}, {"asset_id": "89399296058082802849637265880462852921510982613019570700598879554887149139762", "price": "0.98", "size": "1108.25", "side": "SELL", "hash": "d1b6ea6a032f7ad910b2fedc1442174020129cbd", "best_bid": "0.09", "best_ask": "0.5"}], "timestamp": "1769384843177", "event_type": "price_change"}}
{"_local_timestamp": "2026-01-25T23:47:45.612402+00:00", "data": {"market": "0x07db4ca35f28bc5ca53a161794ab7b6aad0f3f4b32786fd2c3ca3070cbd31d23", "price_changes": [{"asset_id": "24363275266089775305424843015532890390275785659687191694023230547125544911803", "price": "0.02", "size": "308.25", "side": "BUY", "hash": "32c4e9022e74f31757c1928a2a7f7483242ceeae", "best_bid": "0.5", "best_ask": "0.91"}, {"asset_id": "89399296058082802849637265880462852921510982613019570700598879554887149139762", "price": "0.98", "size": "308.25", "side": "SELL", "hash": "0288914bbdb00264a016781479c860e764402577", "best_bid": "0.09", "best_ask": "0.5"}], "timestamp": "1769384865520", "event_type": "price_change"}}
{"_local_timestamp": "2026-01-25T23:47:45.935838+00:00", "data": {"market": "0x07db4ca35f28bc5ca53a161794ab7b6aad0f3f4b32786fd2c3ca3070cbd31d23", "price_changes": [{"asset_id": "24363275266089775305424843015532890390275785659687191694023230547125544911803", "price": "0.05", "size": "730", "side": "BUY", "hash": "3e0b4c2abd60c335dbd911e5ad1672d32a4abceb", "best_bid": "0.5", "best_ask": "0.91"}, {"asset_id": "89399296058082802849637265880462852921510982613019570700598879554887149139762", "price": "0.95", "size": "730", "side": "SELL", "hash": "7f4214904d28abcccf4dd3a7bc0b5f8bc038a631", "best_bid": "0.09", "best_ask": "0.5"}], "timestamp": "1769384865845", "event_type": "price_change"}}
{"_local_timestamp": "2026-01-25T23:48:02.534951+00:00", "data": {"market": "0x07db4ca35f28bc5ca53a161794ab7b6aad0f3f4b32786fd2c3ca3070cbd31d23", "price_changes": [{"asset_id": "24363275266089775305424843015532890390275785659687191694023230547125544911803", "price": "0.01", "size": "2908.55", "side": "BUY", "hash": "d501a2d936d8f1205c304d97f0229bf0ab533c59", "best_bid": "0.5", "best_ask": "0.91"}, {"asset_id": "89399296058082802849637265880462852921510982613019570700598879554887149139762", "price": "0.99", "size": "2908.55", "side": "SELL", "hash": "7ef59e363b153cda33d75297931f6a6a63c762a6", "best_bid": "0.09", "best_ask": "0.5"}], "timestamp": "1769384882446", "event_type": "price_change"}}
{"_local_timestamp": "2026-01-25T23:48:05.430979+00:00", "data": {"market": "0x07db4ca35f28bc5ca53a161794ab7b6aad0f3f4b32786fd2c3ca3070cbd31d23", "price_changes": [{"asset_id": "24363275266089775305424843015532890390275785659687191694023230547125544911803", "price": "0.51", "size": "9.8", "side": "BUY", "hash": "f401da88f127d5b10464e516d0785bad1bd591ae", "best_bid": "0.51", "best_ask": "0.91"}, {"asset_id": "89399296058082802849637265880462852921510982613019570700598879554887149139762", "price": "0.49", "size": "9.8", "side": "SELL", "hash": "a811a652881408334e7e00f0c62f0fe61a0142a4", "best_bid": "0.09", "best_ask": "0.49"}], "timestamp": "1769384885364", "event_type": "price_change"}}
{"_local_timestamp": "2026-01-25T23:48:20.154348+00:00", "data": {"market": "0x07db4ca35f28bc5ca53a161794ab7b6aad0f3f4b32786fd2c3ca3070cbd31d23", "price_changes": [{"asset_id": "24363275266089775305424843015532890390275785659687191694023230547125544911803", "price": "0.5", "size": "70", "side": "BUY", "hash": "c397d3ef1e7774b294ea477bc4cf746cb683bb9f", "best_bid": "0.51", "best_ask": "0.91"}, {"asset_id": "89399296058082802849637265880462852921510982613019570700598879554887149139762", "price": "0.5", "size": "70", "side": "SELL", "hash": "dc0c540f1443f2a59f837553b1cfcf82fe5417e0", "best_bid": "0.09", "best_ask": "0.49"}], "timestamp": "1769384900051", "event_type": "price_change"}}
{"_local_timestamp": "2026-01-25T23:48:32.858673+00:00", "data": {"market": "0x07db4ca35f28bc5ca53a161794ab7b6aad0f3f4b32786fd2c3ca3070cbd31d23", "price_changes": [{"asset_id": "24363275266089775305424843015532890390275785659687191694023230547125544911803", "price": "0.51", "size": "0", "side": "BUY", "hash": "a5159a39925a61ba007d570d2eeda26d2ca37ce0", "best_bid": "0.5", "best_ask": "0.91"}, {"asset_id": "89399296058082802849637265880462852921510982613019570700598879554887149139762", "price": "0.49", "size": "0", "side": "SELL", "hash": "3e0a32bb925db709addfc50880bc18d0aad3e96e", "best_bid": "0.09", "best_ask": "0.5"}], "timestamp": "1769384912776", "event_type": "price_change"}}
{"_local_timestamp": "2026-01-25T23:48:34.760036+00:00", "data": {"market": "0x07db4ca35f28bc5ca53a161794ab7b6aad0f3f4b32786fd2c3ca3070cbd31d23", "price_changes": [{"asset_id": "24363275266089775305424843015532890390275785659687191694023230547125544911803", "price": "0.26", "size": "96", "side": "BUY", "hash": "5b3c65b016aafac281a8de801585ac3c26eb9d58", "best_bid": "0.5", "best_ask": "0.91"}, {"asset_id": "89399296058082802849637265880462852921510982613019570700598879554887149139762", "price": "0.74", "size": "96", "side": "SELL", "hash": "9abab230e609552df09563dda2c5d20dc9003b85", "best_bid": "0.09", "best_ask": "0.5"}], "timestamp": "1769384914683", "event_type": "price_change"}}
{"_local_timestamp": "2026-01-25T23:48:34.760353+00:00", "data": {"market": "0x07db4ca35f28bc5ca53a161794ab7b6aad0f3f4b32786fd2c3ca3070cbd31d23", "price_changes": [{"asset_id": "24363275266089775305424843015532890390275785659687191694023230547125544911803", "price": "0.01", "size": "2808.55", "side": "BUY", "hash": "5b3c65b016aafac281a8de801585ac3c26eb9d58", "best_bid": "0.5", "best_ask": "0.91"}, {"asset_id": "89399296058082802849637265880462852921510982613019570700598879554887149139762", "price": "0.99", "size": "2808.55", "side": "SELL", "hash": "9abab230e609552df09563dda2c5d20dc9003b85", "best_bid": "0.09", "best_ask": "0.5"}], "timestamp": "1769384914683", "event_type": "price_change"}}
{"_local_timestamp": "2026-01-25T23:48:35.243620+00:00", "data": {"market": "0x07db4ca35f28bc5ca53a161794ab7b6aad0f3f4b32786fd2c3ca3070cbd31d23", "price_changes": [{"asset_id": "24363275266089775305424843015532890390275785659687191694023230547125544911803", "price": "0.51", "size": "66.66", "side": "BUY", "hash": "1c319123e58e11c7dd4320571694f810b8de7fb1", "best_bid": "0.51", "best_ask": "0.91"}, {"asset_id": "89399296058082802849637265880462852921510982613019570700598879554887149139762", "price": "0.49", "size": "66.66", "side": "SELL", "hash": "a327d1736e474f5ea489806a02188bb92c740469", "best_bid": "0.09", "best_ask": "0.49"}], "timestamp": "1769384915162", "event_type": "price_change"}}
{"_local_timestamp": "2026-01-25T23:48:35.253757+00:00", "data": {"market": "0x07db4ca35f28bc5ca53a161794ab7b6aad0f3f4b32786fd2c3ca3070cbd31d23", "price_changes": [{"asset_id": "24363275266089775305424843015532890390275785659687191694023230547125544911803", "price": "0.01", "size": "2875.21", "side": "BUY", "hash": "a2a93685240f1cb9a408b4b441f491f1e06c15b1", "best_bid": "0.51", "best_ask": "0.91"}, {"asset_id": "89399296058082802849637265880462852921510982613019570700598879554887149139762", "price": "0.99", "size": "2875.21", "side": "SELL", "hash": "e36329a977b96dedbe6040e16f5f72cbc45c8bf5", "best_bid": "0.09", "best_ask": "0.49"}], "timestamp": "1769384915167", "event_type": "price_change"}}
{"_local_timestamp": "2026-01-25T23:48:35.270738+00:00", "data": {"market": "0x07db4ca35f28bc5ca53a161794ab7b6aad0f3f4b32786fd2c3ca3070cbd31d23", "price_changes": [{"asset_id": "24363275266089775305424843015532890390275785659687191694023230547125544911803", "price": "0.26", "size": "162.66", "side": "BUY", "hash": "a34ba9862ec7150a43d7c1bd133d4f2ce58d0e15", "best_bid": "0.51", "best_ask": "0.91"}, {"asset_id": "89399296058082802849637265880462852921510982613019570700598879554887149139762", "price": "0.74", "size": "162.66", "side": "SELL", "hash": "e435870d9a011722d477fed2bce8a3af3814b699", "best_bid": "0.09", "best_ask": "0.49"}], "timestamp": "1769384915185", "event_type": "price_change"}}
{"_local_timestamp": "2026-01-25T23:48:39.473078+00:00", "data": {"market": "0x07db4ca35f28bc5ca53a161794ab7b6aad0f3f4b32786fd2c3ca3070cbd31d23", "price_changes": [{"asset_id": "24363275266089775305424843015532890390275785659687191694023230547125544911803", "price": "0.5", "size": "20", "side": "BUY", "hash": "e0d15ac2d15672ab22e2929a3bfdfb01c2cc2801", "best_bid": "0.51", "best_ask": "0.91"}, {"asset_id": "89399296058082802849637265880462852921510982613019570700598879554887149139762", "price": "0.5", "size": "20", "side": "SELL", "hash": "32741f04e69aaf75e8c472129fe4b68ea1def59f", "best_bid": "0.09", "best_ask": "0.49"}], "timestamp": "1769384919393", "event_type": "price_change"}}
{"_local_timestamp": "2026-01-25T23:49:00.457576+00:00", "data": {"market": "0x07db4ca35f28bc5ca53a161794ab7b6aad0f3f4b32786fd2c3ca3070cbd31d23", "price_changes": [{"asset_id": "24363275266089775305424843015532890390275785659687191694023230547125544911803", "price": "0.52", "size": "9.61", "side": "BUY", "hash": "6d01239ade614b9e8a64de2fecb9eb1531311feb", "best_bid": "0.52", "best_ask": "0.91"}, {"asset_id": "89399296058082802849637265880462852921510982613019570700598879554887149139762", "price": "0.48", "size": "9.61", "side": "SELL", "hash": "0a6670300c46c0822990cfa7c7e3c2ebd7622c20", "best_bid": "0.09", "best_ask": "0.48"}], "timestamp": "1769384940390", "event_type": "price_change"}}
{"_local_timestamp": "2026-01-25T23:49:19.082880+00:00", "data": {"market": "0x07db4ca35f28bc5ca53a161794ab7b6aad0f3f4b32786fd2c3ca3070cbd31d23", "price_changes": [{"asset_id": "24363275266089775305424843015532890390275785659687191694023230547125544911803", "price": "0.5", "size": "0", "side": "BUY", "hash": "13545edd12dd1d0193d33ab1be8fb1385eef8c5c", "best_bid": "0.52", "best_ask": "0.91"}, {"asset_id": "89399296058082802849637265880462852921510982613019570700598879554887149139762", "price": "0.5", "size": "0", "side": "SELL", "hash": "0c7a21c892eb9db20c9883be2201ef9cea488f76", "best_bid": "0.09", "best_ask": "0.48"}], "timestamp": "1769384959003", "event_type": "price_change"}}
{"_local_timestamp": "2026-01-25T23:49:24.782132+00:00", "data": {"market": "0x07db4ca35f28bc5ca53a161794ab7b6aad0f3f4b32786fd2c3ca3070cbd31d23", "price_changes": [{"asset_id": "24363275266089775305424843015532890390275785659687191694023230547125544911803", "price": "0.21", "size": "100", "side": "BUY", "hash": "7b33544c6aef223164943434a7d8f590d0581974", "best_bid": "0.52", "best_ask": "0.91"}, {"asset_id": "89399296058082802849637265880462852921510982613019570700598879554887149139762", "price": "0.79", "size": "100", "side": "SELL", "hash": "83b636469b6811bcc4f48de4ed3f532e36300b6c", "best_bid": "0.09", "best_ask": "0.48"}], "timestamp": "1769384964683", "event_type": "price_change"}}
{"_local_timestamp": "2026-01-25T23:49:24.782580+00:00", "data": {"market": "0x07db4ca35f28bc5ca53a161794ab7b6aad0f3f4b32786fd2c3ca3070cbd31d23", "price_changes": [{"asset_id": "24363275266089775305424843015532890390275785659687191694023230547125544911803", "price": "0.16", "size": "150", "side": "BUY", "hash": "d69e7c0c659c796d14c5de8ce76c253aa3a66739", "best_bid": "0.52", "best_ask": "0.91"}, {"asset_id": "89399296058082802849637265880462852921510982613019570700598879554887149139762", "price": "0.84", "size": "150", "side": "SELL", "hash": "3c51aa986191e2f0a9a37e9a9aa0db57d94f8690", "best_bid": "0.09", "best_ask": "0.48"}], "timestamp": "1769384964686", "event_type": "price_change"}}
{"_local_timestamp": "2026-01-25T23:49:24.790134+00:00", "data": {"market": "0x07db4ca35f28bc5ca53a161794ab7b6aad0f3f4b32786fd2c3ca3070cbd31d23", "price_changes": [{"asset_id": "24363275266089775305424843015532890390275785659687191694023230547125544911803", "price": "0.11", "size": "225", "side": "BUY", "hash": "27c2c94c0413941815cb0328f3169d8355ede3fa", "best_bid": "0.52", "best_ask": "0.91"}, {"asset_id": "89399296058082802849637265880462852921510982613019570700598879554887149139762", "price": "0.89", "size": "225", "side": "SELL", "hash": "9824dda94b267b53d256c7dc57324448c69089bd", "best_bid": "0.09", "best_ask": "0.48"}], "timestamp": "1769384964688", "event_type": "price_change"}}
{"_local_timestamp": "2026-01-25T23:49:27.795634+00:00", "data": {"market": "0x07db4ca35f28bc5ca53a161794ab7b6aad0f3f4b32786fd2c3ca3070cbd31d23", "price_changes": [{"asset_id": "24363275266089775305424843015532890390275785659687191694023230547125544911803", "price": "0.52", "size": "0", "side": "BUY", "hash": "ddbfd43edfd0e5ba548e8524531eacdb4af33f16", "best_bid": "0.51", "best_ask": "0.91"}, {"asset_id": "89399296058082802849637265880462852921510982613019570700598879554887149139762", "price": "0.48", "size": "0", "side": "SELL", "hash": "b162ae3568412923c6f0741a9718dbd32fca582c", "best_bid": "0.09", "best_ask": "0.49"}], "timestamp": "1769384967729", "event_type": "price_change"}}
{"_local_timestamp": "2026-01-25T23:49:30.484617+00:00", "data": {"market": "0x07db4ca35f28bc5ca53a161794ab7b6aad0f3f4b32786fd2c3ca3070cbd31d23", "price_changes": [{"asset_id": "24363275266089775305424843015532890390275785659687191694023230547125544911803", "price": "0.01", "size": "2575.21", "side": "BUY", "hash": "9018aeef9b74ca0f07e717fbefe8ee0d372acb68", "best_bid": "0.51", "best_ask": "0.91"}, {"asset_id": "89399296058082802849637265880462852921510982613019570700598879554887149139762", "price": "0.99", "size": "2575.21", "side": "SELL", "hash": "3a43f49c11c7d4212053334c7d3b642d29ca785c", "best_bid": "0.09", "best_ask": "0.49"}], "timestamp": "1769384970082", "event_type": "price_change"}}
{"_local_timestamp": "2026-01-25T23:49:36.169606+00:00", "data": {"market": "0x57d601622f7211f1bafc592e21baf81df8f44741e6ee708aee2449b49b58fc82", "price_changes": [{"asset_id": "12668390728546664562591096503585520540809771817912759179044387646050235405928", "price": "0.04", "size": "100", "side": "BUY", "hash": "572224a8f1e99b9178b2593fdfb5b43fc5ad339b", "best_bid": "0.51", "best_ask": "0.83"}, {"asset_id": "97753848768374060999337901528962238014065821426341113231597534959461731339133", "price": "0.96", "size": "100", "side": "SELL", "hash": "7474a390b6416d65e9e9ba0518d45559e6b2e126", "best_bid": "0.17", "best_ask": "0.49"}], "timestamp": "1769384976087", "event_type": "price_change"}}
{"_local_timestamp": "2026-01-25T23:49:36.447029+00:00", "data": {"market": "0x57d601622f7211f1bafc592e21baf81df8f44741e6ee708aee2449b49b58fc82", "price_changes": [{"asset_id": "12668390728546664562591096503585520540809771817912759179044387646050235405928", "price": "0.06", "size": "300", "side": "BUY", "hash": "1af3bfaf802cda7d181236ccb0498633ed852dfd", "best_bid": "0.51", "best_ask": "0.83"}, {"asset_id": "97753848768374060999337901528962238014065821426341113231597534959461731339133", "price": "0.94", "size": "300", "side": "SELL", "hash": "227db64def702786a8b1d0884915bb6ec4a7577f", "best_bid": "0.17", "best_ask": "0.49"}], "timestamp": "1769384976378", "event_type": "price_change"}}
{"_local_timestamp": "2026-01-25T23:50:23.528452+00:00", "data": {"market": "0x07db4ca35f28bc5ca53a161794ab7b6aad0f3f4b32786fd2c3ca3070cbd31d23", "price_changes": [{"asset_id": "24363275266089775305424843015532890390275785659687191694023230547125544911803", "price": "0.52", "size": "9.61", "side": "BUY", "hash": "6ffd31a02c73d6240d91e054f5ee503bb8a0af0b", "best_bid": "0.52", "best_ask": "0.91"}, {"asset_id": "89399296058082802849637265880462852921510982613019570700598879554887149139762", "price": "0.48", "size": "9.61", "side": "SELL", "hash": "eca8b22713491f5348020b3b3f6d381a6447a1b6", "best_bid": "0.09", "best_ask": "0.48"}], "timestamp": "1769385023388", "event_type": "price_change"}}
{"_local_timestamp": "2026-01-25T23:50:51.024055+00:00", "data": {"market": "0x07db4ca35f28bc5ca53a161794ab7b6aad0f3f4b32786fd2c3ca3070cbd31d23", "price_changes": [{"asset_id": "24363275266089775305424843015532890390275785659687191694023230547125544911803", "price": "0.52", "size": "0", "side": "BUY", "hash": "4719fb95ad69ae303c7fb08c6c5f04bd1cb44601", "best_bid": "0.51", "best_ask": "0.91"}, {"asset_id": "89399296058082802849637265880462852921510982613019570700598879554887149139762", "price": "0.48", "size": "0", "side": "SELL", "hash": "1fd079b28749c1a634cef8a4ed0fe0c7530e838c", "best_bid": "0.09", "best_ask": "0.49"}], "timestamp": "1769385050955", "event_type": "price_change"}}
{"_local_timestamp": "2026-01-25T23:51:07.804801+00:00", "data": {"market": "0x57d601622f7211f1bafc592e21baf81df8f44741e6ee708aee2449b49b58fc82", "price_changes": [{"asset_id": "12668390728546664562591096503585520540809771817912759179044387646050235405928", "price": "0.04", "size": "0", "side": "BUY", "hash": "13e99479e01d951ab5c54e5481d250ee376960a4", "best_bid": "0.51", "best_ask": "0.83"}, {"asset_id": "97753848768374060999337901528962238014065821426341113231597534959461731339133", "price": "0.96", "size": "0", "side": "SELL", "hash": "ce4580cf77e2e8bb38d0a7a3f681ed25eeb9970e", "best_bid": "0.17", "best_ask": "0.49"}], "timestamp": "1769385067722", "event_type": "price_change"}}
{"_local_timestamp": "2026-01-25T23:51:08.163617+00:00", "data": {"market": "0x57d601622f7211f1bafc592e21baf81df8f44741e6ee708aee2449b49b58fc82", "price_changes": [{"asset_id": "12668390728546664562591096503585520540809771817912759179044387646050235405928", "price": "0.06", "size": "400", "side": "BUY", "hash": "ce57ab4fcfe269f99ff8c68de3af4ac03414e7b5", "best_bid": "0.51", "best_ask": "0.83"}, {"asset_id": "97753848768374060999337901528962238014065821426341113231597534959461731339133", "price": "0.94", "size": "400", "side": "SELL", "hash": "c7ace528d35fc100269830660d9e05af0e6e4372", "best_bid": "0.17", "best_ask": "0.49"}], "timestamp": "1769385068015", "event_type": "price_change"}}
{"_local_timestamp": "2026-01-25T23:51:12.125441+00:00", "data": {"market": "0x07db4ca35f28bc5ca53a161794ab7b6aad0f3f4b32786fd2c3ca3070cbd31d23", "price_changes": [{"asset_id": "24363275266089775305424843015532890390275785659687191694023230547125544911803", "price": "0.51", "size": "0", "side": "BUY", "hash": "97d8166e0ff72e6b86867a5fa98bb1343366bb74", "best_bid": "0.3", "best_ask": "0.91"}, {"asset_id": "89399296058082802849637265880462852921510982613019570700598879554887149139762", "price": "0.49", "size": "0", "side": "SELL", "hash": "cd70b341e8bf5ef12bbd614d04825d5a0c949aa3", "best_bid": "0.09", "best_ask": "0.7"}], "timestamp": "1769385072011", "event_type": "price_change"}}
{"_local_timestamp": "2026-01-25T23:51:12.126033+00:00", "data": {"market": "0x07db4ca35f28bc5ca53a161794ab7b6aad0f3f4b32786fd2c3ca3070cbd31d23", "price_changes": [{"asset_id": "24363275266089775305424843015532890390275785659687191694023230547125544911803", "price": "0.26", "size": "96", "side": "BUY", "hash": "97d8166e0ff72e6b86867a5fa98bb1343366bb74", "best_bid": "0.3", "best_ask": "0.91"}, {"asset_id": "89399296058082802849637265880462852921510982613019570700598879554887149139762", "price": "0.74", "size": "96", "side": "SELL", "hash": "cd70b341e8bf5ef12bbd614d04825d5a0c949aa3", "best_bid": "0.09", "best_ask": "0.7"}], "timestamp": "1769385072011", "event_type": "price_change"}}
{"_local_timestamp": "2026-01-25T23:51:12.126292+00:00", "data": {"market": "0x07db4ca35f28bc5ca53a161794ab7b6aad0f3f4b32786fd2c3ca3070cbd31d23", "price_changes": [{"asset_id": "24363275266089775305424843015532890390275785659687191694023230547125544911803", "price": "0.31", "size": "20", "side": "BUY", "hash": "0afe3c9ce5c1729a9c8db2d56be02682d34346e5", "best_bid": "0.31", "best_ask": "0.91"}, {"asset_id": "89399296058082802849637265880462852921510982613019570700598879554887149139762", "price": "0.69", "size": "20", "side": "SELL", "hash": "3ac41cd5af484589f3a9d365bb314282a4c5236c", "best_bid": "0.09", "best_ask": "0.69"}], "timestamp": "1769385072052", "event_type": "price_change"}}
{"_local_timestamp": "2026-01-25T23:51:12.418430+00:00", "data": {"market": "0x07db4ca35f28bc5ca53a161794ab7b6aad0f3f4b32786fd2c3ca3070cbd31d23", "price_changes": [{"asset_id": "24363275266089775305424843015532890390275785659687191694023230547125544911803", "price": "0.31", "size": "86.66", "side": "BUY", "hash": "b24140d994a2b5d4bfeb104a24ce29569e1c0ef4", "best_bid": "0.31", "best_ask": "0.91"}, {"asset_id": "89399296058082802849637265880462852921510982613019570700598879554887149139762", "price": "0.69", "size": "86.66", "side": "SELL", "hash": "04a657f6ad885c5140c4239ed87150e86c5f6fca", "best_bid": "0.09", "best_ask": "0.69"}], "timestamp": "1769385072353", "event_type": "price_change"}}
{"_local_timestamp": "2026-01-25T23:51:12.424839+00:00", "data": {"market": "0x07db4ca35f28bc5ca53a161794ab7b6aad0f3f4b32786fd2c3ca3070cbd31d23", "price_changes": [{"asset_id": "24363275266089775305424843015532890390275785659687191694023230547125544911803", "price": "0.16", "size": "216.66", "side": "BUY", "hash": "8d8beb4762d5ac63decc21ca07c151c61fb8df9c", "best_bid": "0.31", "best_ask": "0.91"}, {"asset_id": "89399296058082802849637265880462852921510982613019570700598879554887149139762", "price": "0.84", "size": "216.66", "side": "SELL", "hash": "a6148f74666f0073a10eccb58236fd49580bf60e", "best_bid": "0.09", "best_ask": "0.69"}], "timestamp": "1769385072357", "event_type": "price_change"}}
{"_local_timestamp": "2026-01-25T23:51:16.614716+00:00", "data": {"market": "0x07db4ca35f28bc5ca53a161794ab7b6aad0f3f4b32786fd2c3ca3070cbd31d23", "price_changes": [{"asset_id": "24363275266089775305424843015532890390275785659687191694023230547125544911803", "price": "0.27", "size": "0", "side": "BUY", "hash": "d9f6678cdb89b98c911b5dc18bf7ceead4aeca73", "best_bid": "0.31", "best_ask": "0.91"}, {"asset_id": "89399296058082802849637265880462852921510982613019570700598879554887149139762", "price": "0.73", "size": "0", "side": "SELL", "hash": "c7afe5d5bf2dfe77a6b7d858cc213113cfbdcda1", "best_bid": "0.09", "best_ask": "0.69"}], "timestamp": "1769385076547", "event_type": "price_change"}}
{"_local_timestamp": "2026-01-25T23:51:16.636149+00:00", "data": {"market": "0x07db4ca35f28bc5ca53a161794ab7b6aad0f3f4b32786fd2c3ca3070cbd31d23", "price_changes": [{"asset_id": "24363275266089775305424843015532890390275785659687191694023230547125544911803", "price": "0.32", "size": "20", "side": "BUY", "hash": "fcb3c27d2ef16aed2389076657a848ec4689db7d", "best_bid": "0.32", "best_ask": "0.91"}, {"asset_id": "89399296058082802849637265880462852921510982613019570700598879554887149139762", "price": "0.68", "size": "20", "side": "SELL", "hash": "9e77e68e1c0111dc710a789eb5f88c613fbf490d", "best_bid": "0.09", "best_ask": "0.68"}], "timestamp": "1769385076574", "event_type": "price_change"}}
{"_local_timestamp": "2026-01-25T23:51:16.660395+00:00", "data": {"market": "0x07db4ca35f28bc5ca53a161794ab7b6aad0f3f4b32786fd2c3ca3070cbd31d23", "price_changes": [{"asset_id": "24363275266089775305424843015532890390275785659687191694023230547125544911803", "price": "0.31", "size": "66.66", "side": "BUY", "hash": "73097aded6811dfd7571c42e0178edbee916ca5c", "best_bid": "0.32", "best_ask": "0.91"}, {"asset_id": "89399296058082802849637265880462852921510982613019570700598879554887149139762", "price": "0.69", "size": "66.66", "side": "SELL", "hash": "4e8db1c9f3cd7b4cb89be6c30ed40d69ae396cad", "best_bid": "0.09", "best_ask": "0.68"}], "timestamp": "1769385076595", "event_type": "price_change"}}
{"_local_timestamp": "2026-01-25T23:51:16.682132+00:00", "data": {"market": "0x07db4ca35f28bc5ca53a161794ab7b6aad0f3f4b32786fd2c3ca3070cbd31d23", "price_changes": [{"asset_id": "24363275266089775305424843015532890390275785659687191694023230547125544911803", "price": "0.5", "size": "20", "side": "BUY", "hash": "6782d9aeab521113c3e75d6e2beb796c2d6724da", "best_bid": "0.5", "best_ask": "0.91"}, {"asset_id": "89399296058082802849637265880462852921510982613019570700598879554887149139762", "price": "0.5", "size": "20", "side": "SELL", "hash": "6fc25d4fc7c016b9af27fa11aa5578eb7c40309d", "best_bid": "0.09", "best_ask": "0.5"}], "timestamp": "1769385076617", "event_type": "price_change"}}
