{"_local_timestamp": "2026-01-25T23:40:31.340142+00:00", "data": [{"market": "0x8db2651deb0ca894dfec7963ff43d747e6b203d853ea102ddaaf69272fcbd14e", "asset_id": "55723215967704727452199840811929823276351711374899127881856674926400394790108", "timestamp": "1769384403230", "hash": "a102fce1139bc956829774f6543f82d1c0ef732a", "bids": [{"price": "0.001", "size": "305094.67"}, {"price": "0.002", "size": "1259.94"}, {"price": "0.003", "size": "1400"}, {"price": "0.004", "size": "5000"}, {"price": "0.005", "size": "9.14"}, {"price": "0.006", "size": "200"}, {"price": "0.01", "size": "4500"}, {"price": "0.011", "size": "5000"}, {"price": "0.012", "size": "5.3"}, {"price": "0.02", "size": "2500"}, {"price": "0.021", "size": "2222"}, {"price": "0.022", "size": "5.79"}, {"price": "0.04", "size": "1250"}, {"price": "0.041", "size": "5400"}, {"price": "0.042", "size": "2222"}, {"price": "0.043", "size": "5.02"}, {"price": "0.05", "size": "30"}, {"price": "0.051", "size": "39"}, {"price": "0.06", "size": "500"}, {"price": "0.08", "size": "250"}, {"price": "0.081", "size": "755"}, {"price": "0.082", "size": "5.9"}, {"price": "0.1", "size": "360"}, {"price": "0.14", "size": "567.85"}, {"price": "0.19", "size": "418.42"}, {"price": "0.191", "size": "5.42"}, {"price": "0.24", "size": "116.66"}, {"price": "0.241", "size": "1555"}, {"price": "0.248", "size": "8"}, {"price": "0.254", "size": "150"}, {"price": "0.255", "size": "1000"}, {"price": "0.256", "size": "1953"}, {"price": "0.29", "size": "89.65"}, {"price": "0.34", "size": "70.58"}, {"price": "0.38", "size": "127.63"}, {"price": "0.82", "size": "1327.81"}, {"price": "0.821", "size": "1111"}, {"price": "0.864", "size": "200"}, {"price": "0.866", "size": "20"}, {"price": "0.867", "size": "20"}, {"price": "0.882", "size": "300"}, {"price": "0.883", "size": "20"}, {"price": "0.884", "size": "20"}, {"price": "0.894", "size": "21.66"}, {"price": "0.905", "size": "32"}, {"price": "0.918", "size": "24.4"}, {"price": "0.92", "size": "500"}, {"price": "0.921", "size": "224.27"}, {"price": "0.922", "size": "458.57"}, {"price": "0.923", "size": "110.6"}, {"price": "0.93", "size": "6.19"}, {"price": "0.947", "size": "25"}, {"price": "0.948", "size": "14.99"}], "asks": [{"price": "0.999", "size": "32768"}, {"price": "0.998", "size": "7012.32"}, {"price": "0.997", "size": "250"}, {"price": "0.996", "size": "6.15"}, {"price": "0.995", "size": "28.25"}, {"price": "0.994", "size": "17.32"}, {"price": "0.988", "size": "5000"}, {"price": "0.987", "size": "2000"}, {"price": "0.985", "size": "2000"}, {"price": "0.984", "size": "561.35"}, {"price": "0.979", "size": "32"}, {"price": "0.976", "size": "6.04"}, {"price": "0.974", "size": "3000"}, {"price": "0.973", "size": "2000"}, {"price": "0.97", "size": "35"}, {"price": "0.969", "size": "2000"}, {"price": "0.968", "size": "1555"}, {"price": "0.967", "size": "1000"}, {"price": "0.966", "size": "364"}, {"price": "0.965", "size": "75"}, {"price": "0.964", "size": "200"}, {"price": "0.963", "size": "30"}, {"price": "0.961", "size": "7.4"}, {"price": "0.96", "size": "46.64"}], "event_type": "book", "last_trade_price": "0.036"}, {"market": "0x512ced1584beb41cb6dacdaa92f5d67f8bee28f055ef63b251d20a446422ddaa", "asset_id": "81498082395020979729835659110658786648105896152484850898743462024117016161425", "timestamp": "1769384403229", "hash": "17db4db4ec6675e9159605c99d9a8e3c028b9515", "bids": [{"price": "0.01", "size": "15085"}, {"price": "0.02", "size": "7020"}, {"price": "0.03", "size": "3250"}, {"price": "0.04", "size": "3333"}, {"price": "0.05", "size": "100"}, {"price": "0.06", "size": "3100"}, {"price": "0.07", "size": "2077.78"}, {"price": "0.08", "size": "400"}], "asks": [{"price": "0.99", "size": "25842.52"}, {"price": "0.98", "size": "2900"}, {"price": "0.97", "size": "11.51"}, {"price": "0.96", "size": "1250"}, {"price": "0.95", "size": "30"}, {"price": "0.94", "size": "533"}, {"price": "0.92", "size": "250"}, {"price": "0.91", "size": "605.44"}, {"price": "0.86", "size": "567.85"}, {"price": "0.81", "size": "418.42"}, {"price": "0.8", "size": "5.17"}, {"price": "0.77", "size": "121.73"}, {"price": "0.76", "size": "100"}, {"price": "0.75", "size": "308"}, {"price": "0.74", "size": "1588"}, {"price": "0.72", "size": "92.85"}, {"price": "0.67", "size": "72.72"}, {"price": "0.63", "size": "129.05"}, {"price": "0.37", "size": "700"}, {"price": "0.36", "size": "781"}, {"price": "0.35", "size": "400"}, {"price": "0.31", "size": "20"}, {"price": "0.18", "size": "59.2"}, {"price": "0.17", "size": "40"}, {"price": "0.16", "size": "20"}, {"price": "0.13", "size": "67"}, {"price": "0.12", "size": "1826.99"}, {"price": "0.11", "size": "321.73"}, {"price": "0.1", "size": "163.92"}], "event_type": "book", "last_trade_price": "0.100"}, {"market": "0xb9223ddfda277ecf96cea52aba3d6a47e3bb001bf0173fb3e2145566c28e0c24", "asset_id": "57280055515157002497847996398372581077095661831629922834612019741255629878625", "timestamp": "1769384426387", "hash": "cb479f28ccac951c517caeceb637982f5aeb1f23", "bids": [{"price": "0.01", "size": "35806.68"}, {"price": "0.02", "size": "2506.38"}, {"price": "0.03", "size": "3733"}, {"price": "0.04", "size": "1257.17"}, {"price": "0.06", "size": "500"}, {"price": "0.08", "size": "900"}, {"price": "0.09", "size": "5.51"}, {"price": "0.12", "size": "608.33"}, {"price": "0.16", "size": "200"}, {"price": "0.18", "size": "888"}, {"price": "0.19", "size": "295"}, {"price": "0.2", "size": "395.11"}, {"price": "0.21", "size": "300"}, {"price": "0.22", "size": "1908"}, {"price": "0.24", "size": "108.33"}, {"price": "0.28", "size": "1346.71"}, {"price": "0.32", "size": "62.5"}, {"price": "0.33", "size": "107.87"}, {"price": "0.35", "size": "555"}, {"price": "0.36", "size": "1047"}, {"price": "0.37", "size": "5"}, {"price": "0.42", "size": "20"}, {"price": "0.51", "size": "107.87"}, {"price": "0.65", "size": "299.8"}, {"price": "0.66", "size": "555"}, {"price": "0.67", "size": "258.27"}, {"price": "0.68", "size": "215.73"}, {"price": "0.69", "size": "408.84"}, {"price": "0.7", "size": "1162"}, {"price": "0.71", "size": "121.39"}, {"price": "0.72", "size": "16"}, {"price": "0.73", "size": "40"}, {"price": "0.74", "size": "10"}, {"price": "0.75", "size": "140.64"}, {"price": "0.76", "size": "519.99"}, {"price": "0.77", "size": "130"}], "asks": [{"price": "0.99", "size": "21000"}, {"price": "0.98", "size": "2222"}, {"price": "0.97", "size": "13.33"}, {"price": "0.94", "size": "10000"}, {"price": "0.93", "size": "1361"}, {"price": "0.92", "size": "1000"}, {"price": "0.91", "size": "1111"}, {"price": "0.9", "size": "1111"}, {"price": "0.88", "size": "766"}, {"price": "0.87", "size": "1000"}, {"price": "0.86", "size": "1111"}, {"price": "0.85", "size": "229.67"}, {"price": "0.84", "size": "471"}, {"price": "0.81", "size": "458.41"}, {"price": "0.8", "size": "214.62"}], "event_type": "book", "last_trade_price": "0.770"}, {"market": "0xb9223ddfda277ecf96cea52aba3d6a47e3bb001bf0173fb3e2145566c28e0c24", "asset_id": "64819280345421258482017346931579849092301023088943214992246376036314042237400", "timestamp": "1769384426387", "hash": "38c90ab30f0f9bf3edb861aa7d59b51eb44987b4", "bids": [{"price": "0.01", "size": "21000"}, {"price": "0.02", "size": "2222"}, {"price": "0.03", "size": "13.33"}, {"price": "0.06", "size": "10000"}, {"price": "0.07", "size": "1361"}, {"price": "0.08", "size": "1000"}, {"price": "0.09", "size": "1111"}, {"price": "0.1", "size": "1111"}, {"price": "0.12", "size": "766"}, {"price": "0.13", "size": "1000"}, {"price": "0.14", "size": "1111"}, {"price": "0.15", "size": "229.67"}, {"price": "0.16", "size": "471"}, {"price": "0.19", "size": "458.41"}, {"price": "0.2", "size": "214.62"}], "asks": [{"price": "0.99", "size": "35806.68"}, {"price": "0.98", "size": "2506.38"}, {"price": "0.97", "size": "3733"}, {"price": "0.96", "size": "1257.17"}, {"price": "0.94", "size": "500"}, {"price": "0.92", "size": "900"}, {"price": "0.91", "size": "5.51"}, {"price": "0.88", "size": "608.33"}, {"price": "0.84", "size": "200"}, {"price": "0.82", "size": "888"}, {"price": "0.81", "size": "295"}, {"price": "0.8", "size": "395.11"}, {"price": "0.79", "size": "300"}, {"price": "0.78", "size": "1908"}, {"price": "0.76", "size": "108.33"}, {"price": "0.72", "size": "1346.71"}, {"price": "0.68", "size": "62.5"}, {"price": "0.67", "size": "107.87"}, {"price": "0.65", "size": "555"}, {"price": "0.64", "size": "1047"}, {"price": "0.63", "size": "5"}, {"price": "0.58", "size": "20"}, {"price": "0.49", "size": "107.87"}, {"price": "0.35", "size": "299.8"}, {"price": "0.34", "size": "555"}, {"price": "0.33", "size": "258.27"}, {"price": "0.32", "size": "215.73"}, {"price": "0.31", "size": "408.84"}, {"price": "0.3", "size": "1162"}, {"price": "0.29", "size": "121.39"}, {"price": "0.28", "size": "16"}, {"price": "0.27", "size": "40"}, {"price": "0.26", "size": "10"}, {"price": "0.25", "size": "140.64"}, {"price": "0.24", "size": "519.99"}, {"price": "0.23", "size": "130"}], "event_type": "book", "last_trade_price": "0.770"}, {"market": "0x4ddaff7ab33855ab7ed53f75ae4a331496028177f4bf0557eafe0fb83628332b", "asset_id": "25056163956965564455957738971346869740799169769422815261763807235324372823907", "timestamp": "1769384410627", "hash": "fdc26d06a56f57eb092e65ed501b82de3f7ce028", "bids": [{"price": "0.001", "size": "32818"}, {"price": "0.002", "size": "5010.05"}, {"price": "0.003", "size": "2005.16"}, {"price": "0.004", "size": "3147.92"}, {"price": "0.005", "size": "2000"}, {"price": "0.006", "size": "24.55"}, {"price": "0.01", "size": "200"}, {"price": "0.011", "size": "127.93"}, {"price": "0.012", "size": "3053.02"}, {"price": "0.013", "size": "942"}, {"price": "0.017", "size": "391.12"}, {"price": "0.018", "size": "221.11"}, {"price": "0.019", "size": "100"}, {"price": "0.021", "size": "100"}, {"price": "0.022", "size": "114.77"}], "asks": [{"price": "0.999", "size": "404983.64"}, {"price": "0.998", "size": "1256.61"}, {"price": "0.997", "size": "1400"}, {"price": "0.996", "size": "11.41"}, {"price": "0.994", "size": "200"}, {"price": "0.99", "size": "4500"}, {"price": "0.989", "size": "5.77"}, {"price": "0.98", "size": "2900"}, {"price": "0.979", "size": "11.22"}, {"price": "0.96", "size": "1250"}, {"price": "0.95", "size": "30"}, {"price": "0.949", "size": "39"}, {"price": "0.94", "size": "500"}, {"price": "0.939", "size": "8.17"}, {"price": "0.92", "size": "2450"}, {"price": "0.919", "size": "2222"}, {"price": "0.9", "size": "360"}, {"price": "0.85", "size": "551.66"}, {"price": "0.849", "size": "7.53"}, {"price": "0.8", "size": "410"}, {"price": "0.78", "size": "1000"}, {"price": "0.779", "size": "1705"}, {"price": "0.778", "size": "250"}, {"price": "0.76", "size": "116.66"}, {"price": "0.71", "size": "89.65"}, {"price": "0.66", "size": "70.58"}, {"price": "0.61", "size": "51.28"}, {"price": "0.58", "size": "1000"}, {"price": "0.579", "size": "615"}, {"price": "0.5", "size": "20"}, {"price": "0.462", "size": "1111"}, {"price": "0.461", "size": "927"}, {"price": "0.46", "size": "5"}, {"price": "0.459", "size": "20"}, {"price": "0.179", "size": "555"}, {"price": "0.178", "size": "486"}, {"price": "0.177", "size": "121"}, {"price": "0.128", "size": "116.62"}, {"price": "0.127", "size": "20"}, {"price": "0.109", "size": "20"}, {"price": "0.108", "size": "20"}, {"price": "0.069", "size": "15.85"}, {"price": "0.066", "size": "233.24"}, {"price": "0.061", "size": "161.84"}, {"price": "0.055", "size": "20"}, {"price": "0.048", "size": "400"}, {"price": "0.047", "size": "106.34"}, {"price": "0.045", "size": "199.98"}, {"price": "0.043", "size": "24.99"}, {"price": "0.033", "size": "103.44"}, {"price": "0.032", "size": "35"}], "event_type": "book", "last_trade_price": "0.969"}, {"market": "0x4ddaff7ab33855ab7ed53f75ae4a331496028177f4bf0557eafe0fb83628332b", "asset_id": "25589742673068913841508219929281747394194738561317540491643768947357201371462", "timestamp": "1769384410627", "hash": "c3cc52e558851a51cee691c8d3c90175bb5b0485", "bids": [{"price": "0.001", "size": "404983.64"}, {"price": "0.002", "size": "1256.61"}, {"price": "0.003", "size": "1400"}, {"price": "0.004", "size": "11.41"}, {"price": "0.006", "size": "200"}, {"price": "0.01", "size": "4500"}, {"price": "0.011", "size": "5.77"}, {"price": "0.02", "size": "2900"}, {"price": "0.021", "size": "11.22"}, {"price": "0.04", "size": "1250"}, {"price": "0.05", "size": "30"}, {"price": "0.051", "size": "39"}, {"price": "0.06", "size": "500"}, {"price": "0.061", "size": "8.17"}, {"price": "0.08", "size": "2450"}, {"price": "0.081", "size": "2222"}, {"price": "0.1", "size": "360"}, {"price": "0.15", "size": "551.66"}, {"price": "0.151", "size": "7.53"}, {"price": "0.2", "size": "410"}, {"price": "0.22", "size": "1000"}, {"price": "0.221", "size": "1705"}, {"price": "0.222", "size": "250"}, {"price": "0.24", "size": "116.66"}, {"price": "0.29", "size": "89.65"}, {"price": "0.34", "size": "70.58"}, {"price": "0.39", "size": "51.28"}, {"price": "0.42", "size": "1000"}, {"price": "0.421", "size": "615"}, {"price": "0.5", "size": "20"}, {"price": "0.538", "size": "1111"}, {"price": "0.539", "size": "927"}, {"price": "0.54", "size": "5"}, {"price": "0.541", "size": "20"}, {"price": "0.821", "size": "555"}, {"price": "0.822", "size": "486"}, {"price": "0.823", "size": "121"}, {"price": "0.872", "size": "116.62"}, {"price": "0.873", "size": "20"}, {"price": "0.891", "size": "20"}, {"price": "0.892", "size": "20"}, {"price": "0.931", "size": "15.85"}, {"price": "0.934", "size": "233.24"}, {"price": "0.939", "size": "161.84"}, {"price": "0.945", "size": "20"}, {"price": "0.952", "size": "400"}, {"price": "0.953", "size": "106.34"}, {"price": "0.955", "size": "199.98"}, {"price": "0.957", "size": "24.99"}, {"price": "0.967", "size": "103.44"}, {"price": "0.968", "size": "35"}], "asks": [{"price": "0.999", "size": "32818"}, {"price": "0.998", "size": "5010.05"}, {"price": "0.997", "size": "2005.16"}, {"price": "0.996", "size": "3147.92"}, {"price": "0.995", "size": "2000"}, {"price": "0.994", "size": "24.55"}, {"price": "0.99", "size": "200"}, {"price": "0.989", "size": "127.93"}, {"price": "0.988", "size": "3053.02"}, {"price": "0.987", "size": "942"}, {"price": "0.983", "size": "391.12"}, {"price": "0.982", "size": "221.11"}, {"price": "0.981", "size": "100"}, {"price": "0.979", "size": "100"}, {"price": "0.978", "size": "114.77"}], "event_type": "book", "last_trade_price": "0.969"}, {"market": "0x07baddbeaa7f66706b84f167f835f3cc90782445ff36b2ea736c1c097f6ff537", "asset_id": "58198710311579915535691075580727536486537716969204598157134462435731312061441", "timestamp": "1769384404280", "hash": "28fd618955f48eb89629b8006081b0d4194d4e57", "bids": [{"price": "0.01", "size": "41314.62"}, {"price": "0.03", "size": "3400"}, {"price": "0.04", "size": "2222"}, {"price": "0.05", "size": "250"}, {"price": "0.06", "size": "805.06"}, {"price": "0.1", "size": "350"}, {"price": "0.13", "size": "246.15"}, {"price": "0.14", "size": "1142"}, {"price": "0.15", "size": "1325"}, {"price": "0.16", "size": "175"}, {"price": "0.17", "size": "16"}, {"price": "0.18", "size": "1555"}, {"price": "0.19", "size": "2460"}, {"price": "0.2", "size": "130"}, {"price": "0.23", "size": "104.34"}, {"price": "0.25", "size": "30"}, {"price": "0.26", "size": "1726.92"}, {"price": "0.27", "size": "1000"}, {"price": "0.28", "size": "555"}, {"price": "0.35", "size": "13"}, {"price": "0.36", "size": "1000"}, {"price": "0.38", "size": "560"}, {"price": "0.39", "size": "1025"}, {"price": "0.4", "size": "150"}, {"price": "0.41", "size": "5"}, {"price": "0.5", "size": "1019.64"}, {"price": "0.51", "size": "543.1"}, {"price": "0.52", "size": "555"}, {"price": "0.53", "size": "6"}, {"price": "0.55", "size": "216.59"}, {"price": "0.56", "size": "16"}, {"price": "0.57", "size": "13.62"}, {"price": "0.59", "size": "2016"}, {"price": "0.6", "size": "50.15"}, {"price": "0.61", "size": "561.25"}, {"price": "0.62", "size": "278.17"}], "asks": [{"price": "0.99", "size": "25517.08"}, {"price": "0.98", "size": "2509.13"}, {"price": "0.97", "size": "3733"}, {"price": "0.96", "size": "2158.3"}, {"price": "0.94", "size": "1066.66"}, {"price": "0.93", "size": "5300"}, {"price": "0.92", "size": "1767.11"}, {"price": "0.9", "size": "280"}, {"price": "0.89", "size": "3818"}, {"price": "0.88", "size": "216.66"}, {"price": "0.87", "size": "2000"}, {"price": "0.86", "size": "421.42"}, {"price": "0.85", "size": "6.16"}, {"price": "0.84", "size": "1236"}, {"price": "0.83", "size": "1176"}, {"price": "0.8", "size": "154"}, {"price": "0.79", "size": "10.76"}, {"price": "0.78", "size": "20"}, {"price": "0.74", "size": "1065.99"}, {"price": "0.73", "size": "500"}, {"price": "0.72", "size": "26"}, {"price": "0.7", "size": "803"}, {"price": "0.69", "size": "40"}, {"price": "0.68", "size": "6"}, {"price": "0.67", "size": "110"}, {"price": "0.66", "size": "419.99"}, {"price": "0.65", "size": "429.47"}, {"price": "0.64", "size": "68.43"}], "event_type": "book", "last_trade_price": "0.380"}, {"market": "0x512ced1584beb41cb6dacdaa92f5d67f8bee28f055ef63b251d20a446422ddaa", "asset_id": "105159270423598199664249261738928535905668234939484323704322364820483620754428", "timestamp": "1769384403229", "hash": "2e5c8a919d267de927ff1adbdd47ea06628c3c85", "bids": [{"price": "0.01", "size": "25842.52"}, {"price": "0.02", "size": "2900"}, {"price": "0.03", "size": "11.51"}, {"price": "0.04", "size": "1250"}, {"price": "0.05", "size": "30"}, {"price": "0.06", "size": "533"}, {"price": "0.08", "size": "250"}, {"price": "0.09", "size": "605.44"}, {"price": "0.14", "size": "567.85"}, {"price": "0.19", "size": "418.42"}, {"price": "0.2", "size": "5.17"}, {"price": "0.23", "size": "121.73"}, {"price": "0.24", "size": "100"}, {"price": "0.25", "size": "308"}, {"price": "0.26", "size": "1588"}, {"price": "0.28", "size": "92.85"}, {"price": "0.33", "size": "72.72"}, {"price": "0.37", "size": "129.05"}, {"price": "0.63", "size": "700"}, {"price": "0.64", "size": "781"}, {"price": "0.65", "size": "400"}, {"price": "0.69", "size": "20"}, {"price": "0.82", "size": "59.2"}, {"price": "0.83", "size": "40"}, {"price": "0.84", "size": "20"}, {"price": "0.87", "size": "67"}, {"price": "0.88", "size": "1826.99"}, {"price": "0.89", "size": "321.73"}, {"price": "0.9", "size": "163.92"}], "asks": [{"price": "0.99", "size": "15085"}, {"price": "0.98", "size": "7020"}, {"price": "0.97", "size": "3250"}, {"price": "0.96", "size": "3333"}, {"price": "0.95", "size": "100"}, {"price": "0.94", "size": "3100"}, {"price": "0.93", "size": "2077.78"}, {"price": "0.92", "size": "400"}], "event_type": "book", "last_trade_price": "0.100"}, {"market": "0x8db2651deb0ca894dfec7963ff43d747e6b203d853ea102ddaaf69272fcbd14e", "asset_id": "59454703894867594337219596879618679187053555828199534311880631098862267050015", "timestamp": "1769384403230", "hash": "2852c28a46129eaaff34084c4c7c9c47be3c2e3c", "bids": [{"price": "0.001", "size": "32768"}, {"price": "0.002", "size": "7012.32"}, {"price": "0.003", "size": "250"}, {"price": "0.004", "size": "6.15"}, {"price": "0.005", "size": "28.25"}, {"price": "0.006", "size": "17.32"}, {"price": "0.012", "size": "5000"}, {"price": "0.013", "size": "2000"}, {"price": "0.015", "size": "2000"}, {"price": "0.016", "size": "561.35"}, {"price": "0.021", "size": "32"}, {"price": "0.024", "size": "6.04"}, {"price": "0.026", "size": "3000"}, {"price": "0.027", "size": "2000"}, {"price": "0.03", "size": "35"}, {"price": "0.031", "size": "2000"}, {"price": "0.032", "size": "1555"}, {"price": "0.033", "size": "1000"}, {"price": "0.034", "size": "364"}, {"price": "0.035", "size": "75"}, {"price": "0.036", "size": "200"}, {"price": "0.037", "size": "30"}, {"price": "0.039", "size": "7.4"}, {"price": "0.04", "size": "46.64"}], "asks": [{"price": "0.999", "size": "305094.67"}, {"price": "0.998", "size": "1259.94"}, {"price": "0.997", "size": "1400"}, {"price": "0.996", "size": "5000"}, {"price": "0.995", "size": "9.14"}, {"price": "0.994", "size": "200"}, {"price": "0.99", "size": "4500"}, {"price": "0.989", "size": "5000"}, {"price": "0.988", "size": "5.3"}, {"price": "0.98", "size": "2500"}, {"price": "0.979", "size": "2222"}, {"price": "0.978", "size": "5.79"}, {"price": "0.96", "size": "1250"}, {"price": "0.959", "size": "5400"}, {"price": "0.958", "size": "2222"}, {"price": "0.957", "size": "5.02"}, {"price": "0.95", "size": "30"}, {"price": "0.949", "size": "39"}, {"price": "0.94", "size": "500"}, {"price": "0.92", "size": "250"}, {"price": "0.919", "size": "755"}, {"price": "0.918", "size": "5.9"}, {"price": "0.9", "size": "360"}, {"price": "0.86", "size": "567.85"}, {"price": "0.81", "size": "418.42"}, {"price": "0.809", "size": "5.42"}, {"price": "0.76", "size": "116.66"}, {"price": "0.759", "size": "1555"}, {"price": "0.752", "size": "8"}, {"price": "0.746", "size": "150"}, {"price": "0.745", "size": "1000"}, {"price": "0.744", "size": "1953"}, {"price": "0.71", "size": "89.65"}, {"price": "0.66", "size": "70.58"}, {"price": "0.62", "size": "127.63"}, {"price": "0.18", "size": "1327.81"}, {"price": "0.179", "size": "1111"}, {"price": "0.136", "size": "200"}, {"price": "0.134", "size": "20"}, {"price": "0.133", "size": "20"}, {"price": "0.118", "size": "300"}, {"price": "0.117", "size": "20"}, {"price": "0.116", "size": "20"}, {"price": "0.106", "size": "21.66"}, {"price": "0.095", "size": "32"}, {"price": "0.082", "size": "24.4"}, {"price": "0.08", "size": "500"}, {"price": "0.079", "size": "224.27"}, {"price": "0.078", "size": "458.57"}, {"price": "0.077", "size": "110.6"}, {"price": "0.07", "size": "6.19"}, {"price": "0.053", "size": "25"}, {"price": "0.052", "size": "14.99"}], "event_type": "book", "last_trade_price": "0.036"}, {"market": "0x07baddbeaa7f66706b84f167f835f3cc90782445ff36b2ea736c1c097f6ff537", "asset_id": "106820146733184719100966062623986655992997037363317463528901190592661638187355", "timestamp": "1769384404280", "hash": "cb98757cabb52c7a1dbdc90d1f667c421d5d4236", "bids": [{"price": "0.01", "size": "25517.08"}, {"price": "0.02", "size": "2509.13"}, {"price": "0.03", "size": "3733"}, {"price": "0.04", "size": "2158.3"}, {"price": "0.06", "size": "1066.66"}, {"price": "0.07", "size": "5300"}, {"price": "0.08", "size": "1767.11"}, {"price": "0.1", "size": "280"}, {"price": "0.11", "size": "3818"}, {"price": "0.12", "size": "216.66"}, {"price": "0.13", "size": "2000"}, {"price": "0.14", "size": "421.42"}, {"price": "0.15", "size": "6.16"}, {"price": "0.16", "size": "1236"}, {"price": "0.17", "size": "1176"}, {"price": "0.2", "size": "154"}, {"price": "0.21", "size": "10.76"}, {"price": "0.22", "size": "20"}, {"price": "0.26", "size": "1065.99"}, {"price": "0.27", "size": "500"}, {"price": "0.28", "size": "26"}, {"price": "0.3", "size": "803"}, {"price": "0.31", "size": "40"}, {"price": "0.32", "size": "6"}, {"price": "0.33", "size": "110"}, {"price": "0.34", "size": "419.99"}, {"price": "0.35", "size": "429.47"}, {"price": "0.36", "size": "68.43"}], "asks": [{"price": "0.99", "size": "41314.62"}, {"price": "0.97", "size": "3400"}, {"price": "0.96", "size": "2222"}, {"price": "0.95", "size": "250"}, {"price": "0.94", "size": "805.06"}, {"price": "0.9", "size": "350"}, {"price": "0.87", "size": "246.15"}, {"price": "0.86", "size": "1142"}, {"price": "0.85", "size": "1325"}, {"price": "0.84", "size": "175"}, {"price": "0.83", "size": "16"}, {"price": "0.82", "size": "1555"}, {"price": "0.81", "size": "2460"}, {"price": "0.8", "size": "130"}, {"price": "0.77", "size": "104.34"}, {"price": "0.75", "size": "30"}, {"price": "0.74", "size": "1726.92"}, {"price": "0.73", "size": "1000"}, {"price": "0.72", "size": "555"}, {"price": "0.65", "size": "13"}, {"price": "0.64", "size": "1000"}, {"price": "0.62", "size": "560"}, {"price": "0.61", "size": "1025"}, {"price": "0.6", "size": "150"}, {"price": "0.59", "size": "5"}, {"price": "0.5", "size": "1019.64"}, {"price": "0.49", "size": "543.1"}, {"price": "0.48", "size": "555"}, {"price": "0.47", "size": "6"}, {"price": "0.45", "size": "216.59"}, {"price": "0.44", "size": "16"}, {"price": "0.43", "size": "13.62"}, {"price": "0.41", "size": "2016"}, {"price": "0.4", "size": "50.15"}, {"price": "0.39", "size": "561.25"}, {"price": "0.38", "size": "278.17"}], "event_type": "book", "last_trade_price": "0.380"}]}
{"_local_timestamp": "2026-01-25T23:40:34.098166+00:00", "data": {"market": "0x4ddaff7ab33855ab7ed53f75ae4a331496028177f4bf0557eafe0fb83628332b", "price_changes": [{"asset_id": "25056163956965564455957738971346869740799169769422815261763807235324372823907", "price": "0.033", "size": "0", "side": "SELL", "hash": "7a7b9d4b39aac8e09d5e83db0e20f8c56b0bc007", "best_bid": "0.022", "best_ask": "0.032"}, {"asset_id": "25589742673068913841508219929281747394194738561317540491643768947357201371462", "price": "0.967", "size": "0", "side": "BUY", "hash": "f2395d6a96b93db59b3cfc421df3059640e3ac1f", "best_bid": "0.968", "best_ask": "0.978"}], "timestamp": "1769384434022", "event_type": "price_change"}}
{"_local_timestamp": "2026-01-25T23:40:34.230287+00:00", "data": {"market": "0x4ddaff7ab33855ab7ed53f75ae4a331496028177f4bf0557eafe0fb83628332b", "price_changes": [{"asset_id": "25056163956965564455957738971346869740799169769422815261763807235324372823907", "price": "0.033", "size": "103.44", "side": "SELL", "hash": "2cfd7f04855398b5fa64afe565a25676f35417a2", "best_bid": "0.022", "best_ask": "0.032"}, {"asset_id": "25589742673068913841508219929281747394194738561317540491643768947357201371462", "price": "0.967", "size": "103.44", "side": "BUY", "hash": "07934cc5dd3628ba9fcc0f2ed20117748ca67766", "best_bid": "0.968", "best_ask": "0.978"}], "timestamp": "1769384434163", "event_type": "price_change"}}
{"_local_timestamp": "2026-01-25T23:40:37.863094+00:00", "data": {"market": "0xb9223ddfda277ecf96cea52aba3d6a47e3bb001bf0173fb3e2145566c28e0c24", "price_changes": [{"asset_id": "57280055515157002497847996398372581077095661831629922834612019741255629878625", "price": "0.37", "size": "0", "side": "BUY", "hash": "972b23b765411e2ba362f0ac262162bdb84cc31f", "best_bid": "0.77", "best_ask": "0.8"}, {"asset_id": "64819280345421258482017346931579849092301023088943214992246376036314042237400", "price": "0.63", "size": "0", "side": "SELL", "hash": "27eb44c98398142ab228363de6bab361b3ff2302", "best_bid": "0.2", "best_ask": "0.23"}], "timestamp": "1769384437782", "event_type": "price_change"}}
{"_local_timestamp": "2026-01-25T23:40:37.916302+00:00", "data": {"market": "0xb9223ddfda277ecf96cea52aba3d6a47e3bb001bf0173fb3e2145566c28e0c24", "price_changes": [{"asset_id": "57280055515157002497847996398372581077095661831629922834612019741255629878625", "price": "0.37", "size": "5", "side": "BUY", "hash": "602d274e75d782615dd9f7c8958652a89e14563b", "best_bid": "0.77", "best_ask": "0.8"}, {"asset_id": "64819280345421258482017346931579849092301023088943214992246376036314042237400", "price": "0.63", "size": "5", "side": "SELL", "hash": "40cf5b5854b5b27281c1c6cb29c604993a4ee615", "best_bid": "0.2", "best_ask": "0.23"}], "timestamp": "1769384437829", "event_type": "price_change"}}
{"_local_timestamp": "2026-01-25T23:40:40.403994+00:00", "data": {"market": "0x8db2651deb0ca894dfec7963ff43d747e6b203d853ea102ddaaf69272fcbd14e", "price_changes": [{"asset_id": "55723215967704727452199840811929823276351711374899127881856674926400394790108", "price": "0.254", "size": "100", "side": "BUY", "hash": "24bf9527a4359d417793514e7f3773a4978214d6", "best_bid": "0.948", "best_ask": "0.96"}, {"asset_id": "59454703894867594337219596879618679187053555828199534311880631098862267050015", "price": "0.746", "size": "100", "side": "SELL", "hash": "cc0d570e634b1ac993fe5926cc1bd44ea2fce46a", "best_bid": "0.04", "best_ask": "0.052"}], "timestamp": "1769384440259", "event_type": "price_change"}}
{"_local_timestamp": "2026-01-25T23:40:40.596070+00:00", "data": {"market": "0x8db2651deb0ca894dfec7963ff43d747e6b203d853ea102ddaaf69272fcbd14e", "price_changes": [{"asset_id": "55723215967704727452199840811929823276351711374899127881856674926400394790108", "price": "0.961", "size": "0", "side": "SELL", "hash": "ae1ddccc158d5bcb3af89d41c271fdf1aa51e505", "best_bid": "0.948", "best_ask": "0.96"}, {"asset_id": "59454703894867594337219596879618679187053555828199534311880631098862267050015", "price": "0.039", "size": "0", "side": "BUY", "hash": "f86c478e3e33d44c870b5baeefc091288ddbd186", "best_bid": "0.04", "best_ask": "0.052"}], "timestamp": "1769384440458", "event_type": "price_change"}}
{"_local_timestamp": "2026-01-25T23:40:40.739377+00:00", "data": {"market": "0x8db2651deb0ca894dfec7963ff43d747e6b203d853ea102ddaaf69272fcbd14e", "price_changes": [{"asset_id": "55723215967704727452199840811929823276351711374899127881856674926400394790108", "price": "0.256", "size": "2003", "side": "BUY", "hash": "004b3f7117be1615e637cefbf55cc711286bc068", "best_bid": "0.948", "best_ask": "0.96"}, {"asset_id": "59454703894867594337219596879618679187053555828199534311880631098862267050015", "price": "0.744", "size": "2003", "side": "SELL", "hash": "f40ba813c656dd560fd21250c5a441b1a47a9ebf", "best_bid": "0.04", "best_ask": "0.052"}], "timestamp": "1769384440588", "event_type": "price_change"}}
{"_local_timestamp": "2026-01-25T23:40:40.882892+00:00", "data": {"market": "0x8db2651deb0ca894dfec7963ff43d747e6b203d853ea102ddaaf69272fcbd14e", "price_changes": [{"asset_id": "55723215967704727452199840811929823276351711374899127881856674926400394790108", "price": "0.866", "size": "0", "side": "BUY", "hash": "32516636cb1fa7f96f2cfaa342ac17df48dc3e84", "best_bid": "0.948", "best_ask": "0.96"}, {"asset_id": "59454703894867594337219596879618679187053555828199534311880631098862267050015", "price": "0.134", "size": "0", "side": "SELL", "hash": "6091724d0f9df3cbf13e8c9f67fecee68556106d", "best_bid": "0.04", "best_ask": "0.052"}], "timestamp": "1769384440790", "event_type": "price_change"}}
{"_local_timestamp": "2026-01-25T23:40:42.806961+00:00", "data": {"market": "0x8db2651deb0ca894dfec7963ff43d747e6b203d853ea102ddaaf69272fcbd14e", "price_changes": [{"asset_id": "55723215967704727452199840811929823276351711374899127881856674926400394790108", "price": "0.867", "size": "0", "side": "BUY", "hash": "b59b0b74cb77bdbfb4d6398955b6d04f2ca0c574", "best_bid": "0.948", "best_ask": "0.96"}, {"asset_id": "59454703894867594337219596879618679187053555828199534311880631098862267050015", "price": "0.133", "size": "0", "side": "SELL", "hash": "8fe5148549960429ec321d0839abc1d5260666fc", "best_bid": "0.04", "best_ask": "0.052"}], "timestamp": "1769384442731", "event_type": "price_change"}}
{"_local_timestamp": "2026-01-25T23:40:42.834047+00:00", "data": {"market": "0x8db2651deb0ca894dfec7963ff43d747e6b203d853ea102ddaaf69272fcbd14e", "price_changes": [{"asset_id": "55723215967704727452199840811929823276351711374899127881856674926400394790108", "price": "0.865", "size": "20", "side": "BUY", "hash": "dacfe6443361844959fe897ee411f8a47219416c", "best_bid": "0.948", "best_ask": "0.96"}, {"asset_id": "59454703894867594337219596879618679187053555828199534311880631098862267050015", "price": "0.135", "size": "20", "side": "SELL", "hash": "370b892ba4056d7a5d828ea61e2c1b8db94f1213", "best_bid": "0.04", "best_ask": "0.052"}], "timestamp": "1769384442764", "event_type": "price_change"}}
{"_local_timestamp": "2026-01-25T23:40:46.614513+00:00", "data": {"market": "0x8db2651deb0ca894dfec7963ff43d747e6b203d853ea102ddaaf69272fcbd14e", "price_changes": [{"asset_id": "55723215967704727452199840811929823276351711374899127881856674926400394790108", "price": "0.96", "size": "0", "side": "SELL", "hash": "a73993752feb94d1545290c49c2d7219f7fc5547", "best_bid": "0.948", "best_ask": "0.963"}, {"asset_id": "59454703894867594337219596879618679187053555828199534311880631098862267050015", "price": "0.04", "size": "0", "side": "BUY", "hash": "c777fc1591b56f27860bcbdffe366d019cca9f16", "best_bid": "0.037", "best_ask": "0.052"}], "timestamp": "1769384446535", "event_type": "price_change"}}
{"_local_timestamp": "2026-01-25T23:40:46.640619+00:00", "data": {"market": "0xb9223ddfda277ecf96cea52aba3d6a47e3bb001bf0173fb3e2145566c28e0c24", "price_changes": [{"asset_id": "57280055515157002497847996398372581077095661831629922834612019741255629878625", "price": "0.76", "size": "499.99", "side": "BUY", "hash": "5792d9b24d0b5a09b6ff81c5531b6a4e62bade30", "best_bid": "0.77", "best_ask": "0.8"}, {"asset_id": "64819280345421258482017346931579849092301023088943214992246376036314042237400", "price": "0.24", "size": "499.99", "side": "SELL", "hash": "dd3c43028446563505112d86640bbedc62e12104", "best_bid": "0.2", "best_ask": "0.23"}], "timestamp": "1769384446565", "event_type": "price_change"}}
{"_local_timestamp": "2026-01-25T23:40:46.643230+00:00", "data": {"market": "0x07baddbeaa7f66706b84f167f835f3cc90782445ff36b2ea736c1c097f6ff537", "price_changes": [{"asset_id": "106820146733184719100966062623986655992997037363317463528901190592661638187355", "price": "0.34", "size": "399.99", "side": "BUY", "hash": "2c4fd9f8e3d72ffdf4e0788e8eafb1b37f72bbb6", "best_bid": "0.36", "best_ask": "0.38"}, {"asset_id": "58198710311579915535691075580727536486537716969204598157134462435731312061441", "price": "0.66", "size": "399.99", "side": "SELL", "hash": "a0a5490122f3d5df5bfc0e646b2e9b9ec2bac449", "best_bid": "0.62", "best_ask": "0.64"}], "timestamp": "1769384446566", "event_type": "price_change"}}
{"_local_timestamp": "2026-01-25T23:40:46.645838+00:00", "data": {"market": "0x512ced1584beb41cb6dacdaa92f5d67f8bee28f055ef63b251d20a446422ddaa", "price_changes": [{"asset_id": "105159270423598199664249261738928535905668234939484323704322364820483620754428", "price": "0.88", "size": "1806.99", "side": "BUY", "hash": "fad76262b4e5b9de1432c82c8c78e72b8720b380", "best_bid": "0.9", "best_ask": "0.92"}, {"asset_id": "81498082395020979729835659110658786648105896152484850898743462024117016161425", "price": "0.12", "size": "1806.99", "side": "SELL", "hash": "a4f257dbb9431d97b7c7a4a921ffec5543be437e", "best_bid": "0.08", "best_ask": "0.1"}], "timestamp": "1769384446566", "event_type": "price_change"}}
{"_local_timestamp": "2026-01-25T23:40:46.656865+00:00", "data": {"market": "0xb9223ddfda277ecf96cea52aba3d6a47e3bb001bf0173fb3e2145566c28e0c24", "price_changes": [{"asset_id": "57280055515157002497847996398372581077095661831629922834612019741255629878625", "price": "0.75", "size": "160.64", "side": "BUY", "hash": "675e777e15e0862f2279899cd5b17551fe62b144", "best_bid": "0.77", "best_ask": "0.8"}, {"asset_id": "64819280345421258482017346931579849092301023088943214992246376036314042237400", "price": "0.25", "size": "160.64", "side": "SELL", "hash": "e848078be2d842f3be215deeb561cf31e1b25192", "best_bid": "0.2", "best_ask": "0.23"}], "timestamp": "1769384446592", "event_type": "price_change"}}
{"_local_timestamp": "2026-01-25T23:40:46.686144+00:00", "data": {"market": "0x512ced1584beb41cb6dacdaa92f5d67f8bee28f055ef63b251d20a446422ddaa", "price_changes": [{"asset_id": "105159270423598199664249261738928535905668234939484323704322364820483620754428", "price": "0.87", "size": "87", "side": "BUY", "hash": "f273a0327faf44a43a1f24f8ccecb8aa670dbccf", "best_bid": "0.9", "best_ask": "0.92"}, {"asset_id": "81498082395020979729835659110658786648105896152484850898743462024117016161425", "price": "0.13", "size": "87", "side": "SELL", "hash": "97806816cf7cc210fd3d1d7c3196154af0759ea1", "best_bid": "0.08", "best_ask": "0.1"}], "timestamp": "1769384446617", "event_type": "price_change"}}
{"_local_timestamp": "2026-01-25T23:40:46.709547+00:00", "data": {"market": "0x07baddbeaa7f66706b84f167f835f3cc90782445ff36b2ea736c1c097f6ff537", "price_changes": [{"asset_id": "106820146733184719100966062623986655992997037363317463528901190592661638187355", "price": "0.33", "size": "130", "side": "BUY", "hash": "c7e4b66a215ace37d5886bef7535c5c4057c7259", "best_bid": "0.36", "best_ask": "0.38"}, {"asset_id": "58198710311579915535691075580727536486537716969204598157134462435731312061441", "price": "0.67", "size": "130", "side": "SELL", "hash": "59ec9a33ad99d89db856f85f92325a81b9cb92da", "best_bid": "0.62", "best_ask": "0.64"}], "timestamp": "1769384446644", "event_type": "price_change"}}
{"_local_timestamp": "2026-01-25T23:40:46.891191+00:00", "data": {"market": "0xb9223ddfda277ecf96cea52aba3d6a47e3bb001bf0173fb3e2145566c28e0c24", "price_changes": [{"asset_id": "57280055515157002497847996398372581077095661831629922834612019741255629878625", "price": "0.75", "size": "114", "side": "BUY", "hash": "69637b1fa33bd344ea47683132a200331a7be554", "best_bid": "0.77", "best_ask": "0.8"}, {"asset_id": "64819280345421258482017346931579849092301023088943214992246376036314042237400", "price": "0.25", "size": "114", "side": "SELL", "hash": "9d9a3661ce73c74cd5480b682314cd16e6b5d348", "best_bid": "0.2", "best_ask": "0.23"}], "timestamp": "1769384446820", "event_type": "price_change"}}
{"_local_timestamp": "2026-01-25T23:40:46.970051+00:00", "data": {"market": "0xb9223ddfda277ecf96cea52aba3d6a47e3bb001bf0173fb3e2145566c28e0c24", "price_changes": [{"asset_id": "57280055515157002497847996398372581077095661831629922834612019741255629878625", "price": "0.75", "size": "144", "side": "BUY", "hash": "68cc7ce5252c2af1adc4842fddc271625c606d54", "best_bid": "0.77", "best_ask": "0.8"}, {"asset_id": "64819280345421258482017346931579849092301023088943214992246376036314042237400", "price": "0.25", "size": "144", "side": "SELL", "hash": "86e80f66b47714134ea7225560d54ddfe4794af7", "best_bid": "0.2", "best_ask": "0.23"}], "timestamp": "1769384446896", "event_type": "price_change"}}
{"_local_timestamp": "2026-01-25T23:40:47.032068+00:00", "data": {"market": "0x8db2651deb0ca894dfec7963ff43d747e6b203d853ea102ddaaf69272fcbd14e", "price_changes": [{"asset_id": "55723215967704727452199840811929823276351711374899127881856674926400394790108", "price": "0.962", "size": "46.64", "side": "SELL", "hash": "831d8c481f151ccd395c6363e7d75d5869a0438c", "best_bid": "0.948", "best_ask": "0.962"}, {"asset_id": "59454703894867594337219596879618679187053555828199534311880631098862267050015", "price": "0.038", "size": "46.64", "side": "BUY", "hash": "ed52335583062c2a62476f441d435c7122bc9715", "best_bid": "0.038", "best_ask": "0.052"}], "timestamp": "1769384446953", "event_type": "price_change"}}
{"_local_timestamp": "2026-01-25T23:40:47.153321+00:00", "data": {"market": "0xb9223ddfda277ecf96cea52aba3d6a47e3bb001bf0173fb3e2145566c28e0c24", "price_changes": [{"asset_id": "57280055515157002497847996398372581077095661831629922834612019741255629878625", "price": "0.75", "size": "114", "side": "BUY", "hash": "b7e65f9400b671425f38fa3ab3cbb1ce4c8327df", "best_bid": "0.77", "best_ask": "0.8"}, {"asset_id": "64819280345421258482017346931579849092301023088943214992246376036314042237400", "price": "0.25", "size": "114", "side": "SELL", "hash": "b7d9732cc1ac428bea94738a646a7f1f2e88fc1d", "best_bid": "0.2", "best_ask": "0.23"}], "timestamp": "1769384447079", "event_type": "price_change"}}
{"_local_timestamp": "2026-01-25T23:40:47.253260+00:00", "data": {"market": "0xb9223ddfda277ecf96cea52aba3d6a47e3bb001bf0173fb3e2145566c28e0c24", "price_changes": [{"asset_id": "57280055515157002497847996398372581077095661831629922834612019741255629878625", "price": "0.75", "size": "160.64", "side": "BUY", "hash": "51b5ddf6f671ab7b8a5168fda73aabef6adc5f88", "best_bid": "0.77", "best_ask": "0.8"}, {"asset_id": "64819280345421258482017346931579849092301023088943214992246376036314042237400", "price": "0.25", "size": "160.64", "side": "SELL", "hash": "fd9c84eb63ddf8352430aea1af42a82fd179f1c0", "best_bid": "0.2", "best_ask": "0.23"}], "timestamp": "1769384447175", "event_type": "price_change"}}
{"_local_timestamp": "2026-01-25T23:40:51.145100+00:00", "data": {"market": "0x8db2651deb0ca894dfec7963ff43d747e6b203d853ea102ddaaf69272fcbd14e", "price_changes": [{"asset_id": "59454703894867594337219596879618679187053555828199534311880631098862267050015", "price": "0.015", "size": "5133", "side": "BUY", "hash": "4abaa13086e6a74ac102ed90bb0ea6c07a102ab2", "best_bid": "0.038", "best_ask": "0.052"}, {"asset_id": "55723215967704727452199840811929823276351711374899127881856674926400394790108", "price": "0.985", "size": "5133", "side": "SELL", "hash": "e59808d8d1eb6929dc51694aa57b2a5fa187847c", "best_bid": "0.948", "best_ask": "0.962"}], "timestamp": "1769384451077", "event_type": "price_change"}}
{"_local_timestamp": "2026-01-25T23:40:51.145683+00:00", "data": {"market": "0x8db2651deb0ca894dfec7963ff43d747e6b203d853ea102ddaaf69272fcbd14e", "price_changes": [{"asset_id": "59454703894867594337219596879618679187053555828199534311880631098862267050015", "price": "0.023", "size": "2043", "side": "BUY", "hash": "47a6f90340ce4217ff85cae66c508752824ae096", "best_bid": "0.038", "best_ask": "0.052"}, {"asset_id": "55723215967704727452199840811929823276351711374899127881856674926400394790108", "price": "0.977", "size": "2043", "side": "SELL", "hash": "e5ec3b0fbc9913efc36d508666089c61ec926c1a", "best_bid": "0.948", "best_ask": "0.962"}], "timestamp": "1769384451078", "event_type": "price_change"}}
{"_local_timestamp": "2026-01-25T23:40:51.154100+00:00", "data": {"market": "0x8db2651deb0ca894dfec7963ff43d747e6b203d853ea102ddaaf69272fcbd14e", "price_changes": [{"asset_id": "59454703894867594337219596879618679187053555828199534311880631098862267050015", "price": "0.031", "size": "3516", "side": "BUY", "hash": "530b254cb6b232d06e78c45d962deba5d72b1465", "best_bid": "0.038", "best_ask": "0.052"}, {"asset_id": "55723215967704727452199840811929823276351711374899127881856674926400394790108", "price": "0.969", "size": "3516", "side": "SELL", "hash": "6910480e7e7259f13e5316ef67089a59d05fa3ed", "best_bid": "0.948", "best_ask": "0.962"}], "timestamp": "1769384451080", "event_type": "price_change"}}
{"_local_timestamp": "2026-01-25T23:40:52.834834+00:00", "data": {"market": "0x512ced1584beb41cb6dacdaa92f5d67f8bee28f055ef63b251d20a446422ddaa", "price_changes": [{"asset_id": "81498082395020979729835659110658786648105896152484850898743462024117016161425", "price": "0.03", "size": "4816", "side": "BUY", "hash": "6d2f7b05d5354aea72e713edc097e2bb3be76f1d", "best_bid": "0.08", "best_ask": "0.1"}, {"asset_id": "105159270423598199664249261738928535905668234939484323704322364820483620754428", "price": "0.97", "size": "4816", "side": "SELL", "hash": "e7e64fcbcd64a3faa80d56d5a4b37dfa5946119f", "best_bid": "0.9", "best_ask": "0.92"}], "timestamp": "1769384452762", "event_type": "price_change"}}
{"_local_timestamp": "2026-01-25T23:40:52.835323+00:00", "data": {"market": "0x512ced1584beb41cb6dacdaa92f5d67f8bee28f055ef63b251d20a446422ddaa", "price_changes": [{"asset_id": "81498082395020979729835659110658786648105896152484850898743462024117016161425", "price": "0.07", "size": "2748.78", "side": "BUY", "hash": "265518ff99e095719159f2e26258333b12f6c59b", "best_bid": "0.08", "best_ask": "0.1"}, {"asset_id": "105159270423598199664249261738928535905668234939484323704322364820483620754428", "price": "0.93", "size": "2748.78", "side": "SELL", "hash": "ac62766415643154c6c2f559789897a179ab4d2e", "best_bid": "0.9", "best_ask": "0.92"}], "timestamp": "1769384452763", "event_type": "price_change"}}
{"_local_timestamp": "2026-01-25T23:41:06.011089+00:00", "data": {"market": "0x4ddaff7ab33855ab7ed53f75ae4a331496028177f4bf0557eafe0fb83628332b", "price_changes": [{"asset_id": "25056163956965564455957738971346869740799169769422815261763807235324372823907", "price": "0.033", "size": "0", "side": "SELL", "hash": "ea8008c379c8175efeca1c8f0e7e66ecbbc156d1", "best_bid": "0.022", "best_ask": "0.032"}, {"asset_id": "25589742673068913841508219929281747394194738561317540491643768947357201371462", "price": "0.967", "size": "0", "side": "BUY", "hash": "18e3214970055f778ced59ff47a225cae5a049e4", "best_bid": "0.968", "best_ask": "0.978"}], "timestamp": "1769384465874", "event_type": "price_change"}}
{"_local_timestamp": "2026-01-25T23:41:06.080361+00:00", "data": {"market": "0x4ddaff7ab33855ab7ed53f75ae4a331496028177f4bf0557eafe0fb83628332b", "price_changes": [{"asset_id": "25056163956965564455957738971346869740799169769422815261763807235324372823907", "price": "0.033", "size": "103.44", "side": "SELL", "hash": "5039e31948569339ad3caa1c56b203eb737025a8", "best_bid": "0.022", "best_ask": "0.032"}, {"asset_id": "25589742673068913841508219929281747394194738561317540491643768947357201371462", "price": "0.967", "size": "103.44", "side": "BUY", "hash": "ac5864eb31747e507a4965dddf8a5eb4abecfdc4", "best_bid": "0.968", "best_ask": "0.978"}], "timestamp": "1769384465971", "event_type": "price_change"}}
{"_local_timestamp": "2026-01-25T23:41:18.528233+00:00", "data": {"market": "0x4ddaff7ab33855ab7ed53f75ae4a331496028177f4bf0557eafe0fb83628332b", "price_changes": [{"asset_id": "25589742673068913841508219929281747394194738561317540491643768947357201371462", "price": "0.952", "size": "0", "side": "BUY", "hash": "50ed304280d5f405508d8d2c78644cd4a96babe8", "best_bid": "0.968", "best_ask": "0.978"}, {"asset_id": "25056163956965564455957738971346869740799169769422815261763807235324372823907", "price": "0.048", "size": "0", "side": "SELL", "hash": "a5a41b8ba982b288257b74bfdd2839c2c44964c7", "best_bid": "0.022", "best_ask": "0.032"}], "timestamp": "1769384478399", "event_type": "price_change"}}
{"_local_timestamp": "2026-01-25T23:41:18.688106+00:00", "data": {"market": "0x4ddaff7ab33855ab7ed53f75ae4a331496028177f4bf0557eafe0fb83628332b", "price_changes": [{"asset_id": "25056163956965564455957738971346869740799169769422815261763807235324372823907", "price": "0.004", "size": "2235.89", "side": "BUY", "hash": "0e8e6b46f6ced274b9a70adb3d69777ea3a25ee2", "best_bid": "0.022", "best_ask": "0.032"}, {"asset_id": "25589742673068913841508219929281747394194738561317540491643768947357201371462", "price": "0.996", "size": "2235.89", "side": "SELL", "hash": "41c07804270353391c35600e88cd532e560fab60", "best_bid": "0.968", "best_ask": "0.978"}], "timestamp": "1769384478621", "event_type": "price_change"}}
{"_local_timestamp": "2026-01-25T23:41:20.797695+00:00", "data": {"market": "0x4ddaff7ab33855ab7ed53f75ae4a331496028177f4bf0557eafe0fb83628332b", "price_changes": [{"asset_id": "25589742673068913841508219929281747394194738561317540491643768947357201371462", "price": "0.954", "size": "400", "side": "BUY", "hash": "ce4c7a2804ced26f65cd3008962c85b0f02ca56b", "best_bid": "0.968", "best_ask": "0.978"}, {"asset_id": "25056163956965564455957738971346869740799169769422815261763807235324372823907", "price": "0.046", "size": "400", "side": "SELL", "hash": "7004ea4b318e621a82dd0a28294218ebf14a1185", "best_bid": "0.022", "best_ask": "0.032"}], "timestamp": "1769384480711", "event_type": "price_change"}}
{"_local_timestamp": "2026-01-25T23:41:20.873162+00:00", "data": {"market": "0x4ddaff7ab33855ab7ed53f75ae4a331496028177f4bf0557eafe0fb83628332b", "price_changes": [{"asset_id": "25056163956965564455957738971346869740799169769422815261763807235324372823907", "price": "0.002", "size": "6046.88", "side": "BUY", "hash": "411603400fe19fa549d5b09da3744383a251f4b8", "best_bid": "0.022", "best_ask": "0.032"}, {"asset_id": "25589742673068913841508219929281747394194738561317540491643768947357201371462", "price": "0.998", "size": "6046.88", "side": "SELL", "hash": "1b6e81b8d2a2a95f3c1391e6081d854860e1f53d", "best_bid": "0.968", "best_ask": "0.978"}], "timestamp": "1769384480801", "event_type": "price_change"}}
{"_local_timestamp": "2026-01-25T23:41:44.267284+00:00", "data": {"market": "0x512ced1584beb41cb6dacdaa92f5d67f8bee28f055ef63b251d20a446422ddaa", "price_changes": [{"asset_id": "81498082395020979729835659110658786648105896152484850898743462024117016161425", "price": "0.05", "size": "0", "side": "BUY", "hash": "508b6414a56959108595c0990ddada5ede8d01bf", "best_bid": "0.08", "best_ask": "0.1"}, {"asset_id": "105159270423598199664249261738928535905668234939484323704322364820483620754428", "price": "0.95", "size": "0", "side": "SELL", "hash": "f455ba19460acae5d8caf059572388747c32e19f", "best_bid": "0.9", "best_ask": "0.92"}], "timestamp": "1769384504195", "event_type": "price_change"}}
{"_local_timestamp": "2026-01-25T23:41:48.834555+00:00", "data": {"market": "0x512ced1584beb41cb6dacdaa92f5d67f8bee28f055ef63b251d20a446422ddaa", "price_changes": [{"asset_id": "81498082395020979729835659110658786648105896152484850898743462024117016161425", "price": "0.06", "size": "3000", "side": "BUY", "hash": "a946fce7c28e5efb45e0914cb603109f4f262e97", "best_bid": "0.08", "best_ask": "0.1"}, {"asset_id": "105159270423598199664249261738928535905668234939484323704322364820483620754428", "price": "0.94", "size": "3000", "side": "SELL", "hash": "69c53f9212d546530756b319d1782eee0117e918", "best_bid": "0.9", "best_ask": "0.92"}], "timestamp": "1769384508771", "event_type": "price_change"}}
{"_local_timestamp": "2026-01-25T23:41:48.850201+00:00", "data": {"market": "0x512ced1584beb41cb6dacdaa92f5d67f8bee28f055ef63b251d20a446422ddaa", "price_changes": [{"asset_id": "81498082395020979729835659110658786648105896152484850898743462024117016161425", "price": "0.07", "size": "2848.78", "side": "BUY", "hash": "98a08917905d582d6fb5494f25f6848ac1f320fe", "best_bid": "0.08", "best_ask": "0.1"}, {"asset_id": "105159270423598199664249261738928535905668234939484323704322364820483620754428", "price": "0.93", "size": "2848.78", "side": "SELL", "hash": "a9b0ef3fca21373ef420672f4a3c0b2537d6ad53", "best_bid": "0.9", "best_ask": "0.92"}], "timestamp": "1769384508780", "event_type": "price_change"}}
{"_local_timestamp": "2026-01-25T23:41:50.968468+00:00", "data": {"market": "0xb9223ddfda277ecf96cea52aba3d6a47e3bb001bf0173fb3e2145566c28e0c24", "price_changes": [{"asset_id": "57280055515157002497847996398372581077095661831629922834612019741255629878625", "price": "0.2", "size": "245.11", "side": "BUY", "hash": "73b044efff39a11194eb8da66c81b05b5606f8a4", "best_bid": "0.77", "best_ask": "0.8"}, {"asset_id": "64819280345421258482017346931579849092301023088943214992246376036314042237400", "price": "0.8", "size": "245.11", "side": "SELL", "hash": "830fe4e326b587d1cc7ac39ab7cdf29f573b744d", "best_bid": "0.2", "best_ask": "0.23"}], "timestamp": "1769384510771", "event_type": "price_change"}}
{"_local_timestamp": "2026-01-25T23:41:50.968826+00:00", "data": {"market": "0x512ced1584beb41cb6dacdaa92f5d67f8bee28f055ef63b251d20a446422ddaa", "price_changes": [{"asset_id": "105159270423598199664249261738928535905668234939484323704322364820483620754428", "price": "0.24", "size": "0", "side": "BUY", "hash": "919aa3341fce628fb3de8b69b27806e60d45e89f", "best_bid": "0.9", "best_ask": "0.92"}, {"asset_id": "81498082395020979729835659110658786648105896152484850898743462024117016161425", "price": "0.76", "size": "0", "side": "SELL", "hash": "d4cc6f2f4c0ddb5cdc82d9c040c95c096e697b14", "best_bid": "0.08", "best_ask": "0.1"}], "timestamp": "1769384510786", "event_type": "price_change"}}
{"_local_timestamp": "2026-01-25T23:41:50.969092+00:00", "data": {"market": "0x8db2651deb0ca894dfec7963ff43d747e6b203d853ea102ddaaf69272fcbd14e", "price_changes": [{"asset_id": "55723215967704727452199840811929823276351711374899127881856674926400394790108", "price": "0.254", "size": "0", "side": "BUY", "hash": "69211ab0fdf8f71efb3535b5695c7f50c5e97a78", "best_bid": "0.948", "best_ask": "0.962"}, {"asset_id": "59454703894867594337219596879618679187053555828199534311880631098862267050015", "price": "0.746", "size": "0", "side": "SELL", "hash": "3dda05a4a5028c467276dfcb52402994a62913e6", "best_bid": "0.038", "best_ask": "0.052"}], "timestamp": "1769384510786", "event_type": "price_change"}}
{"_local_timestamp": "2026-01-25T23:41:52.734500+00:00", "data": {"market": "0x512ced1584beb41cb6dacdaa92f5d67f8bee28f055ef63b251d20a446422ddaa", "price_changes": [{"asset_id": "105159270423598199664249261738928535905668234939484323704322364820483620754428", "price": "0.26", "size": "1688", "side": "BUY", "hash": "87c2db9774a5e5f580f004edf29801542fa8bc0e", "best_bid": "0.9", "best_ask": "0.92"}, {"asset_id": "81498082395020979729835659110658786648105896152484850898743462024117016161425", "price": "0.74", "size": "1688", "side": "SELL", "hash": "7694fed7d48decf8f961b15746a64e3ae4a7bc5f", "best_bid": "0.08", "best_ask": "0.1"}], "timestamp": "1769384511776", "event_type": "price_change"}}
{"_local_timestamp": "2026-01-25T23:41:52.875279+00:00", "data": {"market": "0x8db2651deb0ca894dfec7963ff43d747e6b203d853ea102ddaaf69272fcbd14e", "price_changes": [{"asset_id": "55723215967704727452199840811929823276351711374899127881856674926400394790108", "price": "0.256", "size": "2103", "side": "BUY", "hash": "3abbaed12e408927ca920ef983193a0a743a4f91", "best_bid": "0.948", "best_ask": "0.962"}, {"asset_id": "59454703894867594337219596879618679187053555828199534311880631098862267050015", "price": "0.744", "size": "2103", "side": "SELL", "hash": "13b9bfce5dfc319c855ae4d2cbbeb97f3d905431", "best_bid": "0.038", "best_ask": "0.052"}], "timestamp": "1769384511831", "event_type": "price_change"}}
{"_local_timestamp": "2026-01-25T23:41:52.911067+00:00", "data": {"market": "0xb9223ddfda277ecf96cea52aba3d6a47e3bb001bf0173fb3e2145566c28e0c24", "price_changes": [{"asset_id": "57280055515157002497847996398372581077095661831629922834612019741255629878625", "price": "0.18", "size": "1038", "side": "BUY", "hash": "c02def3f84c5757484b02c3012e63f5a1c0342c7", "best_bid": "0.77", "best_ask": "0.8"}, {"asset_id": "64819280345421258482017346931579849092301023088943214992246376036314042237400", "price": "0.82", "size": "1038", "side": "SELL", "hash": "80c54e44399f609001367583689d77c749e0ae4b", "best_bid": "0.2", "best_ask": "0.23"}], "timestamp": "1769384511842", "event_type": "price_change"}}
{"_local_timestamp": "2026-01-25T23:41:53.271240+00:00", "data": {"market": "0x8db2651deb0ca894dfec7963ff43d747e6b203d853ea102ddaaf69272fcbd14e", "price_changes": [{"asset_id": "55723215967704727452199840811929823276351711374899127881856674926400394790108", "price": "0.255", "size": "300", "side": "BUY", "hash": "233ec8b37a68ebb6f369649ac5800785d10aac36", "best_bid": "0.948", "best_ask": "0.962"}, {"asset_id": "59454703894867594337219596879618679187053555828199534311880631098862267050015", "price": "0.745", "size": "300", "side": "SELL", "hash": "a002b94edec545a6b14d6ca1e77593a975f9123b", "best_bid": "0.038", "best_ask": "0.052"}], "timestamp": "1769384513075", "event_type": "price_change"}}
{"_local_timestamp": "2026-01-25T23:41:53.482727+00:00", "data": {"market": "0x8db2651deb0ca894dfec7963ff43d747e6b203d853ea102ddaaf69272fcbd14e", "price_changes": [{"asset_id": "55723215967704727452199840811929823276351711374899127881856674926400394790108", "price": "0.895", "size": "20", "side": "BUY", "hash": "8ba3c3856dba2f99f45ac9d6b5646f691de22c91", "best_bid": "0.948", "best_ask": "0.962"}, {"asset_id": "59454703894867594337219596879618679187053555828199534311880631098862267050015", "price": "0.105", "size": "20", "side": "SELL", "hash": "79923403deca7fe3e6deb2e6fdcf93d8c3988fb9", "best_bid": "0.038", "best_ask": "0.052"}], "timestamp": "1769384513413", "event_type": "price_change"}}
{"_local_timestamp": "2026-01-25T23:41:53.483183+00:00", "data": {"market": "0x8db2651deb0ca894dfec7963ff43d747e6b203d853ea102ddaaf69272fcbd14e", "price_changes": [{"asset_id": "55723215967704727452199840811929823276351711374899127881856674926400394790108", "price": "0.257", "size": "700", "side": "BUY", "hash": "584479e493a3ddec52a6cfbe7709d78bb4057510", "best_bid": "0.948", "best_ask": "0.962"}, {"asset_id": "59454703894867594337219596879618679187053555828199534311880631098862267050015", "price": "0.743", "size": "700", "side": "SELL", "hash": "6e9c29069caf798dcc79b2e7e195a7a86364c4e0", "best_bid": "0.038", "best_ask": "0.052"}], "timestamp": "1769384513414", "event_type": "price_change"}}
{"_local_timestamp": "2026-01-25T23:41:59.877157+00:00", "data": {"market": "0x8db2651deb0ca894dfec7963ff43d747e6b203d853ea102ddaaf69272fcbd14e", "price_changes": [{"asset_id": "55723215967704727452199840811929823276351711374899127881856674926400394790108", "price": "0.256", "size": "150", "side": "BUY", "hash": "648c7a8a974fe661f37b70ea41b7cd146569e28d", "best_bid": "0.948", "best_ask": "0.962"}, {"asset_id": "59454703894867594337219596879618679187053555828199534311880631098862267050015", "price": "0.744", "size": "150", "side": "SELL", "hash": "85c60d841dc8523bfbe59e88a749410b76c6f338", "best_bid": "0.038", "best_ask": "0.052"}], "timestamp": "1769384519805", "event_type": "price_change"}}
{"_local_timestamp": "2026-01-25T23:42:00.291683+00:00", "data": {"market": "0x8db2651deb0ca894dfec7963ff43d747e6b203d853ea102ddaaf69272fcbd14e", "price_changes": [{"asset_id": "55723215967704727452199840811929823276351711374899127881856674926400394790108", "price": "0.258", "size": "1937", "side": "BUY", "hash": "c65487a58141808daef6c12796a85515d5a74d46", "best_bid": "0.948", "best_ask": "0.962"}, {"asset_id": "59454703894867594337219596879618679187053555828199534311880631098862267050015", "price": "0.742", "size": "1937", "side": "SELL", "hash": "3d9f86c3e96f138b6e79ff05d317f1948939ddb1", "best_bid": "0.038", "best_ask": "0.052"}], "timestamp": "1769384520227", "event_type": "price_change"}}
{"_local_timestamp": "2026-01-25T23:42:24.582583+00:00", "data": {"market": "0xb9223ddfda277ecf96cea52aba3d6a47e3bb001bf0173fb3e2145566c28e0c24", "price_changes": [{"asset_id": "57280055515157002497847996398372581077095661831629922834612019741255629878625", "price": "0.2", "size": "145.11", "side": "BUY", "hash": "7a56fffed3e4cf77324030780be840a01e235172", "best_bid": "0.77", "best_ask": "0.8"}, {"asset_id": "64819280345421258482017346931579849092301023088943214992246376036314042237400", "price": "0.8", "size": "145.11", "side": "SELL", "hash": "34290e882f036a7c8322354ee3cea92300359d29", "best_bid": "0.2", "best_ask": "0.23"}], "timestamp": "1769384544475", "event_type": "price_change"}}
{"_local_timestamp": "2026-01-25T23:42:24.583508+00:00", "data": {"market": "0xb9223ddfda277ecf96cea52aba3d6a47e3bb001bf0173fb3e2145566c28e0c24", "price_changes": [{"asset_id": "57280055515157002497847996398372581077095661831629922834612019741255629878625", "price": "0.28", "size": "1296.71", "side": "BUY", "hash": "7a56fffed3e4cf77324030780be840a01e235172", "best_bid": "0.77", "best_ask": "0.8"}, {"asset_id": "64819280345421258482017346931579849092301023088943214992246376036314042237400", "price": "0.72", "size": "1296.71", "side": "SELL", "hash": "34290e882f036a7c8322354ee3cea92300359d29", "best_bid": "0.2", "best_ask": "0.23"}], "timestamp": "1769384544475", "event_type": "price_change"}}
{"_local_timestamp": "2026-01-25T23:42:24.750537+00:00", "data": {"market": "0x512ced1584beb41cb6dacdaa92f5d67f8bee28f055ef63b251d20a446422ddaa", "price_changes": [{"asset_id": "105159270423598199664249261738928535905668234939484323704322364820483620754428", "price": "0.87", "size": "133", "side": "BUY", "hash": "7f9af48e2b434e6678b99ee6fcff89e6550456c7", "best_bid": "0.9", "best_ask": "0.92"}, {"asset_id": "81498082395020979729835659110658786648105896152484850898743462024117016161425", "price": "0.13", "size": "133", "side": "SELL", "hash": "944a597ace2eb9731e0602a45cc398a1e604bd9f", "best_bid": "0.08", "best_ask": "0.1"}], "timestamp": "1769384544507", "event_type": "price_change"}}
{"_local_timestamp": "2026-01-25T23:42:24.750925+00:00", "data": {"market": "0x4ddaff7ab33855ab7ed53f75ae4a331496028177f4bf0557eafe0fb83628332b", "price_changes": [{"asset_id": "25589742673068913841508219929281747394194738561317540491643768947357201371462", "price": "0.936", "size": "46", "side": "BUY", "hash": "f38ca2d14e4617594081ea67b05fa0ae748a13d8", "best_bid": "0.968", "best_ask": "0.978"}, {"asset_id": "25056163956965564455957738971346869740799169769422815261763807235324372823907", "price": "0.064", "size": "46", "side": "SELL", "hash": "0e26bda742d4f17e5532121ae1bc083048febfc1", "best_bid": "0.022", "best_ask": "0.032"}], "timestamp": "1769384544510", "event_type": "price_change"}}
{"_local_timestamp": "2026-01-25T23:42:25.046280+00:00", "data": {"market": "0xb9223ddfda277ecf96cea52aba3d6a47e3bb001bf0173fb3e2145566c28e0c24", "price_changes": [{"asset_id": "57280055515157002497847996398372581077095661831629922834612019741255629878625", "price": "0.18", "size": "1138", "side": "BUY", "hash": "9ed646ecc17d2fa0574604076a15c84dd7edaf4a", "best_bid": "0.77", "best_ask": "0.8"}, {"asset_id": "64819280345421258482017346931579849092301023088943214992246376036314042237400", "price": "0.82", "size": "1138", "side": "SELL", "hash": "bc79bc0955f70ce615d66e7bda8d31a4b5084f9e", "best_bid": "0.2", "best_ask": "0.23"}], "timestamp": "1769384544895", "event_type": "price_change"}}
{"_local_timestamp": "2026-01-25T23:42:25.115057+00:00", "data": {"market": "0xb9223ddfda277ecf96cea52aba3d6a47e3bb001bf0173fb3e2145566c28e0c24", "price_changes": [{"asset_id": "57280055515157002497847996398372581077095661831629922834612019741255629878625", "price": "0.22", "size": "1958", "side": "BUY", "hash": "95c37f74147adf78b93f7f82328d1c65aade2471", "best_bid": "0.77", "best_ask": "0.8"}, {"asset_id": "64819280345421258482017346931579849092301023088943214992246376036314042237400", "price": "0.78", "size": "1958", "side": "SELL", "hash": "7e11079dbeafa809bbdc84ff34d3b9465c476385", "best_bid": "0.2", "best_ask": "0.23"}], "timestamp": "1769384544898", "event_type": "price_change"}}
{"_local_timestamp": "2026-01-25T23:43:07.332897+00:00", "data": {"market": "0xb9223ddfda277ecf96cea52aba3d6a47e3bb001bf0173fb3e2145566c28e0c24", "price_changes": [{"asset_id": "57280055515157002497847996398372581077095661831629922834612019741255629878625", "price": "0.8", "size": "197.25", "side": "SELL", "hash": "47ee992aed072c807d8cc22a8eba6345502f4e42", "best_bid": "0.77", "best_ask": "0.8"}, {"asset_id": "64819280345421258482017346931579849092301023088943214992246376036314042237400", "price": "0.2", "size": "197.25", "side": "BUY", "hash": "f85c1e7ef523227ecbfc65299a7fe542a90fb3b8", "best_bid": "0.2", "best_ask": "0.23"}], "timestamp": "1769384587241", "event_type": "price_change"}}
{"_local_timestamp": "2026-01-25T23:43:07.382300+00:00", "data": {"market": "0x07baddbeaa7f66706b84f167f835f3cc90782445ff36b2ea736c1c097f6ff537", "price_changes": [{"asset_id": "106820146733184719100966062623986655992997037363317463528901190592661638187355", "price": "0.36", "size": "45.23", "side": "BUY", "hash": "8be9a62d5d4ac2d71f731e744b0d2bce55db33d8", "best_bid": "0.36", "best_ask": "0.38"}, {"asset_id": "58198710311579915535691075580727536486537716969204598157134462435731312061441", "price": "0.64", "size": "45.23", "side": "SELL", "hash": "e5b19db63c18eaee4c997c7b8db68a142bef9ac9", "best_bid": "0.62", "best_ask": "0.64"}], "timestamp": "1769384587295", "event_type": "price_change"}}
{"_local_timestamp": "2026-01-25T23:43:07.389515+00:00", "data": {"market": "0x512ced1584beb41cb6dacdaa92f5d67f8bee28f055ef63b251d20a446422ddaa", "price_changes": [{"asset_id": "105159270423598199664249261738928535905668234939484323704322364820483620754428", "price": "0.69", "size": "0", "side": "BUY", "hash": "31eeceffb298c246d241073aed5cfb2a1d597e3a", "best_bid": "0.9", "best_ask": "0.92"}, {"asset_id": "81498082395020979729835659110658786648105896152484850898743462024117016161425", "price": "0.31", "size": "0", "side": "SELL", "hash": "0b3bd626371d1425fa790cac4fa1b44c6f8c3880", "best_bid": "0.08", "best_ask": "0.1"}], "timestamp": "1769384587303", "event_type": "price_change"}}
{"_local_timestamp": "2026-01-25T23:43:07.443292+00:00", "data": {"market": "0x512ced1584beb41cb6dacdaa92f5d67f8bee28f055ef63b251d20a446422ddaa", "price_changes": [{"asset_id": "105159270423598199664249261738928535905668234939484323704322364820483620754428", "price": "0.66", "size": "400", "side": "BUY", "hash": "c9392bbc3b6b9097ff0654a9f603087fbda66722", "best_bid": "0.9", "best_ask": "0.92"}, {"asset_id": "81498082395020979729835659110658786648105896152484850898743462024117016161425", "price": "0.34", "size": "400", "side": "SELL", "hash": "36324be8f9f949120afd9fc2c28399ebb6b451a2", "best_bid": "0.08", "best_ask": "0.1"}], "timestamp": "1769384587350", "event_type": "price_change"}}
{"_local_timestamp": "2026-01-25T23:43:07.443757+00:00", "data": {"market": "0x512ced1584beb41cb6dacdaa92f5d67f8bee28f055ef63b251d20a446422ddaa", "price_changes": [{"asset_id": "105159270423598199664249261738928535905668234939484323704322364820483620754428", "price": "0.85", "size": "30", "side": "BUY", "hash": "2a3cfe4c8e4cbf8eba769ad625be292a4bb64665", "best_bid": "0.9", "best_ask": "0.92"}, {"asset_id": "81498082395020979729835659110658786648105896152484850898743462024117016161425", "price": "0.15", "size": "30", "side": "SELL", "hash": "36ac5ed127bc167c8b029993c3360e2f144344b9", "best_bid": "0.08", "best_ask": "0.1"}], "timestamp": "1769384587351", "event_type": "price_change"}}
{"_local_timestamp": "2026-01-25T23:43:07.479122+00:00", "data": {"market": "0x512ced1584beb41cb6dacdaa92f5d67f8bee28f055ef63b251d20a446422ddaa", "price_changes": [{"asset_id": "105159270423598199664249261738928535905668234939484323704322364820483620754428", "price": "0.65", "size": "0", "side": "BUY", "hash": "b5cc24ae274b0ecb44ff558a3220ab25b3e3f1fd", "best_bid": "0.9", "best_ask": "0.92"}, {"asset_id": "81498082395020979729835659110658786648105896152484850898743462024117016161425", "price": "0.35", "size": "0", "side": "SELL", "hash": "8d1869584ade05d0148cb4fe9ac70be2c6db65d5", "best_bid": "0.08", "best_ask": "0.1"}], "timestamp": "1769384587391", "event_type": "price_change"}}
{"_local_timestamp": "2026-01-25T23:43:07.536820+00:00", "data": {"market": "0x512ced1584beb41cb6dacdaa92f5d67f8bee28f055ef63b251d20a446422ddaa", "price_changes": [{"asset_id": "105159270423598199664249261738928535905668234939484323704322364820483620754428", "price": "0.64", "size": "0", "side": "BUY", "hash": "ec677466a11ff6e8ca15a7e236c1a084804c29ee", "best_bid": "0.9", "best_ask": "0.92"}, {"asset_id": "81498082395020979729835659110658786648105896152484850898743462024117016161425", "price": "0.36", "size": "0", "side": "SELL", "hash": "5aa1aaa4aeb4cd5c82d69bd33c4c70f00eaa989b", "best_bid": "0.08", "best_ask": "0.1"}], "timestamp": "1769384587439", "event_type": "price_change"}}
{"_local_timestamp": "2026-01-25T23:43:07.553966+00:00", "data": {"market": "0x512ced1584beb41cb6dacdaa92f5d67f8bee28f055ef63b251d20a446422ddaa", "price_changes": [{"asset_id": "105159270423598199664249261738928535905668234939484323704322364820483620754428", "price": "0.67", "size": "400", "side": "BUY", "hash": "8de0594e51f53819a75718cfdda88ded35a6828e", "best_bid": "0.9", "best_ask": "0.92"}, {"asset_id": "81498082395020979729835659110658786648105896152484850898743462024117016161425", "price": "0.33", "size": "400", "side": "SELL", "hash": "ef3c5558a98eaf9808fbb4b2b8893647d621c8dd", "best_bid": "0.08", "best_ask": "0.1"}], "timestamp": "1769384587461", "event_type": "price_change"}}
{"_local_timestamp": "2026-01-25T23:43:07.694294+00:00", "data": {"market": "0x512ced1584beb41cb6dacdaa92f5d67f8bee28f055ef63b251d20a446422ddaa", "price_changes": [{"asset_id": "105159270423598199664249261738928535905668234939484323704322364820483620754428", "price": "0.63", "size": "1493", "side": "BUY", "hash": "de0db6799163dd438c7505e4014abebe4b56eb02", "best_bid": "0.9", "best_ask": "0.92"}, {"asset_id": "81498082395020979729835659110658786648105896152484850898743462024117016161425", "price": "0.37", "size": "1493", "side": "SELL", "hash": "775adde5646aae65ffd8742cf068cfed87bf940e", "best_bid": "0.08", "best_ask": "0.1"}], "timestamp": "1769384587602", "event_type": "price_change"}}
{"_local_timestamp": "2026-01-25T23:43:07.834389+00:00", "data": {"market": "0x8db2651deb0ca894dfec7963ff43d747e6b203d853ea102ddaaf69272fcbd14e", "price_changes": [{"asset_id": "59454703894867594337219596879618679187053555828199534311880631098862267050015", "price": "0.078", "size": "400", "side": "SELL", "hash": "88532d4852f8ff72fb350b247bd64e0e81f88e85", "best_bid": "0.038", "best_ask": "0.052"}, {"asset_id": "55723215967704727452199840811929823276351711374899127881856674926400394790108", "price": "0.922", "size": "400", "side": "BUY", "hash": "f32cc75abb6b6d526a4e0cb4318041905ddf3ce8", "best_bid": "0.948", "best_ask": "0.962"}], "timestamp": "1769384587741", "event_type": "price_change"}}
{"_local_timestamp": "2026-01-25T23:43:07.926454+00:00", "data": {"market": "0x512ced1584beb41cb6dacdaa92f5d67f8bee28f055ef63b251d20a446422ddaa", "price_changes": [{"asset_id": "105159270423598199664249261738928535905668234939484323704322364820483620754428", "price": "0.66", "size": "0", "side": "BUY", "hash": "0411bc7ee63368a5bd3e3e107ee520a567e207ea", "best_bid": "0.9", "best_ask": "0.92"}, {"asset_id": "81498082395020979729835659110658786648105896152484850898743462024117016161425", "price": "0.34", "size": "0", "side": "SELL", "hash": "02afdd4443dbb71a19ad21cece70f8f0d120a5df", "best_bid": "0.08", "best_ask": "0.1"}], "timestamp": "1769384587829", "event_type": "price_change"}}
{"_local_timestamp": "2026-01-25T23:43:08.090102+00:00", "data": {"market": "0x8db2651deb0ca894dfec7963ff43d747e6b203d853ea102ddaaf69272fcbd14e", "price_changes": [{"asset_id": "59454703894867594337219596879618679187053555828199534311880631098862267050015", "price": "0.077", "size": "169.17", "side": "SELL", "hash": "712c2c0429f1f37e1a062bdcbeeca27fa1272861", "best_bid": "0.038", "best_ask": "0.052"}, {"asset_id": "55723215967704727452199840811929823276351711374899127881856674926400394790108", "price": "0.923", "size": "169.17", "side": "BUY", "hash": "e3163dc93d53a38739d3998e0b03e86301ed898a", "best_bid": "0.948", "best_ask": "0.962"}], "timestamp": "1769384587995", "event_type": "price_change"}}
{"_local_timestamp": "2026-01-25T23:43:08.182693+00:00", "data": {"market": "0x07baddbeaa7f66706b84f167f835f3cc90782445ff36b2ea736c1c097f6ff537", "price_changes": [{"asset_id": "58198710311579915535691075580727536486537716969204598157134462435731312061441", "price": "0.59", "size": "16", "side": "BUY", "hash": "3bde350ebf229bd6061a410021656385fa38696d", "best_bid": "0.62", "best_ask": "0.64"}, {"asset_id": "106820146733184719100966062623986655992997037363317463528901190592661638187355", "price": "0.41", "size": "16", "side": "SELL", "hash": "68da5ff35507a13e7ba531a8c324ea8699416f3b", "best_bid": "0.36", "best_ask": "0.38"}], "timestamp": "1769384588028", "event_type": "price_change"}}
{"_local_timestamp": "2026-01-25T23:43:08.233861+00:00", "data": {"market": "0x512ced1584beb41cb6dacdaa92f5d67f8bee28f055ef63b251d20a446422ddaa", "price_changes": [{"asset_id": "105159270423598199664249261738928535905668234939484323704322364820483620754428", "price": "0.63", "size": "793", "side": "BUY", "hash": "d76d83e80004ab540ebe986fa8a05469f5ff6b43", "best_bid": "0.9", "best_ask": "0.92"}, {"asset_id": "81498082395020979729835659110658786648105896152484850898743462024117016161425", "price": "0.37", "size": "793", "side": "SELL", "hash": "696517b1067d7fe2aaf6aeaa89d0c03df6862877", "best_bid": "0.08", "best_ask": "0.1"}], "timestamp": "1769384588146", "event_type": "price_change"}}
{"_local_timestamp": "2026-01-25T23:43:08.256369+00:00", "data": {"market": "0xb9223ddfda277ecf96cea52aba3d6a47e3bb001bf0173fb3e2145566c28e0c24", "price_changes": [{"asset_id": "57280055515157002497847996398372581077095661831629922834612019741255629878625", "price": "0.7", "size": "400", "side": "BUY", "hash": "149729723ef15452dedd87d205d1d57f742a60b1", "best_bid": "0.77", "best_ask": "0.8"}, {"asset_id": "64819280345421258482017346931579849092301023088943214992246376036314042237400", "price": "0.3", "size": "400", "side": "SELL", "hash": "d347cbf89e12ce12d845e3036d70639b4fc725e6", "best_bid": "0.2", "best_ask": "0.23"}], "timestamp": "1769384588170", "event_type": "price_change"}}
{"_local_timestamp": "2026-01-25T23:43:08.317011+00:00", "data": {"market": "0x512ced1584beb41cb6dacdaa92f5d67f8bee28f055ef63b251d20a446422ddaa", "price_changes": [{"asset_id": "105159270423598199664249261738928535905668234939484323704322364820483620754428", "price": "0.84", "size": "40", "side": "BUY", "hash": "e89fedc4aceb9bd78d841d91a84c6b0f164cad17", "best_bid": "0.9", "best_ask": "0.92"}, {"asset_id": "81498082395020979729835659110658786648105896152484850898743462024117016161425", "price": "0.16", "size": "40", "side": "SELL", "hash": "f4fd404e953b28512a7b4639ca9d40cc854bf2c8", "best_bid": "0.08", "best_ask": "0.1"}], "timestamp": "1769384588231", "event_type": "price_change"}}
{"_local_timestamp": "2026-01-25T23:43:08.322900+00:00", "data": {"market": "0x512ced1584beb41cb6dacdaa92f5d67f8bee28f055ef63b251d20a446422ddaa", "price_changes": [{"asset_id": "105159270423598199664249261738928535905668234939484323704322364820483620754428", "price": "0.27", "size": "700", "side": "BUY", "hash": "bb372dd3f1179ae9b592aeab076f71a48d1506f5", "best_bid": "0.9", "best_ask": "0.92"}, {"asset_id": "81498082395020979729835659110658786648105896152484850898743462024117016161425", "price": "0.73", "size": "700", "side": "SELL", "hash": "95bb93207ae098854868c43d65407c4e19bd7aa0", "best_bid": "0.08", "best_ask": "0.1"}], "timestamp": "1769384588231", "event_type": "price_change"}}
{"_local_timestamp": "2026-01-25T23:43:08.340596+00:00", "data": {"market": "0xb9223ddfda277ecf96cea52aba3d6a47e3bb001bf0173fb3e2145566c28e0c24", "price_changes": [{"asset_id": "57280055515157002497847996398372581077095661831629922834612019741255629878625", "price": "0.7", "size": "0", "side": "BUY", "hash": "bbb6f61039387899b964fbef4160530f078bd376", "best_bid": "0.77", "best_ask": "0.8"}, {"asset_id": "64819280345421258482017346931579849092301023088943214992246376036314042237400", "price": "0.3", "size": "0", "side": "SELL", "hash": "977eeace51774401a3f4d70216d523fc27347ec5", "best_bid": "0.2", "best_ask": "0.23"}], "timestamp": "1769384588245", "event_type": "price_change"}}
{"_local_timestamp": "2026-01-25T23:43:08.587801+00:00", "data": {"market": "0x8db2651deb0ca894dfec7963ff43d747e6b203d853ea102ddaaf69272fcbd14e", "price_changes": [{"asset_id": "55723215967704727452199840811929823276351711374899127881856674926400394790108", "price": "0.92", "size": "100", "side": "BUY", "hash": "2dada94c6673897e249a33a1e1304b6afe798e88", "best_bid": "0.948", "best_ask": "0.962"}, {"asset_id": "59454703894867594337219596879618679187053555828199534311880631098862267050015", "price": "0.08", "size": "100", "side": "SELL", "hash": "adfc82fa3c389f88463e574e07b68cbc81b9dec2", "best_bid": "0.038", "best_ask": "0.052"}], "timestamp": "1769384588487", "event_type": "price_change"}}
{"_local_timestamp": "2026-01-25T23:43:10.717101+00:00", "data": {"market": "0xb9223ddfda277ecf96cea52aba3d6a47e3bb001bf0173fb3e2145566c28e0c24", "price_changes": [{"asset_id": "57280055515157002497847996398372581077095661831629922834612019741255629878625", "price": "0.71", "size": "101.39", "side": "BUY", "hash": "01e9341cf6846646e5b36b72401d628d5fbc1f42", "best_bid": "0.77", "best_ask": "0.8"}, {"asset_id": "64819280345421258482017346931579849092301023088943214992246376036314042237400", "price": "0.29", "size": "101.39", "side": "SELL", "hash": "0902116e5cae9cfba3995abec6196a42a734299b", "best_bid": "0.2", "best_ask": "0.23"}], "timestamp": "1769384590595", "event_type": "price_change"}}
{"_local_timestamp": "2026-01-25T23:43:10.730857+00:00", "data": {"market": "0xb9223ddfda277ecf96cea52aba3d6a47e3bb001bf0173fb3e2145566c28e0c24", "price_changes": [{"asset_id": "57280055515157002497847996398372581077095661831629922834612019741255629878625", "price": "0.7", "size": "20", "side": "BUY", "hash": "f2431fee9d06e0d0fb6053c43585afd6f16bf3af", "best_bid": "0.77", "best_ask": "0.8"}, {"asset_id": "64819280345421258482017346931579849092301023088943214992246376036314042237400", "price": "0.3", "size": "20", "side": "SELL", "hash": "73f3ca9a5015a629be9649170e66b575ed36a36a", "best_bid": "0.2", "best_ask": "0.23"}], "timestamp": "1769384590622", "event_type": "price_change"}}
{"_local_timestamp": "2026-01-25T23:43:16.652017+00:00", "data": {"market": "0x512ced1584beb41cb6dacdaa92f5d67f8bee28f055ef63b251d20a446422ddaa", "price_changes": [{"asset_id": "105159270423598199664249261738928535905668234939484323704322364820483620754428", "price": "0.26", "size": "150", "side": "BUY", "hash": "bee6f75fa3133f6c4a3896036116e7e771f9d038", "best_bid": "0.9", "best_ask": "0.92"}, {"asset_id": "81498082395020979729835659110658786648105896152484850898743462024117016161425", "price": "0.74", "size": "150", "side": "SELL", "hash": "50fe6b74285f25dd4884be731c2e71aba4130446", "best_bid": "0.08", "best_ask": "0.1"}], "timestamp": "1769384596512", "event_type": "price_change"}}
{"_local_timestamp": "2026-01-25T23:43:17.068428+00:00", "data": {"market": "0x512ced1584beb41cb6dacdaa92f5d67f8bee28f055ef63b251d20a446422ddaa", "price_changes": [{"asset_id": "105159270423598199664249261738928535905668234939484323704322364820483620754428", "price": "0.28", "size": "1520.85", "side": "BUY", "hash": "6930ced0b73666baeb7308bf8eb4dd84e154b57a", "best_bid": "0.9", "best_ask": "0.92"}, {"asset_id": "81498082395020979729835659110658786648105896152484850898743462024117016161425", "price": "0.72", "size": "1520.85", "side": "SELL", "hash": "d2a9d9636a722587fad0b75066869b0d35e9b5ab", "best_bid": "0.08", "best_ask": "0.1"}], "timestamp": "1769384596942", "event_type": "price_change"}}
{"_local_timestamp": "2026-01-25T23:43:17.138072+00:00", "data": {"market": "0x4ddaff7ab33855ab7ed53f75ae4a331496028177f4bf0557eafe0fb83628332b", "price_changes": [{"asset_id": "25589742673068913841508219929281747394194738561317540491643768947357201371462", "price": "0.541", "size": "0", "side": "BUY", "hash": "0f67a35b206b297bc90e213103ef39af3f19c125", "best_bid": "0.968", "best_ask": "0.978"}, {"asset_id": "25056163956965564455957738971346869740799169769422815261763807235324372823907", "price": "0.459", "size": "0", "side": "SELL", "hash": "5ffad21c1cd796e64793777b89a68aeff8f2002e", "best_bid": "0.022", "best_ask": "0.032"}], "timestamp": "1769384597000", "event_type": "price_change"}}
{"_local_timestamp": "2026-01-25T23:43:17.393384+00:00", "data": {"market": "0x4ddaff7ab33855ab7ed53f75ae4a331496028177f4bf0557eafe0fb83628332b", "price_changes": [{"asset_id": "25589742673068913841508219929281747394194738561317540491643768947357201371462", "price": "0.893", "size": "30", "side": "BUY", "hash": "ba0cc5f312532eb8d5546f5a581f1e4f80253f2d", "best_bid": "0.968", "best_ask": "0.978"}, {"asset_id": "25056163956965564455957738971346869740799169769422815261763807235324372823907", "price": "0.107", "size": "30", "side": "SELL", "hash": "4c08e715f6af46ff658ef140c3a24e88b34a7971", "best_bid": "0.022", "best_ask": "0.032"}], "timestamp": "1769384597269", "event_type": "price_change"}}
{"_local_timestamp": "2026-01-25T23:43:32.674954+00:00", "data": {"market": "0x8db2651deb0ca894dfec7963ff43d747e6b203d853ea102ddaaf69272fcbd14e", "price_changes": [{"asset_id": "59454703894867594337219596879618679187053555828199534311880631098862267050015", "price": "0.079", "size": "100", "side": "SELL", "hash": "bccacce67d19655aa7c40be313cc7e51c4bd4bcb", "best_bid": "0.038", "best_ask": "0.052"}, {"asset_id": "55723215967704727452199840811929823276351711374899127881856674926400394790108", "price": "0.921", "size": "100", "side": "BUY", "hash": "9f9a57eef7f74e779410bd73f644e04e59f467bd", "best_bid": "0.948", "best_ask": "0.962"}], "timestamp": "1769384612552", "event_type": "price_change"}}
{"_local_timestamp": "2026-01-25T23:43:32.675303+00:00", "data": {"market": "0x4ddaff7ab33855ab7ed53f75ae4a331496028177f4bf0557eafe0fb83628332b", "price_changes": [{"asset_id": "25056163956965564455957738971346869740799169769422815261763807235324372823907", "price": "0.047", "size": "0", "side": "SELL", "hash": "f43b17d8bd06497b20776fe3a003b925a88fe27f", "best_bid": "0.022", "best_ask": "0.032"}, {"asset_id": "25589742673068913841508219929281747394194738561317540491643768947357201371462", "price": "0.953", "size": "0", "side": "BUY", "hash": "0a01f9880a87f455137b03597fd863f531fa7c78", "best_bid": "0.968", "best_ask": "0.978"}], "timestamp": "1769384612552", "event_type": "price_change"}}
{"_local_timestamp": "2026-01-25T23:43:32.704877+00:00", "data": {"market": "0x512ced1584beb41cb6dacdaa92f5d67f8bee28f055ef63b251d20a446422ddaa", "price_changes": [{"asset_id": "105159270423598199664249261738928535905668234939484323704322364820483620754428", "price": "0.87", "size": "87", "side": "BUY", "hash": "9e1a1770f5465bf5c39f68e20e1d47305b30d6b3", "best_bid": "0.9", "best_ask": "0.92"}, {"asset_id": "81498082395020979729835659110658786648105896152484850898743462024117016161425", "price": "0.13", "size": "87", "side": "SELL", "hash": "5f80dad1d0ba5d918f1e3079f7c9580e67355601", "best_bid": "0.08", "best_ask": "0.1"}], "timestamp": "1769384612577", "event_type": "price_change"}}
{"_local_timestamp": "2026-01-25T23:43:32.705223+00:00", "data": {"market": "0x4ddaff7ab33855ab7ed53f75ae4a331496028177f4bf0557eafe0fb83628332b", "price_changes": [{"asset_id": "25589742673068913841508219929281747394194738561317540491643768947357201371462", "price": "0.936", "size": "0", "side": "BUY", "hash": "57ec52442231a87f19700bcaf9923f90d90a3656", "best_bid": "0.968", "best_ask": "0.978"}, {"asset_id": "25056163956965564455957738971346869740799169769422815261763807235324372823907", "price": "0.064", "size": "0", "side": "SELL", "hash": "98c83a3bfa4052b13464d1d8357991de306580b5", "best_bid": "0.022", "best_ask": "0.032"}], "timestamp": "1769384612582", "event_type": "price_change"}}
{"_local_timestamp": "2026-01-25T23:43:32.898206+00:00", "data": {"market": "0x4ddaff7ab33855ab7ed53f75ae4a331496028177f4bf0557eafe0fb83628332b", "price_changes": [{"asset_id": "25056163956965564455957738971346869740799169769422815261763807235324372823907", "price": "0.045", "size": "306.32", "side": "SELL", "hash": "492e788bf210636890b051fcf6f821168093812e", "best_bid": "0.022", "best_ask": "0.032"}, {"asset_id": "25589742673068913841508219929281747394194738561317540491643768947357201371462", "price": "0.955", "size": "306.32", "side": "BUY", "hash": "dc8005c436623d61fdd221a55d8039e57128877e", "best_bid": "0.968", "best_ask": "0.978"}], "timestamp": "1769384612778", "event_type": "price_change"}}
{"_local_timestamp": "2026-01-25T23:43:32.900485+00:00", "data": {"market": "0x8db2651deb0ca894dfec7963ff43d747e6b203d853ea102ddaaf69272fcbd14e", "price_changes": [{"asset_id": "59454703894867594337219596879618679187053555828199534311880631098862267050015", "price": "0.077", "size": "293.44", "side": "SELL", "hash": "e1cbfd88a0c36836666b4a89588370426c13d57a", "best_bid": "0.038", "best_ask": "0.052"}, {"asset_id": "55723215967704727452199840811929823276351711374899127881856674926400394790108", "price": "0.923", "size": "293.44", "side": "BUY", "hash": "b6c40dc97e5d4a07cfae678e9d2e77959003b9d4", "best_bid": "0.948", "best_ask": "0.962"}], "timestamp": "1769384612779", "event_type": "price_change"}}
{"_local_timestamp": "2026-01-25T23:43:51.729202+00:00", "data": {"market": "0xb9223ddfda277ecf96cea52aba3d6a47e3bb001bf0173fb3e2145566c28e0c24", "price_changes": [{"asset_id": "57280055515157002497847996398372581077095661831629922834612019741255629878625", "price": "0.8", "size": "214.05", "side": "SELL", "hash": "c4d0aa4d1b3d310d7b0e5e88399112c4eb560b12", "best_bid": "0.77", "best_ask": "0.8"}, {"asset_id": "64819280345421258482017346931579849092301023088943214992246376036314042237400", "price": "0.2", "size": "214.05", "side": "BUY", "hash": "096d325738b83a1f4530a636e150d512be3a33d5", "best_bid": "0.2", "best_ask": "0.23"}], "timestamp": "1769384631576", "event_type": "price_change"}}
{"_local_timestamp": "2026-01-25T23:43:56.342881+00:00", "data": {"market": "0x07baddbeaa7f66706b84f167f835f3cc90782445ff36b2ea736c1c097f6ff537", "price_changes": [{"asset_id": "106820146733184719100966062623986655992997037363317463528901190592661638187355", "price": "0.36", "size": "69.03", "side": "BUY", "hash": "6772ba3bdbb04da61933701948d16cb37e1817d9", "best_bid": "0.36", "best_ask": "0.38"}, {"asset_id": "58198710311579915535691075580727536486537716969204598157134462435731312061441", "price": "0.64", "size": "69.03", "side": "SELL", "hash": "f7ac5686b9780380667d425bb33031d9ceff5026", "best_bid": "0.62", "best_ask": "0.64"}], "timestamp": "1769384636193", "event_type": "price_change"}}
{"_local_timestamp": "2026-01-25T23:44:04.220193+00:00", "data": {"market": "0x07baddbeaa7f66706b84f167f835f3cc90782445ff36b2ea736c1c097f6ff537", "price_changes": [{"asset_id": "106820146733184719100966062623986655992997037363317463528901190592661638187355", "price": "0.33", "size": "180", "side": "BUY", "hash": "d781395bed0c4f0d17783b6ded38e6a02b34ae5e", "best_bid": "0.36", "best_ask": "0.38"}, {"asset_id": "58198710311579915535691075580727536486537716969204598157134462435731312061441", "price": "0.67", "size": "180", "side": "SELL", "hash": "83bc0b0c386f488c17c2e053df38a6f96a141301", "best_bid": "0.62", "best_ask": "0.64"}], "timestamp": "1769384644082", "event_type": "price_change"}}
{"_local_timestamp": "2026-01-25T23:44:08.369364+00:00", "data": {"market": "0x4ddaff7ab33855ab7ed53f75ae4a331496028177f4bf0557eafe0fb83628332b", "price_changes": [{"asset_id": "25589742673068913841508219929281747394194738561317540491643768947357201371462", "price": "0.54", "size": "0", "side": "BUY", "hash": "17bcd52897f9fbbafc4a4cb40cc8fbec70d5fab7", "best_bid": "0.968", "best_ask": "0.978"}, {"asset_id": "25056163956965564455957738971346869740799169769422815261763807235324372823907", "price": "0.46", "size": "0", "side": "SELL", "hash": "b1b9581f1e16a21e3b345678a9fdb502a4e9ef9a", "best_bid": "0.022", "best_ask": "0.032"}], "timestamp": "1769384648143", "event_type": "price_change"}}
{"_local_timestamp": "2026-01-25T23:44:08.418629+00:00", "data": {"market": "0x4ddaff7ab33855ab7ed53f75ae4a331496028177f4bf0557eafe0fb83628332b", "price_changes": [{"asset_id": "25589742673068913841508219929281747394194738561317540491643768947357201371462", "price": "0.54", "size": "5", "side": "BUY", "hash": "58cfce2a337bb1ee30c2d9009f49b72a00a6a228", "best_bid": "0.968", "best_ask": "0.978"}, {"asset_id": "25056163956965564455957738971346869740799169769422815261763807235324372823907", "price": "0.46", "size": "5", "side": "SELL", "hash": "77eb2e73b5deeb002646a49e94befa7a558d5ab9", "best_bid": "0.022", "best_ask": "0.032"}], "timestamp": "1769384648198", "event_type": "price_change"}}
{"_local_timestamp": "2026-01-25T23:44:08.682497+00:00", "data": {"market": "0x8db2651deb0ca894dfec7963ff43d747e6b203d853ea102ddaaf69272fcbd14e", "price_changes": [{"asset_id": "55723215967704727452199840811929823276351711374899127881856674926400394790108", "price": "0.256", "size": "100", "side": "BUY", "hash": "ab3675c1dec9ae5d7b53df35a156ecf142a55b10", "best_bid": "0.948", "best_ask": "0.962"}, {"asset_id": "59454703894867594337219596879618679187053555828199534311880631098862267050015", "price": "0.744", "size": "100", "side": "SELL", "hash": "db3d5cf69a2fbd4c70c5dac6fc5d28c185931389", "best_bid": "0.038", "best_ask": "0.052"}], "timestamp": "1769384648428", "event_type": "price_change"}}
{"_local_timestamp": "2026-01-25T23:44:09.110449+00:00", "data": {"market": "0x4ddaff7ab33855ab7ed53f75ae4a331496028177f4bf0557eafe0fb83628332b", "price_changes": [{"asset_id": "25056163956965564455957738971346869740799169769422815261763807235324372823907", "price": "0.033", "size": "0", "side": "SELL", "hash": "4dceabf642e198a5302624422d3098eefef2d960", "best_bid": "0.022", "best_ask": "0.032"}, {"asset_id": "25589742673068913841508219929281747394194738561317540491643768947357201371462", "price": "0.967", "size": "0", "side": "BUY", "hash": "79ca28d1624a6d3021159975cb1c2b4f3ddc551c", "best_bid": "0.968", "best_ask": "0.978"}], "timestamp": "1769384648850", "event_type": "price_change"}}
{"_local_timestamp": "2026-01-25T23:44:09.110789+00:00", "data": {"market": "0x8db2651deb0ca894dfec7963ff43d747e6b203d853ea102ddaaf69272fcbd14e", "price_changes": [{"asset_id": "55723215967704727452199840811929823276351711374899127881856674926400394790108", "price": "0.258", "size": "1987", "side": "BUY", "hash": "29c25166013c1df7cf1fdca17906c9b3e3ee3b32", "best_bid": "0.948", "best_ask": "0.962"}, {"asset_id": "59454703894867594337219596879618679187053555828199534311880631098862267050015", "price": "0.742", "size": "1987", "side": "SELL", "hash": "2b3ffc9231d2a5b74ee2ced128cb34a260abd398", "best_bid": "0.038", "best_ask": "0.052"}], "timestamp": "1769384648777", "event_type": "price_change"}}
{"_local_timestamp": "2026-01-25T23:44:09.225820+00:00", "data": {"market": "0x4ddaff7ab33855ab7ed53f75ae4a331496028177f4bf0557eafe0fb83628332b", "price_changes": [{"asset_id": "25056163956965564455957738971346869740799169769422815261763807235324372823907", "price": "0.034", "size": "103.44", "side": "SELL", "hash": "34fb9d253b187e2411a541f70341120127f4efd3", "best_bid": "0.022", "best_ask": "0.032"}, {"asset_id": "25589742673068913841508219929281747394194738561317540491643768947357201371462", "price": "0.966", "size": "103.44", "side": "BUY", "hash": "571ae255611224643f8b6ed3d591739b57f1c3b0", "best_bid": "0.968", "best_ask": "0.978"}], "timestamp": "1769384649021", "event_type": "price_change"}}
{"_local_timestamp": "2026-01-25T23:44:11.874373+00:00", "data": {"market": "0x4ddaff7ab33855ab7ed53f75ae4a331496028177f4bf0557eafe0fb83628332b", "price_changes": [{"asset_id": "25589742673068913841508219929281747394194738561317540491643768947357201371462", "price": "0.967", "size": "35", "side": "BUY", "hash": "25ae144ebbbe7ccf12482658017e36f9a0e2cd29", "best_bid": "0.968", "best_ask": "0.978"}, {"asset_id": "25056163956965564455957738971346869740799169769422815261763807235324372823907", "price": "0.033", "size": "35", "side": "SELL", "hash": "9d85b54641d7281fc454850bdd290b194ffb165e", "best_bid": "0.022", "best_ask": "0.032"}], "timestamp": "1769384651728", "event_type": "price_change"}}
{"_local_timestamp": "2026-01-25T23:44:12.231031+00:00", "data": {"market": "0x4ddaff7ab33855ab7ed53f75ae4a331496028177f4bf0557eafe0fb83628332b", "price_changes": [{"asset_id": "25589742673068913841508219929281747394194738561317540491643768947357201371462", "price": "0.968", "size": "0", "side": "BUY", "hash": "eb40e3030c6c0a256da3d33a605209c9cc1f337d", "best_bid": "0.967", "best_ask": "0.978"}, {"asset_id": "25056163956965564455957738971346869740799169769422815261763807235324372823907", "price": "0.032", "size": "0", "side": "SELL", "hash": "4da2a2a4363c38d90d7389ded1bf20fcbe0f945f", "best_bid": "0.022", "best_ask": "0.033"}], "timestamp": "1769384652086", "event_type": "price_change"}}
{"_local_timestamp": "2026-01-25T23:44:12.279546+00:00", "data": {"market": "0x4ddaff7ab33855ab7ed53f75ae4a331496028177f4bf0557eafe0fb83628332b", "price_changes": [{"asset_id": "25056163956965564455957738971346869740799169769422815261763807235324372823907", "price": "0.023", "size": "417", "side": "BUY", "hash": "ce10cd37c466cb263e4a25aa31ecedc92d781536", "best_bid": "0.023", "best_ask": "0.033"}, {"asset_id": "25589742673068913841508219929281747394194738561317540491643768947357201371462", "price": "0.977", "size": "417", "side": "SELL", "hash": "0843336dafc4f800bb4743467d1fc6df7d116778", "best_bid": "0.967", "best_ask": "0.977"}], "timestamp": "1769384652112", "event_type": "price_change"}}
{"_local_timestamp": "2026-01-25T23:44:13.135264+00:00", "data": {"market": "0xb9223ddfda277ecf96cea52aba3d6a47e3bb001bf0173fb3e2145566c28e0c24", "price_changes": [{"asset_id": "57280055515157002497847996398372581077095661831629922834612019741255629878625", "price": "0.7", "size": "0", "side": "BUY", "hash": "9c2d3cbee94871368725ec635b7c394572cf7f6a", "best_bid": "0.77", "best_ask": "0.8"}, {"asset_id": "64819280345421258482017346931579849092301023088943214992246376036314042237400", "price": "0.3", "size": "0", "side": "SELL", "hash": "652d814a8c3639f7f371a27c2ae5d9ec1520333f", "best_bid": "0.2", "best_ask": "0.23"}], "timestamp": "1769384652977", "event_type": "price_change"}}
{"_local_timestamp": "2026-01-25T23:44:13.254241+00:00", "data": {"market": "0xb9223ddfda277ecf96cea52aba3d6a47e3bb001bf0173fb3e2145566c28e0c24", "price_changes": [{"asset_id": "57280055515157002497847996398372581077095661831629922834612019741255629878625", "price": "0.71", "size": "121.39", "side": "BUY", "hash": "9e4acf336d8155eb191ac74c6a099941b58d5811", "best_bid": "0.77", "best_ask": "0.8"}, {"asset_id": "64819280345421258482017346931579849092301023088943214992246376036314042237400", "price": "0.29", "size": "121.39", "side": "SELL", "hash": "6b314094a868bf7ef5553f4e027461453b6f38b7", "best_bid": "0.2", "best_ask": "0.23"}], "timestamp": "1769384653049", "event_type": "price_change"}}
{"_local_timestamp": "2026-01-25T23:44:17.638402+00:00", "data": {"market": "0x4ddaff7ab33855ab7ed53f75ae4a331496028177f4bf0557eafe0fb83628332b", "price_changes": [{"asset_id": "25589742673068913841508219929281747394194738561317540491643768947357201371462", "price": "0.978", "size": "0", "side": "SELL", "hash": "781e6b085c15a71e061c0e426f8fdd6680190137", "best_bid": "0.967", "best_ask": "0.977"}, {"asset_id": "25056163956965564455957738971346869740799169769422815261763807235324372823907", "price": "0.022", "size": "0", "side": "BUY", "hash": "81ecc294505a4551c637d853ce51de9e9c27ae42", "best_bid": "0.023", "best_ask": "0.033"}], "timestamp": "1769384657402", "event_type": "price_change"}}
{"_local_timestamp": "2026-01-25T23:44:17.964617+00:00", "data": {"market": "0x4ddaff7ab33855ab7ed53f75ae4a331496028177f4bf0557eafe0fb83628332b", "price_changes": [{"asset_id": "25589742673068913841508219929281747394194738561317540491643768947357201371462", "price": "0.976", "size": "114.77", "side": "SELL", "hash": "0908a0d2c3b361e7648d41424d0821084678e38e", "best_bid": "0.967", "best_ask": "0.976"}, {"asset_id": "25056163956965564455957738971346869740799169769422815261763807235324372823907", "price": "0.024", "size": "114.77", "side": "BUY", "hash": "d2827ce353d9be7836f121c38f23fe5557d39223", "best_bid": "0.024", "best_ask": "0.033"}], "timestamp": "1769384657719", "event_type": "price_change"}}
{"_local_timestamp": "2026-01-25T23:44:17.993455+00:00", "data": {"market": "0x4ddaff7ab33855ab7ed53f75ae4a331496028177f4bf0557eafe0fb83628332b", "price_changes": [{"asset_id": "25056163956965564455957738971346869740799169769422815261763807235324372823907", "price": "0.023", "size": "0", "side": "BUY", "hash": "734f2b54eb0800ff02ab0e30467fd4408718ef33", "best_bid": "0.024", "best_ask": "0.033"}, {"asset_id": "25589742673068913841508219929281747394194738561317540491643768947357201371462", "price": "0.977", "size": "0", "side": "SELL", "hash": "71eeb326293f15bdb3f18397b19f846220adfc58", "best_bid": "0.967", "best_ask": "0.976"}], "timestamp": "1769384657744", "event_type": "price_change"}}
{"_local_timestamp": "2026-01-25T23:44:20.958035+00:00", "data": {"market": "0xb9223ddfda277ecf96cea52aba3d6a47e3bb001bf0173fb3e2145566c28e0c24", "price_changes": [{"asset_id": "57280055515157002497847996398372581077095661831629922834612019741255629878625", "price": "0.28", "size": "1196.71", "side": "BUY", "hash": "75da880cf220d52c8903d5428a54d788e9d8e69e", "best_bid": "0.77", "best_ask": "0.8"}, {"asset_id": "64819280345421258482017346931579849092301023088943214992246376036314042237400", "price": "0.72", "size": "1196.71", "side": "SELL", "hash": "34bc22d2c2201372a2e02f8ebc392bfec7413673", "best_bid": "0.2", "best_ask": "0.23"}], "timestamp": "1769384660501", "event_type": "price_change"}}
{"_local_timestamp": "2026-01-25T23:44:21.003540+00:00", "data": {"market": "0x8db2651deb0ca894dfec7963ff43d747e6b203d853ea102ddaaf69272fcbd14e", "price_changes": [{"asset_id": "55723215967704727452199840811929823276351711374899127881856674926400394790108", "price": "0.256", "size": "0", "side": "BUY", "hash": "35b30d926ef18d8125d77916021bbab67dd6b637", "best_bid": "0.948", "best_ask": "0.962"}, {"asset_id": "59454703894867594337219596879618679187053555828199534311880631098862267050015", "price": "0.744", "size": "0", "side": "SELL", "hash": "004a9938836ca3897ea4407b094a21995e0f2318", "best_bid": "0.038", "best_ask": "0.052"}], "timestamp": "1769384660501", "event_type": "price_change"}}
{"_local_timestamp": "2026-01-25T23:44:21.594808+00:00", "data": {"market": "0x8db2651deb0ca894dfec7963ff43d747e6b203d853ea102ddaaf69272fcbd14e", "price_changes": [{"asset_id": "55723215967704727452199840811929823276351711374899127881856674926400394790108", "price": "0.258", "size": "2087", "side": "BUY", "hash": "5515b60caccf110b6b500b9eda97c828d1025386", "best_bid": "0.948", "best_ask": "0.962"}, {"asset_id": "59454703894867594337219596879618679187053555828199534311880631098862267050015", "price": "0.742", "size": "2087", "side": "SELL", "hash": "38c69e2bfabd9edfffc1958dec77776ae0f65c21", "best_bid": "0.038", "best_ask": "0.052"}], "timestamp": "1769384660895", "event_type": "price_change"}}
{"_local_timestamp": "2026-01-25T23:44:21.653800+00:00", "data": {"market": "0xb9223ddfda277ecf96cea52aba3d6a47e3bb001bf0173fb3e2145566c28e0c24", "price_changes": [{"asset_id": "57280055515157002497847996398372581077095661831629922834612019741255629878625", "price": "0.22", "size": "2058", "side": "BUY", "hash": "c9bbe8322ce8c05f7e69dccc0b893148645d8d94", "best_bid": "0.77", "best_ask": "0.8"}, {"asset_id": "64819280345421258482017346931579849092301023088943214992246376036314042237400", "price": "0.78", "size": "2058", "side": "SELL", "hash": "2a32fab8fa752dcf0b101fcf564be1a6ffd7ff9d", "best_bid": "0.2", "best_ask": "0.23"}], "timestamp": "1769384660908", "event_type": "price_change"}}
{"_local_timestamp": "2026-01-25T23:44:23.564472+00:00", "data": {"market": "0x4ddaff7ab33855ab7ed53f75ae4a331496028177f4bf0557eafe0fb83628332b", "price_changes": [{"asset_id": "25589742673068913841508219929281747394194738561317540491643768947357201371462", "price": "0.976", "size": "0", "side": "SELL", "hash": "703ad15558a67f3b941637f4ac36973925dadc82", "best_bid": "0.967", "best_ask": "0.979"}, {"asset_id": "25056163956965564455957738971346869740799169769422815261763807235324372823907", "price": "0.024", "size": "0", "side": "BUY", "hash": "f47773950b65342635799d2a98583d9f210ac819", "best_bid": "0.021", "best_ask": "0.033"}], "timestamp": "1769384663319", "event_type": "price_change"}}
{"_local_timestamp": "2026-01-25T23:44:23.586474+00:00", "data": {"market": "0x4ddaff7ab33855ab7ed53f75ae4a331496028177f4bf0557eafe0fb83628332b", "price_changes": [{"asset_id": "25056163956965564455957738971346869740799169769422815261763807235324372823907", "price": "0.025", "size": "435", "side": "BUY", "hash": "4104a198af2184bbe22ced90c8b0c3443ade90d6", "best_bid": "0.025", "best_ask": "0.033"}, {"asset_id": "25589742673068913841508219929281747394194738561317540491643768947357201371462", "price": "0.975", "size": "435", "side": "SELL", "hash": "f4f56a1eb50efc3b0928a18320e5810999b22e19", "best_bid": "0.967", "best_ask": "0.975"}], "timestamp": "1769384663347", "event_type": "price_change"}}
{"_local_timestamp": "2026-01-25T23:44:23.698661+00:00", "data": {"market": "0x07baddbeaa7f66706b84f167f835f3cc90782445ff36b2ea736c1c097f6ff537", "price_changes": [{"asset_id": "106820146733184719100966062623986655992997037363317463528901190592661638187355", "price": "0.34", "size": "424.99", "side": "BUY", "hash": "cf3bae4df02ad8f52cea89191f8832b37bd204ee", "best_bid": "0.36", "best_ask": "0.38"}, {"asset_id": "58198710311579915535691075580727536486537716969204598157134462435731312061441", "price": "0.66", "size": "424.99", "side": "SELL", "hash": "c92432688ac8a52615f5c74b0dbfbc1990e22ed1", "best_bid": "0.62", "best_ask": "0.64"}], "timestamp": "1769384663450", "event_type": "price_change"}}
{"_local_timestamp": "2026-01-25T23:44:23.703990+00:00", "data": {"market": "0xb9223ddfda277ecf96cea52aba3d6a47e3bb001bf0173fb3e2145566c28e0c24", "price_changes": [{"asset_id": "57280055515157002497847996398372581077095661831629922834612019741255629878625", "price": "0.76", "size": "524.99", "side": "BUY", "hash": "4c16ca8553878cb542d430b1cbedd3f61fa71dfc", "best_bid": "0.77", "best_ask": "0.8"}, {"asset_id": "64819280345421258482017346931579849092301023088943214992246376036314042237400", "price": "0.24", "size": "524.99", "side": "SELL", "hash": "27b12904c70065c0dc65a10679b5323c0084e61d", "best_bid": "0.2", "best_ask": "0.23"}], "timestamp": "1769384663454", "event_type": "price_change"}}
{"_local_timestamp": "2026-01-25T23:44:23.704368+00:00", "data": {"market": "0xb9223ddfda277ecf96cea52aba3d6a47e3bb001bf0173fb3e2145566c28e0c24", "price_changes": [{"asset_id": "57280055515157002497847996398372581077095661831629922834612019741255629878625", "price": "0.76", "size": "549.99", "side": "BUY", "hash": "a447940271bf61244f9056fddc359281eca2af49", "best_bid": "0.77", "best_ask": "0.8"}, {"asset_id": "64819280345421258482017346931579849092301023088943214992246376036314042237400", "price": "0.24", "size": "549.99", "side": "SELL", "hash": "2680647c2d677a05678acbadc69cef51196d21f8", "best_bid": "0.2", "best_ask": "0.23"}], "timestamp": "1769384663457", "event_type": "price_change"}}
{"_local_timestamp": "2026-01-25T23:44:23.734900+00:00", "data": {"market": "0xb9223ddfda277ecf96cea52aba3d6a47e3bb001bf0173fb3e2145566c28e0c24", "price_changes": [{"asset_id": "57280055515157002497847996398372581077095661831629922834612019741255629878625", "price": "0.76", "size": "574.99", "side": "BUY", "hash": "8d802648d2911c060a6aa17e461b01dbc5281272", "best_bid": "0.77", "best_ask": "0.8"}, {"asset_id": "64819280345421258482017346931579849092301023088943214992246376036314042237400", "price": "0.24", "size": "574.99", "side": "SELL", "hash": "37152631b86ba3381169c9a1a2c2d5a9c816fb09", "best_bid": "0.2", "best_ask": "0.23"}], "timestamp": "1769384663457", "event_type": "price_change"}}
{"_local_timestamp": "2026-01-25T23:44:23.735243+00:00", "data": {"market": "0x07baddbeaa7f66706b84f167f835f3cc90782445ff36b2ea736c1c097f6ff537", "price_changes": [{"asset_id": "106820146733184719100966062623986655992997037363317463528901190592661638187355", "price": "0.34", "size": "449.99", "side": "BUY", "hash": "a9d50d4ed3511de601babb52449c701fd41de132", "best_bid": "0.36", "best_ask": "0.38"}, {"asset_id": "58198710311579915535691075580727536486537716969204598157134462435731312061441", "price": "0.66", "size": "449.99", "side": "SELL", "hash": "a47dfefaf0c34b71773217f0db89b9d29e3cdb73", "best_bid": "0.62", "best_ask": "0.64"}], "timestamp": "1769384663465", "event_type": "price_change"}}
{"_local_timestamp": "2026-01-25T23:44:23.735505+00:00", "data": {"market": "0x8db2651deb0ca894dfec7963ff43d747e6b203d853ea102ddaaf69272fcbd14e", "price_changes": [{"asset_id": "55723215967704727452199840811929823276351711374899127881856674926400394790108", "price": "0.923", "size": "344.44", "side": "BUY", "hash": "81a34a9ba8c8a786d608a59d5845af2e5db182ee", "best_bid": "0.948", "best_ask": "0.962"}, {"asset_id": "59454703894867594337219596879618679187053555828199534311880631098862267050015", "price": "0.077", "size": "344.44", "side": "SELL", "hash": "788cb26ff5483deb65e6f92569e69d219049c799", "best_bid": "0.038", "best_ask": "0.052"}], "timestamp": "1769384663466", "event_type": "price_change"}}
{"_local_timestamp": "2026-01-25T23:44:23.735730+00:00", "data": {"market": "0x07baddbeaa7f66706b84f167f835f3cc90782445ff36b2ea736c1c097f6ff537", "price_changes": [{"asset_id": "106820146733184719100966062623986655992997037363317463528901190592661638187355", "price": "0.34", "size": "474.99", "side": "BUY", "hash": "e9ed325fd7161747f40750e9d5bef62fff3f06ac", "best_bid": "0.36", "best_ask": "0.38"}, {"asset_id": "58198710311579915535691075580727536486537716969204598157134462435731312061441", "price": "0.66", "size": "474.99", "side": "SELL", "hash": "3a8ce93174daa194824aa8b6c6b06a333f6efcf8", "best_bid": "0.62", "best_ask": "0.64"}], "timestamp": "1769384663471", "event_type": "price_change"}}
{"_local_timestamp": "2026-01-25T23:44:23.740479+00:00", "data": {"market": "0x512ced1584beb41cb6dacdaa92f5d67f8bee28f055ef63b251d20a446422ddaa", "price_changes": [{"asset_id": "105159270423598199664249261738928535905668234939484323704322364820483620754428", "price": "0.88", "size": "1831.99", "side": "BUY", "hash": "45ccc77f56917beb0318d271e4cb2282b67eae11", "best_bid": "0.9", "best_ask": "0.92"}, {"asset_id": "81498082395020979729835659110658786648105896152484850898743462024117016161425", "price": "0.12", "size": "1831.99", "side": "SELL", "hash": "3e591c545586d003c0a2b98c2acafaace515f412", "best_bid": "0.08", "best_ask": "0.1"}], "timestamp": "1769384663486", "event_type": "price_change"}}
{"_local_timestamp": "2026-01-25T23:44:23.869178+00:00", "data": {"market": "0x07baddbeaa7f66706b84f167f835f3cc90782445ff36b2ea736c1c097f6ff537", "price_changes": [{"asset_id": "106820146733184719100966062623986655992997037363317463528901190592661638187355", "price": "0.35", "size": "377.47", "side": "BUY", "hash": "64ab53f69c64912fe51e63c90488a773ad416268", "best_bid": "0.36", "best_ask": "0.38"}, {"asset_id": "58198710311579915535691075580727536486537716969204598157134462435731312061441", "price": "0.65", "size": "377.47", "side": "SELL", "hash": "cecf05a122cbfa0ce89e2e5a32fd1956c1dca40a", "best_bid": "0.62", "best_ask": "0.64"}], "timestamp": "1769384663488", "event_type": "price_change"}}
{"_local_timestamp": "2026-01-25T23:44:23.869498+00:00", "data": {"market": "0x8db2651deb0ca894dfec7963ff43d747e6b203d853ea102ddaaf69272fcbd14e", "price_changes": [{"asset_id": "55723215967704727452199840811929823276351711374899127881856674926400394790108", "price": "0.923", "size": "395.44", "side": "BUY", "hash": "9c7350e6592a8ac1e05652f8caeec1de4279a054", "best_bid": "0.948", "best_ask": "0.962"}, {"asset_id": "59454703894867594337219596879618679187053555828199534311880631098862267050015", "price": "0.077", "size": "395.44", "side": "SELL", "hash": "fc7697e4228d1586bdc7cbf425c09d0f08a22772", "best_bid": "0.038", "best_ask": "0.052"}], "timestamp": "1769384663488", "event_type": "price_change"}}
{"_local_timestamp": "2026-01-25T23:44:23.869759+00:00", "data": {"market": "0x512ced1584beb41cb6dacdaa92f5d67f8bee28f055ef63b251d20a446422ddaa", "price_changes": [{"asset_id": "105159270423598199664249261738928535905668234939484323704322364820483620754428", "price": "0.88", "size": "1856.99", "side": "BUY", "hash": "8b939a7ba658149aa49e6d5a6f0d5840d8083909", "best_bid": "0.9", "best_ask": "0.92"}, {"asset_id": "81498082395020979729835659110658786648105896152484850898743462024117016161425", "price": "0.12", "size": "1856.99", "side": "SELL", "hash": "b097b8868e9faa2a10d0c931b4c619893c7b2630", "best_bid": "0.08", "best_ask": "0.1"}], "timestamp": "1769384663496", "event_type": "price_change"}}
{"_local_timestamp": "2026-01-25T23:44:23.870012+00:00", "data": {"market": "0x512ced1584beb41cb6dacdaa92f5d67f8bee28f055ef63b251d20a446422ddaa", "price_changes": [{"asset_id": "105159270423598199664249261738928535905668234939484323704322364820483620754428", "price": "0.88", "size": "1881.99", "side": "BUY", "hash": "2cb26426c9f25510a4e8a01c78590c3959c7f626", "best_bid": "0.9", "best_ask": "0.92"}, {"asset_id": "81498082395020979729835659110658786648105896152484850898743462024117016161425", "price": "0.12", "size": "1881.99", "side": "SELL", "hash": "2bbcc4ace1c6d7811dcfd86b9b5a62a783127cb8", "best_bid": "0.08", "best_ask": "0.1"}], "timestamp": "1769384663499", "event_type": "price_change"}}
{"_local_timestamp": "2026-01-25T23:44:23.892306+00:00", "data": {"market": "0x8db2651deb0ca894dfec7963ff43d747e6b203d853ea102ddaaf69272fcbd14e", "price_changes": [{"asset_id": "55723215967704727452199840811929823276351711374899127881856674926400394790108", "price": "0.923", "size": "446.44", "side": "BUY", "hash": "98b8e3a4e1a771e3aea2b4ccea87ec10fac7d1db", "best_bid": "0.948", "best_ask": "0.962"}, {"asset_id": "59454703894867594337219596879618679187053555828199534311880631098862267050015", "price": "0.077", "size": "446.44", "side": "SELL", "hash": "00d32f555efd561035a88d73c8a85ac232de200b", "best_bid": "0.038", "best_ask": "0.052"}], "timestamp": "1769384663505", "event_type": "price_change"}}
{"_local_timestamp": "2026-01-25T23:44:23.892703+00:00", "data": {"market": "0x07baddbeaa7f66706b84f167f835f3cc90782445ff36b2ea736c1c097f6ff537", "price_changes": [{"asset_id": "106820146733184719100966062623986655992997037363317463528901190592661638187355", "price": "0.35", "size": "467.47", "side": "BUY", "hash": "e9ac49b716a319ac180c5bba8df0f9f45362ba2e", "best_bid": "0.36", "best_ask": "0.38"}, {"asset_id": "58198710311579915535691075580727536486537716969204598157134462435731312061441", "price": "0.65", "size": "467.47", "side": "SELL", "hash": "f04c9043bcd2c76190a0ed3104fcd3dfbef6da5f", "best_bid": "0.62", "best_ask": "0.64"}], "timestamp": "1769384663514", "event_type": "price_change"}}
{"_local_timestamp": "2026-01-25T23:44:23.892971+00:00", "data": {"market": "0x512ced1584beb41cb6dacdaa92f5d67f8bee28f055ef63b251d20a446422ddaa", "price_changes": [{"asset_id": "105159270423598199664249261738928535905668234939484323704322364820483620754428", "price": "0.85", "size": "0", "side": "BUY", "hash": "142debfd699a8328732395cd6ad09a3441578636", "best_bid": "0.9", "best_ask": "0.92"}, {"asset_id": "81498082395020979729835659110658786648105896152484850898743462024117016161425", "price": "0.15", "size": "0", "side": "SELL", "hash": "d73e9f1caabc0dad719d227606ba9625d00648ab", "best_bid": "0.08", "best_ask": "0.1"}], "timestamp": "1769384663522", "event_type": "price_change"}}
{"_local_timestamp": "2026-01-25T23:44:23.893215+00:00", "data": {"market": "0x512ced1584beb41cb6dacdaa92f5d67f8bee28f055ef63b251d20a446422ddaa", "price_changes": [{"asset_id": "105159270423598199664249261738928535905668234939484323704322364820483620754428", "price": "0.68", "size": "30", "side": "BUY", "hash": "6bc7d5ba4496bcd741c4c6dab217d4a320d1fe97", "best_bid": "0.9", "best_ask": "0.92"}, {"asset_id": "81498082395020979729835659110658786648105896152484850898743462024117016161425", "price": "0.32", "size": "30", "side": "SELL", "hash": "92406a4c04a9113c011924348db639fa02f16021", "best_bid": "0.08", "best_ask": "0.1"}], "timestamp": "1769384663621", "event_type": "price_change"}}
{"_local_timestamp": "2026-01-25T23:44:24.013186+00:00", "data": {"market": "0x4ddaff7ab33855ab7ed53f75ae4a331496028177f4bf0557eafe0fb83628332b", "price_changes": [{"asset_id": "25589742673068913841508219929281747394194738561317540491643768947357201371462", "price": "0.978", "size": "114.77", "side": "SELL", "hash": "0e9462721b53d8a28b08a1412c2cfbd43e22d2c2", "best_bid": "0.967", "best_ask": "0.975"}, {"asset_id": "25056163956965564455957738971346869740799169769422815261763807235324372823907", "price": "0.022", "size": "114.77", "side": "BUY", "hash": "8ca23e0719e5c044c1887663bd4d068b0825d001", "best_bid": "0.025", "best_ask": "0.033"}], "timestamp": "1769384663734", "event_type": "price_change"}}
{"_local_timestamp": "2026-01-25T23:44:24.778788+00:00", "data": {"market": "0x4ddaff7ab33855ab7ed53f75ae4a331496028177f4bf0557eafe0fb83628332b", "price_changes": [{"asset_id": "25056163956965564455957738971346869740799169769422815261763807235324372823907", "price": "0.025", "size": "0", "side": "BUY", "hash": "8e3a09f5237c47a631babc488784de0285eea008", "best_bid": "0.022", "best_ask": "0.033"}, {"asset_id": "25589742673068913841508219929281747394194738561317540491643768947357201371462", "price": "0.975", "size": "0", "side": "SELL", "hash": "10bf97138c65e5c692423bdfb30509017cdb966b", "best_bid": "0.967", "best_ask": "0.978"}], "timestamp": "1769384664513", "event_type": "price_change"}}
{"_local_timestamp": "2026-01-25T23:44:24.820033+00:00", "data": {"market": "0x4ddaff7ab33855ab7ed53f75ae4a331496028177f4bf0557eafe0fb83628332b", "price_changes": [{"asset_id": "25056163956965564455957738971346869740799169769422815261763807235324372823907", "price": "0.023", "size": "435", "side": "BUY", "hash": "b13f08d60eff04375239bd472916ddce5a4f7163", "best_bid": "0.023", "best_ask": "0.033"}, {"asset_id": "25589742673068913841508219929281747394194738561317540491643768947357201371462", "price": "0.977", "size": "435", "side": "SELL", "hash": "1046b369838c8bf091ee047e2b15cfb858111777", "best_bid": "0.967", "best_ask": "0.977"}], "timestamp": "1769384664541", "event_type": "price_change"}}
{"_local_timestamp": "2026-01-25T23:44:24.887919+00:00", "data": {"market": "0xb9223ddfda277ecf96cea52aba3d6a47e3bb001bf0173fb3e2145566c28e0c24", "price_changes": [{"asset_id": "57280055515157002497847996398372581077095661831629922834612019741255629878625", "price": "0.76", "size": "549.99", "side": "BUY", "hash": "c90f6c53a008244a8a0c5da55007978e6af725b5", "best_bid": "0.77", "best_ask": "0.8"}, {"asset_id": "64819280345421258482017346931579849092301023088943214992246376036314042237400", "price": "0.24", "size": "549.99", "side": "SELL", "hash": "dfbf50efdd4b0ad0c2488b9afaacfd2cd605415c", "best_bid": "0.2", "best_ask": "0.23"}], "timestamp": "1769384664617", "event_type": "price_change"}}
{"_local_timestamp": "2026-01-25T23:44:24.888250+00:00", "data": {"market": "0x07baddbeaa7f66706b84f167f835f3cc90782445ff36b2ea736c1c097f6ff537", "price_changes": [{"asset_id": "106820146733184719100966062623986655992997037363317463528901190592661638187355", "price": "0.34", "size": "449.99", "side": "BUY", "hash": "1585e6eb94e4d8b95aac78f324014255eefd2e88", "best_bid": "0.36", "best_ask": "0.38"}, {"asset_id": "58198710311579915535691075580727536486537716969204598157134462435731312061441", "price": "0.66", "size": "449.99", "side": "SELL", "hash": "bb0201d41dd06c917047c2efe684ed4274457eb2", "best_bid": "0.62", "best_ask": "0.64"}], "timestamp": "1769384664619", "event_type": "price_change"}}
{"_local_timestamp": "2026-01-25T23:44:24.888516+00:00", "data": {"market": "0x07baddbeaa7f66706b84f167f835f3cc90782445ff36b2ea736c1c097f6ff537", "price_changes": [{"asset_id": "106820146733184719100966062623986655992997037363317463528901190592661638187355", "price": "0.34", "size": "424.99", "side": "BUY", "hash": "c156ad393e0d68cef90a94c0e8904a12e7407dee", "best_bid": "0.36", "best_ask": "0.38"}, {"asset_id": "58198710311579915535691075580727536486537716969204598157134462435731312061441", "price": "0.66", "size": "424.99", "side": "SELL", "hash": "3b90d4e23c17c6b1263b02018914277daae1371b", "best_bid": "0.62", "best_ask": "0.64"}], "timestamp": "1769384664620", "event_type": "price_change"}}
{"_local_timestamp": "2026-01-25T23:44:24.896159+00:00", "data": {"market": "0x07baddbeaa7f66706b84f167f835f3cc90782445ff36b2ea736c1c097f6ff537", "price_changes": [{"asset_id": "106820146733184719100966062623986655992997037363317463528901190592661638187355", "price": "0.34", "size": "399.99", "side": "BUY", "hash": "0b504e22655b11a7ca285d0c379fe13a0ade47e9", "best_bid": "0.36", "best_ask": "0.38"}, {"asset_id": "58198710311579915535691075580727536486537716969204598157134462435731312061441", "price": "0.66", "size": "399.99", "side": "SELL", "hash": "d3df9396e9330d9974216ccde92dbe3307850f49", "best_bid": "0.62", "best_ask": "0.64"}], "timestamp": "1769384664622", "event_type": "price_change"}}
{"_local_timestamp": "2026-01-25T23:44:24.896495+00:00", "data": {"market": "0xb9223ddfda277ecf96cea52aba3d6a47e3bb001bf0173fb3e2145566c28e0c24", "price_changes": [{"asset_id": "57280055515157002497847996398372581077095661831629922834612019741255629878625", "price": "0.76", "size": "524.99", "side": "BUY", "hash": "769709880d6139d6e19ee8d8d98d0d495d3809b8", "best_bid": "0.77", "best_ask": "0.8"}, {"asset_id": "64819280345421258482017346931579849092301023088943214992246376036314042237400", "price": "0.24", "size": "524.99", "side": "SELL", "hash": "eaf0cf40d9dcd4e8384c8e02c302354a8532d467", "best_bid": "0.2", "best_ask": "0.23"}], "timestamp": "1769384664627", "event_type": "price_change"}}
{"_local_timestamp": "2026-01-25T23:44:24.896751+00:00", "data": {"market": "0x512ced1584beb41cb6dacdaa92f5d67f8bee28f055ef63b251d20a446422ddaa", "price_changes": [{"asset_id": "105159270423598199664249261738928535905668234939484323704322364820483620754428", "price": "0.88", "size": "1856.99", "side": "BUY", "hash": "a0f1a5f61401a75b0521b5b91f7058d3eabf3662", "best_bid": "0.9", "best_ask": "0.92"}, {"asset_id": "81498082395020979729835659110658786648105896152484850898743462024117016161425", "price": "0.12", "size": "1856.99", "side": "SELL", "hash": "95a8d95f72535cb8f38dab0fd7d1bdfff29412d0", "best_bid": "0.08", "best_ask": "0.1"}], "timestamp": "1769384664628", "event_type": "price_change"}}
{"_local_timestamp": "2026-01-25T23:44:24.896990+00:00", "data": {"market": "0x8db2651deb0ca894dfec7963ff43d747e6b203d853ea102ddaaf69272fcbd14e", "price_changes": [{"asset_id": "55723215967704727452199840811929823276351711374899127881856674926400394790108", "price": "0.923", "size": "395.44", "side": "BUY", "hash": "567dfadbf6e50f1178c262325a6f6bc81019aee2", "best_bid": "0.948", "best_ask": "0.962"}, {"asset_id": "59454703894867594337219596879618679187053555828199534311880631098862267050015", "price": "0.077", "size": "395.44", "side": "SELL", "hash": "b2f0c332bfd46a82632904b1dbc2b6f61df013ca", "best_bid": "0.038", "best_ask": "0.052"}], "timestamp": "1769384664629", "event_type": "price_change"}}
{"_local_timestamp": "2026-01-25T23:44:24.914765+00:00", "data": {"market": "0xb9223ddfda277ecf96cea52aba3d6a47e3bb001bf0173fb3e2145566c28e0c24", "price_changes": [{"asset_id": "57280055515157002497847996398372581077095661831629922834612019741255629878625", "price": "0.76", "size": "499.99", "side": "BUY", "hash": "4099838d9c27f803259f73c19b3db582ffd05297", "best_bid": "0.77", "best_ask": "0.8"}, {"asset_id": "64819280345421258482017346931579849092301023088943214992246376036314042237400", "price": "0.24", "size": "499.99", "side": "SELL", "hash": "02667a2001bfd158d58fc6e17407207ce6330048", "best_bid": "0.2", "best_ask": "0.23"}], "timestamp": "1769384664651", "event_type": "price_change"}}
{"_local_timestamp": "2026-01-25T23:44:24.932091+00:00", "data": {"market": "0x512ced1584beb41cb6dacdaa92f5d67f8bee28f055ef63b251d20a446422ddaa", "price_changes": [{"asset_id": "105159270423598199664249261738928535905668234939484323704322364820483620754428", "price": "0.88", "size": "1831.99", "side": "BUY", "hash": "adac91bffcce54ecb0cdf6fdf40738bc4093cd00", "best_bid": "0.9", "best_ask": "0.92"}, {"asset_id": "81498082395020979729835659110658786648105896152484850898743462024117016161425", "price": "0.12", "size": "1831.99", "side": "SELL", "hash": "2c1f02f0c7c10301efb9bf506dfd0859d8f6aa23", "best_bid": "0.08", "best_ask": "0.1"}], "timestamp": "1769384664669", "event_type": "price_change"}}
{"_local_timestamp": "2026-01-25T23:44:24.932510+00:00", "data": {"market": "0x8db2651deb0ca894dfec7963ff43d747e6b203d853ea102ddaaf69272fcbd14e", "price_changes": [{"asset_id": "55723215967704727452199840811929823276351711374899127881856674926400394790108", "price": "0.923", "size": "344.44", "side": "BUY", "hash": "eb7e1b7337594723e1b10b52eb273abfdc4cd8a8", "best_bid": "0.948", "best_ask": "0.962"}, {"asset_id": "59454703894867594337219596879618679187053555828199534311880631098862267050015", "price": "0.077", "size": "344.44", "side": "SELL", "hash": "a45efd11827497cf50ed4b9b35be87280b4c547a", "best_bid": "0.038", "best_ask": "0.052"}], "timestamp": "1769384664670", "event_type": "price_change"}}
{"_local_timestamp": "2026-01-25T23:44:25.112528+00:00", "data": {"market": "0x512ced1584beb41cb6dacdaa92f5d67f8bee28f055ef63b251d20a446422ddaa", "price_changes": [{"asset_id": "105159270423598199664249261738928535905668234939484323704322364820483620754428", "price": "0.88", "size": "1806.99", "side": "BUY", "hash": "b6c7fa058933175f71072095168c44d88b9fec53", "best_bid": "0.9", "best_ask": "0.92"}, {"asset_id": "81498082395020979729835659110658786648105896152484850898743462024117016161425", "price": "0.12", "size": "1806.99", "side": "SELL", "hash": "c274bc0b54ed2d505a713d43a584e073269414a4", "best_bid": "0.08", "best_ask": "0.1"}], "timestamp": "1769384664672", "event_type": "price_change"}}
{"_local_timestamp": "2026-01-25T23:44:25.112902+00:00", "data": {"market": "0x8db2651deb0ca894dfec7963ff43d747e6b203d853ea102ddaaf69272fcbd14e", "price_changes": [{"asset_id": "55723215967704727452199840811929823276351711374899127881856674926400394790108", "price": "0.923", "size": "293.44", "side": "BUY", "hash": "02ca09a50e9008ed7a68f64b0c8bf2e1a00c2b04", "best_bid": "0.948", "best_ask": "0.962"}, {"asset_id": "59454703894867594337219596879618679187053555828199534311880631098862267050015", "price": "0.077", "size": "293.44", "side": "SELL", "hash": "e3da9f16492aca8d45949eee306f55d4efce8b44", "best_bid": "0.038", "best_ask": "0.052"}], "timestamp": "1769384664673", "event_type": "price_change"}}
{"_local_timestamp": "2026-01-25T23:44:29.274645+00:00", "data": {"market": "0xb9223ddfda277ecf96cea52aba3d6a47e3bb001bf0173fb3e2145566c28e0c24", "price_changes": [{"asset_id": "57280055515157002497847996398372581077095661831629922834612019741255629878625", "price": "0.75", "size": "114", "side": "BUY", "hash": "b2f297ad9772d67bcbfce05a774ff0546be18e41", "best_bid": "0.77", "best_ask": "0.8"}, {"asset_id": "64819280345421258482017346931579849092301023088943214992246376036314042237400", "price": "0.25", "size": "114", "side": "SELL", "hash": "2c4f5f695d7e4cdbb0f19ea88e547376a69973e7", "best_bid": "0.2", "best_ask": "0.23"}], "timestamp": "1769384669005", "event_type": "price_change"}}
{"_local_timestamp": "2026-01-25T23:44:29.568700+00:00", "data": {"market": "0x4ddaff7ab33855ab7ed53f75ae4a331496028177f4bf0557eafe0fb83628332b", "price_changes": [{"asset_id": "25589742673068913841508219929281747394194738561317540491643768947357201371462", "price": "0.978", "size": "0", "side": "SELL", "hash": "4c125ed3ff8d11fd3f256e821bd80214c69ea634", "best_bid": "0.967", "best_ask": "0.977"}, {"asset_id": "25056163956965564455957738971346869740799169769422815261763807235324372823907", "price": "0.022", "size": "0", "side": "BUY", "hash": "9f536a755443494c463c6355e8087e38398de647", "best_bid": "0.023", "best_ask": "0.033"}], "timestamp": "1769384669307", "event_type": "price_change"}}
{"_local_timestamp": "2026-01-25T23:44:30.037043+00:00", "data": {"market": "0x4ddaff7ab33855ab7ed53f75ae4a331496028177f4bf0557eafe0fb83628332b", "price_changes": [{"asset_id": "25589742673068913841508219929281747394194738561317540491643768947357201371462", "price": "0.976", "size": "114.77", "side": "SELL", "hash": "4207bf2335ddc5f8234e83f1c52a30db87d55055", "best_bid": "0.967", "best_ask": "0.976"}, {"asset_id": "25056163956965564455957738971346869740799169769422815261763807235324372823907", "price": "0.024", "size": "114.77", "side": "BUY", "hash": "64ba3364b06c695c670b4415f57c4c4e02332efa", "best_bid": "0.024", "best_ask": "0.033"}], "timestamp": "1769384669766", "event_type": "price_change"}}
{"_local_timestamp": "2026-01-25T23:44:30.931938+00:00", "data": {"market": "0x4ddaff7ab33855ab7ed53f75ae4a331496028177f4bf0557eafe0fb83628332b", "price_changes": [{"asset_id": "25056163956965564455957738971346869740799169769422815261763807235324372823907", "price": "0.023", "size": "0", "side": "BUY", "hash": "bbc639988ce999a3abcae72f0056d3421ff49646", "best_bid": "0.024", "best_ask": "0.033"}, {"asset_id": "25589742673068913841508219929281747394194738561317540491643768947357201371462", "price": "0.977", "size": "0", "side": "SELL", "hash": "7a0c9d77943fde9eef1b3f2ac7dd00031d1ad89f", "best_bid": "0.967", "best_ask": "0.976"}], "timestamp": "1769384669792", "event_type": "price_change"}}
{"_local_timestamp": "2026-01-25T23:44:35.567500+00:00", "data": {"market": "0x4ddaff7ab33855ab7ed53f75ae4a331496028177f4bf0557eafe0fb83628332b", "price_changes": [{"asset_id": "25589742673068913841508219929281747394194738561317540491643768947357201371462", "price": "0.976", "size": "0", "side": "SELL", "hash": "1eebd17ab8d82e5a283437e0da9170d1b5c9f478", "best_bid": "0.967", "best_ask": "0.979"}, {"asset_id": "25056163956965564455957738971346869740799169769422815261763807235324372823907", "price": "0.024", "size": "0", "side": "BUY", "hash": "b2bb68f0291ad834b5b169223c499d59ee8e74ad", "best_bid": "0.021", "best_ask": "0.033"}], "timestamp": "1769384675286", "event_type": "price_change"}}
{"_local_timestamp": "2026-01-25T23:44:35.582629+00:00", "data": {"market": "0x4ddaff7ab33855ab7ed53f75ae4a331496028177f4bf0557eafe0fb83628332b", "price_changes": [{"asset_id": "25056163956965564455957738971346869740799169769422815261763807235324372823907", "price": "0.025", "size": "435", "side": "BUY", "hash": "a38f9f3a07ff58687439737ef97ce02b550978cb", "best_bid": "0.025", "best_ask": "0.033"}, {"asset_id": "25589742673068913841508219929281747394194738561317540491643768947357201371462", "price": "0.975", "size": "435", "side": "SELL", "hash": "f50fdd59354389219499b10be5e8cfb9f4546b8b", "best_bid": "0.967", "best_ask": "0.975"}], "timestamp": "1769384675313", "event_type": "price_change"}}
{"_local_timestamp": "2026-01-25T23:44:35.702138+00:00", "data": {"market": "0xb9223ddfda277ecf96cea52aba3d6a47e3bb001bf0173fb3e2145566c28e0c24", "price_changes": [{"asset_id": "57280055515157002497847996398372581077095661831629922834612019741255629878625", "price": "0.76", "size": "524.99", "side": "BUY", "hash": "8d131bcba51a4fcd9fbc9bbd1a29e8c51fdf8c03", "best_bid": "0.77", "best_ask": "0.8"}, {"asset_id": "64819280345421258482017346931579849092301023088943214992246376036314042237400", "price": "0.24", "size": "524.99", "side": "SELL", "hash": "45fe614f1f9dd1cbf64cba081f7f4ac70737bfdb", "best_bid": "0.2", "best_ask": "0.23"}], "timestamp": "1769384675419", "event_type": "price_change"}}
{"_local_timestamp": "2026-01-25T23:44:35.702565+00:00", "data": {"market": "0x512ced1584beb41cb6dacdaa92f5d67f8bee28f055ef63b251d20a446422ddaa", "price_changes": [{"asset_id": "105159270423598199664249261738928535905668234939484323704322364820483620754428", "price": "0.88", "size": "1831.99", "side": "BUY", "hash": "170bc9134332db000b36c40a3dfbcc6e129519ea", "best_bid": "0.9", "best_ask": "0.92"}, {"asset_id": "81498082395020979729835659110658786648105896152484850898743462024117016161425", "price": "0.12", "size": "1831.99", "side": "SELL", "hash": "e0a69186f17c5fc3b67613b17848d268bef55143", "best_bid": "0.08", "best_ask": "0.1"}], "timestamp": "1769384675424", "event_type": "price_change"}}
{"_local_timestamp": "2026-01-25T23:44:35.706129+00:00", "data": {"market": "0x512ced1584beb41cb6dacdaa92f5d67f8bee28f055ef63b251d20a446422ddaa", "price_changes": [{"asset_id": "105159270423598199664249261738928535905668234939484323704322364820483620754428", "price": "0.84", "size": "20", "side": "BUY", "hash": "da4cf77dc929a2ccfccb556cb59334bb0678727f", "best_bid": "0.9", "best_ask": "0.92"}, {"asset_id": "81498082395020979729835659110658786648105896152484850898743462024117016161425", "price": "0.16", "size": "20", "side": "SELL", "hash": "5d2f0fb776acba90760ac293473855169ae0dd86", "best_bid": "0.08", "best_ask": "0.1"}], "timestamp": "1769384675427", "event_type": "price_change"}}
{"_local_timestamp": "2026-01-25T23:44:35.706410+00:00", "data": {"market": "0x07baddbeaa7f66706b84f167f835f3cc90782445ff36b2ea736c1c097f6ff537", "price_changes": [{"asset_id": "106820146733184719100966062623986655992997037363317463528901190592661638187355", "price": "0.34", "size": "424.99", "side": "BUY", "hash": "7a361a1138357c06093959fff369f2e9bcfebc05", "best_bid": "0.36", "best_ask": "0.38"}, {"asset_id": "58198710311579915535691075580727536486537716969204598157134462435731312061441", "price": "0.66", "size": "424.99", "side": "SELL", "hash": "6e98be0906275cca295771225d3f9855fa31c17b", "best_bid": "0.62", "best_ask": "0.64"}], "timestamp": "1769384675427", "event_type": "price_change"}}
{"_local_timestamp": "2026-01-25T23:44:35.706661+00:00", "data": {"market": "0xb9223ddfda277ecf96cea52aba3d6a47e3bb001bf0173fb3e2145566c28e0c24", "price_changes": [{"asset_id": "57280055515157002497847996398372581077095661831629922834612019741255629878625", "price": "0.76", "size": "549.99", "side": "BUY", "hash": "d4be9d133f2823d5045f304bc723a81f6cd132bb", "best_bid": "0.77", "best_ask": "0.8"}, {"asset_id": "64819280345421258482017346931579849092301023088943214992246376036314042237400", "price": "0.24", "size": "549.99", "side": "SELL", "hash": "327dd6a89cfddaff9925e98c01bb96574e6433e2", "best_bid": "0.2", "best_ask": "0.23"}], "timestamp": "1769384675428", "event_type": "price_change"}}
{"_local_timestamp": "2026-01-25T23:44:35.721876+00:00", "data": {"market": "0x512ced1584beb41cb6dacdaa92f5d67f8bee28f055ef63b251d20a446422ddaa", "price_changes": [{"asset_id": "105159270423598199664249261738928535905668234939484323704322364820483620754428", "price": "0.88", "size": "1856.99", "side": "BUY", "hash": "55085a7de2976e2745e9ad047178618dfbfa4d82", "best_bid": "0.9", "best_ask": "0.92"}, {"asset_id": "81498082395020979729835659110658786648105896152484850898743462024117016161425", "price": "0.12", "size": "1856.99", "side": "SELL", "hash": "731287f5d389438471e197833373c90dbb56b9f3", "best_bid": "0.08", "best_ask": "0.1"}], "timestamp": "1769384675431", "event_type": "price_change"}}
{"_local_timestamp": "2026-01-25T23:44:35.722155+00:00", "data": {"market": "0x8db2651deb0ca894dfec7963ff43d747e6b203d853ea102ddaaf69272fcbd14e", "price_changes": [{"asset_id": "55723215967704727452199840811929823276351711374899127881856674926400394790108", "price": "0.923", "size": "344.44", "side": "BUY", "hash": "4a2cf7e6fa468b3b1c9b4e4ff54ca1e5c72d3a1e", "best_bid": "0.948", "best_ask": "0.962"}, {"asset_id": "59454703894867594337219596879618679187053555828199534311880631098862267050015", "price": "0.077", "size": "344.44", "side": "SELL", "hash": "c5a91081192f89b6c04fc5bb90de682765ce2f7b", "best_bid": "0.038", "best_ask": "0.052"}], "timestamp": "1769384675431", "event_type": "price_change"}}
{"_local_timestamp": "2026-01-25T23:44:35.729834+00:00", "data": {"market": "0x8db2651deb0ca894dfec7963ff43d747e6b203d853ea102ddaaf69272fcbd14e", "price_changes": [{"asset_id": "55723215967704727452199840811929823276351711374899127881856674926400394790108", "price": "0.923", "size": "395.44", "side": "BUY", "hash": "fc1b5ac4fbac2706d6f1a54786bb4748285699ff", "best_bid": "0.948", "best_ask": "0.962"}, {"asset_id": "59454703894867594337219596879618679187053555828199534311880631098862267050015", "price": "0.077", "size": "395.44", "side": "SELL", "hash": "03328957cabc3a036da433ee0d2221bda77bf265", "best_bid": "0.038", "best_ask": "0.052"}], "timestamp": "1769384675438", "event_type": "price_change"}}
{"_local_timestamp": "2026-01-25T23:44:36.030635+00:00", "data": {"market": "0x8db2651deb0ca894dfec7963ff43d747e6b203d853ea102ddaaf69272fcbd14e", "price_changes": [{"asset_id": "55723215967704727452199840811929823276351711374899127881856674926400394790108", "price": "0.923", "size": "446.44", "side": "BUY", "hash": "c8c105a0bf3d34fc8574ac77f93ff52413a41bee", "best_bid": "0.948", "best_ask": "0.962"}, {"asset_id": "59454703894867594337219596879618679187053555828199534311880631098862267050015", "price": "0.077", "size": "446.44", "side": "SELL", "hash": "833e41f4a95605b2aa94870c67197bc00bc0617a", "best_bid": "0.038", "best_ask": "0.052"}], "timestamp": "1769384675440", "event_type": "price_change"}}
{"_local_timestamp": "2026-01-25T23:44:36.030970+00:00", "data": {"market": "0x07baddbeaa7f66706b84f167f835f3cc90782445ff36b2ea736c1c097f6ff537", "price_changes": [{"asset_id": "106820146733184719100966062623986655992997037363317463528901190592661638187355", "price": "0.34", "size": "449.99", "side": "BUY", "hash": "80764cafb6d87f4583e9b0825f41d29804a8ac63", "best_bid": "0.36", "best_ask": "0.38"}, {"asset_id": "58198710311579915535691075580727536486537716969204598157134462435731312061441", "price": "0.66", "size": "449.99", "side": "SELL", "hash": "0411ab4c55f50d3a2348a663c2d1731e4cf34d8d", "best_bid": "0.62", "best_ask": "0.64"}], "timestamp": "1769384675441", "event_type": "price_change"}}
{"_local_timestamp": "2026-01-25T23:44:36.413224+00:00", "data": {"market": "0xb9223ddfda277ecf96cea52aba3d6a47e3bb001bf0173fb3e2145566c28e0c24", "price_changes": [{"asset_id": "57280055515157002497847996398372581077095661831629922834612019741255629878625", "price": "0.76", "size": "574.99", "side": "BUY", "hash": "d0bf6700090754de63d52eb6df3bf6b6c57d3ac1", "best_bid": "0.77", "best_ask": "0.8"}, {"asset_id": "64819280345421258482017346931579849092301023088943214992246376036314042237400", "price": "0.24", "size": "574.99", "side": "SELL", "hash": "c399f20716161b825812f7fea5240409cf2abb4c", "best_bid": "0.2", "best_ask": "0.23"}], "timestamp": "1769384675443", "event_type": "price_change"}}
{"_local_timestamp": "2026-01-25T23:44:36.413575+00:00", "data": {"market": "0x07baddbeaa7f66706b84f167f835f3cc90782445ff36b2ea736c1c097f6ff537", "price_changes": [{"asset_id": "106820146733184719100966062623986655992997037363317463528901190592661638187355", "price": "0.34", "size": "474.99", "side": "BUY", "hash": "a44b3604bab676ba4df2e3477f64491f4161f887", "best_bid": "0.36", "best_ask": "0.38"}, {"asset_id": "58198710311579915535691075580727536486537716969204598157134462435731312061441", "price": "0.66", "size": "474.99", "side": "SELL", "hash": "f50d5c07a3b764fd17ac8bc5ff542c0dfb9c408a", "best_bid": "0.62", "best_ask": "0.64"}], "timestamp": "1769384675455", "event_type": "price_change"}}
{"_local_timestamp": "2026-01-25T23:44:36.413812+00:00", "data": {"market": "0x512ced1584beb41cb6dacdaa92f5d67f8bee28f055ef63b251d20a446422ddaa", "price_changes": [{"asset_id": "105159270423598199664249261738928535905668234939484323704322364820483620754428", "price": "0.88", "size": "1881.99", "side": "BUY", "hash": "6d76050f73260ca700e02120ea4e5cafa3d54af8", "best_bid": "0.9", "best_ask": "0.92"}, {"asset_id": "81498082395020979729835659110658786648105896152484850898743462024117016161425", "price": "0.12", "size": "1881.99", "side": "SELL", "hash": "8d96cd55356735389f10af792db4d31492a40ca3", "best_bid": "0.08", "best_ask": "0.1"}], "timestamp": "1769384675469", "event_type": "price_change"}}
{"_local_timestamp": "2026-01-25T23:44:36.414117+00:00", "data": {"market": "0x4ddaff7ab33855ab7ed53f75ae4a331496028177f4bf0557eafe0fb83628332b", "price_changes": [{"asset_id": "25589742673068913841508219929281747394194738561317540491643768947357201371462", "price": "0.978", "size": "114.77", "side": "SELL", "hash": "9f1e1006e4f59358dbdc8ca7225e4ecc95756bfc", "best_bid": "0.967", "best_ask": "0.975"}, {"asset_id": "25056163956965564455957738971346869740799169769422815261763807235324372823907", "price": "0.022", "size": "114.77", "side": "BUY", "hash": "26a9638ffee1f845edcddce323ad66405cede332", "best_bid": "0.025", "best_ask": "0.033"}], "timestamp": "1769384675865", "event_type": "price_change"}}
{"_local_timestamp": "2026-01-25T23:44:37.181143+00:00", "data": {"market": "0x4ddaff7ab33855ab7ed53f75ae4a331496028177f4bf0557eafe0fb83628332b", "price_changes": [{"asset_id": "25056163956965564455957738971346869740799169769422815261763807235324372823907", "price": "0.025", "size": "0", "side": "BUY", "hash": "90db79a27dc0e7f1787423b053db26d58f6f7a73", "best_bid": "0.022", "best_ask": "0.033"}, {"asset_id": "25589742673068913841508219929281747394194738561317540491643768947357201371462", "price": "0.975", "size": "0", "side": "SELL", "hash": "602997d03196c322607c5d27e9f070c0360b3a92", "best_bid": "0.967", "best_ask": "0.978"}], "timestamp": "1769384676513", "event_type": "price_change"}}
{"_local_timestamp": "2026-01-25T23:44:37.181604+00:00", "data": {"market": "0x4ddaff7ab33855ab7ed53f75ae4a331496028177f4bf0557eafe0fb83628332b", "price_changes": [{"asset_id": "25056163956965564455957738971346869740799169769422815261763807235324372823907", "price": "0.023", "size": "435", "side": "BUY", "hash": "8b908b546e9571c1c249bafb47a312db58ea6604", "best_bid": "0.023", "best_ask": "0.033"}, {"asset_id": "25589742673068913841508219929281747394194738561317540491643768947357201371462", "price": "0.977", "size": "435", "side": "SELL", "hash": "fc98eb24b93a617913e02a340b3b62837bbe8112", "best_bid": "0.967", "best_ask": "0.977"}], "timestamp": "1769384676541", "event_type": "price_change"}}
{"_local_timestamp": "2026-01-25T23:44:37.181847+00:00", "data": {"market": "0xb9223ddfda277ecf96cea52aba3d6a47e3bb001bf0173fb3e2145566c28e0c24", "price_changes": [{"asset_id": "57280055515157002497847996398372581077095661831629922834612019741255629878625", "price": "0.76", "size": "549.99", "side": "BUY", "hash": "e649aadff7bb0e5f3f7b097a3cf6b303df3e2d19", "best_bid": "0.77", "best_ask": "0.8"}, {"asset_id": "64819280345421258482017346931579849092301023088943214992246376036314042237400", "price": "0.24", "size": "549.99", "side": "SELL", "hash": "98e7f7b1ffd062f13d926d626224a4c0f64445a9", "best_bid": "0.2", "best_ask": "0.23"}], "timestamp": "1769384676618", "event_type": "price_change"}}
{"_local_timestamp": "2026-01-25T23:44:37.182113+00:00", "data": {"market": "0x07baddbeaa7f66706b84f167f835f3cc90782445ff36b2ea736c1c097f6ff537", "price_changes": [{"asset_id": "106820146733184719100966062623986655992997037363317463528901190592661638187355", "price": "0.34", "size": "449.99", "side": "BUY", "hash": "01cf86d70f87736b9bf6a9385dd15de0d473349a", "best_bid": "0.36", "best_ask": "0.38"}, {"asset_id": "58198710311579915535691075580727536486537716969204598157134462435731312061441", "price": "0.66", "size": "449.99", "side": "SELL", "hash": "f716b73bbce4ca91ad6e486b490b7d7f0df522b1", "best_bid": "0.62", "best_ask": "0.64"}], "timestamp": "1769384676619", "event_type": "price_change"}}
{"_local_timestamp": "2026-01-25T23:44:37.182374+00:00", "data": {"market": "0x07baddbeaa7f66706b84f167f835f3cc90782445ff36b2ea736c1c097f6ff537", "price_changes": [{"asset_id": "106820146733184719100966062623986655992997037363317463528901190592661638187355", "price": "0.34", "size": "424.99", "side": "BUY", "hash": "e4713022fa976fa804856533be70d4ce28dfc43f", "best_bid": "0.36", "best_ask": "0.38"}, {"asset_id": "58198710311579915535691075580727536486537716969204598157134462435731312061441", "price": "0.66", "size": "424.99", "side": "SELL", "hash": "5ac33640755427e9d4fa1775fabceb2ad955cc5a", "best_bid": "0.62", "best_ask": "0.64"}], "timestamp": "1769384676620", "event_type": "price_change"}}
{"_local_timestamp": "2026-01-25T23:44:37.182620+00:00", "data": {"market": "0x07baddbeaa7f66706b84f167f835f3cc90782445ff36b2ea736c1c097f6ff537", "price_changes": [{"asset_id": "106820146733184719100966062623986655992997037363317463528901190592661638187355", "price": "0.34", "size": "399.99", "side": "BUY", "hash": "d0b9c5cbaf2a6717d856f0a6b89e824030ec918e", "best_bid": "0.36", "best_ask": "0.38"}, {"asset_id": "58198710311579915535691075580727536486537716969204598157134462435731312061441", "price": "0.66", "size": "399.99", "side": "SELL", "hash": "cbc10efa6d3f3a98bf2ef1151820f7065383d66b", "best_bid": "0.62", "best_ask": "0.64"}], "timestamp": "1769384676621", "event_type": "price_change"}}
{"_local_timestamp": "2026-01-25T23:44:37.182881+00:00", "data": {"market": "0xb9223ddfda277ecf96cea52aba3d6a47e3bb001bf0173fb3e2145566c28e0c24", "price_changes": [{"asset_id": "57280055515157002497847996398372581077095661831629922834612019741255629878625", "price": "0.76", "size": "524.99", "side": "BUY", "hash": "78244b8ad62d093228d1969508906b626f8a9460", "best_bid": "0.77", "best_ask": "0.8"}, {"asset_id": "64819280345421258482017346931579849092301023088943214992246376036314042237400", "price": "0.24", "size": "524.99", "side": "SELL", "hash": "109b316c9884a3be6ed1ed48ef6e13bb4dfe4e87", "best_bid": "0.2", "best_ask": "0.23"}], "timestamp": "1769384676621", "event_type": "price_change"}}
{"_local_timestamp": "2026-01-25T23:44:37.183142+00:00", "data": {"market": "0xb9223ddfda277ecf96cea52aba3d6a47e3bb001bf0173fb3e2145566c28e0c24", "price_changes": [{"asset_id": "57280055515157002497847996398372581077095661831629922834612019741255629878625", "price": "0.76", "size": "499.99", "side": "BUY", "hash": "7ee92ba77c5a0c76615e05b405d3a78d92fc5110", "best_bid": "0.77", "best_ask": "0.8"}, {"asset_id": "64819280345421258482017346931579849092301023088943214992246376036314042237400", "price": "0.24", "size": "499.99", "side": "SELL", "hash": "0c6967a0c4a02f96e1a80a114418fd74f4a157a7", "best_bid": "0.2", "best_ask": "0.23"}], "timestamp": "1769384676622", "event_type": "price_change"}}
{"_local_timestamp": "2026-01-25T23:44:37.208669+00:00", "data": {"market": "0x8db2651deb0ca894dfec7963ff43d747e6b203d853ea102ddaaf69272fcbd14e", "price_changes": [{"asset_id": "55723215967704727452199840811929823276351711374899127881856674926400394790108", "price": "0.923", "size": "395.44", "side": "BUY", "hash": "97de57c8dfeba71417b92a539f1577a0c86c4182", "best_bid": "0.948", "best_ask": "0.962"}, {"asset_id": "59454703894867594337219596879618679187053555828199534311880631098862267050015", "price": "0.077", "size": "395.44", "side": "SELL", "hash": "3d909d85d4682beae49bc1f52efa07f8eae8ec93", "best_bid": "0.038", "best_ask": "0.052"}], "timestamp": "1769384676623", "event_type": "price_change"}}
{"_local_timestamp": "2026-01-25T23:44:37.208945+00:00", "data": {"market": "0x512ced1584beb41cb6dacdaa92f5d67f8bee28f055ef63b251d20a446422ddaa", "price_changes": [{"asset_id": "105159270423598199664249261738928535905668234939484323704322364820483620754428", "price": "0.88", "size": "1856.99", "side": "BUY", "hash": "ebdc6bf6d20cc55ff0e9e4b46455652aa728147c", "best_bid": "0.9", "best_ask": "0.92"}, {"asset_id": "81498082395020979729835659110658786648105896152484850898743462024117016161425", "price": "0.12", "size": "1856.99", "side": "SELL", "hash": "b29cbbb6fe112df1015e7d89431ec739501928db", "best_bid": "0.08", "best_ask": "0.1"}], "timestamp": "1769384676624", "event_type": "price_change"}}
{"_local_timestamp": "2026-01-25T23:44:37.221206+00:00", "data": {"market": "0x8db2651deb0ca894dfec7963ff43d747e6b203d853ea102ddaaf69272fcbd14e", "price_changes": [{"asset_id": "55723215967704727452199840811929823276351711374899127881856674926400394790108", "price": "0.923", "size": "344.44", "side": "BUY", "hash": "181de3925d131f2fa1660fd8cd8ec1e0f4934ac6", "best_bid": "0.948", "best_ask": "0.962"}, {"asset_id": "59454703894867594337219596879618679187053555828199534311880631098862267050015", "price": "0.077", "size": "344.44", "side": "SELL", "hash": "76584b83531cd4ec137774a7b7428c7eeda48b28", "best_bid": "0.038", "best_ask": "0.052"}], "timestamp": "1769384676625", "event_type": "price_change"}}
{"_local_timestamp": "2026-01-25T23:44:37.221526+00:00", "data": {"market": "0x8db2651deb0ca894dfec7963ff43d747e6b203d853ea102ddaaf69272fcbd14e", "price_changes": [{"asset_id": "55723215967704727452199840811929823276351711374899127881856674926400394790108", "price": "0.923", "size": "293.44", "side": "BUY", "hash": "5854260f0b0ebd788b5c64bf464e069500cba7c9", "best_bid": "0.948", "best_ask": "0.962"}, {"asset_id": "59454703894867594337219596879618679187053555828199534311880631098862267050015", "price": "0.077", "size": "293.44", "side": "SELL", "hash": "7aa50bcbd926e341170336e8f756c69a005480dc", "best_bid": "0.038", "best_ask": "0.052"}], "timestamp": "1769384676629", "event_type": "price_change"}}
{"_local_timestamp": "2026-01-25T23:44:37.496668+00:00", "data": {"market": "0x512ced1584beb41cb6dacdaa92f5d67f8bee28f055ef63b251d20a446422ddaa", "price_changes": [{"asset_id": "105159270423598199664249261738928535905668234939484323704322364820483620754428", "price": "0.88", "size": "1831.99", "side": "BUY", "hash": "c6562a51746792a5befddb48b746158ff564f9a0", "best_bid": "0.9", "best_ask": "0.92"}, {"asset_id": "81498082395020979729835659110658786648105896152484850898743462024117016161425", "price": "0.12", "size": "1831.99", "side": "SELL", "hash": "d3053a4b374e8ce2b82c7abb63706beaae1ef54c", "best_bid": "0.08", "best_ask": "0.1"}], "timestamp": "1769384676632", "event_type": "price_change"}}
{"_local_timestamp": "2026-01-25T23:44:37.497012+00:00", "data": {"market": "0x512ced1584beb41cb6dacdaa92f5d67f8bee28f055ef63b251d20a446422ddaa", "price_changes": [{"asset_id": "105159270423598199664249261738928535905668234939484323704322364820483620754428", "price": "0.88", "size": "1806.99", "side": "BUY", "hash": "716b65235564fd4dc3a38c3520908b43adeafeb0", "best_bid": "0.9", "best_ask": "0.92"}, {"asset_id": "81498082395020979729835659110658786648105896152484850898743462024117016161425", "price": "0.12", "size": "1806.99", "side": "SELL", "hash": "d3d894bf3b0a42d33de3290041acab3fb8e28318", "best_bid": "0.08", "best_ask": "0.1"}], "timestamp": "1769384676701", "event_type": "price_change"}}
{"_local_timestamp": "2026-01-25T23:44:41.654833+00:00", "data": {"market": "0x4ddaff7ab33855ab7ed53f75ae4a331496028177f4bf0557eafe0fb83628332b", "price_changes": [{"asset_id": "25589742673068913841508219929281747394194738561317540491643768947357201371462", "price": "0.978", "size": "0", "side": "SELL", "hash": "29dd0f9a520479b15b4ed7f184026829876e841e", "best_bid": "0.967", "best_ask": "0.977"}, {"asset_id": "25056163956965564455957738971346869740799169769422815261763807235324372823907", "price": "0.022", "size": "0", "side": "BUY", "hash": "84eb6315917dfb59b8c84f2331159ef20bd69faf", "best_bid": "0.023", "best_ask": "0.033"}], "timestamp": "1769384681474", "event_type": "price_change"}}
{"_local_timestamp": "2026-01-25T23:44:42.056146+00:00", "data": {"market": "0x4ddaff7ab33855ab7ed53f75ae4a331496028177f4bf0557eafe0fb83628332b", "price_changes": [{"asset_id": "25589742673068913841508219929281747394194738561317540491643768947357201371462", "price": "0.976", "size": "114.77", "side": "SELL", "hash": "d2d776c8b1096fedba4b62ae05ca0cb4ee2b96b1", "best_bid": "0.967", "best_ask": "0.976"}, {"asset_id": "25056163956965564455957738971346869740799169769422815261763807235324372823907", "price": "0.024", "size": "114.77", "side": "BUY", "hash": "7bf59e8c7a360e236b2af7a5f9484b7c7d1faa1a", "best_bid": "0.024", "best_ask": "0.033"}], "timestamp": "1769384681889", "event_type": "price_change"}}
{"_local_timestamp": "2026-01-25T23:44:42.087404+00:00", "data": {"market": "0x4ddaff7ab33855ab7ed53f75ae4a331496028177f4bf0557eafe0fb83628332b", "price_changes": [{"asset_id": "25056163956965564455957738971346869740799169769422815261763807235324372823907", "price": "0.023", "size": "0", "side": "BUY", "hash": "e450bd0e58c6ee7ec540f16500e48f050e695b27", "best_bid": "0.024", "best_ask": "0.033"}, {"asset_id": "25589742673068913841508219929281747394194738561317540491643768947357201371462", "price": "0.977", "size": "0", "side": "SELL", "hash": "56ae387086c80f66267b7724b4c8cfd041405711", "best_bid": "0.967", "best_ask": "0.976"}], "timestamp": "1769384681915", "event_type": "price_change"}}
{"_local_timestamp": "2026-01-25T23:44:42.161442+00:00", "data": {"market": "0x4ddaff7ab33855ab7ed53f75ae4a331496028177f4bf0557eafe0fb83628332b", "price_changes": [{"asset_id": "25056163956965564455957738971346869740799169769422815261763807235324372823907", "price": "0.025", "size": "435", "side": "BUY", "hash": "393ba2f056bf789442063a37603e8d2f2068c3d2", "best_bid": "0.025", "best_ask": "0.033"}, {"asset_id": "25589742673068913841508219929281747394194738561317540491643768947357201371462", "price": "0.975", "size": "435", "side": "SELL", "hash": "fe2c3ddf9c128549549fd253bc8fb3931e0e3ef9", "best_bid": "0.967", "best_ask": "0.975"}], "timestamp": "1769384681943", "event_type": "price_change"}}
{"_local_timestamp": "2026-01-25T23:44:42.225041+00:00", "data": {"market": "0xb9223ddfda277ecf96cea52aba3d6a47e3bb001bf0173fb3e2145566c28e0c24", "price_changes": [{"asset_id": "57280055515157002497847996398372581077095661831629922834612019741255629878625", "price": "0.76", "size": "524.99", "side": "BUY", "hash": "d7ac4af6bde5bb58152a41afa34da5784271dc4d", "best_bid": "0.77", "best_ask": "0.8"}, {"asset_id": "64819280345421258482017346931579849092301023088943214992246376036314042237400", "price": "0.24", "size": "524.99", "side": "SELL", "hash": "772a653f01cbe46f04466c180ca116bdcf79642e", "best_bid": "0.2", "best_ask": "0.23"}], "timestamp": "1769384682051", "event_type": "price_change"}}
{"_local_timestamp": "2026-01-25T23:44:42.225409+00:00", "data": {"market": "0x07baddbeaa7f66706b84f167f835f3cc90782445ff36b2ea736c1c097f6ff537", "price_changes": [{"asset_id": "106820146733184719100966062623986655992997037363317463528901190592661638187355", "price": "0.34", "size": "424.99", "side": "BUY", "hash": "7d9b51eb730c056e48c0a84234151aced20b0572", "best_bid": "0.36", "best_ask": "0.38"}, {"asset_id": "58198710311579915535691075580727536486537716969204598157134462435731312061441", "price": "0.66", "size": "424.99", "side": "SELL", "hash": "967bd2e6203bb42d62aeba607f0d426c893c5e89", "best_bid": "0.62", "best_ask": "0.64"}], "timestamp": "1769384682054", "event_type": "price_change"}}
{"_local_timestamp": "2026-01-25T23:44:42.279920+00:00", "data": {"market": "0x512ced1584beb41cb6dacdaa92f5d67f8bee28f055ef63b251d20a446422ddaa", "price_changes": [{"asset_id": "105159270423598199664249261738928535905668234939484323704322364820483620754428", "price": "0.88", "size": "1831.99", "side": "BUY", "hash": "c08c18f300bf0608158cacef784afa6f57f98097", "best_bid": "0.9", "best_ask": "0.92"}, {"asset_id": "81498082395020979729835659110658786648105896152484850898743462024117016161425", "price": "0.12", "size": "1831.99", "side": "SELL", "hash": "a31cb08fb6a1fe8bebc1be61fa33170c9d25e227", "best_bid": "0.08", "best_ask": "0.1"}], "timestamp": "1769384682055", "event_type": "price_change"}}
{"_local_timestamp": "2026-01-25T23:44:42.280333+00:00", "data": {"market": "0x512ced1584beb41cb6dacdaa92f5d67f8bee28f055ef63b251d20a446422ddaa", "price_changes": [{"asset_id": "105159270423598199664249261738928535905668234939484323704322364820483620754428", "price": "0.88", "size": "1856.99", "side": "BUY", "hash": "b873685d1b6f259db890ca183bb8dc64b9984ed8", "best_bid": "0.9", "best_ask": "0.92"}, {"asset_id": "81498082395020979729835659110658786648105896152484850898743462024117016161425", "price": "0.12", "size": "1856.99", "side": "SELL", "hash": "b90bae89f5ebe536e17ea005c79497d60db70250", "best_bid": "0.08", "best_ask": "0.1"}], "timestamp": "1769384682056", "event_type": "price_change"}}
{"_local_timestamp": "2026-01-25T23:44:42.298919+00:00", "data": {"market": "0x8db2651deb0ca894dfec7963ff43d747e6b203d853ea102ddaaf69272fcbd14e", "price_changes": [{"asset_id": "55723215967704727452199840811929823276351711374899127881856674926400394790108", "price": "0.923", "size": "344.44", "side": "BUY", "hash": "8c6cffb5ae371585fac3d1c2e5d65701abc202a5", "best_bid": "0.948", "best_ask": "0.962"}, {"asset_id": "59454703894867594337219596879618679187053555828199534311880631098862267050015", "price": "0.077", "size": "344.44", "side": "SELL", "hash": "5aab940967fc2031a0c166a2f64652627314f6ca", "best_bid": "0.038", "best_ask": "0.052"}], "timestamp": "1769384682056", "event_type": "price_change"}}
{"_local_timestamp": "2026-01-25T23:44:42.299308+00:00", "data": {"market": "0xb9223ddfda277ecf96cea52aba3d6a47e3bb001bf0173fb3e2145566c28e0c24", "price_changes": [{"asset_id": "57280055515157002497847996398372581077095661831629922834612019741255629878625", "price": "0.76", "size": "549.99", "side": "BUY", "hash": "1148057d9ee34e8c9511bc224dda7cff05d151c3", "best_bid": "0.77", "best_ask": "0.8"}, {"asset_id": "64819280345421258482017346931579849092301023088943214992246376036314042237400", "price": "0.24", "size": "549.99", "side": "SELL", "hash": "caa9fa62af048ea48b627b56cfd93e4e5d61d968", "best_bid": "0.2", "best_ask": "0.23"}], "timestamp": "1769384682057", "event_type": "price_change"}}
{"_local_timestamp": "2026-01-25T23:44:42.330546+00:00", "data": {"market": "0x07baddbeaa7f66706b84f167f835f3cc90782445ff36b2ea736c1c097f6ff537", "price_changes": [{"asset_id": "106820146733184719100966062623986655992997037363317463528901190592661638187355", "price": "0.34", "size": "449.99", "side": "BUY", "hash": "10a2f05d66bf6e622e38aa6fae7fe8af54418ecd", "best_bid": "0.36", "best_ask": "0.38"}, {"asset_id": "58198710311579915535691075580727536486537716969204598157134462435731312061441", "price": "0.66", "size": "449.99", "side": "SELL", "hash": "c7370edab7427f2d8d5dbfc90ff690ef8d29264c", "best_bid": "0.62", "best_ask": "0.64"}], "timestamp": "1769384682058", "event_type": "price_change"}}
{"_local_timestamp": "2026-01-25T23:44:42.330919+00:00", "data": {"market": "0x07baddbeaa7f66706b84f167f835f3cc90782445ff36b2ea736c1c097f6ff537", "price_changes": [{"asset_id": "106820146733184719100966062623986655992997037363317463528901190592661638187355", "price": "0.34", "size": "474.99", "side": "BUY", "hash": "52a30817e65e1dd29b7ad4be00433ee244bf1e9c", "best_bid": "0.36", "best_ask": "0.38"}, {"asset_id": "58198710311579915535691075580727536486537716969204598157134462435731312061441", "price": "0.66", "size": "474.99", "side": "SELL", "hash": "a08e5498ecdd7c64b3c34f4e9e9c57ffc817a840", "best_bid": "0.62", "best_ask": "0.64"}], "timestamp": "1769384682062", "event_type": "price_change"}}
{"_local_timestamp": "2026-01-25T23:44:42.430332+00:00", "data": {"market": "0xb9223ddfda277ecf96cea52aba3d6a47e3bb001bf0173fb3e2145566c28e0c24", "price_changes": [{"asset_id": "57280055515157002497847996398372581077095661831629922834612019741255629878625", "price": "0.76", "size": "574.99", "side": "BUY", "hash": "e77e38ede8766bef73a639049143ccc5769c15e1", "best_bid": "0.77", "best_ask": "0.8"}, {"asset_id": "64819280345421258482017346931579849092301023088943214992246376036314042237400", "price": "0.24", "size": "574.99", "side": "SELL", "hash": "bde2f9c8d3be5274731ecc50b53d169c402cf5fb", "best_bid": "0.2", "best_ask": "0.23"}], "timestamp": "1769384682062", "event_type": "price_change"}}
{"_local_timestamp": "2026-01-25T23:44:42.430718+00:00", "data": {"market": "0x512ced1584beb41cb6dacdaa92f5d67f8bee28f055ef63b251d20a446422ddaa", "price_changes": [{"asset_id": "105159270423598199664249261738928535905668234939484323704322364820483620754428", "price": "0.88", "size": "1881.99", "side": "BUY", "hash": "9f42beaabe588c7e31f4f23e64a29eea6ab2c444", "best_bid": "0.9", "best_ask": "0.92"}, {"asset_id": "81498082395020979729835659110658786648105896152484850898743462024117016161425", "price": "0.12", "size": "1881.99", "side": "SELL", "hash": "71ab953e530c90ccce3b0971dd0ca9092d9ec094", "best_bid": "0.08", "best_ask": "0.1"}], "timestamp": "1769384682066", "event_type": "price_change"}}
{"_local_timestamp": "2026-01-25T23:44:42.430979+00:00", "data": {"market": "0x8db2651deb0ca894dfec7963ff43d747e6b203d853ea102ddaaf69272fcbd14e", "price_changes": [{"asset_id": "55723215967704727452199840811929823276351711374899127881856674926400394790108", "price": "0.923", "size": "395.44", "side": "BUY", "hash": "81f9a9cc2b5fd40eedc91b994f0bcaa18528876e", "best_bid": "0.948", "best_ask": "0.962"}, {"asset_id": "59454703894867594337219596879618679187053555828199534311880631098862267050015", "price": "0.077", "size": "395.44", "side": "SELL", "hash": "3f870412e48d4bb6344ae114f3e99edb0eedb79e", "best_bid": "0.038", "best_ask": "0.052"}], "timestamp": "1769384682072", "event_type": "price_change"}}
{"_local_timestamp": "2026-01-25T23:44:42.431202+00:00", "data": {"market": "0x07baddbeaa7f66706b84f167f835f3cc90782445ff36b2ea736c1c097f6ff537", "price_changes": [{"asset_id": "106820146733184719100966062623986655992997037363317463528901190592661638187355", "price": "0.3", "size": "783", "side": "BUY", "hash": "75a63c2e2749c975ad5885223684e65438c60f8a", "best_bid": "0.36", "best_ask": "0.38"}, {"asset_id": "58198710311579915535691075580727536486537716969204598157134462435731312061441", "price": "0.7", "size": "783", "side": "SELL", "hash": "802a4ec9ec77d62a5212653d8883b840b37f8c22", "best_bid": "0.62", "best_ask": "0.64"}], "timestamp": "1769384682121", "event_type": "price_change"}}
{"_local_timestamp": "2026-01-25T23:44:42.431434+00:00", "data": {"market": "0x8db2651deb0ca894dfec7963ff43d747e6b203d853ea102ddaaf69272fcbd14e", "price_changes": [{"asset_id": "55723215967704727452199840811929823276351711374899127881856674926400394790108", "price": "0.923", "size": "446.44", "side": "BUY", "hash": "e7fffe652aabfeaf6dacad6aa590c02bb7b08432", "best_bid": "0.948", "best_ask": "0.962"}, {"asset_id": "59454703894867594337219596879618679187053555828199534311880631098862267050015", "price": "0.077", "size": "446.44", "side": "SELL", "hash": "ae63792700a4ab5a1b44431d07ea07f1a34c2e0b", "best_bid": "0.038", "best_ask": "0.052"}], "timestamp": "1769384682219", "event_type": "price_change"}}
{"_local_timestamp": "2026-01-25T23:44:43.194676+00:00", "data": {"market": "0x4ddaff7ab33855ab7ed53f75ae4a331496028177f4bf0557eafe0fb83628332b", "price_changes": [{"asset_id": "25056163956965564455957738971346869740799169769422815261763807235324372823907", "price": "0.025", "size": "0", "side": "BUY", "hash": "b94e843b29814eed71165fafdadea9860078cf2f", "best_bid": "0.024", "best_ask": "0.033"}, {"asset_id": "25589742673068913841508219929281747394194738561317540491643768947357201371462", "price": "0.975", "size": "0", "side": "SELL", "hash": "5b261b16c63bdf90174abf0b2104725a32e75f9a", "best_bid": "0.967", "best_ask": "0.976"}], "timestamp": "1769384683012", "event_type": "price_change"}}
{"_local_timestamp": "2026-01-25T23:44:43.228977+00:00", "data": {"market": "0x4ddaff7ab33855ab7ed53f75ae4a331496028177f4bf0557eafe0fb83628332b", "price_changes": [{"asset_id": "25056163956965564455957738971346869740799169769422815261763807235324372823907", "price": "0.025", "size": "435", "side": "BUY", "hash": "3b15b2288689424d0af59f10da6e3b9e5a544dc0", "best_bid": "0.025", "best_ask": "0.033"}, {"asset_id": "25589742673068913841508219929281747394194738561317540491643768947357201371462", "price": "0.975", "size": "435", "side": "SELL", "hash": "1571315b0b4d2552b0c642cd6897bca6cfdec488", "best_bid": "0.967", "best_ask": "0.975"}], "timestamp": "1769384683072", "event_type": "price_change"}}
{"_local_timestamp": "2026-01-25T23:44:43.285499+00:00", "data": {"market": "0xb9223ddfda277ecf96cea52aba3d6a47e3bb001bf0173fb3e2145566c28e0c24", "price_changes": [{"asset_id": "57280055515157002497847996398372581077095661831629922834612019741255629878625", "price": "0.76", "size": "549.99", "side": "BUY", "hash": "fb272f2049eba46c449db1da248eb08610ac9696", "best_bid": "0.77", "best_ask": "0.8"}, {"asset_id": "64819280345421258482017346931579849092301023088943214992246376036314042237400", "price": "0.24", "size": "549.99", "side": "SELL", "hash": "c82a5be0207744d731b4bce29c4941700af7108e", "best_bid": "0.2", "best_ask": "0.23"}], "timestamp": "1769384683139", "event_type": "price_change"}}
{"_local_timestamp": "2026-01-25T23:44:43.286670+00:00", "data": {"market": "0xb9223ddfda277ecf96cea52aba3d6a47e3bb001bf0173fb3e2145566c28e0c24", "price_changes": [{"asset_id": "57280055515157002497847996398372581077095661831629922834612019741255629878625", "price": "0.76", "size": "524.99", "side": "BUY", "hash": "046e68729ed46669996417c13a2d9df2af7978ee", "best_bid": "0.77", "best_ask": "0.8"}, {"asset_id": "64819280345421258482017346931579849092301023088943214992246376036314042237400", "price": "0.24", "size": "524.99", "side": "SELL", "hash": "b0c33dc9a4d6e94b29337dfc8e90e303b78ee8f5", "best_bid": "0.2", "best_ask": "0.23"}], "timestamp": "1769384683142", "event_type": "price_change"}}
{"_local_timestamp": "2026-01-25T23:44:43.286994+00:00", "data": {"market": "0x07baddbeaa7f66706b84f167f835f3cc90782445ff36b2ea736c1c097f6ff537", "price_changes": [{"asset_id": "106820146733184719100966062623986655992997037363317463528901190592661638187355", "price": "0.34", "size": "449.99", "side": "BUY", "hash": "8fe170d76e55aa057b988267336b983211130440", "best_bid": "0.36", "best_ask": "0.38"}, {"asset_id": "58198710311579915535691075580727536486537716969204598157134462435731312061441", "price": "0.66", "size": "449.99", "side": "SELL", "hash": "af494782a43d35f4b3380bb03b116511a340ae6e", "best_bid": "0.62", "best_ask": "0.64"}], "timestamp": "1769384683142", "event_type": "price_change"}}
{"_local_timestamp": "2026-01-25T23:44:43.411942+00:00", "data": {"market": "0x07baddbeaa7f66706b84f167f835f3cc90782445ff36b2ea736c1c097f6ff537", "price_changes": [{"asset_id": "106820146733184719100966062623986655992997037363317463528901190592661638187355", "price": "0.34", "size": "424.99", "side": "BUY", "hash": "138088fa560409c3a89600dcd7edf383524ca039", "best_bid": "0.36", "best_ask": "0.38"}, {"asset_id": "58198710311579915535691075580727536486537716969204598157134462435731312061441", "price": "0.66", "size": "424.99", "side": "SELL", "hash": "63695c825aea6ba1f481c1b45025a4f5727312c5", "best_bid": "0.62", "best_ask": "0.64"}], "timestamp": "1769384683144", "event_type": "price_change"}}
{"_local_timestamp": "2026-01-25T23:44:43.412305+00:00", "data": {"market": "0x512ced1584beb41cb6dacdaa92f5d67f8bee28f055ef63b251d20a446422ddaa", "price_changes": [{"asset_id": "105159270423598199664249261738928535905668234939484323704322364820483620754428", "price": "0.88", "size": "1856.99", "side": "BUY", "hash": "a617420354d3b3259a5bebf0846d5770daff84fc", "best_bid": "0.9", "best_ask": "0.92"}, {"asset_id": "81498082395020979729835659110658786648105896152484850898743462024117016161425", "price": "0.12", "size": "1856.99", "side": "SELL", "hash": "9ae4eeac7bc1b4ebc89abca4d376cb9edabe5a5f", "best_bid": "0.08", "best_ask": "0.1"}], "timestamp": "1769384683145", "event_type": "price_change"}}
{"_local_timestamp": "2026-01-25T23:44:43.440749+00:00", "data": {"market": "0x8db2651deb0ca894dfec7963ff43d747e6b203d853ea102ddaaf69272fcbd14e", "price_changes": [{"asset_id": "55723215967704727452199840811929823276351711374899127881856674926400394790108", "price": "0.923", "size": "395.44", "side": "BUY", "hash": "a855059fae11a46d1b103649ba4cdbbb19f3a642", "best_bid": "0.948", "best_ask": "0.962"}, {"asset_id": "59454703894867594337219596879618679187053555828199534311880631098862267050015", "price": "0.077", "size": "395.44", "side": "SELL", "hash": "f51afcc065f98d69d3b5258d2cd9c5936234d85d", "best_bid": "0.038", "best_ask": "0.052"}], "timestamp": "1769384683150", "event_type": "price_change"}}
{"_local_timestamp": "2026-01-25T23:44:43.441080+00:00", "data": {"market": "0x8db2651deb0ca894dfec7963ff43d747e6b203d853ea102ddaaf69272fcbd14e", "price_changes": [{"asset_id": "55723215967704727452199840811929823276351711374899127881856674926400394790108", "price": "0.923", "size": "344.44", "side": "BUY", "hash": "38dc33e4310d5dcf989201c0adc06b4a169c6d79", "best_bid": "0.948", "best_ask": "0.962"}, {"asset_id": "59454703894867594337219596879618679187053555828199534311880631098862267050015", "price": "0.077", "size": "344.44", "side": "SELL", "hash": "f2657284dfecbe6e8846dceded72db77572ee1e3", "best_bid": "0.038", "best_ask": "0.052"}], "timestamp": "1769384683151", "event_type": "price_change"}}
{"_local_timestamp": "2026-01-25T23:44:43.492353+00:00", "data": {"market": "0x8db2651deb0ca894dfec7963ff43d747e6b203d853ea102ddaaf69272fcbd14e", "price_changes": [{"asset_id": "55723215967704727452199840811929823276351711374899127881856674926400394790108", "price": "0.923", "size": "293.44", "side": "BUY", "hash": "6f615f4b471014740a7001bf4211713124df9da2", "best_bid": "0.948", "best_ask": "0.962"}, {"asset_id": "59454703894867594337219596879618679187053555828199534311880631098862267050015", "price": "0.077", "size": "293.44", "side": "SELL", "hash": "3167aa1fa7403e0e2a2c28271e892695dee4c2b2", "best_bid": "0.038", "best_ask": "0.052"}], "timestamp": "1769384683151", "event_type": "price_change"}}
{"_local_timestamp": "2026-01-25T23:44:43.495646+00:00", "data": {"market": "0x512ced1584beb41cb6dacdaa92f5d67f8bee28f055ef63b251d20a446422ddaa", "price_changes": [{"asset_id": "105159270423598199664249261738928535905668234939484323704322364820483620754428", "price": "0.88", "size": "1831.99", "side": "BUY", "hash": "8a3d86392710720d1f104d452fcd93ac958366d2", "best_bid": "0.9", "best_ask": "0.92"}, {"asset_id": "81498082395020979729835659110658786648105896152484850898743462024117016161425", "price": "0.12", "size": "1831.99", "side": "SELL", "hash": "3a3f2aacfd88336cfc73d025a761e7b47a942641", "best_bid": "0.08", "best_ask": "0.1"}], "timestamp": "1769384683152", "event_type": "price_change"}}
{"_local_timestamp": "2026-01-25T23:44:43.506309+00:00", "data": {"market": "0x512ced1584beb41cb6dacdaa92f5d67f8bee28f055ef63b251d20a446422ddaa", "price_changes": [{"asset_id": "105159270423598199664249261738928535905668234939484323704322364820483620754428", "price": "0.88", "size": "1806.99", "side": "BUY", "hash": "1d090e5c2b18439b8f2b7acb1b86780c0c132aa3", "best_bid": "0.9", "best_ask": "0.92"}, {"asset_id": "81498082395020979729835659110658786648105896152484850898743462024117016161425", "price": "0.12", "size": "1806.99", "side": "SELL", "hash": "aed4e93c21c8f4fd7981d7170ab37246ab4235fc", "best_bid": "0.08", "best_ask": "0.1"}], "timestamp": "1769384683156", "event_type": "price_change"}}
{"_local_timestamp": "2026-01-25T23:44:43.506653+00:00", "data": {"market": "0x07baddbeaa7f66706b84f167f835f3cc90782445ff36b2ea736c1c097f6ff537", "price_changes": [{"asset_id": "106820146733184719100966062623986655992997037363317463528901190592661638187355", "price": "0.34", "size": "399.99", "side": "BUY", "hash": "94116beba910e01f7238024ea29e37eaac370727", "best_bid": "0.36", "best_ask": "0.38"}, {"asset_id": "58198710311579915535691075580727536486537716969204598157134462435731312061441", "price": "0.66", "size": "399.99", "side": "SELL", "hash": "c57d3f869762edc4209cb2153373ac96eac8282b", "best_bid": "0.62", "best_ask": "0.64"}], "timestamp": "1769384683161", "event_type": "price_change"}}
{"_local_timestamp": "2026-01-25T23:44:43.506928+00:00", "data": {"market": "0xb9223ddfda277ecf96cea52aba3d6a47e3bb001bf0173fb3e2145566c28e0c24", "price_changes": [{"asset_id": "57280055515157002497847996398372581077095661831629922834612019741255629878625", "price": "0.76", "size": "499.99", "side": "BUY", "hash": "e02ed440ae50800d99abc6c7e789faa4e1c7b5d1", "best_bid": "0.77", "best_ask": "0.8"}, {"asset_id": "64819280345421258482017346931579849092301023088943214992246376036314042237400", "price": "0.24", "size": "499.99", "side": "SELL", "hash": "6687fa42e1d72a13778c93fbaa6b70efd34e87a1", "best_bid": "0.2", "best_ask": "0.23"}], "timestamp": "1769384683165", "event_type": "price_change"}}
{"_local_timestamp": "2026-01-25T23:44:43.507187+00:00", "data": {"market": "0xb9223ddfda277ecf96cea52aba3d6a47e3bb001bf0173fb3e2145566c28e0c24", "price_changes": [{"asset_id": "57280055515157002497847996398372581077095661831629922834612019741255629878625", "price": "0.76", "size": "524.99", "side": "BUY", "hash": "99b8246c52efc7ff990de23dd4a45b7ceb09b808", "best_bid": "0.77", "best_ask": "0.8"}, {"asset_id": "64819280345421258482017346931579849092301023088943214992246376036314042237400", "price": "0.24", "size": "524.99", "side": "SELL", "hash": "2c45393caa4d29d3a134307606474e51e18815f2", "best_bid": "0.2", "best_ask": "0.23"}], "timestamp": "1769384683254", "event_type": "price_change"}}
{"_local_timestamp": "2026-01-25T23:44:43.507480+00:00", "data": {"market": "0x07baddbeaa7f66706b84f167f835f3cc90782445ff36b2ea736c1c097f6ff537", "price_changes": [{"asset_id": "106820146733184719100966062623986655992997037363317463528901190592661638187355", "price": "0.34", "size": "424.99", "side": "BUY", "hash": "2b416ecd24d92e098bb4eaedff826bff77c0bd9e", "best_bid": "0.36", "best_ask": "0.38"}, {"asset_id": "58198710311579915535691075580727536486537716969204598157134462435731312061441", "price": "0.66", "size": "424.99", "side": "SELL", "hash": "5455d3b6d1bf131dd626678504c435122d4083af", "best_bid": "0.62", "best_ask": "0.64"}], "timestamp": "1769384683259", "event_type": "price_change"}}
{"_local_timestamp": "2026-01-25T23:44:43.615479+00:00", "data": {"market": "0x8db2651deb0ca894dfec7963ff43d747e6b203d853ea102ddaaf69272fcbd14e", "price_changes": [{"asset_id": "55723215967704727452199840811929823276351711374899127881856674926400394790108", "price": "0.923", "size": "344.44", "side": "BUY", "hash": "5ccc4bfe62a5d31efaed4626c449ac6d524985f5", "best_bid": "0.948", "best_ask": "0.962"}, {"asset_id": "59454703894867594337219596879618679187053555828199534311880631098862267050015", "price": "0.077", "size": "344.44", "side": "SELL", "hash": "1ad6684befb40ff6814640c09f82d6870975e8ee", "best_bid": "0.038", "best_ask": "0.052"}], "timestamp": "1769384683263", "event_type": "price_change"}}
{"_local_timestamp": "2026-01-25T23:44:43.615793+00:00", "data": {"market": "0x512ced1584beb41cb6dacdaa92f5d67f8bee28f055ef63b251d20a446422ddaa", "price_changes": [{"asset_id": "105159270423598199664249261738928535905668234939484323704322364820483620754428", "price": "0.88", "size": "1831.99", "side": "BUY", "hash": "65a44b055db5488c482be12c98ee5c4ff73db857", "best_bid": "0.9", "best_ask": "0.92"}, {"asset_id": "81498082395020979729835659110658786648105896152484850898743462024117016161425", "price": "0.12", "size": "1831.99", "side": "SELL", "hash": "0b3f824d0fd39be1f81d2fe6ff33b937dabfc82b", "best_bid": "0.08", "best_ask": "0.1"}], "timestamp": "1769384683263", "event_type": "price_change"}}
{"_local_timestamp": "2026-01-25T23:44:43.616061+00:00", "data": {"market": "0x07baddbeaa7f66706b84f167f835f3cc90782445ff36b2ea736c1c097f6ff537", "price_changes": [{"asset_id": "106820146733184719100966062623986655992997037363317463528901190592661638187355", "price": "0.34", "size": "449.99", "side": "BUY", "hash": "a40456dd5a011c4369821132eae16a3a3d3e26ee", "best_bid": "0.36", "best_ask": "0.38"}, {"asset_id": "58198710311579915535691075580727536486537716969204598157134462435731312061441", "price": "0.66", "size": "449.99", "side": "SELL", "hash": "40a7d164823d66af729f8b86579471ee16ae377c", "best_bid": "0.62", "best_ask": "0.64"}], "timestamp": "1769384683267", "event_type": "price_change"}}
{"_local_timestamp": "2026-01-25T23:44:43.616304+00:00", "data": {"market": "0x8db2651deb0ca894dfec7963ff43d747e6b203d853ea102ddaaf69272fcbd14e", "price_changes": [{"asset_id": "55723215967704727452199840811929823276351711374899127881856674926400394790108", "price": "0.923", "size": "395.44", "side": "BUY", "hash": "135da397734a18fa3044ac6c06c950911941e092", "best_bid": "0.948", "best_ask": "0.962"}, {"asset_id": "59454703894867594337219596879618679187053555828199534311880631098862267050015", "price": "0.077", "size": "395.44", "side": "SELL", "hash": "abb7c932b1c8497ab6c68c8c24ba66b3477fcbd1", "best_bid": "0.038", "best_ask": "0.052"}], "timestamp": "1769384683269", "event_type": "price_change"}}
{"_local_timestamp": "2026-01-25T23:44:43.616546+00:00", "data": {"market": "0xb9223ddfda277ecf96cea52aba3d6a47e3bb001bf0173fb3e2145566c28e0c24", "price_changes": [{"asset_id": "57280055515157002497847996398372581077095661831629922834612019741255629878625", "price": "0.76", "size": "549.99", "side": "BUY", "hash": "e2e905ec6c1b0f58a3106c0b30b72e3087c4032e", "best_bid": "0.77", "best_ask": "0.8"}, {"asset_id": "64819280345421258482017346931579849092301023088943214992246376036314042237400", "price": "0.24", "size": "549.99", "side": "SELL", "hash": "4bda43d921c162dd4692d0446dfbe56b98953abe", "best_bid": "0.2", "best_ask": "0.23"}], "timestamp": "1769384683273", "event_type": "price_change"}}
{"_local_timestamp": "2026-01-25T23:44:43.651741+00:00", "data": {"market": "0xb9223ddfda277ecf96cea52aba3d6a47e3bb001bf0173fb3e2145566c28e0c24", "price_changes": [{"asset_id": "57280055515157002497847996398372581077095661831629922834612019741255629878625", "price": "0.76", "size": "574.99", "side": "BUY", "hash": "33824ff5016eb3b85b353d4b794ffd4aec037a97", "best_bid": "0.77", "best_ask": "0.8"}, {"asset_id": "64819280345421258482017346931579849092301023088943214992246376036314042237400", "price": "0.24", "size": "574.99", "side": "SELL", "hash": "5d8a0cbea95954aed3bf7575f7ea297950ef9dd7", "best_bid": "0.2", "best_ask": "0.23"}], "timestamp": "1769384683277", "event_type": "price_change"}}
{"_local_timestamp": "2026-01-25T23:44:43.652117+00:00", "data": {"market": "0x07baddbeaa7f66706b84f167f835f3cc90782445ff36b2ea736c1c097f6ff537", "price_changes": [{"asset_id": "106820146733184719100966062623986655992997037363317463528901190592661638187355", "price": "0.34", "size": "474.99", "side": "BUY", "hash": "4c1bf78d08e41ee35af75a057bc42016395089ce", "best_bid": "0.36", "best_ask": "0.38"}, {"asset_id": "58198710311579915535691075580727536486537716969204598157134462435731312061441", "price": "0.66", "size": "474.99", "side": "SELL", "hash": "cf4e6633385c4754030bc57b127630b850b681db", "best_bid": "0.62", "best_ask": "0.64"}], "timestamp": "1769384683296", "event_type": "price_change"}}
{"_local_timestamp": "2026-01-25T23:44:43.709057+00:00", "data": {"market": "0x512ced1584beb41cb6dacdaa92f5d67f8bee28f055ef63b251d20a446422ddaa", "price_changes": [{"asset_id": "105159270423598199664249261738928535905668234939484323704322364820483620754428", "price": "0.88", "size": "1856.99", "side": "BUY", "hash": "5a90cf14093ddabc64d83a0750fa8208782b1043", "best_bid": "0.9", "best_ask": "0.92"}, {"asset_id": "81498082395020979729835659110658786648105896152484850898743462024117016161425", "price": "0.12", "size": "1856.99", "side": "SELL", "hash": "72ab86d728614cbdafed4e2653bbb027cbce8b69", "best_bid": "0.08", "best_ask": "0.1"}], "timestamp": "1769384683320", "event_type": "price_change"}}
{"_local_timestamp": "2026-01-25T23:44:43.709364+00:00", "data": {"market": "0x8db2651deb0ca894dfec7963ff43d747e6b203d853ea102ddaaf69272fcbd14e", "price_changes": [{"asset_id": "55723215967704727452199840811929823276351711374899127881856674926400394790108", "price": "0.923", "size": "446.44", "side": "BUY", "hash": "c33857631e868685a4efeebcaae1d12ad57b74ba", "best_bid": "0.948", "best_ask": "0.962"}, {"asset_id": "59454703894867594337219596879618679187053555828199534311880631098862267050015", "price": "0.077", "size": "446.44", "side": "SELL", "hash": "c953366817463dc9716da540bfad143db6396b6c", "best_bid": "0.038", "best_ask": "0.052"}], "timestamp": "1769384683339", "event_type": "price_change"}}
{"_local_timestamp": "2026-01-25T23:44:43.712165+00:00", "data": {"market": "0x512ced1584beb41cb6dacdaa92f5d67f8bee28f055ef63b251d20a446422ddaa", "price_changes": [{"asset_id": "105159270423598199664249261738928535905668234939484323704322364820483620754428", "price": "0.88", "size": "1881.99", "side": "BUY", "hash": "081fa1dfb208ad551d8e4ae954562a605e899e8b", "best_bid": "0.9", "best_ask": "0.92"}, {"asset_id": "81498082395020979729835659110658786648105896152484850898743462024117016161425", "price": "0.12", "size": "1881.99", "side": "SELL", "hash": "57881ec17e26ba79eb1b67d90f97937726c8e203", "best_bid": "0.08", "best_ask": "0.1"}], "timestamp": "1769384683437", "event_type": "price_change"}}
{"_local_timestamp": "2026-01-25T23:44:44.674424+00:00", "data": {"market": "0x4ddaff7ab33855ab7ed53f75ae4a331496028177f4bf0557eafe0fb83628332b", "price_changes": [{"asset_id": "25056163956965564455957738971346869740799169769422815261763807235324372823907", "price": "0.025", "size": "0", "side": "BUY", "hash": "00753ddd2d8b1e2ba596ee8459b5cf461c86174a", "best_bid": "0.024", "best_ask": "0.033"}, {"asset_id": "25589742673068913841508219929281747394194738561317540491643768947357201371462", "price": "0.975", "size": "0", "side": "SELL", "hash": "2b0125496c26014f65807c20bb37ea0f9dc0ffd1", "best_bid": "0.967", "best_ask": "0.976"}], "timestamp": "1769384684516", "event_type": "price_change"}}
{"_local_timestamp": "2026-01-25T23:44:44.709705+00:00", "data": {"market": "0x4ddaff7ab33855ab7ed53f75ae4a331496028177f4bf0557eafe0fb83628332b", "price_changes": [{"asset_id": "25056163956965564455957738971346869740799169769422815261763807235324372823907", "price": "0.025", "size": "435", "side": "BUY", "hash": "0f73fee817f04ba0912ef3d76dbf2a54f9bcf0fd", "best_bid": "0.025", "best_ask": "0.033"}, {"asset_id": "25589742673068913841508219929281747394194738561317540491643768947357201371462", "price": "0.975", "size": "435", "side": "SELL", "hash": "71b40d5a7685f5b207591bcc8223957c41cab0ea", "best_bid": "0.967", "best_ask": "0.975"}], "timestamp": "1769384684544", "event_type": "price_change"}}
{"_local_timestamp": "2026-01-25T23:44:44.791905+00:00", "data": {"market": "0x8db2651deb0ca894dfec7963ff43d747e6b203d853ea102ddaaf69272fcbd14e", "price_changes": [{"asset_id": "55723215967704727452199840811929823276351711374899127881856674926400394790108", "price": "0.923", "size": "395.44", "side": "BUY", "hash": "2daba286249f21e0dfdb12e357c1b73075ac2d56", "best_bid": "0.948", "best_ask": "0.962"}, {"asset_id": "59454703894867594337219596879618679187053555828199534311880631098862267050015", "price": "0.077", "size": "395.44", "side": "SELL", "hash": "873b5d3659e15c2e7e21aec49148f0a0f32113cc", "best_bid": "0.038", "best_ask": "0.052"}], "timestamp": "1769384684620", "event_type": "price_change"}}
{"_local_timestamp": "2026-01-25T23:44:44.792206+00:00", "data": {"market": "0x07baddbeaa7f66706b84f167f835f3cc90782445ff36b2ea736c1c097f6ff537", "price_changes": [{"asset_id": "106820146733184719100966062623986655992997037363317463528901190592661638187355", "price": "0.34", "size": "449.99", "side": "BUY", "hash": "09251b1e7a93f613434f3f1d334bdece1543cac4", "best_bid": "0.36", "best_ask": "0.38"}, {"asset_id": "58198710311579915535691075580727536486537716969204598157134462435731312061441", "price": "0.66", "size": "449.99", "side": "SELL", "hash": "68d6e1d0edc19f2c2e7dbfe2cc1f1032d05ebe04", "best_bid": "0.62", "best_ask": "0.64"}], "timestamp": "1769384684621", "event_type": "price_change"}}
{"_local_timestamp": "2026-01-25T23:44:44.792476+00:00", "data": {"market": "0xb9223ddfda277ecf96cea52aba3d6a47e3bb001bf0173fb3e2145566c28e0c24", "price_changes": [{"asset_id": "57280055515157002497847996398372581077095661831629922834612019741255629878625", "price": "0.76", "size": "549.99", "side": "BUY", "hash": "1c865fbb2b5b31aa6c004b258ddf4a73ff85acf6", "best_bid": "0.77", "best_ask": "0.8"}, {"asset_id": "64819280345421258482017346931579849092301023088943214992246376036314042237400", "price": "0.24", "size": "549.99", "side": "SELL", "hash": "da6322bf08e8669130c90367ec6ae98d316604b5", "best_bid": "0.2", "best_ask": "0.23"}], "timestamp": "1769384684621", "event_type": "price_change"}}
{"_local_timestamp": "2026-01-25T23:44:44.810565+00:00", "data": {"market": "0x07baddbeaa7f66706b84f167f835f3cc90782445ff36b2ea736c1c097f6ff537", "price_changes": [{"asset_id": "106820146733184719100966062623986655992997037363317463528901190592661638187355", "price": "0.34", "size": "424.99", "side": "BUY", "hash": "2550bd180ab85ec8c64249ed898d407178d6b795", "best_bid": "0.36", "best_ask": "0.38"}, {"asset_id": "58198710311579915535691075580727536486537716969204598157134462435731312061441", "price": "0.66", "size": "424.99", "side": "SELL", "hash": "c2f98669503dc41662b163fcf87d369cec47fa25", "best_bid": "0.62", "best_ask": "0.64"}], "timestamp": "1769384684625", "event_type": "price_change"}}
{"_local_timestamp": "2026-01-25T23:44:44.930135+00:00", "data": {"market": "0xb9223ddfda277ecf96cea52aba3d6a47e3bb001bf0173fb3e2145566c28e0c24", "price_changes": [{"asset_id": "57280055515157002497847996398372581077095661831629922834612019741255629878625", "price": "0.76", "size": "524.99", "side": "BUY", "hash": "6b89492a40de3d875ef7bcb1e6e70ee70a4281b1", "best_bid": "0.77", "best_ask": "0.8"}, {"asset_id": "64819280345421258482017346931579849092301023088943214992246376036314042237400", "price": "0.24", "size": "524.99", "side": "SELL", "hash": "c3a658745ea20c7677de67a606f720c181fc0d2d", "best_bid": "0.2", "best_ask": "0.23"}], "timestamp": "1769384684626", "event_type": "price_change"}}
{"_local_timestamp": "2026-01-25T23:44:44.930453+00:00", "data": {"market": "0x512ced1584beb41cb6dacdaa92f5d67f8bee28f055ef63b251d20a446422ddaa", "price_changes": [{"asset_id": "105159270423598199664249261738928535905668234939484323704322364820483620754428", "price": "0.88", "size": "1856.99", "side": "BUY", "hash": "93c4c989a587feb4f703b909c620765d6ff66ee7", "best_bid": "0.9", "best_ask": "0.92"}, {"asset_id": "81498082395020979729835659110658786648105896152484850898743462024117016161425", "price": "0.12", "size": "1856.99", "side": "SELL", "hash": "552c3ade912db62c30507eb5ca08c9eb58300e8b", "best_bid": "0.08", "best_ask": "0.1"}], "timestamp": "1769384684625", "event_type": "price_change"}}
{"_local_timestamp": "2026-01-25T23:44:44.930729+00:00", "data": {"market": "0x8db2651deb0ca894dfec7963ff43d747e6b203d853ea102ddaaf69272fcbd14e", "price_changes": [{"asset_id": "55723215967704727452199840811929823276351711374899127881856674926400394790108", "price": "0.923", "size": "344.44", "side": "BUY", "hash": "c33548772dd870c79f02f9ceab4770410d264872", "best_bid": "0.948", "best_ask": "0.962"}, {"asset_id": "59454703894867594337219596879618679187053555828199534311880631098862267050015", "price": "0.077", "size": "344.44", "side": "SELL", "hash": "aeb5c7d3d469bade231cf73759c2e33c5eb87ebf", "best_bid": "0.038", "best_ask": "0.052"}], "timestamp": "1769384684626", "event_type": "price_change"}}
{"_local_timestamp": "2026-01-25T23:44:44.930961+00:00", "data": {"market": "0x512ced1584beb41cb6dacdaa92f5d67f8bee28f055ef63b251d20a446422ddaa", "price_changes": [{"asset_id": "105159270423598199664249261738928535905668234939484323704322364820483620754428", "price": "0.88", "size": "1831.99", "side": "BUY", "hash": "f597ef64221651e3bc5dd568129041383b5ea937", "best_bid": "0.9", "best_ask": "0.92"}, {"asset_id": "81498082395020979729835659110658786648105896152484850898743462024117016161425", "price": "0.12", "size": "1831.99", "side": "SELL", "hash": "a1c952d87962ae92234aba7cd2ddee4f610af62e", "best_bid": "0.08", "best_ask": "0.1"}], "timestamp": "1769384684627", "event_type": "price_change"}}
{"_local_timestamp": "2026-01-25T23:44:44.957549+00:00", "data": {"market": "0x512ced1584beb41cb6dacdaa92f5d67f8bee28f055ef63b251d20a446422ddaa", "price_changes": [{"asset_id": "105159270423598199664249261738928535905668234939484323704322364820483620754428", "price": "0.88", "size": "1806.99", "side": "BUY", "hash": "90417e0ab64b8cf1917a06110ad963176728decf", "best_bid": "0.9", "best_ask": "0.92"}, {"asset_id": "81498082395020979729835659110658786648105896152484850898743462024117016161425", "price": "0.12", "size": "1806.99", "side": "SELL", "hash": "407f4f358e88c2d74d1ebbdf3d097ccff1ce3f71", "best_bid": "0.08", "best_ask": "0.1"}], "timestamp": "1769384684648", "event_type": "price_change"}}
{"_local_timestamp": "2026-01-25T23:44:44.957874+00:00", "data": {"market": "0x07baddbeaa7f66706b84f167f835f3cc90782445ff36b2ea736c1c097f6ff537", "price_changes": [{"asset_id": "106820146733184719100966062623986655992997037363317463528901190592661638187355", "price": "0.34", "size": "399.99", "side": "BUY", "hash": "143f96c4a8a46a9693f3b5c9fd87772102867213", "best_bid": "0.36", "best_ask": "0.38"}, {"asset_id": "58198710311579915535691075580727536486537716969204598157134462435731312061441", "price": "0.66", "size": "399.99", "side": "SELL", "hash": "222eb82ad82ec4e22d5e3a769ee1128e5320ac92", "best_bid": "0.62", "best_ask": "0.64"}], "timestamp": "1769384684656", "event_type": "price_change"}}
{"_local_timestamp": "2026-01-25T23:44:45.042086+00:00", "data": {"market": "0xb9223ddfda277ecf96cea52aba3d6a47e3bb001bf0173fb3e2145566c28e0c24", "price_changes": [{"asset_id": "57280055515157002497847996398372581077095661831629922834612019741255629878625", "price": "0.76", "size": "499.99", "side": "BUY", "hash": "8770a35db5d3b1aef01339fd89a569d4103d01f3", "best_bid": "0.77", "best_ask": "0.8"}, {"asset_id": "64819280345421258482017346931579849092301023088943214992246376036314042237400", "price": "0.24", "size": "499.99", "side": "SELL", "hash": "969fe420a693f449767599b5c7875ca14396f7f6", "best_bid": "0.2", "best_ask": "0.23"}], "timestamp": "1769384684668", "event_type": "price_change"}}
{"_local_timestamp": "2026-01-25T23:44:45.042408+00:00", "data": {"market": "0x8db2651deb0ca894dfec7963ff43d747e6b203d853ea102ddaaf69272fcbd14e", "price_changes": [{"asset_id": "55723215967704727452199840811929823276351711374899127881856674926400394790108", "price": "0.923", "size": "293.44", "side": "BUY", "hash": "2123764c0e61f0f60b9172daf92c6f545e8c60bb", "best_bid": "0.948", "best_ask": "0.962"}, {"asset_id": "59454703894867594337219596879618679187053555828199534311880631098862267050015", "price": "0.077", "size": "293.44", "side": "SELL", "hash": "4e8f5b33c568108711b245bef81010494f10ce00", "best_bid": "0.038", "best_ask": "0.052"}], "timestamp": "1769384684673", "event_type": "price_change"}}
{"_local_timestamp": "2026-01-25T23:44:45.042870+00:00", "data": {"market": "0x8db2651deb0ca894dfec7963ff43d747e6b203d853ea102ddaaf69272fcbd14e", "price_changes": [{"asset_id": "55723215967704727452199840811929823276351711374899127881856674926400394790108", "price": "0.923", "size": "344.44", "side": "BUY", "hash": "6e84d5145611cb2630401bbc1d175ea343c30b81", "best_bid": "0.948", "best_ask": "0.962"}, {"asset_id": "59454703894867594337219596879618679187053555828199534311880631098862267050015", "price": "0.077", "size": "344.44", "side": "SELL", "hash": "e8883fac0ec5896c15e8cea89d9646e9d32ab3fb", "best_bid": "0.038", "best_ask": "0.052"}], "timestamp": "1769384684733", "event_type": "price_change"}}
{"_local_timestamp": "2026-01-25T23:44:45.043189+00:00", "data": {"market": "0x07baddbeaa7f66706b84f167f835f3cc90782445ff36b2ea736c1c097f6ff537", "price_changes": [{"asset_id": "106820146733184719100966062623986655992997037363317463528901190592661638187355", "price": "0.34", "size": "424.99", "side": "BUY", "hash": "ab67f35e064ade4621442c7913057443f01b947f", "best_bid": "0.36", "best_ask": "0.38"}, {"asset_id": "58198710311579915535691075580727536486537716969204598157134462435731312061441", "price": "0.66", "size": "424.99", "side": "SELL", "hash": "2eacfc853c4f388ad428d92f7c99f114590d3fed", "best_bid": "0.62", "best_ask": "0.64"}], "timestamp": "1769384684735", "event_type": "price_change"}}
{"_local_timestamp": "2026-01-25T23:44:45.043449+00:00", "data": {"market": "0xb9223ddfda277ecf96cea52aba3d6a47e3bb001bf0173fb3e2145566c28e0c24", "price_changes": [{"asset_id": "57280055515157002497847996398372581077095661831629922834612019741255629878625", "price": "0.76", "size": "524.99", "side": "BUY", "hash": "4f13601f36885165a31c568b7285df3d9e2dea99", "best_bid": "0.77", "best_ask": "0.8"}, {"asset_id": "64819280345421258482017346931579849092301023088943214992246376036314042237400", "price": "0.24", "size": "524.99", "side": "SELL", "hash": "52fc824387de77ee7eb33b740298363e6a18a598", "best_bid": "0.2", "best_ask": "0.23"}], "timestamp": "1769384684735", "event_type": "price_change"}}
{"_local_timestamp": "2026-01-25T23:44:45.043702+00:00", "data": {"market": "0x8db2651deb0ca894dfec7963ff43d747e6b203d853ea102ddaaf69272fcbd14e", "price_changes": [{"asset_id": "55723215967704727452199840811929823276351711374899127881856674926400394790108", "price": "0.923", "size": "395.44", "side": "BUY", "hash": "d64e74be8a287845fb146730860437bd47200639", "best_bid": "0.948", "best_ask": "0.962"}, {"asset_id": "59454703894867594337219596879618679187053555828199534311880631098862267050015", "price": "0.077", "size": "395.44", "side": "SELL", "hash": "825e5063efe7bf7f0f6fa7270e37fa0de5e0d44f", "best_bid": "0.038", "best_ask": "0.052"}], "timestamp": "1769384684736", "event_type": "price_change"}}
{"_local_timestamp": "2026-01-25T23:44:45.043965+00:00", "data": {"market": "0x512ced1584beb41cb6dacdaa92f5d67f8bee28f055ef63b251d20a446422ddaa", "price_changes": [{"asset_id": "105159270423598199664249261738928535905668234939484323704322364820483620754428", "price": "0.88", "size": "1831.99", "side": "BUY", "hash": "cf733ad740a7fe516bf1b0c81883b3eb87e779e6", "best_bid": "0.9", "best_ask": "0.92"}, {"asset_id": "81498082395020979729835659110658786648105896152484850898743462024117016161425", "price": "0.12", "size": "1831.99", "side": "SELL", "hash": "f8f2db3fbfd63033e984db63a001497ebb96a4e9", "best_bid": "0.08", "best_ask": "0.1"}], "timestamp": "1769384684739", "event_type": "price_change"}}
{"_local_timestamp": "2026-01-25T23:44:45.046240+00:00", "data": {"market": "0xb9223ddfda277ecf96cea52aba3d6a47e3bb001bf0173fb3e2145566c28e0c24", "price_changes": [{"asset_id": "57280055515157002497847996398372581077095661831629922834612019741255629878625", "price": "0.76", "size": "549.99", "side": "BUY", "hash": "557e1ec8cea31ae9cf84ea5bceef3c94d8b2e10c", "best_bid": "0.77", "best_ask": "0.8"}, {"asset_id": "64819280345421258482017346931579849092301023088943214992246376036314042237400", "price": "0.24", "size": "549.99", "side": "SELL", "hash": "73944312b67cfe5ddd1f1a2e490e5bd1e9c0b2bd", "best_bid": "0.2", "best_ask": "0.23"}], "timestamp": "1769384684740", "event_type": "price_change"}}
{"_local_timestamp": "2026-01-25T23:44:45.046490+00:00", "data": {"market": "0x07baddbeaa7f66706b84f167f835f3cc90782445ff36b2ea736c1c097f6ff537", "price_changes": [{"asset_id": "106820146733184719100966062623986655992997037363317463528901190592661638187355", "price": "0.34", "size": "449.99", "side": "BUY", "hash": "86a4bde9b8659f83107d9ebb772795bb984fe8f2", "best_bid": "0.36", "best_ask": "0.38"}, {"asset_id": "58198710311579915535691075580727536486537716969204598157134462435731312061441", "price": "0.66", "size": "449.99", "side": "SELL", "hash": "204244845d8650d63336ba3a5b05288ac263c378", "best_bid": "0.62", "best_ask": "0.64"}], "timestamp": "1769384684744", "event_type": "price_change"}}
{"_local_timestamp": "2026-01-25T23:44:45.046729+00:00", "data": {"market": "0x512ced1584beb41cb6dacdaa92f5d67f8bee28f055ef63b251d20a446422ddaa", "price_changes": [{"asset_id": "105159270423598199664249261738928535905668234939484323704322364820483620754428", "price": "0.88", "size": "1856.99", "side": "BUY", "hash": "b4aff497b7a31e16780aac5a2a59284bc733c075", "best_bid": "0.9", "best_ask": "0.92"}, {"asset_id": "81498082395020979729835659110658786648105896152484850898743462024117016161425", "price": "0.12", "size": "1856.99", "side": "SELL", "hash": "98d90393a2a7e3d19770d89f11a73695c78c18a6", "best_bid": "0.08", "best_ask": "0.1"}], "timestamp": "1769384684748", "event_type": "price_change"}}
{"_local_timestamp": "2026-01-25T23:44:45.180532+00:00", "data": {"market": "0x512ced1584beb41cb6dacdaa92f5d67f8bee28f055ef63b251d20a446422ddaa", "price_changes": [{"asset_id": "105159270423598199664249261738928535905668234939484323704322364820483620754428", "price": "0.88", "size": "1881.99", "side": "BUY", "hash": "55b5b10830c9cbce53b42362ab830c12088dc7a6", "best_bid": "0.9", "best_ask": "0.92"}, {"asset_id": "81498082395020979729835659110658786648105896152484850898743462024117016161425", "price": "0.12", "size": "1881.99", "side": "SELL", "hash": "6dca01631cb514edc95208402841e28b2711570b", "best_bid": "0.08", "best_ask": "0.1"}], "timestamp": "1769384684754", "event_type": "price_change"}}
{"_local_timestamp": "2026-01-25T23:44:45.180867+00:00", "data": {"market": "0x07baddbeaa7f66706b84f167f835f3cc90782445ff36b2ea736c1c097f6ff537", "price_changes": [{"asset_id": "106820146733184719100966062623986655992997037363317463528901190592661638187355", "price": "0.34", "size": "474.99", "side": "BUY", "hash": "7e1de71bab0634aba0ebb83cc119c069a1d89b0c", "best_bid": "0.36", "best_ask": "0.38"}, {"asset_id": "58198710311579915535691075580727536486537716969204598157134462435731312061441", "price": "0.66", "size": "474.99", "side": "SELL", "hash": "7af7e2d395edb9b830e6d48657d3626cd0bf3cc1", "best_bid": "0.62", "best_ask": "0.64"}], "timestamp": "1769384684762", "event_type": "price_change"}}
{"_local_timestamp": "2026-01-25T23:44:45.181118+00:00", "data": {"market": "0x8db2651deb0ca894dfec7963ff43d747e6b203d853ea102ddaaf69272fcbd14e", "price_changes": [{"asset_id": "55723215967704727452199840811929823276351711374899127881856674926400394790108", "price": "0.923", "size": "446.44", "side": "BUY", "hash": "81145947e35207d7107535d422808a1f7f07760f", "best_bid": "0.948", "best_ask": "0.962"}, {"asset_id": "59454703894867594337219596879618679187053555828199534311880631098862267050015", "price": "0.077", "size": "446.44", "side": "SELL", "hash": "b6ba0d2b47f9f862826af1606993fb31e268de4b", "best_bid": "0.038", "best_ask": "0.052"}], "timestamp": "1769384684775", "event_type": "price_change"}}
{"_local_timestamp": "2026-01-25T23:44:45.181361+00:00", "data": {"market": "0xb9223ddfda277ecf96cea52aba3d6a47e3bb001bf0173fb3e2145566c28e0c24", "price_changes": [{"asset_id": "57280055515157002497847996398372581077095661831629922834612019741255629878625", "price": "0.76", "size": "574.99", "side": "BUY", "hash": "bfaae4e51784161de2ae4b462ce9a005a1d1b6f1", "best_bid": "0.77", "best_ask": "0.8"}, {"asset_id": "64819280345421258482017346931579849092301023088943214992246376036314042237400", "price": "0.24", "size": "574.99", "side": "SELL", "hash": "558ea19ce70d198d3fa7e37cdfe605eed4464b4a", "best_bid": "0.2", "best_ask": "0.23"}], "timestamp": "1769384684776", "event_type": "price_change"}}
{"_local_timestamp": "2026-01-25T23:44:46.218916+00:00", "data": {"market": "0x4ddaff7ab33855ab7ed53f75ae4a331496028177f4bf0557eafe0fb83628332b", "price_changes": [{"asset_id": "25056163956965564455957738971346869740799169769422815261763807235324372823907", "price": "0.025", "size": "0", "side": "BUY", "hash": "3c54850d59a1cc58275396b5d38d31c0d1dcd251", "best_bid": "0.024", "best_ask": "0.033"}, {"asset_id": "25589742673068913841508219929281747394194738561317540491643768947357201371462", "price": "0.975", "size": "0", "side": "SELL", "hash": "bd33aeef06d7b069bd9567ca84e00dadf142c85e", "best_bid": "0.967", "best_ask": "0.976"}], "timestamp": "1769384686014", "event_type": "price_change"}}
{"_local_timestamp": "2026-01-25T23:44:46.245517+00:00", "data": {"market": "0x4ddaff7ab33855ab7ed53f75ae4a331496028177f4bf0557eafe0fb83628332b", "price_changes": [{"asset_id": "25056163956965564455957738971346869740799169769422815261763807235324372823907", "price": "0.025", "size": "435", "side": "BUY", "hash": "588427c28a26f7436d764d027152fb6e5e8c1f67", "best_bid": "0.025", "best_ask": "0.033"}, {"asset_id": "25589742673068913841508219929281747394194738561317540491643768947357201371462", "price": "0.975", "size": "435", "side": "SELL", "hash": "9edce455920262e92ca8709823b72c272b20384a", "best_bid": "0.967", "best_ask": "0.975"}], "timestamp": "1769384686056", "event_type": "price_change"}}
{"_local_timestamp": "2026-01-25T23:44:46.316746+00:00", "data": {"market": "0xb9223ddfda277ecf96cea52aba3d6a47e3bb001bf0173fb3e2145566c28e0c24", "price_changes": [{"asset_id": "57280055515157002497847996398372581077095661831629922834612019741255629878625", "price": "0.76", "size": "549.99", "side": "BUY", "hash": "f0a507d2065c156c7866ba4b522247dcfd6f5dfb", "best_bid": "0.77", "best_ask": "0.8"}, {"asset_id": "64819280345421258482017346931579849092301023088943214992246376036314042237400", "price": "0.24", "size": "549.99", "side": "SELL", "hash": "e83b2da421be22cbf694bef9f22cc0477b28f3a5", "best_bid": "0.2", "best_ask": "0.23"}], "timestamp": "1769384686132", "event_type": "price_change"}}
{"_local_timestamp": "2026-01-25T23:44:46.321947+00:00", "data": {"market": "0x07baddbeaa7f66706b84f167f835f3cc90782445ff36b2ea736c1c097f6ff537", "price_changes": [{"asset_id": "106820146733184719100966062623986655992997037363317463528901190592661638187355", "price": "0.34", "size": "449.99", "side": "BUY", "hash": "445c413a1d7c3a07a11b14b6ff0ec77d13f39797", "best_bid": "0.36", "best_ask": "0.38"}, {"asset_id": "58198710311579915535691075580727536486537716969204598157134462435731312061441", "price": "0.66", "size": "449.99", "side": "SELL", "hash": "99fa28610ec37d7c42c21d048727f82b7d337292", "best_bid": "0.62", "best_ask": "0.64"}], "timestamp": "1769384686137", "event_type": "price_change"}}
{"_local_timestamp": "2026-01-25T23:44:46.322249+00:00", "data": {"market": "0x8db2651deb0ca894dfec7963ff43d747e6b203d853ea102ddaaf69272fcbd14e", "price_changes": [{"asset_id": "55723215967704727452199840811929823276351711374899127881856674926400394790108", "price": "0.923", "size": "395.44", "side": "BUY", "hash": "3bd1a5688006a4dc96e927232e9566848063a399", "best_bid": "0.948", "best_ask": "0.962"}, {"asset_id": "59454703894867594337219596879618679187053555828199534311880631098862267050015", "price": "0.077", "size": "395.44", "side": "SELL", "hash": "b160d6087c52e3d6cba7a94429f407dbc1b85981", "best_bid": "0.038", "best_ask": "0.052"}], "timestamp": "1769384686137", "event_type": "price_change"}}
{"_local_timestamp": "2026-01-25T23:44:46.328432+00:00", "data": {"market": "0x07baddbeaa7f66706b84f167f835f3cc90782445ff36b2ea736c1c097f6ff537", "price_changes": [{"asset_id": "106820146733184719100966062623986655992997037363317463528901190592661638187355", "price": "0.34", "size": "424.99", "side": "BUY", "hash": "797a4fcc53430c95e754e94e07a2db9d7f0a81c2", "best_bid": "0.36", "best_ask": "0.38"}, {"asset_id": "58198710311579915535691075580727536486537716969204598157134462435731312061441", "price": "0.66", "size": "424.99", "side": "SELL", "hash": "36b6c4d3788cab138aefff5151a0e60afd5d8252", "best_bid": "0.62", "best_ask": "0.64"}], "timestamp": "1769384686141", "event_type": "price_change"}}
{"_local_timestamp": "2026-01-25T23:44:46.328794+00:00", "data": {"market": "0x07baddbeaa7f66706b84f167f835f3cc90782445ff36b2ea736c1c097f6ff537", "price_changes": [{"asset_id": "106820146733184719100966062623986655992997037363317463528901190592661638187355", "price": "0.34", "size": "399.99", "side": "BUY", "hash": "0b8caec295739ede97608645e2f91c130c521b58", "best_bid": "0.36", "best_ask": "0.38"}, {"asset_id": "58198710311579915535691075580727536486537716969204598157134462435731312061441", "price": "0.66", "size": "399.99", "side": "SELL", "hash": "1bf6019006a9e928eb9a7043fa8dca59c37ca737", "best_bid": "0.62", "best_ask": "0.64"}], "timestamp": "1769384686142", "event_type": "price_change"}}
{"_local_timestamp": "2026-01-25T23:44:46.330850+00:00", "data": {"market": "0x512ced1584beb41cb6dacdaa92f5d67f8bee28f055ef63b251d20a446422ddaa", "price_changes": [{"asset_id": "105159270423598199664249261738928535905668234939484323704322364820483620754428", "price": "0.88", "size": "1856.99", "side": "BUY", "hash": "8dd2ef48725f55f423ab88cabda033d2cd6d5bd4", "best_bid": "0.9", "best_ask": "0.92"}, {"asset_id": "81498082395020979729835659110658786648105896152484850898743462024117016161425", "price": "0.12", "size": "1856.99", "side": "SELL", "hash": "f0bd9c8c1a591e0ba902430fd281a274ac66dac0", "best_bid": "0.08", "best_ask": "0.1"}], "timestamp": "1769384686144", "event_type": "price_change"}}
{"_local_timestamp": "2026-01-25T23:44:46.331144+00:00", "data": {"market": "0x8db2651deb0ca894dfec7963ff43d747e6b203d853ea102ddaaf69272fcbd14e", "price_changes": [{"asset_id": "55723215967704727452199840811929823276351711374899127881856674926400394790108", "price": "0.923", "size": "344.44", "side": "BUY", "hash": "64ab3665d2c6d5ef66788faf16f09748ecbe3a81", "best_bid": "0.948", "best_ask": "0.962"}, {"asset_id": "59454703894867594337219596879618679187053555828199534311880631098862267050015", "price": "0.077", "size": "344.44", "side": "SELL", "hash": "72a303a2dbe382539d9482bf7402fd7ee735d89d", "best_bid": "0.038", "best_ask": "0.052"}], "timestamp": "1769384686144", "event_type": "price_change"}}
