{"_local_timestamp": "2026-01-25T23:41:14.625980+00:00", "data": [{"market": "0xf83cb3e04e41497723fda6e08021bda61be1da4938c007041d2d0b2dcad71797", "asset_id": "114101043942143326084243846514705158954861305743853088804574718769373357080497", "timestamp": "1769384452556", "hash": "83726e326deff638176fcf1f352d6ac43b84f396", "bids": [{"price": "0.001", "size": "7320.5"}, {"price": "0.002", "size": "1250"}, {"price": "0.004", "size": "3222"}, {"price": "0.005", "size": "8.84"}, {"price": "0.006", "size": "83"}, {"price": "0.01", "size": "150"}, {"price": "0.011", "size": "6.54"}, {"price": "0.02", "size": "400"}, {"price": "0.021", "size": "12.75"}, {"price": "0.04", "size": "12"}, {"price": "0.05", "size": "30"}, {"price": "0.051", "size": "39"}, {"price": "0.06", "size": "1233"}, {"price": "0.061", "size": "8.94"}, {"price": "0.12", "size": "1325"}, {"price": "0.121", "size": "555"}, {"price": "0.162", "size": "395.82"}, {"price": "0.163", "size": "6.34"}, {"price": "0.211", "size": "705"}, {"price": "0.212", "size": "9"}, {"price": "0.219", "size": "7"}, {"price": "0.222", "size": "10"}, {"price": "0.34", "size": "150"}, {"price": "0.341", "size": "20"}, {"price": "0.493", "size": "565"}, {"price": "0.494", "size": "66.66"}, {"price": "0.496", "size": "40"}, {"price": "0.497", "size": "45"}, {"price": "0.509", "size": "51.88"}, {"price": "0.516", "size": "10.05"}, {"price": "0.526", "size": "66.66"}, {"price": "0.559", "size": "66.66"}], "asks": [{"price": "0.999", "size": "2023.79"}, {"price": "0.998", "size": "250"}, {"price": "0.997", "size": "16.8"}, {"price": "0.99", "size": "100"}, {"price": "0.989", "size": "91"}, {"price": "0.988", "size": "5.31"}, {"price": "0.98", "size": "5000"}, {"price": "0.979", "size": "2222"}, {"price": "0.978", "size": "300"}, {"price": "0.977", "size": "66.66"}, {"price": "0.976", "size": "11.45"}, {"price": "0.946", "size": "66.66"}, {"price": "0.932", "size": "222"}, {"price": "0.929", "size": "19"}, {"price": "0.928", "size": "39.84"}, {"price": "0.912", "size": "91.66"}], "event_type": "book", "last_trade_price": "0.515"}, {"market": "0xde7ca5cc7e0c6f3e705ba793b6a31d7274ecdde51c6c6d71afcbaec89f8dd628", "asset_id": "58928203128986583178255755801066319905610768542025260186563417723289468404703", "timestamp": "1769384310221", "hash": "ffd4fe4294408cf183c71ae55ddd1157a25152b6", "bids": [{"price": "0.001", "size": "6788.57"}, {"price": "0.002", "size": "1256.55"}, {"price": "0.003", "size": "1000"}, {"price": "0.004", "size": "11.32"}, {"price": "0.01", "size": "2261"}, {"price": "0.011", "size": "5.73"}, {"price": "0.02", "size": "400"}, {"price": "0.021", "size": "11.16"}, {"price": "0.04", "size": "12"}, {"price": "0.05", "size": "30"}, {"price": "0.06", "size": "66"}, {"price": "0.061", "size": "8.48"}, {"price": "0.09", "size": "900"}, {"price": "0.13", "size": "586.53"}, {"price": "0.17", "size": "438.23"}, {"price": "0.171", "size": "6.55"}, {"price": "0.21", "size": "133.33"}, {"price": "0.26", "size": "100"}, {"price": "0.3", "size": "1180"}, {"price": "0.301", "size": "767"}, {"price": "0.305", "size": "20"}, {"price": "0.306", "size": "10"}, {"price": "0.34", "size": "58.82"}, {"price": "0.41", "size": "20"}, {"price": "0.411", "size": "20"}, {"price": "0.516", "size": "25"}, {"price": "0.517", "size": "20"}, {"price": "0.557", "size": "555"}, {"price": "0.558", "size": "100"}, {"price": "0.561", "size": "20"}, {"price": "0.562", "size": "5"}, {"price": "0.705", "size": "100"}, {"price": "0.8", "size": "10"}, {"price": "0.801", "size": "20"}, {"price": "0.803", "size": "20"}, {"price": "0.853", "size": "18.52"}], "asks": [{"price": "0.999", "size": "2781.99"}, {"price": "0.998", "size": "250"}, {"price": "0.997", "size": "19.73"}, {"price": "0.99", "size": "50"}, {"price": "0.98", "size": "2000"}, {"price": "0.979", "size": "1555"}, {"price": "0.978", "size": "66.66"}, {"price": "0.97", "size": "248.52"}, {"price": "0.969", "size": "124"}, {"price": "0.967", "size": "66.66"}, {"price": "0.966", "size": "5.87"}, {"price": "0.959", "size": "75.55"}], "event_type": "book", "last_trade_price": "0.042"}, {"market": "0xf83cb3e04e41497723fda6e08021bda61be1da4938c007041d2d0b2dcad71797", "asset_id": "106736152322901906044972029267769298472358373627784690231001806733469669851332", "timestamp": "1769384452556", "hash": "e854f055fb59acef9d43eb6e154eeea5e5ce5afe", "bids": [{"price": "0.001", "size": "2023.79"}, {"price": "0.002", "size": "250"}, {"price": "0.003", "size": "16.8"}, {"price": "0.01", "size": "100"}, {"price": "0.011", "size": "91"}, {"price": "0.012", "size": "5.31"}, {"price": "0.02", "size": "5000"}, {"price": "0.021", "size": "2222"}, {"price": "0.022", "size": "300"}, {"price": "0.023", "size": "66.66"}, {"price": "0.024", "size": "11.45"}, {"price": "0.054", "size": "66.66"}, {"price": "0.068", "size": "222"}, {"price": "0.071", "size": "19"}, {"price": "0.072", "size": "39.84"}, {"price": "0.088", "size": "91.66"}], "asks": [{"price": "0.999", "size": "7320.5"}, {"price": "0.998", "size": "1250"}, {"price": "0.996", "size": "3222"}, {"price": "0.995", "size": "8.84"}, {"price": "0.994", "size": "83"}, {"price": "0.99", "size": "150"}, {"price": "0.989", "size": "6.54"}, {"price": "0.98", "size": "400"}, {"price": "0.979", "size": "12.75"}, {"price": "0.96", "size": "12"}, {"price": "0.95", "size": "30"}, {"price": "0.949", "size": "39"}, {"price": "0.94", "size": "1233"}, {"price": "0.939", "size": "8.94"}, {"price": "0.88", "size": "1325"}, {"price": "0.879", "size": "555"}, {"price": "0.838", "size": "395.82"}, {"price": "0.837", "size": "6.34"}, {"price": "0.789", "size": "705"}, {"price": "0.788", "size": "9"}, {"price": "0.781", "size": "7"}, {"price": "0.778", "size": "10"}, {"price": "0.66", "size": "150"}, {"price": "0.659", "size": "20"}, {"price": "0.507", "size": "565"}, {"price": "0.506", "size": "66.66"}, {"price": "0.504", "size": "40"}, {"price": "0.503", "size": "45"}, {"price": "0.491", "size": "51.88"}, {"price": "0.484", "size": "10.05"}, {"price": "0.474", "size": "66.66"}, {"price": "0.441", "size": "66.66"}], "event_type": "book", "last_trade_price": "0.515"}, {"market": "0xf9f7d33b4a2595100b37b5abc0e231d56f76793516b47412d69197ae13e288c5", "asset_id": "19969062771429543855734632774811839113526280738687194048526497157873064236060", "timestamp": "1769384314160", "hash": "e7efdb54c04bc610a3e4e2c1bafc029083372e6f", "bids": [{"price": "0.01", "size": "1162.8"}, {"price": "0.02", "size": "400"}, {"price": "0.03", "size": "7.83"}, {"price": "0.04", "size": "12"}, {"price": "0.05", "size": "30"}, {"price": "0.06", "size": "66"}, {"price": "0.07", "size": "8.47"}, {"price": "0.09", "size": "900"}, {"price": "0.13", "size": "1325"}, {"price": "0.14", "size": "797.85"}, {"price": "0.19", "size": "418.42"}, {"price": "0.2", "size": "5.22"}, {"price": "0.23", "size": "121.73"}, {"price": "0.24", "size": "705"}, {"price": "0.28", "size": "92.85"}, {"price": "0.29", "size": "46"}, {"price": "0.33", "size": "72.72"}, {"price": "0.37", "size": "54.05"}, {"price": "0.41", "size": "20"}, {"price": "0.42", "size": "15"}, {"price": "0.46", "size": "10"}, {"price": "0.47", "size": "20"}, {"price": "0.5", "size": "10"}, {"price": "0.51", "size": "20"}, {"price": "0.52", "size": "20"}, {"price": "0.59", "size": "555"}, {"price": "0.6", "size": "200"}, {"price": "0.61", "size": "5"}, {"price": "0.89", "size": "37.5"}], "asks": [{"price": "0.99", "size": "5685"}, {"price": "0.98", "size": "257"}, {"price": "0.97", "size": "8.66"}, {"price": "0.96", "size": "1026"}, {"price": "0.95", "size": "204.44"}, {"price": "0.94", "size": "44.44"}, {"price": "0.93", "size": "30"}, {"price": "0.92", "size": "40.32"}], "event_type": "book", "last_trade_price": "0.080"}, {"market": "0xddcfc4f1c3ea7e3dbe0b39075d304be8ca03a320a5533fa453487baaf987e389", "asset_id": "88892523453493132977257151245860453482598424178109966987099763847933540476353", "timestamp": "1769384139269", "hash": "879d16f361e6fa2f2cc92b78e616da07a369131e", "bids": [{"price": "0.01", "size": "7018.79"}, {"price": "0.02", "size": "400"}, {"price": "0.03", "size": "10.35"}, {"price": "0.04", "size": "12"}, {"price": "0.05", "size": "30"}, {"price": "0.06", "size": "66"}, {"price": "0.07", "size": "514.28"}, {"price": "0.08", "size": "760.68"}, {"price": "0.1", "size": "340"}, {"price": "0.13", "size": "571.15"}, {"price": "0.16", "size": "175"}, {"price": "0.17", "size": "6.45"}, {"price": "0.19", "size": "150"}, {"price": "0.2", "size": "380"}, {"price": "0.21", "size": "1590"}, {"price": "0.23", "size": "659.34"}, {"price": "0.24", "size": "250"}, {"price": "0.26", "size": "176.92"}, {"price": "0.31", "size": "10"}, {"price": "0.32", "size": "20"}, {"price": "0.36", "size": "500"}, {"price": "0.37", "size": "5"}, {"price": "0.51", "size": "17.95"}, {"price": "0.52", "size": "470"}, {"price": "0.53", "size": "100"}, {"price": "0.58", "size": "100"}, {"price": "0.61", "size": "20"}], "asks": [{"price": "0.99", "size": "56.82"}, {"price": "0.97", "size": "700"}, {"price": "0.96", "size": "8.29"}, {"price": "0.92", "size": "1500"}, {"price": "0.89", "size": "150"}, {"price": "0.88", "size": "555"}, {"price": "0.87", "size": "250"}, {"price": "0.78", "size": "555"}, {"price": "0.77", "size": "133.32"}, {"price": "0.75", "size": "112.54"}], "event_type": "book", "last_trade_price": "0.250"}, {"market": "0x70573bec08bdbf9309a235a43564b69fe51f4dea221eab7addeb24da1fd3035c", "asset_id": "34328613504348250151954487489779346970796086567629120939870499285863212304815", "timestamp": "1769384454706", "hash": "a03b45386cbae0f05ea24dd8a329ba61ac590af8", "bids": [{"price": "0.01", "size": "1163.06"}, {"price": "0.02", "size": "400"}, {"price": "0.03", "size": "7.96"}, {"price": "0.04", "size": "12"}, {"price": "0.05", "size": "30"}, {"price": "0.06", "size": "66"}, {"price": "0.08", "size": "950"}, {"price": "0.09", "size": "5.9"}, {"price": "0.11", "size": "309.09"}, {"price": "0.12", "size": "1325"}, {"price": "0.13", "size": "10"}, {"price": "0.15", "size": "213.33"}, {"price": "0.16", "size": "805"}, {"price": "0.19", "size": "147.36"}, {"price": "0.2", "size": "155.49"}, {"price": "0.23", "size": "113.04"}, {"price": "0.26", "size": "92.3"}, {"price": "0.3", "size": "66.66"}, {"price": "0.31", "size": "555"}, {"price": "0.32", "size": "250"}, {"price": "0.33", "size": "20"}, {"price": "0.36", "size": "15"}, {"price": "0.4", "size": "40"}, {"price": "0.43", "size": "555"}, {"price": "0.44", "size": "100"}, {"price": "0.45", "size": "5"}, {"price": "0.58", "size": "100"}, {"price": "0.72", "size": "9.61"}, {"price": "0.73", "size": "43.46"}], "asks": [{"price": "0.99", "size": "50"}, {"price": "0.98", "size": "5.53"}, {"price": "0.97", "size": "2000"}, {"price": "0.96", "size": "43.72"}, {"price": "0.95", "size": "151.78"}, {"price": "0.9", "size": "43.72"}, {"price": "0.89", "size": "198"}, {"price": "0.88", "size": "75"}, {"price": "0.84", "size": "5"}, {"price": "0.83", "size": "49.59"}], "event_type": "book", "last_trade_price": "0.170"}, {"market": "0xddcfc4f1c3ea7e3dbe0b39075d304be8ca03a320a5533fa453487baaf987e389", "asset_id": "33101068747054334736823480974704617631786497648040798831886047820869947713624", "timestamp": "1769384139269", "hash": "d7ac7efb373ad99e12a17780c0665584c562a0fe", "bids": [{"price": "0.01", "size": "56.82"}, {"price": "0.03", "size": "700"}, {"price": "0.04", "size": "8.29"}, {"price": "0.08", "size": "1500"}, {"price": "0.11", "size": "150"}, {"price": "0.12", "size": "555"}, {"price": "0.13", "size": "250"}, {"price": "0.22", "size": "555"}, {"price": "0.23", "size": "133.32"}, {"price": "0.25", "size": "112.54"}], "asks": [{"price": "0.99", "size": "7018.79"}, {"price": "0.98", "size": "400"}, {"price": "0.97", "size": "10.35"}, {"price": "0.96", "size": "12"}, {"price": "0.95", "size": "30"}, {"price": "0.94", "size": "66"}, {"price": "0.93", "size": "514.28"}, {"price": "0.92", "size": "760.68"}, {"price": "0.9", "size": "340"}, {"price": "0.87", "size": "571.15"}, {"price": "0.84", "size": "175"}, {"price": "0.83", "size": "6.45"}, {"price": "0.81", "size": "150"}, {"price": "0.8", "size": "380"}, {"price": "0.79", "size": "1590"}, {"price": "0.77", "size": "659.34"}, {"price": "0.76", "size": "250"}, {"price": "0.74", "size": "176.92"}, {"price": "0.69", "size": "10"}, {"price": "0.68", "size": "20"}, {"price": "0.64", "size": "500"}, {"price": "0.63", "size": "5"}, {"price": "0.49", "size": "17.95"}, {"price": "0.48", "size": "470"}, {"price": "0.47", "size": "100"}, {"price": "0.42", "size": "100"}, {"price": "0.39", "size": "20"}], "event_type": "book", "last_trade_price": "0.250"}, {"market": "0xf9f7d33b4a2595100b37b5abc0e231d56f76793516b47412d69197ae13e288c5", "asset_id": "4933232974385490525590774943591844812576360482274276127001686520985156152411", "timestamp": "1769384314160", "hash": "739c0281f4f58aaf0bb1cf004694ac9f459f38f0", "bids": [{"price": "0.01", "size": "5685"}, {"price": "0.02", "size": "257"}, {"price": "0.03", "size": "8.66"}, {"price": "0.04", "size": "1026"}, {"price": "0.05", "size": "204.44"}, {"price": "0.06", "size": "44.44"}, {"price": "0.07", "size": "30"}, {"price": "0.08", "size": "40.32"}], "asks": [{"price": "0.99", "size": "1162.8"}, {"price": "0.98", "size": "400"}, {"price": "0.97", "size": "7.83"}, {"price": "0.96", "size": "12"}, {"price": "0.95", "size": "30"}, {"price": "0.94", "size": "66"}, {"price": "0.93", "size": "8.47"}, {"price": "0.91", "size": "900"}, {"price": "0.87", "size": "1325"}, {"price": "0.86", "size": "797.85"}, {"price": "0.81", "size": "418.42"}, {"price": "0.8", "size": "5.22"}, {"price": "0.77", "size": "121.73"}, {"price": "0.76", "size": "705"}, {"price": "0.72", "size": "92.85"}, {"price": "0.71", "size": "46"}, {"price": "0.67", "size": "72.72"}, {"price": "0.63", "size": "54.05"}, {"price": "0.59", "size": "20"}, {"price": "0.58", "size": "15"}, {"price": "0.54", "size": "10"}, {"price": "0.53", "size": "20"}, {"price": "0.5", "size": "10"}, {"price": "0.49", "size": "20"}, {"price": "0.48", "size": "20"}, {"price": "0.41", "size": "555"}, {"price": "0.4", "size": "200"}, {"price": "0.39", "size": "5"}, {"price": "0.11", "size": "37.5"}], "event_type": "book", "last_trade_price": "0.080"}, {"market": "0x70573bec08bdbf9309a235a43564b69fe51f4dea221eab7addeb24da1fd3035c", "asset_id": "16309849227839004264975118747976959817418505128911927142389170217137152348527", "timestamp": "1769384454706", "hash": "31d15c354dbe3c251c9d132a6c28aba4f93f62eb", "bids": [{"price": "0.01", "size": "50"}, {"price": "0.02", "size": "5.53"}, {"price": "0.03", "size": "2000"}, {"price": "0.04", "size": "43.72"}, {"price": "0.05", "size": "151.78"}, {"price": "0.1", "size": "43.72"}, {"price": "0.11", "size": "198"}, {"price": "0.12", "size": "75"}, {"price": "0.16", "size": "5"}, {"price": "0.17", "size": "49.59"}], "asks": [{"price": "0.99", "size": "1163.06"}, {"price": "0.98", "size": "400"}, {"price": "0.97", "size": "7.96"}, {"price": "0.96", "size": "12"}, {"price": "0.95", "size": "30"}, {"price": "0.94", "size": "66"}, {"price": "0.92", "size": "950"}, {"price": "0.91", "size": "5.9"}, {"price": "0.89", "size": "309.09"}, {"price": "0.88", "size": "1325"}, {"price": "0.87", "size": "10"}, {"price": "0.85", "size": "213.33"}, {"price": "0.84", "size": "805"}, {"price": "0.81", "size": "147.36"}, {"price": "0.8", "size": "155.49"}, {"price": "0.77", "size": "113.04"}, {"price": "0.74", "size": "92.3"}, {"price": "0.7", "size": "66.66"}, {"price": "0.69", "size": "555"}, {"price": "0.68", "size": "250"}, {"price": "0.67", "size": "20"}, {"price": "0.64", "size": "15"}, {"price": "0.6", "size": "40"}, {"price": "0.57", "size": "555"}, {"price": "0.56", "size": "100"}, {"price": "0.55", "size": "5"}, {"price": "0.42", "size": "100"}, {"price": "0.28", "size": "9.61"}, {"price": "0.27", "size": "43.46"}], "event_type": "book", "last_trade_price": "0.170"}, {"market": "0xde7ca5cc7e0c6f3e705ba793b6a31d7274ecdde51c6c6d71afcbaec89f8dd628", "asset_id": "63103673643335340612470219774731409977950900795403364162474548382216856767642", "timestamp": "1769384310221", "hash": "48d530bb0fe314f15bf1e868cc1861c65eafdceb", "bids": [{"price": "0.001", "size": "2781.99"}, {"price": "0.002", "size": "250"}, {"price": "0.003", "size": "19.73"}, {"price": "0.01", "size": "50"}, {"price": "0.02", "size": "2000"}, {"price": "0.021", "size": "1555"}, {"price": "0.022", "size": "66.66"}, {"price": "0.03", "size": "248.52"}, {"price": "0.031", "size": "124"}, {"price": "0.033", "size": "66.66"}, {"price": "0.034", "size": "5.87"}, {"price": "0.041", "size": "75.55"}], "asks": [{"price": "0.999", "size": "6788.57"}, {"price": "0.998", "size": "1256.55"}, {"price": "0.997", "size": "1000"}, {"price": "0.996", "size": "11.32"}, {"price": "0.99", "size": "2261"}, {"price": "0.989", "size": "5.73"}, {"price": "0.98", "size": "400"}, {"price": "0.979", "size": "11.16"}, {"price": "0.96", "size": "12"}, {"price": "0.95", "size": "30"}, {"price": "0.94", "size": "66"}, {"price": "0.939", "size": "8.48"}, {"price": "0.91", "size": "900"}, {"price": "0.87", "size": "586.53"}, {"price": "0.83", "size": "438.23"}, {"price": "0.829", "size": "6.55"}, {"price": "0.79", "size": "133.33"}, {"price": "0.74", "size": "100"}, {"price": "0.7", "size": "1180"}, {"price": "0.699", "size": "767"}, {"price": "0.695", "size": "20"}, {"price": "0.694", "size": "10"}, {"price": "0.66", "size": "58.82"}, {"price": "0.59", "size": "20"}, {"price": "0.589", "size": "20"}, {"price": "0.484", "size": "25"}, {"price": "0.483", "size": "20"}, {"price": "0.443", "size": "555"}, {"price": "0.442", "size": "100"}, {"price": "0.439", "size": "20"}, {"price": "0.438", "size": "5"}, {"price": "0.295", "size": "100"}, {"price": "0.2", "size": "10"}, {"price": "0.199", "size": "20"}, {"price": "0.197", "size": "20"}, {"price": "0.147", "size": "18.52"}], "event_type": "book", "last_trade_price": "0.042"}]}
{"_local_timestamp": "2026-01-25T23:41:41.427720+00:00", "data": {"market": "0x70573bec08bdbf9309a235a43564b69fe51f4dea221eab7addeb24da1fd3035c", "price_changes": [{"asset_id": "34328613504348250151954487489779346970796086567629120939870499285863212304815", "price": "0.73", "size": "95.51", "side": "BUY", "hash": "009a92e928e02551ff7d50eb223a95a846926a2f", "best_bid": "0.73", "best_ask": "0.83"}, {"asset_id": "16309849227839004264975118747976959817418505128911927142389170217137152348527", "price": "0.27", "size": "95.51", "side": "SELL", "hash": "ba1f8886d362f820d6051b27e0db509a158a086c", "best_bid": "0.17", "best_ask": "0.27"}], "timestamp": "1769384501358", "event_type": "price_change"}}
{"_local_timestamp": "2026-01-25T23:41:41.585266+00:00", "data": {"market": "0x70573bec08bdbf9309a235a43564b69fe51f4dea221eab7addeb24da1fd3035c", "price_changes": [{"asset_id": "34328613504348250151954487489779346970796086567629120939870499285863212304815", "price": "0.13", "size": "0", "side": "BUY", "hash": "cac58a9fd37235883948c99415a16201587de87e", "best_bid": "0.73", "best_ask": "0.83"}, {"asset_id": "16309849227839004264975118747976959817418505128911927142389170217137152348527", "price": "0.87", "size": "0", "side": "SELL", "hash": "cb6e0d66327c4177426254385bb464361fcfce68", "best_bid": "0.17", "best_ask": "0.27"}], "timestamp": "1769384501521", "event_type": "price_change"}}
{"_local_timestamp": "2026-01-25T23:41:41.682550+00:00", "data": {"market": "0x70573bec08bdbf9309a235a43564b69fe51f4dea221eab7addeb24da1fd3035c", "price_changes": [{"asset_id": "34328613504348250151954487489779346970796086567629120939870499285863212304815", "price": "0.13", "size": "10", "side": "BUY", "hash": "c0a461de1c21d608140c3f01bb552f86d8855e7a", "best_bid": "0.73", "best_ask": "0.83"}, {"asset_id": "16309849227839004264975118747976959817418505128911927142389170217137152348527", "price": "0.87", "size": "10", "side": "SELL", "hash": "6734b4095af5389fa8f06b104c52211c63f9f41e", "best_bid": "0.17", "best_ask": "0.27"}], "timestamp": "1769384501618", "event_type": "price_change"}}
{"_local_timestamp": "2026-01-25T23:41:42.074721+00:00", "data": {"market": "0x70573bec08bdbf9309a235a43564b69fe51f4dea221eab7addeb24da1fd3035c", "price_changes": [{"asset_id": "34328613504348250151954487489779346970796086567629120939870499285863212304815", "price": "0.03", "size": "7.96", "side": "BUY", "hash": "e894cf21e3ea78bd654522bc74e924b5a5aca44e", "best_bid": "0.73", "best_ask": "0.83"}, {"asset_id": "16309849227839004264975118747976959817418505128911927142389170217137152348527", "price": "0.97", "size": "7.96", "side": "SELL", "hash": "ba55065fd5fa01903e6efb91f6f595b4e5df470e", "best_bid": "0.17", "best_ask": "0.27"}], "timestamp": "1769384501908", "event_type": "price_change"}}
{"_local_timestamp": "2026-01-25T23:41:42.075155+00:00", "data": {"market": "0x70573bec08bdbf9309a235a43564b69fe51f4dea221eab7addeb24da1fd3035c", "price_changes": [{"asset_id": "34328613504348250151954487489779346970796086567629120939870499285863212304815", "price": "0.2", "size": "5.49", "side": "BUY", "hash": "e894cf21e3ea78bd654522bc74e924b5a5aca44e", "best_bid": "0.73", "best_ask": "0.83"}, {"asset_id": "16309849227839004264975118747976959817418505128911927142389170217137152348527", "price": "0.8", "size": "5.49", "side": "SELL", "hash": "ba55065fd5fa01903e6efb91f6f595b4e5df470e", "best_bid": "0.17", "best_ask": "0.27"}], "timestamp": "1769384501908", "event_type": "price_change"}}
{"_local_timestamp": "2026-01-25T23:41:52.002375+00:00", "data": {"market": "0x70573bec08bdbf9309a235a43564b69fe51f4dea221eab7addeb24da1fd3035c", "price_changes": [{"asset_id": "34328613504348250151954487489779346970796086567629120939870499285863212304815", "price": "0.23", "size": "213.04", "side": "BUY", "hash": "9ecdd071facde8b1dc4659d82dccd7e5eb74849d", "best_bid": "0.73", "best_ask": "0.83"}, {"asset_id": "16309849227839004264975118747976959817418505128911927142389170217137152348527", "price": "0.77", "size": "213.04", "side": "SELL", "hash": "8ae7e5b8641d5799f7048f38218afe4be7f9d984", "best_bid": "0.17", "best_ask": "0.27"}], "timestamp": "1769384511690", "event_type": "price_change"}}
{"_local_timestamp": "2026-01-25T23:41:52.951283+00:00", "data": {"market": "0x70573bec08bdbf9309a235a43564b69fe51f4dea221eab7addeb24da1fd3035c", "price_changes": [{"asset_id": "34328613504348250151954487489779346970796086567629120939870499285863212304815", "price": "0.32", "size": "325", "side": "BUY", "hash": "62fde043ed9c41b1a3498a1f3852079a451fa433", "best_bid": "0.73", "best_ask": "0.83"}, {"asset_id": "16309849227839004264975118747976959817418505128911927142389170217137152348527", "price": "0.68", "size": "325", "side": "SELL", "hash": "46fcbcbd95c72b16d9bd98872a910aa4f1d7002a", "best_bid": "0.17", "best_ask": "0.27"}], "timestamp": "1769384511924", "event_type": "price_change"}}
{"_local_timestamp": "2026-01-25T23:41:54.506923+00:00", "data": {"market": "0xf83cb3e04e41497723fda6e08021bda61be1da4938c007041d2d0b2dcad71797", "price_changes": [{"asset_id": "114101043942143326084243846514705158954861305743853088804574718769373357080497", "price": "0.559", "size": "0", "side": "BUY", "hash": "c1e49b2f10b0a4ae21c4e2698de19978032fe748", "best_bid": "0.516", "best_ask": "0.912"}, {"asset_id": "106736152322901906044972029267769298472358373627784690231001806733469669851332", "price": "0.441", "size": "0", "side": "SELL", "hash": "ebade2107225303118cb3c33ff5132c80b981172", "best_bid": "0.088", "best_ask": "0.484"}], "timestamp": "1769384514437", "event_type": "price_change"}}
{"_local_timestamp": "2026-01-25T23:41:54.507362+00:00", "data": {"market": "0xf83cb3e04e41497723fda6e08021bda61be1da4938c007041d2d0b2dcad71797", "price_changes": [{"asset_id": "114101043942143326084243846514705158954861305743853088804574718769373357080497", "price": "0.526", "size": "0", "side": "BUY", "hash": "c1e49b2f10b0a4ae21c4e2698de19978032fe748", "best_bid": "0.516", "best_ask": "0.912"}, {"asset_id": "106736152322901906044972029267769298472358373627784690231001806733469669851332", "price": "0.474", "size": "0", "side": "SELL", "hash": "ebade2107225303118cb3c33ff5132c80b981172", "best_bid": "0.088", "best_ask": "0.484"}], "timestamp": "1769384514437", "event_type": "price_change"}}
{"_local_timestamp": "2026-01-25T23:41:54.864115+00:00", "data": {"market": "0xf83cb3e04e41497723fda6e08021bda61be1da4938c007041d2d0b2dcad71797", "price_changes": [{"asset_id": "114101043942143326084243846514705158954861305743853088804574718769373357080497", "price": "0.517", "size": "66.66", "side": "BUY", "hash": "477ed45a81f38372c08733c1e223e831e2c9ec6c", "best_bid": "0.517", "best_ask": "0.912"}, {"asset_id": "106736152322901906044972029267769298472358373627784690231001806733469669851332", "price": "0.483", "size": "66.66", "side": "SELL", "hash": "692a1bfd4a14dbbf0336f2d2261ac5c514db2486", "best_bid": "0.088", "best_ask": "0.483"}], "timestamp": "1769384514793", "event_type": "price_change"}}
{"_local_timestamp": "2026-01-25T23:41:54.886883+00:00", "data": {"market": "0xf83cb3e04e41497723fda6e08021bda61be1da4938c007041d2d0b2dcad71797", "price_changes": [{"asset_id": "114101043942143326084243846514705158954861305743853088804574718769373357080497", "price": "0.522", "size": "20", "side": "BUY", "hash": "c20ab4959037a8e93d0afcfcf69a9deb35b12ac5", "best_bid": "0.522", "best_ask": "0.912"}, {"asset_id": "106736152322901906044972029267769298472358373627784690231001806733469669851332", "price": "0.478", "size": "20", "side": "SELL", "hash": "114e75270f46769486019470c0114cabae37bb41", "best_bid": "0.088", "best_ask": "0.478"}], "timestamp": "1769384514818", "event_type": "price_change"}}
{"_local_timestamp": "2026-01-25T23:41:54.903982+00:00", "data": {"market": "0xf83cb3e04e41497723fda6e08021bda61be1da4938c007041d2d0b2dcad71797", "price_changes": [{"asset_id": "114101043942143326084243846514705158954861305743853088804574718769373357080497", "price": "0.505", "size": "66.66", "side": "BUY", "hash": "011a5012367185a88dbb723243ca4d9dd310ae97", "best_bid": "0.522", "best_ask": "0.912"}, {"asset_id": "106736152322901906044972029267769298472358373627784690231001806733469669851332", "price": "0.495", "size": "66.66", "side": "SELL", "hash": "00db0ed644b98897c0ad86c5274eeed206280c2b", "best_bid": "0.088", "best_ask": "0.478"}], "timestamp": "1769384514834", "event_type": "price_change"}}
{"_local_timestamp": "2026-01-25T23:41:56.710024+00:00", "data": {"market": "0xf83cb3e04e41497723fda6e08021bda61be1da4938c007041d2d0b2dcad71797", "price_changes": [{"asset_id": "114101043942143326084243846514705158954861305743853088804574718769373357080497", "price": "0.527", "size": "72.1", "side": "BUY", "hash": "9ba8084b0744af71b891b42649190c468898964f", "best_bid": "0.527", "best_ask": "0.912"}, {"asset_id": "106736152322901906044972029267769298472358373627784690231001806733469669851332", "price": "0.473", "size": "72.1", "side": "SELL", "hash": "784a784fd19b296841edd210c7d35e904faac9d5", "best_bid": "0.088", "best_ask": "0.473"}], "timestamp": "1769384516645", "event_type": "price_change"}}
{"_local_timestamp": "2026-01-25T23:41:56.734658+00:00", "data": {"market": "0xf83cb3e04e41497723fda6e08021bda61be1da4938c007041d2d0b2dcad71797", "price_changes": [{"asset_id": "114101043942143326084243846514705158954861305743853088804574718769373357080497", "price": "0.522", "size": "0", "side": "BUY", "hash": "b627b9cd10bf905b9da6ba9f18aa9693af69af0d", "best_bid": "0.527", "best_ask": "0.912"}, {"asset_id": "106736152322901906044972029267769298472358373627784690231001806733469669851332", "price": "0.478", "size": "0", "side": "SELL", "hash": "dcca7a4389f6aa7cfd8d0f6938faa2b3db4ca19e", "best_bid": "0.088", "best_ask": "0.473"}], "timestamp": "1769384516669", "event_type": "price_change"}}
{"_local_timestamp": "2026-01-25T23:41:56.781589+00:00", "data": {"market": "0xf83cb3e04e41497723fda6e08021bda61be1da4938c007041d2d0b2dcad71797", "price_changes": [{"asset_id": "114101043942143326084243846514705158954861305743853088804574718769373357080497", "price": "0.536", "size": "20", "side": "BUY", "hash": "5ed8cd7870905ec1fa231d263080089152a3452b", "best_bid": "0.536", "best_ask": "0.912"}, {"asset_id": "106736152322901906044972029267769298472358373627784690231001806733469669851332", "price": "0.464", "size": "20", "side": "SELL", "hash": "140e51dab37f17ada382e50eb4b5b296a7787d8f", "best_bid": "0.088", "best_ask": "0.464"}], "timestamp": "1769384516704", "event_type": "price_change"}}
{"_local_timestamp": "2026-01-25T23:42:23.431623+00:00", "data": {"market": "0xf83cb3e04e41497723fda6e08021bda61be1da4938c007041d2d0b2dcad71797", "price_changes": [{"asset_id": "114101043942143326084243846514705158954861305743853088804574718769373357080497", "price": "0.06", "size": "533", "side": "BUY", "hash": "142f2fa43347a90e8904f6768478f494d012d003", "best_bid": "0.536", "best_ask": "0.912"}, {"asset_id": "106736152322901906044972029267769298472358373627784690231001806733469669851332", "price": "0.94", "size": "533", "side": "SELL", "hash": "1217a48bfc25e265b914dcfa84d50c2fe0ed0529", "best_bid": "0.088", "best_ask": "0.464"}], "timestamp": "1769384543337", "event_type": "price_change"}}
{"_local_timestamp": "2026-01-25T23:42:49.104045+00:00", "data": {"market": "0x70573bec08bdbf9309a235a43564b69fe51f4dea221eab7addeb24da1fd3035c", "price_changes": [{"asset_id": "34328613504348250151954487489779346970796086567629120939870499285863212304815", "price": "0.2", "size": "155.49", "side": "BUY", "hash": "e98dd938a26fb4e5bf8523a4063379a2e197222b", "best_bid": "0.73", "best_ask": "0.83"}, {"asset_id": "16309849227839004264975118747976959817418505128911927142389170217137152348527", "price": "0.8", "size": "155.49", "side": "SELL", "hash": "2170dff238096c291e5ad669841f870bfd62c328", "best_bid": "0.17", "best_ask": "0.27"}], "timestamp": "1769384568988", "event_type": "price_change"}}
{"_local_timestamp": "2026-01-25T23:42:49.107783+00:00", "data": {"market": "0x70573bec08bdbf9309a235a43564b69fe51f4dea221eab7addeb24da1fd3035c", "price_changes": [{"asset_id": "34328613504348250151954487489779346970796086567629120939870499285863212304815", "price": "0.03", "size": "707.96", "side": "BUY", "hash": "3bfdaa0f408fba235d135b2afd54139fc18742f0", "best_bid": "0.73", "best_ask": "0.83"}, {"asset_id": "16309849227839004264975118747976959817418505128911927142389170217137152348527", "price": "0.97", "size": "707.96", "side": "SELL", "hash": "7fc9dccde0886ede3f1d584707dd4d138e6c2a87", "best_bid": "0.17", "best_ask": "0.27"}], "timestamp": "1769384568988", "event_type": "price_change"}}
{"_local_timestamp": "2026-01-25T23:42:49.167673+00:00", "data": {"market": "0xf83cb3e04e41497723fda6e08021bda61be1da4938c007041d2d0b2dcad71797", "price_changes": [{"asset_id": "114101043942143326084243846514705158954861305743853088804574718769373357080497", "price": "0.496", "size": "20", "side": "BUY", "hash": "00c24bdf6e7a5459a4ff0cc0adac7f55742b6086", "best_bid": "0.536", "best_ask": "0.912"}, {"asset_id": "106736152322901906044972029267769298472358373627784690231001806733469669851332", "price": "0.504", "size": "20", "side": "SELL", "hash": "0360c440df4a3b6c72b6ce38743c2962a6a6fde0", "best_bid": "0.088", "best_ask": "0.464"}], "timestamp": "1769384569027", "event_type": "price_change"}}
{"_local_timestamp": "2026-01-25T23:42:49.206295+00:00", "data": {"market": "0xde7ca5cc7e0c6f3e705ba793b6a31d7274ecdde51c6c6d71afcbaec89f8dd628", "price_changes": [{"asset_id": "58928203128986583178255755801066319905610768542025260186563417723289468404703", "price": "0.516", "size": "10", "side": "BUY", "hash": "9926bc8603c66456339bf0463a13bb0c39d608b5", "best_bid": "0.853", "best_ask": "0.959"}, {"asset_id": "63103673643335340612470219774731409977950900795403364162474548382216856767642", "price": "0.484", "size": "10", "side": "SELL", "hash": "bab24816bf30cfecf1ea6eba23470ccd0bf05f19", "best_bid": "0.041", "best_ask": "0.147"}], "timestamp": "1769384569087", "event_type": "price_change"}}
{"_local_timestamp": "2026-01-25T23:42:49.249537+00:00", "data": {"market": "0xf83cb3e04e41497723fda6e08021bda61be1da4938c007041d2d0b2dcad71797", "price_changes": [{"asset_id": "114101043942143326084243846514705158954861305743853088804574718769373357080497", "price": "0.496", "size": "0", "side": "BUY", "hash": "1d3dfe44b62409deb6160c424a751f1578549fc2", "best_bid": "0.536", "best_ask": "0.912"}, {"asset_id": "106736152322901906044972029267769298472358373627784690231001806733469669851332", "price": "0.504", "size": "0", "side": "SELL", "hash": "74ec3fd815817300e200411d30663a78f0d92b63", "best_bid": "0.088", "best_ask": "0.464"}], "timestamp": "1769384569137", "event_type": "price_change"}}
{"_local_timestamp": "2026-01-25T23:42:49.269406+00:00", "data": {"market": "0xf83cb3e04e41497723fda6e08021bda61be1da4938c007041d2d0b2dcad71797", "price_changes": [{"asset_id": "114101043942143326084243846514705158954861305743853088804574718769373357080497", "price": "0.342", "size": "20", "side": "BUY", "hash": "e08b2713d94ed56b7d220c4fa08fa5a2530627dc", "best_bid": "0.536", "best_ask": "0.912"}, {"asset_id": "106736152322901906044972029267769298472358373627784690231001806733469669851332", "price": "0.658", "size": "20", "side": "SELL", "hash": "63210a35a500666e63d18ca37946912328a4f51c", "best_bid": "0.088", "best_ask": "0.464"}], "timestamp": "1769384569152", "event_type": "price_change"}}
{"_local_timestamp": "2026-01-25T23:42:49.321749+00:00", "data": {"market": "0xf83cb3e04e41497723fda6e08021bda61be1da4938c007041d2d0b2dcad71797", "price_changes": [{"asset_id": "114101043942143326084243846514705158954861305743853088804574718769373357080497", "price": "0.342", "size": "40", "side": "BUY", "hash": "8d3f7fc31b88a92117cdc6deb44959a64798e667", "best_bid": "0.536", "best_ask": "0.912"}, {"asset_id": "106736152322901906044972029267769298472358373627784690231001806733469669851332", "price": "0.658", "size": "40", "side": "SELL", "hash": "2fb54bf0dbba3903994e5ce74c35eab95c1be287", "best_bid": "0.088", "best_ask": "0.464"}], "timestamp": "1769384569208", "event_type": "price_change"}}
{"_local_timestamp": "2026-01-25T23:42:49.365451+00:00", "data": {"market": "0xde7ca5cc7e0c6f3e705ba793b6a31d7274ecdde51c6c6d71afcbaec89f8dd628", "price_changes": [{"asset_id": "58928203128986583178255755801066319905610768542025260186563417723289468404703", "price": "0.516", "size": "0", "side": "BUY", "hash": "0ee5c762476787300df50a172d66e4ddbee7d3df", "best_bid": "0.853", "best_ask": "0.959"}, {"asset_id": "63103673643335340612470219774731409977950900795403364162474548382216856767642", "price": "0.484", "size": "0", "side": "SELL", "hash": "15dfdc0a29ba997db8c22214e1df6fd1f18bae97", "best_bid": "0.041", "best_ask": "0.147"}], "timestamp": "1769384569258", "event_type": "price_change"}}
{"_local_timestamp": "2026-01-25T23:42:49.370557+00:00", "data": {"market": "0xf9f7d33b4a2595100b37b5abc0e231d56f76793516b47412d69197ae13e288c5", "price_changes": [{"asset_id": "19969062771429543855734632774811839113526280738687194048526497157873064236060", "price": "0.46", "size": "0", "side": "BUY", "hash": "60f0d27398c06f3c9752bafd7c33764e1fd8c937", "best_bid": "0.89", "best_ask": "0.92"}, {"asset_id": "4933232974385490525590774943591844812576360482274276127001686520985156152411", "price": "0.54", "size": "0", "side": "SELL", "hash": "1ca295c749423e7204dcf76297256b0a435198bb", "best_bid": "0.08", "best_ask": "0.11"}], "timestamp": "1769384569258", "event_type": "price_change"}}
{"_local_timestamp": "2026-01-25T23:42:49.370953+00:00", "data": {"market": "0xf9f7d33b4a2595100b37b5abc0e231d56f76793516b47412d69197ae13e288c5", "price_changes": [{"asset_id": "19969062771429543855734632774811839113526280738687194048526497157873064236060", "price": "0.42", "size": "0", "side": "BUY", "hash": "60f0d27398c06f3c9752bafd7c33764e1fd8c937", "best_bid": "0.89", "best_ask": "0.92"}, {"asset_id": "4933232974385490525590774943591844812576360482274276127001686520985156152411", "price": "0.58", "size": "0", "side": "SELL", "hash": "1ca295c749423e7204dcf76297256b0a435198bb", "best_bid": "0.08", "best_ask": "0.11"}], "timestamp": "1769384569258", "event_type": "price_change"}}
{"_local_timestamp": "2026-01-25T23:42:49.430833+00:00", "data": {"market": "0xf9f7d33b4a2595100b37b5abc0e231d56f76793516b47412d69197ae13e288c5", "price_changes": [{"asset_id": "19969062771429543855734632774811839113526280738687194048526497157873064236060", "price": "0.47", "size": "35", "side": "BUY", "hash": "7df5d4b00bb3a09990c2cf0d91aace3782c24420", "best_bid": "0.89", "best_ask": "0.92"}, {"asset_id": "4933232974385490525590774943591844812576360482274276127001686520985156152411", "price": "0.53", "size": "35", "side": "SELL", "hash": "ab79064d327a62974f2794bcd8026ecaa80444ef", "best_bid": "0.08", "best_ask": "0.11"}], "timestamp": "1769384569313", "event_type": "price_change"}}
{"_local_timestamp": "2026-01-25T23:42:49.431301+00:00", "data": {"market": "0xde7ca5cc7e0c6f3e705ba793b6a31d7274ecdde51c6c6d71afcbaec89f8dd628", "price_changes": [{"asset_id": "58928203128986583178255755801066319905610768542025260186563417723289468404703", "price": "0.518", "size": "15", "side": "BUY", "hash": "6ea58969d5d22ad3c7ba0d504abd2e6bb52624bf", "best_bid": "0.853", "best_ask": "0.959"}, {"asset_id": "63103673643335340612470219774731409977950900795403364162474548382216856767642", "price": "0.482", "size": "15", "side": "SELL", "hash": "509b0f24d7feadfaf37f90ac78f3963055fa8765", "best_bid": "0.041", "best_ask": "0.147"}], "timestamp": "1769384569313", "event_type": "price_change"}}
{"_local_timestamp": "2026-01-25T23:42:49.431650+00:00", "data": {"market": "0xf9f7d33b4a2595100b37b5abc0e231d56f76793516b47412d69197ae13e288c5", "price_changes": [{"asset_id": "19969062771429543855734632774811839113526280738687194048526497157873064236060", "price": "0.48", "size": "10", "side": "BUY", "hash": "741cbef2a56a94db36cf6ba97106fbcd493aaaf6", "best_bid": "0.89", "best_ask": "0.92"}, {"asset_id": "4933232974385490525590774943591844812576360482274276127001686520985156152411", "price": "0.52", "size": "10", "side": "SELL", "hash": "6c764e45baa77304833dca5b0a1453a5bcb64357", "best_bid": "0.08", "best_ask": "0.11"}], "timestamp": "1769384569313", "event_type": "price_change"}}
{"_local_timestamp": "2026-01-25T23:42:49.432072+00:00", "data": {"market": "0xde7ca5cc7e0c6f3e705ba793b6a31d7274ecdde51c6c6d71afcbaec89f8dd628", "price_changes": [{"asset_id": "58928203128986583178255755801066319905610768542025260186563417723289468404703", "price": "0.518", "size": "25", "side": "BUY", "hash": "419aa2c233d7cf31cd31a3e61d5bc4235539845a", "best_bid": "0.853", "best_ask": "0.959"}, {"asset_id": "63103673643335340612470219774731409977950900795403364162474548382216856767642", "price": "0.482", "size": "25", "side": "SELL", "hash": "7ba65de30e89c52bfe5d59dbbd0b7c45c4405859", "best_bid": "0.041", "best_ask": "0.147"}], "timestamp": "1769384569314", "event_type": "price_change"}}
{"_local_timestamp": "2026-01-25T23:42:49.511974+00:00", "data": {"market": "0xf83cb3e04e41497723fda6e08021bda61be1da4938c007041d2d0b2dcad71797", "price_changes": [{"asset_id": "114101043942143326084243846514705158954861305743853088804574718769373357080497", "price": "0.06", "size": "1233", "side": "BUY", "hash": "95fe48ecf3817ea5749aea70804360954adb6985", "best_bid": "0.536", "best_ask": "0.912"}, {"asset_id": "106736152322901906044972029267769298472358373627784690231001806733469669851332", "price": "0.94", "size": "1233", "side": "SELL", "hash": "2d06d2e8a4f9f63b7492201e7164e9417e772a46", "best_bid": "0.088", "best_ask": "0.464"}], "timestamp": "1769384569396", "event_type": "price_change"}}
{"_local_timestamp": "2026-01-25T23:42:49.884008+00:00", "data": {"market": "0xf9f7d33b4a2595100b37b5abc0e231d56f76793516b47412d69197ae13e288c5", "price_changes": [{"asset_id": "19969062771429543855734632774811839113526280738687194048526497157873064236060", "price": "0.47", "size": "20", "side": "BUY", "hash": "7223bb33fe32c0522243ab30dc58f1fb04a61cb5", "best_bid": "0.89", "best_ask": "0.92"}, {"asset_id": "4933232974385490525590774943591844812576360482274276127001686520985156152411", "price": "0.53", "size": "20", "side": "SELL", "hash": "a55f4b81ee45893e551a4a8460fbbf6adbd9af16", "best_bid": "0.08", "best_ask": "0.11"}], "timestamp": "1769384569785", "event_type": "price_change"}}
{"_local_timestamp": "2026-01-25T23:42:56.099026+00:00", "data": {"market": "0xf9f7d33b4a2595100b37b5abc0e231d56f76793516b47412d69197ae13e288c5", "price_changes": [{"asset_id": "19969062771429543855734632774811839113526280738687194048526497157873064236060", "price": "0.47", "size": "0", "side": "BUY", "hash": "7b13f2a21b83ef803830770e4dca703abc03aafb", "best_bid": "0.89", "best_ask": "0.92"}, {"asset_id": "4933232974385490525590774943591844812576360482274276127001686520985156152411", "price": "0.53", "size": "0", "side": "SELL", "hash": "bbd2a7d1bf4ae4888f342b253604a7a614860b46", "best_bid": "0.08", "best_ask": "0.11"}], "timestamp": "1769384576007", "event_type": "price_change"}}
{"_local_timestamp": "2026-01-25T23:42:56.099478+00:00", "data": {"market": "0xde7ca5cc7e0c6f3e705ba793b6a31d7274ecdde51c6c6d71afcbaec89f8dd628", "price_changes": [{"asset_id": "58928203128986583178255755801066319905610768542025260186563417723289468404703", "price": "0.517", "size": "0", "side": "BUY", "hash": "e8f47a4fe0fe7e6c0fde1392ef87d3caecde8603", "best_bid": "0.853", "best_ask": "0.959"}, {"asset_id": "63103673643335340612470219774731409977950900795403364162474548382216856767642", "price": "0.483", "size": "0", "side": "SELL", "hash": "059ad1995eb86406e1db8948f6c32e66a5869202", "best_bid": "0.041", "best_ask": "0.147"}], "timestamp": "1769384576007", "event_type": "price_change"}}
{"_local_timestamp": "2026-01-25T23:42:56.107972+00:00", "data": {"market": "0xf83cb3e04e41497723fda6e08021bda61be1da4938c007041d2d0b2dcad71797", "price_changes": [{"asset_id": "114101043942143326084243846514705158954861305743853088804574718769373357080497", "price": "0.341", "size": "0", "side": "BUY", "hash": "5bbdb67115564fb3c1e18bf89d720c144421504d", "best_bid": "0.536", "best_ask": "0.912"}, {"asset_id": "106736152322901906044972029267769298472358373627784690231001806733469669851332", "price": "0.659", "size": "0", "side": "SELL", "hash": "45f3df0006862f6354d2d69198421c8ac8a86c33", "best_bid": "0.088", "best_ask": "0.464"}], "timestamp": "1769384576007", "event_type": "price_change"}}
{"_local_timestamp": "2026-01-25T23:42:56.130334+00:00", "data": {"market": "0xf83cb3e04e41497723fda6e08021bda61be1da4938c007041d2d0b2dcad71797", "price_changes": [{"asset_id": "114101043942143326084243846514705158954861305743853088804574718769373357080497", "price": "0.343", "size": "20", "side": "BUY", "hash": "c83b959f33e23db7689f67cf40e9dcc07b1bb272", "best_bid": "0.536", "best_ask": "0.912"}, {"asset_id": "106736152322901906044972029267769298472358373627784690231001806733469669851332", "price": "0.657", "size": "20", "side": "SELL", "hash": "7254abf941bea43dcb89cc67d64bc17d0d006eeb", "best_bid": "0.088", "best_ask": "0.464"}], "timestamp": "1769384576036", "event_type": "price_change"}}
{"_local_timestamp": "2026-01-25T23:42:56.130840+00:00", "data": {"market": "0xde7ca5cc7e0c6f3e705ba793b6a31d7274ecdde51c6c6d71afcbaec89f8dd628", "price_changes": [{"asset_id": "58928203128986583178255755801066319905610768542025260186563417723289468404703", "price": "0.519", "size": "20", "side": "BUY", "hash": "5f07b8b1aff3615f0d45e338882297b725037765", "best_bid": "0.853", "best_ask": "0.959"}, {"asset_id": "63103673643335340612470219774731409977950900795403364162474548382216856767642", "price": "0.481", "size": "20", "side": "SELL", "hash": "c21de64933a6d835026b712b4e65cc0b6bd085bc", "best_bid": "0.041", "best_ask": "0.147"}], "timestamp": "1769384576037", "event_type": "price_change"}}
{"_local_timestamp": "2026-01-25T23:42:56.131243+00:00", "data": {"market": "0xf9f7d33b4a2595100b37b5abc0e231d56f76793516b47412d69197ae13e288c5", "price_changes": [{"asset_id": "19969062771429543855734632774811839113526280738687194048526497157873064236060", "price": "0.49", "size": "20", "side": "BUY", "hash": "c1c4b798d2dada867f5c15a296fbc29b0f03c5fb", "best_bid": "0.89", "best_ask": "0.92"}, {"asset_id": "4933232974385490525590774943591844812576360482274276127001686520985156152411", "price": "0.51", "size": "20", "side": "SELL", "hash": "dc2a9615596041c8a7a324bae924e6f07fcb6adf", "best_bid": "0.08", "best_ask": "0.11"}], "timestamp": "1769384576037", "event_type": "price_change"}}
{"_local_timestamp": "2026-01-25T23:43:21.621551+00:00", "data": {"market": "0xf83cb3e04e41497723fda6e08021bda61be1da4938c007041d2d0b2dcad71797", "price_changes": [{"asset_id": "114101043942143326084243846514705158954861305743853088804574718769373357080497", "price": "0.06", "size": "533", "side": "BUY", "hash": "694b0c92d51d8a0933ee95d4b56cf61fcedcb9a6", "best_bid": "0.536", "best_ask": "0.912"}, {"asset_id": "106736152322901906044972029267769298472358373627784690231001806733469669851332", "price": "0.94", "size": "533", "side": "SELL", "hash": "c7dcd6484434bfbc037748141bad2cae0d9fb206", "best_bid": "0.088", "best_ask": "0.464"}], "timestamp": "1769384601481", "event_type": "price_change"}}
{"_local_timestamp": "2026-01-25T23:43:21.622518+00:00", "data": {"market": "0xf83cb3e04e41497723fda6e08021bda61be1da4938c007041d2d0b2dcad71797", "price_changes": [{"asset_id": "114101043942143326084243846514705158954861305743853088804574718769373357080497", "price": "0.34", "size": "0", "side": "BUY", "hash": "694b0c92d51d8a0933ee95d4b56cf61fcedcb9a6", "best_bid": "0.536", "best_ask": "0.912"}, {"asset_id": "106736152322901906044972029267769298472358373627784690231001806733469669851332", "price": "0.66", "size": "0", "side": "SELL", "hash": "c7dcd6484434bfbc037748141bad2cae0d9fb206", "best_bid": "0.088", "best_ask": "0.464"}], "timestamp": "1769384601481", "event_type": "price_change"}}
{"_local_timestamp": "2026-01-25T23:43:41.727439+00:00", "data": {"market": "0xf83cb3e04e41497723fda6e08021bda61be1da4938c007041d2d0b2dcad71797", "price_changes": [{"asset_id": "114101043942143326084243846514705158954861305743853088804574718769373357080497", "price": "0.527", "size": "0", "side": "BUY", "hash": "5fb28054787617e3c21be6799ff58b121d806744", "best_bid": "0.536", "best_ask": "0.912"}, {"asset_id": "106736152322901906044972029267769298472358373627784690231001806733469669851332", "price": "0.473", "size": "0", "side": "SELL", "hash": "28f270c410378e082eaa1ec860cd75bdc14eccb4", "best_bid": "0.088", "best_ask": "0.464"}], "timestamp": "1769384621613", "event_type": "price_change"}}
{"_local_timestamp": "2026-01-25T23:43:45.859562+00:00", "data": {"market": "0x70573bec08bdbf9309a235a43564b69fe51f4dea221eab7addeb24da1fd3035c", "price_changes": [{"asset_id": "34328613504348250151954487489779346970796086567629120939870499285863212304815", "price": "0.73", "size": "43.46", "side": "BUY", "hash": "1ca0ce5818e79d607e8dedab42ec4d5822fa3e76", "best_bid": "0.73", "best_ask": "0.83"}, {"asset_id": "16309849227839004264975118747976959817418505128911927142389170217137152348527", "price": "0.27", "size": "43.46", "side": "SELL", "hash": "dbf592ffd343e344cb8deb563b9c2bac0db827ac", "best_bid": "0.17", "best_ask": "0.27"}], "timestamp": "1769384625741", "event_type": "price_change"}}
{"_local_timestamp": "2026-01-25T23:43:46.224270+00:00", "data": {"market": "0x70573bec08bdbf9309a235a43564b69fe51f4dea221eab7addeb24da1fd3035c", "price_changes": [{"asset_id": "34328613504348250151954487489779346970796086567629120939870499285863212304815", "price": "0.03", "size": "7.96", "side": "BUY", "hash": "a8a15473b9466d4ad1e2c20934efd73e74a0d516", "best_bid": "0.73", "best_ask": "0.83"}, {"asset_id": "16309849227839004264975118747976959817418505128911927142389170217137152348527", "price": "0.97", "size": "7.96", "side": "SELL", "hash": "6e41ad2901af6adb3b5fe9a176f1fd9f326aab51", "best_bid": "0.17", "best_ask": "0.27"}], "timestamp": "1769384626116", "event_type": "price_change"}}
{"_local_timestamp": "2026-01-25T23:43:46.224761+00:00", "data": {"market": "0x70573bec08bdbf9309a235a43564b69fe51f4dea221eab7addeb24da1fd3035c", "price_changes": [{"asset_id": "34328613504348250151954487489779346970796086567629120939870499285863212304815", "price": "0.2", "size": "5.49", "side": "BUY", "hash": "a8a15473b9466d4ad1e2c20934efd73e74a0d516", "best_bid": "0.73", "best_ask": "0.83"}, {"asset_id": "16309849227839004264975118747976959817418505128911927142389170217137152348527", "price": "0.8", "size": "5.49", "side": "SELL", "hash": "6e41ad2901af6adb3b5fe9a176f1fd9f326aab51", "best_bid": "0.17", "best_ask": "0.27"}], "timestamp": "1769384626116", "event_type": "price_change"}}
{"_local_timestamp": "2026-01-25T23:44:06.157666+00:00", "data": {"market": "0xddcfc4f1c3ea7e3dbe0b39075d304be8ca03a320a5533fa453487baaf987e389", "price_changes": [{"asset_id": "88892523453493132977257151245860453482598424178109966987099763847933540476353", "price": "0.19", "size": "0", "side": "BUY", "hash": "f3f36c13fc9a0554fa3c651d4522f67cbc6b230b", "best_bid": "0.61", "best_ask": "0.75"}, {"asset_id": "33101068747054334736823480974704617631786497648040798831886047820869947713624", "price": "0.81", "size": "0", "side": "SELL", "hash": "83102472c7535d87527a6fdcaabb4b34a47d066e", "best_bid": "0.25", "best_ask": "0.39"}], "timestamp": "1769384646006", "event_type": "price_change"}}
{"_local_timestamp": "2026-01-25T23:44:09.713649+00:00", "data": {"market": "0xf83cb3e04e41497723fda6e08021bda61be1da4938c007041d2d0b2dcad71797", "price_changes": [{"asset_id": "114101043942143326084243846514705158954861305743853088804574718769373357080497", "price": "0.06", "size": "1233", "side": "BUY", "hash": "dfbf630877423b6fabfb6b169a426fe0c736e18f", "best_bid": "0.536", "best_ask": "0.912"}, {"asset_id": "106736152322901906044972029267769298472358373627784690231001806733469669851332", "price": "0.94", "size": "1233", "side": "SELL", "hash": "4ef12cfa70751ad72b48bd843cba4af61c43f9e9", "best_bid": "0.088", "best_ask": "0.464"}], "timestamp": "1769384649563", "event_type": "price_change"}}
{"_local_timestamp": "2026-01-25T23:44:09.839878+00:00", "data": {"market": "0xf83cb3e04e41497723fda6e08021bda61be1da4938c007041d2d0b2dcad71797", "price_changes": [{"asset_id": "114101043942143326084243846514705158954861305743853088804574718769373357080497", "price": "0.34", "size": "150", "side": "BUY", "hash": "46b8eb31f745b6dfa73a3370c665fa04037b8eef", "best_bid": "0.536", "best_ask": "0.912"}, {"asset_id": "106736152322901906044972029267769298472358373627784690231001806733469669851332", "price": "0.66", "size": "150", "side": "SELL", "hash": "12797f3a08be59d30d045594c9f5f386a9fbe17e", "best_bid": "0.088", "best_ask": "0.464"}], "timestamp": "1769384649698", "event_type": "price_change"}}
{"_local_timestamp": "2026-01-25T23:44:13.464468+00:00", "data": {"market": "0x70573bec08bdbf9309a235a43564b69fe51f4dea221eab7addeb24da1fd3035c", "price_changes": [{"asset_id": "34328613504348250151954487489779346970796086567629120939870499285863212304815", "price": "0.03", "size": "707.96", "side": "BUY", "hash": "154bfb700538fd31cb6b8d9d4b906c93a5b7e1c2", "best_bid": "0.73", "best_ask": "0.83"}, {"asset_id": "16309849227839004264975118747976959817418505128911927142389170217137152348527", "price": "0.97", "size": "707.96", "side": "SELL", "hash": "d25e924f317a83e8db8efc5e473e3200c56e9a92", "best_bid": "0.17", "best_ask": "0.27"}], "timestamp": "1769384653321", "event_type": "price_change"}}
{"_local_timestamp": "2026-01-25T23:44:13.465022+00:00", "data": {"market": "0x70573bec08bdbf9309a235a43564b69fe51f4dea221eab7addeb24da1fd3035c", "price_changes": [{"asset_id": "34328613504348250151954487489779346970796086567629120939870499285863212304815", "price": "0.2", "size": "155.49", "side": "BUY", "hash": "28f653d08e314500f4385aa67e9ea1654a5c1b53", "best_bid": "0.73", "best_ask": "0.83"}, {"asset_id": "16309849227839004264975118747976959817418505128911927142389170217137152348527", "price": "0.8", "size": "155.49", "side": "SELL", "hash": "2452489d10b286c4d038cef4a9e59f7c2d317339", "best_bid": "0.17", "best_ask": "0.27"}], "timestamp": "1769384653321", "event_type": "price_change"}}
{"_local_timestamp": "2026-01-25T23:44:31.071294+00:00", "data": {"market": "0xde7ca5cc7e0c6f3e705ba793b6a31d7274ecdde51c6c6d71afcbaec89f8dd628", "price_changes": [{"asset_id": "58928203128986583178255755801066319905610768542025260186563417723289468404703", "price": "0.562", "size": "0", "side": "BUY", "hash": "f2c1f346993863a14f0d24ac0c59149e01b87911", "best_bid": "0.853", "best_ask": "0.959"}, {"asset_id": "63103673643335340612470219774731409977950900795403364162474548382216856767642", "price": "0.438", "size": "0", "side": "SELL", "hash": "1c47af630bec009cdcb63ec89cf7b99ce99a682e", "best_bid": "0.041", "best_ask": "0.147"}], "timestamp": "1769384670797", "event_type": "price_change"}}
{"_local_timestamp": "2026-01-25T23:44:31.120725+00:00", "data": {"market": "0xde7ca5cc7e0c6f3e705ba793b6a31d7274ecdde51c6c6d71afcbaec89f8dd628", "price_changes": [{"asset_id": "58928203128986583178255755801066319905610768542025260186563417723289468404703", "price": "0.562", "size": "5", "side": "BUY", "hash": "953047b049ea1b7d44e3c01115b886e27d9bda93", "best_bid": "0.853", "best_ask": "0.959"}, {"asset_id": "63103673643335340612470219774731409977950900795403364162474548382216856767642", "price": "0.438", "size": "5", "side": "SELL", "hash": "c4fcca246e2e295953e0307aba473c222520b9dc", "best_bid": "0.041", "best_ask": "0.147"}], "timestamp": "1769384670853", "event_type": "price_change"}}
{"_local_timestamp": "2026-01-25T23:44:35.789245+00:00", "data": {"market": "0x70573bec08bdbf9309a235a43564b69fe51f4dea221eab7addeb24da1fd3035c", "price_changes": [{"asset_id": "34328613504348250151954487489779346970796086567629120939870499285863212304815", "price": "0.02", "size": "0", "side": "BUY", "hash": "853ce87158c9fd08b5fdcd5fef3f4e6997b56e1d", "best_bid": "0.73", "best_ask": "0.83"}, {"asset_id": "16309849227839004264975118747976959817418505128911927142389170217137152348527", "price": "0.98", "size": "0", "side": "SELL", "hash": "02b74dd9b6cfb824024ba9fd2a01e9d8a3899b5f", "best_bid": "0.17", "best_ask": "0.27"}], "timestamp": "1769384675489", "event_type": "price_change"}}
{"_local_timestamp": "2026-01-25T23:44:36.119313+00:00", "data": {"market": "0x70573bec08bdbf9309a235a43564b69fe51f4dea221eab7addeb24da1fd3035c", "price_changes": [{"asset_id": "34328613504348250151954487489779346970796086567629120939870499285863212304815", "price": "0.03", "size": "1107.96", "side": "BUY", "hash": "cec1d92c307737e5869ecb9cac5baee664badf93", "best_bid": "0.73", "best_ask": "0.83"}, {"asset_id": "16309849227839004264975118747976959817418505128911927142389170217137152348527", "price": "0.97", "size": "1107.96", "side": "SELL", "hash": "bb86e7046dd8fdf3bf37d40d344471d202455cf9", "best_bid": "0.17", "best_ask": "0.27"}], "timestamp": "1769384675802", "event_type": "price_change"}}
{"_local_timestamp": "2026-01-25T23:44:39.034645+00:00", "data": {"market": "0xf83cb3e04e41497723fda6e08021bda61be1da4938c007041d2d0b2dcad71797", "price_changes": [{"asset_id": "114101043942143326084243846514705158954861305743853088804574718769373357080497", "price": "0.505", "size": "0", "side": "BUY", "hash": "f3c163231e6af88f7935fe346e2e02e61f18a7da", "best_bid": "0.536", "best_ask": "0.912"}, {"asset_id": "106736152322901906044972029267769298472358373627784690231001806733469669851332", "price": "0.495", "size": "0", "side": "SELL", "hash": "dab8ed36a04795fbac43d5bdf0e37ee434dfc058", "best_bid": "0.088", "best_ask": "0.464"}], "timestamp": "1769384678747", "event_type": "price_change"}}
{"_local_timestamp": "2026-01-25T23:44:39.458827+00:00", "data": {"market": "0xf83cb3e04e41497723fda6e08021bda61be1da4938c007041d2d0b2dcad71797", "price_changes": [{"asset_id": "114101043942143326084243846514705158954861305743853088804574718769373357080497", "price": "0.537", "size": "66.66", "side": "BUY", "hash": "043d4dbe0707b112be5053a17c5610dac8cd4bac", "best_bid": "0.537", "best_ask": "0.912"}, {"asset_id": "106736152322901906044972029267769298472358373627784690231001806733469669851332", "price": "0.463", "size": "66.66", "side": "SELL", "hash": "be0b8f19e77968407714ce273382b06e0c247dfe", "best_bid": "0.088", "best_ask": "0.463"}], "timestamp": "1769384679175", "event_type": "price_change"}}
{"_local_timestamp": "2026-01-25T23:44:39.464856+00:00", "data": {"market": "0xf83cb3e04e41497723fda6e08021bda61be1da4938c007041d2d0b2dcad71797", "price_changes": [{"asset_id": "114101043942143326084243846514705158954861305743853088804574718769373357080497", "price": "0.536", "size": "0", "side": "BUY", "hash": "1001b5e9b3965545fccbb6e435dd6fb48ff630ae", "best_bid": "0.537", "best_ask": "0.912"}, {"asset_id": "106736152322901906044972029267769298472358373627784690231001806733469669851332", "price": "0.464", "size": "0", "side": "SELL", "hash": "210195fcaaef0bb1896d419ec8f628fb8389091a", "best_bid": "0.088", "best_ask": "0.463"}], "timestamp": "1769384679195", "event_type": "price_change"}}
{"_local_timestamp": "2026-01-25T23:44:39.496140+00:00", "data": {"market": "0xf83cb3e04e41497723fda6e08021bda61be1da4938c007041d2d0b2dcad71797", "price_changes": [{"asset_id": "114101043942143326084243846514705158954861305743853088804574718769373357080497", "price": "0.539", "size": "20", "side": "BUY", "hash": "1a32ee3d3f1833e4aa1c75fc9ebc6f013cfcb42a", "best_bid": "0.539", "best_ask": "0.912"}, {"asset_id": "106736152322901906044972029267769298472358373627784690231001806733469669851332", "price": "0.461", "size": "20", "side": "SELL", "hash": "df301af7185a9dbb6bb6aae7721df7cd142a6ae2", "best_bid": "0.088", "best_ask": "0.461"}], "timestamp": "1769384679216", "event_type": "price_change"}}
{"_local_timestamp": "2026-01-25T23:44:47.704924+00:00", "data": {"market": "0xf83cb3e04e41497723fda6e08021bda61be1da4938c007041d2d0b2dcad71797", "price_changes": [{"asset_id": "114101043942143326084243846514705158954861305743853088804574718769373357080497", "price": "0.497", "size": "0", "side": "BUY", "hash": "92c55bbe75972f3ee561d5087b4e5e0076398f96", "best_bid": "0.539", "best_ask": "0.912"}, {"asset_id": "106736152322901906044972029267769298472358373627784690231001806733469669851332", "price": "0.503", "size": "0", "side": "SELL", "hash": "5705255a7e20895ce6c2e92ddebd39d27744becd", "best_bid": "0.088", "best_ask": "0.461"}], "timestamp": "1769384687467", "event_type": "price_change"}}
{"_local_timestamp": "2026-01-25T23:44:47.707107+00:00", "data": {"market": "0xf83cb3e04e41497723fda6e08021bda61be1da4938c007041d2d0b2dcad71797", "price_changes": [{"asset_id": "114101043942143326084243846514705158954861305743853088804574718769373357080497", "price": "0.928", "size": "0", "side": "SELL", "hash": "92c55bbe75972f3ee561d5087b4e5e0076398f96", "best_bid": "0.539", "best_ask": "0.912"}, {"asset_id": "106736152322901906044972029267769298472358373627784690231001806733469669851332", "price": "0.072", "size": "0", "side": "BUY", "hash": "5705255a7e20895ce6c2e92ddebd39d27744becd", "best_bid": "0.088", "best_ask": "0.461"}], "timestamp": "1769384687467", "event_type": "price_change"}}
{"_local_timestamp": "2026-01-25T23:45:00.954861+00:00", "data": {"market": "0x70573bec08bdbf9309a235a43564b69fe51f4dea221eab7addeb24da1fd3035c", "price_changes": [{"asset_id": "34328613504348250151954487489779346970796086567629120939870499285863212304815", "price": "0.73", "size": "95.51", "side": "BUY", "hash": "54357dfa5b7b44ae4505546af5629e763be34ff5", "best_bid": "0.73", "best_ask": "0.83"}, {"asset_id": "16309849227839004264975118747976959817418505128911927142389170217137152348527", "price": "0.27", "size": "95.51", "side": "SELL", "hash": "f15f9f05825a6e07644c424ac84b7b137fcec09e", "best_bid": "0.17", "best_ask": "0.27"}], "timestamp": "1769384700885", "event_type": "price_change"}}
{"_local_timestamp": "2026-01-25T23:45:01.044161+00:00", "data": {"market": "0xde7ca5cc7e0c6f3e705ba793b6a31d7274ecdde51c6c6d71afcbaec89f8dd628", "price_changes": [{"asset_id": "58928203128986583178255755801066319905610768542025260186563417723289468404703", "price": "0.306", "size": "0", "side": "BUY", "hash": "4b716c152ef8aaa1c7d59ddd482756fe71c86f75", "best_bid": "0.853", "best_ask": "0.959"}, {"asset_id": "63103673643335340612470219774731409977950900795403364162474548382216856767642", "price": "0.694", "size": "0", "side": "SELL", "hash": "8087fdab9a5cbcae6e19c55789f8ae5ff733d441", "best_bid": "0.041", "best_ask": "0.147"}], "timestamp": "1769384700969", "event_type": "price_change"}}
{"_local_timestamp": "2026-01-25T23:45:01.168617+00:00", "data": {"market": "0xde7ca5cc7e0c6f3e705ba793b6a31d7274ecdde51c6c6d71afcbaec89f8dd628", "price_changes": [{"asset_id": "58928203128986583178255755801066319905610768542025260186563417723289468404703", "price": "0.306", "size": "10", "side": "BUY", "hash": "92d47ae480a91884d7cd63e6c135396935ba1975", "best_bid": "0.853", "best_ask": "0.959"}, {"asset_id": "63103673643335340612470219774731409977950900795403364162474548382216856767642", "price": "0.694", "size": "10", "side": "SELL", "hash": "328f46b2abb9d51a0350e79685cccb633576428b", "best_bid": "0.041", "best_ask": "0.147"}], "timestamp": "1769384701082", "event_type": "price_change"}}
{"_local_timestamp": "2026-01-25T23:45:12.475789+00:00", "data": {"market": "0xf83cb3e04e41497723fda6e08021bda61be1da4938c007041d2d0b2dcad71797", "price_changes": [{"asset_id": "114101043942143326084243846514705158954861305743853088804574718769373357080497", "price": "0.538", "size": "70.63", "side": "BUY", "hash": "937901cc9b48f675d3b03a6954b66709bc49cb51", "best_bid": "0.539", "best_ask": "0.912"}, {"asset_id": "106736152322901906044972029267769298472358373627784690231001806733469669851332", "price": "0.462", "size": "70.63", "side": "SELL", "hash": "14e4937d66b0f9feceda8e4cb33d0ce6766434da", "best_bid": "0.088", "best_ask": "0.461"}], "timestamp": "1769384712405", "event_type": "price_change"}}
{"_local_timestamp": "2026-01-25T23:45:14.580271+00:00", "data": {"market": "0xf83cb3e04e41497723fda6e08021bda61be1da4938c007041d2d0b2dcad71797", "price_changes": [{"asset_id": "114101043942143326084243846514705158954861305743853088804574718769373357080497", "price": "0.928", "size": "39.84", "side": "SELL", "hash": "f045d813f80e7d5d7e6181d347ff542af9517bf7", "best_bid": "0.539", "best_ask": "0.912"}, {"asset_id": "106736152322901906044972029267769298472358373627784690231001806733469669851332", "price": "0.072", "size": "39.84", "side": "BUY", "hash": "ee6d86a609747923f918899a59c8ddf3612bf4ea", "best_bid": "0.088", "best_ask": "0.461"}], "timestamp": "1769384714515", "event_type": "price_change"}}
{"_local_timestamp": "2026-01-25T23:45:18.663205+00:00", "data": {"market": "0xf83cb3e04e41497723fda6e08021bda61be1da4938c007041d2d0b2dcad71797", "price_changes": [{"asset_id": "114101043942143326084243846514705158954861305743853088804574718769373357080497", "price": "0.54", "size": "45", "side": "BUY", "hash": "2ad2fa71353a2dbad559cecd0eba5a09b97c9c2f", "best_bid": "0.54", "best_ask": "0.912"}, {"asset_id": "106736152322901906044972029267769298472358373627784690231001806733469669851332", "price": "0.46", "size": "45", "side": "SELL", "hash": "59566223130b04e3ec8b832d876331ac99db6c8f", "best_bid": "0.088", "best_ask": "0.46"}], "timestamp": "1769384718588", "event_type": "price_change"}}
{"_local_timestamp": "2026-01-25T23:45:20.478429+00:00", "data": {"market": "0xf83cb3e04e41497723fda6e08021bda61be1da4938c007041d2d0b2dcad71797", "price_changes": [{"asset_id": "114101043942143326084243846514705158954861305743853088804574718769373357080497", "price": "0.06", "size": "533", "side": "BUY", "hash": "10db90ed4a45bd322a92cdf1b4f546778fac7dd5", "best_bid": "0.54", "best_ask": "0.912"}, {"asset_id": "106736152322901906044972029267769298472358373627784690231001806733469669851332", "price": "0.94", "size": "533", "side": "SELL", "hash": "12fd1d0e6e5cd02e3a7fcfe7830c7d327417bf3a", "best_bid": "0.088", "best_ask": "0.46"}], "timestamp": "1769384720414", "event_type": "price_change"}}
{"_local_timestamp": "2026-01-25T23:45:33.178728+00:00", "data": {"market": "0xf83cb3e04e41497723fda6e08021bda61be1da4938c007041d2d0b2dcad71797", "price_changes": [{"asset_id": "114101043942143326084243846514705158954861305743853088804574718769373357080497", "price": "0.538", "size": "0", "side": "BUY", "hash": "373e1638389816f4b006b3f33cc67caaeede47bb", "best_bid": "0.54", "best_ask": "0.912"}, {"asset_id": "106736152322901906044972029267769298472358373627784690231001806733469669851332", "price": "0.462", "size": "0", "side": "SELL", "hash": "33a0c4b66039b01c85fbedb93900a19b2f232514", "best_bid": "0.088", "best_ask": "0.46"}], "timestamp": "1769384733112", "event_type": "price_change"}}
{"_local_timestamp": "2026-01-25T23:45:35.186843+00:00", "data": {"market": "0xf83cb3e04e41497723fda6e08021bda61be1da4938c007041d2d0b2dcad71797", "price_changes": [{"asset_id": "114101043942143326084243846514705158954861305743853088804574718769373357080497", "price": "0.06", "size": "1233", "side": "BUY", "hash": "7ab017108a4f27f01c65fa18b2b3333cbf7b8088", "best_bid": "0.54", "best_ask": "0.912"}, {"asset_id": "106736152322901906044972029267769298472358373627784690231001806733469669851332", "price": "0.94", "size": "1233", "side": "SELL", "hash": "3bf304c202b6eaf58cf3c17dcc8f87a6f263c8f1", "best_bid": "0.088", "best_ask": "0.46"}], "timestamp": "1769384735120", "event_type": "price_change"}}
{"_local_timestamp": "2026-01-25T23:45:43.179789+00:00", "data": {"market": "0x70573bec08bdbf9309a235a43564b69fe51f4dea221eab7addeb24da1fd3035c", "price_changes": [{"asset_id": "34328613504348250151954487489779346970796086567629120939870499285863212304815", "price": "0.03", "size": "407.96", "side": "BUY", "hash": "e64f5e8aa1da4574589eb710d676e1bba0fdb621", "best_bid": "0.73", "best_ask": "0.83"}, {"asset_id": "16309849227839004264975118747976959817418505128911927142389170217137152348527", "price": "0.97", "size": "407.96", "side": "SELL", "hash": "09659d1bea61c943d9d930f72a2dfc5109dd00bc", "best_bid": "0.17", "best_ask": "0.27"}], "timestamp": "1769384743115", "event_type": "price_change"}}
{"_local_timestamp": "2026-01-25T23:45:43.180347+00:00", "data": {"market": "0x70573bec08bdbf9309a235a43564b69fe51f4dea221eab7addeb24da1fd3035c", "price_changes": [{"asset_id": "34328613504348250151954487489779346970796086567629120939870499285863212304815", "price": "0.2", "size": "5.49", "side": "BUY", "hash": "e64f5e8aa1da4574589eb710d676e1bba0fdb621", "best_bid": "0.73", "best_ask": "0.83"}, {"asset_id": "16309849227839004264975118747976959817418505128911927142389170217137152348527", "price": "0.8", "size": "5.49", "side": "SELL", "hash": "09659d1bea61c943d9d930f72a2dfc5109dd00bc", "best_bid": "0.17", "best_ask": "0.27"}], "timestamp": "1769384743115", "event_type": "price_change"}}
{"_local_timestamp": "2026-01-25T23:45:46.249959+00:00", "data": {"market": "0xf83cb3e04e41497723fda6e08021bda61be1da4938c007041d2d0b2dcad71797", "price_changes": [{"asset_id": "114101043942143326084243846514705158954861305743853088804574718769373357080497", "price": "0.541", "size": "9.24", "side": "BUY", "hash": "5af608b1333be3249886b6b9582603f613f5e612", "best_bid": "0.541", "best_ask": "0.912"}, {"asset_id": "106736152322901906044972029267769298472358373627784690231001806733469669851332", "price": "0.459", "size": "9.24", "side": "SELL", "hash": "72d8bba5d1030d9d893a5bc8a79f2bc0fa0ef671", "best_bid": "0.088", "best_ask": "0.459"}], "timestamp": "1769384746182", "event_type": "price_change"}}
{"_local_timestamp": "2026-01-25T23:45:53.078733+00:00", "data": {"market": "0xf83cb3e04e41497723fda6e08021bda61be1da4938c007041d2d0b2dcad71797", "price_changes": [{"asset_id": "114101043942143326084243846514705158954861305743853088804574718769373357080497", "price": "0.211", "size": "655", "side": "BUY", "hash": "84003909ed381e84518c132dd3faa73cbc0f19ec", "best_bid": "0.541", "best_ask": "0.912"}, {"asset_id": "106736152322901906044972029267769298472358373627784690231001806733469669851332", "price": "0.789", "size": "655", "side": "SELL", "hash": "9041aa76a01424f78f46dba3ce4bfb487cee40b8", "best_bid": "0.088", "best_ask": "0.459"}], "timestamp": "1769384752996", "event_type": "price_change"}}
{"_local_timestamp": "2026-01-25T23:46:02.235432+00:00", "data": {"market": "0x70573bec08bdbf9309a235a43564b69fe51f4dea221eab7addeb24da1fd3035c", "price_changes": [{"asset_id": "34328613504348250151954487489779346970796086567629120939870499285863212304815", "price": "0.01", "size": "1150", "side": "BUY", "hash": "4d68a296eed87942df1f96ea97c7c6ddad789b45", "best_bid": "0.73", "best_ask": "0.83"}, {"asset_id": "16309849227839004264975118747976959817418505128911927142389170217137152348527", "price": "0.99", "size": "1150", "side": "SELL", "hash": "a4f4f51c0dd473ed3cd98121cd8ae55e3127fcdb", "best_bid": "0.17", "best_ask": "0.27"}], "timestamp": "1769384762166", "event_type": "price_change"}}
{"_local_timestamp": "2026-01-25T23:46:02.235998+00:00", "data": {"market": "0x70573bec08bdbf9309a235a43564b69fe51f4dea221eab7addeb24da1fd3035c", "price_changes": [{"asset_id": "34328613504348250151954487489779346970796086567629120939870499285863212304815", "price": "0.03", "size": "400", "side": "BUY", "hash": "4d68a296eed87942df1f96ea97c7c6ddad789b45", "best_bid": "0.73", "best_ask": "0.83"}, {"asset_id": "16309849227839004264975118747976959817418505128911927142389170217137152348527", "price": "0.97", "size": "400", "side": "SELL", "hash": "a4f4f51c0dd473ed3cd98121cd8ae55e3127fcdb", "best_bid": "0.17", "best_ask": "0.27"}], "timestamp": "1769384762166", "event_type": "price_change"}}
{"_local_timestamp": "2026-01-25T23:46:04.884094+00:00", "data": {"market": "0x70573bec08bdbf9309a235a43564b69fe51f4dea221eab7addeb24da1fd3035c", "price_changes": [{"asset_id": "34328613504348250151954487489779346970796086567629120939870499285863212304815", "price": "0.04", "size": "19.52", "side": "BUY", "hash": "ba4dd4bd489bc10c9dee84abc43677540c8a255c", "best_bid": "0.73", "best_ask": "0.83"}, {"asset_id": "16309849227839004264975118747976959817418505128911927142389170217137152348527", "price": "0.96", "size": "19.52", "side": "SELL", "hash": "47c9846db13041de8900ab4722864c35c6351270", "best_bid": "0.17", "best_ask": "0.27"}], "timestamp": "1769384764814", "event_type": "price_change"}}
{"_local_timestamp": "2026-01-25T23:46:04.897229+00:00", "data": {"market": "0x70573bec08bdbf9309a235a43564b69fe51f4dea221eab7addeb24da1fd3035c", "price_changes": [{"asset_id": "34328613504348250151954487489779346970796086567629120939870499285863212304815", "price": "0.01", "size": "1156.99", "side": "BUY", "hash": "39ff131ab94096acf42b21bc6dd714a39d1d28de", "best_bid": "0.73", "best_ask": "0.83"}, {"asset_id": "16309849227839004264975118747976959817418505128911927142389170217137152348527", "price": "0.99", "size": "1156.99", "side": "SELL", "hash": "f406460001511b75a10bde11c6962a5840527cf8", "best_bid": "0.17", "best_ask": "0.27"}], "timestamp": "1769384764823", "event_type": "price_change"}}
{"_local_timestamp": "2026-01-25T23:46:08.701820+00:00", "data": {"market": "0xf83cb3e04e41497723fda6e08021bda61be1da4938c007041d2d0b2dcad71797", "price_changes": [{"asset_id": "114101043942143326084243846514705158954861305743853088804574718769373357080497", "price": "0.06", "size": "533", "side": "BUY", "hash": "ea332029abaee7d27eb91fa3a50b518d82b18a19", "best_bid": "0.541", "best_ask": "0.912"}, {"asset_id": "106736152322901906044972029267769298472358373627784690231001806733469669851332", "price": "0.94", "size": "533", "side": "SELL", "hash": "91b25b976b329319938c197468aa1d5aa5c1e3d2", "best_bid": "0.088", "best_ask": "0.459"}], "timestamp": "1769384768633", "event_type": "price_change"}}
{"_local_timestamp": "2026-01-25T23:46:18.547382+00:00", "data": {"market": "0xf83cb3e04e41497723fda6e08021bda61be1da4938c007041d2d0b2dcad71797", "price_changes": [{"asset_id": "114101043942143326084243846514705158954861305743853088804574718769373357080497", "price": "0.06", "size": "1233", "side": "BUY", "hash": "5197fa8d8129e02829af5a4f2ce938067448031e", "best_bid": "0.541", "best_ask": "0.912"}, {"asset_id": "106736152322901906044972029267769298472358373627784690231001806733469669851332", "price": "0.94", "size": "1233", "side": "SELL", "hash": "0efeeaffa83f1ab58eead6a3d20668d32a520fa9", "best_bid": "0.088", "best_ask": "0.459"}], "timestamp": "1769384778478", "event_type": "price_change"}}
{"_local_timestamp": "2026-01-25T23:46:50.791707+00:00", "data": {"market": "0x70573bec08bdbf9309a235a43564b69fe51f4dea221eab7addeb24da1fd3035c", "price_changes": [{"asset_id": "34328613504348250151954487489779346970796086567629120939870499285863212304815", "price": "0.23", "size": "113.04", "side": "BUY", "hash": "be015d2b0ee2833cb1b5718dcd5eb04d85c5888b", "best_bid": "0.73", "best_ask": "0.83"}, {"asset_id": "16309849227839004264975118747976959817418505128911927142389170217137152348527", "price": "0.77", "size": "113.04", "side": "SELL", "hash": "7e13884db3894a38b950e3d6bccd4ca82dbcfb9e", "best_bid": "0.17", "best_ask": "0.27"}], "timestamp": "1769384810648", "event_type": "price_change"}}
{"_local_timestamp": "2026-01-25T23:46:50.792568+00:00", "data": {"market": "0x70573bec08bdbf9309a235a43564b69fe51f4dea221eab7addeb24da1fd3035c", "price_changes": [{"asset_id": "34328613504348250151954487489779346970796086567629120939870499285863212304815", "price": "0.32", "size": "250", "side": "BUY", "hash": "be015d2b0ee2833cb1b5718dcd5eb04d85c5888b", "best_bid": "0.73", "best_ask": "0.83"}, {"asset_id": "16309849227839004264975118747976959817418505128911927142389170217137152348527", "price": "0.68", "size": "250", "side": "SELL", "hash": "7e13884db3894a38b950e3d6bccd4ca82dbcfb9e", "best_bid": "0.17", "best_ask": "0.27"}], "timestamp": "1769384810648", "event_type": "price_change"}}
{"_local_timestamp": "2026-01-25T23:46:51.153771+00:00", "data": {"market": "0xde7ca5cc7e0c6f3e705ba793b6a31d7274ecdde51c6c6d71afcbaec89f8dd628", "price_changes": [{"asset_id": "58928203128986583178255755801066319905610768542025260186563417723289468404703", "price": "0.518", "size": "15", "side": "BUY", "hash": "099506f71e78ce03e79282de711d27616c9c9a9b", "best_bid": "0.853", "best_ask": "0.959"}, {"asset_id": "63103673643335340612470219774731409977950900795403364162474548382216856767642", "price": "0.482", "size": "15", "side": "SELL", "hash": "3269d515c6fb304b7d237c89104307d7edde2ffd", "best_bid": "0.041", "best_ask": "0.147"}], "timestamp": "1769384810897", "event_type": "price_change"}}
{"_local_timestamp": "2026-01-25T23:46:51.591174+00:00", "data": {"market": "0xf9f7d33b4a2595100b37b5abc0e231d56f76793516b47412d69197ae13e288c5", "price_changes": [{"asset_id": "19969062771429543855734632774811839113526280738687194048526497157873064236060", "price": "0.48", "size": "0", "side": "BUY", "hash": "8a914241248169a1a16a7e761f7c92cd920ca2a0", "best_bid": "0.89", "best_ask": "0.92"}, {"asset_id": "4933232974385490525590774943591844812576360482274276127001686520985156152411", "price": "0.52", "size": "0", "side": "SELL", "hash": "51339453f9357c752241720929d4db2222b9d27e", "best_bid": "0.08", "best_ask": "0.11"}], "timestamp": "1769384811267", "event_type": "price_change"}}
{"_local_timestamp": "2026-01-25T23:46:51.756423+00:00", "data": {"market": "0xf9f7d33b4a2595100b37b5abc0e231d56f76793516b47412d69197ae13e288c5", "price_changes": [{"asset_id": "19969062771429543855734632774811839113526280738687194048526497157873064236060", "price": "0.42", "size": "10", "side": "BUY", "hash": "0a8907e5afc8d1432be29d3a8890d0c4355c3f47", "best_bid": "0.89", "best_ask": "0.92"}, {"asset_id": "4933232974385490525590774943591844812576360482274276127001686520985156152411", "price": "0.58", "size": "10", "side": "SELL", "hash": "fcc3c6d8962bc0d2889cae843023efeca182dec9", "best_bid": "0.08", "best_ask": "0.11"}], "timestamp": "1769384811652", "event_type": "price_change"}}
{"_local_timestamp": "2026-01-25T23:46:51.768761+00:00", "data": {"market": "0xf9f7d33b4a2595100b37b5abc0e231d56f76793516b47412d69197ae13e288c5", "price_changes": [{"asset_id": "19969062771429543855734632774811839113526280738687194048526497157873064236060", "price": "0.42", "size": "25", "side": "BUY", "hash": "d686ab5e796282367e766005f1083770b819c2e0", "best_bid": "0.89", "best_ask": "0.92"}, {"asset_id": "4933232974385490525590774943591844812576360482274276127001686520985156152411", "price": "0.58", "size": "25", "side": "SELL", "hash": "0e689720d8e4632e660613691e480967e66d6a16", "best_bid": "0.08", "best_ask": "0.11"}], "timestamp": "1769384811653", "event_type": "price_change"}}
{"_local_timestamp": "2026-01-25T23:46:55.388569+00:00", "data": {"market": "0xf9f7d33b4a2595100b37b5abc0e231d56f76793516b47412d69197ae13e288c5", "price_changes": [{"asset_id": "19969062771429543855734632774811839113526280738687194048526497157873064236060", "price": "0.49", "size": "0", "side": "BUY", "hash": "fa06ea09f169c177e2ccfdf2bbaf50e6feacc460", "best_bid": "0.89", "best_ask": "0.92"}, {"asset_id": "4933232974385490525590774943591844812576360482274276127001686520985156152411", "price": "0.51", "size": "0", "side": "SELL", "hash": "cee0f41d41b4741fc59365ddc62305367c81b7c5", "best_bid": "0.08", "best_ask": "0.11"}], "timestamp": "1769384815323", "event_type": "price_change"}}
{"_local_timestamp": "2026-01-25T23:46:55.418187+00:00", "data": {"market": "0xf9f7d33b4a2595100b37b5abc0e231d56f76793516b47412d69197ae13e288c5", "price_changes": [{"asset_id": "19969062771429543855734632774811839113526280738687194048526497157873064236060", "price": "0.43", "size": "20", "side": "BUY", "hash": "07ad3036ffe869a815cf6ed038e502babe65c2bc", "best_bid": "0.89", "best_ask": "0.92"}, {"asset_id": "4933232974385490525590774943591844812576360482274276127001686520985156152411", "price": "0.57", "size": "20", "side": "SELL", "hash": "558271978aeb4fadaf0c7b157ab1995c8ee42673", "best_bid": "0.08", "best_ask": "0.11"}], "timestamp": "1769384815354", "event_type": "price_change"}}
{"_local_timestamp": "2026-01-25T23:46:55.562873+00:00", "data": {"market": "0xde7ca5cc7e0c6f3e705ba793b6a31d7274ecdde51c6c6d71afcbaec89f8dd628", "price_changes": [{"asset_id": "58928203128986583178255755801066319905610768542025260186563417723289468404703", "price": "0.518", "size": "0", "side": "BUY", "hash": "9cd29d9bffc773913197f27ab2e9dc5fa403c479", "best_bid": "0.853", "best_ask": "0.959"}, {"asset_id": "63103673643335340612470219774731409977950900795403364162474548382216856767642", "price": "0.482", "size": "0", "side": "SELL", "hash": "6b207e5e25166d7e082b83f0bfd4c1fd16851fe6", "best_bid": "0.041", "best_ask": "0.147"}], "timestamp": "1769384815493", "event_type": "price_change"}}
{"_local_timestamp": "2026-01-25T23:46:55.604771+00:00", "data": {"market": "0xde7ca5cc7e0c6f3e705ba793b6a31d7274ecdde51c6c6d71afcbaec89f8dd628", "price_changes": [{"asset_id": "58928203128986583178255755801066319905610768542025260186563417723289468404703", "price": "0.52", "size": "15", "side": "BUY", "hash": "8216c8bb785327dcb63423245a352cef4d0af52c", "best_bid": "0.853", "best_ask": "0.959"}, {"asset_id": "63103673643335340612470219774731409977950900795403364162474548382216856767642", "price": "0.48", "size": "15", "side": "SELL", "hash": "467ead828bc47f7ddd8a3182a2ae43174b7c5382", "best_bid": "0.041", "best_ask": "0.147"}], "timestamp": "1769384815542", "event_type": "price_change"}}
{"_local_timestamp": "2026-01-25T23:46:55.615546+00:00", "data": {"market": "0xde7ca5cc7e0c6f3e705ba793b6a31d7274ecdde51c6c6d71afcbaec89f8dd628", "price_changes": [{"asset_id": "58928203128986583178255755801066319905610768542025260186563417723289468404703", "price": "0.52", "size": "25", "side": "BUY", "hash": "3a526b1c9a2d2d769a0700fc65e77641941e6bbd", "best_bid": "0.853", "best_ask": "0.959"}, {"asset_id": "63103673643335340612470219774731409977950900795403364162474548382216856767642", "price": "0.48", "size": "25", "side": "SELL", "hash": "283ef600c84ad4cd20de956c3d43d3e007572d42", "best_bid": "0.041", "best_ask": "0.147"}], "timestamp": "1769384815544", "event_type": "price_change"}}
{"_local_timestamp": "2026-01-25T23:46:59.345367+00:00", "data": {"market": "0xde7ca5cc7e0c6f3e705ba793b6a31d7274ecdde51c6c6d71afcbaec89f8dd628", "price_changes": [{"asset_id": "58928203128986583178255755801066319905610768542025260186563417723289468404703", "price": "0.519", "size": "0", "side": "BUY", "hash": "5bbefd7e51ee88ed46c270c9aa16b54048dc06e5", "best_bid": "0.853", "best_ask": "0.959"}, {"asset_id": "63103673643335340612470219774731409977950900795403364162474548382216856767642", "price": "0.481", "size": "0", "side": "SELL", "hash": "ad27667cdac34807981ae65c2b4408a84219aff9", "best_bid": "0.041", "best_ask": "0.147"}], "timestamp": "1769384819241", "event_type": "price_change"}}
{"_local_timestamp": "2026-01-25T23:46:59.363130+00:00", "data": {"market": "0xde7ca5cc7e0c6f3e705ba793b6a31d7274ecdde51c6c6d71afcbaec89f8dd628", "price_changes": [{"asset_id": "58928203128986583178255755801066319905610768542025260186563417723289468404703", "price": "0.521", "size": "20", "side": "BUY", "hash": "a44b9cf625122321a3f89d40250e1f179cdcaca6", "best_bid": "0.853", "best_ask": "0.959"}, {"asset_id": "63103673643335340612470219774731409977950900795403364162474548382216856767642", "price": "0.479", "size": "20", "side": "SELL", "hash": "400fcc12d4a086bd29bab9d6a3621d1715153cb1", "best_bid": "0.041", "best_ask": "0.147"}], "timestamp": "1769384819277", "event_type": "price_change"}}
{"_local_timestamp": "2026-01-25T23:47:00.500010+00:00", "data": {"market": "0x70573bec08bdbf9309a235a43564b69fe51f4dea221eab7addeb24da1fd3035c", "price_changes": [{"asset_id": "34328613504348250151954487489779346970796086567629120939870499285863212304815", "price": "0.2", "size": "155.49", "side": "BUY", "hash": "4b91c4a1b32f91e2950cf762b15cc3b47353db38", "best_bid": "0.73", "best_ask": "0.83"}, {"asset_id": "16309849227839004264975118747976959817418505128911927142389170217137152348527", "price": "0.8", "size": "155.49", "side": "SELL", "hash": "63fabae6a10c420d30f2fcf442d7fc4ec2c44552", "best_bid": "0.17", "best_ask": "0.27"}], "timestamp": "1769384820427", "event_type": "price_change"}}
{"_local_timestamp": "2026-01-25T23:47:00.500615+00:00", "data": {"market": "0x70573bec08bdbf9309a235a43564b69fe51f4dea221eab7addeb24da1fd3035c", "price_changes": [{"asset_id": "34328613504348250151954487489779346970796086567629120939870499285863212304815", "price": "0.03", "size": "1100", "side": "BUY", "hash": "65972b4651072eabd4686cd79d8d48e50d55c689", "best_bid": "0.73", "best_ask": "0.83"}, {"asset_id": "16309849227839004264975118747976959817418505128911927142389170217137152348527", "price": "0.97", "size": "1100", "side": "SELL", "hash": "36610e2b8628c827743b6150ca1e9c2faafbc9d3", "best_bid": "0.17", "best_ask": "0.27"}], "timestamp": "1769384820428", "event_type": "price_change"}}
{"_local_timestamp": "2026-01-25T23:47:05.405545+00:00", "data": {"market": "0x70573bec08bdbf9309a235a43564b69fe51f4dea221eab7addeb24da1fd3035c", "price_changes": [{"asset_id": "34328613504348250151954487489779346970796086567629120939870499285863212304815", "price": "0.73", "size": "43.46", "side": "BUY", "hash": "404e0df81e6b5fb572e1ffabaf300629eb461368", "best_bid": "0.73", "best_ask": "0.83"}, {"asset_id": "16309849227839004264975118747976959817418505128911927142389170217137152348527", "price": "0.27", "size": "43.46", "side": "SELL", "hash": "c214ffaa0557e8a61d536ba3b76aa7de8f50834f", "best_bid": "0.17", "best_ask": "0.27"}], "timestamp": "1769384825331", "event_type": "price_change"}}
{"_local_timestamp": "2026-01-25T23:47:14.453118+00:00", "data": {"market": "0x70573bec08bdbf9309a235a43564b69fe51f4dea221eab7addeb24da1fd3035c", "price_changes": [{"asset_id": "34328613504348250151954487489779346970796086567629120939870499285863212304815", "price": "0.03", "size": "400", "side": "BUY", "hash": "b05681dae9e1f304e2aa2839397395de70174c0f", "best_bid": "0.73", "best_ask": "0.83"}, {"asset_id": "16309849227839004264975118747976959817418505128911927142389170217137152348527", "price": "0.97", "size": "400", "side": "SELL", "hash": "df2908393f18c1a9445b7473d2bc339b1ac8378b", "best_bid": "0.17", "best_ask": "0.27"}], "timestamp": "1769384834381", "event_type": "price_change"}}
{"_local_timestamp": "2026-01-25T23:47:14.453706+00:00", "data": {"market": "0x70573bec08bdbf9309a235a43564b69fe51f4dea221eab7addeb24da1fd3035c", "price_changes": [{"asset_id": "34328613504348250151954487489779346970796086567629120939870499285863212304815", "price": "0.2", "size": "5.49", "side": "BUY", "hash": "b05681dae9e1f304e2aa2839397395de70174c0f", "best_bid": "0.73", "best_ask": "0.83"}, {"asset_id": "16309849227839004264975118747976959817418505128911927142389170217137152348527", "price": "0.8", "size": "5.49", "side": "SELL", "hash": "df2908393f18c1a9445b7473d2bc339b1ac8378b", "best_bid": "0.17", "best_ask": "0.27"}], "timestamp": "1769384834381", "event_type": "price_change"}}
{"_local_timestamp": "2026-01-25T23:47:17.934541+00:00", "data": {"market": "0xf83cb3e04e41497723fda6e08021bda61be1da4938c007041d2d0b2dcad71797", "price_changes": [{"asset_id": "114101043942143326084243846514705158954861305743853088804574718769373357080497", "price": "0.537", "size": "0", "side": "BUY", "hash": "01eee229073fce496cc3934a8b6338b4a58ea076", "best_bid": "0.541", "best_ask": "0.912"}, {"asset_id": "106736152322901906044972029267769298472358373627784690231001806733469669851332", "price": "0.463", "size": "0", "side": "SELL", "hash": "98359db4c95ef6d9e4db41c0b309cdcc31700f9a", "best_bid": "0.088", "best_ask": "0.459"}], "timestamp": "1769384837849", "event_type": "price_change"}}
{"_local_timestamp": "2026-01-25T23:47:18.300524+00:00", "data": {"market": "0xf83cb3e04e41497723fda6e08021bda61be1da4938c007041d2d0b2dcad71797", "price_changes": [{"asset_id": "114101043942143326084243846514705158954861305743853088804574718769373357080497", "price": "0.542", "size": "66.66", "side": "BUY", "hash": "ddadbe0c45f26ea0ef217ab45aa8928784d49e4a", "best_bid": "0.542", "best_ask": "0.912"}, {"asset_id": "106736152322901906044972029267769298472358373627784690231001806733469669851332", "price": "0.458", "size": "66.66", "side": "SELL", "hash": "e9fe8865b131cd0b2fd96ff30ac6f3d85a872af9", "best_bid": "0.088", "best_ask": "0.458"}], "timestamp": "1769384838228", "event_type": "price_change"}}
{"_local_timestamp": "2026-01-25T23:47:36.634113+00:00", "data": {"market": "0xf83cb3e04e41497723fda6e08021bda61be1da4938c007041d2d0b2dcad71797", "price_changes": [{"asset_id": "114101043942143326084243846514705158954861305743853088804574718769373357080497", "price": "0.541", "size": "0", "side": "BUY", "hash": "26db2a9251c5103ecfe936aaf1b21a72b986d429", "best_bid": "0.542", "best_ask": "0.912"}, {"asset_id": "106736152322901906044972029267769298472358373627784690231001806733469669851332", "price": "0.459", "size": "0", "side": "SELL", "hash": "51f028ccb0f05d5271f4b3dbbe6e0793523fc48c", "best_bid": "0.088", "best_ask": "0.458"}], "timestamp": "1769384856524", "event_type": "price_change"}}
{"_local_timestamp": "2026-01-25T23:47:36.657087+00:00", "data": {"market": "0xf83cb3e04e41497723fda6e08021bda61be1da4938c007041d2d0b2dcad71797", "price_changes": [{"asset_id": "114101043942143326084243846514705158954861305743853088804574718769373357080497", "price": "0.543", "size": "9.2", "side": "BUY", "hash": "18e9e86db8c995166bc48ad7fbe1aa2d9d3a6bf2", "best_bid": "0.543", "best_ask": "0.912"}, {"asset_id": "106736152322901906044972029267769298472358373627784690231001806733469669851332", "price": "0.457", "size": "9.2", "side": "SELL", "hash": "f5428109380b78e26b82c529d8350a106043bd27", "best_bid": "0.088", "best_ask": "0.457"}], "timestamp": "1769384856583", "event_type": "price_change"}}
{"_local_timestamp": "2026-01-25T23:47:36.739512+00:00", "data": {"market": "0xf83cb3e04e41497723fda6e08021bda61be1da4938c007041d2d0b2dcad71797", "price_changes": [{"asset_id": "114101043942143326084243846514705158954861305743853088804574718769373357080497", "price": "0.222", "size": "0", "side": "BUY", "hash": "bacfe5cb33c821f6e425863e3a69d9b5a14c6dd9", "best_bid": "0.543", "best_ask": "0.912"}, {"asset_id": "106736152322901906044972029267769298472358373627784690231001806733469669851332", "price": "0.778", "size": "0", "side": "SELL", "hash": "fee6dc8211de1d904e29777243ac173fca39dfeb", "best_bid": "0.088", "best_ask": "0.457"}], "timestamp": "1769384856675", "event_type": "price_change"}}
{"_local_timestamp": "2026-01-25T23:47:38.303545+00:00", "data": {"market": "0xf83cb3e04e41497723fda6e08021bda61be1da4938c007041d2d0b2dcad71797", "price_changes": [{"asset_id": "114101043942143326084243846514705158954861305743853088804574718769373357080497", "price": "0.211", "size": "705", "side": "BUY", "hash": "98c9116c76c4902f2f595260a017217ce6ecee93", "best_bid": "0.543", "best_ask": "0.912"}, {"asset_id": "106736152322901906044972029267769298472358373627784690231001806733469669851332", "price": "0.789", "size": "705", "side": "SELL", "hash": "389a6d290d39781e3490cc0866733850d9d0c003", "best_bid": "0.088", "best_ask": "0.457"}], "timestamp": "1769384858052", "event_type": "price_change"}}
{"_local_timestamp": "2026-01-25T23:47:38.499876+00:00", "data": {"market": "0xf83cb3e04e41497723fda6e08021bda61be1da4938c007041d2d0b2dcad71797", "price_changes": [{"asset_id": "114101043942143326084243846514705158954861305743853088804574718769373357080497", "price": "0.22", "size": "10", "side": "BUY", "hash": "d8339556c29824aae2d1e54049e7f81bba54d8f7", "best_bid": "0.543", "best_ask": "0.912"}, {"asset_id": "106736152322901906044972029267769298472358373627784690231001806733469669851332", "price": "0.78", "size": "10", "side": "SELL", "hash": "6f692936891dfb1418a96fd1ed13045f05194b0a", "best_bid": "0.088", "best_ask": "0.457"}], "timestamp": "1769384858392", "event_type": "price_change"}}
{"_local_timestamp": "2026-01-25T23:47:53.876122+00:00", "data": {"market": "0xf83cb3e04e41497723fda6e08021bda61be1da4938c007041d2d0b2dcad71797", "price_changes": [{"asset_id": "114101043942143326084243846514705158954861305743853088804574718769373357080497", "price": "0.06", "size": "533", "side": "BUY", "hash": "9efed747bd2568bdde04dd1101cf4098936564b9", "best_bid": "0.543", "best_ask": "0.912"}, {"asset_id": "106736152322901906044972029267769298472358373627784690231001806733469669851332", "price": "0.94", "size": "533", "side": "SELL", "hash": "1e08170fb58a4b308a88185aec1edb6e762f07bd", "best_bid": "0.088", "best_ask": "0.457"}], "timestamp": "1769384873806", "event_type": "price_change"}}
{"_local_timestamp": "2026-01-25T23:48:02.509709+00:00", "data": {"market": "0x70573bec08bdbf9309a235a43564b69fe51f4dea221eab7addeb24da1fd3035c", "price_changes": [{"asset_id": "34328613504348250151954487489779346970796086567629120939870499285863212304815", "price": "0.03", "size": "0", "side": "BUY", "hash": "9cc9e078745a5de706d4d2255307fffe404a5eeb", "best_bid": "0.73", "best_ask": "0.83"}, {"asset_id": "16309849227839004264975118747976959817418505128911927142389170217137152348527", "price": "0.97", "size": "0", "side": "SELL", "hash": "357b43b09144e752ddd78e0d265576e2115dfe88", "best_bid": "0.17", "best_ask": "0.27"}], "timestamp": "1769384882433", "event_type": "price_change"}}
{"_local_timestamp": "2026-01-25T23:48:02.932843+00:00", "data": {"market": "0x70573bec08bdbf9309a235a43564b69fe51f4dea221eab7addeb24da1fd3035c", "price_changes": [{"asset_id": "34328613504348250151954487489779346970796086567629120939870499285863212304815", "price": "0.02", "size": "400", "side": "BUY", "hash": "d809672d036b0e865f99d6e2f7e319b8d7ac5c43", "best_bid": "0.73", "best_ask": "0.83"}, {"asset_id": "16309849227839004264975118747976959817418505128911927142389170217137152348527", "price": "0.98", "size": "400", "side": "SELL", "hash": "d091de35df4c8352c86a028e68a039cdb0f08ccf", "best_bid": "0.17", "best_ask": "0.27"}], "timestamp": "1769384882842", "event_type": "price_change"}}
{"_local_timestamp": "2026-01-25T23:48:20.682316+00:00", "data": {"market": "0x70573bec08bdbf9309a235a43564b69fe51f4dea221eab7addeb24da1fd3035c", "price_changes": [{"asset_id": "34328613504348250151954487489779346970796086567629120939870499285863212304815", "price": "0.03", "size": "700", "side": "BUY", "hash": "3ce0c89fabf5615cad4b1a502a6491449e0110a3", "best_bid": "0.73", "best_ask": "0.83"}, {"asset_id": "16309849227839004264975118747976959817418505128911927142389170217137152348527", "price": "0.97", "size": "700", "side": "SELL", "hash": "03e014e800f676814680da808b005a58328f06eb", "best_bid": "0.17", "best_ask": "0.27"}], "timestamp": "1769384900618", "event_type": "price_change"}}
{"_local_timestamp": "2026-01-25T23:48:20.686600+00:00", "data": {"market": "0x70573bec08bdbf9309a235a43564b69fe51f4dea221eab7addeb24da1fd3035c", "price_changes": [{"asset_id": "34328613504348250151954487489779346970796086567629120939870499285863212304815", "price": "0.2", "size": "155.49", "side": "BUY", "hash": "00bec3809d07ca7d9cf2a46bcd71031cec23328d", "best_bid": "0.73", "best_ask": "0.83"}, {"asset_id": "16309849227839004264975118747976959817418505128911927142389170217137152348527", "price": "0.8", "size": "155.49", "side": "SELL", "hash": "070ff4675c2f77d9048ec8c9f7861e892eaf3daf", "best_bid": "0.17", "best_ask": "0.27"}], "timestamp": "1769384900619", "event_type": "price_change"}}
{"_local_timestamp": "2026-01-25T23:48:21.713071+00:00", "data": {"market": "0xf83cb3e04e41497723fda6e08021bda61be1da4938c007041d2d0b2dcad71797", "price_changes": [{"asset_id": "114101043942143326084243846514705158954861305743853088804574718769373357080497", "price": "0.06", "size": "1233", "side": "BUY", "hash": "f1ce5e807b8ea3d17f0ac4e097c4a4eb09c2607f", "best_bid": "0.543", "best_ask": "0.912"}, {"asset_id": "106736152322901906044972029267769298472358373627784690231001806733469669851332", "price": "0.94", "size": "1233", "side": "SELL", "hash": "326295d17e3b5cd552a27d1754651595aba275c1", "best_bid": "0.088", "best_ask": "0.457"}], "timestamp": "1769384901646", "event_type": "price_change"}}
{"_local_timestamp": "2026-01-25T23:48:22.174445+00:00", "data": {"market": "0x70573bec08bdbf9309a235a43564b69fe51f4dea221eab7addeb24da1fd3035c", "price_changes": [{"asset_id": "34328613504348250151954487489779346970796086567629120939870499285863212304815", "price": "0.73", "size": "95.51", "side": "BUY", "hash": "ede0e58974747dd5eac3ae7a752f5bd7c848b70e", "best_bid": "0.73", "best_ask": "0.83"}, {"asset_id": "16309849227839004264975118747976959817418505128911927142389170217137152348527", "price": "0.27", "size": "95.51", "side": "SELL", "hash": "c04d5143a5cc9e7e21ce1beaf51caf9fb01ffd06", "best_bid": "0.17", "best_ask": "0.27"}], "timestamp": "1769384902078", "event_type": "price_change"}}
{"_local_timestamp": "2026-01-25T23:48:22.744331+00:00", "data": {"market": "0x70573bec08bdbf9309a235a43564b69fe51f4dea221eab7addeb24da1fd3035c", "price_changes": [{"asset_id": "34328613504348250151954487489779346970796086567629120939870499285863212304815", "price": "0.03", "size": "0", "side": "BUY", "hash": "aa803af376eff6db1ebe5fee674cdd4e2b4aba97", "best_bid": "0.73", "best_ask": "0.83"}, {"asset_id": "16309849227839004264975118747976959817418505128911927142389170217137152348527", "price": "0.97", "size": "0", "side": "SELL", "hash": "ca4e6675d326b95a4dd2d647ae4f7bb643eb12ab", "best_bid": "0.17", "best_ask": "0.27"}], "timestamp": "1769384902681", "event_type": "price_change"}}
{"_local_timestamp": "2026-01-25T23:48:22.744956+00:00", "data": {"market": "0x70573bec08bdbf9309a235a43564b69fe51f4dea221eab7addeb24da1fd3035c", "price_changes": [{"asset_id": "34328613504348250151954487489779346970796086567629120939870499285863212304815", "price": "0.2", "size": "5.49", "side": "BUY", "hash": "aa803af376eff6db1ebe5fee674cdd4e2b4aba97", "best_bid": "0.73", "best_ask": "0.83"}, {"asset_id": "16309849227839004264975118747976959817418505128911927142389170217137152348527", "price": "0.8", "size": "5.49", "side": "SELL", "hash": "ca4e6675d326b95a4dd2d647ae4f7bb643eb12ab", "best_bid": "0.17", "best_ask": "0.27"}], "timestamp": "1769384902681", "event_type": "price_change"}}
{"_local_timestamp": "2026-01-25T23:48:36.049624+00:00", "data": {"market": "0xf83cb3e04e41497723fda6e08021bda61be1da4938c007041d2d0b2dcad71797", "price_changes": [{"asset_id": "114101043942143326084243846514705158954861305743853088804574718769373357080497", "price": "0.543", "size": "79.18", "side": "BUY", "hash": "a36b2cc10d6540b8e9b74e041b520e45a01cc588", "best_bid": "0.543", "best_ask": "0.912"}, {"asset_id": "106736152322901906044972029267769298472358373627784690231001806733469669851332", "price": "0.457", "size": "79.18", "side": "SELL", "hash": "1d28a5f3bc788a5c1c6242f85684c09f3d560874", "best_bid": "0.088", "best_ask": "0.457"}], "timestamp": "1769384915974", "event_type": "price_change"}}
{"_local_timestamp": "2026-01-25T23:48:53.250129+00:00", "data": {"market": "0xf83cb3e04e41497723fda6e08021bda61be1da4938c007041d2d0b2dcad71797", "price_changes": [{"asset_id": "114101043942143326084243846514705158954861305743853088804574718769373357080497", "price": "0.543", "size": "9.2", "side": "BUY", "hash": "f7a905a794584bec8d5c41d3d293e053e111a197", "best_bid": "0.543", "best_ask": "0.912"}, {"asset_id": "106736152322901906044972029267769298472358373627784690231001806733469669851332", "price": "0.457", "size": "9.2", "side": "SELL", "hash": "3ba700e9173028516fc02dcf48ffeec6b75f3e46", "best_bid": "0.088", "best_ask": "0.457"}], "timestamp": "1769384933153", "event_type": "price_change"}}
{"_local_timestamp": "2026-01-25T23:49:15.666527+00:00", "data": {"market": "0xf83cb3e04e41497723fda6e08021bda61be1da4938c007041d2d0b2dcad71797", "price_changes": [{"asset_id": "114101043942143326084243846514705158954861305743853088804574718769373357080497", "price": "0.06", "size": "533", "side": "BUY", "hash": "6fe6adbe98de9701bc32e638cfc6b4814a325011", "best_bid": "0.543", "best_ask": "0.912"}, {"asset_id": "106736152322901906044972029267769298472358373627784690231001806733469669851332", "price": "0.94", "size": "533", "side": "SELL", "hash": "dba45b504be89e744b144a1d91b94fcdf95886e9", "best_bid": "0.088", "best_ask": "0.457"}], "timestamp": "1769384955586", "event_type": "price_change"}}
{"_local_timestamp": "2026-01-25T23:49:31.107433+00:00", "data": {"market": "0x70573bec08bdbf9309a235a43564b69fe51f4dea221eab7addeb24da1fd3035c", "price_changes": [{"asset_id": "34328613504348250151954487489779346970796086567629120939870499285863212304815", "price": "0.32", "size": "325", "side": "BUY", "hash": "092bd05c58d59385e9606bb9a64ff357cc3eb942", "best_bid": "0.73", "best_ask": "0.83"}, {"asset_id": "16309849227839004264975118747976959817418505128911927142389170217137152348527", "price": "0.68", "size": "325", "side": "SELL", "hash": "1a60b18b11c3326ae42612022840662df0007e72", "best_bid": "0.17", "best_ask": "0.27"}], "timestamp": "1769384970689", "event_type": "price_change"}}
{"_local_timestamp": "2026-01-25T23:49:31.151384+00:00", "data": {"market": "0x70573bec08bdbf9309a235a43564b69fe51f4dea221eab7addeb24da1fd3035c", "price_changes": [{"asset_id": "34328613504348250151954487489779346970796086567629120939870499285863212304815", "price": "0.23", "size": "213.04", "side": "BUY", "hash": "c64d7e4a6392bf98033989ed923dde1b2db364d2", "best_bid": "0.73", "best_ask": "0.83"}, {"asset_id": "16309849227839004264975118747976959817418505128911927142389170217137152348527", "price": "0.77", "size": "213.04", "side": "SELL", "hash": "cc5553d7f8920f055626f59974dd981222a00a06", "best_bid": "0.17", "best_ask": "0.27"}], "timestamp": "1769384970776", "event_type": "price_change"}}
{"_local_timestamp": "2026-01-25T23:49:46.111175+00:00", "data": {"market": "0xde7ca5cc7e0c6f3e705ba793b6a31d7274ecdde51c6c6d71afcbaec89f8dd628", "price_changes": [{"asset_id": "63103673643335340612470219774731409977950900795403364162474548382216856767642", "price": "0.147", "size": "10", "side": "SELL", "hash": "09b6bc88c59047802642855be4432b5c38e6ac3e", "best_bid": "0.041", "best_ask": "0.147"}, {"asset_id": "58928203128986583178255755801066319905610768542025260186563417723289468404703", "price": "0.853", "size": "10", "side": "BUY", "hash": "56e18f0364ec0c0ee1c5a538b4f0e5b01680cda3", "best_bid": "0.853", "best_ask": "0.959"}], "timestamp": "1769384986025", "event_type": "price_change"}}
{"_local_timestamp": "2026-01-25T23:49:46.287748+00:00", "data": {"market": "0xde7ca5cc7e0c6f3e705ba793b6a31d7274ecdde51c6c6d71afcbaec89f8dd628", "price_changes": [{"asset_id": "63103673643335340612470219774731409977950900795403364162474548382216856767642", "price": "0.146", "size": "8.52", "side": "SELL", "hash": "b1b2f9df83cd5ade4490c0343d31c06eab4a06ef", "best_bid": "0.041", "best_ask": "0.146"}, {"asset_id": "58928203128986583178255755801066319905610768542025260186563417723289468404703", "price": "0.854", "size": "8.52", "side": "BUY", "hash": "30e3a258c9f93765ae57a5d430fc642d2651ebf5", "best_bid": "0.854", "best_ask": "0.959"}], "timestamp": "1769384986213", "event_type": "price_change"}}
{"_local_timestamp": "2026-01-25T23:49:49.174083+00:00", "data": {"market": "0x70573bec08bdbf9309a235a43564b69fe51f4dea221eab7addeb24da1fd3035c", "price_changes": [{"asset_id": "16309849227839004264975118747976959817418505128911927142389170217137152348527", "price": "0.28", "size": "0", "side": "SELL", "hash": "6be9b453f1799e4bfec2a226774b34ab5e93eb10", "best_bid": "0.17", "best_ask": "0.27"}, {"asset_id": "34328613504348250151954487489779346970796086567629120939870499285863212304815", "price": "0.72", "size": "0", "side": "BUY", "hash": "117985cbaaa8c9c8fbaf1bff6a695de169d96570", "best_bid": "0.73", "best_ask": "0.83"}], "timestamp": "1769384989109", "event_type": "price_change"}}
{"_local_timestamp": "2026-01-25T23:49:50.075391+00:00", "data": {"market": "0xf83cb3e04e41497723fda6e08021bda61be1da4938c007041d2d0b2dcad71797", "price_changes": [{"asset_id": "114101043942143326084243846514705158954861305743853088804574718769373357080497", "price": "0.928", "size": "0", "side": "SELL", "hash": "b52c3aeb9e10bba52c4ac890404ac96b3eb08da6", "best_bid": "0.543", "best_ask": "0.912"}, {"asset_id": "106736152322901906044972029267769298472358373627784690231001806733469669851332", "price": "0.072", "size": "0", "side": "BUY", "hash": "82efe4d6e7d946d8a5362f9f2254453b8c868b77", "best_bid": "0.088", "best_ask": "0.457"}], "timestamp": "1769384989966", "event_type": "price_change"}}
{"_local_timestamp": "2026-01-25T23:49:50.076441+00:00", "data": {"market": "0xf83cb3e04e41497723fda6e08021bda61be1da4938c007041d2d0b2dcad71797", "price_changes": [{"asset_id": "114101043942143326084243846514705158954861305743853088804574718769373357080497", "price": "0.54", "size": "0", "side": "BUY", "hash": "b52c3aeb9e10bba52c4ac890404ac96b3eb08da6", "best_bid": "0.543", "best_ask": "0.912"}, {"asset_id": "106736152322901906044972029267769298472358373627784690231001806733469669851332", "price": "0.46", "size": "0", "side": "SELL", "hash": "82efe4d6e7d946d8a5362f9f2254453b8c868b77", "best_bid": "0.088", "best_ask": "0.457"}], "timestamp": "1769384989966", "event_type": "price_change"}}
{"_local_timestamp": "2026-01-25T23:49:52.142155+00:00", "data": {"market": "0xde7ca5cc7e0c6f3e705ba793b6a31d7274ecdde51c6c6d71afcbaec89f8dd628", "price_changes": [{"asset_id": "63103673643335340612470219774731409977950900795403364162474548382216856767642", "price": "0.147", "size": "0", "side": "SELL", "hash": "85d7ade911aeee259896b2d0570eb308e03b25a3", "best_bid": "0.041", "best_ask": "0.146"}, {"asset_id": "58928203128986583178255755801066319905610768542025260186563417723289468404703", "price": "0.853", "size": "0", "side": "BUY", "hash": "bad5c027460daa6c69a45a39f0ba214e0a992611", "best_bid": "0.854", "best_ask": "0.959"}], "timestamp": "1769384992046", "event_type": "price_change"}}
{"_local_timestamp": "2026-01-25T23:49:55.622824+00:00", "data": {"market": "0xf83cb3e04e41497723fda6e08021bda61be1da4938c007041d2d0b2dcad71797", "price_changes": [{"asset_id": "114101043942143326084243846514705158954861305743853088804574718769373357080497", "price": "0.542", "size": "0", "side": "BUY", "hash": "08674f760bfe8da7ddf364e45c1179d32357d6a8", "best_bid": "0.543", "best_ask": "0.912"}, {"asset_id": "106736152322901906044972029267769298472358373627784690231001806733469669851332", "price": "0.458", "size": "0", "side": "SELL", "hash": "362d4b0b2ecacfecdeb0f52918f466e12c938788", "best_bid": "0.088", "best_ask": "0.457"}], "timestamp": "1769384995554", "event_type": "price_change"}}
{"_local_timestamp": "2026-01-25T23:49:56.051823+00:00", "data": {"market": "0xf83cb3e04e41497723fda6e08021bda61be1da4938c007041d2d0b2dcad71797", "price_changes": [{"asset_id": "114101043942143326084243846514705158954861305743853088804574718769373357080497", "price": "0.544", "size": "66.66", "side": "BUY", "hash": "3ffaf72bfeffd1acf6ea3ebb87319564945ec800", "best_bid": "0.544", "best_ask": "0.912"}, {"asset_id": "106736152322901906044972029267769298472358373627784690231001806733469669851332", "price": "0.456", "size": "66.66", "side": "SELL", "hash": "6993d683ffb8952ed0afaf17be82d358f46725ad", "best_bid": "0.088", "best_ask": "0.456"}], "timestamp": "1769384995982", "event_type": "price_change"}}
{"_local_timestamp": "2026-01-25T23:50:11.933435+00:00", "data": {"market": "0x70573bec08bdbf9309a235a43564b69fe51f4dea221eab7addeb24da1fd3035c", "price_changes": [{"asset_id": "16309849227839004264975118747976959817418505128911927142389170217137152348527", "price": "0.28", "size": "9.61", "side": "SELL", "hash": "20c611ac0a276a1db2ef7ccd9426124a0c9993cd", "best_bid": "0.17", "best_ask": "0.27"}, {"asset_id": "34328613504348250151954487489779346970796086567629120939870499285863212304815", "price": "0.72", "size": "9.61", "side": "BUY", "hash": "b2ed3254edec6d40702df562283a1f9ccec66b05", "best_bid": "0.73", "best_ask": "0.83"}], "timestamp": "1769385011857", "event_type": "price_change"}}
{"_local_timestamp": "2026-01-25T23:50:17.720808+00:00", "data": {"market": "0xf83cb3e04e41497723fda6e08021bda61be1da4938c007041d2d0b2dcad71797", "price_changes": [{"asset_id": "114101043942143326084243846514705158954861305743853088804574718769373357080497", "price": "0.928", "size": "39.84", "side": "SELL", "hash": "73ca0d36b1c5e411f63f374a828f9cb5fb8220a8", "best_bid": "0.544", "best_ask": "0.912"}, {"asset_id": "106736152322901906044972029267769298472358373627784690231001806733469669851332", "price": "0.072", "size": "39.84", "side": "BUY", "hash": "687482f474789edce15782668b1f96695e6685e7", "best_bid": "0.088", "best_ask": "0.456"}], "timestamp": "1769385017620", "event_type": "price_change"}}
{"_local_timestamp": "2026-01-25T23:50:22.035304+00:00", "data": {"market": "0xf83cb3e04e41497723fda6e08021bda61be1da4938c007041d2d0b2dcad71797", "price_changes": [{"asset_id": "114101043942143326084243846514705158954861305743853088804574718769373357080497", "price": "0.545", "size": "45", "side": "BUY", "hash": "049f5b7bb222aa9a8b618f3ba14308535628895d", "best_bid": "0.545", "best_ask": "0.912"}, {"asset_id": "106736152322901906044972029267769298472358373627784690231001806733469669851332", "price": "0.455", "size": "45", "side": "SELL", "hash": "67731e39faaa0dd8f7edc25ae8a3ce8eb43f160d", "best_bid": "0.088", "best_ask": "0.455"}], "timestamp": "1769385021942", "event_type": "price_change"}}
{"_local_timestamp": "2026-01-25T23:50:22.462163+00:00", "data": {"market": "0x70573bec08bdbf9309a235a43564b69fe51f4dea221eab7addeb24da1fd3035c", "price_changes": [{"asset_id": "34328613504348250151954487489779346970796086567629120939870499285863212304815", "price": "0.73", "size": "43.46", "side": "BUY", "hash": "e76bf7b891d583e9818ed4ec4eb69c06b4525216", "best_bid": "0.73", "best_ask": "0.83"}, {"asset_id": "16309849227839004264975118747976959817418505128911927142389170217137152348527", "price": "0.27", "size": "43.46", "side": "SELL", "hash": "3224f067f5f0facdeee05eff4cd6bbda8f68a075", "best_bid": "0.17", "best_ask": "0.27"}], "timestamp": "1769385022378", "event_type": "price_change"}}
{"_local_timestamp": "2026-01-25T23:50:23.431542+00:00", "data": {"market": "0xf83cb3e04e41497723fda6e08021bda61be1da4938c007041d2d0b2dcad71797", "price_changes": [{"asset_id": "114101043942143326084243846514705158954861305743853088804574718769373357080497", "price": "0.543", "size": "0", "side": "BUY", "hash": "192f2b59cb855fa958c95b3c1324b03738373879", "best_bid": "0.545", "best_ask": "0.912"}, {"asset_id": "106736152322901906044972029267769298472358373627784690231001806733469669851332", "price": "0.457", "size": "0", "side": "SELL", "hash": "d06eabaa118b59d58740dd5df7f3169ccc733f52", "best_bid": "0.088", "best_ask": "0.455"}], "timestamp": "1769385023332", "event_type": "price_change"}}
{"_local_timestamp": "2026-01-25T23:50:23.521407+00:00", "data": {"market": "0xf83cb3e04e41497723fda6e08021bda61be1da4938c007041d2d0b2dcad71797", "price_changes": [{"asset_id": "114101043942143326084243846514705158954861305743853088804574718769373357080497", "price": "0.546", "size": "9.15", "side": "BUY", "hash": "27a55f67bfc3c82fadceac696808586814360e04", "best_bid": "0.546", "best_ask": "0.912"}, {"asset_id": "106736152322901906044972029267769298472358373627784690231001806733469669851332", "price": "0.454", "size": "9.15", "side": "SELL", "hash": "63f74a0fdf3f8929368ad49d76a108439cd85d1d", "best_bid": "0.088", "best_ask": "0.454"}], "timestamp": "1769385023425", "event_type": "price_change"}}
{"_local_timestamp": "2026-01-25T23:50:27.963691+00:00", "data": {"market": "0xde7ca5cc7e0c6f3e705ba793b6a31d7274ecdde51c6c6d71afcbaec89f8dd628", "price_changes": [{"asset_id": "63103673643335340612470219774731409977950900795403364162474548382216856767642", "price": "0.146", "size": "18.52", "side": "SELL", "hash": "c5e082d4e482ee992332e561461c525b7cb79711", "best_bid": "0.041", "best_ask": "0.146"}, {"asset_id": "58928203128986583178255755801066319905610768542025260186563417723289468404703", "price": "0.854", "size": "18.52", "side": "BUY", "hash": "c3cb54ac4c0204e0b5e5d7bee3bb3d7f02426658", "best_bid": "0.854", "best_ask": "0.959"}], "timestamp": "1769385027807", "event_type": "price_change"}}
{"_local_timestamp": "2026-01-25T23:50:30.432788+00:00", "data": {"market": "0xf83cb3e04e41497723fda6e08021bda61be1da4938c007041d2d0b2dcad71797", "price_changes": [{"asset_id": "114101043942143326084243846514705158954861305743853088804574718769373357080497", "price": "0.06", "size": "1233", "side": "BUY", "hash": "909e7875620a4d21e5d0c1f496bbd8bdb657c68e", "best_bid": "0.546", "best_ask": "0.912"}, {"asset_id": "106736152322901906044972029267769298472358373627784690231001806733469669851332", "price": "0.94", "size": "1233", "side": "SELL", "hash": "50bd5a64a6c5b7c2e30eb3367686f18f40fc8707", "best_bid": "0.088", "best_ask": "0.454"}], "timestamp": "1769385030273", "event_type": "price_change"}}
{"_local_timestamp": "2026-01-25T23:50:32.909169+00:00", "data": {"market": "0x70573bec08bdbf9309a235a43564b69fe51f4dea221eab7addeb24da1fd3035c", "price_changes": [{"asset_id": "34328613504348250151954487489779346970796086567629120939870499285863212304815", "price": "0.03", "size": "700", "side": "BUY", "hash": "f4a86990ab5e66ed9f93f1d28cd1febe080694b9", "best_bid": "0.73", "best_ask": "0.83"}, {"asset_id": "16309849227839004264975118747976959817418505128911927142389170217137152348527", "price": "0.97", "size": "700", "side": "SELL", "hash": "bc7614457ed51856abd2bb609122c1e798313728", "best_bid": "0.17", "best_ask": "0.27"}], "timestamp": "1769385032722", "event_type": "price_change"}}
{"_local_timestamp": "2026-01-25T23:50:32.910645+00:00", "data": {"market": "0x70573bec08bdbf9309a235a43564b69fe51f4dea221eab7addeb24da1fd3035c", "price_changes": [{"asset_id": "34328613504348250151954487489779346970796086567629120939870499285863212304815", "price": "0.2", "size": "155.49", "side": "BUY", "hash": "e6b0083ffba41814edf53475fb562cfac2a9a7dc", "best_bid": "0.73", "best_ask": "0.83"}, {"asset_id": "16309849227839004264975118747976959817418505128911927142389170217137152348527", "price": "0.8", "size": "155.49", "side": "SELL", "hash": "5f1f15551aa982858c96756e9f00ae15abbf8f6b", "best_bid": "0.17", "best_ask": "0.27"}], "timestamp": "1769385032723", "event_type": "price_change"}}
{"_local_timestamp": "2026-01-25T23:50:46.953286+00:00", "data": {"market": "0xf83cb3e04e41497723fda6e08021bda61be1da4938c007041d2d0b2dcad71797", "price_changes": [{"asset_id": "114101043942143326084243846514705158954861305743853088804574718769373357080497", "price": "0.06", "size": "533", "side": "BUY", "hash": "f02552f10adcb402e2ca8eeab5499dfa2a13b27e", "best_bid": "0.546", "best_ask": "0.912"}, {"asset_id": "106736152322901906044972029267769298472358373627784690231001806733469669851332", "price": "0.94", "size": "533", "side": "SELL", "hash": "c646e3e3ccc5cabb1d648d05d41f7ddfac0176b1", "best_bid": "0.088", "best_ask": "0.454"}], "timestamp": "1769385046890", "event_type": "price_change"}}
{"_local_timestamp": "2026-01-25T23:51:13.206615+00:00", "data": {"market": "0xf83cb3e04e41497723fda6e08021bda61be1da4938c007041d2d0b2dcad71797", "price_changes": [{"asset_id": "114101043942143326084243846514705158954861305743853088804574718769373357080497", "price": "0.06", "size": "1233", "side": "BUY", "hash": "94ce8afa1245c597c84eaa0414f35cf94d7fcff2", "best_bid": "0.546", "best_ask": "0.912"}, {"asset_id": "106736152322901906044972029267769298472358373627784690231001806733469669851332", "price": "0.94", "size": "1233", "side": "SELL", "hash": "c57d08d652421f5a4a846a4ca1916d5d3310a49c", "best_bid": "0.088", "best_ask": "0.454"}], "timestamp": "1769385073123", "event_type": "price_change"}}
{"_local_timestamp": "2026-01-25T23:51:13.351435+00:00", "data": {"market": "0xde7ca5cc7e0c6f3e705ba793b6a31d7274ecdde51c6c6d71afcbaec89f8dd628", "price_changes": [{"asset_id": "58928203128986583178255755801066319905610768542025260186563417723289468404703", "price": "0.52", "size": "10", "side": "BUY", "hash": "5efaf1a5faf18904715592ce6afd099f72f77cd6", "best_bid": "0.854", "best_ask": "0.959"}, {"asset_id": "63103673643335340612470219774731409977950900795403364162474548382216856767642", "price": "0.48", "size": "10", "side": "SELL", "hash": "d4c8fb7dfc836f65668017b721eaf2ce7e548cb3", "best_bid": "0.041", "best_ask": "0.146"}], "timestamp": "1769385073278", "event_type": "price_change"}}
