{"_local_timestamp": "2026-01-25T23:33:19.459564+00:00", "data": [{"market": "0x2e3433f79c616df13c4955a7134e595ee2ccf4866dce309925e755737b872271", "asset_id": "112202945651691176336626757870751886707772553418125673815227809139773741570078", "timestamp": "1769383998096", "hash": "74755701208ce72cdd7c41d2f53cd8a611755a27", "bids": [{"price": "0.001", "size": "3977.47"}, {"price": "0.002", "size": "1256.64"}, {"price": "0.003", "size": "1400"}, {"price": "0.004", "size": "11.46"}, {"price": "0.006", "size": "200"}, {"price": "0.01", "size": "5525"}, {"price": "0.011", "size": "5.8"}, {"price": "0.02", "size": "3200"}, {"price": "0.021", "size": "5.8"}, {"price": "0.04", "size": "1250"}, {"price": "0.041", "size": "5.43"}, {"price": "0.05", "size": "30"}, {"price": "0.051", "size": "39"}, {"price": "0.06", "size": "700"}, {"price": "0.08", "size": "250"}, {"price": "0.081", "size": "6.08"}, {"price": "0.115", "size": "325"}, {"price": "0.191", "size": "2322"}, {"price": "0.192", "size": "400"}, {"price": "0.193", "size": "5.35"}, {"price": "0.21", "size": "100"}, {"price": "0.337", "size": "2272"}, {"price": "0.338", "size": "1258"}, {"price": "0.407", "size": "5"}, {"price": "0.511", "size": "97"}, {"price": "0.603", "size": "469"}, {"price": "0.792", "size": "20"}, {"price": "0.793", "size": "20"}, {"price": "0.845", "size": "555"}, {"price": "0.846", "size": "479.84"}, {"price": "0.847", "size": "190.55"}, {"price": "0.85", "size": "100"}, {"price": "0.863", "size": "66.66"}, {"price": "0.864", "size": "20"}, {"price": "0.865", "size": "20"}, {"price": "0.866", "size": "190"}, {"price": "0.88", "size": "120"}, {"price": "0.881", "size": "83.66"}, {"price": "0.882", "size": "70"}], "asks": [{"price": "0.999", "size": "1668"}, {"price": "0.998", "size": "26.34"}, {"price": "0.991", "size": "1014.69"}, {"price": "0.99", "size": "2222"}, {"price": "0.989", "size": "311.38"}, {"price": "0.97", "size": "150"}, {"price": "0.969", "size": "555"}, {"price": "0.966", "size": "6.53"}, {"price": "0.94", "size": "100"}, {"price": "0.939", "size": "40.23"}, {"price": "0.931", "size": "105.83"}, {"price": "0.925", "size": "40.23"}, {"price": "0.923", "size": "311.05"}, {"price": "0.922", "size": "219.04"}, {"price": "0.916", "size": "62.2"}], "event_type": "book", "last_trade_price": "0.885"}, {"market": "0x2e3433f79c616df13c4955a7134e595ee2ccf4866dce309925e755737b872271", "asset_id": "18309888943220126175774903330165417854845342977748532448162902228663371934448", "timestamp": "1769383998096", "hash": "447dbc9989fdfeb1068592499f186fca7f513b06", "bids": [{"price": "0.001", "size": "1668"}, {"price": "0.002", "size": "26.34"}, {"price": "0.009", "size": "1014.69"}, {"price": "0.01", "size": "2222"}, {"price": "0.011", "size": "311.38"}, {"price": "0.03", "size": "150"}, {"price": "0.031", "size": "555"}, {"price": "0.034", "size": "6.53"}, {"price": "0.06", "size": "100"}, {"price": "0.061", "size": "40.23"}, {"price": "0.069", "size": "105.83"}, {"price": "0.075", "size": "40.23"}, {"price": "0.077", "size": "311.05"}, {"price": "0.078", "size": "219.04"}, {"price": "0.084", "size": "62.2"}], "asks": [{"price": "0.999", "size": "3977.47"}, {"price": "0.998", "size": "1256.64"}, {"price": "0.997", "size": "1400"}, {"price": "0.996", "size": "11.46"}, {"price": "0.994", "size": "200"}, {"price": "0.99", "size": "5525"}, {"price": "0.989", "size": "5.8"}, {"price": "0.98", "size": "3200"}, {"price": "0.979", "size": "5.8"}, {"price": "0.96", "size": "1250"}, {"price": "0.959", "size": "5.43"}, {"price": "0.95", "size": "30"}, {"price": "0.949", "size": "39"}, {"price": "0.94", "size": "700"}, {"price": "0.92", "size": "250"}, {"price": "0.919", "size": "6.08"}, {"price": "0.885", "size": "325"}, {"price": "0.809", "size": "2322"}, {"price": "0.808", "size": "400"}, {"price": "0.807", "size": "5.35"}, {"price": "0.79", "size": "100"}, {"price": "0.663", "size": "2272"}, {"price": "0.662", "size": "1258"}, {"price": "0.593", "size": "5"}, {"price": "0.489", "size": "97"}, {"price": "0.397", "size": "469"}, {"price": "0.208", "size": "20"}, {"price": "0.207", "size": "20"}, {"price": "0.155", "size": "555"}, {"price": "0.154", "size": "479.84"}, {"price": "0.153", "size": "190.55"}, {"price": "0.15", "size": "100"}, {"price": "0.137", "size": "66.66"}, {"price": "0.136", "size": "20"}, {"price": "0.135", "size": "20"}, {"price": "0.134", "size": "190"}, {"price": "0.12", "size": "120"}, {"price": "0.119", "size": "83.66"}, {"price": "0.118", "size": "70"}], "event_type": "book", "last_trade_price": "0.885"}, {"market": "0xdf0e04194ff7f25807465101e29d7d476bb9cbf7e56e950d2693cedf4787599f", "asset_id": "112838519090657527020403907389517191367689011522812125990685217194554034388792", "timestamp": "1769383993037", "hash": "fad6b26b35eb6e0e3a3f0106ee5a71fe21f3bcf3", "bids": [{"price": "0.001", "size": "1596"}, {"price": "0.002", "size": "1008.82"}, {"price": "0.003", "size": "2227.85"}, {"price": "0.004", "size": "8.71"}, {"price": "0.005", "size": "555"}, {"price": "0.006", "size": "5.25"}, {"price": "0.007", "size": "50"}, {"price": "0.008", "size": "9.67"}, {"price": "0.009", "size": "50"}, {"price": "0.01", "size": "105"}, {"price": "0.011", "size": "222"}, {"price": "0.012", "size": "124.3"}, {"price": "0.015", "size": "29.58"}, {"price": "0.016", "size": "6.84"}, {"price": "0.017", "size": "5.46"}, {"price": "0.019", "size": "489.64"}, {"price": "0.02", "size": "428"}, {"price": "0.026", "size": "5.46"}, {"price": "0.032", "size": "15.06"}, {"price": "0.033", "size": "5.46"}], "asks": [{"price": "0.999", "size": "3996.61"}, {"price": "0.998", "size": "1256.58"}, {"price": "0.997", "size": "1400"}, {"price": "0.996", "size": "11.36"}, {"price": "0.994", "size": "200"}, {"price": "0.99", "size": "5500"}, {"price": "0.989", "size": "5.75"}, {"price": "0.98", "size": "2900"}, {"price": "0.979", "size": "5.76"}, {"price": "0.96", "size": "1250"}, {"price": "0.959", "size": "5.52"}, {"price": "0.95", "size": "30"}, {"price": "0.949", "size": "39"}, {"price": "0.94", "size": "500"}, {"price": "0.92", "size": "250"}, {"price": "0.919", "size": "2722"}, {"price": "0.918", "size": "6.32"}, {"price": "0.9", "size": "360"}, {"price": "0.85", "size": "551.66"}, {"price": "0.8", "size": "410"}, {"price": "0.799", "size": "5"}, {"price": "0.75", "size": "112"}, {"price": "0.7", "size": "2458.66"}, {"price": "0.66", "size": "70.58"}, {"price": "0.63", "size": "700"}, {"price": "0.628", "size": "300"}, {"price": "0.627", "size": "1072"}, {"price": "0.61", "size": "126.28"}, {"price": "0.609", "size": "5"}, {"price": "0.217", "size": "555"}, {"price": "0.216", "size": "300"}, {"price": "0.212", "size": "253"}, {"price": "0.211", "size": "253"}, {"price": "0.169", "size": "120"}, {"price": "0.168", "size": "66.66"}, {"price": "0.118", "size": "20"}, {"price": "0.117", "size": "66.66"}, {"price": "0.115", "size": "20"}, {"price": "0.114", "size": "20"}, {"price": "0.113", "size": "20"}, {"price": "0.073", "size": "120"}, {"price": "0.07", "size": "100"}, {"price": "0.068", "size": "16"}, {"price": "0.066", "size": "96.66"}, {"price": "0.065", "size": "50"}, {"price": "0.061", "size": "9.93"}], "event_type": "book", "last_trade_price": "0.022"}, {"market": "0x0baf5017c6cdd082b72a9f8d81ce7a5568a11d2185b37f24aec4371feffa4508", "asset_id": "1398837009918163072638964138392157627970988230992506005676269129994871270413", "timestamp": "1769383982868", "hash": "2630540201e917cf517fc890b3944b36e72c4f67", "bids": [{"price": "0.001", "size": "4537"}, {"price": "0.002", "size": "250"}], "asks": [{"price": "0.999", "size": "3863.95"}, {"price": "0.998", "size": "1256.57"}, {"price": "0.997", "size": "1400"}, {"price": "0.996", "size": "11.35"}, {"price": "0.994", "size": "200"}, {"price": "0.99", "size": "5700"}, {"price": "0.989", "size": "5.74"}, {"price": "0.98", "size": "3200"}, {"price": "0.979", "size": "5.75"}, {"price": "0.96", "size": "1250"}, {"price": "0.959", "size": "5.39"}, {"price": "0.95", "size": "30"}, {"price": "0.949", "size": "39"}, {"price": "0.94", "size": "500"}, {"price": "0.92", "size": "250"}, {"price": "0.919", "size": "6.46"}, {"price": "0.9", "size": "560"}, {"price": "0.85", "size": "551.66"}, {"price": "0.8", "size": "410"}, {"price": "0.799", "size": "5"}, {"price": "0.798", "size": "300"}, {"price": "0.75", "size": "262"}, {"price": "0.749", "size": "1992"}, {"price": "0.7", "size": "86.66"}, {"price": "0.65", "size": "68.57"}, {"price": "0.648", "size": "127.27"}, {"price": "0.6", "size": "125"}, {"price": "0.477", "size": "176"}, {"price": "0.46", "size": "700"}, {"price": "0.277", "size": "90"}, {"price": "0.276", "size": "2222"}, {"price": "0.218", "size": "510"}, {"price": "0.217", "size": "34.01"}, {"price": "0.177", "size": "101"}, {"price": "0.167", "size": "120"}, {"price": "0.166", "size": "10"}, {"price": "0.09", "size": "150"}, {"price": "0.077", "size": "273"}, {"price": "0.071", "size": "115.16"}, {"price": "0.063", "size": "20"}, {"price": "0.062", "size": "20"}, {"price": "0.049", "size": "206"}, {"price": "0.028", "size": "20"}, {"price": "0.021", "size": "71.55"}, {"price": "0.008", "size": "18.12"}, {"price": "0.007", "size": "61"}], "event_type": "book", "last_trade_price": "0.006"}, {"market": "0x28b09e78c1a37a9212b683d5734c0b8375e9c85777e59bb498a08debb585e941", "asset_id": "44648314711717458063074998921644285938870392557850689878450818223237354241500", "timestamp": "1769383976030", "hash": "a16cb17145d0bfc7a8bae3c4b6434cfd5064f392", "bids": [{"price": "0.001", "size": "2185"}, {"price": "0.002", "size": "133.64"}, {"price": "0.003", "size": "250"}, {"price": "0.004", "size": "198.17"}, {"price": "0.007", "size": "150"}], "asks": [{"price": "0.999", "size": "8756.57"}, {"price": "0.998", "size": "1256.55"}, {"price": "0.997", "size": "1166"}, {"price": "0.996", "size": "11.32"}, {"price": "0.994", "size": "83"}, {"price": "0.99", "size": "100"}, {"price": "0.989", "size": "5.03"}, {"price": "0.98", "size": "400"}, {"price": "0.979", "size": "11.82"}, {"price": "0.95", "size": "40"}, {"price": "0.949", "size": "39"}, {"price": "0.939", "size": "32"}, {"price": "0.938", "size": "10.07"}, {"price": "0.9", "size": "860"}, {"price": "0.899", "size": "250"}, {"price": "0.85", "size": "551.66"}, {"price": "0.8", "size": "410"}, {"price": "0.799", "size": "5.01"}, {"price": "0.75", "size": "262"}, {"price": "0.749", "size": "1992"}, {"price": "0.7", "size": "86.66"}, {"price": "0.65", "size": "68.57"}, {"price": "0.6", "size": "125"}, {"price": "0.599", "size": "5"}, {"price": "0.277", "size": "45"}, {"price": "0.093", "size": "2222"}, {"price": "0.092", "size": "550"}, {"price": "0.09", "size": "150"}, {"price": "0.086", "size": "10"}, {"price": "0.084", "size": "20"}, {"price": "0.083", "size": "20"}, {"price": "0.082", "size": "20"}, {"price": "0.033", "size": "20"}, {"price": "0.025", "size": "63.94"}, {"price": "0.021", "size": "400"}, {"price": "0.02", "size": "222.86"}, {"price": "0.015", "size": "67.5"}], "event_type": "book", "last_trade_price": "0.008"}, {"market": "0x0baf5017c6cdd082b72a9f8d81ce7a5568a11d2185b37f24aec4371feffa4508", "asset_id": "54912585197947912918703938085404885715682857902987396027502188879254644524559", "timestamp": "1769383982868", "hash": "1d008b130fe3199b2c73642f497bb212c058c3c5", "bids": [{"price": "0.001", "size": "3863.95"}, {"price": "0.002", "size": "1256.57"}, {"price": "0.003", "size": "1400"}, {"price": "0.004", "size": "11.35"}, {"price": "0.006", "size": "200"}, {"price": "0.01", "size": "5700"}, {"price": "0.011", "size": "5.74"}, {"price": "0.02", "size": "3200"}, {"price": "0.021", "size": "5.75"}, {"price": "0.04", "size": "1250"}, {"price": "0.041", "size": "5.39"}, {"price": "0.05", "size": "30"}, {"price": "0.051", "size": "39"}, {"price": "0.06", "size": "500"}, {"price": "0.08", "size": "250"}, {"price": "0.081", "size": "6.46"}, {"price": "0.1", "size": "560"}, {"price": "0.15", "size": "551.66"}, {"price": "0.2", "size": "410"}, {"price": "0.201", "size": "5"}, {"price": "0.202", "size": "300"}, {"price": "0.25", "size": "262"}, {"price": "0.251", "size": "1992"}, {"price": "0.3", "size": "86.66"}, {"price": "0.35", "size": "68.57"}, {"price": "0.352", "size": "127.27"}, {"price": "0.4", "size": "125"}, {"price": "0.523", "size": "176"}, {"price": "0.54", "size": "700"}, {"price": "0.723", "size": "90"}, {"price": "0.724", "size": "2222"}, {"price": "0.782", "size": "510"}, {"price": "0.783", "size": "34.01"}, {"price": "0.823", "size": "101"}, {"price": "0.833", "size": "120"}, {"price": "0.834", "size": "10"}, {"price": "0.91", "size": "150"}, {"price": "0.923", "size": "273"}, {"price": "0.929", "size": "115.16"}, {"price": "0.937", "size": "20"}, {"price": "0.938", "size": "20"}, {"price": "0.951", "size": "206"}, {"price": "0.972", "size": "20"}, {"price": "0.979", "size": "71.55"}, {"price": "0.992", "size": "18.12"}, {"price": "0.993", "size": "61"}], "asks": [{"price": "0.999", "size": "4537"}, {"price": "0.998", "size": "250"}], "event_type": "book", "last_trade_price": "0.006"}, {"market": "0x28b09e78c1a37a9212b683d5734c0b8375e9c85777e59bb498a08debb585e941", "asset_id": "80377662132340664016724672073316391179500510732361804244421570371942255684414", "timestamp": "1769383976030", "hash": "f4909b6cf3555fdbd82f8fd71e41390fbb3e09c9", "bids": [{"price": "0.001", "size": "8756.57"}, {"price": "0.002", "size": "1256.55"}, {"price": "0.003", "size": "1166"}, {"price": "0.004", "size": "11.32"}, {"price": "0.006", "size": "83"}, {"price": "0.01", "size": "100"}, {"price": "0.011", "size": "5.03"}, {"price": "0.02", "size": "400"}, {"price": "0.021", "size": "11.82"}, {"price": "0.05", "size": "40"}, {"price": "0.051", "size": "39"}, {"price": "0.061", "size": "32"}, {"price": "0.062", "size": "10.07"}, {"price": "0.1", "size": "860"}, {"price": "0.101", "size": "250"}, {"price": "0.15", "size": "551.66"}, {"price": "0.2", "size": "410"}, {"price": "0.201", "size": "5.01"}, {"price": "0.25", "size": "262"}, {"price": "0.251", "size": "1992"}, {"price": "0.3", "size": "86.66"}, {"price": "0.35", "size": "68.57"}, {"price": "0.4", "size": "125"}, {"price": "0.401", "size": "5"}, {"price": "0.723", "size": "45"}, {"price": "0.907", "size": "2222"}, {"price": "0.908", "size": "550"}, {"price": "0.91", "size": "150"}, {"price": "0.914", "size": "10"}, {"price": "0.916", "size": "20"}, {"price": "0.917", "size": "20"}, {"price": "0.918", "size": "20"}, {"price": "0.967", "size": "20"}, {"price": "0.975", "size": "63.94"}, {"price": "0.979", "size": "400"}, {"price": "0.98", "size": "222.86"}, {"price": "0.985", "size": "67.5"}], "asks": [{"price": "0.999", "size": "2185"}, {"price": "0.998", "size": "133.64"}, {"price": "0.997", "size": "250"}, {"price": "0.996", "size": "198.17"}, {"price": "0.993", "size": "150"}], "event_type": "book", "last_trade_price": "0.008"}, {"market": "0xaf811fcf5edc733781bee6125756d3e1f02d04f2824b89ab7fa4f4ce30f998b5", "asset_id": "27643431546680855679789625370218065863059031034570354610668275237893764523490", "timestamp": "1769383983387", "hash": "a534bfabe0d1b65599c9ef465735579ca34e6f12", "bids": [{"price": "0.01", "size": "6728.38"}, {"price": "0.02", "size": "2511.06"}, {"price": "0.03", "size": "1571.89"}, {"price": "0.04", "size": "1260.64"}, {"price": "0.05", "size": "250"}, {"price": "0.06", "size": "679.87"}, {"price": "0.07", "size": "1246"}, {"price": "0.08", "size": "273.37"}, {"price": "0.09", "size": "85.91"}, {"price": "0.1", "size": "355"}, {"price": "0.11", "size": "225.3"}, {"price": "0.12", "size": "33.33"}, {"price": "0.13", "size": "8.65"}], "asks": [{"price": "0.99", "size": "3231.07"}, {"price": "0.98", "size": "400"}, {"price": "0.95", "size": "40"}, {"price": "0.94", "size": "71.15"}, {"price": "0.91", "size": "400"}, {"price": "0.9", "size": "1166"}, {"price": "0.86", "size": "567.85"}, {"price": "0.82", "size": "427.77"}, {"price": "0.79", "size": "760"}, {"price": "0.77", "size": "121.73"}, {"price": "0.76", "size": "555"}, {"price": "0.75", "size": "1830"}, {"price": "0.73", "size": "96.29"}, {"price": "0.72", "size": "250"}, {"price": "0.68", "size": "75"}, {"price": "0.67", "size": "500"}, {"price": "0.65", "size": "555"}, {"price": "0.64", "size": "963.55"}, {"price": "0.39", "size": "7.49"}, {"price": "0.37", "size": "562.49"}, {"price": "0.27", "size": "8"}, {"price": "0.24", "size": "8"}, {"price": "0.21", "size": "8"}, {"price": "0.2", "size": "655"}, {"price": "0.19", "size": "199.99"}, {"price": "0.18", "size": "217.99"}, {"price": "0.17", "size": "393.21"}, {"price": "0.16", "size": "519.99"}, {"price": "0.15", "size": "393.32"}], "event_type": "book", "last_trade_price": "0.150"}, {"market": "0xaf811fcf5edc733781bee6125756d3e1f02d04f2824b89ab7fa4f4ce30f998b5", "asset_id": "94235206725638004435521288935127321522857776396521937922634976647313998892484", "timestamp": "1769383983387", "hash": "3c78c271526a26a24adb8344ff154d955d30b3e9", "bids": [{"price": "0.01", "size": "3231.07"}, {"price": "0.02", "size": "400"}, {"price": "0.05", "size": "40"}, {"price": "0.06", "size": "71.15"}, {"price": "0.09", "size": "400"}, {"price": "0.1", "size": "1166"}, {"price": "0.14", "size": "567.85"}, {"price": "0.18", "size": "427.77"}, {"price": "0.21", "size": "760"}, {"price": "0.23", "size": "121.73"}, {"price": "0.24", "size": "555"}, {"price": "0.25", "size": "1830"}, {"price": "0.27", "size": "96.29"}, {"price": "0.28", "size": "250"}, {"price": "0.32", "size": "75"}, {"price": "0.33", "size": "500"}, {"price": "0.35", "size": "555"}, {"price": "0.36", "size": "963.55"}, {"price": "0.61", "size": "7.49"}, {"price": "0.63", "size": "562.49"}, {"price": "0.73", "size": "8"}, {"price": "0.76", "size": "8"}, {"price": "0.79", "size": "8"}, {"price": "0.8", "size": "655"}, {"price": "0.81", "size": "199.99"}, {"price": "0.82", "size": "217.99"}, {"price": "0.83", "size": "393.21"}, {"price": "0.84", "size": "519.99"}, {"price": "0.85", "size": "393.32"}], "asks": [{"price": "0.99", "size": "6728.38"}, {"price": "0.98", "size": "2511.06"}, {"price": "0.97", "size": "1571.89"}, {"price": "0.96", "size": "1260.64"}, {"price": "0.95", "size": "250"}, {"price": "0.94", "size": "679.87"}, {"price": "0.93", "size": "1246"}, {"price": "0.92", "size": "273.37"}, {"price": "0.91", "size": "85.91"}, {"price": "0.9", "size": "355"}, {"price": "0.89", "size": "225.3"}, {"price": "0.88", "size": "33.33"}, {"price": "0.87", "size": "8.65"}], "event_type": "book", "last_trade_price": "0.150"}, {"market": "0xdf0e04194ff7f25807465101e29d7d476bb9cbf7e56e950d2693cedf4787599f", "asset_id": "96765239208959541720088187158035685118767037049985993166814389120572666374201", "timestamp": "1769383993037", "hash": "2368c1f57a4f5fdbf6b5490cd9372908755fd3cb", "bids": [{"price": "0.001", "size": "3996.61"}, {"price": "0.002", "size": "1256.58"}, {"price": "0.003", "size": "1400"}, {"price": "0.004", "size": "11.36"}, {"price": "0.006", "size": "200"}, {"price": "0.01", "size": "5500"}, {"price": "0.011", "size": "5.75"}, {"price": "0.02", "size": "2900"}, {"price": "0.021", "size": "5.76"}, {"price": "0.04", "size": "1250"}, {"price": "0.041", "size": "5.52"}, {"price": "0.05", "size": "30"}, {"price": "0.051", "size": "39"}, {"price": "0.06", "size": "500"}, {"price": "0.08", "size": "250"}, {"price": "0.081", "size": "2722"}, {"price": "0.082", "size": "6.32"}, {"price": "0.1", "size": "360"}, {"price": "0.15", "size": "551.66"}, {"price": "0.2", "size": "410"}, {"price": "0.201", "size": "5"}, {"price": "0.25", "size": "112"}, {"price": "0.3", "size": "2458.66"}, {"price": "0.34", "size": "70.58"}, {"price": "0.37", "size": "700"}, {"price": "0.372", "size": "300"}, {"price": "0.373", "size": "1072"}, {"price": "0.39", "size": "126.28"}, {"price": "0.391", "size": "5"}, {"price": "0.783", "size": "555"}, {"price": "0.784", "size": "300"}, {"price": "0.788", "size": "253"}, {"price": "0.789", "size": "253"}, {"price": "0.831", "size": "120"}, {"price": "0.832", "size": "66.66"}, {"price": "0.882", "size": "20"}, {"price": "0.883", "size": "66.66"}, {"price": "0.885", "size": "20"}, {"price": "0.886", "size": "20"}, {"price": "0.887", "size": "20"}, {"price": "0.927", "size": "120"}, {"price": "0.93", "size": "100"}, {"price": "0.932", "size": "16"}, {"price": "0.934", "size": "96.66"}, {"price": "0.935", "size": "50"}, {"price": "0.939", "size": "9.93"}], "asks": [{"price": "0.999", "size": "1596"}, {"price": "0.998", "size": "1008.82"}, {"price": "0.997", "size": "2227.85"}, {"price": "0.996", "size": "8.71"}, {"price": "0.995", "size": "555"}, {"price": "0.994", "size": "5.25"}, {"price": "0.993", "size": "50"}, {"price": "0.992", "size": "9.67"}, {"price": "0.991", "size": "50"}, {"price": "0.99", "size": "105"}, {"price": "0.989", "size": "222"}, {"price": "0.988", "size": "124.3"}, {"price": "0.985", "size": "29.58"}, {"price": "0.984", "size": "6.84"}, {"price": "0.983", "size": "5.46"}, {"price": "0.981", "size": "489.64"}, {"price": "0.98", "size": "428"}, {"price": "0.974", "size": "5.46"}, {"price": "0.968", "size": "15.06"}, {"price": "0.967", "size": "5.46"}], "event_type": "book", "last_trade_price": "0.022"}]}
{"_local_timestamp": "2026-01-25T23:33:23.995528+00:00", "data": {"market": "0x0baf5017c6cdd082b72a9f8d81ce7a5568a11d2185b37f24aec4371feffa4508", "price_changes": [{"asset_id": "54912585197947912918703938085404885715682857902987396027502188879254644524559", "price": "0.54", "size": "0", "side": "BUY", "hash": "82c8150220cfac3fa43f1c86e90a7f12cad40558", "best_bid": "0.993", "best_ask": "0.998"}, {"asset_id": "1398837009918163072638964138392157627970988230992506005676269129994871270413", "price": "0.46", "size": "0", "side": "SELL", "hash": "ffa9a6699b124ded1154685434928b0b8ac923a7", "best_bid": "0.002", "best_ask": "0.007"}], "timestamp": "1769384003923", "event_type": "price_change"}}
{"_local_timestamp": "2026-01-25T23:33:27.433255+00:00", "data": {"market": "0xaf811fcf5edc733781bee6125756d3e1f02d04f2824b89ab7fa4f4ce30f998b5", "price_changes": [{"asset_id": "27643431546680855679789625370218065863059031034570354610668275237893764523490", "price": "0.1", "size": "260", "side": "BUY", "hash": "d1d596861af0300e987ee35aa37cb3a1d77886b1", "best_bid": "0.13", "best_ask": "0.15"}, {"asset_id": "94235206725638004435521288935127321522857776396521937922634976647313998892484", "price": "0.9", "size": "260", "side": "SELL", "hash": "b69dc89e61ab987c617592bbad0802c9e58baa75", "best_bid": "0.85", "best_ask": "0.87"}], "timestamp": "1769384007342", "event_type": "price_change"}}
{"_local_timestamp": "2026-01-25T23:33:40.369273+00:00", "data": {"market": "0x28b09e78c1a37a9212b683d5734c0b8375e9c85777e59bb498a08debb585e941", "price_changes": [{"asset_id": "80377662132340664016724672073316391179500510732361804244421570371942255684414", "price": "0.25", "size": "212", "side": "BUY", "hash": "6934cf0c16a02eb9299d0a0239d913781c0d2dad", "best_bid": "0.985", "best_ask": "0.993"}, {"asset_id": "44648314711717458063074998921644285938870392557850689878450818223237354241500", "price": "0.75", "size": "212", "side": "SELL", "hash": "86a2a6867a7e042f70dd990567c0e964bb9dd29f", "best_bid": "0.007", "best_ask": "0.015"}], "timestamp": "1769384020105", "event_type": "price_change"}}
{"_local_timestamp": "2026-01-25T23:33:40.373843+00:00", "data": {"market": "0x0baf5017c6cdd082b72a9f8d81ce7a5568a11d2185b37f24aec4371feffa4508", "price_changes": [{"asset_id": "54912585197947912918703938085404885715682857902987396027502188879254644524559", "price": "0.25", "size": "212", "side": "BUY", "hash": "ec77daa791219b71d825d9acb49b50fb5cc837eb", "best_bid": "0.993", "best_ask": "0.998"}, {"asset_id": "1398837009918163072638964138392157627970988230992506005676269129994871270413", "price": "0.75", "size": "212", "side": "SELL", "hash": "5b47f2868f1c08834ece2af48f12d4b4033bbc6d", "best_bid": "0.002", "best_ask": "0.007"}], "timestamp": "1769384020105", "event_type": "price_change"}}
{"_local_timestamp": "2026-01-25T23:33:40.662350+00:00", "data": {"market": "0x28b09e78c1a37a9212b683d5734c0b8375e9c85777e59bb498a08debb585e941", "price_changes": [{"asset_id": "80377662132340664016724672073316391179500510732361804244421570371942255684414", "price": "0.251", "size": "2042", "side": "BUY", "hash": "3d7293a148bd702d28f164377013e75f860b4cc9", "best_bid": "0.985", "best_ask": "0.993"}, {"asset_id": "44648314711717458063074998921644285938870392557850689878450818223237354241500", "price": "0.749", "size": "2042", "side": "SELL", "hash": "7a99b5f5cfc218e0fabac36955a4ef54cb23eccb", "best_bid": "0.007", "best_ask": "0.015"}], "timestamp": "1769384020523", "event_type": "price_change"}}
{"_local_timestamp": "2026-01-25T23:33:40.663265+00:00", "data": {"market": "0x0baf5017c6cdd082b72a9f8d81ce7a5568a11d2185b37f24aec4371feffa4508", "price_changes": [{"asset_id": "54912585197947912918703938085404885715682857902987396027502188879254644524559", "price": "0.251", "size": "2042", "side": "BUY", "hash": "766f664119f075348521ba22495eeb5953fb0cbd", "best_bid": "0.993", "best_ask": "0.998"}, {"asset_id": "1398837009918163072638964138392157627970988230992506005676269129994871270413", "price": "0.749", "size": "2042", "side": "SELL", "hash": "67f1e73681110edd6f69db81b6ce3a179aef9599", "best_bid": "0.002", "best_ask": "0.007"}], "timestamp": "1769384020523", "event_type": "price_change"}}
{"_local_timestamp": "2026-01-25T23:33:42.254310+00:00", "data": {"market": "0x28b09e78c1a37a9212b683d5734c0b8375e9c85777e59bb498a08debb585e941", "price_changes": [{"asset_id": "80377662132340664016724672073316391179500510732361804244421570371942255684414", "price": "0.4", "size": "825", "side": "BUY", "hash": "c7c0567b2cca4900c1e627cc8f20552e1944a2a7", "best_bid": "0.985", "best_ask": "0.993"}, {"asset_id": "44648314711717458063074998921644285938870392557850689878450818223237354241500", "price": "0.6", "size": "825", "side": "SELL", "hash": "878063c36ebcd96bd5b6d7e449940654c8d72723", "best_bid": "0.007", "best_ask": "0.015"}], "timestamp": "1769384022188", "event_type": "price_change"}}
{"_local_timestamp": "2026-01-25T23:33:43.325015+00:00", "data": {"market": "0xaf811fcf5edc733781bee6125756d3e1f02d04f2824b89ab7fa4f4ce30f998b5", "price_changes": [{"asset_id": "27643431546680855679789625370218065863059031034570354610668275237893764523490", "price": "0.03", "size": "2271.89", "side": "BUY", "hash": "1140725598d80ea9d950444c5b09c139f1f6d371", "best_bid": "0.13", "best_ask": "0.15"}, {"asset_id": "94235206725638004435521288935127321522857776396521937922634976647313998892484", "price": "0.97", "size": "2271.89", "side": "SELL", "hash": "208ef31d661537f750ca03e910df24dcc54d5c5f", "best_bid": "0.85", "best_ask": "0.87"}], "timestamp": "1769384023254", "event_type": "price_change"}}
{"_local_timestamp": "2026-01-25T23:33:43.874698+00:00", "data": {"market": "0xaf811fcf5edc733781bee6125756d3e1f02d04f2824b89ab7fa4f4ce30f998b5", "price_changes": [{"asset_id": "27643431546680855679789625370218065863059031034570354610668275237893764523490", "price": "0.03", "size": "1571.89", "side": "BUY", "hash": "aa37490a1def5e84fcefb1fa0b770a07c38e2b98", "best_bid": "0.13", "best_ask": "0.15"}, {"asset_id": "94235206725638004435521288935127321522857776396521937922634976647313998892484", "price": "0.97", "size": "1571.89", "side": "SELL", "hash": "844a4ce66bdb6825f8769360965ef57e33013bb0", "best_bid": "0.85", "best_ask": "0.87"}], "timestamp": "1769384023782", "event_type": "price_change"}}
{"_local_timestamp": "2026-01-25T23:33:45.856680+00:00", "data": {"market": "0xaf811fcf5edc733781bee6125756d3e1f02d04f2824b89ab7fa4f4ce30f998b5", "price_changes": [{"asset_id": "94235206725638004435521288935127321522857776396521937922634976647313998892484", "price": "0.24", "size": "1255", "side": "BUY", "hash": "7d98fd40cb8b5af7ece28582d9f606f3b07891b4", "best_bid": "0.85", "best_ask": "0.87"}, {"asset_id": "27643431546680855679789625370218065863059031034570354610668275237893764523490", "price": "0.76", "size": "1255", "side": "SELL", "hash": "4eb5c84e39ead945be0aa46ecbf5c9f74ab4aed9", "best_bid": "0.13", "best_ask": "0.15"}], "timestamp": "1769384025780", "event_type": "price_change"}}
{"_local_timestamp": "2026-01-25T23:33:45.857137+00:00", "data": {"market": "0xaf811fcf5edc733781bee6125756d3e1f02d04f2824b89ab7fa4f4ce30f998b5", "price_changes": [{"asset_id": "94235206725638004435521288935127321522857776396521937922634976647313998892484", "price": "0.31", "size": "150", "side": "BUY", "hash": "370aac3da8de8b967d73ab828442dc4f3459891a", "best_bid": "0.85", "best_ask": "0.87"}, {"asset_id": "27643431546680855679789625370218065863059031034570354610668275237893764523490", "price": "0.69", "size": "150", "side": "SELL", "hash": "798cf91ffd36e261fe1f168d9a5e84845c95a5f8", "best_bid": "0.13", "best_ask": "0.15"}], "timestamp": "1769384025780", "event_type": "price_change"}}
{"_local_timestamp": "2026-01-25T23:33:46.230160+00:00", "data": {"market": "0x2e3433f79c616df13c4955a7134e595ee2ccf4866dce309925e755737b872271", "price_changes": [{"asset_id": "112202945651691176336626757870751886707772553418125673815227809139773741570078", "price": "0.55", "size": "700", "side": "BUY", "hash": "1808769d59b8d3ab1cfed5d8a980b181843bf634", "best_bid": "0.882", "best_ask": "0.916"}, {"asset_id": "18309888943220126175774903330165417854845342977748532448162902228663371934448", "price": "0.45", "size": "700", "side": "SELL", "hash": "741b83ce28a3dcc9104ca33682a334783fc41462", "best_bid": "0.084", "best_ask": "0.118"}], "timestamp": "1769384026152", "event_type": "price_change"}}
{"_local_timestamp": "2026-01-25T23:33:46.231365+00:00", "data": {"market": "0x2e3433f79c616df13c4955a7134e595ee2ccf4866dce309925e755737b872271", "price_changes": [{"asset_id": "112202945651691176336626757870751886707772553418125673815227809139773741570078", "price": "0.79", "size": "150", "side": "BUY", "hash": "416c57ffbeffad43d3f8a997f78f3ce4cbdcd4bc", "best_bid": "0.882", "best_ask": "0.916"}, {"asset_id": "18309888943220126175774903330165417854845342977748532448162902228663371934448", "price": "0.21", "size": "150", "side": "SELL", "hash": "e456a86d0d803382e2c5a862d2eba992f7e0ff04", "best_bid": "0.084", "best_ask": "0.118"}], "timestamp": "1769384026153", "event_type": "price_change"}}
{"_local_timestamp": "2026-01-25T23:33:46.332583+00:00", "data": {"market": "0x2e3433f79c616df13c4955a7134e595ee2ccf4866dce309925e755737b872271", "price_changes": [{"asset_id": "112202945651691176336626757870751886707772553418125673815227809139773741570078", "price": "0.511", "size": "0", "side": "BUY", "hash": "d89d3374a20284d9b9b8ee8d0eb6f1d7d84bba4d", "best_bid": "0.882", "best_ask": "0.916"}, {"asset_id": "18309888943220126175774903330165417854845342977748532448162902228663371934448", "price": "0.489", "size": "0", "side": "SELL", "hash": "ab780d4b09812d5e7fc122f398557f506804f3fa", "best_bid": "0.084", "best_ask": "0.118"}], "timestamp": "1769384026262", "event_type": "price_change"}}
{"_local_timestamp": "2026-01-25T23:33:46.658380+00:00", "data": {"market": "0x2e3433f79c616df13c4955a7134e595ee2ccf4866dce309925e755737b872271", "price_changes": [{"asset_id": "112202945651691176336626757870751886707772553418125673815227809139773741570078", "price": "0.55", "size": "0", "side": "BUY", "hash": "707969020a5ff690f3235b84e312f2924af5346d", "best_bid": "0.882", "best_ask": "0.916"}, {"asset_id": "18309888943220126175774903330165417854845342977748532448162902228663371934448", "price": "0.45", "size": "0", "side": "SELL", "hash": "323326007d8e47a6757df56bfcf0ad05efe7e682", "best_bid": "0.084", "best_ask": "0.118"}], "timestamp": "1769384026585", "event_type": "price_change"}}
{"_local_timestamp": "2026-01-25T23:33:46.742700+00:00", "data": {"market": "0x2e3433f79c616df13c4955a7134e595ee2ccf4866dce309925e755737b872271", "price_changes": [{"asset_id": "112202945651691176336626757870751886707772553418125673815227809139773741570078", "price": "0.339", "size": "800", "side": "BUY", "hash": "26b82d792d72ace39a4a339f65821b6eaa800599", "best_bid": "0.882", "best_ask": "0.916"}, {"asset_id": "18309888943220126175774903330165417854845342977748532448162902228663371934448", "price": "0.661", "size": "800", "side": "SELL", "hash": "cecd22cd6539e6de7e85d0d6fb73dbb689f0389c", "best_bid": "0.084", "best_ask": "0.118"}], "timestamp": "1769384026672", "event_type": "price_change"}}
{"_local_timestamp": "2026-01-25T23:34:10.067226+00:00", "data": {"market": "0xdf0e04194ff7f25807465101e29d7d476bb9cbf7e56e950d2693cedf4787599f", "price_changes": [{"asset_id": "96765239208959541720088187158035685118767037049985993166814389120572666374201", "price": "0.934", "size": "30", "side": "BUY", "hash": "cda65e64642b7c6ee4ffcbde83c323bb362376ce", "best_bid": "0.939", "best_ask": "0.967"}, {"asset_id": "112838519090657527020403907389517191367689011522812125990685217194554034388792", "price": "0.066", "size": "30", "side": "SELL", "hash": "1c0e40b05727a24629b1e2362fda482789de2379", "best_bid": "0.033", "best_ask": "0.061"}], "timestamp": "1769384049986", "event_type": "price_change"}}
{"_local_timestamp": "2026-01-25T23:34:10.073265+00:00", "data": {"market": "0x2e3433f79c616df13c4955a7134e595ee2ccf4866dce309925e755737b872271", "price_changes": [{"asset_id": "18309888943220126175774903330165417854845342977748532448162902228663371934448", "price": "0.084", "size": "21.97", "side": "BUY", "hash": "bb110d69d08be5bfc84d4fc5139d09f5506649bf", "best_bid": "0.084", "best_ask": "0.118"}, {"asset_id": "112202945651691176336626757870751886707772553418125673815227809139773741570078", "price": "0.916", "size": "21.97", "side": "SELL", "hash": "e8b77fd62617d1849c2d9416cbc19ae53ef4a0ce", "best_bid": "0.882", "best_ask": "0.916"}], "timestamp": "1769384049986", "event_type": "price_change"}}
{"_local_timestamp": "2026-01-25T23:34:10.074922+00:00", "data": {"market": "0x2e3433f79c616df13c4955a7134e595ee2ccf4866dce309925e755737b872271", "price_changes": [{"asset_id": "18309888943220126175774903330165417854845342977748532448162902228663371934448", "price": "0.075", "size": "0", "side": "BUY", "hash": "bb110d69d08be5bfc84d4fc5139d09f5506649bf", "best_bid": "0.084", "best_ask": "0.118"}, {"asset_id": "112202945651691176336626757870751886707772553418125673815227809139773741570078", "price": "0.925", "size": "0", "side": "SELL", "hash": "e8b77fd62617d1849c2d9416cbc19ae53ef4a0ce", "best_bid": "0.882", "best_ask": "0.916"}], "timestamp": "1769384049986", "event_type": "price_change"}}
{"_local_timestamp": "2026-01-25T23:34:10.075497+00:00", "data": {"market": "0x2e3433f79c616df13c4955a7134e595ee2ccf4866dce309925e755737b872271", "price_changes": [{"asset_id": "18309888943220126175774903330165417854845342977748532448162902228663371934448", "price": "0.061", "size": "0", "side": "BUY", "hash": "bb110d69d08be5bfc84d4fc5139d09f5506649bf", "best_bid": "0.084", "best_ask": "0.118"}, {"asset_id": "112202945651691176336626757870751886707772553418125673815227809139773741570078", "price": "0.939", "size": "0", "side": "SELL", "hash": "e8b77fd62617d1849c2d9416cbc19ae53ef4a0ce", "best_bid": "0.882", "best_ask": "0.916"}], "timestamp": "1769384049986", "event_type": "price_change"}}
{"_local_timestamp": "2026-01-25T23:34:10.075856+00:00", "data": {"market": "0x2e3433f79c616df13c4955a7134e595ee2ccf4866dce309925e755737b872271", "price_changes": [{"asset_id": "112202945651691176336626757870751886707772553418125673815227809139773741570078", "price": "0.881", "size": "17", "side": "BUY", "hash": "ae041875ad9c10b815d6f231da6a9c05ba3fab0f", "best_bid": "0.882", "best_ask": "0.916"}, {"asset_id": "18309888943220126175774903330165417854845342977748532448162902228663371934448", "price": "0.119", "size": "17", "side": "SELL", "hash": "69c7e359fae35cf5ac5bd6b892b315c75c82c375", "best_bid": "0.084", "best_ask": "0.118"}], "timestamp": "1769384049986", "event_type": "price_change"}}
{"_local_timestamp": "2026-01-25T23:34:10.076116+00:00", "data": {"market": "0x2e3433f79c616df13c4955a7134e595ee2ccf4866dce309925e755737b872271", "price_changes": [{"asset_id": "112202945651691176336626757870751886707772553418125673815227809139773741570078", "price": "0.863", "size": "0", "side": "BUY", "hash": "ae041875ad9c10b815d6f231da6a9c05ba3fab0f", "best_bid": "0.882", "best_ask": "0.916"}, {"asset_id": "18309888943220126175774903330165417854845342977748532448162902228663371934448", "price": "0.137", "size": "0", "side": "SELL", "hash": "69c7e359fae35cf5ac5bd6b892b315c75c82c375", "best_bid": "0.084", "best_ask": "0.118"}], "timestamp": "1769384049986", "event_type": "price_change"}}
{"_local_timestamp": "2026-01-25T23:34:10.076374+00:00", "data": {"market": "0x2e3433f79c616df13c4955a7134e595ee2ccf4866dce309925e755737b872271", "price_changes": [{"asset_id": "112202945651691176336626757870751886707772553418125673815227809139773741570078", "price": "0.847", "size": "123.89", "side": "BUY", "hash": "ae041875ad9c10b815d6f231da6a9c05ba3fab0f", "best_bid": "0.882", "best_ask": "0.916"}, {"asset_id": "18309888943220126175774903330165417854845342977748532448162902228663371934448", "price": "0.153", "size": "123.89", "side": "SELL", "hash": "69c7e359fae35cf5ac5bd6b892b315c75c82c375", "best_bid": "0.084", "best_ask": "0.118"}], "timestamp": "1769384049986", "event_type": "price_change"}}
{"_local_timestamp": "2026-01-25T23:34:10.102289+00:00", "data": {"market": "0xdf0e04194ff7f25807465101e29d7d476bb9cbf7e56e950d2693cedf4787599f", "price_changes": [{"asset_id": "96765239208959541720088187158035685118767037049985993166814389120572666374201", "price": "0.939", "size": "30.93", "side": "BUY", "hash": "16bca58e8d04a4a71343b55c85cd376b13550188", "best_bid": "0.939", "best_ask": "0.967"}, {"asset_id": "112838519090657527020403907389517191367689011522812125990685217194554034388792", "price": "0.061", "size": "30.93", "side": "SELL", "hash": "bf37cedd73ef0c8ea14e85906400da7d1ef8d577", "best_bid": "0.033", "best_ask": "0.061"}], "timestamp": "1769384050011", "event_type": "price_change"}}
{"_local_timestamp": "2026-01-25T23:34:10.265915+00:00", "data": {"market": "0xdf0e04194ff7f25807465101e29d7d476bb9cbf7e56e950d2693cedf4787599f", "price_changes": [{"asset_id": "96765239208959541720088187158035685118767037049985993166814389120572666374201", "price": "0.934", "size": "0", "side": "BUY", "hash": "d47220abffda5eca9687f4a968474efa544d902d", "best_bid": "0.939", "best_ask": "0.967"}, {"asset_id": "112838519090657527020403907389517191367689011522812125990685217194554034388792", "price": "0.066", "size": "0", "side": "SELL", "hash": "836cc7e8fb2da576b8139e803fbd0f7354f810af", "best_bid": "0.033", "best_ask": "0.061"}], "timestamp": "1769384050185", "event_type": "price_change"}}
{"_local_timestamp": "2026-01-25T23:34:10.313912+00:00", "data": {"market": "0xdf0e04194ff7f25807465101e29d7d476bb9cbf7e56e950d2693cedf4787599f", "price_changes": [{"asset_id": "96765239208959541720088187158035685118767037049985993166814389120572666374201", "price": "0.93", "size": "130", "side": "BUY", "hash": "2f00671f17972789d251905482812f2724fe59b0", "best_bid": "0.939", "best_ask": "0.967"}, {"asset_id": "112838519090657527020403907389517191367689011522812125990685217194554034388792", "price": "0.07", "size": "130", "side": "SELL", "hash": "d8ed49cd56b0aa6dcfdb0d50547e553be4e40769", "best_bid": "0.033", "best_ask": "0.061"}], "timestamp": "1769384050246", "event_type": "price_change"}}
{"_local_timestamp": "2026-01-25T23:34:10.712019+00:00", "data": {"market": "0x2e3433f79c616df13c4955a7134e595ee2ccf4866dce309925e755737b872271", "price_changes": [{"asset_id": "112202945651691176336626757870751886707772553418125673815227809139773741570078", "price": "0.851", "size": "66.66", "side": "BUY", "hash": "10b2d156f7841df5272d33a8f3d27929bf2d8b5e", "best_bid": "0.882", "best_ask": "0.916"}, {"asset_id": "18309888943220126175774903330165417854845342977748532448162902228663371934448", "price": "0.149", "size": "66.66", "side": "SELL", "hash": "b252a05352f89b375207b269a0e973bfd9e449bd", "best_bid": "0.084", "best_ask": "0.118"}], "timestamp": "1769384050638", "event_type": "price_change"}}
{"_local_timestamp": "2026-01-25T23:34:10.730406+00:00", "data": {"market": "0xdf0e04194ff7f25807465101e29d7d476bb9cbf7e56e950d2693cedf4787599f", "price_changes": [{"asset_id": "96765239208959541720088187158035685118767037049985993166814389120572666374201", "price": "0.938", "size": "66.66", "side": "BUY", "hash": "0e8a7ca0a84228b6046538d78b25b5c85e1d3471", "best_bid": "0.939", "best_ask": "0.967"}, {"asset_id": "112838519090657527020403907389517191367689011522812125990685217194554034388792", "price": "0.062", "size": "66.66", "side": "SELL", "hash": "e09e3b7fcc2de232a3579f0d93ce893f202f7fe4", "best_bid": "0.033", "best_ask": "0.061"}], "timestamp": "1769384050662", "event_type": "price_change"}}
{"_local_timestamp": "2026-01-25T23:34:10.741865+00:00", "data": {"market": "0x2e3433f79c616df13c4955a7134e595ee2ccf4866dce309925e755737b872271", "price_changes": [{"asset_id": "112202945651691176336626757870751886707772553418125673815227809139773741570078", "price": "0.883", "size": "66.66", "side": "BUY", "hash": "edfa7f33a33c949c52cd604732028de51091a2ce", "best_bid": "0.883", "best_ask": "0.916"}, {"asset_id": "18309888943220126175774903330165417854845342977748532448162902228663371934448", "price": "0.117", "size": "66.66", "side": "SELL", "hash": "18490d44157f04403735e7cf3df186a0f12098f1", "best_bid": "0.084", "best_ask": "0.117"}], "timestamp": "1769384050672", "event_type": "price_change"}}
{"_local_timestamp": "2026-01-25T23:34:10.755018+00:00", "data": {"market": "0x2e3433f79c616df13c4955a7134e595ee2ccf4866dce309925e755737b872271", "price_changes": [{"asset_id": "112202945651691176336626757870751886707772553418125673815227809139773741570078", "price": "0.867", "size": "66.66", "side": "BUY", "hash": "49dd4a20b428302ba9be6d42f18a2537b821404d", "best_bid": "0.883", "best_ask": "0.916"}, {"asset_id": "18309888943220126175774903330165417854845342977748532448162902228663371934448", "price": "0.133", "size": "66.66", "side": "SELL", "hash": "f8173dffcbe2a7bdb47692d2f03724276d4765e2", "best_bid": "0.084", "best_ask": "0.117"}], "timestamp": "1769384050681", "event_type": "price_change"}}
{"_local_timestamp": "2026-01-25T23:34:10.765560+00:00", "data": {"market": "0x2e3433f79c616df13c4955a7134e595ee2ccf4866dce309925e755737b872271", "price_changes": [{"asset_id": "112202945651691176336626757870751886707772553418125673815227809139773741570078", "price": "0.882", "size": "50", "side": "BUY", "hash": "e57af3c141e7c0f075951300755614f820da702d", "best_bid": "0.883", "best_ask": "0.916"}, {"asset_id": "18309888943220126175774903330165417854845342977748532448162902228663371934448", "price": "0.118", "size": "50", "side": "SELL", "hash": "21315d4429e0873b0cec895ca5610340e42b86ff", "best_bid": "0.084", "best_ask": "0.117"}], "timestamp": "1769384050695", "event_type": "price_change"}}
{"_local_timestamp": "2026-01-25T23:34:10.765978+00:00", "data": {"market": "0x2e3433f79c616df13c4955a7134e595ee2ccf4866dce309925e755737b872271", "price_changes": [{"asset_id": "18309888943220126175774903330165417854845342977748532448162902228663371934448", "price": "0.078", "size": "8.04", "side": "BUY", "hash": "a2f8ca9ecf8b7f568a24864f6268a8ac263fa94a", "best_bid": "0.084", "best_ask": "0.117"}, {"asset_id": "112202945651691176336626757870751886707772553418125673815227809139773741570078", "price": "0.922", "size": "8.04", "side": "SELL", "hash": "e6c79db24f87f63bb6371091e862f3148f93d394", "best_bid": "0.883", "best_ask": "0.916"}], "timestamp": "1769384050698", "event_type": "price_change"}}
{"_local_timestamp": "2026-01-25T23:34:10.888427+00:00", "data": {"market": "0x2e3433f79c616df13c4955a7134e595ee2ccf4866dce309925e755737b872271", "price_changes": [{"asset_id": "112202945651691176336626757870751886707772553418125673815227809139773741570078", "price": "0.883", "size": "86.66", "side": "BUY", "hash": "f9828d31f1f4a7d83ad3714b10749514093404f3", "best_bid": "0.883", "best_ask": "0.916"}, {"asset_id": "18309888943220126175774903330165417854845342977748532448162902228663371934448", "price": "0.117", "size": "86.66", "side": "SELL", "hash": "a36b69872e9d484f67b11e18da3600c34c01f1b7", "best_bid": "0.084", "best_ask": "0.117"}], "timestamp": "1769384050820", "event_type": "price_change"}}
{"_local_timestamp": "2026-01-25T23:34:11.060521+00:00", "data": {"market": "0xaf811fcf5edc733781bee6125756d3e1f02d04f2824b89ab7fa4f4ce30f998b5", "price_changes": [{"asset_id": "27643431546680855679789625370218065863059031034570354610668275237893764523490", "price": "0.08", "size": "243.37", "side": "BUY", "hash": "54c6b735515d5ebe11c7c3955458839a7400b1d9", "best_bid": "0.13", "best_ask": "0.15"}, {"asset_id": "94235206725638004435521288935127321522857776396521937922634976647313998892484", "price": "0.92", "size": "243.37", "side": "SELL", "hash": "476da3490d988ca07b5fa8ef9342a5bfae2a8b85", "best_bid": "0.85", "best_ask": "0.87"}], "timestamp": "1769384050985", "event_type": "price_change"}}
{"_local_timestamp": "2026-01-25T23:34:11.061713+00:00", "data": {"market": "0x2e3433f79c616df13c4955a7134e595ee2ccf4866dce309925e755737b872271", "price_changes": [{"asset_id": "112202945651691176336626757870751886707772553418125673815227809139773741570078", "price": "0.792", "size": "0", "side": "BUY", "hash": "eadab8e088741d817dc9a59730765540d7500a39", "best_bid": "0.883", "best_ask": "0.916"}, {"asset_id": "18309888943220126175774903330165417854845342977748532448162902228663371934448", "price": "0.208", "size": "0", "side": "SELL", "hash": "b83e9dc9eb39dd4d09f470b60dbb04765f06f88f", "best_bid": "0.084", "best_ask": "0.117"}], "timestamp": "1769384050985", "event_type": "price_change"}}
{"_local_timestamp": "2026-01-25T23:34:11.219475+00:00", "data": {"market": "0x2e3433f79c616df13c4955a7134e595ee2ccf4866dce309925e755737b872271", "price_changes": [{"asset_id": "112202945651691176336626757870751886707772553418125673815227809139773741570078", "price": "0.793", "size": "0", "side": "BUY", "hash": "a33ddfa95b3522233f6b15efd7d373059ba65a46", "best_bid": "0.883", "best_ask": "0.916"}, {"asset_id": "18309888943220126175774903330165417854845342977748532448162902228663371934448", "price": "0.207", "size": "0", "side": "SELL", "hash": "25b470659631c7c560984f36895bf366dc4f112e", "best_bid": "0.084", "best_ask": "0.117"}], "timestamp": "1769384051124", "event_type": "price_change"}}
{"_local_timestamp": "2026-01-25T23:34:11.235760+00:00", "data": {"market": "0x2e3433f79c616df13c4955a7134e595ee2ccf4866dce309925e755737b872271", "price_changes": [{"asset_id": "112202945651691176336626757870751886707772553418125673815227809139773741570078", "price": "0.852", "size": "30", "side": "BUY", "hash": "d22856cdf9d3ad8fceab73930c6334ed848e9a48", "best_bid": "0.883", "best_ask": "0.916"}, {"asset_id": "18309888943220126175774903330165417854845342977748532448162902228663371934448", "price": "0.148", "size": "30", "side": "SELL", "hash": "c0e2b6bedab0c9c2b2091bf08a93d68bd31bc6d6", "best_bid": "0.084", "best_ask": "0.117"}], "timestamp": "1769384051144", "event_type": "price_change"}}
{"_local_timestamp": "2026-01-25T23:34:11.245412+00:00", "data": {"market": "0x2e3433f79c616df13c4955a7134e595ee2ccf4866dce309925e755737b872271", "price_changes": [{"asset_id": "112202945651691176336626757870751886707772553418125673815227809139773741570078", "price": "0.791", "size": "20", "side": "BUY", "hash": "113d95f0db711122db8f3b9682f8d720abd878c4", "best_bid": "0.883", "best_ask": "0.916"}, {"asset_id": "18309888943220126175774903330165417854845342977748532448162902228663371934448", "price": "0.209", "size": "20", "side": "SELL", "hash": "23d1704cca2b7ecd7fb41dfa323054de19922a01", "best_bid": "0.084", "best_ask": "0.117"}], "timestamp": "1769384051151", "event_type": "price_change"}}
{"_local_timestamp": "2026-01-25T23:34:11.429113+00:00", "data": {"market": "0xdf0e04194ff7f25807465101e29d7d476bb9cbf7e56e950d2693cedf4787599f", "price_changes": [{"asset_id": "96765239208959541720088187158035685118767037049985993166814389120572666374201", "price": "0.93", "size": "100", "side": "BUY", "hash": "40f02a97136fca152ef5773abf021eb4d1ef211b", "best_bid": "0.939", "best_ask": "0.967"}, {"asset_id": "112838519090657527020403907389517191367689011522812125990685217194554034388792", "price": "0.07", "size": "100", "side": "SELL", "hash": "7cd624ecd73a6252adb6df8b7a75d0654db76444", "best_bid": "0.033", "best_ask": "0.061"}], "timestamp": "1769384051358", "event_type": "price_change"}}
{"_local_timestamp": "2026-01-25T23:34:11.501144+00:00", "data": {"market": "0xdf0e04194ff7f25807465101e29d7d476bb9cbf7e56e950d2693cedf4787599f", "price_changes": [{"asset_id": "96765239208959541720088187158035685118767037049985993166814389120572666374201", "price": "0.938", "size": "96.66", "side": "BUY", "hash": "a20acb247a97fa9a550df72088b65c78b07d879f", "best_bid": "0.939", "best_ask": "0.967"}, {"asset_id": "112838519090657527020403907389517191367689011522812125990685217194554034388792", "price": "0.062", "size": "96.66", "side": "SELL", "hash": "91469d69e5f4bca5429dafd3defcbe71d90b7823", "best_bid": "0.033", "best_ask": "0.061"}], "timestamp": "1769384051427", "event_type": "price_change"}}
{"_local_timestamp": "2026-01-25T23:34:12.273479+00:00", "data": {"market": "0xdf0e04194ff7f25807465101e29d7d476bb9cbf7e56e950d2693cedf4787599f", "price_changes": [{"asset_id": "96765239208959541720088187158035685118767037049985993166814389120572666374201", "price": "0.94", "size": "50", "side": "BUY", "hash": "bd7c3197c0b5d5edcf6881bf1cf742e47096dafe", "best_bid": "0.94", "best_ask": "0.967"}, {"asset_id": "112838519090657527020403907389517191367689011522812125990685217194554034388792", "price": "0.06", "size": "50", "side": "SELL", "hash": "95c603b50a19c4bc1c6f09c0774e37ac842ed892", "best_bid": "0.033", "best_ask": "0.06"}], "timestamp": "1769384052200", "event_type": "price_change"}}
{"_local_timestamp": "2026-01-25T23:34:12.626427+00:00", "data": {"market": "0xdf0e04194ff7f25807465101e29d7d476bb9cbf7e56e950d2693cedf4787599f", "price_changes": [{"asset_id": "96765239208959541720088187158035685118767037049985993166814389120572666374201", "price": "0.935", "size": "0", "side": "BUY", "hash": "2561d1f4c589b1556ee5f563460e1ef167965d87", "best_bid": "0.94", "best_ask": "0.967"}, {"asset_id": "112838519090657527020403907389517191367689011522812125990685217194554034388792", "price": "0.065", "size": "0", "side": "SELL", "hash": "7b64cbd54e51484e1f90869b10ca3a2b69d3c128", "best_bid": "0.033", "best_ask": "0.06"}], "timestamp": "1769384052554", "event_type": "price_change"}}
{"_local_timestamp": "2026-01-25T23:34:14.106630+00:00", "data": {"market": "0xdf0e04194ff7f25807465101e29d7d476bb9cbf7e56e950d2693cedf4787599f", "price_changes": [{"asset_id": "96765239208959541720088187158035685118767037049985993166814389120572666374201", "price": "0.938", "size": "66.66", "side": "BUY", "hash": "200e79c9fd7828f597d213cd050aa1fa15672a92", "best_bid": "0.94", "best_ask": "0.967"}, {"asset_id": "112838519090657527020403907389517191367689011522812125990685217194554034388792", "price": "0.062", "size": "66.66", "side": "SELL", "hash": "53e4204543407664996a83a8bd21fa856ef12d27", "best_bid": "0.033", "best_ask": "0.06"}], "timestamp": "1769384054029", "event_type": "price_change"}}
{"_local_timestamp": "2026-01-25T23:34:16.226561+00:00", "data": {"market": "0x2e3433f79c616df13c4955a7134e595ee2ccf4866dce309925e755737b872271", "price_changes": [{"asset_id": "18309888943220126175774903330165417854845342977748532448162902228663371934448", "price": "0.084", "size": "0", "side": "BUY", "hash": "1c8665e3e175200d2444fe7fb498b06a2224fe9b", "best_bid": "0.078", "best_ask": "0.117"}, {"asset_id": "112202945651691176336626757870751886707772553418125673815227809139773741570078", "price": "0.916", "size": "0", "side": "SELL", "hash": "f2c6709c79ce0ffd7a3b40f7572616664e4031b1", "best_bid": "0.883", "best_ask": "0.922"}], "timestamp": "1769384056051", "event_type": "price_change"}}
{"_local_timestamp": "2026-01-25T23:34:16.226993+00:00", "data": {"market": "0xdf0e04194ff7f25807465101e29d7d476bb9cbf7e56e950d2693cedf4787599f", "price_changes": [{"asset_id": "96765239208959541720088187158035685118767037049985993166814389120572666374201", "price": "0.939", "size": "9.93", "side": "BUY", "hash": "88dc7abe528ffb77c7dbe3d4c7f1a734f107cd75", "best_bid": "0.94", "best_ask": "0.967"}, {"asset_id": "112838519090657527020403907389517191367689011522812125990685217194554034388792", "price": "0.061", "size": "9.93", "side": "SELL", "hash": "fb7c285087680d4618248152458dbd8b80de1288", "best_bid": "0.033", "best_ask": "0.06"}], "timestamp": "1769384056074", "event_type": "price_change"}}
{"_local_timestamp": "2026-01-25T23:34:16.227604+00:00", "data": {"market": "0x0baf5017c6cdd082b72a9f8d81ce7a5568a11d2185b37f24aec4371feffa4508", "price_changes": [{"asset_id": "54912585197947912918703938085404885715682857902987396027502188879254644524559", "price": "0.972", "size": "0", "side": "BUY", "hash": "65b4650a2adc9595b5a1222b1bc6ce7c74199dd8", "best_bid": "0.993", "best_ask": "0.998"}, {"asset_id": "1398837009918163072638964138392157627970988230992506005676269129994871270413", "price": "0.028", "size": "0", "side": "SELL", "hash": "0ab6c2f7bbb8f604fca856c0f905262a0eec6038", "best_bid": "0.002", "best_ask": "0.007"}], "timestamp": "1769384056075", "event_type": "price_change"}}
{"_local_timestamp": "2026-01-25T23:34:16.228057+00:00", "data": {"market": "0x28b09e78c1a37a9212b683d5734c0b8375e9c85777e59bb498a08debb585e941", "price_changes": [{"asset_id": "80377662132340664016724672073316391179500510732361804244421570371942255684414", "price": "0.967", "size": "0", "side": "BUY", "hash": "4b0d3d3dd2fca9372313d0a1401aab4552b8d073", "best_bid": "0.985", "best_ask": "0.993"}, {"asset_id": "44648314711717458063074998921644285938870392557850689878450818223237354241500", "price": "0.033", "size": "0", "side": "SELL", "hash": "9530139e8162619aabd0d23664221ff728de0826", "best_bid": "0.007", "best_ask": "0.015"}], "timestamp": "1769384056083", "event_type": "price_change"}}
{"_local_timestamp": "2026-01-25T23:34:16.228439+00:00", "data": {"market": "0xaf811fcf5edc733781bee6125756d3e1f02d04f2824b89ab7fa4f4ce30f998b5", "price_changes": [{"asset_id": "27643431546680855679789625370218065863059031034570354610668275237893764523490", "price": "0.08", "size": "273.37", "side": "BUY", "hash": "7bd3947d1a919aca0ba3583e493092952282ac61", "best_bid": "0.13", "best_ask": "0.15"}, {"asset_id": "94235206725638004435521288935127321522857776396521937922634976647313998892484", "price": "0.92", "size": "273.37", "side": "SELL", "hash": "f8757294d66adf2ad6dbf91221077aa3b45852fa", "best_bid": "0.85", "best_ask": "0.87"}], "timestamp": "1769384056130", "event_type": "price_change"}}
{"_local_timestamp": "2026-01-25T23:34:16.278740+00:00", "data": {"market": "0xdf0e04194ff7f25807465101e29d7d476bb9cbf7e56e950d2693cedf4787599f", "price_changes": [{"asset_id": "96765239208959541720088187158035685118767037049985993166814389120572666374201", "price": "0.935", "size": "20", "side": "BUY", "hash": "68f003184a4b4e87225cc3045cdf56be225d4a46", "best_bid": "0.94", "best_ask": "0.967"}, {"asset_id": "112838519090657527020403907389517191367689011522812125990685217194554034388792", "price": "0.065", "size": "20", "side": "SELL", "hash": "72bc275fb11e4da5bb61e8472dfffdce2b3eb7af", "best_bid": "0.033", "best_ask": "0.06"}], "timestamp": "1769384056201", "event_type": "price_change"}}
{"_local_timestamp": "2026-01-25T23:34:16.279276+00:00", "data": {"market": "0x0baf5017c6cdd082b72a9f8d81ce7a5568a11d2185b37f24aec4371feffa4508", "price_changes": [{"asset_id": "54912585197947912918703938085404885715682857902987396027502188879254644524559", "price": "0.965", "size": "20", "side": "BUY", "hash": "e8da49c1afe321b7499c14f215e949d4b0756599", "best_bid": "0.993", "best_ask": "0.998"}, {"asset_id": "1398837009918163072638964138392157627970988230992506005676269129994871270413", "price": "0.035", "size": "20", "side": "SELL", "hash": "499a457fb4c054fd076cf9b9d1bb636b8e06adaf", "best_bid": "0.002", "best_ask": "0.007"}], "timestamp": "1769384056203", "event_type": "price_change"}}
{"_local_timestamp": "2026-01-25T23:34:16.288946+00:00", "data": {"market": "0x28b09e78c1a37a9212b683d5734c0b8375e9c85777e59bb498a08debb585e941", "price_changes": [{"asset_id": "80377662132340664016724672073316391179500510732361804244421570371942255684414", "price": "0.96", "size": "20", "side": "BUY", "hash": "c626245d742366f60cbcfb99ad9588d7606bb053", "best_bid": "0.985", "best_ask": "0.993"}, {"asset_id": "44648314711717458063074998921644285938870392557850689878450818223237354241500", "price": "0.04", "size": "20", "side": "SELL", "hash": "01623dd7277eac7f8dc416632d8f25d509ad1396", "best_bid": "0.007", "best_ask": "0.015"}], "timestamp": "1769384056210", "event_type": "price_change"}}
{"_local_timestamp": "2026-01-25T23:34:16.558180+00:00", "data": {"market": "0xdf0e04194ff7f25807465101e29d7d476bb9cbf7e56e950d2693cedf4787599f", "price_changes": [{"asset_id": "96765239208959541720088187158035685118767037049985993166814389120572666374201", "price": "0.938", "size": "96.66", "side": "BUY", "hash": "7819ec0974417dacd977acb1dfb0bbc8cb3e9df5", "best_bid": "0.94", "best_ask": "0.967"}, {"asset_id": "112838519090657527020403907389517191367689011522812125990685217194554034388792", "price": "0.062", "size": "96.66", "side": "SELL", "hash": "301611fe85338b3528406dcb2911934871839bdf", "best_bid": "0.033", "best_ask": "0.06"}], "timestamp": "1769384056489", "event_type": "price_change"}}
{"_local_timestamp": "2026-01-25T23:34:17.174068+00:00", "data": {"market": "0xaf811fcf5edc733781bee6125756d3e1f02d04f2824b89ab7fa4f4ce30f998b5", "price_changes": [{"asset_id": "27643431546680855679789625370218065863059031034570354610668275237893764523490", "price": "0.07", "size": "1226", "side": "BUY", "hash": "ca800ee6b14baa89343181bfd4b8a18ec7819596", "best_bid": "0.13", "best_ask": "0.15"}, {"asset_id": "94235206725638004435521288935127321522857776396521937922634976647313998892484", "price": "0.93", "size": "1226", "side": "SELL", "hash": "33b83a6c316d7e06c91ae44071fd3c08b839e6f0", "best_bid": "0.85", "best_ask": "0.87"}], "timestamp": "1769384057105", "event_type": "price_change"}}
{"_local_timestamp": "2026-01-25T23:34:17.176989+00:00", "data": {"market": "0x28b09e78c1a37a9212b683d5734c0b8375e9c85777e59bb498a08debb585e941", "price_changes": [{"asset_id": "80377662132340664016724672073316391179500510732361804244421570371942255684414", "price": "0.918", "size": "0", "side": "BUY", "hash": "384b9832cf4dec257b55d11f746630bdfc3ab9e1", "best_bid": "0.985", "best_ask": "0.993"}, {"asset_id": "44648314711717458063074998921644285938870392557850689878450818223237354241500", "price": "0.082", "size": "0", "side": "SELL", "hash": "5c62a52c95f4b5fd673c995c173d1def1573e5e0", "best_bid": "0.007", "best_ask": "0.015"}], "timestamp": "1769384057106", "event_type": "price_change"}}
{"_local_timestamp": "2026-01-25T23:34:17.177406+00:00", "data": {"market": "0x0baf5017c6cdd082b72a9f8d81ce7a5568a11d2185b37f24aec4371feffa4508", "price_changes": [{"asset_id": "54912585197947912918703938085404885715682857902987396027502188879254644524559", "price": "0.923", "size": "253", "side": "BUY", "hash": "064d8e30157133ffa0a9c00ba672b4c529c75752", "best_bid": "0.993", "best_ask": "0.998"}, {"asset_id": "1398837009918163072638964138392157627970988230992506005676269129994871270413", "price": "0.077", "size": "253", "side": "SELL", "hash": "853b3514e37c887ccbad13c80b7dfb669a68be2d", "best_bid": "0.002", "best_ask": "0.007"}], "timestamp": "1769384057106", "event_type": "price_change"}}
{"_local_timestamp": "2026-01-25T23:34:17.177725+00:00", "data": {"market": "0xdf0e04194ff7f25807465101e29d7d476bb9cbf7e56e950d2693cedf4787599f", "price_changes": [{"asset_id": "96765239208959541720088187158035685118767037049985993166814389120572666374201", "price": "0.887", "size": "0", "side": "BUY", "hash": "aae8f26fd706063a85ddf71f3356039fe434e911", "best_bid": "0.94", "best_ask": "0.967"}, {"asset_id": "112838519090657527020403907389517191367689011522812125990685217194554034388792", "price": "0.113", "size": "0", "side": "SELL", "hash": "651acb4e8f94ba71aae7e6945ea09d473a1f8421", "best_bid": "0.033", "best_ask": "0.06"}], "timestamp": "1769384057106", "event_type": "price_change"}}
{"_local_timestamp": "2026-01-25T23:34:17.213327+00:00", "data": {"market": "0xaf811fcf5edc733781bee6125756d3e1f02d04f2824b89ab7fa4f4ce30f998b5", "price_changes": [{"asset_id": "27643431546680855679789625370218065863059031034570354610668275237893764523490", "price": "0.06", "size": "699.87", "side": "BUY", "hash": "3a9d01a8f3eb5f961d382476c23b6082eea60745", "best_bid": "0.13", "best_ask": "0.15"}, {"asset_id": "94235206725638004435521288935127321522857776396521937922634976647313998892484", "price": "0.94", "size": "699.87", "side": "SELL", "hash": "29dde00377cebed808a7f6b3875fad53a228aaa1", "best_bid": "0.85", "best_ask": "0.87"}], "timestamp": "1769384057139", "event_type": "price_change"}}
{"_local_timestamp": "2026-01-25T23:34:17.214148+00:00", "data": {"market": "0x0baf5017c6cdd082b72a9f8d81ce7a5568a11d2185b37f24aec4371feffa4508", "price_changes": [{"asset_id": "54912585197947912918703938085404885715682857902987396027502188879254644524559", "price": "0.911", "size": "20", "side": "BUY", "hash": "aaac50f22aa26f9622cbe57aede0e48f1c5c3e21", "best_bid": "0.993", "best_ask": "0.998"}, {"asset_id": "1398837009918163072638964138392157627970988230992506005676269129994871270413", "price": "0.089", "size": "20", "side": "SELL", "hash": "11c8c0a0dacfa4881a479a43f534fb2644e99b04", "best_bid": "0.002", "best_ask": "0.007"}], "timestamp": "1769384057139", "event_type": "price_change"}}
{"_local_timestamp": "2026-01-25T23:34:17.214626+00:00", "data": {"market": "0xdf0e04194ff7f25807465101e29d7d476bb9cbf7e56e950d2693cedf4787599f", "price_changes": [{"asset_id": "96765239208959541720088187158035685118767037049985993166814389120572666374201", "price": "0.886", "size": "40", "side": "BUY", "hash": "71480ccd2a50ef2de0cad34b9b7210987724c4ea", "best_bid": "0.94", "best_ask": "0.967"}, {"asset_id": "112838519090657527020403907389517191367689011522812125990685217194554034388792", "price": "0.114", "size": "40", "side": "SELL", "hash": "403513985aa544c2f90a5f173a35fa3f236766e3", "best_bid": "0.033", "best_ask": "0.06"}], "timestamp": "1769384057139", "event_type": "price_change"}}
{"_local_timestamp": "2026-01-25T23:34:17.214999+00:00", "data": {"market": "0x28b09e78c1a37a9212b683d5734c0b8375e9c85777e59bb498a08debb585e941", "price_changes": [{"asset_id": "80377662132340664016724672073316391179500510732361804244421570371942255684414", "price": "0.911", "size": "20", "side": "BUY", "hash": "a843d7cf605c2227649522635c18bb11b95aa95b", "best_bid": "0.985", "best_ask": "0.993"}, {"asset_id": "44648314711717458063074998921644285938870392557850689878450818223237354241500", "price": "0.089", "size": "20", "side": "SELL", "hash": "46332628dea3a5e6ae5bd09053f7c95d4a599a51", "best_bid": "0.007", "best_ask": "0.015"}], "timestamp": "1769384057139", "event_type": "price_change"}}
{"_local_timestamp": "2026-01-25T23:34:18.278590+00:00", "data": {"market": "0xdf0e04194ff7f25807465101e29d7d476bb9cbf7e56e950d2693cedf4787599f", "price_changes": [{"asset_id": "96765239208959541720088187158035685118767037049985993166814389120572666374201", "price": "0.939", "size": "59.93", "side": "BUY", "hash": "fc2ecf1e57487936e9b91eedbe465628da8dc2d2", "best_bid": "0.94", "best_ask": "0.967"}, {"asset_id": "112838519090657527020403907389517191367689011522812125990685217194554034388792", "price": "0.061", "size": "59.93", "side": "SELL", "hash": "9563272d859c45207887a2b151bd3e8d96b98f5e", "best_bid": "0.033", "best_ask": "0.06"}], "timestamp": "1769384058207", "event_type": "price_change"}}
{"_local_timestamp": "2026-01-25T23:34:18.573399+00:00", "data": {"market": "0x2e3433f79c616df13c4955a7134e595ee2ccf4866dce309925e755737b872271", "price_changes": [{"asset_id": "112202945651691176336626757870751886707772553418125673815227809139773741570078", "price": "0.882", "size": "0", "side": "BUY", "hash": "3235b9468984d26b321eb0c21a8eb8dd10cbbed3", "best_bid": "0.883", "best_ask": "0.922"}, {"asset_id": "18309888943220126175774903330165417854845342977748532448162902228663371934448", "price": "0.118", "size": "0", "side": "SELL", "hash": "a81fdafa2b80694cc68ab6f7869c8ca5a97fbdd7", "best_bid": "0.078", "best_ask": "0.117"}], "timestamp": "1769384058503", "event_type": "price_change"}}
{"_local_timestamp": "2026-01-25T23:34:18.597380+00:00", "data": {"market": "0x0baf5017c6cdd082b72a9f8d81ce7a5568a11d2185b37f24aec4371feffa4508", "price_changes": [{"asset_id": "54912585197947912918703938085404885715682857902987396027502188879254644524559", "price": "0.951", "size": "16", "side": "BUY", "hash": "00d9d407a01e5c1acbb0b5383e83351a8ea8d868", "best_bid": "0.993", "best_ask": "0.998"}, {"asset_id": "1398837009918163072638964138392157627970988230992506005676269129994871270413", "price": "0.049", "size": "16", "side": "SELL", "hash": "f29198d11841325ca84330ff26204543a5bd55f6", "best_bid": "0.002", "best_ask": "0.007"}], "timestamp": "1769384058503", "event_type": "price_change"}}
{"_local_timestamp": "2026-01-25T23:34:18.611713+00:00", "data": {"market": "0xdf0e04194ff7f25807465101e29d7d476bb9cbf7e56e950d2693cedf4787599f", "price_changes": [{"asset_id": "96765239208959541720088187158035685118767037049985993166814389120572666374201", "price": "0.94", "size": "0", "side": "BUY", "hash": "9b01aae5ca93896eb856931f8ee63a4685492da7", "best_bid": "0.939", "best_ask": "0.967"}, {"asset_id": "112838519090657527020403907389517191367689011522812125990685217194554034388792", "price": "0.06", "size": "0", "side": "SELL", "hash": "3eb9a20f82b419ddce6c02bff66ebdffd645e834", "best_bid": "0.033", "best_ask": "0.061"}], "timestamp": "1769384058540", "event_type": "price_change"}}
{"_local_timestamp": "2026-01-25T23:34:18.908120+00:00", "data": {"market": "0xdf0e04194ff7f25807465101e29d7d476bb9cbf7e56e950d2693cedf4787599f", "price_changes": [{"asset_id": "96765239208959541720088187158035685118767037049985993166814389120572666374201", "price": "0.938", "size": "66.66", "side": "BUY", "hash": "c2c8c05bb5410f123e1acf2a39ac6d10cbf75f36", "best_bid": "0.939", "best_ask": "0.967"}, {"asset_id": "112838519090657527020403907389517191367689011522812125990685217194554034388792", "price": "0.062", "size": "66.66", "side": "SELL", "hash": "2e2ff30d882be8d04f5ba56baa54ce2928e2df97", "best_bid": "0.033", "best_ask": "0.061"}], "timestamp": "1769384058837", "event_type": "price_change"}}
{"_local_timestamp": "2026-01-25T23:34:18.975152+00:00", "data": {"market": "0xdf0e04194ff7f25807465101e29d7d476bb9cbf7e56e950d2693cedf4787599f", "price_changes": [{"asset_id": "96765239208959541720088187158035685118767037049985993166814389120572666374201", "price": "0.939", "size": "89.93", "side": "BUY", "hash": "c4a26c5e46ea2f65560a8d9f7437ed2a277c538d", "best_bid": "0.939", "best_ask": "0.967"}, {"asset_id": "112838519090657527020403907389517191367689011522812125990685217194554034388792", "price": "0.061", "size": "89.93", "side": "SELL", "hash": "77bde249914ac291c8b5d587c69d5930e251f33e", "best_bid": "0.033", "best_ask": "0.061"}], "timestamp": "1769384058892", "event_type": "price_change"}}
{"_local_timestamp": "2026-01-25T23:34:21.164191+00:00", "data": {"market": "0x2e3433f79c616df13c4955a7134e595ee2ccf4866dce309925e755737b872271", "price_changes": [{"asset_id": "18309888943220126175774903330165417854845342977748532448162902228663371934448", "price": "0.078", "size": "30.01", "side": "BUY", "hash": "fe0a6f25e28bba2f486ea25f237464576ee73b3b", "best_bid": "0.078", "best_ask": "0.117"}, {"asset_id": "112202945651691176336626757870751886707772553418125673815227809139773741570078", "price": "0.922", "size": "30.01", "side": "SELL", "hash": "7c463f71c5692a715a20ce6f138f3c540d44c13c", "best_bid": "0.883", "best_ask": "0.922"}], "timestamp": "1769384061094", "event_type": "price_change"}}
{"_local_timestamp": "2026-01-25T23:34:21.189279+00:00", "data": {"market": "0xdf0e04194ff7f25807465101e29d7d476bb9cbf7e56e950d2693cedf4787599f", "price_changes": [{"asset_id": "96765239208959541720088187158035685118767037049985993166814389120572666374201", "price": "0.935", "size": "0", "side": "BUY", "hash": "d61d3f37fa3911e9db486c3e275da13a1315c31f", "best_bid": "0.939", "best_ask": "0.967"}, {"asset_id": "112838519090657527020403907389517191367689011522812125990685217194554034388792", "price": "0.065", "size": "0", "side": "SELL", "hash": "7ac4a91dadc1557f243005049e7f0589b3f7b5ab", "best_bid": "0.033", "best_ask": "0.061"}], "timestamp": "1769384061116", "event_type": "price_change"}}
{"_local_timestamp": "2026-01-25T23:34:21.307992+00:00", "data": {"market": "0xdf0e04194ff7f25807465101e29d7d476bb9cbf7e56e950d2693cedf4787599f", "price_changes": [{"asset_id": "96765239208959541720088187158035685118767037049985993166814389120572666374201", "price": "0.886", "size": "20", "side": "BUY", "hash": "82c7cf8b13b89c67b6ae7b8926f2f6c9da7e2f1f", "best_bid": "0.939", "best_ask": "0.967"}, {"asset_id": "112838519090657527020403907389517191367689011522812125990685217194554034388792", "price": "0.114", "size": "20", "side": "SELL", "hash": "2f0c89fd8b4315364274a8647e3debd180f93aab", "best_bid": "0.033", "best_ask": "0.061"}], "timestamp": "1769384061235", "event_type": "price_change"}}
{"_local_timestamp": "2026-01-25T23:34:21.340446+00:00", "data": {"market": "0xdf0e04194ff7f25807465101e29d7d476bb9cbf7e56e950d2693cedf4787599f", "price_changes": [{"asset_id": "96765239208959541720088187158035685118767037049985993166814389120572666374201", "price": "0.887", "size": "20", "side": "BUY", "hash": "3c10c75f7cd2d3821ae513ef1b76fee9c122d18c", "best_bid": "0.939", "best_ask": "0.967"}, {"asset_id": "112838519090657527020403907389517191367689011522812125990685217194554034388792", "price": "0.113", "size": "20", "side": "SELL", "hash": "6088304585836a77e4389cc8b04bb26bbe8720c8", "best_bid": "0.033", "best_ask": "0.061"}], "timestamp": "1769384061262", "event_type": "price_change"}}
{"_local_timestamp": "2026-01-25T23:34:22.526600+00:00", "data": {"market": "0xdf0e04194ff7f25807465101e29d7d476bb9cbf7e56e950d2693cedf4787599f", "price_changes": [{"asset_id": "96765239208959541720088187158035685118767037049985993166814389120572666374201", "price": "0.939", "size": "59.93", "side": "BUY", "hash": "72cd02537773eda3d3b2c011b5f2bd92bb53411e", "best_bid": "0.939", "best_ask": "0.967"}, {"asset_id": "112838519090657527020403907389517191367689011522812125990685217194554034388792", "price": "0.061", "size": "59.93", "side": "SELL", "hash": "c14bb5a6c66936d32b5fba05b71efa7448769b3c", "best_bid": "0.033", "best_ask": "0.061"}], "timestamp": "1769384062449", "event_type": "price_change"}}
{"_local_timestamp": "2026-01-25T23:34:22.602025+00:00", "data": {"market": "0xaf811fcf5edc733781bee6125756d3e1f02d04f2824b89ab7fa4f4ce30f998b5", "price_changes": [{"asset_id": "27643431546680855679789625370218065863059031034570354610668275237893764523490", "price": "0.06", "size": "679.87", "side": "BUY", "hash": "b00cf61d01eb0cf755fde10f764fbe8115b95304", "best_bid": "0.13", "best_ask": "0.15"}, {"asset_id": "94235206725638004435521288935127321522857776396521937922634976647313998892484", "price": "0.94", "size": "679.87", "side": "SELL", "hash": "be2494c4bba2b668c8c754bd51077989c3eb824b", "best_bid": "0.85", "best_ask": "0.87"}], "timestamp": "1769384062526", "event_type": "price_change"}}
{"_local_timestamp": "2026-01-25T23:34:27.893665+00:00", "data": {"market": "0x28b09e78c1a37a9212b683d5734c0b8375e9c85777e59bb498a08debb585e941", "price_changes": [{"asset_id": "80377662132340664016724672073316391179500510732361804244421570371942255684414", "price": "0.25", "size": "112", "side": "BUY", "hash": "fdd75e2579a5e1a701890a28855532b1c6f5db1b", "best_bid": "0.985", "best_ask": "0.993"}, {"asset_id": "44648314711717458063074998921644285938870392557850689878450818223237354241500", "price": "0.75", "size": "112", "side": "SELL", "hash": "27f3ca31405a6946a8001d360deaa4ad5d5ceae2", "best_bid": "0.007", "best_ask": "0.015"}], "timestamp": "1769384067618", "event_type": "price_change"}}
{"_local_timestamp": "2026-01-25T23:34:27.897299+00:00", "data": {"market": "0x0baf5017c6cdd082b72a9f8d81ce7a5568a11d2185b37f24aec4371feffa4508", "price_changes": [{"asset_id": "54912585197947912918703938085404885715682857902987396027502188879254644524559", "price": "0.25", "size": "112", "side": "BUY", "hash": "0f1077d0609d50cc051931a55e72f2b131baa99a", "best_bid": "0.993", "best_ask": "0.998"}, {"asset_id": "1398837009918163072638964138392157627970988230992506005676269129994871270413", "price": "0.75", "size": "112", "side": "SELL", "hash": "85667beb141b3ec4714247c9091616fbffbd77cf", "best_bid": "0.002", "best_ask": "0.007"}], "timestamp": "1769384067618", "event_type": "price_change"}}
{"_local_timestamp": "2026-01-25T23:34:28.039409+00:00", "data": {"market": "0xaf811fcf5edc733781bee6125756d3e1f02d04f2824b89ab7fa4f4ce30f998b5", "price_changes": [{"asset_id": "27643431546680855679789625370218065863059031034570354610668275237893764523490", "price": "0.08", "size": "293.37", "side": "BUY", "hash": "4fef3f2b06aa91d894e42312696e93a8118773a2", "best_bid": "0.13", "best_ask": "0.15"}, {"asset_id": "94235206725638004435521288935127321522857776396521937922634976647313998892484", "price": "0.92", "size": "293.37", "side": "SELL", "hash": "522417be611091c589a76e69d22f5230c00b4bfe", "best_bid": "0.85", "best_ask": "0.87"}], "timestamp": "1769384067967", "event_type": "price_change"}}
{"_local_timestamp": "2026-01-25T23:34:28.475671+00:00", "data": {"market": "0x0baf5017c6cdd082b72a9f8d81ce7a5568a11d2185b37f24aec4371feffa4508", "price_changes": [{"asset_id": "54912585197947912918703938085404885715682857902987396027502188879254644524559", "price": "0.251", "size": "2142", "side": "BUY", "hash": "98b55990d764b5e8b1fec0d249691941275a7c16", "best_bid": "0.993", "best_ask": "0.998"}, {"asset_id": "1398837009918163072638964138392157627970988230992506005676269129994871270413", "price": "0.749", "size": "2142", "side": "SELL", "hash": "10c5b32d50970b4d9823be025c98af2c1afbaf2b", "best_bid": "0.002", "best_ask": "0.007"}], "timestamp": "1769384068139", "event_type": "price_change"}}
{"_local_timestamp": "2026-01-25T23:34:28.573661+00:00", "data": {"market": "0x28b09e78c1a37a9212b683d5734c0b8375e9c85777e59bb498a08debb585e941", "price_changes": [{"asset_id": "80377662132340664016724672073316391179500510732361804244421570371942255684414", "price": "0.251", "size": "2142", "side": "BUY", "hash": "4751b6944101039a7b65977952ec490ca27f3687", "best_bid": "0.985", "best_ask": "0.993"}, {"asset_id": "44648314711717458063074998921644285938870392557850689878450818223237354241500", "price": "0.749", "size": "2142", "side": "SELL", "hash": "728f78b8ea77893961934d0d8f75323e8345c086", "best_bid": "0.007", "best_ask": "0.015"}], "timestamp": "1769384068147", "event_type": "price_change"}}
{"_local_timestamp": "2026-01-25T23:34:29.584006+00:00", "data": {"market": "0x2e3433f79c616df13c4955a7134e595ee2ccf4866dce309925e755737b872271", "price_changes": [{"asset_id": "112202945651691176336626757870751886707772553418125673815227809139773741570078", "price": "0.338", "size": "75", "side": "BUY", "hash": "35f4c2d4444a38c8511eed63e5dd008fe90b0632", "best_bid": "0.883", "best_ask": "0.922"}, {"asset_id": "18309888943220126175774903330165417854845342977748532448162902228663371934448", "price": "0.662", "size": "75", "side": "SELL", "hash": "21f79bc173adffa07c84843ba3699e23a591f9e2", "best_bid": "0.078", "best_ask": "0.117"}], "timestamp": "1769384069512", "event_type": "price_change"}}
{"_local_timestamp": "2026-01-25T23:34:30.199561+00:00", "data": {"market": "0x2e3433f79c616df13c4955a7134e595ee2ccf4866dce309925e755737b872271", "price_changes": [{"asset_id": "112202945651691176336626757870751886707772553418125673815227809139773741570078", "price": "0.34", "size": "1176", "side": "BUY", "hash": "0fd077a5b9b62b7c69333f71e2f0da32ae7d320d", "best_bid": "0.883", "best_ask": "0.922"}, {"asset_id": "18309888943220126175774903330165417854845342977748532448162902228663371934448", "price": "0.66", "size": "1176", "side": "SELL", "hash": "dee2d7c28ec91bc7beb538afdd8bb1e7f319ed76", "best_bid": "0.078", "best_ask": "0.117"}], "timestamp": "1769384070038", "event_type": "price_change"}}
{"_local_timestamp": "2026-01-25T23:34:50.029548+00:00", "data": {"market": "0x28b09e78c1a37a9212b683d5734c0b8375e9c85777e59bb498a08debb585e941", "price_changes": [{"asset_id": "80377662132340664016724672073316391179500510732361804244421570371942255684414", "price": "0.4", "size": "125", "side": "BUY", "hash": "3aa966ca8e2b743ce987a3dbc6996094576ea929", "best_bid": "0.985", "best_ask": "0.993"}, {"asset_id": "44648314711717458063074998921644285938870392557850689878450818223237354241500", "price": "0.6", "size": "125", "side": "SELL", "hash": "69f81b3672014c7c1a11961b77e3f10f571764a0", "best_bid": "0.007", "best_ask": "0.015"}], "timestamp": "1769384089959", "event_type": "price_change"}}
{"_local_timestamp": "2026-01-25T23:35:01.717573+00:00", "data": {"market": "0xaf811fcf5edc733781bee6125756d3e1f02d04f2824b89ab7fa4f4ce30f998b5", "price_changes": [{"asset_id": "27643431546680855679789625370218065863059031034570354610668275237893764523490", "price": "0.12", "size": "83.33", "side": "BUY", "hash": "f6bd0eecb28b73762a52d5a28701a1bc7c93ab46", "best_bid": "0.13", "best_ask": "0.15"}, {"asset_id": "94235206725638004435521288935127321522857776396521937922634976647313998892484", "price": "0.88", "size": "83.33", "side": "SELL", "hash": "887a8edce4dbea9606598bcb9a9209811357e15d", "best_bid": "0.85", "best_ask": "0.87"}], "timestamp": "1769384101585", "event_type": "price_change"}}
{"_local_timestamp": "2026-01-25T23:35:01.718032+00:00", "data": {"market": "0xaf811fcf5edc733781bee6125756d3e1f02d04f2824b89ab7fa4f4ce30f998b5", "price_changes": [{"asset_id": "94235206725638004435521288935127321522857776396521937922634976647313998892484", "price": "0.84", "size": "569.99", "side": "BUY", "hash": "26b10178451b0eb2c49e1d35a522e3ea8ba84dc6", "best_bid": "0.85", "best_ask": "0.87"}, {"asset_id": "27643431546680855679789625370218065863059031034570354610668275237893764523490", "price": "0.16", "size": "569.99", "side": "SELL", "hash": "93c169acabcb1d4cb3dd5be89f1ecb13e5284bda", "best_bid": "0.13", "best_ask": "0.15"}], "timestamp": "1769384101586", "event_type": "price_change"}}
{"_local_timestamp": "2026-01-25T23:35:02.601184+00:00", "data": {"market": "0xaf811fcf5edc733781bee6125756d3e1f02d04f2824b89ab7fa4f4ce30f998b5", "price_changes": [{"asset_id": "94235206725638004435521288935127321522857776396521937922634976647313998892484", "price": "0.24", "size": "555", "side": "BUY", "hash": "13503278082925fb3a1227181374287ca75fe4f7", "best_bid": "0.85", "best_ask": "0.87"}, {"asset_id": "27643431546680855679789625370218065863059031034570354610668275237893764523490", "price": "0.76", "size": "555", "side": "SELL", "hash": "260e0ceef4e76eac313b053a6fb6137f5bcebdef", "best_bid": "0.13", "best_ask": "0.15"}], "timestamp": "1769384102452", "event_type": "price_change"}}
{"_local_timestamp": "2026-01-25T23:35:02.601712+00:00", "data": {"market": "0xaf811fcf5edc733781bee6125756d3e1f02d04f2824b89ab7fa4f4ce30f998b5", "price_changes": [{"asset_id": "94235206725638004435521288935127321522857776396521937922634976647313998892484", "price": "0.31", "size": "0", "side": "BUY", "hash": "13503278082925fb3a1227181374287ca75fe4f7", "best_bid": "0.85", "best_ask": "0.87"}, {"asset_id": "27643431546680855679789625370218065863059031034570354610668275237893764523490", "price": "0.69", "size": "0", "side": "SELL", "hash": "260e0ceef4e76eac313b053a6fb6137f5bcebdef", "best_bid": "0.13", "best_ask": "0.15"}], "timestamp": "1769384102452", "event_type": "price_change"}}
{"_local_timestamp": "2026-01-25T23:35:09.264354+00:00", "data": {"market": "0x28b09e78c1a37a9212b683d5734c0b8375e9c85777e59bb498a08debb585e941", "price_changes": [{"asset_id": "80377662132340664016724672073316391179500510732361804244421570371942255684414", "price": "0.251", "size": "150", "side": "BUY", "hash": "9595b3baa80c3bf1ebe252e66f94d6df07ef79c2", "best_bid": "0.985", "best_ask": "0.993"}, {"asset_id": "44648314711717458063074998921644285938870392557850689878450818223237354241500", "price": "0.749", "size": "150", "side": "SELL", "hash": "8996b14e94aec2bd854f4ec1f9755258fd3c9b21", "best_bid": "0.007", "best_ask": "0.015"}], "timestamp": "1769384109072", "event_type": "price_change"}}
{"_local_timestamp": "2026-01-25T23:35:09.772761+00:00", "data": {"market": "0x28b09e78c1a37a9212b683d5734c0b8375e9c85777e59bb498a08debb585e941", "price_changes": [{"asset_id": "80377662132340664016724672073316391179500510732361804244421570371942255684414", "price": "0.201", "size": "2492.01", "side": "BUY", "hash": "f35ea799e1e32b4965c72e26a371e47e67bed3f6", "best_bid": "0.985", "best_ask": "0.993"}, {"asset_id": "44648314711717458063074998921644285938870392557850689878450818223237354241500", "price": "0.799", "size": "2492.01", "side": "SELL", "hash": "09d30aa2d289df9b73a2a8bd356a216346d80297", "best_bid": "0.007", "best_ask": "0.015"}], "timestamp": "1769384109559", "event_type": "price_change"}}
{"_local_timestamp": "2026-01-25T23:35:15.920261+00:00", "data": {"market": "0x0baf5017c6cdd082b72a9f8d81ce7a5568a11d2185b37f24aec4371feffa4508", "price_changes": [{"asset_id": "54912585197947912918703938085404885715682857902987396027502188879254644524559", "price": "0.64", "size": "700", "side": "BUY", "hash": "80ce7f2a54be8642509b3586e9d9448e0a2b7fd8", "best_bid": "0.993", "best_ask": "0.998"}, {"asset_id": "1398837009918163072638964138392157627970988230992506005676269129994871270413", "price": "0.36", "size": "700", "side": "SELL", "hash": "18cc4869e6ee63eb54a8bfc83543868e30d23fb1", "best_bid": "0.002", "best_ask": "0.007"}], "timestamp": "1769384115682", "event_type": "price_change"}}
{"_local_timestamp": "2026-01-25T23:35:16.681283+00:00", "data": {"market": "0x0baf5017c6cdd082b72a9f8d81ce7a5568a11d2185b37f24aec4371feffa4508", "price_changes": [{"asset_id": "54912585197947912918703938085404885715682857902987396027502188879254644524559", "price": "0.64", "size": "0", "side": "BUY", "hash": "070bf8b98cb2a538989720bbbb075c4723e0e152", "best_bid": "0.993", "best_ask": "0.998"}, {"asset_id": "1398837009918163072638964138392157627970988230992506005676269129994871270413", "price": "0.36", "size": "0", "side": "SELL", "hash": "675ef94ff01149919390b99487a0c0a2bba2966b", "best_bid": "0.002", "best_ask": "0.007"}], "timestamp": "1769384116455", "event_type": "price_change"}}
{"_local_timestamp": "2026-01-25T23:35:31.558791+00:00", "data": {"market": "0xdf0e04194ff7f25807465101e29d7d476bb9cbf7e56e950d2693cedf4787599f", "price_changes": [{"asset_id": "112838519090657527020403907389517191367689011522812125990685217194554034388792", "price": "0.02", "size": "0", "side": "BUY", "hash": "d4e627e7846881a4c743bd8022d9c4308aab9df5", "best_bid": "0.033", "best_ask": "0.061"}, {"asset_id": "96765239208959541720088187158035685118767037049985993166814389120572666374201", "price": "0.98", "size": "0", "side": "SELL", "hash": "fd0b576c3e5f9dc4b2ed88c1edd400da30b379b0", "best_bid": "0.939", "best_ask": "0.967"}], "timestamp": "1769384131247", "event_type": "price_change"}}
{"_local_timestamp": "2026-01-25T23:35:31.699829+00:00", "data": {"market": "0xaf811fcf5edc733781bee6125756d3e1f02d04f2824b89ab7fa4f4ce30f998b5", "price_changes": [{"asset_id": "27643431546680855679789625370218065863059031034570354610668275237893764523490", "price": "0.08", "size": "273.37", "side": "BUY", "hash": "249d0177455d7c85702d2ad1cf2811c6b81fcfb3", "best_bid": "0.13", "best_ask": "0.15"}, {"asset_id": "94235206725638004435521288935127321522857776396521937922634976647313998892484", "price": "0.92", "size": "273.37", "side": "SELL", "hash": "3cb0d4bc637c0533621b486cab74596af2a496f8", "best_bid": "0.85", "best_ask": "0.87"}], "timestamp": "1769384131438", "event_type": "price_change"}}
{"_local_timestamp": "2026-01-25T23:35:31.836022+00:00", "data": {"market": "0xaf811fcf5edc733781bee6125756d3e1f02d04f2824b89ab7fa4f4ce30f998b5", "price_changes": [{"asset_id": "27643431546680855679789625370218065863059031034570354610668275237893764523490", "price": "0.06", "size": "699.87", "side": "BUY", "hash": "747cbb9b4dca3d9784456bf3cae3b51a262a7311", "best_bid": "0.13", "best_ask": "0.15"}, {"asset_id": "94235206725638004435521288935127321522857776396521937922634976647313998892484", "price": "0.94", "size": "699.87", "side": "SELL", "hash": "621be7f517021cd5539ba94a1c3459fd92553648", "best_bid": "0.85", "best_ask": "0.87"}], "timestamp": "1769384131615", "event_type": "price_change"}}
{"_local_timestamp": "2026-01-25T23:35:32.754219+00:00", "data": {"market": "0x0baf5017c6cdd082b72a9f8d81ce7a5568a11d2185b37f24aec4371feffa4508", "price_changes": [{"asset_id": "54912585197947912918703938085404885715682857902987396027502188879254644524559", "price": "0.251", "size": "150", "side": "BUY", "hash": "722bc2ce49c5c92b407201ea7a6fed20755cb3ca", "best_bid": "0.993", "best_ask": "0.998"}, {"asset_id": "1398837009918163072638964138392157627970988230992506005676269129994871270413", "price": "0.749", "size": "150", "side": "SELL", "hash": "feb022a75df6b7f704400d367a056e342d55d17b", "best_bid": "0.002", "best_ask": "0.007"}], "timestamp": "1769384132528", "event_type": "price_change"}}
{"_local_timestamp": "2026-01-25T23:35:33.220087+00:00", "data": {"market": "0x0baf5017c6cdd082b72a9f8d81ce7a5568a11d2185b37f24aec4371feffa4508", "price_changes": [{"asset_id": "54912585197947912918703938085404885715682857902987396027502188879254644524559", "price": "0.203", "size": "2463", "side": "BUY", "hash": "0e439ee1b984266d924785f66a2a0c005946f1d3", "best_bid": "0.993", "best_ask": "0.998"}, {"asset_id": "1398837009918163072638964138392157627970988230992506005676269129994871270413", "price": "0.797", "size": "2463", "side": "SELL", "hash": "44bd968aa19feb5f6c18849b57a316ede0d1030f", "best_bid": "0.002", "best_ask": "0.007"}], "timestamp": "1769384132976", "event_type": "price_change"}}
{"_local_timestamp": "2026-01-25T23:35:33.453146+00:00", "data": {"market": "0xdf0e04194ff7f25807465101e29d7d476bb9cbf7e56e950d2693cedf4787599f", "price_changes": [{"asset_id": "112838519090657527020403907389517191367689011522812125990685217194554034388792", "price": "0.02", "size": "450", "side": "BUY", "hash": "5e23029c331968cb221bd837c78a793476e4a0e0", "best_bid": "0.033", "best_ask": "0.061"}, {"asset_id": "96765239208959541720088187158035685118767037049985993166814389120572666374201", "price": "0.98", "size": "450", "side": "SELL", "hash": "1b8ac254214d592f00ec71f842a1a87d86dbd429", "best_bid": "0.939", "best_ask": "0.967"}], "timestamp": "1769384133224", "event_type": "price_change"}}
{"_local_timestamp": "2026-01-25T23:35:51.884288+00:00", "data": {"market": "0x2e3433f79c616df13c4955a7134e595ee2ccf4866dce309925e755737b872271", "price_changes": [{"asset_id": "18309888943220126175774903330165417854845342977748532448162902228663371934448", "price": "0.079", "size": "163", "side": "BUY", "hash": "05b1886ae80d3d9da7cb71d0b10177b18cf774a3", "best_bid": "0.079", "best_ask": "0.117"}, {"asset_id": "112202945651691176336626757870751886707772553418125673815227809139773741570078", "price": "0.921", "size": "163", "side": "SELL", "hash": "86f35f1fdb1d47ba9ec4df6436068171be5b787f", "best_bid": "0.883", "best_ask": "0.921"}], "timestamp": "1769384151813", "event_type": "price_change"}}
{"_local_timestamp": "2026-01-25T23:35:51.908201+00:00", "data": {"market": "0x0baf5017c6cdd082b72a9f8d81ce7a5568a11d2185b37f24aec4371feffa4508", "price_changes": [{"asset_id": "54912585197947912918703938085404885715682857902987396027502188879254644524559", "price": "0.965", "size": "0", "side": "BUY", "hash": "111d7c671aa211b00b3a405ef7a167bab0a6b689", "best_bid": "0.993", "best_ask": "0.998"}, {"asset_id": "1398837009918163072638964138392157627970988230992506005676269129994871270413", "price": "0.035", "size": "0", "side": "SELL", "hash": "2abb32df177ccbe5ffc1457c37ac846d13cba799", "best_bid": "0.002", "best_ask": "0.007"}], "timestamp": "1769384151838", "event_type": "price_change"}}
{"_local_timestamp": "2026-01-25T23:35:51.908542+00:00", "data": {"market": "0x28b09e78c1a37a9212b683d5734c0b8375e9c85777e59bb498a08debb585e941", "price_changes": [{"asset_id": "80377662132340664016724672073316391179500510732361804244421570371942255684414", "price": "0.96", "size": "0", "side": "BUY", "hash": "c5748270d053d2032caf3e9878f207355d7abb9d", "best_bid": "0.985", "best_ask": "0.993"}, {"asset_id": "44648314711717458063074998921644285938870392557850689878450818223237354241500", "price": "0.04", "size": "0", "side": "SELL", "hash": "0f5c4569f1e5699123778a00cbccf240a45e0958", "best_bid": "0.007", "best_ask": "0.015"}], "timestamp": "1769384151840", "event_type": "price_change"}}
{"_local_timestamp": "2026-01-25T23:35:52.034672+00:00", "data": {"market": "0x0baf5017c6cdd082b72a9f8d81ce7a5568a11d2185b37f24aec4371feffa4508", "price_changes": [{"asset_id": "54912585197947912918703938085404885715682857902987396027502188879254644524559", "price": "0.967", "size": "20", "side": "BUY", "hash": "c50d3bb6c905774336175a39c94cc82e3ddf8a7e", "best_bid": "0.993", "best_ask": "0.998"}, {"asset_id": "1398837009918163072638964138392157627970988230992506005676269129994871270413", "price": "0.033", "size": "20", "side": "SELL", "hash": "3926bb49cb2a8496defe0b40d1c33010d561d0f5", "best_bid": "0.002", "best_ask": "0.007"}], "timestamp": "1769384151963", "event_type": "price_change"}}
{"_local_timestamp": "2026-01-25T23:35:52.034984+00:00", "data": {"market": "0x28b09e78c1a37a9212b683d5734c0b8375e9c85777e59bb498a08debb585e941", "price_changes": [{"asset_id": "80377662132340664016724672073316391179500510732361804244421570371942255684414", "price": "0.962", "size": "20", "side": "BUY", "hash": "ad21706720940abb54398e9689ea5a73bd9101bd", "best_bid": "0.985", "best_ask": "0.993"}, {"asset_id": "44648314711717458063074998921644285938870392557850689878450818223237354241500", "price": "0.038", "size": "20", "side": "SELL", "hash": "7a9bc6b6d8b92a7fd411a47167c92d2405b09655", "best_bid": "0.007", "best_ask": "0.015"}], "timestamp": "1769384151964", "event_type": "price_change"}}
{"_local_timestamp": "2026-01-25T23:35:52.173412+00:00", "data": {"market": "0xdf0e04194ff7f25807465101e29d7d476bb9cbf7e56e950d2693cedf4787599f", "price_changes": [{"asset_id": "96765239208959541720088187158035685118767037049985993166814389120572666374201", "price": "0.927", "size": "0", "side": "BUY", "hash": "ba5be3280dc3aefbc1b42f3f5a170606bcfc193b", "best_bid": "0.939", "best_ask": "0.967"}, {"asset_id": "112838519090657527020403907389517191367689011522812125990685217194554034388792", "price": "0.073", "size": "0", "side": "SELL", "hash": "25982248f9f5ca95a301fe94759bd78a0b901425", "best_bid": "0.033", "best_ask": "0.061"}], "timestamp": "1769384152095", "event_type": "price_change"}}
{"_local_timestamp": "2026-01-25T23:35:52.691535+00:00", "data": {"market": "0x2e3433f79c616df13c4955a7134e595ee2ccf4866dce309925e755737b872271", "price_changes": [{"asset_id": "18309888943220126175774903330165417854845342977748532448162902228663371934448", "price": "0.077", "size": "0", "side": "BUY", "hash": "aa5b6d04b0d5e2c3ca28470f46d500e5fc15d4ee", "best_bid": "0.079", "best_ask": "0.117"}, {"asset_id": "112202945651691176336626757870751886707772553418125673815227809139773741570078", "price": "0.923", "size": "0", "side": "SELL", "hash": "dc0f8581f10dfe9d2f96a916268ab3337a494c98", "best_bid": "0.883", "best_ask": "0.921"}], "timestamp": "1769384152614", "event_type": "price_change"}}
{"_local_timestamp": "2026-01-25T23:35:52.692658+00:00", "data": {"market": "0xdf0e04194ff7f25807465101e29d7d476bb9cbf7e56e950d2693cedf4787599f", "price_changes": [{"asset_id": "112838519090657527020403907389517191367689011522812125990685217194554034388792", "price": "0.019", "size": "0", "side": "BUY", "hash": "e0945cc68488b4f40252f4709e8a0bdcbd2569e1", "best_bid": "0.033", "best_ask": "0.061"}, {"asset_id": "96765239208959541720088187158035685118767037049985993166814389120572666374201", "price": "0.981", "size": "0", "side": "SELL", "hash": "bd216c51b3d91c2f8a2be60f541bc40d486fa0f6", "best_bid": "0.939", "best_ask": "0.967"}], "timestamp": "1769384152614", "event_type": "price_change"}}
{"_local_timestamp": "2026-01-25T23:35:52.774664+00:00", "data": {"market": "0xaf811fcf5edc733781bee6125756d3e1f02d04f2824b89ab7fa4f4ce30f998b5", "price_changes": [{"asset_id": "27643431546680855679789625370218065863059031034570354610668275237893764523490", "price": "0.09", "size": "65.91", "side": "BUY", "hash": "fd0f7b4f7216a4bcce51a795c773a803593a4730", "best_bid": "0.13", "best_ask": "0.15"}, {"asset_id": "94235206725638004435521288935127321522857776396521937922634976647313998892484", "price": "0.91", "size": "65.91", "side": "SELL", "hash": "14eb55ca8fe33503d22310bffedfabb22abad33e", "best_bid": "0.85", "best_ask": "0.87"}], "timestamp": "1769384152693", "event_type": "price_change"}}
{"_local_timestamp": "2026-01-25T23:35:52.775104+00:00", "data": {"market": "0x28b09e78c1a37a9212b683d5734c0b8375e9c85777e59bb498a08debb585e941", "price_changes": [{"asset_id": "80377662132340664016724672073316391179500510732361804244421570371942255684414", "price": "0.908", "size": "330", "side": "BUY", "hash": "03a9783cae0eda92acf03a0b6ffa707a298d69c0", "best_bid": "0.985", "best_ask": "0.993"}, {"asset_id": "44648314711717458063074998921644285938870392557850689878450818223237354241500", "price": "0.092", "size": "330", "side": "SELL", "hash": "f7acce5893cab3b342358967bd70c0269a3c3ae7", "best_bid": "0.007", "best_ask": "0.015"}], "timestamp": "1769384152693", "event_type": "price_change"}}
{"_local_timestamp": "2026-01-25T23:35:52.775387+00:00", "data": {"market": "0xaf811fcf5edc733781bee6125756d3e1f02d04f2824b89ab7fa4f4ce30f998b5", "price_changes": [{"asset_id": "27643431546680855679789625370218065863059031034570354610668275237893764523490", "price": "0.1", "size": "60", "side": "BUY", "hash": "ab7d16467a67122e3ce88c49f391cb98e760340e", "best_bid": "0.13", "best_ask": "0.15"}, {"asset_id": "94235206725638004435521288935127321522857776396521937922634976647313998892484", "price": "0.9", "size": "60", "side": "SELL", "hash": "69ab82ec3a50227520114688abd7f3d980cfab42", "best_bid": "0.85", "best_ask": "0.87"}], "timestamp": "1769384152704", "event_type": "price_change"}}
{"_local_timestamp": "2026-01-25T23:35:52.775657+00:00", "data": {"market": "0x2e3433f79c616df13c4955a7134e595ee2ccf4866dce309925e755737b872271", "price_changes": [{"asset_id": "112202945651691176336626757870751886707772553418125673815227809139773741570078", "price": "0.88", "size": "0", "side": "BUY", "hash": "a03281a712167580327fd7fafe36eb145be162ab", "best_bid": "0.883", "best_ask": "0.921"}, {"asset_id": "18309888943220126175774903330165417854845342977748532448162902228663371934448", "price": "0.12", "size": "0", "side": "SELL", "hash": "a5597e6242f2587af17816dd53bc7f0f9a7e9948", "best_bid": "0.079", "best_ask": "0.117"}], "timestamp": "1769384152704", "event_type": "price_change"}}
{"_local_timestamp": "2026-01-25T23:35:52.820473+00:00", "data": {"market": "0xaf811fcf5edc733781bee6125756d3e1f02d04f2824b89ab7fa4f4ce30f998b5", "price_changes": [{"asset_id": "27643431546680855679789625370218065863059031034570354610668275237893764523490", "price": "0.08", "size": "243.37", "side": "BUY", "hash": "e58c8ef424db18f7d7ef8490712cce127325547f", "best_bid": "0.13", "best_ask": "0.15"}, {"asset_id": "94235206725638004435521288935127321522857776396521937922634976647313998892484", "price": "0.92", "size": "243.37", "side": "SELL", "hash": "c89f10a7f55df77038ea52b408d74468d53f4d86", "best_bid": "0.85", "best_ask": "0.87"}], "timestamp": "1769384152749", "event_type": "price_change"}}
{"_local_timestamp": "2026-01-25T23:35:52.912360+00:00", "data": {"market": "0xaf811fcf5edc733781bee6125756d3e1f02d04f2824b89ab7fa4f4ce30f998b5", "price_changes": [{"asset_id": "27643431546680855679789625370218065863059031034570354610668275237893764523490", "price": "0.09", "size": "45.91", "side": "BUY", "hash": "d78d0a363a3ed3b032c9b144aafbe01321c02bb5", "best_bid": "0.13", "best_ask": "0.15"}, {"asset_id": "94235206725638004435521288935127321522857776396521937922634976647313998892484", "price": "0.91", "size": "45.91", "side": "SELL", "hash": "b6f18ebef5bb5ede942c53ad7f0fac416ca90bf2", "best_bid": "0.85", "best_ask": "0.87"}], "timestamp": "1769384152838", "event_type": "price_change"}}
{"_local_timestamp": "2026-01-25T23:35:52.912680+00:00", "data": {"market": "0x28b09e78c1a37a9212b683d5734c0b8375e9c85777e59bb498a08debb585e941", "price_changes": [{"asset_id": "80377662132340664016724672073316391179500510732361804244421570371942255684414", "price": "0.908", "size": "110", "side": "BUY", "hash": "9133e9de4e230b8e11f7449782cef5623df3b94b", "best_bid": "0.985", "best_ask": "0.993"}, {"asset_id": "44648314711717458063074998921644285938870392557850689878450818223237354241500", "price": "0.092", "size": "110", "side": "SELL", "hash": "4430ae1139ffc5af90e9d564cd9e642560c6a472", "best_bid": "0.007", "best_ask": "0.015"}], "timestamp": "1769384152838", "event_type": "price_change"}}
{"_local_timestamp": "2026-01-25T23:35:52.978967+00:00", "data": {"market": "0xaf811fcf5edc733781bee6125756d3e1f02d04f2824b89ab7fa4f4ce30f998b5", "price_changes": [{"asset_id": "27643431546680855679789625370218065863059031034570354610668275237893764523490", "price": "0.06", "size": "679.87", "side": "BUY", "hash": "03e8f367e6a4805a80bcfbfe3a3c3c8c277370c2", "best_bid": "0.13", "best_ask": "0.15"}, {"asset_id": "94235206725638004435521288935127321522857776396521937922634976647313998892484", "price": "0.94", "size": "679.87", "side": "SELL", "hash": "3c93c9393a24ec964067de8190e49ccb8165dd41", "best_bid": "0.85", "best_ask": "0.87"}], "timestamp": "1769384152913", "event_type": "price_change"}}
{"_local_timestamp": "2026-01-25T23:35:52.994586+00:00", "data": {"market": "0xaf811fcf5edc733781bee6125756d3e1f02d04f2824b89ab7fa4f4ce30f998b5", "price_changes": [{"asset_id": "27643431546680855679789625370218065863059031034570354610668275237893764523490", "price": "0.09", "size": "65.91", "side": "BUY", "hash": "f606f03d6f082c7d20090234d745a8699fb316db", "best_bid": "0.13", "best_ask": "0.15"}, {"asset_id": "94235206725638004435521288935127321522857776396521937922634976647313998892484", "price": "0.91", "size": "65.91", "side": "SELL", "hash": "849c13748be103021190a26a0afa9084ca250fb8", "best_bid": "0.85", "best_ask": "0.87"}], "timestamp": "1769384152925", "event_type": "price_change"}}
{"_local_timestamp": "2026-01-25T23:35:53.022558+00:00", "data": {"market": "0xaf811fcf5edc733781bee6125756d3e1f02d04f2824b89ab7fa4f4ce30f998b5", "price_changes": [{"asset_id": "27643431546680855679789625370218065863059031034570354610668275237893764523490", "price": "0.07", "size": "1246", "side": "BUY", "hash": "1ed935fd50f87a406596b75b7fb726a534520143", "best_bid": "0.13", "best_ask": "0.15"}, {"asset_id": "94235206725638004435521288935127321522857776396521937922634976647313998892484", "price": "0.93", "size": "1246", "side": "SELL", "hash": "1bef68ba4762861ddadb83795ade4a1697756045", "best_bid": "0.85", "best_ask": "0.87"}], "timestamp": "1769384152950", "event_type": "price_change"}}
{"_local_timestamp": "2026-01-25T23:35:53.040132+00:00", "data": {"market": "0xaf811fcf5edc733781bee6125756d3e1f02d04f2824b89ab7fa4f4ce30f998b5", "price_changes": [{"asset_id": "27643431546680855679789625370218065863059031034570354610668275237893764523490", "price": "0.09", "size": "85.91", "side": "BUY", "hash": "17d913ae703f12e3373b01d9e54e9037deb47611", "best_bid": "0.13", "best_ask": "0.15"}, {"asset_id": "94235206725638004435521288935127321522857776396521937922634976647313998892484", "price": "0.91", "size": "85.91", "side": "SELL", "hash": "3851975486679466cf6df7d85fd3fc34771db73c", "best_bid": "0.85", "best_ask": "0.87"}], "timestamp": "1769384152971", "event_type": "price_change"}}
{"_local_timestamp": "2026-01-25T23:35:53.403572+00:00", "data": {"market": "0x2e3433f79c616df13c4955a7134e595ee2ccf4866dce309925e755737b872271", "price_changes": [{"asset_id": "18309888943220126175774903330165417854845342977748532448162902228663371934448", "price": "0.079", "size": "0", "side": "BUY", "hash": "b1285cd9415d663d5483676290eb4a5d1d6574dc", "best_bid": "0.078", "best_ask": "0.117"}, {"asset_id": "112202945651691176336626757870751886707772553418125673815227809139773741570078", "price": "0.921", "size": "0", "side": "SELL", "hash": "984af84b64c83b1092513bde016912de816302c9", "best_bid": "0.883", "best_ask": "0.922"}], "timestamp": "1769384153311", "event_type": "price_change"}}
{"_local_timestamp": "2026-01-25T23:35:53.411993+00:00", "data": {"market": "0x28b09e78c1a37a9212b683d5734c0b8375e9c85777e59bb498a08debb585e941", "price_changes": [{"asset_id": "80377662132340664016724672073316391179500510732361804244421570371942255684414", "price": "0.962", "size": "0", "side": "BUY", "hash": "95f4ad345f0486e9a5e0cd569b957ecbf2915c56", "best_bid": "0.985", "best_ask": "0.993"}, {"asset_id": "44648314711717458063074998921644285938870392557850689878450818223237354241500", "price": "0.038", "size": "0", "side": "SELL", "hash": "92987e5816ea00c70090914a27cf066175d2bd1d", "best_bid": "0.007", "best_ask": "0.015"}], "timestamp": "1769384153336", "event_type": "price_change"}}
{"_local_timestamp": "2026-01-25T23:35:53.412388+00:00", "data": {"market": "0x0baf5017c6cdd082b72a9f8d81ce7a5568a11d2185b37f24aec4371feffa4508", "price_changes": [{"asset_id": "54912585197947912918703938085404885715682857902987396027502188879254644524559", "price": "0.967", "size": "0", "side": "BUY", "hash": "0578280b8def07c46a4deddeff7cd2e8d73ecd20", "best_bid": "0.993", "best_ask": "0.998"}, {"asset_id": "1398837009918163072638964138392157627970988230992506005676269129994871270413", "price": "0.033", "size": "0", "side": "SELL", "hash": "b0f2ef7c61d4492694fd7c23e5ac5624b7197277", "best_bid": "0.002", "best_ask": "0.007"}], "timestamp": "1769384153337", "event_type": "price_change"}}
{"_local_timestamp": "2026-01-25T23:35:53.412773+00:00", "data": {"market": "0x2e3433f79c616df13c4955a7134e595ee2ccf4866dce309925e755737b872271", "price_changes": [{"asset_id": "18309888943220126175774903330165417854845342977748532448162902228663371934448", "price": "0.07", "size": "199", "side": "BUY", "hash": "06fff236b9759d3a0ac9913cb2bba57827a59d93", "best_bid": "0.078", "best_ask": "0.117"}, {"asset_id": "112202945651691176336626757870751886707772553418125673815227809139773741570078", "price": "0.93", "size": "199", "side": "SELL", "hash": "f5c7dfb4de18ab26826743551c8b16503732169e", "best_bid": "0.883", "best_ask": "0.922"}], "timestamp": "1769384153338", "event_type": "price_change"}}
{"_local_timestamp": "2026-01-25T23:35:53.497465+00:00", "data": {"market": "0xaf811fcf5edc733781bee6125756d3e1f02d04f2824b89ab7fa4f4ce30f998b5", "price_changes": [{"asset_id": "27643431546680855679789625370218065863059031034570354610668275237893764523490", "price": "0.06", "size": "659.87", "side": "BUY", "hash": "bc025ad4acdc0de7e10d54644c08abb7f54683cf", "best_bid": "0.13", "best_ask": "0.15"}, {"asset_id": "94235206725638004435521288935127321522857776396521937922634976647313998892484", "price": "0.94", "size": "659.87", "side": "SELL", "hash": "96a8fa94c1bdb9b6a68772af23e2d441ae084b22", "best_bid": "0.85", "best_ask": "0.87"}], "timestamp": "1769384153412", "event_type": "price_change"}}
{"_local_timestamp": "2026-01-25T23:35:53.497831+00:00", "data": {"market": "0x28b09e78c1a37a9212b683d5734c0b8375e9c85777e59bb498a08debb585e941", "price_changes": [{"asset_id": "80377662132340664016724672073316391179500510732361804244421570371942255684414", "price": "0.908", "size": "0", "side": "BUY", "hash": "5f3ba2e0dc473098e73adeb0d04b12dfceb56bee", "best_bid": "0.985", "best_ask": "0.993"}, {"asset_id": "44648314711717458063074998921644285938870392557850689878450818223237354241500", "price": "0.092", "size": "0", "side": "SELL", "hash": "25796ada5967cfa2079df3d7928d79ca39b00772", "best_bid": "0.007", "best_ask": "0.015"}], "timestamp": "1769384153412", "event_type": "price_change"}}
{"_local_timestamp": "2026-01-25T23:35:53.559664+00:00", "data": {"market": "0x28b09e78c1a37a9212b683d5734c0b8375e9c85777e59bb498a08debb585e941", "price_changes": [{"asset_id": "80377662132340664016724672073316391179500510732361804244421570371942255684414", "price": "0.961", "size": "20", "side": "BUY", "hash": "dfbf2670ca21a4655f9b3febb0299cc5d0f8db98", "best_bid": "0.985", "best_ask": "0.993"}, {"asset_id": "44648314711717458063074998921644285938870392557850689878450818223237354241500", "price": "0.039", "size": "20", "side": "SELL", "hash": "2f1091edd103c6176ec467b9b0e3b757abd11ee2", "best_bid": "0.007", "best_ask": "0.015"}], "timestamp": "1769384153465", "event_type": "price_change"}}
{"_local_timestamp": "2026-01-25T23:35:53.559993+00:00", "data": {"market": "0x0baf5017c6cdd082b72a9f8d81ce7a5568a11d2185b37f24aec4371feffa4508", "price_changes": [{"asset_id": "54912585197947912918703938085404885715682857902987396027502188879254644524559", "price": "0.966", "size": "20", "side": "BUY", "hash": "f92edd2c61905e0c60e502a511d8f5d2c6471cbd", "best_bid": "0.993", "best_ask": "0.998"}, {"asset_id": "1398837009918163072638964138392157627970988230992506005676269129994871270413", "price": "0.034", "size": "20", "side": "SELL", "hash": "782af5a7e9c8e1c8891e5cdd297975350a1a8b73", "best_bid": "0.002", "best_ask": "0.007"}], "timestamp": "1769384153473", "event_type": "price_change"}}
{"_local_timestamp": "2026-01-25T23:35:53.611855+00:00", "data": {"market": "0xaf811fcf5edc733781bee6125756d3e1f02d04f2824b89ab7fa4f4ce30f998b5", "price_changes": [{"asset_id": "27643431546680855679789625370218065863059031034570354610668275237893764523490", "price": "0.08", "size": "263.37", "side": "BUY", "hash": "78dc5ebc9ad0d2efa8c2b3da6cb6c95b18b1a024", "best_bid": "0.13", "best_ask": "0.15"}, {"asset_id": "94235206725638004435521288935127321522857776396521937922634976647313998892484", "price": "0.92", "size": "263.37", "side": "SELL", "hash": "5a5e4a151e5862a1a21d5d76acb3215abead9766", "best_bid": "0.85", "best_ask": "0.87"}], "timestamp": "1769384153541", "event_type": "price_change"}}
{"_local_timestamp": "2026-01-25T23:35:53.612147+00:00", "data": {"market": "0x28b09e78c1a37a9212b683d5734c0b8375e9c85777e59bb498a08debb585e941", "price_changes": [{"asset_id": "80377662132340664016724672073316391179500510732361804244421570371942255684414", "price": "0.918", "size": "20", "side": "BUY", "hash": "3b8646ef93956c10e706e59ddd013edaebf52249", "best_bid": "0.985", "best_ask": "0.993"}, {"asset_id": "44648314711717458063074998921644285938870392557850689878450818223237354241500", "price": "0.082", "size": "20", "side": "SELL", "hash": "64cda401de114cd1347866f47939705c04b6525c", "best_bid": "0.007", "best_ask": "0.015"}], "timestamp": "1769384153541", "event_type": "price_change"}}
{"_local_timestamp": "2026-01-25T23:35:54.213313+00:00", "data": {"market": "0xaf811fcf5edc733781bee6125756d3e1f02d04f2824b89ab7fa4f4ce30f998b5", "price_changes": [{"asset_id": "27643431546680855679789625370218065863059031034570354610668275237893764523490", "price": "0.1", "size": "860", "side": "BUY", "hash": "db5aaad693e886e906c3080f1e39ba74d6661f2b", "best_bid": "0.13", "best_ask": "0.15"}, {"asset_id": "94235206725638004435521288935127321522857776396521937922634976647313998892484", "price": "0.9", "size": "860", "side": "SELL", "hash": "e2c09a650828ee15d4634995d87604fc5414a79f", "best_bid": "0.85", "best_ask": "0.87"}], "timestamp": "1769384154141", "event_type": "price_change"}}
{"_local_timestamp": "2026-01-25T23:35:54.303688+00:00", "data": {"market": "0xaf811fcf5edc733781bee6125756d3e1f02d04f2824b89ab7fa4f4ce30f998b5", "price_changes": [{"asset_id": "27643431546680855679789625370218065863059031034570354610668275237893764523490", "price": "0.08", "size": "243.37", "side": "BUY", "hash": "512701b0d1f34997e1df9d72181f532cc8d37641", "best_bid": "0.13", "best_ask": "0.15"}, {"asset_id": "94235206725638004435521288935127321522857776396521937922634976647313998892484", "price": "0.92", "size": "243.37", "side": "SELL", "hash": "dd86079254a99521f8ad7422c6f61896b835e804", "best_bid": "0.85", "best_ask": "0.87"}], "timestamp": "1769384154232", "event_type": "price_change"}}
{"_local_timestamp": "2026-01-25T23:35:54.357392+00:00", "data": {"market": "0xaf811fcf5edc733781bee6125756d3e1f02d04f2824b89ab7fa4f4ce30f998b5", "price_changes": [{"asset_id": "27643431546680855679789625370218065863059031034570354610668275237893764523490", "price": "0.06", "size": "679.87", "side": "BUY", "hash": "2ebca9af3f28f511ee1b6fa6afbf2c5c04d333e5", "best_bid": "0.13", "best_ask": "0.15"}, {"asset_id": "94235206725638004435521288935127321522857776396521937922634976647313998892484", "price": "0.94", "size": "679.87", "side": "SELL", "hash": "afdfa5197ef2377073099d8eab58dd66b7fcb645", "best_bid": "0.85", "best_ask": "0.87"}], "timestamp": "1769384154281", "event_type": "price_change"}}
{"_local_timestamp": "2026-01-25T23:35:54.805273+00:00", "data": {"market": "0x2e3433f79c616df13c4955a7134e595ee2ccf4866dce309925e755737b872271", "price_changes": [{"asset_id": "112202945651691176336626757870751886707772553418125673815227809139773741570078", "price": "0.878", "size": "120", "side": "BUY", "hash": "ed4ab8d7a145028d8f77e09811ac2e2b229d9929", "best_bid": "0.883", "best_ask": "0.922"}, {"asset_id": "18309888943220126175774903330165417854845342977748532448162902228663371934448", "price": "0.122", "size": "120", "side": "SELL", "hash": "9000271f094fe37d5c28507718887aa272addcc4", "best_bid": "0.078", "best_ask": "0.117"}], "timestamp": "1769384154708", "event_type": "price_change"}}
{"_local_timestamp": "2026-01-25T23:35:54.839311+00:00", "data": {"market": "0xaf811fcf5edc733781bee6125756d3e1f02d04f2824b89ab7fa4f4ce30f998b5", "price_changes": [{"asset_id": "27643431546680855679789625370218065863059031034570354610668275237893764523490", "price": "0.07", "size": "1226", "side": "BUY", "hash": "20b34c1982949f4ec8561b7ac8325d9eb4b69dc1", "best_bid": "0.13", "best_ask": "0.15"}, {"asset_id": "94235206725638004435521288935127321522857776396521937922634976647313998892484", "price": "0.93", "size": "1226", "side": "SELL", "hash": "111c36d0b7bab8bb4a46885f151e4a0b52a0aaf9", "best_bid": "0.85", "best_ask": "0.87"}], "timestamp": "1769384154771", "event_type": "price_change"}}
{"_local_timestamp": "2026-01-25T23:35:54.864890+00:00", "data": {"market": "0xdf0e04194ff7f25807465101e29d7d476bb9cbf7e56e950d2693cedf4787599f", "price_changes": [{"asset_id": "96765239208959541720088187158035685118767037049985993166814389120572666374201", "price": "0.933", "size": "120", "side": "BUY", "hash": "43720af632513a355ac32b5fa866171d0f9a4192", "best_bid": "0.939", "best_ask": "0.967"}, {"asset_id": "112838519090657527020403907389517191367689011522812125990685217194554034388792", "price": "0.067", "size": "120", "side": "SELL", "hash": "2c14f7bc3c77d76cba000c011d8bd314ad28b85c", "best_bid": "0.033", "best_ask": "0.061"}], "timestamp": "1769384154794", "event_type": "price_change"}}
{"_local_timestamp": "2026-01-25T23:35:54.865286+00:00", "data": {"market": "0x2e3433f79c616df13c4955a7134e595ee2ccf4866dce309925e755737b872271", "price_changes": [{"asset_id": "18309888943220126175774903330165417854845342977748532448162902228663371934448", "price": "0.068", "size": "489.64", "side": "BUY", "hash": "d6af75b348ab170b0503fad2a92f9d5403a0fe4d", "best_bid": "0.078", "best_ask": "0.117"}, {"asset_id": "112202945651691176336626757870751886707772553418125673815227809139773741570078", "price": "0.932", "size": "489.64", "side": "SELL", "hash": "e79a75ebf49830530df6a62234d05a64808e2b27", "best_bid": "0.883", "best_ask": "0.922"}], "timestamp": "1769384154795", "event_type": "price_change"}}
{"_local_timestamp": "2026-01-25T23:35:54.903933+00:00", "data": {"market": "0xdf0e04194ff7f25807465101e29d7d476bb9cbf7e56e950d2693cedf4787599f", "price_changes": [{"asset_id": "112838519090657527020403907389517191367689011522812125990685217194554034388792", "price": "0.016", "size": "961.12", "side": "BUY", "hash": "225eec2a12d02a5218ef2d3c385d2c76847931b8", "best_bid": "0.033", "best_ask": "0.061"}, {"asset_id": "96765239208959541720088187158035685118767037049985993166814389120572666374201", "price": "0.984", "size": "961.12", "side": "SELL", "hash": "ee0d8a67776c70354f4d13eb0c0f53a17c8872c8", "best_bid": "0.939", "best_ask": "0.967"}], "timestamp": "1769384154796", "event_type": "price_change"}}
{"_local_timestamp": "2026-01-25T23:35:54.904263+00:00", "data": {"market": "0xaf811fcf5edc733781bee6125756d3e1f02d04f2824b89ab7fa4f4ce30f998b5", "price_changes": [{"asset_id": "27643431546680855679789625370218065863059031034570354610668275237893764523490", "price": "0.06", "size": "699.87", "side": "BUY", "hash": "f6fcdc2e1a8dbdfd9e35bd3170e82663d37090d0", "best_bid": "0.13", "best_ask": "0.15"}, {"asset_id": "94235206725638004435521288935127321522857776396521937922634976647313998892484", "price": "0.94", "size": "699.87", "side": "SELL", "hash": "abbec86d4c09f38a0888a6505e846e2b44ff56ee", "best_bid": "0.85", "best_ask": "0.87"}], "timestamp": "1769384154804", "event_type": "price_change"}}
{"_local_timestamp": "2026-01-25T23:35:55.358922+00:00", "data": {"market": "0xdf0e04194ff7f25807465101e29d7d476bb9cbf7e56e950d2693cedf4787599f", "price_changes": [{"asset_id": "96765239208959541720088187158035685118767037049985993166814389120572666374201", "price": "0.939", "size": "89.93", "side": "BUY", "hash": "f918ff7fdaf22eeb2b5df4b28e9aba21da27cde8", "best_bid": "0.939", "best_ask": "0.967"}, {"asset_id": "112838519090657527020403907389517191367689011522812125990685217194554034388792", "price": "0.061", "size": "89.93", "side": "SELL", "hash": "803d3a258aa7745ef07b0b24540c68dc514e1972", "best_bid": "0.033", "best_ask": "0.061"}], "timestamp": "1769384155285", "event_type": "price_change"}}
{"_local_timestamp": "2026-01-25T23:36:28.961809+00:00", "data": {"market": "0xdf0e04194ff7f25807465101e29d7d476bb9cbf7e56e950d2693cedf4787599f", "price_changes": [{"asset_id": "112838519090657527020403907389517191367689011522812125990685217194554034388792", "price": "0.02", "size": "0", "side": "BUY", "hash": "23cc8078de2eeb85f6e86ff168b5257eb055753b", "best_bid": "0.033", "best_ask": "0.061"}, {"asset_id": "96765239208959541720088187158035685118767037049985993166814389120572666374201", "price": "0.98", "size": "0", "side": "SELL", "hash": "fdfd7bae3b9cadc24283beaf8ee6b57d31b8e1f0", "best_bid": "0.939", "best_ask": "0.967"}], "timestamp": "1769384188848", "event_type": "price_change"}}
{"_local_timestamp": "2026-01-25T23:36:29.148951+00:00", "data": {"market": "0x2e3433f79c616df13c4955a7134e595ee2ccf4866dce309925e755737b872271", "price_changes": [{"asset_id": "112202945651691176336626757870751886707772553418125673815227809139773741570078", "price": "0.852", "size": "0", "side": "BUY", "hash": "1c2b92456eefb3cdc399158e93ce2a356b9ef4bd", "best_bid": "0.883", "best_ask": "0.922"}, {"asset_id": "18309888943220126175774903330165417854845342977748532448162902228663371934448", "price": "0.148", "size": "0", "side": "SELL", "hash": "9d3f5622314696109065c47f3a57b2b79ea73f03", "best_bid": "0.078", "best_ask": "0.117"}], "timestamp": "1769384189012", "event_type": "price_change"}}
{"_local_timestamp": "2026-01-25T23:36:29.216381+00:00", "data": {"market": "0x2e3433f79c616df13c4955a7134e595ee2ccf4866dce309925e755737b872271", "price_changes": [{"asset_id": "112202945651691176336626757870751886707772553418125673815227809139773741570078", "price": "0.792", "size": "20", "side": "BUY", "hash": "236e866946058f38f94c9e9d60b2dec240007835", "best_bid": "0.883", "best_ask": "0.922"}, {"asset_id": "18309888943220126175774903330165417854845342977748532448162902228663371934448", "price": "0.208", "size": "20", "side": "SELL", "hash": "190354471efe09d0c35bff6d4ec14594bf891fb8", "best_bid": "0.078", "best_ask": "0.117"}], "timestamp": "1769384189141", "event_type": "price_change"}}
{"_local_timestamp": "2026-01-25T23:36:30.390304+00:00", "data": {"market": "0x2e3433f79c616df13c4955a7134e595ee2ccf4866dce309925e755737b872271", "price_changes": [{"asset_id": "112202945651691176336626757870751886707772553418125673815227809139773741570078", "price": "0.791", "size": "0", "side": "BUY", "hash": "f9ca1486c109143ace4c2ba584ffc1d1bc98ada8", "best_bid": "0.883", "best_ask": "0.922"}, {"asset_id": "18309888943220126175774903330165417854845342977748532448162902228663371934448", "price": "0.209", "size": "0", "side": "SELL", "hash": "632c5ac4a23baeea093108859491702b1e94a52d", "best_bid": "0.078", "best_ask": "0.117"}], "timestamp": "1769384190306", "event_type": "price_change"}}
{"_local_timestamp": "2026-01-25T23:36:30.402885+00:00", "data": {"market": "0x2e3433f79c616df13c4955a7134e595ee2ccf4866dce309925e755737b872271", "price_changes": [{"asset_id": "112202945651691176336626757870751886707772553418125673815227809139773741570078", "price": "0.793", "size": "20", "side": "BUY", "hash": "ea270bdf0f4add15f3c6c143251057ae00ef59b5", "best_bid": "0.883", "best_ask": "0.922"}, {"asset_id": "18309888943220126175774903330165417854845342977748532448162902228663371934448", "price": "0.207", "size": "20", "side": "SELL", "hash": "eb229c60da2d017f33d3d95be88483ab59bac3fc", "best_bid": "0.078", "best_ask": "0.117"}], "timestamp": "1769384190333", "event_type": "price_change"}}
{"_local_timestamp": "2026-01-25T23:36:30.773300+00:00", "data": {"market": "0xdf0e04194ff7f25807465101e29d7d476bb9cbf7e56e950d2693cedf4787599f", "price_changes": [{"asset_id": "112838519090657527020403907389517191367689011522812125990685217194554034388792", "price": "0.017", "size": "534.46", "side": "BUY", "hash": "48fe4595a57abdf99c50b5b1275ea9c6dd730c4d", "best_bid": "0.033", "best_ask": "0.061"}, {"asset_id": "96765239208959541720088187158035685118767037049985993166814389120572666374201", "price": "0.983", "size": "534.46", "side": "SELL", "hash": "fd59ea173bae45ed0674e9b3146d3e8ef08e59c0", "best_bid": "0.939", "best_ask": "0.967"}], "timestamp": "1769384190689", "event_type": "price_change"}}
{"_local_timestamp": "2026-01-25T23:36:50.628865+00:00", "data": {"market": "0xdf0e04194ff7f25807465101e29d7d476bb9cbf7e56e950d2693cedf4787599f", "price_changes": [{"asset_id": "96765239208959541720088187158035685118767037049985993166814389120572666374201", "price": "0.908", "size": "190", "side": "BUY", "hash": "4d99f8e0793bcb23205bf3f548cfb235ddbd6dd8", "best_bid": "0.939", "best_ask": "0.967"}, {"asset_id": "112838519090657527020403907389517191367689011522812125990685217194554034388792", "price": "0.092", "size": "190", "side": "SELL", "hash": "57e3d4abdac91a51d58aade3bec554c0b84045f0", "best_bid": "0.033", "best_ask": "0.061"}], "timestamp": "1769384210552", "event_type": "price_change"}}
{"_local_timestamp": "2026-01-25T23:36:50.629259+00:00", "data": {"market": "0x2e3433f79c616df13c4955a7134e595ee2ccf4866dce309925e755737b872271", "price_changes": [{"asset_id": "112202945651691176336626757870751886707772553418125673815227809139773741570078", "price": "0.868", "size": "190", "side": "BUY", "hash": "937a1bcd8413a996d98278096ea6c1bf4aad46f0", "best_bid": "0.883", "best_ask": "0.922"}, {"asset_id": "18309888943220126175774903330165417854845342977748532448162902228663371934448", "price": "0.132", "size": "190", "side": "SELL", "hash": "8a7aa9fa406c417bd5704adaf8e8e5fc6298d219", "best_bid": "0.078", "best_ask": "0.117"}], "timestamp": "1769384210552", "event_type": "price_change"}}
{"_local_timestamp": "2026-01-25T23:36:50.629508+00:00", "data": {"market": "0xdf0e04194ff7f25807465101e29d7d476bb9cbf7e56e950d2693cedf4787599f", "price_changes": [{"asset_id": "96765239208959541720088187158035685118767037049985993166814389120572666374201", "price": "0.888", "size": "190", "side": "BUY", "hash": "7a193d2c407d8154cd7a6bd1cdd93cc3d3566052", "best_bid": "0.939", "best_ask": "0.967"}, {"asset_id": "112838519090657527020403907389517191367689011522812125990685217194554034388792", "price": "0.112", "size": "190", "side": "SELL", "hash": "bd0e785db93c0e671248cb02bacb1e6bd034e463", "best_bid": "0.033", "best_ask": "0.061"}], "timestamp": "1769384210553", "event_type": "price_change"}}
{"_local_timestamp": "2026-01-25T23:36:50.786838+00:00", "data": {"market": "0x2e3433f79c616df13c4955a7134e595ee2ccf4866dce309925e755737b872271", "price_changes": [{"asset_id": "112202945651691176336626757870751886707772553418125673815227809139773741570078", "price": "0.339", "size": "0", "side": "BUY", "hash": "6f9fed16911cc3e7b31e5672b47e34a977182207", "best_bid": "0.883", "best_ask": "0.922"}, {"asset_id": "18309888943220126175774903330165417854845342977748532448162902228663371934448", "price": "0.661", "size": "0", "side": "SELL", "hash": "9e00823c67e92f98a184150b0fa2997bec661508", "best_bid": "0.078", "best_ask": "0.117"}], "timestamp": "1769384210717", "event_type": "price_change"}}
{"_local_timestamp": "2026-01-25T23:36:50.937728+00:00", "data": {"market": "0x2e3433f79c616df13c4955a7134e595ee2ccf4866dce309925e755737b872271", "price_changes": [{"asset_id": "112202945651691176336626757870751886707772553418125673815227809139773741570078", "price": "0.341", "size": "800", "side": "BUY", "hash": "ff993d7fff17bbb2db0a0322b1b2b5f2fecd690c", "best_bid": "0.883", "best_ask": "0.922"}, {"asset_id": "18309888943220126175774903330165417854845342977748532448162902228663371934448", "price": "0.659", "size": "800", "side": "SELL", "hash": "1699c945ce71ed5eeb4db48d06affedda6b4b561", "best_bid": "0.078", "best_ask": "0.117"}], "timestamp": "1769384210858", "event_type": "price_change"}}
{"_local_timestamp": "2026-01-25T23:36:53.709024+00:00", "data": {"market": "0x2e3433f79c616df13c4955a7134e595ee2ccf4866dce309925e755737b872271", "price_changes": [{"asset_id": "112202945651691176336626757870751886707772553418125673815227809139773741570078", "price": "0.851", "size": "0", "side": "BUY", "hash": "5bfdb99d5e5b3566142e4085be4d4ff4166155df", "best_bid": "0.883", "best_ask": "0.922"}, {"asset_id": "18309888943220126175774903330165417854845342977748532448162902228663371934448", "price": "0.149", "size": "0", "side": "SELL", "hash": "d15b522dea4ddccb6672d33735d6aa09e3a54dd7", "best_bid": "0.078", "best_ask": "0.117"}], "timestamp": "1769384213642", "event_type": "price_change"}}
{"_local_timestamp": "2026-01-25T23:36:53.710556+00:00", "data": {"market": "0xaf811fcf5edc733781bee6125756d3e1f02d04f2824b89ab7fa4f4ce30f998b5", "price_changes": [{"asset_id": "27643431546680855679789625370218065863059031034570354610668275237893764523490", "price": "0.11", "size": "185.17", "side": "BUY", "hash": "ac3ff4e2ba00c673297a5b35292a7c2c920f84f9", "best_bid": "0.13", "best_ask": "0.15"}, {"asset_id": "94235206725638004435521288935127321522857776396521937922634976647313998892484", "price": "0.89", "size": "185.17", "side": "SELL", "hash": "94db4f38045f22d8a5e96f10f222f722f186df1d", "best_bid": "0.85", "best_ask": "0.87"}], "timestamp": "1769384213642", "event_type": "price_change"}}
{"_local_timestamp": "2026-01-25T23:36:53.710868+00:00", "data": {"market": "0xaf811fcf5edc733781bee6125756d3e1f02d04f2824b89ab7fa4f4ce30f998b5", "price_changes": [{"asset_id": "27643431546680855679789625370218065863059031034570354610668275237893764523490", "price": "0.09", "size": "45.78", "side": "BUY", "hash": "ac3ff4e2ba00c673297a5b35292a7c2c920f84f9", "best_bid": "0.13", "best_ask": "0.15"}, {"asset_id": "94235206725638004435521288935127321522857776396521937922634976647313998892484", "price": "0.91", "size": "45.78", "side": "SELL", "hash": "94db4f38045f22d8a5e96f10f222f722f186df1d", "best_bid": "0.85", "best_ask": "0.87"}], "timestamp": "1769384213642", "event_type": "price_change"}}
{"_local_timestamp": "2026-01-25T23:36:53.711116+00:00", "data": {"market": "0xdf0e04194ff7f25807465101e29d7d476bb9cbf7e56e950d2693cedf4787599f", "price_changes": [{"asset_id": "96765239208959541720088187158035685118767037049985993166814389120572666374201", "price": "0.883", "size": "0", "side": "BUY", "hash": "2d2803846bf859698f06d97685d4ea9e17c50f91", "best_bid": "0.939", "best_ask": "0.967"}, {"asset_id": "112838519090657527020403907389517191367689011522812125990685217194554034388792", "price": "0.117", "size": "0", "side": "SELL", "hash": "612c2778d01675dae6493cc814fd3e5fdaf8d2f0", "best_bid": "0.033", "best_ask": "0.061"}], "timestamp": "1769384213642", "event_type": "price_change"}}
{"_local_timestamp": "2026-01-25T23:36:53.711366+00:00", "data": {"market": "0xdf0e04194ff7f25807465101e29d7d476bb9cbf7e56e950d2693cedf4787599f", "price_changes": [{"asset_id": "96765239208959541720088187158035685118767037049985993166814389120572666374201", "price": "0.832", "size": "0", "side": "BUY", "hash": "2d2803846bf859698f06d97685d4ea9e17c50f91", "best_bid": "0.939", "best_ask": "0.967"}, {"asset_id": "112838519090657527020403907389517191367689011522812125990685217194554034388792", "price": "0.168", "size": "0", "side": "SELL", "hash": "612c2778d01675dae6493cc814fd3e5fdaf8d2f0", "best_bid": "0.033", "best_ask": "0.061"}], "timestamp": "1769384213642", "event_type": "price_change"}}
{"_local_timestamp": "2026-01-25T23:36:54.145151+00:00", "data": {"market": "0xdf0e04194ff7f25807465101e29d7d476bb9cbf7e56e950d2693cedf4787599f", "price_changes": [{"asset_id": "96765239208959541720088187158035685118767037049985993166814389120572666374201", "price": "0.909", "size": "66.66", "side": "BUY", "hash": "485d0b4ef7b10e4ef5d6495a90faa2d92345c288", "best_bid": "0.939", "best_ask": "0.967"}, {"asset_id": "112838519090657527020403907389517191367689011522812125990685217194554034388792", "price": "0.091", "size": "66.66", "side": "SELL", "hash": "0c51576da3cf86b3a6114b5f8c1b9e3c37d50f5f", "best_bid": "0.033", "best_ask": "0.061"}], "timestamp": "1769384214065", "event_type": "price_change"}}
{"_local_timestamp": "2026-01-25T23:36:54.169949+00:00", "data": {"market": "0xdf0e04194ff7f25807465101e29d7d476bb9cbf7e56e950d2693cedf4787599f", "price_changes": [{"asset_id": "96765239208959541720088187158035685118767037049985993166814389120572666374201", "price": "0.923", "size": "66.66", "side": "BUY", "hash": "9f84b125ae474b58679d9b76ea06e3a6fed107d8", "best_bid": "0.939", "best_ask": "0.967"}, {"asset_id": "112838519090657527020403907389517191367689011522812125990685217194554034388792", "price": "0.077", "size": "66.66", "side": "SELL", "hash": "360dda688bb3eb49e8142510600a67ee9c18a03b", "best_bid": "0.033", "best_ask": "0.061"}], "timestamp": "1769384214098", "event_type": "price_change"}}
{"_local_timestamp": "2026-01-25T23:36:54.189265+00:00", "data": {"market": "0x2e3433f79c616df13c4955a7134e595ee2ccf4866dce309925e755737b872271", "price_changes": [{"asset_id": "112202945651691176336626757870751886707772553418125673815227809139773741570078", "price": "0.875", "size": "66.66", "side": "BUY", "hash": "5af35f1d8d4e0756afa36eb2c53a5315b66b9669", "best_bid": "0.883", "best_ask": "0.922"}, {"asset_id": "18309888943220126175774903330165417854845342977748532448162902228663371934448", "price": "0.125", "size": "66.66", "side": "SELL", "hash": "d61964ff096b09cede87787e5d873580b45d0bce", "best_bid": "0.078", "best_ask": "0.117"}], "timestamp": "1769384214118", "event_type": "price_change"}}
{"_local_timestamp": "2026-01-25T23:36:54.218356+00:00", "data": {"market": "0x2e3433f79c616df13c4955a7134e595ee2ccf4866dce309925e755737b872271", "price_changes": [{"asset_id": "18309888943220126175774903330165417854845342977748532448162902228663371934448", "price": "0.074", "size": "40.23", "side": "BUY", "hash": "4aace76912c4e2e35e2a25e4507aea553990e41c", "best_bid": "0.078", "best_ask": "0.117"}, {"asset_id": "112202945651691176336626757870751886707772553418125673815227809139773741570078", "price": "0.926", "size": "40.23", "side": "SELL", "hash": "fb6b4cfe94f9971960229f0b29e0c8d9ff28435c", "best_bid": "0.883", "best_ask": "0.922"}], "timestamp": "1769384214151", "event_type": "price_change"}}
{"_local_timestamp": "2026-01-25T23:36:54.233023+00:00", "data": {"market": "0x2e3433f79c616df13c4955a7134e595ee2ccf4866dce309925e755737b872271", "price_changes": [{"asset_id": "18309888943220126175774903330165417854845342977748532448162902228663371934448", "price": "0.079", "size": "40.23", "side": "BUY", "hash": "cea11e56b2f66c5afd144c050498f5b88ac40dc1", "best_bid": "0.079", "best_ask": "0.117"}, {"asset_id": "112202945651691176336626757870751886707772553418125673815227809139773741570078", "price": "0.921", "size": "40.23", "side": "SELL", "hash": "1be517ce9257093d477313aeb702081b1b84059c", "best_bid": "0.883", "best_ask": "0.921"}], "timestamp": "1769384214166", "event_type": "price_change"}}
{"_local_timestamp": "2026-01-25T23:36:54.236697+00:00", "data": {"market": "0x2e3433f79c616df13c4955a7134e595ee2ccf4866dce309925e755737b872271", "price_changes": [{"asset_id": "18309888943220126175774903330165417854845342977748532448162902228663371934448", "price": "0.069", "size": "146.06", "side": "BUY", "hash": "d582d64fc4cfa503d86e453c79efc8ccb0b9b8fa", "best_bid": "0.079", "best_ask": "0.117"}, {"asset_id": "112202945651691176336626757870751886707772553418125673815227809139773741570078", "price": "0.931", "size": "146.06", "side": "SELL", "hash": "d67b17077664c479c1f45f2ba12bc31eefd4f0fb", "best_bid": "0.883", "best_ask": "0.921"}], "timestamp": "1769384214169", "event_type": "price_change"}}
{"_local_timestamp": "2026-01-25T23:36:54.270871+00:00", "data": {"market": "0x0baf5017c6cdd082b72a9f8d81ce7a5568a11d2185b37f24aec4371feffa4508", "price_changes": [{"asset_id": "54912585197947912918703938085404885715682857902987396027502188879254644524559", "price": "0.966", "size": "0", "side": "BUY", "hash": "76e193bec767c8d4f8ca0f3b8bafdceaa3926866", "best_bid": "0.993", "best_ask": "0.998"}, {"asset_id": "1398837009918163072638964138392157627970988230992506005676269129994871270413", "price": "0.034", "size": "0", "side": "SELL", "hash": "b933a6c1a19c7d7834dc65e8d1f4f9d08688a975", "best_bid": "0.002", "best_ask": "0.007"}], "timestamp": "1769384214190", "event_type": "price_change"}}
{"_local_timestamp": "2026-01-25T23:36:54.271232+00:00", "data": {"market": "0x28b09e78c1a37a9212b683d5734c0b8375e9c85777e59bb498a08debb585e941", "price_changes": [{"asset_id": "80377662132340664016724672073316391179500510732361804244421570371942255684414", "price": "0.961", "size": "0", "side": "BUY", "hash": "ccd26981da940380eaa2e928ab28eab4ea998b0c", "best_bid": "0.985", "best_ask": "0.993"}, {"asset_id": "44648314711717458063074998921644285938870392557850689878450818223237354241500", "price": "0.039", "size": "0", "side": "SELL", "hash": "47fb50a89f5afffe56d433b75c43c9a806626d46", "best_bid": "0.007", "best_ask": "0.015"}], "timestamp": "1769384214190", "event_type": "price_change"}}
{"_local_timestamp": "2026-01-25T23:36:54.271493+00:00", "data": {"market": "0x2e3433f79c616df13c4955a7134e595ee2ccf4866dce309925e755737b872271", "price_changes": [{"asset_id": "18309888943220126175774903330165417854845342977748532448162902228663371934448", "price": "0.07", "size": "0", "side": "BUY", "hash": "48b22e3e7bfb93618ca47281a4cebca8f97d84fb", "best_bid": "0.079", "best_ask": "0.117"}, {"asset_id": "112202945651691176336626757870751886707772553418125673815227809139773741570078", "price": "0.93", "size": "0", "side": "SELL", "hash": "f63d8dd2fb171e1c296a4f4c8374b9989d51ea45", "best_bid": "0.883", "best_ask": "0.921"}], "timestamp": "1769384214191", "event_type": "price_change"}}
{"_local_timestamp": "2026-01-25T23:36:54.301149+00:00", "data": {"market": "0x2e3433f79c616df13c4955a7134e595ee2ccf4866dce309925e755737b872271", "price_changes": [{"asset_id": "18309888943220126175774903330165417854845342977748532448162902228663371934448", "price": "0.08", "size": "159", "side": "BUY", "hash": "6fc6f05105cd7091cfdff95b9483a0b32737fae6", "best_bid": "0.08", "best_ask": "0.117"}, {"asset_id": "112202945651691176336626757870751886707772553418125673815227809139773741570078", "price": "0.92", "size": "159", "side": "SELL", "hash": "e936533665691cc3fc30f29d48c6d537ab24d0e0", "best_bid": "0.883", "best_ask": "0.92"}], "timestamp": "1769384214223", "event_type": "price_change"}}
{"_local_timestamp": "2026-01-25T23:36:54.389026+00:00", "data": {"market": "0x28b09e78c1a37a9212b683d5734c0b8375e9c85777e59bb498a08debb585e941", "price_changes": [{"asset_id": "80377662132340664016724672073316391179500510732361804244421570371942255684414", "price": "0.963", "size": "20", "side": "BUY", "hash": "60ce0607972ea5a347223bbfc4baf8e7a16df949", "best_bid": "0.985", "best_ask": "0.993"}, {"asset_id": "44648314711717458063074998921644285938870392557850689878450818223237354241500", "price": "0.037", "size": "20", "side": "SELL", "hash": "ecdca02212bef6483822431e521cbe763d2e6b17", "best_bid": "0.007", "best_ask": "0.015"}], "timestamp": "1769384214317", "event_type": "price_change"}}
{"_local_timestamp": "2026-01-25T23:36:54.389370+00:00", "data": {"market": "0x0baf5017c6cdd082b72a9f8d81ce7a5568a11d2185b37f24aec4371feffa4508", "price_changes": [{"asset_id": "54912585197947912918703938085404885715682857902987396027502188879254644524559", "price": "0.968", "size": "20", "side": "BUY", "hash": "3898ce4d6190351af0327428b7cdc672052d3142", "best_bid": "0.993", "best_ask": "0.998"}, {"asset_id": "1398837009918163072638964138392157627970988230992506005676269129994871270413", "price": "0.032", "size": "20", "side": "SELL", "hash": "41124cf7f5cc56da76b0297c56981118c3408922", "best_bid": "0.002", "best_ask": "0.007"}], "timestamp": "1769384214318", "event_type": "price_change"}}
{"_local_timestamp": "2026-01-25T23:36:54.488424+00:00", "data": {"market": "0xaf811fcf5edc733781bee6125756d3e1f02d04f2824b89ab7fa4f4ce30f998b5", "price_changes": [{"asset_id": "27643431546680855679789625370218065863059031034570354610668275237893764523490", "price": "0.06", "size": "679.87", "side": "BUY", "hash": "89c6c8c2aebb74c018a7e68c4946ef9929058ed1", "best_bid": "0.13", "best_ask": "0.15"}, {"asset_id": "94235206725638004435521288935127321522857776396521937922634976647313998892484", "price": "0.94", "size": "679.87", "side": "SELL", "hash": "8dfde5aca8ee79d0f90f39ad2bd6bcdd5d01c294", "best_bid": "0.85", "best_ask": "0.87"}], "timestamp": "1769384214406", "event_type": "price_change"}}
{"_local_timestamp": "2026-01-25T23:36:54.488747+00:00", "data": {"market": "0x28b09e78c1a37a9212b683d5734c0b8375e9c85777e59bb498a08debb585e941", "price_changes": [{"asset_id": "80377662132340664016724672073316391179500510732361804244421570371942255684414", "price": "0.911", "size": "0", "side": "BUY", "hash": "acc10c739cb8464ea2620cd83e8e7256d4fecbf2", "best_bid": "0.985", "best_ask": "0.993"}, {"asset_id": "44648314711717458063074998921644285938870392557850689878450818223237354241500", "price": "0.089", "size": "0", "side": "SELL", "hash": "483fb91511ca991fa2f5ef23c14e84a543b1d8d3", "best_bid": "0.007", "best_ask": "0.015"}], "timestamp": "1769384214406", "event_type": "price_change"}}
{"_local_timestamp": "2026-01-25T23:36:54.489010+00:00", "data": {"market": "0xdf0e04194ff7f25807465101e29d7d476bb9cbf7e56e950d2693cedf4787599f", "price_changes": [{"asset_id": "96765239208959541720088187158035685118767037049985993166814389120572666374201", "price": "0.887", "size": "0", "side": "BUY", "hash": "2d3101aa5b701ceaff8df2aba799fece50357840", "best_bid": "0.939", "best_ask": "0.967"}, {"asset_id": "112838519090657527020403907389517191367689011522812125990685217194554034388792", "price": "0.113", "size": "0", "side": "SELL", "hash": "d2e6a9f0cf9634f00dceb2e96700a786317ec12b", "best_bid": "0.033", "best_ask": "0.061"}], "timestamp": "1769384214406", "event_type": "price_change"}}
{"_local_timestamp": "2026-01-25T23:36:54.510624+00:00", "data": {"market": "0xaf811fcf5edc733781bee6125756d3e1f02d04f2824b89ab7fa4f4ce30f998b5", "price_changes": [{"asset_id": "27643431546680855679789625370218065863059031034570354610668275237893764523490", "price": "0.07", "size": "1246", "side": "BUY", "hash": "b57db1ff19640559ed7652f39b24e6a6ffa4469f", "best_bid": "0.13", "best_ask": "0.15"}, {"asset_id": "94235206725638004435521288935127321522857776396521937922634976647313998892484", "price": "0.93", "size": "1246", "side": "SELL", "hash": "235783453328488c3d9cd208720d06c6ac5ba8b3", "best_bid": "0.85", "best_ask": "0.87"}], "timestamp": "1769384214437", "event_type": "price_change"}}
{"_local_timestamp": "2026-01-25T23:36:54.510948+00:00", "data": {"market": "0xdf0e04194ff7f25807465101e29d7d476bb9cbf7e56e950d2693cedf4787599f", "price_changes": [{"asset_id": "96765239208959541720088187158035685118767037049985993166814389120572666374201", "price": "0.889", "size": "20", "side": "BUY", "hash": "6025983de750e059081f5556cf2660309312e6fc", "best_bid": "0.939", "best_ask": "0.967"}, {"asset_id": "112838519090657527020403907389517191367689011522812125990685217194554034388792", "price": "0.111", "size": "20", "side": "SELL", "hash": "1568a35ece1e89e76f0db637afbdc5afc18fdb34", "best_bid": "0.033", "best_ask": "0.061"}], "timestamp": "1769384214437", "event_type": "price_change"}}
{"_local_timestamp": "2026-01-25T23:36:54.511196+00:00", "data": {"market": "0x28b09e78c1a37a9212b683d5734c0b8375e9c85777e59bb498a08debb585e941", "price_changes": [{"asset_id": "80377662132340664016724672073316391179500510732361804244421570371942255684414", "price": "0.914", "size": "30", "side": "BUY", "hash": "0c36c258ab2762a4f52a57d1808b67f726587864", "best_bid": "0.985", "best_ask": "0.993"}, {"asset_id": "44648314711717458063074998921644285938870392557850689878450818223237354241500", "price": "0.086", "size": "30", "side": "SELL", "hash": "c46b3720d860b2f8e35c201d6f855f0ca0e2853a", "best_bid": "0.007", "best_ask": "0.015"}], "timestamp": "1769384214437", "event_type": "price_change"}}
{"_local_timestamp": "2026-01-25T23:36:54.833282+00:00", "data": {"market": "0x2e3433f79c616df13c4955a7134e595ee2ccf4866dce309925e755737b872271", "price_changes": [{"asset_id": "18309888943220126175774903330165417854845342977748532448162902228663371934448", "price": "0.08", "size": "189", "side": "BUY", "hash": "1f8396935a173b03b1c35135019e65a8f8a21ec5", "best_bid": "0.08", "best_ask": "0.117"}, {"asset_id": "112202945651691176336626757870751886707772553418125673815227809139773741570078", "price": "0.92", "size": "189", "side": "SELL", "hash": "d33533fe4f83562bbec7ead1806f060723101e0b", "best_bid": "0.883", "best_ask": "0.92"}], "timestamp": "1769384214763", "event_type": "price_change"}}
{"_local_timestamp": "2026-01-25T23:36:55.166913+00:00", "data": {"market": "0x2e3433f79c616df13c4955a7134e595ee2ccf4866dce309925e755737b872271", "price_changes": [{"asset_id": "112202945651691176336626757870751886707772553418125673815227809139773741570078", "price": "0.338", "size": "0", "side": "BUY", "hash": "fbd9d7656004fa6d1f1e4a0a4484437def14483b", "best_bid": "0.883", "best_ask": "0.92"}, {"asset_id": "18309888943220126175774903330165417854845342977748532448162902228663371934448", "price": "0.662", "size": "0", "side": "SELL", "hash": "b38fde848a62acb8ba211f0aa8c569fbac2799e8", "best_bid": "0.08", "best_ask": "0.117"}], "timestamp": "1769384215025", "event_type": "price_change"}}
{"_local_timestamp": "2026-01-25T23:36:56.150512+00:00", "data": {"market": "0x2e3433f79c616df13c4955a7134e595ee2ccf4866dce309925e755737b872271", "price_changes": [{"asset_id": "112202945651691176336626757870751886707772553418125673815227809139773741570078", "price": "0.34", "size": "1251", "side": "BUY", "hash": "763adfe3650df507a101bb8e52fa072f6f148da0", "best_bid": "0.883", "best_ask": "0.92"}, {"asset_id": "18309888943220126175774903330165417854845342977748532448162902228663371934448", "price": "0.66", "size": "1251", "side": "SELL", "hash": "910de960611a75c6dae4d57148f85e5ff18c27ca", "best_bid": "0.08", "best_ask": "0.117"}], "timestamp": "1769384215709", "event_type": "price_change"}}
{"_local_timestamp": "2026-01-25T23:36:56.646754+00:00", "data": {"market": "0x2e3433f79c616df13c4955a7134e595ee2ccf4866dce309925e755737b872271", "price_changes": [{"asset_id": "18309888943220126175774903330165417854845342977748532448162902228663371934448", "price": "0.078", "size": "8.04", "side": "BUY", "hash": "0490f0e80161addbf18cda170ee6d0b482941faf", "best_bid": "0.08", "best_ask": "0.117"}, {"asset_id": "112202945651691176336626757870751886707772553418125673815227809139773741570078", "price": "0.922", "size": "8.04", "side": "SELL", "hash": "63826cff8c05c4f6a90bb0d9972e47df5fdb696e", "best_bid": "0.883", "best_ask": "0.92"}], "timestamp": "1769384216576", "event_type": "price_change"}}
{"_local_timestamp": "2026-01-25T23:36:56.677878+00:00", "data": {"market": "0x2e3433f79c616df13c4955a7134e595ee2ccf4866dce309925e755737b872271", "price_changes": [{"asset_id": "18309888943220126175774903330165417854845342977748532448162902228663371934448", "price": "0.081", "size": "21.97", "side": "BUY", "hash": "6a720efc76778f34c06766c4cf6e0ff0d6979124", "best_bid": "0.081", "best_ask": "0.117"}, {"asset_id": "112202945651691176336626757870751886707772553418125673815227809139773741570078", "price": "0.919", "size": "21.97", "side": "SELL", "hash": "7ba31d1bb84ff069ad33e114ff8d1e45fa769f8b", "best_bid": "0.883", "best_ask": "0.919"}], "timestamp": "1769384216610", "event_type": "price_change"}}
{"_local_timestamp": "2026-01-25T23:36:56.703216+00:00", "data": {"market": "0xdf0e04194ff7f25807465101e29d7d476bb9cbf7e56e950d2693cedf4787599f", "price_changes": [{"asset_id": "96765239208959541720088187158035685118767037049985993166814389120572666374201", "price": "0.939", "size": "110.93", "side": "BUY", "hash": "87bb23ab54c5c598caefa37a16ea52d1c69fe249", "best_bid": "0.939", "best_ask": "0.967"}, {"asset_id": "112838519090657527020403907389517191367689011522812125990685217194554034388792", "price": "0.061", "size": "110.93", "side": "SELL", "hash": "ec9afb8416524234bb7bc05fcb7726c2a0fc9789", "best_bid": "0.033", "best_ask": "0.061"}], "timestamp": "1769384216634", "event_type": "price_change"}}
{"_local_timestamp": "2026-01-25T23:36:56.723914+00:00", "data": {"market": "0x2e3433f79c616df13c4955a7134e595ee2ccf4866dce309925e755737b872271", "price_changes": [{"asset_id": "18309888943220126175774903330165417854845342977748532448162902228663371934448", "price": "0.08", "size": "30", "side": "BUY", "hash": "2c57c6a25dcd8f7abac9f6c2945dd693443fed75", "best_bid": "0.081", "best_ask": "0.117"}, {"asset_id": "112202945651691176336626757870751886707772553418125673815227809139773741570078", "price": "0.92", "size": "30", "side": "SELL", "hash": "f98316efac758ed339baaaca04031da50ac4a00e", "best_bid": "0.883", "best_ask": "0.919"}], "timestamp": "1769384216650", "event_type": "price_change"}}
{"_local_timestamp": "2026-01-25T23:36:56.749682+00:00", "data": {"market": "0x2e3433f79c616df13c4955a7134e595ee2ccf4866dce309925e755737b872271", "price_changes": [{"asset_id": "18309888943220126175774903330165417854845342977748532448162902228663371934448", "price": "0.082", "size": "150", "side": "BUY", "hash": "c8e30a393334a5132839f2664c99ebf69cfeedae", "best_bid": "0.082", "best_ask": "0.117"}, {"asset_id": "112202945651691176336626757870751886707772553418125673815227809139773741570078", "price": "0.918", "size": "150", "side": "SELL", "hash": "a27110722917a5e71d7f97be5467f3226823687e", "best_bid": "0.883", "best_ask": "0.918"}], "timestamp": "1769384216678", "event_type": "price_change"}}
{"_local_timestamp": "2026-01-25T23:36:57.196964+00:00", "data": {"market": "0x2e3433f79c616df13c4955a7134e595ee2ccf4866dce309925e755737b872271", "price_changes": [{"asset_id": "18309888943220126175774903330165417854845342977748532448162902228663371934448", "price": "0.08", "size": "0", "side": "BUY", "hash": "ead0387c62a0df57cb217eed9e01d5266a324fea", "best_bid": "0.082", "best_ask": "0.117"}, {"asset_id": "112202945651691176336626757870751886707772553418125673815227809139773741570078", "price": "0.92", "size": "0", "side": "SELL", "hash": "d6c9bb3c698cce9cf6427c39c02163366f32f809", "best_bid": "0.883", "best_ask": "0.918"}], "timestamp": "1769384217123", "event_type": "price_change"}}
{"_local_timestamp": "2026-01-25T23:36:57.240512+00:00", "data": {"market": "0x2e3433f79c616df13c4955a7134e595ee2ccf4866dce309925e755737b872271", "price_changes": [{"asset_id": "18309888943220126175774903330165417854845342977748532448162902228663371934448", "price": "0.069", "size": "176.06", "side": "BUY", "hash": "77629e8ad0bf4608bf04db7164af5acdbcf04eee", "best_bid": "0.082", "best_ask": "0.117"}, {"asset_id": "112202945651691176336626757870751886707772553418125673815227809139773741570078", "price": "0.931", "size": "176.06", "side": "SELL", "hash": "91177eec5a5835b1c5958884e25dd704ae69bed1", "best_bid": "0.883", "best_ask": "0.918"}], "timestamp": "1769384217174", "event_type": "price_change"}}
{"_local_timestamp": "2026-01-25T23:36:57.738097+00:00", "data": {"market": "0x2e3433f79c616df13c4955a7134e595ee2ccf4866dce309925e755737b872271", "price_changes": [{"asset_id": "112202945651691176336626757870751886707772553418125673815227809139773741570078", "price": "0.192", "size": "150", "side": "BUY", "hash": "687f42924bd10e15c5aeb8cb9b926b48ea03c722", "best_bid": "0.883", "best_ask": "0.918"}, {"asset_id": "18309888943220126175774903330165417854845342977748532448162902228663371934448", "price": "0.808", "size": "150", "side": "SELL", "hash": "3c742bf0c728ae1fb90a32ea49bffd978cf9cdba", "best_bid": "0.082", "best_ask": "0.117"}], "timestamp": "1769384217241", "event_type": "price_change"}}
{"_local_timestamp": "2026-01-25T23:36:57.738599+00:00", "data": {"market": "0x2e3433f79c616df13c4955a7134e595ee2ccf4866dce309925e755737b872271", "price_changes": [{"asset_id": "18309888943220126175774903330165417854845342977748532448162902228663371934448", "price": "0.011", "size": "11.38", "side": "BUY", "hash": "05fd5289429d8961c52deafd65194c17b888de41", "best_bid": "0.082", "best_ask": "0.117"}, {"asset_id": "112202945651691176336626757870751886707772553418125673815227809139773741570078", "price": "0.989", "size": "11.38", "side": "SELL", "hash": "f32a05015bbba64101c6a411623eaec80b25b978", "best_bid": "0.883", "best_ask": "0.918"}], "timestamp": "1769384217282", "event_type": "price_change"}}
{"_local_timestamp": "2026-01-25T23:36:57.738912+00:00", "data": {"market": "0xdf0e04194ff7f25807465101e29d7d476bb9cbf7e56e950d2693cedf4787599f", "price_changes": [{"asset_id": "112838519090657527020403907389517191367689011522812125990685217194554034388792", "price": "0.012", "size": "9.3", "side": "BUY", "hash": "414e2391c5636ec87c7e859132c55b8a64fe30ae", "best_bid": "0.033", "best_ask": "0.061"}, {"asset_id": "96765239208959541720088187158035685118767037049985993166814389120572666374201", "price": "0.988", "size": "9.3", "side": "SELL", "hash": "a7009b72b1b9c69659a04f576c1728f6ded8b344", "best_bid": "0.939", "best_ask": "0.967"}], "timestamp": "1769384217237", "event_type": "price_change"}}
{"_local_timestamp": "2026-01-25T23:36:57.739233+00:00", "data": {"market": "0x0baf5017c6cdd082b72a9f8d81ce7a5568a11d2185b37f24aec4371feffa4508", "price_changes": [{"asset_id": "54912585197947912918703938085404885715682857902987396027502188879254644524559", "price": "0.202", "size": "0", "side": "BUY", "hash": "7fbeeaad79c61f5af58e874874e895d509c7c921", "best_bid": "0.993", "best_ask": "0.998"}, {"asset_id": "1398837009918163072638964138392157627970988230992506005676269129994871270413", "price": "0.798", "size": "0", "side": "SELL", "hash": "e3019ac4716bf22635fd20fc73f84a236e2856a0", "best_bid": "0.002", "best_ask": "0.007"}], "timestamp": "1769384217221", "event_type": "price_change"}}
{"_local_timestamp": "2026-01-25T23:36:57.797622+00:00", "data": {"market": "0xdf0e04194ff7f25807465101e29d7d476bb9cbf7e56e950d2693cedf4787599f", "price_changes": [{"asset_id": "96765239208959541720088187158035685118767037049985993166814389120572666374201", "price": "0.372", "size": "0", "side": "BUY", "hash": "05365f1aa3a6f7e909ab18cfb09c16e8d7ef269e", "best_bid": "0.939", "best_ask": "0.967"}, {"asset_id": "112838519090657527020403907389517191367689011522812125990685217194554034388792", "price": "0.628", "size": "0", "side": "SELL", "hash": "8cecb5da6782d8e7244028f666abf69300767c6c", "best_bid": "0.033", "best_ask": "0.061"}], "timestamp": "1769384217285", "event_type": "price_change"}}
{"_local_timestamp": "2026-01-25T23:36:57.821422+00:00", "data": {"market": "0x28b09e78c1a37a9212b683d5734c0b8375e9c85777e59bb498a08debb585e941", "price_changes": [{"asset_id": "80377662132340664016724672073316391179500510732361804244421570371942255684414", "price": "0.914", "size": "10", "side": "BUY", "hash": "d3619a9594585949d23dbe7abf12b6c2def6244c", "best_bid": "0.985", "best_ask": "0.993"}, {"asset_id": "44648314711717458063074998921644285938870392557850689878450818223237354241500", "price": "0.086", "size": "10", "side": "SELL", "hash": "2b4d7e30b7074c68c7393c6e9f0915a14d17f351", "best_bid": "0.007", "best_ask": "0.015"}], "timestamp": "1769384217443", "event_type": "price_change"}}
{"_local_timestamp": "2026-01-25T23:36:57.834814+00:00", "data": {"market": "0x28b09e78c1a37a9212b683d5734c0b8375e9c85777e59bb498a08debb585e941", "price_changes": [{"asset_id": "80377662132340664016724672073316391179500510732361804244421570371942255684414", "price": "0.916", "size": "40", "side": "BUY", "hash": "18904ff00e365ca13af8a947d846cdb5e5cf257b", "best_bid": "0.985", "best_ask": "0.993"}, {"asset_id": "44648314711717458063074998921644285938870392557850689878450818223237354241500", "price": "0.084", "size": "40", "side": "SELL", "hash": "e6b25301da06b8da36c0a5202a4e0d88e3c782ba", "best_bid": "0.007", "best_ask": "0.015"}], "timestamp": "1769384217476", "event_type": "price_change"}}
{"_local_timestamp": "2026-01-25T23:36:57.882915+00:00", "data": {"market": "0xdf0e04194ff7f25807465101e29d7d476bb9cbf7e56e950d2693cedf4787599f", "price_changes": [{"asset_id": "96765239208959541720088187158035685118767037049985993166814389120572666374201", "price": "0.939", "size": "89.93", "side": "BUY", "hash": "61b9c82af462c64c9a30576b90cb4abcf387b563", "best_bid": "0.939", "best_ask": "0.967"}, {"asset_id": "112838519090657527020403907389517191367689011522812125990685217194554034388792", "price": "0.061", "size": "89.93", "side": "SELL", "hash": "df501f531cc51ab94567269bbaa45322099195e7", "best_bid": "0.033", "best_ask": "0.061"}], "timestamp": "1769384217633", "event_type": "price_change"}}
{"_local_timestamp": "2026-01-25T23:36:58.057938+00:00", "data": {"market": "0x2e3433f79c616df13c4955a7134e595ee2ccf4866dce309925e755737b872271", "price_changes": [{"asset_id": "18309888943220126175774903330165417854845342977748532448162902228663371934448", "price": "0.069", "size": "146.06", "side": "BUY", "hash": "9253e4ee5ec9b8ea0a8e839cf6a9d8fbab66d411", "best_bid": "0.082", "best_ask": "0.117"}, {"asset_id": "112202945651691176336626757870751886707772553418125673815227809139773741570078", "price": "0.931", "size": "146.06", "side": "SELL", "hash": "83295a9ebf765fe1c66fbe6f787a7af81ee786be", "best_bid": "0.883", "best_ask": "0.918"}], "timestamp": "1769384217982", "event_type": "price_change"}}
{"_local_timestamp": "2026-01-25T23:36:58.109659+00:00", "data": {"market": "0x2e3433f79c616df13c4955a7134e595ee2ccf4866dce309925e755737b872271", "price_changes": [{"asset_id": "18309888943220126175774903330165417854845342977748532448162902228663371934448", "price": "0.082", "size": "180", "side": "BUY", "hash": "479929e7e637e9b64694c442a9a082818c28e0c7", "best_bid": "0.082", "best_ask": "0.117"}, {"asset_id": "112202945651691176336626757870751886707772553418125673815227809139773741570078", "price": "0.918", "size": "180", "side": "SELL", "hash": "de42e3f2d0ca69d242c4ba6f6028c3128560af56", "best_bid": "0.883", "best_ask": "0.918"}], "timestamp": "1769384218037", "event_type": "price_change"}}
{"_local_timestamp": "2026-01-25T23:36:58.222640+00:00", "data": {"market": "0x28b09e78c1a37a9212b683d5734c0b8375e9c85777e59bb498a08debb585e941", "price_changes": [{"asset_id": "80377662132340664016724672073316391179500510732361804244421570371942255684414", "price": "0.101", "size": "0", "side": "BUY", "hash": "0e7e701f34996972ef9ed0f9d45cc951c9a9530a", "best_bid": "0.985", "best_ask": "0.993"}, {"asset_id": "44648314711717458063074998921644285938870392557850689878450818223237354241500", "price": "0.899", "size": "0", "side": "SELL", "hash": "95ea5ee71f93c5f13f3419a83d97404dbb43d444", "best_bid": "0.007", "best_ask": "0.015"}], "timestamp": "1769384218086", "event_type": "price_change"}}
{"_local_timestamp": "2026-01-25T23:37:03.322598+00:00", "data": {"market": "0xdf0e04194ff7f25807465101e29d7d476bb9cbf7e56e950d2693cedf4787599f", "price_changes": [{"asset_id": "96765239208959541720088187158035685118767037049985993166814389120572666374201", "price": "0.374", "size": "300", "side": "BUY", "hash": "03a487e87c9bb80b54cc4a46cdc8a7abf6803146", "best_bid": "0.939", "best_ask": "0.967"}, {"asset_id": "112838519090657527020403907389517191367689011522812125990685217194554034388792", "price": "0.626", "size": "300", "side": "SELL", "hash": "b3185533f5066ad758e93c1dadbcef8eb82ce668", "best_bid": "0.033", "best_ask": "0.061"}], "timestamp": "1769384223251", "event_type": "price_change"}}
{"_local_timestamp": "2026-01-25T23:37:03.323116+00:00", "data": {"market": "0x0baf5017c6cdd082b72a9f8d81ce7a5568a11d2185b37f24aec4371feffa4508", "price_changes": [{"asset_id": "54912585197947912918703938085404885715682857902987396027502188879254644524559", "price": "0.204", "size": "300", "side": "BUY", "hash": "2385bf7db5dc52d66db8fcd106650ad7a376921f", "best_bid": "0.993", "best_ask": "0.998"}, {"asset_id": "1398837009918163072638964138392157627970988230992506005676269129994871270413", "price": "0.796", "size": "300", "side": "SELL", "hash": "60fbe7bfacad9b507d027ca31f61a056fa8a2c30", "best_bid": "0.002", "best_ask": "0.007"}], "timestamp": "1769384223252", "event_type": "price_change"}}
{"_local_timestamp": "2026-01-25T23:37:03.323454+00:00", "data": {"market": "0x2e3433f79c616df13c4955a7134e595ee2ccf4866dce309925e755737b872271", "price_changes": [{"asset_id": "112202945651691176336626757870751886707772553418125673815227809139773741570078", "price": "0.341", "size": "1100", "side": "BUY", "hash": "0c686d718cde194ce2cd4a15bbe44e0d417eb1c3", "best_bid": "0.883", "best_ask": "0.918"}, {"asset_id": "18309888943220126175774903330165417854845342977748532448162902228663371934448", "price": "0.659", "size": "1100", "side": "SELL", "hash": "7627d894c043b1cd06b2b8026505aa3154b5f9a1", "best_bid": "0.082", "best_ask": "0.117"}], "timestamp": "1769384223252", "event_type": "price_change"}}
{"_local_timestamp": "2026-01-25T23:37:03.323709+00:00", "data": {"market": "0xdf0e04194ff7f25807465101e29d7d476bb9cbf7e56e950d2693cedf4787599f", "price_changes": [{"asset_id": "112838519090657527020403907389517191367689011522812125990685217194554034388792", "price": "0.006", "size": "282.25", "side": "BUY", "hash": "60eb5bd2917740ebe623149c4f079d20a2470111", "best_bid": "0.033", "best_ask": "0.061"}, {"asset_id": "96765239208959541720088187158035685118767037049985993166814389120572666374201", "price": "0.994", "size": "282.25", "side": "SELL", "hash": "85e6a32afeaf1579ec0e6359783b9fd9dd63bd8f", "best_bid": "0.939", "best_ask": "0.967"}], "timestamp": "1769384223254", "event_type": "price_change"}}
{"_local_timestamp": "2026-01-25T23:37:03.324084+00:00", "data": {"market": "0x2e3433f79c616df13c4955a7134e595ee2ccf4866dce309925e755737b872271", "price_changes": [{"asset_id": "18309888943220126175774903330165417854845342977748532448162902228663371934448", "price": "0.032", "size": "277", "side": "BUY", "hash": "3b739f13025809f384b8c9335777ffe3a026a271", "best_bid": "0.082", "best_ask": "0.117"}, {"asset_id": "112202945651691176336626757870751886707772553418125673815227809139773741570078", "price": "0.968", "size": "277", "side": "SELL", "hash": "4afd9a47e39511d9da2d287f2310e2f371209ab6", "best_bid": "0.883", "best_ask": "0.918"}], "timestamp": "1769384223254", "event_type": "price_change"}}
{"_local_timestamp": "2026-01-25T23:37:04.032609+00:00", "data": {"market": "0xaf811fcf5edc733781bee6125756d3e1f02d04f2824b89ab7fa4f4ce30f998b5", "price_changes": [{"asset_id": "27643431546680855679789625370218065863059031034570354610668275237893764523490", "price": "0.27", "size": "0", "side": "SELL", "hash": "19fafb3d78e4aa66f99369e59084d3a00ef5f9d7", "best_bid": "0.13", "best_ask": "0.15"}, {"asset_id": "94235206725638004435521288935127321522857776396521937922634976647313998892484", "price": "0.73", "size": "0", "side": "BUY", "hash": "bb6897578bc6235fa45850dd3cd27f01dea2fd64", "best_bid": "0.85", "best_ask": "0.87"}], "timestamp": "1769384223951", "event_type": "price_change"}}
{"_local_timestamp": "2026-01-25T23:37:04.040204+00:00", "data": {"market": "0xaf811fcf5edc733781bee6125756d3e1f02d04f2824b89ab7fa4f4ce30f998b5", "price_changes": [{"asset_id": "27643431546680855679789625370218065863059031034570354610668275237893764523490", "price": "0.21", "size": "0", "side": "SELL", "hash": "19fafb3d78e4aa66f99369e59084d3a00ef5f9d7", "best_bid": "0.13", "best_ask": "0.15"}, {"asset_id": "94235206725638004435521288935127321522857776396521937922634976647313998892484", "price": "0.79", "size": "0", "side": "BUY", "hash": "bb6897578bc6235fa45850dd3cd27f01dea2fd64", "best_bid": "0.85", "best_ask": "0.87"}], "timestamp": "1769384223951", "event_type": "price_change"}}
{"_local_timestamp": "2026-01-25T23:37:04.041168+00:00", "data": {"market": "0xaf811fcf5edc733781bee6125756d3e1f02d04f2824b89ab7fa4f4ce30f998b5", "price_changes": [{"asset_id": "27643431546680855679789625370218065863059031034570354610668275237893764523490", "price": "0.15", "size": "385.32", "side": "SELL", "hash": "19fafb3d78e4aa66f99369e59084d3a00ef5f9d7", "best_bid": "0.13", "best_ask": "0.15"}, {"asset_id": "94235206725638004435521288935127321522857776396521937922634976647313998892484", "price": "0.85", "size": "385.32", "side": "BUY", "hash": "bb6897578bc6235fa45850dd3cd27f01dea2fd64", "best_bid": "0.85", "best_ask": "0.87"}], "timestamp": "1769384223951", "event_type": "price_change"}}
{"_local_timestamp": "2026-01-25T23:37:04.041686+00:00", "data": {"market": "0xaf811fcf5edc733781bee6125756d3e1f02d04f2824b89ab7fa4f4ce30f998b5", "price_changes": [{"asset_id": "27643431546680855679789625370218065863059031034570354610668275237893764523490", "price": "0.18", "size": "209.99", "side": "SELL", "hash": "19fafb3d78e4aa66f99369e59084d3a00ef5f9d7", "best_bid": "0.13", "best_ask": "0.15"}, {"asset_id": "94235206725638004435521288935127321522857776396521937922634976647313998892484", "price": "0.82", "size": "209.99", "side": "BUY", "hash": "bb6897578bc6235fa45850dd3cd27f01dea2fd64", "best_bid": "0.85", "best_ask": "0.87"}], "timestamp": "1769384223951", "event_type": "price_change"}}
{"_local_timestamp": "2026-01-25T23:37:04.042070+00:00", "data": {"market": "0xaf811fcf5edc733781bee6125756d3e1f02d04f2824b89ab7fa4f4ce30f998b5", "price_changes": [{"asset_id": "27643431546680855679789625370218065863059031034570354610668275237893764523490", "price": "0.24", "size": "0", "side": "SELL", "hash": "19fafb3d78e4aa66f99369e59084d3a00ef5f9d7", "best_bid": "0.13", "best_ask": "0.15"}, {"asset_id": "94235206725638004435521288935127321522857776396521937922634976647313998892484", "price": "0.76", "size": "0", "side": "BUY", "hash": "bb6897578bc6235fa45850dd3cd27f01dea2fd64", "best_bid": "0.85", "best_ask": "0.87"}], "timestamp": "1769384223951", "event_type": "price_change"}}
{"_local_timestamp": "2026-01-25T23:37:10.538683+00:00", "data": {"market": "0x2e3433f79c616df13c4955a7134e595ee2ccf4866dce309925e755737b872271", "price_changes": [{"asset_id": "112202945651691176336626757870751886707772553418125673815227809139773741570078", "price": "0.866", "size": "0", "side": "BUY", "hash": "c4be6e6db066bb6d461f79e198e888d3c36aa6c9", "best_bid": "0.883", "best_ask": "0.918"}, {"asset_id": "18309888943220126175774903330165417854845342977748532448162902228663371934448", "price": "0.134", "size": "0", "side": "SELL", "hash": "1b00af0c49c5e7749d1489e82632c5264d646529", "best_bid": "0.082", "best_ask": "0.117"}], "timestamp": "1769384230466", "event_type": "price_change"}}
{"_local_timestamp": "2026-01-25T23:37:13.129206+00:00", "data": {"market": "0x28b09e78c1a37a9212b683d5734c0b8375e9c85777e59bb498a08debb585e941", "price_changes": [{"asset_id": "80377662132340664016724672073316391179500510732361804244421570371942255684414", "price": "0.251", "size": "100", "side": "BUY", "hash": "faa5d5d83ca5e26c37769b95fe1f32f53d608080", "best_bid": "0.985", "best_ask": "0.993"}, {"asset_id": "44648314711717458063074998921644285938870392557850689878450818223237354241500", "price": "0.749", "size": "100", "side": "SELL", "hash": "35a5d742fce389b191ec44b573fa6c13b1896220", "best_bid": "0.007", "best_ask": "0.015"}], "timestamp": "1769384233009", "event_type": "price_change"}}
{"_local_timestamp": "2026-01-25T23:37:13.157972+00:00", "data": {"market": "0x0baf5017c6cdd082b72a9f8d81ce7a5568a11d2185b37f24aec4371feffa4508", "price_changes": [{"asset_id": "54912585197947912918703938085404885715682857902987396027502188879254644524559", "price": "0.251", "size": "100", "side": "BUY", "hash": "8deb0216e8a87cc71e4e413afec548d6099faaf9", "best_bid": "0.993", "best_ask": "0.998"}, {"asset_id": "1398837009918163072638964138392157627970988230992506005676269129994871270413", "price": "0.749", "size": "100", "side": "SELL", "hash": "2120ca4659684fa6b4ad75a1a9262c7170089cb6", "best_bid": "0.002", "best_ask": "0.007"}], "timestamp": "1769384233007", "event_type": "price_change"}}
{"_local_timestamp": "2026-01-25T23:37:13.522446+00:00", "data": {"market": "0x0baf5017c6cdd082b72a9f8d81ce7a5568a11d2185b37f24aec4371feffa4508", "price_changes": [{"asset_id": "54912585197947912918703938085404885715682857902987396027502188879254644524559", "price": "0.25", "size": "162", "side": "BUY", "hash": "a2c6e1baf32533d0dc34ac1041d0d531a28b0974", "best_bid": "0.993", "best_ask": "0.998"}, {"asset_id": "1398837009918163072638964138392157627970988230992506005676269129994871270413", "price": "0.75", "size": "162", "side": "SELL", "hash": "5107696f78d8243b2c56265ebec23fbfa6d2d4a6", "best_bid": "0.002", "best_ask": "0.007"}], "timestamp": "1769384233374", "event_type": "price_change"}}
{"_local_timestamp": "2026-01-25T23:37:13.523315+00:00", "data": {"market": "0x28b09e78c1a37a9212b683d5734c0b8375e9c85777e59bb498a08debb585e941", "price_changes": [{"asset_id": "80377662132340664016724672073316391179500510732361804244421570371942255684414", "price": "0.25", "size": "162", "side": "BUY", "hash": "426e977d67bbaa135e81b17d0a1bdb7cb6ec3ea3", "best_bid": "0.985", "best_ask": "0.993"}, {"asset_id": "44648314711717458063074998921644285938870392557850689878450818223237354241500", "price": "0.75", "size": "162", "side": "SELL", "hash": "6b49f194a8c5fc4b75f357f9ee1e784e42e3335c", "best_bid": "0.007", "best_ask": "0.015"}], "timestamp": "1769384233376", "event_type": "price_change"}}
{"_local_timestamp": "2026-01-25T23:37:14.831963+00:00", "data": {"market": "0xdf0e04194ff7f25807465101e29d7d476bb9cbf7e56e950d2693cedf4787599f", "price_changes": [{"asset_id": "96765239208959541720088187158035685118767037049985993166814389120572666374201", "price": "0.933", "size": "0", "side": "BUY", "hash": "bdaa03d246894cecb38982513639ec682ce83909", "best_bid": "0.939", "best_ask": "0.967"}, {"asset_id": "112838519090657527020403907389517191367689011522812125990685217194554034388792", "price": "0.067", "size": "0", "side": "SELL", "hash": "19a75977587048f773958a0360b7e14c375be36d", "best_bid": "0.033", "best_ask": "0.061"}], "timestamp": "1769384234755", "event_type": "price_change"}}
{"_local_timestamp": "2026-01-25T23:37:15.122658+00:00", "data": {"market": "0xdf0e04194ff7f25807465101e29d7d476bb9cbf7e56e950d2693cedf4787599f", "price_changes": [{"asset_id": "112838519090657527020403907389517191367689011522812125990685217194554034388792", "price": "0.016", "size": "6.84", "side": "BUY", "hash": "8674201bdfa775182dca53b6e28c7e471433373c", "best_bid": "0.033", "best_ask": "0.061"}, {"asset_id": "96765239208959541720088187158035685118767037049985993166814389120572666374201", "price": "0.984", "size": "6.84", "side": "SELL", "hash": "0f14f60533781c037a04af8822936335832ec234", "best_bid": "0.939", "best_ask": "0.967"}], "timestamp": "1769384235042", "event_type": "price_change"}}
{"_local_timestamp": "2026-01-25T23:37:15.269380+00:00", "data": {"market": "0xdf0e04194ff7f25807465101e29d7d476bb9cbf7e56e950d2693cedf4787599f", "price_changes": [{"asset_id": "96765239208959541720088187158035685118767037049985993166814389120572666374201", "price": "0.939", "size": "59.93", "side": "BUY", "hash": "98921d5849000845ce9647f55bfc1c6c92582060", "best_bid": "0.939", "best_ask": "0.967"}, {"asset_id": "112838519090657527020403907389517191367689011522812125990685217194554034388792", "price": "0.061", "size": "59.93", "side": "SELL", "hash": "f31906712b4d63ee8a918ad4a1239341a2a42340", "best_bid": "0.033", "best_ask": "0.061"}], "timestamp": "1769384235198", "event_type": "price_change"}}
{"_local_timestamp": "2026-01-25T23:37:17.443238+00:00", "data": {"market": "0xdf0e04194ff7f25807465101e29d7d476bb9cbf7e56e950d2693cedf4787599f", "price_changes": [{"asset_id": "112838519090657527020403907389517191367689011522812125990685217194554034388792", "price": "0.016", "size": "105.9", "side": "BUY", "hash": "33850040554ace3ec1afc3d69f6818adc7cc7bed", "best_bid": "0.033", "best_ask": "0.061"}, {"asset_id": "96765239208959541720088187158035685118767037049985993166814389120572666374201", "price": "0.984", "size": "105.9", "side": "SELL", "hash": "05405e8a444956fbd62ae1cea648994cb101e734", "best_bid": "0.939", "best_ask": "0.967"}], "timestamp": "1769384237374", "event_type": "price_change"}}
{"_local_timestamp": "2026-01-25T23:37:17.450838+00:00", "data": {"market": "0xdf0e04194ff7f25807465101e29d7d476bb9cbf7e56e950d2693cedf4787599f", "price_changes": [{"asset_id": "96765239208959541720088187158035685118767037049985993166814389120572666374201", "price": "0.93", "size": "120.1", "side": "BUY", "hash": "7eda55986d4bc3f2a8dd9e13c9499e7771fc239f", "best_bid": "0.939", "best_ask": "0.967"}, {"asset_id": "112838519090657527020403907389517191367689011522812125990685217194554034388792", "price": "0.07", "size": "120.1", "side": "SELL", "hash": "5bf8bbb3473275cbeac23159a432a8b92e4057b8", "best_bid": "0.033", "best_ask": "0.061"}], "timestamp": "1769384237375", "event_type": "price_change"}}
{"_local_timestamp": "2026-01-25T23:37:20.017933+00:00", "data": {"market": "0xdf0e04194ff7f25807465101e29d7d476bb9cbf7e56e950d2693cedf4787599f", "price_changes": [{"asset_id": "112838519090657527020403907389517191367689011522812125990685217194554034388792", "price": "0.017", "size": "5.46", "side": "BUY", "hash": "824020fbec5e2ffa4a2f0c61a0ee6a41c5b14bc6", "best_bid": "0.033", "best_ask": "0.061"}, {"asset_id": "96765239208959541720088187158035685118767037049985993166814389120572666374201", "price": "0.983", "size": "5.46", "side": "SELL", "hash": "22a02be7ad126570d9ca7bfda2fb10e5a4b3d63b", "best_bid": "0.939", "best_ask": "0.967"}], "timestamp": "1769384239947", "event_type": "price_change"}}
{"_local_timestamp": "2026-01-25T23:37:20.287149+00:00", "data": {"market": "0xdf0e04194ff7f25807465101e29d7d476bb9cbf7e56e950d2693cedf4787599f", "price_changes": [{"asset_id": "112838519090657527020403907389517191367689011522812125990685217194554034388792", "price": "0.006", "size": "811.25", "side": "BUY", "hash": "56c35b25ebfdedb3732b4a6124f8898e21f5e1bb", "best_bid": "0.033", "best_ask": "0.061"}, {"asset_id": "96765239208959541720088187158035685118767037049985993166814389120572666374201", "price": "0.994", "size": "811.25", "side": "SELL", "hash": "4644a44a7f31faf6e94a9b9749a0dee8e472a6f0", "best_bid": "0.939", "best_ask": "0.967"}], "timestamp": "1769384240209", "event_type": "price_change"}}
{"_local_timestamp": "2026-01-25T23:37:31.825031+00:00", "data": {"market": "0xdf0e04194ff7f25807465101e29d7d476bb9cbf7e56e950d2693cedf4787599f", "price_changes": [{"asset_id": "96765239208959541720088187158035685118767037049985993166814389120572666374201", "price": "0.908", "size": "0", "side": "BUY", "hash": "a65fcebfb0383c9cda9e5eee78527df625fe1098", "best_bid": "0.939", "best_ask": "0.967"}, {"asset_id": "112838519090657527020403907389517191367689011522812125990685217194554034388792", "price": "0.092", "size": "0", "side": "SELL", "hash": "8e66062d1ff7446903858acc194191ecac596741", "best_bid": "0.033", "best_ask": "0.061"}], "timestamp": "1769384251707", "event_type": "price_change"}}
{"_local_timestamp": "2026-01-25T23:37:31.833079+00:00", "data": {"market": "0xdf0e04194ff7f25807465101e29d7d476bb9cbf7e56e950d2693cedf4787599f", "price_changes": [{"asset_id": "96765239208959541720088187158035685118767037049985993166814389120572666374201", "price": "0.888", "size": "0", "side": "BUY", "hash": "a65fcebfb0383c9cda9e5eee78527df625fe1098", "best_bid": "0.939", "best_ask": "0.967"}, {"asset_id": "112838519090657527020403907389517191367689011522812125990685217194554034388792", "price": "0.112", "size": "0", "side": "SELL", "hash": "8e66062d1ff7446903858acc194191ecac596741", "best_bid": "0.033", "best_ask": "0.061"}], "timestamp": "1769384251707", "event_type": "price_change"}}
{"_local_timestamp": "2026-01-25T23:37:32.668811+00:00", "data": {"market": "0xdf0e04194ff7f25807465101e29d7d476bb9cbf7e56e950d2693cedf4787599f", "price_changes": [{"asset_id": "96765239208959541720088187158035685118767037049985993166814389120572666374201", "price": "0.889", "size": "0", "side": "BUY", "hash": "06733dba3b55e241d8922fa10f8ced59f6e41b42", "best_bid": "0.939", "best_ask": "0.967"}, {"asset_id": "112838519090657527020403907389517191367689011522812125990685217194554034388792", "price": "0.111", "size": "0", "side": "SELL", "hash": "73b4b52537583a8d38be65773c4a7c426f0375f4", "best_bid": "0.033", "best_ask": "0.061"}], "timestamp": "1769384252554", "event_type": "price_change"}}
{"_local_timestamp": "2026-01-25T23:37:32.692696+00:00", "data": {"market": "0xdf0e04194ff7f25807465101e29d7d476bb9cbf7e56e950d2693cedf4787599f", "price_changes": [{"asset_id": "96765239208959541720088187158035685118767037049985993166814389120572666374201", "price": "0.887", "size": "20", "side": "BUY", "hash": "6fb585b4038a4ab30839d0131373243d521c3982", "best_bid": "0.939", "best_ask": "0.967"}, {"asset_id": "112838519090657527020403907389517191367689011522812125990685217194554034388792", "price": "0.113", "size": "20", "side": "SELL", "hash": "4a93a8a9bcc2a04914870dfe40b067939a81771e", "best_bid": "0.033", "best_ask": "0.061"}], "timestamp": "1769384252587", "event_type": "price_change"}}
{"_local_timestamp": "2026-01-25T23:37:34.416610+00:00", "data": {"market": "0x0baf5017c6cdd082b72a9f8d81ce7a5568a11d2185b37f24aec4371feffa4508", "price_changes": [{"asset_id": "54912585197947912918703938085404885715682857902987396027502188879254644524559", "price": "0.203", "size": "0", "side": "BUY", "hash": "8e1939572d7948f1603e6265689a2d9b62cedc95", "best_bid": "0.993", "best_ask": "0.998"}, {"asset_id": "1398837009918163072638964138392157627970988230992506005676269129994871270413", "price": "0.797", "size": "0", "side": "SELL", "hash": "b4217c9925cba0d8085c8617db66255820fa32f5", "best_bid": "0.002", "best_ask": "0.007"}], "timestamp": "1769384254346", "event_type": "price_change"}}
{"_local_timestamp": "2026-01-25T23:37:34.846894+00:00", "data": {"market": "0x0baf5017c6cdd082b72a9f8d81ce7a5568a11d2185b37f24aec4371feffa4508", "price_changes": [{"asset_id": "54912585197947912918703938085404885715682857902987396027502188879254644524559", "price": "0.205", "size": "2439", "side": "BUY", "hash": "08ecb4bfceb177a864caa7a03a6c8863582fd535", "best_bid": "0.993", "best_ask": "0.998"}, {"asset_id": "1398837009918163072638964138392157627970988230992506005676269129994871270413", "price": "0.795", "size": "2439", "side": "SELL", "hash": "1c8ec25fa266a6ce682a02973047371e2fdf7c1f", "best_bid": "0.002", "best_ask": "0.007"}], "timestamp": "1769384254775", "event_type": "price_change"}}
{"_local_timestamp": "2026-01-25T23:37:37.064381+00:00", "data": {"market": "0x2e3433f79c616df13c4955a7134e595ee2ccf4866dce309925e755737b872271", "price_changes": [{"asset_id": "112202945651691176336626757870751886707772553418125673815227809139773741570078", "price": "0.868", "size": "0", "side": "BUY", "hash": "9e42b41c4a9b0e76f20e6175898f5aab48bf354f", "best_bid": "0.883", "best_ask": "0.918"}, {"asset_id": "18309888943220126175774903330165417854845342977748532448162902228663371934448", "price": "0.132", "size": "0", "side": "SELL", "hash": "021ca8ba1d139da61002cca0117f5186236a95a4", "best_bid": "0.082", "best_ask": "0.117"}], "timestamp": "1769384256994", "event_type": "price_change"}}
{"_local_timestamp": "2026-01-25T23:37:39.743054+00:00", "data": {"market": "0xdf0e04194ff7f25807465101e29d7d476bb9cbf7e56e950d2693cedf4787599f", "price_changes": [{"asset_id": "96765239208959541720088187158035685118767037049985993166814389120572666374201", "price": "0.373", "size": "0", "side": "BUY", "hash": "d27212319722319e83148242ad0e71d3123f2189", "best_bid": "0.939", "best_ask": "0.967"}, {"asset_id": "112838519090657527020403907389517191367689011522812125990685217194554034388792", "price": "0.627", "size": "0", "side": "SELL", "hash": "c4e7dd2d47b5983b8dab3bd61799522f72caf8fd", "best_bid": "0.033", "best_ask": "0.061"}], "timestamp": "1769384259669", "event_type": "price_change"}}
{"_local_timestamp": "2026-01-25T23:37:40.304432+00:00", "data": {"market": "0xdf0e04194ff7f25807465101e29d7d476bb9cbf7e56e950d2693cedf4787599f", "price_changes": [{"asset_id": "96765239208959541720088187158035685118767037049985993166814389120572666374201", "price": "0.375", "size": "1066", "side": "BUY", "hash": "e86ccc61bd4a0f7805ef1b7c2952bbaa3510fff0", "best_bid": "0.939", "best_ask": "0.967"}, {"asset_id": "112838519090657527020403907389517191367689011522812125990685217194554034388792", "price": "0.625", "size": "1066", "side": "SELL", "hash": "cc6bceceed61a60cb27724b773a9676d30789e12", "best_bid": "0.033", "best_ask": "0.061"}], "timestamp": "1769384260234", "event_type": "price_change"}}
{"_local_timestamp": "2026-01-25T23:37:54.458141+00:00", "data": {"market": "0x28b09e78c1a37a9212b683d5734c0b8375e9c85777e59bb498a08debb585e941", "price_changes": [{"asset_id": "80377662132340664016724672073316391179500510732361804244421570371942255684414", "price": "0.202", "size": "300", "side": "BUY", "hash": "0688c37a65abbb43c894c82b49e186708ba13791", "best_bid": "0.985", "best_ask": "0.993"}, {"asset_id": "44648314711717458063074998921644285938870392557850689878450818223237354241500", "price": "0.798", "size": "300", "side": "SELL", "hash": "96ad842dae0564da785e71160d7c03391c6a467a", "best_bid": "0.007", "best_ask": "0.015"}], "timestamp": "1769384274387", "event_type": "price_change"}}
{"_local_timestamp": "2026-01-25T23:37:55.395875+00:00", "data": {"market": "0xaf811fcf5edc733781bee6125756d3e1f02d04f2824b89ab7fa4f4ce30f998b5", "price_changes": [{"asset_id": "27643431546680855679789625370218065863059031034570354610668275237893764523490", "price": "0.18", "size": "217.99", "side": "SELL", "hash": "6d20200e1d28bf707cd783a3ad6faab98b3ce08a", "best_bid": "0.13", "best_ask": "0.15"}, {"asset_id": "94235206725638004435521288935127321522857776396521937922634976647313998892484", "price": "0.82", "size": "217.99", "side": "BUY", "hash": "e353e05946b85abdee224422bea45931163efd5b", "best_bid": "0.85", "best_ask": "0.87"}], "timestamp": "1769384275312", "event_type": "price_change"}}
{"_local_timestamp": "2026-01-25T23:37:55.396300+00:00", "data": {"market": "0xaf811fcf5edc733781bee6125756d3e1f02d04f2824b89ab7fa4f4ce30f998b5", "price_changes": [{"asset_id": "27643431546680855679789625370218065863059031034570354610668275237893764523490", "price": "0.15", "size": "393.32", "side": "SELL", "hash": "a281efda5cd4c0f90b6161fbbfa4937022de0354", "best_bid": "0.13", "best_ask": "0.15"}, {"asset_id": "94235206725638004435521288935127321522857776396521937922634976647313998892484", "price": "0.85", "size": "393.32", "side": "BUY", "hash": "01746c577290c0a46e7e9927ed9dde91fcec9f4d", "best_bid": "0.85", "best_ask": "0.87"}], "timestamp": "1769384275313", "event_type": "price_change"}}
{"_local_timestamp": "2026-01-25T23:37:55.396600+00:00", "data": {"market": "0xaf811fcf5edc733781bee6125756d3e1f02d04f2824b89ab7fa4f4ce30f998b5", "price_changes": [{"asset_id": "27643431546680855679789625370218065863059031034570354610668275237893764523490", "price": "0.27", "size": "8", "side": "SELL", "hash": "3369e6eea8e4c5cfc987d36625f0ce09496e0e16", "best_bid": "0.13", "best_ask": "0.15"}, {"asset_id": "94235206725638004435521288935127321522857776396521937922634976647313998892484", "price": "0.73", "size": "8", "side": "BUY", "hash": "9f99d78786ebf3a4226246dbd216f3764c220d8d", "best_bid": "0.85", "best_ask": "0.87"}], "timestamp": "1769384275314", "event_type": "price_change"}}
{"_local_timestamp": "2026-01-25T23:37:55.396896+00:00", "data": {"market": "0xaf811fcf5edc733781bee6125756d3e1f02d04f2824b89ab7fa4f4ce30f998b5", "price_changes": [{"asset_id": "27643431546680855679789625370218065863059031034570354610668275237893764523490", "price": "0.21", "size": "8", "side": "SELL", "hash": "03b978e3570cecdae8aff274b3125ce991fe4299", "best_bid": "0.13", "best_ask": "0.15"}, {"asset_id": "94235206725638004435521288935127321522857776396521937922634976647313998892484", "price": "0.79", "size": "8", "side": "BUY", "hash": "ea5576c5ebfcd940045a972ccce4c73852031df5", "best_bid": "0.85", "best_ask": "0.87"}], "timestamp": "1769384275314", "event_type": "price_change"}}
{"_local_timestamp": "2026-01-25T23:37:55.397210+00:00", "data": {"market": "0xaf811fcf5edc733781bee6125756d3e1f02d04f2824b89ab7fa4f4ce30f998b5", "price_changes": [{"asset_id": "27643431546680855679789625370218065863059031034570354610668275237893764523490", "price": "0.24", "size": "8", "side": "SELL", "hash": "5d16efb24fbc355b345ccd1f3efc359ffe326822", "best_bid": "0.13", "best_ask": "0.15"}, {"asset_id": "94235206725638004435521288935127321522857776396521937922634976647313998892484", "price": "0.76", "size": "8", "side": "BUY", "hash": "0148bea06b71111dfaa68e5faf3ba68cd6fb4e54", "best_bid": "0.85", "best_ask": "0.87"}], "timestamp": "1769384275315", "event_type": "price_change"}}
{"_local_timestamp": "2026-01-25T23:37:58.208697+00:00", "data": {"market": "0x2e3433f79c616df13c4955a7134e595ee2ccf4866dce309925e755737b872271", "price_changes": [{"asset_id": "112202945651691176336626757870751886707772553418125673815227809139773741570078", "price": "0.37", "size": "700", "side": "BUY", "hash": "bf65497f7a80922962e040b27040b8169aa8d05a", "best_bid": "0.883", "best_ask": "0.918"}, {"asset_id": "18309888943220126175774903330165417854845342977748532448162902228663371934448", "price": "0.63", "size": "700", "side": "SELL", "hash": "74984277e4373590961aa520379e52f17d8252c7", "best_bid": "0.082", "best_ask": "0.117"}], "timestamp": "1769384278138", "event_type": "price_change"}}
{"_local_timestamp": "2026-01-25T23:38:03.817426+00:00", "data": {"market": "0xaf811fcf5edc733781bee6125756d3e1f02d04f2824b89ab7fa4f4ce30f998b5", "price_changes": [{"asset_id": "94235206725638004435521288935127321522857776396521937922634976647313998892484", "price": "0.24", "size": "1255", "side": "BUY", "hash": "196e7f9f87b315935b6209d57d4c37f25cc18931", "best_bid": "0.85", "best_ask": "0.87"}, {"asset_id": "27643431546680855679789625370218065863059031034570354610668275237893764523490", "price": "0.76", "size": "1255", "side": "SELL", "hash": "48552477fd04254641d9d3680b185702e0fa3de2", "best_bid": "0.13", "best_ask": "0.15"}], "timestamp": "1769384283741", "event_type": "price_change"}}
{"_local_timestamp": "2026-01-25T23:38:19.284337+00:00", "data": {"market": "0x2e3433f79c616df13c4955a7134e595ee2ccf4866dce309925e755737b872271", "price_changes": [{"asset_id": "112202945651691176336626757870751886707772553418125673815227809139773741570078", "price": "0.37", "size": "0", "side": "BUY", "hash": "f1a7bfe0606388daebb6ab3952dd0168cc425121", "best_bid": "0.883", "best_ask": "0.918"}, {"asset_id": "18309888943220126175774903330165417854845342977748532448162902228663371934448", "price": "0.63", "size": "0", "side": "SELL", "hash": "fb7d73bd6383b91ef7fa69d581a903476f7b2837", "best_bid": "0.082", "best_ask": "0.117"}], "timestamp": "1769384299210", "event_type": "price_change"}}
{"_local_timestamp": "2026-01-25T23:38:32.551170+00:00", "data": {"market": "0x2e3433f79c616df13c4955a7134e595ee2ccf4866dce309925e755737b872271", "price_changes": [{"asset_id": "112202945651691176336626757870751886707772553418125673815227809139773741570078", "price": "0.34", "size": "75", "side": "BUY", "hash": "05787fb138f11bf56fbd60a5af97cbd92661031d", "best_bid": "0.883", "best_ask": "0.918"}, {"asset_id": "18309888943220126175774903330165417854845342977748532448162902228663371934448", "price": "0.66", "size": "75", "side": "SELL", "hash": "c7f549484de3c09d581222dc4c35c9a787b009fd", "best_bid": "0.082", "best_ask": "0.117"}], "timestamp": "1769384312479", "event_type": "price_change"}}
{"_local_timestamp": "2026-01-25T23:38:32.981913+00:00", "data": {"market": "0x2e3433f79c616df13c4955a7134e595ee2ccf4866dce309925e755737b872271", "price_changes": [{"asset_id": "112202945651691176336626757870751886707772553418125673815227809139773741570078", "price": "0.342", "size": "1169", "side": "BUY", "hash": "4ac2a258093c81c9da49533a1dea9a35b19870d1", "best_bid": "0.883", "best_ask": "0.918"}, {"asset_id": "18309888943220126175774903330165417854845342977748532448162902228663371934448", "price": "0.658", "size": "1169", "side": "SELL", "hash": "39508c64cc15e495b478a7e9c30e370c9af3cd0f", "best_bid": "0.082", "best_ask": "0.117"}], "timestamp": "1769384312897", "event_type": "price_change"}}
{"_local_timestamp": "2026-01-25T23:38:38.928722+00:00", "data": {"market": "0xaf811fcf5edc733781bee6125756d3e1f02d04f2824b89ab7fa4f4ce30f998b5", "price_changes": [{"asset_id": "94235206725638004435521288935127321522857776396521937922634976647313998892484", "price": "0.24", "size": "555", "side": "BUY", "hash": "fe377c1a5f891a6b5c0e7fdf99f1bf630166086d", "best_bid": "0.85", "best_ask": "0.87"}, {"asset_id": "27643431546680855679789625370218065863059031034570354610668275237893764523490", "price": "0.76", "size": "555", "side": "SELL", "hash": "42464a11053df4854f03ce09389152a93abb24d6", "best_bid": "0.13", "best_ask": "0.15"}], "timestamp": "1769384318857", "event_type": "price_change"}}
{"_local_timestamp": "2026-01-25T23:38:45.671949+00:00", "data": {"market": "0x2e3433f79c616df13c4955a7134e595ee2ccf4866dce309925e755737b872271", "price_changes": [{"asset_id": "18309888943220126175774903330165417854845342977748532448162902228663371934448", "price": "0.068", "size": "0", "side": "BUY", "hash": "906a902f0fa07aa6688b68e09ce3a497a189ff12", "best_bid": "0.082", "best_ask": "0.117"}, {"asset_id": "112202945651691176336626757870751886707772553418125673815227809139773741570078", "price": "0.932", "size": "0", "side": "SELL", "hash": "f367a2f42b01ee0b4615c08da439bfd514ec0989", "best_bid": "0.883", "best_ask": "0.918"}], "timestamp": "1769384325600", "event_type": "price_change"}}
{"_local_timestamp": "2026-01-25T23:38:46.254569+00:00", "data": {"market": "0xdf0e04194ff7f25807465101e29d7d476bb9cbf7e56e950d2693cedf4787599f", "price_changes": [{"asset_id": "112838519090657527020403907389517191367689011522812125990685217194554034388792", "price": "0.033", "size": "137.46", "side": "BUY", "hash": "2c1cea6f0101dc7ce4d23f6c2bd5445bcd1a51f7", "best_bid": "0.033", "best_ask": "0.061"}, {"asset_id": "96765239208959541720088187158035685118767037049985993166814389120572666374201", "price": "0.967", "size": "137.46", "side": "SELL", "hash": "0ca27a856fa98f3e281856d64b8bd3e3952a6c4f", "best_bid": "0.939", "best_ask": "0.967"}], "timestamp": "1769384326180", "event_type": "price_change"}}
{"_local_timestamp": "2026-01-25T23:38:46.276460+00:00", "data": {"market": "0x28b09e78c1a37a9212b683d5734c0b8375e9c85777e59bb498a08debb585e941", "price_changes": [{"asset_id": "80377662132340664016724672073316391179500510732361804244421570371942255684414", "price": "0.963", "size": "0", "side": "BUY", "hash": "e4694411fe5508c9ffa40305c95ed6b09449c9a4", "best_bid": "0.985", "best_ask": "0.993"}, {"asset_id": "44648314711717458063074998921644285938870392557850689878450818223237354241500", "price": "0.037", "size": "0", "side": "SELL", "hash": "60cdf6d8b3366049db56430f7ed7c0075a11b7f0", "best_bid": "0.007", "best_ask": "0.015"}], "timestamp": "1769384326202", "event_type": "price_change"}}
{"_local_timestamp": "2026-01-25T23:38:46.287892+00:00", "data": {"market": "0x0baf5017c6cdd082b72a9f8d81ce7a5568a11d2185b37f24aec4371feffa4508", "price_changes": [{"asset_id": "54912585197947912918703938085404885715682857902987396027502188879254644524559", "price": "0.968", "size": "0", "side": "BUY", "hash": "befb92b0bd3321d95b9b8919f67fcf077cd0a0b4", "best_bid": "0.993", "best_ask": "0.998"}, {"asset_id": "1398837009918163072638964138392157627970988230992506005676269129994871270413", "price": "0.032", "size": "0", "side": "SELL", "hash": "86c455dafd46c56491ec1de3c8ecce4961b82edf", "best_bid": "0.002", "best_ask": "0.007"}], "timestamp": "1769384326204", "event_type": "price_change"}}
{"_local_timestamp": "2026-01-25T23:38:46.288215+00:00", "data": {"market": "0x2e3433f79c616df13c4955a7134e595ee2ccf4866dce309925e755737b872271", "price_changes": [{"asset_id": "112202945651691176336626757870751886707772553418125673815227809139773741570078", "price": "0.883", "size": "66.66", "side": "BUY", "hash": "8f8c22ef0f7e0094472a0a48293bfe0165e434d2", "best_bid": "0.883", "best_ask": "0.918"}, {"asset_id": "18309888943220126175774903330165417854845342977748532448162902228663371934448", "price": "0.117", "size": "66.66", "side": "SELL", "hash": "b4f6bfb2499e16b6642bb1eca64c68f4ab69fbc1", "best_bid": "0.082", "best_ask": "0.117"}], "timestamp": "1769384326209", "event_type": "price_change"}}
{"_local_timestamp": "2026-01-25T23:38:47.368495+00:00", "data": {"market": "0x28b09e78c1a37a9212b683d5734c0b8375e9c85777e59bb498a08debb585e941", "price_changes": [{"asset_id": "80377662132340664016724672073316391179500510732361804244421570371942255684414", "price": "0.916", "size": "20", "side": "BUY", "hash": "f21f775fb99e7e66f2da103ad1286da31b3f3198", "best_bid": "0.985", "best_ask": "0.993"}, {"asset_id": "44648314711717458063074998921644285938870392557850689878450818223237354241500", "price": "0.084", "size": "20", "side": "SELL", "hash": "b27bf9c00270af15dc9e55e0fec851297498a029", "best_bid": "0.007", "best_ask": "0.015"}], "timestamp": "1769384327299", "event_type": "price_change"}}
{"_local_timestamp": "2026-01-25T23:38:47.397231+00:00", "data": {"market": "0x28b09e78c1a37a9212b683d5734c0b8375e9c85777e59bb498a08debb585e941", "price_changes": [{"asset_id": "80377662132340664016724672073316391179500510732361804244421570371942255684414", "price": "0.917", "size": "40", "side": "BUY", "hash": "3de45acf3ec91da2bf534db2eb7a689b109f315a", "best_bid": "0.985", "best_ask": "0.993"}, {"asset_id": "44648314711717458063074998921644285938870392557850689878450818223237354241500", "price": "0.083", "size": "40", "side": "SELL", "hash": "45ed24d70945eb59a7d4e0cbb254c34165da5210", "best_bid": "0.007", "best_ask": "0.015"}], "timestamp": "1769384327326", "event_type": "price_change"}}
{"_local_timestamp": "2026-01-25T23:38:49.364339+00:00", "data": {"market": "0x2e3433f79c616df13c4955a7134e595ee2ccf4866dce309925e755737b872271", "price_changes": [{"asset_id": "18309888943220126175774903330165417854845342977748532448162902228663371934448", "price": "0.07", "size": "702.76", "side": "BUY", "hash": "7537e7052bf7d73283eb4540265a4455dba26989", "best_bid": "0.082", "best_ask": "0.117"}, {"asset_id": "112202945651691176336626757870751886707772553418125673815227809139773741570078", "price": "0.93", "size": "702.76", "side": "SELL", "hash": "9e3a6bd11e6b8241350d68db1326f203549011fd", "best_bid": "0.883", "best_ask": "0.918"}], "timestamp": "1769384329279", "event_type": "price_change"}}
{"_local_timestamp": "2026-01-25T23:39:12.226151+00:00", "data": {"market": "0x28b09e78c1a37a9212b683d5734c0b8375e9c85777e59bb498a08debb585e941", "price_changes": [{"asset_id": "80377662132340664016724672073316391179500510732361804244421570371942255684414", "price": "0.201", "size": "5.01", "side": "BUY", "hash": "482a589f2139acffc6a013261c310253acad5cdf", "best_bid": "0.985", "best_ask": "0.993"}, {"asset_id": "44648314711717458063074998921644285938870392557850689878450818223237354241500", "price": "0.799", "size": "5.01", "side": "SELL", "hash": "ec115db337d375d1d1e5ceb1fb9efca6dbe2f34e", "best_bid": "0.007", "best_ask": "0.015"}], "timestamp": "1769384352137", "event_type": "price_change"}}
{"_local_timestamp": "2026-01-25T23:39:12.727021+00:00", "data": {"market": "0x28b09e78c1a37a9212b683d5734c0b8375e9c85777e59bb498a08debb585e941", "price_changes": [{"asset_id": "80377662132340664016724672073316391179500510732361804244421570371942255684414", "price": "0.203", "size": "2463", "side": "BUY", "hash": "3b46c9b9f62471453acbf855689f15ea00d03302", "best_bid": "0.985", "best_ask": "0.993"}, {"asset_id": "44648314711717458063074998921644285938870392557850689878450818223237354241500", "price": "0.797", "size": "2463", "side": "SELL", "hash": "cd0ee63e430c7679b0cf0141b5527f1afd8f9d00", "best_bid": "0.007", "best_ask": "0.015"}], "timestamp": "1769384352650", "event_type": "price_change"}}
{"_local_timestamp": "2026-01-25T23:39:22.568653+00:00", "data": {"market": "0x2e3433f79c616df13c4955a7134e595ee2ccf4866dce309925e755737b872271", "price_changes": [{"asset_id": "112202945651691176336626757870751886707772553418125673815227809139773741570078", "price": "0.192", "size": "0", "side": "BUY", "hash": "42def7cb3e66f56e00eea04a6a7d09555307f7a1", "best_bid": "0.883", "best_ask": "0.918"}, {"asset_id": "18309888943220126175774903330165417854845342977748532448162902228663371934448", "price": "0.808", "size": "0", "side": "SELL", "hash": "0858f48573d6c960a81566ddb7d6c11046167ccf", "best_bid": "0.082", "best_ask": "0.117"}], "timestamp": "1769384362222", "event_type": "price_change"}}
{"_local_timestamp": "2026-01-25T23:39:22.569050+00:00", "data": {"market": "0x2e3433f79c616df13c4955a7134e595ee2ccf4866dce309925e755737b872271", "price_changes": [{"asset_id": "112202945651691176336626757870751886707772553418125673815227809139773741570078", "price": "0.34", "size": "0", "side": "BUY", "hash": "42def7cb3e66f56e00eea04a6a7d09555307f7a1", "best_bid": "0.883", "best_ask": "0.918"}, {"asset_id": "18309888943220126175774903330165417854845342977748532448162902228663371934448", "price": "0.66", "size": "0", "side": "SELL", "hash": "0858f48573d6c960a81566ddb7d6c11046167ccf", "best_bid": "0.082", "best_ask": "0.117"}], "timestamp": "1769384362222", "event_type": "price_change"}}
{"_local_timestamp": "2026-01-25T23:39:22.577633+00:00", "data": {"market": "0x28b09e78c1a37a9212b683d5734c0b8375e9c85777e59bb498a08debb585e941", "price_changes": [{"asset_id": "80377662132340664016724672073316391179500510732361804244421570371942255684414", "price": "0.251", "size": "0", "side": "BUY", "hash": "9334e376259395b8441ec3222b4f425af840acac", "best_bid": "0.985", "best_ask": "0.993"}, {"asset_id": "44648314711717458063074998921644285938870392557850689878450818223237354241500", "price": "0.749", "size": "0", "side": "SELL", "hash": "fd0af56f9bb0f4657addd750a0124292cd2ca7ae", "best_bid": "0.007", "best_ask": "0.015"}], "timestamp": "1769384362222", "event_type": "price_change"}}
{"_local_timestamp": "2026-01-25T23:39:22.577968+00:00", "data": {"market": "0x0baf5017c6cdd082b72a9f8d81ce7a5568a11d2185b37f24aec4371feffa4508", "price_changes": [{"asset_id": "54912585197947912918703938085404885715682857902987396027502188879254644524559", "price": "0.251", "size": "0", "side": "BUY", "hash": "6424933e4bd412826b43128aa189b996a3680f8a", "best_bid": "0.993", "best_ask": "0.998"}, {"asset_id": "1398837009918163072638964138392157627970988230992506005676269129994871270413", "price": "0.749", "size": "0", "side": "SELL", "hash": "3bb72ad2b3a56e9842733254a3d11f4269085d93", "best_bid": "0.002", "best_ask": "0.007"}], "timestamp": "1769384362231", "event_type": "price_change"}}
{"_local_timestamp": "2026-01-25T23:39:22.932301+00:00", "data": {"market": "0x28b09e78c1a37a9212b683d5734c0b8375e9c85777e59bb498a08debb585e941", "price_changes": [{"asset_id": "80377662132340664016724672073316391179500510732361804244421570371942255684414", "price": "0.25", "size": "262", "side": "BUY", "hash": "e63ffb6302d771378439bcae34a5ea9b89a1e458", "best_bid": "0.985", "best_ask": "0.993"}, {"asset_id": "44648314711717458063074998921644285938870392557850689878450818223237354241500", "price": "0.75", "size": "262", "side": "SELL", "hash": "d23db0cc92cfa985d53f0f7a6d5106514dd46c8c", "best_bid": "0.007", "best_ask": "0.015"}], "timestamp": "1769384362723", "event_type": "price_change"}}
{"_local_timestamp": "2026-01-25T23:39:22.982983+00:00", "data": {"market": "0x0baf5017c6cdd082b72a9f8d81ce7a5568a11d2185b37f24aec4371feffa4508", "price_changes": [{"asset_id": "54912585197947912918703938085404885715682857902987396027502188879254644524559", "price": "0.25", "size": "262", "side": "BUY", "hash": "205e49e6c3876ade2bf4f42dce5c67d25bc651ea", "best_bid": "0.993", "best_ask": "0.998"}, {"asset_id": "1398837009918163072638964138392157627970988230992506005676269129994871270413", "price": "0.75", "size": "262", "side": "SELL", "hash": "fdd0ded7979507fd537bfb5a34433e21f788add0", "best_bid": "0.002", "best_ask": "0.007"}], "timestamp": "1769384362744", "event_type": "price_change"}}
{"_local_timestamp": "2026-01-25T23:39:22.983414+00:00", "data": {"market": "0x2e3433f79c616df13c4955a7134e595ee2ccf4866dce309925e755737b872271", "price_changes": [{"asset_id": "112202945651691176336626757870751886707772553418125673815227809139773741570078", "price": "0.341", "size": "1175", "side": "BUY", "hash": "debdda9ae32bd5067c260e5e933805e2cec925e2", "best_bid": "0.883", "best_ask": "0.918"}, {"asset_id": "18309888943220126175774903330165417854845342977748532448162902228663371934448", "price": "0.659", "size": "1175", "side": "SELL", "hash": "2f3e9dbd88f4e855dff8dd8f5138a3c259b442fd", "best_bid": "0.082", "best_ask": "0.117"}], "timestamp": "1769384362740", "event_type": "price_change"}}
{"_local_timestamp": "2026-01-25T23:39:23.038978+00:00", "data": {"market": "0x2e3433f79c616df13c4955a7134e595ee2ccf4866dce309925e755737b872271", "price_changes": [{"asset_id": "112202945651691176336626757870751886707772553418125673815227809139773741570078", "price": "0.191", "size": "2472", "side": "BUY", "hash": "25964530a80f8a28c422363759c863a0ef42687f", "best_bid": "0.883", "best_ask": "0.918"}, {"asset_id": "18309888943220126175774903330165417854845342977748532448162902228663371934448", "price": "0.809", "size": "2472", "side": "SELL", "hash": "32172093c27306acb814eb0f27ba61791f847803", "best_bid": "0.082", "best_ask": "0.117"}], "timestamp": "1769384362818", "event_type": "price_change"}}
{"_local_timestamp": "2026-01-25T23:39:23.088820+00:00", "data": {"market": "0x0baf5017c6cdd082b72a9f8d81ce7a5568a11d2185b37f24aec4371feffa4508", "price_changes": [{"asset_id": "54912585197947912918703938085404885715682857902987396027502188879254644524559", "price": "0.54", "size": "700", "side": "BUY", "hash": "a666ab31093daf3b5e65cc217ec95dd616c6089c", "best_bid": "0.993", "best_ask": "0.998"}, {"asset_id": "1398837009918163072638964138392157627970988230992506005676269129994871270413", "price": "0.46", "size": "700", "side": "SELL", "hash": "ff97304292f79add7d2ec2073e4289e1d0711689", "best_bid": "0.002", "best_ask": "0.007"}], "timestamp": "1769384362944", "event_type": "price_change"}}
{"_local_timestamp": "2026-01-25T23:39:29.200113+00:00", "data": {"market": "0xdf0e04194ff7f25807465101e29d7d476bb9cbf7e56e950d2693cedf4787599f", "price_changes": [{"asset_id": "112838519090657527020403907389517191367689011522812125990685217194554034388792", "price": "0.006", "size": "282.25", "side": "BUY", "hash": "2d39935cab4b32cf2380391bf869ae6a938cdfa4", "best_bid": "0.033", "best_ask": "0.061"}, {"asset_id": "96765239208959541720088187158035685118767037049985993166814389120572666374201", "price": "0.994", "size": "282.25", "side": "SELL", "hash": "abd6f18f35e25749f883eb13a68fcd68b231bb12", "best_bid": "0.939", "best_ask": "0.967"}], "timestamp": "1769384369113", "event_type": "price_change"}}
{"_local_timestamp": "2026-01-25T23:39:29.348666+00:00", "data": {"market": "0x28b09e78c1a37a9212b683d5734c0b8375e9c85777e59bb498a08debb585e941", "price_changes": [{"asset_id": "80377662132340664016724672073316391179500510732361804244421570371942255684414", "price": "0.914", "size": "0", "side": "BUY", "hash": "6d7f80e575a60f23a6f40ddf86a55803d8f87657", "best_bid": "0.985", "best_ask": "0.993"}, {"asset_id": "44648314711717458063074998921644285938870392557850689878450818223237354241500", "price": "0.086", "size": "0", "side": "SELL", "hash": "d86f4fc03928d5614147255b715ab796f075d0f9", "best_bid": "0.007", "best_ask": "0.015"}], "timestamp": "1769384369272", "event_type": "price_change"}}
{"_local_timestamp": "2026-01-25T23:39:29.349686+00:00", "data": {"market": "0x0baf5017c6cdd082b72a9f8d81ce7a5568a11d2185b37f24aec4371feffa4508", "price_changes": [{"asset_id": "54912585197947912918703938085404885715682857902987396027502188879254644524559", "price": "0.834", "size": "0", "side": "BUY", "hash": "2f85eb4ed122233054db46a7da58d9db15b4b59e", "best_bid": "0.993", "best_ask": "0.998"}, {"asset_id": "1398837009918163072638964138392157627970988230992506005676269129994871270413", "price": "0.166", "size": "0", "side": "SELL", "hash": "d92b9e962f851110af0b6de24f6522a3d1b2647b", "best_bid": "0.002", "best_ask": "0.007"}], "timestamp": "1769384369272", "event_type": "price_change"}}
{"_local_timestamp": "2026-01-25T23:39:29.543077+00:00", "data": {"market": "0x28b09e78c1a37a9212b683d5734c0b8375e9c85777e59bb498a08debb585e941", "price_changes": [{"asset_id": "80377662132340664016724672073316391179500510732361804244421570371942255684414", "price": "0.919", "size": "20", "side": "BUY", "hash": "7b562704e75595cd5ffcdff2680e8c43ae5d050b", "best_bid": "0.985", "best_ask": "0.993"}, {"asset_id": "44648314711717458063074998921644285938870392557850689878450818223237354241500", "price": "0.081", "size": "20", "side": "SELL", "hash": "645429792fbee1ea77fb7775a0cc0384b6b37042", "best_bid": "0.007", "best_ask": "0.015"}], "timestamp": "1769384369465", "event_type": "price_change"}}
{"_local_timestamp": "2026-01-25T23:39:29.543609+00:00", "data": {"market": "0x0baf5017c6cdd082b72a9f8d81ce7a5568a11d2185b37f24aec4371feffa4508", "price_changes": [{"asset_id": "54912585197947912918703938085404885715682857902987396027502188879254644524559", "price": "0.939", "size": "20", "side": "BUY", "hash": "80a002701e779e47b1ace39329178ba57103c308", "best_bid": "0.993", "best_ask": "0.998"}, {"asset_id": "1398837009918163072638964138392157627970988230992506005676269129994871270413", "price": "0.061", "size": "20", "side": "SELL", "hash": "07d598834486ca8e1aca5ad55d074d0de720afb4", "best_bid": "0.002", "best_ask": "0.007"}], "timestamp": "1769384369465", "event_type": "price_change"}}
