{"_local_timestamp": "2026-01-25T23:34:07.911956+00:00", "data": [{"market": "0x916bb8a256c4369c8c909c543e82a03d73a7fa15ee52c4a09b363c0a35c8d522", "asset_id": "52822071377528308915286289768941040938616825289625853907705142181024906754006", "timestamp": "1769383968014", "hash": "072acf70b22fc9b561df05ce743da540437f2a03", "bids": [{"price": "0.001", "size": "5911.57"}, {"price": "0.002", "size": "1256.55"}, {"price": "0.003", "size": "1000"}, {"price": "0.004", "size": "12.92"}, {"price": "0.01", "size": "301450"}, {"price": "0.011", "size": "2222"}, {"price": "0.012", "size": "5.11"}, {"price": "0.02", "size": "5400"}, {"price": "0.021", "size": "250"}, {"price": "0.031", "size": "7.44"}, {"price": "0.05", "size": "60"}, {"price": "0.06", "size": "66"}, {"price": "0.061", "size": "10.32"}, {"price": "0.1", "size": "570"}, {"price": "0.15", "size": "551.66"}, {"price": "0.2", "size": "410"}, {"price": "0.201", "size": "5.01"}, {"price": "0.24", "size": "116.66"}, {"price": "0.29", "size": "89.65"}, {"price": "0.3", "size": "1261"}, {"price": "0.34", "size": "70.58"}, {"price": "0.39", "size": "126.28"}, {"price": "0.5", "size": "615"}, {"price": "0.503", "size": "5"}, {"price": "0.8", "size": "555"}, {"price": "0.834", "size": "20"}, {"price": "0.838", "size": "45"}, {"price": "0.839", "size": "20"}, {"price": "0.84", "size": "20"}, {"price": "0.9", "size": "1000"}, {"price": "0.93", "size": "300"}, {"price": "0.931", "size": "300"}, {"price": "0.932", "size": "266.65"}, {"price": "0.94", "size": "100"}, {"price": "0.943", "size": "66.66"}, {"price": "0.95", "size": "80"}, {"price": "0.954", "size": "66.66"}, {"price": "0.955", "size": "57.09"}], "asks": [{"price": "0.999", "size": "6564.99"}, {"price": "0.998", "size": "88.83"}, {"price": "0.994", "size": "274.02"}, {"price": "0.993", "size": "133"}, {"price": "0.992", "size": "18.9"}, {"price": "0.99", "size": "66"}, {"price": "0.989", "size": "6.46"}, {"price": "0.988", "size": "66.66"}, {"price": "0.985", "size": "58.61"}, {"price": "0.983", "size": "91.66"}], "event_type": "book", "last_trade_price": "0.015"}, {"market": "0x9e97d6ca3294a0b34044822dae868b116356e442fe23a2e9120d86aa2566285b", "asset_id": "19253153737967360829902330593318407456391424226199683250300283492574668236154", "timestamp": "1769384034132", "hash": "bd93967cc56d767371b4d69475c987cb58ea4fd6", "bids": [{"price": "0.01", "size": "301462.8"}, {"price": "0.02", "size": "5400"}, {"price": "0.03", "size": "562.8"}, {"price": "0.05", "size": "60"}, {"price": "0.06", "size": "66"}, {"price": "0.07", "size": "7.37"}, {"price": "0.09", "size": "400"}, {"price": "0.1", "size": "765"}, {"price": "0.13", "size": "586.53"}, {"price": "0.14", "size": "250"}, {"price": "0.17", "size": "438.23"}, {"price": "0.18", "size": "6.22"}, {"price": "0.22", "size": "127.27"}, {"price": "0.25", "size": "705"}, {"price": "0.26", "size": "100"}, {"price": "0.3", "size": "80"}, {"price": "0.35", "size": "132.14"}, {"price": "0.55", "size": "1111"}, {"price": "0.56", "size": "733"}, {"price": "0.57", "size": "5"}, {"price": "0.75", "size": "12.5"}, {"price": "0.76", "size": "26"}, {"price": "0.8", "size": "26"}, {"price": "0.81", "size": "45"}, {"price": "0.82", "size": "320.16"}, {"price": "0.84", "size": "281.26"}, {"price": "0.85", "size": "8"}], "asks": [{"price": "0.99", "size": "2277"}, {"price": "0.98", "size": "261"}, {"price": "0.97", "size": "5"}, {"price": "0.96", "size": "216"}, {"price": "0.95", "size": "1000"}, {"price": "0.94", "size": "811"}, {"price": "0.91", "size": "200"}, {"price": "0.9", "size": "113.21"}, {"price": "0.89", "size": "26.22"}], "event_type": "book", "last_trade_price": "0.850"}, {"market": "0xfd308e9c9c273fc4baf7560110dbe3bf4e1a07162f31655a0b5d997029c69cfb", "asset_id": "41987510269245635414350451702418306508832372599801516690841435038913020512760", "timestamp": "1769383936662", "hash": "fe24eac8f699039ae95f57cb4a606184e1b06b4e", "bids": [{"price": "0.001", "size": "2793.99"}, {"price": "0.002", "size": "31.24"}, {"price": "0.005", "size": "829.47"}, {"price": "0.006", "size": "17.81"}, {"price": "0.01", "size": "455"}, {"price": "0.011", "size": "555"}, {"price": "0.012", "size": "250"}, {"price": "0.013", "size": "5.71"}, {"price": "0.017", "size": "60"}, {"price": "0.018", "size": "8.69"}, {"price": "0.02", "size": "5"}, {"price": "0.03", "size": "992.55"}, {"price": "0.031", "size": "140.21"}], "asks": [{"price": "0.999", "size": "6800.57"}, {"price": "0.998", "size": "1256.55"}, {"price": "0.997", "size": "1000"}, {"price": "0.996", "size": "11.32"}, {"price": "0.99", "size": "301450"}, {"price": "0.989", "size": "2227.73"}, {"price": "0.98", "size": "5400"}, {"price": "0.979", "size": "11.15"}, {"price": "0.96", "size": "700"}, {"price": "0.95", "size": "60"}, {"price": "0.94", "size": "66"}, {"price": "0.939", "size": "9.72"}, {"price": "0.9", "size": "570"}, {"price": "0.89", "size": "2557"}, {"price": "0.85", "size": "226.66"}, {"price": "0.81", "size": "418.42"}, {"price": "0.809", "size": "5.46"}, {"price": "0.799", "size": "250"}, {"price": "0.76", "size": "266.66"}, {"price": "0.71", "size": "89.65"}, {"price": "0.66", "size": "70.58"}, {"price": "0.61", "size": "51.28"}, {"price": "0.579", "size": "2222"}, {"price": "0.485", "size": "5"}, {"price": "0.48", "size": "534"}, {"price": "0.199", "size": "29"}, {"price": "0.191", "size": "20"}, {"price": "0.189", "size": "20"}, {"price": "0.188", "size": "25"}, {"price": "0.187", "size": "20"}, {"price": "0.186", "size": "20"}, {"price": "0.08", "size": "240"}, {"price": "0.079", "size": "555"}, {"price": "0.078", "size": "369.43"}, {"price": "0.077", "size": "200"}, {"price": "0.06", "size": "17"}, {"price": "0.053", "size": "80"}, {"price": "0.04", "size": "5"}, {"price": "0.039", "size": "15.6"}, {"price": "0.038", "size": "42"}], "event_type": "book", "last_trade_price": "0.031"}, {"market": "0x8c1937a09dc020e283538a3a04ea18445d626e023ac05d8fb763b132eadd289d", "asset_id": "103908283520007978422292376817533115820651896056215083252654661103131408613493", "timestamp": "1769383936662", "hash": "644bacfff6a3675a40f97a687522f064b5a3126a", "bids": [{"price": "0.001", "size": "8296.57"}, {"price": "0.002", "size": "1256.55"}, {"price": "0.003", "size": "1000"}, {"price": "0.004", "size": "11.32"}, {"price": "0.01", "size": "301450"}, {"price": "0.011", "size": "5.73"}, {"price": "0.02", "size": "5000"}, {"price": "0.021", "size": "11.15"}, {"price": "0.05", "size": "2682"}, {"price": "0.06", "size": "66"}, {"price": "0.061", "size": "10.32"}, {"price": "0.1", "size": "570"}, {"price": "0.15", "size": "551.66"}, {"price": "0.2", "size": "410"}, {"price": "0.201", "size": "5.01"}, {"price": "0.25", "size": "2484"}, {"price": "0.251", "size": "250"}, {"price": "0.3", "size": "86.66"}, {"price": "0.35", "size": "68.57"}, {"price": "0.4", "size": "50"}, {"price": "0.45", "size": "760"}, {"price": "0.495", "size": "5"}, {"price": "0.496", "size": "20"}, {"price": "0.84", "size": "150"}, {"price": "0.841", "size": "5"}, {"price": "0.89", "size": "20"}, {"price": "0.892", "size": "40"}, {"price": "0.897", "size": "20"}, {"price": "0.898", "size": "20"}, {"price": "0.9", "size": "1000"}, {"price": "0.901", "size": "222"}, {"price": "0.91", "size": "20"}, {"price": "0.92", "size": "50"}, {"price": "0.93", "size": "50"}, {"price": "0.94", "size": "299.44"}, {"price": "0.955", "size": "37.93"}, {"price": "0.966", "size": "60"}, {"price": "0.97", "size": "367.02"}, {"price": "0.974", "size": "98.94"}, {"price": "0.975", "size": "21.28"}, {"price": "0.983", "size": "34"}, {"price": "0.985", "size": "937.59"}, {"price": "0.986", "size": "161.21"}, {"price": "0.987", "size": "11.25"}], "asks": [{"price": "0.999", "size": "4449.99"}, {"price": "0.998", "size": "292.11"}, {"price": "0.997", "size": "786.82"}, {"price": "0.996", "size": "53.92"}, {"price": "0.995", "size": "16.05"}, {"price": "0.99", "size": "5080"}, {"price": "0.989", "size": "338.66"}], "event_type": "book", "last_trade_price": "0.011"}, {"market": "0xc97a1d10a34399688ccea96d9a05db74135ff67dfee288c4d00379792dcf2011", "asset_id": "46295679083603787387508675043247351552210019749585109050272416293653337105685", "timestamp": "1769383932516", "hash": "89115e108af030a788737c80164556bb3184732b", "bids": [{"price": "0.01", "size": "300056.86"}, {"price": "0.02", "size": "5015.65"}, {"price": "0.03", "size": "555"}, {"price": "0.04", "size": "8.89"}, {"price": "0.05", "size": "615"}, {"price": "0.06", "size": "727"}, {"price": "0.07", "size": "258.26"}, {"price": "0.08", "size": "20"}, {"price": "0.09", "size": "100"}, {"price": "0.1", "size": "10"}, {"price": "0.11", "size": "126.22"}, {"price": "0.13", "size": "40"}, {"price": "0.14", "size": "47"}, {"price": "0.15", "size": "215"}, {"price": "0.16", "size": "30"}], "asks": [{"price": "0.99", "size": "6464.04"}, {"price": "0.98", "size": "5"}, {"price": "0.97", "size": "5"}, {"price": "0.95", "size": "500"}, {"price": "0.94", "size": "560.15"}, {"price": "0.92", "size": "650"}, {"price": "0.87", "size": "586.53"}, {"price": "0.84", "size": "805"}, {"price": "0.83", "size": "438.23"}, {"price": "0.79", "size": "233.33"}, {"price": "0.74", "size": "100"}, {"price": "0.7", "size": "80"}, {"price": "0.68", "size": "750"}, {"price": "0.67", "size": "150"}, {"price": "0.66", "size": "133.82"}, {"price": "0.52", "size": "694.71"}, {"price": "0.23", "size": "150"}, {"price": "0.22", "size": "1547.84"}, {"price": "0.21", "size": "208.52"}], "event_type": "book", "last_trade_price": "0.150"}, {"market": "0x916bb8a256c4369c8c909c543e82a03d73a7fa15ee52c4a09b363c0a35c8d522", "asset_id": "108935516272651260502928073006561933796317904485811751989800726817886684592061", "timestamp": "1769383968014", "hash": "e82ad9e11597672e9562e789454d5f81bc23eedd", "bids": [{"price": "0.001", "size": "6564.99"}, {"price": "0.002", "size": "88.83"}, {"price": "0.006", "size": "274.02"}, {"price": "0.007", "size": "133"}, {"price": "0.008", "size": "18.9"}, {"price": "0.01", "size": "66"}, {"price": "0.011", "size": "6.46"}, {"price": "0.012", "size": "66.66"}, {"price": "0.015", "size": "58.61"}, {"price": "0.017", "size": "91.66"}], "asks": [{"price": "0.999", "size": "5911.57"}, {"price": "0.998", "size": "1256.55"}, {"price": "0.997", "size": "1000"}, {"price": "0.996", "size": "12.92"}, {"price": "0.99", "size": "301450"}, {"price": "0.989", "size": "2222"}, {"price": "0.988", "size": "5.11"}, {"price": "0.98", "size": "5400"}, {"price": "0.979", "size": "250"}, {"price": "0.969", "size": "7.44"}, {"price": "0.95", "size": "60"}, {"price": "0.94", "size": "66"}, {"price": "0.939", "size": "10.32"}, {"price": "0.9", "size": "570"}, {"price": "0.85", "size": "551.66"}, {"price": "0.8", "size": "410"}, {"price": "0.799", "size": "5.01"}, {"price": "0.76", "size": "116.66"}, {"price": "0.71", "size": "89.65"}, {"price": "0.7", "size": "1261"}, {"price": "0.66", "size": "70.58"}, {"price": "0.61", "size": "126.28"}, {"price": "0.5", "size": "615"}, {"price": "0.497", "size": "5"}, {"price": "0.2", "size": "555"}, {"price": "0.166", "size": "20"}, {"price": "0.162", "size": "45"}, {"price": "0.161", "size": "20"}, {"price": "0.16", "size": "20"}, {"price": "0.1", "size": "1000"}, {"price": "0.07", "size": "300"}, {"price": "0.069", "size": "300"}, {"price": "0.068", "size": "266.65"}, {"price": "0.06", "size": "100"}, {"price": "0.057", "size": "66.66"}, {"price": "0.05", "size": "80"}, {"price": "0.046", "size": "66.66"}, {"price": "0.045", "size": "57.09"}], "event_type": "book", "last_trade_price": "0.015"}, {"market": "0x9e97d6ca3294a0b34044822dae868b116356e442fe23a2e9120d86aa2566285b", "asset_id": "13023509041598257520776296029419758530591111697952522984734378906708885744269", "timestamp": "1769384034132", "hash": "e07293dcc85bd029e970bef6dac9377fc31cb171", "bids": [{"price": "0.01", "size": "2277"}, {"price": "0.02", "size": "261"}, {"price": "0.03", "size": "5"}, {"price": "0.04", "size": "216"}, {"price": "0.05", "size": "1000"}, {"price": "0.06", "size": "811"}, {"price": "0.09", "size": "200"}, {"price": "0.1", "size": "113.21"}, {"price": "0.11", "size": "26.22"}], "asks": [{"price": "0.99", "size": "301462.8"}, {"price": "0.98", "size": "5400"}, {"price": "0.97", "size": "562.8"}, {"price": "0.95", "size": "60"}, {"price": "0.94", "size": "66"}, {"price": "0.93", "size": "7.37"}, {"price": "0.91", "size": "400"}, {"price": "0.9", "size": "765"}, {"price": "0.87", "size": "586.53"}, {"price": "0.86", "size": "250"}, {"price": "0.83", "size": "438.23"}, {"price": "0.82", "size": "6.22"}, {"price": "0.78", "size": "127.27"}, {"price": "0.75", "size": "705"}, {"price": "0.74", "size": "100"}, {"price": "0.7", "size": "80"}, {"price": "0.65", "size": "132.14"}, {"price": "0.45", "size": "1111"}, {"price": "0.44", "size": "733"}, {"price": "0.43", "size": "5"}, {"price": "0.25", "size": "12.5"}, {"price": "0.24", "size": "26"}, {"price": "0.2", "size": "26"}, {"price": "0.19", "size": "45"}, {"price": "0.18", "size": "320.16"}, {"price": "0.16", "size": "281.26"}, {"price": "0.15", "size": "8"}], "event_type": "book", "last_trade_price": "0.850"}, {"market": "0x8c1937a09dc020e283538a3a04ea18445d626e023ac05d8fb763b132eadd289d", "asset_id": "51370447146650998467964273203513577067488238207603923199894457994024881064590", "timestamp": "1769383936662", "hash": "139cd47fad6da6a0f0dcdb5f2501b0ef97e9ea1d", "bids": [{"price": "0.001", "size": "4449.99"}, {"price": "0.002", "size": "292.11"}, {"price": "0.003", "size": "786.82"}, {"price": "0.004", "size": "53.92"}, {"price": "0.005", "size": "16.05"}, {"price": "0.01", "size": "5080"}, {"price": "0.011", "size": "338.66"}], "asks": [{"price": "0.999", "size": "8296.57"}, {"price": "0.998", "size": "1256.55"}, {"price": "0.997", "size": "1000"}, {"price": "0.996", "size": "11.32"}, {"price": "0.99", "size": "301450"}, {"price": "0.989", "size": "5.73"}, {"price": "0.98", "size": "5000"}, {"price": "0.979", "size": "11.15"}, {"price": "0.95", "size": "2682"}, {"price": "0.94", "size": "66"}, {"price": "0.939", "size": "10.32"}, {"price": "0.9", "size": "570"}, {"price": "0.85", "size": "551.66"}, {"price": "0.8", "size": "410"}, {"price": "0.799", "size": "5.01"}, {"price": "0.75", "size": "2484"}, {"price": "0.749", "size": "250"}, {"price": "0.7", "size": "86.66"}, {"price": "0.65", "size": "68.57"}, {"price": "0.6", "size": "50"}, {"price": "0.55", "size": "760"}, {"price": "0.505", "size": "5"}, {"price": "0.504", "size": "20"}, {"price": "0.16", "size": "150"}, {"price": "0.159", "size": "5"}, {"price": "0.11", "size": "20"}, {"price": "0.108", "size": "40"}, {"price": "0.103", "size": "20"}, {"price": "0.102", "size": "20"}, {"price": "0.1", "size": "1000"}, {"price": "0.099", "size": "222"}, {"price": "0.09", "size": "20"}, {"price": "0.08", "size": "50"}, {"price": "0.07", "size": "50"}, {"price": "0.06", "size": "299.44"}, {"price": "0.045", "size": "37.93"}, {"price": "0.034", "size": "60"}, {"price": "0.03", "size": "367.02"}, {"price": "0.026", "size": "98.94"}, {"price": "0.025", "size": "21.28"}, {"price": "0.017", "size": "34"}, {"price": "0.015", "size": "937.59"}, {"price": "0.014", "size": "161.21"}, {"price": "0.013", "size": "11.25"}], "event_type": "book", "last_trade_price": "0.011"}, {"market": "0xfd308e9c9c273fc4baf7560110dbe3bf4e1a07162f31655a0b5d997029c69cfb", "asset_id": "77063062487728149614774676568324164832607328044033753723737434149701536733938", "timestamp": "1769383936662", "hash": "2d47a9caf1dbb1f134246a58a8cdfc8824ecaf79", "bids": [{"price": "0.001", "size": "6800.57"}, {"price": "0.002", "size": "1256.55"}, {"price": "0.003", "size": "1000"}, {"price": "0.004", "size": "11.32"}, {"price": "0.01", "size": "301450"}, {"price": "0.011", "size": "2227.73"}, {"price": "0.02", "size": "5400"}, {"price": "0.021", "size": "11.15"}, {"price": "0.04", "size": "700"}, {"price": "0.05", "size": "60"}, {"price": "0.06", "size": "66"}, {"price": "0.061", "size": "9.72"}, {"price": "0.1", "size": "570"}, {"price": "0.11", "size": "2557"}, {"price": "0.15", "size": "226.66"}, {"price": "0.19", "size": "418.42"}, {"price": "0.191", "size": "5.46"}, {"price": "0.201", "size": "250"}, {"price": "0.24", "size": "266.66"}, {"price": "0.29", "size": "89.65"}, {"price": "0.34", "size": "70.58"}, {"price": "0.39", "size": "51.28"}, {"price": "0.421", "size": "2222"}, {"price": "0.515", "size": "5"}, {"price": "0.52", "size": "534"}, {"price": "0.801", "size": "29"}, {"price": "0.809", "size": "20"}, {"price": "0.811", "size": "20"}, {"price": "0.812", "size": "25"}, {"price": "0.813", "size": "20"}, {"price": "0.814", "size": "20"}, {"price": "0.92", "size": "240"}, {"price": "0.921", "size": "555"}, {"price": "0.922", "size": "369.43"}, {"price": "0.923", "size": "200"}, {"price": "0.94", "size": "17"}, {"price": "0.947", "size": "80"}, {"price": "0.96", "size": "5"}, {"price": "0.961", "size": "15.6"}, {"price": "0.962", "size": "42"}], "asks": [{"price": "0.999", "size": "2793.99"}, {"price": "0.998", "size": "31.24"}, {"price": "0.995", "size": "829.47"}, {"price": "0.994", "size": "17.81"}, {"price": "0.99", "size": "455"}, {"price": "0.989", "size": "555"}, {"price": "0.988", "size": "250"}, {"price": "0.987", "size": "5.71"}, {"price": "0.983", "size": "60"}, {"price": "0.982", "size": "8.69"}, {"price": "0.98", "size": "5"}, {"price": "0.97", "size": "992.55"}, {"price": "0.969", "size": "140.21"}], "event_type": "book", "last_trade_price": "0.031"}, {"market": "0xc97a1d10a34399688ccea96d9a05db74135ff67dfee288c4d00379792dcf2011", "asset_id": "105499979175297845859286056968822861912891864044344906696929192748628753089258", "timestamp": "1769383932516", "hash": "5471673fc67d8682b013b9660b2b1f27a7b645e5", "bids": [{"price": "0.01", "size": "6464.04"}, {"price": "0.02", "size": "5"}, {"price": "0.03", "size": "5"}, {"price": "0.05", "size": "500"}, {"price": "0.06", "size": "560.15"}, {"price": "0.08", "size": "650"}, {"price": "0.13", "size": "586.53"}, {"price": "0.16", "size": "805"}, {"price": "0.17", "size": "438.23"}, {"price": "0.21", "size": "233.33"}, {"price": "0.26", "size": "100"}, {"price": "0.3", "size": "80"}, {"price": "0.32", "size": "750"}, {"price": "0.33", "size": "150"}, {"price": "0.34", "size": "133.82"}, {"price": "0.48", "size": "694.71"}, {"price": "0.77", "size": "150"}, {"price": "0.78", "size": "1547.84"}, {"price": "0.79", "size": "208.52"}], "asks": [{"price": "0.99", "size": "300056.86"}, {"price": "0.98", "size": "5015.65"}, {"price": "0.97", "size": "555"}, {"price": "0.96", "size": "8.89"}, {"price": "0.95", "size": "615"}, {"price": "0.94", "size": "727"}, {"price": "0.93", "size": "258.26"}, {"price": "0.92", "size": "20"}, {"price": "0.91", "size": "100"}, {"price": "0.9", "size": "10"}, {"price": "0.89", "size": "126.22"}, {"price": "0.87", "size": "40"}, {"price": "0.86", "size": "47"}, {"price": "0.85", "size": "215"}, {"price": "0.84", "size": "30"}], "event_type": "book", "last_trade_price": "0.150"}]}
{"_local_timestamp": "2026-01-25T23:34:27.706123+00:00", "data": {"market": "0x916bb8a256c4369c8c909c543e82a03d73a7fa15ee52c4a09b363c0a35c8d522", "price_changes": [{"asset_id": "52822071377528308915286289768941040938616825289625853907705142181024906754006", "price": "0.39", "size": "51.28", "side": "BUY", "hash": "22660d45b7f891ff2605267032d74031bdbae823", "best_bid": "0.955", "best_ask": "0.983"}, {"asset_id": "108935516272651260502928073006561933796317904485811751989800726817886684592061", "price": "0.61", "size": "51.28", "side": "SELL", "hash": "b45a6c7ba6527550736f667f0c810935831a0bd9", "best_bid": "0.017", "best_ask": "0.045"}], "timestamp": "1769384067568", "event_type": "price_change"}}
{"_local_timestamp": "2026-01-25T23:36:26.108064+00:00", "data": {"market": "0xc97a1d10a34399688ccea96d9a05db74135ff67dfee288c4d00379792dcf2011", "price_changes": [{"asset_id": "46295679083603787387508675043247351552210019749585109050272416293653337105685", "price": "0.21", "size": "188.52", "side": "SELL", "hash": "ada3492fb42dc0baf2677fb386185efdb092bd5b", "best_bid": "0.16", "best_ask": "0.21"}, {"asset_id": "105499979175297845859286056968822861912891864044344906696929192748628753089258", "price": "0.79", "size": "188.52", "side": "BUY", "hash": "a925a426b91cc82064ea0acb945ada13c88cff37", "best_bid": "0.79", "best_ask": "0.84"}], "timestamp": "1769384186005", "event_type": "price_change"}}
{"_local_timestamp": "2026-01-25T23:36:26.150428+00:00", "data": {"market": "0x916bb8a256c4369c8c909c543e82a03d73a7fa15ee52c4a09b363c0a35c8d522", "price_changes": [{"asset_id": "52822071377528308915286289768941040938616825289625853907705142181024906754006", "price": "0.94", "size": "126", "side": "BUY", "hash": "2866d6f3cb15dcaaa5befa8353c009dbd52ecc63", "best_bid": "0.955", "best_ask": "0.983"}, {"asset_id": "108935516272651260502928073006561933796317904485811751989800726817886684592061", "price": "0.06", "size": "126", "side": "SELL", "hash": "9d798fcdc2448614fee4eb130d582130215b2826", "best_bid": "0.017", "best_ask": "0.045"}], "timestamp": "1769384186056", "event_type": "price_change"}}
{"_local_timestamp": "2026-01-25T23:36:26.150873+00:00", "data": {"market": "0xc97a1d10a34399688ccea96d9a05db74135ff67dfee288c4d00379792dcf2011", "price_changes": [{"asset_id": "46295679083603787387508675043247351552210019749585109050272416293653337105685", "price": "0.16", "size": "56", "side": "BUY", "hash": "29eca7d7282d5d105d36a4d6d860aa229803ebbf", "best_bid": "0.16", "best_ask": "0.21"}, {"asset_id": "105499979175297845859286056968822861912891864044344906696929192748628753089258", "price": "0.84", "size": "56", "side": "SELL", "hash": "1c0f53a0d890e9f39f9bbd8a2d3612dcd24ae22e", "best_bid": "0.79", "best_ask": "0.84"}], "timestamp": "1769384186059", "event_type": "price_change"}}
{"_local_timestamp": "2026-01-25T23:36:26.151143+00:00", "data": {"market": "0x8c1937a09dc020e283538a3a04ea18445d626e023ac05d8fb763b132eadd289d", "price_changes": [{"asset_id": "103908283520007978422292376817533115820651896056215083252654661103131408613493", "price": "0.947", "size": "26", "side": "BUY", "hash": "e15c059098087d8fa7c909e92244cd799042aba5", "best_bid": "0.987", "best_ask": "0.989"}, {"asset_id": "51370447146650998467964273203513577067488238207603923199894457994024881064590", "price": "0.053", "size": "26", "side": "SELL", "hash": "58568779dab4140d3f2e820be13b71748efe5106", "best_bid": "0.011", "best_ask": "0.013"}], "timestamp": "1769384186064", "event_type": "price_change"}}
{"_local_timestamp": "2026-01-25T23:36:26.151373+00:00", "data": {"market": "0xfd308e9c9c273fc4baf7560110dbe3bf4e1a07162f31655a0b5d997029c69cfb", "price_changes": [{"asset_id": "77063062487728149614774676568324164832607328044033753723737434149701536733938", "price": "0.926", "size": "26", "side": "BUY", "hash": "04ea64e470dbcf892fa84ad6acc73a5022683acd", "best_bid": "0.962", "best_ask": "0.969"}, {"asset_id": "41987510269245635414350451702418306508832372599801516690841435038913020512760", "price": "0.074", "size": "26", "side": "SELL", "hash": "4a90d365b0e50b4a82ab562ad472e469e1c48c58", "best_bid": "0.031", "best_ask": "0.038"}], "timestamp": "1769384186072", "event_type": "price_change"}}
{"_local_timestamp": "2026-01-25T23:36:26.180655+00:00", "data": {"market": "0x8c1937a09dc020e283538a3a04ea18445d626e023ac05d8fb763b132eadd289d", "price_changes": [{"asset_id": "103908283520007978422292376817533115820651896056215083252654661103131408613493", "price": "0.496", "size": "0", "side": "BUY", "hash": "118638605e93389bac6bf68618d67ca545b17cce", "best_bid": "0.987", "best_ask": "0.989"}, {"asset_id": "51370447146650998467964273203513577067488238207603923199894457994024881064590", "price": "0.504", "size": "0", "side": "SELL", "hash": "a32b913211e2e47aec1e410f916da8153da2e693", "best_bid": "0.011", "best_ask": "0.013"}], "timestamp": "1769384186102", "event_type": "price_change"}}
{"_local_timestamp": "2026-01-25T23:36:26.180963+00:00", "data": {"market": "0x916bb8a256c4369c8c909c543e82a03d73a7fa15ee52c4a09b363c0a35c8d522", "price_changes": [{"asset_id": "52822071377528308915286289768941040938616825289625853907705142181024906754006", "price": "0.834", "size": "0", "side": "BUY", "hash": "20efc3923092d3095aff380921b4a4498b498c11", "best_bid": "0.955", "best_ask": "0.983"}, {"asset_id": "108935516272651260502928073006561933796317904485811751989800726817886684592061", "price": "0.166", "size": "0", "side": "SELL", "hash": "ee1bae3217256979865b1ad3df4255e9037c435f", "best_bid": "0.017", "best_ask": "0.045"}], "timestamp": "1769384186102", "event_type": "price_change"}}
{"_local_timestamp": "2026-01-25T23:36:26.206259+00:00", "data": {"market": "0x916bb8a256c4369c8c909c543e82a03d73a7fa15ee52c4a09b363c0a35c8d522", "price_changes": [{"asset_id": "52822071377528308915286289768941040938616825289625853907705142181024906754006", "price": "0.84", "size": "40", "side": "BUY", "hash": "3beb5f27859797a799b53fa188987ab36d3db1d5", "best_bid": "0.955", "best_ask": "0.983"}, {"asset_id": "108935516272651260502928073006561933796317904485811751989800726817886684592061", "price": "0.16", "size": "40", "side": "SELL", "hash": "98f7c8199c3c0ed4adc1732d6be84614a6a8b738", "best_bid": "0.017", "best_ask": "0.045"}], "timestamp": "1769384186136", "event_type": "price_change"}}
{"_local_timestamp": "2026-01-25T23:36:26.211801+00:00", "data": {"market": "0x8c1937a09dc020e283538a3a04ea18445d626e023ac05d8fb763b132eadd289d", "price_changes": [{"asset_id": "103908283520007978422292376817533115820651896056215083252654661103131408613493", "price": "0.496", "size": "20", "side": "BUY", "hash": "874ab4505a8f90eff5a47a12d03b36ee487704f2", "best_bid": "0.987", "best_ask": "0.989"}, {"asset_id": "51370447146650998467964273203513577067488238207603923199894457994024881064590", "price": "0.504", "size": "20", "side": "SELL", "hash": "f8271352b93406ace18ec9211a6c2d802bbbef16", "best_bid": "0.011", "best_ask": "0.013"}], "timestamp": "1769384186136", "event_type": "price_change"}}
{"_local_timestamp": "2026-01-25T23:36:26.274744+00:00", "data": {"market": "0xc97a1d10a34399688ccea96d9a05db74135ff67dfee288c4d00379792dcf2011", "price_changes": [{"asset_id": "46295679083603787387508675043247351552210019749585109050272416293653337105685", "price": "0.21", "size": "208.52", "side": "SELL", "hash": "c460647f26cd8eb0ac4eecfd4afc587be5554685", "best_bid": "0.16", "best_ask": "0.21"}, {"asset_id": "105499979175297845859286056968822861912891864044344906696929192748628753089258", "price": "0.79", "size": "208.52", "side": "BUY", "hash": "55becfc778450e616e77989ebb4bc1ad72f82d3d", "best_bid": "0.79", "best_ask": "0.84"}], "timestamp": "1769384186196", "event_type": "price_change"}}
{"_local_timestamp": "2026-01-25T23:36:26.275175+00:00", "data": {"market": "0xfd308e9c9c273fc4baf7560110dbe3bf4e1a07162f31655a0b5d997029c69cfb", "price_changes": [{"asset_id": "77063062487728149614774676568324164832607328044033753723737434149701536733938", "price": "0.812", "size": "5", "side": "BUY", "hash": "6fe6651702b527507ad320ccf9ae81312b909225", "best_bid": "0.962", "best_ask": "0.969"}, {"asset_id": "41987510269245635414350451702418306508832372599801516690841435038913020512760", "price": "0.188", "size": "5", "side": "SELL", "hash": "5a156088b9b60e96c8caa886fa7477dc450650e1", "best_bid": "0.031", "best_ask": "0.038"}], "timestamp": "1769384186207", "event_type": "price_change"}}
{"_local_timestamp": "2026-01-25T23:36:26.296388+00:00", "data": {"market": "0xc97a1d10a34399688ccea96d9a05db74135ff67dfee288c4d00379792dcf2011", "price_changes": [{"asset_id": "46295679083603787387508675043247351552210019749585109050272416293653337105685", "price": "0.13", "size": "20", "side": "BUY", "hash": "6a00eb00534fc646eea8f4f3ccbdb5451e34b7e6", "best_bid": "0.16", "best_ask": "0.21"}, {"asset_id": "105499979175297845859286056968822861912891864044344906696929192748628753089258", "price": "0.87", "size": "20", "side": "SELL", "hash": "5a517edcd6c72b91abaf3c686e14e44d1879a7fe", "best_bid": "0.79", "best_ask": "0.84"}], "timestamp": "1769384186219", "event_type": "price_change"}}
{"_local_timestamp": "2026-01-25T23:36:26.296823+00:00", "data": {"market": "0x8c1937a09dc020e283538a3a04ea18445d626e023ac05d8fb763b132eadd289d", "price_changes": [{"asset_id": "103908283520007978422292376817533115820651896056215083252654661103131408613493", "price": "0.892", "size": "20", "side": "BUY", "hash": "d898920e75dea25848f041e86046d2db3b0fb42d", "best_bid": "0.987", "best_ask": "0.989"}, {"asset_id": "51370447146650998467964273203513577067488238207603923199894457994024881064590", "price": "0.108", "size": "20", "side": "SELL", "hash": "637238a008bbf3f76d30c11ca36d177e66b8963b", "best_bid": "0.011", "best_ask": "0.013"}], "timestamp": "1769384186219", "event_type": "price_change"}}
{"_local_timestamp": "2026-01-25T23:36:26.355996+00:00", "data": {"market": "0xc97a1d10a34399688ccea96d9a05db74135ff67dfee288c4d00379792dcf2011", "price_changes": [{"asset_id": "46295679083603787387508675043247351552210019749585109050272416293653337105685", "price": "0.14", "size": "67", "side": "BUY", "hash": "2b28bd4ec5aad46a5177b9c14769c8c1176d6f73", "best_bid": "0.16", "best_ask": "0.21"}, {"asset_id": "105499979175297845859286056968822861912891864044344906696929192748628753089258", "price": "0.86", "size": "67", "side": "SELL", "hash": "e9f71c4d22bc4d986b0c0988e0d8811e68d1a914", "best_bid": "0.79", "best_ask": "0.84"}], "timestamp": "1769384186284", "event_type": "price_change"}}
{"_local_timestamp": "2026-01-25T23:36:26.356433+00:00", "data": {"market": "0x8c1937a09dc020e283538a3a04ea18445d626e023ac05d8fb763b132eadd289d", "price_changes": [{"asset_id": "103908283520007978422292376817533115820651896056215083252654661103131408613493", "price": "0.892", "size": "40", "side": "BUY", "hash": "89795dcc34b148c155ae985ba07cb578a8e9f161", "best_bid": "0.987", "best_ask": "0.989"}, {"asset_id": "51370447146650998467964273203513577067488238207603923199894457994024881064590", "price": "0.108", "size": "40", "side": "SELL", "hash": "ec94103755323a450f64e078336d5551ef76bae3", "best_bid": "0.011", "best_ask": "0.013"}], "timestamp": "1769384186284", "event_type": "price_change"}}
{"_local_timestamp": "2026-01-25T23:36:26.446410+00:00", "data": {"market": "0x916bb8a256c4369c8c909c543e82a03d73a7fa15ee52c4a09b363c0a35c8d522", "price_changes": [{"asset_id": "52822071377528308915286289768941040938616825289625853907705142181024906754006", "price": "0.838", "size": "25", "side": "BUY", "hash": "9553f79ba9c41a31b98d4ec64651fef6f723f696", "best_bid": "0.955", "best_ask": "0.983"}, {"asset_id": "108935516272651260502928073006561933796317904485811751989800726817886684592061", "price": "0.162", "size": "25", "side": "SELL", "hash": "abb7b2a4489737c4bebe6ff142ae794254d829e7", "best_bid": "0.017", "best_ask": "0.045"}], "timestamp": "1769384186378", "event_type": "price_change"}}
{"_local_timestamp": "2026-01-25T23:36:26.446812+00:00", "data": {"market": "0x8c1937a09dc020e283538a3a04ea18445d626e023ac05d8fb763b132eadd289d", "price_changes": [{"asset_id": "103908283520007978422292376817533115820651896056215083252654661103131408613493", "price": "0.897", "size": "0", "side": "BUY", "hash": "50bd0b7ace1b25719e6c9cc22fab5371f1920450", "best_bid": "0.987", "best_ask": "0.989"}, {"asset_id": "51370447146650998467964273203513577067488238207603923199894457994024881064590", "price": "0.103", "size": "0", "side": "SELL", "hash": "6c49459e2727b497efd11fde6708556769bd3a9d", "best_bid": "0.011", "best_ask": "0.013"}], "timestamp": "1769384186378", "event_type": "price_change"}}
{"_local_timestamp": "2026-01-25T23:36:26.620833+00:00", "data": {"market": "0x916bb8a256c4369c8c909c543e82a03d73a7fa15ee52c4a09b363c0a35c8d522", "price_changes": [{"asset_id": "52822071377528308915286289768941040938616825289625853907705142181024906754006", "price": "0.838", "size": "20", "side": "BUY", "hash": "803f62c453a61be33b6214c1cd719eb992c4cec5", "best_bid": "0.955", "best_ask": "0.983"}, {"asset_id": "108935516272651260502928073006561933796317904485811751989800726817886684592061", "price": "0.162", "size": "20", "side": "SELL", "hash": "c856dd6fb8b174c7a51db71fcb024c024643d98a", "best_bid": "0.017", "best_ask": "0.045"}], "timestamp": "1769384186547", "event_type": "price_change"}}
{"_local_timestamp": "2026-01-25T23:36:26.746729+00:00", "data": {"market": "0x8c1937a09dc020e283538a3a04ea18445d626e023ac05d8fb763b132eadd289d", "price_changes": [{"asset_id": "103908283520007978422292376817533115820651896056215083252654661103131408613493", "price": "0.45", "size": "60", "side": "BUY", "hash": "2009c568fd8f266434ab22ee91b75f2fd666cefb", "best_bid": "0.987", "best_ask": "0.989"}, {"asset_id": "51370447146650998467964273203513577067488238207603923199894457994024881064590", "price": "0.55", "size": "60", "side": "SELL", "hash": "a222c4d2660364c51998f69c4947cfce02e635e3", "best_bid": "0.011", "best_ask": "0.013"}], "timestamp": "1769384186666", "event_type": "price_change"}}
{"_local_timestamp": "2026-01-25T23:36:26.788159+00:00", "data": {"market": "0x916bb8a256c4369c8c909c543e82a03d73a7fa15ee52c4a09b363c0a35c8d522", "price_changes": [{"asset_id": "52822071377528308915286289768941040938616825289625853907705142181024906754006", "price": "0.841", "size": "20", "side": "BUY", "hash": "43319d0b52b70dcc463cbc1a0d1f7ecd697752f3", "best_bid": "0.955", "best_ask": "0.983"}, {"asset_id": "108935516272651260502928073006561933796317904485811751989800726817886684592061", "price": "0.159", "size": "20", "side": "SELL", "hash": "f4dc91e3a070b0ef9214b07dbdae621181139dbc", "best_bid": "0.017", "best_ask": "0.045"}], "timestamp": "1769384186711", "event_type": "price_change"}}
{"_local_timestamp": "2026-01-25T23:36:26.788558+00:00", "data": {"market": "0x916bb8a256c4369c8c909c543e82a03d73a7fa15ee52c4a09b363c0a35c8d522", "price_changes": [{"asset_id": "52822071377528308915286289768941040938616825289625853907705142181024906754006", "price": "0.841", "size": "25", "side": "BUY", "hash": "cfd3df0c1eec065d97ac72d5b228bc5eabf61f78", "best_bid": "0.955", "best_ask": "0.983"}, {"asset_id": "108935516272651260502928073006561933796317904485811751989800726817886684592061", "price": "0.159", "size": "25", "side": "SELL", "hash": "e797ab39b754c2165764c7a941eac08411fcf4bd", "best_bid": "0.017", "best_ask": "0.045"}], "timestamp": "1769384186712", "event_type": "price_change"}}
{"_local_timestamp": "2026-01-25T23:36:26.960686+00:00", "data": {"market": "0xfd308e9c9c273fc4baf7560110dbe3bf4e1a07162f31655a0b5d997029c69cfb", "price_changes": [{"asset_id": "77063062487728149614774676568324164832607328044033753723737434149701536733938", "price": "0.812", "size": "0", "side": "BUY", "hash": "b99f2e83f62e03660a03e336c61d62efc5530d43", "best_bid": "0.962", "best_ask": "0.969"}, {"asset_id": "41987510269245635414350451702418306508832372599801516690841435038913020512760", "price": "0.188", "size": "0", "side": "SELL", "hash": "5497ece6eacc2fd59b570d8b73b273b56c57c918", "best_bid": "0.031", "best_ask": "0.038"}], "timestamp": "1769384186889", "event_type": "price_change"}}
{"_local_timestamp": "2026-01-25T23:36:27.127496+00:00", "data": {"market": "0xfd308e9c9c273fc4baf7560110dbe3bf4e1a07162f31655a0b5d997029c69cfb", "price_changes": [{"asset_id": "77063062487728149614774676568324164832607328044033753723737434149701536733938", "price": "0.815", "size": "5", "side": "BUY", "hash": "40dcc6fe2b82e1b22283c43bf2b816461f41c144", "best_bid": "0.962", "best_ask": "0.969"}, {"asset_id": "41987510269245635414350451702418306508832372599801516690841435038913020512760", "price": "0.185", "size": "5", "side": "SELL", "hash": "1d09bb5bbe64fd5b581f4430205c78761f066ca3", "best_bid": "0.031", "best_ask": "0.038"}], "timestamp": "1769384187016", "event_type": "price_change"}}
{"_local_timestamp": "2026-01-25T23:36:27.130645+00:00", "data": {"market": "0xfd308e9c9c273fc4baf7560110dbe3bf4e1a07162f31655a0b5d997029c69cfb", "price_changes": [{"asset_id": "77063062487728149614774676568324164832607328044033753723737434149701536733938", "price": "0.815", "size": "25", "side": "BUY", "hash": "8672cb172be06655885fb0a2c8169566e8c9a871", "best_bid": "0.962", "best_ask": "0.969"}, {"asset_id": "41987510269245635414350451702418306508832372599801516690841435038913020512760", "price": "0.185", "size": "25", "side": "SELL", "hash": "80042fd72402cddfb5ea3427db91b6c3f1d6be82", "best_bid": "0.031", "best_ask": "0.038"}], "timestamp": "1769384187018", "event_type": "price_change"}}
{"_local_timestamp": "2026-01-25T23:36:27.176700+00:00", "data": {"market": "0x8c1937a09dc020e283538a3a04ea18445d626e023ac05d8fb763b132eadd289d", "price_changes": [{"asset_id": "103908283520007978422292376817533115820651896056215083252654661103131408613493", "price": "0.841", "size": "0", "side": "BUY", "hash": "ef2a42d219acec4dd08c4ff298a3df292a7b7032", "best_bid": "0.987", "best_ask": "0.989"}, {"asset_id": "51370447146650998467964273203513577067488238207603923199894457994024881064590", "price": "0.159", "size": "0", "side": "SELL", "hash": "a648243fe45c74ee3eaab5c8e2a91fe2c855ac9d", "best_bid": "0.011", "best_ask": "0.013"}], "timestamp": "1769384187056", "event_type": "price_change"}}
{"_local_timestamp": "2026-01-25T23:36:27.234129+00:00", "data": {"market": "0x8c1937a09dc020e283538a3a04ea18445d626e023ac05d8fb763b132eadd289d", "price_changes": [{"asset_id": "103908283520007978422292376817533115820651896056215083252654661103131408613493", "price": "0.842", "size": "5", "side": "BUY", "hash": "6d93aa43fc1598fe6e7ceb0f961962f413fc69a4", "best_bid": "0.987", "best_ask": "0.989"}, {"asset_id": "51370447146650998467964273203513577067488238207603923199894457994024881064590", "price": "0.158", "size": "5", "side": "SELL", "hash": "99bc1b25d7ab6194bc3534c07beb62d621846329", "best_bid": "0.011", "best_ask": "0.013"}], "timestamp": "1769384187161", "event_type": "price_change"}}
{"_local_timestamp": "2026-01-25T23:36:27.234573+00:00", "data": {"market": "0x8c1937a09dc020e283538a3a04ea18445d626e023ac05d8fb763b132eadd289d", "price_changes": [{"asset_id": "103908283520007978422292376817533115820651896056215083252654661103131408613493", "price": "0.893", "size": "20", "side": "BUY", "hash": "0fd87487fb625f65ec76ef612bf455ca6cae4f10", "best_bid": "0.987", "best_ask": "0.989"}, {"asset_id": "51370447146650998467964273203513577067488238207603923199894457994024881064590", "price": "0.107", "size": "20", "side": "SELL", "hash": "f7a9fa644adfb2d6f36056d2fc876f8e8f475737", "best_bid": "0.011", "best_ask": "0.013"}], "timestamp": "1769384187162", "event_type": "price_change"}}
{"_local_timestamp": "2026-01-25T23:36:29.922384+00:00", "data": {"market": "0x8c1937a09dc020e283538a3a04ea18445d626e023ac05d8fb763b132eadd289d", "price_changes": [{"asset_id": "103908283520007978422292376817533115820651896056215083252654661103131408613493", "price": "0.898", "size": "0", "side": "BUY", "hash": "82403ef2ac7b6e81be226cdfefa7b41d37c07e64", "best_bid": "0.987", "best_ask": "0.989"}, {"asset_id": "51370447146650998467964273203513577067488238207603923199894457994024881064590", "price": "0.102", "size": "0", "side": "SELL", "hash": "0e3817f65728c97a5725a2258702ae225b76873a", "best_bid": "0.011", "best_ask": "0.013"}], "timestamp": "1769384189849", "event_type": "price_change"}}
{"_local_timestamp": "2026-01-25T23:36:29.922739+00:00", "data": {"market": "0xfd308e9c9c273fc4baf7560110dbe3bf4e1a07162f31655a0b5d997029c69cfb", "price_changes": [{"asset_id": "77063062487728149614774676568324164832607328044033753723737434149701536733938", "price": "0.814", "size": "0", "side": "BUY", "hash": "4504abb580aafb3367b1dc0956cea4118b2057df", "best_bid": "0.962", "best_ask": "0.969"}, {"asset_id": "41987510269245635414350451702418306508832372599801516690841435038913020512760", "price": "0.186", "size": "0", "side": "SELL", "hash": "61c2f19c3f146eb634fff02c7b24bb9536455333", "best_bid": "0.031", "best_ask": "0.038"}], "timestamp": "1769384189849", "event_type": "price_change"}}
{"_local_timestamp": "2026-01-25T23:36:29.923005+00:00", "data": {"market": "0x916bb8a256c4369c8c909c543e82a03d73a7fa15ee52c4a09b363c0a35c8d522", "price_changes": [{"asset_id": "52822071377528308915286289768941040938616825289625853907705142181024906754006", "price": "0.84", "size": "20", "side": "BUY", "hash": "68c5bbdbb9395d64d99f8ef51dbccefad34322df", "best_bid": "0.955", "best_ask": "0.983"}, {"asset_id": "108935516272651260502928073006561933796317904485811751989800726817886684592061", "price": "0.16", "size": "20", "side": "SELL", "hash": "aabccdcc3fa037b88af409b4ad1de8316af9581e", "best_bid": "0.017", "best_ask": "0.045"}], "timestamp": "1769384189849", "event_type": "price_change"}}
{"_local_timestamp": "2026-01-25T23:36:29.942907+00:00", "data": {"market": "0x8c1937a09dc020e283538a3a04ea18445d626e023ac05d8fb763b132eadd289d", "price_changes": [{"asset_id": "103908283520007978422292376817533115820651896056215083252654661103131408613493", "price": "0.894", "size": "20", "side": "BUY", "hash": "27ec11bf0134a7f6e75dbaa67dccf0cba996250e", "best_bid": "0.987", "best_ask": "0.989"}, {"asset_id": "51370447146650998467964273203513577067488238207603923199894457994024881064590", "price": "0.106", "size": "20", "side": "SELL", "hash": "e734c0a3673b2dc7ad5875f76e8547e20aefe526", "best_bid": "0.011", "best_ask": "0.013"}], "timestamp": "1769384189874", "event_type": "price_change"}}
{"_local_timestamp": "2026-01-25T23:36:29.943986+00:00", "data": {"market": "0x916bb8a256c4369c8c909c543e82a03d73a7fa15ee52c4a09b363c0a35c8d522", "price_changes": [{"asset_id": "52822071377528308915286289768941040938616825289625853907705142181024906754006", "price": "0.842", "size": "20", "side": "BUY", "hash": "0ef1e0f07f0c5392a88698f2182ad67fb2ebd32e", "best_bid": "0.955", "best_ask": "0.983"}, {"asset_id": "108935516272651260502928073006561933796317904485811751989800726817886684592061", "price": "0.158", "size": "20", "side": "SELL", "hash": "a3a393bd1b0f4436742e14d563ff61796dc0fc82", "best_bid": "0.017", "best_ask": "0.045"}], "timestamp": "1769384189874", "event_type": "price_change"}}
{"_local_timestamp": "2026-01-25T23:36:29.944326+00:00", "data": {"market": "0xfd308e9c9c273fc4baf7560110dbe3bf4e1a07162f31655a0b5d997029c69cfb", "price_changes": [{"asset_id": "77063062487728149614774676568324164832607328044033753723737434149701536733938", "price": "0.816", "size": "20", "side": "BUY", "hash": "3e5e7ab3193fdc6dbea89986e2669bcddb0ff6f4", "best_bid": "0.962", "best_ask": "0.969"}, {"asset_id": "41987510269245635414350451702418306508832372599801516690841435038913020512760", "price": "0.184", "size": "20", "side": "SELL", "hash": "c2a3218fbfc18ace2de2295ab6914e28830e990e", "best_bid": "0.031", "best_ask": "0.038"}], "timestamp": "1769384189875", "event_type": "price_change"}}
{"_local_timestamp": "2026-01-25T23:36:37.864485+00:00", "data": {"market": "0xc97a1d10a34399688ccea96d9a05db74135ff67dfee288c4d00379792dcf2011", "price_changes": [{"asset_id": "46295679083603787387508675043247351552210019749585109050272416293653337105685", "price": "0.15", "size": "25", "side": "BUY", "hash": "bfa02c37653e57f60b6f78b7bdb7c3481252507f", "best_bid": "0.16", "best_ask": "0.21"}, {"asset_id": "105499979175297845859286056968822861912891864044344906696929192748628753089258", "price": "0.85", "size": "25", "side": "SELL", "hash": "3faf759fe2f8a3747db884b8f548ea63da0b56e4", "best_bid": "0.79", "best_ask": "0.84"}], "timestamp": "1769384197785", "event_type": "price_change"}}
{"_local_timestamp": "2026-01-25T23:36:37.864940+00:00", "data": {"market": "0xc97a1d10a34399688ccea96d9a05db74135ff67dfee288c4d00379792dcf2011", "price_changes": [{"asset_id": "46295679083603787387508675043247351552210019749585109050272416293653337105685", "price": "0.14", "size": "20", "side": "BUY", "hash": "bfa02c37653e57f60b6f78b7bdb7c3481252507f", "best_bid": "0.16", "best_ask": "0.21"}, {"asset_id": "105499979175297845859286056968822861912891864044344906696929192748628753089258", "price": "0.86", "size": "20", "side": "SELL", "hash": "3faf759fe2f8a3747db884b8f548ea63da0b56e4", "best_bid": "0.79", "best_ask": "0.84"}], "timestamp": "1769384197785", "event_type": "price_change"}}
{"_local_timestamp": "2026-01-25T23:36:39.572890+00:00", "data": {"market": "0xc97a1d10a34399688ccea96d9a05db74135ff67dfee288c4d00379792dcf2011", "price_changes": [{"asset_id": "46295679083603787387508675043247351552210019749585109050272416293653337105685", "price": "0.16", "size": "26", "side": "BUY", "hash": "b6b9f07f2c35239c2ab5a1b2b24cbd13a4320c02", "best_bid": "0.16", "best_ask": "0.21"}, {"asset_id": "105499979175297845859286056968822861912891864044344906696929192748628753089258", "price": "0.84", "size": "26", "side": "SELL", "hash": "b7d1987ce1eaf2a933ed0e3390d951065f054139", "best_bid": "0.79", "best_ask": "0.84"}], "timestamp": "1769384199502", "event_type": "price_change"}}
{"_local_timestamp": "2026-01-25T23:36:39.633866+00:00", "data": {"market": "0xc97a1d10a34399688ccea96d9a05db74135ff67dfee288c4d00379792dcf2011", "price_changes": [{"asset_id": "46295679083603787387508675043247351552210019749585109050272416293653337105685", "price": "0.11", "size": "156.22", "side": "BUY", "hash": "674a418100185e75c823402e903866081abfe5dc", "best_bid": "0.16", "best_ask": "0.21"}, {"asset_id": "105499979175297845859286056968822861912891864044344906696929192748628753089258", "price": "0.89", "size": "156.22", "side": "SELL", "hash": "ff7b0f7d0575674e5145444bfa460dbc1c468f1c", "best_bid": "0.79", "best_ask": "0.84"}], "timestamp": "1769384199562", "event_type": "price_change"}}
{"_local_timestamp": "2026-01-25T23:36:55.745418+00:00", "data": {"market": "0x916bb8a256c4369c8c909c543e82a03d73a7fa15ee52c4a09b363c0a35c8d522", "price_changes": [{"asset_id": "52822071377528308915286289768941040938616825289625853907705142181024906754006", "price": "0.39", "size": "126.28", "side": "BUY", "hash": "5e51a08b342e19914eb2f73beedf611db549c5f7", "best_bid": "0.955", "best_ask": "0.983"}, {"asset_id": "108935516272651260502928073006561933796317904485811751989800726817886684592061", "price": "0.61", "size": "126.28", "side": "SELL", "hash": "1dc444f32d0eac258f5c8e6338d52d9b2fcf86df", "best_bid": "0.017", "best_ask": "0.045"}], "timestamp": "1769384215600", "event_type": "price_change"}}
{"_local_timestamp": "2026-01-25T23:37:26.274673+00:00", "data": {"market": "0xc97a1d10a34399688ccea96d9a05db74135ff67dfee288c4d00379792dcf2011", "price_changes": [{"asset_id": "105499979175297845859286056968822861912891864044344906696929192748628753089258", "price": "0.32", "size": "50", "side": "BUY", "hash": "b00307773a4057025583b19eeb232c5a8bad37d8", "best_bid": "0.79", "best_ask": "0.84"}, {"asset_id": "46295679083603787387508675043247351552210019749585109050272416293653337105685", "price": "0.68", "size": "50", "side": "SELL", "hash": "11a659b9400ce011bfe03324de5f9e3dae5a512a", "best_bid": "0.16", "best_ask": "0.21"}], "timestamp": "1769384246196", "event_type": "price_change"}}
{"_local_timestamp": "2026-01-25T23:37:26.275058+00:00", "data": {"market": "0xc97a1d10a34399688ccea96d9a05db74135ff67dfee288c4d00379792dcf2011", "price_changes": [{"asset_id": "105499979175297845859286056968822861912891864044344906696929192748628753089258", "price": "0.33", "size": "0", "side": "BUY", "hash": "b00307773a4057025583b19eeb232c5a8bad37d8", "best_bid": "0.79", "best_ask": "0.84"}, {"asset_id": "46295679083603787387508675043247351552210019749585109050272416293653337105685", "price": "0.67", "size": "0", "side": "SELL", "hash": "11a659b9400ce011bfe03324de5f9e3dae5a512a", "best_bid": "0.16", "best_ask": "0.21"}], "timestamp": "1769384246196", "event_type": "price_change"}}
{"_local_timestamp": "2026-01-25T23:37:46.720979+00:00", "data": {"market": "0xc97a1d10a34399688ccea96d9a05db74135ff67dfee288c4d00379792dcf2011", "price_changes": [{"asset_id": "46295679083603787387508675043247351552210019749585109050272416293653337105685", "price": "0.14", "size": "210", "side": "BUY", "hash": "dfbede2c478b73b07da587da5e580bc0e8320586", "best_bid": "0.16", "best_ask": "0.21"}, {"asset_id": "105499979175297845859286056968822861912891864044344906696929192748628753089258", "price": "0.86", "size": "210", "side": "SELL", "hash": "fda1760646acdac7ab325a005a64411b48eaa6eb", "best_bid": "0.79", "best_ask": "0.84"}], "timestamp": "1769384266640", "event_type": "price_change"}}
{"_local_timestamp": "2026-01-25T23:37:46.721353+00:00", "data": {"market": "0x9e97d6ca3294a0b34044822dae868b116356e442fe23a2e9120d86aa2566285b", "price_changes": [{"asset_id": "19253153737967360829902330593318407456391424226199683250300283492574668236154", "price": "0.81", "size": "235", "side": "BUY", "hash": "fa187afe03fda6ce535a8e7224375cdb8ca4ef52", "best_bid": "0.85", "best_ask": "0.89"}, {"asset_id": "13023509041598257520776296029419758530591111697952522984734378906708885744269", "price": "0.19", "size": "235", "side": "SELL", "hash": "bcb20a48960896c9f99919f1c53f67ead70e0e0c", "best_bid": "0.11", "best_ask": "0.15"}], "timestamp": "1769384266641", "event_type": "price_change"}}
{"_local_timestamp": "2026-01-25T23:37:46.721638+00:00", "data": {"market": "0xc97a1d10a34399688ccea96d9a05db74135ff67dfee288c4d00379792dcf2011", "price_changes": [{"asset_id": "46295679083603787387508675043247351552210019749585109050272416293653337105685", "price": "0.15", "size": "215", "side": "BUY", "hash": "a3ea87aecb8546ce3e34290059a5866e183c08b4", "best_bid": "0.16", "best_ask": "0.21"}, {"asset_id": "105499979175297845859286056968822861912891864044344906696929192748628753089258", "price": "0.85", "size": "215", "side": "SELL", "hash": "52544cc1a8aedcf543cc39cd09b21d92cfc46f43", "best_bid": "0.79", "best_ask": "0.84"}], "timestamp": "1769384266641", "event_type": "price_change"}}
{"_local_timestamp": "2026-01-25T23:37:47.314078+00:00", "data": {"market": "0xc97a1d10a34399688ccea96d9a05db74135ff67dfee288c4d00379792dcf2011", "price_changes": [{"asset_id": "46295679083603787387508675043247351552210019749585109050272416293653337105685", "price": "0.11", "size": "126.22", "side": "BUY", "hash": "5a6d2fbf4d7d3a9d02a21b2d53575aa01baeadfa", "best_bid": "0.16", "best_ask": "0.21"}, {"asset_id": "105499979175297845859286056968822861912891864044344906696929192748628753089258", "price": "0.89", "size": "126.22", "side": "SELL", "hash": "506ded6048296c0383db0e0ce34783f9024db9f3", "best_bid": "0.79", "best_ask": "0.84"}], "timestamp": "1769384267242", "event_type": "price_change"}}
{"_local_timestamp": "2026-01-25T23:37:47.373108+00:00", "data": {"market": "0xc97a1d10a34399688ccea96d9a05db74135ff67dfee288c4d00379792dcf2011", "price_changes": [{"asset_id": "46295679083603787387508675043247351552210019749585109050272416293653337105685", "price": "0.16", "size": "56", "side": "BUY", "hash": "daa01817ee659db261ee8ae302a1eab25d9feee1", "best_bid": "0.16", "best_ask": "0.21"}, {"asset_id": "105499979175297845859286056968822861912891864044344906696929192748628753089258", "price": "0.84", "size": "56", "side": "SELL", "hash": "55de66c67ead63a8bd3edae5119b722bc70897ee", "best_bid": "0.79", "best_ask": "0.84"}], "timestamp": "1769384267299", "event_type": "price_change"}}
{"_local_timestamp": "2026-01-25T23:38:00.510289+00:00", "data": {"market": "0xc97a1d10a34399688ccea96d9a05db74135ff67dfee288c4d00379792dcf2011", "price_changes": [{"asset_id": "105499979175297845859286056968822861912891864044344906696929192748628753089258", "price": "0.33", "size": "150", "side": "BUY", "hash": "703b62fd7114cb3e65d3dd5ee829ba1a82647568", "best_bid": "0.79", "best_ask": "0.84"}, {"asset_id": "46295679083603787387508675043247351552210019749585109050272416293653337105685", "price": "0.67", "size": "150", "side": "SELL", "hash": "ee85cb45320f55b3ecfa63084fdaf0970d3a7885", "best_bid": "0.16", "best_ask": "0.21"}], "timestamp": "1769384280433", "event_type": "price_change"}}
{"_local_timestamp": "2026-01-25T23:38:00.510689+00:00", "data": {"market": "0xc97a1d10a34399688ccea96d9a05db74135ff67dfee288c4d00379792dcf2011", "price_changes": [{"asset_id": "105499979175297845859286056968822861912891864044344906696929192748628753089258", "price": "0.32", "size": "750", "side": "BUY", "hash": "76ddbeb5c05267d173e02b800521a1df5ee6cc00", "best_bid": "0.79", "best_ask": "0.84"}, {"asset_id": "46295679083603787387508675043247351552210019749585109050272416293653337105685", "price": "0.68", "size": "750", "side": "SELL", "hash": "4ad47aec30e49904f9a332bc22c5fe0cf169f7a1", "best_bid": "0.16", "best_ask": "0.21"}], "timestamp": "1769384280434", "event_type": "price_change"}}
{"_local_timestamp": "2026-01-25T23:38:06.724827+00:00", "data": {"market": "0xc97a1d10a34399688ccea96d9a05db74135ff67dfee288c4d00379792dcf2011", "price_changes": [{"asset_id": "46295679083603787387508675043247351552210019749585109050272416293653337105685", "price": "0.15", "size": "25", "side": "BUY", "hash": "b0293da552aa063e93dae7abbbaf70050cdefd25", "best_bid": "0.16", "best_ask": "0.21"}, {"asset_id": "105499979175297845859286056968822861912891864044344906696929192748628753089258", "price": "0.85", "size": "25", "side": "SELL", "hash": "fe31618bc0391630281f39487362d03d51e2a0cc", "best_bid": "0.79", "best_ask": "0.84"}], "timestamp": "1769384286654", "event_type": "price_change"}}
{"_local_timestamp": "2026-01-25T23:38:06.725253+00:00", "data": {"market": "0xc97a1d10a34399688ccea96d9a05db74135ff67dfee288c4d00379792dcf2011", "price_changes": [{"asset_id": "46295679083603787387508675043247351552210019749585109050272416293653337105685", "price": "0.14", "size": "20", "side": "BUY", "hash": "b0293da552aa063e93dae7abbbaf70050cdefd25", "best_bid": "0.16", "best_ask": "0.21"}, {"asset_id": "105499979175297845859286056968822861912891864044344906696929192748628753089258", "price": "0.86", "size": "20", "side": "SELL", "hash": "fe31618bc0391630281f39487362d03d51e2a0cc", "best_bid": "0.79", "best_ask": "0.84"}], "timestamp": "1769384286654", "event_type": "price_change"}}
{"_local_timestamp": "2026-01-25T23:38:06.802064+00:00", "data": {"market": "0xc97a1d10a34399688ccea96d9a05db74135ff67dfee288c4d00379792dcf2011", "price_changes": [{"asset_id": "46295679083603787387508675043247351552210019749585109050272416293653337105685", "price": "0.16", "size": "26", "side": "BUY", "hash": "74b7931bc3298e48df33ee5bb64c8980ca613e36", "best_bid": "0.16", "best_ask": "0.21"}, {"asset_id": "105499979175297845859286056968822861912891864044344906696929192748628753089258", "price": "0.84", "size": "26", "side": "SELL", "hash": "46cb1d994354fb031692a186c39ac079a0d1cab1", "best_bid": "0.79", "best_ask": "0.84"}], "timestamp": "1769384286724", "event_type": "price_change"}}
{"_local_timestamp": "2026-01-25T23:38:06.874553+00:00", "data": {"market": "0xc97a1d10a34399688ccea96d9a05db74135ff67dfee288c4d00379792dcf2011", "price_changes": [{"asset_id": "46295679083603787387508675043247351552210019749585109050272416293653337105685", "price": "0.11", "size": "156.22", "side": "BUY", "hash": "63f8d9030a77de86a9b09a27ea659556e047d1c3", "best_bid": "0.16", "best_ask": "0.21"}, {"asset_id": "105499979175297845859286056968822861912891864044344906696929192748628753089258", "price": "0.89", "size": "156.22", "side": "SELL", "hash": "91a94b60883d442abf020007371789f6d730cbb0", "best_bid": "0.79", "best_ask": "0.84"}], "timestamp": "1769384286790", "event_type": "price_change"}}
{"_local_timestamp": "2026-01-25T23:38:29.720596+00:00", "data": {"market": "0x9e97d6ca3294a0b34044822dae868b116356e442fe23a2e9120d86aa2566285b", "price_changes": [{"asset_id": "19253153737967360829902330593318407456391424226199683250300283492574668236154", "price": "0.81", "size": "45", "side": "BUY", "hash": "f390b2ccb3bc8b1e33e59fe983b191f22dc28d41", "best_bid": "0.85", "best_ask": "0.89"}, {"asset_id": "13023509041598257520776296029419758530591111697952522984734378906708885744269", "price": "0.19", "size": "45", "side": "SELL", "hash": "0685ae2414d9e5a53a4d9043080a1c4a1f91a862", "best_bid": "0.11", "best_ask": "0.15"}], "timestamp": "1769384309620", "event_type": "price_change"}}
{"_local_timestamp": "2026-01-25T23:39:22.275196+00:00", "data": {"market": "0x8c1937a09dc020e283538a3a04ea18445d626e023ac05d8fb763b132eadd289d", "price_changes": [{"asset_id": "103908283520007978422292376817533115820651896056215083252654661103131408613493", "price": "0.45", "size": "0", "side": "BUY", "hash": "2606e32ed33b2036542aff1dd52651653f74ca63", "best_bid": "0.987", "best_ask": "0.989"}, {"asset_id": "51370447146650998467964273203513577067488238207603923199894457994024881064590", "price": "0.55", "size": "0", "side": "SELL", "hash": "e69b40e820481db6da77f76c9bcf8f1b931b963b", "best_bid": "0.011", "best_ask": "0.013"}], "timestamp": "1769384362184", "event_type": "price_change"}}
{"_local_timestamp": "2026-01-25T23:39:22.766182+00:00", "data": {"market": "0x8c1937a09dc020e283538a3a04ea18445d626e023ac05d8fb763b132eadd289d", "price_changes": [{"asset_id": "103908283520007978422292376817533115820651896056215083252654661103131408613493", "price": "0.4", "size": "125", "side": "BUY", "hash": "ec6b97b3ad9d3df2b131c4464cce410039c31ef2", "best_bid": "0.987", "best_ask": "0.989"}, {"asset_id": "51370447146650998467964273203513577067488238207603923199894457994024881064590", "price": "0.6", "size": "125", "side": "SELL", "hash": "1c14ae0d27e91df95cd1184c9399e970479c91b9", "best_bid": "0.011", "best_ask": "0.013"}], "timestamp": "1769384362682", "event_type": "price_change"}}
