{"_local_timestamp": "2026-01-25T23:40:31.447649+00:00", "data": [{"market": "0xafeb856581303e0d248192f2aed941ab52b972b2f4c249d850ee49e0b73f1e0a", "asset_id": "3345017119039865108601589077873396828255638656156390928287117391771035074364", "timestamp": "1769384362720", "hash": "06b584f1ea2929b23fd5d5e4092170e6265a7475", "bids": [{"price": "0.001", "size": "987744.99"}, {"price": "0.002", "size": "1250"}, {"price": "0.003", "size": "1172.62"}, {"price": "0.006", "size": "83"}, {"price": "0.007", "size": "9.76"}, {"price": "0.01", "size": "301500"}, {"price": "0.011", "size": "950"}, {"price": "0.02", "size": "50"}, {"price": "0.021", "size": "9.02"}, {"price": "0.05", "size": "460"}, {"price": "0.051", "size": "39"}, {"price": "0.061", "size": "32"}, {"price": "0.062", "size": "8.68"}, {"price": "0.1", "size": "570"}, {"price": "0.15", "size": "551.66"}, {"price": "0.2", "size": "465"}, {"price": "0.201", "size": "2487"}, {"price": "0.202", "size": "9"}, {"price": "0.203", "size": "5.78"}, {"price": "0.25", "size": "112"}, {"price": "0.251", "size": "150"}, {"price": "0.3", "size": "86.66"}, {"price": "0.35", "size": "68.57"}, {"price": "0.4", "size": "125"}, {"price": "0.76", "size": "5000"}, {"price": "0.762", "size": "700"}, {"price": "0.9", "size": "300"}, {"price": "0.908", "size": "500"}, {"price": "0.909", "size": "30"}, {"price": "0.92", "size": "850"}, {"price": "0.924", "size": "30"}, {"price": "0.926", "size": "30"}, {"price": "0.927", "size": "20"}, {"price": "0.958", "size": "500"}, {"price": "0.98", "size": "100"}, {"price": "0.982", "size": "1000"}, {"price": "0.983", "size": "5080.89"}, {"price": "0.985", "size": "40"}, {"price": "0.989", "size": "188"}, {"price": "0.99", "size": "1553.89"}, {"price": "0.991", "size": "2815.83"}, {"price": "0.992", "size": "269.99"}, {"price": "0.993", "size": "400"}, {"price": "0.994", "size": "5362"}, {"price": "0.995", "size": "3605.49"}], "asks": [{"price": "0.999", "size": "203333.44"}, {"price": "0.998", "size": "255398.33"}, {"price": "0.997", "size": "33583.33"}, {"price": "0.996", "size": "7160.94"}], "event_type": "book", "last_trade_price": "0.004"}, {"market": "0x7dd03775ae64ca4da06121fd75397e3a16cd54bd02a52faee8c22799e34b8458", "asset_id": "19610288044512445018970900383394598704429716248417831382102395080716996421422", "timestamp": "1769384406041", "hash": "a9412ec885041ce6d09107fa2fc9c8e2fd374bb0", "bids": [{"price": "0.001", "size": "389209"}, {"price": "0.002", "size": "32308.08"}, {"price": "0.003", "size": "26574.33"}, {"price": "0.004", "size": "8737.75"}, {"price": "0.005", "size": "2768"}, {"price": "0.006", "size": "683.59"}, {"price": "0.007", "size": "1177.6"}, {"price": "0.008", "size": "627.04"}], "asks": [{"price": "0.999", "size": "2007808.99"}, {"price": "0.998", "size": "1001250"}, {"price": "0.997", "size": "401400"}, {"price": "0.996", "size": "8.65"}, {"price": "0.994", "size": "200"}, {"price": "0.99", "size": "4600"}, {"price": "0.989", "size": "11.31"}, {"price": "0.98", "size": "2500"}, {"price": "0.971", "size": "200700"}, {"price": "0.964", "size": "26000"}, {"price": "0.963", "size": "5.3"}, {"price": "0.962", "size": "60000"}, {"price": "0.96", "size": "1250"}, {"price": "0.959", "size": "40000"}, {"price": "0.95", "size": "30"}, {"price": "0.949", "size": "39"}, {"price": "0.94", "size": "500"}, {"price": "0.939", "size": "40200"}, {"price": "0.92", "size": "250"}, {"price": "0.919", "size": "5.95"}, {"price": "0.9", "size": "360"}, {"price": "0.85", "size": "551.66"}, {"price": "0.84", "size": "3613.69"}, {"price": "0.8", "size": "180"}, {"price": "0.796", "size": "12000"}, {"price": "0.793", "size": "20000"}, {"price": "0.792", "size": "250"}, {"price": "0.791", "size": "2392"}, {"price": "0.79", "size": "5.46"}, {"price": "0.75", "size": "112"}, {"price": "0.749", "size": "150"}, {"price": "0.7", "size": "86.66"}, {"price": "0.65", "size": "68.57"}, {"price": "0.6", "size": "125"}, {"price": "0.224", "size": "2438.68"}, {"price": "0.221", "size": "823.97"}, {"price": "0.22", "size": "10000"}, {"price": "0.175", "size": "28.57"}, {"price": "0.174", "size": "30"}, {"price": "0.099", "size": "431.1"}, {"price": "0.087", "size": "2524.68"}, {"price": "0.085", "size": "30"}, {"price": "0.082", "size": "988.89"}, {"price": "0.08", "size": "3850"}, {"price": "0.075", "size": "374.94"}, {"price": "0.072", "size": "988.88"}, {"price": "0.071", "size": "500"}, {"price": "0.065", "size": "437.77"}, {"price": "0.064", "size": "20"}, {"price": "0.054", "size": "1090.34"}, {"price": "0.049", "size": "300"}, {"price": "0.046", "size": "2560"}, {"price": "0.044", "size": "392.39"}, {"price": "0.043", "size": "309.89"}, {"price": "0.037", "size": "1030.77"}, {"price": "0.03", "size": "669.48"}, {"price": "0.029", "size": "20"}, {"price": "0.026", "size": "1022.29"}, {"price": "0.025", "size": "700"}, {"price": "0.02", "size": "378.89"}, {"price": "0.019", "size": "3281.95"}, {"price": "0.018", "size": "1139"}, {"price": "0.017", "size": "218.6"}, {"price": "0.015", "size": "400"}, {"price": "0.011", "size": "66.6"}, {"price": "0.01", "size": "358.26"}, {"price": "0.009", "size": "1166.79"}], "event_type": "book", "last_trade_price": "0.008"}, {"market": "0x28a1883267fbae3ecb536c0476e3477b744428e9ae50a106d1702cade00794c1", "asset_id": "46346923635040896127384018253032931511241098773389246647292829092182793974150", "timestamp": "1769384401135", "hash": "a7b8943d1d3a847d9e99d31a74debe5d08b1cd40", "bids": [{"price": "0.001", "size": "818145.99"}, {"price": "0.002", "size": "1250"}, {"price": "0.003", "size": "1172.62"}, {"price": "0.004", "size": "5000"}, {"price": "0.006", "size": "83"}, {"price": "0.007", "size": "9.76"}, {"price": "0.01", "size": "200"}, {"price": "0.012", "size": "50000"}, {"price": "0.013", "size": "950"}, {"price": "0.02", "size": "50"}, {"price": "0.021", "size": "9.02"}, {"price": "0.05", "size": "460"}, {"price": "0.051", "size": "39"}, {"price": "0.061", "size": "32"}, {"price": "0.062", "size": "8.79"}, {"price": "0.1", "size": "570"}, {"price": "0.15", "size": "551.66"}, {"price": "0.2", "size": "515"}, {"price": "0.201", "size": "2487"}, {"price": "0.202", "size": "9"}, {"price": "0.203", "size": "5.75"}, {"price": "0.25", "size": "262"}, {"price": "0.3", "size": "86.66"}, {"price": "0.35", "size": "68.57"}, {"price": "0.4", "size": "125"}, {"price": "0.75", "size": "2427.76"}, {"price": "0.752", "size": "5000"}, {"price": "0.846", "size": "2000"}, {"price": "0.866", "size": "30"}, {"price": "0.867", "size": "30"}, {"price": "0.868", "size": "30"}, {"price": "0.92", "size": "1350"}, {"price": "0.921", "size": "20"}, {"price": "0.959", "size": "2000"}, {"price": "0.973", "size": "600"}, {"price": "0.982", "size": "200"}, {"price": "0.983", "size": "3000"}, {"price": "0.988", "size": "12585.31"}, {"price": "0.99", "size": "100"}, {"price": "0.992", "size": "125"}, {"price": "0.995", "size": "1555.62"}, {"price": "0.996", "size": "4201.94"}], "asks": [{"price": "0.999", "size": "400053.74"}, {"price": "0.998", "size": "259980.09"}], "event_type": "book", "last_trade_price": "0.002"}, {"market": "0x101c26a9ff336abf4dffeb109dc40b92d9f55882dd471e57ee875794a6561bf3", "asset_id": "41909517390337506269578561946393939690952797212331290191404935145632561531096", "timestamp": "1769384427337", "hash": "93de3d9b3e771a11c8bd125963f26c9cba1df904", "bids": [{"price": "0.001", "size": "905904.03"}, {"price": "0.002", "size": "1250"}, {"price": "0.003", "size": "1406.64"}, {"price": "0.004", "size": "1001300"}, {"price": "0.005", "size": "400000"}, {"price": "0.006", "size": "200"}, {"price": "0.007", "size": "9.79"}, {"price": "0.01", "size": "5150"}, {"price": "0.02", "size": "2550"}, {"price": "0.021", "size": "12.99"}, {"price": "0.04", "size": "1250"}, {"price": "0.048", "size": "15000"}, {"price": "0.049", "size": "30400"}, {"price": "0.05", "size": "50"}, {"price": "0.051", "size": "39"}, {"price": "0.06", "size": "500"}, {"price": "0.08", "size": "250"}, {"price": "0.081", "size": "6"}, {"price": "0.092", "size": "6200"}, {"price": "0.1", "size": "370"}, {"price": "0.15", "size": "551.66"}, {"price": "0.151", "size": "300"}, {"price": "0.2", "size": "9415"}, {"price": "0.201", "size": "300"}, {"price": "0.209", "size": "200"}, {"price": "0.21", "size": "5.43"}, {"price": "0.23", "size": "5750"}, {"price": "0.233", "size": "6150"}, {"price": "0.241", "size": "58"}, {"price": "0.25", "size": "112"}, {"price": "0.29", "size": "89.65"}, {"price": "0.33", "size": "1500"}, {"price": "0.34", "size": "770.58"}, {"price": "0.341", "size": "5"}, {"price": "0.39", "size": "126.28"}, {"price": "0.542", "size": "432.4"}, {"price": "0.644", "size": "605.49"}, {"price": "0.645", "size": "465"}, {"price": "0.714", "size": "465.97"}, {"price": "0.755", "size": "40"}, {"price": "0.82", "size": "7"}, {"price": "0.844", "size": "75.58"}, {"price": "0.85", "size": "200"}, {"price": "0.851", "size": "876.64"}, {"price": "0.863", "size": "465.1"}, {"price": "0.875", "size": "52.45"}, {"price": "0.882", "size": "1156.53"}, {"price": "0.885", "size": "69.07"}, {"price": "0.89", "size": "3850"}, {"price": "0.893", "size": "509.98"}, {"price": "0.895", "size": "752.64"}, {"price": "0.899", "size": "61.27"}, {"price": "0.9", "size": "10"}, {"price": "0.901", "size": "60"}, {"price": "0.917", "size": "150"}, {"price": "0.919", "size": "571.52"}, {"price": "0.92", "size": "699.97"}, {"price": "0.921", "size": "325"}, {"price": "0.923", "size": "45.53"}, {"price": "0.924", "size": "20"}, {"price": "0.929", "size": "718.57"}, {"price": "0.931", "size": "2000"}, {"price": "0.934", "size": "1213.62"}, {"price": "0.937", "size": "385.3"}, {"price": "0.94", "size": "75"}, {"price": "0.942", "size": "300"}, {"price": "0.943", "size": "276.97"}, {"price": "0.946", "size": "39.99"}, {"price": "0.948", "size": "1230.01"}, {"price": "0.95", "size": "41.01"}, {"price": "0.954", "size": "70"}, {"price": "0.955", "size": "140"}, {"price": "0.96", "size": "400"}, {"price": "0.962", "size": "174.37"}, {"price": "0.963", "size": "174.37"}, {"price": "0.964", "size": "1461.01"}, {"price": "0.965", "size": "302.56"}, {"price": "0.966", "size": "264"}, {"price": "0.967", "size": "176"}, {"price": "0.968", "size": "712.2"}, {"price": "0.969", "size": "270"}, {"price": "0.97", "size": "71.14"}, {"price": "0.973", "size": "100"}, {"price": "0.974", "size": "20"}, {"price": "0.975", "size": "100"}], "asks": [{"price": "0.999", "size": "219881"}, {"price": "0.998", "size": "212506.25"}, {"price": "0.997", "size": "19.01"}, {"price": "0.996", "size": "648.55"}, {"price": "0.995", "size": "13987.13"}, {"price": "0.994", "size": "10250"}, {"price": "0.993", "size": "926.9"}, {"price": "0.992", "size": "30500"}, {"price": "0.991", "size": "20000"}, {"price": "0.99", "size": "9607.39"}, {"price": "0.989", "size": "7942.82"}, {"price": "0.988", "size": "250"}, {"price": "0.987", "size": "3126.54"}, {"price": "0.986", "size": "500"}, {"price": "0.985", "size": "2076.1"}, {"price": "0.984", "size": "4369.16"}, {"price": "0.983", "size": "1011.8"}, {"price": "0.982", "size": "449.6"}, {"price": "0.981", "size": "350"}, {"price": "0.98", "size": "300"}, {"price": "0.979", "size": "200"}, {"price": "0.978", "size": "157.2"}, {"price": "0.977", "size": "43.04"}, {"price": "0.976", "size": "0.27"}], "event_type": "book", "last_trade_price": "0.976"}, {"market": "0x66af911f31ceabb5f9a3ef9203a73f0b23d18aa81bbba7888dec440c622c2528", "asset_id": "101818439776033928818471919550932857351051302350112396692573347503051307979709", "timestamp": "1769384427623", "hash": "5d4f127d937a1ff72f6545dba0cb57d9c307ac29", "bids": [{"price": "0.01", "size": "316490.59"}, {"price": "0.02", "size": "32571.42"}, {"price": "0.03", "size": "50445.97"}, {"price": "0.04", "size": "6050"}, {"price": "0.05", "size": "800.73"}, {"price": "0.06", "size": "625"}, {"price": "0.08", "size": "1545.92"}, {"price": "0.09", "size": "1671.83"}, {"price": "0.1", "size": "10"}, {"price": "0.12", "size": "20"}, {"price": "0.13", "size": "1700"}, {"price": "0.14", "size": "1555"}, {"price": "0.15", "size": "70"}, {"price": "0.16", "size": "5.27"}, {"price": "0.17", "size": "547.53"}, {"price": "0.18", "size": "57.82"}, {"price": "0.2", "size": "82.82"}, {"price": "0.21", "size": "1111"}, {"price": "0.22", "size": "3850"}, {"price": "0.23", "size": "311.13"}, {"price": "0.24", "size": "1358.82"}, {"price": "0.25", "size": "210"}, {"price": "0.26", "size": "46"}, {"price": "0.27", "size": "138.53"}, {"price": "0.28", "size": "5275.31"}, {"price": "0.29", "size": "3049.08"}, {"price": "0.3", "size": "908.37"}], "asks": [{"price": "0.99", "size": "114990"}, {"price": "0.98", "size": "32400"}, {"price": "0.97", "size": "7006.66"}, {"price": "0.96", "size": "1000"}, {"price": "0.95", "size": "1000"}, {"price": "0.93", "size": "514.28"}, {"price": "0.9", "size": "5225"}, {"price": "0.89", "size": "309.09"}, {"price": "0.88", "size": "3325"}, {"price": "0.86", "size": "250"}, {"price": "0.85", "size": "213.33"}, {"price": "0.84", "size": "1000"}, {"price": "0.82", "size": "180"}, {"price": "0.81", "size": "147.36"}, {"price": "0.8", "size": "2250"}, {"price": "0.79", "size": "2098"}, {"price": "0.77", "size": "113.04"}, {"price": "0.75", "size": "500"}, {"price": "0.74", "size": "92.3"}, {"price": "0.7", "size": "66.66"}, {"price": "0.69", "size": "30"}, {"price": "0.67", "size": "5"}, {"price": "0.66", "size": "1500"}, {"price": "0.65", "size": "1553"}, {"price": "0.6", "size": "10"}, {"price": "0.55", "size": "800"}, {"price": "0.54", "size": "7.85"}, {"price": "0.5", "size": "1005"}, {"price": "0.49", "size": "1000"}, {"price": "0.48", "size": "1000"}, {"price": "0.47", "size": "1255"}, {"price": "0.45", "size": "750"}, {"price": "0.44", "size": "3000"}, {"price": "0.43", "size": "1.72"}, {"price": "0.4", "size": "10"}, {"price": "0.39", "size": "5850"}, {"price": "0.38", "size": "1311"}, {"price": "0.37", "size": "2500"}, {"price": "0.36", "size": "1000"}, {"price": "0.35", "size": "1348.26"}, {"price": "0.34", "size": "8405.43"}, {"price": "0.33", "size": "5342.05"}, {"price": "0.32", "size": "5664.54"}, {"price": "0.31", "size": "61.12"}], "event_type": "book", "last_trade_price": "0.700"}, {"market": "0xd405c18b0df642e7f06aadf359183cb8208c1ff6b3a3bca3f8206dca2eb9532e", "asset_id": "69810463519685390977705287406030999283280450973077240059184219530164978871715", "timestamp": "1769384402052", "hash": "62db637d0841f54b9bfb1e16cf406490c324fe3b", "bids": [{"price": "0.001", "size": "6107028.06"}, {"price": "0.002", "size": "401257.56"}, {"price": "0.003", "size": "1400"}, {"price": "0.004", "size": "3000"}, {"price": "0.005", "size": "6.98"}, {"price": "0.006", "size": "200"}, {"price": "0.01", "size": "5050"}, {"price": "0.011", "size": "12000"}, {"price": "0.012", "size": "8.09"}, {"price": "0.02", "size": "2550"}, {"price": "0.03", "size": "50000"}, {"price": "0.031", "size": "90400"}, {"price": "0.032", "size": "6.93"}, {"price": "0.04", "size": "1250"}, {"price": "0.041", "size": "30000"}, {"price": "0.05", "size": "50"}, {"price": "0.051", "size": "39"}, {"price": "0.06", "size": "7500"}, {"price": "0.061", "size": "30200"}, {"price": "0.08", "size": "250"}, {"price": "0.081", "size": "5.65"}, {"price": "0.09", "size": "400"}, {"price": "0.1", "size": "10"}, {"price": "0.14", "size": "242.85"}, {"price": "0.15", "size": "4825"}, {"price": "0.151", "size": "12000"}, {"price": "0.155", "size": "10000"}, {"price": "0.156", "size": "550"}, {"price": "0.157", "size": "300"}, {"price": "0.19", "size": "168.42"}, {"price": "0.191", "size": "200"}, {"price": "0.2", "size": "1055"}, {"price": "0.201", "size": "5.81"}, {"price": "0.24", "size": "116.66"}, {"price": "0.242", "size": "1111"}, {"price": "0.243", "size": "1878"}, {"price": "0.29", "size": "89.65"}, {"price": "0.33", "size": "72.72"}, {"price": "0.38", "size": "552.63"}, {"price": "0.4", "size": "4000"}, {"price": "0.459", "size": "1555"}, {"price": "0.466", "size": "700"}, {"price": "0.467", "size": "1289"}, {"price": "0.468", "size": "701"}, {"price": "0.5", "size": "10"}, {"price": "0.692", "size": "85.95"}, {"price": "0.7", "size": "13"}, {"price": "0.75", "size": "20"}, {"price": "0.751", "size": "213.28"}, {"price": "0.79", "size": "20"}, {"price": "0.808", "size": "171.89"}, {"price": "0.837", "size": "294.11"}, {"price": "0.838", "size": "363.62"}, {"price": "0.841", "size": "210"}, {"price": "0.855", "size": "263.28"}, {"price": "0.86", "size": "48.24"}, {"price": "0.866", "size": "104.16"}, {"price": "0.869", "size": "208.33"}, {"price": "0.88", "size": "3850"}, {"price": "0.882", "size": "30"}, {"price": "0.883", "size": "20"}, {"price": "0.888", "size": "30"}, {"price": "0.89", "size": "64"}, {"price": "0.891", "size": "39.89"}, {"price": "0.892", "size": "30"}, {"price": "0.9", "size": "100"}, {"price": "0.905", "size": "330.45"}, {"price": "0.911", "size": "720.23"}, {"price": "0.912", "size": "2000"}, {"price": "0.913", "size": "70"}, {"price": "0.921", "size": "1200"}, {"price": "0.922", "size": "500"}, {"price": "0.923", "size": "681.64"}, {"price": "0.928", "size": "100"}, {"price": "0.93", "size": "400"}, {"price": "0.932", "size": "411.1"}, {"price": "0.933", "size": "25"}], "asks": [{"price": "0.999", "size": "53788"}, {"price": "0.998", "size": "6007.11"}, {"price": "0.997", "size": "3000"}, {"price": "0.996", "size": "2222"}, {"price": "0.995", "size": "14.47"}, {"price": "0.99", "size": "550"}, {"price": "0.989", "size": "1000"}, {"price": "0.988", "size": "100"}, {"price": "0.986", "size": "10000"}, {"price": "0.985", "size": "8000"}, {"price": "0.984", "size": "1361"}, {"price": "0.981", "size": "1000"}, {"price": "0.98", "size": "551"}, {"price": "0.979", "size": "5.4"}, {"price": "0.974", "size": "161.33"}, {"price": "0.972", "size": "1833"}, {"price": "0.97", "size": "68"}, {"price": "0.965", "size": "3529"}, {"price": "0.963", "size": "15475.35"}, {"price": "0.962", "size": "1027"}, {"price": "0.961", "size": "1821.02"}, {"price": "0.96", "size": "318"}, {"price": "0.959", "size": "2200"}, {"price": "0.958", "size": "1445.64"}, {"price": "0.954", "size": "400"}, {"price": "0.953", "size": "1341.3"}, {"price": "0.952", "size": "800"}, {"price": "0.947", "size": "52"}, {"price": "0.945", "size": "100"}, {"price": "0.943", "size": "210"}, {"price": "0.942", "size": "209.12"}, {"price": "0.94", "size": "16"}, {"price": "0.938", "size": "289.85"}, {"price": "0.937", "size": "289.85"}, {"price": "0.936", "size": "689.85"}, {"price": "0.935", "size": "754.58"}], "event_type": "book", "last_trade_price": "0.065"}, {"market": "0xd405c18b0df642e7f06aadf359183cb8208c1ff6b3a3bca3f8206dca2eb9532e", "asset_id": "17781966920345001333694873962725544399622962807536262226327461471000709887625", "timestamp": "1769384402052", "hash": "e3660ac212a84139075f7ebd7e3e71c138c6490c", "bids": [{"price": "0.001", "size": "53788"}, {"price": "0.002", "size": "6007.11"}, {"price": "0.003", "size": "3000"}, {"price": "0.004", "size": "2222"}, {"price": "0.005", "size": "14.47"}, {"price": "0.01", "size": "550"}, {"price": "0.011", "size": "1000"}, {"price": "0.012", "size": "100"}, {"price": "0.014", "size": "10000"}, {"price": "0.015", "size": "8000"}, {"price": "0.016", "size": "1361"}, {"price": "0.019", "size": "1000"}, {"price": "0.02", "size": "551"}, {"price": "0.021", "size": "5.4"}, {"price": "0.026", "size": "161.33"}, {"price": "0.028", "size": "1833"}, {"price": "0.03", "size": "68"}, {"price": "0.035", "size": "3529"}, {"price": "0.037", "size": "15475.35"}, {"price": "0.038", "size": "1027"}, {"price": "0.039", "size": "1821.02"}, {"price": "0.04", "size": "318"}, {"price": "0.041", "size": "2200"}, {"price": "0.042", "size": "1445.64"}, {"price": "0.046", "size": "400"}, {"price": "0.047", "size": "1341.3"}, {"price": "0.048", "size": "800"}, {"price": "0.053", "size": "52"}, {"price": "0.055", "size": "100"}, {"price": "0.057", "size": "210"}, {"price": "0.058", "size": "209.12"}, {"price": "0.06", "size": "16"}, {"price": "0.062", "size": "289.85"}, {"price": "0.063", "size": "289.85"}, {"price": "0.064", "size": "689.85"}, {"price": "0.065", "size": "754.58"}], "asks": [{"price": "0.999", "size": "6107028.06"}, {"price": "0.998", "size": "401257.56"}, {"price": "0.997", "size": "1400"}, {"price": "0.996", "size": "3000"}, {"price": "0.995", "size": "6.98"}, {"price": "0.994", "size": "200"}, {"price": "0.99", "size": "5050"}, {"price": "0.989", "size": "12000"}, {"price": "0.988", "size": "8.09"}, {"price": "0.98", "size": "2550"}, {"price": "0.97", "size": "50000"}, {"price": "0.969", "size": "90400"}, {"price": "0.968", "size": "6.93"}, {"price": "0.96", "size": "1250"}, {"price": "0.959", "size": "30000"}, {"price": "0.95", "size": "50"}, {"price": "0.949", "size": "39"}, {"price": "0.94", "size": "7500"}, {"price": "0.939", "size": "30200"}, {"price": "0.92", "size": "250"}, {"price": "0.919", "size": "5.65"}, {"price": "0.91", "size": "400"}, {"price": "0.9", "size": "10"}, {"price": "0.86", "size": "242.85"}, {"price": "0.85", "size": "4825"}, {"price": "0.849", "size": "12000"}, {"price": "0.845", "size": "10000"}, {"price": "0.844", "size": "550"}, {"price": "0.843", "size": "300"}, {"price": "0.81", "size": "168.42"}, {"price": "0.809", "size": "200"}, {"price": "0.8", "size": "1055"}, {"price": "0.799", "size": "5.81"}, {"price": "0.76", "size": "116.66"}, {"price": "0.758", "size": "1111"}, {"price": "0.757", "size": "1878"}, {"price": "0.71", "size": "89.65"}, {"price": "0.67", "size": "72.72"}, {"price": "0.62", "size": "552.63"}, {"price": "0.6", "size": "4000"}, {"price": "0.541", "size": "1555"}, {"price": "0.534", "size": "700"}, {"price": "0.533", "size": "1289"}, {"price": "0.532", "size": "701"}, {"price": "0.5", "size": "10"}, {"price": "0.308", "size": "85.95"}, {"price": "0.3", "size": "13"}, {"price": "0.25", "size": "20"}, {"price": "0.249", "size": "213.28"}, {"price": "0.21", "size": "20"}, {"price": "0.192", "size": "171.89"}, {"price": "0.163", "size": "294.11"}, {"price": "0.162", "size": "363.62"}, {"price": "0.159", "size": "210"}, {"price": "0.145", "size": "263.28"}, {"price": "0.14", "size": "48.24"}, {"price": "0.134", "size": "104.16"}, {"price": "0.131", "size": "208.33"}, {"price": "0.12", "size": "3850"}, {"price": "0.118", "size": "30"}, {"price": "0.117", "size": "20"}, {"price": "0.112", "size": "30"}, {"price": "0.11", "size": "64"}, {"price": "0.109", "size": "39.89"}, {"price": "0.108", "size": "30"}, {"price": "0.1", "size": "100"}, {"price": "0.095", "size": "330.45"}, {"price": "0.089", "size": "720.23"}, {"price": "0.088", "size": "2000"}, {"price": "0.087", "size": "70"}, {"price": "0.079", "size": "1200"}, {"price": "0.078", "size": "500"}, {"price": "0.077", "size": "681.64"}, {"price": "0.072", "size": "100"}, {"price": "0.07", "size": "400"}, {"price": "0.068", "size": "411.1"}, {"price": "0.067", "size": "25"}], "event_type": "book", "last_trade_price": "0.065"}, {"market": "0xd87ac5bb74a21061d4f223d2a83c0269607fcb6d4c74d5a3d3220209d089431a", "asset_id": "63433408040190943973509092025756868743192149481060781851142321049882584518043", "timestamp": "1769384427622", "hash": "633ac12acd1ae42d130c7aef226d12a0ab2a1aab", "bids": [{"price": "0.001", "size": "204181"}, {"price": "0.002", "size": "21000"}, {"price": "0.003", "size": "6555"}, {"price": "0.004", "size": "10.48"}, {"price": "0.007", "size": "2000"}, {"price": "0.008", "size": "4444"}, {"price": "0.01", "size": "15550"}, {"price": "0.011", "size": "5500"}, {"price": "0.014", "size": "2041.07"}, {"price": "0.015", "size": "3333"}, {"price": "0.021", "size": "1945.23"}, {"price": "0.022", "size": "3000"}, {"price": "0.027", "size": "2200"}, {"price": "0.028", "size": "2922"}, {"price": "0.029", "size": "500"}, {"price": "0.03", "size": "110.96"}, {"price": "0.032", "size": "900"}, {"price": "0.033", "size": "500"}, {"price": "0.041", "size": "5000"}, {"price": "0.042", "size": "3333"}, {"price": "0.043", "size": "250"}, {"price": "0.05", "size": "85"}, {"price": "0.052", "size": "99.88"}, {"price": "0.06", "size": "700"}, {"price": "0.062", "size": "68"}, {"price": "0.064", "size": "50"}, {"price": "0.1", "size": "1424.45"}, {"price": "0.101", "size": "2500"}, {"price": "0.121", "size": "555"}, {"price": "0.128", "size": "5"}, {"price": "0.14", "size": "3850"}, {"price": "0.143", "size": "555"}, {"price": "0.151", "size": "1000"}, {"price": "0.16", "size": "50"}, {"price": "0.166", "size": "200"}, {"price": "0.17", "size": "2750.53"}, {"price": "0.172", "size": "500"}, {"price": "0.175", "size": "2200.01"}, {"price": "0.178", "size": "900"}, {"price": "0.179", "size": "384.42"}, {"price": "0.18", "size": "2042.3"}, {"price": "0.182", "size": "1500"}, {"price": "0.183", "size": "402.75"}, {"price": "0.184", "size": "78.64"}, {"price": "0.185", "size": "15"}, {"price": "0.187", "size": "210"}, {"price": "0.191", "size": "436.62"}, {"price": "0.192", "size": "24.54"}, {"price": "0.193", "size": "400"}], "asks": [{"price": "0.999", "size": "2005804.68"}, {"price": "0.998", "size": "1001250"}, {"price": "0.997", "size": "501405.31"}, {"price": "0.996", "size": "1001300"}, {"price": "0.995", "size": "400000"}, {"price": "0.994", "size": "205.26"}, {"price": "0.99", "size": "5150"}, {"price": "0.989", "size": "9000"}, {"price": "0.988", "size": "12.24"}, {"price": "0.98", "size": "2500"}, {"price": "0.97", "size": "50000"}, {"price": "0.969", "size": "90400"}, {"price": "0.96", "size": "1275"}, {"price": "0.959", "size": "5.13"}, {"price": "0.95", "size": "30"}, {"price": "0.949", "size": "39"}, {"price": "0.94", "size": "500"}, {"price": "0.92", "size": "700"}, {"price": "0.917", "size": "20000"}, {"price": "0.916", "size": "20000"}, {"price": "0.915", "size": "40200"}, {"price": "0.914", "size": "5.67"}, {"price": "0.879", "size": "20325"}, {"price": "0.876", "size": "7500"}, {"price": "0.875", "size": "10000"}, {"price": "0.87", "size": "261.53"}, {"price": "0.869", "size": "555"}, {"price": "0.83", "size": "188.23"}, {"price": "0.829", "size": "934"}, {"price": "0.8", "size": "2811.87"}, {"price": "0.799", "size": "5000"}, {"price": "0.798", "size": "9000"}, {"price": "0.797", "size": "555"}, {"price": "0.79", "size": "133.33"}, {"price": "0.789", "size": "5.19"}, {"price": "0.75", "size": "604"}, {"price": "0.749", "size": "4150"}, {"price": "0.745", "size": "250"}, {"price": "0.743", "size": "555"}, {"price": "0.742", "size": "1626"}, {"price": "0.71", "size": "82.75"}, {"price": "0.7", "size": "500"}, {"price": "0.66", "size": "58.82"}, {"price": "0.65", "size": "250"}, {"price": "0.64", "size": "1000"}, {"price": "0.61", "size": "930"}, {"price": "0.58", "size": "1000"}, {"price": "0.578", "size": "555"}, {"price": "0.577", "size": "900.89"}, {"price": "0.55", "size": "310"}, {"price": "0.45", "size": "750"}, {"price": "0.439", "size": "555"}, {"price": "0.437", "size": "555"}, {"price": "0.436", "size": "531"}, {"price": "0.318", "size": "333"}, {"price": "0.31", "size": "3850"}, {"price": "0.309", "size": "555"}, {"price": "0.299", "size": "297.1"}, {"price": "0.287", "size": "1000"}, {"price": "0.286", "size": "60"}, {"price": "0.285", "size": "30"}, {"price": "0.25", "size": "73.11"}, {"price": "0.248", "size": "30"}, {"price": "0.247", "size": "20"}, {"price": "0.24", "size": "20"}, {"price": "0.236", "size": "1000"}, {"price": "0.23", "size": "500"}, {"price": "0.229", "size": "320"}, {"price": "0.225", "size": "2000"}, {"price": "0.222", "size": "20"}, {"price": "0.22", "size": "8612.94"}, {"price": "0.213", "size": "70"}, {"price": "0.21", "size": "300"}, {"price": "0.209", "size": "20"}, {"price": "0.208", "size": "318.74"}, {"price": "0.206", "size": "123.49"}, {"price": "0.203", "size": "40"}, {"price": "0.202", "size": "459.53"}, {"price": "0.2", "size": "90"}, {"price": "0.199", "size": "20.7"}, {"price": "0.198", "size": "10"}], "event_type": "book", "last_trade_price": "0.806"}, {"market": "0x4d594c1480eab1db09f6c04c089f92d0a45844bdfae32a6f3f8391f99a1ea081", "asset_id": "70660622350061788470958401793650083315253654094558831635926320178723816495171", "timestamp": "1769384347654", "hash": "7697fb1a2145b1b62b415e9baf943e1d28f1d274", "bids": [{"price": "0.001", "size": "355157"}, {"price": "0.002", "size": "75500"}, {"price": "0.003", "size": "8038"}, {"price": "0.004", "size": "9720.63"}, {"price": "0.005", "size": "13272.22"}, {"price": "0.006", "size": "12489.06"}, {"price": "0.007", "size": "1863.37"}, {"price": "0.008", "size": "540.38"}], "asks": [{"price": "0.999", "size": "2006933.01"}, {"price": "0.998", "size": "1001255.7"}, {"price": "0.997", "size": "1400"}, {"price": "0.996", "size": "8.66"}, {"price": "0.994", "size": "200"}, {"price": "0.99", "size": "4500"}, {"price": "0.989", "size": "5.3"}, {"price": "0.98", "size": "2500"}, {"price": "0.978", "size": "12400"}, {"price": "0.977", "size": "11.43"}, {"price": "0.96", "size": "1250"}, {"price": "0.95", "size": "30"}, {"price": "0.949", "size": "39"}, {"price": "0.942", "size": "30000"}, {"price": "0.941", "size": "60300"}, {"price": "0.94", "size": "500"}, {"price": "0.939", "size": "16000"}, {"price": "0.938", "size": "30200"}, {"price": "0.92", "size": "250"}, {"price": "0.919", "size": "5.62"}, {"price": "0.9", "size": "360"}, {"price": "0.86", "size": "50"}, {"price": "0.85", "size": "551.66"}, {"price": "0.847", "size": "12000"}, {"price": "0.846", "size": "250"}, {"price": "0.8", "size": "410"}, {"price": "0.799", "size": "5.83"}, {"price": "0.75", "size": "262"}, {"price": "0.7", "size": "86.66"}, {"price": "0.65", "size": "68.57"}, {"price": "0.6", "size": "50"}, {"price": "0.59", "size": "4100"}, {"price": "0.589", "size": "3000"}, {"price": "0.585", "size": "1999.97"}, {"price": "0.576", "size": "6000"}, {"price": "0.575", "size": "1236"}, {"price": "0.574", "size": "5"}, {"price": "0.573", "size": "30"}, {"price": "0.2", "size": "1607.74"}, {"price": "0.15", "size": "50"}, {"price": "0.139", "size": "1009.84"}, {"price": "0.136", "size": "30"}, {"price": "0.135", "size": "30"}, {"price": "0.1", "size": "814.97"}, {"price": "0.099", "size": "1037.11"}, {"price": "0.098", "size": "205"}, {"price": "0.082", "size": "1110"}, {"price": "0.08", "size": "3850"}, {"price": "0.075", "size": "1069.83"}, {"price": "0.064", "size": "1366.15"}, {"price": "0.063", "size": "20"}, {"price": "0.049", "size": "617.14"}, {"price": "0.046", "size": "109.97"}, {"price": "0.039", "size": "1122.63"}, {"price": "0.033", "size": "1786.26"}, {"price": "0.03", "size": "1072.75"}, {"price": "0.029", "size": "90"}, {"price": "0.027", "size": "1421.54"}, {"price": "0.026", "size": "2273"}, {"price": "0.025", "size": "1328.14"}, {"price": "0.023", "size": "711.34"}, {"price": "0.02", "size": "1212.52"}, {"price": "0.019", "size": "1111.85"}, {"price": "0.017", "size": "5653.65"}, {"price": "0.016", "size": "1544.86"}, {"price": "0.015", "size": "1426.44"}, {"price": "0.014", "size": "2139.67"}, {"price": "0.012", "size": "5069.63"}, {"price": "0.011", "size": "2128.19"}, {"price": "0.01", "size": "202.89"}], "event_type": "book", "last_trade_price": "0.008"}, {"market": "0x9ec16fa75bc05ef9f9fd786f7122bdec55e708586cee5cbe059fc1b297bead17", "asset_id": "103339433306132630766710426332122099286931745435609856808611744116246970634275", "timestamp": "1769384377719", "hash": "9be0a21299783a81e21ca05ac1e40212f7ce9417", "bids": [{"price": "0.001", "size": "355495"}, {"price": "0.002", "size": "26925.01"}, {"price": "0.003", "size": "12552.59"}, {"price": "0.004", "size": "11688.77"}], "asks": [{"price": "0.999", "size": "2007009.02"}, {"price": "0.998", "size": "1001257.5"}, {"price": "0.997", "size": "501400"}, {"price": "0.996", "size": "90000"}, {"price": "0.995", "size": "5.94"}, {"price": "0.994", "size": "30200"}, {"price": "0.99", "size": "4500"}, {"price": "0.989", "size": "9.63"}, {"price": "0.98", "size": "2550"}, {"price": "0.979", "size": "300700"}, {"price": "0.977", "size": "200000"}, {"price": "0.971", "size": "29000"}, {"price": "0.968", "size": "90000"}, {"price": "0.967", "size": "6.53"}, {"price": "0.96", "size": "1250"}, {"price": "0.95", "size": "30"}, {"price": "0.949", "size": "39"}, {"price": "0.94", "size": "500"}, {"price": "0.925", "size": "9200"}, {"price": "0.924", "size": "250"}, {"price": "0.92", "size": "250"}, {"price": "0.919", "size": "5.63"}, {"price": "0.9", "size": "360"}, {"price": "0.85", "size": "551.66"}, {"price": "0.8", "size": "410"}, {"price": "0.799", "size": "5.83"}, {"price": "0.75", "size": "262"}, {"price": "0.7", "size": "86.66"}, {"price": "0.65", "size": "68.57"}, {"price": "0.6", "size": "50"}, {"price": "0.56", "size": "1641"}, {"price": "0.558", "size": "1000"}, {"price": "0.552", "size": "20000"}, {"price": "0.551", "size": "1173"}, {"price": "0.55", "size": "5"}, {"price": "0.21", "size": "76.92"}, {"price": "0.209", "size": "1223.1"}, {"price": "0.208", "size": "30"}, {"price": "0.11", "size": "120"}, {"price": "0.1", "size": "500"}, {"price": "0.085", "size": "210"}, {"price": "0.08", "size": "3850"}, {"price": "0.079", "size": "583.9"}, {"price": "0.067", "size": "30"}, {"price": "0.066", "size": "30"}, {"price": "0.057", "size": "8.48"}, {"price": "0.056", "size": "20"}, {"price": "0.049", "size": "402.2"}, {"price": "0.036", "size": "1028.23"}, {"price": "0.035", "size": "500"}, {"price": "0.034", "size": "205"}, {"price": "0.033", "size": "290"}, {"price": "0.031", "size": "256.65"}, {"price": "0.03", "size": "250"}, {"price": "0.029", "size": "20"}, {"price": "0.024", "size": "555.99"}, {"price": "0.023", "size": "300"}, {"price": "0.02", "size": "250"}, {"price": "0.019", "size": "35.5"}, {"price": "0.016", "size": "40"}, {"price": "0.015", "size": "3699.81"}, {"price": "0.012", "size": "185"}, {"price": "0.011", "size": "100"}, {"price": "0.01", "size": "629.34"}, {"price": "0.009", "size": "1400"}, {"price": "0.008", "size": "1956.33"}, {"price": "0.007", "size": "3747.52"}, {"price": "0.006", "size": "125"}], "event_type": "book", "last_trade_price": "0.004"}, {"market": "0x9ec16fa75bc05ef9f9fd786f7122bdec55e708586cee5cbe059fc1b297bead17", "asset_id": "103445653913688204590429827609754970098059947043034813689371477999077756154403", "timestamp": "1769384377719", "hash": "583ba20df0da8b5f0db2056e07fa84dcedf45d89", "bids": [{"price": "0.001", "size": "2007009.02"}, {"price": "0.002", "size": "1001257.5"}, {"price": "0.003", "size": "501400"}, {"price": "0.004", "size": "90000"}, {"price": "0.005", "size": "5.94"}, {"price": "0.006", "size": "30200"}, {"price": "0.01", "size": "4500"}, {"price": "0.011", "size": "9.63"}, {"price": "0.02", "size": "2550"}, {"price": "0.021", "size": "300700"}, {"price": "0.023", "size": "200000"}, {"price": "0.029", "size": "29000"}, {"price": "0.032", "size": "90000"}, {"price": "0.033", "size": "6.53"}, {"price": "0.04", "size": "1250"}, {"price": "0.05", "size": "30"}, {"price": "0.051", "size": "39"}, {"price": "0.06", "size": "500"}, {"price": "0.075", "size": "9200"}, {"price": "0.076", "size": "250"}, {"price": "0.08", "size": "250"}, {"price": "0.081", "size": "5.63"}, {"price": "0.1", "size": "360"}, {"price": "0.15", "size": "551.66"}, {"price": "0.2", "size": "410"}, {"price": "0.201", "size": "5.83"}, {"price": "0.25", "size": "262"}, {"price": "0.3", "size": "86.66"}, {"price": "0.35", "size": "68.57"}, {"price": "0.4", "size": "50"}, {"price": "0.44", "size": "1641"}, {"price": "0.442", "size": "1000"}, {"price": "0.448", "size": "20000"}, {"price": "0.449", "size": "1173"}, {"price": "0.45", "size": "5"}, {"price": "0.79", "size": "76.92"}, {"price": "0.791", "size": "1223.1"}, {"price": "0.792", "size": "30"}, {"price": "0.89", "size": "120"}, {"price": "0.9", "size": "500"}, {"price": "0.915", "size": "210"}, {"price": "0.92", "size": "3850"}, {"price": "0.921", "size": "583.9"}, {"price": "0.933", "size": "30"}, {"price": "0.934", "size": "30"}, {"price": "0.943", "size": "8.48"}, {"price": "0.944", "size": "20"}, {"price": "0.951", "size": "402.2"}, {"price": "0.964", "size": "1028.23"}, {"price": "0.965", "size": "500"}, {"price": "0.966", "size": "205"}, {"price": "0.967", "size": "290"}, {"price": "0.969", "size": "256.65"}, {"price": "0.97", "size": "250"}, {"price": "0.971", "size": "20"}, {"price": "0.976", "size": "555.99"}, {"price": "0.977", "size": "300"}, {"price": "0.98", "size": "250"}, {"price": "0.981", "size": "35.5"}, {"price": "0.984", "size": "40"}, {"price": "0.985", "size": "3699.81"}, {"price": "0.988", "size": "185"}, {"price": "0.989", "size": "100"}, {"price": "0.99", "size": "629.34"}, {"price": "0.991", "size": "1400"}, {"price": "0.992", "size": "1956.33"}, {"price": "0.993", "size": "3747.52"}, {"price": "0.994", "size": "125"}], "asks": [{"price": "0.999", "size": "355495"}, {"price": "0.998", "size": "26925.01"}, {"price": "0.997", "size": "12552.59"}, {"price": "0.996", "size": "11688.77"}], "event_type": "book", "last_trade_price": "0.004"}, {"market": "0xe0266da952c7be95f42d76770972075b57ac3823f876a4967b9a696bf7f77cb3", "asset_id": "101410416660845748603825473080512476735733815308377998129165131061476869070298", "timestamp": "1769384402052", "hash": "6615f88484f6634d9955a3a1905c8d3af0526778", "bids": [{"price": "0.001", "size": "609172.98"}, {"price": "0.002", "size": "1850"}, {"price": "0.003", "size": "1266"}, {"price": "0.004", "size": "40107.42"}, {"price": "0.005", "size": "100"}, {"price": "0.006", "size": "183"}, {"price": "0.007", "size": "100"}, {"price": "0.008", "size": "100"}, {"price": "0.009", "size": "100"}, {"price": "0.01", "size": "205.35"}, {"price": "0.011", "size": "77"}, {"price": "0.02", "size": "50"}, {"price": "0.021", "size": "9.02"}, {"price": "0.05", "size": "460"}, {"price": "0.051", "size": "39"}, {"price": "0.061", "size": "32"}, {"price": "0.062", "size": "8.89"}, {"price": "0.1", "size": "570"}, {"price": "0.15", "size": "551.66"}, {"price": "0.2", "size": "615"}, {"price": "0.202", "size": "5000"}, {"price": "0.205", "size": "5.66"}, {"price": "0.25", "size": "262"}, {"price": "0.251", "size": "1992"}, {"price": "0.252", "size": "7"}, {"price": "0.3", "size": "86.66"}, {"price": "0.35", "size": "68.57"}, {"price": "0.4", "size": "125"}, {"price": "0.5", "size": "10"}, {"price": "0.75", "size": "2427.76"}, {"price": "0.751", "size": "5000"}, {"price": "0.83", "size": "100"}, {"price": "0.87", "size": "100"}, {"price": "0.871", "size": "30"}, {"price": "0.895", "size": "500"}, {"price": "0.9", "size": "2000"}, {"price": "0.908", "size": "1000"}, {"price": "0.92", "size": "850"}, {"price": "0.924", "size": "30"}, {"price": "0.925", "size": "30"}, {"price": "0.945", "size": "100"}, {"price": "0.946", "size": "400"}, {"price": "0.947", "size": "20"}, {"price": "0.96", "size": "379.96"}, {"price": "0.975", "size": "1000"}, {"price": "0.976", "size": "1000"}, {"price": "0.977", "size": "20"}, {"price": "0.98", "size": "100"}, {"price": "0.985", "size": "9185.6"}, {"price": "0.99", "size": "200"}, {"price": "0.993", "size": "2061.85"}, {"price": "0.994", "size": "269.26"}, {"price": "0.995", "size": "980.72"}, {"price": "0.996", "size": "1300.5"}, {"price": "0.997", "size": "7253.12"}], "asks": [{"price": "0.999", "size": "339114.73"}, {"price": "0.998", "size": "79230.5"}], "event_type": "book", "last_trade_price": "0.002"}, {"market": "0x7dd03775ae64ca4da06121fd75397e3a16cd54bd02a52faee8c22799e34b8458", "asset_id": "101607178899252540003647394903771939183206092960905788946883703746586650017054", "timestamp": "1769384406041", "hash": "0078d74335b637a403355cd6cb61798e325c42ef", "bids": [{"price": "0.001", "size": "2007808.99"}, {"price": "0.002", "size": "1001250"}, {"price": "0.003", "size": "401400"}, {"price": "0.004", "size": "8.65"}, {"price": "0.006", "size": "200"}, {"price": "0.01", "size": "4600"}, {"price": "0.011", "size": "11.31"}, {"price": "0.02", "size": "2500"}, {"price": "0.029", "size": "200700"}, {"price": "0.036", "size": "26000"}, {"price": "0.037", "size": "5.3"}, {"price": "0.038", "size": "60000"}, {"price": "0.04", "size": "1250"}, {"price": "0.041", "size": "40000"}, {"price": "0.05", "size": "30"}, {"price": "0.051", "size": "39"}, {"price": "0.06", "size": "500"}, {"price": "0.061", "size": "40200"}, {"price": "0.08", "size": "250"}, {"price": "0.081", "size": "5.95"}, {"price": "0.1", "size": "360"}, {"price": "0.15", "size": "551.66"}, {"price": "0.16", "size": "3613.69"}, {"price": "0.2", "size": "180"}, {"price": "0.204", "size": "12000"}, {"price": "0.207", "size": "20000"}, {"price": "0.208", "size": "250"}, {"price": "0.209", "size": "2392"}, {"price": "0.21", "size": "5.46"}, {"price": "0.25", "size": "112"}, {"price": "0.251", "size": "150"}, {"price": "0.3", "size": "86.66"}, {"price": "0.35", "size": "68.57"}, {"price": "0.4", "size": "125"}, {"price": "0.776", "size": "2438.68"}, {"price": "0.779", "size": "823.97"}, {"price": "0.78", "size": "10000"}, {"price": "0.825", "size": "28.57"}, {"price": "0.826", "size": "30"}, {"price": "0.901", "size": "431.1"}, {"price": "0.913", "size": "2524.68"}, {"price": "0.915", "size": "30"}, {"price": "0.918", "size": "988.89"}, {"price": "0.92", "size": "3850"}, {"price": "0.925", "size": "374.94"}, {"price": "0.928", "size": "988.88"}, {"price": "0.929", "size": "500"}, {"price": "0.935", "size": "437.77"}, {"price": "0.936", "size": "20"}, {"price": "0.946", "size": "1090.34"}, {"price": "0.951", "size": "300"}, {"price": "0.954", "size": "2560"}, {"price": "0.956", "size": "392.39"}, {"price": "0.957", "size": "309.89"}, {"price": "0.963", "size": "1030.77"}, {"price": "0.97", "size": "669.48"}, {"price": "0.971", "size": "20"}, {"price": "0.974", "size": "1022.29"}, {"price": "0.975", "size": "700"}, {"price": "0.98", "size": "378.89"}, {"price": "0.981", "size": "3281.95"}, {"price": "0.982", "size": "1139"}, {"price": "0.983", "size": "218.6"}, {"price": "0.985", "size": "400"}, {"price": "0.989", "size": "66.6"}, {"price": "0.99", "size": "358.26"}, {"price": "0.991", "size": "1166.79"}], "asks": [{"price": "0.999", "size": "389209"}, {"price": "0.998", "size": "32308.08"}, {"price": "0.997", "size": "26574.33"}, {"price": "0.996", "size": "8737.75"}, {"price": "0.995", "size": "2768"}, {"price": "0.994", "size": "683.59"}, {"price": "0.993", "size": "1177.6"}, {"price": "0.992", "size": "627.04"}], "event_type": "book", "last_trade_price": "0.008"}, {"market": "0x28a1883267fbae3ecb536c0476e3477b744428e9ae50a106d1702cade00794c1", "asset_id": "101383755724139778378831136472149622688860725550235845907721143637668252085044", "timestamp": "1769384401135", "hash": "ee69d439b97ab8f0a5afbfd60c4ce0a33cdcb924", "bids": [{"price": "0.001", "size": "400053.74"}, {"price": "0.002", "size": "259980.09"}], "asks": [{"price": "0.999", "size": "818145.99"}, {"price": "0.998", "size": "1250"}, {"price": "0.997", "size": "1172.62"}, {"price": "0.996", "size": "5000"}, {"price": "0.994", "size": "83"}, {"price": "0.993", "size": "9.76"}, {"price": "0.99", "size": "200"}, {"price": "0.988", "size": "50000"}, {"price": "0.987", "size": "950"}, {"price": "0.98", "size": "50"}, {"price": "0.979", "size": "9.02"}, {"price": "0.95", "size": "460"}, {"price": "0.949", "size": "39"}, {"price": "0.939", "size": "32"}, {"price": "0.938", "size": "8.79"}, {"price": "0.9", "size": "570"}, {"price": "0.85", "size": "551.66"}, {"price": "0.8", "size": "515"}, {"price": "0.799", "size": "2487"}, {"price": "0.798", "size": "9"}, {"price": "0.797", "size": "5.75"}, {"price": "0.75", "size": "262"}, {"price": "0.7", "size": "86.66"}, {"price": "0.65", "size": "68.57"}, {"price": "0.6", "size": "125"}, {"price": "0.25", "size": "2427.76"}, {"price": "0.248", "size": "5000"}, {"price": "0.154", "size": "2000"}, {"price": "0.134", "size": "30"}, {"price": "0.133", "size": "30"}, {"price": "0.132", "size": "30"}, {"price": "0.08", "size": "1350"}, {"price": "0.079", "size": "20"}, {"price": "0.041", "size": "2000"}, {"price": "0.027", "size": "600"}, {"price": "0.018", "size": "200"}, {"price": "0.017", "size": "3000"}, {"price": "0.012", "size": "12585.31"}, {"price": "0.01", "size": "100"}, {"price": "0.008", "size": "125"}, {"price": "0.005", "size": "1555.62"}, {"price": "0.004", "size": "4201.94"}], "event_type": "book", "last_trade_price": "0.002"}, {"market": "0xd87ac5bb74a21061d4f223d2a83c0269607fcb6d4c74d5a3d3220209d089431a", "asset_id": "73459237018178325517511938237778014293974381812181153063276727733805928508002", "timestamp": "1769384427622", "hash": "46d03986e5c8df2ee9e71b71d3f5965eef748f27", "bids": [{"price": "0.001", "size": "2005804.68"}, {"price": "0.002", "size": "1001250"}, {"price": "0.003", "size": "501405.31"}, {"price": "0.004", "size": "1001300"}, {"price": "0.005", "size": "400000"}, {"price": "0.006", "size": "205.26"}, {"price": "0.01", "size": "5150"}, {"price": "0.011", "size": "9000"}, {"price": "0.012", "size": "12.24"}, {"price": "0.02", "size": "2500"}, {"price": "0.03", "size": "50000"}, {"price": "0.031", "size": "90400"}, {"price": "0.04", "size": "1275"}, {"price": "0.041", "size": "5.13"}, {"price": "0.05", "size": "30"}, {"price": "0.051", "size": "39"}, {"price": "0.06", "size": "500"}, {"price": "0.08", "size": "700"}, {"price": "0.083", "size": "20000"}, {"price": "0.084", "size": "20000"}, {"price": "0.085", "size": "40200"}, {"price": "0.086", "size": "5.67"}, {"price": "0.121", "size": "20325"}, {"price": "0.124", "size": "7500"}, {"price": "0.125", "size": "10000"}, {"price": "0.13", "size": "261.53"}, {"price": "0.131", "size": "555"}, {"price": "0.17", "size": "188.23"}, {"price": "0.171", "size": "934"}, {"price": "0.2", "size": "2811.87"}, {"price": "0.201", "size": "5000"}, {"price": "0.202", "size": "9000"}, {"price": "0.203", "size": "555"}, {"price": "0.21", "size": "133.33"}, {"price": "0.211", "size": "5.19"}, {"price": "0.25", "size": "604"}, {"price": "0.251", "size": "4150"}, {"price": "0.255", "size": "250"}, {"price": "0.257", "size": "555"}, {"price": "0.258", "size": "1626"}, {"price": "0.29", "size": "82.75"}, {"price": "0.3", "size": "500"}, {"price": "0.34", "size": "58.82"}, {"price": "0.35", "size": "250"}, {"price": "0.36", "size": "1000"}, {"price": "0.39", "size": "930"}, {"price": "0.42", "size": "1000"}, {"price": "0.422", "size": "555"}, {"price": "0.423", "size": "900.89"}, {"price": "0.45", "size": "310"}, {"price": "0.55", "size": "750"}, {"price": "0.561", "size": "555"}, {"price": "0.563", "size": "555"}, {"price": "0.564", "size": "531"}, {"price": "0.682", "size": "333"}, {"price": "0.69", "size": "3850"}, {"price": "0.691", "size": "555"}, {"price": "0.701", "size": "297.1"}, {"price": "0.713", "size": "1000"}, {"price": "0.714", "size": "60"}, {"price": "0.715", "size": "30"}, {"price": "0.75", "size": "73.11"}, {"price": "0.752", "size": "30"}, {"price": "0.753", "size": "20"}, {"price": "0.76", "size": "20"}, {"price": "0.764", "size": "1000"}, {"price": "0.77", "size": "500"}, {"price": "0.771", "size": "320"}, {"price": "0.775", "size": "2000"}, {"price": "0.778", "size": "20"}, {"price": "0.78", "size": "8612.94"}, {"price": "0.787", "size": "70"}, {"price": "0.79", "size": "300"}, {"price": "0.791", "size": "20"}, {"price": "0.792", "size": "318.74"}, {"price": "0.794", "size": "123.49"}, {"price": "0.797", "size": "40"}, {"price": "0.798", "size": "459.53"}, {"price": "0.8", "size": "90"}, {"price": "0.801", "size": "20.7"}, {"price": "0.802", "size": "10"}], "asks": [{"price": "0.999", "size": "204181"}, {"price": "0.998", "size": "21000"}, {"price": "0.997", "size": "6555"}, {"price": "0.996", "size": "10.48"}, {"price": "0.993", "size": "2000"}, {"price": "0.992", "size": "4444"}, {"price": "0.99", "size": "15550"}, {"price": "0.989", "size": "5500"}, {"price": "0.986", "size": "2041.07"}, {"price": "0.985", "size": "3333"}, {"price": "0.979", "size": "1945.23"}, {"price": "0.978", "size": "3000"}, {"price": "0.973", "size": "2200"}, {"price": "0.972", "size": "2922"}, {"price": "0.971", "size": "500"}, {"price": "0.97", "size": "110.96"}, {"price": "0.968", "size": "900"}, {"price": "0.967", "size": "500"}, {"price": "0.959", "size": "5000"}, {"price": "0.958", "size": "3333"}, {"price": "0.957", "size": "250"}, {"price": "0.95", "size": "85"}, {"price": "0.948", "size": "99.88"}, {"price": "0.94", "size": "700"}, {"price": "0.938", "size": "68"}, {"price": "0.936", "size": "50"}, {"price": "0.9", "size": "1424.45"}, {"price": "0.899", "size": "2500"}, {"price": "0.879", "size": "555"}, {"price": "0.872", "size": "5"}, {"price": "0.86", "size": "3850"}, {"price": "0.857", "size": "555"}, {"price": "0.849", "size": "1000"}, {"price": "0.84", "size": "50"}, {"price": "0.834", "size": "200"}, {"price": "0.83", "size": "2750.53"}, {"price": "0.828", "size": "500"}, {"price": "0.825", "size": "2200.01"}, {"price": "0.822", "size": "900"}, {"price": "0.821", "size": "384.42"}, {"price": "0.82", "size": "2042.3"}, {"price": "0.818", "size": "1500"}, {"price": "0.817", "size": "402.75"}, {"price": "0.816", "size": "78.64"}, {"price": "0.815", "size": "15"}, {"price": "0.813", "size": "210"}, {"price": "0.809", "size": "436.62"}, {"price": "0.808", "size": "24.54"}, {"price": "0.807", "size": "400"}], "event_type": "book", "last_trade_price": "0.806"}, {"market": "0x66af911f31ceabb5f9a3ef9203a73f0b23d18aa81bbba7888dec440c622c2528", "asset_id": "68639196051170795150992485552561385006521521637825690332014642323694437969760", "timestamp": "1769384427623", "hash": "3c85efa2ce715d1bab9e67eabbe9160bc5a9ccfd", "bids": [{"price": "0.01", "size": "114990"}, {"price": "0.02", "size": "32400"}, {"price": "0.03", "size": "7006.66"}, {"price": "0.04", "size": "1000"}, {"price": "0.05", "size": "1000"}, {"price": "0.07", "size": "514.28"}, {"price": "0.1", "size": "5225"}, {"price": "0.11", "size": "309.09"}, {"price": "0.12", "size": "3325"}, {"price": "0.14", "size": "250"}, {"price": "0.15", "size": "213.33"}, {"price": "0.16", "size": "1000"}, {"price": "0.18", "size": "180"}, {"price": "0.19", "size": "147.36"}, {"price": "0.2", "size": "2250"}, {"price": "0.21", "size": "2098"}, {"price": "0.23", "size": "113.04"}, {"price": "0.25", "size": "500"}, {"price": "0.26", "size": "92.3"}, {"price": "0.3", "size": "66.66"}, {"price": "0.31", "size": "30"}, {"price": "0.33", "size": "5"}, {"price": "0.34", "size": "1500"}, {"price": "0.35", "size": "1553"}, {"price": "0.4", "size": "10"}, {"price": "0.45", "size": "800"}, {"price": "0.46", "size": "7.85"}, {"price": "0.5", "size": "1005"}, {"price": "0.51", "size": "1000"}, {"price": "0.52", "size": "1000"}, {"price": "0.53", "size": "1255"}, {"price": "0.55", "size": "750"}, {"price": "0.56", "size": "3000"}, {"price": "0.57", "size": "1.72"}, {"price": "0.6", "size": "10"}, {"price": "0.61", "size": "5850"}, {"price": "0.62", "size": "1311"}, {"price": "0.63", "size": "2500"}, {"price": "0.64", "size": "1000"}, {"price": "0.65", "size": "1348.26"}, {"price": "0.66", "size": "8405.43"}, {"price": "0.67", "size": "5342.05"}, {"price": "0.68", "size": "5664.54"}, {"price": "0.69", "size": "61.12"}], "asks": [{"price": "0.99", "size": "316490.59"}, {"price": "0.98", "size": "32571.42"}, {"price": "0.97", "size": "50445.97"}, {"price": "0.96", "size": "6050"}, {"price": "0.95", "size": "800.73"}, {"price": "0.94", "size": "625"}, {"price": "0.92", "size": "1545.92"}, {"price": "0.91", "size": "1671.83"}, {"price": "0.9", "size": "10"}, {"price": "0.88", "size": "20"}, {"price": "0.87", "size": "1700"}, {"price": "0.86", "size": "1555"}, {"price": "0.85", "size": "70"}, {"price": "0.84", "size": "5.27"}, {"price": "0.83", "size": "547.53"}, {"price": "0.82", "size": "57.82"}, {"price": "0.8", "size": "82.82"}, {"price": "0.79", "size": "1111"}, {"price": "0.78", "size": "3850"}, {"price": "0.77", "size": "311.13"}, {"price": "0.76", "size": "1358.82"}, {"price": "0.75", "size": "210"}, {"price": "0.74", "size": "46"}, {"price": "0.73", "size": "138.53"}, {"price": "0.72", "size": "5275.31"}, {"price": "0.71", "size": "3049.08"}, {"price": "0.7", "size": "908.37"}], "event_type": "book", "last_trade_price": "0.700"}, {"market": "0x4d594c1480eab1db09f6c04c089f92d0a45844bdfae32a6f3f8391f99a1ea081", "asset_id": "88636577098792919872169756031906573098016372635824568067326776673230264307456", "timestamp": "1769384347654", "hash": "a49d9261c4d7fb0ef81f96729b05751056c7cf0a", "bids": [{"price": "0.001", "size": "2006933.01"}, {"price": "0.002", "size": "1001255.7"}, {"price": "0.003", "size": "1400"}, {"price": "0.004", "size": "8.66"}, {"price": "0.006", "size": "200"}, {"price": "0.01", "size": "4500"}, {"price": "0.011", "size": "5.3"}, {"price": "0.02", "size": "2500"}, {"price": "0.022", "size": "12400"}, {"price": "0.023", "size": "11.43"}, {"price": "0.04", "size": "1250"}, {"price": "0.05", "size": "30"}, {"price": "0.051", "size": "39"}, {"price": "0.058", "size": "30000"}, {"price": "0.059", "size": "60300"}, {"price": "0.06", "size": "500"}, {"price": "0.061", "size": "16000"}, {"price": "0.062", "size": "30200"}, {"price": "0.08", "size": "250"}, {"price": "0.081", "size": "5.62"}, {"price": "0.1", "size": "360"}, {"price": "0.14", "size": "50"}, {"price": "0.15", "size": "551.66"}, {"price": "0.153", "size": "12000"}, {"price": "0.154", "size": "250"}, {"price": "0.2", "size": "410"}, {"price": "0.201", "size": "5.83"}, {"price": "0.25", "size": "262"}, {"price": "0.3", "size": "86.66"}, {"price": "0.35", "size": "68.57"}, {"price": "0.4", "size": "50"}, {"price": "0.41", "size": "4100"}, {"price": "0.411", "size": "3000"}, {"price": "0.415", "size": "1999.97"}, {"price": "0.424", "size": "6000"}, {"price": "0.425", "size": "1236"}, {"price": "0.426", "size": "5"}, {"price": "0.427", "size": "30"}, {"price": "0.8", "size": "1607.74"}, {"price": "0.85", "size": "50"}, {"price": "0.861", "size": "1009.84"}, {"price": "0.864", "size": "30"}, {"price": "0.865", "size": "30"}, {"price": "0.9", "size": "814.97"}, {"price": "0.901", "size": "1037.11"}, {"price": "0.902", "size": "205"}, {"price": "0.918", "size": "1110"}, {"price": "0.92", "size": "3850"}, {"price": "0.925", "size": "1069.83"}, {"price": "0.936", "size": "1366.15"}, {"price": "0.937", "size": "20"}, {"price": "0.951", "size": "617.14"}, {"price": "0.954", "size": "109.97"}, {"price": "0.961", "size": "1122.63"}, {"price": "0.967", "size": "1786.26"}, {"price": "0.97", "size": "1072.75"}, {"price": "0.971", "size": "90"}, {"price": "0.973", "size": "1421.54"}, {"price": "0.974", "size": "2273"}, {"price": "0.975", "size": "1328.14"}, {"price": "0.977", "size": "711.34"}, {"price": "0.98", "size": "1212.52"}, {"price": "0.981", "size": "1111.85"}, {"price": "0.983", "size": "5653.65"}, {"price": "0.984", "size": "1544.86"}, {"price": "0.985", "size": "1426.44"}, {"price": "0.986", "size": "2139.67"}, {"price": "0.988", "size": "5069.63"}, {"price": "0.989", "size": "2128.19"}, {"price": "0.99", "size": "202.89"}], "asks": [{"price": "0.999", "size": "355157"}, {"price": "0.998", "size": "75500"}, {"price": "0.997", "size": "8038"}, {"price": "0.996", "size": "9720.63"}, {"price": "0.995", "size": "13272.22"}, {"price": "0.994", "size": "12489.06"}, {"price": "0.993", "size": "1863.37"}, {"price": "0.992", "size": "540.38"}], "event_type": "book", "last_trade_price": "0.008"}, {"market": "0x101c26a9ff336abf4dffeb109dc40b92d9f55882dd471e57ee875794a6561bf3", "asset_id": "37082726066756590137696446997499452856763598243673867366591242252359474108530", "timestamp": "1769384427337", "hash": "6b657b04b5c6fd4f3a772f8d6faeb452c3584915", "bids": [{"price": "0.001", "size": "219881"}, {"price": "0.002", "size": "212506.25"}, {"price": "0.003", "size": "19.01"}, {"price": "0.004", "size": "648.55"}, {"price": "0.005", "size": "13987.13"}, {"price": "0.006", "size": "10250"}, {"price": "0.007", "size": "926.9"}, {"price": "0.008", "size": "30500"}, {"price": "0.009", "size": "20000"}, {"price": "0.01", "size": "9607.39"}, {"price": "0.011", "size": "7942.82"}, {"price": "0.012", "size": "250"}, {"price": "0.013", "size": "3126.54"}, {"price": "0.014", "size": "500"}, {"price": "0.015", "size": "2076.1"}, {"price": "0.016", "size": "4369.16"}, {"price": "0.017", "size": "1011.8"}, {"price": "0.018", "size": "449.6"}, {"price": "0.019", "size": "350"}, {"price": "0.02", "size": "300"}, {"price": "0.021", "size": "200"}, {"price": "0.022", "size": "157.2"}, {"price": "0.023", "size": "43.04"}, {"price": "0.024", "size": "0.27"}], "asks": [{"price": "0.999", "size": "905904.03"}, {"price": "0.998", "size": "1250"}, {"price": "0.997", "size": "1406.64"}, {"price": "0.996", "size": "1001300"}, {"price": "0.995", "size": "400000"}, {"price": "0.994", "size": "200"}, {"price": "0.993", "size": "9.79"}, {"price": "0.99", "size": "5150"}, {"price": "0.98", "size": "2550"}, {"price": "0.979", "size": "12.99"}, {"price": "0.96", "size": "1250"}, {"price": "0.952", "size": "15000"}, {"price": "0.951", "size": "30400"}, {"price": "0.95", "size": "50"}, {"price": "0.949", "size": "39"}, {"price": "0.94", "size": "500"}, {"price": "0.92", "size": "250"}, {"price": "0.919", "size": "6"}, {"price": "0.908", "size": "6200"}, {"price": "0.9", "size": "370"}, {"price": "0.85", "size": "551.66"}, {"price": "0.849", "size": "300"}, {"price": "0.8", "size": "9415"}, {"price": "0.799", "size": "300"}, {"price": "0.791", "size": "200"}, {"price": "0.79", "size": "5.43"}, {"price": "0.77", "size": "5750"}, {"price": "0.767", "size": "6150"}, {"price": "0.759", "size": "58"}, {"price": "0.75", "size": "112"}, {"price": "0.71", "size": "89.65"}, {"price": "0.67", "size": "1500"}, {"price": "0.66", "size": "770.58"}, {"price": "0.659", "size": "5"}, {"price": "0.61", "size": "126.28"}, {"price": "0.458", "size": "432.4"}, {"price": "0.356", "size": "605.49"}, {"price": "0.355", "size": "465"}, {"price": "0.286", "size": "465.97"}, {"price": "0.245", "size": "40"}, {"price": "0.18", "size": "7"}, {"price": "0.156", "size": "75.58"}, {"price": "0.15", "size": "200"}, {"price": "0.149", "size": "876.64"}, {"price": "0.137", "size": "465.1"}, {"price": "0.125", "size": "52.45"}, {"price": "0.118", "size": "1156.53"}, {"price": "0.115", "size": "69.07"}, {"price": "0.11", "size": "3850"}, {"price": "0.107", "size": "509.98"}, {"price": "0.105", "size": "752.64"}, {"price": "0.101", "size": "61.27"}, {"price": "0.1", "size": "10"}, {"price": "0.099", "size": "60"}, {"price": "0.083", "size": "150"}, {"price": "0.081", "size": "571.52"}, {"price": "0.08", "size": "699.97"}, {"price": "0.079", "size": "325"}, {"price": "0.077", "size": "45.53"}, {"price": "0.076", "size": "20"}, {"price": "0.071", "size": "718.57"}, {"price": "0.069", "size": "2000"}, {"price": "0.066", "size": "1213.62"}, {"price": "0.063", "size": "385.3"}, {"price": "0.06", "size": "75"}, {"price": "0.058", "size": "300"}, {"price": "0.057", "size": "276.97"}, {"price": "0.054", "size": "39.99"}, {"price": "0.052", "size": "1230.01"}, {"price": "0.05", "size": "41.01"}, {"price": "0.046", "size": "70"}, {"price": "0.045", "size": "140"}, {"price": "0.04", "size": "400"}, {"price": "0.038", "size": "174.37"}, {"price": "0.037", "size": "174.37"}, {"price": "0.036", "size": "1461.01"}, {"price": "0.035", "size": "302.56"}, {"price": "0.034", "size": "264"}, {"price": "0.033", "size": "176"}, {"price": "0.032", "size": "712.2"}, {"price": "0.031", "size": "270"}, {"price": "0.03", "size": "71.14"}, {"price": "0.027", "size": "100"}, {"price": "0.026", "size": "20"}, {"price": "0.025", "size": "100"}], "event_type": "book", "last_trade_price": "0.976"}, {"market": "0xafeb856581303e0d248192f2aed941ab52b972b2f4c249d850ee49e0b73f1e0a", "asset_id": "41440565164775085625089015358061986403213794358322082793122112978569975387415", "timestamp": "1769384362720", "hash": "17164d403df89a555f7a6d5e36462e582de8144e", "bids": [{"price": "0.001", "size": "203333.44"}, {"price": "0.002", "size": "255398.33"}, {"price": "0.003", "size": "33583.33"}, {"price": "0.004", "size": "7160.94"}], "asks": [{"price": "0.999", "size": "987744.99"}, {"price": "0.998", "size": "1250"}, {"price": "0.997", "size": "1172.62"}, {"price": "0.994", "size": "83"}, {"price": "0.993", "size": "9.76"}, {"price": "0.99", "size": "301500"}, {"price": "0.989", "size": "950"}, {"price": "0.98", "size": "50"}, {"price": "0.979", "size": "9.02"}, {"price": "0.95", "size": "460"}, {"price": "0.949", "size": "39"}, {"price": "0.939", "size": "32"}, {"price": "0.938", "size": "8.68"}, {"price": "0.9", "size": "570"}, {"price": "0.85", "size": "551.66"}, {"price": "0.8", "size": "465"}, {"price": "0.799", "size": "2487"}, {"price": "0.798", "size": "9"}, {"price": "0.797", "size": "5.78"}, {"price": "0.75", "size": "112"}, {"price": "0.749", "size": "150"}, {"price": "0.7", "size": "86.66"}, {"price": "0.65", "size": "68.57"}, {"price": "0.6", "size": "125"}, {"price": "0.24", "size": "5000"}, {"price": "0.238", "size": "700"}, {"price": "0.1", "size": "300"}, {"price": "0.092", "size": "500"}, {"price": "0.091", "size": "30"}, {"price": "0.08", "size": "850"}, {"price": "0.076", "size": "30"}, {"price": "0.074", "size": "30"}, {"price": "0.073", "size": "20"}, {"price": "0.042", "size": "500"}, {"price": "0.02", "size": "100"}, {"price": "0.018", "size": "1000"}, {"price": "0.017", "size": "5080.89"}, {"price": "0.015", "size": "40"}, {"price": "0.011", "size": "188"}, {"price": "0.01", "size": "1553.89"}, {"price": "0.009", "size": "2815.83"}, {"price": "0.008", "size": "269.99"}, {"price": "0.007", "size": "400"}, {"price": "0.006", "size": "5362"}, {"price": "0.005", "size": "3605.49"}], "event_type": "book", "last_trade_price": "0.004"}, {"market": "0xe0266da952c7be95f42d76770972075b57ac3823f876a4967b9a696bf7f77cb3", "asset_id": "98364222367909646196463824162782128681453799377712476940174507012774514155648", "timestamp": "1769384402052", "hash": "7fe3517b6d525a266f4209dee26d4547ff514212", "bids": [{"price": "0.001", "size": "339114.73"}, {"price": "0.002", "size": "79230.5"}], "asks": [{"price": "0.999", "size": "609172.98"}, {"price": "0.998", "size": "1850"}, {"price": "0.997", "size": "1266"}, {"price": "0.996", "size": "40107.42"}, {"price": "0.995", "size": "100"}, {"price": "0.994", "size": "183"}, {"price": "0.993", "size": "100"}, {"price": "0.992", "size": "100"}, {"price": "0.991", "size": "100"}, {"price": "0.99", "size": "205.35"}, {"price": "0.989", "size": "77"}, {"price": "0.98", "size": "50"}, {"price": "0.979", "size": "9.02"}, {"price": "0.95", "size": "460"}, {"price": "0.949", "size": "39"}, {"price": "0.939", "size": "32"}, {"price": "0.938", "size": "8.89"}, {"price": "0.9", "size": "570"}, {"price": "0.85", "size": "551.66"}, {"price": "0.8", "size": "615"}, {"price": "0.798", "size": "5000"}, {"price": "0.795", "size": "5.66"}, {"price": "0.75", "size": "262"}, {"price": "0.749", "size": "1992"}, {"price": "0.748", "size": "7"}, {"price": "0.7", "size": "86.66"}, {"price": "0.65", "size": "68.57"}, {"price": "0.6", "size": "125"}, {"price": "0.5", "size": "10"}, {"price": "0.25", "size": "2427.76"}, {"price": "0.249", "size": "5000"}, {"price": "0.17", "size": "100"}, {"price": "0.13", "size": "100"}, {"price": "0.129", "size": "30"}, {"price": "0.105", "size": "500"}, {"price": "0.1", "size": "2000"}, {"price": "0.092", "size": "1000"}, {"price": "0.08", "size": "850"}, {"price": "0.076", "size": "30"}, {"price": "0.075", "size": "30"}, {"price": "0.055", "size": "100"}, {"price": "0.054", "size": "400"}, {"price": "0.053", "size": "20"}, {"price": "0.04", "size": "379.96"}, {"price": "0.025", "size": "1000"}, {"price": "0.024", "size": "1000"}, {"price": "0.023", "size": "20"}, {"price": "0.02", "size": "100"}, {"price": "0.015", "size": "9185.6"}, {"price": "0.01", "size": "200"}, {"price": "0.007", "size": "2061.85"}, {"price": "0.006", "size": "269.26"}, {"price": "0.005", "size": "980.72"}, {"price": "0.004", "size": "1300.5"}, {"price": "0.003", "size": "7253.12"}], "event_type": "book", "last_trade_price": "0.002"}]}
{"_local_timestamp": "2026-01-25T23:40:40.369897+00:00", "data": {"market": "0xafeb856581303e0d248192f2aed941ab52b972b2f4c249d850ee49e0b73f1e0a", "price_changes": [{"asset_id": "3345017119039865108601589077873396828255638656156390928287117391771035074364", "price": "0.251", "size": "100", "side": "BUY", "hash": "660d9f84bfce5b4a24bfae6b0412f1587b4f22b7", "best_bid": "0.995", "best_ask": "0.996"}, {"asset_id": "41440565164775085625089015358061986403213794358322082793122112978569975387415", "price": "0.749", "size": "100", "side": "SELL", "hash": "7779b5137cbf50fff9de8e21ba9747bca7b0f664", "best_bid": "0.004", "best_ask": "0.005"}], "timestamp": "1769384440254", "event_type": "price_change"}}
{"_local_timestamp": "2026-01-25T23:40:40.370965+00:00", "data": {"market": "0xe0266da952c7be95f42d76770972075b57ac3823f876a4967b9a696bf7f77cb3", "price_changes": [{"asset_id": "101410416660845748603825473080512476735733815308377998129165131061476869070298", "price": "0.25", "size": "212", "side": "BUY", "hash": "dcadc0a21b392f45a385d16cb8de5941949a9c09", "best_bid": "0.997", "best_ask": "0.998"}, {"asset_id": "98364222367909646196463824162782128681453799377712476940174507012774514155648", "price": "0.75", "size": "212", "side": "SELL", "hash": "c6a86b1f866a3a0b35ebb86c774473e681d674f6", "best_bid": "0.002", "best_ask": "0.003"}], "timestamp": "1769384440254", "event_type": "price_change"}}
{"_local_timestamp": "2026-01-25T23:40:40.568675+00:00", "data": {"market": "0x66af911f31ceabb5f9a3ef9203a73f0b23d18aa81bbba7888dec440c622c2528", "price_changes": [{"asset_id": "101818439776033928818471919550932857351051302350112396692573347503051307979709", "price": "0.3", "size": "958.37", "side": "BUY", "hash": "75cf3768d9e0aff8ccedcec27d274189ab6545ab", "best_bid": "0.3", "best_ask": "0.31"}, {"asset_id": "68639196051170795150992485552561385006521521637825690332014642323694437969760", "price": "0.7", "size": "958.37", "side": "SELL", "hash": "4fe2c771ba32bff3d181cf3b4481342eba744322", "best_bid": "0.69", "best_ask": "0.7"}], "timestamp": "1769384440425", "event_type": "price_change"}}
{"_local_timestamp": "2026-01-25T23:40:40.700086+00:00", "data": {"market": "0x66af911f31ceabb5f9a3ef9203a73f0b23d18aa81bbba7888dec440c622c2528", "price_changes": [{"asset_id": "101818439776033928818471919550932857351051302350112396692573347503051307979709", "price": "0.3", "size": "908.37", "side": "BUY", "hash": "7a6c870f539464da8f6d767c0c5d4238f2940ceb", "best_bid": "0.3", "best_ask": "0.31"}, {"asset_id": "68639196051170795150992485552561385006521521637825690332014642323694437969760", "price": "0.7", "size": "908.37", "side": "SELL", "hash": "e44d612251a523375de249a81a73c83653137afb", "best_bid": "0.69", "best_ask": "0.7"}], "timestamp": "1769384440543", "event_type": "price_change"}}
{"_local_timestamp": "2026-01-25T23:40:40.739378+00:00", "data": {"market": "0xe0266da952c7be95f42d76770972075b57ac3823f876a4967b9a696bf7f77cb3", "price_changes": [{"asset_id": "101410416660845748603825473080512476735733815308377998129165131061476869070298", "price": "0.251", "size": "2042", "side": "BUY", "hash": "1d62bf1cdd8d172fd89d0d6c0f84357e35454b4d", "best_bid": "0.997", "best_ask": "0.998"}, {"asset_id": "98364222367909646196463824162782128681453799377712476940174507012774514155648", "price": "0.749", "size": "2042", "side": "SELL", "hash": "6d18fbbcfb740c8df4f0dd6b416e337f80aa176c", "best_bid": "0.002", "best_ask": "0.003"}], "timestamp": "1769384440579", "event_type": "price_change"}}
{"_local_timestamp": "2026-01-25T23:40:40.788197+00:00", "data": {"market": "0xafeb856581303e0d248192f2aed941ab52b972b2f4c249d850ee49e0b73f1e0a", "price_changes": [{"asset_id": "3345017119039865108601589077873396828255638656156390928287117391771035074364", "price": "0.25", "size": "162", "side": "BUY", "hash": "3555faf9a4cfb19cf4bb1f3728a88873d4d1eb7e", "best_bid": "0.995", "best_ask": "0.996"}, {"asset_id": "41440565164775085625089015358061986403213794358322082793122112978569975387415", "price": "0.75", "size": "162", "side": "SELL", "hash": "184e6a6c7d39e11ac4107214cd136d51b81dd1d0", "best_bid": "0.004", "best_ask": "0.005"}], "timestamp": "1769384440596", "event_type": "price_change"}}
{"_local_timestamp": "2026-01-25T23:40:42.864908+00:00", "data": {"market": "0xd87ac5bb74a21061d4f223d2a83c0269607fcb6d4c74d5a3d3220209d089431a", "price_changes": [{"asset_id": "63433408040190943973509092025756868743192149481060781851142321049882584518043", "price": "0.194", "size": "318", "side": "BUY", "hash": "fb118862a69b5559ef2b530c4eedc13cf16601da", "best_bid": "0.194", "best_ask": "0.198"}, {"asset_id": "73459237018178325517511938237778014293974381812181153063276727733805928508002", "price": "0.806", "size": "318", "side": "SELL", "hash": "ac43acd603407bc935ac2f531727a39f49a99ac9", "best_bid": "0.802", "best_ask": "0.806"}], "timestamp": "1769384442793", "event_type": "price_change"}}
{"_local_timestamp": "2026-01-25T23:40:42.889701+00:00", "data": {"market": "0x101c26a9ff336abf4dffeb109dc40b92d9f55882dd471e57ee875794a6561bf3", "price_changes": [{"asset_id": "41909517390337506269578561946393939690952797212331290191404935145632561531096", "price": "0.974", "size": "0", "side": "BUY", "hash": "957f0917cccc565e03538681b6824b00719995a7", "best_bid": "0.975", "best_ask": "0.976"}, {"asset_id": "37082726066756590137696446997499452856763598243673867366591242252359474108530", "price": "0.026", "size": "0", "side": "SELL", "hash": "59edb955e3fc45f895f47b6c0b59092eebee5ddc", "best_bid": "0.024", "best_ask": "0.025"}], "timestamp": "1769384442819", "event_type": "price_change"}}
{"_local_timestamp": "2026-01-25T23:40:42.910848+00:00", "data": {"market": "0x101c26a9ff336abf4dffeb109dc40b92d9f55882dd471e57ee875794a6561bf3", "price_changes": [{"asset_id": "41909517390337506269578561946393939690952797212331290191404935145632561531096", "price": "0.975", "size": "120", "side": "BUY", "hash": "3ce0e72885e8b15c7446bf5fa469b21df1ae38de", "best_bid": "0.975", "best_ask": "0.976"}, {"asset_id": "37082726066756590137696446997499452856763598243673867366591242252359474108530", "price": "0.025", "size": "120", "side": "SELL", "hash": "cf365d2e87f4f91b0e2784f561429a271c487c77", "best_bid": "0.024", "best_ask": "0.025"}], "timestamp": "1769384442842", "event_type": "price_change"}}
{"_local_timestamp": "2026-01-25T23:40:42.937251+00:00", "data": {"market": "0xd87ac5bb74a21061d4f223d2a83c0269607fcb6d4c74d5a3d3220209d089431a", "price_changes": [{"asset_id": "63433408040190943973509092025756868743192149481060781851142321049882584518043", "price": "0.166", "size": "500", "side": "BUY", "hash": "c46db03c9996563f2ebb34ec6db16e810901af24", "best_bid": "0.194", "best_ask": "0.198"}, {"asset_id": "73459237018178325517511938237778014293974381812181153063276727733805928508002", "price": "0.834", "size": "500", "side": "SELL", "hash": "fe0165d3d4f4b6532050cbb54d44ebef0ae66fb1", "best_bid": "0.802", "best_ask": "0.806"}], "timestamp": "1769384442869", "event_type": "price_change"}}
{"_local_timestamp": "2026-01-25T23:40:42.979436+00:00", "data": {"market": "0x66af911f31ceabb5f9a3ef9203a73f0b23d18aa81bbba7888dec440c622c2528", "price_changes": [{"asset_id": "101818439776033928818471919550932857351051302350112396692573347503051307979709", "price": "0.27", "size": "538.53", "side": "BUY", "hash": "36e8290f78f2aef06fea205609d667b961f67af3", "best_bid": "0.3", "best_ask": "0.31"}, {"asset_id": "68639196051170795150992485552561385006521521637825690332014642323694437969760", "price": "0.73", "size": "538.53", "side": "SELL", "hash": "e01fcf4df6dfca646d4ba2e860e3e28a79b52da5", "best_bid": "0.69", "best_ask": "0.7"}], "timestamp": "1769384442907", "event_type": "price_change"}}
{"_local_timestamp": "2026-01-25T23:40:42.984465+00:00", "data": {"market": "0x66af911f31ceabb5f9a3ef9203a73f0b23d18aa81bbba7888dec440c622c2528", "price_changes": [{"asset_id": "101818439776033928818471919550932857351051302350112396692573347503051307979709", "price": "0.3", "size": "958.37", "side": "BUY", "hash": "3c675606bc78a5e1f78010007dbe6bbb4bab1ea4", "best_bid": "0.3", "best_ask": "0.31"}, {"asset_id": "68639196051170795150992485552561385006521521637825690332014642323694437969760", "price": "0.7", "size": "958.37", "side": "SELL", "hash": "0810e8e97cdfd00e626503fa7d232eb4511be297", "best_bid": "0.69", "best_ask": "0.7"}], "timestamp": "1769384442916", "event_type": "price_change"}}
{"_local_timestamp": "2026-01-25T23:40:42.998100+00:00", "data": {"market": "0x66af911f31ceabb5f9a3ef9203a73f0b23d18aa81bbba7888dec440c622c2528", "price_changes": [{"asset_id": "101818439776033928818471919550932857351051302350112396692573347503051307979709", "price": "0.29", "size": "2743.08", "side": "BUY", "hash": "ed617797030aa6f18ce2ba422131d9ff8a82e162", "best_bid": "0.3", "best_ask": "0.31"}, {"asset_id": "68639196051170795150992485552561385006521521637825690332014642323694437969760", "price": "0.71", "size": "2743.08", "side": "SELL", "hash": "b77e84a896339a013cf74e8ca42db9dc55fb1c36", "best_bid": "0.69", "best_ask": "0.7"}], "timestamp": "1769384442933", "event_type": "price_change"}}
{"_local_timestamp": "2026-01-25T23:40:43.036107+00:00", "data": {"market": "0xd87ac5bb74a21061d4f223d2a83c0269607fcb6d4c74d5a3d3220209d089431a", "price_changes": [{"asset_id": "63433408040190943973509092025756868743192149481060781851142321049882584518043", "price": "0.187", "size": "0", "side": "BUY", "hash": "f0b3fd14fc7439563de62414ae6ecc37ed27cfac", "best_bid": "0.194", "best_ask": "0.198"}, {"asset_id": "73459237018178325517511938237778014293974381812181153063276727733805928508002", "price": "0.813", "size": "0", "side": "SELL", "hash": "92f341e74bd947b1d6cab71aaa00cecc3f0e2b68", "best_bid": "0.802", "best_ask": "0.806"}], "timestamp": "1769384442974", "event_type": "price_change"}}
{"_local_timestamp": "2026-01-25T23:40:43.062332+00:00", "data": {"market": "0xd87ac5bb74a21061d4f223d2a83c0269607fcb6d4c74d5a3d3220209d089431a", "price_changes": [{"asset_id": "73459237018178325517511938237778014293974381812181153063276727733805928508002", "price": "0.774", "size": "300", "side": "BUY", "hash": "cb68ce10d7467c1d29766e953d990988615f3d76", "best_bid": "0.802", "best_ask": "0.806"}, {"asset_id": "63433408040190943973509092025756868743192149481060781851142321049882584518043", "price": "0.226", "size": "300", "side": "SELL", "hash": "009352dade3621cab88cff3a6137e210451a311b", "best_bid": "0.194", "best_ask": "0.198"}], "timestamp": "1769384442995", "event_type": "price_change"}}
{"_local_timestamp": "2026-01-25T23:40:43.111770+00:00", "data": {"market": "0x66af911f31ceabb5f9a3ef9203a73f0b23d18aa81bbba7888dec440c622c2528", "price_changes": [{"asset_id": "101818439776033928818471919550932857351051302350112396692573347503051307979709", "price": "0.3", "size": "908.37", "side": "BUY", "hash": "e6b202a96340c3f7c23e60ceff776f1a0d9818b4", "best_bid": "0.3", "best_ask": "0.31"}, {"asset_id": "68639196051170795150992485552561385006521521637825690332014642323694437969760", "price": "0.7", "size": "908.37", "side": "SELL", "hash": "c1ab9709515320ad4977a375a5d7a4f5adccf1bb", "best_bid": "0.69", "best_ask": "0.7"}], "timestamp": "1769384443035", "event_type": "price_change"}}
{"_local_timestamp": "2026-01-25T23:40:43.112123+00:00", "data": {"market": "0xd87ac5bb74a21061d4f223d2a83c0269607fcb6d4c74d5a3d3220209d089431a", "price_changes": [{"asset_id": "63433408040190943973509092025756868743192149481060781851142321049882584518043", "price": "0.166", "size": "200", "side": "BUY", "hash": "bcf104e0dcca46d941bd5a2391c1fa3324322d3d", "best_bid": "0.194", "best_ask": "0.198"}, {"asset_id": "73459237018178325517511938237778014293974381812181153063276727733805928508002", "price": "0.834", "size": "200", "side": "SELL", "hash": "0677c2e1b6289f4375801dc282909934bc777e03", "best_bid": "0.802", "best_ask": "0.806"}], "timestamp": "1769384443036", "event_type": "price_change"}}
{"_local_timestamp": "2026-01-25T23:40:43.141035+00:00", "data": {"market": "0xd87ac5bb74a21061d4f223d2a83c0269607fcb6d4c74d5a3d3220209d089431a", "price_changes": [{"asset_id": "73459237018178325517511938237778014293974381812181153063276727733805928508002", "price": "0.775", "size": "2200", "side": "BUY", "hash": "c7e22fdc237b316012573a4438fe881d7f103648", "best_bid": "0.802", "best_ask": "0.806"}, {"asset_id": "63433408040190943973509092025756868743192149481060781851142321049882584518043", "price": "0.225", "size": "2200", "side": "SELL", "hash": "c057bc031ebc9d2c33b4a53aba3e92a7f9f296e4", "best_bid": "0.194", "best_ask": "0.198"}], "timestamp": "1769384443070", "event_type": "price_change"}}
{"_local_timestamp": "2026-01-25T23:40:43.175084+00:00", "data": {"market": "0x66af911f31ceabb5f9a3ef9203a73f0b23d18aa81bbba7888dec440c622c2528", "price_changes": [{"asset_id": "101818439776033928818471919550932857351051302350112396692573347503051307979709", "price": "0.27", "size": "138.53", "side": "BUY", "hash": "e6ce8afbb3a421637d45f76cb780c6a2de5db5c8", "best_bid": "0.3", "best_ask": "0.31"}, {"asset_id": "68639196051170795150992485552561385006521521637825690332014642323694437969760", "price": "0.73", "size": "138.53", "side": "SELL", "hash": "0c4ebe99493db659dcbd06d6a5e51f601e3b5ce7", "best_bid": "0.69", "best_ask": "0.7"}], "timestamp": "1769384443108", "event_type": "price_change"}}
{"_local_timestamp": "2026-01-25T23:40:43.488627+00:00", "data": {"market": "0xd87ac5bb74a21061d4f223d2a83c0269607fcb6d4c74d5a3d3220209d089431a", "price_changes": [{"asset_id": "73459237018178325517511938237778014293974381812181153063276727733805928508002", "price": "0.775", "size": "2400", "side": "BUY", "hash": "2c168e2436174c8b32c0d92b580dea26278ad522", "best_bid": "0.802", "best_ask": "0.806"}, {"asset_id": "63433408040190943973509092025756868743192149481060781851142321049882584518043", "price": "0.225", "size": "2400", "side": "SELL", "hash": "4f79433a72a27a8f7891f17d488f3eea1c18d697", "best_bid": "0.194", "best_ask": "0.198"}], "timestamp": "1769384443422", "event_type": "price_change"}}
{"_local_timestamp": "2026-01-25T23:40:43.567063+00:00", "data": {"market": "0x66af911f31ceabb5f9a3ef9203a73f0b23d18aa81bbba7888dec440c622c2528", "price_changes": [{"asset_id": "101818439776033928818471919550932857351051302350112396692573347503051307979709", "price": "0.25", "size": "190", "side": "BUY", "hash": "8ea75e627a9ef1f6d7b281f9b421774b9a5a04ed", "best_bid": "0.3", "best_ask": "0.31"}, {"asset_id": "68639196051170795150992485552561385006521521637825690332014642323694437969760", "price": "0.75", "size": "190", "side": "SELL", "hash": "0453a03b20784609270f42633ebcbb1245778e36", "best_bid": "0.69", "best_ask": "0.7"}], "timestamp": "1769384443486", "event_type": "price_change"}}
{"_local_timestamp": "2026-01-25T23:40:43.575640+00:00", "data": {"market": "0x66af911f31ceabb5f9a3ef9203a73f0b23d18aa81bbba7888dec440c622c2528", "price_changes": [{"asset_id": "101818439776033928818471919550932857351051302350112396692573347503051307979709", "price": "0.26", "size": "66", "side": "BUY", "hash": "683f117d2e44b04c690d03b4e4aac1de546f7436", "best_bid": "0.3", "best_ask": "0.31"}, {"asset_id": "68639196051170795150992485552561385006521521637825690332014642323694437969760", "price": "0.74", "size": "66", "side": "SELL", "hash": "2e462f149b5b3a4d66065d0f6769502d97f7fe40", "best_bid": "0.69", "best_ask": "0.7"}], "timestamp": "1769384443510", "event_type": "price_change"}}
{"_local_timestamp": "2026-01-25T23:40:43.998037+00:00", "data": {"market": "0xd87ac5bb74a21061d4f223d2a83c0269607fcb6d4c74d5a3d3220209d089431a", "price_changes": [{"asset_id": "63433408040190943973509092025756868743192149481060781851142321049882584518043", "price": "0.188", "size": "210", "side": "BUY", "hash": "d5a739de9b52b8ecf388ce9fdd25180cba83fb51", "best_bid": "0.194", "best_ask": "0.198"}, {"asset_id": "73459237018178325517511938237778014293974381812181153063276727733805928508002", "price": "0.812", "size": "210", "side": "SELL", "hash": "26e4ec2407785eb836871c887e5901b1a77cdcd7", "best_bid": "0.802", "best_ask": "0.806"}], "timestamp": "1769384443921", "event_type": "price_change"}}
{"_local_timestamp": "2026-01-25T23:40:44.120728+00:00", "data": {"market": "0xd87ac5bb74a21061d4f223d2a83c0269607fcb6d4c74d5a3d3220209d089431a", "price_changes": [{"asset_id": "63433408040190943973509092025756868743192149481060781851142321049882584518043", "price": "0.166", "size": "500", "side": "BUY", "hash": "9214a634f6ebc72a73d96518c73e03c45d99f0fc", "best_bid": "0.194", "best_ask": "0.198"}, {"asset_id": "73459237018178325517511938237778014293974381812181153063276727733805928508002", "price": "0.834", "size": "500", "side": "SELL", "hash": "a343307bc801978e2e12e20367c85ccd275cc667", "best_bid": "0.802", "best_ask": "0.806"}], "timestamp": "1769384444008", "event_type": "price_change"}}
{"_local_timestamp": "2026-01-25T23:40:44.129492+00:00", "data": {"market": "0xd87ac5bb74a21061d4f223d2a83c0269607fcb6d4c74d5a3d3220209d089431a", "price_changes": [{"asset_id": "63433408040190943973509092025756868743192149481060781851142321049882584518043", "price": "0.194", "size": "0", "side": "BUY", "hash": "c0e4ae4ccef132f7b880dedac240a061cbbabcfe", "best_bid": "0.193", "best_ask": "0.198"}, {"asset_id": "73459237018178325517511938237778014293974381812181153063276727733805928508002", "price": "0.806", "size": "0", "side": "SELL", "hash": "33c6b75d60a90679bbccbfd2e4fb69f217caa2ad", "best_bid": "0.802", "best_ask": "0.807"}], "timestamp": "1769384444013", "event_type": "price_change"}}
{"_local_timestamp": "2026-01-25T23:40:44.133634+00:00", "data": {"market": "0x66af911f31ceabb5f9a3ef9203a73f0b23d18aa81bbba7888dec440c622c2528", "price_changes": [{"asset_id": "101818439776033928818471919550932857351051302350112396692573347503051307979709", "price": "0.3", "size": "958.37", "side": "BUY", "hash": "0911b87bebded1b536e77608bc3ecb6551a08b53", "best_bid": "0.3", "best_ask": "0.31"}, {"asset_id": "68639196051170795150992485552561385006521521637825690332014642323694437969760", "price": "0.7", "size": "958.37", "side": "SELL", "hash": "e4015e96c6fdc879ac2f2fd45a6bc64bf35edb8e", "best_bid": "0.69", "best_ask": "0.7"}], "timestamp": "1769384444038", "event_type": "price_change"}}
{"_local_timestamp": "2026-01-25T23:40:44.145522+00:00", "data": {"market": "0x66af911f31ceabb5f9a3ef9203a73f0b23d18aa81bbba7888dec440c622c2528", "price_changes": [{"asset_id": "101818439776033928818471919550932857351051302350112396692573347503051307979709", "price": "0.27", "size": "538.53", "side": "BUY", "hash": "b0a70addffd0ec6dfa01a03d29fe009a854a4562", "best_bid": "0.3", "best_ask": "0.31"}, {"asset_id": "68639196051170795150992485552561385006521521637825690332014642323694437969760", "price": "0.73", "size": "538.53", "side": "SELL", "hash": "e6c53a13b9988530ed67428ec6371750a059a0b7", "best_bid": "0.69", "best_ask": "0.7"}], "timestamp": "1769384444051", "event_type": "price_change"}}
{"_local_timestamp": "2026-01-25T23:40:44.153713+00:00", "data": {"market": "0x101c26a9ff336abf4dffeb109dc40b92d9f55882dd471e57ee875794a6561bf3", "price_changes": [{"asset_id": "41909517390337506269578561946393939690952797212331290191404935145632561531096", "price": "0.975", "size": "100", "side": "BUY", "hash": "8c501c700f756ce552330cc5a2e4a4be1ceb9d77", "best_bid": "0.975", "best_ask": "0.976"}, {"asset_id": "37082726066756590137696446997499452856763598243673867366591242252359474108530", "price": "0.025", "size": "100", "side": "SELL", "hash": "70a4d125552bba33695e6eec9ddf78993ff34991", "best_bid": "0.024", "best_ask": "0.025"}], "timestamp": "1769384444086", "event_type": "price_change"}}
{"_local_timestamp": "2026-01-25T23:40:44.166723+00:00", "data": {"market": "0x66af911f31ceabb5f9a3ef9203a73f0b23d18aa81bbba7888dec440c622c2528", "price_changes": [{"asset_id": "101818439776033928818471919550932857351051302350112396692573347503051307979709", "price": "0.29", "size": "3051.08", "side": "BUY", "hash": "5399c5942c03ffd36b99aac3ebd2f5a2a756663e", "best_bid": "0.3", "best_ask": "0.31"}, {"asset_id": "68639196051170795150992485552561385006521521637825690332014642323694437969760", "price": "0.71", "size": "3051.08", "side": "SELL", "hash": "acb0d3bd91ffc4981d35bc217fcb72fe31a5965f", "best_bid": "0.69", "best_ask": "0.7"}], "timestamp": "1769384444100", "event_type": "price_change"}}
{"_local_timestamp": "2026-01-25T23:40:44.183200+00:00", "data": {"market": "0x101c26a9ff336abf4dffeb109dc40b92d9f55882dd471e57ee875794a6561bf3", "price_changes": [{"asset_id": "41909517390337506269578561946393939690952797212331290191404935145632561531096", "price": "0.974", "size": "20", "side": "BUY", "hash": "e82e1f09f1266bf05b25499760b8a7e1f5baec7d", "best_bid": "0.975", "best_ask": "0.976"}, {"asset_id": "37082726066756590137696446997499452856763598243673867366591242252359474108530", "price": "0.026", "size": "20", "side": "SELL", "hash": "b4c6f78bf0af044713576538480cde072ffb7670", "best_bid": "0.024", "best_ask": "0.025"}], "timestamp": "1769384444108", "event_type": "price_change"}}
{"_local_timestamp": "2026-01-25T23:40:44.246831+00:00", "data": {"market": "0x66af911f31ceabb5f9a3ef9203a73f0b23d18aa81bbba7888dec440c622c2528", "price_changes": [{"asset_id": "101818439776033928818471919550932857351051302350112396692573347503051307979709", "price": "0.3", "size": "908.37", "side": "BUY", "hash": "0088950e7c32a62de76f3085ca6b8648fb182230", "best_bid": "0.3", "best_ask": "0.31"}, {"asset_id": "68639196051170795150992485552561385006521521637825690332014642323694437969760", "price": "0.7", "size": "908.37", "side": "SELL", "hash": "60424a56f30e5ca35d9c37e6c0e0c82f6653772b", "best_bid": "0.69", "best_ask": "0.7"}], "timestamp": "1769384444174", "event_type": "price_change"}}
{"_local_timestamp": "2026-01-25T23:40:45.613387+00:00", "data": {"market": "0xd87ac5bb74a21061d4f223d2a83c0269607fcb6d4c74d5a3d3220209d089431a", "price_changes": [{"asset_id": "63433408040190943973509092025756868743192149481060781851142321049882584518043", "price": "0.188", "size": "0", "side": "BUY", "hash": "0cebd149e427e308f59f56f33302cb373c1c30e4", "best_bid": "0.193", "best_ask": "0.198"}, {"asset_id": "73459237018178325517511938237778014293974381812181153063276727733805928508002", "price": "0.812", "size": "0", "side": "SELL", "hash": "a304b161db1dca4df5156beb625bcb9ef27a9d1a", "best_bid": "0.802", "best_ask": "0.807"}], "timestamp": "1769384445529", "event_type": "price_change"}}
{"_local_timestamp": "2026-01-25T23:40:45.626928+00:00", "data": {"market": "0xd87ac5bb74a21061d4f223d2a83c0269607fcb6d4c74d5a3d3220209d089431a", "price_changes": [{"asset_id": "63433408040190943973509092025756868743192149481060781851142321049882584518043", "price": "0.166", "size": "200", "side": "BUY", "hash": "983356bbc23bfa453f6c70eef6af08fdb8c15a71", "best_bid": "0.193", "best_ask": "0.198"}, {"asset_id": "73459237018178325517511938237778014293974381812181153063276727733805928508002", "price": "0.834", "size": "200", "side": "SELL", "hash": "e483873bb29ee6e3868266fc652ac552effc03f1", "best_bid": "0.802", "best_ask": "0.807"}], "timestamp": "1769384445552", "event_type": "price_change"}}
{"_local_timestamp": "2026-01-25T23:40:45.717558+00:00", "data": {"market": "0x66af911f31ceabb5f9a3ef9203a73f0b23d18aa81bbba7888dec440c622c2528", "price_changes": [{"asset_id": "101818439776033928818471919550932857351051302350112396692573347503051307979709", "price": "0.3", "size": "958.37", "side": "BUY", "hash": "ceeeaeceb8da673023fdfa51fca794f8bde52f39", "best_bid": "0.3", "best_ask": "0.31"}, {"asset_id": "68639196051170795150992485552561385006521521637825690332014642323694437969760", "price": "0.7", "size": "958.37", "side": "SELL", "hash": "69ebdb25b7d26655fc49c54861b2b5f2d05d8278", "best_bid": "0.69", "best_ask": "0.7"}], "timestamp": "1769384445647", "event_type": "price_change"}}
{"_local_timestamp": "2026-01-25T23:40:45.820727+00:00", "data": {"market": "0x66af911f31ceabb5f9a3ef9203a73f0b23d18aa81bbba7888dec440c622c2528", "price_changes": [{"asset_id": "101818439776033928818471919550932857351051302350112396692573347503051307979709", "price": "0.27", "size": "138.53", "side": "BUY", "hash": "7667bf6a0a0c527425aa4fb8cd25cc6cd437530f", "best_bid": "0.3", "best_ask": "0.31"}, {"asset_id": "68639196051170795150992485552561385006521521637825690332014642323694437969760", "price": "0.73", "size": "138.53", "side": "SELL", "hash": "d1274625aaece9b089f7ea45fc2dbf902978e355", "best_bid": "0.69", "best_ask": "0.7"}], "timestamp": "1769384445743", "event_type": "price_change"}}
{"_local_timestamp": "2026-01-25T23:40:45.824095+00:00", "data": {"market": "0x66af911f31ceabb5f9a3ef9203a73f0b23d18aa81bbba7888dec440c622c2528", "price_changes": [{"asset_id": "101818439776033928818471919550932857351051302350112396692573347503051307979709", "price": "0.3", "size": "908.37", "side": "BUY", "hash": "1efb1b28033ab53f7b4c7ce2ae0d27a653659855", "best_bid": "0.3", "best_ask": "0.31"}, {"asset_id": "68639196051170795150992485552561385006521521637825690332014642323694437969760", "price": "0.7", "size": "908.37", "side": "SELL", "hash": "d163bab73333d5c1db620c965b31a79b9d3ce404", "best_bid": "0.69", "best_ask": "0.7"}], "timestamp": "1769384445754", "event_type": "price_change"}}
{"_local_timestamp": "2026-01-25T23:40:45.847406+00:00", "data": {"market": "0xd87ac5bb74a21061d4f223d2a83c0269607fcb6d4c74d5a3d3220209d089431a", "price_changes": [{"asset_id": "73459237018178325517511938237778014293974381812181153063276727733805928508002", "price": "0.774", "size": "0", "side": "BUY", "hash": "99438cb2b0efcd616b72c5d550eae485b15368c8", "best_bid": "0.802", "best_ask": "0.807"}, {"asset_id": "63433408040190943973509092025756868743192149481060781851142321049882584518043", "price": "0.226", "size": "0", "side": "SELL", "hash": "1b96c2b5eaae2481d77100fd317a282a9f1cc03f", "best_bid": "0.193", "best_ask": "0.198"}], "timestamp": "1769384445778", "event_type": "price_change"}}
{"_local_timestamp": "2026-01-25T23:40:45.948866+00:00", "data": {"market": "0x4d594c1480eab1db09f6c04c089f92d0a45844bdfae32a6f3f8391f99a1ea081", "price_changes": [{"asset_id": "88636577098792919872169756031906573098016372635824568067326776673230264307456", "price": "0.971", "size": "70", "side": "BUY", "hash": "0c8ba0513117dae8bfa854c691997ae916d1f07c", "best_bid": "0.99", "best_ask": "0.992"}, {"asset_id": "70660622350061788470958401793650083315253654094558831635926320178723816495171", "price": "0.029", "size": "70", "side": "SELL", "hash": "e8404f62d71dee4ba2c2111c30c73c466d218486", "best_bid": "0.008", "best_ask": "0.01"}], "timestamp": "1769384445875", "event_type": "price_change"}}
{"_local_timestamp": "2026-01-25T23:40:46.127164+00:00", "data": {"market": "0x4d594c1480eab1db09f6c04c089f92d0a45844bdfae32a6f3f8391f99a1ea081", "price_changes": [{"asset_id": "88636577098792919872169756031906573098016372635824568067326776673230264307456", "price": "0.973", "size": "1441.54", "side": "BUY", "hash": "fb98b9b6558d00b9cfb7cc5c9ddce6241472f0a7", "best_bid": "0.99", "best_ask": "0.992"}, {"asset_id": "70660622350061788470958401793650083315253654094558831635926320178723816495171", "price": "0.027", "size": "1441.54", "side": "SELL", "hash": "ae2837cc224879b803a95d447dcf0940854193fd", "best_bid": "0.008", "best_ask": "0.01"}], "timestamp": "1769384446013", "event_type": "price_change"}}
{"_local_timestamp": "2026-01-25T23:40:46.166374+00:00", "data": {"market": "0xd87ac5bb74a21061d4f223d2a83c0269607fcb6d4c74d5a3d3220209d089431a", "price_changes": [{"asset_id": "73459237018178325517511938237778014293974381812181153063276727733805928508002", "price": "0.775", "size": "2200", "side": "BUY", "hash": "9b8fe69f55fdea7db1d4565a43f001ea460e801d", "best_bid": "0.802", "best_ask": "0.807"}, {"asset_id": "63433408040190943973509092025756868743192149481060781851142321049882584518043", "price": "0.225", "size": "2200", "side": "SELL", "hash": "8ccc04c9bb7c54e627f98f6f41bcad7b5f661dae", "best_bid": "0.193", "best_ask": "0.198"}], "timestamp": "1769384446095", "event_type": "price_change"}}
{"_local_timestamp": "2026-01-25T23:40:46.213656+00:00", "data": {"market": "0xd87ac5bb74a21061d4f223d2a83c0269607fcb6d4c74d5a3d3220209d089431a", "price_changes": [{"asset_id": "73459237018178325517511938237778014293974381812181153063276727733805928508002", "price": "0.775", "size": "2000", "side": "BUY", "hash": "6fd80a9748165f69505a9eb334bf4102d31e525f", "best_bid": "0.802", "best_ask": "0.807"}, {"asset_id": "63433408040190943973509092025756868743192149481060781851142321049882584518043", "price": "0.225", "size": "2000", "side": "SELL", "hash": "28ca2f59fb0c2f8f812a5150b923fce6aea7a09a", "best_bid": "0.193", "best_ask": "0.198"}], "timestamp": "1769384446148", "event_type": "price_change"}}
{"_local_timestamp": "2026-01-25T23:40:46.454894+00:00", "data": {"market": "0xd87ac5bb74a21061d4f223d2a83c0269607fcb6d4c74d5a3d3220209d089431a", "price_changes": [{"asset_id": "63433408040190943973509092025756868743192149481060781851142321049882584518043", "price": "0.187", "size": "210", "side": "BUY", "hash": "4cd9391c89878edfc6e9705abf07ac2f3b241292", "best_bid": "0.193", "best_ask": "0.198"}, {"asset_id": "73459237018178325517511938237778014293974381812181153063276727733805928508002", "price": "0.813", "size": "210", "side": "SELL", "hash": "5971f36ae2b64b88027c067482de039b45ab3fdb", "best_bid": "0.802", "best_ask": "0.807"}], "timestamp": "1769384446389", "event_type": "price_change"}}
{"_local_timestamp": "2026-01-25T23:40:46.694191+00:00", "data": {"market": "0x66af911f31ceabb5f9a3ef9203a73f0b23d18aa81bbba7888dec440c622c2528", "price_changes": [{"asset_id": "101818439776033928818471919550932857351051302350112396692573347503051307979709", "price": "0.26", "size": "46", "side": "BUY", "hash": "7b264d500fb998fd5f5f027125f0f02b325bc0bb", "best_bid": "0.3", "best_ask": "0.31"}, {"asset_id": "68639196051170795150992485552561385006521521637825690332014642323694437969760", "price": "0.74", "size": "46", "side": "SELL", "hash": "bfb8dd8ce581aa866ded7b047b1885f9c31095ad", "best_bid": "0.69", "best_ask": "0.7"}], "timestamp": "1769384446626", "event_type": "price_change"}}
{"_local_timestamp": "2026-01-25T23:40:46.725990+00:00", "data": {"market": "0x66af911f31ceabb5f9a3ef9203a73f0b23d18aa81bbba7888dec440c622c2528", "price_changes": [{"asset_id": "101818439776033928818471919550932857351051302350112396692573347503051307979709", "price": "0.25", "size": "210", "side": "BUY", "hash": "ee85660107281852020ecbe2e2940481024b4fc0", "best_bid": "0.3", "best_ask": "0.31"}, {"asset_id": "68639196051170795150992485552561385006521521637825690332014642323694437969760", "price": "0.75", "size": "210", "side": "SELL", "hash": "e19ae07f66957b5d088292b4fe40c81446831493", "best_bid": "0.69", "best_ask": "0.7"}], "timestamp": "1769384446651", "event_type": "price_change"}}
{"_local_timestamp": "2026-01-25T23:40:46.807662+00:00", "data": {"market": "0x66af911f31ceabb5f9a3ef9203a73f0b23d18aa81bbba7888dec440c622c2528", "price_changes": [{"asset_id": "101818439776033928818471919550932857351051302350112396692573347503051307979709", "price": "0.3", "size": "958.37", "side": "BUY", "hash": "2763f66cc5a33e82a74818bf7053e36706342088", "best_bid": "0.3", "best_ask": "0.31"}, {"asset_id": "68639196051170795150992485552561385006521521637825690332014642323694437969760", "price": "0.7", "size": "958.37", "side": "SELL", "hash": "e307d366b5563f5a814eecc63ea29e6a453677f0", "best_bid": "0.69", "best_ask": "0.7"}], "timestamp": "1769384446740", "event_type": "price_change"}}
{"_local_timestamp": "2026-01-25T23:40:46.944510+00:00", "data": {"market": "0x66af911f31ceabb5f9a3ef9203a73f0b23d18aa81bbba7888dec440c622c2528", "price_changes": [{"asset_id": "101818439776033928818471919550932857351051302350112396692573347503051307979709", "price": "0.3", "size": "908.37", "side": "BUY", "hash": "7bcb731ad0dff10038130a0699c5fd1c8f97cdc8", "best_bid": "0.3", "best_ask": "0.31"}, {"asset_id": "68639196051170795150992485552561385006521521637825690332014642323694437969760", "price": "0.7", "size": "908.37", "side": "SELL", "hash": "279d51d03bca254e7f67e2226e13bdfe0f5fb6ba", "best_bid": "0.69", "best_ask": "0.7"}], "timestamp": "1769384446873", "event_type": "price_change"}}
{"_local_timestamp": "2026-01-25T23:40:52.834051+00:00", "data": {"market": "0x101c26a9ff336abf4dffeb109dc40b92d9f55882dd471e57ee875794a6561bf3", "price_changes": [{"asset_id": "37082726066756590137696446997499452856763598243673867366591242252359474108530", "price": "0.007", "size": "7640.9", "side": "BUY", "hash": "ddb8518a56908e3c2e1bc219f96a6339ccad2655", "best_bid": "0.024", "best_ask": "0.025"}, {"asset_id": "41909517390337506269578561946393939690952797212331290191404935145632561531096", "price": "0.993", "size": "7640.9", "side": "SELL", "hash": "77d2f423b1dec4ef0279213cafeb975135a9d824", "best_bid": "0.975", "best_ask": "0.976"}], "timestamp": "1769384452762", "event_type": "price_change"}}
{"_local_timestamp": "2026-01-25T23:40:52.834529+00:00", "data": {"market": "0x101c26a9ff336abf4dffeb109dc40b92d9f55882dd471e57ee875794a6561bf3", "price_changes": [{"asset_id": "37082726066756590137696446997499452856763598243673867366591242252359474108530", "price": "0.011", "size": "12214.82", "side": "BUY", "hash": "f1425c5d1713124c2a7620285fae913297f8db6c", "best_bid": "0.024", "best_ask": "0.025"}, {"asset_id": "41909517390337506269578561946393939690952797212331290191404935145632561531096", "price": "0.989", "size": "12214.82", "side": "SELL", "hash": "c2ea9eb5f570aec105b54f0c805aa16c4e39be83", "best_bid": "0.975", "best_ask": "0.976"}], "timestamp": "1769384452763", "event_type": "price_change"}}
{"_local_timestamp": "2026-01-25T23:40:52.837341+00:00", "data": {"market": "0x101c26a9ff336abf4dffeb109dc40b92d9f55882dd471e57ee875794a6561bf3", "price_changes": [{"asset_id": "37082726066756590137696446997499452856763598243673867366591242252359474108530", "price": "0.015", "size": "5209.1", "side": "BUY", "hash": "f8e25e15f0d0a48e7ea31050917ea5a4409d4584", "best_bid": "0.024", "best_ask": "0.025"}, {"asset_id": "41909517390337506269578561946393939690952797212331290191404935145632561531096", "price": "0.985", "size": "5209.1", "side": "SELL", "hash": "7fda80b2882a7093ffc3d639482a436162f749be", "best_bid": "0.975", "best_ask": "0.976"}], "timestamp": "1769384452764", "event_type": "price_change"}}
{"_local_timestamp": "2026-01-25T23:40:52.948530+00:00", "data": {"market": "0x66af911f31ceabb5f9a3ef9203a73f0b23d18aa81bbba7888dec440c622c2528", "price_changes": [{"asset_id": "101818439776033928818471919550932857351051302350112396692573347503051307979709", "price": "0.3", "size": "958.37", "side": "BUY", "hash": "f27084053cd56752b89298b60ddc267b2691a0ab", "best_bid": "0.3", "best_ask": "0.31"}, {"asset_id": "68639196051170795150992485552561385006521521637825690332014642323694437969760", "price": "0.7", "size": "958.37", "side": "SELL", "hash": "793bc0f70bc6adaa4e18c078fa23c478c9c7302a", "best_bid": "0.69", "best_ask": "0.7"}], "timestamp": "1769384452880", "event_type": "price_change"}}
{"_local_timestamp": "2026-01-25T23:40:53.054405+00:00", "data": {"market": "0x66af911f31ceabb5f9a3ef9203a73f0b23d18aa81bbba7888dec440c622c2528", "price_changes": [{"asset_id": "101818439776033928818471919550932857351051302350112396692573347503051307979709", "price": "0.3", "size": "908.37", "side": "BUY", "hash": "2b500e2feedee4e8d7083de654b25db810d1bb89", "best_bid": "0.3", "best_ask": "0.31"}, {"asset_id": "68639196051170795150992485552561385006521521637825690332014642323694437969760", "price": "0.7", "size": "908.37", "side": "SELL", "hash": "8e279644301bbff54fbf8512def746b2f9b9bb03", "best_bid": "0.69", "best_ask": "0.7"}], "timestamp": "1769384452989", "event_type": "price_change"}}
{"_local_timestamp": "2026-01-25T23:40:55.441727+00:00", "data": {"market": "0xe0266da952c7be95f42d76770972075b57ac3823f876a4967b9a696bf7f77cb3", "price_changes": [{"asset_id": "101410416660845748603825473080512476735733815308377998129165131061476869070298", "price": "0.251", "size": "50", "side": "BUY", "hash": "e6234d56070592dda9a05517846f57435b29d59d", "best_bid": "0.997", "best_ask": "0.998"}, {"asset_id": "98364222367909646196463824162782128681453799377712476940174507012774514155648", "price": "0.749", "size": "50", "side": "SELL", "hash": "410a100dbb3af2ba38f4c8cfee2f85ea4d73c0db", "best_bid": "0.002", "best_ask": "0.003"}], "timestamp": "1769384455369", "event_type": "price_change"}}
{"_local_timestamp": "2026-01-25T23:40:55.606703+00:00", "data": {"market": "0x66af911f31ceabb5f9a3ef9203a73f0b23d18aa81bbba7888dec440c622c2528", "price_changes": [{"asset_id": "101818439776033928818471919550932857351051302350112396692573347503051307979709", "price": "0.3", "size": "958.37", "side": "BUY", "hash": "6fe885ef5167bf44f9cef1c721dc8138f4763163", "best_bid": "0.3", "best_ask": "0.31"}, {"asset_id": "68639196051170795150992485552561385006521521637825690332014642323694437969760", "price": "0.7", "size": "958.37", "side": "SELL", "hash": "a3d7076f37c6969548f7132e3f78fa319270a6c9", "best_bid": "0.69", "best_ask": "0.7"}], "timestamp": "1769384455491", "event_type": "price_change"}}
{"_local_timestamp": "2026-01-25T23:40:55.693369+00:00", "data": {"market": "0x66af911f31ceabb5f9a3ef9203a73f0b23d18aa81bbba7888dec440c622c2528", "price_changes": [{"asset_id": "101818439776033928818471919550932857351051302350112396692573347503051307979709", "price": "0.3", "size": "908.37", "side": "BUY", "hash": "ed444b929ea0c419e3486daf655dff23a3691de3", "best_bid": "0.3", "best_ask": "0.31"}, {"asset_id": "68639196051170795150992485552561385006521521637825690332014642323694437969760", "price": "0.7", "size": "908.37", "side": "SELL", "hash": "1de56bc26a4d5e75daa69acebf80c33b88a9bc6d", "best_bid": "0.69", "best_ask": "0.7"}], "timestamp": "1769384455621", "event_type": "price_change"}}
{"_local_timestamp": "2026-01-25T23:40:55.962111+00:00", "data": {"market": "0xe0266da952c7be95f42d76770972075b57ac3823f876a4967b9a696bf7f77cb3", "price_changes": [{"asset_id": "101410416660845748603825473080512476735733815308377998129165131061476869070298", "price": "0.203", "size": "2463", "side": "BUY", "hash": "b58514418e316522892eb98c91fcb86ea8e6fffc", "best_bid": "0.997", "best_ask": "0.998"}, {"asset_id": "98364222367909646196463824162782128681453799377712476940174507012774514155648", "price": "0.797", "size": "2463", "side": "SELL", "hash": "fa8c2784c79ed5f0600ba1bb76d5772420bc6077", "best_bid": "0.002", "best_ask": "0.003"}], "timestamp": "1769384455884", "event_type": "price_change"}}
{"_local_timestamp": "2026-01-25T23:41:06.834101+00:00", "data": {"market": "0x101c26a9ff336abf4dffeb109dc40b92d9f55882dd471e57ee875794a6561bf3", "price_changes": [{"asset_id": "37082726066756590137696446997499452856763598243673867366591242252359474108530", "price": "0.018", "size": "349.6", "side": "BUY", "hash": "9cf6717fbff03df3d5595e4b43b66e339a0e94f4", "best_bid": "0.024", "best_ask": "0.025"}, {"asset_id": "41909517390337506269578561946393939690952797212331290191404935145632561531096", "price": "0.982", "size": "349.6", "side": "SELL", "hash": "9d8d29a69fd1372f181ea99b8f4c1efe6ae07c69", "best_bid": "0.975", "best_ask": "0.976"}], "timestamp": "1769384466638", "event_type": "price_change"}}
{"_local_timestamp": "2026-01-25T23:41:06.854989+00:00", "data": {"market": "0xe0266da952c7be95f42d76770972075b57ac3823f876a4967b9a696bf7f77cb3", "price_changes": [{"asset_id": "98364222367909646196463824162782128681453799377712476940174507012774514155648", "price": "0.002", "size": "79130.5", "side": "BUY", "hash": "bb41a13e6f0cc2d9a947295a6dbc5d6261170591", "best_bid": "0.002", "best_ask": "0.003"}, {"asset_id": "101410416660845748603825473080512476735733815308377998129165131061476869070298", "price": "0.998", "size": "79130.5", "side": "SELL", "hash": "410cc6207014a4f2b49caf15e68852a5e9b748ce", "best_bid": "0.997", "best_ask": "0.998"}], "timestamp": "1769384466646", "event_type": "price_change"}}
{"_local_timestamp": "2026-01-25T23:41:06.890473+00:00", "data": {"market": "0x7dd03775ae64ca4da06121fd75397e3a16cd54bd02a52faee8c22799e34b8458", "price_changes": [{"asset_id": "19610288044512445018970900383394598704429716248417831382102395080716996421422", "price": "0.008", "size": "527.04", "side": "BUY", "hash": "c57208819f6f848155917e78b98723052123edea", "best_bid": "0.008", "best_ask": "0.009"}, {"asset_id": "101607178899252540003647394903771939183206092960905788946883703746586650017054", "price": "0.992", "size": "527.04", "side": "SELL", "hash": "37cfea6316e7c52f75c714ff4811d31d7746cda0", "best_bid": "0.991", "best_ask": "0.992"}], "timestamp": "1769384466645", "event_type": "price_change"}}
{"_local_timestamp": "2026-01-25T23:41:06.921472+00:00", "data": {"market": "0x4d594c1480eab1db09f6c04c089f92d0a45844bdfae32a6f3f8391f99a1ea081", "price_changes": [{"asset_id": "70660622350061788470958401793650083315253654094558831635926320178723816495171", "price": "0.008", "size": "440.38", "side": "BUY", "hash": "3175d4125e925922b6169406a0918685d2f46999", "best_bid": "0.008", "best_ask": "0.01"}, {"asset_id": "88636577098792919872169756031906573098016372635824568067326776673230264307456", "price": "0.992", "size": "440.38", "side": "SELL", "hash": "6c97ee4baf8fa0b437ca2167c595a546821e41db", "best_bid": "0.99", "best_ask": "0.992"}], "timestamp": "1769384466652", "event_type": "price_change"}}
{"_local_timestamp": "2026-01-25T23:41:06.937018+00:00", "data": {"market": "0x7dd03775ae64ca4da06121fd75397e3a16cd54bd02a52faee8c22799e34b8458", "price_changes": [{"asset_id": "101607178899252540003647394903771939183206092960905788946883703746586650017054", "price": "0.971", "size": "0", "side": "BUY", "hash": "732b3a452d18ecb6034fc4d9e56bec66472be33a", "best_bid": "0.991", "best_ask": "0.992"}, {"asset_id": "19610288044512445018970900383394598704429716248417831382102395080716996421422", "price": "0.029", "size": "0", "side": "SELL", "hash": "1734d06bf63c81a0c74f8edc2fbdcd2e30a681f5", "best_bid": "0.008", "best_ask": "0.009"}], "timestamp": "1769384466808", "event_type": "price_change"}}
{"_local_timestamp": "2026-01-25T23:41:07.032658+00:00", "data": {"market": "0x66af911f31ceabb5f9a3ef9203a73f0b23d18aa81bbba7888dec440c622c2528", "price_changes": [{"asset_id": "101818439776033928818471919550932857351051302350112396692573347503051307979709", "price": "0.3", "size": "958.37", "side": "BUY", "hash": "e19d121bc49dff512e5f1f0404933bc4074eb356", "best_bid": "0.3", "best_ask": "0.31"}, {"asset_id": "68639196051170795150992485552561385006521521637825690332014642323694437969760", "price": "0.7", "size": "958.37", "side": "SELL", "hash": "084a20bf67fb4b87e0791da027aaf23873d9f954", "best_bid": "0.69", "best_ask": "0.7"}], "timestamp": "1769384466881", "event_type": "price_change"}}
{"_local_timestamp": "2026-01-25T23:41:07.051267+00:00", "data": {"market": "0x7dd03775ae64ca4da06121fd75397e3a16cd54bd02a52faee8c22799e34b8458", "price_changes": [{"asset_id": "101607178899252540003647394903771939183206092960905788946883703746586650017054", "price": "0.972", "size": "20", "side": "BUY", "hash": "4ebe4a1169b1d981cbf9091e81b5dd1c6357cbc2", "best_bid": "0.991", "best_ask": "0.992"}, {"asset_id": "19610288044512445018970900383394598704429716248417831382102395080716996421422", "price": "0.028", "size": "20", "side": "SELL", "hash": "e7b1eb8bb0c24f834bbdb101817a1df71b7a38c4", "best_bid": "0.008", "best_ask": "0.009"}], "timestamp": "1769384466882", "event_type": "price_change"}}
{"_local_timestamp": "2026-01-25T23:41:07.056762+00:00", "data": {"market": "0x66af911f31ceabb5f9a3ef9203a73f0b23d18aa81bbba7888dec440c622c2528", "price_changes": [{"asset_id": "101818439776033928818471919550932857351051302350112396692573347503051307979709", "price": "0.3", "size": "908.37", "side": "BUY", "hash": "e8e56c263bf8f0d18e98504c3752a3e6df1c0ee4", "best_bid": "0.3", "best_ask": "0.31"}, {"asset_id": "68639196051170795150992485552561385006521521637825690332014642323694437969760", "price": "0.7", "size": "908.37", "side": "SELL", "hash": "dca39c7048817f96ee49fe9ee63d771b72663acf", "best_bid": "0.69", "best_ask": "0.7"}], "timestamp": "1769384466983", "event_type": "price_change"}}
{"_local_timestamp": "2026-01-25T23:41:10.088558+00:00", "data": {"market": "0x7dd03775ae64ca4da06121fd75397e3a16cd54bd02a52faee8c22799e34b8458", "price_changes": [{"asset_id": "101607178899252540003647394903771939183206092960905788946883703746586650017054", "price": "0.985", "size": "0", "side": "BUY", "hash": "7a69d7f211930077364adca382ab18c16b42507f", "best_bid": "0.991", "best_ask": "0.992"}, {"asset_id": "19610288044512445018970900383394598704429716248417831382102395080716996421422", "price": "0.015", "size": "0", "side": "SELL", "hash": "dec29e8cad8ede9cdc4e96bf23151dc389304978", "best_bid": "0.008", "best_ask": "0.009"}], "timestamp": "1769384470000", "event_type": "price_change"}}
{"_local_timestamp": "2026-01-25T23:41:10.191815+00:00", "data": {"market": "0x66af911f31ceabb5f9a3ef9203a73f0b23d18aa81bbba7888dec440c622c2528", "price_changes": [{"asset_id": "101818439776033928818471919550932857351051302350112396692573347503051307979709", "price": "0.3", "size": "958.37", "side": "BUY", "hash": "8cc37efc7c9f961e6ba8f01de0e8a5a6d42979c8", "best_bid": "0.3", "best_ask": "0.31"}, {"asset_id": "68639196051170795150992485552561385006521521637825690332014642323694437969760", "price": "0.7", "size": "958.37", "side": "SELL", "hash": "fe55f50cb33fa444c28474299fc071343ac558cf", "best_bid": "0.69", "best_ask": "0.7"}], "timestamp": "1769384470120", "event_type": "price_change"}}
{"_local_timestamp": "2026-01-25T23:41:10.230610+00:00", "data": {"market": "0x7dd03775ae64ca4da06121fd75397e3a16cd54bd02a52faee8c22799e34b8458", "price_changes": [{"asset_id": "101607178899252540003647394903771939183206092960905788946883703746586650017054", "price": "0.978", "size": "50", "side": "BUY", "hash": "0b27e04358ec61057038cce1ae43d5527f866688", "best_bid": "0.991", "best_ask": "0.992"}, {"asset_id": "19610288044512445018970900383394598704429716248417831382102395080716996421422", "price": "0.022", "size": "50", "side": "SELL", "hash": "9f6e2fefad4bc89467ba1fc6d757ff5abeb98119", "best_bid": "0.008", "best_ask": "0.009"}], "timestamp": "1769384470150", "event_type": "price_change"}}
{"_local_timestamp": "2026-01-25T23:41:10.232269+00:00", "data": {"market": "0x7dd03775ae64ca4da06121fd75397e3a16cd54bd02a52faee8c22799e34b8458", "price_changes": [{"asset_id": "101607178899252540003647394903771939183206092960905788946883703746586650017054", "price": "0.973", "size": "150", "side": "BUY", "hash": "f74e933ec3c74f6440eb2d16c489a414ed8ecc49", "best_bid": "0.991", "best_ask": "0.992"}, {"asset_id": "19610288044512445018970900383394598704429716248417831382102395080716996421422", "price": "0.027", "size": "150", "side": "SELL", "hash": "92b66135e017f51a8bfcf34738f9a4081b7f3d08", "best_bid": "0.008", "best_ask": "0.009"}], "timestamp": "1769384470159", "event_type": "price_change"}}
{"_local_timestamp": "2026-01-25T23:41:10.293736+00:00", "data": {"market": "0x66af911f31ceabb5f9a3ef9203a73f0b23d18aa81bbba7888dec440c622c2528", "price_changes": [{"asset_id": "101818439776033928818471919550932857351051302350112396692573347503051307979709", "price": "0.3", "size": "908.37", "side": "BUY", "hash": "779ddc8e03500cc01a6de86e8b30ef7708676544", "best_bid": "0.3", "best_ask": "0.31"}, {"asset_id": "68639196051170795150992485552561385006521521637825690332014642323694437969760", "price": "0.7", "size": "908.37", "side": "SELL", "hash": "6265d57bf492294af2be94f1c05eedefb1ab34b5", "best_bid": "0.69", "best_ask": "0.7"}], "timestamp": "1769384470227", "event_type": "price_change"}}
{"_local_timestamp": "2026-01-25T23:41:10.390450+00:00", "data": {"market": "0x7dd03775ae64ca4da06121fd75397e3a16cd54bd02a52faee8c22799e34b8458", "price_changes": [{"asset_id": "101607178899252540003647394903771939183206092960905788946883703746586650017054", "price": "0.978", "size": "0", "side": "BUY", "hash": "fc3f686f33e4f74aee3d57e091c9d349b426712a", "best_bid": "0.991", "best_ask": "0.992"}, {"asset_id": "19610288044512445018970900383394598704429716248417831382102395080716996421422", "price": "0.022", "size": "0", "side": "SELL", "hash": "b4949dbc8989e290b18060909fe961a69dccb247", "best_bid": "0.008", "best_ask": "0.009"}], "timestamp": "1769384470317", "event_type": "price_change"}}
{"_local_timestamp": "2026-01-25T23:41:14.743611+00:00", "data": {"market": "0xd87ac5bb74a21061d4f223d2a83c0269607fcb6d4c74d5a3d3220209d089431a", "price_changes": [{"asset_id": "73459237018178325517511938237778014293974381812181153063276727733805928508002", "price": "0.788", "size": "547", "side": "BUY", "hash": "f6a3f2c7c518488c3adaa5a0b0aa7b7337124508", "best_bid": "0.802", "best_ask": "0.807"}, {"asset_id": "63433408040190943973509092025756868743192149481060781851142321049882584518043", "price": "0.212", "size": "547", "side": "SELL", "hash": "bd32edf92630057f02954a89a531e6df1a4a507b", "best_bid": "0.193", "best_ask": "0.198"}], "timestamp": "1769384474542", "event_type": "price_change"}}
{"_local_timestamp": "2026-01-25T23:41:14.750774+00:00", "data": {"market": "0xd87ac5bb74a21061d4f223d2a83c0269607fcb6d4c74d5a3d3220209d089431a", "price_changes": [{"asset_id": "63433408040190943973509092025756868743192149481060781851142321049882584518043", "price": "0.183", "size": "949.75", "side": "BUY", "hash": "ed22a3d62895409d7a04dc1e14635126f6c2a607", "best_bid": "0.193", "best_ask": "0.198"}, {"asset_id": "73459237018178325517511938237778014293974381812181153063276727733805928508002", "price": "0.817", "size": "949.75", "side": "SELL", "hash": "c3c74d39371c4180dcdfa896eb3ba616e937fd85", "best_bid": "0.802", "best_ask": "0.807"}], "timestamp": "1769384474543", "event_type": "price_change"}}
{"_local_timestamp": "2026-01-25T23:41:14.867112+00:00", "data": {"market": "0xd87ac5bb74a21061d4f223d2a83c0269607fcb6d4c74d5a3d3220209d089431a", "price_changes": [{"asset_id": "63433408040190943973509092025756868743192149481060781851142321049882584518043", "price": "0.166", "size": "500", "side": "BUY", "hash": "9a5a94d5246ab9842049fad175af8a0faba9b51d", "best_bid": "0.193", "best_ask": "0.198"}, {"asset_id": "73459237018178325517511938237778014293974381812181153063276727733805928508002", "price": "0.834", "size": "500", "side": "SELL", "hash": "eec09a9f7b9c13bbba03a91c9afca9ff6b688d97", "best_bid": "0.802", "best_ask": "0.807"}], "timestamp": "1769384474750", "event_type": "price_change"}}
{"_local_timestamp": "2026-01-25T23:41:14.898437+00:00", "data": {"market": "0x7dd03775ae64ca4da06121fd75397e3a16cd54bd02a52faee8c22799e34b8458", "price_changes": [{"asset_id": "101607178899252540003647394903771939183206092960905788946883703746586650017054", "price": "0.973", "size": "0", "side": "BUY", "hash": "b83af9e343bbee6d1e9f557f8398297dcbb0cd8b", "best_bid": "0.991", "best_ask": "0.992"}, {"asset_id": "19610288044512445018970900383394598704429716248417831382102395080716996421422", "price": "0.027", "size": "0", "side": "SELL", "hash": "5c373ddc8a27f0b689e3e4f0b38421a30fb7b7ad", "best_bid": "0.008", "best_ask": "0.009"}], "timestamp": "1769384474790", "event_type": "price_change"}}
{"_local_timestamp": "2026-01-25T23:41:14.907646+00:00", "data": {"market": "0x66af911f31ceabb5f9a3ef9203a73f0b23d18aa81bbba7888dec440c622c2528", "price_changes": [{"asset_id": "101818439776033928818471919550932857351051302350112396692573347503051307979709", "price": "0.3", "size": "958.37", "side": "BUY", "hash": "912752771d0baf9efbeb15f69c0220a465620520", "best_bid": "0.3", "best_ask": "0.31"}, {"asset_id": "68639196051170795150992485552561385006521521637825690332014642323694437969760", "price": "0.7", "size": "958.37", "side": "SELL", "hash": "09f847246591e0183529c2fbea5680541b982e85", "best_bid": "0.69", "best_ask": "0.7"}], "timestamp": "1769384474792", "event_type": "price_change"}}
{"_local_timestamp": "2026-01-25T23:41:14.913779+00:00", "data": {"market": "0x66af911f31ceabb5f9a3ef9203a73f0b23d18aa81bbba7888dec440c622c2528", "price_changes": [{"asset_id": "101818439776033928818471919550932857351051302350112396692573347503051307979709", "price": "0.27", "size": "538.53", "side": "BUY", "hash": "4f91d47989da9b92a099b4155fa60ac28934d993", "best_bid": "0.3", "best_ask": "0.31"}, {"asset_id": "68639196051170795150992485552561385006521521637825690332014642323694437969760", "price": "0.73", "size": "538.53", "side": "SELL", "hash": "404052d389286eda064de108d9b8ef3331d111f8", "best_bid": "0.69", "best_ask": "0.7"}], "timestamp": "1769384474796", "event_type": "price_change"}}
{"_local_timestamp": "2026-01-25T23:41:14.947094+00:00", "data": {"market": "0x7dd03775ae64ca4da06121fd75397e3a16cd54bd02a52faee8c22799e34b8458", "price_changes": [{"asset_id": "101607178899252540003647394903771939183206092960905788946883703746586650017054", "price": "0.978", "size": "50", "side": "BUY", "hash": "bf1bf2b115dcc5f1de321275f7db673a15831289", "best_bid": "0.991", "best_ask": "0.992"}, {"asset_id": "19610288044512445018970900383394598704429716248417831382102395080716996421422", "price": "0.022", "size": "50", "side": "SELL", "hash": "6ab7231bef7ec652bc7c92bfe72c583322b5682e", "best_bid": "0.008", "best_ask": "0.009"}], "timestamp": "1769384474812", "event_type": "price_change"}}
{"_local_timestamp": "2026-01-25T23:41:14.979094+00:00", "data": {"market": "0x66af911f31ceabb5f9a3ef9203a73f0b23d18aa81bbba7888dec440c622c2528", "price_changes": [{"asset_id": "101818439776033928818471919550932857351051302350112396692573347503051307979709", "price": "0.3", "size": "908.37", "side": "BUY", "hash": "9e87f368a4a5441d8fc5fd68808044dfa049c1f2", "best_bid": "0.3", "best_ask": "0.31"}, {"asset_id": "68639196051170795150992485552561385006521521637825690332014642323694437969760", "price": "0.7", "size": "908.37", "side": "SELL", "hash": "09f770a651fd2a62db3986d04ae833459a1e0b0d", "best_bid": "0.69", "best_ask": "0.7"}], "timestamp": "1769384474911", "event_type": "price_change"}}
{"_local_timestamp": "2026-01-25T23:41:14.984868+00:00", "data": {"market": "0x7dd03775ae64ca4da06121fd75397e3a16cd54bd02a52faee8c22799e34b8458", "price_changes": [{"asset_id": "101607178899252540003647394903771939183206092960905788946883703746586650017054", "price": "0.978", "size": "0", "side": "BUY", "hash": "f246ea28d3f6dddc21c00a41d52ddaf13158f1d6", "best_bid": "0.991", "best_ask": "0.992"}, {"asset_id": "19610288044512445018970900383394598704429716248417831382102395080716996421422", "price": "0.022", "size": "0", "side": "SELL", "hash": "04353f16b73c143cafeec1c08e90e4da0b231948", "best_bid": "0.008", "best_ask": "0.009"}], "timestamp": "1769384474918", "event_type": "price_change"}}
{"_local_timestamp": "2026-01-25T23:41:15.022539+00:00", "data": {"market": "0x7dd03775ae64ca4da06121fd75397e3a16cd54bd02a52faee8c22799e34b8458", "price_changes": [{"asset_id": "101607178899252540003647394903771939183206092960905788946883703746586650017054", "price": "0.978", "size": "50", "side": "BUY", "hash": "43535f66e9cf122af1062fa6200e7c3566bb3388", "best_bid": "0.991", "best_ask": "0.992"}, {"asset_id": "19610288044512445018970900383394598704429716248417831382102395080716996421422", "price": "0.022", "size": "50", "side": "SELL", "hash": "87bd06de5ece3758f071c7ae0c9fd7cd23fca1d1", "best_bid": "0.008", "best_ask": "0.009"}], "timestamp": "1769384474950", "event_type": "price_change"}}
{"_local_timestamp": "2026-01-25T23:41:15.121260+00:00", "data": {"market": "0x7dd03775ae64ca4da06121fd75397e3a16cd54bd02a52faee8c22799e34b8458", "price_changes": [{"asset_id": "101607178899252540003647394903771939183206092960905788946883703746586650017054", "price": "0.978", "size": "0", "side": "BUY", "hash": "965d2cba9a0e08b7cd464a727aeb309d63cd2280", "best_bid": "0.991", "best_ask": "0.992"}, {"asset_id": "19610288044512445018970900383394598704429716248417831382102395080716996421422", "price": "0.022", "size": "0", "side": "SELL", "hash": "5dde93975468f69d6bb4d79d2a6fcf59d549baf8", "best_bid": "0.008", "best_ask": "0.009"}], "timestamp": "1769384475056", "event_type": "price_change"}}
{"_local_timestamp": "2026-01-25T23:41:15.361280+00:00", "data": {"market": "0xd87ac5bb74a21061d4f223d2a83c0269607fcb6d4c74d5a3d3220209d089431a", "price_changes": [{"asset_id": "63433408040190943973509092025756868743192149481060781851142321049882584518043", "price": "0.194", "size": "329", "side": "BUY", "hash": "bcd18275111a30ef920e8b0f1614eb31aa1252f4", "best_bid": "0.194", "best_ask": "0.198"}, {"asset_id": "73459237018178325517511938237778014293974381812181153063276727733805928508002", "price": "0.806", "size": "329", "side": "SELL", "hash": "7c2bad0ddab104c4547c6cf55733bbbf4a975fe9", "best_bid": "0.802", "best_ask": "0.806"}], "timestamp": "1769384475291", "event_type": "price_change"}}
{"_local_timestamp": "2026-01-25T23:41:15.393104+00:00", "data": {"market": "0x101c26a9ff336abf4dffeb109dc40b92d9f55882dd471e57ee875794a6561bf3", "price_changes": [{"asset_id": "41909517390337506269578561946393939690952797212331290191404935145632561531096", "price": "0.974", "size": "0", "side": "BUY", "hash": "1484bb5eb028c2fe0b6f593f39475c1f5013bf97", "best_bid": "0.975", "best_ask": "0.976"}, {"asset_id": "37082726066756590137696446997499452856763598243673867366591242252359474108530", "price": "0.026", "size": "0", "side": "SELL", "hash": "d94edbdc5baa15e7ee769b88b19b36e07564ec5b", "best_bid": "0.024", "best_ask": "0.025"}], "timestamp": "1769384475316", "event_type": "price_change"}}
{"_local_timestamp": "2026-01-25T23:41:15.413164+00:00", "data": {"market": "0x101c26a9ff336abf4dffeb109dc40b92d9f55882dd471e57ee875794a6561bf3", "price_changes": [{"asset_id": "41909517390337506269578561946393939690952797212331290191404935145632561531096", "price": "0.975", "size": "120", "side": "BUY", "hash": "e929141acb4186b0b5681e885ef8fdb47c133c18", "best_bid": "0.975", "best_ask": "0.976"}, {"asset_id": "37082726066756590137696446997499452856763598243673867366591242252359474108530", "price": "0.025", "size": "120", "side": "SELL", "hash": "78c4e3a113fdec3d2f9fcd8b328cd928ed84315b", "best_bid": "0.024", "best_ask": "0.025"}], "timestamp": "1769384475339", "event_type": "price_change"}}
{"_local_timestamp": "2026-01-25T23:41:15.434972+00:00", "data": {"market": "0xd87ac5bb74a21061d4f223d2a83c0269607fcb6d4c74d5a3d3220209d089431a", "price_changes": [{"asset_id": "73459237018178325517511938237778014293974381812181153063276727733805928508002", "price": "0.774", "size": "300", "side": "BUY", "hash": "b9a8b3cca4484c57508c1d300b6ad6d3cc6f5130", "best_bid": "0.802", "best_ask": "0.806"}, {"asset_id": "63433408040190943973509092025756868743192149481060781851142321049882584518043", "price": "0.226", "size": "300", "side": "SELL", "hash": "d02905e365bde532981a9420b7548b679e9f3346", "best_bid": "0.194", "best_ask": "0.198"}], "timestamp": "1769384475361", "event_type": "price_change"}}
{"_local_timestamp": "2026-01-25T23:41:15.485603+00:00", "data": {"market": "0xd87ac5bb74a21061d4f223d2a83c0269607fcb6d4c74d5a3d3220209d089431a", "price_changes": [{"asset_id": "63433408040190943973509092025756868743192149481060781851142321049882584518043", "price": "0.187", "size": "0", "side": "BUY", "hash": "67bece510dc679358208b14606e5cbf724c8c167", "best_bid": "0.194", "best_ask": "0.198"}, {"asset_id": "73459237018178325517511938237778014293974381812181153063276727733805928508002", "price": "0.813", "size": "0", "side": "SELL", "hash": "7c825fe7f6b4ec282188defe73e46835d55898b7", "best_bid": "0.802", "best_ask": "0.806"}], "timestamp": "1769384475414", "event_type": "price_change"}}
{"_local_timestamp": "2026-01-25T23:41:15.485989+00:00", "data": {"market": "0xd87ac5bb74a21061d4f223d2a83c0269607fcb6d4c74d5a3d3220209d089431a", "price_changes": [{"asset_id": "73459237018178325517511938237778014293974381812181153063276727733805928508002", "price": "0.79", "size": "50", "side": "BUY", "hash": "1d85334ccb7bc3e52189fae4ae4cbcdb971ed61f", "best_bid": "0.802", "best_ask": "0.806"}, {"asset_id": "63433408040190943973509092025756868743192149481060781851142321049882584518043", "price": "0.21", "size": "50", "side": "SELL", "hash": "70f7aecc64c18f3d4de7be85b9112f268481b9b9", "best_bid": "0.194", "best_ask": "0.198"}], "timestamp": "1769384475415", "event_type": "price_change"}}
{"_local_timestamp": "2026-01-25T23:41:15.536641+00:00", "data": {"market": "0xd87ac5bb74a21061d4f223d2a83c0269607fcb6d4c74d5a3d3220209d089431a", "price_changes": [{"asset_id": "73459237018178325517511938237778014293974381812181153063276727733805928508002", "price": "0.775", "size": "2200", "side": "BUY", "hash": "6d8a97b46b7d8bdc7cab729a4c0d1d02af403fae", "best_bid": "0.802", "best_ask": "0.806"}, {"asset_id": "63433408040190943973509092025756868743192149481060781851142321049882584518043", "price": "0.225", "size": "2200", "side": "SELL", "hash": "f9e3dfe0dada410663be650e4287e1fa3533b156", "best_bid": "0.194", "best_ask": "0.198"}], "timestamp": "1769384475470", "event_type": "price_change"}}
{"_local_timestamp": "2026-01-25T23:41:15.543139+00:00", "data": {"market": "0x66af911f31ceabb5f9a3ef9203a73f0b23d18aa81bbba7888dec440c622c2528", "price_changes": [{"asset_id": "101818439776033928818471919550932857351051302350112396692573347503051307979709", "price": "0.29", "size": "2743.08", "side": "BUY", "hash": "0aeabf91ad89d7b965c8edcaa3b0682e2600322e", "best_bid": "0.3", "best_ask": "0.31"}, {"asset_id": "68639196051170795150992485552561385006521521637825690332014642323694437969760", "price": "0.71", "size": "2743.08", "side": "SELL", "hash": "ae99037465a2177b3487c464d101a7529afddfdc", "best_bid": "0.69", "best_ask": "0.7"}], "timestamp": "1769384475474", "event_type": "price_change"}}
{"_local_timestamp": "2026-01-25T23:41:15.551254+00:00", "data": {"market": "0xd87ac5bb74a21061d4f223d2a83c0269607fcb6d4c74d5a3d3220209d089431a", "price_changes": [{"asset_id": "73459237018178325517511938237778014293974381812181153063276727733805928508002", "price": "0.775", "size": "2400", "side": "BUY", "hash": "a3f19d3db81288edc3b71875f3b2f89e61bff8b6", "best_bid": "0.802", "best_ask": "0.806"}, {"asset_id": "63433408040190943973509092025756868743192149481060781851142321049882584518043", "price": "0.225", "size": "2400", "side": "SELL", "hash": "c917162e875ac59b754627f5811349c75dcafd2f", "best_bid": "0.194", "best_ask": "0.198"}], "timestamp": "1769384475475", "event_type": "price_change"}}
{"_local_timestamp": "2026-01-25T23:41:15.604665+00:00", "data": {"market": "0x66af911f31ceabb5f9a3ef9203a73f0b23d18aa81bbba7888dec440c622c2528", "price_changes": [{"asset_id": "101818439776033928818471919550932857351051302350112396692573347503051307979709", "price": "0.27", "size": "138.53", "side": "BUY", "hash": "3e8fa248c636ea564a3842a4213da10ac3a79af6", "best_bid": "0.3", "best_ask": "0.31"}, {"asset_id": "68639196051170795150992485552561385006521521637825690332014642323694437969760", "price": "0.73", "size": "138.53", "side": "SELL", "hash": "3498bf5e25e67e6a69274532beeb5e4b767d1b20", "best_bid": "0.69", "best_ask": "0.7"}], "timestamp": "1769384475531", "event_type": "price_change"}}
{"_local_timestamp": "2026-01-25T23:41:16.062158+00:00", "data": {"market": "0x66af911f31ceabb5f9a3ef9203a73f0b23d18aa81bbba7888dec440c622c2528", "price_changes": [{"asset_id": "101818439776033928818471919550932857351051302350112396692573347503051307979709", "price": "0.25", "size": "190", "side": "BUY", "hash": "b45981f5319274d64b04a7a89872855965abe1b2", "best_bid": "0.3", "best_ask": "0.31"}, {"asset_id": "68639196051170795150992485552561385006521521637825690332014642323694437969760", "price": "0.75", "size": "190", "side": "SELL", "hash": "5dcf4e1306637dd79b83cb6f6b3578f1d2fd393f", "best_bid": "0.69", "best_ask": "0.7"}], "timestamp": "1769384475992", "event_type": "price_change"}}
{"_local_timestamp": "2026-01-25T23:41:16.094753+00:00", "data": {"market": "0x66af911f31ceabb5f9a3ef9203a73f0b23d18aa81bbba7888dec440c622c2528", "price_changes": [{"asset_id": "101818439776033928818471919550932857351051302350112396692573347503051307979709", "price": "0.26", "size": "66", "side": "BUY", "hash": "ab1981d6faf99f463c2a7fdfcbe278efaf083c5a", "best_bid": "0.3", "best_ask": "0.31"}, {"asset_id": "68639196051170795150992485552561385006521521637825690332014642323694437969760", "price": "0.74", "size": "66", "side": "SELL", "hash": "f94ed0dd0b21999f4a1aa1f6deb4415fbc563ea2", "best_bid": "0.69", "best_ask": "0.7"}], "timestamp": "1769384476019", "event_type": "price_change"}}
{"_local_timestamp": "2026-01-25T23:41:16.191697+00:00", "data": {"market": "0x66af911f31ceabb5f9a3ef9203a73f0b23d18aa81bbba7888dec440c622c2528", "price_changes": [{"asset_id": "101818439776033928818471919550932857351051302350112396692573347503051307979709", "price": "0.3", "size": "958.37", "side": "BUY", "hash": "dc6db14fc897b4973566fd5bd478d5679956e487", "best_bid": "0.3", "best_ask": "0.31"}, {"asset_id": "68639196051170795150992485552561385006521521637825690332014642323694437969760", "price": "0.7", "size": "958.37", "side": "SELL", "hash": "f6b25f7137eab3ea5ad07167fc8bbf484992da6b", "best_bid": "0.69", "best_ask": "0.7"}], "timestamp": "1769384476118", "event_type": "price_change"}}
{"_local_timestamp": "2026-01-25T23:41:16.304321+00:00", "data": {"market": "0x66af911f31ceabb5f9a3ef9203a73f0b23d18aa81bbba7888dec440c622c2528", "price_changes": [{"asset_id": "101818439776033928818471919550932857351051302350112396692573347503051307979709", "price": "0.3", "size": "908.37", "side": "BUY", "hash": "c1b0a8ab4a08cf7f85a4719c863f3b173de86b7f", "best_bid": "0.3", "best_ask": "0.31"}, {"asset_id": "68639196051170795150992485552561385006521521637825690332014642323694437969760", "price": "0.7", "size": "908.37", "side": "SELL", "hash": "bfdf4967814fe6a94df1e90d60f60b5ab64ab4c3", "best_bid": "0.69", "best_ask": "0.7"}], "timestamp": "1769384476239", "event_type": "price_change"}}
{"_local_timestamp": "2026-01-25T23:41:16.320500+00:00", "data": {"market": "0xd87ac5bb74a21061d4f223d2a83c0269607fcb6d4c74d5a3d3220209d089431a", "price_changes": [{"asset_id": "63433408040190943973509092025756868743192149481060781851142321049882584518043", "price": "0.188", "size": "220", "side": "BUY", "hash": "2972c90eff07c17fc860333612cdfdaf33d821a4", "best_bid": "0.194", "best_ask": "0.198"}, {"asset_id": "73459237018178325517511938237778014293974381812181153063276727733805928508002", "price": "0.812", "size": "220", "side": "SELL", "hash": "19c5a6c56a3b8f8484084e03d06df9c67ab98eee", "best_bid": "0.802", "best_ask": "0.806"}], "timestamp": "1769384476249", "event_type": "price_change"}}
{"_local_timestamp": "2026-01-25T23:41:16.322821+00:00", "data": {"market": "0xd87ac5bb74a21061d4f223d2a83c0269607fcb6d4c74d5a3d3220209d089431a", "price_changes": [{"asset_id": "73459237018178325517511938237778014293974381812181153063276727733805928508002", "price": "0.792", "size": "538.74", "side": "BUY", "hash": "0e2bc9d360854c185df78c95f6567dfddd903353", "best_bid": "0.802", "best_ask": "0.806"}, {"asset_id": "63433408040190943973509092025756868743192149481060781851142321049882584518043", "price": "0.208", "size": "538.74", "side": "SELL", "hash": "db09e274617d611f44d5bed75658e9b5538ff46b", "best_bid": "0.194", "best_ask": "0.198"}], "timestamp": "1769384476250", "event_type": "price_change"}}
{"_local_timestamp": "2026-01-25T23:41:16.566580+00:00", "data": {"market": "0x66af911f31ceabb5f9a3ef9203a73f0b23d18aa81bbba7888dec440c622c2528", "price_changes": [{"asset_id": "101818439776033928818471919550932857351051302350112396692573347503051307979709", "price": "0.27", "size": "538.53", "side": "BUY", "hash": "3acb8e667f2235e3cff1daa1b33e181a98163496", "best_bid": "0.3", "best_ask": "0.31"}, {"asset_id": "68639196051170795150992485552561385006521521637825690332014642323694437969760", "price": "0.73", "size": "538.53", "side": "SELL", "hash": "91ce55dfd43fc55da3f8f65ea525cc5d1c8c0fa1", "best_bid": "0.69", "best_ask": "0.7"}], "timestamp": "1769384476504", "event_type": "price_change"}}
{"_local_timestamp": "2026-01-25T23:41:16.860843+00:00", "data": {"market": "0xd87ac5bb74a21061d4f223d2a83c0269607fcb6d4c74d5a3d3220209d089431a", "price_changes": [{"asset_id": "63433408040190943973509092025756868743192149481060781851142321049882584518043", "price": "0.194", "size": "0", "side": "BUY", "hash": "526bd875adc0ff98ef3f70dcf9af00b10db7074c", "best_bid": "0.193", "best_ask": "0.198"}, {"asset_id": "73459237018178325517511938237778014293974381812181153063276727733805928508002", "price": "0.806", "size": "0", "side": "SELL", "hash": "9f9abec8f07cc0226f9dd8c5567f0a63386de81e", "best_bid": "0.802", "best_ask": "0.807"}], "timestamp": "1769384476791", "event_type": "price_change"}}
{"_local_timestamp": "2026-01-25T23:41:16.881548+00:00", "data": {"market": "0x101c26a9ff336abf4dffeb109dc40b92d9f55882dd471e57ee875794a6561bf3", "price_changes": [{"asset_id": "41909517390337506269578561946393939690952797212331290191404935145632561531096", "price": "0.975", "size": "100", "side": "BUY", "hash": "2ea49ffe3d76062b82becc57b4e9cecb42f41f79", "best_bid": "0.975", "best_ask": "0.976"}, {"asset_id": "37082726066756590137696446997499452856763598243673867366591242252359474108530", "price": "0.025", "size": "100", "side": "SELL", "hash": "11616f7759d145bb7d5cc2074aac4f2fdb72c256", "best_bid": "0.024", "best_ask": "0.025"}], "timestamp": "1769384476813", "event_type": "price_change"}}
{"_local_timestamp": "2026-01-25T23:41:16.913175+00:00", "data": {"market": "0x101c26a9ff336abf4dffeb109dc40b92d9f55882dd471e57ee875794a6561bf3", "price_changes": [{"asset_id": "41909517390337506269578561946393939690952797212331290191404935145632561531096", "price": "0.974", "size": "20", "side": "BUY", "hash": "2874bcee26f42495a165450d74298741495da2da", "best_bid": "0.975", "best_ask": "0.976"}, {"asset_id": "37082726066756590137696446997499452856763598243673867366591242252359474108530", "price": "0.026", "size": "20", "side": "SELL", "hash": "7be5283ad8529ab244f7d3812752dd02d804738d", "best_bid": "0.024", "best_ask": "0.025"}], "timestamp": "1769384476840", "event_type": "price_change"}}
{"_local_timestamp": "2026-01-25T23:41:16.981435+00:00", "data": {"market": "0xd87ac5bb74a21061d4f223d2a83c0269607fcb6d4c74d5a3d3220209d089431a", "price_changes": [{"asset_id": "73459237018178325517511938237778014293974381812181153063276727733805928508002", "price": "0.774", "size": "0", "side": "BUY", "hash": "8a9c2451502f5a8420345512c09c2f56e2dad209", "best_bid": "0.802", "best_ask": "0.807"}, {"asset_id": "63433408040190943973509092025756868743192149481060781851142321049882584518043", "price": "0.226", "size": "0", "side": "SELL", "hash": "eb9a6088200f41389c6dbbc690c8dac1c48b4fe5", "best_bid": "0.193", "best_ask": "0.198"}], "timestamp": "1769384476909", "event_type": "price_change"}}
{"_local_timestamp": "2026-01-25T23:41:17.022112+00:00", "data": {"market": "0xd87ac5bb74a21061d4f223d2a83c0269607fcb6d4c74d5a3d3220209d089431a", "price_changes": [{"asset_id": "73459237018178325517511938237778014293974381812181153063276727733805928508002", "price": "0.775", "size": "2200", "side": "BUY", "hash": "88106cf7774fd7c098c22af4af4faf2587b2bdb2", "best_bid": "0.802", "best_ask": "0.807"}, {"asset_id": "63433408040190943973509092025756868743192149481060781851142321049882584518043", "price": "0.225", "size": "2200", "side": "SELL", "hash": "0d8dfc678a9044dff7523c29ae82d84c9f96d4bf", "best_bid": "0.193", "best_ask": "0.198"}], "timestamp": "1769384476954", "event_type": "price_change"}}
{"_local_timestamp": "2026-01-25T23:41:17.055914+00:00", "data": {"market": "0x66af911f31ceabb5f9a3ef9203a73f0b23d18aa81bbba7888dec440c622c2528", "price_changes": [{"asset_id": "101818439776033928818471919550932857351051302350112396692573347503051307979709", "price": "0.29", "size": "3100.08", "side": "BUY", "hash": "bbd751a89bd892fc3205db3a82b22be6590a2633", "best_bid": "0.3", "best_ask": "0.31"}, {"asset_id": "68639196051170795150992485552561385006521521637825690332014642323694437969760", "price": "0.71", "size": "3100.08", "side": "SELL", "hash": "81c51853cbe834abcf74aa58a7fecbfca00c0337", "best_bid": "0.69", "best_ask": "0.7"}], "timestamp": "1769384476980", "event_type": "price_change"}}
{"_local_timestamp": "2026-01-25T23:41:17.068630+00:00", "data": {"market": "0xd87ac5bb74a21061d4f223d2a83c0269607fcb6d4c74d5a3d3220209d089431a", "price_changes": [{"asset_id": "73459237018178325517511938237778014293974381812181153063276727733805928508002", "price": "0.775", "size": "2000", "side": "BUY", "hash": "407516ac19a8a340675cecf03580af8e0cf8b172", "best_bid": "0.802", "best_ask": "0.807"}, {"asset_id": "63433408040190943973509092025756868743192149481060781851142321049882584518043", "price": "0.225", "size": "2000", "side": "SELL", "hash": "27e2c16daa1ef164ee9fb712e9d8d1805460e7cf", "best_bid": "0.193", "best_ask": "0.198"}], "timestamp": "1769384476997", "event_type": "price_change"}}
{"_local_timestamp": "2026-01-25T23:41:17.131852+00:00", "data": {"market": "0x66af911f31ceabb5f9a3ef9203a73f0b23d18aa81bbba7888dec440c622c2528", "price_changes": [{"asset_id": "101818439776033928818471919550932857351051302350112396692573347503051307979709", "price": "0.27", "size": "138.53", "side": "BUY", "hash": "ce6d3fc4ba6811efb1c3b5001d557e8c67dd687f", "best_bid": "0.3", "best_ask": "0.31"}, {"asset_id": "68639196051170795150992485552561385006521521637825690332014642323694437969760", "price": "0.73", "size": "138.53", "side": "SELL", "hash": "2896f91d7d8a356d1e1ce0c57f57df3ec4ea1c23", "best_bid": "0.69", "best_ask": "0.7"}], "timestamp": "1769384477065", "event_type": "price_change"}}
{"_local_timestamp": "2026-01-25T23:41:17.178256+00:00", "data": {"market": "0x66af911f31ceabb5f9a3ef9203a73f0b23d18aa81bbba7888dec440c622c2528", "price_changes": [{"asset_id": "101818439776033928818471919550932857351051302350112396692573347503051307979709", "price": "0.3", "size": "958.37", "side": "BUY", "hash": "e1d0d1f4cc9f2c6f52a964d3fbc1c52188cdc9f6", "best_bid": "0.3", "best_ask": "0.31"}, {"asset_id": "68639196051170795150992485552561385006521521637825690332014642323694437969760", "price": "0.7", "size": "958.37", "side": "SELL", "hash": "49ece3a0517b4de7b2cb47d51523092719301da5", "best_bid": "0.69", "best_ask": "0.7"}], "timestamp": "1769384477112", "event_type": "price_change"}}
{"_local_timestamp": "2026-01-25T23:41:17.292255+00:00", "data": {"market": "0x66af911f31ceabb5f9a3ef9203a73f0b23d18aa81bbba7888dec440c622c2528", "price_changes": [{"asset_id": "101818439776033928818471919550932857351051302350112396692573347503051307979709", "price": "0.3", "size": "908.37", "side": "BUY", "hash": "5810f03097fdebcf185add84ca5a7ffacba325e1", "best_bid": "0.3", "best_ask": "0.31"}, {"asset_id": "68639196051170795150992485552561385006521521637825690332014642323694437969760", "price": "0.7", "size": "908.37", "side": "SELL", "hash": "4b91bea8c6191539cfa652b3560ba26e3b8f86c9", "best_bid": "0.69", "best_ask": "0.7"}], "timestamp": "1769384477214", "event_type": "price_change"}}
{"_local_timestamp": "2026-01-25T23:41:17.831918+00:00", "data": {"market": "0xd87ac5bb74a21061d4f223d2a83c0269607fcb6d4c74d5a3d3220209d089431a", "price_changes": [{"asset_id": "63433408040190943973509092025756868743192149481060781851142321049882584518043", "price": "0.187", "size": "200", "side": "BUY", "hash": "a030f447a5cebd50d56d03c725fca9c464802133", "best_bid": "0.193", "best_ask": "0.198"}, {"asset_id": "73459237018178325517511938237778014293974381812181153063276727733805928508002", "price": "0.813", "size": "200", "side": "SELL", "hash": "c2b926ea0978bc3e8852363c483ee0a45dfced53", "best_bid": "0.802", "best_ask": "0.807"}], "timestamp": "1769384477726", "event_type": "price_change"}}
{"_local_timestamp": "2026-01-25T23:41:17.832326+00:00", "data": {"market": "0xd87ac5bb74a21061d4f223d2a83c0269607fcb6d4c74d5a3d3220209d089431a", "price_changes": [{"asset_id": "73459237018178325517511938237778014293974381812181153063276727733805928508002", "price": "0.792", "size": "738.74", "side": "BUY", "hash": "52d9ec506a22063f1329f265f60c39fa8ca598fe", "best_bid": "0.802", "best_ask": "0.807"}, {"asset_id": "63433408040190943973509092025756868743192149481060781851142321049882584518043", "price": "0.208", "size": "738.74", "side": "SELL", "hash": "d3fbe8068eb5167c12b5d3f378de014c60550c58", "best_bid": "0.193", "best_ask": "0.198"}], "timestamp": "1769384477727", "event_type": "price_change"}}
{"_local_timestamp": "2026-01-25T23:41:18.002708+00:00", "data": {"market": "0x66af911f31ceabb5f9a3ef9203a73f0b23d18aa81bbba7888dec440c622c2528", "price_changes": [{"asset_id": "101818439776033928818471919550932857351051302350112396692573347503051307979709", "price": "0.27", "size": "538.53", "side": "BUY", "hash": "513e9676c84d122688ffa0ed9631b77447850a48", "best_bid": "0.3", "best_ask": "0.31"}, {"asset_id": "68639196051170795150992485552561385006521521637825690332014642323694437969760", "price": "0.73", "size": "538.53", "side": "SELL", "hash": "1e03eed54bea2621c3d8c74ded08766d98995d59", "best_bid": "0.69", "best_ask": "0.7"}], "timestamp": "1769384477888", "event_type": "price_change"}}
{"_local_timestamp": "2026-01-25T23:41:18.249168+00:00", "data": {"market": "0xd87ac5bb74a21061d4f223d2a83c0269607fcb6d4c74d5a3d3220209d089431a", "price_changes": [{"asset_id": "73459237018178325517511938237778014293974381812181153063276727733805928508002", "price": "0.792", "size": "518.74", "side": "BUY", "hash": "f1277044ab1b87c21c304d66b2be47902e7e0265", "best_bid": "0.802", "best_ask": "0.807"}, {"asset_id": "63433408040190943973509092025756868743192149481060781851142321049882584518043", "price": "0.208", "size": "518.74", "side": "SELL", "hash": "18f16eac8a28ab9e32847edcf15bde4a300f90b1", "best_bid": "0.193", "best_ask": "0.198"}], "timestamp": "1769384478137", "event_type": "price_change"}}
{"_local_timestamp": "2026-01-25T23:41:18.249503+00:00", "data": {"market": "0xd87ac5bb74a21061d4f223d2a83c0269607fcb6d4c74d5a3d3220209d089431a", "price_changes": [{"asset_id": "63433408040190943973509092025756868743192149481060781851142321049882584518043", "price": "0.188", "size": "0", "side": "BUY", "hash": "9624b05e57263b465ddd0f42773293aeee0f055f", "best_bid": "0.193", "best_ask": "0.198"}, {"asset_id": "73459237018178325517511938237778014293974381812181153063276727733805928508002", "price": "0.812", "size": "0", "side": "SELL", "hash": "aa5a388fca1f13915936f5a29b06514a7d2bd344", "best_bid": "0.802", "best_ask": "0.807"}], "timestamp": "1769384478138", "event_type": "price_change"}}
{"_local_timestamp": "2026-01-25T23:41:18.359266+00:00", "data": {"market": "0x101c26a9ff336abf4dffeb109dc40b92d9f55882dd471e57ee875794a6561bf3", "price_changes": [{"asset_id": "41909517390337506269578561946393939690952797212331290191404935145632561531096", "price": "0.96", "size": "0", "side": "BUY", "hash": "900fdcedd5b0a9bdce961f0f1fc2ecca10cd24d2", "best_bid": "0.975", "best_ask": "0.976"}, {"asset_id": "37082726066756590137696446997499452856763598243673867366591242252359474108530", "price": "0.04", "size": "0", "side": "SELL", "hash": "9f82fb1ffe8541038846170cadf33266fea0c2ee", "best_bid": "0.024", "best_ask": "0.025"}], "timestamp": "1769384478238", "event_type": "price_change"}}
{"_local_timestamp": "2026-01-25T23:41:18.365849+00:00", "data": {"market": "0x101c26a9ff336abf4dffeb109dc40b92d9f55882dd471e57ee875794a6561bf3", "price_changes": [{"asset_id": "37082726066756590137696446997499452856763598243673867366591242252359474108530", "price": "0.004", "size": "0", "side": "BUY", "hash": "b37cb0124d5fbc73ff25da745722a5d7e75f2631", "best_bid": "0.024", "best_ask": "0.025"}, {"asset_id": "41909517390337506269578561946393939690952797212331290191404935145632561531096", "price": "0.996", "size": "0", "side": "SELL", "hash": "b02f80750e095b4ad0395c6f15629404cf5b9f92", "best_bid": "0.975", "best_ask": "0.976"}], "timestamp": "1769384478239", "event_type": "price_change"}}
{"_local_timestamp": "2026-01-25T23:41:18.432662+00:00", "data": {"market": "0x66af911f31ceabb5f9a3ef9203a73f0b23d18aa81bbba7888dec440c622c2528", "price_changes": [{"asset_id": "101818439776033928818471919550932857351051302350112396692573347503051307979709", "price": "0.3", "size": "958.37", "side": "BUY", "hash": "949a17f3d99d618fbd7a9d8aa3783006194cb299", "best_bid": "0.3", "best_ask": "0.31"}, {"asset_id": "68639196051170795150992485552561385006521521637825690332014642323694437969760", "price": "0.7", "size": "958.37", "side": "SELL", "hash": "4ae579d5458c38b9dec410f41b339da3092e68c4", "best_bid": "0.69", "best_ask": "0.7"}], "timestamp": "1769384478300", "event_type": "price_change"}}
{"_local_timestamp": "2026-01-25T23:41:18.523488+00:00", "data": {"market": "0x66af911f31ceabb5f9a3ef9203a73f0b23d18aa81bbba7888dec440c622c2528", "price_changes": [{"asset_id": "101818439776033928818471919550932857351051302350112396692573347503051307979709", "price": "0.3", "size": "908.37", "side": "BUY", "hash": "2da3415cd561bd39a33f83a083ae50e4581719c7", "best_bid": "0.3", "best_ask": "0.31"}, {"asset_id": "68639196051170795150992485552561385006521521637825690332014642323694437969760", "price": "0.7", "size": "908.37", "side": "SELL", "hash": "1a9ba3ed83c6b9bf99f10162ca98b6cb6a560766", "best_bid": "0.69", "best_ask": "0.7"}], "timestamp": "1769384478403", "event_type": "price_change"}}
{"_local_timestamp": "2026-01-25T23:41:18.534308+00:00", "data": {"market": "0x66af911f31ceabb5f9a3ef9203a73f0b23d18aa81bbba7888dec440c622c2528", "price_changes": [{"asset_id": "101818439776033928818471919550932857351051302350112396692573347503051307979709", "price": "0.27", "size": "138.53", "side": "BUY", "hash": "e66524669fbdcad1566095bff617bea77ffecf86", "best_bid": "0.3", "best_ask": "0.31"}, {"asset_id": "68639196051170795150992485552561385006521521637825690332014642323694437969760", "price": "0.73", "size": "138.53", "side": "SELL", "hash": "0f0cec5ea6608588cfb02ca2f4585a13bf049301", "best_bid": "0.69", "best_ask": "0.7"}], "timestamp": "1769384478430", "event_type": "price_change"}}
{"_local_timestamp": "2026-01-25T23:41:18.964285+00:00", "data": {"market": "0x66af911f31ceabb5f9a3ef9203a73f0b23d18aa81bbba7888dec440c622c2528", "price_changes": [{"asset_id": "101818439776033928818471919550932857351051302350112396692573347503051307979709", "price": "0.26", "size": "46", "side": "BUY", "hash": "f7c551b9c1993fef9e64e09497f3cfd16ff9ad8a", "best_bid": "0.3", "best_ask": "0.31"}, {"asset_id": "68639196051170795150992485552561385006521521637825690332014642323694437969760", "price": "0.74", "size": "46", "side": "SELL", "hash": "c035985b958302ce8f6d42db8b5c71253158c77f", "best_bid": "0.69", "best_ask": "0.7"}], "timestamp": "1769384478894", "event_type": "price_change"}}
{"_local_timestamp": "2026-01-25T23:41:19.004858+00:00", "data": {"market": "0x66af911f31ceabb5f9a3ef9203a73f0b23d18aa81bbba7888dec440c622c2528", "price_changes": [{"asset_id": "101818439776033928818471919550932857351051302350112396692573347503051307979709", "price": "0.25", "size": "210", "side": "BUY", "hash": "55177ec4c07290c897da35c4cf442e733d30c5ce", "best_bid": "0.3", "best_ask": "0.31"}, {"asset_id": "68639196051170795150992485552561385006521521637825690332014642323694437969760", "price": "0.75", "size": "210", "side": "SELL", "hash": "9b30cb671a6d2d2de8a4b3165251942a79fd5a64", "best_bid": "0.69", "best_ask": "0.7"}], "timestamp": "1769384478921", "event_type": "price_change"}}
{"_local_timestamp": "2026-01-25T23:41:21.240796+00:00", "data": {"market": "0x101c26a9ff336abf4dffeb109dc40b92d9f55882dd471e57ee875794a6561bf3", "price_changes": [{"asset_id": "41909517390337506269578561946393939690952797212331290191404935145632561531096", "price": "0.972", "size": "400", "side": "BUY", "hash": "e198ab743d1a149f934b1cc46d7c129b6c6fe723", "best_bid": "0.975", "best_ask": "0.976"}, {"asset_id": "37082726066756590137696446997499452856763598243673867366591242252359474108530", "price": "0.028", "size": "400", "side": "SELL", "hash": "17c257c9c24c1833c7e5c7cc09b009dea1924d54", "best_bid": "0.024", "best_ask": "0.025"}], "timestamp": "1769384481163", "event_type": "price_change"}}
{"_local_timestamp": "2026-01-25T23:41:21.249227+00:00", "data": {"market": "0x101c26a9ff336abf4dffeb109dc40b92d9f55882dd471e57ee875794a6561bf3", "price_changes": [{"asset_id": "37082726066756590137696446997499452856763598243673867366591242252359474108530", "price": "0.004", "size": "1719.48", "side": "BUY", "hash": "0ff6e004f49862b69a63b9f1e538cd5193868aa0", "best_bid": "0.024", "best_ask": "0.025"}, {"asset_id": "41909517390337506269578561946393939690952797212331290191404935145632561531096", "price": "0.996", "size": "1719.48", "side": "SELL", "hash": "b02aca3d915183aa24659fd288c8060dc39ff3e2", "best_bid": "0.975", "best_ask": "0.976"}], "timestamp": "1769384481163", "event_type": "price_change"}}
{"_local_timestamp": "2026-01-25T23:41:21.353389+00:00", "data": {"market": "0x66af911f31ceabb5f9a3ef9203a73f0b23d18aa81bbba7888dec440c622c2528", "price_changes": [{"asset_id": "101818439776033928818471919550932857351051302350112396692573347503051307979709", "price": "0.3", "size": "958.37", "side": "BUY", "hash": "927821ad7e9b04d4d90a3a1b57c7776a04522577", "best_bid": "0.3", "best_ask": "0.31"}, {"asset_id": "68639196051170795150992485552561385006521521637825690332014642323694437969760", "price": "0.7", "size": "958.37", "side": "SELL", "hash": "af4e62d4f7ca86f45e72557664c1a1c6c23374b4", "best_bid": "0.69", "best_ask": "0.7"}], "timestamp": "1769384481290", "event_type": "price_change"}}
{"_local_timestamp": "2026-01-25T23:41:21.465645+00:00", "data": {"market": "0x66af911f31ceabb5f9a3ef9203a73f0b23d18aa81bbba7888dec440c622c2528", "price_changes": [{"asset_id": "101818439776033928818471919550932857351051302350112396692573347503051307979709", "price": "0.3", "size": "908.37", "side": "BUY", "hash": "78552fb85956d85fa6566c5eab49eded5ea67e4f", "best_bid": "0.3", "best_ask": "0.31"}, {"asset_id": "68639196051170795150992485552561385006521521637825690332014642323694437969760", "price": "0.7", "size": "908.37", "side": "SELL", "hash": "47b22def239ec67e068b2a98cb7c63ea610faad6", "best_bid": "0.69", "best_ask": "0.7"}], "timestamp": "1769384481394", "event_type": "price_change"}}
{"_local_timestamp": "2026-01-25T23:41:24.740675+00:00", "data": {"market": "0xd87ac5bb74a21061d4f223d2a83c0269607fcb6d4c74d5a3d3220209d089431a", "price_changes": [{"asset_id": "73459237018178325517511938237778014293974381812181153063276727733805928508002", "price": "0.802", "size": "60", "side": "BUY", "hash": "c0b542d1aa5d989336cdcc4e9b7ead9b9b2e18ba", "best_bid": "0.802", "best_ask": "0.807"}, {"asset_id": "63433408040190943973509092025756868743192149481060781851142321049882584518043", "price": "0.198", "size": "60", "side": "SELL", "hash": "230d0170092ec833cd5346178ab149002011bba5", "best_bid": "0.193", "best_ask": "0.198"}], "timestamp": "1769384484676", "event_type": "price_change"}}
{"_local_timestamp": "2026-01-25T23:41:24.741441+00:00", "data": {"market": "0xd87ac5bb74a21061d4f223d2a83c0269607fcb6d4c74d5a3d3220209d089431a", "price_changes": [{"asset_id": "73459237018178325517511938237778014293974381812181153063276727733805928508002", "price": "0.803", "size": "50", "side": "BUY", "hash": "077ec6abb56f3c7d2fe9714f72f0512c5e33ab00", "best_bid": "0.803", "best_ask": "0.807"}, {"asset_id": "63433408040190943973509092025756868743192149481060781851142321049882584518043", "price": "0.197", "size": "50", "side": "SELL", "hash": "caed41028c27a98fa8776cd727842801c751624c", "best_bid": "0.193", "best_ask": "0.197"}], "timestamp": "1769384484677", "event_type": "price_change"}}
{"_local_timestamp": "2026-01-25T23:41:24.859152+00:00", "data": {"market": "0x66af911f31ceabb5f9a3ef9203a73f0b23d18aa81bbba7888dec440c622c2528", "price_changes": [{"asset_id": "101818439776033928818471919550932857351051302350112396692573347503051307979709", "price": "0.3", "size": "958.37", "side": "BUY", "hash": "386077e47465a7318982ec5f4e143a618be10d4e", "best_bid": "0.3", "best_ask": "0.31"}, {"asset_id": "68639196051170795150992485552561385006521521637825690332014642323694437969760", "price": "0.7", "size": "958.37", "side": "SELL", "hash": "eb046f6dcd99f7e2065c72091ff0499d28a3a456", "best_bid": "0.69", "best_ask": "0.7"}], "timestamp": "1769384484791", "event_type": "price_change"}}
{"_local_timestamp": "2026-01-25T23:41:24.966478+00:00", "data": {"market": "0x66af911f31ceabb5f9a3ef9203a73f0b23d18aa81bbba7888dec440c622c2528", "price_changes": [{"asset_id": "101818439776033928818471919550932857351051302350112396692573347503051307979709", "price": "0.3", "size": "908.37", "side": "BUY", "hash": "485d9f2ca6f8b26e923614c487789121c7d22ba1", "best_bid": "0.3", "best_ask": "0.31"}, {"asset_id": "68639196051170795150992485552561385006521521637825690332014642323694437969760", "price": "0.7", "size": "908.37", "side": "SELL", "hash": "42849c6e6989576d1be3fe82734c024b9248369e", "best_bid": "0.69", "best_ask": "0.7"}], "timestamp": "1769384484893", "event_type": "price_change"}}
{"_local_timestamp": "2026-01-25T23:41:25.101967+00:00", "data": {"market": "0xd87ac5bb74a21061d4f223d2a83c0269607fcb6d4c74d5a3d3220209d089431a", "price_changes": [{"asset_id": "73459237018178325517511938237778014293974381812181153063276727733805928508002", "price": "0.8", "size": "60", "side": "BUY", "hash": "32263bcb0358cf9c9196d7eedfbf90b8e0710221", "best_bid": "0.803", "best_ask": "0.807"}, {"asset_id": "63433408040190943973509092025756868743192149481060781851142321049882584518043", "price": "0.2", "size": "60", "side": "SELL", "hash": "2d2b344202ae3225695bc3a33eaa52ce92933a9c", "best_bid": "0.193", "best_ask": "0.197"}], "timestamp": "1769384485030", "event_type": "price_change"}}
{"_local_timestamp": "2026-01-25T23:41:25.150464+00:00", "data": {"market": "0xd87ac5bb74a21061d4f223d2a83c0269607fcb6d4c74d5a3d3220209d089431a", "price_changes": [{"asset_id": "73459237018178325517511938237778014293974381812181153063276727733805928508002", "price": "0.802", "size": "90", "side": "BUY", "hash": "d9945f768ec24c199036e4abff5623d970c282fd", "best_bid": "0.803", "best_ask": "0.807"}, {"asset_id": "63433408040190943973509092025756868743192149481060781851142321049882584518043", "price": "0.198", "size": "90", "side": "SELL", "hash": "cf697eb5332b09eade0c434fb7ae8c078cb4b7ff", "best_bid": "0.193", "best_ask": "0.197"}], "timestamp": "1769384485078", "event_type": "price_change"}}
{"_local_timestamp": "2026-01-25T23:41:25.152504+00:00", "data": {"market": "0xd87ac5bb74a21061d4f223d2a83c0269607fcb6d4c74d5a3d3220209d089431a", "price_changes": [{"asset_id": "63433408040190943973509092025756868743192149481060781851142321049882584518043", "price": "0.166", "size": "200", "side": "BUY", "hash": "7cd668df43cddc7cc72f3d1929e20661d62a9913", "best_bid": "0.193", "best_ask": "0.197"}, {"asset_id": "73459237018178325517511938237778014293974381812181153063276727733805928508002", "price": "0.834", "size": "200", "side": "SELL", "hash": "b82bb1f926aed575ce3b2295a7c9326e6b6afd56", "best_bid": "0.803", "best_ask": "0.807"}], "timestamp": "1769384485089", "event_type": "price_change"}}
{"_local_timestamp": "2026-01-25T23:41:25.195412+00:00", "data": {"market": "0xd87ac5bb74a21061d4f223d2a83c0269607fcb6d4c74d5a3d3220209d089431a", "price_changes": [{"asset_id": "63433408040190943973509092025756868743192149481060781851142321049882584518043", "price": "0.165", "size": "300", "side": "BUY", "hash": "363c6067f7a04df231252922415183934b577ca0", "best_bid": "0.193", "best_ask": "0.197"}, {"asset_id": "73459237018178325517511938237778014293974381812181153063276727733805928508002", "price": "0.835", "size": "300", "side": "SELL", "hash": "bed18ec9a88414cac1419e0744ee9e68bb3e5b6d", "best_bid": "0.803", "best_ask": "0.807"}], "timestamp": "1769384485125", "event_type": "price_change"}}
{"_local_timestamp": "2026-01-25T23:41:25.247401+00:00", "data": {"market": "0xd87ac5bb74a21061d4f223d2a83c0269607fcb6d4c74d5a3d3220209d089431a", "price_changes": [{"asset_id": "73459237018178325517511938237778014293974381812181153063276727733805928508002", "price": "0.792", "size": "318.74", "side": "BUY", "hash": "b641f011913cd31e0585f2339215cac2b2bd3d49", "best_bid": "0.803", "best_ask": "0.807"}, {"asset_id": "63433408040190943973509092025756868743192149481060781851142321049882584518043", "price": "0.208", "size": "318.74", "side": "SELL", "hash": "b0e9c576d3527049e0f98d2e1fb0adce35e494e7", "best_bid": "0.193", "best_ask": "0.197"}], "timestamp": "1769384485168", "event_type": "price_change"}}
{"_local_timestamp": "2026-01-25T23:41:25.248258+00:00", "data": {"market": "0xd87ac5bb74a21061d4f223d2a83c0269607fcb6d4c74d5a3d3220209d089431a", "price_changes": [{"asset_id": "63433408040190943973509092025756868743192149481060781851142321049882584518043", "price": "0.187", "size": "0", "side": "BUY", "hash": "e2bad345968dbc5f92cfef0c13c4f0d7fb581c6e", "best_bid": "0.193", "best_ask": "0.197"}, {"asset_id": "73459237018178325517511938237778014293974381812181153063276727733805928508002", "price": "0.813", "size": "0", "side": "SELL", "hash": "ca52bf9661fafd70a2362932cd7311c41a1c14d3", "best_bid": "0.803", "best_ask": "0.807"}], "timestamp": "1769384485168", "event_type": "price_change"}}
{"_local_timestamp": "2026-01-25T23:41:25.414021+00:00", "data": {"market": "0xd87ac5bb74a21061d4f223d2a83c0269607fcb6d4c74d5a3d3220209d089431a", "price_changes": [{"asset_id": "63433408040190943973509092025756868743192149481060781851142321049882584518043", "price": "0.187", "size": "210", "side": "BUY", "hash": "85b581397c9d16b33c4a5b8c02c3fea7e4798f17", "best_bid": "0.193", "best_ask": "0.197"}, {"asset_id": "73459237018178325517511938237778014293974381812181153063276727733805928508002", "price": "0.813", "size": "210", "side": "SELL", "hash": "898b7d6b2ba01587b1083baa2f8a48e3eab5cb11", "best_bid": "0.803", "best_ask": "0.807"}], "timestamp": "1769384485342", "event_type": "price_change"}}
{"_local_timestamp": "2026-01-25T23:41:25.416759+00:00", "data": {"market": "0xd87ac5bb74a21061d4f223d2a83c0269607fcb6d4c74d5a3d3220209d089431a", "price_changes": [{"asset_id": "73459237018178325517511938237778014293974381812181153063276727733805928508002", "price": "0.792", "size": "528.74", "side": "BUY", "hash": "9edba03783c1d6d01835c59dcdef4aa5507c709d", "best_bid": "0.803", "best_ask": "0.807"}, {"asset_id": "63433408040190943973509092025756868743192149481060781851142321049882584518043", "price": "0.208", "size": "528.74", "side": "SELL", "hash": "7047206078a39dafcba9ccffafe0dd7380677fbf", "best_bid": "0.193", "best_ask": "0.197"}], "timestamp": "1769384485343", "event_type": "price_change"}}
{"_local_timestamp": "2026-01-25T23:41:25.634632+00:00", "data": {"market": "0xd87ac5bb74a21061d4f223d2a83c0269607fcb6d4c74d5a3d3220209d089431a", "price_changes": [{"asset_id": "63433408040190943973509092025756868743192149481060781851142321049882584518043", "price": "0.202", "size": "419.03", "side": "SELL", "hash": "fd240474ed333c2e689c3165b39d26a6697330f5", "best_bid": "0.193", "best_ask": "0.197"}, {"asset_id": "73459237018178325517511938237778014293974381812181153063276727733805928508002", "price": "0.798", "size": "419.03", "side": "BUY", "hash": "bc7be0379b1f787750017a111c524c3771466edf", "best_bid": "0.803", "best_ask": "0.807"}], "timestamp": "1769384485570", "event_type": "price_change"}}
{"_local_timestamp": "2026-01-25T23:41:25.655806+00:00", "data": {"market": "0xd87ac5bb74a21061d4f223d2a83c0269607fcb6d4c74d5a3d3220209d089431a", "price_changes": [{"asset_id": "63433408040190943973509092025756868743192149481060781851142321049882584518043", "price": "0.206", "size": "0", "side": "SELL", "hash": "6995398912125961ef8b80aa3b933d38166b7c6c", "best_bid": "0.193", "best_ask": "0.197"}, {"asset_id": "73459237018178325517511938237778014293974381812181153063276727733805928508002", "price": "0.794", "size": "0", "side": "BUY", "hash": "a804544d7020c962edb91b4a6fd34976dab952d3", "best_bid": "0.803", "best_ask": "0.807"}], "timestamp": "1769384485579", "event_type": "price_change"}}
{"_local_timestamp": "2026-01-25T23:41:26.077202+00:00", "data": {"market": "0xd87ac5bb74a21061d4f223d2a83c0269607fcb6d4c74d5a3d3220209d089431a", "price_changes": [{"asset_id": "63433408040190943973509092025756868743192149481060781851142321049882584518043", "price": "0.199", "size": "61.2", "side": "SELL", "hash": "37b67e7a269b497ac3fd58cee5ce56544f9583e1", "best_bid": "0.193", "best_ask": "0.197"}, {"asset_id": "73459237018178325517511938237778014293974381812181153063276727733805928508002", "price": "0.801", "size": "61.2", "side": "BUY", "hash": "e3374283f839ed7a0347ba585f67ed04d96b94d5", "best_bid": "0.803", "best_ask": "0.807"}], "timestamp": "1769384486005", "event_type": "price_change"}}
{"_local_timestamp": "2026-01-25T23:41:26.078311+00:00", "data": {"market": "0xd87ac5bb74a21061d4f223d2a83c0269607fcb6d4c74d5a3d3220209d089431a", "price_changes": [{"asset_id": "63433408040190943973509092025756868743192149481060781851142321049882584518043", "price": "0.201", "size": "13.68", "side": "SELL", "hash": "d777dd2596bf4e7ddcbbfd1e228dc8b449c889a6", "best_bid": "0.193", "best_ask": "0.197"}, {"asset_id": "73459237018178325517511938237778014293974381812181153063276727733805928508002", "price": "0.799", "size": "13.68", "side": "BUY", "hash": "05c5bf77e640af8ff1ca5841765c56511e663149", "best_bid": "0.803", "best_ask": "0.807"}], "timestamp": "1769384486006", "event_type": "price_change"}}
{"_local_timestamp": "2026-01-25T23:41:26.192240+00:00", "data": {"market": "0x66af911f31ceabb5f9a3ef9203a73f0b23d18aa81bbba7888dec440c622c2528", "price_changes": [{"asset_id": "101818439776033928818471919550932857351051302350112396692573347503051307979709", "price": "0.3", "size": "958.37", "side": "BUY", "hash": "cd94d6cf13df7de8dd232329c3d42dfc9a2d27b8", "best_bid": "0.3", "best_ask": "0.31"}, {"asset_id": "68639196051170795150992485552561385006521521637825690332014642323694437969760", "price": "0.7", "size": "958.37", "side": "SELL", "hash": "007dd62993699c6d92348c8098c09a6d31ecfeca", "best_bid": "0.69", "best_ask": "0.7"}], "timestamp": "1769384486126", "event_type": "price_change"}}
{"_local_timestamp": "2026-01-25T23:41:26.302075+00:00", "data": {"market": "0x66af911f31ceabb5f9a3ef9203a73f0b23d18aa81bbba7888dec440c622c2528", "price_changes": [{"asset_id": "101818439776033928818471919550932857351051302350112396692573347503051307979709", "price": "0.3", "size": "908.37", "side": "BUY", "hash": "aa38af63a63cdc5a120391fa7a777123425ce93c", "best_bid": "0.3", "best_ask": "0.31"}, {"asset_id": "68639196051170795150992485552561385006521521637825690332014642323694437969760", "price": "0.7", "size": "908.37", "side": "SELL", "hash": "3c192e2a624128fb704fe521626d44105105a30d", "best_bid": "0.69", "best_ask": "0.7"}], "timestamp": "1769384486228", "event_type": "price_change"}}
{"_local_timestamp": "2026-01-25T23:41:26.744316+00:00", "data": {"market": "0xd87ac5bb74a21061d4f223d2a83c0269607fcb6d4c74d5a3d3220209d089431a", "price_changes": [{"asset_id": "73459237018178325517511938237778014293974381812181153063276727733805928508002", "price": "0.792", "size": "728.74", "side": "BUY", "hash": "a72b71118528dd5f1318dc121075164e5dcf60c1", "best_bid": "0.803", "best_ask": "0.807"}, {"asset_id": "63433408040190943973509092025756868743192149481060781851142321049882584518043", "price": "0.208", "size": "728.74", "side": "SELL", "hash": "cf84f267c202fc3bb49ae7a2817b8850fb14a5e1", "best_bid": "0.193", "best_ask": "0.197"}], "timestamp": "1769384486676", "event_type": "price_change"}}
{"_local_timestamp": "2026-01-25T23:41:26.755266+00:00", "data": {"market": "0xd87ac5bb74a21061d4f223d2a83c0269607fcb6d4c74d5a3d3220209d089431a", "price_changes": [{"asset_id": "63433408040190943973509092025756868743192149481060781851142321049882584518043", "price": "0.186", "size": "200", "side": "BUY", "hash": "1c69e2bcd8a9a4d2012395af25b9900760ca3eea", "best_bid": "0.193", "best_ask": "0.197"}, {"asset_id": "73459237018178325517511938237778014293974381812181153063276727733805928508002", "price": "0.814", "size": "200", "side": "SELL", "hash": "294158a6ea06e18ae5e0d4b205f13ef9ed736543", "best_bid": "0.803", "best_ask": "0.807"}], "timestamp": "1769384486677", "event_type": "price_change"}}
{"_local_timestamp": "2026-01-25T23:41:26.856708+00:00", "data": {"market": "0x66af911f31ceabb5f9a3ef9203a73f0b23d18aa81bbba7888dec440c622c2528", "price_changes": [{"asset_id": "101818439776033928818471919550932857351051302350112396692573347503051307979709", "price": "0.27", "size": "538.53", "side": "BUY", "hash": "e4746aa8615073e067f3fff86e8d3406731beda2", "best_bid": "0.3", "best_ask": "0.31"}, {"asset_id": "68639196051170795150992485552561385006521521637825690332014642323694437969760", "price": "0.73", "size": "538.53", "side": "SELL", "hash": "8b39f62f863a30c9b415ca69371c50e933b7ebe0", "best_bid": "0.69", "best_ask": "0.7"}], "timestamp": "1769384486785", "event_type": "price_change"}}
{"_local_timestamp": "2026-01-25T23:41:27.047742+00:00", "data": {"market": "0xd87ac5bb74a21061d4f223d2a83c0269607fcb6d4c74d5a3d3220209d089431a", "price_changes": [{"asset_id": "63433408040190943973509092025756868743192149481060781851142321049882584518043", "price": "0.201", "size": "54.18", "side": "SELL", "hash": "e9ffac5b66cd9bc89d814f53b8835882dc9f11c7", "best_bid": "0.193", "best_ask": "0.197"}, {"asset_id": "73459237018178325517511938237778014293974381812181153063276727733805928508002", "price": "0.799", "size": "54.18", "side": "BUY", "hash": "14da32d398849f72479a2aa1d1d3d7abe8db98b3", "best_bid": "0.803", "best_ask": "0.807"}], "timestamp": "1769384486963", "event_type": "price_change"}}
{"_local_timestamp": "2026-01-25T23:41:27.146904+00:00", "data": {"market": "0xd87ac5bb74a21061d4f223d2a83c0269607fcb6d4c74d5a3d3220209d089431a", "price_changes": [{"asset_id": "63433408040190943973509092025756868743192149481060781851142321049882584518043", "price": "0.201", "size": "123.49", "side": "SELL", "hash": "150a08fdc5fd9905ee7bdc9875682f8c8085aa0a", "best_bid": "0.193", "best_ask": "0.197"}, {"asset_id": "73459237018178325517511938237778014293974381812181153063276727733805928508002", "price": "0.799", "size": "123.49", "side": "BUY", "hash": "4f7fe851e74fe6cfed6c2060b34c5f102a1aa4ff", "best_bid": "0.803", "best_ask": "0.807"}], "timestamp": "1769384487083", "event_type": "price_change"}}
{"_local_timestamp": "2026-01-25T23:41:27.157047+00:00", "data": {"market": "0xd87ac5bb74a21061d4f223d2a83c0269607fcb6d4c74d5a3d3220209d089431a", "price_changes": [{"asset_id": "63433408040190943973509092025756868743192149481060781851142321049882584518043", "price": "0.187", "size": "0", "side": "BUY", "hash": "0ef532edd85ddb4dd05c535f0986952f38e04536", "best_bid": "0.193", "best_ask": "0.197"}, {"asset_id": "73459237018178325517511938237778014293974381812181153063276727733805928508002", "price": "0.813", "size": "0", "side": "SELL", "hash": "038621d634cd61176e94d84d7884869edf51ee98", "best_bid": "0.803", "best_ask": "0.807"}], "timestamp": "1769384487089", "event_type": "price_change"}}
{"_local_timestamp": "2026-01-25T23:41:27.259472+00:00", "data": {"market": "0x66af911f31ceabb5f9a3ef9203a73f0b23d18aa81bbba7888dec440c622c2528", "price_changes": [{"asset_id": "101818439776033928818471919550932857351051302350112396692573347503051307979709", "price": "0.3", "size": "958.37", "side": "BUY", "hash": "2c6ebd4d25cf489b5f8e48f2eb3356d9de1d7108", "best_bid": "0.3", "best_ask": "0.31"}, {"asset_id": "68639196051170795150992485552561385006521521637825690332014642323694437969760", "price": "0.7", "size": "958.37", "side": "SELL", "hash": "f05cff74cf0189d5b22a53ee2475e0b103961b4e", "best_bid": "0.69", "best_ask": "0.7"}], "timestamp": "1769384487192", "event_type": "price_change"}}
{"_local_timestamp": "2026-01-25T23:41:27.260671+00:00", "data": {"market": "0x66af911f31ceabb5f9a3ef9203a73f0b23d18aa81bbba7888dec440c622c2528", "price_changes": [{"asset_id": "101818439776033928818471919550932857351051302350112396692573347503051307979709", "price": "0.27", "size": "138.53", "side": "BUY", "hash": "ac69375ce6521836311e44da82be962a502927b8", "best_bid": "0.3", "best_ask": "0.31"}, {"asset_id": "68639196051170795150992485552561385006521521637825690332014642323694437969760", "price": "0.73", "size": "138.53", "side": "SELL", "hash": "b27cdda1a926c218ca1cb4eb89cafd1920cee1a7", "best_bid": "0.69", "best_ask": "0.7"}], "timestamp": "1769384487192", "event_type": "price_change"}}
{"_local_timestamp": "2026-01-25T23:41:27.343760+00:00", "data": {"market": "0xd87ac5bb74a21061d4f223d2a83c0269607fcb6d4c74d5a3d3220209d089431a", "price_changes": [{"asset_id": "63433408040190943973509092025756868743192149481060781851142321049882584518043", "price": "0.186", "size": "410", "side": "BUY", "hash": "b7fab1d52bacde26f98aaf64c63d54e0dcdd540c", "best_bid": "0.193", "best_ask": "0.197"}, {"asset_id": "73459237018178325517511938237778014293974381812181153063276727733805928508002", "price": "0.814", "size": "410", "side": "SELL", "hash": "ba0bbb272cceec610a73a5eae6b5b7d13cfa8dde", "best_bid": "0.803", "best_ask": "0.807"}], "timestamp": "1769384487277", "event_type": "price_change"}}
{"_local_timestamp": "2026-01-25T23:41:27.374900+00:00", "data": {"market": "0x66af911f31ceabb5f9a3ef9203a73f0b23d18aa81bbba7888dec440c622c2528", "price_changes": [{"asset_id": "101818439776033928818471919550932857351051302350112396692573347503051307979709", "price": "0.3", "size": "908.37", "side": "BUY", "hash": "85dcd6cfc1e13107664bca9d998e59353e54d36a", "best_bid": "0.3", "best_ask": "0.31"}, {"asset_id": "68639196051170795150992485552561385006521521637825690332014642323694437969760", "price": "0.7", "size": "908.37", "side": "SELL", "hash": "46691cf1fce49b98ad8a1e5324dea24c8ca068e4", "best_bid": "0.69", "best_ask": "0.7"}], "timestamp": "1769384487309", "event_type": "price_change"}}
{"_local_timestamp": "2026-01-25T23:41:27.512940+00:00", "data": {"market": "0x66af911f31ceabb5f9a3ef9203a73f0b23d18aa81bbba7888dec440c622c2528", "price_changes": [{"asset_id": "101818439776033928818471919550932857351051302350112396692573347503051307979709", "price": "0.27", "size": "538.53", "side": "BUY", "hash": "8f92cceaec41a8e402ca7e93e090ffe88ad55454", "best_bid": "0.3", "best_ask": "0.31"}, {"asset_id": "68639196051170795150992485552561385006521521637825690332014642323694437969760", "price": "0.73", "size": "538.53", "side": "SELL", "hash": "533d831908fd69661bf2b492c39d42fdd5f56deb", "best_bid": "0.69", "best_ask": "0.7"}], "timestamp": "1769384487427", "event_type": "price_change"}}
{"_local_timestamp": "2026-01-25T23:41:27.803497+00:00", "data": {"market": "0xd87ac5bb74a21061d4f223d2a83c0269607fcb6d4c74d5a3d3220209d089431a", "price_changes": [{"asset_id": "73459237018178325517511938237778014293974381812181153063276727733805928508002", "price": "0.792", "size": "518.74", "side": "BUY", "hash": "02381bc5f7f056162456b94448053aa29091bce4", "best_bid": "0.803", "best_ask": "0.807"}, {"asset_id": "63433408040190943973509092025756868743192149481060781851142321049882584518043", "price": "0.208", "size": "518.74", "side": "SELL", "hash": "d22d108ac94d0d4dd50e12a0b2c26fa6ddfc251a", "best_bid": "0.193", "best_ask": "0.197"}], "timestamp": "1769384487728", "event_type": "price_change"}}
{"_local_timestamp": "2026-01-25T23:41:28.435720+00:00", "data": {"market": "0xd87ac5bb74a21061d4f223d2a83c0269607fcb6d4c74d5a3d3220209d089431a", "price_changes": [{"asset_id": "73459237018178325517511938237778014293974381812181153063276727733805928508002", "price": "0.792", "size": "318.74", "side": "BUY", "hash": "0f59466061bea20fc993c1cad16d7190256a9148", "best_bid": "0.803", "best_ask": "0.807"}, {"asset_id": "63433408040190943973509092025756868743192149481060781851142321049882584518043", "price": "0.208", "size": "318.74", "side": "SELL", "hash": "d2d6750ba456bb921385655fc4c6d5ba50ffeb4f", "best_bid": "0.193", "best_ask": "0.197"}], "timestamp": "1769384488367", "event_type": "price_change"}}
{"_local_timestamp": "2026-01-25T23:41:28.436147+00:00", "data": {"market": "0xd87ac5bb74a21061d4f223d2a83c0269607fcb6d4c74d5a3d3220209d089431a", "price_changes": [{"asset_id": "63433408040190943973509092025756868743192149481060781851142321049882584518043", "price": "0.186", "size": "210", "side": "BUY", "hash": "07685f505939f551e257e8fb02dff362baa81c4e", "best_bid": "0.193", "best_ask": "0.197"}, {"asset_id": "73459237018178325517511938237778014293974381812181153063276727733805928508002", "price": "0.814", "size": "210", "side": "SELL", "hash": "2fbeded41b47ae9e2a390a68e8468e078d0d0701", "best_bid": "0.803", "best_ask": "0.807"}], "timestamp": "1769384488368", "event_type": "price_change"}}
{"_local_timestamp": "2026-01-25T23:41:28.545458+00:00", "data": {"market": "0x66af911f31ceabb5f9a3ef9203a73f0b23d18aa81bbba7888dec440c622c2528", "price_changes": [{"asset_id": "101818439776033928818471919550932857351051302350112396692573347503051307979709", "price": "0.27", "size": "138.53", "side": "BUY", "hash": "be4d2ba1e9434a73a4042d8795e973117f35f35d", "best_bid": "0.3", "best_ask": "0.31"}, {"asset_id": "68639196051170795150992485552561385006521521637825690332014642323694437969760", "price": "0.73", "size": "138.53", "side": "SELL", "hash": "3e56541fb0de3471a41abc1160d2819ce0203a4a", "best_bid": "0.69", "best_ask": "0.7"}], "timestamp": "1769384488476", "event_type": "price_change"}}
{"_local_timestamp": "2026-01-25T23:41:28.547035+00:00", "data": {"market": "0x66af911f31ceabb5f9a3ef9203a73f0b23d18aa81bbba7888dec440c622c2528", "price_changes": [{"asset_id": "101818439776033928818471919550932857351051302350112396692573347503051307979709", "price": "0.3", "size": "958.37", "side": "BUY", "hash": "87d9d4a16c9502b51938782f6ab18ce5334dc871", "best_bid": "0.3", "best_ask": "0.31"}, {"asset_id": "68639196051170795150992485552561385006521521637825690332014642323694437969760", "price": "0.7", "size": "958.37", "side": "SELL", "hash": "e6cc21d240bc240aaf6151d4f56d4bdfa526f452", "best_bid": "0.69", "best_ask": "0.7"}], "timestamp": "1769384488480", "event_type": "price_change"}}
{"_local_timestamp": "2026-01-25T23:41:28.635202+00:00", "data": {"market": "0xd87ac5bb74a21061d4f223d2a83c0269607fcb6d4c74d5a3d3220209d089431a", "price_changes": [{"asset_id": "73459237018178325517511938237778014293974381812181153063276727733805928508002", "price": "0.793", "size": "210", "side": "BUY", "hash": "63746968fa4288e49412f4ef719048c8812bc4f8", "best_bid": "0.803", "best_ask": "0.807"}, {"asset_id": "63433408040190943973509092025756868743192149481060781851142321049882584518043", "price": "0.207", "size": "210", "side": "SELL", "hash": "150e51e3b0119340fb83431d37305e7269da12f4", "best_bid": "0.193", "best_ask": "0.197"}], "timestamp": "1769384488566", "event_type": "price_change"}}
{"_local_timestamp": "2026-01-25T23:41:28.650467+00:00", "data": {"market": "0x66af911f31ceabb5f9a3ef9203a73f0b23d18aa81bbba7888dec440c622c2528", "price_changes": [{"asset_id": "101818439776033928818471919550932857351051302350112396692573347503051307979709", "price": "0.3", "size": "908.37", "side": "BUY", "hash": "5a99d485187f318f0c92a6c336517c9d7cfc3350", "best_bid": "0.3", "best_ask": "0.31"}, {"asset_id": "68639196051170795150992485552561385006521521637825690332014642323694437969760", "price": "0.7", "size": "908.37", "side": "SELL", "hash": "19e88109b10f4c442b44e807d4a8c269c431328d", "best_bid": "0.69", "best_ask": "0.7"}], "timestamp": "1769384488585", "event_type": "price_change"}}
{"_local_timestamp": "2026-01-25T23:41:29.923550+00:00", "data": {"market": "0xd87ac5bb74a21061d4f223d2a83c0269607fcb6d4c74d5a3d3220209d089431a", "price_changes": [{"asset_id": "73459237018178325517511938237778014293974381812181153063276727733805928508002", "price": "0.794", "size": "210", "side": "BUY", "hash": "37b07be085ce51cdabd4e52231ad0b22ad84acd5", "best_bid": "0.803", "best_ask": "0.807"}, {"asset_id": "63433408040190943973509092025756868743192149481060781851142321049882584518043", "price": "0.206", "size": "210", "side": "SELL", "hash": "96af3a706e1f70be593ac583632865b7c6144b4a", "best_bid": "0.193", "best_ask": "0.197"}], "timestamp": "1769384489858", "event_type": "price_change"}}
{"_local_timestamp": "2026-01-25T23:41:30.054096+00:00", "data": {"market": "0x66af911f31ceabb5f9a3ef9203a73f0b23d18aa81bbba7888dec440c622c2528", "price_changes": [{"asset_id": "101818439776033928818471919550932857351051302350112396692573347503051307979709", "price": "0.3", "size": "958.37", "side": "BUY", "hash": "47549dce34f045e392ff428ce84a6aca93049e3e", "best_bid": "0.3", "best_ask": "0.31"}, {"asset_id": "68639196051170795150992485552561385006521521637825690332014642323694437969760", "price": "0.7", "size": "958.37", "side": "SELL", "hash": "d163537e95c139b510820bf0bdf186e84bf8c972", "best_bid": "0.69", "best_ask": "0.7"}], "timestamp": "1769384489979", "event_type": "price_change"}}
{"_local_timestamp": "2026-01-25T23:41:30.176066+00:00", "data": {"market": "0x66af911f31ceabb5f9a3ef9203a73f0b23d18aa81bbba7888dec440c622c2528", "price_changes": [{"asset_id": "101818439776033928818471919550932857351051302350112396692573347503051307979709", "price": "0.3", "size": "908.37", "side": "BUY", "hash": "180bd26378ac093d58ee782e60a9fdb75319ce66", "best_bid": "0.3", "best_ask": "0.31"}, {"asset_id": "68639196051170795150992485552561385006521521637825690332014642323694437969760", "price": "0.7", "size": "908.37", "side": "SELL", "hash": "250d8209ec976639f4b4e2d95978d5562dcc929a", "best_bid": "0.69", "best_ask": "0.7"}], "timestamp": "1769384490098", "event_type": "price_change"}}
{"_local_timestamp": "2026-01-25T23:41:30.362990+00:00", "data": {"market": "0xd87ac5bb74a21061d4f223d2a83c0269607fcb6d4c74d5a3d3220209d089431a", "price_changes": [{"asset_id": "63433408040190943973509092025756868743192149481060781851142321049882584518043", "price": "0.186", "size": "0", "side": "BUY", "hash": "c7a20dec47e4a3002dd493abb6cbb4554ace3d99", "best_bid": "0.193", "best_ask": "0.197"}, {"asset_id": "73459237018178325517511938237778014293974381812181153063276727733805928508002", "price": "0.814", "size": "0", "side": "SELL", "hash": "d96f0d2294d2aeb6cac489e8356612d48be900fb", "best_bid": "0.803", "best_ask": "0.807"}], "timestamp": "1769384490285", "event_type": "price_change"}}
{"_local_timestamp": "2026-01-25T23:41:30.510618+00:00", "data": {"market": "0xd87ac5bb74a21061d4f223d2a83c0269607fcb6d4c74d5a3d3220209d089431a", "price_changes": [{"asset_id": "63433408040190943973509092025756868743192149481060781851142321049882584518043", "price": "0.186", "size": "230", "side": "BUY", "hash": "37125687ea5ed071321e32bf45cf67e9ff1b85eb", "best_bid": "0.193", "best_ask": "0.197"}, {"asset_id": "73459237018178325517511938237778014293974381812181153063276727733805928508002", "price": "0.814", "size": "230", "side": "SELL", "hash": "a9b0ec37221951e0bca66fd827abc8e553c0fa13", "best_bid": "0.803", "best_ask": "0.807"}], "timestamp": "1769384490444", "event_type": "price_change"}}
{"_local_timestamp": "2026-01-25T23:41:30.991159+00:00", "data": {"market": "0xd87ac5bb74a21061d4f223d2a83c0269607fcb6d4c74d5a3d3220209d089431a", "price_changes": [{"asset_id": "73459237018178325517511938237778014293974381812181153063276727733805928508002", "price": "0.793", "size": "0", "side": "BUY", "hash": "b5ec6eedb370b228492576f331dae99724c09e27", "best_bid": "0.803", "best_ask": "0.807"}, {"asset_id": "63433408040190943973509092025756868743192149481060781851142321049882584518043", "price": "0.207", "size": "0", "side": "SELL", "hash": "32aeabed10cf3ad4e5456bc1ed0e1d58709b43ba", "best_bid": "0.193", "best_ask": "0.197"}], "timestamp": "1769384490923", "event_type": "price_change"}}
{"_local_timestamp": "2026-01-25T23:41:31.104608+00:00", "data": {"market": "0x66af911f31ceabb5f9a3ef9203a73f0b23d18aa81bbba7888dec440c622c2528", "price_changes": [{"asset_id": "101818439776033928818471919550932857351051302350112396692573347503051307979709", "price": "0.3", "size": "958.37", "side": "BUY", "hash": "16c3a3c97ea6597474cca25725f90667dcf13996", "best_bid": "0.3", "best_ask": "0.31"}, {"asset_id": "68639196051170795150992485552561385006521521637825690332014642323694437969760", "price": "0.7", "size": "958.37", "side": "SELL", "hash": "c3437f9778194ec5a3594ec92ced31e1489e7236", "best_bid": "0.69", "best_ask": "0.7"}], "timestamp": "1769384491032", "event_type": "price_change"}}
{"_local_timestamp": "2026-01-25T23:41:31.226079+00:00", "data": {"market": "0x66af911f31ceabb5f9a3ef9203a73f0b23d18aa81bbba7888dec440c622c2528", "price_changes": [{"asset_id": "101818439776033928818471919550932857351051302350112396692573347503051307979709", "price": "0.3", "size": "908.37", "side": "BUY", "hash": "36e35d80e8e15b4b640e2209cae01792966879f2", "best_bid": "0.3", "best_ask": "0.31"}, {"asset_id": "68639196051170795150992485552561385006521521637825690332014642323694437969760", "price": "0.7", "size": "908.37", "side": "SELL", "hash": "2b2f19566985cb0d6f4047e20607449e66004654", "best_bid": "0.69", "best_ask": "0.7"}], "timestamp": "1769384491149", "event_type": "price_change"}}
{"_local_timestamp": "2026-01-25T23:41:32.926315+00:00", "data": {"market": "0xd87ac5bb74a21061d4f223d2a83c0269607fcb6d4c74d5a3d3220209d089431a", "price_changes": [{"asset_id": "63433408040190943973509092025756868743192149481060781851142321049882584518043", "price": "0.186", "size": "0", "side": "BUY", "hash": "87ccb48fd461e99c24b89e0ed8bc1a1d60778a79", "best_bid": "0.193", "best_ask": "0.197"}, {"asset_id": "73459237018178325517511938237778014293974381812181153063276727733805928508002", "price": "0.814", "size": "0", "side": "SELL", "hash": "40c4db088268a6522c58098dc95cb135eea9cb33", "best_bid": "0.803", "best_ask": "0.807"}], "timestamp": "1769384492852", "event_type": "price_change"}}
{"_local_timestamp": "2026-01-25T23:41:33.048063+00:00", "data": {"market": "0x66af911f31ceabb5f9a3ef9203a73f0b23d18aa81bbba7888dec440c622c2528", "price_changes": [{"asset_id": "101818439776033928818471919550932857351051302350112396692573347503051307979709", "price": "0.3", "size": "958.37", "side": "BUY", "hash": "599b981023c91d6e2544edcb6c304c5304ba9f61", "best_bid": "0.3", "best_ask": "0.31"}, {"asset_id": "68639196051170795150992485552561385006521521637825690332014642323694437969760", "price": "0.7", "size": "958.37", "side": "SELL", "hash": "d2c15d914a76293ae48fbd775ae011463cdda750", "best_bid": "0.69", "best_ask": "0.7"}], "timestamp": "1769384492973", "event_type": "price_change"}}
{"_local_timestamp": "2026-01-25T23:41:33.141518+00:00", "data": {"market": "0xd87ac5bb74a21061d4f223d2a83c0269607fcb6d4c74d5a3d3220209d089431a", "price_changes": [{"asset_id": "63433408040190943973509092025756868743192149481060781851142321049882584518043", "price": "0.186", "size": "210", "side": "BUY", "hash": "4a7c3fa17c59c10c21036fe47aa39b556976a416", "best_bid": "0.193", "best_ask": "0.197"}, {"asset_id": "73459237018178325517511938237778014293974381812181153063276727733805928508002", "price": "0.814", "size": "210", "side": "SELL", "hash": "2e4557e6cda74d12b0a9492f6366808acd142847", "best_bid": "0.803", "best_ask": "0.807"}], "timestamp": "1769384493070", "event_type": "price_change"}}
{"_local_timestamp": "2026-01-25T23:41:33.152633+00:00", "data": {"market": "0x66af911f31ceabb5f9a3ef9203a73f0b23d18aa81bbba7888dec440c622c2528", "price_changes": [{"asset_id": "101818439776033928818471919550932857351051302350112396692573347503051307979709", "price": "0.3", "size": "908.37", "side": "BUY", "hash": "0c384f3fe6a66e6b8e560d0989c0e24fb0bb0b59", "best_bid": "0.3", "best_ask": "0.31"}, {"asset_id": "68639196051170795150992485552561385006521521637825690332014642323694437969760", "price": "0.7", "size": "908.37", "side": "SELL", "hash": "cd97022d8ef6b5a896dbc6240ad026a7ceea94ed", "best_bid": "0.69", "best_ask": "0.7"}], "timestamp": "1769384493086", "event_type": "price_change"}}
{"_local_timestamp": "2026-01-25T23:41:37.344729+00:00", "data": {"market": "0xd87ac5bb74a21061d4f223d2a83c0269607fcb6d4c74d5a3d3220209d089431a", "price_changes": [{"asset_id": "73459237018178325517511938237778014293974381812181153063276727733805928508002", "price": "0.8", "size": "0", "side": "BUY", "hash": "90364ef872cba4005c1ccaf3f94932059e7739e0", "best_bid": "0.803", "best_ask": "0.807"}, {"asset_id": "63433408040190943973509092025756868743192149481060781851142321049882584518043", "price": "0.2", "size": "0", "side": "SELL", "hash": "0b86c4a4e59d251b979f692d37574e7ccc0438b4", "best_bid": "0.193", "best_ask": "0.197"}], "timestamp": "1769384497276", "event_type": "price_change"}}
{"_local_timestamp": "2026-01-25T23:41:37.458333+00:00", "data": {"market": "0x66af911f31ceabb5f9a3ef9203a73f0b23d18aa81bbba7888dec440c622c2528", "price_changes": [{"asset_id": "101818439776033928818471919550932857351051302350112396692573347503051307979709", "price": "0.3", "size": "958.37", "side": "BUY", "hash": "149231ce25bb4f53fe00d4edcf9bb013d3335ea4", "best_bid": "0.3", "best_ask": "0.31"}, {"asset_id": "68639196051170795150992485552561385006521521637825690332014642323694437969760", "price": "0.7", "size": "958.37", "side": "SELL", "hash": "86bcc1d4d3dda0f8a2d6241950127c930ed2d694", "best_bid": "0.69", "best_ask": "0.7"}], "timestamp": "1769384497383", "event_type": "price_change"}}
{"_local_timestamp": "2026-01-25T23:41:37.595658+00:00", "data": {"market": "0x66af911f31ceabb5f9a3ef9203a73f0b23d18aa81bbba7888dec440c622c2528", "price_changes": [{"asset_id": "101818439776033928818471919550932857351051302350112396692573347503051307979709", "price": "0.3", "size": "908.37", "side": "BUY", "hash": "77856e77415b46809baa3ee248974dcadbddfeed", "best_bid": "0.3", "best_ask": "0.31"}, {"asset_id": "68639196051170795150992485552561385006521521637825690332014642323694437969760", "price": "0.7", "size": "908.37", "side": "SELL", "hash": "66618a6cbb364bbc8f6bad9e22d11eda5577a573", "best_bid": "0.69", "best_ask": "0.7"}], "timestamp": "1769384497517", "event_type": "price_change"}}
{"_local_timestamp": "2026-01-25T23:41:38.175114+00:00", "data": {"market": "0xd87ac5bb74a21061d4f223d2a83c0269607fcb6d4c74d5a3d3220209d089431a", "price_changes": [{"asset_id": "73459237018178325517511938237778014293974381812181153063276727733805928508002", "price": "0.794", "size": "0", "side": "BUY", "hash": "7e20e3cad4b2c21521d021806417d7c525c313ab", "best_bid": "0.803", "best_ask": "0.807"}, {"asset_id": "63433408040190943973509092025756868743192149481060781851142321049882584518043", "price": "0.206", "size": "0", "side": "SELL", "hash": "bef1322af0975a34779050598dca03208d743db3", "best_bid": "0.193", "best_ask": "0.197"}], "timestamp": "1769384498104", "event_type": "price_change"}}
{"_local_timestamp": "2026-01-25T23:41:38.179343+00:00", "data": {"market": "0xd87ac5bb74a21061d4f223d2a83c0269607fcb6d4c74d5a3d3220209d089431a", "price_changes": [{"asset_id": "63433408040190943973509092025756868743192149481060781851142321049882584518043", "price": "0.186", "size": "0", "side": "BUY", "hash": "8ff6e008a34e560507b5c74b790cf8ef280b3484", "best_bid": "0.193", "best_ask": "0.197"}, {"asset_id": "73459237018178325517511938237778014293974381812181153063276727733805928508002", "price": "0.814", "size": "0", "side": "SELL", "hash": "8c81654c3005353ec152230db20ebf9affced9d2", "best_bid": "0.803", "best_ask": "0.807"}], "timestamp": "1769384498105", "event_type": "price_change"}}
{"_local_timestamp": "2026-01-25T23:41:39.046596+00:00", "data": {"market": "0xd87ac5bb74a21061d4f223d2a83c0269607fcb6d4c74d5a3d3220209d089431a", "price_changes": [{"asset_id": "63433408040190943973509092025756868743192149481060781851142321049882584518043", "price": "0.186", "size": "200", "side": "BUY", "hash": "4af8b2cb4d8eecb7f793d1ca40531065b387d967", "best_bid": "0.193", "best_ask": "0.197"}, {"asset_id": "73459237018178325517511938237778014293974381812181153063276727733805928508002", "price": "0.814", "size": "200", "side": "SELL", "hash": "1fba5bf6d2b6b5bb73a0b2e21d342e0326ed0c3e", "best_bid": "0.803", "best_ask": "0.807"}], "timestamp": "1769384498975", "event_type": "price_change"}}
{"_local_timestamp": "2026-01-25T23:41:39.047159+00:00", "data": {"market": "0xd87ac5bb74a21061d4f223d2a83c0269607fcb6d4c74d5a3d3220209d089431a", "price_changes": [{"asset_id": "73459237018178325517511938237778014293974381812181153063276727733805928508002", "price": "0.794", "size": "200", "side": "BUY", "hash": "17ebec25a4a70d0555deabdc9511bf87839c24e8", "best_bid": "0.803", "best_ask": "0.807"}, {"asset_id": "63433408040190943973509092025756868743192149481060781851142321049882584518043", "price": "0.206", "size": "200", "side": "SELL", "hash": "ad09bbd4d142386a2a6d9dd9fef90351bf0b3ff3", "best_bid": "0.193", "best_ask": "0.197"}], "timestamp": "1769384498976", "event_type": "price_change"}}
{"_local_timestamp": "2026-01-25T23:41:39.169873+00:00", "data": {"market": "0x66af911f31ceabb5f9a3ef9203a73f0b23d18aa81bbba7888dec440c622c2528", "price_changes": [{"asset_id": "101818439776033928818471919550932857351051302350112396692573347503051307979709", "price": "0.3", "size": "958.37", "side": "BUY", "hash": "f1d2990d2d7f81b8c07ad72bf906e01f15cee847", "best_bid": "0.3", "best_ask": "0.31"}, {"asset_id": "68639196051170795150992485552561385006521521637825690332014642323694437969760", "price": "0.7", "size": "958.37", "side": "SELL", "hash": "a5980c83cfd6a19e2666eecc463bbaa4390e6d56", "best_bid": "0.69", "best_ask": "0.7"}], "timestamp": "1769384499088", "event_type": "price_change"}}
{"_local_timestamp": "2026-01-25T23:41:39.284454+00:00", "data": {"market": "0x66af911f31ceabb5f9a3ef9203a73f0b23d18aa81bbba7888dec440c622c2528", "price_changes": [{"asset_id": "101818439776033928818471919550932857351051302350112396692573347503051307979709", "price": "0.3", "size": "908.37", "side": "BUY", "hash": "4adc4f34a91a16098617b8ade011569d8c9de4a9", "best_bid": "0.3", "best_ask": "0.31"}, {"asset_id": "68639196051170795150992485552561385006521521637825690332014642323694437969760", "price": "0.7", "size": "908.37", "side": "SELL", "hash": "6e945c47241dadda2fdbe77632c47d6ad12ee80c", "best_bid": "0.69", "best_ask": "0.7"}], "timestamp": "1769384499210", "event_type": "price_change"}}
{"_local_timestamp": "2026-01-25T23:41:47.155867+00:00", "data": {"market": "0xd87ac5bb74a21061d4f223d2a83c0269607fcb6d4c74d5a3d3220209d089431a", "price_changes": [{"asset_id": "73459237018178325517511938237778014293974381812181153063276727733805928508002", "price": "0.802", "size": "40", "side": "BUY", "hash": "095b4d46e93130ed0b6b9a6393f16d03f2a7caa0", "best_bid": "0.803", "best_ask": "0.807"}, {"asset_id": "63433408040190943973509092025756868743192149481060781851142321049882584518043", "price": "0.198", "size": "40", "side": "SELL", "hash": "c2e592560817741253d9a303d3c8e6da55245433", "best_bid": "0.193", "best_ask": "0.197"}], "timestamp": "1769384507081", "event_type": "price_change"}}
{"_local_timestamp": "2026-01-25T23:41:47.256289+00:00", "data": {"market": "0x66af911f31ceabb5f9a3ef9203a73f0b23d18aa81bbba7888dec440c622c2528", "price_changes": [{"asset_id": "101818439776033928818471919550932857351051302350112396692573347503051307979709", "price": "0.3", "size": "958.37", "side": "BUY", "hash": "5107e6ed1ec673dfe2f17225d8a568f62dcfafde", "best_bid": "0.3", "best_ask": "0.31"}, {"asset_id": "68639196051170795150992485552561385006521521637825690332014642323694437969760", "price": "0.7", "size": "958.37", "side": "SELL", "hash": "482d476872be9ddc837863226a460284b329ad63", "best_bid": "0.69", "best_ask": "0.7"}], "timestamp": "1769384507191", "event_type": "price_change"}}
{"_local_timestamp": "2026-01-25T23:41:47.367098+00:00", "data": {"market": "0x66af911f31ceabb5f9a3ef9203a73f0b23d18aa81bbba7888dec440c622c2528", "price_changes": [{"asset_id": "101818439776033928818471919550932857351051302350112396692573347503051307979709", "price": "0.3", "size": "908.37", "side": "BUY", "hash": "dd05575abe2469960dd9a09439895372e59a4a05", "best_bid": "0.3", "best_ask": "0.31"}, {"asset_id": "68639196051170795150992485552561385006521521637825690332014642323694437969760", "price": "0.7", "size": "908.37", "side": "SELL", "hash": "1b60b05db7a0e56af4d251f2413621ee2e1be39f", "best_bid": "0.69", "best_ask": "0.7"}], "timestamp": "1769384507295", "event_type": "price_change"}}
{"_local_timestamp": "2026-01-25T23:41:47.495108+00:00", "data": {"market": "0xd87ac5bb74a21061d4f223d2a83c0269607fcb6d4c74d5a3d3220209d089431a", "price_changes": [{"asset_id": "73459237018178325517511938237778014293974381812181153063276727733805928508002", "price": "0.794", "size": "0", "side": "BUY", "hash": "183ef03dd5023c96d7512de9e46887d3c3e8d674", "best_bid": "0.803", "best_ask": "0.807"}, {"asset_id": "63433408040190943973509092025756868743192149481060781851142321049882584518043", "price": "0.206", "size": "0", "side": "SELL", "hash": "ed8058a216ab945bdb3990bc367eecef6cb4af9c", "best_bid": "0.193", "best_ask": "0.197"}], "timestamp": "1769384507423", "event_type": "price_change"}}
{"_local_timestamp": "2026-01-25T23:41:47.495511+00:00", "data": {"market": "0xd87ac5bb74a21061d4f223d2a83c0269607fcb6d4c74d5a3d3220209d089431a", "price_changes": [{"asset_id": "63433408040190943973509092025756868743192149481060781851142321049882584518043", "price": "0.186", "size": "0", "side": "BUY", "hash": "0626adadb09516c9d70588c2c570ca0d07861a8e", "best_bid": "0.193", "best_ask": "0.197"}, {"asset_id": "73459237018178325517511938237778014293974381812181153063276727733805928508002", "price": "0.814", "size": "0", "side": "SELL", "hash": "aba2def06d12d384764f4b2eec1fbd116a75b086", "best_bid": "0.803", "best_ask": "0.807"}], "timestamp": "1769384507424", "event_type": "price_change"}}
{"_local_timestamp": "2026-01-25T23:41:47.645753+00:00", "data": {"market": "0xd87ac5bb74a21061d4f223d2a83c0269607fcb6d4c74d5a3d3220209d089431a", "price_changes": [{"asset_id": "63433408040190943973509092025756868743192149481060781851142321049882584518043", "price": "0.201", "size": "163.99", "side": "SELL", "hash": "fa1cce60a7f8b1deb99766004f2e7a251af02deb", "best_bid": "0.193", "best_ask": "0.197"}, {"asset_id": "73459237018178325517511938237778014293974381812181153063276727733805928508002", "price": "0.799", "size": "163.99", "side": "BUY", "hash": "8ea36bdaf25da4f7c3ae80c8d74cd110b01dadc1", "best_bid": "0.803", "best_ask": "0.807"}], "timestamp": "1769384507574", "event_type": "price_change"}}
{"_local_timestamp": "2026-01-25T23:41:47.672739+00:00", "data": {"market": "0xd87ac5bb74a21061d4f223d2a83c0269607fcb6d4c74d5a3d3220209d089431a", "price_changes": [{"asset_id": "63433408040190943973509092025756868743192149481060781851142321049882584518043", "price": "0.199", "size": "20.7", "side": "SELL", "hash": "644a766cdd6cd0318583ee36865dfcde5f203ed1", "best_bid": "0.193", "best_ask": "0.197"}, {"asset_id": "73459237018178325517511938237778014293974381812181153063276727733805928508002", "price": "0.801", "size": "20.7", "side": "BUY", "hash": "a1112e059982ed1444a4ac021232c34f1cce3ddb", "best_bid": "0.803", "best_ask": "0.807"}], "timestamp": "1769384507603", "event_type": "price_change"}}
{"_local_timestamp": "2026-01-25T23:41:48.288309+00:00", "data": {"market": "0xd87ac5bb74a21061d4f223d2a83c0269607fcb6d4c74d5a3d3220209d089431a", "price_changes": [{"asset_id": "73459237018178325517511938237778014293974381812181153063276727733805928508002", "price": "0.802", "size": "10", "side": "BUY", "hash": "48cf9f5f96572f573ed154a0f0b4d5132835160e", "best_bid": "0.803", "best_ask": "0.807"}, {"asset_id": "63433408040190943973509092025756868743192149481060781851142321049882584518043", "price": "0.198", "size": "10", "side": "SELL", "hash": "ba43b04bc478207508cb72a378849ec3142b60e1", "best_bid": "0.193", "best_ask": "0.197"}], "timestamp": "1769384508217", "event_type": "price_change"}}
{"_local_timestamp": "2026-01-25T23:41:48.358909+00:00", "data": {"market": "0xd87ac5bb74a21061d4f223d2a83c0269607fcb6d4c74d5a3d3220209d089431a", "price_changes": [{"asset_id": "73459237018178325517511938237778014293974381812181153063276727733805928508002", "price": "0.799", "size": "193.99", "side": "BUY", "hash": "4e638a4aebc839fecb61edb0ad035b24ba91ca54", "best_bid": "0.803", "best_ask": "0.807"}, {"asset_id": "63433408040190943973509092025756868743192149481060781851142321049882584518043", "price": "0.201", "size": "193.99", "side": "SELL", "hash": "56774f85a82b086c1a48c8d97a8466507b0f1b53", "best_bid": "0.193", "best_ask": "0.197"}], "timestamp": "1769384508294", "event_type": "price_change"}}
{"_local_timestamp": "2026-01-25T23:41:48.408912+00:00", "data": {"market": "0x66af911f31ceabb5f9a3ef9203a73f0b23d18aa81bbba7888dec440c622c2528", "price_changes": [{"asset_id": "101818439776033928818471919550932857351051302350112396692573347503051307979709", "price": "0.3", "size": "958.37", "side": "BUY", "hash": "654a53d87edc7ee487620476c700fa54c54bd716", "best_bid": "0.3", "best_ask": "0.31"}, {"asset_id": "68639196051170795150992485552561385006521521637825690332014642323694437969760", "price": "0.7", "size": "958.37", "side": "SELL", "hash": "10d0f220952da5d469b85b98e90ed27aa4e1a3d8", "best_bid": "0.69", "best_ask": "0.7"}], "timestamp": "1769384508333", "event_type": "price_change"}}
{"_local_timestamp": "2026-01-25T23:41:48.505445+00:00", "data": {"market": "0x66af911f31ceabb5f9a3ef9203a73f0b23d18aa81bbba7888dec440c622c2528", "price_changes": [{"asset_id": "101818439776033928818471919550932857351051302350112396692573347503051307979709", "price": "0.3", "size": "908.37", "side": "BUY", "hash": "23922df24d07e29659ad20343c1ab4f70588e002", "best_bid": "0.3", "best_ask": "0.31"}, {"asset_id": "68639196051170795150992485552561385006521521637825690332014642323694437969760", "price": "0.7", "size": "908.37", "side": "SELL", "hash": "798fdcf2b4dac90818e946a4d752a02db71bd9f1", "best_bid": "0.69", "best_ask": "0.7"}], "timestamp": "1769384508442", "event_type": "price_change"}}
{"_local_timestamp": "2026-01-25T23:41:49.019256+00:00", "data": {"market": "0xd87ac5bb74a21061d4f223d2a83c0269607fcb6d4c74d5a3d3220209d089431a", "price_changes": [{"asset_id": "63433408040190943973509092025756868743192149481060781851142321049882584518043", "price": "0.187", "size": "200", "side": "BUY", "hash": "ab6ffda44a062ae23f822d777558460822430437", "best_bid": "0.193", "best_ask": "0.197"}, {"asset_id": "73459237018178325517511938237778014293974381812181153063276727733805928508002", "price": "0.813", "size": "200", "side": "SELL", "hash": "3494973a40cabd7c7cabe23ccb764a9061b2ac1e", "best_bid": "0.803", "best_ask": "0.807"}], "timestamp": "1769384508950", "event_type": "price_change"}}
{"_local_timestamp": "2026-01-25T23:41:49.025236+00:00", "data": {"market": "0xd87ac5bb74a21061d4f223d2a83c0269607fcb6d4c74d5a3d3220209d089431a", "price_changes": [{"asset_id": "73459237018178325517511938237778014293974381812181153063276727733805928508002", "price": "0.792", "size": "528.74", "side": "BUY", "hash": "5b234eb1f8ef7599c59ead0a9057102f2325295a", "best_bid": "0.803", "best_ask": "0.807"}, {"asset_id": "63433408040190943973509092025756868743192149481060781851142321049882584518043", "price": "0.208", "size": "528.74", "side": "SELL", "hash": "7cb8120f1105c373e6bbbd4e48d7839cd98a5f0f", "best_bid": "0.193", "best_ask": "0.197"}], "timestamp": "1769384508951", "event_type": "price_change"}}
{"_local_timestamp": "2026-01-25T23:41:50.310827+00:00", "data": {"market": "0xd87ac5bb74a21061d4f223d2a83c0269607fcb6d4c74d5a3d3220209d089431a", "price_changes": [{"asset_id": "73459237018178325517511938237778014293974381812181153063276727733805928508002", "price": "0.79", "size": "300", "side": "BUY", "hash": "42bc1d5a91c5ff8dcf06b5a7662632fb95b1d203", "best_bid": "0.803", "best_ask": "0.807"}, {"asset_id": "63433408040190943973509092025756868743192149481060781851142321049882584518043", "price": "0.21", "size": "300", "side": "SELL", "hash": "95afee7604dca9a146c10901f700b4766c9e8a99", "best_bid": "0.193", "best_ask": "0.197"}], "timestamp": "1769384510243", "event_type": "price_change"}}
