{"_local_timestamp": "2026-01-25T23:33:18.140652+00:00", "data": [{"market": "0xe90b27f08082e17740308fdc957528d29a3f334a9ecaeefd056a3427a4cfdaaf", "asset_id": "28238304963115391468520084611709080022027216241044579007402765414035709535435", "timestamp": "1769383973720", "hash": "89208bb92547aeb780fca31080c5b96def635484", "bids": [], "asks": [{"price": "0.999", "size": "3965.21"}, {"price": "0.998", "size": "1250"}, {"price": "0.997", "size": "1406.62"}, {"price": "0.996", "size": "50"}, {"price": "0.994", "size": "200"}, {"price": "0.993", "size": "9.76"}, {"price": "0.99", "size": "6523"}, {"price": "0.989", "size": "30.14"}, {"price": "0.98", "size": "1000"}, {"price": "0.979", "size": "8.81"}, {"price": "0.967", "size": "1600"}, {"price": "0.965", "size": "500"}, {"price": "0.95", "size": "30"}, {"price": "0.94", "size": "900"}, {"price": "0.939", "size": "9.81"}, {"price": "0.9", "size": "860"}, {"price": "0.899", "size": "19"}, {"price": "0.85", "size": "226.66"}, {"price": "0.8", "size": "165"}, {"price": "0.783", "size": "50"}, {"price": "0.782", "size": "5.12"}, {"price": "0.75", "size": "122"}, {"price": "0.7", "size": "86.66"}, {"price": "0.65", "size": "68.57"}, {"price": "0.6", "size": "50"}, {"price": "0.499", "size": "27.22"}, {"price": "0.327", "size": "200"}, {"price": "0.24", "size": "254.63"}, {"price": "0.211", "size": "20"}, {"price": "0.19", "size": "100"}, {"price": "0.143", "size": "4040"}, {"price": "0.112", "size": "222"}, {"price": "0.1", "size": "10"}, {"price": "0.09", "size": "91.5"}, {"price": "0.08", "size": "1000"}, {"price": "0.079", "size": "400"}, {"price": "0.05", "size": "91.5"}, {"price": "0.048", "size": "30"}, {"price": "0.034", "size": "5555"}, {"price": "0.033", "size": "20"}, {"price": "0.027", "size": "39.21"}, {"price": "0.026", "size": "100"}, {"price": "0.015", "size": "750"}, {"price": "0.011", "size": "500"}, {"price": "0.01", "size": "6127.05"}, {"price": "0.008", "size": "2722"}, {"price": "0.007", "size": "999.75"}, {"price": "0.005", "size": "500"}, {"price": "0.003", "size": "1965.16"}, {"price": "0.002", "size": "83250.72"}, {"price": "0.001", "size": "16022.6"}], "event_type": "book", "last_trade_price": "0.001"}, {"market": "0x28101208d1076b3dc8fca84aeebe55cc8505b01f40c8e1d5c5fa3209cc395120", "asset_id": "114268099239767676216932072226652369234485747669785862612893982920970460896563", "timestamp": "1769383973617", "hash": "74bf76a4438b77a94a69a129574f9c3ed60a4de9", "bids": [], "asks": [{"price": "0.999", "size": "3818.06"}, {"price": "0.998", "size": "12.44"}, {"price": "0.997", "size": "1400"}, {"price": "0.994", "size": "200"}, {"price": "0.993", "size": "9.76"}, {"price": "0.99", "size": "6523"}, {"price": "0.98", "size": "3600"}, {"price": "0.979", "size": "8.81"}, {"price": "0.95", "size": "30"}, {"price": "0.94", "size": "900"}, {"price": "0.939", "size": "8.89"}, {"price": "0.9", "size": "360"}, {"price": "0.85", "size": "226.66"}, {"price": "0.808", "size": "2409.97"}, {"price": "0.8", "size": "160"}, {"price": "0.799", "size": "5.84"}, {"price": "0.777", "size": "142"}, {"price": "0.75", "size": "112"}, {"price": "0.749", "size": "7"}, {"price": "0.7", "size": "86.66"}, {"price": "0.65", "size": "68.57"}, {"price": "0.6", "size": "50"}, {"price": "0.477", "size": "136"}, {"price": "0.277", "size": "190"}, {"price": "0.077", "size": "486"}, {"price": "0.07", "size": "800"}, {"price": "0.069", "size": "30"}, {"price": "0.043", "size": "13.33"}, {"price": "0.041", "size": "20"}, {"price": "0.04", "size": "20"}, {"price": "0.039", "size": "500"}, {"price": "0.005", "size": "500"}, {"price": "0.003", "size": "2225.49"}, {"price": "0.002", "size": "4700.66"}, {"price": "0.001", "size": "213004"}], "event_type": "book", "last_trade_price": ""}, {"market": "0x5978de4126f53a200c36ea4b7766939c25018d8a21b33262fe502aafb53ff175", "asset_id": "55686039718579262217898471358118121317954263277833427045622695540288066380442", "timestamp": "1769383973624", "hash": "939234d6d8509ad824d39c04a6de2261fb269944", "bids": [{"price": "0.001", "size": "3434.06"}, {"price": "0.002", "size": "1250"}, {"price": "0.003", "size": "1406.75"}, {"price": "0.006", "size": "200"}, {"price": "0.007", "size": "9.76"}, {"price": "0.01", "size": "6523"}, {"price": "0.02", "size": "2600"}, {"price": "0.021", "size": "11.53"}, {"price": "0.05", "size": "10"}, {"price": "0.073", "size": "978.9"}, {"price": "0.074", "size": "6.56"}, {"price": "0.1", "size": "860"}, {"price": "0.15", "size": "226.66"}, {"price": "0.2", "size": "160"}, {"price": "0.201", "size": "5.84"}, {"price": "0.223", "size": "55"}, {"price": "0.25", "size": "612"}, {"price": "0.251", "size": "7"}, {"price": "0.3", "size": "86.66"}, {"price": "0.35", "size": "68.57"}, {"price": "0.4", "size": "50"}, {"price": "0.5", "size": "500"}, {"price": "0.523", "size": "136"}, {"price": "0.723", "size": "106"}, {"price": "0.75", "size": "500"}, {"price": "0.823", "size": "107"}, {"price": "0.923", "size": "712"}, {"price": "0.926", "size": "623.53"}, {"price": "0.936", "size": "800"}, {"price": "0.945", "size": "30"}, {"price": "0.946", "size": "20"}, {"price": "0.947", "size": "400"}, {"price": "0.983", "size": "467.65"}, {"price": "0.99", "size": "1400"}, {"price": "0.991", "size": "20"}, {"price": "0.992", "size": "100"}, {"price": "0.998", "size": "4098.42"}, {"price": "0.999", "size": "267553.7"}], "asks": [], "event_type": "book", "last_trade_price": ""}, {"market": "0xc9dc3221d327cdca2401a80e8b138e6f81e17e7aabb0ae4915ec744e37d89fb9", "asset_id": "48766341308125246446934576208296715790150929628230476623094742688581948013790", "timestamp": "1769383973709", "hash": "2406415fa271e91c6f38f6415963121a304d006b", "bids": [{"price": "0.001", "size": "3874.54"}, {"price": "0.002", "size": "1250"}, {"price": "0.003", "size": "1406.62"}, {"price": "0.006", "size": "200"}, {"price": "0.007", "size": "9.76"}, {"price": "0.01", "size": "6538"}, {"price": "0.02", "size": "2600"}, {"price": "0.021", "size": "8.81"}, {"price": "0.05", "size": "10"}, {"price": "0.06", "size": "900"}, {"price": "0.061", "size": "8.89"}, {"price": "0.1", "size": "860"}, {"price": "0.15", "size": "226.66"}, {"price": "0.2", "size": "160"}, {"price": "0.201", "size": "5.84"}, {"price": "0.223", "size": "56"}, {"price": "0.25", "size": "112"}, {"price": "0.3", "size": "86.66"}, {"price": "0.34", "size": "3820.9"}, {"price": "0.341", "size": "5"}, {"price": "0.35", "size": "68.57"}, {"price": "0.4", "size": "50"}, {"price": "0.523", "size": "135"}, {"price": "0.65", "size": "2547.26"}, {"price": "0.723", "size": "106"}, {"price": "0.799", "size": "500"}, {"price": "0.823", "size": "107"}, {"price": "0.923", "size": "712"}, {"price": "0.928", "size": "800"}, {"price": "0.953", "size": "30"}, {"price": "0.954", "size": "20"}, {"price": "0.981", "size": "1016.62"}, {"price": "0.987", "size": "100"}, {"price": "0.988", "size": "13.33"}, {"price": "0.989", "size": "20"}, {"price": "0.995", "size": "4843.88"}, {"price": "0.997", "size": "10000"}, {"price": "0.998", "size": "16635.67"}, {"price": "0.999", "size": "246993.37"}], "asks": [], "event_type": "book", "last_trade_price": ""}, {"market": "0x18b1dc1565575cb2ff48bbc078070170ca3278691860cca7c97131fc657a9530", "asset_id": "94238513083578948523157790197851186920885838535648691968842196265124859609799", "timestamp": "1769383973576", "hash": "f083b5da7326a07a24b474e1b483fd7d5fd9d673", "bids": [{"price": "0.001", "size": "107929.06"}, {"price": "0.002", "size": "12.44"}, {"price": "0.003", "size": "1400"}, {"price": "0.006", "size": "200"}, {"price": "0.007", "size": "9.76"}, {"price": "0.01", "size": "2023"}, {"price": "0.02", "size": "2600"}, {"price": "0.021", "size": "8.81"}, {"price": "0.05", "size": "10"}, {"price": "0.06", "size": "900"}, {"price": "0.061", "size": "8.89"}, {"price": "0.1", "size": "860"}, {"price": "0.15", "size": "226.66"}, {"price": "0.2", "size": "160"}, {"price": "0.201", "size": "5.84"}, {"price": "0.223", "size": "116"}, {"price": "0.25", "size": "112"}, {"price": "0.251", "size": "7"}, {"price": "0.3", "size": "86.66"}, {"price": "0.35", "size": "68.57"}, {"price": "0.4", "size": "50"}, {"price": "0.523", "size": "136"}, {"price": "0.723", "size": "163"}, {"price": "0.799", "size": "500"}, {"price": "0.823", "size": "169"}, {"price": "0.923", "size": "1085"}, {"price": "0.95", "size": "300"}, {"price": "0.951", "size": "30"}, {"price": "0.968", "size": "500"}, {"price": "0.969", "size": "13.33"}, {"price": "0.97", "size": "20"}, {"price": "0.971", "size": "20"}, {"price": "0.996", "size": "1913.39"}, {"price": "0.997", "size": "243.12"}, {"price": "0.998", "size": "6941.53"}, {"price": "0.999", "size": "277601.14"}], "asks": [], "event_type": "book", "last_trade_price": ""}, {"market": "0xa062dea464f0e8fc3381176494198cf45574ec190eca77a40f49988320fa15f2", "asset_id": "2941656641529467089826910607945793276058581543804243973571467775773698944388", "timestamp": "1769383997327", "hash": "2bbb03e1d16f083e65b1ac7331a5ed6ed628dd87", "bids": [{"price": "0.001", "size": "45562.37"}, {"price": "0.002", "size": "15734.94"}, {"price": "0.003", "size": "542.73"}, {"price": "0.004", "size": "61.48"}, {"price": "0.005", "size": "4130.4"}, {"price": "0.006", "size": "221.09"}, {"price": "0.007", "size": "34.86"}, {"price": "0.008", "size": "140"}, {"price": "0.009", "size": "2014.08"}, {"price": "0.01", "size": "588.47"}, {"price": "0.011", "size": "3353.39"}, {"price": "0.012", "size": "1710.42"}, {"price": "0.013", "size": "1009.59"}, {"price": "0.014", "size": "57790.89"}, {"price": "0.015", "size": "2344.34"}, {"price": "0.016", "size": "1469.81"}, {"price": "0.017", "size": "1113.04"}, {"price": "0.018", "size": "26165.98"}, {"price": "0.019", "size": "19690.87"}], "asks": [{"price": "0.999", "size": "11982"}, {"price": "0.997", "size": "1000"}, {"price": "0.99", "size": "6538"}, {"price": "0.989", "size": "8.26"}, {"price": "0.98", "size": "1100"}, {"price": "0.978", "size": "101600"}, {"price": "0.97", "size": "53.36"}, {"price": "0.95", "size": "20"}, {"price": "0.949", "size": "39"}, {"price": "0.94", "size": "900"}, {"price": "0.9", "size": "360"}, {"price": "0.899", "size": "8.59"}, {"price": "0.894", "size": "8.59"}, {"price": "0.85", "size": "226.66"}, {"price": "0.815", "size": "735.91"}, {"price": "0.81", "size": "32"}, {"price": "0.8", "size": "190"}, {"price": "0.791", "size": "300"}, {"price": "0.79", "size": "1218.35"}, {"price": "0.75", "size": "112"}, {"price": "0.72", "size": "5"}, {"price": "0.71", "size": "89.65"}, {"price": "0.7", "size": "5"}, {"price": "0.69", "size": "5"}, {"price": "0.67", "size": "19"}, {"price": "0.66", "size": "70.58"}, {"price": "0.64", "size": "30"}, {"price": "0.61", "size": "51.28"}, {"price": "0.555", "size": "12.61"}, {"price": "0.53", "size": "142.31"}, {"price": "0.508", "size": "10"}, {"price": "0.5", "size": "69.03"}, {"price": "0.45", "size": "70"}, {"price": "0.4", "size": "120"}, {"price": "0.35", "size": "247.87"}, {"price": "0.338", "size": "45"}, {"price": "0.331", "size": "37.5"}, {"price": "0.33", "size": "100"}, {"price": "0.321", "size": "200"}, {"price": "0.318", "size": "110"}, {"price": "0.293", "size": "18.75"}, {"price": "0.267", "size": "6.82"}, {"price": "0.255", "size": "6.71"}, {"price": "0.25", "size": "4311.92"}, {"price": "0.247", "size": "100"}, {"price": "0.213", "size": "100"}, {"price": "0.17", "size": "2041.92"}, {"price": "0.15", "size": "4880"}, {"price": "0.109", "size": "1111"}, {"price": "0.1", "size": "356.68"}, {"price": "0.099", "size": "100"}, {"price": "0.098", "size": "200"}, {"price": "0.093", "size": "1000"}, {"price": "0.08", "size": "5000"}, {"price": "0.075", "size": "500"}, {"price": "0.073", "size": "714"}, {"price": "0.072", "size": "400"}, {"price": "0.07", "size": "2222"}, {"price": "0.068", "size": "3222"}, {"price": "0.066", "size": "11000"}, {"price": "0.065", "size": "3381.33"}, {"price": "0.061", "size": "272"}, {"price": "0.06", "size": "2995"}, {"price": "0.059", "size": "20"}, {"price": "0.057", "size": "222"}, {"price": "0.056", "size": "10000"}, {"price": "0.055", "size": "1209.9"}, {"price": "0.054", "size": "100"}, {"price": "0.05", "size": "1748.13"}, {"price": "0.049", "size": "1400"}, {"price": "0.048", "size": "2500"}, {"price": "0.047", "size": "1400"}, {"price": "0.046", "size": "313.58"}, {"price": "0.045", "size": "1000"}, {"price": "0.044", "size": "3433"}, {"price": "0.043", "size": "3333"}, {"price": "0.042", "size": "1600"}, {"price": "0.04", "size": "15040"}, {"price": "0.039", "size": "3938"}, {"price": "0.038", "size": "11883.12"}, {"price": "0.037", "size": "2750"}, {"price": "0.036", "size": "3000"}, {"price": "0.035", "size": "2422"}, {"price": "0.034", "size": "2222"}, {"price": "0.033", "size": "487"}, {"price": "0.032", "size": "3769.05"}, {"price": "0.031", "size": "200"}, {"price": "0.03", "size": "3414.76"}, {"price": "0.029", "size": "2422"}, {"price": "0.028", "size": "6777"}, {"price": "0.027", "size": "2221.23"}, {"price": "0.026", "size": "222"}, {"price": "0.025", "size": "5625"}, {"price": "0.024", "size": "3020.61"}, {"price": "0.023", "size": "200"}, {"price": "0.022", "size": "3399.91"}, {"price": "0.021", "size": "7311.51"}, {"price": "0.02", "size": "1623.34"}], "event_type": "book", "last_trade_price": "0.980"}, {"market": "0x18b1dc1565575cb2ff48bbc078070170ca3278691860cca7c97131fc657a9530", "asset_id": "62947063083572838306765336947158511397004781598875199570718451493234069599112", "timestamp": "1769383973576", "hash": "3c890cb703b9053a61a1aed7e88b3ba548ac2663", "bids": [], "asks": [{"price": "0.999", "size": "107929.06"}, {"price": "0.998", "size": "12.44"}, {"price": "0.997", "size": "1400"}, {"price": "0.994", "size": "200"}, {"price": "0.993", "size": "9.76"}, {"price": "0.99", "size": "2023"}, {"price": "0.98", "size": "2600"}, {"price": "0.979", "size": "8.81"}, {"price": "0.95", "size": "10"}, {"price": "0.94", "size": "900"}, {"price": "0.939", "size": "8.89"}, {"price": "0.9", "size": "860"}, {"price": "0.85", "size": "226.66"}, {"price": "0.8", "size": "160"}, {"price": "0.799", "size": "5.84"}, {"price": "0.777", "size": "116"}, {"price": "0.75", "size": "112"}, {"price": "0.749", "size": "7"}, {"price": "0.7", "size": "86.66"}, {"price": "0.65", "size": "68.57"}, {"price": "0.6", "size": "50"}, {"price": "0.477", "size": "136"}, {"price": "0.277", "size": "163"}, {"price": "0.201", "size": "500"}, {"price": "0.177", "size": "169"}, {"price": "0.077", "size": "1085"}, {"price": "0.05", "size": "300"}, {"price": "0.049", "size": "30"}, {"price": "0.032", "size": "500"}, {"price": "0.031", "size": "13.33"}, {"price": "0.03", "size": "20"}, {"price": "0.029", "size": "20"}, {"price": "0.004", "size": "1913.39"}, {"price": "0.003", "size": "243.12"}, {"price": "0.002", "size": "6941.53"}, {"price": "0.001", "size": "277601.14"}], "event_type": "book", "last_trade_price": ""}, {"market": "0xbc4e7ff877a14d8e0dd44bdc0f95ca7a1cf0956fdcfeaf57828a9a9761f95f91", "asset_id": "81372000365657396899698940022086156768341700625390186483857935271769196010661", "timestamp": "1769383973647", "hash": "b92ea41058cd9f10de96eaad7e1861bdd417271f", "bids": [], "asks": [{"price": "0.999", "size": "107934.12"}, {"price": "0.998", "size": "1250"}, {"price": "0.997", "size": "1406.66"}, {"price": "0.994", "size": "200"}, {"price": "0.993", "size": "9.82"}, {"price": "0.99", "size": "2023"}, {"price": "0.98", "size": "2600"}, {"price": "0.979", "size": "8.81"}, {"price": "0.95", "size": "10"}, {"price": "0.94", "size": "900"}, {"price": "0.939", "size": "8.89"}, {"price": "0.9", "size": "860"}, {"price": "0.85", "size": "226.66"}, {"price": "0.8", "size": "160"}, {"price": "0.799", "size": "5.84"}, {"price": "0.777", "size": "116"}, {"price": "0.75", "size": "112"}, {"price": "0.73", "size": "2346.66"}, {"price": "0.729", "size": "7"}, {"price": "0.7", "size": "86.66"}, {"price": "0.65", "size": "68.57"}, {"price": "0.6", "size": "50"}, {"price": "0.477", "size": "136"}, {"price": "0.277", "size": "163"}, {"price": "0.201", "size": "500"}, {"price": "0.177", "size": "169"}, {"price": "0.077", "size": "1084"}, {"price": "0.067", "size": "30"}, {"price": "0.066", "size": "20"}, {"price": "0.01", "size": "200"}, {"price": "0.009", "size": "20"}, {"price": "0.008", "size": "100"}, {"price": "0.002", "size": "2705.29"}, {"price": "0.001", "size": "275153.52"}], "event_type": "book", "last_trade_price": ""}, {"market": "0x5978de4126f53a200c36ea4b7766939c25018d8a21b33262fe502aafb53ff175", "asset_id": "86404983960076139434906161226427662155018233298930936207604646797328591011555", "timestamp": "1769383973624", "hash": "bfbde2278b61b0f05fb42542e880de6c71a359af", "bids": [], "asks": [{"price": "0.999", "size": "3434.06"}, {"price": "0.998", "size": "1250"}, {"price": "0.997", "size": "1406.75"}, {"price": "0.994", "size": "200"}, {"price": "0.993", "size": "9.76"}, {"price": "0.99", "size": "6523"}, {"price": "0.98", "size": "2600"}, {"price": "0.979", "size": "11.53"}, {"price": "0.95", "size": "10"}, {"price": "0.927", "size": "978.9"}, {"price": "0.926", "size": "6.56"}, {"price": "0.9", "size": "860"}, {"price": "0.85", "size": "226.66"}, {"price": "0.8", "size": "160"}, {"price": "0.799", "size": "5.84"}, {"price": "0.777", "size": "55"}, {"price": "0.75", "size": "612"}, {"price": "0.749", "size": "7"}, {"price": "0.7", "size": "86.66"}, {"price": "0.65", "size": "68.57"}, {"price": "0.6", "size": "50"}, {"price": "0.5", "size": "500"}, {"price": "0.477", "size": "136"}, {"price": "0.277", "size": "106"}, {"price": "0.25", "size": "500"}, {"price": "0.177", "size": "107"}, {"price": "0.077", "size": "712"}, {"price": "0.074", "size": "623.53"}, {"price": "0.064", "size": "800"}, {"price": "0.055", "size": "30"}, {"price": "0.054", "size": "20"}, {"price": "0.053", "size": "400"}, {"price": "0.017", "size": "467.65"}, {"price": "0.01", "size": "1400"}, {"price": "0.009", "size": "20"}, {"price": "0.008", "size": "100"}, {"price": "0.002", "size": "4098.42"}, {"price": "0.001", "size": "267553.7"}], "event_type": "book", "last_trade_price": ""}, {"market": "0x35fdbb84a6a3c45466deea33ee0f0500e70078351ff8b8fb0576d361bb2eeed1", "asset_id": "24011118810488517375094120406825332891380879921211182164289459185965007517350", "timestamp": "1769383973665", "hash": "d683b8311367280a5ac2a9fc1602f4d0b8e909ac", "bids": [{"price": "0.001", "size": "3434.06"}, {"price": "0.002", "size": "3559.81"}, {"price": "0.003", "size": "1406.62"}, {"price": "0.006", "size": "200"}, {"price": "0.007", "size": "9.76"}, {"price": "0.01", "size": "6523"}, {"price": "0.02", "size": "2600"}, {"price": "0.021", "size": "8.81"}, {"price": "0.05", "size": "10"}, {"price": "0.06", "size": "900"}, {"price": "0.061", "size": "8.89"}, {"price": "0.1", "size": "860"}, {"price": "0.15", "size": "226.66"}, {"price": "0.2", "size": "160"}, {"price": "0.201", "size": "5.84"}, {"price": "0.223", "size": "143"}, {"price": "0.25", "size": "112"}, {"price": "0.251", "size": "7"}, {"price": "0.3", "size": "86.66"}, {"price": "0.35", "size": "68.57"}, {"price": "0.4", "size": "50"}, {"price": "0.523", "size": "136"}, {"price": "0.799", "size": "500"}, {"price": "0.888", "size": "1093.97"}, {"price": "0.923", "size": "486"}, {"price": "0.934", "size": "30"}, {"price": "0.935", "size": "20"}, {"price": "0.99", "size": "1010"}, {"price": "0.991", "size": "120"}, {"price": "0.995", "size": "250"}, {"price": "0.996", "size": "250"}, {"price": "0.997", "size": "3090.64"}, {"price": "0.998", "size": "2409.05"}, {"price": "0.999", "size": "253382.64"}], "asks": [], "event_type": "book", "last_trade_price": ""}, {"market": "0xa619cefee23be0abf807ea451642fe20c497ecb2fd705ee645c3d96d8d11637c", "asset_id": "43809300640517111448589613647258299174716089741074782107715826383730069021126", "timestamp": "1769383973664", "hash": "d9b477099ed040c4582d06fdb37fd6ddc0e7b5c2", "bids": [], "asks": [{"price": "0.999", "size": "107934.06"}, {"price": "0.998", "size": "1250"}, {"price": "0.997", "size": "1406.62"}, {"price": "0.996", "size": "4586.03"}, {"price": "0.994", "size": "200"}, {"price": "0.993", "size": "9.76"}, {"price": "0.99", "size": "1023"}, {"price": "0.98", "size": "3600"}, {"price": "0.979", "size": "8.81"}, {"price": "0.95", "size": "10"}, {"price": "0.94", "size": "900"}, {"price": "0.939", "size": "8.89"}, {"price": "0.9", "size": "860"}, {"price": "0.85", "size": "226.66"}, {"price": "0.8", "size": "160"}, {"price": "0.799", "size": "5.84"}, {"price": "0.777", "size": "143"}, {"price": "0.75", "size": "112"}, {"price": "0.749", "size": "7"}, {"price": "0.7", "size": "86.66"}, {"price": "0.65", "size": "68.57"}, {"price": "0.6", "size": "50"}, {"price": "0.477", "size": "136"}, {"price": "0.201", "size": "500"}, {"price": "0.077", "size": "486"}, {"price": "0.064", "size": "400"}, {"price": "0.063", "size": "30"}, {"price": "0.062", "size": "20"}, {"price": "0.016", "size": "660.21"}, {"price": "0.011", "size": "66.66"}, {"price": "0.009", "size": "120"}, {"price": "0.003", "size": "5974.71"}, {"price": "0.002", "size": "1704.63"}, {"price": "0.001", "size": "290815.75"}], "event_type": "book", "last_trade_price": ""}, {"market": "0x1d5827b0448938c4c40a1c6747abc61e4ff690ac3d7306e0690c1741eb6dcb0b", "asset_id": "50298286906716199010522025175676678342201745398212393361362499308691655626332", "timestamp": "1769383973567", "hash": "6cc0414e254cf36c5a2679a79b2d2eafe1cf8714", "bids": [{"price": "0.001", "size": "107934.06"}, {"price": "0.002", "size": "1250"}, {"price": "0.003", "size": "1406.62"}, {"price": "0.006", "size": "200"}, {"price": "0.007", "size": "9.76"}, {"price": "0.01", "size": "2023"}, {"price": "0.02", "size": "2600"}, {"price": "0.021", "size": "8.81"}, {"price": "0.05", "size": "10"}, {"price": "0.06", "size": "900"}, {"price": "0.061", "size": "8.89"}, {"price": "0.1", "size": "860"}, {"price": "0.15", "size": "226.66"}, {"price": "0.151", "size": "13"}, {"price": "0.2", "size": "160"}, {"price": "0.201", "size": "5.84"}, {"price": "0.223", "size": "116"}, {"price": "0.25", "size": "112"}, {"price": "0.3", "size": "86.66"}, {"price": "0.35", "size": "68.57"}, {"price": "0.4", "size": "50"}, {"price": "0.523", "size": "136"}, {"price": "0.723", "size": "163"}, {"price": "0.823", "size": "169"}, {"price": "0.863", "size": "2749.91"}, {"price": "0.923", "size": "1085"}, {"price": "0.924", "size": "30"}, {"price": "0.962", "size": "400"}, {"price": "0.963", "size": "20"}, {"price": "0.987", "size": "166.66"}, {"price": "0.988", "size": "13"}, {"price": "0.989", "size": "20"}, {"price": "0.997", "size": "362.49"}, {"price": "0.998", "size": "7926.21"}, {"price": "0.999", "size": "267471.44"}], "asks": [], "event_type": "book", "last_trade_price": ""}, {"market": "0x0bdf73e4f9d1f9bddd76011f7c7f70ac2a7bf02858f6e724ff17fab39cdb84aa", "asset_id": "44060160461153155780840707322998889704290849153451415562546100515099098148308", "timestamp": "1769383973722", "hash": "8d2158e70345ee4d2969f60d1b510a1777cd0176", "bids": [{"price": "0.001", "size": "3844.06"}, {"price": "0.002", "size": "1250"}, {"price": "0.003", "size": "1406.62"}, {"price": "0.006", "size": "200"}, {"price": "0.007", "size": "9.76"}, {"price": "0.01", "size": "6538"}, {"price": "0.02", "size": "2600"}, {"price": "0.021", "size": "8.81"}, {"price": "0.05", "size": "10"}, {"price": "0.06", "size": "900"}, {"price": "0.061", "size": "8.95"}, {"price": "0.1", "size": "860"}, {"price": "0.15", "size": "226.66"}, {"price": "0.2", "size": "160"}, {"price": "0.203", "size": "9"}, {"price": "0.204", "size": "5.73"}, {"price": "0.223", "size": "5"}, {"price": "0.25", "size": "112"}, {"price": "0.3", "size": "86.66"}, {"price": "0.35", "size": "68.57"}, {"price": "0.4", "size": "50"}, {"price": "0.523", "size": "6"}, {"price": "0.723", "size": "106"}, {"price": "0.823", "size": "107"}, {"price": "0.887", "size": "999.99"}, {"price": "0.923", "size": "711"}, {"price": "0.928", "size": "800"}, {"price": "0.93", "size": "30"}, {"price": "0.963", "size": "749.99"}, {"price": "0.964", "size": "20"}, {"price": "0.972", "size": "69"}, {"price": "0.973", "size": "13"}, {"price": "0.974", "size": "20"}, {"price": "0.975", "size": "500"}, {"price": "0.998", "size": "573.79"}, {"price": "0.999", "size": "274609.06"}], "asks": [], "event_type": "book", "last_trade_price": "0.001"}, {"market": "0x1a550f4be5469a1f7f19a6a87eb1d3c5aee638dd4b325cd7e80c94fcb69a4325", "asset_id": "100299191321741533544964863678141476981783881954596444647911413684277151596082", "timestamp": "1769383973692", "hash": "8cee1802b21fa0f1dcdd3bb523c58d68298c5d16", "bids": [{"price": "0.001", "size": "107929.06"}, {"price": "0.002", "size": "12.44"}, {"price": "0.003", "size": "1400"}, {"price": "0.006", "size": "200"}, {"price": "0.007", "size": "9.76"}, {"price": "0.01", "size": "2023"}, {"price": "0.02", "size": "2600"}, {"price": "0.021", "size": "8.81"}, {"price": "0.05", "size": "10"}, {"price": "0.06", "size": "900"}, {"price": "0.061", "size": "8.89"}, {"price": "0.1", "size": "860"}, {"price": "0.15", "size": "226.66"}, {"price": "0.2", "size": "160"}, {"price": "0.201", "size": "5.84"}, {"price": "0.223", "size": "143"}, {"price": "0.25", "size": "112"}, {"price": "0.3", "size": "86.66"}, {"price": "0.34", "size": "740.77"}, {"price": "0.35", "size": "68.57"}, {"price": "0.351", "size": "5"}, {"price": "0.4", "size": "50"}, {"price": "0.523", "size": "136"}, {"price": "0.799", "size": "500"}, {"price": "0.923", "size": "486"}, {"price": "0.93", "size": "800"}, {"price": "0.939", "size": "13.33"}, {"price": "0.94", "size": "20"}, {"price": "0.941", "size": "30"}, {"price": "0.942", "size": "20"}, {"price": "0.991", "size": "550"}, {"price": "0.992", "size": "746.12"}, {"price": "0.998", "size": "2981.48"}, {"price": "0.999", "size": "260426.46"}], "asks": [], "event_type": "book", "last_trade_price": ""}, {"market": "0xdcf89266de269fa8d785c5a6218c482f08cf26f9987d879fc97d6a335238a08c", "asset_id": "80955738350011048477695041166314820890097312693648599864162887413862093761380", "timestamp": "1769383973583", "hash": "8d75d7e1bf7a874a3e6c209528e540c9fc556649", "bids": [], "asks": [{"price": "0.999", "size": "107934.06"}, {"price": "0.998", "size": "1250"}, {"price": "0.997", "size": "1406.62"}, {"price": "0.994", "size": "200"}, {"price": "0.993", "size": "9.76"}, {"price": "0.99", "size": "2023"}, {"price": "0.98", "size": "2600"}, {"price": "0.979", "size": "9.65"}, {"price": "0.95", "size": "10"}, {"price": "0.936", "size": "1249.74"}, {"price": "0.935", "size": "8.07"}, {"price": "0.9", "size": "860"}, {"price": "0.85", "size": "226.66"}, {"price": "0.8", "size": "160"}, {"price": "0.799", "size": "5.84"}, {"price": "0.777", "size": "143"}, {"price": "0.75", "size": "112"}, {"price": "0.749", "size": "7"}, {"price": "0.7", "size": "86.66"}, {"price": "0.65", "size": "68.57"}, {"price": "0.6", "size": "50"}, {"price": "0.477", "size": "136"}, {"price": "0.201", "size": "500"}, {"price": "0.138", "size": "155.43"}, {"price": "0.117", "size": "1808.27"}, {"price": "0.077", "size": "486"}, {"price": "0.064", "size": "800"}, {"price": "0.062", "size": "30"}, {"price": "0.038", "size": "400"}, {"price": "0.037", "size": "20"}, {"price": "0.015", "size": "116.57"}, {"price": "0.014", "size": "166.66"}, {"price": "0.013", "size": "13"}, {"price": "0.012", "size": "20"}, {"price": "0.003", "size": "243.5"}, {"price": "0.002", "size": "15089.21"}, {"price": "0.001", "size": "262654.81"}], "event_type": "book", "last_trade_price": ""}, {"market": "0xe115524784ad092f0e7e078973922c5010f2a1c38c2fb8a9bce309c0ca79f1a8", "asset_id": "90676939756845354759958308520069974858258774745328085486434854508498315177330", "timestamp": "1769383973703", "hash": "dc80ed68489f47f3575224b147cdff73ea49e0d1", "bids": [], "asks": [{"price": "0.999", "size": "3934.06"}, {"price": "0.998", "size": "1250"}, {"price": "0.997", "size": "1406.62"}, {"price": "0.994", "size": "200"}, {"price": "0.993", "size": "9.76"}, {"price": "0.99", "size": "6538"}, {"price": "0.98", "size": "2600"}, {"price": "0.979", "size": "8.81"}, {"price": "0.95", "size": "10"}, {"price": "0.94", "size": "900"}, {"price": "0.939", "size": "8.89"}, {"price": "0.9", "size": "860"}, {"price": "0.85", "size": "226.66"}, {"price": "0.8", "size": "160"}, {"price": "0.799", "size": "5.84"}, {"price": "0.777", "size": "55"}, {"price": "0.75", "size": "112"}, {"price": "0.749", "size": "7"}, {"price": "0.7", "size": "86.66"}, {"price": "0.65", "size": "68.57"}, {"price": "0.6", "size": "50"}, {"price": "0.477", "size": "135"}, {"price": "0.277", "size": "106"}, {"price": "0.177", "size": "107"}, {"price": "0.08", "size": "500"}, {"price": "0.077", "size": "711"}, {"price": "0.069", "size": "800"}, {"price": "0.06", "size": "30"}, {"price": "0.059", "size": "20"}, {"price": "0.024", "size": "1000"}, {"price": "0.018", "size": "1089.64"}, {"price": "0.017", "size": "100"}, {"price": "0.01", "size": "70"}, {"price": "0.009", "size": "20"}, {"price": "0.003", "size": "475"}, {"price": "0.002", "size": "32542.79"}, {"price": "0.001", "size": "231269.78"}], "event_type": "book", "last_trade_price": ""}, {"market": "0x3b1a3232b14a029f96a3e1b04a5d8dde31575d74024389b53631e73b4a494480", "asset_id": "100873440839630488787675306991927169852104936846951905917156069066481005498699", "timestamp": "1769383973603", "hash": "627573ef61a618c12f18114ad2e12cb6c444f98a", "bids": [], "asks": [{"price": "0.999", "size": "3434.06"}, {"price": "0.998", "size": "1250"}, {"price": "0.997", "size": "1406.62"}, {"price": "0.994", "size": "200"}, {"price": "0.993", "size": "9.76"}, {"price": "0.99", "size": "6523"}, {"price": "0.98", "size": "2600"}, {"price": "0.979", "size": "8.81"}, {"price": "0.95", "size": "10"}, {"price": "0.94", "size": "900"}, {"price": "0.939", "size": "8.89"}, {"price": "0.9", "size": "860"}, {"price": "0.85", "size": "226.66"}, {"price": "0.8", "size": "160"}, {"price": "0.799", "size": "5.84"}, {"price": "0.777", "size": "116"}, {"price": "0.75", "size": "112"}, {"price": "0.749", "size": "7"}, {"price": "0.7", "size": "86.66"}, {"price": "0.65", "size": "68.57"}, {"price": "0.6", "size": "50"}, {"price": "0.477", "size": "136"}, {"price": "0.277", "size": "163"}, {"price": "0.251", "size": "49.54"}, {"price": "0.201", "size": "500"}, {"price": "0.177", "size": "169"}, {"price": "0.077", "size": "1084"}, {"price": "0.076", "size": "30"}, {"price": "0.041", "size": "604.3"}, {"price": "0.039", "size": "800"}, {"price": "0.037", "size": "20"}, {"price": "0.022", "size": "440.47"}, {"price": "0.021", "size": "400"}, {"price": "0.01", "size": "2410"}, {"price": "0.009", "size": "1588.61"}, {"price": "0.003", "size": "50"}, {"price": "0.002", "size": "6638.79"}, {"price": "0.001", "size": "260987.53"}], "event_type": "book", "last_trade_price": "0.001"}, {"market": "0xdcf89266de269fa8d785c5a6218c482f08cf26f9987d879fc97d6a335238a08c", "asset_id": "18180536855858852221205988991865712966455254452005023897135830094334125653819", "timestamp": "1769383973583", "hash": "e6f9f6cc8e3cacd6f8222445452e6cfb01187fe5", "bids": [{"price": "0.001", "size": "107934.06"}, {"price": "0.002", "size": "1250"}, {"price": "0.003", "size": "1406.62"}, {"price": "0.006", "size": "200"}, {"price": "0.007", "size": "9.76"}, {"price": "0.01", "size": "2023"}, {"price": "0.02", "size": "2600"}, {"price": "0.021", "size": "9.65"}, {"price": "0.05", "size": "10"}, {"price": "0.064", "size": "1249.74"}, {"price": "0.065", "size": "8.07"}, {"price": "0.1", "size": "860"}, {"price": "0.15", "size": "226.66"}, {"price": "0.2", "size": "160"}, {"price": "0.201", "size": "5.84"}, {"price": "0.223", "size": "143"}, {"price": "0.25", "size": "112"}, {"price": "0.251", "size": "7"}, {"price": "0.3", "size": "86.66"}, {"price": "0.35", "size": "68.57"}, {"price": "0.4", "size": "50"}, {"price": "0.523", "size": "136"}, {"price": "0.799", "size": "500"}, {"price": "0.862", "size": "155.43"}, {"price": "0.883", "size": "1808.27"}, {"price": "0.923", "size": "486"}, {"price": "0.936", "size": "800"}, {"price": "0.938", "size": "30"}, {"price": "0.962", "size": "400"}, {"price": "0.963", "size": "20"}, {"price": "0.985", "size": "116.57"}, {"price": "0.986", "size": "166.66"}, {"price": "0.987", "size": "13"}, {"price": "0.988", "size": "20"}, {"price": "0.997", "size": "243.5"}, {"price": "0.998", "size": "15089.21"}, {"price": "0.999", "size": "262654.81"}], "asks": [], "event_type": "book", "last_trade_price": ""}, {"market": "0xbc4e7ff877a14d8e0dd44bdc0f95ca7a1cf0956fdcfeaf57828a9a9761f95f91", "asset_id": "19717593141255928822027964107994384903066880005154746512521685165896849884582", "timestamp": "1769383973647", "hash": "f388198873157dc04afd1990e270f8703e4141b0", "bids": [{"price": "0.001", "size": "107934.12"}, {"price": "0.002", "size": "1250"}, {"price": "0.003", "size": "1406.66"}, {"price": "0.006", "size": "200"}, {"price": "0.007", "size": "9.82"}, {"price": "0.01", "size": "2023"}, {"price": "0.02", "size": "2600"}, {"price": "0.021", "size": "8.81"}, {"price": "0.05", "size": "10"}, {"price": "0.06", "size": "900"}, {"price": "0.061", "size": "8.89"}, {"price": "0.1", "size": "860"}, {"price": "0.15", "size": "226.66"}, {"price": "0.2", "size": "160"}, {"price": "0.201", "size": "5.84"}, {"price": "0.223", "size": "116"}, {"price": "0.25", "size": "112"}, {"price": "0.27", "size": "2346.66"}, {"price": "0.271", "size": "7"}, {"price": "0.3", "size": "86.66"}, {"price": "0.35", "size": "68.57"}, {"price": "0.4", "size": "50"}, {"price": "0.523", "size": "136"}, {"price": "0.723", "size": "163"}, {"price": "0.799", "size": "500"}, {"price": "0.823", "size": "169"}, {"price": "0.923", "size": "1084"}, {"price": "0.933", "size": "30"}, {"price": "0.934", "size": "20"}, {"price": "0.99", "size": "200"}, {"price": "0.991", "size": "20"}, {"price": "0.992", "size": "100"}, {"price": "0.998", "size": "2705.29"}, {"price": "0.999", "size": "275153.52"}], "asks": [], "event_type": "book", "last_trade_price": ""}, {"market": "0x1a550f4be5469a1f7f19a6a87eb1d3c5aee638dd4b325cd7e80c94fcb69a4325", "asset_id": "15849160483277897689949967085542532873284061361999325893867258022262592692821", "timestamp": "1769383973692", "hash": "c524ca0bd63edb8b0e8c126343b797ebb38de1b6", "bids": [], "asks": [{"price": "0.999", "size": "107929.06"}, {"price": "0.998", "size": "12.44"}, {"price": "0.997", "size": "1400"}, {"price": "0.994", "size": "200"}, {"price": "0.993", "size": "9.76"}, {"price": "0.99", "size": "2023"}, {"price": "0.98", "size": "2600"}, {"price": "0.979", "size": "8.81"}, {"price": "0.95", "size": "10"}, {"price": "0.94", "size": "900"}, {"price": "0.939", "size": "8.89"}, {"price": "0.9", "size": "860"}, {"price": "0.85", "size": "226.66"}, {"price": "0.8", "size": "160"}, {"price": "0.799", "size": "5.84"}, {"price": "0.777", "size": "143"}, {"price": "0.75", "size": "112"}, {"price": "0.7", "size": "86.66"}, {"price": "0.66", "size": "740.77"}, {"price": "0.65", "size": "68.57"}, {"price": "0.649", "size": "5"}, {"price": "0.6", "size": "50"}, {"price": "0.477", "size": "136"}, {"price": "0.201", "size": "500"}, {"price": "0.077", "size": "486"}, {"price": "0.07", "size": "800"}, {"price": "0.061", "size": "13.33"}, {"price": "0.06", "size": "20"}, {"price": "0.059", "size": "30"}, {"price": "0.058", "size": "20"}, {"price": "0.009", "size": "550"}, {"price": "0.008", "size": "746.12"}, {"price": "0.002", "size": "2981.48"}, {"price": "0.001", "size": "260426.46"}], "event_type": "book", "last_trade_price": ""}, {"market": "0xe90b27f08082e17740308fdc957528d29a3f334a9ecaeefd056a3427a4cfdaaf", "asset_id": "75451051172834512494550300103180129346805464117756687477432133503213607327848", "timestamp": "1769383973720", "hash": "b3481728019ef67a3cfd313a77fa5f720c61ea97", "bids": [{"price": "0.001", "size": "3965.21"}, {"price": "0.002", "size": "1250"}, {"price": "0.003", "size": "1406.62"}, {"price": "0.004", "size": "50"}, {"price": "0.006", "size": "200"}, {"price": "0.007", "size": "9.76"}, {"price": "0.01", "size": "6523"}, {"price": "0.011", "size": "30.14"}, {"price": "0.02", "size": "1000"}, {"price": "0.021", "size": "8.81"}, {"price": "0.033", "size": "1600"}, {"price": "0.035", "size": "500"}, {"price": "0.05", "size": "30"}, {"price": "0.06", "size": "900"}, {"price": "0.061", "size": "9.81"}, {"price": "0.1", "size": "860"}, {"price": "0.101", "size": "19"}, {"price": "0.15", "size": "226.66"}, {"price": "0.2", "size": "165"}, {"price": "0.217", "size": "50"}, {"price": "0.218", "size": "5.12"}, {"price": "0.25", "size": "122"}, {"price": "0.3", "size": "86.66"}, {"price": "0.35", "size": "68.57"}, {"price": "0.4", "size": "50"}, {"price": "0.501", "size": "27.22"}, {"price": "0.673", "size": "200"}, {"price": "0.76", "size": "254.63"}, {"price": "0.789", "size": "20"}, {"price": "0.81", "size": "100"}, {"price": "0.857", "size": "4040"}, {"price": "0.888", "size": "222"}, {"price": "0.9", "size": "10"}, {"price": "0.91", "size": "91.5"}, {"price": "0.92", "size": "1000"}, {"price": "0.921", "size": "400"}, {"price": "0.95", "size": "91.5"}, {"price": "0.952", "size": "30"}, {"price": "0.966", "size": "5555"}, {"price": "0.967", "size": "20"}, {"price": "0.973", "size": "39.21"}, {"price": "0.974", "size": "100"}, {"price": "0.985", "size": "750"}, {"price": "0.989", "size": "500"}, {"price": "0.99", "size": "6127.05"}, {"price": "0.992", "size": "2722"}, {"price": "0.993", "size": "999.75"}, {"price": "0.995", "size": "500"}, {"price": "0.997", "size": "1965.16"}, {"price": "0.998", "size": "83250.72"}, {"price": "0.999", "size": "16022.6"}], "asks": [], "event_type": "book", "last_trade_price": "0.001"}, {"market": "0xa619cefee23be0abf807ea451642fe20c497ecb2fd705ee645c3d96d8d11637c", "asset_id": "52939958389447769550840103890909561906591440097333980523939193138105176513035", "timestamp": "1769383973664", "hash": "4cf9d4a2fcda68ce051720b318b00c8e2b6fdb56", "bids": [{"price": "0.001", "size": "107934.06"}, {"price": "0.002", "size": "1250"}, {"price": "0.003", "size": "1406.62"}, {"price": "0.004", "size": "4586.03"}, {"price": "0.006", "size": "200"}, {"price": "0.007", "size": "9.76"}, {"price": "0.01", "size": "1023"}, {"price": "0.02", "size": "3600"}, {"price": "0.021", "size": "8.81"}, {"price": "0.05", "size": "10"}, {"price": "0.06", "size": "900"}, {"price": "0.061", "size": "8.89"}, {"price": "0.1", "size": "860"}, {"price": "0.15", "size": "226.66"}, {"price": "0.2", "size": "160"}, {"price": "0.201", "size": "5.84"}, {"price": "0.223", "size": "143"}, {"price": "0.25", "size": "112"}, {"price": "0.251", "size": "7"}, {"price": "0.3", "size": "86.66"}, {"price": "0.35", "size": "68.57"}, {"price": "0.4", "size": "50"}, {"price": "0.523", "size": "136"}, {"price": "0.799", "size": "500"}, {"price": "0.923", "size": "486"}, {"price": "0.936", "size": "400"}, {"price": "0.937", "size": "30"}, {"price": "0.938", "size": "20"}, {"price": "0.984", "size": "660.21"}, {"price": "0.989", "size": "66.66"}, {"price": "0.991", "size": "120"}, {"price": "0.997", "size": "5974.71"}, {"price": "0.998", "size": "1704.63"}, {"price": "0.999", "size": "290815.75"}], "asks": [], "event_type": "book", "last_trade_price": ""}, {"market": "0x2bd06b3fd416fa6bbb9cf2667ff62977754e49b6d7966077173d266a71a2f240", "asset_id": "593987206111805798800422884241046902068075988081321399989957365154863560039", "timestamp": "1769383973682", "hash": "78b73cca4eaad2742ad1f0da23926c94503fd1d1", "bids": [{"price": "0.001", "size": "107929.06"}, {"price": "0.002", "size": "12.44"}, {"price": "0.003", "size": "1400"}, {"price": "0.006", "size": "200"}, {"price": "0.007", "size": "9.76"}, {"price": "0.01", "size": "2023"}, {"price": "0.02", "size": "3600"}, {"price": "0.021", "size": "8.81"}, {"price": "0.05", "size": "10"}, {"price": "0.06", "size": "900"}, {"price": "0.061", "size": "8.89"}, {"price": "0.1", "size": "860"}, {"price": "0.15", "size": "226.66"}, {"price": "0.151", "size": "13"}, {"price": "0.2", "size": "160"}, {"price": "0.201", "size": "5.84"}, {"price": "0.223", "size": "46"}, {"price": "0.25", "size": "112"}, {"price": "0.3", "size": "86.66"}, {"price": "0.35", "size": "68.57"}, {"price": "0.4", "size": "50"}, {"price": "0.523", "size": "131"}, {"price": "0.723", "size": "72"}, {"price": "0.799", "size": "500"}, {"price": "0.867", "size": "1498.58"}, {"price": "0.923", "size": "486"}, {"price": "0.954", "size": "1153.93"}, {"price": "0.961", "size": "800"}, {"price": "0.963", "size": "400"}, {"price": "0.964", "size": "20"}, {"price": "0.99", "size": "1010"}, {"price": "0.991", "size": "120"}, {"price": "0.997", "size": "62.49"}, {"price": "0.998", "size": "4955.1"}, {"price": "0.999", "size": "271125.65"}], "asks": [], "event_type": "book", "last_trade_price": ""}, {"market": "0x2b1e18ef56cb7222ce2fb03d6cd9fb8fcca06d80b64d0dacbe6ce2f00ab31d00", "asset_id": "107252287464378185480339300277791815889919330201891674919771186169934663184025", "timestamp": "1769383973611", "hash": "82167a683d79b81c191b0a4c27b41e5ae05d6955", "bids": [], "asks": [{"price": "0.999", "size": "3839.08"}, {"price": "0.998", "size": "1250"}, {"price": "0.997", "size": "1000"}, {"price": "0.996", "size": "20.81"}, {"price": "0.99", "size": "6533"}, {"price": "0.98", "size": "2600"}, {"price": "0.979", "size": "8.81"}, {"price": "0.95", "size": "30"}, {"price": "0.949", "size": "39"}, {"price": "0.94", "size": "900"}, {"price": "0.939", "size": "9.44"}, {"price": "0.9", "size": "860"}, {"price": "0.899", "size": "19"}, {"price": "0.85", "size": "226.66"}, {"price": "0.8", "size": "160"}, {"price": "0.79", "size": "200"}, {"price": "0.789", "size": "5.4"}, {"price": "0.75", "size": "112"}, {"price": "0.7", "size": "96.66"}, {"price": "0.67", "size": "100"}, {"price": "0.65", "size": "68.57"}, {"price": "0.6", "size": "56.66"}, {"price": "0.53", "size": "50"}, {"price": "0.5", "size": "799"}, {"price": "0.36", "size": "1112.15"}, {"price": "0.25", "size": "10"}, {"price": "0.22", "size": "40.71"}, {"price": "0.21", "size": "583.33"}, {"price": "0.2", "size": "10"}, {"price": "0.15", "size": "60"}, {"price": "0.14", "size": "30"}, {"price": "0.12", "size": "661"}, {"price": "0.1", "size": "562.5"}, {"price": "0.08", "size": "65"}, {"price": "0.07", "size": "195"}, {"price": "0.065", "size": "100"}, {"price": "0.06", "size": "145"}, {"price": "0.055", "size": "100"}, {"price": "0.05", "size": "662.5"}, {"price": "0.049", "size": "30"}, {"price": "0.045", "size": "100"}, {"price": "0.04", "size": "100"}, {"price": "0.038", "size": "987.1"}, {"price": "0.035", "size": "100"}, {"price": "0.031", "size": "600"}, {"price": "0.03", "size": "20"}, {"price": "0.024", "size": "800"}, {"price": "0.02", "size": "1610.5"}, {"price": "0.013", "size": "151.07"}, {"price": "0.01", "size": "16368"}, {"price": "0.009", "size": "100"}, {"price": "0.005", "size": "750"}, {"price": "0.003", "size": "3408.42"}, {"price": "0.002", "size": "2580.3"}, {"price": "0.001", "size": "33232.06"}], "event_type": "book", "last_trade_price": "0.001"}, {"market": "0x2bd06b3fd416fa6bbb9cf2667ff62977754e49b6d7966077173d266a71a2f240", "asset_id": "36939152546450760203623734882262020084965306583669559634703365151985518078748", "timestamp": "1769383973682", "hash": "1d9be0c1d15eb85649d3f11bc60ca0cd945a9fa7", "bids": [], "asks": [{"price": "0.999", "size": "107929.06"}, {"price": "0.998", "size": "12.44"}, {"price": "0.997", "size": "1400"}, {"price": "0.994", "size": "200"}, {"price": "0.993", "size": "9.76"}, {"price": "0.99", "size": "2023"}, {"price": "0.98", "size": "3600"}, {"price": "0.979", "size": "8.81"}, {"price": "0.95", "size": "10"}, {"price": "0.94", "size": "900"}, {"price": "0.939", "size": "8.89"}, {"price": "0.9", "size": "860"}, {"price": "0.85", "size": "226.66"}, {"price": "0.849", "size": "13"}, {"price": "0.8", "size": "160"}, {"price": "0.799", "size": "5.84"}, {"price": "0.777", "size": "46"}, {"price": "0.75", "size": "112"}, {"price": "0.7", "size": "86.66"}, {"price": "0.65", "size": "68.57"}, {"price": "0.6", "size": "50"}, {"price": "0.477", "size": "131"}, {"price": "0.277", "size": "72"}, {"price": "0.201", "size": "500"}, {"price": "0.133", "size": "1498.58"}, {"price": "0.077", "size": "486"}, {"price": "0.046", "size": "1153.93"}, {"price": "0.039", "size": "800"}, {"price": "0.037", "size": "400"}, {"price": "0.036", "size": "20"}, {"price": "0.01", "size": "1010"}, {"price": "0.009", "size": "120"}, {"price": "0.003", "size": "62.49"}, {"price": "0.002", "size": "4955.1"}, {"price": "0.001", "size": "271125.65"}], "event_type": "book", "last_trade_price": ""}, {"market": "0xbcb33ad98c8141b10f2350ef687eddf0660484ecc15be42ecdae64339e64dce1", "asset_id": "105108334823274411453837752322302146951506166827237470954759784982159162094956", "timestamp": "1769383993814", "hash": "946423945498c4c44abefbeb9a11e443165a6d90", "bids": [{"price": "0.001", "size": "4274.45"}, {"price": "0.002", "size": "1255.04"}, {"price": "0.003", "size": "1400"}, {"price": "0.004", "size": "5.01"}, {"price": "0.006", "size": "200"}, {"price": "0.007", "size": "100"}, {"price": "0.008", "size": "8"}, {"price": "0.01", "size": "6723.17"}, {"price": "0.02", "size": "2600"}, {"price": "0.021", "size": "8.89"}, {"price": "0.05", "size": "30"}, {"price": "0.051", "size": "39"}, {"price": "0.06", "size": "900"}, {"price": "0.061", "size": "8.94"}, {"price": "0.099", "size": "499.71"}, {"price": "0.1", "size": "360"}, {"price": "0.12", "size": "892.97"}, {"price": "0.15", "size": "226.66"}, {"price": "0.2", "size": "160"}, {"price": "0.201", "size": "5.81"}, {"price": "0.25", "size": "112"}, {"price": "0.3", "size": "1694.71"}, {"price": "0.34", "size": "56236.54"}, {"price": "0.35", "size": "564.32"}, {"price": "0.39", "size": "51.28"}, {"price": "0.4", "size": "1674.11"}, {"price": "0.43", "size": "352.43"}, {"price": "0.47", "size": "469.9"}, {"price": "0.5", "size": "223.32"}, {"price": "0.501", "size": "500"}, {"price": "0.53", "size": "626.54"}, {"price": "0.55", "size": "2779.4"}, {"price": "0.575", "size": "212"}, {"price": "0.6", "size": "134429.46"}, {"price": "0.601", "size": "52600"}, {"price": "0.65", "size": "433.01"}, {"price": "0.665", "size": "40000"}, {"price": "0.7", "size": "656.66"}, {"price": "0.71", "size": "109.09"}, {"price": "0.75", "size": "22406.77"}, {"price": "0.755", "size": "500"}, {"price": "0.76", "size": "10000"}, {"price": "0.77", "size": "2468.88"}, {"price": "0.775", "size": "125"}, {"price": "0.78", "size": "80"}, {"price": "0.791", "size": "10000"}, {"price": "0.795", "size": "19.56"}, {"price": "0.798", "size": "504.95"}, {"price": "0.8", "size": "2240.18"}, {"price": "0.801", "size": "10000"}, {"price": "0.802", "size": "10570"}, {"price": "0.804", "size": "5"}, {"price": "0.805", "size": "175"}, {"price": "0.808", "size": "259"}, {"price": "0.81", "size": "545.91"}, {"price": "0.811", "size": "11500"}, {"price": "0.82", "size": "10047.53"}, {"price": "0.821", "size": "10000"}, {"price": "0.825", "size": "200"}, {"price": "0.83", "size": "2075.36"}, {"price": "0.831", "size": "10000"}, {"price": "0.836", "size": "113.22"}, {"price": "0.838", "size": "500"}, {"price": "0.84", "size": "266.23"}, {"price": "0.841", "size": "10000"}, {"price": "0.845", "size": "250"}, {"price": "0.85", "size": "712.05"}, {"price": "0.851", "size": "10700"}, {"price": "0.854", "size": "32"}, {"price": "0.855", "size": "5432"}, {"price": "0.856", "size": "6161.39"}, {"price": "0.86", "size": "516.41"}, {"price": "0.861", "size": "10000"}, {"price": "0.862", "size": "800"}, {"price": "0.87", "size": "2200.28"}, {"price": "0.871", "size": "10000"}, {"price": "0.874", "size": "1486"}, {"price": "0.875", "size": "1481"}, {"price": "0.876", "size": "1486"}, {"price": "0.877", "size": "1481"}, {"price": "0.878", "size": "8.14"}, {"price": "0.879", "size": "1481"}, {"price": "0.88", "size": "2408.04"}, {"price": "0.881", "size": "12481"}, {"price": "0.882", "size": "1481"}, {"price": "0.883", "size": "1481"}, {"price": "0.884", "size": "1481"}, {"price": "0.885", "size": "1781"}, {"price": "0.886", "size": "1481"}, {"price": "0.887", "size": "1481"}, {"price": "0.888", "size": "1481"}, {"price": "0.889", "size": "1481"}, {"price": "0.89", "size": "8044.36"}, {"price": "0.891", "size": "1481"}, {"price": "0.892", "size": "1481"}, {"price": "0.893", "size": "1481"}, {"price": "0.894", "size": "1481"}, {"price": "0.895", "size": "1481"}, {"price": "0.896", "size": "1481"}, {"price": "0.897", "size": "1481"}, {"price": "0.898", "size": "1481"}, {"price": "0.899", "size": "1481"}, {"price": "0.9", "size": "18258.01"}, {"price": "0.901", "size": "40470"}, {"price": "0.902", "size": "666"}, {"price": "0.905", "size": "10"}, {"price": "0.91", "size": "15"}, {"price": "0.913", "size": "492"}, {"price": "0.914", "size": "400"}, {"price": "0.919", "size": "200"}, {"price": "0.92", "size": "16155.32"}, {"price": "0.922", "size": "500"}, {"price": "0.925", "size": "150"}, {"price": "0.926", "size": "30"}, {"price": "0.927", "size": "20"}, {"price": "0.93", "size": "6510.13"}, {"price": "0.933", "size": "20085.94"}, {"price": "0.934", "size": "3534.15"}, {"price": "0.935", "size": "23.93"}, {"price": "0.937", "size": "1500"}, {"price": "0.94", "size": "3381.51"}, {"price": "0.942", "size": "666"}, {"price": "0.943", "size": "19476.06"}, {"price": "0.944", "size": "19542.74"}, {"price": "0.945", "size": "7159.98"}, {"price": "0.946", "size": "100"}, {"price": "0.947", "size": "22272"}, {"price": "0.948", "size": "3137.19"}, {"price": "0.949", "size": "5158.15"}, {"price": "0.95", "size": "22277.05"}, {"price": "0.951", "size": "17049.99"}, {"price": "0.952", "size": "10300"}, {"price": "0.953", "size": "29172.81"}, {"price": "0.954", "size": "11900.85"}, {"price": "0.955", "size": "21911"}, {"price": "0.956", "size": "12278.25"}, {"price": "0.957", "size": "16110.34"}, {"price": "0.958", "size": "19703"}, {"price": "0.959", "size": "10037.5"}, {"price": "0.96", "size": "25459.97"}, {"price": "0.961", "size": "10000"}, {"price": "0.962", "size": "23400.84"}, {"price": "0.963", "size": "23900"}, {"price": "0.964", "size": "10400"}, {"price": "0.965", "size": "26991.33"}, {"price": "0.966", "size": "35368.86"}, {"price": "0.967", "size": "14340.58"}, {"price": "0.968", "size": "10000"}, {"price": "0.969", "size": "3683.07"}, {"price": "0.97", "size": "2484"}, {"price": "0.971", "size": "12000"}, {"price": "0.972", "size": "5342"}, {"price": "0.975", "size": "3222"}, {"price": "0.976", "size": "2869.16"}, {"price": "0.977", "size": "2732.66"}, {"price": "0.978", "size": "3448.43"}, {"price": "0.979", "size": "3001.81"}, {"price": "0.98", "size": "202.27"}], "asks": [{"price": "0.999", "size": "49302.12"}, {"price": "0.998", "size": "5612.05"}, {"price": "0.997", "size": "10264.74"}, {"price": "0.995", "size": "2659.64"}, {"price": "0.994", "size": "3597.57"}, {"price": "0.993", "size": "2212.14"}, {"price": "0.992", "size": "770.51"}, {"price": "0.991", "size": "2897.03"}, {"price": "0.99", "size": "3033.16"}, {"price": "0.989", "size": "10"}, {"price": "0.988", "size": "1008.34"}, {"price": "0.987", "size": "6215.38"}, {"price": "0.986", "size": "2800"}, {"price": "0.985", "size": "14523.33"}, {"price": "0.984", "size": "30318.17"}, {"price": "0.983", "size": "4004.48"}, {"price": "0.982", "size": "3748.98"}, {"price": "0.981", "size": "328.79"}], "event_type": "book", "last_trade_price": "0.980"}, {"market": "0xbcb33ad98c8141b10f2350ef687eddf0660484ecc15be42ecdae64339e64dce1", "asset_id": "87048058140607839077917415447158941112086606824479198286281986963033007181784", "timestamp": "1769383993814", "hash": "5d9e8e15384081ff544454da2f848bcb5c02c276", "bids": [{"price": "0.001", "size": "49302.12"}, {"price": "0.002", "size": "5612.05"}, {"price": "0.003", "size": "10264.74"}, {"price": "0.005", "size": "2659.64"}, {"price": "0.006", "size": "3597.57"}, {"price": "0.007", "size": "2212.14"}, {"price": "0.008", "size": "770.51"}, {"price": "0.009", "size": "2897.03"}, {"price": "0.01", "size": "3033.16"}, {"price": "0.011", "size": "10"}, {"price": "0.012", "size": "1008.34"}, {"price": "0.013", "size": "6215.38"}, {"price": "0.014", "size": "2800"}, {"price": "0.015", "size": "14523.33"}, {"price": "0.016", "size": "30318.17"}, {"price": "0.017", "size": "4004.48"}, {"price": "0.018", "size": "3748.98"}, {"price": "0.019", "size": "328.79"}], "asks": [{"price": "0.999", "size": "4274.45"}, {"price": "0.998", "size": "1255.04"}, {"price": "0.997", "size": "1400"}, {"price": "0.996", "size": "5.01"}, {"price": "0.994", "size": "200"}, {"price": "0.993", "size": "100"}, {"price": "0.992", "size": "8"}, {"price": "0.99", "size": "6723.17"}, {"price": "0.98", "size": "2600"}, {"price": "0.979", "size": "8.89"}, {"price": "0.95", "size": "30"}, {"price": "0.949", "size": "39"}, {"price": "0.94", "size": "900"}, {"price": "0.939", "size": "8.94"}, {"price": "0.901", "size": "499.71"}, {"price": "0.9", "size": "360"}, {"price": "0.88", "size": "892.97"}, {"price": "0.85", "size": "226.66"}, {"price": "0.8", "size": "160"}, {"price": "0.799", "size": "5.81"}, {"price": "0.75", "size": "112"}, {"price": "0.7", "size": "1694.71"}, {"price": "0.66", "size": "56236.54"}, {"price": "0.65", "size": "564.32"}, {"price": "0.61", "size": "51.28"}, {"price": "0.6", "size": "1674.11"}, {"price": "0.57", "size": "352.43"}, {"price": "0.53", "size": "469.9"}, {"price": "0.5", "size": "223.32"}, {"price": "0.499", "size": "500"}, {"price": "0.47", "size": "626.54"}, {"price": "0.45", "size": "2779.4"}, {"price": "0.425", "size": "212"}, {"price": "0.4", "size": "134429.46"}, {"price": "0.399", "size": "52600"}, {"price": "0.35", "size": "433.01"}, {"price": "0.335", "size": "40000"}, {"price": "0.3", "size": "656.66"}, {"price": "0.29", "size": "109.09"}, {"price": "0.25", "size": "22406.77"}, {"price": "0.245", "size": "500"}, {"price": "0.24", "size": "10000"}, {"price": "0.23", "size": "2468.88"}, {"price": "0.225", "size": "125"}, {"price": "0.22", "size": "80"}, {"price": "0.209", "size": "10000"}, {"price": "0.205", "size": "19.56"}, {"price": "0.202", "size": "504.95"}, {"price": "0.2", "size": "2240.18"}, {"price": "0.199", "size": "10000"}, {"price": "0.198", "size": "10570"}, {"price": "0.196", "size": "5"}, {"price": "0.195", "size": "175"}, {"price": "0.192", "size": "259"}, {"price": "0.19", "size": "545.91"}, {"price": "0.189", "size": "11500"}, {"price": "0.18", "size": "10047.53"}, {"price": "0.179", "size": "10000"}, {"price": "0.175", "size": "200"}, {"price": "0.17", "size": "2075.36"}, {"price": "0.169", "size": "10000"}, {"price": "0.164", "size": "113.22"}, {"price": "0.162", "size": "500"}, {"price": "0.16", "size": "266.23"}, {"price": "0.159", "size": "10000"}, {"price": "0.155", "size": "250"}, {"price": "0.15", "size": "712.05"}, {"price": "0.149", "size": "10700"}, {"price": "0.146", "size": "32"}, {"price": "0.145", "size": "5432"}, {"price": "0.144", "size": "6161.39"}, {"price": "0.14", "size": "516.41"}, {"price": "0.139", "size": "10000"}, {"price": "0.138", "size": "800"}, {"price": "0.13", "size": "2200.28"}, {"price": "0.129", "size": "10000"}, {"price": "0.126", "size": "1486"}, {"price": "0.125", "size": "1481"}, {"price": "0.124", "size": "1486"}, {"price": "0.123", "size": "1481"}, {"price": "0.122", "size": "8.14"}, {"price": "0.121", "size": "1481"}, {"price": "0.12", "size": "2408.04"}, {"price": "0.119", "size": "12481"}, {"price": "0.118", "size": "1481"}, {"price": "0.117", "size": "1481"}, {"price": "0.116", "size": "1481"}, {"price": "0.115", "size": "1781"}, {"price": "0.114", "size": "1481"}, {"price": "0.113", "size": "1481"}, {"price": "0.112", "size": "1481"}, {"price": "0.111", "size": "1481"}, {"price": "0.11", "size": "8044.36"}, {"price": "0.109", "size": "1481"}, {"price": "0.108", "size": "1481"}, {"price": "0.107", "size": "1481"}, {"price": "0.106", "size": "1481"}, {"price": "0.105", "size": "1481"}, {"price": "0.104", "size": "1481"}, {"price": "0.103", "size": "1481"}, {"price": "0.102", "size": "1481"}, {"price": "0.101", "size": "1481"}, {"price": "0.1", "size": "18258.01"}, {"price": "0.099", "size": "40470"}, {"price": "0.098", "size": "666"}, {"price": "0.095", "size": "10"}, {"price": "0.09", "size": "15"}, {"price": "0.087", "size": "492"}, {"price": "0.086", "size": "400"}, {"price": "0.081", "size": "200"}, {"price": "0.08", "size": "16155.32"}, {"price": "0.078", "size": "500"}, {"price": "0.075", "size": "150"}, {"price": "0.074", "size": "30"}, {"price": "0.073", "size": "20"}, {"price": "0.07", "size": "6510.13"}, {"price": "0.067", "size": "20085.94"}, {"price": "0.066", "size": "3534.15"}, {"price": "0.065", "size": "23.93"}, {"price": "0.063", "size": "1500"}, {"price": "0.06", "size": "3381.51"}, {"price": "0.058", "size": "666"}, {"price": "0.057", "size": "19476.06"}, {"price": "0.056", "size": "19542.74"}, {"price": "0.055", "size": "7159.98"}, {"price": "0.054", "size": "100"}, {"price": "0.053", "size": "22272"}, {"price": "0.052", "size": "3137.19"}, {"price": "0.051", "size": "5158.15"}, {"price": "0.05", "size": "22277.05"}, {"price": "0.049", "size": "17049.99"}, {"price": "0.048", "size": "10300"}, {"price": "0.047", "size": "29172.81"}, {"price": "0.046", "size": "11900.85"}, {"price": "0.045", "size": "21911"}, {"price": "0.044", "size": "12278.25"}, {"price": "0.043", "size": "16110.34"}, {"price": "0.042", "size": "19703"}, {"price": "0.041", "size": "10037.5"}, {"price": "0.04", "size": "25459.97"}, {"price": "0.039", "size": "10000"}, {"price": "0.038", "size": "23400.84"}, {"price": "0.037", "size": "23900"}, {"price": "0.036", "size": "10400"}, {"price": "0.035", "size": "26991.33"}, {"price": "0.034", "size": "35368.86"}, {"price": "0.033", "size": "14340.58"}, {"price": "0.032", "size": "10000"}, {"price": "0.031", "size": "3683.07"}, {"price": "0.03", "size": "2484"}, {"price": "0.029", "size": "12000"}, {"price": "0.028", "size": "5342"}, {"price": "0.025", "size": "3222"}, {"price": "0.024", "size": "2869.16"}, {"price": "0.023", "size": "2732.66"}, {"price": "0.022", "size": "3448.43"}, {"price": "0.021", "size": "3001.81"}, {"price": "0.02", "size": "202.27"}], "event_type": "book", "last_trade_price": "0.980"}, {"market": "0xbc4e5a49c32f7d9cc55654ddfbcf8f75706edc07a11ae327730bb877750bbeaa", "asset_id": "53243047997408072043597262379510386757989173994530982334166850503991368110377", "timestamp": "1769383997542", "hash": "af9c1a42418d32d49d37115d233af4a16dda1d01", "bids": [], "asks": [{"price": "0.999", "size": "3778.06"}, {"price": "0.998", "size": "1250"}, {"price": "0.997", "size": "1406.62"}, {"price": "0.994", "size": "200"}, {"price": "0.993", "size": "9.76"}, {"price": "0.99", "size": "6523"}, {"price": "0.98", "size": "2600"}, {"price": "0.979", "size": "8.81"}, {"price": "0.95", "size": "10"}, {"price": "0.94", "size": "900"}, {"price": "0.939", "size": "8.89"}, {"price": "0.9", "size": "860"}, {"price": "0.85", "size": "226.66"}, {"price": "0.8", "size": "160"}, {"price": "0.799", "size": "5.84"}, {"price": "0.777", "size": "143"}, {"price": "0.75", "size": "112"}, {"price": "0.749", "size": "7"}, {"price": "0.7", "size": "86.66"}, {"price": "0.65", "size": "68.57"}, {"price": "0.6", "size": "50"}, {"price": "0.477", "size": "112"}, {"price": "0.077", "size": "486"}, {"price": "0.055", "size": "30"}, {"price": "0.054", "size": "20"}, {"price": "0.053", "size": "400"}, {"price": "0.018", "size": "200"}, {"price": "0.013", "size": "13.33"}, {"price": "0.012", "size": "100"}, {"price": "0.011", "size": "20"}, {"price": "0.005", "size": "6250"}, {"price": "0.003", "size": "62.49"}, {"price": "0.002", "size": "8283.79"}, {"price": "0.001", "size": "136672.76"}], "event_type": "book", "last_trade_price": "0.001"}, {"market": "0x3b1a3232b14a029f96a3e1b04a5d8dde31575d74024389b53631e73b4a494480", "asset_id": "85845913338874356389169581070714431760388168444378600269400508336199873583319", "timestamp": "1769383973603", "hash": "3b3b7ccc9d7103ac412ef0d440a8ee36f13d1ac2", "bids": [{"price": "0.001", "size": "3434.06"}, {"price": "0.002", "size": "1250"}, {"price": "0.003", "size": "1406.62"}, {"price": "0.006", "size": "200"}, {"price": "0.007", "size": "9.76"}, {"price": "0.01", "size": "6523"}, {"price": "0.02", "size": "2600"}, {"price": "0.021", "size": "8.81"}, {"price": "0.05", "size": "10"}, {"price": "0.06", "size": "900"}, {"price": "0.061", "size": "8.89"}, {"price": "0.1", "size": "860"}, {"price": "0.15", "size": "226.66"}, {"price": "0.2", "size": "160"}, {"price": "0.201", "size": "5.84"}, {"price": "0.223", "size": "116"}, {"price": "0.25", "size": "112"}, {"price": "0.251", "size": "7"}, {"price": "0.3", "size": "86.66"}, {"price": "0.35", "size": "68.57"}, {"price": "0.4", "size": "50"}, {"price": "0.523", "size": "136"}, {"price": "0.723", "size": "163"}, {"price": "0.749", "size": "49.54"}, {"price": "0.799", "size": "500"}, {"price": "0.823", "size": "169"}, {"price": "0.923", "size": "1084"}, {"price": "0.924", "size": "30"}, {"price": "0.959", "size": "604.3"}, {"price": "0.961", "size": "800"}, {"price": "0.963", "size": "20"}, {"price": "0.978", "size": "440.47"}, {"price": "0.979", "size": "400"}, {"price": "0.99", "size": "2410"}, {"price": "0.991", "size": "1588.61"}, {"price": "0.997", "size": "50"}, {"price": "0.998", "size": "6638.79"}, {"price": "0.999", "size": "260987.53"}], "asks": [], "event_type": "book", "last_trade_price": "0.001"}, {"market": "0x35fdbb84a6a3c45466deea33ee0f0500e70078351ff8b8fb0576d361bb2eeed1", "asset_id": "74084476985099618644873010373644848339105047027523412961502524755105614279952", "timestamp": "1769383973665", "hash": "ecb8921932d5984572fd306ed7f858acae6d9824", "bids": [], "asks": [{"price": "0.999", "size": "3434.06"}, {"price": "0.998", "size": "3559.81"}, {"price": "0.997", "size": "1406.62"}, {"price": "0.994", "size": "200"}, {"price": "0.993", "size": "9.76"}, {"price": "0.99", "size": "6523"}, {"price": "0.98", "size": "2600"}, {"price": "0.979", "size": "8.81"}, {"price": "0.95", "size": "10"}, {"price": "0.94", "size": "900"}, {"price": "0.939", "size": "8.89"}, {"price": "0.9", "size": "860"}, {"price": "0.85", "size": "226.66"}, {"price": "0.8", "size": "160"}, {"price": "0.799", "size": "5.84"}, {"price": "0.777", "size": "143"}, {"price": "0.75", "size": "112"}, {"price": "0.749", "size": "7"}, {"price": "0.7", "size": "86.66"}, {"price": "0.65", "size": "68.57"}, {"price": "0.6", "size": "50"}, {"price": "0.477", "size": "136"}, {"price": "0.201", "size": "500"}, {"price": "0.112", "size": "1093.97"}, {"price": "0.077", "size": "486"}, {"price": "0.066", "size": "30"}, {"price": "0.065", "size": "20"}, {"price": "0.01", "size": "1010"}, {"price": "0.009", "size": "120"}, {"price": "0.005", "size": "250"}, {"price": "0.004", "size": "250"}, {"price": "0.003", "size": "3090.64"}, {"price": "0.002", "size": "2409.05"}, {"price": "0.001", "size": "253382.64"}], "event_type": "book", "last_trade_price": ""}, {"market": "0xa062dea464f0e8fc3381176494198cf45574ec190eca77a40f49988320fa15f2", "asset_id": "16754375222233973989954094649431109282368408854808102040230156977754673841406", "timestamp": "1769383997327", "hash": "f55b765b4b3e3be197339584b79ce4339649cce1", "bids": [{"price": "0.001", "size": "11982"}, {"price": "0.003", "size": "1000"}, {"price": "0.01", "size": "6538"}, {"price": "0.011", "size": "8.26"}, {"price": "0.02", "size": "1100"}, {"price": "0.022", "size": "101600"}, {"price": "0.03", "size": "53.36"}, {"price": "0.05", "size": "20"}, {"price": "0.051", "size": "39"}, {"price": "0.06", "size": "900"}, {"price": "0.1", "size": "360"}, {"price": "0.101", "size": "8.59"}, {"price": "0.106", "size": "8.59"}, {"price": "0.15", "size": "226.66"}, {"price": "0.185", "size": "735.91"}, {"price": "0.19", "size": "32"}, {"price": "0.2", "size": "190"}, {"price": "0.209", "size": "300"}, {"price": "0.21", "size": "1218.35"}, {"price": "0.25", "size": "112"}, {"price": "0.28", "size": "5"}, {"price": "0.29", "size": "89.65"}, {"price": "0.3", "size": "5"}, {"price": "0.31", "size": "5"}, {"price": "0.33", "size": "19"}, {"price": "0.34", "size": "70.58"}, {"price": "0.36", "size": "30"}, {"price": "0.39", "size": "51.28"}, {"price": "0.445", "size": "12.61"}, {"price": "0.47", "size": "142.31"}, {"price": "0.492", "size": "10"}, {"price": "0.5", "size": "69.03"}, {"price": "0.55", "size": "70"}, {"price": "0.6", "size": "120"}, {"price": "0.65", "size": "247.87"}, {"price": "0.662", "size": "45"}, {"price": "0.669", "size": "37.5"}, {"price": "0.67", "size": "100"}, {"price": "0.679", "size": "200"}, {"price": "0.682", "size": "110"}, {"price": "0.707", "size": "18.75"}, {"price": "0.733", "size": "6.82"}, {"price": "0.745", "size": "6.71"}, {"price": "0.75", "size": "4311.92"}, {"price": "0.753", "size": "100"}, {"price": "0.787", "size": "100"}, {"price": "0.83", "size": "2041.92"}, {"price": "0.85", "size": "4880"}, {"price": "0.891", "size": "1111"}, {"price": "0.9", "size": "356.68"}, {"price": "0.901", "size": "100"}, {"price": "0.902", "size": "200"}, {"price": "0.907", "size": "1000"}, {"price": "0.92", "size": "5000"}, {"price": "0.925", "size": "500"}, {"price": "0.927", "size": "714"}, {"price": "0.928", "size": "400"}, {"price": "0.93", "size": "2222"}, {"price": "0.932", "size": "3222"}, {"price": "0.934", "size": "11000"}, {"price": "0.935", "size": "3381.33"}, {"price": "0.939", "size": "272"}, {"price": "0.94", "size": "2995"}, {"price": "0.941", "size": "20"}, {"price": "0.943", "size": "222"}, {"price": "0.944", "size": "10000"}, {"price": "0.945", "size": "1209.9"}, {"price": "0.946", "size": "100"}, {"price": "0.95", "size": "1748.13"}, {"price": "0.951", "size": "1400"}, {"price": "0.952", "size": "2500"}, {"price": "0.953", "size": "1400"}, {"price": "0.954", "size": "313.58"}, {"price": "0.955", "size": "1000"}, {"price": "0.956", "size": "3433"}, {"price": "0.957", "size": "3333"}, {"price": "0.958", "size": "1600"}, {"price": "0.96", "size": "15040"}, {"price": "0.961", "size": "3938"}, {"price": "0.962", "size": "11883.12"}, {"price": "0.963", "size": "2750"}, {"price": "0.964", "size": "3000"}, {"price": "0.965", "size": "2422"}, {"price": "0.966", "size": "2222"}, {"price": "0.967", "size": "487"}, {"price": "0.968", "size": "3769.05"}, {"price": "0.969", "size": "200"}, {"price": "0.97", "size": "3414.76"}, {"price": "0.971", "size": "2422"}, {"price": "0.972", "size": "6777"}, {"price": "0.973", "size": "2221.23"}, {"price": "0.974", "size": "222"}, {"price": "0.975", "size": "5625"}, {"price": "0.976", "size": "3020.61"}, {"price": "0.977", "size": "200"}, {"price": "0.978", "size": "3399.91"}, {"price": "0.979", "size": "7311.51"}, {"price": "0.98", "size": "1623.34"}], "asks": [{"price": "0.999", "size": "45562.37"}, {"price": "0.998", "size": "15734.94"}, {"price": "0.997", "size": "542.73"}, {"price": "0.996", "size": "61.48"}, {"price": "0.995", "size": "4130.4"}, {"price": "0.994", "size": "221.09"}, {"price": "0.993", "size": "34.86"}, {"price": "0.992", "size": "140"}, {"price": "0.991", "size": "2014.08"}, {"price": "0.99", "size": "588.47"}, {"price": "0.989", "size": "3353.39"}, {"price": "0.988", "size": "1710.42"}, {"price": "0.987", "size": "1009.59"}, {"price": "0.986", "size": "57790.89"}, {"price": "0.985", "size": "2344.34"}, {"price": "0.984", "size": "1469.81"}, {"price": "0.983", "size": "1113.04"}, {"price": "0.982", "size": "26165.98"}, {"price": "0.981", "size": "19690.87"}], "event_type": "book", "last_trade_price": "0.980"}, {"market": "0xc23d4f3a1a96576e93f32ab1806c6d85f5a3d1925df7c80bdb97cfd6787b4dfc", "asset_id": "67331134082972564744861493399409944604495859900890997048640266268482227361024", "timestamp": "1769383973563", "hash": "3e58ad8d46218518abc7136da1690c4d23a88755", "bids": [{"price": "0.001", "size": "107934.06"}, {"price": "0.002", "size": "1250"}, {"price": "0.003", "size": "1406.62"}, {"price": "0.006", "size": "200"}, {"price": "0.007", "size": "9.76"}, {"price": "0.01", "size": "2023"}, {"price": "0.02", "size": "2600"}, {"price": "0.021", "size": "12.96"}, {"price": "0.05", "size": "10"}, {"price": "0.08", "size": "1999.96"}, {"price": "0.081", "size": "5.62"}, {"price": "0.1", "size": "860"}, {"price": "0.15", "size": "226.66"}, {"price": "0.2", "size": "160"}, {"price": "0.201", "size": "5.84"}, {"price": "0.223", "size": "143"}, {"price": "0.25", "size": "112"}, {"price": "0.251", "size": "7"}, {"price": "0.3", "size": "86.66"}, {"price": "0.35", "size": "68.57"}, {"price": "0.4", "size": "50"}, {"price": "0.523", "size": "136"}, {"price": "0.799", "size": "500"}, {"price": "0.923", "size": "486"}, {"price": "0.93", "size": "800"}, {"price": "0.931", "size": "30"}, {"price": "0.956", "size": "20"}, {"price": "0.957", "size": "400"}, {"price": "0.985", "size": "206.61"}, {"price": "0.986", "size": "100"}, {"price": "0.99", "size": "1400"}, {"price": "0.991", "size": "20"}, {"price": "0.996", "size": "1987.53"}, {"price": "0.997", "size": "69.63"}, {"price": "0.998", "size": "10553.4"}, {"price": "0.999", "size": "252902.66"}], "asks": [], "event_type": "book", "last_trade_price": ""}, {"market": "0x1d5827b0448938c4c40a1c6747abc61e4ff690ac3d7306e0690c1741eb6dcb0b", "asset_id": "12066144173721960949299167133110175689689620950083050321772650546514468891687", "timestamp": "1769383973567", "hash": "cfc51e5d1be24178762ff011edd95da525420b9c", "bids": [], "asks": [{"price": "0.999", "size": "107934.06"}, {"price": "0.998", "size": "1250"}, {"price": "0.997", "size": "1406.62"}, {"price": "0.994", "size": "200"}, {"price": "0.993", "size": "9.76"}, {"price": "0.99", "size": "2023"}, {"price": "0.98", "size": "2600"}, {"price": "0.979", "size": "8.81"}, {"price": "0.95", "size": "10"}, {"price": "0.94", "size": "900"}, {"price": "0.939", "size": "8.89"}, {"price": "0.9", "size": "860"}, {"price": "0.85", "size": "226.66"}, {"price": "0.849", "size": "13"}, {"price": "0.8", "size": "160"}, {"price": "0.799", "size": "5.84"}, {"price": "0.777", "size": "116"}, {"price": "0.75", "size": "112"}, {"price": "0.7", "size": "86.66"}, {"price": "0.65", "size": "68.57"}, {"price": "0.6", "size": "50"}, {"price": "0.477", "size": "136"}, {"price": "0.277", "size": "163"}, {"price": "0.177", "size": "169"}, {"price": "0.137", "size": "2749.91"}, {"price": "0.077", "size": "1085"}, {"price": "0.076", "size": "30"}, {"price": "0.038", "size": "400"}, {"price": "0.037", "size": "20"}, {"price": "0.013", "size": "166.66"}, {"price": "0.012", "size": "13"}, {"price": "0.011", "size": "20"}, {"price": "0.003", "size": "362.49"}, {"price": "0.002", "size": "7926.21"}, {"price": "0.001", "size": "267471.44"}], "event_type": "book", "last_trade_price": ""}, {"market": "0xed888eb64bffa457086fb5904e9b2046da9aa31c5db36e9d4a303efa7e850d76", "asset_id": "73052907052175436380025731458637271310287515048140611629593241979776449716131", "timestamp": "1769383973673", "hash": "db3234e5d1b9fb68004539ea6b3e0ca2a307dcdf", "bids": [{"price": "0.001", "size": "2024.14"}, {"price": "0.002", "size": "1250"}, {"price": "0.003", "size": "1000"}, {"price": "0.004", "size": "20.82"}, {"price": "0.01", "size": "11317.9"}, {"price": "0.02", "size": "5831.8"}, {"price": "0.021", "size": "10.91"}, {"price": "0.05", "size": "99.45"}, {"price": "0.051", "size": "39"}, {"price": "0.07", "size": "1400"}, {"price": "0.071", "size": "7.49"}, {"price": "0.09", "size": "35.54"}, {"price": "0.1", "size": "379.04"}, {"price": "0.14", "size": "100"}, {"price": "0.15", "size": "296.66"}, {"price": "0.17", "size": "5"}, {"price": "0.2", "size": "12265"}, {"price": "0.21", "size": "1362.9"}, {"price": "0.211", "size": "5.4"}, {"price": "0.25", "size": "112"}, {"price": "0.28", "size": "8.92"}, {"price": "0.3", "size": "86.66"}, {"price": "0.31", "size": "800"}, {"price": "0.34", "size": "1013.73"}, {"price": "0.35", "size": "1584.47"}, {"price": "0.36", "size": "300"}, {"price": "0.37", "size": "200"}, {"price": "0.38", "size": "27.86"}, {"price": "0.4", "size": "80"}, {"price": "0.41", "size": "18.86"}, {"price": "0.5", "size": "4649.9"}, {"price": "0.501", "size": "5"}, {"price": "0.55", "size": "997.79"}, {"price": "0.56", "size": "55"}, {"price": "0.57", "size": "120"}, {"price": "0.58", "size": "90"}, {"price": "0.59", "size": "195"}, {"price": "0.64", "size": "95"}, {"price": "0.65", "size": "55"}, {"price": "0.66", "size": "183.11"}, {"price": "0.68", "size": "101"}, {"price": "0.7", "size": "2404.99"}, {"price": "0.76", "size": "30"}, {"price": "0.8", "size": "5"}, {"price": "0.801", "size": "100"}, {"price": "0.81", "size": "211"}, {"price": "0.85", "size": "15"}, {"price": "0.9", "size": "5991.25"}, {"price": "0.907", "size": "200"}, {"price": "0.91", "size": "5562"}, {"price": "0.92", "size": "3602"}, {"price": "0.93", "size": "100"}, {"price": "0.94", "size": "100"}, {"price": "0.95", "size": "1812.49"}, {"price": "0.952", "size": "800"}, {"price": "0.953", "size": "30"}, {"price": "0.954", "size": "20"}, {"price": "0.99", "size": "64554.1"}, {"price": "0.991", "size": "20"}, {"price": "0.992", "size": "10100"}, {"price": "0.995", "size": "1999.99"}, {"price": "0.997", "size": "100"}, {"price": "0.998", "size": "663.79"}, {"price": "0.999", "size": "105025.3"}], "asks": [], "event_type": "book", "last_trade_price": "0.001"}, {"market": "0xed888eb64bffa457086fb5904e9b2046da9aa31c5db36e9d4a303efa7e850d76", "asset_id": "4370640939548049160201828166293191503482026064792352053936490018661409706941", "timestamp": "1769383973673", "hash": "e17cf2ed19eb2be6943f45fdc72efbe4da99c94f", "bids": [], "asks": [{"price": "0.999", "size": "2024.14"}, {"price": "0.998", "size": "1250"}, {"price": "0.997", "size": "1000"}, {"price": "0.996", "size": "20.82"}, {"price": "0.99", "size": "11317.9"}, {"price": "0.98", "size": "5831.8"}, {"price": "0.979", "size": "10.91"}, {"price": "0.95", "size": "99.45"}, {"price": "0.949", "size": "39"}, {"price": "0.93", "size": "1400"}, {"price": "0.929", "size": "7.49"}, {"price": "0.91", "size": "35.54"}, {"price": "0.9", "size": "379.04"}, {"price": "0.86", "size": "100"}, {"price": "0.85", "size": "296.66"}, {"price": "0.83", "size": "5"}, {"price": "0.8", "size": "12265"}, {"price": "0.79", "size": "1362.9"}, {"price": "0.789", "size": "5.4"}, {"price": "0.75", "size": "112"}, {"price": "0.72", "size": "8.92"}, {"price": "0.7", "size": "86.66"}, {"price": "0.69", "size": "800"}, {"price": "0.66", "size": "1013.73"}, {"price": "0.65", "size": "1584.47"}, {"price": "0.64", "size": "300"}, {"price": "0.63", "size": "200"}, {"price": "0.62", "size": "27.86"}, {"price": "0.6", "size": "80"}, {"price": "0.59", "size": "18.86"}, {"price": "0.5", "size": "4649.9"}, {"price": "0.499", "size": "5"}, {"price": "0.45", "size": "997.79"}, {"price": "0.44", "size": "55"}, {"price": "0.43", "size": "120"}, {"price": "0.42", "size": "90"}, {"price": "0.41", "size": "195"}, {"price": "0.36", "size": "95"}, {"price": "0.35", "size": "55"}, {"price": "0.34", "size": "183.11"}, {"price": "0.32", "size": "101"}, {"price": "0.3", "size": "2404.99"}, {"price": "0.24", "size": "30"}, {"price": "0.2", "size": "5"}, {"price": "0.199", "size": "100"}, {"price": "0.19", "size": "211"}, {"price": "0.15", "size": "15"}, {"price": "0.1", "size": "5991.25"}, {"price": "0.093", "size": "200"}, {"price": "0.09", "size": "5562"}, {"price": "0.08", "size": "3602"}, {"price": "0.07", "size": "100"}, {"price": "0.06", "size": "100"}, {"price": "0.05", "size": "1812.49"}, {"price": "0.048", "size": "800"}, {"price": "0.047", "size": "30"}, {"price": "0.046", "size": "20"}, {"price": "0.01", "size": "64554.1"}, {"price": "0.009", "size": "20"}, {"price": "0.008", "size": "10100"}, {"price": "0.005", "size": "1999.99"}, {"price": "0.003", "size": "100"}, {"price": "0.002", "size": "663.79"}, {"price": "0.001", "size": "105025.3"}], "event_type": "book", "last_trade_price": "0.001"}, {"market": "0xbc4e5a49c32f7d9cc55654ddfbcf8f75706edc07a11ae327730bb877750bbeaa", "asset_id": "34381077001480453181234991484778155475666970440314626092277835235626736589664", "timestamp": "1769383997542", "hash": "aea75d5a6a5b309b1a39d05271514d20d09ad50f", "bids": [{"price": "0.001", "size": "3778.06"}, {"price": "0.002", "size": "1250"}, {"price": "0.003", "size": "1406.62"}, {"price": "0.006", "size": "200"}, {"price": "0.007", "size": "9.76"}, {"price": "0.01", "size": "6523"}, {"price": "0.02", "size": "2600"}, {"price": "0.021", "size": "8.81"}, {"price": "0.05", "size": "10"}, {"price": "0.06", "size": "900"}, {"price": "0.061", "size": "8.89"}, {"price": "0.1", "size": "860"}, {"price": "0.15", "size": "226.66"}, {"price": "0.2", "size": "160"}, {"price": "0.201", "size": "5.84"}, {"price": "0.223", "size": "143"}, {"price": "0.25", "size": "112"}, {"price": "0.251", "size": "7"}, {"price": "0.3", "size": "86.66"}, {"price": "0.35", "size": "68.57"}, {"price": "0.4", "size": "50"}, {"price": "0.523", "size": "112"}, {"price": "0.923", "size": "486"}, {"price": "0.945", "size": "30"}, {"price": "0.946", "size": "20"}, {"price": "0.947", "size": "400"}, {"price": "0.982", "size": "200"}, {"price": "0.987", "size": "13.33"}, {"price": "0.988", "size": "100"}, {"price": "0.989", "size": "20"}, {"price": "0.995", "size": "6250"}, {"price": "0.997", "size": "62.49"}, {"price": "0.998", "size": "8283.79"}, {"price": "0.999", "size": "136672.76"}], "asks": [], "event_type": "book", "last_trade_price": "0.001"}, {"market": "0x28101208d1076b3dc8fca84aeebe55cc8505b01f40c8e1d5c5fa3209cc395120", "asset_id": "58747865919172231095011168471546530760273932108399756901651325449763346350897", "timestamp": "1769383973617", "hash": "f04bae1106768226724a97a501c4aa766de74278", "bids": [{"price": "0.001", "size": "3818.06"}, {"price": "0.002", "size": "12.44"}, {"price": "0.003", "size": "1400"}, {"price": "0.006", "size": "200"}, {"price": "0.007", "size": "9.76"}, {"price": "0.01", "size": "6523"}, {"price": "0.02", "size": "3600"}, {"price": "0.021", "size": "8.81"}, {"price": "0.05", "size": "30"}, {"price": "0.06", "size": "900"}, {"price": "0.061", "size": "8.89"}, {"price": "0.1", "size": "360"}, {"price": "0.15", "size": "226.66"}, {"price": "0.192", "size": "2409.97"}, {"price": "0.2", "size": "160"}, {"price": "0.201", "size": "5.84"}, {"price": "0.223", "size": "142"}, {"price": "0.25", "size": "112"}, {"price": "0.251", "size": "7"}, {"price": "0.3", "size": "86.66"}, {"price": "0.35", "size": "68.57"}, {"price": "0.4", "size": "50"}, {"price": "0.523", "size": "136"}, {"price": "0.723", "size": "190"}, {"price": "0.923", "size": "486"}, {"price": "0.93", "size": "800"}, {"price": "0.931", "size": "30"}, {"price": "0.957", "size": "13.33"}, {"price": "0.959", "size": "20"}, {"price": "0.96", "size": "20"}, {"price": "0.961", "size": "500"}, {"price": "0.995", "size": "500"}, {"price": "0.997", "size": "2225.49"}, {"price": "0.998", "size": "4700.66"}, {"price": "0.999", "size": "213004"}], "asks": [], "event_type": "book", "last_trade_price": ""}, {"market": "0xc9dc3221d327cdca2401a80e8b138e6f81e17e7aabb0ae4915ec744e37d89fb9", "asset_id": "30832134873051915510376997713155047909911899948937112157265655376345456505246", "timestamp": "1769383973709", "hash": "7a389d6ed57601634f7cd4782c73c181d8e1d828", "bids": [], "asks": [{"price": "0.999", "size": "3874.54"}, {"price": "0.998", "size": "1250"}, {"price": "0.997", "size": "1406.62"}, {"price": "0.994", "size": "200"}, {"price": "0.993", "size": "9.76"}, {"price": "0.99", "size": "6538"}, {"price": "0.98", "size": "2600"}, {"price": "0.979", "size": "8.81"}, {"price": "0.95", "size": "10"}, {"price": "0.94", "size": "900"}, {"price": "0.939", "size": "8.89"}, {"price": "0.9", "size": "860"}, {"price": "0.85", "size": "226.66"}, {"price": "0.8", "size": "160"}, {"price": "0.799", "size": "5.84"}, {"price": "0.777", "size": "56"}, {"price": "0.75", "size": "112"}, {"price": "0.7", "size": "86.66"}, {"price": "0.66", "size": "3820.9"}, {"price": "0.659", "size": "5"}, {"price": "0.65", "size": "68.57"}, {"price": "0.6", "size": "50"}, {"price": "0.477", "size": "135"}, {"price": "0.35", "size": "2547.26"}, {"price": "0.277", "size": "106"}, {"price": "0.201", "size": "500"}, {"price": "0.177", "size": "107"}, {"price": "0.077", "size": "712"}, {"price": "0.072", "size": "800"}, {"price": "0.047", "size": "30"}, {"price": "0.046", "size": "20"}, {"price": "0.019", "size": "1016.62"}, {"price": "0.013", "size": "100"}, {"price": "0.012", "size": "13.33"}, {"price": "0.011", "size": "20"}, {"price": "0.005", "size": "4843.88"}, {"price": "0.003", "size": "10000"}, {"price": "0.002", "size": "16635.67"}, {"price": "0.001", "size": "246993.37"}], "event_type": "book", "last_trade_price": ""}, {"market": "0x87fa1d0200cae34d1abb2796b73a23a0434cef9eae9af694382d2ff63fec804a", "asset_id": "51552111503944829866957429954767286242387279354724573276882383824103379248961", "timestamp": "1769383973666", "hash": "113943ef76f4ac3ff89fa58f691019ff08a106ef", "bids": [{"price": "0.001", "size": "3429.06"}, {"price": "0.002", "size": "12.44"}, {"price": "0.003", "size": "1400"}, {"price": "0.006", "size": "200"}, {"price": "0.007", "size": "9.76"}, {"price": "0.01", "size": "6523"}, {"price": "0.02", "size": "2600"}, {"price": "0.021", "size": "8.81"}, {"price": "0.05", "size": "10"}, {"price": "0.06", "size": "900"}, {"price": "0.061", "size": "8.89"}, {"price": "0.1", "size": "860"}, {"price": "0.15", "size": "226.66"}, {"price": "0.2", "size": "160"}, {"price": "0.201", "size": "5.84"}, {"price": "0.223", "size": "143"}, {"price": "0.25", "size": "112"}, {"price": "0.251", "size": "7"}, {"price": "0.3", "size": "86.66"}, {"price": "0.35", "size": "68.57"}, {"price": "0.4", "size": "50"}, {"price": "0.523", "size": "136"}, {"price": "0.923", "size": "486"}, {"price": "0.936", "size": "800"}, {"price": "0.945", "size": "30"}, {"price": "0.946", "size": "20"}, {"price": "0.979", "size": "1000"}, {"price": "0.981", "size": "1191.37"}, {"price": "0.982", "size": "100"}, {"price": "0.99", "size": "1010"}, {"price": "0.991", "size": "20"}, {"price": "0.997", "size": "6.92"}, {"price": "0.998", "size": "13237.52"}, {"price": "0.999", "size": "262118.75"}], "asks": [], "event_type": "book", "last_trade_price": ""}, {"market": "0x87fa1d0200cae34d1abb2796b73a23a0434cef9eae9af694382d2ff63fec804a", "asset_id": "106678246482354893181601985328926429443842114194215732770784063273593452051663", "timestamp": "1769383973666", "hash": "235cc04839963b8b2e0b3c54f1a594131698b39e", "bids": [], "asks": [{"price": "0.999", "size": "3429.06"}, {"price": "0.998", "size": "12.44"}, {"price": "0.997", "size": "1400"}, {"price": "0.994", "size": "200"}, {"price": "0.993", "size": "9.76"}, {"price": "0.99", "size": "6523"}, {"price": "0.98", "size": "2600"}, {"price": "0.979", "size": "8.81"}, {"price": "0.95", "size": "10"}, {"price": "0.94", "size": "900"}, {"price": "0.939", "size": "8.89"}, {"price": "0.9", "size": "860"}, {"price": "0.85", "size": "226.66"}, {"price": "0.8", "size": "160"}, {"price": "0.799", "size": "5.84"}, {"price": "0.777", "size": "143"}, {"price": "0.75", "size": "112"}, {"price": "0.749", "size": "7"}, {"price": "0.7", "size": "86.66"}, {"price": "0.65", "size": "68.57"}, {"price": "0.6", "size": "50"}, {"price": "0.477", "size": "136"}, {"price": "0.077", "size": "486"}, {"price": "0.064", "size": "800"}, {"price": "0.055", "size": "30"}, {"price": "0.054", "size": "20"}, {"price": "0.021", "size": "1000"}, {"price": "0.019", "size": "1191.37"}, {"price": "0.018", "size": "100"}, {"price": "0.01", "size": "1010"}, {"price": "0.009", "size": "20"}, {"price": "0.003", "size": "6.92"}, {"price": "0.002", "size": "13237.52"}, {"price": "0.001", "size": "262118.75"}], "event_type": "book", "last_trade_price": ""}, {"market": "0xe115524784ad092f0e7e078973922c5010f2a1c38c2fb8a9bce309c0ca79f1a8", "asset_id": "102035716883856394193875777751837051350442691358278511897073452290571434607974", "timestamp": "1769383973703", "hash": "18ee00eb5d9d14431d36a0497352cf28caf3ed3b", "bids": [{"price": "0.001", "size": "3934.06"}, {"price": "0.002", "size": "1250"}, {"price": "0.003", "size": "1406.62"}, {"price": "0.006", "size": "200"}, {"price": "0.007", "size": "9.76"}, {"price": "0.01", "size": "6538"}, {"price": "0.02", "size": "2600"}, {"price": "0.021", "size": "8.81"}, {"price": "0.05", "size": "10"}, {"price": "0.06", "size": "900"}, {"price": "0.061", "size": "8.89"}, {"price": "0.1", "size": "860"}, {"price": "0.15", "size": "226.66"}, {"price": "0.2", "size": "160"}, {"price": "0.201", "size": "5.84"}, {"price": "0.223", "size": "55"}, {"price": "0.25", "size": "112"}, {"price": "0.251", "size": "7"}, {"price": "0.3", "size": "86.66"}, {"price": "0.35", "size": "68.57"}, {"price": "0.4", "size": "50"}, {"price": "0.523", "size": "135"}, {"price": "0.723", "size": "106"}, {"price": "0.823", "size": "107"}, {"price": "0.92", "size": "500"}, {"price": "0.923", "size": "711"}, {"price": "0.931", "size": "800"}, {"price": "0.94", "size": "30"}, {"price": "0.941", "size": "20"}, {"price": "0.976", "size": "1000"}, {"price": "0.982", "size": "1089.64"}, {"price": "0.983", "size": "100"}, {"price": "0.99", "size": "70"}, {"price": "0.991", "size": "20"}, {"price": "0.997", "size": "475"}, {"price": "0.998", "size": "32542.79"}, {"price": "0.999", "size": "231269.78"}], "asks": [], "event_type": "book", "last_trade_price": ""}, {"market": "0x2b1e18ef56cb7222ce2fb03d6cd9fb8fcca06d80b64d0dacbe6ce2f00ab31d00", "asset_id": "108290077635041993245111833080106297350242002571244675087631982922823879559265", "timestamp": "1769383973611", "hash": "18b2517c3495d102375b88a51319c815e3643954", "bids": [{"price": "0.001", "size": "3839.08"}, {"price": "0.002", "size": "1250"}, {"price": "0.003", "size": "1000"}, {"price": "0.004", "size": "20.81"}, {"price": "0.01", "size": "6533"}, {"price": "0.02", "size": "2600"}, {"price": "0.021", "size": "8.81"}, {"price": "0.05", "size": "30"}, {"price": "0.051", "size": "39"}, {"price": "0.06", "size": "900"}, {"price": "0.061", "size": "9.44"}, {"price": "0.1", "size": "860"}, {"price": "0.101", "size": "19"}, {"price": "0.15", "size": "226.66"}, {"price": "0.2", "size": "160"}, {"price": "0.21", "size": "200"}, {"price": "0.211", "size": "5.4"}, {"price": "0.25", "size": "112"}, {"price": "0.3", "size": "96.66"}, {"price": "0.33", "size": "100"}, {"price": "0.35", "size": "68.57"}, {"price": "0.4", "size": "56.66"}, {"price": "0.47", "size": "50"}, {"price": "0.5", "size": "799"}, {"price": "0.64", "size": "1112.15"}, {"price": "0.75", "size": "10"}, {"price": "0.78", "size": "40.71"}, {"price": "0.79", "size": "583.33"}, {"price": "0.8", "size": "10"}, {"price": "0.85", "size": "60"}, {"price": "0.86", "size": "30"}, {"price": "0.88", "size": "661"}, {"price": "0.9", "size": "562.5"}, {"price": "0.92", "size": "65"}, {"price": "0.93", "size": "195"}, {"price": "0.935", "size": "100"}, {"price": "0.94", "size": "145"}, {"price": "0.945", "size": "100"}, {"price": "0.95", "size": "662.5"}, {"price": "0.951", "size": "30"}, {"price": "0.955", "size": "100"}, {"price": "0.96", "size": "100"}, {"price": "0.962", "size": "987.1"}, {"price": "0.965", "size": "100"}, {"price": "0.969", "size": "600"}, {"price": "0.97", "size": "20"}, {"price": "0.976", "size": "800"}, {"price": "0.98", "size": "1610.5"}, {"price": "0.987", "size": "151.07"}, {"price": "0.99", "size": "16368"}, {"price": "0.991", "size": "100"}, {"price": "0.995", "size": "750"}, {"price": "0.997", "size": "3408.42"}, {"price": "0.998", "size": "2580.3"}, {"price": "0.999", "size": "33232.06"}], "asks": [], "event_type": "book", "last_trade_price": "0.001"}, {"market": "0xc23d4f3a1a96576e93f32ab1806c6d85f5a3d1925df7c80bdb97cfd6787b4dfc", "asset_id": "87130116211403737424591584260857843845869047615641100548769654750441704206968", "timestamp": "1769383973563", "hash": "4c51097b61744c5c882a7a4dc617dd52f73dd0f7", "bids": [], "asks": [{"price": "0.999", "size": "107934.06"}, {"price": "0.998", "size": "1250"}, {"price": "0.997", "size": "1406.62"}, {"price": "0.994", "size": "200"}, {"price": "0.993", "size": "9.76"}, {"price": "0.99", "size": "2023"}, {"price": "0.98", "size": "2600"}, {"price": "0.979", "size": "12.96"}, {"price": "0.95", "size": "10"}, {"price": "0.92", "size": "1999.96"}, {"price": "0.919", "size": "5.62"}, {"price": "0.9", "size": "860"}, {"price": "0.85", "size": "226.66"}, {"price": "0.8", "size": "160"}, {"price": "0.799", "size": "5.84"}, {"price": "0.777", "size": "143"}, {"price": "0.75", "size": "112"}, {"price": "0.749", "size": "7"}, {"price": "0.7", "size": "86.66"}, {"price": "0.65", "size": "68.57"}, {"price": "0.6", "size": "50"}, {"price": "0.477", "size": "136"}, {"price": "0.201", "size": "500"}, {"price": "0.077", "size": "486"}, {"price": "0.07", "size": "800"}, {"price": "0.069", "size": "30"}, {"price": "0.044", "size": "20"}, {"price": "0.043", "size": "400"}, {"price": "0.015", "size": "206.61"}, {"price": "0.014", "size": "100"}, {"price": "0.01", "size": "1400"}, {"price": "0.009", "size": "20"}, {"price": "0.004", "size": "1987.53"}, {"price": "0.003", "size": "69.63"}, {"price": "0.002", "size": "10553.4"}, {"price": "0.001", "size": "252902.66"}], "event_type": "book", "last_trade_price": ""}, {"market": "0x0bdf73e4f9d1f9bddd76011f7c7f70ac2a7bf02858f6e724ff17fab39cdb84aa", "asset_id": "91026359419320379024878691909394517154461461579031366036356847269582766989758", "timestamp": "1769383973722", "hash": "3faede84aa3bc985debfeba104e644541e3fa698", "bids": [], "asks": [{"price": "0.999", "size": "3844.06"}, {"price": "0.998", "size": "1250"}, {"price": "0.997", "size": "1406.62"}, {"price": "0.994", "size": "200"}, {"price": "0.993", "size": "9.76"}, {"price": "0.99", "size": "6538"}, {"price": "0.98", "size": "2600"}, {"price": "0.979", "size": "8.81"}, {"price": "0.95", "size": "10"}, {"price": "0.94", "size": "900"}, {"price": "0.939", "size": "8.95"}, {"price": "0.9", "size": "860"}, {"price": "0.85", "size": "226.66"}, {"price": "0.8", "size": "160"}, {"price": "0.797", "size": "9"}, {"price": "0.796", "size": "5.73"}, {"price": "0.777", "size": "5"}, {"price": "0.75", "size": "112"}, {"price": "0.7", "size": "86.66"}, {"price": "0.65", "size": "68.57"}, {"price": "0.6", "size": "50"}, {"price": "0.477", "size": "6"}, {"price": "0.277", "size": "106"}, {"price": "0.177", "size": "107"}, {"price": "0.113", "size": "999.99"}, {"price": "0.077", "size": "711"}, {"price": "0.072", "size": "800"}, {"price": "0.07", "size": "30"}, {"price": "0.037", "size": "749.99"}, {"price": "0.036", "size": "20"}, {"price": "0.028", "size": "69"}, {"price": "0.027", "size": "13"}, {"price": "0.026", "size": "20"}, {"price": "0.025", "size": "500"}, {"price": "0.002", "size": "573.79"}, {"price": "0.001", "size": "274609.06"}], "event_type": "book", "last_trade_price": "0.001"}]}
{"_local_timestamp": "2026-01-25T23:33:18.222008+00:00", "data": {"market": "0xbcb33ad98c8141b10f2350ef687eddf0660484ecc15be42ecdae64339e64dce1", "price_changes": [{"asset_id": "105108334823274411453837752322302146951506166827237470954759784982159162094956", "price": "0.979", "size": "1712.47", "side": "BUY", "hash": "549925f515ddfe6185521fca1c4c69484e2669cb", "best_bid": "0.98", "best_ask": "0.981"}, {"asset_id": "87048058140607839077917415447158941112086606824479198286281986963033007181784", "price": "0.021", "size": "1712.47", "side": "SELL", "hash": "172a001067bd71ab43510319fddaaa6c0234a1d6", "best_bid": "0.019", "best_ask": "0.02"}], "timestamp": "1769383997972", "event_type": "price_change"}}
{"_local_timestamp": "2026-01-25T23:33:28.724971+00:00", "data": {"market": "0xa062dea464f0e8fc3381176494198cf45574ec190eca77a40f49988320fa15f2", "price_changes": [{"asset_id": "16754375222233973989954094649431109282368408854808102040230156977754673841406", "price": "0.962", "size": "19478.12", "side": "BUY", "hash": "e0f397e7ee8faf7220e0b75af9054ba8e818f78f", "best_bid": "0.98", "best_ask": "0.981"}, {"asset_id": "2941656641529467089826910607945793276058581543804243973571467775773698944388", "price": "0.038", "size": "19478.12", "side": "SELL", "hash": "e9de37747269ec5f42c550060a4902c679555aea", "best_bid": "0.019", "best_ask": "0.02"}], "timestamp": "1769384008645", "event_type": "price_change"}}
{"_local_timestamp": "2026-01-25T23:33:28.725802+00:00", "data": {"market": "0xa062dea464f0e8fc3381176494198cf45574ec190eca77a40f49988320fa15f2", "price_changes": [{"asset_id": "16754375222233973989954094649431109282368408854808102040230156977754673841406", "price": "0.991", "size": "14514.08", "side": "SELL", "hash": "2fff760ae79b00430c9c79ce4fe2b8f17e869acd", "best_bid": "0.98", "best_ask": "0.981"}, {"asset_id": "2941656641529467089826910607945793276058581543804243973571467775773698944388", "price": "0.009", "size": "14514.08", "side": "BUY", "hash": "a699511ad3387c8004e6adc912db640fd9bc0292", "best_bid": "0.019", "best_ask": "0.02"}], "timestamp": "1769384008646", "event_type": "price_change"}}
{"_local_timestamp": "2026-01-25T23:33:28.861609+00:00", "data": {"market": "0x1d5827b0448938c4c40a1c6747abc61e4ff690ac3d7306e0690c1741eb6dcb0b", "price_changes": [{"asset_id": "50298286906716199010522025175676678342201745398212393361362499308691655626332", "price": "0.987", "size": "66.66", "side": "BUY", "hash": "e7cd22ac91f7539f7262fe27e2f483bd9eeb8bcc", "best_bid": "0.999", "best_ask": "1"}, {"asset_id": "12066144173721960949299167133110175689689620950083050321772650546514468891687", "price": "0.013", "size": "66.66", "side": "SELL", "hash": "0fba7f21e220a410f504c1a99bfe2b3856c2e023", "best_bid": "0", "best_ask": "0.001"}], "timestamp": "1769384008788", "event_type": "price_change"}}
{"_local_timestamp": "2026-01-25T23:33:28.862292+00:00", "data": {"market": "0xdcf89266de269fa8d785c5a6218c482f08cf26f9987d879fc97d6a335238a08c", "price_changes": [{"asset_id": "18180536855858852221205988991865712966455254452005023897135830094334125653819", "price": "0.986", "size": "66.66", "side": "BUY", "hash": "51e6ada2ef930f7baf73562257ef9ea44add01ea", "best_bid": "0.999", "best_ask": "1"}, {"asset_id": "80955738350011048477695041166314820890097312693648599864162887413862093761380", "price": "0.014", "size": "66.66", "side": "SELL", "hash": "421287f7bc40e52b1412293ede94e864569d3b9d", "best_bid": "0", "best_ask": "0.001"}], "timestamp": "1769384008788", "event_type": "price_change"}}
{"_local_timestamp": "2026-01-25T23:33:28.862822+00:00", "data": {"market": "0x18b1dc1565575cb2ff48bbc078070170ca3278691860cca7c97131fc657a9530", "price_changes": [{"asset_id": "94238513083578948523157790197851186920885838535648691968842196265124859609799", "price": "0.968", "size": "400", "side": "BUY", "hash": "91e513de3a6bc9b8a6fa3897c224a7809418b2ae", "best_bid": "0.999", "best_ask": "1"}, {"asset_id": "62947063083572838306765336947158511397004781598875199570718451493234069599112", "price": "0.032", "size": "400", "side": "SELL", "hash": "5562e27244887d85fccc5863894e5e9e2397f809", "best_bid": "0", "best_ask": "0.001"}], "timestamp": "1769384008788", "event_type": "price_change"}}
{"_local_timestamp": "2026-01-25T23:33:35.465543+00:00", "data": {"market": "0xc9dc3221d327cdca2401a80e8b138e6f81e17e7aabb0ae4915ec744e37d89fb9", "price_changes": [{"asset_id": "48766341308125246446934576208296715790150929628230476623094742688581948013790", "price": "0.988", "size": "0", "side": "BUY", "hash": "d491e2d22cc31f6c4fb6691870b4cb458d71a5e5", "best_bid": "0.999", "best_ask": "1"}, {"asset_id": "30832134873051915510376997713155047909911899948937112157265655376345456505246", "price": "0.012", "size": "0", "side": "SELL", "hash": "f5da35508bac96f5c5c4c8162c348d80d1a84c9b", "best_bid": "0", "best_ask": "0.001"}], "timestamp": "1769384015391", "event_type": "price_change"}}
{"_local_timestamp": "2026-01-25T23:33:35.506294+00:00", "data": {"market": "0xc9dc3221d327cdca2401a80e8b138e6f81e17e7aabb0ae4915ec744e37d89fb9", "price_changes": [{"asset_id": "48766341308125246446934576208296715790150929628230476623094742688581948013790", "price": "0.989", "size": "33.33", "side": "BUY", "hash": "c4e7aa4a39dd71a5654e196cd39a54416d1589f8", "best_bid": "0.999", "best_ask": "1"}, {"asset_id": "30832134873051915510376997713155047909911899948937112157265655376345456505246", "price": "0.011", "size": "33.33", "side": "SELL", "hash": "f8107223565b1216f8675836d9c589137b5d79c4", "best_bid": "0", "best_ask": "0.001"}], "timestamp": "1769384015439", "event_type": "price_change"}}
{"_local_timestamp": "2026-01-25T23:33:35.700232+00:00", "data": {"market": "0xa062dea464f0e8fc3381176494198cf45574ec190eca77a40f49988320fa15f2", "price_changes": [{"asset_id": "16754375222233973989954094649431109282368408854808102040230156977754673841406", "price": "0.962", "size": "11883.12", "side": "BUY", "hash": "df16ba1125f75b830518e70f8db15cb43878d538", "best_bid": "0.98", "best_ask": "0.981"}, {"asset_id": "2941656641529467089826910607945793276058581543804243973571467775773698944388", "price": "0.038", "size": "11883.12", "side": "SELL", "hash": "bab59eea079347cf7975292ee70884e7cfdca86a", "best_bid": "0.019", "best_ask": "0.02"}], "timestamp": "1769384015620", "event_type": "price_change"}}
{"_local_timestamp": "2026-01-25T23:33:35.702082+00:00", "data": {"market": "0xa062dea464f0e8fc3381176494198cf45574ec190eca77a40f49988320fa15f2", "price_changes": [{"asset_id": "16754375222233973989954094649431109282368408854808102040230156977754673841406", "price": "0.991", "size": "2014.08", "side": "SELL", "hash": "df16ba1125f75b830518e70f8db15cb43878d538", "best_bid": "0.98", "best_ask": "0.981"}, {"asset_id": "2941656641529467089826910607945793276058581543804243973571467775773698944388", "price": "0.009", "size": "2014.08", "side": "BUY", "hash": "bab59eea079347cf7975292ee70884e7cfdca86a", "best_bid": "0.019", "best_ask": "0.02"}], "timestamp": "1769384015620", "event_type": "price_change"}}
{"_local_timestamp": "2026-01-25T23:33:35.841144+00:00", "data": {"market": "0x0bdf73e4f9d1f9bddd76011f7c7f70ac2a7bf02858f6e724ff17fab39cdb84aa", "price_changes": [{"asset_id": "44060160461153155780840707322998889704290849153451415562546100515099098148308", "price": "0.972", "size": "0", "side": "BUY", "hash": "63802a12fec2d20e719936a0a1a98d9ab845406a", "best_bid": "0.999", "best_ask": "1"}, {"asset_id": "91026359419320379024878691909394517154461461579031366036356847269582766989758", "price": "0.028", "size": "0", "side": "SELL", "hash": "70d2a456b7436e6dcd1ac155d39408f444bd284f", "best_bid": "0", "best_ask": "0.001"}], "timestamp": "1769384015762", "event_type": "price_change"}}
{"_local_timestamp": "2026-01-25T23:33:35.909274+00:00", "data": {"market": "0x0bdf73e4f9d1f9bddd76011f7c7f70ac2a7bf02858f6e724ff17fab39cdb84aa", "price_changes": [{"asset_id": "44060160461153155780840707322998889704290849153451415562546100515099098148308", "price": "0.973", "size": "0", "side": "BUY", "hash": "7416851786ee2e3006605c855de3c3b947396133", "best_bid": "0.999", "best_ask": "1"}, {"asset_id": "91026359419320379024878691909394517154461461579031366036356847269582766989758", "price": "0.027", "size": "0", "side": "SELL", "hash": "0f19c49866b3ddc8932b23d7541c59ead9d976b7", "best_bid": "0", "best_ask": "0.001"}], "timestamp": "1769384015838", "event_type": "price_change"}}
{"_local_timestamp": "2026-01-25T23:33:35.955888+00:00", "data": {"market": "0x0bdf73e4f9d1f9bddd76011f7c7f70ac2a7bf02858f6e724ff17fab39cdb84aa", "price_changes": [{"asset_id": "44060160461153155780840707322998889704290849153451415562546100515099098148308", "price": "0.975", "size": "582", "side": "BUY", "hash": "21aba06327ee0804a57958c2e6834b34664312a7", "best_bid": "0.999", "best_ask": "1"}, {"asset_id": "91026359419320379024878691909394517154461461579031366036356847269582766989758", "price": "0.025", "size": "582", "side": "SELL", "hash": "2cb3b0067ea64d841b564dc957893b51bdefb516", "best_bid": "0", "best_ask": "0.001"}], "timestamp": "1769384015883", "event_type": "price_change"}}
{"_local_timestamp": "2026-01-25T23:33:36.206687+00:00", "data": {"market": "0xbcb33ad98c8141b10f2350ef687eddf0660484ecc15be42ecdae64339e64dce1", "price_changes": [{"asset_id": "105108334823274411453837752322302146951506166827237470954759784982159162094956", "price": "0.979", "size": "2960.93", "side": "BUY", "hash": "1ceeeecd59d54c5d88e16542c1bcd7380dea9663", "best_bid": "0.98", "best_ask": "0.981"}, {"asset_id": "87048058140607839077917415447158941112086606824479198286281986963033007181784", "price": "0.021", "size": "2960.93", "side": "SELL", "hash": "415edc06e5de4a7615fec83579dbd8f049b0dd6d", "best_bid": "0.019", "best_ask": "0.02"}], "timestamp": "1769384016132", "event_type": "price_change"}}
{"_local_timestamp": "2026-01-25T23:33:36.329232+00:00", "data": {"market": "0xbcb33ad98c8141b10f2350ef687eddf0660484ecc15be42ecdae64339e64dce1", "price_changes": [{"asset_id": "105108334823274411453837752322302146951506166827237470954759784982159162094956", "price": "0.979", "size": "1712.47", "side": "BUY", "hash": "090ec9113fd7d38074e3ae29f9a0d7f6f862b335", "best_bid": "0.98", "best_ask": "0.981"}, {"asset_id": "87048058140607839077917415447158941112086606824479198286281986963033007181784", "price": "0.021", "size": "1712.47", "side": "SELL", "hash": "00688eba034acf78328a7f0a3ac73e9928c70c27", "best_bid": "0.019", "best_ask": "0.02"}], "timestamp": "1769384016258", "event_type": "price_change"}}
{"_local_timestamp": "2026-01-25T23:33:36.467666+00:00", "data": {"market": "0xbcb33ad98c8141b10f2350ef687eddf0660484ecc15be42ecdae64339e64dce1", "price_changes": [{"asset_id": "105108334823274411453837752322302146951506166827237470954759784982159162094956", "price": "0.979", "size": "2960.93", "side": "BUY", "hash": "52df6f72903c478ff7a2609c99ab80bb70b580d6", "best_bid": "0.98", "best_ask": "0.981"}, {"asset_id": "87048058140607839077917415447158941112086606824479198286281986963033007181784", "price": "0.021", "size": "2960.93", "side": "SELL", "hash": "f3f519c11de20b497086a9fb3e9f49048927147d", "best_bid": "0.019", "best_ask": "0.02"}], "timestamp": "1769384016373", "event_type": "price_change"}}
{"_local_timestamp": "2026-01-25T23:33:36.640267+00:00", "data": {"market": "0xbcb33ad98c8141b10f2350ef687eddf0660484ecc15be42ecdae64339e64dce1", "price_changes": [{"asset_id": "105108334823274411453837752322302146951506166827237470954759784982159162094956", "price": "0.979", "size": "1712.47", "side": "BUY", "hash": "b4f5d9c93de8162d5a4c8a7520c2ad65335eaeeb", "best_bid": "0.98", "best_ask": "0.981"}, {"asset_id": "87048058140607839077917415447158941112086606824479198286281986963033007181784", "price": "0.021", "size": "1712.47", "side": "SELL", "hash": "de3e6fe07a3c1080161bc55ad79c87748088e5a1", "best_bid": "0.019", "best_ask": "0.02"}], "timestamp": "1769384016564", "event_type": "price_change"}}
{"_local_timestamp": "2026-01-25T23:33:36.659989+00:00", "data": {"market": "0x28101208d1076b3dc8fca84aeebe55cc8505b01f40c8e1d5c5fa3209cc395120", "price_changes": [{"asset_id": "58747865919172231095011168471546530760273932108399756901651325449763346350897", "price": "0.957", "size": "0", "side": "BUY", "hash": "827930f142442d700ca6ca69eb64fab325fa30ca", "best_bid": "0.999", "best_ask": "1"}, {"asset_id": "114268099239767676216932072226652369234485747669785862612893982920970460896563", "price": "0.043", "size": "0", "side": "SELL", "hash": "ff8070dbf48e71ac20ec5bc95737b7def3984fa1", "best_bid": "0", "best_ask": "0.001"}], "timestamp": "1769384016586", "event_type": "price_change"}}
{"_local_timestamp": "2026-01-25T23:33:36.707951+00:00", "data": {"market": "0x28101208d1076b3dc8fca84aeebe55cc8505b01f40c8e1d5c5fa3209cc395120", "price_changes": [{"asset_id": "58747865919172231095011168471546530760273932108399756901651325449763346350897", "price": "0.961", "size": "583", "side": "BUY", "hash": "3766e66a5730a2569f03e343a22e4a3a93c5fb4b", "best_bid": "0.999", "best_ask": "1"}, {"asset_id": "114268099239767676216932072226652369234485747669785862612893982920970460896563", "price": "0.039", "size": "583", "side": "SELL", "hash": "a1aa5ca5859cdf27d3043ee774dea005dc9ed48f", "best_bid": "0", "best_ask": "0.001"}], "timestamp": "1769384016634", "event_type": "price_change"}}
{"_local_timestamp": "2026-01-25T23:33:36.979117+00:00", "data": {"market": "0xdcf89266de269fa8d785c5a6218c482f08cf26f9987d879fc97d6a335238a08c", "price_changes": [{"asset_id": "18180536855858852221205988991865712966455254452005023897135830094334125653819", "price": "0.986", "size": "0", "side": "BUY", "hash": "7ccecb1796fe93acdb4e0e3473e5f89f8ef8cf5c", "best_bid": "0.999", "best_ask": "1"}, {"asset_id": "80955738350011048477695041166314820890097312693648599864162887413862093761380", "price": "0.014", "size": "0", "side": "SELL", "hash": "313d4ae55425dd4fb886bba101da499cee26070e", "best_bid": "0", "best_ask": "0.001"}], "timestamp": "1769384016904", "event_type": "price_change"}}
{"_local_timestamp": "2026-01-25T23:33:37.032676+00:00", "data": {"market": "0xdcf89266de269fa8d785c5a6218c482f08cf26f9987d879fc97d6a335238a08c", "price_changes": [{"asset_id": "18180536855858852221205988991865712966455254452005023897135830094334125653819", "price": "0.988", "size": "33.33", "side": "BUY", "hash": "a064c37d07e8dcf489f9abbd13dba435084413bf", "best_bid": "0.999", "best_ask": "1"}, {"asset_id": "80955738350011048477695041166314820890097312693648599864162887413862093761380", "price": "0.012", "size": "33.33", "side": "SELL", "hash": "ba66896806d3f1dceb809824ec2b85a8d766134a", "best_bid": "0", "best_ask": "0.001"}], "timestamp": "1769384016953", "event_type": "price_change"}}
{"_local_timestamp": "2026-01-25T23:33:37.081083+00:00", "data": {"market": "0xbcb33ad98c8141b10f2350ef687eddf0660484ecc15be42ecdae64339e64dce1", "price_changes": [{"asset_id": "105108334823274411453837752322302146951506166827237470954759784982159162094956", "price": "0.979", "size": "2960.93", "side": "BUY", "hash": "9c145d1a60fbd3ee1591de2773cf4a37b8559abe", "best_bid": "0.98", "best_ask": "0.981"}, {"asset_id": "87048058140607839077917415447158941112086606824479198286281986963033007181784", "price": "0.021", "size": "2960.93", "side": "SELL", "hash": "98684eeb6634275da0b79d0fc783a33de0374e78", "best_bid": "0.019", "best_ask": "0.02"}], "timestamp": "1769384017007", "event_type": "price_change"}}
{"_local_timestamp": "2026-01-25T23:33:37.198426+00:00", "data": {"market": "0xbcb33ad98c8141b10f2350ef687eddf0660484ecc15be42ecdae64339e64dce1", "price_changes": [{"asset_id": "105108334823274411453837752322302146951506166827237470954759784982159162094956", "price": "0.979", "size": "1712.47", "side": "BUY", "hash": "f0e03ff83741c769ecdf47f82dfc61635b59630d", "best_bid": "0.98", "best_ask": "0.981"}, {"asset_id": "87048058140607839077917415447158941112086606824479198286281986963033007181784", "price": "0.021", "size": "1712.47", "side": "SELL", "hash": "7a8d07d1a37f5620ee3faeed0837d4b1afb3dd17", "best_bid": "0.019", "best_ask": "0.02"}], "timestamp": "1769384017120", "event_type": "price_change"}}
{"_local_timestamp": "2026-01-25T23:33:37.716458+00:00", "data": {"market": "0x1a550f4be5469a1f7f19a6a87eb1d3c5aee638dd4b325cd7e80c94fcb69a4325", "price_changes": [{"asset_id": "100299191321741533544964863678141476981783881954596444647911413684277151596082", "price": "0.939", "size": "0", "side": "BUY", "hash": "907fdc2dc03d15ac66c44e1fec248c4137893df5", "best_bid": "0.999", "best_ask": "1"}, {"asset_id": "15849160483277897689949967085542532873284061361999325893867258022262592692821", "price": "0.061", "size": "0", "side": "SELL", "hash": "7eaca6761da52181289b3e67598d267e4d0b69ab", "best_bid": "0", "best_ask": "0.001"}], "timestamp": "1769384017643", "event_type": "price_change"}}
{"_local_timestamp": "2026-01-25T23:33:37.766204+00:00", "data": {"market": "0x1a550f4be5469a1f7f19a6a87eb1d3c5aee638dd4b325cd7e80c94fcb69a4325", "price_changes": [{"asset_id": "100299191321741533544964863678141476981783881954596444647911413684277151596082", "price": "0.942", "size": "33.33", "side": "BUY", "hash": "149ee89cb9e33d6834c73542b167ec8c55bf95e9", "best_bid": "0.999", "best_ask": "1"}, {"asset_id": "15849160483277897689949967085542532873284061361999325893867258022262592692821", "price": "0.058", "size": "33.33", "side": "SELL", "hash": "e742a931d0e5a2ddf30fa0225f2c65ff2618a82e", "best_bid": "0", "best_ask": "0.001"}], "timestamp": "1769384017692", "event_type": "price_change"}}
{"_local_timestamp": "2026-01-25T23:33:40.065858+00:00", "data": {"market": "0x18b1dc1565575cb2ff48bbc078070170ca3278691860cca7c97131fc657a9530", "price_changes": [{"asset_id": "94238513083578948523157790197851186920885838535648691968842196265124859609799", "price": "0.969", "size": "0", "side": "BUY", "hash": "69b3762fbc8ad5a0e551fb4a9b40c960ddca5d48", "best_bid": "0.999", "best_ask": "1"}, {"asset_id": "62947063083572838306765336947158511397004781598875199570718451493234069599112", "price": "0.031", "size": "0", "side": "SELL", "hash": "4aa9b6b87916b0a832163079d35e4109743615d9", "best_bid": "0", "best_ask": "0.001"}], "timestamp": "1769384019982", "event_type": "price_change"}}
{"_local_timestamp": "2026-01-25T23:33:40.131287+00:00", "data": {"market": "0x18b1dc1565575cb2ff48bbc078070170ca3278691860cca7c97131fc657a9530", "price_changes": [{"asset_id": "94238513083578948523157790197851186920885838535648691968842196265124859609799", "price": "0.971", "size": "33.33", "side": "BUY", "hash": "1fd3bd1525eba1949b9bb7ccd6fddcf2a5d9c64f", "best_bid": "0.999", "best_ask": "1"}, {"asset_id": "62947063083572838306765336947158511397004781598875199570718451493234069599112", "price": "0.029", "size": "33.33", "side": "SELL", "hash": "cf45c27bd1e9670ae33f8373863514c75adbe9d2", "best_bid": "0", "best_ask": "0.001"}], "timestamp": "1769384020035", "event_type": "price_change"}}
{"_local_timestamp": "2026-01-25T23:33:40.161374+00:00", "data": {"market": "0xbcb33ad98c8141b10f2350ef687eddf0660484ecc15be42ecdae64339e64dce1", "price_changes": [{"asset_id": "105108334823274411453837752322302146951506166827237470954759784982159162094956", "price": "0.979", "size": "2960.93", "side": "BUY", "hash": "3ef00c9fcd10db215b2eb23407f65de16222846d", "best_bid": "0.98", "best_ask": "0.981"}, {"asset_id": "87048058140607839077917415447158941112086606824479198286281986963033007181784", "price": "0.021", "size": "2960.93", "side": "SELL", "hash": "8a8a05e771cf7993e46acadc5b1b360e6582ef54", "best_bid": "0.019", "best_ask": "0.02"}], "timestamp": "1769384020060", "event_type": "price_change"}}
{"_local_timestamp": "2026-01-25T23:33:40.416203+00:00", "data": {"market": "0xbcb33ad98c8141b10f2350ef687eddf0660484ecc15be42ecdae64339e64dce1", "price_changes": [{"asset_id": "105108334823274411453837752322302146951506166827237470954759784982159162094956", "price": "0.979", "size": "1712.47", "side": "BUY", "hash": "6cb46ae64ef34ad9d8a0689bfc897a5d2495ba14", "best_bid": "0.98", "best_ask": "0.981"}, {"asset_id": "87048058140607839077917415447158941112086606824479198286281986963033007181784", "price": "0.021", "size": "1712.47", "side": "SELL", "hash": "fa656c46b18e1c1980b94874e60b7e0835532a65", "best_bid": "0.019", "best_ask": "0.02"}], "timestamp": "1769384020246", "event_type": "price_change"}}
{"_local_timestamp": "2026-01-25T23:33:40.450433+00:00", "data": {"market": "0x1d5827b0448938c4c40a1c6747abc61e4ff690ac3d7306e0690c1741eb6dcb0b", "price_changes": [{"asset_id": "50298286906716199010522025175676678342201745398212393361362499308691655626332", "price": "0.987", "size": "0", "side": "BUY", "hash": "50d1c030d3073f72ad7925cca33e92da1e2257ac", "best_bid": "0.999", "best_ask": "1"}, {"asset_id": "12066144173721960949299167133110175689689620950083050321772650546514468891687", "price": "0.013", "size": "0", "side": "SELL", "hash": "e7fa57f186468ff49c4af8f49c8cd5c4aad38afa", "best_bid": "0", "best_ask": "0.001"}], "timestamp": "1769384020328", "event_type": "price_change"}}
{"_local_timestamp": "2026-01-25T23:33:40.492371+00:00", "data": {"market": "0x1d5827b0448938c4c40a1c6747abc61e4ff690ac3d7306e0690c1741eb6dcb0b", "price_changes": [{"asset_id": "50298286906716199010522025175676678342201745398212393361362499308691655626332", "price": "0.989", "size": "33.33", "side": "BUY", "hash": "17ab00fa432519c0a887bf3a92db7e02c53c3485", "best_bid": "0.999", "best_ask": "1"}, {"asset_id": "12066144173721960949299167133110175689689620950083050321772650546514468891687", "price": "0.011", "size": "33.33", "side": "SELL", "hash": "dd94bcb8afc87012a39af2943d61299e0db787d4", "best_bid": "0", "best_ask": "0.001"}], "timestamp": "1769384020385", "event_type": "price_change"}}
{"_local_timestamp": "2026-01-25T23:33:40.496610+00:00", "data": {"market": "0xbcb33ad98c8141b10f2350ef687eddf0660484ecc15be42ecdae64339e64dce1", "price_changes": [{"asset_id": "105108334823274411453837752322302146951506166827237470954759784982159162094956", "price": "0.979", "size": "2960.93", "side": "BUY", "hash": "577cd2316341dd9f8b996eaf63065f1a3960ae78", "best_bid": "0.98", "best_ask": "0.981"}, {"asset_id": "87048058140607839077917415447158941112086606824479198286281986963033007181784", "price": "0.021", "size": "2960.93", "side": "SELL", "hash": "5b668cee51f9393645574fc0e35c9f5364c3bac7", "best_bid": "0.019", "best_ask": "0.02"}], "timestamp": "1769384020397", "event_type": "price_change"}}
{"_local_timestamp": "2026-01-25T23:33:40.762905+00:00", "data": {"market": "0xbcb33ad98c8141b10f2350ef687eddf0660484ecc15be42ecdae64339e64dce1", "price_changes": [{"asset_id": "105108334823274411453837752322302146951506166827237470954759784982159162094956", "price": "0.979", "size": "1712.47", "side": "BUY", "hash": "91547590a072f372aadf2b78d60e667fa1903a78", "best_bid": "0.98", "best_ask": "0.981"}, {"asset_id": "87048058140607839077917415447158941112086606824479198286281986963033007181784", "price": "0.021", "size": "1712.47", "side": "SELL", "hash": "93937d82d7048da0c0bc483250783f1da65a7d83", "best_bid": "0.019", "best_ask": "0.02"}], "timestamp": "1769384020589", "event_type": "price_change"}}
{"_local_timestamp": "2026-01-25T23:33:40.881124+00:00", "data": {"market": "0xbc4e5a49c32f7d9cc55654ddfbcf8f75706edc07a11ae327730bb877750bbeaa", "price_changes": [{"asset_id": "34381077001480453181234991484778155475666970440314626092277835235626736589664", "price": "0.987", "size": "0", "side": "BUY", "hash": "d7fa9f977bb7b0bfc14973487c511a0f744aba8d", "best_bid": "0.999", "best_ask": "1"}, {"asset_id": "53243047997408072043597262379510386757989173994530982334166850503991368110377", "price": "0.013", "size": "0", "side": "SELL", "hash": "ee3a81ae3467e5bf552619dc869461a006cd3d4e", "best_bid": "0", "best_ask": "0.001"}], "timestamp": "1769384020642", "event_type": "price_change"}}
{"_local_timestamp": "2026-01-25T23:33:40.897473+00:00", "data": {"market": "0xbc4e5a49c32f7d9cc55654ddfbcf8f75706edc07a11ae327730bb877750bbeaa", "price_changes": [{"asset_id": "34381077001480453181234991484778155475666970440314626092277835235626736589664", "price": "0.989", "size": "33.33", "side": "BUY", "hash": "46cb4d9b586b4c9416c1b54bdee81755c90e6db7", "best_bid": "0.999", "best_ask": "1"}, {"asset_id": "53243047997408072043597262379510386757989173994530982334166850503991368110377", "price": "0.011", "size": "33.33", "side": "SELL", "hash": "f0f44b5c983794eefad4801e3c2f0ea977923ba5", "best_bid": "0", "best_ask": "0.001"}], "timestamp": "1769384020693", "event_type": "price_change"}}
{"_local_timestamp": "2026-01-25T23:33:40.913556+00:00", "data": {"market": "0xbcb33ad98c8141b10f2350ef687eddf0660484ecc15be42ecdae64339e64dce1", "price_changes": [{"asset_id": "105108334823274411453837752322302146951506166827237470954759784982159162094956", "price": "0.979", "size": "2960.93", "side": "BUY", "hash": "6628857c33338a30eba897697ad4bf63fe9b7577", "best_bid": "0.98", "best_ask": "0.981"}, {"asset_id": "87048058140607839077917415447158941112086606824479198286281986963033007181784", "price": "0.021", "size": "2960.93", "side": "SELL", "hash": "d10a6bea9cf1fe206a5379db91ed6bc4fc8834ef", "best_bid": "0.019", "best_ask": "0.02"}], "timestamp": "1769384020765", "event_type": "price_change"}}
{"_local_timestamp": "2026-01-25T23:33:40.975549+00:00", "data": {"market": "0xbcb33ad98c8141b10f2350ef687eddf0660484ecc15be42ecdae64339e64dce1", "price_changes": [{"asset_id": "105108334823274411453837752322302146951506166827237470954759784982159162094956", "price": "0.979", "size": "1712.47", "side": "BUY", "hash": "a8ddbfe436999bf1c1fa3d4b76571ca171d9bfe8", "best_bid": "0.98", "best_ask": "0.981"}, {"asset_id": "87048058140607839077917415447158941112086606824479198286281986963033007181784", "price": "0.021", "size": "1712.47", "side": "SELL", "hash": "3482178afc154a3c5efcfc925f96472082c99b0d", "best_bid": "0.019", "best_ask": "0.02"}], "timestamp": "1769384020905", "event_type": "price_change"}}
{"_local_timestamp": "2026-01-25T23:33:47.494892+00:00", "data": {"market": "0xa062dea464f0e8fc3381176494198cf45574ec190eca77a40f49988320fa15f2", "price_changes": [{"asset_id": "16754375222233973989954094649431109282368408854808102040230156977754673841406", "price": "0.962", "size": "19473.12", "side": "BUY", "hash": "a45a9cf88646b6d5549ebaf1ed90de478f6c2339", "best_bid": "0.98", "best_ask": "0.981"}, {"asset_id": "2941656641529467089826910607945793276058581543804243973571467775773698944388", "price": "0.038", "size": "19473.12", "side": "SELL", "hash": "33561732c68f068b06b80a8057ea24a86dc85626", "best_bid": "0.019", "best_ask": "0.02"}], "timestamp": "1769384027426", "event_type": "price_change"}}
{"_local_timestamp": "2026-01-25T23:33:47.498027+00:00", "data": {"market": "0xa062dea464f0e8fc3381176494198cf45574ec190eca77a40f49988320fa15f2", "price_changes": [{"asset_id": "16754375222233973989954094649431109282368408854808102040230156977754673841406", "price": "0.991", "size": "14514.08", "side": "SELL", "hash": "fce65f2f53716e06743743d349e2747fc2264ddc", "best_bid": "0.98", "best_ask": "0.981"}, {"asset_id": "2941656641529467089826910607945793276058581543804243973571467775773698944388", "price": "0.009", "size": "14514.08", "side": "BUY", "hash": "f9c00e393e9417d0e1b0ca00b5fa1dd15b87ecec", "best_bid": "0.019", "best_ask": "0.02"}], "timestamp": "1769384027433", "event_type": "price_change"}}
{"_local_timestamp": "2026-01-25T23:33:47.549891+00:00", "data": {"market": "0xbcb33ad98c8141b10f2350ef687eddf0660484ecc15be42ecdae64339e64dce1", "price_changes": [{"asset_id": "105108334823274411453837752322302146951506166827237470954759784982159162094956", "price": "0.979", "size": "3017.6", "side": "BUY", "hash": "29b3c4126a8e493552b12fc941f71924599d165b", "best_bid": "0.98", "best_ask": "0.981"}, {"asset_id": "87048058140607839077917415447158941112086606824479198286281986963033007181784", "price": "0.021", "size": "3017.6", "side": "SELL", "hash": "6670f8e7e11a63852d157bb47e194ee1c0c7b448", "best_bid": "0.019", "best_ask": "0.02"}], "timestamp": "1769384027480", "event_type": "price_change"}}
{"_local_timestamp": "2026-01-25T23:33:47.696169+00:00", "data": {"market": "0xbcb33ad98c8141b10f2350ef687eddf0660484ecc15be42ecdae64339e64dce1", "price_changes": [{"asset_id": "105108334823274411453837752322302146951506166827237470954759784982159162094956", "price": "0.979", "size": "1712.47", "side": "BUY", "hash": "5d2c0eddcb566d3bbb9e90fa3b953bec64a8337a", "best_bid": "0.98", "best_ask": "0.981"}, {"asset_id": "87048058140607839077917415447158941112086606824479198286281986963033007181784", "price": "0.021", "size": "1712.47", "side": "SELL", "hash": "2d2c562534eed20b84c7fdf947f77d242e8c600e", "best_bid": "0.019", "best_ask": "0.02"}], "timestamp": "1769384027623", "event_type": "price_change"}}
{"_local_timestamp": "2026-01-25T23:33:47.746898+00:00", "data": {"market": "0xbcb33ad98c8141b10f2350ef687eddf0660484ecc15be42ecdae64339e64dce1", "price_changes": [{"asset_id": "105108334823274411453837752322302146951506166827237470954759784982159162094956", "price": "0.979", "size": "3017.6", "side": "BUY", "hash": "c95595357515db41f16d46a46794ba09b2afacd6", "best_bid": "0.98", "best_ask": "0.981"}, {"asset_id": "87048058140607839077917415447158941112086606824479198286281986963033007181784", "price": "0.021", "size": "3017.6", "side": "SELL", "hash": "8f0e31eb9955515cf1e0bbf90c4c10a09db766fd", "best_bid": "0.019", "best_ask": "0.02"}], "timestamp": "1769384027672", "event_type": "price_change"}}
{"_local_timestamp": "2026-01-25T23:33:47.993261+00:00", "data": {"market": "0xbcb33ad98c8141b10f2350ef687eddf0660484ecc15be42ecdae64339e64dce1", "price_changes": [{"asset_id": "105108334823274411453837752322302146951506166827237470954759784982159162094956", "price": "0.979", "size": "1712.47", "side": "BUY", "hash": "12fa585f2053c8c2d30c14f33542a5f776ee7b36", "best_bid": "0.98", "best_ask": "0.981"}, {"asset_id": "87048058140607839077917415447158941112086606824479198286281986963033007181784", "price": "0.021", "size": "1712.47", "side": "SELL", "hash": "17df54212b0c6db193c191883da439c8da9b3ff1", "best_bid": "0.019", "best_ask": "0.02"}], "timestamp": "1769384027898", "event_type": "price_change"}}
{"_local_timestamp": "2026-01-25T23:33:48.062975+00:00", "data": {"market": "0xbcb33ad98c8141b10f2350ef687eddf0660484ecc15be42ecdae64339e64dce1", "price_changes": [{"asset_id": "105108334823274411453837752322302146951506166827237470954759784982159162094956", "price": "0.979", "size": "3017.6", "side": "BUY", "hash": "caad55944e97aafe2e71b6f08869b72402e633fd", "best_bid": "0.98", "best_ask": "0.981"}, {"asset_id": "87048058140607839077917415447158941112086606824479198286281986963033007181784", "price": "0.021", "size": "3017.6", "side": "SELL", "hash": "62a5355ac2afc0aea56fa7e72c0d6069f5911825", "best_bid": "0.019", "best_ask": "0.02"}], "timestamp": "1769384027952", "event_type": "price_change"}}
{"_local_timestamp": "2026-01-25T23:33:48.230597+00:00", "data": {"market": "0xbcb33ad98c8141b10f2350ef687eddf0660484ecc15be42ecdae64339e64dce1", "price_changes": [{"asset_id": "105108334823274411453837752322302146951506166827237470954759784982159162094956", "price": "0.979", "size": "1712.47", "side": "BUY", "hash": "ecfd1dc10a64ab01738a3ec6df3347472d1b7c4e", "best_bid": "0.98", "best_ask": "0.981"}, {"asset_id": "87048058140607839077917415447158941112086606824479198286281986963033007181784", "price": "0.021", "size": "1712.47", "side": "SELL", "hash": "dad2f734ad32fc94c4a9ed0f6659c00ec0df3de5", "best_bid": "0.019", "best_ask": "0.02"}], "timestamp": "1769384028155", "event_type": "price_change"}}
{"_local_timestamp": "2026-01-25T23:33:48.379633+00:00", "data": {"market": "0xbcb33ad98c8141b10f2350ef687eddf0660484ecc15be42ecdae64339e64dce1", "price_changes": [{"asset_id": "105108334823274411453837752322302146951506166827237470954759784982159162094956", "price": "0.979", "size": "3017.6", "side": "BUY", "hash": "46c4ecaa2ebd06c58b291685eacddfb6c7ce383b", "best_bid": "0.98", "best_ask": "0.981"}, {"asset_id": "87048058140607839077917415447158941112086606824479198286281986963033007181784", "price": "0.021", "size": "3017.6", "side": "SELL", "hash": "ebdedd5858a3eab0e6b4b45140b99c64db0f0501", "best_bid": "0.019", "best_ask": "0.02"}], "timestamp": "1769384028307", "event_type": "price_change"}}
{"_local_timestamp": "2026-01-25T23:33:48.568331+00:00", "data": {"market": "0xbcb33ad98c8141b10f2350ef687eddf0660484ecc15be42ecdae64339e64dce1", "price_changes": [{"asset_id": "105108334823274411453837752322302146951506166827237470954759784982159162094956", "price": "0.979", "size": "1712.47", "side": "BUY", "hash": "e7d4fc2a7b1caf86217eee1e520ae9dedb1e7673", "best_bid": "0.98", "best_ask": "0.981"}, {"asset_id": "87048058140607839077917415447158941112086606824479198286281986963033007181784", "price": "0.021", "size": "1712.47", "side": "SELL", "hash": "d5a330a24aad458e3192d832263595f2cf2e870b", "best_bid": "0.019", "best_ask": "0.02"}], "timestamp": "1769384028498", "event_type": "price_change"}}
{"_local_timestamp": "2026-01-25T23:33:48.725753+00:00", "data": {"market": "0xbcb33ad98c8141b10f2350ef687eddf0660484ecc15be42ecdae64339e64dce1", "price_changes": [{"asset_id": "105108334823274411453837752322302146951506166827237470954759784982159162094956", "price": "0.979", "size": "3017.6", "side": "BUY", "hash": "3e53bee5ee7ca522baa4b0e7e151388fd15e9a8c", "best_bid": "0.98", "best_ask": "0.981"}, {"asset_id": "87048058140607839077917415447158941112086606824479198286281986963033007181784", "price": "0.021", "size": "3017.6", "side": "SELL", "hash": "c5d7ff4d878abd0b25e9272e5f3903833604f04e", "best_bid": "0.019", "best_ask": "0.02"}], "timestamp": "1769384028658", "event_type": "price_change"}}
{"_local_timestamp": "2026-01-25T23:33:48.911720+00:00", "data": {"market": "0xbcb33ad98c8141b10f2350ef687eddf0660484ecc15be42ecdae64339e64dce1", "price_changes": [{"asset_id": "105108334823274411453837752322302146951506166827237470954759784982159162094956", "price": "0.979", "size": "1712.47", "side": "BUY", "hash": "2a9687a6bf28b39f1389be6553323f82d9547ff4", "best_bid": "0.98", "best_ask": "0.981"}, {"asset_id": "87048058140607839077917415447158941112086606824479198286281986963033007181784", "price": "0.021", "size": "1712.47", "side": "SELL", "hash": "7e79c4d0b10119f263e1b1a013a68f0fa0e1f163", "best_bid": "0.019", "best_ask": "0.02"}], "timestamp": "1769384028839", "event_type": "price_change"}}
{"_local_timestamp": "2026-01-25T23:33:49.033477+00:00", "data": {"market": "0xbcb33ad98c8141b10f2350ef687eddf0660484ecc15be42ecdae64339e64dce1", "price_changes": [{"asset_id": "105108334823274411453837752322302146951506166827237470954759784982159162094956", "price": "0.979", "size": "3017.6", "side": "BUY", "hash": "1d5b88fc15d618e41bc3d15031ebf3a0333f8804", "best_bid": "0.98", "best_ask": "0.981"}, {"asset_id": "87048058140607839077917415447158941112086606824479198286281986963033007181784", "price": "0.021", "size": "3017.6", "side": "SELL", "hash": "9208eaf3acb22fb16c93498114292a4d14c6cfea", "best_bid": "0.019", "best_ask": "0.02"}], "timestamp": "1769384028958", "event_type": "price_change"}}
{"_local_timestamp": "2026-01-25T23:33:49.189336+00:00", "data": {"market": "0xbcb33ad98c8141b10f2350ef687eddf0660484ecc15be42ecdae64339e64dce1", "price_changes": [{"asset_id": "105108334823274411453837752322302146951506166827237470954759784982159162094956", "price": "0.979", "size": "1712.47", "side": "BUY", "hash": "f8850976a1d0c8c4a7585ace7ed4d5649159b4da", "best_bid": "0.98", "best_ask": "0.981"}, {"asset_id": "87048058140607839077917415447158941112086606824479198286281986963033007181784", "price": "0.021", "size": "1712.47", "side": "SELL", "hash": "2fa93e90ae7d91aacff197628f72002ce1b3b166", "best_bid": "0.019", "best_ask": "0.02"}], "timestamp": "1769384029122", "event_type": "price_change"}}
{"_local_timestamp": "2026-01-25T23:33:49.351728+00:00", "data": {"market": "0xbcb33ad98c8141b10f2350ef687eddf0660484ecc15be42ecdae64339e64dce1", "price_changes": [{"asset_id": "105108334823274411453837752322302146951506166827237470954759784982159162094956", "price": "0.979", "size": "3017.6", "side": "BUY", "hash": "5241e7360c1f9688467466cacf9cd304d09f4a5c", "best_bid": "0.98", "best_ask": "0.981"}, {"asset_id": "87048058140607839077917415447158941112086606824479198286281986963033007181784", "price": "0.021", "size": "3017.6", "side": "SELL", "hash": "3753f06d191f737b4e4b976219d460aebbbef96e", "best_bid": "0.019", "best_ask": "0.02"}], "timestamp": "1769384029268", "event_type": "price_change"}}
{"_local_timestamp": "2026-01-25T23:33:49.501407+00:00", "data": {"market": "0xbcb33ad98c8141b10f2350ef687eddf0660484ecc15be42ecdae64339e64dce1", "price_changes": [{"asset_id": "105108334823274411453837752322302146951506166827237470954759784982159162094956", "price": "0.979", "size": "1712.47", "side": "BUY", "hash": "26d37648b60889f0e0308c5313f473a2c44f1984", "best_bid": "0.98", "best_ask": "0.981"}, {"asset_id": "87048058140607839077917415447158941112086606824479198286281986963033007181784", "price": "0.021", "size": "1712.47", "side": "SELL", "hash": "8a5bad5e7c8b56699927f4d573db76199431320c", "best_bid": "0.019", "best_ask": "0.02"}], "timestamp": "1769384029431", "event_type": "price_change"}}
{"_local_timestamp": "2026-01-25T23:33:49.630456+00:00", "data": {"market": "0xbcb33ad98c8141b10f2350ef687eddf0660484ecc15be42ecdae64339e64dce1", "price_changes": [{"asset_id": "105108334823274411453837752322302146951506166827237470954759784982159162094956", "price": "0.979", "size": "3017.6", "side": "BUY", "hash": "77f68fa554201e751cf5e4d9ab1d9586dbf32062", "best_bid": "0.98", "best_ask": "0.981"}, {"asset_id": "87048058140607839077917415447158941112086606824479198286281986963033007181784", "price": "0.021", "size": "3017.6", "side": "SELL", "hash": "061f0bed3f2c17c14ad6b66c01d2fe1cc8304e96", "best_bid": "0.019", "best_ask": "0.02"}], "timestamp": "1769384029563", "event_type": "price_change"}}
{"_local_timestamp": "2026-01-25T23:33:49.818390+00:00", "data": {"market": "0xbcb33ad98c8141b10f2350ef687eddf0660484ecc15be42ecdae64339e64dce1", "price_changes": [{"asset_id": "105108334823274411453837752322302146951506166827237470954759784982159162094956", "price": "0.979", "size": "1712.47", "side": "BUY", "hash": "cc08e4e8ce14503c1644c6d3fae697252dcf0c59", "best_bid": "0.98", "best_ask": "0.981"}, {"asset_id": "87048058140607839077917415447158941112086606824479198286281986963033007181784", "price": "0.021", "size": "1712.47", "side": "SELL", "hash": "8c5869c15353d698e8b3e397a9ad4fb2c91ef2b1", "best_bid": "0.019", "best_ask": "0.02"}], "timestamp": "1769384029736", "event_type": "price_change"}}
{"_local_timestamp": "2026-01-25T23:33:49.891285+00:00", "data": {"market": "0xbcb33ad98c8141b10f2350ef687eddf0660484ecc15be42ecdae64339e64dce1", "price_changes": [{"asset_id": "105108334823274411453837752322302146951506166827237470954759784982159162094956", "price": "0.979", "size": "3017.6", "side": "BUY", "hash": "e0d8741b88b625a7c7613555b61a77687534349b", "best_bid": "0.98", "best_ask": "0.981"}, {"asset_id": "87048058140607839077917415447158941112086606824479198286281986963033007181784", "price": "0.021", "size": "3017.6", "side": "SELL", "hash": "7764d1b405e679d94489fdd9b080cd21f4efc19f", "best_bid": "0.019", "best_ask": "0.02"}], "timestamp": "1769384029823", "event_type": "price_change"}}
{"_local_timestamp": "2026-01-25T23:33:50.076728+00:00", "data": {"market": "0xbcb33ad98c8141b10f2350ef687eddf0660484ecc15be42ecdae64339e64dce1", "price_changes": [{"asset_id": "105108334823274411453837752322302146951506166827237470954759784982159162094956", "price": "0.979", "size": "1712.47", "side": "BUY", "hash": "f62b28ba69061ddf6d2abdea2f27792c9a4c9c09", "best_bid": "0.98", "best_ask": "0.981"}, {"asset_id": "87048058140607839077917415447158941112086606824479198286281986963033007181784", "price": "0.021", "size": "1712.47", "side": "SELL", "hash": "da2acb2e6700d4fb2fb17c27ce7018130aa29157", "best_bid": "0.019", "best_ask": "0.02"}], "timestamp": "1769384029996", "event_type": "price_change"}}
{"_local_timestamp": "2026-01-25T23:33:50.199128+00:00", "data": {"market": "0xbcb33ad98c8141b10f2350ef687eddf0660484ecc15be42ecdae64339e64dce1", "price_changes": [{"asset_id": "105108334823274411453837752322302146951506166827237470954759784982159162094956", "price": "0.979", "size": "3017.6", "side": "BUY", "hash": "8599732e75d47a07e05cdab0bcb0340b7c13bbbb", "best_bid": "0.98", "best_ask": "0.981"}, {"asset_id": "87048058140607839077917415447158941112086606824479198286281986963033007181784", "price": "0.021", "size": "3017.6", "side": "SELL", "hash": "8e3f8989ca889c366eafdef1e5667475d696b30b", "best_bid": "0.019", "best_ask": "0.02"}], "timestamp": "1769384030129", "event_type": "price_change"}}
{"_local_timestamp": "2026-01-25T23:33:57.130702+00:00", "data": {"market": "0xbcb33ad98c8141b10f2350ef687eddf0660484ecc15be42ecdae64339e64dce1", "price_changes": [{"asset_id": "105108334823274411453837752322302146951506166827237470954759784982159162094956", "price": "0.978", "size": "3048.43", "side": "BUY", "hash": "1f555a020bec08ccde0ebe384fe9131d9e89bba3", "best_bid": "0.98", "best_ask": "0.981"}, {"asset_id": "87048058140607839077917415447158941112086606824479198286281986963033007181784", "price": "0.022", "size": "3048.43", "side": "SELL", "hash": "508c42c5f7b468b98595770a57ff43bd8d37798d", "best_bid": "0.019", "best_ask": "0.02"}], "timestamp": "1769384037033", "event_type": "price_change"}}
{"_local_timestamp": "2026-01-25T23:33:57.131452+00:00", "data": {"market": "0xbcb33ad98c8141b10f2350ef687eddf0660484ecc15be42ecdae64339e64dce1", "price_changes": [{"asset_id": "87048058140607839077917415447158941112086606824479198286281986963033007181784", "price": "0.005", "size": "1629.24", "side": "BUY", "hash": "3e0d91039174c798c3e6051753df1acc8edf8323", "best_bid": "0.019", "best_ask": "0.02"}, {"asset_id": "105108334823274411453837752322302146951506166827237470954759784982159162094956", "price": "0.995", "size": "1629.24", "side": "SELL", "hash": "29b06b50dc0f9e4bc62b768ab670c46e7d11763c", "best_bid": "0.98", "best_ask": "0.981"}], "timestamp": "1769384037034", "event_type": "price_change"}}
{"_local_timestamp": "2026-01-25T23:33:57.457989+00:00", "data": {"market": "0xbcb33ad98c8141b10f2350ef687eddf0660484ecc15be42ecdae64339e64dce1", "price_changes": [{"asset_id": "105108334823274411453837752322302146951506166827237470954759784982159162094956", "price": "0.979", "size": "1712.47", "side": "BUY", "hash": "cac6fd6e854dc946d87c137948fcb332bd2a1fcf", "best_bid": "0.98", "best_ask": "0.981"}, {"asset_id": "87048058140607839077917415447158941112086606824479198286281986963033007181784", "price": "0.021", "size": "1712.47", "side": "SELL", "hash": "57071571d911590a0c47d70829c905df11da0f0a", "best_bid": "0.019", "best_ask": "0.02"}], "timestamp": "1769384037390", "event_type": "price_change"}}
{"_local_timestamp": "2026-01-25T23:33:57.595081+00:00", "data": {"market": "0xbcb33ad98c8141b10f2350ef687eddf0660484ecc15be42ecdae64339e64dce1", "price_changes": [{"asset_id": "105108334823274411453837752322302146951506166827237470954759784982159162094956", "price": "0.979", "size": "3017.6", "side": "BUY", "hash": "3bac802990042f5ec227f708b351e9d8f959336a", "best_bid": "0.98", "best_ask": "0.981"}, {"asset_id": "87048058140607839077917415447158941112086606824479198286281986963033007181784", "price": "0.021", "size": "3017.6", "side": "SELL", "hash": "b60091640e7d704abf82aa1670f702d189ec21a4", "best_bid": "0.019", "best_ask": "0.02"}], "timestamp": "1769384037522", "event_type": "price_change"}}
{"_local_timestamp": "2026-01-25T23:34:04.462693+00:00", "data": {"market": "0xa062dea464f0e8fc3381176494198cf45574ec190eca77a40f49988320fa15f2", "price_changes": [{"asset_id": "16754375222233973989954094649431109282368408854808102040230156977754673841406", "price": "0.962", "size": "11883.12", "side": "BUY", "hash": "e44b083eb318dcdbfa5fcca6e2e7aa7dfd435a63", "best_bid": "0.98", "best_ask": "0.981"}, {"asset_id": "2941656641529467089826910607945793276058581543804243973571467775773698944388", "price": "0.038", "size": "11883.12", "side": "SELL", "hash": "212111416cc7d9b2ab9f275b2fb47613c7e87061", "best_bid": "0.019", "best_ask": "0.02"}], "timestamp": "1769384044384", "event_type": "price_change"}}
{"_local_timestamp": "2026-01-25T23:34:04.463774+00:00", "data": {"market": "0xa062dea464f0e8fc3381176494198cf45574ec190eca77a40f49988320fa15f2", "price_changes": [{"asset_id": "16754375222233973989954094649431109282368408854808102040230156977754673841406", "price": "0.991", "size": "2014.08", "side": "SELL", "hash": "e44b083eb318dcdbfa5fcca6e2e7aa7dfd435a63", "best_bid": "0.98", "best_ask": "0.981"}, {"asset_id": "2941656641529467089826910607945793276058581543804243973571467775773698944388", "price": "0.009", "size": "2014.08", "side": "BUY", "hash": "212111416cc7d9b2ab9f275b2fb47613c7e87061", "best_bid": "0.019", "best_ask": "0.02"}], "timestamp": "1769384044384", "event_type": "price_change"}}
{"_local_timestamp": "2026-01-25T23:34:04.798611+00:00", "data": {"market": "0xbcb33ad98c8141b10f2350ef687eddf0660484ecc15be42ecdae64339e64dce1", "price_changes": [{"asset_id": "105108334823274411453837752322302146951506166827237470954759784982159162094956", "price": "0.979", "size": "1712.47", "side": "BUY", "hash": "4bfcc2017065e17aa240be3489dc309bdc727444", "best_bid": "0.98", "best_ask": "0.981"}, {"asset_id": "87048058140607839077917415447158941112086606824479198286281986963033007181784", "price": "0.021", "size": "1712.47", "side": "SELL", "hash": "3dfeb17c3f65d26be32fef6ce794412a3a2ca1d4", "best_bid": "0.019", "best_ask": "0.02"}], "timestamp": "1769384044719", "event_type": "price_change"}}
{"_local_timestamp": "2026-01-25T23:34:04.918078+00:00", "data": {"market": "0x28101208d1076b3dc8fca84aeebe55cc8505b01f40c8e1d5c5fa3209cc395120", "price_changes": [{"asset_id": "58747865919172231095011168471546530760273932108399756901651325449763346350897", "price": "0.959", "size": "0", "side": "BUY", "hash": "c66dd7fb0fe7cde280244d785bf09537b5c6ab31", "best_bid": "0.999", "best_ask": "1"}, {"asset_id": "114268099239767676216932072226652369234485747669785862612893982920970460896563", "price": "0.041", "size": "0", "side": "SELL", "hash": "78478cefb5bd24b1ec7f6f10c218910d9bda4b9f", "best_bid": "0", "best_ask": "0.001"}], "timestamp": "1769384044837", "event_type": "price_change"}}
{"_local_timestamp": "2026-01-25T23:34:04.926825+00:00", "data": {"market": "0xbcb33ad98c8141b10f2350ef687eddf0660484ecc15be42ecdae64339e64dce1", "price_changes": [{"asset_id": "105108334823274411453837752322302146951506166827237470954759784982159162094956", "price": "0.979", "size": "3017.6", "side": "BUY", "hash": "a259405cd602695239fc688668f1658d4578c193", "best_bid": "0.98", "best_ask": "0.981"}, {"asset_id": "87048058140607839077917415447158941112086606824479198286281986963033007181784", "price": "0.021", "size": "3017.6", "side": "SELL", "hash": "0da77010da3c9e72b929181f60ac427cb7f7f18d", "best_bid": "0.019", "best_ask": "0.02"}], "timestamp": "1769384044841", "event_type": "price_change"}}
{"_local_timestamp": "2026-01-25T23:34:05.155499+00:00", "data": {"market": "0x28101208d1076b3dc8fca84aeebe55cc8505b01f40c8e1d5c5fa3209cc395120", "price_changes": [{"asset_id": "58747865919172231095011168471546530760273932108399756901651325449763346350897", "price": "0.962", "size": "20", "side": "BUY", "hash": "d7c06cd11f9f561c04e3a7272463ecfcde876403", "best_bid": "0.999", "best_ask": "1"}, {"asset_id": "114268099239767676216932072226652369234485747669785862612893982920970460896563", "price": "0.038", "size": "20", "side": "SELL", "hash": "a4973353492ac42d2745e28d1130e3f704b2920e", "best_bid": "0", "best_ask": "0.001"}], "timestamp": "1769384045005", "event_type": "price_change"}}
{"_local_timestamp": "2026-01-25T23:34:05.187160+00:00", "data": {"market": "0xbcb33ad98c8141b10f2350ef687eddf0660484ecc15be42ecdae64339e64dce1", "price_changes": [{"asset_id": "105108334823274411453837752322302146951506166827237470954759784982159162094956", "price": "0.979", "size": "1712.47", "side": "BUY", "hash": "5940556530d3c80929aa1c2b2de39a3ab06f150a", "best_bid": "0.98", "best_ask": "0.981"}, {"asset_id": "87048058140607839077917415447158941112086606824479198286281986963033007181784", "price": "0.021", "size": "1712.47", "side": "SELL", "hash": "8f64686b3ade952062f351ee1a9a615f18155ca7", "best_bid": "0.019", "best_ask": "0.02"}], "timestamp": "1769384045032", "event_type": "price_change"}}
{"_local_timestamp": "2026-01-25T23:34:05.195721+00:00", "data": {"market": "0x1a550f4be5469a1f7f19a6a87eb1d3c5aee638dd4b325cd7e80c94fcb69a4325", "price_changes": [{"asset_id": "100299191321741533544964863678141476981783881954596444647911413684277151596082", "price": "0.94", "size": "0", "side": "BUY", "hash": "9f7bd166045030c35ea5d11440bfcc86e14125cb", "best_bid": "0.999", "best_ask": "1"}, {"asset_id": "15849160483277897689949967085542532873284061361999325893867258022262592692821", "price": "0.06", "size": "0", "side": "SELL", "hash": "1dd989f0e25099728c96ab4b527e228d9dd92e51", "best_bid": "0", "best_ask": "0.001"}], "timestamp": "1769384045046", "event_type": "price_change"}}
{"_local_timestamp": "2026-01-25T23:34:05.240799+00:00", "data": {"market": "0xbcb33ad98c8141b10f2350ef687eddf0660484ecc15be42ecdae64339e64dce1", "price_changes": [{"asset_id": "105108334823274411453837752322302146951506166827237470954759784982159162094956", "price": "0.979", "size": "3017.6", "side": "BUY", "hash": "dd657e73c6ac638377346367064b559c5888b81f", "best_bid": "0.98", "best_ask": "0.981"}, {"asset_id": "87048058140607839077917415447158941112086606824479198286281986963033007181784", "price": "0.021", "size": "3017.6", "side": "SELL", "hash": "686ebb99e810aec06e21cdc4026552b812afac7e", "best_bid": "0.019", "best_ask": "0.02"}], "timestamp": "1769384045109", "event_type": "price_change"}}
{"_local_timestamp": "2026-01-25T23:34:05.271463+00:00", "data": {"market": "0xc9dc3221d327cdca2401a80e8b138e6f81e17e7aabb0ae4915ec744e37d89fb9", "price_changes": [{"asset_id": "48766341308125246446934576208296715790150929628230476623094742688581948013790", "price": "0.989", "size": "13.33", "side": "BUY", "hash": "3457ec5f01ec14f7883e82b1e624260c3d659465", "best_bid": "0.999", "best_ask": "1"}, {"asset_id": "30832134873051915510376997713155047909911899948937112157265655376345456505246", "price": "0.011", "size": "13.33", "side": "SELL", "hash": "61cd21077f123af57ec680e432bc7852960ff7c4", "best_bid": "0", "best_ask": "0.001"}], "timestamp": "1769384045171", "event_type": "price_change"}}
{"_local_timestamp": "2026-01-25T23:34:05.383375+00:00", "data": {"market": "0xc9dc3221d327cdca2401a80e8b138e6f81e17e7aabb0ae4915ec744e37d89fb9", "price_changes": [{"asset_id": "48766341308125246446934576208296715790150929628230476623094742688581948013790", "price": "0.99", "size": "20", "side": "BUY", "hash": "5eb5c58c162ddb7e13158c010ec838594713cbff", "best_bid": "0.999", "best_ask": "1"}, {"asset_id": "30832134873051915510376997713155047909911899948937112157265655376345456505246", "price": "0.01", "size": "20", "side": "SELL", "hash": "313e8325ff67dccf03ed79b60ce988f31bb08cab", "best_bid": "0", "best_ask": "0.001"}], "timestamp": "1769384045302", "event_type": "price_change"}}
{"_local_timestamp": "2026-01-25T23:34:05.385144+00:00", "data": {"market": "0x1a550f4be5469a1f7f19a6a87eb1d3c5aee638dd4b325cd7e80c94fcb69a4325", "price_changes": [{"asset_id": "100299191321741533544964863678141476981783881954596444647911413684277151596082", "price": "0.943", "size": "20", "side": "BUY", "hash": "3c0d5d2782d035633d4d3dcb1d4458cb9e842b2e", "best_bid": "0.999", "best_ask": "1"}, {"asset_id": "15849160483277897689949967085542532873284061361999325893867258022262592692821", "price": "0.057", "size": "20", "side": "SELL", "hash": "2319c4eb35f4394095de3561b01822a6e2d22be6", "best_bid": "0", "best_ask": "0.001"}], "timestamp": "1769384045303", "event_type": "price_change"}}
{"_local_timestamp": "2026-01-25T23:34:05.385494+00:00", "data": {"market": "0xbcb33ad98c8141b10f2350ef687eddf0660484ecc15be42ecdae64339e64dce1", "price_changes": [{"asset_id": "105108334823274411453837752322302146951506166827237470954759784982159162094956", "price": "0.979", "size": "1712.47", "side": "BUY", "hash": "7f1d707c0734c99128af03190e370477871cdee2", "best_bid": "0.98", "best_ask": "0.981"}, {"asset_id": "87048058140607839077917415447158941112086606824479198286281986963033007181784", "price": "0.021", "size": "1712.47", "side": "SELL", "hash": "60efc095aab605ab1df63339cbfd19f19b53a18c", "best_bid": "0.019", "best_ask": "0.02"}], "timestamp": "1769384045309", "event_type": "price_change"}}
{"_local_timestamp": "2026-01-25T23:34:05.417298+00:00", "data": {"market": "0x18b1dc1565575cb2ff48bbc078070170ca3278691860cca7c97131fc657a9530", "price_changes": [{"asset_id": "94238513083578948523157790197851186920885838535648691968842196265124859609799", "price": "0.97", "size": "0", "side": "BUY", "hash": "4aafdbb6d6b58a245f14d7711c8257976d5a4905", "best_bid": "0.999", "best_ask": "1"}, {"asset_id": "62947063083572838306765336947158511397004781598875199570718451493234069599112", "price": "0.03", "size": "0", "side": "SELL", "hash": "2ef8986a629d081674b0ac25b769f8da54a9fa8f", "best_bid": "0", "best_ask": "0.001"}], "timestamp": "1769384045341", "event_type": "price_change"}}
{"_local_timestamp": "2026-01-25T23:34:05.463602+00:00", "data": {"market": "0xbcb33ad98c8141b10f2350ef687eddf0660484ecc15be42ecdae64339e64dce1", "price_changes": [{"asset_id": "105108334823274411453837752322302146951506166827237470954759784982159162094956", "price": "0.979", "size": "3017.6", "side": "BUY", "hash": "2d4897c6586b3c2605ac5c46a967e90edb6db220", "best_bid": "0.98", "best_ask": "0.981"}, {"asset_id": "87048058140607839077917415447158941112086606824479198286281986963033007181784", "price": "0.021", "size": "3017.6", "side": "SELL", "hash": "93523142547a1dba1b0d464c3b00c9e9b0f64394", "best_bid": "0.019", "best_ask": "0.02"}], "timestamp": "1769384045393", "event_type": "price_change"}}
{"_local_timestamp": "2026-01-25T23:34:05.522897+00:00", "data": {"market": "0x18b1dc1565575cb2ff48bbc078070170ca3278691860cca7c97131fc657a9530", "price_changes": [{"asset_id": "94238513083578948523157790197851186920885838535648691968842196265124859609799", "price": "0.972", "size": "20", "side": "BUY", "hash": "5144a348bb7c3ef359d0066779ba9577b789562e", "best_bid": "0.999", "best_ask": "1"}, {"asset_id": "62947063083572838306765336947158511397004781598875199570718451493234069599112", "price": "0.028", "size": "20", "side": "SELL", "hash": "4e1435479c2d667d38176044b1bd55464e6bedac", "best_bid": "0", "best_ask": "0.001"}], "timestamp": "1769384045452", "event_type": "price_change"}}
{"_local_timestamp": "2026-01-25T23:34:05.578974+00:00", "data": {"market": "0x0bdf73e4f9d1f9bddd76011f7c7f70ac2a7bf02858f6e724ff17fab39cdb84aa", "price_changes": [{"asset_id": "44060160461153155780840707322998889704290849153451415562546100515099098148308", "price": "0.974", "size": "0", "side": "BUY", "hash": "40f402745c00bebbdd0539c24373ad3ca89eaf8c", "best_bid": "0.999", "best_ask": "1"}, {"asset_id": "91026359419320379024878691909394517154461461579031366036356847269582766989758", "price": "0.026", "size": "0", "side": "SELL", "hash": "ec272f306a2f5555353b6d1831deab3c559981fa", "best_bid": "0", "best_ask": "0.001"}], "timestamp": "1769384045510", "event_type": "price_change"}}
{"_local_timestamp": "2026-01-25T23:34:05.579376+00:00", "data": {"market": "0x1d5827b0448938c4c40a1c6747abc61e4ff690ac3d7306e0690c1741eb6dcb0b", "price_changes": [{"asset_id": "50298286906716199010522025175676678342201745398212393361362499308691655626332", "price": "0.989", "size": "13.33", "side": "BUY", "hash": "6a2897edefd7888ec6213017e6df05fd731a5d90", "best_bid": "0.999", "best_ask": "1"}, {"asset_id": "12066144173721960949299167133110175689689620950083050321772650546514468891687", "price": "0.011", "size": "13.33", "side": "SELL", "hash": "4dc4980d1391a941e43fe891223071889c20d784", "best_bid": "0", "best_ask": "0.001"}], "timestamp": "1769384045510", "event_type": "price_change"}}
{"_local_timestamp": "2026-01-25T23:34:05.667460+00:00", "data": {"market": "0xbcb33ad98c8141b10f2350ef687eddf0660484ecc15be42ecdae64339e64dce1", "price_changes": [{"asset_id": "105108334823274411453837752322302146951506166827237470954759784982159162094956", "price": "0.979", "size": "1712.47", "side": "BUY", "hash": "1765fbfb59b379289cf6891411f67dbb66d78a13", "best_bid": "0.98", "best_ask": "0.981"}, {"asset_id": "87048058140607839077917415447158941112086606824479198286281986963033007181784", "price": "0.021", "size": "1712.47", "side": "SELL", "hash": "cb061929dbf8cd6656ced8c692e042e1e85f717e", "best_bid": "0.019", "best_ask": "0.02"}], "timestamp": "1769384045596", "event_type": "price_change"}}
{"_local_timestamp": "2026-01-25T23:34:05.671639+00:00", "data": {"market": "0x0bdf73e4f9d1f9bddd76011f7c7f70ac2a7bf02858f6e724ff17fab39cdb84aa", "price_changes": [{"asset_id": "44060160461153155780840707322998889704290849153451415562546100515099098148308", "price": "0.976", "size": "20", "side": "BUY", "hash": "7a60dc5221ec645076bc47fd55e5ea7cf884e5d3", "best_bid": "0.999", "best_ask": "1"}, {"asset_id": "91026359419320379024878691909394517154461461579031366036356847269582766989758", "price": "0.024", "size": "20", "side": "SELL", "hash": "9cef6fa598c05aef5cdc51a96db57f02be54b2ab", "best_bid": "0", "best_ask": "0.001"}], "timestamp": "1769384045601", "event_type": "price_change"}}
{"_local_timestamp": "2026-01-25T23:34:05.672012+00:00", "data": {"market": "0x1d5827b0448938c4c40a1c6747abc61e4ff690ac3d7306e0690c1741eb6dcb0b", "price_changes": [{"asset_id": "50298286906716199010522025175676678342201745398212393361362499308691655626332", "price": "0.99", "size": "20", "side": "BUY", "hash": "bd8b2183e5f8c6d8f9cc415d7217e8911a5be4a9", "best_bid": "0.999", "best_ask": "1"}, {"asset_id": "12066144173721960949299167133110175689689620950083050321772650546514468891687", "price": "0.01", "size": "20", "side": "SELL", "hash": "33b8d7d2eabdf264257caaebf3bf4879a14ca140", "best_bid": "0", "best_ask": "0.001"}], "timestamp": "1769384045601", "event_type": "price_change"}}
{"_local_timestamp": "2026-01-25T23:34:19.700407+00:00", "data": {"market": "0xa062dea464f0e8fc3381176494198cf45574ec190eca77a40f49988320fa15f2", "price_changes": [{"asset_id": "16754375222233973989954094649431109282368408854808102040230156977754673841406", "price": "0.991", "size": "14514.08", "side": "SELL", "hash": "0ef7864940e2a740507c1c84cf16c81109c0c526", "best_bid": "0.98", "best_ask": "0.981"}, {"asset_id": "2941656641529467089826910607945793276058581543804243973571467775773698944388", "price": "0.009", "size": "14514.08", "side": "BUY", "hash": "fc8921203362e0d8540ab197b8b2ce447149e19f", "best_bid": "0.019", "best_ask": "0.02"}], "timestamp": "1769384059624", "event_type": "price_change"}}
{"_local_timestamp": "2026-01-25T23:34:19.704306+00:00", "data": {"market": "0xa062dea464f0e8fc3381176494198cf45574ec190eca77a40f49988320fa15f2", "price_changes": [{"asset_id": "16754375222233973989954094649431109282368408854808102040230156977754673841406", "price": "0.962", "size": "19413.12", "side": "BUY", "hash": "1d709c0424433cf5e2165ebb2ef707695226a7df", "best_bid": "0.98", "best_ask": "0.981"}, {"asset_id": "2941656641529467089826910607945793276058581543804243973571467775773698944388", "price": "0.038", "size": "19413.12", "side": "SELL", "hash": "f5b3d5ef6517f7994ac3a8a06013cab5877d9275", "best_bid": "0.019", "best_ask": "0.02"}], "timestamp": "1769384059626", "event_type": "price_change"}}
{"_local_timestamp": "2026-01-25T23:34:19.752464+00:00", "data": {"market": "0xbcb33ad98c8141b10f2350ef687eddf0660484ecc15be42ecdae64339e64dce1", "price_changes": [{"asset_id": "105108334823274411453837752322302146951506166827237470954759784982159162094956", "price": "0.979", "size": "3017.6", "side": "BUY", "hash": "674182175c3010541f9910deb9e2e73693a06afc", "best_bid": "0.98", "best_ask": "0.981"}, {"asset_id": "87048058140607839077917415447158941112086606824479198286281986963033007181784", "price": "0.021", "size": "3017.6", "side": "SELL", "hash": "de2ff4bbf7d3951e49a262bedc26e35fafab98ef", "best_bid": "0.019", "best_ask": "0.02"}], "timestamp": "1769384059675", "event_type": "price_change"}}
{"_local_timestamp": "2026-01-25T23:34:19.947855+00:00", "data": {"market": "0xbcb33ad98c8141b10f2350ef687eddf0660484ecc15be42ecdae64339e64dce1", "price_changes": [{"asset_id": "105108334823274411453837752322302146951506166827237470954759784982159162094956", "price": "0.979", "size": "1712.47", "side": "BUY", "hash": "6b6af7bbb39457ce49959ba4a9d2699b2a9b01b2", "best_bid": "0.98", "best_ask": "0.981"}, {"asset_id": "87048058140607839077917415447158941112086606824479198286281986963033007181784", "price": "0.021", "size": "1712.47", "side": "SELL", "hash": "28a1717d513a1eb555120daf45306805bde5a24f", "best_bid": "0.019", "best_ask": "0.02"}], "timestamp": "1769384059868", "event_type": "price_change"}}
{"_local_timestamp": "2026-01-25T23:34:20.001949+00:00", "data": {"market": "0xbcb33ad98c8141b10f2350ef687eddf0660484ecc15be42ecdae64339e64dce1", "price_changes": [{"asset_id": "105108334823274411453837752322302146951506166827237470954759784982159162094956", "price": "0.979", "size": "3017.6", "side": "BUY", "hash": "fb9ce5431dc500db1e2dc60ed82b72b618094a47", "best_bid": "0.98", "best_ask": "0.981"}, {"asset_id": "87048058140607839077917415447158941112086606824479198286281986963033007181784", "price": "0.021", "size": "3017.6", "side": "SELL", "hash": "e5c25704eee1418a9f7c59fdb72736effadc5b6c", "best_bid": "0.019", "best_ask": "0.02"}], "timestamp": "1769384059927", "event_type": "price_change"}}
{"_local_timestamp": "2026-01-25T23:34:20.177320+00:00", "data": {"market": "0xbcb33ad98c8141b10f2350ef687eddf0660484ecc15be42ecdae64339e64dce1", "price_changes": [{"asset_id": "105108334823274411453837752322302146951506166827237470954759784982159162094956", "price": "0.979", "size": "1712.47", "side": "BUY", "hash": "a3d2dcdbcf446de75e363b055b0abe4d777ed349", "best_bid": "0.98", "best_ask": "0.981"}, {"asset_id": "87048058140607839077917415447158941112086606824479198286281986963033007181784", "price": "0.021", "size": "1712.47", "side": "SELL", "hash": "651f0613180726e7b29f4b08ec46c409bc39822b", "best_bid": "0.019", "best_ask": "0.02"}], "timestamp": "1769384060099", "event_type": "price_change"}}
{"_local_timestamp": "2026-01-25T23:34:20.401181+00:00", "data": {"market": "0xbcb33ad98c8141b10f2350ef687eddf0660484ecc15be42ecdae64339e64dce1", "price_changes": [{"asset_id": "105108334823274411453837752322302146951506166827237470954759784982159162094956", "price": "0.979", "size": "3017.6", "side": "BUY", "hash": "5af4feb20b78007645ee32ff7478ecb9218f178a", "best_bid": "0.98", "best_ask": "0.981"}, {"asset_id": "87048058140607839077917415447158941112086606824479198286281986963033007181784", "price": "0.021", "size": "3017.6", "side": "SELL", "hash": "2ced48c08c58ccfe4c075e491837cc0f82e4a476", "best_bid": "0.019", "best_ask": "0.02"}], "timestamp": "1769384060332", "event_type": "price_change"}}
{"_local_timestamp": "2026-01-25T23:34:20.527838+00:00", "data": {"market": "0xbcb33ad98c8141b10f2350ef687eddf0660484ecc15be42ecdae64339e64dce1", "price_changes": [{"asset_id": "105108334823274411453837752322302146951506166827237470954759784982159162094956", "price": "0.979", "size": "1712.47", "side": "BUY", "hash": "08b361d8d2b04feb59f9778782039ba934e9f373", "best_bid": "0.98", "best_ask": "0.981"}, {"asset_id": "87048058140607839077917415447158941112086606824479198286281986963033007181784", "price": "0.021", "size": "1712.47", "side": "SELL", "hash": "2df89e7fdef4f1ae18bac8abd8995e4f67e3fb60", "best_bid": "0.019", "best_ask": "0.02"}], "timestamp": "1769384060459", "event_type": "price_change"}}
{"_local_timestamp": "2026-01-25T23:34:20.672358+00:00", "data": {"market": "0xbcb33ad98c8141b10f2350ef687eddf0660484ecc15be42ecdae64339e64dce1", "price_changes": [{"asset_id": "105108334823274411453837752322302146951506166827237470954759784982159162094956", "price": "0.979", "size": "3017.6", "side": "BUY", "hash": "6a78c0dc723c1047c68d942af4156bf1395db9ab", "best_bid": "0.98", "best_ask": "0.981"}, {"asset_id": "87048058140607839077917415447158941112086606824479198286281986963033007181784", "price": "0.021", "size": "3017.6", "side": "SELL", "hash": "4cc2ef5a67f9df73036ebe79c7145434937344c3", "best_bid": "0.019", "best_ask": "0.02"}], "timestamp": "1769384060606", "event_type": "price_change"}}
{"_local_timestamp": "2026-01-25T23:34:20.726413+00:00", "data": {"market": "0xdcf89266de269fa8d785c5a6218c482f08cf26f9987d879fc97d6a335238a08c", "price_changes": [{"asset_id": "18180536855858852221205988991865712966455254452005023897135830094334125653819", "price": "0.988", "size": "13.33", "side": "BUY", "hash": "bad6f065da40e6f15388e8d315e3d81946235189", "best_bid": "0.999", "best_ask": "1"}, {"asset_id": "80955738350011048477695041166314820890097312693648599864162887413862093761380", "price": "0.012", "size": "13.33", "side": "SELL", "hash": "1a6dbd4ccdc57abea79550c1c7ec69517e0faca2", "best_bid": "0", "best_ask": "0.001"}], "timestamp": "1769384060656", "event_type": "price_change"}}
{"_local_timestamp": "2026-01-25T23:34:20.829055+00:00", "data": {"market": "0xdcf89266de269fa8d785c5a6218c482f08cf26f9987d879fc97d6a335238a08c", "price_changes": [{"asset_id": "18180536855858852221205988991865712966455254452005023897135830094334125653819", "price": "0.989", "size": "20", "side": "BUY", "hash": "7c3cfd1889420efb0bddb3959fef57cbb9dce7c9", "best_bid": "0.999", "best_ask": "1"}, {"asset_id": "80955738350011048477695041166314820890097312693648599864162887413862093761380", "price": "0.011", "size": "20", "side": "SELL", "hash": "3e762814f61264adead49911aaf47bc500315fd8", "best_bid": "0", "best_ask": "0.001"}], "timestamp": "1769384060759", "event_type": "price_change"}}
{"_local_timestamp": "2026-01-25T23:34:20.837438+00:00", "data": {"market": "0xbcb33ad98c8141b10f2350ef687eddf0660484ecc15be42ecdae64339e64dce1", "price_changes": [{"asset_id": "105108334823274411453837752322302146951506166827237470954759784982159162094956", "price": "0.979", "size": "1712.47", "side": "BUY", "hash": "5aca07d58a37af22d901f13ad102d3fd7c2cd561", "best_bid": "0.98", "best_ask": "0.981"}, {"asset_id": "87048058140607839077917415447158941112086606824479198286281986963033007181784", "price": "0.021", "size": "1712.47", "side": "SELL", "hash": "9d226f65ba78d7cc47d4718ef8835bccfad4bdc3", "best_bid": "0.019", "best_ask": "0.02"}], "timestamp": "1769384060768", "event_type": "price_change"}}
{"_local_timestamp": "2026-01-25T23:34:21.045883+00:00", "data": {"market": "0x87fa1d0200cae34d1abb2796b73a23a0434cef9eae9af694382d2ff63fec804a", "price_changes": [{"asset_id": "51552111503944829866957429954767286242387279354724573276882383824103379248961", "price": "0.251", "size": "0", "side": "BUY", "hash": "cd296cfaddee7eb5b7fce17acc59ce75fc8ad335", "best_bid": "0.999", "best_ask": "1"}, {"asset_id": "106678246482354893181601985328926429443842114194215732770784063273593452051663", "price": "0.749", "size": "0", "side": "SELL", "hash": "a85cb3ff2d02eacb85911f743f13a040a9759c92", "best_bid": "0", "best_ask": "0.001"}], "timestamp": "1769384060974", "event_type": "price_change"}}
{"_local_timestamp": "2026-01-25T23:34:21.113795+00:00", "data": {"market": "0x87fa1d0200cae34d1abb2796b73a23a0434cef9eae9af694382d2ff63fec804a", "price_changes": [{"asset_id": "51552111503944829866957429954767286242387279354724573276882383824103379248961", "price": "0.251", "size": "7", "side": "BUY", "hash": "d4e11c6bf3929b7a4cd9d314ae9fc80550f44a43", "best_bid": "0.999", "best_ask": "1"}, {"asset_id": "106678246482354893181601985328926429443842114194215732770784063273593452051663", "price": "0.749", "size": "7", "side": "SELL", "hash": "0213a773335d39d6819238a593e8589a2803981c", "best_bid": "0", "best_ask": "0.001"}], "timestamp": "1769384061029", "event_type": "price_change"}}
{"_local_timestamp": "2026-01-25T23:34:26.865552+00:00", "data": {"market": "0xa062dea464f0e8fc3381176494198cf45574ec190eca77a40f49988320fa15f2", "price_changes": [{"asset_id": "16754375222233973989954094649431109282368408854808102040230156977754673841406", "price": "0.991", "size": "2014.08", "side": "SELL", "hash": "4e93be3c75f36978ef601045737e1d8851f7120b", "best_bid": "0.98", "best_ask": "0.981"}, {"asset_id": "2941656641529467089826910607945793276058581543804243973571467775773698944388", "price": "0.009", "size": "2014.08", "side": "BUY", "hash": "efb41c6a628a92e0555550315fc6239b0b85d2df", "best_bid": "0.019", "best_ask": "0.02"}], "timestamp": "1769384066782", "event_type": "price_change"}}
{"_local_timestamp": "2026-01-25T23:34:26.866120+00:00", "data": {"market": "0xa062dea464f0e8fc3381176494198cf45574ec190eca77a40f49988320fa15f2", "price_changes": [{"asset_id": "16754375222233973989954094649431109282368408854808102040230156977754673841406", "price": "0.962", "size": "11883.12", "side": "BUY", "hash": "4e93be3c75f36978ef601045737e1d8851f7120b", "best_bid": "0.98", "best_ask": "0.981"}, {"asset_id": "2941656641529467089826910607945793276058581543804243973571467775773698944388", "price": "0.038", "size": "11883.12", "side": "SELL", "hash": "efb41c6a628a92e0555550315fc6239b0b85d2df", "best_bid": "0.019", "best_ask": "0.02"}], "timestamp": "1769384066782", "event_type": "price_change"}}
{"_local_timestamp": "2026-01-25T23:34:26.899652+00:00", "data": {"market": "0xbcb33ad98c8141b10f2350ef687eddf0660484ecc15be42ecdae64339e64dce1", "price_changes": [{"asset_id": "105108334823274411453837752322302146951506166827237470954759784982159162094956", "price": "0.979", "size": "2930.95", "side": "BUY", "hash": "704f9e70c07bdaf6e0ff078cebeaf7ef3f3812ad", "best_bid": "0.98", "best_ask": "0.981"}, {"asset_id": "87048058140607839077917415447158941112086606824479198286281986963033007181784", "price": "0.021", "size": "2930.95", "side": "SELL", "hash": "e02bc6f92ab9fd5a4d1f7e3c336e21b30c9d5e23", "best_bid": "0.019", "best_ask": "0.02"}], "timestamp": "1769384066831", "event_type": "price_change"}}
{"_local_timestamp": "2026-01-25T23:34:27.270624+00:00", "data": {"market": "0xbcb33ad98c8141b10f2350ef687eddf0660484ecc15be42ecdae64339e64dce1", "price_changes": [{"asset_id": "105108334823274411453837752322302146951506166827237470954759784982159162094956", "price": "0.979", "size": "1712.47", "side": "BUY", "hash": "bd1a33ffbfe10ed6c452ad83cc369ae2e02eb916", "best_bid": "0.98", "best_ask": "0.981"}, {"asset_id": "87048058140607839077917415447158941112086606824479198286281986963033007181784", "price": "0.021", "size": "1712.47", "side": "SELL", "hash": "0784d159096640d0afa052fc0780bbd0180ef214", "best_bid": "0.019", "best_ask": "0.02"}], "timestamp": "1769384067181", "event_type": "price_change"}}
{"_local_timestamp": "2026-01-25T23:34:27.376020+00:00", "data": {"market": "0xbcb33ad98c8141b10f2350ef687eddf0660484ecc15be42ecdae64339e64dce1", "price_changes": [{"asset_id": "105108334823274411453837752322302146951506166827237470954759784982159162094956", "price": "0.979", "size": "2910.96", "side": "BUY", "hash": "564fc9bcbf7033501845977ab1951a59c31ccbe2", "best_bid": "0.98", "best_ask": "0.981"}, {"asset_id": "87048058140607839077917415447158941112086606824479198286281986963033007181784", "price": "0.021", "size": "2910.96", "side": "SELL", "hash": "5e1d6bbd945263e387f92484ca3ff712b72f176b", "best_bid": "0.019", "best_ask": "0.02"}], "timestamp": "1769384067293", "event_type": "price_change"}}
{"_local_timestamp": "2026-01-25T23:34:27.537019+00:00", "data": {"market": "0xbcb33ad98c8141b10f2350ef687eddf0660484ecc15be42ecdae64339e64dce1", "price_changes": [{"asset_id": "105108334823274411453837752322302146951506166827237470954759784982159162094956", "price": "0.979", "size": "1712.47", "side": "BUY", "hash": "7df2a5a636c09a45752b377ef8003f98ad1dd212", "best_bid": "0.98", "best_ask": "0.981"}, {"asset_id": "87048058140607839077917415447158941112086606824479198286281986963033007181784", "price": "0.021", "size": "1712.47", "side": "SELL", "hash": "e07208faa6be5153f2a7ddd179b0fa703edaebbf", "best_bid": "0.019", "best_ask": "0.02"}], "timestamp": "1769384067467", "event_type": "price_change"}}
{"_local_timestamp": "2026-01-25T23:34:27.621334+00:00", "data": {"market": "0xbcb33ad98c8141b10f2350ef687eddf0660484ecc15be42ecdae64339e64dce1", "price_changes": [{"asset_id": "105108334823274411453837752322302146951506166827237470954759784982159162094956", "price": "0.979", "size": "2910.96", "side": "BUY", "hash": "94e9f4f15cc2bf94cad62b1c456ed613ec13bc2e", "best_bid": "0.98", "best_ask": "0.981"}, {"asset_id": "87048058140607839077917415447158941112086606824479198286281986963033007181784", "price": "0.021", "size": "2910.96", "side": "SELL", "hash": "38a4e51b0d7da4746a937bff2f7cfc5efb002dd1", "best_bid": "0.019", "best_ask": "0.02"}], "timestamp": "1769384067547", "event_type": "price_change"}}
{"_local_timestamp": "2026-01-25T23:34:27.919017+00:00", "data": {"market": "0xbcb33ad98c8141b10f2350ef687eddf0660484ecc15be42ecdae64339e64dce1", "price_changes": [{"asset_id": "105108334823274411453837752322302146951506166827237470954759784982159162094956", "price": "0.979", "size": "1712.47", "side": "BUY", "hash": "d9f108724e3d69443b5ed01240e47bb88d1c0a66", "best_bid": "0.98", "best_ask": "0.981"}, {"asset_id": "87048058140607839077917415447158941112086606824479198286281986963033007181784", "price": "0.021", "size": "1712.47", "side": "SELL", "hash": "648095c2bf14b3f08772776efbe092d5666a3aeb", "best_bid": "0.019", "best_ask": "0.02"}], "timestamp": "1769384067720", "event_type": "price_change"}}
{"_local_timestamp": "2026-01-25T23:34:27.997381+00:00", "data": {"market": "0xbcb33ad98c8141b10f2350ef687eddf0660484ecc15be42ecdae64339e64dce1", "price_changes": [{"asset_id": "105108334823274411453837752322302146951506166827237470954759784982159162094956", "price": "0.979", "size": "2910.96", "side": "BUY", "hash": "d90d46dc6d965687ff0f649e2ba214677b72e87f", "best_bid": "0.98", "best_ask": "0.981"}, {"asset_id": "87048058140607839077917415447158941112086606824479198286281986963033007181784", "price": "0.021", "size": "2910.96", "side": "SELL", "hash": "4215c2af1ef7328033f80532f27099ce91b64c80", "best_bid": "0.019", "best_ask": "0.02"}], "timestamp": "1769384067884", "event_type": "price_change"}}
{"_local_timestamp": "2026-01-25T23:34:28.041920+00:00", "data": {"market": "0xbcb33ad98c8141b10f2350ef687eddf0660484ecc15be42ecdae64339e64dce1", "price_changes": [{"asset_id": "105108334823274411453837752322302146951506166827237470954759784982159162094956", "price": "0.979", "size": "1712.47", "side": "BUY", "hash": "c974a6fc4f05b7f8a15166cb05b9903920f92a75", "best_bid": "0.98", "best_ask": "0.981"}, {"asset_id": "87048058140607839077917415447158941112086606824479198286281986963033007181784", "price": "0.021", "size": "1712.47", "side": "SELL", "hash": "cde894daede113af305f797635bdc27f78ed6aa0", "best_bid": "0.019", "best_ask": "0.02"}], "timestamp": "1769384067973", "event_type": "price_change"}}
{"_local_timestamp": "2026-01-25T23:34:28.141826+00:00", "data": {"market": "0xbcb33ad98c8141b10f2350ef687eddf0660484ecc15be42ecdae64339e64dce1", "price_changes": [{"asset_id": "105108334823274411453837752322302146951506166827237470954759784982159162094956", "price": "0.979", "size": "2910.96", "side": "BUY", "hash": "fafde42c4a0aaa20fe3482cc47a296be553857e0", "best_bid": "0.98", "best_ask": "0.981"}, {"asset_id": "87048058140607839077917415447158941112086606824479198286281986963033007181784", "price": "0.021", "size": "2910.96", "side": "SELL", "hash": "e77e989808ea01cc6ca0b7521e28a03d4b0f60b1", "best_bid": "0.019", "best_ask": "0.02"}], "timestamp": "1769384068074", "event_type": "price_change"}}
{"_local_timestamp": "2026-01-25T23:34:28.641518+00:00", "data": {"market": "0xbcb33ad98c8141b10f2350ef687eddf0660484ecc15be42ecdae64339e64dce1", "price_changes": [{"asset_id": "105108334823274411453837752322302146951506166827237470954759784982159162094956", "price": "0.979", "size": "1712.47", "side": "BUY", "hash": "6f7ed738bb96c8a2a33f26c733e4a49f04637832", "best_bid": "0.98", "best_ask": "0.981"}, {"asset_id": "87048058140607839077917415447158941112086606824479198286281986963033007181784", "price": "0.021", "size": "1712.47", "side": "SELL", "hash": "88f89a964a71ca630354f6bfee659bb81d70e48f", "best_bid": "0.019", "best_ask": "0.02"}], "timestamp": "1769384068257", "event_type": "price_change"}}
{"_local_timestamp": "2026-01-25T23:34:28.986811+00:00", "data": {"market": "0xbcb33ad98c8141b10f2350ef687eddf0660484ecc15be42ecdae64339e64dce1", "price_changes": [{"asset_id": "105108334823274411453837752322302146951506166827237470954759784982159162094956", "price": "0.979", "size": "2910.96", "side": "BUY", "hash": "e737dee5e3fdcfd40c4579e4af2726d9772366df", "best_bid": "0.98", "best_ask": "0.981"}, {"asset_id": "87048058140607839077917415447158941112086606824479198286281986963033007181784", "price": "0.021", "size": "2910.96", "side": "SELL", "hash": "06323fb1ca8bd821380b1783dc00d5bcdacb9104", "best_bid": "0.019", "best_ask": "0.02"}], "timestamp": "1769384068630", "event_type": "price_change"}}
{"_local_timestamp": "2026-01-25T23:34:29.231277+00:00", "data": {"market": "0xbcb33ad98c8141b10f2350ef687eddf0660484ecc15be42ecdae64339e64dce1", "price_changes": [{"asset_id": "105108334823274411453837752322302146951506166827237470954759784982159162094956", "price": "0.979", "size": "1712.47", "side": "BUY", "hash": "dafb9622d0f5bef8a169c20592d038d2af786ac0", "best_bid": "0.98", "best_ask": "0.981"}, {"asset_id": "87048058140607839077917415447158941112086606824479198286281986963033007181784", "price": "0.021", "size": "1712.47", "side": "SELL", "hash": "b91dee5fe04db95f051622cbde50e069d356942d", "best_bid": "0.019", "best_ask": "0.02"}], "timestamp": "1769384069161", "event_type": "price_change"}}
{"_local_timestamp": "2026-01-25T23:34:29.377326+00:00", "data": {"market": "0xbcb33ad98c8141b10f2350ef687eddf0660484ecc15be42ecdae64339e64dce1", "price_changes": [{"asset_id": "105108334823274411453837752322302146951506166827237470954759784982159162094956", "price": "0.979", "size": "2910.96", "side": "BUY", "hash": "0875c6e0055071e5a816d888ee71a5965efb4a55", "best_bid": "0.98", "best_ask": "0.981"}, {"asset_id": "87048058140607839077917415447158941112086606824479198286281986963033007181784", "price": "0.021", "size": "2910.96", "side": "SELL", "hash": "e3b388f33be86fa41b09b6b74c7f859ff272bda9", "best_bid": "0.019", "best_ask": "0.02"}], "timestamp": "1769384069310", "event_type": "price_change"}}
{"_local_timestamp": "2026-01-25T23:34:29.572286+00:00", "data": {"market": "0xbcb33ad98c8141b10f2350ef687eddf0660484ecc15be42ecdae64339e64dce1", "price_changes": [{"asset_id": "105108334823274411453837752322302146951506166827237470954759784982159162094956", "price": "0.979", "size": "1712.47", "side": "BUY", "hash": "f9de4252708436dede6819f848edc4bdd6685a06", "best_bid": "0.98", "best_ask": "0.981"}, {"asset_id": "87048058140607839077917415447158941112086606824479198286281986963033007181784", "price": "0.021", "size": "1712.47", "side": "SELL", "hash": "170fccc5d18b6937b326e63935d48a28ddf4cb0b", "best_bid": "0.019", "best_ask": "0.02"}], "timestamp": "1769384069496", "event_type": "price_change"}}
{"_local_timestamp": "2026-01-25T23:34:29.704789+00:00", "data": {"market": "0xbcb33ad98c8141b10f2350ef687eddf0660484ecc15be42ecdae64339e64dce1", "price_changes": [{"asset_id": "105108334823274411453837752322302146951506166827237470954759784982159162094956", "price": "0.979", "size": "2910.96", "side": "BUY", "hash": "8ef6e3fad91c3d1bd8697512acb3a252f7aee6da", "best_bid": "0.98", "best_ask": "0.981"}, {"asset_id": "87048058140607839077917415447158941112086606824479198286281986963033007181784", "price": "0.021", "size": "2910.96", "side": "SELL", "hash": "5f6b6f5b56dc893666499f3f48d541ab4d3c8533", "best_bid": "0.019", "best_ask": "0.02"}], "timestamp": "1769384069608", "event_type": "price_change"}}
{"_local_timestamp": "2026-01-25T23:34:30.002311+00:00", "data": {"market": "0xbcb33ad98c8141b10f2350ef687eddf0660484ecc15be42ecdae64339e64dce1", "price_changes": [{"asset_id": "105108334823274411453837752322302146951506166827237470954759784982159162094956", "price": "0.979", "size": "1712.47", "side": "BUY", "hash": "745f301b373ad131b6bd536af8f16dc726e19193", "best_bid": "0.98", "best_ask": "0.981"}, {"asset_id": "87048058140607839077917415447158941112086606824479198286281986963033007181784", "price": "0.021", "size": "1712.47", "side": "SELL", "hash": "c226967603f2224a12f07b17d8b80ce5bf0877b9", "best_bid": "0.019", "best_ask": "0.02"}], "timestamp": "1769384069804", "event_type": "price_change"}}
{"_local_timestamp": "2026-01-25T23:34:30.134058+00:00", "data": {"market": "0xbcb33ad98c8141b10f2350ef687eddf0660484ecc15be42ecdae64339e64dce1", "price_changes": [{"asset_id": "105108334823274411453837752322302146951506166827237470954759784982159162094956", "price": "0.979", "size": "2910.96", "side": "BUY", "hash": "295b7839f92badc642edb04f0b3ebb2c1dd8d1f6", "best_bid": "0.98", "best_ask": "0.981"}, {"asset_id": "87048058140607839077917415447158941112086606824479198286281986963033007181784", "price": "0.021", "size": "2910.96", "side": "SELL", "hash": "4c333a8eafb389d8ffdb13f010b0b92ff20cee27", "best_bid": "0.019", "best_ask": "0.02"}], "timestamp": "1769384069991", "event_type": "price_change"}}
{"_local_timestamp": "2026-01-25T23:34:30.311097+00:00", "data": {"market": "0xbcb33ad98c8141b10f2350ef687eddf0660484ecc15be42ecdae64339e64dce1", "price_changes": [{"asset_id": "105108334823274411453837752322302146951506166827237470954759784982159162094956", "price": "0.979", "size": "1712.47", "side": "BUY", "hash": "a639c518561b3dd0f67136d1346d77fd59b37600", "best_bid": "0.98", "best_ask": "0.981"}, {"asset_id": "87048058140607839077917415447158941112086606824479198286281986963033007181784", "price": "0.021", "size": "1712.47", "side": "SELL", "hash": "668ffd1b3b87478854788e9a307ef38c11cb5aee", "best_bid": "0.019", "best_ask": "0.02"}], "timestamp": "1769384070134", "event_type": "price_change"}}
{"_local_timestamp": "2026-01-25T23:34:30.442975+00:00", "data": {"market": "0xbcb33ad98c8141b10f2350ef687eddf0660484ecc15be42ecdae64339e64dce1", "price_changes": [{"asset_id": "105108334823274411453837752322302146951506166827237470954759784982159162094956", "price": "0.979", "size": "2910.96", "side": "BUY", "hash": "75fa51f299c3cb9f302b7d985eebb252a104a8b2", "best_bid": "0.98", "best_ask": "0.981"}, {"asset_id": "87048058140607839077917415447158941112086606824479198286281986963033007181784", "price": "0.021", "size": "2910.96", "side": "SELL", "hash": "1fd4cf46efb0d6eb5c09b6ed51e45c0fd6b2a831", "best_bid": "0.019", "best_ask": "0.02"}], "timestamp": "1769384070271", "event_type": "price_change"}}
{"_local_timestamp": "2026-01-25T23:34:30.762709+00:00", "data": {"market": "0xbcb33ad98c8141b10f2350ef687eddf0660484ecc15be42ecdae64339e64dce1", "price_changes": [{"asset_id": "105108334823274411453837752322302146951506166827237470954759784982159162094956", "price": "0.979", "size": "1712.47", "side": "BUY", "hash": "c7ff54f7060731df77ffc098181ce4afd4805a92", "best_bid": "0.98", "best_ask": "0.981"}, {"asset_id": "87048058140607839077917415447158941112086606824479198286281986963033007181784", "price": "0.021", "size": "1712.47", "side": "SELL", "hash": "fa37523c1eabe26fa2b4772b536dce8691cc6900", "best_bid": "0.019", "best_ask": "0.02"}], "timestamp": "1769384070643", "event_type": "price_change"}}
{"_local_timestamp": "2026-01-25T23:34:30.829301+00:00", "data": {"market": "0xbcb33ad98c8141b10f2350ef687eddf0660484ecc15be42ecdae64339e64dce1", "price_changes": [{"asset_id": "105108334823274411453837752322302146951506166827237470954759784982159162094956", "price": "0.979", "size": "2910.96", "side": "BUY", "hash": "66d42ee590ab0addd9634f5e9e7bcda147efdfa8", "best_bid": "0.98", "best_ask": "0.981"}, {"asset_id": "87048058140607839077917415447158941112086606824479198286281986963033007181784", "price": "0.021", "size": "2910.96", "side": "SELL", "hash": "11336dd8fa889e3eeeef642dd541688ef83e3965", "best_bid": "0.019", "best_ask": "0.02"}], "timestamp": "1769384070754", "event_type": "price_change"}}
{"_local_timestamp": "2026-01-25T23:34:31.044643+00:00", "data": {"market": "0xbcb33ad98c8141b10f2350ef687eddf0660484ecc15be42ecdae64339e64dce1", "price_changes": [{"asset_id": "105108334823274411453837752322302146951506166827237470954759784982159162094956", "price": "0.979", "size": "1712.47", "side": "BUY", "hash": "9f245e27ebde8434da1fb8bfa080b08b45dbdf8c", "best_bid": "0.98", "best_ask": "0.981"}, {"asset_id": "87048058140607839077917415447158941112086606824479198286281986963033007181784", "price": "0.021", "size": "1712.47", "side": "SELL", "hash": "63790968fefd9b720fd90d020c8b30eaa5d99ecc", "best_bid": "0.019", "best_ask": "0.02"}], "timestamp": "1769384070952", "event_type": "price_change"}}
{"_local_timestamp": "2026-01-25T23:34:31.200918+00:00", "data": {"market": "0xbcb33ad98c8141b10f2350ef687eddf0660484ecc15be42ecdae64339e64dce1", "price_changes": [{"asset_id": "105108334823274411453837752322302146951506166827237470954759784982159162094956", "price": "0.979", "size": "2844.33", "side": "BUY", "hash": "e3293548b9499206fb972525c99d9ae23f03b7b5", "best_bid": "0.98", "best_ask": "0.981"}, {"asset_id": "87048058140607839077917415447158941112086606824479198286281986963033007181784", "price": "0.021", "size": "2844.33", "side": "SELL", "hash": "16ad8760a30381f613a7cfbfed0411b0759bb534", "best_bid": "0.019", "best_ask": "0.02"}], "timestamp": "1769384071128", "event_type": "price_change"}}
{"_local_timestamp": "2026-01-25T23:34:31.375314+00:00", "data": {"market": "0xbcb33ad98c8141b10f2350ef687eddf0660484ecc15be42ecdae64339e64dce1", "price_changes": [{"asset_id": "105108334823274411453837752322302146951506166827237470954759784982159162094956", "price": "0.979", "size": "1712.47", "side": "BUY", "hash": "c4f2f0a1885ee28de55d5aa69169d4c587d7f1d2", "best_bid": "0.98", "best_ask": "0.981"}, {"asset_id": "87048058140607839077917415447158941112086606824479198286281986963033007181784", "price": "0.021", "size": "1712.47", "side": "SELL", "hash": "eb575b995b0b558643a50f661fde30d07c9dbde1", "best_bid": "0.019", "best_ask": "0.02"}], "timestamp": "1769384071304", "event_type": "price_change"}}
{"_local_timestamp": "2026-01-25T23:34:31.493142+00:00", "data": {"market": "0xbcb33ad98c8141b10f2350ef687eddf0660484ecc15be42ecdae64339e64dce1", "price_changes": [{"asset_id": "105108334823274411453837752322302146951506166827237470954759784982159162094956", "price": "0.979", "size": "2844.33", "side": "BUY", "hash": "2e53dba94b205ba0d5d961716e281d0121b51c88", "best_bid": "0.98", "best_ask": "0.981"}, {"asset_id": "87048058140607839077917415447158941112086606824479198286281986963033007181784", "price": "0.021", "size": "2844.33", "side": "SELL", "hash": "fafe071cff22119316b55733cb41bf20e2b5006f", "best_bid": "0.019", "best_ask": "0.02"}], "timestamp": "1769384071424", "event_type": "price_change"}}
{"_local_timestamp": "2026-01-25T23:34:31.683464+00:00", "data": {"market": "0xbcb33ad98c8141b10f2350ef687eddf0660484ecc15be42ecdae64339e64dce1", "price_changes": [{"asset_id": "105108334823274411453837752322302146951506166827237470954759784982159162094956", "price": "0.979", "size": "1712.47", "side": "BUY", "hash": "588ffaea9da9990de2e2b1912fca1048254d5959", "best_bid": "0.98", "best_ask": "0.981"}, {"asset_id": "87048058140607839077917415447158941112086606824479198286281986963033007181784", "price": "0.021", "size": "1712.47", "side": "SELL", "hash": "bc9706ecb5f2b00df912116a54373850289fe9b5", "best_bid": "0.019", "best_ask": "0.02"}], "timestamp": "1769384071613", "event_type": "price_change"}}
{"_local_timestamp": "2026-01-25T23:34:31.777304+00:00", "data": {"market": "0xbcb33ad98c8141b10f2350ef687eddf0660484ecc15be42ecdae64339e64dce1", "price_changes": [{"asset_id": "105108334823274411453837752322302146951506166827237470954759784982159162094956", "price": "0.979", "size": "2844.33", "side": "BUY", "hash": "d573a1ab04c63206043aea69a49533155064a01b", "best_bid": "0.98", "best_ask": "0.981"}, {"asset_id": "87048058140607839077917415447158941112086606824479198286281986963033007181784", "price": "0.021", "size": "2844.33", "side": "SELL", "hash": "3de8a2eb2a766c6a2b6c5578790cfda42e20d15f", "best_bid": "0.019", "best_ask": "0.02"}], "timestamp": "1769384071708", "event_type": "price_change"}}
{"_local_timestamp": "2026-01-25T23:34:31.961641+00:00", "data": {"market": "0xbcb33ad98c8141b10f2350ef687eddf0660484ecc15be42ecdae64339e64dce1", "price_changes": [{"asset_id": "105108334823274411453837752322302146951506166827237470954759784982159162094956", "price": "0.979", "size": "1712.47", "side": "BUY", "hash": "c3cd6dfc96a396fa26c30011db4f4d5419f86c2d", "best_bid": "0.98", "best_ask": "0.981"}, {"asset_id": "87048058140607839077917415447158941112086606824479198286281986963033007181784", "price": "0.021", "size": "1712.47", "side": "SELL", "hash": "2b2c80d28f3278111c1790981b862c79861a7bdd", "best_bid": "0.019", "best_ask": "0.02"}], "timestamp": "1769384071887", "event_type": "price_change"}}
{"_local_timestamp": "2026-01-25T23:34:32.010468+00:00", "data": {"market": "0xbcb33ad98c8141b10f2350ef687eddf0660484ecc15be42ecdae64339e64dce1", "price_changes": [{"asset_id": "105108334823274411453837752322302146951506166827237470954759784982159162094956", "price": "0.979", "size": "2844.33", "side": "BUY", "hash": "ff3f8d3f1fa70b448fcabec0a08e38c814d61050", "best_bid": "0.98", "best_ask": "0.981"}, {"asset_id": "87048058140607839077917415447158941112086606824479198286281986963033007181784", "price": "0.021", "size": "2844.33", "side": "SELL", "hash": "1b74e90e0170de5e3beff1b5be2bb033c91b0420", "best_bid": "0.019", "best_ask": "0.02"}], "timestamp": "1769384071940", "event_type": "price_change"}}
{"_local_timestamp": "2026-01-25T23:34:32.281823+00:00", "data": {"market": "0xbcb33ad98c8141b10f2350ef687eddf0660484ecc15be42ecdae64339e64dce1", "price_changes": [{"asset_id": "105108334823274411453837752322302146951506166827237470954759784982159162094956", "price": "0.979", "size": "1712.47", "side": "BUY", "hash": "441d247d7f9d2fd6ae698f8055eee9c37fdfe1af", "best_bid": "0.98", "best_ask": "0.981"}, {"asset_id": "87048058140607839077917415447158941112086606824479198286281986963033007181784", "price": "0.021", "size": "1712.47", "side": "SELL", "hash": "6dc53f2de18a905cd5d7daa7730639304b01411e", "best_bid": "0.019", "best_ask": "0.02"}], "timestamp": "1769384072145", "event_type": "price_change"}}
{"_local_timestamp": "2026-01-25T23:34:32.390425+00:00", "data": {"market": "0xbcb33ad98c8141b10f2350ef687eddf0660484ecc15be42ecdae64339e64dce1", "price_changes": [{"asset_id": "105108334823274411453837752322302146951506166827237470954759784982159162094956", "price": "0.979", "size": "2844.33", "side": "BUY", "hash": "f3a240b51907c35028558b51390b9d9f988abdad", "best_bid": "0.98", "best_ask": "0.981"}, {"asset_id": "87048058140607839077917415447158941112086606824479198286281986963033007181784", "price": "0.021", "size": "2844.33", "side": "SELL", "hash": "67a7f8569d410fe2685694b33c14755bb5d7d471", "best_bid": "0.019", "best_ask": "0.02"}], "timestamp": "1769384072284", "event_type": "price_change"}}
{"_local_timestamp": "2026-01-25T23:34:32.538895+00:00", "data": {"market": "0xbcb33ad98c8141b10f2350ef687eddf0660484ecc15be42ecdae64339e64dce1", "price_changes": [{"asset_id": "105108334823274411453837752322302146951506166827237470954759784982159162094956", "price": "0.979", "size": "1712.47", "side": "BUY", "hash": "0d777d77a17b8a9b33b9c88fcf6cb8f24f9a640c", "best_bid": "0.98", "best_ask": "0.981"}, {"asset_id": "87048058140607839077917415447158941112086606824479198286281986963033007181784", "price": "0.021", "size": "1712.47", "side": "SELL", "hash": "cd8305860183677c1ad802966d453ef03c49e17b", "best_bid": "0.019", "best_ask": "0.02"}], "timestamp": "1769384072470", "event_type": "price_change"}}
{"_local_timestamp": "2026-01-25T23:34:32.641126+00:00", "data": {"market": "0xbcb33ad98c8141b10f2350ef687eddf0660484ecc15be42ecdae64339e64dce1", "price_changes": [{"asset_id": "105108334823274411453837752322302146951506166827237470954759784982159162094956", "price": "0.979", "size": "2844.33", "side": "BUY", "hash": "4b5a3bbc6284871299c6195baf8162a96661b446", "best_bid": "0.98", "best_ask": "0.981"}, {"asset_id": "87048058140607839077917415447158941112086606824479198286281986963033007181784", "price": "0.021", "size": "2844.33", "side": "SELL", "hash": "c2fc1c72321be6a1e3403a854cc4ced8ce5be37b", "best_bid": "0.019", "best_ask": "0.02"}], "timestamp": "1769384072572", "event_type": "price_change"}}
{"_local_timestamp": "2026-01-25T23:34:32.822792+00:00", "data": {"market": "0xbcb33ad98c8141b10f2350ef687eddf0660484ecc15be42ecdae64339e64dce1", "price_changes": [{"asset_id": "105108334823274411453837752322302146951506166827237470954759784982159162094956", "price": "0.979", "size": "1712.47", "side": "BUY", "hash": "f20e90e5437be95b387a272b8adb68b96916dfc2", "best_bid": "0.98", "best_ask": "0.981"}, {"asset_id": "87048058140607839077917415447158941112086606824479198286281986963033007181784", "price": "0.021", "size": "1712.47", "side": "SELL", "hash": "141ab981d81ab46bfae9872b287a56085514a979", "best_bid": "0.019", "best_ask": "0.02"}], "timestamp": "1769384072754", "event_type": "price_change"}}
{"_local_timestamp": "2026-01-25T23:34:32.980522+00:00", "data": {"market": "0xbcb33ad98c8141b10f2350ef687eddf0660484ecc15be42ecdae64339e64dce1", "price_changes": [{"asset_id": "105108334823274411453837752322302146951506166827237470954759784982159162094956", "price": "0.979", "size": "2844.33", "side": "BUY", "hash": "8779d13a8b6ebb48d00dd3d9765980e4307fd9c6", "best_bid": "0.98", "best_ask": "0.981"}, {"asset_id": "87048058140607839077917415447158941112086606824479198286281986963033007181784", "price": "0.021", "size": "2844.33", "side": "SELL", "hash": "15eb1906180cbf9696c47e61027a094e712dd3e2", "best_bid": "0.019", "best_ask": "0.02"}], "timestamp": "1769384072895", "event_type": "price_change"}}
{"_local_timestamp": "2026-01-25T23:34:33.141148+00:00", "data": {"market": "0xbcb33ad98c8141b10f2350ef687eddf0660484ecc15be42ecdae64339e64dce1", "price_changes": [{"asset_id": "105108334823274411453837752322302146951506166827237470954759784982159162094956", "price": "0.979", "size": "1712.47", "side": "BUY", "hash": "ddfe0629905e753430e81072c7726a1773b67bf6", "best_bid": "0.98", "best_ask": "0.981"}, {"asset_id": "87048058140607839077917415447158941112086606824479198286281986963033007181784", "price": "0.021", "size": "1712.47", "side": "SELL", "hash": "4390be379267d672cb26e570911c2e187ae646d6", "best_bid": "0.019", "best_ask": "0.02"}], "timestamp": "1769384073074", "event_type": "price_change"}}
{"_local_timestamp": "2026-01-25T23:34:33.268815+00:00", "data": {"market": "0xbcb33ad98c8141b10f2350ef687eddf0660484ecc15be42ecdae64339e64dce1", "price_changes": [{"asset_id": "105108334823274411453837752322302146951506166827237470954759784982159162094956", "price": "0.979", "size": "2844.33", "side": "BUY", "hash": "13aaf5e5bf40439593926e7a55a47560c55fbe8f", "best_bid": "0.98", "best_ask": "0.981"}, {"asset_id": "87048058140607839077917415447158941112086606824479198286281986963033007181784", "price": "0.021", "size": "2844.33", "side": "SELL", "hash": "3ed4ef2d5ec9d4b4dd8f7e215b0efaa532bde0ed", "best_bid": "0.019", "best_ask": "0.02"}], "timestamp": "1769384073200", "event_type": "price_change"}}
{"_local_timestamp": "2026-01-25T23:34:33.462471+00:00", "data": {"market": "0xbcb33ad98c8141b10f2350ef687eddf0660484ecc15be42ecdae64339e64dce1", "price_changes": [{"asset_id": "105108334823274411453837752322302146951506166827237470954759784982159162094956", "price": "0.979", "size": "1712.47", "side": "BUY", "hash": "10702e3f8b4bbeefdcf6bdcfd959f604d1c33b6f", "best_bid": "0.98", "best_ask": "0.981"}, {"asset_id": "87048058140607839077917415447158941112086606824479198286281986963033007181784", "price": "0.021", "size": "1712.47", "side": "SELL", "hash": "52236809090da23f0f25670329cf7d0d3775f5a5", "best_bid": "0.019", "best_ask": "0.02"}], "timestamp": "1769384073381", "event_type": "price_change"}}
{"_local_timestamp": "2026-01-25T23:34:33.560647+00:00", "data": {"market": "0xbcb33ad98c8141b10f2350ef687eddf0660484ecc15be42ecdae64339e64dce1", "price_changes": [{"asset_id": "105108334823274411453837752322302146951506166827237470954759784982159162094956", "price": "0.979", "size": "2844.33", "side": "BUY", "hash": "243782c49c213b22fbd9844241ee496024ef3f74", "best_bid": "0.98", "best_ask": "0.981"}, {"asset_id": "87048058140607839077917415447158941112086606824479198286281986963033007181784", "price": "0.021", "size": "2844.33", "side": "SELL", "hash": "a1b5b84ee23a0d7edf0d9e5ca4aed61fa9ab2d4f", "best_bid": "0.019", "best_ask": "0.02"}], "timestamp": "1769384073491", "event_type": "price_change"}}
{"_local_timestamp": "2026-01-25T23:34:33.730515+00:00", "data": {"market": "0xbcb33ad98c8141b10f2350ef687eddf0660484ecc15be42ecdae64339e64dce1", "price_changes": [{"asset_id": "105108334823274411453837752322302146951506166827237470954759784982159162094956", "price": "0.979", "size": "1712.47", "side": "BUY", "hash": "c6e794a3e0e4d693c9925e98520b39c62f9b1747", "best_bid": "0.98", "best_ask": "0.981"}, {"asset_id": "87048058140607839077917415447158941112086606824479198286281986963033007181784", "price": "0.021", "size": "1712.47", "side": "SELL", "hash": "0bc90ee7117f0349559c858c24b3f1689985561a", "best_bid": "0.019", "best_ask": "0.02"}], "timestamp": "1769384073654", "event_type": "price_change"}}
{"_local_timestamp": "2026-01-25T23:34:33.866047+00:00", "data": {"market": "0xbcb33ad98c8141b10f2350ef687eddf0660484ecc15be42ecdae64339e64dce1", "price_changes": [{"asset_id": "105108334823274411453837752322302146951506166827237470954759784982159162094956", "price": "0.979", "size": "2844.33", "side": "BUY", "hash": "e70acb7f8796edf3203227af48b1d4fa41fc7cb6", "best_bid": "0.98", "best_ask": "0.981"}, {"asset_id": "87048058140607839077917415447158941112086606824479198286281986963033007181784", "price": "0.021", "size": "2844.33", "side": "SELL", "hash": "d9db9be4b2d0327a6fb4c35a77b1b4f27589134c", "best_bid": "0.019", "best_ask": "0.02"}], "timestamp": "1769384073799", "event_type": "price_change"}}
{"_local_timestamp": "2026-01-25T23:34:34.025733+00:00", "data": {"market": "0xbcb33ad98c8141b10f2350ef687eddf0660484ecc15be42ecdae64339e64dce1", "price_changes": [{"asset_id": "105108334823274411453837752322302146951506166827237470954759784982159162094956", "price": "0.979", "size": "1712.47", "side": "BUY", "hash": "8db3676193368d5d93d47aad75af96ba0051e145", "best_bid": "0.98", "best_ask": "0.981"}, {"asset_id": "87048058140607839077917415447158941112086606824479198286281986963033007181784", "price": "0.021", "size": "1712.47", "side": "SELL", "hash": "ea73d23ac0f4dc746806a88a9b3fe820b0d67ff5", "best_bid": "0.019", "best_ask": "0.02"}], "timestamp": "1769384073949", "event_type": "price_change"}}
{"_local_timestamp": "2026-01-25T23:34:34.276620+00:00", "data": {"market": "0xbcb33ad98c8141b10f2350ef687eddf0660484ecc15be42ecdae64339e64dce1", "price_changes": [{"asset_id": "87048058140607839077917415447158941112086606824479198286281986963033007181784", "price": "0.023", "size": "2819.29", "side": "SELL", "hash": "2dbb0ef2e87b7dc90e1885f8b0ae930766301b4e", "best_bid": "0.019", "best_ask": "0.02"}, {"asset_id": "105108334823274411453837752322302146951506166827237470954759784982159162094956", "price": "0.977", "size": "2819.29", "side": "BUY", "hash": "fcaba5391ae18f47c519ba5e826914c2e831ad70", "best_bid": "0.98", "best_ask": "0.981"}], "timestamp": "1769384074202", "event_type": "price_change"}}
{"_local_timestamp": "2026-01-25T23:34:34.295434+00:00", "data": {"market": "0xbcb33ad98c8141b10f2350ef687eddf0660484ecc15be42ecdae64339e64dce1", "price_changes": [{"asset_id": "105108334823274411453837752322302146951506166827237470954759784982159162094956", "price": "0.979", "size": "2844.33", "side": "BUY", "hash": "4c6a309c041591ffb75f5dbe38ddfa5668220cbb", "best_bid": "0.98", "best_ask": "0.981"}, {"asset_id": "87048058140607839077917415447158941112086606824479198286281986963033007181784", "price": "0.021", "size": "2844.33", "side": "SELL", "hash": "10ab9db152ef9cc558b9f5ecf35fab63d36281fa", "best_bid": "0.019", "best_ask": "0.02"}], "timestamp": "1769384074224", "event_type": "price_change"}}
{"_local_timestamp": "2026-01-25T23:34:34.618477+00:00", "data": {"market": "0xbcb33ad98c8141b10f2350ef687eddf0660484ecc15be42ecdae64339e64dce1", "price_changes": [{"asset_id": "105108334823274411453837752322302146951506166827237470954759784982159162094956", "price": "0.979", "size": "1712.47", "side": "BUY", "hash": "fe100227d1aa70f131e4b0602ab39807d47cffd1", "best_bid": "0.98", "best_ask": "0.981"}, {"asset_id": "87048058140607839077917415447158941112086606824479198286281986963033007181784", "price": "0.021", "size": "1712.47", "side": "SELL", "hash": "3893c18d1219ef4a87cd4a24b6d872dede9d7b6d", "best_bid": "0.019", "best_ask": "0.02"}], "timestamp": "1769384074545", "event_type": "price_change"}}
{"_local_timestamp": "2026-01-25T23:34:34.963175+00:00", "data": {"market": "0xbcb33ad98c8141b10f2350ef687eddf0660484ecc15be42ecdae64339e64dce1", "price_changes": [{"asset_id": "105108334823274411453837752322302146951506166827237470954759784982159162094956", "price": "0.979", "size": "2844.33", "side": "BUY", "hash": "fa9ec8af74d7c36675c32a7babbea54777103be5", "best_bid": "0.98", "best_ask": "0.981"}, {"asset_id": "87048058140607839077917415447158941112086606824479198286281986963033007181784", "price": "0.021", "size": "2844.33", "side": "SELL", "hash": "1de5fe84dde55b7aa6d132c650cf4cbb9b9f6f88", "best_bid": "0.019", "best_ask": "0.02"}], "timestamp": "1769384074812", "event_type": "price_change"}}
{"_local_timestamp": "2026-01-25T23:34:35.457528+00:00", "data": {"market": "0xbcb33ad98c8141b10f2350ef687eddf0660484ecc15be42ecdae64339e64dce1", "price_changes": [{"asset_id": "105108334823274411453837752322302146951506166827237470954759784982159162094956", "price": "0.979", "size": "1712.47", "side": "BUY", "hash": "1fb7ae049ef084bcb0e6f2b8af9945f96bc6da2c", "best_bid": "0.98", "best_ask": "0.981"}, {"asset_id": "87048058140607839077917415447158941112086606824479198286281986963033007181784", "price": "0.021", "size": "1712.47", "side": "SELL", "hash": "40707f58b494e483ad18430deeadd3b8537e28b6", "best_bid": "0.019", "best_ask": "0.02"}], "timestamp": "1769384075382", "event_type": "price_change"}}
{"_local_timestamp": "2026-01-25T23:34:35.740618+00:00", "data": {"market": "0xbcb33ad98c8141b10f2350ef687eddf0660484ecc15be42ecdae64339e64dce1", "price_changes": [{"asset_id": "105108334823274411453837752322302146951506166827237470954759784982159162094956", "price": "0.979", "size": "2844.33", "side": "BUY", "hash": "d3bb15dc52c4fcd5ecfd7ff9f83de713fc41439c", "best_bid": "0.98", "best_ask": "0.981"}, {"asset_id": "87048058140607839077917415447158941112086606824479198286281986963033007181784", "price": "0.021", "size": "2844.33", "side": "SELL", "hash": "bf5e15e3642658e8bd6cb5523e403b73a62954e7", "best_bid": "0.019", "best_ask": "0.02"}], "timestamp": "1769384075667", "event_type": "price_change"}}
{"_local_timestamp": "2026-01-25T23:34:36.014037+00:00", "data": {"market": "0xa062dea464f0e8fc3381176494198cf45574ec190eca77a40f49988320fa15f2", "price_changes": [{"asset_id": "16754375222233973989954094649431109282368408854808102040230156977754673841406", "price": "0.991", "size": "14514.08", "side": "SELL", "hash": "33d1ec8c9d03746dbb0ecd02c520d68b9c7e6b20", "best_bid": "0.98", "best_ask": "0.981"}, {"asset_id": "2941656641529467089826910607945793276058581543804243973571467775773698944388", "price": "0.009", "size": "14514.08", "side": "BUY", "hash": "ab8cb1c998e2824659088458c7d508652b16f70c", "best_bid": "0.019", "best_ask": "0.02"}], "timestamp": "1769384075942", "event_type": "price_change"}}
{"_local_timestamp": "2026-01-25T23:34:36.023344+00:00", "data": {"market": "0xa062dea464f0e8fc3381176494198cf45574ec190eca77a40f49988320fa15f2", "price_changes": [{"asset_id": "16754375222233973989954094649431109282368408854808102040230156977754673841406", "price": "0.962", "size": "19365.12", "side": "BUY", "hash": "b775c772a7e0487567613f4fe7464adae71ea633", "best_bid": "0.98", "best_ask": "0.981"}, {"asset_id": "2941656641529467089826910607945793276058581543804243973571467775773698944388", "price": "0.038", "size": "19365.12", "side": "SELL", "hash": "f32a752ee4309dcc80d8c83705e75a6370d16677", "best_bid": "0.019", "best_ask": "0.02"}], "timestamp": "1769384075943", "event_type": "price_change"}}
{"_local_timestamp": "2026-01-25T23:34:36.031239+00:00", "data": {"market": "0xbcb33ad98c8141b10f2350ef687eddf0660484ecc15be42ecdae64339e64dce1", "price_changes": [{"asset_id": "105108334823274411453837752322302146951506166827237470954759784982159162094956", "price": "0.979", "size": "1712.47", "side": "BUY", "hash": "a8d17fcdeab3212bd7445990db9f23d945d7ce7c", "best_bid": "0.98", "best_ask": "0.981"}, {"asset_id": "87048058140607839077917415447158941112086606824479198286281986963033007181784", "price": "0.021", "size": "1712.47", "side": "SELL", "hash": "e0548685ea15cd2a5fbc11abbf5398fc46ae30ac", "best_bid": "0.019", "best_ask": "0.02"}], "timestamp": "1769384075961", "event_type": "price_change"}}
{"_local_timestamp": "2026-01-25T23:34:36.256186+00:00", "data": {"market": "0xbcb33ad98c8141b10f2350ef687eddf0660484ecc15be42ecdae64339e64dce1", "price_changes": [{"asset_id": "105108334823274411453837752322302146951506166827237470954759784982159162094956", "price": "0.979", "size": "2844.33", "side": "BUY", "hash": "dba22c12b4ee573dffbc0f4fdb600671e764a508", "best_bid": "0.98", "best_ask": "0.981"}, {"asset_id": "87048058140607839077917415447158941112086606824479198286281986963033007181784", "price": "0.021", "size": "2844.33", "side": "SELL", "hash": "03ce05680ed4649682d0ce0a010bcbec0defe60b", "best_bid": "0.019", "best_ask": "0.02"}], "timestamp": "1769384076187", "event_type": "price_change"}}
{"_local_timestamp": "2026-01-25T23:34:36.662005+00:00", "data": {"market": "0xbcb33ad98c8141b10f2350ef687eddf0660484ecc15be42ecdae64339e64dce1", "price_changes": [{"asset_id": "105108334823274411453837752322302146951506166827237470954759784982159162094956", "price": "0.979", "size": "1712.47", "side": "BUY", "hash": "074a28bb4aac8876a0197cceb9dc386814d8fef4", "best_bid": "0.98", "best_ask": "0.981"}, {"asset_id": "87048058140607839077917415447158941112086606824479198286281986963033007181784", "price": "0.021", "size": "1712.47", "side": "SELL", "hash": "2c7877b4ad36b961d67b86527db4bccc0accb22d", "best_bid": "0.019", "best_ask": "0.02"}], "timestamp": "1769384076590", "event_type": "price_change"}}
{"_local_timestamp": "2026-01-25T23:34:36.885504+00:00", "data": {"market": "0xbcb33ad98c8141b10f2350ef687eddf0660484ecc15be42ecdae64339e64dce1", "price_changes": [{"asset_id": "105108334823274411453837752322302146951506166827237470954759784982159162094956", "price": "0.979", "size": "2844.33", "side": "BUY", "hash": "eded4527b89fd263e2155f321b8f75486ab07a5f", "best_bid": "0.98", "best_ask": "0.981"}, {"asset_id": "87048058140607839077917415447158941112086606824479198286281986963033007181784", "price": "0.021", "size": "2844.33", "side": "SELL", "hash": "276ffe360e53a4c29d48a2f9e3faf175307ac8f1", "best_bid": "0.019", "best_ask": "0.02"}], "timestamp": "1769384076818", "event_type": "price_change"}}
{"_local_timestamp": "2026-01-25T23:34:37.049989+00:00", "data": {"market": "0xbcb33ad98c8141b10f2350ef687eddf0660484ecc15be42ecdae64339e64dce1", "price_changes": [{"asset_id": "105108334823274411453837752322302146951506166827237470954759784982159162094956", "price": "0.979", "size": "1712.47", "side": "BUY", "hash": "9c48a40f0655f00b065bf25f1d2dcb83ea7240b0", "best_bid": "0.98", "best_ask": "0.981"}, {"asset_id": "87048058140607839077917415447158941112086606824479198286281986963033007181784", "price": "0.021", "size": "1712.47", "side": "SELL", "hash": "5bcb56519ebdc5ad0c1cf61714e792c2fd533840", "best_bid": "0.019", "best_ask": "0.02"}], "timestamp": "1769384076970", "event_type": "price_change"}}
