{"_local_timestamp": "2026-01-25T23:33:17.514411+00:00", "data": [{"market": "0x1d54eb5eac2cee8f595f3097c65da7d07f8ab5dee63d7c0c6883eb70e1e9af30", "asset_id": "82991837887127223585838300135823820957946688171642633953055760547186260528157", "timestamp": "1769383991316", "hash": "4f9432e29a069abbd0cf8d112013fb069a0f33ec", "bids": [{"price": "0.01", "size": "531671.08"}, {"price": "0.02", "size": "30520.47"}, {"price": "0.03", "size": "15400"}, {"price": "0.04", "size": "6.48"}, {"price": "0.05", "size": "2498.74"}, {"price": "0.09", "size": "900"}, {"price": "0.1", "size": "1533.33"}, {"price": "0.11", "size": "12266.44"}, {"price": "0.12", "size": "192.06"}, {"price": "0.13", "size": "461.53"}, {"price": "0.15", "size": "700"}, {"price": "0.16", "size": "200"}, {"price": "0.17", "size": "188.23"}, {"price": "0.2", "size": "3550"}, {"price": "0.21", "size": "1093.33"}, {"price": "0.22", "size": "2008"}, {"price": "0.26", "size": "100"}, {"price": "0.27", "size": "12591.39"}, {"price": "0.3", "size": "351.42"}, {"price": "0.31", "size": "220"}, {"price": "0.34", "size": "2388.38"}, {"price": "0.35", "size": "5605"}, {"price": "0.38", "size": "12.19"}, {"price": "0.39", "size": "8.31"}, {"price": "0.4", "size": "2690.56"}, {"price": "0.41", "size": "25"}, {"price": "0.42", "size": "200"}, {"price": "0.44", "size": "9.07"}, {"price": "0.45", "size": "2605"}, {"price": "0.49", "size": "500"}, {"price": "0.5", "size": "285"}, {"price": "0.51", "size": "3490"}, {"price": "0.52", "size": "944.56"}, {"price": "0.55", "size": "586.95"}, {"price": "0.56", "size": "100"}, {"price": "0.57", "size": "259.12"}, {"price": "0.59", "size": "3980"}, {"price": "0.6", "size": "21412.32"}, {"price": "0.61", "size": "700"}, {"price": "0.62", "size": "40"}, {"price": "0.64", "size": "42.3"}, {"price": "0.65", "size": "354.38"}, {"price": "0.67", "size": "233.49"}, {"price": "0.7", "size": "2390.3"}, {"price": "0.71", "size": "18055.74"}, {"price": "0.72", "size": "11520"}, {"price": "0.73", "size": "9710"}, {"price": "0.74", "size": "24679.83"}, {"price": "0.75", "size": "21245.79"}, {"price": "0.76", "size": "32235.07"}, {"price": "0.77", "size": "9011.88"}, {"price": "0.78", "size": "819.1"}, {"price": "0.79", "size": "5377.68"}, {"price": "0.8", "size": "19506.12"}, {"price": "0.81", "size": "16062"}, {"price": "0.82", "size": "10565"}, {"price": "0.83", "size": "35132.84"}, {"price": "0.84", "size": "47699.46"}, {"price": "0.85", "size": "38530.15"}], "asks": [{"price": "0.99", "size": "1121182.35"}, {"price": "0.98", "size": "255780.91"}, {"price": "0.97", "size": "302010"}, {"price": "0.96", "size": "118809.12"}, {"price": "0.95", "size": "33480"}, {"price": "0.94", "size": "22354"}, {"price": "0.93", "size": "39273.09"}, {"price": "0.92", "size": "43981"}, {"price": "0.91", "size": "69982.16"}, {"price": "0.9", "size": "94017.56"}, {"price": "0.89", "size": "55852.86"}, {"price": "0.88", "size": "206598.21"}, {"price": "0.87", "size": "44537.19"}, {"price": "0.86", "size": "11528.45"}], "event_type": "book", "last_trade_price": "0.860"}, {"market": "0x1d54eb5eac2cee8f595f3097c65da7d07f8ab5dee63d7c0c6883eb70e1e9af30", "asset_id": "24394670903706558879845790079760859552309100903651562795058188175118941818512", "timestamp": "1769383991316", "hash": "87396595e554affd2894331a35c9c94d8649d934", "bids": [{"price": "0.01", "size": "1121182.35"}, {"price": "0.02", "size": "255780.91"}, {"price": "0.03", "size": "302010"}, {"price": "0.04", "size": "118809.12"}, {"price": "0.05", "size": "33480"}, {"price": "0.06", "size": "22354"}, {"price": "0.07", "size": "39273.09"}, {"price": "0.08", "size": "43981"}, {"price": "0.09", "size": "69982.16"}, {"price": "0.1", "size": "94017.56"}, {"price": "0.11", "size": "55852.86"}, {"price": "0.12", "size": "206598.21"}, {"price": "0.13", "size": "44537.19"}, {"price": "0.14", "size": "11528.45"}], "asks": [{"price": "0.99", "size": "531671.08"}, {"price": "0.98", "size": "30520.47"}, {"price": "0.97", "size": "15400"}, {"price": "0.96", "size": "6.48"}, {"price": "0.95", "size": "2498.74"}, {"price": "0.91", "size": "900"}, {"price": "0.9", "size": "1533.33"}, {"price": "0.89", "size": "12266.44"}, {"price": "0.88", "size": "192.06"}, {"price": "0.87", "size": "461.53"}, {"price": "0.85", "size": "700"}, {"price": "0.84", "size": "200"}, {"price": "0.83", "size": "188.23"}, {"price": "0.8", "size": "3550"}, {"price": "0.79", "size": "1093.33"}, {"price": "0.78", "size": "2008"}, {"price": "0.74", "size": "100"}, {"price": "0.73", "size": "12591.39"}, {"price": "0.7", "size": "351.42"}, {"price": "0.69", "size": "220"}, {"price": "0.66", "size": "2388.38"}, {"price": "0.65", "size": "5605"}, {"price": "0.62", "size": "12.19"}, {"price": "0.61", "size": "8.31"}, {"price": "0.6", "size": "2690.56"}, {"price": "0.59", "size": "25"}, {"price": "0.58", "size": "200"}, {"price": "0.56", "size": "9.07"}, {"price": "0.55", "size": "2605"}, {"price": "0.51", "size": "500"}, {"price": "0.5", "size": "285"}, {"price": "0.49", "size": "3490"}, {"price": "0.48", "size": "944.56"}, {"price": "0.45", "size": "586.95"}, {"price": "0.44", "size": "100"}, {"price": "0.43", "size": "259.12"}, {"price": "0.41", "size": "3980"}, {"price": "0.4", "size": "21412.32"}, {"price": "0.39", "size": "700"}, {"price": "0.38", "size": "40"}, {"price": "0.36", "size": "42.3"}, {"price": "0.35", "size": "354.38"}, {"price": "0.33", "size": "233.49"}, {"price": "0.3", "size": "2390.3"}, {"price": "0.29", "size": "18055.74"}, {"price": "0.28", "size": "11520"}, {"price": "0.27", "size": "9710"}, {"price": "0.26", "size": "24679.83"}, {"price": "0.25", "size": "21245.79"}, {"price": "0.24", "size": "32235.07"}, {"price": "0.23", "size": "9011.88"}, {"price": "0.22", "size": "819.1"}, {"price": "0.21", "size": "5377.68"}, {"price": "0.2", "size": "19506.12"}, {"price": "0.19", "size": "16062"}, {"price": "0.18", "size": "10565"}, {"price": "0.17", "size": "35132.84"}, {"price": "0.16", "size": "47699.46"}, {"price": "0.15", "size": "38530.15"}], "event_type": "book", "last_trade_price": "0.860"}]}
{"_local_timestamp": "2026-01-25T23:33:41.620079+00:00", "data": {"market": "0x1d54eb5eac2cee8f595f3097c65da7d07f8ab5dee63d7c0c6883eb70e1e9af30", "price_changes": [{"asset_id": "24394670903706558879845790079760859552309100903651562795058188175118941818512", "price": "0.1", "size": "94007.56", "side": "BUY", "hash": "fb9f4071677a077fef0eb91031b1dde5e1edf0ca", "best_bid": "0.14", "best_ask": "0.15"}, {"asset_id": "82991837887127223585838300135823820957946688171642633953055760547186260528157", "price": "0.9", "size": "94007.56", "side": "SELL", "hash": "687a7606c278e3d27c0410b8b66dc6e02b7ad814", "best_bid": "0.85", "best_ask": "0.86"}], "timestamp": "1769384021512", "event_type": "price_change"}}
{"_local_timestamp": "2026-01-25T23:33:41.629037+00:00", "data": {"market": "0x1d54eb5eac2cee8f595f3097c65da7d07f8ab5dee63d7c0c6883eb70e1e9af30", "price_changes": [{"asset_id": "24394670903706558879845790079760859552309100903651562795058188175118941818512", "price": "0.11", "size": "55842.86", "side": "BUY", "hash": "8f7b6a3c93c28173397bbb7b6de5d228299d8c6a", "best_bid": "0.14", "best_ask": "0.15"}, {"asset_id": "82991837887127223585838300135823820957946688171642633953055760547186260528157", "price": "0.89", "size": "55842.86", "side": "SELL", "hash": "dd363e4ac2f5508d05a5217df0bda865e1e91a5e", "best_bid": "0.85", "best_ask": "0.86"}], "timestamp": "1769384021544", "event_type": "price_change"}}
{"_local_timestamp": "2026-01-25T23:33:41.648746+00:00", "data": {"market": "0x1d54eb5eac2cee8f595f3097c65da7d07f8ab5dee63d7c0c6883eb70e1e9af30", "price_changes": [{"asset_id": "24394670903706558879845790079760859552309100903651562795058188175118941818512", "price": "0.12", "size": "206588.21", "side": "BUY", "hash": "a141c8fe80e04d4273f0f8e965b959467f98a1fa", "best_bid": "0.14", "best_ask": "0.15"}, {"asset_id": "82991837887127223585838300135823820957946688171642633953055760547186260528157", "price": "0.88", "size": "206588.21", "side": "SELL", "hash": "eccf491e309cbf7d7e969385b66e49b9889c2dfe", "best_bid": "0.85", "best_ask": "0.86"}], "timestamp": "1769384021576", "event_type": "price_change"}}
{"_local_timestamp": "2026-01-25T23:33:41.683006+00:00", "data": {"market": "0x1d54eb5eac2cee8f595f3097c65da7d07f8ab5dee63d7c0c6883eb70e1e9af30", "price_changes": [{"asset_id": "24394670903706558879845790079760859552309100903651562795058188175118941818512", "price": "0.13", "size": "44527.19", "side": "BUY", "hash": "717de45512536209e863c4b9ac6d7bdabe748f69", "best_bid": "0.14", "best_ask": "0.15"}, {"asset_id": "82991837887127223585838300135823820957946688171642633953055760547186260528157", "price": "0.87", "size": "44527.19", "side": "SELL", "hash": "0c0d7b6302dbdd4d432ec60a54debed568495778", "best_bid": "0.85", "best_ask": "0.86"}], "timestamp": "1769384021603", "event_type": "price_change"}}
{"_local_timestamp": "2026-01-25T23:33:41.728620+00:00", "data": {"market": "0x1d54eb5eac2cee8f595f3097c65da7d07f8ab5dee63d7c0c6883eb70e1e9af30", "price_changes": [{"asset_id": "24394670903706558879845790079760859552309100903651562795058188175118941818512", "price": "0.14", "size": "11518.45", "side": "BUY", "hash": "dbc7a2bdfa94f372a3c401329bfabc6d994c7fee", "best_bid": "0.14", "best_ask": "0.15"}, {"asset_id": "82991837887127223585838300135823820957946688171642633953055760547186260528157", "price": "0.86", "size": "11518.45", "side": "SELL", "hash": "1752f856e865c3e0a0e39a7d690ce38e4bb41de6", "best_bid": "0.85", "best_ask": "0.86"}], "timestamp": "1769384021630", "event_type": "price_change"}}
{"_local_timestamp": "2026-01-25T23:33:41.738459+00:00", "data": {"market": "0x1d54eb5eac2cee8f595f3097c65da7d07f8ab5dee63d7c0c6883eb70e1e9af30", "price_changes": [{"asset_id": "82991837887127223585838300135823820957946688171642633953055760547186260528157", "price": "0.81", "size": "16052", "side": "BUY", "hash": "7faf97c5e9f4d89d6999a700e8b409b54e379bb6", "best_bid": "0.85", "best_ask": "0.86"}, {"asset_id": "24394670903706558879845790079760859552309100903651562795058188175118941818512", "price": "0.19", "size": "16052", "side": "SELL", "hash": "c3270a8573a40542ef63708a2bcfeefb45ab5eaf", "best_bid": "0.14", "best_ask": "0.15"}], "timestamp": "1769384021665", "event_type": "price_change"}}
{"_local_timestamp": "2026-01-25T23:33:41.863532+00:00", "data": {"market": "0x1d54eb5eac2cee8f595f3097c65da7d07f8ab5dee63d7c0c6883eb70e1e9af30", "price_changes": [{"asset_id": "82991837887127223585838300135823820957946688171642633953055760547186260528157", "price": "0.82", "size": "10555", "side": "BUY", "hash": "87a9782b4d935ea91777fc2869968f8f14dc6f75", "best_bid": "0.85", "best_ask": "0.86"}, {"asset_id": "24394670903706558879845790079760859552309100903651562795058188175118941818512", "price": "0.18", "size": "10555", "side": "SELL", "hash": "3dd6b3c4f3392a3bb494a6b4a3c036878cecff3d", "best_bid": "0.14", "best_ask": "0.15"}], "timestamp": "1769384021782", "event_type": "price_change"}}
{"_local_timestamp": "2026-01-25T23:33:41.891781+00:00", "data": {"market": "0x1d54eb5eac2cee8f595f3097c65da7d07f8ab5dee63d7c0c6883eb70e1e9af30", "price_changes": [{"asset_id": "82991837887127223585838300135823820957946688171642633953055760547186260528157", "price": "0.83", "size": "35122.84", "side": "BUY", "hash": "8b839cadf6b4acb8fc8f94386bbeec6c5e0bd2ec", "best_bid": "0.85", "best_ask": "0.86"}, {"asset_id": "24394670903706558879845790079760859552309100903651562795058188175118941818512", "price": "0.17", "size": "35122.84", "side": "SELL", "hash": "b71f08ae998d51bcaee600d3ee7628467b765813", "best_bid": "0.14", "best_ask": "0.15"}], "timestamp": "1769384021824", "event_type": "price_change"}}
{"_local_timestamp": "2026-01-25T23:33:42.036196+00:00", "data": {"market": "0x1d54eb5eac2cee8f595f3097c65da7d07f8ab5dee63d7c0c6883eb70e1e9af30", "price_changes": [{"asset_id": "82991837887127223585838300135823820957946688171642633953055760547186260528157", "price": "0.84", "size": "47689.46", "side": "BUY", "hash": "28056bb4af4353baa245d4155291e02c8c0f15fe", "best_bid": "0.85", "best_ask": "0.86"}, {"asset_id": "24394670903706558879845790079760859552309100903651562795058188175118941818512", "price": "0.16", "size": "47689.46", "side": "SELL", "hash": "765007e8821d78bff8c1b42433cfc491e3463125", "best_bid": "0.14", "best_ask": "0.15"}], "timestamp": "1769384021917", "event_type": "price_change"}}
{"_local_timestamp": "2026-01-25T23:33:42.053339+00:00", "data": {"market": "0x1d54eb5eac2cee8f595f3097c65da7d07f8ab5dee63d7c0c6883eb70e1e9af30", "price_changes": [{"asset_id": "82991837887127223585838300135823820957946688171642633953055760547186260528157", "price": "0.85", "size": "38520.15", "side": "BUY", "hash": "fa7d77d640d578a103f22401802afb8d65e784ef", "best_bid": "0.85", "best_ask": "0.86"}, {"asset_id": "24394670903706558879845790079760859552309100903651562795058188175118941818512", "price": "0.15", "size": "38520.15", "side": "SELL", "hash": "885f05a4d3abaa940895670c2444c67d8dd576bd", "best_bid": "0.14", "best_ask": "0.15"}], "timestamp": "1769384021946", "event_type": "price_change"}}
{"_local_timestamp": "2026-01-25T23:34:12.290172+00:00", "data": {"market": "0x1d54eb5eac2cee8f595f3097c65da7d07f8ab5dee63d7c0c6883eb70e1e9af30", "price_changes": [{"asset_id": "24394670903706558879845790079760859552309100903651562795058188175118941818512", "price": "0.14", "size": "11508.45", "side": "BUY", "hash": "39b5bf427acbf03ab5067f94dd35933b05c79feb", "best_bid": "0.14", "best_ask": "0.15"}, {"asset_id": "82991837887127223585838300135823820957946688171642633953055760547186260528157", "price": "0.86", "size": "11508.45", "side": "SELL", "hash": "a3adc24ad8c5f04a53fb8a9559459e9d0527458b", "best_bid": "0.85", "best_ask": "0.86"}], "timestamp": "1769384052083", "event_type": "price_change"}}
{"_local_timestamp": "2026-01-25T23:34:12.575990+00:00", "data": {"market": "0x1d54eb5eac2cee8f595f3097c65da7d07f8ab5dee63d7c0c6883eb70e1e9af30", "price_changes": [{"asset_id": "24394670903706558879845790079760859552309100903651562795058188175118941818512", "price": "0.14", "size": "11518.45", "side": "BUY", "hash": "f1abb6cb3189598b58b9747c83154479ad125e76", "best_bid": "0.14", "best_ask": "0.15"}, {"asset_id": "82991837887127223585838300135823820957946688171642633953055760547186260528157", "price": "0.86", "size": "11518.45", "side": "SELL", "hash": "34901f78792730a9e296c59596838faf5c2a7258", "best_bid": "0.85", "best_ask": "0.86"}], "timestamp": "1769384052345", "event_type": "price_change"}}
{"_local_timestamp": "2026-01-25T23:34:43.191198+00:00", "data": {"market": "0x1d54eb5eac2cee8f595f3097c65da7d07f8ab5dee63d7c0c6883eb70e1e9af30", "price_changes": [{"asset_id": "24394670903706558879845790079760859552309100903651562795058188175118941818512", "price": "0.14", "size": "11508.45", "side": "BUY", "hash": "690619c343f3177d9dddc2337f6c57b7ab3bd712", "best_bid": "0.14", "best_ask": "0.15"}, {"asset_id": "82991837887127223585838300135823820957946688171642633953055760547186260528157", "price": "0.86", "size": "11508.45", "side": "SELL", "hash": "a57899c309a7a941a8274ab04a57f2a26144cc5a", "best_bid": "0.85", "best_ask": "0.86"}], "timestamp": "1769384083125", "event_type": "price_change"}}
{"_local_timestamp": "2026-01-25T23:34:43.449215+00:00", "data": {"market": "0x1d54eb5eac2cee8f595f3097c65da7d07f8ab5dee63d7c0c6883eb70e1e9af30", "price_changes": [{"asset_id": "24394670903706558879845790079760859552309100903651562795058188175118941818512", "price": "0.14", "size": "11518.45", "side": "BUY", "hash": "c81ad28a52f83785acb9c7df85dee2ee43567b1c", "best_bid": "0.14", "best_ask": "0.15"}, {"asset_id": "82991837887127223585838300135823820957946688171642633953055760547186260528157", "price": "0.86", "size": "11518.45", "side": "SELL", "hash": "fbee06629978e15146660b01c9f3775a6b3ab9a8", "best_bid": "0.85", "best_ask": "0.86"}], "timestamp": "1769384083380", "event_type": "price_change"}}
{"_local_timestamp": "2026-01-25T23:35:14.247467+00:00", "data": {"market": "0x1d54eb5eac2cee8f595f3097c65da7d07f8ab5dee63d7c0c6883eb70e1e9af30", "price_changes": [{"asset_id": "24394670903706558879845790079760859552309100903651562795058188175118941818512", "price": "0.14", "size": "11508.45", "side": "BUY", "hash": "39fa21b3ff7ea372089e8ec8e01c7b28b789ff03", "best_bid": "0.14", "best_ask": "0.15"}, {"asset_id": "82991837887127223585838300135823820957946688171642633953055760547186260528157", "price": "0.86", "size": "11508.45", "side": "SELL", "hash": "006b028ecc2cbd95a45f4d3aa3572b3285dc90dc", "best_bid": "0.85", "best_ask": "0.86"}], "timestamp": "1769384114177", "event_type": "price_change"}}
{"_local_timestamp": "2026-01-25T23:35:14.529321+00:00", "data": {"market": "0x1d54eb5eac2cee8f595f3097c65da7d07f8ab5dee63d7c0c6883eb70e1e9af30", "price_changes": [{"asset_id": "24394670903706558879845790079760859552309100903651562795058188175118941818512", "price": "0.14", "size": "11518.45", "side": "BUY", "hash": "c0dd76ccf6a89396c2b8789fd0b088b1c6b97ba4", "best_bid": "0.14", "best_ask": "0.15"}, {"asset_id": "82991837887127223585838300135823820957946688171642633953055760547186260528157", "price": "0.86", "size": "11518.45", "side": "SELL", "hash": "48a9220a20eabc2132e21659fa91045c3436534d", "best_bid": "0.85", "best_ask": "0.86"}], "timestamp": "1769384114467", "event_type": "price_change"}}
{"_local_timestamp": "2026-01-25T23:35:45.271017+00:00", "data": {"market": "0x1d54eb5eac2cee8f595f3097c65da7d07f8ab5dee63d7c0c6883eb70e1e9af30", "price_changes": [{"asset_id": "24394670903706558879845790079760859552309100903651562795058188175118941818512", "price": "0.14", "size": "11508.45", "side": "BUY", "hash": "e5daf2ade6c9bea74a45f1afe9b02aa2ba0b9e83", "best_bid": "0.14", "best_ask": "0.15"}, {"asset_id": "82991837887127223585838300135823820957946688171642633953055760547186260528157", "price": "0.86", "size": "11508.45", "side": "SELL", "hash": "4475bcb46490d1aaf56ac3e37806d3786e489d2e", "best_bid": "0.85", "best_ask": "0.86"}], "timestamp": "1769384145197", "event_type": "price_change"}}
{"_local_timestamp": "2026-01-25T23:35:45.567590+00:00", "data": {"market": "0x1d54eb5eac2cee8f595f3097c65da7d07f8ab5dee63d7c0c6883eb70e1e9af30", "price_changes": [{"asset_id": "24394670903706558879845790079760859552309100903651562795058188175118941818512", "price": "0.14", "size": "11518.45", "side": "BUY", "hash": "eb9db2d17f2408df4827a92ab6d1ae5ed70ddded", "best_bid": "0.14", "best_ask": "0.15"}, {"asset_id": "82991837887127223585838300135823820957946688171642633953055760547186260528157", "price": "0.86", "size": "11518.45", "side": "SELL", "hash": "503ae8e22e93776dfb58dc1178fd18f6daa9bf72", "best_bid": "0.85", "best_ask": "0.86"}], "timestamp": "1769384145498", "event_type": "price_change"}}
{"_local_timestamp": "2026-01-25T23:35:47.092075+00:00", "data": {"market": "0x1d54eb5eac2cee8f595f3097c65da7d07f8ab5dee63d7c0c6883eb70e1e9af30", "price_changes": [{"asset_id": "24394670903706558879845790079760859552309100903651562795058188175118941818512", "price": "0.11", "size": "55833.86", "side": "BUY", "hash": "3cc46bbca8e1dcb87bd56c1bed313e449e322cff", "best_bid": "0.14", "best_ask": "0.15"}, {"asset_id": "82991837887127223585838300135823820957946688171642633953055760547186260528157", "price": "0.89", "size": "55833.86", "side": "SELL", "hash": "bd07b7a7f2dd06b9c6a546493d6d6e321ca90d79", "best_bid": "0.85", "best_ask": "0.86"}], "timestamp": "1769384147003", "event_type": "price_change"}}
{"_local_timestamp": "2026-01-25T23:35:47.092599+00:00", "data": {"market": "0x1d54eb5eac2cee8f595f3097c65da7d07f8ab5dee63d7c0c6883eb70e1e9af30", "price_changes": [{"asset_id": "24394670903706558879845790079760859552309100903651562795058188175118941818512", "price": "0.1", "size": "89237.56", "side": "BUY", "hash": "c2b9203bab918e9d5cd775ae11725e4be5c2d8c4", "best_bid": "0.14", "best_ask": "0.15"}, {"asset_id": "82991837887127223585838300135823820957946688171642633953055760547186260528157", "price": "0.9", "size": "89237.56", "side": "SELL", "hash": "084546986a2ee0a9ae944ec56cf5084934471087", "best_bid": "0.85", "best_ask": "0.86"}], "timestamp": "1769384147005", "event_type": "price_change"}}
{"_local_timestamp": "2026-01-25T23:35:56.221332+00:00", "data": {"market": "0x1d54eb5eac2cee8f595f3097c65da7d07f8ab5dee63d7c0c6883eb70e1e9af30", "price_changes": [{"asset_id": "24394670903706558879845790079760859552309100903651562795058188175118941818512", "price": "0.1", "size": "94007.56", "side": "BUY", "hash": "acda2a4f274bcd11d9bd7edeb52bc1bf65ccdad4", "best_bid": "0.14", "best_ask": "0.15"}, {"asset_id": "82991837887127223585838300135823820957946688171642633953055760547186260528157", "price": "0.9", "size": "94007.56", "side": "SELL", "hash": "226d49b3e0f6c9b9c72a65bc3eeddec71afd70a2", "best_bid": "0.85", "best_ask": "0.86"}], "timestamp": "1769384156149", "event_type": "price_change"}}
{"_local_timestamp": "2026-01-25T23:35:56.221772+00:00", "data": {"market": "0x1d54eb5eac2cee8f595f3097c65da7d07f8ab5dee63d7c0c6883eb70e1e9af30", "price_changes": [{"asset_id": "24394670903706558879845790079760859552309100903651562795058188175118941818512", "price": "0.11", "size": "55842.86", "side": "BUY", "hash": "274f4ab30cf10a5fddeb6a9e0166edb02a5f5ae9", "best_bid": "0.14", "best_ask": "0.15"}, {"asset_id": "82991837887127223585838300135823820957946688171642633953055760547186260528157", "price": "0.89", "size": "55842.86", "side": "SELL", "hash": "0ba700854e0460a84e0a72fbcbd6b35db6457d3e", "best_bid": "0.85", "best_ask": "0.86"}], "timestamp": "1769384156151", "event_type": "price_change"}}
{"_local_timestamp": "2026-01-25T23:36:26.308721+00:00", "data": {"market": "0x1d54eb5eac2cee8f595f3097c65da7d07f8ab5dee63d7c0c6883eb70e1e9af30", "price_changes": [{"asset_id": "24394670903706558879845790079760859552309100903651562795058188175118941818512", "price": "0.14", "size": "11508.45", "side": "BUY", "hash": "375ac2005285fc281006e04765d915eb90df4a4d", "best_bid": "0.14", "best_ask": "0.15"}, {"asset_id": "82991837887127223585838300135823820957946688171642633953055760547186260528157", "price": "0.86", "size": "11508.45", "side": "SELL", "hash": "b8d78a0b7c319a100ee2311670ad8764f37d0964", "best_bid": "0.85", "best_ask": "0.86"}], "timestamp": "1769384186236", "event_type": "price_change"}}
{"_local_timestamp": "2026-01-25T23:36:26.590194+00:00", "data": {"market": "0x1d54eb5eac2cee8f595f3097c65da7d07f8ab5dee63d7c0c6883eb70e1e9af30", "price_changes": [{"asset_id": "24394670903706558879845790079760859552309100903651562795058188175118941818512", "price": "0.14", "size": "11518.45", "side": "BUY", "hash": "54f70089dae84193cbeca3333f4c474442679ead", "best_bid": "0.14", "best_ask": "0.15"}, {"asset_id": "82991837887127223585838300135823820957946688171642633953055760547186260528157", "price": "0.86", "size": "11518.45", "side": "SELL", "hash": "1f0b5d4985dc60d3b9e19342be36bf12d5f105ee", "best_bid": "0.85", "best_ask": "0.86"}], "timestamp": "1769384186518", "event_type": "price_change"}}
{"_local_timestamp": "2026-01-25T23:36:57.678890+00:00", "data": {"market": "0x1d54eb5eac2cee8f595f3097c65da7d07f8ab5dee63d7c0c6883eb70e1e9af30", "price_changes": [{"asset_id": "24394670903706558879845790079760859552309100903651562795058188175118941818512", "price": "0.14", "size": "11508.45", "side": "BUY", "hash": "b8630ca562703483c4f1ef83f8abe5adb65271e0", "best_bid": "0.14", "best_ask": "0.15"}, {"asset_id": "82991837887127223585838300135823820957946688171642633953055760547186260528157", "price": "0.86", "size": "11508.45", "side": "SELL", "hash": "65d5aea043c03e00f59fb574992286b6b6a34bce", "best_bid": "0.85", "best_ask": "0.86"}], "timestamp": "1769384217277", "event_type": "price_change"}}
{"_local_timestamp": "2026-01-25T23:36:57.850304+00:00", "data": {"market": "0x1d54eb5eac2cee8f595f3097c65da7d07f8ab5dee63d7c0c6883eb70e1e9af30", "price_changes": [{"asset_id": "82991837887127223585838300135823820957946688171642633953055760547186260528157", "price": "0.85", "size": "38510.15", "side": "BUY", "hash": "1964f4182209e0e6b7a2a85d1055889095d0f721", "best_bid": "0.85", "best_ask": "0.86"}, {"asset_id": "24394670903706558879845790079760859552309100903651562795058188175118941818512", "price": "0.15", "size": "38510.15", "side": "SELL", "hash": "d4fbbeb11b73928ee426b5c308f939edd65985f2", "best_bid": "0.14", "best_ask": "0.15"}], "timestamp": "1769384217524", "event_type": "price_change"}}
{"_local_timestamp": "2026-01-25T23:36:57.981684+00:00", "data": {"market": "0x1d54eb5eac2cee8f595f3097c65da7d07f8ab5dee63d7c0c6883eb70e1e9af30", "price_changes": [{"asset_id": "82991837887127223585838300135823820957946688171642633953055760547186260528157", "price": "0.85", "size": "38520.15", "side": "BUY", "hash": "b54ff06b069bb65d6a99624441c70c314685775c", "best_bid": "0.85", "best_ask": "0.86"}, {"asset_id": "24394670903706558879845790079760859552309100903651562795058188175118941818512", "price": "0.15", "size": "38520.15", "side": "SELL", "hash": "1e1bb63f1738bd21d8c8266eabdd8988ff7dfe84", "best_bid": "0.14", "best_ask": "0.15"}], "timestamp": "1769384217905", "event_type": "price_change"}}
{"_local_timestamp": "2026-01-25T23:36:58.136840+00:00", "data": {"market": "0x1d54eb5eac2cee8f595f3097c65da7d07f8ab5dee63d7c0c6883eb70e1e9af30", "price_changes": [{"asset_id": "24394670903706558879845790079760859552309100903651562795058188175118941818512", "price": "0.14", "size": "11518.45", "side": "BUY", "hash": "8a1972f7163b768a2f7a1916b07996ba66aa45ab", "best_bid": "0.14", "best_ask": "0.15"}, {"asset_id": "82991837887127223585838300135823820957946688171642633953055760547186260528157", "price": "0.86", "size": "11518.45", "side": "SELL", "hash": "2510f2fa3c6364d95a02a54e45df1d5130571166", "best_bid": "0.85", "best_ask": "0.86"}], "timestamp": "1769384218057", "event_type": "price_change"}}
{"_local_timestamp": "2026-01-25T23:37:28.361221+00:00", "data": {"market": "0x1d54eb5eac2cee8f595f3097c65da7d07f8ab5dee63d7c0c6883eb70e1e9af30", "price_changes": [{"asset_id": "24394670903706558879845790079760859552309100903651562795058188175118941818512", "price": "0.14", "size": "11508.45", "side": "BUY", "hash": "85ccd7f16d75001362d49c68a7bc85b86dce0ff4", "best_bid": "0.14", "best_ask": "0.15"}, {"asset_id": "82991837887127223585838300135823820957946688171642633953055760547186260528157", "price": "0.86", "size": "11508.45", "side": "SELL", "hash": "5438c4a3c87cbf8084898fbdf2ed28b68cb4cb85", "best_bid": "0.85", "best_ask": "0.86"}], "timestamp": "1769384248296", "event_type": "price_change"}}
{"_local_timestamp": "2026-01-25T23:37:28.633002+00:00", "data": {"market": "0x1d54eb5eac2cee8f595f3097c65da7d07f8ab5dee63d7c0c6883eb70e1e9af30", "price_changes": [{"asset_id": "24394670903706558879845790079760859552309100903651562795058188175118941818512", "price": "0.14", "size": "11518.45", "side": "BUY", "hash": "5f32cef673e25b52529177a326c9c8e80061b568", "best_bid": "0.14", "best_ask": "0.15"}, {"asset_id": "82991837887127223585838300135823820957946688171642633953055760547186260528157", "price": "0.86", "size": "11518.45", "side": "SELL", "hash": "96caa0412d9d41918887678f9283d6590772958e", "best_bid": "0.85", "best_ask": "0.86"}], "timestamp": "1769384248566", "event_type": "price_change"}}
{"_local_timestamp": "2026-01-25T23:37:59.392269+00:00", "data": {"market": "0x1d54eb5eac2cee8f595f3097c65da7d07f8ab5dee63d7c0c6883eb70e1e9af30", "price_changes": [{"asset_id": "24394670903706558879845790079760859552309100903651562795058188175118941818512", "price": "0.14", "size": "11508.45", "side": "BUY", "hash": "787f657972e5cab71b01d7e93654071b214ed019", "best_bid": "0.14", "best_ask": "0.15"}, {"asset_id": "82991837887127223585838300135823820957946688171642633953055760547186260528157", "price": "0.86", "size": "11508.45", "side": "SELL", "hash": "b111e497afbaa2f43c890849cc431e0b6ee6e133", "best_bid": "0.85", "best_ask": "0.86"}], "timestamp": "1769384279322", "event_type": "price_change"}}
{"_local_timestamp": "2026-01-25T23:37:59.680112+00:00", "data": {"market": "0x1d54eb5eac2cee8f595f3097c65da7d07f8ab5dee63d7c0c6883eb70e1e9af30", "price_changes": [{"asset_id": "24394670903706558879845790079760859552309100903651562795058188175118941818512", "price": "0.14", "size": "11518.45", "side": "BUY", "hash": "d4aa7b5b481601872b1369a4e32b5ca22809e48e", "best_bid": "0.14", "best_ask": "0.15"}, {"asset_id": "82991837887127223585838300135823820957946688171642633953055760547186260528157", "price": "0.86", "size": "11518.45", "side": "SELL", "hash": "5ae82af722b440377d0f68b86f9ca0fd631e40ca", "best_bid": "0.85", "best_ask": "0.86"}], "timestamp": "1769384279605", "event_type": "price_change"}}
{"_local_timestamp": "2026-01-25T23:38:30.424077+00:00", "data": {"market": "0x1d54eb5eac2cee8f595f3097c65da7d07f8ab5dee63d7c0c6883eb70e1e9af30", "price_changes": [{"asset_id": "24394670903706558879845790079760859552309100903651562795058188175118941818512", "price": "0.14", "size": "11508.45", "side": "BUY", "hash": "02f9a1b1e9add8d41b93049aa3125833377c3bb6", "best_bid": "0.14", "best_ask": "0.15"}, {"asset_id": "82991837887127223585838300135823820957946688171642633953055760547186260528157", "price": "0.86", "size": "11508.45", "side": "SELL", "hash": "282d9e45dabddb5bfcb9c0057a0bc5ee00f79d67", "best_bid": "0.85", "best_ask": "0.86"}], "timestamp": "1769384310357", "event_type": "price_change"}}
{"_local_timestamp": "2026-01-25T23:38:30.715487+00:00", "data": {"market": "0x1d54eb5eac2cee8f595f3097c65da7d07f8ab5dee63d7c0c6883eb70e1e9af30", "price_changes": [{"asset_id": "24394670903706558879845790079760859552309100903651562795058188175118941818512", "price": "0.14", "size": "11518.45", "side": "BUY", "hash": "890c3165c093f03297ea7423cb9ec90b6e1e76e4", "best_bid": "0.14", "best_ask": "0.15"}, {"asset_id": "82991837887127223585838300135823820957946688171642633953055760547186260528157", "price": "0.86", "size": "11518.45", "side": "SELL", "hash": "6765a862470bac2f903482ae1a60933c97e7d57a", "best_bid": "0.85", "best_ask": "0.86"}], "timestamp": "1769384310647", "event_type": "price_change"}}
{"_local_timestamp": "2026-01-25T23:39:01.464337+00:00", "data": {"market": "0x1d54eb5eac2cee8f595f3097c65da7d07f8ab5dee63d7c0c6883eb70e1e9af30", "price_changes": [{"asset_id": "24394670903706558879845790079760859552309100903651562795058188175118941818512", "price": "0.14", "size": "11508.45", "side": "BUY", "hash": "aa1288365463343b7cde7d41df7e7a8864390ecb", "best_bid": "0.14", "best_ask": "0.15"}, {"asset_id": "82991837887127223585838300135823820957946688171642633953055760547186260528157", "price": "0.86", "size": "11508.45", "side": "SELL", "hash": "7d45a364b070868979d017bfd2550628d8ff93fc", "best_bid": "0.85", "best_ask": "0.86"}], "timestamp": "1769384341390", "event_type": "price_change"}}
{"_local_timestamp": "2026-01-25T23:39:01.728732+00:00", "data": {"market": "0x1d54eb5eac2cee8f595f3097c65da7d07f8ab5dee63d7c0c6883eb70e1e9af30", "price_changes": [{"asset_id": "24394670903706558879845790079760859552309100903651562795058188175118941818512", "price": "0.14", "size": "11518.45", "side": "BUY", "hash": "73ffe07e1c6ca77ef33b9b05cad444921e4d3962", "best_bid": "0.14", "best_ask": "0.15"}, {"asset_id": "82991837887127223585838300135823820957946688171642633953055760547186260528157", "price": "0.86", "size": "11518.45", "side": "SELL", "hash": "b47ae704dc271d73476dfba8b5323ec98bcb9bd4", "best_bid": "0.85", "best_ask": "0.86"}], "timestamp": "1769384341662", "event_type": "price_change"}}
{"_local_timestamp": "2026-01-25T23:39:11.932793+00:00", "data": {"market": "0x1d54eb5eac2cee8f595f3097c65da7d07f8ab5dee63d7c0c6883eb70e1e9af30", "price_changes": [{"asset_id": "82991837887127223585838300135823820957946688171642633953055760547186260528157", "price": "0.86", "size": "11474.45", "side": "SELL", "hash": "8e2a974ccf37535145a6f8532e65cf3097332c54", "best_bid": "0.85", "best_ask": "0.86"}, {"asset_id": "24394670903706558879845790079760859552309100903651562795058188175118941818512", "price": "0.14", "size": "11474.45", "side": "BUY", "hash": "b058054b9ce3af9328e3beb95a7d57cf6e69f951", "best_bid": "0.14", "best_ask": "0.15"}], "timestamp": "1769384351864", "event_type": "price_change"}}
{"_local_timestamp": "2026-01-25T23:39:11.933689+00:00", "data": {"market": "0x1d54eb5eac2cee8f595f3097c65da7d07f8ab5dee63d7c0c6883eb70e1e9af30", "asset_id": "24394670903706558879845790079760859552309100903651562795058188175118941818512", "bids": [{"price": "0.01", "size": "1121182.35"}, {"price": "0.02", "size": "255780.91"}, {"price": "0.03", "size": "302010"}, {"price": "0.04", "size": "118809.12"}, {"price": "0.05", "size": "33480"}, {"price": "0.06", "size": "22354"}, {"price": "0.07", "size": "39273.09"}, {"price": "0.08", "size": "43981"}, {"price": "0.09", "size": "69982.16"}, {"price": "0.1", "size": "94007.56"}, {"price": "0.11", "size": "55842.86"}, {"price": "0.12", "size": "206588.21"}, {"price": "0.13", "size": "44527.19"}, {"price": "0.14", "size": "11474.45"}], "asks": [{"price": "0.99", "size": "531671.08"}, {"price": "0.98", "size": "30520.47"}, {"price": "0.97", "size": "15400"}, {"price": "0.96", "size": "6.48"}, {"price": "0.95", "size": "2498.74"}, {"price": "0.91", "size": "900"}, {"price": "0.9", "size": "1533.33"}, {"price": "0.89", "size": "12266.44"}, {"price": "0.88", "size": "192.06"}, {"price": "0.87", "size": "461.53"}, {"price": "0.85", "size": "700"}, {"price": "0.84", "size": "200"}, {"price": "0.83", "size": "188.23"}, {"price": "0.8", "size": "3550"}, {"price": "0.79", "size": "1093.33"}, {"price": "0.78", "size": "2008"}, {"price": "0.74", "size": "100"}, {"price": "0.73", "size": "12591.39"}, {"price": "0.7", "size": "351.42"}, {"price": "0.69", "size": "220"}, {"price": "0.66", "size": "2388.38"}, {"price": "0.65", "size": "5605"}, {"price": "0.62", "size": "12.19"}, {"price": "0.61", "size": "8.31"}, {"price": "0.6", "size": "2690.56"}, {"price": "0.59", "size": "25"}, {"price": "0.58", "size": "200"}, {"price": "0.56", "size": "9.07"}, {"price": "0.55", "size": "2605"}, {"price": "0.51", "size": "500"}, {"price": "0.5", "size": "285"}, {"price": "0.49", "size": "3490"}, {"price": "0.48", "size": "944.56"}, {"price": "0.45", "size": "586.95"}, {"price": "0.44", "size": "100"}, {"price": "0.43", "size": "259.12"}, {"price": "0.41", "size": "3980"}, {"price": "0.4", "size": "21412.32"}, {"price": "0.39", "size": "700"}, {"price": "0.38", "size": "40"}, {"price": "0.36", "size": "42.3"}, {"price": "0.35", "size": "354.38"}, {"price": "0.33", "size": "233.49"}, {"price": "0.3", "size": "2390.3"}, {"price": "0.29", "size": "18055.74"}, {"price": "0.28", "size": "11520"}, {"price": "0.27", "size": "9710"}, {"price": "0.26", "size": "24679.83"}, {"price": "0.25", "size": "21245.79"}, {"price": "0.24", "size": "32235.07"}, {"price": "0.23", "size": "9011.88"}, {"price": "0.22", "size": "819.1"}, {"price": "0.21", "size": "5377.68"}, {"price": "0.2", "size": "19506.12"}, {"price": "0.19", "size": "16052"}, {"price": "0.18", "size": "10555"}, {"price": "0.17", "size": "35122.84"}, {"price": "0.16", "size": "47689.46"}, {"price": "0.15", "size": "38520.15"}], "hash": "b058054b9ce3af9328e3beb95a7d57cf6e69f951", "timestamp": "1769384351864", "event_type": "book"}}
{"_local_timestamp": "2026-01-25T23:39:11.934601+00:00", "data": {"market": "0x1d54eb5eac2cee8f595f3097c65da7d07f8ab5dee63d7c0c6883eb70e1e9af30", "asset_id": "82991837887127223585838300135823820957946688171642633953055760547186260528157", "bids": [{"price": "0.01", "size": "531671.08"}, {"price": "0.02", "size": "30520.47"}, {"price": "0.03", "size": "15400"}, {"price": "0.04", "size": "6.48"}, {"price": "0.05", "size": "2498.74"}, {"price": "0.09", "size": "900"}, {"price": "0.1", "size": "1533.33"}, {"price": "0.11", "size": "12266.44"}, {"price": "0.12", "size": "192.06"}, {"price": "0.13", "size": "461.53"}, {"price": "0.15", "size": "700"}, {"price": "0.16", "size": "200"}, {"price": "0.17", "size": "188.23"}, {"price": "0.2", "size": "3550"}, {"price": "0.21", "size": "1093.33"}, {"price": "0.22", "size": "2008"}, {"price": "0.26", "size": "100"}, {"price": "0.27", "size": "12591.39"}, {"price": "0.3", "size": "351.42"}, {"price": "0.31", "size": "220"}, {"price": "0.34", "size": "2388.38"}, {"price": "0.35", "size": "5605"}, {"price": "0.38", "size": "12.19"}, {"price": "0.39", "size": "8.31"}, {"price": "0.4", "size": "2690.56"}, {"price": "0.41", "size": "25"}, {"price": "0.42", "size": "200"}, {"price": "0.44", "size": "9.07"}, {"price": "0.45", "size": "2605"}, {"price": "0.49", "size": "500"}, {"price": "0.5", "size": "285"}, {"price": "0.51", "size": "3490"}, {"price": "0.52", "size": "944.56"}, {"price": "0.55", "size": "586.95"}, {"price": "0.56", "size": "100"}, {"price": "0.57", "size": "259.12"}, {"price": "0.59", "size": "3980"}, {"price": "0.6", "size": "21412.32"}, {"price": "0.61", "size": "700"}, {"price": "0.62", "size": "40"}, {"price": "0.64", "size": "42.3"}, {"price": "0.65", "size": "354.38"}, {"price": "0.67", "size": "233.49"}, {"price": "0.7", "size": "2390.3"}, {"price": "0.71", "size": "18055.74"}, {"price": "0.72", "size": "11520"}, {"price": "0.73", "size": "9710"}, {"price": "0.74", "size": "24679.83"}, {"price": "0.75", "size": "21245.79"}, {"price": "0.76", "size": "32235.07"}, {"price": "0.77", "size": "9011.88"}, {"price": "0.78", "size": "819.1"}, {"price": "0.79", "size": "5377.68"}, {"price": "0.8", "size": "19506.12"}, {"price": "0.81", "size": "16052"}, {"price": "0.82", "size": "10555"}, {"price": "0.83", "size": "35122.84"}, {"price": "0.84", "size": "47689.46"}, {"price": "0.85", "size": "38520.15"}], "asks": [{"price": "0.99", "size": "1121182.35"}, {"price": "0.98", "size": "255780.91"}, {"price": "0.97", "size": "302010"}, {"price": "0.96", "size": "118809.12"}, {"price": "0.95", "size": "33480"}, {"price": "0.94", "size": "22354"}, {"price": "0.93", "size": "39273.09"}, {"price": "0.92", "size": "43981"}, {"price": "0.91", "size": "69982.16"}, {"price": "0.9", "size": "94007.56"}, {"price": "0.89", "size": "55842.86"}, {"price": "0.88", "size": "206588.21"}, {"price": "0.87", "size": "44527.19"}, {"price": "0.86", "size": "11474.45"}], "hash": "8e2a974ccf37535145a6f8532e65cf3097332c54", "timestamp": "1769384351864", "event_type": "book"}}
{"_local_timestamp": "2026-01-25T23:39:11.964449+00:00", "data": {"market": "0x1d54eb5eac2cee8f595f3097c65da7d07f8ab5dee63d7c0c6883eb70e1e9af30", "asset_id": "24394670903706558879845790079760859552309100903651562795058188175118941818512", "price": "0.14", "size": "44", "fee_rate_bps": "0", "side": "SELL", "timestamp": "1769384351891", "event_type": "last_trade_price", "transaction_hash": "0x2d614bb70ed14f19e93e3178ba0f35a748369dfc91fe6c33a84ab7d376270def"}}
{"_local_timestamp": "2026-01-25T23:39:29.458714+00:00", "data": {"market": "0x1d54eb5eac2cee8f595f3097c65da7d07f8ab5dee63d7c0c6883eb70e1e9af30", "price_changes": [{"asset_id": "24394670903706558879845790079760859552309100903651562795058188175118941818512", "price": "0.14", "size": "11469.45", "side": "BUY", "hash": "bc4faab4f843fac967405df1a38e49f3a18f1212", "best_bid": "0.14", "best_ask": "0.15"}, {"asset_id": "82991837887127223585838300135823820957946688171642633953055760547186260528157", "price": "0.86", "size": "11469.45", "side": "SELL", "hash": "714911e3a7b1c8747cdafbc092b8d96c9300d0c2", "best_bid": "0.85", "best_ask": "0.86"}], "timestamp": "1769384369391", "event_type": "price_change"}}
{"_local_timestamp": "2026-01-25T23:39:29.806235+00:00", "data": {"market": "0x1d54eb5eac2cee8f595f3097c65da7d07f8ab5dee63d7c0c6883eb70e1e9af30", "price_changes": [{"asset_id": "24394670903706558879845790079760859552309100903651562795058188175118941818512", "price": "0.15", "size": "38525.15", "side": "SELL", "hash": "bdb53c3cebbb86c53f95b739f0ad07f9ae634143", "best_bid": "0.14", "best_ask": "0.15"}, {"asset_id": "82991837887127223585838300135823820957946688171642633953055760547186260528157", "price": "0.85", "size": "38525.15", "side": "BUY", "hash": "e842a9b8386779d9e82773f7509afcacc5857c7e", "best_bid": "0.85", "best_ask": "0.86"}], "timestamp": "1769384369741", "event_type": "price_change"}}
{"_local_timestamp": "2026-01-25T23:40:00.223320+00:00", "data": {"market": "0x1d54eb5eac2cee8f595f3097c65da7d07f8ab5dee63d7c0c6883eb70e1e9af30", "price_changes": [{"asset_id": "24394670903706558879845790079760859552309100903651562795058188175118941818512", "price": "0.15", "size": "38520.15", "side": "SELL", "hash": "a0c3b3926d3f9d676a0ac6cc1301b9424af4cac3", "best_bid": "0.14", "best_ask": "0.15"}, {"asset_id": "82991837887127223585838300135823820957946688171642633953055760547186260528157", "price": "0.85", "size": "38520.15", "side": "BUY", "hash": "11472a4d27afcb83b4debe16b918aad0d7789e8b", "best_bid": "0.85", "best_ask": "0.86"}], "timestamp": "1769384400155", "event_type": "price_change"}}
{"_local_timestamp": "2026-01-25T23:40:01.083751+00:00", "data": {"market": "0x1d54eb5eac2cee8f595f3097c65da7d07f8ab5dee63d7c0c6883eb70e1e9af30", "price_changes": [{"asset_id": "24394670903706558879845790079760859552309100903651562795058188175118941818512", "price": "0.08", "size": "37731", "side": "BUY", "hash": "6f7328a3280f926cf6c2c1b68365f3a9acb0354e", "best_bid": "0.14", "best_ask": "0.15"}, {"asset_id": "82991837887127223585838300135823820957946688171642633953055760547186260528157", "price": "0.92", "size": "37731", "side": "SELL", "hash": "2351ff178dd28e3cfc27995e31a8015e6b34ccd9", "best_bid": "0.85", "best_ask": "0.86"}], "timestamp": "1769384401001", "event_type": "price_change"}}
{"_local_timestamp": "2026-01-25T23:40:01.091818+00:00", "data": {"market": "0x1d54eb5eac2cee8f595f3097c65da7d07f8ab5dee63d7c0c6883eb70e1e9af30", "price_changes": [{"asset_id": "24394670903706558879845790079760859552309100903651562795058188175118941818512", "price": "0.06", "size": "14020", "side": "BUY", "hash": "3b0258d7dd91c089fd3041c23129416925198e7e", "best_bid": "0.14", "best_ask": "0.15"}, {"asset_id": "82991837887127223585838300135823820957946688171642633953055760547186260528157", "price": "0.94", "size": "14020", "side": "SELL", "hash": "4de1a9fca6e5c9db838801a954ee056c91456131", "best_bid": "0.85", "best_ask": "0.86"}], "timestamp": "1769384401003", "event_type": "price_change"}}
{"_local_timestamp": "2026-01-25T23:40:01.092345+00:00", "data": {"market": "0x1d54eb5eac2cee8f595f3097c65da7d07f8ab5dee63d7c0c6883eb70e1e9af30", "price_changes": [{"asset_id": "24394670903706558879845790079760859552309100903651562795058188175118941818512", "price": "0.1", "size": "93977.56", "side": "BUY", "hash": "ed3f1785bc7f7b401521a67035fdc14b4e45749b", "best_bid": "0.14", "best_ask": "0.15"}, {"asset_id": "82991837887127223585838300135823820957946688171642633953055760547186260528157", "price": "0.9", "size": "93977.56", "side": "SELL", "hash": "2d34f87b0c827da576eef8e8d6897f40212980b9", "best_bid": "0.85", "best_ask": "0.86"}], "timestamp": "1769384401004", "event_type": "price_change"}}
{"_local_timestamp": "2026-01-25T23:40:15.548649+00:00", "data": {"market": "0x1d54eb5eac2cee8f595f3097c65da7d07f8ab5dee63d7c0c6883eb70e1e9af30", "price_changes": [{"asset_id": "82991837887127223585838300135823820957946688171642633953055760547186260528157", "price": "0.85", "size": "38515.15", "side": "BUY", "hash": "ece15a56ad68a3d6be31df6d8e5bae21c128193e", "best_bid": "0.85", "best_ask": "0.86"}, {"asset_id": "24394670903706558879845790079760859552309100903651562795058188175118941818512", "price": "0.15", "size": "38515.15", "side": "SELL", "hash": "21ed162b0044904a0c85d0deb336320b287c5d20", "best_bid": "0.14", "best_ask": "0.15"}], "timestamp": "1769384415481", "event_type": "price_change"}}
{"_local_timestamp": "2026-01-25T23:40:15.549492+00:00", "data": {"market": "0x1d54eb5eac2cee8f595f3097c65da7d07f8ab5dee63d7c0c6883eb70e1e9af30", "asset_id": "24394670903706558879845790079760859552309100903651562795058188175118941818512", "bids": [{"price": "0.01", "size": "1121182.35"}, {"price": "0.02", "size": "255780.91"}, {"price": "0.03", "size": "302010"}, {"price": "0.04", "size": "118809.12"}, {"price": "0.05", "size": "33480"}, {"price": "0.06", "size": "14020"}, {"price": "0.07", "size": "39273.09"}, {"price": "0.08", "size": "37731"}, {"price": "0.09", "size": "69982.16"}, {"price": "0.1", "size": "93977.56"}, {"price": "0.11", "size": "55842.86"}, {"price": "0.12", "size": "206588.21"}, {"price": "0.13", "size": "44527.19"}, {"price": "0.14", "size": "11469.45"}], "asks": [{"price": "0.99", "size": "531671.08"}, {"price": "0.98", "size": "30520.47"}, {"price": "0.97", "size": "15400"}, {"price": "0.96", "size": "6.48"}, {"price": "0.95", "size": "2498.74"}, {"price": "0.91", "size": "900"}, {"price": "0.9", "size": "1533.33"}, {"price": "0.89", "size": "12266.44"}, {"price": "0.88", "size": "192.06"}, {"price": "0.87", "size": "461.53"}, {"price": "0.85", "size": "700"}, {"price": "0.84", "size": "200"}, {"price": "0.83", "size": "188.23"}, {"price": "0.8", "size": "3550"}, {"price": "0.79", "size": "1093.33"}, {"price": "0.78", "size": "2008"}, {"price": "0.74", "size": "100"}, {"price": "0.73", "size": "12591.39"}, {"price": "0.7", "size": "351.42"}, {"price": "0.69", "size": "220"}, {"price": "0.66", "size": "2388.38"}, {"price": "0.65", "size": "5605"}, {"price": "0.62", "size": "12.19"}, {"price": "0.61", "size": "8.31"}, {"price": "0.6", "size": "2690.56"}, {"price": "0.59", "size": "25"}, {"price": "0.58", "size": "200"}, {"price": "0.56", "size": "9.07"}, {"price": "0.55", "size": "2605"}, {"price": "0.51", "size": "500"}, {"price": "0.5", "size": "285"}, {"price": "0.49", "size": "3490"}, {"price": "0.48", "size": "944.56"}, {"price": "0.45", "size": "586.95"}, {"price": "0.44", "size": "100"}, {"price": "0.43", "size": "259.12"}, {"price": "0.41", "size": "3980"}, {"price": "0.4", "size": "21412.32"}, {"price": "0.39", "size": "700"}, {"price": "0.38", "size": "40"}, {"price": "0.36", "size": "42.3"}, {"price": "0.35", "size": "354.38"}, {"price": "0.33", "size": "233.49"}, {"price": "0.3", "size": "2390.3"}, {"price": "0.29", "size": "18055.74"}, {"price": "0.28", "size": "11520"}, {"price": "0.27", "size": "9710"}, {"price": "0.26", "size": "24679.83"}, {"price": "0.25", "size": "21245.79"}, {"price": "0.24", "size": "32235.07"}, {"price": "0.23", "size": "9011.88"}, {"price": "0.22", "size": "819.1"}, {"price": "0.21", "size": "5377.68"}, {"price": "0.2", "size": "19506.12"}, {"price": "0.19", "size": "16052"}, {"price": "0.18", "size": "10555"}, {"price": "0.17", "size": "35122.84"}, {"price": "0.16", "size": "47689.46"}, {"price": "0.15", "size": "38515.15"}], "hash": "21ed162b0044904a0c85d0deb336320b287c5d20", "timestamp": "1769384415481", "event_type": "book"}}
{"_local_timestamp": "2026-01-25T23:40:15.550308+00:00", "data": {"market": "0x1d54eb5eac2cee8f595f3097c65da7d07f8ab5dee63d7c0c6883eb70e1e9af30", "asset_id": "82991837887127223585838300135823820957946688171642633953055760547186260528157", "bids": [{"price": "0.01", "size": "531671.08"}, {"price": "0.02", "size": "30520.47"}, {"price": "0.03", "size": "15400"}, {"price": "0.04", "size": "6.48"}, {"price": "0.05", "size": "2498.74"}, {"price": "0.09", "size": "900"}, {"price": "0.1", "size": "1533.33"}, {"price": "0.11", "size": "12266.44"}, {"price": "0.12", "size": "192.06"}, {"price": "0.13", "size": "461.53"}, {"price": "0.15", "size": "700"}, {"price": "0.16", "size": "200"}, {"price": "0.17", "size": "188.23"}, {"price": "0.2", "size": "3550"}, {"price": "0.21", "size": "1093.33"}, {"price": "0.22", "size": "2008"}, {"price": "0.26", "size": "100"}, {"price": "0.27", "size": "12591.39"}, {"price": "0.3", "size": "351.42"}, {"price": "0.31", "size": "220"}, {"price": "0.34", "size": "2388.38"}, {"price": "0.35", "size": "5605"}, {"price": "0.38", "size": "12.19"}, {"price": "0.39", "size": "8.31"}, {"price": "0.4", "size": "2690.56"}, {"price": "0.41", "size": "25"}, {"price": "0.42", "size": "200"}, {"price": "0.44", "size": "9.07"}, {"price": "0.45", "size": "2605"}, {"price": "0.49", "size": "500"}, {"price": "0.5", "size": "285"}, {"price": "0.51", "size": "3490"}, {"price": "0.52", "size": "944.56"}, {"price": "0.55", "size": "586.95"}, {"price": "0.56", "size": "100"}, {"price": "0.57", "size": "259.12"}, {"price": "0.59", "size": "3980"}, {"price": "0.6", "size": "21412.32"}, {"price": "0.61", "size": "700"}, {"price": "0.62", "size": "40"}, {"price": "0.64", "size": "42.3"}, {"price": "0.65", "size": "354.38"}, {"price": "0.67", "size": "233.49"}, {"price": "0.7", "size": "2390.3"}, {"price": "0.71", "size": "18055.74"}, {"price": "0.72", "size": "11520"}, {"price": "0.73", "size": "9710"}, {"price": "0.74", "size": "24679.83"}, {"price": "0.75", "size": "21245.79"}, {"price": "0.76", "size": "32235.07"}, {"price": "0.77", "size": "9011.88"}, {"price": "0.78", "size": "819.1"}, {"price": "0.79", "size": "5377.68"}, {"price": "0.8", "size": "19506.12"}, {"price": "0.81", "size": "16052"}, {"price": "0.82", "size": "10555"}, {"price": "0.83", "size": "35122.84"}, {"price": "0.84", "size": "47689.46"}, {"price": "0.85", "size": "38515.15"}], "asks": [{"price": "0.99", "size": "1121182.35"}, {"price": "0.98", "size": "255780.91"}, {"price": "0.97", "size": "302010"}, {"price": "0.96", "size": "118809.12"}, {"price": "0.95", "size": "33480"}, {"price": "0.94", "size": "14020"}, {"price": "0.93", "size": "39273.09"}, {"price": "0.92", "size": "37731"}, {"price": "0.91", "size": "69982.16"}, {"price": "0.9", "size": "93977.56"}, {"price": "0.89", "size": "55842.86"}, {"price": "0.88", "size": "206588.21"}, {"price": "0.87", "size": "44527.19"}, {"price": "0.86", "size": "11469.45"}], "hash": "ece15a56ad68a3d6be31df6d8e5bae21c128193e", "timestamp": "1769384415481", "event_type": "book"}}
{"_local_timestamp": "2026-01-25T23:40:15.588120+00:00", "data": {"market": "0x1d54eb5eac2cee8f595f3097c65da7d07f8ab5dee63d7c0c6883eb70e1e9af30", "asset_id": "24394670903706558879845790079760859552309100903651562795058188175118941818512", "price": "0.15", "size": "5", "fee_rate_bps": "0", "side": "BUY", "timestamp": "1769384415515", "event_type": "last_trade_price", "transaction_hash": "0x1ba103bfb2426ef835222443ffe01210ba9a69ff4846bb5c330fe1ee3aa17cd9"}}
