{"_local_timestamp": "2026-01-25T23:40:31.183922+00:00", "data": [{"market": "0x4d0d43382de6021ce0e906774caf6fc73fbe24078c9a75c6d7ae07b04299f8d0", "asset_id": "15034789978615861173828275849657317503022772763977464100542193185148987457338", "timestamp": "1769384430892", "hash": "bbfd5908725a6d7607bbc49f546cf22e7b738573", "bids": [{"price": "0.001", "size": "278849.89"}, {"price": "0.002", "size": "75791.05"}, {"price": "0.003", "size": "400"}, {"price": "0.004", "size": "32774.2"}, {"price": "0.006", "size": "200"}, {"price": "0.008", "size": "8192"}, {"price": "0.009", "size": "12.32"}, {"price": "0.016", "size": "4096"}, {"price": "0.032", "size": "3248"}, {"price": "0.033", "size": "7.68"}, {"price": "0.05", "size": "30"}, {"price": "0.051", "size": "39"}, {"price": "0.064", "size": "1724"}, {"price": "0.1", "size": "360"}, {"price": "0.101", "size": "100"}, {"price": "0.102", "size": "5.83"}, {"price": "0.128", "size": "256"}, {"price": "0.14", "size": "617.85"}, {"price": "0.15", "size": "5"}, {"price": "0.19", "size": "168.42"}, {"price": "0.2", "size": "355"}, {"price": "0.201", "size": "300"}, {"price": "0.202", "size": "99.99"}, {"price": "0.24", "size": "116.66"}, {"price": "0.25", "size": "5"}, {"price": "0.256", "size": "278"}, {"price": "0.257", "size": "114"}, {"price": "0.29", "size": "89.65"}, {"price": "0.316", "size": "5"}, {"price": "0.34", "size": "70.58"}, {"price": "0.38", "size": "200"}, {"price": "0.39", "size": "126.28"}, {"price": "0.391", "size": "5"}, {"price": "0.501", "size": "100"}, {"price": "0.512", "size": "64"}, {"price": "0.6", "size": "48"}, {"price": "0.693", "size": "100"}, {"price": "0.7", "size": "32"}, {"price": "0.8", "size": "24"}, {"price": "0.85", "size": "184.77"}, {"price": "0.868", "size": "10"}, {"price": "0.88", "size": "100"}, {"price": "0.9", "size": "16"}, {"price": "0.91", "size": "10"}, {"price": "0.912", "size": "100"}, {"price": "0.913", "size": "100"}, {"price": "0.922", "size": "47.1"}, {"price": "0.937", "size": "240"}, {"price": "0.941", "size": "17.54"}, {"price": "0.942", "size": "84.91"}, {"price": "0.95", "size": "12"}, {"price": "0.951", "size": "36"}, {"price": "0.96", "size": "158.83"}], "asks": [{"price": "0.999", "size": "60"}, {"price": "0.998", "size": "245.51"}, {"price": "0.997", "size": "113.04"}, {"price": "0.985", "size": "333.33"}, {"price": "0.984", "size": "13.4"}, {"price": "0.981", "size": "10"}, {"price": "0.98", "size": "200"}, {"price": "0.978", "size": "227.27"}, {"price": "0.977", "size": "11286.96"}, {"price": "0.976", "size": "13.66"}, {"price": "0.966", "size": "147.05"}, {"price": "0.965", "size": "200.03"}, {"price": "0.964", "size": "60"}], "event_type": "book", "last_trade_price": "0.960"}, {"market": "0x4d0d43382de6021ce0e906774caf6fc73fbe24078c9a75c6d7ae07b04299f8d0", "asset_id": "25543244747871931789882457929775858252769380692407983079026060150445462771991", "timestamp": "1769384430892", "hash": "052cc008ed21f76b94c2049a1c8c0fcd4e897767", "bids": [{"price": "0.001", "size": "60"}, {"price": "0.002", "size": "245.51"}, {"price": "0.003", "size": "113.04"}, {"price": "0.015", "size": "333.33"}, {"price": "0.016", "size": "13.4"}, {"price": "0.019", "size": "10"}, {"price": "0.02", "size": "200"}, {"price": "0.022", "size": "227.27"}, {"price": "0.023", "size": "11286.96"}, {"price": "0.024", "size": "13.66"}, {"price": "0.034", "size": "147.05"}, {"price": "0.035", "size": "200.03"}, {"price": "0.036", "size": "60"}], "asks": [{"price": "0.999", "size": "278849.89"}, {"price": "0.998", "size": "75791.05"}, {"price": "0.997", "size": "400"}, {"price": "0.996", "size": "32774.2"}, {"price": "0.994", "size": "200"}, {"price": "0.992", "size": "8192"}, {"price": "0.991", "size": "12.32"}, {"price": "0.984", "size": "4096"}, {"price": "0.968", "size": "3248"}, {"price": "0.967", "size": "7.68"}, {"price": "0.95", "size": "30"}, {"price": "0.949", "size": "39"}, {"price": "0.936", "size": "1724"}, {"price": "0.9", "size": "360"}, {"price": "0.899", "size": "100"}, {"price": "0.898", "size": "5.83"}, {"price": "0.872", "size": "256"}, {"price": "0.86", "size": "617.85"}, {"price": "0.85", "size": "5"}, {"price": "0.81", "size": "168.42"}, {"price": "0.8", "size": "355"}, {"price": "0.799", "size": "300"}, {"price": "0.798", "size": "99.99"}, {"price": "0.76", "size": "116.66"}, {"price": "0.75", "size": "5"}, {"price": "0.744", "size": "278"}, {"price": "0.743", "size": "114"}, {"price": "0.71", "size": "89.65"}, {"price": "0.684", "size": "5"}, {"price": "0.66", "size": "70.58"}, {"price": "0.62", "size": "200"}, {"price": "0.61", "size": "126.28"}, {"price": "0.609", "size": "5"}, {"price": "0.499", "size": "100"}, {"price": "0.488", "size": "64"}, {"price": "0.4", "size": "48"}, {"price": "0.307", "size": "100"}, {"price": "0.3", "size": "32"}, {"price": "0.2", "size": "24"}, {"price": "0.15", "size": "184.77"}, {"price": "0.132", "size": "10"}, {"price": "0.12", "size": "100"}, {"price": "0.1", "size": "16"}, {"price": "0.09", "size": "10"}, {"price": "0.088", "size": "100"}, {"price": "0.087", "size": "100"}, {"price": "0.078", "size": "47.1"}, {"price": "0.063", "size": "240"}, {"price": "0.059", "size": "17.54"}, {"price": "0.058", "size": "84.91"}, {"price": "0.05", "size": "12"}, {"price": "0.049", "size": "36"}, {"price": "0.04", "size": "158.83"}], "event_type": "book", "last_trade_price": "0.960"}]}
{"_local_timestamp": "2026-01-25T23:40:31.453673+00:00", "data": {"market": "0x4d0d43382de6021ce0e906774caf6fc73fbe24078c9a75c6d7ae07b04299f8d0", "price_changes": [{"asset_id": "25543244747871931789882457929775858252769380692407983079026060150445462771991", "price": "0.003", "size": "120.97", "side": "BUY", "hash": "e1ce7270c2baaf473d36c5e4d1415dd677255e34", "best_bid": "0.036", "best_ask": "0.04"}, {"asset_id": "15034789978615861173828275849657317503022772763977464100542193185148987457338", "price": "0.997", "size": "120.97", "side": "SELL", "hash": "e6f52382709848c92e5a805f8dd229e85fc8537d", "best_bid": "0.96", "best_ask": "0.964"}], "timestamp": "1769384431387", "event_type": "price_change"}}
{"_local_timestamp": "2026-01-25T23:40:32.928023+00:00", "data": {"market": "0x4d0d43382de6021ce0e906774caf6fc73fbe24078c9a75c6d7ae07b04299f8d0", "price_changes": [{"asset_id": "15034789978615861173828275849657317503022772763977464100542193185148987457338", "price": "0.316", "size": "0", "side": "BUY", "hash": "4dbebee1dd2ee9128339702db918aa01c36ee3e6", "best_bid": "0.96", "best_ask": "0.964"}, {"asset_id": "25543244747871931789882457929775858252769380692407983079026060150445462771991", "price": "0.684", "size": "0", "side": "SELL", "hash": "f6ccd4fd702ae5a9af635bad27f396377d5a1ac5", "best_bid": "0.036", "best_ask": "0.04"}], "timestamp": "1769384432862", "event_type": "price_change"}}
{"_local_timestamp": "2026-01-25T23:40:33.332041+00:00", "data": {"market": "0x4d0d43382de6021ce0e906774caf6fc73fbe24078c9a75c6d7ae07b04299f8d0", "price_changes": [{"asset_id": "15034789978615861173828275849657317503022772763977464100542193185148987457338", "price": "0.316", "size": "5", "side": "BUY", "hash": "82e4ac545bded7677bb1a535ca90b8b837b66f23", "best_bid": "0.96", "best_ask": "0.964"}, {"asset_id": "25543244747871931789882457929775858252769380692407983079026060150445462771991", "price": "0.684", "size": "5", "side": "SELL", "hash": "ac98825b726d7f1fcf4abe55859ae1a948541c8e", "best_bid": "0.036", "best_ask": "0.04"}], "timestamp": "1769384433255", "event_type": "price_change"}}
{"_local_timestamp": "2026-01-25T23:40:33.351073+00:00", "data": {"market": "0x4d0d43382de6021ce0e906774caf6fc73fbe24078c9a75c6d7ae07b04299f8d0", "price_changes": [{"asset_id": "25543244747871931789882457929775858252769380692407983079026060150445462771991", "price": "0.003", "size": "113.04", "side": "BUY", "hash": "77f01eaa1e30e88d1819a56234f730d11ef3434f", "best_bid": "0.036", "best_ask": "0.04"}, {"asset_id": "15034789978615861173828275849657317503022772763977464100542193185148987457338", "price": "0.997", "size": "113.04", "side": "SELL", "hash": "517f16a437c56dd125092f09158cb33c185cd75c", "best_bid": "0.96", "best_ask": "0.964"}], "timestamp": "1769384433282", "event_type": "price_change"}}
{"_local_timestamp": "2026-01-25T23:40:33.558432+00:00", "data": {"market": "0x4d0d43382de6021ce0e906774caf6fc73fbe24078c9a75c6d7ae07b04299f8d0", "price_changes": [{"asset_id": "25543244747871931789882457929775858252769380692407983079026060150445462771991", "price": "0.003", "size": "120.97", "side": "BUY", "hash": "57b787ac7b24df2e738fc8f0cb95b559b06c610c", "best_bid": "0.036", "best_ask": "0.04"}, {"asset_id": "15034789978615861173828275849657317503022772763977464100542193185148987457338", "price": "0.997", "size": "120.97", "side": "SELL", "hash": "3ee3465f594da534b73e84ca2ce4a302dd267f2b", "best_bid": "0.96", "best_ask": "0.964"}], "timestamp": "1769384433495", "event_type": "price_change"}}
{"_local_timestamp": "2026-01-25T23:40:34.336734+00:00", "data": {"market": "0x4d0d43382de6021ce0e906774caf6fc73fbe24078c9a75c6d7ae07b04299f8d0", "price_changes": [{"asset_id": "25543244747871931789882457929775858252769380692407983079026060150445462771991", "price": "0.003", "size": "113.04", "side": "BUY", "hash": "d16ee6088e72c4e8c972da4a11cd8eab9241cf11", "best_bid": "0.036", "best_ask": "0.04"}, {"asset_id": "15034789978615861173828275849657317503022772763977464100542193185148987457338", "price": "0.997", "size": "113.04", "side": "SELL", "hash": "e50cdb92ca862e9f554a5050131dba0b82953fcc", "best_bid": "0.96", "best_ask": "0.964"}], "timestamp": "1769384434266", "event_type": "price_change"}}
{"_local_timestamp": "2026-01-25T23:40:34.902246+00:00", "data": {"market": "0x4d0d43382de6021ce0e906774caf6fc73fbe24078c9a75c6d7ae07b04299f8d0", "price_changes": [{"asset_id": "25543244747871931789882457929775858252769380692407983079026060150445462771991", "price": "0.003", "size": "120.97", "side": "BUY", "hash": "59df46d94cd648e6f4ee58c00429a4ebc52f92f3", "best_bid": "0.036", "best_ask": "0.04"}, {"asset_id": "15034789978615861173828275849657317503022772763977464100542193185148987457338", "price": "0.997", "size": "120.97", "side": "SELL", "hash": "82a9b7187822703abfac5a6dcc93aada8848d924", "best_bid": "0.96", "best_ask": "0.964"}], "timestamp": "1769384434828", "event_type": "price_change"}}
{"_local_timestamp": "2026-01-25T23:40:35.035669+00:00", "data": {"market": "0x4d0d43382de6021ce0e906774caf6fc73fbe24078c9a75c6d7ae07b04299f8d0", "price_changes": [{"asset_id": "15034789978615861173828275849657317503022772763977464100542193185148987457338", "price": "0.316", "size": "0", "side": "BUY", "hash": "feb2d0892399b8a3eef4d5435622116692494735", "best_bid": "0.96", "best_ask": "0.964"}, {"asset_id": "25543244747871931789882457929775858252769380692407983079026060150445462771991", "price": "0.684", "size": "0", "side": "SELL", "hash": "68306eef544c420c9a354158db3b3265611f2dd7", "best_bid": "0.036", "best_ask": "0.04"}], "timestamp": "1769384434962", "event_type": "price_change"}}
{"_local_timestamp": "2026-01-25T23:40:35.400654+00:00", "data": {"market": "0x4d0d43382de6021ce0e906774caf6fc73fbe24078c9a75c6d7ae07b04299f8d0", "price_changes": [{"asset_id": "15034789978615861173828275849657317503022772763977464100542193185148987457338", "price": "0.316", "size": "5", "side": "BUY", "hash": "9f987c9bc58cb521f382c7c4cea1ee943f2573b6", "best_bid": "0.96", "best_ask": "0.964"}, {"asset_id": "25543244747871931789882457929775858252769380692407983079026060150445462771991", "price": "0.684", "size": "5", "side": "SELL", "hash": "2f604dfe446ea465ac7b13ab6d1b91051a1966bf", "best_bid": "0.036", "best_ask": "0.04"}], "timestamp": "1769384435331", "event_type": "price_change"}}
{"_local_timestamp": "2026-01-25T23:40:36.789688+00:00", "data": {"market": "0x4d0d43382de6021ce0e906774caf6fc73fbe24078c9a75c6d7ae07b04299f8d0", "price_changes": [{"asset_id": "25543244747871931789882457929775858252769380692407983079026060150445462771991", "price": "0.003", "size": "113.04", "side": "BUY", "hash": "7843b7218422ec94d8b070f30089926f36f21a02", "best_bid": "0.036", "best_ask": "0.04"}, {"asset_id": "15034789978615861173828275849657317503022772763977464100542193185148987457338", "price": "0.997", "size": "113.04", "side": "SELL", "hash": "58fd42abbaf61e4e131a7c8956e3f03e7f9b2eef", "best_bid": "0.96", "best_ask": "0.964"}], "timestamp": "1769384436720", "event_type": "price_change"}}
{"_local_timestamp": "2026-01-25T23:40:37.065106+00:00", "data": {"market": "0x4d0d43382de6021ce0e906774caf6fc73fbe24078c9a75c6d7ae07b04299f8d0", "price_changes": [{"asset_id": "25543244747871931789882457929775858252769380692407983079026060150445462771991", "price": "0.003", "size": "120.97", "side": "BUY", "hash": "1efa2c8af12f20f7dc24437372d2ae50fe3e52de", "best_bid": "0.036", "best_ask": "0.04"}, {"asset_id": "15034789978615861173828275849657317503022772763977464100542193185148987457338", "price": "0.997", "size": "120.97", "side": "SELL", "hash": "dd9953ddd49749d9190d93434d3606d228402aa0", "best_bid": "0.96", "best_ask": "0.964"}], "timestamp": "1769384436996", "event_type": "price_change"}}
{"_local_timestamp": "2026-01-25T23:40:38.115780+00:00", "data": {"market": "0x4d0d43382de6021ce0e906774caf6fc73fbe24078c9a75c6d7ae07b04299f8d0", "price_changes": [{"asset_id": "15034789978615861173828275849657317503022772763977464100542193185148987457338", "price": "0.316", "size": "0", "side": "BUY", "hash": "4d9b5a3b7e5c727b1a134abe63248d104aceae44", "best_bid": "0.96", "best_ask": "0.964"}, {"asset_id": "25543244747871931789882457929775858252769380692407983079026060150445462771991", "price": "0.684", "size": "0", "side": "SELL", "hash": "2b474e981d3b69633e75cb6c33a393fc78088148", "best_bid": "0.036", "best_ask": "0.04"}], "timestamp": "1769384438041", "event_type": "price_change"}}
{"_local_timestamp": "2026-01-25T23:40:38.499757+00:00", "data": {"market": "0x4d0d43382de6021ce0e906774caf6fc73fbe24078c9a75c6d7ae07b04299f8d0", "price_changes": [{"asset_id": "15034789978615861173828275849657317503022772763977464100542193185148987457338", "price": "0.316", "size": "5", "side": "BUY", "hash": "35e460dac3f64dae7d7ede8a7c8bbb52f12ebcc6", "best_bid": "0.96", "best_ask": "0.964"}, {"asset_id": "25543244747871931789882457929775858252769380692407983079026060150445462771991", "price": "0.684", "size": "5", "side": "SELL", "hash": "5a12f183720d644e0ac2a31704e42bc092ecc77b", "best_bid": "0.036", "best_ask": "0.04"}], "timestamp": "1769384438428", "event_type": "price_change"}}
{"_local_timestamp": "2026-01-25T23:40:38.532307+00:00", "data": {"market": "0x4d0d43382de6021ce0e906774caf6fc73fbe24078c9a75c6d7ae07b04299f8d0", "price_changes": [{"asset_id": "25543244747871931789882457929775858252769380692407983079026060150445462771991", "price": "0.003", "size": "113.04", "side": "BUY", "hash": "cd8df5948820e797111f34b16e5450c8163f408e", "best_bid": "0.036", "best_ask": "0.04"}, {"asset_id": "15034789978615861173828275849657317503022772763977464100542193185148987457338", "price": "0.997", "size": "113.04", "side": "SELL", "hash": "f943cbb3f94d1f37ca53a01f63c418abb0b4378f", "best_bid": "0.96", "best_ask": "0.964"}], "timestamp": "1769384438466", "event_type": "price_change"}}
{"_local_timestamp": "2026-01-25T23:40:38.940646+00:00", "data": {"market": "0x4d0d43382de6021ce0e906774caf6fc73fbe24078c9a75c6d7ae07b04299f8d0", "price_changes": [{"asset_id": "25543244747871931789882457929775858252769380692407983079026060150445462771991", "price": "0.003", "size": "120.97", "side": "BUY", "hash": "c147865acdc0e59b6b4c5a8dcb7e0ac28028a38d", "best_bid": "0.036", "best_ask": "0.04"}, {"asset_id": "15034789978615861173828275849657317503022772763977464100542193185148987457338", "price": "0.997", "size": "120.97", "side": "SELL", "hash": "4dbb97114d6ff1b1453ecce05b8251ab19e87ead", "best_bid": "0.96", "best_ask": "0.964"}], "timestamp": "1769384438872", "event_type": "price_change"}}
{"_local_timestamp": "2026-01-25T23:40:39.892207+00:00", "data": {"market": "0x4d0d43382de6021ce0e906774caf6fc73fbe24078c9a75c6d7ae07b04299f8d0", "price_changes": [{"asset_id": "25543244747871931789882457929775858252769380692407983079026060150445462771991", "price": "0.003", "size": "113.04", "side": "BUY", "hash": "ae285b7d6bbe908bbde02fa384261e0b81e84349", "best_bid": "0.036", "best_ask": "0.04"}, {"asset_id": "15034789978615861173828275849657317503022772763977464100542193185148987457338", "price": "0.997", "size": "113.04", "side": "SELL", "hash": "93f6215261157980ebb039fccf10d8e956d6cb13", "best_bid": "0.96", "best_ask": "0.964"}], "timestamp": "1769384439819", "event_type": "price_change"}}
{"_local_timestamp": "2026-01-25T23:40:40.220480+00:00", "data": {"market": "0x4d0d43382de6021ce0e906774caf6fc73fbe24078c9a75c6d7ae07b04299f8d0", "price_changes": [{"asset_id": "25543244747871931789882457929775858252769380692407983079026060150445462771991", "price": "0.003", "size": "120.97", "side": "BUY", "hash": "53274002067a456a166277b2e96984bc5cddacba", "best_bid": "0.036", "best_ask": "0.04"}, {"asset_id": "15034789978615861173828275849657317503022772763977464100542193185148987457338", "price": "0.997", "size": "120.97", "side": "SELL", "hash": "219e4851d17e2beede074836a8820e06dde9b12c", "best_bid": "0.96", "best_ask": "0.964"}], "timestamp": "1769384440146", "event_type": "price_change"}}
{"_local_timestamp": "2026-01-25T23:40:41.191596+00:00", "data": {"market": "0x4d0d43382de6021ce0e906774caf6fc73fbe24078c9a75c6d7ae07b04299f8d0", "price_changes": [{"asset_id": "15034789978615861173828275849657317503022772763977464100542193185148987457338", "price": "0.316", "size": "0", "side": "BUY", "hash": "0d1b162337d41dd97746cce54734f5fc32759dc9", "best_bid": "0.96", "best_ask": "0.964"}, {"asset_id": "25543244747871931789882457929775858252769380692407983079026060150445462771991", "price": "0.684", "size": "0", "side": "SELL", "hash": "dd075035ea237573bd62936f64aaf2f64c8d3608", "best_bid": "0.036", "best_ask": "0.04"}], "timestamp": "1769384441107", "event_type": "price_change"}}
{"_local_timestamp": "2026-01-25T23:40:41.476355+00:00", "data": {"market": "0x4d0d43382de6021ce0e906774caf6fc73fbe24078c9a75c6d7ae07b04299f8d0", "price_changes": [{"asset_id": "15034789978615861173828275849657317503022772763977464100542193185148987457338", "price": "0.316", "size": "5", "side": "BUY", "hash": "985b43635e5e0cdddde44bf2259164bbb11f0e7d", "best_bid": "0.96", "best_ask": "0.964"}, {"asset_id": "25543244747871931789882457929775858252769380692407983079026060150445462771991", "price": "0.684", "size": "5", "side": "SELL", "hash": "ac454c6690e57876ad11eb26b92e54276fd7ba93", "best_bid": "0.036", "best_ask": "0.04"}], "timestamp": "1769384441403", "event_type": "price_change"}}
{"_local_timestamp": "2026-01-25T23:40:42.036756+00:00", "data": {"market": "0x4d0d43382de6021ce0e906774caf6fc73fbe24078c9a75c6d7ae07b04299f8d0", "price_changes": [{"asset_id": "25543244747871931789882457929775858252769380692407983079026060150445462771991", "price": "0.003", "size": "113.04", "side": "BUY", "hash": "e5c9564f57178213db7d12b67585e680d2ba80ba", "best_bid": "0.036", "best_ask": "0.04"}, {"asset_id": "15034789978615861173828275849657317503022772763977464100542193185148987457338", "price": "0.997", "size": "113.04", "side": "SELL", "hash": "555c141a97b1c55754d882c4f0f6cfc91e13abc6", "best_bid": "0.96", "best_ask": "0.964"}], "timestamp": "1769384441950", "event_type": "price_change"}}
{"_local_timestamp": "2026-01-25T23:40:42.259992+00:00", "data": {"market": "0x4d0d43382de6021ce0e906774caf6fc73fbe24078c9a75c6d7ae07b04299f8d0", "price_changes": [{"asset_id": "25543244747871931789882457929775858252769380692407983079026060150445462771991", "price": "0.003", "size": "120.97", "side": "BUY", "hash": "f66ff8d302aceeb207fc7a855fcc9c1287eabcd3", "best_bid": "0.036", "best_ask": "0.04"}, {"asset_id": "15034789978615861173828275849657317503022772763977464100542193185148987457338", "price": "0.997", "size": "120.97", "side": "SELL", "hash": "c38ef3eaf491fbe6794f6ad27390754764874d40", "best_bid": "0.96", "best_ask": "0.964"}], "timestamp": "1769384442184", "event_type": "price_change"}}
{"_local_timestamp": "2026-01-25T23:40:43.430310+00:00", "data": {"market": "0x4d0d43382de6021ce0e906774caf6fc73fbe24078c9a75c6d7ae07b04299f8d0", "price_changes": [{"asset_id": "15034789978615861173828275849657317503022772763977464100542193185148987457338", "price": "0.316", "size": "0", "side": "BUY", "hash": "26ba11ce16469e96d3b85b6b0e8856b601c1d4b2", "best_bid": "0.96", "best_ask": "0.964"}, {"asset_id": "25543244747871931789882457929775858252769380692407983079026060150445462771991", "price": "0.684", "size": "0", "side": "SELL", "hash": "55f11ede67702c676e957592a06449f4378b813d", "best_bid": "0.036", "best_ask": "0.04"}], "timestamp": "1769384443357", "event_type": "price_change"}}
{"_local_timestamp": "2026-01-25T23:40:43.805822+00:00", "data": {"market": "0x4d0d43382de6021ce0e906774caf6fc73fbe24078c9a75c6d7ae07b04299f8d0", "price_changes": [{"asset_id": "15034789978615861173828275849657317503022772763977464100542193185148987457338", "price": "0.316", "size": "5", "side": "BUY", "hash": "15c741892e594220def547e2e61212650e0ffa0b", "best_bid": "0.96", "best_ask": "0.964"}, {"asset_id": "25543244747871931789882457929775858252769380692407983079026060150445462771991", "price": "0.684", "size": "5", "side": "SELL", "hash": "21da8f7245d2e31f97ba80380111090dacf07c76", "best_bid": "0.036", "best_ask": "0.04"}], "timestamp": "1769384443732", "event_type": "price_change"}}
{"_local_timestamp": "2026-01-25T23:40:44.272298+00:00", "data": {"market": "0x4d0d43382de6021ce0e906774caf6fc73fbe24078c9a75c6d7ae07b04299f8d0", "price_changes": [{"asset_id": "25543244747871931789882457929775858252769380692407983079026060150445462771991", "price": "0.003", "size": "113.04", "side": "BUY", "hash": "f35cfad47d80db4f480235ee2cd23c635c5fbdb9", "best_bid": "0.036", "best_ask": "0.04"}, {"asset_id": "15034789978615861173828275849657317503022772763977464100542193185148987457338", "price": "0.997", "size": "113.04", "side": "SELL", "hash": "f091cb4f127f07af8d7cdd7486b444ee30dffbf9", "best_bid": "0.96", "best_ask": "0.964"}], "timestamp": "1769384444206", "event_type": "price_change"}}
{"_local_timestamp": "2026-01-25T23:40:44.609837+00:00", "data": {"market": "0x4d0d43382de6021ce0e906774caf6fc73fbe24078c9a75c6d7ae07b04299f8d0", "price_changes": [{"asset_id": "25543244747871931789882457929775858252769380692407983079026060150445462771991", "price": "0.003", "size": "120.97", "side": "BUY", "hash": "1e229b383216edf2b23476f066d0762647beee82", "best_bid": "0.036", "best_ask": "0.04"}, {"asset_id": "15034789978615861173828275849657317503022772763977464100542193185148987457338", "price": "0.997", "size": "120.97", "side": "SELL", "hash": "b318ae08fc72dc2bc9db10d2b3da735f9fdd9516", "best_bid": "0.96", "best_ask": "0.964"}], "timestamp": "1769384444543", "event_type": "price_change"}}
{"_local_timestamp": "2026-01-25T23:40:45.720116+00:00", "data": {"market": "0x4d0d43382de6021ce0e906774caf6fc73fbe24078c9a75c6d7ae07b04299f8d0", "price_changes": [{"asset_id": "25543244747871931789882457929775858252769380692407983079026060150445462771991", "price": "0.003", "size": "113.04", "side": "BUY", "hash": "af1cba8abbfb12e0048400c1eadcbd319ebbf46e", "best_bid": "0.036", "best_ask": "0.04"}, {"asset_id": "15034789978615861173828275849657317503022772763977464100542193185148987457338", "price": "0.997", "size": "113.04", "side": "SELL", "hash": "d01d2f126bf501ca93b13e083153dd9e1da4a85e", "best_bid": "0.96", "best_ask": "0.964"}], "timestamp": "1769384445646", "event_type": "price_change"}}
{"_local_timestamp": "2026-01-25T23:40:46.010323+00:00", "data": {"market": "0x4d0d43382de6021ce0e906774caf6fc73fbe24078c9a75c6d7ae07b04299f8d0", "price_changes": [{"asset_id": "25543244747871931789882457929775858252769380692407983079026060150445462771991", "price": "0.003", "size": "120.97", "side": "BUY", "hash": "fcdc2e404751430e5aa67fdaed793c5c568e182f", "best_bid": "0.036", "best_ask": "0.04"}, {"asset_id": "15034789978615861173828275849657317503022772763977464100542193185148987457338", "price": "0.997", "size": "120.97", "side": "SELL", "hash": "4b62a9e19f6bbec21ca10dbd92179d0ebde2e86d", "best_bid": "0.96", "best_ask": "0.964"}], "timestamp": "1769384445939", "event_type": "price_change"}}
{"_local_timestamp": "2026-01-25T23:40:46.156223+00:00", "data": {"market": "0x4d0d43382de6021ce0e906774caf6fc73fbe24078c9a75c6d7ae07b04299f8d0", "price_changes": [{"asset_id": "15034789978615861173828275849657317503022772763977464100542193185148987457338", "price": "0.316", "size": "0", "side": "BUY", "hash": "4b522202e1c3ce532c9369d083dff0a725efb6d5", "best_bid": "0.96", "best_ask": "0.964"}, {"asset_id": "25543244747871931789882457929775858252769380692407983079026060150445462771991", "price": "0.684", "size": "0", "side": "SELL", "hash": "2d941d4a288f182433bb69bbecbc2d5922a6882b", "best_bid": "0.036", "best_ask": "0.04"}], "timestamp": "1769384446075", "event_type": "price_change"}}
{"_local_timestamp": "2026-01-25T23:40:46.502168+00:00", "data": {"market": "0x4d0d43382de6021ce0e906774caf6fc73fbe24078c9a75c6d7ae07b04299f8d0", "price_changes": [{"asset_id": "15034789978615861173828275849657317503022772763977464100542193185148987457338", "price": "0.316", "size": "5", "side": "BUY", "hash": "d3c980de466a9856844f0b80188b8cf770f0de98", "best_bid": "0.96", "best_ask": "0.964"}, {"asset_id": "25543244747871931789882457929775858252769380692407983079026060150445462771991", "price": "0.684", "size": "5", "side": "SELL", "hash": "cc03edc92f521d43762a834039ce8a180d8ccd15", "best_bid": "0.036", "best_ask": "0.04"}], "timestamp": "1769384446431", "event_type": "price_change"}}
{"_local_timestamp": "2026-01-25T23:40:46.873170+00:00", "data": {"market": "0x4d0d43382de6021ce0e906774caf6fc73fbe24078c9a75c6d7ae07b04299f8d0", "price_changes": [{"asset_id": "25543244747871931789882457929775858252769380692407983079026060150445462771991", "price": "0.003", "size": "113.04", "side": "BUY", "hash": "41eaad4d14c74f3b0548e012d4c777ac6b961d42", "best_bid": "0.036", "best_ask": "0.04"}, {"asset_id": "15034789978615861173828275849657317503022772763977464100542193185148987457338", "price": "0.997", "size": "113.04", "side": "SELL", "hash": "50204d0059d860e356604c2b8f5b860c9b00fe1f", "best_bid": "0.96", "best_ask": "0.964"}], "timestamp": "1769384446802", "event_type": "price_change"}}
{"_local_timestamp": "2026-01-25T23:40:47.314696+00:00", "data": {"market": "0x4d0d43382de6021ce0e906774caf6fc73fbe24078c9a75c6d7ae07b04299f8d0", "price_changes": [{"asset_id": "25543244747871931789882457929775858252769380692407983079026060150445462771991", "price": "0.003", "size": "120.97", "side": "BUY", "hash": "2bf0e70664046e77d043add29d574f3c6cb00f56", "best_bid": "0.036", "best_ask": "0.04"}, {"asset_id": "15034789978615861173828275849657317503022772763977464100542193185148987457338", "price": "0.997", "size": "120.97", "side": "SELL", "hash": "b9bbd59150bbd178daebdf66b869450962627588", "best_bid": "0.96", "best_ask": "0.964"}], "timestamp": "1769384447240", "event_type": "price_change"}}
{"_local_timestamp": "2026-01-25T23:40:48.141221+00:00", "data": {"market": "0x4d0d43382de6021ce0e906774caf6fc73fbe24078c9a75c6d7ae07b04299f8d0", "price_changes": [{"asset_id": "15034789978615861173828275849657317503022772763977464100542193185148987457338", "price": "0.316", "size": "0", "side": "BUY", "hash": "5c20f2d34104d26873e3d99cdef08a556e73e11a", "best_bid": "0.96", "best_ask": "0.964"}, {"asset_id": "25543244747871931789882457929775858252769380692407983079026060150445462771991", "price": "0.684", "size": "0", "side": "SELL", "hash": "bd300f6c2dad280aeaee6ab06a873de1bcfa0fe7", "best_bid": "0.036", "best_ask": "0.04"}], "timestamp": "1769384448076", "event_type": "price_change"}}
{"_local_timestamp": "2026-01-25T23:40:48.515025+00:00", "data": {"market": "0x4d0d43382de6021ce0e906774caf6fc73fbe24078c9a75c6d7ae07b04299f8d0", "price_changes": [{"asset_id": "15034789978615861173828275849657317503022772763977464100542193185148987457338", "price": "0.316", "size": "5", "side": "BUY", "hash": "67b3e1f9d81449546a53f44975ec79d1c780de58", "best_bid": "0.96", "best_ask": "0.964"}, {"asset_id": "25543244747871931789882457929775858252769380692407983079026060150445462771991", "price": "0.684", "size": "5", "side": "SELL", "hash": "3df9bdab22b65a3b2371da5d6061cfe80821f3b0", "best_bid": "0.036", "best_ask": "0.04"}], "timestamp": "1769384448445", "event_type": "price_change"}}
{"_local_timestamp": "2026-01-25T23:40:48.602840+00:00", "data": {"market": "0x4d0d43382de6021ce0e906774caf6fc73fbe24078c9a75c6d7ae07b04299f8d0", "price_changes": [{"asset_id": "25543244747871931789882457929775858252769380692407983079026060150445462771991", "price": "0.003", "size": "113.04", "side": "BUY", "hash": "255e7a935ef927d0d37decb5805aa3c81fd46bf7", "best_bid": "0.036", "best_ask": "0.04"}, {"asset_id": "15034789978615861173828275849657317503022772763977464100542193185148987457338", "price": "0.997", "size": "113.04", "side": "SELL", "hash": "37cdf92e3ac0be893c3669646f038ef3e04dbc39", "best_bid": "0.96", "best_ask": "0.964"}], "timestamp": "1769384448536", "event_type": "price_change"}}
{"_local_timestamp": "2026-01-25T23:40:48.980279+00:00", "data": {"market": "0x4d0d43382de6021ce0e906774caf6fc73fbe24078c9a75c6d7ae07b04299f8d0", "price_changes": [{"asset_id": "25543244747871931789882457929775858252769380692407983079026060150445462771991", "price": "0.003", "size": "120.97", "side": "BUY", "hash": "3bec9ff4ddf0b916af81f9303fb1e1c01d0ec032", "best_bid": "0.036", "best_ask": "0.04"}, {"asset_id": "15034789978615861173828275849657317503022772763977464100542193185148987457338", "price": "0.997", "size": "120.97", "side": "SELL", "hash": "3dc026d1e352ba9497bf545fede59ef59e89249d", "best_bid": "0.96", "best_ask": "0.964"}], "timestamp": "1769384448909", "event_type": "price_change"}}
{"_local_timestamp": "2026-01-25T23:40:50.323573+00:00", "data": {"market": "0x4d0d43382de6021ce0e906774caf6fc73fbe24078c9a75c6d7ae07b04299f8d0", "price_changes": [{"asset_id": "25543244747871931789882457929775858252769380692407983079026060150445462771991", "price": "0.003", "size": "113.04", "side": "BUY", "hash": "4920b346fd226bf9394b293708bb4c4a8a4ab046", "best_bid": "0.036", "best_ask": "0.04"}, {"asset_id": "15034789978615861173828275849657317503022772763977464100542193185148987457338", "price": "0.997", "size": "113.04", "side": "SELL", "hash": "bae89a7c7c3f6428221ae22ae53df6d7c0b97257", "best_bid": "0.96", "best_ask": "0.964"}], "timestamp": "1769384450200", "event_type": "price_change"}}
{"_local_timestamp": "2026-01-25T23:40:50.705746+00:00", "data": {"market": "0x4d0d43382de6021ce0e906774caf6fc73fbe24078c9a75c6d7ae07b04299f8d0", "price_changes": [{"asset_id": "25543244747871931789882457929775858252769380692407983079026060150445462771991", "price": "0.003", "size": "120.97", "side": "BUY", "hash": "c31595ff5449afce3ea82a0135cac471ae56ff09", "best_bid": "0.036", "best_ask": "0.04"}, {"asset_id": "15034789978615861173828275849657317503022772763977464100542193185148987457338", "price": "0.997", "size": "120.97", "side": "SELL", "hash": "1113c471004f49477d1be3d27d66209c64bde690", "best_bid": "0.96", "best_ask": "0.964"}], "timestamp": "1769384450634", "event_type": "price_change"}}
{"_local_timestamp": "2026-01-25T23:40:51.121484+00:00", "data": {"market": "0x4d0d43382de6021ce0e906774caf6fc73fbe24078c9a75c6d7ae07b04299f8d0", "price_changes": [{"asset_id": "15034789978615861173828275849657317503022772763977464100542193185148987457338", "price": "0.316", "size": "0", "side": "BUY", "hash": "2afb90e1e9c44196762ff17ad9be81d6b52f69da", "best_bid": "0.96", "best_ask": "0.964"}, {"asset_id": "25543244747871931789882457929775858252769380692407983079026060150445462771991", "price": "0.684", "size": "0", "side": "SELL", "hash": "bb967e7ace20bfd1087ed24b46586486e4d0a709", "best_bid": "0.036", "best_ask": "0.04"}], "timestamp": "1769384451054", "event_type": "price_change"}}
{"_local_timestamp": "2026-01-25T23:40:51.500970+00:00", "data": {"market": "0x4d0d43382de6021ce0e906774caf6fc73fbe24078c9a75c6d7ae07b04299f8d0", "price_changes": [{"asset_id": "15034789978615861173828275849657317503022772763977464100542193185148987457338", "price": "0.316", "size": "5", "side": "BUY", "hash": "cde1328f58c91b1d6b061c11d31125527a43d493", "best_bid": "0.96", "best_ask": "0.964"}, {"asset_id": "25543244747871931789882457929775858252769380692407983079026060150445462771991", "price": "0.684", "size": "5", "side": "SELL", "hash": "fe1d2e10d0c8cbdee8b5c884c98a631dd4412ca0", "best_bid": "0.036", "best_ask": "0.04"}], "timestamp": "1769384451423", "event_type": "price_change"}}
{"_local_timestamp": "2026-01-25T23:40:51.542744+00:00", "data": {"market": "0x4d0d43382de6021ce0e906774caf6fc73fbe24078c9a75c6d7ae07b04299f8d0", "price_changes": [{"asset_id": "25543244747871931789882457929775858252769380692407983079026060150445462771991", "price": "0.003", "size": "113.04", "side": "BUY", "hash": "038c8b2880e15ae44b0781ef5aeb2a2af7a0150b", "best_bid": "0.036", "best_ask": "0.04"}, {"asset_id": "15034789978615861173828275849657317503022772763977464100542193185148987457338", "price": "0.997", "size": "113.04", "side": "SELL", "hash": "8b44d71211d029e5143c82ad536fde34cd5b3962", "best_bid": "0.96", "best_ask": "0.964"}], "timestamp": "1769384451474", "event_type": "price_change"}}
{"_local_timestamp": "2026-01-25T23:40:51.783573+00:00", "data": {"market": "0x4d0d43382de6021ce0e906774caf6fc73fbe24078c9a75c6d7ae07b04299f8d0", "price_changes": [{"asset_id": "25543244747871931789882457929775858252769380692407983079026060150445462771991", "price": "0.003", "size": "120.97", "side": "BUY", "hash": "b9562aeadf3d4116378caea0061cfbc5a7d094d1", "best_bid": "0.036", "best_ask": "0.04"}, {"asset_id": "15034789978615861173828275849657317503022772763977464100542193185148987457338", "price": "0.997", "size": "120.97", "side": "SELL", "hash": "3c427022d32620dc06ff8c0c9c46b375cc09ca7b", "best_bid": "0.96", "best_ask": "0.964"}], "timestamp": "1769384451717", "event_type": "price_change"}}
{"_local_timestamp": "2026-01-25T23:40:52.831963+00:00", "data": {"market": "0x4d0d43382de6021ce0e906774caf6fc73fbe24078c9a75c6d7ae07b04299f8d0", "price_changes": [{"asset_id": "25543244747871931789882457929775858252769380692407983079026060150445462771991", "price": "0.003", "size": "113.04", "side": "BUY", "hash": "206126f00fc5f67a29deb00a3fc71da17554aaf6", "best_bid": "0.036", "best_ask": "0.04"}, {"asset_id": "15034789978615861173828275849657317503022772763977464100542193185148987457338", "price": "0.997", "size": "113.04", "side": "SELL", "hash": "f2348927fa3ffb183fa1aa7f5794a3544dd25c3a", "best_bid": "0.96", "best_ask": "0.964"}], "timestamp": "1769384452761", "event_type": "price_change"}}
{"_local_timestamp": "2026-01-25T23:40:53.277333+00:00", "data": {"market": "0x4d0d43382de6021ce0e906774caf6fc73fbe24078c9a75c6d7ae07b04299f8d0", "price_changes": [{"asset_id": "25543244747871931789882457929775858252769380692407983079026060150445462771991", "price": "0.003", "size": "120.97", "side": "BUY", "hash": "eff0b2b148178741e51d5f0db42480e4af9157fb", "best_bid": "0.036", "best_ask": "0.04"}, {"asset_id": "15034789978615861173828275849657317503022772763977464100542193185148987457338", "price": "0.997", "size": "120.97", "side": "SELL", "hash": "aa2952c169005049d85951dfdf9950c7c6bd574c", "best_bid": "0.96", "best_ask": "0.964"}], "timestamp": "1769384453207", "event_type": "price_change"}}
{"_local_timestamp": "2026-01-25T23:40:53.887107+00:00", "data": {"market": "0x4d0d43382de6021ce0e906774caf6fc73fbe24078c9a75c6d7ae07b04299f8d0", "price_changes": [{"asset_id": "15034789978615861173828275849657317503022772763977464100542193185148987457338", "price": "0.316", "size": "0", "side": "BUY", "hash": "4e0b17007110f4a158ad6a1c5b15f8c0924227b1", "best_bid": "0.96", "best_ask": "0.964"}, {"asset_id": "25543244747871931789882457929775858252769380692407983079026060150445462771991", "price": "0.684", "size": "0", "side": "SELL", "hash": "6a40f16e7182a1b7d5ec37c162876e6f1b6e7e9f", "best_bid": "0.036", "best_ask": "0.04"}], "timestamp": "1769384453811", "event_type": "price_change"}}
{"_local_timestamp": "2026-01-25T23:40:54.192950+00:00", "data": {"market": "0x4d0d43382de6021ce0e906774caf6fc73fbe24078c9a75c6d7ae07b04299f8d0", "price_changes": [{"asset_id": "15034789978615861173828275849657317503022772763977464100542193185148987457338", "price": "0.316", "size": "5", "side": "BUY", "hash": "82e1e4ce74a289b8d1363698850cca832b805057", "best_bid": "0.96", "best_ask": "0.964"}, {"asset_id": "25543244747871931789882457929775858252769380692407983079026060150445462771991", "price": "0.684", "size": "5", "side": "SELL", "hash": "223c6419546d607d1929c789ab06532a79ee7531", "best_bid": "0.036", "best_ask": "0.04"}], "timestamp": "1769384454125", "event_type": "price_change"}}
{"_local_timestamp": "2026-01-25T23:40:54.300971+00:00", "data": {"market": "0x4d0d43382de6021ce0e906774caf6fc73fbe24078c9a75c6d7ae07b04299f8d0", "price_changes": [{"asset_id": "25543244747871931789882457929775858252769380692407983079026060150445462771991", "price": "0.003", "size": "113.04", "side": "BUY", "hash": "eab6791122c9642204e890ad8aa87d9198377061", "best_bid": "0.036", "best_ask": "0.04"}, {"asset_id": "15034789978615861173828275849657317503022772763977464100542193185148987457338", "price": "0.997", "size": "113.04", "side": "SELL", "hash": "6c79d2d90d2640fd0400ac0a037034d8f060c955", "best_bid": "0.96", "best_ask": "0.964"}], "timestamp": "1769384454235", "event_type": "price_change"}}
{"_local_timestamp": "2026-01-25T23:40:54.526304+00:00", "data": {"market": "0x4d0d43382de6021ce0e906774caf6fc73fbe24078c9a75c6d7ae07b04299f8d0", "price_changes": [{"asset_id": "25543244747871931789882457929775858252769380692407983079026060150445462771991", "price": "0.003", "size": "120.97", "side": "BUY", "hash": "8f10193257db88f24e5c3721c399fdc04ef5f894", "best_bid": "0.036", "best_ask": "0.04"}, {"asset_id": "15034789978615861173828275849657317503022772763977464100542193185148987457338", "price": "0.997", "size": "120.97", "side": "SELL", "hash": "ce353b5a57c63e00bd7224ad8743e9a6b9307780", "best_bid": "0.96", "best_ask": "0.964"}], "timestamp": "1769384454454", "event_type": "price_change"}}
{"_local_timestamp": "2026-01-25T23:40:55.382448+00:00", "data": {"market": "0x4d0d43382de6021ce0e906774caf6fc73fbe24078c9a75c6d7ae07b04299f8d0", "price_changes": [{"asset_id": "25543244747871931789882457929775858252769380692407983079026060150445462771991", "price": "0.003", "size": "113.04", "side": "BUY", "hash": "04155caf4f07d0f0841aebbf0163769a2151560d", "best_bid": "0.036", "best_ask": "0.04"}, {"asset_id": "15034789978615861173828275849657317503022772763977464100542193185148987457338", "price": "0.997", "size": "113.04", "side": "SELL", "hash": "99334dec9b13d123756910bc54b05559478dfc18", "best_bid": "0.96", "best_ask": "0.964"}], "timestamp": "1769384455315", "event_type": "price_change"}}
{"_local_timestamp": "2026-01-25T23:40:55.900208+00:00", "data": {"market": "0x4d0d43382de6021ce0e906774caf6fc73fbe24078c9a75c6d7ae07b04299f8d0", "price_changes": [{"asset_id": "25543244747871931789882457929775858252769380692407983079026060150445462771991", "price": "0.003", "size": "120.97", "side": "BUY", "hash": "0d203efb9cf0afde6297ec6e27dc08e4166df020", "best_bid": "0.036", "best_ask": "0.04"}, {"asset_id": "15034789978615861173828275849657317503022772763977464100542193185148987457338", "price": "0.997", "size": "120.97", "side": "SELL", "hash": "daf732860f2f36777b7c94bb8e344e4298b6decf", "best_bid": "0.96", "best_ask": "0.964"}], "timestamp": "1769384455825", "event_type": "price_change"}}
{"_local_timestamp": "2026-01-25T23:40:56.254047+00:00", "data": {"market": "0x4d0d43382de6021ce0e906774caf6fc73fbe24078c9a75c6d7ae07b04299f8d0", "price_changes": [{"asset_id": "15034789978615861173828275849657317503022772763977464100542193185148987457338", "price": "0.316", "size": "0", "side": "BUY", "hash": "d55f8e013edc5f4ff6d75164f5b66fb182093c08", "best_bid": "0.96", "best_ask": "0.964"}, {"asset_id": "25543244747871931789882457929775858252769380692407983079026060150445462771991", "price": "0.684", "size": "0", "side": "SELL", "hash": "2d8ff53f923abb8ae17951a7b48926e31affd407", "best_bid": "0.036", "best_ask": "0.04"}], "timestamp": "1769384456183", "event_type": "price_change"}}
{"_local_timestamp": "2026-01-25T23:40:56.717004+00:00", "data": {"market": "0x4d0d43382de6021ce0e906774caf6fc73fbe24078c9a75c6d7ae07b04299f8d0", "price_changes": [{"asset_id": "15034789978615861173828275849657317503022772763977464100542193185148987457338", "price": "0.316", "size": "5", "side": "BUY", "hash": "d655657b26cb57c417bc82c6221edadd22bda5e3", "best_bid": "0.96", "best_ask": "0.964"}, {"asset_id": "25543244747871931789882457929775858252769380692407983079026060150445462771991", "price": "0.684", "size": "5", "side": "SELL", "hash": "6b27787bbbbdf2600c073bc07938572f70b505fb", "best_bid": "0.036", "best_ask": "0.04"}], "timestamp": "1769384456646", "event_type": "price_change"}}
{"_local_timestamp": "2026-01-25T23:40:57.163936+00:00", "data": {"market": "0x4d0d43382de6021ce0e906774caf6fc73fbe24078c9a75c6d7ae07b04299f8d0", "price_changes": [{"asset_id": "25543244747871931789882457929775858252769380692407983079026060150445462771991", "price": "0.003", "size": "113.04", "side": "BUY", "hash": "2a26f2b110c51429d57d9ba8681e03d05e07dc8d", "best_bid": "0.036", "best_ask": "0.04"}, {"asset_id": "15034789978615861173828275849657317503022772763977464100542193185148987457338", "price": "0.997", "size": "113.04", "side": "SELL", "hash": "ce6d133d2cbd1598a3f174d5b0fd5162288e562f", "best_bid": "0.96", "best_ask": "0.964"}], "timestamp": "1769384457067", "event_type": "price_change"}}
{"_local_timestamp": "2026-01-25T23:40:57.500028+00:00", "data": {"market": "0x4d0d43382de6021ce0e906774caf6fc73fbe24078c9a75c6d7ae07b04299f8d0", "price_changes": [{"asset_id": "25543244747871931789882457929775858252769380692407983079026060150445462771991", "price": "0.003", "size": "120.97", "side": "BUY", "hash": "520c454ef3db171614c27fd53a58ca7454056356", "best_bid": "0.036", "best_ask": "0.04"}, {"asset_id": "15034789978615861173828275849657317503022772763977464100542193185148987457338", "price": "0.997", "size": "120.97", "side": "SELL", "hash": "e9f70994733f1f6faaff3dbb6e3554bc1299dcc4", "best_bid": "0.96", "best_ask": "0.964"}], "timestamp": "1769384457428", "event_type": "price_change"}}
{"_local_timestamp": "2026-01-25T23:40:59.336346+00:00", "data": {"market": "0x4d0d43382de6021ce0e906774caf6fc73fbe24078c9a75c6d7ae07b04299f8d0", "price_changes": [{"asset_id": "25543244747871931789882457929775858252769380692407983079026060150445462771991", "price": "0.003", "size": "113.04", "side": "BUY", "hash": "6dae51d6cb6a41dec5adaab97f768db5c2618f96", "best_bid": "0.036", "best_ask": "0.04"}, {"asset_id": "15034789978615861173828275849657317503022772763977464100542193185148987457338", "price": "0.997", "size": "113.04", "side": "SELL", "hash": "1fdde1fb98b5b6facccc679026f181e04c0a64b3", "best_bid": "0.96", "best_ask": "0.964"}], "timestamp": "1769384459264", "event_type": "price_change"}}
{"_local_timestamp": "2026-01-25T23:40:59.654218+00:00", "data": {"market": "0x4d0d43382de6021ce0e906774caf6fc73fbe24078c9a75c6d7ae07b04299f8d0", "price_changes": [{"asset_id": "25543244747871931789882457929775858252769380692407983079026060150445462771991", "price": "0.003", "size": "120.97", "side": "BUY", "hash": "f1bde9d7a009b865a19a19cc4169ce68f9650911", "best_bid": "0.036", "best_ask": "0.04"}, {"asset_id": "15034789978615861173828275849657317503022772763977464100542193185148987457338", "price": "0.997", "size": "120.97", "side": "SELL", "hash": "fb974865620592b2b5b94cb07a99531cf3831c0b", "best_bid": "0.96", "best_ask": "0.964"}], "timestamp": "1769384459583", "event_type": "price_change"}}
{"_local_timestamp": "2026-01-25T23:41:00.188245+00:00", "data": {"market": "0x4d0d43382de6021ce0e906774caf6fc73fbe24078c9a75c6d7ae07b04299f8d0", "price_changes": [{"asset_id": "15034789978615861173828275849657317503022772763977464100542193185148987457338", "price": "0.316", "size": "0", "side": "BUY", "hash": "01f7d0734f6b028da90995ec873122ae82bd4943", "best_bid": "0.96", "best_ask": "0.964"}, {"asset_id": "25543244747871931789882457929775858252769380692407983079026060150445462771991", "price": "0.684", "size": "0", "side": "SELL", "hash": "e97a2df1cbd594a221e41b5652e39603433598cd", "best_bid": "0.036", "best_ask": "0.04"}], "timestamp": "1769384460120", "event_type": "price_change"}}
{"_local_timestamp": "2026-01-25T23:41:00.462849+00:00", "data": {"market": "0x4d0d43382de6021ce0e906774caf6fc73fbe24078c9a75c6d7ae07b04299f8d0", "price_changes": [{"asset_id": "15034789978615861173828275849657317503022772763977464100542193185148987457338", "price": "0.316", "size": "5", "side": "BUY", "hash": "293da893cce27d6866b645dadf14364839a8abbc", "best_bid": "0.96", "best_ask": "0.964"}, {"asset_id": "25543244747871931789882457929775858252769380692407983079026060150445462771991", "price": "0.684", "size": "5", "side": "SELL", "hash": "a16a8ca30071e7751759e657a906103a50eb4fb8", "best_bid": "0.036", "best_ask": "0.04"}], "timestamp": "1769384460381", "event_type": "price_change"}}
{"_local_timestamp": "2026-01-25T23:41:00.630229+00:00", "data": {"market": "0x4d0d43382de6021ce0e906774caf6fc73fbe24078c9a75c6d7ae07b04299f8d0", "price_changes": [{"asset_id": "25543244747871931789882457929775858252769380692407983079026060150445462771991", "price": "0.003", "size": "113.04", "side": "BUY", "hash": "0f28388e7558648964f1eb934c63def9aef1181a", "best_bid": "0.036", "best_ask": "0.04"}, {"asset_id": "15034789978615861173828275849657317503022772763977464100542193185148987457338", "price": "0.997", "size": "113.04", "side": "SELL", "hash": "b3620ba948f9aae36d6069a8e52cd99d47fcc30b", "best_bid": "0.96", "best_ask": "0.964"}], "timestamp": "1769384460553", "event_type": "price_change"}}
{"_local_timestamp": "2026-01-25T23:41:00.922721+00:00", "data": {"market": "0x4d0d43382de6021ce0e906774caf6fc73fbe24078c9a75c6d7ae07b04299f8d0", "price_changes": [{"asset_id": "25543244747871931789882457929775858252769380692407983079026060150445462771991", "price": "0.003", "size": "120.97", "side": "BUY", "hash": "3cb0f07003c05d1d30498e13eb9758a27b7d74bb", "best_bid": "0.036", "best_ask": "0.04"}, {"asset_id": "15034789978615861173828275849657317503022772763977464100542193185148987457338", "price": "0.997", "size": "120.97", "side": "SELL", "hash": "37e94f5010f1e27454774711284cc5868864f1b1", "best_bid": "0.96", "best_ask": "0.964"}], "timestamp": "1769384460855", "event_type": "price_change"}}
{"_local_timestamp": "2026-01-25T23:41:01.627819+00:00", "data": {"market": "0x4d0d43382de6021ce0e906774caf6fc73fbe24078c9a75c6d7ae07b04299f8d0", "price_changes": [{"asset_id": "25543244747871931789882457929775858252769380692407983079026060150445462771991", "price": "0.003", "size": "113.04", "side": "BUY", "hash": "27ca7a09c07c26c1381c20bdd2909401db74cd06", "best_bid": "0.036", "best_ask": "0.04"}, {"asset_id": "15034789978615861173828275849657317503022772763977464100542193185148987457338", "price": "0.997", "size": "113.04", "side": "SELL", "hash": "02ded62336c5dd0bba0124e7ca7d6ffa2191876d", "best_bid": "0.96", "best_ask": "0.964"}], "timestamp": "1769384461550", "event_type": "price_change"}}
{"_local_timestamp": "2026-01-25T23:41:02.073124+00:00", "data": {"market": "0x4d0d43382de6021ce0e906774caf6fc73fbe24078c9a75c6d7ae07b04299f8d0", "price_changes": [{"asset_id": "25543244747871931789882457929775858252769380692407983079026060150445462771991", "price": "0.003", "size": "120.97", "side": "BUY", "hash": "8f9b652fe8efa369fcf8b5f9648d00ea43be103c", "best_bid": "0.036", "best_ask": "0.04"}, {"asset_id": "15034789978615861173828275849657317503022772763977464100542193185148987457338", "price": "0.997", "size": "120.97", "side": "SELL", "hash": "3b31b6518febd9c4a3de8ac0014e1d8a4124a2ab", "best_bid": "0.96", "best_ask": "0.964"}], "timestamp": "1769384462000", "event_type": "price_change"}}
{"_local_timestamp": "2026-01-25T23:41:02.613851+00:00", "data": {"market": "0x4d0d43382de6021ce0e906774caf6fc73fbe24078c9a75c6d7ae07b04299f8d0", "price_changes": [{"asset_id": "15034789978615861173828275849657317503022772763977464100542193185148987457338", "price": "0.316", "size": "0", "side": "BUY", "hash": "9a028e569a2199c80dc88be1d9ec520b02e1d17e", "best_bid": "0.96", "best_ask": "0.964"}, {"asset_id": "25543244747871931789882457929775858252769380692407983079026060150445462771991", "price": "0.684", "size": "0", "side": "SELL", "hash": "8e31200566c55b658f12911819cc3e3870c7603d", "best_bid": "0.036", "best_ask": "0.04"}], "timestamp": "1769384462538", "event_type": "price_change"}}
{"_local_timestamp": "2026-01-25T23:41:02.906319+00:00", "data": {"market": "0x4d0d43382de6021ce0e906774caf6fc73fbe24078c9a75c6d7ae07b04299f8d0", "price_changes": [{"asset_id": "15034789978615861173828275849657317503022772763977464100542193185148987457338", "price": "0.316", "size": "5", "side": "BUY", "hash": "2c7224aea98dbd37329f584f13c61153886dcb5d", "best_bid": "0.96", "best_ask": "0.964"}, {"asset_id": "25543244747871931789882457929775858252769380692407983079026060150445462771991", "price": "0.684", "size": "5", "side": "SELL", "hash": "76272accd73c9d53a74a82aeedc1cbd025a8700c", "best_bid": "0.036", "best_ask": "0.04"}], "timestamp": "1769384462829", "event_type": "price_change"}}
{"_local_timestamp": "2026-01-25T23:41:03.185858+00:00", "data": {"market": "0x4d0d43382de6021ce0e906774caf6fc73fbe24078c9a75c6d7ae07b04299f8d0", "price_changes": [{"asset_id": "25543244747871931789882457929775858252769380692407983079026060150445462771991", "price": "0.003", "size": "113.04", "side": "BUY", "hash": "e7917268a938fa6314f05210e34c9a507840ba83", "best_bid": "0.036", "best_ask": "0.04"}, {"asset_id": "15034789978615861173828275849657317503022772763977464100542193185148987457338", "price": "0.997", "size": "113.04", "side": "SELL", "hash": "6aead70e22fab20d02f284385056790b1189e70a", "best_bid": "0.96", "best_ask": "0.964"}], "timestamp": "1769384463119", "event_type": "price_change"}}
{"_local_timestamp": "2026-01-25T23:41:03.675092+00:00", "data": {"market": "0x4d0d43382de6021ce0e906774caf6fc73fbe24078c9a75c6d7ae07b04299f8d0", "price_changes": [{"asset_id": "25543244747871931789882457929775858252769380692407983079026060150445462771991", "price": "0.003", "size": "120.97", "side": "BUY", "hash": "eb7b51652087925161b4417453d3fbeafcdc6932", "best_bid": "0.036", "best_ask": "0.04"}, {"asset_id": "15034789978615861173828275849657317503022772763977464100542193185148987457338", "price": "0.997", "size": "120.97", "side": "SELL", "hash": "10d8cff36ca8375f73b45ca56a70cd9d3b28d48c", "best_bid": "0.96", "best_ask": "0.964"}], "timestamp": "1769384463603", "event_type": "price_change"}}
{"_local_timestamp": "2026-01-25T23:41:04.503936+00:00", "data": {"market": "0x4d0d43382de6021ce0e906774caf6fc73fbe24078c9a75c6d7ae07b04299f8d0", "price_changes": [{"asset_id": "25543244747871931789882457929775858252769380692407983079026060150445462771991", "price": "0.003", "size": "113.04", "side": "BUY", "hash": "9b93c56fe98fe3963b951e6e355a85f08713d34e", "best_bid": "0.036", "best_ask": "0.04"}, {"asset_id": "15034789978615861173828275849657317503022772763977464100542193185148987457338", "price": "0.997", "size": "113.04", "side": "SELL", "hash": "4800293053bd437c024cf42988de6e1a2dd0f5f1", "best_bid": "0.96", "best_ask": "0.964"}], "timestamp": "1769384464432", "event_type": "price_change"}}
{"_local_timestamp": "2026-01-25T23:41:04.842904+00:00", "data": {"market": "0x4d0d43382de6021ce0e906774caf6fc73fbe24078c9a75c6d7ae07b04299f8d0", "price_changes": [{"asset_id": "25543244747871931789882457929775858252769380692407983079026060150445462771991", "price": "0.003", "size": "120.97", "side": "BUY", "hash": "aa57172488321cca70ef77d4ce8ba239efd501b8", "best_bid": "0.036", "best_ask": "0.04"}, {"asset_id": "15034789978615861173828275849657317503022772763977464100542193185148987457338", "price": "0.997", "size": "120.97", "side": "SELL", "hash": "195e91e0bdefa9f22f2fd48ed67bfe141ebeb70b", "best_bid": "0.96", "best_ask": "0.964"}], "timestamp": "1769384464779", "event_type": "price_change"}}
{"_local_timestamp": "2026-01-25T23:41:05.848364+00:00", "data": {"market": "0x4d0d43382de6021ce0e906774caf6fc73fbe24078c9a75c6d7ae07b04299f8d0", "price_changes": [{"asset_id": "15034789978615861173828275849657317503022772763977464100542193185148987457338", "price": "0.316", "size": "0", "side": "BUY", "hash": "1b0c84ab0abfbbe5a502915a0eeb9f04a592f392", "best_bid": "0.96", "best_ask": "0.964"}, {"asset_id": "25543244747871931789882457929775858252769380692407983079026060150445462771991", "price": "0.684", "size": "0", "side": "SELL", "hash": "f6815c09faaa5a25821f9f62d886a2280eac11b8", "best_bid": "0.036", "best_ask": "0.04"}], "timestamp": "1769384465777", "event_type": "price_change"}}
{"_local_timestamp": "2026-01-25T23:41:05.883511+00:00", "data": {"market": "0x4d0d43382de6021ce0e906774caf6fc73fbe24078c9a75c6d7ae07b04299f8d0", "price_changes": [{"asset_id": "25543244747871931789882457929775858252769380692407983079026060150445462771991", "price": "0.003", "size": "113.04", "side": "BUY", "hash": "dd7aec29217d159072125bd7333c8bec0d600deb", "best_bid": "0.036", "best_ask": "0.04"}, {"asset_id": "15034789978615861173828275849657317503022772763977464100542193185148987457338", "price": "0.997", "size": "113.04", "side": "SELL", "hash": "e51497e5987d85188b1ea32e5256a75f333da23f", "best_bid": "0.96", "best_ask": "0.964"}], "timestamp": "1769384465778", "event_type": "price_change"}}
{"_local_timestamp": "2026-01-25T23:41:06.194591+00:00", "data": {"market": "0x4d0d43382de6021ce0e906774caf6fc73fbe24078c9a75c6d7ae07b04299f8d0", "price_changes": [{"asset_id": "15034789978615861173828275849657317503022772763977464100542193185148987457338", "price": "0.316", "size": "5", "side": "BUY", "hash": "7b98ea92107e823aa0e5a47c313cecf401ecd3dd", "best_bid": "0.96", "best_ask": "0.964"}, {"asset_id": "25543244747871931789882457929775858252769380692407983079026060150445462771991", "price": "0.684", "size": "5", "side": "SELL", "hash": "601a7037c6ee29e3756cf32552f31142777400b0", "best_bid": "0.036", "best_ask": "0.04"}], "timestamp": "1769384466079", "event_type": "price_change"}}
{"_local_timestamp": "2026-01-25T23:41:06.205203+00:00", "data": {"market": "0x4d0d43382de6021ce0e906774caf6fc73fbe24078c9a75c6d7ae07b04299f8d0", "price_changes": [{"asset_id": "25543244747871931789882457929775858252769380692407983079026060150445462771991", "price": "0.004", "size": "5.95", "side": "BUY", "hash": "b6672143d9dd36ffd73e0562d667ac4a1cae0cd7", "best_bid": "0.036", "best_ask": "0.04"}, {"asset_id": "15034789978615861173828275849657317503022772763977464100542193185148987457338", "price": "0.996", "size": "5.95", "side": "SELL", "hash": "bc03df2f0da1fd78f05be4a33937ad59b24338c2", "best_bid": "0.96", "best_ask": "0.964"}], "timestamp": "1769384466080", "event_type": "price_change"}}
{"_local_timestamp": "2026-01-25T23:41:07.636221+00:00", "data": {"market": "0x4d0d43382de6021ce0e906774caf6fc73fbe24078c9a75c6d7ae07b04299f8d0", "price_changes": [{"asset_id": "25543244747871931789882457929775858252769380692407983079026060150445462771991", "price": "0.004", "size": "0", "side": "BUY", "hash": "74812feb191d7488eb29787e3dc26b4ee32a709d", "best_bid": "0.036", "best_ask": "0.04"}, {"asset_id": "15034789978615861173828275849657317503022772763977464100542193185148987457338", "price": "0.996", "size": "0", "side": "SELL", "hash": "e885bc7b9b9a07a59795f0ce76db69b61fcfca30", "best_bid": "0.96", "best_ask": "0.964"}], "timestamp": "1769384467564", "event_type": "price_change"}}
{"_local_timestamp": "2026-01-25T23:41:08.055133+00:00", "data": {"market": "0x4d0d43382de6021ce0e906774caf6fc73fbe24078c9a75c6d7ae07b04299f8d0", "price_changes": [{"asset_id": "25543244747871931789882457929775858252769380692407983079026060150445462771991", "price": "0.003", "size": "120.97", "side": "BUY", "hash": "071b41d84a26877a550679ac53f301d5003331f6", "best_bid": "0.036", "best_ask": "0.04"}, {"asset_id": "15034789978615861173828275849657317503022772763977464100542193185148987457338", "price": "0.997", "size": "120.97", "side": "SELL", "hash": "975118a09c7de93f5cff4b06b37e0c2bed9fd91f", "best_bid": "0.96", "best_ask": "0.964"}], "timestamp": "1769384467977", "event_type": "price_change"}}
{"_local_timestamp": "2026-01-25T23:41:08.569570+00:00", "data": {"market": "0x4d0d43382de6021ce0e906774caf6fc73fbe24078c9a75c6d7ae07b04299f8d0", "price_changes": [{"asset_id": "25543244747871931789882457929775858252769380692407983079026060150445462771991", "price": "0.003", "size": "113.04", "side": "BUY", "hash": "50a55a91209c294b1aacbee7dd3f1ea1f05ee1b2", "best_bid": "0.036", "best_ask": "0.04"}, {"asset_id": "15034789978615861173828275849657317503022772763977464100542193185148987457338", "price": "0.997", "size": "113.04", "side": "SELL", "hash": "426047d7e697755f9d8435481016832f66b31372", "best_bid": "0.96", "best_ask": "0.964"}], "timestamp": "1769384468494", "event_type": "price_change"}}
{"_local_timestamp": "2026-01-25T23:41:09.059446+00:00", "data": {"market": "0x4d0d43382de6021ce0e906774caf6fc73fbe24078c9a75c6d7ae07b04299f8d0", "price_changes": [{"asset_id": "25543244747871931789882457929775858252769380692407983079026060150445462771991", "price": "0.003", "size": "120.97", "side": "BUY", "hash": "4f126e699a1c5c8243f2d774170f8ecc412fea73", "best_bid": "0.036", "best_ask": "0.04"}, {"asset_id": "15034789978615861173828275849657317503022772763977464100542193185148987457338", "price": "0.997", "size": "120.97", "side": "SELL", "hash": "efdc96ad5b8b5180f38516f083a0512054e3bc4a", "best_bid": "0.96", "best_ask": "0.964"}], "timestamp": "1769384468981", "event_type": "price_change"}}
{"_local_timestamp": "2026-01-25T23:41:09.617580+00:00", "data": {"market": "0x4d0d43382de6021ce0e906774caf6fc73fbe24078c9a75c6d7ae07b04299f8d0", "price_changes": [{"asset_id": "15034789978615861173828275849657317503022772763977464100542193185148987457338", "price": "0.316", "size": "0", "side": "BUY", "hash": "9d64ed20b76e7a83327b88fa27e51067355a90eb", "best_bid": "0.96", "best_ask": "0.964"}, {"asset_id": "25543244747871931789882457929775858252769380692407983079026060150445462771991", "price": "0.684", "size": "0", "side": "SELL", "hash": "14fa2340a1355076ad27a4c2addcf2c9e88c303b", "best_bid": "0.036", "best_ask": "0.04"}], "timestamp": "1769384469545", "event_type": "price_change"}}
{"_local_timestamp": "2026-01-25T23:41:09.984997+00:00", "data": {"market": "0x4d0d43382de6021ce0e906774caf6fc73fbe24078c9a75c6d7ae07b04299f8d0", "price_changes": [{"asset_id": "15034789978615861173828275849657317503022772763977464100542193185148987457338", "price": "0.316", "size": "5", "side": "BUY", "hash": "ccbd9a01cb95aff093292a5c86758a42b6b8e905", "best_bid": "0.96", "best_ask": "0.964"}, {"asset_id": "25543244747871931789882457929775858252769380692407983079026060150445462771991", "price": "0.684", "size": "5", "side": "SELL", "hash": "f05e00d4cf445e94913ac3a334599508bd16bc05", "best_bid": "0.036", "best_ask": "0.04"}], "timestamp": "1769384469900", "event_type": "price_change"}}
{"_local_timestamp": "2026-01-25T23:41:10.572096+00:00", "data": {"market": "0x4d0d43382de6021ce0e906774caf6fc73fbe24078c9a75c6d7ae07b04299f8d0", "price_changes": [{"asset_id": "25543244747871931789882457929775858252769380692407983079026060150445462771991", "price": "0.003", "size": "113.04", "side": "BUY", "hash": "e99e8e6d35dcc8fc566387ee37701ea1a06017db", "best_bid": "0.036", "best_ask": "0.04"}, {"asset_id": "15034789978615861173828275849657317503022772763977464100542193185148987457338", "price": "0.997", "size": "113.04", "side": "SELL", "hash": "36509c2255c6f6cce3a058d7b48967fcf02b99ac", "best_bid": "0.96", "best_ask": "0.964"}], "timestamp": "1769384470501", "event_type": "price_change"}}
{"_local_timestamp": "2026-01-25T23:41:10.907159+00:00", "data": {"market": "0x4d0d43382de6021ce0e906774caf6fc73fbe24078c9a75c6d7ae07b04299f8d0", "price_changes": [{"asset_id": "25543244747871931789882457929775858252769380692407983079026060150445462771991", "price": "0.004", "size": "5.95", "side": "BUY", "hash": "e35192f9625746d4b5d376c21e91a3e0a1ba1907", "best_bid": "0.036", "best_ask": "0.04"}, {"asset_id": "15034789978615861173828275849657317503022772763977464100542193185148987457338", "price": "0.996", "size": "5.95", "side": "SELL", "hash": "a0fedddcb240eb5803b6de66dc0ad77ce451bef6", "best_bid": "0.96", "best_ask": "0.964"}], "timestamp": "1769384470841", "event_type": "price_change"}}
{"_local_timestamp": "2026-01-25T23:41:11.910962+00:00", "data": {"market": "0x4d0d43382de6021ce0e906774caf6fc73fbe24078c9a75c6d7ae07b04299f8d0", "price_changes": [{"asset_id": "25543244747871931789882457929775858252769380692407983079026060150445462771991", "price": "0.004", "size": "0", "side": "BUY", "hash": "42d984aba6b694b3add3b8614703b8c6481b4922", "best_bid": "0.036", "best_ask": "0.04"}, {"asset_id": "15034789978615861173828275849657317503022772763977464100542193185148987457338", "price": "0.996", "size": "0", "side": "SELL", "hash": "4a4ea958d1c7f442b943387f24cc65a3f39f596e", "best_bid": "0.96", "best_ask": "0.964"}], "timestamp": "1769384471833", "event_type": "price_change"}}
{"_local_timestamp": "2026-01-25T23:41:12.289666+00:00", "data": {"market": "0x4d0d43382de6021ce0e906774caf6fc73fbe24078c9a75c6d7ae07b04299f8d0", "price_changes": [{"asset_id": "25543244747871931789882457929775858252769380692407983079026060150445462771991", "price": "0.003", "size": "120.97", "side": "BUY", "hash": "c51955efa775c083bd4725f02797c77fe23a7a1b", "best_bid": "0.036", "best_ask": "0.04"}, {"asset_id": "15034789978615861173828275849657317503022772763977464100542193185148987457338", "price": "0.997", "size": "120.97", "side": "SELL", "hash": "7d3a85f14a42cab473a860eff09019bd8545627e", "best_bid": "0.96", "best_ask": "0.964"}], "timestamp": "1769384472188", "event_type": "price_change"}}
{"_local_timestamp": "2026-01-25T23:41:13.224952+00:00", "data": {"market": "0x4d0d43382de6021ce0e906774caf6fc73fbe24078c9a75c6d7ae07b04299f8d0", "price_changes": [{"asset_id": "15034789978615861173828275849657317503022772763977464100542193185148987457338", "price": "0.316", "size": "0", "side": "BUY", "hash": "a538a11ab0d3148287a4a65f87ec54a37e993e63", "best_bid": "0.96", "best_ask": "0.964"}, {"asset_id": "25543244747871931789882457929775858252769380692407983079026060150445462771991", "price": "0.684", "size": "0", "side": "SELL", "hash": "824c51b5623e37c498790b59e988e200da02a9c3", "best_bid": "0.036", "best_ask": "0.04"}], "timestamp": "1769384473157", "event_type": "price_change"}}
{"_local_timestamp": "2026-01-25T23:41:13.582854+00:00", "data": {"market": "0x4d0d43382de6021ce0e906774caf6fc73fbe24078c9a75c6d7ae07b04299f8d0", "price_changes": [{"asset_id": "15034789978615861173828275849657317503022772763977464100542193185148987457338", "price": "0.316", "size": "5", "side": "BUY", "hash": "1756e215365df7ff9777a130f20a93810b2f180a", "best_bid": "0.96", "best_ask": "0.964"}, {"asset_id": "25543244747871931789882457929775858252769380692407983079026060150445462771991", "price": "0.684", "size": "5", "side": "SELL", "hash": "f8d50bc0c07c696347ba442d9a3a41b9e980a23a", "best_bid": "0.036", "best_ask": "0.04"}], "timestamp": "1769384473509", "event_type": "price_change"}}
{"_local_timestamp": "2026-01-25T23:41:13.645973+00:00", "data": {"market": "0x4d0d43382de6021ce0e906774caf6fc73fbe24078c9a75c6d7ae07b04299f8d0", "price_changes": [{"asset_id": "25543244747871931789882457929775858252769380692407983079026060150445462771991", "price": "0.003", "size": "113.04", "side": "BUY", "hash": "d970c41a0c80f30d9162caba91e96293d0d877d9", "best_bid": "0.036", "best_ask": "0.04"}, {"asset_id": "15034789978615861173828275849657317503022772763977464100542193185148987457338", "price": "0.997", "size": "113.04", "side": "SELL", "hash": "cdfe019113f03bc07baf3f35c92680c6bf033a1b", "best_bid": "0.96", "best_ask": "0.964"}], "timestamp": "1769384473579", "event_type": "price_change"}}
{"_local_timestamp": "2026-01-25T23:41:13.934898+00:00", "data": {"market": "0x4d0d43382de6021ce0e906774caf6fc73fbe24078c9a75c6d7ae07b04299f8d0", "price_changes": [{"asset_id": "25543244747871931789882457929775858252769380692407983079026060150445462771991", "price": "0.003", "size": "120.97", "side": "BUY", "hash": "1af2bf8fb83473cdc942729eecabc6c33a1e3588", "best_bid": "0.036", "best_ask": "0.04"}, {"asset_id": "15034789978615861173828275849657317503022772763977464100542193185148987457338", "price": "0.997", "size": "120.97", "side": "SELL", "hash": "e5b49596eea7a016ce3cdc51b2857f06560d1efd", "best_bid": "0.96", "best_ask": "0.964"}], "timestamp": "1769384473861", "event_type": "price_change"}}
{"_local_timestamp": "2026-01-25T23:41:14.972934+00:00", "data": {"market": "0x4d0d43382de6021ce0e906774caf6fc73fbe24078c9a75c6d7ae07b04299f8d0", "price_changes": [{"asset_id": "25543244747871931789882457929775858252769380692407983079026060150445462771991", "price": "0.003", "size": "113.04", "side": "BUY", "hash": "c66286ce4b28a26a32602890b5cb80770ddaa004", "best_bid": "0.036", "best_ask": "0.04"}, {"asset_id": "15034789978615861173828275849657317503022772763977464100542193185148987457338", "price": "0.997", "size": "113.04", "side": "SELL", "hash": "7811b0fb30329b2508fe566fe3be7c931451df25", "best_bid": "0.96", "best_ask": "0.964"}], "timestamp": "1769384474909", "event_type": "price_change"}}
{"_local_timestamp": "2026-01-25T23:41:15.291195+00:00", "data": {"market": "0x4d0d43382de6021ce0e906774caf6fc73fbe24078c9a75c6d7ae07b04299f8d0", "price_changes": [{"asset_id": "25543244747871931789882457929775858252769380692407983079026060150445462771991", "price": "0.004", "size": "5.95", "side": "BUY", "hash": "06e964d998de639a1515f2abad4c91cb44ffed42", "best_bid": "0.036", "best_ask": "0.04"}, {"asset_id": "15034789978615861173828275849657317503022772763977464100542193185148987457338", "price": "0.996", "size": "5.95", "side": "SELL", "hash": "08f1b987f3c43e8595c181aa242aedce9b5a9df9", "best_bid": "0.96", "best_ask": "0.964"}], "timestamp": "1769384475222", "event_type": "price_change"}}
{"_local_timestamp": "2026-01-25T23:41:16.489170+00:00", "data": {"market": "0x4d0d43382de6021ce0e906774caf6fc73fbe24078c9a75c6d7ae07b04299f8d0", "price_changes": [{"asset_id": "15034789978615861173828275849657317503022772763977464100542193185148987457338", "price": "0.316", "size": "0", "side": "BUY", "hash": "0ab2d38b5cc5200d1d5e80c2bd9f3feaebf2a5d9", "best_bid": "0.96", "best_ask": "0.964"}, {"asset_id": "25543244747871931789882457929775858252769380692407983079026060150445462771991", "price": "0.684", "size": "0", "side": "SELL", "hash": "b87414aa45ff07032cd33d3bb9ca1e2c1095e3ab", "best_bid": "0.036", "best_ask": "0.04"}], "timestamp": "1769384476422", "event_type": "price_change"}}
{"_local_timestamp": "2026-01-25T23:41:16.494023+00:00", "data": {"market": "0x4d0d43382de6021ce0e906774caf6fc73fbe24078c9a75c6d7ae07b04299f8d0", "price_changes": [{"asset_id": "25543244747871931789882457929775858252769380692407983079026060150445462771991", "price": "0.004", "size": "0", "side": "BUY", "hash": "48bc346e9b68790677c9ca95e2a5337887e38c13", "best_bid": "0.036", "best_ask": "0.04"}, {"asset_id": "15034789978615861173828275849657317503022772763977464100542193185148987457338", "price": "0.996", "size": "0", "side": "SELL", "hash": "02a25e9158ccdc7a0ddcf8b1837ae25ae0cb6e17", "best_bid": "0.96", "best_ask": "0.964"}], "timestamp": "1769384476423", "event_type": "price_change"}}
{"_local_timestamp": "2026-01-25T23:41:16.827728+00:00", "data": {"market": "0x4d0d43382de6021ce0e906774caf6fc73fbe24078c9a75c6d7ae07b04299f8d0", "price_changes": [{"asset_id": "15034789978615861173828275849657317503022772763977464100542193185148987457338", "price": "0.316", "size": "5", "side": "BUY", "hash": "d8779343860fe5c945f58e2bdfb25a7072158eaa", "best_bid": "0.96", "best_ask": "0.964"}, {"asset_id": "25543244747871931789882457929775858252769380692407983079026060150445462771991", "price": "0.684", "size": "5", "side": "SELL", "hash": "4c53665af50c683589ea45d46910433d9d1fb8f4", "best_bid": "0.036", "best_ask": "0.04"}], "timestamp": "1769384476762", "event_type": "price_change"}}
{"_local_timestamp": "2026-01-25T23:41:16.831494+00:00", "data": {"market": "0x4d0d43382de6021ce0e906774caf6fc73fbe24078c9a75c6d7ae07b04299f8d0", "price_changes": [{"asset_id": "25543244747871931789882457929775858252769380692407983079026060150445462771991", "price": "0.003", "size": "120.97", "side": "BUY", "hash": "29b14896d2d886e61ca6f29c1b3824a5637fc797", "best_bid": "0.036", "best_ask": "0.04"}, {"asset_id": "15034789978615861173828275849657317503022772763977464100542193185148987457338", "price": "0.997", "size": "120.97", "side": "SELL", "hash": "b3c1e3f5b345d09e62de47c42c9cb93c5e3fdc05", "best_bid": "0.96", "best_ask": "0.964"}], "timestamp": "1769384476763", "event_type": "price_change"}}
{"_local_timestamp": "2026-01-25T23:41:18.581302+00:00", "data": {"market": "0x4d0d43382de6021ce0e906774caf6fc73fbe24078c9a75c6d7ae07b04299f8d0", "price_changes": [{"asset_id": "25543244747871931789882457929775858252769380692407983079026060150445462771991", "price": "0.003", "size": "113.04", "side": "BUY", "hash": "a6f2ccc3ff72c0848a9bd2512f7c7ebba8db4310", "best_bid": "0.036", "best_ask": "0.04"}, {"asset_id": "15034789978615861173828275849657317503022772763977464100542193185148987457338", "price": "0.997", "size": "113.04", "side": "SELL", "hash": "bccf2ff2183a3d17b79ce46cf5696491d6a6261c", "best_bid": "0.96", "best_ask": "0.964"}], "timestamp": "1769384478502", "event_type": "price_change"}}
{"_local_timestamp": "2026-01-25T23:41:18.973438+00:00", "data": {"market": "0x4d0d43382de6021ce0e906774caf6fc73fbe24078c9a75c6d7ae07b04299f8d0", "price_changes": [{"asset_id": "25543244747871931789882457929775858252769380692407983079026060150445462771991", "price": "0.003", "size": "120.97", "side": "BUY", "hash": "55a74b97decb5290d2c9258d1865b75a0801c173", "best_bid": "0.036", "best_ask": "0.04"}, {"asset_id": "15034789978615861173828275849657317503022772763977464100542193185148987457338", "price": "0.997", "size": "120.97", "side": "SELL", "hash": "20c2cf42836fa852a37d731860632b3da7252ae7", "best_bid": "0.96", "best_ask": "0.964"}], "timestamp": "1769384478907", "event_type": "price_change"}}
{"_local_timestamp": "2026-01-25T23:41:19.005921+00:00", "data": {"market": "0x4d0d43382de6021ce0e906774caf6fc73fbe24078c9a75c6d7ae07b04299f8d0", "price_changes": [{"asset_id": "15034789978615861173828275849657317503022772763977464100542193185148987457338", "price": "0.316", "size": "0", "side": "BUY", "hash": "7aa47569bb5f5dcc747062c1f7003f5f8c15f5ce", "best_bid": "0.96", "best_ask": "0.964"}, {"asset_id": "25543244747871931789882457929775858252769380692407983079026060150445462771991", "price": "0.684", "size": "0", "side": "SELL", "hash": "7a3dcf20326ee45bd0ce3b98316a5d7e06265ad0", "best_bid": "0.036", "best_ask": "0.04"}], "timestamp": "1769384478932", "event_type": "price_change"}}
{"_local_timestamp": "2026-01-25T23:41:19.285421+00:00", "data": {"market": "0x4d0d43382de6021ce0e906774caf6fc73fbe24078c9a75c6d7ae07b04299f8d0", "price_changes": [{"asset_id": "15034789978615861173828275849657317503022772763977464100542193185148987457338", "price": "0.316", "size": "5", "side": "BUY", "hash": "e1e8781ee03b8f385ac0c5c9c24204e960fe8c27", "best_bid": "0.96", "best_ask": "0.964"}, {"asset_id": "25543244747871931789882457929775858252769380692407983079026060150445462771991", "price": "0.684", "size": "5", "side": "SELL", "hash": "df3baa5deb318974091057f2c4fbbe34f1ba4d65", "best_bid": "0.036", "best_ask": "0.04"}], "timestamp": "1769384479216", "event_type": "price_change"}}
{"_local_timestamp": "2026-01-25T23:41:19.903627+00:00", "data": {"market": "0x4d0d43382de6021ce0e906774caf6fc73fbe24078c9a75c6d7ae07b04299f8d0", "price_changes": [{"asset_id": "25543244747871931789882457929775858252769380692407983079026060150445462771991", "price": "0.003", "size": "113.04", "side": "BUY", "hash": "38eab262e5f991136c3012df8131a6d4b7a51380", "best_bid": "0.036", "best_ask": "0.04"}, {"asset_id": "15034789978615861173828275849657317503022772763977464100542193185148987457338", "price": "0.997", "size": "113.04", "side": "SELL", "hash": "470f2a92bc91361338975d8266fc15f7b6eb0f82", "best_bid": "0.96", "best_ask": "0.964"}], "timestamp": "1769384479803", "event_type": "price_change"}}
{"_local_timestamp": "2026-01-25T23:41:20.280882+00:00", "data": {"market": "0x4d0d43382de6021ce0e906774caf6fc73fbe24078c9a75c6d7ae07b04299f8d0", "price_changes": [{"asset_id": "25543244747871931789882457929775858252769380692407983079026060150445462771991", "price": "0.003", "size": "120.97", "side": "BUY", "hash": "32d648f14c9f98126c87b51458786480f9f8c47b", "best_bid": "0.036", "best_ask": "0.04"}, {"asset_id": "15034789978615861173828275849657317503022772763977464100542193185148987457338", "price": "0.997", "size": "120.97", "side": "SELL", "hash": "7493e070939a23f64249ab5797717b31d25a6f85", "best_bid": "0.96", "best_ask": "0.964"}], "timestamp": "1769384480216", "event_type": "price_change"}}
{"_local_timestamp": "2026-01-25T23:41:21.311500+00:00", "data": {"market": "0x4d0d43382de6021ce0e906774caf6fc73fbe24078c9a75c6d7ae07b04299f8d0", "price_changes": [{"asset_id": "25543244747871931789882457929775858252769380692407983079026060150445462771991", "price": "0.003", "size": "113.04", "side": "BUY", "hash": "842cb53533b7fabdb216dbb0eb24d5ad893b29e3", "best_bid": "0.036", "best_ask": "0.04"}, {"asset_id": "15034789978615861173828275849657317503022772763977464100542193185148987457338", "price": "0.997", "size": "113.04", "side": "SELL", "hash": "d95d7985efc399946baa3c61b6240f4095cfb8b3", "best_bid": "0.96", "best_ask": "0.964"}], "timestamp": "1769384481238", "event_type": "price_change"}}
{"_local_timestamp": "2026-01-25T23:41:21.553880+00:00", "data": {"market": "0x4d0d43382de6021ce0e906774caf6fc73fbe24078c9a75c6d7ae07b04299f8d0", "price_changes": [{"asset_id": "25543244747871931789882457929775858252769380692407983079026060150445462771991", "price": "0.003", "size": "120.97", "side": "BUY", "hash": "7304a7b2b1791b7754108cb4a02d4d285081cc13", "best_bid": "0.036", "best_ask": "0.04"}, {"asset_id": "15034789978615861173828275849657317503022772763977464100542193185148987457338", "price": "0.997", "size": "120.97", "side": "SELL", "hash": "f2eb0e2629bca09d15336936e45a84d5405ef118", "best_bid": "0.96", "best_ask": "0.964"}], "timestamp": "1769384481478", "event_type": "price_change"}}
{"_local_timestamp": "2026-01-25T23:41:21.772039+00:00", "data": {"market": "0x4d0d43382de6021ce0e906774caf6fc73fbe24078c9a75c6d7ae07b04299f8d0", "price_changes": [{"asset_id": "15034789978615861173828275849657317503022772763977464100542193185148987457338", "price": "0.316", "size": "0", "side": "BUY", "hash": "44571699bea3a86730af911ca599fa1fae57ef67", "best_bid": "0.96", "best_ask": "0.964"}, {"asset_id": "25543244747871931789882457929775858252769380692407983079026060150445462771991", "price": "0.684", "size": "0", "side": "SELL", "hash": "d7737289c618fbf181b768959f1b55f7d61edf6b", "best_bid": "0.036", "best_ask": "0.04"}], "timestamp": "1769384481697", "event_type": "price_change"}}
{"_local_timestamp": "2026-01-25T23:41:22.025103+00:00", "data": {"market": "0x4d0d43382de6021ce0e906774caf6fc73fbe24078c9a75c6d7ae07b04299f8d0", "price_changes": [{"asset_id": "15034789978615861173828275849657317503022772763977464100542193185148987457338", "price": "0.316", "size": "5", "side": "BUY", "hash": "1b92441e3c8b2f35d44f8b346cccada23a19c879", "best_bid": "0.96", "best_ask": "0.964"}, {"asset_id": "25543244747871931789882457929775858252769380692407983079026060150445462771991", "price": "0.684", "size": "5", "side": "SELL", "hash": "61acdffcd48d4c1fb7c4223217331d49ad59867f", "best_bid": "0.036", "best_ask": "0.04"}], "timestamp": "1769384481947", "event_type": "price_change"}}
{"_local_timestamp": "2026-01-25T23:41:22.236988+00:00", "data": {"market": "0x4d0d43382de6021ce0e906774caf6fc73fbe24078c9a75c6d7ae07b04299f8d0", "price_changes": [{"asset_id": "25543244747871931789882457929775858252769380692407983079026060150445462771991", "price": "0.003", "size": "113.04", "side": "BUY", "hash": "29e0edb274549af2c5880475245c6f3cf4b4d470", "best_bid": "0.036", "best_ask": "0.04"}, {"asset_id": "15034789978615861173828275849657317503022772763977464100542193185148987457338", "price": "0.997", "size": "113.04", "side": "SELL", "hash": "9982bf5f4d5359480c7d40852f588494f733efb5", "best_bid": "0.96", "best_ask": "0.964"}], "timestamp": "1769384482145", "event_type": "price_change"}}
{"_local_timestamp": "2026-01-25T23:41:22.550687+00:00", "data": {"market": "0x4d0d43382de6021ce0e906774caf6fc73fbe24078c9a75c6d7ae07b04299f8d0", "price_changes": [{"asset_id": "25543244747871931789882457929775858252769380692407983079026060150445462771991", "price": "0.003", "size": "120.97", "side": "BUY", "hash": "2fce1365a8a54c6cfb22b2e65ac4e6837d6772f9", "best_bid": "0.036", "best_ask": "0.04"}, {"asset_id": "15034789978615861173828275849657317503022772763977464100542193185148987457338", "price": "0.997", "size": "120.97", "side": "SELL", "hash": "befa158601a5ce37e474471c8d24cef7c331035f", "best_bid": "0.96", "best_ask": "0.964"}], "timestamp": "1769384482479", "event_type": "price_change"}}
{"_local_timestamp": "2026-01-25T23:41:23.928268+00:00", "data": {"market": "0x4d0d43382de6021ce0e906774caf6fc73fbe24078c9a75c6d7ae07b04299f8d0", "price_changes": [{"asset_id": "25543244747871931789882457929775858252769380692407983079026060150445462771991", "price": "0.003", "size": "113.04", "side": "BUY", "hash": "a57c25bce00ad5f92bcea4d1095c433c54240e46", "best_bid": "0.036", "best_ask": "0.04"}, {"asset_id": "15034789978615861173828275849657317503022772763977464100542193185148987457338", "price": "0.997", "size": "113.04", "side": "SELL", "hash": "b08df0099f726065070b3721d78365687d4d249c", "best_bid": "0.96", "best_ask": "0.964"}], "timestamp": "1769384483862", "event_type": "price_change"}}
{"_local_timestamp": "2026-01-25T23:41:24.248793+00:00", "data": {"market": "0x4d0d43382de6021ce0e906774caf6fc73fbe24078c9a75c6d7ae07b04299f8d0", "price_changes": [{"asset_id": "25543244747871931789882457929775858252769380692407983079026060150445462771991", "price": "0.003", "size": "120.97", "side": "BUY", "hash": "b16cbebc0f418d9f2f65b442ccdea0ddb53405ee", "best_bid": "0.036", "best_ask": "0.04"}, {"asset_id": "15034789978615861173828275849657317503022772763977464100542193185148987457338", "price": "0.997", "size": "120.97", "side": "SELL", "hash": "5748730bba05ace09b06e3d22b432677b22d9c46", "best_bid": "0.96", "best_ask": "0.964"}], "timestamp": "1769384484180", "event_type": "price_change"}}
{"_local_timestamp": "2026-01-25T23:41:24.798866+00:00", "data": {"market": "0x4d0d43382de6021ce0e906774caf6fc73fbe24078c9a75c6d7ae07b04299f8d0", "price_changes": [{"asset_id": "15034789978615861173828275849657317503022772763977464100542193185148987457338", "price": "0.316", "size": "0", "side": "BUY", "hash": "e1455813b2cc870ccf6b3968ee9733ce5a16c528", "best_bid": "0.96", "best_ask": "0.964"}, {"asset_id": "25543244747871931789882457929775858252769380692407983079026060150445462771991", "price": "0.684", "size": "0", "side": "SELL", "hash": "bbdad11d8485bce8b3524346eb29099ec6840925", "best_bid": "0.036", "best_ask": "0.04"}], "timestamp": "1769384484722", "event_type": "price_change"}}
{"_local_timestamp": "2026-01-25T23:41:25.279032+00:00", "data": {"market": "0x4d0d43382de6021ce0e906774caf6fc73fbe24078c9a75c6d7ae07b04299f8d0", "price_changes": [{"asset_id": "15034789978615861173828275849657317503022772763977464100542193185148987457338", "price": "0.316", "size": "5", "side": "BUY", "hash": "f93702b9d7984b9fb02727411188de3bdda7f574", "best_bid": "0.96", "best_ask": "0.964"}, {"asset_id": "25543244747871931789882457929775858252769380692407983079026060150445462771991", "price": "0.684", "size": "5", "side": "SELL", "hash": "cbb8f4fe431a798fde10126f1e13e0eb56c21ce7", "best_bid": "0.036", "best_ask": "0.04"}], "timestamp": "1769384485206", "event_type": "price_change"}}
{"_local_timestamp": "2026-01-25T23:41:26.779832+00:00", "data": {"market": "0x4d0d43382de6021ce0e906774caf6fc73fbe24078c9a75c6d7ae07b04299f8d0", "price_changes": [{"asset_id": "25543244747871931789882457929775858252769380692407983079026060150445462771991", "price": "0.003", "size": "113.04", "side": "BUY", "hash": "2beaad73c7642cb8ac3f0c0bd108fe535ea420a3", "best_bid": "0.036", "best_ask": "0.04"}, {"asset_id": "15034789978615861173828275849657317503022772763977464100542193185148987457338", "price": "0.997", "size": "113.04", "side": "SELL", "hash": "6bae2b98d5a8502913f5eb165dba50d8cae405dd", "best_bid": "0.96", "best_ask": "0.964"}], "timestamp": "1769384486701", "event_type": "price_change"}}
{"_local_timestamp": "2026-01-25T23:41:27.050958+00:00", "data": {"market": "0x4d0d43382de6021ce0e906774caf6fc73fbe24078c9a75c6d7ae07b04299f8d0", "price_changes": [{"asset_id": "25543244747871931789882457929775858252769380692407983079026060150445462771991", "price": "0.003", "size": "120.97", "side": "BUY", "hash": "681ec3d46eee40434cddff29e366a2b9f41125f0", "best_bid": "0.036", "best_ask": "0.04"}, {"asset_id": "15034789978615861173828275849657317503022772763977464100542193185148987457338", "price": "0.997", "size": "120.97", "side": "SELL", "hash": "2bfee2585717f56c6776639fc242d24b381b67e2", "best_bid": "0.96", "best_ask": "0.964"}], "timestamp": "1769384486982", "event_type": "price_change"}}
{"_local_timestamp": "2026-01-25T23:41:27.218375+00:00", "data": {"market": "0x4d0d43382de6021ce0e906774caf6fc73fbe24078c9a75c6d7ae07b04299f8d0", "price_changes": [{"asset_id": "15034789978615861173828275849657317503022772763977464100542193185148987457338", "price": "0.316", "size": "0", "side": "BUY", "hash": "ca43a96ab69c543b3805a7237d4c47559155c90e", "best_bid": "0.96", "best_ask": "0.964"}, {"asset_id": "25543244747871931789882457929775858252769380692407983079026060150445462771991", "price": "0.684", "size": "0", "side": "SELL", "hash": "4e51df5f249e32fd204581d54d1c6a3f96abb533", "best_bid": "0.036", "best_ask": "0.04"}], "timestamp": "1769384487144", "event_type": "price_change"}}
{"_local_timestamp": "2026-01-25T23:41:27.563908+00:00", "data": {"market": "0x4d0d43382de6021ce0e906774caf6fc73fbe24078c9a75c6d7ae07b04299f8d0", "price_changes": [{"asset_id": "15034789978615861173828275849657317503022772763977464100542193185148987457338", "price": "0.316", "size": "5", "side": "BUY", "hash": "7d564c57e61ad92d435977c50f7c1b50f223855e", "best_bid": "0.96", "best_ask": "0.964"}, {"asset_id": "25543244747871931789882457929775858252769380692407983079026060150445462771991", "price": "0.684", "size": "5", "side": "SELL", "hash": "bf1f0fb5dd5f4f227716eb924be16918be801521", "best_bid": "0.036", "best_ask": "0.04"}], "timestamp": "1769384487475", "event_type": "price_change"}}
{"_local_timestamp": "2026-01-25T23:41:27.647097+00:00", "data": {"market": "0x4d0d43382de6021ce0e906774caf6fc73fbe24078c9a75c6d7ae07b04299f8d0", "price_changes": [{"asset_id": "25543244747871931789882457929775858252769380692407983079026060150445462771991", "price": "0.003", "size": "113.04", "side": "BUY", "hash": "ae1c622aa5d359cf22c05331fdf1099a3eed5ed1", "best_bid": "0.036", "best_ask": "0.04"}, {"asset_id": "15034789978615861173828275849657317503022772763977464100542193185148987457338", "price": "0.997", "size": "113.04", "side": "SELL", "hash": "eb10b33ff9201a9330ea2dd140a54b69fd9924fa", "best_bid": "0.96", "best_ask": "0.964"}], "timestamp": "1769384487574", "event_type": "price_change"}}
{"_local_timestamp": "2026-01-25T23:41:28.006579+00:00", "data": {"market": "0x4d0d43382de6021ce0e906774caf6fc73fbe24078c9a75c6d7ae07b04299f8d0", "price_changes": [{"asset_id": "25543244747871931789882457929775858252769380692407983079026060150445462771991", "price": "0.003", "size": "120.97", "side": "BUY", "hash": "c4396eba329c2d1aaa029a87f9941bf44877a9e9", "best_bid": "0.036", "best_ask": "0.04"}, {"asset_id": "15034789978615861173828275849657317503022772763977464100542193185148987457338", "price": "0.997", "size": "120.97", "side": "SELL", "hash": "e31e88977aa3d82a8635aedc0b9fa83dd3be69ba", "best_bid": "0.96", "best_ask": "0.964"}], "timestamp": "1769384487926", "event_type": "price_change"}}
{"_local_timestamp": "2026-01-25T23:41:28.941645+00:00", "data": {"market": "0x4d0d43382de6021ce0e906774caf6fc73fbe24078c9a75c6d7ae07b04299f8d0", "price_changes": [{"asset_id": "25543244747871931789882457929775858252769380692407983079026060150445462771991", "price": "0.003", "size": "113.04", "side": "BUY", "hash": "cc29fb60956a8a5dfce0a2d4578e950eee1f16a8", "best_bid": "0.036", "best_ask": "0.04"}, {"asset_id": "15034789978615861173828275849657317503022772763977464100542193185148987457338", "price": "0.997", "size": "113.04", "side": "SELL", "hash": "3faebfad4fdbefd6ccfb68135a4ff28af8c9cfc1", "best_bid": "0.96", "best_ask": "0.964"}], "timestamp": "1769384488860", "event_type": "price_change"}}
{"_local_timestamp": "2026-01-25T23:41:29.197898+00:00", "data": {"market": "0x4d0d43382de6021ce0e906774caf6fc73fbe24078c9a75c6d7ae07b04299f8d0", "price_changes": [{"asset_id": "25543244747871931789882457929775858252769380692407983079026060150445462771991", "price": "0.003", "size": "120.97", "side": "BUY", "hash": "63b3766f9ffd17d76fd2b1a124b1ae9542312532", "best_bid": "0.036", "best_ask": "0.04"}, {"asset_id": "15034789978615861173828275849657317503022772763977464100542193185148987457338", "price": "0.997", "size": "120.97", "side": "SELL", "hash": "7f54aa02984c7f91950e1bea8754c205f97e8058", "best_bid": "0.96", "best_ask": "0.964"}], "timestamp": "1769384489128", "event_type": "price_change"}}
{"_local_timestamp": "2026-01-25T23:41:30.203415+00:00", "data": {"market": "0x4d0d43382de6021ce0e906774caf6fc73fbe24078c9a75c6d7ae07b04299f8d0", "price_changes": [{"asset_id": "25543244747871931789882457929775858252769380692407983079026060150445462771991", "price": "0.003", "size": "113.04", "side": "BUY", "hash": "d4bb08cb9d548431504ad1f08c16b5d8488e7fb9", "best_bid": "0.036", "best_ask": "0.04"}, {"asset_id": "15034789978615861173828275849657317503022772763977464100542193185148987457338", "price": "0.997", "size": "113.04", "side": "SELL", "hash": "46f16f9fcd078ac869dd45c51976ac85ebba35ad", "best_bid": "0.96", "best_ask": "0.964"}], "timestamp": "1769384490137", "event_type": "price_change"}}
{"_local_timestamp": "2026-01-25T23:41:30.211208+00:00", "data": {"market": "0x4d0d43382de6021ce0e906774caf6fc73fbe24078c9a75c6d7ae07b04299f8d0", "price_changes": [{"asset_id": "15034789978615861173828275849657317503022772763977464100542193185148987457338", "price": "0.316", "size": "0", "side": "BUY", "hash": "40fd9f21104826c352f5393ee2814fb6b3d4e29c", "best_bid": "0.96", "best_ask": "0.964"}, {"asset_id": "25543244747871931789882457929775858252769380692407983079026060150445462771991", "price": "0.684", "size": "0", "side": "SELL", "hash": "1875ee7f4b5440c22116c58ed3f7ceb387e1f7f9", "best_bid": "0.036", "best_ask": "0.04"}], "timestamp": "1769384490137", "event_type": "price_change"}}
{"_local_timestamp": "2026-01-25T23:41:30.668234+00:00", "data": {"market": "0x4d0d43382de6021ce0e906774caf6fc73fbe24078c9a75c6d7ae07b04299f8d0", "price_changes": [{"asset_id": "25543244747871931789882457929775858252769380692407983079026060150445462771991", "price": "0.003", "size": "120.97", "side": "BUY", "hash": "768b76ccb102cd9f71f41f88811bc70467c712fd", "best_bid": "0.036", "best_ask": "0.04"}, {"asset_id": "15034789978615861173828275849657317503022772763977464100542193185148987457338", "price": "0.997", "size": "120.97", "side": "SELL", "hash": "eda372b7383ebc8470b5206d8ec59b9130c915e3", "best_bid": "0.96", "best_ask": "0.964"}], "timestamp": "1769384490588", "event_type": "price_change"}}
{"_local_timestamp": "2026-01-25T23:41:30.678455+00:00", "data": {"market": "0x4d0d43382de6021ce0e906774caf6fc73fbe24078c9a75c6d7ae07b04299f8d0", "price_changes": [{"asset_id": "15034789978615861173828275849657317503022772763977464100542193185148987457338", "price": "0.316", "size": "5", "side": "BUY", "hash": "ab01cacfca428b4041bf783b1f9f68d2ed194357", "best_bid": "0.96", "best_ask": "0.964"}, {"asset_id": "25543244747871931789882457929775858252769380692407983079026060150445462771991", "price": "0.684", "size": "5", "side": "SELL", "hash": "da9c81a897e85a3ed2539219be46ba3a87ac5185", "best_bid": "0.036", "best_ask": "0.04"}], "timestamp": "1769384490589", "event_type": "price_change"}}
{"_local_timestamp": "2026-01-25T23:41:32.000805+00:00", "data": {"market": "0x4d0d43382de6021ce0e906774caf6fc73fbe24078c9a75c6d7ae07b04299f8d0", "price_changes": [{"asset_id": "25543244747871931789882457929775858252769380692407983079026060150445462771991", "price": "0.003", "size": "113.04", "side": "BUY", "hash": "544f67aba41e5f65143372e141405c38ba246261", "best_bid": "0.036", "best_ask": "0.04"}, {"asset_id": "15034789978615861173828275849657317503022772763977464100542193185148987457338", "price": "0.997", "size": "113.04", "side": "SELL", "hash": "57f1d8c4c3f0984c4522d6d7a14d16b7f5b8aed3", "best_bid": "0.96", "best_ask": "0.964"}], "timestamp": "1769384491914", "event_type": "price_change"}}
{"_local_timestamp": "2026-01-25T23:41:32.294613+00:00", "data": {"market": "0x4d0d43382de6021ce0e906774caf6fc73fbe24078c9a75c6d7ae07b04299f8d0", "price_changes": [{"asset_id": "25543244747871931789882457929775858252769380692407983079026060150445462771991", "price": "0.003", "size": "120.97", "side": "BUY", "hash": "f91fc5ccb5835933a57a7f6a7156a253c7c986d8", "best_bid": "0.036", "best_ask": "0.04"}, {"asset_id": "15034789978615861173828275849657317503022772763977464100542193185148987457338", "price": "0.997", "size": "120.97", "side": "SELL", "hash": "0fa5ab5b1c9cd5da44e20c5965cbff8d96d6719b", "best_bid": "0.96", "best_ask": "0.964"}], "timestamp": "1769384492222", "event_type": "price_change"}}
{"_local_timestamp": "2026-01-25T23:41:32.830454+00:00", "data": {"market": "0x4d0d43382de6021ce0e906774caf6fc73fbe24078c9a75c6d7ae07b04299f8d0", "price_changes": [{"asset_id": "15034789978615861173828275849657317503022772763977464100542193185148987457338", "price": "0.316", "size": "0", "side": "BUY", "hash": "fc8f64b7526e5626597c037c278b3f3034c50493", "best_bid": "0.96", "best_ask": "0.964"}, {"asset_id": "25543244747871931789882457929775858252769380692407983079026060150445462771991", "price": "0.684", "size": "0", "side": "SELL", "hash": "adc7757fca1ee02405db1b993624421bcaf48e3c", "best_bid": "0.036", "best_ask": "0.04"}], "timestamp": "1769384492759", "event_type": "price_change"}}
{"_local_timestamp": "2026-01-25T23:41:33.129041+00:00", "data": {"market": "0x4d0d43382de6021ce0e906774caf6fc73fbe24078c9a75c6d7ae07b04299f8d0", "price_changes": [{"asset_id": "15034789978615861173828275849657317503022772763977464100542193185148987457338", "price": "0.316", "size": "5", "side": "BUY", "hash": "3c55c823da16140b27390c1c7144e47a674e6f9e", "best_bid": "0.96", "best_ask": "0.964"}, {"asset_id": "25543244747871931789882457929775858252769380692407983079026060150445462771991", "price": "0.684", "size": "5", "side": "SELL", "hash": "7a214e2b83e383fadb1a2e091d8d6de47f4bb839", "best_bid": "0.036", "best_ask": "0.04"}], "timestamp": "1769384493033", "event_type": "price_change"}}
{"_local_timestamp": "2026-01-25T23:41:33.414017+00:00", "data": {"market": "0x4d0d43382de6021ce0e906774caf6fc73fbe24078c9a75c6d7ae07b04299f8d0", "price_changes": [{"asset_id": "25543244747871931789882457929775858252769380692407983079026060150445462771991", "price": "0.003", "size": "113.04", "side": "BUY", "hash": "0a39dba2ee230f45359338ff3613d90f6c5def00", "best_bid": "0.036", "best_ask": "0.04"}, {"asset_id": "15034789978615861173828275849657317503022772763977464100542193185148987457338", "price": "0.997", "size": "113.04", "side": "SELL", "hash": "740ad4f7bc4c2b00f2525a8dc68117949c27e9a7", "best_bid": "0.96", "best_ask": "0.964"}], "timestamp": "1769384493340", "event_type": "price_change"}}
{"_local_timestamp": "2026-01-25T23:41:33.925058+00:00", "data": {"market": "0x4d0d43382de6021ce0e906774caf6fc73fbe24078c9a75c6d7ae07b04299f8d0", "price_changes": [{"asset_id": "25543244747871931789882457929775858252769380692407983079026060150445462771991", "price": "0.003", "size": "120.97", "side": "BUY", "hash": "c4d3a948c8d777a966de7a6dc04c271bf853a594", "best_bid": "0.036", "best_ask": "0.04"}, {"asset_id": "15034789978615861173828275849657317503022772763977464100542193185148987457338", "price": "0.997", "size": "120.97", "side": "SELL", "hash": "8eec23118915930d6a33cf5f456bdc9002f03ba6", "best_bid": "0.96", "best_ask": "0.964"}], "timestamp": "1769384493855", "event_type": "price_change"}}
{"_local_timestamp": "2026-01-25T23:41:34.698141+00:00", "data": {"market": "0x4d0d43382de6021ce0e906774caf6fc73fbe24078c9a75c6d7ae07b04299f8d0", "price_changes": [{"asset_id": "25543244747871931789882457929775858252769380692407983079026060150445462771991", "price": "0.003", "size": "113.04", "side": "BUY", "hash": "e55fed7a2083335b12604c49f464650fc5925c44", "best_bid": "0.036", "best_ask": "0.04"}, {"asset_id": "15034789978615861173828275849657317503022772763977464100542193185148987457338", "price": "0.997", "size": "113.04", "side": "SELL", "hash": "32260376af0d3cea75cf1073c2e4ce0b64824558", "best_bid": "0.96", "best_ask": "0.964"}], "timestamp": "1769384494630", "event_type": "price_change"}}
{"_local_timestamp": "2026-01-25T23:41:34.986280+00:00", "data": {"market": "0x4d0d43382de6021ce0e906774caf6fc73fbe24078c9a75c6d7ae07b04299f8d0", "price_changes": [{"asset_id": "25543244747871931789882457929775858252769380692407983079026060150445462771991", "price": "0.003", "size": "120.97", "side": "BUY", "hash": "7e04d0799e5883b71be1ee289fd46980062b8537", "best_bid": "0.036", "best_ask": "0.04"}, {"asset_id": "15034789978615861173828275849657317503022772763977464100542193185148987457338", "price": "0.997", "size": "120.97", "side": "SELL", "hash": "a827dc63266c96f8a58a1e2534de1443a3994227", "best_bid": "0.96", "best_ask": "0.964"}], "timestamp": "1769384494916", "event_type": "price_change"}}
{"_local_timestamp": "2026-01-25T23:41:35.140015+00:00", "data": {"market": "0x4d0d43382de6021ce0e906774caf6fc73fbe24078c9a75c6d7ae07b04299f8d0", "price_changes": [{"asset_id": "15034789978615861173828275849657317503022772763977464100542193185148987457338", "price": "0.316", "size": "0", "side": "BUY", "hash": "2aedc7997c1e92355088d7dd390f27a26f95da6c", "best_bid": "0.96", "best_ask": "0.964"}, {"asset_id": "25543244747871931789882457929775858252769380692407983079026060150445462771991", "price": "0.684", "size": "0", "side": "SELL", "hash": "7a5b1dc74798e90286980df5683e6178e309c7e3", "best_bid": "0.036", "best_ask": "0.04"}], "timestamp": "1769384495053", "event_type": "price_change"}}
{"_local_timestamp": "2026-01-25T23:41:35.507384+00:00", "data": {"market": "0x4d0d43382de6021ce0e906774caf6fc73fbe24078c9a75c6d7ae07b04299f8d0", "price_changes": [{"asset_id": "15034789978615861173828275849657317503022772763977464100542193185148987457338", "price": "0.316", "size": "5", "side": "BUY", "hash": "db8fa663765e588f46961ca34b7f1ddc563e36ed", "best_bid": "0.96", "best_ask": "0.964"}, {"asset_id": "25543244747871931789882457929775858252769380692407983079026060150445462771991", "price": "0.684", "size": "5", "side": "SELL", "hash": "a2deec02f47844491bc59f301f2d88a7d1f89b6a", "best_bid": "0.036", "best_ask": "0.04"}], "timestamp": "1769384495435", "event_type": "price_change"}}
{"_local_timestamp": "2026-01-25T23:41:35.849013+00:00", "data": {"market": "0x4d0d43382de6021ce0e906774caf6fc73fbe24078c9a75c6d7ae07b04299f8d0", "price_changes": [{"asset_id": "25543244747871931789882457929775858252769380692407983079026060150445462771991", "price": "0.003", "size": "113.04", "side": "BUY", "hash": "a44df5194a85fb49e47cc8cc89f65420eb1b5965", "best_bid": "0.036", "best_ask": "0.04"}, {"asset_id": "15034789978615861173828275849657317503022772763977464100542193185148987457338", "price": "0.997", "size": "113.04", "side": "SELL", "hash": "695ca98d3648307c93ebca8d8368baacc61a1008", "best_bid": "0.96", "best_ask": "0.964"}], "timestamp": "1769384495781", "event_type": "price_change"}}
{"_local_timestamp": "2026-01-25T23:41:36.371075+00:00", "data": {"market": "0x4d0d43382de6021ce0e906774caf6fc73fbe24078c9a75c6d7ae07b04299f8d0", "price_changes": [{"asset_id": "25543244747871931789882457929775858252769380692407983079026060150445462771991", "price": "0.003", "size": "120.97", "side": "BUY", "hash": "5b98c45ba58feb0b2559e85eb653ef52039d1588", "best_bid": "0.036", "best_ask": "0.04"}, {"asset_id": "15034789978615861173828275849657317503022772763977464100542193185148987457338", "price": "0.997", "size": "120.97", "side": "SELL", "hash": "fee4a955705fd67db6bc09da32e7ac8a14c022fc", "best_bid": "0.96", "best_ask": "0.964"}], "timestamp": "1769384496300", "event_type": "price_change"}}
{"_local_timestamp": "2026-01-25T23:41:37.677108+00:00", "data": {"market": "0x4d0d43382de6021ce0e906774caf6fc73fbe24078c9a75c6d7ae07b04299f8d0", "price_changes": [{"asset_id": "25543244747871931789882457929775858252769380692407983079026060150445462771991", "price": "0.003", "size": "113.04", "side": "BUY", "hash": "83d4667e26c8cc2f18f299cc98296665fab50eaa", "best_bid": "0.036", "best_ask": "0.04"}, {"asset_id": "15034789978615861173828275849657317503022772763977464100542193185148987457338", "price": "0.997", "size": "113.04", "side": "SELL", "hash": "55cd4d8a288437ece7bf79d4d72db65e1efa4ede", "best_bid": "0.96", "best_ask": "0.964"}], "timestamp": "1769384497606", "event_type": "price_change"}}
{"_local_timestamp": "2026-01-25T23:41:37.684212+00:00", "data": {"market": "0x4d0d43382de6021ce0e906774caf6fc73fbe24078c9a75c6d7ae07b04299f8d0", "price_changes": [{"asset_id": "15034789978615861173828275849657317503022772763977464100542193185148987457338", "price": "0.316", "size": "0", "side": "BUY", "hash": "f1693938a8013e2d8aaa5467e28e7179304acc7c", "best_bid": "0.96", "best_ask": "0.964"}, {"asset_id": "25543244747871931789882457929775858252769380692407983079026060150445462771991", "price": "0.684", "size": "0", "side": "SELL", "hash": "da47985cd5c16e83d7a44959a48332a4d2c401f5", "best_bid": "0.036", "best_ask": "0.04"}], "timestamp": "1769384497606", "event_type": "price_change"}}
{"_local_timestamp": "2026-01-25T23:41:38.075955+00:00", "data": {"market": "0x4d0d43382de6021ce0e906774caf6fc73fbe24078c9a75c6d7ae07b04299f8d0", "price_changes": [{"asset_id": "25543244747871931789882457929775858252769380692407983079026060150445462771991", "price": "0.003", "size": "120.97", "side": "BUY", "hash": "e48d0b8e88f4a0c64ebfe21832d97b1045ca74e4", "best_bid": "0.036", "best_ask": "0.04"}, {"asset_id": "15034789978615861173828275849657317503022772763977464100542193185148987457338", "price": "0.997", "size": "120.97", "side": "SELL", "hash": "da61d50e97ef5e286d14dc3f99af51a5b926fdf9", "best_bid": "0.96", "best_ask": "0.964"}], "timestamp": "1769384498000", "event_type": "price_change"}}
{"_local_timestamp": "2026-01-25T23:41:38.129150+00:00", "data": {"market": "0x4d0d43382de6021ce0e906774caf6fc73fbe24078c9a75c6d7ae07b04299f8d0", "price_changes": [{"asset_id": "15034789978615861173828275849657317503022772763977464100542193185148987457338", "price": "0.316", "size": "5", "side": "BUY", "hash": "451bf81cdbe82fe157bac40e36ee18ef2df443a6", "best_bid": "0.96", "best_ask": "0.964"}, {"asset_id": "25543244747871931789882457929775858252769380692407983079026060150445462771991", "price": "0.684", "size": "5", "side": "SELL", "hash": "03e1a0213a1902fbf703c26a5310b70780db186f", "best_bid": "0.036", "best_ask": "0.04"}], "timestamp": "1769384498002", "event_type": "price_change"}}
{"_local_timestamp": "2026-01-25T23:41:39.424961+00:00", "data": {"market": "0x4d0d43382de6021ce0e906774caf6fc73fbe24078c9a75c6d7ae07b04299f8d0", "price_changes": [{"asset_id": "25543244747871931789882457929775858252769380692407983079026060150445462771991", "price": "0.003", "size": "113.04", "side": "BUY", "hash": "31b6943064a8057aaa9b6a7dd9f065b030122f52", "best_bid": "0.036", "best_ask": "0.04"}, {"asset_id": "15034789978615861173828275849657317503022772763977464100542193185148987457338", "price": "0.997", "size": "113.04", "side": "SELL", "hash": "846c218fdfdacc03029f1e08049da724fdf8e917", "best_bid": "0.96", "best_ask": "0.964"}], "timestamp": "1769384499335", "event_type": "price_change"}}
{"_local_timestamp": "2026-01-25T23:41:39.666531+00:00", "data": {"market": "0x4d0d43382de6021ce0e906774caf6fc73fbe24078c9a75c6d7ae07b04299f8d0", "price_changes": [{"asset_id": "25543244747871931789882457929775858252769380692407983079026060150445462771991", "price": "0.003", "size": "120.97", "side": "BUY", "hash": "0935460d241d56d51188f5fd9455adc83646066e", "best_bid": "0.036", "best_ask": "0.04"}, {"asset_id": "15034789978615861173828275849657317503022772763977464100542193185148987457338", "price": "0.997", "size": "120.97", "side": "SELL", "hash": "6513ae2c27539353d5a4a5822d74ed07dbd55692", "best_bid": "0.96", "best_ask": "0.964"}], "timestamp": "1769384499594", "event_type": "price_change"}}
{"_local_timestamp": "2026-01-25T23:41:40.680892+00:00", "data": {"market": "0x4d0d43382de6021ce0e906774caf6fc73fbe24078c9a75c6d7ae07b04299f8d0", "price_changes": [{"asset_id": "15034789978615861173828275849657317503022772763977464100542193185148987457338", "price": "0.316", "size": "0", "side": "BUY", "hash": "f47d8bcc7d0014d938e1122fbb5deef228d6f95d", "best_bid": "0.96", "best_ask": "0.964"}, {"asset_id": "25543244747871931789882457929775858252769380692407983079026060150445462771991", "price": "0.684", "size": "0", "side": "SELL", "hash": "555de50423321c80aeef8d1edcd23dc0d11d0f4f", "best_bid": "0.036", "best_ask": "0.04"}], "timestamp": "1769384500612", "event_type": "price_change"}}
{"_local_timestamp": "2026-01-25T23:41:41.051285+00:00", "data": {"market": "0x4d0d43382de6021ce0e906774caf6fc73fbe24078c9a75c6d7ae07b04299f8d0", "price_changes": [{"asset_id": "15034789978615861173828275849657317503022772763977464100542193185148987457338", "price": "0.316", "size": "5", "side": "BUY", "hash": "5c8a890bfd9c6914cdfc0ae868b30c9c8d7cb518", "best_bid": "0.96", "best_ask": "0.964"}, {"asset_id": "25543244747871931789882457929775858252769380692407983079026060150445462771991", "price": "0.684", "size": "5", "side": "SELL", "hash": "49364fe811213294319fa4d7f8799f3dfb752565", "best_bid": "0.036", "best_ask": "0.04"}], "timestamp": "1769384500972", "event_type": "price_change"}}
{"_local_timestamp": "2026-01-25T23:41:41.117549+00:00", "data": {"market": "0x4d0d43382de6021ce0e906774caf6fc73fbe24078c9a75c6d7ae07b04299f8d0", "price_changes": [{"asset_id": "25543244747871931789882457929775858252769380692407983079026060150445462771991", "price": "0.003", "size": "113.04", "side": "BUY", "hash": "ddb5d62839e96d64a05de0f9aca88743599ee12c", "best_bid": "0.036", "best_ask": "0.04"}, {"asset_id": "15034789978615861173828275849657317503022772763977464100542193185148987457338", "price": "0.997", "size": "113.04", "side": "SELL", "hash": "e4afbb1a8c737ab65d1900c7b04f5eb9c8a9a1f8", "best_bid": "0.96", "best_ask": "0.964"}], "timestamp": "1769384501047", "event_type": "price_change"}}
{"_local_timestamp": "2026-01-25T23:41:41.503362+00:00", "data": {"market": "0x4d0d43382de6021ce0e906774caf6fc73fbe24078c9a75c6d7ae07b04299f8d0", "price_changes": [{"asset_id": "25543244747871931789882457929775858252769380692407983079026060150445462771991", "price": "0.003", "size": "120.97", "side": "BUY", "hash": "1aa77acd4520a03e6cd9242b2972fd3cf47526da", "best_bid": "0.036", "best_ask": "0.04"}, {"asset_id": "15034789978615861173828275849657317503022772763977464100542193185148987457338", "price": "0.997", "size": "120.97", "side": "SELL", "hash": "a9ac1363520cb46f00812c630c35e5c539800749", "best_bid": "0.96", "best_ask": "0.964"}], "timestamp": "1769384501431", "event_type": "price_change"}}
{"_local_timestamp": "2026-01-25T23:41:43.239430+00:00", "data": {"market": "0x4d0d43382de6021ce0e906774caf6fc73fbe24078c9a75c6d7ae07b04299f8d0", "price_changes": [{"asset_id": "15034789978615861173828275849657317503022772763977464100542193185148987457338", "price": "0.316", "size": "0", "side": "BUY", "hash": "23a3c90dc1b6eb2766274e182d2a9992bf7b533a", "best_bid": "0.96", "best_ask": "0.964"}, {"asset_id": "25543244747871931789882457929775858252769380692407983079026060150445462771991", "price": "0.684", "size": "0", "side": "SELL", "hash": "a58d5ac6e0dd6d22d25c4f5767a75f54b744c63b", "best_bid": "0.036", "best_ask": "0.04"}], "timestamp": "1769384503171", "event_type": "price_change"}}
{"_local_timestamp": "2026-01-25T23:41:43.241669+00:00", "data": {"market": "0x4d0d43382de6021ce0e906774caf6fc73fbe24078c9a75c6d7ae07b04299f8d0", "price_changes": [{"asset_id": "25543244747871931789882457929775858252769380692407983079026060150445462771991", "price": "0.003", "size": "113.04", "side": "BUY", "hash": "fd033b25b38deab17dfefb18d34a9111abe2431d", "best_bid": "0.036", "best_ask": "0.04"}, {"asset_id": "15034789978615861173828275849657317503022772763977464100542193185148987457338", "price": "0.997", "size": "113.04", "side": "SELL", "hash": "369fb39a03ac56e8ad0243a5260e2072f2f8ab54", "best_bid": "0.96", "best_ask": "0.964"}], "timestamp": "1769384503171", "event_type": "price_change"}}
{"_local_timestamp": "2026-01-25T23:41:43.501933+00:00", "data": {"market": "0x4d0d43382de6021ce0e906774caf6fc73fbe24078c9a75c6d7ae07b04299f8d0", "price_changes": [{"asset_id": "15034789978615861173828275849657317503022772763977464100542193185148987457338", "price": "0.316", "size": "5", "side": "BUY", "hash": "0b654f6351fdd5a796a27c57636a15e9e42416f3", "best_bid": "0.96", "best_ask": "0.964"}, {"asset_id": "25543244747871931789882457929775858252769380692407983079026060150445462771991", "price": "0.684", "size": "5", "side": "SELL", "hash": "8cf6ab9b8f4eeb0d94434ef2ca70468f2a9b29af", "best_bid": "0.036", "best_ask": "0.04"}], "timestamp": "1769384503432", "event_type": "price_change"}}
{"_local_timestamp": "2026-01-25T23:41:43.738868+00:00", "data": {"market": "0x4d0d43382de6021ce0e906774caf6fc73fbe24078c9a75c6d7ae07b04299f8d0", "price_changes": [{"asset_id": "25543244747871931789882457929775858252769380692407983079026060150445462771991", "price": "0.003", "size": "120.97", "side": "BUY", "hash": "c7edb1db366be81a613a8ac586d3dbaf5f1ee982", "best_bid": "0.036", "best_ask": "0.04"}, {"asset_id": "15034789978615861173828275849657317503022772763977464100542193185148987457338", "price": "0.997", "size": "120.97", "side": "SELL", "hash": "40d491046b76274562c05987192e5b8ebcd3e9bc", "best_bid": "0.96", "best_ask": "0.964"}], "timestamp": "1769384503661", "event_type": "price_change"}}
{"_local_timestamp": "2026-01-25T23:41:44.742401+00:00", "data": {"market": "0x4d0d43382de6021ce0e906774caf6fc73fbe24078c9a75c6d7ae07b04299f8d0", "price_changes": [{"asset_id": "25543244747871931789882457929775858252769380692407983079026060150445462771991", "price": "0.003", "size": "113.04", "side": "BUY", "hash": "0582196fd2894ee3f73e3bfead2df2818bdc9bb6", "best_bid": "0.036", "best_ask": "0.04"}, {"asset_id": "15034789978615861173828275849657317503022772763977464100542193185148987457338", "price": "0.997", "size": "113.04", "side": "SELL", "hash": "08695e1432486b9c2bc71d774b57525d2d454300", "best_bid": "0.96", "best_ask": "0.964"}], "timestamp": "1769384504676", "event_type": "price_change"}}
{"_local_timestamp": "2026-01-25T23:41:45.134599+00:00", "data": {"market": "0x4d0d43382de6021ce0e906774caf6fc73fbe24078c9a75c6d7ae07b04299f8d0", "price_changes": [{"asset_id": "25543244747871931789882457929775858252769380692407983079026060150445462771991", "price": "0.003", "size": "120.97", "side": "BUY", "hash": "1a2049fa10f348f2175aa69bafdc7d12bbaed180", "best_bid": "0.036", "best_ask": "0.04"}, {"asset_id": "15034789978615861173828275849657317503022772763977464100542193185148987457338", "price": "0.997", "size": "120.97", "side": "SELL", "hash": "657e2afcb4f8297c5a7018cde1bfd12846e70b06", "best_bid": "0.96", "best_ask": "0.964"}], "timestamp": "1769384505065", "event_type": "price_change"}}
{"_local_timestamp": "2026-01-25T23:41:45.627727+00:00", "data": {"market": "0x4d0d43382de6021ce0e906774caf6fc73fbe24078c9a75c6d7ae07b04299f8d0", "price_changes": [{"asset_id": "15034789978615861173828275849657317503022772763977464100542193185148987457338", "price": "0.316", "size": "0", "side": "BUY", "hash": "039cbe3c0a3a89db16d41567442031316a920c1a", "best_bid": "0.96", "best_ask": "0.964"}, {"asset_id": "25543244747871931789882457929775858252769380692407983079026060150445462771991", "price": "0.684", "size": "0", "side": "SELL", "hash": "d3af72f6a1ea242fecb81b8a2c688e57c581268f", "best_bid": "0.036", "best_ask": "0.04"}], "timestamp": "1769384505554", "event_type": "price_change"}}
{"_local_timestamp": "2026-01-25T23:41:46.006030+00:00", "data": {"market": "0x4d0d43382de6021ce0e906774caf6fc73fbe24078c9a75c6d7ae07b04299f8d0", "price_changes": [{"asset_id": "15034789978615861173828275849657317503022772763977464100542193185148987457338", "price": "0.316", "size": "5", "side": "BUY", "hash": "dc53987c7d18cd99f36f1360df2f0d41d28aa13b", "best_bid": "0.96", "best_ask": "0.964"}, {"asset_id": "25543244747871931789882457929775858252769380692407983079026060150445462771991", "price": "0.684", "size": "5", "side": "SELL", "hash": "5fbd133fcbc3274e68a935796b44f0af3a1219e4", "best_bid": "0.036", "best_ask": "0.04"}], "timestamp": "1769384505936", "event_type": "price_change"}}
{"_local_timestamp": "2026-01-25T23:41:46.483776+00:00", "data": {"market": "0x4d0d43382de6021ce0e906774caf6fc73fbe24078c9a75c6d7ae07b04299f8d0", "price_changes": [{"asset_id": "25543244747871931789882457929775858252769380692407983079026060150445462771991", "price": "0.003", "size": "113.04", "side": "BUY", "hash": "33853af60ea3a38c5e10156760ba1039eb91d0ff", "best_bid": "0.036", "best_ask": "0.04"}, {"asset_id": "15034789978615861173828275849657317503022772763977464100542193185148987457338", "price": "0.997", "size": "113.04", "side": "SELL", "hash": "7f8e27dc5aafa4324e6761b44acbd6a65753e8f8", "best_bid": "0.96", "best_ask": "0.964"}], "timestamp": "1769384506417", "event_type": "price_change"}}
{"_local_timestamp": "2026-01-25T23:41:46.865322+00:00", "data": {"market": "0x4d0d43382de6021ce0e906774caf6fc73fbe24078c9a75c6d7ae07b04299f8d0", "price_changes": [{"asset_id": "25543244747871931789882457929775858252769380692407983079026060150445462771991", "price": "0.003", "size": "120.97", "side": "BUY", "hash": "6a81b262f78e35154a535e5bba8c22d8c91eeff1", "best_bid": "0.036", "best_ask": "0.04"}, {"asset_id": "15034789978615861173828275849657317503022772763977464100542193185148987457338", "price": "0.997", "size": "120.97", "side": "SELL", "hash": "b04d25402d3d0e79cd63c9da7e01b592cf5efcd4", "best_bid": "0.96", "best_ask": "0.964"}], "timestamp": "1769384506800", "event_type": "price_change"}}
{"_local_timestamp": "2026-01-25T23:41:47.810497+00:00", "data": {"market": "0x4d0d43382de6021ce0e906774caf6fc73fbe24078c9a75c6d7ae07b04299f8d0", "price_changes": [{"asset_id": "25543244747871931789882457929775858252769380692407983079026060150445462771991", "price": "0.003", "size": "113.04", "side": "BUY", "hash": "617060c75bab954b909d7605773051561c05846d", "best_bid": "0.036", "best_ask": "0.04"}, {"asset_id": "15034789978615861173828275849657317503022772763977464100542193185148987457338", "price": "0.997", "size": "113.04", "side": "SELL", "hash": "c77fdc5214b92154d9951f75dcf3b4f3e34567ca", "best_bid": "0.96", "best_ask": "0.964"}], "timestamp": "1769384507727", "event_type": "price_change"}}
{"_local_timestamp": "2026-01-25T23:41:48.196066+00:00", "data": {"market": "0x4d0d43382de6021ce0e906774caf6fc73fbe24078c9a75c6d7ae07b04299f8d0", "price_changes": [{"asset_id": "25543244747871931789882457929775858252769380692407983079026060150445462771991", "price": "0.003", "size": "120.97", "side": "BUY", "hash": "f2011e7dc4fd7c7521bf3c4aa2a6ad95e2002e41", "best_bid": "0.036", "best_ask": "0.04"}, {"asset_id": "15034789978615861173828275849657317503022772763977464100542193185148987457338", "price": "0.997", "size": "120.97", "side": "SELL", "hash": "834a3d8a16e5d3a92e7f5e933fedf74176bb920b", "best_bid": "0.96", "best_ask": "0.964"}], "timestamp": "1769384508129", "event_type": "price_change"}}
{"_local_timestamp": "2026-01-25T23:41:49.153199+00:00", "data": {"market": "0x4d0d43382de6021ce0e906774caf6fc73fbe24078c9a75c6d7ae07b04299f8d0", "price_changes": [{"asset_id": "25543244747871931789882457929775858252769380692407983079026060150445462771991", "price": "0.003", "size": "113.04", "side": "BUY", "hash": "8eb988f1332aeb18db4cbc601d3d440354c29589", "best_bid": "0.036", "best_ask": "0.04"}, {"asset_id": "15034789978615861173828275849657317503022772763977464100542193185148987457338", "price": "0.997", "size": "113.04", "side": "SELL", "hash": "b054516497d4371fd59a682aadc96324c47aa436", "best_bid": "0.96", "best_ask": "0.964"}], "timestamp": "1769384509031", "event_type": "price_change"}}
{"_local_timestamp": "2026-01-25T23:41:49.155791+00:00", "data": {"market": "0x4d0d43382de6021ce0e906774caf6fc73fbe24078c9a75c6d7ae07b04299f8d0", "price_changes": [{"asset_id": "15034789978615861173828275849657317503022772763977464100542193185148987457338", "price": "0.316", "size": "0", "side": "BUY", "hash": "663abc30e5893ef0265721706572e122ade71e1e", "best_bid": "0.96", "best_ask": "0.964"}, {"asset_id": "25543244747871931789882457929775858252769380692407983079026060150445462771991", "price": "0.684", "size": "0", "side": "SELL", "hash": "b070ee998b40f9979a9feaeae33220a68cdfcd45", "best_bid": "0.036", "best_ask": "0.04"}], "timestamp": "1769384509031", "event_type": "price_change"}}
{"_local_timestamp": "2026-01-25T23:41:49.470238+00:00", "data": {"market": "0x4d0d43382de6021ce0e906774caf6fc73fbe24078c9a75c6d7ae07b04299f8d0", "price_changes": [{"asset_id": "15034789978615861173828275849657317503022772763977464100542193185148987457338", "price": "0.316", "size": "5", "side": "BUY", "hash": "a24e3191933bf72869197eaaccec837f67356874", "best_bid": "0.96", "best_ask": "0.964"}, {"asset_id": "25543244747871931789882457929775858252769380692407983079026060150445462771991", "price": "0.684", "size": "5", "side": "SELL", "hash": "a304e228b4477638ec6038a7d3ffb97ed63c672a", "best_bid": "0.036", "best_ask": "0.04"}], "timestamp": "1769384509389", "event_type": "price_change"}}
{"_local_timestamp": "2026-01-25T23:41:49.473087+00:00", "data": {"market": "0x4d0d43382de6021ce0e906774caf6fc73fbe24078c9a75c6d7ae07b04299f8d0", "price_changes": [{"asset_id": "25543244747871931789882457929775858252769380692407983079026060150445462771991", "price": "0.003", "size": "120.97", "side": "BUY", "hash": "f90c27a2912d60560143d3b89db7c0bcba5e516f", "best_bid": "0.036", "best_ask": "0.04"}, {"asset_id": "15034789978615861173828275849657317503022772763977464100542193185148987457338", "price": "0.997", "size": "120.97", "side": "SELL", "hash": "b983bc8dfe61b546d430ef6e54c719bc514cd3f3", "best_bid": "0.96", "best_ask": "0.964"}], "timestamp": "1769384509391", "event_type": "price_change"}}
{"_local_timestamp": "2026-01-25T23:41:50.867830+00:00", "data": {"market": "0x4d0d43382de6021ce0e906774caf6fc73fbe24078c9a75c6d7ae07b04299f8d0", "price_changes": [{"asset_id": "25543244747871931789882457929775858252769380692407983079026060150445462771991", "price": "0.003", "size": "113.04", "side": "BUY", "hash": "fc62f19e689df9fa765480ade8985167fa3ac65b", "best_bid": "0.036", "best_ask": "0.04"}, {"asset_id": "15034789978615861173828275849657317503022772763977464100542193185148987457338", "price": "0.997", "size": "113.04", "side": "SELL", "hash": "d1cbbfe3971d4e7a4dc8eb251d92e5d609cb6efc", "best_bid": "0.96", "best_ask": "0.964"}], "timestamp": "1769384510738", "event_type": "price_change"}}
{"_local_timestamp": "2026-01-25T23:41:50.994453+00:00", "data": {"market": "0x4d0d43382de6021ce0e906774caf6fc73fbe24078c9a75c6d7ae07b04299f8d0", "price_changes": [{"asset_id": "25543244747871931789882457929775858252769380692407983079026060150445462771991", "price": "0.004", "size": "5.95", "side": "BUY", "hash": "f197d7a377a24fd617be4d8cf63cd91e5029e71e", "best_bid": "0.036", "best_ask": "0.04"}, {"asset_id": "15034789978615861173828275849657317503022772763977464100542193185148987457338", "price": "0.996", "size": "5.95", "side": "SELL", "hash": "317628c6a77f20e92d9655907260dfd770aa3778", "best_bid": "0.96", "best_ask": "0.964"}], "timestamp": "1769384510886", "event_type": "price_change"}}
{"_local_timestamp": "2026-01-25T23:41:51.903161+00:00", "data": {"market": "0x4d0d43382de6021ce0e906774caf6fc73fbe24078c9a75c6d7ae07b04299f8d0", "price_changes": [{"asset_id": "15034789978615861173828275849657317503022772763977464100542193185148987457338", "price": "0.316", "size": "0", "side": "BUY", "hash": "4a934ccca464d1219e50f3204ef3958c32fda410", "best_bid": "0.96", "best_ask": "0.964"}, {"asset_id": "25543244747871931789882457929775858252769380692407983079026060150445462771991", "price": "0.684", "size": "0", "side": "SELL", "hash": "15c50032b447b6f97471c50f84738873fdd47ed5", "best_bid": "0.036", "best_ask": "0.04"}], "timestamp": "1769384511794", "event_type": "price_change"}}
{"_local_timestamp": "2026-01-25T23:41:52.329190+00:00", "data": {"market": "0x4d0d43382de6021ce0e906774caf6fc73fbe24078c9a75c6d7ae07b04299f8d0", "price_changes": [{"asset_id": "25543244747871931789882457929775858252769380692407983079026060150445462771991", "price": "0.004", "size": "0", "side": "BUY", "hash": "b669df43483495555ecb31f43db4719d8f9597eb", "best_bid": "0.036", "best_ask": "0.04"}, {"asset_id": "15034789978615861173828275849657317503022772763977464100542193185148987457338", "price": "0.996", "size": "0", "side": "SELL", "hash": "1198c0d39d0423a03ee7e20163516fd8b1b9e2cd", "best_bid": "0.96", "best_ask": "0.964"}], "timestamp": "1769384512256", "event_type": "price_change"}}
{"_local_timestamp": "2026-01-25T23:41:52.350891+00:00", "data": {"market": "0x4d0d43382de6021ce0e906774caf6fc73fbe24078c9a75c6d7ae07b04299f8d0", "price_changes": [{"asset_id": "15034789978615861173828275849657317503022772763977464100542193185148987457338", "price": "0.316", "size": "5", "side": "BUY", "hash": "feab80719a27b51a60bcc1d175a67d2f9b9827a9", "best_bid": "0.96", "best_ask": "0.964"}, {"asset_id": "25543244747871931789882457929775858252769380692407983079026060150445462771991", "price": "0.684", "size": "5", "side": "SELL", "hash": "a5607bca1151897899f4a0e51b9c0ddfc3dc2a49", "best_bid": "0.036", "best_ask": "0.04"}], "timestamp": "1769384512280", "event_type": "price_change"}}
{"_local_timestamp": "2026-01-25T23:41:52.688791+00:00", "data": {"market": "0x4d0d43382de6021ce0e906774caf6fc73fbe24078c9a75c6d7ae07b04299f8d0", "price_changes": [{"asset_id": "25543244747871931789882457929775858252769380692407983079026060150445462771991", "price": "0.003", "size": "120.97", "side": "BUY", "hash": "2f46a24417fbd56ddb57208acb193d16eeccd510", "best_bid": "0.036", "best_ask": "0.04"}, {"asset_id": "15034789978615861173828275849657317503022772763977464100542193185148987457338", "price": "0.997", "size": "120.97", "side": "SELL", "hash": "6102631f9f300b3c64fe0d74fa302b01de41f88a", "best_bid": "0.96", "best_ask": "0.964"}], "timestamp": "1769384512599", "event_type": "price_change"}}
{"_local_timestamp": "2026-01-25T23:41:53.656863+00:00", "data": {"market": "0x4d0d43382de6021ce0e906774caf6fc73fbe24078c9a75c6d7ae07b04299f8d0", "price_changes": [{"asset_id": "25543244747871931789882457929775858252769380692407983079026060150445462771991", "price": "0.003", "size": "113.04", "side": "BUY", "hash": "55a6d33febbb16f6d25c15a3b8bd58f7d93a1826", "best_bid": "0.036", "best_ask": "0.04"}, {"asset_id": "15034789978615861173828275849657317503022772763977464100542193185148987457338", "price": "0.997", "size": "113.04", "side": "SELL", "hash": "640a25e9c717548ec28eff8b60d3664967275157", "best_bid": "0.96", "best_ask": "0.964"}], "timestamp": "1769384513579", "event_type": "price_change"}}
{"_local_timestamp": "2026-01-25T23:41:53.979820+00:00", "data": {"market": "0x4d0d43382de6021ce0e906774caf6fc73fbe24078c9a75c6d7ae07b04299f8d0", "price_changes": [{"asset_id": "25543244747871931789882457929775858252769380692407983079026060150445462771991", "price": "0.003", "size": "120.97", "side": "BUY", "hash": "d3597f2d217f16079fc7df66c2cbff59306051c3", "best_bid": "0.036", "best_ask": "0.04"}, {"asset_id": "15034789978615861173828275849657317503022772763977464100542193185148987457338", "price": "0.997", "size": "120.97", "side": "SELL", "hash": "360fbdce18502b7a156793d1def6d0a1ae982122", "best_bid": "0.96", "best_ask": "0.964"}], "timestamp": "1769384513915", "event_type": "price_change"}}
{"_local_timestamp": "2026-01-25T23:41:54.572501+00:00", "data": {"market": "0x4d0d43382de6021ce0e906774caf6fc73fbe24078c9a75c6d7ae07b04299f8d0", "price_changes": [{"asset_id": "15034789978615861173828275849657317503022772763977464100542193185148987457338", "price": "0.316", "size": "0", "side": "BUY", "hash": "3103f706532ff88db78f7ea51ffd254d0d4c0ce5", "best_bid": "0.96", "best_ask": "0.964"}, {"asset_id": "25543244747871931789882457929775858252769380692407983079026060150445462771991", "price": "0.684", "size": "0", "side": "SELL", "hash": "f0a88dd906773f19323025a1242cf90f46473b17", "best_bid": "0.036", "best_ask": "0.04"}], "timestamp": "1769384514505", "event_type": "price_change"}}
{"_local_timestamp": "2026-01-25T23:41:54.896162+00:00", "data": {"market": "0x4d0d43382de6021ce0e906774caf6fc73fbe24078c9a75c6d7ae07b04299f8d0", "price_changes": [{"asset_id": "15034789978615861173828275849657317503022772763977464100542193185148987457338", "price": "0.316", "size": "5", "side": "BUY", "hash": "35ec5cd3f31bc0424e4401f71cf0e2a010101ca2", "best_bid": "0.96", "best_ask": "0.964"}, {"asset_id": "25543244747871931789882457929775858252769380692407983079026060150445462771991", "price": "0.684", "size": "5", "side": "SELL", "hash": "9579e462bfb4bb8d5a0bac34803d7101e172a128", "best_bid": "0.036", "best_ask": "0.04"}], "timestamp": "1769384514824", "event_type": "price_change"}}
{"_local_timestamp": "2026-01-25T23:41:55.410937+00:00", "data": {"market": "0x4d0d43382de6021ce0e906774caf6fc73fbe24078c9a75c6d7ae07b04299f8d0", "price_changes": [{"asset_id": "25543244747871931789882457929775858252769380692407983079026060150445462771991", "price": "0.003", "size": "113.04", "side": "BUY", "hash": "cf89367b02a61bbd94c592cd07182036d8a97ff9", "best_bid": "0.036", "best_ask": "0.04"}, {"asset_id": "15034789978615861173828275849657317503022772763977464100542193185148987457338", "price": "0.997", "size": "113.04", "side": "SELL", "hash": "cd280437efd242db0c8ea7bc2f5f90db1d20c296", "best_bid": "0.96", "best_ask": "0.964"}], "timestamp": "1769384515345", "event_type": "price_change"}}
{"_local_timestamp": "2026-01-25T23:41:55.864647+00:00", "data": {"market": "0x4d0d43382de6021ce0e906774caf6fc73fbe24078c9a75c6d7ae07b04299f8d0", "price_changes": [{"asset_id": "25543244747871931789882457929775858252769380692407983079026060150445462771991", "price": "0.003", "size": "120.97", "side": "BUY", "hash": "9e35ce206ddcb857b6f0fa816ba8787194c33cf3", "best_bid": "0.036", "best_ask": "0.04"}, {"asset_id": "15034789978615861173828275849657317503022772763977464100542193185148987457338", "price": "0.997", "size": "120.97", "side": "SELL", "hash": "f879b0b54eb8be27d010fa05aa925259110d504a", "best_bid": "0.96", "best_ask": "0.964"}], "timestamp": "1769384515790", "event_type": "price_change"}}
{"_local_timestamp": "2026-01-25T23:41:57.351136+00:00", "data": {"market": "0x4d0d43382de6021ce0e906774caf6fc73fbe24078c9a75c6d7ae07b04299f8d0", "price_changes": [{"asset_id": "15034789978615861173828275849657317503022772763977464100542193185148987457338", "price": "0.316", "size": "0", "side": "BUY", "hash": "a3539140a1339c6fc25458f61578425e2e6e9710", "best_bid": "0.96", "best_ask": "0.964"}, {"asset_id": "25543244747871931789882457929775858252769380692407983079026060150445462771991", "price": "0.684", "size": "0", "side": "SELL", "hash": "45f19f3e33ffe705b171c73d96c1d3fd47e11977", "best_bid": "0.036", "best_ask": "0.04"}], "timestamp": "1769384517286", "event_type": "price_change"}}
{"_local_timestamp": "2026-01-25T23:41:57.620098+00:00", "data": {"market": "0x4d0d43382de6021ce0e906774caf6fc73fbe24078c9a75c6d7ae07b04299f8d0", "price_changes": [{"asset_id": "15034789978615861173828275849657317503022772763977464100542193185148987457338", "price": "0.316", "size": "5", "side": "BUY", "hash": "9f33cddc7599bac53bc38c2b68c7416b76539183", "best_bid": "0.96", "best_ask": "0.964"}, {"asset_id": "25543244747871931789882457929775858252769380692407983079026060150445462771991", "price": "0.684", "size": "5", "side": "SELL", "hash": "f3af0c1a9756c7c8ae0134c95501a1bc4c426013", "best_bid": "0.036", "best_ask": "0.04"}], "timestamp": "1769384517544", "event_type": "price_change"}}
{"_local_timestamp": "2026-01-25T23:41:57.832970+00:00", "data": {"market": "0x4d0d43382de6021ce0e906774caf6fc73fbe24078c9a75c6d7ae07b04299f8d0", "price_changes": [{"asset_id": "25543244747871931789882457929775858252769380692407983079026060150445462771991", "price": "0.003", "size": "113.04", "side": "BUY", "hash": "a70247fb6a70cd21a27e3e8ff01d6ebbdca54bfe", "best_bid": "0.036", "best_ask": "0.04"}, {"asset_id": "15034789978615861173828275849657317503022772763977464100542193185148987457338", "price": "0.997", "size": "113.04", "side": "SELL", "hash": "0378ea47b116d61394b33bb4f0dfb986a4d2ea10", "best_bid": "0.96", "best_ask": "0.964"}], "timestamp": "1769384517738", "event_type": "price_change"}}
{"_local_timestamp": "2026-01-25T23:41:58.107992+00:00", "data": {"market": "0x4d0d43382de6021ce0e906774caf6fc73fbe24078c9a75c6d7ae07b04299f8d0", "price_changes": [{"asset_id": "25543244747871931789882457929775858252769380692407983079026060150445462771991", "price": "0.003", "size": "120.97", "side": "BUY", "hash": "c9d6cb06c7fe6228428af4af4eed27e9a4f3d2d7", "best_bid": "0.036", "best_ask": "0.04"}, {"asset_id": "15034789978615861173828275849657317503022772763977464100542193185148987457338", "price": "0.997", "size": "120.97", "side": "SELL", "hash": "e872fd28a0e903db6cb0ee7c7726bd336b77d63d", "best_bid": "0.96", "best_ask": "0.964"}], "timestamp": "1769384518015", "event_type": "price_change"}}
{"_local_timestamp": "2026-01-25T23:41:58.797050+00:00", "data": {"market": "0x4d0d43382de6021ce0e906774caf6fc73fbe24078c9a75c6d7ae07b04299f8d0", "price_changes": [{"asset_id": "25543244747871931789882457929775858252769380692407983079026060150445462771991", "price": "0.003", "size": "113.04", "side": "BUY", "hash": "88d5996eef0143dbe0e428f788c0c0a4dfa65e5e", "best_bid": "0.036", "best_ask": "0.04"}, {"asset_id": "15034789978615861173828275849657317503022772763977464100542193185148987457338", "price": "0.997", "size": "113.04", "side": "SELL", "hash": "1c62bb8ebde1fdb5014318b930345702493d18b6", "best_bid": "0.96", "best_ask": "0.964"}], "timestamp": "1769384518729", "event_type": "price_change"}}
{"_local_timestamp": "2026-01-25T23:41:58.995056+00:00", "data": {"market": "0x4d0d43382de6021ce0e906774caf6fc73fbe24078c9a75c6d7ae07b04299f8d0", "price_changes": [{"asset_id": "25543244747871931789882457929775858252769380692407983079026060150445462771991", "price": "0.004", "size": "5.95", "side": "BUY", "hash": "b1cb8ba7f7657ab16cccd8040c0bbbf5ff68e772", "best_bid": "0.036", "best_ask": "0.04"}, {"asset_id": "15034789978615861173828275849657317503022772763977464100542193185148987457338", "price": "0.996", "size": "5.95", "side": "SELL", "hash": "2c6db1ede5556e817b36239d1999e015f32bc4b9", "best_bid": "0.96", "best_ask": "0.964"}], "timestamp": "1769384518930", "event_type": "price_change"}}
{"_local_timestamp": "2026-01-25T23:41:59.647809+00:00", "data": {"market": "0x4d0d43382de6021ce0e906774caf6fc73fbe24078c9a75c6d7ae07b04299f8d0", "price_changes": [{"asset_id": "15034789978615861173828275849657317503022772763977464100542193185148987457338", "price": "0.316", "size": "0", "side": "BUY", "hash": "537a629a415f4f9d52f1324743c77c2fca093449", "best_bid": "0.96", "best_ask": "0.964"}, {"asset_id": "25543244747871931789882457929775858252769380692407983079026060150445462771991", "price": "0.684", "size": "0", "side": "SELL", "hash": "1d69e5ea8d6cd31fe2bb36e170dda41e43fb2193", "best_bid": "0.036", "best_ask": "0.04"}], "timestamp": "1769384519574", "event_type": "price_change"}}
{"_local_timestamp": "2026-01-25T23:41:59.919969+00:00", "data": {"market": "0x4d0d43382de6021ce0e906774caf6fc73fbe24078c9a75c6d7ae07b04299f8d0", "price_changes": [{"asset_id": "15034789978615861173828275849657317503022772763977464100542193185148987457338", "price": "0.316", "size": "5", "side": "BUY", "hash": "d1bc1e2590c3fc6daf6e5dd82809f0a403d70757", "best_bid": "0.96", "best_ask": "0.964"}, {"asset_id": "25543244747871931789882457929775858252769380692407983079026060150445462771991", "price": "0.684", "size": "5", "side": "SELL", "hash": "ab88c154903d719380de496633eb44a1fe38c008", "best_bid": "0.036", "best_ask": "0.04"}], "timestamp": "1769384519849", "event_type": "price_change"}}
{"_local_timestamp": "2026-01-25T23:42:00.124544+00:00", "data": {"market": "0x4d0d43382de6021ce0e906774caf6fc73fbe24078c9a75c6d7ae07b04299f8d0", "price_changes": [{"asset_id": "25543244747871931789882457929775858252769380692407983079026060150445462771991", "price": "0.004", "size": "0", "side": "BUY", "hash": "a5ff91e5266ae82889589753389983d63c015a7e", "best_bid": "0.036", "best_ask": "0.04"}, {"asset_id": "15034789978615861173828275849657317503022772763977464100542193185148987457338", "price": "0.996", "size": "0", "side": "SELL", "hash": "3b6a322a3c4c09bddcc6f1978fe4c1e47950f2d4", "best_bid": "0.96", "best_ask": "0.964"}], "timestamp": "1769384520006", "event_type": "price_change"}}
{"_local_timestamp": "2026-01-25T23:42:00.300734+00:00", "data": {"market": "0x4d0d43382de6021ce0e906774caf6fc73fbe24078c9a75c6d7ae07b04299f8d0", "price_changes": [{"asset_id": "25543244747871931789882457929775858252769380692407983079026060150445462771991", "price": "0.003", "size": "120.97", "side": "BUY", "hash": "ac28f972818d050ee88f29d997ed5cb87e88b912", "best_bid": "0.036", "best_ask": "0.04"}, {"asset_id": "15034789978615861173828275849657317503022772763977464100542193185148987457338", "price": "0.997", "size": "120.97", "side": "SELL", "hash": "593ce4551c81341e140928cb0e65e57be89a66ba", "best_bid": "0.96", "best_ask": "0.964"}], "timestamp": "1769384520233", "event_type": "price_change"}}
{"_local_timestamp": "2026-01-25T23:42:00.984758+00:00", "data": {"market": "0x4d0d43382de6021ce0e906774caf6fc73fbe24078c9a75c6d7ae07b04299f8d0", "price_changes": [{"asset_id": "25543244747871931789882457929775858252769380692407983079026060150445462771991", "price": "0.003", "size": "113.04", "side": "BUY", "hash": "7983d7e8a60c97b06c4ab785f9458dae68fe4d19", "best_bid": "0.036", "best_ask": "0.04"}, {"asset_id": "15034789978615861173828275849657317503022772763977464100542193185148987457338", "price": "0.997", "size": "113.04", "side": "SELL", "hash": "70d0d2e24d1a827c3bac12499946ad00b4b6be30", "best_bid": "0.96", "best_ask": "0.964"}], "timestamp": "1769384520916", "event_type": "price_change"}}
{"_local_timestamp": "2026-01-25T23:42:01.267149+00:00", "data": {"market": "0x4d0d43382de6021ce0e906774caf6fc73fbe24078c9a75c6d7ae07b04299f8d0", "price_changes": [{"asset_id": "25543244747871931789882457929775858252769380692407983079026060150445462771991", "price": "0.003", "size": "120.97", "side": "BUY", "hash": "d573a2c79dc6425a68dd318d7950f8193689f4c9", "best_bid": "0.036", "best_ask": "0.04"}, {"asset_id": "15034789978615861173828275849657317503022772763977464100542193185148987457338", "price": "0.997", "size": "120.97", "side": "SELL", "hash": "8eabebd4ba4d09a2d3d1e4a11caa4aad0d93dc7f", "best_bid": "0.96", "best_ask": "0.964"}], "timestamp": "1769384521202", "event_type": "price_change"}}
{"_local_timestamp": "2026-01-25T23:42:02.290474+00:00", "data": {"market": "0x4d0d43382de6021ce0e906774caf6fc73fbe24078c9a75c6d7ae07b04299f8d0", "price_changes": [{"asset_id": "15034789978615861173828275849657317503022772763977464100542193185148987457338", "price": "0.316", "size": "0", "side": "BUY", "hash": "cd168540706343885b7430d1fb92a2b8d3c7e5e3", "best_bid": "0.96", "best_ask": "0.964"}, {"asset_id": "25543244747871931789882457929775858252769380692407983079026060150445462771991", "price": "0.684", "size": "0", "side": "SELL", "hash": "7c051dd07ace4f1455b5bd12f6afc065721e3d38", "best_bid": "0.036", "best_ask": "0.04"}], "timestamp": "1769384522225", "event_type": "price_change"}}
{"_local_timestamp": "2026-01-25T23:42:02.651934+00:00", "data": {"market": "0x4d0d43382de6021ce0e906774caf6fc73fbe24078c9a75c6d7ae07b04299f8d0", "price_changes": [{"asset_id": "15034789978615861173828275849657317503022772763977464100542193185148987457338", "price": "0.316", "size": "5", "side": "BUY", "hash": "4a5d554328c5933f6790a1fe98cb91549d97e767", "best_bid": "0.96", "best_ask": "0.964"}, {"asset_id": "25543244747871931789882457929775858252769380692407983079026060150445462771991", "price": "0.684", "size": "5", "side": "SELL", "hash": "53f5a2d55e9145d153320bf9d2d54cad6ca69655", "best_bid": "0.036", "best_ask": "0.04"}], "timestamp": "1769384522586", "event_type": "price_change"}}
{"_local_timestamp": "2026-01-25T23:42:02.720698+00:00", "data": {"market": "0x4d0d43382de6021ce0e906774caf6fc73fbe24078c9a75c6d7ae07b04299f8d0", "price_changes": [{"asset_id": "25543244747871931789882457929775858252769380692407983079026060150445462771991", "price": "0.003", "size": "113.04", "side": "BUY", "hash": "5f5d1106cf95f8a289dfef3182f3b45573be6e40", "best_bid": "0.036", "best_ask": "0.04"}, {"asset_id": "15034789978615861173828275849657317503022772763977464100542193185148987457338", "price": "0.997", "size": "113.04", "side": "SELL", "hash": "cd3cb261cb71caa69817604e2f5820030b09f4f0", "best_bid": "0.96", "best_ask": "0.964"}], "timestamp": "1769384522656", "event_type": "price_change"}}
{"_local_timestamp": "2026-01-25T23:42:03.012520+00:00", "data": {"market": "0x4d0d43382de6021ce0e906774caf6fc73fbe24078c9a75c6d7ae07b04299f8d0", "price_changes": [{"asset_id": "25543244747871931789882457929775858252769380692407983079026060150445462771991", "price": "0.003", "size": "120.97", "side": "BUY", "hash": "5e04980b232a02ad3e0a0c0b113505c68bbb9395", "best_bid": "0.036", "best_ask": "0.04"}, {"asset_id": "15034789978615861173828275849657317503022772763977464100542193185148987457338", "price": "0.997", "size": "120.97", "side": "SELL", "hash": "a58381940b77cb7bc114709decad5116b6d1a978", "best_bid": "0.96", "best_ask": "0.964"}], "timestamp": "1769384522934", "event_type": "price_change"}}
{"_local_timestamp": "2026-01-25T23:42:04.891727+00:00", "data": {"market": "0x4d0d43382de6021ce0e906774caf6fc73fbe24078c9a75c6d7ae07b04299f8d0", "price_changes": [{"asset_id": "15034789978615861173828275849657317503022772763977464100542193185148987457338", "price": "0.316", "size": "0", "side": "BUY", "hash": "234a06b4cc91f0cd39c7908bbc3bcb3b802098a6", "best_bid": "0.96", "best_ask": "0.964"}, {"asset_id": "25543244747871931789882457929775858252769380692407983079026060150445462771991", "price": "0.684", "size": "0", "side": "SELL", "hash": "c4ea2a727eebf53d6bd9bb2138a2831eed76a644", "best_bid": "0.036", "best_ask": "0.04"}], "timestamp": "1769384524821", "event_type": "price_change"}}
{"_local_timestamp": "2026-01-25T23:42:04.894187+00:00", "data": {"market": "0x4d0d43382de6021ce0e906774caf6fc73fbe24078c9a75c6d7ae07b04299f8d0", "price_changes": [{"asset_id": "25543244747871931789882457929775858252769380692407983079026060150445462771991", "price": "0.003", "size": "113.04", "side": "BUY", "hash": "7fb2813a1d642a5a5868e6eab7fd0773dbb2e3be", "best_bid": "0.036", "best_ask": "0.04"}, {"asset_id": "15034789978615861173828275849657317503022772763977464100542193185148987457338", "price": "0.997", "size": "113.04", "side": "SELL", "hash": "d1a55c2f8359ffbb450fe12d6287e8ea38bd53fc", "best_bid": "0.96", "best_ask": "0.964"}], "timestamp": "1769384524822", "event_type": "price_change"}}
{"_local_timestamp": "2026-01-25T23:42:05.207785+00:00", "data": {"market": "0x4d0d43382de6021ce0e906774caf6fc73fbe24078c9a75c6d7ae07b04299f8d0", "price_changes": [{"asset_id": "25543244747871931789882457929775858252769380692407983079026060150445462771991", "price": "0.003", "size": "120.97", "side": "BUY", "hash": "518280b2cf83de7b4e73f3a0fe44e0a426f3c949", "best_bid": "0.036", "best_ask": "0.04"}, {"asset_id": "15034789978615861173828275849657317503022772763977464100542193185148987457338", "price": "0.997", "size": "120.97", "side": "SELL", "hash": "b606531e2f18cdf28f32493208e2aa53a3ef9908", "best_bid": "0.96", "best_ask": "0.964"}], "timestamp": "1769384525134", "event_type": "price_change"}}
{"_local_timestamp": "2026-01-25T23:42:05.210110+00:00", "data": {"market": "0x4d0d43382de6021ce0e906774caf6fc73fbe24078c9a75c6d7ae07b04299f8d0", "price_changes": [{"asset_id": "15034789978615861173828275849657317503022772763977464100542193185148987457338", "price": "0.316", "size": "5", "side": "BUY", "hash": "23f4d0d1648c8377c273f539e9de6e600fea5c53", "best_bid": "0.96", "best_ask": "0.964"}, {"asset_id": "25543244747871931789882457929775858252769380692407983079026060150445462771991", "price": "0.684", "size": "5", "side": "SELL", "hash": "975b53f61b7b7c8d94b12ac352fc80cfdbb5cc9e", "best_bid": "0.036", "best_ask": "0.04"}], "timestamp": "1769384525139", "event_type": "price_change"}}
{"_local_timestamp": "2026-01-25T23:42:06.187697+00:00", "data": {"market": "0x4d0d43382de6021ce0e906774caf6fc73fbe24078c9a75c6d7ae07b04299f8d0", "price_changes": [{"asset_id": "25543244747871931789882457929775858252769380692407983079026060150445462771991", "price": "0.003", "size": "113.04", "side": "BUY", "hash": "4bf4db5db86884950c5eeb83545b1cdfa1a0615e", "best_bid": "0.036", "best_ask": "0.04"}, {"asset_id": "15034789978615861173828275849657317503022772763977464100542193185148987457338", "price": "0.997", "size": "113.04", "side": "SELL", "hash": "7a725dda320bbd4a40939e04dcc37e4e8178f043", "best_bid": "0.96", "best_ask": "0.964"}], "timestamp": "1769384526122", "event_type": "price_change"}}
{"_local_timestamp": "2026-01-25T23:42:06.475559+00:00", "data": {"market": "0x4d0d43382de6021ce0e906774caf6fc73fbe24078c9a75c6d7ae07b04299f8d0", "price_changes": [{"asset_id": "25543244747871931789882457929775858252769380692407983079026060150445462771991", "price": "0.003", "size": "120.97", "side": "BUY", "hash": "e5613ccc7f7821040f8b06cbb2f8339f612c0dd0", "best_bid": "0.036", "best_ask": "0.04"}, {"asset_id": "15034789978615861173828275849657317503022772763977464100542193185148987457338", "price": "0.997", "size": "120.97", "side": "SELL", "hash": "505f29931708d215e25a9ee01a28112d418769c9", "best_bid": "0.96", "best_ask": "0.964"}], "timestamp": "1769384526405", "event_type": "price_change"}}
{"_local_timestamp": "2026-01-25T23:42:07.091913+00:00", "data": {"market": "0x4d0d43382de6021ce0e906774caf6fc73fbe24078c9a75c6d7ae07b04299f8d0", "price_changes": [{"asset_id": "15034789978615861173828275849657317503022772763977464100542193185148987457338", "price": "0.316", "size": "0", "side": "BUY", "hash": "21d95b20ed26fe69fc49f078d4db40ffae9d9bbb", "best_bid": "0.96", "best_ask": "0.964"}, {"asset_id": "25543244747871931789882457929775858252769380692407983079026060150445462771991", "price": "0.684", "size": "0", "side": "SELL", "hash": "0a5729027f438c825b485820966201e9ed2617e0", "best_bid": "0.036", "best_ask": "0.04"}], "timestamp": "1769384527003", "event_type": "price_change"}}
{"_local_timestamp": "2026-01-25T23:42:07.421288+00:00", "data": {"market": "0x4d0d43382de6021ce0e906774caf6fc73fbe24078c9a75c6d7ae07b04299f8d0", "price_changes": [{"asset_id": "15034789978615861173828275849657317503022772763977464100542193185148987457338", "price": "0.316", "size": "5", "side": "BUY", "hash": "b0a9056dcf9bca76051aaf60a045aa7be627a7a2", "best_bid": "0.96", "best_ask": "0.964"}, {"asset_id": "25543244747871931789882457929775858252769380692407983079026060150445462771991", "price": "0.684", "size": "5", "side": "SELL", "hash": "012a94b674e48bbcbbcc024b50635956a9201c78", "best_bid": "0.036", "best_ask": "0.04"}], "timestamp": "1769384527355", "event_type": "price_change"}}
{"_local_timestamp": "2026-01-25T23:42:07.503848+00:00", "data": {"market": "0x4d0d43382de6021ce0e906774caf6fc73fbe24078c9a75c6d7ae07b04299f8d0", "price_changes": [{"asset_id": "25543244747871931789882457929775858252769380692407983079026060150445462771991", "price": "0.003", "size": "113.04", "side": "BUY", "hash": "fa50f479c8d2d4a851badde03aabb8b6a9cca527", "best_bid": "0.036", "best_ask": "0.04"}, {"asset_id": "15034789978615861173828275849657317503022772763977464100542193185148987457338", "price": "0.997", "size": "113.04", "side": "SELL", "hash": "a11bb52ecb274ef0ee8098341f1cc2b81260e4c7", "best_bid": "0.96", "best_ask": "0.964"}], "timestamp": "1769384527437", "event_type": "price_change"}}
{"_local_timestamp": "2026-01-25T23:42:07.819207+00:00", "data": {"market": "0x4d0d43382de6021ce0e906774caf6fc73fbe24078c9a75c6d7ae07b04299f8d0", "price_changes": [{"asset_id": "25543244747871931789882457929775858252769380692407983079026060150445462771991", "price": "0.003", "size": "120.97", "side": "BUY", "hash": "e37cce59e751463ac46b5fdb1e10fbe8da25edce", "best_bid": "0.036", "best_ask": "0.04"}, {"asset_id": "15034789978615861173828275849657317503022772763977464100542193185148987457338", "price": "0.997", "size": "120.97", "side": "SELL", "hash": "2e66e10e05fa41f68d2e869e901bee5b0ffb9a48", "best_bid": "0.96", "best_ask": "0.964"}], "timestamp": "1769384527750", "event_type": "price_change"}}
{"_local_timestamp": "2026-01-25T23:42:08.788260+00:00", "data": {"market": "0x4d0d43382de6021ce0e906774caf6fc73fbe24078c9a75c6d7ae07b04299f8d0", "price_changes": [{"asset_id": "25543244747871931789882457929775858252769380692407983079026060150445462771991", "price": "0.003", "size": "113.04", "side": "BUY", "hash": "cdefc22722c74b13ec8b76f0e81424980d7eb00c", "best_bid": "0.036", "best_ask": "0.04"}, {"asset_id": "15034789978615861173828275849657317503022772763977464100542193185148987457338", "price": "0.997", "size": "113.04", "side": "SELL", "hash": "139f94784cfcfc0d3fcc16caa486d84c242b48fd", "best_bid": "0.96", "best_ask": "0.964"}], "timestamp": "1769384528721", "event_type": "price_change"}}
{"_local_timestamp": "2026-01-25T23:42:09.100832+00:00", "data": {"market": "0x4d0d43382de6021ce0e906774caf6fc73fbe24078c9a75c6d7ae07b04299f8d0", "price_changes": [{"asset_id": "25543244747871931789882457929775858252769380692407983079026060150445462771991", "price": "0.003", "size": "120.97", "side": "BUY", "hash": "12cd04c08729077ba0a72cce8047df6745492ae8", "best_bid": "0.036", "best_ask": "0.04"}, {"asset_id": "15034789978615861173828275849657317503022772763977464100542193185148987457338", "price": "0.997", "size": "120.97", "side": "SELL", "hash": "87e5a70f8111fd862d2c08f92bf369c0ef981586", "best_bid": "0.96", "best_ask": "0.964"}], "timestamp": "1769384529020", "event_type": "price_change"}}
{"_local_timestamp": "2026-01-25T23:42:10.128539+00:00", "data": {"market": "0x4d0d43382de6021ce0e906774caf6fc73fbe24078c9a75c6d7ae07b04299f8d0", "price_changes": [{"asset_id": "15034789978615861173828275849657317503022772763977464100542193185148987457338", "price": "0.316", "size": "0", "side": "BUY", "hash": "e8d520db91cb2842be576a92f54e209734f4b076", "best_bid": "0.96", "best_ask": "0.964"}, {"asset_id": "25543244747871931789882457929775858252769380692407983079026060150445462771991", "price": "0.684", "size": "0", "side": "SELL", "hash": "437ccbadbdd81879348e5047bc97ea81ca167cb5", "best_bid": "0.036", "best_ask": "0.04"}], "timestamp": "1769384530020", "event_type": "price_change"}}
{"_local_timestamp": "2026-01-25T23:42:10.131254+00:00", "data": {"market": "0x4d0d43382de6021ce0e906774caf6fc73fbe24078c9a75c6d7ae07b04299f8d0", "price_changes": [{"asset_id": "25543244747871931789882457929775858252769380692407983079026060150445462771991", "price": "0.003", "size": "113.04", "side": "BUY", "hash": "25158c90b06bc0a890e9a5197789cdee13da0690", "best_bid": "0.036", "best_ask": "0.04"}, {"asset_id": "15034789978615861173828275849657317503022772763977464100542193185148987457338", "price": "0.997", "size": "113.04", "side": "SELL", "hash": "cd1b9903102c4835b14e2e77a1f0c6597d37482f", "best_bid": "0.96", "best_ask": "0.964"}], "timestamp": "1769384530021", "event_type": "price_change"}}
{"_local_timestamp": "2026-01-25T23:42:10.383358+00:00", "data": {"market": "0x4d0d43382de6021ce0e906774caf6fc73fbe24078c9a75c6d7ae07b04299f8d0", "price_changes": [{"asset_id": "15034789978615861173828275849657317503022772763977464100542193185148987457338", "price": "0.316", "size": "5", "side": "BUY", "hash": "43b2cbedbe007e287809722ee70b59013af61b57", "best_bid": "0.96", "best_ask": "0.964"}, {"asset_id": "25543244747871931789882457929775858252769380692407983079026060150445462771991", "price": "0.684", "size": "5", "side": "SELL", "hash": "731f1cee7cceada16f72469163091c1e300902ad", "best_bid": "0.036", "best_ask": "0.04"}], "timestamp": "1769384530320", "event_type": "price_change"}}
{"_local_timestamp": "2026-01-25T23:42:10.399512+00:00", "data": {"market": "0x4d0d43382de6021ce0e906774caf6fc73fbe24078c9a75c6d7ae07b04299f8d0", "price_changes": [{"asset_id": "25543244747871931789882457929775858252769380692407983079026060150445462771991", "price": "0.004", "size": "5.95", "side": "BUY", "hash": "a3306856a55944018d20b4de84588c4a92f42342", "best_bid": "0.036", "best_ask": "0.04"}, {"asset_id": "15034789978615861173828275849657317503022772763977464100542193185148987457338", "price": "0.996", "size": "5.95", "side": "SELL", "hash": "b2d5592f4309359fc289f8718520ee5636235c46", "best_bid": "0.96", "best_ask": "0.964"}], "timestamp": "1769384530321", "event_type": "price_change"}}
{"_local_timestamp": "2026-01-25T23:42:11.375874+00:00", "data": {"market": "0x4d0d43382de6021ce0e906774caf6fc73fbe24078c9a75c6d7ae07b04299f8d0", "price_changes": [{"asset_id": "25543244747871931789882457929775858252769380692407983079026060150445462771991", "price": "0.004", "size": "0", "side": "BUY", "hash": "155560d208a14e066d5abeb4d98ccac2dc1d2e3b", "best_bid": "0.036", "best_ask": "0.04"}, {"asset_id": "15034789978615861173828275849657317503022772763977464100542193185148987457338", "price": "0.996", "size": "0", "side": "SELL", "hash": "acfcf3a032b004211a6c206c42642c31b7290600", "best_bid": "0.96", "best_ask": "0.964"}], "timestamp": "1769384531308", "event_type": "price_change"}}
{"_local_timestamp": "2026-01-25T23:42:11.732415+00:00", "data": {"market": "0x4d0d43382de6021ce0e906774caf6fc73fbe24078c9a75c6d7ae07b04299f8d0", "price_changes": [{"asset_id": "25543244747871931789882457929775858252769380692407983079026060150445462771991", "price": "0.003", "size": "120.97", "side": "BUY", "hash": "b764a4e92bac4e2d6290d333df93ee5985d16f2b", "best_bid": "0.036", "best_ask": "0.04"}, {"asset_id": "15034789978615861173828275849657317503022772763977464100542193185148987457338", "price": "0.997", "size": "120.97", "side": "SELL", "hash": "b36980947c35dad9864dd81997f7a927d752e67b", "best_bid": "0.96", "best_ask": "0.964"}], "timestamp": "1769384531662", "event_type": "price_change"}}
{"_local_timestamp": "2026-01-25T23:42:12.244035+00:00", "data": {"market": "0x4d0d43382de6021ce0e906774caf6fc73fbe24078c9a75c6d7ae07b04299f8d0", "price_changes": [{"asset_id": "15034789978615861173828275849657317503022772763977464100542193185148987457338", "price": "0.316", "size": "0", "side": "BUY", "hash": "48c0ca68ee2d70e01b992a7ef6772a9b3f7c67eb", "best_bid": "0.96", "best_ask": "0.964"}, {"asset_id": "25543244747871931789882457929775858252769380692407983079026060150445462771991", "price": "0.684", "size": "0", "side": "SELL", "hash": "6981cd1c48593b1f90683703779a75848fe50a4f", "best_bid": "0.036", "best_ask": "0.04"}], "timestamp": "1769384532161", "event_type": "price_change"}}
{"_local_timestamp": "2026-01-25T23:42:12.480268+00:00", "data": {"market": "0x4d0d43382de6021ce0e906774caf6fc73fbe24078c9a75c6d7ae07b04299f8d0", "price_changes": [{"asset_id": "15034789978615861173828275849657317503022772763977464100542193185148987457338", "price": "0.316", "size": "5", "side": "BUY", "hash": "b14b87de53975fdc93f9bb8a208b0b744d7c5054", "best_bid": "0.96", "best_ask": "0.964"}, {"asset_id": "25543244747871931789882457929775858252769380692407983079026060150445462771991", "price": "0.684", "size": "5", "side": "SELL", "hash": "6e9fe9b13fc3d40944ea6848d0023396d548be86", "best_bid": "0.036", "best_ask": "0.04"}], "timestamp": "1769384532412", "event_type": "price_change"}}
{"_local_timestamp": "2026-01-25T23:42:13.508055+00:00", "data": {"market": "0x4d0d43382de6021ce0e906774caf6fc73fbe24078c9a75c6d7ae07b04299f8d0", "price_changes": [{"asset_id": "25543244747871931789882457929775858252769380692407983079026060150445462771991", "price": "0.003", "size": "113.04", "side": "BUY", "hash": "bcb41b693eddcd84ad0db253fb53f6445ec43afc", "best_bid": "0.036", "best_ask": "0.04"}, {"asset_id": "15034789978615861173828275849657317503022772763977464100542193185148987457338", "price": "0.997", "size": "113.04", "side": "SELL", "hash": "9785e9f8adde0c5ad182b82e9c20e0e475bdde05", "best_bid": "0.96", "best_ask": "0.964"}], "timestamp": "1769384533438", "event_type": "price_change"}}
{"_local_timestamp": "2026-01-25T23:42:13.740293+00:00", "data": {"market": "0x4d0d43382de6021ce0e906774caf6fc73fbe24078c9a75c6d7ae07b04299f8d0", "price_changes": [{"asset_id": "25543244747871931789882457929775858252769380692407983079026060150445462771991", "price": "0.003", "size": "120.97", "side": "BUY", "hash": "c9fbdd27a2aff3731ea17e64a211ccc27ab99e40", "best_bid": "0.036", "best_ask": "0.04"}, {"asset_id": "15034789978615861173828275849657317503022772763977464100542193185148987457338", "price": "0.997", "size": "120.97", "side": "SELL", "hash": "8f906adb2ea7125c57f80e36e220f7d6350fe2ca", "best_bid": "0.96", "best_ask": "0.964"}], "timestamp": "1769384533673", "event_type": "price_change"}}
{"_local_timestamp": "2026-01-25T23:42:14.804341+00:00", "data": {"market": "0x4d0d43382de6021ce0e906774caf6fc73fbe24078c9a75c6d7ae07b04299f8d0", "price_changes": [{"asset_id": "15034789978615861173828275849657317503022772763977464100542193185148987457338", "price": "0.316", "size": "0", "side": "BUY", "hash": "4edc3d18dac5d0cd3acb8caf7d16c5b2d43905ab", "best_bid": "0.96", "best_ask": "0.964"}, {"asset_id": "25543244747871931789882457929775858252769380692407983079026060150445462771991", "price": "0.684", "size": "0", "side": "SELL", "hash": "3e5ad5ef03b0039e500ef33498b3ed6dcf0dc3ca", "best_bid": "0.036", "best_ask": "0.04"}], "timestamp": "1769384534719", "event_type": "price_change"}}
{"_local_timestamp": "2026-01-25T23:42:15.117107+00:00", "data": {"market": "0x4d0d43382de6021ce0e906774caf6fc73fbe24078c9a75c6d7ae07b04299f8d0", "price_changes": [{"asset_id": "15034789978615861173828275849657317503022772763977464100542193185148987457338", "price": "0.316", "size": "5", "side": "BUY", "hash": "88d52e93e61aeccd2d2f6fee2ba14222823146be", "best_bid": "0.96", "best_ask": "0.964"}, {"asset_id": "25543244747871931789882457929775858252769380692407983079026060150445462771991", "price": "0.684", "size": "5", "side": "SELL", "hash": "153425ad365f9dd7dc16f6e44065997d7efcbcc6", "best_bid": "0.036", "best_ask": "0.04"}], "timestamp": "1769384535041", "event_type": "price_change"}}
{"_local_timestamp": "2026-01-25T23:42:15.324209+00:00", "data": {"market": "0x4d0d43382de6021ce0e906774caf6fc73fbe24078c9a75c6d7ae07b04299f8d0", "price_changes": [{"asset_id": "25543244747871931789882457929775858252769380692407983079026060150445462771991", "price": "0.003", "size": "113.04", "side": "BUY", "hash": "b69d71971d570279532ddab163ae0710cd86b5a7", "best_bid": "0.036", "best_ask": "0.04"}, {"asset_id": "15034789978615861173828275849657317503022772763977464100542193185148987457338", "price": "0.997", "size": "113.04", "side": "SELL", "hash": "dd5852e780960a8ffcebf12b20536a249bcf2646", "best_bid": "0.96", "best_ask": "0.964"}], "timestamp": "1769384535185", "event_type": "price_change"}}
{"_local_timestamp": "2026-01-25T23:42:15.614905+00:00", "data": {"market": "0x4d0d43382de6021ce0e906774caf6fc73fbe24078c9a75c6d7ae07b04299f8d0", "price_changes": [{"asset_id": "25543244747871931789882457929775858252769380692407983079026060150445462771991", "price": "0.004", "size": "5.95", "side": "BUY", "hash": "e2d85f62a4bc9cce3bdad7a0ca3dbb9ddd0811f8", "best_bid": "0.036", "best_ask": "0.04"}, {"asset_id": "15034789978615861173828275849657317503022772763977464100542193185148987457338", "price": "0.996", "size": "5.95", "side": "SELL", "hash": "97ae11b30da0a48d7da717e5bb1f5a31b00493e9", "best_bid": "0.96", "best_ask": "0.964"}], "timestamp": "1769384535529", "event_type": "price_change"}}
{"_local_timestamp": "2026-01-25T23:42:16.212514+00:00", "data": {"market": "0x4d0d43382de6021ce0e906774caf6fc73fbe24078c9a75c6d7ae07b04299f8d0", "price_changes": [{"asset_id": "25543244747871931789882457929775858252769380692407983079026060150445462771991", "price": "0.004", "size": "0", "side": "BUY", "hash": "50cd7cd6c6b5117d32f99cd3d9983da65b2d3d01", "best_bid": "0.036", "best_ask": "0.04"}, {"asset_id": "15034789978615861173828275849657317503022772763977464100542193185148987457338", "price": "0.996", "size": "0", "side": "SELL", "hash": "eed1f96b99e1a560657e297b16e6595f4ac7d62f", "best_bid": "0.96", "best_ask": "0.964"}], "timestamp": "1769384536105", "event_type": "price_change"}}
{"_local_timestamp": "2026-01-25T23:42:16.540454+00:00", "data": {"market": "0x4d0d43382de6021ce0e906774caf6fc73fbe24078c9a75c6d7ae07b04299f8d0", "price_changes": [{"asset_id": "25543244747871931789882457929775858252769380692407983079026060150445462771991", "price": "0.003", "size": "120.97", "side": "BUY", "hash": "6d11fa2e484df27cd70fd3d2cbe32933f3da3681", "best_bid": "0.036", "best_ask": "0.04"}, {"asset_id": "15034789978615861173828275849657317503022772763977464100542193185148987457338", "price": "0.997", "size": "120.97", "side": "SELL", "hash": "73a1fb31dfae041dd70b856960600865311e42e1", "best_bid": "0.96", "best_ask": "0.964"}], "timestamp": "1769384536429", "event_type": "price_change"}}
{"_local_timestamp": "2026-01-25T23:42:17.070892+00:00", "data": {"market": "0x4d0d43382de6021ce0e906774caf6fc73fbe24078c9a75c6d7ae07b04299f8d0", "price_changes": [{"asset_id": "15034789978615861173828275849657317503022772763977464100542193185148987457338", "price": "0.316", "size": "0", "side": "BUY", "hash": "fe65492204ea54d6d4ca8571c51e5cfe84d26dc9", "best_bid": "0.96", "best_ask": "0.964"}, {"asset_id": "25543244747871931789882457929775858252769380692407983079026060150445462771991", "price": "0.684", "size": "0", "side": "SELL", "hash": "8260fdba2b6c6314632d181f67c67dad48b5f099", "best_bid": "0.036", "best_ask": "0.04"}], "timestamp": "1769384536982", "event_type": "price_change"}}
{"_local_timestamp": "2026-01-25T23:42:17.406328+00:00", "data": {"market": "0x4d0d43382de6021ce0e906774caf6fc73fbe24078c9a75c6d7ae07b04299f8d0", "price_changes": [{"asset_id": "15034789978615861173828275849657317503022772763977464100542193185148987457338", "price": "0.316", "size": "5", "side": "BUY", "hash": "5aaf675d5d08b787a58db1e8e9364f9a527504b4", "best_bid": "0.96", "best_ask": "0.964"}, {"asset_id": "25543244747871931789882457929775858252769380692407983079026060150445462771991", "price": "0.684", "size": "5", "side": "SELL", "hash": "75333d546bf4c1bb97b80b62db4bb5135f887e78", "best_bid": "0.036", "best_ask": "0.04"}], "timestamp": "1769384537314", "event_type": "price_change"}}
{"_local_timestamp": "2026-01-25T23:42:17.516719+00:00", "data": {"market": "0x4d0d43382de6021ce0e906774caf6fc73fbe24078c9a75c6d7ae07b04299f8d0", "price_changes": [{"asset_id": "25543244747871931789882457929775858252769380692407983079026060150445462771991", "price": "0.003", "size": "113.04", "side": "BUY", "hash": "b5ecad0c3627d051f58dac96ca628bf24de259e7", "best_bid": "0.036", "best_ask": "0.04"}, {"asset_id": "15034789978615861173828275849657317503022772763977464100542193185148987457338", "price": "0.997", "size": "113.04", "side": "SELL", "hash": "24b57c31c7e6dd3849b10d45c23ac77e4d688279", "best_bid": "0.96", "best_ask": "0.964"}], "timestamp": "1769384537420", "event_type": "price_change"}}
{"_local_timestamp": "2026-01-25T23:42:17.845334+00:00", "data": {"market": "0x4d0d43382de6021ce0e906774caf6fc73fbe24078c9a75c6d7ae07b04299f8d0", "price_changes": [{"asset_id": "25543244747871931789882457929775858252769380692407983079026060150445462771991", "price": "0.003", "size": "120.97", "side": "BUY", "hash": "d850cefd2fb0794424f3382448370a5f7ec69a2f", "best_bid": "0.036", "best_ask": "0.04"}, {"asset_id": "15034789978615861173828275849657317503022772763977464100542193185148987457338", "price": "0.997", "size": "120.97", "side": "SELL", "hash": "65b02ef04b6563dbfa92b49ce857243329640d77", "best_bid": "0.96", "best_ask": "0.964"}], "timestamp": "1769384537733", "event_type": "price_change"}}
{"_local_timestamp": "2026-01-25T23:42:18.846239+00:00", "data": {"market": "0x4d0d43382de6021ce0e906774caf6fc73fbe24078c9a75c6d7ae07b04299f8d0", "price_changes": [{"asset_id": "25543244747871931789882457929775858252769380692407983079026060150445462771991", "price": "0.003", "size": "113.04", "side": "BUY", "hash": "f0ecde2f23e0d1193a13412f4129060ab4b68c76", "best_bid": "0.036", "best_ask": "0.04"}, {"asset_id": "15034789978615861173828275849657317503022772763977464100542193185148987457338", "price": "0.997", "size": "113.04", "side": "SELL", "hash": "83625cddab00ada31e0a90d10613d9098aa664a8", "best_bid": "0.96", "best_ask": "0.964"}], "timestamp": "1769384538741", "event_type": "price_change"}}
{"_local_timestamp": "2026-01-25T23:42:19.276113+00:00", "data": {"market": "0x4d0d43382de6021ce0e906774caf6fc73fbe24078c9a75c6d7ae07b04299f8d0", "price_changes": [{"asset_id": "25543244747871931789882457929775858252769380692407983079026060150445462771991", "price": "0.003", "size": "120.97", "side": "BUY", "hash": "6afede4f09f35585081a6b81c0feaae102c7264e", "best_bid": "0.036", "best_ask": "0.04"}, {"asset_id": "15034789978615861173828275849657317503022772763977464100542193185148987457338", "price": "0.997", "size": "120.97", "side": "SELL", "hash": "7edfb26d93106646046158cd935fe2a88c59c24b", "best_bid": "0.96", "best_ask": "0.964"}], "timestamp": "1769384539155", "event_type": "price_change"}}
{"_local_timestamp": "2026-01-25T23:42:19.732086+00:00", "data": {"market": "0x4d0d43382de6021ce0e906774caf6fc73fbe24078c9a75c6d7ae07b04299f8d0", "price_changes": [{"asset_id": "25543244747871931789882457929775858252769380692407983079026060150445462771991", "price": "0.003", "size": "113.04", "side": "BUY", "hash": "83de5d90111ec07a47cb1bd805cc5ecd0b928274", "best_bid": "0.036", "best_ask": "0.04"}, {"asset_id": "15034789978615861173828275849657317503022772763977464100542193185148987457338", "price": "0.997", "size": "113.04", "side": "SELL", "hash": "d508139b023876a58380bd556be505f23b63c602", "best_bid": "0.96", "best_ask": "0.964"}], "timestamp": "1769384539621", "event_type": "price_change"}}
{"_local_timestamp": "2026-01-25T23:42:20.112529+00:00", "data": {"market": "0x4d0d43382de6021ce0e906774caf6fc73fbe24078c9a75c6d7ae07b04299f8d0", "price_changes": [{"asset_id": "25543244747871931789882457929775858252769380692407983079026060150445462771991", "price": "0.003", "size": "120.97", "side": "BUY", "hash": "6f3ce52587e7e11b9839111ff82c3d499cfc111f", "best_bid": "0.036", "best_ask": "0.04"}, {"asset_id": "15034789978615861173828275849657317503022772763977464100542193185148987457338", "price": "0.997", "size": "120.97", "side": "SELL", "hash": "3ddfd0e3f973d1b6e539162837677fd547a8e8a5", "best_bid": "0.96", "best_ask": "0.964"}], "timestamp": "1769384539991", "event_type": "price_change"}}
{"_local_timestamp": "2026-01-25T23:42:21.050661+00:00", "data": {"market": "0x4d0d43382de6021ce0e906774caf6fc73fbe24078c9a75c6d7ae07b04299f8d0", "price_changes": [{"asset_id": "15034789978615861173828275849657317503022772763977464100542193185148987457338", "price": "0.316", "size": "0", "side": "BUY", "hash": "03ada744bf61b83f6171662855f9ca545a4a8732", "best_bid": "0.96", "best_ask": "0.964"}, {"asset_id": "25543244747871931789882457929775858252769380692407983079026060150445462771991", "price": "0.684", "size": "0", "side": "SELL", "hash": "7a4633836a2fa90bca7c036906e46b96e601cc5d", "best_bid": "0.036", "best_ask": "0.04"}], "timestamp": "1769384540926", "event_type": "price_change"}}
{"_local_timestamp": "2026-01-25T23:42:21.335528+00:00", "data": {"market": "0x4d0d43382de6021ce0e906774caf6fc73fbe24078c9a75c6d7ae07b04299f8d0", "price_changes": [{"asset_id": "15034789978615861173828275849657317503022772763977464100542193185148987457338", "price": "0.316", "size": "5", "side": "BUY", "hash": "6829aa548d88aafcf70532c099ee31c5c1cbb915", "best_bid": "0.96", "best_ask": "0.964"}, {"asset_id": "25543244747871931789882457929775858252769380692407983079026060150445462771991", "price": "0.684", "size": "5", "side": "SELL", "hash": "3ea2446969fd93b1b3ef3785820cd9d74e91a24f", "best_bid": "0.036", "best_ask": "0.04"}], "timestamp": "1769384541214", "event_type": "price_change"}}
{"_local_timestamp": "2026-01-25T23:42:21.486924+00:00", "data": {"market": "0x4d0d43382de6021ce0e906774caf6fc73fbe24078c9a75c6d7ae07b04299f8d0", "price_changes": [{"asset_id": "25543244747871931789882457929775858252769380692407983079026060150445462771991", "price": "0.003", "size": "113.04", "side": "BUY", "hash": "df9b208fa26745617144cbba78dbf50375ceb84d", "best_bid": "0.036", "best_ask": "0.04"}, {"asset_id": "15034789978615861173828275849657317503022772763977464100542193185148987457338", "price": "0.997", "size": "113.04", "side": "SELL", "hash": "0f6b62e9da392c5e0f2d0d16e2042c13442ee89d", "best_bid": "0.96", "best_ask": "0.964"}], "timestamp": "1769384541358", "event_type": "price_change"}}
{"_local_timestamp": "2026-01-25T23:42:21.875977+00:00", "data": {"market": "0x4d0d43382de6021ce0e906774caf6fc73fbe24078c9a75c6d7ae07b04299f8d0", "price_changes": [{"asset_id": "25543244747871931789882457929775858252769380692407983079026060150445462771991", "price": "0.003", "size": "120.97", "side": "BUY", "hash": "0694d3e78a2c8fd5d7740c53570496b1692e94d6", "best_bid": "0.036", "best_ask": "0.04"}, {"asset_id": "15034789978615861173828275849657317503022772763977464100542193185148987457338", "price": "0.997", "size": "120.97", "side": "SELL", "hash": "d0304d93a2b729a8b2de212ab7003ffa1041f079", "best_bid": "0.96", "best_ask": "0.964"}], "timestamp": "1769384541748", "event_type": "price_change"}}
{"_local_timestamp": "2026-01-25T23:42:23.237370+00:00", "data": {"market": "0x4d0d43382de6021ce0e906774caf6fc73fbe24078c9a75c6d7ae07b04299f8d0", "price_changes": [{"asset_id": "25543244747871931789882457929775858252769380692407983079026060150445462771991", "price": "0.003", "size": "113.04", "side": "BUY", "hash": "ca1a8b8924c5e000f06e0bd655e04e688bec28cc", "best_bid": "0.036", "best_ask": "0.04"}, {"asset_id": "15034789978615861173828275849657317503022772763977464100542193185148987457338", "price": "0.997", "size": "113.04", "side": "SELL", "hash": "6d446dec74e18a26c3a13076281b720e0678d869", "best_bid": "0.96", "best_ask": "0.964"}], "timestamp": "1769384543085", "event_type": "price_change"}}
{"_local_timestamp": "2026-01-25T23:42:23.768824+00:00", "data": {"market": "0x4d0d43382de6021ce0e906774caf6fc73fbe24078c9a75c6d7ae07b04299f8d0", "price_changes": [{"asset_id": "25543244747871931789882457929775858252769380692407983079026060150445462771991", "price": "0.003", "size": "120.97", "side": "BUY", "hash": "d41a74eda00b46aa7c3777554d661779354e8a47", "best_bid": "0.036", "best_ask": "0.04"}, {"asset_id": "15034789978615861173828275849657317503022772763977464100542193185148987457338", "price": "0.997", "size": "120.97", "side": "SELL", "hash": "bb53fbd129053cef4a865ff81a2b4426be80db1e", "best_bid": "0.96", "best_ask": "0.964"}], "timestamp": "1769384543622", "event_type": "price_change"}}
{"_local_timestamp": "2026-01-25T23:42:24.835429+00:00", "data": {"market": "0x4d0d43382de6021ce0e906774caf6fc73fbe24078c9a75c6d7ae07b04299f8d0", "price_changes": [{"asset_id": "25543244747871931789882457929775858252769380692407983079026060150445462771991", "price": "0.003", "size": "113.04", "side": "BUY", "hash": "d79753826c0aa25eaca1d1845830e49a8c605907", "best_bid": "0.036", "best_ask": "0.04"}, {"asset_id": "15034789978615861173828275849657317503022772763977464100542193185148987457338", "price": "0.997", "size": "113.04", "side": "SELL", "hash": "c0ad3099871ef6bb24137aaae1bef5e9df211db1", "best_bid": "0.96", "best_ask": "0.964"}], "timestamp": "1769384544602", "event_type": "price_change"}}
{"_local_timestamp": "2026-01-25T23:42:25.074326+00:00", "data": {"market": "0x4d0d43382de6021ce0e906774caf6fc73fbe24078c9a75c6d7ae07b04299f8d0", "price_changes": [{"asset_id": "25543244747871931789882457929775858252769380692407983079026060150445462771991", "price": "0.004", "size": "5.95", "side": "BUY", "hash": "95e016aaa1262adbc1d65ceeb2b24a77dabbe86c", "best_bid": "0.036", "best_ask": "0.04"}, {"asset_id": "15034789978615861173828275849657317503022772763977464100542193185148987457338", "price": "0.996", "size": "5.95", "side": "SELL", "hash": "97a957ba4dfa2c34defbbf5cfaad342355715f7e", "best_bid": "0.96", "best_ask": "0.964"}], "timestamp": "1769384544929", "event_type": "price_change"}}
{"_local_timestamp": "2026-01-25T23:42:26.068339+00:00", "data": {"market": "0x4d0d43382de6021ce0e906774caf6fc73fbe24078c9a75c6d7ae07b04299f8d0", "price_changes": [{"asset_id": "25543244747871931789882457929775858252769380692407983079026060150445462771991", "price": "0.004", "size": "0", "side": "BUY", "hash": "8e2b338f99fd7cd19167c437f15f801c678904f3", "best_bid": "0.036", "best_ask": "0.04"}, {"asset_id": "15034789978615861173828275849657317503022772763977464100542193185148987457338", "price": "0.996", "size": "0", "side": "SELL", "hash": "586d592011ee6c089727c9ceb5a7e82cc5dbd64b", "best_bid": "0.96", "best_ask": "0.964"}], "timestamp": "1769384545921", "event_type": "price_change"}}
{"_local_timestamp": "2026-01-25T23:42:26.326501+00:00", "data": {"market": "0x4d0d43382de6021ce0e906774caf6fc73fbe24078c9a75c6d7ae07b04299f8d0", "price_changes": [{"asset_id": "25543244747871931789882457929775858252769380692407983079026060150445462771991", "price": "0.003", "size": "120.97", "side": "BUY", "hash": "7308965f97a89b54440b1e5623ffd09cc72f7ca0", "best_bid": "0.036", "best_ask": "0.04"}, {"asset_id": "15034789978615861173828275849657317503022772763977464100542193185148987457338", "price": "0.997", "size": "120.97", "side": "SELL", "hash": "a4a87aa6679b6402df895ecb049efce40de91626", "best_bid": "0.96", "best_ask": "0.964"}], "timestamp": "1769384546191", "event_type": "price_change"}}
{"_local_timestamp": "2026-01-25T23:42:27.366869+00:00", "data": {"market": "0x4d0d43382de6021ce0e906774caf6fc73fbe24078c9a75c6d7ae07b04299f8d0", "price_changes": [{"asset_id": "15034789978615861173828275849657317503022772763977464100542193185148987457338", "price": "0.316", "size": "0", "side": "BUY", "hash": "0856f4275ed4d9cdfcd1a9b12b7f354704869e5b", "best_bid": "0.96", "best_ask": "0.964"}, {"asset_id": "25543244747871931789882457929775858252769380692407983079026060150445462771991", "price": "0.684", "size": "0", "side": "SELL", "hash": "c549f63806c7a74a877aa140c50a10c14a1ca07c", "best_bid": "0.036", "best_ask": "0.04"}], "timestamp": "1769384547227", "event_type": "price_change"}}
{"_local_timestamp": "2026-01-25T23:42:27.369393+00:00", "data": {"market": "0x4d0d43382de6021ce0e906774caf6fc73fbe24078c9a75c6d7ae07b04299f8d0", "price_changes": [{"asset_id": "25543244747871931789882457929775858252769380692407983079026060150445462771991", "price": "0.003", "size": "113.04", "side": "BUY", "hash": "d74300faf676ed50013984ba95d4da8d8ceb616d", "best_bid": "0.036", "best_ask": "0.04"}, {"asset_id": "15034789978615861173828275849657317503022772763977464100542193185148987457338", "price": "0.997", "size": "113.04", "side": "SELL", "hash": "7e52c3bd5d3bab7670a379dcc23e088215d8fbe3", "best_bid": "0.96", "best_ask": "0.964"}], "timestamp": "1769384547228", "event_type": "price_change"}}
{"_local_timestamp": "2026-01-25T23:42:28.116856+00:00", "data": {"market": "0x4d0d43382de6021ce0e906774caf6fc73fbe24078c9a75c6d7ae07b04299f8d0", "price_changes": [{"asset_id": "15034789978615861173828275849657317503022772763977464100542193185148987457338", "price": "0.316", "size": "5", "side": "BUY", "hash": "a539757f0383a2da0e6b5d9bda177bbe7dbd37c3", "best_bid": "0.96", "best_ask": "0.964"}, {"asset_id": "25543244747871931789882457929775858252769380692407983079026060150445462771991", "price": "0.684", "size": "5", "side": "SELL", "hash": "61724b678d1dfe1429f6cc8a3113687ba263cf4b", "best_bid": "0.036", "best_ask": "0.04"}], "timestamp": "1769384547973", "event_type": "price_change"}}
{"_local_timestamp": "2026-01-25T23:42:28.119307+00:00", "data": {"market": "0x4d0d43382de6021ce0e906774caf6fc73fbe24078c9a75c6d7ae07b04299f8d0", "price_changes": [{"asset_id": "25543244747871931789882457929775858252769380692407983079026060150445462771991", "price": "0.003", "size": "120.97", "side": "BUY", "hash": "0c52592f8cd489abbbf00d5203b0f8e24b8cece1", "best_bid": "0.036", "best_ask": "0.04"}, {"asset_id": "15034789978615861173828275849657317503022772763977464100542193185148987457338", "price": "0.997", "size": "120.97", "side": "SELL", "hash": "6b84269d2d20b44dd9f49c970ab6b71e495ec093", "best_bid": "0.96", "best_ask": "0.964"}], "timestamp": "1769384547974", "event_type": "price_change"}}
{"_local_timestamp": "2026-01-25T23:42:30.364933+00:00", "data": {"market": "0x4d0d43382de6021ce0e906774caf6fc73fbe24078c9a75c6d7ae07b04299f8d0", "price_changes": [{"asset_id": "25543244747871931789882457929775858252769380692407983079026060150445462771991", "price": "0.003", "size": "113.04", "side": "BUY", "hash": "09187b679cf5cf47f60838974431f0629479c710", "best_bid": "0.036", "best_ask": "0.04"}, {"asset_id": "15034789978615861173828275849657317503022772763977464100542193185148987457338", "price": "0.997", "size": "113.04", "side": "SELL", "hash": "9c13656ab767e0cc84b6a7bf0b45b4cced10d562", "best_bid": "0.96", "best_ask": "0.964"}], "timestamp": "1769384550218", "event_type": "price_change"}}
{"_local_timestamp": "2026-01-25T23:42:30.645386+00:00", "data": {"market": "0x4d0d43382de6021ce0e906774caf6fc73fbe24078c9a75c6d7ae07b04299f8d0", "price_changes": [{"asset_id": "25543244747871931789882457929775858252769380692407983079026060150445462771991", "price": "0.003", "size": "120.97", "side": "BUY", "hash": "e30b22c195e0c48d575c5b9298fb6e09fe5f853f", "best_bid": "0.036", "best_ask": "0.04"}, {"asset_id": "15034789978615861173828275849657317503022772763977464100542193185148987457338", "price": "0.997", "size": "120.97", "side": "SELL", "hash": "9a9042cc9215d4a5d55537b33fa09decf05a2138", "best_bid": "0.96", "best_ask": "0.964"}], "timestamp": "1769384550513", "event_type": "price_change"}}
{"_local_timestamp": "2026-01-25T23:42:31.722129+00:00", "data": {"market": "0x4d0d43382de6021ce0e906774caf6fc73fbe24078c9a75c6d7ae07b04299f8d0", "price_changes": [{"asset_id": "25543244747871931789882457929775858252769380692407983079026060150445462771991", "price": "0.003", "size": "113.04", "side": "BUY", "hash": "bd0f4bfe3880c6ff91635b2da4872a4f78b0d7c5", "best_bid": "0.036", "best_ask": "0.04"}, {"asset_id": "15034789978615861173828275849657317503022772763977464100542193185148987457338", "price": "0.997", "size": "113.04", "side": "SELL", "hash": "f5fc5437a1d1ebb177958fccbb1a28b9e5dec29f", "best_bid": "0.96", "best_ask": "0.964"}], "timestamp": "1769384551574", "event_type": "price_change"}}
{"_local_timestamp": "2026-01-25T23:42:32.122919+00:00", "data": {"market": "0x4d0d43382de6021ce0e906774caf6fc73fbe24078c9a75c6d7ae07b04299f8d0", "price_changes": [{"asset_id": "25543244747871931789882457929775858252769380692407983079026060150445462771991", "price": "0.003", "size": "120.97", "side": "BUY", "hash": "c5c5f6bd840c5075e1cf8bb575da52524992e7da", "best_bid": "0.036", "best_ask": "0.04"}, {"asset_id": "15034789978615861173828275849657317503022772763977464100542193185148987457338", "price": "0.997", "size": "120.97", "side": "SELL", "hash": "f8bedb86b602d544d2a5b0373b491adfab919ec2", "best_bid": "0.96", "best_ask": "0.964"}], "timestamp": "1769384551989", "event_type": "price_change"}}
{"_local_timestamp": "2026-01-25T23:42:32.567333+00:00", "data": {"market": "0x4d0d43382de6021ce0e906774caf6fc73fbe24078c9a75c6d7ae07b04299f8d0", "price_changes": [{"asset_id": "25543244747871931789882457929775858252769380692407983079026060150445462771991", "price": "0.003", "size": "113.04", "side": "BUY", "hash": "84c88bd466f544ab2e6aec91450b7a520048e757", "best_bid": "0.036", "best_ask": "0.04"}, {"asset_id": "15034789978615861173828275849657317503022772763977464100542193185148987457338", "price": "0.997", "size": "113.04", "side": "SELL", "hash": "5b2ef703a68824984612c62229bd4ad3bb23528c", "best_bid": "0.96", "best_ask": "0.964"}], "timestamp": "1769384552436", "event_type": "price_change"}}
{"_local_timestamp": "2026-01-25T23:42:33.313747+00:00", "data": {"market": "0x4d0d43382de6021ce0e906774caf6fc73fbe24078c9a75c6d7ae07b04299f8d0", "price_changes": [{"asset_id": "25543244747871931789882457929775858252769380692407983079026060150445462771991", "price": "0.003", "size": "120.97", "side": "BUY", "hash": "b0cfc075f48a168f82d7db89a00b267429edf618", "best_bid": "0.036", "best_ask": "0.04"}, {"asset_id": "15034789978615861173828275849657317503022772763977464100542193185148987457338", "price": "0.997", "size": "120.97", "side": "SELL", "hash": "8be4af8cd15630f888c1d199fd89e7b66ce89811", "best_bid": "0.96", "best_ask": "0.964"}], "timestamp": "1769384553187", "event_type": "price_change"}}
{"_local_timestamp": "2026-01-25T23:42:34.226001+00:00", "data": {"market": "0x4d0d43382de6021ce0e906774caf6fc73fbe24078c9a75c6d7ae07b04299f8d0", "price_changes": [{"asset_id": "15034789978615861173828275849657317503022772763977464100542193185148987457338", "price": "0.316", "size": "0", "side": "BUY", "hash": "863dee6a06f5cfa8ef97057216a9fd8edc653e48", "best_bid": "0.96", "best_ask": "0.964"}, {"asset_id": "25543244747871931789882457929775858252769380692407983079026060150445462771991", "price": "0.684", "size": "0", "side": "SELL", "hash": "1739ee9c54351edf0d7aa3662d1eb728d4365c88", "best_bid": "0.036", "best_ask": "0.04"}], "timestamp": "1769384554099", "event_type": "price_change"}}
{"_local_timestamp": "2026-01-25T23:42:34.492748+00:00", "data": {"market": "0x4d0d43382de6021ce0e906774caf6fc73fbe24078c9a75c6d7ae07b04299f8d0", "price_changes": [{"asset_id": "15034789978615861173828275849657317503022772763977464100542193185148987457338", "price": "0.316", "size": "5", "side": "BUY", "hash": "1065bc46df57ee124bdcea26183bd633fb03fed9", "best_bid": "0.96", "best_ask": "0.964"}, {"asset_id": "25543244747871931789882457929775858252769380692407983079026060150445462771991", "price": "0.684", "size": "5", "side": "SELL", "hash": "7cec6bfb095e36e1e42db4dce4a6e910951246ad", "best_bid": "0.036", "best_ask": "0.04"}], "timestamp": "1769384554369", "event_type": "price_change"}}
{"_local_timestamp": "2026-01-25T23:42:34.670932+00:00", "data": {"market": "0x4d0d43382de6021ce0e906774caf6fc73fbe24078c9a75c6d7ae07b04299f8d0", "price_changes": [{"asset_id": "25543244747871931789882457929775858252769380692407983079026060150445462771991", "price": "0.003", "size": "113.04", "side": "BUY", "hash": "aaf9a3ed95f19869b6e31968261d075c3172d582", "best_bid": "0.036", "best_ask": "0.04"}, {"asset_id": "15034789978615861173828275849657317503022772763977464100542193185148987457338", "price": "0.997", "size": "113.04", "side": "SELL", "hash": "3a10fb108feaa8e008a9498671096ad9b3ca2215", "best_bid": "0.96", "best_ask": "0.964"}], "timestamp": "1769384554543", "event_type": "price_change"}}
{"_local_timestamp": "2026-01-25T23:42:34.978133+00:00", "data": {"market": "0x4d0d43382de6021ce0e906774caf6fc73fbe24078c9a75c6d7ae07b04299f8d0", "price_changes": [{"asset_id": "25543244747871931789882457929775858252769380692407983079026060150445462771991", "price": "0.003", "size": "120.97", "side": "BUY", "hash": "86aa924a599d2112c4dce2772fc768c10eaeb0db", "best_bid": "0.036", "best_ask": "0.04"}, {"asset_id": "15034789978615861173828275849657317503022772763977464100542193185148987457338", "price": "0.997", "size": "120.97", "side": "SELL", "hash": "999e5c4d171c86592a4deb976945836556ed84cc", "best_bid": "0.96", "best_ask": "0.964"}], "timestamp": "1769384554846", "event_type": "price_change"}}
{"_local_timestamp": "2026-01-25T23:42:36.747564+00:00", "data": {"market": "0x4d0d43382de6021ce0e906774caf6fc73fbe24078c9a75c6d7ae07b04299f8d0", "price_changes": [{"asset_id": "25543244747871931789882457929775858252769380692407983079026060150445462771991", "price": "0.003", "size": "113.04", "side": "BUY", "hash": "d9dc681cb405803e2cb3459e3b66825f9211c54a", "best_bid": "0.036", "best_ask": "0.04"}, {"asset_id": "15034789978615861173828275849657317503022772763977464100542193185148987457338", "price": "0.997", "size": "113.04", "side": "SELL", "hash": "05b757dad30eab21fa4ab4f63c4b5ae6f1504858", "best_bid": "0.96", "best_ask": "0.964"}], "timestamp": "1769384556614", "event_type": "price_change"}}
{"_local_timestamp": "2026-01-25T23:42:37.204487+00:00", "data": {"market": "0x4d0d43382de6021ce0e906774caf6fc73fbe24078c9a75c6d7ae07b04299f8d0", "price_changes": [{"asset_id": "25543244747871931789882457929775858252769380692407983079026060150445462771991", "price": "0.003", "size": "120.97", "side": "BUY", "hash": "3bd4019f6c4c0806a4d44fe27293e714cbe37655", "best_bid": "0.036", "best_ask": "0.04"}, {"asset_id": "15034789978615861173828275849657317503022772763977464100542193185148987457338", "price": "0.997", "size": "120.97", "side": "SELL", "hash": "a5c1850a5fb04e04b71cb3fbd3dc8ce5bf48742d", "best_bid": "0.96", "best_ask": "0.964"}], "timestamp": "1769384557039", "event_type": "price_change"}}
{"_local_timestamp": "2026-01-25T23:42:38.983318+00:00", "data": {"market": "0x4d0d43382de6021ce0e906774caf6fc73fbe24078c9a75c6d7ae07b04299f8d0", "price_changes": [{"asset_id": "25543244747871931789882457929775858252769380692407983079026060150445462771991", "price": "0.003", "size": "113.04", "side": "BUY", "hash": "79e3124d5f83dcc4244dc7851bd347113f163e51", "best_bid": "0.036", "best_ask": "0.04"}, {"asset_id": "15034789978615861173828275849657317503022772763977464100542193185148987457338", "price": "0.997", "size": "113.04", "side": "SELL", "hash": "ec5461a6791c4ec428badc39c5dd014ee3d8d4a5", "best_bid": "0.96", "best_ask": "0.964"}], "timestamp": "1769384558843", "event_type": "price_change"}}
{"_local_timestamp": "2026-01-25T23:42:39.458062+00:00", "data": {"market": "0x4d0d43382de6021ce0e906774caf6fc73fbe24078c9a75c6d7ae07b04299f8d0", "price_changes": [{"asset_id": "25543244747871931789882457929775858252769380692407983079026060150445462771991", "price": "0.003", "size": "120.97", "side": "BUY", "hash": "e02ccc11e97ef35b8f00e16fa6cbfa573c96f306", "best_bid": "0.036", "best_ask": "0.04"}, {"asset_id": "15034789978615861173828275849657317503022772763977464100542193185148987457338", "price": "0.997", "size": "120.97", "side": "SELL", "hash": "e0473611f35798ccd8a8ffc3eacb56c8f8fa12a9", "best_bid": "0.96", "best_ask": "0.964"}], "timestamp": "1769384559322", "event_type": "price_change"}}
{"_local_timestamp": "2026-01-25T23:42:40.433715+00:00", "data": {"market": "0x4d0d43382de6021ce0e906774caf6fc73fbe24078c9a75c6d7ae07b04299f8d0", "price_changes": [{"asset_id": "25543244747871931789882457929775858252769380692407983079026060150445462771991", "price": "0.003", "size": "113.04", "side": "BUY", "hash": "f0336ea34ec7197f7bdf0b2e36e167041aacb44c", "best_bid": "0.036", "best_ask": "0.04"}, {"asset_id": "15034789978615861173828275849657317503022772763977464100542193185148987457338", "price": "0.997", "size": "113.04", "side": "SELL", "hash": "29f98158dab1d10298a67a927e380b8eae24a410", "best_bid": "0.96", "best_ask": "0.964"}], "timestamp": "1769384560294", "event_type": "price_change"}}
{"_local_timestamp": "2026-01-25T23:42:40.811731+00:00", "data": {"market": "0x4d0d43382de6021ce0e906774caf6fc73fbe24078c9a75c6d7ae07b04299f8d0", "price_changes": [{"asset_id": "25543244747871931789882457929775858252769380692407983079026060150445462771991", "price": "0.003", "size": "120.97", "side": "BUY", "hash": "dfa78a4831644909f116cbdbf4998400f5d3ebbe", "best_bid": "0.036", "best_ask": "0.04"}, {"asset_id": "15034789978615861173828275849657317503022772763977464100542193185148987457338", "price": "0.997", "size": "120.97", "side": "SELL", "hash": "a70ec94eeb31c23d5791776ab2ecbecd01201a5f", "best_bid": "0.96", "best_ask": "0.964"}], "timestamp": "1769384560665", "event_type": "price_change"}}
{"_local_timestamp": "2026-01-25T23:42:42.113199+00:00", "data": {"market": "0x4d0d43382de6021ce0e906774caf6fc73fbe24078c9a75c6d7ae07b04299f8d0", "price_changes": [{"asset_id": "15034789978615861173828275849657317503022772763977464100542193185148987457338", "price": "0.316", "size": "0", "side": "BUY", "hash": "9875ca7dfd9a4f223103df4f968f2839038d64a9", "best_bid": "0.96", "best_ask": "0.964"}, {"asset_id": "25543244747871931789882457929775858252769380692407983079026060150445462771991", "price": "0.684", "size": "0", "side": "SELL", "hash": "68e8994a96e876b95d4feb31d7c3f757317a2d2b", "best_bid": "0.036", "best_ask": "0.04"}], "timestamp": "1769384561978", "event_type": "price_change"}}
{"_local_timestamp": "2026-01-25T23:42:42.115770+00:00", "data": {"market": "0x4d0d43382de6021ce0e906774caf6fc73fbe24078c9a75c6d7ae07b04299f8d0", "price_changes": [{"asset_id": "25543244747871931789882457929775858252769380692407983079026060150445462771991", "price": "0.003", "size": "113.04", "side": "BUY", "hash": "2f0d47a0add7f2a6d01cb51a7434f6d0cd8f16ea", "best_bid": "0.036", "best_ask": "0.04"}, {"asset_id": "15034789978615861173828275849657317503022772763977464100542193185148987457338", "price": "0.997", "size": "113.04", "side": "SELL", "hash": "ac0999a7de0f386c04568f06ae75ab22c4e89773", "best_bid": "0.96", "best_ask": "0.964"}], "timestamp": "1769384561979", "event_type": "price_change"}}
{"_local_timestamp": "2026-01-25T23:42:42.386836+00:00", "data": {"market": "0x4d0d43382de6021ce0e906774caf6fc73fbe24078c9a75c6d7ae07b04299f8d0", "price_changes": [{"asset_id": "15034789978615861173828275849657317503022772763977464100542193185148987457338", "price": "0.316", "size": "5", "side": "BUY", "hash": "8f426bfd88f503ba80a2925c0d312a0f86e337a2", "best_bid": "0.96", "best_ask": "0.964"}, {"asset_id": "25543244747871931789882457929775858252769380692407983079026060150445462771991", "price": "0.684", "size": "5", "side": "SELL", "hash": "7202cfc4dccf0a0b64c04bf6937a25b5daf7cc64", "best_bid": "0.036", "best_ask": "0.04"}], "timestamp": "1769384562253", "event_type": "price_change"}}
{"_local_timestamp": "2026-01-25T23:42:42.527122+00:00", "data": {"market": "0x4d0d43382de6021ce0e906774caf6fc73fbe24078c9a75c6d7ae07b04299f8d0", "price_changes": [{"asset_id": "25543244747871931789882457929775858252769380692407983079026060150445462771991", "price": "0.003", "size": "120.97", "side": "BUY", "hash": "e034c66066da0804084d359a0deccdc522b2cb82", "best_bid": "0.036", "best_ask": "0.04"}, {"asset_id": "15034789978615861173828275849657317503022772763977464100542193185148987457338", "price": "0.997", "size": "120.97", "side": "SELL", "hash": "41407f36d33f701f8d38579ee3888ce6d63c3fec", "best_bid": "0.96", "best_ask": "0.964"}], "timestamp": "1769384562385", "event_type": "price_change"}}
{"_local_timestamp": "2026-01-25T23:42:44.057739+00:00", "data": {"market": "0x4d0d43382de6021ce0e906774caf6fc73fbe24078c9a75c6d7ae07b04299f8d0", "price_changes": [{"asset_id": "25543244747871931789882457929775858252769380692407983079026060150445462771991", "price": "0.003", "size": "113.04", "side": "BUY", "hash": "9c540a950b699462da68192acb94f1047584d9bd", "best_bid": "0.036", "best_ask": "0.04"}, {"asset_id": "15034789978615861173828275849657317503022772763977464100542193185148987457338", "price": "0.997", "size": "113.04", "side": "SELL", "hash": "db1f0f65bdf57712b6f1250e069e0e7e5e0defc4", "best_bid": "0.96", "best_ask": "0.964"}], "timestamp": "1769384563924", "event_type": "price_change"}}
{"_local_timestamp": "2026-01-25T23:42:44.326791+00:00", "data": {"market": "0x4d0d43382de6021ce0e906774caf6fc73fbe24078c9a75c6d7ae07b04299f8d0", "price_changes": [{"asset_id": "25543244747871931789882457929775858252769380692407983079026060150445462771991", "price": "0.003", "size": "120.97", "side": "BUY", "hash": "53b1c7130041d201e0115011c42daebf26d8b304", "best_bid": "0.036", "best_ask": "0.04"}, {"asset_id": "15034789978615861173828275849657317503022772763977464100542193185148987457338", "price": "0.997", "size": "120.97", "side": "SELL", "hash": "176b129163c50cb535eef2863e644f68d71f3fd5", "best_bid": "0.96", "best_ask": "0.964"}], "timestamp": "1769384564191", "event_type": "price_change"}}
{"_local_timestamp": "2026-01-25T23:42:45.882123+00:00", "data": {"market": "0x4d0d43382de6021ce0e906774caf6fc73fbe24078c9a75c6d7ae07b04299f8d0", "price_changes": [{"asset_id": "25543244747871931789882457929775858252769380692407983079026060150445462771991", "price": "0.003", "size": "113.04", "side": "BUY", "hash": "a7aea16d2fc1db76c28fde26e04607e92526c28b", "best_bid": "0.036", "best_ask": "0.04"}, {"asset_id": "15034789978615861173828275849657317503022772763977464100542193185148987457338", "price": "0.997", "size": "113.04", "side": "SELL", "hash": "f1e0f16438aafebdff880e2af12612eea959137e", "best_bid": "0.96", "best_ask": "0.964"}], "timestamp": "1769384565759", "event_type": "price_change"}}
{"_local_timestamp": "2026-01-25T23:42:46.394158+00:00", "data": {"market": "0x4d0d43382de6021ce0e906774caf6fc73fbe24078c9a75c6d7ae07b04299f8d0", "price_changes": [{"asset_id": "25543244747871931789882457929775858252769380692407983079026060150445462771991", "price": "0.004", "size": "5.95", "side": "BUY", "hash": "b208e6a48599bafae451c9c613bb66b0fbe1023f", "best_bid": "0.036", "best_ask": "0.04"}, {"asset_id": "15034789978615861173828275849657317503022772763977464100542193185148987457338", "price": "0.996", "size": "5.95", "side": "SELL", "hash": "38f498a28c73864924a59c9bf8731a9b01ee9760", "best_bid": "0.96", "best_ask": "0.964"}], "timestamp": "1769384566277", "event_type": "price_change"}}
{"_local_timestamp": "2026-01-25T23:42:46.802068+00:00", "data": {"market": "0x4d0d43382de6021ce0e906774caf6fc73fbe24078c9a75c6d7ae07b04299f8d0", "price_changes": [{"asset_id": "25543244747871931789882457929775858252769380692407983079026060150445462771991", "price": "0.004", "size": "0", "side": "BUY", "hash": "77034315829bf892e929066ae34c47911afecc62", "best_bid": "0.036", "best_ask": "0.04"}, {"asset_id": "15034789978615861173828275849657317503022772763977464100542193185148987457338", "price": "0.996", "size": "0", "side": "SELL", "hash": "6df772b042ed8266393a7c452470cc9b7f25deb2", "best_bid": "0.96", "best_ask": "0.964"}], "timestamp": "1769384566676", "event_type": "price_change"}}
{"_local_timestamp": "2026-01-25T23:42:47.287299+00:00", "data": {"market": "0x4d0d43382de6021ce0e906774caf6fc73fbe24078c9a75c6d7ae07b04299f8d0", "price_changes": [{"asset_id": "25543244747871931789882457929775858252769380692407983079026060150445462771991", "price": "0.003", "size": "120.97", "side": "BUY", "hash": "e8983e50177c568b0407283baabd1cb80581ca84", "best_bid": "0.036", "best_ask": "0.04"}, {"asset_id": "15034789978615861173828275849657317503022772763977464100542193185148987457338", "price": "0.997", "size": "120.97", "side": "SELL", "hash": "50fad003357579335afae50ac1188c4a52db47c1", "best_bid": "0.96", "best_ask": "0.964"}], "timestamp": "1769384567033", "event_type": "price_change"}}
{"_local_timestamp": "2026-01-25T23:42:47.689428+00:00", "data": {"market": "0x4d0d43382de6021ce0e906774caf6fc73fbe24078c9a75c6d7ae07b04299f8d0", "price_changes": [{"asset_id": "25543244747871931789882457929775858252769380692407983079026060150445462771991", "price": "0.003", "size": "113.04", "side": "BUY", "hash": "ec5e95cac2292fb7104d9cc06c15071693c32d50", "best_bid": "0.036", "best_ask": "0.04"}, {"asset_id": "15034789978615861173828275849657317503022772763977464100542193185148987457338", "price": "0.997", "size": "113.04", "side": "SELL", "hash": "e15baaa525217a2ce21fe7cd1abc40f291e80a48", "best_bid": "0.96", "best_ask": "0.964"}], "timestamp": "1769384567570", "event_type": "price_change"}}
{"_local_timestamp": "2026-01-25T23:42:48.098882+00:00", "data": {"market": "0x4d0d43382de6021ce0e906774caf6fc73fbe24078c9a75c6d7ae07b04299f8d0", "price_changes": [{"asset_id": "25543244747871931789882457929775858252769380692407983079026060150445462771991", "price": "0.003", "size": "120.97", "side": "BUY", "hash": "4420a69a8363d156f06fc19bef90a2169ef04aa5", "best_bid": "0.036", "best_ask": "0.04"}, {"asset_id": "15034789978615861173828275849657317503022772763977464100542193185148987457338", "price": "0.997", "size": "120.97", "side": "SELL", "hash": "4c1b839e8eb913cd9585ef56a4f735d5341a33ae", "best_bid": "0.96", "best_ask": "0.964"}], "timestamp": "1769384567980", "event_type": "price_change"}}
{"_local_timestamp": "2026-01-25T23:42:49.551151+00:00", "data": {"market": "0x4d0d43382de6021ce0e906774caf6fc73fbe24078c9a75c6d7ae07b04299f8d0", "price_changes": [{"asset_id": "25543244747871931789882457929775858252769380692407983079026060150445462771991", "price": "0.003", "size": "113.04", "side": "BUY", "hash": "facd21b8fe89a0364d236e9321c03dd033102920", "best_bid": "0.036", "best_ask": "0.04"}, {"asset_id": "15034789978615861173828275849657317503022772763977464100542193185148987457338", "price": "0.997", "size": "113.04", "side": "SELL", "hash": "f653dc31248ea9f10c0105b63bfbfd5684f74a16", "best_bid": "0.96", "best_ask": "0.964"}], "timestamp": "1769384569424", "event_type": "price_change"}}
{"_local_timestamp": "2026-01-25T23:42:49.875827+00:00", "data": {"market": "0x4d0d43382de6021ce0e906774caf6fc73fbe24078c9a75c6d7ae07b04299f8d0", "price_changes": [{"asset_id": "25543244747871931789882457929775858252769380692407983079026060150445462771991", "price": "0.003", "size": "120.97", "side": "BUY", "hash": "9862220687bb2ded861a06c124f8a19bd9731302", "best_bid": "0.036", "best_ask": "0.04"}, {"asset_id": "15034789978615861173828275849657317503022772763977464100542193185148987457338", "price": "0.997", "size": "120.97", "side": "SELL", "hash": "8b4ad72ee52c845b945158625263b90b1ea4b933", "best_bid": "0.96", "best_ask": "0.964"}], "timestamp": "1769384569732", "event_type": "price_change"}}
{"_local_timestamp": "2026-01-25T23:42:51.309064+00:00", "data": {"market": "0x4d0d43382de6021ce0e906774caf6fc73fbe24078c9a75c6d7ae07b04299f8d0", "price_changes": [{"asset_id": "25543244747871931789882457929775858252769380692407983079026060150445462771991", "price": "0.003", "size": "113.04", "side": "BUY", "hash": "1305a735e7fbb9ccaae52e4b5037b032ac52905c", "best_bid": "0.036", "best_ask": "0.04"}, {"asset_id": "15034789978615861173828275849657317503022772763977464100542193185148987457338", "price": "0.997", "size": "113.04", "side": "SELL", "hash": "2dd4ba40038672e3026f459619e9ccf3a6d1edd3", "best_bid": "0.96", "best_ask": "0.964"}], "timestamp": "1769384571171", "event_type": "price_change"}}
{"_local_timestamp": "2026-01-25T23:42:51.613393+00:00", "data": {"market": "0x4d0d43382de6021ce0e906774caf6fc73fbe24078c9a75c6d7ae07b04299f8d0", "price_changes": [{"asset_id": "25543244747871931789882457929775858252769380692407983079026060150445462771991", "price": "0.003", "size": "120.97", "side": "BUY", "hash": "a3a88145154e28ad0c73cd526c4c6d6deebbf6f6", "best_bid": "0.036", "best_ask": "0.04"}, {"asset_id": "15034789978615861173828275849657317503022772763977464100542193185148987457338", "price": "0.997", "size": "120.97", "side": "SELL", "hash": "f98bd657815b21b519d2a3cb13d9b35754c482e7", "best_bid": "0.96", "best_ask": "0.964"}], "timestamp": "1769384571472", "event_type": "price_change"}}
{"_local_timestamp": "2026-01-25T23:42:53.034940+00:00", "data": {"market": "0x4d0d43382de6021ce0e906774caf6fc73fbe24078c9a75c6d7ae07b04299f8d0", "price_changes": [{"asset_id": "15034789978615861173828275849657317503022772763977464100542193185148987457338", "price": "0.316", "size": "0", "side": "BUY", "hash": "3bda758329eaab180b6cdfaacdd80f7e26fad5bd", "best_bid": "0.96", "best_ask": "0.964"}, {"asset_id": "25543244747871931789882457929775858252769380692407983079026060150445462771991", "price": "0.684", "size": "0", "side": "SELL", "hash": "b1e64c8ad382ce38e2b70f738244745b325c06ed", "best_bid": "0.036", "best_ask": "0.04"}], "timestamp": "1769384572893", "event_type": "price_change"}}
{"_local_timestamp": "2026-01-25T23:42:53.411298+00:00", "data": {"market": "0x4d0d43382de6021ce0e906774caf6fc73fbe24078c9a75c6d7ae07b04299f8d0", "price_changes": [{"asset_id": "15034789978615861173828275849657317503022772763977464100542193185148987457338", "price": "0.316", "size": "5", "side": "BUY", "hash": "546b378f9e5a01de3a1dccefde29c528ff5ca18e", "best_bid": "0.96", "best_ask": "0.964"}, {"asset_id": "25543244747871931789882457929775858252769380692407983079026060150445462771991", "price": "0.684", "size": "5", "side": "SELL", "hash": "3cb7a293204181270d88c2757de8630362ab7b83", "best_bid": "0.036", "best_ask": "0.04"}], "timestamp": "1769384573266", "event_type": "price_change"}}
{"_local_timestamp": "2026-01-25T23:42:53.465976+00:00", "data": {"market": "0x4d0d43382de6021ce0e906774caf6fc73fbe24078c9a75c6d7ae07b04299f8d0", "price_changes": [{"asset_id": "25543244747871931789882457929775858252769380692407983079026060150445462771991", "price": "0.003", "size": "113.04", "side": "BUY", "hash": "458ef7f09209d0238efa11888c489200f40d1677", "best_bid": "0.036", "best_ask": "0.04"}, {"asset_id": "15034789978615861173828275849657317503022772763977464100542193185148987457338", "price": "0.997", "size": "113.04", "side": "SELL", "hash": "71361a1e7de457ed33fdac9af19c8dd5cab6733f", "best_bid": "0.96", "best_ask": "0.964"}], "timestamp": "1769384573323", "event_type": "price_change"}}
{"_local_timestamp": "2026-01-25T23:42:53.873259+00:00", "data": {"market": "0x4d0d43382de6021ce0e906774caf6fc73fbe24078c9a75c6d7ae07b04299f8d0", "price_changes": [{"asset_id": "25543244747871931789882457929775858252769380692407983079026060150445462771991", "price": "0.003", "size": "120.97", "side": "BUY", "hash": "72ccd55831c8083087e3a4b6d48e4f5b2e850c13", "best_bid": "0.036", "best_ask": "0.04"}, {"asset_id": "15034789978615861173828275849657317503022772763977464100542193185148987457338", "price": "0.997", "size": "120.97", "side": "SELL", "hash": "567763cfdb9aa60ce97ecde053b2f31a7f6c16af", "best_bid": "0.96", "best_ask": "0.964"}], "timestamp": "1769384573725", "event_type": "price_change"}}
{"_local_timestamp": "2026-01-25T23:42:56.083765+00:00", "data": {"market": "0x4d0d43382de6021ce0e906774caf6fc73fbe24078c9a75c6d7ae07b04299f8d0", "price_changes": [{"asset_id": "25543244747871931789882457929775858252769380692407983079026060150445462771991", "price": "0.003", "size": "113.04", "side": "BUY", "hash": "b1b764d13330ecc012dc4bd5f1d1f64ca572b0c9", "best_bid": "0.036", "best_ask": "0.04"}, {"asset_id": "15034789978615861173828275849657317503022772763977464100542193185148987457338", "price": "0.997", "size": "113.04", "side": "SELL", "hash": "d4707ef095cfa36985c3d980e4a4331043314fa9", "best_bid": "0.96", "best_ask": "0.964"}], "timestamp": "1769384575946", "event_type": "price_change"}}
{"_local_timestamp": "2026-01-25T23:42:56.587616+00:00", "data": {"market": "0x4d0d43382de6021ce0e906774caf6fc73fbe24078c9a75c6d7ae07b04299f8d0", "price_changes": [{"asset_id": "25543244747871931789882457929775858252769380692407983079026060150445462771991", "price": "0.003", "size": "120.97", "side": "BUY", "hash": "7f2e0d93ae944eebf7514bfc14198cec84d5aa35", "best_bid": "0.036", "best_ask": "0.04"}, {"asset_id": "15034789978615861173828275849657317503022772763977464100542193185148987457338", "price": "0.997", "size": "120.97", "side": "SELL", "hash": "3c98519ab5dad33f7ea79325b654000fcb3cd6c4", "best_bid": "0.96", "best_ask": "0.964"}], "timestamp": "1769384576449", "event_type": "price_change"}}
{"_local_timestamp": "2026-01-25T23:42:57.418695+00:00", "data": {"market": "0x4d0d43382de6021ce0e906774caf6fc73fbe24078c9a75c6d7ae07b04299f8d0", "price_changes": [{"asset_id": "25543244747871931789882457929775858252769380692407983079026060150445462771991", "price": "0.003", "size": "113.04", "side": "BUY", "hash": "816830823514090bcddcd7932cdf358f91066838", "best_bid": "0.036", "best_ask": "0.04"}, {"asset_id": "15034789978615861173828275849657317503022772763977464100542193185148987457338", "price": "0.997", "size": "113.04", "side": "SELL", "hash": "6ba7d29803371ff9dfb02f95a0b2cdc73f93b910", "best_bid": "0.96", "best_ask": "0.964"}], "timestamp": "1769384577276", "event_type": "price_change"}}
{"_local_timestamp": "2026-01-25T23:42:57.630157+00:00", "data": {"market": "0x4d0d43382de6021ce0e906774caf6fc73fbe24078c9a75c6d7ae07b04299f8d0", "price_changes": [{"asset_id": "25543244747871931789882457929775858252769380692407983079026060150445462771991", "price": "0.003", "size": "120.97", "side": "BUY", "hash": "976304ab3b0c2564ee1fc3fee24f0251528cfb11", "best_bid": "0.036", "best_ask": "0.04"}, {"asset_id": "15034789978615861173828275849657317503022772763977464100542193185148987457338", "price": "0.997", "size": "120.97", "side": "SELL", "hash": "cf0e07b473cf6b3205048ace141c9f4f497758d8", "best_bid": "0.96", "best_ask": "0.964"}], "timestamp": "1769384577492", "event_type": "price_change"}}
{"_local_timestamp": "2026-01-25T23:42:58.691313+00:00", "data": {"market": "0x4d0d43382de6021ce0e906774caf6fc73fbe24078c9a75c6d7ae07b04299f8d0", "price_changes": [{"asset_id": "25543244747871931789882457929775858252769380692407983079026060150445462771991", "price": "0.003", "size": "113.04", "side": "BUY", "hash": "c330ae332640c2807e3bfad964fe5943034f31f1", "best_bid": "0.036", "best_ask": "0.04"}, {"asset_id": "15034789978615861173828275849657317503022772763977464100542193185148987457338", "price": "0.997", "size": "113.04", "side": "SELL", "hash": "b040c5e69966d454c9fd18fec3b1f83c9665abb8", "best_bid": "0.96", "best_ask": "0.964"}], "timestamp": "1769384578569", "event_type": "price_change"}}
{"_local_timestamp": "2026-01-25T23:42:58.952176+00:00", "data": {"market": "0x4d0d43382de6021ce0e906774caf6fc73fbe24078c9a75c6d7ae07b04299f8d0", "price_changes": [{"asset_id": "25543244747871931789882457929775858252769380692407983079026060150445462771991", "price": "0.003", "size": "120.97", "side": "BUY", "hash": "c923e8e0b523f15b4f8e9970ee0903ab49ff3134", "best_bid": "0.036", "best_ask": "0.04"}, {"asset_id": "15034789978615861173828275849657317503022772763977464100542193185148987457338", "price": "0.997", "size": "120.97", "side": "SELL", "hash": "290918cead49ce3a204ed26896c87e4feb15fe02", "best_bid": "0.96", "best_ask": "0.964"}], "timestamp": "1769384578830", "event_type": "price_change"}}
