{"_local_timestamp": "2026-01-25T23:40:30.617358+00:00", "data": [{"market": "0xa740b563bbfe6747b5b583a6a015da34a91ec2d4b78812499adb27b5339567d7", "asset_id": "61686688389034832478617244975844051688063193720856283239929854404269927455550", "timestamp": "1769384283898", "hash": "924aef4b68f791ad7f752b929a4ef2a96c0b08f4", "bids": [{"price": "0.01", "size": "215.53"}, {"price": "0.02", "size": "5017.13"}, {"price": "0.05", "size": "30"}, {"price": "0.06", "size": "33"}, {"price": "0.07", "size": "100"}, {"price": "0.09", "size": "100"}, {"price": "0.1", "size": "230.04"}, {"price": "0.26", "size": "34.93"}, {"price": "0.27", "size": "15"}], "asks": [{"price": "0.99", "size": "62.98"}, {"price": "0.98", "size": "5"}, {"price": "0.97", "size": "250"}, {"price": "0.96", "size": "34.25"}], "event_type": "book", "last_trade_price": ""}, {"market": "0x1ac116ca6128b12ba9dee16cbb862a97c997f618ca465ec3ad9804505029dacd", "asset_id": "57315507480117481325027835038256219537881608729626837750964718238872905592326", "timestamp": "1769384280930", "hash": "d92bd842f9b7e5cebe423013b506f6d8e4d96619", "bids": [{"price": "0.01", "size": "99.87"}, {"price": "0.02", "size": "5.06"}, {"price": "0.06", "size": "250"}, {"price": "0.07", "size": "1428.57"}, {"price": "0.08", "size": "300"}], "asks": [{"price": "0.99", "size": "39.79"}, {"price": "0.98", "size": "13.55"}, {"price": "0.96", "size": "200"}, {"price": "0.95", "size": "2030"}, {"price": "0.94", "size": "75.6"}, {"price": "0.91", "size": "150"}, {"price": "0.9", "size": "6.02"}, {"price": "0.6", "size": "10"}, {"price": "0.5", "size": "60"}, {"price": "0.49", "size": "37.08"}], "event_type": "book", "last_trade_price": ""}, {"market": "0x635cb63797844830d6b4f6179bd5d3bf85df6e902d55ca3551da363a197a6015", "asset_id": "104455382443807393617499593132074029890019204372384161184533887382424965972532", "timestamp": "1769384284469", "hash": "7596f1c7a31b07a588b12e7227368e228ac536f2", "bids": [{"price": "0.01", "size": "44.85"}, {"price": "0.02", "size": "33.16"}, {"price": "0.03", "size": "17.6"}, {"price": "0.06", "size": "6"}, {"price": "0.07", "size": "14.2"}, {"price": "0.08", "size": "6.25"}], "asks": [{"price": "0.99", "size": "27.15"}, {"price": "0.98", "size": "205.42"}, {"price": "0.96", "size": "306.16"}, {"price": "0.95", "size": "2030"}, {"price": "0.94", "size": "31.98"}, {"price": "0.93", "size": "6.76"}, {"price": "0.88", "size": "8.33"}, {"price": "0.87", "size": "5"}], "event_type": "book", "last_trade_price": "0.130"}, {"market": "0xa740b563bbfe6747b5b583a6a015da34a91ec2d4b78812499adb27b5339567d7", "asset_id": "53423629899248148188739723007991406387336891109351059215899025565130176303731", "timestamp": "1769384283898", "hash": "cdb9163d03217204efb17b461b927ce06ce930ce", "bids": [{"price": "0.01", "size": "62.98"}, {"price": "0.02", "size": "5"}, {"price": "0.03", "size": "250"}, {"price": "0.04", "size": "34.25"}], "asks": [{"price": "0.99", "size": "215.53"}, {"price": "0.98", "size": "5017.13"}, {"price": "0.95", "size": "30"}, {"price": "0.94", "size": "33"}, {"price": "0.93", "size": "100"}, {"price": "0.91", "size": "100"}, {"price": "0.9", "size": "230.04"}, {"price": "0.74", "size": "34.93"}, {"price": "0.73", "size": "15"}], "event_type": "book", "last_trade_price": ""}, {"market": "0xa0224dd1786eab161adafee1168cb48cc9ecbf80e938b74d7ae2ab1d097485a7", "asset_id": "44193613907943747725755027726993424777152282107456500311583464431449158738087", "timestamp": "1769384424971", "hash": "9bf480ee2ff479d2a986a4e03a99610baf0f5534", "bids": [{"price": "0.01", "size": "20.29"}, {"price": "0.02", "size": "100"}, {"price": "0.03", "size": "10.76"}, {"price": "0.05", "size": "30"}, {"price": "0.06", "size": "200"}, {"price": "0.07", "size": "1428.57"}, {"price": "0.1", "size": "175"}, {"price": "0.11", "size": "5.22"}, {"price": "0.21", "size": "25"}, {"price": "0.22", "size": "9"}, {"price": "0.53", "size": "45"}], "asks": [{"price": "0.99", "size": "10815.48"}, {"price": "0.98", "size": "705.36"}, {"price": "0.96", "size": "20.94"}, {"price": "0.89", "size": "387"}, {"price": "0.79", "size": "20"}, {"price": "0.78", "size": "780"}, {"price": "0.77", "size": "25"}], "event_type": "book", "last_trade_price": ""}, {"market": "0xca595a16069e6cd9bce150ecd5cec487b848d9040412547c88e87553af24f620", "asset_id": "7800079113080185862147430423231593667955784347592918745149791674372792278395", "timestamp": "1769384417140", "hash": "7aad14e0c7109bb5c3ad036ec893071255d41084", "bids": [{"price": "0.001", "size": "821.59"}, {"price": "0.002", "size": "478.51"}, {"price": "0.003", "size": "100.69"}, {"price": "0.004", "size": "37"}, {"price": "0.005", "size": "30.17"}, {"price": "0.01", "size": "10"}, {"price": "0.011", "size": "34.26"}], "asks": [{"price": "0.999", "size": "2746.47"}, {"price": "0.998", "size": "250"}, {"price": "0.997", "size": "406.9"}, {"price": "0.996", "size": "200"}, {"price": "0.994", "size": "200"}, {"price": "0.993", "size": "15.69"}, {"price": "0.99", "size": "10"}, {"price": "0.989", "size": "9.09"}, {"price": "0.95", "size": "30"}, {"price": "0.949", "size": "39"}, {"price": "0.948", "size": "19"}, {"price": "0.944", "size": "35"}, {"price": "0.943", "size": "13.31"}, {"price": "0.942", "size": "45"}, {"price": "0.4", "size": "25"}, {"price": "0.39", "size": "25"}, {"price": "0.383", "size": "28.63"}], "event_type": "book", "last_trade_price": ""}, {"market": "0x1f27bc2e8ba7d49c159a30d8b5acbf262e37b7bfce49faaa83d97e1230ff85b2", "asset_id": "68693861857134386582315370929389041267603330466263232248785831669012466999405", "timestamp": "1769384078616", "hash": "9aedd07fc93b3d23d26ede240c9919e791770bee", "bids": [{"price": "0.01", "size": "30.09"}, {"price": "0.02", "size": "27"}, {"price": "0.03", "size": "8.82"}, {"price": "0.05", "size": "36"}, {"price": "0.06", "size": "8.9"}, {"price": "0.12", "size": "25"}], "asks": [{"price": "0.99", "size": "47.4"}, {"price": "0.9", "size": "50"}, {"price": "0.89", "size": "5.69"}, {"price": "0.7", "size": "10"}, {"price": "0.6", "size": "10"}, {"price": "0.5", "size": "5"}], "event_type": "book", "last_trade_price": ""}, {"market": "0x027559a14e432690257e412f18d237574155f4aebeee941382423d01c65ba37c", "asset_id": "75546450841602375940945638943612150673916039892841739175120880870878769936289", "timestamp": "1769384417414", "hash": "389456156b82cc2da9b4652640b90496bf775afa", "bids": [{"price": "0.001", "size": "1305.81"}, {"price": "0.002", "size": "484.42"}, {"price": "0.003", "size": "44.45"}, {"price": "0.004", "size": "131"}, {"price": "0.005", "size": "70.46"}, {"price": "0.007", "size": "17.73"}, {"price": "0.01", "size": "10"}, {"price": "0.011", "size": "6.67"}], "asks": [{"price": "0.999", "size": "2810.6"}, {"price": "0.998", "size": "250"}, {"price": "0.997", "size": "172.96"}, {"price": "0.994", "size": "83"}, {"price": "0.993", "size": "17.04"}, {"price": "0.99", "size": "10"}, {"price": "0.989", "size": "9.09"}, {"price": "0.967", "size": "200"}, {"price": "0.966", "size": "11764.7"}, {"price": "0.95", "size": "30"}, {"price": "0.949", "size": "39"}, {"price": "0.947", "size": "7"}, {"price": "0.946", "size": "45"}, {"price": "0.939", "size": "44.28"}, {"price": "0.11", "size": "22.22"}, {"price": "0.109", "size": "5.78"}], "event_type": "book", "last_trade_price": ""}, {"market": "0xe39845e9efee80761e2e9e89d579f8b943a29233153f3ed148f8d84637bea6b7", "asset_id": "12787908846201818836113906836317537483609531613584477341982605123655773837316", "timestamp": "1769384283151", "hash": "8c6f89b7c46c344efdd85ea8d56ade32af3d4e22", "bids": [{"price": "0.01", "size": "29.92"}, {"price": "0.02", "size": "25"}, {"price": "0.03", "size": "8.79"}, {"price": "0.05", "size": "20"}, {"price": "0.06", "size": "8.94"}, {"price": "0.1", "size": "64"}, {"price": "0.11", "size": "175"}, {"price": "0.12", "size": "50.83"}], "asks": [{"price": "0.99", "size": "25.31"}, {"price": "0.98", "size": "5.02"}, {"price": "0.97", "size": "16"}, {"price": "0.96", "size": "205.44"}, {"price": "0.95", "size": "2020"}, {"price": "0.94", "size": "33"}, {"price": "0.93", "size": "7.55"}, {"price": "0.9", "size": "231.17"}, {"price": "0.86", "size": "60"}, {"price": "0.85", "size": "30.48"}], "event_type": "book", "last_trade_price": "0.120"}, {"market": "0x8c51633514afb3a854cb9f5248327ed2d6830d40b68cf23a62866a6e0cd286a0", "asset_id": "71178880545288091437751776636766820229347337814001501090420774267960283440681", "timestamp": "1769384424951", "hash": "3973223e87bf4fdf519e015fd0868cda73254fa1", "bids": [{"price": "0.01", "size": "20.49"}, {"price": "0.02", "size": "700"}, {"price": "0.03", "size": "8.58"}, {"price": "0.06", "size": "2166.66"}, {"price": "0.09", "size": "400"}, {"price": "0.1", "size": "106.37"}, {"price": "0.12", "size": "50"}, {"price": "0.33", "size": "5"}, {"price": "0.4", "size": "20"}, {"price": "0.5", "size": "304.58"}], "asks": [{"price": "0.99", "size": "29.28"}, {"price": "0.98", "size": "205"}, {"price": "0.97", "size": "3333.33"}, {"price": "0.96", "size": "17.67"}, {"price": "0.92", "size": "250"}, {"price": "0.91", "size": "5.45"}, {"price": "0.88", "size": "25"}], "event_type": "book", "last_trade_price": ""}, {"market": "0xe39845e9efee80761e2e9e89d579f8b943a29233153f3ed148f8d84637bea6b7", "asset_id": "6336829643612419106262092052749783689174278821109708845497505799770380553013", "timestamp": "1769384283151", "hash": "d127e39bb729e814668eaaa7d95f2c6076cb1d7e", "bids": [{"price": "0.01", "size": "25.31"}, {"price": "0.02", "size": "5.02"}, {"price": "0.03", "size": "16"}, {"price": "0.04", "size": "205.44"}, {"price": "0.05", "size": "2020"}, {"price": "0.06", "size": "33"}, {"price": "0.07", "size": "7.55"}, {"price": "0.1", "size": "231.17"}, {"price": "0.14", "size": "60"}, {"price": "0.15", "size": "30.48"}], "asks": [{"price": "0.99", "size": "29.92"}, {"price": "0.98", "size": "25"}, {"price": "0.97", "size": "8.79"}, {"price": "0.95", "size": "20"}, {"price": "0.94", "size": "8.94"}, {"price": "0.9", "size": "64"}, {"price": "0.89", "size": "175"}, {"price": "0.88", "size": "50.83"}], "event_type": "book", "last_trade_price": "0.120"}, {"market": "0xa0224dd1786eab161adafee1168cb48cc9ecbf80e938b74d7ae2ab1d097485a7", "asset_id": "22398187790187305120863916278812508331357975196340479087426628481830278112943", "timestamp": "1769384424971", "hash": "2ae6aa6708405ec8cb2366e1595bdd63f4532d71", "bids": [{"price": "0.01", "size": "10815.48"}, {"price": "0.02", "size": "705.36"}, {"price": "0.04", "size": "20.94"}, {"price": "0.11", "size": "387"}, {"price": "0.21", "size": "20"}, {"price": "0.22", "size": "780"}, {"price": "0.23", "size": "25"}], "asks": [{"price": "0.99", "size": "20.29"}, {"price": "0.98", "size": "100"}, {"price": "0.97", "size": "10.76"}, {"price": "0.95", "size": "30"}, {"price": "0.94", "size": "200"}, {"price": "0.93", "size": "1428.57"}, {"price": "0.9", "size": "175"}, {"price": "0.89", "size": "5.22"}, {"price": "0.79", "size": "25"}, {"price": "0.78", "size": "9"}, {"price": "0.47", "size": "45"}], "event_type": "book", "last_trade_price": ""}, {"market": "0x8c51633514afb3a854cb9f5248327ed2d6830d40b68cf23a62866a6e0cd286a0", "asset_id": "7684238634255493981133898590426067650024910633947701282528239993143961130595", "timestamp": "1769384424951", "hash": "05f682b4af4a89d018c189902a293871a3779b7a", "bids": [{"price": "0.01", "size": "29.28"}, {"price": "0.02", "size": "205"}, {"price": "0.03", "size": "3333.33"}, {"price": "0.04", "size": "17.67"}, {"price": "0.08", "size": "250"}, {"price": "0.09", "size": "5.45"}, {"price": "0.12", "size": "25"}], "asks": [{"price": "0.99", "size": "20.49"}, {"price": "0.98", "size": "700"}, {"price": "0.97", "size": "8.58"}, {"price": "0.94", "size": "2166.66"}, {"price": "0.91", "size": "400"}, {"price": "0.9", "size": "106.37"}, {"price": "0.88", "size": "50"}, {"price": "0.67", "size": "5"}, {"price": "0.6", "size": "20"}, {"price": "0.5", "size": "304.58"}], "event_type": "book", "last_trade_price": ""}, {"market": "0x03c42aea715bf13ec60b6dc0dc0a401ad83fb853de3b320d91101b9a636c6026", "asset_id": "67310272555621311553232013859863871375723980292304081825420100284982881301079", "timestamp": "1769384284864", "hash": "f0746ab7cdeee6d98f798f6df5f8e6b9d5646de1", "bids": [{"price": "0.01", "size": "22.55"}, {"price": "0.02", "size": "5.94"}, {"price": "0.03", "size": "16"}, {"price": "0.04", "size": "5.91"}, {"price": "0.05", "size": "20"}, {"price": "0.06", "size": "233"}, {"price": "0.07", "size": "5714.28"}, {"price": "0.08", "size": "14"}, {"price": "0.09", "size": "11.72"}, {"price": "0.21", "size": "13.32"}], "asks": [{"price": "0.99", "size": "22.48"}, {"price": "0.98", "size": "30"}, {"price": "0.97", "size": "47.58"}], "event_type": "book", "last_trade_price": "0.040"}, {"market": "0x027559a14e432690257e412f18d237574155f4aebeee941382423d01c65ba37c", "asset_id": "29656649254811448219539439958370239248598869163495679625271035829447755371901", "timestamp": "1769384417414", "hash": "8f767ce69ad2f1e4367bc71810ae51cc88d96bd5", "bids": [{"price": "0.001", "size": "2810.6"}, {"price": "0.002", "size": "250"}, {"price": "0.003", "size": "172.96"}, {"price": "0.006", "size": "83"}, {"price": "0.007", "size": "17.04"}, {"price": "0.01", "size": "10"}, {"price": "0.011", "size": "9.09"}, {"price": "0.033", "size": "200"}, {"price": "0.034", "size": "11764.7"}, {"price": "0.05", "size": "30"}, {"price": "0.051", "size": "39"}, {"price": "0.053", "size": "7"}, {"price": "0.054", "size": "45"}, {"price": "0.061", "size": "44.28"}, {"price": "0.89", "size": "22.22"}, {"price": "0.891", "size": "5.78"}], "asks": [{"price": "0.999", "size": "1305.81"}, {"price": "0.998", "size": "484.42"}, {"price": "0.997", "size": "44.45"}, {"price": "0.996", "size": "131"}, {"price": "0.995", "size": "70.46"}, {"price": "0.993", "size": "17.73"}, {"price": "0.99", "size": "10"}, {"price": "0.989", "size": "6.67"}], "event_type": "book", "last_trade_price": ""}, {"market": "0x03c42aea715bf13ec60b6dc0dc0a401ad83fb853de3b320d91101b9a636c6026", "asset_id": "25639330389011308493516542271565374194456752331098963441806069638079251368536", "timestamp": "1769384284864", "hash": "81f0a94f75c65204cf0516e563fb3db2707ca3cc", "bids": [{"price": "0.01", "size": "22.48"}, {"price": "0.02", "size": "30"}, {"price": "0.03", "size": "47.58"}], "asks": [{"price": "0.99", "size": "22.55"}, {"price": "0.98", "size": "5.94"}, {"price": "0.97", "size": "16"}, {"price": "0.96", "size": "5.91"}, {"price": "0.95", "size": "20"}, {"price": "0.94", "size": "233"}, {"price": "0.93", "size": "5714.28"}, {"price": "0.92", "size": "14"}, {"price": "0.91", "size": "11.72"}, {"price": "0.79", "size": "13.32"}], "event_type": "book", "last_trade_price": "0.040"}, {"market": "0x1f27bc2e8ba7d49c159a30d8b5acbf262e37b7bfce49faaa83d97e1230ff85b2", "asset_id": "28745788861076672720947634851890673159658681509256104153267819539064558306351", "timestamp": "1769384078616", "hash": "7d41d8ed482a1429f7e1b8c3678cee6e785aadc8", "bids": [{"price": "0.01", "size": "47.4"}, {"price": "0.1", "size": "50"}, {"price": "0.11", "size": "5.69"}, {"price": "0.3", "size": "10"}, {"price": "0.4", "size": "10"}, {"price": "0.5", "size": "5"}], "asks": [{"price": "0.99", "size": "30.09"}, {"price": "0.98", "size": "27"}, {"price": "0.97", "size": "8.82"}, {"price": "0.95", "size": "36"}, {"price": "0.94", "size": "8.9"}, {"price": "0.88", "size": "25"}], "event_type": "book", "last_trade_price": ""}, {"market": "0x635cb63797844830d6b4f6179bd5d3bf85df6e902d55ca3551da363a197a6015", "asset_id": "77910824591036329057262898804355407930105085028914256794097954045220366551556", "timestamp": "1769384284469", "hash": "ee0b538298baf59ce62eb576a4a08deec346f949", "bids": [{"price": "0.01", "size": "27.15"}, {"price": "0.02", "size": "205.42"}, {"price": "0.04", "size": "306.16"}, {"price": "0.05", "size": "2030"}, {"price": "0.06", "size": "31.98"}, {"price": "0.07", "size": "6.76"}, {"price": "0.12", "size": "8.33"}, {"price": "0.13", "size": "5"}], "asks": [{"price": "0.99", "size": "44.85"}, {"price": "0.98", "size": "33.16"}, {"price": "0.97", "size": "17.6"}, {"price": "0.94", "size": "6"}, {"price": "0.93", "size": "14.2"}, {"price": "0.92", "size": "6.25"}], "event_type": "book", "last_trade_price": "0.130"}, {"market": "0x1ac116ca6128b12ba9dee16cbb862a97c997f618ca465ec3ad9804505029dacd", "asset_id": "3288340895010205036170048275599967721898253126704096745341178630581136187620", "timestamp": "1769384280930", "hash": "338ce01cbdc0f99c2d3fee20722aa84576e2d78f", "bids": [{"price": "0.01", "size": "39.79"}, {"price": "0.02", "size": "13.55"}, {"price": "0.04", "size": "200"}, {"price": "0.05", "size": "2030"}, {"price": "0.06", "size": "75.6"}, {"price": "0.09", "size": "150"}, {"price": "0.1", "size": "6.02"}, {"price": "0.4", "size": "10"}, {"price": "0.5", "size": "60"}, {"price": "0.51", "size": "37.08"}], "asks": [{"price": "0.99", "size": "99.87"}, {"price": "0.98", "size": "5.06"}, {"price": "0.94", "size": "250"}, {"price": "0.93", "size": "1428.57"}, {"price": "0.92", "size": "300"}], "event_type": "book", "last_trade_price": ""}, {"market": "0xca595a16069e6cd9bce150ecd5cec487b848d9040412547c88e87553af24f620", "asset_id": "9819058864821277493601798917843605870759192694393888839422379886017252447851", "timestamp": "1769384417140", "hash": "0cae0da4cecfe070a2a3bb2f7eac35dea9820e01", "bids": [{"price": "0.001", "size": "2746.47"}, {"price": "0.002", "size": "250"}, {"price": "0.003", "size": "406.9"}, {"price": "0.004", "size": "200"}, {"price": "0.006", "size": "200"}, {"price": "0.007", "size": "15.69"}, {"price": "0.01", "size": "10"}, {"price": "0.011", "size": "9.09"}, {"price": "0.05", "size": "30"}, {"price": "0.051", "size": "39"}, {"price": "0.052", "size": "19"}, {"price": "0.056", "size": "35"}, {"price": "0.057", "size": "13.31"}, {"price": "0.058", "size": "45"}, {"price": "0.6", "size": "25"}, {"price": "0.61", "size": "25"}, {"price": "0.617", "size": "28.63"}], "asks": [{"price": "0.999", "size": "821.59"}, {"price": "0.998", "size": "478.51"}, {"price": "0.997", "size": "100.69"}, {"price": "0.996", "size": "37"}, {"price": "0.995", "size": "30.17"}, {"price": "0.99", "size": "10"}, {"price": "0.989", "size": "34.26"}], "event_type": "book", "last_trade_price": ""}]}
{"_local_timestamp": "2026-01-25T23:40:37.797165+00:00", "data": {"market": "0x1f27bc2e8ba7d49c159a30d8b5acbf262e37b7bfce49faaa83d97e1230ff85b2", "price_changes": [{"asset_id": "28745788861076672720947634851890673159658681509256104153267819539064558306351", "price": "0.01", "size": "24.18", "side": "BUY", "hash": "ae5aefab002d3d7d4044efbfaf20d1843266fab5", "best_bid": "0.5", "best_ask": "0.88"}, {"asset_id": "68693861857134386582315370929389041267603330466263232248785831669012466999405", "price": "0.99", "size": "24.18", "side": "SELL", "hash": "3ae6c7db698e816af2b995c842539235f791fc5f", "best_bid": "0.12", "best_ask": "0.5"}], "timestamp": "1769384437731", "event_type": "price_change"}}
{"_local_timestamp": "2026-01-25T23:40:39.875048+00:00", "data": {"market": "0x1f27bc2e8ba7d49c159a30d8b5acbf262e37b7bfce49faaa83d97e1230ff85b2", "price_changes": [{"asset_id": "28745788861076672720947634851890673159658681509256104153267819539064558306351", "price": "0.01", "size": "47.4", "side": "BUY", "hash": "737072aa67ecd92c5496732dd37bbaf866f3b796", "best_bid": "0.5", "best_ask": "0.88"}, {"asset_id": "68693861857134386582315370929389041267603330466263232248785831669012466999405", "price": "0.99", "size": "47.4", "side": "SELL", "hash": "1d22838ed86a40806ac1756993ad9555d6407b07", "best_bid": "0.12", "best_ask": "0.5"}], "timestamp": "1769384439795", "event_type": "price_change"}}
{"_local_timestamp": "2026-01-25T23:40:42.979124+00:00", "data": {"market": "0x635cb63797844830d6b4f6179bd5d3bf85df6e902d55ca3551da363a197a6015", "price_changes": [{"asset_id": "77910824591036329057262898804355407930105085028914256794097954045220366551556", "price": "0.02", "size": "200", "side": "BUY", "hash": "fdfb7f3d9abbc1060a9958dbe7f0cb0943dc5edd", "best_bid": "0.13", "best_ask": "0.92"}, {"asset_id": "104455382443807393617499593132074029890019204372384161184533887382424965972532", "price": "0.98", "size": "200", "side": "SELL", "hash": "d1bf37209207bb65c529265b7abe13368a2a30c5", "best_bid": "0.08", "best_ask": "0.87"}], "timestamp": "1769384442888", "event_type": "price_change"}}
{"_local_timestamp": "2026-01-25T23:40:42.980897+00:00", "data": {"market": "0x635cb63797844830d6b4f6179bd5d3bf85df6e902d55ca3551da363a197a6015", "price_changes": [{"asset_id": "77910824591036329057262898804355407930105085028914256794097954045220366551556", "price": "0.04", "size": "300", "side": "BUY", "hash": "fdfb7f3d9abbc1060a9958dbe7f0cb0943dc5edd", "best_bid": "0.13", "best_ask": "0.92"}, {"asset_id": "104455382443807393617499593132074029890019204372384161184533887382424965972532", "price": "0.96", "size": "300", "side": "SELL", "hash": "d1bf37209207bb65c529265b7abe13368a2a30c5", "best_bid": "0.08", "best_ask": "0.87"}], "timestamp": "1769384442888", "event_type": "price_change"}}
{"_local_timestamp": "2026-01-25T23:40:44.795378+00:00", "data": {"market": "0x635cb63797844830d6b4f6179bd5d3bf85df6e902d55ca3551da363a197a6015", "price_changes": [{"asset_id": "77910824591036329057262898804355407930105085028914256794097954045220366551556", "price": "0.03", "size": "11.84", "side": "BUY", "hash": "91849bfa16562ddc4fd6d570b6f4a3bd0535b391", "best_bid": "0.13", "best_ask": "0.92"}, {"asset_id": "104455382443807393617499593132074029890019204372384161184533887382424965972532", "price": "0.97", "size": "11.84", "side": "SELL", "hash": "c313adf39b4e78c30d66f524bcac16ff3a40c7d7", "best_bid": "0.08", "best_ask": "0.87"}], "timestamp": "1769384444721", "event_type": "price_change"}}
{"_local_timestamp": "2026-01-25T23:40:54.237225+00:00", "data": {"market": "0x8c51633514afb3a854cb9f5248327ed2d6830d40b68cf23a62866a6e0cd286a0", "price_changes": [{"asset_id": "71178880545288091437751776636766820229347337814001501090420774267960283440681", "price": "0.1", "size": "100", "side": "BUY", "hash": "056a77330b5361805958301a95f03f2749d520ab", "best_bid": "0.5", "best_ask": "0.88"}, {"asset_id": "7684238634255493981133898590426067650024910633947701282528239993143961130595", "price": "0.9", "size": "100", "side": "SELL", "hash": "c65fdec313d55a2019f438acd4f75f6b3f440b07", "best_bid": "0.12", "best_ask": "0.5"}], "timestamp": "1769384454170", "event_type": "price_change"}}
{"_local_timestamp": "2026-01-25T23:40:54.242205+00:00", "data": {"market": "0xa740b563bbfe6747b5b583a6a015da34a91ec2d4b78812499adb27b5339567d7", "price_changes": [{"asset_id": "61686688389034832478617244975844051688063193720856283239929854404269927455550", "price": "0.02", "size": "5000", "side": "BUY", "hash": "353c56317892545417cc673b519ad329c7b07740", "best_bid": "0.27", "best_ask": "0.96"}, {"asset_id": "53423629899248148188739723007991406387336891109351059215899025565130176303731", "price": "0.98", "size": "5000", "side": "SELL", "hash": "6a08e10f7af76381e00fc3fa71b3aa233bc32904", "best_bid": "0.04", "best_ask": "0.73"}], "timestamp": "1769384454170", "event_type": "price_change"}}
{"_local_timestamp": "2026-01-25T23:40:54.243574+00:00", "data": {"market": "0xa740b563bbfe6747b5b583a6a015da34a91ec2d4b78812499adb27b5339567d7", "price_changes": [{"asset_id": "61686688389034832478617244975844051688063193720856283239929854404269927455550", "price": "0.1", "size": "224.02", "side": "BUY", "hash": "353c56317892545417cc673b519ad329c7b07740", "best_bid": "0.27", "best_ask": "0.96"}, {"asset_id": "53423629899248148188739723007991406387336891109351059215899025565130176303731", "price": "0.9", "size": "224.02", "side": "SELL", "hash": "6a08e10f7af76381e00fc3fa71b3aa233bc32904", "best_bid": "0.04", "best_ask": "0.73"}], "timestamp": "1769384454170", "event_type": "price_change"}}
{"_local_timestamp": "2026-01-25T23:40:58.326798+00:00", "data": {"market": "0xa740b563bbfe6747b5b583a6a015da34a91ec2d4b78812499adb27b5339567d7", "price_changes": [{"asset_id": "61686688389034832478617244975844051688063193720856283239929854404269927455550", "price": "0.1", "size": "229.27", "side": "BUY", "hash": "82e816660c76abf525935a9b8770ad731d2e7f68", "best_bid": "0.27", "best_ask": "0.96"}, {"asset_id": "53423629899248148188739723007991406387336891109351059215899025565130176303731", "price": "0.9", "size": "229.27", "side": "SELL", "hash": "ed129a4138ad3743ffb43e5ea0ebb443db6c670a", "best_bid": "0.04", "best_ask": "0.73"}], "timestamp": "1769384457739", "event_type": "price_change"}}
{"_local_timestamp": "2026-01-25T23:40:58.327538+00:00", "data": {"market": "0x8c51633514afb3a854cb9f5248327ed2d6830d40b68cf23a62866a6e0cd286a0", "price_changes": [{"asset_id": "71178880545288091437751776636766820229347337814001501090420774267960283440681", "price": "0.11", "size": "5.79", "side": "BUY", "hash": "0dd8805b7ac1de09f95e77d4bdcb2c405ecacb86", "best_bid": "0.5", "best_ask": "0.88"}, {"asset_id": "7684238634255493981133898590426067650024910633947701282528239993143961130595", "price": "0.89", "size": "5.79", "side": "SELL", "hash": "63340b071f99129536b13e8368f1bacf7ab24529", "best_bid": "0.12", "best_ask": "0.5"}], "timestamp": "1769384457739", "event_type": "price_change"}}
{"_local_timestamp": "2026-01-25T23:40:58.328210+00:00", "data": {"market": "0xa740b563bbfe6747b5b583a6a015da34a91ec2d4b78812499adb27b5339567d7", "price_changes": [{"asset_id": "61686688389034832478617244975844051688063193720856283239929854404269927455550", "price": "0.01", "size": "222.46", "side": "BUY", "hash": "f7751158b0a4a7973fb4f27a9d6fa4e5188a0b17", "best_bid": "0.27", "best_ask": "0.96"}, {"asset_id": "53423629899248148188739723007991406387336891109351059215899025565130176303731", "price": "0.99", "size": "222.46", "side": "SELL", "hash": "92e4de93ab5054a7f7ecea4512a124b92d7f4ec3", "best_bid": "0.04", "best_ask": "0.73"}], "timestamp": "1769384457740", "event_type": "price_change"}}
{"_local_timestamp": "2026-01-25T23:40:58.328839+00:00", "data": {"market": "0xa740b563bbfe6747b5b583a6a015da34a91ec2d4b78812499adb27b5339567d7", "price_changes": [{"asset_id": "61686688389034832478617244975844051688063193720856283239929854404269927455550", "price": "0.03", "size": "11.65", "side": "BUY", "hash": "6950755b1d18f9a1af61ccee492a60dd77bbfd2e", "best_bid": "0.27", "best_ask": "0.96"}, {"asset_id": "53423629899248148188739723007991406387336891109351059215899025565130176303731", "price": "0.97", "size": "11.65", "side": "SELL", "hash": "bb720c77d169440f4a98f7955a6934f44b1216cc", "best_bid": "0.04", "best_ask": "0.73"}], "timestamp": "1769384457741", "event_type": "price_change"}}
{"_local_timestamp": "2026-01-25T23:41:01.757700+00:00", "data": {"market": "0xa0224dd1786eab161adafee1168cb48cc9ecbf80e938b74d7ae2ab1d097485a7", "price_changes": [{"asset_id": "22398187790187305120863916278812508331357975196340479087426628481830278112943", "price": "0.02", "size": "700", "side": "BUY", "hash": "250d63b2c45d82bdb9bf42ffb2ba7373041a5096", "best_bid": "0.23", "best_ask": "0.47"}, {"asset_id": "44193613907943747725755027726993424777152282107456500311583464431449158738087", "price": "0.98", "size": "700", "side": "SELL", "hash": "83ae0d1653e9ea441b06bd21fcc85dd147da6151", "best_bid": "0.53", "best_ask": "0.77"}], "timestamp": "1769384461685", "event_type": "price_change"}}
{"_local_timestamp": "2026-01-25T23:41:01.759895+00:00", "data": {"market": "0xa0224dd1786eab161adafee1168cb48cc9ecbf80e938b74d7ae2ab1d097485a7", "price_changes": [{"asset_id": "22398187790187305120863916278812508331357975196340479087426628481830278112943", "price": "0.04", "size": "0", "side": "BUY", "hash": "250d63b2c45d82bdb9bf42ffb2ba7373041a5096", "best_bid": "0.23", "best_ask": "0.47"}, {"asset_id": "44193613907943747725755027726993424777152282107456500311583464431449158738087", "price": "0.96", "size": "0", "side": "SELL", "hash": "83ae0d1653e9ea441b06bd21fcc85dd147da6151", "best_bid": "0.53", "best_ask": "0.77"}], "timestamp": "1769384461685", "event_type": "price_change"}}
{"_local_timestamp": "2026-01-25T23:41:04.232811+00:00", "data": {"market": "0xa0224dd1786eab161adafee1168cb48cc9ecbf80e938b74d7ae2ab1d097485a7", "price_changes": [{"asset_id": "22398187790187305120863916278812508331357975196340479087426628481830278112943", "price": "0.01", "size": "10822.94", "side": "BUY", "hash": "f5c2f9c39389e60afbc8a8e7e1a4dfa8da6fbaa6", "best_bid": "0.23", "best_ask": "0.47"}, {"asset_id": "44193613907943747725755027726993424777152282107456500311583464431449158738087", "price": "0.99", "size": "10822.94", "side": "SELL", "hash": "287726204103b5d526f07683af4c35126da09a65", "best_bid": "0.53", "best_ask": "0.77"}], "timestamp": "1769384464165", "event_type": "price_change"}}
{"_local_timestamp": "2026-01-25T23:41:04.252308+00:00", "data": {"market": "0xa0224dd1786eab161adafee1168cb48cc9ecbf80e938b74d7ae2ab1d097485a7", "price_changes": [{"asset_id": "22398187790187305120863916278812508331357975196340479087426628481830278112943", "price": "0.03", "size": "29.01", "side": "BUY", "hash": "3332fbcf82a0a63c4d206870e01ffcea8bcac45c", "best_bid": "0.23", "best_ask": "0.47"}, {"asset_id": "44193613907943747725755027726993424777152282107456500311583464431449158738087", "price": "0.97", "size": "29.01", "side": "SELL", "hash": "6290b82578dacf38d23ae165cac74d27d0480c05", "best_bid": "0.53", "best_ask": "0.77"}], "timestamp": "1769384464169", "event_type": "price_change"}}
{"_local_timestamp": "2026-01-25T23:41:39.685979+00:00", "data": {"market": "0x03c42aea715bf13ec60b6dc0dc0a401ad83fb853de3b320d91101b9a636c6026", "price_changes": [{"asset_id": "25639330389011308493516542271565374194456752331098963441806069638079251368536", "price": "0.79", "size": "5", "side": "SELL", "hash": "ccbacb15580db69cabb944d0f79d08371caac274", "best_bid": "0.03", "best_ask": "0.79"}, {"asset_id": "67310272555621311553232013859863871375723980292304081825420100284982881301079", "price": "0.21", "size": "5", "side": "BUY", "hash": "703e77e11d9328293ee30f353cab5ef32550187b", "best_bid": "0.21", "best_ask": "0.97"}], "timestamp": "1769384499604", "event_type": "price_change"}}
{"_local_timestamp": "2026-01-25T23:41:39.931304+00:00", "data": {"market": "0x03c42aea715bf13ec60b6dc0dc0a401ad83fb853de3b320d91101b9a636c6026", "price_changes": [{"asset_id": "25639330389011308493516542271565374194456752331098963441806069638079251368536", "price": "0.78", "size": "8.32", "side": "SELL", "hash": "7d93260d9c48b8b5b0ae74589999cea90622f7ab", "best_bid": "0.03", "best_ask": "0.78"}, {"asset_id": "67310272555621311553232013859863871375723980292304081825420100284982881301079", "price": "0.22", "size": "8.32", "side": "BUY", "hash": "f955bfbcbbfdf801dd094257ce137113103a4602", "best_bid": "0.22", "best_ask": "0.97"}], "timestamp": "1769384499858", "event_type": "price_change"}}
{"_local_timestamp": "2026-01-25T23:41:41.114747+00:00", "data": {"market": "0x03c42aea715bf13ec60b6dc0dc0a401ad83fb853de3b320d91101b9a636c6026", "price_changes": [{"asset_id": "67310272555621311553232013859863871375723980292304081825420100284982881301079", "price": "0.21", "size": "0", "side": "BUY", "hash": "a6fa30feb4212f19ec36f4312ff6024124e88121", "best_bid": "0.22", "best_ask": "0.97"}, {"asset_id": "25639330389011308493516542271565374194456752331098963441806069638079251368536", "price": "0.79", "size": "0", "side": "SELL", "hash": "16f09138c841c1fcfa916b08d3599216daa32c44", "best_bid": "0.03", "best_ask": "0.78"}], "timestamp": "1769384501040", "event_type": "price_change"}}
{"_local_timestamp": "2026-01-25T23:41:45.512299+00:00", "data": {"market": "0x03c42aea715bf13ec60b6dc0dc0a401ad83fb853de3b320d91101b9a636c6026", "price_changes": [{"asset_id": "67310272555621311553232013859863871375723980292304081825420100284982881301079", "price": "0.22", "size": "13.32", "side": "BUY", "hash": "04402710e74447f2b484f3cb1f04794f3459e28d", "best_bid": "0.22", "best_ask": "0.97"}, {"asset_id": "25639330389011308493516542271565374194456752331098963441806069638079251368536", "price": "0.78", "size": "13.32", "side": "SELL", "hash": "2ce37e82110f0710b6bbe4090f3b07e1390f79b4", "best_bid": "0.03", "best_ask": "0.78"}], "timestamp": "1769384505423", "event_type": "price_change"}}
{"_local_timestamp": "2026-01-25T23:41:48.533664+00:00", "data": {"market": "0xca595a16069e6cd9bce150ecd5cec487b848d9040412547c88e87553af24f620", "price_changes": [{"asset_id": "7800079113080185862147430423231593667955784347592918745149791674372792278395", "price": "0.383", "size": "0", "side": "SELL", "hash": "543cab0e1a662c9c0b1e804d6092105a9189c36f", "best_bid": "0.011", "best_ask": "0.39"}, {"asset_id": "9819058864821277493601798917843605870759192694393888839422379886017252447851", "price": "0.617", "size": "0", "side": "BUY", "hash": "861fe202d58dc64e8170b5e0f324300cfd074462", "best_bid": "0.61", "best_ask": "0.989"}], "timestamp": "1769384508466", "event_type": "price_change"}}
{"_local_timestamp": "2026-01-25T23:41:48.927330+00:00", "data": {"market": "0xca595a16069e6cd9bce150ecd5cec487b848d9040412547c88e87553af24f620", "price_changes": [{"asset_id": "7800079113080185862147430423231593667955784347592918745149791674372792278395", "price": "0.389", "size": "28.63", "side": "SELL", "hash": "2d17b5985f48b49df3f4049dcfc79525e9e2687c", "best_bid": "0.011", "best_ask": "0.389"}, {"asset_id": "9819058864821277493601798917843605870759192694393888839422379886017252447851", "price": "0.611", "size": "28.63", "side": "BUY", "hash": "0fcd3aba68a11054cab8d20bbc0d485f4c1780ef", "best_bid": "0.611", "best_ask": "0.989"}], "timestamp": "1769384508851", "event_type": "price_change"}}
{"_local_timestamp": "2026-01-25T23:41:53.105499+00:00", "data": {"market": "0x8c51633514afb3a854cb9f5248327ed2d6830d40b68cf23a62866a6e0cd286a0", "price_changes": [{"asset_id": "71178880545288091437751776636766820229347337814001501090420774267960283440681", "price": "0.09", "size": "100", "side": "BUY", "hash": "a452a7f3259e1415827d455846b1d0fbdac66617", "best_bid": "0.5", "best_ask": "0.88"}, {"asset_id": "7684238634255493981133898590426067650024910633947701282528239993143961130595", "price": "0.91", "size": "100", "side": "SELL", "hash": "237fbbc3a75f042ca743d27366b75afa33f499cf", "best_bid": "0.12", "best_ask": "0.5"}], "timestamp": "1769384512803", "event_type": "price_change"}}
{"_local_timestamp": "2026-01-25T23:41:53.355790+00:00", "data": {"market": "0x8c51633514afb3a854cb9f5248327ed2d6830d40b68cf23a62866a6e0cd286a0", "price_changes": [{"asset_id": "71178880545288091437751776636766820229347337814001501090420774267960283440681", "price": "0.1", "size": "400", "side": "BUY", "hash": "7ed1d5584c74780906b36650cab33a6d6332e151", "best_bid": "0.5", "best_ask": "0.88"}, {"asset_id": "7684238634255493981133898590426067650024910633947701282528239993143961130595", "price": "0.9", "size": "400", "side": "SELL", "hash": "682b0df7fac6bacc2b6e9b6242e1469cd8d23b73", "best_bid": "0.12", "best_ask": "0.5"}], "timestamp": "1769384513268", "event_type": "price_change"}}
{"_local_timestamp": "2026-01-25T23:41:57.732668+00:00", "data": {"market": "0x027559a14e432690257e412f18d237574155f4aebeee941382423d01c65ba37c", "price_changes": [{"asset_id": "75546450841602375940945638943612150673916039892841739175120880870878769936289", "price": "0.007", "size": "0", "side": "BUY", "hash": "cbd80a53e23b7a007647352202017e207462166d", "best_bid": "0.011", "best_ask": "0.109"}, {"asset_id": "29656649254811448219539439958370239248598869163495679625271035829447755371901", "price": "0.993", "size": "0", "side": "SELL", "hash": "b27517e779dfe209e9a26cabfea59af1146ff9b1", "best_bid": "0.891", "best_ask": "0.989"}], "timestamp": "1769384517657", "event_type": "price_change"}}
{"_local_timestamp": "2026-01-25T23:41:57.957434+00:00", "data": {"market": "0x027559a14e432690257e412f18d237574155f4aebeee941382423d01c65ba37c", "price_changes": [{"asset_id": "75546450841602375940945638943612150673916039892841739175120880870878769936289", "price": "0.005", "size": "95.28", "side": "BUY", "hash": "82ab37a8f239dfaa06b7493d926701f9d1413b98", "best_bid": "0.011", "best_ask": "0.109"}, {"asset_id": "29656649254811448219539439958370239248598869163495679625271035829447755371901", "price": "0.995", "size": "95.28", "side": "SELL", "hash": "2185f09ebd414789f7d36b7873ae6358f7997e82", "best_bid": "0.891", "best_ask": "0.989"}], "timestamp": "1769384517888", "event_type": "price_change"}}
{"_local_timestamp": "2026-01-25T23:42:10.996414+00:00", "data": {"market": "0xca595a16069e6cd9bce150ecd5cec487b848d9040412547c88e87553af24f620", "price_changes": [{"asset_id": "9819058864821277493601798917843605870759192694393888839422379886017252447851", "price": "0.057", "size": "0", "side": "BUY", "hash": "8fe16cf4660fc5783a2df2e2413f879a1bef17ea", "best_bid": "0.611", "best_ask": "0.989"}, {"asset_id": "7800079113080185862147430423231593667955784347592918745149791674372792278395", "price": "0.943", "size": "0", "side": "SELL", "hash": "75f677183f9d95de22d5b9630de0aaa6754a4c1f", "best_bid": "0.011", "best_ask": "0.389"}], "timestamp": "1769384530931", "event_type": "price_change"}}
{"_local_timestamp": "2026-01-25T23:42:11.776665+00:00", "data": {"market": "0xca595a16069e6cd9bce150ecd5cec487b848d9040412547c88e87553af24f620", "price_changes": [{"asset_id": "9819058864821277493601798917843605870759192694393888839422379886017252447851", "price": "0.059", "size": "12.86", "side": "BUY", "hash": "fa248d90c6877532f6a39b53cc3f11a43199cb7f", "best_bid": "0.611", "best_ask": "0.989"}, {"asset_id": "7800079113080185862147430423231593667955784347592918745149791674372792278395", "price": "0.941", "size": "12.86", "side": "SELL", "hash": "b97ac202d1f061406718cfce48758366fe496075", "best_bid": "0.011", "best_ask": "0.389"}], "timestamp": "1769384531700", "event_type": "price_change"}}
{"_local_timestamp": "2026-01-25T23:42:13.128593+00:00", "data": {"market": "0x027559a14e432690257e412f18d237574155f4aebeee941382423d01c65ba37c", "price_changes": [{"asset_id": "29656649254811448219539439958370239248598869163495679625271035829447755371901", "price": "0.061", "size": "32", "side": "BUY", "hash": "8e430fa0a5dbc31bc650cfb999e6f41a1633411e", "best_bid": "0.891", "best_ask": "0.989"}, {"asset_id": "75546450841602375940945638943612150673916039892841739175120880870878769936289", "price": "0.939", "size": "32", "side": "SELL", "hash": "6ae7b598d06eaba219e78c4ab0115ef6783e757b", "best_bid": "0.011", "best_ask": "0.109"}], "timestamp": "1769384533047", "event_type": "price_change"}}
{"_local_timestamp": "2026-01-25T23:42:13.745050+00:00", "data": {"market": "0x027559a14e432690257e412f18d237574155f4aebeee941382423d01c65ba37c", "price_changes": [{"asset_id": "29656649254811448219539439958370239248598869163495679625271035829447755371901", "price": "0.062", "size": "12.08", "side": "BUY", "hash": "d170b445b5f70d31b1f266a40ad1a77e7bf8149a", "best_bid": "0.891", "best_ask": "0.989"}, {"asset_id": "75546450841602375940945638943612150673916039892841739175120880870878769936289", "price": "0.938", "size": "12.08", "side": "SELL", "hash": "0eb943b331fd45134cc341632566bbac2d02efec", "best_bid": "0.011", "best_ask": "0.109"}], "timestamp": "1769384533676", "event_type": "price_change"}}
{"_local_timestamp": "2026-01-25T23:44:03.323040+00:00", "data": {"market": "0xa740b563bbfe6747b5b583a6a015da34a91ec2d4b78812499adb27b5339567d7", "price_changes": [{"asset_id": "61686688389034832478617244975844051688063193720856283239929854404269927455550", "price": "0.09", "size": "0", "side": "BUY", "hash": "c5c1c48b2ac1383aca87048c82e2d9efff34fbeb", "best_bid": "0.27", "best_ask": "0.96"}, {"asset_id": "53423629899248148188739723007991406387336891109351059215899025565130176303731", "price": "0.91", "size": "0", "side": "SELL", "hash": "de71292ef2f94f5ef481b0badf2c2d3160222b4c", "best_bid": "0.04", "best_ask": "0.73"}], "timestamp": "1769384643171", "event_type": "price_change"}}
{"_local_timestamp": "2026-01-25T23:44:03.590161+00:00", "data": {"market": "0xa740b563bbfe6747b5b583a6a015da34a91ec2d4b78812499adb27b5339567d7", "price_changes": [{"asset_id": "61686688389034832478617244975844051688063193720856283239929854404269927455550", "price": "0.03", "size": "111.65", "side": "BUY", "hash": "e529957e74af5afc2c91aedc98e7d3755a17da1a", "best_bid": "0.27", "best_ask": "0.96"}, {"asset_id": "53423629899248148188739723007991406387336891109351059215899025565130176303731", "price": "0.97", "size": "111.65", "side": "SELL", "hash": "d3762dc33ed280135b357e2da7bbe17f88606caa", "best_bid": "0.04", "best_ask": "0.73"}], "timestamp": "1769384643420", "event_type": "price_change"}}
{"_local_timestamp": "2026-01-25T23:44:31.060750+00:00", "data": {"market": "0x1f27bc2e8ba7d49c159a30d8b5acbf262e37b7bfce49faaa83d97e1230ff85b2", "price_changes": [{"asset_id": "28745788861076672720947634851890673159658681509256104153267819539064558306351", "price": "0.01", "size": "24.18", "side": "BUY", "hash": "b543189dd62b7c696fbcf0f4e7ed5f87272c368b", "best_bid": "0.5", "best_ask": "0.88"}, {"asset_id": "68693861857134386582315370929389041267603330466263232248785831669012466999405", "price": "0.99", "size": "24.18", "side": "SELL", "hash": "9db2cd08fcf12b11411ad388870c276c8c947abf", "best_bid": "0.12", "best_ask": "0.5"}], "timestamp": "1769384670992", "event_type": "price_change"}}
{"_local_timestamp": "2026-01-25T23:44:31.432661+00:00", "data": {"market": "0x1f27bc2e8ba7d49c159a30d8b5acbf262e37b7bfce49faaa83d97e1230ff85b2", "price_changes": [{"asset_id": "28745788861076672720947634851890673159658681509256104153267819539064558306351", "price": "0.01", "size": "47.4", "side": "BUY", "hash": "c5007f50443c257aa9515c372d79d15a3fde6c3d", "best_bid": "0.5", "best_ask": "0.88"}, {"asset_id": "68693861857134386582315370929389041267603330466263232248785831669012466999405", "price": "0.99", "size": "47.4", "side": "SELL", "hash": "ffa55d2bdea846ab6c3a6723e54f499b93807138", "best_bid": "0.12", "best_ask": "0.5"}], "timestamp": "1769384671353", "event_type": "price_change"}}
{"_local_timestamp": "2026-01-25T23:44:47.585482+00:00", "data": {"market": "0xca595a16069e6cd9bce150ecd5cec487b848d9040412547c88e87553af24f620", "price_changes": [{"asset_id": "9819058864821277493601798917843605870759192694393888839422379886017252447851", "price": "0.058", "size": "0", "side": "BUY", "hash": "df47a96778bf72b708502ed2573452f2b891ef38", "best_bid": "0.611", "best_ask": "0.989"}, {"asset_id": "7800079113080185862147430423231593667955784347592918745149791674372792278395", "price": "0.942", "size": "0", "side": "SELL", "hash": "53eaf849fac1c8ebcad5f8d22e9bfd82becb3e39", "best_bid": "0.011", "best_ask": "0.389"}], "timestamp": "1769384687466", "event_type": "price_change"}}
{"_local_timestamp": "2026-01-25T23:44:47.644084+00:00", "data": {"market": "0x027559a14e432690257e412f18d237574155f4aebeee941382423d01c65ba37c", "price_changes": [{"asset_id": "29656649254811448219539439958370239248598869163495679625271035829447755371901", "price": "0.054", "size": "0", "side": "BUY", "hash": "9cd6c36cbd02a30b7514a67d07612b3827153e6f", "best_bid": "0.891", "best_ask": "0.989"}, {"asset_id": "75546450841602375940945638943612150673916039892841739175120880870878769936289", "price": "0.946", "size": "0", "side": "SELL", "hash": "b800f7e04986d282c8de536a65ba7930d7592bf4", "best_bid": "0.011", "best_ask": "0.109"}], "timestamp": "1769384687471", "event_type": "price_change"}}
{"_local_timestamp": "2026-01-25T23:44:57.877119+00:00", "data": {"market": "0xa740b563bbfe6747b5b583a6a015da34a91ec2d4b78812499adb27b5339567d7", "price_changes": [{"asset_id": "61686688389034832478617244975844051688063193720856283239929854404269927455550", "price": "0.01", "size": "215.53", "side": "BUY", "hash": "d5f61341e93cba1c68f9bb3839905b74b7debe5f", "best_bid": "0.27", "best_ask": "0.96"}, {"asset_id": "53423629899248148188739723007991406387336891109351059215899025565130176303731", "price": "0.99", "size": "215.53", "side": "SELL", "hash": "0e2687d0195f995d7ad4d4dfd6522b8e6e1ca86e", "best_bid": "0.04", "best_ask": "0.73"}], "timestamp": "1769384697777", "event_type": "price_change"}}
{"_local_timestamp": "2026-01-25T23:44:57.877727+00:00", "data": {"market": "0xa740b563bbfe6747b5b583a6a015da34a91ec2d4b78812499adb27b5339567d7", "price_changes": [{"asset_id": "61686688389034832478617244975844051688063193720856283239929854404269927455550", "price": "0.03", "size": "100", "side": "BUY", "hash": "d5f61341e93cba1c68f9bb3839905b74b7debe5f", "best_bid": "0.27", "best_ask": "0.96"}, {"asset_id": "53423629899248148188739723007991406387336891109351059215899025565130176303731", "price": "0.97", "size": "100", "side": "SELL", "hash": "0e2687d0195f995d7ad4d4dfd6522b8e6e1ca86e", "best_bid": "0.04", "best_ask": "0.73"}], "timestamp": "1769384697777", "event_type": "price_change"}}
{"_local_timestamp": "2026-01-25T23:44:57.878280+00:00", "data": {"market": "0xa740b563bbfe6747b5b583a6a015da34a91ec2d4b78812499adb27b5339567d7", "price_changes": [{"asset_id": "61686688389034832478617244975844051688063193720856283239929854404269927455550", "price": "0.1", "size": "224.02", "side": "BUY", "hash": "d5f61341e93cba1c68f9bb3839905b74b7debe5f", "best_bid": "0.27", "best_ask": "0.96"}, {"asset_id": "53423629899248148188739723007991406387336891109351059215899025565130176303731", "price": "0.9", "size": "224.02", "side": "SELL", "hash": "0e2687d0195f995d7ad4d4dfd6522b8e6e1ca86e", "best_bid": "0.04", "best_ask": "0.73"}], "timestamp": "1769384697777", "event_type": "price_change"}}
{"_local_timestamp": "2026-01-25T23:44:58.259381+00:00", "data": {"market": "0xa740b563bbfe6747b5b583a6a015da34a91ec2d4b78812499adb27b5339567d7", "price_changes": [{"asset_id": "61686688389034832478617244975844051688063193720856283239929854404269927455550", "price": "0.04", "size": "5.15", "side": "BUY", "hash": "5bff5ae0e74c7423c66c344040a0d4802c86e74d", "best_bid": "0.27", "best_ask": "0.96"}, {"asset_id": "53423629899248148188739723007991406387336891109351059215899025565130176303731", "price": "0.96", "size": "5.15", "side": "SELL", "hash": "16daef0f76134e71a7357657b8e41210e1922519", "best_bid": "0.04", "best_ask": "0.73"}], "timestamp": "1769384698185", "event_type": "price_change"}}
{"_local_timestamp": "2026-01-25T23:44:58.259986+00:00", "data": {"market": "0xa740b563bbfe6747b5b583a6a015da34a91ec2d4b78812499adb27b5339567d7", "price_changes": [{"asset_id": "61686688389034832478617244975844051688063193720856283239929854404269927455550", "price": "0.08", "size": "7.73", "side": "BUY", "hash": "490b86ec4fbd8ae8f804525fee94a096f5ce006e", "best_bid": "0.27", "best_ask": "0.96"}, {"asset_id": "53423629899248148188739723007991406387336891109351059215899025565130176303731", "price": "0.92", "size": "7.73", "side": "SELL", "hash": "8a487154bad18d887984165fbcd80e4d537d0545", "best_bid": "0.04", "best_ask": "0.73"}], "timestamp": "1769384698187", "event_type": "price_change"}}
{"_local_timestamp": "2026-01-25T23:44:58.260559+00:00", "data": {"market": "0xa740b563bbfe6747b5b583a6a015da34a91ec2d4b78812499adb27b5339567d7", "price_changes": [{"asset_id": "61686688389034832478617244975844051688063193720856283239929854404269927455550", "price": "0.02", "size": "5005.98", "side": "BUY", "hash": "1bf21081dae40fbd7dd9ce7da8bab4ada0c507f7", "best_bid": "0.27", "best_ask": "0.96"}, {"asset_id": "53423629899248148188739723007991406387336891109351059215899025565130176303731", "price": "0.98", "size": "5005.98", "side": "SELL", "hash": "fc0b868ac58dd4d03cc70b4e6dcd1a6bce6e1501", "best_bid": "0.04", "best_ask": "0.73"}], "timestamp": "1769384698188", "event_type": "price_change"}}
{"_local_timestamp": "2026-01-25T23:45:14.409303+00:00", "data": {"market": "0x03c42aea715bf13ec60b6dc0dc0a401ad83fb853de3b320d91101b9a636c6026", "price_changes": [{"asset_id": "25639330389011308493516542271565374194456752331098963441806069638079251368536", "price": "0.78", "size": "5", "side": "SELL", "hash": "11a6251a4f87e0aebf26b515c7f76b704c0d1e0e", "best_bid": "0.03", "best_ask": "0.78"}, {"asset_id": "67310272555621311553232013859863871375723980292304081825420100284982881301079", "price": "0.22", "size": "5", "side": "BUY", "hash": "84e87eafe3c00274b033435797d73a2d1920c293", "best_bid": "0.22", "best_ask": "0.97"}], "timestamp": "1769384714324", "event_type": "price_change"}}
{"_local_timestamp": "2026-01-25T23:45:15.007962+00:00", "data": {"market": "0x03c42aea715bf13ec60b6dc0dc0a401ad83fb853de3b320d91101b9a636c6026", "price_changes": [{"asset_id": "25639330389011308493516542271565374194456752331098963441806069638079251368536", "price": "0.77", "size": "8.32", "side": "SELL", "hash": "810360d323622b84c3556780c9a9459cb81c31ca", "best_bid": "0.03", "best_ask": "0.77"}, {"asset_id": "67310272555621311553232013859863871375723980292304081825420100284982881301079", "price": "0.23", "size": "8.32", "side": "BUY", "hash": "d3dff37ed74b038e3dd56843248531d617b0c0d1", "best_bid": "0.23", "best_ask": "0.97"}], "timestamp": "1769384714932", "event_type": "price_change"}}
{"_local_timestamp": "2026-01-25T23:45:15.895908+00:00", "data": {"market": "0x03c42aea715bf13ec60b6dc0dc0a401ad83fb853de3b320d91101b9a636c6026", "price_changes": [{"asset_id": "67310272555621311553232013859863871375723980292304081825420100284982881301079", "price": "0.22", "size": "0", "side": "BUY", "hash": "1cdb2d0255411516e154bc07cd4a3cfa30edb6d5", "best_bid": "0.23", "best_ask": "0.97"}, {"asset_id": "25639330389011308493516542271565374194456752331098963441806069638079251368536", "price": "0.78", "size": "0", "side": "SELL", "hash": "65c007c818f61255f29ff5bc21a9cb4e3e680943", "best_bid": "0.03", "best_ask": "0.77"}], "timestamp": "1769384715818", "event_type": "price_change"}}
{"_local_timestamp": "2026-01-25T23:45:18.718831+00:00", "data": {"market": "0x03c42aea715bf13ec60b6dc0dc0a401ad83fb853de3b320d91101b9a636c6026", "price_changes": [{"asset_id": "67310272555621311553232013859863871375723980292304081825420100284982881301079", "price": "0.23", "size": "13.32", "side": "BUY", "hash": "dbf6771eedc9cfdbc847be336c4171f21ec71417", "best_bid": "0.23", "best_ask": "0.97"}, {"asset_id": "25639330389011308493516542271565374194456752331098963441806069638079251368536", "price": "0.77", "size": "13.32", "side": "SELL", "hash": "66455120a2e614a60ccd183ec9b9cf55055822ff", "best_bid": "0.03", "best_ask": "0.77"}], "timestamp": "1769384718647", "event_type": "price_change"}}
{"_local_timestamp": "2026-01-25T23:45:18.815903+00:00", "data": {"market": "0xca595a16069e6cd9bce150ecd5cec487b848d9040412547c88e87553af24f620", "price_changes": [{"asset_id": "9819058864821277493601798917843605870759192694393888839422379886017252447851", "price": "0.612", "size": "45", "side": "BUY", "hash": "d716a06be7f635eb0107c1da5db75627ce0fe047", "best_bid": "0.612", "best_ask": "0.989"}, {"asset_id": "7800079113080185862147430423231593667955784347592918745149791674372792278395", "price": "0.388", "size": "45", "side": "SELL", "hash": "054cf7111b693fffad8ed4bcb25656227bce0434", "best_bid": "0.011", "best_ask": "0.388"}], "timestamp": "1769384718741", "event_type": "price_change"}}
{"_local_timestamp": "2026-01-25T23:45:19.106168+00:00", "data": {"market": "0x027559a14e432690257e412f18d237574155f4aebeee941382423d01c65ba37c", "price_changes": [{"asset_id": "29656649254811448219539439958370239248598869163495679625271035829447755371901", "price": "0.063", "size": "45", "side": "BUY", "hash": "a98d53c67de982663fbc82e6d0a9929d4e1c7486", "best_bid": "0.891", "best_ask": "0.989"}, {"asset_id": "75546450841602375940945638943612150673916039892841739175120880870878769936289", "price": "0.937", "size": "45", "side": "SELL", "hash": "690145181bf81de53347e743f00538163e7e8c7d", "best_bid": "0.011", "best_ask": "0.109"}], "timestamp": "1769384719005", "event_type": "price_change"}}
{"_local_timestamp": "2026-01-25T23:45:33.035083+00:00", "data": {"market": "0xa740b563bbfe6747b5b583a6a015da34a91ec2d4b78812499adb27b5339567d7", "price_changes": [{"asset_id": "61686688389034832478617244975844051688063193720856283239929854404269927455550", "price": "0.07", "size": "0", "side": "BUY", "hash": "4c6fc7bddf96db763a752cec39bb16c9c18b6324", "best_bid": "0.27", "best_ask": "0.96"}, {"asset_id": "53423629899248148188739723007991406387336891109351059215899025565130176303731", "price": "0.93", "size": "0", "side": "SELL", "hash": "69dfb375ce2a952503bd8d2585b99a572ff603fa", "best_bid": "0.04", "best_ask": "0.73"}], "timestamp": "1769384732954", "event_type": "price_change"}}
{"_local_timestamp": "2026-01-25T23:45:33.342597+00:00", "data": {"market": "0xa740b563bbfe6747b5b583a6a015da34a91ec2d4b78812499adb27b5339567d7", "price_changes": [{"asset_id": "61686688389034832478617244975844051688063193720856283239929854404269927455550", "price": "0.03", "size": "200", "side": "BUY", "hash": "1a98622920fcc90136212d0c57fcef4490877cae", "best_bid": "0.27", "best_ask": "0.96"}, {"asset_id": "53423629899248148188739723007991406387336891109351059215899025565130176303731", "price": "0.97", "size": "200", "side": "SELL", "hash": "30c9769de9016abb93b7f4e201728ed3331009dc", "best_bid": "0.04", "best_ask": "0.73"}], "timestamp": "1769384733262", "event_type": "price_change"}}
{"_local_timestamp": "2026-01-25T23:45:56.427321+00:00", "data": {"market": "0x635cb63797844830d6b4f6179bd5d3bf85df6e902d55ca3551da363a197a6015", "price_changes": [{"asset_id": "77910824591036329057262898804355407930105085028914256794097954045220366551556", "price": "0.04", "size": "0", "side": "BUY", "hash": "01e66dcc612a9c2a5ca690231e3d7009a544bcc0", "best_bid": "0.13", "best_ask": "0.92"}, {"asset_id": "104455382443807393617499593132074029890019204372384161184533887382424965972532", "price": "0.96", "size": "0", "side": "SELL", "hash": "9872df98e7f64f7019d609d2c429614730b77233", "best_bid": "0.08", "best_ask": "0.87"}], "timestamp": "1769384756078", "event_type": "price_change"}}
{"_local_timestamp": "2026-01-25T23:45:56.714444+00:00", "data": {"market": "0xa0224dd1786eab161adafee1168cb48cc9ecbf80e938b74d7ae2ab1d097485a7", "price_changes": [{"asset_id": "22398187790187305120863916278812508331357975196340479087426628481830278112943", "price": "0.11", "size": "100", "side": "BUY", "hash": "e87c3fe6253382ff49073ec36f29fcf01ef35e15", "best_bid": "0.23", "best_ask": "0.47"}, {"asset_id": "44193613907943747725755027726993424777152282107456500311583464431449158738087", "price": "0.89", "size": "100", "side": "SELL", "hash": "70dd543ce6e290249906a72b5053a15e6ffc0085", "best_bid": "0.53", "best_ask": "0.77"}], "timestamp": "1769384756093", "event_type": "price_change"}}
{"_local_timestamp": "2026-01-25T23:45:57.697626+00:00", "data": {"market": "0xca595a16069e6cd9bce150ecd5cec487b848d9040412547c88e87553af24f620", "price_changes": [{"asset_id": "7800079113080185862147430423231593667955784347592918745149791674372792278395", "price": "0.389", "size": "0", "side": "SELL", "hash": "163cd78f13cb451ff387e26bfbd36c19675e741f", "best_bid": "0.011", "best_ask": "0.388"}, {"asset_id": "9819058864821277493601798917843605870759192694393888839422379886017252447851", "price": "0.611", "size": "0", "side": "BUY", "hash": "0cc36d92e05b911de275ceb88f5e859397b16813", "best_bid": "0.612", "best_ask": "0.989"}], "timestamp": "1769384757625", "event_type": "price_change"}}
{"_local_timestamp": "2026-01-25T23:45:58.022054+00:00", "data": {"market": "0xca595a16069e6cd9bce150ecd5cec487b848d9040412547c88e87553af24f620", "price_changes": [{"asset_id": "7800079113080185862147430423231593667955784347592918745149791674372792278395", "price": "0.387", "size": "28.63", "side": "SELL", "hash": "20392d7cc27f7e7b3fe0efedf6551bbe56176c64", "best_bid": "0.011", "best_ask": "0.387"}, {"asset_id": "9819058864821277493601798917843605870759192694393888839422379886017252447851", "price": "0.613", "size": "28.63", "side": "BUY", "hash": "8fee4b406a1cc7e16f03ec89593f23f54086bea9", "best_bid": "0.613", "best_ask": "0.989"}], "timestamp": "1769384757954", "event_type": "price_change"}}
{"_local_timestamp": "2026-01-25T23:46:01.461073+00:00", "data": {"market": "0x635cb63797844830d6b4f6179bd5d3bf85df6e902d55ca3551da363a197a6015", "price_changes": [{"asset_id": "77910824591036329057262898804355407930105085028914256794097954045220366551556", "price": "0.06", "size": "331.98", "side": "BUY", "hash": "17b9f3cdb943c17cfc63af43440997c48e65fc79", "best_bid": "0.13", "best_ask": "0.92"}, {"asset_id": "104455382443807393617499593132074029890019204372384161184533887382424965972532", "price": "0.94", "size": "331.98", "side": "SELL", "hash": "83ce9b33aaaceb18f65dfd2182bebe212a2dea43", "best_bid": "0.08", "best_ask": "0.87"}], "timestamp": "1769384761378", "event_type": "price_change"}}
{"_local_timestamp": "2026-01-25T23:46:01.473250+00:00", "data": {"market": "0xa0224dd1786eab161adafee1168cb48cc9ecbf80e938b74d7ae2ab1d097485a7", "price_changes": [{"asset_id": "22398187790187305120863916278812508331357975196340479087426628481830278112943", "price": "0.03", "size": "329.01", "side": "BUY", "hash": "d48a4b882f8a0d3cc1609ec05b20d41ed5ad8d21", "best_bid": "0.23", "best_ask": "0.47"}, {"asset_id": "44193613907943747725755027726993424777152282107456500311583464431449158738087", "price": "0.97", "size": "329.01", "side": "SELL", "hash": "81f46d15639f71998f6edf3ea3d7fb9dd6385a45", "best_bid": "0.53", "best_ask": "0.77"}], "timestamp": "1769384761378", "event_type": "price_change"}}
{"_local_timestamp": "2026-01-25T23:46:11.184835+00:00", "data": {"market": "0x027559a14e432690257e412f18d237574155f4aebeee941382423d01c65ba37c", "price_changes": [{"asset_id": "75546450841602375940945638943612150673916039892841739175120880870878769936289", "price": "0.005", "size": "70.46", "side": "BUY", "hash": "5a6a782f64f32db2e6ae06d5f7cc1ac76c2aec37", "best_bid": "0.011", "best_ask": "0.109"}, {"asset_id": "29656649254811448219539439958370239248598869163495679625271035829447755371901", "price": "0.995", "size": "70.46", "side": "SELL", "hash": "5c2feb23b0c35eca6e211a2510542aa9adc63c5a", "best_bid": "0.891", "best_ask": "0.989"}], "timestamp": "1769384771069", "event_type": "price_change"}}
{"_local_timestamp": "2026-01-25T23:46:11.679093+00:00", "data": {"market": "0x027559a14e432690257e412f18d237574155f4aebeee941382423d01c65ba37c", "price_changes": [{"asset_id": "75546450841602375940945638943612150673916039892841739175120880870878769936289", "price": "0.006", "size": "20.68", "side": "BUY", "hash": "90302f68752daf87cca640eaa5bdf083ccd28735", "best_bid": "0.011", "best_ask": "0.109"}, {"asset_id": "29656649254811448219539439958370239248598869163495679625271035829447755371901", "price": "0.994", "size": "20.68", "side": "SELL", "hash": "5584682a1bb04032eb4a0354e07d23ed3527007d", "best_bid": "0.891", "best_ask": "0.989"}], "timestamp": "1769384771586", "event_type": "price_change"}}
{"_local_timestamp": "2026-01-25T23:46:28.665672+00:00", "data": {"market": "0xca595a16069e6cd9bce150ecd5cec487b848d9040412547c88e87553af24f620", "price_changes": [{"asset_id": "9819058864821277493601798917843605870759192694393888839422379886017252447851", "price": "0.059", "size": "0", "side": "BUY", "hash": "d596ef563fe298e1c34c6dd59e84436b25c81795", "best_bid": "0.613", "best_ask": "0.989"}, {"asset_id": "7800079113080185862147430423231593667955784347592918745149791674372792278395", "price": "0.941", "size": "0", "side": "SELL", "hash": "b6117f1f29c5dfeefceb09f0038132306f2e8789", "best_bid": "0.011", "best_ask": "0.387"}], "timestamp": "1769384788582", "event_type": "price_change"}}
{"_local_timestamp": "2026-01-25T23:46:28.980346+00:00", "data": {"market": "0xca595a16069e6cd9bce150ecd5cec487b848d9040412547c88e87553af24f620", "price_changes": [{"asset_id": "9819058864821277493601798917843605870759192694393888839422379886017252447851", "price": "0.06", "size": "12.65", "side": "BUY", "hash": "8108111d7f90b3eca4ba0fbf75da14ecb32d7972", "best_bid": "0.613", "best_ask": "0.989"}, {"asset_id": "7800079113080185862147430423231593667955784347592918745149791674372792278395", "price": "0.94", "size": "12.65", "side": "SELL", "hash": "b55678e2241d39547b668129abd5d866976d36b1", "best_bid": "0.011", "best_ask": "0.387"}], "timestamp": "1769384788856", "event_type": "price_change"}}
{"_local_timestamp": "2026-01-25T23:46:31.403186+00:00", "data": {"market": "0x03c42aea715bf13ec60b6dc0dc0a401ad83fb853de3b320d91101b9a636c6026", "price_changes": [{"asset_id": "67310272555621311553232013859863871375723980292304081825420100284982881301079", "price": "0.01", "size": "15.2", "side": "BUY", "hash": "051d7f23c65bad2f6fab29285d6167589287460a", "best_bid": "0.23", "best_ask": "0.97"}, {"asset_id": "25639330389011308493516542271565374194456752331098963441806069638079251368536", "price": "0.99", "size": "15.2", "side": "SELL", "hash": "30b47bd69508159e79bd67d0ff2cee0250d8bd4a", "best_bid": "0.03", "best_ask": "0.77"}], "timestamp": "1769384791329", "event_type": "price_change"}}
{"_local_timestamp": "2026-01-25T23:46:31.403927+00:00", "data": {"market": "0x027559a14e432690257e412f18d237574155f4aebeee941382423d01c65ba37c", "price_changes": [{"asset_id": "29656649254811448219539439958370239248598869163495679625271035829447755371901", "price": "0.062", "size": "0", "side": "BUY", "hash": "9874193e9becf15de53dd7d0de3f9d07fa1c6ebe", "best_bid": "0.891", "best_ask": "0.989"}, {"asset_id": "75546450841602375940945638943612150673916039892841739175120880870878769936289", "price": "0.938", "size": "0", "side": "SELL", "hash": "a2e87fe4146ed21a2d642ec7f5aa6e5c2e1cdb3d", "best_bid": "0.011", "best_ask": "0.109"}], "timestamp": "1769384791329", "event_type": "price_change"}}
{"_local_timestamp": "2026-01-25T23:46:31.811335+00:00", "data": {"market": "0x027559a14e432690257e412f18d237574155f4aebeee941382423d01c65ba37c", "price_changes": [{"asset_id": "29656649254811448219539439958370239248598869163495679625271035829447755371901", "price": "0.064", "size": "11.15", "side": "BUY", "hash": "8165d524acb725fb4078d1cfefe538a77e34805a", "best_bid": "0.891", "best_ask": "0.989"}, {"asset_id": "75546450841602375940945638943612150673916039892841739175120880870878769936289", "price": "0.936", "size": "11.15", "side": "SELL", "hash": "879aa3ad80f002079aa7d4dd5a093d247ef164a4", "best_bid": "0.011", "best_ask": "0.109"}], "timestamp": "1769384791736", "event_type": "price_change"}}
{"_local_timestamp": "2026-01-25T23:46:31.812030+00:00", "data": {"market": "0x027559a14e432690257e412f18d237574155f4aebeee941382423d01c65ba37c", "price_changes": [{"asset_id": "29656649254811448219539439958370239248598869163495679625271035829447755371901", "price": "0.007", "size": "22.09", "side": "BUY", "hash": "fdece33b82d7fabc109a783fcb8cd06623c084f1", "best_bid": "0.891", "best_ask": "0.989"}, {"asset_id": "75546450841602375940945638943612150673916039892841739175120880870878769936289", "price": "0.993", "size": "22.09", "side": "SELL", "hash": "7eaa1b0cc8f1ce2dc0a43aff2c0402b64b4950ef", "best_bid": "0.011", "best_ask": "0.109"}], "timestamp": "1769384791737", "event_type": "price_change"}}
{"_local_timestamp": "2026-01-25T23:46:32.247280+00:00", "data": {"market": "0x03c42aea715bf13ec60b6dc0dc0a401ad83fb853de3b320d91101b9a636c6026", "price_changes": [{"asset_id": "67310272555621311553232013859863871375723980292304081825420100284982881301079", "price": "0.01", "size": "22.64", "side": "BUY", "hash": "173b5c73cb64f9abc2535ebd9d40930252646713", "best_bid": "0.23", "best_ask": "0.97"}, {"asset_id": "25639330389011308493516542271565374194456752331098963441806069638079251368536", "price": "0.99", "size": "22.64", "side": "SELL", "hash": "653eef8dc8a794858d0d0872b4920cd63d070a25", "best_bid": "0.03", "best_ask": "0.77"}], "timestamp": "1769384792170", "event_type": "price_change"}}
{"_local_timestamp": "2026-01-25T23:47:18.838641+00:00", "data": {"market": "0xa0224dd1786eab161adafee1168cb48cc9ecbf80e938b74d7ae2ab1d097485a7", "price_changes": [{"asset_id": "22398187790187305120863916278812508331357975196340479087426628481830278112943", "price": "0.11", "size": "0", "side": "BUY", "hash": "40dd335458e16d4497d304e1f96150a926fbd781", "best_bid": "0.23", "best_ask": "0.47"}, {"asset_id": "44193613907943747725755027726993424777152282107456500311583464431449158738087", "price": "0.89", "size": "0", "side": "SELL", "hash": "4f2ce5f62aedbc603ac12807f22453836897301b", "best_bid": "0.53", "best_ask": "0.77"}], "timestamp": "1769384838763", "event_type": "price_change"}}
{"_local_timestamp": "2026-01-25T23:47:18.839645+00:00", "data": {"market": "0xa0224dd1786eab161adafee1168cb48cc9ecbf80e938b74d7ae2ab1d097485a7", "price_changes": [{"asset_id": "22398187790187305120863916278812508331357975196340479087426628481830278112943", "price": "0.02", "size": "0", "side": "BUY", "hash": "40dd335458e16d4497d304e1f96150a926fbd781", "best_bid": "0.23", "best_ask": "0.47"}, {"asset_id": "44193613907943747725755027726993424777152282107456500311583464431449158738087", "price": "0.98", "size": "0", "side": "SELL", "hash": "4f2ce5f62aedbc603ac12807f22453836897301b", "best_bid": "0.53", "best_ask": "0.77"}], "timestamp": "1769384838763", "event_type": "price_change"}}
{"_local_timestamp": "2026-01-25T23:47:18.840269+00:00", "data": {"market": "0xa0224dd1786eab161adafee1168cb48cc9ecbf80e938b74d7ae2ab1d097485a7", "price_changes": [{"asset_id": "22398187790187305120863916278812508331357975196340479087426628481830278112943", "price": "0.01", "size": "10022.94", "side": "BUY", "hash": "40dd335458e16d4497d304e1f96150a926fbd781", "best_bid": "0.23", "best_ask": "0.47"}, {"asset_id": "44193613907943747725755027726993424777152282107456500311583464431449158738087", "price": "0.99", "size": "10022.94", "side": "SELL", "hash": "4f2ce5f62aedbc603ac12807f22453836897301b", "best_bid": "0.53", "best_ask": "0.77"}], "timestamp": "1769384838763", "event_type": "price_change"}}
{"_local_timestamp": "2026-01-25T23:47:19.395523+00:00", "data": {"market": "0xa0224dd1786eab161adafee1168cb48cc9ecbf80e938b74d7ae2ab1d097485a7", "price_changes": [{"asset_id": "22398187790187305120863916278812508331357975196340479087426628481830278112943", "price": "0.03", "size": "1029.01", "side": "BUY", "hash": "854b9143e726f0e43c0893571c067ff25ef72130", "best_bid": "0.23", "best_ask": "0.47"}, {"asset_id": "44193613907943747725755027726993424777152282107456500311583464431449158738087", "price": "0.97", "size": "1029.01", "side": "SELL", "hash": "809f96018be956b98694b8d44a33ccbdfb5a8110", "best_bid": "0.53", "best_ask": "0.77"}], "timestamp": "1769384839123", "event_type": "price_change"}}
{"_local_timestamp": "2026-01-25T23:47:56.805457+00:00", "data": {"market": "0xa0224dd1786eab161adafee1168cb48cc9ecbf80e938b74d7ae2ab1d097485a7", "price_changes": [{"asset_id": "44193613907943747725755027726993424777152282107456500311583464431449158738087", "price": "0.22", "size": "0", "side": "BUY", "hash": "b9f15f4e4035feae7347c4e480816b6d8b46024f", "best_bid": "0.53", "best_ask": "0.77"}, {"asset_id": "22398187790187305120863916278812508331357975196340479087426628481830278112943", "price": "0.78", "size": "0", "side": "SELL", "hash": "ed9a8108bef58ea907e64062fb2a6d9f89d8ac0d", "best_bid": "0.23", "best_ask": "0.47"}], "timestamp": "1769384876732", "event_type": "price_change"}}
{"_local_timestamp": "2026-01-25T23:47:56.881184+00:00", "data": {"market": "0xa0224dd1786eab161adafee1168cb48cc9ecbf80e938b74d7ae2ab1d097485a7", "price_changes": [{"asset_id": "44193613907943747725755027726993424777152282107456500311583464431449158738087", "price": "0.22", "size": "9", "side": "BUY", "hash": "432f49cb2f5f9a48f284d9709fac8d555ca3a203", "best_bid": "0.53", "best_ask": "0.77"}, {"asset_id": "22398187790187305120863916278812508331357975196340479087426628481830278112943", "price": "0.78", "size": "9", "side": "SELL", "hash": "e0e212c7cafc1fcee574ba6dc8a40084800bb006", "best_bid": "0.23", "best_ask": "0.47"}], "timestamp": "1769384876808", "event_type": "price_change"}}
{"_local_timestamp": "2026-01-25T23:48:12.989424+00:00", "data": {"market": "0x1ac116ca6128b12ba9dee16cbb862a97c997f618ca465ec3ad9804505029dacd", "price_changes": [{"asset_id": "57315507480117481325027835038256219537881608729626837750964718238872905592326", "price": "0.94", "size": "39.6", "side": "SELL", "hash": "ad553ef7665d1f9eba4d47b59c7ac69213c7d3b4", "best_bid": "0.08", "best_ask": "0.49"}, {"asset_id": "3288340895010205036170048275599967721898253126704096745341178630581136187620", "price": "0.06", "size": "39.6", "side": "BUY", "hash": "f27a9abdb45b54f349be397479749cfb3078bad6", "best_bid": "0.51", "best_ask": "0.92"}], "timestamp": "1769384892924", "event_type": "price_change"}}
{"_local_timestamp": "2026-01-25T23:48:30.185752+00:00", "data": {"market": "0x1ac116ca6128b12ba9dee16cbb862a97c997f618ca465ec3ad9804505029dacd", "price_changes": [{"asset_id": "57315507480117481325027835038256219537881608729626837750964718238872905592326", "price": "0.95", "size": "2066", "side": "SELL", "hash": "6fb75b578b5dc336fa48f9a9f9fd5013c5b258c7", "best_bid": "0.08", "best_ask": "0.49"}, {"asset_id": "3288340895010205036170048275599967721898253126704096745341178630581136187620", "price": "0.05", "size": "2066", "side": "BUY", "hash": "d00f34188c7746f3a1ab4b8e8497ac303f93ec78", "best_bid": "0.51", "best_ask": "0.92"}], "timestamp": "1769384910108", "event_type": "price_change"}}
{"_local_timestamp": "2026-01-25T23:48:30.678319+00:00", "data": {"market": "0x1f27bc2e8ba7d49c159a30d8b5acbf262e37b7bfce49faaa83d97e1230ff85b2", "price_changes": [{"asset_id": "28745788861076672720947634851890673159658681509256104153267819539064558306351", "price": "0.01", "size": "24.18", "side": "BUY", "hash": "036c2ce79cb25c769bfcabb4a71272562f50c765", "best_bid": "0.5", "best_ask": "0.88"}, {"asset_id": "68693861857134386582315370929389041267603330466263232248785831669012466999405", "price": "0.99", "size": "24.18", "side": "SELL", "hash": "e6d31472c89a720ddac7fc1bbddb12a0b4507f36", "best_bid": "0.12", "best_ask": "0.5"}], "timestamp": "1769384910595", "event_type": "price_change"}}
{"_local_timestamp": "2026-01-25T23:48:31.531964+00:00", "data": {"market": "0x1f27bc2e8ba7d49c159a30d8b5acbf262e37b7bfce49faaa83d97e1230ff85b2", "price_changes": [{"asset_id": "28745788861076672720947634851890673159658681509256104153267819539064558306351", "price": "0.01", "size": "47.4", "side": "BUY", "hash": "a76ef17aea506de6ac4199bada14e84f6ed86e98", "best_bid": "0.5", "best_ask": "0.88"}, {"asset_id": "68693861857134386582315370929389041267603330466263232248785831669012466999405", "price": "0.99", "size": "47.4", "side": "SELL", "hash": "d6e55c45f9b916ce82bc2a9ae382d4a31a6ab33d", "best_bid": "0.12", "best_ask": "0.5"}], "timestamp": "1769384911457", "event_type": "price_change"}}
{"_local_timestamp": "2026-01-25T23:48:37.475764+00:00", "data": {"market": "0x03c42aea715bf13ec60b6dc0dc0a401ad83fb853de3b320d91101b9a636c6026", "price_changes": [{"asset_id": "25639330389011308493516542271565374194456752331098963441806069638079251368536", "price": "0.77", "size": "5", "side": "SELL", "hash": "31f561316c8e1ba8c66029c3dcccd9a30fda1aa0", "best_bid": "0.03", "best_ask": "0.77"}, {"asset_id": "67310272555621311553232013859863871375723980292304081825420100284982881301079", "price": "0.23", "size": "5", "side": "BUY", "hash": "12f998d659c4ca48f84aae69bb8f6fc3650905ce", "best_bid": "0.23", "best_ask": "0.97"}], "timestamp": "1769384917402", "event_type": "price_change"}}
{"_local_timestamp": "2026-01-25T23:48:37.996606+00:00", "data": {"market": "0x03c42aea715bf13ec60b6dc0dc0a401ad83fb853de3b320d91101b9a636c6026", "price_changes": [{"asset_id": "67310272555621311553232013859863871375723980292304081825420100284982881301079", "price": "0.23", "size": "0", "side": "BUY", "hash": "a6e1e5446474b6a1f21e37b8308204912ad23378", "best_bid": "0.09", "best_ask": "0.97"}, {"asset_id": "25639330389011308493516542271565374194456752331098963441806069638079251368536", "price": "0.77", "size": "0", "side": "SELL", "hash": "22146aeaca02bc01b3da82a54dce1871539563bd", "best_bid": "0.03", "best_ask": "0.91"}], "timestamp": "1769384917802", "event_type": "price_change"}}
{"_local_timestamp": "2026-01-25T23:48:38.034352+00:00", "data": {"market": "0x03c42aea715bf13ec60b6dc0dc0a401ad83fb853de3b320d91101b9a636c6026", "price_changes": [{"asset_id": "25639330389011308493516542271565374194456752331098963441806069638079251368536", "price": "0.76", "size": "8.32", "side": "SELL", "hash": "2f9d3bbfae31716618c8a96c4c47b11947f8808d", "best_bid": "0.03", "best_ask": "0.76"}, {"asset_id": "67310272555621311553232013859863871375723980292304081825420100284982881301079", "price": "0.24", "size": "8.32", "side": "BUY", "hash": "e2589c121cf9c54be4378ac6e2e2b4b93966eb00", "best_bid": "0.24", "best_ask": "0.97"}], "timestamp": "1769384917883", "event_type": "price_change"}}
{"_local_timestamp": "2026-01-25T23:48:40.527395+00:00", "data": {"market": "0x03c42aea715bf13ec60b6dc0dc0a401ad83fb853de3b320d91101b9a636c6026", "price_changes": [{"asset_id": "67310272555621311553232013859863871375723980292304081825420100284982881301079", "price": "0.24", "size": "13.32", "side": "BUY", "hash": "998bc63987efda00c8f81b7813edd03602948769", "best_bid": "0.24", "best_ask": "0.97"}, {"asset_id": "25639330389011308493516542271565374194456752331098963441806069638079251368536", "price": "0.76", "size": "13.32", "side": "SELL", "hash": "0d6f605aa7dd56add8acdde943833de15ec83b5a", "best_bid": "0.03", "best_ask": "0.76"}], "timestamp": "1769384920453", "event_type": "price_change"}}
{"_local_timestamp": "2026-01-25T23:48:50.251770+00:00", "data": {"market": "0xa740b563bbfe6747b5b583a6a015da34a91ec2d4b78812499adb27b5339567d7", "price_changes": [{"asset_id": "61686688389034832478617244975844051688063193720856283239929854404269927455550", "price": "0.02", "size": "5000", "side": "BUY", "hash": "671af5f67a8c0db744748dbb09c548ad526827ef", "best_bid": "0.27", "best_ask": "0.96"}, {"asset_id": "53423629899248148188739723007991406387336891109351059215899025565130176303731", "price": "0.98", "size": "5000", "side": "SELL", "hash": "eecc3fb7ac8b453826c36769d101927ec6ca0f0b", "best_bid": "0.04", "best_ask": "0.73"}], "timestamp": "1769384930181", "event_type": "price_change"}}
{"_local_timestamp": "2026-01-25T23:48:50.252464+00:00", "data": {"market": "0xa740b563bbfe6747b5b583a6a015da34a91ec2d4b78812499adb27b5339567d7", "price_changes": [{"asset_id": "61686688389034832478617244975844051688063193720856283239929854404269927455550", "price": "0.04", "size": "0", "side": "BUY", "hash": "671af5f67a8c0db744748dbb09c548ad526827ef", "best_bid": "0.27", "best_ask": "0.96"}, {"asset_id": "53423629899248148188739723007991406387336891109351059215899025565130176303731", "price": "0.96", "size": "0", "side": "SELL", "hash": "eecc3fb7ac8b453826c36769d101927ec6ca0f0b", "best_bid": "0.04", "best_ask": "0.73"}], "timestamp": "1769384930181", "event_type": "price_change"}}
{"_local_timestamp": "2026-01-25T23:48:50.253080+00:00", "data": {"market": "0xa740b563bbfe6747b5b583a6a015da34a91ec2d4b78812499adb27b5339567d7", "price_changes": [{"asset_id": "61686688389034832478617244975844051688063193720856283239929854404269927455550", "price": "0.08", "size": "0", "side": "BUY", "hash": "671af5f67a8c0db744748dbb09c548ad526827ef", "best_bid": "0.27", "best_ask": "0.96"}, {"asset_id": "53423629899248148188739723007991406387336891109351059215899025565130176303731", "price": "0.92", "size": "0", "side": "SELL", "hash": "eecc3fb7ac8b453826c36769d101927ec6ca0f0b", "best_bid": "0.04", "best_ask": "0.73"}], "timestamp": "1769384930181", "event_type": "price_change"}}
{"_local_timestamp": "2026-01-25T23:48:50.793592+00:00", "data": {"market": "0xa740b563bbfe6747b5b583a6a015da34a91ec2d4b78812499adb27b5339567d7", "price_changes": [{"asset_id": "61686688389034832478617244975844051688063193720856283239929854404269927455550", "price": "0.01", "size": "222.46", "side": "BUY", "hash": "923d5c2bd9ecffb1440fe55015cff0ad0f853558", "best_bid": "0.27", "best_ask": "0.96"}, {"asset_id": "53423629899248148188739723007991406387336891109351059215899025565130176303731", "price": "0.99", "size": "222.46", "side": "SELL", "hash": "f00257edb44d6e8a700fe52f04b67301653c131a", "best_bid": "0.04", "best_ask": "0.73"}], "timestamp": "1769384930725", "event_type": "price_change"}}
{"_local_timestamp": "2026-01-25T23:48:50.794356+00:00", "data": {"market": "0xa740b563bbfe6747b5b583a6a015da34a91ec2d4b78812499adb27b5339567d7", "price_changes": [{"asset_id": "61686688389034832478617244975844051688063193720856283239929854404269927455550", "price": "0.07", "size": "9.43", "side": "BUY", "hash": "5ca8e116aade028a543a342b3ca82ef5e1ed5af8", "best_bid": "0.27", "best_ask": "0.96"}, {"asset_id": "53423629899248148188739723007991406387336891109351059215899025565130176303731", "price": "0.93", "size": "9.43", "side": "SELL", "hash": "27bdfe88ca347a80f88144779af2167fff9d3308", "best_bid": "0.04", "best_ask": "0.73"}], "timestamp": "1769384930727", "event_type": "price_change"}}
{"_local_timestamp": "2026-01-25T23:48:50.798760+00:00", "data": {"market": "0xa740b563bbfe6747b5b583a6a015da34a91ec2d4b78812499adb27b5339567d7", "price_changes": [{"asset_id": "61686688389034832478617244975844051688063193720856283239929854404269927455550", "price": "0.03", "size": "207.15", "side": "BUY", "hash": "fa463c47acdca1d85e4506b7b1fb7d4ccdda04e2", "best_bid": "0.27", "best_ask": "0.96"}, {"asset_id": "53423629899248148188739723007991406387336891109351059215899025565130176303731", "price": "0.97", "size": "207.15", "side": "SELL", "hash": "4892d8af36801e5f26abd8dc5c01250b28b59cb8", "best_bid": "0.04", "best_ask": "0.73"}], "timestamp": "1769384930728", "event_type": "price_change"}}
{"_local_timestamp": "2026-01-25T23:48:59.902496+00:00", "data": {"market": "0xa0224dd1786eab161adafee1168cb48cc9ecbf80e938b74d7ae2ab1d097485a7", "price_changes": [{"asset_id": "22398187790187305120863916278812508331357975196340479087426628481830278112943", "price": "0.01", "size": "10015.48", "side": "BUY", "hash": "e866af8ab8f232fcc10bc9b115457c0cb4bb9965", "best_bid": "0.23", "best_ask": "0.47"}, {"asset_id": "44193613907943747725755027726993424777152282107456500311583464431449158738087", "price": "0.99", "size": "10015.48", "side": "SELL", "hash": "ef5d7600d7e34950e1cd5fd6ade4862a10fcd7ff", "best_bid": "0.53", "best_ask": "0.77"}], "timestamp": "1769384939830", "event_type": "price_change"}}
{"_local_timestamp": "2026-01-25T23:48:59.903451+00:00", "data": {"market": "0xa0224dd1786eab161adafee1168cb48cc9ecbf80e938b74d7ae2ab1d097485a7", "price_changes": [{"asset_id": "22398187790187305120863916278812508331357975196340479087426628481830278112943", "price": "0.03", "size": "1000", "side": "BUY", "hash": "e866af8ab8f232fcc10bc9b115457c0cb4bb9965", "best_bid": "0.23", "best_ask": "0.47"}, {"asset_id": "44193613907943747725755027726993424777152282107456500311583464431449158738087", "price": "0.97", "size": "1000", "side": "SELL", "hash": "ef5d7600d7e34950e1cd5fd6ade4862a10fcd7ff", "best_bid": "0.53", "best_ask": "0.77"}], "timestamp": "1769384939830", "event_type": "price_change"}}
{"_local_timestamp": "2026-01-25T23:49:00.462652+00:00", "data": {"market": "0xa0224dd1786eab161adafee1168cb48cc9ecbf80e938b74d7ae2ab1d097485a7", "price_changes": [{"asset_id": "22398187790187305120863916278812508331357975196340479087426628481830278112943", "price": "0.02", "size": "6.61", "side": "BUY", "hash": "1bfa10c2e44cfceec27161555e6d5da3a69abc7e", "best_bid": "0.23", "best_ask": "0.47"}, {"asset_id": "44193613907943747725755027726993424777152282107456500311583464431449158738087", "price": "0.98", "size": "6.61", "side": "SELL", "hash": "9f2f2fb3ac3084bf60e5431f6a02686938257454", "best_bid": "0.53", "best_ask": "0.77"}], "timestamp": "1769384940393", "event_type": "price_change"}}
{"_local_timestamp": "2026-01-25T23:49:00.470037+00:00", "data": {"market": "0xa0224dd1786eab161adafee1168cb48cc9ecbf80e938b74d7ae2ab1d097485a7", "price_changes": [{"asset_id": "22398187790187305120863916278812508331357975196340479087426628481830278112943", "price": "0.04", "size": "20.32", "side": "BUY", "hash": "cb404a3cbacdfdbd8ff49f51c55ef54f42646d66", "best_bid": "0.23", "best_ask": "0.47"}, {"asset_id": "44193613907943747725755027726993424777152282107456500311583464431449158738087", "price": "0.96", "size": "20.32", "side": "SELL", "hash": "01636c1f5b8dc9a7ed79262a9688207fabd67569", "best_bid": "0.53", "best_ask": "0.77"}], "timestamp": "1769384940394", "event_type": "price_change"}}
{"_local_timestamp": "2026-01-25T23:49:21.597227+00:00", "data": {"market": "0xe39845e9efee80761e2e9e89d579f8b943a29233153f3ed148f8d84637bea6b7", "price_changes": [{"asset_id": "12787908846201818836113906836317537483609531613584477341982605123655773837316", "price": "0.12", "size": "30", "side": "BUY", "hash": "0c609b674dc2f76c922a832d7ff644e4ff9d8ae5", "best_bid": "0.12", "best_ask": "0.85"}, {"asset_id": "6336829643612419106262092052749783689174278821109708845497505799770380553013", "price": "0.88", "size": "30", "side": "SELL", "hash": "9872442d1d902c81de1106baad24a1daae339de0", "best_bid": "0.15", "best_ask": "0.88"}], "timestamp": "1769384961528", "event_type": "price_change"}}
{"_local_timestamp": "2026-01-25T23:49:24.908483+00:00", "data": {"market": "0xe39845e9efee80761e2e9e89d579f8b943a29233153f3ed148f8d84637bea6b7", "price_changes": [{"asset_id": "6336829643612419106262092052749783689174278821109708845497505799770380553013", "price": "0.15", "size": "13.82", "side": "BUY", "hash": "9db33de64d7a30378114659c9f17cd6ccc736b2c", "best_bid": "0.15", "best_ask": "0.88"}, {"asset_id": "12787908846201818836113906836317537483609531613584477341982605123655773837316", "price": "0.85", "size": "13.82", "side": "SELL", "hash": "00da93f35437f26970b12f8ecb654280f2f13549", "best_bid": "0.12", "best_ask": "0.85"}], "timestamp": "1769384964816", "event_type": "price_change"}}
{"_local_timestamp": "2026-01-25T23:49:50.047850+00:00", "data": {"market": "0xca595a16069e6cd9bce150ecd5cec487b848d9040412547c88e87553af24f620", "price_changes": [{"asset_id": "9819058864821277493601798917843605870759192694393888839422379886017252447851", "price": "0.612", "size": "0", "side": "BUY", "hash": "f869d9b2c2d79ba331ac544239cdb4e7effb84ce", "best_bid": "0.613", "best_ask": "0.989"}, {"asset_id": "7800079113080185862147430423231593667955784347592918745149791674372792278395", "price": "0.388", "size": "0", "side": "SELL", "hash": "94efd1d0b04c861ac422d5e5423b354ed88439de", "best_bid": "0.011", "best_ask": "0.387"}], "timestamp": "1769384989966", "event_type": "price_change"}}
{"_local_timestamp": "2026-01-25T23:49:50.085642+00:00", "data": {"market": "0x027559a14e432690257e412f18d237574155f4aebeee941382423d01c65ba37c", "price_changes": [{"asset_id": "29656649254811448219539439958370239248598869163495679625271035829447755371901", "price": "0.063", "size": "0", "side": "BUY", "hash": "22bf48a45574cc96208fb2a76197cf7760632b35", "best_bid": "0.891", "best_ask": "0.989"}, {"asset_id": "75546450841602375940945638943612150673916039892841739175120880870878769936289", "price": "0.937", "size": "0", "side": "SELL", "hash": "d70923b0d15d4a394d7ef06cc51fb13e893dd459", "best_bid": "0.011", "best_ask": "0.109"}], "timestamp": "1769384989969", "event_type": "price_change"}}
{"_local_timestamp": "2026-01-25T23:50:01.504826+00:00", "data": {"market": "0x027559a14e432690257e412f18d237574155f4aebeee941382423d01c65ba37c", "price_changes": [{"asset_id": "75546450841602375940945638943612150673916039892841739175120880870878769936289", "price": "0.006", "size": "0", "side": "BUY", "hash": "026d9fdb7d4ed517c533d1ee1bb5527a441ca900", "best_bid": "0.011", "best_ask": "0.109"}, {"asset_id": "29656649254811448219539439958370239248598869163495679625271035829447755371901", "price": "0.994", "size": "0", "side": "SELL", "hash": "f330baa722a52de87a6c11cd7d9d95b5f3c1c746", "best_bid": "0.891", "best_ask": "0.989"}], "timestamp": "1769385001419", "event_type": "price_change"}}
{"_local_timestamp": "2026-01-25T23:50:01.792887+00:00", "data": {"market": "0x027559a14e432690257e412f18d237574155f4aebeee941382423d01c65ba37c", "price_changes": [{"asset_id": "75546450841602375940945638943612150673916039892841739175120880870878769936289", "price": "0.005", "size": "95.28", "side": "BUY", "hash": "50e09730001b7f62a607445a5ed1d5f12d2406a9", "best_bid": "0.011", "best_ask": "0.109"}, {"asset_id": "29656649254811448219539439958370239248598869163495679625271035829447755371901", "price": "0.995", "size": "95.28", "side": "SELL", "hash": "815df2bdb7309792a9489e67a37a5978ba6743e1", "best_bid": "0.891", "best_ask": "0.989"}], "timestamp": "1769385001711", "event_type": "price_change"}}
{"_local_timestamp": "2026-01-25T23:50:07.488498+00:00", "data": {"market": "0xe39845e9efee80761e2e9e89d579f8b943a29233153f3ed148f8d84637bea6b7", "price_changes": [{"asset_id": "12787908846201818836113906836317537483609531613584477341982605123655773837316", "price": "0.12", "size": "50.83", "side": "BUY", "hash": "6e07bcfcba588e386d0ea7c5de58a7d7e8c5a172", "best_bid": "0.12", "best_ask": "0.85"}, {"asset_id": "6336829643612419106262092052749783689174278821109708845497505799770380553013", "price": "0.88", "size": "50.83", "side": "SELL", "hash": "0396e6e35a4fd545047d3144d13dbd580537d18e", "best_bid": "0.15", "best_ask": "0.88"}], "timestamp": "1769385007409", "event_type": "price_change"}}
{"_local_timestamp": "2026-01-25T23:50:22.305828+00:00", "data": {"market": "0xca595a16069e6cd9bce150ecd5cec487b848d9040412547c88e87553af24f620", "price_changes": [{"asset_id": "9819058864821277493601798917843605870759192694393888839422379886017252447851", "price": "0.614", "size": "45", "side": "BUY", "hash": "d9aeb81172a232348f40c979b85add46ce318129", "best_bid": "0.614", "best_ask": "0.989"}, {"asset_id": "7800079113080185862147430423231593667955784347592918745149791674372792278395", "price": "0.386", "size": "45", "side": "SELL", "hash": "fc86b1e4cf465f0a9d3b3b199cd4bd2a573d8299", "best_bid": "0.011", "best_ask": "0.386"}], "timestamp": "1769385022146", "event_type": "price_change"}}
{"_local_timestamp": "2026-01-25T23:50:22.537068+00:00", "data": {"market": "0x027559a14e432690257e412f18d237574155f4aebeee941382423d01c65ba37c", "price_changes": [{"asset_id": "29656649254811448219539439958370239248598869163495679625271035829447755371901", "price": "0.065", "size": "45", "side": "BUY", "hash": "26d7e51a8cc0e8ebfc0bbd042c9be60801fd9b56", "best_bid": "0.891", "best_ask": "0.989"}, {"asset_id": "75546450841602375940945638943612150673916039892841739175120880870878769936289", "price": "0.935", "size": "45", "side": "SELL", "hash": "c3ecdddd2d7412eef5afdf96744b5bc05bbd8227", "best_bid": "0.011", "best_ask": "0.109"}], "timestamp": "1769385022372", "event_type": "price_change"}}
{"_local_timestamp": "2026-01-25T23:50:24.850248+00:00", "data": {"market": "0xe39845e9efee80761e2e9e89d579f8b943a29233153f3ed148f8d84637bea6b7", "price_changes": [{"asset_id": "6336829643612419106262092052749783689174278821109708845497505799770380553013", "price": "0.15", "size": "30.48", "side": "BUY", "hash": "0ddadc0ce82fc4db13419b5612a9e3a7ea41dc91", "best_bid": "0.15", "best_ask": "0.88"}, {"asset_id": "12787908846201818836113906836317537483609531613584477341982605123655773837316", "price": "0.85", "size": "30.48", "side": "SELL", "hash": "355ef95474e632970e03baac29ceebd5177f32d5", "best_bid": "0.12", "best_ask": "0.85"}], "timestamp": "1769385024708", "event_type": "price_change"}}
{"_local_timestamp": "2026-01-25T23:50:25.822147+00:00", "data": {"market": "0xca595a16069e6cd9bce150ecd5cec487b848d9040412547c88e87553af24f620", "price_changes": [{"asset_id": "9819058864821277493601798917843605870759192694393888839422379886017252447851", "price": "0.06", "size": "0", "side": "BUY", "hash": "f080927f960b6924b661c9c3748e9cbb237317ce", "best_bid": "0.614", "best_ask": "0.989"}, {"asset_id": "7800079113080185862147430423231593667955784347592918745149791674372792278395", "price": "0.94", "size": "0", "side": "SELL", "hash": "9e50decf69c0fa1a61fe5c37f96319fcfb185d10", "best_bid": "0.011", "best_ask": "0.386"}], "timestamp": "1769385025664", "event_type": "price_change"}}
{"_local_timestamp": "2026-01-25T23:50:26.450940+00:00", "data": {"market": "0xca595a16069e6cd9bce150ecd5cec487b848d9040412547c88e87553af24f620", "price_changes": [{"asset_id": "9819058864821277493601798917843605870759192694393888839422379886017252447851", "price": "0.057", "size": "13.31", "side": "BUY", "hash": "8abd231c725895d5e5759789edb5f639f460987f", "best_bid": "0.614", "best_ask": "0.989"}, {"asset_id": "7800079113080185862147430423231593667955784347592918745149791674372792278395", "price": "0.943", "size": "13.31", "side": "SELL", "hash": "e9b1d2c964b0772e34a6a279a3a09f8d9cb733e1", "best_bid": "0.011", "best_ask": "0.386"}], "timestamp": "1769385026311", "event_type": "price_change"}}
{"_local_timestamp": "2026-01-25T23:50:30.171635+00:00", "data": {"market": "0x03c42aea715bf13ec60b6dc0dc0a401ad83fb853de3b320d91101b9a636c6026", "price_changes": [{"asset_id": "67310272555621311553232013859863871375723980292304081825420100284982881301079", "price": "0.01", "size": "15.2", "side": "BUY", "hash": "c0b83a7b9b5d852dbf0f7d678319adec3c2ebdf0", "best_bid": "0.24", "best_ask": "0.97"}, {"asset_id": "25639330389011308493516542271565374194456752331098963441806069638079251368536", "price": "0.99", "size": "15.2", "side": "SELL", "hash": "d805a63b78f0b4378bdeadf92fe5957098fb27f0", "best_bid": "0.03", "best_ask": "0.76"}], "timestamp": "1769385029989", "event_type": "price_change"}}
{"_local_timestamp": "2026-01-25T23:50:30.176993+00:00", "data": {"market": "0x027559a14e432690257e412f18d237574155f4aebeee941382423d01c65ba37c", "price_changes": [{"asset_id": "29656649254811448219539439958370239248598869163495679625271035829447755371901", "price": "0.064", "size": "0", "side": "BUY", "hash": "1ecbbad23c4e683f559daa5d0c2ec31e2c1a44e9", "best_bid": "0.891", "best_ask": "0.989"}, {"asset_id": "75546450841602375940945638943612150673916039892841739175120880870878769936289", "price": "0.936", "size": "0", "side": "SELL", "hash": "d3722ac722e7fce973c05f54052ae57447b72696", "best_bid": "0.011", "best_ask": "0.109"}], "timestamp": "1769385029989", "event_type": "price_change"}}
{"_local_timestamp": "2026-01-25T23:50:30.420077+00:00", "data": {"market": "0x027559a14e432690257e412f18d237574155f4aebeee941382423d01c65ba37c", "price_changes": [{"asset_id": "29656649254811448219539439958370239248598869163495679625271035829447755371901", "price": "0.066", "size": "10.81", "side": "BUY", "hash": "ced7be56834183c911c29b24d625042657b7253f", "best_bid": "0.891", "best_ask": "0.989"}, {"asset_id": "75546450841602375940945638943612150673916039892841739175120880870878769936289", "price": "0.934", "size": "10.81", "side": "SELL", "hash": "de4ab64a06332f715791529052aebb83e8547dae", "best_bid": "0.011", "best_ask": "0.109"}], "timestamp": "1769385030234", "event_type": "price_change"}}
{"_local_timestamp": "2026-01-25T23:50:30.420853+00:00", "data": {"market": "0x03c42aea715bf13ec60b6dc0dc0a401ad83fb853de3b320d91101b9a636c6026", "price_changes": [{"asset_id": "67310272555621311553232013859863871375723980292304081825420100284982881301079", "price": "0.01", "size": "22.64", "side": "BUY", "hash": "2cb3647aaa99dd759c8bdd46e1ab5e2cb450ef9d", "best_bid": "0.24", "best_ask": "0.97"}, {"asset_id": "25639330389011308493516542271565374194456752331098963441806069638079251368536", "price": "0.99", "size": "22.64", "side": "SELL", "hash": "387fe462b4ccb25862fac739c684c775574e2a0e", "best_bid": "0.03", "best_ask": "0.76"}], "timestamp": "1769385030235", "event_type": "price_change"}}
{"_local_timestamp": "2026-01-25T23:51:07.810012+00:00", "data": {"market": "0x8c51633514afb3a854cb9f5248327ed2d6830d40b68cf23a62866a6e0cd286a0", "price_changes": [{"asset_id": "71178880545288091437751776636766820229347337814001501090420774267960283440681", "price": "0.1", "size": "300", "side": "BUY", "hash": "0b2a0c3aaddaeabef7efa86906b888cc848213a6", "best_bid": "0.5", "best_ask": "0.88"}, {"asset_id": "7684238634255493981133898590426067650024910633947701282528239993143961130595", "price": "0.9", "size": "300", "side": "SELL", "hash": "bd121e03c60bc085574acc64d4e59307a944f47e", "best_bid": "0.12", "best_ask": "0.5"}], "timestamp": "1769385067724", "event_type": "price_change"}}
{"_local_timestamp": "2026-01-25T23:51:08.148397+00:00", "data": {"market": "0x8c51633514afb3a854cb9f5248327ed2d6830d40b68cf23a62866a6e0cd286a0", "price_changes": [{"asset_id": "71178880545288091437751776636766820229347337814001501090420774267960283440681", "price": "0.07", "size": "100", "side": "BUY", "hash": "098a957f0b1d9f1bcd71a72b80f679b6cae7c317", "best_bid": "0.5", "best_ask": "0.88"}, {"asset_id": "7684238634255493981133898590426067650024910633947701282528239993143961130595", "price": "0.93", "size": "100", "side": "SELL", "hash": "2ce2a507036a0f6c5fa3f0f2f6a5e34832a0a512", "best_bid": "0.12", "best_ask": "0.5"}], "timestamp": "1769385068008", "event_type": "price_change"}}
