{"_local_timestamp": "2026-01-25T23:40:32.307680+00:00", "data": [{"market": "0x1a65d4eb8ac985309e78b48906291fffbf137cee590d8d75365f77a0549e9ab9", "asset_id": "48953332818425460061045724981972442660997032539861914953015827526728376958623", "timestamp": "1769384424438", "hash": "eac5f7320454dbfdf61e0d91a7630323205b893a", "bids": [{"price": "0.01", "size": "35.88"}, {"price": "0.05", "size": "500"}, {"price": "0.06", "size": "200"}, {"price": "0.07", "size": "100"}, {"price": "0.08", "size": "25"}, {"price": "0.09", "size": "6.96"}, {"price": "0.1", "size": "70"}, {"price": "0.13", "size": "50"}, {"price": "0.2", "size": "65"}, {"price": "0.21", "size": "52.38"}, {"price": "0.23", "size": "40"}, {"price": "0.27", "size": "30.6"}, {"price": "0.29", "size": "14"}], "asks": [{"price": "0.99", "size": "5009.94"}, {"price": "0.98", "size": "2200"}, {"price": "0.97", "size": "6.96"}, {"price": "0.95", "size": "300"}, {"price": "0.93", "size": "1314.28"}, {"price": "0.92", "size": "8.64"}, {"price": "0.89", "size": "634.09"}, {"price": "0.86", "size": "228.57"}, {"price": "0.82", "size": "405.55"}, {"price": "0.79", "size": "123.8"}, {"price": "0.75", "size": "276"}, {"price": "0.74", "size": "66.66"}, {"price": "0.73", "size": "33"}, {"price": "0.72", "size": "71.42"}, {"price": "0.71", "size": "20"}, {"price": "0.54", "size": "66.66"}, {"price": "0.5", "size": "249.41"}, {"price": "0.49", "size": "10"}, {"price": "0.45", "size": "10"}, {"price": "0.42", "size": "22.41"}, {"price": "0.41", "size": "18.64"}, {"price": "0.35", "size": "28.9"}, {"price": "0.34", "size": "34.45"}, {"price": "0.33", "size": "88.56"}], "event_type": "book", "last_trade_price": "0.290"}, {"market": "0x6e7f9ca2cf14c89b5c43186b391636fe3257b6e54561af8435690c8e558a7739", "asset_id": "82755084359634849674252481148838131111405532948015666509786048268534735617431", "timestamp": "1769384058238", "hash": "8038f6576d6c9c1c785c753c37ed80902917a9e4", "bids": [{"price": "0.01", "size": "5126.72"}, {"price": "0.02", "size": "1700"}, {"price": "0.03", "size": "11.2"}, {"price": "0.05", "size": "2220"}, {"price": "0.06", "size": "50"}, {"price": "0.07", "size": "330"}, {"price": "0.08", "size": "725"}, {"price": "0.1", "size": "320"}, {"price": "0.11", "size": "5.06"}, {"price": "0.12", "size": "558.33"}, {"price": "0.15", "size": "173.33"}, {"price": "0.16", "size": "130"}, {"price": "0.17", "size": "141.17"}, {"price": "0.18", "size": "66.66"}, {"price": "0.2", "size": "100"}, {"price": "0.21", "size": "9"}, {"price": "0.27", "size": "20"}, {"price": "0.3", "size": "40"}, {"price": "0.31", "size": "66.66"}, {"price": "0.33", "size": "5"}, {"price": "0.34", "size": "6"}, {"price": "0.35", "size": "20"}, {"price": "0.36", "size": "42.11"}, {"price": "0.37", "size": "29.72"}, {"price": "0.38", "size": "6"}, {"price": "0.4", "size": "112.5"}, {"price": "0.41", "size": "5"}, {"price": "0.42", "size": "6"}, {"price": "0.44", "size": "30"}, {"price": "0.45", "size": "96.66"}, {"price": "0.46", "size": "11.86"}], "asks": [{"price": "0.99", "size": "1090.44"}, {"price": "0.98", "size": "200"}, {"price": "0.97", "size": "10.85"}, {"price": "0.95", "size": "1420"}, {"price": "0.94", "size": "70"}, {"price": "0.92", "size": "425"}, {"price": "0.91", "size": "200"}, {"price": "0.9", "size": "190"}, {"price": "0.89", "size": "336.08"}, {"price": "0.86", "size": "200"}, {"price": "0.83", "size": "152.94"}, {"price": "0.81", "size": "126.31"}, {"price": "0.8", "size": "140.89"}, {"price": "0.79", "size": "80"}, {"price": "0.78", "size": "90.9"}, {"price": "0.7", "size": "50"}, {"price": "0.69", "size": "40"}, {"price": "0.67", "size": "50"}, {"price": "0.65", "size": "40.89"}, {"price": "0.64", "size": "6"}, {"price": "0.6", "size": "30"}, {"price": "0.59", "size": "37.7"}, {"price": "0.58", "size": "14.33"}, {"price": "0.57", "size": "6"}, {"price": "0.55", "size": "20"}, {"price": "0.53", "size": "41.19"}, {"price": "0.51", "size": "25"}, {"price": "0.5", "size": "40.89"}], "event_type": "book", "last_trade_price": "0.480"}, {"market": "0x0a9f1c94b012a39a2a91b877b24c15f25ffd1ee68df65a79c12e5fac82519865", "asset_id": "92197810663257226642496081056291543161006633887475519374142132133821877068692", "timestamp": "1769384422087", "hash": "74e54220856b2fe156844f3fcbf4061b3df09952", "bids": [{"price": "0.01", "size": "5059.84"}, {"price": "0.02", "size": "2025"}, {"price": "0.03", "size": "9.18"}, {"price": "0.05", "size": "320"}, {"price": "0.06", "size": "33"}, {"price": "0.09", "size": "1000"}, {"price": "0.1", "size": "6.26"}, {"price": "0.14", "size": "747.85"}, {"price": "0.19", "size": "418.42"}, {"price": "0.24", "size": "316.66"}, {"price": "0.25", "size": "8"}, {"price": "0.27", "size": "50"}, {"price": "0.29", "size": "89.65"}, {"price": "0.33", "size": "72.72"}, {"price": "0.38", "size": "177.63"}, {"price": "0.65", "size": "1989.58"}, {"price": "0.68", "size": "66.66"}, {"price": "0.7", "size": "134.5"}, {"price": "0.71", "size": "299.99"}, {"price": "0.78", "size": "66.66"}, {"price": "0.86", "size": "35.28"}, {"price": "0.87", "size": "20"}, {"price": "0.88", "size": "66.66"}], "asks": [{"price": "0.99", "size": "635"}, {"price": "0.98", "size": "291.14"}, {"price": "0.97", "size": "316.66"}, {"price": "0.96", "size": "73.95"}, {"price": "0.95", "size": "10"}, {"price": "0.94", "size": "73.08"}], "event_type": "book", "last_trade_price": ""}, {"market": "0x2a4d3cf51d27425b0c51d241a7ba6bc44dd27034b44f9e437624f9e0953b1ea9", "asset_id": "58599269208124653793682124721644272657448822176028066253503704155842141815443", "timestamp": "1769384372436", "hash": "7d9956ad1a193ff0c02582b4f152bdd9394c6253", "bids": [{"price": "0.01", "size": "5555"}, {"price": "0.02", "size": "506.24"}, {"price": "0.03", "size": "16"}, {"price": "0.04", "size": "2607.64"}, {"price": "0.05", "size": "70"}, {"price": "0.06", "size": "566.66"}, {"price": "0.07", "size": "457.14"}, {"price": "0.09", "size": "311.11"}, {"price": "0.1", "size": "65.69"}, {"price": "0.11", "size": "236.36"}, {"price": "0.12", "size": "400"}, {"price": "0.13", "size": "184.61"}, {"price": "0.14", "size": "217"}, {"price": "0.15", "size": "213.33"}, {"price": "0.2", "size": "40"}, {"price": "0.22", "size": "40"}, {"price": "0.23", "size": "40"}, {"price": "0.24", "size": "240"}, {"price": "0.25", "size": "65.2"}, {"price": "0.26", "size": "56"}, {"price": "0.27", "size": "40.74"}, {"price": "0.28", "size": "6"}, {"price": "0.3", "size": "126"}, {"price": "0.31", "size": "15.2"}, {"price": "0.32", "size": "28"}, {"price": "0.33", "size": "69"}, {"price": "0.37", "size": "6.66"}], "asks": [{"price": "0.99", "size": "5065.36"}, {"price": "0.98", "size": "2000"}, {"price": "0.97", "size": "16"}, {"price": "0.96", "size": "5.4"}, {"price": "0.94", "size": "1400"}, {"price": "0.93", "size": "300"}, {"price": "0.9", "size": "340"}, {"price": "0.89", "size": "5.73"}, {"price": "0.87", "size": "571.15"}, {"price": "0.86", "size": "30"}, {"price": "0.84", "size": "175"}, {"price": "0.82", "size": "457"}, {"price": "0.8", "size": "180"}, {"price": "0.79", "size": "9"}, {"price": "0.77", "size": "104.34"}, {"price": "0.74", "size": "76.92"}, {"price": "0.73", "size": "150"}, {"price": "0.52", "size": "500"}, {"price": "0.5", "size": "26"}, {"price": "0.49", "size": "27.56"}, {"price": "0.48", "size": "500"}, {"price": "0.47", "size": "72.66"}, {"price": "0.45", "size": "100"}, {"price": "0.44", "size": "6"}, {"price": "0.43", "size": "66.66"}, {"price": "0.41", "size": "77"}, {"price": "0.38", "size": "72.45"}], "event_type": "book", "last_trade_price": "0.350"}, {"market": "0x7f6dadade6357d3ce6681860d002bd3521554aba8b5acda912917b3db41c9549", "asset_id": "50613703516194910329561493534058464924948966095615247532634099427569284124317", "timestamp": "1769384422041", "hash": "3b3d58955ba97616cec1ada4ca1851a80b16cc4f", "bids": [{"price": "0.01", "size": "508.25"}, {"price": "0.02", "size": "550"}, {"price": "0.03", "size": "11.65"}, {"price": "0.04", "size": "97.34"}, {"price": "0.05", "size": "202"}, {"price": "0.07", "size": "80"}, {"price": "0.08", "size": "30"}, {"price": "0.09", "size": "35.12"}, {"price": "0.1", "size": "36.73"}, {"price": "0.12", "size": "100"}, {"price": "0.14", "size": "92.85"}, {"price": "0.15", "size": "73.33"}, {"price": "0.16", "size": "347.66"}, {"price": "0.18", "size": "46"}, {"price": "0.19", "size": "86.66"}, {"price": "0.21", "size": "50.41"}, {"price": "0.22", "size": "96.66"}], "asks": [{"price": "0.99", "size": "4010.58"}, {"price": "0.98", "size": "1000"}, {"price": "0.97", "size": "7.9"}, {"price": "0.95", "size": "1210"}, {"price": "0.92", "size": "450"}, {"price": "0.91", "size": "7.3"}, {"price": "0.88", "size": "283.33"}, {"price": "0.84", "size": "200"}, {"price": "0.8", "size": "140"}, {"price": "0.78", "size": "60"}, {"price": "0.77", "size": "24.8"}, {"price": "0.76", "size": "108.33"}, {"price": "0.75", "size": "8.89"}, {"price": "0.72", "size": "85.71"}, {"price": "0.71", "size": "42"}, {"price": "0.68", "size": "62.5"}, {"price": "0.67", "size": "6"}, {"price": "0.52", "size": "8.89"}, {"price": "0.49", "size": "6"}, {"price": "0.43", "size": "10"}, {"price": "0.39", "size": "6"}, {"price": "0.38", "size": "20.96"}, {"price": "0.37", "size": "17.46"}, {"price": "0.3", "size": "79.94"}, {"price": "0.29", "size": "6.55"}, {"price": "0.28", "size": "8.89"}], "event_type": "book", "last_trade_price": "0.710"}, {"market": "0x0a9f1c94b012a39a2a91b877b24c15f25ffd1ee68df65a79c12e5fac82519865", "asset_id": "73641960431177563453506958377488026157202817565843589479879428094129866219922", "timestamp": "1769384422087", "hash": "b93871a8cb69e46f166e59e9daefa8de0cb5b9c1", "bids": [{"price": "0.01", "size": "635"}, {"price": "0.02", "size": "291.14"}, {"price": "0.03", "size": "316.66"}, {"price": "0.04", "size": "73.95"}, {"price": "0.05", "size": "10"}, {"price": "0.06", "size": "73.08"}], "asks": [{"price": "0.99", "size": "5059.84"}, {"price": "0.98", "size": "2025"}, {"price": "0.97", "size": "9.18"}, {"price": "0.95", "size": "320"}, {"price": "0.94", "size": "33"}, {"price": "0.91", "size": "1000"}, {"price": "0.9", "size": "6.26"}, {"price": "0.86", "size": "747.85"}, {"price": "0.81", "size": "418.42"}, {"price": "0.76", "size": "316.66"}, {"price": "0.75", "size": "8"}, {"price": "0.73", "size": "50"}, {"price": "0.71", "size": "89.65"}, {"price": "0.67", "size": "72.72"}, {"price": "0.62", "size": "177.63"}, {"price": "0.35", "size": "1989.58"}, {"price": "0.32", "size": "66.66"}, {"price": "0.3", "size": "134.5"}, {"price": "0.29", "size": "299.99"}, {"price": "0.22", "size": "66.66"}, {"price": "0.14", "size": "35.28"}, {"price": "0.13", "size": "20"}, {"price": "0.12", "size": "66.66"}], "event_type": "book", "last_trade_price": ""}, {"market": "0x7f6dadade6357d3ce6681860d002bd3521554aba8b5acda912917b3db41c9549", "asset_id": "112538531010841097813690615473978896934576951101485955663285389253633812461690", "timestamp": "1769384422041", "hash": "45e93d51e866b37d8fcebbe1d197d38977463dc5", "bids": [{"price": "0.01", "size": "4010.58"}, {"price": "0.02", "size": "1000"}, {"price": "0.03", "size": "7.9"}, {"price": "0.05", "size": "1210"}, {"price": "0.08", "size": "450"}, {"price": "0.09", "size": "7.3"}, {"price": "0.12", "size": "283.33"}, {"price": "0.16", "size": "200"}, {"price": "0.2", "size": "140"}, {"price": "0.22", "size": "60"}, {"price": "0.23", "size": "24.8"}, {"price": "0.24", "size": "108.33"}, {"price": "0.25", "size": "8.89"}, {"price": "0.28", "size": "85.71"}, {"price": "0.29", "size": "42"}, {"price": "0.32", "size": "62.5"}, {"price": "0.33", "size": "6"}, {"price": "0.48", "size": "8.89"}, {"price": "0.51", "size": "6"}, {"price": "0.57", "size": "10"}, {"price": "0.61", "size": "6"}, {"price": "0.62", "size": "20.96"}, {"price": "0.63", "size": "17.46"}, {"price": "0.7", "size": "79.94"}, {"price": "0.71", "size": "6.55"}, {"price": "0.72", "size": "8.89"}], "asks": [{"price": "0.99", "size": "508.25"}, {"price": "0.98", "size": "550"}, {"price": "0.97", "size": "11.65"}, {"price": "0.96", "size": "97.34"}, {"price": "0.95", "size": "202"}, {"price": "0.93", "size": "80"}, {"price": "0.92", "size": "30"}, {"price": "0.91", "size": "35.12"}, {"price": "0.9", "size": "36.73"}, {"price": "0.88", "size": "100"}, {"price": "0.86", "size": "92.85"}, {"price": "0.85", "size": "73.33"}, {"price": "0.84", "size": "347.66"}, {"price": "0.82", "size": "46"}, {"price": "0.81", "size": "86.66"}, {"price": "0.79", "size": "50.41"}, {"price": "0.78", "size": "96.66"}], "event_type": "book", "last_trade_price": "0.710"}, {"market": "0x6e7f9ca2cf14c89b5c43186b391636fe3257b6e54561af8435690c8e558a7739", "asset_id": "110521490407244651910529066817229252112184013255539741084760915210186176250537", "timestamp": "1769384058238", "hash": "aeb18ce53e2d3b0dc9fc04ddf5bea4ee0af623ab", "bids": [{"price": "0.01", "size": "1090.44"}, {"price": "0.02", "size": "200"}, {"price": "0.03", "size": "10.85"}, {"price": "0.05", "size": "1420"}, {"price": "0.06", "size": "70"}, {"price": "0.08", "size": "425"}, {"price": "0.09", "size": "200"}, {"price": "0.1", "size": "190"}, {"price": "0.11", "size": "336.08"}, {"price": "0.14", "size": "200"}, {"price": "0.17", "size": "152.94"}, {"price": "0.19", "size": "126.31"}, {"price": "0.2", "size": "140.89"}, {"price": "0.21", "size": "80"}, {"price": "0.22", "size": "90.9"}, {"price": "0.3", "size": "50"}, {"price": "0.31", "size": "40"}, {"price": "0.33", "size": "50"}, {"price": "0.35", "size": "40.89"}, {"price": "0.36", "size": "6"}, {"price": "0.4", "size": "30"}, {"price": "0.41", "size": "37.7"}, {"price": "0.42", "size": "14.33"}, {"price": "0.43", "size": "6"}, {"price": "0.45", "size": "20"}, {"price": "0.47", "size": "41.19"}, {"price": "0.49", "size": "25"}, {"price": "0.5", "size": "40.89"}], "asks": [{"price": "0.99", "size": "5126.72"}, {"price": "0.98", "size": "1700"}, {"price": "0.97", "size": "11.2"}, {"price": "0.95", "size": "2220"}, {"price": "0.94", "size": "50"}, {"price": "0.93", "size": "330"}, {"price": "0.92", "size": "725"}, {"price": "0.9", "size": "320"}, {"price": "0.89", "size": "5.06"}, {"price": "0.88", "size": "558.33"}, {"price": "0.85", "size": "173.33"}, {"price": "0.84", "size": "130"}, {"price": "0.83", "size": "141.17"}, {"price": "0.82", "size": "66.66"}, {"price": "0.8", "size": "100"}, {"price": "0.79", "size": "9"}, {"price": "0.73", "size": "20"}, {"price": "0.7", "size": "40"}, {"price": "0.69", "size": "66.66"}, {"price": "0.67", "size": "5"}, {"price": "0.66", "size": "6"}, {"price": "0.65", "size": "20"}, {"price": "0.64", "size": "42.11"}, {"price": "0.63", "size": "29.72"}, {"price": "0.62", "size": "6"}, {"price": "0.6", "size": "112.5"}, {"price": "0.59", "size": "5"}, {"price": "0.58", "size": "6"}, {"price": "0.56", "size": "30"}, {"price": "0.55", "size": "96.66"}, {"price": "0.54", "size": "11.86"}], "event_type": "book", "last_trade_price": "0.480"}, {"market": "0xcc63b656fcb3d80cc37ba73293a0dd41cedfc6113824a7eabc0ea44d47f2e3fb", "asset_id": "53785304590806186448100532051603643727400986103975240944527899277602345885656", "timestamp": "1769384191616", "hash": "96be8280fa1ee06eff5c1db312b1d3aaa249f956", "bids": [{"price": "0.001", "size": "14983"}, {"price": "0.002", "size": "4726"}, {"price": "0.003", "size": "769.83"}], "asks": [{"price": "0.999", "size": "7063.08"}, {"price": "0.998", "size": "3755.04"}, {"price": "0.997", "size": "1400"}, {"price": "0.996", "size": "8.63"}, {"price": "0.994", "size": "200"}, {"price": "0.99", "size": "5000"}, {"price": "0.989", "size": "8.38"}, {"price": "0.98", "size": "2498.97"}, {"price": "0.97", "size": "150"}, {"price": "0.969", "size": "8.35"}, {"price": "0.95", "size": "330"}, {"price": "0.949", "size": "39"}, {"price": "0.93", "size": "300"}, {"price": "0.9", "size": "860"}, {"price": "0.899", "size": "5.93"}, {"price": "0.85", "size": "551.66"}, {"price": "0.828", "size": "20"}, {"price": "0.8", "size": "460"}, {"price": "0.799", "size": "155"}, {"price": "0.75", "size": "112"}, {"price": "0.728", "size": "5.61"}, {"price": "0.7", "size": "286.66"}, {"price": "0.65", "size": "68.57"}, {"price": "0.6", "size": "175"}, {"price": "0.599", "size": "5"}, {"price": "0.25", "size": "431.09"}, {"price": "0.198", "size": "10"}, {"price": "0.049", "size": "300"}, {"price": "0.04", "size": "431.08"}, {"price": "0.034", "size": "7.57"}, {"price": "0.032", "size": "1018.6"}, {"price": "0.027", "size": "0.11"}, {"price": "0.026", "size": "1000"}, {"price": "0.02", "size": "300"}, {"price": "0.015", "size": "1074.9"}, {"price": "0.014", "size": "381.92"}, {"price": "0.013", "size": "241.83"}, {"price": "0.012", "size": "36"}, {"price": "0.011", "size": "25.34"}, {"price": "0.006", "size": "15"}, {"price": "0.005", "size": "5"}, {"price": "0.004", "size": "11.03"}], "event_type": "book", "last_trade_price": "0.004"}, {"market": "0x2a4d3cf51d27425b0c51d241a7ba6bc44dd27034b44f9e437624f9e0953b1ea9", "asset_id": "111798086980787121079742248333092569415172137759139099190565410999420761499752", "timestamp": "1769384372436", "hash": "1adae57467adcf809621e50bd94a30694c474e9b", "bids": [{"price": "0.01", "size": "5065.36"}, {"price": "0.02", "size": "2000"}, {"price": "0.03", "size": "16"}, {"price": "0.04", "size": "5.4"}, {"price": "0.06", "size": "1400"}, {"price": "0.07", "size": "300"}, {"price": "0.1", "size": "340"}, {"price": "0.11", "size": "5.73"}, {"price": "0.13", "size": "571.15"}, {"price": "0.14", "size": "30"}, {"price": "0.16", "size": "175"}, {"price": "0.18", "size": "457"}, {"price": "0.2", "size": "180"}, {"price": "0.21", "size": "9"}, {"price": "0.23", "size": "104.34"}, {"price": "0.26", "size": "76.92"}, {"price": "0.27", "size": "150"}, {"price": "0.48", "size": "500"}, {"price": "0.5", "size": "26"}, {"price": "0.51", "size": "27.56"}, {"price": "0.52", "size": "500"}, {"price": "0.53", "size": "72.66"}, {"price": "0.55", "size": "100"}, {"price": "0.56", "size": "6"}, {"price": "0.57", "size": "66.66"}, {"price": "0.59", "size": "77"}, {"price": "0.62", "size": "72.45"}], "asks": [{"price": "0.99", "size": "5555"}, {"price": "0.98", "size": "506.24"}, {"price": "0.97", "size": "16"}, {"price": "0.96", "size": "2607.64"}, {"price": "0.95", "size": "70"}, {"price": "0.94", "size": "566.66"}, {"price": "0.93", "size": "457.14"}, {"price": "0.91", "size": "311.11"}, {"price": "0.9", "size": "65.69"}, {"price": "0.89", "size": "236.36"}, {"price": "0.88", "size": "400"}, {"price": "0.87", "size": "184.61"}, {"price": "0.86", "size": "217"}, {"price": "0.85", "size": "213.33"}, {"price": "0.8", "size": "40"}, {"price": "0.78", "size": "40"}, {"price": "0.77", "size": "40"}, {"price": "0.76", "size": "240"}, {"price": "0.75", "size": "65.2"}, {"price": "0.74", "size": "56"}, {"price": "0.73", "size": "40.74"}, {"price": "0.72", "size": "6"}, {"price": "0.7", "size": "126"}, {"price": "0.69", "size": "15.2"}, {"price": "0.68", "size": "28"}, {"price": "0.67", "size": "69"}, {"price": "0.63", "size": "6.66"}], "event_type": "book", "last_trade_price": "0.350"}, {"market": "0x1a65d4eb8ac985309e78b48906291fffbf137cee590d8d75365f77a0549e9ab9", "asset_id": "81870625725474135545086561756714985203836689747059214375533433096496527904265", "timestamp": "1769384424438", "hash": "585043e54f04ab0be626bbae520f521f4eb3be40", "bids": [{"price": "0.01", "size": "5009.94"}, {"price": "0.02", "size": "2200"}, {"price": "0.03", "size": "6.96"}, {"price": "0.05", "size": "300"}, {"price": "0.07", "size": "1314.28"}, {"price": "0.08", "size": "8.64"}, {"price": "0.11", "size": "634.09"}, {"price": "0.14", "size": "228.57"}, {"price": "0.18", "size": "405.55"}, {"price": "0.21", "size": "123.8"}, {"price": "0.25", "size": "276"}, {"price": "0.26", "size": "66.66"}, {"price": "0.27", "size": "33"}, {"price": "0.28", "size": "71.42"}, {"price": "0.29", "size": "20"}, {"price": "0.46", "size": "66.66"}, {"price": "0.5", "size": "249.41"}, {"price": "0.51", "size": "10"}, {"price": "0.55", "size": "10"}, {"price": "0.58", "size": "22.41"}, {"price": "0.59", "size": "18.64"}, {"price": "0.65", "size": "28.9"}, {"price": "0.66", "size": "34.45"}, {"price": "0.67", "size": "88.56"}], "asks": [{"price": "0.99", "size": "35.88"}, {"price": "0.95", "size": "500"}, {"price": "0.94", "size": "200"}, {"price": "0.93", "size": "100"}, {"price": "0.92", "size": "25"}, {"price": "0.91", "size": "6.96"}, {"price": "0.9", "size": "70"}, {"price": "0.87", "size": "50"}, {"price": "0.8", "size": "65"}, {"price": "0.79", "size": "52.38"}, {"price": "0.77", "size": "40"}, {"price": "0.73", "size": "30.6"}, {"price": "0.71", "size": "14"}], "event_type": "book", "last_trade_price": "0.290"}, {"market": "0xcc63b656fcb3d80cc37ba73293a0dd41cedfc6113824a7eabc0ea44d47f2e3fb", "asset_id": "78320823329062661687268056381693199301492237595012271766902388562197668380032", "timestamp": "1769384191616", "hash": "7440c71802bc6d2543fff5a3054dcec320250248", "bids": [{"price": "0.001", "size": "7063.08"}, {"price": "0.002", "size": "3755.04"}, {"price": "0.003", "size": "1400"}, {"price": "0.004", "size": "8.63"}, {"price": "0.006", "size": "200"}, {"price": "0.01", "size": "5000"}, {"price": "0.011", "size": "8.38"}, {"price": "0.02", "size": "2498.97"}, {"price": "0.03", "size": "150"}, {"price": "0.031", "size": "8.35"}, {"price": "0.05", "size": "330"}, {"price": "0.051", "size": "39"}, {"price": "0.07", "size": "300"}, {"price": "0.1", "size": "860"}, {"price": "0.101", "size": "5.93"}, {"price": "0.15", "size": "551.66"}, {"price": "0.172", "size": "20"}, {"price": "0.2", "size": "460"}, {"price": "0.201", "size": "155"}, {"price": "0.25", "size": "112"}, {"price": "0.272", "size": "5.61"}, {"price": "0.3", "size": "286.66"}, {"price": "0.35", "size": "68.57"}, {"price": "0.4", "size": "175"}, {"price": "0.401", "size": "5"}, {"price": "0.75", "size": "431.09"}, {"price": "0.802", "size": "10"}, {"price": "0.951", "size": "300"}, {"price": "0.96", "size": "431.08"}, {"price": "0.966", "size": "7.57"}, {"price": "0.968", "size": "1018.6"}, {"price": "0.973", "size": "0.11"}, {"price": "0.974", "size": "1000"}, {"price": "0.98", "size": "300"}, {"price": "0.985", "size": "1074.9"}, {"price": "0.986", "size": "381.92"}, {"price": "0.987", "size": "241.83"}, {"price": "0.988", "size": "36"}, {"price": "0.989", "size": "25.34"}, {"price": "0.994", "size": "15"}, {"price": "0.995", "size": "5"}, {"price": "0.996", "size": "11.03"}], "asks": [{"price": "0.999", "size": "14983"}, {"price": "0.998", "size": "4726"}, {"price": "0.997", "size": "769.83"}], "event_type": "book", "last_trade_price": "0.004"}]}
{"_local_timestamp": "2026-01-25T23:40:40.770176+00:00", "data": {"market": "0x7f6dadade6357d3ce6681860d002bd3521554aba8b5acda912917b3db41c9549", "price_changes": [{"asset_id": "112538531010841097813690615473978896934576951101485955663285389253633812461690", "price": "0.12", "size": "408.33", "side": "BUY", "hash": "a1eb66598898150f587bc08594e95bf38f7a61fe", "best_bid": "0.72", "best_ask": "0.78"}, {"asset_id": "50613703516194910329561493534058464924948966095615247532634099427569284124317", "price": "0.88", "size": "408.33", "side": "SELL", "hash": "f79df39aa550cfa256841670b7f1e60bd1f2d685", "best_bid": "0.22", "best_ask": "0.28"}], "timestamp": "1769384440587", "event_type": "price_change"}}
{"_local_timestamp": "2026-01-25T23:40:40.829809+00:00", "data": {"market": "0x7f6dadade6357d3ce6681860d002bd3521554aba8b5acda912917b3db41c9549", "price_changes": [{"asset_id": "112538531010841097813690615473978896934576951101485955663285389253633812461690", "price": "0.24", "size": "158.33", "side": "BUY", "hash": "150a88137d7bf8546bc128eabddb8d152415e44e", "best_bid": "0.72", "best_ask": "0.78"}, {"asset_id": "50613703516194910329561493534058464924948966095615247532634099427569284124317", "price": "0.76", "size": "158.33", "side": "SELL", "hash": "363773f23a8110a490ed44f02c88fbedaf79d78f", "best_bid": "0.22", "best_ask": "0.28"}], "timestamp": "1769384440637", "event_type": "price_change"}}
{"_local_timestamp": "2026-01-25T23:40:40.841830+00:00", "data": {"market": "0x7f6dadade6357d3ce6681860d002bd3521554aba8b5acda912917b3db41c9549", "price_changes": [{"asset_id": "112538531010841097813690615473978896934576951101485955663285389253633812461690", "price": "0.16", "size": "300", "side": "BUY", "hash": "e5c330636472806660330e6caf7923939a15d247", "best_bid": "0.72", "best_ask": "0.78"}, {"asset_id": "50613703516194910329561493534058464924948966095615247532634099427569284124317", "price": "0.84", "size": "300", "side": "SELL", "hash": "fa4b181441de09b5a6b1404c362e27f2dc170d08", "best_bid": "0.22", "best_ask": "0.28"}], "timestamp": "1769384440662", "event_type": "price_change"}}
{"_local_timestamp": "2026-01-25T23:40:51.444755+00:00", "data": {"market": "0x1a65d4eb8ac985309e78b48906291fffbf137cee590d8d75365f77a0549e9ab9", "price_changes": [{"asset_id": "48953332818425460061045724981972442660997032539861914953015827526728376958623", "price": "0.33", "size": "66.66", "side": "SELL", "hash": "f12a3f0ec5963a35972380c9ad7addd4fb9b6226", "best_bid": "0.29", "best_ask": "0.33"}, {"asset_id": "81870625725474135545086561756714985203836689747059214375533433096496527904265", "price": "0.67", "size": "66.66", "side": "BUY", "hash": "1d961341a870bf44c7ac45e5b034bd6b25ab7773", "best_bid": "0.67", "best_ask": "0.71"}], "timestamp": "1769384451364", "event_type": "price_change"}}
{"_local_timestamp": "2026-01-25T23:40:59.495893+00:00", "data": {"market": "0x7f6dadade6357d3ce6681860d002bd3521554aba8b5acda912917b3db41c9549", "price_changes": [{"asset_id": "112538531010841097813690615473978896934576951101485955663285389253633812461690", "price": "0.08", "size": "650", "side": "BUY", "hash": "22ef323b58aefbecf278e1a89732af2be34a4266", "best_bid": "0.72", "best_ask": "0.78"}, {"asset_id": "50613703516194910329561493534058464924948966095615247532634099427569284124317", "price": "0.92", "size": "650", "side": "SELL", "hash": "22836cd5d1497347e3746b582a9717bea80990f6", "best_bid": "0.22", "best_ask": "0.28"}], "timestamp": "1769384459423", "event_type": "price_change"}}
{"_local_timestamp": "2026-01-25T23:41:03.120561+00:00", "data": {"market": "0x1a65d4eb8ac985309e78b48906291fffbf137cee590d8d75365f77a0549e9ab9", "price_changes": [{"asset_id": "48953332818425460061045724981972442660997032539861914953015827526728376958623", "price": "0.33", "size": "77.61", "side": "SELL", "hash": "ac0826969fb1a8e2442dd25c007dfae2ec1d0616", "best_bid": "0.29", "best_ask": "0.33"}, {"asset_id": "81870625725474135545086561756714985203836689747059214375533433096496527904265", "price": "0.67", "size": "77.61", "side": "BUY", "hash": "430c4d4a7a6c23df19a18ea7f3b7f69bca0e4ac5", "best_bid": "0.67", "best_ask": "0.71"}], "timestamp": "1769384463042", "event_type": "price_change"}}
{"_local_timestamp": "2026-01-25T23:41:03.121594+00:00", "data": {"market": "0x1a65d4eb8ac985309e78b48906291fffbf137cee590d8d75365f77a0549e9ab9", "price_changes": [{"asset_id": "48953332818425460061045724981972442660997032539861914953015827526728376958623", "price": "0.33", "size": "88.56", "side": "SELL", "hash": "bd09a4d0c56a4951c3a884343875cb96efbc9333", "best_bid": "0.29", "best_ask": "0.33"}, {"asset_id": "81870625725474135545086561756714985203836689747059214375533433096496527904265", "price": "0.67", "size": "88.56", "side": "BUY", "hash": "6243fb35d02632d61bb5cee3de35d962856a7322", "best_bid": "0.67", "best_ask": "0.71"}], "timestamp": "1769384463043", "event_type": "price_change"}}
{"_local_timestamp": "2026-01-25T23:41:17.969847+00:00", "data": {"market": "0x0a9f1c94b012a39a2a91b877b24c15f25ffd1ee68df65a79c12e5fac82519865", "price_changes": [{"asset_id": "73641960431177563453506958377488026157202817565843589479879428094129866219922", "price": "0.3", "size": "0", "side": "SELL", "hash": "cda991a7648193fc398dab4cada451cfec168378", "best_bid": "0.06", "best_ask": "0.12"}, {"asset_id": "92197810663257226642496081056291543161006633887475519374142132133821877068692", "price": "0.7", "size": "0", "side": "BUY", "hash": "465af83a9157173656064e60c26bebf7018927d6", "best_bid": "0.88", "best_ask": "0.94"}], "timestamp": "1769384477843", "event_type": "price_change"}}
{"_local_timestamp": "2026-01-25T23:41:18.650081+00:00", "data": {"market": "0x0a9f1c94b012a39a2a91b877b24c15f25ffd1ee68df65a79c12e5fac82519865", "price_changes": [{"asset_id": "73641960431177563453506958377488026157202817565843589479879428094129866219922", "price": "0.28", "size": "134.5", "side": "SELL", "hash": "ebe0ec8664a95127aaae9250ff9b6c356120c49d", "best_bid": "0.06", "best_ask": "0.12"}, {"asset_id": "92197810663257226642496081056291543161006633887475519374142132133821877068692", "price": "0.72", "size": "134.5", "side": "BUY", "hash": "16677fb6bd1b7de4d955425283d0066325464a36", "best_bid": "0.88", "best_ask": "0.94"}], "timestamp": "1769384478577", "event_type": "price_change"}}
{"_local_timestamp": "2026-01-25T23:41:21.376962+00:00", "data": {"market": "0x0a9f1c94b012a39a2a91b877b24c15f25ffd1ee68df65a79c12e5fac82519865", "price_changes": [{"asset_id": "73641960431177563453506958377488026157202817565843589479879428094129866219922", "price": "0.29", "size": "100", "side": "SELL", "hash": "5f9ac67d4fe081024a6b65dd7744dccdf7331e15", "best_bid": "0.06", "best_ask": "0.12"}, {"asset_id": "92197810663257226642496081056291543161006633887475519374142132133821877068692", "price": "0.71", "size": "100", "side": "BUY", "hash": "a042ad208d12eea9df76fcec6df0324c7caa9f1b", "best_bid": "0.88", "best_ask": "0.94"}], "timestamp": "1769384481309", "event_type": "price_change"}}
{"_local_timestamp": "2026-01-25T23:41:21.567104+00:00", "data": {"market": "0x0a9f1c94b012a39a2a91b877b24c15f25ffd1ee68df65a79c12e5fac82519865", "price_changes": [{"asset_id": "92197810663257226642496081056291543161006633887475519374142132133821877068692", "price": "0.71", "size": "0", "side": "BUY", "hash": "ba70f8e338991fc7fad3446613eff3d335819fe0", "best_bid": "0.88", "best_ask": "0.94"}, {"asset_id": "73641960431177563453506958377488026157202817565843589479879428094129866219922", "price": "0.29", "size": "0", "side": "SELL", "hash": "07e1ab1a5559890f65bba5091819a282f1327c54", "best_bid": "0.06", "best_ask": "0.12"}], "timestamp": "1769384481478", "event_type": "price_change"}}
{"_local_timestamp": "2026-01-25T23:41:21.740190+00:00", "data": {"market": "0x0a9f1c94b012a39a2a91b877b24c15f25ffd1ee68df65a79c12e5fac82519865", "price_changes": [{"asset_id": "73641960431177563453506958377488026157202817565843589479879428094129866219922", "price": "0.31", "size": "199.99", "side": "SELL", "hash": "e6a2c1902f360f2d80baf8ecc1dc50d97feb2dd7", "best_bid": "0.06", "best_ask": "0.12"}, {"asset_id": "92197810663257226642496081056291543161006633887475519374142132133821877068692", "price": "0.69", "size": "199.99", "side": "BUY", "hash": "5f387bb5e64aa21fb63fc4608298524e36cbb515", "best_bid": "0.88", "best_ask": "0.94"}], "timestamp": "1769384481668", "event_type": "price_change"}}
{"_local_timestamp": "2026-01-25T23:41:22.190522+00:00", "data": {"market": "0x0a9f1c94b012a39a2a91b877b24c15f25ffd1ee68df65a79c12e5fac82519865", "price_changes": [{"asset_id": "92197810663257226642496081056291543161006633887475519374142132133821877068692", "price": "0.69", "size": "299.99", "side": "BUY", "hash": "52901ad3264d93941778a59237f3234801ab1631", "best_bid": "0.88", "best_ask": "0.94"}, {"asset_id": "73641960431177563453506958377488026157202817565843589479879428094129866219922", "price": "0.31", "size": "299.99", "side": "SELL", "hash": "5fbd977931a18502f96e593e60270b743acb7e82", "best_bid": "0.06", "best_ask": "0.12"}], "timestamp": "1769384482119", "event_type": "price_change"}}
{"_local_timestamp": "2026-01-25T23:41:29.612253+00:00", "data": {"market": "0x2a4d3cf51d27425b0c51d241a7ba6bc44dd27034b44f9e437624f9e0953b1ea9", "price_changes": [{"asset_id": "111798086980787121079742248333092569415172137759139099190565410999420761499752", "price": "0.63", "size": "0", "side": "SELL", "hash": "45981d2cd1ad2821bcf03bb486a3cd9b8c506e36", "best_bid": "0.62", "best_ask": "0.67"}, {"asset_id": "58599269208124653793682124721644272657448822176028066253503704155842141815443", "price": "0.37", "size": "0", "side": "BUY", "hash": "b743e94ad81d8b1ed029d79300f3878c7d2f0d8c", "best_bid": "0.33", "best_ask": "0.38"}], "timestamp": "1769384489500", "event_type": "price_change"}}
{"_local_timestamp": "2026-01-25T23:41:29.618284+00:00", "data": {"market": "0x2a4d3cf51d27425b0c51d241a7ba6bc44dd27034b44f9e437624f9e0953b1ea9", "price_changes": [{"asset_id": "58599269208124653793682124721644272657448822176028066253503704155842141815443", "price": "0.33", "size": "6", "side": "BUY", "hash": "6486540980ef021832e373c64bbba20143d47d6e", "best_bid": "0.33", "best_ask": "0.38"}, {"asset_id": "111798086980787121079742248333092569415172137759139099190565410999420761499752", "price": "0.67", "size": "6", "side": "SELL", "hash": "1ae5ccda98d12131de5af01a3e472be07b1425be", "best_bid": "0.62", "best_ask": "0.67"}], "timestamp": "1769384489526", "event_type": "price_change"}}
{"_local_timestamp": "2026-01-25T23:41:29.619775+00:00", "data": {"market": "0x2a4d3cf51d27425b0c51d241a7ba6bc44dd27034b44f9e437624f9e0953b1ea9", "price_changes": [{"asset_id": "58599269208124653793682124721644272657448822176028066253503704155842141815443", "price": "0.32", "size": "99", "side": "BUY", "hash": "849df920b92b3622f2554e02c341b77c66d09b41", "best_bid": "0.33", "best_ask": "0.38"}, {"asset_id": "111798086980787121079742248333092569415172137759139099190565410999420761499752", "price": "0.68", "size": "99", "side": "SELL", "hash": "e131892d95b760b5a2c70c321c7206bf0f74ae01", "best_bid": "0.62", "best_ask": "0.67"}], "timestamp": "1769384489551", "event_type": "price_change"}}
{"_local_timestamp": "2026-01-25T23:41:29.948614+00:00", "data": {"market": "0x2a4d3cf51d27425b0c51d241a7ba6bc44dd27034b44f9e437624f9e0953b1ea9", "price_changes": [{"asset_id": "58599269208124653793682124721644272657448822176028066253503704155842141815443", "price": "0.32", "size": "129", "side": "BUY", "hash": "dc52c43448daf4b51f669f5896fe7f9526984631", "best_bid": "0.33", "best_ask": "0.38"}, {"asset_id": "111798086980787121079742248333092569415172137759139099190565410999420761499752", "price": "0.68", "size": "129", "side": "SELL", "hash": "bf8606c06ecdebc49b9cb178f914512f253f8520", "best_bid": "0.62", "best_ask": "0.67"}], "timestamp": "1769384489872", "event_type": "price_change"}}
{"_local_timestamp": "2026-01-25T23:41:30.180051+00:00", "data": {"market": "0x2a4d3cf51d27425b0c51d241a7ba6bc44dd27034b44f9e437624f9e0953b1ea9", "price_changes": [{"asset_id": "111798086980787121079742248333092569415172137759139099190565410999420761499752", "price": "0.26", "size": "0", "side": "BUY", "hash": "a24b1a1542e4b4b9da3f8d1def62f40b7872ad14", "best_bid": "0.62", "best_ask": "0.67"}, {"asset_id": "58599269208124653793682124721644272657448822176028066253503704155842141815443", "price": "0.74", "size": "0", "side": "SELL", "hash": "b605f2044ff5a1e1375ecf6737b3f2d0170fb9e8", "best_bid": "0.33", "best_ask": "0.38"}], "timestamp": "1769384490100", "event_type": "price_change"}}
{"_local_timestamp": "2026-01-25T23:41:30.180409+00:00", "data": {"market": "0x2a4d3cf51d27425b0c51d241a7ba6bc44dd27034b44f9e437624f9e0953b1ea9", "price_changes": [{"asset_id": "111798086980787121079742248333092569415172137759139099190565410999420761499752", "price": "0.2", "size": "50", "side": "BUY", "hash": "a24b1a1542e4b4b9da3f8d1def62f40b7872ad14", "best_bid": "0.62", "best_ask": "0.67"}, {"asset_id": "58599269208124653793682124721644272657448822176028066253503704155842141815443", "price": "0.8", "size": "50", "side": "SELL", "hash": "b605f2044ff5a1e1375ecf6737b3f2d0170fb9e8", "best_bid": "0.33", "best_ask": "0.38"}], "timestamp": "1769384490100", "event_type": "price_change"}}
{"_local_timestamp": "2026-01-25T23:41:30.180630+00:00", "data": {"market": "0x2a4d3cf51d27425b0c51d241a7ba6bc44dd27034b44f9e437624f9e0953b1ea9", "price_changes": [{"asset_id": "111798086980787121079742248333092569415172137759139099190565410999420761499752", "price": "0.16", "size": "0", "side": "BUY", "hash": "a24b1a1542e4b4b9da3f8d1def62f40b7872ad14", "best_bid": "0.62", "best_ask": "0.67"}, {"asset_id": "58599269208124653793682124721644272657448822176028066253503704155842141815443", "price": "0.84", "size": "0", "side": "SELL", "hash": "b605f2044ff5a1e1375ecf6737b3f2d0170fb9e8", "best_bid": "0.33", "best_ask": "0.38"}], "timestamp": "1769384490100", "event_type": "price_change"}}
{"_local_timestamp": "2026-01-25T23:41:30.180840+00:00", "data": {"market": "0x2a4d3cf51d27425b0c51d241a7ba6bc44dd27034b44f9e437624f9e0953b1ea9", "price_changes": [{"asset_id": "111798086980787121079742248333092569415172137759139099190565410999420761499752", "price": "0.06", "size": "800", "side": "BUY", "hash": "a24b1a1542e4b4b9da3f8d1def62f40b7872ad14", "best_bid": "0.62", "best_ask": "0.67"}, {"asset_id": "58599269208124653793682124721644272657448822176028066253503704155842141815443", "price": "0.94", "size": "800", "side": "SELL", "hash": "b605f2044ff5a1e1375ecf6737b3f2d0170fb9e8", "best_bid": "0.33", "best_ask": "0.38"}], "timestamp": "1769384490100", "event_type": "price_change"}}
{"_local_timestamp": "2026-01-25T23:41:30.181058+00:00", "data": {"market": "0x2a4d3cf51d27425b0c51d241a7ba6bc44dd27034b44f9e437624f9e0953b1ea9", "price_changes": [{"asset_id": "111798086980787121079742248333092569415172137759139099190565410999420761499752", "price": "0.13", "size": "325", "side": "BUY", "hash": "a24b1a1542e4b4b9da3f8d1def62f40b7872ad14", "best_bid": "0.62", "best_ask": "0.67"}, {"asset_id": "58599269208124653793682124721644272657448822176028066253503704155842141815443", "price": "0.87", "size": "325", "side": "SELL", "hash": "b605f2044ff5a1e1375ecf6737b3f2d0170fb9e8", "best_bid": "0.33", "best_ask": "0.38"}], "timestamp": "1769384490100", "event_type": "price_change"}}
{"_local_timestamp": "2026-01-25T23:41:30.181259+00:00", "data": {"market": "0x2a4d3cf51d27425b0c51d241a7ba6bc44dd27034b44f9e437624f9e0953b1ea9", "price_changes": [{"asset_id": "111798086980787121079742248333092569415172137759139099190565410999420761499752", "price": "0.23", "size": "0", "side": "BUY", "hash": "a24b1a1542e4b4b9da3f8d1def62f40b7872ad14", "best_bid": "0.62", "best_ask": "0.67"}, {"asset_id": "58599269208124653793682124721644272657448822176028066253503704155842141815443", "price": "0.77", "size": "0", "side": "SELL", "hash": "b605f2044ff5a1e1375ecf6737b3f2d0170fb9e8", "best_bid": "0.33", "best_ask": "0.38"}], "timestamp": "1769384490100", "event_type": "price_change"}}
{"_local_timestamp": "2026-01-25T23:41:30.181477+00:00", "data": {"market": "0x2a4d3cf51d27425b0c51d241a7ba6bc44dd27034b44f9e437624f9e0953b1ea9", "price_changes": [{"asset_id": "111798086980787121079742248333092569415172137759139099190565410999420761499752", "price": "0.1", "size": "0", "side": "BUY", "hash": "a24b1a1542e4b4b9da3f8d1def62f40b7872ad14", "best_bid": "0.62", "best_ask": "0.67"}, {"asset_id": "58599269208124653793682124721644272657448822176028066253503704155842141815443", "price": "0.9", "size": "0", "side": "SELL", "hash": "b605f2044ff5a1e1375ecf6737b3f2d0170fb9e8", "best_bid": "0.33", "best_ask": "0.38"}], "timestamp": "1769384490100", "event_type": "price_change"}}
{"_local_timestamp": "2026-01-25T23:41:30.190824+00:00", "data": {"market": "0x2a4d3cf51d27425b0c51d241a7ba6bc44dd27034b44f9e437624f9e0953b1ea9", "price_changes": [{"asset_id": "111798086980787121079742248333092569415172137759139099190565410999420761499752", "price": "0.59", "size": "6", "side": "BUY", "hash": "fd525777a5f3feb4f838e1e1f778365e82f7d7bb", "best_bid": "0.62", "best_ask": "0.67"}, {"asset_id": "58599269208124653793682124721644272657448822176028066253503704155842141815443", "price": "0.41", "size": "6", "side": "SELL", "hash": "b453389f41566b315cc1ed1fc2ec9a0f76edab2c", "best_bid": "0.33", "best_ask": "0.38"}], "timestamp": "1769384490124", "event_type": "price_change"}}
{"_local_timestamp": "2026-01-25T23:41:30.219812+00:00", "data": {"market": "0x2a4d3cf51d27425b0c51d241a7ba6bc44dd27034b44f9e437624f9e0953b1ea9", "price_changes": [{"asset_id": "111798086980787121079742248333092569415172137759139099190565410999420761499752", "price": "0.27", "size": "224.07", "side": "BUY", "hash": "4a898044683fa430d03cc65b6e4c33dce82cade3", "best_bid": "0.62", "best_ask": "0.67"}, {"asset_id": "58599269208124653793682124721644272657448822176028066253503704155842141815443", "price": "0.73", "size": "224.07", "side": "SELL", "hash": "668d132466f56e24a54f04a29ecb8eb45b2475ff", "best_bid": "0.33", "best_ask": "0.38"}], "timestamp": "1769384490147", "event_type": "price_change"}}
{"_local_timestamp": "2026-01-25T23:41:30.227081+00:00", "data": {"market": "0x2a4d3cf51d27425b0c51d241a7ba6bc44dd27034b44f9e437624f9e0953b1ea9", "price_changes": [{"asset_id": "111798086980787121079742248333092569415172137759139099190565410999420761499752", "price": "0.59", "size": "81", "side": "BUY", "hash": "912d2a6178665584d707e15423eff1b0250e5660", "best_bid": "0.62", "best_ask": "0.67"}, {"asset_id": "58599269208124653793682124721644272657448822176028066253503704155842141815443", "price": "0.41", "size": "81", "side": "SELL", "hash": "6da377726c3cad78d00006649747f1118eb9f558", "best_bid": "0.33", "best_ask": "0.38"}], "timestamp": "1769384490151", "event_type": "price_change"}}
{"_local_timestamp": "2026-01-25T23:41:30.260499+00:00", "data": {"market": "0x2a4d3cf51d27425b0c51d241a7ba6bc44dd27034b44f9e437624f9e0953b1ea9", "price_changes": [{"asset_id": "111798086980787121079742248333092569415172137759139099190565410999420761499752", "price": "0.23", "size": "104.34", "side": "BUY", "hash": "b9728c23e37cfd52d095ed08dd5da1edea6c0ef8", "best_bid": "0.62", "best_ask": "0.67"}, {"asset_id": "58599269208124653793682124721644272657448822176028066253503704155842141815443", "price": "0.77", "size": "104.34", "side": "SELL", "hash": "abb050ae79952903f8b87a827d2491456464e6fa", "best_bid": "0.33", "best_ask": "0.38"}], "timestamp": "1769384490185", "event_type": "price_change"}}
{"_local_timestamp": "2026-01-25T23:41:30.290982+00:00", "data": {"market": "0x2a4d3cf51d27425b0c51d241a7ba6bc44dd27034b44f9e437624f9e0953b1ea9", "price_changes": [{"asset_id": "111798086980787121079742248333092569415172137759139099190565410999420761499752", "price": "0.2", "size": "180", "side": "BUY", "hash": "d3ff119a2e071430bb5f9af2fbbba34b78afd0ed", "best_bid": "0.62", "best_ask": "0.67"}, {"asset_id": "58599269208124653793682124721644272657448822176028066253503704155842141815443", "price": "0.8", "size": "180", "side": "SELL", "hash": "bf71c992844f2260704fa748652ba27460d9eb6d", "best_bid": "0.33", "best_ask": "0.38"}], "timestamp": "1769384490222", "event_type": "price_change"}}
{"_local_timestamp": "2026-01-25T23:41:30.331146+00:00", "data": {"market": "0x2a4d3cf51d27425b0c51d241a7ba6bc44dd27034b44f9e437624f9e0953b1ea9", "price_changes": [{"asset_id": "111798086980787121079742248333092569415172137759139099190565410999420761499752", "price": "0.17", "size": "164.7", "side": "BUY", "hash": "81baf8d7507f569c5973708f9e6798e22da030b2", "best_bid": "0.62", "best_ask": "0.67"}, {"asset_id": "58599269208124653793682124721644272657448822176028066253503704155842141815443", "price": "0.83", "size": "164.7", "side": "SELL", "hash": "f0c7965124447a5c6addb659ec10a1c0b6c4062b", "best_bid": "0.33", "best_ask": "0.38"}], "timestamp": "1769384490262", "event_type": "price_change"}}
{"_local_timestamp": "2026-01-25T23:41:30.374213+00:00", "data": {"market": "0x2a4d3cf51d27425b0c51d241a7ba6bc44dd27034b44f9e437624f9e0953b1ea9", "price_changes": [{"asset_id": "111798086980787121079742248333092569415172137759139099190565410999420761499752", "price": "0.13", "size": "571.15", "side": "BUY", "hash": "afc9144ecac06d1e6cd3a0c31b4cf54da0217eb2", "best_bid": "0.62", "best_ask": "0.67"}, {"asset_id": "58599269208124653793682124721644272657448822176028066253503704155842141815443", "price": "0.87", "size": "571.15", "side": "SELL", "hash": "b8c6d2be1d66916aaf41527288d9386519d1c59d", "best_bid": "0.33", "best_ask": "0.38"}], "timestamp": "1769384490304", "event_type": "price_change"}}
{"_local_timestamp": "2026-01-25T23:41:30.417552+00:00", "data": {"market": "0x2a4d3cf51d27425b0c51d241a7ba6bc44dd27034b44f9e437624f9e0953b1ea9", "price_changes": [{"asset_id": "111798086980787121079742248333092569415172137759139099190565410999420761499752", "price": "0.1", "size": "340", "side": "BUY", "hash": "50963896b411f4d59a7721d3227c4e7518a9f38c", "best_bid": "0.62", "best_ask": "0.67"}, {"asset_id": "58599269208124653793682124721644272657448822176028066253503704155842141815443", "price": "0.9", "size": "340", "side": "SELL", "hash": "c54b169f564a8c3cc4e9b7978745700aa7fc566d", "best_bid": "0.33", "best_ask": "0.38"}], "timestamp": "1769384490350", "event_type": "price_change"}}
{"_local_timestamp": "2026-01-25T23:41:30.470515+00:00", "data": {"market": "0x2a4d3cf51d27425b0c51d241a7ba6bc44dd27034b44f9e437624f9e0953b1ea9", "price_changes": [{"asset_id": "111798086980787121079742248333092569415172137759139099190565410999420761499752", "price": "0.07", "size": "814.28", "side": "BUY", "hash": "01aac30446dc9e064fd0ee8bd2e7b3d9a2a2477f", "best_bid": "0.62", "best_ask": "0.67"}, {"asset_id": "58599269208124653793682124721644272657448822176028066253503704155842141815443", "price": "0.93", "size": "814.28", "side": "SELL", "hash": "22adf39e601a6e802819d0760680a3affe4ad55d", "best_bid": "0.33", "best_ask": "0.38"}], "timestamp": "1769384490393", "event_type": "price_change"}}
{"_local_timestamp": "2026-01-25T23:41:32.762596+00:00", "data": {"market": "0x1a65d4eb8ac985309e78b48906291fffbf137cee590d8d75365f77a0549e9ab9", "price_changes": [{"asset_id": "48953332818425460061045724981972442660997032539861914953015827526728376958623", "price": "0.33", "size": "66.66", "side": "SELL", "hash": "2223211aa1ee0945037273036ddaf466deef7bc1", "best_bid": "0.29", "best_ask": "0.33"}, {"asset_id": "81870625725474135545086561756714985203836689747059214375533433096496527904265", "price": "0.67", "size": "66.66", "side": "BUY", "hash": "38661831d72a9372bce29481fd3ae19f9fb82c2e", "best_bid": "0.67", "best_ask": "0.71"}], "timestamp": "1769384492693", "event_type": "price_change"}}
{"_local_timestamp": "2026-01-25T23:41:36.330491+00:00", "data": {"market": "0x2a4d3cf51d27425b0c51d241a7ba6bc44dd27034b44f9e437624f9e0953b1ea9", "price_changes": [{"asset_id": "111798086980787121079742248333092569415172137759139099190565410999420761499752", "price": "0.66", "size": "6.66", "side": "SELL", "hash": "0514483a2db9436c19b0df187639237e047db1a0", "best_bid": "0.62", "best_ask": "0.66"}, {"asset_id": "58599269208124653793682124721644272657448822176028066253503704155842141815443", "price": "0.34", "size": "6.66", "side": "BUY", "hash": "f74aa7f102b0fa5236df916384eb051b8315b6ff", "best_bid": "0.34", "best_ask": "0.38"}], "timestamp": "1769384496255", "event_type": "price_change"}}
{"_local_timestamp": "2026-01-25T23:41:46.615301+00:00", "data": {"market": "0x1a65d4eb8ac985309e78b48906291fffbf137cee590d8d75365f77a0549e9ab9", "price_changes": [{"asset_id": "48953332818425460061045724981972442660997032539861914953015827526728376958623", "price": "0.33", "size": "77.61", "side": "SELL", "hash": "57baab14977130f352f0e815014f6fda49779cd9", "best_bid": "0.29", "best_ask": "0.33"}, {"asset_id": "81870625725474135545086561756714985203836689747059214375533433096496527904265", "price": "0.67", "size": "77.61", "side": "BUY", "hash": "b9bf5d4d1d44a936c6eb2fe5825c84628c2662fa", "best_bid": "0.67", "best_ask": "0.71"}], "timestamp": "1769384506550", "event_type": "price_change"}}
{"_local_timestamp": "2026-01-25T23:41:46.646825+00:00", "data": {"market": "0x1a65d4eb8ac985309e78b48906291fffbf137cee590d8d75365f77a0549e9ab9", "price_changes": [{"asset_id": "48953332818425460061045724981972442660997032539861914953015827526728376958623", "price": "0.33", "size": "88.56", "side": "SELL", "hash": "47c5e2222de8b8c6165c8ecb2e36139d4ed52f18", "best_bid": "0.29", "best_ask": "0.33"}, {"asset_id": "81870625725474135545086561756714985203836689747059214375533433096496527904265", "price": "0.67", "size": "88.56", "side": "BUY", "hash": "8521982045baf7c071e164bfd56d1e31264b97ec", "best_bid": "0.67", "best_ask": "0.71"}], "timestamp": "1769384506577", "event_type": "price_change"}}
{"_local_timestamp": "2026-01-25T23:41:46.742139+00:00", "data": {"market": "0x7f6dadade6357d3ce6681860d002bd3521554aba8b5acda912917b3db41c9549", "price_changes": [{"asset_id": "112538531010841097813690615473978896934576951101485955663285389253633812461690", "price": "0.72", "size": "61.66", "side": "BUY", "hash": "082ca4ffe458a2a64a333f494649662fde43c25c", "best_bid": "0.72", "best_ask": "0.78"}, {"asset_id": "50613703516194910329561493534058464924948966095615247532634099427569284124317", "price": "0.28", "size": "61.66", "side": "SELL", "hash": "5426a0c91fe6d1a2c5cbb140054b50a636009b0a", "best_bid": "0.22", "best_ask": "0.28"}], "timestamp": "1769384506668", "event_type": "price_change"}}
{"_local_timestamp": "2026-01-25T23:41:52.903180+00:00", "data": {"market": "0x7f6dadade6357d3ce6681860d002bd3521554aba8b5acda912917b3db41c9549", "price_changes": [{"asset_id": "112538531010841097813690615473978896934576951101485955663285389253633812461690", "price": "0.32", "size": "137.5", "side": "BUY", "hash": "3258a9348b82c9993a9f409f148b3e69c5ce3e0b", "best_bid": "0.72", "best_ask": "0.78"}, {"asset_id": "50613703516194910329561493534058464924948966095615247532634099427569284124317", "price": "0.68", "size": "137.5", "side": "SELL", "hash": "58e846e55bc5e5f40566887c5cdb1f73d03b3790", "best_bid": "0.22", "best_ask": "0.28"}], "timestamp": "1769384511846", "event_type": "price_change"}}
{"_local_timestamp": "2026-01-25T23:41:53.022890+00:00", "data": {"market": "0x7f6dadade6357d3ce6681860d002bd3521554aba8b5acda912917b3db41c9549", "price_changes": [{"asset_id": "112538531010841097813690615473978896934576951101485955663285389253633812461690", "price": "0.12", "size": "608.33", "side": "BUY", "hash": "5d1d4885417a72b181d5951fffa0e6724b8befc7", "best_bid": "0.72", "best_ask": "0.78"}, {"asset_id": "50613703516194910329561493534058464924948966095615247532634099427569284124317", "price": "0.88", "size": "608.33", "side": "SELL", "hash": "9deed715a3740f7f3d20553c8466748d1ba9bdc6", "best_bid": "0.22", "best_ask": "0.28"}], "timestamp": "1769384512679", "event_type": "price_change"}}
{"_local_timestamp": "2026-01-25T23:41:53.054549+00:00", "data": {"market": "0x7f6dadade6357d3ce6681860d002bd3521554aba8b5acda912917b3db41c9549", "price_changes": [{"asset_id": "112538531010841097813690615473978896934576951101485955663285389253633812461690", "price": "0.16", "size": "450", "side": "BUY", "hash": "9e9fa6eb50f0cea88bdd128efd0c22bcc2e08a77", "best_bid": "0.72", "best_ask": "0.78"}, {"asset_id": "50613703516194910329561493534058464924948966095615247532634099427569284124317", "price": "0.84", "size": "450", "side": "SELL", "hash": "c949560ecb7ee42a7e452652a0db8097c28d90a3", "best_bid": "0.22", "best_ask": "0.28"}], "timestamp": "1769384512694", "event_type": "price_change"}}
{"_local_timestamp": "2026-01-25T23:41:53.062513+00:00", "data": {"market": "0x7f6dadade6357d3ce6681860d002bd3521554aba8b5acda912917b3db41c9549", "price_changes": [{"asset_id": "112538531010841097813690615473978896934576951101485955663285389253633812461690", "price": "0.24", "size": "258.33", "side": "BUY", "hash": "9b99456c2be0d4f2b1bbdba4fb93a374447b8b19", "best_bid": "0.72", "best_ask": "0.78"}, {"asset_id": "50613703516194910329561493534058464924948966095615247532634099427569284124317", "price": "0.76", "size": "258.33", "side": "SELL", "hash": "359ea00703e8a2607558c0e7d1bb0f7be8442a50", "best_bid": "0.22", "best_ask": "0.28"}], "timestamp": "1769384512696", "event_type": "price_change"}}
{"_local_timestamp": "2026-01-25T23:41:59.453133+00:00", "data": {"market": "0x7f6dadade6357d3ce6681860d002bd3521554aba8b5acda912917b3db41c9549", "price_changes": [{"asset_id": "112538531010841097813690615473978896934576951101485955663285389253633812461690", "price": "0.01", "size": "3010.58", "side": "BUY", "hash": "2d9e342719ea6b6fe73a3fdcd0f8cbe6c88d989e", "best_bid": "0.72", "best_ask": "0.78"}, {"asset_id": "50613703516194910329561493534058464924948966095615247532634099427569284124317", "price": "0.99", "size": "3010.58", "side": "SELL", "hash": "728a2a698b56ac815607574545b4dc3b4274934f", "best_bid": "0.22", "best_ask": "0.28"}], "timestamp": "1769384519378", "event_type": "price_change"}}
{"_local_timestamp": "2026-01-25T23:42:10.785876+00:00", "data": {"market": "0x7f6dadade6357d3ce6681860d002bd3521554aba8b5acda912917b3db41c9549", "price_changes": [{"asset_id": "112538531010841097813690615473978896934576951101485955663285389253633812461690", "price": "0.02", "size": "1600", "side": "BUY", "hash": "ba7edd6613dc542c27749134eaa6ba7c2b26fe32", "best_bid": "0.72", "best_ask": "0.78"}, {"asset_id": "50613703516194910329561493534058464924948966095615247532634099427569284124317", "price": "0.98", "size": "1600", "side": "SELL", "hash": "d7f89d9b805dd7f5cd9da762ab898ad9462b4a1f", "best_bid": "0.22", "best_ask": "0.28"}], "timestamp": "1769384530717", "event_type": "price_change"}}
{"_local_timestamp": "2026-01-25T23:42:17.166353+00:00", "data": {"market": "0x1a65d4eb8ac985309e78b48906291fffbf137cee590d8d75365f77a0549e9ab9", "price_changes": [{"asset_id": "48953332818425460061045724981972442660997032539861914953015827526728376958623", "price": "0.33", "size": "66.66", "side": "SELL", "hash": "31b355f1fa3370cf25ef404e485367373ba5ed8f", "best_bid": "0.29", "best_ask": "0.33"}, {"asset_id": "81870625725474135545086561756714985203836689747059214375533433096496527904265", "price": "0.67", "size": "66.66", "side": "BUY", "hash": "8aeddfb06cc7e5a450d45a1945b97c56e64b352d", "best_bid": "0.67", "best_ask": "0.71"}], "timestamp": "1769384537084", "event_type": "price_change"}}
{"_local_timestamp": "2026-01-25T23:42:18.028300+00:00", "data": {"market": "0x0a9f1c94b012a39a2a91b877b24c15f25ffd1ee68df65a79c12e5fac82519865", "price_changes": [{"asset_id": "73641960431177563453506958377488026157202817565843589479879428094129866219922", "price": "0.28", "size": "0", "side": "SELL", "hash": "e14cbe959d41ee3fac3545f4c9ff2ff61e765654", "best_bid": "0.06", "best_ask": "0.12"}, {"asset_id": "92197810663257226642496081056291543161006633887475519374142132133821877068692", "price": "0.72", "size": "0", "side": "BUY", "hash": "dd882eefefe1266e922d98766cd766fcb7b624d2", "best_bid": "0.88", "best_ask": "0.94"}], "timestamp": "1769384537944", "event_type": "price_change"}}
{"_local_timestamp": "2026-01-25T23:42:18.620844+00:00", "data": {"market": "0x0a9f1c94b012a39a2a91b877b24c15f25ffd1ee68df65a79c12e5fac82519865", "price_changes": [{"asset_id": "73641960431177563453506958377488026157202817565843589479879428094129866219922", "price": "0.3", "size": "134.5", "side": "SELL", "hash": "0930630c0f65c1e99ce2ddf06aaef6d929457dd8", "best_bid": "0.06", "best_ask": "0.12"}, {"asset_id": "92197810663257226642496081056291543161006633887475519374142132133821877068692", "price": "0.7", "size": "134.5", "side": "BUY", "hash": "1ae44e84ffd3687e275732c9dcf262cd08b8c1ec", "best_bid": "0.88", "best_ask": "0.94"}], "timestamp": "1769384538538", "event_type": "price_change"}}
{"_local_timestamp": "2026-01-25T23:42:22.604336+00:00", "data": {"market": "0x7f6dadade6357d3ce6681860d002bd3521554aba8b5acda912917b3db41c9549", "price_changes": [{"asset_id": "112538531010841097813690615473978896934576951101485955663285389253633812461690", "price": "0.72", "size": "52.77", "side": "BUY", "hash": "5aaf8fca4be5827afc2bd2e31a81fc737a56006a", "best_bid": "0.72", "best_ask": "0.78"}, {"asset_id": "50613703516194910329561493534058464924948966095615247532634099427569284124317", "price": "0.28", "size": "52.77", "side": "SELL", "hash": "c7fa1b500c3cd9d97cd925a95d73e67c33a1882e", "best_bid": "0.22", "best_ask": "0.28"}], "timestamp": "1769384542500", "event_type": "price_change"}}
{"_local_timestamp": "2026-01-25T23:42:22.612179+00:00", "data": {"market": "0x2a4d3cf51d27425b0c51d241a7ba6bc44dd27034b44f9e437624f9e0953b1ea9", "price_changes": [{"asset_id": "58599269208124653793682124721644272657448822176028066253503704155842141815443", "price": "0.31", "size": "0", "side": "BUY", "hash": "6d8ac4393af4ca655b842210b37332b4cbeb1c91", "best_bid": "0.34", "best_ask": "0.38"}, {"asset_id": "111798086980787121079742248333092569415172137759139099190565410999420761499752", "price": "0.69", "size": "0", "side": "SELL", "hash": "05120df20073aa83b70dc25546ddf732ec83327f", "best_bid": "0.62", "best_ask": "0.66"}], "timestamp": "1769384542500", "event_type": "price_change"}}
{"_local_timestamp": "2026-01-25T23:42:22.612566+00:00", "data": {"market": "0x7f6dadade6357d3ce6681860d002bd3521554aba8b5acda912917b3db41c9549", "price_changes": [{"asset_id": "112538531010841097813690615473978896934576951101485955663285389253633812461690", "price": "0.48", "size": "0", "side": "BUY", "hash": "5aaf8fca4be5827afc2bd2e31a81fc737a56006a", "best_bid": "0.72", "best_ask": "0.78"}, {"asset_id": "50613703516194910329561493534058464924948966095615247532634099427569284124317", "price": "0.52", "size": "0", "side": "SELL", "hash": "c7fa1b500c3cd9d97cd925a95d73e67c33a1882e", "best_bid": "0.22", "best_ask": "0.28"}], "timestamp": "1769384542500", "event_type": "price_change"}}
{"_local_timestamp": "2026-01-25T23:42:22.612926+00:00", "data": {"market": "0x2a4d3cf51d27425b0c51d241a7ba6bc44dd27034b44f9e437624f9e0953b1ea9", "price_changes": [{"asset_id": "58599269208124653793682124721644272657448822176028066253503704155842141815443", "price": "0.25", "size": "50", "side": "BUY", "hash": "6d8ac4393af4ca655b842210b37332b4cbeb1c91", "best_bid": "0.34", "best_ask": "0.38"}, {"asset_id": "111798086980787121079742248333092569415172137759139099190565410999420761499752", "price": "0.75", "size": "50", "side": "SELL", "hash": "05120df20073aa83b70dc25546ddf732ec83327f", "best_bid": "0.62", "best_ask": "0.66"}], "timestamp": "1769384542500", "event_type": "price_change"}}
{"_local_timestamp": "2026-01-25T23:42:22.613183+00:00", "data": {"market": "0x7f6dadade6357d3ce6681860d002bd3521554aba8b5acda912917b3db41c9549", "price_changes": [{"asset_id": "112538531010841097813690615473978896934576951101485955663285389253633812461690", "price": "0.25", "size": "0", "side": "BUY", "hash": "5aaf8fca4be5827afc2bd2e31a81fc737a56006a", "best_bid": "0.72", "best_ask": "0.78"}, {"asset_id": "50613703516194910329561493534058464924948966095615247532634099427569284124317", "price": "0.75", "size": "0", "side": "SELL", "hash": "c7fa1b500c3cd9d97cd925a95d73e67c33a1882e", "best_bid": "0.22", "best_ask": "0.28"}], "timestamp": "1769384542500", "event_type": "price_change"}}
{"_local_timestamp": "2026-01-25T23:42:22.613431+00:00", "data": {"market": "0x0a9f1c94b012a39a2a91b877b24c15f25ffd1ee68df65a79c12e5fac82519865", "price_changes": [{"asset_id": "92197810663257226642496081056291543161006633887475519374142132133821877068692", "price": "0.88", "size": "0", "side": "BUY", "hash": "c497d5e2fdb9e4c1ed3f8a61d97a53d081ec7c97", "best_bid": "0.87", "best_ask": "0.94"}, {"asset_id": "73641960431177563453506958377488026157202817565843589479879428094129866219922", "price": "0.12", "size": "0", "side": "SELL", "hash": "1d7b6c0d3d627f0a989cab28683d4a975940ac23", "best_bid": "0.06", "best_ask": "0.13"}], "timestamp": "1769384542500", "event_type": "price_change"}}
{"_local_timestamp": "2026-01-25T23:42:22.613693+00:00", "data": {"market": "0x2a4d3cf51d27425b0c51d241a7ba6bc44dd27034b44f9e437624f9e0953b1ea9", "price_changes": [{"asset_id": "111798086980787121079742248333092569415172137759139099190565410999420761499752", "price": "0.62", "size": "5.79", "side": "BUY", "hash": "6b5bd3f82b9aec6186ab5336ca99baebd40b963f", "best_bid": "0.62", "best_ask": "0.66"}, {"asset_id": "58599269208124653793682124721644272657448822176028066253503704155842141815443", "price": "0.38", "size": "5.79", "side": "SELL", "hash": "2a643424fa8b7f883ac24082c8d8e778f5dc6fa4", "best_bid": "0.34", "best_ask": "0.38"}], "timestamp": "1769384542501", "event_type": "price_change"}}
{"_local_timestamp": "2026-01-25T23:42:22.613981+00:00", "data": {"market": "0x0a9f1c94b012a39a2a91b877b24c15f25ffd1ee68df65a79c12e5fac82519865", "price_changes": [{"asset_id": "92197810663257226642496081056291543161006633887475519374142132133821877068692", "price": "0.78", "size": "0", "side": "BUY", "hash": "c497d5e2fdb9e4c1ed3f8a61d97a53d081ec7c97", "best_bid": "0.87", "best_ask": "0.94"}, {"asset_id": "73641960431177563453506958377488026157202817565843589479879428094129866219922", "price": "0.22", "size": "0", "side": "SELL", "hash": "1d7b6c0d3d627f0a989cab28683d4a975940ac23", "best_bid": "0.06", "best_ask": "0.13"}], "timestamp": "1769384542500", "event_type": "price_change"}}
{"_local_timestamp": "2026-01-25T23:42:22.614308+00:00", "data": {"market": "0x2a4d3cf51d27425b0c51d241a7ba6bc44dd27034b44f9e437624f9e0953b1ea9", "price_changes": [{"asset_id": "111798086980787121079742248333092569415172137759139099190565410999420761499752", "price": "0.57", "size": "0", "side": "BUY", "hash": "6b5bd3f82b9aec6186ab5336ca99baebd40b963f", "best_bid": "0.62", "best_ask": "0.66"}, {"asset_id": "58599269208124653793682124721644272657448822176028066253503704155842141815443", "price": "0.43", "size": "0", "side": "SELL", "hash": "2a643424fa8b7f883ac24082c8d8e778f5dc6fa4", "best_bid": "0.34", "best_ask": "0.38"}], "timestamp": "1769384542501", "event_type": "price_change"}}
{"_local_timestamp": "2026-01-25T23:42:22.614587+00:00", "data": {"market": "0x0a9f1c94b012a39a2a91b877b24c15f25ffd1ee68df65a79c12e5fac82519865", "price_changes": [{"asset_id": "92197810663257226642496081056291543161006633887475519374142132133821877068692", "price": "0.68", "size": "0", "side": "BUY", "hash": "c497d5e2fdb9e4c1ed3f8a61d97a53d081ec7c97", "best_bid": "0.87", "best_ask": "0.94"}, {"asset_id": "73641960431177563453506958377488026157202817565843589479879428094129866219922", "price": "0.32", "size": "0", "side": "SELL", "hash": "1d7b6c0d3d627f0a989cab28683d4a975940ac23", "best_bid": "0.06", "best_ask": "0.13"}], "timestamp": "1769384542500", "event_type": "price_change"}}
{"_local_timestamp": "2026-01-25T23:42:22.810375+00:00", "data": {"market": "0x2a4d3cf51d27425b0c51d241a7ba6bc44dd27034b44f9e437624f9e0953b1ea9", "price_changes": [{"asset_id": "111798086980787121079742248333092569415172137759139099190565410999420761499752", "price": "0.53", "size": "6", "side": "BUY", "hash": "6b5bd3f82b9aec6186ab5336ca99baebd40b963f", "best_bid": "0.62", "best_ask": "0.66"}, {"asset_id": "58599269208124653793682124721644272657448822176028066253503704155842141815443", "price": "0.47", "size": "6", "side": "SELL", "hash": "2a643424fa8b7f883ac24082c8d8e778f5dc6fa4", "best_bid": "0.34", "best_ask": "0.38"}], "timestamp": "1769384542501", "event_type": "price_change"}}
{"_local_timestamp": "2026-01-25T23:42:22.810767+00:00", "data": {"market": "0x2a4d3cf51d27425b0c51d241a7ba6bc44dd27034b44f9e437624f9e0953b1ea9", "price_changes": [{"asset_id": "111798086980787121079742248333092569415172137759139099190565410999420761499752", "price": "0.59", "size": "6", "side": "BUY", "hash": "0dbca94169d65dbc71df5b95d6da193e208b4b92", "best_bid": "0.62", "best_ask": "0.66"}, {"asset_id": "58599269208124653793682124721644272657448822176028066253503704155842141815443", "price": "0.41", "size": "6", "side": "SELL", "hash": "bb5d7a795c290105f9c24fb4e7765bee89b893a7", "best_bid": "0.34", "best_ask": "0.38"}], "timestamp": "1769384542526", "event_type": "price_change"}}
{"_local_timestamp": "2026-01-25T23:42:22.811032+00:00", "data": {"market": "0x2a4d3cf51d27425b0c51d241a7ba6bc44dd27034b44f9e437624f9e0953b1ea9", "price_changes": [{"asset_id": "58599269208124653793682124721644272657448822176028066253503704155842141815443", "price": "0.32", "size": "58", "side": "BUY", "hash": "c0d53523157daef44e1ad71383c35bb40c11cec1", "best_bid": "0.34", "best_ask": "0.38"}, {"asset_id": "111798086980787121079742248333092569415172137759139099190565410999420761499752", "price": "0.68", "size": "58", "side": "SELL", "hash": "d47790418927211de85b2c223d44647491e9a79d", "best_bid": "0.62", "best_ask": "0.66"}], "timestamp": "1769384542528", "event_type": "price_change"}}
{"_local_timestamp": "2026-01-25T23:42:22.811263+00:00", "data": {"market": "0x0a9f1c94b012a39a2a91b877b24c15f25ffd1ee68df65a79c12e5fac82519865", "price_changes": [{"asset_id": "73641960431177563453506958377488026157202817565843589479879428094129866219922", "price": "0.21", "size": "160", "side": "SELL", "hash": "82e579a95c3d1e87654fd8c210c0893584d63f23", "best_bid": "0.06", "best_ask": "0.13"}, {"asset_id": "92197810663257226642496081056291543161006633887475519374142132133821877068692", "price": "0.79", "size": "160", "side": "BUY", "hash": "41f7c830b050ac78d9084cb1eed1e0faf7766537", "best_bid": "0.87", "best_ask": "0.94"}], "timestamp": "1769384542529", "event_type": "price_change"}}
{"_local_timestamp": "2026-01-25T23:42:22.811516+00:00", "data": {"market": "0x2a4d3cf51d27425b0c51d241a7ba6bc44dd27034b44f9e437624f9e0953b1ea9", "price_changes": [{"asset_id": "111798086980787121079742248333092569415172137759139099190565410999420761499752", "price": "0.56", "size": "88", "side": "BUY", "hash": "d6bf5b0c18a4724a7966a4e1ccdd22de7db72f00", "best_bid": "0.62", "best_ask": "0.66"}, {"asset_id": "58599269208124653793682124721644272657448822176028066253503704155842141815443", "price": "0.44", "size": "88", "side": "SELL", "hash": "134de4606f3d7fbcd5a5fb1599b3c4d8330f34b7", "best_bid": "0.34", "best_ask": "0.38"}], "timestamp": "1769384542552", "event_type": "price_change"}}
{"_local_timestamp": "2026-01-25T23:42:22.811773+00:00", "data": {"market": "0x2a4d3cf51d27425b0c51d241a7ba6bc44dd27034b44f9e437624f9e0953b1ea9", "price_changes": [{"asset_id": "58599269208124653793682124721644272657448822176028066253503704155842141815443", "price": "0.34", "size": "88.66", "side": "BUY", "hash": "1110d745e3b4f228e854db8604d2148f18469dcf", "best_bid": "0.34", "best_ask": "0.38"}, {"asset_id": "111798086980787121079742248333092569415172137759139099190565410999420761499752", "price": "0.66", "size": "88.66", "side": "SELL", "hash": "da8fa57dd0ea61a8e294b64d07e8eb8274c6f86b", "best_bid": "0.62", "best_ask": "0.66"}], "timestamp": "1769384542556", "event_type": "price_change"}}
{"_local_timestamp": "2026-01-25T23:42:22.877015+00:00", "data": {"market": "0x0a9f1c94b012a39a2a91b877b24c15f25ffd1ee68df65a79c12e5fac82519865", "price_changes": [{"asset_id": "73641960431177563453506958377488026157202817565843589479879428094129866219922", "price": "0.31", "size": "100", "side": "SELL", "hash": "4b5f218b1668cb99822953f64b2eef8e7efca237", "best_bid": "0.06", "best_ask": "0.13"}, {"asset_id": "92197810663257226642496081056291543161006633887475519374142132133821877068692", "price": "0.69", "size": "100", "side": "BUY", "hash": "d933008d7e2a5f30aa47fdfe68fdd4512114e01e", "best_bid": "0.87", "best_ask": "0.94"}], "timestamp": "1769384542770", "event_type": "price_change"}}
{"_local_timestamp": "2026-01-25T23:42:22.932216+00:00", "data": {"market": "0x0a9f1c94b012a39a2a91b877b24c15f25ffd1ee68df65a79c12e5fac82519865", "price_changes": [{"asset_id": "73641960431177563453506958377488026157202817565843589479879428094129866219922", "price": "0.14", "size": "5.28", "side": "SELL", "hash": "26135cb26f6660058fb4991555123cd2daf384c7", "best_bid": "0.06", "best_ask": "0.13"}, {"asset_id": "92197810663257226642496081056291543161006633887475519374142132133821877068692", "price": "0.86", "size": "5.28", "side": "BUY", "hash": "abc3bc73f0cc1fbfde23af1c7edaae1c1007c11c", "best_bid": "0.87", "best_ask": "0.94"}], "timestamp": "1769384542815", "event_type": "price_change"}}
{"_local_timestamp": "2026-01-25T23:42:22.932626+00:00", "data": {"market": "0x2a4d3cf51d27425b0c51d241a7ba6bc44dd27034b44f9e437624f9e0953b1ea9", "price_changes": [{"asset_id": "58599269208124653793682124721644272657448822176028066253503704155842141815443", "price": "0.32", "size": "28", "side": "BUY", "hash": "9fcf9d3fedd414409bfbecd4658fd75d884103fb", "best_bid": "0.34", "best_ask": "0.38"}, {"asset_id": "111798086980787121079742248333092569415172137759139099190565410999420761499752", "price": "0.68", "size": "28", "side": "SELL", "hash": "0f4d2c7f46ed7b2ca6ddb45c9df8057be3d9168b", "best_bid": "0.62", "best_ask": "0.66"}], "timestamp": "1769384542816", "event_type": "price_change"}}
{"_local_timestamp": "2026-01-25T23:42:22.986216+00:00", "data": {"market": "0x0a9f1c94b012a39a2a91b877b24c15f25ffd1ee68df65a79c12e5fac82519865", "price_changes": [{"asset_id": "73641960431177563453506958377488026157202817565843589479879428094129866219922", "price": "0.2", "size": "30", "side": "SELL", "hash": "e06b3d7a48084f076df6297ae9d5607d9842bfe3", "best_bid": "0.06", "best_ask": "0.13"}, {"asset_id": "92197810663257226642496081056291543161006633887475519374142132133821877068692", "price": "0.8", "size": "30", "side": "BUY", "hash": "beb2954dbac3889c93955641bf085f7eb3b6d501", "best_bid": "0.87", "best_ask": "0.94"}], "timestamp": "1769384542876", "event_type": "price_change"}}
{"_local_timestamp": "2026-01-25T23:42:23.014788+00:00", "data": {"market": "0x2a4d3cf51d27425b0c51d241a7ba6bc44dd27034b44f9e437624f9e0953b1ea9", "price_changes": [{"asset_id": "58599269208124653793682124721644272657448822176028066253503704155842141815443", "price": "0.34", "size": "118.66", "side": "BUY", "hash": "6bd835914f66bd2a809fc2d6a834743639517189", "best_bid": "0.34", "best_ask": "0.38"}, {"asset_id": "111798086980787121079742248333092569415172137759139099190565410999420761499752", "price": "0.66", "size": "118.66", "side": "SELL", "hash": "3ea9f0590e179b585793333aa5b64ac29e518ba9", "best_bid": "0.62", "best_ask": "0.66"}], "timestamp": "1769384542904", "event_type": "price_change"}}
{"_local_timestamp": "2026-01-25T23:42:23.035041+00:00", "data": {"market": "0x0a9f1c94b012a39a2a91b877b24c15f25ffd1ee68df65a79c12e5fac82519865", "price_changes": [{"asset_id": "92197810663257226642496081056291543161006633887475519374142132133821877068692", "price": "0.66", "size": "100", "side": "BUY", "hash": "79d5a1931d9c4597bcaff635446f114aa755ea25", "best_bid": "0.87", "best_ask": "0.94"}, {"asset_id": "73641960431177563453506958377488026157202817565843589479879428094129866219922", "price": "0.34", "size": "100", "side": "SELL", "hash": "3b451514487d6cbec75f38bcdc7c515ac453e1d3", "best_bid": "0.06", "best_ask": "0.13"}], "timestamp": "1769384542927", "event_type": "price_change"}}
{"_local_timestamp": "2026-01-25T23:42:23.082642+00:00", "data": {"market": "0x2a4d3cf51d27425b0c51d241a7ba6bc44dd27034b44f9e437624f9e0953b1ea9", "price_changes": [{"asset_id": "58599269208124653793682124721644272657448822176028066253503704155842141815443", "price": "0.35", "size": "10.13", "side": "BUY", "hash": "5207ad8b19cf35264a6cdf13bd631adc3bb0d0f3", "best_bid": "0.35", "best_ask": "0.38"}, {"asset_id": "111798086980787121079742248333092569415172137759139099190565410999420761499752", "price": "0.65", "size": "10.13", "side": "SELL", "hash": "3b8a99af0b6737a489f84e38da2d3985f7d8ce99", "best_bid": "0.62", "best_ask": "0.65"}], "timestamp": "1769384542976", "event_type": "price_change"}}
{"_local_timestamp": "2026-01-25T23:42:23.131266+00:00", "data": {"market": "0x2a4d3cf51d27425b0c51d241a7ba6bc44dd27034b44f9e437624f9e0953b1ea9", "price_changes": [{"asset_id": "58599269208124653793682124721644272657448822176028066253503704155842141815443", "price": "0.25", "size": "60.13", "side": "BUY", "hash": "ce4d0e62ef9ea96e4e28b3cbefcbe6ef28731d3a", "best_bid": "0.35", "best_ask": "0.38"}, {"asset_id": "111798086980787121079742248333092569415172137759139099190565410999420761499752", "price": "0.75", "size": "60.13", "side": "SELL", "hash": "4e58517e9597058e6865ffb3ae167587a2e5f774", "best_bid": "0.62", "best_ask": "0.65"}], "timestamp": "1769384543003", "event_type": "price_change"}}
{"_local_timestamp": "2026-01-25T23:42:23.144893+00:00", "data": {"market": "0x2a4d3cf51d27425b0c51d241a7ba6bc44dd27034b44f9e437624f9e0953b1ea9", "price_changes": [{"asset_id": "111798086980787121079742248333092569415172137759139099190565410999420761499752", "price": "0.27", "size": "150", "side": "BUY", "hash": "17240879a1113b233e619d87b40320c7f8819948", "best_bid": "0.62", "best_ask": "0.65"}, {"asset_id": "58599269208124653793682124721644272657448822176028066253503704155842141815443", "price": "0.73", "size": "150", "side": "SELL", "hash": "61825e75bca459e7430653133fbc00d137a6b767", "best_bid": "0.35", "best_ask": "0.38"}], "timestamp": "1769384543012", "event_type": "price_change"}}
{"_local_timestamp": "2026-01-25T23:42:23.145244+00:00", "data": {"market": "0x2a4d3cf51d27425b0c51d241a7ba6bc44dd27034b44f9e437624f9e0953b1ea9", "price_changes": [{"asset_id": "111798086980787121079742248333092569415172137759139099190565410999420761499752", "price": "0.1", "size": "0", "side": "BUY", "hash": "17240879a1113b233e619d87b40320c7f8819948", "best_bid": "0.62", "best_ask": "0.65"}, {"asset_id": "58599269208124653793682124721644272657448822176028066253503704155842141815443", "price": "0.9", "size": "0", "side": "SELL", "hash": "61825e75bca459e7430653133fbc00d137a6b767", "best_bid": "0.35", "best_ask": "0.38"}], "timestamp": "1769384543012", "event_type": "price_change"}}
{"_local_timestamp": "2026-01-25T23:42:23.145498+00:00", "data": {"market": "0x2a4d3cf51d27425b0c51d241a7ba6bc44dd27034b44f9e437624f9e0953b1ea9", "price_changes": [{"asset_id": "111798086980787121079742248333092569415172137759139099190565410999420761499752", "price": "0.2", "size": "50", "side": "BUY", "hash": "17240879a1113b233e619d87b40320c7f8819948", "best_bid": "0.62", "best_ask": "0.65"}, {"asset_id": "58599269208124653793682124721644272657448822176028066253503704155842141815443", "price": "0.8", "size": "50", "side": "SELL", "hash": "61825e75bca459e7430653133fbc00d137a6b767", "best_bid": "0.35", "best_ask": "0.38"}], "timestamp": "1769384543012", "event_type": "price_change"}}
{"_local_timestamp": "2026-01-25T23:42:23.145743+00:00", "data": {"market": "0x2a4d3cf51d27425b0c51d241a7ba6bc44dd27034b44f9e437624f9e0953b1ea9", "price_changes": [{"asset_id": "111798086980787121079742248333092569415172137759139099190565410999420761499752", "price": "0.23", "size": "0", "side": "BUY", "hash": "17240879a1113b233e619d87b40320c7f8819948", "best_bid": "0.62", "best_ask": "0.65"}, {"asset_id": "58599269208124653793682124721644272657448822176028066253503704155842141815443", "price": "0.77", "size": "0", "side": "SELL", "hash": "61825e75bca459e7430653133fbc00d137a6b767", "best_bid": "0.35", "best_ask": "0.38"}], "timestamp": "1769384543012", "event_type": "price_change"}}
{"_local_timestamp": "2026-01-25T23:42:23.146019+00:00", "data": {"market": "0x2a4d3cf51d27425b0c51d241a7ba6bc44dd27034b44f9e437624f9e0953b1ea9", "price_changes": [{"asset_id": "111798086980787121079742248333092569415172137759139099190565410999420761499752", "price": "0.17", "size": "0", "side": "BUY", "hash": "17240879a1113b233e619d87b40320c7f8819948", "best_bid": "0.62", "best_ask": "0.65"}, {"asset_id": "58599269208124653793682124721644272657448822176028066253503704155842141815443", "price": "0.83", "size": "0", "side": "SELL", "hash": "61825e75bca459e7430653133fbc00d137a6b767", "best_bid": "0.35", "best_ask": "0.38"}], "timestamp": "1769384543012", "event_type": "price_change"}}
{"_local_timestamp": "2026-01-25T23:42:23.146278+00:00", "data": {"market": "0x2a4d3cf51d27425b0c51d241a7ba6bc44dd27034b44f9e437624f9e0953b1ea9", "price_changes": [{"asset_id": "111798086980787121079742248333092569415172137759139099190565410999420761499752", "price": "0.07", "size": "300", "side": "BUY", "hash": "17240879a1113b233e619d87b40320c7f8819948", "best_bid": "0.62", "best_ask": "0.65"}, {"asset_id": "58599269208124653793682124721644272657448822176028066253503704155842141815443", "price": "0.93", "size": "300", "side": "SELL", "hash": "61825e75bca459e7430653133fbc00d137a6b767", "best_bid": "0.35", "best_ask": "0.38"}], "timestamp": "1769384543012", "event_type": "price_change"}}
{"_local_timestamp": "2026-01-25T23:42:23.146491+00:00", "data": {"market": "0x2a4d3cf51d27425b0c51d241a7ba6bc44dd27034b44f9e437624f9e0953b1ea9", "price_changes": [{"asset_id": "111798086980787121079742248333092569415172137759139099190565410999420761499752", "price": "0.13", "size": "325", "side": "BUY", "hash": "17240879a1113b233e619d87b40320c7f8819948", "best_bid": "0.62", "best_ask": "0.65"}, {"asset_id": "58599269208124653793682124721644272657448822176028066253503704155842141815443", "price": "0.87", "size": "325", "side": "SELL", "hash": "61825e75bca459e7430653133fbc00d137a6b767", "best_bid": "0.35", "best_ask": "0.38"}], "timestamp": "1769384543012", "event_type": "price_change"}}
{"_local_timestamp": "2026-01-25T23:42:23.167874+00:00", "data": {"market": "0x2a4d3cf51d27425b0c51d241a7ba6bc44dd27034b44f9e437624f9e0953b1ea9", "price_changes": [{"asset_id": "58599269208124653793682124721644272657448822176028066253503704155842141815443", "price": "0.3", "size": "136.13", "side": "BUY", "hash": "add607e65a83541a368abc19a70c57420763d0a9", "best_bid": "0.35", "best_ask": "0.38"}, {"asset_id": "111798086980787121079742248333092569415172137759139099190565410999420761499752", "price": "0.7", "size": "136.13", "side": "SELL", "hash": "66f8d724a1796e8b80daff2ff886879385acacec", "best_bid": "0.62", "best_ask": "0.65"}], "timestamp": "1769384543027", "event_type": "price_change"}}
{"_local_timestamp": "2026-01-25T23:42:23.179470+00:00", "data": {"market": "0x7f6dadade6357d3ce6681860d002bd3521554aba8b5acda912917b3db41c9549", "price_changes": [{"asset_id": "112538531010841097813690615473978896934576951101485955663285389253633812461690", "price": "0.49", "size": "13.33", "side": "BUY", "hash": "7c9e4eccf4bd251cb85970a5182d614b269a5048", "best_bid": "0.72", "best_ask": "0.78"}, {"asset_id": "50613703516194910329561493534058464924948966095615247532634099427569284124317", "price": "0.51", "size": "13.33", "side": "SELL", "hash": "7870d1c4f94ee0a86e152bd10185d4e4c94ebed9", "best_bid": "0.22", "best_ask": "0.28"}], "timestamp": "1769384543045", "event_type": "price_change"}}
{"_local_timestamp": "2026-01-25T23:42:23.183897+00:00", "data": {"market": "0x7f6dadade6357d3ce6681860d002bd3521554aba8b5acda912917b3db41c9549", "price_changes": [{"asset_id": "112538531010841097813690615473978896934576951101485955663285389253633812461690", "price": "0.25", "size": "13.33", "side": "BUY", "hash": "c1c87db8eab703810ae68c01126216845a6f756f", "best_bid": "0.72", "best_ask": "0.78"}, {"asset_id": "50613703516194910329561493534058464924948966095615247532634099427569284124317", "price": "0.75", "size": "13.33", "side": "SELL", "hash": "62d06f13b71cf5e745fe95a5eaf9bd77f59c4d60", "best_bid": "0.22", "best_ask": "0.28"}], "timestamp": "1769384543056", "event_type": "price_change"}}
{"_local_timestamp": "2026-01-25T23:42:23.184271+00:00", "data": {"market": "0x2a4d3cf51d27425b0c51d241a7ba6bc44dd27034b44f9e437624f9e0953b1ea9", "price_changes": [{"asset_id": "111798086980787121079742248333092569415172137759139099190565410999420761499752", "price": "0.26", "size": "76.92", "side": "BUY", "hash": "02d798cf8f7405b790f10e2c1795957d6c3a0d06", "best_bid": "0.62", "best_ask": "0.65"}, {"asset_id": "58599269208124653793682124721644272657448822176028066253503704155842141815443", "price": "0.74", "size": "76.92", "side": "SELL", "hash": "4b8cc317e80af7be9e8c7e2dd64f82e56164edd6", "best_bid": "0.35", "best_ask": "0.38"}], "timestamp": "1769384543063", "event_type": "price_change"}}
{"_local_timestamp": "2026-01-25T23:42:23.199567+00:00", "data": {"market": "0x0a9f1c94b012a39a2a91b877b24c15f25ffd1ee68df65a79c12e5fac82519865", "price_changes": [{"asset_id": "92197810663257226642496081056291543161006633887475519374142132133821877068692", "price": "0.77", "size": "100", "side": "BUY", "hash": "f5ce5e2e63c2dae71ff0f9f4141f1cdab84b866c", "best_bid": "0.87", "best_ask": "0.94"}, {"asset_id": "73641960431177563453506958377488026157202817565843589479879428094129866219922", "price": "0.23", "size": "100", "side": "SELL", "hash": "c504c6b05eb5fce552d8fb8bfdead0d71adb93d4", "best_bid": "0.06", "best_ask": "0.13"}], "timestamp": "1769384543086", "event_type": "price_change"}}
{"_local_timestamp": "2026-01-25T23:42:23.199941+00:00", "data": {"market": "0x2a4d3cf51d27425b0c51d241a7ba6bc44dd27034b44f9e437624f9e0953b1ea9", "price_changes": [{"asset_id": "111798086980787121079742248333092569415172137759139099190565410999420761499752", "price": "0.53", "size": "106", "side": "BUY", "hash": "af4889e1955aa7e24216274dee61d89c3dab4a22", "best_bid": "0.62", "best_ask": "0.65"}, {"asset_id": "58599269208124653793682124721644272657448822176028066253503704155842141815443", "price": "0.47", "size": "106", "side": "SELL", "hash": "b3aa4adf6386c5d1484212f687e715c2e46b3f53", "best_bid": "0.35", "best_ask": "0.38"}], "timestamp": "1769384543097", "event_type": "price_change"}}
{"_local_timestamp": "2026-01-25T23:42:23.206110+00:00", "data": {"market": "0x2a4d3cf51d27425b0c51d241a7ba6bc44dd27034b44f9e437624f9e0953b1ea9", "price_changes": [{"asset_id": "111798086980787121079742248333092569415172137759139099190565410999420761499752", "price": "0.23", "size": "104.34", "side": "BUY", "hash": "1f8d2e5b3e1119ff3038f76df235cbea56e7870e", "best_bid": "0.62", "best_ask": "0.65"}, {"asset_id": "58599269208124653793682124721644272657448822176028066253503704155842141815443", "price": "0.77", "size": "104.34", "side": "SELL", "hash": "fe8155a01dcff0b03a3e73a77ba74fdfc5b617ac", "best_bid": "0.35", "best_ask": "0.38"}], "timestamp": "1769384543101", "event_type": "price_change"}}
{"_local_timestamp": "2026-01-25T23:42:23.206487+00:00", "data": {"market": "0x2a4d3cf51d27425b0c51d241a7ba6bc44dd27034b44f9e437624f9e0953b1ea9", "price_changes": [{"asset_id": "111798086980787121079742248333092569415172137759139099190565410999420761499752", "price": "0.58", "size": "100", "side": "BUY", "hash": "2cffd0f59ba8ac62a9d4a163b74b4834ea11b329", "best_bid": "0.62", "best_ask": "0.65"}, {"asset_id": "58599269208124653793682124721644272657448822176028066253503704155842141815443", "price": "0.42", "size": "100", "side": "SELL", "hash": "049b33d2770d54818832d4df66d888bc62ff174e", "best_bid": "0.35", "best_ask": "0.38"}], "timestamp": "1769384543104", "event_type": "price_change"}}
{"_local_timestamp": "2026-01-25T23:42:23.247902+00:00", "data": {"market": "0x2a4d3cf51d27425b0c51d241a7ba6bc44dd27034b44f9e437624f9e0953b1ea9", "price_changes": [{"asset_id": "111798086980787121079742248333092569415172137759139099190565410999420761499752", "price": "0.2", "size": "180", "side": "BUY", "hash": "e24d6ca94fdd1263e30b2f39fc7e62d04c8bca73", "best_bid": "0.62", "best_ask": "0.65"}, {"asset_id": "58599269208124653793682124721644272657448822176028066253503704155842141815443", "price": "0.8", "size": "180", "side": "SELL", "hash": "f7e15147ebf76f74da70a140af71617bd8ab39a1", "best_bid": "0.35", "best_ask": "0.38"}], "timestamp": "1769384543141", "event_type": "price_change"}}
{"_local_timestamp": "2026-01-25T23:42:23.293488+00:00", "data": {"market": "0x2a4d3cf51d27425b0c51d241a7ba6bc44dd27034b44f9e437624f9e0953b1ea9", "price_changes": [{"asset_id": "111798086980787121079742248333092569415172137759139099190565410999420761499752", "price": "0.16", "size": "175", "side": "BUY", "hash": "1fe0066a78e94da912dbe8ff12e72f1845e89810", "best_bid": "0.62", "best_ask": "0.65"}, {"asset_id": "58599269208124653793682124721644272657448822176028066253503704155842141815443", "price": "0.84", "size": "175", "side": "SELL", "hash": "75a0f211bfb17f08f301c4d1f13636aee9886e4d", "best_bid": "0.35", "best_ask": "0.38"}], "timestamp": "1769384543194", "event_type": "price_change"}}
{"_local_timestamp": "2026-01-25T23:42:23.318839+00:00", "data": {"market": "0x0a9f1c94b012a39a2a91b877b24c15f25ffd1ee68df65a79c12e5fac82519865", "price_changes": [{"asset_id": "73641960431177563453506958377488026157202817565843589479879428094129866219922", "price": "0.7", "size": "199.99", "side": "SELL", "hash": "9f2252e627255dcffade42bb917dfe975f839ad7", "best_bid": "0.06", "best_ask": "0.13"}, {"asset_id": "92197810663257226642496081056291543161006633887475519374142132133821877068692", "price": "0.3", "size": "199.99", "side": "BUY", "hash": "81a718b7ba8fc12b7cf607cb6fd25427eb8d2ed4", "best_bid": "0.87", "best_ask": "0.94"}], "timestamp": "1769384543215", "event_type": "price_change"}}
{"_local_timestamp": "2026-01-25T23:42:23.330639+00:00", "data": {"market": "0x2a4d3cf51d27425b0c51d241a7ba6bc44dd27034b44f9e437624f9e0953b1ea9", "price_changes": [{"asset_id": "111798086980787121079742248333092569415172137759139099190565410999420761499752", "price": "0.13", "size": "571.15", "side": "BUY", "hash": "d83ce8b9de2d632506ce35aec489815778863284", "best_bid": "0.62", "best_ask": "0.65"}, {"asset_id": "58599269208124653793682124721644272657448822176028066253503704155842141815443", "price": "0.87", "size": "571.15", "side": "SELL", "hash": "66c242ad3594c942d01ba42259d895eaa496ae92", "best_bid": "0.35", "best_ask": "0.38"}], "timestamp": "1769384543239", "event_type": "price_change"}}
{"_local_timestamp": "2026-01-25T23:42:23.356069+00:00", "data": {"market": "0x0a9f1c94b012a39a2a91b877b24c15f25ffd1ee68df65a79c12e5fac82519865", "price_changes": [{"asset_id": "92197810663257226642496081056291543161006633887475519374142132133821877068692", "price": "0.69", "size": "0", "side": "BUY", "hash": "35c29e0420e1c51f8f97715fd00e4d0adc3f8524", "best_bid": "0.87", "best_ask": "0.94"}, {"asset_id": "73641960431177563453506958377488026157202817565843589479879428094129866219922", "price": "0.31", "size": "0", "side": "SELL", "hash": "fb51b691c7dddc54e1874143e6e9b0c8713a435a", "best_bid": "0.06", "best_ask": "0.13"}], "timestamp": "1769384543255", "event_type": "price_change"}}
{"_local_timestamp": "2026-01-25T23:42:23.388323+00:00", "data": {"market": "0x2a4d3cf51d27425b0c51d241a7ba6bc44dd27034b44f9e437624f9e0953b1ea9", "price_changes": [{"asset_id": "111798086980787121079742248333092569415172137759139099190565410999420761499752", "price": "0.1", "size": "340", "side": "BUY", "hash": "56e8f5fb94ae5b65fefda905a8d71b3be34f8890", "best_bid": "0.62", "best_ask": "0.65"}, {"asset_id": "58599269208124653793682124721644272657448822176028066253503704155842141815443", "price": "0.9", "size": "340", "side": "SELL", "hash": "182627e25b2f0e2f4054297d64d11fd6526b73db", "best_bid": "0.35", "best_ask": "0.38"}], "timestamp": "1769384543287", "event_type": "price_change"}}
{"_local_timestamp": "2026-01-25T23:42:23.426311+00:00", "data": {"market": "0x2a4d3cf51d27425b0c51d241a7ba6bc44dd27034b44f9e437624f9e0953b1ea9", "price_changes": [{"asset_id": "111798086980787121079742248333092569415172137759139099190565410999420761499752", "price": "0.06", "size": "1400", "side": "BUY", "hash": "f24c236b12e83e36f11d8873c5fa596fe306e7e5", "best_bid": "0.62", "best_ask": "0.65"}, {"asset_id": "58599269208124653793682124721644272657448822176028066253503704155842141815443", "price": "0.94", "size": "1400", "side": "SELL", "hash": "88416d75cbfdbd8cb3742d0fc964503b389dbff4", "best_bid": "0.35", "best_ask": "0.38"}], "timestamp": "1769384543334", "event_type": "price_change"}}
{"_local_timestamp": "2026-01-25T23:42:23.786230+00:00", "data": {"market": "0x0a9f1c94b012a39a2a91b877b24c15f25ffd1ee68df65a79c12e5fac82519865", "price_changes": [{"asset_id": "92197810663257226642496081056291543161006633887475519374142132133821877068692", "price": "0.3", "size": "299.99", "side": "BUY", "hash": "53a9457a67f5594fd559700a799fcc36e182f32e", "best_bid": "0.87", "best_ask": "0.94"}, {"asset_id": "73641960431177563453506958377488026157202817565843589479879428094129866219922", "price": "0.7", "size": "299.99", "side": "SELL", "hash": "406acc6f3023796d3b4f2f3e6801b787af3e31a7", "best_bid": "0.06", "best_ask": "0.13"}], "timestamp": "1769384543683", "event_type": "price_change"}}
{"_local_timestamp": "2026-01-25T23:42:23.819632+00:00", "data": {"market": "0x0a9f1c94b012a39a2a91b877b24c15f25ffd1ee68df65a79c12e5fac82519865", "price_changes": [{"asset_id": "73641960431177563453506958377488026157202817565843589479879428094129866219922", "price": "0.21", "size": "0", "side": "SELL", "hash": "dc754c4fccff37e94df5ed4226a8f567cf94c063", "best_bid": "0.06", "best_ask": "0.13"}, {"asset_id": "92197810663257226642496081056291543161006633887475519374142132133821877068692", "price": "0.79", "size": "0", "side": "BUY", "hash": "d9d7797fd5011aaaf1c26d1fbbc2edb8f2c3e76c", "best_bid": "0.87", "best_ask": "0.94"}], "timestamp": "1769384543716", "event_type": "price_change"}}
{"_local_timestamp": "2026-01-25T23:42:23.842644+00:00", "data": {"market": "0x0a9f1c94b012a39a2a91b877b24c15f25ffd1ee68df65a79c12e5fac82519865", "price_changes": [{"asset_id": "73641960431177563453506958377488026157202817565843589479879428094129866219922", "price": "0.2", "size": "191", "side": "SELL", "hash": "de6432ca42cea0ceb8d9edbe7e257a71e01091a0", "best_bid": "0.06", "best_ask": "0.13"}, {"asset_id": "92197810663257226642496081056291543161006633887475519374142132133821877068692", "price": "0.8", "size": "191", "side": "BUY", "hash": "b98edd2bab279ece6b5a53b1dee7e3cc2d87fbc4", "best_bid": "0.87", "best_ask": "0.94"}], "timestamp": "1769384543743", "event_type": "price_change"}}
{"_local_timestamp": "2026-01-25T23:42:23.850235+00:00", "data": {"market": "0x2a4d3cf51d27425b0c51d241a7ba6bc44dd27034b44f9e437624f9e0953b1ea9", "price_changes": [{"asset_id": "111798086980787121079742248333092569415172137759139099190565410999420761499752", "price": "0.56", "size": "6", "side": "BUY", "hash": "77945e186a01f2e69b924004b3dd556ec0d60285", "best_bid": "0.62", "best_ask": "0.65"}, {"asset_id": "58599269208124653793682124721644272657448822176028066253503704155842141815443", "price": "0.44", "size": "6", "side": "SELL", "hash": "32a8f02faf39a1fe6012045d8ed08b0303f508d3", "best_bid": "0.35", "best_ask": "0.38"}], "timestamp": "1769384543747", "event_type": "price_change"}}
{"_local_timestamp": "2026-01-25T23:42:23.874228+00:00", "data": {"market": "0x2a4d3cf51d27425b0c51d241a7ba6bc44dd27034b44f9e437624f9e0953b1ea9", "price_changes": [{"asset_id": "111798086980787121079742248333092569415172137759139099190565410999420761499752", "price": "0.59", "size": "72", "side": "BUY", "hash": "e0cf7916166abe6749cf3235e4ea77eb63aa8f0f", "best_bid": "0.62", "best_ask": "0.65"}, {"asset_id": "58599269208124653793682124721644272657448822176028066253503704155842141815443", "price": "0.41", "size": "72", "side": "SELL", "hash": "c725df5c044c8a7ec2179c56555ada75716f3374", "best_bid": "0.35", "best_ask": "0.38"}], "timestamp": "1769384543772", "event_type": "price_change"}}
{"_local_timestamp": "2026-01-25T23:42:24.614583+00:00", "data": {"market": "0x7f6dadade6357d3ce6681860d002bd3521554aba8b5acda912917b3db41c9549", "price_changes": [{"asset_id": "112538531010841097813690615473978896934576951101485955663285389253633812461690", "price": "0.12", "size": "483.33", "side": "BUY", "hash": "e66327c3cbe0370284fe93748fb1b4fc7402efa7", "best_bid": "0.72", "best_ask": "0.78"}, {"asset_id": "50613703516194910329561493534058464924948966095615247532634099427569284124317", "price": "0.88", "size": "483.33", "side": "SELL", "hash": "4958e33a0b3af543330b64cd36ed62d7d7a7d067", "best_bid": "0.22", "best_ask": "0.28"}], "timestamp": "1769384544479", "event_type": "price_change"}}
{"_local_timestamp": "2026-01-25T23:42:24.616909+00:00", "data": {"market": "0x7f6dadade6357d3ce6681860d002bd3521554aba8b5acda912917b3db41c9549", "price_changes": [{"asset_id": "112538531010841097813690615473978896934576951101485955663285389253633812461690", "price": "0.24", "size": "208.33", "side": "BUY", "hash": "e66327c3cbe0370284fe93748fb1b4fc7402efa7", "best_bid": "0.72", "best_ask": "0.78"}, {"asset_id": "50613703516194910329561493534058464924948966095615247532634099427569284124317", "price": "0.76", "size": "208.33", "side": "SELL", "hash": "4958e33a0b3af543330b64cd36ed62d7d7a7d067", "best_bid": "0.22", "best_ask": "0.28"}], "timestamp": "1769384544479", "event_type": "price_change"}}
{"_local_timestamp": "2026-01-25T23:42:24.617241+00:00", "data": {"market": "0x7f6dadade6357d3ce6681860d002bd3521554aba8b5acda912917b3db41c9549", "price_changes": [{"asset_id": "112538531010841097813690615473978896934576951101485955663285389253633812461690", "price": "0.16", "size": "350", "side": "BUY", "hash": "e66327c3cbe0370284fe93748fb1b4fc7402efa7", "best_bid": "0.72", "best_ask": "0.78"}, {"asset_id": "50613703516194910329561493534058464924948966095615247532634099427569284124317", "price": "0.84", "size": "350", "side": "SELL", "hash": "4958e33a0b3af543330b64cd36ed62d7d7a7d067", "best_bid": "0.22", "best_ask": "0.28"}], "timestamp": "1769384544479", "event_type": "price_change"}}
{"_local_timestamp": "2026-01-25T23:42:27.105206+00:00", "data": {"market": "0x0a9f1c94b012a39a2a91b877b24c15f25ffd1ee68df65a79c12e5fac82519865", "price_changes": [{"asset_id": "73641960431177563453506958377488026157202817565843589479879428094129866219922", "price": "0.7", "size": "100", "side": "SELL", "hash": "dfe055fe34680c1b507b804fe37e4b73c97b68b2", "best_bid": "0.06", "best_ask": "0.13"}, {"asset_id": "92197810663257226642496081056291543161006633887475519374142132133821877068692", "price": "0.3", "size": "100", "side": "BUY", "hash": "9f676d1a7e9738fcc9fa4a29eac6f4224be86715", "best_bid": "0.87", "best_ask": "0.94"}], "timestamp": "1769384546998", "event_type": "price_change"}}
{"_local_timestamp": "2026-01-25T23:42:27.529294+00:00", "data": {"market": "0x0a9f1c94b012a39a2a91b877b24c15f25ffd1ee68df65a79c12e5fac82519865", "price_changes": [{"asset_id": "73641960431177563453506958377488026157202817565843589479879428094129866219922", "price": "0.19", "size": "199.99", "side": "SELL", "hash": "9d693d3ee36ae46ce22058b290a4bd3cd2272de0", "best_bid": "0.06", "best_ask": "0.13"}, {"asset_id": "92197810663257226642496081056291543161006633887475519374142132133821877068692", "price": "0.81", "size": "199.99", "side": "BUY", "hash": "9065c24e1e501c8f6ba4f66cdd13480487022d86", "best_bid": "0.87", "best_ask": "0.94"}], "timestamp": "1769384547418", "event_type": "price_change"}}
{"_local_timestamp": "2026-01-25T23:42:27.537681+00:00", "data": {"market": "0x0a9f1c94b012a39a2a91b877b24c15f25ffd1ee68df65a79c12e5fac82519865", "price_changes": [{"asset_id": "92197810663257226642496081056291543161006633887475519374142132133821877068692", "price": "0.3", "size": "0", "side": "BUY", "hash": "99cf006d95f8e0c1dcf7f511528434df06b8374a", "best_bid": "0.87", "best_ask": "0.94"}, {"asset_id": "73641960431177563453506958377488026157202817565843589479879428094129866219922", "price": "0.7", "size": "0", "side": "SELL", "hash": "7893ae4d44747a67f87322a197f14d43d57b7fd2", "best_bid": "0.06", "best_ask": "0.13"}], "timestamp": "1769384547430", "event_type": "price_change"}}
{"_local_timestamp": "2026-01-25T23:42:27.563569+00:00", "data": {"market": "0x0a9f1c94b012a39a2a91b877b24c15f25ffd1ee68df65a79c12e5fac82519865", "price_changes": [{"asset_id": "73641960431177563453506958377488026157202817565843589479879428094129866219922", "price": "0.2", "size": "30", "side": "SELL", "hash": "c701736cf3b39c87126fc84ab98cb7173ab4d493", "best_bid": "0.06", "best_ask": "0.13"}, {"asset_id": "92197810663257226642496081056291543161006633887475519374142132133821877068692", "price": "0.8", "size": "30", "side": "BUY", "hash": "5b6916a9b0b8360ccec873cc80ca3bfcf9392ef1", "best_bid": "0.87", "best_ask": "0.94"}], "timestamp": "1769384547449", "event_type": "price_change"}}
{"_local_timestamp": "2026-01-25T23:42:27.585119+00:00", "data": {"market": "0x0a9f1c94b012a39a2a91b877b24c15f25ffd1ee68df65a79c12e5fac82519865", "price_changes": [{"asset_id": "73641960431177563453506958377488026157202817565843589479879428094129866219922", "price": "0.18", "size": "159", "side": "SELL", "hash": "dfffd7ad7065d778edd645c63a8a990ad2fc60d3", "best_bid": "0.06", "best_ask": "0.13"}, {"asset_id": "92197810663257226642496081056291543161006633887475519374142132133821877068692", "price": "0.82", "size": "159", "side": "BUY", "hash": "652aae54e1c3c98098a0d20e5bc0e8cc26ddc942", "best_bid": "0.87", "best_ask": "0.94"}], "timestamp": "1769384547476", "event_type": "price_change"}}
{"_local_timestamp": "2026-01-25T23:42:27.870050+00:00", "data": {"market": "0x0a9f1c94b012a39a2a91b877b24c15f25ffd1ee68df65a79c12e5fac82519865", "price_changes": [{"asset_id": "73641960431177563453506958377488026157202817565843589479879428094129866219922", "price": "0.2", "size": "0", "side": "SELL", "hash": "1d8d81b7aae0811f5256316852f66e805abc2afa", "best_bid": "0.06", "best_ask": "0.13"}, {"asset_id": "92197810663257226642496081056291543161006633887475519374142132133821877068692", "price": "0.8", "size": "0", "side": "BUY", "hash": "626c3f7861b0fd9e74e8ed8fdc7c252ac27b49b5", "best_bid": "0.87", "best_ask": "0.94"}], "timestamp": "1769384547758", "event_type": "price_change"}}
{"_local_timestamp": "2026-01-25T23:42:28.218780+00:00", "data": {"market": "0x0a9f1c94b012a39a2a91b877b24c15f25ffd1ee68df65a79c12e5fac82519865", "price_changes": [{"asset_id": "92197810663257226642496081056291543161006633887475519374142132133821877068692", "price": "0.81", "size": "299.99", "side": "BUY", "hash": "3031c6df8f9e19643237c6c5fd4ed18e979f31a7", "best_bid": "0.87", "best_ask": "0.94"}, {"asset_id": "73641960431177563453506958377488026157202817565843589479879428094129866219922", "price": "0.19", "size": "299.99", "side": "SELL", "hash": "9fc3fb1c4ea07804848b1fba2069370daf238735", "best_bid": "0.06", "best_ask": "0.13"}], "timestamp": "1769384548107", "event_type": "price_change"}}
{"_local_timestamp": "2026-01-25T23:42:28.282283+00:00", "data": {"market": "0x0a9f1c94b012a39a2a91b877b24c15f25ffd1ee68df65a79c12e5fac82519865", "price_changes": [{"asset_id": "73641960431177563453506958377488026157202817565843589479879428094129866219922", "price": "0.17", "size": "30", "side": "SELL", "hash": "cab10b1cfa088e3fba4398b8884eaf3f112d3b35", "best_bid": "0.06", "best_ask": "0.13"}, {"asset_id": "92197810663257226642496081056291543161006633887475519374142132133821877068692", "price": "0.83", "size": "30", "side": "BUY", "hash": "7ec31faf72c0824888775038e367b7bc45c9d621", "best_bid": "0.87", "best_ask": "0.94"}], "timestamp": "1769384548188", "event_type": "price_change"}}
{"_local_timestamp": "2026-01-25T23:42:29.001439+00:00", "data": {"market": "0x0a9f1c94b012a39a2a91b877b24c15f25ffd1ee68df65a79c12e5fac82519865", "price_changes": [{"asset_id": "73641960431177563453506958377488026157202817565843589479879428094129866219922", "price": "0.18", "size": "0", "side": "SELL", "hash": "11df4981bb17a188120c9808338ed53396e74bb0", "best_bid": "0.06", "best_ask": "0.13"}, {"asset_id": "92197810663257226642496081056291543161006633887475519374142132133821877068692", "price": "0.82", "size": "0", "side": "BUY", "hash": "357251083dec2f98cd2ccb0e592e3a2a918f9d0b", "best_bid": "0.87", "best_ask": "0.94"}], "timestamp": "1769384548883", "event_type": "price_change"}}
{"_local_timestamp": "2026-01-25T23:42:29.016511+00:00", "data": {"market": "0x0a9f1c94b012a39a2a91b877b24c15f25ffd1ee68df65a79c12e5fac82519865", "price_changes": [{"asset_id": "73641960431177563453506958377488026157202817565843589479879428094129866219922", "price": "0.17", "size": "190", "side": "SELL", "hash": "4874c0c15010d2ab1db14f7ac7647c9bb06144a1", "best_bid": "0.06", "best_ask": "0.13"}, {"asset_id": "92197810663257226642496081056291543161006633887475519374142132133821877068692", "price": "0.83", "size": "190", "side": "BUY", "hash": "7a87fc690346abaf706afad150fa907e0a08ebf4", "best_bid": "0.87", "best_ask": "0.94"}], "timestamp": "1769384548909", "event_type": "price_change"}}
{"_local_timestamp": "2026-01-25T23:42:29.059404+00:00", "data": {"market": "0x1a65d4eb8ac985309e78b48906291fffbf137cee590d8d75365f77a0549e9ab9", "price_changes": [{"asset_id": "48953332818425460061045724981972442660997032539861914953015827526728376958623", "price": "0.33", "size": "77.61", "side": "SELL", "hash": "ec550ade1a3d19fd86c1a798600049bd39b03852", "best_bid": "0.29", "best_ask": "0.33"}, {"asset_id": "81870625725474135545086561756714985203836689747059214375533433096496527904265", "price": "0.67", "size": "77.61", "side": "BUY", "hash": "926ecf067ac43ea0b5fb8d207235535dc89c846f", "best_bid": "0.67", "best_ask": "0.71"}], "timestamp": "1769384548932", "event_type": "price_change"}}
{"_local_timestamp": "2026-01-25T23:42:29.059747+00:00", "data": {"market": "0x1a65d4eb8ac985309e78b48906291fffbf137cee590d8d75365f77a0549e9ab9", "price_changes": [{"asset_id": "48953332818425460061045724981972442660997032539861914953015827526728376958623", "price": "0.33", "size": "88.56", "side": "SELL", "hash": "a992037b04757adbb793657bd240bd95e95f4e39", "best_bid": "0.29", "best_ask": "0.33"}, {"asset_id": "81870625725474135545086561756714985203836689747059214375533433096496527904265", "price": "0.67", "size": "88.56", "side": "BUY", "hash": "e740a5cf1d701fc965b3793811d7a2bf54fc875b", "best_bid": "0.67", "best_ask": "0.71"}], "timestamp": "1769384548933", "event_type": "price_change"}}
{"_local_timestamp": "2026-01-25T23:42:29.492708+00:00", "data": {"market": "0x0a9f1c94b012a39a2a91b877b24c15f25ffd1ee68df65a79c12e5fac82519865", "price_changes": [{"asset_id": "73641960431177563453506958377488026157202817565843589479879428094129866219922", "price": "0.17", "size": "160", "side": "SELL", "hash": "5ca8ba2e0057c9bf142d60e6eca72c66a57b9923", "best_bid": "0.06", "best_ask": "0.13"}, {"asset_id": "92197810663257226642496081056291543161006633887475519374142132133821877068692", "price": "0.83", "size": "160", "side": "BUY", "hash": "2f9166e8fe59228f40d4d1aa8a864cf8ac5d7400", "best_bid": "0.87", "best_ask": "0.94"}], "timestamp": "1769384549391", "event_type": "price_change"}}
{"_local_timestamp": "2026-01-25T23:42:29.566004+00:00", "data": {"market": "0x0a9f1c94b012a39a2a91b877b24c15f25ffd1ee68df65a79c12e5fac82519865", "price_changes": [{"asset_id": "73641960431177563453506958377488026157202817565843589479879428094129866219922", "price": "0.18", "size": "30", "side": "SELL", "hash": "92402d5eea81d9290b51dfde86d2115f5e24d340", "best_bid": "0.06", "best_ask": "0.13"}, {"asset_id": "92197810663257226642496081056291543161006633887475519374142132133821877068692", "price": "0.82", "size": "30", "side": "BUY", "hash": "4b89bb56c4e5676cdb60ed672cfca0c0d16f4ca4", "best_bid": "0.87", "best_ask": "0.94"}], "timestamp": "1769384549472", "event_type": "price_change"}}
{"_local_timestamp": "2026-01-25T23:42:30.226785+00:00", "data": {"market": "0x0a9f1c94b012a39a2a91b877b24c15f25ffd1ee68df65a79c12e5fac82519865", "price_changes": [{"asset_id": "73641960431177563453506958377488026157202817565843589479879428094129866219922", "price": "0.18", "size": "0", "side": "SELL", "hash": "95a5afd8c36a22b63ea7c787759adbf92f20c79e", "best_bid": "0.06", "best_ask": "0.13"}, {"asset_id": "92197810663257226642496081056291543161006633887475519374142132133821877068692", "price": "0.82", "size": "0", "side": "BUY", "hash": "9d289fd16d86cc78363556b5652b39e6da84407b", "best_bid": "0.87", "best_ask": "0.94"}], "timestamp": "1769384550123", "event_type": "price_change"}}
{"_local_timestamp": "2026-01-25T23:42:30.314162+00:00", "data": {"market": "0x0a9f1c94b012a39a2a91b877b24c15f25ffd1ee68df65a79c12e5fac82519865", "price_changes": [{"asset_id": "73641960431177563453506958377488026157202817565843589479879428094129866219922", "price": "0.16", "size": "30", "side": "SELL", "hash": "c031894126171b11a0b2e4bd019b52144a0084a3", "best_bid": "0.06", "best_ask": "0.13"}, {"asset_id": "92197810663257226642496081056291543161006633887475519374142132133821877068692", "price": "0.84", "size": "30", "side": "BUY", "hash": "6f251ccc3e4ac551280037dd8aa0bb8751047f4c", "best_bid": "0.87", "best_ask": "0.94"}], "timestamp": "1769384550213", "event_type": "price_change"}}
{"_local_timestamp": "2026-01-25T23:42:30.337948+00:00", "data": {"market": "0x0a9f1c94b012a39a2a91b877b24c15f25ffd1ee68df65a79c12e5fac82519865", "price_changes": [{"asset_id": "73641960431177563453506958377488026157202817565843589479879428094129866219922", "price": "0.17", "size": "0", "side": "SELL", "hash": "cf79f1e7e5b9f0704877b450d6b96cf62762bce6", "best_bid": "0.06", "best_ask": "0.13"}, {"asset_id": "92197810663257226642496081056291543161006633887475519374142132133821877068692", "price": "0.83", "size": "0", "side": "BUY", "hash": "9aa28dfc21b0769537eed9938336bc65e5319b53", "best_bid": "0.87", "best_ask": "0.94"}], "timestamp": "1769384550236", "event_type": "price_change"}}
{"_local_timestamp": "2026-01-25T23:42:30.348775+00:00", "data": {"market": "0x0a9f1c94b012a39a2a91b877b24c15f25ffd1ee68df65a79c12e5fac82519865", "price_changes": [{"asset_id": "92197810663257226642496081056291543161006633887475519374142132133821877068692", "price": "0.83", "size": "30", "side": "BUY", "hash": "9786ee67bbd49c259689f4804573ce00f541d633", "best_bid": "0.87", "best_ask": "0.94"}, {"asset_id": "73641960431177563453506958377488026157202817565843589479879428094129866219922", "price": "0.17", "size": "30", "side": "SELL", "hash": "1ac60cefc3a23dc505df51ff01f63bc20fa70309", "best_bid": "0.06", "best_ask": "0.13"}], "timestamp": "1769384550253", "event_type": "price_change"}}
{"_local_timestamp": "2026-01-25T23:42:30.374684+00:00", "data": {"market": "0x0a9f1c94b012a39a2a91b877b24c15f25ffd1ee68df65a79c12e5fac82519865", "price_changes": [{"asset_id": "73641960431177563453506958377488026157202817565843589479879428094129866219922", "price": "0.16", "size": "191", "side": "SELL", "hash": "80b1360133c2179ad296bfabc9dd7509d7bfb556", "best_bid": "0.06", "best_ask": "0.13"}, {"asset_id": "92197810663257226642496081056291543161006633887475519374142132133821877068692", "price": "0.84", "size": "191", "side": "BUY", "hash": "e1b9226b1e1ae50720eddb7e687d7a2af819006a", "best_bid": "0.87", "best_ask": "0.94"}], "timestamp": "1769384550274", "event_type": "price_change"}}
{"_local_timestamp": "2026-01-25T23:42:31.268631+00:00", "data": {"market": "0x0a9f1c94b012a39a2a91b877b24c15f25ffd1ee68df65a79c12e5fac82519865", "price_changes": [{"asset_id": "92197810663257226642496081056291543161006633887475519374142132133821877068692", "price": "0.83", "size": "0", "side": "BUY", "hash": "1dbfc3d83137b31cc2a5848f93e92093319a77d7", "best_bid": "0.87", "best_ask": "0.94"}, {"asset_id": "73641960431177563453506958377488026157202817565843589479879428094129866219922", "price": "0.17", "size": "0", "side": "SELL", "hash": "97a69750ec8767787dbbb9b3aca7e3dcd0b1681d", "best_bid": "0.06", "best_ask": "0.13"}], "timestamp": "1769384551172", "event_type": "price_change"}}
{"_local_timestamp": "2026-01-25T23:42:31.517104+00:00", "data": {"market": "0x0a9f1c94b012a39a2a91b877b24c15f25ffd1ee68df65a79c12e5fac82519865", "price_changes": [{"asset_id": "73641960431177563453506958377488026157202817565843589479879428094129866219922", "price": "0.19", "size": "100", "side": "SELL", "hash": "843a431b5be6c9b4fa67d804f01774fd0260e403", "best_bid": "0.06", "best_ask": "0.13"}, {"asset_id": "92197810663257226642496081056291543161006633887475519374142132133821877068692", "price": "0.81", "size": "100", "side": "BUY", "hash": "43c02e8f2cbe634698fb2ff5b569677330952bf3", "best_bid": "0.87", "best_ask": "0.94"}], "timestamp": "1769384551417", "event_type": "price_change"}}
{"_local_timestamp": "2026-01-25T23:42:31.668904+00:00", "data": {"market": "0x0a9f1c94b012a39a2a91b877b24c15f25ffd1ee68df65a79c12e5fac82519865", "price_changes": [{"asset_id": "92197810663257226642496081056291543161006633887475519374142132133821877068692", "price": "0.84", "size": "221", "side": "BUY", "hash": "be3d82705ae8e094cd0617c71ac3e5a27fa79a66", "best_bid": "0.87", "best_ask": "0.94"}, {"asset_id": "73641960431177563453506958377488026157202817565843589479879428094129866219922", "price": "0.16", "size": "221", "side": "SELL", "hash": "eb9773f903b6a96b9e98b0fd6e50f60b358d2191", "best_bid": "0.06", "best_ask": "0.13"}], "timestamp": "1769384551564", "event_type": "price_change"}}
{"_local_timestamp": "2026-01-25T23:42:31.866600+00:00", "data": {"market": "0x0a9f1c94b012a39a2a91b877b24c15f25ffd1ee68df65a79c12e5fac82519865", "price_changes": [{"asset_id": "73641960431177563453506958377488026157202817565843589479879428094129866219922", "price": "0.33", "size": "199.99", "side": "SELL", "hash": "c9fc4417b8bdc643a4f0d43724d58091719535c4", "best_bid": "0.06", "best_ask": "0.13"}, {"asset_id": "92197810663257226642496081056291543161006633887475519374142132133821877068692", "price": "0.67", "size": "199.99", "side": "BUY", "hash": "ff88369c23addc402fe074ce2dcd5b9e5f8661e5", "best_bid": "0.87", "best_ask": "0.94"}], "timestamp": "1769384551766", "event_type": "price_change"}}
{"_local_timestamp": "2026-01-25T23:42:31.882168+00:00", "data": {"market": "0x0a9f1c94b012a39a2a91b877b24c15f25ffd1ee68df65a79c12e5fac82519865", "price_changes": [{"asset_id": "92197810663257226642496081056291543161006633887475519374142132133821877068692", "price": "0.81", "size": "0", "side": "BUY", "hash": "16031ed0b0ed6bab25b391dcf3179f97279b62b3", "best_bid": "0.87", "best_ask": "0.94"}, {"asset_id": "73641960431177563453506958377488026157202817565843589479879428094129866219922", "price": "0.19", "size": "0", "side": "SELL", "hash": "7d623ff03800ef470a6bd07f2ded3e76d02dc2f5", "best_bid": "0.06", "best_ask": "0.13"}], "timestamp": "1769384551782", "event_type": "price_change"}}
{"_local_timestamp": "2026-01-25T23:42:32.402775+00:00", "data": {"market": "0x0a9f1c94b012a39a2a91b877b24c15f25ffd1ee68df65a79c12e5fac82519865", "price_changes": [{"asset_id": "92197810663257226642496081056291543161006633887475519374142132133821877068692", "price": "0.67", "size": "299.99", "side": "BUY", "hash": "8c1a7a4b39b3b6eaa45d430713a0ff59be50c4fc", "best_bid": "0.87", "best_ask": "0.94"}, {"asset_id": "73641960431177563453506958377488026157202817565843589479879428094129866219922", "price": "0.33", "size": "299.99", "side": "SELL", "hash": "fe91986d4bc28b586dc484c1a25934fb26d8828d", "best_bid": "0.06", "best_ask": "0.13"}], "timestamp": "1769384552294", "event_type": "price_change"}}
{"_local_timestamp": "2026-01-25T23:42:32.441179+00:00", "data": {"market": "0x0a9f1c94b012a39a2a91b877b24c15f25ffd1ee68df65a79c12e5fac82519865", "price_changes": [{"asset_id": "92197810663257226642496081056291543161006633887475519374142132133821877068692", "price": "0.84", "size": "191", "side": "BUY", "hash": "e0cd8f8905fcdfe6b813907834448f29ce137cae", "best_bid": "0.87", "best_ask": "0.94"}, {"asset_id": "73641960431177563453506958377488026157202817565843589479879428094129866219922", "price": "0.16", "size": "191", "side": "SELL", "hash": "987d4db6474b2a74cc31b3c3d7ac595fb6e790bb", "best_bid": "0.06", "best_ask": "0.13"}], "timestamp": "1769384552329", "event_type": "price_change"}}
{"_local_timestamp": "2026-01-25T23:42:39.746106+00:00", "data": {"market": "0x7f6dadade6357d3ce6681860d002bd3521554aba8b5acda912917b3db41c9549", "price_changes": [{"asset_id": "112538531010841097813690615473978896934576951101485955663285389253633812461690", "price": "0.08", "size": "450", "side": "BUY", "hash": "fcbc27d9b7d215c32da7f02740e1c4aa78e35748", "best_bid": "0.72", "best_ask": "0.78"}, {"asset_id": "50613703516194910329561493534058464924948966095615247532634099427569284124317", "price": "0.92", "size": "450", "side": "SELL", "hash": "ad3616df1aad79b9ace97b9d5ebebb06fa5ea700", "best_bid": "0.22", "best_ask": "0.28"}], "timestamp": "1769384559593", "event_type": "price_change"}}
{"_local_timestamp": "2026-01-25T23:42:52.148622+00:00", "data": {"market": "0x2a4d3cf51d27425b0c51d241a7ba6bc44dd27034b44f9e437624f9e0953b1ea9", "price_changes": [{"asset_id": "58599269208124653793682124721644272657448822176028066253503704155842141815443", "price": "0.04", "size": "3207.64", "side": "BUY", "hash": "47e336b6c92bde4a7e0c894b319f53258aebef17", "best_bid": "0.35", "best_ask": "0.38"}, {"asset_id": "111798086980787121079742248333092569415172137759139099190565410999420761499752", "price": "0.96", "size": "3207.64", "side": "SELL", "hash": "b5cba4b1010ce740662223e5ec1d0b1c0af86ede", "best_bid": "0.62", "best_ask": "0.65"}], "timestamp": "1769384572011", "event_type": "price_change"}}
{"_local_timestamp": "2026-01-25T23:42:55.607319+00:00", "data": {"market": "0x1a65d4eb8ac985309e78b48906291fffbf137cee590d8d75365f77a0549e9ab9", "price_changes": [{"asset_id": "48953332818425460061045724981972442660997032539861914953015827526728376958623", "price": "0.33", "size": "66.66", "side": "SELL", "hash": "4486a050050aa6dc3a60a167a076be2e5d1e6d80", "best_bid": "0.29", "best_ask": "0.33"}, {"asset_id": "81870625725474135545086561756714985203836689747059214375533433096496527904265", "price": "0.67", "size": "66.66", "side": "BUY", "hash": "e6fa763801a983b2e7f8e1c246e59bcf0532e343", "best_bid": "0.67", "best_ask": "0.71"}], "timestamp": "1769384575510", "event_type": "price_change"}}
{"_local_timestamp": "2026-01-25T23:43:07.636761+00:00", "data": {"market": "0x1a65d4eb8ac985309e78b48906291fffbf137cee590d8d75365f77a0549e9ab9", "price_changes": [{"asset_id": "48953332818425460061045724981972442660997032539861914953015827526728376958623", "price": "0.33", "size": "77.61", "side": "SELL", "hash": "7d921794c29a081fe3d5cd81fa223662d4cc2edb", "best_bid": "0.29", "best_ask": "0.33"}, {"asset_id": "81870625725474135545086561756714985203836689747059214375533433096496527904265", "price": "0.67", "size": "77.61", "side": "BUY", "hash": "2421a7b0e650ac6e3391c57c4007498b21c2f101", "best_bid": "0.67", "best_ask": "0.71"}], "timestamp": "1769384587542", "event_type": "price_change"}}
{"_local_timestamp": "2026-01-25T23:43:07.637213+00:00", "data": {"market": "0x1a65d4eb8ac985309e78b48906291fffbf137cee590d8d75365f77a0549e9ab9", "price_changes": [{"asset_id": "48953332818425460061045724981972442660997032539861914953015827526728376958623", "price": "0.33", "size": "88.56", "side": "SELL", "hash": "7b256d13d6a71ca49efabe4c13ecc9d56495e53b", "best_bid": "0.29", "best_ask": "0.33"}, {"asset_id": "81870625725474135545086561756714985203836689747059214375533433096496527904265", "price": "0.67", "size": "88.56", "side": "BUY", "hash": "737afd5c8d9c5c2317b792f6d0c05cd89f15b151", "best_bid": "0.67", "best_ask": "0.71"}], "timestamp": "1769384587542", "event_type": "price_change"}}
{"_local_timestamp": "2026-01-25T23:43:28.944933+00:00", "data": {"market": "0x7f6dadade6357d3ce6681860d002bd3521554aba8b5acda912917b3db41c9549", "price_changes": [{"asset_id": "50613703516194910329561493534058464924948966095615247532634099427569284124317", "price": "0.21", "size": "8.41", "side": "BUY", "hash": "888ea44f81e742ab32a45b13f3d54b849707c9e9", "best_bid": "0.22", "best_ask": "0.28"}, {"asset_id": "112538531010841097813690615473978896934576951101485955663285389253633812461690", "price": "0.79", "size": "8.41", "side": "SELL", "hash": "e5327f76bfc5c09f56eb5953627fda754c9cdf51", "best_bid": "0.72", "best_ask": "0.78"}], "timestamp": "1769384608780", "event_type": "price_change"}}
{"_local_timestamp": "2026-01-25T23:43:28.983095+00:00", "data": {"market": "0x2a4d3cf51d27425b0c51d241a7ba6bc44dd27034b44f9e437624f9e0953b1ea9", "price_changes": [{"asset_id": "58599269208124653793682124721644272657448822176028066253503704155842141815443", "price": "0.32", "size": "0", "side": "BUY", "hash": "52e4f35282a29a5d0647261571b649deaf8e1b24", "best_bid": "0.35", "best_ask": "0.38"}, {"asset_id": "111798086980787121079742248333092569415172137759139099190565410999420761499752", "price": "0.68", "size": "0", "side": "SELL", "hash": "aa86d4907759d09ee85b13d7d767a1a98b3daa8f", "best_bid": "0.62", "best_ask": "0.65"}], "timestamp": "1769384608784", "event_type": "price_change"}}
{"_local_timestamp": "2026-01-25T23:43:29.319064+00:00", "data": {"market": "0x2a4d3cf51d27425b0c51d241a7ba6bc44dd27034b44f9e437624f9e0953b1ea9", "price_changes": [{"asset_id": "58599269208124653793682124721644272657448822176028066253503704155842141815443", "price": "0.34", "size": "88.66", "side": "BUY", "hash": "a3ac0ff25dee3962d6bd014ae24f2ec4f361f71c", "best_bid": "0.35", "best_ask": "0.38"}, {"asset_id": "111798086980787121079742248333092569415172137759139099190565410999420761499752", "price": "0.66", "size": "88.66", "side": "SELL", "hash": "e0695bd04f111fb5e2f00065bbb536227753e077", "best_bid": "0.62", "best_ask": "0.65"}], "timestamp": "1769384609183", "event_type": "price_change"}}
{"_local_timestamp": "2026-01-25T23:43:31.068249+00:00", "data": {"market": "0x7f6dadade6357d3ce6681860d002bd3521554aba8b5acda912917b3db41c9549", "price_changes": [{"asset_id": "50613703516194910329561493534058464924948966095615247532634099427569284124317", "price": "0.23", "size": "39", "side": "BUY", "hash": "3dc6f77e6be08c5762f0e845f23aabc9a2eecb83", "best_bid": "0.23", "best_ask": "0.28"}, {"asset_id": "112538531010841097813690615473978896934576951101485955663285389253633812461690", "price": "0.77", "size": "39", "side": "SELL", "hash": "8ed3a072f8430dd304e86290213590231a8af5a0", "best_bid": "0.72", "best_ask": "0.77"}], "timestamp": "1769384610939", "event_type": "price_change"}}
{"_local_timestamp": "2026-01-25T23:43:31.479651+00:00", "data": {"market": "0x2a4d3cf51d27425b0c51d241a7ba6bc44dd27034b44f9e437624f9e0953b1ea9", "price_changes": [{"asset_id": "58599269208124653793682124721644272657448822176028066253503704155842141815443", "price": "0.35", "size": "35.13", "side": "BUY", "hash": "5d5e3c5cf80e63fa31d3aaf1e13a91657b2faf2d", "best_bid": "0.35", "best_ask": "0.38"}, {"asset_id": "111798086980787121079742248333092569415172137759139099190565410999420761499752", "price": "0.65", "size": "35.13", "side": "SELL", "hash": "0bdb293eff2c11ac169dbd18eeae4409ae27587c", "best_bid": "0.62", "best_ask": "0.65"}], "timestamp": "1769384611353", "event_type": "price_change"}}
{"_local_timestamp": "2026-01-25T23:43:32.651232+00:00", "data": {"market": "0x1a65d4eb8ac985309e78b48906291fffbf137cee590d8d75365f77a0549e9ab9", "price_changes": [{"asset_id": "48953332818425460061045724981972442660997032539861914953015827526728376958623", "price": "0.33", "size": "66.66", "side": "SELL", "hash": "cb81406b3fb6b08e427b078108420374c9037bbf", "best_bid": "0.29", "best_ask": "0.33"}, {"asset_id": "81870625725474135545086561756714985203836689747059214375533433096496527904265", "price": "0.67", "size": "66.66", "side": "BUY", "hash": "5462069dca12d72e3cdaec0304cc0c8c0b774eef", "best_bid": "0.67", "best_ask": "0.71"}], "timestamp": "1769384612524", "event_type": "price_change"}}
{"_local_timestamp": "2026-01-25T23:43:44.222405+00:00", "data": {"market": "0x7f6dadade6357d3ce6681860d002bd3521554aba8b5acda912917b3db41c9549", "price_changes": [{"asset_id": "112538531010841097813690615473978896934576951101485955663285389253633812461690", "price": "0.72", "size": "0", "side": "BUY", "hash": "7721ae61ae6084b725be0497dda1fc8e1eacad64", "best_bid": "0.71", "best_ask": "0.77"}, {"asset_id": "50613703516194910329561493534058464924948966095615247532634099427569284124317", "price": "0.28", "size": "0", "side": "SELL", "hash": "37cb35a4f2cde2e2c085f3401def92adc3916fba", "best_bid": "0.23", "best_ask": "0.29"}], "timestamp": "1769384624073", "event_type": "price_change"}}
{"_local_timestamp": "2026-01-25T23:43:44.442007+00:00", "data": {"market": "0x1a65d4eb8ac985309e78b48906291fffbf137cee590d8d75365f77a0549e9ab9", "price_changes": [{"asset_id": "48953332818425460061045724981972442660997032539861914953015827526728376958623", "price": "0.33", "size": "77.61", "side": "SELL", "hash": "298ac37c2ca45d9a316189017425389ed91ed65d", "best_bid": "0.29", "best_ask": "0.33"}, {"asset_id": "81870625725474135545086561756714985203836689747059214375533433096496527904265", "price": "0.67", "size": "77.61", "side": "BUY", "hash": "4d931565493fc4765207cb13a47afc1e5b4a0b58", "best_bid": "0.67", "best_ask": "0.71"}], "timestamp": "1769384624318", "event_type": "price_change"}}
{"_local_timestamp": "2026-01-25T23:43:44.445069+00:00", "data": {"market": "0x1a65d4eb8ac985309e78b48906291fffbf137cee590d8d75365f77a0549e9ab9", "price_changes": [{"asset_id": "48953332818425460061045724981972442660997032539861914953015827526728376958623", "price": "0.33", "size": "88.56", "side": "SELL", "hash": "a4fab0c832372873db3f998d7b95fc638481b7e0", "best_bid": "0.29", "best_ask": "0.33"}, {"asset_id": "81870625725474135545086561756714985203836689747059214375533433096496527904265", "price": "0.67", "size": "88.56", "side": "BUY", "hash": "d663fd98e6c2428f46a1cc3255fb8a5a9fa4ff3c", "best_bid": "0.67", "best_ask": "0.71"}], "timestamp": "1769384624318", "event_type": "price_change"}}
{"_local_timestamp": "2026-01-25T23:43:48.294785+00:00", "data": {"market": "0x7f6dadade6357d3ce6681860d002bd3521554aba8b5acda912917b3db41c9549", "price_changes": [{"asset_id": "112538531010841097813690615473978896934576951101485955663285389253633812461690", "price": "0.02", "size": "600", "side": "BUY", "hash": "359a587b678f4dcd83a4bbab81851b79647f98a5", "best_bid": "0.71", "best_ask": "0.77"}, {"asset_id": "50613703516194910329561493534058464924948966095615247532634099427569284124317", "price": "0.98", "size": "600", "side": "SELL", "hash": "4dd50bde6233520b8ddc65c21e44d56e6bfc6260", "best_bid": "0.23", "best_ask": "0.29"}], "timestamp": "1769384628191", "event_type": "price_change"}}
{"_local_timestamp": "2026-01-25T23:43:56.706351+00:00", "data": {"market": "0x2a4d3cf51d27425b0c51d241a7ba6bc44dd27034b44f9e437624f9e0953b1ea9", "price_changes": [{"asset_id": "58599269208124653793682124721644272657448822176028066253503704155842141815443", "price": "0.04", "size": "2607.64", "side": "BUY", "hash": "c24ef5b58bc9bda14cae73a4c9901fd308f0c955", "best_bid": "0.35", "best_ask": "0.38"}, {"asset_id": "111798086980787121079742248333092569415172137759139099190565410999420761499752", "price": "0.96", "size": "2607.64", "side": "SELL", "hash": "bdc9995fdcc51442500b22b195f32a465e4a692b", "best_bid": "0.62", "best_ask": "0.65"}], "timestamp": "1769384636530", "event_type": "price_change"}}
{"_local_timestamp": "2026-01-25T23:44:09.034287+00:00", "data": {"market": "0x7f6dadade6357d3ce6681860d002bd3521554aba8b5acda912917b3db41c9549", "price_changes": [{"asset_id": "112538531010841097813690615473978896934576951101485955663285389253633812461690", "price": "0.16", "size": "450", "side": "BUY", "hash": "5d363c6cb7adf975156fc37fda543377c533c6bc", "best_bid": "0.71", "best_ask": "0.77"}, {"asset_id": "50613703516194910329561493534058464924948966095615247532634099427569284124317", "price": "0.84", "size": "450", "side": "SELL", "hash": "111d300a0752a01901e84650c439fc46bfc18950", "best_bid": "0.23", "best_ask": "0.29"}], "timestamp": "1769384648738", "event_type": "price_change"}}
{"_local_timestamp": "2026-01-25T23:44:09.137816+00:00", "data": {"market": "0x7f6dadade6357d3ce6681860d002bd3521554aba8b5acda912917b3db41c9549", "price_changes": [{"asset_id": "112538531010841097813690615473978896934576951101485955663285389253633812461690", "price": "0.12", "size": "608.33", "side": "BUY", "hash": "cc01595f47f8ac7ebe07991edf741a1a28d0479f", "best_bid": "0.71", "best_ask": "0.77"}, {"asset_id": "50613703516194910329561493534058464924948966095615247532634099427569284124317", "price": "0.88", "size": "608.33", "side": "SELL", "hash": "8f2087ffe7477a23e2966d144bc8f740da0d9b39", "best_bid": "0.23", "best_ask": "0.29"}], "timestamp": "1769384648820", "event_type": "price_change"}}
{"_local_timestamp": "2026-01-25T23:44:09.181062+00:00", "data": {"market": "0x7f6dadade6357d3ce6681860d002bd3521554aba8b5acda912917b3db41c9549", "price_changes": [{"asset_id": "112538531010841097813690615473978896934576951101485955663285389253633812461690", "price": "0.24", "size": "258.33", "side": "BUY", "hash": "e9c2f89283b40a4efba40a92097a05ec6d09f78b", "best_bid": "0.71", "best_ask": "0.77"}, {"asset_id": "50613703516194910329561493534058464924948966095615247532634099427569284124317", "price": "0.76", "size": "258.33", "side": "SELL", "hash": "541173e9987898758d7fcfd0f20812c8fb696df7", "best_bid": "0.23", "best_ask": "0.29"}], "timestamp": "1769384648894", "event_type": "price_change"}}
{"_local_timestamp": "2026-01-25T23:44:10.721366+00:00", "data": {"market": "0x1a65d4eb8ac985309e78b48906291fffbf137cee590d8d75365f77a0549e9ab9", "price_changes": [{"asset_id": "48953332818425460061045724981972442660997032539861914953015827526728376958623", "price": "0.33", "size": "66.66", "side": "SELL", "hash": "f8f8c280765045563cc5c940c262bde110b7e6d9", "best_bid": "0.29", "best_ask": "0.33"}, {"asset_id": "81870625725474135545086561756714985203836689747059214375533433096496527904265", "price": "0.67", "size": "66.66", "side": "BUY", "hash": "8c6f3d0a01e0dc323d7d00d690ee5586dd4a9659", "best_bid": "0.67", "best_ask": "0.71"}], "timestamp": "1769384650576", "event_type": "price_change"}}
{"_local_timestamp": "2026-01-25T23:44:18.018288+00:00", "data": {"market": "0x0a9f1c94b012a39a2a91b877b24c15f25ffd1ee68df65a79c12e5fac82519865", "price_changes": [{"asset_id": "73641960431177563453506958377488026157202817565843589479879428094129866219922", "price": "0.3", "size": "0", "side": "SELL", "hash": "e2440221a703b480c5f2035c29b7df1b28d2532b", "best_bid": "0.06", "best_ask": "0.13"}, {"asset_id": "92197810663257226642496081056291543161006633887475519374142132133821877068692", "price": "0.7", "size": "0", "side": "BUY", "hash": "0f5f639f20765a316843e36a8a3448ec750f5d96", "best_bid": "0.87", "best_ask": "0.94"}], "timestamp": "1769384657756", "event_type": "price_change"}}
{"_local_timestamp": "2026-01-25T23:44:18.825300+00:00", "data": {"market": "0x0a9f1c94b012a39a2a91b877b24c15f25ffd1ee68df65a79c12e5fac82519865", "price_changes": [{"asset_id": "73641960431177563453506958377488026157202817565843589479879428094129866219922", "price": "0.16", "size": "325.5", "side": "SELL", "hash": "d00676db5166b78bdc807f3a1bb6711debf85f57", "best_bid": "0.06", "best_ask": "0.13"}, {"asset_id": "92197810663257226642496081056291543161006633887475519374142132133821877068692", "price": "0.84", "size": "325.5", "side": "BUY", "hash": "cb01dc024e83760b941b8cdf54e69120883b4231", "best_bid": "0.87", "best_ask": "0.94"}], "timestamp": "1769384658553", "event_type": "price_change"}}
{"_local_timestamp": "2026-01-25T23:44:21.024049+00:00", "data": {"market": "0x2a4d3cf51d27425b0c51d241a7ba6bc44dd27034b44f9e437624f9e0953b1ea9", "price_changes": [{"asset_id": "111798086980787121079742248333092569415172137759139099190565410999420761499752", "price": "0.06", "size": "1100", "side": "BUY", "hash": "976a56e604c1ebf79b4c2dba3eaeeab9d2f5ae93", "best_bid": "0.62", "best_ask": "0.65"}, {"asset_id": "58599269208124653793682124721644272657448822176028066253503704155842141815443", "price": "0.94", "size": "1100", "side": "SELL", "hash": "04af30c7ed725235a13c4f1be016614a52103627", "best_bid": "0.35", "best_ask": "0.38"}], "timestamp": "1769384660494", "event_type": "price_change"}}
{"_local_timestamp": "2026-01-25T23:44:21.024942+00:00", "data": {"market": "0x7f6dadade6357d3ce6681860d002bd3521554aba8b5acda912917b3db41c9549", "price_changes": [{"asset_id": "112538531010841097813690615473978896934576951101485955663285389253633812461690", "price": "0.05", "size": "910", "side": "BUY", "hash": "3367461b16b0682fd569cf514e8725d0456d8ec7", "best_bid": "0.71", "best_ask": "0.77"}, {"asset_id": "50613703516194910329561493534058464924948966095615247532634099427569284124317", "price": "0.95", "size": "910", "side": "SELL", "hash": "d57952cb0afe1b31a746ada7bc90617f3cb6866a", "best_bid": "0.23", "best_ask": "0.29"}], "timestamp": "1769384660496", "event_type": "price_change"}}
{"_local_timestamp": "2026-01-25T23:44:21.567228+00:00", "data": {"market": "0x7f6dadade6357d3ce6681860d002bd3521554aba8b5acda912917b3db41c9549", "price_changes": [{"asset_id": "112538531010841097813690615473978896934576951101485955663285389253633812461690", "price": "0.08", "size": "750", "side": "BUY", "hash": "a9852bf68fab37ee4f13603cee4286de08fd4339", "best_bid": "0.71", "best_ask": "0.77"}, {"asset_id": "50613703516194910329561493534058464924948966095615247532634099427569284124317", "price": "0.92", "size": "750", "side": "SELL", "hash": "b0c631372ee884ac7b1514c9c3bee2741265fdab", "best_bid": "0.23", "best_ask": "0.29"}], "timestamp": "1769384660890", "event_type": "price_change"}}
{"_local_timestamp": "2026-01-25T23:44:21.578799+00:00", "data": {"market": "0x2a4d3cf51d27425b0c51d241a7ba6bc44dd27034b44f9e437624f9e0953b1ea9", "price_changes": [{"asset_id": "111798086980787121079742248333092569415172137759139099190565410999420761499752", "price": "0.07", "size": "600", "side": "BUY", "hash": "515223975777131a385c537ca4e82b6f1d805939", "best_bid": "0.62", "best_ask": "0.65"}, {"asset_id": "58599269208124653793682124721644272657448822176028066253503704155842141815443", "price": "0.93", "size": "600", "side": "SELL", "hash": "bc120309ce0e0b3bf2b3e478028dd99d6e93eb87", "best_bid": "0.35", "best_ask": "0.38"}], "timestamp": "1769384660887", "event_type": "price_change"}}
{"_local_timestamp": "2026-01-25T23:44:23.407429+00:00", "data": {"market": "0x1a65d4eb8ac985309e78b48906291fffbf137cee590d8d75365f77a0549e9ab9", "price_changes": [{"asset_id": "48953332818425460061045724981972442660997032539861914953015827526728376958623", "price": "0.33", "size": "77.61", "side": "SELL", "hash": "2c5b8c2564d0356aa408a5036cb683c31b020a91", "best_bid": "0.29", "best_ask": "0.33"}, {"asset_id": "81870625725474135545086561756714985203836689747059214375533433096496527904265", "price": "0.67", "size": "77.61", "side": "BUY", "hash": "3df9929b3d157ad60f98d722e613f7b5fee62148", "best_bid": "0.67", "best_ask": "0.71"}], "timestamp": "1769384663155", "event_type": "price_change"}}
{"_local_timestamp": "2026-01-25T23:44:23.414235+00:00", "data": {"market": "0x1a65d4eb8ac985309e78b48906291fffbf137cee590d8d75365f77a0549e9ab9", "price_changes": [{"asset_id": "48953332818425460061045724981972442660997032539861914953015827526728376958623", "price": "0.33", "size": "88.56", "side": "SELL", "hash": "ec9aff0c64f6b6053edfaa95bcd84680a3c7d1ca", "best_bid": "0.29", "best_ask": "0.33"}, {"asset_id": "81870625725474135545086561756714985203836689747059214375533433096496527904265", "price": "0.67", "size": "88.56", "side": "BUY", "hash": "3554171adbd379edffefc34be86d742f9ff07acd", "best_bid": "0.67", "best_ask": "0.71"}], "timestamp": "1769384663155", "event_type": "price_change"}}
{"_local_timestamp": "2026-01-25T23:44:36.071832+00:00", "data": {"market": "0x7f6dadade6357d3ce6681860d002bd3521554aba8b5acda912917b3db41c9549", "price_changes": [{"asset_id": "112538531010841097813690615473978896934576951101485955663285389253633812461690", "price": "0.08", "size": "950", "side": "BUY", "hash": "dde97fc992a4fa0837efb052a9e319e1c72f79b3", "best_bid": "0.71", "best_ask": "0.77"}, {"asset_id": "50613703516194910329561493534058464924948966095615247532634099427569284124317", "price": "0.92", "size": "950", "side": "SELL", "hash": "3d6eb37ce3ab3d6b1002d14a00da776b450c9c36", "best_bid": "0.23", "best_ask": "0.29"}], "timestamp": "1769384675791", "event_type": "price_change"}}
{"_local_timestamp": "2026-01-25T23:44:52.523701+00:00", "data": {"market": "0x1a65d4eb8ac985309e78b48906291fffbf137cee590d8d75365f77a0549e9ab9", "price_changes": [{"asset_id": "48953332818425460061045724981972442660997032539861914953015827526728376958623", "price": "0.33", "size": "66.66", "side": "SELL", "hash": "e8c61a4470617869c64071030c691f8ee73622b5", "best_bid": "0.29", "best_ask": "0.33"}, {"asset_id": "81870625725474135545086561756714985203836689747059214375533433096496527904265", "price": "0.67", "size": "66.66", "side": "BUY", "hash": "99b56ff8d6f2638f4a1100a790cc7c1a36de4a33", "best_bid": "0.67", "best_ask": "0.71"}], "timestamp": "1769384692427", "event_type": "price_change"}}
{"_local_timestamp": "2026-01-25T23:44:56.271640+00:00", "data": {"market": "0x7f6dadade6357d3ce6681860d002bd3521554aba8b5acda912917b3db41c9549", "price_changes": [{"asset_id": "112538531010841097813690615473978896934576951101485955663285389253633812461690", "price": "0.01", "size": "4010.58", "side": "BUY", "hash": "29e0e4d03ecd64d1839ac7e763a8125fc363d458", "best_bid": "0.71", "best_ask": "0.77"}, {"asset_id": "50613703516194910329561493534058464924948966095615247532634099427569284124317", "price": "0.99", "size": "4010.58", "side": "SELL", "hash": "54bf21aea66f27c6a10dcea865ad5e7e309b5535", "best_bid": "0.23", "best_ask": "0.29"}], "timestamp": "1769384696176", "event_type": "price_change"}}
{"_local_timestamp": "2026-01-25T23:44:56.272086+00:00", "data": {"market": "0x2a4d3cf51d27425b0c51d241a7ba6bc44dd27034b44f9e437624f9e0953b1ea9", "price_changes": [{"asset_id": "58599269208124653793682124721644272657448822176028066253503704155842141815443", "price": "0.01", "size": "6555", "side": "BUY", "hash": "9dac0d6860e0a32cffa1cc25311f1c526790a530", "best_bid": "0.35", "best_ask": "0.38"}, {"asset_id": "111798086980787121079742248333092569415172137759139099190565410999420761499752", "price": "0.99", "size": "6555", "side": "SELL", "hash": "d941d0e85fa6e3fad2ee2e2d5daf1a0642c7b113", "best_bid": "0.62", "best_ask": "0.65"}], "timestamp": "1769384696174", "event_type": "price_change"}}
{"_local_timestamp": "2026-01-25T23:44:58.404192+00:00", "data": {"market": "0x2a4d3cf51d27425b0c51d241a7ba6bc44dd27034b44f9e437624f9e0953b1ea9", "price_changes": [{"asset_id": "111798086980787121079742248333092569415172137759139099190565410999420761499752", "price": "0.27", "size": "200", "side": "BUY", "hash": "204b8ec67f1954a1c2a23c32e13cd5e7f4769c22", "best_bid": "0.62", "best_ask": "0.65"}, {"asset_id": "58599269208124653793682124721644272657448822176028066253503704155842141815443", "price": "0.73", "size": "200", "side": "SELL", "hash": "cb220080af8d402b40769c680f2d05b40b58465c", "best_bid": "0.35", "best_ask": "0.38"}], "timestamp": "1769384698237", "event_type": "price_change"}}
{"_local_timestamp": "2026-01-25T23:45:05.707840+00:00", "data": {"market": "0x1a65d4eb8ac985309e78b48906291fffbf137cee590d8d75365f77a0549e9ab9", "price_changes": [{"asset_id": "48953332818425460061045724981972442660997032539861914953015827526728376958623", "price": "0.33", "size": "77.61", "side": "SELL", "hash": "e4baa40d50c6466158d1e12bd2185c6b8d0da088", "best_bid": "0.29", "best_ask": "0.33"}, {"asset_id": "81870625725474135545086561756714985203836689747059214375533433096496527904265", "price": "0.67", "size": "77.61", "side": "BUY", "hash": "14ea1d9a3363615bb405740c45434ec37f3bbc33", "best_bid": "0.67", "best_ask": "0.71"}], "timestamp": "1769384705635", "event_type": "price_change"}}
{"_local_timestamp": "2026-01-25T23:45:05.725585+00:00", "data": {"market": "0x1a65d4eb8ac985309e78b48906291fffbf137cee590d8d75365f77a0549e9ab9", "price_changes": [{"asset_id": "48953332818425460061045724981972442660997032539861914953015827526728376958623", "price": "0.33", "size": "88.56", "side": "SELL", "hash": "b49de7125898b935f6c01c82074ba1aa33ab15ea", "best_bid": "0.29", "best_ask": "0.33"}, {"asset_id": "81870625725474135545086561756714985203836689747059214375533433096496527904265", "price": "0.67", "size": "88.56", "side": "BUY", "hash": "551f2bc665a0c42bdd9cbe687703cc701ca23405", "best_bid": "0.67", "best_ask": "0.71"}], "timestamp": "1769384705652", "event_type": "price_change"}}
{"_local_timestamp": "2026-01-25T23:45:06.222138+00:00", "data": {"market": "0x7f6dadade6357d3ce6681860d002bd3521554aba8b5acda912917b3db41c9549", "price_changes": [{"asset_id": "112538531010841097813690615473978896934576951101485955663285389253633812461690", "price": "0.71", "size": "60.07", "side": "BUY", "hash": "4d2aa2454a6b62fd836bd8db48c230345f2788cd", "best_bid": "0.71", "best_ask": "0.77"}, {"asset_id": "50613703516194910329561493534058464924948966095615247532634099427569284124317", "price": "0.29", "size": "60.07", "side": "SELL", "hash": "2b8076c0c4963dfca0bfeb7c9972d97dbd3e9657", "best_bid": "0.23", "best_ask": "0.29"}], "timestamp": "1769384706142", "event_type": "price_change"}}
{"_local_timestamp": "2026-01-25T23:45:09.294234+00:00", "data": {"market": "0x0a9f1c94b012a39a2a91b877b24c15f25ffd1ee68df65a79c12e5fac82519865", "price_changes": [{"asset_id": "92197810663257226642496081056291543161006633887475519374142132133821877068692", "price": "0.77", "size": "0", "side": "BUY", "hash": "bbd803903ac1d1689df288fbcb18f577cffcdfb0", "best_bid": "0.87", "best_ask": "0.94"}, {"asset_id": "73641960431177563453506958377488026157202817565843589479879428094129866219922", "price": "0.23", "size": "0", "side": "SELL", "hash": "4d766e5a3529c73f0e51d2d5022161d42275f2ab", "best_bid": "0.06", "best_ask": "0.13"}], "timestamp": "1769384709220", "event_type": "price_change"}}
{"_local_timestamp": "2026-01-25T23:45:09.294581+00:00", "data": {"market": "0x0a9f1c94b012a39a2a91b877b24c15f25ffd1ee68df65a79c12e5fac82519865", "price_changes": [{"asset_id": "92197810663257226642496081056291543161006633887475519374142132133821877068692", "price": "0.66", "size": "0", "side": "BUY", "hash": "bbd803903ac1d1689df288fbcb18f577cffcdfb0", "best_bid": "0.87", "best_ask": "0.94"}, {"asset_id": "73641960431177563453506958377488026157202817565843589479879428094129866219922", "price": "0.34", "size": "0", "side": "SELL", "hash": "4d766e5a3529c73f0e51d2d5022161d42275f2ab", "best_bid": "0.06", "best_ask": "0.13"}], "timestamp": "1769384709220", "event_type": "price_change"}}
{"_local_timestamp": "2026-01-25T23:45:09.294841+00:00", "data": {"market": "0x7f6dadade6357d3ce6681860d002bd3521554aba8b5acda912917b3db41c9549", "price_changes": [{"asset_id": "112538531010841097813690615473978896934576951101485955663285389253633812461690", "price": "0.49", "size": "0", "side": "BUY", "hash": "fd6444b5cae57e8d6e9470011d7563eb93ba7a23", "best_bid": "0.71", "best_ask": "0.77"}, {"asset_id": "50613703516194910329561493534058464924948966095615247532634099427569284124317", "price": "0.51", "size": "0", "side": "SELL", "hash": "0ecbca8ab08568ef0c7949331bec7dc3529068d2", "best_bid": "0.23", "best_ask": "0.29"}], "timestamp": "1769384709220", "event_type": "price_change"}}
{"_local_timestamp": "2026-01-25T23:45:09.295091+00:00", "data": {"market": "0x0a9f1c94b012a39a2a91b877b24c15f25ffd1ee68df65a79c12e5fac82519865", "price_changes": [{"asset_id": "73641960431177563453506958377488026157202817565843589479879428094129866219922", "price": "0.06", "size": "6.42", "side": "BUY", "hash": "0d5947adb18e71c508f07192c8efb895b1e477cc", "best_bid": "0.06", "best_ask": "0.13"}, {"asset_id": "92197810663257226642496081056291543161006633887475519374142132133821877068692", "price": "0.94", "size": "6.42", "side": "SELL", "hash": "48903419c18d5d436dc73957e9a16fab2c31f959", "best_bid": "0.87", "best_ask": "0.94"}], "timestamp": "1769384709220", "event_type": "price_change"}}
{"_local_timestamp": "2026-01-25T23:45:09.295350+00:00", "data": {"market": "0x7f6dadade6357d3ce6681860d002bd3521554aba8b5acda912917b3db41c9549", "price_changes": [{"asset_id": "112538531010841097813690615473978896934576951101485955663285389253633812461690", "price": "0.25", "size": "0", "side": "BUY", "hash": "fd6444b5cae57e8d6e9470011d7563eb93ba7a23", "best_bid": "0.71", "best_ask": "0.77"}, {"asset_id": "50613703516194910329561493534058464924948966095615247532634099427569284124317", "price": "0.75", "size": "0", "side": "SELL", "hash": "0ecbca8ab08568ef0c7949331bec7dc3529068d2", "best_bid": "0.23", "best_ask": "0.29"}], "timestamp": "1769384709220", "event_type": "price_change"}}
{"_local_timestamp": "2026-01-25T23:45:09.295601+00:00", "data": {"market": "0x0a9f1c94b012a39a2a91b877b24c15f25ffd1ee68df65a79c12e5fac82519865", "price_changes": [{"asset_id": "73641960431177563453506958377488026157202817565843589479879428094129866219922", "price": "0.04", "size": "7.29", "side": "BUY", "hash": "0d5947adb18e71c508f07192c8efb895b1e477cc", "best_bid": "0.06", "best_ask": "0.13"}, {"asset_id": "92197810663257226642496081056291543161006633887475519374142132133821877068692", "price": "0.96", "size": "7.29", "side": "SELL", "hash": "48903419c18d5d436dc73957e9a16fab2c31f959", "best_bid": "0.87", "best_ask": "0.94"}], "timestamp": "1769384709220", "event_type": "price_change"}}
{"_local_timestamp": "2026-01-25T23:45:09.295837+00:00", "data": {"market": "0x0a9f1c94b012a39a2a91b877b24c15f25ffd1ee68df65a79c12e5fac82519865", "price_changes": [{"asset_id": "73641960431177563453506958377488026157202817565843589479879428094129866219922", "price": "0.03", "size": "250", "side": "BUY", "hash": "0d5947adb18e71c508f07192c8efb895b1e477cc", "best_bid": "0.06", "best_ask": "0.13"}, {"asset_id": "92197810663257226642496081056291543161006633887475519374142132133821877068692", "price": "0.97", "size": "250", "side": "SELL", "hash": "48903419c18d5d436dc73957e9a16fab2c31f959", "best_bid": "0.87", "best_ask": "0.94"}], "timestamp": "1769384709220", "event_type": "price_change"}}
{"_local_timestamp": "2026-01-25T23:45:09.296236+00:00", "data": {"market": "0x7f6dadade6357d3ce6681860d002bd3521554aba8b5acda912917b3db41c9549", "price_changes": [{"asset_id": "50613703516194910329561493534058464924948966095615247532634099427569284124317", "price": "0.22", "size": "30", "side": "BUY", "hash": "542800392601c0ba7ebd15abdcbf0d7d7bd05a6c", "best_bid": "0.23", "best_ask": "0.29"}, {"asset_id": "112538531010841097813690615473978896934576951101485955663285389253633812461690", "price": "0.78", "size": "30", "side": "SELL", "hash": "53227db57de3fc249b489af7dbcfeadcfd177bb4", "best_bid": "0.71", "best_ask": "0.77"}], "timestamp": "1769384709220", "event_type": "price_change"}}
{"_local_timestamp": "2026-01-25T23:45:09.739886+00:00", "data": {"market": "0x0a9f1c94b012a39a2a91b877b24c15f25ffd1ee68df65a79c12e5fac82519865", "price_changes": [{"asset_id": "92197810663257226642496081056291543161006633887475519374142132133821877068692", "price": "0.68", "size": "66.66", "side": "BUY", "hash": "64cb3e0a617dd012edbf5d758cd3fbe980a527bd", "best_bid": "0.87", "best_ask": "0.94"}, {"asset_id": "73641960431177563453506958377488026157202817565843589479879428094129866219922", "price": "0.32", "size": "66.66", "side": "SELL", "hash": "d0d3bfde35c1c76cef08fe3b021639fa0e600520", "best_bid": "0.06", "best_ask": "0.13"}], "timestamp": "1769384709676", "event_type": "price_change"}}
{"_local_timestamp": "2026-01-25T23:45:09.792154+00:00", "data": {"market": "0x0a9f1c94b012a39a2a91b877b24c15f25ffd1ee68df65a79c12e5fac82519865", "price_changes": [{"asset_id": "73641960431177563453506958377488026157202817565843589479879428094129866219922", "price": "0.33", "size": "100", "side": "SELL", "hash": "de7e6cfc9bc50f3f135e0fb97d94afdedb8b7513", "best_bid": "0.06", "best_ask": "0.13"}, {"asset_id": "92197810663257226642496081056291543161006633887475519374142132133821877068692", "price": "0.67", "size": "100", "side": "BUY", "hash": "21a504d9f61a6bce5b906a700240e5d094d60de9", "best_bid": "0.87", "best_ask": "0.94"}], "timestamp": "1769384709722", "event_type": "price_change"}}
{"_local_timestamp": "2026-01-25T23:45:09.804581+00:00", "data": {"market": "0x0a9f1c94b012a39a2a91b877b24c15f25ffd1ee68df65a79c12e5fac82519865", "price_changes": [{"asset_id": "92197810663257226642496081056291543161006633887475519374142132133821877068692", "price": "0.78", "size": "66.66", "side": "BUY", "hash": "53b3645ac32be324d32e72d182cfbf16eb29c394", "best_bid": "0.87", "best_ask": "0.94"}, {"asset_id": "73641960431177563453506958377488026157202817565843589479879428094129866219922", "price": "0.22", "size": "66.66", "side": "SELL", "hash": "e262f52b85cde16b6c8419df683a2b1ae71b3a75", "best_bid": "0.06", "best_ask": "0.13"}], "timestamp": "1769384709735", "event_type": "price_change"}}
{"_local_timestamp": "2026-01-25T23:45:09.835927+00:00", "data": {"market": "0x0a9f1c94b012a39a2a91b877b24c15f25ffd1ee68df65a79c12e5fac82519865", "price_changes": [{"asset_id": "73641960431177563453506958377488026157202817565843589479879428094129866219922", "price": "0.16", "size": "164.5", "side": "SELL", "hash": "f319e23636e65d16a03dfec8d7eb786e3f2ed06c", "best_bid": "0.06", "best_ask": "0.13"}, {"asset_id": "92197810663257226642496081056291543161006633887475519374142132133821877068692", "price": "0.84", "size": "164.5", "side": "BUY", "hash": "d65a28137f588a83787c2c5323f428a38d7e48df", "best_bid": "0.87", "best_ask": "0.94"}], "timestamp": "1769384709764", "event_type": "price_change"}}
{"_local_timestamp": "2026-01-25T23:45:09.860932+00:00", "data": {"market": "0x0a9f1c94b012a39a2a91b877b24c15f25ffd1ee68df65a79c12e5fac82519865", "price_changes": [{"asset_id": "73641960431177563453506958377488026157202817565843589479879428094129866219922", "price": "0.03", "size": "350", "side": "BUY", "hash": "91c880e99e0947d15d7acb88e9dad7c867cd0f8a", "best_bid": "0.06", "best_ask": "0.13"}, {"asset_id": "92197810663257226642496081056291543161006633887475519374142132133821877068692", "price": "0.97", "size": "350", "side": "SELL", "hash": "8d3a1c979c65da163c01e12438757acbfc19b05b", "best_bid": "0.87", "best_ask": "0.94"}], "timestamp": "1769384709788", "event_type": "price_change"}}
{"_local_timestamp": "2026-01-25T23:45:09.861210+00:00", "data": {"market": "0x0a9f1c94b012a39a2a91b877b24c15f25ffd1ee68df65a79c12e5fac82519865", "price_changes": [{"asset_id": "73641960431177563453506958377488026157202817565843589479879428094129866219922", "price": "0.14", "size": "153.28", "side": "SELL", "hash": "a9317964fd5b0d33f63f30f882d22221726f2c92", "best_bid": "0.06", "best_ask": "0.13"}, {"asset_id": "92197810663257226642496081056291543161006633887475519374142132133821877068692", "price": "0.86", "size": "153.28", "side": "BUY", "hash": "ac03577027073c1115dc6aae598a0c0823b32bd0", "best_bid": "0.87", "best_ask": "0.94"}], "timestamp": "1769384709790", "event_type": "price_change"}}
{"_local_timestamp": "2026-01-25T23:45:09.915290+00:00", "data": {"market": "0x0a9f1c94b012a39a2a91b877b24c15f25ffd1ee68df65a79c12e5fac82519865", "price_changes": [{"asset_id": "92197810663257226642496081056291543161006633887475519374142132133821877068692", "price": "0.88", "size": "66.66", "side": "BUY", "hash": "a23493ed912e382db4564da403efa8baee04e68e", "best_bid": "0.88", "best_ask": "0.94"}, {"asset_id": "73641960431177563453506958377488026157202817565843589479879428094129866219922", "price": "0.12", "size": "66.66", "side": "SELL", "hash": "1ec0f6f7f305ec2ca6ddc4ad4711b2d82e51f32f", "best_bid": "0.06", "best_ask": "0.12"}], "timestamp": "1769384709845", "event_type": "price_change"}}
{"_local_timestamp": "2026-01-25T23:45:09.915572+00:00", "data": {"market": "0x7f6dadade6357d3ce6681860d002bd3521554aba8b5acda912917b3db41c9549", "price_changes": [{"asset_id": "50613703516194910329561493534058464924948966095615247532634099427569284124317", "price": "0.24", "size": "66.66", "side": "BUY", "hash": "16f68ce3b164d5bee3b2bebc45b837ec936516e5", "best_bid": "0.24", "best_ask": "0.29"}, {"asset_id": "112538531010841097813690615473978896934576951101485955663285389253633812461690", "price": "0.76", "size": "66.66", "side": "SELL", "hash": "5894e7b8f90e430fa74ec46c175629e3b53dcf32", "best_bid": "0.71", "best_ask": "0.76"}], "timestamp": "1769384709848", "event_type": "price_change"}}
{"_local_timestamp": "2026-01-25T23:45:09.924553+00:00", "data": {"market": "0x7f6dadade6357d3ce6681860d002bd3521554aba8b5acda912917b3db41c9549", "price_changes": [{"asset_id": "112538531010841097813690615473978896934576951101485955663285389253633812461690", "price": "0.48", "size": "8.89", "side": "BUY", "hash": "6062b79243c1cb8b20afa7501fca3438d2e1767c", "best_bid": "0.71", "best_ask": "0.76"}, {"asset_id": "50613703516194910329561493534058464924948966095615247532634099427569284124317", "price": "0.52", "size": "8.89", "side": "SELL", "hash": "39b6c75383b385edc4ad4dd4130568731a328d54", "best_bid": "0.24", "best_ask": "0.29"}], "timestamp": "1769384709856", "event_type": "price_change"}}
{"_local_timestamp": "2026-01-25T23:45:09.930741+00:00", "data": {"market": "0x7f6dadade6357d3ce6681860d002bd3521554aba8b5acda912917b3db41c9549", "price_changes": [{"asset_id": "112538531010841097813690615473978896934576951101485955663285389253633812461690", "price": "0.25", "size": "8.89", "side": "BUY", "hash": "63e9216e4ff8eb5b6e190475f9f30d95a52f8963", "best_bid": "0.71", "best_ask": "0.76"}, {"asset_id": "50613703516194910329561493534058464924948966095615247532634099427569284124317", "price": "0.75", "size": "8.89", "side": "SELL", "hash": "9c900bf530898b7e57252cf7e53b696999975c31", "best_bid": "0.24", "best_ask": "0.29"}], "timestamp": "1769384709861", "event_type": "price_change"}}
{"_local_timestamp": "2026-01-25T23:45:09.952210+00:00", "data": {"market": "0x7f6dadade6357d3ce6681860d002bd3521554aba8b5acda912917b3db41c9549", "price_changes": [{"asset_id": "112538531010841097813690615473978896934576951101485955663285389253633812461690", "price": "0.72", "size": "8.89", "side": "BUY", "hash": "c52c6be9ad4e2eb26fa8ba1ae83c7150ed116374", "best_bid": "0.72", "best_ask": "0.76"}, {"asset_id": "50613703516194910329561493534058464924948966095615247532634099427569284124317", "price": "0.28", "size": "8.89", "side": "SELL", "hash": "ce737f1e27b0a56045b34b16fec55d1fe44c6a33", "best_bid": "0.24", "best_ask": "0.28"}], "timestamp": "1769384709876", "event_type": "price_change"}}
{"_local_timestamp": "2026-01-25T23:45:09.960107+00:00", "data": {"market": "0x0a9f1c94b012a39a2a91b877b24c15f25ffd1ee68df65a79c12e5fac82519865", "price_changes": [{"asset_id": "73641960431177563453506958377488026157202817565843589479879428094129866219922", "price": "0.04", "size": "107.29", "side": "BUY", "hash": "3c574c46ae22597b5036ad45e15059d6709aa95f", "best_bid": "0.06", "best_ask": "0.12"}, {"asset_id": "92197810663257226642496081056291543161006633887475519374142132133821877068692", "price": "0.96", "size": "107.29", "side": "SELL", "hash": "18716b170d86f9bd0a9832c640c79bc6dff69875", "best_bid": "0.88", "best_ask": "0.94"}], "timestamp": "1769384709880", "event_type": "price_change"}}
{"_local_timestamp": "2026-01-25T23:45:10.219441+00:00", "data": {"market": "0x0a9f1c94b012a39a2a91b877b24c15f25ffd1ee68df65a79c12e5fac82519865", "price_changes": [{"asset_id": "73641960431177563453506958377488026157202817565843589479879428094129866219922", "price": "0.7", "size": "199.99", "side": "SELL", "hash": "e5876552bcd6075f464dcd609beccd8356e6e722", "best_bid": "0.06", "best_ask": "0.12"}, {"asset_id": "92197810663257226642496081056291543161006633887475519374142132133821877068692", "price": "0.3", "size": "199.99", "side": "BUY", "hash": "0ab12bb3363f2861c621a7da49f7de570d6be983", "best_bid": "0.88", "best_ask": "0.94"}], "timestamp": "1769384710149", "event_type": "price_change"}}
{"_local_timestamp": "2026-01-25T23:45:10.243960+00:00", "data": {"market": "0x0a9f1c94b012a39a2a91b877b24c15f25ffd1ee68df65a79c12e5fac82519865", "price_changes": [{"asset_id": "92197810663257226642496081056291543161006633887475519374142132133821877068692", "price": "0.67", "size": "0", "side": "BUY", "hash": "4cdaf0a93d9b746ba711ec98977689ab6f34f724", "best_bid": "0.88", "best_ask": "0.94"}, {"asset_id": "73641960431177563453506958377488026157202817565843589479879428094129866219922", "price": "0.33", "size": "0", "side": "SELL", "hash": "2dfbb68301f317af01e9a50c5f39f27437a7aa73", "best_bid": "0.06", "best_ask": "0.12"}], "timestamp": "1769384710174", "event_type": "price_change"}}
{"_local_timestamp": "2026-01-25T23:45:10.764000+00:00", "data": {"market": "0x0a9f1c94b012a39a2a91b877b24c15f25ffd1ee68df65a79c12e5fac82519865", "price_changes": [{"asset_id": "92197810663257226642496081056291543161006633887475519374142132133821877068692", "price": "0.87", "size": "120", "side": "BUY", "hash": "11538767066021fe47af81cf08fc556f52208627", "best_bid": "0.88", "best_ask": "0.94"}, {"asset_id": "73641960431177563453506958377488026157202817565843589479879428094129866219922", "price": "0.13", "size": "120", "side": "SELL", "hash": "6bd1fc0424d017f585ed7cef744e844cf7e319ec", "best_bid": "0.06", "best_ask": "0.12"}], "timestamp": "1769384710676", "event_type": "price_change"}}
{"_local_timestamp": "2026-01-25T23:45:11.447047+00:00", "data": {"market": "0x0a9f1c94b012a39a2a91b877b24c15f25ffd1ee68df65a79c12e5fac82519865", "price_changes": [{"asset_id": "92197810663257226642496081056291543161006633887475519374142132133821877068692", "price": "0.87", "size": "163.67", "side": "BUY", "hash": "72c8198b6d759a8b7b81adadd6325a973511181b", "best_bid": "0.88", "best_ask": "0.94"}, {"asset_id": "73641960431177563453506958377488026157202817565843589479879428094129866219922", "price": "0.13", "size": "163.67", "side": "SELL", "hash": "04787c2a3455395063a9d39ca494786749f4cb2c", "best_bid": "0.06", "best_ask": "0.12"}], "timestamp": "1769384711348", "event_type": "price_change"}}
{"_local_timestamp": "2026-01-25T23:45:11.594778+00:00", "data": {"market": "0x7f6dadade6357d3ce6681860d002bd3521554aba8b5acda912917b3db41c9549", "price_changes": [{"asset_id": "50613703516194910329561493534058464924948966095615247532634099427569284124317", "price": "0.22", "size": "0", "side": "BUY", "hash": "6f3ddecc066188c8a53e61509b246adfc7d5883a", "best_bid": "0.24", "best_ask": "0.28"}, {"asset_id": "112538531010841097813690615473978896934576951101485955663285389253633812461690", "price": "0.78", "size": "0", "side": "SELL", "hash": "97971d880e3a93ad24b807c9aab91b422be7fef9", "best_bid": "0.72", "best_ask": "0.76"}], "timestamp": "1769384711517", "event_type": "price_change"}}
{"_local_timestamp": "2026-01-25T23:45:11.660891+00:00", "data": {"market": "0x7f6dadade6357d3ce6681860d002bd3521554aba8b5acda912917b3db41c9549", "price_changes": [{"asset_id": "50613703516194910329561493534058464924948966095615247532634099427569284124317", "price": "0.24", "size": "96.66", "side": "BUY", "hash": "5c775f78d64ca569943657d6d809531d6c44fa0b", "best_bid": "0.24", "best_ask": "0.28"}, {"asset_id": "112538531010841097813690615473978896934576951101485955663285389253633812461690", "price": "0.76", "size": "96.66", "side": "SELL", "hash": "9448a457d36e70f9a664e1900b6758b7b6f0b154", "best_bid": "0.72", "best_ask": "0.76"}], "timestamp": "1769384711589", "event_type": "price_change"}}
{"_local_timestamp": "2026-01-25T23:45:14.435268+00:00", "data": {"market": "0x0a9f1c94b012a39a2a91b877b24c15f25ffd1ee68df65a79c12e5fac82519865", "price_changes": [{"asset_id": "92197810663257226642496081056291543161006633887475519374142132133821877068692", "price": "0.87", "size": "63.67", "side": "BUY", "hash": "35544b171510aa4f0097cf4d4e4d4695c1cdc0bf", "best_bid": "0.88", "best_ask": "0.94"}, {"asset_id": "73641960431177563453506958377488026157202817565843589479879428094129866219922", "price": "0.13", "size": "63.67", "side": "SELL", "hash": "3971d603a1e9425ab5ed869a8512ca064c65701e", "best_bid": "0.06", "best_ask": "0.12"}], "timestamp": "1769384714367", "event_type": "price_change"}}
{"_local_timestamp": "2026-01-25T23:45:15.056959+00:00", "data": {"market": "0x0a9f1c94b012a39a2a91b877b24c15f25ffd1ee68df65a79c12e5fac82519865", "price_changes": [{"asset_id": "92197810663257226642496081056291543161006633887475519374142132133821877068692", "price": "0.89", "size": "100", "side": "BUY", "hash": "aa0f51b7d79a7d5b560a25814c78e18d4a5f18d1", "best_bid": "0.89", "best_ask": "0.94"}, {"asset_id": "73641960431177563453506958377488026157202817565843589479879428094129866219922", "price": "0.11", "size": "100", "side": "SELL", "hash": "5920101dcfda02b90210cf385ac266022941e021", "best_bid": "0.06", "best_ask": "0.11"}], "timestamp": "1769384714991", "event_type": "price_change"}}
{"_local_timestamp": "2026-01-25T23:45:15.110465+00:00", "data": {"market": "0x0a9f1c94b012a39a2a91b877b24c15f25ffd1ee68df65a79c12e5fac82519865", "price_changes": [{"asset_id": "73641960431177563453506958377488026157202817565843589479879428094129866219922", "price": "0.14", "size": "5.28", "side": "SELL", "hash": "053c550eea432295c8cb8136649695ef754ff80b", "best_bid": "0.06", "best_ask": "0.11"}, {"asset_id": "92197810663257226642496081056291543161006633887475519374142132133821877068692", "price": "0.86", "size": "5.28", "side": "BUY", "hash": "e987543e7f93aaae446d08f5d57cafb2b50374a4", "best_bid": "0.89", "best_ask": "0.94"}], "timestamp": "1769384715031", "event_type": "price_change"}}
{"_local_timestamp": "2026-01-25T23:45:15.614235+00:00", "data": {"market": "0x0a9f1c94b012a39a2a91b877b24c15f25ffd1ee68df65a79c12e5fac82519865", "price_changes": [{"asset_id": "92197810663257226642496081056291543161006633887475519374142132133821877068692", "price": "0.89", "size": "130", "side": "BUY", "hash": "c5f2c096793389f3e5cb16d3d767a2b0ecb029fc", "best_bid": "0.89", "best_ask": "0.94"}, {"asset_id": "73641960431177563453506958377488026157202817565843589479879428094129866219922", "price": "0.11", "size": "130", "side": "SELL", "hash": "d2069cac0dda2259d6686e42c036cbad78109b4d", "best_bid": "0.06", "best_ask": "0.11"}], "timestamp": "1769384715545", "event_type": "price_change"}}
{"_local_timestamp": "2026-01-25T23:45:17.956306+00:00", "data": {"market": "0x0a9f1c94b012a39a2a91b877b24c15f25ffd1ee68df65a79c12e5fac82519865", "price_changes": [{"asset_id": "73641960431177563453506958377488026157202817565843589479879428094129866219922", "price": "0.16", "size": "30", "side": "SELL", "hash": "68c0e1cc45a2b95b92815e92b48f2efb14efc513", "best_bid": "0.06", "best_ask": "0.11"}, {"asset_id": "92197810663257226642496081056291543161006633887475519374142132133821877068692", "price": "0.84", "size": "30", "side": "BUY", "hash": "85fcaa15d31ef82007131847c3a617ce549cf0d3", "best_bid": "0.89", "best_ask": "0.94"}], "timestamp": "1769384717874", "event_type": "price_change"}}
{"_local_timestamp": "2026-01-25T23:45:35.618736+00:00", "data": {"market": "0x1a65d4eb8ac985309e78b48906291fffbf137cee590d8d75365f77a0549e9ab9", "price_changes": [{"asset_id": "48953332818425460061045724981972442660997032539861914953015827526728376958623", "price": "0.33", "size": "66.66", "side": "SELL", "hash": "562547bdae406594c3ea9fdb8a6862c5ebc10b0a", "best_bid": "0.29", "best_ask": "0.33"}, {"asset_id": "81870625725474135545086561756714985203836689747059214375533433096496527904265", "price": "0.67", "size": "66.66", "side": "BUY", "hash": "25e0ca35803cb1b5101fc4e3faa4b498fc39de19", "best_bid": "0.67", "best_ask": "0.71"}], "timestamp": "1769384735547", "event_type": "price_change"}}
{"_local_timestamp": "2026-01-25T23:45:47.410189+00:00", "data": {"market": "0x1a65d4eb8ac985309e78b48906291fffbf137cee590d8d75365f77a0549e9ab9", "price_changes": [{"asset_id": "48953332818425460061045724981972442660997032539861914953015827526728376958623", "price": "0.33", "size": "77.61", "side": "SELL", "hash": "72cdc98dd072b377bea25b280ce5180188534bf9", "best_bid": "0.29", "best_ask": "0.33"}, {"asset_id": "81870625725474135545086561756714985203836689747059214375533433096496527904265", "price": "0.67", "size": "77.61", "side": "BUY", "hash": "d4a97de868338f5dae41e48a1e52c6fa3cce0f04", "best_bid": "0.67", "best_ask": "0.71"}], "timestamp": "1769384747342", "event_type": "price_change"}}
{"_local_timestamp": "2026-01-25T23:45:47.412748+00:00", "data": {"market": "0x1a65d4eb8ac985309e78b48906291fffbf137cee590d8d75365f77a0549e9ab9", "price_changes": [{"asset_id": "48953332818425460061045724981972442660997032539861914953015827526728376958623", "price": "0.33", "size": "88.56", "side": "SELL", "hash": "caa0cc608b1bfbfdd476854dbb18aedd9812e1d0", "best_bid": "0.29", "best_ask": "0.33"}, {"asset_id": "81870625725474135545086561756714985203836689747059214375533433096496527904265", "price": "0.67", "size": "88.56", "side": "BUY", "hash": "8e6db27d6626c8fc173979cdf8054a0c22a00791", "best_bid": "0.67", "best_ask": "0.71"}], "timestamp": "1769384747342", "event_type": "price_change"}}
{"_local_timestamp": "2026-01-25T23:45:53.068702+00:00", "data": {"market": "0x7f6dadade6357d3ce6681860d002bd3521554aba8b5acda912917b3db41c9549", "price_changes": [{"asset_id": "112538531010841097813690615473978896934576951101485955663285389253633812461690", "price": "0.16", "size": "350", "side": "BUY", "hash": "c01beb1fb127b0db4a21bb4e6240816eaa4d9777", "best_bid": "0.72", "best_ask": "0.76"}, {"asset_id": "50613703516194910329561493534058464924948966095615247532634099427569284124317", "price": "0.84", "size": "350", "side": "SELL", "hash": "ef41b8598662c4acef1abea8edb6c6b391951135", "best_bid": "0.24", "best_ask": "0.28"}], "timestamp": "1769384752995", "event_type": "price_change"}}
{"_local_timestamp": "2026-01-25T23:45:53.069107+00:00", "data": {"market": "0x7f6dadade6357d3ce6681860d002bd3521554aba8b5acda912917b3db41c9549", "price_changes": [{"asset_id": "112538531010841097813690615473978896934576951101485955663285389253633812461690", "price": "0.12", "size": "483.33", "side": "BUY", "hash": "c01beb1fb127b0db4a21bb4e6240816eaa4d9777", "best_bid": "0.72", "best_ask": "0.76"}, {"asset_id": "50613703516194910329561493534058464924948966095615247532634099427569284124317", "price": "0.88", "size": "483.33", "side": "SELL", "hash": "ef41b8598662c4acef1abea8edb6c6b391951135", "best_bid": "0.24", "best_ask": "0.28"}], "timestamp": "1769384752995", "event_type": "price_change"}}
{"_local_timestamp": "2026-01-25T23:45:53.069358+00:00", "data": {"market": "0x7f6dadade6357d3ce6681860d002bd3521554aba8b5acda912917b3db41c9549", "price_changes": [{"asset_id": "112538531010841097813690615473978896934576951101485955663285389253633812461690", "price": "0.24", "size": "208.33", "side": "BUY", "hash": "c01beb1fb127b0db4a21bb4e6240816eaa4d9777", "best_bid": "0.72", "best_ask": "0.76"}, {"asset_id": "50613703516194910329561493534058464924948966095615247532634099427569284124317", "price": "0.76", "size": "208.33", "side": "SELL", "hash": "ef41b8598662c4acef1abea8edb6c6b391951135", "best_bid": "0.24", "best_ask": "0.28"}], "timestamp": "1769384752995", "event_type": "price_change"}}
{"_local_timestamp": "2026-01-25T23:46:04.639829+00:00", "data": {"market": "0x2a4d3cf51d27425b0c51d241a7ba6bc44dd27034b44f9e437624f9e0953b1ea9", "price_changes": [{"asset_id": "58599269208124653793682124721644272657448822176028066253503704155842141815443", "price": "0.01", "size": "7555", "side": "BUY", "hash": "8803bf8cf08bc400a80e3583f0fec174039646ef", "best_bid": "0.35", "best_ask": "0.38"}, {"asset_id": "111798086980787121079742248333092569415172137759139099190565410999420761499752", "price": "0.99", "size": "7555", "side": "SELL", "hash": "5f60729d09e1503829620c681a7943a6d8b76cc8", "best_bid": "0.62", "best_ask": "0.65"}], "timestamp": "1769384764566", "event_type": "price_change"}}
{"_local_timestamp": "2026-01-25T23:46:04.640151+00:00", "data": {"market": "0x7f6dadade6357d3ce6681860d002bd3521554aba8b5acda912917b3db41c9549", "price_changes": [{"asset_id": "112538531010841097813690615473978896934576951101485955663285389253633812461690", "price": "0.01", "size": "5010.58", "side": "BUY", "hash": "b5b833f23ac76a475a1ca9b02825b4a93a527241", "best_bid": "0.72", "best_ask": "0.76"}, {"asset_id": "50613703516194910329561493534058464924948966095615247532634099427569284124317", "price": "0.99", "size": "5010.58", "side": "SELL", "hash": "0188286ffcd37894aeee92a45323e91a67276ed8", "best_bid": "0.24", "best_ask": "0.28"}], "timestamp": "1769384764566", "event_type": "price_change"}}
{"_local_timestamp": "2026-01-25T23:46:17.060384+00:00", "data": {"market": "0x7f6dadade6357d3ce6681860d002bd3521554aba8b5acda912917b3db41c9549", "price_changes": [{"asset_id": "112538531010841097813690615473978896934576951101485955663285389253633812461690", "price": "0.08", "size": "750", "side": "BUY", "hash": "e637f5fdf5900791855e0490f8ee781b030c6e6b", "best_bid": "0.72", "best_ask": "0.76"}, {"asset_id": "50613703516194910329561493534058464924948966095615247532634099427569284124317", "price": "0.92", "size": "750", "side": "SELL", "hash": "789f6db84db54e72e63091022b556d4b191dbe2f", "best_bid": "0.24", "best_ask": "0.28"}], "timestamp": "1769384776984", "event_type": "price_change"}}
{"_local_timestamp": "2026-01-25T23:46:19.310038+00:00", "data": {"market": "0x1a65d4eb8ac985309e78b48906291fffbf137cee590d8d75365f77a0549e9ab9", "price_changes": [{"asset_id": "48953332818425460061045724981972442660997032539861914953015827526728376958623", "price": "0.33", "size": "66.66", "side": "SELL", "hash": "14e7e7738ae2a277ee0a1b3920a2719922a368df", "best_bid": "0.29", "best_ask": "0.33"}, {"asset_id": "81870625725474135545086561756714985203836689747059214375533433096496527904265", "price": "0.67", "size": "66.66", "side": "BUY", "hash": "209b48dd8ce811b3ac3a54f8c34f4fe4174e5288", "best_bid": "0.67", "best_ask": "0.71"}], "timestamp": "1769384779242", "event_type": "price_change"}}
{"_local_timestamp": "2026-01-25T23:46:27.037656+00:00", "data": {"market": "0xcc63b656fcb3d80cc37ba73293a0dd41cedfc6113824a7eabc0ea44d47f2e3fb", "price_changes": [{"asset_id": "53785304590806186448100532051603643727400986103975240944527899277602345885656", "price": "0.004", "size": "0", "side": "SELL", "hash": "ec77d9be9784f6574b20a7e4d4754de1ec68f99b", "best_bid": "0.003", "best_ask": "0.005"}, {"asset_id": "78320823329062661687268056381693199301492237595012271766902388562197668380032", "price": "0.996", "size": "0", "side": "BUY", "hash": "8c3574b29aa1ae674a26ce77bbb5dd8529740a02", "best_bid": "0.995", "best_ask": "0.997"}], "timestamp": "1769384786919", "event_type": "price_change"}}
{"_local_timestamp": "2026-01-25T23:46:27.038141+00:00", "data": {"market": "0xcc63b656fcb3d80cc37ba73293a0dd41cedfc6113824a7eabc0ea44d47f2e3fb", "asset_id": "53785304590806186448100532051603643727400986103975240944527899277602345885656", "bids": [{"price": "0.001", "size": "14983"}, {"price": "0.002", "size": "4726"}, {"price": "0.003", "size": "769.83"}], "asks": [{"price": "0.999", "size": "7063.08"}, {"price": "0.998", "size": "3755.04"}, {"price": "0.997", "size": "1400"}, {"price": "0.996", "size": "8.63"}, {"price": "0.994", "size": "200"}, {"price": "0.99", "size": "5000"}, {"price": "0.989", "size": "8.38"}, {"price": "0.98", "size": "2498.97"}, {"price": "0.97", "size": "150"}, {"price": "0.969", "size": "8.35"}, {"price": "0.95", "size": "330"}, {"price": "0.949", "size": "39"}, {"price": "0.93", "size": "300"}, {"price": "0.9", "size": "860"}, {"price": "0.899", "size": "5.93"}, {"price": "0.85", "size": "551.66"}, {"price": "0.828", "size": "20"}, {"price": "0.8", "size": "460"}, {"price": "0.799", "size": "155"}, {"price": "0.75", "size": "112"}, {"price": "0.728", "size": "5.61"}, {"price": "0.7", "size": "286.66"}, {"price": "0.65", "size": "68.57"}, {"price": "0.6", "size": "175"}, {"price": "0.599", "size": "5"}, {"price": "0.25", "size": "431.09"}, {"price": "0.198", "size": "10"}, {"price": "0.049", "size": "300"}, {"price": "0.04", "size": "431.08"}, {"price": "0.034", "size": "7.57"}, {"price": "0.032", "size": "1018.6"}, {"price": "0.027", "size": "0.11"}, {"price": "0.026", "size": "1000"}, {"price": "0.02", "size": "300"}, {"price": "0.015", "size": "1074.9"}, {"price": "0.014", "size": "381.92"}, {"price": "0.013", "size": "241.83"}, {"price": "0.012", "size": "36"}, {"price": "0.011", "size": "25.34"}, {"price": "0.006", "size": "15"}, {"price": "0.005", "size": "5"}], "hash": "ec77d9be9784f6574b20a7e4d4754de1ec68f99b", "timestamp": "1769384786919", "event_type": "book"}}
{"_local_timestamp": "2026-01-25T23:46:27.038571+00:00", "data": {"market": "0xcc63b656fcb3d80cc37ba73293a0dd41cedfc6113824a7eabc0ea44d47f2e3fb", "asset_id": "78320823329062661687268056381693199301492237595012271766902388562197668380032", "bids": [{"price": "0.001", "size": "7063.08"}, {"price": "0.002", "size": "3755.04"}, {"price": "0.003", "size": "1400"}, {"price": "0.004", "size": "8.63"}, {"price": "0.006", "size": "200"}, {"price": "0.01", "size": "5000"}, {"price": "0.011", "size": "8.38"}, {"price": "0.02", "size": "2498.97"}, {"price": "0.03", "size": "150"}, {"price": "0.031", "size": "8.35"}, {"price": "0.05", "size": "330"}, {"price": "0.051", "size": "39"}, {"price": "0.07", "size": "300"}, {"price": "0.1", "size": "860"}, {"price": "0.101", "size": "5.93"}, {"price": "0.15", "size": "551.66"}, {"price": "0.172", "size": "20"}, {"price": "0.2", "size": "460"}, {"price": "0.201", "size": "155"}, {"price": "0.25", "size": "112"}, {"price": "0.272", "size": "5.61"}, {"price": "0.3", "size": "286.66"}, {"price": "0.35", "size": "68.57"}, {"price": "0.4", "size": "175"}, {"price": "0.401", "size": "5"}, {"price": "0.75", "size": "431.09"}, {"price": "0.802", "size": "10"}, {"price": "0.951", "size": "300"}, {"price": "0.96", "size": "431.08"}, {"price": "0.966", "size": "7.57"}, {"price": "0.968", "size": "1018.6"}, {"price": "0.973", "size": "0.11"}, {"price": "0.974", "size": "1000"}, {"price": "0.98", "size": "300"}, {"price": "0.985", "size": "1074.9"}, {"price": "0.986", "size": "381.92"}, {"price": "0.987", "size": "241.83"}, {"price": "0.988", "size": "36"}, {"price": "0.989", "size": "25.34"}, {"price": "0.994", "size": "15"}, {"price": "0.995", "size": "5"}], "asks": [{"price": "0.999", "size": "14983"}, {"price": "0.998", "size": "4726"}, {"price": "0.997", "size": "769.83"}], "hash": "8c3574b29aa1ae674a26ce77bbb5dd8529740a02", "timestamp": "1769384786919", "event_type": "book"}}
{"_local_timestamp": "2026-01-25T23:46:27.038810+00:00", "data": {"market": "0xcc63b656fcb3d80cc37ba73293a0dd41cedfc6113824a7eabc0ea44d47f2e3fb", "asset_id": "78320823329062661687268056381693199301492237595012271766902388562197668380032", "price": "0.996", "size": "11.03", "fee_rate_bps": "0", "side": "SELL", "timestamp": "1769384786947", "event_type": "last_trade_price", "transaction_hash": "0xa33fe49a896fde9edc79862da4b5cce31429ebb6c9445b6b6726d25440249e57"}}
{"_local_timestamp": "2026-01-25T23:46:28.480109+00:00", "data": {"market": "0xcc63b656fcb3d80cc37ba73293a0dd41cedfc6113824a7eabc0ea44d47f2e3fb", "price_changes": [{"asset_id": "53785304590806186448100532051603643727400986103975240944527899277602345885656", "price": "0.002", "size": "4753.76", "side": "BUY", "hash": "973c93b85bc07c56c38fc071c4aac0813c390b40", "best_bid": "0.003", "best_ask": "0.005"}, {"asset_id": "78320823329062661687268056381693199301492237595012271766902388562197668380032", "price": "0.998", "size": "4753.76", "side": "SELL", "hash": "984f0292bfb7bbbaf07e6ca4259be9b7f31db4e6", "best_bid": "0.995", "best_ask": "0.997"}], "timestamp": "1769384788369", "event_type": "price_change"}}
{"_local_timestamp": "2026-01-25T23:46:28.832457+00:00", "data": {"market": "0x7f6dadade6357d3ce6681860d002bd3521554aba8b5acda912917b3db41c9549", "price_changes": [{"asset_id": "50613703516194910329561493534058464924948966095615247532634099427569284124317", "price": "0.23", "size": "0", "side": "BUY", "hash": "da2f027f606e4d56ad738ccd6d930bd3dd7dddd7", "best_bid": "0.24", "best_ask": "0.28"}, {"asset_id": "112538531010841097813690615473978896934576951101485955663285389253633812461690", "price": "0.77", "size": "0", "side": "SELL", "hash": "87c412ad0d613e7099a0bc7a341e752ac2368049", "best_bid": "0.72", "best_ask": "0.76"}], "timestamp": "1769384788738", "event_type": "price_change"}}
{"_local_timestamp": "2026-01-25T23:46:29.842799+00:00", "data": {"market": "0xcc63b656fcb3d80cc37ba73293a0dd41cedfc6113824a7eabc0ea44d47f2e3fb", "price_changes": [{"asset_id": "53785304590806186448100532051603643727400986103975240944527899277602345885656", "price": "0.005", "size": "0", "side": "SELL", "hash": "5bbd300a666e31f770b00fa5cd3095e8f4e60d95", "best_bid": "0.003", "best_ask": "0.006"}, {"asset_id": "78320823329062661687268056381693199301492237595012271766902388562197668380032", "price": "0.995", "size": "0", "side": "BUY", "hash": "6ee929bb70e015ba8ba217bbd28bc9c2a73ffe1b", "best_bid": "0.994", "best_ask": "0.997"}], "timestamp": "1769384789736", "event_type": "price_change"}}
{"_local_timestamp": "2026-01-25T23:46:29.849088+00:00", "data": {"market": "0xcc63b656fcb3d80cc37ba73293a0dd41cedfc6113824a7eabc0ea44d47f2e3fb", "asset_id": "53785304590806186448100532051603643727400986103975240944527899277602345885656", "bids": [{"price": "0.001", "size": "14983"}, {"price": "0.002", "size": "4753.76"}, {"price": "0.003", "size": "769.83"}], "asks": [{"price": "0.999", "size": "7063.08"}, {"price": "0.998", "size": "3755.04"}, {"price": "0.997", "size": "1400"}, {"price": "0.996", "size": "8.63"}, {"price": "0.994", "size": "200"}, {"price": "0.99", "size": "5000"}, {"price": "0.989", "size": "8.38"}, {"price": "0.98", "size": "2498.97"}, {"price": "0.97", "size": "150"}, {"price": "0.969", "size": "8.35"}, {"price": "0.95", "size": "330"}, {"price": "0.949", "size": "39"}, {"price": "0.93", "size": "300"}, {"price": "0.9", "size": "860"}, {"price": "0.899", "size": "5.93"}, {"price": "0.85", "size": "551.66"}, {"price": "0.828", "size": "20"}, {"price": "0.8", "size": "460"}, {"price": "0.799", "size": "155"}, {"price": "0.75", "size": "112"}, {"price": "0.728", "size": "5.61"}, {"price": "0.7", "size": "286.66"}, {"price": "0.65", "size": "68.57"}, {"price": "0.6", "size": "175"}, {"price": "0.599", "size": "5"}, {"price": "0.25", "size": "431.09"}, {"price": "0.198", "size": "10"}, {"price": "0.049", "size": "300"}, {"price": "0.04", "size": "431.08"}, {"price": "0.034", "size": "7.57"}, {"price": "0.032", "size": "1018.6"}, {"price": "0.027", "size": "0.11"}, {"price": "0.026", "size": "1000"}, {"price": "0.02", "size": "300"}, {"price": "0.015", "size": "1074.9"}, {"price": "0.014", "size": "381.92"}, {"price": "0.013", "size": "241.83"}, {"price": "0.012", "size": "36"}, {"price": "0.011", "size": "25.34"}, {"price": "0.006", "size": "15"}], "hash": "5bbd300a666e31f770b00fa5cd3095e8f4e60d95", "timestamp": "1769384789736", "event_type": "book"}}
{"_local_timestamp": "2026-01-25T23:46:29.849506+00:00", "data": {"market": "0xcc63b656fcb3d80cc37ba73293a0dd41cedfc6113824a7eabc0ea44d47f2e3fb", "asset_id": "78320823329062661687268056381693199301492237595012271766902388562197668380032", "bids": [{"price": "0.001", "size": "7063.08"}, {"price": "0.002", "size": "3755.04"}, {"price": "0.003", "size": "1400"}, {"price": "0.004", "size": "8.63"}, {"price": "0.006", "size": "200"}, {"price": "0.01", "size": "5000"}, {"price": "0.011", "size": "8.38"}, {"price": "0.02", "size": "2498.97"}, {"price": "0.03", "size": "150"}, {"price": "0.031", "size": "8.35"}, {"price": "0.05", "size": "330"}, {"price": "0.051", "size": "39"}, {"price": "0.07", "size": "300"}, {"price": "0.1", "size": "860"}, {"price": "0.101", "size": "5.93"}, {"price": "0.15", "size": "551.66"}, {"price": "0.172", "size": "20"}, {"price": "0.2", "size": "460"}, {"price": "0.201", "size": "155"}, {"price": "0.25", "size": "112"}, {"price": "0.272", "size": "5.61"}, {"price": "0.3", "size": "286.66"}, {"price": "0.35", "size": "68.57"}, {"price": "0.4", "size": "175"}, {"price": "0.401", "size": "5"}, {"price": "0.75", "size": "431.09"}, {"price": "0.802", "size": "10"}, {"price": "0.951", "size": "300"}, {"price": "0.96", "size": "431.08"}, {"price": "0.966", "size": "7.57"}, {"price": "0.968", "size": "1018.6"}, {"price": "0.973", "size": "0.11"}, {"price": "0.974", "size": "1000"}, {"price": "0.98", "size": "300"}, {"price": "0.985", "size": "1074.9"}, {"price": "0.986", "size": "381.92"}, {"price": "0.987", "size": "241.83"}, {"price": "0.988", "size": "36"}, {"price": "0.989", "size": "25.34"}, {"price": "0.994", "size": "15"}], "asks": [{"price": "0.999", "size": "14983"}, {"price": "0.998", "size": "4753.76"}, {"price": "0.997", "size": "769.83"}], "hash": "6ee929bb70e015ba8ba217bbd28bc9c2a73ffe1b", "timestamp": "1769384789736", "event_type": "book"}}
{"_local_timestamp": "2026-01-25T23:46:29.849712+00:00", "data": {"market": "0xcc63b656fcb3d80cc37ba73293a0dd41cedfc6113824a7eabc0ea44d47f2e3fb", "asset_id": "78320823329062661687268056381693199301492237595012271766902388562197668380032", "price": "0.995", "size": "5", "fee_rate_bps": "0", "side": "SELL", "timestamp": "1769384789763", "event_type": "last_trade_price", "transaction_hash": "0x86b75dd1ab3c8150d89e4fc730938010250be5b7f14fa019e585b9e51df2fb5b"}}
{"_local_timestamp": "2026-01-25T23:46:29.892798+00:00", "data": {"market": "0xcc63b656fcb3d80cc37ba73293a0dd41cedfc6113824a7eabc0ea44d47f2e3fb", "price_changes": [{"asset_id": "53785304590806186448100532051603643727400986103975240944527899277602345885656", "price": "0.013", "size": "620.83", "side": "SELL", "hash": "c9582cf3fc2713b628c5458b571b231d204a18bb", "best_bid": "0.003", "best_ask": "0.006"}, {"asset_id": "78320823329062661687268056381693199301492237595012271766902388562197668380032", "price": "0.987", "size": "620.83", "side": "BUY", "hash": "ba1c5581c84408024f54308d263a6f3c05146573", "best_bid": "0.994", "best_ask": "0.997"}], "timestamp": "1769384789799", "event_type": "price_change"}}
{"_local_timestamp": "2026-01-25T23:46:30.176939+00:00", "data": {"market": "0x7f6dadade6357d3ce6681860d002bd3521554aba8b5acda912917b3db41c9549", "price_changes": [{"asset_id": "50613703516194910329561493534058464924948966095615247532634099427569284124317", "price": "0.24", "size": "66.66", "side": "BUY", "hash": "4761c9a9027215554983f9a819dfa2b1e02a67bd", "best_bid": "0.24", "best_ask": "0.28"}, {"asset_id": "112538531010841097813690615473978896934576951101485955663285389253633812461690", "price": "0.76", "size": "66.66", "side": "SELL", "hash": "61ffdcdcea17d4111a769fd61fe6b302fb68aa56", "best_bid": "0.72", "best_ask": "0.76"}], "timestamp": "1769384790066", "event_type": "price_change"}}
{"_local_timestamp": "2026-01-25T23:46:32.131320+00:00", "data": {"market": "0xcc63b656fcb3d80cc37ba73293a0dd41cedfc6113824a7eabc0ea44d47f2e3fb", "price_changes": [{"asset_id": "53785304590806186448100532051603643727400986103975240944527899277602345885656", "price": "0.005", "size": "11.04", "side": "SELL", "hash": "f7e43ea08fa7785816bc8fdce744ea85ffde1a1a", "best_bid": "0.003", "best_ask": "0.005"}, {"asset_id": "78320823329062661687268056381693199301492237595012271766902388562197668380032", "price": "0.995", "size": "11.04", "side": "BUY", "hash": "2bf004a12768ea31ec0694b3295f47920741b29c", "best_bid": "0.995", "best_ask": "0.997"}], "timestamp": "1769384792033", "event_type": "price_change"}}
{"_local_timestamp": "2026-01-25T23:46:32.151344+00:00", "data": {"market": "0xcc63b656fcb3d80cc37ba73293a0dd41cedfc6113824a7eabc0ea44d47f2e3fb", "price_changes": [{"asset_id": "53785304590806186448100532051603643727400986103975240944527899277602345885656", "price": "0.013", "size": "241.83", "side": "SELL", "hash": "d3440b2ade6e18e80f35124cb724545c965bdc4d", "best_bid": "0.003", "best_ask": "0.005"}, {"asset_id": "78320823329062661687268056381693199301492237595012271766902388562197668380032", "price": "0.987", "size": "241.83", "side": "BUY", "hash": "80ae4382fcbf1bfcda8b709132fec476ffec9765", "best_bid": "0.995", "best_ask": "0.997"}], "timestamp": "1769384792069", "event_type": "price_change"}}
{"_local_timestamp": "2026-01-25T23:46:32.177580+00:00", "data": {"market": "0x1a65d4eb8ac985309e78b48906291fffbf137cee590d8d75365f77a0549e9ab9", "price_changes": [{"asset_id": "48953332818425460061045724981972442660997032539861914953015827526728376958623", "price": "0.33", "size": "77.61", "side": "SELL", "hash": "01c3a9f2bd5ee097e1acfba4bb41388ef39407e0", "best_bid": "0.29", "best_ask": "0.33"}, {"asset_id": "81870625725474135545086561756714985203836689747059214375533433096496527904265", "price": "0.67", "size": "77.61", "side": "BUY", "hash": "82265688d4e61a0f0c932c2eb924ebb233d579ee", "best_bid": "0.67", "best_ask": "0.71"}], "timestamp": "1769384792092", "event_type": "price_change"}}
{"_local_timestamp": "2026-01-25T23:46:32.177884+00:00", "data": {"market": "0x1a65d4eb8ac985309e78b48906291fffbf137cee590d8d75365f77a0549e9ab9", "price_changes": [{"asset_id": "48953332818425460061045724981972442660997032539861914953015827526728376958623", "price": "0.33", "size": "88.56", "side": "SELL", "hash": "03f71b61f6c59876d912f8ca734946bf5b2a1a6a", "best_bid": "0.29", "best_ask": "0.33"}, {"asset_id": "81870625725474135545086561756714985203836689747059214375533433096496527904265", "price": "0.67", "size": "88.56", "side": "BUY", "hash": "d597f8b840e344eb2895d184d960ebcf092a199f", "best_bid": "0.67", "best_ask": "0.71"}], "timestamp": "1769384792093", "event_type": "price_change"}}
{"_local_timestamp": "2026-01-25T23:46:33.028024+00:00", "data": {"market": "0xcc63b656fcb3d80cc37ba73293a0dd41cedfc6113824a7eabc0ea44d47f2e3fb", "price_changes": [{"asset_id": "53785304590806186448100532051603643727400986103975240944527899277602345885656", "price": "0.006", "size": "11.04", "side": "SELL", "hash": "d0e5241851b3acaa396a588a5301ab33972cc06a", "best_bid": "0.003", "best_ask": "0.006"}, {"asset_id": "78320823329062661687268056381693199301492237595012271766902388562197668380032", "price": "0.994", "size": "11.04", "side": "BUY", "hash": "fba067b9b7ea230a7b26a2da128822b57020ec87", "best_bid": "0.994", "best_ask": "0.997"}], "timestamp": "1769384792942", "event_type": "price_change"}}
{"_local_timestamp": "2026-01-25T23:46:33.028313+00:00", "data": {"market": "0xcc63b656fcb3d80cc37ba73293a0dd41cedfc6113824a7eabc0ea44d47f2e3fb", "price_changes": [{"asset_id": "53785304590806186448100532051603643727400986103975240944527899277602345885656", "price": "0.005", "size": "0", "side": "SELL", "hash": "d0e5241851b3acaa396a588a5301ab33972cc06a", "best_bid": "0.003", "best_ask": "0.006"}, {"asset_id": "78320823329062661687268056381693199301492237595012271766902388562197668380032", "price": "0.995", "size": "0", "side": "BUY", "hash": "fba067b9b7ea230a7b26a2da128822b57020ec87", "best_bid": "0.994", "best_ask": "0.997"}], "timestamp": "1769384792942", "event_type": "price_change"}}
