{"_local_timestamp": "2026-01-25T23:33:41.769089+00:00", "data": [{"market": "0x83547249e61eaf92162353753801453d313daaed73b401b9edcc669251f578c0", "asset_id": "64710685063708113016458069418988206406890895555826348081008842775253721088516", "timestamp": "1769384018107", "hash": "48195e40f5e8ef1cde7268e8f024a42ff4855a07", "bids": [{"price": "0.001", "size": "3503.83"}, {"price": "0.002", "size": "250"}, {"price": "0.003", "size": "14.08"}, {"price": "0.005", "size": "200"}, {"price": "0.009", "size": "100"}, {"price": "0.01", "size": "50"}, {"price": "0.011", "size": "15.07"}, {"price": "0.021", "size": "100"}, {"price": "0.022", "size": "13.25"}, {"price": "0.023", "size": "21.28"}, {"price": "0.051", "size": "55"}, {"price": "0.108", "size": "4256"}, {"price": "0.109", "size": "3870"}, {"price": "0.11", "size": "9"}, {"price": "0.613", "size": "21.2"}, {"price": "0.614", "size": "17.91"}, {"price": "0.696", "size": "264.45"}, {"price": "0.714", "size": "335.62"}, {"price": "0.715", "size": "118.37"}, {"price": "0.718", "size": "83.9"}, {"price": "0.719", "size": "20.6"}, {"price": "0.74", "size": "90.69"}], "asks": [{"price": "0.999", "size": "10166.95"}, {"price": "0.998", "size": "350"}, {"price": "0.997", "size": "139.79"}, {"price": "0.996", "size": "65.71"}, {"price": "0.994", "size": "12"}, {"price": "0.993", "size": "10.34"}, {"price": "0.919", "size": "250"}, {"price": "0.918", "size": "6.57"}, {"price": "0.872", "size": "250"}, {"price": "0.862", "size": "94.2"}, {"price": "0.816", "size": "12.6"}, {"price": "0.809", "size": "45.12"}, {"price": "0.796", "size": "50.7"}, {"price": "0.782", "size": "61"}, {"price": "0.781", "size": "106.09"}], "event_type": "book", "last_trade_price": "0.261"}, {"market": "0x83547249e61eaf92162353753801453d313daaed73b401b9edcc669251f578c0", "asset_id": "49285515506903050077566386836604355110855655545900685629915315206051894927030", "timestamp": "1769384018107", "hash": "ee3f234e3c33900fa02befdf8a814b800f9209f0", "bids": [{"price": "0.001", "size": "10166.95"}, {"price": "0.002", "size": "350"}, {"price": "0.003", "size": "139.79"}, {"price": "0.004", "size": "65.71"}, {"price": "0.006", "size": "12"}, {"price": "0.007", "size": "10.34"}, {"price": "0.081", "size": "250"}, {"price": "0.082", "size": "6.57"}, {"price": "0.128", "size": "250"}, {"price": "0.138", "size": "94.2"}, {"price": "0.184", "size": "12.6"}, {"price": "0.191", "size": "45.12"}, {"price": "0.204", "size": "50.7"}, {"price": "0.218", "size": "61"}, {"price": "0.219", "size": "106.09"}], "asks": [{"price": "0.999", "size": "3503.83"}, {"price": "0.998", "size": "250"}, {"price": "0.997", "size": "14.08"}, {"price": "0.995", "size": "200"}, {"price": "0.991", "size": "100"}, {"price": "0.99", "size": "50"}, {"price": "0.989", "size": "15.07"}, {"price": "0.979", "size": "100"}, {"price": "0.978", "size": "13.25"}, {"price": "0.977", "size": "21.28"}, {"price": "0.949", "size": "55"}, {"price": "0.892", "size": "4256"}, {"price": "0.891", "size": "3870"}, {"price": "0.89", "size": "9"}, {"price": "0.387", "size": "21.2"}, {"price": "0.386", "size": "17.91"}, {"price": "0.304", "size": "264.45"}, {"price": "0.286", "size": "335.62"}, {"price": "0.285", "size": "118.37"}, {"price": "0.282", "size": "83.9"}, {"price": "0.281", "size": "20.6"}, {"price": "0.26", "size": "90.69"}], "event_type": "book", "last_trade_price": "0.261"}, {"market": "0x3254c0fde930bd86e5cc6cf9eb9dc16ca364ab4819ed5e1802a53b0fa2f36772", "asset_id": "1243252154129193015238236663840507016761347339076756815039433906036180619298", "timestamp": "1769383952620", "hash": "707154fcf7a54e8865215a4e8f5118f4bf216c3c", "bids": [{"price": "0.01", "size": "55.25"}, {"price": "0.02", "size": "16.68"}, {"price": "0.04", "size": "12"}, {"price": "0.06", "size": "33"}, {"price": "0.09", "size": "100"}, {"price": "0.1", "size": "1600"}, {"price": "0.11", "size": "5.58"}, {"price": "0.14", "size": "46.51"}, {"price": "0.18", "size": "72.22"}, {"price": "0.19", "size": "842"}, {"price": "0.22", "size": "50"}, {"price": "0.25", "size": "13"}, {"price": "0.28", "size": "7"}, {"price": "0.29", "size": "10"}, {"price": "0.79", "size": "105"}, {"price": "0.8", "size": "50"}, {"price": "0.81", "size": "20"}], "asks": [{"price": "0.99", "size": "60"}, {"price": "0.98", "size": "12.23"}, {"price": "0.97", "size": "433.33"}, {"price": "0.96", "size": "343.63"}, {"price": "0.95", "size": "201"}, {"price": "0.94", "size": "7.24"}, {"price": "0.91", "size": "396.11"}], "event_type": "book", "last_trade_price": ""}, {"market": "0x983c1c640da74bd05222b1ae535d9d80e67a7c37ba821e213ab681da63f7b52d", "asset_id": "33334365343701835814605836236502189532077473322352990496796220640667787771374", "timestamp": "1769383810016", "hash": "c2f81f98a0b2990c88cdec92793048080476819a", "bids": [{"price": "0.001", "size": "4285.99"}, {"price": "0.01", "size": "60"}, {"price": "0.011", "size": "200"}, {"price": "0.012", "size": "125"}, {"price": "0.013", "size": "92.3"}], "asks": [{"price": "0.999", "size": "5385.95"}, {"price": "0.998", "size": "250"}, {"price": "0.997", "size": "17.68"}, {"price": "0.99", "size": "50"}, {"price": "0.989", "size": "200"}, {"price": "0.988", "size": "30"}, {"price": "0.987", "size": "17.38"}, {"price": "0.96", "size": "12"}, {"price": "0.94", "size": "33"}, {"price": "0.939", "size": "16"}, {"price": "0.934", "size": "30"}, {"price": "0.933", "size": "10.59"}, {"price": "0.1", "size": "36"}, {"price": "0.098", "size": "8.06"}, {"price": "0.095", "size": "16.43"}, {"price": "0.094", "size": "45"}], "event_type": "book", "last_trade_price": "0.099"}, {"market": "0xc6eaad93752e4f8b58b9faf7e63ec9ba1c548a49e6fe6b21f605ed9d71f4c57a", "asset_id": "25539386078797395599636818043909403100500096091846839226569678716060642614342", "timestamp": "1769383901926", "hash": "58c06fe92193895adaa1877319a8c9a2812614f6", "bids": [{"price": "0.001", "size": "2582.99"}, {"price": "0.002", "size": "100"}, {"price": "0.003", "size": "10"}, {"price": "0.01", "size": "60"}, {"price": "0.011", "size": "230"}, {"price": "0.012", "size": "99.99"}], "asks": [{"price": "0.999", "size": "5793.84"}, {"price": "0.998", "size": "450"}, {"price": "0.997", "size": "19.28"}, {"price": "0.99", "size": "50"}, {"price": "0.989", "size": "200"}, {"price": "0.987", "size": "56"}, {"price": "0.986", "size": "15.32"}, {"price": "0.97", "size": "16"}, {"price": "0.95", "size": "20"}, {"price": "0.94", "size": "33"}, {"price": "0.935", "size": "30"}, {"price": "0.934", "size": "10.86"}, {"price": "0.362", "size": "5"}, {"price": "0.29", "size": "5"}, {"price": "0.282", "size": "21.25"}, {"price": "0.18", "size": "5"}, {"price": "0.179", "size": "6.98"}], "event_type": "book", "last_trade_price": ""}, {"market": "0xaef8cc72583c46308a4f61b93cce219831d4861af26c0ace983300183b5d6f77", "asset_id": "97904810933420938915915184802871896723926497912237502816269649051469198352574", "timestamp": "1769383901916", "hash": "c2f1544ce6a111cbf70945ce1782d6a75d119f7f", "bids": [{"price": "0.01", "size": "64.96"}, {"price": "0.02", "size": "13.81"}, {"price": "0.04", "size": "18.85"}, {"price": "0.05", "size": "16"}, {"price": "0.06", "size": "38"}, {"price": "0.83", "size": "20"}], "asks": [{"price": "0.99", "size": "75.19"}, {"price": "0.98", "size": "2014.02"}, {"price": "0.97", "size": "300"}, {"price": "0.96", "size": "28.54"}, {"price": "0.95", "size": "198"}, {"price": "0.94", "size": "38.1"}, {"price": "0.93", "size": "20"}], "event_type": "book", "last_trade_price": ""}, {"market": "0xee6de29096f712879525fffe70ec19ed1069660c17a96770c990a48a4d6cafca", "asset_id": "79250352452729964397183638491507951490462474124621653995906925320890963543836", "timestamp": "1769383901948", "hash": "3ad7bee7943ebce85d6ffec44f777dfc229488ee", "bids": [{"price": "0.001", "size": "2723.11"}, {"price": "0.002", "size": "355.08"}, {"price": "0.003", "size": "166"}, {"price": "0.004", "size": "8.69"}, {"price": "0.006", "size": "83"}, {"price": "0.01", "size": "50"}, {"price": "0.011", "size": "27.4"}, {"price": "0.04", "size": "12"}, {"price": "0.05", "size": "20"}, {"price": "0.051", "size": "39"}, {"price": "0.084", "size": "12"}, {"price": "0.085", "size": "7.63"}, {"price": "0.115", "size": "17"}, {"price": "0.116", "size": "10"}, {"price": "0.885", "size": "48"}, {"price": "0.886", "size": "32.78"}, {"price": "0.887", "size": "45"}], "asks": [{"price": "0.999", "size": "6541.22"}, {"price": "0.998", "size": "261.42"}, {"price": "0.997", "size": "22.14"}, {"price": "0.995", "size": "1111"}, {"price": "0.994", "size": "18.06"}, {"price": "0.99", "size": "60"}, {"price": "0.989", "size": "28.19"}, {"price": "0.979", "size": "100"}, {"price": "0.976", "size": "1500"}, {"price": "0.975", "size": "100"}, {"price": "0.974", "size": "56.02"}, {"price": "0.967", "size": "105"}, {"price": "0.966", "size": "9.71"}, {"price": "0.953", "size": "55"}, {"price": "0.952", "size": "41"}, {"price": "0.951", "size": "25"}, {"price": "0.95", "size": "15.89"}], "event_type": "book", "last_trade_price": ""}, {"market": "0xee6de29096f712879525fffe70ec19ed1069660c17a96770c990a48a4d6cafca", "asset_id": "91615446195150618766021553383612375719498472212737560539314895278406213528776", "timestamp": "1769383901948", "hash": "c442f09443b10bd296b6ee68eda63cb9074a9e12", "bids": [{"price": "0.001", "size": "6541.22"}, {"price": "0.002", "size": "261.42"}, {"price": "0.003", "size": "22.14"}, {"price": "0.005", "size": "1111"}, {"price": "0.006", "size": "18.06"}, {"price": "0.01", "size": "60"}, {"price": "0.011", "size": "28.19"}, {"price": "0.021", "size": "100"}, {"price": "0.024", "size": "1500"}, {"price": "0.025", "size": "100"}, {"price": "0.026", "size": "56.02"}, {"price": "0.033", "size": "105"}, {"price": "0.034", "size": "9.71"}, {"price": "0.047", "size": "55"}, {"price": "0.048", "size": "41"}, {"price": "0.049", "size": "25"}, {"price": "0.05", "size": "15.89"}], "asks": [{"price": "0.999", "size": "2723.11"}, {"price": "0.998", "size": "355.08"}, {"price": "0.997", "size": "166"}, {"price": "0.996", "size": "8.69"}, {"price": "0.994", "size": "83"}, {"price": "0.99", "size": "50"}, {"price": "0.989", "size": "27.4"}, {"price": "0.96", "size": "12"}, {"price": "0.95", "size": "20"}, {"price": "0.949", "size": "39"}, {"price": "0.916", "size": "12"}, {"price": "0.915", "size": "7.63"}, {"price": "0.885", "size": "17"}, {"price": "0.884", "size": "10"}, {"price": "0.115", "size": "48"}, {"price": "0.114", "size": "32.78"}, {"price": "0.113", "size": "45"}], "event_type": "book", "last_trade_price": ""}, {"market": "0x5abc2d9caaf50e30bdc9559402e379cd2ac2eb6d0ab19d79b0d970c4f69b033a", "asset_id": "39155700119455511234840717902882582282164964669646100365952133017342151164941", "timestamp": "1769381764639", "hash": "73694d7b50cd5fda9d2c7abae0690a52db26804a", "bids": [{"price": "0.001", "size": "9680"}, {"price": "0.002", "size": "484.67"}, {"price": "0.004", "size": "56.41"}], "asks": [{"price": "0.999", "size": "3157.13"}, {"price": "0.998", "size": "255.09"}, {"price": "0.997", "size": "166"}, {"price": "0.996", "size": "8.72"}, {"price": "0.994", "size": "83"}, {"price": "0.99", "size": "50"}, {"price": "0.989", "size": "16.48"}, {"price": "0.96", "size": "12"}, {"price": "0.95", "size": "20"}, {"price": "0.949", "size": "39"}, {"price": "0.948", "size": "14.77"}, {"price": "0.886", "size": "8"}, {"price": "0.885", "size": "17"}, {"price": "0.149", "size": "100"}, {"price": "0.142", "size": "5"}, {"price": "0.045", "size": "110"}, {"price": "0.018", "size": "79.22"}, {"price": "0.016", "size": "110"}, {"price": "0.015", "size": "7.79"}, {"price": "0.014", "size": "10.9"}, {"price": "0.013", "size": "18.16"}, {"price": "0.01", "size": "25"}, {"price": "0.008", "size": "198"}], "event_type": "book", "last_trade_price": "0.002"}, {"market": "0x3254c0fde930bd86e5cc6cf9eb9dc16ca364ab4819ed5e1802a53b0fa2f36772", "asset_id": "28260696393853739649130713837590031037312393528301041179223890674988415162070", "timestamp": "1769383952620", "hash": "4121a4ba2003da8b4e98ccb2553cd17fd48bf91e", "bids": [{"price": "0.01", "size": "60"}, {"price": "0.02", "size": "12.23"}, {"price": "0.03", "size": "433.33"}, {"price": "0.04", "size": "343.63"}, {"price": "0.05", "size": "201"}, {"price": "0.06", "size": "7.24"}, {"price": "0.09", "size": "396.11"}], "asks": [{"price": "0.99", "size": "55.25"}, {"price": "0.98", "size": "16.68"}, {"price": "0.96", "size": "12"}, {"price": "0.94", "size": "33"}, {"price": "0.91", "size": "100"}, {"price": "0.9", "size": "1600"}, {"price": "0.89", "size": "5.58"}, {"price": "0.86", "size": "46.51"}, {"price": "0.82", "size": "72.22"}, {"price": "0.81", "size": "842"}, {"price": "0.78", "size": "50"}, {"price": "0.75", "size": "13"}, {"price": "0.72", "size": "7"}, {"price": "0.71", "size": "10"}, {"price": "0.21", "size": "105"}, {"price": "0.2", "size": "50"}, {"price": "0.19", "size": "20"}], "event_type": "book", "last_trade_price": ""}, {"market": "0x5abc2d9caaf50e30bdc9559402e379cd2ac2eb6d0ab19d79b0d970c4f69b033a", "asset_id": "18405676401614553494335334744262961918896842289177340891934329791228569310162", "timestamp": "1769381764639", "hash": "5f0dafd183ebbf357f0dfb9b906541d341952438", "bids": [{"price": "0.001", "size": "3157.13"}, {"price": "0.002", "size": "255.09"}, {"price": "0.003", "size": "166"}, {"price": "0.004", "size": "8.72"}, {"price": "0.006", "size": "83"}, {"price": "0.01", "size": "50"}, {"price": "0.011", "size": "16.48"}, {"price": "0.04", "size": "12"}, {"price": "0.05", "size": "20"}, {"price": "0.051", "size": "39"}, {"price": "0.052", "size": "14.77"}, {"price": "0.114", "size": "8"}, {"price": "0.115", "size": "17"}, {"price": "0.851", "size": "100"}, {"price": "0.858", "size": "5"}, {"price": "0.955", "size": "110"}, {"price": "0.982", "size": "79.22"}, {"price": "0.984", "size": "110"}, {"price": "0.985", "size": "7.79"}, {"price": "0.986", "size": "10.9"}, {"price": "0.987", "size": "18.16"}, {"price": "0.99", "size": "25"}, {"price": "0.992", "size": "198"}], "asks": [{"price": "0.999", "size": "9680"}, {"price": "0.998", "size": "484.67"}, {"price": "0.996", "size": "56.41"}], "event_type": "book", "last_trade_price": "0.002"}, {"market": "0x4c8a4ecc294553e865f9bed3cf2ba6d1cefe23515f6ece2b6b01f696d2845fe0", "asset_id": "93232945228609658077531889011480905670187160388516295356072507802163300422442", "timestamp": "1769383848494", "hash": "dc9238148d9528a60ecf121a866408a7274b5dda", "bids": [{"price": "0.01", "size": "60"}, {"price": "0.02", "size": "18.31"}, {"price": "0.04", "size": "12"}, {"price": "0.05", "size": "1020"}, {"price": "0.06", "size": "33"}, {"price": "0.07", "size": "9.05"}, {"price": "0.09", "size": "144.44"}, {"price": "0.1", "size": "110"}, {"price": "0.14", "size": "515"}, {"price": "0.15", "size": "250"}, {"price": "0.19", "size": "10.31"}], "asks": [{"price": "0.99", "size": "55.24"}, {"price": "0.98", "size": "8.57"}, {"price": "0.97", "size": "9.97"}, {"price": "0.95", "size": "30"}, {"price": "0.93", "size": "101"}, {"price": "0.92", "size": "50"}, {"price": "0.91", "size": "5.3"}, {"price": "0.9", "size": "10"}, {"price": "0.84", "size": "81.25"}, {"price": "0.83", "size": "64.7"}, {"price": "0.82", "size": "11"}], "event_type": "book", "last_trade_price": ""}, {"market": "0x4f23a49ee29fb939c5362cd64d46308244a57940dbb0b310f8285c9eb86fc716", "asset_id": "97176661089474192633400371830610594863643347280235884018546189389594263735812", "timestamp": "1769383859874", "hash": "97120824f5fbb72e34a9f81f7a0bfa7b68db10a8", "bids": [{"price": "0.001", "size": "2723.38"}, {"price": "0.002", "size": "455.35"}, {"price": "0.003", "size": "166"}, {"price": "0.004", "size": "9.15"}, {"price": "0.006", "size": "83"}, {"price": "0.01", "size": "55"}, {"price": "0.011", "size": "19.39"}, {"price": "0.03", "size": "16"}, {"price": "0.05", "size": "20"}, {"price": "0.051", "size": "39"}, {"price": "0.063", "size": "16"}, {"price": "0.064", "size": "31"}, {"price": "0.065", "size": "11.29"}, {"price": "0.82", "size": "7.98"}, {"price": "0.89", "size": "48.39"}, {"price": "0.98", "size": "2.36"}], "asks": [{"price": "0.999", "size": "6525.99"}, {"price": "0.998", "size": "216.63"}, {"price": "0.997", "size": "111.03"}, {"price": "0.996", "size": "79.56"}, {"price": "0.99", "size": "38.98"}], "event_type": "book", "last_trade_price": "0.020"}, {"market": "0x4c8a4ecc294553e865f9bed3cf2ba6d1cefe23515f6ece2b6b01f696d2845fe0", "asset_id": "51915547669523222925311577874361232586045773418874670768734077060997483885755", "timestamp": "1769383848494", "hash": "381a124674ae267e73b0208c411ca93ba208fd48", "bids": [{"price": "0.01", "size": "55.24"}, {"price": "0.02", "size": "8.57"}, {"price": "0.03", "size": "9.97"}, {"price": "0.05", "size": "30"}, {"price": "0.07", "size": "101"}, {"price": "0.08", "size": "50"}, {"price": "0.09", "size": "5.3"}, {"price": "0.1", "size": "10"}, {"price": "0.16", "size": "81.25"}, {"price": "0.17", "size": "64.7"}, {"price": "0.18", "size": "11"}], "asks": [{"price": "0.99", "size": "60"}, {"price": "0.98", "size": "18.31"}, {"price": "0.96", "size": "12"}, {"price": "0.95", "size": "1020"}, {"price": "0.94", "size": "33"}, {"price": "0.93", "size": "9.05"}, {"price": "0.91", "size": "144.44"}, {"price": "0.9", "size": "110"}, {"price": "0.86", "size": "515"}, {"price": "0.85", "size": "250"}, {"price": "0.81", "size": "10.31"}], "event_type": "book", "last_trade_price": ""}, {"market": "0x983c1c640da74bd05222b1ae535d9d80e67a7c37ba821e213ab681da63f7b52d", "asset_id": "111487994318578797618498789659864547400234714169664391253427670617626566154712", "timestamp": "1769383810016", "hash": "7f0b906dbad20d19100a9cb8cc10cff527068e07", "bids": [{"price": "0.001", "size": "5385.95"}, {"price": "0.002", "size": "250"}, {"price": "0.003", "size": "17.68"}, {"price": "0.01", "size": "50"}, {"price": "0.011", "size": "200"}, {"price": "0.012", "size": "30"}, {"price": "0.013", "size": "17.38"}, {"price": "0.04", "size": "12"}, {"price": "0.06", "size": "33"}, {"price": "0.061", "size": "16"}, {"price": "0.066", "size": "30"}, {"price": "0.067", "size": "10.59"}, {"price": "0.9", "size": "36"}, {"price": "0.902", "size": "8.06"}, {"price": "0.905", "size": "16.43"}, {"price": "0.906", "size": "45"}], "asks": [{"price": "0.999", "size": "4285.99"}, {"price": "0.99", "size": "60"}, {"price": "0.989", "size": "200"}, {"price": "0.988", "size": "125"}, {"price": "0.987", "size": "92.3"}], "event_type": "book", "last_trade_price": "0.099"}, {"market": "0xaef8cc72583c46308a4f61b93cce219831d4861af26c0ace983300183b5d6f77", "asset_id": "23410860411880980077660432875622355119426529164122573169196610980318417032021", "timestamp": "1769383901916", "hash": "500fb3ca83c2b0cbeb7301e4a7b8b64f51f0ec27", "bids": [{"price": "0.01", "size": "75.19"}, {"price": "0.02", "size": "2014.02"}, {"price": "0.03", "size": "300"}, {"price": "0.04", "size": "28.54"}, {"price": "0.05", "size": "198"}, {"price": "0.06", "size": "38.1"}, {"price": "0.07", "size": "20"}], "asks": [{"price": "0.99", "size": "64.96"}, {"price": "0.98", "size": "13.81"}, {"price": "0.96", "size": "18.85"}, {"price": "0.95", "size": "16"}, {"price": "0.94", "size": "38"}, {"price": "0.17", "size": "20"}], "event_type": "book", "last_trade_price": ""}, {"market": "0x4f23a49ee29fb939c5362cd64d46308244a57940dbb0b310f8285c9eb86fc716", "asset_id": "4736807889727546600449711523206670596020980806462877805590160133017151608432", "timestamp": "1769383859874", "hash": "d5b024cebfd309462c842ec78f3e393a138d332c", "bids": [{"price": "0.001", "size": "6525.99"}, {"price": "0.002", "size": "216.63"}, {"price": "0.003", "size": "111.03"}, {"price": "0.004", "size": "79.56"}, {"price": "0.01", "size": "38.98"}], "asks": [{"price": "0.999", "size": "2723.38"}, {"price": "0.998", "size": "455.35"}, {"price": "0.997", "size": "166"}, {"price": "0.996", "size": "9.15"}, {"price": "0.994", "size": "83"}, {"price": "0.99", "size": "55"}, {"price": "0.989", "size": "19.39"}, {"price": "0.97", "size": "16"}, {"price": "0.95", "size": "20"}, {"price": "0.949", "size": "39"}, {"price": "0.937", "size": "16"}, {"price": "0.936", "size": "31"}, {"price": "0.935", "size": "11.29"}, {"price": "0.18", "size": "7.98"}, {"price": "0.11", "size": "48.39"}, {"price": "0.02", "size": "2.36"}], "event_type": "book", "last_trade_price": "0.020"}, {"market": "0xc6eaad93752e4f8b58b9faf7e63ec9ba1c548a49e6fe6b21f605ed9d71f4c57a", "asset_id": "106764258059853211019809099342916860924409096361081427559669257851522126201276", "timestamp": "1769383901926", "hash": "f48150307f2740daed2e8c85049f0352b8aad11b", "bids": [{"price": "0.001", "size": "5793.84"}, {"price": "0.002", "size": "450"}, {"price": "0.003", "size": "19.28"}, {"price": "0.01", "size": "50"}, {"price": "0.011", "size": "200"}, {"price": "0.013", "size": "56"}, {"price": "0.014", "size": "15.32"}, {"price": "0.03", "size": "16"}, {"price": "0.05", "size": "20"}, {"price": "0.06", "size": "33"}, {"price": "0.065", "size": "30"}, {"price": "0.066", "size": "10.86"}, {"price": "0.638", "size": "5"}, {"price": "0.71", "size": "5"}, {"price": "0.718", "size": "21.25"}, {"price": "0.82", "size": "5"}, {"price": "0.821", "size": "6.98"}], "asks": [{"price": "0.999", "size": "2582.99"}, {"price": "0.998", "size": "100"}, {"price": "0.997", "size": "10"}, {"price": "0.99", "size": "60"}, {"price": "0.989", "size": "230"}, {"price": "0.988", "size": "99.99"}], "event_type": "book", "last_trade_price": ""}]}
{"_local_timestamp": "2026-01-25T23:33:47.796112+00:00", "data": {"market": "0x83547249e61eaf92162353753801453d313daaed73b401b9edcc669251f578c0", "price_changes": [{"asset_id": "49285515506903050077566386836604355110855655545900685629915315206051894927030", "price": "0.259", "size": "12.47", "side": "SELL", "hash": "eddf4ed87159aa07fcfe804276dfdb92723a7681", "best_bid": "0.219", "best_ask": "0.259"}, {"asset_id": "64710685063708113016458069418988206406890895555826348081008842775253721088516", "price": "0.741", "size": "12.47", "side": "BUY", "hash": "9bb17b1bf5c409d0bb0a4bdc1230c4e945626290", "best_bid": "0.741", "best_ask": "0.781"}], "timestamp": "1769384027725", "event_type": "price_change"}}
{"_local_timestamp": "2026-01-25T23:33:48.417865+00:00", "data": {"market": "0xaef8cc72583c46308a4f61b93cce219831d4861af26c0ace983300183b5d6f77", "price_changes": [{"asset_id": "23410860411880980077660432875622355119426529164122573169196610980318417032021", "price": "0.07", "size": "41", "side": "BUY", "hash": "13435168260aaac3c16e45153a3c60f5250292e6", "best_bid": "0.07", "best_ask": "0.17"}, {"asset_id": "97904810933420938915915184802871896723926497912237502816269649051469198352574", "price": "0.93", "size": "41", "side": "SELL", "hash": "4f11550d433b1959dfa3d11909d4f0c7e1370748", "best_bid": "0.83", "best_ask": "0.93"}], "timestamp": "1769384028349", "event_type": "price_change"}}
{"_local_timestamp": "2026-01-25T23:33:48.579507+00:00", "data": {"market": "0xaef8cc72583c46308a4f61b93cce219831d4861af26c0ace983300183b5d6f77", "price_changes": [{"asset_id": "97904810933420938915915184802871896723926497912237502816269649051469198352574", "price": "0.83", "size": "42", "side": "BUY", "hash": "867098437d5ee777dc12e7649359a534adc70954", "best_bid": "0.83", "best_ask": "0.93"}, {"asset_id": "23410860411880980077660432875622355119426529164122573169196610980318417032021", "price": "0.17", "size": "42", "side": "SELL", "hash": "0b4512287dcc72bb43b25a08294255f7a55dd736", "best_bid": "0.07", "best_ask": "0.17"}], "timestamp": "1769384028514", "event_type": "price_change"}}
{"_local_timestamp": "2026-01-25T23:34:37.047100+00:00", "data": {"market": "0x983c1c640da74bd05222b1ae535d9d80e67a7c37ba821e213ab681da63f7b52d", "price_changes": [{"asset_id": "33334365343701835814605836236502189532077473322352990496796220640667787771374", "price": "0.095", "size": "0", "side": "SELL", "hash": "0f4c99f528d7147ff01d67f476890260ce196caf", "best_bid": "0.013", "best_ask": "0.094"}, {"asset_id": "111487994318578797618498789659864547400234714169664391253427670617626566154712", "price": "0.905", "size": "0", "side": "BUY", "hash": "8dd5c72be93b9d6d56563bb31b2edc7928a99aee", "best_bid": "0.906", "best_ask": "0.987"}], "timestamp": "1769384076812", "event_type": "price_change"}}
{"_local_timestamp": "2026-01-25T23:34:37.278874+00:00", "data": {"market": "0x983c1c640da74bd05222b1ae535d9d80e67a7c37ba821e213ab681da63f7b52d", "price_changes": [{"asset_id": "33334365343701835814605836236502189532077473322352990496796220640667787771374", "price": "0.093", "size": "16.53", "side": "SELL", "hash": "6419f533e0d2c7fd1517642aa18f47a46cd38693", "best_bid": "0.013", "best_ask": "0.093"}, {"asset_id": "111487994318578797618498789659864547400234714169664391253427670617626566154712", "price": "0.907", "size": "16.53", "side": "BUY", "hash": "2dc70b95576f360641cb0bae013d04f5958ee68f", "best_bid": "0.907", "best_ask": "0.987"}], "timestamp": "1769384077055", "event_type": "price_change"}}
{"_local_timestamp": "2026-01-25T23:34:41.531161+00:00", "data": {"market": "0xee6de29096f712879525fffe70ec19ed1069660c17a96770c990a48a4d6cafca", "price_changes": [{"asset_id": "79250352452729964397183638491507951490462474124621653995906925320890963543836", "price": "0.887", "size": "0", "side": "BUY", "hash": "c456645284b62665efca1e038aa02be3ee211700", "best_bid": "0.886", "best_ask": "0.951"}, {"asset_id": "91615446195150618766021553383612375719498472212737560539314895278406213528776", "price": "0.113", "size": "0", "side": "SELL", "hash": "e6f2631fc6c4f1a821dffd99458c51c01d983866", "best_bid": "0.049", "best_ask": "0.114"}], "timestamp": "1769384081417", "event_type": "price_change"}}
{"_local_timestamp": "2026-01-25T23:34:41.531723+00:00", "data": {"market": "0xee6de29096f712879525fffe70ec19ed1069660c17a96770c990a48a4d6cafca", "price_changes": [{"asset_id": "79250352452729964397183638491507951490462474124621653995906925320890963543836", "price": "0.95", "size": "0", "side": "SELL", "hash": "c456645284b62665efca1e038aa02be3ee211700", "best_bid": "0.886", "best_ask": "0.951"}, {"asset_id": "91615446195150618766021553383612375719498472212737560539314895278406213528776", "price": "0.05", "size": "0", "side": "BUY", "hash": "e6f2631fc6c4f1a821dffd99458c51c01d983866", "best_bid": "0.049", "best_ask": "0.114"}], "timestamp": "1769384081417", "event_type": "price_change"}}
{"_local_timestamp": "2026-01-25T23:34:41.550834+00:00", "data": {"market": "0x983c1c640da74bd05222b1ae535d9d80e67a7c37ba821e213ab681da63f7b52d", "price_changes": [{"asset_id": "111487994318578797618498789659864547400234714169664391253427670617626566154712", "price": "0.906", "size": "0", "side": "BUY", "hash": "9b3df62703f78fe4118ca520c0bfbb40b8f8f198", "best_bid": "0.907", "best_ask": "0.987"}, {"asset_id": "33334365343701835814605836236502189532077473322352990496796220640667787771374", "price": "0.094", "size": "0", "side": "SELL", "hash": "69eb34def164ffd9aaf2a86285a65c031a643831", "best_bid": "0.013", "best_ask": "0.093"}], "timestamp": "1769384081423", "event_type": "price_change"}}
{"_local_timestamp": "2026-01-25T23:35:01.175695+00:00", "data": {"market": "0xee6de29096f712879525fffe70ec19ed1069660c17a96770c990a48a4d6cafca", "price_changes": [{"asset_id": "91615446195150618766021553383612375719498472212737560539314895278406213528776", "price": "0.026", "size": "50", "side": "BUY", "hash": "fd76e114c9e8e2a367eabb3fbed5668602029bd8", "best_bid": "0.049", "best_ask": "0.114"}, {"asset_id": "79250352452729964397183638491507951490462474124621653995906925320890963543836", "price": "0.974", "size": "50", "side": "SELL", "hash": "27f2fef3bfd35a9671507f0219cd9bfd1145db39", "best_bid": "0.886", "best_ask": "0.951"}], "timestamp": "1769384101066", "event_type": "price_change"}}
{"_local_timestamp": "2026-01-25T23:35:01.326379+00:00", "data": {"market": "0xee6de29096f712879525fffe70ec19ed1069660c17a96770c990a48a4d6cafca", "price_changes": [{"asset_id": "91615446195150618766021553383612375719498472212737560539314895278406213528776", "price": "0.027", "size": "5.81", "side": "BUY", "hash": "631c1368174f5aebb435872e5b266f0104eb8ddd", "best_bid": "0.049", "best_ask": "0.114"}, {"asset_id": "79250352452729964397183638491507951490462474124621653995906925320890963543836", "price": "0.973", "size": "5.81", "side": "SELL", "hash": "60550885cf404653f82b3816e3df2e99c00ed8d3", "best_bid": "0.886", "best_ask": "0.951"}], "timestamp": "1769384101250", "event_type": "price_change"}}
{"_local_timestamp": "2026-01-25T23:35:01.963394+00:00", "data": {"market": "0x4c8a4ecc294553e865f9bed3cf2ba6d1cefe23515f6ece2b6b01f696d2845fe0", "price_changes": [{"asset_id": "51915547669523222925311577874361232586045773418874670768734077060997483885755", "price": "0.03", "size": "0", "side": "BUY", "hash": "968be1cb3b047aaf3a8a73d98777a201ee1738ce", "best_bid": "0.18", "best_ask": "0.81"}, {"asset_id": "93232945228609658077531889011480905670187160388516295356072507802163300422442", "price": "0.97", "size": "0", "side": "SELL", "hash": "f83c04b0b3d345d0506e29749adbcaf27f6e2936", "best_bid": "0.19", "best_ask": "0.82"}], "timestamp": "1769384101895", "event_type": "price_change"}}
{"_local_timestamp": "2026-01-25T23:35:02.144480+00:00", "data": {"market": "0x4c8a4ecc294553e865f9bed3cf2ba6d1cefe23515f6ece2b6b01f696d2845fe0", "price_changes": [{"asset_id": "51915547669523222925311577874361232586045773418874670768734077060997483885755", "price": "0.02", "size": "23.53", "side": "BUY", "hash": "26b3f7147cc1a50f5e53c5da7b226d574bf4c584", "best_bid": "0.18", "best_ask": "0.81"}, {"asset_id": "93232945228609658077531889011480905670187160388516295356072507802163300422442", "price": "0.98", "size": "23.53", "side": "SELL", "hash": "56fbe8c3a05d5adaa1008707f6b93f853b056255", "best_bid": "0.19", "best_ask": "0.82"}], "timestamp": "1769384102077", "event_type": "price_change"}}
{"_local_timestamp": "2026-01-25T23:35:08.150151+00:00", "data": {"market": "0xaef8cc72583c46308a4f61b93cce219831d4861af26c0ace983300183b5d6f77", "price_changes": [{"asset_id": "23410860411880980077660432875622355119426529164122573169196610980318417032021", "price": "0.07", "size": "21", "side": "BUY", "hash": "f52e84e40e56c4455972b40c93b3df514a34c12e", "best_bid": "0.07", "best_ask": "0.17"}, {"asset_id": "97904810933420938915915184802871896723926497912237502816269649051469198352574", "price": "0.93", "size": "21", "side": "SELL", "hash": "709dc6643f8a1d8d18b70cee9008f2e6a4ead67a", "best_bid": "0.83", "best_ask": "0.93"}], "timestamp": "1769384108059", "event_type": "price_change"}}
{"_local_timestamp": "2026-01-25T23:35:08.176316+00:00", "data": {"market": "0xaef8cc72583c46308a4f61b93cce219831d4861af26c0ace983300183b5d6f77", "price_changes": [{"asset_id": "97904810933420938915915184802871896723926497912237502816269649051469198352574", "price": "0.83", "size": "22", "side": "BUY", "hash": "f97f7c1f2556b3b1919036b4d4748e63297bc0da", "best_bid": "0.83", "best_ask": "0.93"}, {"asset_id": "23410860411880980077660432875622355119426529164122573169196610980318417032021", "price": "0.17", "size": "22", "side": "SELL", "hash": "b76bf9c466945f1b891cf13ec317f81d03d033a9", "best_bid": "0.07", "best_ask": "0.17"}], "timestamp": "1769384108110", "event_type": "price_change"}}
{"_local_timestamp": "2026-01-25T23:35:08.463097+00:00", "data": {"market": "0x4c8a4ecc294553e865f9bed3cf2ba6d1cefe23515f6ece2b6b01f696d2845fe0", "price_changes": [{"asset_id": "93232945228609658077531889011480905670187160388516295356072507802163300422442", "price": "0.16", "size": "20", "side": "BUY", "hash": "df4481088219ae8ff91ea66d166c885de2242e3d", "best_bid": "0.19", "best_ask": "0.82"}, {"asset_id": "51915547669523222925311577874361232586045773418874670768734077060997483885755", "price": "0.84", "size": "20", "side": "SELL", "hash": "4de86d7b4029796a5abb12593b2f64c5c6db0db5", "best_bid": "0.18", "best_ask": "0.81"}], "timestamp": "1769384108374", "event_type": "price_change"}}
{"_local_timestamp": "2026-01-25T23:35:08.687750+00:00", "data": {"market": "0x4c8a4ecc294553e865f9bed3cf2ba6d1cefe23515f6ece2b6b01f696d2845fe0", "price_changes": [{"asset_id": "51915547669523222925311577874361232586045773418874670768734077060997483885755", "price": "0.74", "size": "20", "side": "BUY", "hash": "a7d41bb11abac95a84d693978b089d63e7b67d3d", "best_bid": "0.74", "best_ask": "0.81"}, {"asset_id": "93232945228609658077531889011480905670187160388516295356072507802163300422442", "price": "0.26", "size": "20", "side": "SELL", "hash": "aa347980620237b5b443512b84104b572fc82ef7", "best_bid": "0.19", "best_ask": "0.26"}], "timestamp": "1769384108615", "event_type": "price_change"}}
{"_local_timestamp": "2026-01-25T23:35:08.733299+00:00", "data": {"market": "0x3254c0fde930bd86e5cc6cf9eb9dc16ca364ab4819ed5e1802a53b0fa2f36772", "price_changes": [{"asset_id": "28260696393853739649130713837590031037312393528301041179223890674988415162070", "price": "0.09", "size": "376.11", "side": "BUY", "hash": "5b1a2700d2e5f5bbc1598653162a63dc8e764236", "best_bid": "0.09", "best_ask": "0.19"}, {"asset_id": "1243252154129193015238236663840507016761347339076756815039433906036180619298", "price": "0.91", "size": "376.11", "side": "SELL", "hash": "af8da46ad98a31259cd0d7e5ad54a6cba7f7bafa", "best_bid": "0.81", "best_ask": "0.91"}], "timestamp": "1769384108670", "event_type": "price_change"}}
{"_local_timestamp": "2026-01-25T23:35:08.792737+00:00", "data": {"market": "0x3254c0fde930bd86e5cc6cf9eb9dc16ca364ab4819ed5e1802a53b0fa2f36772", "price_changes": [{"asset_id": "1243252154129193015238236663840507016761347339076756815039433906036180619298", "price": "0.81", "size": "0", "side": "BUY", "hash": "aa737b30e1e95a54c46c5eb120ed713110c05c70", "best_bid": "0.8", "best_ask": "0.91"}, {"asset_id": "28260696393853739649130713837590031037312393528301041179223890674988415162070", "price": "0.19", "size": "0", "side": "SELL", "hash": "f6999fbf4f4eb6efeb27b8b7019edd913fceaa32", "best_bid": "0.09", "best_ask": "0.2"}], "timestamp": "1769384108722", "event_type": "price_change"}}
{"_local_timestamp": "2026-01-25T23:35:08.825557+00:00", "data": {"market": "0x3254c0fde930bd86e5cc6cf9eb9dc16ca364ab4819ed5e1802a53b0fa2f36772", "price_changes": [{"asset_id": "28260696393853739649130713837590031037312393528301041179223890674988415162070", "price": "0.09", "size": "0", "side": "BUY", "hash": "e655c04f36b74148b3363c7e3f164535d534c9b6", "best_bid": "0.06", "best_ask": "0.2"}, {"asset_id": "1243252154129193015238236663840507016761347339076756815039433906036180619298", "price": "0.91", "size": "0", "side": "SELL", "hash": "9ba56e602480a4b498aac86cdaac50d4e39d60d8", "best_bid": "0.8", "best_ask": "0.94"}], "timestamp": "1769384108759", "event_type": "price_change"}}
{"_local_timestamp": "2026-01-25T23:35:08.918400+00:00", "data": {"market": "0xee6de29096f712879525fffe70ec19ed1069660c17a96770c990a48a4d6cafca", "price_changes": [{"asset_id": "79250352452729964397183638491507951490462474124621653995906925320890963543836", "price": "0.95", "size": "15.89", "side": "SELL", "hash": "8441919b198c78fda228fe297a216202bd58b47d", "best_bid": "0.886", "best_ask": "0.95"}, {"asset_id": "91615446195150618766021553383612375719498472212737560539314895278406213528776", "price": "0.05", "size": "15.89", "side": "BUY", "hash": "d712a79e7b9eca693c583c126ad9313eaa58da8d", "best_bid": "0.05", "best_ask": "0.114"}], "timestamp": "1769384108845", "event_type": "price_change"}}
{"_local_timestamp": "2026-01-25T23:35:08.922061+00:00", "data": {"market": "0x4c8a4ecc294553e865f9bed3cf2ba6d1cefe23515f6ece2b6b01f696d2845fe0", "price_changes": [{"asset_id": "93232945228609658077531889011480905670187160388516295356072507802163300422442", "price": "0.19", "size": "5.05", "side": "BUY", "hash": "ea503f35d1584faa61642d915e3860ced41fd27c", "best_bid": "0.19", "best_ask": "0.26"}, {"asset_id": "51915547669523222925311577874361232586045773418874670768734077060997483885755", "price": "0.81", "size": "5.05", "side": "SELL", "hash": "a6af8dae321564f1c77c44a8d7929afa4308461b", "best_bid": "0.74", "best_ask": "0.81"}], "timestamp": "1769384108857", "event_type": "price_change"}}
{"_local_timestamp": "2026-01-25T23:35:09.484422+00:00", "data": {"market": "0x3254c0fde930bd86e5cc6cf9eb9dc16ca364ab4819ed5e1802a53b0fa2f36772", "price_changes": [{"asset_id": "28260696393853739649130713837590031037312393528301041179223890674988415162070", "price": "0.06", "size": "37.24", "side": "BUY", "hash": "7b789ace6bc509380fcf10b06a88df9c60ea344c", "best_bid": "0.06", "best_ask": "0.2"}, {"asset_id": "1243252154129193015238236663840507016761347339076756815039433906036180619298", "price": "0.94", "size": "37.24", "side": "SELL", "hash": "427ad09de951fe160febfc9349e3e4ac9f79a6c6", "best_bid": "0.8", "best_ask": "0.94"}], "timestamp": "1769384109422", "event_type": "price_change"}}
{"_local_timestamp": "2026-01-25T23:35:13.395529+00:00", "data": {"market": "0xee6de29096f712879525fffe70ec19ed1069660c17a96770c990a48a4d6cafca", "price_changes": [{"asset_id": "79250352452729964397183638491507951490462474124621653995906925320890963543836", "price": "0.887", "size": "45", "side": "BUY", "hash": "16cad441323684739bf41f809aac32751229dbe1", "best_bid": "0.887", "best_ask": "0.95"}, {"asset_id": "91615446195150618766021553383612375719498472212737560539314895278406213528776", "price": "0.113", "size": "45", "side": "SELL", "hash": "2a3177079617b3effb711dcf2f305d973656d621", "best_bid": "0.05", "best_ask": "0.113"}], "timestamp": "1769384113239", "event_type": "price_change"}}
{"_local_timestamp": "2026-01-25T23:35:30.939218+00:00", "data": {"market": "0xee6de29096f712879525fffe70ec19ed1069660c17a96770c990a48a4d6cafca", "price_changes": [{"asset_id": "91615446195150618766021553383612375719498472212737560539314895278406213528776", "price": "0.047", "size": "10", "side": "BUY", "hash": "b1d89f2dda6e953d9efa8187a56c4da87bb56ed3", "best_bid": "0.05", "best_ask": "0.113"}, {"asset_id": "79250352452729964397183638491507951490462474124621653995906925320890963543836", "price": "0.953", "size": "10", "side": "SELL", "hash": "085b3a5b9747cabc2031aeb54ea8733da19facac", "best_bid": "0.887", "best_ask": "0.95"}], "timestamp": "1769384130864", "event_type": "price_change"}}
{"_local_timestamp": "2026-01-25T23:35:30.940018+00:00", "data": {"market": "0xee6de29096f712879525fffe70ec19ed1069660c17a96770c990a48a4d6cafca", "price_changes": [{"asset_id": "79250352452729964397183638491507951490462474124621653995906925320890963543836", "price": "0.885", "size": "0", "side": "BUY", "hash": "8e05b975b1c23f1968001e11dc741de3231e3960", "best_bid": "0.887", "best_ask": "0.95"}, {"asset_id": "91615446195150618766021553383612375719498472212737560539314895278406213528776", "price": "0.115", "size": "0", "side": "SELL", "hash": "b9cf2e9e942ab3496e4ba60087b1e1245c7f2602", "best_bid": "0.05", "best_ask": "0.113"}], "timestamp": "1769384130864", "event_type": "price_change"}}
{"_local_timestamp": "2026-01-25T23:35:31.356033+00:00", "data": {"market": "0x83547249e61eaf92162353753801453d313daaed73b401b9edcc669251f578c0", "price_changes": [{"asset_id": "49285515506903050077566386836604355110855655545900685629915315206051894927030", "price": "0.218", "size": "20", "side": "BUY", "hash": "e5781aaf1eb6c74a12aed22b29adf2b869c27881", "best_bid": "0.219", "best_ask": "0.259"}, {"asset_id": "64710685063708113016458069418988206406890895555826348081008842775253721088516", "price": "0.782", "size": "20", "side": "SELL", "hash": "59937e7ba5525a1753e254963c9b52e24d7aaee7", "best_bid": "0.741", "best_ask": "0.781"}], "timestamp": "1769384131245", "event_type": "price_change"}}
{"_local_timestamp": "2026-01-25T23:35:32.810393+00:00", "data": {"market": "0x83547249e61eaf92162353753801453d313daaed73b401b9edcc669251f578c0", "price_changes": [{"asset_id": "49285515506903050077566386836604355110855655545900685629915315206051894927030", "price": "0.218", "size": "0", "side": "BUY", "hash": "684fade253af8f49dcf8e42b06bb07e72a5aac48", "best_bid": "0.219", "best_ask": "0.259"}, {"asset_id": "64710685063708113016458069418988206406890895555826348081008842775253721088516", "price": "0.782", "size": "0", "side": "SELL", "hash": "dff0b00daf063e85491eba1533275e45fa2fe0f0", "best_bid": "0.741", "best_ask": "0.781"}], "timestamp": "1769384132745", "event_type": "price_change"}}
{"_local_timestamp": "2026-01-25T23:35:33.892303+00:00", "data": {"market": "0x983c1c640da74bd05222b1ae535d9d80e67a7c37ba821e213ab681da63f7b52d", "price_changes": [{"asset_id": "111487994318578797618498789659864547400234714169664391253427670617626566154712", "price": "0.066", "size": "0", "side": "BUY", "hash": "5e0fe0548f141b0be7fdecd3f8dc755a5824e951", "best_bid": "0.907", "best_ask": "0.987"}, {"asset_id": "33334365343701835814605836236502189532077473322352990496796220640667787771374", "price": "0.934", "size": "0", "side": "SELL", "hash": "5ce3e63be377f8e685ba8e6df47cf47f6ccb4e58", "best_bid": "0.013", "best_ask": "0.093"}], "timestamp": "1769384133812", "event_type": "price_change"}}
{"_local_timestamp": "2026-01-25T23:35:33.944000+00:00", "data": {"market": "0x983c1c640da74bd05222b1ae535d9d80e67a7c37ba821e213ab681da63f7b52d", "price_changes": [{"asset_id": "111487994318578797618498789659864547400234714169664391253427670617626566154712", "price": "0.062", "size": "32", "side": "BUY", "hash": "422c86f0542cab6f7136c246cd4163b2b2f2a129", "best_bid": "0.907", "best_ask": "0.987"}, {"asset_id": "33334365343701835814605836236502189532077473322352990496796220640667787771374", "price": "0.938", "size": "32", "side": "SELL", "hash": "af8d1eb25f193248fad6c3ffae5448f776492352", "best_bid": "0.013", "best_ask": "0.093"}], "timestamp": "1769384133859", "event_type": "price_change"}}
{"_local_timestamp": "2026-01-25T23:35:37.452135+00:00", "data": {"market": "0xc6eaad93752e4f8b58b9faf7e63ec9ba1c548a49e6fe6b21f605ed9d71f4c57a", "price_changes": [{"asset_id": "25539386078797395599636818043909403100500096091846839226569678716060642614342", "price": "0.282", "size": "10", "side": "SELL", "hash": "57257b43823012af8ed9d7f155de0907448edb63", "best_bid": "0.012", "best_ask": "0.179"}, {"asset_id": "106764258059853211019809099342916860924409096361081427559669257851522126201276", "price": "0.718", "size": "10", "side": "BUY", "hash": "b866cea7be35f8082f59c6ad7a92f12fd8954791", "best_bid": "0.821", "best_ask": "0.988"}], "timestamp": "1769384137384", "event_type": "price_change"}}
{"_local_timestamp": "2026-01-25T23:35:37.692411+00:00", "data": {"market": "0xc6eaad93752e4f8b58b9faf7e63ec9ba1c548a49e6fe6b21f605ed9d71f4c57a", "price_changes": [{"asset_id": "25539386078797395599636818043909403100500096091846839226569678716060642614342", "price": "0.281", "size": "11.25", "side": "SELL", "hash": "2fd45155bce45878eaeb47afeb167736a6a36d8f", "best_bid": "0.012", "best_ask": "0.179"}, {"asset_id": "106764258059853211019809099342916860924409096361081427559669257851522126201276", "price": "0.719", "size": "11.25", "side": "BUY", "hash": "0b26e1838c3d5b998cd0bcdfa0299514073bc7ec", "best_bid": "0.821", "best_ask": "0.988"}], "timestamp": "1769384137625", "event_type": "price_change"}}
{"_local_timestamp": "2026-01-25T23:35:38.386408+00:00", "data": {"market": "0x83547249e61eaf92162353753801453d313daaed73b401b9edcc669251f578c0", "price_changes": [{"asset_id": "64710685063708113016458069418988206406890895555826348081008842775253721088516", "price": "0.781", "size": "0", "side": "SELL", "hash": "733d81888bd3a7591a0d08e44fac258e4e084451", "best_bid": "0.741", "best_ask": "0.796"}, {"asset_id": "49285515506903050077566386836604355110855655545900685629915315206051894927030", "price": "0.219", "size": "0", "side": "BUY", "hash": "c09b4b023e4ad1b9e2140a102cacfb6539e75d75", "best_bid": "0.204", "best_ask": "0.259"}], "timestamp": "1769384138306", "event_type": "price_change"}}
{"_local_timestamp": "2026-01-25T23:35:38.817002+00:00", "data": {"market": "0x83547249e61eaf92162353753801453d313daaed73b401b9edcc669251f578c0", "price_changes": [{"asset_id": "64710685063708113016458069418988206406890895555826348081008842775253721088516", "price": "0.795", "size": "106.09", "side": "SELL", "hash": "23d23d80e15415ffb499401a1a8d483bb96d4fa9", "best_bid": "0.741", "best_ask": "0.795"}, {"asset_id": "49285515506903050077566386836604355110855655545900685629915315206051894927030", "price": "0.205", "size": "106.09", "side": "BUY", "hash": "e4af105e671e86672e1473aa1d197aae82ebcd04", "best_bid": "0.205", "best_ask": "0.259"}], "timestamp": "1769384138695", "event_type": "price_change"}}
{"_local_timestamp": "2026-01-25T23:35:43.656626+00:00", "data": {"market": "0xee6de29096f712879525fffe70ec19ed1069660c17a96770c990a48a4d6cafca", "price_changes": [{"asset_id": "91615446195150618766021553383612375719498472212737560539314895278406213528776", "price": "0.047", "size": "0", "side": "BUY", "hash": "1367e5f40173b639fa8e5a3cb0cf2dc5d32c2400", "best_bid": "0.05", "best_ask": "0.113"}, {"asset_id": "79250352452729964397183638491507951490462474124621653995906925320890963543836", "price": "0.953", "size": "0", "side": "SELL", "hash": "26e8467aef2de1d582bd2eeb66a5aa4352a3e45a", "best_bid": "0.887", "best_ask": "0.95"}], "timestamp": "1769384143592", "event_type": "price_change"}}
{"_local_timestamp": "2026-01-25T23:35:43.746696+00:00", "data": {"market": "0xee6de29096f712879525fffe70ec19ed1069660c17a96770c990a48a4d6cafca", "price_changes": [{"asset_id": "91615446195150618766021553383612375719498472212737560539314895278406213528776", "price": "0.035", "size": "10", "side": "BUY", "hash": "8d018da7df616aebf5f888cdadb36561864c1914", "best_bid": "0.05", "best_ask": "0.113"}, {"asset_id": "79250352452729964397183638491507951490462474124621653995906925320890963543836", "price": "0.965", "size": "10", "side": "SELL", "hash": "61f1e0748e356981c83170f0cb111192d1bb6b1e", "best_bid": "0.887", "best_ask": "0.95"}], "timestamp": "1769384143684", "event_type": "price_change"}}
{"_local_timestamp": "2026-01-25T23:35:43.843207+00:00", "data": {"market": "0xee6de29096f712879525fffe70ec19ed1069660c17a96770c990a48a4d6cafca", "price_changes": [{"asset_id": "79250352452729964397183638491507951490462474124621653995906925320890963543836", "price": "0.116", "size": "0", "side": "BUY", "hash": "3a7619ec654907d2b019c8cac9aebcac4ba0cf4d", "best_bid": "0.887", "best_ask": "0.95"}, {"asset_id": "91615446195150618766021553383612375719498472212737560539314895278406213528776", "price": "0.884", "size": "0", "side": "SELL", "hash": "65049e2ecbb354d1b8ba2ed5d7cd884e6d3597dd", "best_bid": "0.05", "best_ask": "0.113"}], "timestamp": "1769384143781", "event_type": "price_change"}}
{"_local_timestamp": "2026-01-25T23:35:43.947536+00:00", "data": {"market": "0xee6de29096f712879525fffe70ec19ed1069660c17a96770c990a48a4d6cafca", "price_changes": [{"asset_id": "79250352452729964397183638491507951490462474124621653995906925320890963543836", "price": "0.115", "size": "27", "side": "BUY", "hash": "388bad45042796ef592f6726b72e8a596b83ec31", "best_bid": "0.887", "best_ask": "0.95"}, {"asset_id": "91615446195150618766021553383612375719498472212737560539314895278406213528776", "price": "0.885", "size": "27", "side": "SELL", "hash": "e2d5afc63106c57adcd1ba02b7006e1b4692d609", "best_bid": "0.05", "best_ask": "0.113"}], "timestamp": "1769384143878", "event_type": "price_change"}}
{"_local_timestamp": "2026-01-25T23:35:52.324942+00:00", "data": {"market": "0x3254c0fde930bd86e5cc6cf9eb9dc16ca364ab4819ed5e1802a53b0fa2f36772", "price_changes": [{"asset_id": "28260696393853739649130713837590031037312393528301041179223890674988415162070", "price": "0.05", "size": "191", "side": "BUY", "hash": "681da6c9761e6ac79cacd3ba78aaa3b9555bd2ec", "best_bid": "0.06", "best_ask": "0.2"}, {"asset_id": "1243252154129193015238236663840507016761347339076756815039433906036180619298", "price": "0.95", "size": "191", "side": "SELL", "hash": "8ea76c556f1522f80641601ab1a16ad868981720", "best_bid": "0.8", "best_ask": "0.94"}], "timestamp": "1769384152251", "event_type": "price_change"}}
{"_local_timestamp": "2026-01-25T23:35:52.442852+00:00", "data": {"market": "0x3254c0fde930bd86e5cc6cf9eb9dc16ca364ab4819ed5e1802a53b0fa2f36772", "price_changes": [{"asset_id": "28260696393853739649130713837590031037312393528301041179223890674988415162070", "price": "0.03", "size": "443.33", "side": "BUY", "hash": "d6682fc05c9019529a8f9cbc69e7132b877dc952", "best_bid": "0.06", "best_ask": "0.2"}, {"asset_id": "1243252154129193015238236663840507016761347339076756815039433906036180619298", "price": "0.97", "size": "443.33", "side": "SELL", "hash": "67e1d7353829babbad8f6315f58aeda8dacfc7e7", "best_bid": "0.8", "best_ask": "0.94"}], "timestamp": "1769384152370", "event_type": "price_change"}}
{"_local_timestamp": "2026-01-25T23:35:52.525369+00:00", "data": {"market": "0x3254c0fde930bd86e5cc6cf9eb9dc16ca364ab4819ed5e1802a53b0fa2f36772", "price_changes": [{"asset_id": "1243252154129193015238236663840507016761347339076756815039433906036180619298", "price": "0.29", "size": "0", "side": "BUY", "hash": "b235f664ec8cdf74f575aad4f18fe6c39f0c76ba", "best_bid": "0.8", "best_ask": "0.94"}, {"asset_id": "28260696393853739649130713837590031037312393528301041179223890674988415162070", "price": "0.71", "size": "0", "side": "SELL", "hash": "dd8486f55232b9a252e9ae5ae32bc148a49c7a2e", "best_bid": "0.06", "best_ask": "0.2"}], "timestamp": "1769384152456", "event_type": "price_change"}}
{"_local_timestamp": "2026-01-25T23:35:52.615111+00:00", "data": {"market": "0x3254c0fde930bd86e5cc6cf9eb9dc16ca364ab4819ed5e1802a53b0fa2f36772", "price_changes": [{"asset_id": "1243252154129193015238236663840507016761347339076756815039433906036180619298", "price": "0.28", "size": "17", "side": "BUY", "hash": "1b53be465fa8ca608d42864225a007abe768bda7", "best_bid": "0.8", "best_ask": "0.94"}, {"asset_id": "28260696393853739649130713837590031037312393528301041179223890674988415162070", "price": "0.72", "size": "17", "side": "SELL", "hash": "4a2ef322e5281858740160822fe719d837bd2c4b", "best_bid": "0.06", "best_ask": "0.2"}], "timestamp": "1769384152544", "event_type": "price_change"}}
{"_local_timestamp": "2026-01-25T23:36:04.771259+00:00", "data": {"market": "0xc6eaad93752e4f8b58b9faf7e63ec9ba1c548a49e6fe6b21f605ed9d71f4c57a", "price_changes": [{"asset_id": "106764258059853211019809099342916860924409096361081427559669257851522126201276", "price": "0.718", "size": "0", "side": "BUY", "hash": "bf8cfe440dbeb5b104767d547a2ac6eb23ba4a9b", "best_bid": "0.821", "best_ask": "0.988"}, {"asset_id": "25539386078797395599636818043909403100500096091846839226569678716060642614342", "price": "0.282", "size": "0", "side": "SELL", "hash": "34546cae2cd1f148f53ef12b886d601bbf0c8af4", "best_bid": "0.012", "best_ask": "0.179"}], "timestamp": "1769384164690", "event_type": "price_change"}}
{"_local_timestamp": "2026-01-25T23:36:04.849021+00:00", "data": {"market": "0xc6eaad93752e4f8b58b9faf7e63ec9ba1c548a49e6fe6b21f605ed9d71f4c57a", "price_changes": [{"asset_id": "106764258059853211019809099342916860924409096361081427559669257851522126201276", "price": "0.719", "size": "21.25", "side": "BUY", "hash": "047b29a6e966edb7cf8d77abdbee963de7729663", "best_bid": "0.821", "best_ask": "0.988"}, {"asset_id": "25539386078797395599636818043909403100500096091846839226569678716060642614342", "price": "0.281", "size": "21.25", "side": "SELL", "hash": "b1736c19ffd8192278045fcaeb5e0e8543705546", "best_bid": "0.012", "best_ask": "0.179"}], "timestamp": "1769384164782", "event_type": "price_change"}}
{"_local_timestamp": "2026-01-25T23:36:20.295347+00:00", "data": {"market": "0x4c8a4ecc294553e865f9bed3cf2ba6d1cefe23515f6ece2b6b01f696d2845fe0", "price_changes": [{"asset_id": "93232945228609658077531889011480905670187160388516295356072507802163300422442", "price": "0.14", "size": "505", "side": "BUY", "hash": "a4007d25cf6aa11658b7ae744769c82173e065aa", "best_bid": "0.19", "best_ask": "0.26"}, {"asset_id": "51915547669523222925311577874361232586045773418874670768734077060997483885755", "price": "0.86", "size": "505", "side": "SELL", "hash": "bfaa8a65d8ac3e4a3ce9f101d8e050eabb2aab55", "best_bid": "0.74", "best_ask": "0.81"}], "timestamp": "1769384180216", "event_type": "price_change"}}
{"_local_timestamp": "2026-01-25T23:36:20.423413+00:00", "data": {"market": "0x4c8a4ecc294553e865f9bed3cf2ba6d1cefe23515f6ece2b6b01f696d2845fe0", "price_changes": [{"asset_id": "93232945228609658077531889011480905670187160388516295356072507802163300422442", "price": "0.15", "size": "260", "side": "BUY", "hash": "dee5c98778128e9fe3560f4615a550d3313cad79", "best_bid": "0.19", "best_ask": "0.26"}, {"asset_id": "51915547669523222925311577874361232586045773418874670768734077060997483885755", "price": "0.85", "size": "260", "side": "SELL", "hash": "379c7dca1cd65aa7cd227574b246d918b810bebd", "best_bid": "0.74", "best_ask": "0.81"}], "timestamp": "1769384180350", "event_type": "price_change"}}
{"_local_timestamp": "2026-01-25T23:36:20.588584+00:00", "data": {"market": "0x4c8a4ecc294553e865f9bed3cf2ba6d1cefe23515f6ece2b6b01f696d2845fe0", "price_changes": [{"asset_id": "51915547669523222925311577874361232586045773418874670768734077060997483885755", "price": "0.1", "size": "0", "side": "BUY", "hash": "44c7899806295a5dd1f5cf84e39d8f8c5f7327c9", "best_bid": "0.74", "best_ask": "0.81"}, {"asset_id": "93232945228609658077531889011480905670187160388516295356072507802163300422442", "price": "0.9", "size": "0", "side": "SELL", "hash": "0e8e74357b878d46684cff885594e7213425092d", "best_bid": "0.19", "best_ask": "0.26"}], "timestamp": "1769384180519", "event_type": "price_change"}}
{"_local_timestamp": "2026-01-25T23:36:20.674073+00:00", "data": {"market": "0x4c8a4ecc294553e865f9bed3cf2ba6d1cefe23515f6ece2b6b01f696d2845fe0", "price_changes": [{"asset_id": "51915547669523222925311577874361232586045773418874670768734077060997483885755", "price": "0.17", "size": "74.7", "side": "BUY", "hash": "46bad0f22fe8950933351755924cf7da1c913c95", "best_bid": "0.74", "best_ask": "0.81"}, {"asset_id": "93232945228609658077531889011480905670187160388516295356072507802163300422442", "price": "0.83", "size": "74.7", "side": "SELL", "hash": "3cceaf0ffc5347742e604c7b98b964f0de412b9f", "best_bid": "0.19", "best_ask": "0.26"}], "timestamp": "1769384180607", "event_type": "price_change"}}
{"_local_timestamp": "2026-01-25T23:36:34.033530+00:00", "data": {"market": "0x83547249e61eaf92162353753801453d313daaed73b401b9edcc669251f578c0", "price_changes": [{"asset_id": "49285515506903050077566386836604355110855655545900685629915315206051894927030", "price": "0.206", "size": "43", "side": "BUY", "hash": "33a048b625664f90affbad5521320b857e817fbe", "best_bid": "0.206", "best_ask": "0.259"}, {"asset_id": "64710685063708113016458069418988206406890895555826348081008842775253721088516", "price": "0.794", "size": "43", "side": "SELL", "hash": "97497cca001938cff4daadd4f046c3056c20224d", "best_bid": "0.741", "best_ask": "0.794"}], "timestamp": "1769384193961", "event_type": "price_change"}}
{"_local_timestamp": "2026-01-25T23:36:37.226134+00:00", "data": {"market": "0x83547249e61eaf92162353753801453d313daaed73b401b9edcc669251f578c0", "price_changes": [{"asset_id": "49285515506903050077566386836604355110855655545900685629915315206051894927030", "price": "0.205", "size": "126.09", "side": "BUY", "hash": "8368394c279f7c83c312fad4d2f10246ff66682f", "best_bid": "0.206", "best_ask": "0.259"}, {"asset_id": "64710685063708113016458069418988206406890895555826348081008842775253721088516", "price": "0.795", "size": "126.09", "side": "SELL", "hash": "3383ee8c7e24fcf48e87baabb91df266351a4e60", "best_bid": "0.741", "best_ask": "0.794"}], "timestamp": "1769384197162", "event_type": "price_change"}}
{"_local_timestamp": "2026-01-25T23:36:38.658492+00:00", "data": {"market": "0x83547249e61eaf92162353753801453d313daaed73b401b9edcc669251f578c0", "price_changes": [{"asset_id": "64710685063708113016458069418988206406890895555826348081008842775253721088516", "price": "0.795", "size": "20", "side": "SELL", "hash": "c987fdf6a3c86333dca69bd77064df22dec563dc", "best_bid": "0.741", "best_ask": "0.794"}, {"asset_id": "49285515506903050077566386836604355110855655545900685629915315206051894927030", "price": "0.205", "size": "20", "side": "BUY", "hash": "0b90edc31f343a0aa1e017753682ab8f0fb7c156", "best_bid": "0.206", "best_ask": "0.259"}], "timestamp": "1769384198590", "event_type": "price_change"}}
{"_local_timestamp": "2026-01-25T23:36:39.073723+00:00", "data": {"market": "0x83547249e61eaf92162353753801453d313daaed73b401b9edcc669251f578c0", "price_changes": [{"asset_id": "64710685063708113016458069418988206406890895555826348081008842775253721088516", "price": "0.793", "size": "106.09", "side": "SELL", "hash": "123ca539f66cc6eefb7324890742c2a1e47b600d", "best_bid": "0.741", "best_ask": "0.793"}, {"asset_id": "49285515506903050077566386836604355110855655545900685629915315206051894927030", "price": "0.207", "size": "106.09", "side": "BUY", "hash": "f4aa7d6f1ae2373e487f44fbee75b2940f9e4250", "best_bid": "0.207", "best_ask": "0.259"}], "timestamp": "1769384198968", "event_type": "price_change"}}
{"_local_timestamp": "2026-01-25T23:36:40.216695+00:00", "data": {"market": "0x83547249e61eaf92162353753801453d313daaed73b401b9edcc669251f578c0", "price_changes": [{"asset_id": "49285515506903050077566386836604355110855655545900685629915315206051894927030", "price": "0.205", "size": "0", "side": "BUY", "hash": "cb0f5b1b08781fedd8666417e09397fb9b09d183", "best_bid": "0.207", "best_ask": "0.259"}, {"asset_id": "64710685063708113016458069418988206406890895555826348081008842775253721088516", "price": "0.795", "size": "0", "side": "SELL", "hash": "a29e72a6b149b7748c94e000f00c1a3666d49330", "best_bid": "0.741", "best_ask": "0.793"}], "timestamp": "1769384200144", "event_type": "price_change"}}
{"_local_timestamp": "2026-01-25T23:36:40.442509+00:00", "data": {"market": "0x83547249e61eaf92162353753801453d313daaed73b401b9edcc669251f578c0", "price_changes": [{"asset_id": "49285515506903050077566386836604355110855655545900685629915315206051894927030", "price": "0.206", "size": "63", "side": "BUY", "hash": "3ca1df985e592ebb77c3304991d8a0e6376db838", "best_bid": "0.207", "best_ask": "0.259"}, {"asset_id": "64710685063708113016458069418988206406890895555826348081008842775253721088516", "price": "0.794", "size": "63", "side": "SELL", "hash": "ed5fadcb56977bedb7b6971bc73b50d81dc3bfbc", "best_bid": "0.741", "best_ask": "0.793"}], "timestamp": "1769384200380", "event_type": "price_change"}}
{"_local_timestamp": "2026-01-25T23:36:41.346102+00:00", "data": {"market": "0x83547249e61eaf92162353753801453d313daaed73b401b9edcc669251f578c0", "price_changes": [{"asset_id": "49285515506903050077566386836604355110855655545900685629915315206051894927030", "price": "0.004", "size": "0", "side": "BUY", "hash": "e8684a52f7ff63356b6ba3a8539be2d0d31731e7", "best_bid": "0.207", "best_ask": "0.259"}, {"asset_id": "64710685063708113016458069418988206406890895555826348081008842775253721088516", "price": "0.996", "size": "0", "side": "SELL", "hash": "ec71a58d13cbe9edff3e95896a1874568733d045", "best_bid": "0.741", "best_ask": "0.793"}], "timestamp": "1769384201266", "event_type": "price_change"}}
{"_local_timestamp": "2026-01-25T23:36:49.888132+00:00", "data": {"market": "0xaef8cc72583c46308a4f61b93cce219831d4861af26c0ace983300183b5d6f77", "price_changes": [{"asset_id": "97904810933420938915915184802871896723926497912237502816269649051469198352574", "price": "0.01", "size": "55.28", "side": "BUY", "hash": "d19046dd1367c8b150ffd341181222930cfda2d5", "best_bid": "0.83", "best_ask": "0.93"}, {"asset_id": "23410860411880980077660432875622355119426529164122573169196610980318417032021", "price": "0.99", "size": "55.28", "side": "SELL", "hash": "5d924abddbdfc61b276f7f7d4c902b704319e4aa", "best_bid": "0.07", "best_ask": "0.17"}], "timestamp": "1769384209822", "event_type": "price_change"}}
{"_local_timestamp": "2026-01-25T23:36:49.888653+00:00", "data": {"market": "0xaef8cc72583c46308a4f61b93cce219831d4861af26c0ace983300183b5d6f77", "price_changes": [{"asset_id": "97904810933420938915915184802871896723926497912237502816269649051469198352574", "price": "0.02", "size": "6.08", "side": "BUY", "hash": "d19046dd1367c8b150ffd341181222930cfda2d5", "best_bid": "0.83", "best_ask": "0.93"}, {"asset_id": "23410860411880980077660432875622355119426529164122573169196610980318417032021", "price": "0.98", "size": "6.08", "side": "SELL", "hash": "5d924abddbdfc61b276f7f7d4c902b704319e4aa", "best_bid": "0.07", "best_ask": "0.17"}], "timestamp": "1769384209822", "event_type": "price_change"}}
{"_local_timestamp": "2026-01-25T23:36:49.889071+00:00", "data": {"market": "0xaef8cc72583c46308a4f61b93cce219831d4861af26c0ace983300183b5d6f77", "price_changes": [{"asset_id": "97904810933420938915915184802871896723926497912237502816269649051469198352574", "price": "0.04", "size": "12", "side": "BUY", "hash": "d19046dd1367c8b150ffd341181222930cfda2d5", "best_bid": "0.83", "best_ask": "0.93"}, {"asset_id": "23410860411880980077660432875622355119426529164122573169196610980318417032021", "price": "0.96", "size": "12", "side": "SELL", "hash": "5d924abddbdfc61b276f7f7d4c902b704319e4aa", "best_bid": "0.07", "best_ask": "0.17"}], "timestamp": "1769384209822", "event_type": "price_change"}}
{"_local_timestamp": "2026-01-25T23:36:49.889586+00:00", "data": {"market": "0xaef8cc72583c46308a4f61b93cce219831d4861af26c0ace983300183b5d6f77", "price_changes": [{"asset_id": "97904810933420938915915184802871896723926497912237502816269649051469198352574", "price": "0.06", "size": "33", "side": "BUY", "hash": "d19046dd1367c8b150ffd341181222930cfda2d5", "best_bid": "0.83", "best_ask": "0.93"}, {"asset_id": "23410860411880980077660432875622355119426529164122573169196610980318417032021", "price": "0.94", "size": "33", "side": "SELL", "hash": "5d924abddbdfc61b276f7f7d4c902b704319e4aa", "best_bid": "0.07", "best_ask": "0.17"}], "timestamp": "1769384209822", "event_type": "price_change"}}
{"_local_timestamp": "2026-01-25T23:36:50.366510+00:00", "data": {"market": "0xaef8cc72583c46308a4f61b93cce219831d4861af26c0ace983300183b5d6f77", "price_changes": [{"asset_id": "97904810933420938915915184802871896723926497912237502816269649051469198352574", "price": "0.02", "size": "11.29", "side": "BUY", "hash": "ddc5827aa7a1c2db348dce2ff8c1d031f20a590a", "best_bid": "0.83", "best_ask": "0.93"}, {"asset_id": "23410860411880980077660432875622355119426529164122573169196610980318417032021", "price": "0.98", "size": "11.29", "side": "SELL", "hash": "6f9db155eb0eb4d588e717ad191be597e5d324ab", "best_bid": "0.07", "best_ask": "0.17"}], "timestamp": "1769384210301", "event_type": "price_change"}}
{"_local_timestamp": "2026-01-25T23:36:50.367619+00:00", "data": {"market": "0xaef8cc72583c46308a4f61b93cce219831d4861af26c0ace983300183b5d6f77", "price_changes": [{"asset_id": "97904810933420938915915184802871896723926497912237502816269649051469198352574", "price": "0.07", "size": "10.3", "side": "BUY", "hash": "0afad26c7b71d31690744ae7341318bc098af882", "best_bid": "0.83", "best_ask": "0.93"}, {"asset_id": "23410860411880980077660432875622355119426529164122573169196610980318417032021", "price": "0.93", "size": "10.3", "side": "SELL", "hash": "f42cc4993804e1ac6f7c4473f3ab22c8d7e02428", "best_bid": "0.07", "best_ask": "0.17"}], "timestamp": "1769384210302", "event_type": "price_change"}}
{"_local_timestamp": "2026-01-25T23:36:50.545324+00:00", "data": {"market": "0xaef8cc72583c46308a4f61b93cce219831d4861af26c0ace983300183b5d6f77", "price_changes": [{"asset_id": "23410860411880980077660432875622355119426529164122573169196610980318417032021", "price": "0.01", "size": "60", "side": "BUY", "hash": "bccdd401c4648ab40a0942ca2f0b021c9a8832da", "best_bid": "0.07", "best_ask": "0.17"}, {"asset_id": "97904810933420938915915184802871896723926497912237502816269649051469198352574", "price": "0.99", "size": "60", "side": "SELL", "hash": "ed40bff359412103400561fa47a190459e91bcaa", "best_bid": "0.83", "best_ask": "0.93"}], "timestamp": "1769384210460", "event_type": "price_change"}}
{"_local_timestamp": "2026-01-25T23:36:51.498595+00:00", "data": {"market": "0xaef8cc72583c46308a4f61b93cce219831d4861af26c0ace983300183b5d6f77", "price_changes": [{"asset_id": "23410860411880980077660432875622355119426529164122573169196610980318417032021", "price": "0.01", "size": "75.19", "side": "BUY", "hash": "f1c86ffe4d4b81f19221a740048b68ca6d11bfe5", "best_bid": "0.07", "best_ask": "0.17"}, {"asset_id": "97904810933420938915915184802871896723926497912237502816269649051469198352574", "price": "0.99", "size": "75.19", "side": "SELL", "hash": "0ec6df13973902387116c1569728288b32dfa98e", "best_bid": "0.83", "best_ask": "0.93"}], "timestamp": "1769384211434", "event_type": "price_change"}}
{"_local_timestamp": "2026-01-25T23:36:53.010852+00:00", "data": {"market": "0x983c1c640da74bd05222b1ae535d9d80e67a7c37ba821e213ab681da63f7b52d", "price_changes": [{"asset_id": "111487994318578797618498789659864547400234714169664391253427670617626566154712", "price": "0.067", "size": "0", "side": "BUY", "hash": "b29ba928113c4f9dec2fad8fee2b81ef819ac7b5", "best_bid": "0.907", "best_ask": "0.987"}, {"asset_id": "33334365343701835814605836236502189532077473322352990496796220640667787771374", "price": "0.933", "size": "0", "side": "SELL", "hash": "caf14f66ee46ce273cb49d37d85661c909064b27", "best_bid": "0.013", "best_ask": "0.093"}], "timestamp": "1769384212915", "event_type": "price_change"}}
{"_local_timestamp": "2026-01-25T23:36:53.765742+00:00", "data": {"market": "0x983c1c640da74bd05222b1ae535d9d80e67a7c37ba821e213ab681da63f7b52d", "price_changes": [{"asset_id": "111487994318578797618498789659864547400234714169664391253427670617626566154712", "price": "0.063", "size": "11.27", "side": "BUY", "hash": "08f392d1fe885da4b4ffeed078a4d6a61b40fa5a", "best_bid": "0.907", "best_ask": "0.987"}, {"asset_id": "33334365343701835814605836236502189532077473322352990496796220640667787771374", "price": "0.937", "size": "11.27", "side": "SELL", "hash": "0b20290af208b3a79b8717849d987b6befb6e828", "best_bid": "0.013", "best_ask": "0.093"}], "timestamp": "1769384213702", "event_type": "price_change"}}
{"_local_timestamp": "2026-01-25T23:36:58.404476+00:00", "data": {"market": "0x83547249e61eaf92162353753801453d313daaed73b401b9edcc669251f578c0", "price_changes": [{"asset_id": "64710685063708113016458069418988206406890895555826348081008842775253721088516", "price": "0.011", "size": "0", "side": "BUY", "hash": "7f860d93907433bd4817bde0152cb87f311e2339", "best_bid": "0.741", "best_ask": "0.793"}, {"asset_id": "49285515506903050077566386836604355110855655545900685629915315206051894927030", "price": "0.989", "size": "0", "side": "SELL", "hash": "858819cde3f3f3a31b99d56bd0779f5268b9f1f6", "best_bid": "0.207", "best_ask": "0.259"}], "timestamp": "1769384218274", "event_type": "price_change"}}
{"_local_timestamp": "2026-01-25T23:36:58.405031+00:00", "data": {"market": "0x83547249e61eaf92162353753801453d313daaed73b401b9edcc669251f578c0", "price_changes": [{"asset_id": "64710685063708113016458069418988206406890895555826348081008842775253721088516", "price": "0.023", "size": "0", "side": "BUY", "hash": "7f860d93907433bd4817bde0152cb87f311e2339", "best_bid": "0.741", "best_ask": "0.793"}, {"asset_id": "49285515506903050077566386836604355110855655545900685629915315206051894927030", "price": "0.977", "size": "0", "side": "SELL", "hash": "858819cde3f3f3a31b99d56bd0779f5268b9f1f6", "best_bid": "0.207", "best_ask": "0.259"}], "timestamp": "1769384218274", "event_type": "price_change"}}
{"_local_timestamp": "2026-01-25T23:36:58.974084+00:00", "data": {"market": "0xc6eaad93752e4f8b58b9faf7e63ec9ba1c548a49e6fe6b21f605ed9d71f4c57a", "price_changes": [{"asset_id": "25539386078797395599636818043909403100500096091846839226569678716060642614342", "price": "0.002", "size": "200", "side": "BUY", "hash": "599efa1ea5f786d106247d06eb806e70e3c2458e", "best_bid": "0.012", "best_ask": "0.179"}, {"asset_id": "106764258059853211019809099342916860924409096361081427559669257851522126201276", "price": "0.998", "size": "200", "side": "SELL", "hash": "0be8f9570607125acb10de18c9ec237ed3832f3d", "best_bid": "0.821", "best_ask": "0.988"}], "timestamp": "1769384218734", "event_type": "price_change"}}
{"_local_timestamp": "2026-01-25T23:36:58.981756+00:00", "data": {"market": "0xee6de29096f712879525fffe70ec19ed1069660c17a96770c990a48a4d6cafca", "price_changes": [{"asset_id": "79250352452729964397183638491507951490462474124621653995906925320890963543836", "price": "0.002", "size": "455.08", "side": "BUY", "hash": "e6ba2fe3adfaf7c7b5031d7763c9a787d84c736f", "best_bid": "0.887", "best_ask": "0.95"}, {"asset_id": "91615446195150618766021553383612375719498472212737560539314895278406213528776", "price": "0.998", "size": "455.08", "side": "SELL", "hash": "466b812dc90cc885c37e744a4012a6674814c08f", "best_bid": "0.05", "best_ask": "0.113"}], "timestamp": "1769384218734", "event_type": "price_change"}}
{"_local_timestamp": "2026-01-25T23:36:58.982258+00:00", "data": {"market": "0xc6eaad93752e4f8b58b9faf7e63ec9ba1c548a49e6fe6b21f605ed9d71f4c57a", "price_changes": [{"asset_id": "106764258059853211019809099342916860924409096361081427559669257851522126201276", "price": "0.002", "size": "450", "side": "BUY", "hash": "3dd2e956618637eda062be64c7f2f339218f036c", "best_bid": "0.821", "best_ask": "0.988"}, {"asset_id": "25539386078797395599636818043909403100500096091846839226569678716060642614342", "price": "0.998", "size": "450", "side": "SELL", "hash": "5eed383cb43b90d6d23d9df317c6866b6bfbfb78", "best_bid": "0.012", "best_ask": "0.179"}], "timestamp": "1769384218735", "event_type": "price_change"}}
{"_local_timestamp": "2026-01-25T23:36:59.150471+00:00", "data": {"market": "0x83547249e61eaf92162353753801453d313daaed73b401b9edcc669251f578c0", "price_changes": [{"asset_id": "64710685063708113016458069418988206406890895555826348081008842775253721088516", "price": "0.024", "size": "22.85", "side": "BUY", "hash": "03d694799848a2d4fabb74c659678a941b571b89", "best_bid": "0.741", "best_ask": "0.793"}, {"asset_id": "49285515506903050077566386836604355110855655545900685629915315206051894927030", "price": "0.976", "size": "22.85", "side": "SELL", "hash": "d1aae834e146e366588c47dc35a7b36d17682fce", "best_bid": "0.207", "best_ask": "0.259"}], "timestamp": "1769384219076", "event_type": "price_change"}}
{"_local_timestamp": "2026-01-25T23:36:59.151094+00:00", "data": {"market": "0x83547249e61eaf92162353753801453d313daaed73b401b9edcc669251f578c0", "price_changes": [{"asset_id": "64710685063708113016458069418988206406890895555826348081008842775253721088516", "price": "0.011", "size": "9.72", "side": "BUY", "hash": "d77af56c9d8f81fdccdd05a4d813c84c074a43ac", "best_bid": "0.741", "best_ask": "0.793"}, {"asset_id": "49285515506903050077566386836604355110855655545900685629915315206051894927030", "price": "0.989", "size": "9.72", "side": "SELL", "hash": "79e52b495e8a95e0751f5a0f9a9b0bda44f933bc", "best_bid": "0.207", "best_ask": "0.259"}], "timestamp": "1769384219077", "event_type": "price_change"}}
{"_local_timestamp": "2026-01-25T23:36:59.706184+00:00", "data": {"market": "0x3254c0fde930bd86e5cc6cf9eb9dc16ca364ab4819ed5e1802a53b0fa2f36772", "price_changes": [{"asset_id": "28260696393853739649130713837590031037312393528301041179223890674988415162070", "price": "0.06", "size": "30", "side": "BUY", "hash": "b040291f6dbe474573ba141a578e3963e9fecab8", "best_bid": "0.06", "best_ask": "0.2"}, {"asset_id": "1243252154129193015238236663840507016761347339076756815039433906036180619298", "price": "0.94", "size": "30", "side": "SELL", "hash": "f18103df30d89c1ce9e60adc0168012c2d03da48", "best_bid": "0.8", "best_ask": "0.94"}], "timestamp": "1769384219631", "event_type": "price_change"}}
{"_local_timestamp": "2026-01-25T23:37:00.094161+00:00", "data": {"market": "0x3254c0fde930bd86e5cc6cf9eb9dc16ca364ab4819ed5e1802a53b0fa2f36772", "price_changes": [{"asset_id": "28260696393853739649130713837590031037312393528301041179223890674988415162070", "price": "0.06", "size": "37.18", "side": "BUY", "hash": "dcef4008e5615074ddd33cb0fd507c61de112237", "best_bid": "0.06", "best_ask": "0.2"}, {"asset_id": "1243252154129193015238236663840507016761347339076756815039433906036180619298", "price": "0.94", "size": "37.18", "side": "SELL", "hash": "060bdbfaab6bbbb1af370b547af74d032542a53a", "best_bid": "0.8", "best_ask": "0.94"}], "timestamp": "1769384220023", "event_type": "price_change"}}
{"_local_timestamp": "2026-01-25T23:37:00.105590+00:00", "data": {"market": "0x3254c0fde930bd86e5cc6cf9eb9dc16ca364ab4819ed5e1802a53b0fa2f36772", "price_changes": [{"asset_id": "28260696393853739649130713837590031037312393528301041179223890674988415162070", "price": "0.01", "size": "67.9", "side": "BUY", "hash": "91c3523be58e0f0ee8eaf1a901816e1413735cdd", "best_bid": "0.06", "best_ask": "0.2"}, {"asset_id": "1243252154129193015238236663840507016761347339076756815039433906036180619298", "price": "0.99", "size": "67.9", "side": "SELL", "hash": "f07baf8f99a9faa72b7515f998e8c874bfc461ff", "best_bid": "0.8", "best_ask": "0.94"}], "timestamp": "1769384220025", "event_type": "price_change"}}
{"_local_timestamp": "2026-01-25T23:37:06.066177+00:00", "data": {"market": "0x4f23a49ee29fb939c5362cd64d46308244a57940dbb0b310f8285c9eb86fc716", "price_changes": [{"asset_id": "4736807889727546600449711523206670596020980806462877805590160133017151608432", "price": "0.004", "size": "44.54", "side": "BUY", "hash": "f1493b65af8a86aa00597fb2223bd3c6b77fcf7d", "best_bid": "0.01", "best_ask": "0.02"}, {"asset_id": "97176661089474192633400371830610594863643347280235884018546189389594263735812", "price": "0.996", "size": "44.54", "side": "SELL", "hash": "dff859175835a32b5cb9fe6e75233543fcd85746", "best_bid": "0.98", "best_ask": "0.99"}], "timestamp": "1769384225987", "event_type": "price_change"}}
{"_local_timestamp": "2026-01-25T23:37:06.478249+00:00", "data": {"market": "0x4f23a49ee29fb939c5362cd64d46308244a57940dbb0b310f8285c9eb86fc716", "price_changes": [{"asset_id": "4736807889727546600449711523206670596020980806462877805590160133017151608432", "price": "0.004", "size": "79.56", "side": "BUY", "hash": "b24f7911d1c37d62ec269079516b603e3f8f4cb6", "best_bid": "0.01", "best_ask": "0.02"}, {"asset_id": "97176661089474192633400371830610594863643347280235884018546189389594263735812", "price": "0.996", "size": "79.56", "side": "SELL", "hash": "254ba94dd126ad0cfcf58d68d60aab04892e6169", "best_bid": "0.98", "best_ask": "0.99"}], "timestamp": "1769384226400", "event_type": "price_change"}}
{"_local_timestamp": "2026-01-25T23:37:06.793458+00:00", "data": {"market": "0x4f23a49ee29fb939c5362cd64d46308244a57940dbb0b310f8285c9eb86fc716", "price_changes": [{"asset_id": "4736807889727546600449711523206670596020980806462877805590160133017151608432", "price": "0.004", "size": "44.54", "side": "BUY", "hash": "bb448a3103ddd685934bbc75c9ad35e47c07a5d7", "best_bid": "0.01", "best_ask": "0.02"}, {"asset_id": "97176661089474192633400371830610594863643347280235884018546189389594263735812", "price": "0.996", "size": "44.54", "side": "SELL", "hash": "c1536aac5e3b7d8415cf6df7dbf60cd57ccc3b6a", "best_bid": "0.98", "best_ask": "0.99"}], "timestamp": "1769384226727", "event_type": "price_change"}}
{"_local_timestamp": "2026-01-25T23:37:07.201571+00:00", "data": {"market": "0x4f23a49ee29fb939c5362cd64d46308244a57940dbb0b310f8285c9eb86fc716", "price_changes": [{"asset_id": "4736807889727546600449711523206670596020980806462877805590160133017151608432", "price": "0.004", "size": "79.56", "side": "BUY", "hash": "c5f20d12f09e57d064f240215e6ad822c5a825a0", "best_bid": "0.01", "best_ask": "0.02"}, {"asset_id": "97176661089474192633400371830610594863643347280235884018546189389594263735812", "price": "0.996", "size": "79.56", "side": "SELL", "hash": "7fdca0176a09be586bb7a488bb064779d419d8a7", "best_bid": "0.98", "best_ask": "0.99"}], "timestamp": "1769384227124", "event_type": "price_change"}}
{"_local_timestamp": "2026-01-25T23:38:04.617488+00:00", "data": {"market": "0xaef8cc72583c46308a4f61b93cce219831d4861af26c0ace983300183b5d6f77", "price_changes": [{"asset_id": "97904810933420938915915184802871896723926497912237502816269649051469198352574", "price": "0.05", "size": "6", "side": "BUY", "hash": "19fc852e71e4351f0e8f60f9125b17820ef5005d", "best_bid": "0.83", "best_ask": "0.93"}, {"asset_id": "23410860411880980077660432875622355119426529164122573169196610980318417032021", "price": "0.95", "size": "6", "side": "SELL", "hash": "3c357657d5d2b05a9a6193dff0df0a29cac51852", "best_bid": "0.07", "best_ask": "0.17"}], "timestamp": "1769384284552", "event_type": "price_change"}}
{"_local_timestamp": "2026-01-25T23:38:04.711776+00:00", "data": {"market": "0xaef8cc72583c46308a4f61b93cce219831d4861af26c0ace983300183b5d6f77", "price_changes": [{"asset_id": "97904810933420938915915184802871896723926497912237502816269649051469198352574", "price": "0.06", "size": "43", "side": "BUY", "hash": "23b1c5f1f319786f5ceed8a3d597d43cdc080d3a", "best_bid": "0.83", "best_ask": "0.93"}, {"asset_id": "23410860411880980077660432875622355119426529164122573169196610980318417032021", "price": "0.94", "size": "43", "side": "SELL", "hash": "73d9a79b8b995fc49050d0b081518e0e4bc95604", "best_bid": "0.07", "best_ask": "0.17"}], "timestamp": "1769384284643", "event_type": "price_change"}}
{"_local_timestamp": "2026-01-25T23:38:10.615240+00:00", "data": {"market": "0x983c1c640da74bd05222b1ae535d9d80e67a7c37ba821e213ab681da63f7b52d", "price_changes": [{"asset_id": "33334365343701835814605836236502189532077473322352990496796220640667787771374", "price": "0.093", "size": "0", "side": "SELL", "hash": "709854ecbb072e0826770451cbb8927f80c58a85", "best_bid": "0.013", "best_ask": "0.098"}, {"asset_id": "111487994318578797618498789659864547400234714169664391253427670617626566154712", "price": "0.907", "size": "0", "side": "BUY", "hash": "45f18fcf6e36dc5fbd00606c754d2876c75406bb", "best_bid": "0.902", "best_ask": "0.987"}], "timestamp": "1769384290546", "event_type": "price_change"}}
{"_local_timestamp": "2026-01-25T23:38:11.026558+00:00", "data": {"market": "0x983c1c640da74bd05222b1ae535d9d80e67a7c37ba821e213ab681da63f7b52d", "price_changes": [{"asset_id": "33334365343701835814605836236502189532077473322352990496796220640667787771374", "price": "0.097", "size": "16.53", "side": "SELL", "hash": "800272dfec8927e4e2dd0d29280ec48f5325b8b7", "best_bid": "0.013", "best_ask": "0.097"}, {"asset_id": "111487994318578797618498789659864547400234714169664391253427670617626566154712", "price": "0.903", "size": "16.53", "side": "BUY", "hash": "ab6a392523149373194bd11dfe44417c33928705", "best_bid": "0.903", "best_ask": "0.987"}], "timestamp": "1769384290960", "event_type": "price_change"}}
{"_local_timestamp": "2026-01-25T23:38:20.506996+00:00", "data": {"market": "0x4c8a4ecc294553e865f9bed3cf2ba6d1cefe23515f6ece2b6b01f696d2845fe0", "price_changes": [{"asset_id": "51915547669523222925311577874361232586045773418874670768734077060997483885755", "price": "0.74", "size": "0", "side": "BUY", "hash": "f8db73c32501e10ce91a22103f8120646e2c683a", "best_bid": "0.18", "best_ask": "0.81"}, {"asset_id": "93232945228609658077531889011480905670187160388516295356072507802163300422442", "price": "0.26", "size": "0", "side": "SELL", "hash": "264053a1418dea005ded89e345bf0852ed9639a3", "best_bid": "0.19", "best_ask": "0.82"}], "timestamp": "1769384300438", "event_type": "price_change"}}
{"_local_timestamp": "2026-01-25T23:38:20.507621+00:00", "data": {"market": "0x4c8a4ecc294553e865f9bed3cf2ba6d1cefe23515f6ece2b6b01f696d2845fe0", "asset_id": "93232945228609658077531889011480905670187160388516295356072507802163300422442", "bids": [{"price": "0.01", "size": "60"}, {"price": "0.02", "size": "18.31"}, {"price": "0.04", "size": "12"}, {"price": "0.05", "size": "1020"}, {"price": "0.06", "size": "33"}, {"price": "0.07", "size": "9.05"}, {"price": "0.09", "size": "144.44"}, {"price": "0.1", "size": "110"}, {"price": "0.14", "size": "505"}, {"price": "0.15", "size": "260"}, {"price": "0.16", "size": "20"}, {"price": "0.19", "size": "5.05"}], "asks": [{"price": "0.99", "size": "55.24"}, {"price": "0.98", "size": "23.53"}, {"price": "0.95", "size": "30"}, {"price": "0.93", "size": "101"}, {"price": "0.92", "size": "50"}, {"price": "0.91", "size": "5.3"}, {"price": "0.84", "size": "81.25"}, {"price": "0.83", "size": "74.7"}, {"price": "0.82", "size": "11"}], "hash": "264053a1418dea005ded89e345bf0852ed9639a3", "timestamp": "1769384300438", "event_type": "book"}}
{"_local_timestamp": "2026-01-25T23:38:20.508160+00:00", "data": {"market": "0x4c8a4ecc294553e865f9bed3cf2ba6d1cefe23515f6ece2b6b01f696d2845fe0", "asset_id": "51915547669523222925311577874361232586045773418874670768734077060997483885755", "bids": [{"price": "0.01", "size": "55.24"}, {"price": "0.02", "size": "23.53"}, {"price": "0.05", "size": "30"}, {"price": "0.07", "size": "101"}, {"price": "0.08", "size": "50"}, {"price": "0.09", "size": "5.3"}, {"price": "0.16", "size": "81.25"}, {"price": "0.17", "size": "74.7"}, {"price": "0.18", "size": "11"}], "asks": [{"price": "0.99", "size": "60"}, {"price": "0.98", "size": "18.31"}, {"price": "0.96", "size": "12"}, {"price": "0.95", "size": "1020"}, {"price": "0.94", "size": "33"}, {"price": "0.93", "size": "9.05"}, {"price": "0.91", "size": "144.44"}, {"price": "0.9", "size": "110"}, {"price": "0.86", "size": "505"}, {"price": "0.85", "size": "260"}, {"price": "0.84", "size": "20"}, {"price": "0.81", "size": "5.05"}], "hash": "f8db73c32501e10ce91a22103f8120646e2c683a", "timestamp": "1769384300438", "event_type": "book"}}
{"_local_timestamp": "2026-01-25T23:38:20.532248+00:00", "data": {"market": "0x4c8a4ecc294553e865f9bed3cf2ba6d1cefe23515f6ece2b6b01f696d2845fe0", "asset_id": "51915547669523222925311577874361232586045773418874670768734077060997483885755", "price": "0.74", "size": "20", "fee_rate_bps": "0", "side": "SELL", "timestamp": "1769384300466", "event_type": "last_trade_price", "transaction_hash": "0xdd8ddbacf75d0fb61d27c67107d6496f47f8bf3400bd37ba13880f6341bf64fb"}}
{"_local_timestamp": "2026-01-25T23:38:23.596653+00:00", "data": {"market": "0x4c8a4ecc294553e865f9bed3cf2ba6d1cefe23515f6ece2b6b01f696d2845fe0", "price_changes": [{"asset_id": "93232945228609658077531889011480905670187160388516295356072507802163300422442", "price": "0.19", "size": "10.31", "side": "BUY", "hash": "7641c7e79536d319fe6cd7f4af12de78ea1b0f7a", "best_bid": "0.19", "best_ask": "0.82"}, {"asset_id": "51915547669523222925311577874361232586045773418874670768734077060997483885755", "price": "0.81", "size": "10.31", "side": "SELL", "hash": "0486d7a3bc0d3aea76556d783aa365463fec1a3d", "best_bid": "0.18", "best_ask": "0.81"}], "timestamp": "1769384303531", "event_type": "price_change"}}
{"_local_timestamp": "2026-01-25T23:38:44.546458+00:00", "data": {"market": "0xee6de29096f712879525fffe70ec19ed1069660c17a96770c990a48a4d6cafca", "price_changes": [{"asset_id": "91615446195150618766021553383612375719498472212737560539314895278406213528776", "price": "0.034", "size": "0", "side": "BUY", "hash": "eb4bc507de9e5a8c91ecb6639d97b82f401c1b55", "best_bid": "0.05", "best_ask": "0.113"}, {"asset_id": "79250352452729964397183638491507951490462474124621653995906925320890963543836", "price": "0.966", "size": "0", "side": "SELL", "hash": "dc6d54e0770f880e2d54a67d08a4157c15ffd513", "best_bid": "0.887", "best_ask": "0.95"}], "timestamp": "1769384324478", "event_type": "price_change"}}
{"_local_timestamp": "2026-01-25T23:38:44.893720+00:00", "data": {"market": "0xee6de29096f712879525fffe70ec19ed1069660c17a96770c990a48a4d6cafca", "price_changes": [{"asset_id": "91615446195150618766021553383612375719498472212737560539314895278406213528776", "price": "0.036", "size": "9.17", "side": "BUY", "hash": "82d27250e91afe521e12cd434474ee92cb84b021", "best_bid": "0.05", "best_ask": "0.113"}, {"asset_id": "79250352452729964397183638491507951490462474124621653995906925320890963543836", "price": "0.964", "size": "9.17", "side": "SELL", "hash": "0195f3f9e4bc644cd7605b1343127598721ef992", "best_bid": "0.887", "best_ask": "0.95"}], "timestamp": "1769384324825", "event_type": "price_change"}}
{"_local_timestamp": "2026-01-25T23:39:04.368549+00:00", "data": {"market": "0xc6eaad93752e4f8b58b9faf7e63ec9ba1c548a49e6fe6b21f605ed9d71f4c57a", "price_changes": [{"asset_id": "25539386078797395599636818043909403100500096091846839226569678716060642614342", "price": "0.281", "size": "10", "side": "SELL", "hash": "b9c190316dad4b903031652668cd425a1d2eb155", "best_bid": "0.012", "best_ask": "0.179"}, {"asset_id": "106764258059853211019809099342916860924409096361081427559669257851522126201276", "price": "0.719", "size": "10", "side": "BUY", "hash": "b3a06642776d9edcb39238d38fc49f35150fabf2", "best_bid": "0.821", "best_ask": "0.988"}], "timestamp": "1769384344302", "event_type": "price_change"}}
{"_local_timestamp": "2026-01-25T23:39:04.561801+00:00", "data": {"market": "0xc6eaad93752e4f8b58b9faf7e63ec9ba1c548a49e6fe6b21f605ed9d71f4c57a", "price_changes": [{"asset_id": "25539386078797395599636818043909403100500096091846839226569678716060642614342", "price": "0.28", "size": "11.25", "side": "SELL", "hash": "a607d893d93d3bf2b5bf4423cf31b40ea9f2acfa", "best_bid": "0.012", "best_ask": "0.179"}, {"asset_id": "106764258059853211019809099342916860924409096361081427559669257851522126201276", "price": "0.72", "size": "11.25", "side": "BUY", "hash": "1b7b577b36369b479a1e9c64e4068ff611a3afc4", "best_bid": "0.821", "best_ask": "0.988"}], "timestamp": "1769384344498", "event_type": "price_change"}}
{"_local_timestamp": "2026-01-25T23:39:07.054519+00:00", "data": {"market": "0x4c8a4ecc294553e865f9bed3cf2ba6d1cefe23515f6ece2b6b01f696d2845fe0", "price_changes": [{"asset_id": "51915547669523222925311577874361232586045773418874670768734077060997483885755", "price": "0.17", "size": "64.7", "side": "BUY", "hash": "2236122ef7b5ad5e9b6b15adcd261aae91879bee", "best_bid": "0.18", "best_ask": "0.81"}, {"asset_id": "93232945228609658077531889011480905670187160388516295356072507802163300422442", "price": "0.83", "size": "64.7", "side": "SELL", "hash": "8bc0deb0f88674a70f7b032e01a97e4edde7c634", "best_bid": "0.19", "best_ask": "0.82"}], "timestamp": "1769384346983", "event_type": "price_change"}}
{"_local_timestamp": "2026-01-25T23:39:07.137481+00:00", "data": {"market": "0x4c8a4ecc294553e865f9bed3cf2ba6d1cefe23515f6ece2b6b01f696d2845fe0", "price_changes": [{"asset_id": "51915547669523222925311577874361232586045773418874670768734077060997483885755", "price": "0.1", "size": "10", "side": "BUY", "hash": "b610a5ea961c60d5e8cd981aa219c9f33dcb323f", "best_bid": "0.18", "best_ask": "0.81"}, {"asset_id": "93232945228609658077531889011480905670187160388516295356072507802163300422442", "price": "0.9", "size": "10", "side": "SELL", "hash": "ee6d4be05883435102127398a1deae42e0bc416f", "best_bid": "0.19", "best_ask": "0.82"}], "timestamp": "1769384347070", "event_type": "price_change"}}
{"_local_timestamp": "2026-01-25T23:39:29.219345+00:00", "data": {"market": "0x83547249e61eaf92162353753801453d313daaed73b401b9edcc669251f578c0", "price_changes": [{"asset_id": "49285515506903050077566386836604355110855655545900685629915315206051894927030", "price": "0.206", "size": "20", "side": "BUY", "hash": "946ca70e497f9ed1a684dcac327c650085b041ba", "best_bid": "0.207", "best_ask": "0.259"}, {"asset_id": "64710685063708113016458069418988206406890895555826348081008842775253721088516", "price": "0.794", "size": "20", "side": "SELL", "hash": "edf301fac1cfe0bc6128511e1c166716173d5f2d", "best_bid": "0.741", "best_ask": "0.793"}], "timestamp": "1769384369115", "event_type": "price_change"}}
{"_local_timestamp": "2026-01-25T23:39:30.588965+00:00", "data": {"market": "0x83547249e61eaf92162353753801453d313daaed73b401b9edcc669251f578c0", "price_changes": [{"asset_id": "49285515506903050077566386836604355110855655545900685629915315206051894927030", "price": "0.206", "size": "0", "side": "BUY", "hash": "8c5d1a0a10589ce8baba7239e266a67ddb7bd2e9", "best_bid": "0.207", "best_ask": "0.259"}, {"asset_id": "64710685063708113016458069418988206406890895555826348081008842775253721088516", "price": "0.794", "size": "0", "side": "SELL", "hash": "9a854f689d712b1b28ed1c9f19ec1d279684f393", "best_bid": "0.741", "best_ask": "0.793"}], "timestamp": "1769384370513", "event_type": "price_change"}}
{"_local_timestamp": "2026-01-25T23:39:32.014276+00:00", "data": {"market": "0x83547249e61eaf92162353753801453d313daaed73b401b9edcc669251f578c0", "price_changes": [{"asset_id": "49285515506903050077566386836604355110855655545900685629915315206051894927030", "price": "0.208", "size": "43", "side": "BUY", "hash": "2e92774c980eede01f955fd16ef491ea1af9618c", "best_bid": "0.208", "best_ask": "0.259"}, {"asset_id": "64710685063708113016458069418988206406890895555826348081008842775253721088516", "price": "0.792", "size": "43", "side": "SELL", "hash": "b347931b054f0aa78d28a9d24e59da44d0d4bc59", "best_bid": "0.741", "best_ask": "0.792"}], "timestamp": "1769384371945", "event_type": "price_change"}}
{"_local_timestamp": "2026-01-25T23:39:33.059193+00:00", "data": {"market": "0x83547249e61eaf92162353753801453d313daaed73b401b9edcc669251f578c0", "price_changes": [{"asset_id": "64710685063708113016458069418988206406890895555826348081008842775253721088516", "price": "0.793", "size": "0", "side": "SELL", "hash": "26870fd5dfd252eaf0ec52af10fa3d91b5edc6d4", "best_bid": "0.741", "best_ask": "0.792"}, {"asset_id": "49285515506903050077566386836604355110855655545900685629915315206051894927030", "price": "0.207", "size": "0", "side": "BUY", "hash": "6aa45ac9c2f22fc176856ffd903059e7828bd946", "best_bid": "0.208", "best_ask": "0.259"}], "timestamp": "1769384372991", "event_type": "price_change"}}
{"_local_timestamp": "2026-01-25T23:39:33.554773+00:00", "data": {"market": "0x83547249e61eaf92162353753801453d313daaed73b401b9edcc669251f578c0", "price_changes": [{"asset_id": "64710685063708113016458069418988206406890895555826348081008842775253721088516", "price": "0.791", "size": "106.09", "side": "SELL", "hash": "bde4c1162a2d84cc4e20c8178bc0a670ebe5ff23", "best_bid": "0.741", "best_ask": "0.791"}, {"asset_id": "49285515506903050077566386836604355110855655545900685629915315206051894927030", "price": "0.209", "size": "106.09", "side": "BUY", "hash": "0798597a67a45f5334cefee6697e6aeb86a34248", "best_bid": "0.209", "best_ask": "0.259"}], "timestamp": "1769384373480", "event_type": "price_change"}}
{"_local_timestamp": "2026-01-25T23:39:36.767007+00:00", "data": {"market": "0x83547249e61eaf92162353753801453d313daaed73b401b9edcc669251f578c0", "price_changes": [{"asset_id": "49285515506903050077566386836604355110855655545900685629915315206051894927030", "price": "0.208", "size": "63", "side": "BUY", "hash": "1e7fa062458c29bf41dd5a5eafd28dbd704ce358", "best_bid": "0.209", "best_ask": "0.259"}, {"asset_id": "64710685063708113016458069418988206406890895555826348081008842775253721088516", "price": "0.792", "size": "63", "side": "SELL", "hash": "0effd2be3a1c0df8344d78c9eaf7d4ac4c717f51", "best_bid": "0.741", "best_ask": "0.791"}], "timestamp": "1769384376695", "event_type": "price_change"}}
{"_local_timestamp": "2026-01-25T23:39:39.051825+00:00", "data": {"market": "0xee6de29096f712879525fffe70ec19ed1069660c17a96770c990a48a4d6cafca", "price_changes": [{"asset_id": "91615446195150618766021553383612375719498472212737560539314895278406213528776", "price": "0.035", "size": "0", "side": "BUY", "hash": "74f5d131f25fb36695eeadb1d1287aba4278b3d6", "best_bid": "0.05", "best_ask": "0.113"}, {"asset_id": "79250352452729964397183638491507951490462474124621653995906925320890963543836", "price": "0.965", "size": "0", "side": "SELL", "hash": "5c7313bf1f3e160ff761aba32e3ce762148197a2", "best_bid": "0.887", "best_ask": "0.95"}], "timestamp": "1769384378978", "event_type": "price_change"}}
{"_local_timestamp": "2026-01-25T23:39:39.198109+00:00", "data": {"market": "0xee6de29096f712879525fffe70ec19ed1069660c17a96770c990a48a4d6cafca", "price_changes": [{"asset_id": "91615446195150618766021553383612375719498472212737560539314895278406213528776", "price": "0.037", "size": "10", "side": "BUY", "hash": "5fa013bd7121c01eb92598092f904382915e5d14", "best_bid": "0.05", "best_ask": "0.113"}, {"asset_id": "79250352452729964397183638491507951490462474124621653995906925320890963543836", "price": "0.963", "size": "10", "side": "SELL", "hash": "87c57f4833c08e1967107c1b1436c9b31ee3db95", "best_bid": "0.887", "best_ask": "0.95"}], "timestamp": "1769384379134", "event_type": "price_change"}}
{"_local_timestamp": "2026-01-25T23:39:45.795064+00:00", "data": {"market": "0xee6de29096f712879525fffe70ec19ed1069660c17a96770c990a48a4d6cafca", "price_changes": [{"asset_id": "79250352452729964397183638491507951490462474124621653995906925320890963543836", "price": "0.95", "size": "0", "side": "SELL", "hash": "911d1dd1fd9b79cb3af279491683b0ce6eb2c509", "best_bid": "0.886", "best_ask": "0.951"}, {"asset_id": "91615446195150618766021553383612375719498472212737560539314895278406213528776", "price": "0.05", "size": "0", "side": "BUY", "hash": "27c2cb48dfb6381ecf3fb79d14939ea4d67a8706", "best_bid": "0.049", "best_ask": "0.114"}], "timestamp": "1769384385723", "event_type": "price_change"}}
{"_local_timestamp": "2026-01-25T23:39:45.795718+00:00", "data": {"market": "0xee6de29096f712879525fffe70ec19ed1069660c17a96770c990a48a4d6cafca", "price_changes": [{"asset_id": "79250352452729964397183638491507951490462474124621653995906925320890963543836", "price": "0.887", "size": "0", "side": "BUY", "hash": "911d1dd1fd9b79cb3af279491683b0ce6eb2c509", "best_bid": "0.886", "best_ask": "0.951"}, {"asset_id": "91615446195150618766021553383612375719498472212737560539314895278406213528776", "price": "0.113", "size": "0", "side": "SELL", "hash": "27c2cb48dfb6381ecf3fb79d14939ea4d67a8706", "best_bid": "0.049", "best_ask": "0.114"}], "timestamp": "1769384385723", "event_type": "price_change"}}
{"_local_timestamp": "2026-01-25T23:39:45.942746+00:00", "data": {"market": "0xc6eaad93752e4f8b58b9faf7e63ec9ba1c548a49e6fe6b21f605ed9d71f4c57a", "price_changes": [{"asset_id": "106764258059853211019809099342916860924409096361081427559669257851522126201276", "price": "0.719", "size": "0", "side": "BUY", "hash": "ed765c4b66b69bc7685cf736c12bb547048a1c1d", "best_bid": "0.821", "best_ask": "0.988"}, {"asset_id": "25539386078797395599636818043909403100500096091846839226569678716060642614342", "price": "0.281", "size": "0", "side": "SELL", "hash": "d676f57fef49b02bda496575b88d5bdcae84d9d7", "best_bid": "0.012", "best_ask": "0.179"}], "timestamp": "1769384385825", "event_type": "price_change"}}
{"_local_timestamp": "2026-01-25T23:39:46.012585+00:00", "data": {"market": "0xc6eaad93752e4f8b58b9faf7e63ec9ba1c548a49e6fe6b21f605ed9d71f4c57a", "price_changes": [{"asset_id": "106764258059853211019809099342916860924409096361081427559669257851522126201276", "price": "0.72", "size": "21.25", "side": "BUY", "hash": "da7b0ab02b298e93344c26681e2b4a05270ddda0", "best_bid": "0.821", "best_ask": "0.988"}, {"asset_id": "25539386078797395599636818043909403100500096091846839226569678716060642614342", "price": "0.28", "size": "21.25", "side": "SELL", "hash": "790c68377f79697ad3d1d943a1b67e0c584c9f46", "best_bid": "0.012", "best_ask": "0.179"}], "timestamp": "1769384385923", "event_type": "price_change"}}
{"_local_timestamp": "2026-01-25T23:40:12.875702+00:00", "data": {"market": "0xee6de29096f712879525fffe70ec19ed1069660c17a96770c990a48a4d6cafca", "price_changes": [{"asset_id": "79250352452729964397183638491507951490462474124621653995906925320890963543836", "price": "0.95", "size": "15.89", "side": "SELL", "hash": "3fd82bc4734bf40352fe63ef5b98bba121cb128f", "best_bid": "0.886", "best_ask": "0.95"}, {"asset_id": "91615446195150618766021553383612375719498472212737560539314895278406213528776", "price": "0.05", "size": "15.89", "side": "BUY", "hash": "0e78b5c81df6ad0779c91a826d0a804f14f336f0", "best_bid": "0.05", "best_ask": "0.114"}], "timestamp": "1769384412799", "event_type": "price_change"}}
