{"_local_timestamp": "2026-01-25T23:40:47.183459+00:00", "data": [{"market": "0x120a43c108202f029133104531990a595af4f3700a92bbda4403535235bc4c82", "asset_id": "39828720608155723418301214397692986239980049531210825338778701775676917810839", "timestamp": "1769384426829", "hash": "88ebde57687dd7e6eba3588a189e6f532c6f0bfb", "bids": [{"price": "0.01", "size": "5269.82"}, {"price": "0.02", "size": "2400"}, {"price": "0.03", "size": "8.05"}, {"price": "0.05", "size": "10"}, {"price": "0.06", "size": "1550"}, {"price": "0.08", "size": "200"}, {"price": "0.09", "size": "7.33"}, {"price": "0.14", "size": "50"}, {"price": "0.15", "size": "300"}, {"price": "0.17", "size": "11"}, {"price": "0.18", "size": "888"}, {"price": "0.21", "size": "50"}, {"price": "0.22", "size": "2108"}, {"price": "0.24", "size": "250"}, {"price": "0.27", "size": "250"}, {"price": "0.34", "size": "150"}, {"price": "0.55", "size": "104.32"}, {"price": "0.62", "size": "47.99"}, {"price": "0.63", "size": "100"}, {"price": "0.64", "size": "16"}, {"price": "0.68", "size": "1882.4"}, {"price": "0.72", "size": "810"}, {"price": "0.73", "size": "664"}, {"price": "0.74", "size": "659.1"}, {"price": "0.75", "size": "20"}], "asks": [{"price": "0.99", "size": "2467.79"}, {"price": "0.98", "size": "850"}, {"price": "0.97", "size": "30.73"}, {"price": "0.84", "size": "20"}, {"price": "0.81", "size": "547.23"}, {"price": "0.8", "size": "800"}, {"price": "0.79", "size": "162.84"}, {"price": "0.78", "size": "633"}, {"price": "0.77", "size": "20"}], "event_type": "book", "last_trade_price": ""}, {"market": "0x120a43c108202f029133104531990a595af4f3700a92bbda4403535235bc4c82", "asset_id": "8361104603056110450083567322497943223782511845432999258620698572163981630847", "timestamp": "1769384426829", "hash": "c6f6705178c100c64d0d2e578a0f874fb78a2ebb", "bids": [{"price": "0.01", "size": "2467.79"}, {"price": "0.02", "size": "850"}, {"price": "0.03", "size": "30.73"}, {"price": "0.16", "size": "20"}, {"price": "0.19", "size": "547.23"}, {"price": "0.2", "size": "800"}, {"price": "0.21", "size": "162.84"}, {"price": "0.22", "size": "633"}, {"price": "0.23", "size": "20"}], "asks": [{"price": "0.99", "size": "5269.82"}, {"price": "0.98", "size": "2400"}, {"price": "0.97", "size": "8.05"}, {"price": "0.95", "size": "10"}, {"price": "0.94", "size": "1550"}, {"price": "0.92", "size": "200"}, {"price": "0.91", "size": "7.33"}, {"price": "0.86", "size": "50"}, {"price": "0.85", "size": "300"}, {"price": "0.83", "size": "11"}, {"price": "0.82", "size": "888"}, {"price": "0.79", "size": "50"}, {"price": "0.78", "size": "2108"}, {"price": "0.76", "size": "250"}, {"price": "0.73", "size": "250"}, {"price": "0.66", "size": "150"}, {"price": "0.45", "size": "104.32"}, {"price": "0.38", "size": "47.99"}, {"price": "0.37", "size": "100"}, {"price": "0.36", "size": "16"}, {"price": "0.32", "size": "1882.4"}, {"price": "0.28", "size": "810"}, {"price": "0.27", "size": "664"}, {"price": "0.26", "size": "659.1"}, {"price": "0.25", "size": "20"}], "event_type": "book", "last_trade_price": ""}]}
{"_local_timestamp": "2026-01-25T23:41:14.684643+00:00", "data": {"market": "0x120a43c108202f029133104531990a595af4f3700a92bbda4403535235bc4c82", "price_changes": [{"asset_id": "39828720608155723418301214397692986239980049531210825338778701775676917810839", "price": "0.22", "size": "200", "side": "BUY", "hash": "6b3e4e93509d0da01aeeea154f49570d19aeee47", "best_bid": "0.75", "best_ask": "0.77"}, {"asset_id": "8361104603056110450083567322497943223782511845432999258620698572163981630847", "price": "0.78", "size": "200", "side": "SELL", "hash": "dfa0e10441559e86a5facc485f4d6ebd831758a6", "best_bid": "0.23", "best_ask": "0.25"}], "timestamp": "1769384474530", "event_type": "price_change"}}
{"_local_timestamp": "2026-01-25T23:41:34.579401+00:00", "data": {"market": "0x120a43c108202f029133104531990a595af4f3700a92bbda4403535235bc4c82", "price_changes": [{"asset_id": "39828720608155723418301214397692986239980049531210825338778701775676917810839", "price": "0.21", "size": "2048", "side": "BUY", "hash": "085e81c6f34c4bef1b38fc545f81a65cbf8125d3", "best_bid": "0.75", "best_ask": "0.77"}, {"asset_id": "8361104603056110450083567322497943223782511845432999258620698572163981630847", "price": "0.79", "size": "2048", "side": "SELL", "hash": "7f60136fd4d4c2f30ae8e2f552e7516a147915e4", "best_bid": "0.23", "best_ask": "0.25"}], "timestamp": "1769384494501", "event_type": "price_change"}}
{"_local_timestamp": "2026-01-25T23:41:38.098174+00:00", "data": {"market": "0x120a43c108202f029133104531990a595af4f3700a92bbda4403535235bc4c82", "price_changes": [{"asset_id": "39828720608155723418301214397692986239980049531210825338778701775676917810839", "price": "0.22", "size": "0", "side": "BUY", "hash": "c583ba3076feefc8fd9fb13ec33f44a74c376fe5", "best_bid": "0.75", "best_ask": "0.77"}, {"asset_id": "8361104603056110450083567322497943223782511845432999258620698572163981630847", "price": "0.78", "size": "0", "side": "SELL", "hash": "f1f0ef25e340800e230c3e7affff97a449ba7932", "best_bid": "0.23", "best_ask": "0.25"}], "timestamp": "1769384498030", "event_type": "price_change"}}
{"_local_timestamp": "2026-01-25T23:41:38.414793+00:00", "data": {"market": "0x120a43c108202f029133104531990a595af4f3700a92bbda4403535235bc4c82", "price_changes": [{"asset_id": "39828720608155723418301214397692986239980049531210825338778701775676917810839", "price": "0.2", "size": "200", "side": "BUY", "hash": "abc517c33b6d62d4ee17b6ccd948173840700025", "best_bid": "0.75", "best_ask": "0.77"}, {"asset_id": "8361104603056110450083567322497943223782511845432999258620698572163981630847", "price": "0.8", "size": "200", "side": "SELL", "hash": "2865139d6e06f570bd0df4d30e0683d790ec6359", "best_bid": "0.23", "best_ask": "0.25"}], "timestamp": "1769384498330", "event_type": "price_change"}}
{"_local_timestamp": "2026-01-25T23:41:59.757500+00:00", "data": {"market": "0x120a43c108202f029133104531990a595af4f3700a92bbda4403535235bc4c82", "price_changes": [{"asset_id": "39828720608155723418301214397692986239980049531210825338778701775676917810839", "price": "0.2", "size": "0", "side": "BUY", "hash": "4ac3544961035d9cf88d540c1b14f636771909f8", "best_bid": "0.75", "best_ask": "0.77"}, {"asset_id": "8361104603056110450083567322497943223782511845432999258620698572163981630847", "price": "0.8", "size": "0", "side": "SELL", "hash": "66d522f75ef85202cb35c0ad5365210eb52d2685", "best_bid": "0.23", "best_ask": "0.25"}], "timestamp": "1769384519676", "event_type": "price_change"}}
{"_local_timestamp": "2026-01-25T23:42:00.034727+00:00", "data": {"market": "0x120a43c108202f029133104531990a595af4f3700a92bbda4403535235bc4c82", "price_changes": [{"asset_id": "39828720608155723418301214397692986239980049531210825338778701775676917810839", "price": "0.21", "size": "2248", "side": "BUY", "hash": "f6c750a799a6f2d3d9c35367cb086c8d31bc047d", "best_bid": "0.75", "best_ask": "0.77"}, {"asset_id": "8361104603056110450083567322497943223782511845432999258620698572163981630847", "price": "0.79", "size": "2248", "side": "SELL", "hash": "8642ffd41f2917f37d303bc0999492f728913d04", "best_bid": "0.23", "best_ask": "0.25"}], "timestamp": "1769384519962", "event_type": "price_change"}}
{"_local_timestamp": "2026-01-25T23:42:45.437279+00:00", "data": {"market": "0x120a43c108202f029133104531990a595af4f3700a92bbda4403535235bc4c82", "price_changes": [{"asset_id": "39828720608155723418301214397692986239980049531210825338778701775676917810839", "price": "0.21", "size": "2198", "side": "BUY", "hash": "ae20bd6ed4f316f3cbb193a33ab3b5ffe989220e", "best_bid": "0.75", "best_ask": "0.77"}, {"asset_id": "8361104603056110450083567322497943223782511845432999258620698572163981630847", "price": "0.79", "size": "2198", "side": "SELL", "hash": "6c35e27f311a298ab7650c876c1bd722846f3e36", "best_bid": "0.23", "best_ask": "0.25"}], "timestamp": "1769384565223", "event_type": "price_change"}}
{"_local_timestamp": "2026-01-25T23:42:45.698251+00:00", "data": {"market": "0x120a43c108202f029133104531990a595af4f3700a92bbda4403535235bc4c82", "price_changes": [{"asset_id": "39828720608155723418301214397692986239980049531210825338778701775676917810839", "price": "0.22", "size": "50", "side": "BUY", "hash": "6c3b4ed0f89d65295769f6076174bec31ec222d8", "best_bid": "0.75", "best_ask": "0.77"}, {"asset_id": "8361104603056110450083567322497943223782511845432999258620698572163981630847", "price": "0.78", "size": "50", "side": "SELL", "hash": "0d13e07d9570e6f8db434d3f7d98fece0a88a699", "best_bid": "0.23", "best_ask": "0.25"}], "timestamp": "1769384565584", "event_type": "price_change"}}
{"_local_timestamp": "2026-01-25T23:42:47.158567+00:00", "data": {"market": "0x120a43c108202f029133104531990a595af4f3700a92bbda4403535235bc4c82", "price_changes": [{"asset_id": "39828720608155723418301214397692986239980049531210825338778701775676917810839", "price": "0.21", "size": "200", "side": "BUY", "hash": "d406723c391227e7f5b8d70f58b4acb53c9ae791", "best_bid": "0.75", "best_ask": "0.77"}, {"asset_id": "8361104603056110450083567322497943223782511845432999258620698572163981630847", "price": "0.79", "size": "200", "side": "SELL", "hash": "ff3df2346538a19c6e8ba1bd06e2ccd5b413c3bc", "best_bid": "0.23", "best_ask": "0.25"}], "timestamp": "1769384566993", "event_type": "price_change"}}
{"_local_timestamp": "2026-01-25T23:43:02.111248+00:00", "data": {"market": "0x120a43c108202f029133104531990a595af4f3700a92bbda4403535235bc4c82", "price_changes": [{"asset_id": "8361104603056110450083567322497943223782511845432999258620698572163981630847", "price": "0.22", "size": "613", "side": "BUY", "hash": "b308f55074dccd894544d021aae7d9c60bd3f46c", "best_bid": "0.23", "best_ask": "0.25"}, {"asset_id": "39828720608155723418301214397692986239980049531210825338778701775676917810839", "price": "0.78", "size": "613", "side": "SELL", "hash": "6c306be9acbe5ceb2b0eca19b68f885adcd02c63", "best_bid": "0.75", "best_ask": "0.77"}], "timestamp": "1769384582001", "event_type": "price_change"}}
{"_local_timestamp": "2026-01-25T23:43:02.136104+00:00", "data": {"market": "0x120a43c108202f029133104531990a595af4f3700a92bbda4403535235bc4c82", "price_changes": [{"asset_id": "39828720608155723418301214397692986239980049531210825338778701775676917810839", "price": "0.74", "size": "639.1", "side": "BUY", "hash": "37c154fd7e69a97521ffa9bcd92f21bb8b4629c9", "best_bid": "0.75", "best_ask": "0.77"}, {"asset_id": "8361104603056110450083567322497943223782511845432999258620698572163981630847", "price": "0.26", "size": "639.1", "side": "SELL", "hash": "2873f219db39fb1f64a060de5fd06834ab3b2978", "best_bid": "0.23", "best_ask": "0.25"}], "timestamp": "1769384582003", "event_type": "price_change"}}
{"_local_timestamp": "2026-01-25T23:43:04.132730+00:00", "data": {"market": "0x120a43c108202f029133104531990a595af4f3700a92bbda4403535235bc4c82", "price_changes": [{"asset_id": "39828720608155723418301214397692986239980049531210825338778701775676917810839", "price": "0.21", "size": "0", "side": "BUY", "hash": "ca3268de72027080388795353217d0f996705bc4", "best_bid": "0.75", "best_ask": "0.77"}, {"asset_id": "8361104603056110450083567322497943223782511845432999258620698572163981630847", "price": "0.79", "size": "0", "side": "SELL", "hash": "87c2cea3ca451a196211dbe947e4c80854d156ef", "best_bid": "0.23", "best_ask": "0.25"}], "timestamp": "1769384584023", "event_type": "price_change"}}
{"_local_timestamp": "2026-01-25T23:43:04.400965+00:00", "data": {"market": "0x120a43c108202f029133104531990a595af4f3700a92bbda4403535235bc4c82", "price_changes": [{"asset_id": "39828720608155723418301214397692986239980049531210825338778701775676917810839", "price": "0.2", "size": "200", "side": "BUY", "hash": "b1545c9a76736a867cfb3d1998e10069913d84cd", "best_bid": "0.75", "best_ask": "0.77"}, {"asset_id": "8361104603056110450083567322497943223782511845432999258620698572163981630847", "price": "0.8", "size": "200", "side": "SELL", "hash": "a790624ef584970d5365ae7adb19f39e102fd877", "best_bid": "0.23", "best_ask": "0.25"}], "timestamp": "1769384584298", "event_type": "price_change"}}
{"_local_timestamp": "2026-01-25T23:43:30.111801+00:00", "data": {"market": "0x120a43c108202f029133104531990a595af4f3700a92bbda4403535235bc4c82", "price_changes": [{"asset_id": "8361104603056110450083567322497943223782511845432999258620698572163981630847", "price": "0.23", "size": "0", "side": "BUY", "hash": "e2ab1a3ac7ac12ba134438a32e49391f2f452a62", "best_bid": "0.22", "best_ask": "0.25"}, {"asset_id": "39828720608155723418301214397692986239980049531210825338778701775676917810839", "price": "0.77", "size": "0", "side": "SELL", "hash": "acd0d677016c398623a17308ad5b616e659b7fd6", "best_bid": "0.75", "best_ask": "0.78"}], "timestamp": "1769384609980", "event_type": "price_change"}}
{"_local_timestamp": "2026-01-25T23:43:30.115308+00:00", "data": {"market": "0x120a43c108202f029133104531990a595af4f3700a92bbda4403535235bc4c82", "price_changes": [{"asset_id": "39828720608155723418301214397692986239980049531210825338778701775676917810839", "price": "0.75", "size": "0", "side": "BUY", "hash": "4a5b4c96984b450824490ac19d0d4260adf47360", "best_bid": "0.74", "best_ask": "0.78"}, {"asset_id": "8361104603056110450083567322497943223782511845432999258620698572163981630847", "price": "0.25", "size": "0", "side": "SELL", "hash": "ca61740f832292cd9fd7d5ca4346fd173747511b", "best_bid": "0.22", "best_ask": "0.26"}], "timestamp": "1769384609992", "event_type": "price_change"}}
{"_local_timestamp": "2026-01-25T23:43:30.235238+00:00", "data": {"market": "0x120a43c108202f029133104531990a595af4f3700a92bbda4403535235bc4c82", "price_changes": [{"asset_id": "39828720608155723418301214397692986239980049531210825338778701775676917810839", "price": "0.74", "size": "619.1", "side": "BUY", "hash": "40fa16e463fb5e05531978ca933b526cf1b20c42", "best_bid": "0.74", "best_ask": "0.78"}, {"asset_id": "8361104603056110450083567322497943223782511845432999258620698572163981630847", "price": "0.26", "size": "619.1", "side": "SELL", "hash": "d460cb7a01703f17a2bf863619d40aac5ba595ad", "best_bid": "0.22", "best_ask": "0.26"}], "timestamp": "1769384610098", "event_type": "price_change"}}
{"_local_timestamp": "2026-01-25T23:43:30.235813+00:00", "data": {"market": "0x120a43c108202f029133104531990a595af4f3700a92bbda4403535235bc4c82", "price_changes": [{"asset_id": "8361104603056110450083567322497943223782511845432999258620698572163981630847", "price": "0.22", "size": "593", "side": "BUY", "hash": "c6f1702c53fd17227debda11fd79616ff6bdecdb", "best_bid": "0.22", "best_ask": "0.26"}, {"asset_id": "39828720608155723418301214397692986239980049531210825338778701775676917810839", "price": "0.78", "size": "593", "side": "SELL", "hash": "3b82b2c5661df9741206bfb3742cf62ce106e70e", "best_bid": "0.74", "best_ask": "0.78"}], "timestamp": "1769384610099", "event_type": "price_change"}}
{"_local_timestamp": "2026-01-25T23:43:30.371047+00:00", "data": {"market": "0x120a43c108202f029133104531990a595af4f3700a92bbda4403535235bc4c82", "price_changes": [{"asset_id": "39828720608155723418301214397692986239980049531210825338778701775676917810839", "price": "0.74", "size": "639.1", "side": "BUY", "hash": "c5ebb7f6c2e92c5162baad9f583fd33ef17282ea", "best_bid": "0.74", "best_ask": "0.78"}, {"asset_id": "8361104603056110450083567322497943223782511845432999258620698572163981630847", "price": "0.26", "size": "639.1", "side": "SELL", "hash": "a339104c5b1493908ec446b04aa121718732dceb", "best_bid": "0.22", "best_ask": "0.26"}], "timestamp": "1769384610245", "event_type": "price_change"}}
{"_local_timestamp": "2026-01-25T23:43:30.372278+00:00", "data": {"market": "0x120a43c108202f029133104531990a595af4f3700a92bbda4403535235bc4c82", "price_changes": [{"asset_id": "8361104603056110450083567322497943223782511845432999258620698572163981630847", "price": "0.21", "size": "182.84", "side": "BUY", "hash": "cdf8cb1ec7a82c2c8f7aa12247de315b223d0d04", "best_bid": "0.22", "best_ask": "0.26"}, {"asset_id": "39828720608155723418301214397692986239980049531210825338778701775676917810839", "price": "0.79", "size": "182.84", "side": "SELL", "hash": "3f7d89504239e7df1e0a04cf914b8a0fec864052", "best_bid": "0.74", "best_ask": "0.78"}], "timestamp": "1769384610246", "event_type": "price_change"}}
{"_local_timestamp": "2026-01-25T23:43:31.213105+00:00", "data": {"market": "0x120a43c108202f029133104531990a595af4f3700a92bbda4403535235bc4c82", "price_changes": [{"asset_id": "8361104603056110450083567322497943223782511845432999258620698572163981630847", "price": "0.22", "size": "208", "side": "BUY", "hash": "f394219077aa3852cc7ce58ce60507f298204d65", "best_bid": "0.22", "best_ask": "0.26"}, {"asset_id": "39828720608155723418301214397692986239980049531210825338778701775676917810839", "price": "0.78", "size": "208", "side": "SELL", "hash": "6a0ffff59b3fe15ca8fef9c0c547179ed40f2782", "best_bid": "0.74", "best_ask": "0.78"}], "timestamp": "1769384611093", "event_type": "price_change"}}
{"_local_timestamp": "2026-01-25T23:43:31.303753+00:00", "data": {"market": "0x120a43c108202f029133104531990a595af4f3700a92bbda4403535235bc4c82", "price_changes": [{"asset_id": "39828720608155723418301214397692986239980049531210825338778701775676917810839", "price": "0.74", "size": "619.1", "side": "BUY", "hash": "7cd799a774e56c39e29b9d53ac33feb83a728701", "best_bid": "0.74", "best_ask": "0.78"}, {"asset_id": "8361104603056110450083567322497943223782511845432999258620698572163981630847", "price": "0.26", "size": "619.1", "side": "SELL", "hash": "037632496ee2033a011b41e63215a57002d0ae95", "best_bid": "0.22", "best_ask": "0.26"}], "timestamp": "1769384611180", "event_type": "price_change"}}
{"_local_timestamp": "2026-01-25T23:43:31.304297+00:00", "data": {"market": "0x120a43c108202f029133104531990a595af4f3700a92bbda4403535235bc4c82", "price_changes": [{"asset_id": "8361104603056110450083567322497943223782511845432999258620698572163981630847", "price": "0.21", "size": "162.84", "side": "BUY", "hash": "7f3f1174214a6a052b6dd8d7b797b349e5a3344d", "best_bid": "0.22", "best_ask": "0.26"}, {"asset_id": "39828720608155723418301214397692986239980049531210825338778701775676917810839", "price": "0.79", "size": "162.84", "side": "SELL", "hash": "6f0bfb215467ec3a7d2ec3891f92f01b17490f04", "best_bid": "0.74", "best_ask": "0.78"}], "timestamp": "1769384611181", "event_type": "price_change"}}
{"_local_timestamp": "2026-01-25T23:43:31.482356+00:00", "data": {"market": "0x120a43c108202f029133104531990a595af4f3700a92bbda4403535235bc4c82", "price_changes": [{"asset_id": "8361104603056110450083567322497943223782511845432999258620698572163981630847", "price": "0.21", "size": "486.84", "side": "BUY", "hash": "a38a67d96c3ef4c0b59116301e79286a8bc9f8d8", "best_bid": "0.22", "best_ask": "0.26"}, {"asset_id": "39828720608155723418301214397692986239980049531210825338778701775676917810839", "price": "0.79", "size": "486.84", "side": "SELL", "hash": "7221414e2a3973b6eae31c1b01672f8224c07283", "best_bid": "0.74", "best_ask": "0.78"}], "timestamp": "1769384611365", "event_type": "price_change"}}
{"_local_timestamp": "2026-01-25T23:43:31.542208+00:00", "data": {"market": "0x120a43c108202f029133104531990a595af4f3700a92bbda4403535235bc4c82", "price_changes": [{"asset_id": "8361104603056110450083567322497943223782511845432999258620698572163981630847", "price": "0.21", "size": "506.84", "side": "BUY", "hash": "eed4bd0ce0db57e1dbbf49aac25e99b5d3c7299c", "best_bid": "0.22", "best_ask": "0.26"}, {"asset_id": "39828720608155723418301214397692986239980049531210825338778701775676917810839", "price": "0.79", "size": "506.84", "side": "SELL", "hash": "740bbbb6b14f8f87a694f90ed13e35cfa487dd28", "best_bid": "0.74", "best_ask": "0.78"}], "timestamp": "1769384611418", "event_type": "price_change"}}
{"_local_timestamp": "2026-01-25T23:43:31.542762+00:00", "data": {"market": "0x120a43c108202f029133104531990a595af4f3700a92bbda4403535235bc4c82", "price_changes": [{"asset_id": "39828720608155723418301214397692986239980049531210825338778701775676917810839", "price": "0.73", "size": "684", "side": "BUY", "hash": "e5a2b29af84061eb878a04bfd7852b5ecc369d31", "best_bid": "0.74", "best_ask": "0.78"}, {"asset_id": "8361104603056110450083567322497943223782511845432999258620698572163981630847", "price": "0.27", "size": "684", "side": "SELL", "hash": "6b021f0158709c88cfe2ca880781f0cb309584ce", "best_bid": "0.22", "best_ask": "0.26"}], "timestamp": "1769384611418", "event_type": "price_change"}}
{"_local_timestamp": "2026-01-25T23:43:31.705365+00:00", "data": {"market": "0x120a43c108202f029133104531990a595af4f3700a92bbda4403535235bc4c82", "price_changes": [{"asset_id": "39828720608155723418301214397692986239980049531210825338778701775676917810839", "price": "0.74", "size": "234.1", "side": "BUY", "hash": "2588279b57b5d67837cee7c1964e7b76d827975f", "best_bid": "0.74", "best_ask": "0.78"}, {"asset_id": "8361104603056110450083567322497943223782511845432999258620698572163981630847", "price": "0.26", "size": "234.1", "side": "SELL", "hash": "ac57f982cfbf9136a0b8f444dadad861d11614f3", "best_bid": "0.22", "best_ask": "0.26"}], "timestamp": "1769384611582", "event_type": "price_change"}}
{"_local_timestamp": "2026-01-25T23:43:31.918109+00:00", "data": {"market": "0x120a43c108202f029133104531990a595af4f3700a92bbda4403535235bc4c82", "price_changes": [{"asset_id": "39828720608155723418301214397692986239980049531210825338778701775676917810839", "price": "0.73", "size": "1008", "side": "BUY", "hash": "31e7e49870216a960902f4367de49b687d76713b", "best_bid": "0.74", "best_ask": "0.78"}, {"asset_id": "8361104603056110450083567322497943223782511845432999258620698572163981630847", "price": "0.27", "size": "1008", "side": "SELL", "hash": "d1cb4615711c0f4aad1d6298e10258fb3d7072d7", "best_bid": "0.22", "best_ask": "0.26"}], "timestamp": "1769384611797", "event_type": "price_change"}}
{"_local_timestamp": "2026-01-25T23:43:51.074177+00:00", "data": {"market": "0x120a43c108202f029133104531990a595af4f3700a92bbda4403535235bc4c82", "price_changes": [{"asset_id": "39828720608155723418301214397692986239980049531210825338778701775676917810839", "price": "0.72", "size": "800", "side": "BUY", "hash": "1af64ca495df47c5a6bb052a5b53c3913fac0d97", "best_bid": "0.74", "best_ask": "0.78"}, {"asset_id": "8361104603056110450083567322497943223782511845432999258620698572163981630847", "price": "0.28", "size": "800", "side": "SELL", "hash": "138dfb37d3ce6c0068b7bea00fe396ae44d6fb5e", "best_bid": "0.22", "best_ask": "0.26"}], "timestamp": "1769384630931", "event_type": "price_change"}}
{"_local_timestamp": "2026-01-25T23:43:51.174011+00:00", "data": {"market": "0x120a43c108202f029133104531990a595af4f3700a92bbda4403535235bc4c82", "price_changes": [{"asset_id": "39828720608155723418301214397692986239980049531210825338778701775676917810839", "price": "0.69", "size": "10", "side": "BUY", "hash": "8ca27564910acaf78eb6ce7d827d4171f3ffc0cf", "best_bid": "0.74", "best_ask": "0.78"}, {"asset_id": "8361104603056110450083567322497943223782511845432999258620698572163981630847", "price": "0.31", "size": "10", "side": "SELL", "hash": "5061f4b30036878d13dd4f2309a1abd060f3b363", "best_bid": "0.22", "best_ask": "0.26"}], "timestamp": "1769384631030", "event_type": "price_change"}}
{"_local_timestamp": "2026-01-25T23:43:53.231384+00:00", "data": {"market": "0x120a43c108202f029133104531990a595af4f3700a92bbda4403535235bc4c82", "price_changes": [{"asset_id": "8361104603056110450083567322497943223782511845432999258620698572163981630847", "price": "0.21", "size": "182.84", "side": "BUY", "hash": "46222d64dbe6c77b7ecb433a5dda4afb118c6442", "best_bid": "0.22", "best_ask": "0.26"}, {"asset_id": "39828720608155723418301214397692986239980049531210825338778701775676917810839", "price": "0.79", "size": "182.84", "side": "SELL", "hash": "54b783ada812555fd32867e41f6a35812004bf21", "best_bid": "0.74", "best_ask": "0.78"}], "timestamp": "1769384633046", "event_type": "price_change"}}
{"_local_timestamp": "2026-01-25T23:43:53.483057+00:00", "data": {"market": "0x120a43c108202f029133104531990a595af4f3700a92bbda4403535235bc4c82", "price_changes": [{"asset_id": "8361104603056110450083567322497943223782511845432999258620698572163981630847", "price": "0.21", "size": "502.84", "side": "BUY", "hash": "77700bc6f7a34d37cc7e29cbca399d24b6b63882", "best_bid": "0.22", "best_ask": "0.26"}, {"asset_id": "39828720608155723418301214397692986239980049531210825338778701775676917810839", "price": "0.79", "size": "502.84", "side": "SELL", "hash": "a7514b087941d285f1e070e46b28595bdef188be", "best_bid": "0.74", "best_ask": "0.78"}], "timestamp": "1769384633320", "event_type": "price_change"}}
{"_local_timestamp": "2026-01-25T23:43:53.668213+00:00", "data": {"market": "0x120a43c108202f029133104531990a595af4f3700a92bbda4403535235bc4c82", "price_changes": [{"asset_id": "39828720608155723418301214397692986239980049531210825338778701775676917810839", "price": "0.73", "size": "684", "side": "BUY", "hash": "4f67b237c85a7a5a41c4e13d6ead9d28a6be5928", "best_bid": "0.74", "best_ask": "0.78"}, {"asset_id": "8361104603056110450083567322497943223782511845432999258620698572163981630847", "price": "0.27", "size": "684", "side": "SELL", "hash": "a6306c9c608c561d51ce88b3ef478e75cf34fde6", "best_bid": "0.22", "best_ask": "0.26"}], "timestamp": "1769384633533", "event_type": "price_change"}}
{"_local_timestamp": "2026-01-25T23:43:53.907775+00:00", "data": {"market": "0x120a43c108202f029133104531990a595af4f3700a92bbda4403535235bc4c82", "price_changes": [{"asset_id": "39828720608155723418301214397692986239980049531210825338778701775676917810839", "price": "0.73", "size": "1004", "side": "BUY", "hash": "c4ec2b0d9dda5849d32c0ca237c647368acc032b", "best_bid": "0.74", "best_ask": "0.78"}, {"asset_id": "8361104603056110450083567322497943223782511845432999258620698572163981630847", "price": "0.27", "size": "1004", "side": "SELL", "hash": "748f4473aa1463e1c8376cc092f7ed63fdf40fd2", "best_bid": "0.22", "best_ask": "0.26"}], "timestamp": "1769384633765", "event_type": "price_change"}}
{"_local_timestamp": "2026-01-25T23:43:54.942718+00:00", "data": {"market": "0x120a43c108202f029133104531990a595af4f3700a92bbda4403535235bc4c82", "price_changes": [{"asset_id": "39828720608155723418301214397692986239980049531210825338778701775676917810839", "price": "0.22", "size": "1958", "side": "BUY", "hash": "ba9baadbd3fd7e83a6039ed68a4d71d5cdcb3176", "best_bid": "0.74", "best_ask": "0.78"}, {"asset_id": "8361104603056110450083567322497943223782511845432999258620698572163981630847", "price": "0.78", "size": "1958", "side": "SELL", "hash": "91d3f721ebd37d26e79f420e55ee13287a634249", "best_bid": "0.22", "best_ask": "0.26"}], "timestamp": "1769384634799", "event_type": "price_change"}}
{"_local_timestamp": "2026-01-25T23:44:15.142490+00:00", "data": {"market": "0x120a43c108202f029133104531990a595af4f3700a92bbda4403535235bc4c82", "price_changes": [{"asset_id": "8361104603056110450083567322497943223782511845432999258620698572163981630847", "price": "0.21", "size": "182.84", "side": "BUY", "hash": "9b1fb5580d056cae24aeb038d8da8841a8ab731f", "best_bid": "0.22", "best_ask": "0.26"}, {"asset_id": "39828720608155723418301214397692986239980049531210825338778701775676917810839", "price": "0.79", "size": "182.84", "side": "SELL", "hash": "d7b1d755fc0020412ff84f777edcba97c7a9382a", "best_bid": "0.74", "best_ask": "0.78"}], "timestamp": "1769384654991", "event_type": "price_change"}}
{"_local_timestamp": "2026-01-25T23:44:15.361918+00:00", "data": {"market": "0x120a43c108202f029133104531990a595af4f3700a92bbda4403535235bc4c82", "price_changes": [{"asset_id": "8361104603056110450083567322497943223782511845432999258620698572163981630847", "price": "0.21", "size": "202.84", "side": "BUY", "hash": "f14df56aaf109a9bb3d9a051d03d22a3af37391f", "best_bid": "0.22", "best_ask": "0.26"}, {"asset_id": "39828720608155723418301214397692986239980049531210825338778701775676917810839", "price": "0.79", "size": "202.84", "side": "SELL", "hash": "26e12ab90e0ecf7221fc95191b87dc74fdf42a6e", "best_bid": "0.74", "best_ask": "0.78"}], "timestamp": "1769384655224", "event_type": "price_change"}}
{"_local_timestamp": "2026-01-25T23:44:19.071149+00:00", "data": {"market": "0x120a43c108202f029133104531990a595af4f3700a92bbda4403535235bc4c82", "price_changes": [{"asset_id": "39828720608155723418301214397692986239980049531210825338778701775676917810839", "price": "0.73", "size": "684", "side": "BUY", "hash": "37b4dff155f6f73023648b95c313018150dfcabb", "best_bid": "0.74", "best_ask": "0.78"}, {"asset_id": "8361104603056110450083567322497943223782511845432999258620698572163981630847", "price": "0.27", "size": "684", "side": "SELL", "hash": "035d806a4047d338dc11103e780975c6050b2ca9", "best_bid": "0.22", "best_ask": "0.26"}], "timestamp": "1769384658823", "event_type": "price_change"}}
{"_local_timestamp": "2026-01-25T23:44:19.348707+00:00", "data": {"market": "0x120a43c108202f029133104531990a595af4f3700a92bbda4403535235bc4c82", "price_changes": [{"asset_id": "39828720608155723418301214397692986239980049531210825338778701775676917810839", "price": "0.73", "size": "704", "side": "BUY", "hash": "892c0e7bef5878c1282820f9288c27e3fbbbc75d", "best_bid": "0.74", "best_ask": "0.78"}, {"asset_id": "8361104603056110450083567322497943223782511845432999258620698572163981630847", "price": "0.27", "size": "704", "side": "SELL", "hash": "6ee6523f2321605b51544ec8c4684a7a4775c146", "best_bid": "0.22", "best_ask": "0.26"}], "timestamp": "1769384659052", "event_type": "price_change"}}
{"_local_timestamp": "2026-01-25T23:44:21.081420+00:00", "data": {"market": "0x120a43c108202f029133104531990a595af4f3700a92bbda4403535235bc4c82", "price_changes": [{"asset_id": "39828720608155723418301214397692986239980049531210825338778701775676917810839", "price": "0.74", "size": "254.1", "side": "BUY", "hash": "bf102b0f1c3c1647ad7ef2a3eb869da403c9de73", "best_bid": "0.74", "best_ask": "0.78"}, {"asset_id": "8361104603056110450083567322497943223782511845432999258620698572163981630847", "price": "0.26", "size": "254.1", "side": "SELL", "hash": "e1ce7387eb0fbd7837134a2325614eb16f8fac00", "best_bid": "0.22", "best_ask": "0.26"}], "timestamp": "1769384660632", "event_type": "price_change"}}
{"_local_timestamp": "2026-01-25T23:44:21.090359+00:00", "data": {"market": "0x120a43c108202f029133104531990a595af4f3700a92bbda4403535235bc4c82", "price_changes": [{"asset_id": "8361104603056110450083567322497943223782511845432999258620698572163981630847", "price": "0.22", "size": "228", "side": "BUY", "hash": "7bd28caa94a7cde255e9e04bfc0c66376c25f299", "best_bid": "0.22", "best_ask": "0.26"}, {"asset_id": "39828720608155723418301214397692986239980049531210825338778701775676917810839", "price": "0.78", "size": "228", "side": "SELL", "hash": "7bb8b34002c50a2b9967c21e98c054704b028d78", "best_bid": "0.74", "best_ask": "0.78"}], "timestamp": "1769384660633", "event_type": "price_change"}}
{"_local_timestamp": "2026-01-25T23:44:31.759751+00:00", "data": {"market": "0x120a43c108202f029133104531990a595af4f3700a92bbda4403535235bc4c82", "price_changes": [{"asset_id": "39828720608155723418301214397692986239980049531210825338778701775676917810839", "price": "0.2", "size": "0", "side": "BUY", "hash": "8973f128c09ed395543de1e2093b2c33751b3e40", "best_bid": "0.74", "best_ask": "0.78"}, {"asset_id": "8361104603056110450083567322497943223782511845432999258620698572163981630847", "price": "0.8", "size": "0", "side": "SELL", "hash": "82dbc0d7fda8086c3f40e6f3dd8f022293a32241", "best_bid": "0.22", "best_ask": "0.26"}], "timestamp": "1769384671474", "event_type": "price_change"}}
{"_local_timestamp": "2026-01-25T23:44:32.050075+00:00", "data": {"market": "0x120a43c108202f029133104531990a595af4f3700a92bbda4403535235bc4c82", "price_changes": [{"asset_id": "39828720608155723418301214397692986239980049531210825338778701775676917810839", "price": "0.22", "size": "2158", "side": "BUY", "hash": "bd340046c6afe2f1a657870436ee3507f6078668", "best_bid": "0.74", "best_ask": "0.78"}, {"asset_id": "8361104603056110450083567322497943223782511845432999258620698572163981630847", "price": "0.78", "size": "2158", "side": "SELL", "hash": "65d36b40ad2bdb496ec63796f81cee80a1169f84", "best_bid": "0.22", "best_ask": "0.26"}], "timestamp": "1769384671744", "event_type": "price_change"}}
{"_local_timestamp": "2026-01-25T23:44:32.613809+00:00", "data": {"market": "0x120a43c108202f029133104531990a595af4f3700a92bbda4403535235bc4c82", "price_changes": [{"asset_id": "39828720608155723418301214397692986239980049531210825338778701775676917810839", "price": "0.22", "size": "250", "side": "BUY", "hash": "ebd3da4a97962ff52849a53d3d421cd64f87917c", "best_bid": "0.74", "best_ask": "0.78"}, {"asset_id": "8361104603056110450083567322497943223782511845432999258620698572163981630847", "price": "0.78", "size": "250", "side": "SELL", "hash": "f938229dec9c0ffd80a89b97f286c5f73295795b", "best_bid": "0.22", "best_ask": "0.26"}], "timestamp": "1769384672292", "event_type": "price_change"}}
{"_local_timestamp": "2026-01-25T23:44:54.699872+00:00", "data": {"market": "0x120a43c108202f029133104531990a595af4f3700a92bbda4403535235bc4c82", "price_changes": [{"asset_id": "39828720608155723418301214397692986239980049531210825338778701775676917810839", "price": "0.22", "size": "50", "side": "BUY", "hash": "b70d6cd587845346ea54ed43a0b199d65b3c70f9", "best_bid": "0.74", "best_ask": "0.78"}, {"asset_id": "8361104603056110450083567322497943223782511845432999258620698572163981630847", "price": "0.78", "size": "50", "side": "SELL", "hash": "c9f9ddbc51afb9a525b68cfcd8ae43e28b45fb59", "best_bid": "0.22", "best_ask": "0.26"}], "timestamp": "1769384694598", "event_type": "price_change"}}
{"_local_timestamp": "2026-01-25T23:44:54.964496+00:00", "data": {"market": "0x120a43c108202f029133104531990a595af4f3700a92bbda4403535235bc4c82", "price_changes": [{"asset_id": "39828720608155723418301214397692986239980049531210825338778701775676917810839", "price": "0.2", "size": "200", "side": "BUY", "hash": "7c613723cc9e2295329d120bb6f73066ce290aa6", "best_bid": "0.74", "best_ask": "0.78"}, {"asset_id": "8361104603056110450083567322497943223782511845432999258620698572163981630847", "price": "0.8", "size": "200", "side": "SELL", "hash": "ab712095b16e470dd066646506005d361dabf91d", "best_bid": "0.22", "best_ask": "0.26"}], "timestamp": "1769384694857", "event_type": "price_change"}}
{"_local_timestamp": "2026-01-25T23:44:57.824666+00:00", "data": {"market": "0x120a43c108202f029133104531990a595af4f3700a92bbda4403535235bc4c82", "price_changes": [{"asset_id": "39828720608155723418301214397692986239980049531210825338778701775676917810839", "price": "0.22", "size": "0", "side": "BUY", "hash": "0b5078fec51f1d04e5d404934104ab3cb7df6c81", "best_bid": "0.74", "best_ask": "0.78"}, {"asset_id": "8361104603056110450083567322497943223782511845432999258620698572163981630847", "price": "0.78", "size": "0", "side": "SELL", "hash": "04a7e07085d461677fe0dd9f2bb7412b94df4eab", "best_bid": "0.22", "best_ask": "0.26"}], "timestamp": "1769384697732", "event_type": "price_change"}}
{"_local_timestamp": "2026-01-25T23:44:58.307991+00:00", "data": {"market": "0x120a43c108202f029133104531990a595af4f3700a92bbda4403535235bc4c82", "price_changes": [{"asset_id": "39828720608155723418301214397692986239980049531210825338778701775676917810839", "price": "0.24", "size": "300", "side": "BUY", "hash": "b2f4a1ba41dc4237b0c80415c9b94d946d6d750d", "best_bid": "0.74", "best_ask": "0.78"}, {"asset_id": "8361104603056110450083567322497943223782511845432999258620698572163981630847", "price": "0.76", "size": "300", "side": "SELL", "hash": "11bff5804489f5400d8a033fdf4a1dd6cedb98ed", "best_bid": "0.22", "best_ask": "0.26"}], "timestamp": "1769384698215", "event_type": "price_change"}}
{"_local_timestamp": "2026-01-25T23:45:42.760631+00:00", "data": {"market": "0x120a43c108202f029133104531990a595af4f3700a92bbda4403535235bc4c82", "price_changes": [{"asset_id": "39828720608155723418301214397692986239980049531210825338778701775676917810839", "price": "0.21", "size": "1998", "side": "BUY", "hash": "c6e72b21da6bc0a29507537569ecb2ac4f8b38b5", "best_bid": "0.74", "best_ask": "0.78"}, {"asset_id": "8361104603056110450083567322497943223782511845432999258620698572163981630847", "price": "0.79", "size": "1998", "side": "SELL", "hash": "a4c15b3f70acbab4b5d32a15036d07886aaa645a", "best_bid": "0.22", "best_ask": "0.26"}], "timestamp": "1769384742698", "event_type": "price_change"}}
{"_local_timestamp": "2026-01-25T23:45:48.570721+00:00", "data": {"market": "0x120a43c108202f029133104531990a595af4f3700a92bbda4403535235bc4c82", "price_changes": [{"asset_id": "39828720608155723418301214397692986239980049531210825338778701775676917810839", "price": "0.17", "size": "0", "side": "BUY", "hash": "2d65a75bbdfc8445db3ede5cbce7763287ee4061", "best_bid": "0.74", "best_ask": "0.78"}, {"asset_id": "8361104603056110450083567322497943223782511845432999258620698572163981630847", "price": "0.83", "size": "0", "side": "SELL", "hash": "ad6e3b91e505bdaf2d0393e59d0f5bd4db35a3c2", "best_bid": "0.22", "best_ask": "0.26"}], "timestamp": "1769384748505", "event_type": "price_change"}}
{"_local_timestamp": "2026-01-25T23:45:48.614955+00:00", "data": {"market": "0x120a43c108202f029133104531990a595af4f3700a92bbda4403535235bc4c82", "price_changes": [{"asset_id": "39828720608155723418301214397692986239980049531210825338778701775676917810839", "price": "0.28", "size": "7", "side": "BUY", "hash": "d5fe596a25d481e6da4be0ac2f53072261a59974", "best_bid": "0.74", "best_ask": "0.78"}, {"asset_id": "8361104603056110450083567322497943223782511845432999258620698572163981630847", "price": "0.72", "size": "7", "side": "SELL", "hash": "2574a3f562d9c4473105a4e7c67f718336cfc0b6", "best_bid": "0.22", "best_ask": "0.26"}], "timestamp": "1769384748551", "event_type": "price_change"}}
{"_local_timestamp": "2026-01-25T23:45:56.587143+00:00", "data": {"market": "0x120a43c108202f029133104531990a595af4f3700a92bbda4403535235bc4c82", "price_changes": [{"asset_id": "39828720608155723418301214397692986239980049531210825338778701775676917810839", "price": "0.24", "size": "50", "side": "BUY", "hash": "1e365634e9078a57091c2ad562b996b5f1aae7ae", "best_bid": "0.74", "best_ask": "0.78"}, {"asset_id": "8361104603056110450083567322497943223782511845432999258620698572163981630847", "price": "0.76", "size": "50", "side": "SELL", "hash": "af1144aca5fa56f0993c5b3a5ebf3118b73ac68c", "best_bid": "0.22", "best_ask": "0.26"}], "timestamp": "1769384756086", "event_type": "price_change"}}
{"_local_timestamp": "2026-01-25T23:45:56.598232+00:00", "data": {"market": "0x120a43c108202f029133104531990a595af4f3700a92bbda4403535235bc4c82", "price_changes": [{"asset_id": "8361104603056110450083567322497943223782511845432999258620698572163981630847", "price": "0.02", "size": "600", "side": "BUY", "hash": "2606e12b6b1766fd3f0cde676821dc0f2dc7883b", "best_bid": "0.22", "best_ask": "0.26"}, {"asset_id": "39828720608155723418301214397692986239980049531210825338778701775676917810839", "price": "0.98", "size": "600", "side": "SELL", "hash": "a48fbc1f436d8c5a70c9fc8edd3ecd9fc2f834f2", "best_bid": "0.74", "best_ask": "0.78"}], "timestamp": "1769384756129", "event_type": "price_change"}}
{"_local_timestamp": "2026-01-25T23:46:01.785185+00:00", "data": {"market": "0x120a43c108202f029133104531990a595af4f3700a92bbda4403535235bc4c82", "price_changes": [{"asset_id": "39828720608155723418301214397692986239980049531210825338778701775676917810839", "price": "0.2", "size": "0", "side": "BUY", "hash": "e261b999f697580d947982846297faf23c0c15e7", "best_bid": "0.74", "best_ask": "0.78"}, {"asset_id": "8361104603056110450083567322497943223782511845432999258620698572163981630847", "price": "0.8", "size": "0", "side": "SELL", "hash": "8f4123731bcfd91c6c3aa338ae62b2ce47fc68cd", "best_bid": "0.22", "best_ask": "0.26"}], "timestamp": "1769384761711", "event_type": "price_change"}}
{"_local_timestamp": "2026-01-25T23:46:02.296359+00:00", "data": {"market": "0x120a43c108202f029133104531990a595af4f3700a92bbda4403535235bc4c82", "price_changes": [{"asset_id": "39828720608155723418301214397692986239980049531210825338778701775676917810839", "price": "0.21", "size": "2198", "side": "BUY", "hash": "7164b9bfbea155be7484e92b05aaedfa74492c07", "best_bid": "0.74", "best_ask": "0.78"}, {"asset_id": "8361104603056110450083567322497943223782511845432999258620698572163981630847", "price": "0.79", "size": "2198", "side": "SELL", "hash": "c9d10546a9e37855ed8910f99e595e832288b6bd", "best_bid": "0.22", "best_ask": "0.26"}], "timestamp": "1769384762221", "event_type": "price_change"}}
{"_local_timestamp": "2026-01-25T23:46:10.586487+00:00", "data": {"market": "0x120a43c108202f029133104531990a595af4f3700a92bbda4403535235bc4c82", "price_changes": [{"asset_id": "39828720608155723418301214397692986239980049531210825338778701775676917810839", "price": "0.21", "size": "200", "side": "BUY", "hash": "a5ea463ed5a4d526824a3805433516e892dac662", "best_bid": "0.74", "best_ask": "0.78"}, {"asset_id": "8361104603056110450083567322497943223782511845432999258620698572163981630847", "price": "0.79", "size": "200", "side": "SELL", "hash": "262ea17a1e12ccc131f8a19fefd1ff5a69427952", "best_bid": "0.22", "best_ask": "0.26"}], "timestamp": "1769384770464", "event_type": "price_change"}}
{"_local_timestamp": "2026-01-25T23:46:22.310083+00:00", "data": {"market": "0x120a43c108202f029133104531990a595af4f3700a92bbda4403535235bc4c82", "price_changes": [{"asset_id": "8361104603056110450083567322497943223782511845432999258620698572163981630847", "price": "0.03", "size": "330.73", "side": "BUY", "hash": "1f68de4e8c760996d487db555f2524708419cfb4", "best_bid": "0.22", "best_ask": "0.26"}, {"asset_id": "39828720608155723418301214397692986239980049531210825338778701775676917810839", "price": "0.97", "size": "330.73", "side": "SELL", "hash": "a82b0719dc31efc57924e164592da33bd07dfb72", "best_bid": "0.74", "best_ask": "0.78"}], "timestamp": "1769384782228", "event_type": "price_change"}}
{"_local_timestamp": "2026-01-25T23:46:22.310691+00:00", "data": {"market": "0x120a43c108202f029133104531990a595af4f3700a92bbda4403535235bc4c82", "price_changes": [{"asset_id": "39828720608155723418301214397692986239980049531210825338778701775676917810839", "price": "0.07", "size": "300", "side": "BUY", "hash": "f49e3527e63ea9d0e9915c2c9a3c0afc3b2e5775", "best_bid": "0.74", "best_ask": "0.78"}, {"asset_id": "8361104603056110450083567322497943223782511845432999258620698572163981630847", "price": "0.93", "size": "300", "side": "SELL", "hash": "5b06ff8bfa18fa73a93c8f0ccd13b1d1e9d5fb05", "best_bid": "0.22", "best_ask": "0.26"}], "timestamp": "1769384782230", "event_type": "price_change"}}
{"_local_timestamp": "2026-01-25T23:46:23.631681+00:00", "data": {"market": "0x120a43c108202f029133104531990a595af4f3700a92bbda4403535235bc4c82", "price_changes": [{"asset_id": "8361104603056110450083567322497943223782511845432999258620698572163981630847", "price": "0.02", "size": "0", "side": "BUY", "hash": "1e4f5632a072fb9db16098e15eeeb335a6e4a719", "best_bid": "0.22", "best_ask": "0.26"}, {"asset_id": "39828720608155723418301214397692986239980049531210825338778701775676917810839", "price": "0.98", "size": "0", "side": "SELL", "hash": "5d8d52fd928a431709829b3c436fac26748d2c08", "best_bid": "0.74", "best_ask": "0.78"}], "timestamp": "1769384783562", "event_type": "price_change"}}
{"_local_timestamp": "2026-01-25T23:46:43.139338+00:00", "data": {"market": "0x120a43c108202f029133104531990a595af4f3700a92bbda4403535235bc4c82", "price_changes": [{"asset_id": "39828720608155723418301214397692986239980049531210825338778701775676917810839", "price": "0.21", "size": "0", "side": "BUY", "hash": "8a6af84a218126ee25bf1e4bbed32e5759817ff3", "best_bid": "0.74", "best_ask": "0.78"}, {"asset_id": "8361104603056110450083567322497943223782511845432999258620698572163981630847", "price": "0.79", "size": "0", "side": "SELL", "hash": "45d42dc3c38c9059e419f8ba45be5a28e07128ef", "best_bid": "0.22", "best_ask": "0.26"}], "timestamp": "1769384803017", "event_type": "price_change"}}
{"_local_timestamp": "2026-01-25T23:46:43.501948+00:00", "data": {"market": "0x120a43c108202f029133104531990a595af4f3700a92bbda4403535235bc4c82", "price_changes": [{"asset_id": "39828720608155723418301214397692986239980049531210825338778701775676917810839", "price": "0.2", "size": "200", "side": "BUY", "hash": "def59dbb54ba0825fbec29e4b2644daed8975199", "best_bid": "0.74", "best_ask": "0.78"}, {"asset_id": "8361104603056110450083567322497943223782511845432999258620698572163981630847", "price": "0.8", "size": "200", "side": "SELL", "hash": "401379911806f751f71f0bdb6fc5aa7c2ce77363", "best_bid": "0.22", "best_ask": "0.26"}], "timestamp": "1769384803333", "event_type": "price_change"}}
{"_local_timestamp": "2026-01-25T23:46:45.931193+00:00", "data": {"market": "0x120a43c108202f029133104531990a595af4f3700a92bbda4403535235bc4c82", "price_changes": [{"asset_id": "39828720608155723418301214397692986239980049531210825338778701775676917810839", "price": "0.08", "size": "100", "side": "BUY", "hash": "15fdff5dd272b5dd05ef5446a92fe11ac0307765", "best_bid": "0.74", "best_ask": "0.78"}, {"asset_id": "8361104603056110450083567322497943223782511845432999258620698572163981630847", "price": "0.92", "size": "100", "side": "SELL", "hash": "b58ee2c4bf69d1aa59567ac68a2948b781633333", "best_bid": "0.22", "best_ask": "0.26"}], "timestamp": "1769384805861", "event_type": "price_change"}}
{"_local_timestamp": "2026-01-25T23:46:46.204086+00:00", "data": {"market": "0x120a43c108202f029133104531990a595af4f3700a92bbda4403535235bc4c82", "price_changes": [{"asset_id": "8361104603056110450083567322497943223782511845432999258620698572163981630847", "price": "0.03", "size": "930.73", "side": "BUY", "hash": "f4b4cb136464d86d30c8abb4748e4f8682b442b5", "best_bid": "0.22", "best_ask": "0.26"}, {"asset_id": "39828720608155723418301214397692986239980049531210825338778701775676917810839", "price": "0.97", "size": "930.73", "side": "SELL", "hash": "a7e49e674eefc8630c049e2ba4e52390122c09d9", "best_bid": "0.74", "best_ask": "0.78"}], "timestamp": "1769384806134", "event_type": "price_change"}}
{"_local_timestamp": "2026-01-25T23:46:46.204711+00:00", "data": {"market": "0x120a43c108202f029133104531990a595af4f3700a92bbda4403535235bc4c82", "price_changes": [{"asset_id": "39828720608155723418301214397692986239980049531210825338778701775676917810839", "price": "0.07", "size": "600", "side": "BUY", "hash": "895d382931e809e4038cf7819761fde44bf1b262", "best_bid": "0.74", "best_ask": "0.78"}, {"asset_id": "8361104603056110450083567322497943223782511845432999258620698572163981630847", "price": "0.93", "size": "600", "side": "SELL", "hash": "3346b27fc74426053ea17e73d1f40144e6317fa3", "best_bid": "0.22", "best_ask": "0.26"}], "timestamp": "1769384806135", "event_type": "price_change"}}
{"_local_timestamp": "2026-01-25T23:46:50.364844+00:00", "data": {"market": "0x120a43c108202f029133104531990a595af4f3700a92bbda4403535235bc4c82", "price_changes": [{"asset_id": "39828720608155723418301214397692986239980049531210825338778701775676917810839", "price": "0.23", "size": "1826", "side": "BUY", "hash": "3da71bf857bb7a445ae86b23fb979d0f699ca4cc", "best_bid": "0.74", "best_ask": "0.78"}, {"asset_id": "8361104603056110450083567322497943223782511845432999258620698572163981630847", "price": "0.77", "size": "1826", "side": "SELL", "hash": "4390b86e3a08f4e3d24f91bded1dd2c03921b626", "best_bid": "0.22", "best_ask": "0.26"}], "timestamp": "1769384810271", "event_type": "price_change"}}
{"_local_timestamp": "2026-01-25T23:47:27.108954+00:00", "data": {"market": "0x120a43c108202f029133104531990a595af4f3700a92bbda4403535235bc4c82", "price_changes": [{"asset_id": "39828720608155723418301214397692986239980049531210825338778701775676917810839", "price": "0.2", "size": "0", "side": "BUY", "hash": "ceae4e67350c4a06641722366a12e4cfa3d39d91", "best_bid": "0.74", "best_ask": "0.78"}, {"asset_id": "8361104603056110450083567322497943223782511845432999258620698572163981630847", "price": "0.8", "size": "0", "side": "SELL", "hash": "a7609c6456792475a9c9f7173527c5d666c436ea", "best_bid": "0.22", "best_ask": "0.26"}], "timestamp": "1769384847006", "event_type": "price_change"}}
{"_local_timestamp": "2026-01-25T23:47:27.371157+00:00", "data": {"market": "0x120a43c108202f029133104531990a595af4f3700a92bbda4403535235bc4c82", "price_changes": [{"asset_id": "39828720608155723418301214397692986239980049531210825338778701775676917810839", "price": "0.23", "size": "2026", "side": "BUY", "hash": "6c3137cfb667dbf478010fd9a0abbb4d2aefda19", "best_bid": "0.74", "best_ask": "0.78"}, {"asset_id": "8361104603056110450083567322497943223782511845432999258620698572163981630847", "price": "0.77", "size": "2026", "side": "SELL", "hash": "d2f014179888ac9b1a64ee90cd65fdf258a8ddff", "best_bid": "0.22", "best_ask": "0.26"}], "timestamp": "1769384847309", "event_type": "price_change"}}
{"_local_timestamp": "2026-01-25T23:47:55.592247+00:00", "data": {"market": "0x120a43c108202f029133104531990a595af4f3700a92bbda4403535235bc4c82", "price_changes": [{"asset_id": "39828720608155723418301214397692986239980049531210825338778701775676917810839", "price": "0.23", "size": "200", "side": "BUY", "hash": "32c7fa9466315fd3b294e9f86b6ae1b16f52713a", "best_bid": "0.74", "best_ask": "0.78"}, {"asset_id": "8361104603056110450083567322497943223782511845432999258620698572163981630847", "price": "0.77", "size": "200", "side": "SELL", "hash": "cff4980daff77c3e221ab486fa6676ef4b187ff6", "best_bid": "0.22", "best_ask": "0.26"}], "timestamp": "1769384875413", "event_type": "price_change"}}
{"_local_timestamp": "2026-01-25T23:48:15.085753+00:00", "data": {"market": "0x120a43c108202f029133104531990a595af4f3700a92bbda4403535235bc4c82", "price_changes": [{"asset_id": "39828720608155723418301214397692986239980049531210825338778701775676917810839", "price": "0.23", "size": "0", "side": "BUY", "hash": "cac006d4c42329062294acbf2295274bafd99df7", "best_bid": "0.74", "best_ask": "0.78"}, {"asset_id": "8361104603056110450083567322497943223782511845432999258620698572163981630847", "price": "0.77", "size": "0", "side": "SELL", "hash": "aaa9e282489a150c4b454a1a1dfa3f07b6f5a117", "best_bid": "0.22", "best_ask": "0.26"}], "timestamp": "1769384895022", "event_type": "price_change"}}
{"_local_timestamp": "2026-01-25T23:48:15.382681+00:00", "data": {"market": "0x120a43c108202f029133104531990a595af4f3700a92bbda4403535235bc4c82", "price_changes": [{"asset_id": "39828720608155723418301214397692986239980049531210825338778701775676917810839", "price": "0.2", "size": "200", "side": "BUY", "hash": "6ff01816c3818f260f2383cbba839abaeed16e8c", "best_bid": "0.74", "best_ask": "0.78"}, {"asset_id": "8361104603056110450083567322497943223782511845432999258620698572163981630847", "price": "0.8", "size": "200", "side": "SELL", "hash": "3bc456465e6e0c2985e80c4c7ad141de2889b9f7", "best_bid": "0.22", "best_ask": "0.26"}], "timestamp": "1769384895309", "event_type": "price_change"}}
{"_local_timestamp": "2026-01-25T23:48:30.672310+00:00", "data": {"market": "0x120a43c108202f029133104531990a595af4f3700a92bbda4403535235bc4c82", "price_changes": [{"asset_id": "8361104603056110450083567322497943223782511845432999258620698572163981630847", "price": "0.01", "size": "2460", "side": "BUY", "hash": "8cda81abf358c581e64078434f492ee5fb0cf0fe", "best_bid": "0.22", "best_ask": "0.26"}, {"asset_id": "39828720608155723418301214397692986239980049531210825338778701775676917810839", "price": "0.99", "size": "2460", "side": "SELL", "hash": "6fc6e0143e547d5003d6cb13e5c73bc4dfe056cb", "best_bid": "0.74", "best_ask": "0.78"}], "timestamp": "1769384910595", "event_type": "price_change"}}
{"_local_timestamp": "2026-01-25T23:48:30.673055+00:00", "data": {"market": "0x120a43c108202f029133104531990a595af4f3700a92bbda4403535235bc4c82", "price_changes": [{"asset_id": "8361104603056110450083567322497943223782511845432999258620698572163981630847", "price": "0.03", "size": "900", "side": "BUY", "hash": "8cda81abf358c581e64078434f492ee5fb0cf0fe", "best_bid": "0.22", "best_ask": "0.26"}, {"asset_id": "39828720608155723418301214397692986239980049531210825338778701775676917810839", "price": "0.97", "size": "900", "side": "SELL", "hash": "6fc6e0143e547d5003d6cb13e5c73bc4dfe056cb", "best_bid": "0.74", "best_ask": "0.78"}], "timestamp": "1769384910595", "event_type": "price_change"}}
{"_local_timestamp": "2026-01-25T23:48:31.531863+00:00", "data": {"market": "0x120a43c108202f029133104531990a595af4f3700a92bbda4403535235bc4c82", "price_changes": [{"asset_id": "8361104603056110450083567322497943223782511845432999258620698572163981630847", "price": "0.04", "size": "21.41", "side": "BUY", "hash": "819f08bbed14e318e33d4a7188481c46d9692403", "best_bid": "0.22", "best_ask": "0.26"}, {"asset_id": "39828720608155723418301214397692986239980049531210825338778701775676917810839", "price": "0.96", "size": "21.41", "side": "SELL", "hash": "806e6eb1f1df309921f418cfe90ca29b2f2f84bc", "best_bid": "0.74", "best_ask": "0.78"}], "timestamp": "1769384911457", "event_type": "price_change"}}
{"_local_timestamp": "2026-01-25T23:48:31.537526+00:00", "data": {"market": "0x120a43c108202f029133104531990a595af4f3700a92bbda4403535235bc4c82", "price_changes": [{"asset_id": "8361104603056110450083567322497943223782511845432999258620698572163981630847", "price": "0.02", "size": "7.16", "side": "BUY", "hash": "0b76febc971a537cffa64b887ba0ab823b82f683", "best_bid": "0.22", "best_ask": "0.26"}, {"asset_id": "39828720608155723418301214397692986239980049531210825338778701775676917810839", "price": "0.98", "size": "7.16", "side": "SELL", "hash": "37b17f20e60003ef4760d7b60a794accf2c8d76d", "best_bid": "0.74", "best_ask": "0.78"}], "timestamp": "1769384911458", "event_type": "price_change"}}
{"_local_timestamp": "2026-01-25T23:49:08.157665+00:00", "data": {"market": "0x120a43c108202f029133104531990a595af4f3700a92bbda4403535235bc4c82", "price_changes": [{"asset_id": "39828720608155723418301214397692986239980049531210825338778701775676917810839", "price": "0.19", "size": "2210", "side": "BUY", "hash": "303a38c0ed22c2e400660e2e6ae7201b6731e453", "best_bid": "0.74", "best_ask": "0.78"}, {"asset_id": "8361104603056110450083567322497943223782511845432999258620698572163981630847", "price": "0.81", "size": "2210", "side": "SELL", "hash": "3e05280dee9301624defac254c68f24152979b9e", "best_bid": "0.22", "best_ask": "0.26"}], "timestamp": "1769384948082", "event_type": "price_change"}}
{"_local_timestamp": "2026-01-25T23:49:39.368704+00:00", "data": {"market": "0x120a43c108202f029133104531990a595af4f3700a92bbda4403535235bc4c82", "price_changes": [{"asset_id": "39828720608155723418301214397692986239980049531210825338778701775676917810839", "price": "0.14", "size": "0", "side": "BUY", "hash": "b34209dc69d94eaa0ee145dcaff753add30a65e4", "best_bid": "0.74", "best_ask": "0.78"}, {"asset_id": "8361104603056110450083567322497943223782511845432999258620698572163981630847", "price": "0.86", "size": "0", "side": "SELL", "hash": "bbb1f216268ac489375b067934b3e724f9a8d7f2", "best_bid": "0.22", "best_ask": "0.26"}], "timestamp": "1769384979299", "event_type": "price_change"}}
{"_local_timestamp": "2026-01-25T23:49:39.728817+00:00", "data": {"market": "0x120a43c108202f029133104531990a595af4f3700a92bbda4403535235bc4c82", "price_changes": [{"asset_id": "39828720608155723418301214397692986239980049531210825338778701775676917810839", "price": "0.19", "size": "2260", "side": "BUY", "hash": "a71aaffed714014b0f74ebd0f0495bb870c0c8d0", "best_bid": "0.74", "best_ask": "0.78"}, {"asset_id": "8361104603056110450083567322497943223782511845432999258620698572163981630847", "price": "0.81", "size": "2260", "side": "SELL", "hash": "915b0a1e79ed70294c545872c40ab368781262c5", "best_bid": "0.22", "best_ask": "0.26"}], "timestamp": "1769384979617", "event_type": "price_change"}}
{"_local_timestamp": "2026-01-25T23:49:41.741756+00:00", "data": {"market": "0x120a43c108202f029133104531990a595af4f3700a92bbda4403535235bc4c82", "price_changes": [{"asset_id": "39828720608155723418301214397692986239980049531210825338778701775676917810839", "price": "0.24", "size": "0", "side": "BUY", "hash": "91608e51f868757a67a3a1572377154be88a1368", "best_bid": "0.74", "best_ask": "0.78"}, {"asset_id": "8361104603056110450083567322497943223782511845432999258620698572163981630847", "price": "0.76", "size": "0", "side": "SELL", "hash": "a6883611d5010295cb75f63f5695cad484f6f7e7", "best_bid": "0.22", "best_ask": "0.26"}], "timestamp": "1769384981645", "event_type": "price_change"}}
{"_local_timestamp": "2026-01-25T23:49:42.375721+00:00", "data": {"market": "0x120a43c108202f029133104531990a595af4f3700a92bbda4403535235bc4c82", "price_changes": [{"asset_id": "39828720608155723418301214397692986239980049531210825338778701775676917810839", "price": "0.23", "size": "50", "side": "BUY", "hash": "62b164002efdad263be69b034047f35e0d7e16e5", "best_bid": "0.74", "best_ask": "0.78"}, {"asset_id": "8361104603056110450083567322497943223782511845432999258620698572163981630847", "price": "0.77", "size": "50", "side": "SELL", "hash": "01b05d0c7ccec87c3f24529d33e669a53b49d6ab", "best_bid": "0.22", "best_ask": "0.26"}], "timestamp": "1769384982212", "event_type": "price_change"}}
{"_local_timestamp": "2026-01-25T23:49:51.202152+00:00", "data": {"market": "0x120a43c108202f029133104531990a595af4f3700a92bbda4403535235bc4c82", "price_changes": [{"asset_id": "39828720608155723418301214397692986239980049531210825338778701775676917810839", "price": "0.19", "size": "50", "side": "BUY", "hash": "d83f2e0a85f7176ef18eac31d0e68e267386430e", "best_bid": "0.74", "best_ask": "0.78"}, {"asset_id": "8361104603056110450083567322497943223782511845432999258620698572163981630847", "price": "0.81", "size": "50", "side": "SELL", "hash": "caf7af6c641cd2ab3ba196cfafc95fefe66c207d", "best_bid": "0.22", "best_ask": "0.26"}], "timestamp": "1769384991045", "event_type": "price_change"}}
{"_local_timestamp": "2026-01-25T23:49:57.383886+00:00", "data": {"market": "0x120a43c108202f029133104531990a595af4f3700a92bbda4403535235bc4c82", "price_changes": [{"asset_id": "39828720608155723418301214397692986239980049531210825338778701775676917810839", "price": "0.21", "size": "1998", "side": "BUY", "hash": "139a77239ca9c81ba4e6db1c8065e182a0f66fc1", "best_bid": "0.74", "best_ask": "0.78"}, {"asset_id": "8361104603056110450083567322497943223782511845432999258620698572163981630847", "price": "0.79", "size": "1998", "side": "SELL", "hash": "e2b2748f16bae93f3ee01c29fc4d48024cd44b00", "best_bid": "0.22", "best_ask": "0.26"}], "timestamp": "1769384997303", "event_type": "price_change"}}
{"_local_timestamp": "2026-01-25T23:50:02.772197+00:00", "data": {"market": "0x120a43c108202f029133104531990a595af4f3700a92bbda4403535235bc4c82", "price_changes": [{"asset_id": "39828720608155723418301214397692986239980049531210825338778701775676917810839", "price": "0.18", "size": "0", "side": "BUY", "hash": "d79910e1a1d78e54815637c2a78c602d3d148206", "best_bid": "0.74", "best_ask": "0.78"}, {"asset_id": "8361104603056110450083567322497943223782511845432999258620698572163981630847", "price": "0.82", "size": "0", "side": "SELL", "hash": "86e9396986447e61b4a0703280529e54c209aec1", "best_bid": "0.22", "best_ask": "0.26"}], "timestamp": "1769385002278", "event_type": "price_change"}}
{"_local_timestamp": "2026-01-25T23:50:17.486235+00:00", "data": {"market": "0x120a43c108202f029133104531990a595af4f3700a92bbda4403535235bc4c82", "price_changes": [{"asset_id": "39828720608155723418301214397692986239980049531210825338778701775676917810839", "price": "0.19", "size": "0", "side": "BUY", "hash": "2b0b4e9d05d2f23cfc17c5a4655002e769444963", "best_bid": "0.74", "best_ask": "0.78"}, {"asset_id": "8361104603056110450083567322497943223782511845432999258620698572163981630847", "price": "0.81", "size": "0", "side": "SELL", "hash": "e0baea2fdea5ee14c80ccf30867eabde4b402d30", "best_bid": "0.22", "best_ask": "0.26"}], "timestamp": "1769385017383", "event_type": "price_change"}}
{"_local_timestamp": "2026-01-25T23:50:17.864276+00:00", "data": {"market": "0x120a43c108202f029133104531990a595af4f3700a92bbda4403535235bc4c82", "price_changes": [{"asset_id": "39828720608155723418301214397692986239980049531210825338778701775676917810839", "price": "0.14", "size": "50", "side": "BUY", "hash": "cc0df63f877a6d337d8a98d50ec636f213a31b25", "best_bid": "0.74", "best_ask": "0.78"}, {"asset_id": "8361104603056110450083567322497943223782511845432999258620698572163981630847", "price": "0.86", "size": "50", "side": "SELL", "hash": "2c92d04672eb763103ff2ee802ae41b8ca3a7d83", "best_bid": "0.22", "best_ask": "0.26"}], "timestamp": "1769385017768", "event_type": "price_change"}}
{"_local_timestamp": "2026-01-25T23:50:21.895788+00:00", "data": {"market": "0x120a43c108202f029133104531990a595af4f3700a92bbda4403535235bc4c82", "price_changes": [{"asset_id": "39828720608155723418301214397692986239980049531210825338778701775676917810839", "price": "0.2", "size": "0", "side": "BUY", "hash": "72a35025247b2565efcaa9ef90b08ed4f2f08846", "best_bid": "0.74", "best_ask": "0.78"}, {"asset_id": "8361104603056110450083567322497943223782511845432999258620698572163981630847", "price": "0.8", "size": "0", "side": "SELL", "hash": "a25a9f9922c8cd12ab21b0a1df6853c80d139a6c", "best_bid": "0.22", "best_ask": "0.26"}], "timestamp": "1769385021810", "event_type": "price_change"}}
{"_local_timestamp": "2026-01-25T23:50:22.230002+00:00", "data": {"market": "0x120a43c108202f029133104531990a595af4f3700a92bbda4403535235bc4c82", "price_changes": [{"asset_id": "39828720608155723418301214397692986239980049531210825338778701775676917810839", "price": "0.21", "size": "2198", "side": "BUY", "hash": "9586eb30974331e946955f5e712cae4d837f49d7", "best_bid": "0.74", "best_ask": "0.78"}, {"asset_id": "8361104603056110450083567322497943223782511845432999258620698572163981630847", "price": "0.79", "size": "2198", "side": "SELL", "hash": "086da21e6fc7a2be5cf0fcee76545b9d3e1fd8df", "best_bid": "0.22", "best_ask": "0.26"}], "timestamp": "1769385022105", "event_type": "price_change"}}
