{"_local_timestamp": "2026-01-25T23:40:31.194289+00:00", "data": [{"market": "0xc7aca5ec2ab64207578a5461e4f3d2ad2362a6ca9edcaa6b6f05553a7d541819", "asset_id": "13986990593551346934180369322143442319151776409512592545696715177800565940569", "timestamp": "1769384362705", "hash": "d354bfc3eb8da78a1a88d1c1882046a2767f2a14", "bids": [{"price": "0.001", "size": "46769"}, {"price": "0.002", "size": "4341.31"}, {"price": "0.003", "size": "270.97"}, {"price": "0.004", "size": "7.83"}, {"price": "0.005", "size": "137"}, {"price": "0.006", "size": "7.73"}, {"price": "0.009", "size": "6.75"}, {"price": "0.01", "size": "10"}, {"price": "0.014", "size": "102"}, {"price": "0.015", "size": "268"}, {"price": "0.016", "size": "81.69"}], "asks": [{"price": "0.999", "size": "3818.86"}, {"price": "0.998", "size": "250"}, {"price": "0.997", "size": "408.18"}, {"price": "0.994", "size": "200"}, {"price": "0.993", "size": "11.98"}, {"price": "0.979", "size": "600"}, {"price": "0.978", "size": "11.49"}, {"price": "0.95", "size": "30"}, {"price": "0.949", "size": "39"}, {"price": "0.933", "size": "500"}, {"price": "0.932", "size": "7.66"}, {"price": "0.889", "size": "685"}, {"price": "0.805", "size": "455"}, {"price": "0.803", "size": "5.6"}, {"price": "0.738", "size": "150"}, {"price": "0.539", "size": "5403"}, {"price": "0.535", "size": "5"}, {"price": "0.529", "size": "612"}, {"price": "0.528", "size": "483"}, {"price": "0.527", "size": "20"}, {"price": "0.101", "size": "25"}, {"price": "0.094", "size": "25"}, {"price": "0.093", "size": "20"}, {"price": "0.092", "size": "25"}, {"price": "0.061", "size": "20"}, {"price": "0.039", "size": "200"}, {"price": "0.036", "size": "345.4"}, {"price": "0.033", "size": "370"}, {"price": "0.032", "size": "117.66"}], "event_type": "book", "last_trade_price": ""}, {"market": "0x8ec3037f6f989717b8321b9c6d297698c5827d3f17bc06fa276a6826a0b468bc", "asset_id": "63727355381184542281210853076888298871978167151761041112625093048354950500520", "timestamp": "1769384335958", "hash": "d7e27b29e8254e4a31892a280ff4bb6bb670f93f", "bids": [{"price": "0.001", "size": "3799.4"}, {"price": "0.002", "size": "250"}, {"price": "0.003", "size": "408.19"}, {"price": "0.006", "size": "200"}, {"price": "0.007", "size": "11.98"}, {"price": "0.02", "size": "400"}, {"price": "0.021", "size": "10.84"}, {"price": "0.05", "size": "30"}, {"price": "0.051", "size": "39"}, {"price": "0.062", "size": "750"}, {"price": "0.063", "size": "7.22"}, {"price": "0.11", "size": "325"}, {"price": "0.16", "size": "250"}, {"price": "0.161", "size": "7.43"}, {"price": "0.21", "size": "150"}, {"price": "0.588", "size": "3238"}, {"price": "0.611", "size": "640"}, {"price": "0.615", "size": "5"}, {"price": "0.624", "size": "30"}, {"price": "0.625", "size": "185"}, {"price": "0.626", "size": "25"}, {"price": "0.627", "size": "20"}, {"price": "0.976", "size": "500"}, {"price": "0.978", "size": "25"}, {"price": "0.98", "size": "512.69"}, {"price": "0.981", "size": "91.86"}, {"price": "0.983", "size": "50"}, {"price": "0.992", "size": "10.2"}, {"price": "0.995", "size": "265.29"}], "asks": [{"price": "0.999", "size": "32271"}, {"price": "0.998", "size": "1266.04"}, {"price": "0.997", "size": "5"}], "event_type": "book", "last_trade_price": ""}, {"market": "0x4b04e14bcde7be95db753c88f6fed57423835215bb41937406e75dc22a789b0c", "asset_id": "75013115303617466002500221618724536968904237026728502667764718978862356730825", "timestamp": "1769384366270", "hash": "9d4c84236cbf4b12e482428d2316263fd2089a58", "bids": [{"price": "0.001", "size": "3786.46"}, {"price": "0.002", "size": "250"}, {"price": "0.003", "size": "408.22"}, {"price": "0.006", "size": "200"}, {"price": "0.007", "size": "12.03"}, {"price": "0.02", "size": "400"}, {"price": "0.021", "size": "11.14"}, {"price": "0.05", "size": "30"}, {"price": "0.051", "size": "39"}, {"price": "0.063", "size": "500"}, {"price": "0.064", "size": "7.05"}, {"price": "0.11", "size": "325"}, {"price": "0.166", "size": "250"}, {"price": "0.167", "size": "7.14"}, {"price": "0.224", "size": "4090"}, {"price": "0.225", "size": "400"}, {"price": "0.649", "size": "25"}, {"price": "0.651", "size": "644"}, {"price": "0.652", "size": "178"}, {"price": "0.654", "size": "5"}, {"price": "0.655", "size": "25"}, {"price": "0.656", "size": "20"}, {"price": "0.951", "size": "5"}, {"price": "0.953", "size": "20"}, {"price": "0.962", "size": "85"}, {"price": "0.972", "size": "245.16"}, {"price": "0.992", "size": "35.7"}, {"price": "0.995", "size": "325.31"}], "asks": [{"price": "0.999", "size": "31014"}, {"price": "0.998", "size": "1266.01"}], "event_type": "book", "last_trade_price": ""}, {"market": "0x4f864dda711ee273e6eb7925aada5d984da51a5f423122a00f6ae9532a3c28b9", "asset_id": "32968341948204373341622549015077301743176984559839089527120694005326340631965", "timestamp": "1769384251710", "hash": "2969feef169b8d67f0981b1204781e952174a5a7", "bids": [{"price": "0.001", "size": "32789"}, {"price": "0.002", "size": "685.19"}, {"price": "0.003", "size": "455.22"}, {"price": "0.004", "size": "171.29"}, {"price": "0.005", "size": "240"}, {"price": "0.006", "size": "140"}, {"price": "0.007", "size": "147"}, {"price": "0.008", "size": "148"}], "asks": [{"price": "0.999", "size": "3818.45"}, {"price": "0.998", "size": "250"}, {"price": "0.997", "size": "407.63"}, {"price": "0.994", "size": "200"}, {"price": "0.993", "size": "8.31"}, {"price": "0.98", "size": "400"}, {"price": "0.979", "size": "10.4"}, {"price": "0.95", "size": "30"}, {"price": "0.949", "size": "39"}, {"price": "0.939", "size": "500"}, {"price": "0.938", "size": "7.98"}, {"price": "0.89", "size": "325"}, {"price": "0.827", "size": "203"}, {"price": "0.825", "size": "8005"}, {"price": "0.824", "size": "1350"}, {"price": "0.823", "size": "6.74"}, {"price": "0.79", "size": "100"}, {"price": "0.676", "size": "125"}, {"price": "0.675", "size": "6"}, {"price": "0.186", "size": "500"}, {"price": "0.185", "size": "79.3"}, {"price": "0.184", "size": "99"}, {"price": "0.11", "size": "19.97"}, {"price": "0.109", "size": "20"}, {"price": "0.093", "size": "45"}, {"price": "0.092", "size": "25"}, {"price": "0.066", "size": "32"}, {"price": "0.054", "size": "117.33"}, {"price": "0.053", "size": "131.45"}, {"price": "0.052", "size": "38.88"}, {"price": "0.051", "size": "10"}], "event_type": "book", "last_trade_price": ""}, {"market": "0xc7aca5ec2ab64207578a5461e4f3d2ad2362a6ca9edcaa6b6f05553a7d541819", "asset_id": "46477055511928802305871870544961419728762162363024275463912888154597320120223", "timestamp": "1769384362705", "hash": "6e1cd83f410ae0d0163a4a762b2e1cdaf1c196fa", "bids": [{"price": "0.001", "size": "3818.86"}, {"price": "0.002", "size": "250"}, {"price": "0.003", "size": "408.18"}, {"price": "0.006", "size": "200"}, {"price": "0.007", "size": "11.98"}, {"price": "0.021", "size": "600"}, {"price": "0.022", "size": "11.49"}, {"price": "0.05", "size": "30"}, {"price": "0.051", "size": "39"}, {"price": "0.067", "size": "500"}, {"price": "0.068", "size": "7.66"}, {"price": "0.111", "size": "685"}, {"price": "0.195", "size": "455"}, {"price": "0.197", "size": "5.6"}, {"price": "0.262", "size": "150"}, {"price": "0.461", "size": "5403"}, {"price": "0.465", "size": "5"}, {"price": "0.471", "size": "612"}, {"price": "0.472", "size": "483"}, {"price": "0.473", "size": "20"}, {"price": "0.899", "size": "25"}, {"price": "0.906", "size": "25"}, {"price": "0.907", "size": "20"}, {"price": "0.908", "size": "25"}, {"price": "0.939", "size": "20"}, {"price": "0.961", "size": "200"}, {"price": "0.964", "size": "345.4"}, {"price": "0.967", "size": "370"}, {"price": "0.968", "size": "117.66"}], "asks": [{"price": "0.999", "size": "46769"}, {"price": "0.998", "size": "4341.31"}, {"price": "0.997", "size": "270.97"}, {"price": "0.996", "size": "7.83"}, {"price": "0.995", "size": "137"}, {"price": "0.994", "size": "7.73"}, {"price": "0.991", "size": "6.75"}, {"price": "0.99", "size": "10"}, {"price": "0.986", "size": "102"}, {"price": "0.985", "size": "268"}, {"price": "0.984", "size": "81.69"}], "event_type": "book", "last_trade_price": ""}, {"market": "0x8ec3037f6f989717b8321b9c6d297698c5827d3f17bc06fa276a6826a0b468bc", "asset_id": "54960339021810821002608536313392642741296500124718788520040272866772532121044", "timestamp": "1769384335958", "hash": "d2ea827644df8917ff9e92437371f3402013559b", "bids": [{"price": "0.001", "size": "32271"}, {"price": "0.002", "size": "1266.04"}, {"price": "0.003", "size": "5"}], "asks": [{"price": "0.999", "size": "3799.4"}, {"price": "0.998", "size": "250"}, {"price": "0.997", "size": "408.19"}, {"price": "0.994", "size": "200"}, {"price": "0.993", "size": "11.98"}, {"price": "0.98", "size": "400"}, {"price": "0.979", "size": "10.84"}, {"price": "0.95", "size": "30"}, {"price": "0.949", "size": "39"}, {"price": "0.938", "size": "750"}, {"price": "0.937", "size": "7.22"}, {"price": "0.89", "size": "325"}, {"price": "0.84", "size": "250"}, {"price": "0.839", "size": "7.43"}, {"price": "0.79", "size": "150"}, {"price": "0.412", "size": "3238"}, {"price": "0.389", "size": "640"}, {"price": "0.385", "size": "5"}, {"price": "0.376", "size": "30"}, {"price": "0.375", "size": "185"}, {"price": "0.374", "size": "25"}, {"price": "0.373", "size": "20"}, {"price": "0.024", "size": "500"}, {"price": "0.022", "size": "25"}, {"price": "0.02", "size": "512.69"}, {"price": "0.019", "size": "91.86"}, {"price": "0.017", "size": "50"}, {"price": "0.008", "size": "10.2"}, {"price": "0.005", "size": "265.29"}], "event_type": "book", "last_trade_price": ""}, {"market": "0x4cb1b09d2a17a1e21e459f4e431999bc3bfbb40cc9023b3354aa70e2d7d81875", "asset_id": "114492877966140684018682752756008128367968333531744283465420223400327242203881", "timestamp": "1769384296663", "hash": "ec2a179f643037c83548166b0978ac1487d0c5d3", "bids": [{"price": "0.001", "size": "32035"}, {"price": "0.002", "size": "4405.19"}, {"price": "0.003", "size": "15.08"}, {"price": "0.004", "size": "137.48"}, {"price": "0.007", "size": "142"}, {"price": "0.008", "size": "143"}], "asks": [{"price": "0.999", "size": "3817.43"}, {"price": "0.998", "size": "250"}, {"price": "0.997", "size": "408.22"}, {"price": "0.994", "size": "200"}, {"price": "0.993", "size": "13.71"}, {"price": "0.98", "size": "400"}, {"price": "0.979", "size": "7.81"}, {"price": "0.95", "size": "30"}, {"price": "0.949", "size": "39"}, {"price": "0.938", "size": "500"}, {"price": "0.937", "size": "7.39"}, {"price": "0.89", "size": "325"}, {"price": "0.834", "size": "250"}, {"price": "0.833", "size": "7.4"}, {"price": "0.786", "size": "3564"}, {"price": "0.785", "size": "400"}, {"price": "0.457", "size": "18"}, {"price": "0.447", "size": "695"}, {"price": "0.437", "size": "5"}, {"price": "0.436", "size": "25"}, {"price": "0.434", "size": "30"}, {"price": "0.432", "size": "176"}, {"price": "0.431", "size": "25"}, {"price": "0.429", "size": "25"}, {"price": "0.428", "size": "20"}, {"price": "0.066", "size": "32"}, {"price": "0.053", "size": "20"}, {"price": "0.041", "size": "200"}, {"price": "0.035", "size": "293.27"}], "event_type": "book", "last_trade_price": "0.005"}, {"market": "0xe478b515162e00d4b682e2e480e847487f5e824bbc5c7c1d4587ee68bcb4befe", "asset_id": "53729975633757169097007121898269744507742420238247181414435653260215633496084", "timestamp": "1769384300336", "hash": "104570a5a721f3a3f0e2a7ba706d6793502719eb", "bids": [{"price": "0.01", "size": "669.02"}, {"price": "0.02", "size": "274.98"}, {"price": "0.03", "size": "536.19"}, {"price": "0.04", "size": "306.41"}, {"price": "0.05", "size": "225"}, {"price": "0.06", "size": "665.7"}], "asks": [{"price": "0.99", "size": "1006.18"}, {"price": "0.96", "size": "1200"}, {"price": "0.95", "size": "35.43"}, {"price": "0.94", "size": "233"}, {"price": "0.86", "size": "325"}, {"price": "0.8", "size": "250"}, {"price": "0.79", "size": "190"}, {"price": "0.78", "size": "1908"}, {"price": "0.7", "size": "6788"}, {"price": "0.69", "size": "375"}, {"price": "0.26", "size": "24.73"}, {"price": "0.24", "size": "100"}, {"price": "0.14", "size": "524.75"}, {"price": "0.09", "size": "200"}, {"price": "0.08", "size": "237.55"}], "event_type": "book", "last_trade_price": ""}, {"market": "0x4f864dda711ee273e6eb7925aada5d984da51a5f423122a00f6ae9532a3c28b9", "asset_id": "19845436317498992677729026362700087887065920346030569541585600013099473710639", "timestamp": "1769384251710", "hash": "b0d2b3988dd75b4f1a9d46eb450666e118c92413", "bids": [{"price": "0.001", "size": "3818.45"}, {"price": "0.002", "size": "250"}, {"price": "0.003", "size": "407.63"}, {"price": "0.006", "size": "200"}, {"price": "0.007", "size": "8.31"}, {"price": "0.02", "size": "400"}, {"price": "0.021", "size": "10.4"}, {"price": "0.05", "size": "30"}, {"price": "0.051", "size": "39"}, {"price": "0.061", "size": "500"}, {"price": "0.062", "size": "7.98"}, {"price": "0.11", "size": "325"}, {"price": "0.173", "size": "203"}, {"price": "0.175", "size": "8005"}, {"price": "0.176", "size": "1350"}, {"price": "0.177", "size": "6.74"}, {"price": "0.21", "size": "100"}, {"price": "0.324", "size": "125"}, {"price": "0.325", "size": "6"}, {"price": "0.814", "size": "500"}, {"price": "0.815", "size": "79.3"}, {"price": "0.816", "size": "99"}, {"price": "0.89", "size": "19.97"}, {"price": "0.891", "size": "20"}, {"price": "0.907", "size": "45"}, {"price": "0.908", "size": "25"}, {"price": "0.934", "size": "32"}, {"price": "0.946", "size": "117.33"}, {"price": "0.947", "size": "131.45"}, {"price": "0.948", "size": "38.88"}, {"price": "0.949", "size": "10"}], "asks": [{"price": "0.999", "size": "32789"}, {"price": "0.998", "size": "685.19"}, {"price": "0.997", "size": "455.22"}, {"price": "0.996", "size": "171.29"}, {"price": "0.995", "size": "240"}, {"price": "0.994", "size": "140"}, {"price": "0.993", "size": "147"}, {"price": "0.992", "size": "148"}], "event_type": "book", "last_trade_price": ""}, {"market": "0x4b04e14bcde7be95db753c88f6fed57423835215bb41937406e75dc22a789b0c", "asset_id": "195928349533315596595305126471738494775883003093487532708892885008234493544", "timestamp": "1769384366270", "hash": "b4168176866c1d9c398e23c690d7995944b005e3", "bids": [{"price": "0.001", "size": "31014"}, {"price": "0.002", "size": "1266.01"}], "asks": [{"price": "0.999", "size": "3786.46"}, {"price": "0.998", "size": "250"}, {"price": "0.997", "size": "408.22"}, {"price": "0.994", "size": "200"}, {"price": "0.993", "size": "12.03"}, {"price": "0.98", "size": "400"}, {"price": "0.979", "size": "11.14"}, {"price": "0.95", "size": "30"}, {"price": "0.949", "size": "39"}, {"price": "0.937", "size": "500"}, {"price": "0.936", "size": "7.05"}, {"price": "0.89", "size": "325"}, {"price": "0.834", "size": "250"}, {"price": "0.833", "size": "7.14"}, {"price": "0.776", "size": "4090"}, {"price": "0.775", "size": "400"}, {"price": "0.351", "size": "25"}, {"price": "0.349", "size": "644"}, {"price": "0.348", "size": "178"}, {"price": "0.346", "size": "5"}, {"price": "0.345", "size": "25"}, {"price": "0.344", "size": "20"}, {"price": "0.049", "size": "5"}, {"price": "0.047", "size": "20"}, {"price": "0.038", "size": "85"}, {"price": "0.028", "size": "245.16"}, {"price": "0.008", "size": "35.7"}, {"price": "0.005", "size": "325.31"}], "event_type": "book", "last_trade_price": ""}, {"market": "0x4cb1b09d2a17a1e21e459f4e431999bc3bfbb40cc9023b3354aa70e2d7d81875", "asset_id": "75701058868331201775069911407645821013233843572698963559250184599603027030054", "timestamp": "1769384296663", "hash": "aa3647733a50712591ebfff0886d56d4e991dcaa", "bids": [{"price": "0.001", "size": "3817.43"}, {"price": "0.002", "size": "250"}, {"price": "0.003", "size": "408.22"}, {"price": "0.006", "size": "200"}, {"price": "0.007", "size": "13.71"}, {"price": "0.02", "size": "400"}, {"price": "0.021", "size": "7.81"}, {"price": "0.05", "size": "30"}, {"price": "0.051", "size": "39"}, {"price": "0.062", "size": "500"}, {"price": "0.063", "size": "7.39"}, {"price": "0.11", "size": "325"}, {"price": "0.166", "size": "250"}, {"price": "0.167", "size": "7.4"}, {"price": "0.214", "size": "3564"}, {"price": "0.215", "size": "400"}, {"price": "0.543", "size": "18"}, {"price": "0.553", "size": "695"}, {"price": "0.563", "size": "5"}, {"price": "0.564", "size": "25"}, {"price": "0.566", "size": "30"}, {"price": "0.568", "size": "176"}, {"price": "0.569", "size": "25"}, {"price": "0.571", "size": "25"}, {"price": "0.572", "size": "20"}, {"price": "0.934", "size": "32"}, {"price": "0.947", "size": "20"}, {"price": "0.959", "size": "200"}, {"price": "0.965", "size": "293.27"}], "asks": [{"price": "0.999", "size": "32035"}, {"price": "0.998", "size": "4405.19"}, {"price": "0.997", "size": "15.08"}, {"price": "0.996", "size": "137.48"}, {"price": "0.993", "size": "142"}, {"price": "0.992", "size": "143"}], "event_type": "book", "last_trade_price": "0.005"}, {"market": "0xe478b515162e00d4b682e2e480e847487f5e824bbc5c7c1d4587ee68bcb4befe", "asset_id": "53703724894913146397718355589619605161922119509512772920279877071805641165559", "timestamp": "1769384300336", "hash": "9f8b85b5795bfd9b71ad76d33b099da38381cab0", "bids": [{"price": "0.01", "size": "1006.18"}, {"price": "0.04", "size": "1200"}, {"price": "0.05", "size": "35.43"}, {"price": "0.06", "size": "233"}, {"price": "0.14", "size": "325"}, {"price": "0.2", "size": "250"}, {"price": "0.21", "size": "190"}, {"price": "0.22", "size": "1908"}, {"price": "0.3", "size": "6788"}, {"price": "0.31", "size": "375"}, {"price": "0.74", "size": "24.73"}, {"price": "0.76", "size": "100"}, {"price": "0.86", "size": "524.75"}, {"price": "0.91", "size": "200"}, {"price": "0.92", "size": "237.55"}], "asks": [{"price": "0.99", "size": "669.02"}, {"price": "0.98", "size": "274.98"}, {"price": "0.97", "size": "536.19"}, {"price": "0.96", "size": "306.41"}, {"price": "0.95", "size": "225"}, {"price": "0.94", "size": "665.7"}], "event_type": "book", "last_trade_price": ""}]}
{"_local_timestamp": "2026-01-25T23:40:39.383438+00:00", "data": {"market": "0xc7aca5ec2ab64207578a5461e4f3d2ad2362a6ca9edcaa6b6f05553a7d541819", "price_changes": [{"asset_id": "46477055511928802305871870544961419728762162363024275463912888154597320120223", "price": "0.263", "size": "1596", "side": "BUY", "hash": "386ffcb23f20111dec23ec525781d505b2772c16", "best_bid": "0.968", "best_ask": "0.984"}, {"asset_id": "13986990593551346934180369322143442319151776409512592545696715177800565940569", "price": "0.737", "size": "1596", "side": "SELL", "hash": "34b5e8bbbbc174832ecf4502f6e404c485dfb8de", "best_bid": "0.016", "best_ask": "0.032"}], "timestamp": "1769384439310", "event_type": "price_change"}}
{"_local_timestamp": "2026-01-25T23:40:39.454772+00:00", "data": {"market": "0xc7aca5ec2ab64207578a5461e4f3d2ad2362a6ca9edcaa6b6f05553a7d541819", "price_changes": [{"asset_id": "46477055511928802305871870544961419728762162363024275463912888154597320120223", "price": "0.907", "size": "0", "side": "BUY", "hash": "2e49aa4ff91a27aa8d5b2debdc0ce5fc55ace0ce", "best_bid": "0.968", "best_ask": "0.984"}, {"asset_id": "13986990593551346934180369322143442319151776409512592545696715177800565940569", "price": "0.093", "size": "0", "side": "SELL", "hash": "26fbb9cc6921e497936e1b8a5496fdb3f2add7e1", "best_bid": "0.016", "best_ask": "0.032"}], "timestamp": "1769384439384", "event_type": "price_change"}}
{"_local_timestamp": "2026-01-25T23:40:39.455810+00:00", "data": {"market": "0x4f864dda711ee273e6eb7925aada5d984da51a5f423122a00f6ae9532a3c28b9", "price_changes": [{"asset_id": "19845436317498992677729026362700087887065920346030569541585600013099473710639", "price": "0.907", "size": "25", "side": "BUY", "hash": "456238d5a7268065f846e605dcdcf343d291e5fb", "best_bid": "0.949", "best_ask": "0.992"}, {"asset_id": "32968341948204373341622549015077301743176984559839089527120694005326340631965", "price": "0.093", "size": "25", "side": "SELL", "hash": "59dda9287938f22fd0b6d56957db0fe89bf85ff4", "best_bid": "0.008", "best_ask": "0.051"}], "timestamp": "1769384439385", "event_type": "price_change"}}
{"_local_timestamp": "2026-01-25T23:40:39.503963+00:00", "data": {"market": "0x4f864dda711ee273e6eb7925aada5d984da51a5f423122a00f6ae9532a3c28b9", "price_changes": [{"asset_id": "19845436317498992677729026362700087887065920346030569541585600013099473710639", "price": "0.909", "size": "30", "side": "BUY", "hash": "731d9bfac7487d8e4c04f652a8f7c290c523e5a5", "best_bid": "0.949", "best_ask": "0.992"}, {"asset_id": "32968341948204373341622549015077301743176984559839089527120694005326340631965", "price": "0.091", "size": "30", "side": "SELL", "hash": "6f5128109658b61cc16594acf3b0492206d24e97", "best_bid": "0.008", "best_ask": "0.051"}], "timestamp": "1769384439437", "event_type": "price_change"}}
{"_local_timestamp": "2026-01-25T23:40:39.505133+00:00", "data": {"market": "0xc7aca5ec2ab64207578a5461e4f3d2ad2362a6ca9edcaa6b6f05553a7d541819", "price_changes": [{"asset_id": "46477055511928802305871870544961419728762162363024275463912888154597320120223", "price": "0.909", "size": "30", "side": "BUY", "hash": "d55bfd6a83ba7f5eb7da8493038a59a2ec647d0c", "best_bid": "0.968", "best_ask": "0.984"}, {"asset_id": "13986990593551346934180369322143442319151776409512592545696715177800565940569", "price": "0.091", "size": "30", "side": "SELL", "hash": "bafb2e2fab8be3d17fe01d2331e9e1bf72dd81c4", "best_bid": "0.016", "best_ask": "0.032"}], "timestamp": "1769384439437", "event_type": "price_change"}}
{"_local_timestamp": "2026-01-25T23:40:39.511718+00:00", "data": {"market": "0xc7aca5ec2ab64207578a5461e4f3d2ad2362a6ca9edcaa6b6f05553a7d541819", "price_changes": [{"asset_id": "46477055511928802305871870544961419728762162363024275463912888154597320120223", "price": "0.474", "size": "228", "side": "BUY", "hash": "b5e90dffc3c04dc71e7c5fdde71804fb8c2d97f4", "best_bid": "0.968", "best_ask": "0.984"}, {"asset_id": "13986990593551346934180369322143442319151776409512592545696715177800565940569", "price": "0.526", "size": "228", "side": "SELL", "hash": "ce6eb55a6b23817e5d06e7fbff38fb5dfe4095f4", "best_bid": "0.016", "best_ask": "0.032"}], "timestamp": "1769384439440", "event_type": "price_change"}}
{"_local_timestamp": "2026-01-25T23:40:39.557762+00:00", "data": {"market": "0x8ec3037f6f989717b8321b9c6d297698c5827d3f17bc06fa276a6826a0b468bc", "price_changes": [{"asset_id": "63727355381184542281210853076888298871978167151761041112625093048354950500520", "price": "0.625", "size": "160", "side": "BUY", "hash": "7114beaa223e8be4db2bfab797940da811156d53", "best_bid": "0.995", "best_ask": "0.997"}, {"asset_id": "54960339021810821002608536313392642741296500124718788520040272866772532121044", "price": "0.375", "size": "160", "side": "SELL", "hash": "8aebba0fc3cfb4c00f4d4218942fef9a10aa37e2", "best_bid": "0.003", "best_ask": "0.005"}], "timestamp": "1769384439484", "event_type": "price_change"}}
{"_local_timestamp": "2026-01-25T23:40:39.559157+00:00", "data": {"market": "0x4cb1b09d2a17a1e21e459f4e431999bc3bfbb40cc9023b3354aa70e2d7d81875", "price_changes": [{"asset_id": "75701058868331201775069911407645821013233843572698963559250184599603027030054", "price": "0.564", "size": "0", "side": "BUY", "hash": "6ceacb09a2722d70a06bd03d72a6bf4118c58bae", "best_bid": "0.965", "best_ask": "0.992"}, {"asset_id": "114492877966140684018682752756008128367968333531744283465420223400327242203881", "price": "0.436", "size": "0", "side": "SELL", "hash": "5b080a6721b5a2864b1f0af97a1bb958e83e5c67", "best_bid": "0.008", "best_ask": "0.035"}], "timestamp": "1769384439485", "event_type": "price_change"}}
{"_local_timestamp": "2026-01-25T23:40:39.560237+00:00", "data": {"market": "0x4b04e14bcde7be95db753c88f6fed57423835215bb41937406e75dc22a789b0c", "price_changes": [{"asset_id": "75013115303617466002500221618724536968904237026728502667764718978862356730825", "price": "0.649", "size": "0", "side": "BUY", "hash": "29b49edf0f82f747d5e1483755749f9ca43aa699", "best_bid": "0.995", "best_ask": "0.998"}, {"asset_id": "195928349533315596595305126471738494775883003093487532708892885008234493544", "price": "0.351", "size": "0", "side": "SELL", "hash": "8d23c74c73cbd5f90705273b34d51e64af6433cd", "best_bid": "0.002", "best_ask": "0.005"}], "timestamp": "1769384439485", "event_type": "price_change"}}
{"_local_timestamp": "2026-01-25T23:40:39.610371+00:00", "data": {"market": "0x8ec3037f6f989717b8321b9c6d297698c5827d3f17bc06fa276a6826a0b468bc", "price_changes": [{"asset_id": "63727355381184542281210853076888298871978167151761041112625093048354950500520", "price": "0.626", "size": "0", "side": "BUY", "hash": "933cc078c87a761969fab00ff679d5469f591a2e", "best_bid": "0.995", "best_ask": "0.997"}, {"asset_id": "54960339021810821002608536313392642741296500124718788520040272866772532121044", "price": "0.374", "size": "0", "side": "SELL", "hash": "443e43a50c4eaf478cb40847dda9d1cc4f1584e3", "best_bid": "0.003", "best_ask": "0.005"}], "timestamp": "1769384439543", "event_type": "price_change"}}
{"_local_timestamp": "2026-01-25T23:40:39.611928+00:00", "data": {"market": "0xc7aca5ec2ab64207578a5461e4f3d2ad2362a6ca9edcaa6b6f05553a7d541819", "price_changes": [{"asset_id": "46477055511928802305871870544961419728762162363024275463912888154597320120223", "price": "0.471", "size": "212", "side": "BUY", "hash": "9acc7492d3b200e3a8032561efaafee45002b208", "best_bid": "0.968", "best_ask": "0.984"}, {"asset_id": "13986990593551346934180369322143442319151776409512592545696715177800565940569", "price": "0.529", "size": "212", "side": "SELL", "hash": "f521928fb6f20d83acc3ad433b13270398718d95", "best_bid": "0.016", "best_ask": "0.032"}], "timestamp": "1769384439543", "event_type": "price_change"}}
{"_local_timestamp": "2026-01-25T23:40:39.623869+00:00", "data": {"market": "0x8ec3037f6f989717b8321b9c6d297698c5827d3f17bc06fa276a6826a0b468bc", "price_changes": [{"asset_id": "63727355381184542281210853076888298871978167151761041112625093048354950500520", "price": "0.624", "size": "0", "side": "BUY", "hash": "1d790ae7351ba3ab239e0ecc9799f1787fd64d04", "best_bid": "0.995", "best_ask": "0.997"}, {"asset_id": "54960339021810821002608536313392642741296500124718788520040272866772532121044", "price": "0.376", "size": "0", "side": "SELL", "hash": "357d1da3ae3ace46508c5be6431d29f81f8120ce", "best_bid": "0.003", "best_ask": "0.005"}], "timestamp": "1769384439554", "event_type": "price_change"}}
{"_local_timestamp": "2026-01-25T23:40:39.651947+00:00", "data": {"market": "0x4b04e14bcde7be95db753c88f6fed57423835215bb41937406e75dc22a789b0c", "price_changes": [{"asset_id": "75013115303617466002500221618724536968904237026728502667764718978862356730825", "price": "0.652", "size": "153", "side": "BUY", "hash": "f1864f0d069d4bdab8c3896e0c917a5b667d2110", "best_bid": "0.995", "best_ask": "0.998"}, {"asset_id": "195928349533315596595305126471738494775883003093487532708892885008234493544", "price": "0.348", "size": "153", "side": "SELL", "hash": "9a379331c53388eb7830598652f89ada982c08d4", "best_bid": "0.002", "best_ask": "0.005"}], "timestamp": "1769384439583", "event_type": "price_change"}}
{"_local_timestamp": "2026-01-25T23:40:39.653285+00:00", "data": {"market": "0xc7aca5ec2ab64207578a5461e4f3d2ad2362a6ca9edcaa6b6f05553a7d541819", "price_changes": [{"asset_id": "46477055511928802305871870544961419728762162363024275463912888154597320120223", "price": "0.471", "size": "0", "side": "BUY", "hash": "665ebc65bbaf1480f0317fed1a1e128169c813c5", "best_bid": "0.968", "best_ask": "0.984"}, {"asset_id": "13986990593551346934180369322143442319151776409512592545696715177800565940569", "price": "0.529", "size": "0", "side": "SELL", "hash": "431141d2db350602e14c558d72591407125ae5a5", "best_bid": "0.016", "best_ask": "0.032"}], "timestamp": "1769384439583", "event_type": "price_change"}}
{"_local_timestamp": "2026-01-25T23:40:39.664459+00:00", "data": {"market": "0x8ec3037f6f989717b8321b9c6d297698c5827d3f17bc06fa276a6826a0b468bc", "price_changes": [{"asset_id": "63727355381184542281210853076888298871978167151761041112625093048354950500520", "price": "0.628", "size": "25", "side": "BUY", "hash": "85db171cb237dc72da5f0f7118cccc7b4e813e76", "best_bid": "0.995", "best_ask": "0.997"}, {"asset_id": "54960339021810821002608536313392642741296500124718788520040272866772532121044", "price": "0.372", "size": "25", "side": "SELL", "hash": "2f6c859a921d61fb805177a310c60b866e543712", "best_bid": "0.003", "best_ask": "0.005"}], "timestamp": "1769384439597", "event_type": "price_change"}}
{"_local_timestamp": "2026-01-25T23:40:39.665762+00:00", "data": {"market": "0xc7aca5ec2ab64207578a5461e4f3d2ad2362a6ca9edcaa6b6f05553a7d541819", "price_changes": [{"asset_id": "46477055511928802305871870544961419728762162363024275463912888154597320120223", "price": "0.473", "size": "420", "side": "BUY", "hash": "729f43f0f7f378bd8c355716883ea085a793a3fe", "best_bid": "0.968", "best_ask": "0.984"}, {"asset_id": "13986990593551346934180369322143442319151776409512592545696715177800565940569", "price": "0.527", "size": "420", "side": "SELL", "hash": "7c3c81e3ed6aaa7d08e83012cf72f449f5d11445", "best_bid": "0.016", "best_ask": "0.032"}], "timestamp": "1769384439597", "event_type": "price_change"}}
{"_local_timestamp": "2026-01-25T23:40:39.738027+00:00", "data": {"market": "0x8ec3037f6f989717b8321b9c6d297698c5827d3f17bc06fa276a6826a0b468bc", "price_changes": [{"asset_id": "63727355381184542281210853076888298871978167151761041112625093048354950500520", "price": "0.628", "size": "50", "side": "BUY", "hash": "fbc25807a54546cdebdaccc0aa3112429648361f", "best_bid": "0.995", "best_ask": "0.997"}, {"asset_id": "54960339021810821002608536313392642741296500124718788520040272866772532121044", "price": "0.372", "size": "50", "side": "SELL", "hash": "ff6dcd937eead5e35fd5f81c70c2bf9f443a49ed", "best_bid": "0.003", "best_ask": "0.005"}], "timestamp": "1769384439662", "event_type": "price_change"}}
{"_local_timestamp": "2026-01-25T23:40:39.739261+00:00", "data": {"market": "0x4b04e14bcde7be95db753c88f6fed57423835215bb41937406e75dc22a789b0c", "price_changes": [{"asset_id": "75013115303617466002500221618724536968904237026728502667764718978862356730825", "price": "0.657", "size": "25", "side": "BUY", "hash": "ed7bff346923bb9565218be2d17af228a7ff9dd6", "best_bid": "0.995", "best_ask": "0.998"}, {"asset_id": "195928349533315596595305126471738494775883003093487532708892885008234493544", "price": "0.343", "size": "25", "side": "SELL", "hash": "5e0c0c9707cf72a70c6bf447f33b37e0221639d4", "best_bid": "0.002", "best_ask": "0.005"}], "timestamp": "1769384439662", "event_type": "price_change"}}
{"_local_timestamp": "2026-01-25T23:40:39.740360+00:00", "data": {"market": "0x4cb1b09d2a17a1e21e459f4e431999bc3bfbb40cc9023b3354aa70e2d7d81875", "price_changes": [{"asset_id": "75701058868331201775069911407645821013233843572698963559250184599603027030054", "price": "0.573", "size": "25", "side": "BUY", "hash": "701fcecb6ee789f3bc6d0101df6b898c95097401", "best_bid": "0.965", "best_ask": "0.992"}, {"asset_id": "114492877966140684018682752756008128367968333531744283465420223400327242203881", "price": "0.427", "size": "25", "side": "SELL", "hash": "78f2dc5b7a4292949de45b9bf8e04eeb74bad3c6", "best_bid": "0.008", "best_ask": "0.035"}], "timestamp": "1769384439663", "event_type": "price_change"}}
{"_local_timestamp": "2026-01-25T23:40:39.754023+00:00", "data": {"market": "0xc7aca5ec2ab64207578a5461e4f3d2ad2362a6ca9edcaa6b6f05553a7d541819", "price_changes": [{"asset_id": "46477055511928802305871870544961419728762162363024275463912888154597320120223", "price": "0.472", "size": "60", "side": "BUY", "hash": "e1e5021e9801236993b813c32aae3c1844120c92", "best_bid": "0.968", "best_ask": "0.984"}, {"asset_id": "13986990593551346934180369322143442319151776409512592545696715177800565940569", "price": "0.528", "size": "60", "side": "SELL", "hash": "fc8aa1478e7796d3dac087e73582d5a0760b908d", "best_bid": "0.016", "best_ask": "0.032"}], "timestamp": "1769384439686", "event_type": "price_change"}}
{"_local_timestamp": "2026-01-25T23:40:39.821779+00:00", "data": {"market": "0xc7aca5ec2ab64207578a5461e4f3d2ad2362a6ca9edcaa6b6f05553a7d541819", "price_changes": [{"asset_id": "46477055511928802305871870544961419728762162363024275463912888154597320120223", "price": "0.908", "size": "0", "side": "BUY", "hash": "008e7a17412d032e1b250b10b56430d9fd31e2f2", "best_bid": "0.968", "best_ask": "0.984"}, {"asset_id": "13986990593551346934180369322143442319151776409512592545696715177800565940569", "price": "0.092", "size": "0", "side": "SELL", "hash": "5302406f66eda3a6d18fcb3565b11833d76864dc", "best_bid": "0.016", "best_ask": "0.032"}], "timestamp": "1769384439753", "event_type": "price_change"}}
{"_local_timestamp": "2026-01-25T23:40:39.834207+00:00", "data": {"market": "0x8ec3037f6f989717b8321b9c6d297698c5827d3f17bc06fa276a6826a0b468bc", "price_changes": [{"asset_id": "63727355381184542281210853076888298871978167151761041112625093048354950500520", "price": "0.629", "size": "30", "side": "BUY", "hash": "d469ed6407eca4554889a4cd35bf49a4e1b27190", "best_bid": "0.995", "best_ask": "0.997"}, {"asset_id": "54960339021810821002608536313392642741296500124718788520040272866772532121044", "price": "0.371", "size": "30", "side": "SELL", "hash": "0dc29cbac1343593ad63bce554086f4e7b18dba9", "best_bid": "0.003", "best_ask": "0.005"}], "timestamp": "1769384439762", "event_type": "price_change"}}
{"_local_timestamp": "2026-01-25T23:40:39.835345+00:00", "data": {"market": "0x8ec3037f6f989717b8321b9c6d297698c5827d3f17bc06fa276a6826a0b468bc", "price_changes": [{"asset_id": "63727355381184542281210853076888298871978167151761041112625093048354950500520", "price": "0.629", "size": "185", "side": "BUY", "hash": "f9d2af25c2bc8cb5a700b65afb3080d4647f34e5", "best_bid": "0.995", "best_ask": "0.997"}, {"asset_id": "54960339021810821002608536313392642741296500124718788520040272866772532121044", "price": "0.371", "size": "185", "side": "SELL", "hash": "33837c567d07a4444992017530941fee147b31d2", "best_bid": "0.003", "best_ask": "0.005"}], "timestamp": "1769384439765", "event_type": "price_change"}}
{"_local_timestamp": "2026-01-25T23:40:39.892213+00:00", "data": {"market": "0xc7aca5ec2ab64207578a5461e4f3d2ad2362a6ca9edcaa6b6f05553a7d541819", "price_changes": [{"asset_id": "46477055511928802305871870544961419728762162363024275463912888154597320120223", "price": "0.473", "size": "629", "side": "BUY", "hash": "7432e94353afcd46fe3560b5843cab5ae3b475a5", "best_bid": "0.968", "best_ask": "0.984"}, {"asset_id": "13986990593551346934180369322143442319151776409512592545696715177800565940569", "price": "0.527", "size": "629", "side": "SELL", "hash": "1d0cf7dbbd00e40197025ae5d6d8536f83b716b7", "best_bid": "0.016", "best_ask": "0.032"}], "timestamp": "1769384439818", "event_type": "price_change"}}
{"_local_timestamp": "2026-01-25T23:40:39.922653+00:00", "data": {"market": "0xc7aca5ec2ab64207578a5461e4f3d2ad2362a6ca9edcaa6b6f05553a7d541819", "price_changes": [{"asset_id": "46477055511928802305871870544961419728762162363024275463912888154597320120223", "price": "0.475", "size": "210", "side": "BUY", "hash": "d394d7d5676c8bdd1844c83004bf988fa863f7bf", "best_bid": "0.968", "best_ask": "0.984"}, {"asset_id": "13986990593551346934180369322143442319151776409512592545696715177800565940569", "price": "0.525", "size": "210", "side": "SELL", "hash": "e027744b3028b6006134e3da1c7b207b27616eb6", "best_bid": "0.016", "best_ask": "0.032"}], "timestamp": "1769384439858", "event_type": "price_change"}}
{"_local_timestamp": "2026-01-25T23:40:39.925913+00:00", "data": {"market": "0xc7aca5ec2ab64207578a5461e4f3d2ad2362a6ca9edcaa6b6f05553a7d541819", "price_changes": [{"asset_id": "46477055511928802305871870544961419728762162363024275463912888154597320120223", "price": "0.91", "size": "25", "side": "BUY", "hash": "11ef84e3a7bdc13a90af89fe3fa59e06a5ba1537", "best_bid": "0.968", "best_ask": "0.984"}, {"asset_id": "13986990593551346934180369322143442319151776409512592545696715177800565940569", "price": "0.09", "size": "25", "side": "SELL", "hash": "0486849da70575d0a91f5546717999e37b035745", "best_bid": "0.016", "best_ask": "0.032"}], "timestamp": "1769384439861", "event_type": "price_change"}}
{"_local_timestamp": "2026-01-25T23:40:39.981278+00:00", "data": {"market": "0xc7aca5ec2ab64207578a5461e4f3d2ad2362a6ca9edcaa6b6f05553a7d541819", "price_changes": [{"asset_id": "46477055511928802305871870544961419728762162363024275463912888154597320120223", "price": "0.474", "size": "0", "side": "BUY", "hash": "e5e08368bf446e54bf9f6246900a73af081089f8", "best_bid": "0.968", "best_ask": "0.984"}, {"asset_id": "13986990593551346934180369322143442319151776409512592545696715177800565940569", "price": "0.526", "size": "0", "side": "SELL", "hash": "b9d89eeeca9f550be78e384b498a3e922be3026c", "best_bid": "0.016", "best_ask": "0.032"}], "timestamp": "1769384439897", "event_type": "price_change"}}
{"_local_timestamp": "2026-01-25T23:40:40.428443+00:00", "data": {"market": "0xc7aca5ec2ab64207578a5461e4f3d2ad2362a6ca9edcaa6b6f05553a7d541819", "price_changes": [{"asset_id": "46477055511928802305871870544961419728762162363024275463912888154597320120223", "price": "0.195", "size": "355", "side": "BUY", "hash": "4f71b0ccc725a9b30b9d96a9ad2022bdf282ba1e", "best_bid": "0.968", "best_ask": "0.984"}, {"asset_id": "13986990593551346934180369322143442319151776409512592545696715177800565940569", "price": "0.805", "size": "355", "side": "SELL", "hash": "301299aee26d6756b949544e0186041736b076c9", "best_bid": "0.016", "best_ask": "0.032"}], "timestamp": "1769384440254", "event_type": "price_change"}}
{"_local_timestamp": "2026-01-25T23:40:40.811673+00:00", "data": {"market": "0xc7aca5ec2ab64207578a5461e4f3d2ad2362a6ca9edcaa6b6f05553a7d541819", "price_changes": [{"asset_id": "46477055511928802305871870544961419728762162363024275463912888154597320120223", "price": "0.197", "size": "105.6", "side": "BUY", "hash": "6acca3cf81787ab1fc8a6ad8758d73dbcc233785", "best_bid": "0.968", "best_ask": "0.984"}, {"asset_id": "13986990593551346934180369322143442319151776409512592545696715177800565940569", "price": "0.803", "size": "105.6", "side": "SELL", "hash": "dadd3361fbe5c02f7a1043fc838391472700fbee", "best_bid": "0.016", "best_ask": "0.032"}], "timestamp": "1769384440621", "event_type": "price_change"}}
{"_local_timestamp": "2026-01-25T23:40:41.040481+00:00", "data": {"market": "0x8ec3037f6f989717b8321b9c6d297698c5827d3f17bc06fa276a6826a0b468bc", "price_changes": [{"asset_id": "63727355381184542281210853076888298871978167151761041112625093048354950500520", "price": "0.627", "size": "0", "side": "BUY", "hash": "f2a1a9d5cad9f0adb9a5d3b8b54df92b2173c1c5", "best_bid": "0.995", "best_ask": "0.997"}, {"asset_id": "54960339021810821002608536313392642741296500124718788520040272866772532121044", "price": "0.373", "size": "0", "side": "SELL", "hash": "e8bac5b954c09b288d2817098a7189cef6861f17", "best_bid": "0.003", "best_ask": "0.005"}], "timestamp": "1769384440972", "event_type": "price_change"}}
{"_local_timestamp": "2026-01-25T23:40:41.042420+00:00", "data": {"market": "0xc7aca5ec2ab64207578a5461e4f3d2ad2362a6ca9edcaa6b6f05553a7d541819", "price_changes": [{"asset_id": "46477055511928802305871870544961419728762162363024275463912888154597320120223", "price": "0.473", "size": "609", "side": "BUY", "hash": "f19edc925c50998009fc6922ccd19022b803a32a", "best_bid": "0.968", "best_ask": "0.984"}, {"asset_id": "13986990593551346934180369322143442319151776409512592545696715177800565940569", "price": "0.527", "size": "609", "side": "SELL", "hash": "bbfda47d3f5735fb70ec11a98a48129b875b55bb", "best_bid": "0.016", "best_ask": "0.032"}], "timestamp": "1769384440972", "event_type": "price_change"}}
{"_local_timestamp": "2026-01-25T23:40:41.044183+00:00", "data": {"market": "0x4b04e14bcde7be95db753c88f6fed57423835215bb41937406e75dc22a789b0c", "price_changes": [{"asset_id": "75013115303617466002500221618724536968904237026728502667764718978862356730825", "price": "0.656", "size": "0", "side": "BUY", "hash": "971ff0765d11134c565bd57bb8562ba04d66361e", "best_bid": "0.995", "best_ask": "0.998"}, {"asset_id": "195928349533315596595305126471738494775883003093487532708892885008234493544", "price": "0.344", "size": "0", "side": "SELL", "hash": "be25ae34d82eafbd4e89a8530b258c906f1b719f", "best_bid": "0.002", "best_ask": "0.005"}], "timestamp": "1769384440971", "event_type": "price_change"}}
{"_local_timestamp": "2026-01-25T23:40:41.045835+00:00", "data": {"market": "0x4cb1b09d2a17a1e21e459f4e431999bc3bfbb40cc9023b3354aa70e2d7d81875", "price_changes": [{"asset_id": "75701058868331201775069911407645821013233843572698963559250184599603027030054", "price": "0.572", "size": "0", "side": "BUY", "hash": "e2d36ac99168033cb05d6888b8b8d40dce04508d", "best_bid": "0.965", "best_ask": "0.992"}, {"asset_id": "114492877966140684018682752756008128367968333531744283465420223400327242203881", "price": "0.428", "size": "0", "side": "SELL", "hash": "6046e9bb407bac2e08a8f06185d542a714b0faeb", "best_bid": "0.008", "best_ask": "0.035"}], "timestamp": "1769384440971", "event_type": "price_change"}}
{"_local_timestamp": "2026-01-25T23:40:41.109964+00:00", "data": {"market": "0x8ec3037f6f989717b8321b9c6d297698c5827d3f17bc06fa276a6826a0b468bc", "price_changes": [{"asset_id": "63727355381184542281210853076888298871978167151761041112625093048354950500520", "price": "0.63", "size": "20", "side": "BUY", "hash": "ef2b6be96440825468517c3fcefa11960fec6004", "best_bid": "0.995", "best_ask": "0.997"}, {"asset_id": "54960339021810821002608536313392642741296500124718788520040272866772532121044", "price": "0.37", "size": "20", "side": "SELL", "hash": "3c265ab4d3e43a049fc28868e7ee8ceaab4043ce", "best_bid": "0.003", "best_ask": "0.005"}], "timestamp": "1769384441005", "event_type": "price_change"}}
{"_local_timestamp": "2026-01-25T23:40:41.111374+00:00", "data": {"market": "0x4cb1b09d2a17a1e21e459f4e431999bc3bfbb40cc9023b3354aa70e2d7d81875", "price_changes": [{"asset_id": "75701058868331201775069911407645821013233843572698963559250184599603027030054", "price": "0.574", "size": "20", "side": "BUY", "hash": "48cdbafef68628a43f57a38e038b561bc8ea085d", "best_bid": "0.965", "best_ask": "0.992"}, {"asset_id": "114492877966140684018682752756008128367968333531744283465420223400327242203881", "price": "0.426", "size": "20", "side": "SELL", "hash": "44b915b21bbd665f5cea1b95cfc8c3af485b3e61", "best_bid": "0.008", "best_ask": "0.035"}], "timestamp": "1769384441005", "event_type": "price_change"}}
{"_local_timestamp": "2026-01-25T23:40:41.112516+00:00", "data": {"market": "0x4b04e14bcde7be95db753c88f6fed57423835215bb41937406e75dc22a789b0c", "price_changes": [{"asset_id": "75013115303617466002500221618724536968904237026728502667764718978862356730825", "price": "0.658", "size": "20", "side": "BUY", "hash": "ee1b5697bc2af1c87c9819d1b2f0971d7f25356c", "best_bid": "0.995", "best_ask": "0.998"}, {"asset_id": "195928349533315596595305126471738494775883003093487532708892885008234493544", "price": "0.342", "size": "20", "side": "SELL", "hash": "ff5fa598f9705a18bc01af387db5b3c7108ffedd", "best_bid": "0.002", "best_ask": "0.005"}], "timestamp": "1769384441005", "event_type": "price_change"}}
{"_local_timestamp": "2026-01-25T23:40:41.113530+00:00", "data": {"market": "0xc7aca5ec2ab64207578a5461e4f3d2ad2362a6ca9edcaa6b6f05553a7d541819", "price_changes": [{"asset_id": "46477055511928802305871870544961419728762162363024275463912888154597320120223", "price": "0.476", "size": "20", "side": "BUY", "hash": "e763c7278aaec63218d8830ab5936249ca6d28d3", "best_bid": "0.968", "best_ask": "0.984"}, {"asset_id": "13986990593551346934180369322143442319151776409512592545696715177800565940569", "price": "0.524", "size": "20", "side": "SELL", "hash": "5d38181fea908c1ba61c39fd8012fd6bce41b133", "best_bid": "0.016", "best_ask": "0.032"}], "timestamp": "1769384441006", "event_type": "price_change"}}
{"_local_timestamp": "2026-01-25T23:40:41.192408+00:00", "data": {"market": "0x8ec3037f6f989717b8321b9c6d297698c5827d3f17bc06fa276a6826a0b468bc", "price_changes": [{"asset_id": "63727355381184542281210853076888298871978167151761041112625093048354950500520", "price": "0.629", "size": "30", "side": "BUY", "hash": "01f2a08e6dfd4aa1f15976bd5c7606a7bd260114", "best_bid": "0.995", "best_ask": "0.997"}, {"asset_id": "54960339021810821002608536313392642741296500124718788520040272866772532121044", "price": "0.371", "size": "30", "side": "SELL", "hash": "ad3ea604424f13f62ac8e177b1e57009039ef4f7", "best_bid": "0.003", "best_ask": "0.005"}], "timestamp": "1769384441109", "event_type": "price_change"}}
{"_local_timestamp": "2026-01-25T23:41:06.803234+00:00", "data": {"market": "0x8ec3037f6f989717b8321b9c6d297698c5827d3f17bc06fa276a6826a0b468bc", "price_changes": [{"asset_id": "54960339021810821002608536313392642741296500124718788520040272866772532121044", "price": "0.002", "size": "1166.04", "side": "BUY", "hash": "ea6e86c5b294c0021e566ce28b3fed7414905877", "best_bid": "0.003", "best_ask": "0.005"}, {"asset_id": "63727355381184542281210853076888298871978167151761041112625093048354950500520", "price": "0.998", "size": "1166.04", "side": "SELL", "hash": "749e54ac1b313f63ecfda52962d647c9d45f7389", "best_bid": "0.995", "best_ask": "0.997"}], "timestamp": "1769384466639", "event_type": "price_change"}}
{"_local_timestamp": "2026-01-25T23:41:06.863674+00:00", "data": {"market": "0x4b04e14bcde7be95db753c88f6fed57423835215bb41937406e75dc22a789b0c", "price_changes": [{"asset_id": "195928349533315596595305126471738494775883003093487532708892885008234493544", "price": "0.002", "size": "1166.01", "side": "BUY", "hash": "96cbdf705560e198e063658780c24771dc250e6e", "best_bid": "0.002", "best_ask": "0.005"}, {"asset_id": "75013115303617466002500221618724536968904237026728502667764718978862356730825", "price": "0.998", "size": "1166.01", "side": "SELL", "hash": "02c5f40a679679aa0a67cd737726e242c3102b4c", "best_bid": "0.995", "best_ask": "0.998"}], "timestamp": "1769384466647", "event_type": "price_change"}}
{"_local_timestamp": "2026-01-25T23:41:06.897011+00:00", "data": {"market": "0x4f864dda711ee273e6eb7925aada5d984da51a5f423122a00f6ae9532a3c28b9", "price_changes": [{"asset_id": "32968341948204373341622549015077301743176984559839089527120694005326340631965", "price": "0.003", "size": "355.22", "side": "BUY", "hash": "8c67a4d2bbb8c9a9399b1300988e108cb72cba0f", "best_bid": "0.008", "best_ask": "0.051"}, {"asset_id": "19845436317498992677729026362700087887065920346030569541585600013099473710639", "price": "0.997", "size": "355.22", "side": "SELL", "hash": "4969f9c5f95238655dd898ed684c816b8fdf0c20", "best_bid": "0.949", "best_ask": "0.992"}], "timestamp": "1769384466653", "event_type": "price_change"}}
{"_local_timestamp": "2026-01-25T23:41:09.750839+00:00", "data": {"market": "0xe478b515162e00d4b682e2e480e847487f5e824bbc5c7c1d4587ee68bcb4befe", "price_changes": [{"asset_id": "53729975633757169097007121898269744507742420238247181414435653260215633496084", "price": "0.14", "size": "442.75", "side": "SELL", "hash": "5d046f3b8137c3ced6da086d3b5a6b0608bfb9b6", "best_bid": "0.06", "best_ask": "0.08"}, {"asset_id": "53703724894913146397718355589619605161922119509512772920279877071805641165559", "price": "0.86", "size": "442.75", "side": "BUY", "hash": "2f95a1dfbf35d74a3f3e141e77d6132448ff06f4", "best_bid": "0.92", "best_ask": "0.94"}], "timestamp": "1769384469658", "event_type": "price_change"}}
{"_local_timestamp": "2026-01-25T23:41:09.933082+00:00", "data": {"market": "0xe478b515162e00d4b682e2e480e847487f5e824bbc5c7c1d4587ee68bcb4befe", "price_changes": [{"asset_id": "53729975633757169097007121898269744507742420238247181414435653260215633496084", "price": "0.14", "size": "524.75", "side": "SELL", "hash": "fd97fa4ed9aef88acc2798b1a4eb12de68443844", "best_bid": "0.06", "best_ask": "0.08"}, {"asset_id": "53703724894913146397718355589619605161922119509512772920279877071805641165559", "price": "0.86", "size": "524.75", "side": "BUY", "hash": "7c4362c25561587df058dbfda659ebcf7d7b1ea9", "best_bid": "0.92", "best_ask": "0.94"}], "timestamp": "1769384469849", "event_type": "price_change"}}
{"_local_timestamp": "2026-01-25T23:41:18.751412+00:00", "data": {"market": "0xe478b515162e00d4b682e2e480e847487f5e824bbc5c7c1d4587ee68bcb4befe", "price_changes": [{"asset_id": "53729975633757169097007121898269744507742420238247181414435653260215633496084", "price": "0.02", "size": "250", "side": "BUY", "hash": "e07f2ef3f475b2c130aaeb14bdd97a8bc606b642", "best_bid": "0.06", "best_ask": "0.08"}, {"asset_id": "53703724894913146397718355589619605161922119509512772920279877071805641165559", "price": "0.98", "size": "250", "side": "SELL", "hash": "a48060490896c36b695feaf2796e2cebb534d568", "best_bid": "0.92", "best_ask": "0.94"}], "timestamp": "1769384478679", "event_type": "price_change"}}
{"_local_timestamp": "2026-01-25T23:41:18.754126+00:00", "data": {"market": "0xe478b515162e00d4b682e2e480e847487f5e824bbc5c7c1d4587ee68bcb4befe", "price_changes": [{"asset_id": "53729975633757169097007121898269744507742420238247181414435653260215633496084", "price": "0.03", "size": "520", "side": "BUY", "hash": "e07f2ef3f475b2c130aaeb14bdd97a8bc606b642", "best_bid": "0.06", "best_ask": "0.08"}, {"asset_id": "53703724894913146397718355589619605161922119509512772920279877071805641165559", "price": "0.97", "size": "520", "side": "SELL", "hash": "a48060490896c36b695feaf2796e2cebb534d568", "best_bid": "0.92", "best_ask": "0.94"}], "timestamp": "1769384478679", "event_type": "price_change"}}
{"_local_timestamp": "2026-01-25T23:41:18.756954+00:00", "data": {"market": "0xe478b515162e00d4b682e2e480e847487f5e824bbc5c7c1d4587ee68bcb4befe", "price_changes": [{"asset_id": "53729975633757169097007121898269744507742420238247181414435653260215633496084", "price": "0.04", "size": "294.6", "side": "BUY", "hash": "e07f2ef3f475b2c130aaeb14bdd97a8bc606b642", "best_bid": "0.06", "best_ask": "0.08"}, {"asset_id": "53703724894913146397718355589619605161922119509512772920279877071805641165559", "price": "0.96", "size": "294.6", "side": "SELL", "hash": "a48060490896c36b695feaf2796e2cebb534d568", "best_bid": "0.92", "best_ask": "0.94"}], "timestamp": "1769384478679", "event_type": "price_change"}}
{"_local_timestamp": "2026-01-25T23:41:20.690305+00:00", "data": {"market": "0xe478b515162e00d4b682e2e480e847487f5e824bbc5c7c1d4587ee68bcb4befe", "price_changes": [{"asset_id": "53729975633757169097007121898269744507742420238247181414435653260215633496084", "price": "0.04", "size": "306.41", "side": "BUY", "hash": "c8a1baf58a794d681eb9d1f3a2302810bfca437a", "best_bid": "0.06", "best_ask": "0.08"}, {"asset_id": "53703724894913146397718355589619605161922119509512772920279877071805641165559", "price": "0.96", "size": "306.41", "side": "SELL", "hash": "e1b6ec6d1063a4e28cbd4e7f28df5e68e54a1f1d", "best_bid": "0.92", "best_ask": "0.94"}], "timestamp": "1769384480619", "event_type": "price_change"}}
{"_local_timestamp": "2026-01-25T23:41:20.692537+00:00", "data": {"market": "0xe478b515162e00d4b682e2e480e847487f5e824bbc5c7c1d4587ee68bcb4befe", "price_changes": [{"asset_id": "53729975633757169097007121898269744507742420238247181414435653260215633496084", "price": "0.05", "size": "234.19", "side": "BUY", "hash": "bb1c3e115d549e17818e30305c27e10bc8689f06", "best_bid": "0.06", "best_ask": "0.08"}, {"asset_id": "53703724894913146397718355589619605161922119509512772920279877071805641165559", "price": "0.95", "size": "234.19", "side": "SELL", "hash": "35f70a1863e79ee05de477b598d5bb640fa17558", "best_bid": "0.92", "best_ask": "0.94"}], "timestamp": "1769384480620", "event_type": "price_change"}}
{"_local_timestamp": "2026-01-25T23:41:20.697698+00:00", "data": {"market": "0xe478b515162e00d4b682e2e480e847487f5e824bbc5c7c1d4587ee68bcb4befe", "price_changes": [{"asset_id": "53729975633757169097007121898269744507742420238247181414435653260215633496084", "price": "0.03", "size": "536.19", "side": "BUY", "hash": "d55b2c86578bd330df48dccec563942d495edaa1", "best_bid": "0.06", "best_ask": "0.08"}, {"asset_id": "53703724894913146397718355589619605161922119509512772920279877071805641165559", "price": "0.97", "size": "536.19", "side": "SELL", "hash": "c0ee68f9fd40db69e3529ba81d5071201d56ac2a", "best_bid": "0.92", "best_ask": "0.94"}], "timestamp": "1769384480621", "event_type": "price_change"}}
{"_local_timestamp": "2026-01-25T23:41:20.698892+00:00", "data": {"market": "0xe478b515162e00d4b682e2e480e847487f5e824bbc5c7c1d4587ee68bcb4befe", "price_changes": [{"asset_id": "53729975633757169097007121898269744507742420238247181414435653260215633496084", "price": "0.02", "size": "274.98", "side": "BUY", "hash": "825e072eb950ae19bc0ff9d64ef24997ceddf993", "best_bid": "0.06", "best_ask": "0.08"}, {"asset_id": "53703724894913146397718355589619605161922119509512772920279877071805641165559", "price": "0.98", "size": "274.98", "side": "SELL", "hash": "5bfa3f13282cd7f8c2a3b2475406d032b9e69b7e", "best_bid": "0.92", "best_ask": "0.94"}], "timestamp": "1769384480622", "event_type": "price_change"}}
{"_local_timestamp": "2026-01-25T23:41:20.821155+00:00", "data": {"market": "0x4cb1b09d2a17a1e21e459f4e431999bc3bfbb40cc9023b3354aa70e2d7d81875", "price_changes": [{"asset_id": "75701058868331201775069911407645821013233843572698963559250184599603027030054", "price": "0.569", "size": "0", "side": "BUY", "hash": "037506db89c67f6be5989b9d3a4148e87ebcd77e", "best_bid": "0.965", "best_ask": "0.992"}, {"asset_id": "114492877966140684018682752756008128367968333531744283465420223400327242203881", "price": "0.431", "size": "0", "side": "SELL", "hash": "6260488d801bcaf188c1a0c3c7d42a98011d8f46", "best_bid": "0.008", "best_ask": "0.035"}], "timestamp": "1769384480751", "event_type": "price_change"}}
{"_local_timestamp": "2026-01-25T23:41:23.676151+00:00", "data": {"market": "0x4f864dda711ee273e6eb7925aada5d984da51a5f423122a00f6ae9532a3c28b9", "price_changes": [{"asset_id": "19845436317498992677729026362700087887065920346030569541585600013099473710639", "price": "0.925", "size": "158.33", "side": "BUY", "hash": "b1fed743bcd4f63d7230c00bd68f6af3b3cd7b07", "best_bid": "0.949", "best_ask": "0.992"}, {"asset_id": "32968341948204373341622549015077301743176984559839089527120694005326340631965", "price": "0.075", "size": "158.33", "side": "SELL", "hash": "2c94f7ae6e0f36538866d8e51147d67f36be767e", "best_bid": "0.008", "best_ask": "0.051"}], "timestamp": "1769384483609", "event_type": "price_change"}}
{"_local_timestamp": "2026-01-25T23:41:23.678295+00:00", "data": {"market": "0x4cb1b09d2a17a1e21e459f4e431999bc3bfbb40cc9023b3354aa70e2d7d81875", "price_changes": [{"asset_id": "75701058868331201775069911407645821013233843572698963559250184599603027030054", "price": "0.575", "size": "158.33", "side": "BUY", "hash": "ea6ad079ad2eed1b4777160895b49509da670b1c", "best_bid": "0.965", "best_ask": "0.992"}, {"asset_id": "114492877966140684018682752756008128367968333531744283465420223400327242203881", "price": "0.425", "size": "158.33", "side": "SELL", "hash": "686d2a57cecbff5a77f7357dfb5f413f66205f3a", "best_bid": "0.008", "best_ask": "0.035"}], "timestamp": "1769384483609", "event_type": "price_change"}}
{"_local_timestamp": "2026-01-25T23:41:23.679873+00:00", "data": {"market": "0x4b04e14bcde7be95db753c88f6fed57423835215bb41937406e75dc22a789b0c", "price_changes": [{"asset_id": "75013115303617466002500221618724536968904237026728502667764718978862356730825", "price": "0.658", "size": "178.33", "side": "BUY", "hash": "1b317bb6f80a83299f35eff760ec5c8f02eedaa4", "best_bid": "0.995", "best_ask": "0.998"}, {"asset_id": "195928349533315596595305126471738494775883003093487532708892885008234493544", "price": "0.342", "size": "178.33", "side": "SELL", "hash": "3181abe0e9f6f2410b95da72f0921b8c66349a06", "best_bid": "0.002", "best_ask": "0.005"}], "timestamp": "1769384483609", "event_type": "price_change"}}
{"_local_timestamp": "2026-01-25T23:41:23.682280+00:00", "data": {"market": "0x4f864dda711ee273e6eb7925aada5d984da51a5f423122a00f6ae9532a3c28b9", "price_changes": [{"asset_id": "19845436317498992677729026362700087887065920346030569541585600013099473710639", "price": "0.91", "size": "158.33", "side": "BUY", "hash": "35b0fab706a07919b78e8cbd2804b0da4e4c5255", "best_bid": "0.949", "best_ask": "0.992"}, {"asset_id": "32968341948204373341622549015077301743176984559839089527120694005326340631965", "price": "0.09", "size": "158.33", "side": "SELL", "hash": "ae9597776e0864fed86902109e897afc35f5b620", "best_bid": "0.008", "best_ask": "0.051"}], "timestamp": "1769384483610", "event_type": "price_change"}}
{"_local_timestamp": "2026-01-25T23:41:23.684792+00:00", "data": {"market": "0x4cb1b09d2a17a1e21e459f4e431999bc3bfbb40cc9023b3354aa70e2d7d81875", "price_changes": [{"asset_id": "75701058868331201775069911407645821013233843572698963559250184599603027030054", "price": "0.574", "size": "178.33", "side": "BUY", "hash": "f24f08ae2ea89aa680443c6c10f95ca586cddb95", "best_bid": "0.965", "best_ask": "0.992"}, {"asset_id": "114492877966140684018682752756008128367968333531744283465420223400327242203881", "price": "0.426", "size": "178.33", "side": "SELL", "hash": "824cd036635bcdc650d1012a5ec5f6c55ebbcd76", "best_bid": "0.008", "best_ask": "0.035"}], "timestamp": "1769384483610", "event_type": "price_change"}}
{"_local_timestamp": "2026-01-25T23:41:23.685945+00:00", "data": {"market": "0x4b04e14bcde7be95db753c88f6fed57423835215bb41937406e75dc22a789b0c", "price_changes": [{"asset_id": "75013115303617466002500221618724536968904237026728502667764718978862356730825", "price": "0.659", "size": "158.33", "side": "BUY", "hash": "cb01194e6355dab7e4efa9859eee84643c807b76", "best_bid": "0.995", "best_ask": "0.998"}, {"asset_id": "195928349533315596595305126471738494775883003093487532708892885008234493544", "price": "0.341", "size": "158.33", "side": "SELL", "hash": "ef9dc088892f199795456079f87988ed96ee31b6", "best_bid": "0.002", "best_ask": "0.005"}], "timestamp": "1769384483610", "event_type": "price_change"}}
{"_local_timestamp": "2026-01-25T23:41:24.330209+00:00", "data": {"market": "0x8ec3037f6f989717b8321b9c6d297698c5827d3f17bc06fa276a6826a0b468bc", "price_changes": [{"asset_id": "63727355381184542281210853076888298871978167151761041112625093048354950500520", "price": "0.983", "size": "0", "side": "BUY", "hash": "08afb0f51fb25394e8d23461794a6d12413816bc", "best_bid": "0.995", "best_ask": "0.997"}, {"asset_id": "54960339021810821002608536313392642741296500124718788520040272866772532121044", "price": "0.017", "size": "0", "side": "SELL", "hash": "21e7b6eeecd8955b5fb0540b2bb8cfb6b5eafbd7", "best_bid": "0.003", "best_ask": "0.005"}], "timestamp": "1769384484259", "event_type": "price_change"}}
{"_local_timestamp": "2026-01-25T23:41:25.316436+00:00", "data": {"market": "0x8ec3037f6f989717b8321b9c6d297698c5827d3f17bc06fa276a6826a0b468bc", "price_changes": [{"asset_id": "63727355381184542281210853076888298871978167151761041112625093048354950500520", "price": "0.984", "size": "50", "side": "BUY", "hash": "f09a6af783b86832e4447b55b2944fa27619e997", "best_bid": "0.995", "best_ask": "0.997"}, {"asset_id": "54960339021810821002608536313392642741296500124718788520040272866772532121044", "price": "0.016", "size": "50", "side": "SELL", "hash": "60999907fdb9484a98e98fd144dee296e6939380", "best_bid": "0.003", "best_ask": "0.005"}], "timestamp": "1769384485248", "event_type": "price_change"}}
{"_local_timestamp": "2026-01-25T23:41:25.867526+00:00", "data": {"market": "0x4b04e14bcde7be95db753c88f6fed57423835215bb41937406e75dc22a789b0c", "price_changes": [{"asset_id": "75013115303617466002500221618724536968904237026728502667764718978862356730825", "price": "0.658", "size": "158.33", "side": "BUY", "hash": "42e6f47d492d96acbe96207afccb02407fde5568", "best_bid": "0.995", "best_ask": "0.998"}, {"asset_id": "195928349533315596595305126471738494775883003093487532708892885008234493544", "price": "0.342", "size": "158.33", "side": "SELL", "hash": "db886a24a90a2cd6caf89844319420e668c82179", "best_bid": "0.002", "best_ask": "0.005"}], "timestamp": "1769384485790", "event_type": "price_change"}}
{"_local_timestamp": "2026-01-25T23:41:25.871753+00:00", "data": {"market": "0x4cb1b09d2a17a1e21e459f4e431999bc3bfbb40cc9023b3354aa70e2d7d81875", "price_changes": [{"asset_id": "75701058868331201775069911407645821013233843572698963559250184599603027030054", "price": "0.574", "size": "158.33", "side": "BUY", "hash": "493d9fd2cd6e1cb513af2f310d94234a3d3f28ed", "best_bid": "0.965", "best_ask": "0.992"}, {"asset_id": "114492877966140684018682752756008128367968333531744283465420223400327242203881", "price": "0.426", "size": "158.33", "side": "SELL", "hash": "e8d43fa7435d4e977bf621c3783b50031f93a8e3", "best_bid": "0.008", "best_ask": "0.035"}], "timestamp": "1769384485790", "event_type": "price_change"}}
{"_local_timestamp": "2026-01-25T23:41:25.886726+00:00", "data": {"market": "0x4b04e14bcde7be95db753c88f6fed57423835215bb41937406e75dc22a789b0c", "price_changes": [{"asset_id": "75013115303617466002500221618724536968904237026728502667764718978862356730825", "price": "0.66", "size": "20", "side": "BUY", "hash": "d3fc2a8e170cb1cb546971c09d9d13bddc0fa068", "best_bid": "0.995", "best_ask": "0.998"}, {"asset_id": "195928349533315596595305126471738494775883003093487532708892885008234493544", "price": "0.34", "size": "20", "side": "SELL", "hash": "d3242729f57d24c4c506dca798193779428b8506", "best_bid": "0.002", "best_ask": "0.005"}], "timestamp": "1769384485815", "event_type": "price_change"}}
{"_local_timestamp": "2026-01-25T23:41:25.897019+00:00", "data": {"market": "0x4cb1b09d2a17a1e21e459f4e431999bc3bfbb40cc9023b3354aa70e2d7d81875", "price_changes": [{"asset_id": "75701058868331201775069911407645821013233843572698963559250184599603027030054", "price": "0.576", "size": "20", "side": "BUY", "hash": "73bfe79617cbac6b68e9a41373c21e040f8e504c", "best_bid": "0.965", "best_ask": "0.992"}, {"asset_id": "114492877966140684018682752756008128367968333531744283465420223400327242203881", "price": "0.424", "size": "20", "side": "SELL", "hash": "90b50b6284e15a6cf1d1c4f6cebd78f00d6b187b", "best_bid": "0.008", "best_ask": "0.035"}], "timestamp": "1769384485815", "event_type": "price_change"}}
{"_local_timestamp": "2026-01-25T23:41:36.549027+00:00", "data": {"market": "0x4f864dda711ee273e6eb7925aada5d984da51a5f423122a00f6ae9532a3c28b9", "price_changes": [{"asset_id": "19845436317498992677729026362700087887065920346030569541585600013099473710639", "price": "0.91", "size": "0", "side": "BUY", "hash": "a9c284746fd48a894afc0b1718dd0692a5253d2d", "best_bid": "0.949", "best_ask": "0.992"}, {"asset_id": "32968341948204373341622549015077301743176984559839089527120694005326340631965", "price": "0.09", "size": "0", "side": "SELL", "hash": "57f6ff4c359030136f0d16b9904427dbc0cd29bb", "best_bid": "0.008", "best_ask": "0.051"}], "timestamp": "1769384496476", "event_type": "price_change"}}
{"_local_timestamp": "2026-01-25T23:41:46.959285+00:00", "data": {"market": "0xe478b515162e00d4b682e2e480e847487f5e824bbc5c7c1d4587ee68bcb4befe", "price_changes": [{"asset_id": "53729975633757169097007121898269744507742420238247181414435653260215633496084", "price": "0.05", "size": "225", "side": "BUY", "hash": "21ca6c50bb16e471908f1ee95ac302b0a3d1e712", "best_bid": "0.06", "best_ask": "0.08"}, {"asset_id": "53703724894913146397718355589619605161922119509512772920279877071805641165559", "price": "0.95", "size": "225", "side": "SELL", "hash": "b3c9c954b716b90c697bbb2acf460046d5ead2ec", "best_bid": "0.92", "best_ask": "0.94"}], "timestamp": "1769384506886", "event_type": "price_change"}}
{"_local_timestamp": "2026-01-25T23:41:49.059632+00:00", "data": {"market": "0x4f864dda711ee273e6eb7925aada5d984da51a5f423122a00f6ae9532a3c28b9", "price_changes": [{"asset_id": "19845436317498992677729026362700087887065920346030569541585600013099473710639", "price": "0.925", "size": "0", "side": "BUY", "hash": "4bf6e8036e2439be733b030808479ac8e088e67d", "best_bid": "0.949", "best_ask": "0.992"}, {"asset_id": "32968341948204373341622549015077301743176984559839089527120694005326340631965", "price": "0.075", "size": "0", "side": "SELL", "hash": "975df40f94a548e79821e36973f3a47f5c6271e4", "best_bid": "0.008", "best_ask": "0.051"}], "timestamp": "1769384508969", "event_type": "price_change"}}
{"_local_timestamp": "2026-01-25T23:41:49.062299+00:00", "data": {"market": "0x4cb1b09d2a17a1e21e459f4e431999bc3bfbb40cc9023b3354aa70e2d7d81875", "price_changes": [{"asset_id": "75701058868331201775069911407645821013233843572698963559250184599603027030054", "price": "0.575", "size": "0", "side": "BUY", "hash": "b4e149fcad0fb91774edd49833f1d1718ad143b2", "best_bid": "0.965", "best_ask": "0.992"}, {"asset_id": "114492877966140684018682752756008128367968333531744283465420223400327242203881", "price": "0.425", "size": "0", "side": "SELL", "hash": "6fac6eaedeef584bacbe6a3dc695a71090a915d9", "best_bid": "0.008", "best_ask": "0.035"}], "timestamp": "1769384508968", "event_type": "price_change"}}
{"_local_timestamp": "2026-01-25T23:41:49.063883+00:00", "data": {"market": "0x4cb1b09d2a17a1e21e459f4e431999bc3bfbb40cc9023b3354aa70e2d7d81875", "price_changes": [{"asset_id": "75701058868331201775069911407645821013233843572698963559250184599603027030054", "price": "0.574", "size": "0", "side": "BUY", "hash": "b4e149fcad0fb91774edd49833f1d1718ad143b2", "best_bid": "0.965", "best_ask": "0.992"}, {"asset_id": "114492877966140684018682752756008128367968333531744283465420223400327242203881", "price": "0.426", "size": "0", "side": "SELL", "hash": "6fac6eaedeef584bacbe6a3dc695a71090a915d9", "best_bid": "0.008", "best_ask": "0.035"}], "timestamp": "1769384508968", "event_type": "price_change"}}
{"_local_timestamp": "2026-01-25T23:41:49.067250+00:00", "data": {"market": "0x4b04e14bcde7be95db753c88f6fed57423835215bb41937406e75dc22a789b0c", "price_changes": [{"asset_id": "75013115303617466002500221618724536968904237026728502667764718978862356730825", "price": "0.659", "size": "0", "side": "BUY", "hash": "7426bb5f1ab7b33968847f55ae5fd8209c0afd50", "best_bid": "0.995", "best_ask": "0.998"}, {"asset_id": "195928349533315596595305126471738494775883003093487532708892885008234493544", "price": "0.341", "size": "0", "side": "SELL", "hash": "c96482c8b7768dfe7468b394270ca895e6a8085f", "best_bid": "0.002", "best_ask": "0.005"}], "timestamp": "1769384508968", "event_type": "price_change"}}
{"_local_timestamp": "2026-01-25T23:41:49.068398+00:00", "data": {"market": "0x4b04e14bcde7be95db753c88f6fed57423835215bb41937406e75dc22a789b0c", "price_changes": [{"asset_id": "75013115303617466002500221618724536968904237026728502667764718978862356730825", "price": "0.658", "size": "0", "side": "BUY", "hash": "7426bb5f1ab7b33968847f55ae5fd8209c0afd50", "best_bid": "0.995", "best_ask": "0.998"}, {"asset_id": "195928349533315596595305126471738494775883003093487532708892885008234493544", "price": "0.342", "size": "0", "side": "SELL", "hash": "c96482c8b7768dfe7468b394270ca895e6a8085f", "best_bid": "0.002", "best_ask": "0.005"}], "timestamp": "1769384508968", "event_type": "price_change"}}
{"_local_timestamp": "2026-01-25T23:41:49.244599+00:00", "data": {"market": "0x4cb1b09d2a17a1e21e459f4e431999bc3bfbb40cc9023b3354aa70e2d7d81875", "price_changes": [{"asset_id": "75701058868331201775069911407645821013233843572698963559250184599603027030054", "price": "0.566", "size": "0", "side": "BUY", "hash": "11e92b165783c0c72299b922704408f848b174de", "best_bid": "0.965", "best_ask": "0.992"}, {"asset_id": "114492877966140684018682752756008128367968333531744283465420223400327242203881", "price": "0.434", "size": "0", "side": "SELL", "hash": "5eeb4ea8d12579bb17566c4776d64050ed5c1f3a", "best_bid": "0.008", "best_ask": "0.035"}], "timestamp": "1769384509175", "event_type": "price_change"}}
{"_local_timestamp": "2026-01-25T23:41:49.245926+00:00", "data": {"market": "0x4b04e14bcde7be95db753c88f6fed57423835215bb41937406e75dc22a789b0c", "price_changes": [{"asset_id": "75013115303617466002500221618724536968904237026728502667764718978862356730825", "price": "0.651", "size": "614", "side": "BUY", "hash": "fc64206bc5dc21233a274c5132f8688b76d5e623", "best_bid": "0.995", "best_ask": "0.998"}, {"asset_id": "195928349533315596595305126471738494775883003093487532708892885008234493544", "price": "0.349", "size": "614", "side": "SELL", "hash": "2e4d42fb14dbc98eb3185bc3b64c4dc9f2c63f3c", "best_bid": "0.002", "best_ask": "0.005"}], "timestamp": "1769384509175", "event_type": "price_change"}}
{"_local_timestamp": "2026-01-25T23:41:49.353049+00:00", "data": {"market": "0x4b04e14bcde7be95db753c88f6fed57423835215bb41937406e75dc22a789b0c", "price_changes": [{"asset_id": "75013115303617466002500221618724536968904237026728502667764718978862356730825", "price": "0.661", "size": "258", "side": "BUY", "hash": "e74d5a47a70e848d788038980f043a9cfb31ef4e", "best_bid": "0.995", "best_ask": "0.998"}, {"asset_id": "195928349533315596595305126471738494775883003093487532708892885008234493544", "price": "0.339", "size": "258", "side": "SELL", "hash": "fe31c0cca0f31d40876dea26784e5783b61aab02", "best_bid": "0.002", "best_ask": "0.005"}], "timestamp": "1769384509277", "event_type": "price_change"}}
{"_local_timestamp": "2026-01-25T23:41:49.354303+00:00", "data": {"market": "0x4cb1b09d2a17a1e21e459f4e431999bc3bfbb40cc9023b3354aa70e2d7d81875", "price_changes": [{"asset_id": "75701058868331201775069911407645821013233843572698963559250184599603027030054", "price": "0.577", "size": "257", "side": "BUY", "hash": "999896746b27297ce1c13b79e9a07a3a5635ac54", "best_bid": "0.965", "best_ask": "0.992"}, {"asset_id": "114492877966140684018682752756008128367968333531744283465420223400327242203881", "price": "0.423", "size": "257", "side": "SELL", "hash": "fdac56929f25f0aba62906e584e387b0048a782f", "best_bid": "0.008", "best_ask": "0.035"}], "timestamp": "1769384509277", "event_type": "price_change"}}
{"_local_timestamp": "2026-01-25T23:41:49.355283+00:00", "data": {"market": "0x4cb1b09d2a17a1e21e459f4e431999bc3bfbb40cc9023b3354aa70e2d7d81875", "price_changes": [{"asset_id": "75701058868331201775069911407645821013233843572698963559250184599603027030054", "price": "0.577", "size": "287", "side": "BUY", "hash": "6c36c3d136208af474ab18e70b1ca27047cec580", "best_bid": "0.965", "best_ask": "0.992"}, {"asset_id": "114492877966140684018682752756008128367968333531744283465420223400327242203881", "price": "0.423", "size": "287", "side": "SELL", "hash": "5b09440dc0194f4bbe8ce9c04dad1f5e5579e9d4", "best_bid": "0.008", "best_ask": "0.035"}], "timestamp": "1769384509278", "event_type": "price_change"}}
{"_local_timestamp": "2026-01-25T23:41:49.356456+00:00", "data": {"market": "0x4b04e14bcde7be95db753c88f6fed57423835215bb41937406e75dc22a789b0c", "price_changes": [{"asset_id": "75013115303617466002500221618724536968904237026728502667764718978862356730825", "price": "0.661", "size": "288", "side": "BUY", "hash": "6f808b220b067a7738c74891e385e05c1a00d19d", "best_bid": "0.995", "best_ask": "0.998"}, {"asset_id": "195928349533315596595305126471738494775883003093487532708892885008234493544", "price": "0.339", "size": "288", "side": "SELL", "hash": "4fecd6c098037da873fef463b986fe6a5ca6f68d", "best_bid": "0.002", "best_ask": "0.005"}], "timestamp": "1769384509278", "event_type": "price_change"}}
{"_local_timestamp": "2026-01-25T23:41:50.254870+00:00", "data": {"market": "0x4cb1b09d2a17a1e21e459f4e431999bc3bfbb40cc9023b3354aa70e2d7d81875", "price_changes": [{"asset_id": "75701058868331201775069911407645821013233843572698963559250184599603027030054", "price": "0.576", "size": "0", "side": "BUY", "hash": "1b5e0cfd087779a1a71d9015c3e2ff1a14edd9c2", "best_bid": "0.965", "best_ask": "0.992"}, {"asset_id": "114492877966140684018682752756008128367968333531744283465420223400327242203881", "price": "0.424", "size": "0", "side": "SELL", "hash": "57790d6f69b7042bd52efdd03f510809fcc2d9b2", "best_bid": "0.008", "best_ask": "0.035"}], "timestamp": "1769384510187", "event_type": "price_change"}}
{"_local_timestamp": "2026-01-25T23:41:50.256064+00:00", "data": {"market": "0x4b04e14bcde7be95db753c88f6fed57423835215bb41937406e75dc22a789b0c", "price_changes": [{"asset_id": "75013115303617466002500221618724536968904237026728502667764718978862356730825", "price": "0.66", "size": "0", "side": "BUY", "hash": "0a2f39919e557eed5528037fa0d5bb88a47bff4c", "best_bid": "0.995", "best_ask": "0.998"}, {"asset_id": "195928349533315596595305126471738494775883003093487532708892885008234493544", "price": "0.34", "size": "0", "side": "SELL", "hash": "65a83a9a77a726855c59bd72fbbc12c8f7c292ab", "best_bid": "0.002", "best_ask": "0.005"}], "timestamp": "1769384510187", "event_type": "price_change"}}
{"_local_timestamp": "2026-01-25T23:41:50.281709+00:00", "data": {"market": "0x4b04e14bcde7be95db753c88f6fed57423835215bb41937406e75dc22a789b0c", "price_changes": [{"asset_id": "75013115303617466002500221618724536968904237026728502667764718978862356730825", "price": "0.662", "size": "20", "side": "BUY", "hash": "b37b75e6e139dd56ab6284fe97a4be8788cd9a59", "best_bid": "0.995", "best_ask": "0.998"}, {"asset_id": "195928349533315596595305126471738494775883003093487532708892885008234493544", "price": "0.338", "size": "20", "side": "SELL", "hash": "34be0ae26ef1f876de12b2a10e3d76e88487ab63", "best_bid": "0.002", "best_ask": "0.005"}], "timestamp": "1769384510214", "event_type": "price_change"}}
{"_local_timestamp": "2026-01-25T23:41:50.282818+00:00", "data": {"market": "0x4cb1b09d2a17a1e21e459f4e431999bc3bfbb40cc9023b3354aa70e2d7d81875", "price_changes": [{"asset_id": "75701058868331201775069911407645821013233843572698963559250184599603027030054", "price": "0.578", "size": "20", "side": "BUY", "hash": "fc9f3de79ac65fdacee5a191a9e3d48bb653a12f", "best_bid": "0.965", "best_ask": "0.992"}, {"asset_id": "114492877966140684018682752756008128367968333531744283465420223400327242203881", "price": "0.422", "size": "20", "side": "SELL", "hash": "fab5a4506e09fbb0931b9a1fad1ee2adc4ed5fa0", "best_bid": "0.008", "best_ask": "0.035"}], "timestamp": "1769384510214", "event_type": "price_change"}}
{"_local_timestamp": "2026-01-25T23:41:50.444533+00:00", "data": {"market": "0x4b04e14bcde7be95db753c88f6fed57423835215bb41937406e75dc22a789b0c", "price_changes": [{"asset_id": "75013115303617466002500221618724536968904237026728502667764718978862356730825", "price": "0.661", "size": "30", "side": "BUY", "hash": "91409899401b13a88231e1c0d1244c71174f94cf", "best_bid": "0.995", "best_ask": "0.998"}, {"asset_id": "195928349533315596595305126471738494775883003093487532708892885008234493544", "price": "0.339", "size": "30", "side": "SELL", "hash": "b789df5d12905a66e28f607cc69170001c5a5723", "best_bid": "0.002", "best_ask": "0.005"}], "timestamp": "1769384510363", "event_type": "price_change"}}
{"_local_timestamp": "2026-01-25T23:41:50.457235+00:00", "data": {"market": "0x4cb1b09d2a17a1e21e459f4e431999bc3bfbb40cc9023b3354aa70e2d7d81875", "price_changes": [{"asset_id": "75701058868331201775069911407645821013233843572698963559250184599603027030054", "price": "0.577", "size": "30", "side": "BUY", "hash": "84b43467d1ca26d98089c603e58cab59760688c1", "best_bid": "0.965", "best_ask": "0.992"}, {"asset_id": "114492877966140684018682752756008128367968333531744283465420223400327242203881", "price": "0.423", "size": "30", "side": "SELL", "hash": "c7dc0952a6549ed90f2c6262ece127d2ef2847ec", "best_bid": "0.008", "best_ask": "0.035"}], "timestamp": "1769384510363", "event_type": "price_change"}}
{"_local_timestamp": "2026-01-25T23:42:22.010996+00:00", "data": {"market": "0xc7aca5ec2ab64207578a5461e4f3d2ad2362a6ca9edcaa6b6f05553a7d541819", "price_changes": [{"asset_id": "46477055511928802305871870544961419728762162363024275463912888154597320120223", "price": "0.197", "size": "100", "side": "BUY", "hash": "0a15287b518d5230aa02efae28ff7a049d3ae5c1", "best_bid": "0.968", "best_ask": "0.984"}, {"asset_id": "13986990593551346934180369322143442319151776409512592545696715177800565940569", "price": "0.803", "size": "100", "side": "SELL", "hash": "4bc2192b8b59bd4dbd38c5fe673195070590ae04", "best_bid": "0.016", "best_ask": "0.032"}], "timestamp": "1769384541878", "event_type": "price_change"}}
{"_local_timestamp": "2026-01-25T23:42:24.618265+00:00", "data": {"market": "0xc7aca5ec2ab64207578a5461e4f3d2ad2362a6ca9edcaa6b6f05553a7d541819", "price_changes": [{"asset_id": "46477055511928802305871870544961419728762162363024275463912888154597320120223", "price": "0.262", "size": "100", "side": "BUY", "hash": "67d0bb51da0daf76632554810b973e100b8f74b6", "best_bid": "0.968", "best_ask": "0.984"}, {"asset_id": "13986990593551346934180369322143442319151776409512592545696715177800565940569", "price": "0.738", "size": "100", "side": "SELL", "hash": "501cf5d11fbe4a25a05567b1190ebcd117e61e5b", "best_bid": "0.016", "best_ask": "0.032"}], "timestamp": "1769384544473", "event_type": "price_change"}}
{"_local_timestamp": "2026-01-25T23:42:24.634800+00:00", "data": {"market": "0xc7aca5ec2ab64207578a5461e4f3d2ad2362a6ca9edcaa6b6f05553a7d541819", "price_changes": [{"asset_id": "46477055511928802305871870544961419728762162363024275463912888154597320120223", "price": "0.197", "size": "0", "side": "BUY", "hash": "67d0bb51da0daf76632554810b973e100b8f74b6", "best_bid": "0.968", "best_ask": "0.984"}, {"asset_id": "13986990593551346934180369322143442319151776409512592545696715177800565940569", "price": "0.803", "size": "0", "side": "SELL", "hash": "501cf5d11fbe4a25a05567b1190ebcd117e61e5b", "best_bid": "0.016", "best_ask": "0.032"}], "timestamp": "1769384544473", "event_type": "price_change"}}
{"_local_timestamp": "2026-01-25T23:42:25.051593+00:00", "data": {"market": "0xc7aca5ec2ab64207578a5461e4f3d2ad2362a6ca9edcaa6b6f05553a7d541819", "price_changes": [{"asset_id": "46477055511928802305871870544961419728762162363024275463912888154597320120223", "price": "0.263", "size": "1646", "side": "BUY", "hash": "828fb575285bbd9d333a4e3f7969b7107b5dea0d", "best_bid": "0.968", "best_ask": "0.984"}, {"asset_id": "13986990593551346934180369322143442319151776409512592545696715177800565940569", "price": "0.737", "size": "1646", "side": "SELL", "hash": "27540b6ca86c50576fa7e24d2f6f6932179daf9d", "best_bid": "0.016", "best_ask": "0.032"}], "timestamp": "1769384544895", "event_type": "price_change"}}
{"_local_timestamp": "2026-01-25T23:42:25.067958+00:00", "data": {"market": "0xc7aca5ec2ab64207578a5461e4f3d2ad2362a6ca9edcaa6b6f05553a7d541819", "price_changes": [{"asset_id": "46477055511928802305871870544961419728762162363024275463912888154597320120223", "price": "0.195", "size": "455", "side": "BUY", "hash": "f434271dbd38b5aaf93e12c7869a2559b1101d3e", "best_bid": "0.968", "best_ask": "0.984"}, {"asset_id": "13986990593551346934180369322143442319151776409512592545696715177800565940569", "price": "0.805", "size": "455", "side": "SELL", "hash": "03774b273bae3e366693c2b0ff445e2ca0b2fac1", "best_bid": "0.016", "best_ask": "0.032"}], "timestamp": "1769384544899", "event_type": "price_change"}}
{"_local_timestamp": "2026-01-25T23:42:25.611641+00:00", "data": {"market": "0xc7aca5ec2ab64207578a5461e4f3d2ad2362a6ca9edcaa6b6f05553a7d541819", "price_changes": [{"asset_id": "46477055511928802305871870544961419728762162363024275463912888154597320120223", "price": "0.198", "size": "5.58", "side": "BUY", "hash": "63793cbe22148b8b267b7c3058e65c540fcc4121", "best_bid": "0.968", "best_ask": "0.984"}, {"asset_id": "13986990593551346934180369322143442319151776409512592545696715177800565940569", "price": "0.802", "size": "5.58", "side": "SELL", "hash": "43bde50bb6df62dd6c26948467240dda3e33d7da", "best_bid": "0.016", "best_ask": "0.032"}], "timestamp": "1769384545465", "event_type": "price_change"}}
{"_local_timestamp": "2026-01-25T23:43:01.169653+00:00", "data": {"market": "0xe478b515162e00d4b682e2e480e847487f5e824bbc5c7c1d4587ee68bcb4befe", "price_changes": [{"asset_id": "53729975633757169097007121898269744507742420238247181414435653260215633496084", "price": "0.05", "size": "175", "side": "BUY", "hash": "ff2602f6e29548e97ec593054bf3935618100ab0", "best_bid": "0.06", "best_ask": "0.08"}, {"asset_id": "53703724894913146397718355589619605161922119509512772920279877071805641165559", "price": "0.95", "size": "175", "side": "SELL", "hash": "f71f5d6a57d53c73abc6f830726e78c4fe4fa8ea", "best_bid": "0.92", "best_ask": "0.94"}], "timestamp": "1769384581001", "event_type": "price_change"}}
{"_local_timestamp": "2026-01-25T23:43:01.173171+00:00", "data": {"market": "0xe478b515162e00d4b682e2e480e847487f5e824bbc5c7c1d4587ee68bcb4befe", "price_changes": [{"asset_id": "53703724894913146397718355589619605161922119509512772920279877071805641165559", "price": "0.91", "size": "150", "side": "BUY", "hash": "8721a7bec548ac0886571514bf68aed3fda72d9c", "best_bid": "0.92", "best_ask": "0.94"}, {"asset_id": "53729975633757169097007121898269744507742420238247181414435653260215633496084", "price": "0.09", "size": "150", "side": "SELL", "hash": "25a53a6bb1c75ca615c8168190bd072ed9d1c33f", "best_bid": "0.06", "best_ask": "0.08"}], "timestamp": "1769384581005", "event_type": "price_change"}}
{"_local_timestamp": "2026-01-25T23:43:01.312580+00:00", "data": {"market": "0xc7aca5ec2ab64207578a5461e4f3d2ad2362a6ca9edcaa6b6f05553a7d541819", "price_changes": [{"asset_id": "46477055511928802305871870544961419728762162363024275463912888154597320120223", "price": "0.909", "size": "0", "side": "BUY", "hash": "a10d5c5a773c9971bb76cbf0f400228b0267b99d", "best_bid": "0.968", "best_ask": "0.984"}, {"asset_id": "13986990593551346934180369322143442319151776409512592545696715177800565940569", "price": "0.091", "size": "0", "side": "SELL", "hash": "32fba19cfbf817e69eab91696cab36f3c371f91d", "best_bid": "0.016", "best_ask": "0.032"}], "timestamp": "1769384581175", "event_type": "price_change"}}
{"_local_timestamp": "2026-01-25T23:43:01.313778+00:00", "data": {"market": "0x4f864dda711ee273e6eb7925aada5d984da51a5f423122a00f6ae9532a3c28b9", "price_changes": [{"asset_id": "19845436317498992677729026362700087887065920346030569541585600013099473710639", "price": "0.909", "size": "0", "side": "BUY", "hash": "9a2bcdfa3d5d8d145c50d6651a66b0cae8ba4c6d", "best_bid": "0.949", "best_ask": "0.992"}, {"asset_id": "32968341948204373341622549015077301743176984559839089527120694005326340631965", "price": "0.091", "size": "0", "side": "SELL", "hash": "0d2c09e0e64f4a4a2c565818c68298ead21456dc", "best_bid": "0.008", "best_ask": "0.051"}], "timestamp": "1769384581175", "event_type": "price_change"}}
{"_local_timestamp": "2026-01-25T23:43:01.333918+00:00", "data": {"market": "0xc7aca5ec2ab64207578a5461e4f3d2ad2362a6ca9edcaa6b6f05553a7d541819", "price_changes": [{"asset_id": "46477055511928802305871870544961419728762162363024275463912888154597320120223", "price": "0.91", "size": "0", "side": "BUY", "hash": "459fa3be98aaa83848dc7d2ea24ff1a6a21233ad", "best_bid": "0.968", "best_ask": "0.984"}, {"asset_id": "13986990593551346934180369322143442319151776409512592545696715177800565940569", "price": "0.09", "size": "0", "side": "SELL", "hash": "62dcb633247485a5a1b915c52e1317812addb7aa", "best_bid": "0.016", "best_ask": "0.032"}], "timestamp": "1769384581195", "event_type": "price_change"}}
{"_local_timestamp": "2026-01-25T23:43:01.477120+00:00", "data": {"market": "0x4f864dda711ee273e6eb7925aada5d984da51a5f423122a00f6ae9532a3c28b9", "price_changes": [{"asset_id": "19845436317498992677729026362700087887065920346030569541585600013099473710639", "price": "0.817", "size": "309", "side": "BUY", "hash": "d589a9a70a63883c08ea9a776c03d87d83270a4a", "best_bid": "0.949", "best_ask": "0.992"}, {"asset_id": "32968341948204373341622549015077301743176984559839089527120694005326340631965", "price": "0.183", "size": "309", "side": "SELL", "hash": "15c09f86e42e8a3b876a8493988e4774e47b96f5", "best_bid": "0.008", "best_ask": "0.051"}], "timestamp": "1769384581343", "event_type": "price_change"}}
{"_local_timestamp": "2026-01-25T23:43:01.480012+00:00", "data": {"market": "0xc7aca5ec2ab64207578a5461e4f3d2ad2362a6ca9edcaa6b6f05553a7d541819", "price_changes": [{"asset_id": "46477055511928802305871870544961419728762162363024275463912888154597320120223", "price": "0.907", "size": "20", "side": "BUY", "hash": "f096d3ff997471ffd59f623b04590d922c42af57", "best_bid": "0.968", "best_ask": "0.984"}, {"asset_id": "13986990593551346934180369322143442319151776409512592545696715177800565940569", "price": "0.093", "size": "20", "side": "SELL", "hash": "995877f4c08d2c70c325ae23686917a5fd586c01", "best_bid": "0.016", "best_ask": "0.032"}], "timestamp": "1769384581343", "event_type": "price_change"}}
{"_local_timestamp": "2026-01-25T23:43:01.481135+00:00", "data": {"market": "0x4f864dda711ee273e6eb7925aada5d984da51a5f423122a00f6ae9532a3c28b9", "price_changes": [{"asset_id": "19845436317498992677729026362700087887065920346030569541585600013099473710639", "price": "0.91", "size": "20", "side": "BUY", "hash": "fc730a1e30aec593d6ad3e47aeaf0d4da4102c1e", "best_bid": "0.949", "best_ask": "0.992"}, {"asset_id": "32968341948204373341622549015077301743176984559839089527120694005326340631965", "price": "0.09", "size": "20", "side": "SELL", "hash": "7eec5fdc8b2f43c7e63ef94071b00276c684b18a", "best_bid": "0.008", "best_ask": "0.051"}], "timestamp": "1769384581344", "event_type": "price_change"}}
{"_local_timestamp": "2026-01-25T23:43:01.482163+00:00", "data": {"market": "0xc7aca5ec2ab64207578a5461e4f3d2ad2362a6ca9edcaa6b6f05553a7d541819", "price_changes": [{"asset_id": "46477055511928802305871870544961419728762162363024275463912888154597320120223", "price": "0.477", "size": "400", "side": "BUY", "hash": "9277711bf209c20444bcc2dbabda85f5f200525f", "best_bid": "0.968", "best_ask": "0.984"}, {"asset_id": "13986990593551346934180369322143442319151776409512592545696715177800565940569", "price": "0.523", "size": "400", "side": "SELL", "hash": "c6abd0208564da7a0f3834c5a9a5d92c7d79aabf", "best_bid": "0.016", "best_ask": "0.032"}], "timestamp": "1769384581344", "event_type": "price_change"}}
{"_local_timestamp": "2026-01-25T23:43:01.622692+00:00", "data": {"market": "0xc7aca5ec2ab64207578a5461e4f3d2ad2362a6ca9edcaa6b6f05553a7d541819", "price_changes": [{"asset_id": "46477055511928802305871870544961419728762162363024275463912888154597320120223", "price": "0.473", "size": "209", "side": "BUY", "hash": "ce3fc7432c8be13472462b9393b6a19f676ac107", "best_bid": "0.968", "best_ask": "0.984"}, {"asset_id": "13986990593551346934180369322143442319151776409512592545696715177800565940569", "price": "0.527", "size": "209", "side": "SELL", "hash": "47f79377589a34b794b9d3869b1c89421c47c287", "best_bid": "0.016", "best_ask": "0.032"}], "timestamp": "1769384581484", "event_type": "price_change"}}
{"_local_timestamp": "2026-01-25T23:43:01.748734+00:00", "data": {"market": "0xc7aca5ec2ab64207578a5461e4f3d2ad2362a6ca9edcaa6b6f05553a7d541819", "price_changes": [{"asset_id": "46477055511928802305871870544961419728762162363024275463912888154597320120223", "price": "0.478", "size": "400", "side": "BUY", "hash": "717736bbfadb859e961e18fae5e7603b4c8d4392", "best_bid": "0.968", "best_ask": "0.984"}, {"asset_id": "13986990593551346934180369322143442319151776409512592545696715177800565940569", "price": "0.522", "size": "400", "side": "SELL", "hash": "09085501041fd0fa27b3ddfd5345c24fd63fdf99", "best_bid": "0.016", "best_ask": "0.032"}], "timestamp": "1769384581614", "event_type": "price_change"}}
{"_local_timestamp": "2026-01-25T23:43:01.819356+00:00", "data": {"market": "0xc7aca5ec2ab64207578a5461e4f3d2ad2362a6ca9edcaa6b6f05553a7d541819", "price_changes": [{"asset_id": "46477055511928802305871870544961419728762162363024275463912888154597320120223", "price": "0.475", "size": "0", "side": "BUY", "hash": "20ac7c39f51fdeaba6418fb549f450e496a90355", "best_bid": "0.968", "best_ask": "0.984"}, {"asset_id": "13986990593551346934180369322143442319151776409512592545696715177800565940569", "price": "0.525", "size": "0", "side": "SELL", "hash": "e29e7adcc5253f11fcb36d81d818fb2484f9de65", "best_bid": "0.016", "best_ask": "0.032"}], "timestamp": "1769384581681", "event_type": "price_change"}}
{"_local_timestamp": "2026-01-25T23:43:01.872815+00:00", "data": {"market": "0xc7aca5ec2ab64207578a5461e4f3d2ad2362a6ca9edcaa6b6f05553a7d541819", "price_changes": [{"asset_id": "46477055511928802305871870544961419728762162363024275463912888154597320120223", "price": "0.473", "size": "0", "side": "BUY", "hash": "5b0d9a0f678c5f6fb438a03ec68667c27c2b2d15", "best_bid": "0.968", "best_ask": "0.984"}, {"asset_id": "13986990593551346934180369322143442319151776409512592545696715177800565940569", "price": "0.527", "size": "0", "side": "SELL", "hash": "5216769c1c559b4ef4a65f100e14d2b60bea0a10", "best_bid": "0.016", "best_ask": "0.032"}], "timestamp": "1769384581743", "event_type": "price_change"}}
{"_local_timestamp": "2026-01-25T23:43:01.908508+00:00", "data": {"market": "0xc7aca5ec2ab64207578a5461e4f3d2ad2362a6ca9edcaa6b6f05553a7d541819", "price_changes": [{"asset_id": "46477055511928802305871870544961419728762162363024275463912888154597320120223", "price": "0.479", "size": "208", "side": "BUY", "hash": "0c98dbae5ef7a20bf18ae816d3f3a7cef3d46c7d", "best_bid": "0.968", "best_ask": "0.984"}, {"asset_id": "13986990593551346934180369322143442319151776409512592545696715177800565940569", "price": "0.521", "size": "208", "side": "SELL", "hash": "d4dd448b7a028515f0a67eb133d8c210ad1ba55f", "best_bid": "0.016", "best_ask": "0.032"}], "timestamp": "1769384581771", "event_type": "price_change"}}
{"_local_timestamp": "2026-01-25T23:43:01.909576+00:00", "data": {"market": "0xc7aca5ec2ab64207578a5461e4f3d2ad2362a6ca9edcaa6b6f05553a7d541819", "price_changes": [{"asset_id": "46477055511928802305871870544961419728762162363024275463912888154597320120223", "price": "0.479", "size": "228", "side": "BUY", "hash": "954e96b7951b4e9231f256e9eff55f5c05bcb2a9", "best_bid": "0.968", "best_ask": "0.984"}, {"asset_id": "13986990593551346934180369322143442319151776409512592545696715177800565940569", "price": "0.521", "size": "228", "side": "SELL", "hash": "25994c68013cb11b583d37ad422cbf5e6f997878", "best_bid": "0.016", "best_ask": "0.032"}], "timestamp": "1769384581772", "event_type": "price_change"}}
{"_local_timestamp": "2026-01-25T23:43:01.910579+00:00", "data": {"market": "0xc7aca5ec2ab64207578a5461e4f3d2ad2362a6ca9edcaa6b6f05553a7d541819", "price_changes": [{"asset_id": "46477055511928802305871870544961419728762162363024275463912888154597320120223", "price": "0.479", "size": "233", "side": "BUY", "hash": "061c90918be9e32a7203a9393523ef4cc38f9a85", "best_bid": "0.968", "best_ask": "0.984"}, {"asset_id": "13986990593551346934180369322143442319151776409512592545696715177800565940569", "price": "0.521", "size": "233", "side": "SELL", "hash": "d8a9a9b5eb0db5f768edf0a46e8b15b6008895e7", "best_bid": "0.016", "best_ask": "0.032"}], "timestamp": "1769384581773", "event_type": "price_change"}}
{"_local_timestamp": "2026-01-25T23:43:02.008580+00:00", "data": {"market": "0xc7aca5ec2ab64207578a5461e4f3d2ad2362a6ca9edcaa6b6f05553a7d541819", "price_changes": [{"asset_id": "46477055511928802305871870544961419728762162363024275463912888154597320120223", "price": "0.477", "size": "0", "side": "BUY", "hash": "a4803e608e866fc1a3dc93bebcf69a5b1df1acda", "best_bid": "0.968", "best_ask": "0.984"}, {"asset_id": "13986990593551346934180369322143442319151776409512592545696715177800565940569", "price": "0.523", "size": "0", "side": "SELL", "hash": "c1237a9978695be3c87a0b52cff2a18e8b199ef9", "best_bid": "0.016", "best_ask": "0.032"}], "timestamp": "1769384581874", "event_type": "price_change"}}
{"_local_timestamp": "2026-01-25T23:43:02.111144+00:00", "data": {"market": "0xc7aca5ec2ab64207578a5461e4f3d2ad2362a6ca9edcaa6b6f05553a7d541819", "price_changes": [{"asset_id": "46477055511928802305871870544961419728762162363024275463912888154597320120223", "price": "0.478", "size": "609", "side": "BUY", "hash": "a40d940e64a31d99fe0116b47db980d48b6daba4", "best_bid": "0.968", "best_ask": "0.984"}, {"asset_id": "13986990593551346934180369322143442319151776409512592545696715177800565940569", "price": "0.522", "size": "609", "side": "SELL", "hash": "73d9d5e3066601c32fda450b56f56b66c7d8991f", "best_bid": "0.016", "best_ask": "0.032"}], "timestamp": "1769384581969", "event_type": "price_change"}}
{"_local_timestamp": "2026-01-25T23:43:02.239836+00:00", "data": {"market": "0xc7aca5ec2ab64207578a5461e4f3d2ad2362a6ca9edcaa6b6f05553a7d541819", "price_changes": [{"asset_id": "46477055511928802305871870544961419728762162363024275463912888154597320120223", "price": "0.476", "size": "0", "side": "BUY", "hash": "b7e48f30a8f4316277bdddb3e3798999665ab08d", "best_bid": "0.968", "best_ask": "0.984"}, {"asset_id": "13986990593551346934180369322143442319151776409512592545696715177800565940569", "price": "0.524", "size": "0", "side": "SELL", "hash": "fa2336ff5f30dfeb6c5176635ab439d590c65023", "best_bid": "0.016", "best_ask": "0.032"}], "timestamp": "1769384582042", "event_type": "price_change"}}
{"_local_timestamp": "2026-01-25T23:43:02.271084+00:00", "data": {"market": "0xc7aca5ec2ab64207578a5461e4f3d2ad2362a6ca9edcaa6b6f05553a7d541819", "price_changes": [{"asset_id": "46477055511928802305871870544961419728762162363024275463912888154597320120223", "price": "0.48", "size": "20", "side": "BUY", "hash": "3b30c54f1be69e4c6b19cedf0cbfafb1eb18ca9d", "best_bid": "0.968", "best_ask": "0.984"}, {"asset_id": "13986990593551346934180369322143442319151776409512592545696715177800565940569", "price": "0.52", "size": "20", "side": "SELL", "hash": "0c3ddfc88d75499b8a963aafc9f12b31e9c37bf5", "best_bid": "0.016", "best_ask": "0.032"}], "timestamp": "1769384582072", "event_type": "price_change"}}
{"_local_timestamp": "2026-01-25T23:43:26.508163+00:00", "data": {"market": "0xc7aca5ec2ab64207578a5461e4f3d2ad2362a6ca9edcaa6b6f05553a7d541819", "price_changes": [{"asset_id": "13986990593551346934180369322143442319151776409512592545696715177800565940569", "price": "0.009", "size": "0", "side": "BUY", "hash": "ef2c913fc4fcca8c4bb5c2e452a6b2f4b553102f", "best_bid": "0.016", "best_ask": "0.032"}, {"asset_id": "46477055511928802305871870544961419728762162363024275463912888154597320120223", "price": "0.991", "size": "0", "side": "SELL", "hash": "dd584fbf2e2f2450f5e6452af640acf3eb87769d", "best_bid": "0.968", "best_ask": "0.984"}], "timestamp": "1769384606408", "event_type": "price_change"}}
{"_local_timestamp": "2026-01-25T23:43:29.776202+00:00", "data": {"market": "0xc7aca5ec2ab64207578a5461e4f3d2ad2362a6ca9edcaa6b6f05553a7d541819", "price_changes": [{"asset_id": "13986990593551346934180369322143442319151776409512592545696715177800565940569", "price": "0.006", "size": "17.88", "side": "BUY", "hash": "ccd52c44cf52c4aff8933935ce86e81077678bcf", "best_bid": "0.016", "best_ask": "0.032"}, {"asset_id": "46477055511928802305871870544961419728762162363024275463912888154597320120223", "price": "0.994", "size": "17.88", "side": "SELL", "hash": "0687cf2c1e0fc942de8d2df3e763cf7df5fe9fa9", "best_bid": "0.968", "best_ask": "0.984"}], "timestamp": "1769384609676", "event_type": "price_change"}}
{"_local_timestamp": "2026-01-25T23:43:30.038401+00:00", "data": {"market": "0xc7aca5ec2ab64207578a5461e4f3d2ad2362a6ca9edcaa6b6f05553a7d541819", "price_changes": [{"asset_id": "13986990593551346934180369322143442319151776409512592545696715177800565940569", "price": "0.005", "size": "87", "side": "BUY", "hash": "5e7782b9f573511893336daa80a86e0c85517f19", "best_bid": "0.016", "best_ask": "0.032"}, {"asset_id": "46477055511928802305871870544961419728762162363024275463912888154597320120223", "price": "0.995", "size": "87", "side": "SELL", "hash": "d335ab85468e65c97f856c579b30231518cb9c82", "best_bid": "0.968", "best_ask": "0.984"}], "timestamp": "1769384609942", "event_type": "price_change"}}
{"_local_timestamp": "2026-01-25T23:43:30.647420+00:00", "data": {"market": "0x4cb1b09d2a17a1e21e459f4e431999bc3bfbb40cc9023b3354aa70e2d7d81875", "price_changes": [{"asset_id": "114492877966140684018682752756008128367968333531744283465420223400327242203881", "price": "0.002", "size": "4384.02", "side": "BUY", "hash": "cc76a365112049609a32b50c92e957c5b52ddf84", "best_bid": "0.008", "best_ask": "0.035"}, {"asset_id": "75701058868331201775069911407645821013233843572698963559250184599603027030054", "price": "0.998", "size": "4384.02", "side": "SELL", "hash": "e2ddece31394b3409aba3f74672ba22074c25c5a", "best_bid": "0.965", "best_ask": "0.992"}], "timestamp": "1769384610551", "event_type": "price_change"}}
{"_local_timestamp": "2026-01-25T23:43:30.648710+00:00", "data": {"market": "0x4f864dda711ee273e6eb7925aada5d984da51a5f423122a00f6ae9532a3c28b9", "price_changes": [{"asset_id": "32968341948204373341622549015077301743176984559839089527120694005326340631965", "price": "0.002", "size": "666", "side": "BUY", "hash": "79366ae7f112af0faf18ab40d472ea22648fad9b", "best_bid": "0.008", "best_ask": "0.051"}, {"asset_id": "19845436317498992677729026362700087887065920346030569541585600013099473710639", "price": "0.998", "size": "666", "side": "SELL", "hash": "fc2e15ce743f993f9f8065a57bab1fac0f1043d3", "best_bid": "0.949", "best_ask": "0.992"}], "timestamp": "1769384610551", "event_type": "price_change"}}
{"_local_timestamp": "2026-01-25T23:43:30.650164+00:00", "data": {"market": "0x4f864dda711ee273e6eb7925aada5d984da51a5f423122a00f6ae9532a3c28b9", "price_changes": [{"asset_id": "32968341948204373341622549015077301743176984559839089527120694005326340631965", "price": "0.003", "size": "342.5", "side": "BUY", "hash": "79366ae7f112af0faf18ab40d472ea22648fad9b", "best_bid": "0.008", "best_ask": "0.051"}, {"asset_id": "19845436317498992677729026362700087887065920346030569541585600013099473710639", "price": "0.997", "size": "342.5", "side": "SELL", "hash": "fc2e15ce743f993f9f8065a57bab1fac0f1043d3", "best_bid": "0.949", "best_ask": "0.992"}], "timestamp": "1769384610551", "event_type": "price_change"}}
{"_local_timestamp": "2026-01-25T23:43:30.651241+00:00", "data": {"market": "0x4cb1b09d2a17a1e21e459f4e431999bc3bfbb40cc9023b3354aa70e2d7d81875", "price_changes": [{"asset_id": "114492877966140684018682752756008128367968333531744283465420223400327242203881", "price": "0.004", "size": "127", "side": "BUY", "hash": "cc76a365112049609a32b50c92e957c5b52ddf84", "best_bid": "0.008", "best_ask": "0.035"}, {"asset_id": "75701058868331201775069911407645821013233843572698963559250184599603027030054", "price": "0.996", "size": "127", "side": "SELL", "hash": "e2ddece31394b3409aba3f74672ba22074c25c5a", "best_bid": "0.965", "best_ask": "0.992"}], "timestamp": "1769384610551", "event_type": "price_change"}}
{"_local_timestamp": "2026-01-25T23:43:33.152840+00:00", "data": {"market": "0xc7aca5ec2ab64207578a5461e4f3d2ad2362a6ca9edcaa6b6f05553a7d541819", "price_changes": [{"asset_id": "13986990593551346934180369322143442319151776409512592545696715177800565940569", "price": "0.004", "size": "57.83", "side": "BUY", "hash": "c69196bf96ebef6e37fd3b2a3208aa10f20af77c", "best_bid": "0.016", "best_ask": "0.032"}, {"asset_id": "46477055511928802305871870544961419728762162363024275463912888154597320120223", "price": "0.996", "size": "57.83", "side": "SELL", "hash": "894b9945c1baec05803932fca187c5d6ac3ad43f", "best_bid": "0.968", "best_ask": "0.984"}], "timestamp": "1769384613063", "event_type": "price_change"}}
{"_local_timestamp": "2026-01-25T23:43:33.858155+00:00", "data": {"market": "0x4f864dda711ee273e6eb7925aada5d984da51a5f423122a00f6ae9532a3c28b9", "price_changes": [{"asset_id": "32968341948204373341622549015077301743176984559839089527120694005326340631965", "price": "0.002", "size": "685.19", "side": "BUY", "hash": "ba133f1cec2cd864bf06d00437a7f7cf083711a9", "best_bid": "0.008", "best_ask": "0.051"}, {"asset_id": "19845436317498992677729026362700087887065920346030569541585600013099473710639", "price": "0.998", "size": "685.19", "side": "SELL", "hash": "d17f330fd99077aee5a003367626531db629a696", "best_bid": "0.949", "best_ask": "0.992"}], "timestamp": "1769384613767", "event_type": "price_change"}}
{"_local_timestamp": "2026-01-25T23:43:33.864019+00:00", "data": {"market": "0x4cb1b09d2a17a1e21e459f4e431999bc3bfbb40cc9023b3354aa70e2d7d81875", "price_changes": [{"asset_id": "114492877966140684018682752756008128367968333531744283465420223400327242203881", "price": "0.003", "size": "28.63", "side": "BUY", "hash": "8227d0ce251ce2c7b4538a95d96b75cef0077094", "best_bid": "0.008", "best_ask": "0.035"}, {"asset_id": "75701058868331201775069911407645821013233843572698963559250184599603027030054", "price": "0.997", "size": "28.63", "side": "SELL", "hash": "05a6ccf2a7a188629672daa3650dd901d577543f", "best_bid": "0.965", "best_ask": "0.992"}], "timestamp": "1769384613767", "event_type": "price_change"}}
{"_local_timestamp": "2026-01-25T23:43:33.865132+00:00", "data": {"market": "0x4f864dda711ee273e6eb7925aada5d984da51a5f423122a00f6ae9532a3c28b9", "price_changes": [{"asset_id": "32968341948204373341622549015077301743176984559839089527120694005326340631965", "price": "0.003", "size": "355.22", "side": "BUY", "hash": "523934e2492d8233d7b0c8bfa918d5afbd61117a", "best_bid": "0.008", "best_ask": "0.051"}, {"asset_id": "19845436317498992677729026362700087887065920346030569541585600013099473710639", "price": "0.997", "size": "355.22", "side": "SELL", "hash": "73645bd290461b103c0d0205adee6a586a6742aa", "best_bid": "0.949", "best_ask": "0.992"}], "timestamp": "1769384613768", "event_type": "price_change"}}
{"_local_timestamp": "2026-01-25T23:43:33.866213+00:00", "data": {"market": "0x4cb1b09d2a17a1e21e459f4e431999bc3bfbb40cc9023b3354aa70e2d7d81875", "price_changes": [{"asset_id": "114492877966140684018682752756008128367968333531744283465420223400327242203881", "price": "0.002", "size": "4405.83", "side": "BUY", "hash": "7a8dee488556b951a8e06ab5ae983d24b87d4b77", "best_bid": "0.008", "best_ask": "0.035"}, {"asset_id": "75701058868331201775069911407645821013233843572698963559250184599603027030054", "price": "0.998", "size": "4405.83", "side": "SELL", "hash": "3fccb71ae4ff74d56d56bdb6b5f9641ab73ae340", "best_bid": "0.965", "best_ask": "0.992"}], "timestamp": "1769384613768", "event_type": "price_change"}}
{"_local_timestamp": "2026-01-25T23:44:00.609166+00:00", "data": {"market": "0x8ec3037f6f989717b8321b9c6d297698c5827d3f17bc06fa276a6826a0b468bc", "price_changes": [{"asset_id": "63727355381184542281210853076888298871978167151761041112625093048354950500520", "price": "0.984", "size": "0", "side": "BUY", "hash": "eadb5c3fc362977a052c67f6cb0fb3784f610f9c", "best_bid": "0.995", "best_ask": "0.997"}, {"asset_id": "54960339021810821002608536313392642741296500124718788520040272866772532121044", "price": "0.016", "size": "0", "side": "SELL", "hash": "bee590ccbc20c504628442e45c36f0ea63111a72", "best_bid": "0.003", "best_ask": "0.005"}], "timestamp": "1769384640497", "event_type": "price_change"}}
{"_local_timestamp": "2026-01-25T23:44:01.647574+00:00", "data": {"market": "0x8ec3037f6f989717b8321b9c6d297698c5827d3f17bc06fa276a6826a0b468bc", "price_changes": [{"asset_id": "63727355381184542281210853076888298871978167151761041112625093048354950500520", "price": "0.985", "size": "50", "side": "BUY", "hash": "6c9507dc8b894ec5c419aa61f0613d9325709d2b", "best_bid": "0.995", "best_ask": "0.997"}, {"asset_id": "54960339021810821002608536313392642741296500124718788520040272866772532121044", "price": "0.015", "size": "50", "side": "SELL", "hash": "db1477b8dada5806941622f974442a9587932f39", "best_bid": "0.003", "best_ask": "0.005"}], "timestamp": "1769384641517", "event_type": "price_change"}}
{"_local_timestamp": "2026-01-25T23:44:15.343590+00:00", "data": {"market": "0xe478b515162e00d4b682e2e480e847487f5e824bbc5c7c1d4587ee68bcb4befe", "price_changes": [{"asset_id": "53703724894913146397718355589619605161922119509512772920279877071805641165559", "price": "0.91", "size": "200", "side": "BUY", "hash": "512bd8570e9faf0c1a5d8475dd95c47054e19047", "best_bid": "0.92", "best_ask": "0.94"}, {"asset_id": "53729975633757169097007121898269744507742420238247181414435653260215633496084", "price": "0.09", "size": "200", "side": "SELL", "hash": "d60c40a1398ba8b76818704522ba769a2ff6f2dc", "best_bid": "0.06", "best_ask": "0.08"}], "timestamp": "1769384655200", "event_type": "price_change"}}
{"_local_timestamp": "2026-01-25T23:44:15.344828+00:00", "data": {"market": "0xe478b515162e00d4b682e2e480e847487f5e824bbc5c7c1d4587ee68bcb4befe", "price_changes": [{"asset_id": "53729975633757169097007121898269744507742420238247181414435653260215633496084", "price": "0.05", "size": "225", "side": "BUY", "hash": "cfc666a7598cd58785ca4ad0b9282a3889a8cef7", "best_bid": "0.06", "best_ask": "0.08"}, {"asset_id": "53703724894913146397718355589619605161922119509512772920279877071805641165559", "price": "0.95", "size": "225", "side": "SELL", "hash": "5adfc3909be398be600337a8e8f4ae55c102d435", "best_bid": "0.92", "best_ask": "0.94"}], "timestamp": "1769384655200", "event_type": "price_change"}}
{"_local_timestamp": "2026-01-25T23:44:15.503638+00:00", "data": {"market": "0x4f864dda711ee273e6eb7925aada5d984da51a5f423122a00f6ae9532a3c28b9", "price_changes": [{"asset_id": "19845436317498992677729026362700087887065920346030569541585600013099473710639", "price": "0.817", "size": "0", "side": "BUY", "hash": "9b56300d21f0fc0bf67b08f29aaa473152d41531", "best_bid": "0.949", "best_ask": "0.992"}, {"asset_id": "32968341948204373341622549015077301743176984559839089527120694005326340631965", "price": "0.183", "size": "0", "side": "SELL", "hash": "f2fe9ade8de42f18dd81ad9810f8064f59dc968b", "best_bid": "0.008", "best_ask": "0.051"}], "timestamp": "1769384655358", "event_type": "price_change"}}
{"_local_timestamp": "2026-01-25T23:44:20.812671+00:00", "data": {"market": "0xc7aca5ec2ab64207578a5461e4f3d2ad2362a6ca9edcaa6b6f05553a7d541819", "price_changes": [{"asset_id": "46477055511928802305871870544961419728762162363024275463912888154597320120223", "price": "0.262", "size": "0", "side": "BUY", "hash": "6055bcd7f03d2c6f119123ce936ba9d9f1cd65be", "best_bid": "0.968", "best_ask": "0.984"}, {"asset_id": "13986990593551346934180369322143442319151776409512592545696715177800565940569", "price": "0.738", "size": "0", "side": "SELL", "hash": "dee6944dc6acb5fd17045202a84d887eb2dc89af", "best_bid": "0.016", "best_ask": "0.032"}], "timestamp": "1769384660498", "event_type": "price_change"}}
{"_local_timestamp": "2026-01-25T23:44:20.815848+00:00", "data": {"market": "0xc7aca5ec2ab64207578a5461e4f3d2ad2362a6ca9edcaa6b6f05553a7d541819", "price_changes": [{"asset_id": "46477055511928802305871870544961419728762162363024275463912888154597320120223", "price": "0.472", "size": "0", "side": "BUY", "hash": "6055bcd7f03d2c6f119123ce936ba9d9f1cd65be", "best_bid": "0.968", "best_ask": "0.984"}, {"asset_id": "13986990593551346934180369322143442319151776409512592545696715177800565940569", "price": "0.528", "size": "0", "side": "SELL", "hash": "dee6944dc6acb5fd17045202a84d887eb2dc89af", "best_bid": "0.016", "best_ask": "0.032"}], "timestamp": "1769384660498", "event_type": "price_change"}}
{"_local_timestamp": "2026-01-25T23:44:21.168581+00:00", "data": {"market": "0x4cb1b09d2a17a1e21e459f4e431999bc3bfbb40cc9023b3354aa70e2d7d81875", "price_changes": [{"asset_id": "75701058868331201775069911407645821013233843572698963559250184599603027030054", "price": "0.571", "size": "0", "side": "BUY", "hash": "9f48efd83380962bc8978801114bfc96b4ec33e6", "best_bid": "0.965", "best_ask": "0.992"}, {"asset_id": "114492877966140684018682752756008128367968333531744283465420223400327242203881", "price": "0.429", "size": "0", "side": "SELL", "hash": "bc7a0bad9d25866e7daf46c93a563b38e0d9e398", "best_bid": "0.008", "best_ask": "0.035"}], "timestamp": "1769384660901", "event_type": "price_change"}}
{"_local_timestamp": "2026-01-25T23:44:21.462718+00:00", "data": {"market": "0xc7aca5ec2ab64207578a5461e4f3d2ad2362a6ca9edcaa6b6f05553a7d541819", "price_changes": [{"asset_id": "46477055511928802305871870544961419728762162363024275463912888154597320120223", "price": "0.263", "size": "1746", "side": "BUY", "hash": "e1d9df918d626ded0fdd8a024818429269874a8e", "best_bid": "0.968", "best_ask": "0.984"}, {"asset_id": "13986990593551346934180369322143442319151776409512592545696715177800565940569", "price": "0.737", "size": "1746", "side": "SELL", "hash": "ca12e5973b295037f8fdc1b07e4c4c92907d4bc7", "best_bid": "0.016", "best_ask": "0.032"}], "timestamp": "1769384660909", "event_type": "price_change"}}
{"_local_timestamp": "2026-01-25T23:44:21.499289+00:00", "data": {"market": "0xc7aca5ec2ab64207578a5461e4f3d2ad2362a6ca9edcaa6b6f05553a7d541819", "price_changes": [{"asset_id": "46477055511928802305871870544961419728762162363024275463912888154597320120223", "price": "0.475", "size": "60", "side": "BUY", "hash": "d7cc97c697b7fdb42ccb77f27c2e7a01785e3ff7", "best_bid": "0.968", "best_ask": "0.984"}, {"asset_id": "13986990593551346934180369322143442319151776409512592545696715177800565940569", "price": "0.525", "size": "60", "side": "SELL", "hash": "6063d81ca6d182f47b8ffe955b1baeb33dd6cc08", "best_bid": "0.016", "best_ask": "0.032"}], "timestamp": "1769384660966", "event_type": "price_change"}}
{"_local_timestamp": "2026-01-25T23:44:21.578964+00:00", "data": {"market": "0x4cb1b09d2a17a1e21e459f4e431999bc3bfbb40cc9023b3354aa70e2d7d81875", "price_changes": [{"asset_id": "75701058868331201775069911407645821013233843572698963559250184599603027030054", "price": "0.579", "size": "25", "side": "BUY", "hash": "88a202208182be884435b33cea230bb3de91c495", "best_bid": "0.965", "best_ask": "0.992"}, {"asset_id": "114492877966140684018682752756008128367968333531744283465420223400327242203881", "price": "0.421", "size": "25", "side": "SELL", "hash": "dad666ac38207a466fa5e37d0ec69db7ee2af1b8", "best_bid": "0.008", "best_ask": "0.035"}], "timestamp": "1769384661205", "event_type": "price_change"}}
{"_local_timestamp": "2026-01-25T23:44:23.658508+00:00", "data": {"market": "0x4cb1b09d2a17a1e21e459f4e431999bc3bfbb40cc9023b3354aa70e2d7d81875", "price_changes": [{"asset_id": "75701058868331201775069911407645821013233843572698963559250184599603027030054", "price": "0.578", "size": "0", "side": "BUY", "hash": "a3069784e920c1e91053d2da35abd09e8dee187e", "best_bid": "0.965", "best_ask": "0.992"}, {"asset_id": "114492877966140684018682752756008128367968333531744283465420223400327242203881", "price": "0.422", "size": "0", "side": "SELL", "hash": "a832cbfae34d0aedf79766c9afb01bcffd7ac51a", "best_bid": "0.008", "best_ask": "0.035"}], "timestamp": "1769384663581", "event_type": "price_change"}}
{"_local_timestamp": "2026-01-25T23:44:23.680518+00:00", "data": {"market": "0x4cb1b09d2a17a1e21e459f4e431999bc3bfbb40cc9023b3354aa70e2d7d81875", "price_changes": [{"asset_id": "75701058868331201775069911407645821013233843572698963559250184599603027030054", "price": "0.58", "size": "20", "side": "BUY", "hash": "61fb7c8db112d4c887384d7b4a64b80863cc2305", "best_bid": "0.965", "best_ask": "0.992"}, {"asset_id": "114492877966140684018682752756008128367968333531744283465420223400327242203881", "price": "0.42", "size": "20", "side": "SELL", "hash": "537fff648105cd327e49e460c7a995abfef52426", "best_bid": "0.008", "best_ask": "0.035"}], "timestamp": "1769384663610", "event_type": "price_change"}}
{"_local_timestamp": "2026-01-25T23:44:32.375726+00:00", "data": {"market": "0xc7aca5ec2ab64207578a5461e4f3d2ad2362a6ca9edcaa6b6f05553a7d541819", "price_changes": [{"asset_id": "46477055511928802305871870544961419728762162363024275463912888154597320120223", "price": "0.263", "size": "150", "side": "BUY", "hash": "ac715c97b70afa071206ae4e3386406cdbe4a80b", "best_bid": "0.968", "best_ask": "0.984"}, {"asset_id": "13986990593551346934180369322143442319151776409512592545696715177800565940569", "price": "0.737", "size": "150", "side": "SELL", "hash": "e7867c0121042a87e615c4046cea3db38681cfb3", "best_bid": "0.016", "best_ask": "0.032"}], "timestamp": "1769384672291", "event_type": "price_change"}}
{"_local_timestamp": "2026-01-25T23:45:03.813025+00:00", "data": {"market": "0xe478b515162e00d4b682e2e480e847487f5e824bbc5c7c1d4587ee68bcb4befe", "price_changes": [{"asset_id": "53729975633757169097007121898269744507742420238247181414435653260215633496084", "price": "0.02", "size": "250", "side": "BUY", "hash": "8035ab52d90e319a72dc2c0faa10ac72f2aec5c5", "best_bid": "0.06", "best_ask": "0.08"}, {"asset_id": "53703724894913146397718355589619605161922119509512772920279877071805641165559", "price": "0.98", "size": "250", "side": "SELL", "hash": "5d72d29ad8724e2cf574520ce8f07e7f2c53d310", "best_bid": "0.92", "best_ask": "0.94"}], "timestamp": "1769384703736", "event_type": "price_change"}}
{"_local_timestamp": "2026-01-25T23:45:03.814408+00:00", "data": {"market": "0xe478b515162e00d4b682e2e480e847487f5e824bbc5c7c1d4587ee68bcb4befe", "price_changes": [{"asset_id": "53729975633757169097007121898269744507742420238247181414435653260215633496084", "price": "0.03", "size": "520", "side": "BUY", "hash": "8035ab52d90e319a72dc2c0faa10ac72f2aec5c5", "best_bid": "0.06", "best_ask": "0.08"}, {"asset_id": "53703724894913146397718355589619605161922119509512772920279877071805641165559", "price": "0.97", "size": "520", "side": "SELL", "hash": "5d72d29ad8724e2cf574520ce8f07e7f2c53d310", "best_bid": "0.92", "best_ask": "0.94"}], "timestamp": "1769384703736", "event_type": "price_change"}}
{"_local_timestamp": "2026-01-25T23:45:03.815501+00:00", "data": {"market": "0xe478b515162e00d4b682e2e480e847487f5e824bbc5c7c1d4587ee68bcb4befe", "price_changes": [{"asset_id": "53729975633757169097007121898269744507742420238247181414435653260215633496084", "price": "0.04", "size": "294.6", "side": "BUY", "hash": "8035ab52d90e319a72dc2c0faa10ac72f2aec5c5", "best_bid": "0.06", "best_ask": "0.08"}, {"asset_id": "53703724894913146397718355589619605161922119509512772920279877071805641165559", "price": "0.96", "size": "294.6", "side": "SELL", "hash": "5d72d29ad8724e2cf574520ce8f07e7f2c53d310", "best_bid": "0.92", "best_ask": "0.94"}], "timestamp": "1769384703736", "event_type": "price_change"}}
{"_local_timestamp": "2026-01-25T23:45:04.523576+00:00", "data": {"market": "0xe478b515162e00d4b682e2e480e847487f5e824bbc5c7c1d4587ee68bcb4befe", "price_changes": [{"asset_id": "53729975633757169097007121898269744507742420238247181414435653260215633496084", "price": "0.05", "size": "234.19", "side": "BUY", "hash": "7e462a411990dbf51ec73b0d13f835f5b6b5183b", "best_bid": "0.06", "best_ask": "0.08"}, {"asset_id": "53703724894913146397718355589619605161922119509512772920279877071805641165559", "price": "0.95", "size": "234.19", "side": "SELL", "hash": "984e1649e9ae86370fecacb6d01e934f6205fe27", "best_bid": "0.92", "best_ask": "0.94"}], "timestamp": "1769384704454", "event_type": "price_change"}}
{"_local_timestamp": "2026-01-25T23:45:04.528772+00:00", "data": {"market": "0xe478b515162e00d4b682e2e480e847487f5e824bbc5c7c1d4587ee68bcb4befe", "price_changes": [{"asset_id": "53729975633757169097007121898269744507742420238247181414435653260215633496084", "price": "0.04", "size": "306.41", "side": "BUY", "hash": "bc4af656de281875d37d410892626b390c94a7d3", "best_bid": "0.06", "best_ask": "0.08"}, {"asset_id": "53703724894913146397718355589619605161922119509512772920279877071805641165559", "price": "0.96", "size": "306.41", "side": "SELL", "hash": "a660df76e77fe6bd78f1423399902fc97bc4c3b2", "best_bid": "0.92", "best_ask": "0.94"}], "timestamp": "1769384704456", "event_type": "price_change"}}
{"_local_timestamp": "2026-01-25T23:45:04.530309+00:00", "data": {"market": "0xe478b515162e00d4b682e2e480e847487f5e824bbc5c7c1d4587ee68bcb4befe", "price_changes": [{"asset_id": "53729975633757169097007121898269744507742420238247181414435653260215633496084", "price": "0.02", "size": "274.98", "side": "BUY", "hash": "df75a483e3ba81ec4a830c53ef0316613f765fd9", "best_bid": "0.06", "best_ask": "0.08"}, {"asset_id": "53703724894913146397718355589619605161922119509512772920279877071805641165559", "price": "0.98", "size": "274.98", "side": "SELL", "hash": "072ee499eb5a23ea2f70955f0b46ec0f2bbd3c39", "best_bid": "0.92", "best_ask": "0.94"}], "timestamp": "1769384704457", "event_type": "price_change"}}
{"_local_timestamp": "2026-01-25T23:45:04.531382+00:00", "data": {"market": "0xe478b515162e00d4b682e2e480e847487f5e824bbc5c7c1d4587ee68bcb4befe", "price_changes": [{"asset_id": "53729975633757169097007121898269744507742420238247181414435653260215633496084", "price": "0.03", "size": "536.19", "side": "BUY", "hash": "0b679ee2207af18d82d57d33d2e56b3a795f52a5", "best_bid": "0.06", "best_ask": "0.08"}, {"asset_id": "53703724894913146397718355589619605161922119509512772920279877071805641165559", "price": "0.97", "size": "536.19", "side": "SELL", "hash": "3f6cc61c012dd994a9fff5db1969b085751fc1a8", "best_bid": "0.92", "best_ask": "0.94"}], "timestamp": "1769384704458", "event_type": "price_change"}}
{"_local_timestamp": "2026-01-25T23:45:11.544768+00:00", "data": {"market": "0x4b04e14bcde7be95db753c88f6fed57423835215bb41937406e75dc22a789b0c", "price_changes": [{"asset_id": "195928349533315596595305126471738494775883003093487532708892885008234493544", "price": "0.002", "size": "1266.01", "side": "BUY", "hash": "35cf5b9f6b1feb5d510901ce8a3c95f475733802", "best_bid": "0.002", "best_ask": "0.005"}, {"asset_id": "75013115303617466002500221618724536968904237026728502667764718978862356730825", "price": "0.998", "size": "1266.01", "side": "SELL", "hash": "bc9da7ccd92f085c9fdd343f389b51a9eefcb735", "best_bid": "0.995", "best_ask": "0.998"}], "timestamp": "1769384711435", "event_type": "price_change"}}
{"_local_timestamp": "2026-01-25T23:45:11.546262+00:00", "data": {"market": "0x8ec3037f6f989717b8321b9c6d297698c5827d3f17bc06fa276a6826a0b468bc", "price_changes": [{"asset_id": "54960339021810821002608536313392642741296500124718788520040272866772532121044", "price": "0.002", "size": "1266.04", "side": "BUY", "hash": "8a86d5893e354c04fd6e71766c74903f3adca06f", "best_bid": "0.003", "best_ask": "0.005"}, {"asset_id": "63727355381184542281210853076888298871978167151761041112625093048354950500520", "price": "0.998", "size": "1266.04", "side": "SELL", "hash": "0171c6380c4d3af9775d1928ee93fe03c60e6e97", "best_bid": "0.995", "best_ask": "0.997"}], "timestamp": "1769384711436", "event_type": "price_change"}}
{"_local_timestamp": "2026-01-25T23:45:21.102539+00:00", "data": {"market": "0xc7aca5ec2ab64207578a5461e4f3d2ad2362a6ca9edcaa6b6f05553a7d541819", "price_changes": [{"asset_id": "46477055511928802305871870544961419728762162363024275463912888154597320120223", "price": "0.196", "size": "2142", "side": "BUY", "hash": "c9b70e98ad789951725ee28fa2c02a8985805c5f", "best_bid": "0.968", "best_ask": "0.984"}, {"asset_id": "13986990593551346934180369322143442319151776409512592545696715177800565940569", "price": "0.804", "size": "2142", "side": "SELL", "hash": "8ceb8f59bf9f061912e83e59230e1ea0d30664e4", "best_bid": "0.016", "best_ask": "0.032"}], "timestamp": "1769384721000", "event_type": "price_change"}}
{"_local_timestamp": "2026-01-25T23:45:21.204773+00:00", "data": {"market": "0x4b04e14bcde7be95db753c88f6fed57423835215bb41937406e75dc22a789b0c", "price_changes": [{"asset_id": "75013115303617466002500221618724536968904237026728502667764718978862356730825", "price": "0.655", "size": "0", "side": "BUY", "hash": "dd61d49e536b8f65e012112bf613cae80e31e5b0", "best_bid": "0.995", "best_ask": "0.998"}, {"asset_id": "195928349533315596595305126471738494775883003093487532708892885008234493544", "price": "0.345", "size": "0", "side": "SELL", "hash": "e334062a71adb16a726d914a13b6841ae66b4f66", "best_bid": "0.002", "best_ask": "0.005"}], "timestamp": "1769384721132", "event_type": "price_change"}}
{"_local_timestamp": "2026-01-25T23:45:21.330240+00:00", "data": {"market": "0x4b04e14bcde7be95db753c88f6fed57423835215bb41937406e75dc22a789b0c", "price_changes": [{"asset_id": "75013115303617466002500221618724536968904237026728502667764718978862356730825", "price": "0.663", "size": "25", "side": "BUY", "hash": "083c79e0ed7bc42a29c2c2efbe1a8b428b119acb", "best_bid": "0.995", "best_ask": "0.998"}, {"asset_id": "195928349533315596595305126471738494775883003093487532708892885008234493544", "price": "0.337", "size": "25", "side": "SELL", "hash": "450edc11b77a7d7ea06f5598939f6499ae9e183d", "best_bid": "0.002", "best_ask": "0.005"}], "timestamp": "1769384721259", "event_type": "price_change"}}
{"_local_timestamp": "2026-01-25T23:45:24.742545+00:00", "data": {"market": "0x4b04e14bcde7be95db753c88f6fed57423835215bb41937406e75dc22a789b0c", "price_changes": [{"asset_id": "75013115303617466002500221618724536968904237026728502667764718978862356730825", "price": "0.662", "size": "0", "side": "BUY", "hash": "1d1decee4d75f0569cc87c833f57a2f1562173ba", "best_bid": "0.995", "best_ask": "0.998"}, {"asset_id": "195928349533315596595305126471738494775883003093487532708892885008234493544", "price": "0.338", "size": "0", "side": "SELL", "hash": "a512adfb5f602b965edfa503caa91e41a19be7b0", "best_bid": "0.002", "best_ask": "0.005"}], "timestamp": "1769384724665", "event_type": "price_change"}}
{"_local_timestamp": "2026-01-25T23:45:24.761865+00:00", "data": {"market": "0x4b04e14bcde7be95db753c88f6fed57423835215bb41937406e75dc22a789b0c", "price_changes": [{"asset_id": "75013115303617466002500221618724536968904237026728502667764718978862356730825", "price": "0.664", "size": "20", "side": "BUY", "hash": "d008cd1f60dbc0143fed48bb787f3e604f135414", "best_bid": "0.995", "best_ask": "0.998"}, {"asset_id": "195928349533315596595305126471738494775883003093487532708892885008234493544", "price": "0.336", "size": "20", "side": "SELL", "hash": "cb15d24896a486fa3743623ec00db904ae3009ca", "best_bid": "0.002", "best_ask": "0.005"}], "timestamp": "1769384724694", "event_type": "price_change"}}
{"_local_timestamp": "2026-01-25T23:45:48.454795+00:00", "data": {"market": "0xe478b515162e00d4b682e2e480e847487f5e824bbc5c7c1d4587ee68bcb4befe", "price_changes": [{"asset_id": "53729975633757169097007121898269744507742420238247181414435653260215633496084", "price": "0.04", "size": "256.41", "side": "BUY", "hash": "ac4227c63c80217bc4bdae3e97a7def34aec2d4f", "best_bid": "0.06", "best_ask": "0.08"}, {"asset_id": "53703724894913146397718355589619605161922119509512772920279877071805641165559", "price": "0.96", "size": "256.41", "side": "SELL", "hash": "ec5e142af24e9be5e88a21053e145248ada8ef6a", "best_bid": "0.92", "best_ask": "0.94"}], "timestamp": "1769384748353", "event_type": "price_change"}}
{"_local_timestamp": "2026-01-25T23:45:48.478215+00:00", "data": {"market": "0x4cb1b09d2a17a1e21e459f4e431999bc3bfbb40cc9023b3354aa70e2d7d81875", "price_changes": [{"asset_id": "75701058868331201775069911407645821013233843572698963559250184599603027030054", "price": "0.947", "size": "0", "side": "BUY", "hash": "24c1abf323d133aa8e303eae9f2aaf5d3e8828f4", "best_bid": "0.965", "best_ask": "0.992"}, {"asset_id": "114492877966140684018682752756008128367968333531744283465420223400327242203881", "price": "0.053", "size": "0", "side": "SELL", "hash": "3184d909cb808d3b3f1153d750cc77993661dd7c", "best_bid": "0.008", "best_ask": "0.035"}], "timestamp": "1769384748393", "event_type": "price_change"}}
{"_local_timestamp": "2026-01-25T23:45:48.479375+00:00", "data": {"market": "0xc7aca5ec2ab64207578a5461e4f3d2ad2362a6ca9edcaa6b6f05553a7d541819", "price_changes": [{"asset_id": "46477055511928802305871870544961419728762162363024275463912888154597320120223", "price": "0.939", "size": "0", "side": "BUY", "hash": "8e91275bee2675a079b6948b1cd4aa4c9703fb1c", "best_bid": "0.968", "best_ask": "0.984"}, {"asset_id": "13986990593551346934180369322143442319151776409512592545696715177800565940569", "price": "0.061", "size": "0", "side": "SELL", "hash": "6ed9c1e6c9b40f9277b2c2484adf3942796073af", "best_bid": "0.016", "best_ask": "0.032"}], "timestamp": "1769384748393", "event_type": "price_change"}}
{"_local_timestamp": "2026-01-25T23:45:48.480461+00:00", "data": {"market": "0x4f864dda711ee273e6eb7925aada5d984da51a5f423122a00f6ae9532a3c28b9", "price_changes": [{"asset_id": "19845436317498992677729026362700087887065920346030569541585600013099473710639", "price": "0.946", "size": "97.33", "side": "BUY", "hash": "528cc1c2c5143b2b1c81d01d3d05ae519f8ca111", "best_bid": "0.949", "best_ask": "0.992"}, {"asset_id": "32968341948204373341622549015077301743176984559839089527120694005326340631965", "price": "0.054", "size": "97.33", "side": "SELL", "hash": "0c097c1dcc0488f206761c4c55daffa970715507", "best_bid": "0.008", "best_ask": "0.051"}], "timestamp": "1769384748394", "event_type": "price_change"}}
{"_local_timestamp": "2026-01-25T23:45:48.481569+00:00", "data": {"market": "0x4b04e14bcde7be95db753c88f6fed57423835215bb41937406e75dc22a789b0c", "price_changes": [{"asset_id": "75013115303617466002500221618724536968904237026728502667764718978862356730825", "price": "0.953", "size": "0", "side": "BUY", "hash": "ba572695c8abeabe1c065c43794ba9417da3accc", "best_bid": "0.995", "best_ask": "0.998"}, {"asset_id": "195928349533315596595305126471738494775883003093487532708892885008234493544", "price": "0.047", "size": "0", "side": "SELL", "hash": "64e8d2e408f320bb2358fe334b14f1a818a6e207", "best_bid": "0.002", "best_ask": "0.005"}], "timestamp": "1769384748394", "event_type": "price_change"}}
{"_local_timestamp": "2026-01-25T23:45:48.482690+00:00", "data": {"market": "0xe478b515162e00d4b682e2e480e847487f5e824bbc5c7c1d4587ee68bcb4befe", "price_changes": [{"asset_id": "53729975633757169097007121898269744507742420238247181414435653260215633496084", "price": "0.03", "size": "516.19", "side": "BUY", "hash": "8c76d7df5ab6b5478c7467ac03a533897d35e2eb", "best_bid": "0.06", "best_ask": "0.08"}, {"asset_id": "53703724894913146397718355589619605161922119509512772920279877071805641165559", "price": "0.97", "size": "516.19", "side": "SELL", "hash": "e5829d4b4197ac78c3fd5740b0933c2ee9fb7da0", "best_bid": "0.92", "best_ask": "0.94"}], "timestamp": "1769384748397", "event_type": "price_change"}}
{"_local_timestamp": "2026-01-25T23:45:49.959540+00:00", "data": {"market": "0xc7aca5ec2ab64207578a5461e4f3d2ad2362a6ca9edcaa6b6f05553a7d541819", "price_changes": [{"asset_id": "13986990593551346934180369322143442319151776409512592545696715177800565940569", "price": "0.015", "size": "50", "side": "BUY", "hash": "d0e7b3e170c7993fd7cc939ad861d0adbd944aba", "best_bid": "0.016", "best_ask": "0.032"}, {"asset_id": "46477055511928802305871870544961419728762162363024275463912888154597320120223", "price": "0.985", "size": "50", "side": "SELL", "hash": "232c5a04b08506150145742b823ad212376f2733", "best_bid": "0.968", "best_ask": "0.984"}], "timestamp": "1769384749890", "event_type": "price_change"}}
{"_local_timestamp": "2026-01-25T23:45:50.118947+00:00", "data": {"market": "0xc7aca5ec2ab64207578a5461e4f3d2ad2362a6ca9edcaa6b6f05553a7d541819", "price_changes": [{"asset_id": "46477055511928802305871870544961419728762162363024275463912888154597320120223", "price": "0.967", "size": "320", "side": "BUY", "hash": "da86fcf2986389bc4dea77c80bb0d68a210b149f", "best_bid": "0.968", "best_ask": "0.984"}, {"asset_id": "13986990593551346934180369322143442319151776409512592545696715177800565940569", "price": "0.033", "size": "320", "side": "SELL", "hash": "37591e536be665e5f458e7ab87fa74e6a12bef37", "best_bid": "0.016", "best_ask": "0.032"}], "timestamp": "1769384750009", "event_type": "price_change"}}
{"_local_timestamp": "2026-01-25T23:45:50.120133+00:00", "data": {"market": "0xc7aca5ec2ab64207578a5461e4f3d2ad2362a6ca9edcaa6b6f05553a7d541819", "price_changes": [{"asset_id": "13986990593551346934180369322143442319151776409512592545696715177800565940569", "price": "0.015", "size": "0", "side": "BUY", "hash": "83e5c4dd9a8064e1edecd47c727f4f8c1049077c", "best_bid": "0.016", "best_ask": "0.032"}, {"asset_id": "46477055511928802305871870544961419728762162363024275463912888154597320120223", "price": "0.985", "size": "0", "side": "SELL", "hash": "760f7fc5caa92da64fc1b258321507a611e03373", "best_bid": "0.968", "best_ask": "0.984"}], "timestamp": "1769384750009", "event_type": "price_change"}}
{"_local_timestamp": "2026-01-25T23:45:50.214023+00:00", "data": {"market": "0xc7aca5ec2ab64207578a5461e4f3d2ad2362a6ca9edcaa6b6f05553a7d541819", "price_changes": [{"asset_id": "13986990593551346934180369322143442319151776409512592545696715177800565940569", "price": "0.015", "size": "109", "side": "BUY", "hash": "98d0af703c9dfe4d8d902df7bf4c5791d1136302", "best_bid": "0.016", "best_ask": "0.032"}, {"asset_id": "46477055511928802305871870544961419728762162363024275463912888154597320120223", "price": "0.985", "size": "109", "side": "SELL", "hash": "a53f9bdd29ab491288d7a98c8f362a8b5dd727f2", "best_bid": "0.968", "best_ask": "0.984"}], "timestamp": "1769384750147", "event_type": "price_change"}}
{"_local_timestamp": "2026-01-25T23:45:50.222251+00:00", "data": {"market": "0xc7aca5ec2ab64207578a5461e4f3d2ad2362a6ca9edcaa6b6f05553a7d541819", "price_changes": [{"asset_id": "13986990593551346934180369322143442319151776409512592545696715177800565940569", "price": "0.014", "size": "152", "side": "BUY", "hash": "6fb4df75ef80bc4d3031f9ea8e09f7b4b28f4a78", "best_bid": "0.016", "best_ask": "0.032"}, {"asset_id": "46477055511928802305871870544961419728762162363024275463912888154597320120223", "price": "0.986", "size": "152", "side": "SELL", "hash": "4f88e26c9b45aa5cbaaeae4e1cafc04a7455e36d", "best_bid": "0.968", "best_ask": "0.984"}], "timestamp": "1769384750155", "event_type": "price_change"}}
{"_local_timestamp": "2026-01-25T23:45:50.225309+00:00", "data": {"market": "0xc7aca5ec2ab64207578a5461e4f3d2ad2362a6ca9edcaa6b6f05553a7d541819", "price_changes": [{"asset_id": "46477055511928802305871870544961419728762162363024275463912888154597320120223", "price": "0.967", "size": "370", "side": "BUY", "hash": "05cf3c4d999b0bd8fd94087c10fde1a21fe2c781", "best_bid": "0.968", "best_ask": "0.984"}, {"asset_id": "13986990593551346934180369322143442319151776409512592545696715177800565940569", "price": "0.033", "size": "370", "side": "SELL", "hash": "140b3b87d6cd476d4cdd693ec926616107a69406", "best_bid": "0.016", "best_ask": "0.032"}], "timestamp": "1769384750156", "event_type": "price_change"}}
{"_local_timestamp": "2026-01-25T23:45:50.929305+00:00", "data": {"market": "0xc7aca5ec2ab64207578a5461e4f3d2ad2362a6ca9edcaa6b6f05553a7d541819", "price_changes": [{"asset_id": "46477055511928802305871870544961419728762162363024275463912888154597320120223", "price": "0.967", "size": "152", "side": "BUY", "hash": "2b753555c06402a8c5c3a121926086dcc698522b", "best_bid": "0.968", "best_ask": "0.984"}, {"asset_id": "13986990593551346934180369322143442319151776409512592545696715177800565940569", "price": "0.033", "size": "152", "side": "SELL", "hash": "10ab7771d4308f081b9adfaebb0ab1618fdc7fa6", "best_bid": "0.016", "best_ask": "0.032"}], "timestamp": "1769384750862", "event_type": "price_change"}}
{"_local_timestamp": "2026-01-25T23:45:51.144684+00:00", "data": {"market": "0xc7aca5ec2ab64207578a5461e4f3d2ad2362a6ca9edcaa6b6f05553a7d541819", "price_changes": [{"asset_id": "46477055511928802305871870544961419728762162363024275463912888154597320120223", "price": "0.967", "size": "102", "side": "BUY", "hash": "fc02db2ec16f1c72b8506b727d02cc8304674a01", "best_bid": "0.968", "best_ask": "0.984"}, {"asset_id": "13986990593551346934180369322143442319151776409512592545696715177800565940569", "price": "0.033", "size": "102", "side": "SELL", "hash": "8264b1df853ceda9b7186b80fa79e94ba810a05c", "best_bid": "0.016", "best_ask": "0.032"}], "timestamp": "1769384751081", "event_type": "price_change"}}
{"_local_timestamp": "2026-01-25T23:45:51.146055+00:00", "data": {"market": "0xc7aca5ec2ab64207578a5461e4f3d2ad2362a6ca9edcaa6b6f05553a7d541819", "price_changes": [{"asset_id": "13986990593551346934180369322143442319151776409512592545696715177800565940569", "price": "0.014", "size": "102", "side": "BUY", "hash": "82b3c7f1d1d4de9aad2a940d62031e31179653cc", "best_bid": "0.016", "best_ask": "0.032"}, {"asset_id": "46477055511928802305871870544961419728762162363024275463912888154597320120223", "price": "0.986", "size": "102", "side": "SELL", "hash": "47c1bb6d97bb48738e27cbb9a746b517f412f31a", "best_bid": "0.968", "best_ask": "0.984"}], "timestamp": "1769384751081", "event_type": "price_change"}}
{"_local_timestamp": "2026-01-25T23:45:51.178269+00:00", "data": {"market": "0xc7aca5ec2ab64207578a5461e4f3d2ad2362a6ca9edcaa6b6f05553a7d541819", "price_changes": [{"asset_id": "46477055511928802305871870544961419728762162363024275463912888154597320120223", "price": "0.967", "size": "211", "side": "BUY", "hash": "c83e935b00b9cc529b1aeb634941fc7ef431dbbf", "best_bid": "0.968", "best_ask": "0.984"}, {"asset_id": "13986990593551346934180369322143442319151776409512592545696715177800565940569", "price": "0.033", "size": "211", "side": "SELL", "hash": "815011947568e14f01b04ce552e93ca3db7ce63b", "best_bid": "0.016", "best_ask": "0.032"}], "timestamp": "1769384751102", "event_type": "price_change"}}
{"_local_timestamp": "2026-01-25T23:45:51.301208+00:00", "data": {"market": "0xc7aca5ec2ab64207578a5461e4f3d2ad2362a6ca9edcaa6b6f05553a7d541819", "price_changes": [{"asset_id": "46477055511928802305871870544961419728762162363024275463912888154597320120223", "price": "0.967", "size": "261", "side": "BUY", "hash": "e0ef176e80e7037697a8423b756672fbd63b29cb", "best_bid": "0.968", "best_ask": "0.984"}, {"asset_id": "13986990593551346934180369322143442319151776409512592545696715177800565940569", "price": "0.033", "size": "261", "side": "SELL", "hash": "92187b6245eee38c329c6d6a652407997a56dac2", "best_bid": "0.016", "best_ask": "0.032"}], "timestamp": "1769384751237", "event_type": "price_change"}}
{"_local_timestamp": "2026-01-25T23:45:51.302455+00:00", "data": {"market": "0xc7aca5ec2ab64207578a5461e4f3d2ad2362a6ca9edcaa6b6f05553a7d541819", "price_changes": [{"asset_id": "13986990593551346934180369322143442319151776409512592545696715177800565940569", "price": "0.015", "size": "159", "side": "BUY", "hash": "0a5473e1e3dba95ffb75b6f48ec71138896f1bda", "best_bid": "0.016", "best_ask": "0.032"}, {"asset_id": "46477055511928802305871870544961419728762162363024275463912888154597320120223", "price": "0.985", "size": "159", "side": "SELL", "hash": "0a77796812518bdc80c9ea42d18056764f021b42", "best_bid": "0.968", "best_ask": "0.984"}], "timestamp": "1769384751238", "event_type": "price_change"}}
{"_local_timestamp": "2026-01-25T23:45:55.451238+00:00", "data": {"market": "0xe478b515162e00d4b682e2e480e847487f5e824bbc5c7c1d4587ee68bcb4befe", "price_changes": [{"asset_id": "53729975633757169097007121898269744507742420238247181414435653260215633496084", "price": "0.05", "size": "225", "side": "BUY", "hash": "4841b3b96094eaee75e60e25399ca811b5dc2fea", "best_bid": "0.06", "best_ask": "0.08"}, {"asset_id": "53703724894913146397718355589619605161922119509512772920279877071805641165559", "price": "0.95", "size": "225", "side": "SELL", "hash": "6176ac69ef4b64579b275818089c25afa9ce2061", "best_bid": "0.92", "best_ask": "0.94"}], "timestamp": "1769384755379", "event_type": "price_change"}}
{"_local_timestamp": "2026-01-25T23:45:57.805431+00:00", "data": {"market": "0x4f864dda711ee273e6eb7925aada5d984da51a5f423122a00f6ae9532a3c28b9", "price_changes": [{"asset_id": "19845436317498992677729026362700087887065920346030569541585600013099473710639", "price": "0.175", "size": "100", "side": "BUY", "hash": "249d32e56fccd7ff05c59495b0e91ca12d1ff525", "best_bid": "0.949", "best_ask": "0.992"}, {"asset_id": "32968341948204373341622549015077301743176984559839089527120694005326340631965", "price": "0.825", "size": "100", "side": "SELL", "hash": "bda71b573b8875f21e861cb20d4996f74d1abd26", "best_bid": "0.008", "best_ask": "0.051"}], "timestamp": "1769384757730", "event_type": "price_change"}}
{"_local_timestamp": "2026-01-25T23:45:57.980219+00:00", "data": {"market": "0x4f864dda711ee273e6eb7925aada5d984da51a5f423122a00f6ae9532a3c28b9", "price_changes": [{"asset_id": "19845436317498992677729026362700087887065920346030569541585600013099473710639", "price": "0.177", "size": "7831.74", "side": "BUY", "hash": "3c9c263e442de5658eed52499133d478984aed1b", "best_bid": "0.949", "best_ask": "0.992"}, {"asset_id": "32968341948204373341622549015077301743176984559839089527120694005326340631965", "price": "0.823", "size": "7831.74", "side": "SELL", "hash": "dc5dd19a97b7d7fe85c32aa0519d8795627d5ed9", "best_bid": "0.008", "best_ask": "0.051"}], "timestamp": "1769384757902", "event_type": "price_change"}}
{"_local_timestamp": "2026-01-25T23:45:58.128644+00:00", "data": {"market": "0x4f864dda711ee273e6eb7925aada5d984da51a5f423122a00f6ae9532a3c28b9", "price_changes": [{"asset_id": "19845436317498992677729026362700087887065920346030569541585600013099473710639", "price": "0.176", "size": "550", "side": "BUY", "hash": "9f6aec0fe28ff23107e972cb98d98f53a172c2a1", "best_bid": "0.949", "best_ask": "0.992"}, {"asset_id": "32968341948204373341622549015077301743176984559839089527120694005326340631965", "price": "0.824", "size": "550", "side": "SELL", "hash": "8b311207bd6a900515012d4bc9f903605f2695be", "best_bid": "0.008", "best_ask": "0.051"}], "timestamp": "1769384758035", "event_type": "price_change"}}
{"_local_timestamp": "2026-01-25T23:45:58.133096+00:00", "data": {"market": "0x4f864dda711ee273e6eb7925aada5d984da51a5f423122a00f6ae9532a3c28b9", "price_changes": [{"asset_id": "19845436317498992677729026362700087887065920346030569541585600013099473710639", "price": "0.176", "size": "150", "side": "BUY", "hash": "ca74d9c56e36f53359ce2f30c701393cad896a0d", "best_bid": "0.949", "best_ask": "0.992"}, {"asset_id": "32968341948204373341622549015077301743176984559839089527120694005326340631965", "price": "0.824", "size": "150", "side": "SELL", "hash": "20354cda4b5afd4062742e3c6fd0edf349d55ce6", "best_bid": "0.008", "best_ask": "0.051"}], "timestamp": "1769384758047", "event_type": "price_change"}}
{"_local_timestamp": "2026-01-25T23:45:58.193411+00:00", "data": {"market": "0xc7aca5ec2ab64207578a5461e4f3d2ad2362a6ca9edcaa6b6f05553a7d541819", "price_changes": [{"asset_id": "46477055511928802305871870544961419728762162363024275463912888154597320120223", "price": "0.461", "size": "1300", "side": "BUY", "hash": "083adafb1dee6568aa37fd7e0564b874f391d8ab", "best_bid": "0.968", "best_ask": "0.984"}, {"asset_id": "13986990593551346934180369322143442319151776409512592545696715177800565940569", "price": "0.539", "size": "1300", "side": "SELL", "hash": "4206cdca4449bcf937f8c80c4ad61d316e4dfeff", "best_bid": "0.016", "best_ask": "0.032"}], "timestamp": "1769384758097", "event_type": "price_change"}}
{"_local_timestamp": "2026-01-25T23:45:58.253715+00:00", "data": {"market": "0x4f864dda711ee273e6eb7925aada5d984da51a5f423122a00f6ae9532a3c28b9", "price_changes": [{"asset_id": "19845436317498992677729026362700087887065920346030569541585600013099473710639", "price": "0.178", "size": "800", "side": "BUY", "hash": "158563ef8940a18aca17abbe233cad50ca955165", "best_bid": "0.949", "best_ask": "0.992"}, {"asset_id": "32968341948204373341622549015077301743176984559839089527120694005326340631965", "price": "0.822", "size": "800", "side": "SELL", "hash": "d583f5940a1895a1297bfbcab9ecd032f5efec3e", "best_bid": "0.008", "best_ask": "0.051"}], "timestamp": "1769384758174", "event_type": "price_change"}}
{"_local_timestamp": "2026-01-25T23:45:58.262678+00:00", "data": {"market": "0x4f864dda711ee273e6eb7925aada5d984da51a5f423122a00f6ae9532a3c28b9", "price_changes": [{"asset_id": "19845436317498992677729026362700087887065920346030569541585600013099473710639", "price": "0.178", "size": "1200", "side": "BUY", "hash": "b897187e92adbad703dd93bf7624796b7cdeef18", "best_bid": "0.949", "best_ask": "0.992"}, {"asset_id": "32968341948204373341622549015077301743176984559839089527120694005326340631965", "price": "0.822", "size": "1200", "side": "SELL", "hash": "378cd43b67cd3451fd303fa8bb8dfd8fb22585cc", "best_bid": "0.008", "best_ask": "0.051"}], "timestamp": "1769384758194", "event_type": "price_change"}}
{"_local_timestamp": "2026-01-25T23:45:58.322453+00:00", "data": {"market": "0xc7aca5ec2ab64207578a5461e4f3d2ad2362a6ca9edcaa6b6f05553a7d541819", "price_changes": [{"asset_id": "46477055511928802305871870544961419728762162363024275463912888154597320120223", "price": "0.48", "size": "3975", "side": "BUY", "hash": "d5ac677f6150be9a23f28f857522997b9f1533a9", "best_bid": "0.968", "best_ask": "0.984"}, {"asset_id": "13986990593551346934180369322143442319151776409512592545696715177800565940569", "price": "0.52", "size": "3975", "side": "SELL", "hash": "aedcc83d5a635d494e3df55af3f6fd2977d23412", "best_bid": "0.016", "best_ask": "0.032"}], "timestamp": "1769384758252", "event_type": "price_change"}}
{"_local_timestamp": "2026-01-25T23:45:58.394891+00:00", "data": {"market": "0xc7aca5ec2ab64207578a5461e4f3d2ad2362a6ca9edcaa6b6f05553a7d541819", "price_changes": [{"asset_id": "46477055511928802305871870544961419728762162363024275463912888154597320120223", "price": "0.479", "size": "25", "side": "BUY", "hash": "e0482d9c801b088ac15b10d22664247dbfe91704", "best_bid": "0.968", "best_ask": "0.984"}, {"asset_id": "13986990593551346934180369322143442319151776409512592545696715177800565940569", "price": "0.521", "size": "25", "side": "SELL", "hash": "fe39e6cd97752c043359d39b4ecbec22907925b9", "best_bid": "0.016", "best_ask": "0.032"}], "timestamp": "1769384758319", "event_type": "price_change"}}
{"_local_timestamp": "2026-01-25T23:45:58.453436+00:00", "data": {"market": "0xc7aca5ec2ab64207578a5461e4f3d2ad2362a6ca9edcaa6b6f05553a7d541819", "price_changes": [{"asset_id": "46477055511928802305871870544961419728762162363024275463912888154597320120223", "price": "0.478", "size": "400", "side": "BUY", "hash": "dc8b00ebc0fa7d1133cfdcd6d861b7954e083bd3", "best_bid": "0.968", "best_ask": "0.984"}, {"asset_id": "13986990593551346934180369322143442319151776409512592545696715177800565940569", "price": "0.522", "size": "400", "side": "SELL", "hash": "219fd2c025b2015bb159e277c07394fd541d891e", "best_bid": "0.016", "best_ask": "0.032"}], "timestamp": "1769384758386", "event_type": "price_change"}}
{"_local_timestamp": "2026-01-25T23:45:58.465379+00:00", "data": {"market": "0xc7aca5ec2ab64207578a5461e4f3d2ad2362a6ca9edcaa6b6f05553a7d541819", "price_changes": [{"asset_id": "46477055511928802305871870544961419728762162363024275463912888154597320120223", "price": "0.478", "size": "0", "side": "BUY", "hash": "042a5e2694708865dc415422228a851555f69674", "best_bid": "0.968", "best_ask": "0.984"}, {"asset_id": "13986990593551346934180369322143442319151776409512592545696715177800565940569", "price": "0.522", "size": "0", "side": "SELL", "hash": "2ff2877a65fbfbb5787da09aa7395c60b5505a0d", "best_bid": "0.016", "best_ask": "0.032"}], "timestamp": "1769384758388", "event_type": "price_change"}}
{"_local_timestamp": "2026-01-25T23:45:58.523951+00:00", "data": {"market": "0x4cb1b09d2a17a1e21e459f4e431999bc3bfbb40cc9023b3354aa70e2d7d81875", "price_changes": [{"asset_id": "75701058868331201775069911407645821013233843572698963559250184599603027030054", "price": "0.214", "size": "50", "side": "BUY", "hash": "df516b28ef6023b8fa4531334e708f738eb4999f", "best_bid": "0.965", "best_ask": "0.992"}, {"asset_id": "114492877966140684018682752756008128367968333531744283465420223400327242203881", "price": "0.786", "size": "50", "side": "SELL", "hash": "8f74c2871d61881887d774364a5331d7836ba870", "best_bid": "0.008", "best_ask": "0.035"}], "timestamp": "1769384758451", "event_type": "price_change"}}
{"_local_timestamp": "2026-01-25T23:45:58.555204+00:00", "data": {"market": "0xc7aca5ec2ab64207578a5461e4f3d2ad2362a6ca9edcaa6b6f05553a7d541819", "price_changes": [{"asset_id": "46477055511928802305871870544961419728762162363024275463912888154597320120223", "price": "0.481", "size": "400", "side": "BUY", "hash": "f29432e6cedf15273cf5977f7e65e50b00774848", "best_bid": "0.968", "best_ask": "0.984"}, {"asset_id": "13986990593551346934180369322143442319151776409512592545696715177800565940569", "price": "0.519", "size": "400", "side": "SELL", "hash": "ff9eaae67815bd67caa6c348e7ce8ed0b6a190b2", "best_bid": "0.016", "best_ask": "0.032"}], "timestamp": "1769384758487", "event_type": "price_change"}}
{"_local_timestamp": "2026-01-25T23:45:58.572074+00:00", "data": {"market": "0xc7aca5ec2ab64207578a5461e4f3d2ad2362a6ca9edcaa6b6f05553a7d541819", "price_changes": [{"asset_id": "46477055511928802305871870544961419728762162363024275463912888154597320120223", "price": "0.481", "size": "815", "side": "BUY", "hash": "c1f79a4a76298fbd0dfca40b44d08d6473633563", "best_bid": "0.968", "best_ask": "0.984"}, {"asset_id": "13986990593551346934180369322143442319151776409512592545696715177800565940569", "price": "0.519", "size": "815", "side": "SELL", "hash": "0fcd221ec982718ceaf6481f247ab194f72d736c", "best_bid": "0.016", "best_ask": "0.032"}], "timestamp": "1769384758502", "event_type": "price_change"}}
{"_local_timestamp": "2026-01-25T23:45:58.704116+00:00", "data": {"market": "0x4cb1b09d2a17a1e21e459f4e431999bc3bfbb40cc9023b3354aa70e2d7d81875", "price_changes": [{"asset_id": "75701058868331201775069911407645821013233843572698963559250184599603027030054", "price": "0.216", "size": "3492", "side": "BUY", "hash": "2baf6c69dedbd367348936bef224248f2419b01c", "best_bid": "0.965", "best_ask": "0.992"}, {"asset_id": "114492877966140684018682752756008128367968333531744283465420223400327242203881", "price": "0.784", "size": "3492", "side": "SELL", "hash": "30b1fb9c754f0d9269657cab3d86f831cf36faa4", "best_bid": "0.008", "best_ask": "0.035"}], "timestamp": "1769384758628", "event_type": "price_change"}}
{"_local_timestamp": "2026-01-25T23:45:58.888837+00:00", "data": {"market": "0x8ec3037f6f989717b8321b9c6d297698c5827d3f17bc06fa276a6826a0b468bc", "price_changes": [{"asset_id": "63727355381184542281210853076888298871978167151761041112625093048354950500520", "price": "0.588", "size": "0", "side": "BUY", "hash": "9b5e28d07b4e5977eb163e02d4c5b9518c669229", "best_bid": "0.995", "best_ask": "0.997"}, {"asset_id": "54960339021810821002608536313392642741296500124718788520040272866772532121044", "price": "0.412", "size": "0", "side": "SELL", "hash": "59c1c6683ac04f752573ea0d8d14e04e9d4dce28", "best_bid": "0.003", "best_ask": "0.005"}], "timestamp": "1769384758817", "event_type": "price_change"}}
{"_local_timestamp": "2026-01-25T23:45:59.058402+00:00", "data": {"market": "0x8ec3037f6f989717b8321b9c6d297698c5827d3f17bc06fa276a6826a0b468bc", "price_changes": [{"asset_id": "63727355381184542281210853076888298871978167151761041112625093048354950500520", "price": "0.612", "size": "3123", "side": "BUY", "hash": "97b9d64ab36891b6db1be49e94611bd3745b9866", "best_bid": "0.995", "best_ask": "0.997"}, {"asset_id": "54960339021810821002608536313392642741296500124718788520040272866772532121044", "price": "0.388", "size": "3123", "side": "SELL", "hash": "40819eaa2fc7b92373eda026b23e5d8390f694c9", "best_bid": "0.003", "best_ask": "0.005"}], "timestamp": "1769384758985", "event_type": "price_change"}}
{"_local_timestamp": "2026-01-25T23:45:59.163871+00:00", "data": {"market": "0x8ec3037f6f989717b8321b9c6d297698c5827d3f17bc06fa276a6826a0b468bc", "price_changes": [{"asset_id": "63727355381184542281210853076888298871978167151761041112625093048354950500520", "price": "0.611", "size": "313", "side": "BUY", "hash": "0039acd1237534c9f469ef0d94df4799a66e1797", "best_bid": "0.995", "best_ask": "0.997"}, {"asset_id": "54960339021810821002608536313392642741296500124718788520040272866772532121044", "price": "0.389", "size": "313", "side": "SELL", "hash": "ea473c15412c4e5ecde135019f5e7c3100180895", "best_bid": "0.003", "best_ask": "0.005"}], "timestamp": "1769384759071", "event_type": "price_change"}}
{"_local_timestamp": "2026-01-25T23:45:59.181552+00:00", "data": {"market": "0x8ec3037f6f989717b8321b9c6d297698c5827d3f17bc06fa276a6826a0b468bc", "price_changes": [{"asset_id": "63727355381184542281210853076888298871978167151761041112625093048354950500520", "price": "0.611", "size": "0", "side": "BUY", "hash": "b6daae3c5401467b772200cf1c3c2596f7591b35", "best_bid": "0.995", "best_ask": "0.997"}, {"asset_id": "54960339021810821002608536313392642741296500124718788520040272866772532121044", "price": "0.389", "size": "0", "side": "SELL", "hash": "306e8685bb773f8209b46a78b297155aa081106c", "best_bid": "0.003", "best_ask": "0.005"}], "timestamp": "1769384759092", "event_type": "price_change"}}
{"_local_timestamp": "2026-01-25T23:45:59.291513+00:00", "data": {"market": "0x4b04e14bcde7be95db753c88f6fed57423835215bb41937406e75dc22a789b0c", "price_changes": [{"asset_id": "75013115303617466002500221618724536968904237026728502667764718978862356730825", "price": "0.224", "size": "50", "side": "BUY", "hash": "01529341b8d07c6f66198599a4b6757fb0740cc6", "best_bid": "0.995", "best_ask": "0.998"}, {"asset_id": "195928349533315596595305126471738494775883003093487532708892885008234493544", "price": "0.776", "size": "50", "side": "SELL", "hash": "8a7550bff9a8a044456184541fd4e24c72add5aa", "best_bid": "0.002", "best_ask": "0.005"}], "timestamp": "1769384759221", "event_type": "price_change"}}
{"_local_timestamp": "2026-01-25T23:45:59.310912+00:00", "data": {"market": "0x8ec3037f6f989717b8321b9c6d297698c5827d3f17bc06fa276a6826a0b468bc", "price_changes": [{"asset_id": "63727355381184542281210853076888298871978167151761041112625093048354950500520", "price": "0.613", "size": "326", "side": "BUY", "hash": "6d4e7409bdabd61d2003ab07ee936ec7e914ee9e", "best_bid": "0.995", "best_ask": "0.997"}, {"asset_id": "54960339021810821002608536313392642741296500124718788520040272866772532121044", "price": "0.387", "size": "326", "side": "SELL", "hash": "01575268f352c6a11154a6807cb60d3d1d542d2d", "best_bid": "0.003", "best_ask": "0.005"}], "timestamp": "1769384759237", "event_type": "price_change"}}
{"_local_timestamp": "2026-01-25T23:45:59.363694+00:00", "data": {"market": "0x8ec3037f6f989717b8321b9c6d297698c5827d3f17bc06fa276a6826a0b468bc", "price_changes": [{"asset_id": "63727355381184542281210853076888298871978167151761041112625093048354950500520", "price": "0.613", "size": "652", "side": "BUY", "hash": "de8f20fc5d9c1f73566d18d5e4344c2e1b5c6aa8", "best_bid": "0.995", "best_ask": "0.997"}, {"asset_id": "54960339021810821002608536313392642741296500124718788520040272866772532121044", "price": "0.387", "size": "652", "side": "SELL", "hash": "aa3f093e8ae52836fd93b07ba4c401ed4f43eef7", "best_bid": "0.003", "best_ask": "0.005"}], "timestamp": "1769384759289", "event_type": "price_change"}}
{"_local_timestamp": "2026-01-25T23:45:59.481275+00:00", "data": {"market": "0x4b04e14bcde7be95db753c88f6fed57423835215bb41937406e75dc22a789b0c", "price_changes": [{"asset_id": "75013115303617466002500221618724536968904237026728502667764718978862356730825", "price": "0.226", "size": "4002", "side": "BUY", "hash": "dd48b99d05d5fd177654ae4e5dc9848491d19894", "best_bid": "0.995", "best_ask": "0.998"}, {"asset_id": "195928349533315596595305126471738494775883003093487532708892885008234493544", "price": "0.774", "size": "4002", "side": "SELL", "hash": "9d7cf8539e38f6da5a64d2ef2516f89a51d07396", "best_bid": "0.002", "best_ask": "0.005"}], "timestamp": "1769384759406", "event_type": "price_change"}}
{"_local_timestamp": "2026-01-25T23:45:59.673247+00:00", "data": {"market": "0xe478b515162e00d4b682e2e480e847487f5e824bbc5c7c1d4587ee68bcb4befe", "price_changes": [{"asset_id": "53703724894913146397718355589619605161922119509512772920279877071805641165559", "price": "0.3", "size": "2150", "side": "BUY", "hash": "ce75d1b107a1722ca4a91ca8910404ad914deca6", "best_bid": "0.92", "best_ask": "0.94"}, {"asset_id": "53729975633757169097007121898269744507742420238247181414435653260215633496084", "price": "0.7", "size": "2150", "side": "SELL", "hash": "a2bb8fe49cba636feb5382bc78831518ea560c67", "best_bid": "0.06", "best_ask": "0.08"}], "timestamp": "1769384759599", "event_type": "price_change"}}
{"_local_timestamp": "2026-01-25T23:45:59.835119+00:00", "data": {"market": "0xe478b515162e00d4b682e2e480e847487f5e824bbc5c7c1d4587ee68bcb4befe", "price_changes": [{"asset_id": "53703724894913146397718355589619605161922119509512772920279877071805641165559", "price": "0.32", "size": "4318", "side": "BUY", "hash": "5253ee1dada415b67a5cb9848021a0f0f1c7fe98", "best_bid": "0.92", "best_ask": "0.94"}, {"asset_id": "53729975633757169097007121898269744507742420238247181414435653260215633496084", "price": "0.68", "size": "4318", "side": "SELL", "hash": "e341d744022c2678969c839808b6615fa14971db", "best_bid": "0.06", "best_ask": "0.08"}], "timestamp": "1769384759762", "event_type": "price_change"}}
{"_local_timestamp": "2026-01-25T23:46:00.893740+00:00", "data": {"market": "0xc7aca5ec2ab64207578a5461e4f3d2ad2362a6ca9edcaa6b6f05553a7d541819", "price_changes": [{"asset_id": "46477055511928802305871870544961419728762162363024275463912888154597320120223", "price": "0.48", "size": "3955", "side": "BUY", "hash": "cc5e3d2733ef621afa9716b87c4f1fa28cb09e87", "best_bid": "0.968", "best_ask": "0.984"}, {"asset_id": "13986990593551346934180369322143442319151776409512592545696715177800565940569", "price": "0.52", "size": "3955", "side": "SELL", "hash": "16bddeb230f65f1e6a4ec170223fd928db574dc8", "best_bid": "0.016", "best_ask": "0.032"}], "timestamp": "1769384760823", "event_type": "price_change"}}
{"_local_timestamp": "2026-01-25T23:46:00.915513+00:00", "data": {"market": "0xc7aca5ec2ab64207578a5461e4f3d2ad2362a6ca9edcaa6b6f05553a7d541819", "price_changes": [{"asset_id": "46477055511928802305871870544961419728762162363024275463912888154597320120223", "price": "0.482", "size": "20", "side": "BUY", "hash": "f82513388273877800b559a03eb6f56e910bb7aa", "best_bid": "0.968", "best_ask": "0.984"}, {"asset_id": "13986990593551346934180369322143442319151776409512592545696715177800565940569", "price": "0.518", "size": "20", "side": "SELL", "hash": "5c768a375499cb73dc549dbffd51152aaf03cc2e", "best_bid": "0.016", "best_ask": "0.032"}], "timestamp": "1769384760847", "event_type": "price_change"}}
{"_local_timestamp": "2026-01-25T23:46:05.471210+00:00", "data": {"market": "0xe478b515162e00d4b682e2e480e847487f5e824bbc5c7c1d4587ee68bcb4befe", "price_changes": [{"asset_id": "53729975633757169097007121898269744507742420238247181414435653260215633496084", "price": "0.04", "size": "306.41", "side": "BUY", "hash": "b866bb1938ef643e681eaecd7cec9ad6a6101b40", "best_bid": "0.06", "best_ask": "0.08"}, {"asset_id": "53703724894913146397718355589619605161922119509512772920279877071805641165559", "price": "0.96", "size": "306.41", "side": "SELL", "hash": "50d5aa4a8e6124c637b626d87f11678d3f270e08", "best_bid": "0.92", "best_ask": "0.94"}], "timestamp": "1769384765395", "event_type": "price_change"}}
{"_local_timestamp": "2026-01-25T23:46:10.586330+00:00", "data": {"market": "0xc7aca5ec2ab64207578a5461e4f3d2ad2362a6ca9edcaa6b6f05553a7d541819", "price_changes": [{"asset_id": "46477055511928802305871870544961419728762162363024275463912888154597320120223", "price": "0.196", "size": "0", "side": "BUY", "hash": "9418ec2a75360a7752f6f27be2ad3b14a9b0481b", "best_bid": "0.968", "best_ask": "0.984"}, {"asset_id": "13986990593551346934180369322143442319151776409512592545696715177800565940569", "price": "0.804", "size": "0", "side": "SELL", "hash": "75c1220528657344a0686d574479f7df24a93cff", "best_bid": "0.016", "best_ask": "0.032"}], "timestamp": "1769384770467", "event_type": "price_change"}}
{"_local_timestamp": "2026-01-25T23:46:39.017121+00:00", "data": {"market": "0x8ec3037f6f989717b8321b9c6d297698c5827d3f17bc06fa276a6826a0b468bc", "price_changes": [{"asset_id": "63727355381184542281210853076888298871978167151761041112625093048354950500520", "price": "0.985", "size": "0", "side": "BUY", "hash": "23aa78495b42444758a31479ad9f1085c936a8a6", "best_bid": "0.995", "best_ask": "0.997"}, {"asset_id": "54960339021810821002608536313392642741296500124718788520040272866772532121044", "price": "0.015", "size": "0", "side": "SELL", "hash": "8b740c7a269afc05dccc22ce6e6ad0fc739ba609", "best_bid": "0.003", "best_ask": "0.005"}], "timestamp": "1769384798931", "event_type": "price_change"}}
{"_local_timestamp": "2026-01-25T23:46:40.109991+00:00", "data": {"market": "0x8ec3037f6f989717b8321b9c6d297698c5827d3f17bc06fa276a6826a0b468bc", "price_changes": [{"asset_id": "63727355381184542281210853076888298871978167151761041112625093048354950500520", "price": "0.982", "size": "50", "side": "BUY", "hash": "4b40195b10f995818cf298232388a7aaa7c694c0", "best_bid": "0.995", "best_ask": "0.997"}, {"asset_id": "54960339021810821002608536313392642741296500124718788520040272866772532121044", "price": "0.018", "size": "50", "side": "SELL", "hash": "a98cc1991b02ebce96b8904da9e6ab6000492116", "best_bid": "0.003", "best_ask": "0.005"}], "timestamp": "1769384800005", "event_type": "price_change"}}
{"_local_timestamp": "2026-01-25T23:46:40.175639+00:00", "data": {"market": "0x8ec3037f6f989717b8321b9c6d297698c5827d3f17bc06fa276a6826a0b468bc", "price_changes": [{"asset_id": "63727355381184542281210853076888298871978167151761041112625093048354950500520", "price": "0.628", "size": "25", "side": "BUY", "hash": "72631a51afb83284ec610d116770302ae1ade4b7", "best_bid": "0.995", "best_ask": "0.997"}, {"asset_id": "54960339021810821002608536313392642741296500124718788520040272866772532121044", "price": "0.372", "size": "25", "side": "SELL", "hash": "8f656e56d4082e4ee863afb1710d206b1fa75228", "best_bid": "0.003", "best_ask": "0.005"}], "timestamp": "1769384800093", "event_type": "price_change"}}
{"_local_timestamp": "2026-01-25T23:46:40.312913+00:00", "data": {"market": "0x4b04e14bcde7be95db753c88f6fed57423835215bb41937406e75dc22a789b0c", "price_changes": [{"asset_id": "75013115303617466002500221618724536968904237026728502667764718978862356730825", "price": "0.657", "size": "0", "side": "BUY", "hash": "8e737c2bbd331255758d6cd924115fa87e758679", "best_bid": "0.995", "best_ask": "0.998"}, {"asset_id": "195928349533315596595305126471738494775883003093487532708892885008234493544", "price": "0.343", "size": "0", "side": "SELL", "hash": "1d48588ef736f824ef2364009f1553a2db4599a6", "best_bid": "0.002", "best_ask": "0.005"}], "timestamp": "1769384800224", "event_type": "price_change"}}
{"_local_timestamp": "2026-01-25T23:46:40.315501+00:00", "data": {"market": "0x4cb1b09d2a17a1e21e459f4e431999bc3bfbb40cc9023b3354aa70e2d7d81875", "price_changes": [{"asset_id": "75701058868331201775069911407645821013233843572698963559250184599603027030054", "price": "0.573", "size": "0", "side": "BUY", "hash": "e8c15aa21c53afa94f09752e7ca728a86532055b", "best_bid": "0.965", "best_ask": "0.992"}, {"asset_id": "114492877966140684018682752756008128367968333531744283465420223400327242203881", "price": "0.427", "size": "0", "side": "SELL", "hash": "2cefecb386905fec286b993527339241734fdf4c", "best_bid": "0.008", "best_ask": "0.035"}], "timestamp": "1769384800224", "event_type": "price_change"}}
{"_local_timestamp": "2026-01-25T23:46:40.318191+00:00", "data": {"market": "0x8ec3037f6f989717b8321b9c6d297698c5827d3f17bc06fa276a6826a0b468bc", "price_changes": [{"asset_id": "63727355381184542281210853076888298871978167151761041112625093048354950500520", "price": "0.628", "size": "0", "side": "BUY", "hash": "4455204d0b13bd3926f20ae39e800a7cea050120", "best_bid": "0.995", "best_ask": "0.997"}, {"asset_id": "54960339021810821002608536313392642741296500124718788520040272866772532121044", "price": "0.372", "size": "0", "side": "SELL", "hash": "f200dd905333bd047a845a59162307d3da4261cc", "best_bid": "0.003", "best_ask": "0.005"}], "timestamp": "1769384800224", "event_type": "price_change"}}
{"_local_timestamp": "2026-01-25T23:46:40.321804+00:00", "data": {"market": "0x8ec3037f6f989717b8321b9c6d297698c5827d3f17bc06fa276a6826a0b468bc", "price_changes": [{"asset_id": "63727355381184542281210853076888298871978167151761041112625093048354950500520", "price": "0.631", "size": "25", "side": "BUY", "hash": "ba6254e675e1136d1b42be00135f0b9cbc2ea22c", "best_bid": "0.995", "best_ask": "0.997"}, {"asset_id": "54960339021810821002608536313392642741296500124718788520040272866772532121044", "price": "0.369", "size": "25", "side": "SELL", "hash": "78c2fef9df456a99c51ab532d666d3c5111d58b1", "best_bid": "0.003", "best_ask": "0.005"}], "timestamp": "1769384800234", "event_type": "price_change"}}
{"_local_timestamp": "2026-01-25T23:46:40.355814+00:00", "data": {"market": "0x8ec3037f6f989717b8321b9c6d297698c5827d3f17bc06fa276a6826a0b468bc", "price_changes": [{"asset_id": "63727355381184542281210853076888298871978167151761041112625093048354950500520", "price": "0.63", "size": "0", "side": "BUY", "hash": "3230cf5a184626a44773d158b98608c911bf4ae7", "best_bid": "0.995", "best_ask": "0.997"}, {"asset_id": "54960339021810821002608536313392642741296500124718788520040272866772532121044", "price": "0.37", "size": "0", "side": "SELL", "hash": "80d5aaa9a54376df2e72e7e6cee72036f8c0b04e", "best_bid": "0.003", "best_ask": "0.005"}], "timestamp": "1769384800274", "event_type": "price_change"}}
{"_local_timestamp": "2026-01-25T23:46:40.390083+00:00", "data": {"market": "0x8ec3037f6f989717b8321b9c6d297698c5827d3f17bc06fa276a6826a0b468bc", "price_changes": [{"asset_id": "63727355381184542281210853076888298871978167151761041112625093048354950500520", "price": "0.632", "size": "20", "side": "BUY", "hash": "1986909e0c668a915800271af6c8f040ee6f4d4f", "best_bid": "0.995", "best_ask": "0.997"}, {"asset_id": "54960339021810821002608536313392642741296500124718788520040272866772532121044", "price": "0.368", "size": "20", "side": "SELL", "hash": "ee13211bf893b2c2a26e2dd4a1277dcfcf8b676e", "best_bid": "0.003", "best_ask": "0.005"}], "timestamp": "1769384800303", "event_type": "price_change"}}
{"_local_timestamp": "2026-01-25T23:46:40.443542+00:00", "data": {"market": "0x4cb1b09d2a17a1e21e459f4e431999bc3bfbb40cc9023b3354aa70e2d7d81875", "price_changes": [{"asset_id": "75701058868331201775069911407645821013233843572698963559250184599603027030054", "price": "0.581", "size": "25", "side": "BUY", "hash": "96146a8aaa6aab41d48764c7b120483ac5b3ee53", "best_bid": "0.965", "best_ask": "0.992"}, {"asset_id": "114492877966140684018682752756008128367968333531744283465420223400327242203881", "price": "0.419", "size": "25", "side": "SELL", "hash": "405e5da250484701fe61404c5444a480d02b00d0", "best_bid": "0.008", "best_ask": "0.035"}], "timestamp": "1769384800355", "event_type": "price_change"}}
{"_local_timestamp": "2026-01-25T23:46:40.444899+00:00", "data": {"market": "0x8ec3037f6f989717b8321b9c6d297698c5827d3f17bc06fa276a6826a0b468bc", "price_changes": [{"asset_id": "63727355381184542281210853076888298871978167151761041112625093048354950500520", "price": "0.631", "size": "50", "side": "BUY", "hash": "3327946fa0d94660a0a64eb3688b2fc8f2bdda69", "best_bid": "0.995", "best_ask": "0.997"}, {"asset_id": "54960339021810821002608536313392642741296500124718788520040272866772532121044", "price": "0.369", "size": "50", "side": "SELL", "hash": "24c4e30efcc05c0586d008f08aa5dbdf6d4cd64b", "best_bid": "0.003", "best_ask": "0.005"}], "timestamp": "1769384800356", "event_type": "price_change"}}
{"_local_timestamp": "2026-01-25T23:46:40.446130+00:00", "data": {"market": "0x4b04e14bcde7be95db753c88f6fed57423835215bb41937406e75dc22a789b0c", "price_changes": [{"asset_id": "75013115303617466002500221618724536968904237026728502667764718978862356730825", "price": "0.665", "size": "25", "side": "BUY", "hash": "d861376ead5534fe7fef564372c95a891f4e864b", "best_bid": "0.995", "best_ask": "0.998"}, {"asset_id": "195928349533315596595305126471738494775883003093487532708892885008234493544", "price": "0.335", "size": "25", "side": "SELL", "hash": "e5192bd56e69ad004e92f6f2c8af8b9535c2b2f3", "best_bid": "0.002", "best_ask": "0.005"}], "timestamp": "1769384800356", "event_type": "price_change"}}
{"_local_timestamp": "2026-01-25T23:46:40.643814+00:00", "data": {"market": "0x4b04e14bcde7be95db753c88f6fed57423835215bb41937406e75dc22a789b0c", "price_changes": [{"asset_id": "75013115303617466002500221618724536968904237026728502667764718978862356730825", "price": "0.664", "size": "0", "side": "BUY", "hash": "caf14ba0b0c8feff962f54caca0f0f26c1a10968", "best_bid": "0.995", "best_ask": "0.998"}, {"asset_id": "195928349533315596595305126471738494775883003093487532708892885008234493544", "price": "0.336", "size": "0", "side": "SELL", "hash": "d7811cd16b3702365ecf5a62108673734662aa0f", "best_bid": "0.002", "best_ask": "0.005"}], "timestamp": "1769384800555", "event_type": "price_change"}}
{"_local_timestamp": "2026-01-25T23:46:40.647064+00:00", "data": {"market": "0x4cb1b09d2a17a1e21e459f4e431999bc3bfbb40cc9023b3354aa70e2d7d81875", "price_changes": [{"asset_id": "75701058868331201775069911407645821013233843572698963559250184599603027030054", "price": "0.58", "size": "0", "side": "BUY", "hash": "16d19df941d1263ca13dce0c09395eab04b4abb3", "best_bid": "0.965", "best_ask": "0.992"}, {"asset_id": "114492877966140684018682752756008128367968333531744283465420223400327242203881", "price": "0.42", "size": "0", "side": "SELL", "hash": "64ffbc091c3503b9f4fd2c49a6f43a2ca6ab9e04", "best_bid": "0.008", "best_ask": "0.035"}], "timestamp": "1769384800555", "event_type": "price_change"}}
{"_local_timestamp": "2026-01-25T23:46:40.665311+00:00", "data": {"market": "0x4b04e14bcde7be95db753c88f6fed57423835215bb41937406e75dc22a789b0c", "price_changes": [{"asset_id": "75013115303617466002500221618724536968904237026728502667764718978862356730825", "price": "0.666", "size": "20", "side": "BUY", "hash": "f2c2d2f683a31a5e06816bb5e7710343b494cc22", "best_bid": "0.995", "best_ask": "0.998"}, {"asset_id": "195928349533315596595305126471738494775883003093487532708892885008234493544", "price": "0.334", "size": "20", "side": "SELL", "hash": "1a4f24a96a9538bba7501a8a71c2ee533eb6e7e1", "best_bid": "0.002", "best_ask": "0.005"}], "timestamp": "1769384800583", "event_type": "price_change"}}
{"_local_timestamp": "2026-01-25T23:46:40.666636+00:00", "data": {"market": "0x4cb1b09d2a17a1e21e459f4e431999bc3bfbb40cc9023b3354aa70e2d7d81875", "price_changes": [{"asset_id": "75701058868331201775069911407645821013233843572698963559250184599603027030054", "price": "0.582", "size": "20", "side": "BUY", "hash": "f17e68659443d08e8a0aeba724a81cab8a887222", "best_bid": "0.965", "best_ask": "0.992"}, {"asset_id": "114492877966140684018682752756008128367968333531744283465420223400327242203881", "price": "0.418", "size": "20", "side": "SELL", "hash": "e9bf173bb7e34fa7d5053651c19b98832167e1ce", "best_bid": "0.008", "best_ask": "0.035"}], "timestamp": "1769384800583", "event_type": "price_change"}}
{"_local_timestamp": "2026-01-25T23:46:41.890117+00:00", "data": {"market": "0xc7aca5ec2ab64207578a5461e4f3d2ad2362a6ca9edcaa6b6f05553a7d541819", "price_changes": [{"asset_id": "13986990593551346934180369322143442319151776409512592545696715177800565940569", "price": "0.004", "size": "7.83", "side": "BUY", "hash": "5361ec7cfe6b557149a30344c3ede92ab4aa44e3", "best_bid": "0.016", "best_ask": "0.032"}, {"asset_id": "46477055511928802305871870544961419728762162363024275463912888154597320120223", "price": "0.996", "size": "7.83", "side": "SELL", "hash": "3f4dcf7c3eb22315c24b1b68cb65b061d05442e8", "best_bid": "0.968", "best_ask": "0.984"}], "timestamp": "1769384801763", "event_type": "price_change"}}
{"_local_timestamp": "2026-01-25T23:46:46.192103+00:00", "data": {"market": "0xc7aca5ec2ab64207578a5461e4f3d2ad2362a6ca9edcaa6b6f05553a7d541819", "price_changes": [{"asset_id": "13986990593551346934180369322143442319151776409512592545696715177800565940569", "price": "0.004", "size": "57.83", "side": "BUY", "hash": "367786ef43b07f5a477d4e1ee0bfde2f13ea38b6", "best_bid": "0.016", "best_ask": "0.032"}, {"asset_id": "46477055511928802305871870544961419728762162363024275463912888154597320120223", "price": "0.996", "size": "57.83", "side": "SELL", "hash": "39f02a826ec48dcb96e03236447f55436217cdfc", "best_bid": "0.968", "best_ask": "0.984"}], "timestamp": "1769384806119", "event_type": "price_change"}}
{"_local_timestamp": "2026-01-25T23:46:50.987211+00:00", "data": {"market": "0xc7aca5ec2ab64207578a5461e4f3d2ad2362a6ca9edcaa6b6f05553a7d541819", "price_changes": [{"asset_id": "46477055511928802305871870544961419728762162363024275463912888154597320120223", "price": "0.475", "size": "0", "side": "BUY", "hash": "f796963beb55c91cf3ae9f276c70543e37b9d1aa", "best_bid": "0.968", "best_ask": "0.984"}, {"asset_id": "13986990593551346934180369322143442319151776409512592545696715177800565940569", "price": "0.525", "size": "0", "side": "SELL", "hash": "8e7ab7ab380dc939e698f3bf0a1d69ca6f0bfe44", "best_bid": "0.016", "best_ask": "0.032"}], "timestamp": "1769384810676", "event_type": "price_change"}}
{"_local_timestamp": "2026-01-25T23:46:51.615453+00:00", "data": {"market": "0xc7aca5ec2ab64207578a5461e4f3d2ad2362a6ca9edcaa6b6f05553a7d541819", "price_changes": [{"asset_id": "46477055511928802305871870544961419728762162363024275463912888154597320120223", "price": "0.479", "size": "85", "side": "BUY", "hash": "7e3522d9729d42a32026a200e1adb891da9cfcb3", "best_bid": "0.968", "best_ask": "0.984"}, {"asset_id": "13986990593551346934180369322143442319151776409512592545696715177800565940569", "price": "0.521", "size": "85", "side": "SELL", "hash": "d9441dd4deb9987a249c8e4d97e5261d67343395", "best_bid": "0.016", "best_ask": "0.032"}], "timestamp": "1769384811229", "event_type": "price_change"}}
{"_local_timestamp": "2026-01-25T23:46:52.001886+00:00", "data": {"market": "0xc7aca5ec2ab64207578a5461e4f3d2ad2362a6ca9edcaa6b6f05553a7d541819", "price_changes": [{"asset_id": "46477055511928802305871870544961419728762162363024275463912888154597320120223", "price": "0.198", "size": "0", "side": "BUY", "hash": "052ca98b0eb9f6dc6a39667f8ad8163b65f59d38", "best_bid": "0.968", "best_ask": "0.984"}, {"asset_id": "13986990593551346934180369322143442319151776409512592545696715177800565940569", "price": "0.802", "size": "0", "side": "SELL", "hash": "83d5ec9f7425c800facf1f0f04b81ab8110ce768", "best_bid": "0.016", "best_ask": "0.032"}], "timestamp": "1769384811926", "event_type": "price_change"}}
{"_local_timestamp": "2026-01-25T23:46:52.389245+00:00", "data": {"market": "0xc7aca5ec2ab64207578a5461e4f3d2ad2362a6ca9edcaa6b6f05553a7d541819", "price_changes": [{"asset_id": "46477055511928802305871870544961419728762162363024275463912888154597320120223", "price": "0.199", "size": "5.55", "side": "BUY", "hash": "4f77317d7c13cec27fc8f95488b44a3c0de589c2", "best_bid": "0.968", "best_ask": "0.984"}, {"asset_id": "13986990593551346934180369322143442319151776409512592545696715177800565940569", "price": "0.801", "size": "5.55", "side": "SELL", "hash": "a741ae4e7def316d7ac4d8879271ae9944f64042", "best_bid": "0.016", "best_ask": "0.032"}], "timestamp": "1769384812320", "event_type": "price_change"}}
{"_local_timestamp": "2026-01-25T23:46:53.349046+00:00", "data": {"market": "0x4f864dda711ee273e6eb7925aada5d984da51a5f423122a00f6ae9532a3c28b9", "price_changes": [{"asset_id": "19845436317498992677729026362700087887065920346030569541585600013099473710639", "price": "0.177", "size": "7825", "side": "BUY", "hash": "3e7b960aee52d24b16fa5ec19cb35d118f3ea3a9", "best_bid": "0.949", "best_ask": "0.992"}, {"asset_id": "32968341948204373341622549015077301743176984559839089527120694005326340631965", "price": "0.823", "size": "7825", "side": "SELL", "hash": "5318075a534f93141437282aaf98eb25e113b7c8", "best_bid": "0.008", "best_ask": "0.051"}], "timestamp": "1769384813271", "event_type": "price_change"}}
{"_local_timestamp": "2026-01-25T23:46:54.151886+00:00", "data": {"market": "0x4f864dda711ee273e6eb7925aada5d984da51a5f423122a00f6ae9532a3c28b9", "price_changes": [{"asset_id": "19845436317498992677729026362700087887065920346030569541585600013099473710639", "price": "0.179", "size": "6.66", "side": "BUY", "hash": "8435796a10b13ede3b046f9dc86d54da0fcb75d6", "best_bid": "0.949", "best_ask": "0.992"}, {"asset_id": "32968341948204373341622549015077301743176984559839089527120694005326340631965", "price": "0.821", "size": "6.66", "side": "SELL", "hash": "b65c3350e1407f3f4613e5cb62bfe1e437d0a193", "best_bid": "0.008", "best_ask": "0.051"}], "timestamp": "1769384814079", "event_type": "price_change"}}
{"_local_timestamp": "2026-01-25T23:46:54.210359+00:00", "data": {"market": "0xc7aca5ec2ab64207578a5461e4f3d2ad2362a6ca9edcaa6b6f05553a7d541819", "price_changes": [{"asset_id": "46477055511928802305871870544961419728762162363024275463912888154597320120223", "price": "0.479", "size": "65", "side": "BUY", "hash": "c4173f4419090de33dd45527be05ed5fe56616eb", "best_bid": "0.968", "best_ask": "0.984"}, {"asset_id": "13986990593551346934180369322143442319151776409512592545696715177800565940569", "price": "0.521", "size": "65", "side": "SELL", "hash": "a802f9a3522eb91063ddc6ddd6cbc394996cfc06", "best_bid": "0.016", "best_ask": "0.032"}], "timestamp": "1769384814134", "event_type": "price_change"}}
{"_local_timestamp": "2026-01-25T23:46:59.270895+00:00", "data": {"market": "0xc7aca5ec2ab64207578a5461e4f3d2ad2362a6ca9edcaa6b6f05553a7d541819", "price_changes": [{"asset_id": "13986990593551346934180369322143442319151776409512592545696715177800565940569", "price": "0.003", "size": "0", "side": "BUY", "hash": "7cc3b305ec25f6b986295333faee42e180ec171d", "best_bid": "0.016", "best_ask": "0.032"}, {"asset_id": "46477055511928802305871870544961419728762162363024275463912888154597320120223", "price": "0.997", "size": "0", "side": "SELL", "hash": "72b4a38b987ea1be85f815ac0c3c7fe285f6b1f8", "best_bid": "0.968", "best_ask": "0.984"}], "timestamp": "1769384819178", "event_type": "price_change"}}
{"_local_timestamp": "2026-01-25T23:46:59.671268+00:00", "data": {"market": "0xc7aca5ec2ab64207578a5461e4f3d2ad2362a6ca9edcaa6b6f05553a7d541819", "price_changes": [{"asset_id": "13986990593551346934180369322143442319151776409512592545696715177800565940569", "price": "0.01", "size": "0", "side": "BUY", "hash": "001015b131b76a2791ffb0df3bf442782cfb1b51", "best_bid": "0.016", "best_ask": "0.032"}, {"asset_id": "46477055511928802305871870544961419728762162363024275463912888154597320120223", "price": "0.99", "size": "0", "side": "SELL", "hash": "a17d34f536602083df101748fb010a84fc2da588", "best_bid": "0.968", "best_ask": "0.984"}], "timestamp": "1769384819601", "event_type": "price_change"}}
{"_local_timestamp": "2026-01-25T23:46:59.748037+00:00", "data": {"market": "0xc7aca5ec2ab64207578a5461e4f3d2ad2362a6ca9edcaa6b6f05553a7d541819", "price_changes": [{"asset_id": "46477055511928802305871870544961419728762162363024275463912888154597320120223", "price": "0.961", "size": "0", "side": "BUY", "hash": "d4dc5d3fe50f669295ed69f32d35241a0843f222", "best_bid": "0.968", "best_ask": "0.984"}, {"asset_id": "13986990593551346934180369322143442319151776409512592545696715177800565940569", "price": "0.039", "size": "0", "side": "SELL", "hash": "5472ff3db6232ba42778367457e9c8158772ca0e", "best_bid": "0.016", "best_ask": "0.032"}], "timestamp": "1769384819672", "event_type": "price_change"}}
{"_local_timestamp": "2026-01-25T23:47:01.554938+00:00", "data": {"market": "0xc7aca5ec2ab64207578a5461e4f3d2ad2362a6ca9edcaa6b6f05553a7d541819", "price_changes": [{"asset_id": "13986990593551346934180369322143442319151776409512592545696715177800565940569", "price": "0.002", "size": "4541.31", "side": "BUY", "hash": "ae82d8ef8dfda16119679a993087bdec67425bb7", "best_bid": "0.016", "best_ask": "0.032"}, {"asset_id": "46477055511928802305871870544961419728762162363024275463912888154597320120223", "price": "0.998", "size": "4541.31", "side": "SELL", "hash": "80f4cd57ab71a28c5088e5ef9a2c4b372a314678", "best_bid": "0.968", "best_ask": "0.984"}], "timestamp": "1769384821464", "event_type": "price_change"}}
{"_local_timestamp": "2026-01-25T23:47:01.559470+00:00", "data": {"market": "0xc7aca5ec2ab64207578a5461e4f3d2ad2362a6ca9edcaa6b6f05553a7d541819", "price_changes": [{"asset_id": "46477055511928802305871870544961419728762162363024275463912888154597320120223", "price": "0.955", "size": "200", "side": "BUY", "hash": "5f2a50b7074d8f233008e96037ddd3d8e99e4fad", "best_bid": "0.968", "best_ask": "0.984"}, {"asset_id": "13986990593551346934180369322143442319151776409512592545696715177800565940569", "price": "0.045", "size": "200", "side": "SELL", "hash": "c5cac67f3f3779341725390ea0b97926972fb1ed", "best_bid": "0.016", "best_ask": "0.032"}], "timestamp": "1769384821465", "event_type": "price_change"}}
{"_local_timestamp": "2026-01-25T23:47:01.651568+00:00", "data": {"market": "0xc7aca5ec2ab64207578a5461e4f3d2ad2362a6ca9edcaa6b6f05553a7d541819", "price_changes": [{"asset_id": "13986990593551346934180369322143442319151776409512592545696715177800565940569", "price": "0.015", "size": "50", "side": "BUY", "hash": "8dc6521f4371a5cd3ca2376d5f1358cab691b166", "best_bid": "0.016", "best_ask": "0.032"}, {"asset_id": "46477055511928802305871870544961419728762162363024275463912888154597320120223", "price": "0.985", "size": "50", "side": "SELL", "hash": "27de98bad321e11fa21e16033fc698afbcf96cc0", "best_bid": "0.968", "best_ask": "0.984"}], "timestamp": "1769384821583", "event_type": "price_change"}}
{"_local_timestamp": "2026-01-25T23:47:01.706163+00:00", "data": {"market": "0x8ec3037f6f989717b8321b9c6d297698c5827d3f17bc06fa276a6826a0b468bc", "price_changes": [{"asset_id": "63727355381184542281210853076888298871978167151761041112625093048354950500520", "price": "0.629", "size": "0", "side": "BUY", "hash": "a0fd2fdd475c26cfdeca89bfbc2ab0b81393a984", "best_bid": "0.995", "best_ask": "0.997"}, {"asset_id": "54960339021810821002608536313392642741296500124718788520040272866772532121044", "price": "0.371", "size": "0", "side": "SELL", "hash": "eb3e01614f78815a2ec216cfb47b73260815e090", "best_bid": "0.003", "best_ask": "0.005"}], "timestamp": "1769384821631", "event_type": "price_change"}}
{"_local_timestamp": "2026-01-25T23:47:01.805949+00:00", "data": {"market": "0x8ec3037f6f989717b8321b9c6d297698c5827d3f17bc06fa276a6826a0b468bc", "price_changes": [{"asset_id": "63727355381184542281210853076888298871978167151761041112625093048354950500520", "price": "0.633", "size": "245", "side": "BUY", "hash": "fd71e5caeabef063ec70ab6cbf065f24c95acb44", "best_bid": "0.995", "best_ask": "0.997"}, {"asset_id": "54960339021810821002608536313392642741296500124718788520040272866772532121044", "price": "0.367", "size": "245", "side": "SELL", "hash": "46883bbe9b571bbab845c64596776aef177b057f", "best_bid": "0.003", "best_ask": "0.005"}], "timestamp": "1769384821734", "event_type": "price_change"}}
{"_local_timestamp": "2026-01-25T23:47:01.807449+00:00", "data": {"market": "0x8ec3037f6f989717b8321b9c6d297698c5827d3f17bc06fa276a6826a0b468bc", "price_changes": [{"asset_id": "63727355381184542281210853076888298871978167151761041112625093048354950500520", "price": "0.633", "size": "275", "side": "BUY", "hash": "c0f3fbe4dcf098f5f7dfe3f123a421b374f0fe2e", "best_bid": "0.995", "best_ask": "0.997"}, {"asset_id": "54960339021810821002608536313392642741296500124718788520040272866772532121044", "price": "0.367", "size": "275", "side": "SELL", "hash": "715ae0a6c07f7185929504aa42fe3c71be2c7598", "best_bid": "0.003", "best_ask": "0.005"}], "timestamp": "1769384821736", "event_type": "price_change"}}
{"_local_timestamp": "2026-01-25T23:47:01.911315+00:00", "data": {"market": "0xc7aca5ec2ab64207578a5461e4f3d2ad2362a6ca9edcaa6b6f05553a7d541819", "price_changes": [{"asset_id": "13986990593551346934180369322143442319151776409512592545696715177800565940569", "price": "0.015", "size": "119", "side": "BUY", "hash": "163c845ee9929e03e5824cdfcfe88cf042dc69a3", "best_bid": "0.016", "best_ask": "0.032"}, {"asset_id": "46477055511928802305871870544961419728762162363024275463912888154597320120223", "price": "0.985", "size": "119", "side": "SELL", "hash": "0c244b42440f117350a9c55e22a4feab2b54d6ca", "best_bid": "0.968", "best_ask": "0.984"}], "timestamp": "1769384821842", "event_type": "price_change"}}
{"_local_timestamp": "2026-01-25T23:47:01.927903+00:00", "data": {"market": "0xc7aca5ec2ab64207578a5461e4f3d2ad2362a6ca9edcaa6b6f05553a7d541819", "price_changes": [{"asset_id": "46477055511928802305871870544961419728762162363024275463912888154597320120223", "price": "0.967", "size": "211", "side": "BUY", "hash": "1afc99f40c0f332849e9106d6744e4f9d3c3e71d", "best_bid": "0.968", "best_ask": "0.984"}, {"asset_id": "13986990593551346934180369322143442319151776409512592545696715177800565940569", "price": "0.033", "size": "211", "side": "SELL", "hash": "e7608275c25c52f67313ca8cc18954311a3bcdd0", "best_bid": "0.016", "best_ask": "0.032"}], "timestamp": "1769384821854", "event_type": "price_change"}}
{"_local_timestamp": "2026-01-25T23:47:01.929384+00:00", "data": {"market": "0xc7aca5ec2ab64207578a5461e4f3d2ad2362a6ca9edcaa6b6f05553a7d541819", "price_changes": [{"asset_id": "13986990593551346934180369322143442319151776409512592545696715177800565940569", "price": "0.015", "size": "69", "side": "BUY", "hash": "42a060185148f9ed9db85171101248e166fc5dcd", "best_bid": "0.016", "best_ask": "0.032"}, {"asset_id": "46477055511928802305871870544961419728762162363024275463912888154597320120223", "price": "0.985", "size": "69", "side": "SELL", "hash": "18863177a2ef30ea2dd55a4d50e67526bd1abc68", "best_bid": "0.968", "best_ask": "0.984"}], "timestamp": "1769384821854", "event_type": "price_change"}}
{"_local_timestamp": "2026-01-25T23:47:02.169799+00:00", "data": {"market": "0xc7aca5ec2ab64207578a5461e4f3d2ad2362a6ca9edcaa6b6f05553a7d541819", "price_changes": [{"asset_id": "46477055511928802305871870544961419728762162363024275463912888154597320120223", "price": "0.967", "size": "102", "side": "BUY", "hash": "317f23652eb52f069a9f9f365fc06f1f6a776e26", "best_bid": "0.968", "best_ask": "0.984"}, {"asset_id": "13986990593551346934180369322143442319151776409512592545696715177800565940569", "price": "0.033", "size": "102", "side": "SELL", "hash": "d3faff6601b13454b6766dd5abf210e64ffe5210", "best_bid": "0.016", "best_ask": "0.032"}], "timestamp": "1769384822089", "event_type": "price_change"}}
{"_local_timestamp": "2026-01-25T23:47:02.215957+00:00", "data": {"market": "0xc7aca5ec2ab64207578a5461e4f3d2ad2362a6ca9edcaa6b6f05553a7d541819", "price_changes": [{"asset_id": "13986990593551346934180369322143442319151776409512592545696715177800565940569", "price": "0.014", "size": "152", "side": "BUY", "hash": "131cfce0c1f3211ce5e7ab5bbb46afdff33df10c", "best_bid": "0.016", "best_ask": "0.032"}, {"asset_id": "46477055511928802305871870544961419728762162363024275463912888154597320120223", "price": "0.986", "size": "152", "side": "SELL", "hash": "49d0ee70ee3cf90b85ef1c9aa2f3c6decb41c0dd", "best_bid": "0.968", "best_ask": "0.984"}], "timestamp": "1769384822149", "event_type": "price_change"}}
{"_local_timestamp": "2026-01-25T23:47:02.228792+00:00", "data": {"market": "0xc7aca5ec2ab64207578a5461e4f3d2ad2362a6ca9edcaa6b6f05553a7d541819", "price_changes": [{"asset_id": "46477055511928802305871870544961419728762162363024275463912888154597320120223", "price": "0.967", "size": "152", "side": "BUY", "hash": "f2261565340f39f47d52eca29cfe4ae1f9262932", "best_bid": "0.968", "best_ask": "0.984"}, {"asset_id": "13986990593551346934180369322143442319151776409512592545696715177800565940569", "price": "0.033", "size": "152", "side": "SELL", "hash": "7c8dd199eafb0eb11d7d3407056e3ccbf6e6650a", "best_bid": "0.016", "best_ask": "0.032"}], "timestamp": "1769384822150", "event_type": "price_change"}}
{"_local_timestamp": "2026-01-25T23:47:02.420299+00:00", "data": {"market": "0xc7aca5ec2ab64207578a5461e4f3d2ad2362a6ca9edcaa6b6f05553a7d541819", "price_changes": [{"asset_id": "46477055511928802305871870544961419728762162363024275463912888154597320120223", "price": "0.967", "size": "221", "side": "BUY", "hash": "41dfa83edcbfbe6305a2a69c67c3113a3b87aa6e", "best_bid": "0.968", "best_ask": "0.984"}, {"asset_id": "13986990593551346934180369322143442319151776409512592545696715177800565940569", "price": "0.033", "size": "221", "side": "SELL", "hash": "69a3dacbfb06f2504804da34c9b87bc4185b6380", "best_bid": "0.016", "best_ask": "0.032"}], "timestamp": "1769384822350", "event_type": "price_change"}}
{"_local_timestamp": "2026-01-25T23:47:03.182769+00:00", "data": {"market": "0xc7aca5ec2ab64207578a5461e4f3d2ad2362a6ca9edcaa6b6f05553a7d541819", "price_changes": [{"asset_id": "46477055511928802305871870544961419728762162363024275463912888154597320120223", "price": "0.967", "size": "171", "side": "BUY", "hash": "30f678eea81573ad863ae310de16bc8057f4a57c", "best_bid": "0.968", "best_ask": "0.984"}, {"asset_id": "13986990593551346934180369322143442319151776409512592545696715177800565940569", "price": "0.033", "size": "171", "side": "SELL", "hash": "dd8ca4a994d5cd48646ead85f736acaf48edad53", "best_bid": "0.016", "best_ask": "0.032"}], "timestamp": "1769384823108", "event_type": "price_change"}}
{"_local_timestamp": "2026-01-25T23:47:03.184211+00:00", "data": {"market": "0xc7aca5ec2ab64207578a5461e4f3d2ad2362a6ca9edcaa6b6f05553a7d541819", "price_changes": [{"asset_id": "13986990593551346934180369322143442319151776409512592545696715177800565940569", "price": "0.014", "size": "102", "side": "BUY", "hash": "49b94420f715917b9d29816e3c9efe217d793730", "best_bid": "0.016", "best_ask": "0.032"}, {"asset_id": "46477055511928802305871870544961419728762162363024275463912888154597320120223", "price": "0.986", "size": "102", "side": "SELL", "hash": "147b58604e3af4f5068e4740101a657b49078d4e", "best_bid": "0.968", "best_ask": "0.984"}], "timestamp": "1769384823109", "event_type": "price_change"}}
{"_local_timestamp": "2026-01-25T23:47:03.399109+00:00", "data": {"market": "0xc7aca5ec2ab64207578a5461e4f3d2ad2362a6ca9edcaa6b6f05553a7d541819", "price_changes": [{"asset_id": "13986990593551346934180369322143442319151776409512592545696715177800565940569", "price": "0.015", "size": "119", "side": "BUY", "hash": "eb123b9683d8c3e11c62812933a80be95403551b", "best_bid": "0.016", "best_ask": "0.032"}, {"asset_id": "46477055511928802305871870544961419728762162363024275463912888154597320120223", "price": "0.985", "size": "119", "side": "SELL", "hash": "2741be57a647d2403ed78b4f1342d1115b6646d8", "best_bid": "0.968", "best_ask": "0.984"}], "timestamp": "1769384823333", "event_type": "price_change"}}
{"_local_timestamp": "2026-01-25T23:47:03.405777+00:00", "data": {"market": "0xc7aca5ec2ab64207578a5461e4f3d2ad2362a6ca9edcaa6b6f05553a7d541819", "price_changes": [{"asset_id": "46477055511928802305871870544961419728762162363024275463912888154597320120223", "price": "0.967", "size": "221", "side": "BUY", "hash": "54880c1ab2aeff0919fd6602f9acca1916d95026", "best_bid": "0.968", "best_ask": "0.984"}, {"asset_id": "13986990593551346934180369322143442319151776409512592545696715177800565940569", "price": "0.033", "size": "221", "side": "SELL", "hash": "22f1da675bca54cfe7161474c0affc0e90b811a6", "best_bid": "0.016", "best_ask": "0.032"}], "timestamp": "1769384823334", "event_type": "price_change"}}
{"_local_timestamp": "2026-01-25T23:47:03.529403+00:00", "data": {"market": "0x8ec3037f6f989717b8321b9c6d297698c5827d3f17bc06fa276a6826a0b468bc", "price_changes": [{"asset_id": "63727355381184542281210853076888298871978167151761041112625093048354950500520", "price": "0.632", "size": "0", "side": "BUY", "hash": "4cca91766fdc181493a84ece1cf65fd132d5c394", "best_bid": "0.995", "best_ask": "0.997"}, {"asset_id": "54960339021810821002608536313392642741296500124718788520040272866772532121044", "price": "0.368", "size": "0", "side": "SELL", "hash": "d0ea2c91d11fc5fbe066db1a72c804ad1f19be7f", "best_bid": "0.003", "best_ask": "0.005"}], "timestamp": "1769384823460", "event_type": "price_change"}}
{"_local_timestamp": "2026-01-25T23:47:03.553563+00:00", "data": {"market": "0x8ec3037f6f989717b8321b9c6d297698c5827d3f17bc06fa276a6826a0b468bc", "price_changes": [{"asset_id": "63727355381184542281210853076888298871978167151761041112625093048354950500520", "price": "0.634", "size": "20", "side": "BUY", "hash": "a740759631c0170d042795d40a8d962b7c6fa6ff", "best_bid": "0.995", "best_ask": "0.997"}, {"asset_id": "54960339021810821002608536313392642741296500124718788520040272866772532121044", "price": "0.366", "size": "20", "side": "SELL", "hash": "36ae7bd1b0ffc9c294f2bd1343867173d1459c80", "best_bid": "0.003", "best_ask": "0.005"}], "timestamp": "1769384823485", "event_type": "price_change"}}
{"_local_timestamp": "2026-01-25T23:47:03.572170+00:00", "data": {"market": "0x8ec3037f6f989717b8321b9c6d297698c5827d3f17bc06fa276a6826a0b468bc", "price_changes": [{"asset_id": "63727355381184542281210853076888298871978167151761041112625093048354950500520", "price": "0.633", "size": "30", "side": "BUY", "hash": "11da01f3874f239c9e43396cbe94eaff2aa9d2ed", "best_bid": "0.995", "best_ask": "0.997"}, {"asset_id": "54960339021810821002608536313392642741296500124718788520040272866772532121044", "price": "0.367", "size": "30", "side": "SELL", "hash": "4e25920b7bc51c8e71585684e70dd680fb2d11be", "best_bid": "0.003", "best_ask": "0.005"}], "timestamp": "1769384823498", "event_type": "price_change"}}
{"_local_timestamp": "2026-01-25T23:47:04.754332+00:00", "data": {"market": "0xc7aca5ec2ab64207578a5461e4f3d2ad2362a6ca9edcaa6b6f05553a7d541819", "price_changes": [{"asset_id": "13986990593551346934180369322143442319151776409512592545696715177800565940569", "price": "0.015", "size": "50", "side": "BUY", "hash": "ba4cf3cc3c29d98ea9abbf5ad613258f6b0cdaaa", "best_bid": "0.016", "best_ask": "0.032"}, {"asset_id": "46477055511928802305871870544961419728762162363024275463912888154597320120223", "price": "0.985", "size": "50", "side": "SELL", "hash": "9b52fd4a6e741e3482457bc85700e6b270372dca", "best_bid": "0.968", "best_ask": "0.984"}], "timestamp": "1769384824672", "event_type": "price_change"}}
{"_local_timestamp": "2026-01-25T23:47:04.996246+00:00", "data": {"market": "0xc7aca5ec2ab64207578a5461e4f3d2ad2362a6ca9edcaa6b6f05553a7d541819", "price_changes": [{"asset_id": "13986990593551346934180369322143442319151776409512592545696715177800565940569", "price": "0.015", "size": "268", "side": "BUY", "hash": "f1c70d1afd3bd8d9b4368f4341239671cbe05a6c", "best_bid": "0.016", "best_ask": "0.032"}, {"asset_id": "46477055511928802305871870544961419728762162363024275463912888154597320120223", "price": "0.985", "size": "268", "side": "SELL", "hash": "eb48de02ad283811f810efbce15aa3aff386c8e6", "best_bid": "0.968", "best_ask": "0.984"}], "timestamp": "1769384824919", "event_type": "price_change"}}
{"_local_timestamp": "2026-01-25T23:47:05.216526+00:00", "data": {"market": "0xc7aca5ec2ab64207578a5461e4f3d2ad2362a6ca9edcaa6b6f05553a7d541819", "price_changes": [{"asset_id": "46477055511928802305871870544961419728762162363024275463912888154597320120223", "price": "0.967", "size": "152", "side": "BUY", "hash": "40358a5d503449dd5f13fbac1683284396533848", "best_bid": "0.968", "best_ask": "0.984"}, {"asset_id": "13986990593551346934180369322143442319151776409512592545696715177800565940569", "price": "0.033", "size": "152", "side": "SELL", "hash": "e1b4967fa402ea889b3d74d5b60c0532b3ffba08", "best_bid": "0.016", "best_ask": "0.032"}], "timestamp": "1769384825144", "event_type": "price_change"}}
{"_local_timestamp": "2026-01-25T23:47:05.439553+00:00", "data": {"market": "0xc7aca5ec2ab64207578a5461e4f3d2ad2362a6ca9edcaa6b6f05553a7d541819", "price_changes": [{"asset_id": "46477055511928802305871870544961419728762162363024275463912888154597320120223", "price": "0.479", "size": "60", "side": "BUY", "hash": "3dd6d3baf388676e804dcea1848aec092e188633", "best_bid": "0.968", "best_ask": "0.984"}, {"asset_id": "13986990593551346934180369322143442319151776409512592545696715177800565940569", "price": "0.521", "size": "60", "side": "SELL", "hash": "b669e79c566b024070ce5ffb5b9dfff661874447", "best_bid": "0.016", "best_ask": "0.032"}], "timestamp": "1769384825362", "event_type": "price_change"}}
{"_local_timestamp": "2026-01-25T23:47:05.443415+00:00", "data": {"market": "0xc7aca5ec2ab64207578a5461e4f3d2ad2362a6ca9edcaa6b6f05553a7d541819", "price_changes": [{"asset_id": "46477055511928802305871870544961419728762162363024275463912888154597320120223", "price": "0.967", "size": "370", "side": "BUY", "hash": "64444ed99292c5edecbcd39a8a895d80207e9eb4", "best_bid": "0.968", "best_ask": "0.984"}, {"asset_id": "13986990593551346934180369322143442319151776409512592545696715177800565940569", "price": "0.033", "size": "370", "side": "SELL", "hash": "1c012b23bdb5458e59a2684bfee12f7729a8a555", "best_bid": "0.016", "best_ask": "0.032"}], "timestamp": "1769384825372", "event_type": "price_change"}}
{"_local_timestamp": "2026-01-25T23:47:05.537021+00:00", "data": {"market": "0xc7aca5ec2ab64207578a5461e4f3d2ad2362a6ca9edcaa6b6f05553a7d541819", "price_changes": [{"asset_id": "46477055511928802305871870544961419728762162363024275463912888154597320120223", "price": "0.482", "size": "227", "side": "BUY", "hash": "d9d4b28c27e37b5b54a3adc18fec27a53abba4ae", "best_bid": "0.968", "best_ask": "0.984"}, {"asset_id": "13986990593551346934180369322143442319151776409512592545696715177800565940569", "price": "0.518", "size": "227", "side": "SELL", "hash": "f4e436877c81a563b2df05708f96f4d6a16f257d", "best_bid": "0.016", "best_ask": "0.032"}], "timestamp": "1769384825457", "event_type": "price_change"}}
{"_local_timestamp": "2026-01-25T23:47:05.538773+00:00", "data": {"market": "0xc7aca5ec2ab64207578a5461e4f3d2ad2362a6ca9edcaa6b6f05553a7d541819", "price_changes": [{"asset_id": "46477055511928802305871870544961419728762162363024275463912888154597320120223", "price": "0.908", "size": "25", "side": "BUY", "hash": "ff093cf3e2e3ef3d96c39c0405f17797dabd9cbf", "best_bid": "0.968", "best_ask": "0.984"}, {"asset_id": "13986990593551346934180369322143442319151776409512592545696715177800565940569", "price": "0.092", "size": "25", "side": "SELL", "hash": "a0c64833b846d702769fbd189898a359f4a9de64", "best_bid": "0.016", "best_ask": "0.032"}], "timestamp": "1769384825459", "event_type": "price_change"}}
{"_local_timestamp": "2026-01-25T23:47:08.730321+00:00", "data": {"market": "0xc7aca5ec2ab64207578a5461e4f3d2ad2362a6ca9edcaa6b6f05553a7d541819", "price_changes": [{"asset_id": "46477055511928802305871870544961419728762162363024275463912888154597320120223", "price": "0.482", "size": "207", "side": "BUY", "hash": "55f6b43099a0b455f27923cb62fcc136fb914762", "best_bid": "0.968", "best_ask": "0.984"}, {"asset_id": "13986990593551346934180369322143442319151776409512592545696715177800565940569", "price": "0.518", "size": "207", "side": "SELL", "hash": "6c971586c4c3eccb14c19dc30710c02a977e02c4", "best_bid": "0.016", "best_ask": "0.032"}], "timestamp": "1769384828624", "event_type": "price_change"}}
{"_local_timestamp": "2026-01-25T23:47:08.745628+00:00", "data": {"market": "0xc7aca5ec2ab64207578a5461e4f3d2ad2362a6ca9edcaa6b6f05553a7d541819", "price_changes": [{"asset_id": "46477055511928802305871870544961419728762162363024275463912888154597320120223", "price": "0.483", "size": "20", "side": "BUY", "hash": "db6f43c81f497b7a2df43cee7a72b90671e85bfa", "best_bid": "0.968", "best_ask": "0.984"}, {"asset_id": "13986990593551346934180369322143442319151776409512592545696715177800565940569", "price": "0.517", "size": "20", "side": "SELL", "hash": "c66173f047c80dea117f23515ee3f713e76dfa30", "best_bid": "0.016", "best_ask": "0.032"}], "timestamp": "1769384828662", "event_type": "price_change"}}
{"_local_timestamp": "2026-01-25T23:47:11.637242+00:00", "data": {"market": "0xc7aca5ec2ab64207578a5461e4f3d2ad2362a6ca9edcaa6b6f05553a7d541819", "price_changes": [{"asset_id": "13986990593551346934180369322143442319151776409512592545696715177800565940569", "price": "0.004", "size": "7.83", "side": "BUY", "hash": "dbcb614fa24e48c4d1be948af8b0a09f10b623b3", "best_bid": "0.016", "best_ask": "0.032"}, {"asset_id": "46477055511928802305871870544961419728762162363024275463912888154597320120223", "price": "0.996", "size": "7.83", "side": "SELL", "hash": "b26cc090e492833ba600a6d95ad75ac4691525ed", "best_bid": "0.968", "best_ask": "0.984"}], "timestamp": "1769384831563", "event_type": "price_change"}}
{"_local_timestamp": "2026-01-25T23:47:15.858923+00:00", "data": {"market": "0xc7aca5ec2ab64207578a5461e4f3d2ad2362a6ca9edcaa6b6f05553a7d541819", "price_changes": [{"asset_id": "13986990593551346934180369322143442319151776409512592545696715177800565940569", "price": "0.002", "size": "4591.31", "side": "BUY", "hash": "b2211392b2dd114709af58aecdb6322d5bb8e908", "best_bid": "0.016", "best_ask": "0.032"}, {"asset_id": "46477055511928802305871870544961419728762162363024275463912888154597320120223", "price": "0.998", "size": "4591.31", "side": "SELL", "hash": "664e4e698e1a666a27545e0a333cbb7c365bc1c6", "best_bid": "0.968", "best_ask": "0.984"}], "timestamp": "1769384835784", "event_type": "price_change"}}
{"_local_timestamp": "2026-01-25T23:47:21.291389+00:00", "data": {"market": "0xc7aca5ec2ab64207578a5461e4f3d2ad2362a6ca9edcaa6b6f05553a7d541819", "price_changes": [{"asset_id": "46477055511928802305871870544961419728762162363024275463912888154597320120223", "price": "0.264", "size": "1590", "side": "BUY", "hash": "81d1e1290f168316da8154a6e30b3384fcf913df", "best_bid": "0.968", "best_ask": "0.984"}, {"asset_id": "13986990593551346934180369322143442319151776409512592545696715177800565940569", "price": "0.736", "size": "1590", "side": "SELL", "hash": "cfbc9ca425676efbd99bd86b2a440a92ddfabe9b", "best_bid": "0.016", "best_ask": "0.032"}], "timestamp": "1769384841224", "event_type": "price_change"}}
{"_local_timestamp": "2026-01-25T23:47:37.671940+00:00", "data": {"market": "0x4b04e14bcde7be95db753c88f6fed57423835215bb41937406e75dc22a789b0c", "price_changes": [{"asset_id": "75013115303617466002500221618724536968904237026728502667764718978862356730825", "price": "0.224", "size": "0", "side": "BUY", "hash": "e1b5b27ec871ab093e458114789d1a58e7ca6c6d", "best_bid": "0.995", "best_ask": "0.998"}, {"asset_id": "195928349533315596595305126471738494775883003093487532708892885008234493544", "price": "0.776", "size": "0", "side": "SELL", "hash": "d75f310c90557b9e44be7d25d348d3659e722883", "best_bid": "0.002", "best_ask": "0.005"}], "timestamp": "1769384857530", "event_type": "price_change"}}
{"_local_timestamp": "2026-01-25T23:47:37.673932+00:00", "data": {"market": "0x4f864dda711ee273e6eb7925aada5d984da51a5f423122a00f6ae9532a3c28b9", "price_changes": [{"asset_id": "19845436317498992677729026362700087887065920346030569541585600013099473710639", "price": "0.175", "size": "0", "side": "BUY", "hash": "ec1d082ea53fb8d20ef226e0c0e689982008fb6c", "best_bid": "0.949", "best_ask": "0.992"}, {"asset_id": "32968341948204373341622549015077301743176984559839089527120694005326340631965", "price": "0.825", "size": "0", "side": "SELL", "hash": "16baaa74f4a3cbed8de1655adfbd3455b34cc881", "best_bid": "0.008", "best_ask": "0.051"}], "timestamp": "1769384857531", "event_type": "price_change"}}
{"_local_timestamp": "2026-01-25T23:47:37.675314+00:00", "data": {"market": "0xc7aca5ec2ab64207578a5461e4f3d2ad2362a6ca9edcaa6b6f05553a7d541819", "price_changes": [{"asset_id": "46477055511928802305871870544961419728762162363024275463912888154597320120223", "price": "0.195", "size": "355", "side": "BUY", "hash": "bdbd4aab7b591dd7a39f2e897a892d36d8bff97f", "best_bid": "0.968", "best_ask": "0.984"}, {"asset_id": "13986990593551346934180369322143442319151776409512592545696715177800565940569", "price": "0.805", "size": "355", "side": "SELL", "hash": "188b5d1dbd680f34a96a408b439d3e1a9bd82a49", "best_bid": "0.016", "best_ask": "0.032"}], "timestamp": "1769384857531", "event_type": "price_change"}}
{"_local_timestamp": "2026-01-25T23:47:37.676855+00:00", "data": {"market": "0x4cb1b09d2a17a1e21e459f4e431999bc3bfbb40cc9023b3354aa70e2d7d81875", "price_changes": [{"asset_id": "75701058868331201775069911407645821013233843572698963559250184599603027030054", "price": "0.214", "size": "0", "side": "BUY", "hash": "47a5f05a389069726190b766b145d0f67df451e1", "best_bid": "0.965", "best_ask": "0.992"}, {"asset_id": "114492877966140684018682752756008128367968333531744283465420223400327242203881", "price": "0.786", "size": "0", "side": "SELL", "hash": "1de18d64bd4d66365d17f74bd3d2aee1996ac118", "best_bid": "0.008", "best_ask": "0.035"}], "timestamp": "1769384857530", "event_type": "price_change"}}
