{"_local_timestamp": "2026-01-25T23:40:30.648454+00:00", "data": [{"market": "0xe2dfc02908b8fb5e7c6578a42e17b52434f5346bb532ab5715dbbfd46af57a21", "asset_id": "79024099644769201382883588167557335172113039460336000034907727657308480799729", "timestamp": "1769384331456", "hash": "4356f968ae256980f7c70c96e277e0221e9ea61d", "bids": [{"price": "0.001", "size": "830"}], "asks": [{"price": "0.999", "size": "100144.23"}, {"price": "0.998", "size": "55000"}, {"price": "0.997", "size": "22.41"}, {"price": "0.992", "size": "155"}, {"price": "0.99", "size": "920410"}, {"price": "0.989", "size": "55710"}, {"price": "0.988", "size": "11.81"}, {"price": "0.98", "size": "6000"}, {"price": "0.969", "size": "10000"}, {"price": "0.968", "size": "5.88"}, {"price": "0.96", "size": "303200"}, {"price": "0.95", "size": "1620"}, {"price": "0.94", "size": "33"}, {"price": "0.939", "size": "7.75"}, {"price": "0.92", "size": "155"}, {"price": "0.903", "size": "100"}, {"price": "0.901", "size": "100"}, {"price": "0.9", "size": "6000"}, {"price": "0.899", "size": "10300"}, {"price": "0.89", "size": "3000"}, {"price": "0.85", "size": "500"}, {"price": "0.849", "size": "7.37"}, {"price": "0.795", "size": "2640"}, {"price": "0.794", "size": "1800"}, {"price": "0.793", "size": "300"}, {"price": "0.78", "size": "21"}, {"price": "0.53", "size": "100"}, {"price": "0.51", "size": "100"}, {"price": "0.503", "size": "100"}, {"price": "0.501", "size": "500"}, {"price": "0.5", "size": "480"}, {"price": "0.499", "size": "20"}, {"price": "0.498", "size": "5"}, {"price": "0.426", "size": "5"}, {"price": "0.25", "size": "60"}, {"price": "0.249", "size": "53"}, {"price": "0.23", "size": "180"}, {"price": "0.2", "size": "100"}, {"price": "0.18", "size": "100"}, {"price": "0.17", "size": "50"}, {"price": "0.16", "size": "100"}, {"price": "0.159", "size": "144"}, {"price": "0.15", "size": "50"}, {"price": "0.14", "size": "5"}, {"price": "0.1", "size": "30"}, {"price": "0.01", "size": "100"}, {"price": "0.009", "size": "500"}], "event_type": "book", "last_trade_price": "0.010"}, {"market": "0x0b436d14d29b7f778768ffb123a526b4dc496054e26d820d691e9b59f2ae15bf", "asset_id": "18488621325714747371592358988913690051744048045248507898917802091914468336625", "timestamp": "1769384412226", "hash": "267fef94fb7817e34fbf144ddbd3b444d4c00211", "bids": [{"price": "0.01", "size": "803230.08"}, {"price": "0.02", "size": "1800"}, {"price": "0.03", "size": "17.31"}, {"price": "0.05", "size": "1000"}, {"price": "0.08", "size": "2000"}, {"price": "0.09", "size": "505.27"}, {"price": "0.1", "size": "500"}, {"price": "0.11", "size": "250"}, {"price": "0.15", "size": "500"}, {"price": "0.16", "size": "5.03"}, {"price": "0.28", "size": "230"}, {"price": "0.29", "size": "83.91"}, {"price": "0.3", "size": "40"}, {"price": "0.32", "size": "218"}], "asks": [{"price": "0.99", "size": "203210"}, {"price": "0.98", "size": "1009.26"}, {"price": "0.97", "size": "6200"}, {"price": "0.95", "size": "760"}, {"price": "0.94", "size": "8.02"}, {"price": "0.9", "size": "15"}, {"price": "0.68", "size": "200"}, {"price": "0.67", "size": "100"}, {"price": "0.66", "size": "40"}, {"price": "0.65", "size": "350"}], "event_type": "book", "last_trade_price": "0.310"}, {"market": "0xe2dfc02908b8fb5e7c6578a42e17b52434f5346bb532ab5715dbbfd46af57a21", "asset_id": "3269263393231035282910557398978207346672294813068410578094427630928688366591", "timestamp": "1769384331456", "hash": "a5af46b37e4eb1d77672385e5fc8835b675f55ae", "bids": [{"price": "0.001", "size": "100144.23"}, {"price": "0.002", "size": "55000"}, {"price": "0.003", "size": "22.41"}, {"price": "0.008", "size": "155"}, {"price": "0.01", "size": "920410"}, {"price": "0.011", "size": "55710"}, {"price": "0.012", "size": "11.81"}, {"price": "0.02", "size": "6000"}, {"price": "0.031", "size": "10000"}, {"price": "0.032", "size": "5.88"}, {"price": "0.04", "size": "303200"}, {"price": "0.05", "size": "1620"}, {"price": "0.06", "size": "33"}, {"price": "0.061", "size": "7.75"}, {"price": "0.08", "size": "155"}, {"price": "0.097", "size": "100"}, {"price": "0.099", "size": "100"}, {"price": "0.1", "size": "6000"}, {"price": "0.101", "size": "10300"}, {"price": "0.11", "size": "3000"}, {"price": "0.15", "size": "500"}, {"price": "0.151", "size": "7.37"}, {"price": "0.205", "size": "2640"}, {"price": "0.206", "size": "1800"}, {"price": "0.207", "size": "300"}, {"price": "0.22", "size": "21"}, {"price": "0.47", "size": "100"}, {"price": "0.49", "size": "100"}, {"price": "0.497", "size": "100"}, {"price": "0.499", "size": "500"}, {"price": "0.5", "size": "480"}, {"price": "0.501", "size": "20"}, {"price": "0.502", "size": "5"}, {"price": "0.574", "size": "5"}, {"price": "0.75", "size": "60"}, {"price": "0.751", "size": "53"}, {"price": "0.77", "size": "180"}, {"price": "0.8", "size": "100"}, {"price": "0.82", "size": "100"}, {"price": "0.83", "size": "50"}, {"price": "0.84", "size": "100"}, {"price": "0.841", "size": "144"}, {"price": "0.85", "size": "50"}, {"price": "0.86", "size": "5"}, {"price": "0.9", "size": "30"}, {"price": "0.99", "size": "100"}, {"price": "0.991", "size": "500"}], "asks": [{"price": "0.999", "size": "830"}], "event_type": "book", "last_trade_price": "0.010"}, {"market": "0x092c91d348e732e6e1d10cb85e855ae2982167cc8a514de6d5ce0ed6a81b3406", "asset_id": "106600613356134795904313062212730477275252691648870475628884876817519043940991", "timestamp": "1769384394310", "hash": "639d655db9be13cfa12530289af765bd7f6051b9", "bids": [{"price": "0.01", "size": "203208.5"}, {"price": "0.02", "size": "2205.92"}, {"price": "0.03", "size": "300"}, {"price": "0.04", "size": "56.25"}, {"price": "0.05", "size": "10.96"}, {"price": "0.17", "size": "100"}, {"price": "0.28", "size": "75"}, {"price": "0.29", "size": "90"}, {"price": "0.3", "size": "40"}, {"price": "0.31", "size": "50"}, {"price": "0.32", "size": "145"}, {"price": "0.33", "size": "113.64"}], "asks": [{"price": "0.99", "size": "803225.17"}, {"price": "0.98", "size": "6800"}, {"price": "0.97", "size": "6.92"}, {"price": "0.95", "size": "1030"}, {"price": "0.94", "size": "2933"}, {"price": "0.93", "size": "7.89"}, {"price": "0.9", "size": "500"}, {"price": "0.85", "size": "800"}, {"price": "0.84", "size": "2000"}, {"price": "0.83", "size": "11"}, {"price": "0.82", "size": "6.04"}, {"price": "0.8", "size": "12"}, {"price": "0.79", "size": "20"}, {"price": "0.67", "size": "60"}, {"price": "0.41", "size": "50"}, {"price": "0.4", "size": "100"}, {"price": "0.39", "size": "40"}, {"price": "0.38", "size": "100"}, {"price": "0.37", "size": "70.44"}, {"price": "0.36", "size": "100"}], "event_type": "book", "last_trade_price": "0.330"}, {"market": "0x092c91d348e732e6e1d10cb85e855ae2982167cc8a514de6d5ce0ed6a81b3406", "asset_id": "63124470287776887476483587791259448657774659174144661407693923638503676979579", "timestamp": "1769384394310", "hash": "ab32b1d5905f0ec494f1ecc98cd9d50b03a706d2", "bids": [{"price": "0.01", "size": "803225.17"}, {"price": "0.02", "size": "6800"}, {"price": "0.03", "size": "6.92"}, {"price": "0.05", "size": "1030"}, {"price": "0.06", "size": "2933"}, {"price": "0.07", "size": "7.89"}, {"price": "0.1", "size": "500"}, {"price": "0.15", "size": "800"}, {"price": "0.16", "size": "2000"}, {"price": "0.17", "size": "11"}, {"price": "0.18", "size": "6.04"}, {"price": "0.2", "size": "12"}, {"price": "0.21", "size": "20"}, {"price": "0.33", "size": "60"}, {"price": "0.59", "size": "50"}, {"price": "0.6", "size": "100"}, {"price": "0.61", "size": "40"}, {"price": "0.62", "size": "100"}, {"price": "0.63", "size": "70.44"}, {"price": "0.64", "size": "100"}], "asks": [{"price": "0.99", "size": "203208.5"}, {"price": "0.98", "size": "2205.92"}, {"price": "0.97", "size": "300"}, {"price": "0.96", "size": "56.25"}, {"price": "0.95", "size": "10.96"}, {"price": "0.83", "size": "100"}, {"price": "0.72", "size": "75"}, {"price": "0.71", "size": "90"}, {"price": "0.7", "size": "40"}, {"price": "0.69", "size": "50"}, {"price": "0.68", "size": "145"}, {"price": "0.67", "size": "113.64"}], "event_type": "book", "last_trade_price": "0.330"}, {"market": "0x0b436d14d29b7f778768ffb123a526b4dc496054e26d820d691e9b59f2ae15bf", "asset_id": "78125564118195609688130723464750437875510814435361379152154876368715602249491", "timestamp": "1769384412226", "hash": "17376236fc265420f21564ae234770fe2291e334", "bids": [{"price": "0.01", "size": "203210"}, {"price": "0.02", "size": "1009.26"}, {"price": "0.03", "size": "6200"}, {"price": "0.05", "size": "760"}, {"price": "0.06", "size": "8.02"}, {"price": "0.1", "size": "15"}, {"price": "0.32", "size": "200"}, {"price": "0.33", "size": "100"}, {"price": "0.34", "size": "40"}, {"price": "0.35", "size": "350"}], "asks": [{"price": "0.99", "size": "803230.08"}, {"price": "0.98", "size": "1800"}, {"price": "0.97", "size": "17.31"}, {"price": "0.95", "size": "1000"}, {"price": "0.92", "size": "2000"}, {"price": "0.91", "size": "505.27"}, {"price": "0.9", "size": "500"}, {"price": "0.89", "size": "250"}, {"price": "0.85", "size": "500"}, {"price": "0.84", "size": "5.03"}, {"price": "0.72", "size": "230"}, {"price": "0.71", "size": "83.91"}, {"price": "0.7", "size": "40"}, {"price": "0.68", "size": "218"}], "event_type": "book", "last_trade_price": "0.310"}]}
{"_local_timestamp": "2026-01-25T23:40:32.134443+00:00", "data": {"market": "0x092c91d348e732e6e1d10cb85e855ae2982167cc8a514de6d5ce0ed6a81b3406", "price_changes": [{"asset_id": "63124470287776887476483587791259448657774659174144661407693923638503676979579", "price": "0.18", "size": "0", "side": "BUY", "hash": "4693f462e84d7d09d35a56efd6e5a59ef652ab2c", "best_bid": "0.64", "best_ask": "0.67"}, {"asset_id": "106600613356134795904313062212730477275252691648870475628884876817519043940991", "price": "0.82", "size": "0", "side": "SELL", "hash": "16a30b78ed2f24da2a5c95ea39baded0dbf4f37a", "best_bid": "0.33", "best_ask": "0.36"}], "timestamp": "1769384432069", "event_type": "price_change"}}
{"_local_timestamp": "2026-01-25T23:40:32.747697+00:00", "data": {"market": "0x092c91d348e732e6e1d10cb85e855ae2982167cc8a514de6d5ce0ed6a81b3406", "price_changes": [{"asset_id": "63124470287776887476483587791259448657774659174144661407693923638503676979579", "price": "0.18", "size": "6.04", "side": "BUY", "hash": "3e79a32a147cf0242b079ae37fc24bec2be845eb", "best_bid": "0.64", "best_ask": "0.67"}, {"asset_id": "106600613356134795904313062212730477275252691648870475628884876817519043940991", "price": "0.82", "size": "6.04", "side": "SELL", "hash": "309862376ea0f595f7c4d32d445bd432be65dbc6", "best_bid": "0.33", "best_ask": "0.36"}], "timestamp": "1769384432685", "event_type": "price_change"}}
{"_local_timestamp": "2026-01-25T23:40:33.862810+00:00", "data": {"market": "0x0b436d14d29b7f778768ffb123a526b4dc496054e26d820d691e9b59f2ae15bf", "price_changes": [{"asset_id": "18488621325714747371592358988913690051744048045248507898917802091914468336625", "price": "0.03", "size": "7.49", "side": "BUY", "hash": "95228a433ae975cf0ae09213c965f2a0b67b61c4", "best_bid": "0.32", "best_ask": "0.65"}, {"asset_id": "78125564118195609688130723464750437875510814435361379152154876368715602249491", "price": "0.97", "size": "7.49", "side": "SELL", "hash": "45016ba863d25c003397f0cbb3f2cb7beeaa847c", "best_bid": "0.35", "best_ask": "0.68"}], "timestamp": "1769384433798", "event_type": "price_change"}}
{"_local_timestamp": "2026-01-25T23:40:33.864211+00:00", "data": {"market": "0x0b436d14d29b7f778768ffb123a526b4dc496054e26d820d691e9b59f2ae15bf", "price_changes": [{"asset_id": "18488621325714747371592358988913690051744048045248507898917802091914468336625", "price": "0.09", "size": "500", "side": "BUY", "hash": "95228a433ae975cf0ae09213c965f2a0b67b61c4", "best_bid": "0.32", "best_ask": "0.65"}, {"asset_id": "78125564118195609688130723464750437875510814435361379152154876368715602249491", "price": "0.91", "size": "500", "side": "SELL", "hash": "45016ba863d25c003397f0cbb3f2cb7beeaa847c", "best_bid": "0.35", "best_ask": "0.68"}], "timestamp": "1769384433798", "event_type": "price_change"}}
{"_local_timestamp": "2026-01-25T23:40:33.864785+00:00", "data": {"market": "0x0b436d14d29b7f778768ffb123a526b4dc496054e26d820d691e9b59f2ae15bf", "price_changes": [{"asset_id": "18488621325714747371592358988913690051744048045248507898917802091914468336625", "price": "0.16", "size": "0", "side": "BUY", "hash": "95228a433ae975cf0ae09213c965f2a0b67b61c4", "best_bid": "0.32", "best_ask": "0.65"}, {"asset_id": "78125564118195609688130723464750437875510814435361379152154876368715602249491", "price": "0.84", "size": "0", "side": "SELL", "hash": "45016ba863d25c003397f0cbb3f2cb7beeaa847c", "best_bid": "0.35", "best_ask": "0.68"}], "timestamp": "1769384433798", "event_type": "price_change"}}
{"_local_timestamp": "2026-01-25T23:40:35.353118+00:00", "data": {"market": "0x0b436d14d29b7f778768ffb123a526b4dc496054e26d820d691e9b59f2ae15bf", "price_changes": [{"asset_id": "18488621325714747371592358988913690051744048045248507898917802091914468336625", "price": "0.06", "size": "8.03", "side": "BUY", "hash": "faca2ae9cdfeba9e995b827457c170cf4b352727", "best_bid": "0.32", "best_ask": "0.65"}, {"asset_id": "78125564118195609688130723464750437875510814435361379152154876368715602249491", "price": "0.94", "size": "8.03", "side": "SELL", "hash": "89e8293512fed573c30acf90757d6765ee22fb1d", "best_bid": "0.35", "best_ask": "0.68"}], "timestamp": "1769384435286", "event_type": "price_change"}}
{"_local_timestamp": "2026-01-25T23:40:35.353853+00:00", "data": {"market": "0x0b436d14d29b7f778768ffb123a526b4dc496054e26d820d691e9b59f2ae15bf", "price_changes": [{"asset_id": "18488621325714747371592358988913690051744048045248507898917802091914468336625", "price": "0.12", "size": "9.1", "side": "BUY", "hash": "a5808f5553fe895e49c3446339a1619871cfe9e8", "best_bid": "0.32", "best_ask": "0.65"}, {"asset_id": "78125564118195609688130723464750437875510814435361379152154876368715602249491", "price": "0.88", "size": "9.1", "side": "SELL", "hash": "a7ecb863b16000a23b65429daf421345989317f2", "best_bid": "0.35", "best_ask": "0.68"}], "timestamp": "1769384435287", "event_type": "price_change"}}
{"_local_timestamp": "2026-01-25T23:40:40.963075+00:00", "data": {"market": "0x092c91d348e732e6e1d10cb85e855ae2982167cc8a514de6d5ce0ed6a81b3406", "price_changes": [{"asset_id": "106600613356134795904313062212730477275252691648870475628884876817519043940991", "price": "0.33", "size": "70", "side": "BUY", "hash": "10dac097ad4f83cbaa8325f2fa7811ca763c69a2", "best_bid": "0.33", "best_ask": "0.36"}, {"asset_id": "63124470287776887476483587791259448657774659174144661407693923638503676979579", "price": "0.67", "size": "70", "side": "SELL", "hash": "a67f6481799ab101bf1766c008b32d6844378515", "best_bid": "0.64", "best_ask": "0.67"}], "timestamp": "1769384440894", "event_type": "price_change"}}
{"_local_timestamp": "2026-01-25T23:40:53.715963+00:00", "data": {"market": "0x092c91d348e732e6e1d10cb85e855ae2982167cc8a514de6d5ce0ed6a81b3406", "price_changes": [{"asset_id": "106600613356134795904313062212730477275252691648870475628884876817519043940991", "price": "0.33", "size": "80.91", "side": "BUY", "hash": "c40786a601601e94c8b52899937254afe6bbd029", "best_bid": "0.33", "best_ask": "0.36"}, {"asset_id": "63124470287776887476483587791259448657774659174144661407693923638503676979579", "price": "0.67", "size": "80.91", "side": "SELL", "hash": "24cf94bb0a135610cc8fdf0c59f586d6e2b91300", "best_bid": "0.64", "best_ask": "0.67"}], "timestamp": "1769384453650", "event_type": "price_change"}}
{"_local_timestamp": "2026-01-25T23:40:53.716863+00:00", "data": {"market": "0x092c91d348e732e6e1d10cb85e855ae2982167cc8a514de6d5ce0ed6a81b3406", "price_changes": [{"asset_id": "106600613356134795904313062212730477275252691648870475628884876817519043940991", "price": "0.33", "size": "91.82", "side": "BUY", "hash": "1180ad9f8f66ca272b6edcbaac29f58bde0fbe3d", "best_bid": "0.33", "best_ask": "0.36"}, {"asset_id": "63124470287776887476483587791259448657774659174144661407693923638503676979579", "price": "0.67", "size": "91.82", "side": "SELL", "hash": "e41ed8597f972734263b13457b63af6db51d95db", "best_bid": "0.64", "best_ask": "0.67"}], "timestamp": "1769384453650", "event_type": "price_change"}}
{"_local_timestamp": "2026-01-25T23:40:53.720232+00:00", "data": {"market": "0x092c91d348e732e6e1d10cb85e855ae2982167cc8a514de6d5ce0ed6a81b3406", "price_changes": [{"asset_id": "106600613356134795904313062212730477275252691648870475628884876817519043940991", "price": "0.33", "size": "102.73", "side": "BUY", "hash": "f00a1d40d2e818200572d7c20593c2dc6bf517a7", "best_bid": "0.33", "best_ask": "0.36"}, {"asset_id": "63124470287776887476483587791259448657774659174144661407693923638503676979579", "price": "0.67", "size": "102.73", "side": "SELL", "hash": "881d2c5eea0bf7ad9396cacd4a7b475b3e8d8f01", "best_bid": "0.64", "best_ask": "0.67"}], "timestamp": "1769384453651", "event_type": "price_change"}}
{"_local_timestamp": "2026-01-25T23:40:53.721472+00:00", "data": {"market": "0x092c91d348e732e6e1d10cb85e855ae2982167cc8a514de6d5ce0ed6a81b3406", "price_changes": [{"asset_id": "106600613356134795904313062212730477275252691648870475628884876817519043940991", "price": "0.33", "size": "113.64", "side": "BUY", "hash": "35a15d43eb819cfdbd60b2b16dcdcfe2e897eb90", "best_bid": "0.33", "best_ask": "0.36"}, {"asset_id": "63124470287776887476483587791259448657774659174144661407693923638503676979579", "price": "0.67", "size": "113.64", "side": "SELL", "hash": "bdcc78ad264998394e9839a0a601d360699f6aea", "best_bid": "0.64", "best_ask": "0.67"}], "timestamp": "1769384453651", "event_type": "price_change"}}
{"_local_timestamp": "2026-01-25T23:40:58.387828+00:00", "data": {"market": "0xe2dfc02908b8fb5e7c6578a42e17b52434f5346bb532ab5715dbbfd46af57a21", "price_changes": [{"asset_id": "3269263393231035282910557398978207346672294813068410578094427630928688366591", "price": "0.208", "size": "2640", "side": "BUY", "hash": "aa8501b443099c2e271d9fb64e1976f0d337330d", "best_bid": "0.991", "best_ask": "0.999"}, {"asset_id": "79024099644769201382883588167557335172113039460336000034907727657308480799729", "price": "0.792", "size": "2640", "side": "SELL", "hash": "fca6ed3ea7dc844a23727cc18b3d156c2d897d18", "best_bid": "0.001", "best_ask": "0.009"}], "timestamp": "1769384457859", "event_type": "price_change"}}
{"_local_timestamp": "2026-01-25T23:40:58.931102+00:00", "data": {"market": "0xe2dfc02908b8fb5e7c6578a42e17b52434f5346bb532ab5715dbbfd46af57a21", "price_changes": [{"asset_id": "3269263393231035282910557398978207346672294813068410578094427630928688366591", "price": "0.991", "size": "644", "side": "BUY", "hash": "6fca828c8b001454da5f95a324b69440fc577e60", "best_bid": "0.991", "best_ask": "0.999"}, {"asset_id": "79024099644769201382883588167557335172113039460336000034907727657308480799729", "price": "0.009", "size": "644", "side": "SELL", "hash": "8fcf8737e1ccf786adf1b1a5cd1eb07ae04cc354", "best_bid": "0.001", "best_ask": "0.009"}], "timestamp": "1769384458860", "event_type": "price_change"}}
{"_local_timestamp": "2026-01-25T23:40:59.672917+00:00", "data": {"market": "0xe2dfc02908b8fb5e7c6578a42e17b52434f5346bb532ab5715dbbfd46af57a21", "price_changes": [{"asset_id": "3269263393231035282910557398978207346672294813068410578094427630928688366591", "price": "0.205", "size": "0", "side": "BUY", "hash": "e3bf2cb720ec2bc531d501dca0eb107f9fa52df9", "best_bid": "0.991", "best_ask": "0.999"}, {"asset_id": "79024099644769201382883588167557335172113039460336000034907727657308480799729", "price": "0.795", "size": "0", "side": "SELL", "hash": "da3ebd04b48563278629c7bb4d4b491e882d814e", "best_bid": "0.001", "best_ask": "0.009"}], "timestamp": "1769384459608", "event_type": "price_change"}}
{"_local_timestamp": "2026-01-25T23:41:00.644625+00:00", "data": {"market": "0xe2dfc02908b8fb5e7c6578a42e17b52434f5346bb532ab5715dbbfd46af57a21", "price_changes": [{"asset_id": "3269263393231035282910557398978207346672294813068410578094427630928688366591", "price": "0.841", "size": "0", "side": "BUY", "hash": "bcf8138d08d239a495df996ade8fc30f2c41b292", "best_bid": "0.991", "best_ask": "0.999"}, {"asset_id": "79024099644769201382883588167557335172113039460336000034907727657308480799729", "price": "0.159", "size": "0", "side": "SELL", "hash": "f9edddfb7e0b21e7acabf5415f12c25f50d32dde", "best_bid": "0.001", "best_ask": "0.009"}], "timestamp": "1769384460578", "event_type": "price_change"}}
{"_local_timestamp": "2026-01-25T23:41:05.721290+00:00", "data": {"market": "0x0b436d14d29b7f778768ffb123a526b4dc496054e26d820d691e9b59f2ae15bf", "price_changes": [{"asset_id": "18488621325714747371592358988913690051744048045248507898917802091914468336625", "price": "0.3", "size": "0", "side": "BUY", "hash": "233d2cb1ea146379928cdbfb2c6aff54e69244d0", "best_bid": "0.32", "best_ask": "0.65"}, {"asset_id": "78125564118195609688130723464750437875510814435361379152154876368715602249491", "price": "0.7", "size": "0", "side": "SELL", "hash": "0f5affc05aa0f5139f66db78c28318a25b692132", "best_bid": "0.35", "best_ask": "0.68"}], "timestamp": "1769384465645", "event_type": "price_change"}}
{"_local_timestamp": "2026-01-25T23:41:05.745680+00:00", "data": {"market": "0x0b436d14d29b7f778768ffb123a526b4dc496054e26d820d691e9b59f2ae15bf", "price_changes": [{"asset_id": "18488621325714747371592358988913690051744048045248507898917802091914468336625", "price": "0.32", "size": "258", "side": "BUY", "hash": "88f72d9989a4f4561eb1328f17436bef1a06ae85", "best_bid": "0.32", "best_ask": "0.65"}, {"asset_id": "78125564118195609688130723464750437875510814435361379152154876368715602249491", "price": "0.68", "size": "258", "side": "SELL", "hash": "1154b36621fbee1b9ec8ed6349ee67e86b19c1bc", "best_bid": "0.35", "best_ask": "0.68"}], "timestamp": "1769384465671", "event_type": "price_change"}}
{"_local_timestamp": "2026-01-25T23:41:17.970018+00:00", "data": {"market": "0xe2dfc02908b8fb5e7c6578a42e17b52434f5346bb532ab5715dbbfd46af57a21", "price_changes": [{"asset_id": "79024099644769201382883588167557335172113039460336000034907727657308480799729", "price": "0.794", "size": "0", "side": "SELL", "hash": "7677caf9f6dca61cda382fbf042b45dd37d1f860", "best_bid": "0.001", "best_ask": "0.009"}, {"asset_id": "3269263393231035282910557398978207346672294813068410578094427630928688366591", "price": "0.206", "size": "0", "side": "BUY", "hash": "956c41e4b609466355d0807298918ed0e751e2d6", "best_bid": "0.991", "best_ask": "0.999"}], "timestamp": "1769384477843", "event_type": "price_change"}}
{"_local_timestamp": "2026-01-25T23:41:18.748852+00:00", "data": {"market": "0xe2dfc02908b8fb5e7c6578a42e17b52434f5346bb532ab5715dbbfd46af57a21", "price_changes": [{"asset_id": "79024099644769201382883588167557335172113039460336000034907727657308480799729", "price": "0.791", "size": "1800", "side": "SELL", "hash": "efd5f3ebd9b82051d1b818b92df2f3b5b1c18c78", "best_bid": "0.001", "best_ask": "0.009"}, {"asset_id": "3269263393231035282910557398978207346672294813068410578094427630928688366591", "price": "0.209", "size": "1800", "side": "BUY", "hash": "088d10c627548ea746ff5dca704edc13c02c6592", "best_bid": "0.991", "best_ask": "0.999"}], "timestamp": "1769384478681", "event_type": "price_change"}}
{"_local_timestamp": "2026-01-25T23:41:24.589545+00:00", "data": {"market": "0x0b436d14d29b7f778768ffb123a526b4dc496054e26d820d691e9b59f2ae15bf", "price_changes": [{"asset_id": "18488621325714747371592358988913690051744048045248507898917802091914468336625", "price": "0.32", "size": "218", "side": "BUY", "hash": "4d3d42cba42d029c679a26c3f364b1b233499da3", "best_bid": "0.32", "best_ask": "0.65"}, {"asset_id": "78125564118195609688130723464750437875510814435361379152154876368715602249491", "price": "0.68", "size": "218", "side": "SELL", "hash": "612876150d0e07f1bbf9652e3d94553ca27c1b96", "best_bid": "0.35", "best_ask": "0.68"}], "timestamp": "1769384484526", "event_type": "price_change"}}
{"_local_timestamp": "2026-01-25T23:41:25.879513+00:00", "data": {"market": "0x0b436d14d29b7f778768ffb123a526b4dc496054e26d820d691e9b59f2ae15bf", "price_changes": [{"asset_id": "18488621325714747371592358988913690051744048045248507898917802091914468336625", "price": "0.3", "size": "40", "side": "BUY", "hash": "6001ce90bfe661deef73222a68f07c16597eb3aa", "best_bid": "0.32", "best_ask": "0.65"}, {"asset_id": "78125564118195609688130723464750437875510814435361379152154876368715602249491", "price": "0.7", "size": "40", "side": "SELL", "hash": "3f93c3f6ea92d618359dfb17ec5ce0b52072dfc2", "best_bid": "0.35", "best_ask": "0.68"}], "timestamp": "1769384485805", "event_type": "price_change"}}
{"_local_timestamp": "2026-01-25T23:41:30.663877+00:00", "data": {"market": "0x0b436d14d29b7f778768ffb123a526b4dc496054e26d820d691e9b59f2ae15bf", "price_changes": [{"asset_id": "18488621325714747371592358988913690051744048045248507898917802091914468336625", "price": "0.29", "size": "162.91", "side": "BUY", "hash": "9ec3e4e05bf8aae0392b0ee96e38c07b48c311ce", "best_bid": "0.32", "best_ask": "0.65"}, {"asset_id": "78125564118195609688130723464750437875510814435361379152154876368715602249491", "price": "0.71", "size": "162.91", "side": "SELL", "hash": "8995e3bae1ad8cb5159ca7b41dde6c8190721a88", "best_bid": "0.35", "best_ask": "0.68"}], "timestamp": "1769384490586", "event_type": "price_change"}}
{"_local_timestamp": "2026-01-25T23:41:30.664733+00:00", "data": {"market": "0x0b436d14d29b7f778768ffb123a526b4dc496054e26d820d691e9b59f2ae15bf", "price_changes": [{"asset_id": "18488621325714747371592358988913690051744048045248507898917802091914468336625", "price": "0.3", "size": "198", "side": "BUY", "hash": "7a105c7dcdf869370ca80745c60a76df022d4f14", "best_bid": "0.32", "best_ask": "0.65"}, {"asset_id": "78125564118195609688130723464750437875510814435361379152154876368715602249491", "price": "0.7", "size": "198", "side": "SELL", "hash": "0a6a5b31805eb911672785f3a1986bbbf35acd06", "best_bid": "0.35", "best_ask": "0.68"}], "timestamp": "1769384490587", "event_type": "price_change"}}
{"_local_timestamp": "2026-01-25T23:41:33.833163+00:00", "data": {"market": "0xe2dfc02908b8fb5e7c6578a42e17b52434f5346bb532ab5715dbbfd46af57a21", "price_changes": [{"asset_id": "3269263393231035282910557398978207346672294813068410578094427630928688366591", "price": "0.574", "size": "0", "side": "BUY", "hash": "b3fa3448692ea7c1905c37e071090382737dc24f", "best_bid": "0.991", "best_ask": "0.999"}, {"asset_id": "79024099644769201382883588167557335172113039460336000034907727657308480799729", "price": "0.426", "size": "0", "side": "SELL", "hash": "5312a4acc45ea088acce1847fa1a9c7736c96181", "best_bid": "0.001", "best_ask": "0.009"}], "timestamp": "1769384493700", "event_type": "price_change"}}
{"_local_timestamp": "2026-01-25T23:41:34.155178+00:00", "data": {"market": "0xe2dfc02908b8fb5e7c6578a42e17b52434f5346bb532ab5715dbbfd46af57a21", "price_changes": [{"asset_id": "3269263393231035282910557398978207346672294813068410578094427630928688366591", "price": "0.574", "size": "5", "side": "BUY", "hash": "85616893d07d8185c878c3efa624f986fab518ec", "best_bid": "0.991", "best_ask": "0.999"}, {"asset_id": "79024099644769201382883588167557335172113039460336000034907727657308480799729", "price": "0.426", "size": "5", "side": "SELL", "hash": "78667b26195b1bdb0e8c906492090f0ea0a6c384", "best_bid": "0.001", "best_ask": "0.009"}], "timestamp": "1769384494088", "event_type": "price_change"}}
{"_local_timestamp": "2026-01-25T23:41:43.623053+00:00", "data": {"market": "0x092c91d348e732e6e1d10cb85e855ae2982167cc8a514de6d5ce0ed6a81b3406", "price_changes": [{"asset_id": "106600613356134795904313062212730477275252691648870475628884876817519043940991", "price": "0.33", "size": "70", "side": "BUY", "hash": "dfad21f66cd74e18ba296bfa514766a72d73dc16", "best_bid": "0.33", "best_ask": "0.36"}, {"asset_id": "63124470287776887476483587791259448657774659174144661407693923638503676979579", "price": "0.67", "size": "70", "side": "SELL", "hash": "86f1a0ae6feecd5d6765963bed1eca3db091b90f", "best_bid": "0.64", "best_ask": "0.67"}], "timestamp": "1769384503551", "event_type": "price_change"}}
{"_local_timestamp": "2026-01-25T23:41:46.778493+00:00", "data": {"market": "0x0b436d14d29b7f778768ffb123a526b4dc496054e26d820d691e9b59f2ae15bf", "price_changes": [{"asset_id": "18488621325714747371592358988913690051744048045248507898917802091914468336625", "price": "0.29", "size": "83.91", "side": "BUY", "hash": "65a7ea6581b8a3a1fd6eb9d5ede93d598af1ec8c", "best_bid": "0.32", "best_ask": "0.65"}, {"asset_id": "78125564118195609688130723464750437875510814435361379152154876368715602249491", "price": "0.71", "size": "83.91", "side": "SELL", "hash": "5c787ad88e392f020393d10b6c95618835869c6f", "best_bid": "0.35", "best_ask": "0.68"}], "timestamp": "1769384506710", "event_type": "price_change"}}
{"_local_timestamp": "2026-01-25T23:41:54.259017+00:00", "data": {"market": "0x092c91d348e732e6e1d10cb85e855ae2982167cc8a514de6d5ce0ed6a81b3406", "price_changes": [{"asset_id": "63124470287776887476483587791259448657774659174144661407693923638503676979579", "price": "0.68", "size": "100", "side": "SELL", "hash": "ff0fc7179e95956d0c955047202c33fe33ceb18a", "best_bid": "0.64", "best_ask": "0.67"}, {"asset_id": "106600613356134795904313062212730477275252691648870475628884876817519043940991", "price": "0.32", "size": "100", "side": "BUY", "hash": "df8defb9755af0efa71baeb511c833b2d2cd3cec", "best_bid": "0.33", "best_ask": "0.36"}], "timestamp": "1769384514190", "event_type": "price_change"}}
{"_local_timestamp": "2026-01-25T23:41:54.274449+00:00", "data": {"market": "0x0b436d14d29b7f778768ffb123a526b4dc496054e26d820d691e9b59f2ae15bf", "price_changes": [{"asset_id": "18488621325714747371592358988913690051744048045248507898917802091914468336625", "price": "0.28", "size": "170", "side": "BUY", "hash": "e4d8ec8cbe9dc037304f547cffaa65260dd2c22c", "best_bid": "0.32", "best_ask": "0.65"}, {"asset_id": "78125564118195609688130723464750437875510814435361379152154876368715602249491", "price": "0.72", "size": "170", "side": "SELL", "hash": "32017b298254295948aae028c19119ff5694ccd3", "best_bid": "0.35", "best_ask": "0.68"}], "timestamp": "1769384514212", "event_type": "price_change"}}
{"_local_timestamp": "2026-01-25T23:41:54.282560+00:00", "data": {"market": "0x0b436d14d29b7f778768ffb123a526b4dc496054e26d820d691e9b59f2ae15bf", "price_changes": [{"asset_id": "18488621325714747371592358988913690051744048045248507898917802091914468336625", "price": "0.32", "size": "178", "side": "BUY", "hash": "0e2345068dbbf76cc6b6b4662c293c39e9de92f0", "best_bid": "0.32", "best_ask": "0.65"}, {"asset_id": "78125564118195609688130723464750437875510814435361379152154876368715602249491", "price": "0.68", "size": "178", "side": "SELL", "hash": "70d4d893321949c938d033eadc257465e234d2d0", "best_bid": "0.35", "best_ask": "0.68"}], "timestamp": "1769384514217", "event_type": "price_change"}}
{"_local_timestamp": "2026-01-25T23:41:54.444365+00:00", "data": {"market": "0x092c91d348e732e6e1d10cb85e855ae2982167cc8a514de6d5ce0ed6a81b3406", "price_changes": [{"asset_id": "63124470287776887476483587791259448657774659174144661407693923638503676979579", "price": "0.68", "size": "145", "side": "SELL", "hash": "17dcdc44aab008d7e315e19f158a3ebb75608cb4", "best_bid": "0.64", "best_ask": "0.67"}, {"asset_id": "106600613356134795904313062212730477275252691648870475628884876817519043940991", "price": "0.32", "size": "145", "side": "BUY", "hash": "2249dbe62f6799f3aca7a0835168308c567841c6", "best_bid": "0.33", "best_ask": "0.36"}], "timestamp": "1769384514374", "event_type": "price_change"}}
{"_local_timestamp": "2026-01-25T23:41:55.682347+00:00", "data": {"market": "0x0b436d14d29b7f778768ffb123a526b4dc496054e26d820d691e9b59f2ae15bf", "price_changes": [{"asset_id": "18488621325714747371592358988913690051744048045248507898917802091914468336625", "price": "0.3", "size": "158", "side": "BUY", "hash": "77e889e1f7ec8aba48f94108325b5716df854848", "best_bid": "0.32", "best_ask": "0.65"}, {"asset_id": "78125564118195609688130723464750437875510814435361379152154876368715602249491", "price": "0.7", "size": "158", "side": "SELL", "hash": "aec2257466a747a28ce1d600d663b2086abc603c", "best_bid": "0.35", "best_ask": "0.68"}], "timestamp": "1769384515613", "event_type": "price_change"}}
{"_local_timestamp": "2026-01-25T23:41:55.720828+00:00", "data": {"market": "0x0b436d14d29b7f778768ffb123a526b4dc496054e26d820d691e9b59f2ae15bf", "price_changes": [{"asset_id": "18488621325714747371592358988913690051744048045248507898917802091914468336625", "price": "0.31", "size": "40", "side": "BUY", "hash": "23aba79a04ab66066e77fa66e12543a1f927fb08", "best_bid": "0.32", "best_ask": "0.65"}, {"asset_id": "78125564118195609688130723464750437875510814435361379152154876368715602249491", "price": "0.69", "size": "40", "side": "SELL", "hash": "477006d6313c736b59b3b0e8c5dadf76745f4906", "best_bid": "0.35", "best_ask": "0.68"}], "timestamp": "1769384515638", "event_type": "price_change"}}
{"_local_timestamp": "2026-01-25T23:41:55.721427+00:00", "data": {"market": "0x0b436d14d29b7f778768ffb123a526b4dc496054e26d820d691e9b59f2ae15bf", "price_changes": [{"asset_id": "18488621325714747371592358988913690051744048045248507898917802091914468336625", "price": "0.28", "size": "230", "side": "BUY", "hash": "442354bf57565f7a7dfb71d718063b43f4e959e0", "best_bid": "0.32", "best_ask": "0.65"}, {"asset_id": "78125564118195609688130723464750437875510814435361379152154876368715602249491", "price": "0.72", "size": "230", "side": "SELL", "hash": "ace780192f56a86dcfceacba4d62ebf4264ce05c", "best_bid": "0.35", "best_ask": "0.68"}], "timestamp": "1769384515639", "event_type": "price_change"}}
{"_local_timestamp": "2026-01-25T23:41:55.721927+00:00", "data": {"market": "0x0b436d14d29b7f778768ffb123a526b4dc496054e26d820d691e9b59f2ae15bf", "price_changes": [{"asset_id": "18488621325714747371592358988913690051744048045248507898917802091914468336625", "price": "0.32", "size": "218", "side": "BUY", "hash": "c987e5fc8d6dd1e169f83a7a20c2ed85dd6ce5d4", "best_bid": "0.32", "best_ask": "0.65"}, {"asset_id": "78125564118195609688130723464750437875510814435361379152154876368715602249491", "price": "0.68", "size": "218", "side": "SELL", "hash": "1733e965480dec159b34821453a33ac176f2ee91", "best_bid": "0.35", "best_ask": "0.68"}], "timestamp": "1769384515639", "event_type": "price_change"}}
{"_local_timestamp": "2026-01-25T23:41:56.157853+00:00", "data": {"market": "0x0b436d14d29b7f778768ffb123a526b4dc496054e26d820d691e9b59f2ae15bf", "price_changes": [{"asset_id": "18488621325714747371592358988913690051744048045248507898917802091914468336625", "price": "0.33", "size": "30", "side": "BUY", "hash": "cf774f8d4a7447e7c8ada247e45472fddaa93ac8", "best_bid": "0.33", "best_ask": "0.65"}, {"asset_id": "78125564118195609688130723464750437875510814435361379152154876368715602249491", "price": "0.67", "size": "30", "side": "SELL", "hash": "b79ca839051e9cfd547522034d744f4dce71b874", "best_bid": "0.35", "best_ask": "0.67"}], "timestamp": "1769384516091", "event_type": "price_change"}}
{"_local_timestamp": "2026-01-25T23:41:59.676823+00:00", "data": {"market": "0x092c91d348e732e6e1d10cb85e855ae2982167cc8a514de6d5ce0ed6a81b3406", "price_changes": [{"asset_id": "106600613356134795904313062212730477275252691648870475628884876817519043940991", "price": "0.33", "size": "80.91", "side": "BUY", "hash": "e58ba7e556339940d52344ba3205079a290aecc1", "best_bid": "0.33", "best_ask": "0.36"}, {"asset_id": "63124470287776887476483587791259448657774659174144661407693923638503676979579", "price": "0.67", "size": "80.91", "side": "SELL", "hash": "1665de9f2b699339034d6c7d90aedabdbc8c2e94", "best_bid": "0.64", "best_ask": "0.67"}], "timestamp": "1769384519609", "event_type": "price_change"}}
{"_local_timestamp": "2026-01-25T23:41:59.677777+00:00", "data": {"market": "0x092c91d348e732e6e1d10cb85e855ae2982167cc8a514de6d5ce0ed6a81b3406", "price_changes": [{"asset_id": "106600613356134795904313062212730477275252691648870475628884876817519043940991", "price": "0.33", "size": "91.82", "side": "BUY", "hash": "3bd7e27e19605ca41df571661b1b3c1da8d6941c", "best_bid": "0.33", "best_ask": "0.36"}, {"asset_id": "63124470287776887476483587791259448657774659174144661407693923638503676979579", "price": "0.67", "size": "91.82", "side": "SELL", "hash": "374ef6dea94e358607c7888eff5df01cbe9054d5", "best_bid": "0.64", "best_ask": "0.67"}], "timestamp": "1769384519609", "event_type": "price_change"}}
{"_local_timestamp": "2026-01-25T23:41:59.684960+00:00", "data": {"market": "0x092c91d348e732e6e1d10cb85e855ae2982167cc8a514de6d5ce0ed6a81b3406", "price_changes": [{"asset_id": "106600613356134795904313062212730477275252691648870475628884876817519043940991", "price": "0.33", "size": "102.73", "side": "BUY", "hash": "91c4d478af207d8cf429c8b3283f44caf09fa424", "best_bid": "0.33", "best_ask": "0.36"}, {"asset_id": "63124470287776887476483587791259448657774659174144661407693923638503676979579", "price": "0.67", "size": "102.73", "side": "SELL", "hash": "ab85bf665a2d40cbeb92fb037d0bc6d1fb422c56", "best_bid": "0.64", "best_ask": "0.67"}], "timestamp": "1769384519610", "event_type": "price_change"}}
{"_local_timestamp": "2026-01-25T23:41:59.685743+00:00", "data": {"market": "0x092c91d348e732e6e1d10cb85e855ae2982167cc8a514de6d5ce0ed6a81b3406", "price_changes": [{"asset_id": "106600613356134795904313062212730477275252691648870475628884876817519043940991", "price": "0.33", "size": "113.64", "side": "BUY", "hash": "b27e8ae5f59b395041f13f813f31c548645af6ec", "best_bid": "0.33", "best_ask": "0.36"}, {"asset_id": "63124470287776887476483587791259448657774659174144661407693923638503676979579", "price": "0.67", "size": "113.64", "side": "SELL", "hash": "28a02fc4de867a95e80e9594db3c91c64c8bda5e", "best_bid": "0.64", "best_ask": "0.67"}], "timestamp": "1769384519611", "event_type": "price_change"}}
{"_local_timestamp": "2026-01-25T23:42:01.804535+00:00", "data": {"market": "0x0b436d14d29b7f778768ffb123a526b4dc496054e26d820d691e9b59f2ae15bf", "price_changes": [{"asset_id": "18488621325714747371592358988913690051744048045248507898917802091914468336625", "price": "0.3", "size": "0", "side": "BUY", "hash": "018937bb0bf2420dced9e5d1e55fe185e983a015", "best_bid": "0.33", "best_ask": "0.65"}, {"asset_id": "78125564118195609688130723464750437875510814435361379152154876368715602249491", "price": "0.7", "size": "0", "side": "SELL", "hash": "7a029cd80a6ee33617ceff81d92de19d7d38c393", "best_bid": "0.35", "best_ask": "0.67"}], "timestamp": "1769384521741", "event_type": "price_change"}}
{"_local_timestamp": "2026-01-25T23:42:24.483750+00:00", "data": {"market": "0xe2dfc02908b8fb5e7c6578a42e17b52434f5346bb532ab5715dbbfd46af57a21", "price_changes": [{"asset_id": "3269263393231035282910557398978207346672294813068410578094427630928688366591", "price": "0.574", "size": "0", "side": "BUY", "hash": "bb6f17ae3ecfe9a01d0e841a69f944119b8915ea", "best_bid": "0.991", "best_ask": "0.999"}, {"asset_id": "79024099644769201382883588167557335172113039460336000034907727657308480799729", "price": "0.426", "size": "0", "side": "SELL", "hash": "006ec3e6671552d2b0a35bd67966701ee3d8254e", "best_bid": "0.001", "best_ask": "0.009"}], "timestamp": "1769384544272", "event_type": "price_change"}}
{"_local_timestamp": "2026-01-25T23:42:24.506474+00:00", "data": {"market": "0x0b436d14d29b7f778768ffb123a526b4dc496054e26d820d691e9b59f2ae15bf", "price_changes": [{"asset_id": "18488621325714747371592358988913690051744048045248507898917802091914468336625", "price": "0.32", "size": "331", "side": "BUY", "hash": "78b35137462802271223a285fb34bdb46c9d516e", "best_bid": "0.33", "best_ask": "0.65"}, {"asset_id": "78125564118195609688130723464750437875510814435361379152154876368715602249491", "price": "0.68", "size": "331", "side": "SELL", "hash": "7b7f1a9c4e0d8235d730ceab0f491e78f3d56680", "best_bid": "0.35", "best_ask": "0.67"}], "timestamp": "1769384544299", "event_type": "price_change"}}
{"_local_timestamp": "2026-01-25T23:42:24.942543+00:00", "data": {"market": "0xe2dfc02908b8fb5e7c6578a42e17b52434f5346bb532ab5715dbbfd46af57a21", "price_changes": [{"asset_id": "3269263393231035282910557398978207346672294813068410578094427630928688366591", "price": "0.574", "size": "5", "side": "BUY", "hash": "9e3015bbd9938f19db848a8cfdb842807ce4d9ca", "best_bid": "0.991", "best_ask": "0.999"}, {"asset_id": "79024099644769201382883588167557335172113039460336000034907727657308480799729", "price": "0.426", "size": "5", "side": "SELL", "hash": "7bf5108c83d22cfde6a56ec646c2190cc15f0e7d", "best_bid": "0.001", "best_ask": "0.009"}], "timestamp": "1769384544639", "event_type": "price_change"}}
{"_local_timestamp": "2026-01-25T23:42:45.214207+00:00", "data": {"market": "0x092c91d348e732e6e1d10cb85e855ae2982167cc8a514de6d5ce0ed6a81b3406", "price_changes": [{"asset_id": "106600613356134795904313062212730477275252691648870475628884876817519043940991", "price": "0.33", "size": "70", "side": "BUY", "hash": "722fb077f0cb539f156c8836163f5b5002705af8", "best_bid": "0.33", "best_ask": "0.36"}, {"asset_id": "63124470287776887476483587791259448657774659174144661407693923638503676979579", "price": "0.67", "size": "70", "side": "SELL", "hash": "7cf4aed9039c94bde06b4ca8e097bcb78f046250", "best_bid": "0.64", "best_ask": "0.67"}], "timestamp": "1769384565059", "event_type": "price_change"}}
{"_local_timestamp": "2026-01-25T23:42:45.242036+00:00", "data": {"market": "0x0b436d14d29b7f778768ffb123a526b4dc496054e26d820d691e9b59f2ae15bf", "price_changes": [{"asset_id": "18488621325714747371592358988913690051744048045248507898917802091914468336625", "price": "0.32", "size": "218", "side": "BUY", "hash": "5780702d7767e73c2faf98bad3cf2fcc5a7e0b86", "best_bid": "0.33", "best_ask": "0.65"}, {"asset_id": "78125564118195609688130723464750437875510814435361379152154876368715602249491", "price": "0.68", "size": "218", "side": "SELL", "hash": "16b0445c98e6abea3f40e7086cae61b694b7be15", "best_bid": "0.35", "best_ask": "0.67"}], "timestamp": "1769384565083", "event_type": "price_change"}}
{"_local_timestamp": "2026-01-25T23:42:45.393908+00:00", "data": {"market": "0x0b436d14d29b7f778768ffb123a526b4dc496054e26d820d691e9b59f2ae15bf", "price_changes": [{"asset_id": "18488621325714747371592358988913690051744048045248507898917802091914468336625", "price": "0.32", "size": "288", "side": "BUY", "hash": "fa45e056cefacbc23abb491ec4e2717244d7557e", "best_bid": "0.33", "best_ask": "0.65"}, {"asset_id": "78125564118195609688130723464750437875510814435361379152154876368715602249491", "price": "0.68", "size": "288", "side": "SELL", "hash": "ae1291c7bf1fc66af47c45a5a22d505dee2abdd2", "best_bid": "0.35", "best_ask": "0.67"}], "timestamp": "1769384565210", "event_type": "price_change"}}
{"_local_timestamp": "2026-01-25T23:42:48.362035+00:00", "data": {"market": "0x0b436d14d29b7f778768ffb123a526b4dc496054e26d820d691e9b59f2ae15bf", "price_changes": [{"asset_id": "18488621325714747371592358988913690051744048045248507898917802091914468336625", "price": "0.32", "size": "248", "side": "BUY", "hash": "dafc8f699969cb5ac1199feb1c3365ef0abe810f", "best_bid": "0.33", "best_ask": "0.65"}, {"asset_id": "78125564118195609688130723464750437875510814435361379152154876368715602249491", "price": "0.68", "size": "248", "side": "SELL", "hash": "317fe19fea01dbe418f36de9d73bc4eecca24ee8", "best_bid": "0.35", "best_ask": "0.67"}], "timestamp": "1769384568240", "event_type": "price_change"}}
{"_local_timestamp": "2026-01-25T23:42:50.865972+00:00", "data": {"market": "0x0b436d14d29b7f778768ffb123a526b4dc496054e26d820d691e9b59f2ae15bf", "price_changes": [{"asset_id": "18488621325714747371592358988913690051744048045248507898917802091914468336625", "price": "0.31", "size": "80", "side": "BUY", "hash": "811744a5857d560368ac59544e0b4ba9cf55554c", "best_bid": "0.33", "best_ask": "0.65"}, {"asset_id": "78125564118195609688130723464750437875510814435361379152154876368715602249491", "price": "0.69", "size": "80", "side": "SELL", "hash": "dd7f5c07199203f48d5f2afbb3f9a9ba407d649b", "best_bid": "0.35", "best_ask": "0.67"}], "timestamp": "1769384570738", "event_type": "price_change"}}
{"_local_timestamp": "2026-01-25T23:42:58.238556+00:00", "data": {"market": "0x092c91d348e732e6e1d10cb85e855ae2982167cc8a514de6d5ce0ed6a81b3406", "price_changes": [{"asset_id": "106600613356134795904313062212730477275252691648870475628884876817519043940991", "price": "0.33", "size": "80.91", "side": "BUY", "hash": "1b4291e8c4977429f1ff7f6423557645ec2254d8", "best_bid": "0.33", "best_ask": "0.36"}, {"asset_id": "63124470287776887476483587791259448657774659174144661407693923638503676979579", "price": "0.67", "size": "80.91", "side": "SELL", "hash": "7c8acfcdb25a09a015cf54c2cb4d7c94934cbef3", "best_bid": "0.64", "best_ask": "0.67"}], "timestamp": "1769384578116", "event_type": "price_change"}}
{"_local_timestamp": "2026-01-25T23:42:58.278960+00:00", "data": {"market": "0x092c91d348e732e6e1d10cb85e855ae2982167cc8a514de6d5ce0ed6a81b3406", "price_changes": [{"asset_id": "106600613356134795904313062212730477275252691648870475628884876817519043940991", "price": "0.33", "size": "91.82", "side": "BUY", "hash": "c9bd1ca61bbaf7dbe7c3bf6902cf705f12b76248", "best_bid": "0.33", "best_ask": "0.36"}, {"asset_id": "63124470287776887476483587791259448657774659174144661407693923638503676979579", "price": "0.67", "size": "91.82", "side": "SELL", "hash": "1f4c1fc0cb035e344e6b8cf51cc427ab12b17e66", "best_bid": "0.64", "best_ask": "0.67"}], "timestamp": "1769384578116", "event_type": "price_change"}}
{"_local_timestamp": "2026-01-25T23:42:58.279554+00:00", "data": {"market": "0x092c91d348e732e6e1d10cb85e855ae2982167cc8a514de6d5ce0ed6a81b3406", "price_changes": [{"asset_id": "106600613356134795904313062212730477275252691648870475628884876817519043940991", "price": "0.33", "size": "102.73", "side": "BUY", "hash": "d15768c49bcbdc94e676174843c69040300ba0ee", "best_bid": "0.33", "best_ask": "0.36"}, {"asset_id": "63124470287776887476483587791259448657774659174144661407693923638503676979579", "price": "0.67", "size": "102.73", "side": "SELL", "hash": "7b35085965304f8c56f6ffb289b9c9bc4a852622", "best_bid": "0.64", "best_ask": "0.67"}], "timestamp": "1769384578117", "event_type": "price_change"}}
{"_local_timestamp": "2026-01-25T23:42:58.286885+00:00", "data": {"market": "0x092c91d348e732e6e1d10cb85e855ae2982167cc8a514de6d5ce0ed6a81b3406", "price_changes": [{"asset_id": "106600613356134795904313062212730477275252691648870475628884876817519043940991", "price": "0.33", "size": "113.64", "side": "BUY", "hash": "1d964c97293734b87fc3e3271e9b8e3275421f59", "best_bid": "0.33", "best_ask": "0.36"}, {"asset_id": "63124470287776887476483587791259448657774659174144661407693923638503676979579", "price": "0.67", "size": "113.64", "side": "SELL", "hash": "ac0625b36838b02f738b3f9ad448e1cca35c51be", "best_bid": "0.64", "best_ask": "0.67"}], "timestamp": "1769384578117", "event_type": "price_change"}}
{"_local_timestamp": "2026-01-25T23:42:58.287417+00:00", "data": {"market": "0x0b436d14d29b7f778768ffb123a526b4dc496054e26d820d691e9b59f2ae15bf", "price_changes": [{"asset_id": "18488621325714747371592358988913690051744048045248507898917802091914468336625", "price": "0.32", "size": "178", "side": "BUY", "hash": "1407e36d121b9c8e7f42b6f2f602d20b6ec9ddfc", "best_bid": "0.33", "best_ask": "0.65"}, {"asset_id": "78125564118195609688130723464750437875510814435361379152154876368715602249491", "price": "0.68", "size": "178", "side": "SELL", "hash": "f0085499f830f43b4104267c9accf1b1ab180516", "best_bid": "0.35", "best_ask": "0.67"}], "timestamp": "1769384578140", "event_type": "price_change"}}
{"_local_timestamp": "2026-01-25T23:42:58.387723+00:00", "data": {"market": "0x0b436d14d29b7f778768ffb123a526b4dc496054e26d820d691e9b59f2ae15bf", "price_changes": [{"asset_id": "18488621325714747371592358988913690051744048045248507898917802091914468336625", "price": "0.32", "size": "291", "side": "BUY", "hash": "d53b805f322ff9a65c25a912dc2fc4b5465797b7", "best_bid": "0.33", "best_ask": "0.65"}, {"asset_id": "78125564118195609688130723464750437875510814435361379152154876368715602249491", "price": "0.68", "size": "291", "side": "SELL", "hash": "a14895278751a35dc2953e6c8d3073c92bc054c0", "best_bid": "0.35", "best_ask": "0.67"}], "timestamp": "1769384578268", "event_type": "price_change"}}
{"_local_timestamp": "2026-01-25T23:43:08.267169+00:00", "data": {"market": "0xe2dfc02908b8fb5e7c6578a42e17b52434f5346bb532ab5715dbbfd46af57a21", "price_changes": [{"asset_id": "3269263393231035282910557398978207346672294813068410578094427630928688366591", "price": "0.574", "size": "0", "side": "BUY", "hash": "f1ee462d7bc8072bff0f9d90186fff1cda3b4c15", "best_bid": "0.991", "best_ask": "0.999"}, {"asset_id": "79024099644769201382883588167557335172113039460336000034907727657308480799729", "price": "0.426", "size": "0", "side": "SELL", "hash": "7ed8ebf71a177ee7ae37f7a46d5ab5113824c89d", "best_bid": "0.001", "best_ask": "0.009"}], "timestamp": "1769384588101", "event_type": "price_change"}}
{"_local_timestamp": "2026-01-25T23:43:08.620071+00:00", "data": {"market": "0xe2dfc02908b8fb5e7c6578a42e17b52434f5346bb532ab5715dbbfd46af57a21", "price_changes": [{"asset_id": "3269263393231035282910557398978207346672294813068410578094427630928688366591", "price": "0.574", "size": "5", "side": "BUY", "hash": "160dd4531b9ed55d7819477855e8abb5f9c4337c", "best_bid": "0.991", "best_ask": "0.999"}, {"asset_id": "79024099644769201382883588167557335172113039460336000034907727657308480799729", "price": "0.426", "size": "5", "side": "SELL", "hash": "7f4a84c222e9caf5d33d37873d440105b3c539bd", "best_bid": "0.001", "best_ask": "0.009"}], "timestamp": "1769384588476", "event_type": "price_change"}}
{"_local_timestamp": "2026-01-25T23:43:08.984811+00:00", "data": {"market": "0xe2dfc02908b8fb5e7c6578a42e17b52434f5346bb532ab5715dbbfd46af57a21", "price_changes": [{"asset_id": "3269263393231035282910557398978207346672294813068410578094427630928688366591", "price": "0.574", "size": "0", "side": "BUY", "hash": "d0440b1da72571f1850a1506262e8e77f694061e", "best_bid": "0.991", "best_ask": "0.999"}, {"asset_id": "79024099644769201382883588167557335172113039460336000034907727657308480799729", "price": "0.426", "size": "0", "side": "SELL", "hash": "582f364feb789cf9315e01e0f0c2609d6d9401e7", "best_bid": "0.001", "best_ask": "0.009"}], "timestamp": "1769384588851", "event_type": "price_change"}}
{"_local_timestamp": "2026-01-25T23:43:09.505445+00:00", "data": {"market": "0xe2dfc02908b8fb5e7c6578a42e17b52434f5346bb532ab5715dbbfd46af57a21", "price_changes": [{"asset_id": "3269263393231035282910557398978207346672294813068410578094427630928688366591", "price": "0.574", "size": "5", "side": "BUY", "hash": "591089f3f733c2d086c365b6b7d9424740bc4815", "best_bid": "0.991", "best_ask": "0.999"}, {"asset_id": "79024099644769201382883588167557335172113039460336000034907727657308480799729", "price": "0.426", "size": "5", "side": "SELL", "hash": "a3384ba221d17c614ece0affbea8c44746bbbbc8", "best_bid": "0.001", "best_ask": "0.009"}], "timestamp": "1769384589372", "event_type": "price_change"}}
{"_local_timestamp": "2026-01-25T23:43:09.857396+00:00", "data": {"market": "0xe2dfc02908b8fb5e7c6578a42e17b52434f5346bb532ab5715dbbfd46af57a21", "price_changes": [{"asset_id": "3269263393231035282910557398978207346672294813068410578094427630928688366591", "price": "0.99", "size": "995.59", "side": "BUY", "hash": "e670b265993ea27048c7442c8f2eb023eea8ca16", "best_bid": "0.991", "best_ask": "0.999"}, {"asset_id": "79024099644769201382883588167557335172113039460336000034907727657308480799729", "price": "0.01", "size": "995.59", "side": "SELL", "hash": "4d43babdd47facbcce5fd7a38302f2dc6a659d8f", "best_bid": "0.001", "best_ask": "0.009"}], "timestamp": "1769384589730", "event_type": "price_change"}}
{"_local_timestamp": "2026-01-25T23:43:25.430280+00:00", "data": {"market": "0xe2dfc02908b8fb5e7c6578a42e17b52434f5346bb532ab5715dbbfd46af57a21", "price_changes": [{"asset_id": "3269263393231035282910557398978207346672294813068410578094427630928688366591", "price": "0.21", "size": "2640", "side": "BUY", "hash": "c8badc8a550e05a597194bdc6296a5f0acbaa248", "best_bid": "0.991", "best_ask": "0.999"}, {"asset_id": "79024099644769201382883588167557335172113039460336000034907727657308480799729", "price": "0.79", "size": "2640", "side": "SELL", "hash": "21cb661bf40bdf4965bc5a8899ceee85bb94a58f", "best_bid": "0.001", "best_ask": "0.009"}], "timestamp": "1769384605288", "event_type": "price_change"}}
{"_local_timestamp": "2026-01-25T23:43:25.445319+00:00", "data": {"market": "0x0b436d14d29b7f778768ffb123a526b4dc496054e26d820d691e9b59f2ae15bf", "price_changes": [{"asset_id": "18488621325714747371592358988913690051744048045248507898917802091914468336625", "price": "0.32", "size": "178", "side": "BUY", "hash": "4248b23e88a0c23837ad7f43ee6b3c01cf6692a7", "best_bid": "0.33", "best_ask": "0.65"}, {"asset_id": "78125564118195609688130723464750437875510814435361379152154876368715602249491", "price": "0.68", "size": "178", "side": "SELL", "hash": "7f8d1dca548ea2fd1dc7399b6bae8cf1a7d91cb5", "best_bid": "0.35", "best_ask": "0.67"}], "timestamp": "1769384605313", "event_type": "price_change"}}
{"_local_timestamp": "2026-01-25T23:43:26.333175+00:00", "data": {"market": "0xe2dfc02908b8fb5e7c6578a42e17b52434f5346bb532ab5715dbbfd46af57a21", "price_changes": [{"asset_id": "3269263393231035282910557398978207346672294813068410578094427630928688366591", "price": "0.208", "size": "0", "side": "BUY", "hash": "3a116d8f174d225757188711fa9dea04927e1e4b", "best_bid": "0.991", "best_ask": "0.999"}, {"asset_id": "79024099644769201382883588167557335172113039460336000034907727657308480799729", "price": "0.792", "size": "0", "side": "SELL", "hash": "675f0e1d2298b4a59c68888882c32ac755d848b3", "best_bid": "0.001", "best_ask": "0.009"}], "timestamp": "1769384606199", "event_type": "price_change"}}
{"_local_timestamp": "2026-01-25T23:43:42.234719+00:00", "data": {"market": "0x092c91d348e732e6e1d10cb85e855ae2982167cc8a514de6d5ce0ed6a81b3406", "price_changes": [{"asset_id": "106600613356134795904313062212730477275252691648870475628884876817519043940991", "price": "0.33", "size": "70", "side": "BUY", "hash": "4fd564b012d4502cee1acc47f79524c6be855ff0", "best_bid": "0.33", "best_ask": "0.36"}, {"asset_id": "63124470287776887476483587791259448657774659174144661407693923638503676979579", "price": "0.67", "size": "70", "side": "SELL", "hash": "469301c37941a18fe97131bada125fe3ec6d83a0", "best_bid": "0.64", "best_ask": "0.67"}], "timestamp": "1769384622129", "event_type": "price_change"}}
{"_local_timestamp": "2026-01-25T23:43:42.269443+00:00", "data": {"market": "0x0b436d14d29b7f778768ffb123a526b4dc496054e26d820d691e9b59f2ae15bf", "price_changes": [{"asset_id": "18488621325714747371592358988913690051744048045248507898917802091914468336625", "price": "0.32", "size": "248", "side": "BUY", "hash": "c7c03b26c14a32d819ffe1f078bf1b5321724737", "best_bid": "0.33", "best_ask": "0.65"}, {"asset_id": "78125564118195609688130723464750437875510814435361379152154876368715602249491", "price": "0.68", "size": "248", "side": "SELL", "hash": "2c51f5f258302636ffd45f2b66eb514633c15896", "best_bid": "0.35", "best_ask": "0.67"}], "timestamp": "1769384622159", "event_type": "price_change"}}
{"_local_timestamp": "2026-01-25T23:43:53.360998+00:00", "data": {"market": "0xe2dfc02908b8fb5e7c6578a42e17b52434f5346bb532ab5715dbbfd46af57a21", "price_changes": [{"asset_id": "3269263393231035282910557398978207346672294813068410578094427630928688366591", "price": "0.574", "size": "0", "side": "BUY", "hash": "6db5f554ec5eb66b1f8688da2c8f0fb3c40a4315", "best_bid": "0.991", "best_ask": "0.999"}, {"asset_id": "79024099644769201382883588167557335172113039460336000034907727657308480799729", "price": "0.426", "size": "0", "side": "SELL", "hash": "3cbef408e095ed2d1ff7d1d69432eb3619950691", "best_bid": "0.001", "best_ask": "0.009"}], "timestamp": "1769384633111", "event_type": "price_change"}}
{"_local_timestamp": "2026-01-25T23:43:53.823854+00:00", "data": {"market": "0xe2dfc02908b8fb5e7c6578a42e17b52434f5346bb532ab5715dbbfd46af57a21", "price_changes": [{"asset_id": "3269263393231035282910557398978207346672294813068410578094427630928688366591", "price": "0.574", "size": "5", "side": "BUY", "hash": "a40857d2f3b9116ee3fe20a77512ca25cc98382a", "best_bid": "0.991", "best_ask": "0.999"}, {"asset_id": "79024099644769201382883588167557335172113039460336000034907727657308480799729", "price": "0.426", "size": "5", "side": "SELL", "hash": "cc07f08afbb841ab4b488c41e55d9d6de48b9755", "best_bid": "0.001", "best_ask": "0.009"}], "timestamp": "1769384633600", "event_type": "price_change"}}
{"_local_timestamp": "2026-01-25T23:43:54.942889+00:00", "data": {"market": "0x092c91d348e732e6e1d10cb85e855ae2982167cc8a514de6d5ce0ed6a81b3406", "price_changes": [{"asset_id": "106600613356134795904313062212730477275252691648870475628884876817519043940991", "price": "0.33", "size": "80.91", "side": "BUY", "hash": "8cf5dbd51f376b63081e5c8ed5ba337d26089a39", "best_bid": "0.33", "best_ask": "0.36"}, {"asset_id": "63124470287776887476483587791259448657774659174144661407693923638503676979579", "price": "0.67", "size": "80.91", "side": "SELL", "hash": "c1fd0961fa97e43b7278034c4c03b33a29a232f2", "best_bid": "0.64", "best_ask": "0.67"}], "timestamp": "1769384634719", "event_type": "price_change"}}
{"_local_timestamp": "2026-01-25T23:43:54.943469+00:00", "data": {"market": "0x092c91d348e732e6e1d10cb85e855ae2982167cc8a514de6d5ce0ed6a81b3406", "price_changes": [{"asset_id": "106600613356134795904313062212730477275252691648870475628884876817519043940991", "price": "0.33", "size": "91.82", "side": "BUY", "hash": "cfaa9269f624f7ada22881382978718a5a293455", "best_bid": "0.33", "best_ask": "0.36"}, {"asset_id": "63124470287776887476483587791259448657774659174144661407693923638503676979579", "price": "0.67", "size": "91.82", "side": "SELL", "hash": "ce096c556a1ba1e6d8ddf560bd94708f733c7bf6", "best_bid": "0.64", "best_ask": "0.67"}], "timestamp": "1769384634719", "event_type": "price_change"}}
{"_local_timestamp": "2026-01-25T23:43:54.943987+00:00", "data": {"market": "0x092c91d348e732e6e1d10cb85e855ae2982167cc8a514de6d5ce0ed6a81b3406", "price_changes": [{"asset_id": "106600613356134795904313062212730477275252691648870475628884876817519043940991", "price": "0.33", "size": "102.73", "side": "BUY", "hash": "d9e06bff7ab0d2be6fab4aac6c75198cd45ae847", "best_bid": "0.33", "best_ask": "0.36"}, {"asset_id": "63124470287776887476483587791259448657774659174144661407693923638503676979579", "price": "0.67", "size": "102.73", "side": "SELL", "hash": "a675cd3eff86a09b1d31b9fdecf85ddab868fe8d", "best_bid": "0.64", "best_ask": "0.67"}], "timestamp": "1769384634720", "event_type": "price_change"}}
{"_local_timestamp": "2026-01-25T23:43:54.944477+00:00", "data": {"market": "0x092c91d348e732e6e1d10cb85e855ae2982167cc8a514de6d5ce0ed6a81b3406", "price_changes": [{"asset_id": "106600613356134795904313062212730477275252691648870475628884876817519043940991", "price": "0.33", "size": "113.64", "side": "BUY", "hash": "22bce1f908ea408461e1a4bc773c58faf00d9f05", "best_bid": "0.33", "best_ask": "0.36"}, {"asset_id": "63124470287776887476483587791259448657774659174144661407693923638503676979579", "price": "0.67", "size": "113.64", "side": "SELL", "hash": "78bcc975dd950831e86df22b6be00a8b933106ee", "best_bid": "0.64", "best_ask": "0.67"}], "timestamp": "1769384634720", "event_type": "price_change"}}
{"_local_timestamp": "2026-01-25T23:43:54.964995+00:00", "data": {"market": "0x0b436d14d29b7f778768ffb123a526b4dc496054e26d820d691e9b59f2ae15bf", "price_changes": [{"asset_id": "18488621325714747371592358988913690051744048045248507898917802091914468336625", "price": "0.32", "size": "178", "side": "BUY", "hash": "5ce06c5452205307604ce0da7070c9a345acd84a", "best_bid": "0.33", "best_ask": "0.65"}, {"asset_id": "78125564118195609688130723464750437875510814435361379152154876368715602249491", "price": "0.68", "size": "178", "side": "SELL", "hash": "66b3229edf9376c91c145d715339d77a62bc3dfa", "best_bid": "0.35", "best_ask": "0.67"}], "timestamp": "1769384634742", "event_type": "price_change"}}
{"_local_timestamp": "2026-01-25T23:44:10.962176+00:00", "data": {"market": "0x0b436d14d29b7f778768ffb123a526b4dc496054e26d820d691e9b59f2ae15bf", "price_changes": [{"asset_id": "18488621325714747371592358988913690051744048045248507898917802091914468336625", "price": "0.28", "size": "130", "side": "BUY", "hash": "3da150989eff1fcaa2907c288f1c66547547014f", "best_bid": "0.33", "best_ask": "0.65"}, {"asset_id": "78125564118195609688130723464750437875510814435361379152154876368715602249491", "price": "0.72", "size": "130", "side": "SELL", "hash": "4085e575326ed6c2be941552801683fd81ee6b6c", "best_bid": "0.35", "best_ask": "0.67"}], "timestamp": "1769384650688", "event_type": "price_change"}}
{"_local_timestamp": "2026-01-25T23:44:10.981997+00:00", "data": {"market": "0x0b436d14d29b7f778768ffb123a526b4dc496054e26d820d691e9b59f2ae15bf", "price_changes": [{"asset_id": "18488621325714747371592358988913690051744048045248507898917802091914468336625", "price": "0.31", "size": "180", "side": "BUY", "hash": "27058ce6abbbc69dbe842512bbc3389680b0c0df", "best_bid": "0.33", "best_ask": "0.65"}, {"asset_id": "78125564118195609688130723464750437875510814435361379152154876368715602249491", "price": "0.69", "size": "180", "side": "SELL", "hash": "2f6e8dd2f3fd7087e79ac1c19ec1f600fd79c14d", "best_bid": "0.35", "best_ask": "0.67"}], "timestamp": "1769384650717", "event_type": "price_change"}}
{"_local_timestamp": "2026-01-25T23:44:12.666856+00:00", "data": {"market": "0x0b436d14d29b7f778768ffb123a526b4dc496054e26d820d691e9b59f2ae15bf", "price_changes": [{"asset_id": "18488621325714747371592358988913690051744048045248507898917802091914468336625", "price": "0.31", "size": "80", "side": "BUY", "hash": "0cf83d4ce90b956ec0d8e41d05006e8a02130c9a", "best_bid": "0.33", "best_ask": "0.65"}, {"asset_id": "78125564118195609688130723464750437875510814435361379152154876368715602249491", "price": "0.69", "size": "80", "side": "SELL", "hash": "cfcaffdf8d21f73c6e0e78f528f5cbc25ecd4d13", "best_bid": "0.35", "best_ask": "0.67"}], "timestamp": "1769384652517", "event_type": "price_change"}}
{"_local_timestamp": "2026-01-25T23:44:15.864571+00:00", "data": {"market": "0x0b436d14d29b7f778768ffb123a526b4dc496054e26d820d691e9b59f2ae15bf", "price_changes": [{"asset_id": "18488621325714747371592358988913690051744048045248507898917802091914468336625", "price": "0.31", "size": "40", "side": "BUY", "hash": "846d5a55a068b80c6aec74953a83301c8798072a", "best_bid": "0.33", "best_ask": "0.65"}, {"asset_id": "78125564118195609688130723464750437875510814435361379152154876368715602249491", "price": "0.69", "size": "40", "side": "SELL", "hash": "6d651fe8d5d4485b2c6f10b43c2eec285ad8ea87", "best_bid": "0.35", "best_ask": "0.67"}], "timestamp": "1769384655723", "event_type": "price_change"}}
{"_local_timestamp": "2026-01-25T23:44:15.865144+00:00", "data": {"market": "0x0b436d14d29b7f778768ffb123a526b4dc496054e26d820d691e9b59f2ae15bf", "price_changes": [{"asset_id": "18488621325714747371592358988913690051744048045248507898917802091914468336625", "price": "0.28", "size": "80", "side": "BUY", "hash": "846d5a55a068b80c6aec74953a83301c8798072a", "best_bid": "0.33", "best_ask": "0.65"}, {"asset_id": "78125564118195609688130723464750437875510814435361379152154876368715602249491", "price": "0.72", "size": "80", "side": "SELL", "hash": "6d651fe8d5d4485b2c6f10b43c2eec285ad8ea87", "best_bid": "0.35", "best_ask": "0.67"}], "timestamp": "1769384655723", "event_type": "price_change"}}
{"_local_timestamp": "2026-01-25T23:44:15.897230+00:00", "data": {"market": "0x0b436d14d29b7f778768ffb123a526b4dc496054e26d820d691e9b59f2ae15bf", "price_changes": [{"asset_id": "18488621325714747371592358988913690051744048045248507898917802091914468336625", "price": "0.32", "size": "278", "side": "BUY", "hash": "bf6aa1dec92a1a0c21a928161a4ef63b5d3d247d", "best_bid": "0.33", "best_ask": "0.65"}, {"asset_id": "78125564118195609688130723464750437875510814435361379152154876368715602249491", "price": "0.68", "size": "278", "side": "SELL", "hash": "089457b96cadd1664054c74177f644e930510071", "best_bid": "0.35", "best_ask": "0.67"}], "timestamp": "1769384655750", "event_type": "price_change"}}
{"_local_timestamp": "2026-01-25T23:44:15.897776+00:00", "data": {"market": "0x0b436d14d29b7f778768ffb123a526b4dc496054e26d820d691e9b59f2ae15bf", "price_changes": [{"asset_id": "18488621325714747371592358988913690051744048045248507898917802091914468336625", "price": "0.31", "size": "90", "side": "BUY", "hash": "4903d89842feb30b22f2712cf27099c86390e624", "best_bid": "0.33", "best_ask": "0.65"}, {"asset_id": "78125564118195609688130723464750437875510814435361379152154876368715602249491", "price": "0.69", "size": "90", "side": "SELL", "hash": "bbb26d4a1c322f47ab0359c4d800562461ff03b5", "best_bid": "0.35", "best_ask": "0.67"}], "timestamp": "1769384655751", "event_type": "price_change"}}
{"_local_timestamp": "2026-01-25T23:44:15.898256+00:00", "data": {"market": "0x0b436d14d29b7f778768ffb123a526b4dc496054e26d820d691e9b59f2ae15bf", "price_changes": [{"asset_id": "18488621325714747371592358988913690051744048045248507898917802091914468336625", "price": "0.33", "size": "70", "side": "BUY", "hash": "5aea8a7cf1f2e524525e309c11e9b541074c369a", "best_bid": "0.33", "best_ask": "0.65"}, {"asset_id": "78125564118195609688130723464750437875510814435361379152154876368715602249491", "price": "0.67", "size": "70", "side": "SELL", "hash": "5d187e3ecff9287ea86a8175fd5f61228d33568f", "best_bid": "0.35", "best_ask": "0.67"}], "timestamp": "1769384655751", "event_type": "price_change"}}
{"_local_timestamp": "2026-01-25T23:44:16.095682+00:00", "data": {"market": "0x0b436d14d29b7f778768ffb123a526b4dc496054e26d820d691e9b59f2ae15bf", "price_changes": [{"asset_id": "18488621325714747371592358988913690051744048045248507898917802091914468336625", "price": "0.31", "size": "40", "side": "BUY", "hash": "0c93800b56b55c1f179f74f7cade0a4d4e79418f", "best_bid": "0.33", "best_ask": "0.65"}, {"asset_id": "78125564118195609688130723464750437875510814435361379152154876368715602249491", "price": "0.69", "size": "40", "side": "SELL", "hash": "32da2c3adf32c00af04fe7eee5531f6a44c6e4c0", "best_bid": "0.35", "best_ask": "0.67"}], "timestamp": "1769384655994", "event_type": "price_change"}}
{"_local_timestamp": "2026-01-25T23:44:16.096255+00:00", "data": {"market": "0x0b436d14d29b7f778768ffb123a526b4dc496054e26d820d691e9b59f2ae15bf", "price_changes": [{"asset_id": "18488621325714747371592358988913690051744048045248507898917802091914468336625", "price": "0.32", "size": "178", "side": "BUY", "hash": "e90cd84e26665bcb9c32093593d5d08522f200fc", "best_bid": "0.33", "best_ask": "0.65"}, {"asset_id": "78125564118195609688130723464750437875510814435361379152154876368715602249491", "price": "0.68", "size": "178", "side": "SELL", "hash": "97ba92c8bb9042a5f51a0dd832048e3c09a40244", "best_bid": "0.35", "best_ask": "0.67"}], "timestamp": "1769384655996", "event_type": "price_change"}}
{"_local_timestamp": "2026-01-25T23:44:17.838010+00:00", "data": {"market": "0xe2dfc02908b8fb5e7c6578a42e17b52434f5346bb532ab5715dbbfd46af57a21", "price_changes": [{"asset_id": "79024099644769201382883588167557335172113039460336000034907727657308480799729", "price": "0.791", "size": "0", "side": "SELL", "hash": "138007dd1837091af3a9a4cef72fa9e0ef655d19", "best_bid": "0.001", "best_ask": "0.009"}, {"asset_id": "3269263393231035282910557398978207346672294813068410578094427630928688366591", "price": "0.209", "size": "0", "side": "BUY", "hash": "17a846beac1409db0f45a42d1bbb6410ee9bdf0d", "best_bid": "0.991", "best_ask": "0.999"}], "timestamp": "1769384657757", "event_type": "price_change"}}
{"_local_timestamp": "2026-01-25T23:44:18.769721+00:00", "data": {"market": "0x0b436d14d29b7f778768ffb123a526b4dc496054e26d820d691e9b59f2ae15bf", "price_changes": [{"asset_id": "18488621325714747371592358988913690051744048045248507898917802091914468336625", "price": "0.33", "size": "30", "side": "BUY", "hash": "4cd1087f7d6898e6ff0153c50a51a6d9f02edd99", "best_bid": "0.33", "best_ask": "0.65"}, {"asset_id": "78125564118195609688130723464750437875510814435361379152154876368715602249491", "price": "0.67", "size": "30", "side": "SELL", "hash": "f67055567a301ac79b0cf3ac44b8aa46b8cbcf84", "best_bid": "0.35", "best_ask": "0.67"}], "timestamp": "1769384658702", "event_type": "price_change"}}
{"_local_timestamp": "2026-01-25T23:44:20.994805+00:00", "data": {"market": "0x0b436d14d29b7f778768ffb123a526b4dc496054e26d820d691e9b59f2ae15bf", "price_changes": [{"asset_id": "18488621325714747371592358988913690051744048045248507898917802091914468336625", "price": "0.29", "size": "133.91", "side": "BUY", "hash": "5c1cda19e0155bc4b99446d3e89eb2bb1e358b85", "best_bid": "0.33", "best_ask": "0.65"}, {"asset_id": "78125564118195609688130723464750437875510814435361379152154876368715602249491", "price": "0.71", "size": "133.91", "side": "SELL", "hash": "1a5b084769557c50ada80455a0090dc6bd308031", "best_bid": "0.35", "best_ask": "0.67"}], "timestamp": "1769384660719", "event_type": "price_change"}}
{"_local_timestamp": "2026-01-25T23:44:21.027286+00:00", "data": {"market": "0x0b436d14d29b7f778768ffb123a526b4dc496054e26d820d691e9b59f2ae15bf", "price_changes": [{"asset_id": "18488621325714747371592358988913690051744048045248507898917802091914468336625", "price": "0.32", "size": "218", "side": "BUY", "hash": "528711032be67c13a1f81215ec81ed49fa6c017c", "best_bid": "0.33", "best_ask": "0.65"}, {"asset_id": "78125564118195609688130723464750437875510814435361379152154876368715602249491", "price": "0.68", "size": "218", "side": "SELL", "hash": "bab3856ca578f92edd251bcc94f9f7693779958f", "best_bid": "0.35", "best_ask": "0.67"}], "timestamp": "1769384660738", "event_type": "price_change"}}
{"_local_timestamp": "2026-01-25T23:44:21.075097+00:00", "data": {"market": "0x0b436d14d29b7f778768ffb123a526b4dc496054e26d820d691e9b59f2ae15bf", "price_changes": [{"asset_id": "18488621325714747371592358988913690051744048045248507898917802091914468336625", "price": "0.3", "size": "100", "side": "BUY", "hash": "4be0107265c2a3d7e6a7378a35be51740e0cd51f", "best_bid": "0.33", "best_ask": "0.65"}, {"asset_id": "78125564118195609688130723464750437875510814435361379152154876368715602249491", "price": "0.7", "size": "100", "side": "SELL", "hash": "21e2da6e30d089fe66124b1b6fd3ce602dc9ac69", "best_bid": "0.35", "best_ask": "0.67"}], "timestamp": "1769384660768", "event_type": "price_change"}}
{"_local_timestamp": "2026-01-25T23:44:25.149499+00:00", "data": {"market": "0x092c91d348e732e6e1d10cb85e855ae2982167cc8a514de6d5ce0ed6a81b3406", "price_changes": [{"asset_id": "63124470287776887476483587791259448657774659174144661407693923638503676979579", "price": "0.18", "size": "0", "side": "BUY", "hash": "ac2dc641076e63cd50b7c2680da03e238a5a83f6", "best_bid": "0.64", "best_ask": "0.67"}, {"asset_id": "106600613356134795904313062212730477275252691648870475628884876817519043940991", "price": "0.82", "size": "0", "side": "SELL", "hash": "e2132117cca17a48a399f6ff7db79b54982c04e4", "best_bid": "0.33", "best_ask": "0.36"}], "timestamp": "1769384665080", "event_type": "price_change"}}
{"_local_timestamp": "2026-01-25T23:44:25.684503+00:00", "data": {"market": "0x092c91d348e732e6e1d10cb85e855ae2982167cc8a514de6d5ce0ed6a81b3406", "price_changes": [{"asset_id": "63124470287776887476483587791259448657774659174144661407693923638503676979579", "price": "0.18", "size": "6.04", "side": "BUY", "hash": "1c25b3e759d3398c7821b8f82c05d01b972ba131", "best_bid": "0.64", "best_ask": "0.67"}, {"asset_id": "106600613356134795904313062212730477275252691648870475628884876817519043940991", "price": "0.82", "size": "6.04", "side": "SELL", "hash": "a0acac0bb0cfb585941a6493529cd1a9627a2a50", "best_bid": "0.33", "best_ask": "0.36"}], "timestamp": "1769384665613", "event_type": "price_change"}}
{"_local_timestamp": "2026-01-25T23:44:26.134503+00:00", "data": {"market": "0x0b436d14d29b7f778768ffb123a526b4dc496054e26d820d691e9b59f2ae15bf", "price_changes": [{"asset_id": "18488621325714747371592358988913690051744048045248507898917802091914468336625", "price": "0.06", "size": "0", "side": "BUY", "hash": "58cedc779fe5781503adb92d59ce76ea9a8e9f86", "best_bid": "0.33", "best_ask": "0.65"}, {"asset_id": "78125564118195609688130723464750437875510814435361379152154876368715602249491", "price": "0.94", "size": "0", "side": "SELL", "hash": "4c4ea31e9694c240728b082d97566973d81585b2", "best_bid": "0.35", "best_ask": "0.67"}], "timestamp": "1769384666067", "event_type": "price_change"}}
{"_local_timestamp": "2026-01-25T23:44:26.135039+00:00", "data": {"market": "0x0b436d14d29b7f778768ffb123a526b4dc496054e26d820d691e9b59f2ae15bf", "price_changes": [{"asset_id": "18488621325714747371592358988913690051744048045248507898917802091914468336625", "price": "0.12", "size": "0", "side": "BUY", "hash": "58cedc779fe5781503adb92d59ce76ea9a8e9f86", "best_bid": "0.33", "best_ask": "0.65"}, {"asset_id": "78125564118195609688130723464750437875510814435361379152154876368715602249491", "price": "0.88", "size": "0", "side": "SELL", "hash": "4c4ea31e9694c240728b082d97566973d81585b2", "best_bid": "0.35", "best_ask": "0.67"}], "timestamp": "1769384666067", "event_type": "price_change"}}
{"_local_timestamp": "2026-01-25T23:44:27.027879+00:00", "data": {"market": "0x0b436d14d29b7f778768ffb123a526b4dc496054e26d820d691e9b59f2ae15bf", "price_changes": [{"asset_id": "18488621325714747371592358988913690051744048045248507898917802091914468336625", "price": "0.09", "size": "505.24", "side": "BUY", "hash": "5eca9b29d312cf7251cb44cb6ce9adebb3744334", "best_bid": "0.33", "best_ask": "0.65"}, {"asset_id": "78125564118195609688130723464750437875510814435361379152154876368715602249491", "price": "0.91", "size": "505.24", "side": "SELL", "hash": "f6d05851252a7bba3f20a8b09181f5cd655abc89", "best_bid": "0.35", "best_ask": "0.67"}], "timestamp": "1769384666915", "event_type": "price_change"}}
{"_local_timestamp": "2026-01-25T23:44:27.062641+00:00", "data": {"market": "0x0b436d14d29b7f778768ffb123a526b4dc496054e26d820d691e9b59f2ae15bf", "price_changes": [{"asset_id": "18488621325714747371592358988913690051744048045248507898917802091914468336625", "price": "0.16", "size": "5.09", "side": "BUY", "hash": "5f5f80d652fed246c259e4899732278bd452d2f1", "best_bid": "0.33", "best_ask": "0.65"}, {"asset_id": "78125564118195609688130723464750437875510814435361379152154876368715602249491", "price": "0.84", "size": "5.09", "side": "SELL", "hash": "6962a22edbc17a086c46d986e7740029f7906a3e", "best_bid": "0.35", "best_ask": "0.67"}], "timestamp": "1769384666917", "event_type": "price_change"}}
{"_local_timestamp": "2026-01-25T23:44:27.071969+00:00", "data": {"market": "0x0b436d14d29b7f778768ffb123a526b4dc496054e26d820d691e9b59f2ae15bf", "price_changes": [{"asset_id": "18488621325714747371592358988913690051744048045248507898917802091914468336625", "price": "0.03", "size": "17.06", "side": "BUY", "hash": "f2a1317d948caa59dd90dc8b9b3840115309be6c", "best_bid": "0.33", "best_ask": "0.65"}, {"asset_id": "78125564118195609688130723464750437875510814435361379152154876368715602249491", "price": "0.97", "size": "17.06", "side": "SELL", "hash": "698b9504e625ca2a6ed1e4b4393dafd0e75c6cbe", "best_bid": "0.35", "best_ask": "0.67"}], "timestamp": "1769384666918", "event_type": "price_change"}}
{"_local_timestamp": "2026-01-25T23:44:27.628927+00:00", "data": {"market": "0xe2dfc02908b8fb5e7c6578a42e17b52434f5346bb532ab5715dbbfd46af57a21", "price_changes": [{"asset_id": "3269263393231035282910557398978207346672294813068410578094427630928688366591", "price": "0.574", "size": "0", "side": "BUY", "hash": "835ffa55f5a4a4cbf5c0de16e90501fb9828b61c", "best_bid": "0.991", "best_ask": "0.999"}, {"asset_id": "79024099644769201382883588167557335172113039460336000034907727657308480799729", "price": "0.426", "size": "0", "side": "SELL", "hash": "ff92b885e1e78e9694084cd28f605244887e73b2", "best_bid": "0.001", "best_ask": "0.009"}], "timestamp": "1769384667567", "event_type": "price_change"}}
{"_local_timestamp": "2026-01-25T23:44:27.923655+00:00", "data": {"market": "0xe2dfc02908b8fb5e7c6578a42e17b52434f5346bb532ab5715dbbfd46af57a21", "price_changes": [{"asset_id": "3269263393231035282910557398978207346672294813068410578094427630928688366591", "price": "0.574", "size": "5", "side": "BUY", "hash": "00c8d98c7decb0adb0aef99feaaeff830c11790e", "best_bid": "0.991", "best_ask": "0.999"}, {"asset_id": "79024099644769201382883588167557335172113039460336000034907727657308480799729", "price": "0.426", "size": "5", "side": "SELL", "hash": "c2b500224d7403daa23c121e7edcfbff51d7244c", "best_bid": "0.001", "best_ask": "0.009"}], "timestamp": "1769384667847", "event_type": "price_change"}}
{"_local_timestamp": "2026-01-25T23:44:28.934508+00:00", "data": {"market": "0xe2dfc02908b8fb5e7c6578a42e17b52434f5346bb532ab5715dbbfd46af57a21", "price_changes": [{"asset_id": "3269263393231035282910557398978207346672294813068410578094427630928688366591", "price": "0.574", "size": "0", "side": "BUY", "hash": "40fadfe7e312f874a31dd7c446cda0dfcf2a7f98", "best_bid": "0.991", "best_ask": "0.999"}, {"asset_id": "79024099644769201382883588167557335172113039460336000034907727657308480799729", "price": "0.426", "size": "0", "side": "SELL", "hash": "8459d39a9e49fe86be7a6a57054b8dc99339a6cb", "best_bid": "0.001", "best_ask": "0.009"}], "timestamp": "1769384668871", "event_type": "price_change"}}
{"_local_timestamp": "2026-01-25T23:44:30.556986+00:00", "data": {"market": "0xe2dfc02908b8fb5e7c6578a42e17b52434f5346bb532ab5715dbbfd46af57a21", "price_changes": [{"asset_id": "3269263393231035282910557398978207346672294813068410578094427630928688366591", "price": "0.574", "size": "5", "side": "BUY", "hash": "791aaaeecbdbccd63f6a4901ee8aabe2b990ea78", "best_bid": "0.991", "best_ask": "0.999"}, {"asset_id": "79024099644769201382883588167557335172113039460336000034907727657308480799729", "price": "0.426", "size": "5", "side": "SELL", "hash": "e0609e706eb09cc64d4eb9f8f8af2d2522495212", "best_bid": "0.001", "best_ask": "0.009"}], "timestamp": "1769384670493", "event_type": "price_change"}}
{"_local_timestamp": "2026-01-25T23:44:41.861586+00:00", "data": {"market": "0x092c91d348e732e6e1d10cb85e855ae2982167cc8a514de6d5ce0ed6a81b3406", "price_changes": [{"asset_id": "106600613356134795904313062212730477275252691648870475628884876817519043940991", "price": "0.33", "size": "70", "side": "BUY", "hash": "4fbefe91c4fbfa9d7cd710ef960a6b9c18b87ce6", "best_bid": "0.33", "best_ask": "0.36"}, {"asset_id": "63124470287776887476483587791259448657774659174144661407693923638503676979579", "price": "0.67", "size": "70", "side": "SELL", "hash": "69d7a662bf9d7efb7043ee07d4c5400704596a4e", "best_bid": "0.64", "best_ask": "0.67"}], "timestamp": "1769384681784", "event_type": "price_change"}}
{"_local_timestamp": "2026-01-25T23:44:55.860431+00:00", "data": {"market": "0x092c91d348e732e6e1d10cb85e855ae2982167cc8a514de6d5ce0ed6a81b3406", "price_changes": [{"asset_id": "106600613356134795904313062212730477275252691648870475628884876817519043940991", "price": "0.33", "size": "80.91", "side": "BUY", "hash": "bdd612461f79e71f90e3a66e8ae82bc736921cc2", "best_bid": "0.33", "best_ask": "0.36"}, {"asset_id": "63124470287776887476483587791259448657774659174144661407693923638503676979579", "price": "0.67", "size": "80.91", "side": "SELL", "hash": "99389ca4ddd23f09d8c0e6853ccb235a041486ff", "best_bid": "0.64", "best_ask": "0.67"}], "timestamp": "1769384695796", "event_type": "price_change"}}
{"_local_timestamp": "2026-01-25T23:44:55.871166+00:00", "data": {"market": "0x092c91d348e732e6e1d10cb85e855ae2982167cc8a514de6d5ce0ed6a81b3406", "price_changes": [{"asset_id": "106600613356134795904313062212730477275252691648870475628884876817519043940991", "price": "0.33", "size": "91.82", "side": "BUY", "hash": "5b9facccd1e3e11c11d75d6d7451e3a7ed2856e0", "best_bid": "0.33", "best_ask": "0.36"}, {"asset_id": "63124470287776887476483587791259448657774659174144661407693923638503676979579", "price": "0.67", "size": "91.82", "side": "SELL", "hash": "77fa15dd72426a0ab549fe0ec2997c59b6fd92b6", "best_bid": "0.64", "best_ask": "0.67"}], "timestamp": "1769384695798", "event_type": "price_change"}}
{"_local_timestamp": "2026-01-25T23:44:55.871783+00:00", "data": {"market": "0x092c91d348e732e6e1d10cb85e855ae2982167cc8a514de6d5ce0ed6a81b3406", "price_changes": [{"asset_id": "106600613356134795904313062212730477275252691648870475628884876817519043940991", "price": "0.33", "size": "102.73", "side": "BUY", "hash": "cca7d9445b1f138989d4d8f1a5fdc9036a7b1014", "best_bid": "0.33", "best_ask": "0.36"}, {"asset_id": "63124470287776887476483587791259448657774659174144661407693923638503676979579", "price": "0.67", "size": "102.73", "side": "SELL", "hash": "5af2f3c50588c29a42d40e73d68c581e2ba01b23", "best_bid": "0.64", "best_ask": "0.67"}], "timestamp": "1769384695798", "event_type": "price_change"}}
{"_local_timestamp": "2026-01-25T23:44:55.872373+00:00", "data": {"market": "0x092c91d348e732e6e1d10cb85e855ae2982167cc8a514de6d5ce0ed6a81b3406", "price_changes": [{"asset_id": "106600613356134795904313062212730477275252691648870475628884876817519043940991", "price": "0.33", "size": "113.64", "side": "BUY", "hash": "e547b6f3d41b6f51c835081b2cdb88e172a757d1", "best_bid": "0.33", "best_ask": "0.36"}, {"asset_id": "63124470287776887476483587791259448657774659174144661407693923638503676979579", "price": "0.67", "size": "113.64", "side": "SELL", "hash": "e3a2237a95555fabee8cb4c9e50df8c49ded03e4", "best_bid": "0.64", "best_ask": "0.67"}], "timestamp": "1769384695800", "event_type": "price_change"}}
{"_local_timestamp": "2026-01-25T23:45:07.148796+00:00", "data": {"market": "0xe2dfc02908b8fb5e7c6578a42e17b52434f5346bb532ab5715dbbfd46af57a21", "price_changes": [{"asset_id": "3269263393231035282910557398978207346672294813068410578094427630928688366591", "price": "0.574", "size": "0", "side": "BUY", "hash": "3404833c57bc62a06b52fe0f5a614533ba6f50dd", "best_bid": "0.991", "best_ask": "0.999"}, {"asset_id": "79024099644769201382883588167557335172113039460336000034907727657308480799729", "price": "0.426", "size": "0", "side": "SELL", "hash": "640d7f85814374841e671c52b905d191189a7d22", "best_bid": "0.001", "best_ask": "0.009"}], "timestamp": "1769384707082", "event_type": "price_change"}}
{"_local_timestamp": "2026-01-25T23:45:07.380140+00:00", "data": {"market": "0xe2dfc02908b8fb5e7c6578a42e17b52434f5346bb532ab5715dbbfd46af57a21", "price_changes": [{"asset_id": "3269263393231035282910557398978207346672294813068410578094427630928688366591", "price": "0.574", "size": "5", "side": "BUY", "hash": "4abb88d8eed5e3360af9515d41daad8a0e539bea", "best_bid": "0.991", "best_ask": "0.999"}, {"asset_id": "79024099644769201382883588167557335172113039460336000034907727657308480799729", "price": "0.426", "size": "5", "side": "SELL", "hash": "28f283e8fd9900a1706b193a77400bd81258fcf6", "best_bid": "0.001", "best_ask": "0.009"}], "timestamp": "1769384707311", "event_type": "price_change"}}
{"_local_timestamp": "2026-01-25T23:45:23.466398+00:00", "data": {"market": "0x0b436d14d29b7f778768ffb123a526b4dc496054e26d820d691e9b59f2ae15bf", "price_changes": [{"asset_id": "18488621325714747371592358988913690051744048045248507898917802091914468336625", "price": "0.3", "size": "0", "side": "BUY", "hash": "bbb44e7601a26cce58c2fd0c004b82b93059c825", "best_bid": "0.33", "best_ask": "0.65"}, {"asset_id": "78125564118195609688130723464750437875510814435361379152154876368715602249491", "price": "0.7", "size": "0", "side": "SELL", "hash": "f7d92562034e20a853e0963a54ac4147700d566e", "best_bid": "0.35", "best_ask": "0.67"}], "timestamp": "1769384723388", "event_type": "price_change"}}
{"_local_timestamp": "2026-01-25T23:45:25.798657+00:00", "data": {"market": "0x0b436d14d29b7f778768ffb123a526b4dc496054e26d820d691e9b59f2ae15bf", "price_changes": [{"asset_id": "18488621325714747371592358988913690051744048045248507898917802091914468336625", "price": "0.29", "size": "233.91", "side": "BUY", "hash": "a9ab0366f0d101706a16e38d107d8dbe835563b4", "best_bid": "0.33", "best_ask": "0.65"}, {"asset_id": "78125564118195609688130723464750437875510814435361379152154876368715602249491", "price": "0.71", "size": "233.91", "side": "SELL", "hash": "3a3cbc98b63cb9cd14c75d5e227008463db05afb", "best_bid": "0.35", "best_ask": "0.67"}], "timestamp": "1769384725732", "event_type": "price_change"}}
{"_local_timestamp": "2026-01-25T23:45:33.195461+00:00", "data": {"market": "0x0b436d14d29b7f778768ffb123a526b4dc496054e26d820d691e9b59f2ae15bf", "price_changes": [{"asset_id": "18488621325714747371592358988913690051744048045248507898917802091914468336625", "price": "0.33", "size": "109", "side": "BUY", "hash": "6d9ca48dd6e6f370109bf0722ba51c9ab5a2471c", "best_bid": "0.33", "best_ask": "0.65"}, {"asset_id": "78125564118195609688130723464750437875510814435361379152154876368715602249491", "price": "0.67", "size": "109", "side": "SELL", "hash": "250fc655e006704b3a7069160f9302a935edad79", "best_bid": "0.35", "best_ask": "0.67"}], "timestamp": "1769384733130", "event_type": "price_change"}}
{"_local_timestamp": "2026-01-25T23:45:43.682946+00:00", "data": {"market": "0x0b436d14d29b7f778768ffb123a526b4dc496054e26d820d691e9b59f2ae15bf", "price_changes": [{"asset_id": "18488621325714747371592358988913690051744048045248507898917802091914468336625", "price": "0.32", "size": "178", "side": "BUY", "hash": "c36431ac53358f0045ea09060ff84c3d24d348a5", "best_bid": "0.33", "best_ask": "0.65"}, {"asset_id": "78125564118195609688130723464750437875510814435361379152154876368715602249491", "price": "0.68", "size": "178", "side": "SELL", "hash": "46a9110ac7106a5371338d5e605bacb2af5cf897", "best_bid": "0.35", "best_ask": "0.67"}], "timestamp": "1769384743614", "event_type": "price_change"}}
{"_local_timestamp": "2026-01-25T23:45:45.637016+00:00", "data": {"market": "0x092c91d348e732e6e1d10cb85e855ae2982167cc8a514de6d5ce0ed6a81b3406", "price_changes": [{"asset_id": "106600613356134795904313062212730477275252691648870475628884876817519043940991", "price": "0.33", "size": "70", "side": "BUY", "hash": "a5fbd056001893945a0eebb413ef0b55d9cb46dc", "best_bid": "0.33", "best_ask": "0.36"}, {"asset_id": "63124470287776887476483587791259448657774659174144661407693923638503676979579", "price": "0.67", "size": "70", "side": "SELL", "hash": "23ea3981235bf0aa4c88b739abb7f049ede14be9", "best_bid": "0.64", "best_ask": "0.67"}], "timestamp": "1769384745570", "event_type": "price_change"}}
{"_local_timestamp": "2026-01-25T23:45:45.831243+00:00", "data": {"market": "0x0b436d14d29b7f778768ffb123a526b4dc496054e26d820d691e9b59f2ae15bf", "price_changes": [{"asset_id": "18488621325714747371592358988913690051744048045248507898917802091914468336625", "price": "0.32", "size": "218", "side": "BUY", "hash": "4b605139e2dcd181527083c7edacd8cbbf8bdf40", "best_bid": "0.33", "best_ask": "0.65"}, {"asset_id": "78125564118195609688130723464750437875510814435361379152154876368715602249491", "price": "0.68", "size": "218", "side": "SELL", "hash": "093fc080c90e6bc56745b41ac3432a94869d8044", "best_bid": "0.35", "best_ask": "0.67"}], "timestamp": "1769384745763", "event_type": "price_change"}}
{"_local_timestamp": "2026-01-25T23:45:47.926173+00:00", "data": {"market": "0xe2dfc02908b8fb5e7c6578a42e17b52434f5346bb532ab5715dbbfd46af57a21", "price_changes": [{"asset_id": "3269263393231035282910557398978207346672294813068410578094427630928688366591", "price": "0.208", "size": "2640", "side": "BUY", "hash": "bcd8b7d3bf91397571a2161d59b50e0893aa21fa", "best_bid": "0.991", "best_ask": "0.999"}, {"asset_id": "79024099644769201382883588167557335172113039460336000034907727657308480799729", "price": "0.792", "size": "2640", "side": "SELL", "hash": "9dfd39f88401a2f4d05f217683a61d4a2e5976f5", "best_bid": "0.001", "best_ask": "0.009"}], "timestamp": "1769384747864", "event_type": "price_change"}}
{"_local_timestamp": "2026-01-25T23:45:47.937104+00:00", "data": {"market": "0xe2dfc02908b8fb5e7c6578a42e17b52434f5346bb532ab5715dbbfd46af57a21", "price_changes": [{"asset_id": "79024099644769201382883588167557335172113039460336000034907727657308480799729", "price": "0.001", "size": "0", "side": "BUY", "hash": "86698a9e6096ab9cf157a57ad3fda8c353b3959e", "best_bid": "0", "best_ask": "0.009"}, {"asset_id": "3269263393231035282910557398978207346672294813068410578094427630928688366591", "price": "0.999", "size": "0", "side": "SELL", "hash": "1c50f25f327b98808e9f75ba2c2a70416b0ed7af", "best_bid": "0.991", "best_ask": "1"}], "timestamp": "1769384747874", "event_type": "price_change"}}
{"_local_timestamp": "2026-01-25T23:45:47.937809+00:00", "data": {"market": "0xe2dfc02908b8fb5e7c6578a42e17b52434f5346bb532ab5715dbbfd46af57a21", "asset_id": "79024099644769201382883588167557335172113039460336000034907727657308480799729", "bids": [], "asks": [{"price": "0.999", "size": "100144.23"}, {"price": "0.998", "size": "55000"}, {"price": "0.997", "size": "22.41"}, {"price": "0.992", "size": "155"}, {"price": "0.99", "size": "920410"}, {"price": "0.989", "size": "55710"}, {"price": "0.988", "size": "11.81"}, {"price": "0.98", "size": "6000"}, {"price": "0.969", "size": "10000"}, {"price": "0.968", "size": "5.88"}, {"price": "0.96", "size": "303200"}, {"price": "0.95", "size": "1620"}, {"price": "0.94", "size": "33"}, {"price": "0.939", "size": "7.75"}, {"price": "0.92", "size": "155"}, {"price": "0.903", "size": "100"}, {"price": "0.901", "size": "100"}, {"price": "0.9", "size": "6000"}, {"price": "0.899", "size": "10300"}, {"price": "0.89", "size": "3000"}, {"price": "0.85", "size": "500"}, {"price": "0.849", "size": "7.37"}, {"price": "0.793", "size": "300"}, {"price": "0.792", "size": "2640"}, {"price": "0.79", "size": "2640"}, {"price": "0.78", "size": "21"}, {"price": "0.53", "size": "100"}, {"price": "0.51", "size": "100"}, {"price": "0.503", "size": "100"}, {"price": "0.501", "size": "500"}, {"price": "0.5", "size": "480"}, {"price": "0.499", "size": "20"}, {"price": "0.498", "size": "5"}, {"price": "0.426", "size": "5"}, {"price": "0.25", "size": "60"}, {"price": "0.249", "size": "53"}, {"price": "0.23", "size": "180"}, {"price": "0.2", "size": "100"}, {"price": "0.18", "size": "100"}, {"price": "0.17", "size": "50"}, {"price": "0.16", "size": "100"}, {"price": "0.15", "size": "50"}, {"price": "0.14", "size": "5"}, {"price": "0.1", "size": "30"}, {"price": "0.01", "size": "995.59"}, {"price": "0.009", "size": "644"}], "hash": "86698a9e6096ab9cf157a57ad3fda8c353b3959e", "timestamp": "1769384747874", "event_type": "book"}}
{"_local_timestamp": "2026-01-25T23:45:47.938525+00:00", "data": {"market": "0xe2dfc02908b8fb5e7c6578a42e17b52434f5346bb532ab5715dbbfd46af57a21", "asset_id": "3269263393231035282910557398978207346672294813068410578094427630928688366591", "bids": [{"price": "0.001", "size": "100144.23"}, {"price": "0.002", "size": "55000"}, {"price": "0.003", "size": "22.41"}, {"price": "0.008", "size": "155"}, {"price": "0.01", "size": "920410"}, {"price": "0.011", "size": "55710"}, {"price": "0.012", "size": "11.81"}, {"price": "0.02", "size": "6000"}, {"price": "0.031", "size": "10000"}, {"price": "0.032", "size": "5.88"}, {"price": "0.04", "size": "303200"}, {"price": "0.05", "size": "1620"}, {"price": "0.06", "size": "33"}, {"price": "0.061", "size": "7.75"}, {"price": "0.08", "size": "155"}, {"price": "0.097", "size": "100"}, {"price": "0.099", "size": "100"}, {"price": "0.1", "size": "6000"}, {"price": "0.101", "size": "10300"}, {"price": "0.11", "size": "3000"}, {"price": "0.15", "size": "500"}, {"price": "0.151", "size": "7.37"}, {"price": "0.207", "size": "300"}, {"price": "0.208", "size": "2640"}, {"price": "0.21", "size": "2640"}, {"price": "0.22", "size": "21"}, {"price": "0.47", "size": "100"}, {"price": "0.49", "size": "100"}, {"price": "0.497", "size": "100"}, {"price": "0.499", "size": "500"}, {"price": "0.5", "size": "480"}, {"price": "0.501", "size": "20"}, {"price": "0.502", "size": "5"}, {"price": "0.574", "size": "5"}, {"price": "0.75", "size": "60"}, {"price": "0.751", "size": "53"}, {"price": "0.77", "size": "180"}, {"price": "0.8", "size": "100"}, {"price": "0.82", "size": "100"}, {"price": "0.83", "size": "50"}, {"price": "0.84", "size": "100"}, {"price": "0.85", "size": "50"}, {"price": "0.86", "size": "5"}, {"price": "0.9", "size": "30"}, {"price": "0.99", "size": "995.59"}, {"price": "0.991", "size": "644"}], "asks": [], "hash": "1c50f25f327b98808e9f75ba2c2a70416b0ed7af", "timestamp": "1769384747874", "event_type": "book"}}
{"_local_timestamp": "2026-01-25T23:45:47.980706+00:00", "data": {"market": "0xe2dfc02908b8fb5e7c6578a42e17b52434f5346bb532ab5715dbbfd46af57a21", "asset_id": "3269263393231035282910557398978207346672294813068410578094427630928688366591", "price": "0.999", "size": "830", "fee_rate_bps": "0", "side": "BUY", "timestamp": "1769384747908", "event_type": "last_trade_price", "transaction_hash": "0xf610a8fc502af1788aecb8c6282f0fbf10cb794dbeb310606854076143b17197"}}
{"_local_timestamp": "2026-01-25T23:45:48.205834+00:00", "data": {"market": "0x0b436d14d29b7f778768ffb123a526b4dc496054e26d820d691e9b59f2ae15bf", "price_changes": [{"asset_id": "18488621325714747371592358988913690051744048045248507898917802091914468336625", "price": "0.33", "size": "30", "side": "BUY", "hash": "36f0185233f736151ce2f8a9ade48476208f88a1", "best_bid": "0.33", "best_ask": "0.65"}, {"asset_id": "78125564118195609688130723464750437875510814435361379152154876368715602249491", "price": "0.67", "size": "30", "side": "SELL", "hash": "cc64e129da1f683184b40e71b7fbe1cd7b35c32e", "best_bid": "0.35", "best_ask": "0.67"}], "timestamp": "1769384748140", "event_type": "price_change"}}
{"_local_timestamp": "2026-01-25T23:45:49.146904+00:00", "data": {"market": "0xe2dfc02908b8fb5e7c6578a42e17b52434f5346bb532ab5715dbbfd46af57a21", "price_changes": [{"asset_id": "3269263393231035282910557398978207346672294813068410578094427630928688366591", "price": "0.501", "size": "0", "side": "BUY", "hash": "0f8cbfc625b53d4f69f45edb3c5bf2a718aa278b", "best_bid": "0.991", "best_ask": "1"}, {"asset_id": "79024099644769201382883588167557335172113039460336000034907727657308480799729", "price": "0.499", "size": "0", "side": "SELL", "hash": "a3d77598d23454c866344048ed302f8100a9ca34", "best_bid": "0", "best_ask": "0.009"}], "timestamp": "1769384749080", "event_type": "price_change"}}
{"_local_timestamp": "2026-01-25T23:45:49.153954+00:00", "data": {"market": "0x0b436d14d29b7f778768ffb123a526b4dc496054e26d820d691e9b59f2ae15bf", "price_changes": [{"asset_id": "18488621325714747371592358988913690051744048045248507898917802091914468336625", "price": "0.28", "size": "60", "side": "BUY", "hash": "51c840e494410ee34d95fb9caac990b11b1c71b0", "best_bid": "0.33", "best_ask": "0.65"}, {"asset_id": "78125564118195609688130723464750437875510814435361379152154876368715602249491", "price": "0.72", "size": "60", "side": "SELL", "hash": "6a5c8dd8a959539f877a6b92d935369d8149248d", "best_bid": "0.35", "best_ask": "0.67"}], "timestamp": "1769384749080", "event_type": "price_change"}}
{"_local_timestamp": "2026-01-25T23:45:49.169927+00:00", "data": {"market": "0x0b436d14d29b7f778768ffb123a526b4dc496054e26d820d691e9b59f2ae15bf", "price_changes": [{"asset_id": "18488621325714747371592358988913690051744048045248507898917802091914468336625", "price": "0.16", "size": "25.09", "side": "BUY", "hash": "84e6257c0bfe9073129478579e24839540a268fa", "best_bid": "0.33", "best_ask": "0.65"}, {"asset_id": "78125564118195609688130723464750437875510814435361379152154876368715602249491", "price": "0.84", "size": "25.09", "side": "SELL", "hash": "a265b2a6da860107ba752a317b86bf56b914a25b", "best_bid": "0.35", "best_ask": "0.67"}], "timestamp": "1769384749103", "event_type": "price_change"}}
{"_local_timestamp": "2026-01-25T23:45:49.616715+00:00", "data": {"market": "0xe2dfc02908b8fb5e7c6578a42e17b52434f5346bb532ab5715dbbfd46af57a21", "price_changes": [{"asset_id": "3269263393231035282910557398978207346672294813068410578094427630928688366591", "price": "0.21", "size": "0", "side": "BUY", "hash": "44888670e7686da1a331edc9caa1b9706e580b7d", "best_bid": "0.991", "best_ask": "1"}, {"asset_id": "79024099644769201382883588167557335172113039460336000034907727657308480799729", "price": "0.79", "size": "0", "side": "SELL", "hash": "7053fd11ba280d5abd0a53095fae5900ea8df4c4", "best_bid": "0", "best_ask": "0.009"}], "timestamp": "1769384749551", "event_type": "price_change"}}
{"_local_timestamp": "2026-01-25T23:45:56.213772+00:00", "data": {"market": "0x0b436d14d29b7f778768ffb123a526b4dc496054e26d820d691e9b59f2ae15bf", "price_changes": [{"asset_id": "78125564118195609688130723464750437875510814435361379152154876368715602249491", "price": "0.05", "size": "610", "side": "BUY", "hash": "7657e0e0050c972aef1b93755eed35c8abc6292c", "best_bid": "0.35", "best_ask": "0.67"}, {"asset_id": "18488621325714747371592358988913690051744048045248507898917802091914468336625", "price": "0.95", "size": "610", "side": "SELL", "hash": "07a26775808ee23bc1656b1b5bdaa7c4cea9500d", "best_bid": "0.33", "best_ask": "0.65"}], "timestamp": "1769384756072", "event_type": "price_change"}}
{"_local_timestamp": "2026-01-25T23:45:56.520965+00:00", "data": {"market": "0xe2dfc02908b8fb5e7c6578a42e17b52434f5346bb532ab5715dbbfd46af57a21", "price_changes": [{"asset_id": "3269263393231035282910557398978207346672294813068410578094427630928688366591", "price": "0.207", "size": "0", "side": "BUY", "hash": "136ac691d550e33807ad0855d22496b643ce0730", "best_bid": "0.991", "best_ask": "1"}, {"asset_id": "79024099644769201382883588167557335172113039460336000034907727657308480799729", "price": "0.793", "size": "0", "side": "SELL", "hash": "908280b03cffed63a46e4e42ba919bacfc97de43", "best_bid": "0", "best_ask": "0.009"}], "timestamp": "1769384756087", "event_type": "price_change"}}
{"_local_timestamp": "2026-01-25T23:45:57.473858+00:00", "data": {"market": "0x0b436d14d29b7f778768ffb123a526b4dc496054e26d820d691e9b59f2ae15bf", "price_changes": [{"asset_id": "18488621325714747371592358988913690051744048045248507898917802091914468336625", "price": "0.32", "size": "178", "side": "BUY", "hash": "21a8e6ee7678a769dc9ef6387126f30716c49934", "best_bid": "0.33", "best_ask": "0.65"}, {"asset_id": "78125564118195609688130723464750437875510814435361379152154876368715602249491", "price": "0.68", "size": "178", "side": "SELL", "hash": "f1c7ba265d2a8d0d4b516817ad9afb54499bad0b", "best_bid": "0.35", "best_ask": "0.67"}], "timestamp": "1769384757362", "event_type": "price_change"}}
{"_local_timestamp": "2026-01-25T23:45:58.582982+00:00", "data": {"market": "0xe2dfc02908b8fb5e7c6578a42e17b52434f5346bb532ab5715dbbfd46af57a21", "price_changes": [{"asset_id": "3269263393231035282910557398978207346672294813068410578094427630928688366591", "price": "0.574", "size": "0", "side": "BUY", "hash": "ddd9e8beaff677b5c554eeab5206356d9f2a463d", "best_bid": "0.991", "best_ask": "1"}, {"asset_id": "79024099644769201382883588167557335172113039460336000034907727657308480799729", "price": "0.426", "size": "0", "side": "SELL", "hash": "c39b4d681ba99aaa6514f48e19099fcffa000380", "best_bid": "0", "best_ask": "0.009"}], "timestamp": "1769384758518", "event_type": "price_change"}}
{"_local_timestamp": "2026-01-25T23:45:58.855925+00:00", "data": {"market": "0xe2dfc02908b8fb5e7c6578a42e17b52434f5346bb532ab5715dbbfd46af57a21", "price_changes": [{"asset_id": "3269263393231035282910557398978207346672294813068410578094427630928688366591", "price": "0.574", "size": "5", "side": "BUY", "hash": "c1c1072c92d8da035e6b949bb365c04187e0612a", "best_bid": "0.991", "best_ask": "1"}, {"asset_id": "79024099644769201382883588167557335172113039460336000034907727657308480799729", "price": "0.426", "size": "5", "side": "SELL", "hash": "0cc3a15f8aa71067228bff1db4ec622dfa33ba47", "best_bid": "0", "best_ask": "0.009"}], "timestamp": "1769384758788", "event_type": "price_change"}}
{"_local_timestamp": "2026-01-25T23:46:00.704373+00:00", "data": {"market": "0x092c91d348e732e6e1d10cb85e855ae2982167cc8a514de6d5ce0ed6a81b3406", "price_changes": [{"asset_id": "106600613356134795904313062212730477275252691648870475628884876817519043940991", "price": "0.33", "size": "80.91", "side": "BUY", "hash": "6352d2db8e45caee36a516672180cf49c7e08435", "best_bid": "0.33", "best_ask": "0.36"}, {"asset_id": "63124470287776887476483587791259448657774659174144661407693923638503676979579", "price": "0.67", "size": "80.91", "side": "SELL", "hash": "290d57b6d0ff7582b0b77ca8468df9e5a21b3920", "best_bid": "0.64", "best_ask": "0.67"}], "timestamp": "1769384760640", "event_type": "price_change"}}
{"_local_timestamp": "2026-01-25T23:46:00.704984+00:00", "data": {"market": "0x092c91d348e732e6e1d10cb85e855ae2982167cc8a514de6d5ce0ed6a81b3406", "price_changes": [{"asset_id": "106600613356134795904313062212730477275252691648870475628884876817519043940991", "price": "0.33", "size": "91.82", "side": "BUY", "hash": "d30d802543ab0f95c8bc2ba9c6faf32e2202f22c", "best_bid": "0.33", "best_ask": "0.36"}, {"asset_id": "63124470287776887476483587791259448657774659174144661407693923638503676979579", "price": "0.67", "size": "91.82", "side": "SELL", "hash": "673405f706974e3ddb7771564102714124ebad24", "best_bid": "0.64", "best_ask": "0.67"}], "timestamp": "1769384760640", "event_type": "price_change"}}
{"_local_timestamp": "2026-01-25T23:46:00.708309+00:00", "data": {"market": "0x092c91d348e732e6e1d10cb85e855ae2982167cc8a514de6d5ce0ed6a81b3406", "price_changes": [{"asset_id": "106600613356134795904313062212730477275252691648870475628884876817519043940991", "price": "0.33", "size": "102.73", "side": "BUY", "hash": "864ef70b5dca65d30aae1b86ef9ce1a321ad7736", "best_bid": "0.33", "best_ask": "0.36"}, {"asset_id": "63124470287776887476483587791259448657774659174144661407693923638503676979579", "price": "0.67", "size": "102.73", "side": "SELL", "hash": "315dc40440c8dd421a4f11b81d556ea332bca83e", "best_bid": "0.64", "best_ask": "0.67"}], "timestamp": "1769384760641", "event_type": "price_change"}}
{"_local_timestamp": "2026-01-25T23:46:00.708808+00:00", "data": {"market": "0x092c91d348e732e6e1d10cb85e855ae2982167cc8a514de6d5ce0ed6a81b3406", "price_changes": [{"asset_id": "106600613356134795904313062212730477275252691648870475628884876817519043940991", "price": "0.33", "size": "113.64", "side": "BUY", "hash": "5cf607dda6beb6a59aa63539af0b9c6a0a00dc3c", "best_bid": "0.33", "best_ask": "0.36"}, {"asset_id": "63124470287776887476483587791259448657774659174144661407693923638503676979579", "price": "0.67", "size": "113.64", "side": "SELL", "hash": "2b95853a6d5f0637025377f5e9054261a337d417", "best_bid": "0.64", "best_ask": "0.67"}], "timestamp": "1769384760641", "event_type": "price_change"}}
{"_local_timestamp": "2026-01-25T23:46:00.821880+00:00", "data": {"market": "0x0b436d14d29b7f778768ffb123a526b4dc496054e26d820d691e9b59f2ae15bf", "price_changes": [{"asset_id": "18488621325714747371592358988913690051744048045248507898917802091914468336625", "price": "0.3", "size": "40", "side": "BUY", "hash": "ba9dc0c95efa48b0285539d7641d755073147e80", "best_bid": "0.33", "best_ask": "0.65"}, {"asset_id": "78125564118195609688130723464750437875510814435361379152154876368715602249491", "price": "0.7", "size": "40", "side": "SELL", "hash": "2006afe973bea6640a8a1f64463feb817423715d", "best_bid": "0.35", "best_ask": "0.67"}], "timestamp": "1769384760748", "event_type": "price_change"}}
{"_local_timestamp": "2026-01-25T23:46:01.802754+00:00", "data": {"market": "0xe2dfc02908b8fb5e7c6578a42e17b52434f5346bb532ab5715dbbfd46af57a21", "price_changes": [{"asset_id": "3269263393231035282910557398978207346672294813068410578094427630928688366591", "price": "0.211", "size": "300", "side": "BUY", "hash": "ef68d5039138ffec054375ae60c07deaa2a287a8", "best_bid": "0.991", "best_ask": "1"}, {"asset_id": "79024099644769201382883588167557335172113039460336000034907727657308480799729", "price": "0.789", "size": "300", "side": "SELL", "hash": "40f6f1bea95a60fa06c4768e6da00959a5df41c6", "best_bid": "0", "best_ask": "0.009"}], "timestamp": "1769384761730", "event_type": "price_change"}}
{"_local_timestamp": "2026-01-25T23:46:01.803423+00:00", "data": {"market": "0x0b436d14d29b7f778768ffb123a526b4dc496054e26d820d691e9b59f2ae15bf", "price_changes": [{"asset_id": "78125564118195609688130723464750437875510814435361379152154876368715602249491", "price": "0.06", "size": "308.02", "side": "BUY", "hash": "53b12b0e79d6f79576af759c6d7a1cdbe1c9b6cc", "best_bid": "0.35", "best_ask": "0.67"}, {"asset_id": "18488621325714747371592358988913690051744048045248507898917802091914468336625", "price": "0.94", "size": "308.02", "side": "SELL", "hash": "177e3be80ac273a4cd4b0fe19acd2d08726c9f07", "best_bid": "0.33", "best_ask": "0.65"}], "timestamp": "1769384761730", "event_type": "price_change"}}
{"_local_timestamp": "2026-01-25T23:46:05.367824+00:00", "data": {"market": "0xe2dfc02908b8fb5e7c6578a42e17b52434f5346bb532ab5715dbbfd46af57a21", "price_changes": [{"asset_id": "3269263393231035282910557398978207346672294813068410578094427630928688366591", "price": "0.999", "size": "830", "side": "BUY", "hash": "31fe558951f2edf090037d04715c9672310416b7", "best_bid": "0.999", "best_ask": "1"}, {"asset_id": "79024099644769201382883588167557335172113039460336000034907727657308480799729", "price": "0.001", "size": "830", "side": "SELL", "hash": "dd6389b2fa7133d52699147c7d80def54cd822ae", "best_bid": "0", "best_ask": "0.001"}], "timestamp": "1769384765298", "event_type": "price_change"}}
{"_local_timestamp": "2026-01-25T23:46:10.932795+00:00", "data": {"market": "0xe2dfc02908b8fb5e7c6578a42e17b52434f5346bb532ab5715dbbfd46af57a21", "price_changes": [{"asset_id": "3269263393231035282910557398978207346672294813068410578094427630928688366591", "price": "0.999", "size": "0", "side": "BUY", "hash": "84f466f969fb54cb993a60cbcbaf1223700c1e87", "best_bid": "0.991", "best_ask": "1"}, {"asset_id": "79024099644769201382883588167557335172113039460336000034907727657308480799729", "price": "0.001", "size": "0", "side": "SELL", "hash": "a640e8e4ab32601d48fdeb5651e3c9b76d21dae1", "best_bid": "0", "best_ask": "0.009"}], "timestamp": "1769384770758", "event_type": "price_change"}}
{"_local_timestamp": "2026-01-25T23:46:15.837224+00:00", "data": {"market": "0x0b436d14d29b7f778768ffb123a526b4dc496054e26d820d691e9b59f2ae15bf", "price_changes": [{"asset_id": "18488621325714747371592358988913690051744048045248507898917802091914468336625", "price": "0.3", "size": "0", "side": "BUY", "hash": "aa7fc85674d2bd9c21ac0b8e914f9a4937b891dc", "best_bid": "0.33", "best_ask": "0.65"}, {"asset_id": "78125564118195609688130723464750437875510814435361379152154876368715602249491", "price": "0.7", "size": "0", "side": "SELL", "hash": "8f5ede5eb076eacdd8f86f24a44e99f65f94ad5d", "best_bid": "0.35", "best_ask": "0.67"}], "timestamp": "1769384775755", "event_type": "price_change"}}
{"_local_timestamp": "2026-01-25T23:46:15.859739+00:00", "data": {"market": "0x0b436d14d29b7f778768ffb123a526b4dc496054e26d820d691e9b59f2ae15bf", "price_changes": [{"asset_id": "18488621325714747371592358988913690051744048045248507898917802091914468336625", "price": "0.32", "size": "218", "side": "BUY", "hash": "956ca1f2930e5ab01fba904b639aed38ccc04ba1", "best_bid": "0.33", "best_ask": "0.65"}, {"asset_id": "78125564118195609688130723464750437875510814435361379152154876368715602249491", "price": "0.68", "size": "218", "side": "SELL", "hash": "9013eeea27e37344c4c1f6d94d0e1090112f5621", "best_bid": "0.35", "best_ask": "0.67"}], "timestamp": "1769384775782", "event_type": "price_change"}}
{"_local_timestamp": "2026-01-25T23:46:16.907102+00:00", "data": {"market": "0x0b436d14d29b7f778768ffb123a526b4dc496054e26d820d691e9b59f2ae15bf", "price_changes": [{"asset_id": "18488621325714747371592358988913690051744048045248507898917802091914468336625", "price": "0.32", "size": "178", "side": "BUY", "hash": "4ebf1dc38ca507c0610a1f4eabb240d51a2b4e1f", "best_bid": "0.33", "best_ask": "0.65"}, {"asset_id": "78125564118195609688130723464750437875510814435361379152154876368715602249491", "price": "0.68", "size": "178", "side": "SELL", "hash": "9fdffae4ca43d01e8a7039e64426979e8d06353e", "best_bid": "0.35", "best_ask": "0.67"}], "timestamp": "1769384776845", "event_type": "price_change"}}
{"_local_timestamp": "2026-01-25T23:46:20.871186+00:00", "data": {"market": "0x0b436d14d29b7f778768ffb123a526b4dc496054e26d820d691e9b59f2ae15bf", "price_changes": [{"asset_id": "18488621325714747371592358988913690051744048045248507898917802091914468336625", "price": "0.32", "size": "218", "side": "BUY", "hash": "598dac118fa020f7b5f1cad2033c5875ecc0bd2e", "best_bid": "0.33", "best_ask": "0.65"}, {"asset_id": "78125564118195609688130723464750437875510814435361379152154876368715602249491", "price": "0.68", "size": "218", "side": "SELL", "hash": "9bbf71647a7e4cd4585cf01cf92d0771a664ed79", "best_bid": "0.35", "best_ask": "0.67"}], "timestamp": "1769384780808", "event_type": "price_change"}}
{"_local_timestamp": "2026-01-25T23:46:24.044674+00:00", "data": {"market": "0x0b436d14d29b7f778768ffb123a526b4dc496054e26d820d691e9b59f2ae15bf", "price_changes": [{"asset_id": "18488621325714747371592358988913690051744048045248507898917802091914468336625", "price": "0.32", "size": "178", "side": "BUY", "hash": "e5ee7e9f7f6142259594bdbe477116c2a16ee713", "best_bid": "0.33", "best_ask": "0.65"}, {"asset_id": "78125564118195609688130723464750437875510814435361379152154876368715602249491", "price": "0.68", "size": "178", "side": "SELL", "hash": "6e03fbe2217819700de8bd608ecd6c62a51688c2", "best_bid": "0.35", "best_ask": "0.67"}], "timestamp": "1769384783973", "event_type": "price_change"}}
{"_local_timestamp": "2026-01-25T23:46:25.796368+00:00", "data": {"market": "0x0b436d14d29b7f778768ffb123a526b4dc496054e26d820d691e9b59f2ae15bf", "price_changes": [{"asset_id": "18488621325714747371592358988913690051744048045248507898917802091914468336625", "price": "0.31", "size": "80", "side": "BUY", "hash": "ed8056e510c276aa9db39358cded4f27a9df29bd", "best_bid": "0.33", "best_ask": "0.65"}, {"asset_id": "78125564118195609688130723464750437875510814435361379152154876368715602249491", "price": "0.69", "size": "80", "side": "SELL", "hash": "d50158ef0f32b64fb4bf77190a70cc5173af1151", "best_bid": "0.35", "best_ask": "0.67"}], "timestamp": "1769384785732", "event_type": "price_change"}}
{"_local_timestamp": "2026-01-25T23:46:25.910154+00:00", "data": {"market": "0x0b436d14d29b7f778768ffb123a526b4dc496054e26d820d691e9b59f2ae15bf", "price_changes": [{"asset_id": "78125564118195609688130723464750437875510814435361379152154876368715602249491", "price": "0.05", "size": "310", "side": "BUY", "hash": "d64c73813f04311e8c1fd7137de5c77f5b293e41", "best_bid": "0.35", "best_ask": "0.67"}, {"asset_id": "18488621325714747371592358988913690051744048045248507898917802091914468336625", "price": "0.95", "size": "310", "side": "SELL", "hash": "c6895f18ee987c7dbee0f13662e799d204c25f6b", "best_bid": "0.33", "best_ask": "0.65"}], "timestamp": "1769384785838", "event_type": "price_change"}}
{"_local_timestamp": "2026-01-25T23:46:35.641128+00:00", "data": {"market": "0x0b436d14d29b7f778768ffb123a526b4dc496054e26d820d691e9b59f2ae15bf", "price_changes": [{"asset_id": "78125564118195609688130723464750437875510814435361379152154876368715602249491", "price": "0.05", "size": "10", "side": "BUY", "hash": "70b5d8b26d01f0de35ea0422752f974b033645cd", "best_bid": "0.35", "best_ask": "0.67"}, {"asset_id": "18488621325714747371592358988913690051744048045248507898917802091914468336625", "price": "0.95", "size": "10", "side": "SELL", "hash": "9d6d47b1a772ae3fbd5727ec6216d50f97d92548", "best_bid": "0.33", "best_ask": "0.65"}], "timestamp": "1769384795551", "event_type": "price_change"}}
{"_local_timestamp": "2026-01-25T23:46:44.187979+00:00", "data": {"market": "0x0b436d14d29b7f778768ffb123a526b4dc496054e26d820d691e9b59f2ae15bf", "price_changes": [{"asset_id": "18488621325714747371592358988913690051744048045248507898917802091914468336625", "price": "0.31", "size": "40", "side": "BUY", "hash": "16e1ebad44db528c125965016dd550782c5b3797", "best_bid": "0.33", "best_ask": "0.65"}, {"asset_id": "78125564118195609688130723464750437875510814435361379152154876368715602249491", "price": "0.69", "size": "40", "side": "SELL", "hash": "0bd5b881a2ae22dab720fbdd23c572680c41a5c5", "best_bid": "0.35", "best_ask": "0.67"}], "timestamp": "1769384804121", "event_type": "price_change"}}
{"_local_timestamp": "2026-01-25T23:46:45.617610+00:00", "data": {"market": "0xe2dfc02908b8fb5e7c6578a42e17b52434f5346bb532ab5715dbbfd46af57a21", "price_changes": [{"asset_id": "3269263393231035282910557398978207346672294813068410578094427630928688366591", "price": "0.574", "size": "0", "side": "BUY", "hash": "18818251ed46f8fbae6af19fec5b61110e4d817c", "best_bid": "0.991", "best_ask": "1"}, {"asset_id": "79024099644769201382883588167557335172113039460336000034907727657308480799729", "price": "0.426", "size": "0", "side": "SELL", "hash": "4fe3d2d25b2dedb8715c77713dfe5a8d3d406efe", "best_bid": "0", "best_ask": "0.009"}], "timestamp": "1769384805543", "event_type": "price_change"}}
{"_local_timestamp": "2026-01-25T23:46:45.869297+00:00", "data": {"market": "0x0b436d14d29b7f778768ffb123a526b4dc496054e26d820d691e9b59f2ae15bf", "price_changes": [{"asset_id": "18488621325714747371592358988913690051744048045248507898917802091914468336625", "price": "0.3", "size": "40", "side": "BUY", "hash": "fe6db9cd6a2f0f113eb812f36a336a41a6858db0", "best_bid": "0.33", "best_ask": "0.65"}, {"asset_id": "78125564118195609688130723464750437875510814435361379152154876368715602249491", "price": "0.7", "size": "40", "side": "SELL", "hash": "4cfcc58d60e74fdc3ef38313735f5cab3270dae3", "best_bid": "0.35", "best_ask": "0.67"}], "timestamp": "1769384805796", "event_type": "price_change"}}
{"_local_timestamp": "2026-01-25T23:46:46.139650+00:00", "data": {"market": "0xe2dfc02908b8fb5e7c6578a42e17b52434f5346bb532ab5715dbbfd46af57a21", "price_changes": [{"asset_id": "3269263393231035282910557398978207346672294813068410578094427630928688366591", "price": "0.574", "size": "5", "side": "BUY", "hash": "94d95a65c83a1e80b3649a2b4b97b79262b0832b", "best_bid": "0.991", "best_ask": "1"}, {"asset_id": "79024099644769201382883588167557335172113039460336000034907727657308480799729", "price": "0.426", "size": "5", "side": "SELL", "hash": "f3c221b68316264d3bf5e6f986d9ab255e4dfede", "best_bid": "0", "best_ask": "0.009"}], "timestamp": "1769384806042", "event_type": "price_change"}}
{"_local_timestamp": "2026-01-25T23:46:51.046580+00:00", "data": {"market": "0x092c91d348e732e6e1d10cb85e855ae2982167cc8a514de6d5ce0ed6a81b3406", "price_changes": [{"asset_id": "106600613356134795904313062212730477275252691648870475628884876817519043940991", "price": "0.33", "size": "70", "side": "BUY", "hash": "14a17cbff63f8ed70448bd046b01ef4935012a74", "best_bid": "0.33", "best_ask": "0.36"}, {"asset_id": "63124470287776887476483587791259448657774659174144661407693923638503676979579", "price": "0.67", "size": "70", "side": "SELL", "hash": "d8e14f88fd93ee8a237cc5b5756a5a56468ca43c", "best_bid": "0.64", "best_ask": "0.67"}], "timestamp": "1769384810762", "event_type": "price_change"}}
{"_local_timestamp": "2026-01-25T23:46:55.808882+00:00", "data": {"market": "0x0b436d14d29b7f778768ffb123a526b4dc496054e26d820d691e9b59f2ae15bf", "price_changes": [{"asset_id": "18488621325714747371592358988913690051744048045248507898917802091914468336625", "price": "0.3", "size": "0", "side": "BUY", "hash": "d9cfd771e3f7d8e5410124b6ef53caa78c9d34d5", "best_bid": "0.33", "best_ask": "0.65"}, {"asset_id": "78125564118195609688130723464750437875510814435361379152154876368715602249491", "price": "0.7", "size": "0", "side": "SELL", "hash": "cdd3a21ee2ef7b943ef6d13939c3576fa7c4917e", "best_bid": "0.35", "best_ask": "0.67"}], "timestamp": "1769384815742", "event_type": "price_change"}}
{"_local_timestamp": "2026-01-25T23:46:55.840737+00:00", "data": {"market": "0x0b436d14d29b7f778768ffb123a526b4dc496054e26d820d691e9b59f2ae15bf", "price_changes": [{"asset_id": "18488621325714747371592358988913690051744048045248507898917802091914468336625", "price": "0.32", "size": "218", "side": "BUY", "hash": "1040f65289cdba5750844d617347970d61b0e47f", "best_bid": "0.33", "best_ask": "0.65"}, {"asset_id": "78125564118195609688130723464750437875510814435361379152154876368715602249491", "price": "0.68", "size": "218", "side": "SELL", "hash": "b36875808d982f69582df38e5ca91ecddf2a6e09", "best_bid": "0.35", "best_ask": "0.67"}], "timestamp": "1769384815773", "event_type": "price_change"}}
{"_local_timestamp": "2026-01-25T23:46:56.218333+00:00", "data": {"market": "0x0b436d14d29b7f778768ffb123a526b4dc496054e26d820d691e9b59f2ae15bf", "price_changes": [{"asset_id": "18488621325714747371592358988913690051744048045248507898917802091914468336625", "price": "0.29", "size": "183.91", "side": "BUY", "hash": "4315a24dc78af5b398d2a2c094e5b7f7ec84650e", "best_bid": "0.33", "best_ask": "0.65"}, {"asset_id": "78125564118195609688130723464750437875510814435361379152154876368715602249491", "price": "0.71", "size": "183.91", "side": "SELL", "hash": "f1313260e6de5e47612db780e7046d8e1d94b2a0", "best_bid": "0.35", "best_ask": "0.67"}], "timestamp": "1769384816144", "event_type": "price_change"}}
{"_local_timestamp": "2026-01-25T23:46:56.219891+00:00", "data": {"market": "0x0b436d14d29b7f778768ffb123a526b4dc496054e26d820d691e9b59f2ae15bf", "price_changes": [{"asset_id": "18488621325714747371592358988913690051744048045248507898917802091914468336625", "price": "0.32", "size": "178", "side": "BUY", "hash": "3797cf2a5d5db11838d8edadc6b06eee8937fed9", "best_bid": "0.33", "best_ask": "0.65"}, {"asset_id": "78125564118195609688130723464750437875510814435361379152154876368715602249491", "price": "0.68", "size": "178", "side": "SELL", "hash": "4e7bcda62a8a1e1edf0ed3876753af53d90303a5", "best_bid": "0.35", "best_ask": "0.67"}], "timestamp": "1769384816150", "event_type": "price_change"}}
{"_local_timestamp": "2026-01-25T23:47:00.814762+00:00", "data": {"market": "0x0b436d14d29b7f778768ffb123a526b4dc496054e26d820d691e9b59f2ae15bf", "price_changes": [{"asset_id": "18488621325714747371592358988913690051744048045248507898917802091914468336625", "price": "0.31", "size": "80", "side": "BUY", "hash": "579792b67a6771f3b6ff52224e35f42936125439", "best_bid": "0.33", "best_ask": "0.65"}, {"asset_id": "78125564118195609688130723464750437875510814435361379152154876368715602249491", "price": "0.69", "size": "80", "side": "SELL", "hash": "325cdac71dbc1bf8ab77f50492908b695fa2f849", "best_bid": "0.35", "best_ask": "0.67"}], "timestamp": "1769384820744", "event_type": "price_change"}}
{"_local_timestamp": "2026-01-25T23:47:00.819623+00:00", "data": {"market": "0x0b436d14d29b7f778768ffb123a526b4dc496054e26d820d691e9b59f2ae15bf", "price_changes": [{"asset_id": "18488621325714747371592358988913690051744048045248507898917802091914468336625", "price": "0.28", "size": "110", "side": "BUY", "hash": "dfb246abc0616c5c47d53c733ddbc32173039f61", "best_bid": "0.33", "best_ask": "0.65"}, {"asset_id": "78125564118195609688130723464750437875510814435361379152154876368715602249491", "price": "0.72", "size": "110", "side": "SELL", "hash": "788e70d666e1fb6622751fa6a06c4c0767577885", "best_bid": "0.35", "best_ask": "0.67"}], "timestamp": "1769384820744", "event_type": "price_change"}}
{"_local_timestamp": "2026-01-25T23:47:02.316548+00:00", "data": {"market": "0x0b436d14d29b7f778768ffb123a526b4dc496054e26d820d691e9b59f2ae15bf", "price_changes": [{"asset_id": "18488621325714747371592358988913690051744048045248507898917802091914468336625", "price": "0.29", "size": "83.91", "side": "BUY", "hash": "773f7b9d57045af0c73612951e3b5bda2a6e4516", "best_bid": "0.33", "best_ask": "0.65"}, {"asset_id": "78125564118195609688130723464750437875510814435361379152154876368715602249491", "price": "0.71", "size": "83.91", "side": "SELL", "hash": "b174de88ef6960296b9c4e38ab9607c85151affe", "best_bid": "0.35", "best_ask": "0.67"}], "timestamp": "1769384822245", "event_type": "price_change"}}
{"_local_timestamp": "2026-01-25T23:47:02.317706+00:00", "data": {"market": "0x0b436d14d29b7f778768ffb123a526b4dc496054e26d820d691e9b59f2ae15bf", "price_changes": [{"asset_id": "18488621325714747371592358988913690051744048045248507898917802091914468336625", "price": "0.28", "size": "60", "side": "BUY", "hash": "cd6d43d20c45cebd47b44cd620a5bfd0dd026143", "best_bid": "0.33", "best_ask": "0.65"}, {"asset_id": "78125564118195609688130723464750437875510814435361379152154876368715602249491", "price": "0.72", "size": "60", "side": "SELL", "hash": "1b312cbf54d8950d051d1adfa7c6b5f8b30b39dc", "best_bid": "0.35", "best_ask": "0.67"}], "timestamp": "1769384822248", "event_type": "price_change"}}
{"_local_timestamp": "2026-01-25T23:47:02.539598+00:00", "data": {"market": "0x0b436d14d29b7f778768ffb123a526b4dc496054e26d820d691e9b59f2ae15bf", "price_changes": [{"asset_id": "18488621325714747371592358988913690051744048045248507898917802091914468336625", "price": "0.31", "size": "40", "side": "BUY", "hash": "4e7d4124cc807b637c196da9c4db42cd27fde6de", "best_bid": "0.33", "best_ask": "0.65"}, {"asset_id": "78125564118195609688130723464750437875510814435361379152154876368715602249491", "price": "0.69", "size": "40", "side": "SELL", "hash": "8bff258f2711c9bd3664522e2e3f62ea2a35f17d", "best_bid": "0.35", "best_ask": "0.67"}], "timestamp": "1769384822467", "event_type": "price_change"}}
{"_local_timestamp": "2026-01-25T23:47:04.775804+00:00", "data": {"market": "0x092c91d348e732e6e1d10cb85e855ae2982167cc8a514de6d5ce0ed6a81b3406", "price_changes": [{"asset_id": "106600613356134795904313062212730477275252691648870475628884876817519043940991", "price": "0.33", "size": "80.91", "side": "BUY", "hash": "545604fb26ce4311c6e9dfdd30ee4f8fe809a258", "best_bid": "0.33", "best_ask": "0.36"}, {"asset_id": "63124470287776887476483587791259448657774659174144661407693923638503676979579", "price": "0.67", "size": "80.91", "side": "SELL", "hash": "2f8ccb0b62e7c1330c01d7b358552fd616099f08", "best_bid": "0.64", "best_ask": "0.67"}], "timestamp": "1769384824698", "event_type": "price_change"}}
{"_local_timestamp": "2026-01-25T23:47:04.781678+00:00", "data": {"market": "0x092c91d348e732e6e1d10cb85e855ae2982167cc8a514de6d5ce0ed6a81b3406", "price_changes": [{"asset_id": "106600613356134795904313062212730477275252691648870475628884876817519043940991", "price": "0.33", "size": "91.82", "side": "BUY", "hash": "19bef878e10a7922cb69374b86323869db77eff2", "best_bid": "0.33", "best_ask": "0.36"}, {"asset_id": "63124470287776887476483587791259448657774659174144661407693923638503676979579", "price": "0.67", "size": "91.82", "side": "SELL", "hash": "5c50edc8183363411f686dd718b49b21093cf27b", "best_bid": "0.64", "best_ask": "0.67"}], "timestamp": "1769384824699", "event_type": "price_change"}}
{"_local_timestamp": "2026-01-25T23:47:04.867041+00:00", "data": {"market": "0x092c91d348e732e6e1d10cb85e855ae2982167cc8a514de6d5ce0ed6a81b3406", "price_changes": [{"asset_id": "106600613356134795904313062212730477275252691648870475628884876817519043940991", "price": "0.33", "size": "102.73", "side": "BUY", "hash": "88155fc324305c808e2286c200c50fc42dec583f", "best_bid": "0.33", "best_ask": "0.36"}, {"asset_id": "63124470287776887476483587791259448657774659174144661407693923638503676979579", "price": "0.67", "size": "102.73", "side": "SELL", "hash": "c556420216492b4cc4558f35704cd6770d45091e", "best_bid": "0.64", "best_ask": "0.67"}], "timestamp": "1769384824801", "event_type": "price_change"}}
{"_local_timestamp": "2026-01-25T23:47:04.867721+00:00", "data": {"market": "0x092c91d348e732e6e1d10cb85e855ae2982167cc8a514de6d5ce0ed6a81b3406", "price_changes": [{"asset_id": "106600613356134795904313062212730477275252691648870475628884876817519043940991", "price": "0.33", "size": "113.64", "side": "BUY", "hash": "06917ecd8248c387c2bd3cd9c42d297254393d75", "best_bid": "0.33", "best_ask": "0.36"}, {"asset_id": "63124470287776887476483587791259448657774659174144661407693923638503676979579", "price": "0.67", "size": "113.64", "side": "SELL", "hash": "ab7c9c5e39f3106f790185048736f83ce14f9898", "best_bid": "0.64", "best_ask": "0.67"}], "timestamp": "1769384824801", "event_type": "price_change"}}
{"_local_timestamp": "2026-01-25T23:47:05.071031+00:00", "data": {"market": "0x0b436d14d29b7f778768ffb123a526b4dc496054e26d820d691e9b59f2ae15bf", "price_changes": [{"asset_id": "18488621325714747371592358988913690051744048045248507898917802091914468336625", "price": "0.32", "size": "158", "side": "BUY", "hash": "cdf52a645194bf431aa635fee449b1d49388fede", "best_bid": "0.33", "best_ask": "0.65"}, {"asset_id": "78125564118195609688130723464750437875510814435361379152154876368715602249491", "price": "0.68", "size": "158", "side": "SELL", "hash": "4d4b2e7af4dec6295721fb0d419a1cfe542d4e5e", "best_bid": "0.35", "best_ask": "0.67"}], "timestamp": "1769384825000", "event_type": "price_change"}}
{"_local_timestamp": "2026-01-25T23:47:05.774688+00:00", "data": {"market": "0x0b436d14d29b7f778768ffb123a526b4dc496054e26d820d691e9b59f2ae15bf", "price_changes": [{"asset_id": "18488621325714747371592358988913690051744048045248507898917802091914468336625", "price": "0.29", "size": "123.91", "side": "BUY", "hash": "f4160ddb42305a44b01c28c8531ead6a90b3017a", "best_bid": "0.33", "best_ask": "0.65"}, {"asset_id": "78125564118195609688130723464750437875510814435361379152154876368715602249491", "price": "0.71", "size": "123.91", "side": "SELL", "hash": "1c40e91a1dcf66211950defd080a8c65d2963349", "best_bid": "0.35", "best_ask": "0.67"}], "timestamp": "1769384825705", "event_type": "price_change"}}
{"_local_timestamp": "2026-01-25T23:47:05.799770+00:00", "data": {"market": "0x0b436d14d29b7f778768ffb123a526b4dc496054e26d820d691e9b59f2ae15bf", "price_changes": [{"asset_id": "18488621325714747371592358988913690051744048045248507898917802091914468336625", "price": "0.27", "size": "100", "side": "BUY", "hash": "784b2bf542c648aad1654f9d5f0e82ef35ded093", "best_bid": "0.33", "best_ask": "0.65"}, {"asset_id": "78125564118195609688130723464750437875510814435361379152154876368715602249491", "price": "0.73", "size": "100", "side": "SELL", "hash": "77a681d8a5dbee83a6dce7d7e1788fefc64c8bef", "best_bid": "0.35", "best_ask": "0.67"}], "timestamp": "1769384825731", "event_type": "price_change"}}
{"_local_timestamp": "2026-01-25T23:47:05.801332+00:00", "data": {"market": "0x0b436d14d29b7f778768ffb123a526b4dc496054e26d820d691e9b59f2ae15bf", "price_changes": [{"asset_id": "18488621325714747371592358988913690051744048045248507898917802091914468336625", "price": "0.26", "size": "50", "side": "BUY", "hash": "421847d24f7b1af035c6cc467704338a2bed4398", "best_bid": "0.33", "best_ask": "0.65"}, {"asset_id": "78125564118195609688130723464750437875510814435361379152154876368715602249491", "price": "0.74", "size": "50", "side": "SELL", "hash": "5be27903267daef512569d7ce85386df755e712a", "best_bid": "0.35", "best_ask": "0.67"}], "timestamp": "1769384825731", "event_type": "price_change"}}
{"_local_timestamp": "2026-01-25T23:47:07.450342+00:00", "data": {"market": "0x0b436d14d29b7f778768ffb123a526b4dc496054e26d820d691e9b59f2ae15bf", "price_changes": [{"asset_id": "18488621325714747371592358988913690051744048045248507898917802091914468336625", "price": "0.16", "size": "5.09", "side": "BUY", "hash": "1c446de878f9e604bd2446a61b97369dc0bd8a02", "best_bid": "0.33", "best_ask": "0.65"}, {"asset_id": "78125564118195609688130723464750437875510814435361379152154876368715602249491", "price": "0.84", "size": "5.09", "side": "SELL", "hash": "0197d7ad7d576ed2580db1982d49ff0c727a9ffa", "best_bid": "0.35", "best_ask": "0.67"}], "timestamp": "1769384827386", "event_type": "price_change"}}
{"_local_timestamp": "2026-01-25T23:47:07.492611+00:00", "data": {"market": "0x0b436d14d29b7f778768ffb123a526b4dc496054e26d820d691e9b59f2ae15bf", "price_changes": [{"asset_id": "18488621325714747371592358988913690051744048045248507898917802091914468336625", "price": "0.28", "size": "80", "side": "BUY", "hash": "9157b3a59024135d32a61b17a8ffd067883c422e", "best_bid": "0.33", "best_ask": "0.65"}, {"asset_id": "78125564118195609688130723464750437875510814435361379152154876368715602249491", "price": "0.72", "size": "80", "side": "SELL", "hash": "7f32534e5d44d82cfb868ca712d43a4c374292b7", "best_bid": "0.35", "best_ask": "0.67"}], "timestamp": "1769384827419", "event_type": "price_change"}}
{"_local_timestamp": "2026-01-25T23:47:20.809147+00:00", "data": {"market": "0x0b436d14d29b7f778768ffb123a526b4dc496054e26d820d691e9b59f2ae15bf", "price_changes": [{"asset_id": "18488621325714747371592358988913690051744048045248507898917802091914468336625", "price": "0.29", "size": "83.91", "side": "BUY", "hash": "2a71f4e9afd5e44687311b6b45ae11b259647e08", "best_bid": "0.33", "best_ask": "0.65"}, {"asset_id": "78125564118195609688130723464750437875510814435361379152154876368715602249491", "price": "0.71", "size": "83.91", "side": "SELL", "hash": "bca01dad8fbfcffc11930c30f3d5efd43e9d50a1", "best_bid": "0.35", "best_ask": "0.67"}], "timestamp": "1769384840743", "event_type": "price_change"}}
{"_local_timestamp": "2026-01-25T23:47:20.835506+00:00", "data": {"market": "0x0b436d14d29b7f778768ffb123a526b4dc496054e26d820d691e9b59f2ae15bf", "price_changes": [{"asset_id": "18488621325714747371592358988913690051744048045248507898917802091914468336625", "price": "0.31", "size": "80", "side": "BUY", "hash": "9e111c55930c9e945e2fde1e645633fa5c70c76b", "best_bid": "0.33", "best_ask": "0.65"}, {"asset_id": "78125564118195609688130723464750437875510814435361379152154876368715602249491", "price": "0.69", "size": "80", "side": "SELL", "hash": "6ad07282e6bc8a3233e3b64f85dc8b7ab5788985", "best_bid": "0.35", "best_ask": "0.67"}], "timestamp": "1769384840769", "event_type": "price_change"}}
{"_local_timestamp": "2026-01-25T23:47:21.682361+00:00", "data": {"market": "0x0b436d14d29b7f778768ffb123a526b4dc496054e26d820d691e9b59f2ae15bf", "price_changes": [{"asset_id": "18488621325714747371592358988913690051744048045248507898917802091914468336625", "price": "0.31", "size": "40", "side": "BUY", "hash": "878bf581c626ccb146442aa83bc3eaf03557db05", "best_bid": "0.33", "best_ask": "0.65"}, {"asset_id": "78125564118195609688130723464750437875510814435361379152154876368715602249491", "price": "0.69", "size": "40", "side": "SELL", "hash": "4b9b9036302bd83cc0436fb54110ff3153ee2c14", "best_bid": "0.35", "best_ask": "0.67"}], "timestamp": "1769384841611", "event_type": "price_change"}}
{"_local_timestamp": "2026-01-25T23:47:22.127745+00:00", "data": {"market": "0x0b436d14d29b7f778768ffb123a526b4dc496054e26d820d691e9b59f2ae15bf", "price_changes": [{"asset_id": "18488621325714747371592358988913690051744048045248507898917802091914468336625", "price": "0.27", "size": "0", "side": "BUY", "hash": "1698992ffdf10a61458eeec6194b27660d793548", "best_bid": "0.33", "best_ask": "0.65"}, {"asset_id": "78125564118195609688130723464750437875510814435361379152154876368715602249491", "price": "0.73", "size": "0", "side": "SELL", "hash": "ccc055552ed0b6a4b749449cff92ccca3695d57b", "best_bid": "0.35", "best_ask": "0.67"}], "timestamp": "1769384842058", "event_type": "price_change"}}
{"_local_timestamp": "2026-01-25T23:47:22.128330+00:00", "data": {"market": "0x0b436d14d29b7f778768ffb123a526b4dc496054e26d820d691e9b59f2ae15bf", "price_changes": [{"asset_id": "18488621325714747371592358988913690051744048045248507898917802091914468336625", "price": "0.26", "size": "0", "side": "BUY", "hash": "471f818b79b75ff75aac9a69bfb133ca65cd679b", "best_bid": "0.33", "best_ask": "0.65"}, {"asset_id": "78125564118195609688130723464750437875510814435361379152154876368715602249491", "price": "0.74", "size": "0", "side": "SELL", "hash": "dc358e237120a09b75e29d1e1c871feb44b8d5ce", "best_bid": "0.35", "best_ask": "0.67"}], "timestamp": "1769384842065", "event_type": "price_change"}}
{"_local_timestamp": "2026-01-25T23:47:22.697721+00:00", "data": {"market": "0x0b436d14d29b7f778768ffb123a526b4dc496054e26d820d691e9b59f2ae15bf", "price_changes": [{"asset_id": "18488621325714747371592358988913690051744048045248507898917802091914468336625", "price": "0.28", "size": "60", "side": "BUY", "hash": "70614e3cad65369818f946f0d92aefe357ff0b85", "best_bid": "0.33", "best_ask": "0.65"}, {"asset_id": "78125564118195609688130723464750437875510814435361379152154876368715602249491", "price": "0.72", "size": "60", "side": "SELL", "hash": "d49b6d2b927ca61e767a19466e8f9235230b60e4", "best_bid": "0.35", "best_ask": "0.67"}], "timestamp": "1769384842631", "event_type": "price_change"}}
{"_local_timestamp": "2026-01-25T23:47:22.723385+00:00", "data": {"market": "0x0b436d14d29b7f778768ffb123a526b4dc496054e26d820d691e9b59f2ae15bf", "price_changes": [{"asset_id": "18488621325714747371592358988913690051744048045248507898917802091914468336625", "price": "0.16", "size": "25.09", "side": "BUY", "hash": "04beb9e920930bdc48270c4a6f51184593374d3e", "best_bid": "0.33", "best_ask": "0.65"}, {"asset_id": "78125564118195609688130723464750437875510814435361379152154876368715602249491", "price": "0.84", "size": "25.09", "side": "SELL", "hash": "2cc1ec63fe873e6ca815fc77b7419c926bcd65dc", "best_bid": "0.35", "best_ask": "0.67"}], "timestamp": "1769384842661", "event_type": "price_change"}}
{"_local_timestamp": "2026-01-25T23:47:25.796094+00:00", "data": {"market": "0x0b436d14d29b7f778768ffb123a526b4dc496054e26d820d691e9b59f2ae15bf", "price_changes": [{"asset_id": "18488621325714747371592358988913690051744048045248507898917802091914468336625", "price": "0.31", "size": "80", "side": "BUY", "hash": "b3886824edc1414e73c763027728870514c96949", "best_bid": "0.33", "best_ask": "0.65"}, {"asset_id": "78125564118195609688130723464750437875510814435361379152154876368715602249491", "price": "0.69", "size": "80", "side": "SELL", "hash": "e28a6b0d036ffb20ca78e65199f24c42837bd40d", "best_bid": "0.35", "best_ask": "0.67"}], "timestamp": "1769384845730", "event_type": "price_change"}}
{"_local_timestamp": "2026-01-25T23:47:25.828455+00:00", "data": {"market": "0x0b436d14d29b7f778768ffb123a526b4dc496054e26d820d691e9b59f2ae15bf", "price_changes": [{"asset_id": "18488621325714747371592358988913690051744048045248507898917802091914468336625", "price": "0.27", "size": "100", "side": "BUY", "hash": "283b93f4ae04af624b16497bb8e53d2f2fb41405", "best_bid": "0.33", "best_ask": "0.65"}, {"asset_id": "78125564118195609688130723464750437875510814435361379152154876368715602249491", "price": "0.73", "size": "100", "side": "SELL", "hash": "7d246728e14e29f8e71238bec2ef15e9ceabe7a9", "best_bid": "0.35", "best_ask": "0.67"}], "timestamp": "1769384845762", "event_type": "price_change"}}
{"_local_timestamp": "2026-01-25T23:47:25.828985+00:00", "data": {"market": "0x0b436d14d29b7f778768ffb123a526b4dc496054e26d820d691e9b59f2ae15bf", "price_changes": [{"asset_id": "18488621325714747371592358988913690051744048045248507898917802091914468336625", "price": "0.26", "size": "50", "side": "BUY", "hash": "52986b9182c154fc96a25605cb72345c0ccb3ab2", "best_bid": "0.33", "best_ask": "0.65"}, {"asset_id": "78125564118195609688130723464750437875510814435361379152154876368715602249491", "price": "0.74", "size": "50", "side": "SELL", "hash": "c78e8ba9710ab6d59097c672d1027c11d632f71b", "best_bid": "0.35", "best_ask": "0.67"}], "timestamp": "1769384845762", "event_type": "price_change"}}
{"_local_timestamp": "2026-01-25T23:47:27.188913+00:00", "data": {"market": "0x0b436d14d29b7f778768ffb123a526b4dc496054e26d820d691e9b59f2ae15bf", "price_changes": [{"asset_id": "18488621325714747371592358988913690051744048045248507898917802091914468336625", "price": "0.26", "size": "0", "side": "BUY", "hash": "bf2d9e32ca9d3e0bcb471148b89d77b7133004e4", "best_bid": "0.33", "best_ask": "0.65"}, {"asset_id": "78125564118195609688130723464750437875510814435361379152154876368715602249491", "price": "0.74", "size": "0", "side": "SELL", "hash": "ff440af232c66c19d47c7dde24473390c131b90f", "best_bid": "0.35", "best_ask": "0.67"}], "timestamp": "1769384847122", "event_type": "price_change"}}
{"_local_timestamp": "2026-01-25T23:47:27.971228+00:00", "data": {"market": "0x0b436d14d29b7f778768ffb123a526b4dc496054e26d820d691e9b59f2ae15bf", "price_changes": [{"asset_id": "18488621325714747371592358988913690051744048045248507898917802091914468336625", "price": "0.16", "size": "5.09", "side": "BUY", "hash": "84b3c62b4a1048a8a0e64649837954b1a23ebf06", "best_bid": "0.33", "best_ask": "0.65"}, {"asset_id": "78125564118195609688130723464750437875510814435361379152154876368715602249491", "price": "0.84", "size": "5.09", "side": "SELL", "hash": "6fc9d60f678ab7a873800d3af18473dcd9f42bab", "best_bid": "0.35", "best_ask": "0.67"}], "timestamp": "1769384847903", "event_type": "price_change"}}
{"_local_timestamp": "2026-01-25T23:47:27.995132+00:00", "data": {"market": "0x0b436d14d29b7f778768ffb123a526b4dc496054e26d820d691e9b59f2ae15bf", "price_changes": [{"asset_id": "18488621325714747371592358988913690051744048045248507898917802091914468336625", "price": "0.28", "size": "80", "side": "BUY", "hash": "2e8e79a4ef2c2990fd79e757571e3f7afd4576a9", "best_bid": "0.33", "best_ask": "0.65"}, {"asset_id": "78125564118195609688130723464750437875510814435361379152154876368715602249491", "price": "0.72", "size": "80", "side": "SELL", "hash": "df8180040faa5e0ffeb0f9771a226bc4d613eb62", "best_bid": "0.35", "best_ask": "0.67"}], "timestamp": "1769384847931", "event_type": "price_change"}}
{"_local_timestamp": "2026-01-25T23:47:28.849799+00:00", "data": {"market": "0x0b436d14d29b7f778768ffb123a526b4dc496054e26d820d691e9b59f2ae15bf", "price_changes": [{"asset_id": "18488621325714747371592358988913690051744048045248507898917802091914468336625", "price": "0.12", "size": "16", "side": "BUY", "hash": "410cba2b8a499522dbd643ab81907e9e11c9ae53", "best_bid": "0.33", "best_ask": "0.65"}, {"asset_id": "78125564118195609688130723464750437875510814435361379152154876368715602249491", "price": "0.88", "size": "16", "side": "SELL", "hash": "9329762a862303482f5fabbbbdad1b74b70baa3b", "best_bid": "0.35", "best_ask": "0.67"}], "timestamp": "1769384848784", "event_type": "price_change"}}
{"_local_timestamp": "2026-01-25T23:47:30.848259+00:00", "data": {"market": "0x0b436d14d29b7f778768ffb123a526b4dc496054e26d820d691e9b59f2ae15bf", "price_changes": [{"asset_id": "18488621325714747371592358988913690051744048045248507898917802091914468336625", "price": "0.27", "size": "150", "side": "BUY", "hash": "df123c9a470ee6b8c6762d02d6029e3c1f11cb7c", "best_bid": "0.33", "best_ask": "0.65"}, {"asset_id": "78125564118195609688130723464750437875510814435361379152154876368715602249491", "price": "0.73", "size": "150", "side": "SELL", "hash": "fc5ce51d8e63da93cdc302c8ded690530d3ef5ae", "best_bid": "0.35", "best_ask": "0.67"}], "timestamp": "1769384850781", "event_type": "price_change"}}
{"_local_timestamp": "2026-01-25T23:47:35.705996+00:00", "data": {"market": "0x0b436d14d29b7f778768ffb123a526b4dc496054e26d820d691e9b59f2ae15bf", "price_changes": [{"asset_id": "18488621325714747371592358988913690051744048045248507898917802091914468336625", "price": "0.31", "size": "40", "side": "BUY", "hash": "469929abbc948ed12c674d8af057ec0a20edf8e9", "best_bid": "0.33", "best_ask": "0.65"}, {"asset_id": "78125564118195609688130723464750437875510814435361379152154876368715602249491", "price": "0.69", "size": "40", "side": "SELL", "hash": "29ffd5c510d1d6addf59b208dd042bd5b548c68c", "best_bid": "0.35", "best_ask": "0.67"}], "timestamp": "1769384855641", "event_type": "price_change"}}
{"_local_timestamp": "2026-01-25T23:47:35.898017+00:00", "data": {"market": "0x0b436d14d29b7f778768ffb123a526b4dc496054e26d820d691e9b59f2ae15bf", "price_changes": [{"asset_id": "18488621325714747371592358988913690051744048045248507898917802091914468336625", "price": "0.29", "size": "123.91", "side": "BUY", "hash": "066983d8a4b2f68228a86630bc3ad5885535a1d7", "best_bid": "0.33", "best_ask": "0.65"}, {"asset_id": "78125564118195609688130723464750437875510814435361379152154876368715602249491", "price": "0.71", "size": "123.91", "side": "SELL", "hash": "bf08c4a9f113dfdea93e70fed6cec3d9a6bc2df7", "best_bid": "0.35", "best_ask": "0.67"}], "timestamp": "1769384855830", "event_type": "price_change"}}
{"_local_timestamp": "2026-01-25T23:47:38.001789+00:00", "data": {"market": "0xe2dfc02908b8fb5e7c6578a42e17b52434f5346bb532ab5715dbbfd46af57a21", "price_changes": [{"asset_id": "79024099644769201382883588167557335172113039460336000034907727657308480799729", "price": "0.01", "size": "895.59", "side": "SELL", "hash": "4891793ee6d579e46aa41c876a5ce1631249a5dc", "best_bid": "0", "best_ask": "0.009"}, {"asset_id": "3269263393231035282910557398978207346672294813068410578094427630928688366591", "price": "0.99", "size": "895.59", "side": "BUY", "hash": "095b51b791616fe2528631e5c553ba121e8f90bf", "best_bid": "0.991", "best_ask": "1"}], "timestamp": "1769384857720", "event_type": "price_change"}}
{"_local_timestamp": "2026-01-25T23:47:40.956464+00:00", "data": {"market": "0xe2dfc02908b8fb5e7c6578a42e17b52434f5346bb532ab5715dbbfd46af57a21", "price_changes": [{"asset_id": "3269263393231035282910557398978207346672294813068410578094427630928688366591", "price": "0.574", "size": "0", "side": "BUY", "hash": "3598e5aa3d305e7e8891598ab5c7b70b2c85c83b", "best_bid": "0.991", "best_ask": "1"}, {"asset_id": "79024099644769201382883588167557335172113039460336000034907727657308480799729", "price": "0.426", "size": "0", "side": "SELL", "hash": "9bb6349340ba10df6203f8750e27266cb40f78fc", "best_bid": "0", "best_ask": "0.009"}], "timestamp": "1769384860889", "event_type": "price_change"}}
{"_local_timestamp": "2026-01-25T23:47:41.387431+00:00", "data": {"market": "0xe2dfc02908b8fb5e7c6578a42e17b52434f5346bb532ab5715dbbfd46af57a21", "price_changes": [{"asset_id": "3269263393231035282910557398978207346672294813068410578094427630928688366591", "price": "0.574", "size": "5", "side": "BUY", "hash": "6919d2340a59b3a5f66336a1eab9d1cf0c79fa13", "best_bid": "0.991", "best_ask": "1"}, {"asset_id": "79024099644769201382883588167557335172113039460336000034907727657308480799729", "price": "0.426", "size": "5", "side": "SELL", "hash": "aac7c0ec00bf558bc35543c75b0213480e43947c", "best_bid": "0", "best_ask": "0.009"}], "timestamp": "1769384861321", "event_type": "price_change"}}
{"_local_timestamp": "2026-01-25T23:47:55.961631+00:00", "data": {"market": "0x0b436d14d29b7f778768ffb123a526b4dc496054e26d820d691e9b59f2ae15bf", "price_changes": [{"asset_id": "18488621325714747371592358988913690051744048045248507898917802091914468336625", "price": "0.29", "size": "83.91", "side": "BUY", "hash": "5235ffc72bf573003442266131a3509f076f52d3", "best_bid": "0.33", "best_ask": "0.65"}, {"asset_id": "78125564118195609688130723464750437875510814435361379152154876368715602249491", "price": "0.71", "size": "83.91", "side": "SELL", "hash": "e3d4ca4723be77b8f2f7b3300487faa7aeeddf21", "best_bid": "0.35", "best_ask": "0.67"}], "timestamp": "1769384875783", "event_type": "price_change"}}
{"_local_timestamp": "2026-01-25T23:47:55.969437+00:00", "data": {"market": "0x0b436d14d29b7f778768ffb123a526b4dc496054e26d820d691e9b59f2ae15bf", "price_changes": [{"asset_id": "18488621325714747371592358988913690051744048045248507898917802091914468336625", "price": "0.31", "size": "80", "side": "BUY", "hash": "d109c6dd070d3ed7e22c00e1a6d98d53c91ae4de", "best_bid": "0.33", "best_ask": "0.65"}, {"asset_id": "78125564118195609688130723464750437875510814435361379152154876368715602249491", "price": "0.69", "size": "80", "side": "SELL", "hash": "38221a75e872fa82b4c4507539560d3087fafc6c", "best_bid": "0.35", "best_ask": "0.67"}], "timestamp": "1769384875809", "event_type": "price_change"}}
{"_local_timestamp": "2026-01-25T23:47:56.425474+00:00", "data": {"market": "0x0b436d14d29b7f778768ffb123a526b4dc496054e26d820d691e9b59f2ae15bf", "price_changes": [{"asset_id": "18488621325714747371592358988913690051744048045248507898917802091914468336625", "price": "0.31", "size": "40", "side": "BUY", "hash": "a94dbe32a96b43671f9834a912f14962b6ac72fd", "best_bid": "0.33", "best_ask": "0.65"}, {"asset_id": "78125564118195609688130723464750437875510814435361379152154876368715602249491", "price": "0.69", "size": "40", "side": "SELL", "hash": "4c4eb9e8c4fe0d1d4cc94b6a5685d9a3561aeab5", "best_bid": "0.35", "best_ask": "0.67"}], "timestamp": "1769384876260", "event_type": "price_change"}}
{"_local_timestamp": "2026-01-25T23:47:57.231369+00:00", "data": {"market": "0x092c91d348e732e6e1d10cb85e855ae2982167cc8a514de6d5ce0ed6a81b3406", "price_changes": [{"asset_id": "106600613356134795904313062212730477275252691648870475628884876817519043940991", "price": "0.33", "size": "70", "side": "BUY", "hash": "637772929d3a2352f6de84ecc4675784c77770e9", "best_bid": "0.33", "best_ask": "0.36"}, {"asset_id": "63124470287776887476483587791259448657774659174144661407693923638503676979579", "price": "0.67", "size": "70", "side": "SELL", "hash": "25301d28af30d1effb09cfb2ddb1ddadaf5e4730", "best_bid": "0.64", "best_ask": "0.67"}], "timestamp": "1769384877008", "event_type": "price_change"}}
{"_local_timestamp": "2026-01-25T23:47:57.835634+00:00", "data": {"market": "0xe2dfc02908b8fb5e7c6578a42e17b52434f5346bb532ab5715dbbfd46af57a21", "price_changes": [{"asset_id": "3269263393231035282910557398978207346672294813068410578094427630928688366591", "price": "0.999", "size": "208", "side": "BUY", "hash": "6912cac2e8e866ee7bb07a66a487afb2da4a588a", "best_bid": "0.999", "best_ask": "1"}, {"asset_id": "79024099644769201382883588167557335172113039460336000034907727657308480799729", "price": "0.001", "size": "208", "side": "SELL", "hash": "a89334b9d749701d5ef81f112dd8953fc9038b26", "best_bid": "0", "best_ask": "0.001"}], "timestamp": "1769384877693", "event_type": "price_change"}}
{"_local_timestamp": "2026-01-25T23:48:00.890297+00:00", "data": {"market": "0x0b436d14d29b7f778768ffb123a526b4dc496054e26d820d691e9b59f2ae15bf", "price_changes": [{"asset_id": "18488621325714747371592358988913690051744048045248507898917802091914468336625", "price": "0.3", "size": "40", "side": "BUY", "hash": "330cb6a9da1ecd83d7a825fd1797bf908bdefef2", "best_bid": "0.33", "best_ask": "0.65"}, {"asset_id": "78125564118195609688130723464750437875510814435361379152154876368715602249491", "price": "0.7", "size": "40", "side": "SELL", "hash": "8d47e14c4f6330fbf0454a57b2dadfc099ecafe4", "best_bid": "0.35", "best_ask": "0.67"}], "timestamp": "1769384880738", "event_type": "price_change"}}
{"_local_timestamp": "2026-01-25T23:48:11.303033+00:00", "data": {"market": "0x092c91d348e732e6e1d10cb85e855ae2982167cc8a514de6d5ce0ed6a81b3406", "price_changes": [{"asset_id": "106600613356134795904313062212730477275252691648870475628884876817519043940991", "price": "0.33", "size": "80.91", "side": "BUY", "hash": "95a272b8550e2b401a45c5835332a818ebb0f154", "best_bid": "0.33", "best_ask": "0.36"}, {"asset_id": "63124470287776887476483587791259448657774659174144661407693923638503676979579", "price": "0.67", "size": "80.91", "side": "SELL", "hash": "268fdf709309248097c832e01aea969f1bd902bc", "best_bid": "0.64", "best_ask": "0.67"}], "timestamp": "1769384891079", "event_type": "price_change"}}
{"_local_timestamp": "2026-01-25T23:48:11.303683+00:00", "data": {"market": "0x092c91d348e732e6e1d10cb85e855ae2982167cc8a514de6d5ce0ed6a81b3406", "price_changes": [{"asset_id": "106600613356134795904313062212730477275252691648870475628884876817519043940991", "price": "0.33", "size": "91.82", "side": "BUY", "hash": "1237a61b870e1d985e6b5232489cc123294493fb", "best_bid": "0.33", "best_ask": "0.36"}, {"asset_id": "63124470287776887476483587791259448657774659174144661407693923638503676979579", "price": "0.67", "size": "91.82", "side": "SELL", "hash": "3bec19acba9ec4825911cc4d3a591700b88c2f82", "best_bid": "0.64", "best_ask": "0.67"}], "timestamp": "1769384891080", "event_type": "price_change"}}
{"_local_timestamp": "2026-01-25T23:48:11.304172+00:00", "data": {"market": "0x092c91d348e732e6e1d10cb85e855ae2982167cc8a514de6d5ce0ed6a81b3406", "price_changes": [{"asset_id": "106600613356134795904313062212730477275252691648870475628884876817519043940991", "price": "0.33", "size": "102.73", "side": "BUY", "hash": "67c209b2947c777ab3185489dac238e5e544e059", "best_bid": "0.33", "best_ask": "0.36"}, {"asset_id": "63124470287776887476483587791259448657774659174144661407693923638503676979579", "price": "0.67", "size": "102.73", "side": "SELL", "hash": "81298769e266405f1647667111e632fe79e994e7", "best_bid": "0.64", "best_ask": "0.67"}], "timestamp": "1769384891080", "event_type": "price_change"}}
{"_local_timestamp": "2026-01-25T23:48:11.304731+00:00", "data": {"market": "0x092c91d348e732e6e1d10cb85e855ae2982167cc8a514de6d5ce0ed6a81b3406", "price_changes": [{"asset_id": "106600613356134795904313062212730477275252691648870475628884876817519043940991", "price": "0.33", "size": "113.64", "side": "BUY", "hash": "e8771395e9b0df936600bbe4ca6eb6727c7c57fb", "best_bid": "0.33", "best_ask": "0.36"}, {"asset_id": "63124470287776887476483587791259448657774659174144661407693923638503676979579", "price": "0.67", "size": "113.64", "side": "SELL", "hash": "87b008db30b42e24b54eb49a7042b4dcf20e24f9", "best_bid": "0.64", "best_ask": "0.67"}], "timestamp": "1769384891081", "event_type": "price_change"}}
{"_local_timestamp": "2026-01-25T23:48:16.977467+00:00", "data": {"market": "0xe2dfc02908b8fb5e7c6578a42e17b52434f5346bb532ab5715dbbfd46af57a21", "price_changes": [{"asset_id": "3269263393231035282910557398978207346672294813068410578094427630928688366591", "price": "0.574", "size": "0", "side": "BUY", "hash": "1f138b8f72b2cf238154efd61de36e25200737d4", "best_bid": "0.999", "best_ask": "1"}, {"asset_id": "79024099644769201382883588167557335172113039460336000034907727657308480799729", "price": "0.426", "size": "0", "side": "SELL", "hash": "f9c7f0aa65b7c129ecd51d8c95313804845c797f", "best_bid": "0", "best_ask": "0.001"}], "timestamp": "1769384896727", "event_type": "price_change"}}
{"_local_timestamp": "2026-01-25T23:48:17.721934+00:00", "data": {"market": "0xe2dfc02908b8fb5e7c6578a42e17b52434f5346bb532ab5715dbbfd46af57a21", "price_changes": [{"asset_id": "3269263393231035282910557398978207346672294813068410578094427630928688366591", "price": "0.574", "size": "5", "side": "BUY", "hash": "f7e3c544bd04d27490b00b2312fbd9b43441a0ff", "best_bid": "0.999", "best_ask": "1"}, {"asset_id": "79024099644769201382883588167557335172113039460336000034907727657308480799729", "price": "0.426", "size": "5", "side": "SELL", "hash": "7c93d1df440013188f9b1195c71f9f70781dc414", "best_bid": "0", "best_ask": "0.001"}], "timestamp": "1769384897486", "event_type": "price_change"}}
{"_local_timestamp": "2026-01-25T23:48:18.964695+00:00", "data": {"market": "0xe2dfc02908b8fb5e7c6578a42e17b52434f5346bb532ab5715dbbfd46af57a21", "price_changes": [{"asset_id": "79024099644769201382883588167557335172113039460336000034907727657308480799729", "price": "0.791", "size": "1800", "side": "SELL", "hash": "5ba7680d9df7ca82a95b9786389d85f89f4068ad", "best_bid": "0", "best_ask": "0.001"}, {"asset_id": "3269263393231035282910557398978207346672294813068410578094427630928688366591", "price": "0.209", "size": "1800", "side": "BUY", "hash": "dec5c4e6b6e582d39b857ce1b29322f00d37dd1f", "best_bid": "0.999", "best_ask": "1"}], "timestamp": "1769384898699", "event_type": "price_change"}}
{"_local_timestamp": "2026-01-25T23:48:28.118009+00:00", "data": {"market": "0x092c91d348e732e6e1d10cb85e855ae2982167cc8a514de6d5ce0ed6a81b3406", "price_changes": [{"asset_id": "63124470287776887476483587791259448657774659174144661407693923638503676979579", "price": "0.18", "size": "0", "side": "BUY", "hash": "ab7074781bc7df7ec93cbc15712911f0f5c81ad4", "best_bid": "0.64", "best_ask": "0.67"}, {"asset_id": "106600613356134795904313062212730477275252691648870475628884876817519043940991", "price": "0.82", "size": "0", "side": "SELL", "hash": "f6bc3a92d4813d70da839f073e88b08545475f15", "best_bid": "0.33", "best_ask": "0.36"}], "timestamp": "1769384907874", "event_type": "price_change"}}
{"_local_timestamp": "2026-01-25T23:48:28.583229+00:00", "data": {"market": "0x092c91d348e732e6e1d10cb85e855ae2982167cc8a514de6d5ce0ed6a81b3406", "price_changes": [{"asset_id": "63124470287776887476483587791259448657774659174144661407693923638503676979579", "price": "0.18", "size": "6.04", "side": "BUY", "hash": "88af1de48579496f372768f4b75b4c11094b36ac", "best_bid": "0.64", "best_ask": "0.67"}, {"asset_id": "106600613356134795904313062212730477275252691648870475628884876817519043940991", "price": "0.82", "size": "6.04", "side": "SELL", "hash": "0160443c62286c0a0ab167fb302d0e1dcf881664", "best_bid": "0.33", "best_ask": "0.36"}], "timestamp": "1769384908352", "event_type": "price_change"}}
{"_local_timestamp": "2026-01-25T23:48:30.988716+00:00", "data": {"market": "0x0b436d14d29b7f778768ffb123a526b4dc496054e26d820d691e9b59f2ae15bf", "price_changes": [{"asset_id": "18488621325714747371592358988913690051744048045248507898917802091914468336625", "price": "0.27", "size": "50", "side": "BUY", "hash": "6ded0b9a76ce8eec3ac2208b252da0c10efab70e", "best_bid": "0.33", "best_ask": "0.65"}, {"asset_id": "78125564118195609688130723464750437875510814435361379152154876368715602249491", "price": "0.73", "size": "50", "side": "SELL", "hash": "0e06ff2499ae94598b4bdb0f4d7e753379425d2d", "best_bid": "0.35", "best_ask": "0.67"}], "timestamp": "1769384910736", "event_type": "price_change"}}
{"_local_timestamp": "2026-01-25T23:48:31.006717+00:00", "data": {"market": "0x0b436d14d29b7f778768ffb123a526b4dc496054e26d820d691e9b59f2ae15bf", "price_changes": [{"asset_id": "18488621325714747371592358988913690051744048045248507898917802091914468336625", "price": "0.3", "size": "140", "side": "BUY", "hash": "8d4464e1784c177a68214cceb1e7cab2e5c53789", "best_bid": "0.33", "best_ask": "0.65"}, {"asset_id": "78125564118195609688130723464750437875510814435361379152154876368715602249491", "price": "0.7", "size": "140", "side": "SELL", "hash": "b36a5a440af1f5e6fe167c94683df20acebde3a2", "best_bid": "0.35", "best_ask": "0.67"}], "timestamp": "1769384910762", "event_type": "price_change"}}
{"_local_timestamp": "2026-01-25T23:48:37.436572+00:00", "data": {"market": "0x0b436d14d29b7f778768ffb123a526b4dc496054e26d820d691e9b59f2ae15bf", "price_changes": [{"asset_id": "18488621325714747371592358988913690051744048045248507898917802091914468336625", "price": "0.3", "size": "40", "side": "BUY", "hash": "ba6a9ad6bcaa73d5cdef6b0091f8580f6fe7c897", "best_bid": "0.33", "best_ask": "0.65"}, {"asset_id": "78125564118195609688130723464750437875510814435361379152154876368715602249491", "price": "0.7", "size": "40", "side": "SELL", "hash": "e3ed9b1578609872fd8df6b2785b10ad0e1b6750", "best_bid": "0.35", "best_ask": "0.67"}], "timestamp": "1769384917185", "event_type": "price_change"}}
{"_local_timestamp": "2026-01-25T23:48:37.438894+00:00", "data": {"market": "0x0b436d14d29b7f778768ffb123a526b4dc496054e26d820d691e9b59f2ae15bf", "price_changes": [{"asset_id": "18488621325714747371592358988913690051744048045248507898917802091914468336625", "price": "0.3", "size": "0", "side": "BUY", "hash": "91b6639600ee52a07264303b55d81585321ebbc4", "best_bid": "0.33", "best_ask": "0.65"}, {"asset_id": "78125564118195609688130723464750437875510814435361379152154876368715602249491", "price": "0.7", "size": "0", "side": "SELL", "hash": "7fc9ed7289e0167d1de8890884bf5bacee043d03", "best_bid": "0.35", "best_ask": "0.67"}], "timestamp": "1769384917187", "event_type": "price_change"}}
{"_local_timestamp": "2026-01-25T23:48:40.344418+00:00", "data": {"market": "0xe2dfc02908b8fb5e7c6578a42e17b52434f5346bb532ab5715dbbfd46af57a21", "price_changes": [{"asset_id": "3269263393231035282910557398978207346672294813068410578094427630928688366591", "price": "0.574", "size": "0", "side": "BUY", "hash": "29df81e745679848fbd1aa6c5e8225f288195eb3", "best_bid": "0.999", "best_ask": "1"}, {"asset_id": "79024099644769201382883588167557335172113039460336000034907727657308480799729", "price": "0.426", "size": "0", "side": "SELL", "hash": "fdb4029f75a9efa3ab62301c4785a36238137954", "best_bid": "0", "best_ask": "0.001"}], "timestamp": "1769384920112", "event_type": "price_change"}}
{"_local_timestamp": "2026-01-25T23:48:40.964242+00:00", "data": {"market": "0x0b436d14d29b7f778768ffb123a526b4dc496054e26d820d691e9b59f2ae15bf", "price_changes": [{"asset_id": "18488621325714747371592358988913690051744048045248507898917802091914468336625", "price": "0.3", "size": "40", "side": "BUY", "hash": "17f1778466196a2afac39ef252abe8bb49bf4241", "best_bid": "0.33", "best_ask": "0.65"}, {"asset_id": "78125564118195609688130723464750437875510814435361379152154876368715602249491", "price": "0.7", "size": "40", "side": "SELL", "hash": "f6775cc4fcf3f8b142ce104e06cf92668ebfd531", "best_bid": "0.35", "best_ask": "0.67"}], "timestamp": "1769384920740", "event_type": "price_change"}}
{"_local_timestamp": "2026-01-25T23:48:40.964828+00:00", "data": {"market": "0x0b436d14d29b7f778768ffb123a526b4dc496054e26d820d691e9b59f2ae15bf", "price_changes": [{"asset_id": "18488621325714747371592358988913690051744048045248507898917802091914468336625", "price": "0.29", "size": "183.91", "side": "BUY", "hash": "fc5bbe0a639dab2a4e36fb24a648899d76f0ee78", "best_bid": "0.33", "best_ask": "0.65"}, {"asset_id": "78125564118195609688130723464750437875510814435361379152154876368715602249491", "price": "0.71", "size": "183.91", "side": "SELL", "hash": "ed506078fd172433c5e17125fb74df853fb3a536", "best_bid": "0.35", "best_ask": "0.67"}], "timestamp": "1769384920740", "event_type": "price_change"}}
{"_local_timestamp": "2026-01-25T23:48:41.104864+00:00", "data": {"market": "0xe2dfc02908b8fb5e7c6578a42e17b52434f5346bb532ab5715dbbfd46af57a21", "price_changes": [{"asset_id": "3269263393231035282910557398978207346672294813068410578094427630928688366591", "price": "0.574", "size": "5", "side": "BUY", "hash": "7d3d0e728cc597f96a0e8a7da03dd0dc89404276", "best_bid": "0.999", "best_ask": "1"}, {"asset_id": "79024099644769201382883588167557335172113039460336000034907727657308480799729", "price": "0.426", "size": "5", "side": "SELL", "hash": "3d8927a02513e91c2a4673db7bcbbcb1f0a89a9a", "best_bid": "0", "best_ask": "0.001"}], "timestamp": "1769384920869", "event_type": "price_change"}}
{"_local_timestamp": "2026-01-25T23:48:42.934053+00:00", "data": {"market": "0x0b436d14d29b7f778768ffb123a526b4dc496054e26d820d691e9b59f2ae15bf", "price_changes": [{"asset_id": "18488621325714747371592358988913690051744048045248507898917802091914468336625", "price": "0.29", "size": "83.91", "side": "BUY", "hash": "bbb843f9d7880c262867c29eb1614ef1c27c1dbc", "best_bid": "0.33", "best_ask": "0.65"}, {"asset_id": "78125564118195609688130723464750437875510814435361379152154876368715602249491", "price": "0.71", "size": "83.91", "side": "SELL", "hash": "71cf51f0440c4db9c999c4fbe50869d050290d96", "best_bid": "0.35", "best_ask": "0.67"}], "timestamp": "1769384922839", "event_type": "price_change"}}
{"_local_timestamp": "2026-01-25T23:48:43.331032+00:00", "data": {"market": "0x0b436d14d29b7f778768ffb123a526b4dc496054e26d820d691e9b59f2ae15bf", "price_changes": [{"asset_id": "18488621325714747371592358988913690051744048045248507898917802091914468336625", "price": "0.3", "size": "0", "side": "BUY", "hash": "3258f02e3ef6a2c8a49a635981bc8664a4c961e7", "best_bid": "0.33", "best_ask": "0.65"}, {"asset_id": "78125564118195609688130723464750437875510814435361379152154876368715602249491", "price": "0.7", "size": "0", "side": "SELL", "hash": "6e1d3d426c93c1061b738af4bbfc34b87367bf0f", "best_bid": "0.35", "best_ask": "0.67"}], "timestamp": "1769384923264", "event_type": "price_change"}}
{"_local_timestamp": "2026-01-25T23:48:43.331617+00:00", "data": {"market": "0x0b436d14d29b7f778768ffb123a526b4dc496054e26d820d691e9b59f2ae15bf", "price_changes": [{"asset_id": "18488621325714747371592358988913690051744048045248507898917802091914468336625", "price": "0.27", "size": "0", "side": "BUY", "hash": "803174c925a3c7b1558dfb9ee657ced3911d6b8f", "best_bid": "0.33", "best_ask": "0.65"}, {"asset_id": "78125564118195609688130723464750437875510814435361379152154876368715602249491", "price": "0.73", "size": "0", "side": "SELL", "hash": "2bc923cafd435445eaaaf0ca8b127b7748519a65", "best_bid": "0.35", "best_ask": "0.67"}], "timestamp": "1769384923265", "event_type": "price_change"}}
{"_local_timestamp": "2026-01-25T23:48:44.492823+00:00", "data": {"market": "0x0b436d14d29b7f778768ffb123a526b4dc496054e26d820d691e9b59f2ae15bf", "price_changes": [{"asset_id": "18488621325714747371592358988913690051744048045248507898917802091914468336625", "price": "0.28", "size": "60", "side": "BUY", "hash": "cd4bd75fdf3579930aaaa1a9e46ce5d5528fe0f7", "best_bid": "0.33", "best_ask": "0.65"}, {"asset_id": "78125564118195609688130723464750437875510814435361379152154876368715602249491", "price": "0.72", "size": "60", "side": "SELL", "hash": "cfe6d21c6895bd8309f7540456250815a99454be", "best_bid": "0.35", "best_ask": "0.67"}], "timestamp": "1769384924414", "event_type": "price_change"}}
{"_local_timestamp": "2026-01-25T23:48:44.512104+00:00", "data": {"market": "0x0b436d14d29b7f778768ffb123a526b4dc496054e26d820d691e9b59f2ae15bf", "price_changes": [{"asset_id": "18488621325714747371592358988913690051744048045248507898917802091914468336625", "price": "0.16", "size": "25.09", "side": "BUY", "hash": "976e8e3d48bc2569d57913a2be2afcb02ded8463", "best_bid": "0.33", "best_ask": "0.65"}, {"asset_id": "78125564118195609688130723464750437875510814435361379152154876368715602249491", "price": "0.84", "size": "25.09", "side": "SELL", "hash": "7e78c17b7713fcb9bef830d5c140095b201e6b55", "best_bid": "0.35", "best_ask": "0.67"}], "timestamp": "1769384924445", "event_type": "price_change"}}
{"_local_timestamp": "2026-01-25T23:48:45.881552+00:00", "data": {"market": "0x0b436d14d29b7f778768ffb123a526b4dc496054e26d820d691e9b59f2ae15bf", "price_changes": [{"asset_id": "18488621325714747371592358988913690051744048045248507898917802091914468336625", "price": "0.28", "size": "160", "side": "BUY", "hash": "6a3819ce62f561d0ecac9671f1555165625cd7f2", "best_bid": "0.33", "best_ask": "0.65"}, {"asset_id": "78125564118195609688130723464750437875510814435361379152154876368715602249491", "price": "0.72", "size": "160", "side": "SELL", "hash": "3bc701dc8aeb68c7f7a593a7587b6c1be4b4b0d9", "best_bid": "0.35", "best_ask": "0.67"}], "timestamp": "1769384925816", "event_type": "price_change"}}
{"_local_timestamp": "2026-01-25T23:48:45.886032+00:00", "data": {"market": "0x0b436d14d29b7f778768ffb123a526b4dc496054e26d820d691e9b59f2ae15bf", "price_changes": [{"asset_id": "18488621325714747371592358988913690051744048045248507898917802091914468336625", "price": "0.32", "size": "198", "side": "BUY", "hash": "ab46b66edf4a03bb2293eabac14111f6a46f29b9", "best_bid": "0.33", "best_ask": "0.65"}, {"asset_id": "78125564118195609688130723464750437875510814435361379152154876368715602249491", "price": "0.68", "size": "198", "side": "SELL", "hash": "31e1b330223a3465094d07209df526d815f1c0ec", "best_bid": "0.35", "best_ask": "0.67"}], "timestamp": "1769384925817", "event_type": "price_change"}}
{"_local_timestamp": "2026-01-25T23:48:45.886669+00:00", "data": {"market": "0x0b436d14d29b7f778768ffb123a526b4dc496054e26d820d691e9b59f2ae15bf", "price_changes": [{"asset_id": "18488621325714747371592358988913690051744048045248507898917802091914468336625", "price": "0.23", "size": "50", "side": "BUY", "hash": "b0294bd7a97588226e54a7e62bb309ceddce0590", "best_bid": "0.33", "best_ask": "0.65"}, {"asset_id": "78125564118195609688130723464750437875510814435361379152154876368715602249491", "price": "0.77", "size": "50", "side": "SELL", "hash": "63f7f5848bd3715d07644ff7f8c2b8289e410f4c", "best_bid": "0.35", "best_ask": "0.67"}], "timestamp": "1769384925818", "event_type": "price_change"}}
{"_local_timestamp": "2026-01-25T23:48:46.132198+00:00", "data": {"market": "0x0b436d14d29b7f778768ffb123a526b4dc496054e26d820d691e9b59f2ae15bf", "price_changes": [{"asset_id": "18488621325714747371592358988913690051744048045248507898917802091914468336625", "price": "0.28", "size": "60", "side": "BUY", "hash": "736e477b18e12628f8e9eaacb4a40346e28951ff", "best_bid": "0.33", "best_ask": "0.65"}, {"asset_id": "78125564118195609688130723464750437875510814435361379152154876368715602249491", "price": "0.72", "size": "60", "side": "SELL", "hash": "b587030f535d223da20d42bad7758bdb1a7882d0", "best_bid": "0.35", "best_ask": "0.67"}], "timestamp": "1769384926014", "event_type": "price_change"}}
{"_local_timestamp": "2026-01-25T23:48:46.225555+00:00", "data": {"market": "0x0b436d14d29b7f778768ffb123a526b4dc496054e26d820d691e9b59f2ae15bf", "price_changes": [{"asset_id": "18488621325714747371592358988913690051744048045248507898917802091914468336625", "price": "0.32", "size": "158", "side": "BUY", "hash": "45e8ff5de5ae27b967fc1de4fcebeeb9fcd28e3c", "best_bid": "0.33", "best_ask": "0.65"}, {"asset_id": "78125564118195609688130723464750437875510814435361379152154876368715602249491", "price": "0.68", "size": "158", "side": "SELL", "hash": "1be9e5c981aa4d53a3f83db852d18ae9abe971e4", "best_bid": "0.35", "best_ask": "0.67"}], "timestamp": "1769384926157", "event_type": "price_change"}}
{"_local_timestamp": "2026-01-25T23:48:47.163422+00:00", "data": {"market": "0x0b436d14d29b7f778768ffb123a526b4dc496054e26d820d691e9b59f2ae15bf", "price_changes": [{"asset_id": "18488621325714747371592358988913690051744048045248507898917802091914468336625", "price": "0.16", "size": "5.09", "side": "BUY", "hash": "1387e8f3c1ee3c87dbb7e3401be9f99f8a9b4180", "best_bid": "0.33", "best_ask": "0.65"}, {"asset_id": "78125564118195609688130723464750437875510814435361379152154876368715602249491", "price": "0.84", "size": "5.09", "side": "SELL", "hash": "f06b80fbba3183b3a905be345933ac8d71927ec8", "best_bid": "0.35", "best_ask": "0.67"}], "timestamp": "1769384927079", "event_type": "price_change"}}
{"_local_timestamp": "2026-01-25T23:48:47.185361+00:00", "data": {"market": "0x0b436d14d29b7f778768ffb123a526b4dc496054e26d820d691e9b59f2ae15bf", "price_changes": [{"asset_id": "18488621325714747371592358988913690051744048045248507898917802091914468336625", "price": "0.24", "size": "20", "side": "BUY", "hash": "62a375545ea365dd0ae7f2079e750e6d05fdf883", "best_bid": "0.33", "best_ask": "0.65"}, {"asset_id": "78125564118195609688130723464750437875510814435361379152154876368715602249491", "price": "0.76", "size": "20", "side": "SELL", "hash": "3c1608612c68fd3bb4a731036d6c815df2803f50", "best_bid": "0.35", "best_ask": "0.67"}], "timestamp": "1769384927102", "event_type": "price_change"}}
{"_local_timestamp": "2026-01-25T23:48:50.748538+00:00", "data": {"market": "0x0b436d14d29b7f778768ffb123a526b4dc496054e26d820d691e9b59f2ae15bf", "price_changes": [{"asset_id": "18488621325714747371592358988913690051744048045248507898917802091914468336625", "price": "0.23", "size": "0", "side": "BUY", "hash": "73e4e5a77cc4836d8987b617d5896bfa27c0f677", "best_bid": "0.33", "best_ask": "0.65"}, {"asset_id": "78125564118195609688130723464750437875510814435361379152154876368715602249491", "price": "0.77", "size": "0", "side": "SELL", "hash": "58dc6564d3c105ef4684818c8b02f182e3e8c909", "best_bid": "0.35", "best_ask": "0.67"}], "timestamp": "1769384930681", "event_type": "price_change"}}
{"_local_timestamp": "2026-01-25T23:48:50.778991+00:00", "data": {"market": "0x0b436d14d29b7f778768ffb123a526b4dc496054e26d820d691e9b59f2ae15bf", "price_changes": [{"asset_id": "18488621325714747371592358988913690051744048045248507898917802091914468336625", "price": "0.31", "size": "80", "side": "BUY", "hash": "4106d0dea1989fa7b617f3ec2c3877985dd427b3", "best_bid": "0.33", "best_ask": "0.65"}, {"asset_id": "78125564118195609688130723464750437875510814435361379152154876368715602249491", "price": "0.69", "size": "80", "side": "SELL", "hash": "e4d2055a526eafc2c31afedf00f16defd79808c3", "best_bid": "0.35", "best_ask": "0.67"}], "timestamp": "1769384930710", "event_type": "price_change"}}
{"_local_timestamp": "2026-01-25T23:48:50.783524+00:00", "data": {"market": "0x0b436d14d29b7f778768ffb123a526b4dc496054e26d820d691e9b59f2ae15bf", "price_changes": [{"asset_id": "18488621325714747371592358988913690051744048045248507898917802091914468336625", "price": "0.28", "size": "110", "side": "BUY", "hash": "1b7988602c6023f9361e106e1c7f9e011fbb555c", "best_bid": "0.33", "best_ask": "0.65"}, {"asset_id": "78125564118195609688130723464750437875510814435361379152154876368715602249491", "price": "0.72", "size": "110", "side": "SELL", "hash": "b714146e8aff58825b835f94fad4ec398a9175e1", "best_bid": "0.35", "best_ask": "0.67"}], "timestamp": "1769384930711", "event_type": "price_change"}}
{"_local_timestamp": "2026-01-25T23:48:50.784095+00:00", "data": {"market": "0x0b436d14d29b7f778768ffb123a526b4dc496054e26d820d691e9b59f2ae15bf", "price_changes": [{"asset_id": "18488621325714747371592358988913690051744048045248507898917802091914468336625", "price": "0.29", "size": "183.91", "side": "BUY", "hash": "dcc7430ba53e4586a25bcf509d8e402e8af2e05a", "best_bid": "0.33", "best_ask": "0.65"}, {"asset_id": "78125564118195609688130723464750437875510814435361379152154876368715602249491", "price": "0.71", "size": "183.91", "side": "SELL", "hash": "7a90076f9718c084022a2ef87992aab6bf6d1aa6", "best_bid": "0.35", "best_ask": "0.67"}], "timestamp": "1769384930711", "event_type": "price_change"}}
{"_local_timestamp": "2026-01-25T23:48:52.026070+00:00", "data": {"market": "0x0b436d14d29b7f778768ffb123a526b4dc496054e26d820d691e9b59f2ae15bf", "price_changes": [{"asset_id": "18488621325714747371592358988913690051744048045248507898917802091914468336625", "price": "0.24", "size": "0", "side": "BUY", "hash": "18ffe1a9d39b8d9e4a416db2ab5f7fa06f06a888", "best_bid": "0.33", "best_ask": "0.65"}, {"asset_id": "78125564118195609688130723464750437875510814435361379152154876368715602249491", "price": "0.76", "size": "0", "side": "SELL", "hash": "cc15745e3c74eed5872f6c47475b676e87637f7c", "best_bid": "0.35", "best_ask": "0.67"}], "timestamp": "1769384931953", "event_type": "price_change"}}
{"_local_timestamp": "2026-01-25T23:48:52.045969+00:00", "data": {"market": "0x0b436d14d29b7f778768ffb123a526b4dc496054e26d820d691e9b59f2ae15bf", "price_changes": [{"asset_id": "18488621325714747371592358988913690051744048045248507898917802091914468336625", "price": "0.16", "size": "25.09", "side": "BUY", "hash": "f4a9fdd0f42bc83406abd55b9dfcea64268a213c", "best_bid": "0.33", "best_ask": "0.65"}, {"asset_id": "78125564118195609688130723464750437875510814435361379152154876368715602249491", "price": "0.84", "size": "25.09", "side": "SELL", "hash": "5bba0dc6a94d57aeb207523dbe87eed31d1a38ea", "best_bid": "0.35", "best_ask": "0.67"}], "timestamp": "1769384931977", "event_type": "price_change"}}
{"_local_timestamp": "2026-01-25T23:48:57.545179+00:00", "data": {"market": "0x092c91d348e732e6e1d10cb85e855ae2982167cc8a514de6d5ce0ed6a81b3406", "price_changes": [{"asset_id": "106600613356134795904313062212730477275252691648870475628884876817519043940991", "price": "0.33", "size": "70", "side": "BUY", "hash": "42fa77e4d76ff5aa54eb9180d544e622ac5baa39", "best_bid": "0.33", "best_ask": "0.36"}, {"asset_id": "63124470287776887476483587791259448657774659174144661407693923638503676979579", "price": "0.67", "size": "70", "side": "SELL", "hash": "86755bde017d5eb9adf4e304b4fda100baf83846", "best_bid": "0.64", "best_ask": "0.67"}], "timestamp": "1769384937479", "event_type": "price_change"}}
{"_local_timestamp": "2026-01-25T23:48:58.313290+00:00", "data": {"market": "0x0b436d14d29b7f778768ffb123a526b4dc496054e26d820d691e9b59f2ae15bf", "price_changes": [{"asset_id": "18488621325714747371592358988913690051744048045248507898917802091914468336625", "price": "0.28", "size": "60", "side": "BUY", "hash": "263c602b16832f40935c8f4818cf8f156dcb3e9c", "best_bid": "0.33", "best_ask": "0.65"}, {"asset_id": "78125564118195609688130723464750437875510814435361379152154876368715602249491", "price": "0.72", "size": "60", "side": "SELL", "hash": "032698fa9b0b3ed9d925a8e5f0e4e1d8ee376395", "best_bid": "0.35", "best_ask": "0.67"}], "timestamp": "1769384938248", "event_type": "price_change"}}
{"_local_timestamp": "2026-01-25T23:48:58.853588+00:00", "data": {"market": "0x0b436d14d29b7f778768ffb123a526b4dc496054e26d820d691e9b59f2ae15bf", "price_changes": [{"asset_id": "18488621325714747371592358988913690051744048045248507898917802091914468336625", "price": "0.31", "size": "40", "side": "BUY", "hash": "196ea23821b64bb987f512b1d6dea10c916537dd", "best_bid": "0.33", "best_ask": "0.65"}, {"asset_id": "78125564118195609688130723464750437875510814435361379152154876368715602249491", "price": "0.69", "size": "40", "side": "SELL", "hash": "1239951231fff004be83aafd6a1765f28b72ee2d", "best_bid": "0.35", "best_ask": "0.67"}], "timestamp": "1769384938782", "event_type": "price_change"}}
{"_local_timestamp": "2026-01-25T23:48:58.854200+00:00", "data": {"market": "0x0b436d14d29b7f778768ffb123a526b4dc496054e26d820d691e9b59f2ae15bf", "price_changes": [{"asset_id": "18488621325714747371592358988913690051744048045248507898917802091914468336625", "price": "0.29", "size": "83.91", "side": "BUY", "hash": "d336750b231c8deaf75035728b60a6fcb22cf36a", "best_bid": "0.33", "best_ask": "0.65"}, {"asset_id": "78125564118195609688130723464750437875510814435361379152154876368715602249491", "price": "0.71", "size": "83.91", "side": "SELL", "hash": "1c70919281956c5eb1469dc7a32326e5d8a3f541", "best_bid": "0.35", "best_ask": "0.67"}], "timestamp": "1769384938787", "event_type": "price_change"}}
{"_local_timestamp": "2026-01-25T23:49:00.787042+00:00", "data": {"market": "0x0b436d14d29b7f778768ffb123a526b4dc496054e26d820d691e9b59f2ae15bf", "price_changes": [{"asset_id": "18488621325714747371592358988913690051744048045248507898917802091914468336625", "price": "0.26", "size": "50", "side": "BUY", "hash": "718676bf02c04b5149deaad928d176b9b762a3e5", "best_bid": "0.33", "best_ask": "0.65"}, {"asset_id": "78125564118195609688130723464750437875510814435361379152154876368715602249491", "price": "0.74", "size": "50", "side": "SELL", "hash": "0f8e8e075a736b1caa927b6375458bd29adc8878", "best_bid": "0.35", "best_ask": "0.67"}], "timestamp": "1769384940715", "event_type": "price_change"}}
{"_local_timestamp": "2026-01-25T23:49:00.787679+00:00", "data": {"market": "0x0b436d14d29b7f778768ffb123a526b4dc496054e26d820d691e9b59f2ae15bf", "price_changes": [{"asset_id": "18488621325714747371592358988913690051744048045248507898917802091914468336625", "price": "0.3", "size": "40", "side": "BUY", "hash": "b3d4675443e6fb1ff26218d13d449e2ad79fe1c3", "best_bid": "0.33", "best_ask": "0.65"}, {"asset_id": "78125564118195609688130723464750437875510814435361379152154876368715602249491", "price": "0.7", "size": "40", "side": "SELL", "hash": "02e214d8c04ba3d52d5104b502f1e233ac68d47f", "best_bid": "0.35", "best_ask": "0.67"}], "timestamp": "1769384940715", "event_type": "price_change"}}
{"_local_timestamp": "2026-01-25T23:49:00.821633+00:00", "data": {"market": "0x0b436d14d29b7f778768ffb123a526b4dc496054e26d820d691e9b59f2ae15bf", "price_changes": [{"asset_id": "18488621325714747371592358988913690051744048045248507898917802091914468336625", "price": "0.28", "size": "160", "side": "BUY", "hash": "51a070b56f2ec9504595399454bb045949195908", "best_bid": "0.33", "best_ask": "0.65"}, {"asset_id": "78125564118195609688130723464750437875510814435361379152154876368715602249491", "price": "0.72", "size": "160", "side": "SELL", "hash": "6b27e8d0c60a94871eff0b4a6eeafee496cf2098", "best_bid": "0.35", "best_ask": "0.67"}], "timestamp": "1769384940743", "event_type": "price_change"}}
{"_local_timestamp": "2026-01-25T23:49:01.741689+00:00", "data": {"market": "0x0b436d14d29b7f778768ffb123a526b4dc496054e26d820d691e9b59f2ae15bf", "price_changes": [{"asset_id": "18488621325714747371592358988913690051744048045248507898917802091914468336625", "price": "0.16", "size": "5.09", "side": "BUY", "hash": "fb2022c86026bacf8e705d3c2b5bb0b093016c80", "best_bid": "0.33", "best_ask": "0.65"}, {"asset_id": "78125564118195609688130723464750437875510814435361379152154876368715602249491", "price": "0.84", "size": "5.09", "side": "SELL", "hash": "8dd6e6d03fe41f9e8c10bd5625c32438f1e9baee", "best_bid": "0.35", "best_ask": "0.67"}], "timestamp": "1769384941671", "event_type": "price_change"}}
{"_local_timestamp": "2026-01-25T23:49:01.763996+00:00", "data": {"market": "0x0b436d14d29b7f778768ffb123a526b4dc496054e26d820d691e9b59f2ae15bf", "price_changes": [{"asset_id": "18488621325714747371592358988913690051744048045248507898917802091914468336625", "price": "0.27", "size": "20", "side": "BUY", "hash": "ee94b770d70a6d457e2401e3b8062d209015efbb", "best_bid": "0.33", "best_ask": "0.65"}, {"asset_id": "78125564118195609688130723464750437875510814435361379152154876368715602249491", "price": "0.73", "size": "20", "side": "SELL", "hash": "367994dfbf0437a8dbba7801a3ea6b926f0eb004", "best_bid": "0.35", "best_ask": "0.67"}], "timestamp": "1769384941697", "event_type": "price_change"}}
{"_local_timestamp": "2026-01-25T23:49:02.383633+00:00", "data": {"market": "0xe2dfc02908b8fb5e7c6578a42e17b52434f5346bb532ab5715dbbfd46af57a21", "price_changes": [{"asset_id": "3269263393231035282910557398978207346672294813068410578094427630928688366591", "price": "0.99", "size": "0", "side": "BUY", "hash": "b49334490fd0806c08a74261427c3c0a6007ed20", "best_bid": "0.999", "best_ask": "1"}, {"asset_id": "79024099644769201382883588167557335172113039460336000034907727657308480799729", "price": "0.01", "size": "0", "side": "SELL", "hash": "8debc7ead04cf6c9a8d1301b624de38686bee3d4", "best_bid": "0", "best_ask": "0.001"}], "timestamp": "1769384942313", "event_type": "price_change"}}
{"_local_timestamp": "2026-01-25T23:49:05.211061+00:00", "data": {"market": "0x092c91d348e732e6e1d10cb85e855ae2982167cc8a514de6d5ce0ed6a81b3406", "price_changes": [{"asset_id": "63124470287776887476483587791259448657774659174144661407693923638503676979579", "price": "0.68", "size": "100", "side": "SELL", "hash": "6fa93a4d87f1fd3befff77c1ed47ed9544f03480", "best_bid": "0.64", "best_ask": "0.67"}, {"asset_id": "106600613356134795904313062212730477275252691648870475628884876817519043940991", "price": "0.32", "size": "100", "side": "BUY", "hash": "37297c5db1663299d49a3b4b8d24d738cfb207ef", "best_bid": "0.33", "best_ask": "0.36"}], "timestamp": "1769384945143", "event_type": "price_change"}}
{"_local_timestamp": "2026-01-25T23:49:05.236257+00:00", "data": {"market": "0x0b436d14d29b7f778768ffb123a526b4dc496054e26d820d691e9b59f2ae15bf", "price_changes": [{"asset_id": "18488621325714747371592358988913690051744048045248507898917802091914468336625", "price": "0.31", "size": "0", "side": "BUY", "hash": "ff4fb47311882b4c485424e0c2f75ac8815b0d8a", "best_bid": "0.33", "best_ask": "0.65"}, {"asset_id": "78125564118195609688130723464750437875510814435361379152154876368715602249491", "price": "0.69", "size": "0", "side": "SELL", "hash": "389196704893ee1b3b05eb1b6e4cd077c071a41a", "best_bid": "0.35", "best_ask": "0.67"}], "timestamp": "1769384945167", "event_type": "price_change"}}
{"_local_timestamp": "2026-01-25T23:49:05.236811+00:00", "data": {"market": "0x0b436d14d29b7f778768ffb123a526b4dc496054e26d820d691e9b59f2ae15bf", "price_changes": [{"asset_id": "18488621325714747371592358988913690051744048045248507898917802091914468336625", "price": "0.28", "size": "100", "side": "BUY", "hash": "8fe76535956fe26be2ac2f9c8b89f17ab94b91f6", "best_bid": "0.33", "best_ask": "0.65"}, {"asset_id": "78125564118195609688130723464750437875510814435361379152154876368715602249491", "price": "0.72", "size": "100", "side": "SELL", "hash": "9bfc5bcbb58b699ce4e704ff3d4ce0e56da28f1e", "best_bid": "0.35", "best_ask": "0.67"}], "timestamp": "1769384945167", "event_type": "price_change"}}
{"_local_timestamp": "2026-01-25T23:49:05.447490+00:00", "data": {"market": "0x092c91d348e732e6e1d10cb85e855ae2982167cc8a514de6d5ce0ed6a81b3406", "price_changes": [{"asset_id": "63124470287776887476483587791259448657774659174144661407693923638503676979579", "price": "0.68", "size": "145", "side": "SELL", "hash": "67384670a1b97e469064cc4b890117627a7de1ca", "best_bid": "0.64", "best_ask": "0.67"}, {"asset_id": "106600613356134795904313062212730477275252691648870475628884876817519043940991", "price": "0.32", "size": "145", "side": "BUY", "hash": "2a0484ab53a6139f2a900f60fe146828c2977bfc", "best_bid": "0.33", "best_ask": "0.36"}], "timestamp": "1769384945369", "event_type": "price_change"}}
{"_local_timestamp": "2026-01-25T23:49:05.753694+00:00", "data": {"market": "0x0b436d14d29b7f778768ffb123a526b4dc496054e26d820d691e9b59f2ae15bf", "price_changes": [{"asset_id": "18488621325714747371592358988913690051744048045248507898917802091914468336625", "price": "0.31", "size": "40", "side": "BUY", "hash": "9999f4c0ce5f46ccc98a8e11767c24e3b2ea8aac", "best_bid": "0.33", "best_ask": "0.65"}, {"asset_id": "78125564118195609688130723464750437875510814435361379152154876368715602249491", "price": "0.69", "size": "40", "side": "SELL", "hash": "16c45e7d3a4b77cae8fc565292fba11b67cfe732", "best_bid": "0.35", "best_ask": "0.67"}], "timestamp": "1769384945683", "event_type": "price_change"}}
{"_local_timestamp": "2026-01-25T23:49:05.754335+00:00", "data": {"market": "0x0b436d14d29b7f778768ffb123a526b4dc496054e26d820d691e9b59f2ae15bf", "price_changes": [{"asset_id": "18488621325714747371592358988913690051744048045248507898917802091914468336625", "price": "0.28", "size": "160", "side": "BUY", "hash": "3a7cc465bf1abe095d8312208a2d0fd0e71549f4", "best_bid": "0.33", "best_ask": "0.65"}, {"asset_id": "78125564118195609688130723464750437875510814435361379152154876368715602249491", "price": "0.72", "size": "160", "side": "SELL", "hash": "3b8c3d10407aa96f917d1ebc7a6cee5590eac927", "best_bid": "0.35", "best_ask": "0.67"}], "timestamp": "1769384945684", "event_type": "price_change"}}
{"_local_timestamp": "2026-01-25T23:49:07.204644+00:00", "data": {"market": "0x0b436d14d29b7f778768ffb123a526b4dc496054e26d820d691e9b59f2ae15bf", "price_changes": [{"asset_id": "18488621325714747371592358988913690051744048045248507898917802091914468336625", "price": "0.3", "size": "0", "side": "BUY", "hash": "0c247fd6b96680ab87b63ca0699f9870a93c76ed", "best_bid": "0.33", "best_ask": "0.65"}, {"asset_id": "78125564118195609688130723464750437875510814435361379152154876368715602249491", "price": "0.7", "size": "0", "side": "SELL", "hash": "5cd49ea6251cc12b4f62420e6758f8b4ceea58ac", "best_bid": "0.35", "best_ask": "0.67"}], "timestamp": "1769384947142", "event_type": "price_change"}}
{"_local_timestamp": "2026-01-25T23:49:07.468122+00:00", "data": {"market": "0xe2dfc02908b8fb5e7c6578a42e17b52434f5346bb532ab5715dbbfd46af57a21", "price_changes": [{"asset_id": "3269263393231035282910557398978207346672294813068410578094427630928688366591", "price": "0.574", "size": "0", "side": "BUY", "hash": "1fd722360fc65130260086e6c522508ed2019c2a", "best_bid": "0.999", "best_ask": "1"}, {"asset_id": "79024099644769201382883588167557335172113039460336000034907727657308480799729", "price": "0.426", "size": "0", "side": "SELL", "hash": "4070665accda2d3db7688b6e1c8712daa6df8a6f", "best_bid": "0", "best_ask": "0.001"}], "timestamp": "1769384947399", "event_type": "price_change"}}
{"_local_timestamp": "2026-01-25T23:49:07.942388+00:00", "data": {"market": "0xe2dfc02908b8fb5e7c6578a42e17b52434f5346bb532ab5715dbbfd46af57a21", "price_changes": [{"asset_id": "3269263393231035282910557398978207346672294813068410578094427630928688366591", "price": "0.574", "size": "5", "side": "BUY", "hash": "e3b01f213a53c084b27e36add167912484cc6ab8", "best_bid": "0.999", "best_ask": "1"}, {"asset_id": "79024099644769201382883588167557335172113039460336000034907727657308480799729", "price": "0.426", "size": "5", "side": "SELL", "hash": "c7a70490446932cef2969f5e5dc57ed161bd3666", "best_bid": "0", "best_ask": "0.001"}], "timestamp": "1769384947878", "event_type": "price_change"}}
{"_local_timestamp": "2026-01-25T23:49:09.371154+00:00", "data": {"market": "0x0b436d14d29b7f778768ffb123a526b4dc496054e26d820d691e9b59f2ae15bf", "price_changes": [{"asset_id": "18488621325714747371592358988913690051744048045248507898917802091914468336625", "price": "0.26", "size": "0", "side": "BUY", "hash": "534b74601822a279740daad88170f568279a649c", "best_bid": "0.33", "best_ask": "0.65"}, {"asset_id": "78125564118195609688130723464750437875510814435361379152154876368715602249491", "price": "0.74", "size": "0", "side": "SELL", "hash": "24f905230288b500247237862c402f34b08354de", "best_bid": "0.35", "best_ask": "0.67"}], "timestamp": "1769384949305", "event_type": "price_change"}}
{"_local_timestamp": "2026-01-25T23:49:09.689058+00:00", "data": {"market": "0x0b436d14d29b7f778768ffb123a526b4dc496054e26d820d691e9b59f2ae15bf", "price_changes": [{"asset_id": "18488621325714747371592358988913690051744048045248507898917802091914468336625", "price": "0.27", "size": "0", "side": "BUY", "hash": "4c2839d811a7f9b4316ad89e6ecf503ca7531cc9", "best_bid": "0.33", "best_ask": "0.65"}, {"asset_id": "78125564118195609688130723464750437875510814435361379152154876368715602249491", "price": "0.73", "size": "0", "side": "SELL", "hash": "abe8bde65574fc5f9fb4b2c2a7e5a06779b9eace", "best_bid": "0.35", "best_ask": "0.67"}], "timestamp": "1769384949597", "event_type": "price_change"}}
{"_local_timestamp": "2026-01-25T23:49:09.712978+00:00", "data": {"market": "0x0b436d14d29b7f778768ffb123a526b4dc496054e26d820d691e9b59f2ae15bf", "price_changes": [{"asset_id": "18488621325714747371592358988913690051744048045248507898917802091914468336625", "price": "0.16", "size": "25.09", "side": "BUY", "hash": "5e5c851c27502847878472e2947f45cc3e2e6b5f", "best_bid": "0.33", "best_ask": "0.65"}, {"asset_id": "78125564118195609688130723464750437875510814435361379152154876368715602249491", "price": "0.84", "size": "25.09", "side": "SELL", "hash": "b20c1800e6f9636b6107cbc5486413cf3b0c3d47", "best_bid": "0.35", "best_ask": "0.67"}], "timestamp": "1769384949628", "event_type": "price_change"}}
{"_local_timestamp": "2026-01-25T23:49:09.983264+00:00", "data": {"market": "0xe2dfc02908b8fb5e7c6578a42e17b52434f5346bb532ab5715dbbfd46af57a21", "price_changes": [{"asset_id": "3269263393231035282910557398978207346672294813068410578094427630928688366591", "price": "0.212", "size": "2640", "side": "BUY", "hash": "3e9a11dcb827d793bb9803f8770dade33d02cc57", "best_bid": "0.999", "best_ask": "1"}, {"asset_id": "79024099644769201382883588167557335172113039460336000034907727657308480799729", "price": "0.788", "size": "2640", "side": "SELL", "hash": "47b93990c01361cf842e8c1fe7b6ea0a17035b90", "best_bid": "0", "best_ask": "0.001"}], "timestamp": "1769384949917", "event_type": "price_change"}}
{"_local_timestamp": "2026-01-25T23:49:10.793425+00:00", "data": {"market": "0x0b436d14d29b7f778768ffb123a526b4dc496054e26d820d691e9b59f2ae15bf", "price_changes": [{"asset_id": "18488621325714747371592358988913690051744048045248507898917802091914468336625", "price": "0.29", "size": "123.91", "side": "BUY", "hash": "0302c20209bb3513433c74eb12d07cecd9f922e9", "best_bid": "0.33", "best_ask": "0.65"}, {"asset_id": "78125564118195609688130723464750437875510814435361379152154876368715602249491", "price": "0.71", "size": "123.91", "side": "SELL", "hash": "bbce23306d77e324de67de487a4d5852808eef3f", "best_bid": "0.35", "best_ask": "0.67"}], "timestamp": "1769384950728", "event_type": "price_change"}}
{"_local_timestamp": "2026-01-25T23:49:10.794019+00:00", "data": {"market": "0x0b436d14d29b7f778768ffb123a526b4dc496054e26d820d691e9b59f2ae15bf", "price_changes": [{"asset_id": "18488621325714747371592358988913690051744048045248507898917802091914468336625", "price": "0.25", "size": "50", "side": "BUY", "hash": "7e5d5db5ea561032212037a22f0e31b29bbd7b6b", "best_bid": "0.33", "best_ask": "0.65"}, {"asset_id": "78125564118195609688130723464750437875510814435361379152154876368715602249491", "price": "0.75", "size": "50", "side": "SELL", "hash": "2087101a5898739edd76f308a77b7867807995d7", "best_bid": "0.35", "best_ask": "0.67"}], "timestamp": "1769384950729", "event_type": "price_change"}}
{"_local_timestamp": "2026-01-25T23:49:10.886519+00:00", "data": {"market": "0x0b436d14d29b7f778768ffb123a526b4dc496054e26d820d691e9b59f2ae15bf", "price_changes": [{"asset_id": "18488621325714747371592358988913690051744048045248507898917802091914468336625", "price": "0.28", "size": "60", "side": "BUY", "hash": "5d50b8d9ec0eb534d203d23335586d2b5debb5be", "best_bid": "0.33", "best_ask": "0.65"}, {"asset_id": "78125564118195609688130723464750437875510814435361379152154876368715602249491", "price": "0.72", "size": "60", "side": "SELL", "hash": "e5d945fb429c776440d6d5797a07bf3e5f8bc30e", "best_bid": "0.35", "best_ask": "0.67"}], "timestamp": "1769384950821", "event_type": "price_change"}}
{"_local_timestamp": "2026-01-25T23:49:11.449563+00:00", "data": {"market": "0x0b436d14d29b7f778768ffb123a526b4dc496054e26d820d691e9b59f2ae15bf", "price_changes": [{"asset_id": "18488621325714747371592358988913690051744048045248507898917802091914468336625", "price": "0.16", "size": "5.09", "side": "BUY", "hash": "5f8de128ed6bc9f7d27c5cf69367b44247244375", "best_bid": "0.33", "best_ask": "0.65"}, {"asset_id": "78125564118195609688130723464750437875510814435361379152154876368715602249491", "price": "0.84", "size": "5.09", "side": "SELL", "hash": "8e41ce49f2497f1dfe34450e52db69b09770c9f4", "best_bid": "0.35", "best_ask": "0.67"}], "timestamp": "1769384951355", "event_type": "price_change"}}
{"_local_timestamp": "2026-01-25T23:49:11.450135+00:00", "data": {"market": "0x0b436d14d29b7f778768ffb123a526b4dc496054e26d820d691e9b59f2ae15bf", "price_changes": [{"asset_id": "18488621325714747371592358988913690051744048045248507898917802091914468336625", "price": "0.26", "size": "20", "side": "BUY", "hash": "13dcc7bdd2c8388fccb2180799220601934a8bae", "best_bid": "0.33", "best_ask": "0.65"}, {"asset_id": "78125564118195609688130723464750437875510814435361379152154876368715602249491", "price": "0.74", "size": "20", "side": "SELL", "hash": "29de2fb59b89f78aed02e760708d12df41ab8439", "best_bid": "0.35", "best_ask": "0.67"}], "timestamp": "1769384951378", "event_type": "price_change"}}
{"_local_timestamp": "2026-01-25T23:49:11.642786+00:00", "data": {"market": "0x092c91d348e732e6e1d10cb85e855ae2982167cc8a514de6d5ce0ed6a81b3406", "price_changes": [{"asset_id": "106600613356134795904313062212730477275252691648870475628884876817519043940991", "price": "0.33", "size": "80.91", "side": "BUY", "hash": "5a590812cad18c56ec4a13f1cd4b70b6ffa66389", "best_bid": "0.33", "best_ask": "0.36"}, {"asset_id": "63124470287776887476483587791259448657774659174144661407693923638503676979579", "price": "0.67", "size": "80.91", "side": "SELL", "hash": "60eac7062f9b47f3190f70c92a7601e9e7a1ad1b", "best_bid": "0.64", "best_ask": "0.67"}], "timestamp": "1769384951570", "event_type": "price_change"}}
{"_local_timestamp": "2026-01-25T23:49:11.648151+00:00", "data": {"market": "0x092c91d348e732e6e1d10cb85e855ae2982167cc8a514de6d5ce0ed6a81b3406", "price_changes": [{"asset_id": "106600613356134795904313062212730477275252691648870475628884876817519043940991", "price": "0.33", "size": "91.82", "side": "BUY", "hash": "162d1dc1014722d1530d00940c286b573631e1dc", "best_bid": "0.33", "best_ask": "0.36"}, {"asset_id": "63124470287776887476483587791259448657774659174144661407693923638503676979579", "price": "0.67", "size": "91.82", "side": "SELL", "hash": "93afa562b4181d446be64428711bfc26b7c8b101", "best_bid": "0.64", "best_ask": "0.67"}], "timestamp": "1769384951571", "event_type": "price_change"}}
{"_local_timestamp": "2026-01-25T23:49:11.648723+00:00", "data": {"market": "0x092c91d348e732e6e1d10cb85e855ae2982167cc8a514de6d5ce0ed6a81b3406", "price_changes": [{"asset_id": "106600613356134795904313062212730477275252691648870475628884876817519043940991", "price": "0.33", "size": "102.73", "side": "BUY", "hash": "e225148d07f94422f4ea2504065dbef0738cc68a", "best_bid": "0.33", "best_ask": "0.36"}, {"asset_id": "63124470287776887476483587791259448657774659174144661407693923638503676979579", "price": "0.67", "size": "102.73", "side": "SELL", "hash": "7fcf2af328611011d6c09841f4e1f3f642b54cc0", "best_bid": "0.64", "best_ask": "0.67"}], "timestamp": "1769384951571", "event_type": "price_change"}}
{"_local_timestamp": "2026-01-25T23:49:11.649214+00:00", "data": {"market": "0x092c91d348e732e6e1d10cb85e855ae2982167cc8a514de6d5ce0ed6a81b3406", "price_changes": [{"asset_id": "106600613356134795904313062212730477275252691648870475628884876817519043940991", "price": "0.33", "size": "113.64", "side": "BUY", "hash": "19700fcf4bcb8ab354ad8ba18194a1a3bcec092f", "best_bid": "0.33", "best_ask": "0.36"}, {"asset_id": "63124470287776887476483587791259448657774659174144661407693923638503676979579", "price": "0.67", "size": "113.64", "side": "SELL", "hash": "07372f6033dbe557bfa53fabd1ab47d6d2bcdd66", "best_bid": "0.64", "best_ask": "0.67"}], "timestamp": "1769384951572", "event_type": "price_change"}}
{"_local_timestamp": "2026-01-25T23:49:12.036129+00:00", "data": {"market": "0xe2dfc02908b8fb5e7c6578a42e17b52434f5346bb532ab5715dbbfd46af57a21", "price_changes": [{"asset_id": "3269263393231035282910557398978207346672294813068410578094427630928688366591", "price": "0.841", "size": "144", "side": "BUY", "hash": "3a6059d173289e4123972b93650d3e2639e6ce09", "best_bid": "0.999", "best_ask": "1"}, {"asset_id": "79024099644769201382883588167557335172113039460336000034907727657308480799729", "price": "0.159", "size": "144", "side": "SELL", "hash": "5d685918908b0e021e08b78c51885596b3411616", "best_bid": "0", "best_ask": "0.001"}], "timestamp": "1769384951926", "event_type": "price_change"}}
{"_local_timestamp": "2026-01-25T23:49:12.785323+00:00", "data": {"market": "0x0b436d14d29b7f778768ffb123a526b4dc496054e26d820d691e9b59f2ae15bf", "price_changes": [{"asset_id": "78125564118195609688130723464750437875510814435361379152154876368715602249491", "price": "0.06", "size": "300", "side": "BUY", "hash": "85f8c0eaca83861518d6d0a9bcb548d4d62b4979", "best_bid": "0.35", "best_ask": "0.67"}, {"asset_id": "18488621325714747371592358988913690051744048045248507898917802091914468336625", "price": "0.94", "size": "300", "side": "SELL", "hash": "d7f783872765dc540a9ba46afac4eed933a3fcbf", "best_bid": "0.33", "best_ask": "0.65"}], "timestamp": "1769384952720", "event_type": "price_change"}}
{"_local_timestamp": "2026-01-25T23:49:13.591021+00:00", "data": {"market": "0x0b436d14d29b7f778768ffb123a526b4dc496054e26d820d691e9b59f2ae15bf", "price_changes": [{"asset_id": "78125564118195609688130723464750437875510814435361379152154876368715602249491", "price": "0.07", "size": "6.87", "side": "BUY", "hash": "f6cbfd2cf642b24dc1e0885213ad945469eba464", "best_bid": "0.35", "best_ask": "0.67"}, {"asset_id": "18488621325714747371592358988913690051744048045248507898917802091914468336625", "price": "0.93", "size": "6.87", "side": "SELL", "hash": "ddd1013d53df587c7a99d5c6cd02eaca751a7e1a", "best_bid": "0.33", "best_ask": "0.65"}], "timestamp": "1769384953513", "event_type": "price_change"}}
{"_local_timestamp": "2026-01-25T23:49:13.675821+00:00", "data": {"market": "0xe2dfc02908b8fb5e7c6578a42e17b52434f5346bb532ab5715dbbfd46af57a21", "price_changes": [{"asset_id": "3269263393231035282910557398978207346672294813068410578094427630928688366591", "price": "0.208", "size": "0", "side": "BUY", "hash": "b2e46595322f8c16fd2f75565eebd14f9666a340", "best_bid": "0.999", "best_ask": "1"}, {"asset_id": "79024099644769201382883588167557335172113039460336000034907727657308480799729", "price": "0.792", "size": "0", "side": "SELL", "hash": "37dd38d4d09d3c004475cf126978e809e24feb03", "best_bid": "0", "best_ask": "0.001"}], "timestamp": "1769384953604", "event_type": "price_change"}}
{"_local_timestamp": "2026-01-25T23:49:14.710254+00:00", "data": {"market": "0xe2dfc02908b8fb5e7c6578a42e17b52434f5346bb532ab5715dbbfd46af57a21", "price_changes": [{"asset_id": "3269263393231035282910557398978207346672294813068410578094427630928688366591", "price": "0.991", "size": "500", "side": "BUY", "hash": "1226f4e721beae9fb6f4d5935e59471032f8bb9b", "best_bid": "0.999", "best_ask": "1"}, {"asset_id": "79024099644769201382883588167557335172113039460336000034907727657308480799729", "price": "0.009", "size": "500", "side": "SELL", "hash": "707fffcca16746bb02c004354bf3bfbffb270bfc", "best_bid": "0", "best_ask": "0.001"}], "timestamp": "1769384954645", "event_type": "price_change"}}
{"_local_timestamp": "2026-01-25T23:49:15.787630+00:00", "data": {"market": "0x0b436d14d29b7f778768ffb123a526b4dc496054e26d820d691e9b59f2ae15bf", "price_changes": [{"asset_id": "18488621325714747371592358988913690051744048045248507898917802091914468336625", "price": "0.26", "size": "120", "side": "BUY", "hash": "0888964a72e65263a643b89b6be352e89922eead", "best_bid": "0.33", "best_ask": "0.65"}, {"asset_id": "78125564118195609688130723464750437875510814435361379152154876368715602249491", "price": "0.74", "size": "120", "side": "SELL", "hash": "567369951f73be8cdf3ffa3e0b87e10631c6124d", "best_bid": "0.35", "best_ask": "0.67"}], "timestamp": "1769384955717", "event_type": "price_change"}}
{"_local_timestamp": "2026-01-25T23:49:16.166864+00:00", "data": {"market": "0x0b436d14d29b7f778768ffb123a526b4dc496054e26d820d691e9b59f2ae15bf", "price_changes": [{"asset_id": "18488621325714747371592358988913690051744048045248507898917802091914468336625", "price": "0.26", "size": "100", "side": "BUY", "hash": "06ee0784ec4ea4367bc18c6d798ce741f668138a", "best_bid": "0.33", "best_ask": "0.65"}, {"asset_id": "78125564118195609688130723464750437875510814435361379152154876368715602249491", "price": "0.74", "size": "100", "side": "SELL", "hash": "2be84794d85c9d1867a0ebf7ab66b247ca8cf214", "best_bid": "0.35", "best_ask": "0.67"}], "timestamp": "1769384956083", "event_type": "price_change"}}
{"_local_timestamp": "2026-01-25T23:49:16.180188+00:00", "data": {"market": "0x0b436d14d29b7f778768ffb123a526b4dc496054e26d820d691e9b59f2ae15bf", "price_changes": [{"asset_id": "18488621325714747371592358988913690051744048045248507898917802091914468336625", "price": "0.27", "size": "20", "side": "BUY", "hash": "e842c8da022f1ae4a18a765a1f07467ddcdddf55", "best_bid": "0.33", "best_ask": "0.65"}, {"asset_id": "78125564118195609688130723464750437875510814435361379152154876368715602249491", "price": "0.73", "size": "20", "side": "SELL", "hash": "2581da4d391062d894cff1358ef4538308152084", "best_bid": "0.35", "best_ask": "0.67"}], "timestamp": "1769384956111", "event_type": "price_change"}}
{"_local_timestamp": "2026-01-25T23:49:20.940568+00:00", "data": {"market": "0xe2dfc02908b8fb5e7c6578a42e17b52434f5346bb532ab5715dbbfd46af57a21", "price_changes": [{"asset_id": "3269263393231035282910557398978207346672294813068410578094427630928688366591", "price": "0.999", "size": "0", "side": "BUY", "hash": "cf7fc4be102027a066a5b83ef5434328442215b1", "best_bid": "0.991", "best_ask": "1"}, {"asset_id": "79024099644769201382883588167557335172113039460336000034907727657308480799729", "price": "0.001", "size": "0", "side": "SELL", "hash": "1e6b60e8b319a7d522a6a4d629ee3db32f1bcb10", "best_bid": "0", "best_ask": "0.009"}], "timestamp": "1769384960834", "event_type": "price_change"}}
{"_local_timestamp": "2026-01-25T23:49:34.333818+00:00", "data": {"market": "0xe2dfc02908b8fb5e7c6578a42e17b52434f5346bb532ab5715dbbfd46af57a21", "price_changes": [{"asset_id": "3269263393231035282910557398978207346672294813068410578094427630928688366591", "price": "0.574", "size": "0", "side": "BUY", "hash": "1055be006aa51bccc661486b3db07e8e2a6aaf3c", "best_bid": "0.991", "best_ask": "1"}, {"asset_id": "79024099644769201382883588167557335172113039460336000034907727657308480799729", "price": "0.426", "size": "0", "side": "SELL", "hash": "82efcc1746ab2b65a4c9a0253784535b6dee9fe5", "best_bid": "0", "best_ask": "0.009"}], "timestamp": "1769384974265", "event_type": "price_change"}}
