{"_local_timestamp": "2026-01-25T23:41:19.885876+00:00", "data": [{"market": "0xad0784334a1443a3203e6940c717718d1b96ef666ffd68f5b5dc1f7c6215dd4b", "asset_id": "50710439625838530440232612154448392211388175978405785956032457226185816417967", "timestamp": "1769384027186", "hash": "1e885969311dcab9942467c6891a8474add57284", "bids": [{"price": "0.01", "size": "2691.46"}, {"price": "0.02", "size": "250"}, {"price": "0.03", "size": "10.39"}, {"price": "0.05", "size": "100"}, {"price": "0.06", "size": "33"}, {"price": "0.08", "size": "450"}, {"price": "0.09", "size": "5.49"}, {"price": "0.12", "size": "283.33"}, {"price": "0.16", "size": "200"}, {"price": "0.2", "size": "140"}, {"price": "0.21", "size": "5.14"}, {"price": "0.24", "size": "108.33"}, {"price": "0.28", "size": "85.71"}, {"price": "0.29", "size": "42"}, {"price": "0.32", "size": "62.5"}, {"price": "0.45", "size": "70"}, {"price": "0.46", "size": "16"}, {"price": "0.47", "size": "25"}, {"price": "0.55", "size": "5"}, {"price": "0.6", "size": "11.8"}, {"price": "0.61", "size": "12.03"}, {"price": "0.78", "size": "0.9"}, {"price": "0.79", "size": "26"}], "asks": [{"price": "0.99", "size": "187.98"}, {"price": "0.98", "size": "100"}, {"price": "0.97", "size": "5500"}, {"price": "0.96", "size": "479.05"}, {"price": "0.95", "size": "21.64"}], "event_type": "book", "last_trade_price": "0.050"}, {"market": "0xb173baab75adc686608fa70d2825ffe64e58980d5aa81359f4593d42131c6a8a", "asset_id": "87893908705321757372452753993024042073787859909760312398837104466511141920544", "timestamp": "1769384002161", "hash": "c31e60cd1509610c28eb46fc0eeb84a1bcf2f915", "bids": [{"price": "0.01", "size": "310"}, {"price": "0.02", "size": "4000"}, {"price": "0.03", "size": "250"}], "asks": [{"price": "0.99", "size": "2691.43"}, {"price": "0.98", "size": "250"}, {"price": "0.97", "size": "7.06"}, {"price": "0.95", "size": "100"}, {"price": "0.94", "size": "33"}, {"price": "0.93", "size": "7.95"}, {"price": "0.9", "size": "360"}, {"price": "0.85", "size": "226.66"}, {"price": "0.81", "size": "168.42"}, {"price": "0.8", "size": "5.58"}, {"price": "0.76", "size": "116.66"}, {"price": "0.71", "size": "89.65"}, {"price": "0.66", "size": "70.58"}, {"price": "0.65", "size": "53"}, {"price": "0.61", "size": "51.28"}, {"price": "0.54", "size": "70"}, {"price": "0.53", "size": "17.09"}, {"price": "0.51", "size": "50"}, {"price": "0.5", "size": "25"}, {"price": "0.19", "size": "6"}, {"price": "0.13", "size": "11.78"}], "event_type": "book", "last_trade_price": "0.050"}, {"market": "0xbd46a9a86d53f1c6ed88d2ec2d6b7fa25f312a2330224a50b055fed30b6f487c", "asset_id": "103549663553180106742188583785378823515789409688357997461583563558502280722246", "timestamp": "1769384423684", "hash": "ec3a2b2cce5c00428bfdecb9b9426e7073fab13e", "bids": [{"price": "0.01", "size": "2691.66"}, {"price": "0.02", "size": "250"}, {"price": "0.03", "size": "10.54"}, {"price": "0.05", "size": "100"}, {"price": "0.06", "size": "33"}, {"price": "0.08", "size": "450"}, {"price": "0.09", "size": "5.2"}, {"price": "0.12", "size": "283.33"}, {"price": "0.16", "size": "200"}, {"price": "0.19", "size": "147.36"}, {"price": "0.2", "size": "5.49"}, {"price": "0.23", "size": "113.04"}, {"price": "0.27", "size": "88.88"}, {"price": "0.28", "size": "44"}, {"price": "0.31", "size": "64.51"}, {"price": "0.32", "size": "6"}, {"price": "0.45", "size": "70"}, {"price": "0.46", "size": "20"}, {"price": "0.58", "size": "13.69"}, {"price": "0.6", "size": "18.33"}, {"price": "0.73", "size": "42.58"}], "asks": [{"price": "0.99", "size": "230"}, {"price": "0.98", "size": "100"}, {"price": "0.97", "size": "55"}, {"price": "0.96", "size": "137.5"}, {"price": "0.95", "size": "20"}, {"price": "0.94", "size": "6.31"}], "event_type": "book", "last_trade_price": "0.270"}, {"market": "0xbfd944007d7204b05e19d6fdf2cbe5f3e0b8d37bfb19c15d8e1c813e8ec2dec5", "asset_id": "75413567795086771542191436050004337965652039236856821284921766890217813492508", "timestamp": "1769384479263", "hash": "51cecf2514d824ad3b142bf937e1b85b5b79fa44", "bids": [{"price": "0.01", "size": "2685.85"}, {"price": "0.02", "size": "255.63"}, {"price": "0.03", "size": "40"}, {"price": "0.04", "size": "6.45"}, {"price": "0.05", "size": "100"}, {"price": "0.06", "size": "33"}, {"price": "0.08", "size": "450"}, {"price": "0.09", "size": "5.15"}, {"price": "0.11", "size": "309.09"}, {"price": "0.15", "size": "213.33"}, {"price": "0.19", "size": "147.36"}, {"price": "0.2", "size": "5.53"}, {"price": "0.23", "size": "113.04"}, {"price": "0.26", "size": "92.3"}, {"price": "0.3", "size": "66.66"}, {"price": "0.31", "size": "33"}, {"price": "0.32", "size": "6"}, {"price": "0.47", "size": "70"}, {"price": "0.48", "size": "20"}, {"price": "0.51", "size": "20"}, {"price": "0.69", "size": "40"}, {"price": "0.71", "size": "10"}, {"price": "0.75", "size": "50"}], "asks": [{"price": "0.99", "size": "230"}, {"price": "0.98", "size": "215"}, {"price": "0.95", "size": "40.93"}], "event_type": "book", "last_trade_price": "0.120"}, {"market": "0xb173baab75adc686608fa70d2825ffe64e58980d5aa81359f4593d42131c6a8a", "asset_id": "74944121521778523284044841371348063504904671735441125873074013853973325630918", "timestamp": "1769384002161", "hash": "b29dfa1b7456e8917d5ca71c2b6050ab1a54079f", "bids": [{"price": "0.01", "size": "2691.43"}, {"price": "0.02", "size": "250"}, {"price": "0.03", "size": "7.06"}, {"price": "0.05", "size": "100"}, {"price": "0.06", "size": "33"}, {"price": "0.07", "size": "7.95"}, {"price": "0.1", "size": "360"}, {"price": "0.15", "size": "226.66"}, {"price": "0.19", "size": "168.42"}, {"price": "0.2", "size": "5.58"}, {"price": "0.24", "size": "116.66"}, {"price": "0.29", "size": "89.65"}, {"price": "0.34", "size": "70.58"}, {"price": "0.35", "size": "53"}, {"price": "0.39", "size": "51.28"}, {"price": "0.46", "size": "70"}, {"price": "0.47", "size": "17.09"}, {"price": "0.49", "size": "50"}, {"price": "0.5", "size": "25"}, {"price": "0.81", "size": "6"}, {"price": "0.87", "size": "11.78"}], "asks": [{"price": "0.99", "size": "310"}, {"price": "0.98", "size": "4000"}, {"price": "0.97", "size": "250"}], "event_type": "book", "last_trade_price": "0.050"}, {"market": "0xbd46a9a86d53f1c6ed88d2ec2d6b7fa25f312a2330224a50b055fed30b6f487c", "asset_id": "103642153283858206072910718526021885682012582207057190439694348950566724371976", "timestamp": "1769384423684", "hash": "8a6ed90707162d817d1a1630adcb9ed0c8df7303", "bids": [{"price": "0.01", "size": "230"}, {"price": "0.02", "size": "100"}, {"price": "0.03", "size": "55"}, {"price": "0.04", "size": "137.5"}, {"price": "0.05", "size": "20"}, {"price": "0.06", "size": "6.31"}], "asks": [{"price": "0.99", "size": "2691.66"}, {"price": "0.98", "size": "250"}, {"price": "0.97", "size": "10.54"}, {"price": "0.95", "size": "100"}, {"price": "0.94", "size": "33"}, {"price": "0.92", "size": "450"}, {"price": "0.91", "size": "5.2"}, {"price": "0.88", "size": "283.33"}, {"price": "0.84", "size": "200"}, {"price": "0.81", "size": "147.36"}, {"price": "0.8", "size": "5.49"}, {"price": "0.77", "size": "113.04"}, {"price": "0.73", "size": "88.88"}, {"price": "0.72", "size": "44"}, {"price": "0.69", "size": "64.51"}, {"price": "0.68", "size": "6"}, {"price": "0.55", "size": "70"}, {"price": "0.54", "size": "20"}, {"price": "0.42", "size": "13.69"}, {"price": "0.4", "size": "18.33"}, {"price": "0.27", "size": "42.58"}], "event_type": "book", "last_trade_price": "0.270"}, {"market": "0x97b4a74e6ad96c4601a70bffea6b3ea48227b0676658f1a77c5e4dfeb03c1422", "asset_id": "67088219062664412623221891896187729302515136551189145648713076701295675541006", "timestamp": "1769384283448", "hash": "6c9d204f1406494d9a092f2a249aa30d35494c9c", "bids": [{"price": "0.01", "size": "229.69"}, {"price": "0.02", "size": "163.64"}, {"price": "0.03", "size": "34"}, {"price": "0.04", "size": "250"}, {"price": "0.05", "size": "20"}], "asks": [{"price": "0.99", "size": "695.44"}, {"price": "0.98", "size": "250"}, {"price": "0.97", "size": "18.31"}, {"price": "0.95", "size": "100"}, {"price": "0.94", "size": "33"}, {"price": "0.92", "size": "14"}, {"price": "0.91", "size": "22"}, {"price": "0.9", "size": "12.96"}, {"price": "0.57", "size": "70"}, {"price": "0.48", "size": "87.89"}], "event_type": "book", "last_trade_price": "0.060"}, {"market": "0x27441dae2a80c3c8c6eaddeb4e12857618e36c209479704ebc416c5e9bcdf48b", "asset_id": "20942804418898366041360868834735971328710307350569283381969854921720954083179", "timestamp": "1769384026067", "hash": "aefcfc6d13ed85ec4a783d4f121247740df99ea7", "bids": [{"price": "0.01", "size": "693.8"}, {"price": "0.02", "size": "250"}, {"price": "0.03", "size": "8.52"}, {"price": "0.05", "size": "20"}, {"price": "0.06", "size": "10"}, {"price": "0.07", "size": "28"}, {"price": "0.08", "size": "20.07"}, {"price": "0.25", "size": "70"}, {"price": "0.26", "size": "20"}, {"price": "0.35", "size": "37.14"}, {"price": "0.42", "size": "19.24"}, {"price": "0.49", "size": "36.25"}], "asks": [{"price": "0.99", "size": "185.97"}, {"price": "0.97", "size": "100"}, {"price": "0.96", "size": "55.65"}, {"price": "0.95", "size": "20"}, {"price": "0.91", "size": "12"}, {"price": "0.86", "size": "8"}, {"price": "0.85", "size": "6.87"}, {"price": "0.79", "size": "10"}, {"price": "0.77", "size": "56.52"}, {"price": "0.75", "size": "44"}, {"price": "0.74", "size": "16.94"}], "event_type": "book", "last_trade_price": "0.600"}, {"market": "0x27441dae2a80c3c8c6eaddeb4e12857618e36c209479704ebc416c5e9bcdf48b", "asset_id": "63317147287133286781047610956697981288778237042668675686742554461630558935769", "timestamp": "1769384026067", "hash": "3a5458562143f8b90cabf2060d701de9d31f7961", "bids": [{"price": "0.01", "size": "185.97"}, {"price": "0.03", "size": "100"}, {"price": "0.04", "size": "55.65"}, {"price": "0.05", "size": "20"}, {"price": "0.09", "size": "12"}, {"price": "0.14", "size": "8"}, {"price": "0.15", "size": "6.87"}, {"price": "0.21", "size": "10"}, {"price": "0.23", "size": "56.52"}, {"price": "0.25", "size": "44"}, {"price": "0.26", "size": "16.94"}], "asks": [{"price": "0.99", "size": "693.8"}, {"price": "0.98", "size": "250"}, {"price": "0.97", "size": "8.52"}, {"price": "0.95", "size": "20"}, {"price": "0.94", "size": "10"}, {"price": "0.93", "size": "28"}, {"price": "0.92", "size": "20.07"}, {"price": "0.75", "size": "70"}, {"price": "0.74", "size": "20"}, {"price": "0.65", "size": "37.14"}, {"price": "0.58", "size": "19.24"}, {"price": "0.51", "size": "36.25"}], "event_type": "book", "last_trade_price": "0.600"}, {"market": "0xbfd944007d7204b05e19d6fdf2cbe5f3e0b8d37bfb19c15d8e1c813e8ec2dec5", "asset_id": "67189754674778985353824371461876088774339766303744275466510582338820578610808", "timestamp": "1769384479263", "hash": "26d6666303ce4e86e380381cd53550324940489b", "bids": [{"price": "0.01", "size": "230"}, {"price": "0.02", "size": "215"}, {"price": "0.05", "size": "40.93"}], "asks": [{"price": "0.99", "size": "2685.85"}, {"price": "0.98", "size": "255.63"}, {"price": "0.97", "size": "40"}, {"price": "0.96", "size": "6.45"}, {"price": "0.95", "size": "100"}, {"price": "0.94", "size": "33"}, {"price": "0.92", "size": "450"}, {"price": "0.91", "size": "5.15"}, {"price": "0.89", "size": "309.09"}, {"price": "0.85", "size": "213.33"}, {"price": "0.81", "size": "147.36"}, {"price": "0.8", "size": "5.53"}, {"price": "0.77", "size": "113.04"}, {"price": "0.74", "size": "92.3"}, {"price": "0.7", "size": "66.66"}, {"price": "0.69", "size": "33"}, {"price": "0.68", "size": "6"}, {"price": "0.53", "size": "70"}, {"price": "0.52", "size": "20"}, {"price": "0.49", "size": "20"}, {"price": "0.31", "size": "40"}, {"price": "0.29", "size": "10"}, {"price": "0.25", "size": "50"}], "event_type": "book", "last_trade_price": "0.120"}, {"market": "0x97b4a74e6ad96c4601a70bffea6b3ea48227b0676658f1a77c5e4dfeb03c1422", "asset_id": "74328021459889543390175687510268557967371044615256517664604837321395650238724", "timestamp": "1769384283448", "hash": "864511245381f784b26ab8299cc55d1e24364858", "bids": [{"price": "0.01", "size": "695.44"}, {"price": "0.02", "size": "250"}, {"price": "0.03", "size": "18.31"}, {"price": "0.05", "size": "100"}, {"price": "0.06", "size": "33"}, {"price": "0.08", "size": "14"}, {"price": "0.09", "size": "22"}, {"price": "0.1", "size": "12.96"}, {"price": "0.43", "size": "70"}, {"price": "0.52", "size": "87.89"}], "asks": [{"price": "0.99", "size": "229.69"}, {"price": "0.98", "size": "163.64"}, {"price": "0.97", "size": "34"}, {"price": "0.96", "size": "250"}, {"price": "0.95", "size": "20"}], "event_type": "book", "last_trade_price": "0.060"}, {"market": "0xed993e502937b8f06d86b6a2635366cf71ac179d6baf5095746c7bf29ad8641f", "asset_id": "68135793646196945235030919877614400184995079439290824250423103677950217046359", "timestamp": "1769383438652", "hash": "70c51c7a9d67ef208b12ac8a320328a882b43057", "bids": [{"price": "0.01", "size": "2692.21"}, {"price": "0.02", "size": "250"}, {"price": "0.03", "size": "9.31"}, {"price": "0.05", "size": "100"}, {"price": "0.06", "size": "33"}, {"price": "0.07", "size": "514.28"}, {"price": "0.08", "size": "6.28"}, {"price": "0.11", "size": "309.09"}, {"price": "0.14", "size": "228.57"}, {"price": "0.18", "size": "155.55"}, {"price": "0.19", "size": "5.76"}, {"price": "0.21", "size": "123.8"}, {"price": "0.25", "size": "96"}, {"price": "0.28", "size": "71.42"}, {"price": "0.29", "size": "35"}, {"price": "0.38", "size": "70"}, {"price": "0.41", "size": "31.7"}, {"price": "0.42", "size": "20"}, {"price": "0.43", "size": "5"}, {"price": "0.53", "size": "20.75"}, {"price": "0.59", "size": "1.69"}, {"price": "0.65", "size": "50"}], "asks": [{"price": "0.99", "size": "380"}, {"price": "0.98", "size": "14.28"}, {"price": "0.95", "size": "320"}, {"price": "0.94", "size": "216.66"}, {"price": "0.93", "size": "99.77"}, {"price": "0.92", "size": "108.25"}, {"price": "0.87", "size": "75.1"}, {"price": "0.86", "size": "0.45"}], "event_type": "book", "last_trade_price": "0.140"}, {"market": "0xad0784334a1443a3203e6940c717718d1b96ef666ffd68f5b5dc1f7c6215dd4b", "asset_id": "100883661802120918650919670304317942093957399672393308790719879423528989246012", "timestamp": "1769384027186", "hash": "0d21b0a7f138d45dacc9e29bbd7aba79f848cc83", "bids": [{"price": "0.01", "size": "187.98"}, {"price": "0.02", "size": "100"}, {"price": "0.03", "size": "5500"}, {"price": "0.04", "size": "479.05"}, {"price": "0.05", "size": "21.64"}], "asks": [{"price": "0.99", "size": "2691.46"}, {"price": "0.98", "size": "250"}, {"price": "0.97", "size": "10.39"}, {"price": "0.95", "size": "100"}, {"price": "0.94", "size": "33"}, {"price": "0.92", "size": "450"}, {"price": "0.91", "size": "5.49"}, {"price": "0.88", "size": "283.33"}, {"price": "0.84", "size": "200"}, {"price": "0.8", "size": "140"}, {"price": "0.79", "size": "5.14"}, {"price": "0.76", "size": "108.33"}, {"price": "0.72", "size": "85.71"}, {"price": "0.71", "size": "42"}, {"price": "0.68", "size": "62.5"}, {"price": "0.55", "size": "70"}, {"price": "0.54", "size": "16"}, {"price": "0.53", "size": "25"}, {"price": "0.45", "size": "5"}, {"price": "0.4", "size": "11.8"}, {"price": "0.39", "size": "12.03"}, {"price": "0.22", "size": "0.9"}, {"price": "0.21", "size": "26"}], "event_type": "book", "last_trade_price": "0.050"}, {"market": "0xed993e502937b8f06d86b6a2635366cf71ac179d6baf5095746c7bf29ad8641f", "asset_id": "26881842239842804813300039730139457907422060630292563945602138057659136428072", "timestamp": "1769383438652", "hash": "663feb723f0e284399107594e99a10a1ecacf1bf", "bids": [{"price": "0.01", "size": "380"}, {"price": "0.02", "size": "14.28"}, {"price": "0.05", "size": "320"}, {"price": "0.06", "size": "216.66"}, {"price": "0.07", "size": "99.77"}, {"price": "0.08", "size": "108.25"}, {"price": "0.13", "size": "75.1"}, {"price": "0.14", "size": "0.45"}], "asks": [{"price": "0.99", "size": "2692.21"}, {"price": "0.98", "size": "250"}, {"price": "0.97", "size": "9.31"}, {"price": "0.95", "size": "100"}, {"price": "0.94", "size": "33"}, {"price": "0.93", "size": "514.28"}, {"price": "0.92", "size": "6.28"}, {"price": "0.89", "size": "309.09"}, {"price": "0.86", "size": "228.57"}, {"price": "0.82", "size": "155.55"}, {"price": "0.81", "size": "5.76"}, {"price": "0.79", "size": "123.8"}, {"price": "0.75", "size": "96"}, {"price": "0.72", "size": "71.42"}, {"price": "0.71", "size": "35"}, {"price": "0.62", "size": "70"}, {"price": "0.59", "size": "31.7"}, {"price": "0.58", "size": "20"}, {"price": "0.57", "size": "5"}, {"price": "0.47", "size": "20.75"}, {"price": "0.41", "size": "1.69"}, {"price": "0.35", "size": "50"}], "event_type": "book", "last_trade_price": "0.140"}]}
{"_local_timestamp": "2026-01-25T23:41:23.069610+00:00", "data": {"market": "0xbfd944007d7204b05e19d6fdf2cbe5f3e0b8d37bfb19c15d8e1c813e8ec2dec5", "price_changes": [{"asset_id": "75413567795086771542191436050004337965652039236856821284921766890217813492508", "price": "0.51", "size": "0", "side": "BUY", "hash": "68a4341bd4a83b5c6ad3e642ebd2fd85f309788d", "best_bid": "0.75", "best_ask": "0.95"}, {"asset_id": "67189754674778985353824371461876088774339766303744275466510582338820578610808", "price": "0.49", "size": "0", "side": "SELL", "hash": "92ea1014021dcbea1147c9cda297558b1d7c89f1", "best_bid": "0.05", "best_ask": "0.25"}], "timestamp": "1769384482957", "event_type": "price_change"}}
{"_local_timestamp": "2026-01-25T23:41:23.093853+00:00", "data": {"market": "0xbfd944007d7204b05e19d6fdf2cbe5f3e0b8d37bfb19c15d8e1c813e8ec2dec5", "price_changes": [{"asset_id": "75413567795086771542191436050004337965652039236856821284921766890217813492508", "price": "0.49", "size": "20", "side": "BUY", "hash": "bc62cecf22d207cbbe39621496ab51d8c772fdfd", "best_bid": "0.75", "best_ask": "0.95"}, {"asset_id": "67189754674778985353824371461876088774339766303744275466510582338820578610808", "price": "0.51", "size": "20", "side": "SELL", "hash": "ffdf2f3695bed7b7cae576bda50afa262ea923e4", "best_bid": "0.05", "best_ask": "0.25"}], "timestamp": "1769384482981", "event_type": "price_change"}}
{"_local_timestamp": "2026-01-25T23:41:23.226359+00:00", "data": {"market": "0xbfd944007d7204b05e19d6fdf2cbe5f3e0b8d37bfb19c15d8e1c813e8ec2dec5", "price_changes": [{"asset_id": "75413567795086771542191436050004337965652039236856821284921766890217813492508", "price": "0.5", "size": "25", "side": "BUY", "hash": "be11dfdc8d12c7117cfbd5af682c414f6b8b527a", "best_bid": "0.75", "best_ask": "0.95"}, {"asset_id": "67189754674778985353824371461876088774339766303744275466510582338820578610808", "price": "0.5", "size": "25", "side": "SELL", "hash": "eeece8f36ca37481c95a08fa947a30c5d3f23df3", "best_bid": "0.05", "best_ask": "0.25"}], "timestamp": "1769384483110", "event_type": "price_change"}}
{"_local_timestamp": "2026-01-25T23:41:23.228956+00:00", "data": {"market": "0xbfd944007d7204b05e19d6fdf2cbe5f3e0b8d37bfb19c15d8e1c813e8ec2dec5", "price_changes": [{"asset_id": "75413567795086771542191436050004337965652039236856821284921766890217813492508", "price": "0.5", "size": "50", "side": "BUY", "hash": "85c9ca71f8dfe917d6fa5b7e99b7facb9b99d6df", "best_bid": "0.75", "best_ask": "0.95"}, {"asset_id": "67189754674778985353824371461876088774339766303744275466510582338820578610808", "price": "0.5", "size": "50", "side": "SELL", "hash": "914ed4984b79f88ce91efa5d6537f4e4f78cf86a", "best_bid": "0.05", "best_ask": "0.25"}], "timestamp": "1769384483112", "event_type": "price_change"}}
{"_local_timestamp": "2026-01-25T23:41:26.361344+00:00", "data": {"market": "0xbfd944007d7204b05e19d6fdf2cbe5f3e0b8d37bfb19c15d8e1c813e8ec2dec5", "price_changes": [{"asset_id": "75413567795086771542191436050004337965652039236856821284921766890217813492508", "price": "0.49", "size": "0", "side": "BUY", "hash": "d5259cea18d6e8b7c98bdd9453f0fa462f8caa8c", "best_bid": "0.75", "best_ask": "0.95"}, {"asset_id": "67189754674778985353824371461876088774339766303744275466510582338820578610808", "price": "0.51", "size": "0", "side": "SELL", "hash": "d5a12a9d0b6339952efeebc228a1898bd7e75f5d", "best_bid": "0.05", "best_ask": "0.25"}], "timestamp": "1769384486245", "event_type": "price_change"}}
{"_local_timestamp": "2026-01-25T23:41:26.376881+00:00", "data": {"market": "0xbfd944007d7204b05e19d6fdf2cbe5f3e0b8d37bfb19c15d8e1c813e8ec2dec5", "price_changes": [{"asset_id": "75413567795086771542191436050004337965652039236856821284921766890217813492508", "price": "0.51", "size": "20", "side": "BUY", "hash": "25ab56ecfadbf78622da706474fc350e85643bea", "best_bid": "0.75", "best_ask": "0.95"}, {"asset_id": "67189754674778985353824371461876088774339766303744275466510582338820578610808", "price": "0.49", "size": "20", "side": "SELL", "hash": "315fc71fcb11c8d6c35be416f4bb2710a2de383a", "best_bid": "0.05", "best_ask": "0.25"}], "timestamp": "1769384486270", "event_type": "price_change"}}
{"_local_timestamp": "2026-01-25T23:41:26.541510+00:00", "data": {"market": "0xbfd944007d7204b05e19d6fdf2cbe5f3e0b8d37bfb19c15d8e1c813e8ec2dec5", "price_changes": [{"asset_id": "75413567795086771542191436050004337965652039236856821284921766890217813492508", "price": "0.5", "size": "25", "side": "BUY", "hash": "7564c9c74068c586f5a5b73ce98419459154158a", "best_bid": "0.75", "best_ask": "0.95"}, {"asset_id": "67189754674778985353824371461876088774339766303744275466510582338820578610808", "price": "0.5", "size": "25", "side": "SELL", "hash": "3d11727910e7f77bff8fe0137792afb9615e2160", "best_bid": "0.05", "best_ask": "0.25"}], "timestamp": "1769384486421", "event_type": "price_change"}}
{"_local_timestamp": "2026-01-25T23:41:26.574990+00:00", "data": {"market": "0xbfd944007d7204b05e19d6fdf2cbe5f3e0b8d37bfb19c15d8e1c813e8ec2dec5", "price_changes": [{"asset_id": "75413567795086771542191436050004337965652039236856821284921766890217813492508", "price": "0.5", "size": "0", "side": "BUY", "hash": "1bd3526b3062c0448375b399c3a8af226d5c8241", "best_bid": "0.75", "best_ask": "0.95"}, {"asset_id": "67189754674778985353824371461876088774339766303744275466510582338820578610808", "price": "0.5", "size": "0", "side": "SELL", "hash": "8e8c941904db82e7c880070a920e8e962c86bba0", "best_bid": "0.05", "best_ask": "0.25"}], "timestamp": "1769384486449", "event_type": "price_change"}}
{"_local_timestamp": "2026-01-25T23:41:28.759740+00:00", "data": {"market": "0xbfd944007d7204b05e19d6fdf2cbe5f3e0b8d37bfb19c15d8e1c813e8ec2dec5", "price_changes": [{"asset_id": "75413567795086771542191436050004337965652039236856821284921766890217813492508", "price": "0.51", "size": "0", "side": "BUY", "hash": "0f7ec08f458ae9cd961b4ae6d8d019c38d392521", "best_bid": "0.75", "best_ask": "0.95"}, {"asset_id": "67189754674778985353824371461876088774339766303744275466510582338820578610808", "price": "0.49", "size": "0", "side": "SELL", "hash": "4f56097b4bf2489546549c5669a139709b64e7ab", "best_bid": "0.05", "best_ask": "0.25"}], "timestamp": "1769384488651", "event_type": "price_change"}}
{"_local_timestamp": "2026-01-25T23:41:28.789474+00:00", "data": {"market": "0xbfd944007d7204b05e19d6fdf2cbe5f3e0b8d37bfb19c15d8e1c813e8ec2dec5", "price_changes": [{"asset_id": "75413567795086771542191436050004337965652039236856821284921766890217813492508", "price": "0.49", "size": "20", "side": "BUY", "hash": "f8f1563f704ddc6487028be3d8f0000a559d80cf", "best_bid": "0.75", "best_ask": "0.95"}, {"asset_id": "67189754674778985353824371461876088774339766303744275466510582338820578610808", "price": "0.51", "size": "20", "side": "SELL", "hash": "e6c78f87064dd35343b60b72ec678463e35601ba", "best_bid": "0.05", "best_ask": "0.25"}], "timestamp": "1769384488681", "event_type": "price_change"}}
{"_local_timestamp": "2026-01-25T23:41:28.896411+00:00", "data": {"market": "0xbfd944007d7204b05e19d6fdf2cbe5f3e0b8d37bfb19c15d8e1c813e8ec2dec5", "price_changes": [{"asset_id": "75413567795086771542191436050004337965652039236856821284921766890217813492508", "price": "0.5", "size": "25", "side": "BUY", "hash": "cadf34d752ee9ff53bb3a6182328646e20b74c88", "best_bid": "0.75", "best_ask": "0.95"}, {"asset_id": "67189754674778985353824371461876088774339766303744275466510582338820578610808", "price": "0.5", "size": "25", "side": "SELL", "hash": "9a84ce9ef011723acb21ad028a60e97905c64c1c", "best_bid": "0.05", "best_ask": "0.25"}], "timestamp": "1769384488796", "event_type": "price_change"}}
{"_local_timestamp": "2026-01-25T23:41:28.912895+00:00", "data": {"market": "0xbfd944007d7204b05e19d6fdf2cbe5f3e0b8d37bfb19c15d8e1c813e8ec2dec5", "price_changes": [{"asset_id": "75413567795086771542191436050004337965652039236856821284921766890217813492508", "price": "0.5", "size": "50", "side": "BUY", "hash": "cdf254b2e3308a8bca2018a67509d2506b38c976", "best_bid": "0.75", "best_ask": "0.95"}, {"asset_id": "67189754674778985353824371461876088774339766303744275466510582338820578610808", "price": "0.5", "size": "50", "side": "SELL", "hash": "67ca3a0a35b600668cc891f4fbe184ad5a111244", "best_bid": "0.05", "best_ask": "0.25"}], "timestamp": "1769384488809", "event_type": "price_change"}}
{"_local_timestamp": "2026-01-25T23:41:30.017565+00:00", "data": {"market": "0xbfd944007d7204b05e19d6fdf2cbe5f3e0b8d37bfb19c15d8e1c813e8ec2dec5", "price_changes": [{"asset_id": "75413567795086771542191436050004337965652039236856821284921766890217813492508", "price": "0.49", "size": "0", "side": "BUY", "hash": "09d56baf009e85899f07b1146733c65b6c5ab6f8", "best_bid": "0.75", "best_ask": "0.95"}, {"asset_id": "67189754674778985353824371461876088774339766303744275466510582338820578610808", "price": "0.51", "size": "0", "side": "SELL", "hash": "e18d479e019084e1e6d04d5b85b34896264ad085", "best_bid": "0.05", "best_ask": "0.25"}], "timestamp": "1769384489890", "event_type": "price_change"}}
{"_local_timestamp": "2026-01-25T23:41:30.042883+00:00", "data": {"market": "0xbfd944007d7204b05e19d6fdf2cbe5f3e0b8d37bfb19c15d8e1c813e8ec2dec5", "price_changes": [{"asset_id": "75413567795086771542191436050004337965652039236856821284921766890217813492508", "price": "0.51", "size": "20", "side": "BUY", "hash": "be3b1d31d086acaf132b89a16a746f4f879ba25e", "best_bid": "0.75", "best_ask": "0.95"}, {"asset_id": "67189754674778985353824371461876088774339766303744275466510582338820578610808", "price": "0.49", "size": "20", "side": "SELL", "hash": "8d008d6a8ee099aba46e380e08c1d66a47d0715f", "best_bid": "0.05", "best_ask": "0.25"}], "timestamp": "1769384489916", "event_type": "price_change"}}
{"_local_timestamp": "2026-01-25T23:41:30.158774+00:00", "data": {"market": "0xbfd944007d7204b05e19d6fdf2cbe5f3e0b8d37bfb19c15d8e1c813e8ec2dec5", "price_changes": [{"asset_id": "75413567795086771542191436050004337965652039236856821284921766890217813492508", "price": "0.5", "size": "25", "side": "BUY", "hash": "a3c6c1ebbf79ad26be8487e1716acdd0486a032c", "best_bid": "0.75", "best_ask": "0.95"}, {"asset_id": "67189754674778985353824371461876088774339766303744275466510582338820578610808", "price": "0.5", "size": "25", "side": "SELL", "hash": "c5d6e452777530dbbd5fdcd5e773b91eaff8ffd2", "best_bid": "0.05", "best_ask": "0.25"}], "timestamp": "1769384490021", "event_type": "price_change"}}
{"_local_timestamp": "2026-01-25T23:41:30.160182+00:00", "data": {"market": "0xbfd944007d7204b05e19d6fdf2cbe5f3e0b8d37bfb19c15d8e1c813e8ec2dec5", "price_changes": [{"asset_id": "75413567795086771542191436050004337965652039236856821284921766890217813492508", "price": "0.5", "size": "0", "side": "BUY", "hash": "304ed807b2104685f834ee6c0d0fde950830ce73", "best_bid": "0.75", "best_ask": "0.95"}, {"asset_id": "67189754674778985353824371461876088774339766303744275466510582338820578610808", "price": "0.5", "size": "0", "side": "SELL", "hash": "ad25c01282e64c15e8867e46dc0aafd68c958b71", "best_bid": "0.05", "best_ask": "0.25"}], "timestamp": "1769384490022", "event_type": "price_change"}}
{"_local_timestamp": "2026-01-25T23:41:31.146513+00:00", "data": {"market": "0xbfd944007d7204b05e19d6fdf2cbe5f3e0b8d37bfb19c15d8e1c813e8ec2dec5", "price_changes": [{"asset_id": "75413567795086771542191436050004337965652039236856821284921766890217813492508", "price": "0.51", "size": "0", "side": "BUY", "hash": "14fc6d4a24a61f9689e60500a0cc3338142dbbd3", "best_bid": "0.75", "best_ask": "0.95"}, {"asset_id": "67189754674778985353824371461876088774339766303744275466510582338820578610808", "price": "0.49", "size": "0", "side": "SELL", "hash": "1d75c8b12a020369ded74fe32835218f6bf9d6dd", "best_bid": "0.05", "best_ask": "0.25"}], "timestamp": "1769384490987", "event_type": "price_change"}}
{"_local_timestamp": "2026-01-25T23:41:31.194947+00:00", "data": {"market": "0xbfd944007d7204b05e19d6fdf2cbe5f3e0b8d37bfb19c15d8e1c813e8ec2dec5", "price_changes": [{"asset_id": "75413567795086771542191436050004337965652039236856821284921766890217813492508", "price": "0.49", "size": "20", "side": "BUY", "hash": "34435387e0a517260f9504a5242395ac6492de4d", "best_bid": "0.75", "best_ask": "0.95"}, {"asset_id": "67189754674778985353824371461876088774339766303744275466510582338820578610808", "price": "0.51", "size": "20", "side": "SELL", "hash": "3d23064cabbfde5500d0bd1b698eeafab5d99249", "best_bid": "0.05", "best_ask": "0.25"}], "timestamp": "1769384491016", "event_type": "price_change"}}
{"_local_timestamp": "2026-01-25T23:41:31.286201+00:00", "data": {"market": "0xbfd944007d7204b05e19d6fdf2cbe5f3e0b8d37bfb19c15d8e1c813e8ec2dec5", "price_changes": [{"asset_id": "75413567795086771542191436050004337965652039236856821284921766890217813492508", "price": "0.5", "size": "25", "side": "BUY", "hash": "3a4c62e116b24c30456ddc1f6b2241d3194a33d3", "best_bid": "0.75", "best_ask": "0.95"}, {"asset_id": "67189754674778985353824371461876088774339766303744275466510582338820578610808", "price": "0.5", "size": "25", "side": "SELL", "hash": "458cf4f148a337bfc42a12ccb82cb79f69aabd6b", "best_bid": "0.05", "best_ask": "0.25"}], "timestamp": "1769384491133", "event_type": "price_change"}}
{"_local_timestamp": "2026-01-25T23:41:31.306107+00:00", "data": {"market": "0xbfd944007d7204b05e19d6fdf2cbe5f3e0b8d37bfb19c15d8e1c813e8ec2dec5", "price_changes": [{"asset_id": "75413567795086771542191436050004337965652039236856821284921766890217813492508", "price": "0.5", "size": "50", "side": "BUY", "hash": "1b56e3cd3533fd380539e321e7a6e29715e4eebf", "best_bid": "0.75", "best_ask": "0.95"}, {"asset_id": "67189754674778985353824371461876088774339766303744275466510582338820578610808", "price": "0.5", "size": "50", "side": "SELL", "hash": "66e3475be926f77a077b8ebcf33502b6102193b8", "best_bid": "0.05", "best_ask": "0.25"}], "timestamp": "1769384491161", "event_type": "price_change"}}
{"_local_timestamp": "2026-01-25T23:41:32.614867+00:00", "data": {"market": "0xbfd944007d7204b05e19d6fdf2cbe5f3e0b8d37bfb19c15d8e1c813e8ec2dec5", "price_changes": [{"asset_id": "75413567795086771542191436050004337965652039236856821284921766890217813492508", "price": "0.49", "size": "0", "side": "BUY", "hash": "379215274c1e04ca21982d5ba08eff6532770008", "best_bid": "0.75", "best_ask": "0.95"}, {"asset_id": "67189754674778985353824371461876088774339766303744275466510582338820578610808", "price": "0.51", "size": "0", "side": "SELL", "hash": "0767813f9a01431f5b654b9946ba30a220716986", "best_bid": "0.05", "best_ask": "0.25"}], "timestamp": "1769384492457", "event_type": "price_change"}}
{"_local_timestamp": "2026-01-25T23:41:32.657997+00:00", "data": {"market": "0xbfd944007d7204b05e19d6fdf2cbe5f3e0b8d37bfb19c15d8e1c813e8ec2dec5", "price_changes": [{"asset_id": "75413567795086771542191436050004337965652039236856821284921766890217813492508", "price": "0.51", "size": "20", "side": "BUY", "hash": "01e9fe9239fe66d4509a911c67cf85c8f2f146cb", "best_bid": "0.75", "best_ask": "0.95"}, {"asset_id": "67189754674778985353824371461876088774339766303744275466510582338820578610808", "price": "0.49", "size": "20", "side": "SELL", "hash": "7e88765896040dd508cd4604d7689bc503fa2cdf", "best_bid": "0.05", "best_ask": "0.25"}], "timestamp": "1769384492487", "event_type": "price_change"}}
{"_local_timestamp": "2026-01-25T23:41:32.762651+00:00", "data": {"market": "0xbfd944007d7204b05e19d6fdf2cbe5f3e0b8d37bfb19c15d8e1c813e8ec2dec5", "price_changes": [{"asset_id": "75413567795086771542191436050004337965652039236856821284921766890217813492508", "price": "0.5", "size": "25", "side": "BUY", "hash": "2986ae19347b513eb03b652f6f1b90a8c3b43fac", "best_bid": "0.75", "best_ask": "0.95"}, {"asset_id": "67189754674778985353824371461876088774339766303744275466510582338820578610808", "price": "0.5", "size": "25", "side": "SELL", "hash": "a7cfbd7fdd0507700d9417157dd2f7fa08e37458", "best_bid": "0.05", "best_ask": "0.25"}], "timestamp": "1769384492603", "event_type": "price_change"}}
{"_local_timestamp": "2026-01-25T23:41:32.779308+00:00", "data": {"market": "0xbfd944007d7204b05e19d6fdf2cbe5f3e0b8d37bfb19c15d8e1c813e8ec2dec5", "price_changes": [{"asset_id": "75413567795086771542191436050004337965652039236856821284921766890217813492508", "price": "0.5", "size": "0", "side": "BUY", "hash": "1bcc0f6792a36f880b3f6b77e7720dc24ff8e27d", "best_bid": "0.75", "best_ask": "0.95"}, {"asset_id": "67189754674778985353824371461876088774339766303744275466510582338820578610808", "price": "0.5", "size": "0", "side": "SELL", "hash": "6f36d39abdaeb927822cba1149eea9ca15e6c531", "best_bid": "0.05", "best_ask": "0.25"}], "timestamp": "1769384492618", "event_type": "price_change"}}
{"_local_timestamp": "2026-01-25T23:41:34.092577+00:00", "data": {"market": "0xbfd944007d7204b05e19d6fdf2cbe5f3e0b8d37bfb19c15d8e1c813e8ec2dec5", "price_changes": [{"asset_id": "75413567795086771542191436050004337965652039236856821284921766890217813492508", "price": "0.51", "size": "0", "side": "BUY", "hash": "5d8dfa0f17f76c4a08886ec2ad5f98d496d275a1", "best_bid": "0.75", "best_ask": "0.95"}, {"asset_id": "67189754674778985353824371461876088774339766303744275466510582338820578610808", "price": "0.49", "size": "0", "side": "SELL", "hash": "0d716ccd295867e5bb20268c718cc42543730dac", "best_bid": "0.05", "best_ask": "0.25"}], "timestamp": "1769384493949", "event_type": "price_change"}}
{"_local_timestamp": "2026-01-25T23:41:34.130574+00:00", "data": {"market": "0xbfd944007d7204b05e19d6fdf2cbe5f3e0b8d37bfb19c15d8e1c813e8ec2dec5", "price_changes": [{"asset_id": "75413567795086771542191436050004337965652039236856821284921766890217813492508", "price": "0.49", "size": "20", "side": "BUY", "hash": "a6d851c154e21a5efca07f507ed974dd32fe157a", "best_bid": "0.75", "best_ask": "0.95"}, {"asset_id": "67189754674778985353824371461876088774339766303744275466510582338820578610808", "price": "0.51", "size": "20", "side": "SELL", "hash": "a32e9b5a1e67bc6afc1a555cb8107e0c1f4fd153", "best_bid": "0.05", "best_ask": "0.25"}], "timestamp": "1769384493983", "event_type": "price_change"}}
{"_local_timestamp": "2026-01-25T23:41:34.268138+00:00", "data": {"market": "0xbfd944007d7204b05e19d6fdf2cbe5f3e0b8d37bfb19c15d8e1c813e8ec2dec5", "price_changes": [{"asset_id": "75413567795086771542191436050004337965652039236856821284921766890217813492508", "price": "0.5", "size": "25", "side": "BUY", "hash": "ac274dc729e6c40e338b4ac22eaae9ba9f0bd3d5", "best_bid": "0.75", "best_ask": "0.95"}, {"asset_id": "67189754674778985353824371461876088774339766303744275466510582338820578610808", "price": "0.5", "size": "25", "side": "SELL", "hash": "cf224083ad92783e2e016456d176caff8fda31c2", "best_bid": "0.05", "best_ask": "0.25"}], "timestamp": "1769384494109", "event_type": "price_change"}}
{"_local_timestamp": "2026-01-25T23:41:34.269730+00:00", "data": {"market": "0xbfd944007d7204b05e19d6fdf2cbe5f3e0b8d37bfb19c15d8e1c813e8ec2dec5", "price_changes": [{"asset_id": "75413567795086771542191436050004337965652039236856821284921766890217813492508", "price": "0.5", "size": "50", "side": "BUY", "hash": "1e04f57ce8829b7c3c565be85bf6d6a0a81f6a04", "best_bid": "0.75", "best_ask": "0.95"}, {"asset_id": "67189754674778985353824371461876088774339766303744275466510582338820578610808", "price": "0.5", "size": "50", "side": "SELL", "hash": "873284c9861780384bb7acf92e31e2dbf458cb1f", "best_bid": "0.05", "best_ask": "0.25"}], "timestamp": "1769384494111", "event_type": "price_change"}}
{"_local_timestamp": "2026-01-25T23:41:35.487321+00:00", "data": {"market": "0xbfd944007d7204b05e19d6fdf2cbe5f3e0b8d37bfb19c15d8e1c813e8ec2dec5", "price_changes": [{"asset_id": "75413567795086771542191436050004337965652039236856821284921766890217813492508", "price": "0.49", "size": "0", "side": "BUY", "hash": "607249c85b75ebae932b4f1f48498ed6636eeb33", "best_bid": "0.75", "best_ask": "0.95"}, {"asset_id": "67189754674778985353824371461876088774339766303744275466510582338820578610808", "price": "0.51", "size": "0", "side": "SELL", "hash": "2ae4f617f9baad29fe95c6886b2064fe24757853", "best_bid": "0.05", "best_ask": "0.25"}], "timestamp": "1769384495353", "event_type": "price_change"}}
{"_local_timestamp": "2026-01-25T23:41:35.509084+00:00", "data": {"market": "0xbfd944007d7204b05e19d6fdf2cbe5f3e0b8d37bfb19c15d8e1c813e8ec2dec5", "price_changes": [{"asset_id": "75413567795086771542191436050004337965652039236856821284921766890217813492508", "price": "0.51", "size": "20", "side": "BUY", "hash": "21e9136321826d1cfdc872db8e0416fff17d6307", "best_bid": "0.75", "best_ask": "0.95"}, {"asset_id": "67189754674778985353824371461876088774339766303744275466510582338820578610808", "price": "0.49", "size": "20", "side": "SELL", "hash": "9a3ad414505f7f4f151fcba8d7e78e3478ad28c8", "best_bid": "0.05", "best_ask": "0.25"}], "timestamp": "1769384495383", "event_type": "price_change"}}
{"_local_timestamp": "2026-01-25T23:41:35.631796+00:00", "data": {"market": "0xbfd944007d7204b05e19d6fdf2cbe5f3e0b8d37bfb19c15d8e1c813e8ec2dec5", "price_changes": [{"asset_id": "75413567795086771542191436050004337965652039236856821284921766890217813492508", "price": "0.5", "size": "25", "side": "BUY", "hash": "e9d8ef57b5a3547be86028a32a8259d5af1c7934", "best_bid": "0.75", "best_ask": "0.95"}, {"asset_id": "67189754674778985353824371461876088774339766303744275466510582338820578610808", "price": "0.5", "size": "25", "side": "SELL", "hash": "dd7ba6b83d09febc1d85ad2f4cb2e9433b59da7d", "best_bid": "0.05", "best_ask": "0.25"}], "timestamp": "1769384495506", "event_type": "price_change"}}
{"_local_timestamp": "2026-01-25T23:41:35.649749+00:00", "data": {"market": "0xbfd944007d7204b05e19d6fdf2cbe5f3e0b8d37bfb19c15d8e1c813e8ec2dec5", "price_changes": [{"asset_id": "75413567795086771542191436050004337965652039236856821284921766890217813492508", "price": "0.5", "size": "0", "side": "BUY", "hash": "2605a2a9ea4baf457ff57dd6005fa6ddf6f9282d", "best_bid": "0.75", "best_ask": "0.95"}, {"asset_id": "67189754674778985353824371461876088774339766303744275466510582338820578610808", "price": "0.5", "size": "0", "side": "SELL", "hash": "538b4a694b22649eb405289f0546b7fe632c149c", "best_bid": "0.05", "best_ask": "0.25"}], "timestamp": "1769384495521", "event_type": "price_change"}}
{"_local_timestamp": "2026-01-25T23:41:37.435734+00:00", "data": {"market": "0xbfd944007d7204b05e19d6fdf2cbe5f3e0b8d37bfb19c15d8e1c813e8ec2dec5", "price_changes": [{"asset_id": "75413567795086771542191436050004337965652039236856821284921766890217813492508", "price": "0.51", "size": "0", "side": "BUY", "hash": "94a2d56223035396f5333442bc5f2db5ddd4969b", "best_bid": "0.75", "best_ask": "0.95"}, {"asset_id": "67189754674778985353824371461876088774339766303744275466510582338820578610808", "price": "0.49", "size": "0", "side": "SELL", "hash": "22446eb05f27143de1e9bba1c9195298b844402d", "best_bid": "0.05", "best_ask": "0.25"}], "timestamp": "1769384497293", "event_type": "price_change"}}
{"_local_timestamp": "2026-01-25T23:41:37.466050+00:00", "data": {"market": "0xbfd944007d7204b05e19d6fdf2cbe5f3e0b8d37bfb19c15d8e1c813e8ec2dec5", "price_changes": [{"asset_id": "75413567795086771542191436050004337965652039236856821284921766890217813492508", "price": "0.49", "size": "20", "side": "BUY", "hash": "5e5b74565cda08001d1bc4ece888780d94b58917", "best_bid": "0.75", "best_ask": "0.95"}, {"asset_id": "67189754674778985353824371461876088774339766303744275466510582338820578610808", "price": "0.51", "size": "20", "side": "SELL", "hash": "2e0182841f588d179869d309896555ee586d5f3d", "best_bid": "0.05", "best_ask": "0.25"}], "timestamp": "1769384497327", "event_type": "price_change"}}
{"_local_timestamp": "2026-01-25T23:41:37.579316+00:00", "data": {"market": "0xbfd944007d7204b05e19d6fdf2cbe5f3e0b8d37bfb19c15d8e1c813e8ec2dec5", "price_changes": [{"asset_id": "75413567795086771542191436050004337965652039236856821284921766890217813492508", "price": "0.5", "size": "25", "side": "BUY", "hash": "f143528215150b1171c37b60664230d22cd5ea1d", "best_bid": "0.75", "best_ask": "0.95"}, {"asset_id": "67189754674778985353824371461876088774339766303744275466510582338820578610808", "price": "0.5", "size": "25", "side": "SELL", "hash": "e7029ae30f3b21f45456a4d176acf873741987b9", "best_bid": "0.05", "best_ask": "0.25"}], "timestamp": "1769384497444", "event_type": "price_change"}}
{"_local_timestamp": "2026-01-25T23:41:40.033994+00:00", "data": {"market": "0xbfd944007d7204b05e19d6fdf2cbe5f3e0b8d37bfb19c15d8e1c813e8ec2dec5", "price_changes": [{"asset_id": "75413567795086771542191436050004337965652039236856821284921766890217813492508", "price": "0.49", "size": "0", "side": "BUY", "hash": "3d17b7d923e3fe035871981b7168b88540641a81", "best_bid": "0.75", "best_ask": "0.95"}, {"asset_id": "67189754674778985353824371461876088774339766303744275466510582338820578610808", "price": "0.51", "size": "0", "side": "SELL", "hash": "d6e41f1c225bc7fa3bc11eb786ecb27e70dcc147", "best_bid": "0.05", "best_ask": "0.25"}], "timestamp": "1769384499929", "event_type": "price_change"}}
{"_local_timestamp": "2026-01-25T23:41:40.059007+00:00", "data": {"market": "0xbfd944007d7204b05e19d6fdf2cbe5f3e0b8d37bfb19c15d8e1c813e8ec2dec5", "price_changes": [{"asset_id": "75413567795086771542191436050004337965652039236856821284921766890217813492508", "price": "0.51", "size": "20", "side": "BUY", "hash": "95e52b3057d2ac77edd8c62b625d9f2088aaaebc", "best_bid": "0.75", "best_ask": "0.95"}, {"asset_id": "67189754674778985353824371461876088774339766303744275466510582338820578610808", "price": "0.49", "size": "20", "side": "SELL", "hash": "fb61f6aceb9ad2562fbe22459389ac2583e11b8f", "best_bid": "0.05", "best_ask": "0.25"}], "timestamp": "1769384499963", "event_type": "price_change"}}
{"_local_timestamp": "2026-01-25T23:41:40.122042+00:00", "data": {"market": "0xbfd944007d7204b05e19d6fdf2cbe5f3e0b8d37bfb19c15d8e1c813e8ec2dec5", "price_changes": [{"asset_id": "75413567795086771542191436050004337965652039236856821284921766890217813492508", "price": "0.5", "size": "0", "side": "BUY", "hash": "2ff8ad60939d2bd75d21c290fdfaba95ddee74a0", "best_bid": "0.75", "best_ask": "0.95"}, {"asset_id": "67189754674778985353824371461876088774339766303744275466510582338820578610808", "price": "0.5", "size": "0", "side": "SELL", "hash": "80421993481e1d14381881a0ac0c6fae7c88a3bb", "best_bid": "0.05", "best_ask": "0.25"}], "timestamp": "1769384500031", "event_type": "price_change"}}
{"_local_timestamp": "2026-01-25T23:41:40.123692+00:00", "data": {"market": "0x27441dae2a80c3c8c6eaddeb4e12857618e36c209479704ebc416c5e9bcdf48b", "price_changes": [{"asset_id": "20942804418898366041360868834735971328710307350569283381969854921720954083179", "price": "0.29", "size": "25", "side": "BUY", "hash": "79269ee7b56249be5cc94d02b9476be17bd68324", "best_bid": "0.49", "best_ask": "0.74"}, {"asset_id": "63317147287133286781047610956697981288778237042668675686742554461630558935769", "price": "0.71", "size": "25", "side": "SELL", "hash": "276d73f02852b7322b7c912698b880080a3d34ff", "best_bid": "0.26", "best_ask": "0.51"}], "timestamp": "1769384500041", "event_type": "price_change"}}
{"_local_timestamp": "2026-01-25T23:41:40.129372+00:00", "data": {"market": "0xbfd944007d7204b05e19d6fdf2cbe5f3e0b8d37bfb19c15d8e1c813e8ec2dec5", "price_changes": [{"asset_id": "75413567795086771542191436050004337965652039236856821284921766890217813492508", "price": "0.5", "size": "25", "side": "BUY", "hash": "619f0f0a3b8af740664f260f58645c62612bbc6d", "best_bid": "0.75", "best_ask": "0.95"}, {"asset_id": "67189754674778985353824371461876088774339766303744275466510582338820578610808", "price": "0.5", "size": "25", "side": "SELL", "hash": "e95c65fd85e06d0f73162ea8e4b8d1c1ede34e58", "best_bid": "0.05", "best_ask": "0.25"}], "timestamp": "1769384500047", "event_type": "price_change"}}
{"_local_timestamp": "2026-01-25T23:41:41.426985+00:00", "data": {"market": "0xbd46a9a86d53f1c6ed88d2ec2d6b7fa25f312a2330224a50b055fed30b6f487c", "price_changes": [{"asset_id": "103549663553180106742188583785378823515789409688357997461583563558502280722246", "price": "0.61", "size": "62.29", "side": "BUY", "hash": "5b155b7a8163e71d771bb4fd162b521cfee43fa7", "best_bid": "0.73", "best_ask": "0.94"}, {"asset_id": "103642153283858206072910718526021885682012582207057190439694348950566724371976", "price": "0.39", "size": "62.29", "side": "SELL", "hash": "d5e3deb13891fc5209a4f2c69bb73da89c729ebc", "best_bid": "0.06", "best_ask": "0.27"}], "timestamp": "1769384501357", "event_type": "price_change"}}
{"_local_timestamp": "2026-01-25T23:41:41.542695+00:00", "data": {"market": "0xbfd944007d7204b05e19d6fdf2cbe5f3e0b8d37bfb19c15d8e1c813e8ec2dec5", "price_changes": [{"asset_id": "75413567795086771542191436050004337965652039236856821284921766890217813492508", "price": "0.5", "size": "0", "side": "BUY", "hash": "8b8a1c537ceb85fd7d700967120a7c9eaad3b280", "best_bid": "0.75", "best_ask": "0.95"}, {"asset_id": "67189754674778985353824371461876088774339766303744275466510582338820578610808", "price": "0.5", "size": "0", "side": "SELL", "hash": "3c8efdace535e287ab9baec76a1107a028378148", "best_bid": "0.05", "best_ask": "0.25"}], "timestamp": "1769384501471", "event_type": "price_change"}}
{"_local_timestamp": "2026-01-25T23:41:42.414103+00:00", "data": {"market": "0x27441dae2a80c3c8c6eaddeb4e12857618e36c209479704ebc416c5e9bcdf48b", "price_changes": [{"asset_id": "20942804418898366041360868834735971328710307350569283381969854921720954083179", "price": "0.26", "size": "0", "side": "BUY", "hash": "6cda1498d0af2e3f96e21cee265b2eb48e347faf", "best_bid": "0.49", "best_ask": "0.74"}, {"asset_id": "63317147287133286781047610956697981288778237042668675686742554461630558935769", "price": "0.74", "size": "0", "side": "SELL", "hash": "d4582a6e802540e87e8d3adfaa8434bef7092b9b", "best_bid": "0.26", "best_ask": "0.51"}], "timestamp": "1769384502347", "event_type": "price_change"}}
{"_local_timestamp": "2026-01-25T23:41:42.415913+00:00", "data": {"market": "0xbfd944007d7204b05e19d6fdf2cbe5f3e0b8d37bfb19c15d8e1c813e8ec2dec5", "price_changes": [{"asset_id": "75413567795086771542191436050004337965652039236856821284921766890217813492508", "price": "0.51", "size": "0", "side": "BUY", "hash": "6a32e8bcdf3cc222b0d250f08317e52b48ffb34f", "best_bid": "0.75", "best_ask": "0.95"}, {"asset_id": "67189754674778985353824371461876088774339766303744275466510582338820578610808", "price": "0.49", "size": "0", "side": "SELL", "hash": "a41558197ffd71b2634fcfd68895cce4061d5448", "best_bid": "0.05", "best_ask": "0.25"}], "timestamp": "1769384502347", "event_type": "price_change"}}
{"_local_timestamp": "2026-01-25T23:41:42.448877+00:00", "data": {"market": "0x27441dae2a80c3c8c6eaddeb4e12857618e36c209479704ebc416c5e9bcdf48b", "price_changes": [{"asset_id": "20942804418898366041360868834735971328710307350569283381969854921720954083179", "price": "0.3", "size": "20", "side": "BUY", "hash": "ee1bc1d8d075733220ab4c83513746fa479abc9d", "best_bid": "0.49", "best_ask": "0.74"}, {"asset_id": "63317147287133286781047610956697981288778237042668675686742554461630558935769", "price": "0.7", "size": "20", "side": "SELL", "hash": "e5a4e8c8dc7bc9a8d3c0d43e6bb2d57b80837238", "best_bid": "0.26", "best_ask": "0.51"}], "timestamp": "1769384502377", "event_type": "price_change"}}
{"_local_timestamp": "2026-01-25T23:41:42.450440+00:00", "data": {"market": "0xbfd944007d7204b05e19d6fdf2cbe5f3e0b8d37bfb19c15d8e1c813e8ec2dec5", "price_changes": [{"asset_id": "75413567795086771542191436050004337965652039236856821284921766890217813492508", "price": "0.49", "size": "20", "side": "BUY", "hash": "825c2a389b6f8b2304effe49605249836e8f2147", "best_bid": "0.75", "best_ask": "0.95"}, {"asset_id": "67189754674778985353824371461876088774339766303744275466510582338820578610808", "price": "0.51", "size": "20", "side": "SELL", "hash": "d5207da733486ceebf8b3efb58de036235651295", "best_bid": "0.05", "best_ask": "0.25"}], "timestamp": "1769384502377", "event_type": "price_change"}}
{"_local_timestamp": "2026-01-25T23:41:42.557887+00:00", "data": {"market": "0xbfd944007d7204b05e19d6fdf2cbe5f3e0b8d37bfb19c15d8e1c813e8ec2dec5", "price_changes": [{"asset_id": "75413567795086771542191436050004337965652039236856821284921766890217813492508", "price": "0.5", "size": "25", "side": "BUY", "hash": "f77e56a7905e5b955d0e19736a57834abdba388d", "best_bid": "0.75", "best_ask": "0.95"}, {"asset_id": "67189754674778985353824371461876088774339766303744275466510582338820578610808", "price": "0.5", "size": "25", "side": "SELL", "hash": "0d6386a815275ac6dbce938aa3f0f1967fdc8209", "best_bid": "0.05", "best_ask": "0.25"}], "timestamp": "1769384502490", "event_type": "price_change"}}
{"_local_timestamp": "2026-01-25T23:41:42.566783+00:00", "data": {"market": "0xbfd944007d7204b05e19d6fdf2cbe5f3e0b8d37bfb19c15d8e1c813e8ec2dec5", "price_changes": [{"asset_id": "75413567795086771542191436050004337965652039236856821284921766890217813492508", "price": "0.5", "size": "50", "side": "BUY", "hash": "1b6f5338a3f5e32322fbf4a295e087a12a24bd38", "best_bid": "0.75", "best_ask": "0.95"}, {"asset_id": "67189754674778985353824371461876088774339766303744275466510582338820578610808", "price": "0.5", "size": "50", "side": "SELL", "hash": "d9bef5b5ef84e54cea5330f1939ae77a01ac764e", "best_bid": "0.05", "best_ask": "0.25"}], "timestamp": "1769384502496", "event_type": "price_change"}}
{"_local_timestamp": "2026-01-25T23:41:43.815551+00:00", "data": {"market": "0xbfd944007d7204b05e19d6fdf2cbe5f3e0b8d37bfb19c15d8e1c813e8ec2dec5", "price_changes": [{"asset_id": "75413567795086771542191436050004337965652039236856821284921766890217813492508", "price": "0.49", "size": "0", "side": "BUY", "hash": "b2e51318279ee69c2c7b8553e3eca17bc55b4ee0", "best_bid": "0.75", "best_ask": "0.95"}, {"asset_id": "67189754674778985353824371461876088774339766303744275466510582338820578610808", "price": "0.51", "size": "0", "side": "SELL", "hash": "3e095d49fc106f6f40699d8127137369b5ecc94e", "best_bid": "0.05", "best_ask": "0.25"}], "timestamp": "1769384503731", "event_type": "price_change"}}
{"_local_timestamp": "2026-01-25T23:41:43.835154+00:00", "data": {"market": "0xbfd944007d7204b05e19d6fdf2cbe5f3e0b8d37bfb19c15d8e1c813e8ec2dec5", "price_changes": [{"asset_id": "75413567795086771542191436050004337965652039236856821284921766890217813492508", "price": "0.51", "size": "20", "side": "BUY", "hash": "ee78d5aedd50d79d5b68f8c3fdbf052021c346c8", "best_bid": "0.75", "best_ask": "0.95"}, {"asset_id": "67189754674778985353824371461876088774339766303744275466510582338820578610808", "price": "0.49", "size": "20", "side": "SELL", "hash": "0a120d8da86a3e650671a9f59d67062b72f9c3f6", "best_bid": "0.05", "best_ask": "0.25"}], "timestamp": "1769384503767", "event_type": "price_change"}}
{"_local_timestamp": "2026-01-25T23:41:43.946376+00:00", "data": {"market": "0xbfd944007d7204b05e19d6fdf2cbe5f3e0b8d37bfb19c15d8e1c813e8ec2dec5", "price_changes": [{"asset_id": "75413567795086771542191436050004337965652039236856821284921766890217813492508", "price": "0.5", "size": "25", "side": "BUY", "hash": "2f5482efb03b18c787c98cfe062db668139a0ef5", "best_bid": "0.75", "best_ask": "0.95"}, {"asset_id": "67189754674778985353824371461876088774339766303744275466510582338820578610808", "price": "0.5", "size": "25", "side": "SELL", "hash": "00a196f01443167ff17e71d105e3189ff5c63621", "best_bid": "0.05", "best_ask": "0.25"}], "timestamp": "1769384503877", "event_type": "price_change"}}
{"_local_timestamp": "2026-01-25T23:41:43.961549+00:00", "data": {"market": "0xbfd944007d7204b05e19d6fdf2cbe5f3e0b8d37bfb19c15d8e1c813e8ec2dec5", "price_changes": [{"asset_id": "75413567795086771542191436050004337965652039236856821284921766890217813492508", "price": "0.5", "size": "0", "side": "BUY", "hash": "52830905d01aae4e705e090b2606b6314e8dd1e1", "best_bid": "0.75", "best_ask": "0.95"}, {"asset_id": "67189754674778985353824371461876088774339766303744275466510582338820578610808", "price": "0.5", "size": "0", "side": "SELL", "hash": "4dcf961e9c908baae2831d108cb658709bdb31f7", "best_bid": "0.05", "best_ask": "0.25"}], "timestamp": "1769384503897", "event_type": "price_change"}}
{"_local_timestamp": "2026-01-25T23:41:45.859174+00:00", "data": {"market": "0xbfd944007d7204b05e19d6fdf2cbe5f3e0b8d37bfb19c15d8e1c813e8ec2dec5", "price_changes": [{"asset_id": "75413567795086771542191436050004337965652039236856821284921766890217813492508", "price": "0.51", "size": "0", "side": "BUY", "hash": "6c31cc4a63681f86f6ad4999e2bd2abdb0585769", "best_bid": "0.75", "best_ask": "0.95"}, {"asset_id": "67189754674778985353824371461876088774339766303744275466510582338820578610808", "price": "0.49", "size": "0", "side": "SELL", "hash": "6bc909d0e2ccc876011df02751f5728f017fc977", "best_bid": "0.05", "best_ask": "0.25"}], "timestamp": "1769384505792", "event_type": "price_change"}}
{"_local_timestamp": "2026-01-25T23:41:45.892529+00:00", "data": {"market": "0xbfd944007d7204b05e19d6fdf2cbe5f3e0b8d37bfb19c15d8e1c813e8ec2dec5", "price_changes": [{"asset_id": "75413567795086771542191436050004337965652039236856821284921766890217813492508", "price": "0.49", "size": "20", "side": "BUY", "hash": "d8a959fd497915ec1bfb27abcade24486a9ce990", "best_bid": "0.75", "best_ask": "0.95"}, {"asset_id": "67189754674778985353824371461876088774339766303744275466510582338820578610808", "price": "0.51", "size": "20", "side": "SELL", "hash": "9cbb68c6719c45f96c7de1e6969fda7c73925c6e", "best_bid": "0.05", "best_ask": "0.25"}], "timestamp": "1769384505822", "event_type": "price_change"}}
{"_local_timestamp": "2026-01-25T23:41:45.991497+00:00", "data": {"market": "0xbfd944007d7204b05e19d6fdf2cbe5f3e0b8d37bfb19c15d8e1c813e8ec2dec5", "price_changes": [{"asset_id": "75413567795086771542191436050004337965652039236856821284921766890217813492508", "price": "0.5", "size": "25", "side": "BUY", "hash": "fae9274497a7e0a9ec6deebc4f6ba8c3a151221a", "best_bid": "0.75", "best_ask": "0.95"}, {"asset_id": "67189754674778985353824371461876088774339766303744275466510582338820578610808", "price": "0.5", "size": "25", "side": "SELL", "hash": "dcc090ec5d9defd5ecd3f9c088be0dc301350609", "best_bid": "0.05", "best_ask": "0.25"}], "timestamp": "1769384505928", "event_type": "price_change"}}
{"_local_timestamp": "2026-01-25T23:41:45.998464+00:00", "data": {"market": "0xbfd944007d7204b05e19d6fdf2cbe5f3e0b8d37bfb19c15d8e1c813e8ec2dec5", "price_changes": [{"asset_id": "75413567795086771542191436050004337965652039236856821284921766890217813492508", "price": "0.5", "size": "50", "side": "BUY", "hash": "a320b5ddf4bcffc4f230a91b909f87abc4dabb49", "best_bid": "0.75", "best_ask": "0.95"}, {"asset_id": "67189754674778985353824371461876088774339766303744275466510582338820578610808", "price": "0.5", "size": "50", "side": "SELL", "hash": "fb6fbe09f868bcf191f8258f0ed287a789bb7d14", "best_bid": "0.05", "best_ask": "0.25"}], "timestamp": "1769384505932", "event_type": "price_change"}}
{"_local_timestamp": "2026-01-25T23:41:47.706827+00:00", "data": {"market": "0xbfd944007d7204b05e19d6fdf2cbe5f3e0b8d37bfb19c15d8e1c813e8ec2dec5", "price_changes": [{"asset_id": "75413567795086771542191436050004337965652039236856821284921766890217813492508", "price": "0.49", "size": "0", "side": "BUY", "hash": "c65b2dc29814e449320aac0a6c6baf55de67f548", "best_bid": "0.75", "best_ask": "0.95"}, {"asset_id": "67189754674778985353824371461876088774339766303744275466510582338820578610808", "price": "0.51", "size": "0", "side": "SELL", "hash": "79ec9b1fbd0d10b2b458b8039df47624ecba7ffb", "best_bid": "0.05", "best_ask": "0.25"}], "timestamp": "1769384507640", "event_type": "price_change"}}
{"_local_timestamp": "2026-01-25T23:41:47.734597+00:00", "data": {"market": "0xbfd944007d7204b05e19d6fdf2cbe5f3e0b8d37bfb19c15d8e1c813e8ec2dec5", "price_changes": [{"asset_id": "75413567795086771542191436050004337965652039236856821284921766890217813492508", "price": "0.51", "size": "20", "side": "BUY", "hash": "3c6cbb23a32f07c2cbe5df3f7e3aeb4123d2b911", "best_bid": "0.75", "best_ask": "0.95"}, {"asset_id": "67189754674778985353824371461876088774339766303744275466510582338820578610808", "price": "0.49", "size": "20", "side": "SELL", "hash": "0a8e5b6fb9196f72367978be855bf33294fabb74", "best_bid": "0.05", "best_ask": "0.25"}], "timestamp": "1769384507668", "event_type": "price_change"}}
{"_local_timestamp": "2026-01-25T23:41:47.842655+00:00", "data": {"market": "0xbfd944007d7204b05e19d6fdf2cbe5f3e0b8d37bfb19c15d8e1c813e8ec2dec5", "price_changes": [{"asset_id": "75413567795086771542191436050004337965652039236856821284921766890217813492508", "price": "0.5", "size": "25", "side": "BUY", "hash": "827823a9da5f6b1b8fb5f86a2cac3588eafd6838", "best_bid": "0.75", "best_ask": "0.95"}, {"asset_id": "67189754674778985353824371461876088774339766303744275466510582338820578610808", "price": "0.5", "size": "25", "side": "SELL", "hash": "039dd12c7b18209c7e79d21858321cec8ec8b09c", "best_bid": "0.05", "best_ask": "0.25"}], "timestamp": "1769384507779", "event_type": "price_change"}}
{"_local_timestamp": "2026-01-25T23:41:47.854443+00:00", "data": {"market": "0xbfd944007d7204b05e19d6fdf2cbe5f3e0b8d37bfb19c15d8e1c813e8ec2dec5", "price_changes": [{"asset_id": "75413567795086771542191436050004337965652039236856821284921766890217813492508", "price": "0.5", "size": "0", "side": "BUY", "hash": "c5e6b80e2481a92504391a8760e9bc3e018f7fd2", "best_bid": "0.75", "best_ask": "0.95"}, {"asset_id": "67189754674778985353824371461876088774339766303744275466510582338820578610808", "price": "0.5", "size": "0", "side": "SELL", "hash": "1b5e465cd11631b1d302ba0c5ea6fbba9d1fb760", "best_bid": "0.05", "best_ask": "0.25"}], "timestamp": "1769384507786", "event_type": "price_change"}}
{"_local_timestamp": "2026-01-25T23:41:50.031681+00:00", "data": {"market": "0xbfd944007d7204b05e19d6fdf2cbe5f3e0b8d37bfb19c15d8e1c813e8ec2dec5", "price_changes": [{"asset_id": "75413567795086771542191436050004337965652039236856821284921766890217813492508", "price": "0.51", "size": "0", "side": "BUY", "hash": "28e25f0e08560e5563a7b2c92fdededd75f3584e", "best_bid": "0.75", "best_ask": "0.95"}, {"asset_id": "67189754674778985353824371461876088774339766303744275466510582338820578610808", "price": "0.49", "size": "0", "side": "SELL", "hash": "40e61c4bdb99ab18074a82c00e99a094a98253f7", "best_bid": "0.05", "best_ask": "0.25"}], "timestamp": "1769384509960", "event_type": "price_change"}}
{"_local_timestamp": "2026-01-25T23:41:50.053163+00:00", "data": {"market": "0xbfd944007d7204b05e19d6fdf2cbe5f3e0b8d37bfb19c15d8e1c813e8ec2dec5", "price_changes": [{"asset_id": "75413567795086771542191436050004337965652039236856821284921766890217813492508", "price": "0.49", "size": "20", "side": "BUY", "hash": "d29c84dbeb8da643c0c897b6bacb954a34c91d93", "best_bid": "0.75", "best_ask": "0.95"}, {"asset_id": "67189754674778985353824371461876088774339766303744275466510582338820578610808", "price": "0.51", "size": "20", "side": "SELL", "hash": "22ee78d776ec7068fc9bd13a8b30b5163bc14f15", "best_bid": "0.05", "best_ask": "0.25"}], "timestamp": "1769384509985", "event_type": "price_change"}}
{"_local_timestamp": "2026-01-25T23:41:50.166439+00:00", "data": {"market": "0xbfd944007d7204b05e19d6fdf2cbe5f3e0b8d37bfb19c15d8e1c813e8ec2dec5", "price_changes": [{"asset_id": "75413567795086771542191436050004337965652039236856821284921766890217813492508", "price": "0.5", "size": "25", "side": "BUY", "hash": "0630277909208318a1dd217fee735ae90c69d0c3", "best_bid": "0.75", "best_ask": "0.95"}, {"asset_id": "67189754674778985353824371461876088774339766303744275466510582338820578610808", "price": "0.5", "size": "25", "side": "SELL", "hash": "edabc3280d312d703a172210d3b6a0d2ded9dd32", "best_bid": "0.05", "best_ask": "0.25"}], "timestamp": "1769384510098", "event_type": "price_change"}}
{"_local_timestamp": "2026-01-25T23:41:50.174555+00:00", "data": {"market": "0xbfd944007d7204b05e19d6fdf2cbe5f3e0b8d37bfb19c15d8e1c813e8ec2dec5", "price_changes": [{"asset_id": "75413567795086771542191436050004337965652039236856821284921766890217813492508", "price": "0.5", "size": "50", "side": "BUY", "hash": "84aae0f20671ca5adcbc5ebe8542b86dd432ba0c", "best_bid": "0.75", "best_ask": "0.95"}, {"asset_id": "67189754674778985353824371461876088774339766303744275466510582338820578610808", "price": "0.5", "size": "50", "side": "SELL", "hash": "e4bf870677970bf2e8bfebf5fc08791c9aee5f35", "best_bid": "0.05", "best_ask": "0.25"}], "timestamp": "1769384510106", "event_type": "price_change"}}
{"_local_timestamp": "2026-01-25T23:41:52.754452+00:00", "data": {"market": "0xbfd944007d7204b05e19d6fdf2cbe5f3e0b8d37bfb19c15d8e1c813e8ec2dec5", "price_changes": [{"asset_id": "75413567795086771542191436050004337965652039236856821284921766890217813492508", "price": "0.49", "size": "0", "side": "BUY", "hash": "6582f13bf43c7604d0521107567dbe765e928129", "best_bid": "0.75", "best_ask": "0.95"}, {"asset_id": "67189754674778985353824371461876088774339766303744275466510582338820578610808", "price": "0.51", "size": "0", "side": "SELL", "hash": "e194c716971b353704636674d7cdcea88a02e9a2", "best_bid": "0.05", "best_ask": "0.25"}], "timestamp": "1769384512646", "event_type": "price_change"}}
{"_local_timestamp": "2026-01-25T23:41:52.966966+00:00", "data": {"market": "0xbfd944007d7204b05e19d6fdf2cbe5f3e0b8d37bfb19c15d8e1c813e8ec2dec5", "price_changes": [{"asset_id": "75413567795086771542191436050004337965652039236856821284921766890217813492508", "price": "0.51", "size": "20", "side": "BUY", "hash": "ebc8aca996f8622e871f355476c021be7597d795", "best_bid": "0.75", "best_ask": "0.95"}, {"asset_id": "67189754674778985353824371461876088774339766303744275466510582338820578610808", "price": "0.49", "size": "20", "side": "SELL", "hash": "3d782936c06949c8c5aae66c1d79afdcc441e7a4", "best_bid": "0.05", "best_ask": "0.25"}], "timestamp": "1769384512680", "event_type": "price_change"}}
{"_local_timestamp": "2026-01-25T23:41:53.246531+00:00", "data": {"market": "0xbfd944007d7204b05e19d6fdf2cbe5f3e0b8d37bfb19c15d8e1c813e8ec2dec5", "price_changes": [{"asset_id": "75413567795086771542191436050004337965652039236856821284921766890217813492508", "price": "0.5", "size": "25", "side": "BUY", "hash": "27874ada91068ad1d0286407c1883a65d01bbd67", "best_bid": "0.75", "best_ask": "0.95"}, {"asset_id": "67189754674778985353824371461876088774339766303744275466510582338820578610808", "price": "0.5", "size": "25", "side": "SELL", "hash": "6cc57e0910657bba7268c57932a4796a06667934", "best_bid": "0.05", "best_ask": "0.25"}], "timestamp": "1769384513007", "event_type": "price_change"}}
{"_local_timestamp": "2026-01-25T23:41:53.303016+00:00", "data": {"market": "0xbfd944007d7204b05e19d6fdf2cbe5f3e0b8d37bfb19c15d8e1c813e8ec2dec5", "price_changes": [{"asset_id": "75413567795086771542191436050004337965652039236856821284921766890217813492508", "price": "0.5", "size": "0", "side": "BUY", "hash": "0b33c5949502d563aae63b08e3abd4ad85d53001", "best_bid": "0.75", "best_ask": "0.95"}, {"asset_id": "67189754674778985353824371461876088774339766303744275466510582338820578610808", "price": "0.5", "size": "0", "side": "SELL", "hash": "477f833a744d33a5d4017f35688c37b48147869b", "best_bid": "0.05", "best_ask": "0.25"}], "timestamp": "1769384513152", "event_type": "price_change"}}
{"_local_timestamp": "2026-01-25T23:41:56.210893+00:00", "data": {"market": "0xbfd944007d7204b05e19d6fdf2cbe5f3e0b8d37bfb19c15d8e1c813e8ec2dec5", "price_changes": [{"asset_id": "75413567795086771542191436050004337965652039236856821284921766890217813492508", "price": "0.51", "size": "0", "side": "BUY", "hash": "abed61d2653900432210f58802499ee471de0c88", "best_bid": "0.75", "best_ask": "0.95"}, {"asset_id": "67189754674778985353824371461876088774339766303744275466510582338820578610808", "price": "0.49", "size": "0", "side": "SELL", "hash": "f5cf547af7c0c4e7ed11de9a079fe85f0105ad3e", "best_bid": "0.05", "best_ask": "0.25"}], "timestamp": "1769384516145", "event_type": "price_change"}}
{"_local_timestamp": "2026-01-25T23:41:56.250384+00:00", "data": {"market": "0xbfd944007d7204b05e19d6fdf2cbe5f3e0b8d37bfb19c15d8e1c813e8ec2dec5", "price_changes": [{"asset_id": "75413567795086771542191436050004337965652039236856821284921766890217813492508", "price": "0.49", "size": "20", "side": "BUY", "hash": "5401194afc9e3562f9f8b1a359ac42cf8c809e2b", "best_bid": "0.75", "best_ask": "0.95"}, {"asset_id": "67189754674778985353824371461876088774339766303744275466510582338820578610808", "price": "0.51", "size": "20", "side": "SELL", "hash": "3fea9cfadaa981d763aa964e10ad2ca8a1399e1d", "best_bid": "0.05", "best_ask": "0.25"}], "timestamp": "1769384516185", "event_type": "price_change"}}
{"_local_timestamp": "2026-01-25T23:41:56.358230+00:00", "data": {"market": "0xbfd944007d7204b05e19d6fdf2cbe5f3e0b8d37bfb19c15d8e1c813e8ec2dec5", "price_changes": [{"asset_id": "75413567795086771542191436050004337965652039236856821284921766890217813492508", "price": "0.5", "size": "25", "side": "BUY", "hash": "452ab291d7269775e87f74f32d09dc85a685abf4", "best_bid": "0.75", "best_ask": "0.95"}, {"asset_id": "67189754674778985353824371461876088774339766303744275466510582338820578610808", "price": "0.5", "size": "25", "side": "SELL", "hash": "e67ca1707922698bea50a7aa54c24c8e13e249f9", "best_bid": "0.05", "best_ask": "0.25"}], "timestamp": "1769384516292", "event_type": "price_change"}}
{"_local_timestamp": "2026-01-25T23:41:56.381983+00:00", "data": {"market": "0xbfd944007d7204b05e19d6fdf2cbe5f3e0b8d37bfb19c15d8e1c813e8ec2dec5", "price_changes": [{"asset_id": "75413567795086771542191436050004337965652039236856821284921766890217813492508", "price": "0.5", "size": "50", "side": "BUY", "hash": "241538f4c57e7a0a4dc83ad0cdcd93b2f6eadbaf", "best_bid": "0.75", "best_ask": "0.95"}, {"asset_id": "67189754674778985353824371461876088774339766303744275466510582338820578610808", "price": "0.5", "size": "50", "side": "SELL", "hash": "162947bb447df7b9f4f574c6a8d47eff3f88898e", "best_bid": "0.05", "best_ask": "0.25"}], "timestamp": "1769384516314", "event_type": "price_change"}}
{"_local_timestamp": "2026-01-25T23:42:01.667851+00:00", "data": {"market": "0xbfd944007d7204b05e19d6fdf2cbe5f3e0b8d37bfb19c15d8e1c813e8ec2dec5", "price_changes": [{"asset_id": "75413567795086771542191436050004337965652039236856821284921766890217813492508", "price": "0.49", "size": "0", "side": "BUY", "hash": "afe75e5bbca1e1ec6f88db9f362eb1ec552c1240", "best_bid": "0.75", "best_ask": "0.95"}, {"asset_id": "67189754674778985353824371461876088774339766303744275466510582338820578610808", "price": "0.51", "size": "0", "side": "SELL", "hash": "b136b94372890d5a1d880d75ee02114a79f7c181", "best_bid": "0.05", "best_ask": "0.25"}], "timestamp": "1769384521597", "event_type": "price_change"}}
{"_local_timestamp": "2026-01-25T23:42:01.688234+00:00", "data": {"market": "0xbfd944007d7204b05e19d6fdf2cbe5f3e0b8d37bfb19c15d8e1c813e8ec2dec5", "price_changes": [{"asset_id": "75413567795086771542191436050004337965652039236856821284921766890217813492508", "price": "0.51", "size": "20", "side": "BUY", "hash": "f09c57eac99f546d4e7c723fb9b08353f425f481", "best_bid": "0.75", "best_ask": "0.95"}, {"asset_id": "67189754674778985353824371461876088774339766303744275466510582338820578610808", "price": "0.49", "size": "20", "side": "SELL", "hash": "30090d86b28b67c44f6525838a177c8dbdef301d", "best_bid": "0.05", "best_ask": "0.25"}], "timestamp": "1769384521623", "event_type": "price_change"}}
{"_local_timestamp": "2026-01-25T23:42:01.800249+00:00", "data": {"market": "0xbfd944007d7204b05e19d6fdf2cbe5f3e0b8d37bfb19c15d8e1c813e8ec2dec5", "price_changes": [{"asset_id": "75413567795086771542191436050004337965652039236856821284921766890217813492508", "price": "0.5", "size": "25", "side": "BUY", "hash": "0c6aedebe77f328cfca4c291f3ba0ba926f284f1", "best_bid": "0.75", "best_ask": "0.95"}, {"asset_id": "67189754674778985353824371461876088774339766303744275466510582338820578610808", "price": "0.5", "size": "25", "side": "SELL", "hash": "b8ff6269d3c46189340ca10e8daf847c4cc29116", "best_bid": "0.05", "best_ask": "0.25"}], "timestamp": "1769384521733", "event_type": "price_change"}}
{"_local_timestamp": "2026-01-25T23:42:01.812320+00:00", "data": {"market": "0xbfd944007d7204b05e19d6fdf2cbe5f3e0b8d37bfb19c15d8e1c813e8ec2dec5", "price_changes": [{"asset_id": "75413567795086771542191436050004337965652039236856821284921766890217813492508", "price": "0.5", "size": "0", "side": "BUY", "hash": "a2434b301c1451cbedbcdc696a748fd30f97ea85", "best_bid": "0.75", "best_ask": "0.95"}, {"asset_id": "67189754674778985353824371461876088774339766303744275466510582338820578610808", "price": "0.5", "size": "0", "side": "SELL", "hash": "54560b04002349f8b5d91317ca41c905287960fa", "best_bid": "0.05", "best_ask": "0.25"}], "timestamp": "1769384521746", "event_type": "price_change"}}
{"_local_timestamp": "2026-01-25T23:42:04.820525+00:00", "data": {"market": "0xbfd944007d7204b05e19d6fdf2cbe5f3e0b8d37bfb19c15d8e1c813e8ec2dec5", "price_changes": [{"asset_id": "75413567795086771542191436050004337965652039236856821284921766890217813492508", "price": "0.51", "size": "0", "side": "BUY", "hash": "3009e4f29cec581d7af6d7cedc8db84ac1e8cf01", "best_bid": "0.75", "best_ask": "0.95"}, {"asset_id": "67189754674778985353824371461876088774339766303744275466510582338820578610808", "price": "0.49", "size": "0", "side": "SELL", "hash": "57fd432626cc6180b84e91f97b2e72dbfffbd0a5", "best_bid": "0.05", "best_ask": "0.25"}], "timestamp": "1769384524748", "event_type": "price_change"}}
{"_local_timestamp": "2026-01-25T23:42:04.852441+00:00", "data": {"market": "0xbfd944007d7204b05e19d6fdf2cbe5f3e0b8d37bfb19c15d8e1c813e8ec2dec5", "price_changes": [{"asset_id": "75413567795086771542191436050004337965652039236856821284921766890217813492508", "price": "0.49", "size": "20", "side": "BUY", "hash": "ff453cf7870ec08a57769a9958fb728237ef3342", "best_bid": "0.75", "best_ask": "0.95"}, {"asset_id": "67189754674778985353824371461876088774339766303744275466510582338820578610808", "price": "0.51", "size": "20", "side": "SELL", "hash": "0312d08fbc6a0858f4fbf8a27992d737901617cb", "best_bid": "0.05", "best_ask": "0.25"}], "timestamp": "1769384524778", "event_type": "price_change"}}
{"_local_timestamp": "2026-01-25T23:42:04.963497+00:00", "data": {"market": "0xbfd944007d7204b05e19d6fdf2cbe5f3e0b8d37bfb19c15d8e1c813e8ec2dec5", "price_changes": [{"asset_id": "75413567795086771542191436050004337965652039236856821284921766890217813492508", "price": "0.5", "size": "25", "side": "BUY", "hash": "920937b408dd475a031b6bff0c9ab7a5effdfa7c", "best_bid": "0.75", "best_ask": "0.95"}, {"asset_id": "67189754674778985353824371461876088774339766303744275466510582338820578610808", "price": "0.5", "size": "25", "side": "SELL", "hash": "4bdcd6396f914fbb570acf806ebb6fed692ca31e", "best_bid": "0.05", "best_ask": "0.25"}], "timestamp": "1769384524892", "event_type": "price_change"}}
{"_local_timestamp": "2026-01-25T23:42:04.993776+00:00", "data": {"market": "0xbfd944007d7204b05e19d6fdf2cbe5f3e0b8d37bfb19c15d8e1c813e8ec2dec5", "price_changes": [{"asset_id": "75413567795086771542191436050004337965652039236856821284921766890217813492508", "price": "0.5", "size": "50", "side": "BUY", "hash": "c2c36d8f25c656522977d2df37563c1fd72935bd", "best_bid": "0.75", "best_ask": "0.95"}, {"asset_id": "67189754674778985353824371461876088774339766303744275466510582338820578610808", "price": "0.5", "size": "50", "side": "SELL", "hash": "d3a4a92c90c26e1f095ba41e2545d36016556de9", "best_bid": "0.05", "best_ask": "0.25"}], "timestamp": "1769384524924", "event_type": "price_change"}}
{"_local_timestamp": "2026-01-25T23:42:07.715252+00:00", "data": {"market": "0xbfd944007d7204b05e19d6fdf2cbe5f3e0b8d37bfb19c15d8e1c813e8ec2dec5", "price_changes": [{"asset_id": "75413567795086771542191436050004337965652039236856821284921766890217813492508", "price": "0.49", "size": "0", "side": "BUY", "hash": "26650f841c06722a8228af1f8f28c83080a36c93", "best_bid": "0.75", "best_ask": "0.95"}, {"asset_id": "67189754674778985353824371461876088774339766303744275466510582338820578610808", "price": "0.51", "size": "0", "side": "SELL", "hash": "d18321cfc7596da77f87af52e3fbd07f894b46b2", "best_bid": "0.05", "best_ask": "0.25"}], "timestamp": "1769384527650", "event_type": "price_change"}}
{"_local_timestamp": "2026-01-25T23:42:07.764701+00:00", "data": {"market": "0xbfd944007d7204b05e19d6fdf2cbe5f3e0b8d37bfb19c15d8e1c813e8ec2dec5", "price_changes": [{"asset_id": "75413567795086771542191436050004337965652039236856821284921766890217813492508", "price": "0.51", "size": "20", "side": "BUY", "hash": "ae215a05b65ab34c9e61d846790c2ec4e1df8931", "best_bid": "0.75", "best_ask": "0.95"}, {"asset_id": "67189754674778985353824371461876088774339766303744275466510582338820578610808", "price": "0.49", "size": "20", "side": "SELL", "hash": "60900a1547218575635e8d3879274f657aff98c9", "best_bid": "0.05", "best_ask": "0.25"}], "timestamp": "1769384527691", "event_type": "price_change"}}
{"_local_timestamp": "2026-01-25T23:42:07.877091+00:00", "data": {"market": "0xbfd944007d7204b05e19d6fdf2cbe5f3e0b8d37bfb19c15d8e1c813e8ec2dec5", "price_changes": [{"asset_id": "75413567795086771542191436050004337965652039236856821284921766890217813492508", "price": "0.5", "size": "25", "side": "BUY", "hash": "70eb7758502293e6aff890b4024065375b076da1", "best_bid": "0.75", "best_ask": "0.95"}, {"asset_id": "67189754674778985353824371461876088774339766303744275466510582338820578610808", "price": "0.5", "size": "25", "side": "SELL", "hash": "618a0c336e6ca9ebafcad8580f926df6da4bc7cd", "best_bid": "0.05", "best_ask": "0.25"}], "timestamp": "1769384527811", "event_type": "price_change"}}
{"_local_timestamp": "2026-01-25T23:42:07.884692+00:00", "data": {"market": "0xbfd944007d7204b05e19d6fdf2cbe5f3e0b8d37bfb19c15d8e1c813e8ec2dec5", "price_changes": [{"asset_id": "75413567795086771542191436050004337965652039236856821284921766890217813492508", "price": "0.5", "size": "0", "side": "BUY", "hash": "8a6e9ff3897b391fcb95528bcd28ffaeff0bec35", "best_bid": "0.75", "best_ask": "0.95"}, {"asset_id": "67189754674778985353824371461876088774339766303744275466510582338820578610808", "price": "0.5", "size": "0", "side": "SELL", "hash": "ea95104dcbae7d99793d5199b7bfde9fe4e01ff3", "best_bid": "0.05", "best_ask": "0.25"}], "timestamp": "1769384527814", "event_type": "price_change"}}
{"_local_timestamp": "2026-01-25T23:42:10.206374+00:00", "data": {"market": "0xbfd944007d7204b05e19d6fdf2cbe5f3e0b8d37bfb19c15d8e1c813e8ec2dec5", "price_changes": [{"asset_id": "75413567795086771542191436050004337965652039236856821284921766890217813492508", "price": "0.51", "size": "0", "side": "BUY", "hash": "a3d6e68358e7648859f158a996a701a976b8a7df", "best_bid": "0.75", "best_ask": "0.95"}, {"asset_id": "67189754674778985353824371461876088774339766303744275466510582338820578610808", "price": "0.49", "size": "0", "side": "SELL", "hash": "7b5017da49747bd635e35ebd40f20fa7583e8986", "best_bid": "0.05", "best_ask": "0.25"}], "timestamp": "1769384530130", "event_type": "price_change"}}
{"_local_timestamp": "2026-01-25T23:42:10.236755+00:00", "data": {"market": "0xbfd944007d7204b05e19d6fdf2cbe5f3e0b8d37bfb19c15d8e1c813e8ec2dec5", "price_changes": [{"asset_id": "75413567795086771542191436050004337965652039236856821284921766890217813492508", "price": "0.49", "size": "20", "side": "BUY", "hash": "248dcdf8a3bf9bd096948f4bba8aaa6e4a29ed6f", "best_bid": "0.75", "best_ask": "0.95"}, {"asset_id": "67189754674778985353824371461876088774339766303744275466510582338820578610808", "price": "0.51", "size": "20", "side": "SELL", "hash": "a2fc94859941b574e3a9a673d559324442dfbfd8", "best_bid": "0.05", "best_ask": "0.25"}], "timestamp": "1769384530163", "event_type": "price_change"}}
{"_local_timestamp": "2026-01-25T23:42:10.350438+00:00", "data": {"market": "0xbfd944007d7204b05e19d6fdf2cbe5f3e0b8d37bfb19c15d8e1c813e8ec2dec5", "price_changes": [{"asset_id": "75413567795086771542191436050004337965652039236856821284921766890217813492508", "price": "0.5", "size": "25", "side": "BUY", "hash": "fa53bff778a6f7054fdba69bd15cefda43fff16b", "best_bid": "0.75", "best_ask": "0.95"}, {"asset_id": "67189754674778985353824371461876088774339766303744275466510582338820578610808", "price": "0.5", "size": "25", "side": "SELL", "hash": "fcbd2a5dd237b0427377edba2c31f0ecda50fdf8", "best_bid": "0.05", "best_ask": "0.25"}], "timestamp": "1769384530270", "event_type": "price_change"}}
{"_local_timestamp": "2026-01-25T23:42:10.352161+00:00", "data": {"market": "0xbfd944007d7204b05e19d6fdf2cbe5f3e0b8d37bfb19c15d8e1c813e8ec2dec5", "price_changes": [{"asset_id": "75413567795086771542191436050004337965652039236856821284921766890217813492508", "price": "0.5", "size": "50", "side": "BUY", "hash": "3f28cd737700093af98893c549d1d6741d4d67ac", "best_bid": "0.75", "best_ask": "0.95"}, {"asset_id": "67189754674778985353824371461876088774339766303744275466510582338820578610808", "price": "0.5", "size": "50", "side": "SELL", "hash": "95b48b0502ef0c1854d47c8e8f5cdf8fa4bc27c7", "best_bid": "0.05", "best_ask": "0.25"}], "timestamp": "1769384530285", "event_type": "price_change"}}
{"_local_timestamp": "2026-01-25T23:42:11.800369+00:00", "data": {"market": "0x97b4a74e6ad96c4601a70bffea6b3ea48227b0676658f1a77c5e4dfeb03c1422", "price_changes": [{"asset_id": "74328021459889543390175687510268557967371044615256517664604837321395650238724", "price": "0.53", "size": "67", "side": "BUY", "hash": "06deb1c0d6a56ba265fa3fb4f9e47de88753e913", "best_bid": "0.53", "best_ask": "0.95"}, {"asset_id": "67088219062664412623221891896187729302515136551189145648713076701295675541006", "price": "0.47", "size": "67", "side": "SELL", "hash": "1dd93812bfaf7c098cd7f6fd29cba9e818f4df06", "best_bid": "0.05", "best_ask": "0.47"}], "timestamp": "1769384531735", "event_type": "price_change"}}
{"_local_timestamp": "2026-01-25T23:42:12.520114+00:00", "data": {"market": "0x97b4a74e6ad96c4601a70bffea6b3ea48227b0676658f1a77c5e4dfeb03c1422", "price_changes": [{"asset_id": "67088219062664412623221891896187729302515136551189145648713076701295675541006", "price": "0.48", "size": "60", "side": "SELL", "hash": "78d5b195b742923e23a71f022b3ca49d2c1ddcc4", "best_bid": "0.05", "best_ask": "0.47"}, {"asset_id": "74328021459889543390175687510268557967371044615256517664604837321395650238724", "price": "0.52", "size": "60", "side": "BUY", "hash": "aeddb1a60af15459d2d9f9688bb05d03cdf4b8ef", "best_bid": "0.53", "best_ask": "0.95"}], "timestamp": "1769384532454", "event_type": "price_change"}}
{"_local_timestamp": "2026-01-25T23:42:12.571861+00:00", "data": {"market": "0x97b4a74e6ad96c4601a70bffea6b3ea48227b0676658f1a77c5e4dfeb03c1422", "price_changes": [{"asset_id": "67088219062664412623221891896187729302515136551189145648713076701295675541006", "price": "0.46", "size": "27.89", "side": "SELL", "hash": "9b3cec517a84bd8d9643832069b48b1f953d665a", "best_bid": "0.05", "best_ask": "0.46"}, {"asset_id": "74328021459889543390175687510268557967371044615256517664604837321395650238724", "price": "0.54", "size": "27.89", "side": "BUY", "hash": "a721d880e0bd7f5c7f4408882f9f362937ecbe06", "best_bid": "0.54", "best_ask": "0.95"}], "timestamp": "1769384532509", "event_type": "price_change"}}
{"_local_timestamp": "2026-01-25T23:42:12.685042+00:00", "data": {"market": "0xbfd944007d7204b05e19d6fdf2cbe5f3e0b8d37bfb19c15d8e1c813e8ec2dec5", "price_changes": [{"asset_id": "75413567795086771542191436050004337965652039236856821284921766890217813492508", "price": "0.49", "size": "0", "side": "BUY", "hash": "bc07ecf2f110443467ebac67c85a258827f4f6de", "best_bid": "0.75", "best_ask": "0.95"}, {"asset_id": "67189754674778985353824371461876088774339766303744275466510582338820578610808", "price": "0.51", "size": "0", "side": "SELL", "hash": "f483d33d7e5cccf599cb7f036391883841189032", "best_bid": "0.05", "best_ask": "0.25"}], "timestamp": "1769384532616", "event_type": "price_change"}}
{"_local_timestamp": "2026-01-25T23:42:12.715957+00:00", "data": {"market": "0xbfd944007d7204b05e19d6fdf2cbe5f3e0b8d37bfb19c15d8e1c813e8ec2dec5", "price_changes": [{"asset_id": "75413567795086771542191436050004337965652039236856821284921766890217813492508", "price": "0.51", "size": "20", "side": "BUY", "hash": "50f3fe09a311470754edf5b19fd8cf5d36cb0fbf", "best_bid": "0.75", "best_ask": "0.95"}, {"asset_id": "67189754674778985353824371461876088774339766303744275466510582338820578610808", "price": "0.49", "size": "20", "side": "SELL", "hash": "611ebf0d28051635d69c9e1f92dab503ee6997f1", "best_bid": "0.05", "best_ask": "0.25"}], "timestamp": "1769384532646", "event_type": "price_change"}}
{"_local_timestamp": "2026-01-25T23:42:12.832024+00:00", "data": {"market": "0xbfd944007d7204b05e19d6fdf2cbe5f3e0b8d37bfb19c15d8e1c813e8ec2dec5", "price_changes": [{"asset_id": "75413567795086771542191436050004337965652039236856821284921766890217813492508", "price": "0.5", "size": "25", "side": "BUY", "hash": "b1c9dd1b3d2997ee439ff8875173bef032bd3024", "best_bid": "0.75", "best_ask": "0.95"}, {"asset_id": "67189754674778985353824371461876088774339766303744275466510582338820578610808", "price": "0.5", "size": "25", "side": "SELL", "hash": "a8090d5540b761b404c5c985e09aa3ec62e385a6", "best_bid": "0.05", "best_ask": "0.25"}], "timestamp": "1769384532756", "event_type": "price_change"}}
{"_local_timestamp": "2026-01-25T23:42:12.839565+00:00", "data": {"market": "0xbfd944007d7204b05e19d6fdf2cbe5f3e0b8d37bfb19c15d8e1c813e8ec2dec5", "price_changes": [{"asset_id": "75413567795086771542191436050004337965652039236856821284921766890217813492508", "price": "0.5", "size": "0", "side": "BUY", "hash": "d58199b856aff83dba5130bc9d4518b0d27ef0a7", "best_bid": "0.75", "best_ask": "0.95"}, {"asset_id": "67189754674778985353824371461876088774339766303744275466510582338820578610808", "price": "0.5", "size": "0", "side": "SELL", "hash": "c903649dfb40bc3eba09ab42a606f9c683fe5e7d", "best_bid": "0.05", "best_ask": "0.25"}], "timestamp": "1769384532772", "event_type": "price_change"}}
{"_local_timestamp": "2026-01-25T23:42:14.226079+00:00", "data": {"market": "0xbfd944007d7204b05e19d6fdf2cbe5f3e0b8d37bfb19c15d8e1c813e8ec2dec5", "price_changes": [{"asset_id": "75413567795086771542191436050004337965652039236856821284921766890217813492508", "price": "0.51", "size": "0", "side": "BUY", "hash": "0aac2bf75f25f80d3e998448eff00258b294fec7", "best_bid": "0.75", "best_ask": "0.95"}, {"asset_id": "67189754674778985353824371461876088774339766303744275466510582338820578610808", "price": "0.49", "size": "0", "side": "SELL", "hash": "4ed15323f37664ea18327367d3b1cbd82a07658f", "best_bid": "0.05", "best_ask": "0.25"}], "timestamp": "1769384534149", "event_type": "price_change"}}
{"_local_timestamp": "2026-01-25T23:42:14.245053+00:00", "data": {"market": "0xbfd944007d7204b05e19d6fdf2cbe5f3e0b8d37bfb19c15d8e1c813e8ec2dec5", "price_changes": [{"asset_id": "75413567795086771542191436050004337965652039236856821284921766890217813492508", "price": "0.49", "size": "20", "side": "BUY", "hash": "66b9128605c121cb28cf37b1636caeb62906fd45", "best_bid": "0.75", "best_ask": "0.95"}, {"asset_id": "67189754674778985353824371461876088774339766303744275466510582338820578610808", "price": "0.51", "size": "20", "side": "SELL", "hash": "73ad4c57da13583c5f6f9b2254ceafb1fab02e07", "best_bid": "0.05", "best_ask": "0.25"}], "timestamp": "1769384534178", "event_type": "price_change"}}
{"_local_timestamp": "2026-01-25T23:42:14.350417+00:00", "data": {"market": "0xbfd944007d7204b05e19d6fdf2cbe5f3e0b8d37bfb19c15d8e1c813e8ec2dec5", "price_changes": [{"asset_id": "75413567795086771542191436050004337965652039236856821284921766890217813492508", "price": "0.5", "size": "25", "side": "BUY", "hash": "a49a9937b71d13e9decb9304e3bcc9677d16b6b8", "best_bid": "0.75", "best_ask": "0.95"}, {"asset_id": "67189754674778985353824371461876088774339766303744275466510582338820578610808", "price": "0.5", "size": "25", "side": "SELL", "hash": "d5cb970c2db3a4abb2f8a8d7db7ff923ace99fa6", "best_bid": "0.05", "best_ask": "0.25"}], "timestamp": "1769384534287", "event_type": "price_change"}}
{"_local_timestamp": "2026-01-25T23:42:14.374846+00:00", "data": {"market": "0xbfd944007d7204b05e19d6fdf2cbe5f3e0b8d37bfb19c15d8e1c813e8ec2dec5", "price_changes": [{"asset_id": "75413567795086771542191436050004337965652039236856821284921766890217813492508", "price": "0.5", "size": "50", "side": "BUY", "hash": "ee7ad2aba01be5d0c504039293528b01091ec21f", "best_bid": "0.75", "best_ask": "0.95"}, {"asset_id": "67189754674778985353824371461876088774339766303744275466510582338820578610808", "price": "0.5", "size": "50", "side": "SELL", "hash": "55c23eaa6694a1d104edc6b0fb48920f7f694a0d", "best_bid": "0.05", "best_ask": "0.25"}], "timestamp": "1769384534293", "event_type": "price_change"}}
{"_local_timestamp": "2026-01-25T23:42:16.100314+00:00", "data": {"market": "0x97b4a74e6ad96c4601a70bffea6b3ea48227b0676658f1a77c5e4dfeb03c1422", "price_changes": [{"asset_id": "74328021459889543390175687510268557967371044615256517664604837321395650238724", "price": "0.52", "size": "20", "side": "BUY", "hash": "bcd89208cd21ea1abad68598de3d425a52b7d305", "best_bid": "0.54", "best_ask": "0.95"}, {"asset_id": "67088219062664412623221891896187729302515136551189145648713076701295675541006", "price": "0.48", "size": "20", "side": "SELL", "hash": "ab5e1eea4ea5f5a853f55b04600f7ccb79f534d0", "best_bid": "0.05", "best_ask": "0.46"}], "timestamp": "1769384536007", "event_type": "price_change"}}
{"_local_timestamp": "2026-01-25T23:42:16.130666+00:00", "data": {"market": "0x97b4a74e6ad96c4601a70bffea6b3ea48227b0676658f1a77c5e4dfeb03c1422", "price_changes": [{"asset_id": "74328021459889543390175687510268557967371044615256517664604837321395650238724", "price": "0.54", "size": "67.89", "side": "BUY", "hash": "87bf6cbefcfca0bd0bef0c981996505f46d72b73", "best_bid": "0.54", "best_ask": "0.95"}, {"asset_id": "67088219062664412623221891896187729302515136551189145648713076701295675541006", "price": "0.46", "size": "67.89", "side": "SELL", "hash": "cef6ecbb5eb19406bdba327e0cde4e7317d322d2", "best_bid": "0.05", "best_ask": "0.46"}], "timestamp": "1769384536046", "event_type": "price_change"}}
{"_local_timestamp": "2026-01-25T23:42:17.343821+00:00", "data": {"market": "0x97b4a74e6ad96c4601a70bffea6b3ea48227b0676658f1a77c5e4dfeb03c1422", "price_changes": [{"asset_id": "74328021459889543390175687510268557967371044615256517664604837321395650238724", "price": "0.52", "size": "0", "side": "BUY", "hash": "bb2b46383f2a1d12a207da78290900b64130349a", "best_bid": "0.54", "best_ask": "0.95"}, {"asset_id": "67088219062664412623221891896187729302515136551189145648713076701295675541006", "price": "0.48", "size": "0", "side": "SELL", "hash": "1202fc8fe2be3c58b1037ed8e6ce29a932d70520", "best_bid": "0.05", "best_ask": "0.46"}], "timestamp": "1769384537272", "event_type": "price_change"}}
{"_local_timestamp": "2026-01-25T23:42:17.366340+00:00", "data": {"market": "0xbfd944007d7204b05e19d6fdf2cbe5f3e0b8d37bfb19c15d8e1c813e8ec2dec5", "price_changes": [{"asset_id": "75413567795086771542191436050004337965652039236856821284921766890217813492508", "price": "0.49", "size": "0", "side": "BUY", "hash": "3e7a1b8e1e12d9ebd6b55e40b84b68e245e0b46c", "best_bid": "0.75", "best_ask": "0.95"}, {"asset_id": "67189754674778985353824371461876088774339766303744275466510582338820578610808", "price": "0.51", "size": "0", "side": "SELL", "hash": "7c22678c1a1a4da815440174e4f61e778881fdd7", "best_bid": "0.05", "best_ask": "0.25"}], "timestamp": "1769384537272", "event_type": "price_change"}}
{"_local_timestamp": "2026-01-25T23:42:17.374338+00:00", "data": {"market": "0x97b4a74e6ad96c4601a70bffea6b3ea48227b0676658f1a77c5e4dfeb03c1422", "price_changes": [{"asset_id": "74328021459889543390175687510268557967371044615256517664604837321395650238724", "price": "0.44", "size": "20", "side": "BUY", "hash": "bd12caf26b3c5219d79c575314d9f734fbcb1be8", "best_bid": "0.54", "best_ask": "0.95"}, {"asset_id": "67088219062664412623221891896187729302515136551189145648713076701295675541006", "price": "0.56", "size": "20", "side": "SELL", "hash": "2b430e54cb79b7dc784ca45d6c4b5e81582592b3", "best_bid": "0.05", "best_ask": "0.46"}], "timestamp": "1769384537303", "event_type": "price_change"}}
{"_local_timestamp": "2026-01-25T23:42:17.376004+00:00", "data": {"market": "0xbfd944007d7204b05e19d6fdf2cbe5f3e0b8d37bfb19c15d8e1c813e8ec2dec5", "price_changes": [{"asset_id": "75413567795086771542191436050004337965652039236856821284921766890217813492508", "price": "0.51", "size": "20", "side": "BUY", "hash": "f09c7693c569f0e55fbdfc681ac0454d1f9ff58c", "best_bid": "0.75", "best_ask": "0.95"}, {"asset_id": "67189754674778985353824371461876088774339766303744275466510582338820578610808", "price": "0.49", "size": "20", "side": "SELL", "hash": "fb29fbdf3ce7dbad41302abe26265884c7fe16bd", "best_bid": "0.05", "best_ask": "0.25"}], "timestamp": "1769384537303", "event_type": "price_change"}}
{"_local_timestamp": "2026-01-25T23:42:17.478617+00:00", "data": {"market": "0xbfd944007d7204b05e19d6fdf2cbe5f3e0b8d37bfb19c15d8e1c813e8ec2dec5", "price_changes": [{"asset_id": "75413567795086771542191436050004337965652039236856821284921766890217813492508", "price": "0.5", "size": "25", "side": "BUY", "hash": "3e632de3beddc20ebdd69c625e21fafabfce8e10", "best_bid": "0.75", "best_ask": "0.95"}, {"asset_id": "67189754674778985353824371461876088774339766303744275466510582338820578610808", "price": "0.5", "size": "25", "side": "SELL", "hash": "1d991baaa2ed0cf481cf4e947761aa40d82794e8", "best_bid": "0.05", "best_ask": "0.25"}], "timestamp": "1769384537418", "event_type": "price_change"}}
{"_local_timestamp": "2026-01-25T23:42:17.524300+00:00", "data": {"market": "0xbfd944007d7204b05e19d6fdf2cbe5f3e0b8d37bfb19c15d8e1c813e8ec2dec5", "price_changes": [{"asset_id": "75413567795086771542191436050004337965652039236856821284921766890217813492508", "price": "0.5", "size": "0", "side": "BUY", "hash": "318fcbc0527ea80ba72c4dd06859dbb57a4bf79d", "best_bid": "0.75", "best_ask": "0.95"}, {"asset_id": "67189754674778985353824371461876088774339766303744275466510582338820578610808", "price": "0.5", "size": "0", "side": "SELL", "hash": "d8e030b82a47b26c6883f294f7b50bf1e54c2e62", "best_bid": "0.05", "best_ask": "0.25"}], "timestamp": "1769384537422", "event_type": "price_change"}}
{"_local_timestamp": "2026-01-25T23:42:17.526089+00:00", "data": {"market": "0x97b4a74e6ad96c4601a70bffea6b3ea48227b0676658f1a77c5e4dfeb03c1422", "price_changes": [{"asset_id": "74328021459889543390175687510268557967371044615256517664604837321395650238724", "price": "0.48", "size": "25", "side": "BUY", "hash": "e48caf240187ab89e83081caf5da43f8501be2e3", "best_bid": "0.54", "best_ask": "0.95"}, {"asset_id": "67088219062664412623221891896187729302515136551189145648713076701295675541006", "price": "0.52", "size": "25", "side": "SELL", "hash": "49f5c5cb6a51ac83abe3bc80bd2b24d857b7eb45", "best_bid": "0.05", "best_ask": "0.46"}], "timestamp": "1769384537424", "event_type": "price_change"}}
{"_local_timestamp": "2026-01-25T23:42:17.527703+00:00", "data": {"market": "0x97b4a74e6ad96c4601a70bffea6b3ea48227b0676658f1a77c5e4dfeb03c1422", "price_changes": [{"asset_id": "74328021459889543390175687510268557967371044615256517664604837321395650238724", "price": "0.48", "size": "50", "side": "BUY", "hash": "5ea7a68da9cfb498c38ce06e1ef6cac4dab99c02", "best_bid": "0.54", "best_ask": "0.95"}, {"asset_id": "67088219062664412623221891896187729302515136551189145648713076701295675541006", "price": "0.52", "size": "50", "side": "SELL", "hash": "316acc6dd6c19f88cf74d7e2884ef8514057f837", "best_bid": "0.05", "best_ask": "0.46"}], "timestamp": "1769384537425", "event_type": "price_change"}}
{"_local_timestamp": "2026-01-25T23:42:18.948163+00:00", "data": {"market": "0x97b4a74e6ad96c4601a70bffea6b3ea48227b0676658f1a77c5e4dfeb03c1422", "price_changes": [{"asset_id": "74328021459889543390175687510268557967371044615256517664604837321395650238724", "price": "0.03", "size": "0", "side": "BUY", "hash": "e8a4189fb12c6bd00f6a1ab2cfd268930bb28d14", "best_bid": "0.54", "best_ask": "0.95"}, {"asset_id": "67088219062664412623221891896187729302515136551189145648713076701295675541006", "price": "0.97", "size": "0", "side": "SELL", "hash": "2d5e82f46b21cdb1cfc2b7e0fc3c5ba11975caa3", "best_bid": "0.05", "best_ask": "0.46"}], "timestamp": "1769384538874", "event_type": "price_change"}}
{"_local_timestamp": "2026-01-25T23:42:20.384767+00:00", "data": {"market": "0xbfd944007d7204b05e19d6fdf2cbe5f3e0b8d37bfb19c15d8e1c813e8ec2dec5", "price_changes": [{"asset_id": "75413567795086771542191436050004337965652039236856821284921766890217813492508", "price": "0.51", "size": "0", "side": "BUY", "hash": "58bf34a31c6bcf2f6612b68fb903098aff562acd", "best_bid": "0.75", "best_ask": "0.95"}, {"asset_id": "67189754674778985353824371461876088774339766303744275466510582338820578610808", "price": "0.49", "size": "0", "side": "SELL", "hash": "c753845cf986c3995bca3a119d11b43ea97332d4", "best_bid": "0.05", "best_ask": "0.25"}], "timestamp": "1769384540314", "event_type": "price_change"}}
{"_local_timestamp": "2026-01-25T23:42:20.386545+00:00", "data": {"market": "0x97b4a74e6ad96c4601a70bffea6b3ea48227b0676658f1a77c5e4dfeb03c1422", "price_changes": [{"asset_id": "74328021459889543390175687510268557967371044615256517664604837321395650238724", "price": "0.44", "size": "0", "side": "BUY", "hash": "d9a7179d2a1ddb75d30171b64286d2797f2c2d4d", "best_bid": "0.54", "best_ask": "0.95"}, {"asset_id": "67088219062664412623221891896187729302515136551189145648713076701295675541006", "price": "0.56", "size": "0", "side": "SELL", "hash": "08faf9c6a1140feba7b74f4441e747e69e9c49a4", "best_bid": "0.05", "best_ask": "0.46"}], "timestamp": "1769384540314", "event_type": "price_change"}}
{"_local_timestamp": "2026-01-25T23:42:20.415954+00:00", "data": {"market": "0x97b4a74e6ad96c4601a70bffea6b3ea48227b0676658f1a77c5e4dfeb03c1422", "price_changes": [{"asset_id": "74328021459889543390175687510268557967371044615256517664604837321395650238724", "price": "0.49", "size": "20", "side": "BUY", "hash": "04169fb17c7585024a2002849e31ad4aac8496bf", "best_bid": "0.54", "best_ask": "0.95"}, {"asset_id": "67088219062664412623221891896187729302515136551189145648713076701295675541006", "price": "0.51", "size": "20", "side": "SELL", "hash": "27dd89523d4a22d96fea4656cca88d2331c8f7b5", "best_bid": "0.05", "best_ask": "0.46"}], "timestamp": "1769384540348", "event_type": "price_change"}}
{"_local_timestamp": "2026-01-25T23:42:20.417714+00:00", "data": {"market": "0xbfd944007d7204b05e19d6fdf2cbe5f3e0b8d37bfb19c15d8e1c813e8ec2dec5", "price_changes": [{"asset_id": "75413567795086771542191436050004337965652039236856821284921766890217813492508", "price": "0.49", "size": "20", "side": "BUY", "hash": "3b9aae4988222e4b30bd72d0acb1ede7b4fffd57", "best_bid": "0.75", "best_ask": "0.95"}, {"asset_id": "67189754674778985353824371461876088774339766303744275466510582338820578610808", "price": "0.51", "size": "20", "side": "SELL", "hash": "ea49cb090c2f6f2e3db32694ff004b3e5150fb32", "best_bid": "0.05", "best_ask": "0.25"}], "timestamp": "1769384540348", "event_type": "price_change"}}
{"_local_timestamp": "2026-01-25T23:42:20.508135+00:00", "data": {"market": "0x97b4a74e6ad96c4601a70bffea6b3ea48227b0676658f1a77c5e4dfeb03c1422", "price_changes": [{"asset_id": "74328021459889543390175687510268557967371044615256517664604837321395650238724", "price": "0.48", "size": "25", "side": "BUY", "hash": "64d484a953743b0a27329f314aa6dca2b84480d7", "best_bid": "0.54", "best_ask": "0.95"}, {"asset_id": "67088219062664412623221891896187729302515136551189145648713076701295675541006", "price": "0.52", "size": "25", "side": "SELL", "hash": "46306e3c7dd2d27833e51e18821d1af246f72b2c", "best_bid": "0.05", "best_ask": "0.46"}], "timestamp": "1769384540439", "event_type": "price_change"}}
{"_local_timestamp": "2026-01-25T23:42:20.521378+00:00", "data": {"market": "0xbfd944007d7204b05e19d6fdf2cbe5f3e0b8d37bfb19c15d8e1c813e8ec2dec5", "price_changes": [{"asset_id": "75413567795086771542191436050004337965652039236856821284921766890217813492508", "price": "0.5", "size": "25", "side": "BUY", "hash": "2e49cc253ad5161009494ee137ddaa390153823a", "best_bid": "0.75", "best_ask": "0.95"}, {"asset_id": "67189754674778985353824371461876088774339766303744275466510582338820578610808", "price": "0.5", "size": "25", "side": "SELL", "hash": "bc6ea2e799a41707e70c1b58ffa903186452a1e9", "best_bid": "0.05", "best_ask": "0.25"}], "timestamp": "1769384540454", "event_type": "price_change"}}
{"_local_timestamp": "2026-01-25T23:42:20.551010+00:00", "data": {"market": "0xbfd944007d7204b05e19d6fdf2cbe5f3e0b8d37bfb19c15d8e1c813e8ec2dec5", "price_changes": [{"asset_id": "75413567795086771542191436050004337965652039236856821284921766890217813492508", "price": "0.5", "size": "50", "side": "BUY", "hash": "03a4f41c9291a8897c3412661a910dc122f29b3f", "best_bid": "0.75", "best_ask": "0.95"}, {"asset_id": "67189754674778985353824371461876088774339766303744275466510582338820578610808", "price": "0.5", "size": "50", "side": "SELL", "hash": "97aec5680fdc4992d76a29f5105639bff7f5673c", "best_bid": "0.05", "best_ask": "0.25"}], "timestamp": "1769384540481", "event_type": "price_change"}}
{"_local_timestamp": "2026-01-25T23:42:20.620560+00:00", "data": {"market": "0x97b4a74e6ad96c4601a70bffea6b3ea48227b0676658f1a77c5e4dfeb03c1422", "price_changes": [{"asset_id": "74328021459889543390175687510268557967371044615256517664604837321395650238724", "price": "0.48", "size": "0", "side": "BUY", "hash": "d9e90d44dad5ab7b28917c430fe50f66e7b46932", "best_bid": "0.54", "best_ask": "0.95"}, {"asset_id": "67088219062664412623221891896187729302515136551189145648713076701295675541006", "price": "0.52", "size": "0", "side": "SELL", "hash": "af504477dd312157994e3fd503b94e665b0b2d05", "best_bid": "0.05", "best_ask": "0.46"}], "timestamp": "1769384540547", "event_type": "price_change"}}
{"_local_timestamp": "2026-01-25T23:42:21.598255+00:00", "data": {"market": "0x97b4a74e6ad96c4601a70bffea6b3ea48227b0676658f1a77c5e4dfeb03c1422", "price_changes": [{"asset_id": "74328021459889543390175687510268557967371044615256517664604837321395650238724", "price": "0.03", "size": "18.31", "side": "BUY", "hash": "9baa5542090d1ac0a2d392b6365499ec08f2d805", "best_bid": "0.54", "best_ask": "0.95"}, {"asset_id": "67088219062664412623221891896187729302515136551189145648713076701295675541006", "price": "0.97", "size": "18.31", "side": "SELL", "hash": "f254e1c03e303f415d90feb5c55381fda8e1f66d", "best_bid": "0.05", "best_ask": "0.46"}], "timestamp": "1769384541531", "event_type": "price_change"}}
{"_local_timestamp": "2026-01-25T23:42:21.706451+00:00", "data": {"market": "0x97b4a74e6ad96c4601a70bffea6b3ea48227b0676658f1a77c5e4dfeb03c1422", "price_changes": [{"asset_id": "74328021459889543390175687510268557967371044615256517664604837321395650238724", "price": "0.2", "size": "50", "side": "BUY", "hash": "2558527f7bb632e9f3bb7fff3c4dded271aa2c0f", "best_bid": "0.54", "best_ask": "0.95"}, {"asset_id": "67088219062664412623221891896187729302515136551189145648713076701295675541006", "price": "0.8", "size": "50", "side": "SELL", "hash": "2bee83f645996c661493106f0c55d6727be51880", "best_bid": "0.05", "best_ask": "0.46"}], "timestamp": "1769384541641", "event_type": "price_change"}}
{"_local_timestamp": "2026-01-25T23:42:21.714465+00:00", "data": {"market": "0x97b4a74e6ad96c4601a70bffea6b3ea48227b0676658f1a77c5e4dfeb03c1422", "price_changes": [{"asset_id": "74328021459889543390175687510268557967371044615256517664604837321395650238724", "price": "0.04", "size": "800", "side": "BUY", "hash": "17259fd691ca988a801ab38a33ecab63574dc6ba", "best_bid": "0.54", "best_ask": "0.95"}, {"asset_id": "67088219062664412623221891896187729302515136551189145648713076701295675541006", "price": "0.96", "size": "800", "side": "SELL", "hash": "9a53183ee751eb949db7a6ce4a9a331499ceec2a", "best_bid": "0.05", "best_ask": "0.46"}], "timestamp": "1769384541646", "event_type": "price_change"}}
{"_local_timestamp": "2026-01-25T23:42:21.820007+00:00", "data": {"market": "0x97b4a74e6ad96c4601a70bffea6b3ea48227b0676658f1a77c5e4dfeb03c1422", "price_changes": [{"asset_id": "74328021459889543390175687510268557967371044615256517664604837321395650238724", "price": "0.04", "size": "0", "side": "BUY", "hash": "6173c954847622b63ff631c4e5f21e55035d29a2", "best_bid": "0.54", "best_ask": "0.95"}, {"asset_id": "67088219062664412623221891896187729302515136551189145648713076701295675541006", "price": "0.96", "size": "0", "side": "SELL", "hash": "2d1f32919b8b2f9c5b185230334dfd66ea0f9174", "best_bid": "0.05", "best_ask": "0.46"}], "timestamp": "1769384541752", "event_type": "price_change"}}
{"_local_timestamp": "2026-01-25T23:42:22.596303+00:00", "data": {"market": "0x97b4a74e6ad96c4601a70bffea6b3ea48227b0676658f1a77c5e4dfeb03c1422", "price_changes": [{"asset_id": "74328021459889543390175687510268557967371044615256517664604837321395650238724", "price": "0.49", "size": "0", "side": "BUY", "hash": "eb70e9342b6e78c3f8466621f13cfa0eb59e78f1", "best_bid": "0.54", "best_ask": "0.95"}, {"asset_id": "67088219062664412623221891896187729302515136551189145648713076701295675541006", "price": "0.51", "size": "0", "side": "SELL", "hash": "9180126915149a4851409c028ff8c43c5633c5ee", "best_bid": "0.05", "best_ask": "0.46"}], "timestamp": "1769384542522", "event_type": "price_change"}}
{"_local_timestamp": "2026-01-25T23:42:22.598571+00:00", "data": {"market": "0xbfd944007d7204b05e19d6fdf2cbe5f3e0b8d37bfb19c15d8e1c813e8ec2dec5", "price_changes": [{"asset_id": "75413567795086771542191436050004337965652039236856821284921766890217813492508", "price": "0.49", "size": "0", "side": "BUY", "hash": "d6ff2110310a5c1cd8d27a913c58e10052dc412b", "best_bid": "0.75", "best_ask": "0.95"}, {"asset_id": "67189754674778985353824371461876088774339766303744275466510582338820578610808", "price": "0.51", "size": "0", "side": "SELL", "hash": "5a4949771f928600c29b1140202f93d308aedbbd", "best_bid": "0.05", "best_ask": "0.25"}], "timestamp": "1769384542522", "event_type": "price_change"}}
{"_local_timestamp": "2026-01-25T23:42:22.618509+00:00", "data": {"market": "0x97b4a74e6ad96c4601a70bffea6b3ea48227b0676658f1a77c5e4dfeb03c1422", "price_changes": [{"asset_id": "74328021459889543390175687510268557967371044615256517664604837321395650238724", "price": "0.44", "size": "20", "side": "BUY", "hash": "6f09256500a39496a5e319dce8f54f2f7e2f6d75", "best_bid": "0.54", "best_ask": "0.95"}, {"asset_id": "67088219062664412623221891896187729302515136551189145648713076701295675541006", "price": "0.56", "size": "20", "side": "SELL", "hash": "709d410e65895de590213ba3999cde629c78bc54", "best_bid": "0.05", "best_ask": "0.46"}], "timestamp": "1769384542552", "event_type": "price_change"}}
{"_local_timestamp": "2026-01-25T23:42:22.629942+00:00", "data": {"market": "0xbfd944007d7204b05e19d6fdf2cbe5f3e0b8d37bfb19c15d8e1c813e8ec2dec5", "price_changes": [{"asset_id": "75413567795086771542191436050004337965652039236856821284921766890217813492508", "price": "0.51", "size": "20", "side": "BUY", "hash": "8a72d5d6194bc9e1f4050e96570beb29d5900017", "best_bid": "0.75", "best_ask": "0.95"}, {"asset_id": "67189754674778985353824371461876088774339766303744275466510582338820578610808", "price": "0.49", "size": "20", "side": "SELL", "hash": "d67d3484dc62b13fe1bf3888e8ab25fee50f6a6a", "best_bid": "0.05", "best_ask": "0.25"}], "timestamp": "1769384542552", "event_type": "price_change"}}
{"_local_timestamp": "2026-01-25T23:42:22.709890+00:00", "data": {"market": "0x97b4a74e6ad96c4601a70bffea6b3ea48227b0676658f1a77c5e4dfeb03c1422", "price_changes": [{"asset_id": "74328021459889543390175687510268557967371044615256517664604837321395650238724", "price": "0.2", "size": "100", "side": "BUY", "hash": "f0da0d1b7c78bce318cf915b751933687c17fabd", "best_bid": "0.54", "best_ask": "0.95"}, {"asset_id": "67088219062664412623221891896187729302515136551189145648713076701295675541006", "price": "0.8", "size": "100", "side": "SELL", "hash": "926c985daab0dc7ab256d9c696137ff853627194", "best_bid": "0.05", "best_ask": "0.46"}], "timestamp": "1769384542648", "event_type": "price_change"}}
{"_local_timestamp": "2026-01-25T23:42:22.731876+00:00", "data": {"market": "0xbfd944007d7204b05e19d6fdf2cbe5f3e0b8d37bfb19c15d8e1c813e8ec2dec5", "price_changes": [{"asset_id": "75413567795086771542191436050004337965652039236856821284921766890217813492508", "price": "0.5", "size": "25", "side": "BUY", "hash": "728d2f00e617dc6e5e3ab9b206a09f840ab02e2f", "best_bid": "0.75", "best_ask": "0.95"}, {"asset_id": "67189754674778985353824371461876088774339766303744275466510582338820578610808", "price": "0.5", "size": "25", "side": "SELL", "hash": "6422dc3a7b5a9c6048c5b517c79d8f0a3c9d13a6", "best_bid": "0.05", "best_ask": "0.25"}], "timestamp": "1769384542666", "event_type": "price_change"}}
{"_local_timestamp": "2026-01-25T23:42:22.738321+00:00", "data": {"market": "0x97b4a74e6ad96c4601a70bffea6b3ea48227b0676658f1a77c5e4dfeb03c1422", "price_changes": [{"asset_id": "74328021459889543390175687510268557967371044615256517664604837321395650238724", "price": "0.48", "size": "25", "side": "BUY", "hash": "8f8058cc0c113af5e000ffc81940a0617fa7671c", "best_bid": "0.54", "best_ask": "0.95"}, {"asset_id": "67088219062664412623221891896187729302515136551189145648713076701295675541006", "price": "0.52", "size": "25", "side": "SELL", "hash": "b1f60aed2cdabe9cb1f67122874216e5f1c45d1f", "best_bid": "0.05", "best_ask": "0.46"}], "timestamp": "1769384542677", "event_type": "price_change"}}
{"_local_timestamp": "2026-01-25T23:42:22.755357+00:00", "data": {"market": "0x97b4a74e6ad96c4601a70bffea6b3ea48227b0676658f1a77c5e4dfeb03c1422", "price_changes": [{"asset_id": "74328021459889543390175687510268557967371044615256517664604837321395650238724", "price": "0.2", "size": "50", "side": "BUY", "hash": "802dc62bec6243eebb79143af1951ed6c49bbfb6", "best_bid": "0.54", "best_ask": "0.95"}, {"asset_id": "67088219062664412623221891896187729302515136551189145648713076701295675541006", "price": "0.8", "size": "50", "side": "SELL", "hash": "929d07cf946c629cad7d3bc5c182b75107dbc647", "best_bid": "0.05", "best_ask": "0.46"}], "timestamp": "1769384542691", "event_type": "price_change"}}
{"_local_timestamp": "2026-01-25T23:42:22.767398+00:00", "data": {"market": "0xbfd944007d7204b05e19d6fdf2cbe5f3e0b8d37bfb19c15d8e1c813e8ec2dec5", "price_changes": [{"asset_id": "75413567795086771542191436050004337965652039236856821284921766890217813492508", "price": "0.5", "size": "0", "side": "BUY", "hash": "a5844fa57fab534af76055d12a651ad5e4530a2b", "best_bid": "0.75", "best_ask": "0.95"}, {"asset_id": "67189754674778985353824371461876088774339766303744275466510582338820578610808", "price": "0.5", "size": "0", "side": "SELL", "hash": "52b50e6c8c17eb1a740fbb0795485b84d4ed09e2", "best_bid": "0.05", "best_ask": "0.25"}], "timestamp": "1769384542699", "event_type": "price_change"}}
{"_local_timestamp": "2026-01-25T23:42:22.819518+00:00", "data": {"market": "0x97b4a74e6ad96c4601a70bffea6b3ea48227b0676658f1a77c5e4dfeb03c1422", "price_changes": [{"asset_id": "74328021459889543390175687510268557967371044615256517664604837321395650238724", "price": "0.2", "size": "0", "side": "BUY", "hash": "8ca9f31ba6a694095fa447b28d7f953ab60bd7b3", "best_bid": "0.54", "best_ask": "0.95"}, {"asset_id": "67088219062664412623221891896187729302515136551189145648713076701295675541006", "price": "0.8", "size": "0", "side": "SELL", "hash": "e0ebd807e01d6a6473046a81ba28f81fe4a82b96", "best_bid": "0.05", "best_ask": "0.46"}], "timestamp": "1769384542751", "event_type": "price_change"}}
{"_local_timestamp": "2026-01-25T23:42:23.692566+00:00", "data": {"market": "0x97b4a74e6ad96c4601a70bffea6b3ea48227b0676658f1a77c5e4dfeb03c1422", "price_changes": [{"asset_id": "74328021459889543390175687510268557967371044615256517664604837321395650238724", "price": "0.44", "size": "0", "side": "BUY", "hash": "921deb997ae5cd257dc2e89dc9266af53795d613", "best_bid": "0.54", "best_ask": "0.95"}, {"asset_id": "67088219062664412623221891896187729302515136551189145648713076701295675541006", "price": "0.56", "size": "0", "side": "SELL", "hash": "4fd98203893a09f4d4c5760517cc46e1ab5cb3f0", "best_bid": "0.05", "best_ask": "0.46"}], "timestamp": "1769384543625", "event_type": "price_change"}}
{"_local_timestamp": "2026-01-25T23:42:23.694360+00:00", "data": {"market": "0xbfd944007d7204b05e19d6fdf2cbe5f3e0b8d37bfb19c15d8e1c813e8ec2dec5", "price_changes": [{"asset_id": "75413567795086771542191436050004337965652039236856821284921766890217813492508", "price": "0.51", "size": "0", "side": "BUY", "hash": "f00ea7cc9af02f543b59faadb4708a2d97d12740", "best_bid": "0.75", "best_ask": "0.95"}, {"asset_id": "67189754674778985353824371461876088774339766303744275466510582338820578610808", "price": "0.49", "size": "0", "side": "SELL", "hash": "d0f12f825d7b78fed3aace32312763ece7cdc1c4", "best_bid": "0.05", "best_ask": "0.25"}], "timestamp": "1769384543625", "event_type": "price_change"}}
{"_local_timestamp": "2026-01-25T23:42:23.719874+00:00", "data": {"market": "0x97b4a74e6ad96c4601a70bffea6b3ea48227b0676658f1a77c5e4dfeb03c1422", "price_changes": [{"asset_id": "74328021459889543390175687510268557967371044615256517664604837321395650238724", "price": "0.49", "size": "20", "side": "BUY", "hash": "7097b238d9ea50be7e77217cfe5846e08a4a4c5e", "best_bid": "0.54", "best_ask": "0.95"}, {"asset_id": "67088219062664412623221891896187729302515136551189145648713076701295675541006", "price": "0.51", "size": "20", "side": "SELL", "hash": "76865c97edc5900ce2aaed890ac09c241ca0d6bc", "best_bid": "0.05", "best_ask": "0.46"}], "timestamp": "1769384543653", "event_type": "price_change"}}
{"_local_timestamp": "2026-01-25T23:42:23.721635+00:00", "data": {"market": "0xbfd944007d7204b05e19d6fdf2cbe5f3e0b8d37bfb19c15d8e1c813e8ec2dec5", "price_changes": [{"asset_id": "75413567795086771542191436050004337965652039236856821284921766890217813492508", "price": "0.49", "size": "20", "side": "BUY", "hash": "498964a09271373c2e15acbacefc4ae057d32c95", "best_bid": "0.75", "best_ask": "0.95"}, {"asset_id": "67189754674778985353824371461876088774339766303744275466510582338820578610808", "price": "0.51", "size": "20", "side": "SELL", "hash": "3600ae808e6f8f902de0837ec3db34d0ab99b2f8", "best_bid": "0.05", "best_ask": "0.25"}], "timestamp": "1769384543653", "event_type": "price_change"}}
{"_local_timestamp": "2026-01-25T23:42:23.874220+00:00", "data": {"market": "0xbfd944007d7204b05e19d6fdf2cbe5f3e0b8d37bfb19c15d8e1c813e8ec2dec5", "price_changes": [{"asset_id": "75413567795086771542191436050004337965652039236856821284921766890217813492508", "price": "0.5", "size": "25", "side": "BUY", "hash": "5508ce55ac8f853f343062148b58f0ac30fa97b8", "best_bid": "0.75", "best_ask": "0.95"}, {"asset_id": "67189754674778985353824371461876088774339766303744275466510582338820578610808", "price": "0.5", "size": "25", "side": "SELL", "hash": "1e12b2a402e3f9107bf49c3daf609cd9e502e520", "best_bid": "0.05", "best_ask": "0.25"}], "timestamp": "1769384543768", "event_type": "price_change"}}
{"_local_timestamp": "2026-01-25T23:42:23.876158+00:00", "data": {"market": "0xbfd944007d7204b05e19d6fdf2cbe5f3e0b8d37bfb19c15d8e1c813e8ec2dec5", "price_changes": [{"asset_id": "75413567795086771542191436050004337965652039236856821284921766890217813492508", "price": "0.5", "size": "50", "side": "BUY", "hash": "4e21b0f89db1f500564fc396cbc080f71b68adaa", "best_bid": "0.75", "best_ask": "0.95"}, {"asset_id": "67189754674778985353824371461876088774339766303744275466510582338820578610808", "price": "0.5", "size": "50", "side": "SELL", "hash": "783d483e62053c2d34502a3024a4cfe2933dc4fc", "best_bid": "0.05", "best_ask": "0.25"}], "timestamp": "1769384543770", "event_type": "price_change"}}
{"_local_timestamp": "2026-01-25T23:42:23.877952+00:00", "data": {"market": "0x97b4a74e6ad96c4601a70bffea6b3ea48227b0676658f1a77c5e4dfeb03c1422", "price_changes": [{"asset_id": "74328021459889543390175687510268557967371044615256517664604837321395650238724", "price": "0.48", "size": "50", "side": "BUY", "hash": "394de41603884dfcd9391515059ae1393997ea02", "best_bid": "0.54", "best_ask": "0.95"}, {"asset_id": "67088219062664412623221891896187729302515136551189145648713076701295675541006", "price": "0.52", "size": "50", "side": "SELL", "hash": "055c8fc4dca8ba9d0ad3f2853992d16c5f484bce", "best_bid": "0.05", "best_ask": "0.46"}], "timestamp": "1769384543774", "event_type": "price_change"}}
{"_local_timestamp": "2026-01-25T23:42:23.879648+00:00", "data": {"market": "0x97b4a74e6ad96c4601a70bffea6b3ea48227b0676658f1a77c5e4dfeb03c1422", "price_changes": [{"asset_id": "74328021459889543390175687510268557967371044615256517664604837321395650238724", "price": "0.48", "size": "25", "side": "BUY", "hash": "cb0c0df0fbd321a66123aa86845c8b1caebbdce0", "best_bid": "0.54", "best_ask": "0.95"}, {"asset_id": "67088219062664412623221891896187729302515136551189145648713076701295675541006", "price": "0.52", "size": "25", "side": "SELL", "hash": "db6b00e29ec9d981383a68b01ef96a106c4dcd70", "best_bid": "0.05", "best_ask": "0.46"}], "timestamp": "1769384543774", "event_type": "price_change"}}
{"_local_timestamp": "2026-01-25T23:42:23.947044+00:00", "data": {"market": "0x97b4a74e6ad96c4601a70bffea6b3ea48227b0676658f1a77c5e4dfeb03c1422", "price_changes": [{"asset_id": "74328021459889543390175687510268557967371044615256517664604837321395650238724", "price": "0.48", "size": "0", "side": "BUY", "hash": "8f70aba209f4323c53dad7f53324fb42fc5b4671", "best_bid": "0.54", "best_ask": "0.95"}, {"asset_id": "67088219062664412623221891896187729302515136551189145648713076701295675541006", "price": "0.52", "size": "0", "side": "SELL", "hash": "1ec023dd36a9e1dfc4aa9817246da9a9b01e7607", "best_bid": "0.05", "best_ask": "0.46"}], "timestamp": "1769384543879", "event_type": "price_change"}}
{"_local_timestamp": "2026-01-25T23:42:25.316883+00:00", "data": {"market": "0x97b4a74e6ad96c4601a70bffea6b3ea48227b0676658f1a77c5e4dfeb03c1422", "price_changes": [{"asset_id": "74328021459889543390175687510268557967371044615256517664604837321395650238724", "price": "0.49", "size": "0", "side": "BUY", "hash": "169fce05a27d178db21e7181f16a42904c99ba0a", "best_bid": "0.54", "best_ask": "0.95"}, {"asset_id": "67088219062664412623221891896187729302515136551189145648713076701295675541006", "price": "0.51", "size": "0", "side": "SELL", "hash": "478b1e2565d8a20b9385389b7d84d42929cef3dd", "best_bid": "0.05", "best_ask": "0.46"}], "timestamp": "1769384545188", "event_type": "price_change"}}
{"_local_timestamp": "2026-01-25T23:42:25.318700+00:00", "data": {"market": "0xbfd944007d7204b05e19d6fdf2cbe5f3e0b8d37bfb19c15d8e1c813e8ec2dec5", "price_changes": [{"asset_id": "75413567795086771542191436050004337965652039236856821284921766890217813492508", "price": "0.49", "size": "0", "side": "BUY", "hash": "74e253031b5a196118e3ee945a0851850cda9ff3", "best_bid": "0.75", "best_ask": "0.95"}, {"asset_id": "67189754674778985353824371461876088774339766303744275466510582338820578610808", "price": "0.51", "size": "0", "side": "SELL", "hash": "33d04afb6f6c595174f0f10d02d80adc4443b6fe", "best_bid": "0.05", "best_ask": "0.25"}], "timestamp": "1769384545188", "event_type": "price_change"}}
{"_local_timestamp": "2026-01-25T23:42:25.320327+00:00", "data": {"market": "0x97b4a74e6ad96c4601a70bffea6b3ea48227b0676658f1a77c5e4dfeb03c1422", "price_changes": [{"asset_id": "74328021459889543390175687510268557967371044615256517664604837321395650238724", "price": "0.44", "size": "20", "side": "BUY", "hash": "ff3426e45e05d4eeecf3b93fdcdd30be31832cea", "best_bid": "0.54", "best_ask": "0.95"}, {"asset_id": "67088219062664412623221891896187729302515136551189145648713076701295675541006", "price": "0.56", "size": "20", "side": "SELL", "hash": "c5a84f56d66499c274fa842b3db0389d9609c3ce", "best_bid": "0.05", "best_ask": "0.46"}], "timestamp": "1769384545215", "event_type": "price_change"}}
{"_local_timestamp": "2026-01-25T23:42:25.321973+00:00", "data": {"market": "0xbfd944007d7204b05e19d6fdf2cbe5f3e0b8d37bfb19c15d8e1c813e8ec2dec5", "price_changes": [{"asset_id": "75413567795086771542191436050004337965652039236856821284921766890217813492508", "price": "0.51", "size": "20", "side": "BUY", "hash": "8a11e3042857b86e7f4757f6463b4a63554e9bb0", "best_bid": "0.75", "best_ask": "0.95"}, {"asset_id": "67189754674778985353824371461876088774339766303744275466510582338820578610808", "price": "0.49", "size": "20", "side": "SELL", "hash": "0ca192b9f47531c17ec6d116a082b15361f20658", "best_bid": "0.05", "best_ask": "0.25"}], "timestamp": "1769384545215", "event_type": "price_change"}}
{"_local_timestamp": "2026-01-25T23:42:25.452224+00:00", "data": {"market": "0xbfd944007d7204b05e19d6fdf2cbe5f3e0b8d37bfb19c15d8e1c813e8ec2dec5", "price_changes": [{"asset_id": "75413567795086771542191436050004337965652039236856821284921766890217813492508", "price": "0.5", "size": "25", "side": "BUY", "hash": "ff41c54e6d9dd77c0d46a554ef481f32d943ca82", "best_bid": "0.75", "best_ask": "0.95"}, {"asset_id": "67189754674778985353824371461876088774339766303744275466510582338820578610808", "price": "0.5", "size": "25", "side": "SELL", "hash": "ffe9509ccd989e083832403d0f6c9663f54748da", "best_bid": "0.05", "best_ask": "0.25"}], "timestamp": "1769384545369", "event_type": "price_change"}}
{"_local_timestamp": "2026-01-25T23:42:25.468444+00:00", "data": {"market": "0x97b4a74e6ad96c4601a70bffea6b3ea48227b0676658f1a77c5e4dfeb03c1422", "price_changes": [{"asset_id": "74328021459889543390175687510268557967371044615256517664604837321395650238724", "price": "0.48", "size": "25", "side": "BUY", "hash": "596fde2c2dc1c54ad9f98b082060b72887817dbf", "best_bid": "0.54", "best_ask": "0.95"}, {"asset_id": "67088219062664412623221891896187729302515136551189145648713076701295675541006", "price": "0.52", "size": "25", "side": "SELL", "hash": "f684a2b7662fcb2bc492674bcbeff7bddeff595c", "best_bid": "0.05", "best_ask": "0.46"}], "timestamp": "1769384545378", "event_type": "price_change"}}
{"_local_timestamp": "2026-01-25T23:42:25.470318+00:00", "data": {"market": "0xbfd944007d7204b05e19d6fdf2cbe5f3e0b8d37bfb19c15d8e1c813e8ec2dec5", "price_changes": [{"asset_id": "75413567795086771542191436050004337965652039236856821284921766890217813492508", "price": "0.5", "size": "0", "side": "BUY", "hash": "53064f51f4d22bcd5f5d007f717ffe955e4e6b58", "best_bid": "0.75", "best_ask": "0.95"}, {"asset_id": "67189754674778985353824371461876088774339766303744275466510582338820578610808", "price": "0.5", "size": "0", "side": "SELL", "hash": "8692c567a09dfd7b94f4837dc2b3211a597f3128", "best_bid": "0.05", "best_ask": "0.25"}], "timestamp": "1769384545385", "event_type": "price_change"}}
{"_local_timestamp": "2026-01-25T23:42:25.474860+00:00", "data": {"market": "0x97b4a74e6ad96c4601a70bffea6b3ea48227b0676658f1a77c5e4dfeb03c1422", "price_changes": [{"asset_id": "74328021459889543390175687510268557967371044615256517664604837321395650238724", "price": "0.48", "size": "50", "side": "BUY", "hash": "702e10d847020ecc28426ff1f836d8d780ee7cb0", "best_bid": "0.54", "best_ask": "0.95"}, {"asset_id": "67088219062664412623221891896187729302515136551189145648713076701295675541006", "price": "0.52", "size": "50", "side": "SELL", "hash": "a66dc7c9495dda3ec98f9ab79f3a0b0921532c33", "best_bid": "0.05", "best_ask": "0.46"}], "timestamp": "1769384545405", "event_type": "price_change"}}
{"_local_timestamp": "2026-01-25T23:42:28.305579+00:00", "data": {"market": "0x97b4a74e6ad96c4601a70bffea6b3ea48227b0676658f1a77c5e4dfeb03c1422", "price_changes": [{"asset_id": "74328021459889543390175687510268557967371044615256517664604837321395650238724", "price": "0.44", "size": "0", "side": "BUY", "hash": "fe922788d4844d099bc010878251926df00ca326", "best_bid": "0.54", "best_ask": "0.95"}, {"asset_id": "67088219062664412623221891896187729302515136551189145648713076701295675541006", "price": "0.56", "size": "0", "side": "SELL", "hash": "de27106ff90585526f463b29368d8f36e812839b", "best_bid": "0.05", "best_ask": "0.46"}], "timestamp": "1769384548241", "event_type": "price_change"}}
{"_local_timestamp": "2026-01-25T23:42:28.307380+00:00", "data": {"market": "0xbfd944007d7204b05e19d6fdf2cbe5f3e0b8d37bfb19c15d8e1c813e8ec2dec5", "price_changes": [{"asset_id": "75413567795086771542191436050004337965652039236856821284921766890217813492508", "price": "0.51", "size": "0", "side": "BUY", "hash": "6f1fa33b8b5ad030d4622cc6ed3b6310c0402858", "best_bid": "0.75", "best_ask": "0.95"}, {"asset_id": "67189754674778985353824371461876088774339766303744275466510582338820578610808", "price": "0.49", "size": "0", "side": "SELL", "hash": "cddf1d7997aa38734d2a15fc7fc0bec13fb03bfb", "best_bid": "0.05", "best_ask": "0.25"}], "timestamp": "1769384548241", "event_type": "price_change"}}
{"_local_timestamp": "2026-01-25T23:42:28.355390+00:00", "data": {"market": "0x97b4a74e6ad96c4601a70bffea6b3ea48227b0676658f1a77c5e4dfeb03c1422", "price_changes": [{"asset_id": "74328021459889543390175687510268557967371044615256517664604837321395650238724", "price": "0.49", "size": "20", "side": "BUY", "hash": "a9dc25c9cf469a32293560eaafefb8ec97403a27", "best_bid": "0.54", "best_ask": "0.95"}, {"asset_id": "67088219062664412623221891896187729302515136551189145648713076701295675541006", "price": "0.51", "size": "20", "side": "SELL", "hash": "60a40379ac764cfafd2f89ad9439f98fb4b586f4", "best_bid": "0.05", "best_ask": "0.46"}], "timestamp": "1769384548284", "event_type": "price_change"}}
{"_local_timestamp": "2026-01-25T23:42:28.357342+00:00", "data": {"market": "0xbfd944007d7204b05e19d6fdf2cbe5f3e0b8d37bfb19c15d8e1c813e8ec2dec5", "price_changes": [{"asset_id": "75413567795086771542191436050004337965652039236856821284921766890217813492508", "price": "0.49", "size": "20", "side": "BUY", "hash": "1b58c844bc81584c768c1a4b8106a082331b63e0", "best_bid": "0.75", "best_ask": "0.95"}, {"asset_id": "67189754674778985353824371461876088774339766303744275466510582338820578610808", "price": "0.51", "size": "20", "side": "SELL", "hash": "bd5aa7c0f0923a9caa597d01f3e4a7485a74d844", "best_bid": "0.05", "best_ask": "0.25"}], "timestamp": "1769384548284", "event_type": "price_change"}}
{"_local_timestamp": "2026-01-25T23:42:28.439002+00:00", "data": {"market": "0x97b4a74e6ad96c4601a70bffea6b3ea48227b0676658f1a77c5e4dfeb03c1422", "price_changes": [{"asset_id": "74328021459889543390175687510268557967371044615256517664604837321395650238724", "price": "0.48", "size": "25", "side": "BUY", "hash": "a23ad095a0591f85ac51260f990ee940c29d2fd3", "best_bid": "0.54", "best_ask": "0.95"}, {"asset_id": "67088219062664412623221891896187729302515136551189145648713076701295675541006", "price": "0.52", "size": "25", "side": "SELL", "hash": "3f1a9865e1d0cace65b66098685b0f3306e452c6", "best_bid": "0.05", "best_ask": "0.46"}], "timestamp": "1769384548366", "event_type": "price_change"}}
{"_local_timestamp": "2026-01-25T23:42:28.474397+00:00", "data": {"market": "0xbfd944007d7204b05e19d6fdf2cbe5f3e0b8d37bfb19c15d8e1c813e8ec2dec5", "price_changes": [{"asset_id": "75413567795086771542191436050004337965652039236856821284921766890217813492508", "price": "0.5", "size": "25", "side": "BUY", "hash": "62e1e0d5be30e7db01cd7ce31994731f045db752", "best_bid": "0.75", "best_ask": "0.95"}, {"asset_id": "67189754674778985353824371461876088774339766303744275466510582338820578610808", "price": "0.5", "size": "25", "side": "SELL", "hash": "3d38e90b75373df4fd420598f760c1b3976f71c5", "best_bid": "0.05", "best_ask": "0.25"}], "timestamp": "1769384548405", "event_type": "price_change"}}
{"_local_timestamp": "2026-01-25T23:42:28.498462+00:00", "data": {"market": "0xbfd944007d7204b05e19d6fdf2cbe5f3e0b8d37bfb19c15d8e1c813e8ec2dec5", "price_changes": [{"asset_id": "75413567795086771542191436050004337965652039236856821284921766890217813492508", "price": "0.5", "size": "50", "side": "BUY", "hash": "e51466b057f3a5ddfc620bf5124883af74d1de0d", "best_bid": "0.75", "best_ask": "0.95"}, {"asset_id": "67189754674778985353824371461876088774339766303744275466510582338820578610808", "price": "0.5", "size": "50", "side": "SELL", "hash": "b8615fb701b9a814a99167a3ddd2068ec11bf567", "best_bid": "0.05", "best_ask": "0.25"}], "timestamp": "1769384548434", "event_type": "price_change"}}
{"_local_timestamp": "2026-01-25T23:42:28.562440+00:00", "data": {"market": "0x97b4a74e6ad96c4601a70bffea6b3ea48227b0676658f1a77c5e4dfeb03c1422", "price_changes": [{"asset_id": "74328021459889543390175687510268557967371044615256517664604837321395650238724", "price": "0.48", "size": "0", "side": "BUY", "hash": "925c5ef4b197a1ca771d60257ecbb3c005fd87ef", "best_bid": "0.54", "best_ask": "0.95"}, {"asset_id": "67088219062664412623221891896187729302515136551189145648713076701295675541006", "price": "0.52", "size": "0", "side": "SELL", "hash": "bf4b9b1ec5d792e044e96a2a1b1d26e7534b619c", "best_bid": "0.05", "best_ask": "0.46"}], "timestamp": "1769384548491", "event_type": "price_change"}}
{"_local_timestamp": "2026-01-25T23:42:32.162561+00:00", "data": {"market": "0x97b4a74e6ad96c4601a70bffea6b3ea48227b0676658f1a77c5e4dfeb03c1422", "price_changes": [{"asset_id": "74328021459889543390175687510268557967371044615256517664604837321395650238724", "price": "0.49", "size": "0", "side": "BUY", "hash": "93fdc553411cbfb1d982ddea41246d59574cff1b", "best_bid": "0.54", "best_ask": "0.95"}, {"asset_id": "67088219062664412623221891896187729302515136551189145648713076701295675541006", "price": "0.51", "size": "0", "side": "SELL", "hash": "6bf8d08ef16ff3caaefad66ab344c186f3084750", "best_bid": "0.05", "best_ask": "0.46"}], "timestamp": "1769384552093", "event_type": "price_change"}}
{"_local_timestamp": "2026-01-25T23:42:32.164452+00:00", "data": {"market": "0xbfd944007d7204b05e19d6fdf2cbe5f3e0b8d37bfb19c15d8e1c813e8ec2dec5", "price_changes": [{"asset_id": "75413567795086771542191436050004337965652039236856821284921766890217813492508", "price": "0.49", "size": "0", "side": "BUY", "hash": "15d2318c6d1f1714f149b72fc472542a0f343a78", "best_bid": "0.75", "best_ask": "0.95"}, {"asset_id": "67189754674778985353824371461876088774339766303744275466510582338820578610808", "price": "0.51", "size": "0", "side": "SELL", "hash": "6faf92af8b9bc80513e9368fb817749c47ffbf23", "best_bid": "0.05", "best_ask": "0.25"}], "timestamp": "1769384552093", "event_type": "price_change"}}
{"_local_timestamp": "2026-01-25T23:42:32.203598+00:00", "data": {"market": "0x97b4a74e6ad96c4601a70bffea6b3ea48227b0676658f1a77c5e4dfeb03c1422", "price_changes": [{"asset_id": "74328021459889543390175687510268557967371044615256517664604837321395650238724", "price": "0.44", "size": "20", "side": "BUY", "hash": "bded9586a288d52e32e34c9091316dc1ccbabd13", "best_bid": "0.54", "best_ask": "0.95"}, {"asset_id": "67088219062664412623221891896187729302515136551189145648713076701295675541006", "price": "0.56", "size": "20", "side": "SELL", "hash": "0abc386106460448e45d199dafca356804469b8a", "best_bid": "0.05", "best_ask": "0.46"}], "timestamp": "1769384552131", "event_type": "price_change"}}
{"_local_timestamp": "2026-01-25T23:42:32.205301+00:00", "data": {"market": "0xbfd944007d7204b05e19d6fdf2cbe5f3e0b8d37bfb19c15d8e1c813e8ec2dec5", "price_changes": [{"asset_id": "75413567795086771542191436050004337965652039236856821284921766890217813492508", "price": "0.51", "size": "20", "side": "BUY", "hash": "c37c077043bc2805b77499c8ddd6ac6004935266", "best_bid": "0.75", "best_ask": "0.95"}, {"asset_id": "67189754674778985353824371461876088774339766303744275466510582338820578610808", "price": "0.49", "size": "20", "side": "SELL", "hash": "38fb3315cab5fc61db431ab46e5a115736f13a59", "best_bid": "0.05", "best_ask": "0.25"}], "timestamp": "1769384552131", "event_type": "price_change"}}
{"_local_timestamp": "2026-01-25T23:42:32.316020+00:00", "data": {"market": "0x97b4a74e6ad96c4601a70bffea6b3ea48227b0676658f1a77c5e4dfeb03c1422", "price_changes": [{"asset_id": "74328021459889543390175687510268557967371044615256517664604837321395650238724", "price": "0.48", "size": "25", "side": "BUY", "hash": "fc79941c5f031f708d60745745583318424b3a1e", "best_bid": "0.54", "best_ask": "0.95"}, {"asset_id": "67088219062664412623221891896187729302515136551189145648713076701295675541006", "price": "0.52", "size": "25", "side": "SELL", "hash": "426f2deb533387cadf84779b68e79ff1fe5bc748", "best_bid": "0.05", "best_ask": "0.46"}], "timestamp": "1769384552238", "event_type": "price_change"}}
{"_local_timestamp": "2026-01-25T23:42:32.318157+00:00", "data": {"market": "0xbfd944007d7204b05e19d6fdf2cbe5f3e0b8d37bfb19c15d8e1c813e8ec2dec5", "price_changes": [{"asset_id": "75413567795086771542191436050004337965652039236856821284921766890217813492508", "price": "0.5", "size": "25", "side": "BUY", "hash": "54aba7fd7b91d9d392044adc9091fc25d946544a", "best_bid": "0.75", "best_ask": "0.95"}, {"asset_id": "67189754674778985353824371461876088774339766303744275466510582338820578610808", "price": "0.5", "size": "25", "side": "SELL", "hash": "8af0a31f0aa121ce4c33395ee2d4a178461eacac", "best_bid": "0.05", "best_ask": "0.25"}], "timestamp": "1769384552238", "event_type": "price_change"}}
{"_local_timestamp": "2026-01-25T23:42:32.323173+00:00", "data": {"market": "0x97b4a74e6ad96c4601a70bffea6b3ea48227b0676658f1a77c5e4dfeb03c1422", "price_changes": [{"asset_id": "74328021459889543390175687510268557967371044615256517664604837321395650238724", "price": "0.48", "size": "50", "side": "BUY", "hash": "9d2a32b2fb4a1d17a02569dc8f70b7aa2dab1b98", "best_bid": "0.54", "best_ask": "0.95"}, {"asset_id": "67088219062664412623221891896187729302515136551189145648713076701295675541006", "price": "0.52", "size": "50", "side": "SELL", "hash": "e406ea35d4f6e6ebb805133b12719f141c655648", "best_bid": "0.05", "best_ask": "0.46"}], "timestamp": "1769384552245", "event_type": "price_change"}}
{"_local_timestamp": "2026-01-25T23:42:32.325043+00:00", "data": {"market": "0xbfd944007d7204b05e19d6fdf2cbe5f3e0b8d37bfb19c15d8e1c813e8ec2dec5", "price_changes": [{"asset_id": "75413567795086771542191436050004337965652039236856821284921766890217813492508", "price": "0.5", "size": "0", "side": "BUY", "hash": "e420ffd7df4a97d6c99fa8140f429196b9dd0072", "best_bid": "0.75", "best_ask": "0.95"}, {"asset_id": "67189754674778985353824371461876088774339766303744275466510582338820578610808", "price": "0.5", "size": "0", "side": "SELL", "hash": "5d38b7cecaaff55e6b0b92fd9a2dc770e327da9f", "best_bid": "0.05", "best_ask": "0.25"}], "timestamp": "1769384552246", "event_type": "price_change"}}
{"_local_timestamp": "2026-01-25T23:42:35.576848+00:00", "data": {"market": "0x97b4a74e6ad96c4601a70bffea6b3ea48227b0676658f1a77c5e4dfeb03c1422", "price_changes": [{"asset_id": "74328021459889543390175687510268557967371044615256517664604837321395650238724", "price": "0.44", "size": "0", "side": "BUY", "hash": "ccbbe2ec0523b5c5559f05d0ffb2ee9bbafbb06b", "best_bid": "0.54", "best_ask": "0.95"}, {"asset_id": "67088219062664412623221891896187729302515136551189145648713076701295675541006", "price": "0.56", "size": "0", "side": "SELL", "hash": "b48f7217c35e5fd7f9c92f70e8b36c2662703424", "best_bid": "0.05", "best_ask": "0.46"}], "timestamp": "1769384555505", "event_type": "price_change"}}
{"_local_timestamp": "2026-01-25T23:42:35.578628+00:00", "data": {"market": "0xbfd944007d7204b05e19d6fdf2cbe5f3e0b8d37bfb19c15d8e1c813e8ec2dec5", "price_changes": [{"asset_id": "75413567795086771542191436050004337965652039236856821284921766890217813492508", "price": "0.51", "size": "0", "side": "BUY", "hash": "17c3d8c16528dcb49b7dcfe04a986a3d9c864ee4", "best_bid": "0.75", "best_ask": "0.95"}, {"asset_id": "67189754674778985353824371461876088774339766303744275466510582338820578610808", "price": "0.49", "size": "0", "side": "SELL", "hash": "ac5f9927dc025aae69a2f7ed08d794a8f859ccd9", "best_bid": "0.05", "best_ask": "0.25"}], "timestamp": "1769384555505", "event_type": "price_change"}}
{"_local_timestamp": "2026-01-25T23:42:35.602713+00:00", "data": {"market": "0x97b4a74e6ad96c4601a70bffea6b3ea48227b0676658f1a77c5e4dfeb03c1422", "price_changes": [{"asset_id": "74328021459889543390175687510268557967371044615256517664604837321395650238724", "price": "0.49", "size": "20", "side": "BUY", "hash": "86883469bcc062777f52690ff525f076ff5dd268", "best_bid": "0.54", "best_ask": "0.95"}, {"asset_id": "67088219062664412623221891896187729302515136551189145648713076701295675541006", "price": "0.51", "size": "20", "side": "SELL", "hash": "4492e9b03cd0a107541503e15dfc287cba17d3fa", "best_bid": "0.05", "best_ask": "0.46"}], "timestamp": "1769384555536", "event_type": "price_change"}}
{"_local_timestamp": "2026-01-25T23:42:35.604753+00:00", "data": {"market": "0xbfd944007d7204b05e19d6fdf2cbe5f3e0b8d37bfb19c15d8e1c813e8ec2dec5", "price_changes": [{"asset_id": "75413567795086771542191436050004337965652039236856821284921766890217813492508", "price": "0.49", "size": "20", "side": "BUY", "hash": "d4561171be575256cb285d71ffa19a681b28f72e", "best_bid": "0.75", "best_ask": "0.95"}, {"asset_id": "67189754674778985353824371461876088774339766303744275466510582338820578610808", "price": "0.51", "size": "20", "side": "SELL", "hash": "72c47b094cc9ef04b93d8195145114bd877d3796", "best_bid": "0.05", "best_ask": "0.25"}], "timestamp": "1769384555536", "event_type": "price_change"}}
{"_local_timestamp": "2026-01-25T23:42:35.673374+00:00", "data": {"market": "0x97b4a74e6ad96c4601a70bffea6b3ea48227b0676658f1a77c5e4dfeb03c1422", "price_changes": [{"asset_id": "74328021459889543390175687510268557967371044615256517664604837321395650238724", "price": "0.48", "size": "25", "side": "BUY", "hash": "e947f9e5035944b40aa3ea1e667c89cd7da4d428", "best_bid": "0.54", "best_ask": "0.95"}, {"asset_id": "67088219062664412623221891896187729302515136551189145648713076701295675541006", "price": "0.52", "size": "25", "side": "SELL", "hash": "e36b1555d3b23418377a46a0e54a232c04c87509", "best_bid": "0.05", "best_ask": "0.46"}], "timestamp": "1769384555605", "event_type": "price_change"}}
{"_local_timestamp": "2026-01-25T23:42:35.711093+00:00", "data": {"market": "0xbfd944007d7204b05e19d6fdf2cbe5f3e0b8d37bfb19c15d8e1c813e8ec2dec5", "price_changes": [{"asset_id": "75413567795086771542191436050004337965652039236856821284921766890217813492508", "price": "0.5", "size": "25", "side": "BUY", "hash": "292ddc4b277e1801fb765127071ab3819ee4da5a", "best_bid": "0.75", "best_ask": "0.95"}, {"asset_id": "67189754674778985353824371461876088774339766303744275466510582338820578610808", "price": "0.5", "size": "25", "side": "SELL", "hash": "7cad6f88cc62cca30899c54b3493f882b6a86000", "best_bid": "0.05", "best_ask": "0.25"}], "timestamp": "1769384555646", "event_type": "price_change"}}
{"_local_timestamp": "2026-01-25T23:42:35.769823+00:00", "data": {"market": "0xbfd944007d7204b05e19d6fdf2cbe5f3e0b8d37bfb19c15d8e1c813e8ec2dec5", "price_changes": [{"asset_id": "75413567795086771542191436050004337965652039236856821284921766890217813492508", "price": "0.5", "size": "50", "side": "BUY", "hash": "f4426b7943eca3fe41ec4ac002d6d605a4395dfb", "best_bid": "0.75", "best_ask": "0.95"}, {"asset_id": "67189754674778985353824371461876088774339766303744275466510582338820578610808", "price": "0.5", "size": "50", "side": "SELL", "hash": "f8eb6b96d7e128348c78ac96301def7b170c9d35", "best_bid": "0.05", "best_ask": "0.25"}], "timestamp": "1769384555699", "event_type": "price_change"}}
{"_local_timestamp": "2026-01-25T23:42:35.794933+00:00", "data": {"market": "0x97b4a74e6ad96c4601a70bffea6b3ea48227b0676658f1a77c5e4dfeb03c1422", "price_changes": [{"asset_id": "74328021459889543390175687510268557967371044615256517664604837321395650238724", "price": "0.48", "size": "0", "side": "BUY", "hash": "901a1c54dc8e78940a92760f6590d54fcaff03ce", "best_bid": "0.54", "best_ask": "0.95"}, {"asset_id": "67088219062664412623221891896187729302515136551189145648713076701295675541006", "price": "0.52", "size": "0", "side": "SELL", "hash": "d4a1d1406455eba4fb168db45d59c5be65bf9548", "best_bid": "0.05", "best_ask": "0.46"}], "timestamp": "1769384555712", "event_type": "price_change"}}
{"_local_timestamp": "2026-01-25T23:42:36.185706+00:00", "data": {"market": "0x97b4a74e6ad96c4601a70bffea6b3ea48227b0676658f1a77c5e4dfeb03c1422", "price_changes": [{"asset_id": "74328021459889543390175687510268557967371044615256517664604837321395650238724", "price": "0.53", "size": "0", "side": "BUY", "hash": "8f93720af4a7e40e60a653320a6aaff3315cdfec", "best_bid": "0.54", "best_ask": "0.95"}, {"asset_id": "67088219062664412623221891896187729302515136551189145648713076701295675541006", "price": "0.47", "size": "0", "side": "SELL", "hash": "5c0f6870a13b0382621d64d0831831fc18e200c5", "best_bid": "0.05", "best_ask": "0.46"}], "timestamp": "1769384556098", "event_type": "price_change"}}
{"_local_timestamp": "2026-01-25T23:42:36.952040+00:00", "data": {"market": "0x97b4a74e6ad96c4601a70bffea6b3ea48227b0676658f1a77c5e4dfeb03c1422", "price_changes": [{"asset_id": "67088219062664412623221891896187729302515136551189145648713076701295675541006", "price": "0.46", "size": "40", "side": "SELL", "hash": "0ab9dbcbeb9565f1904ce10f98261dbe643b0e16", "best_bid": "0.05", "best_ask": "0.46"}, {"asset_id": "74328021459889543390175687510268557967371044615256517664604837321395650238724", "price": "0.54", "size": "40", "side": "BUY", "hash": "e15bd95ebc65ace340273aa8a1ab0897f7929ac7", "best_bid": "0.54", "best_ask": "0.95"}], "timestamp": "1769384556878", "event_type": "price_change"}}
{"_local_timestamp": "2026-01-25T23:42:37.019127+00:00", "data": {"market": "0x97b4a74e6ad96c4601a70bffea6b3ea48227b0676658f1a77c5e4dfeb03c1422", "price_changes": [{"asset_id": "67088219062664412623221891896187729302515136551189145648713076701295675541006", "price": "0.56", "size": "27.89", "side": "SELL", "hash": "456b14078b6b003bfdc8d82fa632802fefc24b7e", "best_bid": "0.05", "best_ask": "0.46"}, {"asset_id": "74328021459889543390175687510268557967371044615256517664604837321395650238724", "price": "0.44", "size": "27.89", "side": "BUY", "hash": "ec8a9b539068989c2655f19f11fae1da34ec4507", "best_bid": "0.54", "best_ask": "0.95"}], "timestamp": "1769384556955", "event_type": "price_change"}}
{"_local_timestamp": "2026-01-25T23:42:37.186035+00:00", "data": {"market": "0x97b4a74e6ad96c4601a70bffea6b3ea48227b0676658f1a77c5e4dfeb03c1422", "price_changes": [{"asset_id": "74328021459889543390175687510268557967371044615256517664604837321395650238724", "price": "0.48", "size": "25", "side": "BUY", "hash": "041df0fbdf89d7a78e202f58ac016fdb5737eda9", "best_bid": "0.54", "best_ask": "0.95"}, {"asset_id": "67088219062664412623221891896187729302515136551189145648713076701295675541006", "price": "0.52", "size": "25", "side": "SELL", "hash": "5123f1e01e51b81d1734839d4e19b82cd7608cb4", "best_bid": "0.05", "best_ask": "0.46"}], "timestamp": "1769384557064", "event_type": "price_change"}}
{"_local_timestamp": "2026-01-25T23:42:37.212243+00:00", "data": {"market": "0x97b4a74e6ad96c4601a70bffea6b3ea48227b0676658f1a77c5e4dfeb03c1422", "price_changes": [{"asset_id": "74328021459889543390175687510268557967371044615256517664604837321395650238724", "price": "0.48", "size": "50", "side": "BUY", "hash": "aae6b1ab52f701dd5e6e77782208ee9e9d7f483f", "best_bid": "0.54", "best_ask": "0.95"}, {"asset_id": "67088219062664412623221891896187729302515136551189145648713076701295675541006", "price": "0.52", "size": "50", "side": "SELL", "hash": "0b0e033554a25f5cb06e2029b6b4f4f173c30c08", "best_bid": "0.05", "best_ask": "0.46"}], "timestamp": "1769384557146", "event_type": "price_change"}}
{"_local_timestamp": "2026-01-25T23:42:37.856255+00:00", "data": {"market": "0xbfd944007d7204b05e19d6fdf2cbe5f3e0b8d37bfb19c15d8e1c813e8ec2dec5", "price_changes": [{"asset_id": "75413567795086771542191436050004337965652039236856821284921766890217813492508", "price": "0.49", "size": "0", "side": "BUY", "hash": "dd23bc18137de03d013e5c3ac70c2d99da346b3a", "best_bid": "0.75", "best_ask": "0.95"}, {"asset_id": "67189754674778985353824371461876088774339766303744275466510582338820578610808", "price": "0.51", "size": "0", "side": "SELL", "hash": "5d37c717c6bd907160a22e38d47b0168fe835927", "best_bid": "0.05", "best_ask": "0.25"}], "timestamp": "1769384557795", "event_type": "price_change"}}
{"_local_timestamp": "2026-01-25T23:42:37.889531+00:00", "data": {"market": "0xbfd944007d7204b05e19d6fdf2cbe5f3e0b8d37bfb19c15d8e1c813e8ec2dec5", "price_changes": [{"asset_id": "75413567795086771542191436050004337965652039236856821284921766890217813492508", "price": "0.51", "size": "20", "side": "BUY", "hash": "6928dd833036043ef570c0fa3e810390ab02c4e3", "best_bid": "0.75", "best_ask": "0.95"}, {"asset_id": "67189754674778985353824371461876088774339766303744275466510582338820578610808", "price": "0.49", "size": "20", "side": "SELL", "hash": "f5fb72ba815b4617bad7e8f5606ef79d7cebb91e", "best_bid": "0.05", "best_ask": "0.25"}], "timestamp": "1769384557825", "event_type": "price_change"}}
{"_local_timestamp": "2026-01-25T23:42:38.005122+00:00", "data": {"market": "0xbfd944007d7204b05e19d6fdf2cbe5f3e0b8d37bfb19c15d8e1c813e8ec2dec5", "price_changes": [{"asset_id": "75413567795086771542191436050004337965652039236856821284921766890217813492508", "price": "0.5", "size": "25", "side": "BUY", "hash": "18c4882a31fa7eb9bd3d676b6dbd5862ec763637", "best_bid": "0.75", "best_ask": "0.95"}, {"asset_id": "67189754674778985353824371461876088774339766303744275466510582338820578610808", "price": "0.5", "size": "25", "side": "SELL", "hash": "d5a506608b79f3bb3ff3890abcc50f4f2e40d6ce", "best_bid": "0.05", "best_ask": "0.25"}], "timestamp": "1769384557939", "event_type": "price_change"}}
{"_local_timestamp": "2026-01-25T23:42:38.006834+00:00", "data": {"market": "0xbfd944007d7204b05e19d6fdf2cbe5f3e0b8d37bfb19c15d8e1c813e8ec2dec5", "price_changes": [{"asset_id": "75413567795086771542191436050004337965652039236856821284921766890217813492508", "price": "0.5", "size": "0", "side": "BUY", "hash": "331c29ecd1709d5b545ab23b22fc3df7a16b6305", "best_bid": "0.75", "best_ask": "0.95"}, {"asset_id": "67189754674778985353824371461876088774339766303744275466510582338820578610808", "price": "0.5", "size": "0", "side": "SELL", "hash": "c34640a6f448bfc7f6673695eaba745aa654be14", "best_bid": "0.05", "best_ask": "0.25"}], "timestamp": "1769384557939", "event_type": "price_change"}}
{"_local_timestamp": "2026-01-25T23:42:40.259908+00:00", "data": {"market": "0xbfd944007d7204b05e19d6fdf2cbe5f3e0b8d37bfb19c15d8e1c813e8ec2dec5", "price_changes": [{"asset_id": "75413567795086771542191436050004337965652039236856821284921766890217813492508", "price": "0.51", "size": "0", "side": "BUY", "hash": "0cb06fe0e8a0a9b29883bbb3ab810ccd17c2cd56", "best_bid": "0.75", "best_ask": "0.95"}, {"asset_id": "67189754674778985353824371461876088774339766303744275466510582338820578610808", "price": "0.49", "size": "0", "side": "SELL", "hash": "7898aa035977871d59e0865049323166285b188a", "best_bid": "0.05", "best_ask": "0.25"}], "timestamp": "1769384560167", "event_type": "price_change"}}
{"_local_timestamp": "2026-01-25T23:42:40.266780+00:00", "data": {"market": "0xbfd944007d7204b05e19d6fdf2cbe5f3e0b8d37bfb19c15d8e1c813e8ec2dec5", "price_changes": [{"asset_id": "75413567795086771542191436050004337965652039236856821284921766890217813492508", "price": "0.49", "size": "20", "side": "BUY", "hash": "bad9aab6f3f310ac1faec7d1e583050ba888118c", "best_bid": "0.75", "best_ask": "0.95"}, {"asset_id": "67189754674778985353824371461876088774339766303744275466510582338820578610808", "price": "0.51", "size": "20", "side": "SELL", "hash": "f365ad10f389af36f63b9f8bae71ba28a4b34d15", "best_bid": "0.05", "best_ask": "0.25"}], "timestamp": "1769384560204", "event_type": "price_change"}}
{"_local_timestamp": "2026-01-25T23:42:40.393920+00:00", "data": {"market": "0xbfd944007d7204b05e19d6fdf2cbe5f3e0b8d37bfb19c15d8e1c813e8ec2dec5", "price_changes": [{"asset_id": "75413567795086771542191436050004337965652039236856821284921766890217813492508", "price": "0.5", "size": "25", "side": "BUY", "hash": "0c7e651faa95393f263a2a49f392f870e02e5a6d", "best_bid": "0.75", "best_ask": "0.95"}, {"asset_id": "67189754674778985353824371461876088774339766303744275466510582338820578610808", "price": "0.5", "size": "25", "side": "SELL", "hash": "3b7058a6115531fd4affbe7e410431cb13d643e3", "best_bid": "0.05", "best_ask": "0.25"}], "timestamp": "1769384560326", "event_type": "price_change"}}
{"_local_timestamp": "2026-01-25T23:42:40.395861+00:00", "data": {"market": "0xbfd944007d7204b05e19d6fdf2cbe5f3e0b8d37bfb19c15d8e1c813e8ec2dec5", "price_changes": [{"asset_id": "75413567795086771542191436050004337965652039236856821284921766890217813492508", "price": "0.5", "size": "50", "side": "BUY", "hash": "80bb6651f5cc5a0f2e551c2a6aa5c8e3d335a389", "best_bid": "0.75", "best_ask": "0.95"}, {"asset_id": "67189754674778985353824371461876088774339766303744275466510582338820578610808", "price": "0.5", "size": "50", "side": "SELL", "hash": "e94aa9d5b29322fee0c76fec3b2cc38c775d6ad6", "best_bid": "0.05", "best_ask": "0.25"}], "timestamp": "1769384560331", "event_type": "price_change"}}
{"_local_timestamp": "2026-01-25T23:42:41.026590+00:00", "data": {"market": "0x97b4a74e6ad96c4601a70bffea6b3ea48227b0676658f1a77c5e4dfeb03c1422", "price_changes": [{"asset_id": "74328021459889543390175687510268557967371044615256517664604837321395650238724", "price": "0.54", "size": "0", "side": "BUY", "hash": "3fc62fc47d4a6c2bbaa414995e053669f706c553", "best_bid": "0.49", "best_ask": "0.95"}, {"asset_id": "67088219062664412623221891896187729302515136551189145648713076701295675541006", "price": "0.46", "size": "0", "side": "SELL", "hash": "833ae590e63da138355e435ab26d0b5826e0b9b8", "best_bid": "0.05", "best_ask": "0.51"}], "timestamp": "1769384560956", "event_type": "price_change"}}
{"_local_timestamp": "2026-01-25T23:42:41.053559+00:00", "data": {"market": "0x97b4a74e6ad96c4601a70bffea6b3ea48227b0676658f1a77c5e4dfeb03c1422", "price_changes": [{"asset_id": "74328021459889543390175687510268557967371044615256517664604837321395650238724", "price": "0.49", "size": "60", "side": "BUY", "hash": "9239f30ae7e364e2e1a4a7fd40584ada0c1eb404", "best_bid": "0.49", "best_ask": "0.95"}, {"asset_id": "67088219062664412623221891896187729302515136551189145648713076701295675541006", "price": "0.51", "size": "60", "side": "SELL", "hash": "2bebbf36372c57bc4346095248ac3b65006e9036", "best_bid": "0.05", "best_ask": "0.51"}], "timestamp": "1769384560983", "event_type": "price_change"}}
{"_local_timestamp": "2026-01-25T23:42:42.647001+00:00", "data": {"market": "0x97b4a74e6ad96c4601a70bffea6b3ea48227b0676658f1a77c5e4dfeb03c1422", "price_changes": [{"asset_id": "74328021459889543390175687510268557967371044615256517664604837321395650238724", "price": "0.49", "size": "40", "side": "BUY", "hash": "36d5ba9a2d6a8cc35b5e40fb653ea1c80bd8d89f", "best_bid": "0.49", "best_ask": "0.95"}, {"asset_id": "67088219062664412623221891896187729302515136551189145648713076701295675541006", "price": "0.51", "size": "40", "side": "SELL", "hash": "b5d5e64d685ddd18483b9b88b8c722e07c1883b2", "best_bid": "0.05", "best_ask": "0.51"}], "timestamp": "1769384562560", "event_type": "price_change"}}
{"_local_timestamp": "2026-01-25T23:42:42.648901+00:00", "data": {"market": "0xbfd944007d7204b05e19d6fdf2cbe5f3e0b8d37bfb19c15d8e1c813e8ec2dec5", "price_changes": [{"asset_id": "75413567795086771542191436050004337965652039236856821284921766890217813492508", "price": "0.49", "size": "0", "side": "BUY", "hash": "876aead5f679ed6a25a6d940c0328e9ada58d5f2", "best_bid": "0.75", "best_ask": "0.95"}, {"asset_id": "67189754674778985353824371461876088774339766303744275466510582338820578610808", "price": "0.51", "size": "0", "side": "SELL", "hash": "07e8f4dbf356bd0eebeaf2929a1e762fb5d05f36", "best_bid": "0.05", "best_ask": "0.25"}], "timestamp": "1769384562560", "event_type": "price_change"}}
{"_local_timestamp": "2026-01-25T23:42:42.670070+00:00", "data": {"market": "0xbfd944007d7204b05e19d6fdf2cbe5f3e0b8d37bfb19c15d8e1c813e8ec2dec5", "price_changes": [{"asset_id": "75413567795086771542191436050004337965652039236856821284921766890217813492508", "price": "0.51", "size": "20", "side": "BUY", "hash": "98512998e6710a86bbb07fd735d994d3b990a5b2", "best_bid": "0.75", "best_ask": "0.95"}, {"asset_id": "67189754674778985353824371461876088774339766303744275466510582338820578610808", "price": "0.49", "size": "20", "side": "SELL", "hash": "ce1b84501b53df410a854592f6346cbf62325326", "best_bid": "0.05", "best_ask": "0.25"}], "timestamp": "1769384562589", "event_type": "price_change"}}
{"_local_timestamp": "2026-01-25T23:42:42.678808+00:00", "data": {"market": "0x97b4a74e6ad96c4601a70bffea6b3ea48227b0676658f1a77c5e4dfeb03c1422", "price_changes": [{"asset_id": "74328021459889543390175687510268557967371044615256517664604837321395650238724", "price": "0.5", "size": "20", "side": "BUY", "hash": "767c7987c4de20980c2a89093806abc98f2bf1a1", "best_bid": "0.5", "best_ask": "0.95"}, {"asset_id": "67088219062664412623221891896187729302515136551189145648713076701295675541006", "price": "0.5", "size": "20", "side": "SELL", "hash": "b26cf25476e5ce3d268b2b996ec18ddbff07f684", "best_bid": "0.05", "best_ask": "0.5"}], "timestamp": "1769384562589", "event_type": "price_change"}}
{"_local_timestamp": "2026-01-25T23:42:42.687233+00:00", "data": {"market": "0x97b4a74e6ad96c4601a70bffea6b3ea48227b0676658f1a77c5e4dfeb03c1422", "price_changes": [{"asset_id": "67088219062664412623221891896187729302515136551189145648713076701295675541006", "price": "0.56", "size": "0", "side": "SELL", "hash": "8c661b8f15f1ea525444e20f82e26bb5868ed81b", "best_bid": "0.05", "best_ask": "0.5"}, {"asset_id": "74328021459889543390175687510268557967371044615256517664604837321395650238724", "price": "0.44", "size": "0", "side": "BUY", "hash": "e5d8bfc4996cb0b5be69ec057218dced65fbce77", "best_bid": "0.5", "best_ask": "0.95"}], "timestamp": "1769384562591", "event_type": "price_change"}}
{"_local_timestamp": "2026-01-25T23:42:42.792480+00:00", "data": {"market": "0x97b4a74e6ad96c4601a70bffea6b3ea48227b0676658f1a77c5e4dfeb03c1422", "price_changes": [{"asset_id": "67088219062664412623221891896187729302515136551189145648713076701295675541006", "price": "0.5", "size": "47.89", "side": "SELL", "hash": "8f9765d528eaf6821f496a6bf2e41fd248524318", "best_bid": "0.05", "best_ask": "0.5"}, {"asset_id": "74328021459889543390175687510268557967371044615256517664604837321395650238724", "price": "0.5", "size": "47.89", "side": "BUY", "hash": "bef1f013f086e20dc9272a5d1cdb69b04b783e0b", "best_bid": "0.5", "best_ask": "0.95"}], "timestamp": "1769384562691", "event_type": "price_change"}}
{"_local_timestamp": "2026-01-25T23:42:42.811177+00:00", "data": {"market": "0x97b4a74e6ad96c4601a70bffea6b3ea48227b0676658f1a77c5e4dfeb03c1422", "price_changes": [{"asset_id": "74328021459889543390175687510268557967371044615256517664604837321395650238724", "price": "0.48", "size": "25", "side": "BUY", "hash": "4de7aa68aba283b0f2ec8a3d1378a98b8dc45c0d", "best_bid": "0.5", "best_ask": "0.95"}, {"asset_id": "67088219062664412623221891896187729302515136551189145648713076701295675541006", "price": "0.52", "size": "25", "side": "SELL", "hash": "90db7d6a7ede5faa5f335843d30a725b1aa7d244", "best_bid": "0.05", "best_ask": "0.5"}], "timestamp": "1769384562705", "event_type": "price_change"}}
{"_local_timestamp": "2026-01-25T23:42:42.813091+00:00", "data": {"market": "0xbfd944007d7204b05e19d6fdf2cbe5f3e0b8d37bfb19c15d8e1c813e8ec2dec5", "price_changes": [{"asset_id": "75413567795086771542191436050004337965652039236856821284921766890217813492508", "price": "0.5", "size": "25", "side": "BUY", "hash": "24ef5989dbe283387a9ea05a3436079e4d2ad54d", "best_bid": "0.75", "best_ask": "0.95"}, {"asset_id": "67189754674778985353824371461876088774339766303744275466510582338820578610808", "price": "0.5", "size": "25", "side": "SELL", "hash": "3e7424b30e1d2a3f0d10acfae554f417332adafb", "best_bid": "0.05", "best_ask": "0.25"}], "timestamp": "1769384562709", "event_type": "price_change"}}
{"_local_timestamp": "2026-01-25T23:42:42.814907+00:00", "data": {"market": "0xbfd944007d7204b05e19d6fdf2cbe5f3e0b8d37bfb19c15d8e1c813e8ec2dec5", "price_changes": [{"asset_id": "75413567795086771542191436050004337965652039236856821284921766890217813492508", "price": "0.5", "size": "0", "side": "BUY", "hash": "7e3a2d89c0258dab4a27eb81c6e9fceea713c33d", "best_bid": "0.75", "best_ask": "0.95"}, {"asset_id": "67189754674778985353824371461876088774339766303744275466510582338820578610808", "price": "0.5", "size": "0", "side": "SELL", "hash": "18a869c4a880431d98840fe1662ca5fefa821a82", "best_bid": "0.05", "best_ask": "0.25"}], "timestamp": "1769384562712", "event_type": "price_change"}}
{"_local_timestamp": "2026-01-25T23:42:42.923260+00:00", "data": {"market": "0x97b4a74e6ad96c4601a70bffea6b3ea48227b0676658f1a77c5e4dfeb03c1422", "price_changes": [{"asset_id": "74328021459889543390175687510268557967371044615256517664604837321395650238724", "price": "0.48", "size": "0", "side": "BUY", "hash": "41ec7e8508985ff5b1d3146f193bd3ec1c8132e7", "best_bid": "0.5", "best_ask": "0.95"}, {"asset_id": "67088219062664412623221891896187729302515136551189145648713076701295675541006", "price": "0.52", "size": "0", "side": "SELL", "hash": "62b802ccfed2a3f8f734a9adfb580e94d92a6970", "best_bid": "0.05", "best_ask": "0.5"}], "timestamp": "1769384562822", "event_type": "price_change"}}
{"_local_timestamp": "2026-01-25T23:42:43.818883+00:00", "data": {"market": "0x97b4a74e6ad96c4601a70bffea6b3ea48227b0676658f1a77c5e4dfeb03c1422", "price_changes": [{"asset_id": "67088219062664412623221891896187729302515136551189145648713076701295675541006", "price": "0.5", "size": "20", "side": "SELL", "hash": "0f49661b753838029abd382ab4ccc46d281550e3", "best_bid": "0.05", "best_ask": "0.5"}, {"asset_id": "74328021459889543390175687510268557967371044615256517664604837321395650238724", "price": "0.5", "size": "20", "side": "BUY", "hash": "d306edce94dff576b54ecab1b8cfc65e96d14714", "best_bid": "0.5", "best_ask": "0.95"}], "timestamp": "1769384563708", "event_type": "price_change"}}
{"_local_timestamp": "2026-01-25T23:42:43.895435+00:00", "data": {"market": "0x97b4a74e6ad96c4601a70bffea6b3ea48227b0676658f1a77c5e4dfeb03c1422", "price_changes": [{"asset_id": "67088219062664412623221891896187729302515136551189145648713076701295675541006", "price": "0.56", "size": "27.89", "side": "SELL", "hash": "9560c690c6465b137b8120ecb7afa61884c10235", "best_bid": "0.05", "best_ask": "0.5"}, {"asset_id": "74328021459889543390175687510268557967371044615256517664604837321395650238724", "price": "0.44", "size": "27.89", "side": "BUY", "hash": "2c9de425a7ca2c1565e61ee6f85ebc1094c7e559", "best_bid": "0.5", "best_ask": "0.95"}], "timestamp": "1769384563772", "event_type": "price_change"}}
{"_local_timestamp": "2026-01-25T23:42:44.023461+00:00", "data": {"market": "0x97b4a74e6ad96c4601a70bffea6b3ea48227b0676658f1a77c5e4dfeb03c1422", "price_changes": [{"asset_id": "74328021459889543390175687510268557967371044615256517664604837321395650238724", "price": "0.48", "size": "25", "side": "BUY", "hash": "da040b24bdaf7dab284949b53c23b0a1b20e3a02", "best_bid": "0.5", "best_ask": "0.95"}, {"asset_id": "67088219062664412623221891896187729302515136551189145648713076701295675541006", "price": "0.52", "size": "25", "side": "SELL", "hash": "7b38499cc9128b4e8fb9215e8d90c2cc2502ff97", "best_bid": "0.05", "best_ask": "0.5"}], "timestamp": "1769384563894", "event_type": "price_change"}}
{"_local_timestamp": "2026-01-25T23:42:44.031680+00:00", "data": {"market": "0x97b4a74e6ad96c4601a70bffea6b3ea48227b0676658f1a77c5e4dfeb03c1422", "price_changes": [{"asset_id": "74328021459889543390175687510268557967371044615256517664604837321395650238724", "price": "0.48", "size": "50", "side": "BUY", "hash": "79c3aac90561a99152fe107cc851bdd506251d9d", "best_bid": "0.5", "best_ask": "0.95"}, {"asset_id": "67088219062664412623221891896187729302515136551189145648713076701295675541006", "price": "0.52", "size": "50", "side": "SELL", "hash": "9c7be472b881de9f8b782b8aca5d7d309b422bd2", "best_bid": "0.05", "best_ask": "0.5"}], "timestamp": "1769384563898", "event_type": "price_change"}}
{"_local_timestamp": "2026-01-25T23:42:46.194231+00:00", "data": {"market": "0xbfd944007d7204b05e19d6fdf2cbe5f3e0b8d37bfb19c15d8e1c813e8ec2dec5", "price_changes": [{"asset_id": "75413567795086771542191436050004337965652039236856821284921766890217813492508", "price": "0.51", "size": "0", "side": "BUY", "hash": "1f407e4ed6fb2f51af339a3508d890ea8dbed45f", "best_bid": "0.75", "best_ask": "0.95"}, {"asset_id": "67189754674778985353824371461876088774339766303744275466510582338820578610808", "price": "0.49", "size": "0", "side": "SELL", "hash": "d5cd712723624b8029cced638c8dcccb64a39965", "best_bid": "0.05", "best_ask": "0.25"}], "timestamp": "1769384566036", "event_type": "price_change"}}
{"_local_timestamp": "2026-01-25T23:42:46.225336+00:00", "data": {"market": "0xbfd944007d7204b05e19d6fdf2cbe5f3e0b8d37bfb19c15d8e1c813e8ec2dec5", "price_changes": [{"asset_id": "75413567795086771542191436050004337965652039236856821284921766890217813492508", "price": "0.49", "size": "20", "side": "BUY", "hash": "43759e75f1fc6d20495ce4df09a6b4ea9b2b4829", "best_bid": "0.75", "best_ask": "0.95"}, {"asset_id": "67189754674778985353824371461876088774339766303744275466510582338820578610808", "price": "0.51", "size": "20", "side": "SELL", "hash": "64dffebf78c3c7d1056572a46b30885ed83070e4", "best_bid": "0.05", "best_ask": "0.25"}], "timestamp": "1769384566063", "event_type": "price_change"}}
{"_local_timestamp": "2026-01-25T23:42:46.342963+00:00", "data": {"market": "0xbfd944007d7204b05e19d6fdf2cbe5f3e0b8d37bfb19c15d8e1c813e8ec2dec5", "price_changes": [{"asset_id": "75413567795086771542191436050004337965652039236856821284921766890217813492508", "price": "0.5", "size": "25", "side": "BUY", "hash": "159a38e928254b3c3428b863bf00f8b3eb9b1771", "best_bid": "0.75", "best_ask": "0.95"}, {"asset_id": "67189754674778985353824371461876088774339766303744275466510582338820578610808", "price": "0.5", "size": "25", "side": "SELL", "hash": "b3829db86d7bbebb06710e587f26b047a8b64f3e", "best_bid": "0.05", "best_ask": "0.25"}], "timestamp": "1769384566169", "event_type": "price_change"}}
{"_local_timestamp": "2026-01-25T23:42:46.345097+00:00", "data": {"market": "0xbfd944007d7204b05e19d6fdf2cbe5f3e0b8d37bfb19c15d8e1c813e8ec2dec5", "price_changes": [{"asset_id": "75413567795086771542191436050004337965652039236856821284921766890217813492508", "price": "0.5", "size": "50", "side": "BUY", "hash": "f9670f8c2369e43c09294564b2dcc806c33fca7d", "best_bid": "0.75", "best_ask": "0.95"}, {"asset_id": "67189754674778985353824371461876088774339766303744275466510582338820578610808", "price": "0.5", "size": "50", "side": "SELL", "hash": "4b0c505a0949df19ace16a122417df67da6ac5c4", "best_bid": "0.05", "best_ask": "0.25"}], "timestamp": "1769384566169", "event_type": "price_change"}}
{"_local_timestamp": "2026-01-25T23:42:50.407142+00:00", "data": {"market": "0xbfd944007d7204b05e19d6fdf2cbe5f3e0b8d37bfb19c15d8e1c813e8ec2dec5", "price_changes": [{"asset_id": "75413567795086771542191436050004337965652039236856821284921766890217813492508", "price": "0.49", "size": "0", "side": "BUY", "hash": "8d974188051696aa836cf464fc9709e70f57e944", "best_bid": "0.75", "best_ask": "0.95"}, {"asset_id": "67189754674778985353824371461876088774339766303744275466510582338820578610808", "price": "0.51", "size": "0", "side": "SELL", "hash": "ab92fcb256ede32396d9c351b3401205e4c87abc", "best_bid": "0.05", "best_ask": "0.25"}], "timestamp": "1769384570234", "event_type": "price_change"}}
{"_local_timestamp": "2026-01-25T23:42:50.448049+00:00", "data": {"market": "0xbfd944007d7204b05e19d6fdf2cbe5f3e0b8d37bfb19c15d8e1c813e8ec2dec5", "price_changes": [{"asset_id": "75413567795086771542191436050004337965652039236856821284921766890217813492508", "price": "0.51", "size": "20", "side": "BUY", "hash": "353ace15a2c2d3a4a02512ed9ddec34371fa0a54", "best_bid": "0.75", "best_ask": "0.95"}, {"asset_id": "67189754674778985353824371461876088774339766303744275466510582338820578610808", "price": "0.49", "size": "20", "side": "SELL", "hash": "420097a4c6fd6aac1f22b5803577cb21eb5a9c5e", "best_bid": "0.05", "best_ask": "0.25"}], "timestamp": "1769384570263", "event_type": "price_change"}}
{"_local_timestamp": "2026-01-25T23:42:50.505765+00:00", "data": {"market": "0xbfd944007d7204b05e19d6fdf2cbe5f3e0b8d37bfb19c15d8e1c813e8ec2dec5", "price_changes": [{"asset_id": "75413567795086771542191436050004337965652039236856821284921766890217813492508", "price": "0.5", "size": "25", "side": "BUY", "hash": "122e51c3d4d7bd81be44e7bcb0bd7a3bb42359ee", "best_bid": "0.75", "best_ask": "0.95"}, {"asset_id": "67189754674778985353824371461876088774339766303744275466510582338820578610808", "price": "0.5", "size": "25", "side": "SELL", "hash": "3235ecc277d9c2029f7bad49613fa3a29a2759d9", "best_bid": "0.05", "best_ask": "0.25"}], "timestamp": "1769384570365", "event_type": "price_change"}}
{"_local_timestamp": "2026-01-25T23:42:50.540309+00:00", "data": {"market": "0xbfd944007d7204b05e19d6fdf2cbe5f3e0b8d37bfb19c15d8e1c813e8ec2dec5", "price_changes": [{"asset_id": "75413567795086771542191436050004337965652039236856821284921766890217813492508", "price": "0.5", "size": "0", "side": "BUY", "hash": "c7aab2de6f34bec3f97126323715dc390cac143e", "best_bid": "0.75", "best_ask": "0.95"}, {"asset_id": "67189754674778985353824371461876088774339766303744275466510582338820578610808", "price": "0.5", "size": "0", "side": "SELL", "hash": "53c166b5dc2daa183a38b5661d2079dbda1561ad", "best_bid": "0.05", "best_ask": "0.25"}], "timestamp": "1769384570378", "event_type": "price_change"}}
{"_local_timestamp": "2026-01-25T23:42:55.514789+00:00", "data": {"market": "0xbfd944007d7204b05e19d6fdf2cbe5f3e0b8d37bfb19c15d8e1c813e8ec2dec5", "price_changes": [{"asset_id": "75413567795086771542191436050004337965652039236856821284921766890217813492508", "price": "0.51", "size": "0", "side": "BUY", "hash": "a82683ac42a15742fb644b625e062f420ea8e5a0", "best_bid": "0.75", "best_ask": "0.95"}, {"asset_id": "67189754674778985353824371461876088774339766303744275466510582338820578610808", "price": "0.49", "size": "0", "side": "SELL", "hash": "0cfd659a5955f15bb1611850953d975a7cc7053c", "best_bid": "0.05", "best_ask": "0.25"}], "timestamp": "1769384575342", "event_type": "price_change"}}
{"_local_timestamp": "2026-01-25T23:42:55.561289+00:00", "data": {"market": "0xbfd944007d7204b05e19d6fdf2cbe5f3e0b8d37bfb19c15d8e1c813e8ec2dec5", "price_changes": [{"asset_id": "75413567795086771542191436050004337965652039236856821284921766890217813492508", "price": "0.49", "size": "20", "side": "BUY", "hash": "4ea22aa1f9c28118d9134f56986030b6851ee5c6", "best_bid": "0.75", "best_ask": "0.95"}, {"asset_id": "67189754674778985353824371461876088774339766303744275466510582338820578610808", "price": "0.51", "size": "20", "side": "SELL", "hash": "012acfcf5102daab7fa90730885dd6a036de4c1e", "best_bid": "0.05", "best_ask": "0.25"}], "timestamp": "1769384575393", "event_type": "price_change"}}
{"_local_timestamp": "2026-01-25T23:42:55.675253+00:00", "data": {"market": "0xbfd944007d7204b05e19d6fdf2cbe5f3e0b8d37bfb19c15d8e1c813e8ec2dec5", "price_changes": [{"asset_id": "75413567795086771542191436050004337965652039236856821284921766890217813492508", "price": "0.5", "size": "25", "side": "BUY", "hash": "5626cdad8e5b49c833c78675f2b350bc38186f93", "best_bid": "0.75", "best_ask": "0.95"}, {"asset_id": "67189754674778985353824371461876088774339766303744275466510582338820578610808", "price": "0.5", "size": "25", "side": "SELL", "hash": "e530a6e13183202287dba16420c510076c52579a", "best_bid": "0.05", "best_ask": "0.25"}], "timestamp": "1769384575511", "event_type": "price_change"}}
{"_local_timestamp": "2026-01-25T23:42:55.689588+00:00", "data": {"market": "0xbfd944007d7204b05e19d6fdf2cbe5f3e0b8d37bfb19c15d8e1c813e8ec2dec5", "price_changes": [{"asset_id": "75413567795086771542191436050004337965652039236856821284921766890217813492508", "price": "0.5", "size": "50", "side": "BUY", "hash": "f6b4ef55d6089cb6e01c131a482bb9289530cb13", "best_bid": "0.75", "best_ask": "0.95"}, {"asset_id": "67189754674778985353824371461876088774339766303744275466510582338820578610808", "price": "0.5", "size": "50", "side": "SELL", "hash": "299e54f28a53c0394802d8bb8b906df14e9241db", "best_bid": "0.05", "best_ask": "0.25"}], "timestamp": "1769384575531", "event_type": "price_change"}}
{"_local_timestamp": "2026-01-25T23:42:58.605648+00:00", "data": {"market": "0xbfd944007d7204b05e19d6fdf2cbe5f3e0b8d37bfb19c15d8e1c813e8ec2dec5", "price_changes": [{"asset_id": "75413567795086771542191436050004337965652039236856821284921766890217813492508", "price": "0.49", "size": "0", "side": "BUY", "hash": "794ae988052a0e1f04243c53036356a439b14682", "best_bid": "0.75", "best_ask": "0.95"}, {"asset_id": "67189754674778985353824371461876088774339766303744275466510582338820578610808", "price": "0.51", "size": "0", "side": "SELL", "hash": "c2841790f82c1395dcb96b57cced5f37a03f4531", "best_bid": "0.05", "best_ask": "0.25"}], "timestamp": "1769384578398", "event_type": "price_change"}}
{"_local_timestamp": "2026-01-25T23:42:58.637868+00:00", "data": {"market": "0xbfd944007d7204b05e19d6fdf2cbe5f3e0b8d37bfb19c15d8e1c813e8ec2dec5", "price_changes": [{"asset_id": "75413567795086771542191436050004337965652039236856821284921766890217813492508", "price": "0.51", "size": "20", "side": "BUY", "hash": "96c212216c0c2fe1bcb18655612d0fdee451c292", "best_bid": "0.75", "best_ask": "0.95"}, {"asset_id": "67189754674778985353824371461876088774339766303744275466510582338820578610808", "price": "0.49", "size": "20", "side": "SELL", "hash": "9b2368364b4f242bc6bbffedaaf974a497a252f4", "best_bid": "0.05", "best_ask": "0.25"}], "timestamp": "1769384578426", "event_type": "price_change"}}
{"_local_timestamp": "2026-01-25T23:42:58.738760+00:00", "data": {"market": "0xbfd944007d7204b05e19d6fdf2cbe5f3e0b8d37bfb19c15d8e1c813e8ec2dec5", "price_changes": [{"asset_id": "75413567795086771542191436050004337965652039236856821284921766890217813492508", "price": "0.5", "size": "25", "side": "BUY", "hash": "68f1dcc07fbe0a03f7b85ef560298e8b96f789f0", "best_bid": "0.75", "best_ask": "0.95"}, {"asset_id": "67189754674778985353824371461876088774339766303744275466510582338820578610808", "price": "0.5", "size": "25", "side": "SELL", "hash": "461dbedaffbb01a4f9bd57c3ef702fb350845869", "best_bid": "0.05", "best_ask": "0.25"}], "timestamp": "1769384578530", "event_type": "price_change"}}
{"_local_timestamp": "2026-01-25T23:42:58.800704+00:00", "data": {"market": "0xbfd944007d7204b05e19d6fdf2cbe5f3e0b8d37bfb19c15d8e1c813e8ec2dec5", "price_changes": [{"asset_id": "75413567795086771542191436050004337965652039236856821284921766890217813492508", "price": "0.5", "size": "0", "side": "BUY", "hash": "cc6e151fe11607c1713b1b9b72b2faa49b5abae0", "best_bid": "0.75", "best_ask": "0.95"}, {"asset_id": "67189754674778985353824371461876088774339766303744275466510582338820578610808", "price": "0.5", "size": "0", "side": "SELL", "hash": "30b8a44ed77d7927cc06b687591be49247bc4769", "best_bid": "0.05", "best_ask": "0.25"}], "timestamp": "1769384578598", "event_type": "price_change"}}
{"_local_timestamp": "2026-01-25T23:43:01.704837+00:00", "data": {"market": "0xbfd944007d7204b05e19d6fdf2cbe5f3e0b8d37bfb19c15d8e1c813e8ec2dec5", "price_changes": [{"asset_id": "75413567795086771542191436050004337965652039236856821284921766890217813492508", "price": "0.51", "size": "0", "side": "BUY", "hash": "75a37d29e40d1c5c3533bf5e630cba9bb5c9646a", "best_bid": "0.75", "best_ask": "0.95"}, {"asset_id": "67189754674778985353824371461876088774339766303744275466510582338820578610808", "price": "0.49", "size": "0", "side": "SELL", "hash": "da2a813d9d1ecf06bfea4f44c725f0bd4b326ba4", "best_bid": "0.05", "best_ask": "0.25"}], "timestamp": "1769384581509", "event_type": "price_change"}}
{"_local_timestamp": "2026-01-25T23:43:01.748640+00:00", "data": {"market": "0xbfd944007d7204b05e19d6fdf2cbe5f3e0b8d37bfb19c15d8e1c813e8ec2dec5", "price_changes": [{"asset_id": "75413567795086771542191436050004337965652039236856821284921766890217813492508", "price": "0.49", "size": "20", "side": "BUY", "hash": "286431eb8f77b69250c70554b9ccc9adbdcc46cd", "best_bid": "0.75", "best_ask": "0.95"}, {"asset_id": "67189754674778985353824371461876088774339766303744275466510582338820578610808", "price": "0.51", "size": "20", "side": "SELL", "hash": "845469b798aa66d7e202061e6fa6d14c88050fa0", "best_bid": "0.05", "best_ask": "0.25"}], "timestamp": "1769384581537", "event_type": "price_change"}}
{"_local_timestamp": "2026-01-25T23:43:01.868549+00:00", "data": {"market": "0xbfd944007d7204b05e19d6fdf2cbe5f3e0b8d37bfb19c15d8e1c813e8ec2dec5", "price_changes": [{"asset_id": "75413567795086771542191436050004337965652039236856821284921766890217813492508", "price": "0.5", "size": "25", "side": "BUY", "hash": "97f8be1e985a9e82f622a3c1996a5f95b1e038f4", "best_bid": "0.75", "best_ask": "0.95"}, {"asset_id": "67189754674778985353824371461876088774339766303744275466510582338820578610808", "price": "0.5", "size": "25", "side": "SELL", "hash": "b735bfc78addb9da090058878cd806e621b02850", "best_bid": "0.05", "best_ask": "0.25"}], "timestamp": "1769384581686", "event_type": "price_change"}}
{"_local_timestamp": "2026-01-25T23:43:01.870544+00:00", "data": {"market": "0xbfd944007d7204b05e19d6fdf2cbe5f3e0b8d37bfb19c15d8e1c813e8ec2dec5", "price_changes": [{"asset_id": "75413567795086771542191436050004337965652039236856821284921766890217813492508", "price": "0.5", "size": "50", "side": "BUY", "hash": "0733f3075c7020749b7cf568ff046499dfc1a4b0", "best_bid": "0.75", "best_ask": "0.95"}, {"asset_id": "67189754674778985353824371461876088774339766303744275466510582338820578610808", "price": "0.5", "size": "50", "side": "SELL", "hash": "2dafd16a8c998240d54cd844768067c942b0b3fa", "best_bid": "0.05", "best_ask": "0.25"}], "timestamp": "1769384581689", "event_type": "price_change"}}
{"_local_timestamp": "2026-01-25T23:43:04.101199+00:00", "data": {"market": "0xbfd944007d7204b05e19d6fdf2cbe5f3e0b8d37bfb19c15d8e1c813e8ec2dec5", "price_changes": [{"asset_id": "75413567795086771542191436050004337965652039236856821284921766890217813492508", "price": "0.49", "size": "0", "side": "BUY", "hash": "b8272740bd9f3803e077d63c0dcd084b6a0b7062", "best_bid": "0.75", "best_ask": "0.95"}, {"asset_id": "67189754674778985353824371461876088774339766303744275466510582338820578610808", "price": "0.51", "size": "0", "side": "SELL", "hash": "30a2b89dc4ef5ed6396921b1a6928ef00c9f0175", "best_bid": "0.05", "best_ask": "0.25"}], "timestamp": "1769384583898", "event_type": "price_change"}}
{"_local_timestamp": "2026-01-25T23:43:04.142243+00:00", "data": {"market": "0xbfd944007d7204b05e19d6fdf2cbe5f3e0b8d37bfb19c15d8e1c813e8ec2dec5", "price_changes": [{"asset_id": "75413567795086771542191436050004337965652039236856821284921766890217813492508", "price": "0.51", "size": "20", "side": "BUY", "hash": "9a3be010568dc42e612eceb6a16acd67b6aafb95", "best_bid": "0.75", "best_ask": "0.95"}, {"asset_id": "67189754674778985353824371461876088774339766303744275466510582338820578610808", "price": "0.49", "size": "20", "side": "SELL", "hash": "02c801778c857d2923f2f81382665087ce686d15", "best_bid": "0.05", "best_ask": "0.25"}], "timestamp": "1769384583935", "event_type": "price_change"}}
{"_local_timestamp": "2026-01-25T23:43:04.245962+00:00", "data": {"market": "0xbfd944007d7204b05e19d6fdf2cbe5f3e0b8d37bfb19c15d8e1c813e8ec2dec5", "price_changes": [{"asset_id": "75413567795086771542191436050004337965652039236856821284921766890217813492508", "price": "0.5", "size": "25", "side": "BUY", "hash": "bc2f42942fe0445e3664b4b43ceefa28666bc41e", "best_bid": "0.75", "best_ask": "0.95"}, {"asset_id": "67189754674778985353824371461876088774339766303744275466510582338820578610808", "price": "0.5", "size": "25", "side": "SELL", "hash": "0b7dc98053aac55b1acdb09d02b74cafa87b5c90", "best_bid": "0.05", "best_ask": "0.25"}], "timestamp": "1769384584040", "event_type": "price_change"}}
{"_local_timestamp": "2026-01-25T23:43:04.255181+00:00", "data": {"market": "0xbfd944007d7204b05e19d6fdf2cbe5f3e0b8d37bfb19c15d8e1c813e8ec2dec5", "price_changes": [{"asset_id": "75413567795086771542191436050004337965652039236856821284921766890217813492508", "price": "0.5", "size": "0", "side": "BUY", "hash": "5471a4047077a66cbfac00e2de3a232fefc24d20", "best_bid": "0.75", "best_ask": "0.95"}, {"asset_id": "67189754674778985353824371461876088774339766303744275466510582338820578610808", "price": "0.5", "size": "0", "side": "SELL", "hash": "418cdfc6ffaec17f2cdb72462b8b5157b3fa2bf0", "best_bid": "0.05", "best_ask": "0.25"}], "timestamp": "1769384584052", "event_type": "price_change"}}
{"_local_timestamp": "2026-01-25T23:43:06.487989+00:00", "data": {"market": "0xbfd944007d7204b05e19d6fdf2cbe5f3e0b8d37bfb19c15d8e1c813e8ec2dec5", "price_changes": [{"asset_id": "75413567795086771542191436050004337965652039236856821284921766890217813492508", "price": "0.51", "size": "0", "side": "BUY", "hash": "23c05cd182e075896350f0ff72251dfa88a84f24", "best_bid": "0.75", "best_ask": "0.95"}, {"asset_id": "67189754674778985353824371461876088774339766303744275466510582338820578610808", "price": "0.49", "size": "0", "side": "SELL", "hash": "6f779b6152ae701852e2ded47eedee5271ed84e8", "best_bid": "0.05", "best_ask": "0.25"}], "timestamp": "1769384586280", "event_type": "price_change"}}
{"_local_timestamp": "2026-01-25T23:43:06.510083+00:00", "data": {"market": "0xbfd944007d7204b05e19d6fdf2cbe5f3e0b8d37bfb19c15d8e1c813e8ec2dec5", "price_changes": [{"asset_id": "75413567795086771542191436050004337965652039236856821284921766890217813492508", "price": "0.49", "size": "20", "side": "BUY", "hash": "4557c69d58d4f3c86d5252bb894abeddd07890ea", "best_bid": "0.75", "best_ask": "0.95"}, {"asset_id": "67189754674778985353824371461876088774339766303744275466510582338820578610808", "price": "0.51", "size": "20", "side": "SELL", "hash": "1a7f634be58606aca26607b475662760a382bb6a", "best_bid": "0.05", "best_ask": "0.25"}], "timestamp": "1769384586306", "event_type": "price_change"}}
{"_local_timestamp": "2026-01-25T23:43:06.649106+00:00", "data": {"market": "0xbfd944007d7204b05e19d6fdf2cbe5f3e0b8d37bfb19c15d8e1c813e8ec2dec5", "price_changes": [{"asset_id": "75413567795086771542191436050004337965652039236856821284921766890217813492508", "price": "0.5", "size": "25", "side": "BUY", "hash": "c09bee244aff02738feb5266250be99410549039", "best_bid": "0.75", "best_ask": "0.95"}, {"asset_id": "67189754674778985353824371461876088774339766303744275466510582338820578610808", "price": "0.5", "size": "25", "side": "SELL", "hash": "60b8252d5691bb9fe9c1fa949109e7e6ab77486d", "best_bid": "0.05", "best_ask": "0.25"}], "timestamp": "1769384586445", "event_type": "price_change"}}
{"_local_timestamp": "2026-01-25T23:43:06.711002+00:00", "data": {"market": "0xbfd944007d7204b05e19d6fdf2cbe5f3e0b8d37bfb19c15d8e1c813e8ec2dec5", "price_changes": [{"asset_id": "75413567795086771542191436050004337965652039236856821284921766890217813492508", "price": "0.5", "size": "50", "side": "BUY", "hash": "5ee8211cf152b8b1fe0c2c09da3992987e857951", "best_bid": "0.75", "best_ask": "0.95"}, {"asset_id": "67189754674778985353824371461876088774339766303744275466510582338820578610808", "price": "0.5", "size": "50", "side": "SELL", "hash": "cf6cc06839f55493d5a22ccca528f55a51539403", "best_bid": "0.05", "best_ask": "0.25"}], "timestamp": "1769384586511", "event_type": "price_change"}}
{"_local_timestamp": "2026-01-25T23:43:08.534618+00:00", "data": {"market": "0xbfd944007d7204b05e19d6fdf2cbe5f3e0b8d37bfb19c15d8e1c813e8ec2dec5", "price_changes": [{"asset_id": "75413567795086771542191436050004337965652039236856821284921766890217813492508", "price": "0.49", "size": "0", "side": "BUY", "hash": "f660d9e3fd4ebbdfcdd662005a0743ddf34a2de3", "best_bid": "0.75", "best_ask": "0.95"}, {"asset_id": "67189754674778985353824371461876088774339766303744275466510582338820578610808", "price": "0.51", "size": "0", "side": "SELL", "hash": "8a59eaca8b1c07d3a0249336f2df98262469ff25", "best_bid": "0.05", "best_ask": "0.25"}], "timestamp": "1769384588411", "event_type": "price_change"}}
{"_local_timestamp": "2026-01-25T23:43:08.587560+00:00", "data": {"market": "0xbfd944007d7204b05e19d6fdf2cbe5f3e0b8d37bfb19c15d8e1c813e8ec2dec5", "price_changes": [{"asset_id": "75413567795086771542191436050004337965652039236856821284921766890217813492508", "price": "0.51", "size": "20", "side": "BUY", "hash": "d8d3ad2faebeefc9e6c969d4d303ee98a2ea9d9d", "best_bid": "0.75", "best_ask": "0.95"}, {"asset_id": "67189754674778985353824371461876088774339766303744275466510582338820578610808", "price": "0.49", "size": "20", "side": "SELL", "hash": "228987e4197141899b9eaa5f7c2046dfc7ba6f87", "best_bid": "0.05", "best_ask": "0.25"}], "timestamp": "1769384588449", "event_type": "price_change"}}
{"_local_timestamp": "2026-01-25T23:43:08.681061+00:00", "data": {"market": "0xbfd944007d7204b05e19d6fdf2cbe5f3e0b8d37bfb19c15d8e1c813e8ec2dec5", "price_changes": [{"asset_id": "75413567795086771542191436050004337965652039236856821284921766890217813492508", "price": "0.5", "size": "25", "side": "BUY", "hash": "85f1e572885b86aa34493e085675a49c29b50faa", "best_bid": "0.75", "best_ask": "0.95"}, {"asset_id": "67189754674778985353824371461876088774339766303744275466510582338820578610808", "price": "0.5", "size": "25", "side": "SELL", "hash": "a825caa1bf83e0a435649a0d1ca6563162a15e83", "best_bid": "0.05", "best_ask": "0.25"}], "timestamp": "1769384588553", "event_type": "price_change"}}
{"_local_timestamp": "2026-01-25T23:43:08.687266+00:00", "data": {"market": "0xbfd944007d7204b05e19d6fdf2cbe5f3e0b8d37bfb19c15d8e1c813e8ec2dec5", "price_changes": [{"asset_id": "75413567795086771542191436050004337965652039236856821284921766890217813492508", "price": "0.5", "size": "0", "side": "BUY", "hash": "e4c0db20e690fde03df002846659af8a2ccbaaf1", "best_bid": "0.75", "best_ask": "0.95"}, {"asset_id": "67189754674778985353824371461876088774339766303744275466510582338820578610808", "price": "0.5", "size": "0", "side": "SELL", "hash": "84cb60c343abbd56ac7c89a0591a46eaf4d2ed3f", "best_bid": "0.05", "best_ask": "0.25"}], "timestamp": "1769384588557", "event_type": "price_change"}}
{"_local_timestamp": "2026-01-25T23:43:10.842397+00:00", "data": {"market": "0xbfd944007d7204b05e19d6fdf2cbe5f3e0b8d37bfb19c15d8e1c813e8ec2dec5", "price_changes": [{"asset_id": "75413567795086771542191436050004337965652039236856821284921766890217813492508", "price": "0.51", "size": "0", "side": "BUY", "hash": "caf6ad3055327021e569ebbcb8441ea3e90f8ef5", "best_bid": "0.75", "best_ask": "0.95"}, {"asset_id": "67189754674778985353824371461876088774339766303744275466510582338820578610808", "price": "0.49", "size": "0", "side": "SELL", "hash": "5b8d3905c97b4ef435ffdd46bc992e4e012dc495", "best_bid": "0.05", "best_ask": "0.25"}], "timestamp": "1769384590776", "event_type": "price_change"}}
{"_local_timestamp": "2026-01-25T23:43:10.866650+00:00", "data": {"market": "0xbfd944007d7204b05e19d6fdf2cbe5f3e0b8d37bfb19c15d8e1c813e8ec2dec5", "price_changes": [{"asset_id": "75413567795086771542191436050004337965652039236856821284921766890217813492508", "price": "0.49", "size": "20", "side": "BUY", "hash": "c948ef350b4450f52822b810efe56b7597fab387", "best_bid": "0.75", "best_ask": "0.95"}, {"asset_id": "67189754674778985353824371461876088774339766303744275466510582338820578610808", "price": "0.51", "size": "20", "side": "SELL", "hash": "c691ddd91e7a9278fffbab8fcfa6c1b85305b337", "best_bid": "0.05", "best_ask": "0.25"}], "timestamp": "1769384590803", "event_type": "price_change"}}
{"_local_timestamp": "2026-01-25T23:43:10.982174+00:00", "data": {"market": "0xbfd944007d7204b05e19d6fdf2cbe5f3e0b8d37bfb19c15d8e1c813e8ec2dec5", "price_changes": [{"asset_id": "75413567795086771542191436050004337965652039236856821284921766890217813492508", "price": "0.5", "size": "25", "side": "BUY", "hash": "e298e5ea6e4720cfd7224f2a4d02c32bfa36ac59", "best_bid": "0.75", "best_ask": "0.95"}, {"asset_id": "67189754674778985353824371461876088774339766303744275466510582338820578610808", "price": "0.5", "size": "25", "side": "SELL", "hash": "81156d8f3cbb6ed509829f7017f33ebb46c46382", "best_bid": "0.05", "best_ask": "0.25"}], "timestamp": "1769384590916", "event_type": "price_change"}}
{"_local_timestamp": "2026-01-25T23:43:10.984186+00:00", "data": {"market": "0xbfd944007d7204b05e19d6fdf2cbe5f3e0b8d37bfb19c15d8e1c813e8ec2dec5", "price_changes": [{"asset_id": "75413567795086771542191436050004337965652039236856821284921766890217813492508", "price": "0.5", "size": "50", "side": "BUY", "hash": "cf61ed9c3a288fe8e7b639c20fa5e4d07b6d43a7", "best_bid": "0.75", "best_ask": "0.95"}, {"asset_id": "67189754674778985353824371461876088774339766303744275466510582338820578610808", "price": "0.5", "size": "50", "side": "SELL", "hash": "95ed0ef16a1614d2dce93b3a8fac3636c9747a01", "best_bid": "0.05", "best_ask": "0.25"}], "timestamp": "1769384590918", "event_type": "price_change"}}
{"_local_timestamp": "2026-01-25T23:43:12.532729+00:00", "data": {"market": "0xbfd944007d7204b05e19d6fdf2cbe5f3e0b8d37bfb19c15d8e1c813e8ec2dec5", "price_changes": [{"asset_id": "75413567795086771542191436050004337965652039236856821284921766890217813492508", "price": "0.49", "size": "0", "side": "BUY", "hash": "52e851488bfb7d32b830bc8587aa3a32b872f6a6", "best_bid": "0.75", "best_ask": "0.95"}, {"asset_id": "67189754674778985353824371461876088774339766303744275466510582338820578610808", "price": "0.51", "size": "0", "side": "SELL", "hash": "530c1430e036b37e248fa91de9a8fdd5867332c7", "best_bid": "0.05", "best_ask": "0.25"}], "timestamp": "1769384592468", "event_type": "price_change"}}
{"_local_timestamp": "2026-01-25T23:43:12.585123+00:00", "data": {"market": "0xbfd944007d7204b05e19d6fdf2cbe5f3e0b8d37bfb19c15d8e1c813e8ec2dec5", "price_changes": [{"asset_id": "75413567795086771542191436050004337965652039236856821284921766890217813492508", "price": "0.51", "size": "20", "side": "BUY", "hash": "37bdf840b088de6d2a1d84ec73c2e5d4c0cc75d8", "best_bid": "0.75", "best_ask": "0.95"}, {"asset_id": "67189754674778985353824371461876088774339766303744275466510582338820578610808", "price": "0.49", "size": "20", "side": "SELL", "hash": "093db10957469a56da851130c04d0522c7431eab", "best_bid": "0.05", "best_ask": "0.25"}], "timestamp": "1769384592507", "event_type": "price_change"}}
{"_local_timestamp": "2026-01-25T23:43:12.697103+00:00", "data": {"market": "0xbfd944007d7204b05e19d6fdf2cbe5f3e0b8d37bfb19c15d8e1c813e8ec2dec5", "price_changes": [{"asset_id": "75413567795086771542191436050004337965652039236856821284921766890217813492508", "price": "0.5", "size": "25", "side": "BUY", "hash": "83cc9c73ee35cf582e08569e6298beb93241eb18", "best_bid": "0.75", "best_ask": "0.95"}, {"asset_id": "67189754674778985353824371461876088774339766303744275466510582338820578610808", "price": "0.5", "size": "25", "side": "SELL", "hash": "5abdc653eb56d891fd7922a8c30ccb8a9aba7e20", "best_bid": "0.05", "best_ask": "0.25"}], "timestamp": "1769384592615", "event_type": "price_change"}}
{"_local_timestamp": "2026-01-25T23:43:12.699161+00:00", "data": {"market": "0xbfd944007d7204b05e19d6fdf2cbe5f3e0b8d37bfb19c15d8e1c813e8ec2dec5", "price_changes": [{"asset_id": "75413567795086771542191436050004337965652039236856821284921766890217813492508", "price": "0.5", "size": "0", "side": "BUY", "hash": "021ff9ef54e5ba944e3ca562be3b7acc7c124e90", "best_bid": "0.75", "best_ask": "0.95"}, {"asset_id": "67189754674778985353824371461876088774339766303744275466510582338820578610808", "price": "0.5", "size": "0", "side": "SELL", "hash": "b22fa358f78362754beaf1266198f46cf7ccbddd", "best_bid": "0.05", "best_ask": "0.25"}], "timestamp": "1769384592621", "event_type": "price_change"}}
{"_local_timestamp": "2026-01-25T23:43:13.554407+00:00", "data": {"market": "0xbfd944007d7204b05e19d6fdf2cbe5f3e0b8d37bfb19c15d8e1c813e8ec2dec5", "price_changes": [{"asset_id": "75413567795086771542191436050004337965652039236856821284921766890217813492508", "price": "0.51", "size": "0", "side": "BUY", "hash": "4a7cd5a06c15bbb8886a57f9d114690b876fd827", "best_bid": "0.75", "best_ask": "0.95"}, {"asset_id": "67189754674778985353824371461876088774339766303744275466510582338820578610808", "price": "0.49", "size": "0", "side": "SELL", "hash": "9c8510a2181de3ca4123aee77ee71595cd5b444f", "best_bid": "0.05", "best_ask": "0.25"}], "timestamp": "1769384593488", "event_type": "price_change"}}
{"_local_timestamp": "2026-01-25T23:43:13.589417+00:00", "data": {"market": "0xbfd944007d7204b05e19d6fdf2cbe5f3e0b8d37bfb19c15d8e1c813e8ec2dec5", "price_changes": [{"asset_id": "75413567795086771542191436050004337965652039236856821284921766890217813492508", "price": "0.49", "size": "20", "side": "BUY", "hash": "193eea58e18f9f44c14929774c0675a5c3545916", "best_bid": "0.75", "best_ask": "0.95"}, {"asset_id": "67189754674778985353824371461876088774339766303744275466510582338820578610808", "price": "0.51", "size": "20", "side": "SELL", "hash": "7bbc1f74e21ec5670c4dc59575aa371381ae2382", "best_bid": "0.05", "best_ask": "0.25"}], "timestamp": "1769384593516", "event_type": "price_change"}}
{"_local_timestamp": "2026-01-25T23:43:13.699969+00:00", "data": {"market": "0xbfd944007d7204b05e19d6fdf2cbe5f3e0b8d37bfb19c15d8e1c813e8ec2dec5", "price_changes": [{"asset_id": "75413567795086771542191436050004337965652039236856821284921766890217813492508", "price": "0.5", "size": "25", "side": "BUY", "hash": "6284372a832951104d1be6fbb0c7729741567e22", "best_bid": "0.75", "best_ask": "0.95"}, {"asset_id": "67189754674778985353824371461876088774339766303744275466510582338820578610808", "price": "0.5", "size": "25", "side": "SELL", "hash": "dcf0c438305c969a5b74d716a5b6d6c05c1d469c", "best_bid": "0.05", "best_ask": "0.25"}], "timestamp": "1769384593630", "event_type": "price_change"}}
{"_local_timestamp": "2026-01-25T23:43:13.709657+00:00", "data": {"market": "0xbfd944007d7204b05e19d6fdf2cbe5f3e0b8d37bfb19c15d8e1c813e8ec2dec5", "price_changes": [{"asset_id": "75413567795086771542191436050004337965652039236856821284921766890217813492508", "price": "0.5", "size": "50", "side": "BUY", "hash": "7f7f19a03d9ad3026a647bc51c3c6083ed73e750", "best_bid": "0.75", "best_ask": "0.95"}, {"asset_id": "67189754674778985353824371461876088774339766303744275466510582338820578610808", "price": "0.5", "size": "50", "side": "SELL", "hash": "036383ec9f23a91204cee7f9263832d8ba8907f9", "best_bid": "0.05", "best_ask": "0.25"}], "timestamp": "1769384593635", "event_type": "price_change"}}
{"_local_timestamp": "2026-01-25T23:43:16.004558+00:00", "data": {"market": "0xbfd944007d7204b05e19d6fdf2cbe5f3e0b8d37bfb19c15d8e1c813e8ec2dec5", "price_changes": [{"asset_id": "75413567795086771542191436050004337965652039236856821284921766890217813492508", "price": "0.49", "size": "0", "side": "BUY", "hash": "9214a832425dab497f3156b199ba212f069fbf69", "best_bid": "0.75", "best_ask": "0.95"}, {"asset_id": "67189754674778985353824371461876088774339766303744275466510582338820578610808", "price": "0.51", "size": "0", "side": "SELL", "hash": "02e132f2d82db850292499c2639427af7ef656f2", "best_bid": "0.05", "best_ask": "0.25"}], "timestamp": "1769384595939", "event_type": "price_change"}}
{"_local_timestamp": "2026-01-25T23:43:16.040887+00:00", "data": {"market": "0xbfd944007d7204b05e19d6fdf2cbe5f3e0b8d37bfb19c15d8e1c813e8ec2dec5", "price_changes": [{"asset_id": "75413567795086771542191436050004337965652039236856821284921766890217813492508", "price": "0.51", "size": "20", "side": "BUY", "hash": "ae7e95fbcba668a8736789655bb6bd250b8f19bf", "best_bid": "0.75", "best_ask": "0.95"}, {"asset_id": "67189754674778985353824371461876088774339766303744275466510582338820578610808", "price": "0.49", "size": "20", "side": "SELL", "hash": "2b1fff5d7fb0bc6b5d1d1efd46270bfc067041c4", "best_bid": "0.05", "best_ask": "0.25"}], "timestamp": "1769384595973", "event_type": "price_change"}}
{"_local_timestamp": "2026-01-25T23:43:16.157800+00:00", "data": {"market": "0xbfd944007d7204b05e19d6fdf2cbe5f3e0b8d37bfb19c15d8e1c813e8ec2dec5", "price_changes": [{"asset_id": "75413567795086771542191436050004337965652039236856821284921766890217813492508", "price": "0.5", "size": "25", "side": "BUY", "hash": "8a46d36f59767298b4298b4b08df572ae179d735", "best_bid": "0.75", "best_ask": "0.95"}, {"asset_id": "67189754674778985353824371461876088774339766303744275466510582338820578610808", "price": "0.5", "size": "25", "side": "SELL", "hash": "1cff8f0eaabce12db0b77b148677cf7e7426143a", "best_bid": "0.05", "best_ask": "0.25"}], "timestamp": "1769384596088", "event_type": "price_change"}}
{"_local_timestamp": "2026-01-25T23:43:16.164040+00:00", "data": {"market": "0xbfd944007d7204b05e19d6fdf2cbe5f3e0b8d37bfb19c15d8e1c813e8ec2dec5", "price_changes": [{"asset_id": "75413567795086771542191436050004337965652039236856821284921766890217813492508", "price": "0.5", "size": "0", "side": "BUY", "hash": "3c21758ad910df562d22ae709d050104e993fc34", "best_bid": "0.75", "best_ask": "0.95"}, {"asset_id": "67189754674778985353824371461876088774339766303744275466510582338820578610808", "price": "0.5", "size": "0", "side": "SELL", "hash": "1910cfca28770c8ecc064e60e3c7212b05341e21", "best_bid": "0.05", "best_ask": "0.25"}], "timestamp": "1769384596097", "event_type": "price_change"}}
{"_local_timestamp": "2026-01-25T23:43:18.011678+00:00", "data": {"market": "0xbfd944007d7204b05e19d6fdf2cbe5f3e0b8d37bfb19c15d8e1c813e8ec2dec5", "price_changes": [{"asset_id": "75413567795086771542191436050004337965652039236856821284921766890217813492508", "price": "0.51", "size": "0", "side": "BUY", "hash": "69cdd4fb4420689237a6d4c962d2573e68a642d9", "best_bid": "0.75", "best_ask": "0.95"}, {"asset_id": "67189754674778985353824371461876088774339766303744275466510582338820578610808", "price": "0.49", "size": "0", "side": "SELL", "hash": "b7ff9945dd832b184e2d105a9cb11278372287e7", "best_bid": "0.05", "best_ask": "0.25"}], "timestamp": "1769384597945", "event_type": "price_change"}}
{"_local_timestamp": "2026-01-25T23:43:18.041121+00:00", "data": {"market": "0xbfd944007d7204b05e19d6fdf2cbe5f3e0b8d37bfb19c15d8e1c813e8ec2dec5", "price_changes": [{"asset_id": "75413567795086771542191436050004337965652039236856821284921766890217813492508", "price": "0.49", "size": "20", "side": "BUY", "hash": "aaf888058d698b24ae9f2e1a810ddb86410df1f6", "best_bid": "0.75", "best_ask": "0.95"}, {"asset_id": "67189754674778985353824371461876088774339766303744275466510582338820578610808", "price": "0.51", "size": "20", "side": "SELL", "hash": "69abf90bbfc94614af6ba880e48e4fd3047df74e", "best_bid": "0.05", "best_ask": "0.25"}], "timestamp": "1769384597974", "event_type": "price_change"}}
{"_local_timestamp": "2026-01-25T23:43:18.147438+00:00", "data": {"market": "0xbfd944007d7204b05e19d6fdf2cbe5f3e0b8d37bfb19c15d8e1c813e8ec2dec5", "price_changes": [{"asset_id": "75413567795086771542191436050004337965652039236856821284921766890217813492508", "price": "0.5", "size": "25", "side": "BUY", "hash": "49b542b6ee0ce38acc9e0774d561f2124a807ea5", "best_bid": "0.75", "best_ask": "0.95"}, {"asset_id": "67189754674778985353824371461876088774339766303744275466510582338820578610808", "price": "0.5", "size": "25", "side": "SELL", "hash": "0fc13fd8282a217ebe1eb375bfdefa495d586d83", "best_bid": "0.05", "best_ask": "0.25"}], "timestamp": "1769384598080", "event_type": "price_change"}}
{"_local_timestamp": "2026-01-25T23:43:18.151326+00:00", "data": {"market": "0xbfd944007d7204b05e19d6fdf2cbe5f3e0b8d37bfb19c15d8e1c813e8ec2dec5", "price_changes": [{"asset_id": "75413567795086771542191436050004337965652039236856821284921766890217813492508", "price": "0.5", "size": "50", "side": "BUY", "hash": "4e657a6c660f2a86c2efa0af3d9f779d8a999320", "best_bid": "0.75", "best_ask": "0.95"}, {"asset_id": "67189754674778985353824371461876088774339766303744275466510582338820578610808", "price": "0.5", "size": "50", "side": "SELL", "hash": "dd2a72c2da25d94a6bede18cb48c7b5c3258033d", "best_bid": "0.05", "best_ask": "0.25"}], "timestamp": "1769384598086", "event_type": "price_change"}}
{"_local_timestamp": "2026-01-25T23:43:19.652700+00:00", "data": {"market": "0xbfd944007d7204b05e19d6fdf2cbe5f3e0b8d37bfb19c15d8e1c813e8ec2dec5", "price_changes": [{"asset_id": "75413567795086771542191436050004337965652039236856821284921766890217813492508", "price": "0.49", "size": "0", "side": "BUY", "hash": "816c9fc9c8faea8e1751bc5bafde6b67b3e47c60", "best_bid": "0.75", "best_ask": "0.95"}, {"asset_id": "67189754674778985353824371461876088774339766303744275466510582338820578610808", "price": "0.51", "size": "0", "side": "SELL", "hash": "0f60c92156a8f16326080e91c2d20b2f28b13f20", "best_bid": "0.05", "best_ask": "0.25"}], "timestamp": "1769384599559", "event_type": "price_change"}}
{"_local_timestamp": "2026-01-25T23:43:19.687233+00:00", "data": {"market": "0xbfd944007d7204b05e19d6fdf2cbe5f3e0b8d37bfb19c15d8e1c813e8ec2dec5", "price_changes": [{"asset_id": "75413567795086771542191436050004337965652039236856821284921766890217813492508", "price": "0.51", "size": "20", "side": "BUY", "hash": "2a56b03ea1558b807a13e324376dc1376171b5e6", "best_bid": "0.75", "best_ask": "0.95"}, {"asset_id": "67189754674778985353824371461876088774339766303744275466510582338820578610808", "price": "0.49", "size": "20", "side": "SELL", "hash": "f4a4262de2a88540f64b8fc056a5561a6277012c", "best_bid": "0.05", "best_ask": "0.25"}], "timestamp": "1769384599589", "event_type": "price_change"}}
{"_local_timestamp": "2026-01-25T23:43:19.803464+00:00", "data": {"market": "0xbfd944007d7204b05e19d6fdf2cbe5f3e0b8d37bfb19c15d8e1c813e8ec2dec5", "price_changes": [{"asset_id": "75413567795086771542191436050004337965652039236856821284921766890217813492508", "price": "0.5", "size": "25", "side": "BUY", "hash": "4dd4226090d85583e7fb470bc55670db07cdaa62", "best_bid": "0.75", "best_ask": "0.95"}, {"asset_id": "67189754674778985353824371461876088774339766303744275466510582338820578610808", "price": "0.5", "size": "25", "side": "SELL", "hash": "eac8e8e61bea62eda76add3a9b56eefa84efb48f", "best_bid": "0.05", "best_ask": "0.25"}], "timestamp": "1769384599726", "event_type": "price_change"}}
{"_local_timestamp": "2026-01-25T23:43:19.805434+00:00", "data": {"market": "0xbfd944007d7204b05e19d6fdf2cbe5f3e0b8d37bfb19c15d8e1c813e8ec2dec5", "price_changes": [{"asset_id": "75413567795086771542191436050004337965652039236856821284921766890217813492508", "price": "0.5", "size": "0", "side": "BUY", "hash": "420f6bd56cac6cdf0af75ad50d52e43074e09920", "best_bid": "0.75", "best_ask": "0.95"}, {"asset_id": "67189754674778985353824371461876088774339766303744275466510582338820578610808", "price": "0.5", "size": "0", "side": "SELL", "hash": "8bfde141b6f1c89488098eaf9e1ae8a7137edae7", "best_bid": "0.05", "best_ask": "0.25"}], "timestamp": "1769384599738", "event_type": "price_change"}}
{"_local_timestamp": "2026-01-25T23:43:20.413273+00:00", "data": {"market": "0xbd46a9a86d53f1c6ed88d2ec2d6b7fa25f312a2330224a50b055fed30b6f487c", "price_changes": [{"asset_id": "103642153283858206072910718526021885682012582207057190439694348950566724371976", "price": "0.01", "size": "258.57", "side": "BUY", "hash": "abeb0d5077fc38d0611960ffe9bda3506913c558", "best_bid": "0.06", "best_ask": "0.27"}, {"asset_id": "103549663553180106742188583785378823515789409688357997461583563558502280722246", "price": "0.99", "size": "258.57", "side": "SELL", "hash": "bd1162db56c7356f1f684e5c6acbddb91e5a0f78", "best_bid": "0.73", "best_ask": "0.94"}], "timestamp": "1769384600347", "event_type": "price_change"}}
{"_local_timestamp": "2026-01-25T23:43:21.504904+00:00", "data": {"market": "0xbfd944007d7204b05e19d6fdf2cbe5f3e0b8d37bfb19c15d8e1c813e8ec2dec5", "price_changes": [{"asset_id": "75413567795086771542191436050004337965652039236856821284921766890217813492508", "price": "0.51", "size": "0", "side": "BUY", "hash": "74a28e730edd93ace4df72fb85a38c2f4983de34", "best_bid": "0.75", "best_ask": "0.95"}, {"asset_id": "67189754674778985353824371461876088774339766303744275466510582338820578610808", "price": "0.49", "size": "0", "side": "SELL", "hash": "63317edec85805caf14368e527bcd79c60625d60", "best_bid": "0.05", "best_ask": "0.25"}], "timestamp": "1769384601441", "event_type": "price_change"}}
{"_local_timestamp": "2026-01-25T23:43:21.537159+00:00", "data": {"market": "0xbfd944007d7204b05e19d6fdf2cbe5f3e0b8d37bfb19c15d8e1c813e8ec2dec5", "price_changes": [{"asset_id": "75413567795086771542191436050004337965652039236856821284921766890217813492508", "price": "0.49", "size": "20", "side": "BUY", "hash": "babe13101b196847a6e519624576ea1c379d4215", "best_bid": "0.75", "best_ask": "0.95"}, {"asset_id": "67189754674778985353824371461876088774339766303744275466510582338820578610808", "price": "0.51", "size": "20", "side": "SELL", "hash": "2c4038ad08a9b843e6b991688c73f8d65db4c110", "best_bid": "0.05", "best_ask": "0.25"}], "timestamp": "1769384601471", "event_type": "price_change"}}
{"_local_timestamp": "2026-01-25T23:43:21.649332+00:00", "data": {"market": "0xbfd944007d7204b05e19d6fdf2cbe5f3e0b8d37bfb19c15d8e1c813e8ec2dec5", "price_changes": [{"asset_id": "75413567795086771542191436050004337965652039236856821284921766890217813492508", "price": "0.5", "size": "25", "side": "BUY", "hash": "7b2666d4bd0d4757f408121621ca82fddf02d640", "best_bid": "0.75", "best_ask": "0.95"}, {"asset_id": "67189754674778985353824371461876088774339766303744275466510582338820578610808", "price": "0.5", "size": "25", "side": "SELL", "hash": "2afffbabfdccc82efa21ec1d1d7f87f70ce44498", "best_bid": "0.05", "best_ask": "0.25"}], "timestamp": "1769384601579", "event_type": "price_change"}}
{"_local_timestamp": "2026-01-25T23:43:21.675903+00:00", "data": {"market": "0xbfd944007d7204b05e19d6fdf2cbe5f3e0b8d37bfb19c15d8e1c813e8ec2dec5", "price_changes": [{"asset_id": "75413567795086771542191436050004337965652039236856821284921766890217813492508", "price": "0.5", "size": "50", "side": "BUY", "hash": "dff06677f74db0d46e97ec9a2833b702810b2edf", "best_bid": "0.75", "best_ask": "0.95"}, {"asset_id": "67189754674778985353824371461876088774339766303744275466510582338820578610808", "price": "0.5", "size": "50", "side": "SELL", "hash": "803344c9d72fe9f76f708ba3fe424ea5d003c72a", "best_bid": "0.05", "best_ask": "0.25"}], "timestamp": "1769384601609", "event_type": "price_change"}}
{"_local_timestamp": "2026-01-25T23:43:22.490406+00:00", "data": {"market": "0xbfd944007d7204b05e19d6fdf2cbe5f3e0b8d37bfb19c15d8e1c813e8ec2dec5", "price_changes": [{"asset_id": "75413567795086771542191436050004337965652039236856821284921766890217813492508", "price": "0.49", "size": "0", "side": "BUY", "hash": "0daa01d227f703c0e3cbed28b205b5b0d7d4eb99", "best_bid": "0.75", "best_ask": "0.95"}, {"asset_id": "67189754674778985353824371461876088774339766303744275466510582338820578610808", "price": "0.51", "size": "0", "side": "SELL", "hash": "df5c24848cd53da4586aed3aaa06d2e830a0d956", "best_bid": "0.05", "best_ask": "0.25"}], "timestamp": "1769384602400", "event_type": "price_change"}}
{"_local_timestamp": "2026-01-25T23:43:22.493496+00:00", "data": {"market": "0xbfd944007d7204b05e19d6fdf2cbe5f3e0b8d37bfb19c15d8e1c813e8ec2dec5", "price_changes": [{"asset_id": "75413567795086771542191436050004337965652039236856821284921766890217813492508", "price": "0.51", "size": "20", "side": "BUY", "hash": "0e86b025a54968ed5e89f018bf31e74828479f0c", "best_bid": "0.75", "best_ask": "0.95"}, {"asset_id": "67189754674778985353824371461876088774339766303744275466510582338820578610808", "price": "0.49", "size": "20", "side": "SELL", "hash": "358d5a5747df6e22ff94b2858498c00a428d94b4", "best_bid": "0.05", "best_ask": "0.25"}], "timestamp": "1769384602427", "event_type": "price_change"}}
