{"_local_timestamp": "2026-01-25T23:40:43.701982+00:00", "data": [{"market": "0x938e6a0a011f9534ffd2d86c65dde3aeb7c66ad06cee29ead70b832179c3b6de", "asset_id": "84559926953146780213236573115780107039976526543427713229500373094335659185505", "timestamp": "1769384094991", "hash": "0ff69591d43657e90b71d97ae34b51670dfc8da0", "bids": [{"price": "0.01", "size": "317800"}, {"price": "0.02", "size": "12250"}, {"price": "0.03", "size": "6.66"}, {"price": "0.04", "size": "21000"}, {"price": "0.05", "size": "300"}, {"price": "0.07", "size": "450"}, {"price": "0.08", "size": "19.44"}, {"price": "0.14", "size": "325"}, {"price": "0.28", "size": "380"}, {"price": "0.35", "size": "9.99"}, {"price": "0.37", "size": "49.99"}, {"price": "0.39", "size": "100"}, {"price": "0.4", "size": "10"}, {"price": "0.42", "size": "850"}, {"price": "0.43", "size": "20"}, {"price": "0.48", "size": "1.99"}], "asks": [{"price": "0.99", "size": "1111556.34"}, {"price": "0.98", "size": "25006.15"}, {"price": "0.97", "size": "3333"}, {"price": "0.96", "size": "1257.17"}, {"price": "0.95", "size": "720"}, {"price": "0.94", "size": "1050"}, {"price": "0.93", "size": "4500"}, {"price": "0.92", "size": "448.25"}, {"price": "0.91", "size": "5.49"}, {"price": "0.9", "size": "320"}, {"price": "0.88", "size": "375"}, {"price": "0.87", "size": "215.38"}, {"price": "0.85", "size": "825"}, {"price": "0.84", "size": "162.5"}, {"price": "0.83", "size": "28.57"}, {"price": "0.82", "size": "383.33"}, {"price": "0.81", "size": "5.42"}, {"price": "0.8", "size": "800"}, {"price": "0.79", "size": "345.23"}, {"price": "0.78", "size": "9"}, {"price": "0.77", "size": "10"}, {"price": "0.65", "size": "10"}, {"price": "0.62", "size": "250"}, {"price": "0.6", "size": "40"}, {"price": "0.59", "size": "101.7"}, {"price": "0.58", "size": "66.74"}, {"price": "0.57", "size": "20"}, {"price": "0.55", "size": "115"}, {"price": "0.54", "size": "6"}, {"price": "0.52", "size": "13.33"}, {"price": "0.5", "size": "100"}], "event_type": "book", "last_trade_price": "0.520"}, {"market": "0x29134729ec74a0dbab6ddad9d9a745e4c0b83c59682bdc4b76412c9635d66627", "asset_id": "109408722309726159994284194907981745959708334274938135190768342039858793034476", "timestamp": "1769384440601", "hash": "c169e958aee3b26d230c802ec44790ef1ef37c15", "bids": [{"price": "0.001", "size": "172862"}, {"price": "0.002", "size": "7006.55"}, {"price": "0.003", "size": "800"}, {"price": "0.005", "size": "500"}, {"price": "0.006", "size": "5.27"}, {"price": "0.01", "size": "92.74"}, {"price": "0.012", "size": "500"}, {"price": "0.013", "size": "400"}, {"price": "0.014", "size": "200"}, {"price": "0.015", "size": "100"}, {"price": "0.016", "size": "9.7"}, {"price": "0.025", "size": "273.97"}, {"price": "0.027", "size": "68"}, {"price": "0.034", "size": "100"}, {"price": "0.035", "size": "30"}, {"price": "0.039", "size": "50"}, {"price": "0.05", "size": "150"}, {"price": "0.054", "size": "79.97"}, {"price": "0.076", "size": "10.43"}, {"price": "0.077", "size": "7.08"}, {"price": "0.08", "size": "20"}, {"price": "0.081", "size": "25"}], "asks": [{"price": "0.999", "size": "11007196.92"}, {"price": "0.998", "size": "61255"}, {"price": "0.997", "size": "1400"}, {"price": "0.996", "size": "9.91"}, {"price": "0.994", "size": "200"}, {"price": "0.99", "size": "8250"}, {"price": "0.989", "size": "60000"}, {"price": "0.988", "size": "7.63"}, {"price": "0.98", "size": "35000"}, {"price": "0.97", "size": "12000"}, {"price": "0.969", "size": "5.01"}, {"price": "0.96", "size": "1250"}, {"price": "0.95", "size": "3330"}, {"price": "0.949", "size": "39"}, {"price": "0.94", "size": "750"}, {"price": "0.936", "size": "3400"}, {"price": "0.935", "size": "8.09"}, {"price": "0.91", "size": "500"}, {"price": "0.88", "size": "375"}, {"price": "0.86", "size": "242.85"}, {"price": "0.85", "size": "825"}, {"price": "0.82", "size": "250"}, {"price": "0.81", "size": "168.42"}, {"price": "0.8", "size": "800"}, {"price": "0.799", "size": "5.83"}, {"price": "0.76", "size": "116.66"}, {"price": "0.72", "size": "92.85"}, {"price": "0.717", "size": "100"}, {"price": "0.716", "size": "653"}, {"price": "0.67", "size": "72.72"}, {"price": "0.62", "size": "52.63"}, {"price": "0.618", "size": "207"}, {"price": "0.617", "size": "5"}, {"price": "0.616", "size": "10"}, {"price": "0.217", "size": "40"}, {"price": "0.216", "size": "20"}, {"price": "0.2", "size": "400"}, {"price": "0.199", "size": "66.66"}, {"price": "0.198", "size": "30"}, {"price": "0.19", "size": "30.61"}, {"price": "0.15", "size": "66.66"}, {"price": "0.125", "size": "13"}, {"price": "0.103", "size": "280"}, {"price": "0.101", "size": "42.14"}, {"price": "0.1", "size": "66.66"}], "event_type": "book", "last_trade_price": ""}, {"market": "0x1cbe7cbbfb481ed76c054bc4c36c6fb966a2d1671d908d0e89e1f22b0adfa1d6", "asset_id": "23234069812587403133665543339348944952052706164431007953765598952013802512997", "timestamp": "1769384421106", "hash": "4a0bb3374a9da1f92d161cd3407bd9513c21fb4f", "bids": [{"price": "0.001", "size": "11007151.04"}, {"price": "0.002", "size": "61250"}, {"price": "0.003", "size": "1406.65"}, {"price": "0.006", "size": "200"}, {"price": "0.007", "size": "9.8"}, {"price": "0.01", "size": "8250"}, {"price": "0.012", "size": "60000"}, {"price": "0.02", "size": "35000"}, {"price": "0.021", "size": "10.95"}, {"price": "0.04", "size": "13250"}, {"price": "0.05", "size": "3330"}, {"price": "0.051", "size": "39"}, {"price": "0.06", "size": "950"}, {"price": "0.07", "size": "300"}, {"price": "0.071", "size": "7.08"}, {"price": "0.1", "size": "360"}, {"price": "0.12", "size": "375"}, {"price": "0.15", "size": "1051.66"}, {"price": "0.18", "size": "250"}, {"price": "0.2", "size": "960"}, {"price": "0.201", "size": "250"}, {"price": "0.202", "size": "5.78"}, {"price": "0.25", "size": "112"}, {"price": "0.3", "size": "286.66"}, {"price": "0.34", "size": "50"}, {"price": "0.35", "size": "68.57"}, {"price": "0.4", "size": "50"}, {"price": "0.401", "size": "214"}, {"price": "0.402", "size": "5"}, {"price": "0.403", "size": "10"}, {"price": "0.683", "size": "70"}, {"price": "0.685", "size": "15"}, {"price": "0.686", "size": "20"}, {"price": "0.865", "size": "100.6"}, {"price": "0.866", "size": "10"}, {"price": "0.91", "size": "850"}, {"price": "0.951", "size": "5"}, {"price": "0.97", "size": "300"}, {"price": "0.971", "size": "30"}, {"price": "0.987", "size": "200"}, {"price": "0.991", "size": "133.33"}, {"price": "0.992", "size": "259"}], "asks": [{"price": "0.999", "size": "68025.5"}, {"price": "0.998", "size": "5275.06"}, {"price": "0.997", "size": "250"}, {"price": "0.994", "size": "9.04"}, {"price": "0.993", "size": "24.8"}], "event_type": "book", "last_trade_price": "0.009"}, {"market": "0x91ebc8bf88c5f99dd4550cb75255766f638d1932ede36e8eae78a76df0c15455", "asset_id": "20552877126021963309330960377901114870262231239849696600236708023505406755774", "timestamp": "1769384287044", "hash": "dbdeb34ae9a471dbb24b22af9779e45496ac4a29", "bids": [{"price": "0.001", "size": "72196"}, {"price": "0.002", "size": "4666.44"}, {"price": "0.003", "size": "40.73"}, {"price": "0.01", "size": "230.19"}, {"price": "0.011", "size": "300"}, {"price": "0.012", "size": "5.41"}, {"price": "0.013", "size": "295.33"}, {"price": "0.014", "size": "27.09"}, {"price": "0.015", "size": "184.69"}, {"price": "0.018", "size": "43.46"}, {"price": "0.024", "size": "68.46"}], "asks": [{"price": "0.999", "size": "3851.05"}, {"price": "0.998", "size": "1250"}, {"price": "0.997", "size": "1406.66"}, {"price": "0.994", "size": "200"}, {"price": "0.993", "size": "9.81"}, {"price": "0.99", "size": "1111550"}, {"price": "0.98", "size": "35000"}, {"price": "0.979", "size": "13.83"}, {"price": "0.96", "size": "1250"}, {"price": "0.95", "size": "3330"}, {"price": "0.949", "size": "39"}, {"price": "0.945", "size": "7.22"}, {"price": "0.94", "size": "750"}, {"price": "0.93", "size": "2000"}, {"price": "0.916", "size": "2700"}, {"price": "0.915", "size": "5.21"}, {"price": "0.9", "size": "360"}, {"price": "0.88", "size": "375"}, {"price": "0.85", "size": "1051.66"}, {"price": "0.82", "size": "250"}, {"price": "0.8", "size": "960"}, {"price": "0.799", "size": "250"}, {"price": "0.798", "size": "5.78"}, {"price": "0.75", "size": "262"}, {"price": "0.73", "size": "50"}, {"price": "0.7", "size": "86.66"}, {"price": "0.66", "size": "50"}, {"price": "0.65", "size": "68.57"}, {"price": "0.61", "size": "51.28"}, {"price": "0.59", "size": "563"}, {"price": "0.589", "size": "126.5"}, {"price": "0.581", "size": "60"}, {"price": "0.58", "size": "5"}, {"price": "0.25", "size": "5"}, {"price": "0.249", "size": "10"}, {"price": "0.2", "size": "10"}, {"price": "0.193", "size": "30"}, {"price": "0.192", "size": "40"}, {"price": "0.191", "size": "15"}, {"price": "0.17", "size": "6.96"}, {"price": "0.161", "size": "10"}, {"price": "0.16", "size": "20"}, {"price": "0.13", "size": "23.25"}, {"price": "0.12", "size": "100"}, {"price": "0.1", "size": "250"}, {"price": "0.099", "size": "66.66"}, {"price": "0.09", "size": "6.96"}, {"price": "0.081", "size": "66.66"}, {"price": "0.08", "size": "100"}, {"price": "0.072", "size": "223.27"}, {"price": "0.066", "size": "40"}, {"price": "0.063", "size": "73.66"}, {"price": "0.062", "size": "63.18"}], "event_type": "book", "last_trade_price": "0.045"}, {"market": "0xa087422678cebf674c69d2c86a13b89d153951f067f753e0c2044eb991c0652f", "asset_id": "94297885496428433994612881192883747282447345164360333822514231082582602051560", "timestamp": "1769384418416", "hash": "5e9955721c5914146fafefddbe63980004c01bb8", "bids": [{"price": "0.01", "size": "1111564.75"}, {"price": "0.02", "size": "35000"}, {"price": "0.03", "size": "20000"}, {"price": "0.04", "size": "1255.66"}, {"price": "0.05", "size": "3330"}, {"price": "0.06", "size": "783"}, {"price": "0.07", "size": "3500"}, {"price": "0.08", "size": "2000"}, {"price": "0.09", "size": "405.09"}, {"price": "0.12", "size": "375"}, {"price": "0.13", "size": "261.53"}, {"price": "0.15", "size": "825"}, {"price": "0.18", "size": "427.77"}, {"price": "0.2", "size": "800"}, {"price": "0.21", "size": "5.56"}, {"price": "0.22", "size": "127.27"}, {"price": "0.27", "size": "96.29"}, {"price": "0.28", "size": "450"}, {"price": "0.31", "size": "77.41"}, {"price": "0.36", "size": "55.55"}, {"price": "0.38", "size": "530"}, {"price": "0.39", "size": "175"}, {"price": "0.4", "size": "5"}, {"price": "0.43", "size": "10"}, {"price": "0.7", "size": "100"}, {"price": "0.71", "size": "49.61"}, {"price": "0.72", "size": "70"}, {"price": "0.74", "size": "24.99"}, {"price": "0.75", "size": "120"}, {"price": "0.77", "size": "16.88"}, {"price": "0.78", "size": "48.71"}, {"price": "0.81", "size": "150"}, {"price": "0.85", "size": "63.63"}], "asks": [{"price": "0.99", "size": "1100"}, {"price": "0.98", "size": "10"}, {"price": "0.97", "size": "433.33"}, {"price": "0.96", "size": "987.5"}, {"price": "0.95", "size": "350"}, {"price": "0.94", "size": "166.66"}, {"price": "0.93", "size": "328.67"}, {"price": "0.92", "size": "200"}, {"price": "0.91", "size": "93.76"}, {"price": "0.89", "size": "130.75"}], "event_type": "book", "last_trade_price": ""}, {"market": "0x3936de01f890af302ca75727b772fe6dffe915ce638a08809042a3a81dd346c0", "asset_id": "68682941687946159092109471523402081762244652970943030009984394444937274201240", "timestamp": "1769384287044", "hash": "fd782e134cd4cc1266406a6f0e92602440dfbaed", "bids": [{"price": "0.001", "size": "60354.35"}, {"price": "0.002", "size": "5225.09"}, {"price": "0.003", "size": "11.54"}, {"price": "0.004", "size": "130"}, {"price": "0.008", "size": "158.7"}, {"price": "0.009", "size": "145.6"}], "asks": [{"price": "0.999", "size": "11007151"}, {"price": "0.998", "size": "61250"}, {"price": "0.997", "size": "1406.63"}, {"price": "0.994", "size": "200"}, {"price": "0.993", "size": "9.77"}, {"price": "0.99", "size": "8250"}, {"price": "0.98", "size": "35000"}, {"price": "0.979", "size": "10.91"}, {"price": "0.96", "size": "1250"}, {"price": "0.95", "size": "3330"}, {"price": "0.949", "size": "39"}, {"price": "0.94", "size": "750"}, {"price": "0.93", "size": "3500"}, {"price": "0.929", "size": "7.02"}, {"price": "0.9", "size": "360"}, {"price": "0.88", "size": "375"}, {"price": "0.85", "size": "1051.66"}, {"price": "0.82", "size": "250"}, {"price": "0.8", "size": "960"}, {"price": "0.799", "size": "250"}, {"price": "0.798", "size": "5.81"}, {"price": "0.75", "size": "262"}, {"price": "0.73", "size": "50"}, {"price": "0.7", "size": "86.66"}, {"price": "0.66", "size": "50"}, {"price": "0.65", "size": "68.57"}, {"price": "0.6", "size": "50"}, {"price": "0.586", "size": "399"}, {"price": "0.585", "size": "10"}, {"price": "0.583", "size": "15"}, {"price": "0.16", "size": "700"}, {"price": "0.148", "size": "40"}, {"price": "0.144", "size": "30"}, {"price": "0.142", "size": "10"}, {"price": "0.141", "size": "20"}, {"price": "0.094", "size": "66.67"}, {"price": "0.08", "size": "150"}, {"price": "0.055", "size": "50"}, {"price": "0.045", "size": "50"}, {"price": "0.037", "size": "200"}, {"price": "0.035", "size": "340.97"}, {"price": "0.03", "size": "6.34"}, {"price": "0.029", "size": "26"}], "event_type": "book", "last_trade_price": "0.009"}, {"market": "0x0afa82ff8cb4dcf8c7a248ccaf438597619d3a6a4e4463adb109e1a1034d6e10", "asset_id": "30455848075861160607924869725570428601171045624621952729814709348346858289488", "timestamp": "1769384440920", "hash": "ee44f5421b0e500e434d62c607de8359a08443bf", "bids": [{"price": "0.01", "size": "5500"}, {"price": "0.02", "size": "1250"}, {"price": "0.03", "size": "306.66"}, {"price": "0.04", "size": "100"}, {"price": "0.05", "size": "100"}, {"price": "0.06", "size": "200"}, {"price": "0.07", "size": "150"}, {"price": "0.1", "size": "60"}, {"price": "0.13", "size": "150"}, {"price": "0.15", "size": "40"}, {"price": "0.16", "size": "181.25"}, {"price": "0.17", "size": "64.7"}, {"price": "0.18", "size": "100"}, {"price": "0.2", "size": "130"}, {"price": "0.21", "size": "100"}, {"price": "0.22", "size": "100"}, {"price": "0.23", "size": "0.34"}, {"price": "0.24", "size": "12.55"}], "asks": [{"price": "0.99", "size": "1111560.36"}, {"price": "0.98", "size": "35000"}, {"price": "0.97", "size": "9.55"}, {"price": "0.96", "size": "1250"}, {"price": "0.94", "size": "1050"}, {"price": "0.93", "size": "3500"}, {"price": "0.92", "size": "1380"}, {"price": "0.91", "size": "5.3"}, {"price": "0.88", "size": "983.33"}, {"price": "0.85", "size": "500"}, {"price": "0.84", "size": "200"}, {"price": "0.82", "size": "250"}, {"price": "0.8", "size": "940"}, {"price": "0.79", "size": "5.39"}, {"price": "0.78", "size": "350"}, {"price": "0.77", "size": "113.04"}, {"price": "0.73", "size": "88.88"}, {"price": "0.69", "size": "64.51"}, {"price": "0.68", "size": "580"}, {"price": "0.66", "size": "125"}, {"price": "0.63", "size": "5"}, {"price": "0.55", "size": "30"}, {"price": "0.54", "size": "10"}, {"price": "0.53", "size": "40"}, {"price": "0.38", "size": "10"}, {"price": "0.37", "size": "20"}, {"price": "0.36", "size": "100"}, {"price": "0.34", "size": "119.69"}, {"price": "0.33", "size": "726.41"}, {"price": "0.31", "size": "814.98"}, {"price": "0.3", "size": "41.45"}, {"price": "0.28", "size": "180.12"}, {"price": "0.26", "size": "41.45"}], "event_type": "book", "last_trade_price": "0.240"}, {"market": "0x0afa82ff8cb4dcf8c7a248ccaf438597619d3a6a4e4463adb109e1a1034d6e10", "asset_id": "69317727912918260368347049966647382207251169560838202627585212468740589465040", "timestamp": "1769384440920", "hash": "05463ad848c8d9861527c8ef8f14d608b4f30331", "bids": [{"price": "0.01", "size": "1111560.36"}, {"price": "0.02", "size": "35000"}, {"price": "0.03", "size": "9.55"}, {"price": "0.04", "size": "1250"}, {"price": "0.06", "size": "1050"}, {"price": "0.07", "size": "3500"}, {"price": "0.08", "size": "1380"}, {"price": "0.09", "size": "5.3"}, {"price": "0.12", "size": "983.33"}, {"price": "0.15", "size": "500"}, {"price": "0.16", "size": "200"}, {"price": "0.18", "size": "250"}, {"price": "0.2", "size": "940"}, {"price": "0.21", "size": "5.39"}, {"price": "0.22", "size": "350"}, {"price": "0.23", "size": "113.04"}, {"price": "0.27", "size": "88.88"}, {"price": "0.31", "size": "64.51"}, {"price": "0.32", "size": "580"}, {"price": "0.34", "size": "125"}, {"price": "0.37", "size": "5"}, {"price": "0.45", "size": "30"}, {"price": "0.46", "size": "10"}, {"price": "0.47", "size": "40"}, {"price": "0.62", "size": "10"}, {"price": "0.63", "size": "20"}, {"price": "0.64", "size": "100"}, {"price": "0.66", "size": "119.69"}, {"price": "0.67", "size": "726.41"}, {"price": "0.69", "size": "814.98"}, {"price": "0.7", "size": "41.45"}, {"price": "0.72", "size": "180.12"}, {"price": "0.74", "size": "41.45"}], "asks": [{"price": "0.99", "size": "5500"}, {"price": "0.98", "size": "1250"}, {"price": "0.97", "size": "306.66"}, {"price": "0.96", "size": "100"}, {"price": "0.95", "size": "100"}, {"price": "0.94", "size": "200"}, {"price": "0.93", "size": "150"}, {"price": "0.9", "size": "60"}, {"price": "0.87", "size": "150"}, {"price": "0.85", "size": "40"}, {"price": "0.84", "size": "181.25"}, {"price": "0.83", "size": "64.7"}, {"price": "0.82", "size": "100"}, {"price": "0.8", "size": "130"}, {"price": "0.79", "size": "100"}, {"price": "0.78", "size": "100"}, {"price": "0.77", "size": "0.34"}, {"price": "0.76", "size": "12.55"}], "event_type": "book", "last_trade_price": "0.240"}, {"market": "0xa087422678cebf674c69d2c86a13b89d153951f067f753e0c2044eb991c0652f", "asset_id": "12369294935701377203300019700047987848793450009787501327274207549237196997903", "timestamp": "1769384418416", "hash": "dda1825b1758be0f65e474c4b1ba623471bee422", "bids": [{"price": "0.01", "size": "1100"}, {"price": "0.02", "size": "10"}, {"price": "0.03", "size": "433.33"}, {"price": "0.04", "size": "987.5"}, {"price": "0.05", "size": "350"}, {"price": "0.06", "size": "166.66"}, {"price": "0.07", "size": "328.67"}, {"price": "0.08", "size": "200"}, {"price": "0.09", "size": "93.76"}, {"price": "0.11", "size": "130.75"}], "asks": [{"price": "0.99", "size": "1111564.75"}, {"price": "0.98", "size": "35000"}, {"price": "0.97", "size": "20000"}, {"price": "0.96", "size": "1255.66"}, {"price": "0.95", "size": "3330"}, {"price": "0.94", "size": "783"}, {"price": "0.93", "size": "3500"}, {"price": "0.92", "size": "2000"}, {"price": "0.91", "size": "405.09"}, {"price": "0.88", "size": "375"}, {"price": "0.87", "size": "261.53"}, {"price": "0.85", "size": "825"}, {"price": "0.82", "size": "427.77"}, {"price": "0.8", "size": "800"}, {"price": "0.79", "size": "5.56"}, {"price": "0.78", "size": "127.27"}, {"price": "0.73", "size": "96.29"}, {"price": "0.72", "size": "450"}, {"price": "0.69", "size": "77.41"}, {"price": "0.64", "size": "55.55"}, {"price": "0.62", "size": "530"}, {"price": "0.61", "size": "175"}, {"price": "0.6", "size": "5"}, {"price": "0.57", "size": "10"}, {"price": "0.3", "size": "100"}, {"price": "0.29", "size": "49.61"}, {"price": "0.28", "size": "70"}, {"price": "0.26", "size": "24.99"}, {"price": "0.25", "size": "120"}, {"price": "0.23", "size": "16.88"}, {"price": "0.22", "size": "48.71"}, {"price": "0.19", "size": "150"}, {"price": "0.15", "size": "63.63"}], "event_type": "book", "last_trade_price": ""}, {"market": "0x021e7689a90ac39c268a39ddff6269fd0f41ed84ea6833f6e5b7d900569e6d8b", "asset_id": "25265857280574792887110878653665871891927967464924536706348687031929049209739", "timestamp": "1769384418185", "hash": "d09c5d8d52aad0a9a674fec8536d6a315bd82871", "bids": [{"price": "0.001", "size": "68205"}, {"price": "0.002", "size": "5553.28"}, {"price": "0.003", "size": "347.1"}, {"price": "0.004", "size": "175.52"}, {"price": "0.005", "size": "56.82"}, {"price": "0.006", "size": "35.52"}], "asks": [{"price": "0.999", "size": "11007151"}, {"price": "0.998", "size": "61250"}, {"price": "0.997", "size": "1406.63"}, {"price": "0.994", "size": "200"}, {"price": "0.993", "size": "10.45"}, {"price": "0.99", "size": "8250"}, {"price": "0.98", "size": "4000"}, {"price": "0.979", "size": "31000"}, {"price": "0.978", "size": "10.19"}, {"price": "0.96", "size": "1950"}, {"price": "0.95", "size": "30"}, {"price": "0.949", "size": "39"}, {"price": "0.94", "size": "1050"}, {"price": "0.93", "size": "3500"}, {"price": "0.929", "size": "7.07"}, {"price": "0.9", "size": "360"}, {"price": "0.88", "size": "375"}, {"price": "0.85", "size": "1051.66"}, {"price": "0.82", "size": "250"}, {"price": "0.8", "size": "960"}, {"price": "0.799", "size": "5.82"}, {"price": "0.75", "size": "262"}, {"price": "0.749", "size": "131"}, {"price": "0.73", "size": "50"}, {"price": "0.7", "size": "86.66"}, {"price": "0.65", "size": "68.57"}, {"price": "0.6", "size": "175"}, {"price": "0.482", "size": "699"}, {"price": "0.477", "size": "5"}, {"price": "0.474", "size": "121"}, {"price": "0.471", "size": "40"}, {"price": "0.469", "size": "30"}, {"price": "0.468", "size": "20"}, {"price": "0.12", "size": "50"}, {"price": "0.1", "size": "50"}, {"price": "0.08", "size": "175"}, {"price": "0.049", "size": "5"}, {"price": "0.034", "size": "69"}, {"price": "0.031", "size": "101"}, {"price": "0.027", "size": "93"}, {"price": "0.01", "size": "162.33"}, {"price": "0.008", "size": "8.38"}], "event_type": "book", "last_trade_price": "0.008"}, {"market": "0xfdc642275936ee1281df776b1b8a67a35eefbf9095c1266fd178dfa6996ebb4f", "asset_id": "55757497654516464627481151189384108294745827872104744655495700337681469992599", "timestamp": "1769384287044", "hash": "b7bf31d12025634de857e472233cf0f522c250a2", "bids": [{"price": "0.001", "size": "11007301.95"}, {"price": "0.002", "size": "61250"}, {"price": "0.003", "size": "1406.67"}, {"price": "0.006", "size": "200"}, {"price": "0.007", "size": "9.82"}, {"price": "0.01", "size": "8250"}, {"price": "0.02", "size": "35000"}, {"price": "0.021", "size": "10.96"}, {"price": "0.04", "size": "1250"}, {"price": "0.05", "size": "3330"}, {"price": "0.051", "size": "39"}, {"price": "0.06", "size": "750"}, {"price": "0.07", "size": "3500"}, {"price": "0.071", "size": "7.04"}, {"price": "0.1", "size": "360"}, {"price": "0.12", "size": "375"}, {"price": "0.15", "size": "1051.66"}, {"price": "0.18", "size": "250"}, {"price": "0.2", "size": "960"}, {"price": "0.201", "size": "5.82"}, {"price": "0.25", "size": "262"}, {"price": "0.27", "size": "50"}, {"price": "0.271", "size": "25"}, {"price": "0.3", "size": "86.66"}, {"price": "0.34", "size": "50"}, {"price": "0.35", "size": "68.57"}, {"price": "0.4", "size": "50"}, {"price": "0.401", "size": "146"}, {"price": "0.49", "size": "5"}, {"price": "0.533", "size": "10"}, {"price": "0.535", "size": "30"}, {"price": "0.536", "size": "25"}, {"price": "0.538", "size": "40"}, {"price": "0.539", "size": "20"}, {"price": "0.91", "size": "850"}, {"price": "0.913", "size": "100"}, {"price": "0.922", "size": "57.11"}, {"price": "0.927", "size": "16"}, {"price": "0.933", "size": "100"}, {"price": "0.938", "size": "300"}, {"price": "0.939", "size": "30"}, {"price": "0.955", "size": "6"}, {"price": "0.956", "size": "63.18"}, {"price": "0.957", "size": "13.51"}], "asks": [{"price": "0.999", "size": "61824"}, {"price": "0.998", "size": "5334.31"}, {"price": "0.997", "size": "5"}, {"price": "0.996", "size": "127"}, {"price": "0.995", "size": "147"}, {"price": "0.994", "size": "148"}], "event_type": "book", "last_trade_price": "0.014"}, {"market": "0x938e6a0a011f9534ffd2d86c65dde3aeb7c66ad06cee29ead70b832179c3b6de", "asset_id": "24797805539254249433781044462430878338801384554813443486130356027573519184087", "timestamp": "1769384094991", "hash": "39cc243ce5f30da9a32ed71bc9cc5535f467d52c", "bids": [{"price": "0.01", "size": "1111556.34"}, {"price": "0.02", "size": "25006.15"}, {"price": "0.03", "size": "3333"}, {"price": "0.04", "size": "1257.17"}, {"price": "0.05", "size": "720"}, {"price": "0.06", "size": "1050"}, {"price": "0.07", "size": "4500"}, {"price": "0.08", "size": "448.25"}, {"price": "0.09", "size": "5.49"}, {"price": "0.1", "size": "320"}, {"price": "0.12", "size": "375"}, {"price": "0.13", "size": "215.38"}, {"price": "0.15", "size": "825"}, {"price": "0.16", "size": "162.5"}, {"price": "0.17", "size": "28.57"}, {"price": "0.18", "size": "383.33"}, {"price": "0.19", "size": "5.42"}, {"price": "0.2", "size": "800"}, {"price": "0.21", "size": "345.23"}, {"price": "0.22", "size": "9"}, {"price": "0.23", "size": "10"}, {"price": "0.35", "size": "10"}, {"price": "0.38", "size": "250"}, {"price": "0.4", "size": "40"}, {"price": "0.41", "size": "101.7"}, {"price": "0.42", "size": "66.74"}, {"price": "0.43", "size": "20"}, {"price": "0.45", "size": "115"}, {"price": "0.46", "size": "6"}, {"price": "0.48", "size": "13.33"}, {"price": "0.5", "size": "100"}], "asks": [{"price": "0.99", "size": "317800"}, {"price": "0.98", "size": "12250"}, {"price": "0.97", "size": "6.66"}, {"price": "0.96", "size": "21000"}, {"price": "0.95", "size": "300"}, {"price": "0.93", "size": "450"}, {"price": "0.92", "size": "19.44"}, {"price": "0.86", "size": "325"}, {"price": "0.72", "size": "380"}, {"price": "0.65", "size": "9.99"}, {"price": "0.63", "size": "49.99"}, {"price": "0.61", "size": "100"}, {"price": "0.6", "size": "10"}, {"price": "0.58", "size": "850"}, {"price": "0.57", "size": "20"}, {"price": "0.52", "size": "1.99"}], "event_type": "book", "last_trade_price": "0.520"}, {"market": "0xfc64306c19c1faab6dee0e3d3bf4b1ec35599692a11eec762a7f54d25bc268f2", "asset_id": "87783727256798391598144762644215659792411859939354027829302503274879035245702", "timestamp": "1769384419531", "hash": "182fdcafa4146d2b24dcbd9d97a95628d2232f75", "bids": [{"price": "0.001", "size": "83650"}, {"price": "0.002", "size": "8284.47"}, {"price": "0.003", "size": "3755.51"}, {"price": "0.004", "size": "500"}, {"price": "0.005", "size": "25.44"}, {"price": "0.006", "size": "175.44"}, {"price": "0.008", "size": "28.4"}, {"price": "0.009", "size": "54.04"}], "asks": [{"price": "0.999", "size": "11007144.13"}, {"price": "0.998", "size": "61250"}, {"price": "0.997", "size": "1406.64"}, {"price": "0.994", "size": "200"}, {"price": "0.993", "size": "10.48"}, {"price": "0.99", "size": "8250"}, {"price": "0.98", "size": "4000"}, {"price": "0.979", "size": "21000"}, {"price": "0.978", "size": "10.22"}, {"price": "0.96", "size": "1250"}, {"price": "0.95", "size": "3330"}, {"price": "0.949", "size": "39"}, {"price": "0.94", "size": "750"}, {"price": "0.93", "size": "3500"}, {"price": "0.929", "size": "7.08"}, {"price": "0.9", "size": "397.5"}, {"price": "0.88", "size": "375"}, {"price": "0.85", "size": "1051.66"}, {"price": "0.82", "size": "250"}, {"price": "0.8", "size": "960"}, {"price": "0.799", "size": "5.81"}, {"price": "0.75", "size": "262"}, {"price": "0.749", "size": "106"}, {"price": "0.73", "size": "50"}, {"price": "0.7", "size": "86.66"}, {"price": "0.65", "size": "68.57"}, {"price": "0.6", "size": "175"}, {"price": "0.5", "size": "24.99"}, {"price": "0.458", "size": "601"}, {"price": "0.457", "size": "284"}, {"price": "0.456", "size": "5"}, {"price": "0.239", "size": "100"}, {"price": "0.223", "size": "40"}, {"price": "0.222", "size": "10"}, {"price": "0.15", "size": "15"}, {"price": "0.149", "size": "30"}, {"price": "0.148", "size": "20"}, {"price": "0.097", "size": "99.99"}, {"price": "0.058", "size": "13.33"}, {"price": "0.027", "size": "100"}, {"price": "0.026", "size": "14.75"}, {"price": "0.02", "size": "70"}], "event_type": "book", "last_trade_price": "0.009"}, {"market": "0xfc64306c19c1faab6dee0e3d3bf4b1ec35599692a11eec762a7f54d25bc268f2", "asset_id": "59580829599216932260845656819640492314194305910396233354387067124740172992769", "timestamp": "1769384419531", "hash": "ebb8ce0a19564806bcce06a5165f2a157776ed22", "bids": [{"price": "0.001", "size": "11007144.13"}, {"price": "0.002", "size": "61250"}, {"price": "0.003", "size": "1406.64"}, {"price": "0.006", "size": "200"}, {"price": "0.007", "size": "10.48"}, {"price": "0.01", "size": "8250"}, {"price": "0.02", "size": "4000"}, {"price": "0.021", "size": "21000"}, {"price": "0.022", "size": "10.22"}, {"price": "0.04", "size": "1250"}, {"price": "0.05", "size": "3330"}, {"price": "0.051", "size": "39"}, {"price": "0.06", "size": "750"}, {"price": "0.07", "size": "3500"}, {"price": "0.071", "size": "7.08"}, {"price": "0.1", "size": "397.5"}, {"price": "0.12", "size": "375"}, {"price": "0.15", "size": "1051.66"}, {"price": "0.18", "size": "250"}, {"price": "0.2", "size": "960"}, {"price": "0.201", "size": "5.81"}, {"price": "0.25", "size": "262"}, {"price": "0.251", "size": "106"}, {"price": "0.27", "size": "50"}, {"price": "0.3", "size": "86.66"}, {"price": "0.35", "size": "68.57"}, {"price": "0.4", "size": "175"}, {"price": "0.5", "size": "24.99"}, {"price": "0.542", "size": "601"}, {"price": "0.543", "size": "284"}, {"price": "0.544", "size": "5"}, {"price": "0.761", "size": "100"}, {"price": "0.777", "size": "40"}, {"price": "0.778", "size": "10"}, {"price": "0.85", "size": "15"}, {"price": "0.851", "size": "30"}, {"price": "0.852", "size": "20"}, {"price": "0.903", "size": "99.99"}, {"price": "0.942", "size": "13.33"}, {"price": "0.973", "size": "100"}, {"price": "0.974", "size": "14.75"}, {"price": "0.98", "size": "70"}], "asks": [{"price": "0.999", "size": "83650"}, {"price": "0.998", "size": "8284.47"}, {"price": "0.997", "size": "3755.51"}, {"price": "0.996", "size": "500"}, {"price": "0.995", "size": "25.44"}, {"price": "0.994", "size": "175.44"}, {"price": "0.992", "size": "28.4"}, {"price": "0.991", "size": "54.04"}], "event_type": "book", "last_trade_price": "0.009"}, {"market": "0xfdc642275936ee1281df776b1b8a67a35eefbf9095c1266fd178dfa6996ebb4f", "asset_id": "75055518491634343238225754172066804322353911200619603473770017059656868007002", "timestamp": "1769384287044", "hash": "8316dfbbb8e43b4e2a2b9b51faa69db4ebbc6c99", "bids": [{"price": "0.001", "size": "61824"}, {"price": "0.002", "size": "5334.31"}, {"price": "0.003", "size": "5"}, {"price": "0.004", "size": "127"}, {"price": "0.005", "size": "147"}, {"price": "0.006", "size": "148"}], "asks": [{"price": "0.999", "size": "11007301.95"}, {"price": "0.998", "size": "61250"}, {"price": "0.997", "size": "1406.67"}, {"price": "0.994", "size": "200"}, {"price": "0.993", "size": "9.82"}, {"price": "0.99", "size": "8250"}, {"price": "0.98", "size": "35000"}, {"price": "0.979", "size": "10.96"}, {"price": "0.96", "size": "1250"}, {"price": "0.95", "size": "3330"}, {"price": "0.949", "size": "39"}, {"price": "0.94", "size": "750"}, {"price": "0.93", "size": "3500"}, {"price": "0.929", "size": "7.04"}, {"price": "0.9", "size": "360"}, {"price": "0.88", "size": "375"}, {"price": "0.85", "size": "1051.66"}, {"price": "0.82", "size": "250"}, {"price": "0.8", "size": "960"}, {"price": "0.799", "size": "5.82"}, {"price": "0.75", "size": "262"}, {"price": "0.73", "size": "50"}, {"price": "0.729", "size": "25"}, {"price": "0.7", "size": "86.66"}, {"price": "0.66", "size": "50"}, {"price": "0.65", "size": "68.57"}, {"price": "0.6", "size": "50"}, {"price": "0.599", "size": "146"}, {"price": "0.51", "size": "5"}, {"price": "0.467", "size": "10"}, {"price": "0.465", "size": "30"}, {"price": "0.464", "size": "25"}, {"price": "0.462", "size": "40"}, {"price": "0.461", "size": "20"}, {"price": "0.09", "size": "850"}, {"price": "0.087", "size": "100"}, {"price": "0.078", "size": "57.11"}, {"price": "0.073", "size": "16"}, {"price": "0.067", "size": "100"}, {"price": "0.062", "size": "300"}, {"price": "0.061", "size": "30"}, {"price": "0.045", "size": "6"}, {"price": "0.044", "size": "63.18"}, {"price": "0.043", "size": "13.51"}], "event_type": "book", "last_trade_price": "0.014"}, {"market": "0x1cbe7cbbfb481ed76c054bc4c36c6fb966a2d1671d908d0e89e1f22b0adfa1d6", "asset_id": "76756244323959292580621865343466747413597132817678365592077495382609595329059", "timestamp": "1769384421106", "hash": "b0954d832a588f9f3aa20ea2167722b58301db1a", "bids": [{"price": "0.001", "size": "68025.5"}, {"price": "0.002", "size": "5275.06"}, {"price": "0.003", "size": "250"}, {"price": "0.006", "size": "9.04"}, {"price": "0.007", "size": "24.8"}], "asks": [{"price": "0.999", "size": "11007151.04"}, {"price": "0.998", "size": "61250"}, {"price": "0.997", "size": "1406.65"}, {"price": "0.994", "size": "200"}, {"price": "0.993", "size": "9.8"}, {"price": "0.99", "size": "8250"}, {"price": "0.988", "size": "60000"}, {"price": "0.98", "size": "35000"}, {"price": "0.979", "size": "10.95"}, {"price": "0.96", "size": "13250"}, {"price": "0.95", "size": "3330"}, {"price": "0.949", "size": "39"}, {"price": "0.94", "size": "950"}, {"price": "0.93", "size": "300"}, {"price": "0.929", "size": "7.08"}, {"price": "0.9", "size": "360"}, {"price": "0.88", "size": "375"}, {"price": "0.85", "size": "1051.66"}, {"price": "0.82", "size": "250"}, {"price": "0.8", "size": "960"}, {"price": "0.799", "size": "250"}, {"price": "0.798", "size": "5.78"}, {"price": "0.75", "size": "112"}, {"price": "0.7", "size": "286.66"}, {"price": "0.66", "size": "50"}, {"price": "0.65", "size": "68.57"}, {"price": "0.6", "size": "50"}, {"price": "0.599", "size": "214"}, {"price": "0.598", "size": "5"}, {"price": "0.597", "size": "10"}, {"price": "0.317", "size": "70"}, {"price": "0.315", "size": "15"}, {"price": "0.314", "size": "20"}, {"price": "0.135", "size": "100.6"}, {"price": "0.134", "size": "10"}, {"price": "0.09", "size": "850"}, {"price": "0.049", "size": "5"}, {"price": "0.03", "size": "300"}, {"price": "0.029", "size": "30"}, {"price": "0.013", "size": "200"}, {"price": "0.009", "size": "133.33"}, {"price": "0.008", "size": "259"}], "event_type": "book", "last_trade_price": "0.009"}, {"market": "0x3936de01f890af302ca75727b772fe6dffe915ce638a08809042a3a81dd346c0", "asset_id": "93832008664246723386944798388205104088345581837255215982492503205563374375162", "timestamp": "1769384287044", "hash": "686c8f75f2a2837b90f57584efec7731b739ba2e", "bids": [{"price": "0.001", "size": "11007151"}, {"price": "0.002", "size": "61250"}, {"price": "0.003", "size": "1406.63"}, {"price": "0.006", "size": "200"}, {"price": "0.007", "size": "9.77"}, {"price": "0.01", "size": "8250"}, {"price": "0.02", "size": "35000"}, {"price": "0.021", "size": "10.91"}, {"price": "0.04", "size": "1250"}, {"price": "0.05", "size": "3330"}, {"price": "0.051", "size": "39"}, {"price": "0.06", "size": "750"}, {"price": "0.07", "size": "3500"}, {"price": "0.071", "size": "7.02"}, {"price": "0.1", "size": "360"}, {"price": "0.12", "size": "375"}, {"price": "0.15", "size": "1051.66"}, {"price": "0.18", "size": "250"}, {"price": "0.2", "size": "960"}, {"price": "0.201", "size": "250"}, {"price": "0.202", "size": "5.81"}, {"price": "0.25", "size": "262"}, {"price": "0.27", "size": "50"}, {"price": "0.3", "size": "86.66"}, {"price": "0.34", "size": "50"}, {"price": "0.35", "size": "68.57"}, {"price": "0.4", "size": "50"}, {"price": "0.414", "size": "399"}, {"price": "0.415", "size": "10"}, {"price": "0.417", "size": "15"}, {"price": "0.84", "size": "700"}, {"price": "0.852", "size": "40"}, {"price": "0.856", "size": "30"}, {"price": "0.858", "size": "10"}, {"price": "0.859", "size": "20"}, {"price": "0.906", "size": "66.67"}, {"price": "0.92", "size": "150"}, {"price": "0.945", "size": "50"}, {"price": "0.955", "size": "50"}, {"price": "0.963", "size": "200"}, {"price": "0.965", "size": "340.97"}, {"price": "0.97", "size": "6.34"}, {"price": "0.971", "size": "26"}], "asks": [{"price": "0.999", "size": "60354.35"}, {"price": "0.998", "size": "5225.09"}, {"price": "0.997", "size": "11.54"}, {"price": "0.996", "size": "130"}, {"price": "0.992", "size": "158.7"}, {"price": "0.991", "size": "145.6"}], "event_type": "book", "last_trade_price": "0.009"}, {"market": "0x91ebc8bf88c5f99dd4550cb75255766f638d1932ede36e8eae78a76df0c15455", "asset_id": "63365825049551318024252373648592413954954442733807178648368002993460348485956", "timestamp": "1769384287044", "hash": "f4022c8669bd7150a3d29388448d73a6ff7018ea", "bids": [{"price": "0.001", "size": "3851.05"}, {"price": "0.002", "size": "1250"}, {"price": "0.003", "size": "1406.66"}, {"price": "0.006", "size": "200"}, {"price": "0.007", "size": "9.81"}, {"price": "0.01", "size": "1111550"}, {"price": "0.02", "size": "35000"}, {"price": "0.021", "size": "13.83"}, {"price": "0.04", "size": "1250"}, {"price": "0.05", "size": "3330"}, {"price": "0.051", "size": "39"}, {"price": "0.055", "size": "7.22"}, {"price": "0.06", "size": "750"}, {"price": "0.07", "size": "2000"}, {"price": "0.084", "size": "2700"}, {"price": "0.085", "size": "5.21"}, {"price": "0.1", "size": "360"}, {"price": "0.12", "size": "375"}, {"price": "0.15", "size": "1051.66"}, {"price": "0.18", "size": "250"}, {"price": "0.2", "size": "960"}, {"price": "0.201", "size": "250"}, {"price": "0.202", "size": "5.78"}, {"price": "0.25", "size": "262"}, {"price": "0.27", "size": "50"}, {"price": "0.3", "size": "86.66"}, {"price": "0.34", "size": "50"}, {"price": "0.35", "size": "68.57"}, {"price": "0.39", "size": "51.28"}, {"price": "0.41", "size": "563"}, {"price": "0.411", "size": "126.5"}, {"price": "0.419", "size": "60"}, {"price": "0.42", "size": "5"}, {"price": "0.75", "size": "5"}, {"price": "0.751", "size": "10"}, {"price": "0.8", "size": "10"}, {"price": "0.807", "size": "30"}, {"price": "0.808", "size": "40"}, {"price": "0.809", "size": "15"}, {"price": "0.83", "size": "6.96"}, {"price": "0.839", "size": "10"}, {"price": "0.84", "size": "20"}, {"price": "0.87", "size": "23.25"}, {"price": "0.88", "size": "100"}, {"price": "0.9", "size": "250"}, {"price": "0.901", "size": "66.66"}, {"price": "0.91", "size": "6.96"}, {"price": "0.919", "size": "66.66"}, {"price": "0.92", "size": "100"}, {"price": "0.928", "size": "223.27"}, {"price": "0.934", "size": "40"}, {"price": "0.937", "size": "73.66"}, {"price": "0.938", "size": "63.18"}], "asks": [{"price": "0.999", "size": "72196"}, {"price": "0.998", "size": "4666.44"}, {"price": "0.997", "size": "40.73"}, {"price": "0.99", "size": "230.19"}, {"price": "0.989", "size": "300"}, {"price": "0.988", "size": "5.41"}, {"price": "0.987", "size": "295.33"}, {"price": "0.986", "size": "27.09"}, {"price": "0.985", "size": "184.69"}, {"price": "0.982", "size": "43.46"}, {"price": "0.976", "size": "68.46"}], "event_type": "book", "last_trade_price": "0.045"}, {"market": "0x29134729ec74a0dbab6ddad9d9a745e4c0b83c59682bdc4b76412c9635d66627", "asset_id": "63263918316087383998965771464254486398250019398684443889644959466369157825041", "timestamp": "1769384440601", "hash": "e6a86723180fd36dd2d267cca9b4b4a452a1d1fd", "bids": [{"price": "0.001", "size": "11007196.92"}, {"price": "0.002", "size": "61255"}, {"price": "0.003", "size": "1400"}, {"price": "0.004", "size": "9.91"}, {"price": "0.006", "size": "200"}, {"price": "0.01", "size": "8250"}, {"price": "0.011", "size": "60000"}, {"price": "0.012", "size": "7.63"}, {"price": "0.02", "size": "35000"}, {"price": "0.03", "size": "12000"}, {"price": "0.031", "size": "5.01"}, {"price": "0.04", "size": "1250"}, {"price": "0.05", "size": "3330"}, {"price": "0.051", "size": "39"}, {"price": "0.06", "size": "750"}, {"price": "0.064", "size": "3400"}, {"price": "0.065", "size": "8.09"}, {"price": "0.09", "size": "500"}, {"price": "0.12", "size": "375"}, {"price": "0.14", "size": "242.85"}, {"price": "0.15", "size": "825"}, {"price": "0.18", "size": "250"}, {"price": "0.19", "size": "168.42"}, {"price": "0.2", "size": "800"}, {"price": "0.201", "size": "5.83"}, {"price": "0.24", "size": "116.66"}, {"price": "0.28", "size": "92.85"}, {"price": "0.283", "size": "100"}, {"price": "0.284", "size": "653"}, {"price": "0.33", "size": "72.72"}, {"price": "0.38", "size": "52.63"}, {"price": "0.382", "size": "207"}, {"price": "0.383", "size": "5"}, {"price": "0.384", "size": "10"}, {"price": "0.783", "size": "40"}, {"price": "0.784", "size": "20"}, {"price": "0.8", "size": "400"}, {"price": "0.801", "size": "66.66"}, {"price": "0.802", "size": "30"}, {"price": "0.81", "size": "30.61"}, {"price": "0.85", "size": "66.66"}, {"price": "0.875", "size": "13"}, {"price": "0.897", "size": "280"}, {"price": "0.899", "size": "42.14"}, {"price": "0.9", "size": "66.66"}], "asks": [{"price": "0.999", "size": "172862"}, {"price": "0.998", "size": "7006.55"}, {"price": "0.997", "size": "800"}, {"price": "0.995", "size": "500"}, {"price": "0.994", "size": "5.27"}, {"price": "0.99", "size": "92.74"}, {"price": "0.988", "size": "500"}, {"price": "0.987", "size": "400"}, {"price": "0.986", "size": "200"}, {"price": "0.985", "size": "100"}, {"price": "0.984", "size": "9.7"}, {"price": "0.975", "size": "273.97"}, {"price": "0.973", "size": "68"}, {"price": "0.966", "size": "100"}, {"price": "0.965", "size": "30"}, {"price": "0.961", "size": "50"}, {"price": "0.95", "size": "150"}, {"price": "0.946", "size": "79.97"}, {"price": "0.924", "size": "10.43"}, {"price": "0.923", "size": "7.08"}, {"price": "0.92", "size": "20"}, {"price": "0.919", "size": "25"}], "event_type": "book", "last_trade_price": ""}, {"market": "0x021e7689a90ac39c268a39ddff6269fd0f41ed84ea6833f6e5b7d900569e6d8b", "asset_id": "21609653795728383864795868045140971967534750053984809993030488713671979919753", "timestamp": "1769384418185", "hash": "4bd5185a60b009bb2931d2cbdf758aa76039dc46", "bids": [{"price": "0.001", "size": "11007151"}, {"price": "0.002", "size": "61250"}, {"price": "0.003", "size": "1406.63"}, {"price": "0.006", "size": "200"}, {"price": "0.007", "size": "10.45"}, {"price": "0.01", "size": "8250"}, {"price": "0.02", "size": "4000"}, {"price": "0.021", "size": "31000"}, {"price": "0.022", "size": "10.19"}, {"price": "0.04", "size": "1950"}, {"price": "0.05", "size": "30"}, {"price": "0.051", "size": "39"}, {"price": "0.06", "size": "1050"}, {"price": "0.07", "size": "3500"}, {"price": "0.071", "size": "7.07"}, {"price": "0.1", "size": "360"}, {"price": "0.12", "size": "375"}, {"price": "0.15", "size": "1051.66"}, {"price": "0.18", "size": "250"}, {"price": "0.2", "size": "960"}, {"price": "0.201", "size": "5.82"}, {"price": "0.25", "size": "262"}, {"price": "0.251", "size": "131"}, {"price": "0.27", "size": "50"}, {"price": "0.3", "size": "86.66"}, {"price": "0.35", "size": "68.57"}, {"price": "0.4", "size": "175"}, {"price": "0.518", "size": "699"}, {"price": "0.523", "size": "5"}, {"price": "0.526", "size": "121"}, {"price": "0.529", "size": "40"}, {"price": "0.531", "size": "30"}, {"price": "0.532", "size": "20"}, {"price": "0.88", "size": "50"}, {"price": "0.9", "size": "50"}, {"price": "0.92", "size": "175"}, {"price": "0.951", "size": "5"}, {"price": "0.966", "size": "69"}, {"price": "0.969", "size": "101"}, {"price": "0.973", "size": "93"}, {"price": "0.99", "size": "162.33"}, {"price": "0.992", "size": "8.38"}], "asks": [{"price": "0.999", "size": "68205"}, {"price": "0.998", "size": "5553.28"}, {"price": "0.997", "size": "347.1"}, {"price": "0.996", "size": "175.52"}, {"price": "0.995", "size": "56.82"}, {"price": "0.994", "size": "35.52"}], "event_type": "book", "last_trade_price": "0.008"}]}
{"_local_timestamp": "2026-01-25T23:41:06.868191+00:00", "data": {"market": "0x29134729ec74a0dbab6ddad9d9a745e4c0b83c59682bdc4b76412c9635d66627", "price_changes": [{"asset_id": "109408722309726159994284194907981745959708334274938135190768342039858793034476", "price": "0.013", "size": "300", "side": "BUY", "hash": "0e97f4cb6c2469e045199ccb23a36d045f2b296d", "best_bid": "0.081", "best_ask": "0.1"}, {"asset_id": "63263918316087383998965771464254486398250019398684443889644959466369157825041", "price": "0.987", "size": "300", "side": "SELL", "hash": "93b83b025a0fff20642d50be93b24b1c8156a2f0", "best_bid": "0.9", "best_ask": "0.919"}], "timestamp": "1769384466650", "event_type": "price_change"}}
{"_local_timestamp": "2026-01-25T23:41:17.952166+00:00", "data": {"market": "0xfc64306c19c1faab6dee0e3d3bf4b1ec35599692a11eec762a7f54d25bc268f2", "price_changes": [{"asset_id": "87783727256798391598144762644215659792411859939354027829302503274879035245702", "price": "0.026", "size": "0", "side": "SELL", "hash": "8a309b4e6684054499e0149e45efad65f840d79d", "best_bid": "0.009", "best_ask": "0.02"}, {"asset_id": "59580829599216932260845656819640492314194305910396233354387067124740172992769", "price": "0.974", "size": "0", "side": "BUY", "hash": "34b3726cc118b94c0815592d2684425e65fc8aa3", "best_bid": "0.98", "best_ask": "0.991"}], "timestamp": "1769384477839", "event_type": "price_change"}}
{"_local_timestamp": "2026-01-25T23:41:19.051486+00:00", "data": {"market": "0xfc64306c19c1faab6dee0e3d3bf4b1ec35599692a11eec762a7f54d25bc268f2", "price_changes": [{"asset_id": "87783727256798391598144762644215659792411859939354027829302503274879035245702", "price": "0.026", "size": "14.75", "side": "SELL", "hash": "ab1d8b4351707eae812f898f716399eb6fda3407", "best_bid": "0.009", "best_ask": "0.02"}, {"asset_id": "59580829599216932260845656819640492314194305910396233354387067124740172992769", "price": "0.974", "size": "14.75", "side": "BUY", "hash": "247454214622a2a9067fcf054a16805f4bbd562b", "best_bid": "0.98", "best_ask": "0.991"}], "timestamp": "1769384478981", "event_type": "price_change"}}
{"_local_timestamp": "2026-01-25T23:41:44.134620+00:00", "data": {"market": "0x29134729ec74a0dbab6ddad9d9a745e4c0b83c59682bdc4b76412c9635d66627", "price_changes": [{"asset_id": "109408722309726159994284194907981745959708334274938135190768342039858793034476", "price": "0.05", "size": "0", "side": "BUY", "hash": "0109f0b5efd2d4cab5c20b62344330918c80bc65", "best_bid": "0.081", "best_ask": "0.1"}, {"asset_id": "63263918316087383998965771464254486398250019398684443889644959466369157825041", "price": "0.95", "size": "0", "side": "SELL", "hash": "5ba10f5eedc839bc1658098052991dd4cad395b4", "best_bid": "0.9", "best_ask": "0.919"}], "timestamp": "1769384504071", "event_type": "price_change"}}
{"_local_timestamp": "2026-01-25T23:41:44.259494+00:00", "data": {"market": "0x0afa82ff8cb4dcf8c7a248ccaf438597619d3a6a4e4463adb109e1a1034d6e10", "price_changes": [{"asset_id": "69317727912918260368347049966647382207251169560838202627585212468740589465040", "price": "0.45", "size": "0", "side": "BUY", "hash": "e94ae58a2e26940844634dd64b31816139b95fd0", "best_bid": "0.74", "best_ask": "0.76"}, {"asset_id": "30455848075861160607924869725570428601171045624621952729814709348346858289488", "price": "0.55", "size": "0", "side": "SELL", "hash": "b89b8d76a20a96e5e9f4477d68e09cfa91d64def", "best_bid": "0.24", "best_ask": "0.26"}], "timestamp": "1769384504193", "event_type": "price_change"}}
{"_local_timestamp": "2026-01-25T23:41:44.302637+00:00", "data": {"market": "0x021e7689a90ac39c268a39ddff6269fd0f41ed84ea6833f6e5b7d900569e6d8b", "price_changes": [{"asset_id": "21609653795728383864795868045140971967534750053984809993030488713671979919753", "price": "0.518", "size": "506", "side": "BUY", "hash": "bbd891702205f9f92286e447e581b6e0b3dc4ac5", "best_bid": "0.992", "best_ask": "0.994"}, {"asset_id": "25265857280574792887110878653665871891927967464924536706348687031929049209739", "price": "0.482", "size": "506", "side": "SELL", "hash": "177f209fe3cbd011fa2121afc9bfb343d4f1babe", "best_bid": "0.006", "best_ask": "0.008"}], "timestamp": "1769384504228", "event_type": "price_change"}}
{"_local_timestamp": "2026-01-25T23:41:44.369727+00:00", "data": {"market": "0x0afa82ff8cb4dcf8c7a248ccaf438597619d3a6a4e4463adb109e1a1034d6e10", "price_changes": [{"asset_id": "69317727912918260368347049966647382207251169560838202627585212468740589465040", "price": "0.48", "size": "30", "side": "BUY", "hash": "9ba17939d16edceb0ecef5ed0aeaf110ef3ee723", "best_bid": "0.74", "best_ask": "0.76"}, {"asset_id": "30455848075861160607924869725570428601171045624621952729814709348346858289488", "price": "0.52", "size": "30", "side": "SELL", "hash": "6b277224f0ca8c9ec10d8721a8115b66d41dd259", "best_bid": "0.24", "best_ask": "0.26"}], "timestamp": "1769384504297", "event_type": "price_change"}}
{"_local_timestamp": "2026-01-25T23:41:44.503168+00:00", "data": {"market": "0x021e7689a90ac39c268a39ddff6269fd0f41ed84ea6833f6e5b7d900569e6d8b", "price_changes": [{"asset_id": "21609653795728383864795868045140971967534750053984809993030488713671979919753", "price": "0.526", "size": "311", "side": "BUY", "hash": "f6db6a5d4ccc724ea8a3334af2e1947b58b82bfe", "best_bid": "0.992", "best_ask": "0.994"}, {"asset_id": "25265857280574792887110878653665871891927967464924536706348687031929049209739", "price": "0.474", "size": "311", "side": "SELL", "hash": "a3c6b64cd61725f774988cbfcbffd9778ffc5411", "best_bid": "0.006", "best_ask": "0.008"}], "timestamp": "1769384504437", "event_type": "price_change"}}
{"_local_timestamp": "2026-01-25T23:41:44.503486+00:00", "data": {"market": "0x021e7689a90ac39c268a39ddff6269fd0f41ed84ea6833f6e5b7d900569e6d8b", "price_changes": [{"asset_id": "21609653795728383864795868045140971967534750053984809993030488713671979919753", "price": "0.533", "size": "10", "side": "BUY", "hash": "44d9e60c2350541f1ca44bf3c08c5383d810d722", "best_bid": "0.992", "best_ask": "0.994"}, {"asset_id": "25265857280574792887110878653665871891927967464924536706348687031929049209739", "price": "0.467", "size": "10", "side": "SELL", "hash": "2ed046a28f72977a1347904511788ce64f2375fc", "best_bid": "0.006", "best_ask": "0.008"}], "timestamp": "1769384504438", "event_type": "price_change"}}
{"_local_timestamp": "2026-01-25T23:41:44.503770+00:00", "data": {"market": "0x021e7689a90ac39c268a39ddff6269fd0f41ed84ea6833f6e5b7d900569e6d8b", "price_changes": [{"asset_id": "21609653795728383864795868045140971967534750053984809993030488713671979919753", "price": "0.533", "size": "25", "side": "BUY", "hash": "7b7049286681b3dd1494ee4b80cd94ca37670843", "best_bid": "0.992", "best_ask": "0.994"}, {"asset_id": "25265857280574792887110878653665871891927967464924536706348687031929049209739", "price": "0.467", "size": "25", "side": "SELL", "hash": "752ba0622e6c2fb396071ec3052ca98a79beaf79", "best_bid": "0.006", "best_ask": "0.008"}], "timestamp": "1769384504439", "event_type": "price_change"}}
{"_local_timestamp": "2026-01-25T23:41:44.619081+00:00", "data": {"market": "0x021e7689a90ac39c268a39ddff6269fd0f41ed84ea6833f6e5b7d900569e6d8b", "price_changes": [{"asset_id": "21609653795728383864795868045140971967534750053984809993030488713671979919753", "price": "0.518", "size": "249", "side": "BUY", "hash": "2843b21a80d5044f4541fb0e2063893b4d9769ba", "best_bid": "0.992", "best_ask": "0.994"}, {"asset_id": "25265857280574792887110878653665871891927967464924536706348687031929049209739", "price": "0.482", "size": "249", "side": "SELL", "hash": "94921d312ff1b7c7b3b82c856386e2e4231af0b2", "best_bid": "0.006", "best_ask": "0.008"}], "timestamp": "1769384504542", "event_type": "price_change"}}
{"_local_timestamp": "2026-01-25T23:41:44.665792+00:00", "data": {"market": "0x021e7689a90ac39c268a39ddff6269fd0f41ed84ea6833f6e5b7d900569e6d8b", "price_changes": [{"asset_id": "21609653795728383864795868045140971967534750053984809993030488713671979919753", "price": "0.518", "size": "0", "side": "BUY", "hash": "df5f0dbfce68e328e02718d234ac2afcaa78c7ec", "best_bid": "0.992", "best_ask": "0.994"}, {"asset_id": "25265857280574792887110878653665871891927967464924536706348687031929049209739", "price": "0.482", "size": "0", "side": "SELL", "hash": "30ec4654a041099e7cfff2b4105fbe74eb93040f", "best_bid": "0.006", "best_ask": "0.008"}], "timestamp": "1769384504595", "event_type": "price_change"}}
{"_local_timestamp": "2026-01-25T23:41:44.666246+00:00", "data": {"market": "0x021e7689a90ac39c268a39ddff6269fd0f41ed84ea6833f6e5b7d900569e6d8b", "price_changes": [{"asset_id": "21609653795728383864795868045140971967534750053984809993030488713671979919753", "price": "0.526", "size": "504", "side": "BUY", "hash": "639e5f3a5afc38fab97a3f63df00cc428625c9b7", "best_bid": "0.992", "best_ask": "0.994"}, {"asset_id": "25265857280574792887110878653665871891927967464924536706348687031929049209739", "price": "0.474", "size": "504", "side": "SELL", "hash": "9050e2b3c6a240a4b5864252701f784879c5e8d2", "best_bid": "0.006", "best_ask": "0.008"}], "timestamp": "1769384504597", "event_type": "price_change"}}
{"_local_timestamp": "2026-01-25T23:41:44.732264+00:00", "data": {"market": "0x021e7689a90ac39c268a39ddff6269fd0f41ed84ea6833f6e5b7d900569e6d8b", "price_changes": [{"asset_id": "21609653795728383864795868045140971967534750053984809993030488713671979919753", "price": "0.526", "size": "691", "side": "BUY", "hash": "4a122dcf5c8f558072e2edf1e9dd49e5e8799b55", "best_bid": "0.992", "best_ask": "0.994"}, {"asset_id": "25265857280574792887110878653665871891927967464924536706348687031929049209739", "price": "0.474", "size": "691", "side": "SELL", "hash": "9bec5b66f1a6efa76b0c49bc14de1cb96fff2cdc", "best_bid": "0.006", "best_ask": "0.008"}], "timestamp": "1769384504659", "event_type": "price_change"}}
{"_local_timestamp": "2026-01-25T23:41:44.972884+00:00", "data": {"market": "0xfdc642275936ee1281df776b1b8a67a35eefbf9095c1266fd178dfa6996ebb4f", "price_changes": [{"asset_id": "55757497654516464627481151189384108294745827872104744655495700337681469992599", "price": "0.536", "size": "15", "side": "BUY", "hash": "459c6deba1aee8966936eb32692569e56a53897e", "best_bid": "0.957", "best_ask": "0.994"}, {"asset_id": "75055518491634343238225754172066804322353911200619603473770017059656868007002", "price": "0.464", "size": "15", "side": "SELL", "hash": "491c53fbabc48bdc790e4d7727934551972362ec", "best_bid": "0.006", "best_ask": "0.043"}], "timestamp": "1769384504909", "event_type": "price_change"}}
{"_local_timestamp": "2026-01-25T23:41:45.222931+00:00", "data": {"market": "0x021e7689a90ac39c268a39ddff6269fd0f41ed84ea6833f6e5b7d900569e6d8b", "price_changes": [{"asset_id": "21609653795728383864795868045140971967534750053984809993030488713671979919753", "price": "0.532", "size": "0", "side": "BUY", "hash": "11907c93f1b1e06a7f664aaf9f9b22ae8d067e7e", "best_bid": "0.992", "best_ask": "0.994"}, {"asset_id": "25265857280574792887110878653665871891927967464924536706348687031929049209739", "price": "0.468", "size": "0", "side": "SELL", "hash": "db5377e4d39a6f826f424db30600583126dfabf3", "best_bid": "0.006", "best_ask": "0.008"}], "timestamp": "1769384505149", "event_type": "price_change"}}
{"_local_timestamp": "2026-01-25T23:41:45.246737+00:00", "data": {"market": "0x021e7689a90ac39c268a39ddff6269fd0f41ed84ea6833f6e5b7d900569e6d8b", "price_changes": [{"asset_id": "21609653795728383864795868045140971967534750053984809993030488713671979919753", "price": "0.534", "size": "20", "side": "BUY", "hash": "0653b2e4582113fd78014ea35bb9f884a3870933", "best_bid": "0.992", "best_ask": "0.994"}, {"asset_id": "25265857280574792887110878653665871891927967464924536706348687031929049209739", "price": "0.466", "size": "20", "side": "SELL", "hash": "5c54c16d57003e338e0df0e5f05ffe52b0d8bccc", "best_bid": "0.006", "best_ask": "0.008"}], "timestamp": "1769384505175", "event_type": "price_change"}}
{"_local_timestamp": "2026-01-25T23:41:45.343458+00:00", "data": {"market": "0xfdc642275936ee1281df776b1b8a67a35eefbf9095c1266fd178dfa6996ebb4f", "price_changes": [{"asset_id": "55757497654516464627481151189384108294745827872104744655495700337681469992599", "price": "0.536", "size": "0", "side": "BUY", "hash": "75e1b90e9ae18416e32ad0035d2b1422a6386270", "best_bid": "0.957", "best_ask": "0.994"}, {"asset_id": "75055518491634343238225754172066804322353911200619603473770017059656868007002", "price": "0.464", "size": "0", "side": "SELL", "hash": "8ce5349f7765db589793aca1eebe64604142bdc7", "best_bid": "0.006", "best_ask": "0.043"}], "timestamp": "1769384505249", "event_type": "price_change"}}
{"_local_timestamp": "2026-01-25T23:41:45.377033+00:00", "data": {"market": "0xfdc642275936ee1281df776b1b8a67a35eefbf9095c1266fd178dfa6996ebb4f", "price_changes": [{"asset_id": "55757497654516464627481151189384108294745827872104744655495700337681469992599", "price": "0.54", "size": "15", "side": "BUY", "hash": "fd76fbc982977f5617543c0644574889a58000c8", "best_bid": "0.957", "best_ask": "0.994"}, {"asset_id": "75055518491634343238225754172066804322353911200619603473770017059656868007002", "price": "0.46", "size": "15", "side": "SELL", "hash": "e0405a6f29dad9ee6cff997715ed0f743e3f0a03", "best_bid": "0.006", "best_ask": "0.043"}], "timestamp": "1769384505304", "event_type": "price_change"}}
{"_local_timestamp": "2026-01-25T23:41:45.378100+00:00", "data": {"market": "0xfdc642275936ee1281df776b1b8a67a35eefbf9095c1266fd178dfa6996ebb4f", "price_changes": [{"asset_id": "55757497654516464627481151189384108294745827872104744655495700337681469992599", "price": "0.54", "size": "25", "side": "BUY", "hash": "ab82198b5b38aadd544108411dfaaad43e6741cb", "best_bid": "0.957", "best_ask": "0.994"}, {"asset_id": "75055518491634343238225754172066804322353911200619603473770017059656868007002", "price": "0.46", "size": "25", "side": "SELL", "hash": "ed20c5ef6758ced530b18202bb76bb603b031c8b", "best_bid": "0.006", "best_ask": "0.043"}], "timestamp": "1769384505305", "event_type": "price_change"}}
{"_local_timestamp": "2026-01-25T23:41:47.614640+00:00", "data": {"market": "0xfdc642275936ee1281df776b1b8a67a35eefbf9095c1266fd178dfa6996ebb4f", "price_changes": [{"asset_id": "55757497654516464627481151189384108294745827872104744655495700337681469992599", "price": "0.539", "size": "0", "side": "BUY", "hash": "8dae17462028e2627a40b768d3811382022edad0", "best_bid": "0.957", "best_ask": "0.994"}, {"asset_id": "75055518491634343238225754172066804322353911200619603473770017059656868007002", "price": "0.461", "size": "0", "side": "SELL", "hash": "a8ff6ad1e1b636ca1f3d93c7fe96e97922cc80bf", "best_bid": "0.006", "best_ask": "0.043"}], "timestamp": "1769384507542", "event_type": "price_change"}}
{"_local_timestamp": "2026-01-25T23:41:47.638841+00:00", "data": {"market": "0xfdc642275936ee1281df776b1b8a67a35eefbf9095c1266fd178dfa6996ebb4f", "price_changes": [{"asset_id": "55757497654516464627481151189384108294745827872104744655495700337681469992599", "price": "0.541", "size": "20", "side": "BUY", "hash": "27b59b1909a0ba3966c5688b8d7e1523448bcb59", "best_bid": "0.957", "best_ask": "0.994"}, {"asset_id": "75055518491634343238225754172066804322353911200619603473770017059656868007002", "price": "0.459", "size": "20", "side": "SELL", "hash": "5423fa8fdea0a678dae2788eb6f4a64217c7182f", "best_bid": "0.006", "best_ask": "0.043"}], "timestamp": "1769384507568", "event_type": "price_change"}}
{"_local_timestamp": "2026-01-25T23:41:50.912173+00:00", "data": {"market": "0x29134729ec74a0dbab6ddad9d9a745e4c0b83c59682bdc4b76412c9635d66627", "price_changes": [{"asset_id": "63263918316087383998965771464254486398250019398684443889644959466369157825041", "price": "0.283", "size": "0", "side": "BUY", "hash": "e50693d2c9a89913c7f1933140770ef7dc912cbe", "best_bid": "0.9", "best_ask": "0.919"}, {"asset_id": "109408722309726159994284194907981745959708334274938135190768342039858793034476", "price": "0.717", "size": "0", "side": "SELL", "hash": "22f55732e7b88701fc8ca27e4b571d179d960613", "best_bid": "0.081", "best_ask": "0.1"}], "timestamp": "1769384510746", "event_type": "price_change"}}
{"_local_timestamp": "2026-01-25T23:41:50.912642+00:00", "data": {"market": "0x91ebc8bf88c5f99dd4550cb75255766f638d1932ede36e8eae78a76df0c15455", "price_changes": [{"asset_id": "63365825049551318024252373648592413954954442733807178648368002993460348485956", "price": "0.419", "size": "0", "side": "BUY", "hash": "1145a9f3e9ab4b6c7c9e3c6a38053d58f31428f1", "best_bid": "0.938", "best_ask": "0.976"}, {"asset_id": "20552877126021963309330960377901114870262231239849696600236708023505406755774", "price": "0.581", "size": "0", "side": "SELL", "hash": "dbf746d421add4631733d03a14c92004c6b26f77", "best_bid": "0.024", "best_ask": "0.062"}], "timestamp": "1769384510746", "event_type": "price_change"}}
{"_local_timestamp": "2026-01-25T23:41:52.800061+00:00", "data": {"market": "0x91ebc8bf88c5f99dd4550cb75255766f638d1932ede36e8eae78a76df0c15455", "price_changes": [{"asset_id": "63365825049551318024252373648592413954954442733807178648368002993460348485956", "price": "0.411", "size": "186.5", "side": "BUY", "hash": "4325be6fdc0a35d9892f183091578dfca0e79b77", "best_bid": "0.938", "best_ask": "0.976"}, {"asset_id": "20552877126021963309330960377901114870262231239849696600236708023505406755774", "price": "0.589", "size": "186.5", "side": "SELL", "hash": "0dfac65967e431c39d7bd52ab302e7ba65f7e053", "best_bid": "0.024", "best_ask": "0.062"}], "timestamp": "1769384511798", "event_type": "price_change"}}
{"_local_timestamp": "2026-01-25T23:41:52.815510+00:00", "data": {"market": "0x29134729ec74a0dbab6ddad9d9a745e4c0b83c59682bdc4b76412c9635d66627", "price_changes": [{"asset_id": "63263918316087383998965771464254486398250019398684443889644959466369157825041", "price": "0.284", "size": "753", "side": "BUY", "hash": "a6424e2b24a6b9bbb6bd94cccfed7e670d266aec", "best_bid": "0.9", "best_ask": "0.919"}, {"asset_id": "109408722309726159994284194907981745959708334274938135190768342039858793034476", "price": "0.716", "size": "753", "side": "SELL", "hash": "1156f3d2fd72ccbd516423367447c704e5271a07", "best_bid": "0.081", "best_ask": "0.1"}], "timestamp": "1769384511798", "event_type": "price_change"}}
{"_local_timestamp": "2026-01-25T23:41:53.214347+00:00", "data": {"market": "0x3936de01f890af302ca75727b772fe6dffe915ce638a08809042a3a81dd346c0", "price_changes": [{"asset_id": "93832008664246723386944798388205104088345581837255215982492503205563374375162", "price": "0.858", "size": "0", "side": "BUY", "hash": "69ddcc122e7ae1258503ece767629917e8be2b8a", "best_bid": "0.971", "best_ask": "0.991"}, {"asset_id": "68682941687946159092109471523402081762244652970943030009984394444937274201240", "price": "0.142", "size": "0", "side": "SELL", "hash": "d325ff5f01c695fdcde52f9cdd5d431c01f395bc", "best_bid": "0.009", "best_ask": "0.029"}], "timestamp": "1769384512903", "event_type": "price_change"}}
{"_local_timestamp": "2026-01-25T23:41:53.214793+00:00", "data": {"market": "0x91ebc8bf88c5f99dd4550cb75255766f638d1932ede36e8eae78a76df0c15455", "price_changes": [{"asset_id": "63365825049551318024252373648592413954954442733807178648368002993460348485956", "price": "0.839", "size": "0", "side": "BUY", "hash": "fcc20fb9f6554c7450566a46fafcf7559dfe14dc", "best_bid": "0.938", "best_ask": "0.976"}, {"asset_id": "20552877126021963309330960377901114870262231239849696600236708023505406755774", "price": "0.161", "size": "0", "side": "SELL", "hash": "6dcef05db6a394b51e4441a20c3f414f70d99b48", "best_bid": "0.024", "best_ask": "0.062"}], "timestamp": "1769384512903", "event_type": "price_change"}}
{"_local_timestamp": "2026-01-25T23:41:55.774417+00:00", "data": {"market": "0x3936de01f890af302ca75727b772fe6dffe915ce638a08809042a3a81dd346c0", "price_changes": [{"asset_id": "93832008664246723386944798388205104088345581837255215982492503205563374375162", "price": "0.859", "size": "0", "side": "BUY", "hash": "1776667e11fa70af158d86db36d58f1edbbfe000", "best_bid": "0.971", "best_ask": "0.991"}, {"asset_id": "68682941687946159092109471523402081762244652970943030009984394444937274201240", "price": "0.141", "size": "0", "side": "SELL", "hash": "4ac00d4ec5da03379528762ade021f5bce17263e", "best_bid": "0.009", "best_ask": "0.029"}], "timestamp": "1769384515704", "event_type": "price_change"}}
{"_local_timestamp": "2026-01-25T23:41:55.774789+00:00", "data": {"market": "0x91ebc8bf88c5f99dd4550cb75255766f638d1932ede36e8eae78a76df0c15455", "price_changes": [{"asset_id": "63365825049551318024252373648592413954954442733807178648368002993460348485956", "price": "0.84", "size": "0", "side": "BUY", "hash": "b6c0e387420b78880d19925f62c6c2373842dd91", "best_bid": "0.938", "best_ask": "0.976"}, {"asset_id": "20552877126021963309330960377901114870262231239849696600236708023505406755774", "price": "0.16", "size": "0", "side": "SELL", "hash": "5d1f44ed4ad359a32f51e4ea080686cb315bac9e", "best_bid": "0.024", "best_ask": "0.062"}], "timestamp": "1769384515704", "event_type": "price_change"}}
{"_local_timestamp": "2026-01-25T23:41:55.798662+00:00", "data": {"market": "0x3936de01f890af302ca75727b772fe6dffe915ce638a08809042a3a81dd346c0", "price_changes": [{"asset_id": "93832008664246723386944798388205104088345581837255215982492503205563374375162", "price": "0.857", "size": "20", "side": "BUY", "hash": "1ce94a4d4dd75c7c8ba3556cfb628aa7ff9fe511", "best_bid": "0.971", "best_ask": "0.991"}, {"asset_id": "68682941687946159092109471523402081762244652970943030009984394444937274201240", "price": "0.143", "size": "20", "side": "SELL", "hash": "1f9a2dbca61875ec25494f2ba0ac959d8a835acf", "best_bid": "0.009", "best_ask": "0.029"}], "timestamp": "1769384515730", "event_type": "price_change"}}
{"_local_timestamp": "2026-01-25T23:41:55.806470+00:00", "data": {"market": "0x91ebc8bf88c5f99dd4550cb75255766f638d1932ede36e8eae78a76df0c15455", "price_changes": [{"asset_id": "63365825049551318024252373648592413954954442733807178648368002993460348485956", "price": "0.831", "size": "20", "side": "BUY", "hash": "ee2b6f7922a96343acbf4fd61712495395bade20", "best_bid": "0.938", "best_ask": "0.976"}, {"asset_id": "20552877126021963309330960377901114870262231239849696600236708023505406755774", "price": "0.169", "size": "20", "side": "SELL", "hash": "a611155cc63ccebb71cbe2280d6d4d685a1faeb3", "best_bid": "0.024", "best_ask": "0.062"}], "timestamp": "1769384515730", "event_type": "price_change"}}
{"_local_timestamp": "2026-01-25T23:42:18.036453+00:00", "data": {"market": "0xfc64306c19c1faab6dee0e3d3bf4b1ec35599692a11eec762a7f54d25bc268f2", "price_changes": [{"asset_id": "87783727256798391598144762644215659792411859939354027829302503274879035245702", "price": "0.026", "size": "0", "side": "SELL", "hash": "615fb87c097cf7575f97c9d8de76f49ff8a2b2cd", "best_bid": "0.009", "best_ask": "0.02"}, {"asset_id": "59580829599216932260845656819640492314194305910396233354387067124740172992769", "price": "0.974", "size": "0", "side": "BUY", "hash": "c867de0d7e824d34d58ba16d5810ba87368419dd", "best_bid": "0.98", "best_ask": "0.991"}], "timestamp": "1769384537945", "event_type": "price_change"}}
{"_local_timestamp": "2026-01-25T23:42:18.082180+00:00", "data": {"market": "0x0afa82ff8cb4dcf8c7a248ccaf438597619d3a6a4e4463adb109e1a1034d6e10", "price_changes": [{"asset_id": "69317727912918260368347049966647382207251169560838202627585212468740589465040", "price": "0.68", "size": "20", "side": "BUY", "hash": "b0c29f641e3ac018437b85f8b50a1233b509c856", "best_bid": "0.74", "best_ask": "0.76"}, {"asset_id": "30455848075861160607924869725570428601171045624621952729814709348346858289488", "price": "0.32", "size": "20", "side": "SELL", "hash": "dc961beb48b852a407001eba4c5f4e03f3eac003", "best_bid": "0.24", "best_ask": "0.26"}], "timestamp": "1769384537993", "event_type": "price_change"}}
{"_local_timestamp": "2026-01-25T23:42:18.082569+00:00", "data": {"market": "0xa087422678cebf674c69d2c86a13b89d153951f067f753e0c2044eb991c0652f", "price_changes": [{"asset_id": "94297885496428433994612881192883747282447345164360333822514231082582602051560", "price": "0.8", "size": "20", "side": "BUY", "hash": "0d23465d2e972a31a22a3902af0e17adfd7a054e", "best_bid": "0.85", "best_ask": "0.89"}, {"asset_id": "12369294935701377203300019700047987848793450009787501327274207549237196997903", "price": "0.2", "size": "20", "side": "SELL", "hash": "9a689ae982b5db782ca90f7efc80e57bfb7889e6", "best_bid": "0.11", "best_ask": "0.15"}], "timestamp": "1769384537993", "event_type": "price_change"}}
{"_local_timestamp": "2026-01-25T23:42:18.082874+00:00", "data": {"market": "0x91ebc8bf88c5f99dd4550cb75255766f638d1932ede36e8eae78a76df0c15455", "price_changes": [{"asset_id": "63365825049551318024252373648592413954954442733807178648368002993460348485956", "price": "0.894", "size": "20", "side": "BUY", "hash": "1474fcb8c7c8bfd50f6ea2edfa37cda9909e972c", "best_bid": "0.938", "best_ask": "0.976"}, {"asset_id": "20552877126021963309330960377901114870262231239849696600236708023505406755774", "price": "0.106", "size": "20", "side": "SELL", "hash": "73cd6faa9afb94d4a23fc1c6a1b9959555cc947e", "best_bid": "0.024", "best_ask": "0.062"}], "timestamp": "1769384537994", "event_type": "price_change"}}
{"_local_timestamp": "2026-01-25T23:42:18.084668+00:00", "data": {"market": "0x938e6a0a011f9534ffd2d86c65dde3aeb7c66ad06cee29ead70b832179c3b6de", "price_changes": [{"asset_id": "24797805539254249433781044462430878338801384554813443486130356027573519184087", "price": "0.48", "size": "33.33", "side": "BUY", "hash": "753b70b2e2a2e942d02958eb959937d156096b29", "best_bid": "0.5", "best_ask": "0.52"}, {"asset_id": "84559926953146780213236573115780107039976526543427713229500373094335659185505", "price": "0.52", "size": "33.33", "side": "SELL", "hash": "ca5f8ec6dc2ecf9103dce33d74e7975c22508fc4", "best_bid": "0.48", "best_ask": "0.5"}], "timestamp": "1769384537995", "event_type": "price_change"}}
{"_local_timestamp": "2026-01-25T23:42:18.087436+00:00", "data": {"market": "0xfdc642275936ee1281df776b1b8a67a35eefbf9095c1266fd178dfa6996ebb4f", "price_changes": [{"asset_id": "55757497654516464627481151189384108294745827872104744655495700337681469992599", "price": "0.912", "size": "20", "side": "BUY", "hash": "5bb18491a507c190fc546385a9389351a6405542", "best_bid": "0.957", "best_ask": "0.994"}, {"asset_id": "75055518491634343238225754172066804322353911200619603473770017059656868007002", "price": "0.088", "size": "20", "side": "SELL", "hash": "08ac27ba992ebd359b07e839d88496adce9ca1ac", "best_bid": "0.006", "best_ask": "0.043"}], "timestamp": "1769384537996", "event_type": "price_change"}}
{"_local_timestamp": "2026-01-25T23:42:18.087740+00:00", "data": {"market": "0xfc64306c19c1faab6dee0e3d3bf4b1ec35599692a11eec762a7f54d25bc268f2", "price_changes": [{"asset_id": "59580829599216932260845656819640492314194305910396233354387067124740172992769", "price": "0.909", "size": "20", "side": "BUY", "hash": "943d7d3d76c7c044a0fe93b29f9e38451cea07a6", "best_bid": "0.98", "best_ask": "0.991"}, {"asset_id": "87783727256798391598144762644215659792411859939354027829302503274879035245702", "price": "0.091", "size": "20", "side": "SELL", "hash": "cb90b356c561fbe00203c234241c7f33cdbe08a1", "best_bid": "0.009", "best_ask": "0.02"}], "timestamp": "1769384537996", "event_type": "price_change"}}
{"_local_timestamp": "2026-01-25T23:42:18.140031+00:00", "data": {"market": "0x29134729ec74a0dbab6ddad9d9a745e4c0b83c59682bdc4b76412c9635d66627", "price_changes": [{"asset_id": "63263918316087383998965771464254486398250019398684443889644959466369157825041", "price": "0.837", "size": "20", "side": "BUY", "hash": "14a98232ed23665cd6ad3487f7b33db5aa0ee364", "best_bid": "0.9", "best_ask": "0.919"}, {"asset_id": "109408722309726159994284194907981745959708334274938135190768342039858793034476", "price": "0.163", "size": "20", "side": "SELL", "hash": "9a77da2e00957deadaa2a69b07d9dd0eb4ea4182", "best_bid": "0.081", "best_ask": "0.1"}], "timestamp": "1769384538007", "event_type": "price_change"}}
{"_local_timestamp": "2026-01-25T23:42:18.911004+00:00", "data": {"market": "0xfc64306c19c1faab6dee0e3d3bf4b1ec35599692a11eec762a7f54d25bc268f2", "price_changes": [{"asset_id": "87783727256798391598144762644215659792411859939354027829302503274879035245702", "price": "0.026", "size": "14.75", "side": "SELL", "hash": "4f0b14198362c119f9c588201e27a108ab575eb7", "best_bid": "0.009", "best_ask": "0.02"}, {"asset_id": "59580829599216932260845656819640492314194305910396233354387067124740172992769", "price": "0.974", "size": "14.75", "side": "BUY", "hash": "d91c9da9a0bb766862154b49c41c3bde46b234b3", "best_bid": "0.98", "best_ask": "0.991"}], "timestamp": "1769384538824", "event_type": "price_change"}}
{"_local_timestamp": "2026-01-25T23:43:20.091795+00:00", "data": {"market": "0xfdc642275936ee1281df776b1b8a67a35eefbf9095c1266fd178dfa6996ebb4f", "price_changes": [{"asset_id": "55757497654516464627481151189384108294745827872104744655495700337681469992599", "price": "0.933", "size": "0", "side": "BUY", "hash": "d6c6bff747d6a4f8e49d942a66a412cb4a529b9c", "best_bid": "0.957", "best_ask": "0.994"}, {"asset_id": "75055518491634343238225754172066804322353911200619603473770017059656868007002", "price": "0.067", "size": "0", "side": "SELL", "hash": "5c288856ae78c3ea016d87d84adce763cb621a40", "best_bid": "0.006", "best_ask": "0.043"}], "timestamp": "1769384599974", "event_type": "price_change"}}
{"_local_timestamp": "2026-01-25T23:43:20.185834+00:00", "data": {"market": "0x1cbe7cbbfb481ed76c054bc4c36c6fb966a2d1671d908d0e89e1f22b0adfa1d6", "price_changes": [{"asset_id": "23234069812587403133665543339348944952052706164431007953765598952013802512997", "price": "0.403", "size": "0", "side": "BUY", "hash": "a818838b2809905c0dda9905b79bd925ce38b21c", "best_bid": "0.992", "best_ask": "0.993"}, {"asset_id": "76756244323959292580621865343466747413597132817678365592077495382609595329059", "price": "0.597", "size": "0", "side": "SELL", "hash": "f40cf1b902d5d5777f38e0b64fdadae12562d73b", "best_bid": "0.007", "best_ask": "0.008"}], "timestamp": "1769384600064", "event_type": "price_change"}}
{"_local_timestamp": "2026-01-25T23:43:20.232026+00:00", "data": {"market": "0x1cbe7cbbfb481ed76c054bc4c36c6fb966a2d1671d908d0e89e1f22b0adfa1d6", "price_changes": [{"asset_id": "23234069812587403133665543339348944952052706164431007953765598952013802512997", "price": "0.403", "size": "10", "side": "BUY", "hash": "73b023a2121a2480bcdaf4b14de749184789b49b", "best_bid": "0.992", "best_ask": "0.993"}, {"asset_id": "76756244323959292580621865343466747413597132817678365592077495382609595329059", "price": "0.597", "size": "10", "side": "SELL", "hash": "71353a94015a1a1d4594e799d97b03a4a09a7a14", "best_bid": "0.007", "best_ask": "0.008"}], "timestamp": "1769384600111", "event_type": "price_change"}}
{"_local_timestamp": "2026-01-25T23:43:20.271280+00:00", "data": {"market": "0xfc64306c19c1faab6dee0e3d3bf4b1ec35599692a11eec762a7f54d25bc268f2", "price_changes": [{"asset_id": "59580829599216932260845656819640492314194305910396233354387067124740172992769", "price": "0.851", "size": "0", "side": "BUY", "hash": "7b309b819c69078f02141ef79028392d344d6987", "best_bid": "0.98", "best_ask": "0.991"}, {"asset_id": "87783727256798391598144762644215659792411859939354027829302503274879035245702", "price": "0.149", "size": "0", "side": "SELL", "hash": "1be9c122d43db3b5b27684a6bbf7d7b006ee0703", "best_bid": "0.009", "best_ask": "0.02"}], "timestamp": "1769384600150", "event_type": "price_change"}}
{"_local_timestamp": "2026-01-25T23:43:20.343970+00:00", "data": {"market": "0xfc64306c19c1faab6dee0e3d3bf4b1ec35599692a11eec762a7f54d25bc268f2", "price_changes": [{"asset_id": "59580829599216932260845656819640492314194305910396233354387067124740172992769", "price": "0.779", "size": "30", "side": "BUY", "hash": "853b42fd686dbadaa382a7ded5340dd4752226f4", "best_bid": "0.98", "best_ask": "0.991"}, {"asset_id": "87783727256798391598144762644215659792411859939354027829302503274879035245702", "price": "0.221", "size": "30", "side": "SELL", "hash": "3d98a54024c1c02fafbacac1bc8d8ab67ce73376", "best_bid": "0.009", "best_ask": "0.02"}], "timestamp": "1769384600222", "event_type": "price_change"}}
{"_local_timestamp": "2026-01-25T23:43:20.347800+00:00", "data": {"market": "0x91ebc8bf88c5f99dd4550cb75255766f638d1932ede36e8eae78a76df0c15455", "price_changes": [{"asset_id": "63365825049551318024252373648592413954954442733807178648368002993460348485956", "price": "0.809", "size": "0", "side": "BUY", "hash": "8dbb95644a04a2631f7db4b2d5ca4f8a04a28c74", "best_bid": "0.938", "best_ask": "0.976"}, {"asset_id": "20552877126021963309330960377901114870262231239849696600236708023505406755774", "price": "0.191", "size": "0", "side": "SELL", "hash": "6fed21193b86e68de36d809bf5765b6b805deba3", "best_bid": "0.024", "best_ask": "0.062"}], "timestamp": "1769384600227", "event_type": "price_change"}}
{"_local_timestamp": "2026-01-25T23:43:20.503497+00:00", "data": {"market": "0x91ebc8bf88c5f99dd4550cb75255766f638d1932ede36e8eae78a76df0c15455", "price_changes": [{"asset_id": "63365825049551318024252373648592413954954442733807178648368002993460348485956", "price": "0.809", "size": "15", "side": "BUY", "hash": "a06e5284f8986f633f627c197a66dc622432bc18", "best_bid": "0.938", "best_ask": "0.976"}, {"asset_id": "20552877126021963309330960377901114870262231239849696600236708023505406755774", "price": "0.191", "size": "15", "side": "SELL", "hash": "81b0d75b13290a0a8d7e9c23f93a3edd3a339ad9", "best_bid": "0.024", "best_ask": "0.062"}], "timestamp": "1769384600384", "event_type": "price_change"}}
{"_local_timestamp": "2026-01-25T23:43:20.503966+00:00", "data": {"market": "0x91ebc8bf88c5f99dd4550cb75255766f638d1932ede36e8eae78a76df0c15455", "price_changes": [{"asset_id": "63365825049551318024252373648592413954954442733807178648368002993460348485956", "price": "0.832", "size": "10", "side": "BUY", "hash": "1fee9d7a031a37253586afcb7dc0b828f933c953", "best_bid": "0.938", "best_ask": "0.976"}, {"asset_id": "20552877126021963309330960377901114870262231239849696600236708023505406755774", "price": "0.168", "size": "10", "side": "SELL", "hash": "8420627fd10f111d3c8287e7fa9d3960f4508288", "best_bid": "0.024", "best_ask": "0.062"}], "timestamp": "1769384600386", "event_type": "price_change"}}
{"_local_timestamp": "2026-01-25T23:43:20.544047+00:00", "data": {"market": "0x3936de01f890af302ca75727b772fe6dffe915ce638a08809042a3a81dd346c0", "price_changes": [{"asset_id": "93832008664246723386944798388205104088345581837255215982492503205563374375162", "price": "0.417", "size": "0", "side": "BUY", "hash": "096aa490b98511b171f5de4d9afd38ea8dc6194a", "best_bid": "0.971", "best_ask": "0.991"}, {"asset_id": "68682941687946159092109471523402081762244652970943030009984394444937274201240", "price": "0.583", "size": "0", "side": "SELL", "hash": "e5df7fe78b1b8dc25b97bca4eab84bcce65b47c6", "best_bid": "0.009", "best_ask": "0.029"}], "timestamp": "1769384600408", "event_type": "price_change"}}
{"_local_timestamp": "2026-01-25T23:43:20.591329+00:00", "data": {"market": "0xfdc642275936ee1281df776b1b8a67a35eefbf9095c1266fd178dfa6996ebb4f", "price_changes": [{"asset_id": "55757497654516464627481151189384108294745827872104744655495700337681469992599", "price": "0.935", "size": "100", "side": "BUY", "hash": "bda28be2d57e1531b9c82279aaebb06e55ab8f9d", "best_bid": "0.957", "best_ask": "0.994"}, {"asset_id": "75055518491634343238225754172066804322353911200619603473770017059656868007002", "price": "0.065", "size": "100", "side": "SELL", "hash": "fe1967d84a10f141ecd56fe6a9ca29486cd4edaa", "best_bid": "0.006", "best_ask": "0.043"}], "timestamp": "1769384600465", "event_type": "price_change"}}
{"_local_timestamp": "2026-01-25T23:43:20.663191+00:00", "data": {"market": "0x3936de01f890af302ca75727b772fe6dffe915ce638a08809042a3a81dd346c0", "price_changes": [{"asset_id": "93832008664246723386944798388205104088345581837255215982492503205563374375162", "price": "0.416", "size": "15", "side": "BUY", "hash": "05ccd928389d8eda0bbfc9061937808ac6829660", "best_bid": "0.971", "best_ask": "0.991"}, {"asset_id": "68682941687946159092109471523402081762244652970943030009984394444937274201240", "price": "0.584", "size": "15", "side": "SELL", "hash": "3846684c0162ad50265107d6767105f362d32e03", "best_bid": "0.009", "best_ask": "0.029"}], "timestamp": "1769384600545", "event_type": "price_change"}}
{"_local_timestamp": "2026-01-25T23:43:20.667371+00:00", "data": {"market": "0x3936de01f890af302ca75727b772fe6dffe915ce638a08809042a3a81dd346c0", "price_changes": [{"asset_id": "93832008664246723386944798388205104088345581837255215982492503205563374375162", "price": "0.858", "size": "10", "side": "BUY", "hash": "6e5cbb88c4f425b901fc996cbe9a5ed5994947d5", "best_bid": "0.971", "best_ask": "0.991"}, {"asset_id": "68682941687946159092109471523402081762244652970943030009984394444937274201240", "price": "0.142", "size": "10", "side": "SELL", "hash": "fe731de13d93df07b580f84370b4021fca38db44", "best_bid": "0.009", "best_ask": "0.029"}], "timestamp": "1769384600546", "event_type": "price_change"}}
{"_local_timestamp": "2026-01-25T23:43:21.428226+00:00", "data": {"market": "0xfc64306c19c1faab6dee0e3d3bf4b1ec35599692a11eec762a7f54d25bc268f2", "price_changes": [{"asset_id": "59580829599216932260845656819640492314194305910396233354387067124740172992769", "price": "0.852", "size": "0", "side": "BUY", "hash": "966bd9ed888f709aeb2f94ca71ebcf608c96495b", "best_bid": "0.98", "best_ask": "0.991"}, {"asset_id": "87783727256798391598144762644215659792411859939354027829302503274879035245702", "price": "0.148", "size": "0", "side": "SELL", "hash": "85bcb5705bbb7a83a3c9af5816ca70489b13fd21", "best_bid": "0.009", "best_ask": "0.02"}], "timestamp": "1769384601277", "event_type": "price_change"}}
{"_local_timestamp": "2026-01-25T23:43:21.436521+00:00", "data": {"market": "0xfc64306c19c1faab6dee0e3d3bf4b1ec35599692a11eec762a7f54d25bc268f2", "price_changes": [{"asset_id": "59580829599216932260845656819640492314194305910396233354387067124740172992769", "price": "0.851", "size": "20", "side": "BUY", "hash": "d184183171324486cc9f5239847c9680ffe411d0", "best_bid": "0.98", "best_ask": "0.991"}, {"asset_id": "87783727256798391598144762644215659792411859939354027829302503274879035245702", "price": "0.149", "size": "20", "side": "SELL", "hash": "c0b1a62c3e7e0f2792b043137846745536c77d57", "best_bid": "0.009", "best_ask": "0.02"}], "timestamp": "1769384601303", "event_type": "price_change"}}
{"_local_timestamp": "2026-01-25T23:43:22.263199+00:00", "data": {"market": "0x3936de01f890af302ca75727b772fe6dffe915ce638a08809042a3a81dd346c0", "price_changes": [{"asset_id": "93832008664246723386944798388205104088345581837255215982492503205563374375162", "price": "0.857", "size": "0", "side": "BUY", "hash": "af535ed43817359c44cc55f0f2abf97f2b25244d", "best_bid": "0.971", "best_ask": "0.991"}, {"asset_id": "68682941687946159092109471523402081762244652970943030009984394444937274201240", "price": "0.143", "size": "0", "side": "SELL", "hash": "4184eef2e221f0ce427b680f98b7e72ad788597f", "best_bid": "0.009", "best_ask": "0.029"}], "timestamp": "1769384602127", "event_type": "price_change"}}
{"_local_timestamp": "2026-01-25T23:43:22.263811+00:00", "data": {"market": "0x91ebc8bf88c5f99dd4550cb75255766f638d1932ede36e8eae78a76df0c15455", "price_changes": [{"asset_id": "63365825049551318024252373648592413954954442733807178648368002993460348485956", "price": "0.831", "size": "0", "side": "BUY", "hash": "1dd5c0aced8e56b72a8568180ffb83e6303a8e5a", "best_bid": "0.938", "best_ask": "0.976"}, {"asset_id": "20552877126021963309330960377901114870262231239849696600236708023505406755774", "price": "0.169", "size": "0", "side": "SELL", "hash": "7da176b11b29bd6bf9cfa9af0b8c1c7b28f8fddd", "best_bid": "0.024", "best_ask": "0.062"}], "timestamp": "1769384602127", "event_type": "price_change"}}
{"_local_timestamp": "2026-01-25T23:43:22.298333+00:00", "data": {"market": "0x91ebc8bf88c5f99dd4550cb75255766f638d1932ede36e8eae78a76df0c15455", "price_changes": [{"asset_id": "63365825049551318024252373648592413954954442733807178648368002993460348485956", "price": "0.833", "size": "20", "side": "BUY", "hash": "55f69bb889bedc9282d8cbca4f9f2f131eb25d15", "best_bid": "0.938", "best_ask": "0.976"}, {"asset_id": "20552877126021963309330960377901114870262231239849696600236708023505406755774", "price": "0.167", "size": "20", "side": "SELL", "hash": "eb46b5474279f44fa5666c8815ec631d516b184d", "best_bid": "0.024", "best_ask": "0.062"}], "timestamp": "1769384602155", "event_type": "price_change"}}
{"_local_timestamp": "2026-01-25T23:43:22.298697+00:00", "data": {"market": "0x3936de01f890af302ca75727b772fe6dffe915ce638a08809042a3a81dd346c0", "price_changes": [{"asset_id": "93832008664246723386944798388205104088345581837255215982492503205563374375162", "price": "0.859", "size": "20", "side": "BUY", "hash": "0ef054a2faeb8291479e38adc277d398892e170a", "best_bid": "0.971", "best_ask": "0.991"}, {"asset_id": "68682941687946159092109471523402081762244652970943030009984394444937274201240", "price": "0.141", "size": "20", "side": "SELL", "hash": "04464693fe38ed3faf1c87958bbbe7b0ee8fc011", "best_bid": "0.009", "best_ask": "0.029"}], "timestamp": "1769384602155", "event_type": "price_change"}}
{"_local_timestamp": "2026-01-25T23:43:55.565299+00:00", "data": {"market": "0xa087422678cebf674c69d2c86a13b89d153951f067f753e0c2044eb991c0652f", "price_changes": [{"asset_id": "94297885496428433994612881192883747282447345164360333822514231082582602051560", "price": "0.4", "size": "0", "side": "BUY", "hash": "6cc6ad8591cd1a406914919aab2f73659421f607", "best_bid": "0.85", "best_ask": "0.89"}, {"asset_id": "12369294935701377203300019700047987848793450009787501327274207549237196997903", "price": "0.6", "size": "0", "side": "SELL", "hash": "a7ab25aa29e8d0ad5ef9794b8f988557c52a102b", "best_bid": "0.11", "best_ask": "0.15"}], "timestamp": "1769384635419", "event_type": "price_change"}}
{"_local_timestamp": "2026-01-25T23:43:55.581851+00:00", "data": {"market": "0x938e6a0a011f9534ffd2d86c65dde3aeb7c66ad06cee29ead70b832179c3b6de", "price_changes": [{"asset_id": "24797805539254249433781044462430878338801384554813443486130356027573519184087", "price": "0.48", "size": "13.33", "side": "BUY", "hash": "53cb0e578a03b083ed8912487a64819a3cd2e470", "best_bid": "0.5", "best_ask": "0.52"}, {"asset_id": "84559926953146780213236573115780107039976526543427713229500373094335659185505", "price": "0.52", "size": "13.33", "side": "SELL", "hash": "a169d6af8f14be2367f7e7b72374f8d53151802e", "best_bid": "0.48", "best_ask": "0.5"}], "timestamp": "1769384635441", "event_type": "price_change"}}
{"_local_timestamp": "2026-01-25T23:43:55.582170+00:00", "data": {"market": "0xfdc642275936ee1281df776b1b8a67a35eefbf9095c1266fd178dfa6996ebb4f", "price_changes": [{"asset_id": "55757497654516464627481151189384108294745827872104744655495700337681469992599", "price": "0.912", "size": "0", "side": "BUY", "hash": "4db588e8303d1bc3c92c4f2348f2416258db77f9", "best_bid": "0.957", "best_ask": "0.994"}, {"asset_id": "75055518491634343238225754172066804322353911200619603473770017059656868007002", "price": "0.088", "size": "0", "side": "SELL", "hash": "65033bdb10b750cd600a7848fe75086bd72d62bc", "best_bid": "0.006", "best_ask": "0.043"}], "timestamp": "1769384635441", "event_type": "price_change"}}
{"_local_timestamp": "2026-01-25T23:43:55.582424+00:00", "data": {"market": "0x0afa82ff8cb4dcf8c7a248ccaf438597619d3a6a4e4463adb109e1a1034d6e10", "price_changes": [{"asset_id": "69317727912918260368347049966647382207251169560838202627585212468740589465040", "price": "0.68", "size": "0", "side": "BUY", "hash": "1d79e5368b578584bdb928c6d2ae4b952723b45e", "best_bid": "0.74", "best_ask": "0.76"}, {"asset_id": "30455848075861160607924869725570428601171045624621952729814709348346858289488", "price": "0.32", "size": "0", "side": "SELL", "hash": "b49f1855a20994c3e08832d2286b551c52725448", "best_bid": "0.24", "best_ask": "0.26"}], "timestamp": "1769384635442", "event_type": "price_change"}}
{"_local_timestamp": "2026-01-25T23:43:55.582691+00:00", "data": {"market": "0x29134729ec74a0dbab6ddad9d9a745e4c0b83c59682bdc4b76412c9635d66627", "price_changes": [{"asset_id": "63263918316087383998965771464254486398250019398684443889644959466369157825041", "price": "0.837", "size": "0", "side": "BUY", "hash": "431ed5bc87d92624d8176dbe8bcb3a8deaca3020", "best_bid": "0.9", "best_ask": "0.919"}, {"asset_id": "109408722309726159994284194907981745959708334274938135190768342039858793034476", "price": "0.163", "size": "0", "side": "SELL", "hash": "aa45c28ea4e8fabf350f41b22cc4d31a63ff4407", "best_bid": "0.081", "best_ask": "0.1"}], "timestamp": "1769384635442", "event_type": "price_change"}}
{"_local_timestamp": "2026-01-25T23:43:55.588227+00:00", "data": {"market": "0xa087422678cebf674c69d2c86a13b89d153951f067f753e0c2044eb991c0652f", "price_changes": [{"asset_id": "94297885496428433994612881192883747282447345164360333822514231082582602051560", "price": "0.8", "size": "0", "side": "BUY", "hash": "6cfd1b191ecf96f8d0a7550639b94cc3c259055f", "best_bid": "0.85", "best_ask": "0.89"}, {"asset_id": "12369294935701377203300019700047987848793450009787501327274207549237196997903", "price": "0.2", "size": "0", "side": "SELL", "hash": "59c2b0b9aedf46acd544d6b89dac332aa1dfc6bb", "best_bid": "0.11", "best_ask": "0.15"}], "timestamp": "1769384635445", "event_type": "price_change"}}
{"_local_timestamp": "2026-01-25T23:43:55.588610+00:00", "data": {"market": "0x91ebc8bf88c5f99dd4550cb75255766f638d1932ede36e8eae78a76df0c15455", "price_changes": [{"asset_id": "63365825049551318024252373648592413954954442733807178648368002993460348485956", "price": "0.894", "size": "0", "side": "BUY", "hash": "65769c708783fc6c4005a55b4a4e42794d22ccba", "best_bid": "0.938", "best_ask": "0.976"}, {"asset_id": "20552877126021963309330960377901114870262231239849696600236708023505406755774", "price": "0.106", "size": "0", "side": "SELL", "hash": "8f7bd0147b8a7ecc1e70dfba153b1431c0556d45", "best_bid": "0.024", "best_ask": "0.062"}], "timestamp": "1769384635445", "event_type": "price_change"}}
{"_local_timestamp": "2026-01-25T23:43:55.588838+00:00", "data": {"market": "0xfc64306c19c1faab6dee0e3d3bf4b1ec35599692a11eec762a7f54d25bc268f2", "price_changes": [{"asset_id": "59580829599216932260845656819640492314194305910396233354387067124740172992769", "price": "0.909", "size": "0", "side": "BUY", "hash": "93b47628213ffa586eca56f100dcea057e9f3876", "best_bid": "0.98", "best_ask": "0.991"}, {"asset_id": "87783727256798391598144762644215659792411859939354027829302503274879035245702", "price": "0.091", "size": "0", "side": "SELL", "hash": "51271737188058c1debc2dab101bc71f26457ae0", "best_bid": "0.009", "best_ask": "0.02"}], "timestamp": "1769384635445", "event_type": "price_change"}}
{"_local_timestamp": "2026-01-25T23:43:55.612128+00:00", "data": {"market": "0xa087422678cebf674c69d2c86a13b89d153951f067f753e0c2044eb991c0652f", "price_changes": [{"asset_id": "94297885496428433994612881192883747282447345164360333822514231082582602051560", "price": "0.4", "size": "5", "side": "BUY", "hash": "edf010bb51971670fe28a6e3429e08d64789b777", "best_bid": "0.85", "best_ask": "0.89"}, {"asset_id": "12369294935701377203300019700047987848793450009787501327274207549237196997903", "price": "0.6", "size": "5", "side": "SELL", "hash": "27e857119af29c6b2b00b5a21b182252935cfb1d", "best_bid": "0.11", "best_ask": "0.15"}], "timestamp": "1769384635475", "event_type": "price_change"}}
{"_local_timestamp": "2026-01-25T23:43:55.668236+00:00", "data": {"market": "0xfdc642275936ee1281df776b1b8a67a35eefbf9095c1266fd178dfa6996ebb4f", "price_changes": [{"asset_id": "55757497654516464627481151189384108294745827872104744655495700337681469992599", "price": "0.535", "size": "0", "side": "BUY", "hash": "e242f0b5ff74ebad49486f1a33e2c0eecb8c7c18", "best_bid": "0.957", "best_ask": "0.994"}, {"asset_id": "75055518491634343238225754172066804322353911200619603473770017059656868007002", "price": "0.465", "size": "0", "side": "SELL", "hash": "e13fb7c26592c3a1c5ae235db703b1ab81d410ba", "best_bid": "0.006", "best_ask": "0.043"}], "timestamp": "1769384635530", "event_type": "price_change"}}
{"_local_timestamp": "2026-01-25T23:43:55.794189+00:00", "data": {"market": "0xfdc642275936ee1281df776b1b8a67a35eefbf9095c1266fd178dfa6996ebb4f", "price_changes": [{"asset_id": "55757497654516464627481151189384108294745827872104744655495700337681469992599", "price": "0.542", "size": "30", "side": "BUY", "hash": "c8262d454dad032ebd14fed61f8d0f7bf91b454a", "best_bid": "0.957", "best_ask": "0.994"}, {"asset_id": "75055518491634343238225754172066804322353911200619603473770017059656868007002", "price": "0.458", "size": "30", "side": "SELL", "hash": "9d85c93622c7c3a856531febc69d511e73b38bff", "best_bid": "0.006", "best_ask": "0.043"}], "timestamp": "1769384635651", "event_type": "price_change"}}
{"_local_timestamp": "2026-01-25T23:43:56.540454+00:00", "data": {"market": "0xfdc642275936ee1281df776b1b8a67a35eefbf9095c1266fd178dfa6996ebb4f", "price_changes": [{"asset_id": "55757497654516464627481151189384108294745827872104744655495700337681469992599", "price": "0.541", "size": "0", "side": "BUY", "hash": "106384162b00c6ea4aae038b19452d0a37ff9baa", "best_bid": "0.957", "best_ask": "0.994"}, {"asset_id": "75055518491634343238225754172066804322353911200619603473770017059656868007002", "price": "0.459", "size": "0", "side": "SELL", "hash": "75ca5d5a32653ac4531e0db2aec8737330462751", "best_bid": "0.006", "best_ask": "0.043"}], "timestamp": "1769384636401", "event_type": "price_change"}}
{"_local_timestamp": "2026-01-25T23:43:56.575690+00:00", "data": {"market": "0xfdc642275936ee1281df776b1b8a67a35eefbf9095c1266fd178dfa6996ebb4f", "price_changes": [{"asset_id": "55757497654516464627481151189384108294745827872104744655495700337681469992599", "price": "0.543", "size": "20", "side": "BUY", "hash": "f1484144e09ea4fc9a6c95f59cbe0aedfb2df7ed", "best_bid": "0.957", "best_ask": "0.994"}, {"asset_id": "75055518491634343238225754172066804322353911200619603473770017059656868007002", "price": "0.457", "size": "20", "side": "SELL", "hash": "3ad60aa95c8c8466b382c055d949e575d0544e99", "best_bid": "0.006", "best_ask": "0.043"}], "timestamp": "1769384636433", "event_type": "price_change"}}
{"_local_timestamp": "2026-01-25T23:44:18.018417+00:00", "data": {"market": "0xfc64306c19c1faab6dee0e3d3bf4b1ec35599692a11eec762a7f54d25bc268f2", "price_changes": [{"asset_id": "87783727256798391598144762644215659792411859939354027829302503274879035245702", "price": "0.026", "size": "0", "side": "SELL", "hash": "6a3d35183f050662910ccca5aa2f47f41cf79490", "best_bid": "0.009", "best_ask": "0.02"}, {"asset_id": "59580829599216932260845656819640492314194305910396233354387067124740172992769", "price": "0.974", "size": "0", "side": "BUY", "hash": "f79209797e43ea4edfc94c79abbe6f92a3902210", "best_bid": "0.98", "best_ask": "0.991"}], "timestamp": "1769384657756", "event_type": "price_change"}}
{"_local_timestamp": "2026-01-25T23:44:18.203682+00:00", "data": {"market": "0xfdc642275936ee1281df776b1b8a67a35eefbf9095c1266fd178dfa6996ebb4f", "price_changes": [{"asset_id": "55757497654516464627481151189384108294745827872104744655495700337681469992599", "price": "0.538", "size": "0", "side": "BUY", "hash": "ab41123a3f4e1c0e88398f51dce99edf4e4365c6", "best_bid": "0.957", "best_ask": "0.994"}, {"asset_id": "75055518491634343238225754172066804322353911200619603473770017059656868007002", "price": "0.462", "size": "0", "side": "SELL", "hash": "fa25794d2aa5b4b7343ef0b2fb5ae8b137dc7091", "best_bid": "0.006", "best_ask": "0.043"}], "timestamp": "1769384657944", "event_type": "price_change"}}
{"_local_timestamp": "2026-01-25T23:44:18.203991+00:00", "data": {"market": "0x021e7689a90ac39c268a39ddff6269fd0f41ed84ea6833f6e5b7d900569e6d8b", "price_changes": [{"asset_id": "21609653795728383864795868045140971967534750053984809993030488713671979919753", "price": "0.529", "size": "0", "side": "BUY", "hash": "643d030a560d4ed160b0a5e83d05b89fa7f8272f", "best_bid": "0.992", "best_ask": "0.994"}, {"asset_id": "25265857280574792887110878653665871891927967464924536706348687031929049209739", "price": "0.471", "size": "0", "side": "SELL", "hash": "eba32c6f0787d6072b1313c2d7fc8965fa5e3f4f", "best_bid": "0.006", "best_ask": "0.008"}], "timestamp": "1769384657944", "event_type": "price_change"}}
{"_local_timestamp": "2026-01-25T23:44:18.326267+00:00", "data": {"market": "0x021e7689a90ac39c268a39ddff6269fd0f41ed84ea6833f6e5b7d900569e6d8b", "price_changes": [{"asset_id": "21609653795728383864795868045140971967534750053984809993030488713671979919753", "price": "0.535", "size": "40", "side": "BUY", "hash": "2e9da876507e49f5ea3f106cb9ee83c0fa643f63", "best_bid": "0.992", "best_ask": "0.994"}, {"asset_id": "25265857280574792887110878653665871891927967464924536706348687031929049209739", "price": "0.465", "size": "40", "side": "SELL", "hash": "afbdcd448ebb936f3966b21613b17f85ccd77993", "best_bid": "0.006", "best_ask": "0.008"}], "timestamp": "1769384658081", "event_type": "price_change"}}
{"_local_timestamp": "2026-01-25T23:44:18.326571+00:00", "data": {"market": "0xfdc642275936ee1281df776b1b8a67a35eefbf9095c1266fd178dfa6996ebb4f", "price_changes": [{"asset_id": "55757497654516464627481151189384108294745827872104744655495700337681469992599", "price": "0.544", "size": "40", "side": "BUY", "hash": "3f0fe9bfa6081b2c4fd36bae7607468dd425eb74", "best_bid": "0.957", "best_ask": "0.994"}, {"asset_id": "75055518491634343238225754172066804322353911200619603473770017059656868007002", "price": "0.456", "size": "40", "side": "SELL", "hash": "3f5c47c57ab05d4dae44aa294a0c4cfdc19929f4", "best_bid": "0.006", "best_ask": "0.043"}], "timestamp": "1769384658081", "event_type": "price_change"}}
{"_local_timestamp": "2026-01-25T23:44:19.456258+00:00", "data": {"market": "0xfc64306c19c1faab6dee0e3d3bf4b1ec35599692a11eec762a7f54d25bc268f2", "price_changes": [{"asset_id": "87783727256798391598144762644215659792411859939354027829302503274879035245702", "price": "0.026", "size": "14.75", "side": "SELL", "hash": "59b7876c1cb8c8afca6dd1d07fb4ddbe86f5a882", "best_bid": "0.009", "best_ask": "0.02"}, {"asset_id": "59580829599216932260845656819640492314194305910396233354387067124740172992769", "price": "0.974", "size": "14.75", "side": "BUY", "hash": "b77bd6249fb18988351bcc0042c89233f30b7e12", "best_bid": "0.98", "best_ask": "0.991"}], "timestamp": "1769384659147", "event_type": "price_change"}}
{"_local_timestamp": "2026-01-25T23:44:20.571213+00:00", "data": {"market": "0xfdc642275936ee1281df776b1b8a67a35eefbf9095c1266fd178dfa6996ebb4f", "price_changes": [{"asset_id": "55757497654516464627481151189384108294745827872104744655495700337681469992599", "price": "0.543", "size": "0", "side": "BUY", "hash": "42fc2aef30d87214f3fd20b8a6d49860f1b3b027", "best_bid": "0.957", "best_ask": "0.994"}, {"asset_id": "75055518491634343238225754172066804322353911200619603473770017059656868007002", "price": "0.457", "size": "0", "side": "SELL", "hash": "0553cef467dd86539b51c609a1d42c6f8c7c513f", "best_bid": "0.006", "best_ask": "0.043"}], "timestamp": "1769384660305", "event_type": "price_change"}}
{"_local_timestamp": "2026-01-25T23:44:20.574949+00:00", "data": {"market": "0x021e7689a90ac39c268a39ddff6269fd0f41ed84ea6833f6e5b7d900569e6d8b", "price_changes": [{"asset_id": "21609653795728383864795868045140971967534750053984809993030488713671979919753", "price": "0.534", "size": "0", "side": "BUY", "hash": "82ab7df4a0bddbb6dcbd5500e8fbd5bc4b1e1278", "best_bid": "0.992", "best_ask": "0.994"}, {"asset_id": "25265857280574792887110878653665871891927967464924536706348687031929049209739", "price": "0.466", "size": "0", "side": "SELL", "hash": "51b72a383f50d4f7025a4cc0f7840a2693a92278", "best_bid": "0.006", "best_ask": "0.008"}], "timestamp": "1769384660305", "event_type": "price_change"}}
{"_local_timestamp": "2026-01-25T23:44:20.600822+00:00", "data": {"market": "0xfdc642275936ee1281df776b1b8a67a35eefbf9095c1266fd178dfa6996ebb4f", "price_changes": [{"asset_id": "55757497654516464627481151189384108294745827872104744655495700337681469992599", "price": "0.545", "size": "20", "side": "BUY", "hash": "25ff44dafd52491768e5d0449a6f5b82340514bd", "best_bid": "0.957", "best_ask": "0.994"}, {"asset_id": "75055518491634343238225754172066804322353911200619603473770017059656868007002", "price": "0.455", "size": "20", "side": "SELL", "hash": "887cb819b59ca071aebdc98c0f0975eb1fe6eb7e", "best_bid": "0.006", "best_ask": "0.043"}], "timestamp": "1769384660336", "event_type": "price_change"}}
{"_local_timestamp": "2026-01-25T23:44:20.603361+00:00", "data": {"market": "0x021e7689a90ac39c268a39ddff6269fd0f41ed84ea6833f6e5b7d900569e6d8b", "price_changes": [{"asset_id": "21609653795728383864795868045140971967534750053984809993030488713671979919753", "price": "0.536", "size": "20", "side": "BUY", "hash": "28cc119c9c4c3dd270ea02ae3c4110a0213315eb", "best_bid": "0.992", "best_ask": "0.994"}, {"asset_id": "25265857280574792887110878653665871891927967464924536706348687031929049209739", "price": "0.464", "size": "20", "side": "SELL", "hash": "42368c353e33060ebfc00304e9d55a58d290f493", "best_bid": "0.006", "best_ask": "0.008"}], "timestamp": "1769384660336", "event_type": "price_change"}}
{"_local_timestamp": "2026-01-25T23:44:30.055318+00:00", "data": {"market": "0x938e6a0a011f9534ffd2d86c65dde3aeb7c66ad06cee29ead70b832179c3b6de", "price_changes": [{"asset_id": "24797805539254249433781044462430878338801384554813443486130356027573519184087", "price": "0.22", "size": "0", "side": "BUY", "hash": "3f8a15af13b6a58b330d82c49642a3ff65003a85", "best_bid": "0.5", "best_ask": "0.52"}, {"asset_id": "84559926953146780213236573115780107039976526543427713229500373094335659185505", "price": "0.78", "size": "0", "side": "SELL", "hash": "08c3827a53516761ba975545b90a69be844aba2e", "best_bid": "0.48", "best_ask": "0.5"}], "timestamp": "1769384669778", "event_type": "price_change"}}
{"_local_timestamp": "2026-01-25T23:44:30.110167+00:00", "data": {"market": "0x938e6a0a011f9534ffd2d86c65dde3aeb7c66ad06cee29ead70b832179c3b6de", "price_changes": [{"asset_id": "24797805539254249433781044462430878338801384554813443486130356027573519184087", "price": "0.22", "size": "9", "side": "BUY", "hash": "1ced134207e58669d5d0b4584f7e2cc7bc8db8bf", "best_bid": "0.5", "best_ask": "0.52"}, {"asset_id": "84559926953146780213236573115780107039976526543427713229500373094335659185505", "price": "0.78", "size": "9", "side": "SELL", "hash": "bd5e98d1b8b268858be81a2e5135baa1ecde03cf", "best_bid": "0.48", "best_ask": "0.5"}], "timestamp": "1769384669837", "event_type": "price_change"}}
{"_local_timestamp": "2026-01-25T23:44:30.253891+00:00", "data": {"market": "0x1cbe7cbbfb481ed76c054bc4c36c6fb966a2d1671d908d0e89e1f22b0adfa1d6", "price_changes": [{"asset_id": "23234069812587403133665543339348944952052706164431007953765598952013802512997", "price": "0.866", "size": "0", "side": "BUY", "hash": "42462e0851a48b0d5ef4b25583b6a910aa17f812", "best_bid": "0.992", "best_ask": "0.993"}, {"asset_id": "76756244323959292580621865343466747413597132817678365592077495382609595329059", "price": "0.134", "size": "0", "side": "SELL", "hash": "3a8efc92ddb01018744ca35ad1b99f8bfe1e202c", "best_bid": "0.007", "best_ask": "0.008"}], "timestamp": "1769384669987", "event_type": "price_change"}}
{"_local_timestamp": "2026-01-25T23:44:30.254265+00:00", "data": {"market": "0x1cbe7cbbfb481ed76c054bc4c36c6fb966a2d1671d908d0e89e1f22b0adfa1d6", "price_changes": [{"asset_id": "23234069812587403133665543339348944952052706164431007953765598952013802512997", "price": "0.685", "size": "0", "side": "BUY", "hash": "42462e0851a48b0d5ef4b25583b6a910aa17f812", "best_bid": "0.992", "best_ask": "0.993"}, {"asset_id": "76756244323959292580621865343466747413597132817678365592077495382609595329059", "price": "0.315", "size": "0", "side": "SELL", "hash": "3a8efc92ddb01018744ca35ad1b99f8bfe1e202c", "best_bid": "0.007", "best_ask": "0.008"}], "timestamp": "1769384669987", "event_type": "price_change"}}
{"_local_timestamp": "2026-01-25T23:44:30.281807+00:00", "data": {"market": "0x3936de01f890af302ca75727b772fe6dffe915ce638a08809042a3a81dd346c0", "price_changes": [{"asset_id": "93832008664246723386944798388205104088345581837255215982492503205563374375162", "price": "0.415", "size": "0", "side": "BUY", "hash": "e769c4b065c36282bee316cfcc2959a88a233917", "best_bid": "0.971", "best_ask": "0.991"}, {"asset_id": "68682941687946159092109471523402081762244652970943030009984394444937274201240", "price": "0.585", "size": "0", "side": "SELL", "hash": "44b3b0a7deb1310071da7f10f1bf6417b88a5149", "best_bid": "0.009", "best_ask": "0.029"}], "timestamp": "1769384670017", "event_type": "price_change"}}
{"_local_timestamp": "2026-01-25T23:44:30.340250+00:00", "data": {"market": "0x1cbe7cbbfb481ed76c054bc4c36c6fb966a2d1671d908d0e89e1f22b0adfa1d6", "price_changes": [{"asset_id": "23234069812587403133665543339348944952052706164431007953765598952013802512997", "price": "0.687", "size": "15", "side": "BUY", "hash": "8c2884830b5e4e59885cfd9869d7ecd1cb57eaa2", "best_bid": "0.992", "best_ask": "0.993"}, {"asset_id": "76756244323959292580621865343466747413597132817678365592077495382609595329059", "price": "0.313", "size": "15", "side": "SELL", "hash": "5963dbcc5016d6ea9d5b1756ac3c2f7a11105f28", "best_bid": "0.007", "best_ask": "0.008"}], "timestamp": "1769384670077", "event_type": "price_change"}}
{"_local_timestamp": "2026-01-25T23:44:30.355131+00:00", "data": {"market": "0x1cbe7cbbfb481ed76c054bc4c36c6fb966a2d1671d908d0e89e1f22b0adfa1d6", "price_changes": [{"asset_id": "23234069812587403133665543339348944952052706164431007953765598952013802512997", "price": "0.866", "size": "10", "side": "BUY", "hash": "c5f7b638b87895ba00ea075b12b6ea0b2baa59a7", "best_bid": "0.992", "best_ask": "0.993"}, {"asset_id": "76756244323959292580621865343466747413597132817678365592077495382609595329059", "price": "0.134", "size": "10", "side": "SELL", "hash": "16c0d60e9faa3d5b1ee99ea103005ec88e654e67", "best_bid": "0.007", "best_ask": "0.008"}], "timestamp": "1769384670083", "event_type": "price_change"}}
{"_local_timestamp": "2026-01-25T23:44:30.527065+00:00", "data": {"market": "0x3936de01f890af302ca75727b772fe6dffe915ce638a08809042a3a81dd346c0", "price_changes": [{"asset_id": "93832008664246723386944798388205104088345581837255215982492503205563374375162", "price": "0.417", "size": "10", "side": "BUY", "hash": "f3f1929711b62101f24583de6d16a78074fb08df", "best_bid": "0.971", "best_ask": "0.991"}, {"asset_id": "68682941687946159092109471523402081762244652970943030009984394444937274201240", "price": "0.583", "size": "10", "side": "SELL", "hash": "d7b4598a87ee596d91e457f206688403601b1308", "best_bid": "0.009", "best_ask": "0.029"}], "timestamp": "1769384670241", "event_type": "price_change"}}
{"_local_timestamp": "2026-01-25T23:44:34.040841+00:00", "data": {"market": "0x1cbe7cbbfb481ed76c054bc4c36c6fb966a2d1671d908d0e89e1f22b0adfa1d6", "price_changes": [{"asset_id": "23234069812587403133665543339348944952052706164431007953765598952013802512997", "price": "0.686", "size": "0", "side": "BUY", "hash": "dd3b7bef4524f45e66f6aba2f3b081aceab5901d", "best_bid": "0.992", "best_ask": "0.993"}, {"asset_id": "76756244323959292580621865343466747413597132817678365592077495382609595329059", "price": "0.314", "size": "0", "side": "SELL", "hash": "04e510040f851fea409f9ad6fd4aa54699e934dc", "best_bid": "0.007", "best_ask": "0.008"}], "timestamp": "1769384673767", "event_type": "price_change"}}
{"_local_timestamp": "2026-01-25T23:44:34.076433+00:00", "data": {"market": "0x1cbe7cbbfb481ed76c054bc4c36c6fb966a2d1671d908d0e89e1f22b0adfa1d6", "price_changes": [{"asset_id": "23234069812587403133665543339348944952052706164431007953765598952013802512997", "price": "0.688", "size": "20", "side": "BUY", "hash": "9acfff489223149badb0ce45663948cae026ffea", "best_bid": "0.992", "best_ask": "0.993"}, {"asset_id": "76756244323959292580621865343466747413597132817678365592077495382609595329059", "price": "0.312", "size": "20", "side": "SELL", "hash": "45a1233f9db15be48f8ae45cd6f09f3aa2d2f528", "best_bid": "0.007", "best_ask": "0.008"}], "timestamp": "1769384673795", "event_type": "price_change"}}
{"_local_timestamp": "2026-01-25T23:44:34.214405+00:00", "data": {"market": "0xfdc642275936ee1281df776b1b8a67a35eefbf9095c1266fd178dfa6996ebb4f", "price_changes": [{"asset_id": "55757497654516464627481151189384108294745827872104744655495700337681469992599", "price": "0.49", "size": "0", "side": "BUY", "hash": "7b381d8f39b83895d262d3632b936fd0ca5cc695", "best_bid": "0.957", "best_ask": "0.994"}, {"asset_id": "75055518491634343238225754172066804322353911200619603473770017059656868007002", "price": "0.51", "size": "0", "side": "SELL", "hash": "0c0c3ce172af7b163117c55de24b5912c0c986cf", "best_bid": "0.006", "best_ask": "0.043"}], "timestamp": "1769384673942", "event_type": "price_change"}}
{"_local_timestamp": "2026-01-25T23:44:34.273782+00:00", "data": {"market": "0xfdc642275936ee1281df776b1b8a67a35eefbf9095c1266fd178dfa6996ebb4f", "price_changes": [{"asset_id": "55757497654516464627481151189384108294745827872104744655495700337681469992599", "price": "0.402", "size": "5", "side": "BUY", "hash": "ffc234dc4688519f164c6cef7693033ecf6cb289", "best_bid": "0.957", "best_ask": "0.994"}, {"asset_id": "75055518491634343238225754172066804322353911200619603473770017059656868007002", "price": "0.598", "size": "5", "side": "SELL", "hash": "7fde6efe038de74dd800bf675449205686c39677", "best_bid": "0.006", "best_ask": "0.043"}], "timestamp": "1769384673988", "event_type": "price_change"}}
{"_local_timestamp": "2026-01-25T23:44:53.763010+00:00", "data": {"market": "0xa087422678cebf674c69d2c86a13b89d153951f067f753e0c2044eb991c0652f", "price_changes": [{"asset_id": "94297885496428433994612881192883747282447345164360333822514231082582602051560", "price": "0.73", "size": "700", "side": "BUY", "hash": "64a1c8c6663d4d1878bb5af5d4c9ea1c00104d9c", "best_bid": "0.85", "best_ask": "0.89"}, {"asset_id": "12369294935701377203300019700047987848793450009787501327274207549237196997903", "price": "0.27", "size": "700", "side": "SELL", "hash": "80c8e99a1de3af93de9f5749d905a802b495e4d5", "best_bid": "0.11", "best_ask": "0.15"}], "timestamp": "1769384693673", "event_type": "price_change"}}
{"_local_timestamp": "2026-01-25T23:44:54.707783+00:00", "data": {"market": "0x938e6a0a011f9534ffd2d86c65dde3aeb7c66ad06cee29ead70b832179c3b6de", "price_changes": [{"asset_id": "84559926953146780213236573115780107039976526543427713229500373094335659185505", "price": "0.83", "size": "0", "side": "SELL", "hash": "7cc136ed38054fb8753aaa7ba75733b76071c654", "best_bid": "0.48", "best_ask": "0.5"}, {"asset_id": "24797805539254249433781044462430878338801384554813443486130356027573519184087", "price": "0.17", "size": "0", "side": "BUY", "hash": "bf69b22e8ae576e06e912541e150a43fa3a4cc8d", "best_bid": "0.5", "best_ask": "0.52"}], "timestamp": "1769384694602", "event_type": "price_change"}}
{"_local_timestamp": "2026-01-25T23:44:55.910225+00:00", "data": {"market": "0xa087422678cebf674c69d2c86a13b89d153951f067f753e0c2044eb991c0652f", "price_changes": [{"asset_id": "94297885496428433994612881192883747282447345164360333822514231082582602051560", "price": "0.91", "size": "86.76", "side": "SELL", "hash": "5b748b1f3ea4a97a6f7b4191adf2969f782108e9", "best_bid": "0.85", "best_ask": "0.89"}, {"asset_id": "12369294935701377203300019700047987848793450009787501327274207549237196997903", "price": "0.09", "size": "86.76", "side": "BUY", "hash": "07f4536704f563eab91763ba3bcb661c4aabf22e", "best_bid": "0.11", "best_ask": "0.15"}], "timestamp": "1769384695792", "event_type": "price_change"}}
{"_local_timestamp": "2026-01-25T23:44:56.095650+00:00", "data": {"market": "0xa087422678cebf674c69d2c86a13b89d153951f067f753e0c2044eb991c0652f", "price_changes": [{"asset_id": "94297885496428433994612881192883747282447345164360333822514231082582602051560", "price": "0.91", "size": "93.76", "side": "SELL", "hash": "014cbaf3c7f0f502edaaa6b0daa9b79971cd671e", "best_bid": "0.85", "best_ask": "0.89"}, {"asset_id": "12369294935701377203300019700047987848793450009787501327274207549237196997903", "price": "0.09", "size": "93.76", "side": "BUY", "hash": "329a0e90a290852617b735d6d1d358a1e39d5509", "best_bid": "0.11", "best_ask": "0.15"}], "timestamp": "1769384695985", "event_type": "price_change"}}
{"_local_timestamp": "2026-01-25T23:45:01.443150+00:00", "data": {"market": "0x938e6a0a011f9534ffd2d86c65dde3aeb7c66ad06cee29ead70b832179c3b6de", "price_changes": [{"asset_id": "84559926953146780213236573115780107039976526543427713229500373094335659185505", "price": "0.83", "size": "28.57", "side": "SELL", "hash": "fd23d311c47d2f128cda8f82f4066539cbcc60b0", "best_bid": "0.48", "best_ask": "0.5"}, {"asset_id": "24797805539254249433781044462430878338801384554813443486130356027573519184087", "price": "0.17", "size": "28.57", "side": "BUY", "hash": "09d4e07756f71e3053ca611cdf95c8ec9c98d487", "best_bid": "0.5", "best_ask": "0.52"}], "timestamp": "1769384701373", "event_type": "price_change"}}
{"_local_timestamp": "2026-01-25T23:45:01.532953+00:00", "data": {"market": "0xa087422678cebf674c69d2c86a13b89d153951f067f753e0c2044eb991c0652f", "price_changes": [{"asset_id": "94297885496428433994612881192883747282447345164360333822514231082582602051560", "price": "0.72", "size": "30", "side": "BUY", "hash": "090fed42721f6ef99c7ee10d683f206f219004b0", "best_bid": "0.85", "best_ask": "0.89"}, {"asset_id": "12369294935701377203300019700047987848793450009787501327274207549237196997903", "price": "0.28", "size": "30", "side": "SELL", "hash": "4aa178c7a0dda7ffd878c7d73474b4054ba75938", "best_bid": "0.11", "best_ask": "0.15"}], "timestamp": "1769384701465", "event_type": "price_change"}}
{"_local_timestamp": "2026-01-25T23:45:01.619706+00:00", "data": {"market": "0xa087422678cebf674c69d2c86a13b89d153951f067f753e0c2044eb991c0652f", "price_changes": [{"asset_id": "94297885496428433994612881192883747282447345164360333822514231082582602051560", "price": "0.72", "size": "0", "side": "BUY", "hash": "8165433239c994f8dfeffbaedc0bcbef92c2bb05", "best_bid": "0.85", "best_ask": "0.89"}, {"asset_id": "12369294935701377203300019700047987848793450009787501327274207549237196997903", "price": "0.28", "size": "0", "side": "SELL", "hash": "3b4a605a91b442759622a3d535349260f8eb459e", "best_bid": "0.11", "best_ask": "0.15"}], "timestamp": "1769384701554", "event_type": "price_change"}}
{"_local_timestamp": "2026-01-25T23:45:01.667049+00:00", "data": {"market": "0xa087422678cebf674c69d2c86a13b89d153951f067f753e0c2044eb991c0652f", "price_changes": [{"asset_id": "94297885496428433994612881192883747282447345164360333822514231082582602051560", "price": "0.71", "size": "79.61", "side": "BUY", "hash": "269d40dca5685e27af97f694bdf6e9619b041faf", "best_bid": "0.85", "best_ask": "0.89"}, {"asset_id": "12369294935701377203300019700047987848793450009787501327274207549237196997903", "price": "0.29", "size": "79.61", "side": "SELL", "hash": "b250be5542dc56e16b32630ebd233c2c38f4eb9d", "best_bid": "0.11", "best_ask": "0.15"}], "timestamp": "1769384701594", "event_type": "price_change"}}
{"_local_timestamp": "2026-01-25T23:45:01.734831+00:00", "data": {"market": "0xa087422678cebf674c69d2c86a13b89d153951f067f753e0c2044eb991c0652f", "price_changes": [{"asset_id": "94297885496428433994612881192883747282447345164360333822514231082582602051560", "price": "0.71", "size": "119.61", "side": "BUY", "hash": "3a59e9b2cb23209cfc51d53a0046fae04bf20283", "best_bid": "0.85", "best_ask": "0.89"}, {"asset_id": "12369294935701377203300019700047987848793450009787501327274207549237196997903", "price": "0.29", "size": "119.61", "side": "SELL", "hash": "4d411c30167743fd15ed7886ebe33bb1c43eab9e", "best_bid": "0.11", "best_ask": "0.15"}], "timestamp": "1769384701668", "event_type": "price_change"}}
{"_local_timestamp": "2026-01-25T23:45:17.955690+00:00", "data": {"market": "0xfc64306c19c1faab6dee0e3d3bf4b1ec35599692a11eec762a7f54d25bc268f2", "price_changes": [{"asset_id": "87783727256798391598144762644215659792411859939354027829302503274879035245702", "price": "0.026", "size": "0", "side": "SELL", "hash": "1c2b16a7f28171d3ab24f946cebd6f80d13c5191", "best_bid": "0.009", "best_ask": "0.02"}, {"asset_id": "59580829599216932260845656819640492314194305910396233354387067124740172992769", "price": "0.974", "size": "0", "side": "BUY", "hash": "78b755d49b2740dd783293bb5c4414c896a839a4", "best_bid": "0.98", "best_ask": "0.991"}], "timestamp": "1769384717874", "event_type": "price_change"}}
{"_local_timestamp": "2026-01-25T23:45:19.036582+00:00", "data": {"market": "0xfc64306c19c1faab6dee0e3d3bf4b1ec35599692a11eec762a7f54d25bc268f2", "price_changes": [{"asset_id": "87783727256798391598144762644215659792411859939354027829302503274879035245702", "price": "0.026", "size": "14.75", "side": "SELL", "hash": "8fe4064df4ef4e5cdc38b6eda8f8736833853bca", "best_bid": "0.009", "best_ask": "0.02"}, {"asset_id": "59580829599216932260845656819640492314194305910396233354387067124740172992769", "price": "0.974", "size": "14.75", "side": "BUY", "hash": "854f7e824cb6912d24549a19a42ce952e17b4adf", "best_bid": "0.98", "best_ask": "0.991"}], "timestamp": "1769384718971", "event_type": "price_change"}}
{"_local_timestamp": "2026-01-25T23:45:30.113098+00:00", "data": {"market": "0xa087422678cebf674c69d2c86a13b89d153951f067f753e0c2044eb991c0652f", "price_changes": [{"asset_id": "94297885496428433994612881192883747282447345164360333822514231082582602051560", "price": "0.73", "size": "0", "side": "BUY", "hash": "7407102b73f0d530407f422a6936b6a8e26c4ca4", "best_bid": "0.85", "best_ask": "0.89"}, {"asset_id": "12369294935701377203300019700047987848793450009787501327274207549237196997903", "price": "0.27", "size": "0", "side": "SELL", "hash": "ae298053398803e834b99bfc5de2cc44ef71ef01", "best_bid": "0.11", "best_ask": "0.15"}], "timestamp": "1769384730009", "event_type": "price_change"}}
{"_local_timestamp": "2026-01-25T23:45:34.177650+00:00", "data": {"market": "0x29134729ec74a0dbab6ddad9d9a745e4c0b83c59682bdc4b76412c9635d66627", "price_changes": [{"asset_id": "109408722309726159994284194907981745959708334274938135190768342039858793034476", "price": "0.03", "size": "150", "side": "BUY", "hash": "f61131fd63cdfb89fc0f4f7d331b3b77f3fd2756", "best_bid": "0.081", "best_ask": "0.1"}, {"asset_id": "63263918316087383998965771464254486398250019398684443889644959466369157825041", "price": "0.97", "size": "150", "side": "SELL", "hash": "38ad4c694965bfccb1161d0a4c0642795a9386da", "best_bid": "0.9", "best_ask": "0.919"}], "timestamp": "1769384734088", "event_type": "price_change"}}
{"_local_timestamp": "2026-01-25T23:45:35.831253+00:00", "data": {"market": "0x29134729ec74a0dbab6ddad9d9a745e4c0b83c59682bdc4b76412c9635d66627", "price_changes": [{"asset_id": "63263918316087383998965771464254486398250019398684443889644959466369157825041", "price": "0.18", "size": "950", "side": "BUY", "hash": "073e86786caa0e23702c72a34c0dece03536ab75", "best_bid": "0.9", "best_ask": "0.919"}, {"asset_id": "109408722309726159994284194907981745959708334274938135190768342039858793034476", "price": "0.82", "size": "950", "side": "SELL", "hash": "acf3d2426919a574886ab57b57241aeda238ef7b", "best_bid": "0.081", "best_ask": "0.1"}], "timestamp": "1769384735766", "event_type": "price_change"}}
{"_local_timestamp": "2026-01-25T23:45:35.831612+00:00", "data": {"market": "0x29134729ec74a0dbab6ddad9d9a745e4c0b83c59682bdc4b76412c9635d66627", "price_changes": [{"asset_id": "63263918316087383998965771464254486398250019398684443889644959466369157825041", "price": "0.77", "size": "150", "side": "BUY", "hash": "a49e5a9f6fb5639ec53d8093e1c14736f120c896", "best_bid": "0.9", "best_ask": "0.919"}, {"asset_id": "109408722309726159994284194907981745959708334274938135190768342039858793034476", "price": "0.23", "size": "150", "side": "SELL", "hash": "b42c17c0d693e82e993ee8dd057aa0a191a65fc6", "best_bid": "0.081", "best_ask": "0.1"}], "timestamp": "1769384735767", "event_type": "price_change"}}
{"_local_timestamp": "2026-01-25T23:45:35.932174+00:00", "data": {"market": "0x021e7689a90ac39c268a39ddff6269fd0f41ed84ea6833f6e5b7d900569e6d8b", "price_changes": [{"asset_id": "21609653795728383864795868045140971967534750053984809993030488713671979919753", "price": "0.533", "size": "10", "side": "BUY", "hash": "de1381b19b48a8bf2bfadcead743874f57d7dc54", "best_bid": "0.992", "best_ask": "0.994"}, {"asset_id": "25265857280574792887110878653665871891927967464924536706348687031929049209739", "price": "0.467", "size": "10", "side": "SELL", "hash": "b68a2bd101acda395b8d63ee2ea8fa92b4fe9257", "best_bid": "0.006", "best_ask": "0.008"}], "timestamp": "1769384735863", "event_type": "price_change"}}
{"_local_timestamp": "2026-01-25T23:45:36.415049+00:00", "data": {"market": "0x29134729ec74a0dbab6ddad9d9a745e4c0b83c59682bdc4b76412c9635d66627", "price_changes": [{"asset_id": "63263918316087383998965771464254486398250019398684443889644959466369157825041", "price": "0.18", "size": "250", "side": "BUY", "hash": "aba387fc0cfb5b3834a1d0925c7b580af792bcff", "best_bid": "0.9", "best_ask": "0.919"}, {"asset_id": "109408722309726159994284194907981745959708334274938135190768342039858793034476", "price": "0.82", "size": "250", "side": "SELL", "hash": "af24ac620de0b6a15b271036d939fb7c9745cf6b", "best_bid": "0.081", "best_ask": "0.1"}], "timestamp": "1769384736343", "event_type": "price_change"}}
{"_local_timestamp": "2026-01-25T23:45:36.415374+00:00", "data": {"market": "0x29134729ec74a0dbab6ddad9d9a745e4c0b83c59682bdc4b76412c9635d66627", "price_changes": [{"asset_id": "109408722309726159994284194907981745959708334274938135190768342039858793034476", "price": "0.03", "size": "0", "side": "BUY", "hash": "282cb4e6474e8ded0b3126fdb1c0a3602288810a", "best_bid": "0.081", "best_ask": "0.1"}, {"asset_id": "63263918316087383998965771464254486398250019398684443889644959466369157825041", "price": "0.97", "size": "0", "side": "SELL", "hash": "54196150b1fc09738c33feae6af5d37b93e29842", "best_bid": "0.9", "best_ask": "0.919"}], "timestamp": "1769384736343", "event_type": "price_change"}}
{"_local_timestamp": "2026-01-25T23:45:56.765416+00:00", "data": {"market": "0x29134729ec74a0dbab6ddad9d9a745e4c0b83c59682bdc4b76412c9635d66627", "price_changes": [{"asset_id": "63263918316087383998965771464254486398250019398684443889644959466369157825041", "price": "0.284", "size": "453", "side": "BUY", "hash": "817e94613d18f38a04353197284ba70e41ae8d43", "best_bid": "0.9", "best_ask": "0.919"}, {"asset_id": "109408722309726159994284194907981745959708334274938135190768342039858793034476", "price": "0.716", "size": "453", "side": "SELL", "hash": "f1789c07241d18f66bb30bcd46b581600f981b78", "best_bid": "0.081", "best_ask": "0.1"}], "timestamp": "1769384756089", "event_type": "price_change"}}
{"_local_timestamp": "2026-01-25T23:45:57.199008+00:00", "data": {"market": "0x021e7689a90ac39c268a39ddff6269fd0f41ed84ea6833f6e5b7d900569e6d8b", "price_changes": [{"asset_id": "21609653795728383864795868045140971967534750053984809993030488713671979919753", "price": "0.533", "size": "0", "side": "BUY", "hash": "4e2bbbf4e2c905787af5284cf66a56a2fc58cd05", "best_bid": "0.992", "best_ask": "0.994"}, {"asset_id": "25265857280574792887110878653665871891927967464924536706348687031929049209739", "price": "0.467", "size": "0", "side": "SELL", "hash": "421294d1dce6c2b6e15d59f9b3e0f6e323f733a4", "best_bid": "0.006", "best_ask": "0.008"}], "timestamp": "1769384756793", "event_type": "price_change"}}
{"_local_timestamp": "2026-01-25T23:45:57.253384+00:00", "data": {"market": "0x021e7689a90ac39c268a39ddff6269fd0f41ed84ea6833f6e5b7d900569e6d8b", "price_changes": [{"asset_id": "21609653795728383864795868045140971967534750053984809993030488713671979919753", "price": "0.531", "size": "0", "side": "BUY", "hash": "0edda3e40e153d6db32df307fa69cdceaac6caed", "best_bid": "0.992", "best_ask": "0.994"}, {"asset_id": "25265857280574792887110878653665871891927967464924536706348687031929049209739", "price": "0.469", "size": "0", "side": "SELL", "hash": "b69d0fb98ccc2744e965df85aab099b43fbe1cb8", "best_bid": "0.006", "best_ask": "0.008"}], "timestamp": "1769384756856", "event_type": "price_change"}}
{"_local_timestamp": "2026-01-25T23:45:57.431231+00:00", "data": {"market": "0x021e7689a90ac39c268a39ddff6269fd0f41ed84ea6833f6e5b7d900569e6d8b", "price_changes": [{"asset_id": "21609653795728383864795868045140971967534750053984809993030488713671979919753", "price": "0.537", "size": "30", "side": "BUY", "hash": "77353e4834e60ff4fec5c78fa1a1159a1c7ac43d", "best_bid": "0.992", "best_ask": "0.994"}, {"asset_id": "25265857280574792887110878653665871891927967464924536706348687031929049209739", "price": "0.463", "size": "30", "side": "SELL", "hash": "ab6118170c4345f8f0e7fb4416ffee422a5f802d", "best_bid": "0.006", "best_ask": "0.008"}], "timestamp": "1769384757292", "event_type": "price_change"}}
{"_local_timestamp": "2026-01-25T23:45:57.431587+00:00", "data": {"market": "0xfdc642275936ee1281df776b1b8a67a35eefbf9095c1266fd178dfa6996ebb4f", "price_changes": [{"asset_id": "55757497654516464627481151189384108294745827872104744655495700337681469992599", "price": "0.54", "size": "15", "side": "BUY", "hash": "eaa4ca2dc1691eb86ee0a87366b47fb8b6403256", "best_bid": "0.957", "best_ask": "0.994"}, {"asset_id": "75055518491634343238225754172066804322353911200619603473770017059656868007002", "price": "0.46", "size": "15", "side": "SELL", "hash": "a51cfd904af2a82a3b7736fbc4d693d2c98f3abe", "best_bid": "0.006", "best_ask": "0.043"}], "timestamp": "1769384757302", "event_type": "price_change"}}
{"_local_timestamp": "2026-01-25T23:45:57.556889+00:00", "data": {"market": "0xfdc642275936ee1281df776b1b8a67a35eefbf9095c1266fd178dfa6996ebb4f", "price_changes": [{"asset_id": "55757497654516464627481151189384108294745827872104744655495700337681469992599", "price": "0.54", "size": "0", "side": "BUY", "hash": "a4e323bf8e25ff5306802733f2b24f1f05e99d7e", "best_bid": "0.957", "best_ask": "0.994"}, {"asset_id": "75055518491634343238225754172066804322353911200619603473770017059656868007002", "price": "0.46", "size": "0", "side": "SELL", "hash": "9bcbebe7c555c79d27c71c6c41c87d5a194ee1e4", "best_bid": "0.006", "best_ask": "0.043"}], "timestamp": "1769384757484", "event_type": "price_change"}}
{"_local_timestamp": "2026-01-25T23:45:57.687601+00:00", "data": {"market": "0xfdc642275936ee1281df776b1b8a67a35eefbf9095c1266fd178dfa6996ebb4f", "price_changes": [{"asset_id": "55757497654516464627481151189384108294745827872104744655495700337681469992599", "price": "0.546", "size": "15", "side": "BUY", "hash": "5a685e4b119614113bc17b6fdcf2a4d79d54d6ec", "best_bid": "0.957", "best_ask": "0.994"}, {"asset_id": "75055518491634343238225754172066804322353911200619603473770017059656868007002", "price": "0.454", "size": "15", "side": "SELL", "hash": "3a7abf45475c16558507d03c41e965b0485010fc", "best_bid": "0.006", "best_ask": "0.043"}], "timestamp": "1769384757618", "event_type": "price_change"}}
{"_local_timestamp": "2026-01-25T23:45:57.687992+00:00", "data": {"market": "0xfdc642275936ee1281df776b1b8a67a35eefbf9095c1266fd178dfa6996ebb4f", "price_changes": [{"asset_id": "55757497654516464627481151189384108294745827872104744655495700337681469992599", "price": "0.546", "size": "25", "side": "BUY", "hash": "8e1449488da4e3cf7d57b0b255653ba7c5724520", "best_bid": "0.957", "best_ask": "0.994"}, {"asset_id": "75055518491634343238225754172066804322353911200619603473770017059656868007002", "price": "0.454", "size": "25", "side": "SELL", "hash": "64184831d700ae9b6bc521a1223ddf452b2aaa80", "best_bid": "0.006", "best_ask": "0.043"}], "timestamp": "1769384757619", "event_type": "price_change"}}
{"_local_timestamp": "2026-01-25T23:46:02.046866+00:00", "data": {"market": "0x021e7689a90ac39c268a39ddff6269fd0f41ed84ea6833f6e5b7d900569e6d8b", "price_changes": [{"asset_id": "21609653795728383864795868045140971967534750053984809993030488713671979919753", "price": "0.536", "size": "0", "side": "BUY", "hash": "396f8c56c02e2feb4afec7ad18e658ed8174dd2b", "best_bid": "0.992", "best_ask": "0.994"}, {"asset_id": "25265857280574792887110878653665871891927967464924536706348687031929049209739", "price": "0.464", "size": "0", "side": "SELL", "hash": "40b0710c57868959d42e629aca4b0ea6ea9beb6b", "best_bid": "0.006", "best_ask": "0.008"}], "timestamp": "1769384761972", "event_type": "price_change"}}
{"_local_timestamp": "2026-01-25T23:46:02.047199+00:00", "data": {"market": "0xfdc642275936ee1281df776b1b8a67a35eefbf9095c1266fd178dfa6996ebb4f", "price_changes": [{"asset_id": "55757497654516464627481151189384108294745827872104744655495700337681469992599", "price": "0.545", "size": "0", "side": "BUY", "hash": "0504104d09b706c97a814bea9a9803a409d05943", "best_bid": "0.957", "best_ask": "0.994"}, {"asset_id": "75055518491634343238225754172066804322353911200619603473770017059656868007002", "price": "0.455", "size": "0", "side": "SELL", "hash": "6ed1e9b71646d650f42b32571e5fa5a775774e3c", "best_bid": "0.006", "best_ask": "0.043"}], "timestamp": "1769384761972", "event_type": "price_change"}}
{"_local_timestamp": "2026-01-25T23:46:02.107045+00:00", "data": {"market": "0x021e7689a90ac39c268a39ddff6269fd0f41ed84ea6833f6e5b7d900569e6d8b", "price_changes": [{"asset_id": "21609653795728383864795868045140971967534750053984809993030488713671979919753", "price": "0.538", "size": "20", "side": "BUY", "hash": "259dc11baca4db4c70a1df40a3ebab41251b2288", "best_bid": "0.992", "best_ask": "0.994"}, {"asset_id": "25265857280574792887110878653665871891927967464924536706348687031929049209739", "price": "0.462", "size": "20", "side": "SELL", "hash": "ef637afdad29517b6f3209f1cb7b7df8cae98f19", "best_bid": "0.006", "best_ask": "0.008"}], "timestamp": "1769384762011", "event_type": "price_change"}}
{"_local_timestamp": "2026-01-25T23:46:02.107390+00:00", "data": {"market": "0xfdc642275936ee1281df776b1b8a67a35eefbf9095c1266fd178dfa6996ebb4f", "price_changes": [{"asset_id": "55757497654516464627481151189384108294745827872104744655495700337681469992599", "price": "0.547", "size": "20", "side": "BUY", "hash": "64be37b14d6fac27485af4b4e3e50984c4579160", "best_bid": "0.957", "best_ask": "0.994"}, {"asset_id": "75055518491634343238225754172066804322353911200619603473770017059656868007002", "price": "0.453", "size": "20", "side": "SELL", "hash": "fd649c392c4d39e65d191af8749dac317dc9557e", "best_bid": "0.006", "best_ask": "0.043"}], "timestamp": "1769384762011", "event_type": "price_change"}}
{"_local_timestamp": "2026-01-25T23:46:05.156472+00:00", "data": {"market": "0xfdc642275936ee1281df776b1b8a67a35eefbf9095c1266fd178dfa6996ebb4f", "price_changes": [{"asset_id": "55757497654516464627481151189384108294745827872104744655495700337681469992599", "price": "0.935", "size": "0", "side": "BUY", "hash": "30519dfa37036d283e8bd6b47fef0265a14a27ef", "best_bid": "0.957", "best_ask": "0.994"}, {"asset_id": "75055518491634343238225754172066804322353911200619603473770017059656868007002", "price": "0.065", "size": "0", "side": "SELL", "hash": "2e0477da9fb441663531456e0be588218a5f4267", "best_bid": "0.006", "best_ask": "0.043"}], "timestamp": "1769384765082", "event_type": "price_change"}}
{"_local_timestamp": "2026-01-25T23:46:05.542652+00:00", "data": {"market": "0xfdc642275936ee1281df776b1b8a67a35eefbf9095c1266fd178dfa6996ebb4f", "price_changes": [{"asset_id": "55757497654516464627481151189384108294745827872104744655495700337681469992599", "price": "0.933", "size": "100", "side": "BUY", "hash": "13f053bcb8cfe5df733d2d74091a10a9023257fe", "best_bid": "0.957", "best_ask": "0.994"}, {"asset_id": "75055518491634343238225754172066804322353911200619603473770017059656868007002", "price": "0.067", "size": "100", "side": "SELL", "hash": "79a79c8e3c53c1e9211ded3bc68a7ad2c393ed37", "best_bid": "0.006", "best_ask": "0.043"}], "timestamp": "1769384765470", "event_type": "price_change"}}
{"_local_timestamp": "2026-01-25T23:46:11.246070+00:00", "data": {"market": "0x0afa82ff8cb4dcf8c7a248ccaf438597619d3a6a4e4463adb109e1a1034d6e10", "price_changes": [{"asset_id": "30455848075861160607924869725570428601171045624621952729814709348346858289488", "price": "0.06", "size": "100", "side": "BUY", "hash": "2649fb14832788f58680e2d282754d5173706cbb", "best_bid": "0.24", "best_ask": "0.26"}, {"asset_id": "69317727912918260368347049966647382207251169560838202627585212468740589465040", "price": "0.94", "size": "100", "side": "SELL", "hash": "80f7bbfface468155a377ac1e9d8fcfdd5a9e97f", "best_bid": "0.74", "best_ask": "0.76"}], "timestamp": "1769384771129", "event_type": "price_change"}}
{"_local_timestamp": "2026-01-25T23:46:11.253232+00:00", "data": {"market": "0x29134729ec74a0dbab6ddad9d9a745e4c0b83c59682bdc4b76412c9635d66627", "price_changes": [{"asset_id": "109408722309726159994284194907981745959708334274938135190768342039858793034476", "price": "0.015", "size": "0", "side": "BUY", "hash": "b9d4107259f814344aca407303d89c447fb0c795", "best_bid": "0.081", "best_ask": "0.1"}, {"asset_id": "63263918316087383998965771464254486398250019398684443889644959466369157825041", "price": "0.985", "size": "0", "side": "SELL", "hash": "a05ea2cf850fab70da1adc9ced1267920b7876f0", "best_bid": "0.9", "best_ask": "0.919"}], "timestamp": "1769384771129", "event_type": "price_change"}}
{"_local_timestamp": "2026-01-25T23:46:11.254535+00:00", "data": {"market": "0xa087422678cebf674c69d2c86a13b89d153951f067f753e0c2044eb991c0652f", "price_changes": [{"asset_id": "12369294935701377203300019700047987848793450009787501327274207549237196997903", "price": "0.06", "size": "66.66", "side": "BUY", "hash": "05f930a3e3f52f50cce5d8481e128457f0c9702b", "best_bid": "0.11", "best_ask": "0.15"}, {"asset_id": "94297885496428433994612881192883747282447345164360333822514231082582602051560", "price": "0.94", "size": "66.66", "side": "SELL", "hash": "63e63eb6eb234d2169c46d1127609e1aaa152bdb", "best_bid": "0.85", "best_ask": "0.89"}], "timestamp": "1769384771129", "event_type": "price_change"}}
{"_local_timestamp": "2026-01-25T23:46:11.659641+00:00", "data": {"market": "0xa087422678cebf674c69d2c86a13b89d153951f067f753e0c2044eb991c0652f", "price_changes": [{"asset_id": "12369294935701377203300019700047987848793450009787501327274207549237196997903", "price": "0.08", "size": "300", "side": "BUY", "hash": "09e023a576b4d4d9c031926a9c4414696885455d", "best_bid": "0.11", "best_ask": "0.15"}, {"asset_id": "94297885496428433994612881192883747282447345164360333822514231082582602051560", "price": "0.92", "size": "300", "side": "SELL", "hash": "601db667d06f8283b11482e19681df40b47dba97", "best_bid": "0.85", "best_ask": "0.89"}], "timestamp": "1769384771577", "event_type": "price_change"}}
{"_local_timestamp": "2026-01-25T23:46:11.660093+00:00", "data": {"market": "0x29134729ec74a0dbab6ddad9d9a745e4c0b83c59682bdc4b76412c9635d66627", "price_changes": [{"asset_id": "109408722309726159994284194907981745959708334274938135190768342039858793034476", "price": "0.014", "size": "300", "side": "BUY", "hash": "7f8e2a6d83ceec0721803b8a67a5a422a18a8106", "best_bid": "0.081", "best_ask": "0.1"}, {"asset_id": "63263918316087383998965771464254486398250019398684443889644959466369157825041", "price": "0.986", "size": "300", "side": "SELL", "hash": "c38732acac4eac18999f6b65afb75cf2e9826240", "best_bid": "0.9", "best_ask": "0.919"}], "timestamp": "1769384771577", "event_type": "price_change"}}
{"_local_timestamp": "2026-01-25T23:46:11.660435+00:00", "data": {"market": "0x0afa82ff8cb4dcf8c7a248ccaf438597619d3a6a4e4463adb109e1a1034d6e10", "price_changes": [{"asset_id": "30455848075861160607924869725570428601171045624621952729814709348346858289488", "price": "0.04", "size": "200", "side": "BUY", "hash": "fc7349581267a5789e9020f8084156a6b784e4ad", "best_bid": "0.24", "best_ask": "0.26"}, {"asset_id": "69317727912918260368347049966647382207251169560838202627585212468740589465040", "price": "0.96", "size": "200", "side": "SELL", "hash": "e36fdaf6c0e9d19c915b190e445a9cb7e988af98", "best_bid": "0.74", "best_ask": "0.76"}], "timestamp": "1769384771577", "event_type": "price_change"}}
{"_local_timestamp": "2026-01-25T23:46:15.657146+00:00", "data": {"market": "0x938e6a0a011f9534ffd2d86c65dde3aeb7c66ad06cee29ead70b832179c3b6de", "price_changes": [{"asset_id": "24797805539254249433781044462430878338801384554813443486130356027573519184087", "price": "0.07", "size": "5200", "side": "BUY", "hash": "24920db86bb605b1c24beb471f41a3c79648befb", "best_bid": "0.5", "best_ask": "0.52"}, {"asset_id": "84559926953146780213236573115780107039976526543427713229500373094335659185505", "price": "0.93", "size": "5200", "side": "SELL", "hash": "ab665c392e5b7d2a4272291f442012f85c3c44fe", "best_bid": "0.48", "best_ask": "0.5"}], "timestamp": "1769384775593", "event_type": "price_change"}}
{"_local_timestamp": "2026-01-25T23:46:16.326950+00:00", "data": {"market": "0x938e6a0a011f9534ffd2d86c65dde3aeb7c66ad06cee29ead70b832179c3b6de", "price_changes": [{"asset_id": "24797805539254249433781044462430878338801384554813443486130356027573519184087", "price": "0.07", "size": "4500", "side": "BUY", "hash": "c00ab7287e9ed40939daea1a8c40a72d0bb7311e", "best_bid": "0.5", "best_ask": "0.52"}, {"asset_id": "84559926953146780213236573115780107039976526543427713229500373094335659185505", "price": "0.93", "size": "4500", "side": "SELL", "hash": "d94034a1eb0f351d2c3d8f8682104be7a2b65ab8", "best_bid": "0.48", "best_ask": "0.5"}], "timestamp": "1769384776258", "event_type": "price_change"}}
{"_local_timestamp": "2026-01-25T23:46:18.414483+00:00", "data": {"market": "0x29134729ec74a0dbab6ddad9d9a745e4c0b83c59682bdc4b76412c9635d66627", "price_changes": [{"asset_id": "63263918316087383998965771464254486398250019398684443889644959466369157825041", "price": "0.285", "size": "300", "side": "BUY", "hash": "b6519927364cf9c5c1e27b0013ca73bed8d84a43", "best_bid": "0.9", "best_ask": "0.919"}, {"asset_id": "109408722309726159994284194907981745959708334274938135190768342039858793034476", "price": "0.715", "size": "300", "side": "SELL", "hash": "9c3dc396a4f464d551e2c9feaa5537bcba46e95d", "best_bid": "0.081", "best_ask": "0.1"}], "timestamp": "1769384778345", "event_type": "price_change"}}
{"_local_timestamp": "2026-01-25T23:46:18.518116+00:00", "data": {"market": "0x29134729ec74a0dbab6ddad9d9a745e4c0b83c59682bdc4b76412c9635d66627", "price_changes": [{"asset_id": "63263918316087383998965771464254486398250019398684443889644959466369157825041", "price": "0.284", "size": "329", "side": "BUY", "hash": "3b91d6f59f63560949e2748bc3d25e8cfee05afc", "best_bid": "0.9", "best_ask": "0.919"}, {"asset_id": "109408722309726159994284194907981745959708334274938135190768342039858793034476", "price": "0.716", "size": "329", "side": "SELL", "hash": "0be3e6e1208aa21a353e7b584e21fd05d281542d", "best_bid": "0.081", "best_ask": "0.1"}], "timestamp": "1769384778445", "event_type": "price_change"}}
{"_local_timestamp": "2026-01-25T23:46:18.537048+00:00", "data": {"market": "0x29134729ec74a0dbab6ddad9d9a745e4c0b83c59682bdc4b76412c9635d66627", "price_changes": [{"asset_id": "63263918316087383998965771464254486398250019398684443889644959466369157825041", "price": "0.284", "size": "200", "side": "BUY", "hash": "167bed7381fbf7bd57de27602afac37677d611e7", "best_bid": "0.9", "best_ask": "0.919"}, {"asset_id": "109408722309726159994284194907981745959708334274938135190768342039858793034476", "price": "0.716", "size": "200", "side": "SELL", "hash": "5c5d8ce249177d62f7087379929b09cf3390e90e", "best_bid": "0.081", "best_ask": "0.1"}], "timestamp": "1769384778474", "event_type": "price_change"}}
{"_local_timestamp": "2026-01-25T23:46:18.592116+00:00", "data": {"market": "0x29134729ec74a0dbab6ddad9d9a745e4c0b83c59682bdc4b76412c9635d66627", "price_changes": [{"asset_id": "63263918316087383998965771464254486398250019398684443889644959466369157825041", "price": "0.285", "size": "324", "side": "BUY", "hash": "baf49281c253e4cb3c24eaca0a22175ae358c810", "best_bid": "0.9", "best_ask": "0.919"}, {"asset_id": "109408722309726159994284194907981745959708334274938135190768342039858793034476", "price": "0.715", "size": "324", "side": "SELL", "hash": "f6affa34900186f79cffba96ffdf225cc03ad026", "best_bid": "0.081", "best_ask": "0.1"}], "timestamp": "1769384778524", "event_type": "price_change"}}
{"_local_timestamp": "2026-01-25T23:47:17.908854+00:00", "data": {"market": "0xfc64306c19c1faab6dee0e3d3bf4b1ec35599692a11eec762a7f54d25bc268f2", "price_changes": [{"asset_id": "87783727256798391598144762644215659792411859939354027829302503274879035245702", "price": "0.026", "size": "0", "side": "SELL", "hash": "10515190436cced3dbfc90253ea2481eb3e07097", "best_bid": "0.009", "best_ask": "0.02"}, {"asset_id": "59580829599216932260845656819640492314194305910396233354387067124740172992769", "price": "0.974", "size": "0", "side": "BUY", "hash": "352b48d22a795c349248bcaff403319a265ef94a", "best_bid": "0.98", "best_ask": "0.991"}], "timestamp": "1769384837829", "event_type": "price_change"}}
{"_local_timestamp": "2026-01-25T23:47:18.066670+00:00", "data": {"market": "0xa087422678cebf674c69d2c86a13b89d153951f067f753e0c2044eb991c0652f", "price_changes": [{"asset_id": "94297885496428433994612881192883747282447345164360333822514231082582602051560", "price": "0.43", "size": "0", "side": "BUY", "hash": "4883a6e990c6fe5438059fee90fbce2d5f6a0085", "best_bid": "0.85", "best_ask": "0.89"}, {"asset_id": "12369294935701377203300019700047987848793450009787501327274207549237196997903", "price": "0.57", "size": "0", "side": "SELL", "hash": "c97a9bdd123fa85640f53ffa5873edebb03e491f", "best_bid": "0.11", "best_ask": "0.15"}], "timestamp": "1769384837989", "event_type": "price_change"}}
{"_local_timestamp": "2026-01-25T23:47:18.067023+00:00", "data": {"market": "0x29134729ec74a0dbab6ddad9d9a745e4c0b83c59682bdc4b76412c9635d66627", "price_changes": [{"asset_id": "63263918316087383998965771464254486398250019398684443889644959466369157825041", "price": "0.384", "size": "0", "side": "BUY", "hash": "0dc0a907d844981c7c2608a00965dc7edfab0885", "best_bid": "0.9", "best_ask": "0.919"}, {"asset_id": "109408722309726159994284194907981745959708334274938135190768342039858793034476", "price": "0.616", "size": "0", "side": "SELL", "hash": "ec89f2f9b095cf6b6a06fce27bd69314e0942d27", "best_bid": "0.081", "best_ask": "0.1"}], "timestamp": "1769384837989", "event_type": "price_change"}}
{"_local_timestamp": "2026-01-25T23:47:18.190000+00:00", "data": {"market": "0x3936de01f890af302ca75727b772fe6dffe915ce638a08809042a3a81dd346c0", "price_changes": [{"asset_id": "93832008664246723386944798388205104088345581837255215982492503205563374375162", "price": "0.416", "size": "0", "side": "BUY", "hash": "839cbef5b9df2ab8526e36a0bd44648da5e20e1d", "best_bid": "0.971", "best_ask": "0.991"}, {"asset_id": "68682941687946159092109471523402081762244652970943030009984394444937274201240", "price": "0.584", "size": "0", "side": "SELL", "hash": "a8b10dd6cb575b302c5c18084542c539c2d53e20", "best_bid": "0.009", "best_ask": "0.029"}], "timestamp": "1769384838120", "event_type": "price_change"}}
{"_local_timestamp": "2026-01-25T23:47:18.190517+00:00", "data": {"market": "0x91ebc8bf88c5f99dd4550cb75255766f638d1932ede36e8eae78a76df0c15455", "price_changes": [{"asset_id": "63365825049551318024252373648592413954954442733807178648368002993460348485956", "price": "0.832", "size": "0", "side": "BUY", "hash": "798e40ec0b0162d637a001982cac48deb2e37ff2", "best_bid": "0.938", "best_ask": "0.976"}, {"asset_id": "20552877126021963309330960377901114870262231239849696600236708023505406755774", "price": "0.168", "size": "0", "side": "SELL", "hash": "8f5f07069df63f69095fbb18cc2ce1aec445f83b", "best_bid": "0.024", "best_ask": "0.062"}], "timestamp": "1769384838120", "event_type": "price_change"}}
{"_local_timestamp": "2026-01-25T23:47:18.335458+00:00", "data": {"market": "0xa087422678cebf674c69d2c86a13b89d153951f067f753e0c2044eb991c0652f", "price_changes": [{"asset_id": "94297885496428433994612881192883747282447345164360333822514231082582602051560", "price": "0.41", "size": "10", "side": "BUY", "hash": "547db6b20754cd3bcad4d70d3ca3644955342a8e", "best_bid": "0.85", "best_ask": "0.89"}, {"asset_id": "12369294935701377203300019700047987848793450009787501327274207549237196997903", "price": "0.59", "size": "10", "side": "SELL", "hash": "139637e06dff1ccbdc5a54c61ec953e01832852c", "best_bid": "0.11", "best_ask": "0.15"}], "timestamp": "1769384838269", "event_type": "price_change"}}
{"_local_timestamp": "2026-01-25T23:47:18.336450+00:00", "data": {"market": "0x29134729ec74a0dbab6ddad9d9a745e4c0b83c59682bdc4b76412c9635d66627", "price_changes": [{"asset_id": "63263918316087383998965771464254486398250019398684443889644959466369157825041", "price": "0.384", "size": "10", "side": "BUY", "hash": "fa17d84c0725eb642869c9451e1a4a15c749abd1", "best_bid": "0.9", "best_ask": "0.919"}, {"asset_id": "109408722309726159994284194907981745959708334274938135190768342039858793034476", "price": "0.616", "size": "10", "side": "SELL", "hash": "54b2be60ebab38a701d359acfe9be983a50a2692", "best_bid": "0.081", "best_ask": "0.1"}], "timestamp": "1769384838269", "event_type": "price_change"}}
{"_local_timestamp": "2026-01-25T23:47:19.570022+00:00", "data": {"market": "0xfc64306c19c1faab6dee0e3d3bf4b1ec35599692a11eec762a7f54d25bc268f2", "price_changes": [{"asset_id": "87783727256798391598144762644215659792411859939354027829302503274879035245702", "price": "0.026", "size": "14.75", "side": "SELL", "hash": "a5112a20d19ba5ecb1a2d4eb80e0c012591ac1e7", "best_bid": "0.009", "best_ask": "0.02"}, {"asset_id": "59580829599216932260845656819640492314194305910396233354387067124740172992769", "price": "0.974", "size": "14.75", "side": "BUY", "hash": "e2cb39e18848fb78119ed67d3d6c49005e6ec93e", "best_bid": "0.98", "best_ask": "0.991"}], "timestamp": "1769384839314", "event_type": "price_change"}}
{"_local_timestamp": "2026-01-25T23:47:21.184298+00:00", "data": {"market": "0x91ebc8bf88c5f99dd4550cb75255766f638d1932ede36e8eae78a76df0c15455", "price_changes": [{"asset_id": "63365825049551318024252373648592413954954442733807178648368002993460348485956", "price": "0.833", "size": "0", "side": "BUY", "hash": "3f9b49894006e792542b45042f80ce085e1a23e4", "best_bid": "0.938", "best_ask": "0.976"}, {"asset_id": "20552877126021963309330960377901114870262231239849696600236708023505406755774", "price": "0.167", "size": "0", "side": "SELL", "hash": "1b93b1951ab8263f09037473c4724a0d4a625b05", "best_bid": "0.024", "best_ask": "0.062"}], "timestamp": "1769384841099", "event_type": "price_change"}}
{"_local_timestamp": "2026-01-25T23:47:21.191999+00:00", "data": {"market": "0x91ebc8bf88c5f99dd4550cb75255766f638d1932ede36e8eae78a76df0c15455", "price_changes": [{"asset_id": "63365825049551318024252373648592413954954442733807178648368002993460348485956", "price": "0.831", "size": "20", "side": "BUY", "hash": "60f03b6b3ea742f74f68f0907ae17476e03cd682", "best_bid": "0.938", "best_ask": "0.976"}, {"asset_id": "20552877126021963309330960377901114870262231239849696600236708023505406755774", "price": "0.169", "size": "20", "side": "SELL", "hash": "958c1e911ad1bd4f4b3b19f060757bbb469c9bbe", "best_bid": "0.024", "best_ask": "0.062"}], "timestamp": "1769384841128", "event_type": "price_change"}}
{"_local_timestamp": "2026-01-25T23:48:17.985200+00:00", "data": {"market": "0xfc64306c19c1faab6dee0e3d3bf4b1ec35599692a11eec762a7f54d25bc268f2", "price_changes": [{"asset_id": "87783727256798391598144762644215659792411859939354027829302503274879035245702", "price": "0.026", "size": "0", "side": "SELL", "hash": "be5143ef87919f5220ce9054d91076c1f825e21a", "best_bid": "0.009", "best_ask": "0.02"}, {"asset_id": "59580829599216932260845656819640492314194305910396233354387067124740172992769", "price": "0.974", "size": "0", "side": "BUY", "hash": "ab08f14f9f035c8dfe9abaea06c8d6fd904493fc", "best_bid": "0.98", "best_ask": "0.991"}], "timestamp": "1769384897909", "event_type": "price_change"}}
{"_local_timestamp": "2026-01-25T23:48:19.197843+00:00", "data": {"market": "0xfc64306c19c1faab6dee0e3d3bf4b1ec35599692a11eec762a7f54d25bc268f2", "price_changes": [{"asset_id": "87783727256798391598144762644215659792411859939354027829302503274879035245702", "price": "0.026", "size": "14.75", "side": "SELL", "hash": "76b72adcd62e26fb7f2d30331c7a4530dd60c176", "best_bid": "0.009", "best_ask": "0.02"}, {"asset_id": "59580829599216932260845656819640492314194305910396233354387067124740172992769", "price": "0.974", "size": "14.75", "side": "BUY", "hash": "547e4a62390149417244b58984f0c66a22138014", "best_bid": "0.98", "best_ask": "0.991"}], "timestamp": "1769384899134", "event_type": "price_change"}}
{"_local_timestamp": "2026-01-25T23:48:19.286700+00:00", "data": {"market": "0x3936de01f890af302ca75727b772fe6dffe915ce638a08809042a3a81dd346c0", "price_changes": [{"asset_id": "93832008664246723386944798388205104088345581837255215982492503205563374375162", "price": "0.858", "size": "0", "side": "BUY", "hash": "edc0ccdf1baa29ca06180ce2dade3588f8bfa1cb", "best_bid": "0.971", "best_ask": "0.991"}, {"asset_id": "68682941687946159092109471523402081762244652970943030009984394444937274201240", "price": "0.142", "size": "0", "side": "SELL", "hash": "ec335fe9cbf06328f33ec4ab03ac8ca0071e5431", "best_bid": "0.009", "best_ask": "0.029"}], "timestamp": "1769384899222", "event_type": "price_change"}}
{"_local_timestamp": "2026-01-25T23:48:19.287043+00:00", "data": {"market": "0x91ebc8bf88c5f99dd4550cb75255766f638d1932ede36e8eae78a76df0c15455", "price_changes": [{"asset_id": "63365825049551318024252373648592413954954442733807178648368002993460348485956", "price": "0.809", "size": "0", "side": "BUY", "hash": "7d898c10769da4acf5573d8b71da07d16e2f20a1", "best_bid": "0.938", "best_ask": "0.976"}, {"asset_id": "20552877126021963309330960377901114870262231239849696600236708023505406755774", "price": "0.191", "size": "0", "side": "SELL", "hash": "5c75f96cd8202afe105c804c42b7abbba8600db0", "best_bid": "0.024", "best_ask": "0.062"}], "timestamp": "1769384899222", "event_type": "price_change"}}
{"_local_timestamp": "2026-01-25T23:48:20.585624+00:00", "data": {"market": "0x3936de01f890af302ca75727b772fe6dffe915ce638a08809042a3a81dd346c0", "price_changes": [{"asset_id": "93832008664246723386944798388205104088345581837255215982492503205563374375162", "price": "0.859", "size": "0", "side": "BUY", "hash": "44dd338cd1a7621d5d3b5cd07dc0744540a6ccb0", "best_bid": "0.971", "best_ask": "0.991"}, {"asset_id": "68682941687946159092109471523402081762244652970943030009984394444937274201240", "price": "0.141", "size": "0", "side": "SELL", "hash": "bd7409f641363a69fec503c715a4004f4bdd3d2f", "best_bid": "0.009", "best_ask": "0.029"}], "timestamp": "1769384900516", "event_type": "price_change"}}
{"_local_timestamp": "2026-01-25T23:48:20.607060+00:00", "data": {"market": "0x3936de01f890af302ca75727b772fe6dffe915ce638a08809042a3a81dd346c0", "price_changes": [{"asset_id": "93832008664246723386944798388205104088345581837255215982492503205563374375162", "price": "0.857", "size": "20", "side": "BUY", "hash": "4f6433aa90bf227f407db0ed2975dbe3822d6f6b", "best_bid": "0.971", "best_ask": "0.991"}, {"asset_id": "68682941687946159092109471523402081762244652970943030009984394444937274201240", "price": "0.143", "size": "20", "side": "SELL", "hash": "0be9c28280eec7a716b43ff589252c83d1f39493", "best_bid": "0.009", "best_ask": "0.029"}], "timestamp": "1769384900542", "event_type": "price_change"}}
{"_local_timestamp": "2026-01-25T23:48:20.737428+00:00", "data": {"market": "0x91ebc8bf88c5f99dd4550cb75255766f638d1932ede36e8eae78a76df0c15455", "price_changes": [{"asset_id": "63365825049551318024252373648592413954954442733807178648368002993460348485956", "price": "0.809", "size": "15", "side": "BUY", "hash": "80141607befdeff7fe9b50004582e7d65c4f6d7e", "best_bid": "0.938", "best_ask": "0.976"}, {"asset_id": "20552877126021963309330960377901114870262231239849696600236708023505406755774", "price": "0.191", "size": "15", "side": "SELL", "hash": "4cdfe461179144bb3ab6eb2301efff64d9d058ae", "best_bid": "0.024", "best_ask": "0.062"}], "timestamp": "1769384900673", "event_type": "price_change"}}
{"_local_timestamp": "2026-01-25T23:48:20.741310+00:00", "data": {"market": "0x3936de01f890af302ca75727b772fe6dffe915ce638a08809042a3a81dd346c0", "price_changes": [{"asset_id": "93832008664246723386944798388205104088345581837255215982492503205563374375162", "price": "0.857", "size": "30", "side": "BUY", "hash": "30511e352864328df524d5f77c7fa1bd3287473f", "best_bid": "0.971", "best_ask": "0.991"}, {"asset_id": "68682941687946159092109471523402081762244652970943030009984394444937274201240", "price": "0.143", "size": "30", "side": "SELL", "hash": "ec38e8658bfb6ada66871b1d8b763a7a1add1970", "best_bid": "0.009", "best_ask": "0.029"}], "timestamp": "1769384900673", "event_type": "price_change"}}
{"_local_timestamp": "2026-01-25T23:48:20.746061+00:00", "data": {"market": "0x91ebc8bf88c5f99dd4550cb75255766f638d1932ede36e8eae78a76df0c15455", "price_changes": [{"asset_id": "63365825049551318024252373648592413954954442733807178648368002993460348485956", "price": "0.832", "size": "10", "side": "BUY", "hash": "34a6c6cc4ae9283db4c08d0a2201b889babfc91e", "best_bid": "0.938", "best_ask": "0.976"}, {"asset_id": "20552877126021963309330960377901114870262231239849696600236708023505406755774", "price": "0.168", "size": "10", "side": "SELL", "hash": "cd681ad6a2747bcaa88c634ecb9ffb2e526d5033", "best_bid": "0.024", "best_ask": "0.062"}], "timestamp": "1769384900674", "event_type": "price_change"}}
{"_local_timestamp": "2026-01-25T23:48:20.746328+00:00", "data": {"market": "0x3936de01f890af302ca75727b772fe6dffe915ce638a08809042a3a81dd346c0", "price_changes": [{"asset_id": "93832008664246723386944798388205104088345581837255215982492503205563374375162", "price": "0.418", "size": "15", "side": "BUY", "hash": "a7dff0348bf34ef815a6f593a23e3604e2e0eb28", "best_bid": "0.971", "best_ask": "0.991"}, {"asset_id": "68682941687946159092109471523402081762244652970943030009984394444937274201240", "price": "0.582", "size": "15", "side": "SELL", "hash": "5c78e12e595598d85e6cb0cd2208ff930f82ea13", "best_bid": "0.009", "best_ask": "0.029"}], "timestamp": "1769384900674", "event_type": "price_change"}}
{"_local_timestamp": "2026-01-25T23:48:27.229640+00:00", "data": {"market": "0x3936de01f890af302ca75727b772fe6dffe915ce638a08809042a3a81dd346c0", "price_changes": [{"asset_id": "93832008664246723386944798388205104088345581837255215982492503205563374375162", "price": "0.857", "size": "10", "side": "BUY", "hash": "a458da6854f261fd185703b405a07f07bb434c34", "best_bid": "0.971", "best_ask": "0.991"}, {"asset_id": "68682941687946159092109471523402081762244652970943030009984394444937274201240", "price": "0.143", "size": "10", "side": "SELL", "hash": "a222117febf690f6bb2c21ee9405a7d782fbbb4b", "best_bid": "0.009", "best_ask": "0.029"}], "timestamp": "1769384907136", "event_type": "price_change"}}
{"_local_timestamp": "2026-01-25T23:48:27.229977+00:00", "data": {"market": "0x91ebc8bf88c5f99dd4550cb75255766f638d1932ede36e8eae78a76df0c15455", "price_changes": [{"asset_id": "63365825049551318024252373648592413954954442733807178648368002993460348485956", "price": "0.831", "size": "0", "side": "BUY", "hash": "e1c2cc84281c4fdd7f88e68fefbf472df525e0ee", "best_bid": "0.938", "best_ask": "0.976"}, {"asset_id": "20552877126021963309330960377901114870262231239849696600236708023505406755774", "price": "0.169", "size": "0", "side": "SELL", "hash": "724b8e519e0697dba0140cde9fef96f90a532f0c", "best_bid": "0.024", "best_ask": "0.062"}], "timestamp": "1769384907136", "event_type": "price_change"}}
{"_local_timestamp": "2026-01-25T23:48:27.252860+00:00", "data": {"market": "0x3936de01f890af302ca75727b772fe6dffe915ce638a08809042a3a81dd346c0", "price_changes": [{"asset_id": "93832008664246723386944798388205104088345581837255215982492503205563374375162", "price": "0.858", "size": "20", "side": "BUY", "hash": "be422cc571d964607719ece596381391aba19694", "best_bid": "0.971", "best_ask": "0.991"}, {"asset_id": "68682941687946159092109471523402081762244652970943030009984394444937274201240", "price": "0.142", "size": "20", "side": "SELL", "hash": "9479b6bcbbbaef0dd074326b54aa14a901b9b854", "best_bid": "0.009", "best_ask": "0.029"}], "timestamp": "1769384907170", "event_type": "price_change"}}
{"_local_timestamp": "2026-01-25T23:48:27.253155+00:00", "data": {"market": "0x91ebc8bf88c5f99dd4550cb75255766f638d1932ede36e8eae78a76df0c15455", "price_changes": [{"asset_id": "63365825049551318024252373648592413954954442733807178648368002993460348485956", "price": "0.833", "size": "20", "side": "BUY", "hash": "d8856364c774bee2cbd9193ddf28998379b7b0be", "best_bid": "0.938", "best_ask": "0.976"}, {"asset_id": "20552877126021963309330960377901114870262231239849696600236708023505406755774", "price": "0.167", "size": "20", "side": "SELL", "hash": "792a4b7a06452c2879c11de7f222074c1b981e52", "best_bid": "0.024", "best_ask": "0.062"}], "timestamp": "1769384907170", "event_type": "price_change"}}
{"_local_timestamp": "2026-01-25T23:48:27.297881+00:00", "data": {"market": "0x1cbe7cbbfb481ed76c054bc4c36c6fb966a2d1671d908d0e89e1f22b0adfa1d6", "price_changes": [{"asset_id": "23234069812587403133665543339348944952052706164431007953765598952013802512997", "price": "0.866", "size": "0", "side": "BUY", "hash": "a08df3b58bd9da21fbcde6803873afbcc87054e5", "best_bid": "0.992", "best_ask": "0.993"}, {"asset_id": "76756244323959292580621865343466747413597132817678365592077495382609595329059", "price": "0.134", "size": "0", "side": "SELL", "hash": "35762d6fe063bdd486911ddd5f65ec2838e98368", "best_bid": "0.007", "best_ask": "0.008"}], "timestamp": "1769384907217", "event_type": "price_change"}}
{"_local_timestamp": "2026-01-25T23:48:27.298255+00:00", "data": {"market": "0x1cbe7cbbfb481ed76c054bc4c36c6fb966a2d1671d908d0e89e1f22b0adfa1d6", "price_changes": [{"asset_id": "23234069812587403133665543339348944952052706164431007953765598952013802512997", "price": "0.687", "size": "0", "side": "BUY", "hash": "a08df3b58bd9da21fbcde6803873afbcc87054e5", "best_bid": "0.992", "best_ask": "0.993"}, {"asset_id": "76756244323959292580621865343466747413597132817678365592077495382609595329059", "price": "0.313", "size": "0", "side": "SELL", "hash": "35762d6fe063bdd486911ddd5f65ec2838e98368", "best_bid": "0.007", "best_ask": "0.008"}], "timestamp": "1769384907217", "event_type": "price_change"}}
{"_local_timestamp": "2026-01-25T23:48:27.319826+00:00", "data": {"market": "0x938e6a0a011f9534ffd2d86c65dde3aeb7c66ad06cee29ead70b832179c3b6de", "price_changes": [{"asset_id": "24797805539254249433781044462430878338801384554813443486130356027573519184087", "price": "0.23", "size": "0", "side": "BUY", "hash": "835812d9feb76997d5c3e1c902d9855e15ba1583", "best_bid": "0.5", "best_ask": "0.52"}, {"asset_id": "84559926953146780213236573115780107039976526543427713229500373094335659185505", "price": "0.77", "size": "0", "side": "SELL", "hash": "a17cef8a126c82c6ebf292aaa41e05783cfaa76c", "best_bid": "0.48", "best_ask": "0.5"}], "timestamp": "1769384907243", "event_type": "price_change"}}
{"_local_timestamp": "2026-01-25T23:48:27.320122+00:00", "data": {"market": "0xfdc642275936ee1281df776b1b8a67a35eefbf9095c1266fd178dfa6996ebb4f", "price_changes": [{"asset_id": "55757497654516464627481151189384108294745827872104744655495700337681469992599", "price": "0.533", "size": "0", "side": "BUY", "hash": "1174b14290e7aeaa2a75af07c80b21d7ab10e803", "best_bid": "0.957", "best_ask": "0.994"}, {"asset_id": "75055518491634343238225754172066804322353911200619603473770017059656868007002", "price": "0.467", "size": "0", "side": "SELL", "hash": "53f1ea1e0d5459dced6ca91d9382e6178b8ea9d0", "best_bid": "0.006", "best_ask": "0.043"}], "timestamp": "1769384907243", "event_type": "price_change"}}
{"_local_timestamp": "2026-01-25T23:48:27.365542+00:00", "data": {"market": "0x1cbe7cbbfb481ed76c054bc4c36c6fb966a2d1671d908d0e89e1f22b0adfa1d6", "price_changes": [{"asset_id": "23234069812587403133665543339348944952052706164431007953765598952013802512997", "price": "0.866", "size": "10", "side": "BUY", "hash": "98831b1a0cf4c8abc4abcbe0e8d179c201c5e9fa", "best_bid": "0.992", "best_ask": "0.993"}, {"asset_id": "76756244323959292580621865343466747413597132817678365592077495382609595329059", "price": "0.134", "size": "10", "side": "SELL", "hash": "463f609ea008cd00a12dd5317423d4353a9845de", "best_bid": "0.007", "best_ask": "0.008"}], "timestamp": "1769384907285", "event_type": "price_change"}}
{"_local_timestamp": "2026-01-25T23:48:27.374398+00:00", "data": {"market": "0x1cbe7cbbfb481ed76c054bc4c36c6fb966a2d1671d908d0e89e1f22b0adfa1d6", "price_changes": [{"asset_id": "23234069812587403133665543339348944952052706164431007953765598952013802512997", "price": "0.689", "size": "15", "side": "BUY", "hash": "798ce7d22026e4e7312fd3c6f4ab23dc1637c873", "best_bid": "0.992", "best_ask": "0.993"}, {"asset_id": "76756244323959292580621865343466747413597132817678365592077495382609595329059", "price": "0.311", "size": "15", "side": "SELL", "hash": "b2a0fcf5202430fd9dfa0d01a2ad299aefcd83bd", "best_bid": "0.007", "best_ask": "0.008"}], "timestamp": "1769384907288", "event_type": "price_change"}}
{"_local_timestamp": "2026-01-25T23:48:27.443072+00:00", "data": {"market": "0xfdc642275936ee1281df776b1b8a67a35eefbf9095c1266fd178dfa6996ebb4f", "price_changes": [{"asset_id": "55757497654516464627481151189384108294745827872104744655495700337681469992599", "price": "0.548", "size": "10", "side": "BUY", "hash": "d20fbdcc8d283ab570b97e960f32b2135ee34521", "best_bid": "0.957", "best_ask": "0.994"}, {"asset_id": "75055518491634343238225754172066804322353911200619603473770017059656868007002", "price": "0.452", "size": "10", "side": "SELL", "hash": "2665bff9d27e6cfed53d731f8647110fb3d60690", "best_bid": "0.006", "best_ask": "0.043"}], "timestamp": "1769384907361", "event_type": "price_change"}}
{"_local_timestamp": "2026-01-25T23:48:27.443356+00:00", "data": {"market": "0x938e6a0a011f9534ffd2d86c65dde3aeb7c66ad06cee29ead70b832179c3b6de", "price_changes": [{"asset_id": "24797805539254249433781044462430878338801384554813443486130356027573519184087", "price": "0.23", "size": "10", "side": "BUY", "hash": "6977a59515d40eff1b1d7b3f2a213355bb7d5635", "best_bid": "0.5", "best_ask": "0.52"}, {"asset_id": "84559926953146780213236573115780107039976526543427713229500373094335659185505", "price": "0.77", "size": "10", "side": "SELL", "hash": "005e4a31a7c4abb607e538c62e2b00bd6209c13b", "best_bid": "0.48", "best_ask": "0.5"}], "timestamp": "1769384907362", "event_type": "price_change"}}
{"_local_timestamp": "2026-01-25T23:48:30.612839+00:00", "data": {"market": "0x1cbe7cbbfb481ed76c054bc4c36c6fb966a2d1671d908d0e89e1f22b0adfa1d6", "price_changes": [{"asset_id": "23234069812587403133665543339348944952052706164431007953765598952013802512997", "price": "0.688", "size": "0", "side": "BUY", "hash": "1d48c509d415f8f16ad9cc0468ea60c63bf6e738", "best_bid": "0.992", "best_ask": "0.993"}, {"asset_id": "76756244323959292580621865343466747413597132817678365592077495382609595329059", "price": "0.312", "size": "0", "side": "SELL", "hash": "10058869de49f64f2f90f8d2fab7b77bbf46350a", "best_bid": "0.007", "best_ask": "0.008"}], "timestamp": "1769384910527", "event_type": "price_change"}}
{"_local_timestamp": "2026-01-25T23:48:30.613333+00:00", "data": {"market": "0xfdc642275936ee1281df776b1b8a67a35eefbf9095c1266fd178dfa6996ebb4f", "price_changes": [{"asset_id": "55757497654516464627481151189384108294745827872104744655495700337681469992599", "price": "0.547", "size": "0", "side": "BUY", "hash": "c4de4af51058dde2758270fa147a7ea328157540", "best_bid": "0.957", "best_ask": "0.994"}, {"asset_id": "75055518491634343238225754172066804322353911200619603473770017059656868007002", "price": "0.453", "size": "0", "side": "SELL", "hash": "985e7fbb23622b9a75e1c4746e646d42b4a08a7e", "best_bid": "0.006", "best_ask": "0.043"}], "timestamp": "1769384910527", "event_type": "price_change"}}
{"_local_timestamp": "2026-01-25T23:48:30.640241+00:00", "data": {"market": "0xfdc642275936ee1281df776b1b8a67a35eefbf9095c1266fd178dfa6996ebb4f", "price_changes": [{"asset_id": "55757497654516464627481151189384108294745827872104744655495700337681469992599", "price": "0.549", "size": "20", "side": "BUY", "hash": "b733084df7749597d548d1058b94ebc48fa13f90", "best_bid": "0.957", "best_ask": "0.994"}, {"asset_id": "75055518491634343238225754172066804322353911200619603473770017059656868007002", "price": "0.451", "size": "20", "side": "SELL", "hash": "266889f04e4bf9704dab443f53512b24d1493500", "best_bid": "0.006", "best_ask": "0.043"}], "timestamp": "1769384910554", "event_type": "price_change"}}
{"_local_timestamp": "2026-01-25T23:48:30.640642+00:00", "data": {"market": "0x1cbe7cbbfb481ed76c054bc4c36c6fb966a2d1671d908d0e89e1f22b0adfa1d6", "price_changes": [{"asset_id": "23234069812587403133665543339348944952052706164431007953765598952013802512997", "price": "0.69", "size": "20", "side": "BUY", "hash": "239bf982cf166ee1158b7e2504356c9bcb4b7bfc", "best_bid": "0.992", "best_ask": "0.993"}, {"asset_id": "76756244323959292580621865343466747413597132817678365592077495382609595329059", "price": "0.31", "size": "20", "side": "SELL", "hash": "e9dbfe9608720bed0e6b93fe92469d4ba64d2ccf", "best_bid": "0.007", "best_ask": "0.008"}], "timestamp": "1769384910554", "event_type": "price_change"}}
{"_local_timestamp": "2026-01-25T23:48:53.906079+00:00", "data": {"market": "0x938e6a0a011f9534ffd2d86c65dde3aeb7c66ad06cee29ead70b832179c3b6de", "price_changes": [{"asset_id": "84559926953146780213236573115780107039976526543427713229500373094335659185505", "price": "0.92", "size": "425", "side": "SELL", "hash": "ebb40a4464167c7fb3734eca19f718562dd6eb3e", "best_bid": "0.48", "best_ask": "0.5"}, {"asset_id": "24797805539254249433781044462430878338801384554813443486130356027573519184087", "price": "0.08", "size": "425", "side": "BUY", "hash": "c1280c976cbd2fc315d4e311319a64e48211e701", "best_bid": "0.5", "best_ask": "0.52"}], "timestamp": "1769384933828", "event_type": "price_change"}}
{"_local_timestamp": "2026-01-25T23:48:53.925405+00:00", "data": {"market": "0x938e6a0a011f9534ffd2d86c65dde3aeb7c66ad06cee29ead70b832179c3b6de", "price_changes": [{"asset_id": "24797805539254249433781044462430878338801384554813443486130356027573519184087", "price": "0.92", "size": "0", "side": "SELL", "hash": "77aa3d56b4200fafa1baf02cf82b7b7f3fb9d2fd", "best_bid": "0.5", "best_ask": "0.52"}, {"asset_id": "84559926953146780213236573115780107039976526543427713229500373094335659185505", "price": "0.08", "size": "0", "side": "BUY", "hash": "a142de998b6d686ba8546285d9fda441eb6210fe", "best_bid": "0.48", "best_ask": "0.5"}], "timestamp": "1769384933829", "event_type": "price_change"}}
{"_local_timestamp": "2026-01-25T23:49:03.637030+00:00", "data": {"market": "0x938e6a0a011f9534ffd2d86c65dde3aeb7c66ad06cee29ead70b832179c3b6de", "price_changes": [{"asset_id": "84559926953146780213236573115780107039976526543427713229500373094335659185505", "price": "0.92", "size": "448.25", "side": "SELL", "hash": "b6859888a8bb14ef24d4b5357d030708a6fc8e4f", "best_bid": "0.48", "best_ask": "0.5"}, {"asset_id": "24797805539254249433781044462430878338801384554813443486130356027573519184087", "price": "0.08", "size": "448.25", "side": "BUY", "hash": "e1435eebb3c4589aaa5f43579fe61e2695a917f8", "best_bid": "0.5", "best_ask": "0.52"}], "timestamp": "1769384943552", "event_type": "price_change"}}
{"_local_timestamp": "2026-01-25T23:49:03.727384+00:00", "data": {"market": "0x021e7689a90ac39c268a39ddff6269fd0f41ed84ea6833f6e5b7d900569e6d8b", "price_changes": [{"asset_id": "21609653795728383864795868045140971967534750053984809993030488713671979919753", "price": "0.526", "size": "570", "side": "BUY", "hash": "8958f57c83928fabf9f22107dda7623292ca942b", "best_bid": "0.992", "best_ask": "0.994"}, {"asset_id": "25265857280574792887110878653665871891927967464924536706348687031929049209739", "price": "0.474", "size": "570", "side": "SELL", "hash": "f341a40ae4dccb91a8da62e7ef0634d6c985f21d", "best_bid": "0.006", "best_ask": "0.008"}], "timestamp": "1769384943656", "event_type": "price_change"}}
{"_local_timestamp": "2026-01-25T23:49:03.788112+00:00", "data": {"market": "0x021e7689a90ac39c268a39ddff6269fd0f41ed84ea6833f6e5b7d900569e6d8b", "price_changes": [{"asset_id": "21609653795728383864795868045140971967534750053984809993030488713671979919753", "price": "0.539", "size": "195", "side": "BUY", "hash": "3025d7a2828a29977e20a9917b4a753870e922d8", "best_bid": "0.992", "best_ask": "0.994"}, {"asset_id": "25265857280574792887110878653665871891927967464924536706348687031929049209739", "price": "0.461", "size": "195", "side": "SELL", "hash": "d661fa42f02459048e7b7b916ced45b8fd2ec1ab", "best_bid": "0.006", "best_ask": "0.008"}], "timestamp": "1769384943709", "event_type": "price_change"}}
{"_local_timestamp": "2026-01-25T23:49:03.788414+00:00", "data": {"market": "0x021e7689a90ac39c268a39ddff6269fd0f41ed84ea6833f6e5b7d900569e6d8b", "price_changes": [{"asset_id": "21609653795728383864795868045140971967534750053984809993030488713671979919753", "price": "0.539", "size": "205", "side": "BUY", "hash": "0d956c0a2ce0473ce2d20dc0d2465d0e32ff8c21", "best_bid": "0.992", "best_ask": "0.994"}, {"asset_id": "25265857280574792887110878653665871891927967464924536706348687031929049209739", "price": "0.461", "size": "205", "side": "SELL", "hash": "f6ed7e246dfaa2ff8afb9976199a431c37684ce8", "best_bid": "0.006", "best_ask": "0.008"}], "timestamp": "1769384943710", "event_type": "price_change"}}
{"_local_timestamp": "2026-01-25T23:49:03.866665+00:00", "data": {"market": "0x021e7689a90ac39c268a39ddff6269fd0f41ed84ea6833f6e5b7d900569e6d8b", "price_changes": [{"asset_id": "21609653795728383864795868045140971967534750053984809993030488713671979919753", "price": "0.526", "size": "380", "side": "BUY", "hash": "d91e25c53f44766e363b62299f403acdc3e5cf4f", "best_bid": "0.992", "best_ask": "0.994"}, {"asset_id": "25265857280574792887110878653665871891927967464924536706348687031929049209739", "price": "0.474", "size": "380", "side": "SELL", "hash": "d365c777913b6b680c8ffa1180e426f4472049e7", "best_bid": "0.006", "best_ask": "0.008"}], "timestamp": "1769384943790", "event_type": "price_change"}}
{"_local_timestamp": "2026-01-25T23:49:03.989961+00:00", "data": {"market": "0x021e7689a90ac39c268a39ddff6269fd0f41ed84ea6833f6e5b7d900569e6d8b", "price_changes": [{"asset_id": "21609653795728383864795868045140971967534750053984809993030488713671979919753", "price": "0.54", "size": "185", "side": "BUY", "hash": "6d5d950e2d056ef949a8ff2668b609e1cdaffa5c", "best_bid": "0.992", "best_ask": "0.994"}, {"asset_id": "25265857280574792887110878653665871891927967464924536706348687031929049209739", "price": "0.46", "size": "185", "side": "SELL", "hash": "2214500b7e1c9925b630c2066f23b6a972c5d72e", "best_bid": "0.006", "best_ask": "0.008"}], "timestamp": "1769384943919", "event_type": "price_change"}}
{"_local_timestamp": "2026-01-25T23:49:03.990268+00:00", "data": {"market": "0x021e7689a90ac39c268a39ddff6269fd0f41ed84ea6833f6e5b7d900569e6d8b", "price_changes": [{"asset_id": "21609653795728383864795868045140971967534750053984809993030488713671979919753", "price": "0.54", "size": "200", "side": "BUY", "hash": "2e0d4d45c82d04877723af36ad18ffd709800cdc", "best_bid": "0.992", "best_ask": "0.994"}, {"asset_id": "25265857280574792887110878653665871891927967464924536706348687031929049209739", "price": "0.46", "size": "200", "side": "SELL", "hash": "1dee0c3f0fd68e02c1a0f2209e9146ab5621d7c1", "best_bid": "0.006", "best_ask": "0.008"}], "timestamp": "1769384943920", "event_type": "price_change"}}
{"_local_timestamp": "2026-01-25T23:49:03.990541+00:00", "data": {"market": "0x021e7689a90ac39c268a39ddff6269fd0f41ed84ea6833f6e5b7d900569e6d8b", "price_changes": [{"asset_id": "21609653795728383864795868045140971967534750053984809993030488713671979919753", "price": "0.54", "size": "210", "side": "BUY", "hash": "85a409f2c6cbf8fbb25724aaac38e7d0cfc6b98e", "best_bid": "0.992", "best_ask": "0.994"}, {"asset_id": "25265857280574792887110878653665871891927967464924536706348687031929049209739", "price": "0.46", "size": "210", "side": "SELL", "hash": "68f50f7d3f31bab17761f7c68af93c2e6e970705", "best_bid": "0.006", "best_ask": "0.008"}], "timestamp": "1769384943921", "event_type": "price_change"}}
{"_local_timestamp": "2026-01-25T23:49:04.891778+00:00", "data": {"market": "0x021e7689a90ac39c268a39ddff6269fd0f41ed84ea6833f6e5b7d900569e6d8b", "price_changes": [{"asset_id": "21609653795728383864795868045140971967534750053984809993030488713671979919753", "price": "0.538", "size": "0", "side": "BUY", "hash": "8cf86a299d94fa3744e1633670843d1564e43622", "best_bid": "0.992", "best_ask": "0.994"}, {"asset_id": "25265857280574792887110878653665871891927967464924536706348687031929049209739", "price": "0.462", "size": "0", "side": "SELL", "hash": "c0a58747b1c8889cdcc63f3801e44dff728a4d52", "best_bid": "0.006", "best_ask": "0.008"}], "timestamp": "1769384944821", "event_type": "price_change"}}
{"_local_timestamp": "2026-01-25T23:49:04.917271+00:00", "data": {"market": "0x021e7689a90ac39c268a39ddff6269fd0f41ed84ea6833f6e5b7d900569e6d8b", "price_changes": [{"asset_id": "21609653795728383864795868045140971967534750053984809993030488713671979919753", "price": "0.541", "size": "20", "side": "BUY", "hash": "075381a23d58ed60aa7152cfbcf1febf8e0f0bc4", "best_bid": "0.992", "best_ask": "0.994"}, {"asset_id": "25265857280574792887110878653665871891927967464924536706348687031929049209739", "price": "0.459", "size": "20", "side": "SELL", "hash": "0a9cbb2c38f7cadaec267ac04fa5873e31847bb6", "best_bid": "0.006", "best_ask": "0.008"}], "timestamp": "1769384944848", "event_type": "price_change"}}
{"_local_timestamp": "2026-01-25T23:49:05.364292+00:00", "data": {"market": "0x938e6a0a011f9534ffd2d86c65dde3aeb7c66ad06cee29ead70b832179c3b6de", "price_changes": [{"asset_id": "24797805539254249433781044462430878338801384554813443486130356027573519184087", "price": "0.92", "size": "19.44", "side": "SELL", "hash": "25bac3bd5bbe1823e81da4dda1714f0035b7b1e6", "best_bid": "0.5", "best_ask": "0.52"}, {"asset_id": "84559926953146780213236573115780107039976526543427713229500373094335659185505", "price": "0.08", "size": "19.44", "side": "BUY", "hash": "193682bc64b75e1cd7345abe1e56180b99815d68", "best_bid": "0.48", "best_ask": "0.5"}], "timestamp": "1769384945296", "event_type": "price_change"}}
{"_local_timestamp": "2026-01-25T23:49:07.617013+00:00", "data": {"market": "0x29134729ec74a0dbab6ddad9d9a745e4c0b83c59682bdc4b76412c9635d66627", "price_changes": [{"asset_id": "109408722309726159994284194907981745959708334274938135190768342039858793034476", "price": "0.05", "size": "150", "side": "BUY", "hash": "1183e0e91ec74682ca44736af663bffcac1a0ec2", "best_bid": "0.081", "best_ask": "0.1"}, {"asset_id": "63263918316087383998965771464254486398250019398684443889644959466369157825041", "price": "0.95", "size": "150", "side": "SELL", "hash": "8032e1fa13e7334eeb335fb78bb218d27a1e89a6", "best_bid": "0.9", "best_ask": "0.919"}], "timestamp": "1769384947548", "event_type": "price_change"}}
{"_local_timestamp": "2026-01-25T23:49:08.908740+00:00", "data": {"market": "0x91ebc8bf88c5f99dd4550cb75255766f638d1932ede36e8eae78a76df0c15455", "price_changes": [{"asset_id": "20552877126021963309330960377901114870262231239849696600236708023505406755774", "price": "0.003", "size": "21.95", "side": "BUY", "hash": "84ec2e15efb4b0cb54dae04809c3260ad60fc3a1", "best_bid": "0.024", "best_ask": "0.062"}, {"asset_id": "63365825049551318024252373648592413954954442733807178648368002993460348485956", "price": "0.997", "size": "21.95", "side": "SELL", "hash": "0aba533a0dae65a6bb6ecc942f0755620e7dfd0b", "best_bid": "0.938", "best_ask": "0.976"}], "timestamp": "1769384948837", "event_type": "price_change"}}
{"_local_timestamp": "2026-01-25T23:49:09.381240+00:00", "data": {"market": "0xa087422678cebf674c69d2c86a13b89d153951f067f753e0c2044eb991c0652f", "price_changes": [{"asset_id": "12369294935701377203300019700047987848793450009787501327274207549237196997903", "price": "0.02", "size": "0", "side": "BUY", "hash": "32e762d2c7f1a11f702720a9195d4d02bb3a2a43", "best_bid": "0.11", "best_ask": "0.15"}, {"asset_id": "94297885496428433994612881192883747282447345164360333822514231082582602051560", "price": "0.98", "size": "0", "side": "SELL", "hash": "d99ba5bcec517134df5d05e455eca7923ae362b7", "best_bid": "0.85", "best_ask": "0.89"}], "timestamp": "1769384949306", "event_type": "price_change"}}
{"_local_timestamp": "2026-01-25T23:49:09.381552+00:00", "data": {"market": "0x29134729ec74a0dbab6ddad9d9a745e4c0b83c59682bdc4b76412c9635d66627", "price_changes": [{"asset_id": "109408722309726159994284194907981745959708334274938135190768342039858793034476", "price": "0.002", "size": "7000", "side": "BUY", "hash": "89d600782c1231f01c400daa3ae48d4a50b29a68", "best_bid": "0.081", "best_ask": "0.1"}, {"asset_id": "63263918316087383998965771464254486398250019398684443889644959466369157825041", "price": "0.998", "size": "7000", "side": "SELL", "hash": "11dd4ad303c8b59f157eebd46c9df44ebd5ef0d0", "best_bid": "0.9", "best_ask": "0.919"}], "timestamp": "1769384949306", "event_type": "price_change"}}
{"_local_timestamp": "2026-01-25T23:49:09.381792+00:00", "data": {"market": "0x29134729ec74a0dbab6ddad9d9a745e4c0b83c59682bdc4b76412c9635d66627", "price_changes": [{"asset_id": "109408722309726159994284194907981745959708334274938135190768342039858793034476", "price": "0.006", "size": "0", "side": "BUY", "hash": "89d600782c1231f01c400daa3ae48d4a50b29a68", "best_bid": "0.081", "best_ask": "0.1"}, {"asset_id": "63263918316087383998965771464254486398250019398684443889644959466369157825041", "price": "0.994", "size": "0", "side": "SELL", "hash": "11dd4ad303c8b59f157eebd46c9df44ebd5ef0d0", "best_bid": "0.9", "best_ask": "0.919"}], "timestamp": "1769384949306", "event_type": "price_change"}}
{"_local_timestamp": "2026-01-25T23:49:09.382275+00:00", "data": {"market": "0x29134729ec74a0dbab6ddad9d9a745e4c0b83c59682bdc4b76412c9635d66627", "price_changes": [{"asset_id": "109408722309726159994284194907981745959708334274938135190768342039858793034476", "price": "0.016", "size": "0", "side": "BUY", "hash": "89d600782c1231f01c400daa3ae48d4a50b29a68", "best_bid": "0.081", "best_ask": "0.1"}, {"asset_id": "63263918316087383998965771464254486398250019398684443889644959466369157825041", "price": "0.984", "size": "0", "side": "SELL", "hash": "11dd4ad303c8b59f157eebd46c9df44ebd5ef0d0", "best_bid": "0.9", "best_ask": "0.919"}], "timestamp": "1769384949306", "event_type": "price_change"}}
{"_local_timestamp": "2026-01-25T23:49:10.943656+00:00", "data": {"market": "0x91ebc8bf88c5f99dd4550cb75255766f638d1932ede36e8eae78a76df0c15455", "price_changes": [{"asset_id": "20552877126021963309330960377901114870262231239849696600236708023505406755774", "price": "0.004", "size": "14.08", "side": "BUY", "hash": "b66aaaaae05c3ef1bab725cd9942977486a7687f", "best_bid": "0.024", "best_ask": "0.062"}, {"asset_id": "63365825049551318024252373648592413954954442733807178648368002993460348485956", "price": "0.996", "size": "14.08", "side": "SELL", "hash": "5127f1c13dc0c0a75fde5062ec67f0d41afc6101", "best_bid": "0.938", "best_ask": "0.976"}], "timestamp": "1769384950873", "event_type": "price_change"}}
{"_local_timestamp": "2026-01-25T23:49:19.621679+00:00", "data": {"market": "0x29134729ec74a0dbab6ddad9d9a745e4c0b83c59682bdc4b76412c9635d66627", "price_changes": [{"asset_id": "109408722309726159994284194907981745959708334274938135190768342039858793034476", "price": "0.05", "size": "0", "side": "BUY", "hash": "1838ff4bb3f48c91cb1c6696df02203a6c0b797d", "best_bid": "0.081", "best_ask": "0.1"}, {"asset_id": "63263918316087383998965771464254486398250019398684443889644959466369157825041", "price": "0.95", "size": "0", "side": "SELL", "hash": "e1ed515e02eb181d09c00448819d24faac34c126", "best_bid": "0.9", "best_ask": "0.919"}], "timestamp": "1769384959551", "event_type": "price_change"}}
{"_local_timestamp": "2026-01-25T23:49:25.419923+00:00", "data": {"market": "0x29134729ec74a0dbab6ddad9d9a745e4c0b83c59682bdc4b76412c9635d66627", "price_changes": [{"asset_id": "63263918316087383998965771464254486398250019398684443889644959466369157825041", "price": "0.284", "size": "150", "side": "BUY", "hash": "8e3e2a8c3784126e0e5225589d53ed19d2226620", "best_bid": "0.9", "best_ask": "0.919"}, {"asset_id": "109408722309726159994284194907981745959708334274938135190768342039858793034476", "price": "0.716", "size": "150", "side": "SELL", "hash": "83bf7a0d7455b13b5544eaa2a1fef152611ffa44", "best_bid": "0.081", "best_ask": "0.1"}], "timestamp": "1769384965279", "event_type": "price_change"}}
{"_local_timestamp": "2026-01-25T23:49:26.030487+00:00", "data": {"market": "0x29134729ec74a0dbab6ddad9d9a745e4c0b83c59682bdc4b76412c9635d66627", "price_changes": [{"asset_id": "63263918316087383998965771464254486398250019398684443889644959466369157825041", "price": "0.285", "size": "374", "side": "BUY", "hash": "c45829c5460af940a4c29ed382a9bf8b3df8d026", "best_bid": "0.9", "best_ask": "0.919"}, {"asset_id": "109408722309726159994284194907981745959708334274938135190768342039858793034476", "price": "0.715", "size": "374", "side": "SELL", "hash": "d3613ad4c71c1dfeee0de1211d5217e42708ab21", "best_bid": "0.081", "best_ask": "0.1"}], "timestamp": "1769384965800", "event_type": "price_change"}}
{"_local_timestamp": "2026-01-25T23:49:30.237932+00:00", "data": {"market": "0x29134729ec74a0dbab6ddad9d9a745e4c0b83c59682bdc4b76412c9635d66627", "price_changes": [{"asset_id": "63263918316087383998965771464254486398250019398684443889644959466369157825041", "price": "0.284", "size": "50", "side": "BUY", "hash": "80ae3a8c6979917ee6920a8221c5c6f0899ba5de", "best_bid": "0.9", "best_ask": "0.919"}, {"asset_id": "109408722309726159994284194907981745959708334274938135190768342039858793034476", "price": "0.716", "size": "50", "side": "SELL", "hash": "ef05e69e49da4eaf8658e9dde8d9087e5bf73c7a", "best_bid": "0.081", "best_ask": "0.1"}], "timestamp": "1769384970046", "event_type": "price_change"}}
{"_local_timestamp": "2026-01-25T23:49:31.049623+00:00", "data": {"market": "0x29134729ec74a0dbab6ddad9d9a745e4c0b83c59682bdc4b76412c9635d66627", "price_changes": [{"asset_id": "63263918316087383998965771464254486398250019398684443889644959466369157825041", "price": "0.285", "size": "474", "side": "BUY", "hash": "c76a33e78ab4f2bf95a464a06a6e8d13712fa173", "best_bid": "0.9", "best_ask": "0.919"}, {"asset_id": "109408722309726159994284194907981745959708334274938135190768342039858793034476", "price": "0.715", "size": "474", "side": "SELL", "hash": "cbf875a911a336396779b07a5fc7d10a48c41329", "best_bid": "0.081", "best_ask": "0.1"}], "timestamp": "1769384970654", "event_type": "price_change"}}
{"_local_timestamp": "2026-01-25T23:49:42.052239+00:00", "data": {"market": "0x29134729ec74a0dbab6ddad9d9a745e4c0b83c59682bdc4b76412c9635d66627", "price_changes": [{"asset_id": "63263918316087383998965771464254486398250019398684443889644959466369157825041", "price": "0.284", "size": "0", "side": "BUY", "hash": "92e8500dd24eedbc73810d722218a57e7e05aa46", "best_bid": "0.9", "best_ask": "0.919"}, {"asset_id": "109408722309726159994284194907981745959708334274938135190768342039858793034476", "price": "0.716", "size": "0", "side": "SELL", "hash": "65d8c070961230e56954133e801998896629c4ac", "best_bid": "0.081", "best_ask": "0.1"}], "timestamp": "1769384981896", "event_type": "price_change"}}
{"_local_timestamp": "2026-01-25T23:49:42.284095+00:00", "data": {"market": "0x1cbe7cbbfb481ed76c054bc4c36c6fb966a2d1671d908d0e89e1f22b0adfa1d6", "price_changes": [{"asset_id": "23234069812587403133665543339348944952052706164431007953765598952013802512997", "price": "0.403", "size": "0", "side": "BUY", "hash": "1d5c764cfc0d7739ad1fa3983e1678102560a8b4", "best_bid": "0.992", "best_ask": "0.993"}, {"asset_id": "76756244323959292580621865343466747413597132817678365592077495382609595329059", "price": "0.597", "size": "0", "side": "SELL", "hash": "8615ea033fed189ac478971fbcfdf215bfc3cbf7", "best_bid": "0.007", "best_ask": "0.008"}], "timestamp": "1769384982134", "event_type": "price_change"}}
{"_local_timestamp": "2026-01-25T23:49:42.375920+00:00", "data": {"market": "0x29134729ec74a0dbab6ddad9d9a745e4c0b83c59682bdc4b76412c9635d66627", "price_changes": [{"asset_id": "63263918316087383998965771464254486398250019398684443889644959466369157825041", "price": "0.285", "size": "524", "side": "BUY", "hash": "16ca80d7ed53bc8b57ec11899f96051afdaf47c5", "best_bid": "0.9", "best_ask": "0.919"}, {"asset_id": "109408722309726159994284194907981745959708334274938135190768342039858793034476", "price": "0.715", "size": "524", "side": "SELL", "hash": "da80ff4684624998b970ca3382468442a5f5216d", "best_bid": "0.081", "best_ask": "0.1"}], "timestamp": "1769384982214", "event_type": "price_change"}}
{"_local_timestamp": "2026-01-25T23:49:42.455522+00:00", "data": {"market": "0x1cbe7cbbfb481ed76c054bc4c36c6fb966a2d1671d908d0e89e1f22b0adfa1d6", "price_changes": [{"asset_id": "23234069812587403133665543339348944952052706164431007953765598952013802512997", "price": "0.403", "size": "10", "side": "BUY", "hash": "aba52853d7fe35803517db157c08fc9e93ffb8f1", "best_bid": "0.992", "best_ask": "0.993"}, {"asset_id": "76756244323959292580621865343466747413597132817678365592077495382609595329059", "price": "0.597", "size": "10", "side": "SELL", "hash": "b606bc4b3f4794c4b5c3909518bde5de66a8b60b", "best_bid": "0.007", "best_ask": "0.008"}], "timestamp": "1769384982326", "event_type": "price_change"}}
{"_local_timestamp": "2026-01-25T23:50:18.035807+00:00", "data": {"market": "0xfc64306c19c1faab6dee0e3d3bf4b1ec35599692a11eec762a7f54d25bc268f2", "price_changes": [{"asset_id": "87783727256798391598144762644215659792411859939354027829302503274879035245702", "price": "0.026", "size": "0", "side": "SELL", "hash": "333ba668961eea2b48a4362cbfbee68d3504247b", "best_bid": "0.009", "best_ask": "0.02"}, {"asset_id": "59580829599216932260845656819640492314194305910396233354387067124740172992769", "price": "0.974", "size": "0", "side": "BUY", "hash": "ed4dec6c33862721c2b790e87f420d7c16c6764e", "best_bid": "0.98", "best_ask": "0.991"}], "timestamp": "1769385017926", "event_type": "price_change"}}
{"_local_timestamp": "2026-01-25T23:50:18.169133+00:00", "data": {"market": "0xfdc642275936ee1281df776b1b8a67a35eefbf9095c1266fd178dfa6996ebb4f", "price_changes": [{"asset_id": "55757497654516464627481151189384108294745827872104744655495700337681469992599", "price": "0.542", "size": "0", "side": "BUY", "hash": "6d4eb2e76d8fdf3b3d5148089cd4207062da6498", "best_bid": "0.957", "best_ask": "0.994"}, {"asset_id": "75055518491634343238225754172066804322353911200619603473770017059656868007002", "price": "0.458", "size": "0", "side": "SELL", "hash": "b1ae5d2f3a55a0798591941becf4943e3ef5a0a9", "best_bid": "0.006", "best_ask": "0.043"}], "timestamp": "1769385018031", "event_type": "price_change"}}
{"_local_timestamp": "2026-01-25T23:50:18.263931+00:00", "data": {"market": "0xfdc642275936ee1281df776b1b8a67a35eefbf9095c1266fd178dfa6996ebb4f", "price_changes": [{"asset_id": "55757497654516464627481151189384108294745827872104744655495700337681469992599", "price": "0.546", "size": "10", "side": "BUY", "hash": "cb53f594776281e136ffd0b948255e8eb712be93", "best_bid": "0.957", "best_ask": "0.994"}, {"asset_id": "75055518491634343238225754172066804322353911200619603473770017059656868007002", "price": "0.454", "size": "10", "side": "SELL", "hash": "c562f0b177cfb664911b5b83a19832c451c6daa0", "best_bid": "0.006", "best_ask": "0.043"}], "timestamp": "1769385018146", "event_type": "price_change"}}
{"_local_timestamp": "2026-01-25T23:50:18.355669+00:00", "data": {"market": "0xfdc642275936ee1281df776b1b8a67a35eefbf9095c1266fd178dfa6996ebb4f", "price_changes": [{"asset_id": "55757497654516464627481151189384108294745827872104744655495700337681469992599", "price": "0.55", "size": "30", "side": "BUY", "hash": "0a3b97fcfd0c84d4cefa0284544cf3ff77f1c1ab", "best_bid": "0.957", "best_ask": "0.994"}, {"asset_id": "75055518491634343238225754172066804322353911200619603473770017059656868007002", "price": "0.45", "size": "30", "side": "SELL", "hash": "d7cdc9d864947d71d0ecb6754b996d9feedc571d", "best_bid": "0.006", "best_ask": "0.043"}], "timestamp": "1769385018249", "event_type": "price_change"}}
{"_local_timestamp": "2026-01-25T23:50:18.398228+00:00", "data": {"market": "0xfdc642275936ee1281df776b1b8a67a35eefbf9095c1266fd178dfa6996ebb4f", "price_changes": [{"asset_id": "55757497654516464627481151189384108294745827872104744655495700337681469992599", "price": "0.544", "size": "0", "side": "BUY", "hash": "7b373842b3ee0ab7329d6b5b6d25c186def2c76c", "best_bid": "0.957", "best_ask": "0.994"}, {"asset_id": "75055518491634343238225754172066804322353911200619603473770017059656868007002", "price": "0.456", "size": "0", "side": "SELL", "hash": "597f0f404b4d4a46b9ff606b188b5b3a70c7d532", "best_bid": "0.006", "best_ask": "0.043"}], "timestamp": "1769385018298", "event_type": "price_change"}}
{"_local_timestamp": "2026-01-25T23:50:18.398558+00:00", "data": {"market": "0x021e7689a90ac39c268a39ddff6269fd0f41ed84ea6833f6e5b7d900569e6d8b", "price_changes": [{"asset_id": "21609653795728383864795868045140971967534750053984809993030488713671979919753", "price": "0.535", "size": "0", "side": "BUY", "hash": "2ba3f2647ecd318de07d5ddf845c15992818ad96", "best_bid": "0.992", "best_ask": "0.994"}, {"asset_id": "25265857280574792887110878653665871891927967464924536706348687031929049209739", "price": "0.465", "size": "0", "side": "SELL", "hash": "6a26ed3de228e380a56963bea3fca496bd631734", "best_bid": "0.006", "best_ask": "0.008"}], "timestamp": "1769385018298", "event_type": "price_change"}}
{"_local_timestamp": "2026-01-25T23:50:18.525781+00:00", "data": {"market": "0xfdc642275936ee1281df776b1b8a67a35eefbf9095c1266fd178dfa6996ebb4f", "price_changes": [{"asset_id": "55757497654516464627481151189384108294745827872104744655495700337681469992599", "price": "0.551", "size": "40", "side": "BUY", "hash": "f4ae83c3ab15beb8ec09e15dcbaa75c0cfaff569", "best_bid": "0.957", "best_ask": "0.994"}, {"asset_id": "75055518491634343238225754172066804322353911200619603473770017059656868007002", "price": "0.449", "size": "40", "side": "SELL", "hash": "7decd4614339bcfef27f5db718f4828df6d7b9c0", "best_bid": "0.006", "best_ask": "0.043"}], "timestamp": "1769385018434", "event_type": "price_change"}}
{"_local_timestamp": "2026-01-25T23:50:18.526050+00:00", "data": {"market": "0x021e7689a90ac39c268a39ddff6269fd0f41ed84ea6833f6e5b7d900569e6d8b", "price_changes": [{"asset_id": "21609653795728383864795868045140971967534750053984809993030488713671979919753", "price": "0.542", "size": "40", "side": "BUY", "hash": "aa9a332b79a41310aaa3c9f902c35aca100384e1", "best_bid": "0.992", "best_ask": "0.994"}, {"asset_id": "25265857280574792887110878653665871891927967464924536706348687031929049209739", "price": "0.458", "size": "40", "side": "SELL", "hash": "193403cd3de6299ad1a722d8c78e61cab9723203", "best_bid": "0.006", "best_ask": "0.008"}], "timestamp": "1769385018434", "event_type": "price_change"}}
{"_local_timestamp": "2026-01-25T23:50:18.686518+00:00", "data": {"market": "0x021e7689a90ac39c268a39ddff6269fd0f41ed84ea6833f6e5b7d900569e6d8b", "price_changes": [{"asset_id": "21609653795728383864795868045140971967534750053984809993030488713671979919753", "price": "0.539", "size": "10", "side": "BUY", "hash": "e84d16fb15424fb36dc346d775f210881c343591", "best_bid": "0.992", "best_ask": "0.994"}, {"asset_id": "25265857280574792887110878653665871891927967464924536706348687031929049209739", "price": "0.461", "size": "10", "side": "SELL", "hash": "afc80a4fc6295a5b5cf4352317328689edaf07c5", "best_bid": "0.006", "best_ask": "0.008"}], "timestamp": "1769385018569", "event_type": "price_change"}}
{"_local_timestamp": "2026-01-25T23:50:18.750128+00:00", "data": {"market": "0xfdc642275936ee1281df776b1b8a67a35eefbf9095c1266fd178dfa6996ebb4f", "price_changes": [{"asset_id": "55757497654516464627481151189384108294745827872104744655495700337681469992599", "price": "0.546", "size": "0", "side": "BUY", "hash": "8a6e557178a8341596f86bb72f949721cdcfc2b0", "best_bid": "0.957", "best_ask": "0.994"}, {"asset_id": "75055518491634343238225754172066804322353911200619603473770017059656868007002", "price": "0.454", "size": "0", "side": "SELL", "hash": "ac0a53f0eb475d5bb9a6713732e2b5dc4cd509ce", "best_bid": "0.006", "best_ask": "0.043"}], "timestamp": "1769385018654", "event_type": "price_change"}}
{"_local_timestamp": "2026-01-25T23:50:18.962399+00:00", "data": {"market": "0xfdc642275936ee1281df776b1b8a67a35eefbf9095c1266fd178dfa6996ebb4f", "price_changes": [{"asset_id": "55757497654516464627481151189384108294745827872104744655495700337681469992599", "price": "0.552", "size": "10", "side": "BUY", "hash": "b13e141872ef1b9a7d2996f682e6d2381780f43d", "best_bid": "0.957", "best_ask": "0.994"}, {"asset_id": "75055518491634343238225754172066804322353911200619603473770017059656868007002", "price": "0.448", "size": "10", "side": "SELL", "hash": "27450627c71516c02dabe32850056d52cd3f6d77", "best_bid": "0.006", "best_ask": "0.043"}], "timestamp": "1769385018869", "event_type": "price_change"}}
{"_local_timestamp": "2026-01-25T23:50:18.968533+00:00", "data": {"market": "0xfdc642275936ee1281df776b1b8a67a35eefbf9095c1266fd178dfa6996ebb4f", "price_changes": [{"asset_id": "55757497654516464627481151189384108294745827872104744655495700337681469992599", "price": "0.552", "size": "25", "side": "BUY", "hash": "70c4127f44de92053582fe2002b9e56e6948599f", "best_bid": "0.957", "best_ask": "0.994"}, {"asset_id": "75055518491634343238225754172066804322353911200619603473770017059656868007002", "price": "0.448", "size": "25", "side": "SELL", "hash": "0916f5d4d82fc3e0f1ab96134fdf74ce879cb12c", "best_bid": "0.006", "best_ask": "0.043"}], "timestamp": "1769385018870", "event_type": "price_change"}}
{"_local_timestamp": "2026-01-25T23:50:19.388925+00:00", "data": {"market": "0xfc64306c19c1faab6dee0e3d3bf4b1ec35599692a11eec762a7f54d25bc268f2", "price_changes": [{"asset_id": "87783727256798391598144762644215659792411859939354027829302503274879035245702", "price": "0.026", "size": "14.75", "side": "SELL", "hash": "2e7234bd913b0d9b2f4b45a7b3457902fcbb127d", "best_bid": "0.009", "best_ask": "0.02"}, {"asset_id": "59580829599216932260845656819640492314194305910396233354387067124740172992769", "price": "0.974", "size": "14.75", "side": "BUY", "hash": "f137c3f04d5cdb904c2fc5d43ff11b0443adc6a0", "best_bid": "0.98", "best_ask": "0.991"}], "timestamp": "1769385019298", "event_type": "price_change"}}
{"_local_timestamp": "2026-01-25T23:50:20.915125+00:00", "data": {"market": "0xfdc642275936ee1281df776b1b8a67a35eefbf9095c1266fd178dfa6996ebb4f", "price_changes": [{"asset_id": "55757497654516464627481151189384108294745827872104744655495700337681469992599", "price": "0.549", "size": "0", "side": "BUY", "hash": "8ab7bf927d90d61b1052d2ebf08ba964e4055852", "best_bid": "0.957", "best_ask": "0.994"}, {"asset_id": "75055518491634343238225754172066804322353911200619603473770017059656868007002", "price": "0.451", "size": "0", "side": "SELL", "hash": "11ed12304d1f703c1c1a2c7e731ec6fc2f89244d", "best_bid": "0.006", "best_ask": "0.043"}], "timestamp": "1769385020820", "event_type": "price_change"}}
{"_local_timestamp": "2026-01-25T23:50:20.915462+00:00", "data": {"market": "0x021e7689a90ac39c268a39ddff6269fd0f41ed84ea6833f6e5b7d900569e6d8b", "price_changes": [{"asset_id": "21609653795728383864795868045140971967534750053984809993030488713671979919753", "price": "0.541", "size": "0", "side": "BUY", "hash": "d1432dd547a4af9083430b2594d1cc6cc9671cc2", "best_bid": "0.992", "best_ask": "0.994"}, {"asset_id": "25265857280574792887110878653665871891927967464924536706348687031929049209739", "price": "0.459", "size": "0", "side": "SELL", "hash": "b09d6043ccfe0d240c7e3949cab7bfed71db0a01", "best_bid": "0.006", "best_ask": "0.008"}], "timestamp": "1769385020820", "event_type": "price_change"}}
{"_local_timestamp": "2026-01-25T23:50:20.947053+00:00", "data": {"market": "0xfdc642275936ee1281df776b1b8a67a35eefbf9095c1266fd178dfa6996ebb4f", "price_changes": [{"asset_id": "55757497654516464627481151189384108294745827872104744655495700337681469992599", "price": "0.553", "size": "20", "side": "BUY", "hash": "486a0b6c557c9bdf7460f9d62a739130c6a95446", "best_bid": "0.957", "best_ask": "0.994"}, {"asset_id": "75055518491634343238225754172066804322353911200619603473770017059656868007002", "price": "0.447", "size": "20", "side": "SELL", "hash": "09c2c3e61f902b774a9999cc8a3da656967a4dce", "best_bid": "0.006", "best_ask": "0.043"}], "timestamp": "1769385020851", "event_type": "price_change"}}
{"_local_timestamp": "2026-01-25T23:50:20.947354+00:00", "data": {"market": "0x021e7689a90ac39c268a39ddff6269fd0f41ed84ea6833f6e5b7d900569e6d8b", "price_changes": [{"asset_id": "21609653795728383864795868045140971967534750053984809993030488713671979919753", "price": "0.543", "size": "20", "side": "BUY", "hash": "c7527d85dc9deb547576817f2dc299402d73bd43", "best_bid": "0.992", "best_ask": "0.994"}, {"asset_id": "25265857280574792887110878653665871891927967464924536706348687031929049209739", "price": "0.457", "size": "20", "side": "SELL", "hash": "2677e553fc00c3c49cfe2c9f2ea51bd9c4ce92f8", "best_bid": "0.006", "best_ask": "0.008"}], "timestamp": "1769385020852", "event_type": "price_change"}}
{"_local_timestamp": "2026-01-25T23:50:58.072187+00:00", "data": {"market": "0x1cbe7cbbfb481ed76c054bc4c36c6fb966a2d1671d908d0e89e1f22b0adfa1d6", "price_changes": [{"asset_id": "76756244323959292580621865343466747413597132817678365592077495382609595329059", "price": "0.001", "size": "67817", "side": "BUY", "hash": "f97bf0158987e83e8e14aee1b77e80e2e014a066", "best_bid": "0.007", "best_ask": "0.008"}, {"asset_id": "23234069812587403133665543339348944952052706164431007953765598952013802512997", "price": "0.999", "size": "67817", "side": "SELL", "hash": "bf7f2d10afb6777062b917a240d8d08fc48ad9f5", "best_bid": "0.992", "best_ask": "0.993"}], "timestamp": "1769385058000", "event_type": "price_change"}}
{"_local_timestamp": "2026-01-25T23:50:58.095260+00:00", "data": {"market": "0x1cbe7cbbfb481ed76c054bc4c36c6fb966a2d1671d908d0e89e1f22b0adfa1d6", "price_changes": [{"asset_id": "23234069812587403133665543339348944952052706164431007953765598952013802512997", "price": "0.987", "size": "0", "side": "BUY", "hash": "482a3525934d5204e6aad6eb8dd0cab687240909", "best_bid": "0.992", "best_ask": "0.993"}, {"asset_id": "76756244323959292580621865343466747413597132817678365592077495382609595329059", "price": "0.013", "size": "0", "side": "SELL", "hash": "dfe93d90cdaf1c72940aa20b19be52bbccea72db", "best_bid": "0.007", "best_ask": "0.008"}], "timestamp": "1769385058003", "event_type": "price_change"}}
{"_local_timestamp": "2026-01-25T23:50:58.153653+00:00", "data": {"market": "0x3936de01f890af302ca75727b772fe6dffe915ce638a08809042a3a81dd346c0", "price_changes": [{"asset_id": "93832008664246723386944798388205104088345581837255215982492503205563374375162", "price": "0.417", "size": "0", "side": "BUY", "hash": "bf85642793f989644205dddd39c80764893abfc9", "best_bid": "0.971", "best_ask": "0.991"}, {"asset_id": "68682941687946159092109471523402081762244652970943030009984394444937274201240", "price": "0.583", "size": "0", "side": "SELL", "hash": "2b934894d475334a85cbb20f65865114b2a8bb3c", "best_bid": "0.009", "best_ask": "0.029"}], "timestamp": "1769385058053", "event_type": "price_change"}}
{"_local_timestamp": "2026-01-25T23:50:58.267188+00:00", "data": {"market": "0x3936de01f890af302ca75727b772fe6dffe915ce638a08809042a3a81dd346c0", "price_changes": [{"asset_id": "93832008664246723386944798388205104088345581837255215982492503205563374375162", "price": "0.419", "size": "10", "side": "BUY", "hash": "3490dc3caf46022567c76ed410e07e2bcf931a4d", "best_bid": "0.971", "best_ask": "0.991"}, {"asset_id": "68682941687946159092109471523402081762244652970943030009984394444937274201240", "price": "0.581", "size": "10", "side": "SELL", "hash": "56aaa55244be3e76ffde372c5bd909e0a7540fac", "best_bid": "0.009", "best_ask": "0.029"}], "timestamp": "1769385058187", "event_type": "price_change"}}
{"_local_timestamp": "2026-01-25T23:51:08.331106+00:00", "data": {"market": "0x1cbe7cbbfb481ed76c054bc4c36c6fb966a2d1671d908d0e89e1f22b0adfa1d6", "price_changes": [{"asset_id": "23234069812587403133665543339348944952052706164431007953765598952013802512997", "price": "0.402", "size": "0", "side": "BUY", "hash": "96319f125da555da30db7fb3a70d71fb8a10f878", "best_bid": "0.992", "best_ask": "0.993"}, {"asset_id": "76756244323959292580621865343466747413597132817678365592077495382609595329059", "price": "0.598", "size": "0", "side": "SELL", "hash": "2ba4aad914a90f58a947aca4ed8e380df8e82eb1", "best_bid": "0.007", "best_ask": "0.008"}], "timestamp": "1769385068260", "event_type": "price_change"}}
