{"_local_timestamp": "2026-01-25T23:41:17.880965+00:00", "data": [{"market": "0xa3cf11c4cd5c39be6af763782278dd2ae871286e50413c736fc02e378c7b194a", "asset_id": "47098692578463382240924923935626520236879739693617300734585244751793795800081", "timestamp": "1769384474532", "hash": "3edb78a2f186b41dd72cb1f62690353601b584e3", "bids": [{"price": "0.01", "size": "2063.99"}, {"price": "0.02", "size": "256.14"}, {"price": "0.03", "size": "34.93"}, {"price": "0.08", "size": "93"}, {"price": "0.09", "size": "112"}, {"price": "0.1", "size": "6"}, {"price": "0.11", "size": "1000"}, {"price": "0.15", "size": "500"}, {"price": "0.16", "size": "398.8"}, {"price": "0.17", "size": "30"}, {"price": "0.2", "size": "8.5"}, {"price": "0.21", "size": "10"}, {"price": "0.22", "size": "500"}, {"price": "0.24", "size": "180"}], "asks": [{"price": "0.99", "size": "2217.49"}, {"price": "0.98", "size": "1405.26"}, {"price": "0.97", "size": "17.72"}, {"price": "0.95", "size": "20"}, {"price": "0.93", "size": "300"}, {"price": "0.92", "size": "6.23"}, {"price": "0.9", "size": "200"}, {"price": "0.87", "size": "3030"}, {"price": "0.84", "size": "400"}, {"price": "0.83", "size": "20"}, {"price": "0.8", "size": "5"}, {"price": "0.76", "size": "268"}, {"price": "0.72", "size": "150"}, {"price": "0.61", "size": "196.45"}, {"price": "0.55", "size": "26.4"}, {"price": "0.5", "size": "5"}, {"price": "0.48", "size": "21.15"}, {"price": "0.47", "size": "125"}, {"price": "0.4", "size": "5"}, {"price": "0.39", "size": "10"}, {"price": "0.36", "size": "20.31"}, {"price": "0.35", "size": "67.95"}, {"price": "0.34", "size": "5"}], "event_type": "book", "last_trade_price": "0.200"}, {"market": "0xa3cf11c4cd5c39be6af763782278dd2ae871286e50413c736fc02e378c7b194a", "asset_id": "115499136196208654254049968774021214764893087674315074576157301876433223848835", "timestamp": "1769384474532", "hash": "2ba54b969d4465f8bd0c3afae8b552a080a3708e", "bids": [{"price": "0.01", "size": "2217.49"}, {"price": "0.02", "size": "1405.26"}, {"price": "0.03", "size": "17.72"}, {"price": "0.05", "size": "20"}, {"price": "0.07", "size": "300"}, {"price": "0.08", "size": "6.23"}, {"price": "0.1", "size": "200"}, {"price": "0.13", "size": "3030"}, {"price": "0.16", "size": "400"}, {"price": "0.17", "size": "20"}, {"price": "0.2", "size": "5"}, {"price": "0.24", "size": "268"}, {"price": "0.28", "size": "150"}, {"price": "0.39", "size": "196.45"}, {"price": "0.45", "size": "26.4"}, {"price": "0.5", "size": "5"}, {"price": "0.52", "size": "21.15"}, {"price": "0.53", "size": "125"}, {"price": "0.6", "size": "5"}, {"price": "0.61", "size": "10"}, {"price": "0.64", "size": "20.31"}, {"price": "0.65", "size": "67.95"}, {"price": "0.66", "size": "5"}], "asks": [{"price": "0.99", "size": "2063.99"}, {"price": "0.98", "size": "256.14"}, {"price": "0.97", "size": "34.93"}, {"price": "0.92", "size": "93"}, {"price": "0.91", "size": "112"}, {"price": "0.9", "size": "6"}, {"price": "0.89", "size": "1000"}, {"price": "0.85", "size": "500"}, {"price": "0.84", "size": "398.8"}, {"price": "0.83", "size": "30"}, {"price": "0.8", "size": "8.5"}, {"price": "0.79", "size": "10"}, {"price": "0.78", "size": "500"}, {"price": "0.76", "size": "180"}], "event_type": "book", "last_trade_price": "0.200"}]}
{"_local_timestamp": "2026-01-25T23:41:21.057998+00:00", "data": {"market": "0xa3cf11c4cd5c39be6af763782278dd2ae871286e50413c736fc02e378c7b194a", "price_changes": [{"asset_id": "115499136196208654254049968774021214764893087674315074576157301876433223848835", "price": "0.11", "size": "3818", "side": "BUY", "hash": "eeeeb9a9395d8a3bfb85475a661be6de75e49b30", "best_bid": "0.66", "best_ask": "0.76"}, {"asset_id": "47098692578463382240924923935626520236879739693617300734585244751793795800081", "price": "0.89", "size": "3818", "side": "SELL", "hash": "1fbe76a9c1f4c20e4ca15a87b960fa7d20165f95", "best_bid": "0.24", "best_ask": "0.34"}], "timestamp": "1769384480988", "event_type": "price_change"}}
{"_local_timestamp": "2026-01-25T23:41:50.790307+00:00", "data": {"market": "0xa3cf11c4cd5c39be6af763782278dd2ae871286e50413c736fc02e378c7b194a", "price_changes": [{"asset_id": "115499136196208654254049968774021214764893087674315074576157301876433223848835", "price": "0.07", "size": "0", "side": "BUY", "hash": "e03d47a472539c7d2c69ec91361c46d2f299052b", "best_bid": "0.66", "best_ask": "0.76"}, {"asset_id": "47098692578463382240924923935626520236879739693617300734585244751793795800081", "price": "0.93", "size": "0", "side": "SELL", "hash": "727dd5b5322e85230b4b15027b28c0184b3cee0c", "best_bid": "0.24", "best_ask": "0.34"}], "timestamp": "1769384510719", "event_type": "price_change"}}
{"_local_timestamp": "2026-01-25T23:41:52.918836+00:00", "data": {"market": "0xa3cf11c4cd5c39be6af763782278dd2ae871286e50413c736fc02e378c7b194a", "price_changes": [{"asset_id": "115499136196208654254049968774021214764893087674315074576157301876433223848835", "price": "0.1", "size": "500", "side": "BUY", "hash": "32b12a1735de91989e557fa395cae4c27be3f747", "best_bid": "0.66", "best_ask": "0.76"}, {"asset_id": "47098692578463382240924923935626520236879739693617300734585244751793795800081", "price": "0.9", "size": "500", "side": "SELL", "hash": "9a26dc51bb4fe87f2f3179040d96c9aec3fa0947", "best_bid": "0.24", "best_ask": "0.34"}], "timestamp": "1769384511848", "event_type": "price_change"}}
{"_local_timestamp": "2026-01-25T23:42:25.101015+00:00", "data": {"market": "0xa3cf11c4cd5c39be6af763782278dd2ae871286e50413c736fc02e378c7b194a", "price_changes": [{"asset_id": "115499136196208654254049968774021214764893087674315074576157301876433223848835", "price": "0.13", "size": "2805", "side": "BUY", "hash": "3517f5198a5f8c633587703ded46d83fe52437ba", "best_bid": "0.66", "best_ask": "0.76"}, {"asset_id": "47098692578463382240924923935626520236879739693617300734585244751793795800081", "price": "0.87", "size": "2805", "side": "SELL", "hash": "9c5ba7ebea8a1a673647ef66debb73e111fc38be", "best_bid": "0.24", "best_ask": "0.34"}], "timestamp": "1769384544877", "event_type": "price_change"}}
{"_local_timestamp": "2026-01-25T23:42:25.355921+00:00", "data": {"market": "0xa3cf11c4cd5c39be6af763782278dd2ae871286e50413c736fc02e378c7b194a", "price_changes": [{"asset_id": "115499136196208654254049968774021214764893087674315074576157301876433223848835", "price": "0.11", "size": "4043", "side": "BUY", "hash": "0fdedff901a7170538a76ca036b212134af42460", "best_bid": "0.66", "best_ask": "0.76"}, {"asset_id": "47098692578463382240924923935626520236879739693617300734585244751793795800081", "price": "0.89", "size": "4043", "side": "SELL", "hash": "eb021052bef0f542ae269084d7751c8cb540335e", "best_bid": "0.24", "best_ask": "0.34"}], "timestamp": "1769384545146", "event_type": "price_change"}}
{"_local_timestamp": "2026-01-25T23:42:40.322403+00:00", "data": {"market": "0xa3cf11c4cd5c39be6af763782278dd2ae871286e50413c736fc02e378c7b194a", "price_changes": [{"asset_id": "115499136196208654254049968774021214764893087674315074576157301876433223848835", "price": "0.03", "size": "0", "side": "BUY", "hash": "6f4a3c41852688a7399a0f2fae6e69238660d9e9", "best_bid": "0.66", "best_ask": "0.76"}, {"asset_id": "47098692578463382240924923935626520236879739693617300734585244751793795800081", "price": "0.97", "size": "0", "side": "SELL", "hash": "ea4cccfc468dd6b99f38311047c9c99343972796", "best_bid": "0.24", "best_ask": "0.34"}], "timestamp": "1769384560019", "event_type": "price_change"}}
{"_local_timestamp": "2026-01-25T23:42:40.322773+00:00", "data": {"market": "0xa3cf11c4cd5c39be6af763782278dd2ae871286e50413c736fc02e378c7b194a", "price_changes": [{"asset_id": "115499136196208654254049968774021214764893087674315074576157301876433223848835", "price": "0.08", "size": "0", "side": "BUY", "hash": "6f4a3c41852688a7399a0f2fae6e69238660d9e9", "best_bid": "0.66", "best_ask": "0.76"}, {"asset_id": "47098692578463382240924923935626520236879739693617300734585244751793795800081", "price": "0.92", "size": "0", "side": "SELL", "hash": "ea4cccfc468dd6b99f38311047c9c99343972796", "best_bid": "0.24", "best_ask": "0.34"}], "timestamp": "1769384560019", "event_type": "price_change"}}
{"_local_timestamp": "2026-01-25T23:42:40.524246+00:00", "data": {"market": "0xa3cf11c4cd5c39be6af763782278dd2ae871286e50413c736fc02e378c7b194a", "price_changes": [{"asset_id": "115499136196208654254049968774021214764893087674315074576157301876433223848835", "price": "0.04", "size": "5.34", "side": "BUY", "hash": "c0c0b82b5a5d63c8c9122a555fa684a4bbbed6d7", "best_bid": "0.66", "best_ask": "0.76"}, {"asset_id": "47098692578463382240924923935626520236879739693617300734585244751793795800081", "price": "0.96", "size": "5.34", "side": "SELL", "hash": "6536f7a86dddc2dae2d287cb59978d2654826d7f", "best_bid": "0.24", "best_ask": "0.34"}], "timestamp": "1769384560392", "event_type": "price_change"}}
{"_local_timestamp": "2026-01-25T23:42:40.533955+00:00", "data": {"market": "0xa3cf11c4cd5c39be6af763782278dd2ae871286e50413c736fc02e378c7b194a", "price_changes": [{"asset_id": "115499136196208654254049968774021214764893087674315074576157301876433223848835", "price": "0.06", "size": "11.44", "side": "BUY", "hash": "d205753a28fd09ad65f925c09bd7f5503edece67", "best_bid": "0.66", "best_ask": "0.76"}, {"asset_id": "47098692578463382240924923935626520236879739693617300734585244751793795800081", "price": "0.94", "size": "11.44", "side": "SELL", "hash": "3160392ed30789f9f47ce09d1c6296fce93cf141", "best_bid": "0.24", "best_ask": "0.34"}], "timestamp": "1769384560401", "event_type": "price_change"}}
{"_local_timestamp": "2026-01-25T23:42:40.545419+00:00", "data": {"market": "0xa3cf11c4cd5c39be6af763782278dd2ae871286e50413c736fc02e378c7b194a", "price_changes": [{"asset_id": "115499136196208654254049968774021214764893087674315074576157301876433223848835", "price": "0.02", "size": "1411.7", "side": "BUY", "hash": "30ee58f08c4e307084c9ae05425d50fe180c90c0", "best_bid": "0.66", "best_ask": "0.76"}, {"asset_id": "47098692578463382240924923935626520236879739693617300734585244751793795800081", "price": "0.98", "size": "1411.7", "side": "SELL", "hash": "d889937d08e9a773be19d0027fc46be968a3488e", "best_bid": "0.24", "best_ask": "0.34"}], "timestamp": "1769384560407", "event_type": "price_change"}}
{"_local_timestamp": "2026-01-25T23:43:45.136551+00:00", "data": {"market": "0xa3cf11c4cd5c39be6af763782278dd2ae871286e50413c736fc02e378c7b194a", "price_changes": [{"asset_id": "47098692578463382240924923935626520236879739693617300734585244751793795800081", "price": "0.01", "size": "63.99", "side": "BUY", "hash": "31b4c4773ae57babff581e4e42ad046d70b3a5eb", "best_bid": "0.24", "best_ask": "0.34"}, {"asset_id": "115499136196208654254049968774021214764893087674315074576157301876433223848835", "price": "0.99", "size": "63.99", "side": "SELL", "hash": "4f06b7e34aa8320d240d43b20b2d33392f7f2153", "best_bid": "0.66", "best_ask": "0.76"}], "timestamp": "1769384625001", "event_type": "price_change"}}
{"_local_timestamp": "2026-01-25T23:43:45.141323+00:00", "data": {"market": "0xa3cf11c4cd5c39be6af763782278dd2ae871286e50413c736fc02e378c7b194a", "price_changes": [{"asset_id": "47098692578463382240924923935626520236879739693617300734585244751793795800081", "price": "0.09", "size": "0", "side": "BUY", "hash": "9e7a8b8de427c2c2988d6a27837f7ce4479a4515", "best_bid": "0.24", "best_ask": "0.34"}, {"asset_id": "115499136196208654254049968774021214764893087674315074576157301876433223848835", "price": "0.91", "size": "0", "side": "SELL", "hash": "110e98a8762ef8e4ac257191d8f68fafe1fdc24d", "best_bid": "0.66", "best_ask": "0.76"}], "timestamp": "1769384625002", "event_type": "price_change"}}
{"_local_timestamp": "2026-01-25T23:43:54.233322+00:00", "data": {"market": "0xa3cf11c4cd5c39be6af763782278dd2ae871286e50413c736fc02e378c7b194a", "price_changes": [{"asset_id": "115499136196208654254049968774021214764893087674315074576157301876433223848835", "price": "0.02", "size": "1405.26", "side": "BUY", "hash": "d9e6a9b365f3c15f943a65c13410a3cd054b6f9f", "best_bid": "0.66", "best_ask": "0.76"}, {"asset_id": "47098692578463382240924923935626520236879739693617300734585244751793795800081", "price": "0.98", "size": "1405.26", "side": "SELL", "hash": "ddbe936e0912cdbcb8ac82984fe8cee1311f152d", "best_bid": "0.24", "best_ask": "0.34"}], "timestamp": "1769384633999", "event_type": "price_change"}}
{"_local_timestamp": "2026-01-25T23:43:54.234371+00:00", "data": {"market": "0xa3cf11c4cd5c39be6af763782278dd2ae871286e50413c736fc02e378c7b194a", "price_changes": [{"asset_id": "115499136196208654254049968774021214764893087674315074576157301876433223848835", "price": "0.04", "size": "0", "side": "BUY", "hash": "d9e6a9b365f3c15f943a65c13410a3cd054b6f9f", "best_bid": "0.66", "best_ask": "0.76"}, {"asset_id": "47098692578463382240924923935626520236879739693617300734585244751793795800081", "price": "0.96", "size": "0", "side": "SELL", "hash": "ddbe936e0912cdbcb8ac82984fe8cee1311f152d", "best_bid": "0.24", "best_ask": "0.34"}], "timestamp": "1769384633999", "event_type": "price_change"}}
{"_local_timestamp": "2026-01-25T23:43:54.625373+00:00", "data": {"market": "0xa3cf11c4cd5c39be6af763782278dd2ae871286e50413c736fc02e378c7b194a", "price_changes": [{"asset_id": "115499136196208654254049968774021214764893087674315074576157301876433223848835", "price": "0.03", "size": "11.43", "side": "BUY", "hash": "6ee4f9669526badc19a140a8f60998a015274ff1", "best_bid": "0.66", "best_ask": "0.76"}, {"asset_id": "47098692578463382240924923935626520236879739693617300734585244751793795800081", "price": "0.97", "size": "11.43", "side": "SELL", "hash": "650770a2bb5e00878341d0f50534eaa2c4a7ab00", "best_bid": "0.24", "best_ask": "0.34"}], "timestamp": "1769384634385", "event_type": "price_change"}}
{"_local_timestamp": "2026-01-25T23:44:08.698289+00:00", "data": {"market": "0xa3cf11c4cd5c39be6af763782278dd2ae871286e50413c736fc02e378c7b194a", "price_changes": [{"asset_id": "115499136196208654254049968774021214764893087674315074576157301876433223848835", "price": "0.13", "size": "2680", "side": "BUY", "hash": "f4a376a94080e963473a2dd7514dcbbbcd27641b", "best_bid": "0.66", "best_ask": "0.76"}, {"asset_id": "47098692578463382240924923935626520236879739693617300734585244751793795800081", "price": "0.87", "size": "2680", "side": "SELL", "hash": "81d7952555aeab9b4de76825ad69dd3232844203", "best_bid": "0.24", "best_ask": "0.34"}], "timestamp": "1769384648347", "event_type": "price_change"}}
{"_local_timestamp": "2026-01-25T23:44:09.161873+00:00", "data": {"market": "0xa3cf11c4cd5c39be6af763782278dd2ae871286e50413c736fc02e378c7b194a", "price_changes": [{"asset_id": "115499136196208654254049968774021214764893087674315074576157301876433223848835", "price": "0.11", "size": "4168", "side": "BUY", "hash": "cf43085959d575a5cd6135c6789fec34b91ef3c1", "best_bid": "0.66", "best_ask": "0.76"}, {"asset_id": "47098692578463382240924923935626520236879739693617300734585244751793795800081", "price": "0.89", "size": "4168", "side": "SELL", "hash": "52b7f7c43bcdaee48a2d49d5b546953618430bb2", "best_bid": "0.24", "best_ask": "0.34"}], "timestamp": "1769384648722", "event_type": "price_change"}}
{"_local_timestamp": "2026-01-25T23:44:20.559296+00:00", "data": {"market": "0xa3cf11c4cd5c39be6af763782278dd2ae871286e50413c736fc02e378c7b194a", "price_changes": [{"asset_id": "115499136196208654254049968774021214764893087674315074576157301876433223848835", "price": "0.13", "size": "2480", "side": "BUY", "hash": "3b73f08185116ad296da218e03a85a5ffe761235", "best_bid": "0.66", "best_ask": "0.76"}, {"asset_id": "47098692578463382240924923935626520236879739693617300734585244751793795800081", "price": "0.87", "size": "2480", "side": "SELL", "hash": "3b22930c1e1b475680195545242556ba212b4566", "best_bid": "0.24", "best_ask": "0.34"}], "timestamp": "1769384660463", "event_type": "price_change"}}
{"_local_timestamp": "2026-01-25T23:44:20.568536+00:00", "data": {"market": "0xa3cf11c4cd5c39be6af763782278dd2ae871286e50413c736fc02e378c7b194a", "price_changes": [{"asset_id": "115499136196208654254049968774021214764893087674315074576157301876433223848835", "price": "0.1", "size": "200", "side": "BUY", "hash": "3b73f08185116ad296da218e03a85a5ffe761235", "best_bid": "0.66", "best_ask": "0.76"}, {"asset_id": "47098692578463382240924923935626520236879739693617300734585244751793795800081", "price": "0.9", "size": "200", "side": "SELL", "hash": "3b22930c1e1b475680195545242556ba212b4566", "best_bid": "0.24", "best_ask": "0.34"}], "timestamp": "1769384660463", "event_type": "price_change"}}
{"_local_timestamp": "2026-01-25T23:44:21.204812+00:00", "data": {"market": "0xa3cf11c4cd5c39be6af763782278dd2ae871286e50413c736fc02e378c7b194a", "price_changes": [{"asset_id": "115499136196208654254049968774021214764893087674315074576157301876433223848835", "price": "0.11", "size": "4368", "side": "BUY", "hash": "ebee34d835585598e6d1470edb4bba9c9832d610", "best_bid": "0.66", "best_ask": "0.76"}, {"asset_id": "47098692578463382240924923935626520236879739693617300734585244751793795800081", "price": "0.89", "size": "4368", "side": "SELL", "hash": "0fb75b0510d693f0b9a20a70639d383f7e3c1c3e", "best_bid": "0.24", "best_ask": "0.34"}], "timestamp": "1769384660832", "event_type": "price_change"}}
{"_local_timestamp": "2026-01-25T23:44:21.487173+00:00", "data": {"market": "0xa3cf11c4cd5c39be6af763782278dd2ae871286e50413c736fc02e378c7b194a", "price_changes": [{"asset_id": "115499136196208654254049968774021214764893087674315074576157301876433223848835", "price": "0.02", "size": "1705.26", "side": "BUY", "hash": "b77e520054c8bf3d45c46fddfc4fa0ad57a0556a", "best_bid": "0.66", "best_ask": "0.76"}, {"asset_id": "47098692578463382240924923935626520236879739693617300734585244751793795800081", "price": "0.98", "size": "1705.26", "side": "SELL", "hash": "af262bab45dd2b1ae2eccf8217c7a36cdcd3bf82", "best_bid": "0.24", "best_ask": "0.34"}], "timestamp": "1769384660929", "event_type": "price_change"}}
{"_local_timestamp": "2026-01-25T23:45:56.210157+00:00", "data": {"market": "0xa3cf11c4cd5c39be6af763782278dd2ae871286e50413c736fc02e378c7b194a", "price_changes": [{"asset_id": "115499136196208654254049968774021214764893087674315074576157301876433223848835", "price": "0.24", "size": "100", "side": "BUY", "hash": "4c03e6658a0cf2ba663a2dd71e2e96d8a04a6edb", "best_bid": "0.66", "best_ask": "0.76"}, {"asset_id": "47098692578463382240924923935626520236879739693617300734585244751793795800081", "price": "0.76", "size": "100", "side": "SELL", "hash": "5148c3c2903f8f9320a683cc816db021b1da2100", "best_bid": "0.24", "best_ask": "0.34"}], "timestamp": "1769384756073", "event_type": "price_change"}}
{"_local_timestamp": "2026-01-25T23:46:17.088704+00:00", "data": {"market": "0xa3cf11c4cd5c39be6af763782278dd2ae871286e50413c736fc02e378c7b194a", "price_changes": [{"asset_id": "115499136196208654254049968774021214764893087674315074576157301876433223848835", "price": "0.1", "size": "0", "side": "BUY", "hash": "7438d2ca9d1573e46071c50e654175330b4cf93d", "best_bid": "0.66", "best_ask": "0.76"}, {"asset_id": "47098692578463382240924923935626520236879739693617300734585244751793795800081", "price": "0.9", "size": "0", "side": "SELL", "hash": "c7c35cb54ce60fca12961ad3bee8d6a1d74c7410", "best_bid": "0.24", "best_ask": "0.34"}], "timestamp": "1769384776994", "event_type": "price_change"}}
{"_local_timestamp": "2026-01-25T23:46:17.393432+00:00", "data": {"market": "0xa3cf11c4cd5c39be6af763782278dd2ae871286e50413c736fc02e378c7b194a", "price_changes": [{"asset_id": "115499136196208654254049968774021214764893087674315074576157301876433223848835", "price": "0.06", "size": "211.44", "side": "BUY", "hash": "d0c9706daa106c0bb5dcdfbce3cf34cd659603dd", "best_bid": "0.66", "best_ask": "0.76"}, {"asset_id": "47098692578463382240924923935626520236879739693617300734585244751793795800081", "price": "0.94", "size": "211.44", "side": "SELL", "hash": "cb56506eafa922a39f79797afa713d0f952a547c", "best_bid": "0.24", "best_ask": "0.34"}], "timestamp": "1769384777313", "event_type": "price_change"}}
{"_local_timestamp": "2026-01-25T23:46:17.568962+00:00", "data": {"market": "0xa3cf11c4cd5c39be6af763782278dd2ae871286e50413c736fc02e378c7b194a", "price_changes": [{"asset_id": "47098692578463382240924923935626520236879739693617300734585244751793795800081", "price": "0.09", "size": "112", "side": "BUY", "hash": "903e5071a4efad81af3a851b0f269eb0c80bc83d", "best_bid": "0.24", "best_ask": "0.34"}, {"asset_id": "115499136196208654254049968774021214764893087674315074576157301876433223848835", "price": "0.91", "size": "112", "side": "SELL", "hash": "2eb24eecb6daa8a9f188c5d90dcb8bc065aa4808", "best_bid": "0.66", "best_ask": "0.76"}], "timestamp": "1769384777501", "event_type": "price_change"}}
{"_local_timestamp": "2026-01-25T23:46:17.570421+00:00", "data": {"market": "0xa3cf11c4cd5c39be6af763782278dd2ae871286e50413c736fc02e378c7b194a", "price_changes": [{"asset_id": "47098692578463382240924923935626520236879739693617300734585244751793795800081", "price": "0.01", "size": "2063.99", "side": "BUY", "hash": "11617120af716347fca31a15c9102c247a853ebf", "best_bid": "0.24", "best_ask": "0.34"}, {"asset_id": "115499136196208654254049968774021214764893087674315074576157301876433223848835", "price": "0.99", "size": "2063.99", "side": "SELL", "hash": "d33d0e958bd3d9d4a1967a75c4d0384cd6c0b299", "best_bid": "0.66", "best_ask": "0.76"}], "timestamp": "1769384777502", "event_type": "price_change"}}
{"_local_timestamp": "2026-01-25T23:46:51.936899+00:00", "data": {"market": "0xa3cf11c4cd5c39be6af763782278dd2ae871286e50413c736fc02e378c7b194a", "price_changes": [{"asset_id": "115499136196208654254049968774021214764893087674315074576157301876433223848835", "price": "0.17", "size": "220", "side": "BUY", "hash": "5118975d68a0f9a1ca92ae832c457842545e6f3b", "best_bid": "0.66", "best_ask": "0.76"}, {"asset_id": "47098692578463382240924923935626520236879739693617300734585244751793795800081", "price": "0.83", "size": "220", "side": "SELL", "hash": "302e36cb12728e11898cf3fcfe15587f5025fd65", "best_bid": "0.24", "best_ask": "0.34"}], "timestamp": "1769384811869", "event_type": "price_change"}}
{"_local_timestamp": "2026-01-25T23:46:58.965670+00:00", "data": {"market": "0xa3cf11c4cd5c39be6af763782278dd2ae871286e50413c736fc02e378c7b194a", "price_changes": [{"asset_id": "115499136196208654254049968774021214764893087674315074576157301876433223848835", "price": "0.24", "size": "0", "side": "BUY", "hash": "785876838264b456d323a5dc0e4b54fa8ef3ac04", "best_bid": "0.66", "best_ask": "0.76"}, {"asset_id": "47098692578463382240924923935626520236879739693617300734585244751793795800081", "price": "0.76", "size": "0", "side": "SELL", "hash": "aa476c52d95508d9625eb1fdb9b418ff757db6e8", "best_bid": "0.24", "best_ask": "0.34"}], "timestamp": "1769384818860", "event_type": "price_change"}}
{"_local_timestamp": "2026-01-25T23:46:59.304857+00:00", "data": {"market": "0xa3cf11c4cd5c39be6af763782278dd2ae871286e50413c736fc02e378c7b194a", "price_changes": [{"asset_id": "115499136196208654254049968774021214764893087674315074576157301876433223848835", "price": "0.21", "size": "100", "side": "BUY", "hash": "a166e27eac30f634a5ea1c8952166083eb28a22d", "best_bid": "0.66", "best_ask": "0.76"}, {"asset_id": "47098692578463382240924923935626520236879739693617300734585244751793795800081", "price": "0.79", "size": "100", "side": "SELL", "hash": "5d152a0e849f893cd467e6a06f4c748f7abbd2b5", "best_bid": "0.24", "best_ask": "0.34"}], "timestamp": "1769384819161", "event_type": "price_change"}}
{"_local_timestamp": "2026-01-25T23:47:55.609679+00:00", "data": {"market": "0xa3cf11c4cd5c39be6af763782278dd2ae871286e50413c736fc02e378c7b194a", "price_changes": [{"asset_id": "115499136196208654254049968774021214764893087674315074576157301876433223848835", "price": "0.11", "size": "550", "side": "BUY", "hash": "d2a99ea0474568b95be37733cdc2271597546f78", "best_bid": "0.66", "best_ask": "0.76"}, {"asset_id": "47098692578463382240924923935626520236879739693617300734585244751793795800081", "price": "0.89", "size": "550", "side": "SELL", "hash": "08787312ed951d3cc6a0fb09c970668f061fc811", "best_bid": "0.24", "best_ask": "0.34"}], "timestamp": "1769384875415", "event_type": "price_change"}}
{"_local_timestamp": "2026-01-25T23:47:58.079071+00:00", "data": {"market": "0xa3cf11c4cd5c39be6af763782278dd2ae871286e50413c736fc02e378c7b194a", "price_changes": [{"asset_id": "115499136196208654254049968774021214764893087674315074576157301876433223848835", "price": "0.07", "size": "6000", "side": "BUY", "hash": "0a0c215a0fd08a2476334831188153915eae59c4", "best_bid": "0.66", "best_ask": "0.76"}, {"asset_id": "47098692578463382240924923935626520236879739693617300734585244751793795800081", "price": "0.93", "size": "6000", "side": "SELL", "hash": "ddcae5353abc12c9dbd398bc48ad0d29a4b67785", "best_bid": "0.24", "best_ask": "0.34"}], "timestamp": "1769384877952", "event_type": "price_change"}}
{"_local_timestamp": "2026-01-25T23:48:06.446164+00:00", "data": {"market": "0xa3cf11c4cd5c39be6af763782278dd2ae871286e50413c736fc02e378c7b194a", "price_changes": [{"asset_id": "115499136196208654254049968774021214764893087674315074576157301876433223848835", "price": "0.06", "size": "200", "side": "BUY", "hash": "41afc76c28242c48c8a5c8182c7f4b0768b8751e", "best_bid": "0.66", "best_ask": "0.76"}, {"asset_id": "47098692578463382240924923935626520236879739693617300734585244751793795800081", "price": "0.94", "size": "200", "side": "SELL", "hash": "29f60a4e7a2868e15c7bfb379304035a30043ffd", "best_bid": "0.24", "best_ask": "0.34"}], "timestamp": "1769384886230", "event_type": "price_change"}}
{"_local_timestamp": "2026-01-25T23:48:07.098684+00:00", "data": {"market": "0xa3cf11c4cd5c39be6af763782278dd2ae871286e50413c736fc02e378c7b194a", "price_changes": [{"asset_id": "115499136196208654254049968774021214764893087674315074576157301876433223848835", "price": "0.03", "size": "17.57", "side": "BUY", "hash": "176521597718e5a2d89ea935762a6c2912cbb190", "best_bid": "0.66", "best_ask": "0.76"}, {"asset_id": "47098692578463382240924923935626520236879739693617300734585244751793795800081", "price": "0.97", "size": "17.57", "side": "SELL", "hash": "c7e2c6fb2d912173931bbc2dcc073c0b62c65868", "best_bid": "0.24", "best_ask": "0.34"}], "timestamp": "1769384886888", "event_type": "price_change"}}
{"_local_timestamp": "2026-01-25T23:48:07.099078+00:00", "data": {"market": "0xa3cf11c4cd5c39be6af763782278dd2ae871286e50413c736fc02e378c7b194a", "price_changes": [{"asset_id": "115499136196208654254049968774021214764893087674315074576157301876433223848835", "price": "0.08", "size": "6.26", "side": "BUY", "hash": "2196841a523726643c91372462e24a32e7762d2f", "best_bid": "0.66", "best_ask": "0.76"}, {"asset_id": "47098692578463382240924923935626520236879739693617300734585244751793795800081", "price": "0.92", "size": "6.26", "side": "SELL", "hash": "d9a4b6b30f7d0fcae7bd1502a65a08fa2128af48", "best_bid": "0.24", "best_ask": "0.34"}], "timestamp": "1769384886892", "event_type": "price_change"}}
{"_local_timestamp": "2026-01-25T23:48:48.693526+00:00", "data": {"market": "0xa3cf11c4cd5c39be6af763782278dd2ae871286e50413c736fc02e378c7b194a", "price_changes": [{"asset_id": "115499136196208654254049968774021214764893087674315074576157301876433223848835", "price": "0.11", "size": "325", "side": "BUY", "hash": "40b4c2b56ca2eff637b75c29a5f13e88a2cd3712", "best_bid": "0.66", "best_ask": "0.76"}, {"asset_id": "47098692578463382240924923935626520236879739693617300734585244751793795800081", "price": "0.89", "size": "325", "side": "SELL", "hash": "8944a8c2d849f201924ee161542c5581065d0b7b", "best_bid": "0.24", "best_ask": "0.34"}], "timestamp": "1769384928586", "event_type": "price_change"}}
{"_local_timestamp": "2026-01-25T23:48:48.936337+00:00", "data": {"market": "0xa3cf11c4cd5c39be6af763782278dd2ae871286e50413c736fc02e378c7b194a", "price_changes": [{"asset_id": "115499136196208654254049968774021214764893087674315074576157301876433223848835", "price": "0.13", "size": "2705", "side": "BUY", "hash": "6e000d0b0131a32420571a114b9a4c7dc2a944c3", "best_bid": "0.66", "best_ask": "0.76"}, {"asset_id": "47098692578463382240924923935626520236879739693617300734585244751793795800081", "price": "0.87", "size": "2705", "side": "SELL", "hash": "8fdb9fac27bcc568f52a39fc0ca1f16414e03df9", "best_bid": "0.24", "best_ask": "0.34"}], "timestamp": "1769384928844", "event_type": "price_change"}}
{"_local_timestamp": "2026-01-25T23:49:41.874468+00:00", "data": {"market": "0xa3cf11c4cd5c39be6af763782278dd2ae871286e50413c736fc02e378c7b194a", "price_changes": [{"asset_id": "115499136196208654254049968774021214764893087674315074576157301876433223848835", "price": "0.06", "size": "0", "side": "BUY", "hash": "7164a7221096c0ced8b2a680eaace4b64b778b85", "best_bid": "0.66", "best_ask": "0.76"}, {"asset_id": "47098692578463382240924923935626520236879739693617300734585244751793795800081", "price": "0.94", "size": "0", "side": "SELL", "hash": "f5b020fd6cb8cc8a4a395fb600b63cc90c1620d2", "best_bid": "0.24", "best_ask": "0.34"}], "timestamp": "1769384981740", "event_type": "price_change"}}
{"_local_timestamp": "2026-01-25T23:49:42.231201+00:00", "data": {"market": "0xa3cf11c4cd5c39be6af763782278dd2ae871286e50413c736fc02e378c7b194a", "price_changes": [{"asset_id": "115499136196208654254049968774021214764893087674315074576157301876433223848835", "price": "0.07", "size": "6200", "side": "BUY", "hash": "18c3b054cf8e92d6126639d6cbb52a676912a72a", "best_bid": "0.66", "best_ask": "0.76"}, {"asset_id": "47098692578463382240924923935626520236879739693617300734585244751793795800081", "price": "0.93", "size": "6200", "side": "SELL", "hash": "4f75665737b65afe074fc42a2d2f2327dbac3f86", "best_bid": "0.24", "best_ask": "0.34"}], "timestamp": "1769384982100", "event_type": "price_change"}}
{"_local_timestamp": "2026-01-25T23:49:42.408534+00:00", "data": {"market": "0xa3cf11c4cd5c39be6af763782278dd2ae871286e50413c736fc02e378c7b194a", "price_changes": [{"asset_id": "115499136196208654254049968774021214764893087674315074576157301876433223848835", "price": "0.21", "size": "150", "side": "BUY", "hash": "75445d2c0d04852b51e87625bee52cfbae314938", "best_bid": "0.66", "best_ask": "0.76"}, {"asset_id": "47098692578463382240924923935626520236879739693617300734585244751793795800081", "price": "0.79", "size": "150", "side": "SELL", "hash": "b730267644f16cea1581d5a49a277dae978b04ff", "best_bid": "0.24", "best_ask": "0.34"}], "timestamp": "1769384982212", "event_type": "price_change"}}
{"_local_timestamp": "2026-01-25T23:49:51.263923+00:00", "data": {"market": "0xa3cf11c4cd5c39be6af763782278dd2ae871286e50413c736fc02e378c7b194a", "price_changes": [{"asset_id": "115499136196208654254049968774021214764893087674315074576157301876433223848835", "price": "0.07", "size": "200", "side": "BUY", "hash": "8f577a4331ea2c76d31d8c01df4b8120d1ff9855", "best_bid": "0.66", "best_ask": "0.76"}, {"asset_id": "47098692578463382240924923935626520236879739693617300734585244751793795800081", "price": "0.93", "size": "200", "side": "SELL", "hash": "87fda45bcb364ff925c3f298c4a89f3483111e5e", "best_bid": "0.24", "best_ask": "0.34"}], "timestamp": "1769384991047", "event_type": "price_change"}}
{"_local_timestamp": "2026-01-25T23:50:02.598753+00:00", "data": {"market": "0xa3cf11c4cd5c39be6af763782278dd2ae871286e50413c736fc02e378c7b194a", "price_changes": [{"asset_id": "115499136196208654254049968774021214764893087674315074576157301876433223848835", "price": "0.13", "size": "1475", "side": "BUY", "hash": "5ac7216605c0c2c230c0f4ec56174f6f77dc43f4", "best_bid": "0.66", "best_ask": "0.76"}, {"asset_id": "47098692578463382240924923935626520236879739693617300734585244751793795800081", "price": "0.87", "size": "1475", "side": "SELL", "hash": "1023e91613707466521a908d4d157c10fe0d7738", "best_bid": "0.24", "best_ask": "0.34"}], "timestamp": "1769385002279", "event_type": "price_change"}}
{"_local_timestamp": "2026-01-25T23:50:03.181659+00:00", "data": {"market": "0xa3cf11c4cd5c39be6af763782278dd2ae871286e50413c736fc02e378c7b194a", "price_changes": [{"asset_id": "115499136196208654254049968774021214764893087674315074576157301876433223848835", "price": "0.13", "size": "245", "side": "BUY", "hash": "28f194e9ba4d4bdfb4f850b435022d676441f949", "best_bid": "0.66", "best_ask": "0.76"}, {"asset_id": "47098692578463382240924923935626520236879739693617300734585244751793795800081", "price": "0.87", "size": "245", "side": "SELL", "hash": "b3fd4904667efa29cb4322f43b8018fc388d13b8", "best_bid": "0.24", "best_ask": "0.34"}], "timestamp": "1769385002727", "event_type": "price_change"}}
{"_local_timestamp": "2026-01-25T23:50:11.376914+00:00", "data": {"market": "0xa3cf11c4cd5c39be6af763782278dd2ae871286e50413c736fc02e378c7b194a", "price_changes": [{"asset_id": "115499136196208654254049968774021214764893087674315074576157301876433223848835", "price": "0.12", "size": "3500", "side": "BUY", "hash": "3d33f52adc2b0d76e8e8df4906d7a0b69e7930c7", "best_bid": "0.66", "best_ask": "0.76"}, {"asset_id": "47098692578463382240924923935626520236879739693617300734585244751793795800081", "price": "0.88", "size": "3500", "side": "SELL", "hash": "e7e322c79e81aa74548da4a11c56cd5024cb4e2c", "best_bid": "0.24", "best_ask": "0.34"}], "timestamp": "1769385011300", "event_type": "price_change"}}
{"_local_timestamp": "2026-01-25T23:50:46.399828+00:00", "data": {"market": "0xa3cf11c4cd5c39be6af763782278dd2ae871286e50413c736fc02e378c7b194a", "price_changes": [{"asset_id": "115499136196208654254049968774021214764893087674315074576157301876433223848835", "price": "0.13", "size": "20", "side": "BUY", "hash": "5de69021a8a8674fe062ee851ef6b4d8ea692959", "best_bid": "0.66", "best_ask": "0.76"}, {"asset_id": "47098692578463382240924923935626520236879739693617300734585244751793795800081", "price": "0.87", "size": "20", "side": "SELL", "hash": "d52d134f160cbece5c000550cdb17d541e68334f", "best_bid": "0.24", "best_ask": "0.34"}], "timestamp": "1769385046276", "event_type": "price_change"}}
{"_local_timestamp": "2026-01-25T23:50:46.742824+00:00", "data": {"market": "0xa3cf11c4cd5c39be6af763782278dd2ae871286e50413c736fc02e378c7b194a", "price_changes": [{"asset_id": "115499136196208654254049968774021214764893087674315074576157301876433223848835", "price": "0.11", "size": "550", "side": "BUY", "hash": "c30048bb257357233bd43a8b25e155789e36e418", "best_bid": "0.66", "best_ask": "0.76"}, {"asset_id": "47098692578463382240924923935626520236879739693617300734585244751793795800081", "price": "0.89", "size": "550", "side": "SELL", "hash": "88d6b9b271519c9a34ec1e92044a7b1a8e1a2168", "best_bid": "0.24", "best_ask": "0.34"}], "timestamp": "1769385046630", "event_type": "price_change"}}
{"_local_timestamp": "2026-01-25T23:51:05.597600+00:00", "data": {"market": "0xa3cf11c4cd5c39be6af763782278dd2ae871286e50413c736fc02e378c7b194a", "price_changes": [{"asset_id": "115499136196208654254049968774021214764893087674315074576157301876433223848835", "price": "0.11", "size": "425", "side": "BUY", "hash": "9824a25d6ac18ea4d86cd4298287c6dc496376f9", "best_bid": "0.66", "best_ask": "0.76"}, {"asset_id": "47098692578463382240924923935626520236879739693617300734585244751793795800081", "price": "0.89", "size": "425", "side": "SELL", "hash": "062d737c5881c575fd665443e3cd639f14d1e321", "best_bid": "0.24", "best_ask": "0.34"}], "timestamp": "1769385065431", "event_type": "price_change"}}
{"_local_timestamp": "2026-01-25T23:51:05.953754+00:00", "data": {"market": "0xa3cf11c4cd5c39be6af763782278dd2ae871286e50413c736fc02e378c7b194a", "price_changes": [{"asset_id": "115499136196208654254049968774021214764893087674315074576157301876433223848835", "price": "0.13", "size": "145", "side": "BUY", "hash": "70ef171465d85f4a656bb7aa04c01aaa008c1bc7", "best_bid": "0.66", "best_ask": "0.76"}, {"asset_id": "47098692578463382240924923935626520236879739693617300734585244751793795800081", "price": "0.87", "size": "145", "side": "SELL", "hash": "349c32a1ce0e8743eb1c3ef5d821ab57534d8db2", "best_bid": "0.24", "best_ask": "0.34"}], "timestamp": "1769385065776", "event_type": "price_change"}}
