{"_local_timestamp": "2026-01-25T23:33:49.068468+00:00", "data": [{"market": "0x53d7dab8196554be4d3198f446427d886a1b0cca4af0d980b5db69781d3065a9", "asset_id": "50416017845112722830648576285355962859836703684331757667284549974224475224302", "timestamp": "1769381899954", "hash": "6fa54b64fe7d1a3c369b8c0dbdd9df8ec1b95c36", "bids": [{"price": "0.01", "size": "99.23"}, {"price": "0.02", "size": "850"}, {"price": "0.03", "size": "8.3"}, {"price": "0.05", "size": "500"}, {"price": "0.08", "size": "300"}, {"price": "0.09", "size": "7.2"}, {"price": "0.24", "size": "54.16"}, {"price": "0.25", "size": "44"}, {"price": "0.78", "size": "350"}, {"price": "0.79", "size": "25600"}, {"price": "0.81", "size": "361"}], "asks": [{"price": "0.99", "size": "102.24"}, {"price": "0.98", "size": "210"}, {"price": "0.97", "size": "12.99"}, {"price": "0.94", "size": "30"}, {"price": "0.93", "size": "185.71"}, {"price": "0.92", "size": "26.59"}, {"price": "0.91", "size": "61.11"}, {"price": "0.9", "size": "20"}, {"price": "0.86", "size": "456"}, {"price": "0.84", "size": "25606.25"}, {"price": "0.83", "size": "42"}], "event_type": "book", "last_trade_price": ""}, {"market": "0xe91afed2cf59036aa2263e56d7928a5ae8ee85d54b1b46ccf679cf12ef664753", "asset_id": "52571443025345708025030679766882856603822335849274985584394259288472261399283", "timestamp": "1769383667056", "hash": "687f4837900c1414f27e578c882069b4e694f143", "bids": [{"price": "0.01", "size": "104.21"}, {"price": "0.02", "size": "850"}, {"price": "0.03", "size": "8.29"}, {"price": "0.05", "size": "500"}, {"price": "0.08", "size": "300"}, {"price": "0.09", "size": "7.21"}, {"price": "0.21", "size": "30"}, {"price": "0.55", "size": "16368"}, {"price": "0.58", "size": "14093.25"}, {"price": "0.61", "size": "11868"}, {"price": "0.64", "size": "9672"}, {"price": "0.67", "size": "7470"}, {"price": "0.68", "size": "19.11"}, {"price": "0.69", "size": "15.94"}, {"price": "0.7", "size": "5271"}, {"price": "0.72", "size": "103"}, {"price": "0.73", "size": "3048"}, {"price": "0.74", "size": "3063"}, {"price": "0.75", "size": "3431"}, {"price": "0.78", "size": "25600"}, {"price": "0.79", "size": "42"}], "asks": [{"price": "0.99", "size": "89"}, {"price": "0.98", "size": "158.46"}, {"price": "0.97", "size": "41466.75"}, {"price": "0.96", "size": "255.56"}, {"price": "0.94", "size": "18742.5"}, {"price": "0.93", "size": "8.68"}, {"price": "0.91", "size": "10059"}, {"price": "0.9", "size": "240"}, {"price": "0.88", "size": "4875"}, {"price": "0.87", "size": "4674"}, {"price": "0.86", "size": "4503"}, {"price": "0.84", "size": "350"}, {"price": "0.83", "size": "25605.88"}, {"price": "0.82", "size": "204"}], "event_type": "book", "last_trade_price": ""}, {"market": "0x937de722f8deb4c75aa4a307cb8e5eeb2510a6b5ea86f76ca09a2dc0cd20a4bc", "asset_id": "54159141424996573001673795486235351282895050934599122504282991350686939527644", "timestamp": "1769383942265", "hash": "a9e54625213b2b0571223ff94232b6ea0c1c7349", "bids": [{"price": "0.01", "size": "155.19"}, {"price": "0.02", "size": "850"}, {"price": "0.03", "size": "5.83"}, {"price": "0.05", "size": "530"}, {"price": "0.06", "size": "33"}, {"price": "0.09", "size": "8.03"}, {"price": "0.13", "size": "237"}, {"price": "0.23", "size": "56.52"}, {"price": "0.24", "size": "45.83"}, {"price": "0.56", "size": "350"}, {"price": "0.58", "size": "203"}, {"price": "0.59", "size": "43"}], "asks": [{"price": "0.99", "size": "140"}, {"price": "0.98", "size": "855.82"}, {"price": "0.97", "size": "16"}, {"price": "0.96", "size": "30.97"}, {"price": "0.95", "size": "500"}, {"price": "0.91", "size": "7.16"}, {"price": "0.9", "size": "578"}, {"price": "0.81", "size": "68.42"}, {"price": "0.8", "size": "55"}, {"price": "0.65", "size": "350"}, {"price": "0.63", "size": "101"}, {"price": "0.62", "size": "43"}], "event_type": "book", "last_trade_price": ""}, {"market": "0x937de722f8deb4c75aa4a307cb8e5eeb2510a6b5ea86f76ca09a2dc0cd20a4bc", "asset_id": "42980630208864318379919380711046026375503533727978237281500044871471440019852", "timestamp": "1769383942265", "hash": "26879bb50c3651bbe14de3501ddbf77675076620", "bids": [{"price": "0.01", "size": "140"}, {"price": "0.02", "size": "855.82"}, {"price": "0.03", "size": "16"}, {"price": "0.04", "size": "30.97"}, {"price": "0.05", "size": "500"}, {"price": "0.09", "size": "7.16"}, {"price": "0.1", "size": "578"}, {"price": "0.19", "size": "68.42"}, {"price": "0.2", "size": "55"}, {"price": "0.35", "size": "350"}, {"price": "0.37", "size": "101"}, {"price": "0.38", "size": "43"}], "asks": [{"price": "0.99", "size": "155.19"}, {"price": "0.98", "size": "850"}, {"price": "0.97", "size": "5.83"}, {"price": "0.95", "size": "530"}, {"price": "0.94", "size": "33"}, {"price": "0.91", "size": "8.03"}, {"price": "0.87", "size": "237"}, {"price": "0.77", "size": "56.52"}, {"price": "0.76", "size": "45.83"}, {"price": "0.44", "size": "350"}, {"price": "0.42", "size": "203"}, {"price": "0.41", "size": "43"}], "event_type": "book", "last_trade_price": ""}, {"market": "0xe91afed2cf59036aa2263e56d7928a5ae8ee85d54b1b46ccf679cf12ef664753", "asset_id": "63152720970971968001690179005626043167942208308910151565176976232568233779040", "timestamp": "1769383667056", "hash": "167b3253561c9daf246a2e0b7f09a83ecddd5631", "bids": [{"price": "0.01", "size": "89"}, {"price": "0.02", "size": "158.46"}, {"price": "0.03", "size": "41466.75"}, {"price": "0.04", "size": "255.56"}, {"price": "0.06", "size": "18742.5"}, {"price": "0.07", "size": "8.68"}, {"price": "0.09", "size": "10059"}, {"price": "0.1", "size": "240"}, {"price": "0.12", "size": "4875"}, {"price": "0.13", "size": "4674"}, {"price": "0.14", "size": "4503"}, {"price": "0.16", "size": "350"}, {"price": "0.17", "size": "25605.88"}, {"price": "0.18", "size": "204"}], "asks": [{"price": "0.99", "size": "104.21"}, {"price": "0.98", "size": "850"}, {"price": "0.97", "size": "8.29"}, {"price": "0.95", "size": "500"}, {"price": "0.92", "size": "300"}, {"price": "0.91", "size": "7.21"}, {"price": "0.79", "size": "30"}, {"price": "0.45", "size": "16368"}, {"price": "0.42", "size": "14093.25"}, {"price": "0.39", "size": "11868"}, {"price": "0.36", "size": "9672"}, {"price": "0.33", "size": "7470"}, {"price": "0.32", "size": "19.11"}, {"price": "0.31", "size": "15.94"}, {"price": "0.3", "size": "5271"}, {"price": "0.28", "size": "103"}, {"price": "0.27", "size": "3048"}, {"price": "0.26", "size": "3063"}, {"price": "0.25", "size": "3431"}, {"price": "0.22", "size": "25600"}, {"price": "0.21", "size": "42"}], "event_type": "book", "last_trade_price": ""}, {"market": "0x5399e84f207adf1614c642b1b0829b110159c91cf7331f567b88a1dcf587e779", "asset_id": "100715172532828128539584818881319138941352610561521393079458208964903259330699", "timestamp": "1769383980891", "hash": "70cbb7f162bb08a571b58df8cc753e41b166ab38", "bids": [{"price": "0.01", "size": "98.7"}, {"price": "0.02", "size": "1100"}, {"price": "0.03", "size": "9.24"}, {"price": "0.05", "size": "500"}, {"price": "0.08", "size": "300"}, {"price": "0.09", "size": "6.95"}, {"price": "0.2", "size": "21120"}, {"price": "0.23", "size": "17285.25"}, {"price": "0.26", "size": "13956"}, {"price": "0.29", "size": "10959"}, {"price": "0.32", "size": "8238.12"}, {"price": "0.33", "size": "33.33"}, {"price": "0.35", "size": "5607"}, {"price": "0.38", "size": "3144"}, {"price": "0.39", "size": "3466.29"}, {"price": "0.4", "size": "28800"}, {"price": "0.41", "size": "95"}, {"price": "0.42", "size": "160"}], "asks": [{"price": "0.99", "size": "104.21"}, {"price": "0.98", "size": "1100"}, {"price": "0.97", "size": "8.36"}, {"price": "0.95", "size": "500"}, {"price": "0.92", "size": "300"}, {"price": "0.91", "size": "7.18"}, {"price": "0.66", "size": "17754"}, {"price": "0.63", "size": "15019.5"}, {"price": "0.6", "size": "12444"}, {"price": "0.57", "size": "9964.5"}, {"price": "0.54", "size": "7582.5"}, {"price": "0.53", "size": "27.65"}, {"price": "0.51", "size": "5260.5"}, {"price": "0.5", "size": "22"}, {"price": "0.48", "size": "3338"}, {"price": "0.47", "size": "3066"}, {"price": "0.46", "size": "3274.55"}, {"price": "0.45", "size": "25897"}, {"price": "0.44", "size": "54"}], "event_type": "book", "last_trade_price": "0.570"}, {"market": "0x53d7dab8196554be4d3198f446427d886a1b0cca4af0d980b5db69781d3065a9", "asset_id": "98584735062828774636898378898502011795360187693844488208471424555750267825841", "timestamp": "1769381899954", "hash": "f116bfa2892c6402d063855741b46949942493a6", "bids": [{"price": "0.01", "size": "102.24"}, {"price": "0.02", "size": "210"}, {"price": "0.03", "size": "12.99"}, {"price": "0.06", "size": "30"}, {"price": "0.07", "size": "185.71"}, {"price": "0.08", "size": "26.59"}, {"price": "0.09", "size": "61.11"}, {"price": "0.1", "size": "20"}, {"price": "0.14", "size": "456"}, {"price": "0.16", "size": "25606.25"}, {"price": "0.17", "size": "42"}], "asks": [{"price": "0.99", "size": "99.23"}, {"price": "0.98", "size": "850"}, {"price": "0.97", "size": "8.3"}, {"price": "0.95", "size": "500"}, {"price": "0.92", "size": "300"}, {"price": "0.91", "size": "7.2"}, {"price": "0.76", "size": "54.16"}, {"price": "0.75", "size": "44"}, {"price": "0.22", "size": "350"}, {"price": "0.21", "size": "25600"}, {"price": "0.19", "size": "361"}], "event_type": "book", "last_trade_price": ""}, {"market": "0x5399e84f207adf1614c642b1b0829b110159c91cf7331f567b88a1dcf587e779", "asset_id": "87540986142349541251416387669319613039979965784850055709534778197048463392328", "timestamp": "1769383980891", "hash": "78c16b59c49d4a51b8b3895f2afb9060056fb82b", "bids": [{"price": "0.01", "size": "104.21"}, {"price": "0.02", "size": "1100"}, {"price": "0.03", "size": "8.36"}, {"price": "0.05", "size": "500"}, {"price": "0.08", "size": "300"}, {"price": "0.09", "size": "7.18"}, {"price": "0.34", "size": "17754"}, {"price": "0.37", "size": "15019.5"}, {"price": "0.4", "size": "12444"}, {"price": "0.43", "size": "9964.5"}, {"price": "0.46", "size": "7582.5"}, {"price": "0.47", "size": "27.65"}, {"price": "0.49", "size": "5260.5"}, {"price": "0.5", "size": "22"}, {"price": "0.52", "size": "3338"}, {"price": "0.53", "size": "3066"}, {"price": "0.54", "size": "3274.55"}, {"price": "0.55", "size": "25897"}, {"price": "0.56", "size": "54"}], "asks": [{"price": "0.99", "size": "98.7"}, {"price": "0.98", "size": "1100"}, {"price": "0.97", "size": "9.24"}, {"price": "0.95", "size": "500"}, {"price": "0.92", "size": "300"}, {"price": "0.91", "size": "6.95"}, {"price": "0.8", "size": "21120"}, {"price": "0.77", "size": "17285.25"}, {"price": "0.74", "size": "13956"}, {"price": "0.71", "size": "10959"}, {"price": "0.68", "size": "8238.12"}, {"price": "0.67", "size": "33.33"}, {"price": "0.65", "size": "5607"}, {"price": "0.62", "size": "3144"}, {"price": "0.61", "size": "3466.29"}, {"price": "0.6", "size": "28800"}, {"price": "0.59", "size": "95"}, {"price": "0.58", "size": "160"}], "event_type": "book", "last_trade_price": "0.570"}, {"market": "0xe85f66ca3258249e3fa3cfb7eded108c31a854af9eb1d0f2e1c463d787bd587e", "asset_id": "89085785705693135663344595542401989320859278708688805320605944475346324962521", "timestamp": "1769383991769", "hash": "28c32c966e4f7da1345164d8613b7d6dc2126499", "bids": [{"price": "0.01", "size": "99.19"}, {"price": "0.02", "size": "850"}, {"price": "0.03", "size": "9.47"}, {"price": "0.05", "size": "500"}, {"price": "0.08", "size": "300"}, {"price": "0.09", "size": "6.82"}, {"price": "0.4", "size": "17110.5"}, {"price": "0.43", "size": "14563.5"}, {"price": "0.46", "size": "12132"}, {"price": "0.49", "size": "9769.5"}, {"price": "0.52", "size": "7470"}, {"price": "0.53", "size": "24.52"}, {"price": "0.54", "size": "20.37"}, {"price": "0.55", "size": "5208"}, {"price": "0.58", "size": "2967"}, {"price": "0.59", "size": "2967"}, {"price": "0.6", "size": "3317"}, {"price": "0.62", "size": "25690"}, {"price": "0.63", "size": "118"}, {"price": "0.64", "size": "144"}], "asks": [{"price": "0.99", "size": "102.93"}, {"price": "0.98", "size": "850"}, {"price": "0.97", "size": "30.35"}, {"price": "0.9", "size": "29700"}, {"price": "0.87", "size": "22201.5"}, {"price": "0.84", "size": "16896"}, {"price": "0.81", "size": "12743.25"}, {"price": "0.78", "size": "9247.5"}, {"price": "0.77", "size": "56.52"}, {"price": "0.76", "size": "45.83"}, {"price": "0.75", "size": "6184.5"}, {"price": "0.73", "size": "117"}, {"price": "0.72", "size": "3408"}, {"price": "0.71", "size": "3372"}, {"price": "0.7", "size": "3339"}, {"price": "0.69", "size": "350"}, {"price": "0.68", "size": "25665.09"}, {"price": "0.67", "size": "52"}], "event_type": "book", "last_trade_price": ""}, {"market": "0xe85f66ca3258249e3fa3cfb7eded108c31a854af9eb1d0f2e1c463d787bd587e", "asset_id": "9959766640993038566313541584805552672310282986889616646650002978435506606528", "timestamp": "1769383991769", "hash": "8e6190e9265ac40b6851055407ec078d32c0716a", "bids": [{"price": "0.01", "size": "102.93"}, {"price": "0.02", "size": "850"}, {"price": "0.03", "size": "30.35"}, {"price": "0.1", "size": "29700"}, {"price": "0.13", "size": "22201.5"}, {"price": "0.16", "size": "16896"}, {"price": "0.19", "size": "12743.25"}, {"price": "0.22", "size": "9247.5"}, {"price": "0.23", "size": "56.52"}, {"price": "0.24", "size": "45.83"}, {"price": "0.25", "size": "6184.5"}, {"price": "0.27", "size": "117"}, {"price": "0.28", "size": "3408"}, {"price": "0.29", "size": "3372"}, {"price": "0.3", "size": "3339"}, {"price": "0.31", "size": "350"}, {"price": "0.32", "size": "25665.09"}, {"price": "0.33", "size": "52"}], "asks": [{"price": "0.99", "size": "99.19"}, {"price": "0.98", "size": "850"}, {"price": "0.97", "size": "9.47"}, {"price": "0.95", "size": "500"}, {"price": "0.92", "size": "300"}, {"price": "0.91", "size": "6.82"}, {"price": "0.6", "size": "17110.5"}, {"price": "0.57", "size": "14563.5"}, {"price": "0.54", "size": "12132"}, {"price": "0.51", "size": "9769.5"}, {"price": "0.48", "size": "7470"}, {"price": "0.47", "size": "24.52"}, {"price": "0.46", "size": "20.37"}, {"price": "0.45", "size": "5208"}, {"price": "0.42", "size": "2967"}, {"price": "0.41", "size": "2967"}, {"price": "0.4", "size": "3317"}, {"price": "0.38", "size": "25690"}, {"price": "0.37", "size": "118"}, {"price": "0.36", "size": "144"}], "event_type": "book", "last_trade_price": ""}]}
{"_local_timestamp": "2026-01-25T23:34:04.314110+00:00", "data": {"market": "0x5399e84f207adf1614c642b1b0829b110159c91cf7331f567b88a1dcf587e779", "price_changes": [{"asset_id": "100715172532828128539584818881319138941352610561521393079458208964903259330699", "price": "0.42", "size": "107", "side": "BUY", "hash": "8297a269e4f222d1ce6cba2185e617341710561f", "best_bid": "0.42", "best_ask": "0.44"}, {"asset_id": "87540986142349541251416387669319613039979965784850055709534778197048463392328", "price": "0.58", "size": "107", "side": "SELL", "hash": "33b7532114e0d18151a7cc54ea1d3f1c9623e334", "best_bid": "0.56", "best_ask": "0.58"}], "timestamp": "1769384044247", "event_type": "price_change"}}
{"_local_timestamp": "2026-01-25T23:34:04.315172+00:00", "data": {"market": "0x5399e84f207adf1614c642b1b0829b110159c91cf7331f567b88a1dcf587e779", "price_changes": [{"asset_id": "100715172532828128539584818881319138941352610561521393079458208964903259330699", "price": "0.41", "size": "148", "side": "BUY", "hash": "614131c74a490cc1c4d136919b68b4b209003573", "best_bid": "0.42", "best_ask": "0.44"}, {"asset_id": "87540986142349541251416387669319613039979965784850055709534778197048463392328", "price": "0.59", "size": "148", "side": "SELL", "hash": "b4b567891afac65763a696307fabdf72e3890d07", "best_bid": "0.56", "best_ask": "0.58"}], "timestamp": "1769384044249", "event_type": "price_change"}}
{"_local_timestamp": "2026-01-25T23:34:12.783846+00:00", "data": {"market": "0x5399e84f207adf1614c642b1b0829b110159c91cf7331f567b88a1dcf587e779", "price_changes": [{"asset_id": "100715172532828128539584818881319138941352610561521393079458208964903259330699", "price": "0.42", "size": "160", "side": "BUY", "hash": "15867ca81a16a06e0f477631adc96ed6245b7de9", "best_bid": "0.42", "best_ask": "0.44"}, {"asset_id": "87540986142349541251416387669319613039979965784850055709534778197048463392328", "price": "0.58", "size": "160", "side": "SELL", "hash": "b242b2e0d71b36740afd2ae7866d9b2e3f03e7fe", "best_bid": "0.56", "best_ask": "0.58"}], "timestamp": "1769384052706", "event_type": "price_change"}}
{"_local_timestamp": "2026-01-25T23:34:13.346800+00:00", "data": {"market": "0x5399e84f207adf1614c642b1b0829b110159c91cf7331f567b88a1dcf587e779", "price_changes": [{"asset_id": "100715172532828128539584818881319138941352610561521393079458208964903259330699", "price": "0.41", "size": "95", "side": "BUY", "hash": "6afb0f21df8a9fc9cb5b4b7ff64be2158807727f", "best_bid": "0.42", "best_ask": "0.44"}, {"asset_id": "87540986142349541251416387669319613039979965784850055709534778197048463392328", "price": "0.59", "size": "95", "side": "SELL", "hash": "5e0c1ea319fba5d3345a755f3a9f530933d54b22", "best_bid": "0.56", "best_ask": "0.58"}], "timestamp": "1769384053258", "event_type": "price_change"}}
{"_local_timestamp": "2026-01-25T23:36:02.686098+00:00", "data": {"market": "0x5399e84f207adf1614c642b1b0829b110159c91cf7331f567b88a1dcf587e779", "price_changes": [{"asset_id": "100715172532828128539584818881319138941352610561521393079458208964903259330699", "price": "0.42", "size": "107", "side": "BUY", "hash": "764ae76ca265370fd1a6c4b205e5ae093c0b88dd", "best_bid": "0.42", "best_ask": "0.44"}, {"asset_id": "87540986142349541251416387669319613039979965784850055709534778197048463392328", "price": "0.58", "size": "107", "side": "SELL", "hash": "5b5612f23f896b395a0c7e9571c049640e233cc3", "best_bid": "0.56", "best_ask": "0.58"}], "timestamp": "1769384162584", "event_type": "price_change"}}
{"_local_timestamp": "2026-01-25T23:36:02.764970+00:00", "data": {"market": "0x5399e84f207adf1614c642b1b0829b110159c91cf7331f567b88a1dcf587e779", "price_changes": [{"asset_id": "100715172532828128539584818881319138941352610561521393079458208964903259330699", "price": "0.41", "size": "148", "side": "BUY", "hash": "717737754fd6e67b52ac57842f4eb2d06811af79", "best_bid": "0.42", "best_ask": "0.44"}, {"asset_id": "87540986142349541251416387669319613039979965784850055709534778197048463392328", "price": "0.59", "size": "148", "side": "SELL", "hash": "33f1b44f755e27c35543a00ac7984e16959e0651", "best_bid": "0.56", "best_ask": "0.58"}], "timestamp": "1769384162699", "event_type": "price_change"}}
{"_local_timestamp": "2026-01-25T23:36:11.232975+00:00", "data": {"market": "0x5399e84f207adf1614c642b1b0829b110159c91cf7331f567b88a1dcf587e779", "price_changes": [{"asset_id": "100715172532828128539584818881319138941352610561521393079458208964903259330699", "price": "0.42", "size": "160", "side": "BUY", "hash": "e2ee78a0ea51f5d50d1e7df55038bf0079e59c5f", "best_bid": "0.42", "best_ask": "0.44"}, {"asset_id": "87540986142349541251416387669319613039979965784850055709534778197048463392328", "price": "0.58", "size": "160", "side": "SELL", "hash": "ee5c934b0275348f33802ac6e3592a2a583cdc95", "best_bid": "0.56", "best_ask": "0.58"}], "timestamp": "1769384171165", "event_type": "price_change"}}
{"_local_timestamp": "2026-01-25T23:36:11.631404+00:00", "data": {"market": "0x5399e84f207adf1614c642b1b0829b110159c91cf7331f567b88a1dcf587e779", "price_changes": [{"asset_id": "100715172532828128539584818881319138941352610561521393079458208964903259330699", "price": "0.41", "size": "95", "side": "BUY", "hash": "9ec7c3a7f70a4b155440941aeece306a5320ea35", "best_bid": "0.42", "best_ask": "0.44"}, {"asset_id": "87540986142349541251416387669319613039979965784850055709534778197048463392328", "price": "0.59", "size": "95", "side": "SELL", "hash": "6054844f66af1bc4fbf67162130b4793c11867ae", "best_bid": "0.56", "best_ask": "0.58"}], "timestamp": "1769384171560", "event_type": "price_change"}}
{"_local_timestamp": "2026-01-25T23:36:23.276886+00:00", "data": {"market": "0x5399e84f207adf1614c642b1b0829b110159c91cf7331f567b88a1dcf587e779", "price_changes": [{"asset_id": "100715172532828128539584818881319138941352610561521393079458208964903259330699", "price": "0.42", "size": "107", "side": "BUY", "hash": "963108491f51896ec2c635759fc7997f34bbbacb", "best_bid": "0.42", "best_ask": "0.44"}, {"asset_id": "87540986142349541251416387669319613039979965784850055709534778197048463392328", "price": "0.58", "size": "107", "side": "SELL", "hash": "2b3ddc412cb5f8e8e6e4069ab033852acabd4a40", "best_bid": "0.56", "best_ask": "0.58"}], "timestamp": "1769384183204", "event_type": "price_change"}}
{"_local_timestamp": "2026-01-25T23:36:23.277349+00:00", "data": {"market": "0x5399e84f207adf1614c642b1b0829b110159c91cf7331f567b88a1dcf587e779", "price_changes": [{"asset_id": "100715172532828128539584818881319138941352610561521393079458208964903259330699", "price": "0.41", "size": "148", "side": "BUY", "hash": "ca790d9427d90059beea57b6425945251bcc7a1b", "best_bid": "0.42", "best_ask": "0.44"}, {"asset_id": "87540986142349541251416387669319613039979965784850055709534778197048463392328", "price": "0.59", "size": "148", "side": "SELL", "hash": "1f11a621ab166c714a07bfd2b9303d6f2f3188f6", "best_bid": "0.56", "best_ask": "0.58"}], "timestamp": "1769384183208", "event_type": "price_change"}}
{"_local_timestamp": "2026-01-25T23:36:25.052636+00:00", "data": {"market": "0x937de722f8deb4c75aa4a307cb8e5eeb2510a6b5ea86f76ca09a2dc0cd20a4bc", "price_changes": [{"asset_id": "42980630208864318379919380711046026375503533727978237281500044871471440019852", "price": "0.38", "size": "0", "side": "BUY", "hash": "83670b21319aa7dbfd7ba801011012fe22cfb900", "best_bid": "0.37", "best_ask": "0.41"}, {"asset_id": "54159141424996573001673795486235351282895050934599122504282991350686939527644", "price": "0.62", "size": "0", "side": "SELL", "hash": "7fdd5ef0dc02950d53efed0c46df46f773e5ddb8", "best_bid": "0.59", "best_ask": "0.63"}], "timestamp": "1769384184985", "event_type": "price_change"}}
{"_local_timestamp": "2026-01-25T23:36:25.618778+00:00", "data": {"market": "0x937de722f8deb4c75aa4a307cb8e5eeb2510a6b5ea86f76ca09a2dc0cd20a4bc", "price_changes": [{"asset_id": "42980630208864318379919380711046026375503533727978237281500044871471440019852", "price": "0.37", "size": "144", "side": "BUY", "hash": "5d5c0a2b21cf572b45f963909060e149800f8d05", "best_bid": "0.37", "best_ask": "0.41"}, {"asset_id": "54159141424996573001673795486235351282895050934599122504282991350686939527644", "price": "0.63", "size": "144", "side": "SELL", "hash": "d1d4eb6073aa3d896863db9519c246d5c4b43c77", "best_bid": "0.59", "best_ask": "0.63"}], "timestamp": "1769384185547", "event_type": "price_change"}}
{"_local_timestamp": "2026-01-25T23:36:25.987692+00:00", "data": {"market": "0x937de722f8deb4c75aa4a307cb8e5eeb2510a6b5ea86f76ca09a2dc0cd20a4bc", "price_changes": [{"asset_id": "42980630208864318379919380711046026375503533727978237281500044871471440019852", "price": "0.37", "size": "101", "side": "BUY", "hash": "68a3470895bca27b634fa7632fea1e8c1c1c9c0d", "best_bid": "0.37", "best_ask": "0.41"}, {"asset_id": "54159141424996573001673795486235351282895050934599122504282991350686939527644", "price": "0.63", "size": "101", "side": "SELL", "hash": "d6007da2d11bc1b823436cd4fc9ee533fa32d850", "best_bid": "0.59", "best_ask": "0.63"}], "timestamp": "1769384185922", "event_type": "price_change"}}
{"_local_timestamp": "2026-01-25T23:36:33.701054+00:00", "data": {"market": "0x937de722f8deb4c75aa4a307cb8e5eeb2510a6b5ea86f76ca09a2dc0cd20a4bc", "price_changes": [{"asset_id": "42980630208864318379919380711046026375503533727978237281500044871471440019852", "price": "0.38", "size": "43", "side": "BUY", "hash": "0bdec28a8fa8a41aeebb6e2b94f6b6e6ea995e96", "best_bid": "0.38", "best_ask": "0.41"}, {"asset_id": "54159141424996573001673795486235351282895050934599122504282991350686939527644", "price": "0.62", "size": "43", "side": "SELL", "hash": "47e8bb76d0a84bda5180111585d33db8c5bcf886", "best_bid": "0.59", "best_ask": "0.62"}], "timestamp": "1769384193628", "event_type": "price_change"}}
{"_local_timestamp": "2026-01-25T23:36:54.254781+00:00", "data": {"market": "0xe91afed2cf59036aa2263e56d7928a5ae8ee85d54b1b46ccf679cf12ef664753", "price_changes": [{"asset_id": "52571443025345708025030679766882856603822335849274985584394259288472261399283", "price": "0.79", "size": "91.5", "side": "BUY", "hash": "920359ef7d7bc8496ee2a42c21d529f29177974d", "best_bid": "0.79", "best_ask": "0.82"}, {"asset_id": "63152720970971968001690179005626043167942208308910151565176976232568233779040", "price": "0.21", "size": "91.5", "side": "SELL", "hash": "7084f22ecc4652f9e266ee0f1dbb562b2e689fc4", "best_bid": "0.18", "best_ask": "0.21"}], "timestamp": "1769384214190", "event_type": "price_change"}}
{"_local_timestamp": "2026-01-25T23:36:57.769700+00:00", "data": {"market": "0x937de722f8deb4c75aa4a307cb8e5eeb2510a6b5ea86f76ca09a2dc0cd20a4bc", "price_changes": [{"asset_id": "42980630208864318379919380711046026375503533727978237281500044871471440019852", "price": "0.1", "size": "300", "side": "BUY", "hash": "6968fc00d36b2dbd82b6109818979fb5e5f3d860", "best_bid": "0.38", "best_ask": "0.41"}, {"asset_id": "54159141424996573001673795486235351282895050934599122504282991350686939527644", "price": "0.9", "size": "300", "side": "SELL", "hash": "7a5c2cffe162ab302d02e4bc010737e2611abaa1", "best_bid": "0.59", "best_ask": "0.62"}], "timestamp": "1769384217248", "event_type": "price_change"}}
{"_local_timestamp": "2026-01-25T23:37:40.016512+00:00", "data": {"market": "0x937de722f8deb4c75aa4a307cb8e5eeb2510a6b5ea86f76ca09a2dc0cd20a4bc", "price_changes": [{"asset_id": "42980630208864318379919380711046026375503533727978237281500044871471440019852", "price": "0.11", "size": "289", "side": "BUY", "hash": "7d09167e9a44522985d415e56636024c9fa11c2a", "best_bid": "0.38", "best_ask": "0.41"}, {"asset_id": "54159141424996573001673795486235351282895050934599122504282991350686939527644", "price": "0.89", "size": "289", "side": "SELL", "hash": "a7711bf54117c78867b215eb6235c2058b85e988", "best_bid": "0.59", "best_ask": "0.62"}], "timestamp": "1769384259945", "event_type": "price_change"}}
{"_local_timestamp": "2026-01-25T23:37:57.031172+00:00", "data": {"market": "0x5399e84f207adf1614c642b1b0829b110159c91cf7331f567b88a1dcf587e779", "price_changes": [{"asset_id": "100715172532828128539584818881319138941352610561521393079458208964903259330699", "price": "0.41", "size": "95", "side": "BUY", "hash": "d0a01ea3986272e6e39f0b4d7bc461ac2639ce6d", "best_bid": "0.42", "best_ask": "0.44"}, {"asset_id": "87540986142349541251416387669319613039979965784850055709534778197048463392328", "price": "0.59", "size": "95", "side": "SELL", "hash": "cb1317c0911361b310d413604a56754cfaf2d50c", "best_bid": "0.56", "best_ask": "0.58"}], "timestamp": "1769384276913", "event_type": "price_change"}}
{"_local_timestamp": "2026-01-25T23:38:00.701204+00:00", "data": {"market": "0x5399e84f207adf1614c642b1b0829b110159c91cf7331f567b88a1dcf587e779", "price_changes": [{"asset_id": "100715172532828128539584818881319138941352610561521393079458208964903259330699", "price": "0.41", "size": "148", "side": "BUY", "hash": "d695325b107ff0c62144e96d450e086aaf293506", "best_bid": "0.42", "best_ask": "0.44"}, {"asset_id": "87540986142349541251416387669319613039979965784850055709534778197048463392328", "price": "0.59", "size": "148", "side": "SELL", "hash": "1719788dab74cfb45f60f068ce24f673f8f687f1", "best_bid": "0.56", "best_ask": "0.58"}], "timestamp": "1769384280629", "event_type": "price_change"}}
{"_local_timestamp": "2026-01-25T23:38:13.283316+00:00", "data": {"market": "0x5399e84f207adf1614c642b1b0829b110159c91cf7331f567b88a1dcf587e779", "price_changes": [{"asset_id": "100715172532828128539584818881319138941352610561521393079458208964903259330699", "price": "0.41", "size": "95", "side": "BUY", "hash": "43d883ba180c9a4c3f0898357df293dce24367af", "best_bid": "0.42", "best_ask": "0.44"}, {"asset_id": "87540986142349541251416387669319613039979965784850055709534778197048463392328", "price": "0.59", "size": "95", "side": "SELL", "hash": "e32b872c0372e3e6885f6880e1e3c96ed99ffc5b", "best_bid": "0.56", "best_ask": "0.58"}], "timestamp": "1769384293219", "event_type": "price_change"}}
{"_local_timestamp": "2026-01-25T23:38:13.792129+00:00", "data": {"market": "0x5399e84f207adf1614c642b1b0829b110159c91cf7331f567b88a1dcf587e779", "price_changes": [{"asset_id": "100715172532828128539584818881319138941352610561521393079458208964903259330699", "price": "0.41", "size": "148", "side": "BUY", "hash": "695ef49272ecf68142c0ecdd0c47270d2fae8f03", "best_bid": "0.42", "best_ask": "0.44"}, {"asset_id": "87540986142349541251416387669319613039979965784850055709534778197048463392328", "price": "0.59", "size": "148", "side": "SELL", "hash": "8424144de5d26fa3b67c65a78fd9df5b5ab12d7c", "best_bid": "0.56", "best_ask": "0.58"}], "timestamp": "1769384293725", "event_type": "price_change"}}
{"_local_timestamp": "2026-01-25T23:38:18.083220+00:00", "data": {"market": "0xe85f66ca3258249e3fa3cfb7eded108c31a854af9eb1d0f2e1c463d787bd587e", "price_changes": [{"asset_id": "9959766640993038566313541584805552672310282986889616646650002978435506606528", "price": "0.32", "size": "25600", "side": "BUY", "hash": "b786a8bfa443bd4fbfc714d3ddde866c5cef7e0f", "best_bid": "0.33", "best_ask": "0.36"}, {"asset_id": "89085785705693135663344595542401989320859278708688805320605944475346324962521", "price": "0.68", "size": "25600", "side": "SELL", "hash": "08d16d8f5c626c265f41f563e084679d0286dc43", "best_bid": "0.64", "best_ask": "0.67"}], "timestamp": "1769384298000", "event_type": "price_change"}}
{"_local_timestamp": "2026-01-25T23:38:18.120366+00:00", "data": {"market": "0xe91afed2cf59036aa2263e56d7928a5ae8ee85d54b1b46ccf679cf12ef664753", "price_changes": [{"asset_id": "63152720970971968001690179005626043167942208308910151565176976232568233779040", "price": "0.18", "size": "134", "side": "BUY", "hash": "a4f0e536cce9459eec4bb0cd6446ad9c1d7ecde2", "best_bid": "0.18", "best_ask": "0.21"}, {"asset_id": "52571443025345708025030679766882856603822335849274985584394259288472261399283", "price": "0.82", "size": "134", "side": "SELL", "hash": "7595ca29c97e5c41d8becf885c1afe6c1447e858", "best_bid": "0.79", "best_ask": "0.82"}], "timestamp": "1769384298003", "event_type": "price_change"}}
{"_local_timestamp": "2026-01-25T23:38:33.085052+00:00", "data": {"market": "0xe91afed2cf59036aa2263e56d7928a5ae8ee85d54b1b46ccf679cf12ef664753", "price_changes": [{"asset_id": "63152720970971968001690179005626043167942208308910151565176976232568233779040", "price": "0.18", "size": "204", "side": "BUY", "hash": "c17147aefbcdef6f4b9b667541277d4a33170c3f", "best_bid": "0.18", "best_ask": "0.21"}, {"asset_id": "52571443025345708025030679766882856603822335849274985584394259288472261399283", "price": "0.82", "size": "204", "side": "SELL", "hash": "845e6ac16bc1b91cf93e656615345c2454eb74c6", "best_bid": "0.79", "best_ask": "0.82"}], "timestamp": "1769384313003", "event_type": "price_change"}}
{"_local_timestamp": "2026-01-25T23:38:33.215275+00:00", "data": {"market": "0x5399e84f207adf1614c642b1b0829b110159c91cf7331f567b88a1dcf587e779", "price_changes": [{"asset_id": "100715172532828128539584818881319138941352610561521393079458208964903259330699", "price": "0.41", "size": "95", "side": "BUY", "hash": "3b1f15e9d846b8c7e28a7377556b9d127300925f", "best_bid": "0.42", "best_ask": "0.44"}, {"asset_id": "87540986142349541251416387669319613039979965784850055709534778197048463392328", "price": "0.59", "size": "95", "side": "SELL", "hash": "c4d5d73950ab7e69b72c844fa12258a68272b87b", "best_bid": "0.56", "best_ask": "0.58"}], "timestamp": "1769384313147", "event_type": "price_change"}}
{"_local_timestamp": "2026-01-25T23:38:33.791535+00:00", "data": {"market": "0x5399e84f207adf1614c642b1b0829b110159c91cf7331f567b88a1dcf587e779", "price_changes": [{"asset_id": "100715172532828128539584818881319138941352610561521393079458208964903259330699", "price": "0.42", "size": "160", "side": "BUY", "hash": "4b643c7c2de1f9909d91b03298ce6184dbe181af", "best_bid": "0.42", "best_ask": "0.44"}, {"asset_id": "87540986142349541251416387669319613039979965784850055709534778197048463392328", "price": "0.58", "size": "160", "side": "SELL", "hash": "42809e03bd482ad1e5ad8da5d741115750f1d8eb", "best_bid": "0.56", "best_ask": "0.58"}], "timestamp": "1769384313719", "event_type": "price_change"}}
{"_local_timestamp": "2026-01-25T23:38:37.017040+00:00", "data": {"market": "0xe85f66ca3258249e3fa3cfb7eded108c31a854af9eb1d0f2e1c463d787bd587e", "price_changes": [{"asset_id": "9959766640993038566313541584805552672310282986889616646650002978435506606528", "price": "0.32", "size": "25665.09", "side": "BUY", "hash": "c7422193c89b54a2fa0aea250d93ec46fb097da6", "best_bid": "0.33", "best_ask": "0.36"}, {"asset_id": "89085785705693135663344595542401989320859278708688805320605944475346324962521", "price": "0.68", "size": "25665.09", "side": "SELL", "hash": "a17c7c8a87bc15fdc8f76d45eb4a8aad04cc4fd9", "best_bid": "0.64", "best_ask": "0.67"}], "timestamp": "1769384316945", "event_type": "price_change"}}
{"_local_timestamp": "2026-01-25T23:38:39.112347+00:00", "data": {"market": "0x53d7dab8196554be4d3198f446427d886a1b0cca4af0d980b5db69781d3065a9", "price_changes": [{"asset_id": "50416017845112722830648576285355962859836703684331757667284549974224475224302", "price": "0.02", "size": "700", "side": "BUY", "hash": "5dab976cfaeb6ac4d4f53511f8a0d81cb7e5c899", "best_bid": "0.81", "best_ask": "0.83"}, {"asset_id": "98584735062828774636898378898502011795360187693844488208471424555750267825841", "price": "0.98", "size": "700", "side": "SELL", "hash": "55bc158f95a07663c19a5c9447d2d35c2b38323f", "best_bid": "0.17", "best_ask": "0.19"}], "timestamp": "1769384319000", "event_type": "price_change"}}
{"_local_timestamp": "2026-01-25T23:38:39.124678+00:00", "data": {"market": "0x53d7dab8196554be4d3198f446427d886a1b0cca4af0d980b5db69781d3065a9", "price_changes": [{"asset_id": "98584735062828774636898378898502011795360187693844488208471424555750267825841", "price": "0.02", "size": "60", "side": "BUY", "hash": "b35d2c643ea71bfe8795efa7927f0e3ee6e4c831", "best_bid": "0.17", "best_ask": "0.19"}, {"asset_id": "50416017845112722830648576285355962859836703684331757667284549974224475224302", "price": "0.98", "size": "60", "side": "SELL", "hash": "0cadbd859453e6c30f2b08beab9b8204a5d80243", "best_bid": "0.81", "best_ask": "0.83"}], "timestamp": "1769384319005", "event_type": "price_change"}}
{"_local_timestamp": "2026-01-25T23:38:45.266560+00:00", "data": {"market": "0x53d7dab8196554be4d3198f446427d886a1b0cca4af0d980b5db69781d3065a9", "price_changes": [{"asset_id": "50416017845112722830648576285355962859836703684331757667284549974224475224302", "price": "0.02", "size": "850", "side": "BUY", "hash": "5c20aeccffa8913ec71c1fa7a4bb0a439c826546", "best_bid": "0.81", "best_ask": "0.83"}, {"asset_id": "98584735062828774636898378898502011795360187693844488208471424555750267825841", "price": "0.98", "size": "850", "side": "SELL", "hash": "ea7b1f7a4565b97d3d9d2da4e976b930c1a461c2", "best_bid": "0.17", "best_ask": "0.19"}], "timestamp": "1769384325198", "event_type": "price_change"}}
{"_local_timestamp": "2026-01-25T23:38:45.267048+00:00", "data": {"market": "0x53d7dab8196554be4d3198f446427d886a1b0cca4af0d980b5db69781d3065a9", "price_changes": [{"asset_id": "98584735062828774636898378898502011795360187693844488208471424555750267825841", "price": "0.02", "size": "210", "side": "BUY", "hash": "5c6dd11ecd615b244ee3c6ddd8843ffe4e72720d", "best_bid": "0.17", "best_ask": "0.19"}, {"asset_id": "50416017845112722830648576285355962859836703684331757667284549974224475224302", "price": "0.98", "size": "210", "side": "SELL", "hash": "90294839dd5e08b6e7c6ed930efaba44baf56bf7", "best_bid": "0.81", "best_ask": "0.83"}], "timestamp": "1769384325199", "event_type": "price_change"}}
{"_local_timestamp": "2026-01-25T23:38:59.014115+00:00", "data": {"market": "0x937de722f8deb4c75aa4a307cb8e5eeb2510a6b5ea86f76ca09a2dc0cd20a4bc", "price_changes": [{"asset_id": "42980630208864318379919380711046026375503533727978237281500044871471440019852", "price": "0.1", "size": "0", "side": "BUY", "hash": "d0c33071bac7876c8a6421f78125e44d55b29c23", "best_bid": "0.38", "best_ask": "0.41"}, {"asset_id": "54159141424996573001673795486235351282895050934599122504282991350686939527644", "price": "0.9", "size": "0", "side": "SELL", "hash": "d99a7aa47d0e3a47ece0e5b9dd2463bc86f2ab60", "best_bid": "0.59", "best_ask": "0.62"}], "timestamp": "1769384338933", "event_type": "price_change"}}
{"_local_timestamp": "2026-01-25T23:38:59.557569+00:00", "data": {"market": "0x937de722f8deb4c75aa4a307cb8e5eeb2510a6b5ea86f76ca09a2dc0cd20a4bc", "price_changes": [{"asset_id": "42980630208864318379919380711046026375503533727978237281500044871471440019852", "price": "0.11", "size": "389", "side": "BUY", "hash": "271f10ed2346ce585505d29f2b532a8fd4f173b7", "best_bid": "0.38", "best_ask": "0.41"}, {"asset_id": "54159141424996573001673795486235351282895050934599122504282991350686939527644", "price": "0.89", "size": "389", "side": "SELL", "hash": "7ece46f48e644a9f2582d92634bea1f9f48af0f1", "best_bid": "0.59", "best_ask": "0.62"}], "timestamp": "1769384339464", "event_type": "price_change"}}
{"_local_timestamp": "2026-01-25T23:40:07.171620+00:00", "data": {"market": "0x5399e84f207adf1614c642b1b0829b110159c91cf7331f567b88a1dcf587e779", "price_changes": [{"asset_id": "100715172532828128539584818881319138941352610561521393079458208964903259330699", "price": "0.41", "size": "148", "side": "BUY", "hash": "8999ed8acdd960c12dfa60f54f6cc1d6baff295b", "best_bid": "0.42", "best_ask": "0.44"}, {"asset_id": "87540986142349541251416387669319613039979965784850055709534778197048463392328", "price": "0.59", "size": "148", "side": "SELL", "hash": "a3116ab73d6742e12976a9f450085c1c95147b54", "best_bid": "0.56", "best_ask": "0.58"}], "timestamp": "1769384407097", "event_type": "price_change"}}
{"_local_timestamp": "2026-01-25T23:40:07.172396+00:00", "data": {"market": "0x5399e84f207adf1614c642b1b0829b110159c91cf7331f567b88a1dcf587e779", "price_changes": [{"asset_id": "100715172532828128539584818881319138941352610561521393079458208964903259330699", "price": "0.42", "size": "107", "side": "BUY", "hash": "85e899f9d0f03154f6afcf56677c8ac804a301dd", "best_bid": "0.42", "best_ask": "0.44"}, {"asset_id": "87540986142349541251416387669319613039979965784850055709534778197048463392328", "price": "0.58", "size": "107", "side": "SELL", "hash": "a63b1a91d92209985f23bf8cee3abd87d3621487", "best_bid": "0.56", "best_ask": "0.58"}], "timestamp": "1769384407097", "event_type": "price_change"}}
{"_local_timestamp": "2026-01-25T23:40:11.501788+00:00", "data": {"market": "0x5399e84f207adf1614c642b1b0829b110159c91cf7331f567b88a1dcf587e779", "price_changes": [{"asset_id": "100715172532828128539584818881319138941352610561521393079458208964903259330699", "price": "0.41", "size": "95", "side": "BUY", "hash": "9b3d294446abdcb7d43eb0cbd28e114ae2603c02", "best_bid": "0.42", "best_ask": "0.44"}, {"asset_id": "87540986142349541251416387669319613039979965784850055709534778197048463392328", "price": "0.59", "size": "95", "side": "SELL", "hash": "25b4472726beda41041e1aded0d949146e3de291", "best_bid": "0.56", "best_ask": "0.58"}], "timestamp": "1769384411434", "event_type": "price_change"}}
{"_local_timestamp": "2026-01-25T23:40:15.692282+00:00", "data": {"market": "0x5399e84f207adf1614c642b1b0829b110159c91cf7331f567b88a1dcf587e779", "price_changes": [{"asset_id": "100715172532828128539584818881319138941352610561521393079458208964903259330699", "price": "0.41", "size": "148", "side": "BUY", "hash": "68020d75687afbcaa2f2a883d9224db56bfe5123", "best_bid": "0.42", "best_ask": "0.44"}, {"asset_id": "87540986142349541251416387669319613039979965784850055709534778197048463392328", "price": "0.59", "size": "148", "side": "SELL", "hash": "6b1985db6c63aa8991b8d1e42a1b494e9c486f17", "best_bid": "0.56", "best_ask": "0.58"}], "timestamp": "1769384415624", "event_type": "price_change"}}
