{"_local_timestamp": "2026-01-25T23:40:56.779030+00:00", "data": [{"market": "0x85096ae131a795ac80db209f9e633e5310fd4fd11b3c2e8b2748614139480c41", "asset_id": "87939649752104648558739188569294623185189846388915750654886353417082965270846", "timestamp": "1769384339464", "hash": "a72a18b7dd7e7e7df819c7d03b655351912e58aa", "bids": [{"price": "0.01", "size": "104.34"}, {"price": "0.02", "size": "850"}, {"price": "0.03", "size": "9.52"}, {"price": "0.05", "size": "500"}, {"price": "0.1", "size": "6.1"}, {"price": "0.13", "size": "237"}, {"price": "0.26", "size": "50"}, {"price": "0.27", "size": "40.74"}, {"price": "0.81", "size": "90"}, {"price": "0.82", "size": "100"}, {"price": "0.84", "size": "350"}, {"price": "0.88", "size": "45"}], "asks": [{"price": "0.99", "size": "489"}, {"price": "0.98", "size": "163.28"}, {"price": "0.97", "size": "77"}, {"price": "0.96", "size": "18.36"}, {"price": "0.93", "size": "364.2"}, {"price": "0.92", "size": "270"}, {"price": "0.91", "size": "115"}], "event_type": "book", "last_trade_price": ""}, {"market": "0x92dbb7abf136a99dbdbd0bf6b3e168324aba36c885f050a81b9f99f5c86a2c89", "asset_id": "85926585546290965710378781547851562606368161566069895279131565989650277464683", "timestamp": "1769384339464", "hash": "534d53dea5529136bee5b735497b90736347eff8", "bids": [{"price": "0.01", "size": "155.14"}, {"price": "0.02", "size": "1100"}, {"price": "0.03", "size": "8.28"}, {"price": "0.04", "size": "37"}, {"price": "0.05", "size": "500"}, {"price": "0.06", "size": "33"}, {"price": "0.08", "size": "300"}, {"price": "0.09", "size": "7.22"}, {"price": "0.23", "size": "56.52"}, {"price": "0.24", "size": "45.83"}, {"price": "0.64", "size": "100294.5"}, {"price": "0.66", "size": "226"}, {"price": "0.67", "size": "36"}], "asks": [{"price": "0.99", "size": "190"}, {"price": "0.98", "size": "909.25"}, {"price": "0.95", "size": "16.29"}, {"price": "0.93", "size": "800"}, {"price": "0.84", "size": "81.25"}, {"price": "0.83", "size": "64.7"}, {"price": "0.72", "size": "294.5"}, {"price": "0.7", "size": "331"}, {"price": "0.69", "size": "36"}], "event_type": "book", "last_trade_price": "0.280"}, {"market": "0xda3d932d75604f9eef2b0aac29e49132e7bff5b2ebec4d60e95cb9ad50a214ad", "asset_id": "9749864131097834365617477122730765285247792511165587454264409956819594383410", "timestamp": "1769383537052", "hash": "7f0d1a365b9e1ace2f7b0022ce2675abff5e673e", "bids": [{"price": "0.01", "size": "104.51"}, {"price": "0.02", "size": "850"}, {"price": "0.03", "size": "8.59"}, {"price": "0.06", "size": "750"}, {"price": "0.08", "size": "300"}, {"price": "0.09", "size": "7.07"}, {"price": "0.3", "size": "18364.5"}, {"price": "0.33", "size": "15447"}, {"price": "0.36", "size": "12732"}, {"price": "0.39", "size": "10159.5"}, {"price": "0.42", "size": "7702.5"}, {"price": "0.43", "size": "100"}, {"price": "0.44", "size": "29.54"}, {"price": "0.45", "size": "5428.75"}, {"price": "0.46", "size": "23.91"}, {"price": "0.47", "size": "100"}, {"price": "0.48", "size": "3631"}, {"price": "0.49", "size": "3145"}, {"price": "0.5", "size": "30713.38"}, {"price": "0.51", "size": "1487"}], "asks": [{"price": "0.99", "size": "99.43"}, {"price": "0.98", "size": "850"}, {"price": "0.97", "size": "10.12"}, {"price": "0.95", "size": "500"}, {"price": "0.91", "size": "454"}, {"price": "0.9", "size": "5.91"}, {"price": "0.76", "size": "19717.5"}, {"price": "0.73", "size": "16373.25"}, {"price": "0.72", "size": "46.42"}, {"price": "0.71", "size": "37.93"}, {"price": "0.7", "size": "13356"}, {"price": "0.67", "size": "10569"}, {"price": "0.64", "size": "7957.5"}, {"price": "0.61", "size": "5470.5"}, {"price": "0.58", "size": "3274"}, {"price": "0.57", "size": "3167"}, {"price": "0.56", "size": "3054"}, {"price": "0.55", "size": "25609.71"}, {"price": "0.54", "size": "315"}, {"price": "0.53", "size": "45"}], "event_type": "book", "last_trade_price": "0.520"}, {"market": "0x92dbb7abf136a99dbdbd0bf6b3e168324aba36c885f050a81b9f99f5c86a2c89", "asset_id": "742549944322286743622311352663151843513942481342353661165797752687706656334", "timestamp": "1769384339464", "hash": "121d6be65fdb7595932e23619dc7700f8d2b8935", "bids": [{"price": "0.01", "size": "190"}, {"price": "0.02", "size": "909.25"}, {"price": "0.05", "size": "16.29"}, {"price": "0.07", "size": "800"}, {"price": "0.16", "size": "81.25"}, {"price": "0.17", "size": "64.7"}, {"price": "0.28", "size": "294.5"}, {"price": "0.3", "size": "331"}, {"price": "0.31", "size": "36"}], "asks": [{"price": "0.99", "size": "155.14"}, {"price": "0.98", "size": "1100"}, {"price": "0.97", "size": "8.28"}, {"price": "0.96", "size": "37"}, {"price": "0.95", "size": "500"}, {"price": "0.94", "size": "33"}, {"price": "0.92", "size": "300"}, {"price": "0.91", "size": "7.22"}, {"price": "0.77", "size": "56.52"}, {"price": "0.76", "size": "45.83"}, {"price": "0.36", "size": "100294.5"}, {"price": "0.34", "size": "226"}, {"price": "0.33", "size": "36"}], "event_type": "book", "last_trade_price": "0.280"}, {"market": "0xe1d8d93576a561c63ef303c278dac376a95e71e88f956b488c25b08688a81b57", "asset_id": "110252161993776196960668611920941766461422541474085598864316166041753604647992", "timestamp": "1769383943550", "hash": "36530da4998107d9764a84aaf6e02bc3ab8abf21", "bids": [{"price": "0.01", "size": "97.1"}, {"price": "0.02", "size": "150"}, {"price": "0.03", "size": "70882.5"}, {"price": "0.04", "size": "250"}, {"price": "0.06", "size": "35610.75"}, {"price": "0.07", "size": "9.69"}, {"price": "0.09", "size": "22992"}, {"price": "0.12", "size": "15952.08"}, {"price": "0.13", "size": "84.61"}, {"price": "0.15", "size": "10890"}, {"price": "0.18", "size": "7019.25"}, {"price": "0.21", "size": "3765"}, {"price": "0.22", "size": "3699"}, {"price": "0.23", "size": "3639"}, {"price": "0.24", "size": "551"}, {"price": "0.25", "size": "25718"}, {"price": "0.26", "size": "170"}, {"price": "0.27", "size": "45"}], "asks": [{"price": "0.99", "size": "103.97"}, {"price": "0.98", "size": "1100"}, {"price": "0.97", "size": "8.15"}, {"price": "0.95", "size": "500"}, {"price": "0.92", "size": "300"}, {"price": "0.91", "size": "7.28"}, {"price": "0.75", "size": "52"}, {"price": "0.74", "size": "42.3"}, {"price": "0.53", "size": "16632"}, {"price": "0.5", "size": "14250"}, {"price": "0.47", "size": "11928"}, {"price": "0.44", "size": "9662.25"}, {"price": "0.41", "size": "7417.5"}, {"price": "0.38", "size": "5197.5"}, {"price": "0.37", "size": "100"}, {"price": "0.35", "size": "3079"}, {"price": "0.34", "size": "3082"}, {"price": "0.33", "size": "3555"}, {"price": "0.32", "size": "466"}, {"price": "0.31", "size": "25750"}, {"price": "0.3", "size": "45"}], "event_type": "book", "last_trade_price": ""}, {"market": "0xe1d8d93576a561c63ef303c278dac376a95e71e88f956b488c25b08688a81b57", "asset_id": "65973752395054621107714955397531733385161540393395321312831009365229146782387", "timestamp": "1769383943550", "hash": "29ef7528f3a1584fbdff18b8a3faa8aba83d6965", "bids": [{"price": "0.01", "size": "103.97"}, {"price": "0.02", "size": "1100"}, {"price": "0.03", "size": "8.15"}, {"price": "0.05", "size": "500"}, {"price": "0.08", "size": "300"}, {"price": "0.09", "size": "7.28"}, {"price": "0.25", "size": "52"}, {"price": "0.26", "size": "42.3"}, {"price": "0.47", "size": "16632"}, {"price": "0.5", "size": "14250"}, {"price": "0.53", "size": "11928"}, {"price": "0.56", "size": "9662.25"}, {"price": "0.59", "size": "7417.5"}, {"price": "0.62", "size": "5197.5"}, {"price": "0.63", "size": "100"}, {"price": "0.65", "size": "3079"}, {"price": "0.66", "size": "3082"}, {"price": "0.67", "size": "3555"}, {"price": "0.68", "size": "466"}, {"price": "0.69", "size": "25750"}, {"price": "0.7", "size": "45"}], "asks": [{"price": "0.99", "size": "97.1"}, {"price": "0.98", "size": "150"}, {"price": "0.97", "size": "70882.5"}, {"price": "0.96", "size": "250"}, {"price": "0.94", "size": "35610.75"}, {"price": "0.93", "size": "9.69"}, {"price": "0.91", "size": "22992"}, {"price": "0.88", "size": "15952.08"}, {"price": "0.87", "size": "84.61"}, {"price": "0.85", "size": "10890"}, {"price": "0.82", "size": "7019.25"}, {"price": "0.79", "size": "3765"}, {"price": "0.78", "size": "3699"}, {"price": "0.77", "size": "3639"}, {"price": "0.76", "size": "551"}, {"price": "0.75", "size": "25718"}, {"price": "0.74", "size": "170"}, {"price": "0.73", "size": "45"}], "event_type": "book", "last_trade_price": ""}, {"market": "0xa144885538281db77b81b3bc88ea29d6332d88f6ab95e26aa5adb287cde301d6", "asset_id": "113861618415069729564597166750878018457148842262819426612500520860061156510491", "timestamp": "1769383537044", "hash": "9a497a892270b3de4d12a22874e39e11756c56c2", "bids": [{"price": "0.01", "size": "94.21"}, {"price": "0.02", "size": "859.18"}, {"price": "0.05", "size": "500"}, {"price": "0.06", "size": "12.73"}, {"price": "0.13", "size": "238"}, {"price": "0.24", "size": "54.16"}, {"price": "0.25", "size": "44"}, {"price": "0.41", "size": "17011.5"}, {"price": "0.44", "size": "14506.5"}, {"price": "0.47", "size": "12096"}, {"price": "0.5", "size": "9750"}, {"price": "0.53", "size": "7455"}, {"price": "0.56", "size": "5202.75"}, {"price": "0.59", "size": "2967"}, {"price": "0.6", "size": "2967"}, {"price": "0.61", "size": "2967"}, {"price": "0.62", "size": "100"}, {"price": "0.64", "size": "350"}, {"price": "0.65", "size": "25703"}, {"price": "0.66", "size": "516"}, {"price": "0.67", "size": "153"}], "asks": [{"price": "0.99", "size": "94"}, {"price": "0.98", "size": "856.23"}, {"price": "0.97", "size": "40"}, {"price": "0.96", "size": "7.63"}, {"price": "0.94", "size": "50"}, {"price": "0.92", "size": "34053"}, {"price": "0.91", "size": "250"}, {"price": "0.9", "size": "5.69"}, {"price": "0.89", "size": "24282"}, {"price": "0.86", "size": "18012"}, {"price": "0.83", "size": "13357.5"}, {"price": "0.8", "size": "9665"}, {"price": "0.79", "size": "52.38"}, {"price": "0.77", "size": "6368.25"}, {"price": "0.74", "size": "3489"}, {"price": "0.73", "size": "3970"}, {"price": "0.72", "size": "3688"}, {"price": "0.71", "size": "25704"}, {"price": "0.7", "size": "517"}, {"price": "0.69", "size": "26"}], "event_type": "book", "last_trade_price": ""}, {"market": "0xa144885538281db77b81b3bc88ea29d6332d88f6ab95e26aa5adb287cde301d6", "asset_id": "47125656062844317856889885896137727172968890279458526369610476685407136517672", "timestamp": "1769383537044", "hash": "d35f742d7dec95e8c2d8fdddec5a29ef8386b407", "bids": [{"price": "0.01", "size": "94"}, {"price": "0.02", "size": "856.23"}, {"price": "0.03", "size": "40"}, {"price": "0.04", "size": "7.63"}, {"price": "0.06", "size": "50"}, {"price": "0.08", "size": "34053"}, {"price": "0.09", "size": "250"}, {"price": "0.1", "size": "5.69"}, {"price": "0.11", "size": "24282"}, {"price": "0.14", "size": "18012"}, {"price": "0.17", "size": "13357.5"}, {"price": "0.2", "size": "9665"}, {"price": "0.21", "size": "52.38"}, {"price": "0.23", "size": "6368.25"}, {"price": "0.26", "size": "3489"}, {"price": "0.27", "size": "3970"}, {"price": "0.28", "size": "3688"}, {"price": "0.29", "size": "25704"}, {"price": "0.3", "size": "517"}, {"price": "0.31", "size": "26"}], "asks": [{"price": "0.99", "size": "94.21"}, {"price": "0.98", "size": "859.18"}, {"price": "0.95", "size": "500"}, {"price": "0.94", "size": "12.73"}, {"price": "0.87", "size": "238"}, {"price": "0.76", "size": "54.16"}, {"price": "0.75", "size": "44"}, {"price": "0.59", "size": "17011.5"}, {"price": "0.56", "size": "14506.5"}, {"price": "0.53", "size": "12096"}, {"price": "0.5", "size": "9750"}, {"price": "0.47", "size": "7455"}, {"price": "0.44", "size": "5202.75"}, {"price": "0.41", "size": "2967"}, {"price": "0.4", "size": "2967"}, {"price": "0.39", "size": "2967"}, {"price": "0.38", "size": "100"}, {"price": "0.36", "size": "350"}, {"price": "0.35", "size": "25703"}, {"price": "0.34", "size": "516"}, {"price": "0.33", "size": "153"}], "event_type": "book", "last_trade_price": ""}, {"market": "0xda3d932d75604f9eef2b0aac29e49132e7bff5b2ebec4d60e95cb9ad50a214ad", "asset_id": "29559395671818638141962984824853034620919750514683889452935133176263054426881", "timestamp": "1769383537052", "hash": "54181b829a59b3c52d8200b4d3a41f80dbc8c93f", "bids": [{"price": "0.01", "size": "99.43"}, {"price": "0.02", "size": "850"}, {"price": "0.03", "size": "10.12"}, {"price": "0.05", "size": "500"}, {"price": "0.09", "size": "454"}, {"price": "0.1", "size": "5.91"}, {"price": "0.24", "size": "19717.5"}, {"price": "0.27", "size": "16373.25"}, {"price": "0.28", "size": "46.42"}, {"price": "0.29", "size": "37.93"}, {"price": "0.3", "size": "13356"}, {"price": "0.33", "size": "10569"}, {"price": "0.36", "size": "7957.5"}, {"price": "0.39", "size": "5470.5"}, {"price": "0.42", "size": "3274"}, {"price": "0.43", "size": "3167"}, {"price": "0.44", "size": "3054"}, {"price": "0.45", "size": "25609.71"}, {"price": "0.46", "size": "315"}, {"price": "0.47", "size": "45"}], "asks": [{"price": "0.99", "size": "104.51"}, {"price": "0.98", "size": "850"}, {"price": "0.97", "size": "8.59"}, {"price": "0.94", "size": "750"}, {"price": "0.92", "size": "300"}, {"price": "0.91", "size": "7.07"}, {"price": "0.7", "size": "18364.5"}, {"price": "0.67", "size": "15447"}, {"price": "0.64", "size": "12732"}, {"price": "0.61", "size": "10159.5"}, {"price": "0.58", "size": "7702.5"}, {"price": "0.57", "size": "100"}, {"price": "0.56", "size": "29.54"}, {"price": "0.55", "size": "5428.75"}, {"price": "0.54", "size": "23.91"}, {"price": "0.53", "size": "100"}, {"price": "0.52", "size": "3631"}, {"price": "0.51", "size": "3145"}, {"price": "0.5", "size": "30713.38"}, {"price": "0.49", "size": "1487"}], "event_type": "book", "last_trade_price": "0.520"}, {"market": "0x85096ae131a795ac80db209f9e633e5310fd4fd11b3c2e8b2748614139480c41", "asset_id": "46550817779287714248071035919960687231435496748461488768996323006087698669681", "timestamp": "1769384339464", "hash": "f574a143a50d4fd24dd3ac21f36ea6778f68d4b0", "bids": [{"price": "0.01", "size": "489"}, {"price": "0.02", "size": "163.28"}, {"price": "0.03", "size": "77"}, {"price": "0.04", "size": "18.36"}, {"price": "0.07", "size": "364.2"}, {"price": "0.08", "size": "270"}, {"price": "0.09", "size": "115"}], "asks": [{"price": "0.99", "size": "104.34"}, {"price": "0.98", "size": "850"}, {"price": "0.97", "size": "9.52"}, {"price": "0.95", "size": "500"}, {"price": "0.9", "size": "6.1"}, {"price": "0.87", "size": "237"}, {"price": "0.74", "size": "50"}, {"price": "0.73", "size": "40.74"}, {"price": "0.19", "size": "90"}, {"price": "0.18", "size": "100"}, {"price": "0.16", "size": "350"}, {"price": "0.12", "size": "45"}], "event_type": "book", "last_trade_price": ""}]}
{"_local_timestamp": "2026-01-25T23:42:39.233027+00:00", "data": {"market": "0x85096ae131a795ac80db209f9e633e5310fd4fd11b3c2e8b2748614139480c41", "price_changes": [{"asset_id": "46550817779287714248071035919960687231435496748461488768996323006087698669681", "price": "0.09", "size": "45", "side": "BUY", "hash": "678200b477406e2e3702b389c69ef69366225890", "best_bid": "0.09", "best_ask": "0.12"}, {"asset_id": "87939649752104648558739188569294623185189846388915750654886353417082965270846", "price": "0.91", "size": "45", "side": "SELL", "hash": "268f812881538dcd03a1faa8c49e1f048af8d643", "best_bid": "0.88", "best_ask": "0.91"}], "timestamp": "1769384559025", "event_type": "price_change"}}
{"_local_timestamp": "2026-01-25T23:42:45.604230+00:00", "data": {"market": "0x85096ae131a795ac80db209f9e633e5310fd4fd11b3c2e8b2748614139480c41", "price_changes": [{"asset_id": "46550817779287714248071035919960687231435496748461488768996323006087698669681", "price": "0.09", "size": "115", "side": "BUY", "hash": "b90b08b935c3f9065b2ea5f1a98ac4616625f765", "best_bid": "0.09", "best_ask": "0.12"}, {"asset_id": "87939649752104648558739188569294623185189846388915750654886353417082965270846", "price": "0.91", "size": "115", "side": "SELL", "hash": "e504321288126aeae5aca1c47096bed2cfeaabfd", "best_bid": "0.88", "best_ask": "0.91"}], "timestamp": "1769384565456", "event_type": "price_change"}}
{"_local_timestamp": "2026-01-25T23:43:08.169901+00:00", "data": {"market": "0xa144885538281db77b81b3bc88ea29d6332d88f6ab95e26aa5adb287cde301d6", "price_changes": [{"asset_id": "47125656062844317856889885896137727172968890279458526369610476685407136517672", "price": "0.02", "size": "706.23", "side": "BUY", "hash": "6e5fd0cf3b2505139813ed1e74caf96434a55b73", "best_bid": "0.31", "best_ask": "0.33"}, {"asset_id": "113861618415069729564597166750878018457148842262819426612500520860061156510491", "price": "0.98", "size": "706.23", "side": "SELL", "hash": "520b514a66691dbffa8de12fecd68f7337aad6fa", "best_bid": "0.67", "best_ask": "0.69"}], "timestamp": "1769384588000", "event_type": "price_change"}}
{"_local_timestamp": "2026-01-25T23:43:14.796111+00:00", "data": {"market": "0xa144885538281db77b81b3bc88ea29d6332d88f6ab95e26aa5adb287cde301d6", "price_changes": [{"asset_id": "47125656062844317856889885896137727172968890279458526369610476685407136517672", "price": "0.02", "size": "856.23", "side": "BUY", "hash": "ec750cc88d551f91048146026d03a424478244b9", "best_bid": "0.31", "best_ask": "0.33"}, {"asset_id": "113861618415069729564597166750878018457148842262819426612500520860061156510491", "price": "0.98", "size": "856.23", "side": "SELL", "hash": "c749fcb12ac4df9d153cfb55e3166571c5e3cf1f", "best_bid": "0.67", "best_ask": "0.69"}], "timestamp": "1769384594670", "event_type": "price_change"}}
{"_local_timestamp": "2026-01-25T23:44:46.131624+00:00", "data": {"market": "0xe1d8d93576a561c63ef303c278dac376a95e71e88f956b488c25b08688a81b57", "price_changes": [{"asset_id": "110252161993776196960668611920941766461422541474085598864316166041753604647992", "price": "0.26", "size": "88", "side": "BUY", "hash": "b1150dff89021f2372423e437393b11f0db431bf", "best_bid": "0.27", "best_ask": "0.3"}, {"asset_id": "65973752395054621107714955397531733385161540393395321312831009365229146782387", "price": "0.74", "size": "88", "side": "SELL", "hash": "14b8bc5ea7f6959faf46a91144b9cd38a856f12e", "best_bid": "0.7", "best_ask": "0.73"}], "timestamp": "1769384686062", "event_type": "price_change"}}
{"_local_timestamp": "2026-01-25T23:44:46.141056+00:00", "data": {"market": "0xe1d8d93576a561c63ef303c278dac376a95e71e88f956b488c25b08688a81b57", "price_changes": [{"asset_id": "110252161993776196960668611920941766461422541474085598864316166041753604647992", "price": "0.27", "size": "128", "side": "BUY", "hash": "0ffb7718e8997aa85c496a03a1ac625b839dccf8", "best_bid": "0.27", "best_ask": "0.3"}, {"asset_id": "65973752395054621107714955397531733385161540393395321312831009365229146782387", "price": "0.73", "size": "128", "side": "SELL", "hash": "782022d92140d753a3792eb59c7bedf984040835", "best_bid": "0.7", "best_ask": "0.73"}], "timestamp": "1769384686073", "event_type": "price_change"}}
{"_local_timestamp": "2026-01-25T23:44:46.156490+00:00", "data": {"market": "0xe1d8d93576a561c63ef303c278dac376a95e71e88f956b488c25b08688a81b57", "price_changes": [{"asset_id": "110252161993776196960668611920941766461422541474085598864316166041753604647992", "price": "0.24", "size": "450", "side": "BUY", "hash": "0fc273a8952b42e5986b23cc5eea974f7d71b626", "best_bid": "0.27", "best_ask": "0.3"}, {"asset_id": "65973752395054621107714955397531733385161540393395321312831009365229146782387", "price": "0.76", "size": "450", "side": "SELL", "hash": "cc55c1a0a5dfd0d475ea3f4e432abfac514162a8", "best_bid": "0.7", "best_ask": "0.73"}], "timestamp": "1769384686086", "event_type": "price_change"}}
{"_local_timestamp": "2026-01-25T23:44:48.448123+00:00", "data": {"market": "0x85096ae131a795ac80db209f9e633e5310fd4fd11b3c2e8b2748614139480c41", "price_changes": [{"asset_id": "46550817779287714248071035919960687231435496748461488768996323006087698669681", "price": "0.09", "size": "175", "side": "BUY", "hash": "f7ba8dc6aac81b73734801da360bc729a1847d17", "best_bid": "0.09", "best_ask": "0.12"}, {"asset_id": "87939649752104648558739188569294623185189846388915750654886353417082965270846", "price": "0.91", "size": "175", "side": "SELL", "hash": "b6bcc78d207ac9fe15d7a322f88bbf78180ac2c1", "best_bid": "0.88", "best_ask": "0.91"}], "timestamp": "1769384688378", "event_type": "price_change"}}
{"_local_timestamp": "2026-01-25T23:44:48.448555+00:00", "data": {"market": "0x85096ae131a795ac80db209f9e633e5310fd4fd11b3c2e8b2748614139480c41", "price_changes": [{"asset_id": "46550817779287714248071035919960687231435496748461488768996323006087698669681", "price": "0.09", "size": "3175", "side": "BUY", "hash": "a598535e989c55e950ce92b30809bf70237cc632", "best_bid": "0.09", "best_ask": "0.12"}, {"asset_id": "87939649752104648558739188569294623185189846388915750654886353417082965270846", "price": "0.91", "size": "3175", "side": "SELL", "hash": "c08555d0701c71cf24460ee92875f503877f5d82", "best_bid": "0.88", "best_ask": "0.91"}], "timestamp": "1769384688382", "event_type": "price_change"}}
{"_local_timestamp": "2026-01-25T23:44:48.448854+00:00", "data": {"market": "0x85096ae131a795ac80db209f9e633e5310fd4fd11b3c2e8b2748614139480c41", "price_changes": [{"asset_id": "46550817779287714248071035919960687231435496748461488768996323006087698669681", "price": "0.09", "size": "3295", "side": "BUY", "hash": "ac8487a59214ddc9a6d6f52bc6308abad3d1746f", "best_bid": "0.09", "best_ask": "0.12"}, {"asset_id": "87939649752104648558739188569294623185189846388915750654886353417082965270846", "price": "0.91", "size": "3295", "side": "SELL", "hash": "c492822136b6a12ee1dd48c9d6975eb1087252df", "best_bid": "0.88", "best_ask": "0.91"}], "timestamp": "1769384688383", "event_type": "price_change"}}
{"_local_timestamp": "2026-01-25T23:44:48.449112+00:00", "data": {"market": "0x85096ae131a795ac80db209f9e633e5310fd4fd11b3c2e8b2748614139480c41", "price_changes": [{"asset_id": "46550817779287714248071035919960687231435496748461488768996323006087698669681", "price": "0.09", "size": "13295", "side": "BUY", "hash": "4fa2801e03da58072bcf5c25ed29d7bb421a2046", "best_bid": "0.09", "best_ask": "0.12"}, {"asset_id": "87939649752104648558739188569294623185189846388915750654886353417082965270846", "price": "0.91", "size": "13295", "side": "SELL", "hash": "3fa53694c49267822e05705c279d22d668a03a50", "best_bid": "0.88", "best_ask": "0.91"}], "timestamp": "1769384688384", "event_type": "price_change"}}
{"_local_timestamp": "2026-01-25T23:44:48.449381+00:00", "data": {"market": "0x85096ae131a795ac80db209f9e633e5310fd4fd11b3c2e8b2748614139480c41", "price_changes": [{"asset_id": "87939649752104648558739188569294623185189846388915750654886353417082965270846", "price": "0.86", "size": "3000", "side": "BUY", "hash": "78f1b0bc7e4d4a97cbb85a2c25945bc6d4a8ba63", "best_bid": "0.88", "best_ask": "0.91"}, {"asset_id": "46550817779287714248071035919960687231435496748461488768996323006087698669681", "price": "0.14", "size": "3000", "side": "SELL", "hash": "b33726355970807c16ac33c5eaa59d57b2ee544a", "best_bid": "0.09", "best_ask": "0.12"}], "timestamp": "1769384688385", "event_type": "price_change"}}
{"_local_timestamp": "2026-01-25T23:44:48.458853+00:00", "data": {"market": "0x85096ae131a795ac80db209f9e633e5310fd4fd11b3c2e8b2748614139480c41", "price_changes": [{"asset_id": "87939649752104648558739188569294623185189846388915750654886353417082965270846", "price": "0.86", "size": "13000", "side": "BUY", "hash": "70f9b8a705d9fe4b5d8997ce512906105d30d7c7", "best_bid": "0.88", "best_ask": "0.91"}, {"asset_id": "46550817779287714248071035919960687231435496748461488768996323006087698669681", "price": "0.14", "size": "13000", "side": "SELL", "hash": "674792c511d155702fd6d33372ca95e054fb053e", "best_bid": "0.09", "best_ask": "0.12"}], "timestamp": "1769384688386", "event_type": "price_change"}}
{"_local_timestamp": "2026-01-25T23:44:48.459125+00:00", "data": {"market": "0x85096ae131a795ac80db209f9e633e5310fd4fd11b3c2e8b2748614139480c41", "price_changes": [{"asset_id": "87939649752104648558739188569294623185189846388915750654886353417082965270846", "price": "0.86", "size": "13420", "side": "BUY", "hash": "4edc61d9a1c3bcad4f427a600d6b3b77c555c4ce", "best_bid": "0.88", "best_ask": "0.91"}, {"asset_id": "46550817779287714248071035919960687231435496748461488768996323006087698669681", "price": "0.14", "size": "13420", "side": "SELL", "hash": "c26ab7c21a72448645c9ba79aa2e0e858f9ed039", "best_bid": "0.09", "best_ask": "0.12"}], "timestamp": "1769384688393", "event_type": "price_change"}}
{"_local_timestamp": "2026-01-25T23:44:48.459428+00:00", "data": {"market": "0x85096ae131a795ac80db209f9e633e5310fd4fd11b3c2e8b2748614139480c41", "price_changes": [{"asset_id": "87939649752104648558739188569294623185189846388915750654886353417082965270846", "price": "0.86", "size": "13540", "side": "BUY", "hash": "43e80168404fb8cd8d604dd2a362b29a05a2a840", "best_bid": "0.88", "best_ask": "0.91"}, {"asset_id": "46550817779287714248071035919960687231435496748461488768996323006087698669681", "price": "0.14", "size": "13540", "side": "SELL", "hash": "7748616266470dcc30dd486b819e8341d6e85e86", "best_bid": "0.09", "best_ask": "0.12"}], "timestamp": "1769384688393", "event_type": "price_change"}}
{"_local_timestamp": "2026-01-25T23:44:48.461338+00:00", "data": {"market": "0x85096ae131a795ac80db209f9e633e5310fd4fd11b3c2e8b2748614139480c41", "price_changes": [{"asset_id": "87939649752104648558739188569294623185189846388915750654886353417082965270846", "price": "0.86", "size": "13690", "side": "BUY", "hash": "97368666324968b4435893071658ab9d7d9ca64c", "best_bid": "0.88", "best_ask": "0.91"}, {"asset_id": "46550817779287714248071035919960687231435496748461488768996323006087698669681", "price": "0.14", "size": "13690", "side": "SELL", "hash": "06919b8cb75efc8c469907dcc9f60695a4c86436", "best_bid": "0.09", "best_ask": "0.12"}], "timestamp": "1769384688396", "event_type": "price_change"}}
{"_local_timestamp": "2026-01-25T23:44:48.461703+00:00", "data": {"market": "0x85096ae131a795ac80db209f9e633e5310fd4fd11b3c2e8b2748614139480c41", "price_changes": [{"asset_id": "87939649752104648558739188569294623185189846388915750654886353417082965270846", "price": "0.86", "size": "13760", "side": "BUY", "hash": "8f296b9fea7fab06ceb52910392b7f171d98a861", "best_bid": "0.88", "best_ask": "0.91"}, {"asset_id": "46550817779287714248071035919960687231435496748461488768996323006087698669681", "price": "0.14", "size": "13760", "side": "SELL", "hash": "1f290ad61f983c9c94f42abea31f76d9cf4547a6", "best_bid": "0.09", "best_ask": "0.12"}], "timestamp": "1769384688397", "event_type": "price_change"}}
{"_local_timestamp": "2026-01-25T23:44:48.571551+00:00", "data": {"market": "0x85096ae131a795ac80db209f9e633e5310fd4fd11b3c2e8b2748614139480c41", "price_changes": [{"asset_id": "46550817779287714248071035919960687231435496748461488768996323006087698669681", "price": "0.09", "size": "13625", "side": "BUY", "hash": "674b4c80bfddead603985cf595ba3cdbd016e6be", "best_bid": "0.09", "best_ask": "0.12"}, {"asset_id": "87939649752104648558739188569294623185189846388915750654886353417082965270846", "price": "0.91", "size": "13625", "side": "SELL", "hash": "34f4007428f792a5956a7918d4ad02170b8543e3", "best_bid": "0.88", "best_ask": "0.91"}], "timestamp": "1769384688400", "event_type": "price_change"}}
{"_local_timestamp": "2026-01-25T23:44:48.571950+00:00", "data": {"market": "0x85096ae131a795ac80db209f9e633e5310fd4fd11b3c2e8b2748614139480c41", "price_changes": [{"asset_id": "46550817779287714248071035919960687231435496748461488768996323006087698669681", "price": "0.09", "size": "13695", "side": "BUY", "hash": "3868785ba64bec8a165e0bdc1682dfeec62cbed9", "best_bid": "0.09", "best_ask": "0.12"}, {"asset_id": "87939649752104648558739188569294623185189846388915750654886353417082965270846", "price": "0.91", "size": "13695", "side": "SELL", "hash": "d2b1a73e48bef3ba766c334e12bf9e3acc90ae65", "best_bid": "0.88", "best_ask": "0.91"}], "timestamp": "1769384688401", "event_type": "price_change"}}
{"_local_timestamp": "2026-01-25T23:44:48.572276+00:00", "data": {"market": "0x85096ae131a795ac80db209f9e633e5310fd4fd11b3c2e8b2748614139480c41", "price_changes": [{"asset_id": "46550817779287714248071035919960687231435496748461488768996323006087698669681", "price": "0.09", "size": "13845", "side": "BUY", "hash": "ff00484a41b541f58196f3ef1dc75d76f7b909b7", "best_bid": "0.09", "best_ask": "0.12"}, {"asset_id": "87939649752104648558739188569294623185189846388915750654886353417082965270846", "price": "0.91", "size": "13845", "side": "SELL", "hash": "e8c2c213b4cd657cbb145eb4351b6cb97a7e8dde", "best_bid": "0.88", "best_ask": "0.91"}], "timestamp": "1769384688402", "event_type": "price_change"}}
{"_local_timestamp": "2026-01-25T23:44:48.572704+00:00", "data": {"market": "0x85096ae131a795ac80db209f9e633e5310fd4fd11b3c2e8b2748614139480c41", "price_changes": [{"asset_id": "46550817779287714248071035919960687231435496748461488768996323006087698669681", "price": "0.09", "size": "14265", "side": "BUY", "hash": "501c52380cba73de9409af22f13742a03c04dd95", "best_bid": "0.09", "best_ask": "0.12"}, {"asset_id": "87939649752104648558739188569294623185189846388915750654886353417082965270846", "price": "0.91", "size": "14265", "side": "SELL", "hash": "4698719a3bca2aeed4c783d6d67773d6b0bcbc7f", "best_bid": "0.88", "best_ask": "0.91"}], "timestamp": "1769384688403", "event_type": "price_change"}}
{"_local_timestamp": "2026-01-25T23:44:48.581720+00:00", "data": {"market": "0x85096ae131a795ac80db209f9e633e5310fd4fd11b3c2e8b2748614139480c41", "price_changes": [{"asset_id": "46550817779287714248071035919960687231435496748461488768996323006087698669681", "price": "0.09", "size": "14665", "side": "BUY", "hash": "b792fcbeb409340f8ab9c8fbed168980fe1a99ff", "best_bid": "0.09", "best_ask": "0.12"}, {"asset_id": "87939649752104648558739188569294623185189846388915750654886353417082965270846", "price": "0.91", "size": "14665", "side": "SELL", "hash": "b07a84ef3a76bde23b27c8f27f3d7aa1be207f34", "best_bid": "0.88", "best_ask": "0.91"}], "timestamp": "1769384688403", "event_type": "price_change"}}
{"_local_timestamp": "2026-01-25T23:44:48.582060+00:00", "data": {"market": "0x85096ae131a795ac80db209f9e633e5310fd4fd11b3c2e8b2748614139480c41", "price_changes": [{"asset_id": "87939649752104648558739188569294623185189846388915750654886353417082965270846", "price": "0.86", "size": "13880", "side": "BUY", "hash": "ff57b2d9d29266c18710f26fb85aabcd5fe9b5d1", "best_bid": "0.88", "best_ask": "0.91"}, {"asset_id": "46550817779287714248071035919960687231435496748461488768996323006087698669681", "price": "0.14", "size": "13880", "side": "SELL", "hash": "bfe8f731e2d0378f7f291bc04ebcf4afbed70a03", "best_bid": "0.09", "best_ask": "0.12"}], "timestamp": "1769384688404", "event_type": "price_change"}}
{"_local_timestamp": "2026-01-25T23:44:48.582388+00:00", "data": {"market": "0x85096ae131a795ac80db209f9e633e5310fd4fd11b3c2e8b2748614139480c41", "price_changes": [{"asset_id": "87939649752104648558739188569294623185189846388915750654886353417082965270846", "price": "0.86", "size": "13940", "side": "BUY", "hash": "7c81afa3f34c685ab2ee6593bd4ed1b0dcd1d221", "best_bid": "0.88", "best_ask": "0.91"}, {"asset_id": "46550817779287714248071035919960687231435496748461488768996323006087698669681", "price": "0.14", "size": "13940", "side": "SELL", "hash": "9868db7c9b612d593f1a79d35f780f7d0cfc235e", "best_bid": "0.09", "best_ask": "0.12"}], "timestamp": "1769384688405", "event_type": "price_change"}}
{"_local_timestamp": "2026-01-25T23:44:48.582686+00:00", "data": {"market": "0x85096ae131a795ac80db209f9e633e5310fd4fd11b3c2e8b2748614139480c41", "price_changes": [{"asset_id": "46550817779287714248071035919960687231435496748461488768996323006087698669681", "price": "0.09", "size": "14765", "side": "BUY", "hash": "05502c26f39628160761c8bb5bdbf26b58c9782d", "best_bid": "0.09", "best_ask": "0.12"}, {"asset_id": "87939649752104648558739188569294623185189846388915750654886353417082965270846", "price": "0.91", "size": "14765", "side": "SELL", "hash": "05cb8c0c32acd8b87947416d6d7a92a87bca5caa", "best_bid": "0.88", "best_ask": "0.91"}], "timestamp": "1769384688410", "event_type": "price_change"}}
{"_local_timestamp": "2026-01-25T23:44:48.582988+00:00", "data": {"market": "0x85096ae131a795ac80db209f9e633e5310fd4fd11b3c2e8b2748614139480c41", "price_changes": [{"asset_id": "87939649752104648558739188569294623185189846388915750654886353417082965270846", "price": "0.86", "size": "14270", "side": "BUY", "hash": "342958b0269edaee682b15133e58ec544dbd8ca8", "best_bid": "0.88", "best_ask": "0.91"}, {"asset_id": "46550817779287714248071035919960687231435496748461488768996323006087698669681", "price": "0.14", "size": "14270", "side": "SELL", "hash": "62e825f61fac756b4f667d85af96820efc9da0e9", "best_bid": "0.09", "best_ask": "0.12"}], "timestamp": "1769384688412", "event_type": "price_change"}}
{"_local_timestamp": "2026-01-25T23:44:48.583321+00:00", "data": {"market": "0x85096ae131a795ac80db209f9e633e5310fd4fd11b3c2e8b2748614139480c41", "price_changes": [{"asset_id": "46550817779287714248071035919960687231435496748461488768996323006087698669681", "price": "0.09", "size": "14885", "side": "BUY", "hash": "c43df8a3edc0fddbf123ed50e44a6cef2fce2a85", "best_bid": "0.09", "best_ask": "0.12"}, {"asset_id": "87939649752104648558739188569294623185189846388915750654886353417082965270846", "price": "0.91", "size": "14885", "side": "SELL", "hash": "99fcae1c86b35b07c2c98654b416c01a580d424d", "best_bid": "0.88", "best_ask": "0.91"}], "timestamp": "1769384688414", "event_type": "price_change"}}
{"_local_timestamp": "2026-01-25T23:44:48.583650+00:00", "data": {"market": "0x85096ae131a795ac80db209f9e633e5310fd4fd11b3c2e8b2748614139480c41", "price_changes": [{"asset_id": "87939649752104648558739188569294623185189846388915750654886353417082965270846", "price": "0.86", "size": "14350", "side": "BUY", "hash": "7c0993b7e8c1c6fbebc0cd1e756b0628641d2cd1", "best_bid": "0.88", "best_ask": "0.91"}, {"asset_id": "46550817779287714248071035919960687231435496748461488768996323006087698669681", "price": "0.14", "size": "14350", "side": "SELL", "hash": "778ce7d6a870c94d7e766c813d263e35467eb747", "best_bid": "0.09", "best_ask": "0.12"}], "timestamp": "1769384688417", "event_type": "price_change"}}
{"_local_timestamp": "2026-01-25T23:44:48.583957+00:00", "data": {"market": "0x85096ae131a795ac80db209f9e633e5310fd4fd11b3c2e8b2748614139480c41", "price_changes": [{"asset_id": "87939649752104648558739188569294623185189846388915750654886353417082965270846", "price": "0.86", "size": "14770", "side": "BUY", "hash": "fc02ca76c1af5aacb9d173876b511b77fbd32c52", "best_bid": "0.88", "best_ask": "0.91"}, {"asset_id": "46550817779287714248071035919960687231435496748461488768996323006087698669681", "price": "0.14", "size": "14770", "side": "SELL", "hash": "9ca4e594bd39ba1e547eb7de53130047cfb721be", "best_bid": "0.09", "best_ask": "0.12"}], "timestamp": "1769384688418", "event_type": "price_change"}}
{"_local_timestamp": "2026-01-25T23:44:48.584287+00:00", "data": {"market": "0x85096ae131a795ac80db209f9e633e5310fd4fd11b3c2e8b2748614139480c41", "price_changes": [{"asset_id": "87939649752104648558739188569294623185189846388915750654886353417082965270846", "price": "0.86", "size": "15570", "side": "BUY", "hash": "6eb796d383277efd1c4d00f6ddfc59521e0015ec", "best_bid": "0.88", "best_ask": "0.91"}, {"asset_id": "46550817779287714248071035919960687231435496748461488768996323006087698669681", "price": "0.14", "size": "15570", "side": "SELL", "hash": "3462454fe0c2f867955488a38f3b74646eb069f0", "best_bid": "0.09", "best_ask": "0.12"}], "timestamp": "1769384688419", "event_type": "price_change"}}
{"_local_timestamp": "2026-01-25T23:44:48.584594+00:00", "data": {"market": "0x85096ae131a795ac80db209f9e633e5310fd4fd11b3c2e8b2748614139480c41", "price_changes": [{"asset_id": "46550817779287714248071035919960687231435496748461488768996323006087698669681", "price": "0.09", "size": "15685", "side": "BUY", "hash": "50cecab36cc36b247c706ae2ffdeb135af664837", "best_bid": "0.09", "best_ask": "0.12"}, {"asset_id": "87939649752104648558739188569294623185189846388915750654886353417082965270846", "price": "0.91", "size": "15685", "side": "SELL", "hash": "fc5042efb032e471e3c8019dd715f0311f703770", "best_bid": "0.88", "best_ask": "0.91"}], "timestamp": "1769384688420", "event_type": "price_change"}}
{"_local_timestamp": "2026-01-25T23:44:48.585282+00:00", "data": {"market": "0x85096ae131a795ac80db209f9e633e5310fd4fd11b3c2e8b2748614139480c41", "price_changes": [{"asset_id": "46550817779287714248071035919960687231435496748461488768996323006087698669681", "price": "0.09", "size": "15765", "side": "BUY", "hash": "fc78be5ed933e00306ae06eba999dad1cd2ba22f", "best_bid": "0.09", "best_ask": "0.12"}, {"asset_id": "87939649752104648558739188569294623185189846388915750654886353417082965270846", "price": "0.91", "size": "15765", "side": "SELL", "hash": "0ca93813e13ee9d2ed40a9ce08faded1c14987d9", "best_bid": "0.88", "best_ask": "0.91"}], "timestamp": "1769384688421", "event_type": "price_change"}}
{"_local_timestamp": "2026-01-25T23:44:48.585602+00:00", "data": {"market": "0x85096ae131a795ac80db209f9e633e5310fd4fd11b3c2e8b2748614139480c41", "price_changes": [{"asset_id": "46550817779287714248071035919960687231435496748461488768996323006087698669681", "price": "0.09", "size": "15825", "side": "BUY", "hash": "f429b15a604385f85021126b317c5827eefd5053", "best_bid": "0.09", "best_ask": "0.12"}, {"asset_id": "87939649752104648558739188569294623185189846388915750654886353417082965270846", "price": "0.91", "size": "15825", "side": "SELL", "hash": "1eadd6e56ccdcdeec397305c2e77082b5622b99e", "best_bid": "0.88", "best_ask": "0.91"}], "timestamp": "1769384688422", "event_type": "price_change"}}
{"_local_timestamp": "2026-01-25T23:44:48.585912+00:00", "data": {"market": "0x85096ae131a795ac80db209f9e633e5310fd4fd11b3c2e8b2748614139480c41", "price_changes": [{"asset_id": "87939649752104648558739188569294623185189846388915750654886353417082965270846", "price": "0.86", "size": "15670", "side": "BUY", "hash": "da6a88f2bb47cd350057b17a6cb39e1a022a6900", "best_bid": "0.88", "best_ask": "0.91"}, {"asset_id": "46550817779287714248071035919960687231435496748461488768996323006087698669681", "price": "0.14", "size": "15670", "side": "SELL", "hash": "5220bfeeb67b94b4cfd5d68f92ee55f49b96f758", "best_bid": "0.09", "best_ask": "0.12"}], "timestamp": "1769384688426", "event_type": "price_change"}}
{"_local_timestamp": "2026-01-25T23:44:48.586232+00:00", "data": {"market": "0x85096ae131a795ac80db209f9e633e5310fd4fd11b3c2e8b2748614139480c41", "price_changes": [{"asset_id": "87939649752104648558739188569294623185189846388915750654886353417082965270846", "price": "0.86", "size": "16070", "side": "BUY", "hash": "7ec2674909e43ffafcee7d36c02b156da8e70a25", "best_bid": "0.88", "best_ask": "0.91"}, {"asset_id": "46550817779287714248071035919960687231435496748461488768996323006087698669681", "price": "0.14", "size": "16070", "side": "SELL", "hash": "039ec269e351218fb4fa81cd352d81014c670e32", "best_bid": "0.09", "best_ask": "0.12"}], "timestamp": "1769384688426", "event_type": "price_change"}}
{"_local_timestamp": "2026-01-25T23:44:48.586528+00:00", "data": {"market": "0x85096ae131a795ac80db209f9e633e5310fd4fd11b3c2e8b2748614139480c41", "price_changes": [{"asset_id": "46550817779287714248071035919960687231435496748461488768996323006087698669681", "price": "0.09", "size": "16155", "side": "BUY", "hash": "57ca802b4727b7b3270254daa418f1b802aa3cf7", "best_bid": "0.09", "best_ask": "0.12"}, {"asset_id": "87939649752104648558739188569294623185189846388915750654886353417082965270846", "price": "0.91", "size": "16155", "side": "SELL", "hash": "6ad97f3053110c62716635b0abff8cb79fc85a85", "best_bid": "0.88", "best_ask": "0.91"}], "timestamp": "1769384688429", "event_type": "price_change"}}
{"_local_timestamp": "2026-01-25T23:44:48.586845+00:00", "data": {"market": "0x85096ae131a795ac80db209f9e633e5310fd4fd11b3c2e8b2748614139480c41", "price_changes": [{"asset_id": "46550817779287714248071035919960687231435496748461488768996323006087698669681", "price": "0.09", "size": "16575", "side": "BUY", "hash": "8bfbecaa4c9f6bc21a5d6ae4513763f87019f61b", "best_bid": "0.09", "best_ask": "0.12"}, {"asset_id": "87939649752104648558739188569294623185189846388915750654886353417082965270846", "price": "0.91", "size": "16575", "side": "SELL", "hash": "c83ab8279b6c387435eff5521424b90e7c7779ac", "best_bid": "0.88", "best_ask": "0.91"}], "timestamp": "1769384688429", "event_type": "price_change"}}
{"_local_timestamp": "2026-01-25T23:44:48.587167+00:00", "data": {"market": "0x85096ae131a795ac80db209f9e633e5310fd4fd11b3c2e8b2748614139480c41", "price_changes": [{"asset_id": "87939649752104648558739188569294623185189846388915750654886353417082965270846", "price": "0.86", "size": "16370", "side": "BUY", "hash": "ac9203905ba48a49c4e6f52c3cf60b9e912774e5", "best_bid": "0.88", "best_ask": "0.91"}, {"asset_id": "46550817779287714248071035919960687231435496748461488768996323006087698669681", "price": "0.14", "size": "16370", "side": "SELL", "hash": "9f4298b15028cf39ef458493670e945e2a958373", "best_bid": "0.09", "best_ask": "0.12"}], "timestamp": "1769384688431", "event_type": "price_change"}}
{"_local_timestamp": "2026-01-25T23:44:48.587509+00:00", "data": {"market": "0x85096ae131a795ac80db209f9e633e5310fd4fd11b3c2e8b2748614139480c41", "price_changes": [{"asset_id": "87939649752104648558739188569294623185189846388915750654886353417082965270846", "price": "0.86", "size": "16520", "side": "BUY", "hash": "92077732e7338ffb75eb5cf7755c75e527449a12", "best_bid": "0.88", "best_ask": "0.91"}, {"asset_id": "46550817779287714248071035919960687231435496748461488768996323006087698669681", "price": "0.14", "size": "16520", "side": "SELL", "hash": "87bc9079e7e11af44334118c6216bd17a498c928", "best_bid": "0.09", "best_ask": "0.12"}], "timestamp": "1769384688432", "event_type": "price_change"}}
{"_local_timestamp": "2026-01-25T23:44:48.587846+00:00", "data": {"market": "0x85096ae131a795ac80db209f9e633e5310fd4fd11b3c2e8b2748614139480c41", "price_changes": [{"asset_id": "46550817779287714248071035919960687231435496748461488768996323006087698669681", "price": "0.09", "size": "16725", "side": "BUY", "hash": "e1a5f02f98a108b60df9da05ac91ee238247de7f", "best_bid": "0.09", "best_ask": "0.12"}, {"asset_id": "87939649752104648558739188569294623185189846388915750654886353417082965270846", "price": "0.91", "size": "16725", "side": "SELL", "hash": "f741cd8ea6958816347337296b736ad6bc5652ec", "best_bid": "0.88", "best_ask": "0.91"}], "timestamp": "1769384688434", "event_type": "price_change"}}
{"_local_timestamp": "2026-01-25T23:44:48.588270+00:00", "data": {"market": "0x85096ae131a795ac80db209f9e633e5310fd4fd11b3c2e8b2748614139480c41", "price_changes": [{"asset_id": "46550817779287714248071035919960687231435496748461488768996323006087698669681", "price": "0.09", "size": "16885", "side": "BUY", "hash": "5cc0243319b90b1f4a933c36395293b6773b2488", "best_bid": "0.09", "best_ask": "0.12"}, {"asset_id": "87939649752104648558739188569294623185189846388915750654886353417082965270846", "price": "0.91", "size": "16885", "side": "SELL", "hash": "17ac1609c1421528c6c6b6921b937a57fad04fe4", "best_bid": "0.88", "best_ask": "0.91"}], "timestamp": "1769384688435", "event_type": "price_change"}}
{"_local_timestamp": "2026-01-25T23:44:48.588620+00:00", "data": {"market": "0x85096ae131a795ac80db209f9e633e5310fd4fd11b3c2e8b2748614139480c41", "price_changes": [{"asset_id": "87939649752104648558739188569294623185189846388915750654886353417082965270846", "price": "0.86", "size": "16680", "side": "BUY", "hash": "5676db812ed3c973ae0e543832a263af2789e731", "best_bid": "0.88", "best_ask": "0.91"}, {"asset_id": "46550817779287714248071035919960687231435496748461488768996323006087698669681", "price": "0.14", "size": "16680", "side": "SELL", "hash": "9321f50edf288fc7510a69c011a7ee86bfb3906b", "best_bid": "0.09", "best_ask": "0.12"}], "timestamp": "1769384688436", "event_type": "price_change"}}
{"_local_timestamp": "2026-01-25T23:44:48.588945+00:00", "data": {"market": "0x85096ae131a795ac80db209f9e633e5310fd4fd11b3c2e8b2748614139480c41", "price_changes": [{"asset_id": "87939649752104648558739188569294623185189846388915750654886353417082965270846", "price": "0.86", "size": "16740", "side": "BUY", "hash": "ec06ed301a843ee43e4a610aeb91639d396c5c27", "best_bid": "0.88", "best_ask": "0.91"}, {"asset_id": "46550817779287714248071035919960687231435496748461488768996323006087698669681", "price": "0.14", "size": "16740", "side": "SELL", "hash": "4d7d2456e244057fb3c09c3fc81d58a250157cf9", "best_bid": "0.09", "best_ask": "0.12"}], "timestamp": "1769384688437", "event_type": "price_change"}}
{"_local_timestamp": "2026-01-25T23:44:48.589296+00:00", "data": {"market": "0x85096ae131a795ac80db209f9e633e5310fd4fd11b3c2e8b2748614139480c41", "price_changes": [{"asset_id": "46550817779287714248071035919960687231435496748461488768996323006087698669681", "price": "0.09", "size": "16945", "side": "BUY", "hash": "2a862d0f9158208c7ef62106cd328197f9492b69", "best_bid": "0.09", "best_ask": "0.12"}, {"asset_id": "87939649752104648558739188569294623185189846388915750654886353417082965270846", "price": "0.91", "size": "16945", "side": "SELL", "hash": "cf5e43a566f6b4df94e3ab97d630b9178eefcd37", "best_bid": "0.88", "best_ask": "0.91"}], "timestamp": "1769384688437", "event_type": "price_change"}}
{"_local_timestamp": "2026-01-25T23:44:48.589640+00:00", "data": {"market": "0x85096ae131a795ac80db209f9e633e5310fd4fd11b3c2e8b2748614139480c41", "price_changes": [{"asset_id": "46550817779287714248071035919960687231435496748461488768996323006087698669681", "price": "0.09", "size": "17245", "side": "BUY", "hash": "55ac1a312187336ceb588fb428a96a7401644c52", "best_bid": "0.09", "best_ask": "0.12"}, {"asset_id": "87939649752104648558739188569294623185189846388915750654886353417082965270846", "price": "0.91", "size": "17245", "side": "SELL", "hash": "2e1f1a88207e134d85521423a26965c9fc279574", "best_bid": "0.88", "best_ask": "0.91"}], "timestamp": "1769384688439", "event_type": "price_change"}}
{"_local_timestamp": "2026-01-25T23:44:48.589994+00:00", "data": {"market": "0x85096ae131a795ac80db209f9e633e5310fd4fd11b3c2e8b2748614139480c41", "price_changes": [{"asset_id": "46550817779287714248071035919960687231435496748461488768996323006087698669681", "price": "0.09", "size": "17545", "side": "BUY", "hash": "1907c2ed173249fe09ee66bbc2193beeb2ac4202", "best_bid": "0.09", "best_ask": "0.12"}, {"asset_id": "87939649752104648558739188569294623185189846388915750654886353417082965270846", "price": "0.91", "size": "17545", "side": "SELL", "hash": "ecdda6eaca0a179a547ebf4f735edb8da15f4ee6", "best_bid": "0.88", "best_ask": "0.91"}], "timestamp": "1769384688440", "event_type": "price_change"}}
{"_local_timestamp": "2026-01-25T23:44:48.590321+00:00", "data": {"market": "0x85096ae131a795ac80db209f9e633e5310fd4fd11b3c2e8b2748614139480c41", "price_changes": [{"asset_id": "87939649752104648558739188569294623185189846388915750654886353417082965270846", "price": "0.86", "size": "16800", "side": "BUY", "hash": "fdd769e09ff72dfa1f5014b85be614354a9fd1a3", "best_bid": "0.88", "best_ask": "0.91"}, {"asset_id": "46550817779287714248071035919960687231435496748461488768996323006087698669681", "price": "0.14", "size": "16800", "side": "SELL", "hash": "b86991bc58ca8860ac9072c91b90dbea9dc0adcf", "best_bid": "0.09", "best_ask": "0.12"}], "timestamp": "1769384688444", "event_type": "price_change"}}
{"_local_timestamp": "2026-01-25T23:44:48.590667+00:00", "data": {"market": "0x85096ae131a795ac80db209f9e633e5310fd4fd11b3c2e8b2748614139480c41", "price_changes": [{"asset_id": "46550817779287714248071035919960687231435496748461488768996323006087698669681", "price": "0.09", "size": "17695", "side": "BUY", "hash": "66211474beb67a946150475753589941e92e2bfa", "best_bid": "0.09", "best_ask": "0.12"}, {"asset_id": "87939649752104648558739188569294623185189846388915750654886353417082965270846", "price": "0.91", "size": "17695", "side": "SELL", "hash": "5439e77b1fb51bf69081d8a05d33c86271c9059a", "best_bid": "0.88", "best_ask": "0.91"}], "timestamp": "1769384688458", "event_type": "price_change"}}
{"_local_timestamp": "2026-01-25T23:44:48.591020+00:00", "data": {"market": "0x85096ae131a795ac80db209f9e633e5310fd4fd11b3c2e8b2748614139480c41", "price_changes": [{"asset_id": "46550817779287714248071035919960687231435496748461488768996323006087698669681", "price": "0.09", "size": "18115", "side": "BUY", "hash": "33a627febed4ed929bf398f908286815b6e55360", "best_bid": "0.09", "best_ask": "0.12"}, {"asset_id": "87939649752104648558739188569294623185189846388915750654886353417082965270846", "price": "0.91", "size": "18115", "side": "SELL", "hash": "d792e87153bc69a52583efd4d8a7b6a3766b9f19", "best_bid": "0.88", "best_ask": "0.91"}], "timestamp": "1769384688460", "event_type": "price_change"}}
{"_local_timestamp": "2026-01-25T23:44:48.591386+00:00", "data": {"market": "0x85096ae131a795ac80db209f9e633e5310fd4fd11b3c2e8b2748614139480c41", "price_changes": [{"asset_id": "87939649752104648558739188569294623185189846388915750654886353417082965270846", "price": "0.86", "size": "17220", "side": "BUY", "hash": "b5c9b45a6fd10eeb9058dac289d403fab8111cd0", "best_bid": "0.88", "best_ask": "0.91"}, {"asset_id": "46550817779287714248071035919960687231435496748461488768996323006087698669681", "price": "0.14", "size": "17220", "side": "SELL", "hash": "ac471f1d241361462ad36e5d1ad7c365798fa71e", "best_bid": "0.09", "best_ask": "0.12"}], "timestamp": "1769384688461", "event_type": "price_change"}}
{"_local_timestamp": "2026-01-25T23:44:48.591764+00:00", "data": {"market": "0x85096ae131a795ac80db209f9e633e5310fd4fd11b3c2e8b2748614139480c41", "price_changes": [{"asset_id": "87939649752104648558739188569294623185189846388915750654886353417082965270846", "price": "0.86", "size": "17370", "side": "BUY", "hash": "6b6ada387b42d50012812640535c9fba36331a65", "best_bid": "0.88", "best_ask": "0.91"}, {"asset_id": "46550817779287714248071035919960687231435496748461488768996323006087698669681", "price": "0.14", "size": "17370", "side": "SELL", "hash": "362211fc9ea036988a8c81bd1b2a73520ad1969a", "best_bid": "0.09", "best_ask": "0.12"}], "timestamp": "1769384688461", "event_type": "price_change"}}
{"_local_timestamp": "2026-01-25T23:44:48.592106+00:00", "data": {"market": "0x85096ae131a795ac80db209f9e633e5310fd4fd11b3c2e8b2748614139480c41", "price_changes": [{"asset_id": "87939649752104648558739188569294623185189846388915750654886353417082965270846", "price": "0.86", "size": "17700", "side": "BUY", "hash": "068b86699b0af2e5620127749c527b6bd3dfc880", "best_bid": "0.88", "best_ask": "0.91"}, {"asset_id": "46550817779287714248071035919960687231435496748461488768996323006087698669681", "price": "0.14", "size": "17700", "side": "SELL", "hash": "8045172b0ad4479fb7f5aaf4b79c138e8cbca590", "best_bid": "0.09", "best_ask": "0.12"}], "timestamp": "1769384688472", "event_type": "price_change"}}
{"_local_timestamp": "2026-01-25T23:44:48.592448+00:00", "data": {"market": "0x85096ae131a795ac80db209f9e633e5310fd4fd11b3c2e8b2748614139480c41", "price_changes": [{"asset_id": "87939649752104648558739188569294623185189846388915750654886353417082965270846", "price": "0.86", "size": "18000", "side": "BUY", "hash": "7729dc79853646b5ea6c9f2dd719447f2966b00f", "best_bid": "0.88", "best_ask": "0.91"}, {"asset_id": "46550817779287714248071035919960687231435496748461488768996323006087698669681", "price": "0.14", "size": "18000", "side": "SELL", "hash": "3a3dbd3cdcc143307a77782b351cdbf9910b55f5", "best_bid": "0.09", "best_ask": "0.12"}], "timestamp": "1769384688473", "event_type": "price_change"}}
{"_local_timestamp": "2026-01-25T23:44:48.592785+00:00", "data": {"market": "0x85096ae131a795ac80db209f9e633e5310fd4fd11b3c2e8b2748614139480c41", "price_changes": [{"asset_id": "46550817779287714248071035919960687231435496748461488768996323006087698669681", "price": "0.09", "size": "18315", "side": "BUY", "hash": "2275b3239a025b1036ec2a1ab88afe2c5eeffe5d", "best_bid": "0.09", "best_ask": "0.12"}, {"asset_id": "87939649752104648558739188569294623185189846388915750654886353417082965270846", "price": "0.91", "size": "18315", "side": "SELL", "hash": "90d3c4492033344258c80efb4490752646f7fa95", "best_bid": "0.88", "best_ask": "0.91"}], "timestamp": "1769384688475", "event_type": "price_change"}}
{"_local_timestamp": "2026-01-25T23:44:48.593141+00:00", "data": {"market": "0x85096ae131a795ac80db209f9e633e5310fd4fd11b3c2e8b2748614139480c41", "price_changes": [{"asset_id": "46550817779287714248071035919960687231435496748461488768996323006087698669681", "price": "0.09", "size": "18615", "side": "BUY", "hash": "c6abf1857a6ae5dafadd476ddf1e971f689f9e0b", "best_bid": "0.09", "best_ask": "0.12"}, {"asset_id": "87939649752104648558739188569294623185189846388915750654886353417082965270846", "price": "0.91", "size": "18615", "side": "SELL", "hash": "18fc27abe8c3dca5481f27dd878547abc02123ea", "best_bid": "0.88", "best_ask": "0.91"}], "timestamp": "1769384688477", "event_type": "price_change"}}
{"_local_timestamp": "2026-01-25T23:44:48.593494+00:00", "data": {"market": "0x85096ae131a795ac80db209f9e633e5310fd4fd11b3c2e8b2748614139480c41", "price_changes": [{"asset_id": "46550817779287714248071035919960687231435496748461488768996323006087698669681", "price": "0.09", "size": "21615", "side": "BUY", "hash": "437af213e13c8c3fff5aa9a4be38f91ea28c48e6", "best_bid": "0.09", "best_ask": "0.12"}, {"asset_id": "87939649752104648558739188569294623185189846388915750654886353417082965270846", "price": "0.91", "size": "21615", "side": "SELL", "hash": "58879df45d2c160606a1f474c30809e39d13afe0", "best_bid": "0.88", "best_ask": "0.91"}], "timestamp": "1769384688477", "event_type": "price_change"}}
{"_local_timestamp": "2026-01-25T23:44:48.593886+00:00", "data": {"market": "0x85096ae131a795ac80db209f9e633e5310fd4fd11b3c2e8b2748614139480c41", "price_changes": [{"asset_id": "87939649752104648558739188569294623185189846388915750654886353417082965270846", "price": "0.86", "size": "18060", "side": "BUY", "hash": "a3908fd49e0bae5958ec5175270779faff9579af", "best_bid": "0.88", "best_ask": "0.91"}, {"asset_id": "46550817779287714248071035919960687231435496748461488768996323006087698669681", "price": "0.14", "size": "18060", "side": "SELL", "hash": "13bc5bbcc376fc4b28c499f1e6999526920344fe", "best_bid": "0.09", "best_ask": "0.12"}], "timestamp": "1769384688478", "event_type": "price_change"}}
{"_local_timestamp": "2026-01-25T23:44:48.594255+00:00", "data": {"market": "0x85096ae131a795ac80db209f9e633e5310fd4fd11b3c2e8b2748614139480c41", "price_changes": [{"asset_id": "46550817779287714248071035919960687231435496748461488768996323006087698669681", "price": "0.09", "size": "21675", "side": "BUY", "hash": "b256a55e5631c98b229b5ae82493f9f29359e575", "best_bid": "0.09", "best_ask": "0.12"}, {"asset_id": "87939649752104648558739188569294623185189846388915750654886353417082965270846", "price": "0.91", "size": "21675", "side": "SELL", "hash": "8d818486d5a4ee9f57f24dac25fed500e2f4e07c", "best_bid": "0.88", "best_ask": "0.91"}], "timestamp": "1769384688480", "event_type": "price_change"}}
{"_local_timestamp": "2026-01-25T23:44:48.594613+00:00", "data": {"market": "0x85096ae131a795ac80db209f9e633e5310fd4fd11b3c2e8b2748614139480c41", "price_changes": [{"asset_id": "87939649752104648558739188569294623185189846388915750654886353417082965270846", "price": "0.86", "size": "18230", "side": "BUY", "hash": "8b622ee8cd91fbb13188ed7067bff97351d760ab", "best_bid": "0.88", "best_ask": "0.91"}, {"asset_id": "46550817779287714248071035919960687231435496748461488768996323006087698669681", "price": "0.14", "size": "18230", "side": "SELL", "hash": "e69e43ae8f0563bae20bea0ceaf40d87cfdf19e0", "best_bid": "0.09", "best_ask": "0.12"}], "timestamp": "1769384688481", "event_type": "price_change"}}
{"_local_timestamp": "2026-01-25T23:44:48.595001+00:00", "data": {"market": "0x85096ae131a795ac80db209f9e633e5310fd4fd11b3c2e8b2748614139480c41", "price_changes": [{"asset_id": "46550817779287714248071035919960687231435496748461488768996323006087698669681", "price": "0.09", "size": "21845", "side": "BUY", "hash": "26b576742230473dbef333b36683fa421ab2bdd5", "best_bid": "0.09", "best_ask": "0.12"}, {"asset_id": "87939649752104648558739188569294623185189846388915750654886353417082965270846", "price": "0.91", "size": "21845", "side": "SELL", "hash": "ce166c0dc6b62f0dade3f5ac035459c5c49e1842", "best_bid": "0.88", "best_ask": "0.91"}], "timestamp": "1769384688482", "event_type": "price_change"}}
{"_local_timestamp": "2026-01-25T23:44:48.595420+00:00", "data": {"market": "0x85096ae131a795ac80db209f9e633e5310fd4fd11b3c2e8b2748614139480c41", "price_changes": [{"asset_id": "87939649752104648558739188569294623185189846388915750654886353417082965270846", "price": "0.86", "size": "18510", "side": "BUY", "hash": "cf1ddede004040ca7879bdc4956af0ce97a07734", "best_bid": "0.88", "best_ask": "0.91"}, {"asset_id": "46550817779287714248071035919960687231435496748461488768996323006087698669681", "price": "0.14", "size": "18510", "side": "SELL", "hash": "b4c128159ff92837d496940eacc2c3b89e74c88e", "best_bid": "0.09", "best_ask": "0.12"}], "timestamp": "1769384688483", "event_type": "price_change"}}
{"_local_timestamp": "2026-01-25T23:44:48.595857+00:00", "data": {"market": "0x85096ae131a795ac80db209f9e633e5310fd4fd11b3c2e8b2748614139480c41", "price_changes": [{"asset_id": "87939649752104648558739188569294623185189846388915750654886353417082965270846", "price": "0.86", "size": "18810", "side": "BUY", "hash": "919233e14c47365191d95d8aacbadd4a97abb462", "best_bid": "0.88", "best_ask": "0.91"}, {"asset_id": "46550817779287714248071035919960687231435496748461488768996323006087698669681", "price": "0.14", "size": "18810", "side": "SELL", "hash": "939fdb0fcd7e2bd4d3b80d3e55183dba6ef520ae", "best_bid": "0.09", "best_ask": "0.12"}], "timestamp": "1769384688484", "event_type": "price_change"}}
{"_local_timestamp": "2026-01-25T23:44:48.596357+00:00", "data": {"market": "0x85096ae131a795ac80db209f9e633e5310fd4fd11b3c2e8b2748614139480c41", "price_changes": [{"asset_id": "87939649752104648558739188569294623185189846388915750654886353417082965270846", "price": "0.86", "size": "21810", "side": "BUY", "hash": "b2bd51312d8873070d6fb0f6fdd0d5f038dc9988", "best_bid": "0.88", "best_ask": "0.91"}, {"asset_id": "46550817779287714248071035919960687231435496748461488768996323006087698669681", "price": "0.14", "size": "21810", "side": "SELL", "hash": "7ac082df2dfc717a5ffbe10aa47f519cd0e2044f", "best_bid": "0.09", "best_ask": "0.12"}], "timestamp": "1769384688485", "event_type": "price_change"}}
{"_local_timestamp": "2026-01-25T23:44:48.705329+00:00", "data": {"market": "0x85096ae131a795ac80db209f9e633e5310fd4fd11b3c2e8b2748614139480c41", "price_changes": [{"asset_id": "46550817779287714248071035919960687231435496748461488768996323006087698669681", "price": "0.09", "size": "21905", "side": "BUY", "hash": "13eda4871ab2b7b36ec3e75416589e65501c8aa0", "best_bid": "0.09", "best_ask": "0.12"}, {"asset_id": "87939649752104648558739188569294623185189846388915750654886353417082965270846", "price": "0.91", "size": "21905", "side": "SELL", "hash": "fde12483abe77a846de356a60f055eb2fec1b782", "best_bid": "0.88", "best_ask": "0.91"}], "timestamp": "1769384688487", "event_type": "price_change"}}
{"_local_timestamp": "2026-01-25T23:44:48.705830+00:00", "data": {"market": "0x85096ae131a795ac80db209f9e633e5310fd4fd11b3c2e8b2748614139480c41", "price_changes": [{"asset_id": "46550817779287714248071035919960687231435496748461488768996323006087698669681", "price": "0.09", "size": "22025", "side": "BUY", "hash": "405bbaf396b4ada409c3c9685505e389c2d99596", "best_bid": "0.09", "best_ask": "0.12"}, {"asset_id": "87939649752104648558739188569294623185189846388915750654886353417082965270846", "price": "0.91", "size": "22025", "side": "SELL", "hash": "34af35609be2c00e265630d8fd1b3eeb16bfe504", "best_bid": "0.88", "best_ask": "0.91"}], "timestamp": "1769384688488", "event_type": "price_change"}}
{"_local_timestamp": "2026-01-25T23:44:48.706257+00:00", "data": {"market": "0x85096ae131a795ac80db209f9e633e5310fd4fd11b3c2e8b2748614139480c41", "price_changes": [{"asset_id": "87939649752104648558739188569294623185189846388915750654886353417082965270846", "price": "0.86", "size": "21930", "side": "BUY", "hash": "6d22c83611c5683dbdf5c9ff8c6175574f747260", "best_bid": "0.88", "best_ask": "0.91"}, {"asset_id": "46550817779287714248071035919960687231435496748461488768996323006087698669681", "price": "0.14", "size": "21930", "side": "SELL", "hash": "97f8d3277c7e178819cb9ff30457b66d3f48fe11", "best_bid": "0.09", "best_ask": "0.12"}], "timestamp": "1769384688489", "event_type": "price_change"}}
{"_local_timestamp": "2026-01-25T23:44:48.706703+00:00", "data": {"market": "0x85096ae131a795ac80db209f9e633e5310fd4fd11b3c2e8b2748614139480c41", "price_changes": [{"asset_id": "46550817779287714248071035919960687231435496748461488768996323006087698669681", "price": "0.09", "size": "22305", "side": "BUY", "hash": "a837891ce7f961a96aba1312e9183b0435c8dea6", "best_bid": "0.09", "best_ask": "0.12"}, {"asset_id": "87939649752104648558739188569294623185189846388915750654886353417082965270846", "price": "0.91", "size": "22305", "side": "SELL", "hash": "89c30a0024052ad0e475a4c840aa821506bad98f", "best_bid": "0.88", "best_ask": "0.91"}], "timestamp": "1769384688489", "event_type": "price_change"}}
{"_local_timestamp": "2026-01-25T23:44:48.707147+00:00", "data": {"market": "0x85096ae131a795ac80db209f9e633e5310fd4fd11b3c2e8b2748614139480c41", "price_changes": [{"asset_id": "87939649752104648558739188569294623185189846388915750654886353417082965270846", "price": "0.86", "size": "22080", "side": "BUY", "hash": "12357f99c2ae99a97123e3ce7e7d7eed07938775", "best_bid": "0.88", "best_ask": "0.91"}, {"asset_id": "46550817779287714248071035919960687231435496748461488768996323006087698669681", "price": "0.14", "size": "22080", "side": "SELL", "hash": "42942e75aef01bbac356acac1fe058eb1eecfe89", "best_bid": "0.09", "best_ask": "0.12"}], "timestamp": "1769384688490", "event_type": "price_change"}}
{"_local_timestamp": "2026-01-25T23:44:48.707572+00:00", "data": {"market": "0x85096ae131a795ac80db209f9e633e5310fd4fd11b3c2e8b2748614139480c41", "price_changes": [{"asset_id": "46550817779287714248071035919960687231435496748461488768996323006087698669681", "price": "0.09", "size": "22475", "side": "BUY", "hash": "7569827af9090b62b7483d27f10de7c6fb4a9e3e", "best_bid": "0.09", "best_ask": "0.12"}, {"asset_id": "87939649752104648558739188569294623185189846388915750654886353417082965270846", "price": "0.91", "size": "22475", "side": "SELL", "hash": "004ae9ba67b6f6271343760c549cc5f736a6a43b", "best_bid": "0.88", "best_ask": "0.91"}], "timestamp": "1769384688491", "event_type": "price_change"}}
{"_local_timestamp": "2026-01-25T23:44:48.707995+00:00", "data": {"market": "0x85096ae131a795ac80db209f9e633e5310fd4fd11b3c2e8b2748614139480c41", "price_changes": [{"asset_id": "87939649752104648558739188569294623185189846388915750654886353417082965270846", "price": "0.86", "size": "22280", "side": "BUY", "hash": "b9dce9232fc365455d9f04cf45b3434421097cb6", "best_bid": "0.88", "best_ask": "0.91"}, {"asset_id": "46550817779287714248071035919960687231435496748461488768996323006087698669681", "price": "0.14", "size": "22280", "side": "SELL", "hash": "9eb7104a836d791d1f65eca28961584752ff3ab1", "best_bid": "0.09", "best_ask": "0.12"}], "timestamp": "1769384688491", "event_type": "price_change"}}
{"_local_timestamp": "2026-01-25T23:44:48.708413+00:00", "data": {"market": "0x85096ae131a795ac80db209f9e633e5310fd4fd11b3c2e8b2748614139480c41", "price_changes": [{"asset_id": "87939649752104648558739188569294623185189846388915750654886353417082965270846", "price": "0.86", "size": "22340", "side": "BUY", "hash": "6331d5d59129633526fa024dca900127a19442e7", "best_bid": "0.88", "best_ask": "0.91"}, {"asset_id": "46550817779287714248071035919960687231435496748461488768996323006087698669681", "price": "0.14", "size": "22340", "side": "SELL", "hash": "a69d7c604836a27e855f1a79be80ef5f75fa6c42", "best_bid": "0.09", "best_ask": "0.12"}], "timestamp": "1769384688492", "event_type": "price_change"}}
{"_local_timestamp": "2026-01-25T23:44:48.708837+00:00", "data": {"market": "0x85096ae131a795ac80db209f9e633e5310fd4fd11b3c2e8b2748614139480c41", "price_changes": [{"asset_id": "87939649752104648558739188569294623185189846388915750654886353417082965270846", "price": "0.86", "size": "22510", "side": "BUY", "hash": "756ac2778148cf88130aea0a335783c0550e6f74", "best_bid": "0.88", "best_ask": "0.91"}, {"asset_id": "46550817779287714248071035919960687231435496748461488768996323006087698669681", "price": "0.14", "size": "22510", "side": "SELL", "hash": "8f3923dc3ba24a4fb6d0e417af3d772b07d92802", "best_bid": "0.09", "best_ask": "0.12"}], "timestamp": "1769384688493", "event_type": "price_change"}}
{"_local_timestamp": "2026-01-25T23:44:48.709273+00:00", "data": {"market": "0x85096ae131a795ac80db209f9e633e5310fd4fd11b3c2e8b2748614139480c41", "price_changes": [{"asset_id": "46550817779287714248071035919960687231435496748461488768996323006087698669681", "price": "0.09", "size": "22595", "side": "BUY", "hash": "db7641ee5649bb69478bda30a5352ce8ecd8adfc", "best_bid": "0.09", "best_ask": "0.12"}, {"asset_id": "87939649752104648558739188569294623185189846388915750654886353417082965270846", "price": "0.91", "size": "22595", "side": "SELL", "hash": "7e1ef6f3360e5542da2be79153975976e9b7852c", "best_bid": "0.88", "best_ask": "0.91"}], "timestamp": "1769384688494", "event_type": "price_change"}}
{"_local_timestamp": "2026-01-25T23:44:48.712069+00:00", "data": {"market": "0x85096ae131a795ac80db209f9e633e5310fd4fd11b3c2e8b2748614139480c41", "price_changes": [{"asset_id": "46550817779287714248071035919960687231435496748461488768996323006087698669681", "price": "0.09", "size": "22765", "side": "BUY", "hash": "605c0d5697da8091abbb880d6cbc08afacfe344a", "best_bid": "0.09", "best_ask": "0.12"}, {"asset_id": "87939649752104648558739188569294623185189846388915750654886353417082965270846", "price": "0.91", "size": "22765", "side": "SELL", "hash": "bf0006019a29740814649f0aec501e27d362fabb", "best_bid": "0.88", "best_ask": "0.91"}], "timestamp": "1769384688496", "event_type": "price_change"}}
{"_local_timestamp": "2026-01-25T23:44:48.712541+00:00", "data": {"market": "0x85096ae131a795ac80db209f9e633e5310fd4fd11b3c2e8b2748614139480c41", "price_changes": [{"asset_id": "87939649752104648558739188569294623185189846388915750654886353417082965270846", "price": "0.86", "size": "22570", "side": "BUY", "hash": "845a959eee271af3bb24ae27f31a262745de1951", "best_bid": "0.88", "best_ask": "0.91"}, {"asset_id": "46550817779287714248071035919960687231435496748461488768996323006087698669681", "price": "0.14", "size": "22570", "side": "SELL", "hash": "c70ed67e7e4a092d42ba7b3febdc6118413df077", "best_bid": "0.09", "best_ask": "0.12"}], "timestamp": "1769384688498", "event_type": "price_change"}}
{"_local_timestamp": "2026-01-25T23:44:48.713014+00:00", "data": {"market": "0x85096ae131a795ac80db209f9e633e5310fd4fd11b3c2e8b2748614139480c41", "price_changes": [{"asset_id": "87939649752104648558739188569294623185189846388915750654886353417082965270846", "price": "0.86", "size": "22630", "side": "BUY", "hash": "4fe659ee4f98d65c3f3de66879ed6d68b36ce91b", "best_bid": "0.88", "best_ask": "0.91"}, {"asset_id": "46550817779287714248071035919960687231435496748461488768996323006087698669681", "price": "0.14", "size": "22630", "side": "SELL", "hash": "f5a025138e2e40cd0af993334115e99e29c5d008", "best_bid": "0.09", "best_ask": "0.12"}], "timestamp": "1769384688500", "event_type": "price_change"}}
{"_local_timestamp": "2026-01-25T23:44:48.713445+00:00", "data": {"market": "0x85096ae131a795ac80db209f9e633e5310fd4fd11b3c2e8b2748614139480c41", "price_changes": [{"asset_id": "46550817779287714248071035919960687231435496748461488768996323006087698669681", "price": "0.09", "size": "22915", "side": "BUY", "hash": "82858475d87f8271209eaf23098f1efd4cb84928", "best_bid": "0.09", "best_ask": "0.12"}, {"asset_id": "87939649752104648558739188569294623185189846388915750654886353417082965270846", "price": "0.91", "size": "22915", "side": "SELL", "hash": "4b267e640e67dbc54e4260431e13cf2545989ee3", "best_bid": "0.88", "best_ask": "0.91"}], "timestamp": "1769384688501", "event_type": "price_change"}}
{"_local_timestamp": "2026-01-25T23:44:48.713925+00:00", "data": {"market": "0x85096ae131a795ac80db209f9e633e5310fd4fd11b3c2e8b2748614139480c41", "price_changes": [{"asset_id": "46550817779287714248071035919960687231435496748461488768996323006087698669681", "price": "0.09", "size": "23105", "side": "BUY", "hash": "92890439b3113ce3d2efd4c115bb8d77523c07b1", "best_bid": "0.09", "best_ask": "0.12"}, {"asset_id": "87939649752104648558739188569294623185189846388915750654886353417082965270846", "price": "0.91", "size": "23105", "side": "SELL", "hash": "a07586395b7878406f7b19df2da9897715a3190f", "best_bid": "0.88", "best_ask": "0.91"}], "timestamp": "1769384688502", "event_type": "price_change"}}
{"_local_timestamp": "2026-01-25T23:44:48.714394+00:00", "data": {"market": "0x85096ae131a795ac80db209f9e633e5310fd4fd11b3c2e8b2748614139480c41", "price_changes": [{"asset_id": "46550817779287714248071035919960687231435496748461488768996323006087698669681", "price": "0.09", "size": "23165", "side": "BUY", "hash": "9a87e420541a68de0cd78b78114f21dc73dac972", "best_bid": "0.09", "best_ask": "0.12"}, {"asset_id": "87939649752104648558739188569294623185189846388915750654886353417082965270846", "price": "0.91", "size": "23165", "side": "SELL", "hash": "cd1107828f6634f094e6baa313d0d9a46afa5a44", "best_bid": "0.88", "best_ask": "0.91"}], "timestamp": "1769384688503", "event_type": "price_change"}}
{"_local_timestamp": "2026-01-25T23:44:48.714843+00:00", "data": {"market": "0x85096ae131a795ac80db209f9e633e5310fd4fd11b3c2e8b2748614139480c41", "price_changes": [{"asset_id": "87939649752104648558739188569294623185189846388915750654886353417082965270846", "price": "0.86", "size": "22730", "side": "BUY", "hash": "1225c0e9b624354fe48d7d76b96cf88c8a64133b", "best_bid": "0.88", "best_ask": "0.91"}, {"asset_id": "46550817779287714248071035919960687231435496748461488768996323006087698669681", "price": "0.14", "size": "22730", "side": "SELL", "hash": "13bb1b79f091dfe50d13bb6bf30b50c2190056b6", "best_bid": "0.09", "best_ask": "0.12"}], "timestamp": "1769384688503", "event_type": "price_change"}}
{"_local_timestamp": "2026-01-25T23:44:48.715304+00:00", "data": {"market": "0x85096ae131a795ac80db209f9e633e5310fd4fd11b3c2e8b2748614139480c41", "price_changes": [{"asset_id": "87939649752104648558739188569294623185189846388915750654886353417082965270846", "price": "0.86", "size": "22920", "side": "BUY", "hash": "99687ac305918e4eb81d9038c54f074c694c4c3c", "best_bid": "0.88", "best_ask": "0.91"}, {"asset_id": "46550817779287714248071035919960687231435496748461488768996323006087698669681", "price": "0.14", "size": "22920", "side": "SELL", "hash": "500f3a6a93a3d7a1f7af5f23f50773a98f9cbcda", "best_bid": "0.09", "best_ask": "0.12"}], "timestamp": "1769384688504", "event_type": "price_change"}}
{"_local_timestamp": "2026-01-25T23:44:48.715787+00:00", "data": {"market": "0x85096ae131a795ac80db209f9e633e5310fd4fd11b3c2e8b2748614139480c41", "price_changes": [{"asset_id": "46550817779287714248071035919960687231435496748461488768996323006087698669681", "price": "0.09", "size": "23225", "side": "BUY", "hash": "0203114bca094e8efa288525f3cfaca9ad90dfc9", "best_bid": "0.09", "best_ask": "0.12"}, {"asset_id": "87939649752104648558739188569294623185189846388915750654886353417082965270846", "price": "0.91", "size": "23225", "side": "SELL", "hash": "e07817dcde6652ac851ff8988ddcc9c9defe0162", "best_bid": "0.88", "best_ask": "0.91"}], "timestamp": "1769384688506", "event_type": "price_change"}}
{"_local_timestamp": "2026-01-25T23:44:48.716245+00:00", "data": {"market": "0x85096ae131a795ac80db209f9e633e5310fd4fd11b3c2e8b2748614139480c41", "price_changes": [{"asset_id": "87939649752104648558739188569294623185189846388915750654886353417082965270846", "price": "0.86", "size": "22980", "side": "BUY", "hash": "ad4c36a33de42762bdf3565036c163ce013aa464", "best_bid": "0.88", "best_ask": "0.91"}, {"asset_id": "46550817779287714248071035919960687231435496748461488768996323006087698669681", "price": "0.14", "size": "22980", "side": "SELL", "hash": "f1411d034eafbf0150fce44e8b6a81ac7dbc46fc", "best_bid": "0.09", "best_ask": "0.12"}], "timestamp": "1769384688508", "event_type": "price_change"}}
{"_local_timestamp": "2026-01-25T23:44:48.716707+00:00", "data": {"market": "0x85096ae131a795ac80db209f9e633e5310fd4fd11b3c2e8b2748614139480c41", "price_changes": [{"asset_id": "87939649752104648558739188569294623185189846388915750654886353417082965270846", "price": "0.86", "size": "23160", "side": "BUY", "hash": "503c9203e3b7fbda402003e50e99cff078074237", "best_bid": "0.88", "best_ask": "0.91"}, {"asset_id": "46550817779287714248071035919960687231435496748461488768996323006087698669681", "price": "0.14", "size": "23160", "side": "SELL", "hash": "c5d3efabe51606ac4a3decf9deabae76aa329c89", "best_bid": "0.09", "best_ask": "0.12"}], "timestamp": "1769384688509", "event_type": "price_change"}}
{"_local_timestamp": "2026-01-25T23:44:48.717182+00:00", "data": {"market": "0x85096ae131a795ac80db209f9e633e5310fd4fd11b3c2e8b2748614139480c41", "price_changes": [{"asset_id": "87939649752104648558739188569294623185189846388915750654886353417082965270846", "price": "0.86", "size": "23330", "side": "BUY", "hash": "61d0508a7093ee567a108705c7a0ab62cc87e17e", "best_bid": "0.88", "best_ask": "0.91"}, {"asset_id": "46550817779287714248071035919960687231435496748461488768996323006087698669681", "price": "0.14", "size": "23330", "side": "SELL", "hash": "d11116087f88ccc7ed942a1712f4d92f74a40a7a", "best_bid": "0.09", "best_ask": "0.12"}], "timestamp": "1769384688509", "event_type": "price_change"}}
{"_local_timestamp": "2026-01-25T23:44:48.717632+00:00", "data": {"market": "0x85096ae131a795ac80db209f9e633e5310fd4fd11b3c2e8b2748614139480c41", "price_changes": [{"asset_id": "46550817779287714248071035919960687231435496748461488768996323006087698669681", "price": "0.09", "size": "23285", "side": "BUY", "hash": "2fb59c732854f1e79b7327a4bc1b01fb10c0a6ed", "best_bid": "0.09", "best_ask": "0.12"}, {"asset_id": "87939649752104648558739188569294623185189846388915750654886353417082965270846", "price": "0.91", "size": "23285", "side": "SELL", "hash": "5df150564f3718a62049c615f17b48442a8326c5", "best_bid": "0.88", "best_ask": "0.91"}], "timestamp": "1769384688510", "event_type": "price_change"}}
{"_local_timestamp": "2026-01-25T23:44:48.718090+00:00", "data": {"market": "0x85096ae131a795ac80db209f9e633e5310fd4fd11b3c2e8b2748614139480c41", "price_changes": [{"asset_id": "46550817779287714248071035919960687231435496748461488768996323006087698669681", "price": "0.09", "size": "23345", "side": "BUY", "hash": "814a4468f35bd0ca7398c32332a9a3b8fe679a0e", "best_bid": "0.09", "best_ask": "0.12"}, {"asset_id": "87939649752104648558739188569294623185189846388915750654886353417082965270846", "price": "0.91", "size": "23345", "side": "SELL", "hash": "9e66cde3513a6bf4e2a03bc1ecf6a774dc8a3a69", "best_bid": "0.88", "best_ask": "0.91"}], "timestamp": "1769384688511", "event_type": "price_change"}}
{"_local_timestamp": "2026-01-25T23:44:48.718566+00:00", "data": {"market": "0x85096ae131a795ac80db209f9e633e5310fd4fd11b3c2e8b2748614139480c41", "price_changes": [{"asset_id": "87939649752104648558739188569294623185189846388915750654886353417082965270846", "price": "0.86", "size": "23500", "side": "BUY", "hash": "72f4061307d42c23840dcd0510bc768fce5e7ad6", "best_bid": "0.88", "best_ask": "0.91"}, {"asset_id": "46550817779287714248071035919960687231435496748461488768996323006087698669681", "price": "0.14", "size": "23500", "side": "SELL", "hash": "a3ac84db4f7c2b2cf589098d5cc549ec79ee59b3", "best_bid": "0.09", "best_ask": "0.12"}], "timestamp": "1769384688511", "event_type": "price_change"}}
{"_local_timestamp": "2026-01-25T23:44:48.719026+00:00", "data": {"market": "0x85096ae131a795ac80db209f9e633e5310fd4fd11b3c2e8b2748614139480c41", "price_changes": [{"asset_id": "87939649752104648558739188569294623185189846388915750654886353417082965270846", "price": "0.86", "size": "23620", "side": "BUY", "hash": "444619b38300eff66373fd5b4e52eabfa7fe40cb", "best_bid": "0.88", "best_ask": "0.91"}, {"asset_id": "46550817779287714248071035919960687231435496748461488768996323006087698669681", "price": "0.14", "size": "23620", "side": "SELL", "hash": "080b6012e828a1681cb79ee0f434be3e13df053f", "best_bid": "0.09", "best_ask": "0.12"}], "timestamp": "1769384688512", "event_type": "price_change"}}
{"_local_timestamp": "2026-01-25T23:44:48.719483+00:00", "data": {"market": "0x85096ae131a795ac80db209f9e633e5310fd4fd11b3c2e8b2748614139480c41", "price_changes": [{"asset_id": "87939649752104648558739188569294623185189846388915750654886353417082965270846", "price": "0.86", "size": "23790", "side": "BUY", "hash": "6b50362b4e3be68707887df478cb6fa1c0433de7", "best_bid": "0.88", "best_ask": "0.91"}, {"asset_id": "46550817779287714248071035919960687231435496748461488768996323006087698669681", "price": "0.14", "size": "23790", "side": "SELL", "hash": "7f97b19c293bfcadd7d02617a6cfed16e2ba2843", "best_bid": "0.09", "best_ask": "0.12"}], "timestamp": "1769384688513", "event_type": "price_change"}}
{"_local_timestamp": "2026-01-25T23:44:48.719945+00:00", "data": {"market": "0x85096ae131a795ac80db209f9e633e5310fd4fd11b3c2e8b2748614139480c41", "price_changes": [{"asset_id": "46550817779287714248071035919960687231435496748461488768996323006087698669681", "price": "0.09", "size": "23405", "side": "BUY", "hash": "8be11ffd4c1164a8e60800a8b8a82a9299a70646", "best_bid": "0.09", "best_ask": "0.12"}, {"asset_id": "87939649752104648558739188569294623185189846388915750654886353417082965270846", "price": "0.91", "size": "23405", "side": "SELL", "hash": "ea7172bd862c50927abae7b131ced39cd04d281f", "best_bid": "0.88", "best_ask": "0.91"}], "timestamp": "1769384688514", "event_type": "price_change"}}
{"_local_timestamp": "2026-01-25T23:44:48.720413+00:00", "data": {"market": "0x85096ae131a795ac80db209f9e633e5310fd4fd11b3c2e8b2748614139480c41", "price_changes": [{"asset_id": "87939649752104648558739188569294623185189846388915750654886353417082965270846", "price": "0.86", "size": "23850", "side": "BUY", "hash": "5f1019b9708deedda4d1e5d15ffd473863f8a6b4", "best_bid": "0.88", "best_ask": "0.91"}, {"asset_id": "46550817779287714248071035919960687231435496748461488768996323006087698669681", "price": "0.14", "size": "23850", "side": "SELL", "hash": "58571bc63a446b23e5ace8ce1ddd10ed7a9f1321", "best_bid": "0.09", "best_ask": "0.12"}], "timestamp": "1769384688514", "event_type": "price_change"}}
{"_local_timestamp": "2026-01-25T23:44:48.720892+00:00", "data": {"market": "0x85096ae131a795ac80db209f9e633e5310fd4fd11b3c2e8b2748614139480c41", "price_changes": [{"asset_id": "46550817779287714248071035919960687231435496748461488768996323006087698669681", "price": "0.09", "size": "23585", "side": "BUY", "hash": "0d52b1ed5059d67b40a0fa9ffa9ae85df30d6435", "best_bid": "0.09", "best_ask": "0.12"}, {"asset_id": "87939649752104648558739188569294623185189846388915750654886353417082965270846", "price": "0.91", "size": "23585", "side": "SELL", "hash": "845f5d9608ddd1c7ec8dd1208d2a38b829f6a8dd", "best_bid": "0.88", "best_ask": "0.91"}], "timestamp": "1769384688515", "event_type": "price_change"}}
{"_local_timestamp": "2026-01-25T23:44:48.721377+00:00", "data": {"market": "0x85096ae131a795ac80db209f9e633e5310fd4fd11b3c2e8b2748614139480c41", "price_changes": [{"asset_id": "87939649752104648558739188569294623185189846388915750654886353417082965270846", "price": "0.86", "size": "23970", "side": "BUY", "hash": "1c64ba9e1055f31a5f4fa407cb78b1cd4cba415a", "best_bid": "0.88", "best_ask": "0.91"}, {"asset_id": "46550817779287714248071035919960687231435496748461488768996323006087698669681", "price": "0.14", "size": "23970", "side": "SELL", "hash": "f443d1714a56bb8657ccedb75a49a044ed78c281", "best_bid": "0.09", "best_ask": "0.12"}], "timestamp": "1769384688515", "event_type": "price_change"}}
{"_local_timestamp": "2026-01-25T23:44:48.721854+00:00", "data": {"market": "0x85096ae131a795ac80db209f9e633e5310fd4fd11b3c2e8b2748614139480c41", "price_changes": [{"asset_id": "46550817779287714248071035919960687231435496748461488768996323006087698669681", "price": "0.09", "size": "23755", "side": "BUY", "hash": "6ae0f510d4ac2e4fab87857a7008aaf15cefd9db", "best_bid": "0.09", "best_ask": "0.12"}, {"asset_id": "87939649752104648558739188569294623185189846388915750654886353417082965270846", "price": "0.91", "size": "23755", "side": "SELL", "hash": "d50080ae6cd8e4f2a6d23df5cdadececf44bece5", "best_bid": "0.88", "best_ask": "0.91"}], "timestamp": "1769384688516", "event_type": "price_change"}}
{"_local_timestamp": "2026-01-25T23:44:48.722331+00:00", "data": {"market": "0x85096ae131a795ac80db209f9e633e5310fd4fd11b3c2e8b2748614139480c41", "price_changes": [{"asset_id": "46550817779287714248071035919960687231435496748461488768996323006087698669681", "price": "0.09", "size": "23855", "side": "BUY", "hash": "08f957475774a5a0515d1d32dca5286a32d2c77d", "best_bid": "0.09", "best_ask": "0.12"}, {"asset_id": "87939649752104648558739188569294623185189846388915750654886353417082965270846", "price": "0.91", "size": "23855", "side": "SELL", "hash": "d2f58533ca8dbc4b18bc51b2f82671ba24268b3f", "best_bid": "0.88", "best_ask": "0.91"}], "timestamp": "1769384688517", "event_type": "price_change"}}
{"_local_timestamp": "2026-01-25T23:44:48.722935+00:00", "data": {"market": "0x85096ae131a795ac80db209f9e633e5310fd4fd11b3c2e8b2748614139480c41", "price_changes": [{"asset_id": "46550817779287714248071035919960687231435496748461488768996323006087698669681", "price": "0.09", "size": "23975", "side": "BUY", "hash": "23d2f819da4c8ad1e8736d86bc1e855ab282b54c", "best_bid": "0.09", "best_ask": "0.12"}, {"asset_id": "87939649752104648558739188569294623185189846388915750654886353417082965270846", "price": "0.91", "size": "23975", "side": "SELL", "hash": "9bdaf7ab80adc98cfece0811914b76f17dbc6d64", "best_bid": "0.88", "best_ask": "0.91"}], "timestamp": "1769384688518", "event_type": "price_change"}}
{"_local_timestamp": "2026-01-25T23:44:48.723435+00:00", "data": {"market": "0x85096ae131a795ac80db209f9e633e5310fd4fd11b3c2e8b2748614139480c41", "price_changes": [{"asset_id": "46550817779287714248071035919960687231435496748461488768996323006087698669681", "price": "0.09", "size": "24145", "side": "BUY", "hash": "fc76c5f53d743aa0ad7718f8db7237cb963ada98", "best_bid": "0.09", "best_ask": "0.12"}, {"asset_id": "87939649752104648558739188569294623185189846388915750654886353417082965270846", "price": "0.91", "size": "24145", "side": "SELL", "hash": "f6341423be2062136520862a6b7100d7b45cc5e5", "best_bid": "0.88", "best_ask": "0.91"}], "timestamp": "1769384688520", "event_type": "price_change"}}
{"_local_timestamp": "2026-01-25T23:44:48.723913+00:00", "data": {"market": "0x85096ae131a795ac80db209f9e633e5310fd4fd11b3c2e8b2748614139480c41", "price_changes": [{"asset_id": "46550817779287714248071035919960687231435496748461488768996323006087698669681", "price": "0.09", "size": "24265", "side": "BUY", "hash": "bbae22f52807d682b20971173b7bea0a00030cb0", "best_bid": "0.09", "best_ask": "0.12"}, {"asset_id": "87939649752104648558739188569294623185189846388915750654886353417082965270846", "price": "0.91", "size": "24265", "side": "SELL", "hash": "077b80097cdead7e12d90de41bb72cc86cc83240", "best_bid": "0.88", "best_ask": "0.91"}], "timestamp": "1769384688522", "event_type": "price_change"}}
{"_local_timestamp": "2026-01-25T23:44:48.724395+00:00", "data": {"market": "0x85096ae131a795ac80db209f9e633e5310fd4fd11b3c2e8b2748614139480c41", "price_changes": [{"asset_id": "87939649752104648558739188569294623185189846388915750654886353417082965270846", "price": "0.86", "size": "24140", "side": "BUY", "hash": "27587fc8ace4d8be5dc1a12686376f9d32e5e8bd", "best_bid": "0.88", "best_ask": "0.91"}, {"asset_id": "46550817779287714248071035919960687231435496748461488768996323006087698669681", "price": "0.14", "size": "24140", "side": "SELL", "hash": "6df32b9c5e00d6b71febd411d8835d77449d6a84", "best_bid": "0.09", "best_ask": "0.12"}], "timestamp": "1769384688523", "event_type": "price_change"}}
{"_local_timestamp": "2026-01-25T23:44:48.724872+00:00", "data": {"market": "0x85096ae131a795ac80db209f9e633e5310fd4fd11b3c2e8b2748614139480c41", "price_changes": [{"asset_id": "46550817779287714248071035919960687231435496748461488768996323006087698669681", "price": "0.09", "size": "24385", "side": "BUY", "hash": "f377c13ae9fa034d7771eeed6e391d8f418cefe9", "best_bid": "0.09", "best_ask": "0.12"}, {"asset_id": "87939649752104648558739188569294623185189846388915750654886353417082965270846", "price": "0.91", "size": "24385", "side": "SELL", "hash": "41f5cac96fe4fa5a91f285bc158f7d1590bbc595", "best_bid": "0.88", "best_ask": "0.91"}], "timestamp": "1769384688523", "event_type": "price_change"}}
{"_local_timestamp": "2026-01-25T23:44:48.725370+00:00", "data": {"market": "0x85096ae131a795ac80db209f9e633e5310fd4fd11b3c2e8b2748614139480c41", "price_changes": [{"asset_id": "87939649752104648558739188569294623185189846388915750654886353417082965270846", "price": "0.86", "size": "24200", "side": "BUY", "hash": "b0c4087868f72bd17e35502e8bb075653207840c", "best_bid": "0.88", "best_ask": "0.91"}, {"asset_id": "46550817779287714248071035919960687231435496748461488768996323006087698669681", "price": "0.14", "size": "24200", "side": "SELL", "hash": "31b501c3ed085d3954e354245ed29d03eab260e0", "best_bid": "0.09", "best_ask": "0.12"}], "timestamp": "1769384688524", "event_type": "price_change"}}
{"_local_timestamp": "2026-01-25T23:44:48.725856+00:00", "data": {"market": "0x85096ae131a795ac80db209f9e633e5310fd4fd11b3c2e8b2748614139480c41", "price_changes": [{"asset_id": "87939649752104648558739188569294623185189846388915750654886353417082965270846", "price": "0.86", "size": "24450", "side": "BUY", "hash": "126e904165c5be24201ceaf007b475ffe5917def", "best_bid": "0.88", "best_ask": "0.91"}, {"asset_id": "46550817779287714248071035919960687231435496748461488768996323006087698669681", "price": "0.14", "size": "24450", "side": "SELL", "hash": "eb33a8bd1a4b995a4d0d4c37a79d53068eeb29d5", "best_bid": "0.09", "best_ask": "0.12"}], "timestamp": "1769384688528", "event_type": "price_change"}}
{"_local_timestamp": "2026-01-25T23:44:48.726329+00:00", "data": {"market": "0x85096ae131a795ac80db209f9e633e5310fd4fd11b3c2e8b2748614139480c41", "price_changes": [{"asset_id": "87939649752104648558739188569294623185189846388915750654886353417082965270846", "price": "0.86", "size": "24570", "side": "BUY", "hash": "d305367c0e2b1c95636ae36b7c196112bfe75e5c", "best_bid": "0.88", "best_ask": "0.91"}, {"asset_id": "46550817779287714248071035919960687231435496748461488768996323006087698669681", "price": "0.14", "size": "24570", "side": "SELL", "hash": "5eff13f799aaa0a7216942f3885903acce233b36", "best_bid": "0.09", "best_ask": "0.12"}], "timestamp": "1769384688528", "event_type": "price_change"}}
{"_local_timestamp": "2026-01-25T23:44:48.726809+00:00", "data": {"market": "0x85096ae131a795ac80db209f9e633e5310fd4fd11b3c2e8b2748614139480c41", "price_changes": [{"asset_id": "87939649752104648558739188569294623185189846388915750654886353417082965270846", "price": "0.86", "size": "24690", "side": "BUY", "hash": "f61263fa8c01f5594285b331c4c9896ff0033ab9", "best_bid": "0.88", "best_ask": "0.91"}, {"asset_id": "46550817779287714248071035919960687231435496748461488768996323006087698669681", "price": "0.14", "size": "24690", "side": "SELL", "hash": "2c3cf2ffb2afadad2cc5a3d58d49c736aa05db6c", "best_bid": "0.09", "best_ask": "0.12"}], "timestamp": "1769384688530", "event_type": "price_change"}}
{"_local_timestamp": "2026-01-25T23:44:48.727293+00:00", "data": {"market": "0x85096ae131a795ac80db209f9e633e5310fd4fd11b3c2e8b2748614139480c41", "price_changes": [{"asset_id": "46550817779287714248071035919960687231435496748461488768996323006087698669681", "price": "0.09", "size": "24635", "side": "BUY", "hash": "007335703192b80c0e34b7f21f5537dc0be1fac6", "best_bid": "0.09", "best_ask": "0.12"}, {"asset_id": "87939649752104648558739188569294623185189846388915750654886353417082965270846", "price": "0.91", "size": "24635", "side": "SELL", "hash": "b2a3c19674d9a1d829724ca61f75d3aa99dc89c9", "best_bid": "0.88", "best_ask": "0.91"}], "timestamp": "1769384688536", "event_type": "price_change"}}
{"_local_timestamp": "2026-01-25T23:44:48.727789+00:00", "data": {"market": "0x85096ae131a795ac80db209f9e633e5310fd4fd11b3c2e8b2748614139480c41", "price_changes": [{"asset_id": "46550817779287714248071035919960687231435496748461488768996323006087698669681", "price": "0.09", "size": "24735", "side": "BUY", "hash": "5ede95b6f409d69ec1281dff7209171769e4674d", "best_bid": "0.09", "best_ask": "0.12"}, {"asset_id": "87939649752104648558739188569294623185189846388915750654886353417082965270846", "price": "0.91", "size": "24735", "side": "SELL", "hash": "087c4e341e1e65d19376f61403758f9bc37423be", "best_bid": "0.88", "best_ask": "0.91"}], "timestamp": "1769384688537", "event_type": "price_change"}}
{"_local_timestamp": "2026-01-25T23:44:48.728301+00:00", "data": {"market": "0x85096ae131a795ac80db209f9e633e5310fd4fd11b3c2e8b2748614139480c41", "price_changes": [{"asset_id": "87939649752104648558739188569294623185189846388915750654886353417082965270846", "price": "0.86", "size": "24790", "side": "BUY", "hash": "7261f6ef9cac5d85bce202ab8fcf50097b51565e", "best_bid": "0.88", "best_ask": "0.91"}, {"asset_id": "46550817779287714248071035919960687231435496748461488768996323006087698669681", "price": "0.14", "size": "24790", "side": "SELL", "hash": "cd6bdffe56e11d518a6d671f0d42595c5e0b2f29", "best_bid": "0.09", "best_ask": "0.12"}], "timestamp": "1769384688537", "event_type": "price_change"}}
{"_local_timestamp": "2026-01-25T23:44:48.728796+00:00", "data": {"market": "0x85096ae131a795ac80db209f9e633e5310fd4fd11b3c2e8b2748614139480c41", "price_changes": [{"asset_id": "46550817779287714248071035919960687231435496748461488768996323006087698669681", "price": "0.09", "size": "24905", "side": "BUY", "hash": "e4a11a0aa2a6a3341dba49dc73f3346558dfe5af", "best_bid": "0.09", "best_ask": "0.12"}, {"asset_id": "87939649752104648558739188569294623185189846388915750654886353417082965270846", "price": "0.91", "size": "24905", "side": "SELL", "hash": "3c5c648ec4d6d59552db1d1615e14e30ae310fa8", "best_bid": "0.88", "best_ask": "0.91"}], "timestamp": "1769384688542", "event_type": "price_change"}}
{"_local_timestamp": "2026-01-25T23:44:48.729286+00:00", "data": {"market": "0x85096ae131a795ac80db209f9e633e5310fd4fd11b3c2e8b2748614139480c41", "price_changes": [{"asset_id": "87939649752104648558739188569294623185189846388915750654886353417082965270846", "price": "0.86", "size": "24960", "side": "BUY", "hash": "b75f4d863d57c0a94f3427b978955c1176b0feae", "best_bid": "0.88", "best_ask": "0.91"}, {"asset_id": "46550817779287714248071035919960687231435496748461488768996323006087698669681", "price": "0.14", "size": "24960", "side": "SELL", "hash": "632bae51867e9d626732da21a11506274a87ea79", "best_bid": "0.09", "best_ask": "0.12"}], "timestamp": "1769384688551", "event_type": "price_change"}}
{"_local_timestamp": "2026-01-25T23:44:48.729819+00:00", "data": {"market": "0x85096ae131a795ac80db209f9e633e5310fd4fd11b3c2e8b2748614139480c41", "price_changes": [{"asset_id": "46550817779287714248071035919960687231435496748461488768996323006087698669681", "price": "0.09", "size": "25075", "side": "BUY", "hash": "46617a9f8201716ab32b59d494a85e7555b937a5", "best_bid": "0.09", "best_ask": "0.12"}, {"asset_id": "87939649752104648558739188569294623185189846388915750654886353417082965270846", "price": "0.91", "size": "25075", "side": "SELL", "hash": "9af7ec75fbe5f3e3413955a2f65027c9aa86cf81", "best_bid": "0.88", "best_ask": "0.91"}], "timestamp": "1769384688556", "event_type": "price_change"}}
{"_local_timestamp": "2026-01-25T23:44:48.730320+00:00", "data": {"market": "0x85096ae131a795ac80db209f9e633e5310fd4fd11b3c2e8b2748614139480c41", "price_changes": [{"asset_id": "46550817779287714248071035919960687231435496748461488768996323006087698669681", "price": "0.09", "size": "25155", "side": "BUY", "hash": "91c948312b0a1350da915eb9e570ff458b342213", "best_bid": "0.09", "best_ask": "0.12"}, {"asset_id": "87939649752104648558739188569294623185189846388915750654886353417082965270846", "price": "0.91", "size": "25155", "side": "SELL", "hash": "66308ee629f5ec9636aa057415c5093d8bbe0c6c", "best_bid": "0.88", "best_ask": "0.91"}], "timestamp": "1769384688607", "event_type": "price_change"}}
{"_local_timestamp": "2026-01-25T23:44:48.730825+00:00", "data": {"market": "0x85096ae131a795ac80db209f9e633e5310fd4fd11b3c2e8b2748614139480c41", "price_changes": [{"asset_id": "87939649752104648558739188569294623185189846388915750654886353417082965270846", "price": "0.86", "size": "25040", "side": "BUY", "hash": "74e41acfd5a53b88ae8b1fa851e8cc5707d6a3b5", "best_bid": "0.88", "best_ask": "0.91"}, {"asset_id": "46550817779287714248071035919960687231435496748461488768996323006087698669681", "price": "0.14", "size": "25040", "side": "SELL", "hash": "3390272677915023961e5d948194c50e3822e1f3", "best_bid": "0.09", "best_ask": "0.12"}], "timestamp": "1769384688617", "event_type": "price_change"}}
{"_local_timestamp": "2026-01-25T23:44:48.918043+00:00", "data": {"market": "0x85096ae131a795ac80db209f9e633e5310fd4fd11b3c2e8b2748614139480c41", "price_changes": [{"asset_id": "46550817779287714248071035919960687231435496748461488768996323006087698669681", "price": "0.09", "size": "25215", "side": "BUY", "hash": "51258334957eccb6babe2b6f0333f3d10c0358a4", "best_bid": "0.09", "best_ask": "0.12"}, {"asset_id": "87939649752104648558739188569294623185189846388915750654886353417082965270846", "price": "0.91", "size": "25215", "side": "SELL", "hash": "1f5363d70d03e1236b1728724d362b3a3aa59e6f", "best_bid": "0.88", "best_ask": "0.91"}], "timestamp": "1769384688829", "event_type": "price_change"}}
{"_local_timestamp": "2026-01-25T23:44:48.923878+00:00", "data": {"market": "0x85096ae131a795ac80db209f9e633e5310fd4fd11b3c2e8b2748614139480c41", "price_changes": [{"asset_id": "87939649752104648558739188569294623185189846388915750654886353417082965270846", "price": "0.86", "size": "25100", "side": "BUY", "hash": "a0464d9513297ddb5f8af5ae0f7076fe8924c15e", "best_bid": "0.88", "best_ask": "0.91"}, {"asset_id": "46550817779287714248071035919960687231435496748461488768996323006087698669681", "price": "0.14", "size": "25100", "side": "SELL", "hash": "6863bc388725b26ff26553f38c69228863a8a7ac", "best_bid": "0.09", "best_ask": "0.12"}], "timestamp": "1769384688849", "event_type": "price_change"}}
{"_local_timestamp": "2026-01-25T23:44:49.093881+00:00", "data": {"market": "0x85096ae131a795ac80db209f9e633e5310fd4fd11b3c2e8b2748614139480c41", "price_changes": [{"asset_id": "46550817779287714248071035919960687231435496748461488768996323006087698669681", "price": "0.09", "size": "25515", "side": "BUY", "hash": "a2b03c231df63f4d0ec35960b4d623bb7d844852", "best_bid": "0.09", "best_ask": "0.12"}, {"asset_id": "87939649752104648558739188569294623185189846388915750654886353417082965270846", "price": "0.91", "size": "25515", "side": "SELL", "hash": "26401aff62ed7ac5017d3790a0090631b5778e8f", "best_bid": "0.88", "best_ask": "0.91"}], "timestamp": "1769384689005", "event_type": "price_change"}}
{"_local_timestamp": "2026-01-25T23:44:49.454925+00:00", "data": {"market": "0x85096ae131a795ac80db209f9e633e5310fd4fd11b3c2e8b2748614139480c41", "price_changes": [{"asset_id": "46550817779287714248071035919960687231435496748461488768996323006087698669681", "price": "0.09", "size": "25715", "side": "BUY", "hash": "afd75ec1fa87fa484fa940c8df6d1310cd883af2", "best_bid": "0.09", "best_ask": "0.12"}, {"asset_id": "87939649752104648558739188569294623185189846388915750654886353417082965270846", "price": "0.91", "size": "25715", "side": "SELL", "hash": "ccb5375536d0587784d639f405dd6f7ed32f2af3", "best_bid": "0.88", "best_ask": "0.91"}], "timestamp": "1769384689391", "event_type": "price_change"}}
{"_local_timestamp": "2026-01-25T23:44:49.632512+00:00", "data": {"market": "0x85096ae131a795ac80db209f9e633e5310fd4fd11b3c2e8b2748614139480c41", "price_changes": [{"asset_id": "87939649752104648558739188569294623185189846388915750654886353417082965270846", "price": "0.86", "size": "25400", "side": "BUY", "hash": "6e6728e382bda78874e0d39aba6dd0de266dc7c3", "best_bid": "0.88", "best_ask": "0.91"}, {"asset_id": "46550817779287714248071035919960687231435496748461488768996323006087698669681", "price": "0.14", "size": "25400", "side": "SELL", "hash": "63ccb3061026feef6f88fdd32c1de68c04066766", "best_bid": "0.09", "best_ask": "0.12"}], "timestamp": "1769384689563", "event_type": "price_change"}}
{"_local_timestamp": "2026-01-25T23:44:50.135149+00:00", "data": {"market": "0x85096ae131a795ac80db209f9e633e5310fd4fd11b3c2e8b2748614139480c41", "price_changes": [{"asset_id": "87939649752104648558739188569294623185189846388915750654886353417082965270846", "price": "0.86", "size": "25600", "side": "BUY", "hash": "256557d9d76f5ede949f1e2dad996bea905e09bb", "best_bid": "0.88", "best_ask": "0.91"}, {"asset_id": "46550817779287714248071035919960687231435496748461488768996323006087698669681", "price": "0.14", "size": "25600", "side": "SELL", "hash": "6a82b93834a81b099bf5973811553e04275d46e9", "best_bid": "0.09", "best_ask": "0.12"}], "timestamp": "1769384690055", "event_type": "price_change"}}
{"_local_timestamp": "2026-01-25T23:45:31.006248+00:00", "data": {"market": "0x85096ae131a795ac80db209f9e633e5310fd4fd11b3c2e8b2748614139480c41", "price_changes": [{"asset_id": "46550817779287714248071035919960687231435496748461488768996323006087698669681", "price": "0.08", "size": "370", "side": "BUY", "hash": "201b26e3abd429dd0acad95fb773875cf8eec9a4", "best_bid": "0.09", "best_ask": "0.12"}, {"asset_id": "87939649752104648558739188569294623185189846388915750654886353417082965270846", "price": "0.92", "size": "370", "side": "SELL", "hash": "baec126caf34fb3285238efe7ea516062f121b0f", "best_bid": "0.88", "best_ask": "0.91"}], "timestamp": "1769384730935", "event_type": "price_change"}}
{"_local_timestamp": "2026-01-25T23:45:31.006921+00:00", "data": {"market": "0x85096ae131a795ac80db209f9e633e5310fd4fd11b3c2e8b2748614139480c41", "price_changes": [{"asset_id": "87939649752104648558739188569294623185189846388915750654886353417082965270846", "price": "0.82", "size": "200", "side": "BUY", "hash": "de1b23d10c8ffeeadd43226ede205d2b6924a618", "best_bid": "0.88", "best_ask": "0.91"}, {"asset_id": "46550817779287714248071035919960687231435496748461488768996323006087698669681", "price": "0.18", "size": "200", "side": "SELL", "hash": "fad00d2890dc3e84d734d604492b3a5873a0c4ad", "best_bid": "0.09", "best_ask": "0.12"}], "timestamp": "1769384730936", "event_type": "price_change"}}
{"_local_timestamp": "2026-01-25T23:45:56.538015+00:00", "data": {"market": "0x85096ae131a795ac80db209f9e633e5310fd4fd11b3c2e8b2748614139480c41", "price_changes": [{"asset_id": "87939649752104648558739188569294623185189846388915750654886353417082965270846", "price": "0.13", "size": "100", "side": "BUY", "hash": "26786833adc70a68f0adfa3e271c01fb4fbf37e5", "best_bid": "0.88", "best_ask": "0.91"}, {"asset_id": "46550817779287714248071035919960687231435496748461488768996323006087698669681", "price": "0.87", "size": "100", "side": "SELL", "hash": "4f57d4d9465c5f5ad3c2235439b6f38bda886bb5", "best_bid": "0.09", "best_ask": "0.12"}], "timestamp": "1769384756081", "event_type": "price_change"}}
{"_local_timestamp": "2026-01-25T23:45:56.655149+00:00", "data": {"market": "0x92dbb7abf136a99dbdbd0bf6b3e168324aba36c885f050a81b9f99f5c86a2c89", "price_changes": [{"asset_id": "742549944322286743622311352663151843513942481342353661165797752687706656334", "price": "0.07", "size": "500", "side": "BUY", "hash": "aba0fcdadade3a4b4c229d8ad5d4f47c2df4cc32", "best_bid": "0.31", "best_ask": "0.33"}, {"asset_id": "85926585546290965710378781547851562606368161566069895279131565989650277464683", "price": "0.93", "size": "500", "side": "SELL", "hash": "4b8ada2813779c3c7184e2a806e609fcb35fc649", "best_bid": "0.67", "best_ask": "0.69"}], "timestamp": "1769384756093", "event_type": "price_change"}}
{"_local_timestamp": "2026-01-25T23:46:36.437102+00:00", "data": {"market": "0x85096ae131a795ac80db209f9e633e5310fd4fd11b3c2e8b2748614139480c41", "price_changes": [{"asset_id": "87939649752104648558739188569294623185189846388915750654886353417082965270846", "price": "0.03", "size": "309.52", "side": "BUY", "hash": "466194ed342fb1ed5958b1bee25739370f24bac9", "best_bid": "0.88", "best_ask": "0.91"}, {"asset_id": "46550817779287714248071035919960687231435496748461488768996323006087698669681", "price": "0.97", "size": "309.52", "side": "SELL", "hash": "4a09b36d238b376ba05834b129dae186dc7a91dc", "best_bid": "0.09", "best_ask": "0.12"}], "timestamp": "1769384796363", "event_type": "price_change"}}
{"_local_timestamp": "2026-01-25T23:46:36.766120+00:00", "data": {"market": "0x92dbb7abf136a99dbdbd0bf6b3e168324aba36c885f050a81b9f99f5c86a2c89", "price_changes": [{"asset_id": "742549944322286743622311352663151843513942481342353661165797752687706656334", "price": "0.08", "size": "300", "side": "BUY", "hash": "c193e81e92bd393dc8d0e12df5162e5189ba2a8b", "best_bid": "0.31", "best_ask": "0.33"}, {"asset_id": "85926585546290965710378781547851562606368161566069895279131565989650277464683", "price": "0.92", "size": "300", "side": "SELL", "hash": "8d0087cd671a465ef2eb47018362a03c3a225421", "best_bid": "0.67", "best_ask": "0.69"}], "timestamp": "1769384796692", "event_type": "price_change"}}
{"_local_timestamp": "2026-01-25T23:47:18.869380+00:00", "data": {"market": "0x92dbb7abf136a99dbdbd0bf6b3e168324aba36c885f050a81b9f99f5c86a2c89", "price_changes": [{"asset_id": "742549944322286743622311352663151843513942481342353661165797752687706656334", "price": "0.07", "size": "0", "side": "BUY", "hash": "c5607d2055d04b0b2de9c529f017e3aacb7d0691", "best_bid": "0.31", "best_ask": "0.33"}, {"asset_id": "85926585546290965710378781547851562606368161566069895279131565989650277464683", "price": "0.93", "size": "0", "side": "SELL", "hash": "100215f26cc68567eec4a517d818c18afcbc8d0f", "best_bid": "0.67", "best_ask": "0.69"}], "timestamp": "1769384838768", "event_type": "price_change"}}
{"_local_timestamp": "2026-01-25T23:47:18.870563+00:00", "data": {"market": "0x85096ae131a795ac80db209f9e633e5310fd4fd11b3c2e8b2748614139480c41", "price_changes": [{"asset_id": "87939649752104648558739188569294623185189846388915750654886353417082965270846", "price": "0.13", "size": "0", "side": "BUY", "hash": "de8904a45d4f75773e8870bb8943d073c85a0a01", "best_bid": "0.88", "best_ask": "0.91"}, {"asset_id": "46550817779287714248071035919960687231435496748461488768996323006087698669681", "price": "0.87", "size": "0", "side": "SELL", "hash": "885137cb23f3667e11fd0483b59d9eac99747075", "best_bid": "0.09", "best_ask": "0.12"}], "timestamp": "1769384838768", "event_type": "price_change"}}
{"_local_timestamp": "2026-01-25T23:47:19.387746+00:00", "data": {"market": "0x85096ae131a795ac80db209f9e633e5310fd4fd11b3c2e8b2748614139480c41", "price_changes": [{"asset_id": "87939649752104648558739188569294623185189846388915750654886353417082965270846", "price": "0.08", "size": "300", "side": "BUY", "hash": "bc889fb21654b1677e1196d463bd9dd6fabd3cc1", "best_bid": "0.88", "best_ask": "0.91"}, {"asset_id": "46550817779287714248071035919960687231435496748461488768996323006087698669681", "price": "0.92", "size": "300", "side": "SELL", "hash": "93cbdb6f0dcc48958fbdb2c5bc0a33686c4455a3", "best_bid": "0.09", "best_ask": "0.12"}], "timestamp": "1769384839122", "event_type": "price_change"}}
{"_local_timestamp": "2026-01-25T23:48:38.083500+00:00", "data": {"market": "0x85096ae131a795ac80db209f9e633e5310fd4fd11b3c2e8b2748614139480c41", "price_changes": [{"asset_id": "87939649752104648558739188569294623185189846388915750654886353417082965270846", "price": "0.02", "size": "150", "side": "BUY", "hash": "6cbe419d7020b431f71dfa5c8850709bf550b78f", "best_bid": "0.88", "best_ask": "0.91"}, {"asset_id": "46550817779287714248071035919960687231435496748461488768996323006087698669681", "price": "0.98", "size": "150", "side": "SELL", "hash": "a4e03abc716662fcba23faf0869446c6a83423bd", "best_bid": "0.09", "best_ask": "0.12"}], "timestamp": "1769384917749", "event_type": "price_change"}}
{"_local_timestamp": "2026-01-25T23:48:38.395587+00:00", "data": {"market": "0x85096ae131a795ac80db209f9e633e5310fd4fd11b3c2e8b2748614139480c41", "price_changes": [{"asset_id": "87939649752104648558739188569294623185189846388915750654886353417082965270846", "price": "0.03", "size": "1009.52", "side": "BUY", "hash": "f3715146d99328b0f848c99c6982a6f5bb0a0b69", "best_bid": "0.88", "best_ask": "0.91"}, {"asset_id": "46550817779287714248071035919960687231435496748461488768996323006087698669681", "price": "0.97", "size": "1009.52", "side": "SELL", "hash": "cb890f2ea5125cbaebccd1b2c7c2bde40351835a", "best_bid": "0.09", "best_ask": "0.12"}], "timestamp": "1769384918080", "event_type": "price_change"}}
{"_local_timestamp": "2026-01-25T23:48:38.396249+00:00", "data": {"market": "0x92dbb7abf136a99dbdbd0bf6b3e168324aba36c885f050a81b9f99f5c86a2c89", "price_changes": [{"asset_id": "742549944322286743622311352663151843513942481342353661165797752687706656334", "price": "0.08", "size": "600", "side": "BUY", "hash": "22cf86c0ae7d779e0bf0d0e42bfa3ace0cf972e2", "best_bid": "0.31", "best_ask": "0.33"}, {"asset_id": "85926585546290965710378781547851562606368161566069895279131565989650277464683", "price": "0.92", "size": "600", "side": "SELL", "hash": "1d10c3271b909cb485db15058e4cb097dd078350", "best_bid": "0.67", "best_ask": "0.69"}], "timestamp": "1769384918076", "event_type": "price_change"}}
{"_local_timestamp": "2026-01-25T23:49:18.039274+00:00", "data": {"market": "0xe1d8d93576a561c63ef303c278dac376a95e71e88f956b488c25b08688a81b57", "price_changes": [{"asset_id": "110252161993776196960668611920941766461422541474085598864316166041753604647992", "price": "0.01", "size": "89", "side": "BUY", "hash": "3fc7305d96d10078bcd0b047680c4c76c51c3e48", "best_bid": "0.27", "best_ask": "0.3"}, {"asset_id": "65973752395054621107714955397531733385161540393395321312831009365229146782387", "price": "0.99", "size": "89", "side": "SELL", "hash": "7d02c28f1a5ed91641fdd58f25730e1d84bf14c4", "best_bid": "0.7", "best_ask": "0.73"}], "timestamp": "1769384957970", "event_type": "price_change"}}
{"_local_timestamp": "2026-01-25T23:49:18.040129+00:00", "data": {"market": "0xe1d8d93576a561c63ef303c278dac376a95e71e88f956b488c25b08688a81b57", "price_changes": [{"asset_id": "110252161993776196960668611920941766461422541474085598864316166041753604647992", "price": "0.03", "size": "70874.5", "side": "BUY", "hash": "3fc7305d96d10078bcd0b047680c4c76c51c3e48", "best_bid": "0.27", "best_ask": "0.3"}, {"asset_id": "65973752395054621107714955397531733385161540393395321312831009365229146782387", "price": "0.97", "size": "70874.5", "side": "SELL", "hash": "7d02c28f1a5ed91641fdd58f25730e1d84bf14c4", "best_bid": "0.7", "best_ask": "0.73"}], "timestamp": "1769384957970", "event_type": "price_change"}}
{"_local_timestamp": "2026-01-25T23:49:18.040780+00:00", "data": {"market": "0xe1d8d93576a561c63ef303c278dac376a95e71e88f956b488c25b08688a81b57", "price_changes": [{"asset_id": "110252161993776196960668611920941766461422541474085598864316166041753604647992", "price": "0.07", "size": "0", "side": "BUY", "hash": "3fc7305d96d10078bcd0b047680c4c76c51c3e48", "best_bid": "0.27", "best_ask": "0.3"}, {"asset_id": "65973752395054621107714955397531733385161540393395321312831009365229146782387", "price": "0.93", "size": "0", "side": "SELL", "hash": "7d02c28f1a5ed91641fdd58f25730e1d84bf14c4", "best_bid": "0.7", "best_ask": "0.73"}], "timestamp": "1769384957970", "event_type": "price_change"}}
{"_local_timestamp": "2026-01-25T23:49:21.035927+00:00", "data": {"market": "0xe1d8d93576a561c63ef303c278dac376a95e71e88f956b488c25b08688a81b57", "price_changes": [{"asset_id": "110252161993776196960668611920941766461422541474085598864316166041753604647992", "price": "0.04", "size": "258.1", "side": "BUY", "hash": "0a96b42b8e8b66589955e7162a2413c47431f826", "best_bid": "0.27", "best_ask": "0.3"}, {"asset_id": "65973752395054621107714955397531733385161540393395321312831009365229146782387", "price": "0.96", "size": "258.1", "side": "SELL", "hash": "0f95b8c26d0801837d920d95983c012d91c80784", "best_bid": "0.7", "best_ask": "0.73"}], "timestamp": "1769384960966", "event_type": "price_change"}}
{"_local_timestamp": "2026-01-25T23:49:21.036615+00:00", "data": {"market": "0xe1d8d93576a561c63ef303c278dac376a95e71e88f956b488c25b08688a81b57", "price_changes": [{"asset_id": "110252161993776196960668611920941766461422541474085598864316166041753604647992", "price": "0.02", "size": "156.6", "side": "BUY", "hash": "aa021cb2e7bdc73efe5ff615c1e4e13e83735f52", "best_bid": "0.27", "best_ask": "0.3"}, {"asset_id": "65973752395054621107714955397531733385161540393395321312831009365229146782387", "price": "0.98", "size": "156.6", "side": "SELL", "hash": "9bb6941a4eca05ec4eefcb56d1644d12d853b755", "best_bid": "0.7", "best_ask": "0.73"}], "timestamp": "1769384960968", "event_type": "price_change"}}
{"_local_timestamp": "2026-01-25T23:49:21.037263+00:00", "data": {"market": "0xe1d8d93576a561c63ef303c278dac376a95e71e88f956b488c25b08688a81b57", "price_changes": [{"asset_id": "110252161993776196960668611920941766461422541474085598864316166041753604647992", "price": "0.1", "size": "5.43", "side": "BUY", "hash": "26ee232c7583c9338ad3c0aa499b31a4cb19b652", "best_bid": "0.27", "best_ask": "0.3"}, {"asset_id": "65973752395054621107714955397531733385161540393395321312831009365229146782387", "price": "0.9", "size": "5.43", "side": "SELL", "hash": "5a046f5c664817be81ee3e875eaba10e2a51d0c6", "best_bid": "0.7", "best_ask": "0.73"}], "timestamp": "1769384960970", "event_type": "price_change"}}
