{"_local_timestamp": "2026-01-25T23:41:00.233820+00:00", "data": [{"market": "0x8442c38c99caf98639415ed14080e055d6609c2fc7613f8c23177b99f7488cc0", "asset_id": "43151550904608031994812122462528093658527736846573386213326114950032120527926", "timestamp": "1769384010154", "hash": "cafe07e9adc55842f7a990bf43d3cb4d1e1fb204", "bids": [{"price": "0.01", "size": "555.48"}, {"price": "0.02", "size": "1150"}, {"price": "0.03", "size": "7.04"}, {"price": "0.05", "size": "730"}, {"price": "0.06", "size": "38.95"}, {"price": "0.11", "size": "450"}, {"price": "0.12", "size": "10.63"}, {"price": "0.4", "size": "300"}, {"price": "0.45", "size": "200"}, {"price": "0.49", "size": "125"}, {"price": "0.53", "size": "75"}, {"price": "0.64", "size": "60"}, {"price": "0.65", "size": "10"}, {"price": "0.66", "size": "19.69"}, {"price": "0.68", "size": "16.17"}, {"price": "0.72", "size": "450"}, {"price": "0.73", "size": "49.58"}, {"price": "0.74", "size": "178.9"}, {"price": "0.75", "size": "23.2"}], "asks": [{"price": "0.99", "size": "45"}, {"price": "0.98", "size": "159.96"}, {"price": "0.97", "size": "75"}, {"price": "0.94", "size": "7.78"}, {"price": "0.9", "size": "300"}, {"price": "0.88", "size": "200"}, {"price": "0.87", "size": "125"}, {"price": "0.86", "size": "167.85"}, {"price": "0.85", "size": "73.33"}, {"price": "0.84", "size": "8.88"}, {"price": "0.82", "size": "450"}, {"price": "0.8", "size": "35.12"}, {"price": "0.79", "size": "107"}, {"price": "0.78", "size": "25.4"}], "event_type": "book", "last_trade_price": ""}, {"market": "0x75e7746b83f53e85d5684d5fef6e49fc452f865b6e83a0ebe2b0942f550bdd03", "asset_id": "47884350108418615197770865197095031131543030780360535858897660411470051234625", "timestamp": "1769384135693", "hash": "c5558773858a03fc40835790d46b276e92835747", "bids": [{"price": "0.01", "size": "765"}, {"price": "0.02", "size": "160.39"}, {"price": "0.03", "size": "250"}, {"price": "0.05", "size": "9.17"}, {"price": "0.07", "size": "485.71"}, {"price": "0.08", "size": "268.75"}, {"price": "0.09", "size": "125"}, {"price": "0.1", "size": "75"}, {"price": "0.12", "size": "50"}, {"price": "0.13", "size": "507.88"}, {"price": "0.14", "size": "147.86"}, {"price": "0.15", "size": "47.23"}], "asks": [{"price": "0.99", "size": "1275.48"}, {"price": "0.98", "size": "1150"}, {"price": "0.97", "size": "9.21"}, {"price": "0.95", "size": "30"}, {"price": "0.94", "size": "959"}, {"price": "0.93", "size": "7.58"}, {"price": "0.92", "size": "300"}, {"price": "0.84", "size": "202"}, {"price": "0.83", "size": "6.1"}, {"price": "0.56", "size": "300"}, {"price": "0.5", "size": "200"}, {"price": "0.46", "size": "125"}, {"price": "0.42", "size": "75"}, {"price": "0.4", "size": "21.66"}, {"price": "0.38", "size": "17.74"}, {"price": "0.23", "size": "450"}, {"price": "0.2", "size": "64.99"}, {"price": "0.19", "size": "140.15"}, {"price": "0.18", "size": "40.4"}], "event_type": "book", "last_trade_price": ""}, {"market": "0x8442c38c99caf98639415ed14080e055d6609c2fc7613f8c23177b99f7488cc0", "asset_id": "99086316696015448398478425791443871671895949203487745540409948681487622207594", "timestamp": "1769384010154", "hash": "2e6ab9d84cc6299a45b02464081696c6903c7341", "bids": [{"price": "0.01", "size": "45"}, {"price": "0.02", "size": "159.96"}, {"price": "0.03", "size": "75"}, {"price": "0.06", "size": "7.78"}, {"price": "0.1", "size": "300"}, {"price": "0.12", "size": "200"}, {"price": "0.13", "size": "125"}, {"price": "0.14", "size": "167.85"}, {"price": "0.15", "size": "73.33"}, {"price": "0.16", "size": "8.88"}, {"price": "0.18", "size": "450"}, {"price": "0.2", "size": "35.12"}, {"price": "0.21", "size": "107"}, {"price": "0.22", "size": "25.4"}], "asks": [{"price": "0.99", "size": "555.48"}, {"price": "0.98", "size": "1150"}, {"price": "0.97", "size": "7.04"}, {"price": "0.95", "size": "730"}, {"price": "0.94", "size": "38.95"}, {"price": "0.89", "size": "450"}, {"price": "0.88", "size": "10.63"}, {"price": "0.6", "size": "300"}, {"price": "0.55", "size": "200"}, {"price": "0.51", "size": "125"}, {"price": "0.47", "size": "75"}, {"price": "0.36", "size": "60"}, {"price": "0.35", "size": "10"}, {"price": "0.34", "size": "19.69"}, {"price": "0.32", "size": "16.17"}, {"price": "0.28", "size": "450"}, {"price": "0.27", "size": "49.58"}, {"price": "0.26", "size": "178.9"}, {"price": "0.25", "size": "23.2"}], "event_type": "book", "last_trade_price": ""}, {"market": "0xadb5b2457848b4cde25031495cd1a520363393b81b1110451caca2ee2053f9de", "asset_id": "64380900244237458579669611562854121322372696763621791641804740469125484043289", "timestamp": "1769384424940", "hash": "c6aebdcd2f9fc1a8369985ab2900064713b74e11", "bids": [{"price": "0.01", "size": "1175.74"}, {"price": "0.02", "size": "1150"}, {"price": "0.03", "size": "16.59"}, {"price": "0.06", "size": "912"}, {"price": "0.08", "size": "650"}, {"price": "0.09", "size": "14.94"}, {"price": "0.19", "size": "300"}, {"price": "0.2", "size": "397"}, {"price": "0.21", "size": "285"}, {"price": "0.22", "size": "200"}, {"price": "0.24", "size": "125"}, {"price": "0.25", "size": "75"}, {"price": "0.3", "size": "43.33"}, {"price": "0.31", "size": "35.48"}, {"price": "0.35", "size": "50"}, {"price": "0.36", "size": "850"}, {"price": "0.37", "size": "21.3"}, {"price": "0.38", "size": "36.59"}, {"price": "0.39", "size": "8.36"}], "asks": [{"price": "0.99", "size": "1215"}, {"price": "0.98", "size": "1157.93"}, {"price": "0.95", "size": "30"}, {"price": "0.94", "size": "733"}, {"price": "0.93", "size": "7.25"}, {"price": "0.9", "size": "700"}, {"price": "0.7", "size": "300"}, {"price": "0.66", "size": "200"}, {"price": "0.63", "size": "125"}, {"price": "0.6", "size": "85"}, {"price": "0.49", "size": "25.49"}, {"price": "0.48", "size": "21.15"}, {"price": "0.47", "size": "50"}, {"price": "0.46", "size": "450"}, {"price": "0.45", "size": "285"}, {"price": "0.42", "size": "8.23"}, {"price": "0.41", "size": "41.34"}, {"price": "0.4", "size": "11.18"}], "event_type": "book", "last_trade_price": "0.390"}, {"market": "0xadb5b2457848b4cde25031495cd1a520363393b81b1110451caca2ee2053f9de", "asset_id": "70676785231872628122945643176004673546413040265214614324126365673769398149249", "timestamp": "1769384424940", "hash": "d024b8b33e6cb34a15db50178bc871705b160ae7", "bids": [{"price": "0.01", "size": "1215"}, {"price": "0.02", "size": "1157.93"}, {"price": "0.05", "size": "30"}, {"price": "0.06", "size": "733"}, {"price": "0.07", "size": "7.25"}, {"price": "0.1", "size": "700"}, {"price": "0.3", "size": "300"}, {"price": "0.34", "size": "200"}, {"price": "0.37", "size": "125"}, {"price": "0.4", "size": "85"}, {"price": "0.51", "size": "25.49"}, {"price": "0.52", "size": "21.15"}, {"price": "0.53", "size": "50"}, {"price": "0.54", "size": "450"}, {"price": "0.55", "size": "285"}, {"price": "0.58", "size": "8.23"}, {"price": "0.59", "size": "41.34"}, {"price": "0.6", "size": "11.18"}], "asks": [{"price": "0.99", "size": "1175.74"}, {"price": "0.98", "size": "1150"}, {"price": "0.97", "size": "16.59"}, {"price": "0.94", "size": "912"}, {"price": "0.92", "size": "650"}, {"price": "0.91", "size": "14.94"}, {"price": "0.81", "size": "300"}, {"price": "0.8", "size": "397"}, {"price": "0.79", "size": "285"}, {"price": "0.78", "size": "200"}, {"price": "0.76", "size": "125"}, {"price": "0.75", "size": "75"}, {"price": "0.7", "size": "43.33"}, {"price": "0.69", "size": "35.48"}, {"price": "0.65", "size": "50"}, {"price": "0.64", "size": "850"}, {"price": "0.63", "size": "21.3"}, {"price": "0.62", "size": "36.59"}, {"price": "0.61", "size": "8.36"}], "event_type": "book", "last_trade_price": "0.390"}, {"market": "0x75e7746b83f53e85d5684d5fef6e49fc452f865b6e83a0ebe2b0942f550bdd03", "asset_id": "112818684217285049373394970300912246725692512435350502775015469723427543698392", "timestamp": "1769384135693", "hash": "cecf316bd588aa315bb7b16cf024de3d90cf7447", "bids": [{"price": "0.01", "size": "1275.48"}, {"price": "0.02", "size": "1150"}, {"price": "0.03", "size": "9.21"}, {"price": "0.05", "size": "30"}, {"price": "0.06", "size": "959"}, {"price": "0.07", "size": "7.58"}, {"price": "0.08", "size": "300"}, {"price": "0.16", "size": "202"}, {"price": "0.17", "size": "6.1"}, {"price": "0.44", "size": "300"}, {"price": "0.5", "size": "200"}, {"price": "0.54", "size": "125"}, {"price": "0.58", "size": "75"}, {"price": "0.6", "size": "21.66"}, {"price": "0.62", "size": "17.74"}, {"price": "0.77", "size": "450"}, {"price": "0.8", "size": "64.99"}, {"price": "0.81", "size": "140.15"}, {"price": "0.82", "size": "40.4"}], "asks": [{"price": "0.99", "size": "765"}, {"price": "0.98", "size": "160.39"}, {"price": "0.97", "size": "250"}, {"price": "0.95", "size": "9.17"}, {"price": "0.93", "size": "485.71"}, {"price": "0.92", "size": "268.75"}, {"price": "0.91", "size": "125"}, {"price": "0.9", "size": "75"}, {"price": "0.88", "size": "50"}, {"price": "0.87", "size": "507.88"}, {"price": "0.86", "size": "147.86"}, {"price": "0.85", "size": "47.23"}], "event_type": "book", "last_trade_price": ""}]}
{"_local_timestamp": "2026-01-25T23:43:02.157569+00:00", "data": {"market": "0xadb5b2457848b4cde25031495cd1a520363393b81b1110451caca2ee2053f9de", "price_changes": [{"asset_id": "64380900244237458579669611562854121322372696763621791641804740469125484043289", "price": "0.02", "size": "1000", "side": "BUY", "hash": "6b15dd5e4e0cd9946a1a4be1c8b1f219b414c2aa", "best_bid": "0.39", "best_ask": "0.4"}, {"asset_id": "70676785231872628122945643176004673546413040265214614324126365673769398149249", "price": "0.98", "size": "1000", "side": "SELL", "hash": "0825ca1f20ffb12f79aff231403d69cb429f3e3e", "best_bid": "0.6", "best_ask": "0.61"}], "timestamp": "1769384582001", "event_type": "price_change"}}
{"_local_timestamp": "2026-01-25T23:43:02.209542+00:00", "data": {"market": "0xadb5b2457848b4cde25031495cd1a520363393b81b1110451caca2ee2053f9de", "price_changes": [{"asset_id": "70676785231872628122945643176004673546413040265214614324126365673769398149249", "price": "0.02", "size": "1007.93", "side": "BUY", "hash": "b2bea03ee9d9f5b22767932ef7d12b20d150a70b", "best_bid": "0.6", "best_ask": "0.61"}, {"asset_id": "64380900244237458579669611562854121322372696763621791641804740469125484043289", "price": "0.98", "size": "1007.93", "side": "SELL", "hash": "7b888c038a327bed4e119fab687675767bd86d55", "best_bid": "0.39", "best_ask": "0.4"}], "timestamp": "1769384582006", "event_type": "price_change"}}
{"_local_timestamp": "2026-01-25T23:43:06.299091+00:00", "data": {"market": "0xadb5b2457848b4cde25031495cd1a520363393b81b1110451caca2ee2053f9de", "price_changes": [{"asset_id": "70676785231872628122945643176004673546413040265214614324126365673769398149249", "price": "0.02", "size": "1157.93", "side": "BUY", "hash": "e311adbc0c5155b5d166f29d166c932d2832c5ad", "best_bid": "0.6", "best_ask": "0.61"}, {"asset_id": "64380900244237458579669611562854121322372696763621791641804740469125484043289", "price": "0.98", "size": "1157.93", "side": "SELL", "hash": "e84b2d8862a202aa6e2b1bf419ae6f361bd90fa1", "best_bid": "0.39", "best_ask": "0.4"}], "timestamp": "1769384586153", "event_type": "price_change"}}
{"_local_timestamp": "2026-01-25T23:43:06.307241+00:00", "data": {"market": "0xadb5b2457848b4cde25031495cd1a520363393b81b1110451caca2ee2053f9de", "price_changes": [{"asset_id": "64380900244237458579669611562854121322372696763621791641804740469125484043289", "price": "0.02", "size": "1150", "side": "BUY", "hash": "0eb592480bd86699563200fdbd39e2db4f628bbe", "best_bid": "0.39", "best_ask": "0.4"}, {"asset_id": "70676785231872628122945643176004673546413040265214614324126365673769398149249", "price": "0.98", "size": "1150", "side": "SELL", "hash": "e1e23b1082263a7f4d40f809deaaefbc0f825fe0", "best_bid": "0.6", "best_ask": "0.61"}], "timestamp": "1769384586154", "event_type": "price_change"}}
{"_local_timestamp": "2026-01-25T23:44:05.649856+00:00", "data": {"market": "0xadb5b2457848b4cde25031495cd1a520363393b81b1110451caca2ee2053f9de", "price_changes": [{"asset_id": "70676785231872628122945643176004673546413040265214614324126365673769398149249", "price": "0.53", "size": "0", "side": "BUY", "hash": "5daceda4e8d22a94a44e1e0c4e3ba3003f411a24", "best_bid": "0.6", "best_ask": "0.61"}, {"asset_id": "64380900244237458579669611562854121322372696763621791641804740469125484043289", "price": "0.47", "size": "0", "side": "SELL", "hash": "bfbf3c09541fe7dcb7df23f9932195fe1bf3ab7f", "best_bid": "0.39", "best_ask": "0.4"}], "timestamp": "1769384645374", "event_type": "price_change"}}
{"_local_timestamp": "2026-01-25T23:44:05.870088+00:00", "data": {"market": "0x75e7746b83f53e85d5684d5fef6e49fc452f865b6e83a0ebe2b0942f550bdd03", "price_changes": [{"asset_id": "47884350108418615197770865197095031131543030780360535858897660411470051234625", "price": "0.12", "size": "0", "side": "BUY", "hash": "d10498e236ce47ff3ccda0d3b262f7e76b7d81ce", "best_bid": "0.15", "best_ask": "0.18"}, {"asset_id": "112818684217285049373394970300912246725692512435350502775015469723427543698392", "price": "0.88", "size": "0", "side": "SELL", "hash": "098ded456a030a9f18f09af1b55b62adb83bc7dd", "best_bid": "0.82", "best_ask": "0.85"}], "timestamp": "1769384645572", "event_type": "price_change"}}
{"_local_timestamp": "2026-01-25T23:44:08.067252+00:00", "data": {"market": "0xadb5b2457848b4cde25031495cd1a520363393b81b1110451caca2ee2053f9de", "price_changes": [{"asset_id": "64380900244237458579669611562854121322372696763621791641804740469125484043289", "price": "0.35", "size": "0", "side": "BUY", "hash": "3e1a7582f49c872ebf88486b01c0280703c5e580", "best_bid": "0.39", "best_ask": "0.4"}, {"asset_id": "70676785231872628122945643176004673546413040265214614324126365673769398149249", "price": "0.65", "size": "0", "side": "SELL", "hash": "2a5b7b02e2a24c8af14184f75eed7bec384bceb5", "best_bid": "0.6", "best_ask": "0.61"}], "timestamp": "1769384647778", "event_type": "price_change"}}
{"_local_timestamp": "2026-01-25T23:44:30.137706+00:00", "data": {"market": "0x75e7746b83f53e85d5684d5fef6e49fc452f865b6e83a0ebe2b0942f550bdd03", "price_changes": [{"asset_id": "47884350108418615197770865197095031131543030780360535858897660411470051234625", "price": "0.13", "size": "460", "side": "BUY", "hash": "7fdcfa9919427bba42ce574e7ef1534134165a7b", "best_bid": "0.15", "best_ask": "0.18"}, {"asset_id": "112818684217285049373394970300912246725692512435350502775015469723427543698392", "price": "0.87", "size": "460", "side": "SELL", "hash": "8ab1143b7a01f850fd3e1b191f359cdc5dd60185", "best_bid": "0.82", "best_ask": "0.85"}], "timestamp": "1769384670068", "event_type": "price_change"}}
{"_local_timestamp": "2026-01-25T23:44:30.146128+00:00", "data": {"market": "0x75e7746b83f53e85d5684d5fef6e49fc452f865b6e83a0ebe2b0942f550bdd03", "price_changes": [{"asset_id": "47884350108418615197770865197095031131543030780360535858897660411470051234625", "price": "0.12", "size": "48.39", "side": "BUY", "hash": "343bd0e8b1c07c4c6ff03753ee42d00d9729eba2", "best_bid": "0.15", "best_ask": "0.18"}, {"asset_id": "112818684217285049373394970300912246725692512435350502775015469723427543698392", "price": "0.88", "size": "48.39", "side": "SELL", "hash": "9a6d3d2715f8daff233a4fe746d8906fbb858e92", "best_bid": "0.82", "best_ask": "0.85"}], "timestamp": "1769384670071", "event_type": "price_change"}}
{"_local_timestamp": "2026-01-25T23:44:34.308346+00:00", "data": {"market": "0x75e7746b83f53e85d5684d5fef6e49fc452f865b6e83a0ebe2b0942f550bdd03", "price_changes": [{"asset_id": "47884350108418615197770865197095031131543030780360535858897660411470051234625", "price": "0.12", "size": "0", "side": "BUY", "hash": "d61783cb75ac44227d2c8ba3ec244051a65027fc", "best_bid": "0.15", "best_ask": "0.18"}, {"asset_id": "112818684217285049373394970300912246725692512435350502775015469723427543698392", "price": "0.88", "size": "0", "side": "SELL", "hash": "1607623a3996be4095a59573a062bcd552a4d1b0", "best_bid": "0.82", "best_ask": "0.85"}], "timestamp": "1769384674235", "event_type": "price_change"}}
{"_local_timestamp": "2026-01-25T23:44:34.308728+00:00", "data": {"market": "0x75e7746b83f53e85d5684d5fef6e49fc452f865b6e83a0ebe2b0942f550bdd03", "price_changes": [{"asset_id": "47884350108418615197770865197095031131543030780360535858897660411470051234625", "price": "0.13", "size": "513.84", "side": "BUY", "hash": "d02084746973aa1e76a0e64e3e068575e904e7da", "best_bid": "0.15", "best_ask": "0.18"}, {"asset_id": "112818684217285049373394970300912246725692512435350502775015469723427543698392", "price": "0.87", "size": "513.84", "side": "SELL", "hash": "1937eb27d1ec39e2d87e8dc5009c36cf0fba766f", "best_bid": "0.82", "best_ask": "0.85"}], "timestamp": "1769384674237", "event_type": "price_change"}}
{"_local_timestamp": "2026-01-25T23:45:00.764104+00:00", "data": {"market": "0x75e7746b83f53e85d5684d5fef6e49fc452f865b6e83a0ebe2b0942f550bdd03", "price_changes": [{"asset_id": "47884350108418615197770865197095031131543030780360535858897660411470051234625", "price": "0.12", "size": "84.28", "side": "BUY", "hash": "2bd52f223e0d5a79493017583fd78076f11f99cc", "best_bid": "0.15", "best_ask": "0.18"}, {"asset_id": "112818684217285049373394970300912246725692512435350502775015469723427543698392", "price": "0.88", "size": "84.28", "side": "SELL", "hash": "e706d1d6f35ad99f61c70c9cd9ca02c0fca2ad6a", "best_bid": "0.82", "best_ask": "0.85"}], "timestamp": "1769384700688", "event_type": "price_change"}}
{"_local_timestamp": "2026-01-25T23:45:00.764679+00:00", "data": {"market": "0x75e7746b83f53e85d5684d5fef6e49fc452f865b6e83a0ebe2b0942f550bdd03", "price_changes": [{"asset_id": "47884350108418615197770865197095031131543030780360535858897660411470051234625", "price": "0.14", "size": "114.07", "side": "BUY", "hash": "f01740d6ea570428b1bc8bdcb6fc5fd90b10c809", "best_bid": "0.15", "best_ask": "0.18"}, {"asset_id": "112818684217285049373394970300912246725692512435350502775015469723427543698392", "price": "0.86", "size": "114.07", "side": "SELL", "hash": "8bd6bfeaef1ee777111f549e89077c28b6b6ef94", "best_bid": "0.82", "best_ask": "0.85"}], "timestamp": "1769384700694", "event_type": "price_change"}}
{"_local_timestamp": "2026-01-25T23:45:00.765044+00:00", "data": {"market": "0x75e7746b83f53e85d5684d5fef6e49fc452f865b6e83a0ebe2b0942f550bdd03", "price_changes": [{"asset_id": "47884350108418615197770865197095031131543030780360535858897660411470051234625", "price": "0.13", "size": "460", "side": "BUY", "hash": "f01740d6ea570428b1bc8bdcb6fc5fd90b10c809", "best_bid": "0.15", "best_ask": "0.18"}, {"asset_id": "112818684217285049373394970300912246725692512435350502775015469723427543698392", "price": "0.87", "size": "460", "side": "SELL", "hash": "8bd6bfeaef1ee777111f549e89077c28b6b6ef94", "best_bid": "0.82", "best_ask": "0.85"}], "timestamp": "1769384700694", "event_type": "price_change"}}
{"_local_timestamp": "2026-01-25T23:45:05.208036+00:00", "data": {"market": "0x75e7746b83f53e85d5684d5fef6e49fc452f865b6e83a0ebe2b0942f550bdd03", "price_changes": [{"asset_id": "47884350108418615197770865197095031131543030780360535858897660411470051234625", "price": "0.13", "size": "525.81", "side": "BUY", "hash": "b2ba904d012cf31a410ff2a11aad256bc26d894e", "best_bid": "0.15", "best_ask": "0.18"}, {"asset_id": "112818684217285049373394970300912246725692512435350502775015469723427543698392", "price": "0.87", "size": "525.81", "side": "SELL", "hash": "2839d146b556b694a2d0d4be9476056db6f2781d", "best_bid": "0.82", "best_ask": "0.85"}], "timestamp": "1769384705139", "event_type": "price_change"}}
{"_local_timestamp": "2026-01-25T23:45:05.709766+00:00", "data": {"market": "0x8442c38c99caf98639415ed14080e055d6609c2fc7613f8c23177b99f7488cc0", "price_changes": [{"asset_id": "43151550904608031994812122462528093658527736846573386213326114950032120527926", "price": "0.76", "size": "13.84", "side": "BUY", "hash": "205b7fba54a6fd060aa00cd27d7481502f3a8a0d", "best_bid": "0.76", "best_ask": "0.78"}, {"asset_id": "99086316696015448398478425791443871671895949203487745540409948681487622207594", "price": "0.24", "size": "13.84", "side": "SELL", "hash": "e0dd61cd056333b87d4172808b9ab34a51124e90", "best_bid": "0.22", "best_ask": "0.24"}], "timestamp": "1769384705628", "event_type": "price_change"}}
{"_local_timestamp": "2026-01-25T23:45:05.710209+00:00", "data": {"market": "0x8442c38c99caf98639415ed14080e055d6609c2fc7613f8c23177b99f7488cc0", "price_changes": [{"asset_id": "43151550904608031994812122462528093658527736846573386213326114950032120527926", "price": "0.73", "size": "0", "side": "BUY", "hash": "39377211d2eb941d9d5c821c92a1da39af78e406", "best_bid": "0.76", "best_ask": "0.78"}, {"asset_id": "99086316696015448398478425791443871671895949203487745540409948681487622207594", "price": "0.27", "size": "0", "side": "SELL", "hash": "b0b153aec7e0da2821ef99c41a05c7a8f57bf9d1", "best_bid": "0.22", "best_ask": "0.24"}], "timestamp": "1769384705629", "event_type": "price_change"}}
{"_local_timestamp": "2026-01-25T23:45:56.853094+00:00", "data": {"market": "0xadb5b2457848b4cde25031495cd1a520363393b81b1110451caca2ee2053f9de", "price_changes": [{"asset_id": "70676785231872628122945643176004673546413040265214614324126365673769398149249", "price": "0.1", "size": "400", "side": "BUY", "hash": "6d2e9b5be5b5b78b4d3a0db60c26e4da62234c33", "best_bid": "0.6", "best_ask": "0.61"}, {"asset_id": "64380900244237458579669611562854121322372696763621791641804740469125484043289", "price": "0.9", "size": "400", "side": "SELL", "hash": "5f6dec9694ca8b3a758ece8a9270eafafc69ff03", "best_bid": "0.39", "best_ask": "0.4"}], "timestamp": "1769384756101", "event_type": "price_change"}}
{"_local_timestamp": "2026-01-25T23:46:13.638134+00:00", "data": {"market": "0xadb5b2457848b4cde25031495cd1a520363393b81b1110451caca2ee2053f9de", "price_changes": [{"asset_id": "64380900244237458579669611562854121322372696763621791641804740469125484043289", "price": "0.35", "size": "50", "side": "BUY", "hash": "d8997671887f680df391cb4d19843edde2bf4369", "best_bid": "0.39", "best_ask": "0.4"}, {"asset_id": "70676785231872628122945643176004673546413040265214614324126365673769398149249", "price": "0.65", "size": "50", "side": "SELL", "hash": "c0ea85f2831f27779af9754d093d2f2bd738e5dd", "best_bid": "0.6", "best_ask": "0.61"}], "timestamp": "1769384773568", "event_type": "price_change"}}
{"_local_timestamp": "2026-01-25T23:46:38.349019+00:00", "data": {"market": "0xadb5b2457848b4cde25031495cd1a520363393b81b1110451caca2ee2053f9de", "price_changes": [{"asset_id": "70676785231872628122945643176004673546413040265214614324126365673769398149249", "price": "0.11", "size": "300", "side": "BUY", "hash": "6bee3abbe121dc772be78660f79026d1d414461f", "best_bid": "0.6", "best_ask": "0.61"}, {"asset_id": "64380900244237458579669611562854121322372696763621791641804740469125484043289", "price": "0.89", "size": "300", "side": "SELL", "hash": "eb754806cdd69082537bfb8c9bb07c03a7a344a2", "best_bid": "0.39", "best_ask": "0.4"}], "timestamp": "1769384798256", "event_type": "price_change"}}
{"_local_timestamp": "2026-01-25T23:46:49.209618+00:00", "data": {"market": "0xadb5b2457848b4cde25031495cd1a520363393b81b1110451caca2ee2053f9de", "price_changes": [{"asset_id": "70676785231872628122945643176004673546413040265214614324126365673769398149249", "price": "0.1", "size": "300", "side": "BUY", "hash": "ab618a19607dcfc83a7353c29488a247fa52f492", "best_bid": "0.6", "best_ask": "0.61"}, {"asset_id": "64380900244237458579669611562854121322372696763621791641804740469125484043289", "price": "0.9", "size": "300", "side": "SELL", "hash": "bb45030ff1c6d3e0c46d0cb54908afbef6c672d9", "best_bid": "0.39", "best_ask": "0.4"}], "timestamp": "1769384809139", "event_type": "price_change"}}
{"_local_timestamp": "2026-01-25T23:46:49.441973+00:00", "data": {"market": "0xadb5b2457848b4cde25031495cd1a520363393b81b1110451caca2ee2053f9de", "price_changes": [{"asset_id": "70676785231872628122945643176004673546413040265214614324126365673769398149249", "price": "0.11", "size": "400", "side": "BUY", "hash": "368e1386b9136042a8263cf7c260a59f427b7cc0", "best_bid": "0.6", "best_ask": "0.61"}, {"asset_id": "64380900244237458579669611562854121322372696763621791641804740469125484043289", "price": "0.89", "size": "400", "side": "SELL", "hash": "c0edb5dd2a733edd7ca5ac2279936b44981c6d70", "best_bid": "0.39", "best_ask": "0.4"}], "timestamp": "1769384809371", "event_type": "price_change"}}
{"_local_timestamp": "2026-01-25T23:47:43.344975+00:00", "data": {"market": "0x75e7746b83f53e85d5684d5fef6e49fc452f865b6e83a0ebe2b0942f550bdd03", "price_changes": [{"asset_id": "47884350108418615197770865197095031131543030780360535858897660411470051234625", "price": "0.08", "size": "68.75", "side": "BUY", "hash": "7c576af9ef14428d43767b00d3bd74eab5ce5526", "best_bid": "0.15", "best_ask": "0.18"}, {"asset_id": "112818684217285049373394970300912246725692512435350502775015469723427543698392", "price": "0.92", "size": "68.75", "side": "SELL", "hash": "fb026ea2cba5e499bd1b6b4696e46fd6a8569aaf", "best_bid": "0.82", "best_ask": "0.85"}], "timestamp": "1769384863253", "event_type": "price_change"}}
{"_local_timestamp": "2026-01-25T23:47:43.345712+00:00", "data": {"market": "0x75e7746b83f53e85d5684d5fef6e49fc452f865b6e83a0ebe2b0942f550bdd03", "price_changes": [{"asset_id": "47884350108418615197770865197095031131543030780360535858897660411470051234625", "price": "0.07", "size": "185.71", "side": "BUY", "hash": "7c576af9ef14428d43767b00d3bd74eab5ce5526", "best_bid": "0.15", "best_ask": "0.18"}, {"asset_id": "112818684217285049373394970300912246725692512435350502775015469723427543698392", "price": "0.93", "size": "185.71", "side": "SELL", "hash": "fb026ea2cba5e499bd1b6b4696e46fd6a8569aaf", "best_bid": "0.82", "best_ask": "0.85"}], "timestamp": "1769384863253", "event_type": "price_change"}}
{"_local_timestamp": "2026-01-25T23:47:43.346101+00:00", "data": {"market": "0x75e7746b83f53e85d5684d5fef6e49fc452f865b6e83a0ebe2b0942f550bdd03", "price_changes": [{"asset_id": "47884350108418615197770865197095031131543030780360535858897660411470051234625", "price": "0.1", "size": "0", "side": "BUY", "hash": "7c576af9ef14428d43767b00d3bd74eab5ce5526", "best_bid": "0.15", "best_ask": "0.18"}, {"asset_id": "112818684217285049373394970300912246725692512435350502775015469723427543698392", "price": "0.9", "size": "0", "side": "SELL", "hash": "fb026ea2cba5e499bd1b6b4696e46fd6a8569aaf", "best_bid": "0.82", "best_ask": "0.85"}], "timestamp": "1769384863253", "event_type": "price_change"}}
{"_local_timestamp": "2026-01-25T23:47:43.346438+00:00", "data": {"market": "0x75e7746b83f53e85d5684d5fef6e49fc452f865b6e83a0ebe2b0942f550bdd03", "price_changes": [{"asset_id": "47884350108418615197770865197095031131543030780360535858897660411470051234625", "price": "0.09", "size": "0", "side": "BUY", "hash": "7c576af9ef14428d43767b00d3bd74eab5ce5526", "best_bid": "0.15", "best_ask": "0.18"}, {"asset_id": "112818684217285049373394970300912246725692512435350502775015469723427543698392", "price": "0.91", "size": "0", "side": "SELL", "hash": "fb026ea2cba5e499bd1b6b4696e46fd6a8569aaf", "best_bid": "0.82", "best_ask": "0.85"}], "timestamp": "1769384863253", "event_type": "price_change"}}
{"_local_timestamp": "2026-01-25T23:47:43.346771+00:00", "data": {"market": "0x75e7746b83f53e85d5684d5fef6e49fc452f865b6e83a0ebe2b0942f550bdd03", "price_changes": [{"asset_id": "112818684217285049373394970300912246725692512435350502775015469723427543698392", "price": "0.44", "size": "0", "side": "BUY", "hash": "60ab49741225979fc13eb224c46a8d605bccb498", "best_bid": "0.82", "best_ask": "0.85"}, {"asset_id": "47884350108418615197770865197095031131543030780360535858897660411470051234625", "price": "0.56", "size": "0", "side": "SELL", "hash": "bb243ddabdca183ef0edfc1a803b71ae211d9679", "best_bid": "0.15", "best_ask": "0.18"}], "timestamp": "1769384863253", "event_type": "price_change"}}
{"_local_timestamp": "2026-01-25T23:47:43.347089+00:00", "data": {"market": "0x75e7746b83f53e85d5684d5fef6e49fc452f865b6e83a0ebe2b0942f550bdd03", "price_changes": [{"asset_id": "112818684217285049373394970300912246725692512435350502775015469723427543698392", "price": "0.58", "size": "0", "side": "BUY", "hash": "60ab49741225979fc13eb224c46a8d605bccb498", "best_bid": "0.82", "best_ask": "0.85"}, {"asset_id": "47884350108418615197770865197095031131543030780360535858897660411470051234625", "price": "0.42", "size": "0", "side": "SELL", "hash": "bb243ddabdca183ef0edfc1a803b71ae211d9679", "best_bid": "0.15", "best_ask": "0.18"}], "timestamp": "1769384863253", "event_type": "price_change"}}
{"_local_timestamp": "2026-01-25T23:47:43.347416+00:00", "data": {"market": "0x75e7746b83f53e85d5684d5fef6e49fc452f865b6e83a0ebe2b0942f550bdd03", "price_changes": [{"asset_id": "112818684217285049373394970300912246725692512435350502775015469723427543698392", "price": "0.5", "size": "0", "side": "BUY", "hash": "60ab49741225979fc13eb224c46a8d605bccb498", "best_bid": "0.82", "best_ask": "0.85"}, {"asset_id": "47884350108418615197770865197095031131543030780360535858897660411470051234625", "price": "0.5", "size": "0", "side": "SELL", "hash": "bb243ddabdca183ef0edfc1a803b71ae211d9679", "best_bid": "0.15", "best_ask": "0.18"}], "timestamp": "1769384863253", "event_type": "price_change"}}
{"_local_timestamp": "2026-01-25T23:47:43.347767+00:00", "data": {"market": "0x75e7746b83f53e85d5684d5fef6e49fc452f865b6e83a0ebe2b0942f550bdd03", "price_changes": [{"asset_id": "112818684217285049373394970300912246725692512435350502775015469723427543698392", "price": "0.54", "size": "0", "side": "BUY", "hash": "60ab49741225979fc13eb224c46a8d605bccb498", "best_bid": "0.82", "best_ask": "0.85"}, {"asset_id": "47884350108418615197770865197095031131543030780360535858897660411470051234625", "price": "0.46", "size": "0", "side": "SELL", "hash": "bb243ddabdca183ef0edfc1a803b71ae211d9679", "best_bid": "0.15", "best_ask": "0.18"}], "timestamp": "1769384863253", "event_type": "price_change"}}
{"_local_timestamp": "2026-01-25T23:47:45.646081+00:00", "data": {"market": "0x75e7746b83f53e85d5684d5fef6e49fc452f865b6e83a0ebe2b0942f550bdd03", "price_changes": [{"asset_id": "47884350108418615197770865197095031131543030780360535858897660411470051234625", "price": "0.08", "size": "268.75", "side": "BUY", "hash": "3f7ac1a7a042d7627ada68bbdb9e1a5a2595dffe", "best_bid": "0.15", "best_ask": "0.18"}, {"asset_id": "112818684217285049373394970300912246725692512435350502775015469723427543698392", "price": "0.92", "size": "268.75", "side": "SELL", "hash": "ac453c683c2a4b04398d1b9404a021f4b90d645c", "best_bid": "0.82", "best_ask": "0.85"}], "timestamp": "1769384865554", "event_type": "price_change"}}
{"_local_timestamp": "2026-01-25T23:47:45.647048+00:00", "data": {"market": "0x75e7746b83f53e85d5684d5fef6e49fc452f865b6e83a0ebe2b0942f550bdd03", "price_changes": [{"asset_id": "47884350108418615197770865197095031131543030780360535858897660411470051234625", "price": "0.09", "size": "125", "side": "BUY", "hash": "2c8161572d9dadc9ef53746411d46bb85fa285fa", "best_bid": "0.15", "best_ask": "0.18"}, {"asset_id": "112818684217285049373394970300912246725692512435350502775015469723427543698392", "price": "0.91", "size": "125", "side": "SELL", "hash": "1e6668203d250fd156564626920b99140fbaf142", "best_bid": "0.82", "best_ask": "0.85"}], "timestamp": "1769384865555", "event_type": "price_change"}}
{"_local_timestamp": "2026-01-25T23:47:45.647417+00:00", "data": {"market": "0x75e7746b83f53e85d5684d5fef6e49fc452f865b6e83a0ebe2b0942f550bdd03", "price_changes": [{"asset_id": "112818684217285049373394970300912246725692512435350502775015469723427543698392", "price": "0.58", "size": "75", "side": "BUY", "hash": "ef64c1f4de897ccb30c751c64d35fa9cfe237d19", "best_bid": "0.82", "best_ask": "0.85"}, {"asset_id": "47884350108418615197770865197095031131543030780360535858897660411470051234625", "price": "0.42", "size": "75", "side": "SELL", "hash": "1e1b946cd0d97598f9d58b3f38b494c35e8cf26b", "best_bid": "0.15", "best_ask": "0.18"}], "timestamp": "1769384865557", "event_type": "price_change"}}
{"_local_timestamp": "2026-01-25T23:47:45.647768+00:00", "data": {"market": "0x75e7746b83f53e85d5684d5fef6e49fc452f865b6e83a0ebe2b0942f550bdd03", "price_changes": [{"asset_id": "112818684217285049373394970300912246725692512435350502775015469723427543698392", "price": "0.54", "size": "125", "side": "BUY", "hash": "e09258ee7965308632329d8b93ef22eb8ed7e1ba", "best_bid": "0.82", "best_ask": "0.85"}, {"asset_id": "47884350108418615197770865197095031131543030780360535858897660411470051234625", "price": "0.46", "size": "125", "side": "SELL", "hash": "c87bf0fd0f0743768e9e9103cd398611c217c1eb", "best_bid": "0.15", "best_ask": "0.18"}], "timestamp": "1769384865558", "event_type": "price_change"}}
{"_local_timestamp": "2026-01-25T23:47:45.648155+00:00", "data": {"market": "0x75e7746b83f53e85d5684d5fef6e49fc452f865b6e83a0ebe2b0942f550bdd03", "price_changes": [{"asset_id": "47884350108418615197770865197095031131543030780360535858897660411470051234625", "price": "0.07", "size": "485.71", "side": "BUY", "hash": "60606f48c5a80ad7cf7082c6aab3239ff4507496", "best_bid": "0.15", "best_ask": "0.18"}, {"asset_id": "112818684217285049373394970300912246725692512435350502775015469723427543698392", "price": "0.93", "size": "485.71", "side": "SELL", "hash": "bee57ed6f2e80c1a164a9e9a59d113d946d8f7ae", "best_bid": "0.82", "best_ask": "0.85"}], "timestamp": "1769384865560", "event_type": "price_change"}}
{"_local_timestamp": "2026-01-25T23:47:45.659194+00:00", "data": {"market": "0x75e7746b83f53e85d5684d5fef6e49fc452f865b6e83a0ebe2b0942f550bdd03", "price_changes": [{"asset_id": "112818684217285049373394970300912246725692512435350502775015469723427543698392", "price": "0.44", "size": "300", "side": "BUY", "hash": "ad6712c1820a622e170a8c96bfa827e00d995c49", "best_bid": "0.82", "best_ask": "0.85"}, {"asset_id": "47884350108418615197770865197095031131543030780360535858897660411470051234625", "price": "0.56", "size": "300", "side": "SELL", "hash": "e98876215a77f605f9cd8aaf8f9b06c97c9df2fe", "best_bid": "0.15", "best_ask": "0.18"}], "timestamp": "1769384865561", "event_type": "price_change"}}
{"_local_timestamp": "2026-01-25T23:47:45.659615+00:00", "data": {"market": "0x75e7746b83f53e85d5684d5fef6e49fc452f865b6e83a0ebe2b0942f550bdd03", "price_changes": [{"asset_id": "47884350108418615197770865197095031131543030780360535858897660411470051234625", "price": "0.1", "size": "75", "side": "BUY", "hash": "1c41273a8ec4e730da67890266fbebfd9ae13c79", "best_bid": "0.15", "best_ask": "0.18"}, {"asset_id": "112818684217285049373394970300912246725692512435350502775015469723427543698392", "price": "0.9", "size": "75", "side": "SELL", "hash": "ca8b6d5205d47264879d976878a308a108f84dd6", "best_bid": "0.82", "best_ask": "0.85"}], "timestamp": "1769384865563", "event_type": "price_change"}}
{"_local_timestamp": "2026-01-25T23:47:45.659983+00:00", "data": {"market": "0x75e7746b83f53e85d5684d5fef6e49fc452f865b6e83a0ebe2b0942f550bdd03", "price_changes": [{"asset_id": "112818684217285049373394970300912246725692512435350502775015469723427543698392", "price": "0.5", "size": "200", "side": "BUY", "hash": "24e9eda45dd1e8b13b8a41b9008b827dd5cb2e2a", "best_bid": "0.82", "best_ask": "0.85"}, {"asset_id": "47884350108418615197770865197095031131543030780360535858897660411470051234625", "price": "0.5", "size": "200", "side": "SELL", "hash": "eb4834a6499e857e05d606b3109b49ee7c1aa949", "best_bid": "0.15", "best_ask": "0.18"}], "timestamp": "1769384865564", "event_type": "price_change"}}
{"_local_timestamp": "2026-01-25T23:47:45.821540+00:00", "data": {"market": "0x8442c38c99caf98639415ed14080e055d6609c2fc7613f8c23177b99f7488cc0", "price_changes": [{"asset_id": "99086316696015448398478425791443871671895949203487745540409948681487622207594", "price": "0.12", "size": "0", "side": "BUY", "hash": "679849b477963c5ee75e77962232f9d4e895573d", "best_bid": "0.22", "best_ask": "0.24"}, {"asset_id": "43151550904608031994812122462528093658527736846573386213326114950032120527926", "price": "0.88", "size": "0", "side": "SELL", "hash": "b8fbc0fadae755eec730332b65d0bab564d1b4fa", "best_bid": "0.76", "best_ask": "0.78"}], "timestamp": "1769384865748", "event_type": "price_change"}}
{"_local_timestamp": "2026-01-25T23:47:45.822006+00:00", "data": {"market": "0x8442c38c99caf98639415ed14080e055d6609c2fc7613f8c23177b99f7488cc0", "price_changes": [{"asset_id": "99086316696015448398478425791443871671895949203487745540409948681487622207594", "price": "0.14", "size": "92.85", "side": "BUY", "hash": "679849b477963c5ee75e77962232f9d4e895573d", "best_bid": "0.22", "best_ask": "0.24"}, {"asset_id": "43151550904608031994812122462528093658527736846573386213326114950032120527926", "price": "0.86", "size": "92.85", "side": "SELL", "hash": "b8fbc0fadae755eec730332b65d0bab564d1b4fa", "best_bid": "0.76", "best_ask": "0.78"}], "timestamp": "1769384865748", "event_type": "price_change"}}
{"_local_timestamp": "2026-01-25T23:47:45.822390+00:00", "data": {"market": "0x8442c38c99caf98639415ed14080e055d6609c2fc7613f8c23177b99f7488cc0", "price_changes": [{"asset_id": "99086316696015448398478425791443871671895949203487745540409948681487622207594", "price": "0.13", "size": "0", "side": "BUY", "hash": "679849b477963c5ee75e77962232f9d4e895573d", "best_bid": "0.22", "best_ask": "0.24"}, {"asset_id": "43151550904608031994812122462528093658527736846573386213326114950032120527926", "price": "0.87", "size": "0", "side": "SELL", "hash": "b8fbc0fadae755eec730332b65d0bab564d1b4fa", "best_bid": "0.76", "best_ask": "0.78"}], "timestamp": "1769384865748", "event_type": "price_change"}}
{"_local_timestamp": "2026-01-25T23:47:45.822777+00:00", "data": {"market": "0x8442c38c99caf98639415ed14080e055d6609c2fc7613f8c23177b99f7488cc0", "price_changes": [{"asset_id": "99086316696015448398478425791443871671895949203487745540409948681487622207594", "price": "0.1", "size": "0", "side": "BUY", "hash": "679849b477963c5ee75e77962232f9d4e895573d", "best_bid": "0.22", "best_ask": "0.24"}, {"asset_id": "43151550904608031994812122462528093658527736846573386213326114950032120527926", "price": "0.9", "size": "0", "side": "SELL", "hash": "b8fbc0fadae755eec730332b65d0bab564d1b4fa", "best_bid": "0.76", "best_ask": "0.78"}], "timestamp": "1769384865748", "event_type": "price_change"}}
{"_local_timestamp": "2026-01-25T23:47:45.823135+00:00", "data": {"market": "0x8442c38c99caf98639415ed14080e055d6609c2fc7613f8c23177b99f7488cc0", "price_changes": [{"asset_id": "43151550904608031994812122462528093658527736846573386213326114950032120527926", "price": "0.4", "size": "0", "side": "BUY", "hash": "0a13d6f89aef0a0e27c70094be80a6da9ebf9d4e", "best_bid": "0.76", "best_ask": "0.78"}, {"asset_id": "99086316696015448398478425791443871671895949203487745540409948681487622207594", "price": "0.6", "size": "0", "side": "SELL", "hash": "3e7ee5d54afa0525bad2ed51e341a41b43a0fd50", "best_bid": "0.22", "best_ask": "0.24"}], "timestamp": "1769384865748", "event_type": "price_change"}}
{"_local_timestamp": "2026-01-25T23:47:45.823512+00:00", "data": {"market": "0x8442c38c99caf98639415ed14080e055d6609c2fc7613f8c23177b99f7488cc0", "price_changes": [{"asset_id": "43151550904608031994812122462528093658527736846573386213326114950032120527926", "price": "0.45", "size": "0", "side": "BUY", "hash": "0a13d6f89aef0a0e27c70094be80a6da9ebf9d4e", "best_bid": "0.76", "best_ask": "0.78"}, {"asset_id": "99086316696015448398478425791443871671895949203487745540409948681487622207594", "price": "0.55", "size": "0", "side": "SELL", "hash": "3e7ee5d54afa0525bad2ed51e341a41b43a0fd50", "best_bid": "0.22", "best_ask": "0.24"}], "timestamp": "1769384865748", "event_type": "price_change"}}
{"_local_timestamp": "2026-01-25T23:47:45.825187+00:00", "data": {"market": "0x8442c38c99caf98639415ed14080e055d6609c2fc7613f8c23177b99f7488cc0", "price_changes": [{"asset_id": "43151550904608031994812122462528093658527736846573386213326114950032120527926", "price": "0.53", "size": "0", "side": "BUY", "hash": "0a13d6f89aef0a0e27c70094be80a6da9ebf9d4e", "best_bid": "0.76", "best_ask": "0.78"}, {"asset_id": "99086316696015448398478425791443871671895949203487745540409948681487622207594", "price": "0.47", "size": "0", "side": "SELL", "hash": "3e7ee5d54afa0525bad2ed51e341a41b43a0fd50", "best_bid": "0.22", "best_ask": "0.24"}], "timestamp": "1769384865748", "event_type": "price_change"}}
{"_local_timestamp": "2026-01-25T23:47:45.825622+00:00", "data": {"market": "0x8442c38c99caf98639415ed14080e055d6609c2fc7613f8c23177b99f7488cc0", "price_changes": [{"asset_id": "43151550904608031994812122462528093658527736846573386213326114950032120527926", "price": "0.49", "size": "0", "side": "BUY", "hash": "0a13d6f89aef0a0e27c70094be80a6da9ebf9d4e", "best_bid": "0.76", "best_ask": "0.78"}, {"asset_id": "99086316696015448398478425791443871671895949203487745540409948681487622207594", "price": "0.51", "size": "0", "side": "SELL", "hash": "3e7ee5d54afa0525bad2ed51e341a41b43a0fd50", "best_bid": "0.22", "best_ask": "0.24"}], "timestamp": "1769384865748", "event_type": "price_change"}}
{"_local_timestamp": "2026-01-25T23:47:48.397388+00:00", "data": {"market": "0x8442c38c99caf98639415ed14080e055d6609c2fc7613f8c23177b99f7488cc0", "price_changes": [{"asset_id": "43151550904608031994812122462528093658527736846573386213326114950032120527926", "price": "0.4", "size": "300", "side": "BUY", "hash": "fd47482cc7aa56d6f49954685ee0e5c63f0a02b9", "best_bid": "0.76", "best_ask": "0.78"}, {"asset_id": "99086316696015448398478425791443871671895949203487745540409948681487622207594", "price": "0.6", "size": "300", "side": "SELL", "hash": "d1e9016ee0d0e8ad9f503bae115bb56eab552224", "best_bid": "0.22", "best_ask": "0.24"}], "timestamp": "1769384868311", "event_type": "price_change"}}
{"_local_timestamp": "2026-01-25T23:47:48.404306+00:00", "data": {"market": "0x8442c38c99caf98639415ed14080e055d6609c2fc7613f8c23177b99f7488cc0", "price_changes": [{"asset_id": "99086316696015448398478425791443871671895949203487745540409948681487622207594", "price": "0.15", "size": "148.33", "side": "BUY", "hash": "2105bc09adbf783977dc443dd46b0cb001c518d6", "best_bid": "0.22", "best_ask": "0.24"}, {"asset_id": "43151550904608031994812122462528093658527736846573386213326114950032120527926", "price": "0.85", "size": "148.33", "side": "SELL", "hash": "d818402037fd8a4489760ce0dcbe8b226103131e", "best_bid": "0.76", "best_ask": "0.78"}], "timestamp": "1769384868323", "event_type": "price_change"}}
{"_local_timestamp": "2026-01-25T23:47:48.423509+00:00", "data": {"market": "0x8442c38c99caf98639415ed14080e055d6609c2fc7613f8c23177b99f7488cc0", "price_changes": [{"asset_id": "99086316696015448398478425791443871671895949203487745540409948681487622207594", "price": "0.14", "size": "217.85", "side": "BUY", "hash": "101f108c2e51f8d44f85cebdd8ffc101fcb17fb4", "best_bid": "0.22", "best_ask": "0.24"}, {"asset_id": "43151550904608031994812122462528093658527736846573386213326114950032120527926", "price": "0.86", "size": "217.85", "side": "SELL", "hash": "f925b93e8ef6ee048d4ad7f12446d2cb8fbc4e30", "best_bid": "0.76", "best_ask": "0.78"}], "timestamp": "1769384868334", "event_type": "price_change"}}
{"_local_timestamp": "2026-01-25T23:47:48.423993+00:00", "data": {"market": "0x8442c38c99caf98639415ed14080e055d6609c2fc7613f8c23177b99f7488cc0", "price_changes": [{"asset_id": "99086316696015448398478425791443871671895949203487745540409948681487622207594", "price": "0.11", "size": "300", "side": "BUY", "hash": "71b216f956167f315575d2b3250a988cf6e5c968", "best_bid": "0.22", "best_ask": "0.24"}, {"asset_id": "43151550904608031994812122462528093658527736846573386213326114950032120527926", "price": "0.89", "size": "300", "side": "SELL", "hash": "17a6f473bed7ed141c85e0c0de62ed6c1c8a5474", "best_bid": "0.76", "best_ask": "0.78"}], "timestamp": "1769384868346", "event_type": "price_change"}}
{"_local_timestamp": "2026-01-25T23:47:48.436914+00:00", "data": {"market": "0x8442c38c99caf98639415ed14080e055d6609c2fc7613f8c23177b99f7488cc0", "price_changes": [{"asset_id": "43151550904608031994812122462528093658527736846573386213326114950032120527926", "price": "0.49", "size": "125", "side": "BUY", "hash": "005d87968f73727de7c53c5146b32c6d2de077e0", "best_bid": "0.76", "best_ask": "0.78"}, {"asset_id": "99086316696015448398478425791443871671895949203487745540409948681487622207594", "price": "0.51", "size": "125", "side": "SELL", "hash": "b41ea325016414834a0bc0750d665e5da13374ce", "best_bid": "0.22", "best_ask": "0.24"}], "timestamp": "1769384868355", "event_type": "price_change"}}
{"_local_timestamp": "2026-01-25T23:47:48.437425+00:00", "data": {"market": "0x8442c38c99caf98639415ed14080e055d6609c2fc7613f8c23177b99f7488cc0", "price_changes": [{"asset_id": "43151550904608031994812122462528093658527736846573386213326114950032120527926", "price": "0.45", "size": "200", "side": "BUY", "hash": "f936ac335a6e07bd6c41a397ebda983894641600", "best_bid": "0.76", "best_ask": "0.78"}, {"asset_id": "99086316696015448398478425791443871671895949203487745540409948681487622207594", "price": "0.55", "size": "200", "side": "SELL", "hash": "159cb1cb048ec68b84e8427b45e9e53ab4848575", "best_bid": "0.22", "best_ask": "0.24"}], "timestamp": "1769384868363", "event_type": "price_change"}}
{"_local_timestamp": "2026-01-25T23:47:48.445395+00:00", "data": {"market": "0x8442c38c99caf98639415ed14080e055d6609c2fc7613f8c23177b99f7488cc0", "price_changes": [{"asset_id": "43151550904608031994812122462528093658527736846573386213326114950032120527926", "price": "0.53", "size": "75", "side": "BUY", "hash": "58c1da40208fb6bfad311bbb970711bd51193543", "best_bid": "0.76", "best_ask": "0.78"}, {"asset_id": "99086316696015448398478425791443871671895949203487745540409948681487622207594", "price": "0.47", "size": "75", "side": "SELL", "hash": "874e879447e697768836cbb952678da80b6881a2", "best_bid": "0.22", "best_ask": "0.24"}], "timestamp": "1769384868375", "event_type": "price_change"}}
{"_local_timestamp": "2026-01-25T23:47:48.453521+00:00", "data": {"market": "0x8442c38c99caf98639415ed14080e055d6609c2fc7613f8c23177b99f7488cc0", "price_changes": [{"asset_id": "99086316696015448398478425791443871671895949203487745540409948681487622207594", "price": "0.13", "size": "200", "side": "BUY", "hash": "d96148b3eb9818a1871274e6826bb87b51ef06fb", "best_bid": "0.22", "best_ask": "0.24"}, {"asset_id": "43151550904608031994812122462528093658527736846573386213326114950032120527926", "price": "0.87", "size": "200", "side": "SELL", "hash": "829641943b7520ad79d3585a51d7c0a86673dd23", "best_bid": "0.76", "best_ask": "0.78"}], "timestamp": "1769384868384", "event_type": "price_change"}}
{"_local_timestamp": "2026-01-25T23:47:48.643602+00:00", "data": {"market": "0xadb5b2457848b4cde25031495cd1a520363393b81b1110451caca2ee2053f9de", "price_changes": [{"asset_id": "70676785231872628122945643176004673546413040265214614324126365673769398149249", "price": "0.37", "size": "0", "side": "BUY", "hash": "6f36f5c1ff2ffd329e8e0eb201c5dbce19d67b0a", "best_bid": "0.6", "best_ask": "0.61"}, {"asset_id": "64380900244237458579669611562854121322372696763621791641804740469125484043289", "price": "0.63", "size": "0", "side": "SELL", "hash": "a33c861cfd7e2dc54ed34a9902cc84e233e450d4", "best_bid": "0.39", "best_ask": "0.4"}], "timestamp": "1769384868573", "event_type": "price_change"}}
{"_local_timestamp": "2026-01-25T23:47:48.644177+00:00", "data": {"market": "0xadb5b2457848b4cde25031495cd1a520363393b81b1110451caca2ee2053f9de", "price_changes": [{"asset_id": "70676785231872628122945643176004673546413040265214614324126365673769398149249", "price": "0.3", "size": "0", "side": "BUY", "hash": "6f36f5c1ff2ffd329e8e0eb201c5dbce19d67b0a", "best_bid": "0.6", "best_ask": "0.61"}, {"asset_id": "64380900244237458579669611562854121322372696763621791641804740469125484043289", "price": "0.7", "size": "0", "side": "SELL", "hash": "a33c861cfd7e2dc54ed34a9902cc84e233e450d4", "best_bid": "0.39", "best_ask": "0.4"}], "timestamp": "1769384868573", "event_type": "price_change"}}
{"_local_timestamp": "2026-01-25T23:47:48.644774+00:00", "data": {"market": "0xadb5b2457848b4cde25031495cd1a520363393b81b1110451caca2ee2053f9de", "price_changes": [{"asset_id": "70676785231872628122945643176004673546413040265214614324126365673769398149249", "price": "0.34", "size": "0", "side": "BUY", "hash": "6f36f5c1ff2ffd329e8e0eb201c5dbce19d67b0a", "best_bid": "0.6", "best_ask": "0.61"}, {"asset_id": "64380900244237458579669611562854121322372696763621791641804740469125484043289", "price": "0.66", "size": "0", "side": "SELL", "hash": "a33c861cfd7e2dc54ed34a9902cc84e233e450d4", "best_bid": "0.39", "best_ask": "0.4"}], "timestamp": "1769384868573", "event_type": "price_change"}}
{"_local_timestamp": "2026-01-25T23:47:48.645266+00:00", "data": {"market": "0xadb5b2457848b4cde25031495cd1a520363393b81b1110451caca2ee2053f9de", "price_changes": [{"asset_id": "70676785231872628122945643176004673546413040265214614324126365673769398149249", "price": "0.4", "size": "10", "side": "BUY", "hash": "6f36f5c1ff2ffd329e8e0eb201c5dbce19d67b0a", "best_bid": "0.6", "best_ask": "0.61"}, {"asset_id": "64380900244237458579669611562854121322372696763621791641804740469125484043289", "price": "0.6", "size": "10", "side": "SELL", "hash": "a33c861cfd7e2dc54ed34a9902cc84e233e450d4", "best_bid": "0.39", "best_ask": "0.4"}], "timestamp": "1769384868573", "event_type": "price_change"}}
{"_local_timestamp": "2026-01-25T23:47:48.649043+00:00", "data": {"market": "0xadb5b2457848b4cde25031495cd1a520363393b81b1110451caca2ee2053f9de", "price_changes": [{"asset_id": "64380900244237458579669611562854121322372696763621791641804740469125484043289", "price": "0.24", "size": "0", "side": "BUY", "hash": "8de9593709a4705e7170e5cd585949970ec077c3", "best_bid": "0.39", "best_ask": "0.4"}, {"asset_id": "70676785231872628122945643176004673546413040265214614324126365673769398149249", "price": "0.76", "size": "0", "side": "SELL", "hash": "61fa0a2fd1e1ac86f119fff2656fc33af44e4e23", "best_bid": "0.6", "best_ask": "0.61"}], "timestamp": "1769384868574", "event_type": "price_change"}}
{"_local_timestamp": "2026-01-25T23:47:48.649599+00:00", "data": {"market": "0xadb5b2457848b4cde25031495cd1a520363393b81b1110451caca2ee2053f9de", "price_changes": [{"asset_id": "64380900244237458579669611562854121322372696763621791641804740469125484043289", "price": "0.22", "size": "0", "side": "BUY", "hash": "8de9593709a4705e7170e5cd585949970ec077c3", "best_bid": "0.39", "best_ask": "0.4"}, {"asset_id": "70676785231872628122945643176004673546413040265214614324126365673769398149249", "price": "0.78", "size": "0", "side": "SELL", "hash": "61fa0a2fd1e1ac86f119fff2656fc33af44e4e23", "best_bid": "0.6", "best_ask": "0.61"}], "timestamp": "1769384868574", "event_type": "price_change"}}
{"_local_timestamp": "2026-01-25T23:47:48.650122+00:00", "data": {"market": "0xadb5b2457848b4cde25031495cd1a520363393b81b1110451caca2ee2053f9de", "price_changes": [{"asset_id": "64380900244237458579669611562854121322372696763621791641804740469125484043289", "price": "0.19", "size": "0", "side": "BUY", "hash": "8de9593709a4705e7170e5cd585949970ec077c3", "best_bid": "0.39", "best_ask": "0.4"}, {"asset_id": "70676785231872628122945643176004673546413040265214614324126365673769398149249", "price": "0.81", "size": "0", "side": "SELL", "hash": "61fa0a2fd1e1ac86f119fff2656fc33af44e4e23", "best_bid": "0.6", "best_ask": "0.61"}], "timestamp": "1769384868574", "event_type": "price_change"}}
{"_local_timestamp": "2026-01-25T23:47:48.650613+00:00", "data": {"market": "0xadb5b2457848b4cde25031495cd1a520363393b81b1110451caca2ee2053f9de", "price_changes": [{"asset_id": "64380900244237458579669611562854121322372696763621791641804740469125484043289", "price": "0.25", "size": "0", "side": "BUY", "hash": "8de9593709a4705e7170e5cd585949970ec077c3", "best_bid": "0.39", "best_ask": "0.4"}, {"asset_id": "70676785231872628122945643176004673546413040265214614324126365673769398149249", "price": "0.75", "size": "0", "side": "SELL", "hash": "61fa0a2fd1e1ac86f119fff2656fc33af44e4e23", "best_bid": "0.6", "best_ask": "0.61"}], "timestamp": "1769384868574", "event_type": "price_change"}}
{"_local_timestamp": "2026-01-25T23:47:50.573897+00:00", "data": {"market": "0xadb5b2457848b4cde25031495cd1a520363393b81b1110451caca2ee2053f9de", "price_changes": [{"asset_id": "64380900244237458579669611562854121322372696763621791641804740469125484043289", "price": "0.2", "size": "697", "side": "BUY", "hash": "aeddf2cee72d5bdb450b0c1f3c3dccd9cf75a6fc", "best_bid": "0.39", "best_ask": "0.4"}, {"asset_id": "70676785231872628122945643176004673546413040265214614324126365673769398149249", "price": "0.8", "size": "697", "side": "SELL", "hash": "e4faf0642154eeb75041897747313ecf4c41c98a", "best_bid": "0.6", "best_ask": "0.61"}], "timestamp": "1769384870502", "event_type": "price_change"}}
{"_local_timestamp": "2026-01-25T23:47:50.582481+00:00", "data": {"market": "0xadb5b2457848b4cde25031495cd1a520363393b81b1110451caca2ee2053f9de", "price_changes": [{"asset_id": "70676785231872628122945643176004673546413040265214614324126365673769398149249", "price": "0.3", "size": "300", "side": "BUY", "hash": "6cb317d9d60e43b6e0d1bd939c5caa4d9a6c1e6e", "best_bid": "0.6", "best_ask": "0.61"}, {"asset_id": "64380900244237458579669611562854121322372696763621791641804740469125484043289", "price": "0.7", "size": "300", "side": "SELL", "hash": "442845136e270538bbd82231b47ec48a7d36a26e", "best_bid": "0.39", "best_ask": "0.4"}], "timestamp": "1769384870504", "event_type": "price_change"}}
{"_local_timestamp": "2026-01-25T23:47:50.583071+00:00", "data": {"market": "0xadb5b2457848b4cde25031495cd1a520363393b81b1110451caca2ee2053f9de", "price_changes": [{"asset_id": "64380900244237458579669611562854121322372696763621791641804740469125484043289", "price": "0.26", "size": "75", "side": "BUY", "hash": "edce03be858b708ca524549ca9187041bc5ef9b5", "best_bid": "0.39", "best_ask": "0.4"}, {"asset_id": "70676785231872628122945643176004673546413040265214614324126365673769398149249", "price": "0.74", "size": "75", "side": "SELL", "hash": "1d053e399522db7d64610dd92a081b50fda16be8", "best_bid": "0.6", "best_ask": "0.61"}], "timestamp": "1769384870507", "event_type": "price_change"}}
{"_local_timestamp": "2026-01-25T23:47:50.584186+00:00", "data": {"market": "0xadb5b2457848b4cde25031495cd1a520363393b81b1110451caca2ee2053f9de", "price_changes": [{"asset_id": "70676785231872628122945643176004673546413040265214614324126365673769398149249", "price": "0.34", "size": "200", "side": "BUY", "hash": "348f96403f385214b6cb440a2db0beb22cfa8fd5", "best_bid": "0.6", "best_ask": "0.61"}, {"asset_id": "64380900244237458579669611562854121322372696763621791641804740469125484043289", "price": "0.66", "size": "200", "side": "SELL", "hash": "e6194f9445dd15fc0133edc59b59b08bd4358c6a", "best_bid": "0.39", "best_ask": "0.4"}], "timestamp": "1769384870509", "event_type": "price_change"}}
{"_local_timestamp": "2026-01-25T23:47:50.585044+00:00", "data": {"market": "0xadb5b2457848b4cde25031495cd1a520363393b81b1110451caca2ee2053f9de", "price_changes": [{"asset_id": "64380900244237458579669611562854121322372696763621791641804740469125484043289", "price": "0.24", "size": "125", "side": "BUY", "hash": "0b44a81c05ae27668c59279bea6f5f4cea2cb086", "best_bid": "0.39", "best_ask": "0.4"}, {"asset_id": "70676785231872628122945643176004673546413040265214614324126365673769398149249", "price": "0.76", "size": "125", "side": "SELL", "hash": "44c5c058cb2734a7606bf62b1ef1a78b1a7dc277", "best_bid": "0.6", "best_ask": "0.61"}], "timestamp": "1769384870510", "event_type": "price_change"}}
{"_local_timestamp": "2026-01-25T23:47:50.592738+00:00", "data": {"market": "0xadb5b2457848b4cde25031495cd1a520363393b81b1110451caca2ee2053f9de", "price_changes": [{"asset_id": "64380900244237458579669611562854121322372696763621791641804740469125484043289", "price": "0.22", "size": "200", "side": "BUY", "hash": "5627eddd9cf91bef2a66898c231f4b0de002747a", "best_bid": "0.39", "best_ask": "0.4"}, {"asset_id": "70676785231872628122945643176004673546413040265214614324126365673769398149249", "price": "0.78", "size": "200", "side": "SELL", "hash": "b40fdcea5838d5235cae5f927ddd9065604a7a78", "best_bid": "0.6", "best_ask": "0.61"}], "timestamp": "1769384870512", "event_type": "price_change"}}
{"_local_timestamp": "2026-01-25T23:47:50.599891+00:00", "data": {"market": "0xadb5b2457848b4cde25031495cd1a520363393b81b1110451caca2ee2053f9de", "price_changes": [{"asset_id": "70676785231872628122945643176004673546413040265214614324126365673769398149249", "price": "0.4", "size": "85", "side": "BUY", "hash": "f2e555570f49e03428624b29b2b70832c1b995b8", "best_bid": "0.6", "best_ask": "0.61"}, {"asset_id": "64380900244237458579669611562854121322372696763621791641804740469125484043289", "price": "0.6", "size": "85", "side": "SELL", "hash": "7f1f6de543bc5777e84242392b8fe06f5f20ccda", "best_bid": "0.39", "best_ask": "0.4"}], "timestamp": "1769384870514", "event_type": "price_change"}}
{"_local_timestamp": "2026-01-25T23:47:50.600414+00:00", "data": {"market": "0xadb5b2457848b4cde25031495cd1a520363393b81b1110451caca2ee2053f9de", "price_changes": [{"asset_id": "70676785231872628122945643176004673546413040265214614324126365673769398149249", "price": "0.37", "size": "125", "side": "BUY", "hash": "498a1f01874e5beeda060da91368a4ed56050376", "best_bid": "0.6", "best_ask": "0.61"}, {"asset_id": "64380900244237458579669611562854121322372696763621791641804740469125484043289", "price": "0.63", "size": "125", "side": "SELL", "hash": "32b715f79d6af69359abcda2e6ca9844b0267a35", "best_bid": "0.39", "best_ask": "0.4"}], "timestamp": "1769384870515", "event_type": "price_change"}}
{"_local_timestamp": "2026-01-25T23:47:50.733952+00:00", "data": {"market": "0x75e7746b83f53e85d5684d5fef6e49fc452f865b6e83a0ebe2b0942f550bdd03", "price_changes": [{"asset_id": "47884350108418615197770865197095031131543030780360535858897660411470051234625", "price": "0.03", "size": "550", "side": "BUY", "hash": "a17faac93a1ce15b9428a5b3c65588eceb128c0e", "best_bid": "0.15", "best_ask": "0.18"}, {"asset_id": "112818684217285049373394970300912246725692512435350502775015469723427543698392", "price": "0.97", "size": "550", "side": "SELL", "hash": "22f4019ab0cc2ea6d060bb5f59e963d5dd81dccf", "best_bid": "0.82", "best_ask": "0.85"}], "timestamp": "1769384870653", "event_type": "price_change"}}
{"_local_timestamp": "2026-01-25T23:48:02.890258+00:00", "data": {"market": "0x75e7746b83f53e85d5684d5fef6e49fc452f865b6e83a0ebe2b0942f550bdd03", "price_changes": [{"asset_id": "47884350108418615197770865197095031131543030780360535858897660411470051234625", "price": "0.03", "size": "250", "side": "BUY", "hash": "990d95b62c10344e4114fe9a729d70b111a7a119", "best_bid": "0.15", "best_ask": "0.18"}, {"asset_id": "112818684217285049373394970300912246725692512435350502775015469723427543698392", "price": "0.97", "size": "250", "side": "SELL", "hash": "23471905c8284a129cea3b13149826a1f008ed57", "best_bid": "0.82", "best_ask": "0.85"}], "timestamp": "1769384882694", "event_type": "price_change"}}
{"_local_timestamp": "2026-01-25T23:48:14.561110+00:00", "data": {"market": "0x75e7746b83f53e85d5684d5fef6e49fc452f865b6e83a0ebe2b0942f550bdd03", "price_changes": [{"asset_id": "47884350108418615197770865197095031131543030780360535858897660411470051234625", "price": "0.12", "size": "134.28", "side": "BUY", "hash": "ce2b6c4684f7deaf1617fa3af585a1f072093bd3", "best_bid": "0.15", "best_ask": "0.18"}, {"asset_id": "112818684217285049373394970300912246725692512435350502775015469723427543698392", "price": "0.88", "size": "134.28", "side": "SELL", "hash": "a3563d623a9ee9232dec20fc6a9f0ca854b57970", "best_bid": "0.82", "best_ask": "0.85"}], "timestamp": "1769384894328", "event_type": "price_change"}}
{"_local_timestamp": "2026-01-25T23:48:16.888292+00:00", "data": {"market": "0xadb5b2457848b4cde25031495cd1a520363393b81b1110451caca2ee2053f9de", "price_changes": [{"asset_id": "70676785231872628122945643176004673546413040265214614324126365673769398149249", "price": "0.53", "size": "50", "side": "BUY", "hash": "d7bf676a96cd3baeef7fba5a1e5ac2689ff19427", "best_bid": "0.6", "best_ask": "0.61"}, {"asset_id": "64380900244237458579669611562854121322372696763621791641804740469125484043289", "price": "0.47", "size": "50", "side": "SELL", "hash": "6a03ab9e96aeb28693e22dbbc5c9ed47b1f38492", "best_bid": "0.39", "best_ask": "0.4"}], "timestamp": "1769384896639", "event_type": "price_change"}}
{"_local_timestamp": "2026-01-25T23:48:38.148798+00:00", "data": {"market": "0xadb5b2457848b4cde25031495cd1a520363393b81b1110451caca2ee2053f9de", "price_changes": [{"asset_id": "70676785231872628122945643176004673546413040265214614324126365673769398149249", "price": "0.1", "size": "0", "side": "BUY", "hash": "bcda4b0928a4e8a9aad6a4048f02faf810dbfd50", "best_bid": "0.6", "best_ask": "0.61"}, {"asset_id": "64380900244237458579669611562854121322372696763621791641804740469125484043289", "price": "0.9", "size": "0", "side": "SELL", "hash": "6555f27f167ea8a0a729b6121359d6d7b9c9db5f", "best_bid": "0.39", "best_ask": "0.4"}], "timestamp": "1769384917758", "event_type": "price_change"}}
{"_local_timestamp": "2026-01-25T23:48:38.427940+00:00", "data": {"market": "0xadb5b2457848b4cde25031495cd1a520363393b81b1110451caca2ee2053f9de", "price_changes": [{"asset_id": "70676785231872628122945643176004673546413040265214614324126365673769398149249", "price": "0.11", "size": "500", "side": "BUY", "hash": "94c2053f29d99f4477198c91cb57681da8a5a54e", "best_bid": "0.6", "best_ask": "0.61"}, {"asset_id": "64380900244237458579669611562854121322372696763621791641804740469125484043289", "price": "0.89", "size": "500", "side": "SELL", "hash": "03cfa3c9b70a319302334551f24672403ba3d73b", "best_bid": "0.39", "best_ask": "0.4"}], "timestamp": "1769384918096", "event_type": "price_change"}}
