{"_local_timestamp": "2026-01-25T23:33:35.215328+00:00", "data": [{"market": "0x0dcb82c1f435a34fd6f80b0ed6ac98e96125e347d50c258426e5c9600e085661", "asset_id": "23971807630734160157347033369840060495008877902009661072297332891205643761964", "timestamp": "1769383980341", "hash": "f90828022b4634c2cb63983621f8f0526665d7ef", "bids": [{"price": "0.001", "size": "36578.99"}, {"price": "0.002", "size": "8222.69"}, {"price": "0.003", "size": "3037.61"}, {"price": "0.004", "size": "278.06"}, {"price": "0.005", "size": "1333.33"}, {"price": "0.006", "size": "223.82"}, {"price": "0.007", "size": "858.92"}, {"price": "0.008", "size": "255.98"}, {"price": "0.009", "size": "24.26"}, {"price": "0.01", "size": "549.4"}, {"price": "0.012", "size": "5"}], "asks": [{"price": "0.999", "size": "8501.07"}, {"price": "0.998", "size": "3255.04"}, {"price": "0.997", "size": "1166"}, {"price": "0.996", "size": "8.63"}, {"price": "0.994", "size": "83"}, {"price": "0.99", "size": "3000"}, {"price": "0.989", "size": "8.38"}, {"price": "0.98", "size": "2150"}, {"price": "0.97", "size": "1000"}, {"price": "0.969", "size": "9.42"}, {"price": "0.95", "size": "30"}, {"price": "0.949", "size": "39"}, {"price": "0.92", "size": "400"}, {"price": "0.9", "size": "860"}, {"price": "0.889", "size": "200"}, {"price": "0.888", "size": "5.05"}, {"price": "0.85", "size": "2026.66"}, {"price": "0.849", "size": "250"}, {"price": "0.8", "size": "610"}, {"price": "0.75", "size": "362"}, {"price": "0.7", "size": "186.66"}, {"price": "0.65", "size": "68.57"}, {"price": "0.6", "size": "1445"}, {"price": "0.599", "size": "5"}, {"price": "0.25", "size": "60"}, {"price": "0.17", "size": "500"}, {"price": "0.16", "size": "100"}, {"price": "0.09", "size": "12.5"}, {"price": "0.074", "size": "386"}, {"price": "0.069", "size": "366"}, {"price": "0.054", "size": "1111"}, {"price": "0.053", "size": "222"}, {"price": "0.049", "size": "300"}, {"price": "0.047", "size": "222"}, {"price": "0.046", "size": "300"}, {"price": "0.045", "size": "69.99"}, {"price": "0.039", "size": "10"}, {"price": "0.033", "size": "400"}, {"price": "0.028", "size": "200"}, {"price": "0.027", "size": "1000"}, {"price": "0.025", "size": "202"}, {"price": "0.02", "size": "1495.05"}, {"price": "0.013", "size": "1024.98"}], "event_type": "book", "last_trade_price": "0.013"}, {"market": "0xf019dab83a6175caa9fbba00969cb975f507361946f6c525e06f8309511895a5", "asset_id": "83785219409901830836243369060901996372184012390787478757821683053398319156195", "timestamp": "1769382399708", "hash": "95ae96cd5ed7eca0b78330a87962930ab8aec537", "bids": [{"price": "0.01", "size": "4507.61"}, {"price": "0.02", "size": "1250"}, {"price": "0.03", "size": "13.02"}, {"price": "0.04", "size": "75"}, {"price": "0.05", "size": "10"}, {"price": "0.07", "size": "80"}, {"price": "0.08", "size": "162.5"}, {"price": "0.09", "size": "5.92"}, {"price": "0.13", "size": "400"}, {"price": "0.14", "size": "78.57"}, {"price": "0.19", "size": "422"}, {"price": "0.21", "size": "491.36"}], "asks": [{"price": "0.99", "size": "3259.76"}, {"price": "0.98", "size": "1000"}, {"price": "0.97", "size": "10.19"}, {"price": "0.95", "size": "1710"}, {"price": "0.92", "size": "450"}, {"price": "0.9", "size": "700"}, {"price": "0.89", "size": "5.42"}, {"price": "0.88", "size": "833.33"}, {"price": "0.84", "size": "600"}, {"price": "0.8", "size": "140"}, {"price": "0.76", "size": "408.33"}, {"price": "0.75", "size": "179"}, {"price": "0.72", "size": "185.71"}, {"price": "0.68", "size": "62.5"}, {"price": "0.65", "size": "225"}, {"price": "0.64", "size": "5"}, {"price": "0.46", "size": "5"}, {"price": "0.44", "size": "100"}, {"price": "0.43", "size": "10"}, {"price": "0.4", "size": "20"}, {"price": "0.35", "size": "300"}, {"price": "0.32", "size": "19.11"}, {"price": "0.31", "size": "51.94"}, {"price": "0.3", "size": "39.69"}, {"price": "0.25", "size": "9.34"}, {"price": "0.24", "size": "10"}], "event_type": "book", "last_trade_price": "0.210"}, {"market": "0xa56434f3ea8fffc460fc1d7cb9cb6b65edabadb490593c795e22d90fe57d17f0", "asset_id": "59439039310742412354907293409831028082512392186247250574941418012522361318651", "timestamp": "1769383963559", "hash": "ad4d26bbb6c31ca3d26532f94ea562c207a00e52", "bids": [{"price": "0.01", "size": "1500"}, {"price": "0.02", "size": "13.24"}, {"price": "0.05", "size": "4080"}, {"price": "0.06", "size": "33"}, {"price": "0.07", "size": "10.5"}, {"price": "0.15", "size": "2300"}, {"price": "0.16", "size": "86.67"}, {"price": "0.17", "size": "400"}, {"price": "0.23", "size": "325"}, {"price": "0.26", "size": "50"}, {"price": "0.27", "size": "7"}, {"price": "0.48", "size": "86.67"}, {"price": "0.73", "size": "20"}, {"price": "0.74", "size": "5"}, {"price": "0.75", "size": "50.66"}, {"price": "0.79", "size": "10"}], "asks": [{"price": "0.99", "size": "1505.61"}, {"price": "0.98", "size": "62.39"}, {"price": "0.97", "size": "35"}, {"price": "0.96", "size": "17.39"}, {"price": "0.94", "size": "2222"}, {"price": "0.93", "size": "472"}, {"price": "0.92", "size": "224.92"}, {"price": "0.91", "size": "130"}], "event_type": "book", "last_trade_price": "0.900"}, {"market": "0x0dcb82c1f435a34fd6f80b0ed6ac98e96125e347d50c258426e5c9600e085661", "asset_id": "25786306769392419954082257849170188721482659475898153836815032693554224565734", "timestamp": "1769383980341", "hash": "a95dcce6c061b9b80549ebd5bb9e6b26572c70b4", "bids": [{"price": "0.001", "size": "8501.07"}, {"price": "0.002", "size": "3255.04"}, {"price": "0.003", "size": "1166"}, {"price": "0.004", "size": "8.63"}, {"price": "0.006", "size": "83"}, {"price": "0.01", "size": "3000"}, {"price": "0.011", "size": "8.38"}, {"price": "0.02", "size": "2150"}, {"price": "0.03", "size": "1000"}, {"price": "0.031", "size": "9.42"}, {"price": "0.05", "size": "30"}, {"price": "0.051", "size": "39"}, {"price": "0.08", "size": "400"}, {"price": "0.1", "size": "860"}, {"price": "0.111", "size": "200"}, {"price": "0.112", "size": "5.05"}, {"price": "0.15", "size": "2026.66"}, {"price": "0.151", "size": "250"}, {"price": "0.2", "size": "610"}, {"price": "0.25", "size": "362"}, {"price": "0.3", "size": "186.66"}, {"price": "0.35", "size": "68.57"}, {"price": "0.4", "size": "1445"}, {"price": "0.401", "size": "5"}, {"price": "0.75", "size": "60"}, {"price": "0.83", "size": "500"}, {"price": "0.84", "size": "100"}, {"price": "0.91", "size": "12.5"}, {"price": "0.926", "size": "386"}, {"price": "0.931", "size": "366"}, {"price": "0.946", "size": "1111"}, {"price": "0.947", "size": "222"}, {"price": "0.951", "size": "300"}, {"price": "0.953", "size": "222"}, {"price": "0.954", "size": "300"}, {"price": "0.955", "size": "69.99"}, {"price": "0.961", "size": "10"}, {"price": "0.967", "size": "400"}, {"price": "0.972", "size": "200"}, {"price": "0.973", "size": "1000"}, {"price": "0.975", "size": "202"}, {"price": "0.98", "size": "1495.05"}, {"price": "0.987", "size": "1024.98"}], "asks": [{"price": "0.999", "size": "36578.99"}, {"price": "0.998", "size": "8222.69"}, {"price": "0.997", "size": "3037.61"}, {"price": "0.996", "size": "278.06"}, {"price": "0.995", "size": "1333.33"}, {"price": "0.994", "size": "223.82"}, {"price": "0.993", "size": "858.92"}, {"price": "0.992", "size": "255.98"}, {"price": "0.991", "size": "24.26"}, {"price": "0.99", "size": "549.4"}, {"price": "0.988", "size": "5"}], "event_type": "book", "last_trade_price": "0.013"}, {"market": "0xa56434f3ea8fffc460fc1d7cb9cb6b65edabadb490593c795e22d90fe57d17f0", "asset_id": "93559682575679849377661192498326372065972403403118003982372243474989955649691", "timestamp": "1769383963559", "hash": "aa02a7013849aeaccf1190ce78e1b2dc8e2de273", "bids": [{"price": "0.01", "size": "1505.61"}, {"price": "0.02", "size": "62.39"}, {"price": "0.03", "size": "35"}, {"price": "0.04", "size": "17.39"}, {"price": "0.06", "size": "2222"}, {"price": "0.07", "size": "472"}, {"price": "0.08", "size": "224.92"}, {"price": "0.09", "size": "130"}], "asks": [{"price": "0.99", "size": "1500"}, {"price": "0.98", "size": "13.24"}, {"price": "0.95", "size": "4080"}, {"price": "0.94", "size": "33"}, {"price": "0.93", "size": "10.5"}, {"price": "0.85", "size": "2300"}, {"price": "0.84", "size": "86.67"}, {"price": "0.83", "size": "400"}, {"price": "0.77", "size": "325"}, {"price": "0.74", "size": "50"}, {"price": "0.73", "size": "7"}, {"price": "0.52", "size": "86.67"}, {"price": "0.27", "size": "20"}, {"price": "0.26", "size": "5"}, {"price": "0.25", "size": "50.66"}, {"price": "0.21", "size": "10"}], "event_type": "book", "last_trade_price": "0.900"}, {"market": "0xf019dab83a6175caa9fbba00969cb975f507361946f6c525e06f8309511895a5", "asset_id": "34114221682820460544077326888333943191501616706946091153792888341321117039105", "timestamp": "1769382399708", "hash": "54196ad00b8a400b83040c3e0c980c368de3fc36", "bids": [{"price": "0.01", "size": "3259.76"}, {"price": "0.02", "size": "1000"}, {"price": "0.03", "size": "10.19"}, {"price": "0.05", "size": "1710"}, {"price": "0.08", "size": "450"}, {"price": "0.1", "size": "700"}, {"price": "0.11", "size": "5.42"}, {"price": "0.12", "size": "833.33"}, {"price": "0.16", "size": "600"}, {"price": "0.2", "size": "140"}, {"price": "0.24", "size": "408.33"}, {"price": "0.25", "size": "179"}, {"price": "0.28", "size": "185.71"}, {"price": "0.32", "size": "62.5"}, {"price": "0.35", "size": "225"}, {"price": "0.36", "size": "5"}, {"price": "0.54", "size": "5"}, {"price": "0.56", "size": "100"}, {"price": "0.57", "size": "10"}, {"price": "0.6", "size": "20"}, {"price": "0.65", "size": "300"}, {"price": "0.68", "size": "19.11"}, {"price": "0.69", "size": "51.94"}, {"price": "0.7", "size": "39.69"}, {"price": "0.75", "size": "9.34"}, {"price": "0.76", "size": "10"}], "asks": [{"price": "0.99", "size": "4507.61"}, {"price": "0.98", "size": "1250"}, {"price": "0.97", "size": "13.02"}, {"price": "0.96", "size": "75"}, {"price": "0.95", "size": "10"}, {"price": "0.93", "size": "80"}, {"price": "0.92", "size": "162.5"}, {"price": "0.91", "size": "5.92"}, {"price": "0.87", "size": "400"}, {"price": "0.86", "size": "78.57"}, {"price": "0.81", "size": "422"}, {"price": "0.79", "size": "491.36"}], "event_type": "book", "last_trade_price": "0.210"}]}
{"_local_timestamp": "2026-01-25T23:33:40.196704+00:00", "data": {"market": "0xa56434f3ea8fffc460fc1d7cb9cb6b65edabadb490593c795e22d90fe57d17f0", "price_changes": [{"asset_id": "59439039310742412354907293409831028082512392186247250574941418012522361318651", "price": "0.17", "size": "300", "side": "BUY", "hash": "707285f58bcfe743e508a5b329dce1af4ad6110b", "best_bid": "0.79", "best_ask": "0.91"}, {"asset_id": "93559682575679849377661192498326372065972403403118003982372243474989955649691", "price": "0.83", "size": "300", "side": "SELL", "hash": "ad3b72b4f874de246ee9dfa680e298f5ecf910df", "best_bid": "0.09", "best_ask": "0.21"}], "timestamp": "1769384020086", "event_type": "price_change"}}
{"_local_timestamp": "2026-01-25T23:33:40.790356+00:00", "data": {"market": "0xa56434f3ea8fffc460fc1d7cb9cb6b65edabadb490593c795e22d90fe57d17f0", "price_changes": [{"asset_id": "59439039310742412354907293409831028082512392186247250574941418012522361318651", "price": "0.16", "size": "186.67", "side": "BUY", "hash": "513c708e91115b9b13a4de33094e230ddb4ea250", "best_bid": "0.79", "best_ask": "0.91"}, {"asset_id": "93559682575679849377661192498326372065972403403118003982372243474989955649691", "price": "0.84", "size": "186.67", "side": "SELL", "hash": "59173e9ede75bba1721704186427acd98da922f4", "best_bid": "0.09", "best_ask": "0.21"}], "timestamp": "1769384020558", "event_type": "price_change"}}
{"_local_timestamp": "2026-01-25T23:33:54.036069+00:00", "data": {"market": "0xa56434f3ea8fffc460fc1d7cb9cb6b65edabadb490593c795e22d90fe57d17f0", "price_changes": [{"asset_id": "59439039310742412354907293409831028082512392186247250574941418012522361318651", "price": "0.75", "size": "0", "side": "BUY", "hash": "cf2e423d37d6de222e71207f524f2e0a6e43174c", "best_bid": "0.79", "best_ask": "0.91"}, {"asset_id": "93559682575679849377661192498326372065972403403118003982372243474989955649691", "price": "0.25", "size": "0", "side": "SELL", "hash": "9411dc10d36ad53e4ce8bb8889b61a4eb26d7ead", "best_bid": "0.09", "best_ask": "0.21"}], "timestamp": "1769384033960", "event_type": "price_change"}}
{"_local_timestamp": "2026-01-25T23:34:01.653165+00:00", "data": {"market": "0xa56434f3ea8fffc460fc1d7cb9cb6b65edabadb490593c795e22d90fe57d17f0", "price_changes": [{"asset_id": "59439039310742412354907293409831028082512392186247250574941418012522361318651", "price": "0.05", "size": "4480", "side": "BUY", "hash": "0e8c05b323f7b3b952e678f9079629b67bdeb5b0", "best_bid": "0.79", "best_ask": "0.91"}, {"asset_id": "93559682575679849377661192498326372065972403403118003982372243474989955649691", "price": "0.95", "size": "4480", "side": "SELL", "hash": "762082c744915974adbb344fe9d348d2887cd1ab", "best_bid": "0.09", "best_ask": "0.21"}], "timestamp": "1769384041558", "event_type": "price_change"}}
{"_local_timestamp": "2026-01-25T23:34:01.660483+00:00", "data": {"market": "0xa56434f3ea8fffc460fc1d7cb9cb6b65edabadb490593c795e22d90fe57d17f0", "price_changes": [{"asset_id": "59439039310742412354907293409831028082512392186247250574941418012522361318651", "price": "0.06", "size": "233", "side": "BUY", "hash": "5415637bbafdf315da445c8867dd6b5115834d87", "best_bid": "0.79", "best_ask": "0.91"}, {"asset_id": "93559682575679849377661192498326372065972403403118003982372243474989955649691", "price": "0.94", "size": "233", "side": "SELL", "hash": "51e7fbf3db86a93d63f4e41bc067702d94669e14", "best_bid": "0.09", "best_ask": "0.21"}], "timestamp": "1769384041566", "event_type": "price_change"}}
{"_local_timestamp": "2026-01-25T23:34:26.101480+00:00", "data": {"market": "0x0dcb82c1f435a34fd6f80b0ed6ac98e96125e347d50c258426e5c9600e085661", "price_changes": [{"asset_id": "23971807630734160157347033369840060495008877902009661072297332891205643761964", "price": "0.002", "size": "8166", "side": "BUY", "hash": "039f3fc6cdc1b05fed54c8504c1f22b9add3d709", "best_bid": "0.012", "best_ask": "0.013"}, {"asset_id": "25786306769392419954082257849170188721482659475898153836815032693554224565734", "price": "0.998", "size": "8166", "side": "SELL", "hash": "64172fcbd02fc8f004a3c0543590c5d25aba1971", "best_bid": "0.987", "best_ask": "0.988"}], "timestamp": "1769384065852", "event_type": "price_change"}}
{"_local_timestamp": "2026-01-25T23:34:26.108466+00:00", "data": {"market": "0x0dcb82c1f435a34fd6f80b0ed6ac98e96125e347d50c258426e5c9600e085661", "price_changes": [{"asset_id": "23971807630734160157347033369840060495008877902009661072297332891205643761964", "price": "0.003", "size": "3000", "side": "BUY", "hash": "039f3fc6cdc1b05fed54c8504c1f22b9add3d709", "best_bid": "0.012", "best_ask": "0.013"}, {"asset_id": "25786306769392419954082257849170188721482659475898153836815032693554224565734", "price": "0.997", "size": "3000", "side": "SELL", "hash": "64172fcbd02fc8f004a3c0543590c5d25aba1971", "best_bid": "0.987", "best_ask": "0.988"}], "timestamp": "1769384065852", "event_type": "price_change"}}
{"_local_timestamp": "2026-01-25T23:34:26.109733+00:00", "data": {"market": "0x0dcb82c1f435a34fd6f80b0ed6ac98e96125e347d50c258426e5c9600e085661", "price_changes": [{"asset_id": "23971807630734160157347033369840060495008877902009661072297332891205643761964", "price": "0.004", "size": "250", "side": "BUY", "hash": "039f3fc6cdc1b05fed54c8504c1f22b9add3d709", "best_bid": "0.012", "best_ask": "0.013"}, {"asset_id": "25786306769392419954082257849170188721482659475898153836815032693554224565734", "price": "0.996", "size": "250", "side": "SELL", "hash": "64172fcbd02fc8f004a3c0543590c5d25aba1971", "best_bid": "0.987", "best_ask": "0.988"}], "timestamp": "1769384065852", "event_type": "price_change"}}
{"_local_timestamp": "2026-01-25T23:34:27.883125+00:00", "data": {"market": "0xa56434f3ea8fffc460fc1d7cb9cb6b65edabadb490593c795e22d90fe57d17f0", "price_changes": [{"asset_id": "59439039310742412354907293409831028082512392186247250574941418012522361318651", "price": "0.17", "size": "150", "side": "BUY", "hash": "02537c0f37ba1daeae3b2e56a893cc382a946407", "best_bid": "0.79", "best_ask": "0.91"}, {"asset_id": "93559682575679849377661192498326372065972403403118003982372243474989955649691", "price": "0.83", "size": "150", "side": "SELL", "hash": "8f50f3a9a1ff41e2f9afcb91c24c28a35c5b6cbf", "best_bid": "0.09", "best_ask": "0.21"}], "timestamp": "1769384067573", "event_type": "price_change"}}
{"_local_timestamp": "2026-01-25T23:34:28.712358+00:00", "data": {"market": "0xa56434f3ea8fffc460fc1d7cb9cb6b65edabadb490593c795e22d90fe57d17f0", "price_changes": [{"asset_id": "59439039310742412354907293409831028082512392186247250574941418012522361318651", "price": "0.16", "size": "336.67", "side": "BUY", "hash": "cdb009eb33059b98df49704a804fb980939a470c", "best_bid": "0.79", "best_ask": "0.91"}, {"asset_id": "93559682575679849377661192498326372065972403403118003982372243474989955649691", "price": "0.84", "size": "336.67", "side": "SELL", "hash": "b9f34bb6f7bf9c3a04ee3871aa4b610e572fcb9f", "best_bid": "0.09", "best_ask": "0.21"}], "timestamp": "1769384068150", "event_type": "price_change"}}
{"_local_timestamp": "2026-01-25T23:34:28.918747+00:00", "data": {"market": "0x0dcb82c1f435a34fd6f80b0ed6ac98e96125e347d50c258426e5c9600e085661", "price_changes": [{"asset_id": "23971807630734160157347033369840060495008877902009661072297332891205643761964", "price": "0.003", "size": "3037.61", "side": "BUY", "hash": "e2495ec6fa73c57ea53528a0bb33bef6016fb961", "best_bid": "0.012", "best_ask": "0.013"}, {"asset_id": "25786306769392419954082257849170188721482659475898153836815032693554224565734", "price": "0.997", "size": "3037.61", "side": "SELL", "hash": "1d675ca6fb1e199bf6f2de7b1ee4dbfaadaf3d00", "best_bid": "0.987", "best_ask": "0.988"}], "timestamp": "1769384068336", "event_type": "price_change"}}
{"_local_timestamp": "2026-01-25T23:34:28.919774+00:00", "data": {"market": "0x0dcb82c1f435a34fd6f80b0ed6ac98e96125e347d50c258426e5c9600e085661", "price_changes": [{"asset_id": "23971807630734160157347033369840060495008877902009661072297332891205643761964", "price": "0.004", "size": "278.06", "side": "BUY", "hash": "98e61f7f1d39be35431b9344260d213cae1d3b06", "best_bid": "0.012", "best_ask": "0.013"}, {"asset_id": "25786306769392419954082257849170188721482659475898153836815032693554224565734", "price": "0.996", "size": "278.06", "side": "SELL", "hash": "8c9583a6e1e7704816955ca4b7e2aba0212bae3f", "best_bid": "0.987", "best_ask": "0.988"}], "timestamp": "1769384068337", "event_type": "price_change"}}
{"_local_timestamp": "2026-01-25T23:34:28.923281+00:00", "data": {"market": "0x0dcb82c1f435a34fd6f80b0ed6ac98e96125e347d50c258426e5c9600e085661", "price_changes": [{"asset_id": "23971807630734160157347033369840060495008877902009661072297332891205643761964", "price": "0.002", "size": "8222.69", "side": "BUY", "hash": "0069d45d917b6f15eced27f6471f7c865e264b0f", "best_bid": "0.012", "best_ask": "0.013"}, {"asset_id": "25786306769392419954082257849170188721482659475898153836815032693554224565734", "price": "0.998", "size": "8222.69", "side": "SELL", "hash": "0a15a9b5c95ae7f3ab3e902eac867f3c1e6aaca9", "best_bid": "0.987", "best_ask": "0.988"}], "timestamp": "1769384068338", "event_type": "price_change"}}
{"_local_timestamp": "2026-01-25T23:34:43.641307+00:00", "data": {"market": "0xa56434f3ea8fffc460fc1d7cb9cb6b65edabadb490593c795e22d90fe57d17f0", "price_changes": [{"asset_id": "59439039310742412354907293409831028082512392186247250574941418012522361318651", "price": "0.26", "size": "0", "side": "BUY", "hash": "4be9af0b6176dd36ed7a65935390f39ff102923b", "best_bid": "0.79", "best_ask": "0.91"}, {"asset_id": "93559682575679849377661192498326372065972403403118003982372243474989955649691", "price": "0.74", "size": "0", "side": "SELL", "hash": "2716b52074e804e537fa55c090c03f2155169f70", "best_bid": "0.09", "best_ask": "0.21"}], "timestamp": "1769384083548", "event_type": "price_change"}}
{"_local_timestamp": "2026-01-25T23:34:43.646241+00:00", "data": {"market": "0xa56434f3ea8fffc460fc1d7cb9cb6b65edabadb490593c795e22d90fe57d17f0", "price_changes": [{"asset_id": "59439039310742412354907293409831028082512392186247250574941418012522361318651", "price": "0.17", "size": "0", "side": "BUY", "hash": "4be9af0b6176dd36ed7a65935390f39ff102923b", "best_bid": "0.79", "best_ask": "0.91"}, {"asset_id": "93559682575679849377661192498326372065972403403118003982372243474989955649691", "price": "0.83", "size": "0", "side": "SELL", "hash": "2716b52074e804e537fa55c090c03f2155169f70", "best_bid": "0.09", "best_ask": "0.21"}], "timestamp": "1769384083548", "event_type": "price_change"}}
{"_local_timestamp": "2026-01-25T23:34:43.872493+00:00", "data": {"market": "0xa56434f3ea8fffc460fc1d7cb9cb6b65edabadb490593c795e22d90fe57d17f0", "price_changes": [{"asset_id": "59439039310742412354907293409831028082512392186247250574941418012522361318651", "price": "0.16", "size": "486.67", "side": "BUY", "hash": "de8ddb7c88c6ee53cb1ef92601e20ec0a043c7c0", "best_bid": "0.79", "best_ask": "0.91"}, {"asset_id": "93559682575679849377661192498326372065972403403118003982372243474989955649691", "price": "0.84", "size": "486.67", "side": "SELL", "hash": "322df3e22cdf1d934b368a1729adce1a3e6d14aa", "best_bid": "0.09", "best_ask": "0.21"}], "timestamp": "1769384083798", "event_type": "price_change"}}
{"_local_timestamp": "2026-01-25T23:35:09.036518+00:00", "data": {"market": "0xa56434f3ea8fffc460fc1d7cb9cb6b65edabadb490593c795e22d90fe57d17f0", "price_changes": [{"asset_id": "59439039310742412354907293409831028082512392186247250574941418012522361318651", "price": "0.75", "size": "50.66", "side": "BUY", "hash": "18f6835c1f03a33c46fc4c3209521a57924ed827", "best_bid": "0.79", "best_ask": "0.91"}, {"asset_id": "93559682575679849377661192498326372065972403403118003982372243474989955649691", "price": "0.25", "size": "50.66", "side": "SELL", "hash": "cf077116f53bb0d678985fe1ad465cd912796977", "best_bid": "0.09", "best_ask": "0.21"}], "timestamp": "1769384108970", "event_type": "price_change"}}
{"_local_timestamp": "2026-01-25T23:35:26.726704+00:00", "data": {"market": "0xa56434f3ea8fffc460fc1d7cb9cb6b65edabadb490593c795e22d90fe57d17f0", "price_changes": [{"asset_id": "59439039310742412354907293409831028082512392186247250574941418012522361318651", "price": "0.16", "size": "386.67", "side": "BUY", "hash": "e7bd1bc908d0ec92b8f3880a59a05faab4ca9b8f", "best_bid": "0.79", "best_ask": "0.91"}, {"asset_id": "93559682575679849377661192498326372065972403403118003982372243474989955649691", "price": "0.84", "size": "386.67", "side": "SELL", "hash": "aedd4d5a02306964d1d8280ba7a6f0af7f5a9398", "best_bid": "0.09", "best_ask": "0.21"}], "timestamp": "1769384126571", "event_type": "price_change"}}
{"_local_timestamp": "2026-01-25T23:35:27.053333+00:00", "data": {"market": "0xa56434f3ea8fffc460fc1d7cb9cb6b65edabadb490593c795e22d90fe57d17f0", "price_changes": [{"asset_id": "59439039310742412354907293409831028082512392186247250574941418012522361318651", "price": "0.17", "size": "100", "side": "BUY", "hash": "ed6f37a0cf7e9ce0c7a8b7196cc9d8fc2539a2d3", "best_bid": "0.79", "best_ask": "0.91"}, {"asset_id": "93559682575679849377661192498326372065972403403118003982372243474989955649691", "price": "0.83", "size": "100", "side": "SELL", "hash": "029b359f4c31b52e68e137e290693a2f43604447", "best_bid": "0.09", "best_ask": "0.21"}], "timestamp": "1769384126886", "event_type": "price_change"}}
{"_local_timestamp": "2026-01-25T23:35:38.790175+00:00", "data": {"market": "0xa56434f3ea8fffc460fc1d7cb9cb6b65edabadb490593c795e22d90fe57d17f0", "price_changes": [{"asset_id": "59439039310742412354907293409831028082512392186247250574941418012522361318651", "price": "0.05", "size": "4080", "side": "BUY", "hash": "cbaf7808262575a34b8fd84061066765b660aacd", "best_bid": "0.79", "best_ask": "0.91"}, {"asset_id": "93559682575679849377661192498326372065972403403118003982372243474989955649691", "price": "0.95", "size": "4080", "side": "SELL", "hash": "97c01c82e0b2f0ac94fc59bea7ab33e5dc83c8ba", "best_bid": "0.09", "best_ask": "0.21"}], "timestamp": "1769384138688", "event_type": "price_change"}}
{"_local_timestamp": "2026-01-25T23:35:38.790636+00:00", "data": {"market": "0xa56434f3ea8fffc460fc1d7cb9cb6b65edabadb490593c795e22d90fe57d17f0", "price_changes": [{"asset_id": "59439039310742412354907293409831028082512392186247250574941418012522361318651", "price": "0.06", "size": "33", "side": "BUY", "hash": "cbaf7808262575a34b8fd84061066765b660aacd", "best_bid": "0.79", "best_ask": "0.91"}, {"asset_id": "93559682575679849377661192498326372065972403403118003982372243474989955649691", "price": "0.94", "size": "33", "side": "SELL", "hash": "97c01c82e0b2f0ac94fc59bea7ab33e5dc83c8ba", "best_bid": "0.09", "best_ask": "0.21"}], "timestamp": "1769384138688", "event_type": "price_change"}}
{"_local_timestamp": "2026-01-25T23:36:02.701462+00:00", "data": {"market": "0xa56434f3ea8fffc460fc1d7cb9cb6b65edabadb490593c795e22d90fe57d17f0", "price_changes": [{"asset_id": "59439039310742412354907293409831028082512392186247250574941418012522361318651", "price": "0.26", "size": "50", "side": "BUY", "hash": "8e9b03186628a4cc51f3c07b9d706a6a2663f341", "best_bid": "0.79", "best_ask": "0.91"}, {"asset_id": "93559682575679849377661192498326372065972403403118003982372243474989955649691", "price": "0.74", "size": "50", "side": "SELL", "hash": "53a114a471d5d72a43dd0c5945dd02bf77e85501", "best_bid": "0.09", "best_ask": "0.21"}], "timestamp": "1769384162608", "event_type": "price_change"}}
{"_local_timestamp": "2026-01-25T23:36:55.140293+00:00", "data": {"market": "0xa56434f3ea8fffc460fc1d7cb9cb6b65edabadb490593c795e22d90fe57d17f0", "price_changes": [{"asset_id": "59439039310742412354907293409831028082512392186247250574941418012522361318651", "price": "0.16", "size": "236.67", "side": "BUY", "hash": "aab3f9756ba54ca0a20c67d6d8938cdce1ba4882", "best_bid": "0.79", "best_ask": "0.91"}, {"asset_id": "93559682575679849377661192498326372065972403403118003982372243474989955649691", "price": "0.84", "size": "236.67", "side": "SELL", "hash": "346eb85a99b32cdcf86552beb05ea743db4c1854", "best_bid": "0.09", "best_ask": "0.21"}], "timestamp": "1769384215019", "event_type": "price_change"}}
{"_local_timestamp": "2026-01-25T23:36:55.186761+00:00", "data": {"market": "0xa56434f3ea8fffc460fc1d7cb9cb6b65edabadb490593c795e22d90fe57d17f0", "price_changes": [{"asset_id": "59439039310742412354907293409831028082512392186247250574941418012522361318651", "price": "0.15", "size": "2100", "side": "BUY", "hash": "6d461d2c0fb5b1b65e45613d305f807921e65452", "best_bid": "0.79", "best_ask": "0.91"}, {"asset_id": "93559682575679849377661192498326372065972403403118003982372243474989955649691", "price": "0.85", "size": "2100", "side": "SELL", "hash": "2ef3f2edf4a02da7a5bc329db36830aafe309380", "best_bid": "0.09", "best_ask": "0.21"}], "timestamp": "1769384215027", "event_type": "price_change"}}
{"_local_timestamp": "2026-01-25T23:36:55.187176+00:00", "data": {"market": "0xa56434f3ea8fffc460fc1d7cb9cb6b65edabadb490593c795e22d90fe57d17f0", "price_changes": [{"asset_id": "59439039310742412354907293409831028082512392186247250574941418012522361318651", "price": "0.05", "size": "3780", "side": "BUY", "hash": "6d461d2c0fb5b1b65e45613d305f807921e65452", "best_bid": "0.79", "best_ask": "0.91"}, {"asset_id": "93559682575679849377661192498326372065972403403118003982372243474989955649691", "price": "0.95", "size": "3780", "side": "SELL", "hash": "2ef3f2edf4a02da7a5bc329db36830aafe309380", "best_bid": "0.09", "best_ask": "0.21"}], "timestamp": "1769384215027", "event_type": "price_change"}}
{"_local_timestamp": "2026-01-25T23:36:55.187534+00:00", "data": {"market": "0xa56434f3ea8fffc460fc1d7cb9cb6b65edabadb490593c795e22d90fe57d17f0", "price_changes": [{"asset_id": "59439039310742412354907293409831028082512392186247250574941418012522361318651", "price": "0.23", "size": "225", "side": "BUY", "hash": "6d461d2c0fb5b1b65e45613d305f807921e65452", "best_bid": "0.79", "best_ask": "0.91"}, {"asset_id": "93559682575679849377661192498326372065972403403118003982372243474989955649691", "price": "0.77", "size": "225", "side": "SELL", "hash": "2ef3f2edf4a02da7a5bc329db36830aafe309380", "best_bid": "0.09", "best_ask": "0.21"}], "timestamp": "1769384215027", "event_type": "price_change"}}
{"_local_timestamp": "2026-01-25T23:36:57.714888+00:00", "data": {"market": "0xa56434f3ea8fffc460fc1d7cb9cb6b65edabadb490593c795e22d90fe57d17f0", "price_changes": [{"asset_id": "59439039310742412354907293409831028082512392186247250574941418012522361318651", "price": "0.23", "size": "100", "side": "BUY", "hash": "0e8bf223f490ea6b74652b54bbf0ba2446eb30a5", "best_bid": "0.79", "best_ask": "0.91"}, {"asset_id": "93559682575679849377661192498326372065972403403118003982372243474989955649691", "price": "0.77", "size": "100", "side": "SELL", "hash": "b3e4729529e8ffb54e39b7c330e6c3fc42c2df24", "best_bid": "0.09", "best_ask": "0.21"}], "timestamp": "1769384217246", "event_type": "price_change"}}
{"_local_timestamp": "2026-01-25T23:37:05.877913+00:00", "data": {"market": "0xa56434f3ea8fffc460fc1d7cb9cb6b65edabadb490593c795e22d90fe57d17f0", "price_changes": [{"asset_id": "59439039310742412354907293409831028082512392186247250574941418012522361318651", "price": "0.75", "size": "0", "side": "BUY", "hash": "b48751825f48e941a3abd959b87b1ecd54d88288", "best_bid": "0.79", "best_ask": "0.91"}, {"asset_id": "93559682575679849377661192498326372065972403403118003982372243474989955649691", "price": "0.25", "size": "0", "side": "SELL", "hash": "4e965d6d93763478c3d0749db4fe9e43927d9588", "best_bid": "0.09", "best_ask": "0.21"}], "timestamp": "1769384225808", "event_type": "price_change"}}
{"_local_timestamp": "2026-01-25T23:37:13.125090+00:00", "data": {"market": "0xa56434f3ea8fffc460fc1d7cb9cb6b65edabadb490593c795e22d90fe57d17f0", "price_changes": [{"asset_id": "59439039310742412354907293409831028082512392186247250574941418012522361318651", "price": "0.17", "size": "0", "side": "BUY", "hash": "a5104a42ca7f0ff84cdc1b207435d78c9da5b890", "best_bid": "0.79", "best_ask": "0.91"}, {"asset_id": "93559682575679849377661192498326372065972403403118003982372243474989955649691", "price": "0.83", "size": "0", "side": "SELL", "hash": "e6405ebcd0bafe451ef683d1601b82e4382c3921", "best_bid": "0.09", "best_ask": "0.21"}], "timestamp": "1769384233012", "event_type": "price_change"}}
{"_local_timestamp": "2026-01-25T23:37:13.467808+00:00", "data": {"market": "0xa56434f3ea8fffc460fc1d7cb9cb6b65edabadb490593c795e22d90fe57d17f0", "price_changes": [{"asset_id": "59439039310742412354907293409831028082512392186247250574941418012522361318651", "price": "0.16", "size": "336.67", "side": "BUY", "hash": "584e6d16871ef399bcdc7c11b9ffb1eef0f88845", "best_bid": "0.79", "best_ask": "0.91"}, {"asset_id": "93559682575679849377661192498326372065972403403118003982372243474989955649691", "price": "0.84", "size": "336.67", "side": "SELL", "hash": "08dc3e8454755d6982b0ebc5b00f177773d79dca", "best_bid": "0.09", "best_ask": "0.21"}], "timestamp": "1769384233358", "event_type": "price_change"}}
{"_local_timestamp": "2026-01-25T23:37:23.978048+00:00", "data": {"market": "0xa56434f3ea8fffc460fc1d7cb9cb6b65edabadb490593c795e22d90fe57d17f0", "price_changes": [{"asset_id": "59439039310742412354907293409831028082512392186247250574941418012522361318651", "price": "0.27", "size": "0", "side": "BUY", "hash": "3a8cbbfd8f3fd16712f0180d4263c61ee2dd97c7", "best_bid": "0.79", "best_ask": "0.91"}, {"asset_id": "93559682575679849377661192498326372065972403403118003982372243474989955649691", "price": "0.73", "size": "0", "side": "SELL", "hash": "3404893ceb00b85d823ae3a9eefafb5654d3925e", "best_bid": "0.09", "best_ask": "0.21"}], "timestamp": "1769384243910", "event_type": "price_change"}}
{"_local_timestamp": "2026-01-25T23:37:24.025328+00:00", "data": {"market": "0xa56434f3ea8fffc460fc1d7cb9cb6b65edabadb490593c795e22d90fe57d17f0", "price_changes": [{"asset_id": "59439039310742412354907293409831028082512392186247250574941418012522361318651", "price": "0.27", "size": "7", "side": "BUY", "hash": "fd5bca4f8f532f79a10c96f671a63bf213b346a7", "best_bid": "0.79", "best_ask": "0.91"}, {"asset_id": "93559682575679849377661192498326372065972403403118003982372243474989955649691", "price": "0.73", "size": "7", "side": "SELL", "hash": "686d7975ac1bc9efc872cdcf3f5469c846a43e0c", "best_bid": "0.09", "best_ask": "0.21"}], "timestamp": "1769384243959", "event_type": "price_change"}}
{"_local_timestamp": "2026-01-25T23:37:25.201132+00:00", "data": {"market": "0xa56434f3ea8fffc460fc1d7cb9cb6b65edabadb490593c795e22d90fe57d17f0", "price_changes": [{"asset_id": "59439039310742412354907293409831028082512392186247250574941418012522361318651", "price": "0.24", "size": "162", "side": "BUY", "hash": "acce4cc98f0727a5c3a4180d7f5620ff8e072b3d", "best_bid": "0.79", "best_ask": "0.91"}, {"asset_id": "93559682575679849377661192498326372065972403403118003982372243474989955649691", "price": "0.76", "size": "162", "side": "SELL", "hash": "343ab640b494dd91ae6246a29e85cdff1e2ec942", "best_bid": "0.09", "best_ask": "0.21"}], "timestamp": "1769384245133", "event_type": "price_change"}}
{"_local_timestamp": "2026-01-25T23:37:33.040809+00:00", "data": {"market": "0xa56434f3ea8fffc460fc1d7cb9cb6b65edabadb490593c795e22d90fe57d17f0", "price_changes": [{"asset_id": "59439039310742412354907293409831028082512392186247250574941418012522361318651", "price": "0.05", "size": "4180", "side": "BUY", "hash": "90fc1c91c7c5ccdeb21199b48bdae4f5612d9f47", "best_bid": "0.79", "best_ask": "0.91"}, {"asset_id": "93559682575679849377661192498326372065972403403118003982372243474989955649691", "price": "0.95", "size": "4180", "side": "SELL", "hash": "92bf987f4a872a4e29de13e32c660e0d2178922b", "best_bid": "0.09", "best_ask": "0.21"}], "timestamp": "1769384252895", "event_type": "price_change"}}
{"_local_timestamp": "2026-01-25T23:37:33.065306+00:00", "data": {"market": "0xa56434f3ea8fffc460fc1d7cb9cb6b65edabadb490593c795e22d90fe57d17f0", "price_changes": [{"asset_id": "59439039310742412354907293409831028082512392186247250574941418012522361318651", "price": "0.06", "size": "233", "side": "BUY", "hash": "2a24524bfbe6e47ce01c22b279f9fdd6f188c12a", "best_bid": "0.79", "best_ask": "0.91"}, {"asset_id": "93559682575679849377661192498326372065972403403118003982372243474989955649691", "price": "0.94", "size": "233", "side": "SELL", "hash": "366e2a4a61cf3d98a0b3b75d0d2cd6a9a80c8275", "best_bid": "0.09", "best_ask": "0.21"}], "timestamp": "1769384252907", "event_type": "price_change"}}
{"_local_timestamp": "2026-01-25T23:38:03.758274+00:00", "data": {"market": "0xa56434f3ea8fffc460fc1d7cb9cb6b65edabadb490593c795e22d90fe57d17f0", "price_changes": [{"asset_id": "59439039310742412354907293409831028082512392186247250574941418012522361318651", "price": "0.23", "size": "0", "side": "BUY", "hash": "2425b3144ffd8eae8b793b48532060b4f968357a", "best_bid": "0.79", "best_ask": "0.91"}, {"asset_id": "93559682575679849377661192498326372065972403403118003982372243474989955649691", "price": "0.77", "size": "0", "side": "SELL", "hash": "9314b6ef7a1bed696079fe94c7d747884f824c8c", "best_bid": "0.09", "best_ask": "0.21"}], "timestamp": "1769384283683", "event_type": "price_change"}}
{"_local_timestamp": "2026-01-25T23:38:03.761934+00:00", "data": {"market": "0xa56434f3ea8fffc460fc1d7cb9cb6b65edabadb490593c795e22d90fe57d17f0", "price_changes": [{"asset_id": "59439039310742412354907293409831028082512392186247250574941418012522361318651", "price": "0.26", "size": "0", "side": "BUY", "hash": "2425b3144ffd8eae8b793b48532060b4f968357a", "best_bid": "0.79", "best_ask": "0.91"}, {"asset_id": "93559682575679849377661192498326372065972403403118003982372243474989955649691", "price": "0.74", "size": "0", "side": "SELL", "hash": "9314b6ef7a1bed696079fe94c7d747884f824c8c", "best_bid": "0.09", "best_ask": "0.21"}], "timestamp": "1769384283683", "event_type": "price_change"}}
{"_local_timestamp": "2026-01-25T23:38:08.020807+00:00", "data": {"market": "0x0dcb82c1f435a34fd6f80b0ed6ac98e96125e347d50c258426e5c9600e085661", "price_changes": [{"asset_id": "23971807630734160157347033369840060495008877902009661072297332891205643761964", "price": "0.002", "size": "8166", "side": "BUY", "hash": "f0d1a523087cbcb6a9c7e72b6946fd6c29907424", "best_bid": "0.012", "best_ask": "0.013"}, {"asset_id": "25786306769392419954082257849170188721482659475898153836815032693554224565734", "price": "0.998", "size": "8166", "side": "SELL", "hash": "cca9b156ff3f8d09ad28b432f35bd3c11d1e99da", "best_bid": "0.987", "best_ask": "0.988"}], "timestamp": "1769384287945", "event_type": "price_change"}}
{"_local_timestamp": "2026-01-25T23:38:08.021291+00:00", "data": {"market": "0x0dcb82c1f435a34fd6f80b0ed6ac98e96125e347d50c258426e5c9600e085661", "price_changes": [{"asset_id": "23971807630734160157347033369840060495008877902009661072297332891205643761964", "price": "0.003", "size": "3000", "side": "BUY", "hash": "f0d1a523087cbcb6a9c7e72b6946fd6c29907424", "best_bid": "0.012", "best_ask": "0.013"}, {"asset_id": "25786306769392419954082257849170188721482659475898153836815032693554224565734", "price": "0.997", "size": "3000", "side": "SELL", "hash": "cca9b156ff3f8d09ad28b432f35bd3c11d1e99da", "best_bid": "0.987", "best_ask": "0.988"}], "timestamp": "1769384287945", "event_type": "price_change"}}
{"_local_timestamp": "2026-01-25T23:38:08.021700+00:00", "data": {"market": "0x0dcb82c1f435a34fd6f80b0ed6ac98e96125e347d50c258426e5c9600e085661", "price_changes": [{"asset_id": "23971807630734160157347033369840060495008877902009661072297332891205643761964", "price": "0.004", "size": "250", "side": "BUY", "hash": "f0d1a523087cbcb6a9c7e72b6946fd6c29907424", "best_bid": "0.012", "best_ask": "0.013"}, {"asset_id": "25786306769392419954082257849170188721482659475898153836815032693554224565734", "price": "0.996", "size": "250", "side": "SELL", "hash": "cca9b156ff3f8d09ad28b432f35bd3c11d1e99da", "best_bid": "0.987", "best_ask": "0.988"}], "timestamp": "1769384287945", "event_type": "price_change"}}
{"_local_timestamp": "2026-01-25T23:38:08.259302+00:00", "data": {"market": "0x0dcb82c1f435a34fd6f80b0ed6ac98e96125e347d50c258426e5c9600e085661", "price_changes": [{"asset_id": "23971807630734160157347033369840060495008877902009661072297332891205643761964", "price": "0.003", "size": "3037.61", "side": "BUY", "hash": "13be47aa4ab6732b6e87f2ad4ab7b7f3c97bd879", "best_bid": "0.012", "best_ask": "0.013"}, {"asset_id": "25786306769392419954082257849170188721482659475898153836815032693554224565734", "price": "0.997", "size": "3037.61", "side": "SELL", "hash": "a1d59a1526949c84ab893339e0b46d5326b25bd4", "best_bid": "0.987", "best_ask": "0.988"}], "timestamp": "1769384288183", "event_type": "price_change"}}
{"_local_timestamp": "2026-01-25T23:38:08.259721+00:00", "data": {"market": "0x0dcb82c1f435a34fd6f80b0ed6ac98e96125e347d50c258426e5c9600e085661", "price_changes": [{"asset_id": "23971807630734160157347033369840060495008877902009661072297332891205643761964", "price": "0.004", "size": "278.06", "side": "BUY", "hash": "f9af5de90508e3e6eb3f7cd7c8f03e1c5c313585", "best_bid": "0.012", "best_ask": "0.013"}, {"asset_id": "25786306769392419954082257849170188721482659475898153836815032693554224565734", "price": "0.996", "size": "278.06", "side": "SELL", "hash": "3bed31cbb923ff2dda0949019eb71bf4d6fbdff5", "best_bid": "0.987", "best_ask": "0.988"}], "timestamp": "1769384288184", "event_type": "price_change"}}
{"_local_timestamp": "2026-01-25T23:38:08.260094+00:00", "data": {"market": "0x0dcb82c1f435a34fd6f80b0ed6ac98e96125e347d50c258426e5c9600e085661", "price_changes": [{"asset_id": "23971807630734160157347033369840060495008877902009661072297332891205643761964", "price": "0.002", "size": "8222.69", "side": "BUY", "hash": "70b9947a8413d005de150e9a6ed840297549db2a", "best_bid": "0.012", "best_ask": "0.013"}, {"asset_id": "25786306769392419954082257849170188721482659475898153836815032693554224565734", "price": "0.998", "size": "8222.69", "side": "SELL", "hash": "9b6ec68e8fa0ee9c0cc98ee33dfbe1a3d67a2912", "best_bid": "0.987", "best_ask": "0.988"}], "timestamp": "1769384288185", "event_type": "price_change"}}
{"_local_timestamp": "2026-01-25T23:38:08.858713+00:00", "data": {"market": "0xa56434f3ea8fffc460fc1d7cb9cb6b65edabadb490593c795e22d90fe57d17f0", "price_changes": [{"asset_id": "59439039310742412354907293409831028082512392186247250574941418012522361318651", "price": "0.48", "size": "0", "side": "BUY", "hash": "87dae4c207c2e6ccc4ee7258cebaa838c05dc822", "best_bid": "0.79", "best_ask": "0.91"}, {"asset_id": "93559682575679849377661192498326372065972403403118003982372243474989955649691", "price": "0.52", "size": "0", "side": "SELL", "hash": "49f44968fe7d937db4b685a57dd45f30d06a6dc4", "best_bid": "0.09", "best_ask": "0.21"}], "timestamp": "1769384288766", "event_type": "price_change"}}
{"_local_timestamp": "2026-01-25T23:38:08.859162+00:00", "data": {"market": "0xa56434f3ea8fffc460fc1d7cb9cb6b65edabadb490593c795e22d90fe57d17f0", "price_changes": [{"asset_id": "59439039310742412354907293409831028082512392186247250574941418012522361318651", "price": "0.16", "size": "250", "side": "BUY", "hash": "87dae4c207c2e6ccc4ee7258cebaa838c05dc822", "best_bid": "0.79", "best_ask": "0.91"}, {"asset_id": "93559682575679849377661192498326372065972403403118003982372243474989955649691", "price": "0.84", "size": "250", "side": "SELL", "hash": "49f44968fe7d937db4b685a57dd45f30d06a6dc4", "best_bid": "0.09", "best_ask": "0.21"}], "timestamp": "1769384288766", "event_type": "price_change"}}
{"_local_timestamp": "2026-01-25T23:38:09.770083+00:00", "data": {"market": "0xa56434f3ea8fffc460fc1d7cb9cb6b65edabadb490593c795e22d90fe57d17f0", "price_changes": [{"asset_id": "59439039310742412354907293409831028082512392186247250574941418012522361318651", "price": "0.16", "size": "423.34", "side": "BUY", "hash": "fe6e93fd77305e83a77ede0ff4b3fba04def9fda", "best_bid": "0.79", "best_ask": "0.91"}, {"asset_id": "93559682575679849377661192498326372065972403403118003982372243474989955649691", "price": "0.84", "size": "423.34", "side": "SELL", "hash": "d23ad813ad0bd63f14a69e400cef21622b6138fc", "best_bid": "0.09", "best_ask": "0.21"}], "timestamp": "1769384289665", "event_type": "price_change"}}
{"_local_timestamp": "2026-01-25T23:38:26.058157+00:00", "data": {"market": "0xa56434f3ea8fffc460fc1d7cb9cb6b65edabadb490593c795e22d90fe57d17f0", "price_changes": [{"asset_id": "59439039310742412354907293409831028082512392186247250574941418012522361318651", "price": "0.75", "size": "50.66", "side": "BUY", "hash": "328de4d2a6ee3496cfe7b5e74364471b4321913b", "best_bid": "0.79", "best_ask": "0.91"}, {"asset_id": "93559682575679849377661192498326372065972403403118003982372243474989955649691", "price": "0.25", "size": "50.66", "side": "SELL", "hash": "178588b5b59324c2326ddad31b982ae17991d437", "best_bid": "0.09", "best_ask": "0.21"}], "timestamp": "1769384305989", "event_type": "price_change"}}
{"_local_timestamp": "2026-01-25T23:38:41.511209+00:00", "data": {"market": "0xa56434f3ea8fffc460fc1d7cb9cb6b65edabadb490593c795e22d90fe57d17f0", "price_changes": [{"asset_id": "59439039310742412354907293409831028082512392186247250574941418012522361318651", "price": "0.15", "size": "1875", "side": "BUY", "hash": "ae791f259c08a65424f7822ceaa814173ee75095", "best_bid": "0.79", "best_ask": "0.91"}, {"asset_id": "93559682575679849377661192498326372065972403403118003982372243474989955649691", "price": "0.85", "size": "1875", "side": "SELL", "hash": "6170635467b333abb042f8ecd43009b27dcfb1a8", "best_bid": "0.09", "best_ask": "0.21"}], "timestamp": "1769384321397", "event_type": "price_change"}}
{"_local_timestamp": "2026-01-25T23:38:41.511698+00:00", "data": {"market": "0xa56434f3ea8fffc460fc1d7cb9cb6b65edabadb490593c795e22d90fe57d17f0", "price_changes": [{"asset_id": "59439039310742412354907293409831028082512392186247250574941418012522361318651", "price": "0.16", "size": "273.34", "side": "BUY", "hash": "ae791f259c08a65424f7822ceaa814173ee75095", "best_bid": "0.79", "best_ask": "0.91"}, {"asset_id": "93559682575679849377661192498326372065972403403118003982372243474989955649691", "price": "0.84", "size": "273.34", "side": "SELL", "hash": "6170635467b333abb042f8ecd43009b27dcfb1a8", "best_bid": "0.09", "best_ask": "0.21"}], "timestamp": "1769384321397", "event_type": "price_change"}}
{"_local_timestamp": "2026-01-25T23:38:58.457559+00:00", "data": {"market": "0xa56434f3ea8fffc460fc1d7cb9cb6b65edabadb490593c795e22d90fe57d17f0", "price_changes": [{"asset_id": "59439039310742412354907293409831028082512392186247250574941418012522361318651", "price": "0.15", "size": "1750", "side": "BUY", "hash": "84075fb70dd4d921bc2273dab12e66f0edeff42d", "best_bid": "0.79", "best_ask": "0.91"}, {"asset_id": "93559682575679849377661192498326372065972403403118003982372243474989955649691", "price": "0.85", "size": "1750", "side": "SELL", "hash": "dc4b249ad66e7f8903527e3721dba981911ee53d", "best_bid": "0.09", "best_ask": "0.21"}], "timestamp": "1769384338230", "event_type": "price_change"}}
{"_local_timestamp": "2026-01-25T23:38:58.458054+00:00", "data": {"market": "0xa56434f3ea8fffc460fc1d7cb9cb6b65edabadb490593c795e22d90fe57d17f0", "price_changes": [{"asset_id": "59439039310742412354907293409831028082512392186247250574941418012522361318651", "price": "0.16", "size": "173.34", "side": "BUY", "hash": "84075fb70dd4d921bc2273dab12e66f0edeff42d", "best_bid": "0.79", "best_ask": "0.91"}, {"asset_id": "93559682575679849377661192498326372065972403403118003982372243474989955649691", "price": "0.84", "size": "173.34", "side": "SELL", "hash": "dc4b249ad66e7f8903527e3721dba981911ee53d", "best_bid": "0.09", "best_ask": "0.21"}], "timestamp": "1769384338230", "event_type": "price_change"}}
{"_local_timestamp": "2026-01-25T23:39:16.807981+00:00", "data": {"market": "0xa56434f3ea8fffc460fc1d7cb9cb6b65edabadb490593c795e22d90fe57d17f0", "price_changes": [{"asset_id": "59439039310742412354907293409831028082512392186247250574941418012522361318651", "price": "0.06", "size": "33", "side": "BUY", "hash": "538207443b458f2c91f3d9adedc6e8c4bacdc48e", "best_bid": "0.79", "best_ask": "0.91"}, {"asset_id": "93559682575679849377661192498326372065972403403118003982372243474989955649691", "price": "0.94", "size": "33", "side": "SELL", "hash": "852ac7717e2e069ad542c996016f54121d6c6df9", "best_bid": "0.09", "best_ask": "0.21"}], "timestamp": "1769384356688", "event_type": "price_change"}}
{"_local_timestamp": "2026-01-25T23:39:16.838031+00:00", "data": {"market": "0xa56434f3ea8fffc460fc1d7cb9cb6b65edabadb490593c795e22d90fe57d17f0", "price_changes": [{"asset_id": "59439039310742412354907293409831028082512392186247250574941418012522361318651", "price": "0.05", "size": "3780", "side": "BUY", "hash": "8afd94b89a12b667c1538cda6cb7a551de09c8f9", "best_bid": "0.79", "best_ask": "0.91"}, {"asset_id": "93559682575679849377661192498326372065972403403118003982372243474989955649691", "price": "0.95", "size": "3780", "side": "SELL", "hash": "af8d0f68891246e0cd120152b4cc905125d3bb94", "best_bid": "0.09", "best_ask": "0.21"}], "timestamp": "1769384356694", "event_type": "price_change"}}
{"_local_timestamp": "2026-01-25T23:39:17.357501+00:00", "data": {"market": "0xa56434f3ea8fffc460fc1d7cb9cb6b65edabadb490593c795e22d90fe57d17f0", "price_changes": [{"asset_id": "59439039310742412354907293409831028082512392186247250574941418012522361318651", "price": "0.24", "size": "262", "side": "BUY", "hash": "c85f6128b151c65fa41add7d5a856248b1b6e4ed", "best_bid": "0.79", "best_ask": "0.91"}, {"asset_id": "93559682575679849377661192498326372065972403403118003982372243474989955649691", "price": "0.76", "size": "262", "side": "SELL", "hash": "68598caad8f106cdbba23d76109da804314d98cd", "best_bid": "0.09", "best_ask": "0.21"}], "timestamp": "1769384357174", "event_type": "price_change"}}
{"_local_timestamp": "2026-01-25T23:39:17.414536+00:00", "data": {"market": "0xa56434f3ea8fffc460fc1d7cb9cb6b65edabadb490593c795e22d90fe57d17f0", "price_changes": [{"asset_id": "59439039310742412354907293409831028082512392186247250574941418012522361318651", "price": "0.26", "size": "50", "side": "BUY", "hash": "c6e02bedb9af0f74849073e61b81f8ec00d1c889", "best_bid": "0.79", "best_ask": "0.91"}, {"asset_id": "93559682575679849377661192498326372065972403403118003982372243474989955649691", "price": "0.74", "size": "50", "side": "SELL", "hash": "d6bda396a754bf62e94e771386331c4c4ff2fe2f", "best_bid": "0.09", "best_ask": "0.21"}], "timestamp": "1769384357196", "event_type": "price_change"}}
{"_local_timestamp": "2026-01-25T23:39:17.425391+00:00", "data": {"market": "0xa56434f3ea8fffc460fc1d7cb9cb6b65edabadb490593c795e22d90fe57d17f0", "price_changes": [{"asset_id": "59439039310742412354907293409831028082512392186247250574941418012522361318651", "price": "0.16", "size": "323.34", "side": "BUY", "hash": "3710c83dd1a37d5a0036c03a8b529cbe9af9cd05", "best_bid": "0.79", "best_ask": "0.91"}, {"asset_id": "93559682575679849377661192498326372065972403403118003982372243474989955649691", "price": "0.84", "size": "323.34", "side": "SELL", "hash": "024f768d00803ec347e2a65dbf8b000514da510c", "best_bid": "0.09", "best_ask": "0.21"}], "timestamp": "1769384357216", "event_type": "price_change"}}
{"_local_timestamp": "2026-01-25T23:39:17.437371+00:00", "data": {"market": "0xa56434f3ea8fffc460fc1d7cb9cb6b65edabadb490593c795e22d90fe57d17f0", "price_changes": [{"asset_id": "59439039310742412354907293409831028082512392186247250574941418012522361318651", "price": "0.15", "size": "1975", "side": "BUY", "hash": "f71d85811635953ba0d83077a6c784f9a5770d98", "best_bid": "0.79", "best_ask": "0.91"}, {"asset_id": "93559682575679849377661192498326372065972403403118003982372243474989955649691", "price": "0.85", "size": "1975", "side": "SELL", "hash": "18c70663cc46df04d73f8f287926e70eacfa93d1", "best_bid": "0.09", "best_ask": "0.21"}], "timestamp": "1769384357219", "event_type": "price_change"}}
