{"_local_timestamp": "2026-01-25T23:40:33.349092+00:00", "data": [{"market": "0x10dc09c7fb32ce782e2f1f383eb84c2b5434281f488e6eb6651b2a7d91ac3d34", "asset_id": "2877673002297742223763034790345770068008096660059409706124696651087462401120", "timestamp": "1769384297032", "hash": "1c6ce08036ebbe45fe8ed1c34a549d2207c9c940", "bids": [{"price": "0.01", "size": "4515.58"}, {"price": "0.02", "size": "2550"}, {"price": "0.03", "size": "250"}, {"price": "0.04", "size": "507.05"}, {"price": "0.05", "size": "100"}, {"price": "0.1", "size": "250"}, {"price": "0.11", "size": "5.11"}, {"price": "0.15", "size": "475"}, {"price": "0.17", "size": "100"}, {"price": "0.18", "size": "156"}, {"price": "0.22", "size": "20"}, {"price": "0.23", "size": "8"}, {"price": "0.26", "size": "45"}, {"price": "0.35", "size": "100"}, {"price": "0.36", "size": "36.11"}, {"price": "0.37", "size": "29.72"}, {"price": "0.38", "size": "8.5"}, {"price": "0.39", "size": "45"}, {"price": "0.47", "size": "10"}, {"price": "0.52", "size": "7.99"}], "asks": [{"price": "0.99", "size": "10.77"}, {"price": "0.98", "size": "500"}, {"price": "0.97", "size": "11.97"}, {"price": "0.96", "size": "900"}, {"price": "0.94", "size": "566.66"}, {"price": "0.92", "size": "470"}, {"price": "0.91", "size": "200"}, {"price": "0.9", "size": "385.33"}, {"price": "0.88", "size": "216.66"}, {"price": "0.86", "size": "171.42"}, {"price": "0.85", "size": "85"}, {"price": "0.84", "size": "164.94"}, {"price": "0.8", "size": "108.98"}, {"price": "0.79", "size": "92.32"}, {"price": "0.78", "size": "8.5"}, {"price": "0.76", "size": "87.96"}, {"price": "0.74", "size": "4.48"}, {"price": "0.73", "size": "0.61"}, {"price": "0.72", "size": "94.94"}], "event_type": "book", "last_trade_price": ""}, {"market": "0x10dc09c7fb32ce782e2f1f383eb84c2b5434281f488e6eb6651b2a7d91ac3d34", "asset_id": "105233400859414924844071137932068265322197459969475638102195871238609459335708", "timestamp": "1769384297032", "hash": "9d34dd177a19015298d3eed49fd8e0f63b1e2e8e", "bids": [{"price": "0.01", "size": "10.77"}, {"price": "0.02", "size": "500"}, {"price": "0.03", "size": "11.97"}, {"price": "0.04", "size": "900"}, {"price": "0.06", "size": "566.66"}, {"price": "0.08", "size": "470"}, {"price": "0.09", "size": "200"}, {"price": "0.1", "size": "385.33"}, {"price": "0.12", "size": "216.66"}, {"price": "0.14", "size": "171.42"}, {"price": "0.15", "size": "85"}, {"price": "0.16", "size": "164.94"}, {"price": "0.2", "size": "108.98"}, {"price": "0.21", "size": "92.32"}, {"price": "0.22", "size": "8.5"}, {"price": "0.24", "size": "87.96"}, {"price": "0.26", "size": "4.48"}, {"price": "0.27", "size": "0.61"}, {"price": "0.28", "size": "94.94"}], "asks": [{"price": "0.99", "size": "4515.58"}, {"price": "0.98", "size": "2550"}, {"price": "0.97", "size": "250"}, {"price": "0.96", "size": "507.05"}, {"price": "0.95", "size": "100"}, {"price": "0.9", "size": "250"}, {"price": "0.89", "size": "5.11"}, {"price": "0.85", "size": "475"}, {"price": "0.83", "size": "100"}, {"price": "0.82", "size": "156"}, {"price": "0.78", "size": "20"}, {"price": "0.77", "size": "8"}, {"price": "0.74", "size": "45"}, {"price": "0.65", "size": "100"}, {"price": "0.64", "size": "36.11"}, {"price": "0.63", "size": "29.72"}, {"price": "0.62", "size": "8.5"}, {"price": "0.61", "size": "45"}, {"price": "0.53", "size": "10"}, {"price": "0.48", "size": "7.99"}], "event_type": "book", "last_trade_price": ""}]}
{"_local_timestamp": "2026-01-25T23:41:29.634415+00:00", "data": {"market": "0x10dc09c7fb32ce782e2f1f383eb84c2b5434281f488e6eb6651b2a7d91ac3d34", "price_changes": [{"asset_id": "105233400859414924844071137932068265322197459969475638102195871238609459335708", "price": "0.48", "size": "0", "side": "SELL", "hash": "8c727dd5e41d6653bfd1b63fc3b03ad070ca97f7", "best_bid": "0.28", "best_ask": "0.53"}, {"asset_id": "2877673002297742223763034790345770068008096660059409706124696651087462401120", "price": "0.52", "size": "0", "side": "BUY", "hash": "aa912d9cccdf6aa83cf345563815cf41abdabbf7", "best_bid": "0.47", "best_ask": "0.72"}], "timestamp": "1769384489500", "event_type": "price_change"}}
{"_local_timestamp": "2026-01-25T23:41:36.845447+00:00", "data": {"market": "0x10dc09c7fb32ce782e2f1f383eb84c2b5434281f488e6eb6651b2a7d91ac3d34", "price_changes": [{"asset_id": "105233400859414924844071137932068265322197459969475638102195871238609459335708", "price": "0.52", "size": "7.99", "side": "SELL", "hash": "bdae9ae449f8eadb4830f80c6bda5e84eb99fec3", "best_bid": "0.28", "best_ask": "0.52"}, {"asset_id": "2877673002297742223763034790345770068008096660059409706124696651087462401120", "price": "0.48", "size": "7.99", "side": "BUY", "hash": "d26abb42d39a44735e18f0259aad34832668015c", "best_bid": "0.48", "best_ask": "0.72"}], "timestamp": "1769384496718", "event_type": "price_change"}}
{"_local_timestamp": "2026-01-25T23:42:25.317547+00:00", "data": {"market": "0x10dc09c7fb32ce782e2f1f383eb84c2b5434281f488e6eb6651b2a7d91ac3d34", "price_changes": [{"asset_id": "2877673002297742223763034790345770068008096660059409706124696651087462401120", "price": "0.35", "size": "0", "side": "BUY", "hash": "25dd12e0f6362dd0ca217815d49f2f29cf995e38", "best_bid": "0.48", "best_ask": "0.72"}, {"asset_id": "105233400859414924844071137932068265322197459969475638102195871238609459335708", "price": "0.65", "size": "0", "side": "SELL", "hash": "f8dde488a1cc604567c88c000f4fb012dd9b1440", "best_bid": "0.28", "best_ask": "0.52"}], "timestamp": "1769384545220", "event_type": "price_change"}}
{"_local_timestamp": "2026-01-25T23:42:25.318566+00:00", "data": {"market": "0x10dc09c7fb32ce782e2f1f383eb84c2b5434281f488e6eb6651b2a7d91ac3d34", "price_changes": [{"asset_id": "2877673002297742223763034790345770068008096660059409706124696651087462401120", "price": "0.17", "size": "0", "side": "BUY", "hash": "25dd12e0f6362dd0ca217815d49f2f29cf995e38", "best_bid": "0.48", "best_ask": "0.72"}, {"asset_id": "105233400859414924844071137932068265322197459969475638102195871238609459335708", "price": "0.83", "size": "0", "side": "SELL", "hash": "f8dde488a1cc604567c88c000f4fb012dd9b1440", "best_bid": "0.28", "best_ask": "0.52"}], "timestamp": "1769384545220", "event_type": "price_change"}}
{"_local_timestamp": "2026-01-25T23:42:26.208861+00:00", "data": {"market": "0x10dc09c7fb32ce782e2f1f383eb84c2b5434281f488e6eb6651b2a7d91ac3d34", "price_changes": [{"asset_id": "2877673002297742223763034790345770068008096660059409706124696651087462401120", "price": "0.32", "size": "66.66", "side": "BUY", "hash": "f1b857c7428f34ee73868aa0e62b18753cc0f9cb", "best_bid": "0.48", "best_ask": "0.72"}, {"asset_id": "105233400859414924844071137932068265322197459969475638102195871238609459335708", "price": "0.68", "size": "66.66", "side": "SELL", "hash": "bf2edb27d3e1f2fb4d7fcedfca44d30736fd7869", "best_bid": "0.28", "best_ask": "0.52"}], "timestamp": "1769384546052", "event_type": "price_change"}}
{"_local_timestamp": "2026-01-25T23:42:26.216144+00:00", "data": {"market": "0x10dc09c7fb32ce782e2f1f383eb84c2b5434281f488e6eb6651b2a7d91ac3d34", "price_changes": [{"asset_id": "2877673002297742223763034790345770068008096660059409706124696651087462401120", "price": "0.16", "size": "66.66", "side": "BUY", "hash": "d64dfe98ec6d6fb96346b979038565868779bda9", "best_bid": "0.48", "best_ask": "0.72"}, {"asset_id": "105233400859414924844071137932068265322197459969475638102195871238609459335708", "price": "0.84", "size": "66.66", "side": "SELL", "hash": "0d593db5cbf5cea92fb723eeabb763ac17fbfb2e", "best_bid": "0.28", "best_ask": "0.52"}], "timestamp": "1769384546083", "event_type": "price_change"}}
{"_local_timestamp": "2026-01-25T23:42:26.224840+00:00", "data": {"market": "0x10dc09c7fb32ce782e2f1f383eb84c2b5434281f488e6eb6651b2a7d91ac3d34", "price_changes": [{"asset_id": "2877673002297742223763034790345770068008096660059409706124696651087462401120", "price": "0.49", "size": "66.66", "side": "BUY", "hash": "1193e9d5f667e409bc0faea7fcfe5e75c839875b", "best_bid": "0.49", "best_ask": "0.72"}, {"asset_id": "105233400859414924844071137932068265322197459969475638102195871238609459335708", "price": "0.51", "size": "66.66", "side": "SELL", "hash": "fd643e7ec99756632f707ae108f82f4bd94eb569", "best_bid": "0.28", "best_ask": "0.51"}], "timestamp": "1769384546134", "event_type": "price_change"}}
{"_local_timestamp": "2026-01-25T23:42:59.186823+00:00", "data": {"market": "0x10dc09c7fb32ce782e2f1f383eb84c2b5434281f488e6eb6651b2a7d91ac3d34", "price_changes": [{"asset_id": "2877673002297742223763034790345770068008096660059409706124696651087462401120", "price": "0.18", "size": "306", "side": "BUY", "hash": "429916fe610a6a2e1427db7a33cd121d8e6d14dd", "best_bid": "0.49", "best_ask": "0.72"}, {"asset_id": "105233400859414924844071137932068265322197459969475638102195871238609459335708", "price": "0.82", "size": "306", "side": "SELL", "hash": "c143393013b1f3cc5b27687d59aea8d68ce1d7bb", "best_bid": "0.28", "best_ask": "0.51"}], "timestamp": "1769384578979", "event_type": "price_change"}}
{"_local_timestamp": "2026-01-25T23:42:59.196664+00:00", "data": {"market": "0x10dc09c7fb32ce782e2f1f383eb84c2b5434281f488e6eb6651b2a7d91ac3d34", "price_changes": [{"asset_id": "2877673002297742223763034790345770068008096660059409706124696651087462401120", "price": "0.21", "size": "100", "side": "BUY", "hash": "1007021e898edc6ca834b77ba1aaeb3f41e320e2", "best_bid": "0.49", "best_ask": "0.72"}, {"asset_id": "105233400859414924844071137932068265322197459969475638102195871238609459335708", "price": "0.79", "size": "100", "side": "SELL", "hash": "8cd3437c2bac3a3c505598e0a8a7fe1e1f1c734a", "best_bid": "0.28", "best_ask": "0.51"}], "timestamp": "1769384578981", "event_type": "price_change"}}
{"_local_timestamp": "2026-01-25T23:43:09.194006+00:00", "data": {"market": "0x10dc09c7fb32ce782e2f1f383eb84c2b5434281f488e6eb6651b2a7d91ac3d34", "price_changes": [{"asset_id": "2877673002297742223763034790345770068008096660059409706124696651087462401120", "price": "0.01", "size": "2015.58", "side": "BUY", "hash": "1a2a2ff12fc47fbebe9f8b6445515f9bf4e12b9f", "best_bid": "0.49", "best_ask": "0.72"}, {"asset_id": "105233400859414924844071137932068265322197459969475638102195871238609459335708", "price": "0.99", "size": "2015.58", "side": "SELL", "hash": "2b8af1e179ad5eb51033cc37445a5c2b2bd8aec0", "best_bid": "0.28", "best_ask": "0.51"}], "timestamp": "1769384589054", "event_type": "price_change"}}
{"_local_timestamp": "2026-01-25T23:43:09.194673+00:00", "data": {"market": "0x10dc09c7fb32ce782e2f1f383eb84c2b5434281f488e6eb6651b2a7d91ac3d34", "price_changes": [{"asset_id": "2877673002297742223763034790345770068008096660059409706124696651087462401120", "price": "0.02", "size": "1750", "side": "BUY", "hash": "1a2a2ff12fc47fbebe9f8b6445515f9bf4e12b9f", "best_bid": "0.49", "best_ask": "0.72"}, {"asset_id": "105233400859414924844071137932068265322197459969475638102195871238609459335708", "price": "0.98", "size": "1750", "side": "SELL", "hash": "2b8af1e179ad5eb51033cc37445a5c2b2bd8aec0", "best_bid": "0.28", "best_ask": "0.51"}], "timestamp": "1769384589054", "event_type": "price_change"}}
{"_local_timestamp": "2026-01-25T23:43:09.195000+00:00", "data": {"market": "0x10dc09c7fb32ce782e2f1f383eb84c2b5434281f488e6eb6651b2a7d91ac3d34", "price_changes": [{"asset_id": "2877673002297742223763034790345770068008096660059409706124696651087462401120", "price": "0.18", "size": "256", "side": "BUY", "hash": "1a2a2ff12fc47fbebe9f8b6445515f9bf4e12b9f", "best_bid": "0.49", "best_ask": "0.72"}, {"asset_id": "105233400859414924844071137932068265322197459969475638102195871238609459335708", "price": "0.82", "size": "256", "side": "SELL", "hash": "2b8af1e179ad5eb51033cc37445a5c2b2bd8aec0", "best_bid": "0.28", "best_ask": "0.51"}], "timestamp": "1769384589054", "event_type": "price_change"}}
{"_local_timestamp": "2026-01-25T23:43:52.707707+00:00", "data": {"market": "0x10dc09c7fb32ce782e2f1f383eb84c2b5434281f488e6eb6651b2a7d91ac3d34", "price_changes": [{"asset_id": "2877673002297742223763034790345770068008096660059409706124696651087462401120", "price": "0.01", "size": "4515.58", "side": "BUY", "hash": "105ffecf4110e32d98fc99605ee749447b4b4bc3", "best_bid": "0.49", "best_ask": "0.72"}, {"asset_id": "105233400859414924844071137932068265322197459969475638102195871238609459335708", "price": "0.99", "size": "4515.58", "side": "SELL", "hash": "03c26442a7d6a0ddd7e55d1d981f53f23c08021b", "best_bid": "0.28", "best_ask": "0.51"}], "timestamp": "1769384632638", "event_type": "price_change"}}
{"_local_timestamp": "2026-01-25T23:44:35.864423+00:00", "data": {"market": "0x10dc09c7fb32ce782e2f1f383eb84c2b5434281f488e6eb6651b2a7d91ac3d34", "price_changes": [{"asset_id": "2877673002297742223763034790345770068008096660059409706124696651087462401120", "price": "0.01", "size": "5515.58", "side": "BUY", "hash": "496d18585e4826d850ae4b58caa9e72b6929abc8", "best_bid": "0.49", "best_ask": "0.72"}, {"asset_id": "105233400859414924844071137932068265322197459969475638102195871238609459335708", "price": "0.99", "size": "5515.58", "side": "SELL", "hash": "8d509c60bde4788f9d862b7787577196bdfbee6c", "best_bid": "0.28", "best_ask": "0.51"}], "timestamp": "1769384675791", "event_type": "price_change"}}
{"_local_timestamp": "2026-01-25T23:44:35.870097+00:00", "data": {"market": "0x10dc09c7fb32ce782e2f1f383eb84c2b5434281f488e6eb6651b2a7d91ac3d34", "price_changes": [{"asset_id": "2877673002297742223763034790345770068008096660059409706124696651087462401120", "price": "0.02", "size": "2150", "side": "BUY", "hash": "aff072cc99c348439ac2e0ccb909350c3b41978e", "best_bid": "0.49", "best_ask": "0.72"}, {"asset_id": "105233400859414924844071137932068265322197459969475638102195871238609459335708", "price": "0.98", "size": "2150", "side": "SELL", "hash": "7733d796d7c0cfc8a3751d4f8656d41894611aea", "best_bid": "0.28", "best_ask": "0.51"}], "timestamp": "1769384675794", "event_type": "price_change"}}
{"_local_timestamp": "2026-01-25T23:44:55.981448+00:00", "data": {"market": "0x10dc09c7fb32ce782e2f1f383eb84c2b5434281f488e6eb6651b2a7d91ac3d34", "price_changes": [{"asset_id": "2877673002297742223763034790345770068008096660059409706124696651087462401120", "price": "0.01", "size": "4515.58", "side": "BUY", "hash": "504d40b7aa1a5f7cd320a29bb6536d980d341f86", "best_bid": "0.49", "best_ask": "0.72"}, {"asset_id": "105233400859414924844071137932068265322197459969475638102195871238609459335708", "price": "0.99", "size": "4515.58", "side": "SELL", "hash": "b006b5302783b124245e3fff4cdb201aac11cac8", "best_bid": "0.28", "best_ask": "0.51"}], "timestamp": "1769384695893", "event_type": "price_change"}}
{"_local_timestamp": "2026-01-25T23:45:56.567194+00:00", "data": {"market": "0x10dc09c7fb32ce782e2f1f383eb84c2b5434281f488e6eb6651b2a7d91ac3d34", "price_changes": [{"asset_id": "2877673002297742223763034790345770068008096660059409706124696651087462401120", "price": "0.18", "size": "150", "side": "BUY", "hash": "7e77c63944292b92017a8fbf70c4dca0fd01a878", "best_bid": "0.49", "best_ask": "0.72"}, {"asset_id": "105233400859414924844071137932068265322197459969475638102195871238609459335708", "price": "0.82", "size": "150", "side": "SELL", "hash": "0129a3d08c5ff7c54b8fe97668fbca319e83446f", "best_bid": "0.28", "best_ask": "0.51"}], "timestamp": "1769384756089", "event_type": "price_change"}}
{"_local_timestamp": "2026-01-25T23:46:10.222806+00:00", "data": {"market": "0x10dc09c7fb32ce782e2f1f383eb84c2b5434281f488e6eb6651b2a7d91ac3d34", "price_changes": [{"asset_id": "2877673002297742223763034790345770068008096660059409706124696651087462401120", "price": "0.22", "size": "70", "side": "BUY", "hash": "be3866818ff3bffdbe776292bb889ee6856f095d", "best_bid": "0.49", "best_ask": "0.72"}, {"asset_id": "105233400859414924844071137932068265322197459969475638102195871238609459335708", "price": "0.78", "size": "70", "side": "SELL", "hash": "0d1c653932ce2e0b6551cb43c376161d7366a4cf", "best_bid": "0.28", "best_ask": "0.51"}], "timestamp": "1769384770147", "event_type": "price_change"}}
{"_local_timestamp": "2026-01-25T23:46:51.694560+00:00", "data": {"market": "0x10dc09c7fb32ce782e2f1f383eb84c2b5434281f488e6eb6651b2a7d91ac3d34", "price_changes": [{"asset_id": "2877673002297742223763034790345770068008096660059409706124696651087462401120", "price": "0.01", "size": "4815.58", "side": "BUY", "hash": "01ef2aaf8387a36a7c113a5e706d74787047f385", "best_bid": "0.49", "best_ask": "0.72"}, {"asset_id": "105233400859414924844071137932068265322197459969475638102195871238609459335708", "price": "0.99", "size": "4815.58", "side": "SELL", "hash": "3fb800bce18c3fe0723e382fe5b8ba6d40081e97", "best_bid": "0.28", "best_ask": "0.51"}], "timestamp": "1769384811241", "event_type": "price_change"}}
{"_local_timestamp": "2026-01-25T23:46:58.995601+00:00", "data": {"market": "0x10dc09c7fb32ce782e2f1f383eb84c2b5434281f488e6eb6651b2a7d91ac3d34", "price_changes": [{"asset_id": "2877673002297742223763034790345770068008096660059409706124696651087462401120", "price": "0.18", "size": "0", "side": "BUY", "hash": "412d1efba457581a45db0b3a95fd5c2f50123459", "best_bid": "0.49", "best_ask": "0.72"}, {"asset_id": "105233400859414924844071137932068265322197459969475638102195871238609459335708", "price": "0.82", "size": "0", "side": "SELL", "hash": "08dc06f9dc2a32088d44d07f3fa74a5d6a80d140", "best_bid": "0.28", "best_ask": "0.51"}], "timestamp": "1769384818846", "event_type": "price_change"}}
{"_local_timestamp": "2026-01-25T23:46:58.996138+00:00", "data": {"market": "0x10dc09c7fb32ce782e2f1f383eb84c2b5434281f488e6eb6651b2a7d91ac3d34", "price_changes": [{"asset_id": "2877673002297742223763034790345770068008096660059409706124696651087462401120", "price": "0.21", "size": "0", "side": "BUY", "hash": "412d1efba457581a45db0b3a95fd5c2f50123459", "best_bid": "0.49", "best_ask": "0.72"}, {"asset_id": "105233400859414924844071137932068265322197459969475638102195871238609459335708", "price": "0.79", "size": "0", "side": "SELL", "hash": "08dc06f9dc2a32088d44d07f3fa74a5d6a80d140", "best_bid": "0.28", "best_ask": "0.51"}], "timestamp": "1769384818846", "event_type": "price_change"}}
{"_local_timestamp": "2026-01-25T23:46:59.403991+00:00", "data": {"market": "0x10dc09c7fb32ce782e2f1f383eb84c2b5434281f488e6eb6651b2a7d91ac3d34", "price_changes": [{"asset_id": "2877673002297742223763034790345770068008096660059409706124696651087462401120", "price": "0.22", "size": "170", "side": "BUY", "hash": "99845edb4fb48d87a44df83fa7da36375bb73d23", "best_bid": "0.49", "best_ask": "0.72"}, {"asset_id": "105233400859414924844071137932068265322197459969475638102195871238609459335708", "price": "0.78", "size": "170", "side": "SELL", "hash": "481b7fd170a7141db647643a155bca56c51ef8dd", "best_bid": "0.28", "best_ask": "0.51"}], "timestamp": "1769384819187", "event_type": "price_change"}}
{"_local_timestamp": "2026-01-25T23:46:59.404363+00:00", "data": {"market": "0x10dc09c7fb32ce782e2f1f383eb84c2b5434281f488e6eb6651b2a7d91ac3d34", "price_changes": [{"asset_id": "2877673002297742223763034790345770068008096660059409706124696651087462401120", "price": "0.16", "size": "216.66", "side": "BUY", "hash": "567fee3364ab4212d70250ca1a97e1ec976f62a2", "best_bid": "0.49", "best_ask": "0.72"}, {"asset_id": "105233400859414924844071137932068265322197459969475638102195871238609459335708", "price": "0.84", "size": "216.66", "side": "SELL", "hash": "9dd297fc5537add4f31f9981ce848ce3c60eeb5d", "best_bid": "0.28", "best_ask": "0.51"}], "timestamp": "1769384819238", "event_type": "price_change"}}
{"_local_timestamp": "2026-01-25T23:47:23.375626+00:00", "data": {"market": "0x10dc09c7fb32ce782e2f1f383eb84c2b5434281f488e6eb6651b2a7d91ac3d34", "price_changes": [{"asset_id": "2877673002297742223763034790345770068008096660059409706124696651087462401120", "price": "0.02", "size": "1150", "side": "BUY", "hash": "5c400f648d9dc3b5bc43cc696be3963d53ed1a45", "best_bid": "0.49", "best_ask": "0.72"}, {"asset_id": "105233400859414924844071137932068265322197459969475638102195871238609459335708", "price": "0.98", "size": "1150", "side": "SELL", "hash": "f94658d154d80ec4ddd9eeab89097c3251fd52ba", "best_bid": "0.28", "best_ask": "0.51"}], "timestamp": "1769384843177", "event_type": "price_change"}}
{"_local_timestamp": "2026-01-25T23:47:26.561093+00:00", "data": {"market": "0x10dc09c7fb32ce782e2f1f383eb84c2b5434281f488e6eb6651b2a7d91ac3d34", "price_changes": [{"asset_id": "2877673002297742223763034790345770068008096660059409706124696651087462401120", "price": "0.05", "size": "0", "side": "BUY", "hash": "c4146b3f5a08f02e003a591131542833d86ce09a", "best_bid": "0.49", "best_ask": "0.72"}, {"asset_id": "105233400859414924844071137932068265322197459969475638102195871238609459335708", "price": "0.95", "size": "0", "side": "SELL", "hash": "ce6f2528f74e26aee2f954129b273f2393c64fdc", "best_bid": "0.28", "best_ask": "0.51"}], "timestamp": "1769384846297", "event_type": "price_change"}}
{"_local_timestamp": "2026-01-25T23:47:45.950039+00:00", "data": {"market": "0x10dc09c7fb32ce782e2f1f383eb84c2b5434281f488e6eb6651b2a7d91ac3d34", "price_changes": [{"asset_id": "2877673002297742223763034790345770068008096660059409706124696651087462401120", "price": "0.02", "size": "1950", "side": "BUY", "hash": "ac57185759eeebd429193692aeea59e0c991b674", "best_bid": "0.49", "best_ask": "0.72"}, {"asset_id": "105233400859414924844071137932068265322197459969475638102195871238609459335708", "price": "0.98", "size": "1950", "side": "SELL", "hash": "7b397dfecb3f373a3bf034c0f33f359d0e57b0b0", "best_bid": "0.28", "best_ask": "0.51"}], "timestamp": "1769384865858", "event_type": "price_change"}}
