{"_local_timestamp": "2026-01-25T23:40:49.932744+00:00", "data": [{"market": "0x3b41890d5e8c9640649a9e6f724d1f74aa67af855506db6f871c5fdac70cfd90", "asset_id": "24393720551520374522532949229976185621516426573885698267923116722310834739486", "timestamp": "1769384430939", "hash": "44907972cd20435ac6828013d394ed0893bea23c", "bids": [{"price": "0.01", "size": "7810.27"}, {"price": "0.02", "size": "3400"}, {"price": "0.03", "size": "10.67"}, {"price": "0.04", "size": "500"}, {"price": "0.06", "size": "800"}, {"price": "0.08", "size": "425"}, {"price": "0.1", "size": "50"}, {"price": "0.11", "size": "296.14"}, {"price": "0.14", "size": "200"}, {"price": "0.15", "size": "1616"}, {"price": "0.17", "size": "152.94"}, {"price": "0.18", "size": "2332"}, {"price": "0.19", "size": "400"}, {"price": "0.2", "size": "125"}, {"price": "0.22", "size": "10390.9"}, {"price": "0.23", "size": "731"}, {"price": "0.25", "size": "300"}, {"price": "0.26", "size": "374"}, {"price": "0.28", "size": "50"}, {"price": "0.36", "size": "18.14"}, {"price": "0.37", "size": "100"}, {"price": "0.38", "size": "129.14"}, {"price": "0.42", "size": "4.99"}, {"price": "0.5", "size": "26"}, {"price": "0.52", "size": "53.15"}, {"price": "0.53", "size": "17"}, {"price": "0.57", "size": "200"}, {"price": "0.58", "size": "109"}, {"price": "0.59", "size": "504"}, {"price": "0.6", "size": "286.67"}], "asks": [{"price": "0.99", "size": "3059.39"}, {"price": "0.98", "size": "1000"}, {"price": "0.97", "size": "10.92"}, {"price": "0.96", "size": "1600"}, {"price": "0.93", "size": "485.71"}, {"price": "0.91", "size": "355.55"}, {"price": "0.9", "size": "55.78"}, {"price": "0.89", "size": "254.54"}, {"price": "0.88", "size": "3725"}, {"price": "0.87", "size": "310.16"}, {"price": "0.86", "size": "185.71"}, {"price": "0.84", "size": "300"}, {"price": "0.83", "size": "11"}, {"price": "0.82", "size": "111.11"}, {"price": "0.7", "size": "100"}, {"price": "0.69", "size": "41.93"}, {"price": "0.68", "size": "34.37"}, {"price": "0.67", "size": "100"}, {"price": "0.66", "size": "283"}, {"price": "0.65", "size": "100"}, {"price": "0.61", "size": "856"}], "event_type": "book", "last_trade_price": "0.600"}, {"market": "0xdd9f55a4a214da7231a64eb6f43a05f525b51e7bcf714db0c2d3b2fd0fc0c9ca", "asset_id": "87855193300342526755310181206520215785023964324419734896948555881922627101363", "timestamp": "1769384440598", "hash": "495e06f31823c9f4eeb35a0f02b7fef983621a23", "bids": [{"price": "0.01", "size": "113360.04"}, {"price": "0.02", "size": "5900"}, {"price": "0.03", "size": "8.21"}, {"price": "0.04", "size": "2250"}, {"price": "0.05", "size": "10"}, {"price": "0.07", "size": "514.28"}, {"price": "0.08", "size": "700"}, {"price": "0.1", "size": "340"}, {"price": "0.11", "size": "555.93"}, {"price": "0.16", "size": "10400"}, {"price": "0.17", "size": "250"}, {"price": "0.18", "size": "199.99"}, {"price": "0.23", "size": "150"}, {"price": "0.29", "size": "250"}, {"price": "0.39", "size": "575"}, {"price": "0.5", "size": "500"}, {"price": "0.51", "size": "33.42"}, {"price": "0.57", "size": "33.42"}, {"price": "0.58", "size": "250"}, {"price": "0.6", "size": "26.66"}, {"price": "0.61", "size": "18.03"}, {"price": "0.64", "size": "195"}, {"price": "0.65", "size": "33.42"}], "asks": [{"price": "0.99", "size": "66.66"}, {"price": "0.98", "size": "109.34"}, {"price": "0.96", "size": "33"}, {"price": "0.95", "size": "16.26"}, {"price": "0.88", "size": "66.66"}, {"price": "0.81", "size": "68.42"}, {"price": "0.8", "size": "55"}, {"price": "0.79", "size": "100"}, {"price": "0.76", "size": "91.66"}], "event_type": "book", "last_trade_price": "0.240"}, {"market": "0x3b41890d5e8c9640649a9e6f724d1f74aa67af855506db6f871c5fdac70cfd90", "asset_id": "88830742474573630269392959399954338068265843991617686189000213034050940973037", "timestamp": "1769384430939", "hash": "ac73d6015375ed161d4f7438e427c94f1ec976d1", "bids": [{"price": "0.01", "size": "3059.39"}, {"price": "0.02", "size": "1000"}, {"price": "0.03", "size": "10.92"}, {"price": "0.04", "size": "1600"}, {"price": "0.07", "size": "485.71"}, {"price": "0.09", "size": "355.55"}, {"price": "0.1", "size": "55.78"}, {"price": "0.11", "size": "254.54"}, {"price": "0.12", "size": "3725"}, {"price": "0.13", "size": "310.16"}, {"price": "0.14", "size": "185.71"}, {"price": "0.16", "size": "300"}, {"price": "0.17", "size": "11"}, {"price": "0.18", "size": "111.11"}, {"price": "0.3", "size": "100"}, {"price": "0.31", "size": "41.93"}, {"price": "0.32", "size": "34.37"}, {"price": "0.33", "size": "100"}, {"price": "0.34", "size": "283"}, {"price": "0.35", "size": "100"}, {"price": "0.39", "size": "856"}], "asks": [{"price": "0.99", "size": "7810.27"}, {"price": "0.98", "size": "3400"}, {"price": "0.97", "size": "10.67"}, {"price": "0.96", "size": "500"}, {"price": "0.94", "size": "800"}, {"price": "0.92", "size": "425"}, {"price": "0.9", "size": "50"}, {"price": "0.89", "size": "296.14"}, {"price": "0.86", "size": "200"}, {"price": "0.85", "size": "1616"}, {"price": "0.83", "size": "152.94"}, {"price": "0.82", "size": "2332"}, {"price": "0.81", "size": "400"}, {"price": "0.8", "size": "125"}, {"price": "0.78", "size": "10390.9"}, {"price": "0.77", "size": "731"}, {"price": "0.75", "size": "300"}, {"price": "0.74", "size": "374"}, {"price": "0.72", "size": "50"}, {"price": "0.64", "size": "18.14"}, {"price": "0.63", "size": "100"}, {"price": "0.62", "size": "129.14"}, {"price": "0.58", "size": "4.99"}, {"price": "0.5", "size": "26"}, {"price": "0.48", "size": "53.15"}, {"price": "0.47", "size": "17"}, {"price": "0.43", "size": "200"}, {"price": "0.42", "size": "109"}, {"price": "0.41", "size": "504"}, {"price": "0.4", "size": "286.67"}], "event_type": "book", "last_trade_price": "0.600"}, {"market": "0xdd9f55a4a214da7231a64eb6f43a05f525b51e7bcf714db0c2d3b2fd0fc0c9ca", "asset_id": "18582106713580348058065911013375325630183346495483834588274922531241537980162", "timestamp": "1769384440598", "hash": "7851e11af930c3d0348a5addd2e1b8f98c090961", "bids": [{"price": "0.01", "size": "66.66"}, {"price": "0.02", "size": "109.34"}, {"price": "0.04", "size": "33"}, {"price": "0.05", "size": "16.26"}, {"price": "0.12", "size": "66.66"}, {"price": "0.19", "size": "68.42"}, {"price": "0.2", "size": "55"}, {"price": "0.21", "size": "100"}, {"price": "0.24", "size": "91.66"}], "asks": [{"price": "0.99", "size": "113360.04"}, {"price": "0.98", "size": "5900"}, {"price": "0.97", "size": "8.21"}, {"price": "0.96", "size": "2250"}, {"price": "0.95", "size": "10"}, {"price": "0.93", "size": "514.28"}, {"price": "0.92", "size": "700"}, {"price": "0.9", "size": "340"}, {"price": "0.89", "size": "555.93"}, {"price": "0.84", "size": "10400"}, {"price": "0.83", "size": "250"}, {"price": "0.82", "size": "199.99"}, {"price": "0.77", "size": "150"}, {"price": "0.71", "size": "250"}, {"price": "0.61", "size": "575"}, {"price": "0.5", "size": "500"}, {"price": "0.49", "size": "33.42"}, {"price": "0.43", "size": "33.42"}, {"price": "0.42", "size": "250"}, {"price": "0.4", "size": "26.66"}, {"price": "0.39", "size": "18.03"}, {"price": "0.36", "size": "195"}, {"price": "0.35", "size": "33.42"}], "event_type": "book", "last_trade_price": "0.240"}]}
{"_local_timestamp": "2026-01-25T23:41:09.647698+00:00", "data": {"market": "0x3b41890d5e8c9640649a9e6f724d1f74aa67af855506db6f871c5fdac70cfd90", "price_changes": [{"asset_id": "24393720551520374522532949229976185621516426573885698267923116722310834739486", "price": "0.19", "size": "250", "side": "BUY", "hash": "05d428d9842a916529f30d411c362b5694b1b565", "best_bid": "0.6", "best_ask": "0.61"}, {"asset_id": "88830742474573630269392959399954338068265843991617686189000213034050940973037", "price": "0.81", "size": "250", "side": "SELL", "hash": "d3fa84c059a38136e5570a2037d466bec3c10626", "best_bid": "0.39", "best_ask": "0.4"}], "timestamp": "1769384469552", "event_type": "price_change"}}
{"_local_timestamp": "2026-01-25T23:41:09.921316+00:00", "data": {"market": "0x3b41890d5e8c9640649a9e6f724d1f74aa67af855506db6f871c5fdac70cfd90", "price_changes": [{"asset_id": "24393720551520374522532949229976185621516426573885698267923116722310834739486", "price": "0.18", "size": "2482", "side": "BUY", "hash": "e9cf7dd0aad52afd9f0dd35fb7afa1d671d370ff", "best_bid": "0.6", "best_ask": "0.61"}, {"asset_id": "88830742474573630269392959399954338068265843991617686189000213034050940973037", "price": "0.82", "size": "2482", "side": "SELL", "hash": "ddcd9624a21052172438fa9ef08198067f00dac8", "best_bid": "0.39", "best_ask": "0.4"}], "timestamp": "1769384469806", "event_type": "price_change"}}
{"_local_timestamp": "2026-01-25T23:41:42.547403+00:00", "data": {"market": "0xdd9f55a4a214da7231a64eb6f43a05f525b51e7bcf714db0c2d3b2fd0fc0c9ca", "price_changes": [{"asset_id": "87855193300342526755310181206520215785023964324419734896948555881922627101363", "price": "0.65", "size": "91.88", "side": "BUY", "hash": "12cc424ecc9228068cb282c71f0053e758de35c9", "best_bid": "0.65", "best_ask": "0.76"}, {"asset_id": "18582106713580348058065911013375325630183346495483834588274922531241537980162", "price": "0.35", "size": "91.88", "side": "SELL", "hash": "e9a51f90004b2da06a2afa94e967ff342d6cb3cb", "best_bid": "0.24", "best_ask": "0.35"}], "timestamp": "1769384502467", "event_type": "price_change"}}
{"_local_timestamp": "2026-01-25T23:41:43.320210+00:00", "data": {"market": "0xdd9f55a4a214da7231a64eb6f43a05f525b51e7bcf714db0c2d3b2fd0fc0c9ca", "price_changes": [{"asset_id": "87855193300342526755310181206520215785023964324419734896948555881922627101363", "price": "0.18", "size": "99.99", "side": "BUY", "hash": "a8e5082a550f0bf6ab0eb4f494dabbb3f3e2927b", "best_bid": "0.65", "best_ask": "0.76"}, {"asset_id": "18582106713580348058065911013375325630183346495483834588274922531241537980162", "price": "0.82", "size": "99.99", "side": "SELL", "hash": "03168fcc3c41e7fda2b862deec5180168eb68e98", "best_bid": "0.24", "best_ask": "0.35"}], "timestamp": "1769384503245", "event_type": "price_change"}}
{"_local_timestamp": "2026-01-25T23:41:44.038906+00:00", "data": {"market": "0xdd9f55a4a214da7231a64eb6f43a05f525b51e7bcf714db0c2d3b2fd0fc0c9ca", "price_changes": [{"asset_id": "87855193300342526755310181206520215785023964324419734896948555881922627101363", "price": "0.66", "size": "100", "side": "BUY", "hash": "93a168602abe8d200f1b174f844d2886b260a3f9", "best_bid": "0.66", "best_ask": "0.76"}, {"asset_id": "18582106713580348058065911013375325630183346495483834588274922531241537980162", "price": "0.34", "size": "100", "side": "SELL", "hash": "30e5244d243d9b76fac4e15a63f2949a5002b3b0", "best_bid": "0.24", "best_ask": "0.34"}], "timestamp": "1769384503969", "event_type": "price_change"}}
{"_local_timestamp": "2026-01-25T23:41:50.933088+00:00", "data": {"market": "0x3b41890d5e8c9640649a9e6f724d1f74aa67af855506db6f871c5fdac70cfd90", "price_changes": [{"asset_id": "24393720551520374522532949229976185621516426573885698267923116722310834739486", "price": "0.22", "size": "10290.9", "side": "BUY", "hash": "830b52f161a813d0cf803fcb36387a7eef6f1f5a", "best_bid": "0.6", "best_ask": "0.61"}, {"asset_id": "88830742474573630269392959399954338068265843991617686189000213034050940973037", "price": "0.78", "size": "10290.9", "side": "SELL", "hash": "ebe34bb8ae443b313144d8ffcfc5b5c15b7b6859", "best_bid": "0.39", "best_ask": "0.4"}], "timestamp": "1769384510759", "event_type": "price_change"}}
{"_local_timestamp": "2026-01-25T23:41:52.699762+00:00", "data": {"market": "0x3b41890d5e8c9640649a9e6f724d1f74aa67af855506db6f871c5fdac70cfd90", "price_changes": [{"asset_id": "24393720551520374522532949229976185621516426573885698267923116722310834739486", "price": "0.27", "size": "100", "side": "BUY", "hash": "5e07c6553f072ba09a0c49bfa5ddef797af8c0d4", "best_bid": "0.6", "best_ask": "0.61"}, {"asset_id": "88830742474573630269392959399954338068265843991617686189000213034050940973037", "price": "0.73", "size": "100", "side": "SELL", "hash": "982b2841d1b889560b30ce20e013fbcf7f5bd4bd", "best_bid": "0.39", "best_ask": "0.4"}], "timestamp": "1769384511763", "event_type": "price_change"}}
{"_local_timestamp": "2026-01-25T23:42:24.667363+00:00", "data": {"market": "0xdd9f55a4a214da7231a64eb6f43a05f525b51e7bcf714db0c2d3b2fd0fc0c9ca", "price_changes": [{"asset_id": "87855193300342526755310181206520215785023964324419734896948555881922627101363", "price": "0.29", "size": "200", "side": "BUY", "hash": "912057851ae95b771c38f1fd075fc1c6c30f478b", "best_bid": "0.66", "best_ask": "0.76"}, {"asset_id": "18582106713580348058065911013375325630183346495483834588274922531241537980162", "price": "0.71", "size": "200", "side": "SELL", "hash": "d57027b23236c31a9ef256b1ca90e3c8b806c50f", "best_bid": "0.24", "best_ask": "0.34"}], "timestamp": "1769384544486", "event_type": "price_change"}}
{"_local_timestamp": "2026-01-25T23:42:24.668757+00:00", "data": {"market": "0x3b41890d5e8c9640649a9e6f724d1f74aa67af855506db6f871c5fdac70cfd90", "price_changes": [{"asset_id": "24393720551520374522532949229976185621516426573885698267923116722310834739486", "price": "0.19", "size": "150", "side": "BUY", "hash": "05af16fc2a8c4f1b9128687571f6910022b2e834", "best_bid": "0.6", "best_ask": "0.61"}, {"asset_id": "88830742474573630269392959399954338068265843991617686189000213034050940973037", "price": "0.81", "size": "150", "side": "SELL", "hash": "6c02ac5e91630d1b1c86ed46166b9e8574c4234e", "best_bid": "0.39", "best_ask": "0.4"}], "timestamp": "1769384544486", "event_type": "price_change"}}
{"_local_timestamp": "2026-01-25T23:42:25.106320+00:00", "data": {"market": "0x3b41890d5e8c9640649a9e6f724d1f74aa67af855506db6f871c5fdac70cfd90", "price_changes": [{"asset_id": "24393720551520374522532949229976185621516426573885698267923116722310834739486", "price": "0.18", "size": "2582", "side": "BUY", "hash": "daa6827c2055641f2df128712edad19614d0c01f", "best_bid": "0.6", "best_ask": "0.61"}, {"asset_id": "88830742474573630269392959399954338068265843991617686189000213034050940973037", "price": "0.82", "size": "2582", "side": "SELL", "hash": "4b468adf7d63661c15135a987006fcf92a66cba7", "best_bid": "0.39", "best_ask": "0.4"}], "timestamp": "1769384544927", "event_type": "price_change"}}
{"_local_timestamp": "2026-01-25T23:42:28.033140+00:00", "data": {"market": "0x3b41890d5e8c9640649a9e6f724d1f74aa67af855506db6f871c5fdac70cfd90", "price_changes": [{"asset_id": "24393720551520374522532949229976185621516426573885698267923116722310834739486", "price": "0.23", "size": "0", "side": "BUY", "hash": "b5d38e093fa31bd4555acb12ea6058c010713efd", "best_bid": "0.6", "best_ask": "0.61"}, {"asset_id": "88830742474573630269392959399954338068265843991617686189000213034050940973037", "price": "0.77", "size": "0", "side": "SELL", "hash": "6cec457b7a30ec291abc8a9b764eb50aaea46c2f", "best_bid": "0.39", "best_ask": "0.4"}], "timestamp": "1769384547928", "event_type": "price_change"}}
{"_local_timestamp": "2026-01-25T23:42:28.033593+00:00", "data": {"market": "0x3b41890d5e8c9640649a9e6f724d1f74aa67af855506db6f871c5fdac70cfd90", "price_changes": [{"asset_id": "24393720551520374522532949229976185621516426573885698267923116722310834739486", "price": "0.38", "size": "44.14", "side": "BUY", "hash": "b5d38e093fa31bd4555acb12ea6058c010713efd", "best_bid": "0.6", "best_ask": "0.61"}, {"asset_id": "88830742474573630269392959399954338068265843991617686189000213034050940973037", "price": "0.62", "size": "44.14", "side": "SELL", "hash": "6cec457b7a30ec291abc8a9b764eb50aaea46c2f", "best_bid": "0.39", "best_ask": "0.4"}], "timestamp": "1769384547928", "event_type": "price_change"}}
{"_local_timestamp": "2026-01-25T23:42:28.061121+00:00", "data": {"market": "0x3b41890d5e8c9640649a9e6f724d1f74aa67af855506db6f871c5fdac70cfd90", "price_changes": [{"asset_id": "24393720551520374522532949229976185621516426573885698267923116722310834739486", "price": "0.66", "size": "0", "side": "SELL", "hash": "2a5eb1ba2768139e78f867f3f62cf5b37e0d307b", "best_bid": "0.6", "best_ask": "0.61"}, {"asset_id": "88830742474573630269392959399954338068265843991617686189000213034050940973037", "price": "0.34", "size": "0", "side": "BUY", "hash": "4d91ff8e202081fedabc05e37d3134b2b6d3267a", "best_bid": "0.39", "best_ask": "0.4"}], "timestamp": "1769384547954", "event_type": "price_change"}}
{"_local_timestamp": "2026-01-25T23:42:28.082032+00:00", "data": {"market": "0x3b41890d5e8c9640649a9e6f724d1f74aa67af855506db6f871c5fdac70cfd90", "price_changes": [{"asset_id": "24393720551520374522532949229976185621516426573885698267923116722310834739486", "price": "0.67", "size": "383", "side": "SELL", "hash": "a2f14ccb9f13ddfef8680b8877eacf39fe51a835", "best_bid": "0.6", "best_ask": "0.61"}, {"asset_id": "88830742474573630269392959399954338068265843991617686189000213034050940973037", "price": "0.33", "size": "383", "side": "BUY", "hash": "b04f8c66fc9126f981acb333d931b6dda770c99c", "best_bid": "0.39", "best_ask": "0.4"}], "timestamp": "1769384547981", "event_type": "price_change"}}
{"_local_timestamp": "2026-01-25T23:42:28.154321+00:00", "data": {"market": "0x3b41890d5e8c9640649a9e6f724d1f74aa67af855506db6f871c5fdac70cfd90", "price_changes": [{"asset_id": "24393720551520374522532949229976185621516426573885698267923116722310834739486", "price": "0.26", "size": "639", "side": "BUY", "hash": "c663705e268cdc5c622bf9638763e27581335d70", "best_bid": "0.6", "best_ask": "0.61"}, {"asset_id": "88830742474573630269392959399954338068265843991617686189000213034050940973037", "price": "0.74", "size": "639", "side": "SELL", "hash": "d1179d3750031988e946cebe30655d28905281cb", "best_bid": "0.39", "best_ask": "0.4"}], "timestamp": "1769384548043", "event_type": "price_change"}}
{"_local_timestamp": "2026-01-25T23:42:28.155915+00:00", "data": {"market": "0x3b41890d5e8c9640649a9e6f724d1f74aa67af855506db6f871c5fdac70cfd90", "price_changes": [{"asset_id": "24393720551520374522532949229976185621516426573885698267923116722310834739486", "price": "0.38", "size": "121.14", "side": "BUY", "hash": "6fd4394913053be6d9f565b9532bdf7ee39fa3c6", "best_bid": "0.6", "best_ask": "0.61"}, {"asset_id": "88830742474573630269392959399954338068265843991617686189000213034050940973037", "price": "0.62", "size": "121.14", "side": "SELL", "hash": "6643442ab0906ef59f450942af0b1c208f4364f0", "best_bid": "0.39", "best_ask": "0.4"}], "timestamp": "1769384548044", "event_type": "price_change"}}
{"_local_timestamp": "2026-01-25T23:42:28.156244+00:00", "data": {"market": "0x3b41890d5e8c9640649a9e6f724d1f74aa67af855506db6f871c5fdac70cfd90", "price_changes": [{"asset_id": "24393720551520374522532949229976185621516426573885698267923116722310834739486", "price": "0.28", "size": "325", "side": "BUY", "hash": "e4bcae6ae0a92ffda07aa4a69ff7014075a1a1a4", "best_bid": "0.6", "best_ask": "0.61"}, {"asset_id": "88830742474573630269392959399954338068265843991617686189000213034050940973037", "price": "0.72", "size": "325", "side": "SELL", "hash": "d1e112ff42d7ec05e91fdbfdd669244bf0a946ec", "best_bid": "0.39", "best_ask": "0.4"}], "timestamp": "1769384548045", "event_type": "price_change"}}
{"_local_timestamp": "2026-01-25T23:42:28.156527+00:00", "data": {"market": "0x3b41890d5e8c9640649a9e6f724d1f74aa67af855506db6f871c5fdac70cfd90", "price_changes": [{"asset_id": "24393720551520374522532949229976185621516426573885698267923116722310834739486", "price": "0.52", "size": "60.15", "side": "BUY", "hash": "25704ba773f2fda5c21dea14ee30cb4de2288c12", "best_bid": "0.6", "best_ask": "0.61"}, {"asset_id": "88830742474573630269392959399954338068265843991617686189000213034050940973037", "price": "0.48", "size": "60.15", "side": "SELL", "hash": "df4b1405a2d996edbdb418f56cbe7cb9cd7e18b8", "best_bid": "0.39", "best_ask": "0.4"}], "timestamp": "1769384548046", "event_type": "price_change"}}
{"_local_timestamp": "2026-01-25T23:42:31.891036+00:00", "data": {"market": "0x3b41890d5e8c9640649a9e6f724d1f74aa67af855506db6f871c5fdac70cfd90", "price_changes": [{"asset_id": "88830742474573630269392959399954338068265843991617686189000213034050940973037", "price": "0.35", "size": "0", "side": "BUY", "hash": "1ff754cb84de0689b3ae72c40355790969e91fdf", "best_bid": "0.39", "best_ask": "0.4"}, {"asset_id": "24393720551520374522532949229976185621516426573885698267923116722310834739486", "price": "0.65", "size": "0", "side": "SELL", "hash": "115d6b54f8f4f2a22f2499818ddc646a59f88460", "best_bid": "0.6", "best_ask": "0.61"}], "timestamp": "1769384551782", "event_type": "price_change"}}
{"_local_timestamp": "2026-01-25T23:42:32.457105+00:00", "data": {"market": "0x3b41890d5e8c9640649a9e6f724d1f74aa67af855506db6f871c5fdac70cfd90", "price_changes": [{"asset_id": "88830742474573630269392959399954338068265843991617686189000213034050940973037", "price": "0.34", "size": "100", "side": "BUY", "hash": "a037e0aa52bdc0aa02dd65592ca1f83805406d6b", "best_bid": "0.39", "best_ask": "0.4"}, {"asset_id": "24393720551520374522532949229976185621516426573885698267923116722310834739486", "price": "0.66", "size": "100", "side": "SELL", "hash": "4c35c97391f4a108c18b91f9b1843be05b7fc3ea", "best_bid": "0.6", "best_ask": "0.61"}], "timestamp": "1769384552344", "event_type": "price_change"}}
{"_local_timestamp": "2026-01-25T23:42:32.489785+00:00", "data": {"market": "0x3b41890d5e8c9640649a9e6f724d1f74aa67af855506db6f871c5fdac70cfd90", "price_changes": [{"asset_id": "24393720551520374522532949229976185621516426573885698267923116722310834739486", "price": "0.67", "size": "100", "side": "SELL", "hash": "3301dde9c42c0ca9ada26dab0dbfb266f8f7c73f", "best_bid": "0.6", "best_ask": "0.61"}, {"asset_id": "88830742474573630269392959399954338068265843991617686189000213034050940973037", "price": "0.33", "size": "100", "side": "BUY", "hash": "36cf2983dc221a0c1a50aaa0145d0a5a3b0d349e", "best_bid": "0.39", "best_ask": "0.4"}], "timestamp": "1769384552376", "event_type": "price_change"}}
{"_local_timestamp": "2026-01-25T23:42:32.520964+00:00", "data": {"market": "0x3b41890d5e8c9640649a9e6f724d1f74aa67af855506db6f871c5fdac70cfd90", "price_changes": [{"asset_id": "24393720551520374522532949229976185621516426573885698267923116722310834739486", "price": "0.65", "size": "283", "side": "SELL", "hash": "ded2c7fb6decb389f05a11aa7a50f706fb2b1115", "best_bid": "0.6", "best_ask": "0.61"}, {"asset_id": "88830742474573630269392959399954338068265843991617686189000213034050940973037", "price": "0.35", "size": "283", "side": "BUY", "hash": "2d2d32d0bdaee6fd5e8adafc16bdc77857807322", "best_bid": "0.39", "best_ask": "0.4"}], "timestamp": "1769384552403", "event_type": "price_change"}}
{"_local_timestamp": "2026-01-25T23:42:36.191176+00:00", "data": {"market": "0x3b41890d5e8c9640649a9e6f724d1f74aa67af855506db6f871c5fdac70cfd90", "price_changes": [{"asset_id": "88830742474573630269392959399954338068265843991617686189000213034050940973037", "price": "0.34", "size": "0", "side": "BUY", "hash": "57a531a32cd2f6566ab7f93a3a89e8f80f95b7ac", "best_bid": "0.39", "best_ask": "0.4"}, {"asset_id": "24393720551520374522532949229976185621516426573885698267923116722310834739486", "price": "0.66", "size": "0", "side": "SELL", "hash": "f9f79a84f3aa235b2a3e329728dcc806519f1c27", "best_bid": "0.6", "best_ask": "0.61"}], "timestamp": "1769384556044", "event_type": "price_change"}}
{"_local_timestamp": "2026-01-25T23:42:36.746573+00:00", "data": {"market": "0x3b41890d5e8c9640649a9e6f724d1f74aa67af855506db6f871c5fdac70cfd90", "price_changes": [{"asset_id": "88830742474573630269392959399954338068265843991617686189000213034050940973037", "price": "0.36", "size": "100", "side": "BUY", "hash": "6ae9c435c74bcb0092d79332f3c91c2850c74416", "best_bid": "0.39", "best_ask": "0.4"}, {"asset_id": "24393720551520374522532949229976185621516426573885698267923116722310834739486", "price": "0.64", "size": "100", "side": "SELL", "hash": "b6b840319677395993bebf5c3c18730e0dfe2b98", "best_bid": "0.6", "best_ask": "0.61"}], "timestamp": "1769384556636", "event_type": "price_change"}}
{"_local_timestamp": "2026-01-25T23:42:45.403668+00:00", "data": {"market": "0x3b41890d5e8c9640649a9e6f724d1f74aa67af855506db6f871c5fdac70cfd90", "price_changes": [{"asset_id": "24393720551520374522532949229976185621516426573885698267923116722310834739486", "price": "0.28", "size": "275", "side": "BUY", "hash": "486fb305c34569dc82f52a0e70144df322cac35c", "best_bid": "0.6", "best_ask": "0.61"}, {"asset_id": "88830742474573630269392959399954338068265843991617686189000213034050940973037", "price": "0.72", "size": "275", "side": "SELL", "hash": "5e50a476b01c2026e885b8a3271c30bdcbe75d73", "best_bid": "0.39", "best_ask": "0.4"}], "timestamp": "1769384565217", "event_type": "price_change"}}
{"_local_timestamp": "2026-01-25T23:42:45.511608+00:00", "data": {"market": "0x3b41890d5e8c9640649a9e6f724d1f74aa67af855506db6f871c5fdac70cfd90", "price_changes": [{"asset_id": "24393720551520374522532949229976185621516426573885698267923116722310834739486", "price": "0.65", "size": "0", "side": "SELL", "hash": "87a99295df1dd8a27a66ad767f83d9468536fca1", "best_bid": "0.6", "best_ask": "0.61"}, {"asset_id": "88830742474573630269392959399954338068265843991617686189000213034050940973037", "price": "0.35", "size": "0", "side": "BUY", "hash": "a0546e839c96b79fd891f39f57385880b8a49690", "best_bid": "0.39", "best_ask": "0.4"}], "timestamp": "1769384565311", "event_type": "price_change"}}
{"_local_timestamp": "2026-01-25T23:42:45.512141+00:00", "data": {"market": "0x3b41890d5e8c9640649a9e6f724d1f74aa67af855506db6f871c5fdac70cfd90", "price_changes": [{"asset_id": "24393720551520374522532949229976185621516426573885698267923116722310834739486", "price": "0.67", "size": "383", "side": "SELL", "hash": "f7ca3d7f523b1e8458ecd4fa425071afd8bc8a8a", "best_bid": "0.6", "best_ask": "0.61"}, {"asset_id": "88830742474573630269392959399954338068265843991617686189000213034050940973037", "price": "0.33", "size": "383", "side": "BUY", "hash": "56691152132df06d4de7c918ca7ee0e90c623b3d", "best_bid": "0.39", "best_ask": "0.4"}], "timestamp": "1769384565337", "event_type": "price_change"}}
{"_local_timestamp": "2026-01-25T23:42:45.760394+00:00", "data": {"market": "0x3b41890d5e8c9640649a9e6f724d1f74aa67af855506db6f871c5fdac70cfd90", "price_changes": [{"asset_id": "24393720551520374522532949229976185621516426573885698267923116722310834739486", "price": "0.27", "size": "150", "side": "BUY", "hash": "00cb7ba606d72306bf2eb461f4f26157dfcbfcec", "best_bid": "0.6", "best_ask": "0.61"}, {"asset_id": "88830742474573630269392959399954338068265843991617686189000213034050940973037", "price": "0.73", "size": "150", "side": "SELL", "hash": "0c14952e1574ba5aae1b70e392c577b41c19767e", "best_bid": "0.39", "best_ask": "0.4"}], "timestamp": "1769384565599", "event_type": "price_change"}}
{"_local_timestamp": "2026-01-25T23:42:47.275347+00:00", "data": {"market": "0x3b41890d5e8c9640649a9e6f724d1f74aa67af855506db6f871c5fdac70cfd90", "price_changes": [{"asset_id": "24393720551520374522532949229976185621516426573885698267923116722310834739486", "price": "0.18", "size": "250", "side": "BUY", "hash": "736a1875fe5cd5e69b6674bf04bd07c4e1c98dd2", "best_bid": "0.6", "best_ask": "0.61"}, {"asset_id": "88830742474573630269392959399954338068265843991617686189000213034050940973037", "price": "0.82", "size": "250", "side": "SELL", "hash": "4149366d52e66525d169faeebd426a61a1821a62", "best_bid": "0.39", "best_ask": "0.4"}], "timestamp": "1769384566994", "event_type": "price_change"}}
{"_local_timestamp": "2026-01-25T23:42:48.737546+00:00", "data": {"market": "0x3b41890d5e8c9640649a9e6f724d1f74aa67af855506db6f871c5fdac70cfd90", "price_changes": [{"asset_id": "88830742474573630269392959399954338068265843991617686189000213034050940973037", "price": "0.36", "size": "0", "side": "BUY", "hash": "419b539cb04e8b3eb6f225a4d54d3afa87966e33", "best_bid": "0.39", "best_ask": "0.4"}, {"asset_id": "24393720551520374522532949229976185621516426573885698267923116722310834739486", "price": "0.64", "size": "0", "side": "SELL", "hash": "9b01e04e363933d76ba6d78269fb517cea00f656", "best_bid": "0.6", "best_ask": "0.61"}], "timestamp": "1769384568614", "event_type": "price_change"}}
{"_local_timestamp": "2026-01-25T23:42:49.517340+00:00", "data": {"market": "0x3b41890d5e8c9640649a9e6f724d1f74aa67af855506db6f871c5fdac70cfd90", "price_changes": [{"asset_id": "88830742474573630269392959399954338068265843991617686189000213034050940973037", "price": "0.34", "size": "100", "side": "BUY", "hash": "e1c7e45717dcf57204f09fa199d6f3c104a4fcc2", "best_bid": "0.39", "best_ask": "0.4"}, {"asset_id": "24393720551520374522532949229976185621516426573885698267923116722310834739486", "price": "0.66", "size": "100", "side": "SELL", "hash": "84a97c821cc87af3baf88a4d263240a4fd14bfbd", "best_bid": "0.6", "best_ask": "0.61"}], "timestamp": "1769384569408", "event_type": "price_change"}}
{"_local_timestamp": "2026-01-25T23:42:49.541368+00:00", "data": {"market": "0x3b41890d5e8c9640649a9e6f724d1f74aa67af855506db6f871c5fdac70cfd90", "price_changes": [{"asset_id": "24393720551520374522532949229976185621516426573885698267923116722310834739486", "price": "0.67", "size": "100", "side": "SELL", "hash": "7b20870f984ce9af711928317096ec3701748e3a", "best_bid": "0.6", "best_ask": "0.61"}, {"asset_id": "88830742474573630269392959399954338068265843991617686189000213034050940973037", "price": "0.33", "size": "100", "side": "BUY", "hash": "045b039cd1346c87d8264356289554cd60f99f0e", "best_bid": "0.39", "best_ask": "0.4"}], "timestamp": "1769384569432", "event_type": "price_change"}}
{"_local_timestamp": "2026-01-25T23:42:49.580085+00:00", "data": {"market": "0x3b41890d5e8c9640649a9e6f724d1f74aa67af855506db6f871c5fdac70cfd90", "price_changes": [{"asset_id": "24393720551520374522532949229976185621516426573885698267923116722310834739486", "price": "0.65", "size": "283", "side": "SELL", "hash": "c3a5d291632f94796dea53e05a527a358bb0b143", "best_bid": "0.6", "best_ask": "0.61"}, {"asset_id": "88830742474573630269392959399954338068265843991617686189000213034050940973037", "price": "0.35", "size": "283", "side": "BUY", "hash": "ac60c25641c1f04dc8a42d0bd743556993a903a2", "best_bid": "0.39", "best_ask": "0.4"}], "timestamp": "1769384569459", "event_type": "price_change"}}
{"_local_timestamp": "2026-01-25T23:42:53.245313+00:00", "data": {"market": "0x3b41890d5e8c9640649a9e6f724d1f74aa67af855506db6f871c5fdac70cfd90", "price_changes": [{"asset_id": "88830742474573630269392959399954338068265843991617686189000213034050940973037", "price": "0.34", "size": "0", "side": "BUY", "hash": "4c976aa900fa90390d1a9d35622b2a245eaadb7b", "best_bid": "0.39", "best_ask": "0.4"}, {"asset_id": "24393720551520374522532949229976185621516426573885698267923116722310834739486", "price": "0.66", "size": "0", "side": "SELL", "hash": "85eb0f0163849e2f98a9baced9193f99b01889fd", "best_bid": "0.6", "best_ask": "0.61"}], "timestamp": "1769384573138", "event_type": "price_change"}}
{"_local_timestamp": "2026-01-25T23:42:53.777946+00:00", "data": {"market": "0x3b41890d5e8c9640649a9e6f724d1f74aa67af855506db6f871c5fdac70cfd90", "price_changes": [{"asset_id": "88830742474573630269392959399954338068265843991617686189000213034050940973037", "price": "0.36", "size": "100", "side": "BUY", "hash": "6afb7a32863e91db05650f7eca29ed8dcb931025", "best_bid": "0.39", "best_ask": "0.4"}, {"asset_id": "24393720551520374522532949229976185621516426573885698267923116722310834739486", "price": "0.64", "size": "100", "side": "SELL", "hash": "632ff688c336168c8920616fdaa9abdfd78ab0d7", "best_bid": "0.6", "best_ask": "0.61"}], "timestamp": "1769384573678", "event_type": "price_change"}}
{"_local_timestamp": "2026-01-25T23:43:28.232487+00:00", "data": {"market": "0x3b41890d5e8c9640649a9e6f724d1f74aa67af855506db6f871c5fdac70cfd90", "price_changes": [{"asset_id": "24393720551520374522532949229976185621516426573885698267923116722310834739486", "price": "0.19", "size": "2360", "side": "BUY", "hash": "eb60b09398dd431872ecf0ad1c6c4e8ab55ba5b7", "best_bid": "0.6", "best_ask": "0.61"}, {"asset_id": "88830742474573630269392959399954338068265843991617686189000213034050940973037", "price": "0.81", "size": "2360", "side": "SELL", "hash": "42f5f90f22893a115edeaff1314bb82b04fa4caf", "best_bid": "0.39", "best_ask": "0.4"}], "timestamp": "1769384608108", "event_type": "price_change"}}
{"_local_timestamp": "2026-01-25T23:43:28.254310+00:00", "data": {"market": "0x3b41890d5e8c9640649a9e6f724d1f74aa67af855506db6f871c5fdac70cfd90", "price_changes": [{"asset_id": "24393720551520374522532949229976185621516426573885698267923116722310834739486", "price": "0.65", "size": "0", "side": "SELL", "hash": "9ef67d1b50a75019c141cd4edd898a016d738943", "best_bid": "0.6", "best_ask": "0.61"}, {"asset_id": "88830742474573630269392959399954338068265843991617686189000213034050940973037", "price": "0.35", "size": "0", "side": "BUY", "hash": "40e0985faad68eaa060b1623dec8b19ff70fd8e2", "best_bid": "0.39", "best_ask": "0.4"}], "timestamp": "1769384608131", "event_type": "price_change"}}
{"_local_timestamp": "2026-01-25T23:43:28.290105+00:00", "data": {"market": "0x3b41890d5e8c9640649a9e6f724d1f74aa67af855506db6f871c5fdac70cfd90", "price_changes": [{"asset_id": "24393720551520374522532949229976185621516426573885698267923116722310834739486", "price": "0.67", "size": "383", "side": "SELL", "hash": "99952afdf6c9a7f633c39460f511f73724725089", "best_bid": "0.6", "best_ask": "0.61"}, {"asset_id": "88830742474573630269392959399954338068265843991617686189000213034050940973037", "price": "0.33", "size": "383", "side": "BUY", "hash": "e9b2ae210c8a16c298ff1e108ca6110690da9d78", "best_bid": "0.39", "best_ask": "0.4"}], "timestamp": "1769384608155", "event_type": "price_change"}}
{"_local_timestamp": "2026-01-25T23:43:31.484634+00:00", "data": {"market": "0x3b41890d5e8c9640649a9e6f724d1f74aa67af855506db6f871c5fdac70cfd90", "price_changes": [{"asset_id": "88830742474573630269392959399954338068265843991617686189000213034050940973037", "price": "0.36", "size": "0", "side": "BUY", "hash": "fbeb6598566fd8fc0d0443b78ddbee73f0a9f5ac", "best_bid": "0.39", "best_ask": "0.4"}, {"asset_id": "24393720551520374522532949229976185621516426573885698267923116722310834739486", "price": "0.64", "size": "0", "side": "SELL", "hash": "59ac54ba9aff83c292fad3af328572030d4f3944", "best_bid": "0.6", "best_ask": "0.61"}], "timestamp": "1769384611366", "event_type": "price_change"}}
{"_local_timestamp": "2026-01-25T23:43:32.214423+00:00", "data": {"market": "0x3b41890d5e8c9640649a9e6f724d1f74aa67af855506db6f871c5fdac70cfd90", "price_changes": [{"asset_id": "88830742474573630269392959399954338068265843991617686189000213034050940973037", "price": "0.34", "size": "100", "side": "BUY", "hash": "ce1f9b83cfc987174f2c779bc5e6b2e26448239c", "best_bid": "0.39", "best_ask": "0.4"}, {"asset_id": "24393720551520374522532949229976185621516426573885698267923116722310834739486", "price": "0.66", "size": "100", "side": "SELL", "hash": "5d2ac6a485c437ac8570bd41923836cb58f77ebe", "best_bid": "0.6", "best_ask": "0.61"}], "timestamp": "1769384612085", "event_type": "price_change"}}
{"_local_timestamp": "2026-01-25T23:43:32.231479+00:00", "data": {"market": "0x3b41890d5e8c9640649a9e6f724d1f74aa67af855506db6f871c5fdac70cfd90", "price_changes": [{"asset_id": "24393720551520374522532949229976185621516426573885698267923116722310834739486", "price": "0.67", "size": "100", "side": "SELL", "hash": "b6593a57233d52f3fbcb3f02e99dc2ca606b08c8", "best_bid": "0.6", "best_ask": "0.61"}, {"asset_id": "88830742474573630269392959399954338068265843991617686189000213034050940973037", "price": "0.33", "size": "100", "side": "BUY", "hash": "6cf7610b3195906107d4cf79d308bc2063c7877f", "best_bid": "0.39", "best_ask": "0.4"}], "timestamp": "1769384612109", "event_type": "price_change"}}
{"_local_timestamp": "2026-01-25T23:43:32.252825+00:00", "data": {"market": "0x3b41890d5e8c9640649a9e6f724d1f74aa67af855506db6f871c5fdac70cfd90", "price_changes": [{"asset_id": "24393720551520374522532949229976185621516426573885698267923116722310834739486", "price": "0.65", "size": "283", "side": "SELL", "hash": "f5787f5402cbb83bb523e90f54cb997abc742549", "best_bid": "0.6", "best_ask": "0.61"}, {"asset_id": "88830742474573630269392959399954338068265843991617686189000213034050940973037", "price": "0.35", "size": "283", "side": "BUY", "hash": "240c170d0ef3422d05bcd87eb715a7f2920ba6b6", "best_bid": "0.39", "best_ask": "0.4"}], "timestamp": "1769384612135", "event_type": "price_change"}}
{"_local_timestamp": "2026-01-25T23:43:35.104861+00:00", "data": {"market": "0xdd9f55a4a214da7231a64eb6f43a05f525b51e7bcf714db0c2d3b2fd0fc0c9ca", "price_changes": [{"asset_id": "87855193300342526755310181206520215785023964324419734896948555881922627101363", "price": "0.51", "size": "0", "side": "BUY", "hash": "caf1ebbd590c9d9bbd836f715f3d68a700a4033c", "best_bid": "0.66", "best_ask": "0.76"}, {"asset_id": "18582106713580348058065911013375325630183346495483834588274922531241537980162", "price": "0.49", "size": "0", "side": "SELL", "hash": "e0796920250915ad5cfa0a4ed509ea5f3d77d3c0", "best_bid": "0.24", "best_ask": "0.34"}], "timestamp": "1769384614973", "event_type": "price_change"}}
{"_local_timestamp": "2026-01-25T23:43:35.950974+00:00", "data": {"market": "0x3b41890d5e8c9640649a9e6f724d1f74aa67af855506db6f871c5fdac70cfd90", "price_changes": [{"asset_id": "88830742474573630269392959399954338068265843991617686189000213034050940973037", "price": "0.34", "size": "0", "side": "BUY", "hash": "6b02c43b56a3daa386d01b9083fcbd145b15d53e", "best_bid": "0.39", "best_ask": "0.4"}, {"asset_id": "24393720551520374522532949229976185621516426573885698267923116722310834739486", "price": "0.66", "size": "0", "side": "SELL", "hash": "6a9b97bcc575b643cfb059b032dc30bffb62e836", "best_bid": "0.6", "best_ask": "0.61"}], "timestamp": "1769384615800", "event_type": "price_change"}}
{"_local_timestamp": "2026-01-25T23:43:36.538672+00:00", "data": {"market": "0xdd9f55a4a214da7231a64eb6f43a05f525b51e7bcf714db0c2d3b2fd0fc0c9ca", "price_changes": [{"asset_id": "87855193300342526755310181206520215785023964324419734896948555881922627101363", "price": "0.67", "size": "33.42", "side": "BUY", "hash": "0d2140c18944073599a53cb9b505572834cc8ea5", "best_bid": "0.67", "best_ask": "0.76"}, {"asset_id": "18582106713580348058065911013375325630183346495483834588274922531241537980162", "price": "0.33", "size": "33.42", "side": "SELL", "hash": "4840aea588f86f537c7bde6e1b9dcf6fd80eadd2", "best_bid": "0.24", "best_ask": "0.33"}], "timestamp": "1769384616400", "event_type": "price_change"}}
{"_local_timestamp": "2026-01-25T23:43:36.570769+00:00", "data": {"market": "0x3b41890d5e8c9640649a9e6f724d1f74aa67af855506db6f871c5fdac70cfd90", "price_changes": [{"asset_id": "88830742474573630269392959399954338068265843991617686189000213034050940973037", "price": "0.36", "size": "100", "side": "BUY", "hash": "f11c84e3e0f900984b3eceac3483ee9d08983371", "best_bid": "0.39", "best_ask": "0.4"}, {"asset_id": "24393720551520374522532949229976185621516426573885698267923116722310834739486", "price": "0.64", "size": "100", "side": "SELL", "hash": "011ca0e51855e66176edebcf9a3fc1f69e8a503d", "best_bid": "0.6", "best_ask": "0.61"}], "timestamp": "1769384616431", "event_type": "price_change"}}
{"_local_timestamp": "2026-01-25T23:43:38.606016+00:00", "data": {"market": "0x3b41890d5e8c9640649a9e6f724d1f74aa67af855506db6f871c5fdac70cfd90", "price_changes": [{"asset_id": "24393720551520374522532949229976185621516426573885698267923116722310834739486", "price": "0.18", "size": "100", "side": "BUY", "hash": "0b60450e699626ab94c3873ba89c86310208bc90", "best_bid": "0.6", "best_ask": "0.61"}, {"asset_id": "88830742474573630269392959399954338068265843991617686189000213034050940973037", "price": "0.82", "size": "100", "side": "SELL", "hash": "1faa653dcedb03dea91fe67db2f1ffbbfc8a7b31", "best_bid": "0.39", "best_ask": "0.4"}], "timestamp": "1769384618452", "event_type": "price_change"}}
{"_local_timestamp": "2026-01-25T23:43:38.899728+00:00", "data": {"market": "0x3b41890d5e8c9640649a9e6f724d1f74aa67af855506db6f871c5fdac70cfd90", "price_changes": [{"asset_id": "24393720551520374522532949229976185621516426573885698267923116722310834739486", "price": "0.19", "size": "2510", "side": "BUY", "hash": "a1f7f25f81e5a3bef39e156fcad7478987a80d7a", "best_bid": "0.6", "best_ask": "0.61"}, {"asset_id": "88830742474573630269392959399954338068265843991617686189000213034050940973037", "price": "0.81", "size": "2510", "side": "SELL", "hash": "a0adc66189540bcb1cd2e1f8cdd9fbe12f7af7e7", "best_bid": "0.39", "best_ask": "0.4"}], "timestamp": "1769384618721", "event_type": "price_change"}}
{"_local_timestamp": "2026-01-25T23:43:45.615788+00:00", "data": {"market": "0xdd9f55a4a214da7231a64eb6f43a05f525b51e7bcf714db0c2d3b2fd0fc0c9ca", "price_changes": [{"asset_id": "87855193300342526755310181206520215785023964324419734896948555881922627101363", "price": "0.65", "size": "33.42", "side": "BUY", "hash": "8d4685478685798a4f1ef3891d3989d356134b2c", "best_bid": "0.67", "best_ask": "0.76"}, {"asset_id": "18582106713580348058065911013375325630183346495483834588274922531241537980162", "price": "0.35", "size": "33.42", "side": "SELL", "hash": "7b618c990a05195ca00012fa486107162d54c67e", "best_bid": "0.24", "best_ask": "0.33"}], "timestamp": "1769384625508", "event_type": "price_change"}}
{"_local_timestamp": "2026-01-25T23:43:48.465358+00:00", "data": {"market": "0xdd9f55a4a214da7231a64eb6f43a05f525b51e7bcf714db0c2d3b2fd0fc0c9ca", "price_changes": [{"asset_id": "87855193300342526755310181206520215785023964324419734896948555881922627101363", "price": "0.66", "size": "0", "side": "BUY", "hash": "74cb73a398c092dd7717d13aaf4e457e5037c4a0", "best_bid": "0.67", "best_ask": "0.76"}, {"asset_id": "18582106713580348058065911013375325630183346495483834588274922531241537980162", "price": "0.34", "size": "0", "side": "SELL", "hash": "bfc4259722621e75c5777e240eb35109bc39517e", "best_bid": "0.24", "best_ask": "0.33"}], "timestamp": "1769384628363", "event_type": "price_change"}}
{"_local_timestamp": "2026-01-25T23:43:48.960317+00:00", "data": {"market": "0xdd9f55a4a214da7231a64eb6f43a05f525b51e7bcf714db0c2d3b2fd0fc0c9ca", "price_changes": [{"asset_id": "87855193300342526755310181206520215785023964324419734896948555881922627101363", "price": "0.18", "size": "199.99", "side": "BUY", "hash": "a66c417b77b2606f8a082fa9612be21594ae58b0", "best_bid": "0.67", "best_ask": "0.76"}, {"asset_id": "18582106713580348058065911013375325630183346495483834588274922531241537980162", "price": "0.82", "size": "199.99", "side": "SELL", "hash": "535742c889c0cb89babd6e13a024e429d5b23d61", "best_bid": "0.24", "best_ask": "0.33"}], "timestamp": "1769384628870", "event_type": "price_change"}}
{"_local_timestamp": "2026-01-25T23:44:09.085723+00:00", "data": {"market": "0xdd9f55a4a214da7231a64eb6f43a05f525b51e7bcf714db0c2d3b2fd0fc0c9ca", "price_changes": [{"asset_id": "87855193300342526755310181206520215785023964324419734896948555881922627101363", "price": "0.29", "size": "250", "side": "BUY", "hash": "26a47ca966cc9a4f0aa43cc3f95bae4eaf6f002f", "best_bid": "0.67", "best_ask": "0.76"}, {"asset_id": "18582106713580348058065911013375325630183346495483834588274922531241537980162", "price": "0.71", "size": "250", "side": "SELL", "hash": "ef3fa1a0076ed99b20f79ace44272733f7b61e89", "best_bid": "0.24", "best_ask": "0.33"}], "timestamp": "1769384648763", "event_type": "price_change"}}
{"_local_timestamp": "2026-01-25T23:44:12.031440+00:00", "data": {"market": "0x3b41890d5e8c9640649a9e6f724d1f74aa67af855506db6f871c5fdac70cfd90", "price_changes": [{"asset_id": "24393720551520374522532949229976185621516426573885698267923116722310834739486", "price": "0.59", "size": "400", "side": "BUY", "hash": "c6e2db44726b1c03fa478c72e54e14a81db0da15", "best_bid": "0.6", "best_ask": "0.61"}, {"asset_id": "88830742474573630269392959399954338068265843991617686189000213034050940973037", "price": "0.41", "size": "400", "side": "SELL", "hash": "6c5ebaaa42e5256d1abfad46cf53e0e7a261c273", "best_bid": "0.39", "best_ask": "0.4"}], "timestamp": "1769384651873", "event_type": "price_change"}}
{"_local_timestamp": "2026-01-25T23:44:12.051996+00:00", "data": {"market": "0x3b41890d5e8c9640649a9e6f724d1f74aa67af855506db6f871c5fdac70cfd90", "price_changes": [{"asset_id": "24393720551520374522532949229976185621516426573885698267923116722310834739486", "price": "0.65", "size": "0", "side": "SELL", "hash": "4df91b28fbc7bd706e96bbfd909ddc77ff07e8b3", "best_bid": "0.6", "best_ask": "0.61"}, {"asset_id": "88830742474573630269392959399954338068265843991617686189000213034050940973037", "price": "0.35", "size": "0", "side": "BUY", "hash": "098e962200a38bef27ac70174fbaa143a98dd976", "best_bid": "0.39", "best_ask": "0.4"}], "timestamp": "1769384651904", "event_type": "price_change"}}
{"_local_timestamp": "2026-01-25T23:44:12.081110+00:00", "data": {"market": "0x3b41890d5e8c9640649a9e6f724d1f74aa67af855506db6f871c5fdac70cfd90", "price_changes": [{"asset_id": "24393720551520374522532949229976185621516426573885698267923116722310834739486", "price": "0.67", "size": "383", "side": "SELL", "hash": "efb071196e40cebf474a94e9310ba7d11038c055", "best_bid": "0.6", "best_ask": "0.61"}, {"asset_id": "88830742474573630269392959399954338068265843991617686189000213034050940973037", "price": "0.33", "size": "383", "side": "BUY", "hash": "bdbaa1dc68a0c3ac103e19f8eecc174fe2859283", "best_bid": "0.39", "best_ask": "0.4"}], "timestamp": "1769384651935", "event_type": "price_change"}}
{"_local_timestamp": "2026-01-25T23:44:13.527656+00:00", "data": {"market": "0x3b41890d5e8c9640649a9e6f724d1f74aa67af855506db6f871c5fdac70cfd90", "price_changes": [{"asset_id": "88830742474573630269392959399954338068265843991617686189000213034050940973037", "price": "0.36", "size": "0", "side": "BUY", "hash": "d5313f420f88e51eeb21a46fc76bed4b735e378c", "best_bid": "0.39", "best_ask": "0.4"}, {"asset_id": "24393720551520374522532949229976185621516426573885698267923116722310834739486", "price": "0.64", "size": "0", "side": "SELL", "hash": "9638c98dbf5b346704ef78dbd9d20912a99e711c", "best_bid": "0.6", "best_ask": "0.61"}], "timestamp": "1769384653377", "event_type": "price_change"}}
{"_local_timestamp": "2026-01-25T23:44:14.131178+00:00", "data": {"market": "0x3b41890d5e8c9640649a9e6f724d1f74aa67af855506db6f871c5fdac70cfd90", "price_changes": [{"asset_id": "88830742474573630269392959399954338068265843991617686189000213034050940973037", "price": "0.34", "size": "100", "side": "BUY", "hash": "31973c0367b6105d43e29c3d9641e04655103000", "best_bid": "0.39", "best_ask": "0.4"}, {"asset_id": "24393720551520374522532949229976185621516426573885698267923116722310834739486", "price": "0.66", "size": "100", "side": "SELL", "hash": "9661946e94b331fa2f1f1b5dadca602f115bb19f", "best_bid": "0.6", "best_ask": "0.61"}], "timestamp": "1769384653985", "event_type": "price_change"}}
{"_local_timestamp": "2026-01-25T23:44:14.172721+00:00", "data": {"market": "0x3b41890d5e8c9640649a9e6f724d1f74aa67af855506db6f871c5fdac70cfd90", "price_changes": [{"asset_id": "24393720551520374522532949229976185621516426573885698267923116722310834739486", "price": "0.67", "size": "100", "side": "SELL", "hash": "fa99fe78b3d283ea35cb652c816ea8a6c023e5b6", "best_bid": "0.6", "best_ask": "0.61"}, {"asset_id": "88830742474573630269392959399954338068265843991617686189000213034050940973037", "price": "0.33", "size": "100", "side": "BUY", "hash": "c6f2424c4f02cc39174fe6603d3b5e580b29a62e", "best_bid": "0.39", "best_ask": "0.4"}], "timestamp": "1769384654010", "event_type": "price_change"}}
{"_local_timestamp": "2026-01-25T23:44:14.187187+00:00", "data": {"market": "0x3b41890d5e8c9640649a9e6f724d1f74aa67af855506db6f871c5fdac70cfd90", "price_changes": [{"asset_id": "24393720551520374522532949229976185621516426573885698267923116722310834739486", "price": "0.65", "size": "283", "side": "SELL", "hash": "3863932d5a17758837407c1d4708dfc8a6bfe9df", "best_bid": "0.6", "best_ask": "0.61"}, {"asset_id": "88830742474573630269392959399954338068265843991617686189000213034050940973037", "price": "0.35", "size": "283", "side": "BUY", "hash": "f13f7425f19948fc3650b860d57db21792962760", "best_bid": "0.39", "best_ask": "0.4"}], "timestamp": "1769384654038", "event_type": "price_change"}}
{"_local_timestamp": "2026-01-25T23:44:17.922631+00:00", "data": {"market": "0x3b41890d5e8c9640649a9e6f724d1f74aa67af855506db6f871c5fdac70cfd90", "price_changes": [{"asset_id": "88830742474573630269392959399954338068265843991617686189000213034050940973037", "price": "0.34", "size": "0", "side": "BUY", "hash": "037023e1bd246e29b39d1056254a52e866aaa37e", "best_bid": "0.39", "best_ask": "0.4"}, {"asset_id": "24393720551520374522532949229976185621516426573885698267923116722310834739486", "price": "0.66", "size": "0", "side": "SELL", "hash": "2293a19d2a98569b0f35dc6ed5c4717d20a8f129", "best_bid": "0.6", "best_ask": "0.61"}], "timestamp": "1769384657677", "event_type": "price_change"}}
{"_local_timestamp": "2026-01-25T23:44:18.444265+00:00", "data": {"market": "0x3b41890d5e8c9640649a9e6f724d1f74aa67af855506db6f871c5fdac70cfd90", "price_changes": [{"asset_id": "88830742474573630269392959399954338068265843991617686189000213034050940973037", "price": "0.36", "size": "100", "side": "BUY", "hash": "939fe64222156867d15c96a959502bb27060b7d7", "best_bid": "0.39", "best_ask": "0.4"}, {"asset_id": "24393720551520374522532949229976185621516426573885698267923116722310834739486", "price": "0.64", "size": "100", "side": "SELL", "hash": "c1133053865d5f76cf267c764d2d673b0667cc81", "best_bid": "0.6", "best_ask": "0.61"}], "timestamp": "1769384658184", "event_type": "price_change"}}
{"_local_timestamp": "2026-01-25T23:44:20.804450+00:00", "data": {"market": "0x3b41890d5e8c9640649a9e6f724d1f74aa67af855506db6f871c5fdac70cfd90", "price_changes": [{"asset_id": "24393720551520374522532949229976185621516426573885698267923116722310834739486", "price": "0.19", "size": "2360", "side": "BUY", "hash": "5c117b2f6be6ccd5adf21d0eaf4bc7cfa4fbbedf", "best_bid": "0.6", "best_ask": "0.61"}, {"asset_id": "88830742474573630269392959399954338068265843991617686189000213034050940973037", "price": "0.81", "size": "2360", "side": "SELL", "hash": "df2f922ed5ea600f91725cbaee3638c58ef3c2fe", "best_bid": "0.39", "best_ask": "0.4"}], "timestamp": "1769384660470", "event_type": "price_change"}}
{"_local_timestamp": "2026-01-25T23:44:20.806368+00:00", "data": {"market": "0x3b41890d5e8c9640649a9e6f724d1f74aa67af855506db6f871c5fdac70cfd90", "price_changes": [{"asset_id": "24393720551520374522532949229976185621516426573885698267923116722310834739486", "price": "0.27", "size": "50", "side": "BUY", "hash": "5c117b2f6be6ccd5adf21d0eaf4bc7cfa4fbbedf", "best_bid": "0.6", "best_ask": "0.61"}, {"asset_id": "88830742474573630269392959399954338068265843991617686189000213034050940973037", "price": "0.73", "size": "50", "side": "SELL", "hash": "df2f922ed5ea600f91725cbaee3638c58ef3c2fe", "best_bid": "0.39", "best_ask": "0.4"}], "timestamp": "1769384660470", "event_type": "price_change"}}
{"_local_timestamp": "2026-01-25T23:44:21.487227+00:00", "data": {"market": "0x3b41890d5e8c9640649a9e6f724d1f74aa67af855506db6f871c5fdac70cfd90", "price_changes": [{"asset_id": "24393720551520374522532949229976185621516426573885698267923116722310834739486", "price": "0.22", "size": "10390.9", "side": "BUY", "hash": "38c8e4cc02a90924c8796ba97edbcc2907b57a2b", "best_bid": "0.6", "best_ask": "0.61"}, {"asset_id": "88830742474573630269392959399954338068265843991617686189000213034050940973037", "price": "0.78", "size": "10390.9", "side": "SELL", "hash": "7a5fcc59439d3a81e435119d0fd7ccb79216ceb0", "best_bid": "0.39", "best_ask": "0.4"}], "timestamp": "1769384660863", "event_type": "price_change"}}
{"_local_timestamp": "2026-01-25T23:44:21.679488+00:00", "data": {"market": "0x3b41890d5e8c9640649a9e6f724d1f74aa67af855506db6f871c5fdac70cfd90", "price_changes": [{"asset_id": "24393720551520374522532949229976185621516426573885698267923116722310834739486", "price": "0.18", "size": "250", "side": "BUY", "hash": "dfc36728ad4174b88e1d0d089340f48a29c505a9", "best_bid": "0.6", "best_ask": "0.61"}, {"asset_id": "88830742474573630269392959399954338068265843991617686189000213034050940973037", "price": "0.82", "size": "250", "side": "SELL", "hash": "5169708d219b49927aded8150275626981c648df", "best_bid": "0.39", "best_ask": "0.4"}], "timestamp": "1769384660941", "event_type": "price_change"}}
{"_local_timestamp": "2026-01-25T23:44:23.132954+00:00", "data": {"market": "0x3b41890d5e8c9640649a9e6f724d1f74aa67af855506db6f871c5fdac70cfd90", "price_changes": [{"asset_id": "24393720551520374522532949229976185621516426573885698267923116722310834739486", "price": "0.26", "size": "315", "side": "BUY", "hash": "f6d7dca07cf4e6fad16315bf8219aee1ec4af322", "best_bid": "0.6", "best_ask": "0.61"}, {"asset_id": "88830742474573630269392959399954338068265843991617686189000213034050940973037", "price": "0.74", "size": "315", "side": "SELL", "hash": "434eef944e29c9d7d878c823751ea4679804c60d", "best_bid": "0.39", "best_ask": "0.4"}], "timestamp": "1769384662878", "event_type": "price_change"}}
{"_local_timestamp": "2026-01-25T23:44:23.134890+00:00", "data": {"market": "0x3b41890d5e8c9640649a9e6f724d1f74aa67af855506db6f871c5fdac70cfd90", "price_changes": [{"asset_id": "24393720551520374522532949229976185621516426573885698267923116722310834739486", "price": "0.28", "size": "0", "side": "BUY", "hash": "f6d7dca07cf4e6fad16315bf8219aee1ec4af322", "best_bid": "0.6", "best_ask": "0.61"}, {"asset_id": "88830742474573630269392959399954338068265843991617686189000213034050940973037", "price": "0.72", "size": "0", "side": "SELL", "hash": "434eef944e29c9d7d878c823751ea4679804c60d", "best_bid": "0.39", "best_ask": "0.4"}], "timestamp": "1769384662878", "event_type": "price_change"}}
{"_local_timestamp": "2026-01-25T23:44:23.178326+00:00", "data": {"market": "0x3b41890d5e8c9640649a9e6f724d1f74aa67af855506db6f871c5fdac70cfd90", "price_changes": [{"asset_id": "24393720551520374522532949229976185621516426573885698267923116722310834739486", "price": "0.23", "size": "666", "side": "BUY", "hash": "703f9fba3c837728ab89d6e24a89d620416fc0a3", "best_bid": "0.6", "best_ask": "0.61"}, {"asset_id": "88830742474573630269392959399954338068265843991617686189000213034050940973037", "price": "0.77", "size": "666", "side": "SELL", "hash": "caaffcf02cf92fa662ed447ac89610bc02a91b1b", "best_bid": "0.39", "best_ask": "0.4"}], "timestamp": "1769384662934", "event_type": "price_change"}}
{"_local_timestamp": "2026-01-25T23:44:23.187147+00:00", "data": {"market": "0x3b41890d5e8c9640649a9e6f724d1f74aa67af855506db6f871c5fdac70cfd90", "price_changes": [{"asset_id": "24393720551520374522532949229976185621516426573885698267923116722310834739486", "price": "0.26", "size": "347", "side": "BUY", "hash": "0be3afcbff99b009d4be2e3ae03e4b18098cb0d9", "best_bid": "0.6", "best_ask": "0.61"}, {"asset_id": "88830742474573630269392959399954338068265843991617686189000213034050940973037", "price": "0.74", "size": "347", "side": "SELL", "hash": "e5814a6dd026d30feafd3e0ef5e165f1977e126f", "best_bid": "0.39", "best_ask": "0.4"}], "timestamp": "1769384662935", "event_type": "price_change"}}
{"_local_timestamp": "2026-01-25T23:44:32.654805+00:00", "data": {"market": "0x3b41890d5e8c9640649a9e6f724d1f74aa67af855506db6f871c5fdac70cfd90", "price_changes": [{"asset_id": "24393720551520374522532949229976185621516426573885698267923116722310834739486", "price": "0.19", "size": "150", "side": "BUY", "hash": "c5a479b0d65b201f166096a3afa041f05c3940b7", "best_bid": "0.6", "best_ask": "0.61"}, {"asset_id": "88830742474573630269392959399954338068265843991617686189000213034050940973037", "price": "0.81", "size": "150", "side": "SELL", "hash": "1bb3e905864f3d3153ed307208379a4071fab9f7", "best_bid": "0.39", "best_ask": "0.4"}], "timestamp": "1769384672301", "event_type": "price_change"}}
{"_local_timestamp": "2026-01-25T23:44:32.696515+00:00", "data": {"market": "0x3b41890d5e8c9640649a9e6f724d1f74aa67af855506db6f871c5fdac70cfd90", "price_changes": [{"asset_id": "24393720551520374522532949229976185621516426573885698267923116722310834739486", "price": "0.65", "size": "0", "side": "SELL", "hash": "3774c04349f784357e9bf698775ed164b8f8e54d", "best_bid": "0.6", "best_ask": "0.61"}, {"asset_id": "88830742474573630269392959399954338068265843991617686189000213034050940973037", "price": "0.35", "size": "0", "side": "BUY", "hash": "6c7a6941d3e497848d2161415ea1dbb771401df4", "best_bid": "0.39", "best_ask": "0.4"}], "timestamp": "1769384672401", "event_type": "price_change"}}
{"_local_timestamp": "2026-01-25T23:44:32.708795+00:00", "data": {"market": "0x3b41890d5e8c9640649a9e6f724d1f74aa67af855506db6f871c5fdac70cfd90", "price_changes": [{"asset_id": "24393720551520374522532949229976185621516426573885698267923116722310834739486", "price": "0.67", "size": "353", "side": "SELL", "hash": "ae37202f39be2935c0e83a9db37f4268306d8772", "best_bid": "0.6", "best_ask": "0.61"}, {"asset_id": "88830742474573630269392959399954338068265843991617686189000213034050940973037", "price": "0.33", "size": "353", "side": "BUY", "hash": "2e98b9220474c5413a3dec5e529075c13e922e8b", "best_bid": "0.39", "best_ask": "0.4"}], "timestamp": "1769384672435", "event_type": "price_change"}}
{"_local_timestamp": "2026-01-25T23:44:35.060622+00:00", "data": {"market": "0x3b41890d5e8c9640649a9e6f724d1f74aa67af855506db6f871c5fdac70cfd90", "price_changes": [{"asset_id": "88830742474573630269392959399954338068265843991617686189000213034050940973037", "price": "0.36", "size": "0", "side": "BUY", "hash": "720317cc40f86b74d97d969fc868a80b2f2831e0", "best_bid": "0.39", "best_ask": "0.4"}, {"asset_id": "24393720551520374522532949229976185621516426573885698267923116722310834739486", "price": "0.64", "size": "0", "side": "SELL", "hash": "da42c7e3d04948d42ebe67fcc3d1987c8dd83db4", "best_bid": "0.6", "best_ask": "0.61"}], "timestamp": "1769384674782", "event_type": "price_change"}}
{"_local_timestamp": "2026-01-25T23:44:35.666918+00:00", "data": {"market": "0x3b41890d5e8c9640649a9e6f724d1f74aa67af855506db6f871c5fdac70cfd90", "price_changes": [{"asset_id": "88830742474573630269392959399954338068265843991617686189000213034050940973037", "price": "0.34", "size": "100", "side": "BUY", "hash": "e97d8487fe1e42a46664b6a66d409beaca30bcfe", "best_bid": "0.39", "best_ask": "0.4"}, {"asset_id": "24393720551520374522532949229976185621516426573885698267923116722310834739486", "price": "0.66", "size": "100", "side": "SELL", "hash": "bc07d8bf0022a7710554db12865b3ceed31f0375", "best_bid": "0.6", "best_ask": "0.61"}], "timestamp": "1769384675390", "event_type": "price_change"}}
{"_local_timestamp": "2026-01-25T23:44:35.701930+00:00", "data": {"market": "0x3b41890d5e8c9640649a9e6f724d1f74aa67af855506db6f871c5fdac70cfd90", "price_changes": [{"asset_id": "24393720551520374522532949229976185621516426573885698267923116722310834739486", "price": "0.67", "size": "100", "side": "SELL", "hash": "66d27b980d8dadaa08be0808fe5b931844d4d651", "best_bid": "0.6", "best_ask": "0.61"}, {"asset_id": "88830742474573630269392959399954338068265843991617686189000213034050940973037", "price": "0.33", "size": "100", "side": "BUY", "hash": "8c2d2171a7e1864646540ecb8b09bf5e91413b5e", "best_bid": "0.39", "best_ask": "0.4"}], "timestamp": "1769384675414", "event_type": "price_change"}}
{"_local_timestamp": "2026-01-25T23:44:35.729632+00:00", "data": {"market": "0x3b41890d5e8c9640649a9e6f724d1f74aa67af855506db6f871c5fdac70cfd90", "price_changes": [{"asset_id": "24393720551520374522532949229976185621516426573885698267923116722310834739486", "price": "0.65", "size": "283", "side": "SELL", "hash": "9c5c6749fcbb589e233b40dab8a7a969a93e198f", "best_bid": "0.6", "best_ask": "0.61"}, {"asset_id": "88830742474573630269392959399954338068265843991617686189000213034050940973037", "price": "0.35", "size": "283", "side": "BUY", "hash": "d8d3cd65ed87d8e7ccdc0a0eb8527fa77a9708e5", "best_bid": "0.39", "best_ask": "0.4"}], "timestamp": "1769384675446", "event_type": "price_change"}}
{"_local_timestamp": "2026-01-25T23:44:39.453911+00:00", "data": {"market": "0x3b41890d5e8c9640649a9e6f724d1f74aa67af855506db6f871c5fdac70cfd90", "price_changes": [{"asset_id": "88830742474573630269392959399954338068265843991617686189000213034050940973037", "price": "0.34", "size": "0", "side": "BUY", "hash": "9f9ef66886edf12b22ec4c11bbe3447873f674b7", "best_bid": "0.39", "best_ask": "0.4"}, {"asset_id": "24393720551520374522532949229976185621516426573885698267923116722310834739486", "price": "0.66", "size": "0", "side": "SELL", "hash": "95803c24b64786b8b75ee4e52c5df07b249c7ab3", "best_bid": "0.6", "best_ask": "0.61"}], "timestamp": "1769384679158", "event_type": "price_change"}}
{"_local_timestamp": "2026-01-25T23:44:40.120322+00:00", "data": {"market": "0x3b41890d5e8c9640649a9e6f724d1f74aa67af855506db6f871c5fdac70cfd90", "price_changes": [{"asset_id": "88830742474573630269392959399954338068265843991617686189000213034050940973037", "price": "0.36", "size": "100", "side": "BUY", "hash": "71f58b306593a19c90583d6d08cbd8fd4133bb0b", "best_bid": "0.39", "best_ask": "0.4"}, {"asset_id": "24393720551520374522532949229976185621516426573885698267923116722310834739486", "price": "0.64", "size": "100", "side": "SELL", "hash": "2b036d349e2d4c2f6cea68416c4a5490ac0ad8d5", "best_bid": "0.6", "best_ask": "0.61"}], "timestamp": "1769384679839", "event_type": "price_change"}}
{"_local_timestamp": "2026-01-25T23:44:57.107786+00:00", "data": {"market": "0x3b41890d5e8c9640649a9e6f724d1f74aa67af855506db6f871c5fdac70cfd90", "price_changes": [{"asset_id": "24393720551520374522532949229976185621516426573885698267923116722310834739486", "price": "0.52", "size": "37.15", "side": "BUY", "hash": "5897ef8ff94fdfb420c8796782457a91bbdc3708", "best_bid": "0.6", "best_ask": "0.61"}, {"asset_id": "88830742474573630269392959399954338068265843991617686189000213034050940973037", "price": "0.48", "size": "37.15", "side": "SELL", "hash": "20d8725c9ac00910bce5f1db6a134ec341aabaf4", "best_bid": "0.39", "best_ask": "0.4"}], "timestamp": "1769384697000", "event_type": "price_change"}}
{"_local_timestamp": "2026-01-25T23:44:57.124479+00:00", "data": {"market": "0x3b41890d5e8c9640649a9e6f724d1f74aa67af855506db6f871c5fdac70cfd90", "price_changes": [{"asset_id": "24393720551520374522532949229976185621516426573885698267923116722310834739486", "price": "0.38", "size": "116.14", "side": "BUY", "hash": "f5568cb7f70c60f2caa58916b7aa78e4cef06851", "best_bid": "0.6", "best_ask": "0.61"}, {"asset_id": "88830742474573630269392959399954338068265843991617686189000213034050940973037", "price": "0.62", "size": "116.14", "side": "SELL", "hash": "a1aa36881ae41b2e42ad0a151dbe7a100d1a8116", "best_bid": "0.39", "best_ask": "0.4"}], "timestamp": "1769384697004", "event_type": "price_change"}}
{"_local_timestamp": "2026-01-25T23:44:57.159485+00:00", "data": {"market": "0x3b41890d5e8c9640649a9e6f724d1f74aa67af855506db6f871c5fdac70cfd90", "price_changes": [{"asset_id": "24393720551520374522532949229976185621516426573885698267923116722310834739486", "price": "0.65", "size": "0", "side": "SELL", "hash": "6fc7ea3fa2cdf1eb94d1f3305e2692ace704a054", "best_bid": "0.6", "best_ask": "0.61"}, {"asset_id": "88830742474573630269392959399954338068265843991617686189000213034050940973037", "price": "0.35", "size": "0", "side": "BUY", "hash": "7a08567da05c3f20ffdf3ffb666f8f9b13d3bfab", "best_bid": "0.39", "best_ask": "0.4"}], "timestamp": "1769384697055", "event_type": "price_change"}}
{"_local_timestamp": "2026-01-25T23:44:57.175847+00:00", "data": {"market": "0x3b41890d5e8c9640649a9e6f724d1f74aa67af855506db6f871c5fdac70cfd90", "price_changes": [{"asset_id": "24393720551520374522532949229976185621516426573885698267923116722310834739486", "price": "0.67", "size": "353", "side": "SELL", "hash": "d3a586448921bd383be010062a192686ba18bbbc", "best_bid": "0.6", "best_ask": "0.61"}, {"asset_id": "88830742474573630269392959399954338068265843991617686189000213034050940973037", "price": "0.33", "size": "353", "side": "BUY", "hash": "798ce4037e84417d84dbb012580b5d52c4f0378a", "best_bid": "0.39", "best_ask": "0.4"}], "timestamp": "1769384697084", "event_type": "price_change"}}
{"_local_timestamp": "2026-01-25T23:44:57.872008+00:00", "data": {"market": "0x3b41890d5e8c9640649a9e6f724d1f74aa67af855506db6f871c5fdac70cfd90", "price_changes": [{"asset_id": "24393720551520374522532949229976185621516426573885698267923116722310834739486", "price": "0.27", "size": "0", "side": "BUY", "hash": "b9b5feaeca0bc5d274e36b9aeada6361fb8ac800", "best_bid": "0.6", "best_ask": "0.61"}, {"asset_id": "88830742474573630269392959399954338068265843991617686189000213034050940973037", "price": "0.73", "size": "0", "side": "SELL", "hash": "d664624b9e0a163c1ec98f1bb74d0e5ad10ea929", "best_bid": "0.39", "best_ask": "0.4"}], "timestamp": "1769384697751", "event_type": "price_change"}}
{"_local_timestamp": "2026-01-25T23:44:58.395942+00:00", "data": {"market": "0x3b41890d5e8c9640649a9e6f724d1f74aa67af855506db6f871c5fdac70cfd90", "price_changes": [{"asset_id": "24393720551520374522532949229976185621516426573885698267923116722310834739486", "price": "0.28", "size": "50", "side": "BUY", "hash": "95ad0eb8cd49c527cba72c7e4b33d9f251fcaa42", "best_bid": "0.6", "best_ask": "0.61"}, {"asset_id": "88830742474573630269392959399954338068265843991617686189000213034050940973037", "price": "0.72", "size": "50", "side": "SELL", "hash": "7746f8d15d7b335431d7e6ab3359916e9865ef0a", "best_bid": "0.39", "best_ask": "0.4"}], "timestamp": "1769384698231", "event_type": "price_change"}}
{"_local_timestamp": "2026-01-25T23:45:01.617306+00:00", "data": {"market": "0x3b41890d5e8c9640649a9e6f724d1f74aa67af855506db6f871c5fdac70cfd90", "price_changes": [{"asset_id": "88830742474573630269392959399954338068265843991617686189000213034050940973037", "price": "0.36", "size": "0", "side": "BUY", "hash": "d4838f7ea72d3ea9a87304651771f440efc9db75", "best_bid": "0.39", "best_ask": "0.4"}, {"asset_id": "24393720551520374522532949229976185621516426573885698267923116722310834739486", "price": "0.64", "size": "0", "side": "SELL", "hash": "c134c56dc1e40ea82c5cdd5a529fb1b2c548f997", "best_bid": "0.6", "best_ask": "0.61"}], "timestamp": "1769384701541", "event_type": "price_change"}}
{"_local_timestamp": "2026-01-25T23:45:02.028439+00:00", "data": {"market": "0xdd9f55a4a214da7231a64eb6f43a05f525b51e7bcf714db0c2d3b2fd0fc0c9ca", "price_changes": [{"asset_id": "87855193300342526755310181206520215785023964324419734896948555881922627101363", "price": "0.66", "size": "57.57", "side": "BUY", "hash": "3b660ce582e4f0f814c96b31e965970333f762e3", "best_bid": "0.67", "best_ask": "0.76"}, {"asset_id": "18582106713580348058065911013375325630183346495483834588274922531241537980162", "price": "0.34", "size": "57.57", "side": "SELL", "hash": "9fa4ac102d6dbd2c497ba5f6982d8544cd1586b5", "best_bid": "0.24", "best_ask": "0.33"}], "timestamp": "1769384701947", "event_type": "price_change"}}
{"_local_timestamp": "2026-01-25T23:45:02.290759+00:00", "data": {"market": "0x3b41890d5e8c9640649a9e6f724d1f74aa67af855506db6f871c5fdac70cfd90", "price_changes": [{"asset_id": "88830742474573630269392959399954338068265843991617686189000213034050940973037", "price": "0.34", "size": "100", "side": "BUY", "hash": "387825ba5378dd9ebdd0678a9e9e426cc569dc73", "best_bid": "0.39", "best_ask": "0.4"}, {"asset_id": "24393720551520374522532949229976185621516426573885698267923116722310834739486", "price": "0.66", "size": "100", "side": "SELL", "hash": "cdc64efe6f69648e8747d31e3e87553324aa06c0", "best_bid": "0.6", "best_ask": "0.61"}], "timestamp": "1769384702224", "event_type": "price_change"}}
{"_local_timestamp": "2026-01-25T23:45:02.320792+00:00", "data": {"market": "0x3b41890d5e8c9640649a9e6f724d1f74aa67af855506db6f871c5fdac70cfd90", "price_changes": [{"asset_id": "24393720551520374522532949229976185621516426573885698267923116722310834739486", "price": "0.67", "size": "100", "side": "SELL", "hash": "2ae0b2e864139633e18d0a614c41beda51996af8", "best_bid": "0.6", "best_ask": "0.61"}, {"asset_id": "88830742474573630269392959399954338068265843991617686189000213034050940973037", "price": "0.33", "size": "100", "side": "BUY", "hash": "e909660519d56bcd7bbe4c4572bf893178b20dba", "best_bid": "0.39", "best_ask": "0.4"}], "timestamp": "1769384702253", "event_type": "price_change"}}
{"_local_timestamp": "2026-01-25T23:45:02.359202+00:00", "data": {"market": "0x3b41890d5e8c9640649a9e6f724d1f74aa67af855506db6f871c5fdac70cfd90", "price_changes": [{"asset_id": "24393720551520374522532949229976185621516426573885698267923116722310834739486", "price": "0.65", "size": "283", "side": "SELL", "hash": "319a75742faa1c054b96d93e22fc672c38100b48", "best_bid": "0.6", "best_ask": "0.61"}, {"asset_id": "88830742474573630269392959399954338068265843991617686189000213034050940973037", "price": "0.35", "size": "283", "side": "BUY", "hash": "9afd9a6e02f68e9072f25e5f57eb29dd5d024b36", "best_bid": "0.39", "best_ask": "0.4"}], "timestamp": "1769384702290", "event_type": "price_change"}}
{"_local_timestamp": "2026-01-25T23:45:05.988597+00:00", "data": {"market": "0xdd9f55a4a214da7231a64eb6f43a05f525b51e7bcf714db0c2d3b2fd0fc0c9ca", "price_changes": [{"asset_id": "87855193300342526755310181206520215785023964324419734896948555881922627101363", "price": "0.18", "size": "99.99", "side": "BUY", "hash": "74607e28bee5ea3c7c6b78738f5c24acf6d3bfca", "best_bid": "0.67", "best_ask": "0.76"}, {"asset_id": "18582106713580348058065911013375325630183346495483834588274922531241537980162", "price": "0.82", "size": "99.99", "side": "SELL", "hash": "111d5c67860fc30fc114dac432844e2bbfc0e8f5", "best_bid": "0.24", "best_ask": "0.33"}], "timestamp": "1769384705916", "event_type": "price_change"}}
{"_local_timestamp": "2026-01-25T23:45:05.993265+00:00", "data": {"market": "0x3b41890d5e8c9640649a9e6f724d1f74aa67af855506db6f871c5fdac70cfd90", "price_changes": [{"asset_id": "88830742474573630269392959399954338068265843991617686189000213034050940973037", "price": "0.34", "size": "0", "side": "BUY", "hash": "c264dc6d78a01e08d33722b99c16fce887e166b5", "best_bid": "0.39", "best_ask": "0.4"}, {"asset_id": "24393720551520374522532949229976185621516426573885698267923116722310834739486", "price": "0.66", "size": "0", "side": "SELL", "hash": "8a0a4e6c24f6627acccca309d6986e06aaed9dbb", "best_bid": "0.6", "best_ask": "0.61"}], "timestamp": "1769384705918", "event_type": "price_change"}}
{"_local_timestamp": "2026-01-25T23:45:05.994257+00:00", "data": {"market": "0x3b41890d5e8c9640649a9e6f724d1f74aa67af855506db6f871c5fdac70cfd90", "price_changes": [{"asset_id": "24393720551520374522532949229976185621516426573885698267923116722310834739486", "price": "0.38", "size": "121.14", "side": "BUY", "hash": "6f4e138a0730847dffba6158e0a7a20db6d838b3", "best_bid": "0.6", "best_ask": "0.61"}, {"asset_id": "88830742474573630269392959399954338068265843991617686189000213034050940973037", "price": "0.62", "size": "121.14", "side": "SELL", "hash": "ba526546629176f2260d932ea136e9ae93063aa7", "best_bid": "0.39", "best_ask": "0.4"}], "timestamp": "1769384705922", "event_type": "price_change"}}
{"_local_timestamp": "2026-01-25T23:45:05.998823+00:00", "data": {"market": "0x3b41890d5e8c9640649a9e6f724d1f74aa67af855506db6f871c5fdac70cfd90", "price_changes": [{"asset_id": "24393720551520374522532949229976185621516426573885698267923116722310834739486", "price": "0.52", "size": "60.15", "side": "BUY", "hash": "7d182010b412003602aede86656a4940ededdcaf", "best_bid": "0.6", "best_ask": "0.61"}, {"asset_id": "88830742474573630269392959399954338068265843991617686189000213034050940973037", "price": "0.48", "size": "60.15", "side": "SELL", "hash": "0a61a2c217185791ef722966f08d1ccd7fe2281a", "best_bid": "0.39", "best_ask": "0.4"}], "timestamp": "1769384705926", "event_type": "price_change"}}
{"_local_timestamp": "2026-01-25T23:45:06.516017+00:00", "data": {"market": "0xdd9f55a4a214da7231a64eb6f43a05f525b51e7bcf714db0c2d3b2fd0fc0c9ca", "price_changes": [{"asset_id": "87855193300342526755310181206520215785023964324419734896948555881922627101363", "price": "0.67", "size": "133.42", "side": "BUY", "hash": "9b9026bbced8c0afc4493088fac356a20268ab64", "best_bid": "0.67", "best_ask": "0.76"}, {"asset_id": "18582106713580348058065911013375325630183346495483834588274922531241537980162", "price": "0.33", "size": "133.42", "side": "SELL", "hash": "27fa18ec891872ff3331ad0f89caed6c641b7256", "best_bid": "0.24", "best_ask": "0.33"}], "timestamp": "1769384706447", "event_type": "price_change"}}
{"_local_timestamp": "2026-01-25T23:45:06.556792+00:00", "data": {"market": "0x3b41890d5e8c9640649a9e6f724d1f74aa67af855506db6f871c5fdac70cfd90", "price_changes": [{"asset_id": "88830742474573630269392959399954338068265843991617686189000213034050940973037", "price": "0.36", "size": "100", "side": "BUY", "hash": "d7c95c748db209d36ca3958382b203ab4f83f26e", "best_bid": "0.39", "best_ask": "0.4"}, {"asset_id": "24393720551520374522532949229976185621516426573885698267923116722310834739486", "price": "0.64", "size": "100", "side": "SELL", "hash": "7f70bc0423105ee4318db797d81050285061f975", "best_bid": "0.6", "best_ask": "0.61"}], "timestamp": "1769384706486", "event_type": "price_change"}}
{"_local_timestamp": "2026-01-25T23:45:07.084522+00:00", "data": {"market": "0x3b41890d5e8c9640649a9e6f724d1f74aa67af855506db6f871c5fdac70cfd90", "price_changes": [{"asset_id": "24393720551520374522532949229976185621516426573885698267923116722310834739486", "price": "0.52", "size": "51.15", "side": "BUY", "hash": "e4711167bb6f1aa29caa4af799964fba389cb529", "best_bid": "0.6", "best_ask": "0.61"}, {"asset_id": "88830742474573630269392959399954338068265843991617686189000213034050940973037", "price": "0.48", "size": "51.15", "side": "SELL", "hash": "2bb59573e784b5dba8935cc6fb1fe5a6e4f82783", "best_bid": "0.39", "best_ask": "0.4"}], "timestamp": "1769384707000", "event_type": "price_change"}}
{"_local_timestamp": "2026-01-25T23:45:07.085304+00:00", "data": {"market": "0x3b41890d5e8c9640649a9e6f724d1f74aa67af855506db6f871c5fdac70cfd90", "price_changes": [{"asset_id": "24393720551520374522532949229976185621516426573885698267923116722310834739486", "price": "0.38", "size": "100.14", "side": "BUY", "hash": "7185d12503b7ffabd00fab8909e3878fa9219f98", "best_bid": "0.6", "best_ask": "0.61"}, {"asset_id": "88830742474573630269392959399954338068265843991617686189000213034050940973037", "price": "0.62", "size": "100.14", "side": "SELL", "hash": "11ff50475f4f3090ce8cf36881fa11c392d639b8", "best_bid": "0.39", "best_ask": "0.4"}], "timestamp": "1769384707004", "event_type": "price_change"}}
{"_local_timestamp": "2026-01-25T23:45:10.635858+00:00", "data": {"market": "0x3b41890d5e8c9640649a9e6f724d1f74aa67af855506db6f871c5fdac70cfd90", "price_changes": [{"asset_id": "24393720551520374522532949229976185621516426573885698267923116722310834739486", "price": "0.18", "size": "2582", "side": "BUY", "hash": "552621ba000887b7115d1ce87d6264f1a2cac7fb", "best_bid": "0.6", "best_ask": "0.61"}, {"asset_id": "88830742474573630269392959399954338068265843991617686189000213034050940973037", "price": "0.82", "size": "2582", "side": "SELL", "hash": "c832e3504556f2efcd24169640b423639fcee849", "best_bid": "0.39", "best_ask": "0.4"}], "timestamp": "1769384710567", "event_type": "price_change"}}
{"_local_timestamp": "2026-01-25T23:45:38.927985+00:00", "data": {"market": "0x3b41890d5e8c9640649a9e6f724d1f74aa67af855506db6f871c5fdac70cfd90", "price_changes": [{"asset_id": "24393720551520374522532949229976185621516426573885698267923116722310834739486", "price": "0.19", "size": "0", "side": "BUY", "hash": "a3c411ca3bc4154fffaf96c3fa80b8c896b36b37", "best_bid": "0.6", "best_ask": "0.61"}, {"asset_id": "88830742474573630269392959399954338068265843991617686189000213034050940973037", "price": "0.81", "size": "0", "side": "SELL", "hash": "d90cd5e4093d4cffbad590d1d32747b7c5469983", "best_bid": "0.39", "best_ask": "0.4"}], "timestamp": "1769384738819", "event_type": "price_change"}}
{"_local_timestamp": "2026-01-25T23:45:38.986124+00:00", "data": {"market": "0x3b41890d5e8c9640649a9e6f724d1f74aa67af855506db6f871c5fdac70cfd90", "price_changes": [{"asset_id": "24393720551520374522532949229976185621516426573885698267923116722310834739486", "price": "0.65", "size": "0", "side": "SELL", "hash": "50d274b783fbfe1c229d79a30b12acc0d2292914", "best_bid": "0.6", "best_ask": "0.61"}, {"asset_id": "88830742474573630269392959399954338068265843991617686189000213034050940973037", "price": "0.35", "size": "0", "side": "BUY", "hash": "c5326b204195aefc8435dba1048ea49d842eec74", "best_bid": "0.39", "best_ask": "0.4"}], "timestamp": "1769384738884", "event_type": "price_change"}}
{"_local_timestamp": "2026-01-25T23:45:38.992217+00:00", "data": {"market": "0x3b41890d5e8c9640649a9e6f724d1f74aa67af855506db6f871c5fdac70cfd90", "price_changes": [{"asset_id": "24393720551520374522532949229976185621516426573885698267923116722310834739486", "price": "0.67", "size": "383", "side": "SELL", "hash": "6adfdc2a53b956e0a58c518cb23fdaafe72586b0", "best_bid": "0.6", "best_ask": "0.61"}, {"asset_id": "88830742474573630269392959399954338068265843991617686189000213034050940973037", "price": "0.33", "size": "383", "side": "BUY", "hash": "ef7c17949b6d6042091a89775373cbde53132126", "best_bid": "0.39", "best_ask": "0.4"}], "timestamp": "1769384738909", "event_type": "price_change"}}
{"_local_timestamp": "2026-01-25T23:45:39.217841+00:00", "data": {"market": "0x3b41890d5e8c9640649a9e6f724d1f74aa67af855506db6f871c5fdac70cfd90", "price_changes": [{"asset_id": "24393720551520374522532949229976185621516426573885698267923116722310834739486", "price": "0.18", "size": "2732", "side": "BUY", "hash": "fa30b0df3294f67944c0fba17a08386ffc317729", "best_bid": "0.6", "best_ask": "0.61"}, {"asset_id": "88830742474573630269392959399954338068265843991617686189000213034050940973037", "price": "0.82", "size": "2732", "side": "SELL", "hash": "bb1b6bc023761373e3521c8be7802114729bc234", "best_bid": "0.39", "best_ask": "0.4"}], "timestamp": "1769384739089", "event_type": "price_change"}}
{"_local_timestamp": "2026-01-25T23:45:40.486575+00:00", "data": {"market": "0x3b41890d5e8c9640649a9e6f724d1f74aa67af855506db6f871c5fdac70cfd90", "price_changes": [{"asset_id": "88830742474573630269392959399954338068265843991617686189000213034050940973037", "price": "0.36", "size": "0", "side": "BUY", "hash": "490f55e4b5edd33e8af1d4d327db91490c99ead1", "best_bid": "0.39", "best_ask": "0.4"}, {"asset_id": "24393720551520374522532949229976185621516426573885698267923116722310834739486", "price": "0.64", "size": "0", "side": "SELL", "hash": "c20fa52d93b4278d42fce44bfcca2e8881ba8dda", "best_bid": "0.6", "best_ask": "0.61"}], "timestamp": "1769384740415", "event_type": "price_change"}}
{"_local_timestamp": "2026-01-25T23:45:41.054003+00:00", "data": {"market": "0x3b41890d5e8c9640649a9e6f724d1f74aa67af855506db6f871c5fdac70cfd90", "price_changes": [{"asset_id": "88830742474573630269392959399954338068265843991617686189000213034050940973037", "price": "0.34", "size": "100", "side": "BUY", "hash": "f026db3c9356d383cf04702d4a7035a484c06db2", "best_bid": "0.39", "best_ask": "0.4"}, {"asset_id": "24393720551520374522532949229976185621516426573885698267923116722310834739486", "price": "0.66", "size": "100", "side": "SELL", "hash": "238b7c01372658ebf97dbd631f91968a33898b40", "best_bid": "0.6", "best_ask": "0.61"}], "timestamp": "1769384740986", "event_type": "price_change"}}
{"_local_timestamp": "2026-01-25T23:45:41.127546+00:00", "data": {"market": "0x3b41890d5e8c9640649a9e6f724d1f74aa67af855506db6f871c5fdac70cfd90", "price_changes": [{"asset_id": "24393720551520374522532949229976185621516426573885698267923116722310834739486", "price": "0.67", "size": "100", "side": "SELL", "hash": "74a3d93f9c31e6ca0fa711176044eb3d30584916", "best_bid": "0.6", "best_ask": "0.61"}, {"asset_id": "88830742474573630269392959399954338068265843991617686189000213034050940973037", "price": "0.33", "size": "100", "side": "BUY", "hash": "53a7e65836c8f07ac5708009fb2711271b0d2500", "best_bid": "0.39", "best_ask": "0.4"}], "timestamp": "1769384741011", "event_type": "price_change"}}
{"_local_timestamp": "2026-01-25T23:45:41.130284+00:00", "data": {"market": "0x3b41890d5e8c9640649a9e6f724d1f74aa67af855506db6f871c5fdac70cfd90", "price_changes": [{"asset_id": "24393720551520374522532949229976185621516426573885698267923116722310834739486", "price": "0.65", "size": "283", "side": "SELL", "hash": "c5593945ddd136bf2124ee4a0580f41e25c76446", "best_bid": "0.6", "best_ask": "0.61"}, {"asset_id": "88830742474573630269392959399954338068265843991617686189000213034050940973037", "price": "0.35", "size": "283", "side": "BUY", "hash": "c7487033a19a0663baca19692cb9a8faf248b14b", "best_bid": "0.39", "best_ask": "0.4"}], "timestamp": "1769384741039", "event_type": "price_change"}}
{"_local_timestamp": "2026-01-25T23:45:44.736918+00:00", "data": {"market": "0x3b41890d5e8c9640649a9e6f724d1f74aa67af855506db6f871c5fdac70cfd90", "price_changes": [{"asset_id": "88830742474573630269392959399954338068265843991617686189000213034050940973037", "price": "0.34", "size": "0", "side": "BUY", "hash": "f6ac0177c82134a48221963af8c48a95124aaeb3", "best_bid": "0.39", "best_ask": "0.4"}, {"asset_id": "24393720551520374522532949229976185621516426573885698267923116722310834739486", "price": "0.66", "size": "0", "side": "SELL", "hash": "6f4fabaebfe7aa6cc1bc30a42b3972a59702ff32", "best_bid": "0.6", "best_ask": "0.61"}], "timestamp": "1769384744667", "event_type": "price_change"}}
{"_local_timestamp": "2026-01-25T23:45:45.337078+00:00", "data": {"market": "0x3b41890d5e8c9640649a9e6f724d1f74aa67af855506db6f871c5fdac70cfd90", "price_changes": [{"asset_id": "88830742474573630269392959399954338068265843991617686189000213034050940973037", "price": "0.36", "size": "100", "side": "BUY", "hash": "3bfdd6d8bd3b88ffe283b4bc5a96aa58f5a962e6", "best_bid": "0.39", "best_ask": "0.4"}, {"asset_id": "24393720551520374522532949229976185621516426573885698267923116722310834739486", "price": "0.64", "size": "100", "side": "SELL", "hash": "7313e01e17a48f8e4d33142a7419aa411af3f250", "best_bid": "0.6", "best_ask": "0.61"}], "timestamp": "1769384745270", "event_type": "price_change"}}
{"_local_timestamp": "2026-01-25T23:45:53.178119+00:00", "data": {"market": "0xdd9f55a4a214da7231a64eb6f43a05f525b51e7bcf714db0c2d3b2fd0fc0c9ca", "price_changes": [{"asset_id": "87855193300342526755310181206520215785023964324419734896948555881922627101363", "price": "0.29", "size": "200", "side": "BUY", "hash": "d5c2e49674fd95a9bef873f7c8f582badf1f4fce", "best_bid": "0.67", "best_ask": "0.76"}, {"asset_id": "18582106713580348058065911013375325630183346495483834588274922531241537980162", "price": "0.71", "size": "200", "side": "SELL", "hash": "a57771261e7cc3c07334cca43652ed50927525c3", "best_bid": "0.24", "best_ask": "0.33"}], "timestamp": "1769384753010", "event_type": "price_change"}}
{"_local_timestamp": "2026-01-25T23:45:53.201187+00:00", "data": {"market": "0x3b41890d5e8c9640649a9e6f724d1f74aa67af855506db6f871c5fdac70cfd90", "price_changes": [{"asset_id": "24393720551520374522532949229976185621516426573885698267923116722310834739486", "price": "0.18", "size": "2632", "side": "BUY", "hash": "b466d76015d16153943fca1afb36bc11eecf83dd", "best_bid": "0.6", "best_ask": "0.61"}, {"asset_id": "88830742474573630269392959399954338068265843991617686189000213034050940973037", "price": "0.82", "size": "2632", "side": "SELL", "hash": "aec73c50772afe581e7056942341ace79a45e9ed", "best_bid": "0.39", "best_ask": "0.4"}], "timestamp": "1769384753010", "event_type": "price_change"}}
{"_local_timestamp": "2026-01-25T23:45:53.351463+00:00", "data": {"market": "0x3b41890d5e8c9640649a9e6f724d1f74aa67af855506db6f871c5fdac70cfd90", "price_changes": [{"asset_id": "24393720551520374522532949229976185621516426573885698267923116722310834739486", "price": "0.65", "size": "0", "side": "SELL", "hash": "b7b539fb72d53c39e0cdf5143ab87fe9e737ebd4", "best_bid": "0.6", "best_ask": "0.61"}, {"asset_id": "88830742474573630269392959399954338068265843991617686189000213034050940973037", "price": "0.35", "size": "0", "side": "BUY", "hash": "f1945571b505fb98d2107f45146e36ab534e97b7", "best_bid": "0.39", "best_ask": "0.4"}], "timestamp": "1769384753157", "event_type": "price_change"}}
{"_local_timestamp": "2026-01-25T23:45:53.354613+00:00", "data": {"market": "0x3b41890d5e8c9640649a9e6f724d1f74aa67af855506db6f871c5fdac70cfd90", "price_changes": [{"asset_id": "24393720551520374522532949229976185621516426573885698267923116722310834739486", "price": "0.67", "size": "383", "side": "SELL", "hash": "996cd8dd93654953d5fe6151f5ef5a13a85fdf22", "best_bid": "0.6", "best_ask": "0.61"}, {"asset_id": "88830742474573630269392959399954338068265843991617686189000213034050940973037", "price": "0.33", "size": "383", "side": "BUY", "hash": "8ab7b4cb200b6efdd642325f41d0a2576115db36", "best_bid": "0.39", "best_ask": "0.4"}], "timestamp": "1769384753183", "event_type": "price_change"}}
{"_local_timestamp": "2026-01-25T23:45:53.678292+00:00", "data": {"market": "0x3b41890d5e8c9640649a9e6f724d1f74aa67af855506db6f871c5fdac70cfd90", "price_changes": [{"asset_id": "24393720551520374522532949229976185621516426573885698267923116722310834739486", "price": "0.19", "size": "100", "side": "BUY", "hash": "af559f363dbb0619131243e011fb64244ba0cb80", "best_bid": "0.6", "best_ask": "0.61"}, {"asset_id": "88830742474573630269392959399954338068265843991617686189000213034050940973037", "price": "0.81", "size": "100", "side": "SELL", "hash": "9b24280f26123586e47b7726668c82165fb4196c", "best_bid": "0.39", "best_ask": "0.4"}], "timestamp": "1769384753521", "event_type": "price_change"}}
{"_local_timestamp": "2026-01-25T23:45:57.343582+00:00", "data": {"market": "0x3b41890d5e8c9640649a9e6f724d1f74aa67af855506db6f871c5fdac70cfd90", "price_changes": [{"asset_id": "88830742474573630269392959399954338068265843991617686189000213034050940973037", "price": "0.36", "size": "0", "side": "BUY", "hash": "96aa5d0cbed1b38dc2d1635daa49747a02c51a7c", "best_bid": "0.39", "best_ask": "0.4"}, {"asset_id": "24393720551520374522532949229976185621516426573885698267923116722310834739486", "price": "0.64", "size": "0", "side": "SELL", "hash": "aada994ec8294e7552f3675fca4c2c93f606eb05", "best_bid": "0.6", "best_ask": "0.61"}], "timestamp": "1769384757110", "event_type": "price_change"}}
{"_local_timestamp": "2026-01-25T23:45:57.832641+00:00", "data": {"market": "0x3b41890d5e8c9640649a9e6f724d1f74aa67af855506db6f871c5fdac70cfd90", "price_changes": [{"asset_id": "88830742474573630269392959399954338068265843991617686189000213034050940973037", "price": "0.34", "size": "100", "side": "BUY", "hash": "27516962f2d47a968173d8d9f6b303e653c9f417", "best_bid": "0.39", "best_ask": "0.4"}, {"asset_id": "24393720551520374522532949229976185621516426573885698267923116722310834739486", "price": "0.66", "size": "100", "side": "SELL", "hash": "d8d61382ff9175a03aeb0a1d59dc6edbb454120d", "best_bid": "0.6", "best_ask": "0.61"}], "timestamp": "1769384757757", "event_type": "price_change"}}
{"_local_timestamp": "2026-01-25T23:45:57.866203+00:00", "data": {"market": "0x3b41890d5e8c9640649a9e6f724d1f74aa67af855506db6f871c5fdac70cfd90", "price_changes": [{"asset_id": "24393720551520374522532949229976185621516426573885698267923116722310834739486", "price": "0.67", "size": "100", "side": "SELL", "hash": "e5604a616f0c299641ffe39dff6bb93e0aed009e", "best_bid": "0.6", "best_ask": "0.61"}, {"asset_id": "88830742474573630269392959399954338068265843991617686189000213034050940973037", "price": "0.33", "size": "100", "side": "BUY", "hash": "9cc2a6f64fea56755d1650aa99d961d65bbc663e", "best_bid": "0.39", "best_ask": "0.4"}], "timestamp": "1769384757782", "event_type": "price_change"}}
{"_local_timestamp": "2026-01-25T23:45:57.888165+00:00", "data": {"market": "0x3b41890d5e8c9640649a9e6f724d1f74aa67af855506db6f871c5fdac70cfd90", "price_changes": [{"asset_id": "24393720551520374522532949229976185621516426573885698267923116722310834739486", "price": "0.65", "size": "283", "side": "SELL", "hash": "3fa415bdc754efd5b4f9e6a0631d03358a664083", "best_bid": "0.6", "best_ask": "0.61"}, {"asset_id": "88830742474573630269392959399954338068265843991617686189000213034050940973037", "price": "0.35", "size": "283", "side": "BUY", "hash": "f5479ac8345979b142c2cb2090d60413ea62f0b2", "best_bid": "0.39", "best_ask": "0.4"}], "timestamp": "1769384757808", "event_type": "price_change"}}
{"_local_timestamp": "2026-01-25T23:45:58.969917+00:00", "data": {"market": "0x3b41890d5e8c9640649a9e6f724d1f74aa67af855506db6f871c5fdac70cfd90", "price_changes": [{"asset_id": "24393720551520374522532949229976185621516426573885698267923116722310834739486", "price": "0.53", "size": "25", "side": "BUY", "hash": "29554697d2f71b7d1cf08da258f3bb7e55ed94eb", "best_bid": "0.6", "best_ask": "0.61"}, {"asset_id": "88830742474573630269392959399954338068265843991617686189000213034050940973037", "price": "0.47", "size": "25", "side": "SELL", "hash": "24bcb2dcc2f942835d6fd2d0bd14f85f763275bd", "best_bid": "0.39", "best_ask": "0.4"}], "timestamp": "1769384758893", "event_type": "price_change"}}
{"_local_timestamp": "2026-01-25T23:45:58.970552+00:00", "data": {"market": "0x3b41890d5e8c9640649a9e6f724d1f74aa67af855506db6f871c5fdac70cfd90", "price_changes": [{"asset_id": "24393720551520374522532949229976185621516426573885698267923116722310834739486", "price": "0.23", "size": "900", "side": "BUY", "hash": "93c324aa3650e4eebf4d7c6a26686694471199d4", "best_bid": "0.6", "best_ask": "0.61"}, {"asset_id": "88830742474573630269392959399954338068265843991617686189000213034050940973037", "price": "0.77", "size": "900", "side": "SELL", "hash": "2aa48b5834232daa8ff911ac6e37435e4d493a96", "best_bid": "0.39", "best_ask": "0.4"}], "timestamp": "1769384758894", "event_type": "price_change"}}
{"_local_timestamp": "2026-01-25T23:45:58.971081+00:00", "data": {"market": "0x3b41890d5e8c9640649a9e6f724d1f74aa67af855506db6f871c5fdac70cfd90", "price_changes": [{"asset_id": "24393720551520374522532949229976185621516426573885698267923116722310834739486", "price": "0.52", "size": "71.15", "side": "BUY", "hash": "013d54a143d6519017d957359fa5d3a91455546e", "best_bid": "0.6", "best_ask": "0.61"}, {"asset_id": "88830742474573630269392959399954338068265843991617686189000213034050940973037", "price": "0.48", "size": "71.15", "side": "SELL", "hash": "383b408c5a06cc24a9c0fb0dfca031159319752f", "best_bid": "0.39", "best_ask": "0.4"}], "timestamp": "1769384758895", "event_type": "price_change"}}
{"_local_timestamp": "2026-01-25T23:45:58.971620+00:00", "data": {"market": "0x3b41890d5e8c9640649a9e6f724d1f74aa67af855506db6f871c5fdac70cfd90", "price_changes": [{"asset_id": "24393720551520374522532949229976185621516426573885698267923116722310834739486", "price": "0.38", "size": "155.14", "side": "BUY", "hash": "ed4b98827fc636b8ae75d9c15432fa7652faa5ce", "best_bid": "0.6", "best_ask": "0.61"}, {"asset_id": "88830742474573630269392959399954338068265843991617686189000213034050940973037", "price": "0.62", "size": "155.14", "side": "SELL", "hash": "4cf0c9db6212355d8113df25744dc6a0f59b49d7", "best_bid": "0.39", "best_ask": "0.4"}], "timestamp": "1769384758896", "event_type": "price_change"}}
{"_local_timestamp": "2026-01-25T23:45:58.972234+00:00", "data": {"market": "0x3b41890d5e8c9640649a9e6f724d1f74aa67af855506db6f871c5fdac70cfd90", "price_changes": [{"asset_id": "24393720551520374522532949229976185621516426573885698267923116722310834739486", "price": "0.26", "size": "450", "side": "BUY", "hash": "b4b46b2e26ad4c777c6676faa8258ba18e5c6549", "best_bid": "0.6", "best_ask": "0.61"}, {"asset_id": "88830742474573630269392959399954338068265843991617686189000213034050940973037", "price": "0.74", "size": "450", "side": "SELL", "hash": "568f25fb02e21f4e0816d180e83a3847c17c7d30", "best_bid": "0.39", "best_ask": "0.4"}], "timestamp": "1769384758896", "event_type": "price_change"}}
{"_local_timestamp": "2026-01-25T23:46:01.601113+00:00", "data": {"market": "0x3b41890d5e8c9640649a9e6f724d1f74aa67af855506db6f871c5fdac70cfd90", "price_changes": [{"asset_id": "88830742474573630269392959399954338068265843991617686189000213034050940973037", "price": "0.34", "size": "0", "side": "BUY", "hash": "c972bd1a74be0caf622feecebd2529c9aaff8107", "best_bid": "0.39", "best_ask": "0.4"}, {"asset_id": "24393720551520374522532949229976185621516426573885698267923116722310834739486", "price": "0.66", "size": "0", "side": "SELL", "hash": "a4598b730ba2d4acb3c7b46fd5920b46b997aacb", "best_bid": "0.6", "best_ask": "0.61"}], "timestamp": "1769384761529", "event_type": "price_change"}}
{"_local_timestamp": "2026-01-25T23:46:02.469877+00:00", "data": {"market": "0x3b41890d5e8c9640649a9e6f724d1f74aa67af855506db6f871c5fdac70cfd90", "price_changes": [{"asset_id": "88830742474573630269392959399954338068265843991617686189000213034050940973037", "price": "0.36", "size": "100", "side": "BUY", "hash": "1170f52e53a0f52f31e5b7ed481726180269c620", "best_bid": "0.39", "best_ask": "0.4"}, {"asset_id": "24393720551520374522532949229976185621516426573885698267923116722310834739486", "price": "0.64", "size": "100", "side": "SELL", "hash": "0edc5a6f8c72024252ed38d904e546f35823612c", "best_bid": "0.6", "best_ask": "0.61"}], "timestamp": "1769384762389", "event_type": "price_change"}}
{"_local_timestamp": "2026-01-25T23:46:10.559018+00:00", "data": {"market": "0x3b41890d5e8c9640649a9e6f724d1f74aa67af855506db6f871c5fdac70cfd90", "price_changes": [{"asset_id": "24393720551520374522532949229976185621516426573885698267923116722310834739486", "price": "0.18", "size": "300", "side": "BUY", "hash": "e7b845b885c37bb52ecf040b5fd9eedc51819a9d", "best_bid": "0.6", "best_ask": "0.61"}, {"asset_id": "88830742474573630269392959399954338068265843991617686189000213034050940973037", "price": "0.82", "size": "300", "side": "SELL", "hash": "c52524f1588e6dacab4c1cd57479b4b70b723fbf", "best_bid": "0.39", "best_ask": "0.4"}], "timestamp": "1769384770459", "event_type": "price_change"}}
{"_local_timestamp": "2026-01-25T23:46:10.698428+00:00", "data": {"market": "0x3b41890d5e8c9640649a9e6f724d1f74aa67af855506db6f871c5fdac70cfd90", "price_changes": [{"asset_id": "24393720551520374522532949229976185621516426573885698267923116722310834739486", "price": "0.65", "size": "0", "side": "SELL", "hash": "0c4a8e7951186ee96e9b583c2fa7d69bafe29f2a", "best_bid": "0.6", "best_ask": "0.61"}, {"asset_id": "88830742474573630269392959399954338068265843991617686189000213034050940973037", "price": "0.35", "size": "0", "side": "BUY", "hash": "20b0024229e0f60f3d5efb645e2a62a0ee490e08", "best_bid": "0.39", "best_ask": "0.4"}], "timestamp": "1769384770507", "event_type": "price_change"}}
{"_local_timestamp": "2026-01-25T23:46:10.727530+00:00", "data": {"market": "0x3b41890d5e8c9640649a9e6f724d1f74aa67af855506db6f871c5fdac70cfd90", "price_changes": [{"asset_id": "24393720551520374522532949229976185621516426573885698267923116722310834739486", "price": "0.67", "size": "361", "side": "SELL", "hash": "16e18f2a0ffeec48559a18a1d8336ed066a9310f", "best_bid": "0.6", "best_ask": "0.61"}, {"asset_id": "88830742474573630269392959399954338068265843991617686189000213034050940973037", "price": "0.33", "size": "361", "side": "BUY", "hash": "ed879742020d31c66855a51b21061683f35a507b", "best_bid": "0.39", "best_ask": "0.4"}], "timestamp": "1769384770536", "event_type": "price_change"}}
{"_local_timestamp": "2026-01-25T23:46:14.410056+00:00", "data": {"market": "0x3b41890d5e8c9640649a9e6f724d1f74aa67af855506db6f871c5fdac70cfd90", "price_changes": [{"asset_id": "88830742474573630269392959399954338068265843991617686189000213034050940973037", "price": "0.36", "size": "0", "side": "BUY", "hash": "21f5255c189567c2a1799a312d5143976bcd8892", "best_bid": "0.39", "best_ask": "0.4"}, {"asset_id": "24393720551520374522532949229976185621516426573885698267923116722310834739486", "price": "0.64", "size": "0", "side": "SELL", "hash": "61b4db2e1c001438110688a81b3ce96d158e9894", "best_bid": "0.6", "best_ask": "0.61"}], "timestamp": "1769384774338", "event_type": "price_change"}}
{"_local_timestamp": "2026-01-25T23:46:15.033696+00:00", "data": {"market": "0x3b41890d5e8c9640649a9e6f724d1f74aa67af855506db6f871c5fdac70cfd90", "price_changes": [{"asset_id": "88830742474573630269392959399954338068265843991617686189000213034050940973037", "price": "0.34", "size": "100", "side": "BUY", "hash": "9009fff6913bbac873827c6d2824ab257fb24f07", "best_bid": "0.39", "best_ask": "0.4"}, {"asset_id": "24393720551520374522532949229976185621516426573885698267923116722310834739486", "price": "0.66", "size": "100", "side": "SELL", "hash": "89b19960e259fb364a67528d902ebd31bac0748d", "best_bid": "0.6", "best_ask": "0.61"}], "timestamp": "1769384774967", "event_type": "price_change"}}
{"_local_timestamp": "2026-01-25T23:46:15.063866+00:00", "data": {"market": "0x3b41890d5e8c9640649a9e6f724d1f74aa67af855506db6f871c5fdac70cfd90", "price_changes": [{"asset_id": "24393720551520374522532949229976185621516426573885698267923116722310834739486", "price": "0.67", "size": "100", "side": "SELL", "hash": "1ed587ab40c5e6c01a075da3fc0a0dea0a6f73d2", "best_bid": "0.6", "best_ask": "0.61"}, {"asset_id": "88830742474573630269392959399954338068265843991617686189000213034050940973037", "price": "0.33", "size": "100", "side": "BUY", "hash": "5036dac18f38f0271861da5d71be52e94bdf00d2", "best_bid": "0.39", "best_ask": "0.4"}], "timestamp": "1769384774993", "event_type": "price_change"}}
{"_local_timestamp": "2026-01-25T23:46:15.097815+00:00", "data": {"market": "0x3b41890d5e8c9640649a9e6f724d1f74aa67af855506db6f871c5fdac70cfd90", "price_changes": [{"asset_id": "24393720551520374522532949229976185621516426573885698267923116722310834739486", "price": "0.65", "size": "283", "side": "SELL", "hash": "e3aee39c1f4fe4803879346c45f9040a8fb057fb", "best_bid": "0.6", "best_ask": "0.61"}, {"asset_id": "88830742474573630269392959399954338068265843991617686189000213034050940973037", "price": "0.35", "size": "283", "side": "BUY", "hash": "6d918089a90e9b67c3e214e18c7c5da28c8eb1c7", "best_bid": "0.39", "best_ask": "0.4"}], "timestamp": "1769384775022", "event_type": "price_change"}}
{"_local_timestamp": "2026-01-25T23:46:18.801275+00:00", "data": {"market": "0x3b41890d5e8c9640649a9e6f724d1f74aa67af855506db6f871c5fdac70cfd90", "price_changes": [{"asset_id": "88830742474573630269392959399954338068265843991617686189000213034050940973037", "price": "0.34", "size": "0", "side": "BUY", "hash": "9fd44dd16c36ba701e0aae9a64c1cb86c08cc426", "best_bid": "0.39", "best_ask": "0.4"}, {"asset_id": "24393720551520374522532949229976185621516426573885698267923116722310834739486", "price": "0.66", "size": "0", "side": "SELL", "hash": "40bd4c402acfbaec00da8fda4c2cf418b53af393", "best_bid": "0.6", "best_ask": "0.61"}], "timestamp": "1769384778729", "event_type": "price_change"}}
{"_local_timestamp": "2026-01-25T23:46:19.512404+00:00", "data": {"market": "0x3b41890d5e8c9640649a9e6f724d1f74aa67af855506db6f871c5fdac70cfd90", "price_changes": [{"asset_id": "88830742474573630269392959399954338068265843991617686189000213034050940973037", "price": "0.36", "size": "100", "side": "BUY", "hash": "987f11b6bc9c41ff251a7b51760793b4e35de6a2", "best_bid": "0.39", "best_ask": "0.4"}, {"asset_id": "24393720551520374522532949229976185621516426573885698267923116722310834739486", "price": "0.64", "size": "100", "side": "SELL", "hash": "470777f4eaea5c0f0f846390faf095b83fd5c48b", "best_bid": "0.6", "best_ask": "0.61"}], "timestamp": "1769384779446", "event_type": "price_change"}}
{"_local_timestamp": "2026-01-25T23:46:50.860070+00:00", "data": {"market": "0xdd9f55a4a214da7231a64eb6f43a05f525b51e7bcf714db0c2d3b2fd0fc0c9ca", "price_changes": [{"asset_id": "87855193300342526755310181206520215785023964324419734896948555881922627101363", "price": "0.39", "size": "500", "side": "BUY", "hash": "a6ddd82533451a7127f5b9a98406afdbb2b755d1", "best_bid": "0.67", "best_ask": "0.76"}, {"asset_id": "18582106713580348058065911013375325630183346495483834588274922531241537980162", "price": "0.61", "size": "500", "side": "SELL", "hash": "0b9f829bcef8ead6959e312e44d7121d0c42df75", "best_bid": "0.24", "best_ask": "0.33"}], "timestamp": "1769384810655", "event_type": "price_change"}}
{"_local_timestamp": "2026-01-25T23:46:50.908454+00:00", "data": {"market": "0x3b41890d5e8c9640649a9e6f724d1f74aa67af855506db6f871c5fdac70cfd90", "price_changes": [{"asset_id": "24393720551520374522532949229976185621516426573885698267923116722310834739486", "price": "0.22", "size": "10290.9", "side": "BUY", "hash": "4b35fcaa099559401398f345e43e263c4a963e18", "best_bid": "0.6", "best_ask": "0.61"}, {"asset_id": "88830742474573630269392959399954338068265843991617686189000213034050940973037", "price": "0.78", "size": "10290.9", "side": "SELL", "hash": "02eea12f7d2190a9ce4e18b5dcc6659df3875c40", "best_bid": "0.39", "best_ask": "0.4"}], "timestamp": "1769384810654", "event_type": "price_change"}}
{"_local_timestamp": "2026-01-25T23:46:50.917911+00:00", "data": {"market": "0x3b41890d5e8c9640649a9e6f724d1f74aa67af855506db6f871c5fdac70cfd90", "price_changes": [{"asset_id": "24393720551520374522532949229976185621516426573885698267923116722310834739486", "price": "0.18", "size": "150", "side": "BUY", "hash": "4b35fcaa099559401398f345e43e263c4a963e18", "best_bid": "0.6", "best_ask": "0.61"}, {"asset_id": "88830742474573630269392959399954338068265843991617686189000213034050940973037", "price": "0.82", "size": "150", "side": "SELL", "hash": "02eea12f7d2190a9ce4e18b5dcc6659df3875c40", "best_bid": "0.39", "best_ask": "0.4"}], "timestamp": "1769384810654", "event_type": "price_change"}}
{"_local_timestamp": "2026-01-25T23:46:51.135213+00:00", "data": {"market": "0x3b41890d5e8c9640649a9e6f724d1f74aa67af855506db6f871c5fdac70cfd90", "price_changes": [{"asset_id": "24393720551520374522532949229976185621516426573885698267923116722310834739486", "price": "0.65", "size": "0", "side": "SELL", "hash": "247b7719db4fe3e34bf5aaa7ba9c523014525bb4", "best_bid": "0.6", "best_ask": "0.61"}, {"asset_id": "88830742474573630269392959399954338068265843991617686189000213034050940973037", "price": "0.35", "size": "0", "side": "BUY", "hash": "cdeee1ced063e8a8cec26b33efea091f1bf0478f", "best_bid": "0.39", "best_ask": "0.4"}], "timestamp": "1769384810862", "event_type": "price_change"}}
{"_local_timestamp": "2026-01-25T23:46:51.153854+00:00", "data": {"market": "0x3b41890d5e8c9640649a9e6f724d1f74aa67af855506db6f871c5fdac70cfd90", "price_changes": [{"asset_id": "24393720551520374522532949229976185621516426573885698267923116722310834739486", "price": "0.67", "size": "358", "side": "SELL", "hash": "050a5c0cfd2a9ef416007d94aa82e4a252e9091b", "best_bid": "0.6", "best_ask": "0.61"}, {"asset_id": "88830742474573630269392959399954338068265843991617686189000213034050940973037", "price": "0.33", "size": "358", "side": "BUY", "hash": "525ae8fdce2381e6d85a45ebe8dcbf70df5d7c5a", "best_bid": "0.39", "best_ask": "0.4"}], "timestamp": "1769384810889", "event_type": "price_change"}}
{"_local_timestamp": "2026-01-25T23:46:51.633115+00:00", "data": {"market": "0x3b41890d5e8c9640649a9e6f724d1f74aa67af855506db6f871c5fdac70cfd90", "price_changes": [{"asset_id": "24393720551520374522532949229976185621516426573885698267923116722310834739486", "price": "0.27", "size": "100", "side": "BUY", "hash": "8ab400fd49bc860da51ee0c7bbc3a48a697295cd", "best_bid": "0.6", "best_ask": "0.61"}, {"asset_id": "88830742474573630269392959399954338068265843991617686189000213034050940973037", "price": "0.73", "size": "100", "side": "SELL", "hash": "eb4e3de12326c1c77f34dfc6dceca0e8b2a0e3e6", "best_bid": "0.39", "best_ask": "0.4"}], "timestamp": "1769384811242", "event_type": "price_change"}}
{"_local_timestamp": "2026-01-25T23:46:51.675697+00:00", "data": {"market": "0x3b41890d5e8c9640649a9e6f724d1f74aa67af855506db6f871c5fdac70cfd90", "price_changes": [{"asset_id": "24393720551520374522532949229976185621516426573885698267923116722310834739486", "price": "0.19", "size": "250", "side": "BUY", "hash": "906dd214c9bc340579344fb27efd68fa466cb96e", "best_bid": "0.6", "best_ask": "0.61"}, {"asset_id": "88830742474573630269392959399954338068265843991617686189000213034050940973037", "price": "0.81", "size": "250", "side": "SELL", "hash": "4f0d80f6edad7d4ed6ef2c4bb5fbafc9b35505ba", "best_bid": "0.39", "best_ask": "0.4"}], "timestamp": "1769384811279", "event_type": "price_change"}}
{"_local_timestamp": "2026-01-25T23:46:53.103406+00:00", "data": {"market": "0x3b41890d5e8c9640649a9e6f724d1f74aa67af855506db6f871c5fdac70cfd90", "price_changes": [{"asset_id": "88830742474573630269392959399954338068265843991617686189000213034050940973037", "price": "0.36", "size": "0", "side": "BUY", "hash": "7978d32bf2cb252d931bdad0454d5283b0bb982b", "best_bid": "0.39", "best_ask": "0.4"}, {"asset_id": "24393720551520374522532949229976185621516426573885698267923116722310834739486", "price": "0.64", "size": "0", "side": "SELL", "hash": "b08b6647db16dc9c2dc8addfc68a2670663fd1cc", "best_bid": "0.6", "best_ask": "0.61"}], "timestamp": "1769384813034", "event_type": "price_change"}}
{"_local_timestamp": "2026-01-25T23:46:53.774499+00:00", "data": {"market": "0x3b41890d5e8c9640649a9e6f724d1f74aa67af855506db6f871c5fdac70cfd90", "price_changes": [{"asset_id": "88830742474573630269392959399954338068265843991617686189000213034050940973037", "price": "0.34", "size": "100", "side": "BUY", "hash": "2c196d63efe2caf44ff673d8a3edf84fb799a1a3", "best_bid": "0.39", "best_ask": "0.4"}, {"asset_id": "24393720551520374522532949229976185621516426573885698267923116722310834739486", "price": "0.66", "size": "100", "side": "SELL", "hash": "20756ba44aae8cd22b862e60c594e3ec044a588a", "best_bid": "0.6", "best_ask": "0.61"}], "timestamp": "1769384813706", "event_type": "price_change"}}
{"_local_timestamp": "2026-01-25T23:46:53.799121+00:00", "data": {"market": "0x3b41890d5e8c9640649a9e6f724d1f74aa67af855506db6f871c5fdac70cfd90", "price_changes": [{"asset_id": "24393720551520374522532949229976185621516426573885698267923116722310834739486", "price": "0.67", "size": "100", "side": "SELL", "hash": "20ce9c2f41ab8730317a3ceea01d6e6f0bbe66c4", "best_bid": "0.6", "best_ask": "0.61"}, {"asset_id": "88830742474573630269392959399954338068265843991617686189000213034050940973037", "price": "0.33", "size": "100", "side": "BUY", "hash": "90e91fd2ae8b09a2719e5f9161e6c7be06d95968", "best_bid": "0.39", "best_ask": "0.4"}], "timestamp": "1769384813731", "event_type": "price_change"}}
{"_local_timestamp": "2026-01-25T23:46:53.830525+00:00", "data": {"market": "0x3b41890d5e8c9640649a9e6f724d1f74aa67af855506db6f871c5fdac70cfd90", "price_changes": [{"asset_id": "24393720551520374522532949229976185621516426573885698267923116722310834739486", "price": "0.66", "size": "383", "side": "SELL", "hash": "c8b27165276d9fddc4a954315c39ff30c1e1f7c4", "best_bid": "0.6", "best_ask": "0.61"}, {"asset_id": "88830742474573630269392959399954338068265843991617686189000213034050940973037", "price": "0.34", "size": "383", "side": "BUY", "hash": "2bab9e8926679af7d49e17835f44dcc325c04e09", "best_bid": "0.39", "best_ask": "0.4"}], "timestamp": "1769384813756", "event_type": "price_change"}}
{"_local_timestamp": "2026-01-25T23:46:54.438102+00:00", "data": {"market": "0x3b41890d5e8c9640649a9e6f724d1f74aa67af855506db6f871c5fdac70cfd90", "price_changes": [{"asset_id": "24393720551520374522532949229976185621516426573885698267923116722310834739486", "price": "0.23", "size": "0", "side": "BUY", "hash": "57a41855ee04a19903a234d1e37176a7e436ca0f", "best_bid": "0.6", "best_ask": "0.61"}, {"asset_id": "88830742474573630269392959399954338068265843991617686189000213034050940973037", "price": "0.77", "size": "0", "side": "SELL", "hash": "3632e9d74eab62015b81f35ea4b11a85186eca59", "best_bid": "0.39", "best_ask": "0.4"}], "timestamp": "1769384814318", "event_type": "price_change"}}
{"_local_timestamp": "2026-01-25T23:46:54.440051+00:00", "data": {"market": "0x3b41890d5e8c9640649a9e6f724d1f74aa67af855506db6f871c5fdac70cfd90", "price_changes": [{"asset_id": "24393720551520374522532949229976185621516426573885698267923116722310834739486", "price": "0.28", "size": "422", "side": "BUY", "hash": "e3173f56312f8eaf1194f27f24a1d254dd114a80", "best_bid": "0.6", "best_ask": "0.61"}, {"asset_id": "88830742474573630269392959399954338068265843991617686189000213034050940973037", "price": "0.72", "size": "422", "side": "SELL", "hash": "90e47cd563ceb54aa4e3d7d2f35f9bf2e60c7303", "best_bid": "0.39", "best_ask": "0.4"}], "timestamp": "1769384814365", "event_type": "price_change"}}
{"_local_timestamp": "2026-01-25T23:46:54.440693+00:00", "data": {"market": "0x3b41890d5e8c9640649a9e6f724d1f74aa67af855506db6f871c5fdac70cfd90", "price_changes": [{"asset_id": "24393720551520374522532949229976185621516426573885698267923116722310834739486", "price": "0.26", "size": "847", "side": "BUY", "hash": "7aac51f96fc39dd2a83c347f4684cf3bd7c073f1", "best_bid": "0.6", "best_ask": "0.61"}, {"asset_id": "88830742474573630269392959399954338068265843991617686189000213034050940973037", "price": "0.74", "size": "847", "side": "SELL", "hash": "b9c6b07e3e1f10cb58f2feafcc3862f72a5a751e", "best_bid": "0.39", "best_ask": "0.4"}], "timestamp": "1769384814366", "event_type": "price_change"}}
{"_local_timestamp": "2026-01-25T23:46:57.356809+00:00", "data": {"market": "0x3b41890d5e8c9640649a9e6f724d1f74aa67af855506db6f871c5fdac70cfd90", "price_changes": [{"asset_id": "88830742474573630269392959399954338068265843991617686189000213034050940973037", "price": "0.34", "size": "283", "side": "BUY", "hash": "530b5b751f7ea06d9451870524bb01ea03d442b3", "best_bid": "0.39", "best_ask": "0.4"}, {"asset_id": "24393720551520374522532949229976185621516426573885698267923116722310834739486", "price": "0.66", "size": "283", "side": "SELL", "hash": "e2f9ec045de02331d0bcd837264b531ed61e23ac", "best_bid": "0.6", "best_ask": "0.61"}], "timestamp": "1769384817274", "event_type": "price_change"}}
{"_local_timestamp": "2026-01-25T23:46:57.889789+00:00", "data": {"market": "0x3b41890d5e8c9640649a9e6f724d1f74aa67af855506db6f871c5fdac70cfd90", "price_changes": [{"asset_id": "88830742474573630269392959399954338068265843991617686189000213034050940973037", "price": "0.35", "size": "100", "side": "BUY", "hash": "06b6fb146a3775d30f87075102a4e2702f3f7e4d", "best_bid": "0.39", "best_ask": "0.4"}, {"asset_id": "24393720551520374522532949229976185621516426573885698267923116722310834739486", "price": "0.65", "size": "100", "side": "SELL", "hash": "4e2794deeb98aa3189eb1819ef58b943980d3833", "best_bid": "0.6", "best_ask": "0.61"}], "timestamp": "1769384817823", "event_type": "price_change"}}
{"_local_timestamp": "2026-01-25T23:47:05.023136+00:00", "data": {"market": "0xdd9f55a4a214da7231a64eb6f43a05f525b51e7bcf714db0c2d3b2fd0fc0c9ca", "price_changes": [{"asset_id": "87855193300342526755310181206520215785023964324419734896948555881922627101363", "price": "0.66", "size": "0", "side": "BUY", "hash": "14c48bdefb2af13b69f7bdfe5eeb98bb5d066754", "best_bid": "0.67", "best_ask": "0.76"}, {"asset_id": "18582106713580348058065911013375325630183346495483834588274922531241537980162", "price": "0.34", "size": "0", "side": "SELL", "hash": "24b6731a31d56fd2a333965e0271d0813ec9bfc4", "best_bid": "0.24", "best_ask": "0.33"}], "timestamp": "1769384824942", "event_type": "price_change"}}
{"_local_timestamp": "2026-01-25T23:47:05.724608+00:00", "data": {"market": "0xdd9f55a4a214da7231a64eb6f43a05f525b51e7bcf714db0c2d3b2fd0fc0c9ca", "price_changes": [{"asset_id": "87855193300342526755310181206520215785023964324419734896948555881922627101363", "price": "0.67", "size": "33.42", "side": "BUY", "hash": "3718a6bfc876b43bba936f1b0309b16a6fc9954a", "best_bid": "0.67", "best_ask": "0.76"}, {"asset_id": "18582106713580348058065911013375325630183346495483834588274922531241537980162", "price": "0.33", "size": "33.42", "side": "SELL", "hash": "9093cc25ac17fbf0da9223c6c5216fa2be3dd61b", "best_bid": "0.24", "best_ask": "0.33"}], "timestamp": "1769384825649", "event_type": "price_change"}}
{"_local_timestamp": "2026-01-25T23:47:06.298468+00:00", "data": {"market": "0xdd9f55a4a214da7231a64eb6f43a05f525b51e7bcf714db0c2d3b2fd0fc0c9ca", "price_changes": [{"asset_id": "87855193300342526755310181206520215785023964324419734896948555881922627101363", "price": "0.18", "size": "199.99", "side": "BUY", "hash": "dc4c46476ad6f322f998528abedcf22a490de464", "best_bid": "0.67", "best_ask": "0.76"}, {"asset_id": "18582106713580348058065911013375325630183346495483834588274922531241537980162", "price": "0.82", "size": "199.99", "side": "SELL", "hash": "524e180df37f8bef3aac451035ac01063f5136dc", "best_bid": "0.24", "best_ask": "0.33"}], "timestamp": "1769384826214", "event_type": "price_change"}}
{"_local_timestamp": "2026-01-25T23:47:16.825029+00:00", "data": {"market": "0x3b41890d5e8c9640649a9e6f724d1f74aa67af855506db6f871c5fdac70cfd90", "price_changes": [{"asset_id": "24393720551520374522532949229976185621516426573885698267923116722310834739486", "price": "0.19", "size": "2460", "side": "BUY", "hash": "7be21e93d22cc625aba6dfab09d3c966f00780af", "best_bid": "0.6", "best_ask": "0.61"}, {"asset_id": "88830742474573630269392959399954338068265843991617686189000213034050940973037", "price": "0.81", "size": "2460", "side": "SELL", "hash": "63104127414273061f8abbee2da194469216eaea", "best_bid": "0.39", "best_ask": "0.4"}], "timestamp": "1769384836747", "event_type": "price_change"}}
{"_local_timestamp": "2026-01-25T23:47:16.849285+00:00", "data": {"market": "0x3b41890d5e8c9640649a9e6f724d1f74aa67af855506db6f871c5fdac70cfd90", "price_changes": [{"asset_id": "24393720551520374522532949229976185621516426573885698267923116722310834739486", "price": "0.66", "size": "0", "side": "SELL", "hash": "3c2cbda6750094e690f05cad5fd0b2a905617382", "best_bid": "0.6", "best_ask": "0.61"}, {"asset_id": "88830742474573630269392959399954338068265843991617686189000213034050940973037", "price": "0.34", "size": "0", "side": "BUY", "hash": "4f1665ee00ae0c37c11ccdb5abff6cd13696e5eb", "best_bid": "0.39", "best_ask": "0.4"}], "timestamp": "1769384836781", "event_type": "price_change"}}
{"_local_timestamp": "2026-01-25T23:47:16.884729+00:00", "data": {"market": "0x3b41890d5e8c9640649a9e6f724d1f74aa67af855506db6f871c5fdac70cfd90", "price_changes": [{"asset_id": "24393720551520374522532949229976185621516426573885698267923116722310834739486", "price": "0.67", "size": "383", "side": "SELL", "hash": "7bcfe293865b33432f5c1a0d2dcff0415442d488", "best_bid": "0.6", "best_ask": "0.61"}, {"asset_id": "88830742474573630269392959399954338068265843991617686189000213034050940973037", "price": "0.33", "size": "383", "side": "BUY", "hash": "9d95e752d81329b3f05342a9139d46d2a593bbb0", "best_bid": "0.39", "best_ask": "0.4"}], "timestamp": "1769384836810", "event_type": "price_change"}}
{"_local_timestamp": "2026-01-25T23:47:18.610201+00:00", "data": {"market": "0x3b41890d5e8c9640649a9e6f724d1f74aa67af855506db6f871c5fdac70cfd90", "price_changes": [{"asset_id": "88830742474573630269392959399954338068265843991617686189000213034050940973037", "price": "0.35", "size": "0", "side": "BUY", "hash": "4034a67b8f567d100dd5e473200674ea6aa770a2", "best_bid": "0.39", "best_ask": "0.4"}, {"asset_id": "24393720551520374522532949229976185621516426573885698267923116722310834739486", "price": "0.65", "size": "0", "side": "SELL", "hash": "d4597f70a341b428bd99756bc85c803bc84671af", "best_bid": "0.6", "best_ask": "0.61"}], "timestamp": "1769384838540", "event_type": "price_change"}}
{"_local_timestamp": "2026-01-25T23:47:19.491507+00:00", "data": {"market": "0x3b41890d5e8c9640649a9e6f724d1f74aa67af855506db6f871c5fdac70cfd90", "price_changes": [{"asset_id": "88830742474573630269392959399954338068265843991617686189000213034050940973037", "price": "0.34", "size": "100", "side": "BUY", "hash": "1ac37f62f5455a4526188290d7fcc762f5f8ca24", "best_bid": "0.39", "best_ask": "0.4"}, {"asset_id": "24393720551520374522532949229976185621516426573885698267923116722310834739486", "price": "0.66", "size": "100", "side": "SELL", "hash": "cd1ca730087ebfc748b942efe30771a18ae5124e", "best_bid": "0.6", "best_ask": "0.61"}], "timestamp": "1769384839193", "event_type": "price_change"}}
{"_local_timestamp": "2026-01-25T23:47:19.646116+00:00", "data": {"market": "0x3b41890d5e8c9640649a9e6f724d1f74aa67af855506db6f871c5fdac70cfd90", "price_changes": [{"asset_id": "24393720551520374522532949229976185621516426573885698267923116722310834739486", "price": "0.67", "size": "100", "side": "SELL", "hash": "f7314f620442c1ec6201c1b6849f9a8a55e068d0", "best_bid": "0.6", "best_ask": "0.61"}, {"asset_id": "88830742474573630269392959399954338068265843991617686189000213034050940973037", "price": "0.33", "size": "100", "side": "BUY", "hash": "b3afde6a956188c728dbb5f580fcc13e0e71cf1f", "best_bid": "0.39", "best_ask": "0.4"}], "timestamp": "1769384839447", "event_type": "price_change"}}
{"_local_timestamp": "2026-01-25T23:47:19.662926+00:00", "data": {"market": "0x3b41890d5e8c9640649a9e6f724d1f74aa67af855506db6f871c5fdac70cfd90", "price_changes": [{"asset_id": "24393720551520374522532949229976185621516426573885698267923116722310834739486", "price": "0.65", "size": "283", "side": "SELL", "hash": "9e8a49135bf4911d75a24d911162a9bc58d4a51f", "best_bid": "0.6", "best_ask": "0.61"}, {"asset_id": "88830742474573630269392959399954338068265843991617686189000213034050940973037", "price": "0.35", "size": "283", "side": "BUY", "hash": "38e7aec107d97abe16fccb23b48d89f84c082bad", "best_bid": "0.39", "best_ask": "0.4"}], "timestamp": "1769384839481", "event_type": "price_change"}}
{"_local_timestamp": "2026-01-25T23:47:22.955666+00:00", "data": {"market": "0x3b41890d5e8c9640649a9e6f724d1f74aa67af855506db6f871c5fdac70cfd90", "price_changes": [{"asset_id": "88830742474573630269392959399954338068265843991617686189000213034050940973037", "price": "0.34", "size": "0", "side": "BUY", "hash": "bbc5c5e1f89fcd092fd5e0f571a6b19ce403d9aa", "best_bid": "0.39", "best_ask": "0.4"}, {"asset_id": "24393720551520374522532949229976185621516426573885698267923116722310834739486", "price": "0.66", "size": "0", "side": "SELL", "hash": "2b82ffdfa26b5af6ed20e93914303ed32ba17e78", "best_bid": "0.6", "best_ask": "0.61"}], "timestamp": "1769384842877", "event_type": "price_change"}}
{"_local_timestamp": "2026-01-25T23:47:23.587252+00:00", "data": {"market": "0x3b41890d5e8c9640649a9e6f724d1f74aa67af855506db6f871c5fdac70cfd90", "price_changes": [{"asset_id": "24393720551520374522532949229976185621516426573885698267923116722310834739486", "price": "0.28", "size": "372", "side": "BUY", "hash": "e5b490b8441d446f015cb201c0bdeb4ad030ea72", "best_bid": "0.6", "best_ask": "0.61"}, {"asset_id": "88830742474573630269392959399954338068265843991617686189000213034050940973037", "price": "0.72", "size": "372", "side": "SELL", "hash": "a06215535f63a746eefbfa8c7b4cec5079508ae4", "best_bid": "0.39", "best_ask": "0.4"}], "timestamp": "1769384843410", "event_type": "price_change"}}
{"_local_timestamp": "2026-01-25T23:47:23.680142+00:00", "data": {"market": "0x3b41890d5e8c9640649a9e6f724d1f74aa67af855506db6f871c5fdac70cfd90", "price_changes": [{"asset_id": "88830742474573630269392959399954338068265843991617686189000213034050940973037", "price": "0.36", "size": "100", "side": "BUY", "hash": "5b8a6e5482474880192b9859b4ace6bb48e84ec5", "best_bid": "0.39", "best_ask": "0.4"}, {"asset_id": "24393720551520374522532949229976185621516426573885698267923116722310834739486", "price": "0.64", "size": "100", "side": "SELL", "hash": "4b8cb412d374695f81086226530f58e0fe19aa78", "best_bid": "0.6", "best_ask": "0.61"}], "timestamp": "1769384843529", "event_type": "price_change"}}
{"_local_timestamp": "2026-01-25T23:47:23.953737+00:00", "data": {"market": "0x3b41890d5e8c9640649a9e6f724d1f74aa67af855506db6f871c5fdac70cfd90", "price_changes": [{"asset_id": "24393720551520374522532949229976185621516426573885698267923116722310834739486", "price": "0.27", "size": "150", "side": "BUY", "hash": "0b2be8f75a2c81bcd46e4754f43f234b5dbc0cdb", "best_bid": "0.6", "best_ask": "0.61"}, {"asset_id": "88830742474573630269392959399954338068265843991617686189000213034050940973037", "price": "0.73", "size": "150", "side": "SELL", "hash": "53f9e5655e344ca8f99bd6f4691e82dff4fe2a77", "best_bid": "0.39", "best_ask": "0.4"}], "timestamp": "1769384843829", "event_type": "price_change"}}
{"_local_timestamp": "2026-01-25T23:47:37.415987+00:00", "data": {"market": "0x3b41890d5e8c9640649a9e6f724d1f74aa67af855506db6f871c5fdac70cfd90", "price_changes": [{"asset_id": "24393720551520374522532949229976185621516426573885698267923116722310834739486", "price": "0.18", "size": "0", "side": "BUY", "hash": "6a95a9bf1b0dd2901de2d232ec2ea697636e2f8c", "best_bid": "0.6", "best_ask": "0.61"}, {"asset_id": "88830742474573630269392959399954338068265843991617686189000213034050940973037", "price": "0.82", "size": "0", "side": "SELL", "hash": "003bd8f379cd30e3ffff59bfe0d4936c95c4da62", "best_bid": "0.39", "best_ask": "0.4"}], "timestamp": "1769384857300", "event_type": "price_change"}}
{"_local_timestamp": "2026-01-25T23:47:37.743319+00:00", "data": {"market": "0x3b41890d5e8c9640649a9e6f724d1f74aa67af855506db6f871c5fdac70cfd90", "price_changes": [{"asset_id": "24393720551520374522532949229976185621516426573885698267923116722310834739486", "price": "0.19", "size": "2360", "side": "BUY", "hash": "d33f60642451e14e33aee5c01d938033f72548bb", "best_bid": "0.6", "best_ask": "0.61"}, {"asset_id": "88830742474573630269392959399954338068265843991617686189000213034050940973037", "price": "0.81", "size": "2360", "side": "SELL", "hash": "f10a85f67320371c3e724b2cf142d4cef18e70cf", "best_bid": "0.39", "best_ask": "0.4"}], "timestamp": "1769384857542", "event_type": "price_change"}}
{"_local_timestamp": "2026-01-25T23:47:37.872456+00:00", "data": {"market": "0x3b41890d5e8c9640649a9e6f724d1f74aa67af855506db6f871c5fdac70cfd90", "price_changes": [{"asset_id": "24393720551520374522532949229976185621516426573885698267923116722310834739486", "price": "0.19", "size": "2510", "side": "BUY", "hash": "3796f87a4ded0a57b32394a072f3785f6668151a", "best_bid": "0.6", "best_ask": "0.61"}, {"asset_id": "88830742474573630269392959399954338068265843991617686189000213034050940973037", "price": "0.81", "size": "2510", "side": "SELL", "hash": "d412c96b26f37a34e8e7919611ee5ec5bbcc209d", "best_bid": "0.39", "best_ask": "0.4"}], "timestamp": "1769384857590", "event_type": "price_change"}}
{"_local_timestamp": "2026-01-25T23:47:38.436668+00:00", "data": {"market": "0xdd9f55a4a214da7231a64eb6f43a05f525b51e7bcf714db0c2d3b2fd0fc0c9ca", "price_changes": [{"asset_id": "87855193300342526755310181206520215785023964324419734896948555881922627101363", "price": "0.29", "size": "250", "side": "BUY", "hash": "9535d9040b62197dbc6221b12558fead0befb63a", "best_bid": "0.67", "best_ask": "0.76"}, {"asset_id": "18582106713580348058065911013375325630183346495483834588274922531241537980162", "price": "0.71", "size": "250", "side": "SELL", "hash": "dc7c9b661b3752fafdf285e58d87f2939f883ed0", "best_bid": "0.24", "best_ask": "0.33"}], "timestamp": "1769384858093", "event_type": "price_change"}}
{"_local_timestamp": "2026-01-25T23:47:38.437762+00:00", "data": {"market": "0x3b41890d5e8c9640649a9e6f724d1f74aa67af855506db6f871c5fdac70cfd90", "price_changes": [{"asset_id": "24393720551520374522532949229976185621516426573885698267923116722310834739486", "price": "0.18", "size": "100", "side": "BUY", "hash": "d4038121b7e02e2e7d87c5bcd74d08774506a75f", "best_bid": "0.6", "best_ask": "0.61"}, {"asset_id": "88830742474573630269392959399954338068265843991617686189000213034050940973037", "price": "0.82", "size": "100", "side": "SELL", "hash": "59c4d58ad2b50357d2a19ad7f1ea82131de0f77b", "best_bid": "0.39", "best_ask": "0.4"}], "timestamp": "1769384858093", "event_type": "price_change"}}
{"_local_timestamp": "2026-01-25T23:48:24.242019+00:00", "data": {"market": "0xdd9f55a4a214da7231a64eb6f43a05f525b51e7bcf714db0c2d3b2fd0fc0c9ca", "price_changes": [{"asset_id": "87855193300342526755310181206520215785023964324419734896948555881922627101363", "price": "0.66", "size": "57.57", "side": "BUY", "hash": "c33f4a9a584ee397ba62b1ab86290d8a25d061ec", "best_bid": "0.67", "best_ask": "0.76"}, {"asset_id": "18582106713580348058065911013375325630183346495483834588274922531241537980162", "price": "0.34", "size": "57.57", "side": "SELL", "hash": "c3c76642ff39fe82701e679e515634ab5f01132a", "best_bid": "0.24", "best_ask": "0.33"}], "timestamp": "1769384904174", "event_type": "price_change"}}
{"_local_timestamp": "2026-01-25T23:48:26.823495+00:00", "data": {"market": "0xdd9f55a4a214da7231a64eb6f43a05f525b51e7bcf714db0c2d3b2fd0fc0c9ca", "price_changes": [{"asset_id": "87855193300342526755310181206520215785023964324419734896948555881922627101363", "price": "0.18", "size": "99.99", "side": "BUY", "hash": "4a055768ba0d0a2e0fcb8bbd9b6f3a10003f0d45", "best_bid": "0.67", "best_ask": "0.76"}, {"asset_id": "18582106713580348058065911013375325630183346495483834588274922531241537980162", "price": "0.82", "size": "99.99", "side": "SELL", "hash": "b2470b0f90e6d8f80f66ddb1c0429874aab509aa", "best_bid": "0.24", "best_ask": "0.33"}], "timestamp": "1769384906754", "event_type": "price_change"}}
{"_local_timestamp": "2026-01-25T23:48:27.468026+00:00", "data": {"market": "0xdd9f55a4a214da7231a64eb6f43a05f525b51e7bcf714db0c2d3b2fd0fc0c9ca", "price_changes": [{"asset_id": "87855193300342526755310181206520215785023964324419734896948555881922627101363", "price": "0.67", "size": "133.42", "side": "BUY", "hash": "a0615d6891bc48a16cac22e92cd44361cd9ec783", "best_bid": "0.67", "best_ask": "0.76"}, {"asset_id": "18582106713580348058065911013375325630183346495483834588274922531241537980162", "price": "0.33", "size": "133.42", "side": "SELL", "hash": "27c4eb4ad3d908f605fa7cbe71009ff9773c5333", "best_bid": "0.24", "best_ask": "0.33"}], "timestamp": "1769384907395", "event_type": "price_change"}}
{"_local_timestamp": "2026-01-25T23:49:25.429282+00:00", "data": {"market": "0x3b41890d5e8c9640649a9e6f724d1f74aa67af855506db6f871c5fdac70cfd90", "price_changes": [{"asset_id": "24393720551520374522532949229976185621516426573885698267923116722310834739486", "price": "0.18", "size": "0", "side": "BUY", "hash": "135755041ffb5013ec65919bd4a690d8fda1ae51", "best_bid": "0.6", "best_ask": "0.61"}, {"asset_id": "88830742474573630269392959399954338068265843991617686189000213034050940973037", "price": "0.82", "size": "0", "side": "SELL", "hash": "865da66c82079fc9823ffe0a9f4eba778b6c2a0a", "best_bid": "0.39", "best_ask": "0.4"}], "timestamp": "1769384965280", "event_type": "price_change"}}
{"_local_timestamp": "2026-01-25T23:49:25.430293+00:00", "data": {"market": "0xdd9f55a4a214da7231a64eb6f43a05f525b51e7bcf714db0c2d3b2fd0fc0c9ca", "price_changes": [{"asset_id": "87855193300342526755310181206520215785023964324419734896948555881922627101363", "price": "0.29", "size": "200", "side": "BUY", "hash": "222eb137937489efafa0076216f41842b971bf92", "best_bid": "0.67", "best_ask": "0.76"}, {"asset_id": "18582106713580348058065911013375325630183346495483834588274922531241537980162", "price": "0.71", "size": "200", "side": "SELL", "hash": "3f0e06cbb6638d3fd5c3ec8ae38f4baecc62e813", "best_bid": "0.24", "best_ask": "0.33"}], "timestamp": "1769384965280", "event_type": "price_change"}}
{"_local_timestamp": "2026-01-25T23:49:25.903704+00:00", "data": {"market": "0x3b41890d5e8c9640649a9e6f724d1f74aa67af855506db6f871c5fdac70cfd90", "price_changes": [{"asset_id": "24393720551520374522532949229976185621516426573885698267923116722310834739486", "price": "0.19", "size": "2610", "side": "BUY", "hash": "0438dd5239e8dc8431f0638f3241962ba580019f", "best_bid": "0.6", "best_ask": "0.61"}, {"asset_id": "88830742474573630269392959399954338068265843991617686189000213034050940973037", "price": "0.81", "size": "2610", "side": "SELL", "hash": "afd2e5c1bac355784bc561be075cdc0a032a0ada", "best_bid": "0.39", "best_ask": "0.4"}], "timestamp": "1769384965794", "event_type": "price_change"}}
{"_local_timestamp": "2026-01-25T23:49:30.298010+00:00", "data": {"market": "0x3b41890d5e8c9640649a9e6f724d1f74aa67af855506db6f871c5fdac70cfd90", "price_changes": [{"asset_id": "24393720551520374522532949229976185621516426573885698267923116722310834739486", "price": "0.27", "size": "50", "side": "BUY", "hash": "4d7c825522d64efa917cd2de07753a6a1a6906a5", "best_bid": "0.6", "best_ask": "0.61"}, {"asset_id": "88830742474573630269392959399954338068265843991617686189000213034050940973037", "price": "0.73", "size": "50", "side": "SELL", "hash": "e157c4de65d4a00a16e47d7879ccdf91f72e81d0", "best_bid": "0.39", "best_ask": "0.4"}], "timestamp": "1769384970056", "event_type": "price_change"}}
{"_local_timestamp": "2026-01-25T23:49:30.308417+00:00", "data": {"market": "0x3b41890d5e8c9640649a9e6f724d1f74aa67af855506db6f871c5fdac70cfd90", "price_changes": [{"asset_id": "24393720551520374522532949229976185621516426573885698267923116722310834739486", "price": "0.19", "size": "2460", "side": "BUY", "hash": "4d7c825522d64efa917cd2de07753a6a1a6906a5", "best_bid": "0.6", "best_ask": "0.61"}, {"asset_id": "88830742474573630269392959399954338068265843991617686189000213034050940973037", "price": "0.81", "size": "2460", "side": "SELL", "hash": "e157c4de65d4a00a16e47d7879ccdf91f72e81d0", "best_bid": "0.39", "best_ask": "0.4"}], "timestamp": "1769384970056", "event_type": "price_change"}}
{"_local_timestamp": "2026-01-25T23:49:31.001248+00:00", "data": {"market": "0xdd9f55a4a214da7231a64eb6f43a05f525b51e7bcf714db0c2d3b2fd0fc0c9ca", "price_changes": [{"asset_id": "87855193300342526755310181206520215785023964324419734896948555881922627101363", "price": "0.39", "size": "575", "side": "BUY", "hash": "a5443024d3705dd314b574762c75218b7587cfe3", "best_bid": "0.67", "best_ask": "0.76"}, {"asset_id": "18582106713580348058065911013375325630183346495483834588274922531241537980162", "price": "0.61", "size": "575", "side": "SELL", "hash": "485554aafc567be50d22854a1c4d8e8144d86362", "best_bid": "0.24", "best_ask": "0.33"}], "timestamp": "1769384970632", "event_type": "price_change"}}
{"_local_timestamp": "2026-01-25T23:49:31.002160+00:00", "data": {"market": "0x3b41890d5e8c9640649a9e6f724d1f74aa67af855506db6f871c5fdac70cfd90", "price_changes": [{"asset_id": "24393720551520374522532949229976185621516426573885698267923116722310834739486", "price": "0.18", "size": "150", "side": "BUY", "hash": "8f2e543244d53d90959fb3a48599b81d4d1e1a1d", "best_bid": "0.6", "best_ask": "0.61"}, {"asset_id": "88830742474573630269392959399954338068265843991617686189000213034050940973037", "price": "0.82", "size": "150", "side": "SELL", "hash": "5747244afdf7cb4b2fc29de499a5f743811931a8", "best_bid": "0.39", "best_ask": "0.4"}], "timestamp": "1769384970633", "event_type": "price_change"}}
{"_local_timestamp": "2026-01-25T23:49:31.132580+00:00", "data": {"market": "0x3b41890d5e8c9640649a9e6f724d1f74aa67af855506db6f871c5fdac70cfd90", "price_changes": [{"asset_id": "24393720551520374522532949229976185621516426573885698267923116722310834739486", "price": "0.22", "size": "10390.9", "side": "BUY", "hash": "a24138f92f0b23014ba0937dc0d77dd3263e45a6", "best_bid": "0.6", "best_ask": "0.61"}, {"asset_id": "88830742474573630269392959399954338068265843991617686189000213034050940973037", "price": "0.78", "size": "10390.9", "side": "SELL", "hash": "ac802b0c1d915200344168cb1fd61dab1b6025b5", "best_bid": "0.39", "best_ask": "0.4"}], "timestamp": "1769384970737", "event_type": "price_change"}}
{"_local_timestamp": "2026-01-25T23:49:36.131917+00:00", "data": {"market": "0x3b41890d5e8c9640649a9e6f724d1f74aa67af855506db6f871c5fdac70cfd90", "price_changes": [{"asset_id": "24393720551520374522532949229976185621516426573885698267923116722310834739486", "price": "0.26", "size": "450", "side": "BUY", "hash": "23c7db3cee478cd1276afa2bd2e93faf43b264fe", "best_bid": "0.6", "best_ask": "0.61"}, {"asset_id": "88830742474573630269392959399954338068265843991617686189000213034050940973037", "price": "0.74", "size": "450", "side": "SELL", "hash": "78ccb91120e449386d830da672850c923102a04f", "best_bid": "0.39", "best_ask": "0.4"}], "timestamp": "1769384976023", "event_type": "price_change"}}
{"_local_timestamp": "2026-01-25T23:49:36.132798+00:00", "data": {"market": "0x3b41890d5e8c9640649a9e6f724d1f74aa67af855506db6f871c5fdac70cfd90", "price_changes": [{"asset_id": "24393720551520374522532949229976185621516426573885698267923116722310834739486", "price": "0.28", "size": "0", "side": "BUY", "hash": "23c7db3cee478cd1276afa2bd2e93faf43b264fe", "best_bid": "0.6", "best_ask": "0.61"}, {"asset_id": "88830742474573630269392959399954338068265843991617686189000213034050940973037", "price": "0.72", "size": "0", "side": "SELL", "hash": "78ccb91120e449386d830da672850c923102a04f", "best_bid": "0.39", "best_ask": "0.4"}], "timestamp": "1769384976023", "event_type": "price_change"}}
{"_local_timestamp": "2026-01-25T23:49:36.173254+00:00", "data": {"market": "0x3b41890d5e8c9640649a9e6f724d1f74aa67af855506db6f871c5fdac70cfd90", "price_changes": [{"asset_id": "24393720551520374522532949229976185621516426573885698267923116722310834739486", "price": "0.65", "size": "0", "side": "SELL", "hash": "2924c1fee4ccf06756d386858a494cb5c3d053a5", "best_bid": "0.6", "best_ask": "0.61"}, {"asset_id": "88830742474573630269392959399954338068265843991617686189000213034050940973037", "price": "0.35", "size": "0", "side": "BUY", "hash": "cd4559d961e03f9177223de872cfaf8e52f5b304", "best_bid": "0.39", "best_ask": "0.4"}], "timestamp": "1769384976088", "event_type": "price_change"}}
{"_local_timestamp": "2026-01-25T23:49:36.174133+00:00", "data": {"market": "0x3b41890d5e8c9640649a9e6f724d1f74aa67af855506db6f871c5fdac70cfd90", "price_changes": [{"asset_id": "24393720551520374522532949229976185621516426573885698267923116722310834739486", "price": "0.23", "size": "900", "side": "BUY", "hash": "0925716b780dcc9df486319107669d9285b69294", "best_bid": "0.6", "best_ask": "0.61"}, {"asset_id": "88830742474573630269392959399954338068265843991617686189000213034050940973037", "price": "0.77", "size": "900", "side": "SELL", "hash": "f0d549a2e6094e351973fa88cd9edc455ea1f611", "best_bid": "0.39", "best_ask": "0.4"}], "timestamp": "1769384976097", "event_type": "price_change"}}
{"_local_timestamp": "2026-01-25T23:49:36.193483+00:00", "data": {"market": "0x3b41890d5e8c9640649a9e6f724d1f74aa67af855506db6f871c5fdac70cfd90", "price_changes": [{"asset_id": "24393720551520374522532949229976185621516426573885698267923116722310834739486", "price": "0.66", "size": "283", "side": "SELL", "hash": "b459602477fa9824418911fb99e080bcd7c513c7", "best_bid": "0.6", "best_ask": "0.61"}, {"asset_id": "88830742474573630269392959399954338068265843991617686189000213034050940973037", "price": "0.34", "size": "283", "side": "BUY", "hash": "8df028d46653a1c9d7934af0fb2e89ffb69b5405", "best_bid": "0.39", "best_ask": "0.4"}], "timestamp": "1769384976122", "event_type": "price_change"}}
{"_local_timestamp": "2026-01-25T23:49:38.815536+00:00", "data": {"market": "0x3b41890d5e8c9640649a9e6f724d1f74aa67af855506db6f871c5fdac70cfd90", "price_changes": [{"asset_id": "88830742474573630269392959399954338068265843991617686189000213034050940973037", "price": "0.36", "size": "0", "side": "BUY", "hash": "e4dafeb71e5c441e33ffcb5efdd1bda864770e51", "best_bid": "0.39", "best_ask": "0.4"}, {"asset_id": "24393720551520374522532949229976185621516426573885698267923116722310834739486", "price": "0.64", "size": "0", "side": "SELL", "hash": "ba6438250ea20589ceadb8c2dc7354d97a80ba4e", "best_bid": "0.6", "best_ask": "0.61"}], "timestamp": "1769384978735", "event_type": "price_change"}}
{"_local_timestamp": "2026-01-25T23:49:39.557646+00:00", "data": {"market": "0x3b41890d5e8c9640649a9e6f724d1f74aa67af855506db6f871c5fdac70cfd90", "price_changes": [{"asset_id": "88830742474573630269392959399954338068265843991617686189000213034050940973037", "price": "0.35", "size": "100", "side": "BUY", "hash": "7fb3e58200032e1511f30707da3f5cf69bef8271", "best_bid": "0.39", "best_ask": "0.4"}, {"asset_id": "24393720551520374522532949229976185621516426573885698267923116722310834739486", "price": "0.65", "size": "100", "side": "SELL", "hash": "9c2f2bbafadf2076a87f3618bfb004f0676e6513", "best_bid": "0.6", "best_ask": "0.61"}], "timestamp": "1769384979487", "event_type": "price_change"}}
{"_local_timestamp": "2026-01-25T23:49:41.864021+00:00", "data": {"market": "0x3b41890d5e8c9640649a9e6f724d1f74aa67af855506db6f871c5fdac70cfd90", "price_changes": [{"asset_id": "24393720551520374522532949229976185621516426573885698267923116722310834739486", "price": "0.27", "size": "0", "side": "BUY", "hash": "69d97766cb61ddd4aa54e8339537085bb6e39672", "best_bid": "0.6", "best_ask": "0.61"}, {"asset_id": "88830742474573630269392959399954338068265843991617686189000213034050940973037", "price": "0.73", "size": "0", "side": "SELL", "hash": "77f3f19260921200a59f39de883e534aefccfa27", "best_bid": "0.39", "best_ask": "0.4"}], "timestamp": "1769384981726", "event_type": "price_change"}}
{"_local_timestamp": "2026-01-25T23:49:42.396918+00:00", "data": {"market": "0x3b41890d5e8c9640649a9e6f724d1f74aa67af855506db6f871c5fdac70cfd90", "price_changes": [{"asset_id": "24393720551520374522532949229976185621516426573885698267923116722310834739486", "price": "0.28", "size": "50", "side": "BUY", "hash": "5dffd4c703acbf17aa4bc80dbbd82dd395c084d0", "best_bid": "0.6", "best_ask": "0.61"}, {"asset_id": "88830742474573630269392959399954338068265843991617686189000213034050940973037", "price": "0.72", "size": "50", "side": "SELL", "hash": "b189eab5b5a04e3e6ca9d3d329022d1d8ab5ca3e", "best_bid": "0.39", "best_ask": "0.4"}], "timestamp": "1769384982227", "event_type": "price_change"}}
{"_local_timestamp": "2026-01-25T23:49:51.215666+00:00", "data": {"market": "0x3b41890d5e8c9640649a9e6f724d1f74aa67af855506db6f871c5fdac70cfd90", "price_changes": [{"asset_id": "24393720551520374522532949229976185621516426573885698267923116722310834739486", "price": "0.19", "size": "250", "side": "BUY", "hash": "cfd6be26e54b6fa24e5287c33d570196e773e928", "best_bid": "0.6", "best_ask": "0.61"}, {"asset_id": "88830742474573630269392959399954338068265843991617686189000213034050940973037", "price": "0.81", "size": "250", "side": "SELL", "hash": "a862bc40be8cf2c7815a3ea54c22ed9581f9addb", "best_bid": "0.39", "best_ask": "0.4"}], "timestamp": "1769384991039", "event_type": "price_change"}}
{"_local_timestamp": "2026-01-25T23:50:02.630460+00:00", "data": {"market": "0x3b41890d5e8c9640649a9e6f724d1f74aa67af855506db6f871c5fdac70cfd90", "price_changes": [{"asset_id": "24393720551520374522532949229976185621516426573885698267923116722310834739486", "price": "0.15", "size": "550", "side": "BUY", "hash": "76864e5c5dc63a54d0e1ab6242f1b6f3da74c01a", "best_bid": "0.6", "best_ask": "0.61"}, {"asset_id": "88830742474573630269392959399954338068265843991617686189000213034050940973037", "price": "0.85", "size": "550", "side": "SELL", "hash": "d481b8a0d6853cf3c7776811dcb881d26c30f77a", "best_bid": "0.39", "best_ask": "0.4"}], "timestamp": "1769385002279", "event_type": "price_change"}}
{"_local_timestamp": "2026-01-25T23:50:08.975721+00:00", "data": {"market": "0x3b41890d5e8c9640649a9e6f724d1f74aa67af855506db6f871c5fdac70cfd90", "price_changes": [{"asset_id": "24393720551520374522532949229976185621516426573885698267923116722310834739486", "price": "0.18", "size": "2482", "side": "BUY", "hash": "8af7c8ff60a24e93c722f0c6a3815a4a6c735a23", "best_bid": "0.6", "best_ask": "0.61"}, {"asset_id": "88830742474573630269392959399954338068265843991617686189000213034050940973037", "price": "0.82", "size": "2482", "side": "SELL", "hash": "0beba2b02126ce8bc34d0a6c0d92488871fa4b31", "best_bid": "0.39", "best_ask": "0.4"}], "timestamp": "1769385008901", "event_type": "price_change"}}
{"_local_timestamp": "2026-01-25T23:50:21.975984+00:00", "data": {"market": "0xdd9f55a4a214da7231a64eb6f43a05f525b51e7bcf714db0c2d3b2fd0fc0c9ca", "price_changes": [{"asset_id": "87855193300342526755310181206520215785023964324419734896948555881922627101363", "price": "0.66", "size": "0", "side": "BUY", "hash": "c5a27a39a1a969e6239e0fc3cb900e603301a065", "best_bid": "0.67", "best_ask": "0.76"}, {"asset_id": "18582106713580348058065911013375325630183346495483834588274922531241537980162", "price": "0.34", "size": "0", "side": "SELL", "hash": "af4a8deb184893e467f2a96860eea240ba451553", "best_bid": "0.24", "best_ask": "0.33"}], "timestamp": "1769385021887", "event_type": "price_change"}}
{"_local_timestamp": "2026-01-25T23:50:22.583369+00:00", "data": {"market": "0xdd9f55a4a214da7231a64eb6f43a05f525b51e7bcf714db0c2d3b2fd0fc0c9ca", "price_changes": [{"asset_id": "87855193300342526755310181206520215785023964324419734896948555881922627101363", "price": "0.67", "size": "33.42", "side": "BUY", "hash": "578bf7c7218df588fd112565e121850624b5c98a", "best_bid": "0.67", "best_ask": "0.76"}, {"asset_id": "18582106713580348058065911013375325630183346495483834588274922531241537980162", "price": "0.33", "size": "33.42", "side": "SELL", "hash": "fc4f36fd7df41a1dec51993ef6f8bfca48b3f27b", "best_bid": "0.24", "best_ask": "0.33"}], "timestamp": "1769385022497", "event_type": "price_change"}}
{"_local_timestamp": "2026-01-25T23:50:23.270881+00:00", "data": {"market": "0xdd9f55a4a214da7231a64eb6f43a05f525b51e7bcf714db0c2d3b2fd0fc0c9ca", "price_changes": [{"asset_id": "87855193300342526755310181206520215785023964324419734896948555881922627101363", "price": "0.18", "size": "199.99", "side": "BUY", "hash": "9c875aedae52a895519209edcf65a675f0dbb4f6", "best_bid": "0.67", "best_ask": "0.76"}, {"asset_id": "18582106713580348058065911013375325630183346495483834588274922531241537980162", "price": "0.82", "size": "199.99", "side": "SELL", "hash": "590fd5e3e91d265a903cb2bd5844f47bf938131e", "best_bid": "0.24", "best_ask": "0.33"}], "timestamp": "1769385023175", "event_type": "price_change"}}
{"_local_timestamp": "2026-01-25T23:50:46.377798+00:00", "data": {"market": "0x3b41890d5e8c9640649a9e6f724d1f74aa67af855506db6f871c5fdac70cfd90", "price_changes": [{"asset_id": "24393720551520374522532949229976185621516426573885698267923116722310834739486", "price": "0.19", "size": "100", "side": "BUY", "hash": "d1739fca88e7d75d4d401ea6fbd918f85898aff3", "best_bid": "0.6", "best_ask": "0.61"}, {"asset_id": "88830742474573630269392959399954338068265843991617686189000213034050940973037", "price": "0.81", "size": "100", "side": "SELL", "hash": "f1d02ccdf1e726eb52587757f3647871b9ecfc02", "best_bid": "0.39", "best_ask": "0.4"}], "timestamp": "1769385046266", "event_type": "price_change"}}
{"_local_timestamp": "2026-01-25T23:50:46.774350+00:00", "data": {"market": "0x3b41890d5e8c9640649a9e6f724d1f74aa67af855506db6f871c5fdac70cfd90", "price_changes": [{"asset_id": "24393720551520374522532949229976185621516426573885698267923116722310834739486", "price": "0.18", "size": "2632", "side": "BUY", "hash": "9a4b7589a2274ab384fcf1614bde2e7b37881f13", "best_bid": "0.6", "best_ask": "0.61"}, {"asset_id": "88830742474573630269392959399954338068265843991617686189000213034050940973037", "price": "0.82", "size": "2632", "side": "SELL", "hash": "4081e32b9cfcf04740dbb18406c21d0261232c08", "best_bid": "0.39", "best_ask": "0.4"}], "timestamp": "1769385046645", "event_type": "price_change"}}
{"_local_timestamp": "2026-01-25T23:51:05.972797+00:00", "data": {"market": "0xdd9f55a4a214da7231a64eb6f43a05f525b51e7bcf714db0c2d3b2fd0fc0c9ca", "price_changes": [{"asset_id": "87855193300342526755310181206520215785023964324419734896948555881922627101363", "price": "0.29", "size": "250", "side": "BUY", "hash": "ed6810db141955600bcc9f2dc42f9609461987d8", "best_bid": "0.67", "best_ask": "0.76"}, {"asset_id": "18582106713580348058065911013375325630183346495483834588274922531241537980162", "price": "0.71", "size": "250", "side": "SELL", "hash": "2575a14b1a497d958b479442f4b176d2c791c12c", "best_bid": "0.24", "best_ask": "0.33"}], "timestamp": "1769385065783", "event_type": "price_change"}}
{"_local_timestamp": "2026-01-25T23:51:09.435350+00:00", "data": {"market": "0x3b41890d5e8c9640649a9e6f724d1f74aa67af855506db6f871c5fdac70cfd90", "price_changes": [{"asset_id": "24393720551520374522532949229976185621516426573885698267923116722310834739486", "price": "0.23", "size": "918", "side": "BUY", "hash": "8399fc3354d98d8d8c232b64449b92f73604d2e7", "best_bid": "0.6", "best_ask": "0.61"}, {"asset_id": "88830742474573630269392959399954338068265843991617686189000213034050940973037", "price": "0.77", "size": "918", "side": "SELL", "hash": "0428d60a11df0362856192b6ecddf46a47861e02", "best_bid": "0.39", "best_ask": "0.4"}], "timestamp": "1769385069356", "event_type": "price_change"}}
{"_local_timestamp": "2026-01-25T23:51:09.436194+00:00", "data": {"market": "0x3b41890d5e8c9640649a9e6f724d1f74aa67af855506db6f871c5fdac70cfd90", "price_changes": [{"asset_id": "24393720551520374522532949229976185621516426573885698267923116722310834739486", "price": "0.26", "size": "458", "side": "BUY", "hash": "0eda671ba2ef87be71e9fcb38631c8f288242008", "best_bid": "0.6", "best_ask": "0.61"}, {"asset_id": "88830742474573630269392959399954338068265843991617686189000213034050940973037", "price": "0.74", "size": "458", "side": "SELL", "hash": "c377a6f1512f21a4eadffd90cba875250d125ac7", "best_bid": "0.39", "best_ask": "0.4"}], "timestamp": "1769385069357", "event_type": "price_change"}}
