{"_local_timestamp": "2026-01-25T23:33:24.908073+00:00", "data": [{"market": "0x1512828f4c735012fde09e2424f033bd2cd128a1a84e7aa7769440b66a1dd7c5", "asset_id": "59446984750383689166016671329084781990333496644061769271895177118630247823357", "timestamp": "1769384004265", "hash": "a42a4462d59fb5e60c893459e5c0412aa86e7a39", "bids": [{"price": "0.01", "size": "1750"}, {"price": "0.02", "size": "1508.04"}, {"price": "0.03", "size": "2667"}, {"price": "0.04", "size": "6.92"}, {"price": "0.05", "size": "148"}, {"price": "0.07", "size": "6"}, {"price": "0.09", "size": "6.24"}, {"price": "0.12", "size": "6"}, {"price": "0.13", "size": "415.69"}, {"price": "0.14", "size": "78.57"}, {"price": "0.15", "size": "159"}, {"price": "0.18", "size": "780.2"}, {"price": "0.19", "size": "227"}, {"price": "0.2", "size": "235.75"}], "asks": [{"price": "0.99", "size": "7509.87"}, {"price": "0.98", "size": "5800"}, {"price": "0.97", "size": "508.06"}, {"price": "0.96", "size": "1250"}, {"price": "0.92", "size": "1150"}, {"price": "0.91", "size": "7.32"}, {"price": "0.88", "size": "283.33"}, {"price": "0.87", "size": "550"}, {"price": "0.84", "size": "200"}, {"price": "0.83", "size": "940"}, {"price": "0.8", "size": "1140"}, {"price": "0.78", "size": "1908"}, {"price": "0.76", "size": "408.33"}, {"price": "0.74", "size": "300"}, {"price": "0.73", "size": "50"}, {"price": "0.72", "size": "85.71"}, {"price": "0.71", "size": "6"}, {"price": "0.68", "size": "62.5"}, {"price": "0.66", "size": "125"}, {"price": "0.5", "size": "560"}, {"price": "0.49", "size": "31.44"}, {"price": "0.42", "size": "10"}, {"price": "0.4", "size": "17"}, {"price": "0.34", "size": "200"}, {"price": "0.33", "size": "241.56"}, {"price": "0.32", "size": "119.11"}, {"price": "0.31", "size": "21.94"}, {"price": "0.29", "size": "931.4"}, {"price": "0.27", "size": "30"}, {"price": "0.26", "size": "6"}, {"price": "0.24", "size": "481.99"}, {"price": "0.23", "size": "30"}, {"price": "0.22", "size": "7"}], "event_type": "book", "last_trade_price": "0.800"}, {"market": "0x1512828f4c735012fde09e2424f033bd2cd128a1a84e7aa7769440b66a1dd7c5", "asset_id": "36050353753599194454464623080394572359037222441624334030228054568398520086707", "timestamp": "1769384004265", "hash": "b7f4eaed45076c37304fad060879ce800b794441", "bids": [{"price": "0.01", "size": "7509.87"}, {"price": "0.02", "size": "5800"}, {"price": "0.03", "size": "508.06"}, {"price": "0.04", "size": "1250"}, {"price": "0.08", "size": "1150"}, {"price": "0.09", "size": "7.32"}, {"price": "0.12", "size": "283.33"}, {"price": "0.13", "size": "550"}, {"price": "0.16", "size": "200"}, {"price": "0.17", "size": "940"}, {"price": "0.2", "size": "1140"}, {"price": "0.22", "size": "1908"}, {"price": "0.24", "size": "408.33"}, {"price": "0.26", "size": "300"}, {"price": "0.27", "size": "50"}, {"price": "0.28", "size": "85.71"}, {"price": "0.29", "size": "6"}, {"price": "0.32", "size": "62.5"}, {"price": "0.34", "size": "125"}, {"price": "0.5", "size": "560"}, {"price": "0.51", "size": "31.44"}, {"price": "0.58", "size": "10"}, {"price": "0.6", "size": "17"}, {"price": "0.66", "size": "200"}, {"price": "0.67", "size": "241.56"}, {"price": "0.68", "size": "119.11"}, {"price": "0.69", "size": "21.94"}, {"price": "0.71", "size": "931.4"}, {"price": "0.73", "size": "30"}, {"price": "0.74", "size": "6"}, {"price": "0.76", "size": "481.99"}, {"price": "0.77", "size": "30"}, {"price": "0.78", "size": "7"}], "asks": [{"price": "0.99", "size": "1750"}, {"price": "0.98", "size": "1508.04"}, {"price": "0.97", "size": "2667"}, {"price": "0.96", "size": "6.92"}, {"price": "0.95", "size": "148"}, {"price": "0.93", "size": "6"}, {"price": "0.91", "size": "6.24"}, {"price": "0.88", "size": "6"}, {"price": "0.87", "size": "415.69"}, {"price": "0.86", "size": "78.57"}, {"price": "0.85", "size": "159"}, {"price": "0.82", "size": "780.2"}, {"price": "0.81", "size": "227"}, {"price": "0.8", "size": "235.75"}], "event_type": "book", "last_trade_price": "0.800"}]}
{"_local_timestamp": "2026-01-25T23:33:33.354926+00:00", "data": {"market": "0x1512828f4c735012fde09e2424f033bd2cd128a1a84e7aa7769440b66a1dd7c5", "price_changes": [{"asset_id": "36050353753599194454464623080394572359037222441624334030228054568398520086707", "price": "0.24", "size": "358.33", "side": "BUY", "hash": "d67dcf6fc9d519b74579ceadc0d338c9d0fd88cc", "best_bid": "0.78", "best_ask": "0.8"}, {"asset_id": "59446984750383689166016671329084781990333496644061769271895177118630247823357", "price": "0.76", "size": "358.33", "side": "SELL", "hash": "5a2d36fb7dc5f5b312b6297864f7f73282c39046", "best_bid": "0.2", "best_ask": "0.22"}], "timestamp": "1769384013154", "event_type": "price_change"}}
{"_local_timestamp": "2026-01-25T23:33:33.711515+00:00", "data": {"market": "0x1512828f4c735012fde09e2424f033bd2cd128a1a84e7aa7769440b66a1dd7c5", "price_changes": [{"asset_id": "36050353753599194454464623080394572359037222441624334030228054568398520086707", "price": "0.2", "size": "1190", "side": "BUY", "hash": "3bb92fb8d28f7968688bdc99b9ee7c92926683d2", "best_bid": "0.78", "best_ask": "0.8"}, {"asset_id": "59446984750383689166016671329084781990333496644061769271895177118630247823357", "price": "0.8", "size": "1190", "side": "SELL", "hash": "bab1d319046743f8296a17667d32428a1ddcb583", "best_bid": "0.2", "best_ask": "0.22"}], "timestamp": "1769384013546", "event_type": "price_change"}}
{"_local_timestamp": "2026-01-25T23:33:38.109091+00:00", "data": {"market": "0x1512828f4c735012fde09e2424f033bd2cd128a1a84e7aa7769440b66a1dd7c5", "price_changes": [{"asset_id": "36050353753599194454464623080394572359037222441624334030228054568398520086707", "price": "0.29", "size": "0", "side": "BUY", "hash": "d3a5bf38a67c063bc45c3f1fbe4cf2cb13668619", "best_bid": "0.78", "best_ask": "0.8"}, {"asset_id": "59446984750383689166016671329084781990333496644061769271895177118630247823357", "price": "0.71", "size": "0", "side": "SELL", "hash": "b848f020e06eec286cfb48b25714bf8eda53be00", "best_bid": "0.2", "best_ask": "0.22"}], "timestamp": "1769384018030", "event_type": "price_change"}}
{"_local_timestamp": "2026-01-25T23:33:38.176006+00:00", "data": {"market": "0x1512828f4c735012fde09e2424f033bd2cd128a1a84e7aa7769440b66a1dd7c5", "price_changes": [{"asset_id": "36050353753599194454464623080394572359037222441624334030228054568398520086707", "price": "0.29", "size": "6", "side": "BUY", "hash": "bd111f7789365331df80516081c022c97066b1bd", "best_bid": "0.78", "best_ask": "0.8"}, {"asset_id": "59446984750383689166016671329084781990333496644061769271895177118630247823357", "price": "0.71", "size": "6", "side": "SELL", "hash": "f71f018e7ffef9300cf9b7838a214ab73d604e7c", "best_bid": "0.2", "best_ask": "0.22"}], "timestamp": "1769384018094", "event_type": "price_change"}}
{"_local_timestamp": "2026-01-25T23:33:40.284079+00:00", "data": {"market": "0x1512828f4c735012fde09e2424f033bd2cd128a1a84e7aa7769440b66a1dd7c5", "price_changes": [{"asset_id": "36050353753599194454464623080394572359037222441624334030228054568398520086707", "price": "0.24", "size": "308.33", "side": "BUY", "hash": "f1a163bf200a884506a48eaf81f1b68c1903649f", "best_bid": "0.78", "best_ask": "0.8"}, {"asset_id": "59446984750383689166016671329084781990333496644061769271895177118630247823357", "price": "0.76", "size": "308.33", "side": "SELL", "hash": "437cbaf35ae56d708b6c1dfc03e37ed7c3ad9932", "best_bid": "0.2", "best_ask": "0.22"}], "timestamp": "1769384020097", "event_type": "price_change"}}
{"_local_timestamp": "2026-01-25T23:33:40.760872+00:00", "data": {"market": "0x1512828f4c735012fde09e2424f033bd2cd128a1a84e7aa7769440b66a1dd7c5", "price_changes": [{"asset_id": "36050353753599194454464623080394572359037222441624334030228054568398520086707", "price": "0.21", "size": "50", "side": "BUY", "hash": "8213af1e3e09f43f7838ce32608b466fa6159a85", "best_bid": "0.78", "best_ask": "0.8"}, {"asset_id": "59446984750383689166016671329084781990333496644061769271895177118630247823357", "price": "0.79", "size": "50", "side": "SELL", "hash": "81bce6a95d62dec72eeb0d0b48a72a795892bb04", "best_bid": "0.2", "best_ask": "0.22"}], "timestamp": "1769384020552", "event_type": "price_change"}}
{"_local_timestamp": "2026-01-25T23:33:41.381870+00:00", "data": {"market": "0x1512828f4c735012fde09e2424f033bd2cd128a1a84e7aa7769440b66a1dd7c5", "price_changes": [{"asset_id": "59446984750383689166016671329084781990333496644061769271895177118630247823357", "price": "0.09", "size": "0", "side": "BUY", "hash": "97b67e1df3a9e947b0457615bb7da061f1c33348", "best_bid": "0.2", "best_ask": "0.22"}, {"asset_id": "36050353753599194454464623080394572359037222441624334030228054568398520086707", "price": "0.91", "size": "0", "side": "SELL", "hash": "246b9dda5b8adae631b0786718945c40a5d0135d", "best_bid": "0.78", "best_ask": "0.8"}], "timestamp": "1769384021291", "event_type": "price_change"}}
{"_local_timestamp": "2026-01-25T23:33:41.683592+00:00", "data": {"market": "0x1512828f4c735012fde09e2424f033bd2cd128a1a84e7aa7769440b66a1dd7c5", "price_changes": [{"asset_id": "59446984750383689166016671329084781990333496644061769271895177118630247823357", "price": "0.08", "size": "7.03", "side": "BUY", "hash": "e94e39ebe164ba9ea132b4a412c3127ff600e051", "best_bid": "0.2", "best_ask": "0.22"}, {"asset_id": "36050353753599194454464623080394572359037222441624334030228054568398520086707", "price": "0.92", "size": "7.03", "side": "SELL", "hash": "ae31fbb0e55da5cc194a5c3b9600f0a8d4b45824", "best_bid": "0.78", "best_ask": "0.8"}], "timestamp": "1769384021604", "event_type": "price_change"}}
{"_local_timestamp": "2026-01-25T23:34:04.788374+00:00", "data": {"market": "0x1512828f4c735012fde09e2424f033bd2cd128a1a84e7aa7769440b66a1dd7c5", "price_changes": [{"asset_id": "36050353753599194454464623080394572359037222441624334030228054568398520086707", "price": "0.24", "size": "208.33", "side": "BUY", "hash": "4af4a322e5de0f0ba59256b87e55f840c2f04402", "best_bid": "0.78", "best_ask": "0.8"}, {"asset_id": "59446984750383689166016671329084781990333496644061769271895177118630247823357", "price": "0.76", "size": "208.33", "side": "SELL", "hash": "596ef946d560827f982198bf8d27fd0a364323da", "best_bid": "0.2", "best_ask": "0.22"}], "timestamp": "1769384044567", "event_type": "price_change"}}
{"_local_timestamp": "2026-01-25T23:34:05.159806+00:00", "data": {"market": "0x1512828f4c735012fde09e2424f033bd2cd128a1a84e7aa7769440b66a1dd7c5", "price_changes": [{"asset_id": "36050353753599194454464623080394572359037222441624334030228054568398520086707", "price": "0.22", "size": "2008", "side": "BUY", "hash": "db03defe2d7f74896c2283f8f5d0d994689fc9ad", "best_bid": "0.78", "best_ask": "0.8"}, {"asset_id": "59446984750383689166016671329084781990333496644061769271895177118630247823357", "price": "0.78", "size": "2008", "side": "SELL", "hash": "d3cde89b9defdf5cc0572c1734f3a4aea43c1a94", "best_bid": "0.2", "best_ask": "0.22"}], "timestamp": "1769384044848", "event_type": "price_change"}}
{"_local_timestamp": "2026-01-25T23:34:28.003631+00:00", "data": {"market": "0x1512828f4c735012fde09e2424f033bd2cd128a1a84e7aa7769440b66a1dd7c5", "price_changes": [{"asset_id": "36050353753599194454464623080394572359037222441624334030228054568398520086707", "price": "0.24", "size": "108.33", "side": "BUY", "hash": "d2852c53fb0ade80edde6b4355f3233232f3726e", "best_bid": "0.78", "best_ask": "0.8"}, {"asset_id": "59446984750383689166016671329084781990333496644061769271895177118630247823357", "price": "0.76", "size": "108.33", "side": "SELL", "hash": "cee4b13357aa3e8a61659c3c34e747de0ad81b53", "best_bid": "0.2", "best_ask": "0.22"}], "timestamp": "1769384067610", "event_type": "price_change"}}
{"_local_timestamp": "2026-01-25T23:34:28.643722+00:00", "data": {"market": "0x1512828f4c735012fde09e2424f033bd2cd128a1a84e7aa7769440b66a1dd7c5", "price_changes": [{"asset_id": "36050353753599194454464623080394572359037222441624334030228054568398520086707", "price": "0.21", "size": "150", "side": "BUY", "hash": "2c7099478a902dd23b8f0303f006fe7904ae3c90", "best_bid": "0.78", "best_ask": "0.8"}, {"asset_id": "59446984750383689166016671329084781990333496644061769271895177118630247823357", "price": "0.79", "size": "150", "side": "SELL", "hash": "b599aebd684bbf932237623339f9dfe26e9672b4", "best_bid": "0.2", "best_ask": "0.22"}], "timestamp": "1769384068139", "event_type": "price_change"}}
{"_local_timestamp": "2026-01-25T23:34:33.881571+00:00", "data": {"market": "0x1512828f4c735012fde09e2424f033bd2cd128a1a84e7aa7769440b66a1dd7c5", "price_changes": [{"asset_id": "36050353753599194454464623080394572359037222441624334030228054568398520086707", "price": "0.76", "size": "332", "side": "BUY", "hash": "2163384e9330a733a29add16e826e0c0ee754b46", "best_bid": "0.78", "best_ask": "0.8"}, {"asset_id": "59446984750383689166016671329084781990333496644061769271895177118630247823357", "price": "0.24", "size": "332", "side": "SELL", "hash": "cf0fc2e2ed79f7ca8cd222d0883c8be11285ea4a", "best_bid": "0.2", "best_ask": "0.22"}], "timestamp": "1769384073639", "event_type": "price_change"}}
{"_local_timestamp": "2026-01-25T23:34:34.967365+00:00", "data": {"market": "0x1512828f4c735012fde09e2424f033bd2cd128a1a84e7aa7769440b66a1dd7c5", "price_changes": [{"asset_id": "36050353753599194454464623080394572359037222441624334030228054568398520086707", "price": "0.75", "size": "150", "side": "BUY", "hash": "1d297ee47c8e92724be7c3122d14503c732d568a", "best_bid": "0.78", "best_ask": "0.8"}, {"asset_id": "59446984750383689166016671329084781990333496644061769271895177118630247823357", "price": "0.25", "size": "150", "side": "SELL", "hash": "3788a2f89d4fc3a9f71855390d3f1ac770eb426a", "best_bid": "0.2", "best_ask": "0.22"}], "timestamp": "1769384074754", "event_type": "price_change"}}
{"_local_timestamp": "2026-01-25T23:34:35.129797+00:00", "data": {"market": "0x1512828f4c735012fde09e2424f033bd2cd128a1a84e7aa7769440b66a1dd7c5", "price_changes": [{"asset_id": "36050353753599194454464623080394572359037222441624334030228054568398520086707", "price": "0.76", "size": "282", "side": "BUY", "hash": "309cec3c42359cab1e1663ebc57d786442478a85", "best_bid": "0.78", "best_ask": "0.8"}, {"asset_id": "59446984750383689166016671329084781990333496644061769271895177118630247823357", "price": "0.24", "size": "282", "side": "SELL", "hash": "c086f95ab7ab10a25a62f87b72f689623566b194", "best_bid": "0.2", "best_ask": "0.22"}], "timestamp": "1769384074903", "event_type": "price_change"}}
{"_local_timestamp": "2026-01-25T23:34:35.130488+00:00", "data": {"market": "0x1512828f4c735012fde09e2424f033bd2cd128a1a84e7aa7769440b66a1dd7c5", "price_changes": [{"asset_id": "59446984750383689166016671329084781990333496644061769271895177118630247823357", "price": "0.19", "size": "177", "side": "BUY", "hash": "4f42f2136c68f50f8d801aa00f5408379477010e", "best_bid": "0.2", "best_ask": "0.22"}, {"asset_id": "36050353753599194454464623080394572359037222441624334030228054568398520086707", "price": "0.81", "size": "177", "side": "SELL", "hash": "fc87a6db06d8160f39ed806cc99513562224a0a4", "best_bid": "0.78", "best_ask": "0.8"}], "timestamp": "1769384074904", "event_type": "price_change"}}
{"_local_timestamp": "2026-01-25T23:34:35.354511+00:00", "data": {"market": "0x1512828f4c735012fde09e2424f033bd2cd128a1a84e7aa7769440b66a1dd7c5", "price_changes": [{"asset_id": "59446984750383689166016671329084781990333496644061769271895177118630247823357", "price": "0.19", "size": "227", "side": "BUY", "hash": "094e65e92c4cd11aede27fbbbcd80762281f78f2", "best_bid": "0.2", "best_ask": "0.22"}, {"asset_id": "36050353753599194454464623080394572359037222441624334030228054568398520086707", "price": "0.81", "size": "227", "side": "SELL", "hash": "e2718459b2855d4d7f41fe16faf8d956280b930b", "best_bid": "0.78", "best_ask": "0.8"}], "timestamp": "1769384075084", "event_type": "price_change"}}
{"_local_timestamp": "2026-01-25T23:34:35.355668+00:00", "data": {"market": "0x1512828f4c735012fde09e2424f033bd2cd128a1a84e7aa7769440b66a1dd7c5", "price_changes": [{"asset_id": "36050353753599194454464623080394572359037222441624334030228054568398520086707", "price": "0.75", "size": "200", "side": "BUY", "hash": "dfe31f0c01da70e79b05d4b5eeaec12f9c3e0a5e", "best_bid": "0.78", "best_ask": "0.8"}, {"asset_id": "59446984750383689166016671329084781990333496644061769271895177118630247823357", "price": "0.25", "size": "200", "side": "SELL", "hash": "ca1b6b45ee899880866ba05231d6c4c9d0d23956", "best_bid": "0.2", "best_ask": "0.22"}], "timestamp": "1769384075084", "event_type": "price_change"}}
{"_local_timestamp": "2026-01-25T23:34:37.481093+00:00", "data": {"market": "0x1512828f4c735012fde09e2424f033bd2cd128a1a84e7aa7769440b66a1dd7c5", "price_changes": [{"asset_id": "36050353753599194454464623080394572359037222441624334030228054568398520086707", "price": "0.68", "size": "19.11", "side": "BUY", "hash": "d5ef2f5be02fb9f6855d4de1cdc0b35e2df72045", "best_bid": "0.78", "best_ask": "0.8"}, {"asset_id": "59446984750383689166016671329084781990333496644061769271895177118630247823357", "price": "0.32", "size": "19.11", "side": "SELL", "hash": "d2c08a59d9bdb5f6e1bf3731986b0e85469bf7d4", "best_bid": "0.2", "best_ask": "0.22"}], "timestamp": "1769384077268", "event_type": "price_change"}}
{"_local_timestamp": "2026-01-25T23:34:38.100529+00:00", "data": {"market": "0x1512828f4c735012fde09e2424f033bd2cd128a1a84e7aa7769440b66a1dd7c5", "price_changes": [{"asset_id": "36050353753599194454464623080394572359037222441624334030228054568398520086707", "price": "0.77", "size": "130", "side": "BUY", "hash": "958f18b5094fe64aaa81a123c972cc11af96a5ee", "best_bid": "0.78", "best_ask": "0.8"}, {"asset_id": "59446984750383689166016671329084781990333496644061769271895177118630247823357", "price": "0.23", "size": "130", "side": "SELL", "hash": "1b24c144454aaec1433c1c76bb2d2751b6c25ead", "best_bid": "0.2", "best_ask": "0.22"}], "timestamp": "1769384078026", "event_type": "price_change"}}
{"_local_timestamp": "2026-01-25T23:34:38.549611+00:00", "data": {"market": "0x1512828f4c735012fde09e2424f033bd2cd128a1a84e7aa7769440b66a1dd7c5", "price_changes": [{"asset_id": "36050353753599194454464623080394572359037222441624334030228054568398520086707", "price": "0.75", "size": "150", "side": "BUY", "hash": "2010d40888e80829b185a7ad0d44f9ccdef00058", "best_bid": "0.78", "best_ask": "0.8"}, {"asset_id": "59446984750383689166016671329084781990333496644061769271895177118630247823357", "price": "0.25", "size": "150", "side": "SELL", "hash": "3a33188dbcc1d59b0eb5d73a1a8cacd7f104867c", "best_bid": "0.2", "best_ask": "0.22"}], "timestamp": "1769384078468", "event_type": "price_change"}}
{"_local_timestamp": "2026-01-25T23:34:38.550102+00:00", "data": {"market": "0x1512828f4c735012fde09e2424f033bd2cd128a1a84e7aa7769440b66a1dd7c5", "price_changes": [{"asset_id": "59446984750383689166016671329084781990333496644061769271895177118630247823357", "price": "0.19", "size": "177", "side": "BUY", "hash": "d8d34dff2435277de90b92ba4c0c855f74b6190a", "best_bid": "0.2", "best_ask": "0.22"}, {"asset_id": "36050353753599194454464623080394572359037222441624334030228054568398520086707", "price": "0.81", "size": "177", "side": "SELL", "hash": "aabbecd26635634fc0533916eae742b09287a0de", "best_bid": "0.78", "best_ask": "0.8"}], "timestamp": "1769384078469", "event_type": "price_change"}}
{"_local_timestamp": "2026-01-25T23:34:38.774229+00:00", "data": {"market": "0x1512828f4c735012fde09e2424f033bd2cd128a1a84e7aa7769440b66a1dd7c5", "price_changes": [{"asset_id": "36050353753599194454464623080394572359037222441624334030228054568398520086707", "price": "0.76", "size": "332", "side": "BUY", "hash": "37f0c6fb6322f0c662430e0900d5c13faec08ab4", "best_bid": "0.78", "best_ask": "0.8"}, {"asset_id": "59446984750383689166016671329084781990333496644061769271895177118630247823357", "price": "0.24", "size": "332", "side": "SELL", "hash": "5d684efa7171efe408be0a28d07ecfa44f426505", "best_bid": "0.2", "best_ask": "0.22"}], "timestamp": "1769384078701", "event_type": "price_change"}}
{"_local_timestamp": "2026-01-25T23:34:38.774667+00:00", "data": {"market": "0x1512828f4c735012fde09e2424f033bd2cd128a1a84e7aa7769440b66a1dd7c5", "price_changes": [{"asset_id": "59446984750383689166016671329084781990333496644061769271895177118630247823357", "price": "0.19", "size": "227", "side": "BUY", "hash": "3b4d170997cc6ecbd2fc1ab11353b578abf133ee", "best_bid": "0.2", "best_ask": "0.22"}, {"asset_id": "36050353753599194454464623080394572359037222441624334030228054568398520086707", "price": "0.81", "size": "227", "side": "SELL", "hash": "a7d43a23949a63a712bdfa63f6ad0def36d1dc50", "best_bid": "0.78", "best_ask": "0.8"}], "timestamp": "1769384078701", "event_type": "price_change"}}
{"_local_timestamp": "2026-01-25T23:34:41.357697+00:00", "data": {"market": "0x1512828f4c735012fde09e2424f033bd2cd128a1a84e7aa7769440b66a1dd7c5", "price_changes": [{"asset_id": "59446984750383689166016671329084781990333496644061769271895177118630247823357", "price": "0.08", "size": "0", "side": "BUY", "hash": "c50a5cbad7a6b0f6b691d376a709199f30c818b2", "best_bid": "0.2", "best_ask": "0.22"}, {"asset_id": "36050353753599194454464623080394572359037222441624334030228054568398520086707", "price": "0.92", "size": "0", "side": "SELL", "hash": "eb403f5188fd58ffcb35c3b24bfecdba14a10399", "best_bid": "0.78", "best_ask": "0.8"}], "timestamp": "1769384081287", "event_type": "price_change"}}
{"_local_timestamp": "2026-01-25T23:34:43.734636+00:00", "data": {"market": "0x1512828f4c735012fde09e2424f033bd2cd128a1a84e7aa7769440b66a1dd7c5", "price_changes": [{"asset_id": "59446984750383689166016671329084781990333496644061769271895177118630247823357", "price": "0.08", "size": "7.03", "side": "BUY", "hash": "41209ef2e4b5aaa5d9296e27c9adeb30d2636b7e", "best_bid": "0.2", "best_ask": "0.22"}, {"asset_id": "36050353753599194454464623080394572359037222441624334030228054568398520086707", "price": "0.92", "size": "7.03", "side": "SELL", "hash": "5a701afea23444272ebf87d8053b9c50880314e1", "best_bid": "0.78", "best_ask": "0.8"}], "timestamp": "1769384083662", "event_type": "price_change"}}
{"_local_timestamp": "2026-01-25T23:35:26.737570+00:00", "data": {"market": "0x1512828f4c735012fde09e2424f033bd2cd128a1a84e7aa7769440b66a1dd7c5", "price_changes": [{"asset_id": "36050353753599194454464623080394572359037222441624334030228054568398520086707", "price": "0.21", "size": "100", "side": "BUY", "hash": "f918a2ef4335ce5dedf55d5d2cdd763eb0865a26", "best_bid": "0.78", "best_ask": "0.8"}, {"asset_id": "59446984750383689166016671329084781990333496644061769271895177118630247823357", "price": "0.79", "size": "100", "side": "SELL", "hash": "c8312b5dd7851ab0d659314fb75afa11bcc8f991", "best_bid": "0.2", "best_ask": "0.22"}], "timestamp": "1769384126573", "event_type": "price_change"}}
{"_local_timestamp": "2026-01-25T23:35:27.049701+00:00", "data": {"market": "0x1512828f4c735012fde09e2424f033bd2cd128a1a84e7aa7769440b66a1dd7c5", "price_changes": [{"asset_id": "36050353753599194454464623080394572359037222441624334030228054568398520086707", "price": "0.22", "size": "2058", "side": "BUY", "hash": "a50e246cb32dc74d6647a9540adc14b5f3ab20fa", "best_bid": "0.78", "best_ask": "0.8"}, {"asset_id": "59446984750383689166016671329084781990333496644061769271895177118630247823357", "price": "0.78", "size": "2058", "side": "SELL", "hash": "480f61e82ed86ace48b37d71cc35dc496f2f234b", "best_bid": "0.2", "best_ask": "0.22"}], "timestamp": "1769384126882", "event_type": "price_change"}}
{"_local_timestamp": "2026-01-25T23:35:52.325076+00:00", "data": {"market": "0x1512828f4c735012fde09e2424f033bd2cd128a1a84e7aa7769440b66a1dd7c5", "price_changes": [{"asset_id": "36050353753599194454464623080394572359037222441624334030228054568398520086707", "price": "0.75", "size": "0", "side": "BUY", "hash": "149dadc379ee19c1175df506708d3374377d38d7", "best_bid": "0.78", "best_ask": "0.8"}, {"asset_id": "59446984750383689166016671329084781990333496644061769271895177118630247823357", "price": "0.25", "size": "0", "side": "SELL", "hash": "e1be08336aba739cf821333dea9ac859942f287b", "best_bid": "0.2", "best_ask": "0.22"}], "timestamp": "1769384152247", "event_type": "price_change"}}
{"_local_timestamp": "2026-01-25T23:35:54.022218+00:00", "data": {"market": "0x1512828f4c735012fde09e2424f033bd2cd128a1a84e7aa7769440b66a1dd7c5", "price_changes": [{"asset_id": "36050353753599194454464623080394572359037222441624334030228054568398520086707", "price": "0.76", "size": "481.99", "side": "BUY", "hash": "3c40700b2a2328bc7779fa1a9f0aea83fe72d344", "best_bid": "0.78", "best_ask": "0.8"}, {"asset_id": "59446984750383689166016671329084781990333496644061769271895177118630247823357", "price": "0.24", "size": "481.99", "side": "SELL", "hash": "ab0055746bb533c70713937db11bc8f88415a7fa", "best_bid": "0.2", "best_ask": "0.22"}], "timestamp": "1769384153948", "event_type": "price_change"}}
{"_local_timestamp": "2026-01-25T23:35:55.374039+00:00", "data": {"market": "0x1512828f4c735012fde09e2424f033bd2cd128a1a84e7aa7769440b66a1dd7c5", "price_changes": [{"asset_id": "36050353753599194454464623080394572359037222441624334030228054568398520086707", "price": "0.77", "size": "30", "side": "BUY", "hash": "a8cf217d038d47e02fa27b71a03cb164cd28e85e", "best_bid": "0.78", "best_ask": "0.8"}, {"asset_id": "59446984750383689166016671329084781990333496644061769271895177118630247823357", "price": "0.23", "size": "30", "side": "SELL", "hash": "2cc1fc267760fd271dd5862d53cf531db60e0d97", "best_bid": "0.2", "best_ask": "0.22"}], "timestamp": "1769384155306", "event_type": "price_change"}}
{"_local_timestamp": "2026-01-25T23:35:55.983356+00:00", "data": {"market": "0x1512828f4c735012fde09e2424f033bd2cd128a1a84e7aa7769440b66a1dd7c5", "price_changes": [{"asset_id": "36050353753599194454464623080394572359037222441624334030228054568398520086707", "price": "0.68", "size": "119.11", "side": "BUY", "hash": "72c9ce6d5c1f3b9da446434c05717da42071f30f", "best_bid": "0.78", "best_ask": "0.8"}, {"asset_id": "59446984750383689166016671329084781990333496644061769271895177118630247823357", "price": "0.32", "size": "119.11", "side": "SELL", "hash": "7f028d66ad893744069ee9b00f71c1afaf943ceb", "best_bid": "0.2", "best_ask": "0.22"}], "timestamp": "1769384155909", "event_type": "price_change"}}
{"_local_timestamp": "2026-01-25T23:35:56.445952+00:00", "data": {"market": "0x1512828f4c735012fde09e2424f033bd2cd128a1a84e7aa7769440b66a1dd7c5", "price_changes": [{"asset_id": "36050353753599194454464623080394572359037222441624334030228054568398520086707", "price": "0.2", "size": "1140", "side": "BUY", "hash": "53f16a2cbaa74b41fb7c172969e8be00554c9208", "best_bid": "0.78", "best_ask": "0.8"}, {"asset_id": "59446984750383689166016671329084781990333496644061769271895177118630247823357", "price": "0.8", "size": "1140", "side": "SELL", "hash": "258e5b813bb1e9404da92da2a1b7167b8e1c6a4c", "best_bid": "0.2", "best_ask": "0.22"}], "timestamp": "1769384156294", "event_type": "price_change"}}
{"_local_timestamp": "2026-01-25T23:35:56.854947+00:00", "data": {"market": "0x1512828f4c735012fde09e2424f033bd2cd128a1a84e7aa7769440b66a1dd7c5", "price_changes": [{"asset_id": "36050353753599194454464623080394572359037222441624334030228054568398520086707", "price": "0.22", "size": "2108", "side": "BUY", "hash": "f1ddbc9877719b5ffed99236f3af45cd3d67b0f2", "best_bid": "0.78", "best_ask": "0.8"}, {"asset_id": "59446984750383689166016671329084781990333496644061769271895177118630247823357", "price": "0.78", "size": "2108", "side": "SELL", "hash": "9d316a53d4a82db17b8731eee4659e578e98146e", "best_bid": "0.2", "best_ask": "0.22"}], "timestamp": "1769384156733", "event_type": "price_change"}}
{"_local_timestamp": "2026-01-25T23:36:55.170487+00:00", "data": {"market": "0x1512828f4c735012fde09e2424f033bd2cd128a1a84e7aa7769440b66a1dd7c5", "price_changes": [{"asset_id": "36050353753599194454464623080394572359037222441624334030228054568398520086707", "price": "0.21", "size": "0", "side": "BUY", "hash": "28285eb8a555260b407d46715a7822f75bef5e80", "best_bid": "0.78", "best_ask": "0.8"}, {"asset_id": "59446984750383689166016671329084781990333496644061769271895177118630247823357", "price": "0.79", "size": "0", "side": "SELL", "hash": "f6bb986eee4e109cdd67200c19b2aadd07cd479c", "best_bid": "0.2", "best_ask": "0.22"}], "timestamp": "1769384215024", "event_type": "price_change"}}
{"_local_timestamp": "2026-01-25T23:36:56.089531+00:00", "data": {"market": "0x1512828f4c735012fde09e2424f033bd2cd128a1a84e7aa7769440b66a1dd7c5", "price_changes": [{"asset_id": "36050353753599194454464623080394572359037222441624334030228054568398520086707", "price": "0.22", "size": "2208", "side": "BUY", "hash": "dfa1cb7db63df3afac207551f756b805a1e8f284", "best_bid": "0.78", "best_ask": "0.8"}, {"asset_id": "59446984750383689166016671329084781990333496644061769271895177118630247823357", "price": "0.78", "size": "2208", "side": "SELL", "hash": "736fb22b6f314c28be5a7a6d42ac9da798986b03", "best_bid": "0.2", "best_ask": "0.22"}], "timestamp": "1769384215692", "event_type": "price_change"}}
{"_local_timestamp": "2026-01-25T23:37:14.831946+00:00", "data": {"market": "0x1512828f4c735012fde09e2424f033bd2cd128a1a84e7aa7769440b66a1dd7c5", "price_changes": [{"asset_id": "36050353753599194454464623080394572359037222441624334030228054568398520086707", "price": "0.76", "size": "332", "side": "BUY", "hash": "f00bf199ac1f4aa2758059dd486fe7aa08c93481", "best_bid": "0.78", "best_ask": "0.8"}, {"asset_id": "59446984750383689166016671329084781990333496644061769271895177118630247823357", "price": "0.24", "size": "332", "side": "SELL", "hash": "5fc72db8f03a119af34850d5fcfcfd02451b1e2f", "best_bid": "0.2", "best_ask": "0.22"}], "timestamp": "1769384234754", "event_type": "price_change"}}
{"_local_timestamp": "2026-01-25T23:37:16.739875+00:00", "data": {"market": "0x1512828f4c735012fde09e2424f033bd2cd128a1a84e7aa7769440b66a1dd7c5", "price_changes": [{"asset_id": "36050353753599194454464623080394572359037222441624334030228054568398520086707", "price": "0.75", "size": "150", "side": "BUY", "hash": "acf574eb6e69a838a896a2c2ef3ebb786514fdd0", "best_bid": "0.78", "best_ask": "0.8"}, {"asset_id": "59446984750383689166016671329084781990333496644061769271895177118630247823357", "price": "0.25", "size": "150", "side": "SELL", "hash": "9714944889230005f2184fc67551bfd4f41cf1b1", "best_bid": "0.2", "best_ask": "0.22"}], "timestamp": "1769384236669", "event_type": "price_change"}}
{"_local_timestamp": "2026-01-25T23:37:16.862719+00:00", "data": {"market": "0x1512828f4c735012fde09e2424f033bd2cd128a1a84e7aa7769440b66a1dd7c5", "price_changes": [{"asset_id": "36050353753599194454464623080394572359037222441624334030228054568398520086707", "price": "0.76", "size": "282", "side": "BUY", "hash": "11402f0d9b8ed7e55e9267a6d44b505b6d01a51e", "best_bid": "0.78", "best_ask": "0.8"}, {"asset_id": "59446984750383689166016671329084781990333496644061769271895177118630247823357", "price": "0.24", "size": "282", "side": "SELL", "hash": "044936592b433fc1ddac66954efd460c1366bff8", "best_bid": "0.2", "best_ask": "0.22"}], "timestamp": "1769384236797", "event_type": "price_change"}}
{"_local_timestamp": "2026-01-25T23:37:16.863183+00:00", "data": {"market": "0x1512828f4c735012fde09e2424f033bd2cd128a1a84e7aa7769440b66a1dd7c5", "price_changes": [{"asset_id": "59446984750383689166016671329084781990333496644061769271895177118630247823357", "price": "0.19", "size": "177", "side": "BUY", "hash": "8ad3b939bc71d5b90c0c1c5f989f64bcaba9f02a", "best_bid": "0.2", "best_ask": "0.22"}, {"asset_id": "36050353753599194454464623080394572359037222441624334030228054568398520086707", "price": "0.81", "size": "177", "side": "SELL", "hash": "436db3e38169d9c91d7804cfe89092f54d159ed8", "best_bid": "0.78", "best_ask": "0.8"}], "timestamp": "1769384236798", "event_type": "price_change"}}
{"_local_timestamp": "2026-01-25T23:37:17.029510+00:00", "data": {"market": "0x1512828f4c735012fde09e2424f033bd2cd128a1a84e7aa7769440b66a1dd7c5", "price_changes": [{"asset_id": "36050353753599194454464623080394572359037222441624334030228054568398520086707", "price": "0.75", "size": "200", "side": "BUY", "hash": "db6281bc6814a43226b337290135829b50604687", "best_bid": "0.78", "best_ask": "0.8"}, {"asset_id": "59446984750383689166016671329084781990333496644061769271895177118630247823357", "price": "0.25", "size": "200", "side": "SELL", "hash": "96e4be0c655bbcec7f9c8a1e0f074259925a0ee7", "best_bid": "0.2", "best_ask": "0.22"}], "timestamp": "1769384236951", "event_type": "price_change"}}
{"_local_timestamp": "2026-01-25T23:37:17.029951+00:00", "data": {"market": "0x1512828f4c735012fde09e2424f033bd2cd128a1a84e7aa7769440b66a1dd7c5", "price_changes": [{"asset_id": "59446984750383689166016671329084781990333496644061769271895177118630247823357", "price": "0.19", "size": "227", "side": "BUY", "hash": "c178c56fe45e8115da167b4fc9e0aeaf55cd9c30", "best_bid": "0.2", "best_ask": "0.22"}, {"asset_id": "36050353753599194454464623080394572359037222441624334030228054568398520086707", "price": "0.81", "size": "227", "side": "SELL", "hash": "6674977a7af4ea683dd6ca4ef57e57651337c750", "best_bid": "0.78", "best_ask": "0.8"}], "timestamp": "1769384236952", "event_type": "price_change"}}
{"_local_timestamp": "2026-01-25T23:37:17.365947+00:00", "data": {"market": "0x1512828f4c735012fde09e2424f033bd2cd128a1a84e7aa7769440b66a1dd7c5", "price_changes": [{"asset_id": "36050353753599194454464623080394572359037222441624334030228054568398520086707", "price": "0.68", "size": "19.11", "side": "BUY", "hash": "748cace866c74829867b7b4e7330637745daf5da", "best_bid": "0.78", "best_ask": "0.8"}, {"asset_id": "59446984750383689166016671329084781990333496644061769271895177118630247823357", "price": "0.32", "size": "19.11", "side": "SELL", "hash": "e9e42edf2c982ae3559bcdcf9a766a4b1d926111", "best_bid": "0.2", "best_ask": "0.22"}], "timestamp": "1769384237294", "event_type": "price_change"}}
{"_local_timestamp": "2026-01-25T23:37:18.069586+00:00", "data": {"market": "0x1512828f4c735012fde09e2424f033bd2cd128a1a84e7aa7769440b66a1dd7c5", "price_changes": [{"asset_id": "36050353753599194454464623080394572359037222441624334030228054568398520086707", "price": "0.77", "size": "130", "side": "BUY", "hash": "ea3e330e201ca6c126222e0049bf73a14febb832", "best_bid": "0.78", "best_ask": "0.8"}, {"asset_id": "59446984750383689166016671329084781990333496644061769271895177118630247823357", "price": "0.23", "size": "130", "side": "SELL", "hash": "b5482858d57bba1b4f0f9c609ee9fa75d509abb3", "best_bid": "0.2", "best_ask": "0.22"}], "timestamp": "1769384237989", "event_type": "price_change"}}
{"_local_timestamp": "2026-01-25T23:37:18.750651+00:00", "data": {"market": "0x1512828f4c735012fde09e2424f033bd2cd128a1a84e7aa7769440b66a1dd7c5", "price_changes": [{"asset_id": "59446984750383689166016671329084781990333496644061769271895177118630247823357", "price": "0.19", "size": "177", "side": "BUY", "hash": "6981a7fa5c8e586f95525a046f01b00d87f6924e", "best_bid": "0.2", "best_ask": "0.22"}, {"asset_id": "36050353753599194454464623080394572359037222441624334030228054568398520086707", "price": "0.81", "size": "177", "side": "SELL", "hash": "48b507af333eef71171d215fbc9ad4bd0774696a", "best_bid": "0.78", "best_ask": "0.8"}], "timestamp": "1769384238675", "event_type": "price_change"}}
{"_local_timestamp": "2026-01-25T23:37:18.751169+00:00", "data": {"market": "0x1512828f4c735012fde09e2424f033bd2cd128a1a84e7aa7769440b66a1dd7c5", "price_changes": [{"asset_id": "36050353753599194454464623080394572359037222441624334030228054568398520086707", "price": "0.75", "size": "150", "side": "BUY", "hash": "5c6559d6d8a904f2730c5900b0381aa55891c1c5", "best_bid": "0.78", "best_ask": "0.8"}, {"asset_id": "59446984750383689166016671329084781990333496644061769271895177118630247823357", "price": "0.25", "size": "150", "side": "SELL", "hash": "6d5e9d171176961eb7ed608f4adaea115362d330", "best_bid": "0.2", "best_ask": "0.22"}], "timestamp": "1769384238675", "event_type": "price_change"}}
{"_local_timestamp": "2026-01-25T23:37:18.895925+00:00", "data": {"market": "0x1512828f4c735012fde09e2424f033bd2cd128a1a84e7aa7769440b66a1dd7c5", "price_changes": [{"asset_id": "36050353753599194454464623080394572359037222441624334030228054568398520086707", "price": "0.76", "size": "332", "side": "BUY", "hash": "7885b1657b1d8c4eb1aed0ba2ec3fd929207cf4a", "best_bid": "0.78", "best_ask": "0.8"}, {"asset_id": "59446984750383689166016671329084781990333496644061769271895177118630247823357", "price": "0.24", "size": "332", "side": "SELL", "hash": "deed076619e69d5eb3cd7d7d68c0b9231dc227f8", "best_bid": "0.2", "best_ask": "0.22"}], "timestamp": "1769384238828", "event_type": "price_change"}}
{"_local_timestamp": "2026-01-25T23:37:18.904944+00:00", "data": {"market": "0x1512828f4c735012fde09e2424f033bd2cd128a1a84e7aa7769440b66a1dd7c5", "price_changes": [{"asset_id": "59446984750383689166016671329084781990333496644061769271895177118630247823357", "price": "0.19", "size": "227", "side": "BUY", "hash": "a911ad5545b6fc93bd7640b9f0a27891a4639f97", "best_bid": "0.2", "best_ask": "0.22"}, {"asset_id": "36050353753599194454464623080394572359037222441624334030228054568398520086707", "price": "0.81", "size": "227", "side": "SELL", "hash": "22efe0e1d05823fe2767de2c77d94d99a2c48127", "best_bid": "0.78", "best_ask": "0.8"}], "timestamp": "1769384238828", "event_type": "price_change"}}
{"_local_timestamp": "2026-01-25T23:37:35.229534+00:00", "data": {"market": "0x1512828f4c735012fde09e2424f033bd2cd128a1a84e7aa7769440b66a1dd7c5", "price_changes": [{"asset_id": "36050353753599194454464623080394572359037222441624334030228054568398520086707", "price": "0.22", "size": "300", "side": "BUY", "hash": "9bac088b75a89d36e73dbe69307bc3094abd41df", "best_bid": "0.78", "best_ask": "0.8"}, {"asset_id": "59446984750383689166016671329084781990333496644061769271895177118630247823357", "price": "0.78", "size": "300", "side": "SELL", "hash": "4bd50bf864a3f52ea1c95724b430570f8a3843eb", "best_bid": "0.2", "best_ask": "0.22"}], "timestamp": "1769384255121", "event_type": "price_change"}}
{"_local_timestamp": "2026-01-25T23:37:41.128593+00:00", "data": {"market": "0x1512828f4c735012fde09e2424f033bd2cd128a1a84e7aa7769440b66a1dd7c5", "price_changes": [{"asset_id": "59446984750383689166016671329084781990333496644061769271895177118630247823357", "price": "0.03", "size": "0", "side": "BUY", "hash": "2cfc1d93080c4eb7e6544ec5ce6c4320058dff7b", "best_bid": "0.2", "best_ask": "0.22"}, {"asset_id": "36050353753599194454464623080394572359037222441624334030228054568398520086707", "price": "0.97", "size": "0", "side": "SELL", "hash": "ca1fd798eb9b1bc29f87bae98dc76812fddd4039", "best_bid": "0.78", "best_ask": "0.8"}], "timestamp": "1769384261037", "event_type": "price_change"}}
{"_local_timestamp": "2026-01-25T23:37:41.131566+00:00", "data": {"market": "0x1512828f4c735012fde09e2424f033bd2cd128a1a84e7aa7769440b66a1dd7c5", "price_changes": [{"asset_id": "59446984750383689166016671329084781990333496644061769271895177118630247823357", "price": "0.15", "size": "92", "side": "BUY", "hash": "2fddd4cd5f367e7711eedd622426c90ebf20c018", "best_bid": "0.2", "best_ask": "0.22"}, {"asset_id": "36050353753599194454464623080394572359037222441624334030228054568398520086707", "price": "0.85", "size": "92", "side": "SELL", "hash": "9133bfe4b6f2beee9daf5e3289c1c2a04f64789b", "best_bid": "0.78", "best_ask": "0.8"}], "timestamp": "1769384261040", "event_type": "price_change"}}
{"_local_timestamp": "2026-01-25T23:37:41.132072+00:00", "data": {"market": "0x1512828f4c735012fde09e2424f033bd2cd128a1a84e7aa7769440b66a1dd7c5", "price_changes": [{"asset_id": "59446984750383689166016671329084781990333496644061769271895177118630247823357", "price": "0.18", "size": "752.2", "side": "BUY", "hash": "fc01f3f0c812ddec0de5ea11ed0f1fe2c4338928", "best_bid": "0.2", "best_ask": "0.22"}, {"asset_id": "36050353753599194454464623080394572359037222441624334030228054568398520086707", "price": "0.82", "size": "752.2", "side": "SELL", "hash": "c42f39fc9c2e49397b38cd611b418f307e69a0a7", "best_bid": "0.78", "best_ask": "0.8"}], "timestamp": "1769384261042", "event_type": "price_change"}}
{"_local_timestamp": "2026-01-25T23:37:41.139231+00:00", "data": {"market": "0x1512828f4c735012fde09e2424f033bd2cd128a1a84e7aa7769440b66a1dd7c5", "price_changes": [{"asset_id": "59446984750383689166016671329084781990333496644061769271895177118630247823357", "price": "0.13", "size": "107.69", "side": "BUY", "hash": "d7334f4936515476d93222559ed2670a4877328a", "best_bid": "0.2", "best_ask": "0.22"}, {"asset_id": "36050353753599194454464623080394572359037222441624334030228054568398520086707", "price": "0.87", "size": "107.69", "side": "SELL", "hash": "79ebeffdec761d58abad9505a6515d852555e509", "best_bid": "0.78", "best_ask": "0.8"}], "timestamp": "1769384261043", "event_type": "price_change"}}
{"_local_timestamp": "2026-01-25T23:37:44.519971+00:00", "data": {"market": "0x1512828f4c735012fde09e2424f033bd2cd128a1a84e7aa7769440b66a1dd7c5", "price_changes": [{"asset_id": "59446984750383689166016671329084781990333496644061769271895177118630247823357", "price": "0.13", "size": "415.69", "side": "BUY", "hash": "a8185bf1f02102f2ac0b6cebdf34789feb6079cb", "best_bid": "0.2", "best_ask": "0.22"}, {"asset_id": "36050353753599194454464623080394572359037222441624334030228054568398520086707", "price": "0.87", "size": "415.69", "side": "SELL", "hash": "c79cd34663f2664f0c616e4562df2e5122243976", "best_bid": "0.78", "best_ask": "0.8"}], "timestamp": "1769384264445", "event_type": "price_change"}}
{"_local_timestamp": "2026-01-25T23:37:44.520712+00:00", "data": {"market": "0x1512828f4c735012fde09e2424f033bd2cd128a1a84e7aa7769440b66a1dd7c5", "price_changes": [{"asset_id": "59446984750383689166016671329084781990333496644061769271895177118630247823357", "price": "0.03", "size": "2667", "side": "BUY", "hash": "18b8abd45193a46d686a8d3c8c4730ab6f7600aa", "best_bid": "0.2", "best_ask": "0.22"}, {"asset_id": "36050353753599194454464623080394572359037222441624334030228054568398520086707", "price": "0.97", "size": "2667", "side": "SELL", "hash": "bb2081801f07df486ddcad2cb6c86fe4ad12920b", "best_bid": "0.78", "best_ask": "0.8"}], "timestamp": "1769384264446", "event_type": "price_change"}}
{"_local_timestamp": "2026-01-25T23:37:44.521125+00:00", "data": {"market": "0x1512828f4c735012fde09e2424f033bd2cd128a1a84e7aa7769440b66a1dd7c5", "price_changes": [{"asset_id": "59446984750383689166016671329084781990333496644061769271895177118630247823357", "price": "0.18", "size": "780.2", "side": "BUY", "hash": "7e233fb048286bfb41a32c843a5252517addfd44", "best_bid": "0.2", "best_ask": "0.22"}, {"asset_id": "36050353753599194454464623080394572359037222441624334030228054568398520086707", "price": "0.82", "size": "780.2", "side": "SELL", "hash": "dcbebd0a45d62ed86735313282ca8d569d84dc63", "best_bid": "0.78", "best_ask": "0.8"}], "timestamp": "1769384264447", "event_type": "price_change"}}
{"_local_timestamp": "2026-01-25T23:37:44.521527+00:00", "data": {"market": "0x1512828f4c735012fde09e2424f033bd2cd128a1a84e7aa7769440b66a1dd7c5", "price_changes": [{"asset_id": "59446984750383689166016671329084781990333496644061769271895177118630247823357", "price": "0.15", "size": "159", "side": "BUY", "hash": "74fecf4ace47cd164ebc25dd578c71060ea77401", "best_bid": "0.2", "best_ask": "0.22"}, {"asset_id": "36050353753599194454464623080394572359037222441624334030228054568398520086707", "price": "0.85", "size": "159", "side": "SELL", "hash": "caf462dd3c6ddfd91c63d631565a4aace4e7c2e2", "best_bid": "0.78", "best_ask": "0.8"}], "timestamp": "1769384264448", "event_type": "price_change"}}
{"_local_timestamp": "2026-01-25T23:38:02.154222+00:00", "data": {"market": "0x1512828f4c735012fde09e2424f033bd2cd128a1a84e7aa7769440b66a1dd7c5", "price_changes": [{"asset_id": "36050353753599194454464623080394572359037222441624334030228054568398520086707", "price": "0.21", "size": "1998", "side": "BUY", "hash": "1843486012f52facf7eb76141c23f7219907d10d", "best_bid": "0.78", "best_ask": "0.8"}, {"asset_id": "59446984750383689166016671329084781990333496644061769271895177118630247823357", "price": "0.79", "size": "1998", "side": "SELL", "hash": "7f1172818c2f2434da86bbfefd71930f863e5cb9", "best_bid": "0.2", "best_ask": "0.22"}], "timestamp": "1769384282080", "event_type": "price_change"}}
{"_local_timestamp": "2026-01-25T23:38:06.030480+00:00", "data": {"market": "0x1512828f4c735012fde09e2424f033bd2cd128a1a84e7aa7769440b66a1dd7c5", "price_changes": [{"asset_id": "59446984750383689166016671329084781990333496644061769271895177118630247823357", "price": "0.18", "size": "808.2", "side": "BUY", "hash": "14d579fc39fc062592b3a7417c1d236a8f50e9db", "best_bid": "0.2", "best_ask": "0.22"}, {"asset_id": "36050353753599194454464623080394572359037222441624334030228054568398520086707", "price": "0.82", "size": "808.2", "side": "SELL", "hash": "19d35d13fdc2a1fe5d43342d6bdc2536254103ab", "best_bid": "0.78", "best_ask": "0.8"}], "timestamp": "1769384285961", "event_type": "price_change"}}
{"_local_timestamp": "2026-01-25T23:38:39.735881+00:00", "data": {"market": "0x1512828f4c735012fde09e2424f033bd2cd128a1a84e7aa7769440b66a1dd7c5", "price_changes": [{"asset_id": "59446984750383689166016671329084781990333496644061769271895177118630247823357", "price": "0.08", "size": "0", "side": "BUY", "hash": "1f65d91a93164c8266688b3a7be7b279f7dec6c1", "best_bid": "0.2", "best_ask": "0.22"}, {"asset_id": "36050353753599194454464623080394572359037222441624334030228054568398520086707", "price": "0.92", "size": "0", "side": "SELL", "hash": "12965ff08aacdcef0c9b7ab6f703a2d68c8f0d77", "best_bid": "0.78", "best_ask": "0.8"}], "timestamp": "1769384319666", "event_type": "price_change"}}
{"_local_timestamp": "2026-01-25T23:38:40.065875+00:00", "data": {"market": "0x1512828f4c735012fde09e2424f033bd2cd128a1a84e7aa7769440b66a1dd7c5", "price_changes": [{"asset_id": "59446984750383689166016671329084781990333496644061769271895177118630247823357", "price": "0.08", "size": "7.03", "side": "BUY", "hash": "20329cf3dad562449ac4af693c1aa6ab502dd2e4", "best_bid": "0.2", "best_ask": "0.22"}, {"asset_id": "36050353753599194454464623080394572359037222441624334030228054568398520086707", "price": "0.92", "size": "7.03", "side": "SELL", "hash": "77d92086c9ec0941e98c39d9fa30a87428afd9a3", "best_bid": "0.78", "best_ask": "0.8"}], "timestamp": "1769384319992", "event_type": "price_change"}}
{"_local_timestamp": "2026-01-25T23:38:41.480134+00:00", "data": {"market": "0x1512828f4c735012fde09e2424f033bd2cd128a1a84e7aa7769440b66a1dd7c5", "price_changes": [{"asset_id": "36050353753599194454464623080394572359037222441624334030228054568398520086707", "price": "0.22", "size": "200", "side": "BUY", "hash": "6f9a10fa7d6db7f6af69822d161ca932e0cb4407", "best_bid": "0.78", "best_ask": "0.8"}, {"asset_id": "59446984750383689166016671329084781990333496644061769271895177118630247823357", "price": "0.78", "size": "200", "side": "SELL", "hash": "adf63222105fd5e6439f7e174e48cd0dc7ae06a2", "best_bid": "0.2", "best_ask": "0.22"}], "timestamp": "1769384321392", "event_type": "price_change"}}
{"_local_timestamp": "2026-01-25T23:38:41.848562+00:00", "data": {"market": "0x1512828f4c735012fde09e2424f033bd2cd128a1a84e7aa7769440b66a1dd7c5", "price_changes": [{"asset_id": "36050353753599194454464623080394572359037222441624334030228054568398520086707", "price": "0.21", "size": "2098", "side": "BUY", "hash": "22b3f20712880547835ce0d0fb0a8d9717adfe91", "best_bid": "0.78", "best_ask": "0.8"}, {"asset_id": "59446984750383689166016671329084781990333496644061769271895177118630247823357", "price": "0.79", "size": "2098", "side": "SELL", "hash": "d5722ba02367f76e9afa29160784acd6272d84cc", "best_bid": "0.2", "best_ask": "0.22"}], "timestamp": "1769384321677", "event_type": "price_change"}}
{"_local_timestamp": "2026-01-25T23:38:41.933060+00:00", "data": {"market": "0x1512828f4c735012fde09e2424f033bd2cd128a1a84e7aa7769440b66a1dd7c5", "price_changes": [{"asset_id": "59446984750383689166016671329084781990333496644061769271895177118630247823357", "price": "0.18", "size": "780.2", "side": "BUY", "hash": "84df9f077306f07b669d2148d9a069a5fe6d958f", "best_bid": "0.2", "best_ask": "0.22"}, {"asset_id": "36050353753599194454464623080394572359037222441624334030228054568398520086707", "price": "0.82", "size": "780.2", "side": "SELL", "hash": "f21429f8d248d97710fec6b897968270789b8034", "best_bid": "0.78", "best_ask": "0.8"}], "timestamp": "1769384321797", "event_type": "price_change"}}
{"_local_timestamp": "2026-01-25T23:38:46.072387+00:00", "data": {"market": "0x1512828f4c735012fde09e2424f033bd2cd128a1a84e7aa7769440b66a1dd7c5", "price_changes": [{"asset_id": "36050353753599194454464623080394572359037222441624334030228054568398520086707", "price": "0.75", "size": "0", "side": "BUY", "hash": "2de95773a08d72cbcf87e9ca43a66ff69718c64f", "best_bid": "0.78", "best_ask": "0.8"}, {"asset_id": "59446984750383689166016671329084781990333496644061769271895177118630247823357", "price": "0.25", "size": "0", "side": "SELL", "hash": "cb5e0607121a1ce5729ee627ddfd5edd9ea79141", "best_bid": "0.2", "best_ask": "0.22"}], "timestamp": "1769384325993", "event_type": "price_change"}}
{"_local_timestamp": "2026-01-25T23:38:46.700957+00:00", "data": {"market": "0x1512828f4c735012fde09e2424f033bd2cd128a1a84e7aa7769440b66a1dd7c5", "price_changes": [{"asset_id": "36050353753599194454464623080394572359037222441624334030228054568398520086707", "price": "0.77", "size": "30", "side": "BUY", "hash": "87ac9205df5b96cb05b8a585736d005a10640b3f", "best_bid": "0.78", "best_ask": "0.8"}, {"asset_id": "59446984750383689166016671329084781990333496644061769271895177118630247823357", "price": "0.23", "size": "30", "side": "SELL", "hash": "df875de1d0fefab969e5f067478d9017e6bb36f6", "best_bid": "0.2", "best_ask": "0.22"}], "timestamp": "1769384326625", "event_type": "price_change"}}
{"_local_timestamp": "2026-01-25T23:38:47.237952+00:00", "data": {"market": "0x1512828f4c735012fde09e2424f033bd2cd128a1a84e7aa7769440b66a1dd7c5", "price_changes": [{"asset_id": "36050353753599194454464623080394572359037222441624334030228054568398520086707", "price": "0.68", "size": "119.11", "side": "BUY", "hash": "3886b0ccefc44fbd72c2193f3096f41bbbe21f52", "best_bid": "0.78", "best_ask": "0.8"}, {"asset_id": "59446984750383689166016671329084781990333496644061769271895177118630247823357", "price": "0.32", "size": "119.11", "side": "SELL", "hash": "7884f61525d743fde1177c6c06e0373bbaebbddd", "best_bid": "0.2", "best_ask": "0.22"}], "timestamp": "1769384327161", "event_type": "price_change"}}
{"_local_timestamp": "2026-01-25T23:38:47.745692+00:00", "data": {"market": "0x1512828f4c735012fde09e2424f033bd2cd128a1a84e7aa7769440b66a1dd7c5", "price_changes": [{"asset_id": "36050353753599194454464623080394572359037222441624334030228054568398520086707", "price": "0.76", "size": "481.99", "side": "BUY", "hash": "17c3d9076bc2ac7e6a4c9c11f7741e0c30fca59a", "best_bid": "0.78", "best_ask": "0.8"}, {"asset_id": "59446984750383689166016671329084781990333496644061769271895177118630247823357", "price": "0.24", "size": "481.99", "side": "SELL", "hash": "8bcb525c2a6806f5041e1f80e755dae3b3c5eba4", "best_bid": "0.2", "best_ask": "0.22"}], "timestamp": "1769384327673", "event_type": "price_change"}}
{"_local_timestamp": "2026-01-25T23:39:05.392508+00:00", "data": {"market": "0x1512828f4c735012fde09e2424f033bd2cd128a1a84e7aa7769440b66a1dd7c5", "price_changes": [{"asset_id": "59446984750383689166016671329084781990333496644061769271895177118630247823357", "price": "0.07", "size": "0", "side": "BUY", "hash": "4a49be74382d58710216e3ccfb0ebf2c37d26bb9", "best_bid": "0.2", "best_ask": "0.22"}, {"asset_id": "36050353753599194454464623080394572359037222441624334030228054568398520086707", "price": "0.93", "size": "0", "side": "SELL", "hash": "0420a8bad646ff49a8dd040ab07d818f3910898c", "best_bid": "0.78", "best_ask": "0.8"}], "timestamp": "1769384345320", "event_type": "price_change"}}
{"_local_timestamp": "2026-01-25T23:39:05.626251+00:00", "data": {"market": "0x1512828f4c735012fde09e2424f033bd2cd128a1a84e7aa7769440b66a1dd7c5", "price_changes": [{"asset_id": "59446984750383689166016671329084781990333496644061769271895177118630247823357", "price": "0.12", "size": "0", "side": "BUY", "hash": "274b528c7a852150a1db9dd1b958ded611d3ba33", "best_bid": "0.2", "best_ask": "0.22"}, {"asset_id": "36050353753599194454464623080394572359037222441624334030228054568398520086707", "price": "0.88", "size": "0", "side": "SELL", "hash": "1876db8e0d6b64fb1df1fe0f68367b62bba77463", "best_bid": "0.78", "best_ask": "0.8"}], "timestamp": "1769384345556", "event_type": "price_change"}}
{"_local_timestamp": "2026-01-25T23:39:05.872743+00:00", "data": {"market": "0x1512828f4c735012fde09e2424f033bd2cd128a1a84e7aa7769440b66a1dd7c5", "price_changes": [{"asset_id": "36050353753599194454464623080394572359037222441624334030228054568398520086707", "price": "0.69", "size": "15.94", "side": "BUY", "hash": "b5ba024057dff6d77400162513a1d6d80e2073f3", "best_bid": "0.78", "best_ask": "0.8"}, {"asset_id": "59446984750383689166016671329084781990333496644061769271895177118630247823357", "price": "0.31", "size": "15.94", "side": "SELL", "hash": "05e06873c5da73ffd4f1e3bee563a7741f6686ee", "best_bid": "0.2", "best_ask": "0.22"}], "timestamp": "1769384345799", "event_type": "price_change"}}
{"_local_timestamp": "2026-01-25T23:39:06.357412+00:00", "data": {"market": "0x1512828f4c735012fde09e2424f033bd2cd128a1a84e7aa7769440b66a1dd7c5", "price_changes": [{"asset_id": "59446984750383689166016671329084781990333496644061769271895177118630247823357", "price": "0.19", "size": "233", "side": "BUY", "hash": "e68ae0da07ce10ae24243e70367472949d3f0a1e", "best_bid": "0.2", "best_ask": "0.22"}, {"asset_id": "36050353753599194454464623080394572359037222441624334030228054568398520086707", "price": "0.81", "size": "233", "side": "SELL", "hash": "82dcab6bbe317535e883c114b0f7fbd9679d8e1d", "best_bid": "0.78", "best_ask": "0.8"}], "timestamp": "1769384346285", "event_type": "price_change"}}
{"_local_timestamp": "2026-01-25T23:39:06.622307+00:00", "data": {"market": "0x1512828f4c735012fde09e2424f033bd2cd128a1a84e7aa7769440b66a1dd7c5", "price_changes": [{"asset_id": "59446984750383689166016671329084781990333496644061769271895177118630247823357", "price": "0.15", "size": "165", "side": "BUY", "hash": "7bc171fedd8ce661acf3b17f4beabf6fc6e39bb9", "best_bid": "0.2", "best_ask": "0.22"}, {"asset_id": "36050353753599194454464623080394572359037222441624334030228054568398520086707", "price": "0.85", "size": "165", "side": "SELL", "hash": "0b82c101d7ed6e946063c7b5e047e31bbffa0f16", "best_bid": "0.78", "best_ask": "0.8"}], "timestamp": "1769384346550", "event_type": "price_change"}}
{"_local_timestamp": "2026-01-25T23:39:06.865312+00:00", "data": {"market": "0x1512828f4c735012fde09e2424f033bd2cd128a1a84e7aa7769440b66a1dd7c5", "price_changes": [{"asset_id": "59446984750383689166016671329084781990333496644061769271895177118630247823357", "price": "0.13", "size": "421.69", "side": "BUY", "hash": "516702a46e015e60e73412a808f1956b111eb615", "best_bid": "0.2", "best_ask": "0.22"}, {"asset_id": "36050353753599194454464623080394572359037222441624334030228054568398520086707", "price": "0.87", "size": "421.69", "side": "SELL", "hash": "40d637290e2d3b67742bb449f78bdcece398f105", "best_bid": "0.78", "best_ask": "0.8"}], "timestamp": "1769384346793", "event_type": "price_change"}}
{"_local_timestamp": "2026-01-25T23:39:07.126438+00:00", "data": {"market": "0x1512828f4c735012fde09e2424f033bd2cd128a1a84e7aa7769440b66a1dd7c5", "price_changes": [{"asset_id": "59446984750383689166016671329084781990333496644061769271895177118630247823357", "price": "0.08", "size": "13.03", "side": "BUY", "hash": "bdf5af82a3f2925dafc20b4814ca1cc0f71a672a", "best_bid": "0.2", "best_ask": "0.22"}, {"asset_id": "36050353753599194454464623080394572359037222441624334030228054568398520086707", "price": "0.92", "size": "13.03", "side": "SELL", "hash": "ca55e3fb96323c3aa413532eba587828ed2c9ba3", "best_bid": "0.78", "best_ask": "0.8"}], "timestamp": "1769384347046", "event_type": "price_change"}}
{"_local_timestamp": "2026-01-25T23:39:07.365667+00:00", "data": {"market": "0x1512828f4c735012fde09e2424f033bd2cd128a1a84e7aa7769440b66a1dd7c5", "price_changes": [{"asset_id": "36050353753599194454464623080394572359037222441624334030228054568398520086707", "price": "0.77", "size": "36", "side": "BUY", "hash": "32cd26ea9a124aa902e84d46f6c8ee748546ab50", "best_bid": "0.78", "best_ask": "0.8"}, {"asset_id": "59446984750383689166016671329084781990333496644061769271895177118630247823357", "price": "0.23", "size": "36", "side": "SELL", "hash": "68859a648b7cab2048c30a1d1632a6e66e4be0f4", "best_bid": "0.2", "best_ask": "0.22"}], "timestamp": "1769384347292", "event_type": "price_change"}}
{"_local_timestamp": "2026-01-25T23:39:07.614654+00:00", "data": {"market": "0x1512828f4c735012fde09e2424f033bd2cd128a1a84e7aa7769440b66a1dd7c5", "price_changes": [{"asset_id": "36050353753599194454464623080394572359037222441624334030228054568398520086707", "price": "0.7", "size": "6", "side": "BUY", "hash": "65a225a0ebb8679e8c2e2d71e037d198de6c0515", "best_bid": "0.78", "best_ask": "0.8"}, {"asset_id": "59446984750383689166016671329084781990333496644061769271895177118630247823357", "price": "0.3", "size": "6", "side": "SELL", "hash": "273996c3a52e88e55709bf5e0019b7ee0d8a9ac6", "best_bid": "0.2", "best_ask": "0.22"}], "timestamp": "1769384347534", "event_type": "price_change"}}
{"_local_timestamp": "2026-01-25T23:39:07.860893+00:00", "data": {"market": "0x1512828f4c735012fde09e2424f033bd2cd128a1a84e7aa7769440b66a1dd7c5", "price_changes": [{"asset_id": "36050353753599194454464623080394572359037222441624334030228054568398520086707", "price": "0.68", "size": "125.11", "side": "BUY", "hash": "0341dee4494126363581fb286670e550342d1f5a", "best_bid": "0.78", "best_ask": "0.8"}, {"asset_id": "59446984750383689166016671329084781990333496644061769271895177118630247823357", "price": "0.32", "size": "125.11", "side": "SELL", "hash": "9380761d2c3d0f2d4ed11885c93a9dd845b340b0", "best_bid": "0.2", "best_ask": "0.22"}], "timestamp": "1769384347779", "event_type": "price_change"}}
{"_local_timestamp": "2026-01-25T23:39:20.581209+00:00", "data": {"market": "0x1512828f4c735012fde09e2424f033bd2cd128a1a84e7aa7769440b66a1dd7c5", "price_changes": [{"asset_id": "36050353753599194454464623080394572359037222441624334030228054568398520086707", "price": "0.21", "size": "100", "side": "BUY", "hash": "fff5fb1574cd225a129321c2b7e8e185c93868e3", "best_bid": "0.78", "best_ask": "0.8"}, {"asset_id": "59446984750383689166016671329084781990333496644061769271895177118630247823357", "price": "0.79", "size": "100", "side": "SELL", "hash": "c94a54344232ef8dda1ab78c8f91c953027f0bb6", "best_bid": "0.2", "best_ask": "0.22"}], "timestamp": "1769384360333", "event_type": "price_change"}}
{"_local_timestamp": "2026-01-25T23:39:22.548156+00:00", "data": {"market": "0x1512828f4c735012fde09e2424f033bd2cd128a1a84e7aa7769440b66a1dd7c5", "price_changes": [{"asset_id": "36050353753599194454464623080394572359037222441624334030228054568398520086707", "price": "0.5", "size": "500", "side": "BUY", "hash": "33894eaa1e0f4d260249b58ce9c0225f70bc9db5", "best_bid": "0.78", "best_ask": "0.8"}, {"asset_id": "59446984750383689166016671329084781990333496644061769271895177118630247823357", "price": "0.5", "size": "500", "side": "SELL", "hash": "602de1329a3b2ef9e6e952b5d73adf366972e8ff", "best_bid": "0.2", "best_ask": "0.22"}], "timestamp": "1769384362228", "event_type": "price_change"}}
{"_local_timestamp": "2026-01-25T23:39:56.461582+00:00", "data": {"market": "0x1512828f4c735012fde09e2424f033bd2cd128a1a84e7aa7769440b66a1dd7c5", "price_changes": [{"asset_id": "36050353753599194454464623080394572359037222441624334030228054568398520086707", "price": "0.21", "size": "0", "side": "BUY", "hash": "90281168b8e56519583f6fd831e1bf7f471f8667", "best_bid": "0.78", "best_ask": "0.8"}, {"asset_id": "59446984750383689166016671329084781990333496644061769271895177118630247823357", "price": "0.79", "size": "0", "side": "SELL", "hash": "fa5f859a8b200ae9d5dd15319bf07acfacb61680", "best_bid": "0.2", "best_ask": "0.22"}], "timestamp": "1769384396339", "event_type": "price_change"}}
{"_local_timestamp": "2026-01-25T23:39:56.769745+00:00", "data": {"market": "0x1512828f4c735012fde09e2424f033bd2cd128a1a84e7aa7769440b66a1dd7c5", "price_changes": [{"asset_id": "36050353753599194454464623080394572359037222441624334030228054568398520086707", "price": "0.22", "size": "300", "side": "BUY", "hash": "3c628dbc7d48d7e5c5226201b356bb2688524b64", "best_bid": "0.78", "best_ask": "0.8"}, {"asset_id": "59446984750383689166016671329084781990333496644061769271895177118630247823357", "price": "0.78", "size": "300", "side": "SELL", "hash": "5d0a9682fa3abbbb4ccc497535a1243fe40e9b2b", "best_bid": "0.2", "best_ask": "0.22"}], "timestamp": "1769384396617", "event_type": "price_change"}}
{"_local_timestamp": "2026-01-25T23:39:57.111901+00:00", "data": {"market": "0x1512828f4c735012fde09e2424f033bd2cd128a1a84e7aa7769440b66a1dd7c5", "price_changes": [{"asset_id": "59446984750383689166016671329084781990333496644061769271895177118630247823357", "price": "0.15", "size": "132", "side": "BUY", "hash": "198a236c7fcfb96494e58cdb93695bc735e16614", "best_bid": "0.2", "best_ask": "0.22"}, {"asset_id": "36050353753599194454464623080394572359037222441624334030228054568398520086707", "price": "0.85", "size": "132", "side": "SELL", "hash": "653f1d9d68d52ca4cfee94fa42279341d4386be2", "best_bid": "0.78", "best_ask": "0.8"}], "timestamp": "1769384397001", "event_type": "price_change"}}
{"_local_timestamp": "2026-01-25T23:39:59.992656+00:00", "data": {"market": "0x1512828f4c735012fde09e2424f033bd2cd128a1a84e7aa7769440b66a1dd7c5", "price_changes": [{"asset_id": "36050353753599194454464623080394572359037222441624334030228054568398520086707", "price": "0.76", "size": "332", "side": "BUY", "hash": "570980f16af059c83280146e40752b03bb3836d3", "best_bid": "0.78", "best_ask": "0.8"}, {"asset_id": "59446984750383689166016671329084781990333496644061769271895177118630247823357", "price": "0.24", "size": "332", "side": "SELL", "hash": "2c725e3443e17044c7a22ac37a2be435d260d50f", "best_bid": "0.2", "best_ask": "0.22"}], "timestamp": "1769384399902", "event_type": "price_change"}}
{"_local_timestamp": "2026-01-25T23:40:00.683589+00:00", "data": {"market": "0x1512828f4c735012fde09e2424f033bd2cd128a1a84e7aa7769440b66a1dd7c5", "price_changes": [{"asset_id": "36050353753599194454464623080394572359037222441624334030228054568398520086707", "price": "0.75", "size": "150", "side": "BUY", "hash": "72c36ba2e85341255fdcd4dc9f04896345e468e3", "best_bid": "0.78", "best_ask": "0.8"}, {"asset_id": "59446984750383689166016671329084781990333496644061769271895177118630247823357", "price": "0.25", "size": "150", "side": "SELL", "hash": "0f347919748c7bce25369b202c2d6a51e73e4d33", "best_bid": "0.2", "best_ask": "0.22"}], "timestamp": "1769384400615", "event_type": "price_change"}}
{"_local_timestamp": "2026-01-25T23:40:00.947499+00:00", "data": {"market": "0x1512828f4c735012fde09e2424f033bd2cd128a1a84e7aa7769440b66a1dd7c5", "price_changes": [{"asset_id": "36050353753599194454464623080394572359037222441624334030228054568398520086707", "price": "0.76", "size": "282", "side": "BUY", "hash": "65c01b8c1ef13b0c34182cc6bb97d943968cc79d", "best_bid": "0.78", "best_ask": "0.8"}, {"asset_id": "59446984750383689166016671329084781990333496644061769271895177118630247823357", "price": "0.24", "size": "282", "side": "SELL", "hash": "0e73aee1397e8b727042336a30b866feb9466167", "best_bid": "0.2", "best_ask": "0.22"}], "timestamp": "1769384400872", "event_type": "price_change"}}
{"_local_timestamp": "2026-01-25T23:40:00.948044+00:00", "data": {"market": "0x1512828f4c735012fde09e2424f033bd2cd128a1a84e7aa7769440b66a1dd7c5", "price_changes": [{"asset_id": "59446984750383689166016671329084781990333496644061769271895177118630247823357", "price": "0.19", "size": "183", "side": "BUY", "hash": "f2e7bb75098bba15946fb38aa4001853e3c08049", "best_bid": "0.2", "best_ask": "0.22"}, {"asset_id": "36050353753599194454464623080394572359037222441624334030228054568398520086707", "price": "0.81", "size": "183", "side": "SELL", "hash": "5e803f64e4c14328cf4a132e47f21f4d6fefac62", "best_bid": "0.78", "best_ask": "0.8"}], "timestamp": "1769384400872", "event_type": "price_change"}}
{"_local_timestamp": "2026-01-25T23:40:01.115658+00:00", "data": {"market": "0x1512828f4c735012fde09e2424f033bd2cd128a1a84e7aa7769440b66a1dd7c5", "price_changes": [{"asset_id": "36050353753599194454464623080394572359037222441624334030228054568398520086707", "price": "0.75", "size": "200", "side": "BUY", "hash": "598f67b40b62426725f266d56535c1b865fdcc37", "best_bid": "0.78", "best_ask": "0.8"}, {"asset_id": "59446984750383689166016671329084781990333496644061769271895177118630247823357", "price": "0.25", "size": "200", "side": "SELL", "hash": "7736941cdc1978b21392b937f11d0e93e9bdb52d", "best_bid": "0.2", "best_ask": "0.22"}], "timestamp": "1769384401037", "event_type": "price_change"}}
{"_local_timestamp": "2026-01-25T23:40:01.116311+00:00", "data": {"market": "0x1512828f4c735012fde09e2424f033bd2cd128a1a84e7aa7769440b66a1dd7c5", "price_changes": [{"asset_id": "59446984750383689166016671329084781990333496644061769271895177118630247823357", "price": "0.19", "size": "233", "side": "BUY", "hash": "5d24e12ef99058cf27cfa15636eb652169a9c98c", "best_bid": "0.2", "best_ask": "0.22"}, {"asset_id": "36050353753599194454464623080394572359037222441624334030228054568398520086707", "price": "0.81", "size": "233", "side": "SELL", "hash": "00c7d6541ecae2310ab74793ee7cd458192d4d2d", "best_bid": "0.78", "best_ask": "0.8"}], "timestamp": "1769384401038", "event_type": "price_change"}}
{"_local_timestamp": "2026-01-25T23:40:04.653732+00:00", "data": {"market": "0x1512828f4c735012fde09e2424f033bd2cd128a1a84e7aa7769440b66a1dd7c5", "price_changes": [{"asset_id": "36050353753599194454464623080394572359037222441624334030228054568398520086707", "price": "0.68", "size": "25.11", "side": "BUY", "hash": "116bfb091de47080923a5cd7b3a37640e565a1ec", "best_bid": "0.78", "best_ask": "0.8"}, {"asset_id": "59446984750383689166016671329084781990333496644061769271895177118630247823357", "price": "0.32", "size": "25.11", "side": "SELL", "hash": "cd3d3351ed0504e6bad7d83b5cd3597944194b95", "best_bid": "0.2", "best_ask": "0.22"}], "timestamp": "1769384404550", "event_type": "price_change"}}
{"_local_timestamp": "2026-01-25T23:40:05.228583+00:00", "data": {"market": "0x1512828f4c735012fde09e2424f033bd2cd128a1a84e7aa7769440b66a1dd7c5", "price_changes": [{"asset_id": "36050353753599194454464623080394572359037222441624334030228054568398520086707", "price": "0.77", "size": "136", "side": "BUY", "hash": "38712a78e6d5b7a1420d6c3eaa8b64c9beac2a03", "best_bid": "0.78", "best_ask": "0.8"}, {"asset_id": "59446984750383689166016671329084781990333496644061769271895177118630247823357", "price": "0.23", "size": "136", "side": "SELL", "hash": "afdb1a078cf236c86893ab133e1905fa97d4c6f7", "best_bid": "0.2", "best_ask": "0.22"}], "timestamp": "1769384405156", "event_type": "price_change"}}
{"_local_timestamp": "2026-01-25T23:40:05.548546+00:00", "data": {"market": "0x1512828f4c735012fde09e2424f033bd2cd128a1a84e7aa7769440b66a1dd7c5", "price_changes": [{"asset_id": "36050353753599194454464623080394572359037222441624334030228054568398520086707", "price": "0.75", "size": "150", "side": "BUY", "hash": "f34cf79fde0a17850d22e2456bcea154ce32c8bf", "best_bid": "0.78", "best_ask": "0.8"}, {"asset_id": "59446984750383689166016671329084781990333496644061769271895177118630247823357", "price": "0.25", "size": "150", "side": "SELL", "hash": "5778e104e63917b388388fb7fdce6c7c6fe447b1", "best_bid": "0.2", "best_ask": "0.22"}], "timestamp": "1769384405480", "event_type": "price_change"}}
{"_local_timestamp": "2026-01-25T23:40:05.549132+00:00", "data": {"market": "0x1512828f4c735012fde09e2424f033bd2cd128a1a84e7aa7769440b66a1dd7c5", "price_changes": [{"asset_id": "59446984750383689166016671329084781990333496644061769271895177118630247823357", "price": "0.19", "size": "183", "side": "BUY", "hash": "61a3959c941de8e07779be8cc6e8dffff80b25ae", "best_bid": "0.2", "best_ask": "0.22"}, {"asset_id": "36050353753599194454464623080394572359037222441624334030228054568398520086707", "price": "0.81", "size": "183", "side": "SELL", "hash": "ea5d5c2f9c665d792d33052e949e63022d186666", "best_bid": "0.78", "best_ask": "0.8"}], "timestamp": "1769384405480", "event_type": "price_change"}}
{"_local_timestamp": "2026-01-25T23:40:05.707621+00:00", "data": {"market": "0x1512828f4c735012fde09e2424f033bd2cd128a1a84e7aa7769440b66a1dd7c5", "price_changes": [{"asset_id": "36050353753599194454464623080394572359037222441624334030228054568398520086707", "price": "0.76", "size": "332", "side": "BUY", "hash": "3dbd5388c0672e200629f57e66b4793c72261c0c", "best_bid": "0.78", "best_ask": "0.8"}, {"asset_id": "59446984750383689166016671329084781990333496644061769271895177118630247823357", "price": "0.24", "size": "332", "side": "SELL", "hash": "f730d51e590344f2a3a21553e831ed8f2169866c", "best_bid": "0.2", "best_ask": "0.22"}], "timestamp": "1769384405634", "event_type": "price_change"}}
{"_local_timestamp": "2026-01-25T23:40:05.708209+00:00", "data": {"market": "0x1512828f4c735012fde09e2424f033bd2cd128a1a84e7aa7769440b66a1dd7c5", "price_changes": [{"asset_id": "59446984750383689166016671329084781990333496644061769271895177118630247823357", "price": "0.19", "size": "233", "side": "BUY", "hash": "e86c92bee790377bf69698a63e9d8497af18755a", "best_bid": "0.2", "best_ask": "0.22"}, {"asset_id": "36050353753599194454464623080394572359037222441624334030228054568398520086707", "price": "0.81", "size": "233", "side": "SELL", "hash": "443efba65fa4417f0ae4029c9a1a6b898a12acdd", "best_bid": "0.78", "best_ask": "0.8"}], "timestamp": "1769384405635", "event_type": "price_change"}}
{"_local_timestamp": "2026-01-25T23:40:06.947401+00:00", "data": {"market": "0x1512828f4c735012fde09e2424f033bd2cd128a1a84e7aa7769440b66a1dd7c5", "price_changes": [{"asset_id": "59446984750383689166016671329084781990333496644061769271895177118630247823357", "price": "0.15", "size": "165", "side": "BUY", "hash": "52929d2cbcb95006fe84481532e33d70c1fe2ad9", "best_bid": "0.2", "best_ask": "0.22"}, {"asset_id": "36050353753599194454464623080394572359037222441624334030228054568398520086707", "price": "0.85", "size": "165", "side": "SELL", "hash": "6fcaa6bfc7055745d077bf8cd3b5d8d7274e2b84", "best_bid": "0.78", "best_ask": "0.8"}], "timestamp": "1769384406802", "event_type": "price_change"}}
