{"_local_timestamp": "2026-01-25T23:41:23.818475+00:00", "data": [{"market": "0xf4f48f5b93ad07125c1487eca5c05632aa299a9ce8d547b3181906455b6ffc30", "asset_id": "45351011268357454489754819517897238839825192588635910066796851405573865769474", "timestamp": "1769384262790", "hash": "9d3b6923bdfaec51a2a8183b8880487ed2122a77", "bids": [{"price": "0.01", "size": "201.38"}, {"price": "0.02", "size": "100.17"}, {"price": "0.03", "size": "52.57"}], "asks": [{"price": "0.99", "size": "195.47"}, {"price": "0.98", "size": "95.18"}, {"price": "0.97", "size": "24.72"}, {"price": "0.96", "size": "5.47"}], "event_type": "book", "last_trade_price": ""}, {"market": "0x27ca72003935168fa5145df02d60bf388556aae40004bf8878ca07908679c90a", "asset_id": "63076381782914098979289416106534140467979969107420034465007654424987247815951", "timestamp": "1769384437999", "hash": "3a1f60427575d367c09bfe434ce6fae24c7e80b0", "bids": [{"price": "0.01", "size": "202.04"}, {"price": "0.02", "size": "38.98"}, {"price": "0.04", "size": "29.99"}], "asks": [{"price": "0.99", "size": "210.72"}, {"price": "0.98", "size": "24.38"}, {"price": "0.97", "size": "5.47"}], "event_type": "book", "last_trade_price": ""}, {"market": "0x75f85ab4766e55b79b02c01d71585e35ad6ff20b548cab627068d4ea3da80485", "asset_id": "104504205045662795329945488148492743675810133796968616764429718268976392822157", "timestamp": "1769379487650", "hash": "b31a3777326b909f374b2a09c55f3f0a85405296", "bids": [{"price": "0.01", "size": "241.91"}, {"price": "0.02", "size": "65"}, {"price": "0.03", "size": "29.86"}, {"price": "0.48", "size": "100"}], "asks": [{"price": "0.99", "size": "242.27"}, {"price": "0.98", "size": "65"}, {"price": "0.97", "size": "29.74"}, {"price": "0.58", "size": "100"}], "event_type": "book", "last_trade_price": ""}, {"market": "0xf4f48f5b93ad07125c1487eca5c05632aa299a9ce8d547b3181906455b6ffc30", "asset_id": "52037538169528564564638458855755309591097235785433599464625697767410175594920", "timestamp": "1769384262790", "hash": "f4c153ef09431941e8cb3a843ddb536abe789917", "bids": [{"price": "0.01", "size": "195.47"}, {"price": "0.02", "size": "95.18"}, {"price": "0.03", "size": "24.72"}, {"price": "0.04", "size": "5.47"}], "asks": [{"price": "0.99", "size": "201.38"}, {"price": "0.98", "size": "100.17"}, {"price": "0.97", "size": "52.57"}], "event_type": "book", "last_trade_price": ""}, {"market": "0x1bdd565e28318829d29533292ab34a7d1e5cfaa1d97b7665b7f328f171f873b6", "asset_id": "85840758564805505176869795845167015003228304095996904373607844076140180838264", "timestamp": "1769379660866", "hash": "7f81ef64674ecbaa247f3627b861a437a3d46def", "bids": [{"price": "0.01", "size": "152.04"}, {"price": "0.02", "size": "92.48"}, {"price": "0.03", "size": "18.99"}, {"price": "0.04", "size": "29.99"}], "asks": [{"price": "0.99", "size": "151.38"}, {"price": "0.98", "size": "82.17"}, {"price": "0.97", "size": "58.04"}], "event_type": "book", "last_trade_price": ""}, {"market": "0x230607f610338c5d3a16bd50be25aa7ab60de534e39e8d5d699c5001c1e595b6", "asset_id": "54704412367939001823042963194576165230971916634123177373358746651929926233731", "timestamp": "1769384369562", "hash": "cfd9808743c7a466feeabbbcf673163e082397bd", "bids": [{"price": "0.01", "size": "201.38"}, {"price": "0.02", "size": "29.05"}, {"price": "0.03", "size": "39.99"}], "asks": [{"price": "0.99", "size": "208.36"}, {"price": "0.98", "size": "25.56"}, {"price": "0.97", "size": "5.47"}], "event_type": "book", "last_trade_price": ""}, {"market": "0x9f0edfabe936932ce4acaf03211ae9e01606ef130b9617437f5784b8bd1f5d88", "asset_id": "57085542488554071660683610906572351111789487514540898136105126107823308874102", "timestamp": "1769380506183", "hash": "25b39b3affe86e8c7df102312cfc7d1b42245cab", "bids": [{"price": "0.01", "size": "185.22"}, {"price": "0.02", "size": "95"}, {"price": "0.03", "size": "31.59"}, {"price": "0.53", "size": "100"}], "asks": [{"price": "0.99", "size": "190.58"}, {"price": "0.98", "size": "90"}, {"price": "0.97", "size": "29.8"}, {"price": "0.63", "size": "100"}], "event_type": "book", "last_trade_price": ""}, {"market": "0x13d3b44b12294fc57ae0bd7eaa03ce913c557cfd86a75bf9d2f824081be0af06", "asset_id": "61753867760589263716170746998286765860517841601052294758213209498622686532394", "timestamp": "1769384262886", "hash": "dc9986e8d894c0de3114eb7eebd280ae471cafcd", "bids": [{"price": "0.01", "size": "180"}, {"price": "0.02", "size": "49.99"}, {"price": "0.12", "size": "300"}, {"price": "0.13", "size": "200"}, {"price": "0.14", "size": "125"}, {"price": "0.15", "size": "137"}, {"price": "0.3", "size": "50"}, {"price": "0.34", "size": "78.31"}], "asks": [{"price": "0.99", "size": "194.58"}, {"price": "0.97", "size": "600"}, {"price": "0.96", "size": "5.84"}, {"price": "0.91", "size": "550"}, {"price": "0.9", "size": "6.2"}, {"price": "0.86", "size": "200"}, {"price": "0.69", "size": "300"}, {"price": "0.65", "size": "200"}, {"price": "0.62", "size": "125"}, {"price": "0.59", "size": "75"}, {"price": "0.5", "size": "20"}, {"price": "0.46", "size": "50"}, {"price": "0.44", "size": "100"}, {"price": "0.39", "size": "1013.49"}], "event_type": "book", "last_trade_price": "0.610"}, {"market": "0x9f0edfabe936932ce4acaf03211ae9e01606ef130b9617437f5784b8bd1f5d88", "asset_id": "57471138523385998132008949658093357640901088614468756096607699684059051953514", "timestamp": "1769380506183", "hash": "6dbf995f429fcf91299c10f16fee62ef0e3484ba", "bids": [{"price": "0.01", "size": "190.58"}, {"price": "0.02", "size": "90"}, {"price": "0.03", "size": "29.8"}, {"price": "0.37", "size": "100"}], "asks": [{"price": "0.99", "size": "185.22"}, {"price": "0.98", "size": "95"}, {"price": "0.97", "size": "31.59"}, {"price": "0.47", "size": "100"}], "event_type": "book", "last_trade_price": ""}, {"market": "0x27ca72003935168fa5145df02d60bf388556aae40004bf8878ca07908679c90a", "asset_id": "39988103022538972074566738669948101601617351308210751441166542218243560439585", "timestamp": "1769384437999", "hash": "325345b223803e5c1031d674aef4ae5519aa734b", "bids": [{"price": "0.01", "size": "210.72"}, {"price": "0.02", "size": "24.38"}, {"price": "0.03", "size": "5.47"}], "asks": [{"price": "0.99", "size": "202.04"}, {"price": "0.98", "size": "38.98"}, {"price": "0.96", "size": "29.99"}], "event_type": "book", "last_trade_price": ""}, {"market": "0x1bdd565e28318829d29533292ab34a7d1e5cfaa1d97b7665b7f328f171f873b6", "asset_id": "97642619114940658254269942296991909819649349898970948363534450154519749526259", "timestamp": "1769379660866", "hash": "4e029dc6db71b8996bbb37f6dd7c139449e3b2db", "bids": [{"price": "0.01", "size": "151.38"}, {"price": "0.02", "size": "82.17"}, {"price": "0.03", "size": "58.04"}], "asks": [{"price": "0.99", "size": "152.04"}, {"price": "0.98", "size": "92.48"}, {"price": "0.97", "size": "18.99"}, {"price": "0.96", "size": "29.99"}], "event_type": "book", "last_trade_price": ""}, {"market": "0xea99692e10dc5d0482fc6caa7e69f4e6a59c2ea6c3263633a55803dac12f8853", "asset_id": "38823163295698136758635047917084453491563154949905934699872945477550628055004", "timestamp": "1769381471593", "hash": "4ba2667f00c6bd29ea671dfde951d68e4bff0b07", "bids": [{"price": "0.01", "size": "201.38"}, {"price": "0.02", "size": "29.05"}, {"price": "0.03", "size": "39.99"}], "asks": [{"price": "0.99", "size": "201.38"}, {"price": "0.98", "size": "29.05"}, {"price": "0.97", "size": "45.46"}], "event_type": "book", "last_trade_price": ""}, {"market": "0x13d3b44b12294fc57ae0bd7eaa03ce913c557cfd86a75bf9d2f824081be0af06", "asset_id": "27534087816472888388482777492068482333587764608177303542485554201592863278418", "timestamp": "1769384262886", "hash": "3ec1a005989926952e76357aff7416e028f5213a", "bids": [{"price": "0.01", "size": "194.58"}, {"price": "0.03", "size": "600"}, {"price": "0.04", "size": "5.84"}, {"price": "0.09", "size": "550"}, {"price": "0.1", "size": "6.2"}, {"price": "0.14", "size": "200"}, {"price": "0.31", "size": "300"}, {"price": "0.35", "size": "200"}, {"price": "0.38", "size": "125"}, {"price": "0.41", "size": "75"}, {"price": "0.5", "size": "20"}, {"price": "0.54", "size": "50"}, {"price": "0.56", "size": "100"}, {"price": "0.61", "size": "1013.49"}], "asks": [{"price": "0.99", "size": "180"}, {"price": "0.98", "size": "49.99"}, {"price": "0.88", "size": "300"}, {"price": "0.87", "size": "200"}, {"price": "0.86", "size": "125"}, {"price": "0.85", "size": "137"}, {"price": "0.7", "size": "50"}, {"price": "0.66", "size": "78.31"}], "event_type": "book", "last_trade_price": "0.610"}, {"market": "0x6368d8b032107a3d98d5d48bbf11f645884650afb1cc44f7c4f42802c0ec50e9", "asset_id": "88936879235639575889922650331264430559946655028214095693959269405772447138257", "timestamp": "1769379492245", "hash": "1663ec80e5c5771d501c231e8d73f0fae4dc0633", "bids": [{"price": "0.01", "size": "190.58"}, {"price": "0.02", "size": "90"}, {"price": "0.03", "size": "29.8"}, {"price": "0.37", "size": "100"}], "asks": [{"price": "0.99", "size": "190.2"}, {"price": "0.98", "size": "95"}, {"price": "0.97", "size": "29.93"}, {"price": "0.47", "size": "100"}], "event_type": "book", "last_trade_price": ""}, {"market": "0xf03b83ca811da2bd2fc61195a40a4de255083315e40e91716f282e7f64a4681d", "asset_id": "99539110833954966113637313399179884315619862011580759033158888790135001736151", "timestamp": "1769384223562", "hash": "2c6a0b5228d17c871ffc0459b06f2edbeb00a62e", "bids": [{"price": "0.01", "size": "195.47"}, {"price": "0.02", "size": "95.18"}, {"price": "0.03", "size": "24.72"}, {"price": "0.04", "size": "5.47"}], "asks": [{"price": "0.99", "size": "201.38"}, {"price": "0.98", "size": "100.17"}, {"price": "0.97", "size": "52.57"}], "event_type": "book", "last_trade_price": ""}, {"market": "0x230607f610338c5d3a16bd50be25aa7ab60de534e39e8d5d699c5001c1e595b6", "asset_id": "97475721730557716007480813374619905620491367538874061914903518785234203691652", "timestamp": "1769384369562", "hash": "18d9d97dd521f3b4dd88672cb7a1c88e5dca6aae", "bids": [{"price": "0.01", "size": "208.36"}, {"price": "0.02", "size": "25.56"}, {"price": "0.03", "size": "5.47"}], "asks": [{"price": "0.99", "size": "201.38"}, {"price": "0.98", "size": "29.05"}, {"price": "0.97", "size": "39.99"}], "event_type": "book", "last_trade_price": ""}, {"market": "0x75f85ab4766e55b79b02c01d71585e35ad6ff20b548cab627068d4ea3da80485", "asset_id": "45680141513984007621811434593349360061748472127524556055696225422287120995477", "timestamp": "1769379487650", "hash": "38cc8702548f3d47750aeccbcc98b869fc140fda", "bids": [{"price": "0.01", "size": "242.27"}, {"price": "0.02", "size": "65"}, {"price": "0.03", "size": "29.74"}, {"price": "0.42", "size": "100"}], "asks": [{"price": "0.99", "size": "241.91"}, {"price": "0.98", "size": "65"}, {"price": "0.97", "size": "29.86"}, {"price": "0.52", "size": "100"}], "event_type": "book", "last_trade_price": ""}, {"market": "0xf03b83ca811da2bd2fc61195a40a4de255083315e40e91716f282e7f64a4681d", "asset_id": "12621476053563245870567256726900519038270292247970234647772913506087402134800", "timestamp": "1769384223562", "hash": "9f1ca6e2b77104ff641a0a06e8bd8c8e6b6e89e4", "bids": [{"price": "0.01", "size": "201.38"}, {"price": "0.02", "size": "100.17"}, {"price": "0.03", "size": "52.57"}], "asks": [{"price": "0.99", "size": "195.47"}, {"price": "0.98", "size": "95.18"}, {"price": "0.97", "size": "24.72"}, {"price": "0.96", "size": "5.47"}], "event_type": "book", "last_trade_price": ""}, {"market": "0x6368d8b032107a3d98d5d48bbf11f645884650afb1cc44f7c4f42802c0ec50e9", "asset_id": "17317859465220493694662701923786153616051066037292795638259267848918590536237", "timestamp": "1769379492245", "hash": "6139cb59ce185c2b33ada2802b81767572546869", "bids": [{"price": "0.01", "size": "190.2"}, {"price": "0.02", "size": "95"}, {"price": "0.03", "size": "29.93"}, {"price": "0.53", "size": "100"}], "asks": [{"price": "0.99", "size": "190.58"}, {"price": "0.98", "size": "90"}, {"price": "0.97", "size": "29.8"}, {"price": "0.63", "size": "100"}], "event_type": "book", "last_trade_price": ""}, {"market": "0xea99692e10dc5d0482fc6caa7e69f4e6a59c2ea6c3263633a55803dac12f8853", "asset_id": "80083871253257763661981303321159551720491415465567704045574035061765371860867", "timestamp": "1769381471593", "hash": "793941a1b4b8e00808df23a53a30566e58d7bccb", "bids": [{"price": "0.01", "size": "201.38"}, {"price": "0.02", "size": "29.05"}, {"price": "0.03", "size": "45.46"}], "asks": [{"price": "0.99", "size": "201.38"}, {"price": "0.98", "size": "29.05"}, {"price": "0.97", "size": "39.99"}], "event_type": "book", "last_trade_price": ""}]}
{"_local_timestamp": "2026-01-25T23:42:07.847788+00:00", "data": {"market": "0x27ca72003935168fa5145df02d60bf388556aae40004bf8878ca07908679c90a", "price_changes": [{"asset_id": "39988103022538972074566738669948101601617351308210751441166542218243560439585", "price": "0.04", "size": "29.99", "side": "BUY", "hash": "cbfc1a6ec097e233d49ec10e7cc887e194ec397b", "best_bid": "0.04", "best_ask": "0.96"}, {"asset_id": "63076381782914098979289416106534140467979969107420034465007654424987247815951", "price": "0.96", "size": "29.99", "side": "SELL", "hash": "50c93aba3a2a4732025789bde98c983704b39d9e", "best_bid": "0.04", "best_ask": "0.96"}], "timestamp": "1769384527767", "event_type": "price_change"}}
{"_local_timestamp": "2026-01-25T23:42:10.877254+00:00", "data": {"market": "0x27ca72003935168fa5145df02d60bf388556aae40004bf8878ca07908679c90a", "price_changes": [{"asset_id": "39988103022538972074566738669948101601617351308210751441166542218243560439585", "price": "0.03", "size": "0", "side": "BUY", "hash": "d4efa99e917f8803ac50061bfc05fe370abd44ad", "best_bid": "0.04", "best_ask": "0.96"}, {"asset_id": "63076381782914098979289416106534140467979969107420034465007654424987247815951", "price": "0.97", "size": "0", "side": "SELL", "hash": "d12893b13f77f27d9207f5647d9873a2afa4bc8f", "best_bid": "0.04", "best_ask": "0.96"}], "timestamp": "1769384530792", "event_type": "price_change"}}
{"_local_timestamp": "2026-01-25T23:42:11.201713+00:00", "data": {"market": "0x27ca72003935168fa5145df02d60bf388556aae40004bf8878ca07908679c90a", "price_changes": [{"asset_id": "39988103022538972074566738669948101601617351308210751441166542218243560439585", "price": "0.05", "size": "5.47", "side": "BUY", "hash": "efcf2ee1bf6f21ce170e673865e51a45f0725f9a", "best_bid": "0.05", "best_ask": "0.96"}, {"asset_id": "63076381782914098979289416106534140467979969107420034465007654424987247815951", "price": "0.95", "size": "5.47", "side": "SELL", "hash": "760f111969f1055c99aa1772fc9eaec2fea92986", "best_bid": "0.04", "best_ask": "0.95"}], "timestamp": "1769384531128", "event_type": "price_change"}}
{"_local_timestamp": "2026-01-25T23:42:45.088220+00:00", "data": {"market": "0xf03b83ca811da2bd2fc61195a40a4de255083315e40e91716f282e7f64a4681d", "price_changes": [{"asset_id": "99539110833954966113637313399179884315619862011580759033158888790135001736151", "price": "0.03", "size": "9.8", "side": "BUY", "hash": "ffaff6c77dd89ea32c0644d8ff0ca42b1e82f10f", "best_bid": "0.04", "best_ask": "0.97"}, {"asset_id": "12621476053563245870567256726900519038270292247970234647772913506087402134800", "price": "0.97", "size": "9.8", "side": "SELL", "hash": "cca87dad82899e901da56c875bc11adfeaf9d53b", "best_bid": "0.03", "best_ask": "0.96"}], "timestamp": "1769384564941", "event_type": "price_change"}}
{"_local_timestamp": "2026-01-25T23:42:45.492798+00:00", "data": {"market": "0xf03b83ca811da2bd2fc61195a40a4de255083315e40e91716f282e7f64a4681d", "price_changes": [{"asset_id": "99539110833954966113637313399179884315619862011580759033158888790135001736151", "price": "0.01", "size": "202.04", "side": "BUY", "hash": "e38d9b43fae1e26c7f22a0646cb30cf9bb1e3a05", "best_bid": "0.04", "best_ask": "0.97"}, {"asset_id": "12621476053563245870567256726900519038270292247970234647772913506087402134800", "price": "0.99", "size": "202.04", "side": "SELL", "hash": "493f815063a984b0fc9420ae6157cb55778a9047", "best_bid": "0.03", "best_ask": "0.96"}], "timestamp": "1769384565234", "event_type": "price_change"}}
{"_local_timestamp": "2026-01-25T23:42:45.493638+00:00", "data": {"market": "0xf03b83ca811da2bd2fc61195a40a4de255083315e40e91716f282e7f64a4681d", "price_changes": [{"asset_id": "99539110833954966113637313399179884315619862011580759033158888790135001736151", "price": "0.03", "size": "18.99", "side": "BUY", "hash": "808612d0c192b674e0c998dbf24f3c028161ece9", "best_bid": "0.04", "best_ask": "0.97"}, {"asset_id": "12621476053563245870567256726900519038270292247970234647772913506087402134800", "price": "0.97", "size": "18.99", "side": "SELL", "hash": "7b48fb58c3bd9f9f63231d28b4428676ca59122c", "best_bid": "0.03", "best_ask": "0.96"}], "timestamp": "1769384565235", "event_type": "price_change"}}
{"_local_timestamp": "2026-01-25T23:42:45.494138+00:00", "data": {"market": "0xf03b83ca811da2bd2fc61195a40a4de255083315e40e91716f282e7f64a4681d", "price_changes": [{"asset_id": "99539110833954966113637313399179884315619862011580759033158888790135001736151", "price": "0.02", "size": "100.48", "side": "BUY", "hash": "73c3e40b274d883f403918ca518f666d485fdf22", "best_bid": "0.04", "best_ask": "0.97"}, {"asset_id": "12621476053563245870567256726900519038270292247970234647772913506087402134800", "price": "0.98", "size": "100.48", "side": "SELL", "hash": "d130eb87c3c09f128f5b758be43b8961191b496d", "best_bid": "0.03", "best_ask": "0.96"}], "timestamp": "1769384565236", "event_type": "price_change"}}
{"_local_timestamp": "2026-01-25T23:43:35.210851+00:00", "data": {"market": "0x27ca72003935168fa5145df02d60bf388556aae40004bf8878ca07908679c90a", "price_changes": [{"asset_id": "39988103022538972074566738669948101601617351308210751441166542218243560439585", "price": "0.04", "size": "0", "side": "BUY", "hash": "598f02cbb510aaa1ad17c775aa94037a01e4b15a", "best_bid": "0.05", "best_ask": "0.96"}, {"asset_id": "63076381782914098979289416106534140467979969107420034465007654424987247815951", "price": "0.96", "size": "0", "side": "SELL", "hash": "0a5415af64406fe790d7031d4e561c2cb294b3f3", "best_bid": "0.04", "best_ask": "0.95"}], "timestamp": "1769384615119", "event_type": "price_change"}}
{"_local_timestamp": "2026-01-25T23:43:36.109279+00:00", "data": {"market": "0xf4f48f5b93ad07125c1487eca5c05632aa299a9ce8d547b3181906455b6ffc30", "price_changes": [{"asset_id": "52037538169528564564638458855755309591097235785433599464625697767410175594920", "price": "0.05", "size": "23.99", "side": "BUY", "hash": "57cb06ad867aae34b78e4629ce2eec31ea4d0134", "best_bid": "0.05", "best_ask": "0.97"}, {"asset_id": "45351011268357454489754819517897238839825192588635910066796851405573865769474", "price": "0.95", "size": "23.99", "side": "SELL", "hash": "c19408e97ec4a2e9a0851385473cce4fd526d799", "best_bid": "0.03", "best_ask": "0.95"}], "timestamp": "1769384615995", "event_type": "price_change"}}
{"_local_timestamp": "2026-01-25T23:43:36.109638+00:00", "data": {"market": "0x230607f610338c5d3a16bd50be25aa7ab60de534e39e8d5d699c5001c1e595b6", "price_changes": [{"asset_id": "97475721730557716007480813374619905620491367538874061914903518785234203691652", "price": "0.04", "size": "29.99", "side": "BUY", "hash": "4d0e509b58f7fe2382caba2324aa701d9c4193b1", "best_bid": "0.04", "best_ask": "0.97"}, {"asset_id": "54704412367939001823042963194576165230971916634123177373358746651929926233731", "price": "0.96", "size": "29.99", "side": "SELL", "hash": "e558817e79d13889db2578b7e89bb329502612cc", "best_bid": "0.03", "best_ask": "0.96"}], "timestamp": "1769384615995", "event_type": "price_change"}}
{"_local_timestamp": "2026-01-25T23:43:36.109917+00:00", "data": {"market": "0xf03b83ca811da2bd2fc61195a40a4de255083315e40e91716f282e7f64a4681d", "price_changes": [{"asset_id": "99539110833954966113637313399179884315619862011580759033158888790135001736151", "price": "0.05", "size": "23.99", "side": "BUY", "hash": "1f44b397b3b4f0a86614007a5bbbc7b8fbda11a7", "best_bid": "0.05", "best_ask": "0.97"}, {"asset_id": "12621476053563245870567256726900519038270292247970234647772913506087402134800", "price": "0.95", "size": "23.99", "side": "SELL", "hash": "25bab193f6b0ee53a1bcbcac785af32758a4fc83", "best_bid": "0.03", "best_ask": "0.95"}], "timestamp": "1769384615996", "event_type": "price_change"}}
{"_local_timestamp": "2026-01-25T23:43:36.222234+00:00", "data": {"market": "0xf4f48f5b93ad07125c1487eca5c05632aa299a9ce8d547b3181906455b6ffc30", "price_changes": [{"asset_id": "52037538169528564564638458855755309591097235785433599464625697767410175594920", "price": "0.03", "size": "9.8", "side": "BUY", "hash": "6cbb8b936853ce87076c9e92a26d759d026b330e", "best_bid": "0.05", "best_ask": "0.97"}, {"asset_id": "45351011268357454489754819517897238839825192588635910066796851405573865769474", "price": "0.97", "size": "9.8", "side": "SELL", "hash": "d9c89a6d978d22da3be1139141fdd889d6762116", "best_bid": "0.03", "best_ask": "0.95"}], "timestamp": "1769384616128", "event_type": "price_change"}}
{"_local_timestamp": "2026-01-25T23:43:36.532246+00:00", "data": {"market": "0xf4f48f5b93ad07125c1487eca5c05632aa299a9ce8d547b3181906455b6ffc30", "price_changes": [{"asset_id": "52037538169528564564638458855755309591097235785433599464625697767410175594920", "price": "0.03", "size": "18.99", "side": "BUY", "hash": "396500cce35a7f4ec2aa0dfe985edb84429812a7", "best_bid": "0.05", "best_ask": "0.97"}, {"asset_id": "45351011268357454489754819517897238839825192588635910066796851405573865769474", "price": "0.97", "size": "18.99", "side": "SELL", "hash": "189ee346a464ae914e9651e8e240c891a401387e", "best_bid": "0.03", "best_ask": "0.95"}], "timestamp": "1769384616450", "event_type": "price_change"}}
{"_local_timestamp": "2026-01-25T23:43:36.538742+00:00", "data": {"market": "0xf4f48f5b93ad07125c1487eca5c05632aa299a9ce8d547b3181906455b6ffc30", "price_changes": [{"asset_id": "52037538169528564564638458855755309591097235785433599464625697767410175594920", "price": "0.01", "size": "202.04", "side": "BUY", "hash": "acd14c824369b1f5e864e5a717b347cbdd4d026c", "best_bid": "0.05", "best_ask": "0.97"}, {"asset_id": "45351011268357454489754819517897238839825192588635910066796851405573865769474", "price": "0.99", "size": "202.04", "side": "SELL", "hash": "1867dcaa78b8613cf0379ae3a0915edffa93654e", "best_bid": "0.03", "best_ask": "0.95"}], "timestamp": "1769384616450", "event_type": "price_change"}}
{"_local_timestamp": "2026-01-25T23:43:36.539183+00:00", "data": {"market": "0xf4f48f5b93ad07125c1487eca5c05632aa299a9ce8d547b3181906455b6ffc30", "price_changes": [{"asset_id": "52037538169528564564638458855755309591097235785433599464625697767410175594920", "price": "0.02", "size": "100.48", "side": "BUY", "hash": "804d7528e8a5626bdb4884e514327b75f526900e", "best_bid": "0.05", "best_ask": "0.97"}, {"asset_id": "45351011268357454489754819517897238839825192588635910066796851405573865769474", "price": "0.98", "size": "100.48", "side": "SELL", "hash": "bc698387c2e9b436b08c14aa3c2a97549bc98f85", "best_bid": "0.03", "best_ask": "0.95"}], "timestamp": "1769384616451", "event_type": "price_change"}}
{"_local_timestamp": "2026-01-25T23:43:38.013273+00:00", "data": {"market": "0x13d3b44b12294fc57ae0bd7eaa03ce913c557cfd86a75bf9d2f824081be0af06", "price_changes": [{"asset_id": "61753867760589263716170746998286765860517841601052294758213209498622686532394", "price": "0.02", "size": "5.82", "side": "BUY", "hash": "6d84c50b6839c771f866eee004287f5aa0a637a4", "best_bid": "0.34", "best_ask": "0.39"}, {"asset_id": "27534087816472888388482777492068482333587764608177303542485554201592863278418", "price": "0.98", "size": "5.82", "side": "SELL", "hash": "5e5041565c8db13f59edbcae39bb177fe32972ed", "best_bid": "0.61", "best_ask": "0.66"}], "timestamp": "1769384617933", "event_type": "price_change"}}
{"_local_timestamp": "2026-01-25T23:43:38.198545+00:00", "data": {"market": "0x13d3b44b12294fc57ae0bd7eaa03ce913c557cfd86a75bf9d2f824081be0af06", "price_changes": [{"asset_id": "61753867760589263716170746998286765860517841601052294758213209498622686532394", "price": "0.02", "size": "49.99", "side": "BUY", "hash": "aa662526be2737e55c2f3f5e0b9491375f6a2a2c", "best_bid": "0.34", "best_ask": "0.39"}, {"asset_id": "27534087816472888388482777492068482333587764608177303542485554201592863278418", "price": "0.98", "size": "49.99", "side": "SELL", "hash": "db634ba852a9c1b94e4d7e72267e20263a6c07b6", "best_bid": "0.61", "best_ask": "0.66"}], "timestamp": "1769384618129", "event_type": "price_change"}}
{"_local_timestamp": "2026-01-25T23:43:39.897796+00:00", "data": {"market": "0xf03b83ca811da2bd2fc61195a40a4de255083315e40e91716f282e7f64a4681d", "price_changes": [{"asset_id": "99539110833954966113637313399179884315619862011580759033158888790135001736151", "price": "0.04", "size": "0", "side": "BUY", "hash": "09ca9e006468bb0cec7516ffe0552d4b64db232a", "best_bid": "0.05", "best_ask": "0.97"}, {"asset_id": "12621476053563245870567256726900519038270292247970234647772913506087402134800", "price": "0.96", "size": "0", "side": "SELL", "hash": "b0ff836bf612d301258406008b9a8fd5e64cedb6", "best_bid": "0.03", "best_ask": "0.95"}], "timestamp": "1769384619812", "event_type": "price_change"}}
{"_local_timestamp": "2026-01-25T23:43:39.907896+00:00", "data": {"market": "0xf4f48f5b93ad07125c1487eca5c05632aa299a9ce8d547b3181906455b6ffc30", "price_changes": [{"asset_id": "52037538169528564564638458855755309591097235785433599464625697767410175594920", "price": "0.04", "size": "0", "side": "BUY", "hash": "4ebfa4a14b2d6aa8090d67e14ba6d5ec610b1fe9", "best_bid": "0.05", "best_ask": "0.97"}, {"asset_id": "45351011268357454489754819517897238839825192588635910066796851405573865769474", "price": "0.96", "size": "0", "side": "SELL", "hash": "26cb0bae514efc27e2455c5f75bafc6aa7da0e95", "best_bid": "0.03", "best_ask": "0.95"}], "timestamp": "1769384619812", "event_type": "price_change"}}
{"_local_timestamp": "2026-01-25T23:43:39.911292+00:00", "data": {"market": "0x230607f610338c5d3a16bd50be25aa7ab60de534e39e8d5d699c5001c1e595b6", "price_changes": [{"asset_id": "97475721730557716007480813374619905620491367538874061914903518785234203691652", "price": "0.03", "size": "0", "side": "BUY", "hash": "1b2a32caf1e028ed81503b0e3ad72b4d6bc121a3", "best_bid": "0.04", "best_ask": "0.97"}, {"asset_id": "54704412367939001823042963194576165230971916634123177373358746651929926233731", "price": "0.97", "size": "0", "side": "SELL", "hash": "444406c2b8f64c066d20c53cdacb3b9a8a3f3bdb", "best_bid": "0.03", "best_ask": "0.96"}], "timestamp": "1769384619813", "event_type": "price_change"}}
{"_local_timestamp": "2026-01-25T23:43:39.911676+00:00", "data": {"market": "0x27ca72003935168fa5145df02d60bf388556aae40004bf8878ca07908679c90a", "price_changes": [{"asset_id": "39988103022538972074566738669948101601617351308210751441166542218243560439585", "price": "0.05", "size": "0", "side": "BUY", "hash": "035204a5582f8c73e2d46c4250b71934d260081f", "best_bid": "0.02", "best_ask": "0.96"}, {"asset_id": "63076381782914098979289416106534140467979969107420034465007654424987247815951", "price": "0.95", "size": "0", "side": "SELL", "hash": "3b38358ccbe769861e337b84173103293f9a318c", "best_bid": "0.04", "best_ask": "0.98"}], "timestamp": "1769384619813", "event_type": "price_change"}}
{"_local_timestamp": "2026-01-25T23:43:40.207739+00:00", "data": {"market": "0x27ca72003935168fa5145df02d60bf388556aae40004bf8878ca07908679c90a", "price_changes": [{"asset_id": "39988103022538972074566738669948101601617351308210751441166542218243560439585", "price": "0.03", "size": "5.47", "side": "BUY", "hash": "936b975b16cb424f8e3da35280a879614f37929e", "best_bid": "0.03", "best_ask": "0.96"}, {"asset_id": "63076381782914098979289416106534140467979969107420034465007654424987247815951", "price": "0.97", "size": "5.47", "side": "SELL", "hash": "27b5ecfae7a3bbaade22fdd90fb0e34d027b2a50", "best_bid": "0.04", "best_ask": "0.97"}], "timestamp": "1769384620121", "event_type": "price_change"}}
{"_local_timestamp": "2026-01-25T23:43:40.208172+00:00", "data": {"market": "0xf03b83ca811da2bd2fc61195a40a4de255083315e40e91716f282e7f64a4681d", "price_changes": [{"asset_id": "99539110833954966113637313399179884315619862011580759033158888790135001736151", "price": "0.06", "size": "5.47", "side": "BUY", "hash": "a7def03cc8bea52a34e0e40d0f71c28f1a0aba54", "best_bid": "0.06", "best_ask": "0.97"}, {"asset_id": "12621476053563245870567256726900519038270292247970234647772913506087402134800", "price": "0.94", "size": "5.47", "side": "SELL", "hash": "cd05bd623f16777670abf4a1ca2c97ab728dfe31", "best_bid": "0.03", "best_ask": "0.94"}], "timestamp": "1769384620121", "event_type": "price_change"}}
{"_local_timestamp": "2026-01-25T23:43:40.208474+00:00", "data": {"market": "0x230607f610338c5d3a16bd50be25aa7ab60de534e39e8d5d699c5001c1e595b6", "price_changes": [{"asset_id": "97475721730557716007480813374619905620491367538874061914903518785234203691652", "price": "0.05", "size": "5.47", "side": "BUY", "hash": "7d5083c5e408fb7bbcf80cd02f538f87449b2903", "best_bid": "0.05", "best_ask": "0.97"}, {"asset_id": "54704412367939001823042963194576165230971916634123177373358746651929926233731", "price": "0.95", "size": "5.47", "side": "SELL", "hash": "2cdad6edbe008e83644fb5c791fa6d8a9a66bada", "best_bid": "0.03", "best_ask": "0.95"}], "timestamp": "1769384620121", "event_type": "price_change"}}
{"_local_timestamp": "2026-01-25T23:43:40.208803+00:00", "data": {"market": "0xf4f48f5b93ad07125c1487eca5c05632aa299a9ce8d547b3181906455b6ffc30", "price_changes": [{"asset_id": "52037538169528564564638458855755309591097235785433599464625697767410175594920", "price": "0.06", "size": "5.47", "side": "BUY", "hash": "b74affe9657c724e5ff5c8f2aede5466bb95416c", "best_bid": "0.06", "best_ask": "0.97"}, {"asset_id": "45351011268357454489754819517897238839825192588635910066796851405573865769474", "price": "0.94", "size": "5.47", "side": "SELL", "hash": "25920fba3af358bec788a85ea6da5455bde49b37", "best_bid": "0.03", "best_ask": "0.94"}], "timestamp": "1769384620121", "event_type": "price_change"}}
{"_local_timestamp": "2026-01-25T23:43:40.677146+00:00", "data": {"market": "0x27ca72003935168fa5145df02d60bf388556aae40004bf8878ca07908679c90a", "price_changes": [{"asset_id": "39988103022538972074566738669948101601617351308210751441166542218243560439585", "price": "0.01", "size": "197.51", "side": "BUY", "hash": "dc3b9f07aa166e91a75376d942dfa5c94a9390d6", "best_bid": "0.03", "best_ask": "0.96"}, {"asset_id": "63076381782914098979289416106534140467979969107420034465007654424987247815951", "price": "0.99", "size": "197.51", "side": "SELL", "hash": "4eb8453e787b8c7e18e37413aec12ea1bd399a40", "best_bid": "0.04", "best_ask": "0.97"}], "timestamp": "1769384620600", "event_type": "price_change"}}
{"_local_timestamp": "2026-01-25T23:43:40.677562+00:00", "data": {"market": "0x27ca72003935168fa5145df02d60bf388556aae40004bf8878ca07908679c90a", "price_changes": [{"asset_id": "39988103022538972074566738669948101601617351308210751441166542218243560439585", "price": "0.02", "size": "8.94", "side": "BUY", "hash": "dc3b9f07aa166e91a75376d942dfa5c94a9390d6", "best_bid": "0.03", "best_ask": "0.96"}, {"asset_id": "63076381782914098979289416106534140467979969107420034465007654424987247815951", "price": "0.98", "size": "8.94", "side": "SELL", "hash": "4eb8453e787b8c7e18e37413aec12ea1bd399a40", "best_bid": "0.04", "best_ask": "0.97"}], "timestamp": "1769384620600", "event_type": "price_change"}}
{"_local_timestamp": "2026-01-25T23:43:41.844218+00:00", "data": {"market": "0x27ca72003935168fa5145df02d60bf388556aae40004bf8878ca07908679c90a", "price_changes": [{"asset_id": "39988103022538972074566738669948101601617351308210751441166542218243560439585", "price": "0.03", "size": "13.33", "side": "BUY", "hash": "02d12df424033cd52a7db22881b6e489977485b9", "best_bid": "0.03", "best_ask": "0.96"}, {"asset_id": "63076381782914098979289416106534140467979969107420034465007654424987247815951", "price": "0.97", "size": "13.33", "side": "SELL", "hash": "d0ee4ed43fede53a555fafcc36f4ace1142761a3", "best_bid": "0.04", "best_ask": "0.97"}], "timestamp": "1769384621767", "event_type": "price_change"}}
{"_local_timestamp": "2026-01-25T23:45:09.924943+00:00", "data": {"market": "0xf03b83ca811da2bd2fc61195a40a4de255083315e40e91716f282e7f64a4681d", "price_changes": [{"asset_id": "99539110833954966113637313399179884315619862011580759033158888790135001736151", "price": "0.05", "size": "0", "side": "BUY", "hash": "7bc8be1fdbe21f94d8ef3aabdc2d7b188bce4d8c", "best_bid": "0.06", "best_ask": "0.97"}, {"asset_id": "12621476053563245870567256726900519038270292247970234647772913506087402134800", "price": "0.95", "size": "0", "side": "SELL", "hash": "58aa7f99bc38db10dafaefa06e8e56b223ad3b2a", "best_bid": "0.03", "best_ask": "0.94"}], "timestamp": "1769384709855", "event_type": "price_change"}}
{"_local_timestamp": "2026-01-25T23:45:09.928115+00:00", "data": {"market": "0x230607f610338c5d3a16bd50be25aa7ab60de534e39e8d5d699c5001c1e595b6", "price_changes": [{"asset_id": "97475721730557716007480813374619905620491367538874061914903518785234203691652", "price": "0.04", "size": "0", "side": "BUY", "hash": "12f7db141a9882e1f138ec4de7a1ccac688ee338", "best_bid": "0.05", "best_ask": "0.97"}, {"asset_id": "54704412367939001823042963194576165230971916634123177373358746651929926233731", "price": "0.96", "size": "0", "side": "SELL", "hash": "d2ac09b2f16736049820041bcefbe14045cdc18c", "best_bid": "0.03", "best_ask": "0.95"}], "timestamp": "1769384709855", "event_type": "price_change"}}
{"_local_timestamp": "2026-01-25T23:45:09.928464+00:00", "data": {"market": "0xf4f48f5b93ad07125c1487eca5c05632aa299a9ce8d547b3181906455b6ffc30", "price_changes": [{"asset_id": "52037538169528564564638458855755309591097235785433599464625697767410175594920", "price": "0.05", "size": "0", "side": "BUY", "hash": "2cef7a058227839748e564a8f7cf529daafc2561", "best_bid": "0.06", "best_ask": "0.97"}, {"asset_id": "45351011268357454489754819517897238839825192588635910066796851405573865769474", "price": "0.95", "size": "0", "side": "SELL", "hash": "8d11a428198ef6bd384d916a3c4547978bde73ed", "best_bid": "0.03", "best_ask": "0.94"}], "timestamp": "1769384709855", "event_type": "price_change"}}
{"_local_timestamp": "2026-01-25T23:45:11.856416+00:00", "data": {"market": "0xf03b83ca811da2bd2fc61195a40a4de255083315e40e91716f282e7f64a4681d", "price_changes": [{"asset_id": "99539110833954966113637313399179884315619862011580759033158888790135001736151", "price": "0.06", "size": "0", "side": "BUY", "hash": "026f2710cb0589bba28a15559aa73a081faba8e3", "best_bid": "0.03", "best_ask": "0.97"}, {"asset_id": "12621476053563245870567256726900519038270292247970234647772913506087402134800", "price": "0.94", "size": "0", "side": "SELL", "hash": "c4afbeac513f586b3c6c06d0a6f5c432dff8226d", "best_bid": "0.03", "best_ask": "0.97"}], "timestamp": "1769384711771", "event_type": "price_change"}}
{"_local_timestamp": "2026-01-25T23:45:11.865150+00:00", "data": {"market": "0x230607f610338c5d3a16bd50be25aa7ab60de534e39e8d5d699c5001c1e595b6", "price_changes": [{"asset_id": "97475721730557716007480813374619905620491367538874061914903518785234203691652", "price": "0.05", "size": "0", "side": "BUY", "hash": "609587dba236150aac9274a856f1eeaea91e8115", "best_bid": "0.02", "best_ask": "0.97"}, {"asset_id": "54704412367939001823042963194576165230971916634123177373358746651929926233731", "price": "0.95", "size": "0", "side": "SELL", "hash": "6736ae4e83ae2a160f5c868c18d559e6e3f84ab6", "best_bid": "0.03", "best_ask": "0.98"}], "timestamp": "1769384711772", "event_type": "price_change"}}
{"_local_timestamp": "2026-01-25T23:45:11.867037+00:00", "data": {"market": "0xf4f48f5b93ad07125c1487eca5c05632aa299a9ce8d547b3181906455b6ffc30", "price_changes": [{"asset_id": "52037538169528564564638458855755309591097235785433599464625697767410175594920", "price": "0.06", "size": "0", "side": "BUY", "hash": "ba668784692ff143d216ed1f46f4753d774b167a", "best_bid": "0.03", "best_ask": "0.97"}, {"asset_id": "45351011268357454489754819517897238839825192588635910066796851405573865769474", "price": "0.94", "size": "0", "side": "SELL", "hash": "f627ec47aa08a477f6192c956a358af260b522f1", "best_bid": "0.03", "best_ask": "0.97"}], "timestamp": "1769384711771", "event_type": "price_change"}}
{"_local_timestamp": "2026-01-25T23:45:12.137291+00:00", "data": {"market": "0xf03b83ca811da2bd2fc61195a40a4de255083315e40e91716f282e7f64a4681d", "price_changes": [{"asset_id": "99539110833954966113637313399179884315619862011580759033158888790135001736151", "price": "0.04", "size": "5.47", "side": "BUY", "hash": "2e2b3e287e3abfaaf2f758a67b1f55d30357af9d", "best_bid": "0.04", "best_ask": "0.97"}, {"asset_id": "12621476053563245870567256726900519038270292247970234647772913506087402134800", "price": "0.96", "size": "5.47", "side": "SELL", "hash": "106df307d7096ab1872fdc85773a9653915d2955", "best_bid": "0.03", "best_ask": "0.96"}], "timestamp": "1769384712067", "event_type": "price_change"}}
{"_local_timestamp": "2026-01-25T23:45:12.137709+00:00", "data": {"market": "0x230607f610338c5d3a16bd50be25aa7ab60de534e39e8d5d699c5001c1e595b6", "price_changes": [{"asset_id": "97475721730557716007480813374619905620491367538874061914903518785234203691652", "price": "0.03", "size": "5.47", "side": "BUY", "hash": "6c03f459183eb5200085fd6b41ca148809ccefd5", "best_bid": "0.03", "best_ask": "0.97"}, {"asset_id": "54704412367939001823042963194576165230971916634123177373358746651929926233731", "price": "0.97", "size": "5.47", "side": "SELL", "hash": "26327df8792ae8f5b036680bea02cfb79ddff93d", "best_bid": "0.03", "best_ask": "0.97"}], "timestamp": "1769384712067", "event_type": "price_change"}}
{"_local_timestamp": "2026-01-25T23:45:12.138068+00:00", "data": {"market": "0xf4f48f5b93ad07125c1487eca5c05632aa299a9ce8d547b3181906455b6ffc30", "price_changes": [{"asset_id": "52037538169528564564638458855755309591097235785433599464625697767410175594920", "price": "0.04", "size": "5.47", "side": "BUY", "hash": "e6d10043c0003ff06814abd48f7ecfb72e86b0d1", "best_bid": "0.04", "best_ask": "0.97"}, {"asset_id": "45351011268357454489754819517897238839825192588635910066796851405573865769474", "price": "0.96", "size": "5.47", "side": "SELL", "hash": "cf551c57cc1fb2f3c2a75a5854497de5a5385da4", "best_bid": "0.03", "best_ask": "0.96"}], "timestamp": "1769384712067", "event_type": "price_change"}}
{"_local_timestamp": "2026-01-25T23:45:28.499253+00:00", "data": {"market": "0x13d3b44b12294fc57ae0bd7eaa03ce913c557cfd86a75bf9d2f824081be0af06", "price_changes": [{"asset_id": "61753867760589263716170746998286765860517841601052294758213209498622686532394", "price": "0.02", "size": "5.82", "side": "BUY", "hash": "29407bab47080a9038803115392d8425cb39fe3a", "best_bid": "0.34", "best_ask": "0.39"}, {"asset_id": "27534087816472888388482777492068482333587764608177303542485554201592863278418", "price": "0.98", "size": "5.82", "side": "SELL", "hash": "247c72f47e5934c42a33164bb5827405d968be65", "best_bid": "0.61", "best_ask": "0.66"}], "timestamp": "1769384728424", "event_type": "price_change"}}
{"_local_timestamp": "2026-01-25T23:45:30.444679+00:00", "data": {"market": "0x230607f610338c5d3a16bd50be25aa7ab60de534e39e8d5d699c5001c1e595b6", "price_changes": [{"asset_id": "97475721730557716007480813374619905620491367538874061914903518785234203691652", "price": "0.01", "size": "198.81", "side": "BUY", "hash": "f4e94126a9e72be12d5f3a968b05676a5524fe01", "best_bid": "0.03", "best_ask": "0.97"}, {"asset_id": "54704412367939001823042963194576165230971916634123177373358746651929926233731", "price": "0.99", "size": "198.81", "side": "SELL", "hash": "816e787de097f9f47630520aadda39ec57d25411", "best_bid": "0.03", "best_ask": "0.97"}], "timestamp": "1769384730377", "event_type": "price_change"}}
{"_local_timestamp": "2026-01-25T23:45:31.167168+00:00", "data": {"market": "0x230607f610338c5d3a16bd50be25aa7ab60de534e39e8d5d699c5001c1e595b6", "price_changes": [{"asset_id": "97475721730557716007480813374619905620491367538874061914903518785234203691652", "price": "0.01", "size": "208.36", "side": "BUY", "hash": "81dfa1af9bc35d62d014fa10359c9f03790ad43d", "best_bid": "0.03", "best_ask": "0.97"}, {"asset_id": "54704412367939001823042963194576165230971916634123177373358746651929926233731", "price": "0.99", "size": "208.36", "side": "SELL", "hash": "adddd9d41a02bfb39917eac04c1ca6ca594a72ca", "best_bid": "0.03", "best_ask": "0.97"}], "timestamp": "1769384731094", "event_type": "price_change"}}
{"_local_timestamp": "2026-01-25T23:45:31.355393+00:00", "data": {"market": "0x13d3b44b12294fc57ae0bd7eaa03ce913c557cfd86a75bf9d2f824081be0af06", "price_changes": [{"asset_id": "61753867760589263716170746998286765860517841601052294758213209498622686532394", "price": "0.02", "size": "49.99", "side": "BUY", "hash": "fb1104b7113b9f3db0077b1d13fcfc13ce9af48d", "best_bid": "0.34", "best_ask": "0.39"}, {"asset_id": "27534087816472888388482777492068482333587764608177303542485554201592863278418", "price": "0.98", "size": "49.99", "side": "SELL", "hash": "169ed8539dcd400bd492792e57b539a24fda3a73", "best_bid": "0.61", "best_ask": "0.66"}], "timestamp": "1769384731285", "event_type": "price_change"}}
{"_local_timestamp": "2026-01-25T23:46:12.374742+00:00", "data": {"market": "0x27ca72003935168fa5145df02d60bf388556aae40004bf8878ca07908679c90a", "price_changes": [{"asset_id": "39988103022538972074566738669948101601617351308210751441166542218243560439585", "price": "0.03", "size": "5.47", "side": "BUY", "hash": "d088f5a73f53a59ff0d645f265470436714b19d3", "best_bid": "0.03", "best_ask": "0.96"}, {"asset_id": "63076381782914098979289416106534140467979969107420034465007654424987247815951", "price": "0.97", "size": "5.47", "side": "SELL", "hash": "745b5488f17e0a7e37d22be2f801920edabbb11e", "best_bid": "0.04", "best_ask": "0.97"}], "timestamp": "1769384772291", "event_type": "price_change"}}
{"_local_timestamp": "2026-01-25T23:46:14.455794+00:00", "data": {"market": "0x27ca72003935168fa5145df02d60bf388556aae40004bf8878ca07908679c90a", "price_changes": [{"asset_id": "39988103022538972074566738669948101601617351308210751441166542218243560439585", "price": "0.02", "size": "30.98", "side": "BUY", "hash": "e2fbf081cd7b03dccbe33c7e6dedc4d0acd507b0", "best_bid": "0.03", "best_ask": "0.96"}, {"asset_id": "63076381782914098979289416106534140467979969107420034465007654424987247815951", "price": "0.98", "size": "30.98", "side": "SELL", "hash": "fc10729a4d1fe81058e2b2aff9fac772a2d3ffd9", "best_bid": "0.04", "best_ask": "0.97"}], "timestamp": "1769384774383", "event_type": "price_change"}}
{"_local_timestamp": "2026-01-25T23:46:48.895290+00:00", "data": {"market": "0x230607f610338c5d3a16bd50be25aa7ab60de534e39e8d5d699c5001c1e595b6", "price_changes": [{"asset_id": "97475721730557716007480813374619905620491367538874061914903518785234203691652", "price": "0.04", "size": "29.99", "side": "BUY", "hash": "8059bc033711a6352d6fabe11c2ec31aa78d68ab", "best_bid": "0.04", "best_ask": "0.97"}, {"asset_id": "54704412367939001823042963194576165230971916634123177373358746651929926233731", "price": "0.96", "size": "29.99", "side": "SELL", "hash": "943c117d5defeeef12fdda3eb700307f1bf92457", "best_bid": "0.03", "best_ask": "0.96"}], "timestamp": "1769384808827", "event_type": "price_change"}}
{"_local_timestamp": "2026-01-25T23:46:48.896881+00:00", "data": {"market": "0xf4f48f5b93ad07125c1487eca5c05632aa299a9ce8d547b3181906455b6ffc30", "price_changes": [{"asset_id": "52037538169528564564638458855755309591097235785433599464625697767410175594920", "price": "0.05", "size": "23.99", "side": "BUY", "hash": "80441ecdd56dcb02b9cd03ff026080663dc01b25", "best_bid": "0.05", "best_ask": "0.97"}, {"asset_id": "45351011268357454489754819517897238839825192588635910066796851405573865769474", "price": "0.95", "size": "23.99", "side": "SELL", "hash": "9bea112acd269940f13d001649f7e7b48b2f1276", "best_bid": "0.03", "best_ask": "0.95"}], "timestamp": "1769384808827", "event_type": "price_change"}}
{"_local_timestamp": "2026-01-25T23:46:49.032826+00:00", "data": {"market": "0xf03b83ca811da2bd2fc61195a40a4de255083315e40e91716f282e7f64a4681d", "price_changes": [{"asset_id": "99539110833954966113637313399179884315619862011580759033158888790135001736151", "price": "0.05", "size": "23.99", "side": "BUY", "hash": "b4ef8a15bb2df1c8c6d5848c49c8e7128aca3c6d", "best_bid": "0.05", "best_ask": "0.97"}, {"asset_id": "12621476053563245870567256726900519038270292247970234647772913506087402134800", "price": "0.95", "size": "23.99", "side": "SELL", "hash": "b6786641d08d7b9a1bcff6368390897faac087a6", "best_bid": "0.03", "best_ask": "0.95"}], "timestamp": "1769384808922", "event_type": "price_change"}}
{"_local_timestamp": "2026-01-25T23:46:50.071713+00:00", "data": {"market": "0xf03b83ca811da2bd2fc61195a40a4de255083315e40e91716f282e7f64a4681d", "price_changes": [{"asset_id": "99539110833954966113637313399179884315619862011580759033158888790135001736151", "price": "0.04", "size": "0", "side": "BUY", "hash": "0bf8414f82df14efd4847d14081455da60a9d77a", "best_bid": "0.05", "best_ask": "0.97"}, {"asset_id": "12621476053563245870567256726900519038270292247970234647772913506087402134800", "price": "0.96", "size": "0", "side": "SELL", "hash": "b5ba05dae62aed5b97af0db84feddecbc8ddbd0c", "best_bid": "0.03", "best_ask": "0.95"}], "timestamp": "1769384809945", "event_type": "price_change"}}
{"_local_timestamp": "2026-01-25T23:46:50.072213+00:00", "data": {"market": "0x230607f610338c5d3a16bd50be25aa7ab60de534e39e8d5d699c5001c1e595b6", "price_changes": [{"asset_id": "97475721730557716007480813374619905620491367538874061914903518785234203691652", "price": "0.03", "size": "0", "side": "BUY", "hash": "aa6e6a91370f9ab8ff3e2cef000bbf45f6c9b852", "best_bid": "0.04", "best_ask": "0.97"}, {"asset_id": "54704412367939001823042963194576165230971916634123177373358746651929926233731", "price": "0.97", "size": "0", "side": "SELL", "hash": "6479bcd9b1f2656639bde4f9ff7b057217ebdce3", "best_bid": "0.03", "best_ask": "0.96"}], "timestamp": "1769384809945", "event_type": "price_change"}}
{"_local_timestamp": "2026-01-25T23:46:50.080080+00:00", "data": {"market": "0xf4f48f5b93ad07125c1487eca5c05632aa299a9ce8d547b3181906455b6ffc30", "price_changes": [{"asset_id": "52037538169528564564638458855755309591097235785433599464625697767410175594920", "price": "0.04", "size": "0", "side": "BUY", "hash": "b49327f6f7a24f55e1bc4e3df15d37224134c8b7", "best_bid": "0.05", "best_ask": "0.97"}, {"asset_id": "45351011268357454489754819517897238839825192588635910066796851405573865769474", "price": "0.96", "size": "0", "side": "SELL", "hash": "478f87685e0a05baa129a700a11d10b8b013a72c", "best_bid": "0.03", "best_ask": "0.95"}], "timestamp": "1769384809946", "event_type": "price_change"}}
{"_local_timestamp": "2026-01-25T23:46:50.284002+00:00", "data": {"market": "0xf4f48f5b93ad07125c1487eca5c05632aa299a9ce8d547b3181906455b6ffc30", "price_changes": [{"asset_id": "52037538169528564564638458855755309591097235785433599464625697767410175594920", "price": "0.06", "size": "5.47", "side": "BUY", "hash": "85d05f6dd231093e1704d8efcf3f2046e2bb4b28", "best_bid": "0.06", "best_ask": "0.97"}, {"asset_id": "45351011268357454489754819517897238839825192588635910066796851405573865769474", "price": "0.94", "size": "5.47", "side": "SELL", "hash": "5fff22ba29ef305c292e1d5b65b7544570beebc2", "best_bid": "0.03", "best_ask": "0.94"}], "timestamp": "1769384810156", "event_type": "price_change"}}
{"_local_timestamp": "2026-01-25T23:46:50.284441+00:00", "data": {"market": "0xf03b83ca811da2bd2fc61195a40a4de255083315e40e91716f282e7f64a4681d", "price_changes": [{"asset_id": "99539110833954966113637313399179884315619862011580759033158888790135001736151", "price": "0.06", "size": "5.47", "side": "BUY", "hash": "a9e878ccd873028251720a818fee034bc60ecade", "best_bid": "0.06", "best_ask": "0.97"}, {"asset_id": "12621476053563245870567256726900519038270292247970234647772913506087402134800", "price": "0.94", "size": "5.47", "side": "SELL", "hash": "fa126bf8667f88a475c942794be93efc0b2337c9", "best_bid": "0.03", "best_ask": "0.94"}], "timestamp": "1769384810156", "event_type": "price_change"}}
{"_local_timestamp": "2026-01-25T23:46:50.284833+00:00", "data": {"market": "0x230607f610338c5d3a16bd50be25aa7ab60de534e39e8d5d699c5001c1e595b6", "price_changes": [{"asset_id": "97475721730557716007480813374619905620491367538874061914903518785234203691652", "price": "0.05", "size": "5.47", "side": "BUY", "hash": "0224fa36e62e9bc261289a08ca42770c197408a5", "best_bid": "0.05", "best_ask": "0.97"}, {"asset_id": "54704412367939001823042963194576165230971916634123177373358746651929926233731", "price": "0.95", "size": "5.47", "side": "SELL", "hash": "53b1b9b0c3a5d5907e4acc9553b08836fd77e841", "best_bid": "0.03", "best_ask": "0.95"}], "timestamp": "1769384810157", "event_type": "price_change"}}
{"_local_timestamp": "2026-01-25T23:48:18.111106+00:00", "data": {"market": "0xf4f48f5b93ad07125c1487eca5c05632aa299a9ce8d547b3181906455b6ffc30", "price_changes": [{"asset_id": "52037538169528564564638458855755309591097235785433599464625697767410175594920", "price": "0.05", "size": "0", "side": "BUY", "hash": "257e9d7c070502388fa24c98711dd83034eb2f7b", "best_bid": "0.06", "best_ask": "0.97"}, {"asset_id": "45351011268357454489754819517897238839825192588635910066796851405573865769474", "price": "0.95", "size": "0", "side": "SELL", "hash": "00abd546a52d95f4366c38afce9996ce8ce40407", "best_bid": "0.03", "best_ask": "0.94"}], "timestamp": "1769384898004", "event_type": "price_change"}}
{"_local_timestamp": "2026-01-25T23:48:18.112145+00:00", "data": {"market": "0x230607f610338c5d3a16bd50be25aa7ab60de534e39e8d5d699c5001c1e595b6", "price_changes": [{"asset_id": "97475721730557716007480813374619905620491367538874061914903518785234203691652", "price": "0.04", "size": "0", "side": "BUY", "hash": "9f40dd65260739bdf2d12561b98e0fe169633fcb", "best_bid": "0.05", "best_ask": "0.97"}, {"asset_id": "54704412367939001823042963194576165230971916634123177373358746651929926233731", "price": "0.96", "size": "0", "side": "SELL", "hash": "993dfee3f83a47357a3d4b3b2761efbd83a4b4d9", "best_bid": "0.03", "best_ask": "0.95"}], "timestamp": "1769384898005", "event_type": "price_change"}}
{"_local_timestamp": "2026-01-25T23:48:18.112568+00:00", "data": {"market": "0xf03b83ca811da2bd2fc61195a40a4de255083315e40e91716f282e7f64a4681d", "price_changes": [{"asset_id": "99539110833954966113637313399179884315619862011580759033158888790135001736151", "price": "0.05", "size": "0", "side": "BUY", "hash": "30e8b4d44dceaeca8ccf1f7df6e98691477da322", "best_bid": "0.06", "best_ask": "0.97"}, {"asset_id": "12621476053563245870567256726900519038270292247970234647772913506087402134800", "price": "0.95", "size": "0", "side": "SELL", "hash": "6945bdc7bfc51dec1328b56a5248f209ff5b7f77", "best_bid": "0.03", "best_ask": "0.94"}], "timestamp": "1769384898005", "event_type": "price_change"}}
{"_local_timestamp": "2026-01-25T23:48:19.035539+00:00", "data": {"market": "0x27ca72003935168fa5145df02d60bf388556aae40004bf8878ca07908679c90a", "price_changes": [{"asset_id": "39988103022538972074566738669948101601617351308210751441166542218243560439585", "price": "0.04", "size": "29.99", "side": "BUY", "hash": "9ebcccc7014706eb1a4926ca40073ecfb5c443e2", "best_bid": "0.04", "best_ask": "0.96"}, {"asset_id": "63076381782914098979289416106534140467979969107420034465007654424987247815951", "price": "0.96", "size": "29.99", "side": "SELL", "hash": "b0025b8e4c867f06a8a40682edb7d2dc9252ac4e", "best_bid": "0.04", "best_ask": "0.96"}], "timestamp": "1769384898953", "event_type": "price_change"}}
{"_local_timestamp": "2026-01-25T23:48:21.760576+00:00", "data": {"market": "0x230607f610338c5d3a16bd50be25aa7ab60de534e39e8d5d699c5001c1e595b6", "price_changes": [{"asset_id": "97475721730557716007480813374619905620491367538874061914903518785234203691652", "price": "0.05", "size": "0", "side": "BUY", "hash": "41649f38b57bb15d7cd400affe2c76bce503d119", "best_bid": "0.02", "best_ask": "0.97"}, {"asset_id": "54704412367939001823042963194576165230971916634123177373358746651929926233731", "price": "0.95", "size": "0", "side": "SELL", "hash": "2c68cd89b54b40eab285b70d4077098c038368f9", "best_bid": "0.03", "best_ask": "0.98"}], "timestamp": "1769384901682", "event_type": "price_change"}}
{"_local_timestamp": "2026-01-25T23:48:21.765767+00:00", "data": {"market": "0xf03b83ca811da2bd2fc61195a40a4de255083315e40e91716f282e7f64a4681d", "price_changes": [{"asset_id": "99539110833954966113637313399179884315619862011580759033158888790135001736151", "price": "0.06", "size": "0", "side": "BUY", "hash": "4e563e9468f0adae5d5c086bfba74a290622f463", "best_bid": "0.03", "best_ask": "0.97"}, {"asset_id": "12621476053563245870567256726900519038270292247970234647772913506087402134800", "price": "0.94", "size": "0", "side": "SELL", "hash": "fd0f1034f0498970c23ee956e8cfe47f38b79c6d", "best_bid": "0.03", "best_ask": "0.97"}], "timestamp": "1769384901682", "event_type": "price_change"}}
{"_local_timestamp": "2026-01-25T23:48:21.766243+00:00", "data": {"market": "0xf4f48f5b93ad07125c1487eca5c05632aa299a9ce8d547b3181906455b6ffc30", "price_changes": [{"asset_id": "52037538169528564564638458855755309591097235785433599464625697767410175594920", "price": "0.06", "size": "0", "side": "BUY", "hash": "12c585199d964831af2fb72a0ff1c864dd9eee5d", "best_bid": "0.03", "best_ask": "0.97"}, {"asset_id": "45351011268357454489754819517897238839825192588635910066796851405573865769474", "price": "0.94", "size": "0", "side": "SELL", "hash": "2480325a52236b78a3eb55ab3b7adc555f124ef6", "best_bid": "0.03", "best_ask": "0.97"}], "timestamp": "1769384901682", "event_type": "price_change"}}
{"_local_timestamp": "2026-01-25T23:48:21.769748+00:00", "data": {"market": "0x27ca72003935168fa5145df02d60bf388556aae40004bf8878ca07908679c90a", "price_changes": [{"asset_id": "39988103022538972074566738669948101601617351308210751441166542218243560439585", "price": "0.03", "size": "0", "side": "BUY", "hash": "20ca067e9e4e4ca0490611ea54a43643abfc5b4d", "best_bid": "0.04", "best_ask": "0.96"}, {"asset_id": "63076381782914098979289416106534140467979969107420034465007654424987247815951", "price": "0.97", "size": "0", "side": "SELL", "hash": "0b8c0270a1ba70b9e46b40f72c3dfa257a6fd62e", "best_bid": "0.04", "best_ask": "0.96"}], "timestamp": "1769384901682", "event_type": "price_change"}}
{"_local_timestamp": "2026-01-25T23:48:22.186110+00:00", "data": {"market": "0xf4f48f5b93ad07125c1487eca5c05632aa299a9ce8d547b3181906455b6ffc30", "price_changes": [{"asset_id": "52037538169528564564638458855755309591097235785433599464625697767410175594920", "price": "0.04", "size": "5.47", "side": "BUY", "hash": "00902fec397caf0e89938b0a74ad6212480177cb", "best_bid": "0.04", "best_ask": "0.97"}, {"asset_id": "45351011268357454489754819517897238839825192588635910066796851405573865769474", "price": "0.96", "size": "5.47", "side": "SELL", "hash": "01324f31c03b606ebb6dd53a276a498eb5559303", "best_bid": "0.03", "best_ask": "0.96"}], "timestamp": "1769384902097", "event_type": "price_change"}}
{"_local_timestamp": "2026-01-25T23:48:22.216311+00:00", "data": {"market": "0x27ca72003935168fa5145df02d60bf388556aae40004bf8878ca07908679c90a", "price_changes": [{"asset_id": "39988103022538972074566738669948101601617351308210751441166542218243560439585", "price": "0.05", "size": "5.47", "side": "BUY", "hash": "26c110af30eb6e84862f9f924354f87da8fd1f9d", "best_bid": "0.05", "best_ask": "0.96"}, {"asset_id": "63076381782914098979289416106534140467979969107420034465007654424987247815951", "price": "0.95", "size": "5.47", "side": "SELL", "hash": "1ea9308cdda72ff7fef472a638110b1b3db123fd", "best_bid": "0.04", "best_ask": "0.95"}], "timestamp": "1769384902150", "event_type": "price_change"}}
{"_local_timestamp": "2026-01-25T23:48:22.217556+00:00", "data": {"market": "0x230607f610338c5d3a16bd50be25aa7ab60de534e39e8d5d699c5001c1e595b6", "price_changes": [{"asset_id": "97475721730557716007480813374619905620491367538874061914903518785234203691652", "price": "0.03", "size": "5.47", "side": "BUY", "hash": "eda0db150564292d3728091cad0559639d150041", "best_bid": "0.03", "best_ask": "0.97"}, {"asset_id": "54704412367939001823042963194576165230971916634123177373358746651929926233731", "price": "0.97", "size": "5.47", "side": "SELL", "hash": "c0b88d3e4cc708bc8abfc3a86630e9d5c688339e", "best_bid": "0.03", "best_ask": "0.97"}], "timestamp": "1769384902150", "event_type": "price_change"}}
{"_local_timestamp": "2026-01-25T23:48:22.218050+00:00", "data": {"market": "0xf03b83ca811da2bd2fc61195a40a4de255083315e40e91716f282e7f64a4681d", "price_changes": [{"asset_id": "99539110833954966113637313399179884315619862011580759033158888790135001736151", "price": "0.04", "size": "5.47", "side": "BUY", "hash": "4ded8fa56825925adaa385db3c316e740e6a5142", "best_bid": "0.04", "best_ask": "0.97"}, {"asset_id": "12621476053563245870567256726900519038270292247970234647772913506087402134800", "price": "0.96", "size": "5.47", "side": "SELL", "hash": "8e5f94285eef6c5880e03eaf9fcaa857d52d2cdd", "best_bid": "0.03", "best_ask": "0.96"}], "timestamp": "1769384902150", "event_type": "price_change"}}
{"_local_timestamp": "2026-01-25T23:49:37.636200+00:00", "data": {"market": "0x13d3b44b12294fc57ae0bd7eaa03ce913c557cfd86a75bf9d2f824081be0af06", "price_changes": [{"asset_id": "61753867760589263716170746998286765860517841601052294758213209498622686532394", "price": "0.02", "size": "5.82", "side": "BUY", "hash": "40e20eb2136bc88504d9d23220d6e6f4a3199270", "best_bid": "0.34", "best_ask": "0.39"}, {"asset_id": "27534087816472888388482777492068482333587764608177303542485554201592863278418", "price": "0.98", "size": "5.82", "side": "SELL", "hash": "6ea1e96080527160b576be835ff78a2bee76be65", "best_bid": "0.61", "best_ask": "0.66"}], "timestamp": "1769384977567", "event_type": "price_change"}}
{"_local_timestamp": "2026-01-25T23:49:38.102954+00:00", "data": {"market": "0x230607f610338c5d3a16bd50be25aa7ab60de534e39e8d5d699c5001c1e595b6", "price_changes": [{"asset_id": "97475721730557716007480813374619905620491367538874061914903518785234203691652", "price": "0.01", "size": "198.81", "side": "BUY", "hash": "6ef374ed2fd80f7dce00f3eb026de40a53b28b7a", "best_bid": "0.03", "best_ask": "0.97"}, {"asset_id": "54704412367939001823042963194576165230971916634123177373358746651929926233731", "price": "0.99", "size": "198.81", "side": "SELL", "hash": "262aac30de47707d6763ed38d53cff41d7386add", "best_bid": "0.03", "best_ask": "0.97"}], "timestamp": "1769384978015", "event_type": "price_change"}}
{"_local_timestamp": "2026-01-25T23:49:38.401269+00:00", "data": {"market": "0x13d3b44b12294fc57ae0bd7eaa03ce913c557cfd86a75bf9d2f824081be0af06", "price_changes": [{"asset_id": "61753867760589263716170746998286765860517841601052294758213209498622686532394", "price": "0.02", "size": "49.99", "side": "BUY", "hash": "e8fca385102e03f1e2a16b9d875dd11725ba11f1", "best_bid": "0.34", "best_ask": "0.39"}, {"asset_id": "27534087816472888388482777492068482333587764608177303542485554201592863278418", "price": "0.98", "size": "49.99", "side": "SELL", "hash": "409d5e8af4595257b5d6c25055167522566645d1", "best_bid": "0.61", "best_ask": "0.66"}], "timestamp": "1769384978328", "event_type": "price_change"}}
{"_local_timestamp": "2026-01-25T23:49:38.954142+00:00", "data": {"market": "0x230607f610338c5d3a16bd50be25aa7ab60de534e39e8d5d699c5001c1e595b6", "price_changes": [{"asset_id": "97475721730557716007480813374619905620491367538874061914903518785234203691652", "price": "0.01", "size": "208.36", "side": "BUY", "hash": "2cf5ea133d6a4b546319a846afdb8c8dc7da2daf", "best_bid": "0.03", "best_ask": "0.97"}, {"asset_id": "54704412367939001823042963194576165230971916634123177373358746651929926233731", "price": "0.99", "size": "208.36", "side": "SELL", "hash": "41eae370ec2aa7ebc7b1fdfe07eff7889f6b1587", "best_bid": "0.03", "best_ask": "0.97"}], "timestamp": "1769384978881", "event_type": "price_change"}}
{"_local_timestamp": "2026-01-25T23:49:43.013162+00:00", "data": {"market": "0x27ca72003935168fa5145df02d60bf388556aae40004bf8878ca07908679c90a", "price_changes": [{"asset_id": "39988103022538972074566738669948101601617351308210751441166542218243560439585", "price": "0.04", "size": "0", "side": "BUY", "hash": "85a39c9e5de66a736d3992a53f6858df66bab515", "best_bid": "0.05", "best_ask": "0.96"}, {"asset_id": "63076381782914098979289416106534140467979969107420034465007654424987247815951", "price": "0.96", "size": "0", "side": "SELL", "hash": "ef2a7f7f1920e7a57af3f0bdf08f552823ffe45e", "best_bid": "0.04", "best_ask": "0.95"}], "timestamp": "1769384982932", "event_type": "price_change"}}
{"_local_timestamp": "2026-01-25T23:49:46.662329+00:00", "data": {"market": "0x27ca72003935168fa5145df02d60bf388556aae40004bf8878ca07908679c90a", "price_changes": [{"asset_id": "39988103022538972074566738669948101601617351308210751441166542218243560439585", "price": "0.05", "size": "0", "side": "BUY", "hash": "a2618de19ffecbe53f5d6edacc1c41a316daa974", "best_bid": "0.02", "best_ask": "0.96"}, {"asset_id": "63076381782914098979289416106534140467979969107420034465007654424987247815951", "price": "0.95", "size": "0", "side": "SELL", "hash": "814bf1cfaa4b644b22bd34d374b5c4765fe5268e", "best_bid": "0.04", "best_ask": "0.98"}], "timestamp": "1769384986576", "event_type": "price_change"}}
{"_local_timestamp": "2026-01-25T23:49:46.866090+00:00", "data": {"market": "0x27ca72003935168fa5145df02d60bf388556aae40004bf8878ca07908679c90a", "price_changes": [{"asset_id": "39988103022538972074566738669948101601617351308210751441166542218243560439585", "price": "0.03", "size": "5.47", "side": "BUY", "hash": "e1ed36cedba7b80471d900c93f984c77c7771719", "best_bid": "0.03", "best_ask": "0.96"}, {"asset_id": "63076381782914098979289416106534140467979969107420034465007654424987247815951", "price": "0.97", "size": "5.47", "side": "SELL", "hash": "7c9b739f358d03fa79b63d7f010aed6245c41d3c", "best_bid": "0.04", "best_ask": "0.97"}], "timestamp": "1769384986792", "event_type": "price_change"}}
{"_local_timestamp": "2026-01-25T23:51:11.804020+00:00", "data": {"market": "0x230607f610338c5d3a16bd50be25aa7ab60de534e39e8d5d699c5001c1e595b6", "price_changes": [{"asset_id": "97475721730557716007480813374619905620491367538874061914903518785234203691652", "price": "0.04", "size": "29.99", "side": "BUY", "hash": "e7e48ddf60c366a5a5318b8ec90bf39f126869ab", "best_bid": "0.04", "best_ask": "0.97"}, {"asset_id": "54704412367939001823042963194576165230971916634123177373358746651929926233731", "price": "0.96", "size": "29.99", "side": "SELL", "hash": "47f88e9efd42a3225b7cd87e425eda2f109282da", "best_bid": "0.03", "best_ask": "0.96"}], "timestamp": "1769385071727", "event_type": "price_change"}}
{"_local_timestamp": "2026-01-25T23:51:11.804950+00:00", "data": {"market": "0xf03b83ca811da2bd2fc61195a40a4de255083315e40e91716f282e7f64a4681d", "price_changes": [{"asset_id": "99539110833954966113637313399179884315619862011580759033158888790135001736151", "price": "0.05", "size": "23.99", "side": "BUY", "hash": "644633f53918fb188f067c1c76ff36fae9ce7e59", "best_bid": "0.05", "best_ask": "0.97"}, {"asset_id": "12621476053563245870567256726900519038270292247970234647772913506087402134800", "price": "0.95", "size": "23.99", "side": "SELL", "hash": "634b007dbdf686b10092abca3eec205c3d9438ed", "best_bid": "0.03", "best_ask": "0.95"}], "timestamp": "1769385071727", "event_type": "price_change"}}
{"_local_timestamp": "2026-01-25T23:51:11.805467+00:00", "data": {"market": "0xf4f48f5b93ad07125c1487eca5c05632aa299a9ce8d547b3181906455b6ffc30", "price_changes": [{"asset_id": "52037538169528564564638458855755309591097235785433599464625697767410175594920", "price": "0.05", "size": "23.99", "side": "BUY", "hash": "813242c9c9bbce76d73b0aac1b4a0e972b559dc5", "best_bid": "0.05", "best_ask": "0.97"}, {"asset_id": "45351011268357454489754819517897238839825192588635910066796851405573865769474", "price": "0.95", "size": "23.99", "side": "SELL", "hash": "308de48e7e1da4fdaa22fc6afb1f968de2a627bd", "best_bid": "0.03", "best_ask": "0.95"}], "timestamp": "1769385071727", "event_type": "price_change"}}
{"_local_timestamp": "2026-01-25T23:51:14.062936+00:00", "data": {"market": "0x230607f610338c5d3a16bd50be25aa7ab60de534e39e8d5d699c5001c1e595b6", "price_changes": [{"asset_id": "97475721730557716007480813374619905620491367538874061914903518785234203691652", "price": "0.03", "size": "0", "side": "BUY", "hash": "d3b0fec6d64d6d59bc2ae9fd29a25b505d5e5b64", "best_bid": "0.04", "best_ask": "0.97"}, {"asset_id": "54704412367939001823042963194576165230971916634123177373358746651929926233731", "price": "0.97", "size": "0", "side": "SELL", "hash": "d8f5381471694bbe7c003618e2535c6c5705b106", "best_bid": "0.03", "best_ask": "0.96"}], "timestamp": "1769385073993", "event_type": "price_change"}}
{"_local_timestamp": "2026-01-25T23:51:14.066508+00:00", "data": {"market": "0xf4f48f5b93ad07125c1487eca5c05632aa299a9ce8d547b3181906455b6ffc30", "price_changes": [{"asset_id": "52037538169528564564638458855755309591097235785433599464625697767410175594920", "price": "0.04", "size": "0", "side": "BUY", "hash": "c09f86eb23656c4c70bfe5313a8b96c6d79ffced", "best_bid": "0.05", "best_ask": "0.97"}, {"asset_id": "45351011268357454489754819517897238839825192588635910066796851405573865769474", "price": "0.96", "size": "0", "side": "SELL", "hash": "a9c7062d8e7b55b58a3fb0c3e70c3b5ff709701d", "best_bid": "0.03", "best_ask": "0.95"}], "timestamp": "1769385073994", "event_type": "price_change"}}
{"_local_timestamp": "2026-01-25T23:51:14.067086+00:00", "data": {"market": "0xf03b83ca811da2bd2fc61195a40a4de255083315e40e91716f282e7f64a4681d", "price_changes": [{"asset_id": "99539110833954966113637313399179884315619862011580759033158888790135001736151", "price": "0.04", "size": "0", "side": "BUY", "hash": "20aee517c7cc97668693ae3b3b4a0ea78acfdfeb", "best_bid": "0.05", "best_ask": "0.97"}, {"asset_id": "12621476053563245870567256726900519038270292247970234647772913506087402134800", "price": "0.96", "size": "0", "side": "SELL", "hash": "0e98bf546d1809386f88a9eeaf6a583c0d1f7851", "best_bid": "0.03", "best_ask": "0.95"}], "timestamp": "1769385073994", "event_type": "price_change"}}
{"_local_timestamp": "2026-01-25T23:51:14.404370+00:00", "data": {"market": "0xf4f48f5b93ad07125c1487eca5c05632aa299a9ce8d547b3181906455b6ffc30", "price_changes": [{"asset_id": "52037538169528564564638458855755309591097235785433599464625697767410175594920", "price": "0.06", "size": "5.47", "side": "BUY", "hash": "b590192f846c000f79e13b410de2fd549f9ebd76", "best_bid": "0.06", "best_ask": "0.97"}, {"asset_id": "45351011268357454489754819517897238839825192588635910066796851405573865769474", "price": "0.94", "size": "5.47", "side": "SELL", "hash": "67d531d884a75a958f850c0c45009e608cf90808", "best_bid": "0.03", "best_ask": "0.94"}], "timestamp": "1769385074331", "event_type": "price_change"}}
{"_local_timestamp": "2026-01-25T23:51:14.404958+00:00", "data": {"market": "0xf03b83ca811da2bd2fc61195a40a4de255083315e40e91716f282e7f64a4681d", "price_changes": [{"asset_id": "99539110833954966113637313399179884315619862011580759033158888790135001736151", "price": "0.06", "size": "5.47", "side": "BUY", "hash": "05a655990ec047caf6fc04c769034a511ddd4b3f", "best_bid": "0.06", "best_ask": "0.97"}, {"asset_id": "12621476053563245870567256726900519038270292247970234647772913506087402134800", "price": "0.94", "size": "5.47", "side": "SELL", "hash": "ab834161b724a3b6151f11bcaac5e204f19b8b81", "best_bid": "0.03", "best_ask": "0.94"}], "timestamp": "1769385074331", "event_type": "price_change"}}
{"_local_timestamp": "2026-01-25T23:51:14.405431+00:00", "data": {"market": "0x230607f610338c5d3a16bd50be25aa7ab60de534e39e8d5d699c5001c1e595b6", "price_changes": [{"asset_id": "97475721730557716007480813374619905620491367538874061914903518785234203691652", "price": "0.05", "size": "5.47", "side": "BUY", "hash": "8a791f3e4161ec73016d5a7fae852668f0d2f5e2", "best_bid": "0.05", "best_ask": "0.97"}, {"asset_id": "54704412367939001823042963194576165230971916634123177373358746651929926233731", "price": "0.95", "size": "5.47", "side": "SELL", "hash": "7e13a086816f5bdcc437224957d37029f3f7d38f", "best_bid": "0.03", "best_ask": "0.95"}], "timestamp": "1769385074331", "event_type": "price_change"}}
