{"_local_timestamp": "2026-01-25T23:34:27.919859+00:00", "data": [{"market": "0xa8e6996b216b0f053c999cdd14ebd26b9c0f21f2d4be2285bf0f263a9e249387", "asset_id": "87638910251680107180976444182220421878711803379550436919896332953657681609792", "timestamp": "1769383983182", "hash": "ca9472011cd1d1388cf2cc1fd55375b0da092399", "bids": [{"price": "0.01", "size": "255.04"}, {"price": "0.02", "size": "144.48"}, {"price": "0.03", "size": "18.99"}, {"price": "0.04", "size": "29.99"}], "asks": [{"price": "0.99", "size": "256.36"}, {"price": "0.98", "size": "123.03"}, {"price": "0.97", "size": "20.86"}, {"price": "0.95", "size": "23.99"}, {"price": "0.94", "size": "5.47"}], "event_type": "book", "last_trade_price": ""}, {"market": "0xa8e6996b216b0f053c999cdd14ebd26b9c0f21f2d4be2285bf0f263a9e249387", "asset_id": "79548151070664457970653465049625822055893281924971573086501134120908067838792", "timestamp": "1769383983182", "hash": "05105e5ec144d04097fcfcb1430b0f21878ab229", "bids": [{"price": "0.01", "size": "256.36"}, {"price": "0.02", "size": "123.03"}, {"price": "0.03", "size": "20.86"}, {"price": "0.05", "size": "23.99"}, {"price": "0.06", "size": "5.47"}], "asks": [{"price": "0.99", "size": "255.04"}, {"price": "0.98", "size": "144.48"}, {"price": "0.97", "size": "18.99"}, {"price": "0.96", "size": "29.99"}], "event_type": "book", "last_trade_price": ""}, {"market": "0xe3f6807770d960b407329b12b5e890e1d665fc042050c4034b0f98ac86f348e6", "asset_id": "5184462202147532513580739399944335715356799440407775484730001589320402350543", "timestamp": "1769383983182", "hash": "150e45b89fed00f106e1ad07518fdb4c1993dd39", "bids": [{"price": "0.01", "size": "201.11"}, {"price": "0.02", "size": "114.03"}, {"price": "0.03", "size": "21.61"}, {"price": "0.05", "size": "23.99"}, {"price": "0.06", "size": "5.47"}], "asks": [{"price": "0.99", "size": "202.04"}, {"price": "0.98", "size": "117.48"}, {"price": "0.97", "size": "18.99"}, {"price": "0.96", "size": "29.99"}], "event_type": "book", "last_trade_price": ""}, {"market": "0x9460eee8f4eb73bfe88ddc0e3dc51670102e8687a74307d5d529003cd9f911cc", "asset_id": "90974674996325816587803977618907300151709708200404217989605632387971109382242", "timestamp": "1769383983181", "hash": "b43fbbdf04d050d47a8ed8fb7f94b665698ffb10", "bids": [{"price": "0.01", "size": "202.04"}, {"price": "0.02", "size": "117.48"}, {"price": "0.03", "size": "18.99"}, {"price": "0.04", "size": "29.99"}], "asks": [{"price": "0.99", "size": "203.64"}, {"price": "0.98", "size": "97.03"}, {"price": "0.97", "size": "20.76"}, {"price": "0.95", "size": "23.99"}, {"price": "0.94", "size": "5.47"}], "event_type": "book", "last_trade_price": ""}, {"market": "0xa46df1799c4af6da9ec7183c731200023d64356f7d1a5974219f13f394a1ec1c", "asset_id": "35038303114312465943420184667183543641707720914936739151125733005465499923666", "timestamp": "1769379339533", "hash": "83058a55431b8dc9df734cab149f6ed7a93958a3", "bids": [{"price": "0.01", "size": "191.4"}, {"price": "0.02", "size": "90"}, {"price": "0.03", "size": "29.53"}, {"price": "0.34", "size": "10"}, {"price": "0.35", "size": "50"}], "asks": [{"price": "0.99", "size": "191"}, {"price": "0.98", "size": "90"}, {"price": "0.97", "size": "29.66"}, {"price": "0.61", "size": "50"}], "event_type": "book", "last_trade_price": ""}, {"market": "0x9460eee8f4eb73bfe88ddc0e3dc51670102e8687a74307d5d529003cd9f911cc", "asset_id": "73111694502202039458765701041717258004804405380693116794104644278670571271514", "timestamp": "1769383983181", "hash": "b49d236874b7596aa3885f1b3ad3965ead06e2bf", "bids": [{"price": "0.01", "size": "203.64"}, {"price": "0.02", "size": "97.03"}, {"price": "0.03", "size": "20.76"}, {"price": "0.05", "size": "23.99"}, {"price": "0.06", "size": "5.47"}], "asks": [{"price": "0.99", "size": "202.04"}, {"price": "0.98", "size": "117.48"}, {"price": "0.97", "size": "18.99"}, {"price": "0.96", "size": "29.99"}], "event_type": "book", "last_trade_price": ""}, {"market": "0x5f8e2e997dfed26ce4d4150995a9be18770bf6534d868dac53078912e3cd88f5", "asset_id": "17664961292382291288936637834868324273780812098632528035707240895282525127009", "timestamp": "1769383983182", "hash": "8bbcbe81807caf2244c4d7fdda334feb0a5c769a", "bids": [{"price": "0.01", "size": "203.99"}, {"price": "0.02", "size": "97.03"}, {"price": "0.03", "size": "20.65"}, {"price": "0.05", "size": "23.99"}, {"price": "0.06", "size": "5.47"}], "asks": [{"price": "0.99", "size": "202.04"}, {"price": "0.98", "size": "117.48"}, {"price": "0.97", "size": "18.99"}, {"price": "0.96", "size": "29.99"}], "event_type": "book", "last_trade_price": ""}, {"market": "0xa46df1799c4af6da9ec7183c731200023d64356f7d1a5974219f13f394a1ec1c", "asset_id": "26591473454881571586711746869026095273809392017256748080505224605205787862024", "timestamp": "1769379339533", "hash": "e01aa9e2bf6639a30d8b600dc970eb0500d00c26", "bids": [{"price": "0.01", "size": "191"}, {"price": "0.02", "size": "90"}, {"price": "0.03", "size": "29.66"}, {"price": "0.39", "size": "50"}], "asks": [{"price": "0.99", "size": "191.4"}, {"price": "0.98", "size": "90"}, {"price": "0.97", "size": "29.53"}, {"price": "0.66", "size": "10"}, {"price": "0.65", "size": "50"}], "event_type": "book", "last_trade_price": ""}, {"market": "0x5f8e2e997dfed26ce4d4150995a9be18770bf6534d868dac53078912e3cd88f5", "asset_id": "111286054640907956490772998022079647475566330126206509656788553491340216917730", "timestamp": "1769383983182", "hash": "4522a5b32243f85ec0bdee3a4335759165ae875f", "bids": [{"price": "0.01", "size": "202.04"}, {"price": "0.02", "size": "117.48"}, {"price": "0.03", "size": "18.99"}, {"price": "0.04", "size": "29.99"}], "asks": [{"price": "0.99", "size": "203.99"}, {"price": "0.98", "size": "97.03"}, {"price": "0.97", "size": "20.65"}, {"price": "0.95", "size": "23.99"}, {"price": "0.94", "size": "5.47"}], "event_type": "book", "last_trade_price": ""}, {"market": "0xe3f6807770d960b407329b12b5e890e1d665fc042050c4034b0f98ac86f348e6", "asset_id": "73398331601879459556878408255341546321967259114676130015041957881093323306597", "timestamp": "1769383983182", "hash": "b1fea29c8ad64adf0f6a177b6164452ad639b180", "bids": [{"price": "0.01", "size": "202.04"}, {"price": "0.02", "size": "117.48"}, {"price": "0.03", "size": "18.99"}, {"price": "0.04", "size": "29.99"}], "asks": [{"price": "0.99", "size": "201.11"}, {"price": "0.98", "size": "114.03"}, {"price": "0.97", "size": "21.61"}, {"price": "0.95", "size": "23.99"}, {"price": "0.94", "size": "5.47"}], "event_type": "book", "last_trade_price": ""}]}
{"_local_timestamp": "2026-01-25T23:34:34.337210+00:00", "data": {"market": "0xa8e6996b216b0f053c999cdd14ebd26b9c0f21f2d4be2285bf0f263a9e249387", "price_changes": [{"asset_id": "79548151070664457970653465049625822055893281924971573086501134120908067838792", "price": "0.05", "size": "0", "side": "BUY", "hash": "56332645c02df90084c6adb4aca9857c1356d137", "best_bid": "0.06", "best_ask": "0.96"}, {"asset_id": "87638910251680107180976444182220421878711803379550436919896332953657681609792", "price": "0.95", "size": "0", "side": "SELL", "hash": "e543d33be04582ba4ff70df2f221534afe20a3c2", "best_bid": "0.04", "best_ask": "0.94"}], "timestamp": "1769384074075", "event_type": "price_change"}}
{"_local_timestamp": "2026-01-25T23:34:34.341256+00:00", "data": {"market": "0xe3f6807770d960b407329b12b5e890e1d665fc042050c4034b0f98ac86f348e6", "price_changes": [{"asset_id": "5184462202147532513580739399944335715356799440407775484730001589320402350543", "price": "0.05", "size": "0", "side": "BUY", "hash": "b66fc9961201b2ed55ea64666de2cec8a771f410", "best_bid": "0.06", "best_ask": "0.96"}, {"asset_id": "73398331601879459556878408255341546321967259114676130015041957881093323306597", "price": "0.95", "size": "0", "side": "SELL", "hash": "f158ab620c8a6274ed9c34ce4494c02fac17c67a", "best_bid": "0.04", "best_ask": "0.94"}], "timestamp": "1769384074075", "event_type": "price_change"}}
{"_local_timestamp": "2026-01-25T23:34:34.390911+00:00", "data": {"market": "0x9460eee8f4eb73bfe88ddc0e3dc51670102e8687a74307d5d529003cd9f911cc", "price_changes": [{"asset_id": "73111694502202039458765701041717258004804405380693116794104644278670571271514", "price": "0.05", "size": "0", "side": "BUY", "hash": "9533be75b03bfb3ee5703284ab43a047cfb96f44", "best_bid": "0.06", "best_ask": "0.96"}, {"asset_id": "90974674996325816587803977618907300151709708200404217989605632387971109382242", "price": "0.95", "size": "0", "side": "SELL", "hash": "d8282f351462ea38270eab03755be60ac09a6188", "best_bid": "0.04", "best_ask": "0.94"}], "timestamp": "1769384074174", "event_type": "price_change"}}
{"_local_timestamp": "2026-01-25T23:34:34.610171+00:00", "data": {"market": "0x5f8e2e997dfed26ce4d4150995a9be18770bf6534d868dac53078912e3cd88f5", "price_changes": [{"asset_id": "17664961292382291288936637834868324273780812098632528035707240895282525127009", "price": "0.05", "size": "0", "side": "BUY", "hash": "92e6c7849a377ace4eabeb93533c19096b74f000", "best_bid": "0.06", "best_ask": "0.96"}, {"asset_id": "111286054640907956490772998022079647475566330126206509656788553491340216917730", "price": "0.95", "size": "0", "side": "SELL", "hash": "393fcacfe911198924839f16712cbdbefaea11f8", "best_bid": "0.04", "best_ask": "0.94"}], "timestamp": "1769384074376", "event_type": "price_change"}}
{"_local_timestamp": "2026-01-25T23:34:35.334118+00:00", "data": {"market": "0x9460eee8f4eb73bfe88ddc0e3dc51670102e8687a74307d5d529003cd9f911cc", "price_changes": [{"asset_id": "73111694502202039458765701041717258004804405380693116794104644278670571271514", "price": "0.06", "size": "0", "side": "BUY", "hash": "b7bbe4e1b6e67cbdf59dd990402d5dfd13fc0b23", "best_bid": "0.03", "best_ask": "0.96"}, {"asset_id": "90974674996325816587803977618907300151709708200404217989605632387971109382242", "price": "0.94", "size": "0", "side": "SELL", "hash": "5c6f5c0ff5c99cc0a4d080b2787ab7ae46597da4", "best_bid": "0.04", "best_ask": "0.97"}], "timestamp": "1769384075094", "event_type": "price_change"}}
{"_local_timestamp": "2026-01-25T23:34:35.347722+00:00", "data": {"market": "0xe3f6807770d960b407329b12b5e890e1d665fc042050c4034b0f98ac86f348e6", "price_changes": [{"asset_id": "5184462202147532513580739399944335715356799440407775484730001589320402350543", "price": "0.06", "size": "0", "side": "BUY", "hash": "0c4464a042f0d25668f8c42a1d7269ca1b46ae91", "best_bid": "0.03", "best_ask": "0.96"}, {"asset_id": "73398331601879459556878408255341546321967259114676130015041957881093323306597", "price": "0.94", "size": "0", "side": "SELL", "hash": "a777c7e4e11b45e4e38e2322930952548391e9b2", "best_bid": "0.04", "best_ask": "0.97"}], "timestamp": "1769384075094", "event_type": "price_change"}}
{"_local_timestamp": "2026-01-25T23:34:35.349395+00:00", "data": {"market": "0x5f8e2e997dfed26ce4d4150995a9be18770bf6534d868dac53078912e3cd88f5", "price_changes": [{"asset_id": "17664961292382291288936637834868324273780812098632528035707240895282525127009", "price": "0.06", "size": "0", "side": "BUY", "hash": "1df937c02e377712240274e55565484420833f9d", "best_bid": "0.03", "best_ask": "0.96"}, {"asset_id": "111286054640907956490772998022079647475566330126206509656788553491340216917730", "price": "0.94", "size": "0", "side": "SELL", "hash": "97870e369494f7b1834970bbc831d11abac0f23a", "best_bid": "0.04", "best_ask": "0.97"}], "timestamp": "1769384075094", "event_type": "price_change"}}
{"_local_timestamp": "2026-01-25T23:34:35.354485+00:00", "data": {"market": "0xa8e6996b216b0f053c999cdd14ebd26b9c0f21f2d4be2285bf0f263a9e249387", "price_changes": [{"asset_id": "79548151070664457970653465049625822055893281924971573086501134120908067838792", "price": "0.06", "size": "0", "side": "BUY", "hash": "99c37cdfb017c9a162ff212c3fc72ace02782b34", "best_bid": "0.03", "best_ask": "0.96"}, {"asset_id": "87638910251680107180976444182220421878711803379550436919896332953657681609792", "price": "0.94", "size": "0", "side": "SELL", "hash": "30ff23b73ec43ab530ea9ff9e46dca30b3c28fcd", "best_bid": "0.04", "best_ask": "0.97"}], "timestamp": "1769384075094", "event_type": "price_change"}}
{"_local_timestamp": "2026-01-25T23:34:35.763126+00:00", "data": {"market": "0xa8e6996b216b0f053c999cdd14ebd26b9c0f21f2d4be2285bf0f263a9e249387", "price_changes": [{"asset_id": "79548151070664457970653465049625822055893281924971573086501134120908067838792", "price": "0.04", "size": "5.47", "side": "BUY", "hash": "bcc83919e7633385d7d63999f32c8de3263e0151", "best_bid": "0.04", "best_ask": "0.96"}, {"asset_id": "87638910251680107180976444182220421878711803379550436919896332953657681609792", "price": "0.96", "size": "5.47", "side": "SELL", "hash": "6481c6a6db51fcbcbb60c9add043be5ffce0fe5d", "best_bid": "0.04", "best_ask": "0.96"}], "timestamp": "1769384075530", "event_type": "price_change"}}
{"_local_timestamp": "2026-01-25T23:34:35.765316+00:00", "data": {"market": "0xe3f6807770d960b407329b12b5e890e1d665fc042050c4034b0f98ac86f348e6", "price_changes": [{"asset_id": "5184462202147532513580739399944335715356799440407775484730001589320402350543", "price": "0.04", "size": "5.47", "side": "BUY", "hash": "de8b03791e3244c00c9247cfbc68c823ec07099d", "best_bid": "0.04", "best_ask": "0.96"}, {"asset_id": "73398331601879459556878408255341546321967259114676130015041957881093323306597", "price": "0.96", "size": "5.47", "side": "SELL", "hash": "6b80b53065ff699ef17b1b9836aa64cbc30a9ce2", "best_bid": "0.04", "best_ask": "0.96"}], "timestamp": "1769384075530", "event_type": "price_change"}}
{"_local_timestamp": "2026-01-25T23:34:35.765684+00:00", "data": {"market": "0x5f8e2e997dfed26ce4d4150995a9be18770bf6534d868dac53078912e3cd88f5", "price_changes": [{"asset_id": "17664961292382291288936637834868324273780812098632528035707240895282525127009", "price": "0.04", "size": "5.47", "side": "BUY", "hash": "f448f88a6edf1524daf768457da15bea8ee2d06d", "best_bid": "0.04", "best_ask": "0.96"}, {"asset_id": "111286054640907956490772998022079647475566330126206509656788553491340216917730", "price": "0.96", "size": "5.47", "side": "SELL", "hash": "1f3f34eb893659489fd48a7c6cfd85a37aaa9afb", "best_bid": "0.04", "best_ask": "0.96"}], "timestamp": "1769384075531", "event_type": "price_change"}}
{"_local_timestamp": "2026-01-25T23:34:35.766043+00:00", "data": {"market": "0x9460eee8f4eb73bfe88ddc0e3dc51670102e8687a74307d5d529003cd9f911cc", "price_changes": [{"asset_id": "73111694502202039458765701041717258004804405380693116794104644278670571271514", "price": "0.04", "size": "5.47", "side": "BUY", "hash": "66b417d05f968ea214b2c7114fc52aeb6468876d", "best_bid": "0.04", "best_ask": "0.96"}, {"asset_id": "90974674996325816587803977618907300151709708200404217989605632387971109382242", "price": "0.96", "size": "5.47", "side": "SELL", "hash": "05ec090aece072993c6114db0cb6bcfe2c7e1bb1", "best_bid": "0.04", "best_ask": "0.96"}], "timestamp": "1769384075530", "event_type": "price_change"}}
{"_local_timestamp": "2026-01-25T23:34:55.810068+00:00", "data": {"market": "0xe3f6807770d960b407329b12b5e890e1d665fc042050c4034b0f98ac86f348e6", "price_changes": [{"asset_id": "5184462202147532513580739399944335715356799440407775484730001589320402350543", "price": "0.03", "size": "10.35", "side": "BUY", "hash": "4de1d7dea1e668c9daf10780b5cc52ae57a8dba9", "best_bid": "0.04", "best_ask": "0.96"}, {"asset_id": "73398331601879459556878408255341546321967259114676130015041957881093323306597", "price": "0.97", "size": "10.35", "side": "SELL", "hash": "57875271d0675891987eb609422ee5811fbbc73f", "best_bid": "0.04", "best_ask": "0.96"}], "timestamp": "1769384095743", "event_type": "price_change"}}
{"_local_timestamp": "2026-01-25T23:34:56.153917+00:00", "data": {"market": "0xe3f6807770d960b407329b12b5e890e1d665fc042050c4034b0f98ac86f348e6", "price_changes": [{"asset_id": "5184462202147532513580739399944335715356799440407775484730001589320402350543", "price": "0.03", "size": "21.61", "side": "BUY", "hash": "ef582bda9402b07c5c8828a0d8887c768ab787cb", "best_bid": "0.04", "best_ask": "0.96"}, {"asset_id": "73398331601879459556878408255341546321967259114676130015041957881093323306597", "price": "0.97", "size": "21.61", "side": "SELL", "hash": "95fb670c54102bc708c466018142165aeda36a6c", "best_bid": "0.04", "best_ask": "0.96"}], "timestamp": "1769384096015", "event_type": "price_change"}}
{"_local_timestamp": "2026-01-25T23:36:06.439894+00:00", "data": {"market": "0x9460eee8f4eb73bfe88ddc0e3dc51670102e8687a74307d5d529003cd9f911cc", "price_changes": [{"asset_id": "73111694502202039458765701041717258004804405380693116794104644278670571271514", "price": "0.05", "size": "23.99", "side": "BUY", "hash": "603485f68404dd13ec359a22e5522721b92c5f9c", "best_bid": "0.05", "best_ask": "0.96"}, {"asset_id": "90974674996325816587803977618907300151709708200404217989605632387971109382242", "price": "0.95", "size": "23.99", "side": "SELL", "hash": "7ab7f12eb29a8156d22efcdebd63f504ceafc2b9", "best_bid": "0.04", "best_ask": "0.95"}], "timestamp": "1769384166370", "event_type": "price_change"}}
{"_local_timestamp": "2026-01-25T23:36:06.441017+00:00", "data": {"market": "0x5f8e2e997dfed26ce4d4150995a9be18770bf6534d868dac53078912e3cd88f5", "price_changes": [{"asset_id": "17664961292382291288936637834868324273780812098632528035707240895282525127009", "price": "0.05", "size": "23.99", "side": "BUY", "hash": "52fb00939ffff82ed882e301495f47d98873189a", "best_bid": "0.05", "best_ask": "0.96"}, {"asset_id": "111286054640907956490772998022079647475566330126206509656788553491340216917730", "price": "0.95", "size": "23.99", "side": "SELL", "hash": "5ccf16841b95cbb0b596d482f1eca8a4431cb042", "best_bid": "0.04", "best_ask": "0.95"}], "timestamp": "1769384166370", "event_type": "price_change"}}
{"_local_timestamp": "2026-01-25T23:36:06.441314+00:00", "data": {"market": "0xa8e6996b216b0f053c999cdd14ebd26b9c0f21f2d4be2285bf0f263a9e249387", "price_changes": [{"asset_id": "79548151070664457970653465049625822055893281924971573086501134120908067838792", "price": "0.05", "size": "23.99", "side": "BUY", "hash": "17fd6be40336f10d7bd0d6480c1ef25a93a3706a", "best_bid": "0.05", "best_ask": "0.96"}, {"asset_id": "87638910251680107180976444182220421878711803379550436919896332953657681609792", "price": "0.95", "size": "23.99", "side": "SELL", "hash": "7e67cd8df1cc610fdffae2f670f5bf2b606b8d6a", "best_bid": "0.04", "best_ask": "0.95"}], "timestamp": "1769384166370", "event_type": "price_change"}}
{"_local_timestamp": "2026-01-25T23:36:06.714798+00:00", "data": {"market": "0xe3f6807770d960b407329b12b5e890e1d665fc042050c4034b0f98ac86f348e6", "price_changes": [{"asset_id": "5184462202147532513580739399944335715356799440407775484730001589320402350543", "price": "0.05", "size": "23.99", "side": "BUY", "hash": "b8f0ba320e6bd84cb88ee296d54e8c187fa869db", "best_bid": "0.05", "best_ask": "0.96"}, {"asset_id": "73398331601879459556878408255341546321967259114676130015041957881093323306597", "price": "0.95", "size": "23.99", "side": "SELL", "hash": "b0d4a27b75c8ff49af4640f3f1d53c65ee1f1366", "best_bid": "0.04", "best_ask": "0.95"}], "timestamp": "1769384166370", "event_type": "price_change"}}
{"_local_timestamp": "2026-01-25T23:36:09.242669+00:00", "data": {"market": "0xe3f6807770d960b407329b12b5e890e1d665fc042050c4034b0f98ac86f348e6", "price_changes": [{"asset_id": "5184462202147532513580739399944335715356799440407775484730001589320402350543", "price": "0.04", "size": "0", "side": "BUY", "hash": "28605a35427ec72b935892f8dc2e07167320556a", "best_bid": "0.05", "best_ask": "0.96"}, {"asset_id": "73398331601879459556878408255341546321967259114676130015041957881093323306597", "price": "0.96", "size": "0", "side": "SELL", "hash": "1213f8b3ada5c84706a734b9bbad990670810481", "best_bid": "0.04", "best_ask": "0.95"}], "timestamp": "1769384169171", "event_type": "price_change"}}
{"_local_timestamp": "2026-01-25T23:36:09.252236+00:00", "data": {"market": "0x5f8e2e997dfed26ce4d4150995a9be18770bf6534d868dac53078912e3cd88f5", "price_changes": [{"asset_id": "17664961292382291288936637834868324273780812098632528035707240895282525127009", "price": "0.04", "size": "0", "side": "BUY", "hash": "1e6687380c5df637c06f17d58cf37b4dd8302cb3", "best_bid": "0.05", "best_ask": "0.96"}, {"asset_id": "111286054640907956490772998022079647475566330126206509656788553491340216917730", "price": "0.96", "size": "0", "side": "SELL", "hash": "ee3de1bd07e8d9e4c1ed7f720b8722189ccc2241", "best_bid": "0.04", "best_ask": "0.95"}], "timestamp": "1769384169172", "event_type": "price_change"}}
{"_local_timestamp": "2026-01-25T23:36:09.253033+00:00", "data": {"market": "0xa8e6996b216b0f053c999cdd14ebd26b9c0f21f2d4be2285bf0f263a9e249387", "price_changes": [{"asset_id": "79548151070664457970653465049625822055893281924971573086501134120908067838792", "price": "0.04", "size": "0", "side": "BUY", "hash": "042c2fffaae8517b7cc7f750c8f21c5c48edef06", "best_bid": "0.05", "best_ask": "0.96"}, {"asset_id": "87638910251680107180976444182220421878711803379550436919896332953657681609792", "price": "0.96", "size": "0", "side": "SELL", "hash": "8d34040be378af9cfe557a1c15edd44d22b9841a", "best_bid": "0.04", "best_ask": "0.95"}], "timestamp": "1769384169172", "event_type": "price_change"}}
{"_local_timestamp": "2026-01-25T23:36:09.256867+00:00", "data": {"market": "0x9460eee8f4eb73bfe88ddc0e3dc51670102e8687a74307d5d529003cd9f911cc", "price_changes": [{"asset_id": "73111694502202039458765701041717258004804405380693116794104644278670571271514", "price": "0.04", "size": "0", "side": "BUY", "hash": "c86d58aeb1f7e03127cbdd5c957933478720f05e", "best_bid": "0.05", "best_ask": "0.96"}, {"asset_id": "90974674996325816587803977618907300151709708200404217989605632387971109382242", "price": "0.96", "size": "0", "side": "SELL", "hash": "c1d67af998707dc86dc73f249e8b1c58e3836926", "best_bid": "0.04", "best_ask": "0.95"}], "timestamp": "1769384169172", "event_type": "price_change"}}
{"_local_timestamp": "2026-01-25T23:36:09.766814+00:00", "data": {"market": "0x5f8e2e997dfed26ce4d4150995a9be18770bf6534d868dac53078912e3cd88f5", "price_changes": [{"asset_id": "17664961292382291288936637834868324273780812098632528035707240895282525127009", "price": "0.06", "size": "5.47", "side": "BUY", "hash": "05afb0ae161f17e89f5a76e88cc92ff8c430bcf9", "best_bid": "0.06", "best_ask": "0.96"}, {"asset_id": "111286054640907956490772998022079647475566330126206509656788553491340216917730", "price": "0.94", "size": "5.47", "side": "SELL", "hash": "362fd082236f96c69b9d71ac631919cdbb7c5a00", "best_bid": "0.04", "best_ask": "0.94"}], "timestamp": "1769384169699", "event_type": "price_change"}}
{"_local_timestamp": "2026-01-25T23:36:09.767211+00:00", "data": {"market": "0xe3f6807770d960b407329b12b5e890e1d665fc042050c4034b0f98ac86f348e6", "price_changes": [{"asset_id": "5184462202147532513580739399944335715356799440407775484730001589320402350543", "price": "0.06", "size": "5.47", "side": "BUY", "hash": "ac7cb16995756d53d7204d4a6c629aa4a03195cc", "best_bid": "0.06", "best_ask": "0.96"}, {"asset_id": "73398331601879459556878408255341546321967259114676130015041957881093323306597", "price": "0.94", "size": "5.47", "side": "SELL", "hash": "ee0dc2938b5f2494fb0cec0ea7f0ef38715c959a", "best_bid": "0.04", "best_ask": "0.94"}], "timestamp": "1769384169699", "event_type": "price_change"}}
{"_local_timestamp": "2026-01-25T23:36:09.767535+00:00", "data": {"market": "0xa8e6996b216b0f053c999cdd14ebd26b9c0f21f2d4be2285bf0f263a9e249387", "price_changes": [{"asset_id": "79548151070664457970653465049625822055893281924971573086501134120908067838792", "price": "0.06", "size": "5.47", "side": "BUY", "hash": "35d18271cd9151b23da0848eb975d06cec7eeca8", "best_bid": "0.06", "best_ask": "0.96"}, {"asset_id": "87638910251680107180976444182220421878711803379550436919896332953657681609792", "price": "0.94", "size": "5.47", "side": "SELL", "hash": "eec8b670279fb8b59d62820f6dd2e6653fb15db4", "best_bid": "0.04", "best_ask": "0.94"}], "timestamp": "1769384169699", "event_type": "price_change"}}
{"_local_timestamp": "2026-01-25T23:36:09.767922+00:00", "data": {"market": "0x9460eee8f4eb73bfe88ddc0e3dc51670102e8687a74307d5d529003cd9f911cc", "price_changes": [{"asset_id": "73111694502202039458765701041717258004804405380693116794104644278670571271514", "price": "0.06", "size": "5.47", "side": "BUY", "hash": "4617e9028942b4df92b47ff857ac07436de2a68b", "best_bid": "0.06", "best_ask": "0.96"}, {"asset_id": "90974674996325816587803977618907300151709708200404217989605632387971109382242", "price": "0.94", "size": "5.47", "side": "SELL", "hash": "ffc4d8d6f0522945133fcbbb3db15e2fedfeff99", "best_bid": "0.04", "best_ask": "0.94"}], "timestamp": "1769384169699", "event_type": "price_change"}}
{"_local_timestamp": "2026-01-25T23:37:43.935922+00:00", "data": {"market": "0xe3f6807770d960b407329b12b5e890e1d665fc042050c4034b0f98ac86f348e6", "price_changes": [{"asset_id": "5184462202147532513580739399944335715356799440407775484730001589320402350543", "price": "0.05", "size": "0", "side": "BUY", "hash": "d4773b32204d618011de111e6ef531387e15ea7b", "best_bid": "0.06", "best_ask": "0.96"}, {"asset_id": "73398331601879459556878408255341546321967259114676130015041957881093323306597", "price": "0.95", "size": "0", "side": "SELL", "hash": "039ba6c2d793d24f839a2a4d759ee53c1d6cb4d8", "best_bid": "0.04", "best_ask": "0.94"}], "timestamp": "1769384263863", "event_type": "price_change"}}
{"_local_timestamp": "2026-01-25T23:37:43.936734+00:00", "data": {"market": "0x5f8e2e997dfed26ce4d4150995a9be18770bf6534d868dac53078912e3cd88f5", "price_changes": [{"asset_id": "17664961292382291288936637834868324273780812098632528035707240895282525127009", "price": "0.05", "size": "0", "side": "BUY", "hash": "1cf45af93a0b00e6916011e23ebbccf4ee498dbb", "best_bid": "0.06", "best_ask": "0.96"}, {"asset_id": "111286054640907956490772998022079647475566330126206509656788553491340216917730", "price": "0.95", "size": "0", "side": "SELL", "hash": "499eac99998364b437cf2da323221a6aad93d6b3", "best_bid": "0.04", "best_ask": "0.94"}], "timestamp": "1769384263863", "event_type": "price_change"}}
{"_local_timestamp": "2026-01-25T23:37:43.937109+00:00", "data": {"market": "0xa8e6996b216b0f053c999cdd14ebd26b9c0f21f2d4be2285bf0f263a9e249387", "price_changes": [{"asset_id": "79548151070664457970653465049625822055893281924971573086501134120908067838792", "price": "0.05", "size": "0", "side": "BUY", "hash": "e58b579532ff498c8124334781f808acd294ddd9", "best_bid": "0.06", "best_ask": "0.96"}, {"asset_id": "87638910251680107180976444182220421878711803379550436919896332953657681609792", "price": "0.95", "size": "0", "side": "SELL", "hash": "51d8fb2252f3e368629c4d2063919e0c7257e45e", "best_bid": "0.04", "best_ask": "0.94"}], "timestamp": "1769384263863", "event_type": "price_change"}}
{"_local_timestamp": "2026-01-25T23:37:44.150776+00:00", "data": {"market": "0x9460eee8f4eb73bfe88ddc0e3dc51670102e8687a74307d5d529003cd9f911cc", "price_changes": [{"asset_id": "73111694502202039458765701041717258004804405380693116794104644278670571271514", "price": "0.05", "size": "0", "side": "BUY", "hash": "6ae78ee080a6a6005d1f763045b7e7622cb87d9b", "best_bid": "0.06", "best_ask": "0.96"}, {"asset_id": "90974674996325816587803977618907300151709708200404217989605632387971109382242", "price": "0.95", "size": "0", "side": "SELL", "hash": "b54644af4e8b58c928d169a35bb1fe96f6deccf4", "best_bid": "0.04", "best_ask": "0.94"}], "timestamp": "1769384264060", "event_type": "price_change"}}
{"_local_timestamp": "2026-01-25T23:37:46.309399+00:00", "data": {"market": "0x9460eee8f4eb73bfe88ddc0e3dc51670102e8687a74307d5d529003cd9f911cc", "price_changes": [{"asset_id": "73111694502202039458765701041717258004804405380693116794104644278670571271514", "price": "0.06", "size": "0", "side": "BUY", "hash": "2d881433772b106248c2df9544f789f2610455f8", "best_bid": "0.03", "best_ask": "0.96"}, {"asset_id": "90974674996325816587803977618907300151709708200404217989605632387971109382242", "price": "0.94", "size": "0", "side": "SELL", "hash": "10de25def955c38d5af3d67043d045a734ec1fcc", "best_bid": "0.04", "best_ask": "0.97"}], "timestamp": "1769384266173", "event_type": "price_change"}}
{"_local_timestamp": "2026-01-25T23:37:46.312335+00:00", "data": {"market": "0xe3f6807770d960b407329b12b5e890e1d665fc042050c4034b0f98ac86f348e6", "price_changes": [{"asset_id": "5184462202147532513580739399944335715356799440407775484730001589320402350543", "price": "0.06", "size": "0", "side": "BUY", "hash": "aa571834c48c22cae66703257776d76e6688b9c1", "best_bid": "0.03", "best_ask": "0.96"}, {"asset_id": "73398331601879459556878408255341546321967259114676130015041957881093323306597", "price": "0.94", "size": "0", "side": "SELL", "hash": "4560a004c8330f243d097930dc90b588477c6614", "best_bid": "0.04", "best_ask": "0.97"}], "timestamp": "1769384266173", "event_type": "price_change"}}
{"_local_timestamp": "2026-01-25T23:37:46.314862+00:00", "data": {"market": "0x5f8e2e997dfed26ce4d4150995a9be18770bf6534d868dac53078912e3cd88f5", "price_changes": [{"asset_id": "17664961292382291288936637834868324273780812098632528035707240895282525127009", "price": "0.06", "size": "0", "side": "BUY", "hash": "0d114a8a441edef28c0705cf575872fb65aae5b0", "best_bid": "0.03", "best_ask": "0.96"}, {"asset_id": "111286054640907956490772998022079647475566330126206509656788553491340216917730", "price": "0.94", "size": "0", "side": "SELL", "hash": "3fd30d5b800f0d259ccc99967405f6d5ce4552a9", "best_bid": "0.04", "best_ask": "0.97"}], "timestamp": "1769384266173", "event_type": "price_change"}}
{"_local_timestamp": "2026-01-25T23:37:46.316157+00:00", "data": {"market": "0xa8e6996b216b0f053c999cdd14ebd26b9c0f21f2d4be2285bf0f263a9e249387", "price_changes": [{"asset_id": "79548151070664457970653465049625822055893281924971573086501134120908067838792", "price": "0.06", "size": "0", "side": "BUY", "hash": "ff0990337129f1d9d67a1cc64925929b665526f7", "best_bid": "0.03", "best_ask": "0.96"}, {"asset_id": "87638910251680107180976444182220421878711803379550436919896332953657681609792", "price": "0.94", "size": "0", "side": "SELL", "hash": "baccf4611d87dd920894f897d90c6db8ed097155", "best_bid": "0.04", "best_ask": "0.97"}], "timestamp": "1769384266173", "event_type": "price_change"}}
{"_local_timestamp": "2026-01-25T23:37:46.680303+00:00", "data": {"market": "0xe3f6807770d960b407329b12b5e890e1d665fc042050c4034b0f98ac86f348e6", "price_changes": [{"asset_id": "5184462202147532513580739399944335715356799440407775484730001589320402350543", "price": "0.04", "size": "5.47", "side": "BUY", "hash": "26a856a34d804b5df969d0f3ba764e0c65b88337", "best_bid": "0.04", "best_ask": "0.96"}, {"asset_id": "73398331601879459556878408255341546321967259114676130015041957881093323306597", "price": "0.96", "size": "5.47", "side": "SELL", "hash": "80aa7f087d236fabbe53ff888e95850cc40a8e37", "best_bid": "0.04", "best_ask": "0.96"}], "timestamp": "1769384266611", "event_type": "price_change"}}
{"_local_timestamp": "2026-01-25T23:37:46.680752+00:00", "data": {"market": "0xa8e6996b216b0f053c999cdd14ebd26b9c0f21f2d4be2285bf0f263a9e249387", "price_changes": [{"asset_id": "79548151070664457970653465049625822055893281924971573086501134120908067838792", "price": "0.04", "size": "5.47", "side": "BUY", "hash": "5dec4f57d7a2f60eb3fa306f042fd8dca20c3cc8", "best_bid": "0.04", "best_ask": "0.96"}, {"asset_id": "87638910251680107180976444182220421878711803379550436919896332953657681609792", "price": "0.96", "size": "5.47", "side": "SELL", "hash": "9ea67e72756d1f8e07e2d1f44e533cbd948f5bc2", "best_bid": "0.04", "best_ask": "0.96"}], "timestamp": "1769384266611", "event_type": "price_change"}}
{"_local_timestamp": "2026-01-25T23:37:46.681137+00:00", "data": {"market": "0x5f8e2e997dfed26ce4d4150995a9be18770bf6534d868dac53078912e3cd88f5", "price_changes": [{"asset_id": "17664961292382291288936637834868324273780812098632528035707240895282525127009", "price": "0.04", "size": "5.47", "side": "BUY", "hash": "eab8ad5f1f0045dfb55b9ccc8efaa8c69c204525", "best_bid": "0.04", "best_ask": "0.96"}, {"asset_id": "111286054640907956490772998022079647475566330126206509656788553491340216917730", "price": "0.96", "size": "5.47", "side": "SELL", "hash": "a9628351aa3274e64cd1246ad966dbf7bf6ac343", "best_bid": "0.04", "best_ask": "0.96"}], "timestamp": "1769384266611", "event_type": "price_change"}}
{"_local_timestamp": "2026-01-25T23:37:46.681489+00:00", "data": {"market": "0x9460eee8f4eb73bfe88ddc0e3dc51670102e8687a74307d5d529003cd9f911cc", "price_changes": [{"asset_id": "73111694502202039458765701041717258004804405380693116794104644278670571271514", "price": "0.04", "size": "5.47", "side": "BUY", "hash": "90a6db819f79b2aa1010ce5143734e4a37c88996", "best_bid": "0.04", "best_ask": "0.96"}, {"asset_id": "90974674996325816587803977618907300151709708200404217989605632387971109382242", "price": "0.96", "size": "5.47", "side": "SELL", "hash": "42b777518d46a206a234aae9a85fbe19093a6d39", "best_bid": "0.04", "best_ask": "0.96"}], "timestamp": "1769384266611", "event_type": "price_change"}}
{"_local_timestamp": "2026-01-25T23:39:12.688037+00:00", "data": {"market": "0xa8e6996b216b0f053c999cdd14ebd26b9c0f21f2d4be2285bf0f263a9e249387", "price_changes": [{"asset_id": "79548151070664457970653465049625822055893281924971573086501134120908067838792", "price": "0.05", "size": "23.99", "side": "BUY", "hash": "90e1a00b1f668aab863af8d3ea1e6add8d213c2e", "best_bid": "0.05", "best_ask": "0.96"}, {"asset_id": "87638910251680107180976444182220421878711803379550436919896332953657681609792", "price": "0.95", "size": "23.99", "side": "SELL", "hash": "98178a461ed89c28f34aefe332acfdcd4135c51b", "best_bid": "0.04", "best_ask": "0.95"}], "timestamp": "1769384352595", "event_type": "price_change"}}
{"_local_timestamp": "2026-01-25T23:39:12.690459+00:00", "data": {"market": "0x5f8e2e997dfed26ce4d4150995a9be18770bf6534d868dac53078912e3cd88f5", "price_changes": [{"asset_id": "17664961292382291288936637834868324273780812098632528035707240895282525127009", "price": "0.05", "size": "23.99", "side": "BUY", "hash": "090b61421ce1d82b907708d2aa51ab50879ee7be", "best_bid": "0.05", "best_ask": "0.96"}, {"asset_id": "111286054640907956490772998022079647475566330126206509656788553491340216917730", "price": "0.95", "size": "23.99", "side": "SELL", "hash": "2e9e4c16e380779937f27c1f94ab64fdeb13bb28", "best_bid": "0.04", "best_ask": "0.95"}], "timestamp": "1769384352595", "event_type": "price_change"}}
{"_local_timestamp": "2026-01-25T23:39:12.759554+00:00", "data": {"market": "0xe3f6807770d960b407329b12b5e890e1d665fc042050c4034b0f98ac86f348e6", "price_changes": [{"asset_id": "5184462202147532513580739399944335715356799440407775484730001589320402350543", "price": "0.05", "size": "23.99", "side": "BUY", "hash": "03910be8141241e92feca9515a5725e39dbe42dd", "best_bid": "0.05", "best_ask": "0.96"}, {"asset_id": "73398331601879459556878408255341546321967259114676130015041957881093323306597", "price": "0.95", "size": "23.99", "side": "SELL", "hash": "ab96ff569d290878ec31bfd9d8c0876a79e6e457", "best_bid": "0.04", "best_ask": "0.95"}], "timestamp": "1769384352694", "event_type": "price_change"}}
{"_local_timestamp": "2026-01-25T23:39:12.764379+00:00", "data": {"market": "0x9460eee8f4eb73bfe88ddc0e3dc51670102e8687a74307d5d529003cd9f911cc", "price_changes": [{"asset_id": "73111694502202039458765701041717258004804405380693116794104644278670571271514", "price": "0.05", "size": "23.99", "side": "BUY", "hash": "487ddc2f08d6ff6cf3e8504eb44f397708b6d673", "best_bid": "0.05", "best_ask": "0.96"}, {"asset_id": "90974674996325816587803977618907300151709708200404217989605632387971109382242", "price": "0.95", "size": "23.99", "side": "SELL", "hash": "47561f3036e3edbbea5d1fd6103e096cb106cdb7", "best_bid": "0.04", "best_ask": "0.95"}], "timestamp": "1769384352694", "event_type": "price_change"}}
{"_local_timestamp": "2026-01-25T23:39:15.212140+00:00", "data": {"market": "0x5f8e2e997dfed26ce4d4150995a9be18770bf6534d868dac53078912e3cd88f5", "price_changes": [{"asset_id": "17664961292382291288936637834868324273780812098632528035707240895282525127009", "price": "0.04", "size": "0", "side": "BUY", "hash": "05178fe577166ad41cca9a2f3157952a64521003", "best_bid": "0.05", "best_ask": "0.96"}, {"asset_id": "111286054640907956490772998022079647475566330126206509656788553491340216917730", "price": "0.96", "size": "0", "side": "SELL", "hash": "6e5aedd3ef80ef46d8a9f801640f94fcb6cb397e", "best_bid": "0.04", "best_ask": "0.95"}], "timestamp": "1769384355090", "event_type": "price_change"}}
{"_local_timestamp": "2026-01-25T23:39:15.243944+00:00", "data": {"market": "0xe3f6807770d960b407329b12b5e890e1d665fc042050c4034b0f98ac86f348e6", "price_changes": [{"asset_id": "5184462202147532513580739399944335715356799440407775484730001589320402350543", "price": "0.04", "size": "0", "side": "BUY", "hash": "f8a38af524248123d683c9094382a7bfd6d90cbf", "best_bid": "0.05", "best_ask": "0.96"}, {"asset_id": "73398331601879459556878408255341546321967259114676130015041957881093323306597", "price": "0.96", "size": "0", "side": "SELL", "hash": "473c87e30d6d8b902b26a26073dfe0720fb6f789", "best_bid": "0.04", "best_ask": "0.95"}], "timestamp": "1769384355124", "event_type": "price_change"}}
{"_local_timestamp": "2026-01-25T23:39:15.244378+00:00", "data": {"market": "0x9460eee8f4eb73bfe88ddc0e3dc51670102e8687a74307d5d529003cd9f911cc", "price_changes": [{"asset_id": "73111694502202039458765701041717258004804405380693116794104644278670571271514", "price": "0.04", "size": "0", "side": "BUY", "hash": "162a8dad5c09c707592683a072a2cd57e04637d3", "best_bid": "0.05", "best_ask": "0.96"}, {"asset_id": "90974674996325816587803977618907300151709708200404217989605632387971109382242", "price": "0.96", "size": "0", "side": "SELL", "hash": "f1191a6bc216cfe4c337e6e460a2d6cd61393a68", "best_bid": "0.04", "best_ask": "0.95"}], "timestamp": "1769384355124", "event_type": "price_change"}}
{"_local_timestamp": "2026-01-25T23:39:15.244718+00:00", "data": {"market": "0xa8e6996b216b0f053c999cdd14ebd26b9c0f21f2d4be2285bf0f263a9e249387", "price_changes": [{"asset_id": "79548151070664457970653465049625822055893281924971573086501134120908067838792", "price": "0.04", "size": "0", "side": "BUY", "hash": "18f6f29d7c71efccf92db4cf45a04ae687ab4078", "best_bid": "0.05", "best_ask": "0.96"}, {"asset_id": "87638910251680107180976444182220421878711803379550436919896332953657681609792", "price": "0.96", "size": "0", "side": "SELL", "hash": "5d5a8f5e3dbd4830556059e4089fe79e70d86c4a", "best_bid": "0.04", "best_ask": "0.95"}], "timestamp": "1769384355125", "event_type": "price_change"}}
{"_local_timestamp": "2026-01-25T23:39:15.760664+00:00", "data": {"market": "0x5f8e2e997dfed26ce4d4150995a9be18770bf6534d868dac53078912e3cd88f5", "price_changes": [{"asset_id": "17664961292382291288936637834868324273780812098632528035707240895282525127009", "price": "0.06", "size": "5.47", "side": "BUY", "hash": "4847038d441d51f5fa0ad6a8e7bea563e6b64892", "best_bid": "0.06", "best_ask": "0.96"}, {"asset_id": "111286054640907956490772998022079647475566330126206509656788553491340216917730", "price": "0.94", "size": "5.47", "side": "SELL", "hash": "f0bffc359cbccbce5c28592ea1beb05d03b15a88", "best_bid": "0.04", "best_ask": "0.94"}], "timestamp": "1769384355694", "event_type": "price_change"}}
{"_local_timestamp": "2026-01-25T23:39:15.810108+00:00", "data": {"market": "0x9460eee8f4eb73bfe88ddc0e3dc51670102e8687a74307d5d529003cd9f911cc", "price_changes": [{"asset_id": "73111694502202039458765701041717258004804405380693116794104644278670571271514", "price": "0.06", "size": "5.47", "side": "BUY", "hash": "37dc94942bbffef07e9c7d8caa3d4ee3ec0ffe1e", "best_bid": "0.06", "best_ask": "0.96"}, {"asset_id": "90974674996325816587803977618907300151709708200404217989605632387971109382242", "price": "0.94", "size": "5.47", "side": "SELL", "hash": "a2d4c18467092293ed0c1cb8ff97edfa0546ce30", "best_bid": "0.04", "best_ask": "0.94"}], "timestamp": "1769384355746", "event_type": "price_change"}}
{"_local_timestamp": "2026-01-25T23:39:15.810560+00:00", "data": {"market": "0xa8e6996b216b0f053c999cdd14ebd26b9c0f21f2d4be2285bf0f263a9e249387", "price_changes": [{"asset_id": "79548151070664457970653465049625822055893281924971573086501134120908067838792", "price": "0.06", "size": "5.47", "side": "BUY", "hash": "1516d50e6936d2e97631e487c97d8c01fb5bb716", "best_bid": "0.06", "best_ask": "0.96"}, {"asset_id": "87638910251680107180976444182220421878711803379550436919896332953657681609792", "price": "0.94", "size": "5.47", "side": "SELL", "hash": "6a01a1d102b4dbe1e4008079a81a6c12beebdab9", "best_bid": "0.04", "best_ask": "0.94"}], "timestamp": "1769384355746", "event_type": "price_change"}}
{"_local_timestamp": "2026-01-25T23:39:15.815257+00:00", "data": {"market": "0xe3f6807770d960b407329b12b5e890e1d665fc042050c4034b0f98ac86f348e6", "price_changes": [{"asset_id": "5184462202147532513580739399944335715356799440407775484730001589320402350543", "price": "0.06", "size": "5.47", "side": "BUY", "hash": "2340c4aa5b39d37a105c8a600973593891cb3a79", "best_bid": "0.06", "best_ask": "0.96"}, {"asset_id": "73398331601879459556878408255341546321967259114676130015041957881093323306597", "price": "0.94", "size": "5.47", "side": "SELL", "hash": "1cff2caa1f717cad81dc98fa96e2b8045b027240", "best_bid": "0.04", "best_ask": "0.94"}], "timestamp": "1769384355746", "event_type": "price_change"}}
