{"_local_timestamp": "2026-01-25T23:41:24.000805+00:00", "data": [{"market": "0xecac69f1b33d6466f3238adfe4c4d264ddabd49d4a0682a4e4ee74f982f1b0c8", "asset_id": "20298647012997843629636031084705400211535778676415975243776176061572856151092", "timestamp": "1769379492595", "hash": "5bd076c80dcbc54c10f34f6a33b3ba63641cd8d1", "bids": [{"price": "0.01", "size": "240.97"}, {"price": "0.02", "size": "115"}, {"price": "0.03", "size": "30.17"}, {"price": "0.24", "size": "100"}], "asks": [{"price": "0.99", "size": "241.36"}, {"price": "0.98", "size": "65"}, {"price": "0.97", "size": "30.04"}, {"price": "0.34", "size": "100"}], "event_type": "book", "last_trade_price": ""}, {"market": "0x96bfe43b664cafd7a219d22a694e3283beaa0323344cf62b1083409ca0d5f9cb", "asset_id": "51459039894234139549980154216140427952049987907220959101717179699606648637406", "timestamp": "1769379652750", "hash": "ba69696002a47efff9f11c17d5ea70c8b4113347", "bids": [{"price": "0.01", "size": "201.38"}, {"price": "0.02", "size": "100.17"}, {"price": "0.03", "size": "58.04"}], "asks": [{"price": "0.99", "size": "202.04"}, {"price": "0.98", "size": "100.48"}, {"price": "0.97", "size": "18.99"}, {"price": "0.96", "size": "29.99"}], "event_type": "book", "last_trade_price": ""}, {"market": "0xc9855139cab97e536de1cd15906fa7b3f9ae4e078af5aad9e944816bb2159711", "asset_id": "85494679103805115610079943463933518665037708338189637736300704310010756140302", "timestamp": "1769384230479", "hash": "f948c73fe3b65f2d59765ee20623c8939604e1e4", "bids": [{"price": "0.01", "size": "260"}, {"price": "0.02", "size": "711.02"}, {"price": "0.03", "size": "256.99"}, {"price": "0.04", "size": "14.24"}, {"price": "0.05", "size": "130"}], "asks": [{"price": "0.99", "size": "180"}, {"price": "0.98", "size": "15.05"}, {"price": "0.97", "size": "600"}, {"price": "0.92", "size": "400"}, {"price": "0.91", "size": "7.76"}, {"price": "0.86", "size": "200"}, {"price": "0.79", "size": "198"}, {"price": "0.54", "size": "300"}, {"price": "0.5", "size": "20"}, {"price": "0.49", "size": "200"}, {"price": "0.44", "size": "125"}, {"price": "0.4", "size": "75"}, {"price": "0.2", "size": "50"}, {"price": "0.15", "size": "100"}, {"price": "0.13", "size": "10"}], "event_type": "book", "last_trade_price": ""}, {"market": "0xc9855139cab97e536de1cd15906fa7b3f9ae4e078af5aad9e944816bb2159711", "asset_id": "33702039415152587930284278059349972411131709035008901806037913666966254369742", "timestamp": "1769384230479", "hash": "f6023981b76ce5a98a4866b33ac400ea899f70e9", "bids": [{"price": "0.01", "size": "180"}, {"price": "0.02", "size": "15.05"}, {"price": "0.03", "size": "600"}, {"price": "0.08", "size": "400"}, {"price": "0.09", "size": "7.76"}, {"price": "0.14", "size": "200"}, {"price": "0.21", "size": "198"}, {"price": "0.46", "size": "300"}, {"price": "0.5", "size": "20"}, {"price": "0.51", "size": "200"}, {"price": "0.56", "size": "125"}, {"price": "0.6", "size": "75"}, {"price": "0.8", "size": "50"}, {"price": "0.85", "size": "100"}, {"price": "0.87", "size": "10"}], "asks": [{"price": "0.99", "size": "260"}, {"price": "0.98", "size": "711.02"}, {"price": "0.97", "size": "256.99"}, {"price": "0.96", "size": "14.24"}, {"price": "0.95", "size": "130"}], "event_type": "book", "last_trade_price": ""}, {"market": "0xb4e3a03b7b9d32524e50a18643bc8b635f5db847ec228459e63ada4654232266", "asset_id": "61429815324316585285190173773753095389900760670737146252386183662368970056071", "timestamp": "1769384447736", "hash": "3afe15ca6fd6834f2c45c42e6a359ce4187db5d0", "bids": [{"price": "0.01", "size": "202.79"}, {"price": "0.02", "size": "98.94"}, {"price": "0.03", "size": "19.77"}, {"price": "0.05", "size": "23.99"}, {"price": "0.06", "size": "5.47"}], "asks": [{"price": "0.99", "size": "202.04"}, {"price": "0.98", "size": "100.48"}, {"price": "0.97", "size": "18.99"}, {"price": "0.96", "size": "37.48"}], "event_type": "book", "last_trade_price": ""}, {"market": "0xb4e3a03b7b9d32524e50a18643bc8b635f5db847ec228459e63ada4654232266", "asset_id": "59015750890371857600345791870768842601163744323962019697925860773975224241703", "timestamp": "1769384447736", "hash": "5f73a8c79bcd282170a7c12d7f2230835a8ff10c", "bids": [{"price": "0.01", "size": "202.04"}, {"price": "0.02", "size": "100.48"}, {"price": "0.03", "size": "18.99"}, {"price": "0.04", "size": "37.48"}], "asks": [{"price": "0.99", "size": "202.79"}, {"price": "0.98", "size": "98.94"}, {"price": "0.97", "size": "19.77"}, {"price": "0.95", "size": "23.99"}, {"price": "0.94", "size": "5.47"}], "event_type": "book", "last_trade_price": ""}, {"market": "0x25ba0e34abf08ca67e940e0a9de39d77ab9969ba040b54d59b8c9557e7e1209e", "asset_id": "34658822313166366862155307121179859104291458361815588542611104845760657957057", "timestamp": "1769384437999", "hash": "0c8f2000d100d4841a9ab79c4417a1374de09842", "bids": [{"price": "0.01", "size": "202.04"}, {"price": "0.02", "size": "100.48"}, {"price": "0.03", "size": "18.99"}, {"price": "0.04", "size": "29.99"}], "asks": [{"price": "0.99", "size": "202.63"}, {"price": "0.98", "size": "98.94"}, {"price": "0.97", "size": "19.82"}, {"price": "0.96", "size": "5.47"}], "event_type": "book", "last_trade_price": ""}, {"market": "0xdea4796b1330cc138fddbd7588ade544272dbbb5534d5c7e668d9793cd0eb88f", "asset_id": "64337076081574293087836622474147344770540617949234564813925323344969252999147", "timestamp": "1769384447778", "hash": "1997557d48b669eb2de204e36ca129f309e5784c", "bids": [{"price": "0.01", "size": "201.38"}, {"price": "0.02", "size": "100.17"}, {"price": "0.03", "size": "52.57"}], "asks": [{"price": "0.99", "size": "199.91"}, {"price": "0.98", "size": "95.66"}, {"price": "0.97", "size": "22.92"}, {"price": "0.95", "size": "23.99"}, {"price": "0.94", "size": "5.47"}], "event_type": "book", "last_trade_price": ""}, {"market": "0x95fc9afae2e9bcfba41be1318b9b232c954d4066deb69293201f60e312e1deb2", "asset_id": "1398772603884009307910454931960162936237268068359444250489356436701623282401", "timestamp": "1769384447778", "hash": "fb6a20b4860d23ce1f8f01231ff7a8eef2a2b328", "bids": [{"price": "0.01", "size": "201.43"}, {"price": "0.02", "size": "99.25"}, {"price": "0.03", "size": "20.02"}, {"price": "0.05", "size": "23.99"}, {"price": "0.06", "size": "5.47"}], "asks": [{"price": "0.99", "size": "201.38"}, {"price": "0.98", "size": "100.17"}, {"price": "0.97", "size": "52.57"}], "event_type": "book", "last_trade_price": ""}, {"market": "0xecac69f1b33d6466f3238adfe4c4d264ddabd49d4a0682a4e4ee74f982f1b0c8", "asset_id": "68556933551036161350674598979676711744509043145888665533658549767408893849406", "timestamp": "1769379492595", "hash": "f9a7af399f7902d58f93a4e63523bd6be206acb8", "bids": [{"price": "0.01", "size": "241.36"}, {"price": "0.02", "size": "65"}, {"price": "0.03", "size": "30.04"}, {"price": "0.66", "size": "100"}], "asks": [{"price": "0.99", "size": "240.97"}, {"price": "0.98", "size": "115"}, {"price": "0.97", "size": "30.17"}, {"price": "0.76", "size": "100"}], "event_type": "book", "last_trade_price": ""}, {"market": "0x723f251ab60ea2dd4f99374a74f80be8548c2c4fe2cca22f2fa6f90bd905b559", "asset_id": "48978425543742752818803322458870690562079517439055041342251621857158978447363", "timestamp": "1769384231392", "hash": "b48bab48e3321f67b4ae9cad0a134f89456d6b57", "bids": [{"price": "0.01", "size": "189.19"}, {"price": "0.02", "size": "90"}, {"price": "0.03", "size": "30.27"}, {"price": "0.13", "size": "100"}, {"price": "0.14", "size": "7.14"}], "asks": [{"price": "0.99", "size": "189.71"}, {"price": "0.98", "size": "90"}, {"price": "0.97", "size": "30.09"}, {"price": "0.23", "size": "100"}], "event_type": "book", "last_trade_price": ""}, {"market": "0x723f251ab60ea2dd4f99374a74f80be8548c2c4fe2cca22f2fa6f90bd905b559", "asset_id": "112174093579349393205957859148865812063897305228582002453213788215242068235765", "timestamp": "1769384231392", "hash": "1458a85ab3777e3c7a6d798a3d1217c1bca80d98", "bids": [{"price": "0.01", "size": "189.71"}, {"price": "0.02", "size": "90"}, {"price": "0.03", "size": "30.09"}, {"price": "0.77", "size": "100"}], "asks": [{"price": "0.99", "size": "189.19"}, {"price": "0.98", "size": "90"}, {"price": "0.97", "size": "30.27"}, {"price": "0.87", "size": "100"}, {"price": "0.86", "size": "7.14"}], "event_type": "book", "last_trade_price": ""}, {"market": "0x25ba0e34abf08ca67e940e0a9de39d77ab9969ba040b54d59b8c9557e7e1209e", "asset_id": "100230850484605537426827028089591201602750218213849583160902003942949141764541", "timestamp": "1769384437999", "hash": "fa81588b231a30791e49b8d92bf704ec9cd4f234", "bids": [{"price": "0.01", "size": "202.63"}, {"price": "0.02", "size": "98.94"}, {"price": "0.03", "size": "19.82"}, {"price": "0.04", "size": "5.47"}], "asks": [{"price": "0.99", "size": "202.04"}, {"price": "0.98", "size": "100.48"}, {"price": "0.97", "size": "18.99"}, {"price": "0.96", "size": "29.99"}], "event_type": "book", "last_trade_price": ""}, {"market": "0xac316c01625b0fa8dd06da51970c50c8fdd764f82e535b9e21d13613331023c4", "asset_id": "12995286023077810117688664821031077590385716779526746803320299864462527923165", "timestamp": "1769384261305", "hash": "bec0331315a5c6c5b72178ed5a551c2316588416", "bids": [{"price": "0.01", "size": "189.71"}, {"price": "0.02", "size": "82"}, {"price": "0.03", "size": "30.09"}, {"price": "0.77", "size": "100"}], "asks": [{"price": "0.99", "size": "189.19"}, {"price": "0.98", "size": "97.21"}, {"price": "0.97", "size": "6.02"}, {"price": "0.96", "size": "14.57"}, {"price": "0.87", "size": "107.69"}], "event_type": "book", "last_trade_price": ""}, {"market": "0xac316c01625b0fa8dd06da51970c50c8fdd764f82e535b9e21d13613331023c4", "asset_id": "92711393135578327663235479520022176862589684688868437494076107570235367457535", "timestamp": "1769384261305", "hash": "e384147f995f7f04908594ed51f6d306a780f953", "bids": [{"price": "0.01", "size": "189.19"}, {"price": "0.02", "size": "97.21"}, {"price": "0.03", "size": "6.02"}, {"price": "0.04", "size": "14.57"}, {"price": "0.13", "size": "107.69"}], "asks": [{"price": "0.99", "size": "189.71"}, {"price": "0.98", "size": "82"}, {"price": "0.97", "size": "30.09"}, {"price": "0.23", "size": "100"}], "event_type": "book", "last_trade_price": ""}, {"market": "0x95fc9afae2e9bcfba41be1318b9b232c954d4066deb69293201f60e312e1deb2", "asset_id": "59592741249661515665302592630910670026326604112506560769678078156146744114566", "timestamp": "1769384447778", "hash": "a3bd7533decea8a093291ea4685732f43651df1a", "bids": [{"price": "0.01", "size": "201.38"}, {"price": "0.02", "size": "100.17"}, {"price": "0.03", "size": "52.57"}], "asks": [{"price": "0.99", "size": "201.43"}, {"price": "0.98", "size": "99.25"}, {"price": "0.97", "size": "20.02"}, {"price": "0.95", "size": "23.99"}, {"price": "0.94", "size": "5.47"}], "event_type": "book", "last_trade_price": ""}, {"market": "0x96bfe43b664cafd7a219d22a694e3283beaa0323344cf62b1083409ca0d5f9cb", "asset_id": "113536014786804901586031232135275432369215216055458158881028615233206425578295", "timestamp": "1769379652750", "hash": "73acebfc50eac324ba3c26c7928c800f7507a31a", "bids": [{"price": "0.01", "size": "202.04"}, {"price": "0.02", "size": "100.48"}, {"price": "0.03", "size": "18.99"}, {"price": "0.04", "size": "29.99"}], "asks": [{"price": "0.99", "size": "201.38"}, {"price": "0.98", "size": "100.17"}, {"price": "0.97", "size": "58.04"}], "event_type": "book", "last_trade_price": ""}, {"market": "0xdea4796b1330cc138fddbd7588ade544272dbbb5534d5c7e668d9793cd0eb88f", "asset_id": "110814814064089248423115833517094810833597085672984019468073735637142359900748", "timestamp": "1769384447778", "hash": "463ceb3394f7f980ad3d8ae19344863c6d07d470", "bids": [{"price": "0.01", "size": "199.91"}, {"price": "0.02", "size": "95.66"}, {"price": "0.03", "size": "22.92"}, {"price": "0.05", "size": "23.99"}, {"price": "0.06", "size": "5.47"}], "asks": [{"price": "0.99", "size": "201.38"}, {"price": "0.98", "size": "100.17"}, {"price": "0.97", "size": "52.57"}], "event_type": "book", "last_trade_price": ""}]}
{"_local_timestamp": "2026-01-25T23:42:06.644844+00:00", "data": {"market": "0xdea4796b1330cc138fddbd7588ade544272dbbb5534d5c7e668d9793cd0eb88f", "price_changes": [{"asset_id": "110814814064089248423115833517094810833597085672984019468073735637142359900748", "price": "0.05", "size": "0", "side": "BUY", "hash": "7c005f41572d44c83a516b57436dee605655c15a", "best_bid": "0.06", "best_ask": "0.97"}, {"asset_id": "64337076081574293087836622474147344770540617949234564813925323344969252999147", "price": "0.95", "size": "0", "side": "SELL", "hash": "26056b1a5f23ab8a7d4f2c9f4f0706418624648b", "best_bid": "0.03", "best_ask": "0.94"}], "timestamp": "1769384526567", "event_type": "price_change"}}
{"_local_timestamp": "2026-01-25T23:42:06.646068+00:00", "data": {"market": "0x95fc9afae2e9bcfba41be1318b9b232c954d4066deb69293201f60e312e1deb2", "price_changes": [{"asset_id": "1398772603884009307910454931960162936237268068359444250489356436701623282401", "price": "0.05", "size": "0", "side": "BUY", "hash": "42f736c4523b93e0191ed6f50e665bf0b6e511d4", "best_bid": "0.06", "best_ask": "0.97"}, {"asset_id": "59592741249661515665302592630910670026326604112506560769678078156146744114566", "price": "0.95", "size": "0", "side": "SELL", "hash": "c45f5d637988f1e9629644981f441366e560e662", "best_bid": "0.03", "best_ask": "0.94"}], "timestamp": "1769384526567", "event_type": "price_change"}}
{"_local_timestamp": "2026-01-25T23:42:06.646737+00:00", "data": {"market": "0xb4e3a03b7b9d32524e50a18643bc8b635f5db847ec228459e63ada4654232266", "price_changes": [{"asset_id": "61429815324316585285190173773753095389900760670737146252386183662368970056071", "price": "0.05", "size": "0", "side": "BUY", "hash": "cead4eef339110abaea190d19c0670e74c9ad185", "best_bid": "0.06", "best_ask": "0.96"}, {"asset_id": "59015750890371857600345791870768842601163744323962019697925860773975224241703", "price": "0.95", "size": "0", "side": "SELL", "hash": "720dfc569e695e61708324c67224d87cfd3e89cc", "best_bid": "0.04", "best_ask": "0.94"}], "timestamp": "1769384526567", "event_type": "price_change"}}
{"_local_timestamp": "2026-01-25T23:42:07.457242+00:00", "data": {"market": "0x95fc9afae2e9bcfba41be1318b9b232c954d4066deb69293201f60e312e1deb2", "price_changes": [{"asset_id": "1398772603884009307910454931960162936237268068359444250489356436701623282401", "price": "0.06", "size": "0", "side": "BUY", "hash": "232dd76f327e2ff9cef9cad0fcd53977663be12e", "best_bid": "0.03", "best_ask": "0.97"}, {"asset_id": "59592741249661515665302592630910670026326604112506560769678078156146744114566", "price": "0.94", "size": "0", "side": "SELL", "hash": "4553224d3c48b8cce7043fce77e37e79e054d8d9", "best_bid": "0.03", "best_ask": "0.97"}], "timestamp": "1769384527383", "event_type": "price_change"}}
{"_local_timestamp": "2026-01-25T23:42:07.458263+00:00", "data": {"market": "0xdea4796b1330cc138fddbd7588ade544272dbbb5534d5c7e668d9793cd0eb88f", "price_changes": [{"asset_id": "110814814064089248423115833517094810833597085672984019468073735637142359900748", "price": "0.06", "size": "0", "side": "BUY", "hash": "068c60e7c194c5eb9315eb5c54cf4b43239083d2", "best_bid": "0.03", "best_ask": "0.97"}, {"asset_id": "64337076081574293087836622474147344770540617949234564813925323344969252999147", "price": "0.94", "size": "0", "side": "SELL", "hash": "6eff796580e3ccb3d7f2ca5c1d5f116de5c12c78", "best_bid": "0.03", "best_ask": "0.97"}], "timestamp": "1769384527384", "event_type": "price_change"}}
{"_local_timestamp": "2026-01-25T23:42:07.458827+00:00", "data": {"market": "0xb4e3a03b7b9d32524e50a18643bc8b635f5db847ec228459e63ada4654232266", "price_changes": [{"asset_id": "61429815324316585285190173773753095389900760670737146252386183662368970056071", "price": "0.06", "size": "0", "side": "BUY", "hash": "fd64b8e15bce6b7669f6d918330351e3446d8920", "best_bid": "0.03", "best_ask": "0.96"}, {"asset_id": "59015750890371857600345791870768842601163744323962019697925860773975224241703", "price": "0.94", "size": "0", "side": "SELL", "hash": "d81f47e35f6ee1f4143001bfbbda404bc6505129", "best_bid": "0.04", "best_ask": "0.97"}], "timestamp": "1769384527384", "event_type": "price_change"}}
{"_local_timestamp": "2026-01-25T23:42:07.495990+00:00", "data": {"market": "0x95fc9afae2e9bcfba41be1318b9b232c954d4066deb69293201f60e312e1deb2", "price_changes": [{"asset_id": "1398772603884009307910454931960162936237268068359444250489356436701623282401", "price": "0.04", "size": "5.47", "side": "BUY", "hash": "30f74b5fce3446e4a85d1bf7a648f0979643f5e5", "best_bid": "0.04", "best_ask": "0.97"}, {"asset_id": "59592741249661515665302592630910670026326604112506560769678078156146744114566", "price": "0.96", "size": "5.47", "side": "SELL", "hash": "d8cd61a1fca82dc89f95166f8e5e222e006b9efb", "best_bid": "0.03", "best_ask": "0.96"}], "timestamp": "1769384527432", "event_type": "price_change"}}
{"_local_timestamp": "2026-01-25T23:42:07.503731+00:00", "data": {"market": "0xdea4796b1330cc138fddbd7588ade544272dbbb5534d5c7e668d9793cd0eb88f", "price_changes": [{"asset_id": "110814814064089248423115833517094810833597085672984019468073735637142359900748", "price": "0.04", "size": "5.47", "side": "BUY", "hash": "4c9ec671591a75974321fbfa34b6b287de59d96a", "best_bid": "0.04", "best_ask": "0.97"}, {"asset_id": "64337076081574293087836622474147344770540617949234564813925323344969252999147", "price": "0.96", "size": "5.47", "side": "SELL", "hash": "e6e90cf413e2386b075755ea35e845b32292e51f", "best_bid": "0.03", "best_ask": "0.96"}], "timestamp": "1769384527432", "event_type": "price_change"}}
{"_local_timestamp": "2026-01-25T23:42:07.504460+00:00", "data": {"market": "0xb4e3a03b7b9d32524e50a18643bc8b635f5db847ec228459e63ada4654232266", "price_changes": [{"asset_id": "61429815324316585285190173773753095389900760670737146252386183662368970056071", "price": "0.04", "size": "5.47", "side": "BUY", "hash": "116121ec2973ca3f657fc40f6711d1e15ccf1576", "best_bid": "0.04", "best_ask": "0.96"}, {"asset_id": "59015750890371857600345791870768842601163744323962019697925860773975224241703", "price": "0.96", "size": "5.47", "side": "SELL", "hash": "b159c7d6dc82fd5974cd55e90c0e7bba1da834aa", "best_bid": "0.04", "best_ask": "0.96"}], "timestamp": "1769384527432", "event_type": "price_change"}}
{"_local_timestamp": "2026-01-25T23:42:07.840766+00:00", "data": {"market": "0x25ba0e34abf08ca67e940e0a9de39d77ab9969ba040b54d59b8c9557e7e1209e", "price_changes": [{"asset_id": "100230850484605537426827028089591201602750218213849583160902003942949141764541", "price": "0.05", "size": "23.99", "side": "BUY", "hash": "9078f149984fd963f8fc595a6048b332bd167dba", "best_bid": "0.05", "best_ask": "0.96"}, {"asset_id": "34658822313166366862155307121179859104291458361815588542611104845760657957057", "price": "0.95", "size": "23.99", "side": "SELL", "hash": "5b5f6a589ea7e17d857722e8ec82ee01892dcf4a", "best_bid": "0.04", "best_ask": "0.95"}], "timestamp": "1769384527767", "event_type": "price_change"}}
{"_local_timestamp": "2026-01-25T23:42:10.869277+00:00", "data": {"market": "0x25ba0e34abf08ca67e940e0a9de39d77ab9969ba040b54d59b8c9557e7e1209e", "price_changes": [{"asset_id": "100230850484605537426827028089591201602750218213849583160902003942949141764541", "price": "0.04", "size": "0", "side": "BUY", "hash": "298162c7c47bd2d5907adf4b47677fb61a346318", "best_bid": "0.05", "best_ask": "0.96"}, {"asset_id": "34658822313166366862155307121179859104291458361815588542611104845760657957057", "price": "0.96", "size": "0", "side": "SELL", "hash": "9a5f3488f76d4db463df8b79abd146ee8a84b016", "best_bid": "0.04", "best_ask": "0.95"}], "timestamp": "1769384530792", "event_type": "price_change"}}
{"_local_timestamp": "2026-01-25T23:42:11.201777+00:00", "data": {"market": "0x25ba0e34abf08ca67e940e0a9de39d77ab9969ba040b54d59b8c9557e7e1209e", "price_changes": [{"asset_id": "100230850484605537426827028089591201602750218213849583160902003942949141764541", "price": "0.06", "size": "5.47", "side": "BUY", "hash": "06fbd5cb789861f5a9d456a608030dfdde38eec4", "best_bid": "0.06", "best_ask": "0.96"}, {"asset_id": "34658822313166366862155307121179859104291458361815588542611104845760657957057", "price": "0.94", "size": "5.47", "side": "SELL", "hash": "d9f327df674ee435c4f931a81b2d2ca6da70513e", "best_bid": "0.04", "best_ask": "0.94"}], "timestamp": "1769384531128", "event_type": "price_change"}}
{"_local_timestamp": "2026-01-25T23:42:59.278007+00:00", "data": {"market": "0xc9855139cab97e536de1cd15906fa7b3f9ae4e078af5aad9e944816bb2159711", "price_changes": [{"asset_id": "85494679103805115610079943463933518665037708338189637736300704310010756140302", "price": "0.04", "size": "0", "side": "BUY", "hash": "0cb72cf8aa8b07d005d528076e74306997753a83", "best_bid": "0.05", "best_ask": "0.13"}, {"asset_id": "33702039415152587930284278059349972411131709035008901806037913666966254369742", "price": "0.96", "size": "0", "side": "SELL", "hash": "9ee23aef892bbfcd93eaec95ca8749711bebcccb", "best_bid": "0.87", "best_ask": "0.95"}], "timestamp": "1769384579072", "event_type": "price_change"}}
{"_local_timestamp": "2026-01-25T23:42:59.505230+00:00", "data": {"market": "0xc9855139cab97e536de1cd15906fa7b3f9ae4e078af5aad9e944816bb2159711", "price_changes": [{"asset_id": "85494679103805115610079943463933518665037708338189637736300704310010756140302", "price": "0.04", "size": "14.24", "side": "BUY", "hash": "72e2a3a164de84f964c89fcffb0a2bc509f92283", "best_bid": "0.05", "best_ask": "0.13"}, {"asset_id": "33702039415152587930284278059349972411131709035008901806037913666966254369742", "price": "0.96", "size": "14.24", "side": "SELL", "hash": "af378a2f711474a4080a49fcbc03beb7441ea61f", "best_bid": "0.87", "best_ask": "0.95"}], "timestamp": "1769384579308", "event_type": "price_change"}}
{"_local_timestamp": "2026-01-25T23:43:02.364489+00:00", "data": {"market": "0x723f251ab60ea2dd4f99374a74f80be8548c2c4fe2cca22f2fa6f90bd905b559", "price_changes": [{"asset_id": "48978425543742752818803322458870690562079517439055041342251621857158978447363", "price": "0.03", "size": "6.02", "side": "BUY", "hash": "d1b4a8d3cf449890f39804cc9dbac0c8e09a4df7", "best_bid": "0.14", "best_ask": "0.23"}, {"asset_id": "112174093579349393205957859148865812063897305228582002453213788215242068235765", "price": "0.97", "size": "6.02", "side": "SELL", "hash": "e63c31a58e56a176bdedc1920e9787a5b39bd244", "best_bid": "0.77", "best_ask": "0.86"}], "timestamp": "1769384582155", "event_type": "price_change"}}
{"_local_timestamp": "2026-01-25T23:43:02.624338+00:00", "data": {"market": "0x723f251ab60ea2dd4f99374a74f80be8548c2c4fe2cca22f2fa6f90bd905b559", "price_changes": [{"asset_id": "48978425543742752818803322458870690562079517439055041342251621857158978447363", "price": "0.03", "size": "30.27", "side": "BUY", "hash": "d5a996ee6bb8b5ea5d591f9e50ea2476d39c655a", "best_bid": "0.14", "best_ask": "0.23"}, {"asset_id": "112174093579349393205957859148865812063897305228582002453213788215242068235765", "price": "0.97", "size": "30.27", "side": "SELL", "hash": "611068806bf8566b0c7e2ed817a111fa5aa180a9", "best_bid": "0.77", "best_ask": "0.86"}], "timestamp": "1769384582434", "event_type": "price_change"}}
{"_local_timestamp": "2026-01-25T23:43:35.189154+00:00", "data": {"market": "0x25ba0e34abf08ca67e940e0a9de39d77ab9969ba040b54d59b8c9557e7e1209e", "price_changes": [{"asset_id": "100230850484605537426827028089591201602750218213849583160902003942949141764541", "price": "0.05", "size": "0", "side": "BUY", "hash": "47256cb508e04f2b840584becfd242a5730353d1", "best_bid": "0.06", "best_ask": "0.96"}, {"asset_id": "34658822313166366862155307121179859104291458361815588542611104845760657957057", "price": "0.95", "size": "0", "side": "SELL", "hash": "2a839a7ca99f71b8d4ca6044104abbca3df37ad0", "best_bid": "0.04", "best_ask": "0.94"}], "timestamp": "1769384615119", "event_type": "price_change"}}
{"_local_timestamp": "2026-01-25T23:43:36.063858+00:00", "data": {"market": "0xdea4796b1330cc138fddbd7588ade544272dbbb5534d5c7e668d9793cd0eb88f", "price_changes": [{"asset_id": "110814814064089248423115833517094810833597085672984019468073735637142359900748", "price": "0.05", "size": "23.99", "side": "BUY", "hash": "2190a0b1a9bcff76e4a5b81c69290f0bab4da567", "best_bid": "0.05", "best_ask": "0.97"}, {"asset_id": "64337076081574293087836622474147344770540617949234564813925323344969252999147", "price": "0.95", "size": "23.99", "side": "SELL", "hash": "a26b634c9533e1d3265688b1492d9a72d823ef70", "best_bid": "0.03", "best_ask": "0.95"}], "timestamp": "1769384615995", "event_type": "price_change"}}
{"_local_timestamp": "2026-01-25T23:43:36.064440+00:00", "data": {"market": "0x95fc9afae2e9bcfba41be1318b9b232c954d4066deb69293201f60e312e1deb2", "price_changes": [{"asset_id": "1398772603884009307910454931960162936237268068359444250489356436701623282401", "price": "0.05", "size": "23.99", "side": "BUY", "hash": "75b2240b6e3cd493beb92c6e3e80e9be24534106", "best_bid": "0.05", "best_ask": "0.97"}, {"asset_id": "59592741249661515665302592630910670026326604112506560769678078156146744114566", "price": "0.95", "size": "23.99", "side": "SELL", "hash": "af601f6374d6adadca2bae4f77170a230e133d21", "best_bid": "0.03", "best_ask": "0.95"}], "timestamp": "1769384615995", "event_type": "price_change"}}
{"_local_timestamp": "2026-01-25T23:43:36.070856+00:00", "data": {"market": "0xb4e3a03b7b9d32524e50a18643bc8b635f5db847ec228459e63ada4654232266", "price_changes": [{"asset_id": "61429815324316585285190173773753095389900760670737146252386183662368970056071", "price": "0.05", "size": "23.99", "side": "BUY", "hash": "3e1770a525f24f7185c092126ed9126a00e4b364", "best_bid": "0.05", "best_ask": "0.96"}, {"asset_id": "59015750890371857600345791870768842601163744323962019697925860773975224241703", "price": "0.95", "size": "23.99", "side": "SELL", "hash": "52d6a676403cdc32d2cd4233d0f0b21f2a276add", "best_bid": "0.04", "best_ask": "0.95"}], "timestamp": "1769384615996", "event_type": "price_change"}}
{"_local_timestamp": "2026-01-25T23:43:36.966514+00:00", "data": {"market": "0x25ba0e34abf08ca67e940e0a9de39d77ab9969ba040b54d59b8c9557e7e1209e", "price_changes": [{"asset_id": "100230850484605537426827028089591201602750218213849583160902003942949141764541", "price": "0.01", "size": "191.93", "side": "BUY", "hash": "783a1faf3100b27bb8e9086470229d4ae83e8125", "best_bid": "0.06", "best_ask": "0.96"}, {"asset_id": "34658822313166366862155307121179859104291458361815588542611104845760657957057", "price": "0.99", "size": "191.93", "side": "SELL", "hash": "9a0a2c0e31840ed104c6fe3a3b839a66765289fc", "best_bid": "0.04", "best_ask": "0.94"}], "timestamp": "1769384616898", "event_type": "price_change"}}
{"_local_timestamp": "2026-01-25T23:43:36.967094+00:00", "data": {"market": "0xac316c01625b0fa8dd06da51970c50c8fdd764f82e535b9e21d13613331023c4", "price_changes": [{"asset_id": "92711393135578327663235479520022176862589684688868437494076107570235367457535", "price": "0.02", "size": "90", "side": "BUY", "hash": "d05ebcb097fbb0647f449e8e030a062e17834f7a", "best_bid": "0.13", "best_ask": "0.23"}, {"asset_id": "12995286023077810117688664821031077590385716779526746803320299864462527923165", "price": "0.98", "size": "90", "side": "SELL", "hash": "56191415f63eeb351be4d28754ba3cfed1a2bd12", "best_bid": "0.77", "best_ask": "0.87"}], "timestamp": "1769384616898", "event_type": "price_change"}}
{"_local_timestamp": "2026-01-25T23:43:36.967566+00:00", "data": {"market": "0xac316c01625b0fa8dd06da51970c50c8fdd764f82e535b9e21d13613331023c4", "price_changes": [{"asset_id": "92711393135578327663235479520022176862589684688868437494076107570235367457535", "price": "0.04", "size": "0", "side": "BUY", "hash": "d05ebcb097fbb0647f449e8e030a062e17834f7a", "best_bid": "0.13", "best_ask": "0.23"}, {"asset_id": "12995286023077810117688664821031077590385716779526746803320299864462527923165", "price": "0.96", "size": "0", "side": "SELL", "hash": "56191415f63eeb351be4d28754ba3cfed1a2bd12", "best_bid": "0.77", "best_ask": "0.87"}], "timestamp": "1769384616898", "event_type": "price_change"}}
{"_local_timestamp": "2026-01-25T23:43:37.662552+00:00", "data": {"market": "0xac316c01625b0fa8dd06da51970c50c8fdd764f82e535b9e21d13613331023c4", "price_changes": [{"asset_id": "92711393135578327663235479520022176862589684688868437494076107570235367457535", "price": "0.03", "size": "30.27", "side": "BUY", "hash": "3447287977c1e45b0ad4353017c56f44d4142cfa", "best_bid": "0.13", "best_ask": "0.23"}, {"asset_id": "12995286023077810117688664821031077590385716779526746803320299864462527923165", "price": "0.97", "size": "30.27", "side": "SELL", "hash": "a0a3098e94d77fce7f923a78d3977bafdcdf95f1", "best_bid": "0.77", "best_ask": "0.87"}], "timestamp": "1769384617591", "event_type": "price_change"}}
{"_local_timestamp": "2026-01-25T23:43:37.663168+00:00", "data": {"market": "0x25ba0e34abf08ca67e940e0a9de39d77ab9969ba040b54d59b8c9557e7e1209e", "price_changes": [{"asset_id": "100230850484605537426827028089591201602750218213849583160902003942949141764541", "price": "0.01", "size": "202.65", "side": "BUY", "hash": "08de9dae59312c735a077684a58a70934e8d8e6b", "best_bid": "0.06", "best_ask": "0.96"}, {"asset_id": "34658822313166366862155307121179859104291458361815588542611104845760657957057", "price": "0.99", "size": "202.65", "side": "SELL", "hash": "b2fc0bc767afb6a34c62845e732505b34104e070", "best_bid": "0.04", "best_ask": "0.94"}], "timestamp": "1769384617591", "event_type": "price_change"}}
{"_local_timestamp": "2026-01-25T23:43:37.999365+00:00", "data": {"market": "0xdea4796b1330cc138fddbd7588ade544272dbbb5534d5c7e668d9793cd0eb88f", "price_changes": [{"asset_id": "110814814064089248423115833517094810833597085672984019468073735637142359900748", "price": "0.03", "size": "9.8", "side": "BUY", "hash": "6a78763aa44826238315f29929fc3091f4aa27bb", "best_bid": "0.05", "best_ask": "0.97"}, {"asset_id": "64337076081574293087836622474147344770540617949234564813925323344969252999147", "price": "0.97", "size": "9.8", "side": "SELL", "hash": "42a293ec0cab3ecdc9a14c914882d96825fef811", "best_bid": "0.03", "best_ask": "0.95"}], "timestamp": "1769384617933", "event_type": "price_change"}}
{"_local_timestamp": "2026-01-25T23:43:38.398412+00:00", "data": {"market": "0xdea4796b1330cc138fddbd7588ade544272dbbb5534d5c7e668d9793cd0eb88f", "price_changes": [{"asset_id": "110814814064089248423115833517094810833597085672984019468073735637142359900748", "price": "0.03", "size": "22.92", "side": "BUY", "hash": "86b431ef7d70a41dae3de7e3cd84c5108b49d411", "best_bid": "0.05", "best_ask": "0.97"}, {"asset_id": "64337076081574293087836622474147344770540617949234564813925323344969252999147", "price": "0.97", "size": "22.92", "side": "SELL", "hash": "f4fbaf55b9f3bb495069f523892579429af7c71b", "best_bid": "0.03", "best_ask": "0.95"}], "timestamp": "1769384618332", "event_type": "price_change"}}
{"_local_timestamp": "2026-01-25T23:43:39.880673+00:00", "data": {"market": "0xb4e3a03b7b9d32524e50a18643bc8b635f5db847ec228459e63ada4654232266", "price_changes": [{"asset_id": "61429815324316585285190173773753095389900760670737146252386183662368970056071", "price": "0.04", "size": "0", "side": "BUY", "hash": "48c5e70515d39c3f4a162fdc4e1b691929d04541", "best_bid": "0.05", "best_ask": "0.96"}, {"asset_id": "59015750890371857600345791870768842601163744323962019697925860773975224241703", "price": "0.96", "size": "0", "side": "SELL", "hash": "7c14c4187056894d64010f6e977a44e5b869278b", "best_bid": "0.04", "best_ask": "0.95"}], "timestamp": "1769384619812", "event_type": "price_change"}}
{"_local_timestamp": "2026-01-25T23:43:39.897798+00:00", "data": {"market": "0x25ba0e34abf08ca67e940e0a9de39d77ab9969ba040b54d59b8c9557e7e1209e", "price_changes": [{"asset_id": "100230850484605537426827028089591201602750218213849583160902003942949141764541", "price": "0.06", "size": "0", "side": "BUY", "hash": "ed7bd085522a2b8f2bbead03e74af75a25099647", "best_bid": "0.03", "best_ask": "0.96"}, {"asset_id": "34658822313166366862155307121179859104291458361815588542611104845760657957057", "price": "0.94", "size": "0", "side": "SELL", "hash": "1763fd278b9b41fa1e7a64cee4102fe7ac39409b", "best_bid": "0.04", "best_ask": "0.97"}], "timestamp": "1769384619812", "event_type": "price_change"}}
{"_local_timestamp": "2026-01-25T23:43:39.907726+00:00", "data": {"market": "0xdea4796b1330cc138fddbd7588ade544272dbbb5534d5c7e668d9793cd0eb88f", "price_changes": [{"asset_id": "110814814064089248423115833517094810833597085672984019468073735637142359900748", "price": "0.04", "size": "0", "side": "BUY", "hash": "efad92231532dcd5666bd83ac2f696c06f152f99", "best_bid": "0.05", "best_ask": "0.97"}, {"asset_id": "64337076081574293087836622474147344770540617949234564813925323344969252999147", "price": "0.96", "size": "0", "side": "SELL", "hash": "3da52e7f5773712357184887ec03930da8065ec1", "best_bid": "0.03", "best_ask": "0.95"}], "timestamp": "1769384619813", "event_type": "price_change"}}
{"_local_timestamp": "2026-01-25T23:43:39.908372+00:00", "data": {"market": "0x95fc9afae2e9bcfba41be1318b9b232c954d4066deb69293201f60e312e1deb2", "price_changes": [{"asset_id": "1398772603884009307910454931960162936237268068359444250489356436701623282401", "price": "0.04", "size": "0", "side": "BUY", "hash": "e19e5f215525308a5af9edba3c2e5c508673170c", "best_bid": "0.05", "best_ask": "0.97"}, {"asset_id": "59592741249661515665302592630910670026326604112506560769678078156146744114566", "price": "0.96", "size": "0", "side": "SELL", "hash": "ed51ed0622ac9cd9c260cdfdc33d50e25d64b0e1", "best_bid": "0.03", "best_ask": "0.95"}], "timestamp": "1769384619813", "event_type": "price_change"}}
{"_local_timestamp": "2026-01-25T23:43:40.209277+00:00", "data": {"market": "0x95fc9afae2e9bcfba41be1318b9b232c954d4066deb69293201f60e312e1deb2", "price_changes": [{"asset_id": "1398772603884009307910454931960162936237268068359444250489356436701623282401", "price": "0.06", "size": "5.47", "side": "BUY", "hash": "c8235a192683be4310f4894809cd299d84add3a7", "best_bid": "0.06", "best_ask": "0.97"}, {"asset_id": "59592741249661515665302592630910670026326604112506560769678078156146744114566", "price": "0.94", "size": "5.47", "side": "SELL", "hash": "fbcc60402adfe2ac37357d425692ba3eb39ba540", "best_bid": "0.03", "best_ask": "0.94"}], "timestamp": "1769384620121", "event_type": "price_change"}}
{"_local_timestamp": "2026-01-25T23:43:40.209906+00:00", "data": {"market": "0x25ba0e34abf08ca67e940e0a9de39d77ab9969ba040b54d59b8c9557e7e1209e", "price_changes": [{"asset_id": "100230850484605537426827028089591201602750218213849583160902003942949141764541", "price": "0.04", "size": "5.47", "side": "BUY", "hash": "4beb5660a27d8c03dae631d81c05ded918247bf1", "best_bid": "0.04", "best_ask": "0.96"}, {"asset_id": "34658822313166366862155307121179859104291458361815588542611104845760657957057", "price": "0.96", "size": "5.47", "side": "SELL", "hash": "99e05756801252fcc3ff239a072ce8b37585eab0", "best_bid": "0.04", "best_ask": "0.96"}], "timestamp": "1769384620121", "event_type": "price_change"}}
{"_local_timestamp": "2026-01-25T23:43:40.210568+00:00", "data": {"market": "0xdea4796b1330cc138fddbd7588ade544272dbbb5534d5c7e668d9793cd0eb88f", "price_changes": [{"asset_id": "110814814064089248423115833517094810833597085672984019468073735637142359900748", "price": "0.06", "size": "5.47", "side": "BUY", "hash": "5b4222fee3f8530c4e62864481ddb94ec627596e", "best_bid": "0.06", "best_ask": "0.97"}, {"asset_id": "64337076081574293087836622474147344770540617949234564813925323344969252999147", "price": "0.94", "size": "5.47", "side": "SELL", "hash": "93c6a891eacf4d13af7d57f86f64baa15aa0ddf9", "best_bid": "0.03", "best_ask": "0.94"}], "timestamp": "1769384620121", "event_type": "price_change"}}
{"_local_timestamp": "2026-01-25T23:43:40.211104+00:00", "data": {"market": "0xb4e3a03b7b9d32524e50a18643bc8b635f5db847ec228459e63ada4654232266", "price_changes": [{"asset_id": "61429815324316585285190173773753095389900760670737146252386183662368970056071", "price": "0.06", "size": "5.47", "side": "BUY", "hash": "036b6967856df4a61fda0b66004c3b36858753f5", "best_bid": "0.06", "best_ask": "0.96"}, {"asset_id": "59015750890371857600345791870768842601163744323962019697925860773975224241703", "price": "0.94", "size": "5.47", "side": "SELL", "hash": "c71427f8dbc7beaeb99d111be0fc288776bc3022", "best_bid": "0.04", "best_ask": "0.94"}], "timestamp": "1769384620122", "event_type": "price_change"}}
{"_local_timestamp": "2026-01-25T23:45:09.828931+00:00", "data": {"market": "0xdea4796b1330cc138fddbd7588ade544272dbbb5534d5c7e668d9793cd0eb88f", "price_changes": [{"asset_id": "110814814064089248423115833517094810833597085672984019468073735637142359900748", "price": "0.05", "size": "0", "side": "BUY", "hash": "1b3b14fa7901a87fdc45995ba5d5d19281e754b3", "best_bid": "0.06", "best_ask": "0.97"}, {"asset_id": "64337076081574293087836622474147344770540617949234564813925323344969252999147", "price": "0.95", "size": "0", "side": "SELL", "hash": "90ad5b089779ef8108147f557399ed1dae11019d", "best_bid": "0.03", "best_ask": "0.94"}], "timestamp": "1769384709760", "event_type": "price_change"}}
{"_local_timestamp": "2026-01-25T23:45:09.924489+00:00", "data": {"market": "0x95fc9afae2e9bcfba41be1318b9b232c954d4066deb69293201f60e312e1deb2", "price_changes": [{"asset_id": "1398772603884009307910454931960162936237268068359444250489356436701623282401", "price": "0.05", "size": "0", "side": "BUY", "hash": "c9732df02450fd079c3183d4b074d91bb6bf7d63", "best_bid": "0.06", "best_ask": "0.97"}, {"asset_id": "59592741249661515665302592630910670026326604112506560769678078156146744114566", "price": "0.95", "size": "0", "side": "SELL", "hash": "9a354fdca7cd65b231bf5a9e418f8e3714a41f7e", "best_bid": "0.03", "best_ask": "0.94"}], "timestamp": "1769384709855", "event_type": "price_change"}}
{"_local_timestamp": "2026-01-25T23:45:09.925022+00:00", "data": {"market": "0xb4e3a03b7b9d32524e50a18643bc8b635f5db847ec228459e63ada4654232266", "price_changes": [{"asset_id": "61429815324316585285190173773753095389900760670737146252386183662368970056071", "price": "0.05", "size": "0", "side": "BUY", "hash": "54daa8aca85602baab7fe0f2a7fa4a2f27be5626", "best_bid": "0.06", "best_ask": "0.96"}, {"asset_id": "59015750890371857600345791870768842601163744323962019697925860773975224241703", "price": "0.95", "size": "0", "side": "SELL", "hash": "24acecf6249a0dd67b31b419baca3f6b53e94146", "best_bid": "0.04", "best_ask": "0.94"}], "timestamp": "1769384709855", "event_type": "price_change"}}
{"_local_timestamp": "2026-01-25T23:45:11.853113+00:00", "data": {"market": "0xdea4796b1330cc138fddbd7588ade544272dbbb5534d5c7e668d9793cd0eb88f", "price_changes": [{"asset_id": "110814814064089248423115833517094810833597085672984019468073735637142359900748", "price": "0.06", "size": "0", "side": "BUY", "hash": "9d56a3fe4d579f3f8af0dd40a99ea7d31d15a727", "best_bid": "0.03", "best_ask": "0.97"}, {"asset_id": "64337076081574293087836622474147344770540617949234564813925323344969252999147", "price": "0.94", "size": "0", "side": "SELL", "hash": "7798a057bd5de2741633282433e716bd69c099b0", "best_bid": "0.03", "best_ask": "0.97"}], "timestamp": "1769384711771", "event_type": "price_change"}}
{"_local_timestamp": "2026-01-25T23:45:11.853758+00:00", "data": {"market": "0x95fc9afae2e9bcfba41be1318b9b232c954d4066deb69293201f60e312e1deb2", "price_changes": [{"asset_id": "1398772603884009307910454931960162936237268068359444250489356436701623282401", "price": "0.06", "size": "0", "side": "BUY", "hash": "206c9ce986ef75a3664d1ba8545d9617782ee464", "best_bid": "0.03", "best_ask": "0.97"}, {"asset_id": "59592741249661515665302592630910670026326604112506560769678078156146744114566", "price": "0.94", "size": "0", "side": "SELL", "hash": "5bfbd0abb2bd9013d813b3424f0498464ec6a9a7", "best_bid": "0.03", "best_ask": "0.97"}], "timestamp": "1769384711771", "event_type": "price_change"}}
{"_local_timestamp": "2026-01-25T23:45:11.857390+00:00", "data": {"market": "0xb4e3a03b7b9d32524e50a18643bc8b635f5db847ec228459e63ada4654232266", "price_changes": [{"asset_id": "61429815324316585285190173773753095389900760670737146252386183662368970056071", "price": "0.06", "size": "0", "side": "BUY", "hash": "da535fd66c94a31b085d67a416cdaa8d80cc83b4", "best_bid": "0.03", "best_ask": "0.96"}, {"asset_id": "59015750890371857600345791870768842601163744323962019697925860773975224241703", "price": "0.94", "size": "0", "side": "SELL", "hash": "40dbe679d1a48fb5e70ab0fc9a03028a324eba92", "best_bid": "0.04", "best_ask": "0.97"}], "timestamp": "1769384711771", "event_type": "price_change"}}
{"_local_timestamp": "2026-01-25T23:45:12.146193+00:00", "data": {"market": "0x95fc9afae2e9bcfba41be1318b9b232c954d4066deb69293201f60e312e1deb2", "price_changes": [{"asset_id": "1398772603884009307910454931960162936237268068359444250489356436701623282401", "price": "0.04", "size": "5.47", "side": "BUY", "hash": "c829329ee4c53f81069af2c24bc76aa1b79297f3", "best_bid": "0.04", "best_ask": "0.97"}, {"asset_id": "59592741249661515665302592630910670026326604112506560769678078156146744114566", "price": "0.96", "size": "5.47", "side": "SELL", "hash": "decac28450370ca3b54dddb780ac1b253715b8ba", "best_bid": "0.03", "best_ask": "0.96"}], "timestamp": "1769384712067", "event_type": "price_change"}}
{"_local_timestamp": "2026-01-25T23:45:12.146804+00:00", "data": {"market": "0xb4e3a03b7b9d32524e50a18643bc8b635f5db847ec228459e63ada4654232266", "price_changes": [{"asset_id": "61429815324316585285190173773753095389900760670737146252386183662368970056071", "price": "0.04", "size": "5.47", "side": "BUY", "hash": "13224355e2b6c39e33ebc9a02fbbb347c10ea556", "best_bid": "0.04", "best_ask": "0.96"}, {"asset_id": "59015750890371857600345791870768842601163744323962019697925860773975224241703", "price": "0.96", "size": "5.47", "side": "SELL", "hash": "5b1be66bbb830154f52d25aa76c06b9ac42044d5", "best_bid": "0.04", "best_ask": "0.96"}], "timestamp": "1769384712067", "event_type": "price_change"}}
{"_local_timestamp": "2026-01-25T23:45:12.147343+00:00", "data": {"market": "0xdea4796b1330cc138fddbd7588ade544272dbbb5534d5c7e668d9793cd0eb88f", "price_changes": [{"asset_id": "110814814064089248423115833517094810833597085672984019468073735637142359900748", "price": "0.04", "size": "5.47", "side": "BUY", "hash": "5f63f0428218881e7664e3dd8db30a8a934ad881", "best_bid": "0.04", "best_ask": "0.97"}, {"asset_id": "64337076081574293087836622474147344770540617949234564813925323344969252999147", "price": "0.96", "size": "5.47", "side": "SELL", "hash": "6eb43fb3c8c17b1d4c162c49051c0860aea80029", "best_bid": "0.03", "best_ask": "0.96"}], "timestamp": "1769384712067", "event_type": "price_change"}}
{"_local_timestamp": "2026-01-25T23:45:27.170068+00:00", "data": {"market": "0xc9855139cab97e536de1cd15906fa7b3f9ae4e078af5aad9e944816bb2159711", "price_changes": [{"asset_id": "85494679103805115610079943463933518665037708338189637736300704310010756140302", "price": "0.04", "size": "0", "side": "BUY", "hash": "5d11cf5a202f54bc77faadfef1cbcee613a7d847", "best_bid": "0.05", "best_ask": "0.13"}, {"asset_id": "33702039415152587930284278059349972411131709035008901806037913666966254369742", "price": "0.96", "size": "0", "side": "SELL", "hash": "934942877b83238d0f627009e2af8445e644d1a5", "best_bid": "0.87", "best_ask": "0.95"}], "timestamp": "1769384727105", "event_type": "price_change"}}
{"_local_timestamp": "2026-01-25T23:45:28.358562+00:00", "data": {"market": "0xc9855139cab97e536de1cd15906fa7b3f9ae4e078af5aad9e944816bb2159711", "price_changes": [{"asset_id": "85494679103805115610079943463933518665037708338189637736300704310010756140302", "price": "0.04", "size": "14.24", "side": "BUY", "hash": "4a93122dbc14ef006da3d1073ecb00f90e0c0dda", "best_bid": "0.05", "best_ask": "0.13"}, {"asset_id": "33702039415152587930284278059349972411131709035008901806037913666966254369742", "price": "0.96", "size": "14.24", "side": "SELL", "hash": "8d319b5f7be13394240cb1431c1073caadb7f234", "best_bid": "0.87", "best_ask": "0.95"}], "timestamp": "1769384728291", "event_type": "price_change"}}
{"_local_timestamp": "2026-01-25T23:45:28.499389+00:00", "data": {"market": "0x723f251ab60ea2dd4f99374a74f80be8548c2c4fe2cca22f2fa6f90bd905b559", "price_changes": [{"asset_id": "48978425543742752818803322458870690562079517439055041342251621857158978447363", "price": "0.03", "size": "6.02", "side": "BUY", "hash": "23d03b83fb526319b8ab676d90acd8eb82abf50c", "best_bid": "0.14", "best_ask": "0.23"}, {"asset_id": "112174093579349393205957859148865812063897305228582002453213788215242068235765", "price": "0.97", "size": "6.02", "side": "SELL", "hash": "e40169eb381bf64322d4b482118985d151b285dc", "best_bid": "0.77", "best_ask": "0.86"}], "timestamp": "1769384728424", "event_type": "price_change"}}
{"_local_timestamp": "2026-01-25T23:45:28.499985+00:00", "data": {"market": "0xac316c01625b0fa8dd06da51970c50c8fdd764f82e535b9e21d13613331023c4", "price_changes": [{"asset_id": "92711393135578327663235479520022176862589684688868437494076107570235367457535", "price": "0.03", "size": "6.02", "side": "BUY", "hash": "3d0320cd2946d0d874b4bbee912b0cfa83f82151", "best_bid": "0.13", "best_ask": "0.23"}, {"asset_id": "12995286023077810117688664821031077590385716779526746803320299864462527923165", "price": "0.97", "size": "6.02", "side": "SELL", "hash": "3cb81fa11363094b47bde7eb5b9340f5c91fe31c", "best_bid": "0.77", "best_ask": "0.87"}], "timestamp": "1769384728424", "event_type": "price_change"}}
{"_local_timestamp": "2026-01-25T23:45:28.500540+00:00", "data": {"market": "0xdea4796b1330cc138fddbd7588ade544272dbbb5534d5c7e668d9793cd0eb88f", "price_changes": [{"asset_id": "110814814064089248423115833517094810833597085672984019468073735637142359900748", "price": "0.03", "size": "9.8", "side": "BUY", "hash": "5f3f42bb7e28f1efbbe7fb606b9163a9b4e5736b", "best_bid": "0.04", "best_ask": "0.97"}, {"asset_id": "64337076081574293087836622474147344770540617949234564813925323344969252999147", "price": "0.97", "size": "9.8", "side": "SELL", "hash": "096126449598a912e203a0987bbb08bcbac12c82", "best_bid": "0.03", "best_ask": "0.96"}], "timestamp": "1769384728424", "event_type": "price_change"}}
{"_local_timestamp": "2026-01-25T23:45:29.134098+00:00", "data": {"market": "0xac316c01625b0fa8dd06da51970c50c8fdd764f82e535b9e21d13613331023c4", "price_changes": [{"asset_id": "92711393135578327663235479520022176862589684688868437494076107570235367457535", "price": "0.03", "size": "30.27", "side": "BUY", "hash": "86165ab8e21aa256baf2e9fdf2e36420de7bc437", "best_bid": "0.13", "best_ask": "0.23"}, {"asset_id": "12995286023077810117688664821031077590385716779526746803320299864462527923165", "price": "0.97", "size": "30.27", "side": "SELL", "hash": "61ba0024229f2df6f9b87190dbfd7e2e0573232c", "best_bid": "0.77", "best_ask": "0.87"}], "timestamp": "1769384729042", "event_type": "price_change"}}
{"_local_timestamp": "2026-01-25T23:45:31.354807+00:00", "data": {"market": "0x723f251ab60ea2dd4f99374a74f80be8548c2c4fe2cca22f2fa6f90bd905b559", "price_changes": [{"asset_id": "48978425543742752818803322458870690562079517439055041342251621857158978447363", "price": "0.03", "size": "30.27", "side": "BUY", "hash": "cc8fcd2a7a97f7e697a385fc408da9b87ef6228b", "best_bid": "0.14", "best_ask": "0.23"}, {"asset_id": "112174093579349393205957859148865812063897305228582002453213788215242068235765", "price": "0.97", "size": "30.27", "side": "SELL", "hash": "e9b861b67df18ac6bca3ce0cfd95a615d789a919", "best_bid": "0.77", "best_ask": "0.86"}], "timestamp": "1769384731284", "event_type": "price_change"}}
{"_local_timestamp": "2026-01-25T23:45:31.355562+00:00", "data": {"market": "0xdea4796b1330cc138fddbd7588ade544272dbbb5534d5c7e668d9793cd0eb88f", "price_changes": [{"asset_id": "110814814064089248423115833517094810833597085672984019468073735637142359900748", "price": "0.03", "size": "22.92", "side": "BUY", "hash": "550b23dbc988bd598c4db23d4c257bc990deb542", "best_bid": "0.04", "best_ask": "0.97"}, {"asset_id": "64337076081574293087836622474147344770540617949234564813925323344969252999147", "price": "0.97", "size": "22.92", "side": "SELL", "hash": "c3364c4758a353d795310de43d90053424c4d3ed", "best_bid": "0.03", "best_ask": "0.96"}], "timestamp": "1769384731285", "event_type": "price_change"}}
{"_local_timestamp": "2026-01-25T23:46:49.021097+00:00", "data": {"market": "0x95fc9afae2e9bcfba41be1318b9b232c954d4066deb69293201f60e312e1deb2", "price_changes": [{"asset_id": "1398772603884009307910454931960162936237268068359444250489356436701623282401", "price": "0.05", "size": "23.99", "side": "BUY", "hash": "e8e77e60dce6f0edc6d1856e2332df7d2aa908c1", "best_bid": "0.05", "best_ask": "0.97"}, {"asset_id": "59592741249661515665302592630910670026326604112506560769678078156146744114566", "price": "0.95", "size": "23.99", "side": "SELL", "hash": "42a5e9175ee145caac5466c7b5ac2bf6ac7b60b8", "best_bid": "0.03", "best_ask": "0.95"}], "timestamp": "1769384808827", "event_type": "price_change"}}
{"_local_timestamp": "2026-01-25T23:46:49.021991+00:00", "data": {"market": "0xdea4796b1330cc138fddbd7588ade544272dbbb5534d5c7e668d9793cd0eb88f", "price_changes": [{"asset_id": "110814814064089248423115833517094810833597085672984019468073735637142359900748", "price": "0.05", "size": "23.99", "side": "BUY", "hash": "99718886405ecab09f05efea07b90fe73836facf", "best_bid": "0.05", "best_ask": "0.97"}, {"asset_id": "64337076081574293087836622474147344770540617949234564813925323344969252999147", "price": "0.95", "size": "23.99", "side": "SELL", "hash": "2a3779eb656dbb10fa9850993ca531a15eb7c2b2", "best_bid": "0.03", "best_ask": "0.95"}], "timestamp": "1769384808827", "event_type": "price_change"}}
{"_local_timestamp": "2026-01-25T23:46:49.111255+00:00", "data": {"market": "0xb4e3a03b7b9d32524e50a18643bc8b635f5db847ec228459e63ada4654232266", "price_changes": [{"asset_id": "61429815324316585285190173773753095389900760670737146252386183662368970056071", "price": "0.05", "size": "23.99", "side": "BUY", "hash": "2e2d4f73d07ea9b3b002ff22efc4acad2c39bdce", "best_bid": "0.05", "best_ask": "0.96"}, {"asset_id": "59015750890371857600345791870768842601163744323962019697925860773975224241703", "price": "0.95", "size": "23.99", "side": "SELL", "hash": "57c5e2a6ef59ab104027f85d794f7de3bf0e9172", "best_bid": "0.04", "best_ask": "0.95"}], "timestamp": "1769384808922", "event_type": "price_change"}}
{"_local_timestamp": "2026-01-25T23:46:50.132415+00:00", "data": {"market": "0x95fc9afae2e9bcfba41be1318b9b232c954d4066deb69293201f60e312e1deb2", "price_changes": [{"asset_id": "1398772603884009307910454931960162936237268068359444250489356436701623282401", "price": "0.04", "size": "0", "side": "BUY", "hash": "7810c91b21e671814f728429ea1591c24d45f401", "best_bid": "0.05", "best_ask": "0.97"}, {"asset_id": "59592741249661515665302592630910670026326604112506560769678078156146744114566", "price": "0.96", "size": "0", "side": "SELL", "hash": "e6b4f55648db535a127ea44cab5c1d4faf689f10", "best_bid": "0.03", "best_ask": "0.95"}], "timestamp": "1769384809945", "event_type": "price_change"}}
{"_local_timestamp": "2026-01-25T23:46:50.152903+00:00", "data": {"market": "0xb4e3a03b7b9d32524e50a18643bc8b635f5db847ec228459e63ada4654232266", "price_changes": [{"asset_id": "61429815324316585285190173773753095389900760670737146252386183662368970056071", "price": "0.04", "size": "0", "side": "BUY", "hash": "f71f7bcace3a2dbaf0d526ba955483340192f43e", "best_bid": "0.05", "best_ask": "0.96"}, {"asset_id": "59015750890371857600345791870768842601163744323962019697925860773975224241703", "price": "0.96", "size": "0", "side": "SELL", "hash": "5b03c3c3bdfbe0b5aaa4c0d2377cfcf55b1e89ba", "best_bid": "0.04", "best_ask": "0.95"}], "timestamp": "1769384809945", "event_type": "price_change"}}
{"_local_timestamp": "2026-01-25T23:46:50.153510+00:00", "data": {"market": "0xdea4796b1330cc138fddbd7588ade544272dbbb5534d5c7e668d9793cd0eb88f", "price_changes": [{"asset_id": "110814814064089248423115833517094810833597085672984019468073735637142359900748", "price": "0.04", "size": "0", "side": "BUY", "hash": "819cb320d3ec6ea88ff3369de55efcef9a503578", "best_bid": "0.05", "best_ask": "0.97"}, {"asset_id": "64337076081574293087836622474147344770540617949234564813925323344969252999147", "price": "0.96", "size": "0", "side": "SELL", "hash": "4992682ff44e34addd3e31986292fb3514d704ab", "best_bid": "0.03", "best_ask": "0.95"}], "timestamp": "1769384809945", "event_type": "price_change"}}
{"_local_timestamp": "2026-01-25T23:46:50.327117+00:00", "data": {"market": "0x95fc9afae2e9bcfba41be1318b9b232c954d4066deb69293201f60e312e1deb2", "price_changes": [{"asset_id": "1398772603884009307910454931960162936237268068359444250489356436701623282401", "price": "0.06", "size": "5.47", "side": "BUY", "hash": "5f840d859a7bf3ede32cbd2872322272405a3c07", "best_bid": "0.06", "best_ask": "0.97"}, {"asset_id": "59592741249661515665302592630910670026326604112506560769678078156146744114566", "price": "0.94", "size": "5.47", "side": "SELL", "hash": "382147ee75d89107f566a59afbe466122e80319c", "best_bid": "0.03", "best_ask": "0.94"}], "timestamp": "1769384810156", "event_type": "price_change"}}
{"_local_timestamp": "2026-01-25T23:46:50.330660+00:00", "data": {"market": "0xdea4796b1330cc138fddbd7588ade544272dbbb5534d5c7e668d9793cd0eb88f", "price_changes": [{"asset_id": "110814814064089248423115833517094810833597085672984019468073735637142359900748", "price": "0.06", "size": "5.47", "side": "BUY", "hash": "9e4e601d7fb82e5b864df33ca9ff0c70dfec768a", "best_bid": "0.06", "best_ask": "0.97"}, {"asset_id": "64337076081574293087836622474147344770540617949234564813925323344969252999147", "price": "0.94", "size": "5.47", "side": "SELL", "hash": "94ae6aa93e8b8f90c98f4e59f6653a3bd154d7f1", "best_bid": "0.03", "best_ask": "0.94"}], "timestamp": "1769384810157", "event_type": "price_change"}}
{"_local_timestamp": "2026-01-25T23:46:50.331284+00:00", "data": {"market": "0xb4e3a03b7b9d32524e50a18643bc8b635f5db847ec228459e63ada4654232266", "price_changes": [{"asset_id": "61429815324316585285190173773753095389900760670737146252386183662368970056071", "price": "0.06", "size": "5.47", "side": "BUY", "hash": "f7a9de11b5ab8957b224ea9a61d4f573ff010839", "best_bid": "0.06", "best_ask": "0.96"}, {"asset_id": "59015750890371857600345791870768842601163744323962019697925860773975224241703", "price": "0.94", "size": "5.47", "side": "SELL", "hash": "cd7ddfe4b131c85698537cf9213515ac144c254a", "best_bid": "0.04", "best_ask": "0.94"}], "timestamp": "1769384810156", "event_type": "price_change"}}
{"_local_timestamp": "2026-01-25T23:48:18.098930+00:00", "data": {"market": "0x95fc9afae2e9bcfba41be1318b9b232c954d4066deb69293201f60e312e1deb2", "price_changes": [{"asset_id": "1398772603884009307910454931960162936237268068359444250489356436701623282401", "price": "0.05", "size": "0", "side": "BUY", "hash": "243ac60b1ad62237cf2c26661e2bbf372ec22ae8", "best_bid": "0.06", "best_ask": "0.97"}, {"asset_id": "59592741249661515665302592630910670026326604112506560769678078156146744114566", "price": "0.95", "size": "0", "side": "SELL", "hash": "45812e3b8aaae0886ff2aff45361bb5cedaf05a6", "best_bid": "0.03", "best_ask": "0.94"}], "timestamp": "1769384898005", "event_type": "price_change"}}
{"_local_timestamp": "2026-01-25T23:48:18.100703+00:00", "data": {"market": "0xdea4796b1330cc138fddbd7588ade544272dbbb5534d5c7e668d9793cd0eb88f", "price_changes": [{"asset_id": "110814814064089248423115833517094810833597085672984019468073735637142359900748", "price": "0.05", "size": "0", "side": "BUY", "hash": "8de40813a8663ca3189ff15bacf797aa1293ad23", "best_bid": "0.06", "best_ask": "0.97"}, {"asset_id": "64337076081574293087836622474147344770540617949234564813925323344969252999147", "price": "0.95", "size": "0", "side": "SELL", "hash": "04d5e277bb055a310758ceb4eca8937ac8b36845", "best_bid": "0.03", "best_ask": "0.94"}], "timestamp": "1769384898005", "event_type": "price_change"}}
{"_local_timestamp": "2026-01-25T23:48:18.101308+00:00", "data": {"market": "0xb4e3a03b7b9d32524e50a18643bc8b635f5db847ec228459e63ada4654232266", "price_changes": [{"asset_id": "61429815324316585285190173773753095389900760670737146252386183662368970056071", "price": "0.05", "size": "0", "side": "BUY", "hash": "a0c8ec6c60f66710de3ea08d6be8ebe6ac74ee9a", "best_bid": "0.06", "best_ask": "0.96"}, {"asset_id": "59015750890371857600345791870768842601163744323962019697925860773975224241703", "price": "0.95", "size": "0", "side": "SELL", "hash": "38c6b60c28bf7601a9db9072c836475401335e99", "best_bid": "0.04", "best_ask": "0.94"}], "timestamp": "1769384898005", "event_type": "price_change"}}
{"_local_timestamp": "2026-01-25T23:48:18.922906+00:00", "data": {"market": "0x25ba0e34abf08ca67e940e0a9de39d77ab9969ba040b54d59b8c9557e7e1209e", "price_changes": [{"asset_id": "100230850484605537426827028089591201602750218213849583160902003942949141764541", "price": "0.05", "size": "23.99", "side": "BUY", "hash": "6483cbd856dc8fd18b168d92cb3407ed208068ef", "best_bid": "0.05", "best_ask": "0.96"}, {"asset_id": "34658822313166366862155307121179859104291458361815588542611104845760657957057", "price": "0.95", "size": "23.99", "side": "SELL", "hash": "865b723a74d13b1941105030a18e40772237e8c6", "best_bid": "0.04", "best_ask": "0.95"}], "timestamp": "1769384898856", "event_type": "price_change"}}
{"_local_timestamp": "2026-01-25T23:48:21.750004+00:00", "data": {"market": "0x25ba0e34abf08ca67e940e0a9de39d77ab9969ba040b54d59b8c9557e7e1209e", "price_changes": [{"asset_id": "100230850484605537426827028089591201602750218213849583160902003942949141764541", "price": "0.04", "size": "0", "side": "BUY", "hash": "81494f1ef07399c17c3a326f411535d688f38313", "best_bid": "0.05", "best_ask": "0.96"}, {"asset_id": "34658822313166366862155307121179859104291458361815588542611104845760657957057", "price": "0.96", "size": "0", "side": "SELL", "hash": "9c6343b682e73f00ebcb23137a407dcaed3fd3e7", "best_bid": "0.04", "best_ask": "0.95"}], "timestamp": "1769384901682", "event_type": "price_change"}}
{"_local_timestamp": "2026-01-25T23:48:21.753173+00:00", "data": {"market": "0xb4e3a03b7b9d32524e50a18643bc8b635f5db847ec228459e63ada4654232266", "price_changes": [{"asset_id": "61429815324316585285190173773753095389900760670737146252386183662368970056071", "price": "0.06", "size": "0", "side": "BUY", "hash": "6fa48c3e87d7f673a2bc9f12c34355b3975dc0bf", "best_bid": "0.03", "best_ask": "0.96"}, {"asset_id": "59015750890371857600345791870768842601163744323962019697925860773975224241703", "price": "0.94", "size": "0", "side": "SELL", "hash": "f067be66c898deaf8ad92f399bf4ef8760d84978", "best_bid": "0.04", "best_ask": "0.97"}], "timestamp": "1769384901682", "event_type": "price_change"}}
{"_local_timestamp": "2026-01-25T23:48:21.760864+00:00", "data": {"market": "0xdea4796b1330cc138fddbd7588ade544272dbbb5534d5c7e668d9793cd0eb88f", "price_changes": [{"asset_id": "110814814064089248423115833517094810833597085672984019468073735637142359900748", "price": "0.06", "size": "0", "side": "BUY", "hash": "b8dc8043fcc504a94320bdfd6b38a10111c6d6d5", "best_bid": "0.03", "best_ask": "0.97"}, {"asset_id": "64337076081574293087836622474147344770540617949234564813925323344969252999147", "price": "0.94", "size": "0", "side": "SELL", "hash": "4437e53645dee2315092cf0d40aa792f8c32a25e", "best_bid": "0.03", "best_ask": "0.97"}], "timestamp": "1769384901682", "event_type": "price_change"}}
{"_local_timestamp": "2026-01-25T23:48:21.769684+00:00", "data": {"market": "0x95fc9afae2e9bcfba41be1318b9b232c954d4066deb69293201f60e312e1deb2", "price_changes": [{"asset_id": "1398772603884009307910454931960162936237268068359444250489356436701623282401", "price": "0.06", "size": "0", "side": "BUY", "hash": "8bf9795eedf51a9656e2ceb88f353b3f5c94ca70", "best_bid": "0.03", "best_ask": "0.97"}, {"asset_id": "59592741249661515665302592630910670026326604112506560769678078156146744114566", "price": "0.94", "size": "0", "side": "SELL", "hash": "6e1987f9cfe5f1a6d80c5e63a66ce0f7de9b997e", "best_bid": "0.03", "best_ask": "0.97"}], "timestamp": "1769384901682", "event_type": "price_change"}}
{"_local_timestamp": "2026-01-25T23:48:22.180566+00:00", "data": {"market": "0x95fc9afae2e9bcfba41be1318b9b232c954d4066deb69293201f60e312e1deb2", "price_changes": [{"asset_id": "1398772603884009307910454931960162936237268068359444250489356436701623282401", "price": "0.04", "size": "5.47", "side": "BUY", "hash": "53cfb5415ef532112630cdc4e2479595fe932040", "best_bid": "0.04", "best_ask": "0.97"}, {"asset_id": "59592741249661515665302592630910670026326604112506560769678078156146744114566", "price": "0.96", "size": "5.47", "side": "SELL", "hash": "2b554066bbe42566a83470267f1996a8e274f4ed", "best_bid": "0.03", "best_ask": "0.96"}], "timestamp": "1769384902096", "event_type": "price_change"}}
{"_local_timestamp": "2026-01-25T23:48:22.181196+00:00", "data": {"market": "0x25ba0e34abf08ca67e940e0a9de39d77ab9969ba040b54d59b8c9557e7e1209e", "price_changes": [{"asset_id": "100230850484605537426827028089591201602750218213849583160902003942949141764541", "price": "0.06", "size": "5.47", "side": "BUY", "hash": "7e7c6cd9c2ee5d10812cc0623d9ce2ae09df0259", "best_bid": "0.06", "best_ask": "0.96"}, {"asset_id": "34658822313166366862155307121179859104291458361815588542611104845760657957057", "price": "0.94", "size": "5.47", "side": "SELL", "hash": "eaaf2d6dc3d5ccf452d1b4c398b879745f696b2b", "best_bid": "0.04", "best_ask": "0.94"}], "timestamp": "1769384902097", "event_type": "price_change"}}
{"_local_timestamp": "2026-01-25T23:48:22.182571+00:00", "data": {"market": "0xb4e3a03b7b9d32524e50a18643bc8b635f5db847ec228459e63ada4654232266", "price_changes": [{"asset_id": "61429815324316585285190173773753095389900760670737146252386183662368970056071", "price": "0.04", "size": "5.47", "side": "BUY", "hash": "357d1c6704d855b660901d67894795cc63054eb2", "best_bid": "0.04", "best_ask": "0.96"}, {"asset_id": "59015750890371857600345791870768842601163744323962019697925860773975224241703", "price": "0.96", "size": "5.47", "side": "SELL", "hash": "cf2eaadc0678710412e453fe649164319b0e2a1a", "best_bid": "0.04", "best_ask": "0.96"}], "timestamp": "1769384902097", "event_type": "price_change"}}
{"_local_timestamp": "2026-01-25T23:48:22.183194+00:00", "data": {"market": "0xdea4796b1330cc138fddbd7588ade544272dbbb5534d5c7e668d9793cd0eb88f", "price_changes": [{"asset_id": "110814814064089248423115833517094810833597085672984019468073735637142359900748", "price": "0.04", "size": "5.47", "side": "BUY", "hash": "25aea5800d7425abd250be8dd504d44af7d59057", "best_bid": "0.04", "best_ask": "0.97"}, {"asset_id": "64337076081574293087836622474147344770540617949234564813925323344969252999147", "price": "0.96", "size": "5.47", "side": "SELL", "hash": "8101d16538e1207d6e578fae6a02a90f41c17876", "best_bid": "0.03", "best_ask": "0.96"}], "timestamp": "1769384902097", "event_type": "price_change"}}
{"_local_timestamp": "2026-01-25T23:49:33.965348+00:00", "data": {"market": "0xdea4796b1330cc138fddbd7588ade544272dbbb5534d5c7e668d9793cd0eb88f", "price_changes": [{"asset_id": "110814814064089248423115833517094810833597085672984019468073735637142359900748", "price": "0.03", "size": "9.8", "side": "BUY", "hash": "334de76b489e54cf13f57b2140d82e7466498052", "best_bid": "0.04", "best_ask": "0.97"}, {"asset_id": "64337076081574293087836622474147344770540617949234564813925323344969252999147", "price": "0.97", "size": "9.8", "side": "SELL", "hash": "cf33aca2f0f380c7f449b78d17c3b68fb56747b7", "best_bid": "0.03", "best_ask": "0.96"}], "timestamp": "1769384973900", "event_type": "price_change"}}
{"_local_timestamp": "2026-01-25T23:49:33.969359+00:00", "data": {"market": "0xc9855139cab97e536de1cd15906fa7b3f9ae4e078af5aad9e944816bb2159711", "price_changes": [{"asset_id": "85494679103805115610079943463933518665037708338189637736300704310010756140302", "price": "0.04", "size": "0", "side": "BUY", "hash": "7bda4aa95e15baa0f545a98034ed0fa9cf6ee6d0", "best_bid": "0.05", "best_ask": "0.13"}, {"asset_id": "33702039415152587930284278059349972411131709035008901806037913666966254369742", "price": "0.96", "size": "0", "side": "SELL", "hash": "c228a810ce8da6408cc2555df3aa36c32b676cfa", "best_bid": "0.87", "best_ask": "0.95"}], "timestamp": "1769384973900", "event_type": "price_change"}}
{"_local_timestamp": "2026-01-25T23:49:34.342678+00:00", "data": {"market": "0xdea4796b1330cc138fddbd7588ade544272dbbb5534d5c7e668d9793cd0eb88f", "price_changes": [{"asset_id": "110814814064089248423115833517094810833597085672984019468073735637142359900748", "price": "0.03", "size": "22.92", "side": "BUY", "hash": "ba3a4dc9428d23759c6924eb472ae374689bca35", "best_bid": "0.04", "best_ask": "0.97"}, {"asset_id": "64337076081574293087836622474147344770540617949234564813925323344969252999147", "price": "0.97", "size": "22.92", "side": "SELL", "hash": "9f4cc5c8c5bf9c41f1d4fb315fe016e3d38523f8", "best_bid": "0.03", "best_ask": "0.96"}], "timestamp": "1769384974276", "event_type": "price_change"}}
{"_local_timestamp": "2026-01-25T23:49:34.343321+00:00", "data": {"market": "0xc9855139cab97e536de1cd15906fa7b3f9ae4e078af5aad9e944816bb2159711", "price_changes": [{"asset_id": "85494679103805115610079943463933518665037708338189637736300704310010756140302", "price": "0.04", "size": "14.24", "side": "BUY", "hash": "75de9e96c21df2b3a6b3a019b77e8a0cf2927086", "best_bid": "0.05", "best_ask": "0.13"}, {"asset_id": "33702039415152587930284278059349972411131709035008901806037913666966254369742", "price": "0.96", "size": "14.24", "side": "SELL", "hash": "f5e616e6f0aef34fbdf5c087d4b719f9fb4158c7", "best_bid": "0.87", "best_ask": "0.95"}], "timestamp": "1769384974276", "event_type": "price_change"}}
{"_local_timestamp": "2026-01-25T23:49:37.633253+00:00", "data": {"market": "0x723f251ab60ea2dd4f99374a74f80be8548c2c4fe2cca22f2fa6f90bd905b559", "price_changes": [{"asset_id": "48978425543742752818803322458870690562079517439055041342251621857158978447363", "price": "0.03", "size": "6.02", "side": "BUY", "hash": "ea256138b332562f37b09c90ad66440c35a43087", "best_bid": "0.14", "best_ask": "0.23"}, {"asset_id": "112174093579349393205957859148865812063897305228582002453213788215242068235765", "price": "0.97", "size": "6.02", "side": "SELL", "hash": "2b9f8c5aeab1889786c505b45e2f6c6d15e80d72", "best_bid": "0.77", "best_ask": "0.86"}], "timestamp": "1769384977567", "event_type": "price_change"}}
{"_local_timestamp": "2026-01-25T23:49:37.634102+00:00", "data": {"market": "0xac316c01625b0fa8dd06da51970c50c8fdd764f82e535b9e21d13613331023c4", "price_changes": [{"asset_id": "92711393135578327663235479520022176862589684688868437494076107570235367457535", "price": "0.03", "size": "6.02", "side": "BUY", "hash": "bcea5902d0960138117e063abbee94737d9d9a48", "best_bid": "0.13", "best_ask": "0.23"}, {"asset_id": "12995286023077810117688664821031077590385716779526746803320299864462527923165", "price": "0.97", "size": "6.02", "side": "SELL", "hash": "8754b95e94112b838fdce385a96f79ed2c42d800", "best_bid": "0.77", "best_ask": "0.87"}], "timestamp": "1769384977567", "event_type": "price_change"}}
{"_local_timestamp": "2026-01-25T23:49:37.634704+00:00", "data": {"market": "0x25ba0e34abf08ca67e940e0a9de39d77ab9969ba040b54d59b8c9557e7e1209e", "price_changes": [{"asset_id": "100230850484605537426827028089591201602750218213849583160902003942949141764541", "price": "0.01", "size": "191.93", "side": "BUY", "hash": "42f14617a15b0842ac6204221839d97ec6525a40", "best_bid": "0.06", "best_ask": "0.96"}, {"asset_id": "34658822313166366862155307121179859104291458361815588542611104845760657957057", "price": "0.99", "size": "191.93", "side": "SELL", "hash": "32a22302c68f1c6e03842c5123653428beb3b995", "best_bid": "0.04", "best_ask": "0.94"}], "timestamp": "1769384977567", "event_type": "price_change"}}
{"_local_timestamp": "2026-01-25T23:49:37.635324+00:00", "data": {"market": "0x25ba0e34abf08ca67e940e0a9de39d77ab9969ba040b54d59b8c9557e7e1209e", "price_changes": [{"asset_id": "100230850484605537426827028089591201602750218213849583160902003942949141764541", "price": "0.03", "size": "9.79", "side": "BUY", "hash": "42f14617a15b0842ac6204221839d97ec6525a40", "best_bid": "0.06", "best_ask": "0.96"}, {"asset_id": "34658822313166366862155307121179859104291458361815588542611104845760657957057", "price": "0.97", "size": "9.79", "side": "SELL", "hash": "32a22302c68f1c6e03842c5123653428beb3b995", "best_bid": "0.04", "best_ask": "0.94"}], "timestamp": "1769384977567", "event_type": "price_change"}}
{"_local_timestamp": "2026-01-25T23:49:38.401126+00:00", "data": {"market": "0x723f251ab60ea2dd4f99374a74f80be8548c2c4fe2cca22f2fa6f90bd905b559", "price_changes": [{"asset_id": "48978425543742752818803322458870690562079517439055041342251621857158978447363", "price": "0.03", "size": "30.27", "side": "BUY", "hash": "84ed6701093c9ed33f4f635e4f551fcb5f90fce9", "best_bid": "0.14", "best_ask": "0.23"}, {"asset_id": "112174093579349393205957859148865812063897305228582002453213788215242068235765", "price": "0.97", "size": "30.27", "side": "SELL", "hash": "a269d6caec100faa5c1cfccbb14f03caf3a833df", "best_bid": "0.77", "best_ask": "0.86"}], "timestamp": "1769384978328", "event_type": "price_change"}}
{"_local_timestamp": "2026-01-25T23:49:38.401963+00:00", "data": {"market": "0xac316c01625b0fa8dd06da51970c50c8fdd764f82e535b9e21d13613331023c4", "price_changes": [{"asset_id": "92711393135578327663235479520022176862589684688868437494076107570235367457535", "price": "0.03", "size": "30.27", "side": "BUY", "hash": "df04540004fb28411597f57b6ac2eccb786f051e", "best_bid": "0.13", "best_ask": "0.23"}, {"asset_id": "12995286023077810117688664821031077590385716779526746803320299864462527923165", "price": "0.97", "size": "30.27", "side": "SELL", "hash": "d22cd7e087331a300a97f51b93c8f9f80aa4cd80", "best_bid": "0.77", "best_ask": "0.87"}], "timestamp": "1769384978328", "event_type": "price_change"}}
{"_local_timestamp": "2026-01-25T23:49:38.402607+00:00", "data": {"market": "0x25ba0e34abf08ca67e940e0a9de39d77ab9969ba040b54d59b8c9557e7e1209e", "price_changes": [{"asset_id": "100230850484605537426827028089591201602750218213849583160902003942949141764541", "price": "0.02", "size": "104.61", "side": "BUY", "hash": "d8e39e65406ef07825f8e873ce48118ba328ef8c", "best_bid": "0.06", "best_ask": "0.96"}, {"asset_id": "34658822313166366862155307121179859104291458361815588542611104845760657957057", "price": "0.98", "size": "104.61", "side": "SELL", "hash": "4f857d6ce3aa1a8ef6ce105f9aeace3a2d449e0c", "best_bid": "0.04", "best_ask": "0.94"}], "timestamp": "1769384978328", "event_type": "price_change"}}
{"_local_timestamp": "2026-01-25T23:49:38.403248+00:00", "data": {"market": "0x25ba0e34abf08ca67e940e0a9de39d77ab9969ba040b54d59b8c9557e7e1209e", "price_changes": [{"asset_id": "100230850484605537426827028089591201602750218213849583160902003942949141764541", "price": "0.04", "size": "7.36", "side": "BUY", "hash": "91dbb505a832d8a9af28f76ca52eab3d6561a641", "best_bid": "0.06", "best_ask": "0.96"}, {"asset_id": "34658822313166366862155307121179859104291458361815588542611104845760657957057", "price": "0.96", "size": "7.36", "side": "SELL", "hash": "05c19eadfdd50bf8adf98c005c0c6b1a863b1ae2", "best_bid": "0.04", "best_ask": "0.94"}], "timestamp": "1769384978329", "event_type": "price_change"}}
{"_local_timestamp": "2026-01-25T23:49:39.084805+00:00", "data": {"market": "0x723f251ab60ea2dd4f99374a74f80be8548c2c4fe2cca22f2fa6f90bd905b559", "price_changes": [{"asset_id": "48978425543742752818803322458870690562079517439055041342251621857158978447363", "price": "0.03", "size": "6.02", "side": "BUY", "hash": "060d0cba0cb6c03a0bc4816bd285266c2dfe140f", "best_bid": "0.14", "best_ask": "0.23"}, {"asset_id": "112174093579349393205957859148865812063897305228582002453213788215242068235765", "price": "0.97", "size": "6.02", "side": "SELL", "hash": "9ed2e65f6dd848d6cc8f15fb8ff28bd0f930c129", "best_bid": "0.77", "best_ask": "0.86"}], "timestamp": "1769384979005", "event_type": "price_change"}}
{"_local_timestamp": "2026-01-25T23:49:39.678489+00:00", "data": {"market": "0x723f251ab60ea2dd4f99374a74f80be8548c2c4fe2cca22f2fa6f90bd905b559", "price_changes": [{"asset_id": "48978425543742752818803322458870690562079517439055041342251621857158978447363", "price": "0.03", "size": "30.27", "side": "BUY", "hash": "a23706ee6e6fbc21dfe2279abd6e50a315f1c137", "best_bid": "0.14", "best_ask": "0.23"}, {"asset_id": "112174093579349393205957859148865812063897305228582002453213788215242068235765", "price": "0.97", "size": "30.27", "side": "SELL", "hash": "b1c19d2ca51b9c6afffb225db1775bd250a43e65", "best_bid": "0.77", "best_ask": "0.86"}], "timestamp": "1769384979606", "event_type": "price_change"}}
{"_local_timestamp": "2026-01-25T23:49:43.012868+00:00", "data": {"market": "0x25ba0e34abf08ca67e940e0a9de39d77ab9969ba040b54d59b8c9557e7e1209e", "price_changes": [{"asset_id": "100230850484605537426827028089591201602750218213849583160902003942949141764541", "price": "0.05", "size": "0", "side": "BUY", "hash": "ccb135c1bc89d2c633a6e295a18862591953e971", "best_bid": "0.06", "best_ask": "0.96"}, {"asset_id": "34658822313166366862155307121179859104291458361815588542611104845760657957057", "price": "0.95", "size": "0", "side": "SELL", "hash": "82261639d6e584d75247b4ceb447dac0a747706b", "best_bid": "0.04", "best_ask": "0.94"}], "timestamp": "1769384982932", "event_type": "price_change"}}
{"_local_timestamp": "2026-01-25T23:49:46.669873+00:00", "data": {"market": "0x25ba0e34abf08ca67e940e0a9de39d77ab9969ba040b54d59b8c9557e7e1209e", "price_changes": [{"asset_id": "100230850484605537426827028089591201602750218213849583160902003942949141764541", "price": "0.06", "size": "0", "side": "BUY", "hash": "240c4ddee5c0b98aaae8d668fa7398ea8541e719", "best_bid": "0.04", "best_ask": "0.96"}, {"asset_id": "34658822313166366862155307121179859104291458361815588542611104845760657957057", "price": "0.94", "size": "0", "side": "SELL", "hash": "be45be5dfa5de2129e0c6bc9410e62f33f22beff", "best_bid": "0.04", "best_ask": "0.96"}], "timestamp": "1769384986576", "event_type": "price_change"}}
{"_local_timestamp": "2026-01-25T23:49:46.865959+00:00", "data": {"market": "0x25ba0e34abf08ca67e940e0a9de39d77ab9969ba040b54d59b8c9557e7e1209e", "price_changes": [{"asset_id": "100230850484605537426827028089591201602750218213849583160902003942949141764541", "price": "0.05", "size": "5.47", "side": "BUY", "hash": "1b1a14eeef5f37e98555bf2436e8789ccd2372fe", "best_bid": "0.05", "best_ask": "0.96"}, {"asset_id": "34658822313166366862155307121179859104291458361815588542611104845760657957057", "price": "0.95", "size": "5.47", "side": "SELL", "hash": "038044524f18a334a2f18bcbf682f319aa6cff05", "best_bid": "0.04", "best_ask": "0.95"}], "timestamp": "1769384986792", "event_type": "price_change"}}
{"_local_timestamp": "2026-01-25T23:51:11.702525+00:00", "data": {"market": "0xdea4796b1330cc138fddbd7588ade544272dbbb5534d5c7e668d9793cd0eb88f", "price_changes": [{"asset_id": "110814814064089248423115833517094810833597085672984019468073735637142359900748", "price": "0.05", "size": "23.99", "side": "BUY", "hash": "5646b418ed87e12a7aa1416fa85ad51ce6ef6e01", "best_bid": "0.05", "best_ask": "0.97"}, {"asset_id": "64337076081574293087836622474147344770540617949234564813925323344969252999147", "price": "0.95", "size": "23.99", "side": "SELL", "hash": "11a8aeef309b134b02580b4cf94825e0627235b3", "best_bid": "0.03", "best_ask": "0.95"}], "timestamp": "1769385071629", "event_type": "price_change"}}
{"_local_timestamp": "2026-01-25T23:51:11.703637+00:00", "data": {"market": "0x95fc9afae2e9bcfba41be1318b9b232c954d4066deb69293201f60e312e1deb2", "price_changes": [{"asset_id": "1398772603884009307910454931960162936237268068359444250489356436701623282401", "price": "0.05", "size": "23.99", "side": "BUY", "hash": "6eb6578af5c63f3a4d29f27378392475c7b11d23", "best_bid": "0.05", "best_ask": "0.97"}, {"asset_id": "59592741249661515665302592630910670026326604112506560769678078156146744114566", "price": "0.95", "size": "23.99", "side": "SELL", "hash": "5d9c320c411f43f03f785bd08a92ace630b44a8d", "best_bid": "0.03", "best_ask": "0.95"}], "timestamp": "1769385071629", "event_type": "price_change"}}
{"_local_timestamp": "2026-01-25T23:51:11.803719+00:00", "data": {"market": "0xb4e3a03b7b9d32524e50a18643bc8b635f5db847ec228459e63ada4654232266", "price_changes": [{"asset_id": "61429815324316585285190173773753095389900760670737146252386183662368970056071", "price": "0.05", "size": "23.99", "side": "BUY", "hash": "fe1af0d4bcb60033d16d6b484cda710f859bad75", "best_bid": "0.05", "best_ask": "0.96"}, {"asset_id": "59015750890371857600345791870768842601163744323962019697925860773975224241703", "price": "0.95", "size": "23.99", "side": "SELL", "hash": "db6965fcd1764c41ce4c1b0d049d4a344454aa98", "best_bid": "0.04", "best_ask": "0.95"}], "timestamp": "1769385071727", "event_type": "price_change"}}
{"_local_timestamp": "2026-01-25T23:51:14.024154+00:00", "data": {"market": "0x95fc9afae2e9bcfba41be1318b9b232c954d4066deb69293201f60e312e1deb2", "price_changes": [{"asset_id": "1398772603884009307910454931960162936237268068359444250489356436701623282401", "price": "0.04", "size": "0", "side": "BUY", "hash": "d5a625ee10c3d0aaf85fca30b50c8065b8ca850a", "best_bid": "0.05", "best_ask": "0.97"}, {"asset_id": "59592741249661515665302592630910670026326604112506560769678078156146744114566", "price": "0.96", "size": "0", "side": "SELL", "hash": "277066a13862cf4cbe412fc9e9c2ba564c2572ee", "best_bid": "0.03", "best_ask": "0.95"}], "timestamp": "1769385073958", "event_type": "price_change"}}
{"_local_timestamp": "2026-01-25T23:51:14.044368+00:00", "data": {"market": "0xb4e3a03b7b9d32524e50a18643bc8b635f5db847ec228459e63ada4654232266", "price_changes": [{"asset_id": "61429815324316585285190173773753095389900760670737146252386183662368970056071", "price": "0.04", "size": "0", "side": "BUY", "hash": "0d3fed31c8520fe6a903f335e86a78d2fa1c56fe", "best_bid": "0.05", "best_ask": "0.96"}, {"asset_id": "59015750890371857600345791870768842601163744323962019697925860773975224241703", "price": "0.96", "size": "0", "side": "SELL", "hash": "8fd25876188f050c4dd081cb2dabe670b5a797aa", "best_bid": "0.04", "best_ask": "0.95"}], "timestamp": "1769385073959", "event_type": "price_change"}}
{"_local_timestamp": "2026-01-25T23:51:14.045023+00:00", "data": {"market": "0xdea4796b1330cc138fddbd7588ade544272dbbb5534d5c7e668d9793cd0eb88f", "price_changes": [{"asset_id": "110814814064089248423115833517094810833597085672984019468073735637142359900748", "price": "0.04", "size": "0", "side": "BUY", "hash": "a943d1649785485ef8f23ba7f1488b467953f45d", "best_bid": "0.05", "best_ask": "0.97"}, {"asset_id": "64337076081574293087836622474147344770540617949234564813925323344969252999147", "price": "0.96", "size": "0", "side": "SELL", "hash": "b898d58b3e27914749f4824eda986d3e55b68a21", "best_bid": "0.03", "best_ask": "0.95"}], "timestamp": "1769385073959", "event_type": "price_change"}}
{"_local_timestamp": "2026-01-25T23:51:14.393277+00:00", "data": {"market": "0xdea4796b1330cc138fddbd7588ade544272dbbb5534d5c7e668d9793cd0eb88f", "price_changes": [{"asset_id": "110814814064089248423115833517094810833597085672984019468073735637142359900748", "price": "0.06", "size": "5.47", "side": "BUY", "hash": "4879eb7d84d84682e9a9bcdba606a8ea8794b33f", "best_bid": "0.06", "best_ask": "0.97"}, {"asset_id": "64337076081574293087836622474147344770540617949234564813925323344969252999147", "price": "0.94", "size": "5.47", "side": "SELL", "hash": "7fa3edb3633fbe26ff4b7b8d54b4799c6b30438f", "best_bid": "0.03", "best_ask": "0.94"}], "timestamp": "1769385074331", "event_type": "price_change"}}
{"_local_timestamp": "2026-01-25T23:51:14.404318+00:00", "data": {"market": "0x95fc9afae2e9bcfba41be1318b9b232c954d4066deb69293201f60e312e1deb2", "price_changes": [{"asset_id": "1398772603884009307910454931960162936237268068359444250489356436701623282401", "price": "0.06", "size": "5.47", "side": "BUY", "hash": "88cbf688274d017b796e5969682d8b8db31522be", "best_bid": "0.06", "best_ask": "0.97"}, {"asset_id": "59592741249661515665302592630910670026326604112506560769678078156146744114566", "price": "0.94", "size": "5.47", "side": "SELL", "hash": "2b574964fe7c6091a1c8cb2b444ba0aa0b93768c", "best_bid": "0.03", "best_ask": "0.94"}], "timestamp": "1769385074331", "event_type": "price_change"}}
{"_local_timestamp": "2026-01-25T23:51:14.405025+00:00", "data": {"market": "0xb4e3a03b7b9d32524e50a18643bc8b635f5db847ec228459e63ada4654232266", "price_changes": [{"asset_id": "61429815324316585285190173773753095389900760670737146252386183662368970056071", "price": "0.06", "size": "5.47", "side": "BUY", "hash": "f5acd4f6eb99131683117db4256779ff9c31928b", "best_bid": "0.06", "best_ask": "0.96"}, {"asset_id": "59015750890371857600345791870768842601163744323962019697925860773975224241703", "price": "0.94", "size": "5.47", "side": "SELL", "hash": "9b9cadaf313025937643f676bba8a72ef898b7a6", "best_bid": "0.04", "best_ask": "0.94"}], "timestamp": "1769385074331", "event_type": "price_change"}}
