{"_local_timestamp": "2026-01-25T23:40:48.385807+00:00", "data": [{"market": "0x759b597b20756bff4086ed700c82b91b8b9fdee4267853dd9773c267738dcd1e", "asset_id": "46916586432008324922492054082741681707965821813662860795622799670086307371133", "timestamp": "1769384406302", "hash": "ebccbd49de8a29f6d55cce3f5cd248248394bd3e", "bids": [{"price": "0.001", "size": "3310.14"}, {"price": "0.002", "size": "1250"}, {"price": "0.003", "size": "1172.66"}, {"price": "0.006", "size": "83"}, {"price": "0.007", "size": "10.25"}, {"price": "0.01", "size": "7850"}, {"price": "0.02", "size": "3300"}, {"price": "0.021", "size": "250"}, {"price": "0.022", "size": "13.6"}, {"price": "0.05", "size": "30"}, {"price": "0.051", "size": "39"}, {"price": "0.06", "size": "1100"}, {"price": "0.1", "size": "360"}, {"price": "0.101", "size": "5.93"}, {"price": "0.15", "size": "1376.66"}, {"price": "0.2", "size": "610"}, {"price": "0.25", "size": "362"}, {"price": "0.251", "size": "7"}, {"price": "0.3", "size": "186.66"}, {"price": "0.35", "size": "68.57"}, {"price": "0.37", "size": "150"}, {"price": "0.4", "size": "50"}, {"price": "0.41", "size": "100"}, {"price": "0.44", "size": "100"}, {"price": "0.47", "size": "160"}, {"price": "0.81", "size": "20"}, {"price": "0.83", "size": "200"}, {"price": "0.84", "size": "220"}, {"price": "0.85", "size": "295.23"}, {"price": "0.86", "size": "205"}, {"price": "0.87", "size": "42.85"}, {"price": "0.89", "size": "8.45"}, {"price": "0.9", "size": "1000"}, {"price": "0.901", "size": "1000"}, {"price": "0.93", "size": "222"}, {"price": "0.94", "size": "2222"}, {"price": "0.95", "size": "1194.99"}, {"price": "0.97", "size": "100"}, {"price": "0.972", "size": "100"}, {"price": "0.973", "size": "100"}, {"price": "0.975", "size": "222"}, {"price": "0.98", "size": "577.35"}, {"price": "0.981", "size": "2222"}, {"price": "0.982", "size": "222"}, {"price": "0.984", "size": "1544.14"}, {"price": "0.987", "size": "10015"}, {"price": "0.988", "size": "434.28"}, {"price": "0.99", "size": "987.41"}], "asks": [{"price": "0.999", "size": "18070"}, {"price": "0.998", "size": "5434.37"}, {"price": "0.997", "size": "10490.97"}, {"price": "0.996", "size": "2891.76"}, {"price": "0.995", "size": "477.24"}, {"price": "0.994", "size": "4992.3"}, {"price": "0.993", "size": "23.51"}, {"price": "0.992", "size": "1445.02"}, {"price": "0.991", "size": "2058.45"}], "event_type": "book", "last_trade_price": "0.008"}, {"market": "0xbc27e1a503d5d962491fb41d0f0efd432c222fbfbb484b775ca0def7ed52288c", "asset_id": "22424973164442660525283958049724397021587362098150529484937062183898885124879", "timestamp": "1769384426837", "hash": "2965cf45ea6d83e1e246e7775d00c0e5d9732102", "bids": [{"price": "0.01", "size": "111600"}, {"price": "0.02", "size": "15998.11"}, {"price": "0.03", "size": "250"}, {"price": "0.04", "size": "132.28"}, {"price": "0.05", "size": "3450"}, {"price": "0.06", "size": "4045.98"}, {"price": "0.07", "size": "1029"}, {"price": "0.08", "size": "3118.14"}], "asks": [{"price": "0.99", "size": "8259.71"}, {"price": "0.98", "size": "1000"}, {"price": "0.97", "size": "10.14"}, {"price": "0.96", "size": "3550"}, {"price": "0.95", "size": "30"}, {"price": "0.94", "size": "33"}, {"price": "0.91", "size": "1100"}, {"price": "0.9", "size": "500"}, {"price": "0.89", "size": "5.43"}, {"price": "0.86", "size": "1142.85"}, {"price": "0.82", "size": "177.77"}, {"price": "0.8", "size": "400"}, {"price": "0.79", "size": "760"}, {"price": "0.78", "size": "2208"}, {"price": "0.77", "size": "121.73"}, {"price": "0.72", "size": "142.85"}, {"price": "0.71", "size": "50"}, {"price": "0.68", "size": "75"}, {"price": "0.66", "size": "5"}, {"price": "0.63", "size": "54.05"}, {"price": "0.62", "size": "1703"}, {"price": "0.53", "size": "35"}, {"price": "0.52", "size": "35"}, {"price": "0.39", "size": "200"}, {"price": "0.37", "size": "350.17"}, {"price": "0.28", "size": "36.07"}, {"price": "0.25", "size": "517.39"}, {"price": "0.15", "size": "105"}, {"price": "0.13", "size": "156.23"}, {"price": "0.12", "size": "2422"}, {"price": "0.11", "size": "3847"}, {"price": "0.1", "size": "2554.17"}], "event_type": "book", "last_trade_price": "0.080"}, {"market": "0x759b597b20756bff4086ed700c82b91b8b9fdee4267853dd9773c267738dcd1e", "asset_id": "39225767916489160517007045909404121985668346072423315764460339415130171638654", "timestamp": "1769384406302", "hash": "f2b236c9f54208261afcae7d7a8bcf575c42981c", "bids": [{"price": "0.001", "size": "18070"}, {"price": "0.002", "size": "5434.37"}, {"price": "0.003", "size": "10490.97"}, {"price": "0.004", "size": "2891.76"}, {"price": "0.005", "size": "477.24"}, {"price": "0.006", "size": "4992.3"}, {"price": "0.007", "size": "23.51"}, {"price": "0.008", "size": "1445.02"}, {"price": "0.009", "size": "2058.45"}], "asks": [{"price": "0.999", "size": "3310.14"}, {"price": "0.998", "size": "1250"}, {"price": "0.997", "size": "1172.66"}, {"price": "0.994", "size": "83"}, {"price": "0.993", "size": "10.25"}, {"price": "0.99", "size": "7850"}, {"price": "0.98", "size": "3300"}, {"price": "0.979", "size": "250"}, {"price": "0.978", "size": "13.6"}, {"price": "0.95", "size": "30"}, {"price": "0.949", "size": "39"}, {"price": "0.94", "size": "1100"}, {"price": "0.9", "size": "360"}, {"price": "0.899", "size": "5.93"}, {"price": "0.85", "size": "1376.66"}, {"price": "0.8", "size": "610"}, {"price": "0.75", "size": "362"}, {"price": "0.749", "size": "7"}, {"price": "0.7", "size": "186.66"}, {"price": "0.65", "size": "68.57"}, {"price": "0.63", "size": "150"}, {"price": "0.6", "size": "50"}, {"price": "0.59", "size": "100"}, {"price": "0.56", "size": "100"}, {"price": "0.53", "size": "160"}, {"price": "0.19", "size": "20"}, {"price": "0.17", "size": "200"}, {"price": "0.16", "size": "220"}, {"price": "0.15", "size": "295.23"}, {"price": "0.14", "size": "205"}, {"price": "0.13", "size": "42.85"}, {"price": "0.11", "size": "8.45"}, {"price": "0.1", "size": "1000"}, {"price": "0.099", "size": "1000"}, {"price": "0.07", "size": "222"}, {"price": "0.06", "size": "2222"}, {"price": "0.05", "size": "1194.99"}, {"price": "0.03", "size": "100"}, {"price": "0.028", "size": "100"}, {"price": "0.027", "size": "100"}, {"price": "0.025", "size": "222"}, {"price": "0.02", "size": "577.35"}, {"price": "0.019", "size": "2222"}, {"price": "0.018", "size": "222"}, {"price": "0.016", "size": "1544.14"}, {"price": "0.013", "size": "10015"}, {"price": "0.012", "size": "434.28"}, {"price": "0.01", "size": "987.41"}], "event_type": "book", "last_trade_price": "0.008"}, {"market": "0xbc27e1a503d5d962491fb41d0f0efd432c222fbfbb484b775ca0def7ed52288c", "asset_id": "84464967243852186849141927382392363797190214011244597826174886881676581745178", "timestamp": "1769384426837", "hash": "c301baece1a34cd2fd2b32e37bc54aeb51a5b9b0", "bids": [{"price": "0.01", "size": "8259.71"}, {"price": "0.02", "size": "1000"}, {"price": "0.03", "size": "10.14"}, {"price": "0.04", "size": "3550"}, {"price": "0.05", "size": "30"}, {"price": "0.06", "size": "33"}, {"price": "0.09", "size": "1100"}, {"price": "0.1", "size": "500"}, {"price": "0.11", "size": "5.43"}, {"price": "0.14", "size": "1142.85"}, {"price": "0.18", "size": "177.77"}, {"price": "0.2", "size": "400"}, {"price": "0.21", "size": "760"}, {"price": "0.22", "size": "2208"}, {"price": "0.23", "size": "121.73"}, {"price": "0.28", "size": "142.85"}, {"price": "0.29", "size": "50"}, {"price": "0.32", "size": "75"}, {"price": "0.34", "size": "5"}, {"price": "0.37", "size": "54.05"}, {"price": "0.38", "size": "1703"}, {"price": "0.47", "size": "35"}, {"price": "0.48", "size": "35"}, {"price": "0.61", "size": "200"}, {"price": "0.63", "size": "350.17"}, {"price": "0.72", "size": "36.07"}, {"price": "0.75", "size": "517.39"}, {"price": "0.85", "size": "105"}, {"price": "0.87", "size": "156.23"}, {"price": "0.88", "size": "2422"}, {"price": "0.89", "size": "3847"}, {"price": "0.9", "size": "2554.17"}], "asks": [{"price": "0.99", "size": "111600"}, {"price": "0.98", "size": "15998.11"}, {"price": "0.97", "size": "250"}, {"price": "0.96", "size": "132.28"}, {"price": "0.95", "size": "3450"}, {"price": "0.94", "size": "4045.98"}, {"price": "0.93", "size": "1029"}, {"price": "0.92", "size": "3118.14"}], "event_type": "book", "last_trade_price": "0.080"}]}
{"_local_timestamp": "2026-01-25T23:41:02.106937+00:00", "data": {"market": "0xbc27e1a503d5d962491fb41d0f0efd432c222fbfbb484b775ca0def7ed52288c", "price_changes": [{"asset_id": "22424973164442660525283958049724397021587362098150529484937062183898885124879", "price": "0.05", "size": "3350", "side": "BUY", "hash": "58ea2c6c42b8de6c9fc2086f5fd4bf6430bd39dd", "best_bid": "0.08", "best_ask": "0.1"}, {"asset_id": "84464967243852186849141927382392363797190214011244597826174886881676581745178", "price": "0.95", "size": "3350", "side": "SELL", "hash": "8a81e5c8b0bc002342c5a041944126f7eb4fc481", "best_bid": "0.9", "best_ask": "0.92"}], "timestamp": "1769384462000", "event_type": "price_change"}}
{"_local_timestamp": "2026-01-25T23:41:02.108706+00:00", "data": {"market": "0xbc27e1a503d5d962491fb41d0f0efd432c222fbfbb484b775ca0def7ed52288c", "price_changes": [{"asset_id": "22424973164442660525283958049724397021587362098150529484937062183898885124879", "price": "0.06", "size": "4011.98", "side": "BUY", "hash": "f4f3fa210fc77732e0676310b0077649cc33e9db", "best_bid": "0.08", "best_ask": "0.1"}, {"asset_id": "84464967243852186849141927382392363797190214011244597826174886881676581745178", "price": "0.94", "size": "4011.98", "side": "SELL", "hash": "fb3a70b7754848af476397bc999ba9fa3fc41b69", "best_bid": "0.9", "best_ask": "0.92"}], "timestamp": "1769384462003", "event_type": "price_change"}}
{"_local_timestamp": "2026-01-25T23:41:02.109307+00:00", "data": {"market": "0xbc27e1a503d5d962491fb41d0f0efd432c222fbfbb484b775ca0def7ed52288c", "price_changes": [{"asset_id": "22424973164442660525283958049724397021587362098150529484937062183898885124879", "price": "0.02", "size": "15398.11", "side": "BUY", "hash": "717eec30ce7400ff055a4bdd35824e7317477943", "best_bid": "0.08", "best_ask": "0.1"}, {"asset_id": "84464967243852186849141927382392363797190214011244597826174886881676581745178", "price": "0.98", "size": "15398.11", "side": "SELL", "hash": "fcb1d625e05b6ad5ff3cb1be7537a7ea2581a99b", "best_bid": "0.9", "best_ask": "0.92"}], "timestamp": "1769384462004", "event_type": "price_change"}}
{"_local_timestamp": "2026-01-25T23:41:06.442338+00:00", "data": {"market": "0xbc27e1a503d5d962491fb41d0f0efd432c222fbfbb484b775ca0def7ed52288c", "price_changes": [{"asset_id": "84464967243852186849141927382392363797190214011244597826174886881676581745178", "price": "0.88", "size": "2322", "side": "BUY", "hash": "a9092f664447ad3ef408253eda0e33bd76d1b02a", "best_bid": "0.9", "best_ask": "0.92"}, {"asset_id": "22424973164442660525283958049724397021587362098150529484937062183898885124879", "price": "0.12", "size": "2322", "side": "SELL", "hash": "67549553dc657b9f355d127111194f193f057803", "best_bid": "0.08", "best_ask": "0.1"}], "timestamp": "1769384466196", "event_type": "price_change"}}
{"_local_timestamp": "2026-01-25T23:41:06.574319+00:00", "data": {"market": "0xbc27e1a503d5d962491fb41d0f0efd432c222fbfbb484b775ca0def7ed52288c", "price_changes": [{"asset_id": "22424973164442660525283958049724397021587362098150529484937062183898885124879", "price": "0.06", "size": "3911.98", "side": "BUY", "hash": "9da0f9a63614f0289f4757d0deec6742065d27c7", "best_bid": "0.08", "best_ask": "0.1"}, {"asset_id": "84464967243852186849141927382392363797190214011244597826174886881676581745178", "price": "0.94", "size": "3911.98", "side": "SELL", "hash": "eeade1c4499105d26235375c8d9ef73d61d8b080", "best_bid": "0.9", "best_ask": "0.92"}], "timestamp": "1769384466198", "event_type": "price_change"}}
{"_local_timestamp": "2026-01-25T23:41:18.163583+00:00", "data": {"market": "0xbc27e1a503d5d962491fb41d0f0efd432c222fbfbb484b775ca0def7ed52288c", "price_changes": [{"asset_id": "22424973164442660525283958049724397021587362098150529484937062183898885124879", "price": "0.02", "size": "16048.11", "side": "BUY", "hash": "5ab693f76eae62419f89082272a5ea44b6f3be57", "best_bid": "0.08", "best_ask": "0.1"}, {"asset_id": "84464967243852186849141927382392363797190214011244597826174886881676581745178", "price": "0.98", "size": "16048.11", "side": "SELL", "hash": "7687de5b2b7e9a8b8cf07c88d7ae9f197414cfad", "best_bid": "0.9", "best_ask": "0.92"}], "timestamp": "1769384478053", "event_type": "price_change"}}
{"_local_timestamp": "2026-01-25T23:41:18.176147+00:00", "data": {"market": "0xbc27e1a503d5d962491fb41d0f0efd432c222fbfbb484b775ca0def7ed52288c", "price_changes": [{"asset_id": "22424973164442660525283958049724397021587362098150529484937062183898885124879", "price": "0.06", "size": "3978.98", "side": "BUY", "hash": "b1460d8ce63a765d0960333d826675da16f558c9", "best_bid": "0.08", "best_ask": "0.1"}, {"asset_id": "84464967243852186849141927382392363797190214011244597826174886881676581745178", "price": "0.94", "size": "3978.98", "side": "SELL", "hash": "d7d51a87bf94532b4c89719961461c3f9aaabe1b", "best_bid": "0.9", "best_ask": "0.92"}], "timestamp": "1769384478056", "event_type": "price_change"}}
{"_local_timestamp": "2026-01-25T23:41:18.177387+00:00", "data": {"market": "0xbc27e1a503d5d962491fb41d0f0efd432c222fbfbb484b775ca0def7ed52288c", "price_changes": [{"asset_id": "22424973164442660525283958049724397021587362098150529484937062183898885124879", "price": "0.05", "size": "6010", "side": "BUY", "hash": "289be832bb88a3078843460f478fe074b56e3f98", "best_bid": "0.08", "best_ask": "0.1"}, {"asset_id": "84464967243852186849141927382392363797190214011244597826174886881676581745178", "price": "0.95", "size": "6010", "side": "SELL", "hash": "cfed31497fd0a0a3b271f0d622a9788f75c93e58", "best_bid": "0.9", "best_ask": "0.92"}], "timestamp": "1769384478059", "event_type": "price_change"}}
{"_local_timestamp": "2026-01-25T23:41:20.749499+00:00", "data": {"market": "0xbc27e1a503d5d962491fb41d0f0efd432c222fbfbb484b775ca0def7ed52288c", "price_changes": [{"asset_id": "22424973164442660525283958049724397021587362098150529484937062183898885124879", "price": "0.06", "size": "4078.98", "side": "BUY", "hash": "2ec6937d06013a86a7b8f2e9264ab832a47255f4", "best_bid": "0.08", "best_ask": "0.1"}, {"asset_id": "84464967243852186849141927382392363797190214011244597826174886881676581745178", "price": "0.94", "size": "4078.98", "side": "SELL", "hash": "24b33d63b35154dd570804960a2fb9cf4955f1e8", "best_bid": "0.9", "best_ask": "0.92"}], "timestamp": "1769384480681", "event_type": "price_change"}}
{"_local_timestamp": "2026-01-25T23:41:44.801280+00:00", "data": {"market": "0xbc27e1a503d5d962491fb41d0f0efd432c222fbfbb484b775ca0def7ed52288c", "price_changes": [{"asset_id": "84464967243852186849141927382392363797190214011244597826174886881676581745178", "price": "0.88", "size": "2422", "side": "BUY", "hash": "1722ed515e9aff9d68b153524ecc8acec1dc39c0", "best_bid": "0.9", "best_ask": "0.92"}, {"asset_id": "22424973164442660525283958049724397021587362098150529484937062183898885124879", "price": "0.12", "size": "2422", "side": "SELL", "hash": "1b61984c97ee3d07aed3bce580b364888e052023", "best_bid": "0.08", "best_ask": "0.1"}], "timestamp": "1769384504733", "event_type": "price_change"}}
{"_local_timestamp": "2026-01-25T23:41:47.102306+00:00", "data": {"market": "0xbc27e1a503d5d962491fb41d0f0efd432c222fbfbb484b775ca0def7ed52288c", "price_changes": [{"asset_id": "22424973164442660525283958049724397021587362098150529484937062183898885124879", "price": "0.05", "size": "5950", "side": "BUY", "hash": "981a4d1b5a33b7ab5512e2d6bb787285f7a31139", "best_bid": "0.08", "best_ask": "0.1"}, {"asset_id": "84464967243852186849141927382392363797190214011244597826174886881676581745178", "price": "0.95", "size": "5950", "side": "SELL", "hash": "81d99eba03495fbe1021bc61f044638a26ba8899", "best_bid": "0.9", "best_ask": "0.92"}], "timestamp": "1769384507000", "event_type": "price_change"}}
{"_local_timestamp": "2026-01-25T23:41:47.110692+00:00", "data": {"market": "0xbc27e1a503d5d962491fb41d0f0efd432c222fbfbb484b775ca0def7ed52288c", "price_changes": [{"asset_id": "22424973164442660525283958049724397021587362098150529484937062183898885124879", "price": "0.02", "size": "15798.11", "side": "BUY", "hash": "be6a0545ba27724d316b36353111aa60161192ae", "best_bid": "0.08", "best_ask": "0.1"}, {"asset_id": "84464967243852186849141927382392363797190214011244597826174886881676581745178", "price": "0.98", "size": "15798.11", "side": "SELL", "hash": "ddd28783ff9f6273c47bcbdd82a8f63198991495", "best_bid": "0.9", "best_ask": "0.92"}], "timestamp": "1769384507004", "event_type": "price_change"}}
{"_local_timestamp": "2026-01-25T23:41:47.111051+00:00", "data": {"market": "0xbc27e1a503d5d962491fb41d0f0efd432c222fbfbb484b775ca0def7ed52288c", "price_changes": [{"asset_id": "22424973164442660525283958049724397021587362098150529484937062183898885124879", "price": "0.06", "size": "4045.98", "side": "BUY", "hash": "feb59c84e0cdcc90e35c968a0a66c6e43c76e0cf", "best_bid": "0.08", "best_ask": "0.1"}, {"asset_id": "84464967243852186849141927382392363797190214011244597826174886881676581745178", "price": "0.94", "size": "4045.98", "side": "SELL", "hash": "94d16bd05629ddb8c539cfcd76ce5519f03cdffe", "best_bid": "0.9", "best_ask": "0.92"}], "timestamp": "1769384507005", "event_type": "price_change"}}
{"_local_timestamp": "2026-01-25T23:41:50.062615+00:00", "data": {"market": "0xbc27e1a503d5d962491fb41d0f0efd432c222fbfbb484b775ca0def7ed52288c", "price_changes": [{"asset_id": "22424973164442660525283958049724397021587362098150529484937062183898885124879", "price": "0.05", "size": "6010", "side": "BUY", "hash": "b5d9a6d4aafdf34a25b00b1b8794a7a948f6f1e3", "best_bid": "0.08", "best_ask": "0.1"}, {"asset_id": "84464967243852186849141927382392363797190214011244597826174886881676581745178", "price": "0.95", "size": "6010", "side": "SELL", "hash": "9902f073e7637d0c22440e72c79e4b1647180855", "best_bid": "0.9", "best_ask": "0.92"}], "timestamp": "1769384509996", "event_type": "price_change"}}
{"_local_timestamp": "2026-01-25T23:41:50.063427+00:00", "data": {"market": "0xbc27e1a503d5d962491fb41d0f0efd432c222fbfbb484b775ca0def7ed52288c", "price_changes": [{"asset_id": "22424973164442660525283958049724397021587362098150529484937062183898885124879", "price": "0.02", "size": "16048.11", "side": "BUY", "hash": "150f4761f1bd4a5db3fada64193618a2d8e7ac3e", "best_bid": "0.08", "best_ask": "0.1"}, {"asset_id": "84464967243852186849141927382392363797190214011244597826174886881676581745178", "price": "0.98", "size": "16048.11", "side": "SELL", "hash": "7550f01b918c3704e76aec6b32c0d19490e53dc2", "best_bid": "0.9", "best_ask": "0.92"}], "timestamp": "1769384509997", "event_type": "price_change"}}
{"_local_timestamp": "2026-01-25T23:41:50.063783+00:00", "data": {"market": "0xbc27e1a503d5d962491fb41d0f0efd432c222fbfbb484b775ca0def7ed52288c", "price_changes": [{"asset_id": "22424973164442660525283958049724397021587362098150529484937062183898885124879", "price": "0.06", "size": "4078.98", "side": "BUY", "hash": "08f2ef798c0066a9c54538385ce21a3be65027b3", "best_bid": "0.08", "best_ask": "0.1"}, {"asset_id": "84464967243852186849141927382392363797190214011244597826174886881676581745178", "price": "0.94", "size": "4078.98", "side": "SELL", "hash": "8612b8d7e411017f19b65633cc6b25626dc00f43", "best_bid": "0.9", "best_ask": "0.92"}], "timestamp": "1769384509998", "event_type": "price_change"}}
{"_local_timestamp": "2026-01-25T23:42:45.477294+00:00", "data": {"market": "0xbc27e1a503d5d962491fb41d0f0efd432c222fbfbb484b775ca0def7ed52288c", "price_changes": [{"asset_id": "84464967243852186849141927382392363797190214011244597826174886881676581745178", "price": "0.29", "size": "0", "side": "BUY", "hash": "6bc4661e556907f2259fa73c7bf08dc1a2a5f9eb", "best_bid": "0.9", "best_ask": "0.92"}, {"asset_id": "22424973164442660525283958049724397021587362098150529484937062183898885124879", "price": "0.71", "size": "0", "side": "SELL", "hash": "4af0a466a7bf626cbe6fb80594df5724eadfe0ea", "best_bid": "0.08", "best_ask": "0.1"}], "timestamp": "1769384565228", "event_type": "price_change"}}
{"_local_timestamp": "2026-01-25T23:42:45.751818+00:00", "data": {"market": "0xbc27e1a503d5d962491fb41d0f0efd432c222fbfbb484b775ca0def7ed52288c", "price_changes": [{"asset_id": "84464967243852186849141927382392363797190214011244597826174886881676581745178", "price": "0.28", "size": "192.85", "side": "BUY", "hash": "f0ac1c2914eb07cc779d1a4eca9fb6af35f2ca93", "best_bid": "0.9", "best_ask": "0.92"}, {"asset_id": "22424973164442660525283958049724397021587362098150529484937062183898885124879", "price": "0.72", "size": "192.85", "side": "SELL", "hash": "2190d341593e40305a5465febc071d38a1cf81ab", "best_bid": "0.08", "best_ask": "0.1"}], "timestamp": "1769384565590", "event_type": "price_change"}}
{"_local_timestamp": "2026-01-25T23:44:23.137598+00:00", "data": {"market": "0xbc27e1a503d5d962491fb41d0f0efd432c222fbfbb484b775ca0def7ed52288c", "price_changes": [{"asset_id": "22424973164442660525283958049724397021587362098150529484937062183898885124879", "price": "0.07", "size": "1129", "side": "BUY", "hash": "5b043ae399678acf5741100c65d9f9af95f5d2c1", "best_bid": "0.08", "best_ask": "0.1"}, {"asset_id": "84464967243852186849141927382392363797190214011244597826174886881676581745178", "price": "0.93", "size": "1129", "side": "SELL", "hash": "3a907953e153751b694ad65c942721c527db7c88", "best_bid": "0.9", "best_ask": "0.92"}], "timestamp": "1769384662995", "event_type": "price_change"}}
{"_local_timestamp": "2026-01-25T23:44:23.544329+00:00", "data": {"market": "0xbc27e1a503d5d962491fb41d0f0efd432c222fbfbb484b775ca0def7ed52288c", "price_changes": [{"asset_id": "84464967243852186849141927382392363797190214011244597826174886881676581745178", "price": "0.89", "size": "3947", "side": "BUY", "hash": "067695ebed40a43070a9638d609c824daebd7e31", "best_bid": "0.9", "best_ask": "0.92"}, {"asset_id": "22424973164442660525283958049724397021587362098150529484937062183898885124879", "price": "0.11", "size": "3947", "side": "SELL", "hash": "52a780e977483311c428a88acf80a2e54cc16f79", "best_bid": "0.08", "best_ask": "0.1"}], "timestamp": "1769384663473", "event_type": "price_change"}}
{"_local_timestamp": "2026-01-25T23:44:32.432446+00:00", "data": {"market": "0xbc27e1a503d5d962491fb41d0f0efd432c222fbfbb484b775ca0def7ed52288c", "price_changes": [{"asset_id": "84464967243852186849141927382392363797190214011244597826174886881676581745178", "price": "0.22", "size": "300", "side": "BUY", "hash": "67e392cefcc435038815ab0661f6dc45e83017a8", "best_bid": "0.9", "best_ask": "0.92"}, {"asset_id": "22424973164442660525283958049724397021587362098150529484937062183898885124879", "price": "0.78", "size": "300", "side": "SELL", "hash": "5138abe5a5559c7e52cab164d9ba6ca1b595965a", "best_bid": "0.08", "best_ask": "0.1"}], "timestamp": "1769384672298", "event_type": "price_change"}}
{"_local_timestamp": "2026-01-25T23:44:45.762986+00:00", "data": {"market": "0xbc27e1a503d5d962491fb41d0f0efd432c222fbfbb484b775ca0def7ed52288c", "price_changes": [{"asset_id": "84464967243852186849141927382392363797190214011244597826174886881676581745178", "price": "0.29", "size": "1448", "side": "BUY", "hash": "a08f150578bc216f6636535e251bb051166fb064", "best_bid": "0.9", "best_ask": "0.92"}, {"asset_id": "22424973164442660525283958049724397021587362098150529484937062183898885124879", "price": "0.71", "size": "1448", "side": "SELL", "hash": "9e017cafa51a0ed0258c660041f1572ea5c472be", "best_bid": "0.08", "best_ask": "0.1"}], "timestamp": "1769384685702", "event_type": "price_change"}}
{"_local_timestamp": "2026-01-25T23:45:09.091535+00:00", "data": {"market": "0xbc27e1a503d5d962491fb41d0f0efd432c222fbfbb484b775ca0def7ed52288c", "price_changes": [{"asset_id": "22424973164442660525283958049724397021587362098150529484937062183898885124879", "price": "0.02", "size": "15948.11", "side": "BUY", "hash": "528582c18e4c8f823e4f8fc42a46375acd5c2836", "best_bid": "0.08", "best_ask": "0.1"}, {"asset_id": "84464967243852186849141927382392363797190214011244597826174886881676581745178", "price": "0.98", "size": "15948.11", "side": "SELL", "hash": "33e6946d8b6e1b979e73bf529e878c65b4941eef", "best_bid": "0.9", "best_ask": "0.92"}], "timestamp": "1769384709000", "event_type": "price_change"}}
{"_local_timestamp": "2026-01-25T23:45:09.092210+00:00", "data": {"market": "0xbc27e1a503d5d962491fb41d0f0efd432c222fbfbb484b775ca0def7ed52288c", "price_changes": [{"asset_id": "22424973164442660525283958049724397021587362098150529484937062183898885124879", "price": "0.05", "size": "5990", "side": "BUY", "hash": "c79ead32f16156bf080ef28a97c8bc68e9fc86a5", "best_bid": "0.08", "best_ask": "0.1"}, {"asset_id": "84464967243852186849141927382392363797190214011244597826174886881676581745178", "price": "0.95", "size": "5990", "side": "SELL", "hash": "42c9ed740c0af01118ae0a5b8ff8466a03960341", "best_bid": "0.9", "best_ask": "0.92"}], "timestamp": "1769384709004", "event_type": "price_change"}}
{"_local_timestamp": "2026-01-25T23:45:13.391538+00:00", "data": {"market": "0x759b597b20756bff4086ed700c82b91b8b9fdee4267853dd9773c267738dcd1e", "price_changes": [{"asset_id": "39225767916489160517007045909404121985668346072423315764460339415130171638654", "price": "0.002", "size": "5350", "side": "BUY", "hash": "8e838d8f7b15b6fa5b3581ee2bd9be39a1e7c6d4", "best_bid": "0.009", "best_ask": "0.01"}, {"asset_id": "46916586432008324922492054082741681707965821813662860795622799670086307371133", "price": "0.998", "size": "5350", "side": "SELL", "hash": "945b7115a04738ebb463d329371ced0c66c8e872", "best_bid": "0.99", "best_ask": "0.991"}], "timestamp": "1769384713325", "event_type": "price_change"}}
{"_local_timestamp": "2026-01-25T23:45:13.391977+00:00", "data": {"market": "0x759b597b20756bff4086ed700c82b91b8b9fdee4267853dd9773c267738dcd1e", "price_changes": [{"asset_id": "39225767916489160517007045909404121985668346072423315764460339415130171638654", "price": "0.003", "size": "10435", "side": "BUY", "hash": "8e838d8f7b15b6fa5b3581ee2bd9be39a1e7c6d4", "best_bid": "0.009", "best_ask": "0.01"}, {"asset_id": "46916586432008324922492054082741681707965821813662860795622799670086307371133", "price": "0.997", "size": "10435", "side": "SELL", "hash": "945b7115a04738ebb463d329371ced0c66c8e872", "best_bid": "0.99", "best_ask": "0.991"}], "timestamp": "1769384713325", "event_type": "price_change"}}
{"_local_timestamp": "2026-01-25T23:45:13.392317+00:00", "data": {"market": "0x759b597b20756bff4086ed700c82b91b8b9fdee4267853dd9773c267738dcd1e", "price_changes": [{"asset_id": "39225767916489160517007045909404121985668346072423315764460339415130171638654", "price": "0.004", "size": "2850", "side": "BUY", "hash": "8e838d8f7b15b6fa5b3581ee2bd9be39a1e7c6d4", "best_bid": "0.009", "best_ask": "0.01"}, {"asset_id": "46916586432008324922492054082741681707965821813662860795622799670086307371133", "price": "0.996", "size": "2850", "side": "SELL", "hash": "945b7115a04738ebb463d329371ced0c66c8e872", "best_bid": "0.99", "best_ask": "0.991"}], "timestamp": "1769384713325", "event_type": "price_change"}}
{"_local_timestamp": "2026-01-25T23:45:13.399729+00:00", "data": {"market": "0x759b597b20756bff4086ed700c82b91b8b9fdee4267853dd9773c267738dcd1e", "price_changes": [{"asset_id": "39225767916489160517007045909404121985668346072423315764460339415130171638654", "price": "0.005", "size": "444", "side": "BUY", "hash": "8e838d8f7b15b6fa5b3581ee2bd9be39a1e7c6d4", "best_bid": "0.009", "best_ask": "0.01"}, {"asset_id": "46916586432008324922492054082741681707965821813662860795622799670086307371133", "price": "0.995", "size": "444", "side": "SELL", "hash": "945b7115a04738ebb463d329371ced0c66c8e872", "best_bid": "0.99", "best_ask": "0.991"}], "timestamp": "1769384713325", "event_type": "price_change"}}
{"_local_timestamp": "2026-01-25T23:45:13.400275+00:00", "data": {"market": "0x759b597b20756bff4086ed700c82b91b8b9fdee4267853dd9773c267738dcd1e", "price_changes": [{"asset_id": "39225767916489160517007045909404121985668346072423315764460339415130171638654", "price": "0.006", "size": "4964.74", "side": "BUY", "hash": "8e838d8f7b15b6fa5b3581ee2bd9be39a1e7c6d4", "best_bid": "0.009", "best_ask": "0.01"}, {"asset_id": "46916586432008324922492054082741681707965821813662860795622799670086307371133", "price": "0.994", "size": "4964.74", "side": "SELL", "hash": "945b7115a04738ebb463d329371ced0c66c8e872", "best_bid": "0.99", "best_ask": "0.991"}], "timestamp": "1769384713325", "event_type": "price_change"}}
{"_local_timestamp": "2026-01-25T23:45:13.400654+00:00", "data": {"market": "0x759b597b20756bff4086ed700c82b91b8b9fdee4267853dd9773c267738dcd1e", "price_changes": [{"asset_id": "39225767916489160517007045909404121985668346072423315764460339415130171638654", "price": "0.007", "size": "0", "side": "BUY", "hash": "8e838d8f7b15b6fa5b3581ee2bd9be39a1e7c6d4", "best_bid": "0.009", "best_ask": "0.01"}, {"asset_id": "46916586432008324922492054082741681707965821813662860795622799670086307371133", "price": "0.993", "size": "0", "side": "SELL", "hash": "945b7115a04738ebb463d329371ced0c66c8e872", "best_bid": "0.99", "best_ask": "0.991"}], "timestamp": "1769384713325", "event_type": "price_change"}}
{"_local_timestamp": "2026-01-25T23:45:13.864648+00:00", "data": {"market": "0x759b597b20756bff4086ed700c82b91b8b9fdee4267853dd9773c267738dcd1e", "price_changes": [{"asset_id": "39225767916489160517007045909404121985668346072423315764460339415130171638654", "price": "0.002", "size": "5434.37", "side": "BUY", "hash": "c5f871fcdb48da8ef6361c55cd7f4287ef7a2a4e", "best_bid": "0.009", "best_ask": "0.01"}, {"asset_id": "46916586432008324922492054082741681707965821813662860795622799670086307371133", "price": "0.998", "size": "5434.37", "side": "SELL", "hash": "e2e2272ebc54c254149d36d98a3b5e9b81aacb01", "best_bid": "0.99", "best_ask": "0.991"}], "timestamp": "1769384713800", "event_type": "price_change"}}
{"_local_timestamp": "2026-01-25T23:45:13.865060+00:00", "data": {"market": "0x759b597b20756bff4086ed700c82b91b8b9fdee4267853dd9773c267738dcd1e", "price_changes": [{"asset_id": "39225767916489160517007045909404121985668346072423315764460339415130171638654", "price": "0.005", "size": "477.24", "side": "BUY", "hash": "406a70fb1d1e3012eebe5563c701a9ed090f6d5f", "best_bid": "0.009", "best_ask": "0.01"}, {"asset_id": "46916586432008324922492054082741681707965821813662860795622799670086307371133", "price": "0.995", "size": "477.24", "side": "SELL", "hash": "7b413794424d8bf111587cf334ad5f0e39bad847", "best_bid": "0.99", "best_ask": "0.991"}], "timestamp": "1769384713801", "event_type": "price_change"}}
{"_local_timestamp": "2026-01-25T23:45:13.865787+00:00", "data": {"market": "0x759b597b20756bff4086ed700c82b91b8b9fdee4267853dd9773c267738dcd1e", "price_changes": [{"asset_id": "39225767916489160517007045909404121985668346072423315764460339415130171638654", "price": "0.007", "size": "23.51", "side": "BUY", "hash": "db692ccb22091227caf4830bca550b90c5bfcefc", "best_bid": "0.009", "best_ask": "0.01"}, {"asset_id": "46916586432008324922492054082741681707965821813662860795622799670086307371133", "price": "0.993", "size": "23.51", "side": "SELL", "hash": "c0013112f7a8223abc869a6ab6e33babeae0c282", "best_bid": "0.99", "best_ask": "0.991"}], "timestamp": "1769384713803", "event_type": "price_change"}}
{"_local_timestamp": "2026-01-25T23:45:13.868319+00:00", "data": {"market": "0x759b597b20756bff4086ed700c82b91b8b9fdee4267853dd9773c267738dcd1e", "price_changes": [{"asset_id": "39225767916489160517007045909404121985668346072423315764460339415130171638654", "price": "0.004", "size": "2891.76", "side": "BUY", "hash": "143358835bab8a26538f3ec968fc3c6c6cfa7c6c", "best_bid": "0.009", "best_ask": "0.01"}, {"asset_id": "46916586432008324922492054082741681707965821813662860795622799670086307371133", "price": "0.996", "size": "2891.76", "side": "SELL", "hash": "dc86538391539dcdeb9f8f1fe56e08bdb6f5a9dc", "best_bid": "0.99", "best_ask": "0.991"}], "timestamp": "1769384713805", "event_type": "price_change"}}
{"_local_timestamp": "2026-01-25T23:45:13.868728+00:00", "data": {"market": "0x759b597b20756bff4086ed700c82b91b8b9fdee4267853dd9773c267738dcd1e", "price_changes": [{"asset_id": "39225767916489160517007045909404121985668346072423315764460339415130171638654", "price": "0.006", "size": "4992.3", "side": "BUY", "hash": "e434addddaceafb6741bf3409e473a77197b864f", "best_bid": "0.009", "best_ask": "0.01"}, {"asset_id": "46916586432008324922492054082741681707965821813662860795622799670086307371133", "price": "0.994", "size": "4992.3", "side": "SELL", "hash": "647b9aa83960f82d7b8303c8dfccaead4be1132e", "best_bid": "0.99", "best_ask": "0.991"}], "timestamp": "1769384713807", "event_type": "price_change"}}
{"_local_timestamp": "2026-01-25T23:45:13.878435+00:00", "data": {"market": "0x759b597b20756bff4086ed700c82b91b8b9fdee4267853dd9773c267738dcd1e", "price_changes": [{"asset_id": "39225767916489160517007045909404121985668346072423315764460339415130171638654", "price": "0.003", "size": "10490.97", "side": "BUY", "hash": "584557ea1edf580705a4436a22373961029c4bd9", "best_bid": "0.009", "best_ask": "0.01"}, {"asset_id": "46916586432008324922492054082741681707965821813662860795622799670086307371133", "price": "0.997", "size": "10490.97", "side": "SELL", "hash": "f6046118a7d71fc08d35d4b9cb81c21a50c648ee", "best_bid": "0.99", "best_ask": "0.991"}], "timestamp": "1769384713809", "event_type": "price_change"}}
{"_local_timestamp": "2026-01-25T23:45:15.042277+00:00", "data": {"market": "0xbc27e1a503d5d962491fb41d0f0efd432c222fbfbb484b775ca0def7ed52288c", "price_changes": [{"asset_id": "22424973164442660525283958049724397021587362098150529484937062183898885124879", "price": "0.05", "size": "5980", "side": "BUY", "hash": "8dd7280576ebf1324db034e5f6fa9bc3b1b76782", "best_bid": "0.08", "best_ask": "0.1"}, {"asset_id": "84464967243852186849141927382392363797190214011244597826174886881676581745178", "price": "0.95", "size": "5980", "side": "SELL", "hash": "0b0961d5fb71d2917c9395a21812e9b0d2c71365", "best_bid": "0.9", "best_ask": "0.92"}], "timestamp": "1769384714974", "event_type": "price_change"}}
{"_local_timestamp": "2026-01-25T23:45:15.042697+00:00", "data": {"market": "0xbc27e1a503d5d962491fb41d0f0efd432c222fbfbb484b775ca0def7ed52288c", "price_changes": [{"asset_id": "84464967243852186849141927382392363797190214011244597826174886881676581745178", "price": "0.87", "size": "146.23", "side": "BUY", "hash": "3419b5d4b88551a11b00e263aba0c2a1b2029cae", "best_bid": "0.9", "best_ask": "0.92"}, {"asset_id": "22424973164442660525283958049724397021587362098150529484937062183898885124879", "price": "0.13", "size": "146.23", "side": "SELL", "hash": "718ecf9f32d8b4c3466881eedad5de60d1547f0d", "best_bid": "0.08", "best_ask": "0.1"}], "timestamp": "1769384714975", "event_type": "price_change"}}
{"_local_timestamp": "2026-01-25T23:45:38.939556+00:00", "data": {"market": "0xbc27e1a503d5d962491fb41d0f0efd432c222fbfbb484b775ca0def7ed52288c", "price_changes": [{"asset_id": "84464967243852186849141927382392363797190214011244597826174886881676581745178", "price": "0.22", "size": "200", "side": "BUY", "hash": "b31ca1908264da83f30ebebfad7f92af4c468c4d", "best_bid": "0.9", "best_ask": "0.92"}, {"asset_id": "22424973164442660525283958049724397021587362098150529484937062183898885124879", "price": "0.78", "size": "200", "side": "SELL", "hash": "994ad5099c1b8bd105397d1f9db638669b688ef3", "best_bid": "0.08", "best_ask": "0.1"}], "timestamp": "1769384738821", "event_type": "price_change"}}
{"_local_timestamp": "2026-01-25T23:45:38.940232+00:00", "data": {"market": "0xbc27e1a503d5d962491fb41d0f0efd432c222fbfbb484b775ca0def7ed52288c", "price_changes": [{"asset_id": "84464967243852186849141927382392363797190214011244597826174886881676581745178", "price": "0.28", "size": "142.85", "side": "BUY", "hash": "9ba263e9c9142ad0c6d2c2fb6c156019acd93e82", "best_bid": "0.9", "best_ask": "0.92"}, {"asset_id": "22424973164442660525283958049724397021587362098150529484937062183898885124879", "price": "0.72", "size": "142.85", "side": "SELL", "hash": "d05a5da66c9f80c2fbe5e95dce9cc28bcb9b0325", "best_bid": "0.08", "best_ask": "0.1"}], "timestamp": "1769384738822", "event_type": "price_change"}}
{"_local_timestamp": "2026-01-25T23:45:39.164684+00:00", "data": {"market": "0xbc27e1a503d5d962491fb41d0f0efd432c222fbfbb484b775ca0def7ed52288c", "price_changes": [{"asset_id": "84464967243852186849141927382392363797190214011244597826174886881676581745178", "price": "0.29", "size": "1498", "side": "BUY", "hash": "4c90e66d201ad1e47043a0bc1931a3f3204fbdc4", "best_bid": "0.9", "best_ask": "0.92"}, {"asset_id": "22424973164442660525283958049724397021587362098150529484937062183898885124879", "price": "0.71", "size": "1498", "side": "SELL", "hash": "da68797332844c4cdf16795589a45a7967fef301", "best_bid": "0.08", "best_ask": "0.1"}], "timestamp": "1769384739075", "event_type": "price_change"}}
{"_local_timestamp": "2026-01-25T23:45:39.231045+00:00", "data": {"market": "0xbc27e1a503d5d962491fb41d0f0efd432c222fbfbb484b775ca0def7ed52288c", "price_changes": [{"asset_id": "84464967243852186849141927382392363797190214011244597826174886881676581745178", "price": "0.21", "size": "860", "side": "BUY", "hash": "f54ca5bfc6b449622daf8f2c936fdd2a2f73c093", "best_bid": "0.9", "best_ask": "0.92"}, {"asset_id": "22424973164442660525283958049724397021587362098150529484937062183898885124879", "price": "0.79", "size": "860", "side": "SELL", "hash": "6617110415389766313aaa710a300d6474d4089e", "best_bid": "0.08", "best_ask": "0.1"}], "timestamp": "1769384739087", "event_type": "price_change"}}
{"_local_timestamp": "2026-01-25T23:46:03.509410+00:00", "data": {"market": "0xbc27e1a503d5d962491fb41d0f0efd432c222fbfbb484b775ca0def7ed52288c", "price_changes": [{"asset_id": "22424973164442660525283958049724397021587362098150529484937062183898885124879", "price": "0.02", "size": "16248.11", "side": "BUY", "hash": "4ce81bc5dd0d4f7b8a90f1bb901b66a681c2a4cf", "best_bid": "0.08", "best_ask": "0.1"}, {"asset_id": "84464967243852186849141927382392363797190214011244597826174886881676581745178", "price": "0.98", "size": "16248.11", "side": "SELL", "hash": "2c52992bc799e53c18fe34b93f2740c6cc501352", "best_bid": "0.9", "best_ask": "0.92"}], "timestamp": "1769384763436", "event_type": "price_change"}}
{"_local_timestamp": "2026-01-25T23:46:03.509832+00:00", "data": {"market": "0xbc27e1a503d5d962491fb41d0f0efd432c222fbfbb484b775ca0def7ed52288c", "price_changes": [{"asset_id": "22424973164442660525283958049724397021587362098150529484937062183898885124879", "price": "0.06", "size": "4095.98", "side": "BUY", "hash": "cf51b1e6404ff2ff49cef789722d4bd954f66db7", "best_bid": "0.08", "best_ask": "0.1"}, {"asset_id": "84464967243852186849141927382392363797190214011244597826174886881676581745178", "price": "0.94", "size": "4095.98", "side": "SELL", "hash": "1555d7f93876f99f5f80a73f314ec43f84585bb8", "best_bid": "0.9", "best_ask": "0.92"}], "timestamp": "1769384763437", "event_type": "price_change"}}
{"_local_timestamp": "2026-01-25T23:46:03.510251+00:00", "data": {"market": "0xbc27e1a503d5d962491fb41d0f0efd432c222fbfbb484b775ca0def7ed52288c", "price_changes": [{"asset_id": "22424973164442660525283958049724397021587362098150529484937062183898885124879", "price": "0.05", "size": "6040", "side": "BUY", "hash": "15a85502c876bebba49e19991cdd864a4c8573ad", "best_bid": "0.08", "best_ask": "0.1"}, {"asset_id": "84464967243852186849141927382392363797190214011244597826174886881676581745178", "price": "0.95", "size": "6040", "side": "SELL", "hash": "38a22e4c64624e6243391dcf4329fb1b4f9497fe", "best_bid": "0.9", "best_ask": "0.92"}], "timestamp": "1769384763438", "event_type": "price_change"}}
{"_local_timestamp": "2026-01-25T23:46:10.627064+00:00", "data": {"market": "0xbc27e1a503d5d962491fb41d0f0efd432c222fbfbb484b775ca0def7ed52288c", "price_changes": [{"asset_id": "84464967243852186849141927382392363797190214011244597826174886881676581745178", "price": "0.29", "size": "50", "side": "BUY", "hash": "c36acd75ede5e2cf4a2eb345b9982a73555e8d7b", "best_bid": "0.9", "best_ask": "0.92"}, {"asset_id": "22424973164442660525283958049724397021587362098150529484937062183898885124879", "price": "0.71", "size": "50", "side": "SELL", "hash": "3f0c012ddf0709efc0b9d9ee24c4a9f92afadbdb", "best_bid": "0.08", "best_ask": "0.1"}], "timestamp": "1769384770466", "event_type": "price_change"}}
{"_local_timestamp": "2026-01-25T23:46:30.761184+00:00", "data": {"market": "0xbc27e1a503d5d962491fb41d0f0efd432c222fbfbb484b775ca0def7ed52288c", "price_changes": [{"asset_id": "84464967243852186849141927382392363797190214011244597826174886881676581745178", "price": "0.23", "size": "1947.73", "side": "BUY", "hash": "52e8dfadf3a610bb59af74793a49403a4e475964", "best_bid": "0.9", "best_ask": "0.92"}, {"asset_id": "22424973164442660525283958049724397021587362098150529484937062183898885124879", "price": "0.77", "size": "1947.73", "side": "SELL", "hash": "f20ed948fab7e5f0c922e858f44f246013534b7a", "best_bid": "0.08", "best_ask": "0.1"}], "timestamp": "1769384790677", "event_type": "price_change"}}
{"_local_timestamp": "2026-01-25T23:46:58.965470+00:00", "data": {"market": "0xbc27e1a503d5d962491fb41d0f0efd432c222fbfbb484b775ca0def7ed52288c", "price_changes": [{"asset_id": "84464967243852186849141927382392363797190214011244597826174886881676581745178", "price": "0.29", "size": "0", "side": "BUY", "hash": "30625225cda0d086a05d137d078de424a36cc497", "best_bid": "0.9", "best_ask": "0.92"}, {"asset_id": "22424973164442660525283958049724397021587362098150529484937062183898885124879", "price": "0.71", "size": "0", "side": "SELL", "hash": "764190e2c64ba6c282d030874052d4299c517cca", "best_bid": "0.08", "best_ask": "0.1"}], "timestamp": "1769384818861", "event_type": "price_change"}}
{"_local_timestamp": "2026-01-25T23:46:59.295105+00:00", "data": {"market": "0xbc27e1a503d5d962491fb41d0f0efd432c222fbfbb484b775ca0def7ed52288c", "price_changes": [{"asset_id": "84464967243852186849141927382392363797190214011244597826174886881676581745178", "price": "0.28", "size": "192.85", "side": "BUY", "hash": "123122cb5cb6c7c97e79717ba629a30acba1e091", "best_bid": "0.9", "best_ask": "0.92"}, {"asset_id": "22424973164442660525283958049724397021587362098150529484937062183898885124879", "price": "0.72", "size": "192.85", "side": "SELL", "hash": "caa99b9369c48575fee5b8843a654c37273f1e17", "best_bid": "0.08", "best_ask": "0.1"}], "timestamp": "1769384819162", "event_type": "price_change"}}
{"_local_timestamp": "2026-01-25T23:47:23.557522+00:00", "data": {"market": "0xbc27e1a503d5d962491fb41d0f0efd432c222fbfbb484b775ca0def7ed52288c", "price_changes": [{"asset_id": "84464967243852186849141927382392363797190214011244597826174886881676581745178", "price": "0.22", "size": "150", "side": "BUY", "hash": "a6f45d99fffbf3e63dbe0cc8fa9ea551c12c050d", "best_bid": "0.9", "best_ask": "0.92"}, {"asset_id": "22424973164442660525283958049724397021587362098150529484937062183898885124879", "price": "0.78", "size": "150", "side": "SELL", "hash": "79e07f89275bab5ccb63c8b87afe6215c561ca27", "best_bid": "0.08", "best_ask": "0.1"}], "timestamp": "1769384843405", "event_type": "price_change"}}
{"_local_timestamp": "2026-01-25T23:47:23.558258+00:00", "data": {"market": "0xbc27e1a503d5d962491fb41d0f0efd432c222fbfbb484b775ca0def7ed52288c", "price_changes": [{"asset_id": "84464967243852186849141927382392363797190214011244597826174886881676581745178", "price": "0.28", "size": "142.85", "side": "BUY", "hash": "a6f45d99fffbf3e63dbe0cc8fa9ea551c12c050d", "best_bid": "0.9", "best_ask": "0.92"}, {"asset_id": "22424973164442660525283958049724397021587362098150529484937062183898885124879", "price": "0.72", "size": "142.85", "side": "SELL", "hash": "79e07f89275bab5ccb63c8b87afe6215c561ca27", "best_bid": "0.08", "best_ask": "0.1"}], "timestamp": "1769384843405", "event_type": "price_change"}}
{"_local_timestamp": "2026-01-25T23:47:23.993134+00:00", "data": {"market": "0xbc27e1a503d5d962491fb41d0f0efd432c222fbfbb484b775ca0def7ed52288c", "price_changes": [{"asset_id": "84464967243852186849141927382392363797190214011244597826174886881676581745178", "price": "0.29", "size": "50", "side": "BUY", "hash": "95d5cb4d7a6bfbad8f79868829c40fe89bd28b26", "best_bid": "0.9", "best_ask": "0.92"}, {"asset_id": "22424973164442660525283958049724397021587362098150529484937062183898885124879", "price": "0.71", "size": "50", "side": "SELL", "hash": "c22c035cd752865702364244b6e2e24763c5114f", "best_bid": "0.08", "best_ask": "0.1"}], "timestamp": "1769384843841", "event_type": "price_change"}}
{"_local_timestamp": "2026-01-25T23:47:23.993611+00:00", "data": {"market": "0xbc27e1a503d5d962491fb41d0f0efd432c222fbfbb484b775ca0def7ed52288c", "price_changes": [{"asset_id": "84464967243852186849141927382392363797190214011244597826174886881676581745178", "price": "0.21", "size": "910", "side": "BUY", "hash": "1b7b14f0829e9ef4d44cc26aa11dcfce6ac6c7d1", "best_bid": "0.9", "best_ask": "0.92"}, {"asset_id": "22424973164442660525283958049724397021587362098150529484937062183898885124879", "price": "0.79", "size": "910", "side": "SELL", "hash": "fd34f40d72d925b87e171a67c3edb70f704e9bd8", "best_bid": "0.08", "best_ask": "0.1"}], "timestamp": "1769384843864", "event_type": "price_change"}}
{"_local_timestamp": "2026-01-25T23:47:37.383347+00:00", "data": {"market": "0xbc27e1a503d5d962491fb41d0f0efd432c222fbfbb484b775ca0def7ed52288c", "price_changes": [{"asset_id": "84464967243852186849141927382392363797190214011244597826174886881676581745178", "price": "0.21", "size": "810", "side": "BUY", "hash": "82450785b3352d6f2f1984770e4abd4fcfc340ac", "best_bid": "0.9", "best_ask": "0.92"}, {"asset_id": "22424973164442660525283958049724397021587362098150529484937062183898885124879", "price": "0.79", "size": "810", "side": "SELL", "hash": "b2c72e661d1bdff01223d9092dff9089fdc2115a", "best_bid": "0.08", "best_ask": "0.1"}], "timestamp": "1769384857297", "event_type": "price_change"}}
{"_local_timestamp": "2026-01-25T23:47:37.687158+00:00", "data": {"market": "0xbc27e1a503d5d962491fb41d0f0efd432c222fbfbb484b775ca0def7ed52288c", "price_changes": [{"asset_id": "84464967243852186849141927382392363797190214011244597826174886881676581745178", "price": "0.22", "size": "100", "side": "BUY", "hash": "92a11dc4a7b49b4cd35003d9d86314aa99686467", "best_bid": "0.9", "best_ask": "0.92"}, {"asset_id": "22424973164442660525283958049724397021587362098150529484937062183898885124879", "price": "0.78", "size": "100", "side": "SELL", "hash": "0d09e0cd03559c07672eda9f5bac05e3bbb625ee", "best_bid": "0.08", "best_ask": "0.1"}], "timestamp": "1769384857535", "event_type": "price_change"}}
{"_local_timestamp": "2026-01-25T23:47:37.923474+00:00", "data": {"market": "0xbc27e1a503d5d962491fb41d0f0efd432c222fbfbb484b775ca0def7ed52288c", "price_changes": [{"asset_id": "84464967243852186849141927382392363797190214011244597826174886881676581745178", "price": "0.23", "size": "2047.73", "side": "BUY", "hash": "7d44fa9cbb09a14a309b273098d0df67e75b04c0", "best_bid": "0.9", "best_ask": "0.92"}, {"asset_id": "22424973164442660525283958049724397021587362098150529484937062183898885124879", "price": "0.77", "size": "2047.73", "side": "SELL", "hash": "66efce55612e3dcb0f67d4e2b4045b2d34c26ae7", "best_bid": "0.08", "best_ask": "0.1"}], "timestamp": "1769384857602", "event_type": "price_change"}}
{"_local_timestamp": "2026-01-25T23:47:38.265906+00:00", "data": {"market": "0xbc27e1a503d5d962491fb41d0f0efd432c222fbfbb484b775ca0def7ed52288c", "price_changes": [{"asset_id": "84464967243852186849141927382392363797190214011244597826174886881676581745178", "price": "0.29", "size": "100", "side": "BUY", "hash": "b734b641efa91a1c987d0824340da690523e0676", "best_bid": "0.9", "best_ask": "0.92"}, {"asset_id": "22424973164442660525283958049724397021587362098150529484937062183898885124879", "price": "0.71", "size": "100", "side": "SELL", "hash": "43bd849b02deece3da1f33f55435a221456a0f2e", "best_bid": "0.08", "best_ask": "0.1"}], "timestamp": "1769384858036", "event_type": "price_change"}}
{"_local_timestamp": "2026-01-25T23:47:56.071933+00:00", "data": {"market": "0xbc27e1a503d5d962491fb41d0f0efd432c222fbfbb484b775ca0def7ed52288c", "price_changes": [{"asset_id": "22424973164442660525283958049724397021587362098150529484937062183898885124879", "price": "0.05", "size": "5880", "side": "BUY", "hash": "9b9febedfaefad0fe1eb819ed8d8dccf4bd192cd", "best_bid": "0.08", "best_ask": "0.1"}, {"asset_id": "84464967243852186849141927382392363797190214011244597826174886881676581745178", "price": "0.95", "size": "5880", "side": "SELL", "hash": "cff7c7c444d46c2520a663e0f177cf5be1c8e8f4", "best_bid": "0.9", "best_ask": "0.92"}], "timestamp": "1769384876000", "event_type": "price_change"}}
{"_local_timestamp": "2026-01-25T23:47:56.081708+00:00", "data": {"market": "0xbc27e1a503d5d962491fb41d0f0efd432c222fbfbb484b775ca0def7ed52288c", "price_changes": [{"asset_id": "22424973164442660525283958049724397021587362098150529484937062183898885124879", "price": "0.06", "size": "2978.98", "side": "BUY", "hash": "d556fca3d9cb170d80c9bcb7d5e23762c68e55b8", "best_bid": "0.08", "best_ask": "0.1"}, {"asset_id": "84464967243852186849141927382392363797190214011244597826174886881676581745178", "price": "0.94", "size": "2978.98", "side": "SELL", "hash": "35ce003c64ab0e9a6e843a56ab4e6556f7576c06", "best_bid": "0.9", "best_ask": "0.92"}], "timestamp": "1769384876001", "event_type": "price_change"}}
{"_local_timestamp": "2026-01-25T23:47:56.090071+00:00", "data": {"market": "0xbc27e1a503d5d962491fb41d0f0efd432c222fbfbb484b775ca0def7ed52288c", "price_changes": [{"asset_id": "22424973164442660525283958049724397021587362098150529484937062183898885124879", "price": "0.02", "size": "2798.11", "side": "BUY", "hash": "fa4ccbb3dd1ea713040bf7d336d03abfa7540d88", "best_bid": "0.08", "best_ask": "0.1"}, {"asset_id": "84464967243852186849141927382392363797190214011244597826174886881676581745178", "price": "0.98", "size": "2798.11", "side": "SELL", "hash": "98a5ff4b60d6927c21d308aff918f718265853ab", "best_bid": "0.9", "best_ask": "0.92"}], "timestamp": "1769384876002", "event_type": "price_change"}}
{"_local_timestamp": "2026-01-25T23:48:11.530413+00:00", "data": {"market": "0xbc27e1a503d5d962491fb41d0f0efd432c222fbfbb484b775ca0def7ed52288c", "price_changes": [{"asset_id": "84464967243852186849141927382392363797190214011244597826174886881676581745178", "price": "0.28", "size": "92.85", "side": "BUY", "hash": "c3fac67c02b3a0c68722ec1fc2f2baad3bb51901", "best_bid": "0.9", "best_ask": "0.92"}, {"asset_id": "22424973164442660525283958049724397021587362098150529484937062183898885124879", "price": "0.72", "size": "92.85", "side": "SELL", "hash": "e640082f166ec7bad1175c9657dea3a7a4883f24", "best_bid": "0.08", "best_ask": "0.1"}], "timestamp": "1769384891444", "event_type": "price_change"}}
{"_local_timestamp": "2026-01-25T23:48:11.756358+00:00", "data": {"market": "0xbc27e1a503d5d962491fb41d0f0efd432c222fbfbb484b775ca0def7ed52288c", "price_changes": [{"asset_id": "84464967243852186849141927382392363797190214011244597826174886881676581745178", "price": "0.29", "size": "150", "side": "BUY", "hash": "fb4b34bebe216e0e768974e2ff05045f7565aecb", "best_bid": "0.9", "best_ask": "0.92"}, {"asset_id": "22424973164442660525283958049724397021587362098150529484937062183898885124879", "price": "0.71", "size": "150", "side": "SELL", "hash": "618744d8e66e467e24436d5eb2ae36dd8184c2e4", "best_bid": "0.08", "best_ask": "0.1"}], "timestamp": "1769384891680", "event_type": "price_change"}}
{"_local_timestamp": "2026-01-25T23:49:25.429207+00:00", "data": {"market": "0xbc27e1a503d5d962491fb41d0f0efd432c222fbfbb484b775ca0def7ed52288c", "price_changes": [{"asset_id": "84464967243852186849141927382392363797190214011244597826174886881676581745178", "price": "0.29", "size": "100", "side": "BUY", "hash": "277b23f239c1b0507baba02f82bafb9b0940ae1e", "best_bid": "0.9", "best_ask": "0.92"}, {"asset_id": "22424973164442660525283958049724397021587362098150529484937062183898885124879", "price": "0.71", "size": "100", "side": "SELL", "hash": "7e09085e9c35d4f217d3780b8686aa840114e4f1", "best_bid": "0.08", "best_ask": "0.1"}], "timestamp": "1769384965279", "event_type": "price_change"}}
{"_local_timestamp": "2026-01-25T23:49:25.670020+00:00", "data": {"market": "0x759b597b20756bff4086ed700c82b91b8b9fdee4267853dd9773c267738dcd1e", "price_changes": [{"asset_id": "39225767916489160517007045909404121985668346072423315764460339415130171638654", "price": "0.002", "size": "5350", "side": "BUY", "hash": "17ff75db361152b52a8b3dddce39dfd7792d1ca7", "best_bid": "0.009", "best_ask": "0.01"}, {"asset_id": "46916586432008324922492054082741681707965821813662860795622799670086307371133", "price": "0.998", "size": "5350", "side": "SELL", "hash": "d86db4f79d466d7a00b4ca114f2bb2a291bc0288", "best_bid": "0.99", "best_ask": "0.991"}], "timestamp": "1769384965605", "event_type": "price_change"}}
{"_local_timestamp": "2026-01-25T23:49:25.676553+00:00", "data": {"market": "0x759b597b20756bff4086ed700c82b91b8b9fdee4267853dd9773c267738dcd1e", "price_changes": [{"asset_id": "39225767916489160517007045909404121985668346072423315764460339415130171638654", "price": "0.003", "size": "10435", "side": "BUY", "hash": "17ff75db361152b52a8b3dddce39dfd7792d1ca7", "best_bid": "0.009", "best_ask": "0.01"}, {"asset_id": "46916586432008324922492054082741681707965821813662860795622799670086307371133", "price": "0.997", "size": "10435", "side": "SELL", "hash": "d86db4f79d466d7a00b4ca114f2bb2a291bc0288", "best_bid": "0.99", "best_ask": "0.991"}], "timestamp": "1769384965605", "event_type": "price_change"}}
{"_local_timestamp": "2026-01-25T23:49:25.677140+00:00", "data": {"market": "0x759b597b20756bff4086ed700c82b91b8b9fdee4267853dd9773c267738dcd1e", "price_changes": [{"asset_id": "39225767916489160517007045909404121985668346072423315764460339415130171638654", "price": "0.004", "size": "2850", "side": "BUY", "hash": "17ff75db361152b52a8b3dddce39dfd7792d1ca7", "best_bid": "0.009", "best_ask": "0.01"}, {"asset_id": "46916586432008324922492054082741681707965821813662860795622799670086307371133", "price": "0.996", "size": "2850", "side": "SELL", "hash": "d86db4f79d466d7a00b4ca114f2bb2a291bc0288", "best_bid": "0.99", "best_ask": "0.991"}], "timestamp": "1769384965605", "event_type": "price_change"}}
{"_local_timestamp": "2026-01-25T23:49:25.677610+00:00", "data": {"market": "0x759b597b20756bff4086ed700c82b91b8b9fdee4267853dd9773c267738dcd1e", "price_changes": [{"asset_id": "39225767916489160517007045909404121985668346072423315764460339415130171638654", "price": "0.005", "size": "444", "side": "BUY", "hash": "17ff75db361152b52a8b3dddce39dfd7792d1ca7", "best_bid": "0.009", "best_ask": "0.01"}, {"asset_id": "46916586432008324922492054082741681707965821813662860795622799670086307371133", "price": "0.995", "size": "444", "side": "SELL", "hash": "d86db4f79d466d7a00b4ca114f2bb2a291bc0288", "best_bid": "0.99", "best_ask": "0.991"}], "timestamp": "1769384965605", "event_type": "price_change"}}
{"_local_timestamp": "2026-01-25T23:49:25.678031+00:00", "data": {"market": "0x759b597b20756bff4086ed700c82b91b8b9fdee4267853dd9773c267738dcd1e", "price_changes": [{"asset_id": "39225767916489160517007045909404121985668346072423315764460339415130171638654", "price": "0.006", "size": "4964.74", "side": "BUY", "hash": "17ff75db361152b52a8b3dddce39dfd7792d1ca7", "best_bid": "0.009", "best_ask": "0.01"}, {"asset_id": "46916586432008324922492054082741681707965821813662860795622799670086307371133", "price": "0.994", "size": "4964.74", "side": "SELL", "hash": "d86db4f79d466d7a00b4ca114f2bb2a291bc0288", "best_bid": "0.99", "best_ask": "0.991"}], "timestamp": "1769384965605", "event_type": "price_change"}}
{"_local_timestamp": "2026-01-25T23:49:25.678470+00:00", "data": {"market": "0x759b597b20756bff4086ed700c82b91b8b9fdee4267853dd9773c267738dcd1e", "price_changes": [{"asset_id": "39225767916489160517007045909404121985668346072423315764460339415130171638654", "price": "0.007", "size": "0", "side": "BUY", "hash": "17ff75db361152b52a8b3dddce39dfd7792d1ca7", "best_bid": "0.009", "best_ask": "0.01"}, {"asset_id": "46916586432008324922492054082741681707965821813662860795622799670086307371133", "price": "0.993", "size": "0", "side": "SELL", "hash": "d86db4f79d466d7a00b4ca114f2bb2a291bc0288", "best_bid": "0.99", "best_ask": "0.991"}], "timestamp": "1769384965605", "event_type": "price_change"}}
{"_local_timestamp": "2026-01-25T23:49:25.971235+00:00", "data": {"market": "0xbc27e1a503d5d962491fb41d0f0efd432c222fbfbb484b775ca0def7ed52288c", "price_changes": [{"asset_id": "84464967243852186849141927382392363797190214011244597826174886881676581745178", "price": "0.23", "size": "2097.73", "side": "BUY", "hash": "b288c604672835dfc5855dcfd550dbe05142e00d", "best_bid": "0.9", "best_ask": "0.92"}, {"asset_id": "22424973164442660525283958049724397021587362098150529484937062183898885124879", "price": "0.77", "size": "2097.73", "side": "SELL", "hash": "67e3262a41c37c9ac70510f623117cf65891bf60", "best_bid": "0.08", "best_ask": "0.1"}], "timestamp": "1769384965785", "event_type": "price_change"}}
{"_local_timestamp": "2026-01-25T23:49:26.211345+00:00", "data": {"market": "0x759b597b20756bff4086ed700c82b91b8b9fdee4267853dd9773c267738dcd1e", "price_changes": [{"asset_id": "39225767916489160517007045909404121985668346072423315764460339415130171638654", "price": "0.005", "size": "477.24", "side": "BUY", "hash": "96f972ee08d50eb1c6314034683622581a5d0b8f", "best_bid": "0.009", "best_ask": "0.01"}, {"asset_id": "46916586432008324922492054082741681707965821813662860795622799670086307371133", "price": "0.995", "size": "477.24", "side": "SELL", "hash": "9c72da4a02184721b1c346ea7b7fb8fe71fad759", "best_bid": "0.99", "best_ask": "0.991"}], "timestamp": "1769384966033", "event_type": "price_change"}}
{"_local_timestamp": "2026-01-25T23:49:26.221607+00:00", "data": {"market": "0x759b597b20756bff4086ed700c82b91b8b9fdee4267853dd9773c267738dcd1e", "price_changes": [{"asset_id": "39225767916489160517007045909404121985668346072423315764460339415130171638654", "price": "0.006", "size": "4992.3", "side": "BUY", "hash": "7a223f01e561b4d577e11b5e102743ef2ee3d238", "best_bid": "0.009", "best_ask": "0.01"}, {"asset_id": "46916586432008324922492054082741681707965821813662860795622799670086307371133", "price": "0.994", "size": "4992.3", "side": "SELL", "hash": "dfa9776230ad5fa53756052fd2bf1d618b8e2354", "best_bid": "0.99", "best_ask": "0.991"}], "timestamp": "1769384966034", "event_type": "price_change"}}
{"_local_timestamp": "2026-01-25T23:49:26.222216+00:00", "data": {"market": "0x759b597b20756bff4086ed700c82b91b8b9fdee4267853dd9773c267738dcd1e", "price_changes": [{"asset_id": "39225767916489160517007045909404121985668346072423315764460339415130171638654", "price": "0.002", "size": "5434.37", "side": "BUY", "hash": "9c9e5888954f8738fb79fa3ab4079f6af07868f1", "best_bid": "0.009", "best_ask": "0.01"}, {"asset_id": "46916586432008324922492054082741681707965821813662860795622799670086307371133", "price": "0.998", "size": "5434.37", "side": "SELL", "hash": "639036c3aff9e9e8eb95ebc0f24b0749987538c3", "best_bid": "0.99", "best_ask": "0.991"}], "timestamp": "1769384966036", "event_type": "price_change"}}
{"_local_timestamp": "2026-01-25T23:49:26.222684+00:00", "data": {"market": "0x759b597b20756bff4086ed700c82b91b8b9fdee4267853dd9773c267738dcd1e", "price_changes": [{"asset_id": "39225767916489160517007045909404121985668346072423315764460339415130171638654", "price": "0.003", "size": "10490.97", "side": "BUY", "hash": "e7440b64ef27c7775b3ef0e54abfe7f4fe082e19", "best_bid": "0.009", "best_ask": "0.01"}, {"asset_id": "46916586432008324922492054082741681707965821813662860795622799670086307371133", "price": "0.997", "size": "10490.97", "side": "SELL", "hash": "9775b4b991a9ff17c4d14b23c9e5f024df977d38", "best_bid": "0.99", "best_ask": "0.991"}], "timestamp": "1769384966037", "event_type": "price_change"}}
{"_local_timestamp": "2026-01-25T23:49:26.223131+00:00", "data": {"market": "0x759b597b20756bff4086ed700c82b91b8b9fdee4267853dd9773c267738dcd1e", "price_changes": [{"asset_id": "39225767916489160517007045909404121985668346072423315764460339415130171638654", "price": "0.007", "size": "23.51", "side": "BUY", "hash": "de2a59e306524e07e30a3115ecc7aa9045f2833f", "best_bid": "0.009", "best_ask": "0.01"}, {"asset_id": "46916586432008324922492054082741681707965821813662860795622799670086307371133", "price": "0.993", "size": "23.51", "side": "SELL", "hash": "c428c40d0ac3cc28c143ac2110f97f0cbd377b71", "best_bid": "0.99", "best_ask": "0.991"}], "timestamp": "1769384966038", "event_type": "price_change"}}
{"_local_timestamp": "2026-01-25T23:49:26.223603+00:00", "data": {"market": "0x759b597b20756bff4086ed700c82b91b8b9fdee4267853dd9773c267738dcd1e", "price_changes": [{"asset_id": "39225767916489160517007045909404121985668346072423315764460339415130171638654", "price": "0.004", "size": "2891.76", "side": "BUY", "hash": "1f348add7b192dc6d4887865269efc16f438d133", "best_bid": "0.009", "best_ask": "0.01"}, {"asset_id": "46916586432008324922492054082741681707965821813662860795622799670086307371133", "price": "0.996", "size": "2891.76", "side": "SELL", "hash": "cf19203cdb32c74e954a31b55864bd24ddb23aff", "best_bid": "0.99", "best_ask": "0.991"}], "timestamp": "1769384966040", "event_type": "price_change"}}
{"_local_timestamp": "2026-01-25T23:49:28.945520+00:00", "data": {"market": "0xbc27e1a503d5d962491fb41d0f0efd432c222fbfbb484b775ca0def7ed52288c", "price_changes": [{"asset_id": "22424973164442660525283958049724397021587362098150529484937062183898885124879", "price": "0.02", "size": "16248.11", "side": "BUY", "hash": "319a29cd8e2f6653cc978415ce7123d777cc994c", "best_bid": "0.08", "best_ask": "0.1"}, {"asset_id": "84464967243852186849141927382392363797190214011244597826174886881676581745178", "price": "0.98", "size": "16248.11", "side": "SELL", "hash": "40ad8365387576c765aa200227243ffc43b04e65", "best_bid": "0.9", "best_ask": "0.92"}], "timestamp": "1769384968874", "event_type": "price_change"}}
{"_local_timestamp": "2026-01-25T23:49:28.946219+00:00", "data": {"market": "0xbc27e1a503d5d962491fb41d0f0efd432c222fbfbb484b775ca0def7ed52288c", "price_changes": [{"asset_id": "22424973164442660525283958049724397021587362098150529484937062183898885124879", "price": "0.06", "size": "4095.98", "side": "BUY", "hash": "7e8927845d73ea94d164d9b51212aac545747ae4", "best_bid": "0.08", "best_ask": "0.1"}, {"asset_id": "84464967243852186849141927382392363797190214011244597826174886881676581745178", "price": "0.94", "size": "4095.98", "side": "SELL", "hash": "c39673a53e2f9c364cdd6570da25d361dee33232", "best_bid": "0.9", "best_ask": "0.92"}], "timestamp": "1769384968877", "event_type": "price_change"}}
{"_local_timestamp": "2026-01-25T23:49:28.946788+00:00", "data": {"market": "0xbc27e1a503d5d962491fb41d0f0efd432c222fbfbb484b775ca0def7ed52288c", "price_changes": [{"asset_id": "22424973164442660525283958049724397021587362098150529484937062183898885124879", "price": "0.05", "size": "6040", "side": "BUY", "hash": "b0457c3ffcef51dceeb1cae13f09256500814cda", "best_bid": "0.08", "best_ask": "0.1"}, {"asset_id": "84464967243852186849141927382392363797190214011244597826174886881676581745178", "price": "0.95", "size": "6040", "side": "SELL", "hash": "6cb6d8088d7871622a90b3f912a7f2d16552e76d", "best_bid": "0.9", "best_ask": "0.92"}], "timestamp": "1769384968880", "event_type": "price_change"}}
{"_local_timestamp": "2026-01-25T23:49:30.298818+00:00", "data": {"market": "0xbc27e1a503d5d962491fb41d0f0efd432c222fbfbb484b775ca0def7ed52288c", "price_changes": [{"asset_id": "84464967243852186849141927382392363797190214011244597826174886881676581745178", "price": "0.22", "size": "0", "side": "BUY", "hash": "143773eaec87fc048de9fcaf464c26d9fc141dfc", "best_bid": "0.9", "best_ask": "0.92"}, {"asset_id": "22424973164442660525283958049724397021587362098150529484937062183898885124879", "price": "0.78", "size": "0", "side": "SELL", "hash": "ec5a1874b4295617283b55c76d0fa2fe5ec22571", "best_bid": "0.08", "best_ask": "0.1"}], "timestamp": "1769384970053", "event_type": "price_change"}}
{"_local_timestamp": "2026-01-25T23:49:31.034458+00:00", "data": {"market": "0xbc27e1a503d5d962491fb41d0f0efd432c222fbfbb484b775ca0def7ed52288c", "price_changes": [{"asset_id": "84464967243852186849141927382392363797190214011244597826174886881676581745178", "price": "0.23", "size": "2197.73", "side": "BUY", "hash": "f86efebde965f3e04250b061afac29b8f5478508", "best_bid": "0.9", "best_ask": "0.92"}, {"asset_id": "22424973164442660525283958049724397021587362098150529484937062183898885124879", "price": "0.77", "size": "2197.73", "side": "SELL", "hash": "6e08abe2fd0ff7cc02fd9497b5ec323fc82cd9cc", "best_bid": "0.08", "best_ask": "0.1"}], "timestamp": "1769384970648", "event_type": "price_change"}}
{"_local_timestamp": "2026-01-25T23:49:41.824268+00:00", "data": {"market": "0xbc27e1a503d5d962491fb41d0f0efd432c222fbfbb484b775ca0def7ed52288c", "price_changes": [{"asset_id": "84464967243852186849141927382392363797190214011244597826174886881676581745178", "price": "0.29", "size": "50", "side": "BUY", "hash": "b9906d8a87fac4aa1d554bdd1afd02972d3ae1fd", "best_bid": "0.9", "best_ask": "0.92"}, {"asset_id": "22424973164442660525283958049724397021587362098150529484937062183898885124879", "price": "0.71", "size": "50", "side": "SELL", "hash": "c4339427cae83333b05f51fd3c9df0942a11c26c", "best_bid": "0.08", "best_ask": "0.1"}], "timestamp": "1769384981673", "event_type": "price_change"}}
{"_local_timestamp": "2026-01-25T23:49:41.825266+00:00", "data": {"market": "0xbc27e1a503d5d962491fb41d0f0efd432c222fbfbb484b775ca0def7ed52288c", "price_changes": [{"asset_id": "84464967243852186849141927382392363797190214011244597826174886881676581745178", "price": "0.21", "size": "760", "side": "BUY", "hash": "b9906d8a87fac4aa1d554bdd1afd02972d3ae1fd", "best_bid": "0.9", "best_ask": "0.92"}, {"asset_id": "22424973164442660525283958049724397021587362098150529484937062183898885124879", "price": "0.79", "size": "760", "side": "SELL", "hash": "c4339427cae83333b05f51fd3c9df0942a11c26c", "best_bid": "0.08", "best_ask": "0.1"}], "timestamp": "1769384981673", "event_type": "price_change"}}
{"_local_timestamp": "2026-01-25T23:49:42.425105+00:00", "data": {"market": "0xbc27e1a503d5d962491fb41d0f0efd432c222fbfbb484b775ca0def7ed52288c", "price_changes": [{"asset_id": "84464967243852186849141927382392363797190214011244597826174886881676581745178", "price": "0.23", "size": "2247.73", "side": "BUY", "hash": "24dd04449353f143dd0ca1492445ec0160aa4f07", "best_bid": "0.9", "best_ask": "0.92"}, {"asset_id": "22424973164442660525283958049724397021587362098150529484937062183898885124879", "price": "0.77", "size": "2247.73", "side": "SELL", "hash": "19dfdd75f7be5075bb8aa25c30da73bd7bd86bd9", "best_bid": "0.08", "best_ask": "0.1"}], "timestamp": "1769384982239", "event_type": "price_change"}}
{"_local_timestamp": "2026-01-25T23:49:42.440484+00:00", "data": {"market": "0xbc27e1a503d5d962491fb41d0f0efd432c222fbfbb484b775ca0def7ed52288c", "price_changes": [{"asset_id": "84464967243852186849141927382392363797190214011244597826174886881676581745178", "price": "0.28", "size": "142.85", "side": "BUY", "hash": "98d7075082301ea49474065d0131e589b1c3c8f6", "best_bid": "0.9", "best_ask": "0.92"}, {"asset_id": "22424973164442660525283958049724397021587362098150529484937062183898885124879", "price": "0.72", "size": "142.85", "side": "SELL", "hash": "4d20fb9829430d3e0e16acfaf2fe51989ac96348", "best_bid": "0.08", "best_ask": "0.1"}], "timestamp": "1769384982263", "event_type": "price_change"}}
{"_local_timestamp": "2026-01-25T23:49:51.304617+00:00", "data": {"market": "0xbc27e1a503d5d962491fb41d0f0efd432c222fbfbb484b775ca0def7ed52288c", "price_changes": [{"asset_id": "84464967243852186849141927382392363797190214011244597826174886881676581745178", "price": "0.23", "size": "421.73", "side": "BUY", "hash": "33602de34202b61e2f5ee3276b88bb5e4ab23116", "best_bid": "0.9", "best_ask": "0.92"}, {"asset_id": "22424973164442660525283958049724397021587362098150529484937062183898885124879", "price": "0.77", "size": "421.73", "side": "SELL", "hash": "8bc3c7897ac754bf364b00b5102be521a0d42c19", "best_bid": "0.08", "best_ask": "0.1"}], "timestamp": "1769384991054", "event_type": "price_change"}}
{"_local_timestamp": "2026-01-25T23:50:02.520203+00:00", "data": {"market": "0xbc27e1a503d5d962491fb41d0f0efd432c222fbfbb484b775ca0def7ed52288c", "price_changes": [{"asset_id": "84464967243852186849141927382392363797190214011244597826174886881676581745178", "price": "0.21", "size": "0", "side": "BUY", "hash": "f8e927b193a26729d23b9fd2cfe086c084e92bd2", "best_bid": "0.9", "best_ask": "0.92"}, {"asset_id": "22424973164442660525283958049724397021587362098150529484937062183898885124879", "price": "0.79", "size": "0", "side": "SELL", "hash": "7cba974480b1dced72cbea78f8e142c22965e119", "best_bid": "0.08", "best_ask": "0.1"}], "timestamp": "1769385002301", "event_type": "price_change"}}
{"_local_timestamp": "2026-01-25T23:50:02.908079+00:00", "data": {"market": "0xbc27e1a503d5d962491fb41d0f0efd432c222fbfbb484b775ca0def7ed52288c", "price_changes": [{"asset_id": "84464967243852186849141927382392363797190214011244597826174886881676581745178", "price": "0.38", "size": "125", "side": "BUY", "hash": "17f3da504d6bd77c679374423f01040eaccae47e", "best_bid": "0.9", "best_ask": "0.92"}, {"asset_id": "22424973164442660525283958049724397021587362098150529484937062183898885124879", "price": "0.62", "size": "125", "side": "SELL", "hash": "534c85f25867c97de8457f872dc83c624fd85b8f", "best_bid": "0.08", "best_ask": "0.1"}], "timestamp": "1769385002363", "event_type": "price_change"}}
{"_local_timestamp": "2026-01-25T23:50:05.545043+00:00", "data": {"market": "0xbc27e1a503d5d962491fb41d0f0efd432c222fbfbb484b775ca0def7ed52288c", "price_changes": [{"asset_id": "84464967243852186849141927382392363797190214011244597826174886881676581745178", "price": "0.29", "size": "0", "side": "BUY", "hash": "1be505f640f3e60ec990d08fbe3daf50a3ad2df9", "best_bid": "0.9", "best_ask": "0.92"}, {"asset_id": "22424973164442660525283958049724397021587362098150529484937062183898885124879", "price": "0.71", "size": "0", "side": "SELL", "hash": "bd3fbd6f9a6bcad2ce853b1ab87c76e4701467f7", "best_bid": "0.08", "best_ask": "0.1"}], "timestamp": "1769385005465", "event_type": "price_change"}}
{"_local_timestamp": "2026-01-25T23:50:05.803424+00:00", "data": {"market": "0xbc27e1a503d5d962491fb41d0f0efd432c222fbfbb484b775ca0def7ed52288c", "price_changes": [{"asset_id": "84464967243852186849141927382392363797190214011244597826174886881676581745178", "price": "0.28", "size": "192.85", "side": "BUY", "hash": "9ebfe7985359a847c73b4b9e9ae585598450cdc8", "best_bid": "0.9", "best_ask": "0.92"}, {"asset_id": "22424973164442660525283958049724397021587362098150529484937062183898885124879", "price": "0.72", "size": "192.85", "side": "SELL", "hash": "590046c925675126de74f56925be67ee6acbed24", "best_bid": "0.08", "best_ask": "0.1"}], "timestamp": "1769385005716", "event_type": "price_change"}}
{"_local_timestamp": "2026-01-25T23:50:09.097907+00:00", "data": {"market": "0xbc27e1a503d5d962491fb41d0f0efd432c222fbfbb484b775ca0def7ed52288c", "price_changes": [{"asset_id": "22424973164442660525283958049724397021587362098150529484937062183898885124879", "price": "0.06", "size": "4028.98", "side": "BUY", "hash": "8fa0b7661baace6a0d846745481ca3b10c04740c", "best_bid": "0.08", "best_ask": "0.1"}, {"asset_id": "84464967243852186849141927382392363797190214011244597826174886881676581745178", "price": "0.94", "size": "4028.98", "side": "SELL", "hash": "9320740418f8d883c3eab742dcfc1c8456dcb9b3", "best_bid": "0.9", "best_ask": "0.92"}], "timestamp": "1769385009000", "event_type": "price_change"}}
{"_local_timestamp": "2026-01-25T23:50:09.104976+00:00", "data": {"market": "0xbc27e1a503d5d962491fb41d0f0efd432c222fbfbb484b775ca0def7ed52288c", "price_changes": [{"asset_id": "22424973164442660525283958049724397021587362098150529484937062183898885124879", "price": "0.02", "size": "15598.11", "side": "BUY", "hash": "4c397ff2a9e63d25b7e24bca7e9f9afe353be4d6", "best_bid": "0.08", "best_ask": "0.1"}, {"asset_id": "84464967243852186849141927382392363797190214011244597826174886881676581745178", "price": "0.98", "size": "15598.11", "side": "SELL", "hash": "5df9148ddf6c7b4103f916d74f52ed9751d67183", "best_bid": "0.9", "best_ask": "0.92"}], "timestamp": "1769385009003", "event_type": "price_change"}}
{"_local_timestamp": "2026-01-25T23:50:09.114832+00:00", "data": {"market": "0xbc27e1a503d5d962491fb41d0f0efd432c222fbfbb484b775ca0def7ed52288c", "price_changes": [{"asset_id": "22424973164442660525283958049724397021587362098150529484937062183898885124879", "price": "0.05", "size": "3380", "side": "BUY", "hash": "d2489ee3387bcecd3128536a5f96c3d424fe55af", "best_bid": "0.08", "best_ask": "0.1"}, {"asset_id": "84464967243852186849141927382392363797190214011244597826174886881676581745178", "price": "0.95", "size": "3380", "side": "SELL", "hash": "859271d50e539bd97f3aa806c4406abf09f2a09d", "best_bid": "0.9", "best_ask": "0.92"}], "timestamp": "1769385009004", "event_type": "price_change"}}
{"_local_timestamp": "2026-01-25T23:50:09.644910+00:00", "data": {"market": "0xbc27e1a503d5d962491fb41d0f0efd432c222fbfbb484b775ca0def7ed52288c", "price_changes": [{"asset_id": "84464967243852186849141927382392363797190214011244597826174886881676581745178", "price": "0.22", "size": "1908", "side": "BUY", "hash": "a2be4e58ee610dfbebfcc036cf920b1325e5f078", "best_bid": "0.9", "best_ask": "0.92"}, {"asset_id": "22424973164442660525283958049724397021587362098150529484937062183898885124879", "price": "0.78", "size": "1908", "side": "SELL", "hash": "65068d9ad065ce6171571484b77ef72217b2c70c", "best_bid": "0.08", "best_ask": "0.1"}], "timestamp": "1769385009571", "event_type": "price_change"}}
{"_local_timestamp": "2026-01-25T23:50:46.370166+00:00", "data": {"market": "0xbc27e1a503d5d962491fb41d0f0efd432c222fbfbb484b775ca0def7ed52288c", "price_changes": [{"asset_id": "84464967243852186849141927382392363797190214011244597826174886881676581745178", "price": "0.23", "size": "321.73", "side": "BUY", "hash": "840e86bdc28fd0e62ea53459607225a95abed9d4", "best_bid": "0.9", "best_ask": "0.92"}, {"asset_id": "22424973164442660525283958049724397021587362098150529484937062183898885124879", "price": "0.77", "size": "321.73", "side": "SELL", "hash": "f86f472b9dbee99733e73afd8abdbdbf94f59c17", "best_bid": "0.08", "best_ask": "0.1"}], "timestamp": "1769385046267", "event_type": "price_change"}}
{"_local_timestamp": "2026-01-25T23:50:46.774268+00:00", "data": {"market": "0xbc27e1a503d5d962491fb41d0f0efd432c222fbfbb484b775ca0def7ed52288c", "price_changes": [{"asset_id": "84464967243852186849141927382392363797190214011244597826174886881676581745178", "price": "0.22", "size": "2008", "side": "BUY", "hash": "ff4870ed8600794b1f411db3a244d9ba8e207686", "best_bid": "0.9", "best_ask": "0.92"}, {"asset_id": "22424973164442660525283958049724397021587362098150529484937062183898885124879", "price": "0.78", "size": "2008", "side": "SELL", "hash": "f6e59d8b97cb36536c8e5f760eb321625ef37789", "best_bid": "0.08", "best_ask": "0.1"}], "timestamp": "1769385046637", "event_type": "price_change"}}
{"_local_timestamp": "2026-01-25T23:50:51.116315+00:00", "data": {"market": "0xbc27e1a503d5d962491fb41d0f0efd432c222fbfbb484b775ca0def7ed52288c", "price_changes": [{"asset_id": "22424973164442660525283958049724397021587362098150529484937062183898885124879", "price": "0.06", "size": "3995.98", "side": "BUY", "hash": "05333d8f4e8c81c6924f168b1ebd5c8f529cb11e", "best_bid": "0.08", "best_ask": "0.1"}, {"asset_id": "84464967243852186849141927382392363797190214011244597826174886881676581745178", "price": "0.94", "size": "3995.98", "side": "SELL", "hash": "edfa0d8be0355d64a55e06868075ae74151381db", "best_bid": "0.9", "best_ask": "0.92"}], "timestamp": "1769385051000", "event_type": "price_change"}}
{"_local_timestamp": "2026-01-25T23:50:51.117085+00:00", "data": {"market": "0xbc27e1a503d5d962491fb41d0f0efd432c222fbfbb484b775ca0def7ed52288c", "price_changes": [{"asset_id": "22424973164442660525283958049724397021587362098150529484937062183898885124879", "price": "0.05", "size": "3320", "side": "BUY", "hash": "7e17ae34a0262a4d4c7a6feeba4c0034dfcba24d", "best_bid": "0.08", "best_ask": "0.1"}, {"asset_id": "84464967243852186849141927382392363797190214011244597826174886881676581745178", "price": "0.95", "size": "3320", "side": "SELL", "hash": "d486f8236cf5518b699cce22028f5514b3b406f2", "best_bid": "0.9", "best_ask": "0.92"}], "timestamp": "1769385051004", "event_type": "price_change"}}
{"_local_timestamp": "2026-01-25T23:50:51.117577+00:00", "data": {"market": "0xbc27e1a503d5d962491fb41d0f0efd432c222fbfbb484b775ca0def7ed52288c", "price_changes": [{"asset_id": "22424973164442660525283958049724397021587362098150529484937062183898885124879", "price": "0.02", "size": "15348.11", "side": "BUY", "hash": "9ee88a6c2fe4d9b4bb97f9c2e2d188057821a866", "best_bid": "0.08", "best_ask": "0.1"}, {"asset_id": "84464967243852186849141927382392363797190214011244597826174886881676581745178", "price": "0.98", "size": "15348.11", "side": "SELL", "hash": "ff066bca8f7944fc54c5351c7892d0589fce05bf", "best_bid": "0.9", "best_ask": "0.92"}], "timestamp": "1769385051005", "event_type": "price_change"}}
{"_local_timestamp": "2026-01-25T23:51:06.442927+00:00", "data": {"market": "0xbc27e1a503d5d962491fb41d0f0efd432c222fbfbb484b775ca0def7ed52288c", "price_changes": [{"asset_id": "22424973164442660525283958049724397021587362098150529484937062183898885124879", "price": "0.06", "size": "4078.98", "side": "BUY", "hash": "11385ecd1d29d08fc06ef09db3245d4303316ebc", "best_bid": "0.08", "best_ask": "0.1"}, {"asset_id": "84464967243852186849141927382392363797190214011244597826174886881676581745178", "price": "0.94", "size": "4078.98", "side": "SELL", "hash": "915013dde03e39d7648d5b0835a03f5fb504d62e", "best_bid": "0.9", "best_ask": "0.92"}], "timestamp": "1769385066378", "event_type": "price_change"}}
{"_local_timestamp": "2026-01-25T23:51:06.443818+00:00", "data": {"market": "0xbc27e1a503d5d962491fb41d0f0efd432c222fbfbb484b775ca0def7ed52288c", "price_changes": [{"asset_id": "22424973164442660525283958049724397021587362098150529484937062183898885124879", "price": "0.02", "size": "16148.11", "side": "BUY", "hash": "f09a1cea413cce6c74a6b80bbdf890d42fb620fd", "best_bid": "0.08", "best_ask": "0.1"}, {"asset_id": "84464967243852186849141927382392363797190214011244597826174886881676581745178", "price": "0.98", "size": "16148.11", "side": "SELL", "hash": "2c519050f28779ec35ce2df161ee1bf473db07f9", "best_bid": "0.9", "best_ask": "0.92"}], "timestamp": "1769385066379", "event_type": "price_change"}}
{"_local_timestamp": "2026-01-25T23:51:06.451135+00:00", "data": {"market": "0xbc27e1a503d5d962491fb41d0f0efd432c222fbfbb484b775ca0def7ed52288c", "price_changes": [{"asset_id": "22424973164442660525283958049724397021587362098150529484937062183898885124879", "price": "0.05", "size": "6020", "side": "BUY", "hash": "bf38dcbaf6d9f976ec391e36d26a1371ff3ae828", "best_bid": "0.08", "best_ask": "0.1"}, {"asset_id": "84464967243852186849141927382392363797190214011244597826174886881676581745178", "price": "0.95", "size": "6020", "side": "SELL", "hash": "9f150200d6b1cef28fec4a5bed12d02fcba73c3c", "best_bid": "0.9", "best_ask": "0.92"}], "timestamp": "1769385066380", "event_type": "price_change"}}
{"_local_timestamp": "2026-01-25T23:51:12.766008+00:00", "data": {"market": "0xbc27e1a503d5d962491fb41d0f0efd432c222fbfbb484b775ca0def7ed52288c", "price_changes": [{"asset_id": "84464967243852186849141927382392363797190214011244597826174886881676581745178", "price": "0.39", "size": "1538", "side": "BUY", "hash": "32adc26f5d6083f6893410121cf9fd10e6c2cd7c", "best_bid": "0.9", "best_ask": "0.92"}, {"asset_id": "22424973164442660525283958049724397021587362098150529484937062183898885124879", "price": "0.61", "size": "1538", "side": "SELL", "hash": "4a5ff57497048d99e5b9e50ae6c3cc473ad5f20a", "best_bid": "0.08", "best_ask": "0.1"}], "timestamp": "1769385072697", "event_type": "price_change"}}
