{"_local_timestamp": "2026-01-25T23:33:44.650491+00:00", "data": [{"market": "0xdf05643dbc763608d34bc226b096250bf1a84138c8cd0dcaaaf17e997255f38e", "asset_id": "43023538293333812216499804487756700300792959769060172823656702362022968756163", "timestamp": "1769383988450", "hash": "15d633c2b1edf56eff6bed3c6031f906fb66baed", "bids": [{"price": "0.01", "size": "19257"}, {"price": "0.02", "size": "5346"}, {"price": "0.04", "size": "2048"}, {"price": "0.05", "size": "10"}, {"price": "0.08", "size": "512"}, {"price": "0.09", "size": "400"}, {"price": "0.1", "size": "3000"}, {"price": "0.11", "size": "5.44"}, {"price": "0.14", "size": "242.85"}, {"price": "0.16", "size": "256"}, {"price": "0.17", "size": "940"}, {"price": "0.18", "size": "888"}, {"price": "0.19", "size": "168.42"}, {"price": "0.23", "size": "815.73"}, {"price": "0.28", "size": "92.85"}, {"price": "0.32", "size": "128"}, {"price": "0.33", "size": "72.72"}, {"price": "0.34", "size": "1764"}, {"price": "0.35", "size": "5"}, {"price": "0.38", "size": "52.63"}, {"price": "0.48", "size": "96"}, {"price": "0.58", "size": "125.59"}, {"price": "0.64", "size": "61.22"}, {"price": "0.74", "size": "10"}, {"price": "0.86", "size": "20"}, {"price": "0.89", "size": "1580.24"}, {"price": "0.9", "size": "500"}, {"price": "0.92", "size": "221.72"}, {"price": "0.93", "size": "21.51"}], "asks": [{"price": "0.99", "size": "2129"}, {"price": "0.98", "size": "517.15"}, {"price": "0.97", "size": "260.88"}, {"price": "0.96", "size": "7.76"}, {"price": "0.95", "size": "622.46"}, {"price": "0.94", "size": "99.99"}], "event_type": "book", "last_trade_price": "0.100"}, {"market": "0x620d24e05a0839f300f9d970dd0cf742ecc25e9542720146591a7c4426deb1a5", "asset_id": "96474726578408966331514241663172702037609428534006805163072430995039661018902", "timestamp": "1769383966836", "hash": "a18abc0bfe78bf13f9db034b3d4b15d5afab1d30", "bids": [{"price": "0.01", "size": "2882.79"}, {"price": "0.02", "size": "1250"}, {"price": "0.03", "size": "10.2"}, {"price": "0.05", "size": "10"}, {"price": "0.09", "size": "400"}, {"price": "0.1", "size": "86.2"}, {"price": "0.11", "size": "2731.41"}, {"price": "0.14", "size": "242.85"}, {"price": "0.15", "size": "1066"}, {"price": "0.19", "size": "168.42"}, {"price": "0.2", "size": "800"}, {"price": "0.22", "size": "1908"}, {"price": "0.23", "size": "121.73"}, {"price": "0.28", "size": "92.85"}, {"price": "0.33", "size": "72.72"}, {"price": "0.37", "size": "996.85"}, {"price": "0.38", "size": "52.63"}, {"price": "0.4", "size": "300"}, {"price": "0.41", "size": "5"}, {"price": "0.83", "size": "3000"}, {"price": "0.87", "size": "300"}, {"price": "0.88", "size": "196.1"}, {"price": "0.89", "size": "90.9"}], "asks": [{"price": "0.99", "size": "2023"}, {"price": "0.98", "size": "516.13"}, {"price": "0.97", "size": "250"}, {"price": "0.96", "size": "7.29"}, {"price": "0.95", "size": "200"}, {"price": "0.94", "size": "806.2"}, {"price": "0.93", "size": "230.42"}, {"price": "0.92", "size": "16"}], "event_type": "book", "last_trade_price": "0.890"}, {"market": "0x70faa2973143a515446a36a95f9d34efa9bc9bbf39442e21a177658657ebba08", "asset_id": "18608970036028559160373657392306556765154646514657507810165774750998893361620", "timestamp": "1769383953255", "hash": "3e51616aa845ea3c4b712c4453f27e5ebe7c2e42", "bids": [{"price": "0.01", "size": "2123"}, {"price": "0.02", "size": "512.14"}, {"price": "0.03", "size": "250"}, {"price": "0.04", "size": "1208.01"}, {"price": "0.05", "size": "2212.06"}, {"price": "0.06", "size": "532.14"}, {"price": "0.07", "size": "6.23"}, {"price": "0.08", "size": "500"}, {"price": "0.09", "size": "100"}, {"price": "0.1", "size": "88.1"}, {"price": "0.11", "size": "29.99"}], "asks": [{"price": "0.99", "size": "2882.88"}, {"price": "0.98", "size": "1583"}, {"price": "0.97", "size": "10.27"}, {"price": "0.91", "size": "400"}, {"price": "0.9", "size": "67.56"}, {"price": "0.89", "size": "2731.38"}, {"price": "0.86", "size": "242.85"}, {"price": "0.85", "size": "1066"}, {"price": "0.81", "size": "168.42"}, {"price": "0.8", "size": "800"}, {"price": "0.79", "size": "1998"}, {"price": "0.77", "size": "121.73"}, {"price": "0.73", "size": "72.53"}, {"price": "0.72", "size": "97.85"}, {"price": "0.69", "size": "285.67"}, {"price": "0.67", "size": "72.72"}, {"price": "0.62", "size": "53.69"}, {"price": "0.61", "size": "5"}, {"price": "0.24", "size": "116.87"}, {"price": "0.2", "size": "187.24"}, {"price": "0.16", "size": "300"}, {"price": "0.15", "size": "127.49"}, {"price": "0.14", "size": "100"}], "event_type": "book", "last_trade_price": "0.870"}, {"market": "0xdf05643dbc763608d34bc226b096250bf1a84138c8cd0dcaaaf17e997255f38e", "asset_id": "54033749301194428028417107915177981267461869759594673805572129279965077627691", "timestamp": "1769383988450", "hash": "4f7ffc854bd75514c7dcc323d6f23f74b064c4f0", "bids": [{"price": "0.01", "size": "2129"}, {"price": "0.02", "size": "517.15"}, {"price": "0.03", "size": "260.88"}, {"price": "0.04", "size": "7.76"}, {"price": "0.05", "size": "622.46"}, {"price": "0.06", "size": "99.99"}], "asks": [{"price": "0.99", "size": "19257"}, {"price": "0.98", "size": "5346"}, {"price": "0.96", "size": "2048"}, {"price": "0.95", "size": "10"}, {"price": "0.92", "size": "512"}, {"price": "0.91", "size": "400"}, {"price": "0.9", "size": "3000"}, {"price": "0.89", "size": "5.44"}, {"price": "0.86", "size": "242.85"}, {"price": "0.84", "size": "256"}, {"price": "0.83", "size": "940"}, {"price": "0.82", "size": "888"}, {"price": "0.81", "size": "168.42"}, {"price": "0.77", "size": "815.73"}, {"price": "0.72", "size": "92.85"}, {"price": "0.68", "size": "128"}, {"price": "0.67", "size": "72.72"}, {"price": "0.66", "size": "1764"}, {"price": "0.65", "size": "5"}, {"price": "0.62", "size": "52.63"}, {"price": "0.52", "size": "96"}, {"price": "0.42", "size": "125.59"}, {"price": "0.36", "size": "61.22"}, {"price": "0.26", "size": "10"}, {"price": "0.14", "size": "20"}, {"price": "0.11", "size": "1580.24"}, {"price": "0.1", "size": "500"}, {"price": "0.08", "size": "221.72"}, {"price": "0.07", "size": "21.51"}], "event_type": "book", "last_trade_price": "0.100"}, {"market": "0x70faa2973143a515446a36a95f9d34efa9bc9bbf39442e21a177658657ebba08", "asset_id": "65609516077620000999206912136749570806454562507007008956560753919902115040651", "timestamp": "1769383953255", "hash": "f42853ecd1881b38ade6fae36fef8466d5c6478f", "bids": [{"price": "0.01", "size": "2882.88"}, {"price": "0.02", "size": "1583"}, {"price": "0.03", "size": "10.27"}, {"price": "0.09", "size": "400"}, {"price": "0.1", "size": "67.56"}, {"price": "0.11", "size": "2731.38"}, {"price": "0.14", "size": "242.85"}, {"price": "0.15", "size": "1066"}, {"price": "0.19", "size": "168.42"}, {"price": "0.2", "size": "800"}, {"price": "0.21", "size": "1998"}, {"price": "0.23", "size": "121.73"}, {"price": "0.27", "size": "72.53"}, {"price": "0.28", "size": "97.85"}, {"price": "0.31", "size": "285.67"}, {"price": "0.33", "size": "72.72"}, {"price": "0.38", "size": "53.69"}, {"price": "0.39", "size": "5"}, {"price": "0.76", "size": "116.87"}, {"price": "0.8", "size": "187.24"}, {"price": "0.84", "size": "300"}, {"price": "0.85", "size": "127.49"}, {"price": "0.86", "size": "100"}], "asks": [{"price": "0.99", "size": "2123"}, {"price": "0.98", "size": "512.14"}, {"price": "0.97", "size": "250"}, {"price": "0.96", "size": "1208.01"}, {"price": "0.95", "size": "2212.06"}, {"price": "0.94", "size": "532.14"}, {"price": "0.93", "size": "6.23"}, {"price": "0.92", "size": "500"}, {"price": "0.91", "size": "100"}, {"price": "0.9", "size": "88.1"}, {"price": "0.89", "size": "29.99"}], "event_type": "book", "last_trade_price": "0.870"}, {"market": "0x620d24e05a0839f300f9d970dd0cf742ecc25e9542720146591a7c4426deb1a5", "asset_id": "63562937989606194538516926327707872978632537481944654374894817966365498120132", "timestamp": "1769383966836", "hash": "48c446d98379a8cf664c64348ec6b7d67c27b583", "bids": [{"price": "0.01", "size": "2023"}, {"price": "0.02", "size": "516.13"}, {"price": "0.03", "size": "250"}, {"price": "0.04", "size": "7.29"}, {"price": "0.05", "size": "200"}, {"price": "0.06", "size": "806.2"}, {"price": "0.07", "size": "230.42"}, {"price": "0.08", "size": "16"}], "asks": [{"price": "0.99", "size": "2882.79"}, {"price": "0.98", "size": "1250"}, {"price": "0.97", "size": "10.2"}, {"price": "0.95", "size": "10"}, {"price": "0.91", "size": "400"}, {"price": "0.9", "size": "86.2"}, {"price": "0.89", "size": "2731.41"}, {"price": "0.86", "size": "242.85"}, {"price": "0.85", "size": "1066"}, {"price": "0.81", "size": "168.42"}, {"price": "0.8", "size": "800"}, {"price": "0.78", "size": "1908"}, {"price": "0.77", "size": "121.73"}, {"price": "0.72", "size": "92.85"}, {"price": "0.67", "size": "72.72"}, {"price": "0.63", "size": "996.85"}, {"price": "0.62", "size": "52.63"}, {"price": "0.6", "size": "300"}, {"price": "0.59", "size": "5"}, {"price": "0.17", "size": "3000"}, {"price": "0.13", "size": "300"}, {"price": "0.12", "size": "196.1"}, {"price": "0.11", "size": "90.9"}], "event_type": "book", "last_trade_price": "0.890"}]}
{"_local_timestamp": "2026-01-25T23:33:44.998470+00:00", "data": {"market": "0xdf05643dbc763608d34bc226b096250bf1a84138c8cd0dcaaaf17e997255f38e", "price_changes": [{"asset_id": "43023538293333812216499804487756700300792959769060172823656702362022968756163", "price": "0.24", "size": "1748", "side": "BUY", "hash": "d0a276fade375d554a4eea7104d06a7885360327", "best_bid": "0.93", "best_ask": "0.94"}, {"asset_id": "54033749301194428028417107915177981267461869759594673805572129279965077627691", "price": "0.76", "size": "1748", "side": "SELL", "hash": "74df7382d3045b5d875876262e171f25a5f8a500", "best_bid": "0.06", "best_ask": "0.07"}], "timestamp": "1769384024934", "event_type": "price_change"}}
{"_local_timestamp": "2026-01-25T23:34:03.264415+00:00", "data": {"market": "0xdf05643dbc763608d34bc226b096250bf1a84138c8cd0dcaaaf17e997255f38e", "price_changes": [{"asset_id": "54033749301194428028417107915177981267461869759594673805572129279965077627691", "price": "0.02", "size": "500", "side": "BUY", "hash": "79a8731fc1e96a800ec6c13b026a48e0e077a0ab", "best_bid": "0.06", "best_ask": "0.07"}, {"asset_id": "43023538293333812216499804487756700300792959769060172823656702362022968756163", "price": "0.98", "size": "500", "side": "SELL", "hash": "4a5dc9f549028923c7fdaa9360abfcee2e23e059", "best_bid": "0.93", "best_ask": "0.94"}], "timestamp": "1769384043180", "event_type": "price_change"}}
{"_local_timestamp": "2026-01-25T23:34:03.266033+00:00", "data": {"market": "0xdf05643dbc763608d34bc226b096250bf1a84138c8cd0dcaaaf17e997255f38e", "price_changes": [{"asset_id": "54033749301194428028417107915177981267461869759594673805572129279965077627691", "price": "0.03", "size": "250", "side": "BUY", "hash": "79a8731fc1e96a800ec6c13b026a48e0e077a0ab", "best_bid": "0.06", "best_ask": "0.07"}, {"asset_id": "43023538293333812216499804487756700300792959769060172823656702362022968756163", "price": "0.97", "size": "250", "side": "SELL", "hash": "4a5dc9f549028923c7fdaa9360abfcee2e23e059", "best_bid": "0.93", "best_ask": "0.94"}], "timestamp": "1769384043180", "event_type": "price_change"}}
{"_local_timestamp": "2026-01-25T23:34:03.267017+00:00", "data": {"market": "0xdf05643dbc763608d34bc226b096250bf1a84138c8cd0dcaaaf17e997255f38e", "price_changes": [{"asset_id": "54033749301194428028417107915177981267461869759594673805572129279965077627691", "price": "0.04", "size": "0", "side": "BUY", "hash": "79a8731fc1e96a800ec6c13b026a48e0e077a0ab", "best_bid": "0.06", "best_ask": "0.07"}, {"asset_id": "43023538293333812216499804487756700300792959769060172823656702362022968756163", "price": "0.96", "size": "0", "side": "SELL", "hash": "4a5dc9f549028923c7fdaa9360abfcee2e23e059", "best_bid": "0.93", "best_ask": "0.94"}], "timestamp": "1769384043180", "event_type": "price_change"}}
{"_local_timestamp": "2026-01-25T23:34:03.816108+00:00", "data": {"market": "0xdf05643dbc763608d34bc226b096250bf1a84138c8cd0dcaaaf17e997255f38e", "price_changes": [{"asset_id": "54033749301194428028417107915177981267461869759594673805572129279965077627691", "price": "0.02", "size": "517.15", "side": "BUY", "hash": "d9931e18a85833fa8631a6e2d4330778b772e1e6", "best_bid": "0.06", "best_ask": "0.07"}, {"asset_id": "43023538293333812216499804487756700300792959769060172823656702362022968756163", "price": "0.98", "size": "517.15", "side": "SELL", "hash": "548deecaf078fbde5ddde789aee3995cbbbcdbe1", "best_bid": "0.93", "best_ask": "0.94"}], "timestamp": "1769384043746", "event_type": "price_change"}}
{"_local_timestamp": "2026-01-25T23:34:03.817232+00:00", "data": {"market": "0xdf05643dbc763608d34bc226b096250bf1a84138c8cd0dcaaaf17e997255f38e", "price_changes": [{"asset_id": "54033749301194428028417107915177981267461869759594673805572129279965077627691", "price": "0.03", "size": "260.88", "side": "BUY", "hash": "a73a954c2d11a2eea14b75d6973b6f1895985a71", "best_bid": "0.06", "best_ask": "0.07"}, {"asset_id": "43023538293333812216499804487756700300792959769060172823656702362022968756163", "price": "0.97", "size": "260.88", "side": "SELL", "hash": "b34075af4ea4e08c7a9b637895ffabc4e0426611", "best_bid": "0.93", "best_ask": "0.94"}], "timestamp": "1769384043747", "event_type": "price_change"}}
{"_local_timestamp": "2026-01-25T23:34:03.817745+00:00", "data": {"market": "0xdf05643dbc763608d34bc226b096250bf1a84138c8cd0dcaaaf17e997255f38e", "price_changes": [{"asset_id": "54033749301194428028417107915177981267461869759594673805572129279965077627691", "price": "0.04", "size": "7.76", "side": "BUY", "hash": "12d6b8409c137c5f00c753728148686b09cd066d", "best_bid": "0.06", "best_ask": "0.07"}, {"asset_id": "43023538293333812216499804487756700300792959769060172823656702362022968756163", "price": "0.96", "size": "7.76", "side": "SELL", "hash": "096c7e50423e03ab754024f67d0d54634eec7c92", "best_bid": "0.93", "best_ask": "0.94"}], "timestamp": "1769384043748", "event_type": "price_change"}}
{"_local_timestamp": "2026-01-25T23:34:19.868969+00:00", "data": {"market": "0x70faa2973143a515446a36a95f9d34efa9bc9bbf39442e21a177658657ebba08", "price_changes": [{"asset_id": "65609516077620000999206912136749570806454562507007008956560753919902115040651", "price": "0.21", "size": "0", "side": "BUY", "hash": "be22218e071d9a8b87fd7ddf9a2996526ab507bf", "best_bid": "0.86", "best_ask": "0.89"}, {"asset_id": "18608970036028559160373657392306556765154646514657507810165774750998893361620", "price": "0.79", "size": "0", "side": "SELL", "hash": "295a971d724ce3be3d1d4554893ca538e6390a46", "best_bid": "0.11", "best_ask": "0.14"}], "timestamp": "1769384059754", "event_type": "price_change"}}
{"_local_timestamp": "2026-01-25T23:34:19.900797+00:00", "data": {"market": "0xdf05643dbc763608d34bc226b096250bf1a84138c8cd0dcaaaf17e997255f38e", "price_changes": [{"asset_id": "43023538293333812216499804487756700300792959769060172823656702362022968756163", "price": "0.24", "size": "0", "side": "BUY", "hash": "38da0241c27a698750cf40fe5ffe0b89407c1b4c", "best_bid": "0.93", "best_ask": "0.94"}, {"asset_id": "54033749301194428028417107915177981267461869759594673805572129279965077627691", "price": "0.76", "size": "0", "side": "SELL", "hash": "fca9f4c96d57f1173b3a086087238c43f7c17586", "best_bid": "0.06", "best_ask": "0.07"}], "timestamp": "1769384059754", "event_type": "price_change"}}
{"_local_timestamp": "2026-01-25T23:34:22.093475+00:00", "data": {"market": "0xdf05643dbc763608d34bc226b096250bf1a84138c8cd0dcaaaf17e997255f38e", "price_changes": [{"asset_id": "43023538293333812216499804487756700300792959769060172823656702362022968756163", "price": "0.26", "size": "1614", "side": "BUY", "hash": "40195368521b5b60d90698cb1dcec4579c09bfa4", "best_bid": "0.93", "best_ask": "0.94"}, {"asset_id": "54033749301194428028417107915177981267461869759594673805572129279965077627691", "price": "0.74", "size": "1614", "side": "SELL", "hash": "7f82ec364834548edb283d974e25ed65a233766e", "best_bid": "0.06", "best_ask": "0.07"}], "timestamp": "1769384062011", "event_type": "price_change"}}
{"_local_timestamp": "2026-01-25T23:34:22.093910+00:00", "data": {"market": "0x70faa2973143a515446a36a95f9d34efa9bc9bbf39442e21a177658657ebba08", "price_changes": [{"asset_id": "65609516077620000999206912136749570806454562507007008956560753919902115040651", "price": "0.23", "size": "1947.73", "side": "BUY", "hash": "23284afac1f5f51ecac5a739a1fcc39112e7c9f7", "best_bid": "0.86", "best_ask": "0.89"}, {"asset_id": "18608970036028559160373657392306556765154646514657507810165774750998893361620", "price": "0.77", "size": "1947.73", "side": "SELL", "hash": "f1437b56b2206e6e3be9f0ec995294098f63964a", "best_bid": "0.11", "best_ask": "0.14"}], "timestamp": "1769384062026", "event_type": "price_change"}}
{"_local_timestamp": "2026-01-25T23:34:34.341517+00:00", "data": {"market": "0xdf05643dbc763608d34bc226b096250bf1a84138c8cd0dcaaaf17e997255f38e", "price_changes": [{"asset_id": "43023538293333812216499804487756700300792959769060172823656702362022968756163", "price": "0.01", "size": "19266.71", "side": "BUY", "hash": "d7dfae545aeca3be6220c8e6044258cc8d97c5b9", "best_bid": "0.93", "best_ask": "0.94"}, {"asset_id": "54033749301194428028417107915177981267461869759594673805572129279965077627691", "price": "0.99", "size": "19266.71", "side": "SELL", "hash": "8819e0a18df710337a79bbc834facc2b8480ba79", "best_bid": "0.06", "best_ask": "0.07"}], "timestamp": "1769384074265", "event_type": "price_change"}}
{"_local_timestamp": "2026-01-25T23:34:34.342341+00:00", "data": {"market": "0xdf05643dbc763608d34bc226b096250bf1a84138c8cd0dcaaaf17e997255f38e", "price_changes": [{"asset_id": "43023538293333812216499804487756700300792959769060172823656702362022968756163", "price": "0.03", "size": "10.14", "side": "BUY", "hash": "a70f5e9ec2120c805d2acb08e0a4c865ad70207f", "best_bid": "0.93", "best_ask": "0.94"}, {"asset_id": "54033749301194428028417107915177981267461869759594673805572129279965077627691", "price": "0.97", "size": "10.14", "side": "SELL", "hash": "5f3d1a29f45cd6511d66b791d15ceacdedbd96b5", "best_bid": "0.06", "best_ask": "0.07"}], "timestamp": "1769384074266", "event_type": "price_change"}}
{"_local_timestamp": "2026-01-25T23:35:58.136208+00:00", "data": {"market": "0x70faa2973143a515446a36a95f9d34efa9bc9bbf39442e21a177658657ebba08", "price_changes": [{"asset_id": "65609516077620000999206912136749570806454562507007008956560753919902115040651", "price": "0.23", "size": "121.73", "side": "BUY", "hash": "fed502405c43cd0916fa043e4fff0fbebcfa561c", "best_bid": "0.86", "best_ask": "0.89"}, {"asset_id": "18608970036028559160373657392306556765154646514657507810165774750998893361620", "price": "0.77", "size": "121.73", "side": "SELL", "hash": "4c30c9bfa59513d51715aca67947f05369d964ff", "best_bid": "0.11", "best_ask": "0.14"}], "timestamp": "1769384158066", "event_type": "price_change"}}
{"_local_timestamp": "2026-01-25T23:35:58.154908+00:00", "data": {"market": "0x620d24e05a0839f300f9d970dd0cf742ecc25e9542720146591a7c4426deb1a5", "price_changes": [{"asset_id": "96474726578408966331514241663172702037609428534006805163072430995039661018902", "price": "0.22", "size": "0", "side": "BUY", "hash": "dee039831d39189decd376e997c02ec5f087f554", "best_bid": "0.89", "best_ask": "0.92"}, {"asset_id": "63562937989606194538516926327707872978632537481944654374894817966365498120132", "price": "0.78", "size": "0", "side": "SELL", "hash": "9c6377bf0039c4f3cb9c1e800a640a60831b0eca", "best_bid": "0.08", "best_ask": "0.11"}], "timestamp": "1769384158068", "event_type": "price_change"}}
{"_local_timestamp": "2026-01-25T23:35:58.168635+00:00", "data": {"market": "0xdf05643dbc763608d34bc226b096250bf1a84138c8cd0dcaaaf17e997255f38e", "price_changes": [{"asset_id": "43023538293333812216499804487756700300792959769060172823656702362022968756163", "price": "0.26", "size": "0", "side": "BUY", "hash": "9a7fa93cab9621ae497c59bd10d790d7fab47c50", "best_bid": "0.93", "best_ask": "0.94"}, {"asset_id": "54033749301194428028417107915177981267461869759594673805572129279965077627691", "price": "0.74", "size": "0", "side": "SELL", "hash": "e5bc553a97220ca585699f24e2af2ed2fd355a64", "best_bid": "0.06", "best_ask": "0.07"}], "timestamp": "1769384158071", "event_type": "price_change"}}
{"_local_timestamp": "2026-01-25T23:36:03.460868+00:00", "data": {"market": "0x620d24e05a0839f300f9d970dd0cf742ecc25e9542720146591a7c4426deb1a5", "price_changes": [{"asset_id": "96474726578408966331514241663172702037609428534006805163072430995039661018902", "price": "0.21", "size": "1998", "side": "BUY", "hash": "9fc11902443ba952d705a32b29bc0abed058d35d", "best_bid": "0.89", "best_ask": "0.92"}, {"asset_id": "63562937989606194538516926327707872978632537481944654374894817966365498120132", "price": "0.79", "size": "1998", "side": "SELL", "hash": "06d3bd47f298aa483a9fccf1fbabbee8c03557b7", "best_bid": "0.08", "best_ask": "0.11"}], "timestamp": "1769384163396", "event_type": "price_change"}}
{"_local_timestamp": "2026-01-25T23:36:03.674950+00:00", "data": {"market": "0x70faa2973143a515446a36a95f9d34efa9bc9bbf39442e21a177658657ebba08", "price_changes": [{"asset_id": "65609516077620000999206912136749570806454562507007008956560753919902115040651", "price": "0.21", "size": "1998", "side": "BUY", "hash": "9567a2e2659b7a60ec94f70f652869e09fb402b9", "best_bid": "0.86", "best_ask": "0.89"}, {"asset_id": "18608970036028559160373657392306556765154646514657507810165774750998893361620", "price": "0.79", "size": "1998", "side": "SELL", "hash": "16f5c4e3f0d03ffd71a987d1aed7757be1a43e2f", "best_bid": "0.11", "best_ask": "0.14"}], "timestamp": "1769384163599", "event_type": "price_change"}}
{"_local_timestamp": "2026-01-25T23:36:09.426947+00:00", "data": {"market": "0xdf05643dbc763608d34bc226b096250bf1a84138c8cd0dcaaaf17e997255f38e", "price_changes": [{"asset_id": "54033749301194428028417107915177981267461869759594673805572129279965077627691", "price": "0.02", "size": "500", "side": "BUY", "hash": "bdf26a9bb6d8830a4163a8090b86d012fad78888", "best_bid": "0.06", "best_ask": "0.07"}, {"asset_id": "43023538293333812216499804487756700300792959769060172823656702362022968756163", "price": "0.98", "size": "500", "side": "SELL", "hash": "2a6f0c51eadc485779b78298e57492493b1c51a2", "best_bid": "0.93", "best_ask": "0.94"}], "timestamp": "1769384169355", "event_type": "price_change"}}
{"_local_timestamp": "2026-01-25T23:36:09.435001+00:00", "data": {"market": "0xdf05643dbc763608d34bc226b096250bf1a84138c8cd0dcaaaf17e997255f38e", "price_changes": [{"asset_id": "54033749301194428028417107915177981267461869759594673805572129279965077627691", "price": "0.03", "size": "250", "side": "BUY", "hash": "bdf26a9bb6d8830a4163a8090b86d012fad78888", "best_bid": "0.06", "best_ask": "0.07"}, {"asset_id": "43023538293333812216499804487756700300792959769060172823656702362022968756163", "price": "0.97", "size": "250", "side": "SELL", "hash": "2a6f0c51eadc485779b78298e57492493b1c51a2", "best_bid": "0.93", "best_ask": "0.94"}], "timestamp": "1769384169355", "event_type": "price_change"}}
{"_local_timestamp": "2026-01-25T23:36:09.435586+00:00", "data": {"market": "0xdf05643dbc763608d34bc226b096250bf1a84138c8cd0dcaaaf17e997255f38e", "price_changes": [{"asset_id": "54033749301194428028417107915177981267461869759594673805572129279965077627691", "price": "0.04", "size": "0", "side": "BUY", "hash": "bdf26a9bb6d8830a4163a8090b86d012fad78888", "best_bid": "0.06", "best_ask": "0.07"}, {"asset_id": "43023538293333812216499804487756700300792959769060172823656702362022968756163", "price": "0.96", "size": "0", "side": "SELL", "hash": "2a6f0c51eadc485779b78298e57492493b1c51a2", "best_bid": "0.93", "best_ask": "0.94"}], "timestamp": "1769384169355", "event_type": "price_change"}}
{"_local_timestamp": "2026-01-25T23:36:09.791338+00:00", "data": {"market": "0xdf05643dbc763608d34bc226b096250bf1a84138c8cd0dcaaaf17e997255f38e", "price_changes": [{"asset_id": "54033749301194428028417107915177981267461869759594673805572129279965077627691", "price": "0.02", "size": "517.15", "side": "BUY", "hash": "11ec81a748ef1bb11fe36f7b66785b04dfefaf90", "best_bid": "0.06", "best_ask": "0.07"}, {"asset_id": "43023538293333812216499804487756700300792959769060172823656702362022968756163", "price": "0.98", "size": "517.15", "side": "SELL", "hash": "80658e8f3e8732b6d426848e8ab80aa80cbc65f4", "best_bid": "0.93", "best_ask": "0.94"}], "timestamp": "1769384169720", "event_type": "price_change"}}
{"_local_timestamp": "2026-01-25T23:36:09.791835+00:00", "data": {"market": "0xdf05643dbc763608d34bc226b096250bf1a84138c8cd0dcaaaf17e997255f38e", "price_changes": [{"asset_id": "54033749301194428028417107915177981267461869759594673805572129279965077627691", "price": "0.03", "size": "260.88", "side": "BUY", "hash": "56215fbeb015121e173c821e01f5a0ba6278d15e", "best_bid": "0.06", "best_ask": "0.07"}, {"asset_id": "43023538293333812216499804487756700300792959769060172823656702362022968756163", "price": "0.97", "size": "260.88", "side": "SELL", "hash": "487fc47847227bd0bda30ce3ce205bbf864d2f2e", "best_bid": "0.93", "best_ask": "0.94"}], "timestamp": "1769384169721", "event_type": "price_change"}}
{"_local_timestamp": "2026-01-25T23:36:09.792284+00:00", "data": {"market": "0xdf05643dbc763608d34bc226b096250bf1a84138c8cd0dcaaaf17e997255f38e", "price_changes": [{"asset_id": "54033749301194428028417107915177981267461869759594673805572129279965077627691", "price": "0.04", "size": "7.76", "side": "BUY", "hash": "371fa99ab99a5ce65d79048f27eb65e9a3bc5f34", "best_bid": "0.06", "best_ask": "0.07"}, {"asset_id": "43023538293333812216499804487756700300792959769060172823656702362022968756163", "price": "0.96", "size": "7.76", "side": "SELL", "hash": "c9f2b44f6381b273fdd1dca8db178829e875a841", "best_bid": "0.93", "best_ask": "0.94"}], "timestamp": "1769384169722", "event_type": "price_change"}}
{"_local_timestamp": "2026-01-25T23:36:12.658086+00:00", "data": {"market": "0xdf05643dbc763608d34bc226b096250bf1a84138c8cd0dcaaaf17e997255f38e", "price_changes": [{"asset_id": "43023538293333812216499804487756700300792959769060172823656702362022968756163", "price": "0.24", "size": "1748", "side": "BUY", "hash": "4a836f3dc9686a5654d285f1268e5c828b9ce5e4", "best_bid": "0.93", "best_ask": "0.94"}, {"asset_id": "54033749301194428028417107915177981267461869759594673805572129279965077627691", "price": "0.76", "size": "1748", "side": "SELL", "hash": "a52f6f8a46ebee49158b69d91c777a51545cdb12", "best_bid": "0.06", "best_ask": "0.07"}], "timestamp": "1769384172592", "event_type": "price_change"}}
{"_local_timestamp": "2026-01-25T23:37:35.221525+00:00", "data": {"market": "0xdf05643dbc763608d34bc226b096250bf1a84138c8cd0dcaaaf17e997255f38e", "price_changes": [{"asset_id": "43023538293333812216499804487756700300792959769060172823656702362022968756163", "price": "0.24", "size": "0", "side": "BUY", "hash": "ed3342f4a6371e627a20c636ec2724594334d01f", "best_bid": "0.93", "best_ask": "0.94"}, {"asset_id": "54033749301194428028417107915177981267461869759594673805572129279965077627691", "price": "0.76", "size": "0", "side": "SELL", "hash": "38eeaaa58b0e85a8533e533d6daa50d2817b2f31", "best_bid": "0.06", "best_ask": "0.07"}], "timestamp": "1769384255116", "event_type": "price_change"}}
{"_local_timestamp": "2026-01-25T23:37:35.328439+00:00", "data": {"market": "0x620d24e05a0839f300f9d970dd0cf742ecc25e9542720146591a7c4426deb1a5", "price_changes": [{"asset_id": "96474726578408966331514241663172702037609428534006805163072430995039661018902", "price": "0.21", "size": "0", "side": "BUY", "hash": "2b807306026888ce4c4803736a835802f83fabc6", "best_bid": "0.89", "best_ask": "0.92"}, {"asset_id": "63562937989606194538516926327707872978632537481944654374894817966365498120132", "price": "0.79", "size": "0", "side": "SELL", "hash": "223066f9e230c6f6ea8148e4107f4abf7081cfa2", "best_bid": "0.08", "best_ask": "0.11"}], "timestamp": "1769384255124", "event_type": "price_change"}}
{"_local_timestamp": "2026-01-25T23:37:35.328949+00:00", "data": {"market": "0x70faa2973143a515446a36a95f9d34efa9bc9bbf39442e21a177658657ebba08", "price_changes": [{"asset_id": "65609516077620000999206912136749570806454562507007008956560753919902115040651", "price": "0.21", "size": "0", "side": "BUY", "hash": "5f3343adfef646623028e7bf9653f5027b248a75", "best_bid": "0.86", "best_ask": "0.89"}, {"asset_id": "18608970036028559160373657392306556765154646514657507810165774750998893361620", "price": "0.79", "size": "0", "side": "SELL", "hash": "cd16a74bc79d58c4b412e43816715293f1273995", "best_bid": "0.11", "best_ask": "0.14"}], "timestamp": "1769384255124", "event_type": "price_change"}}
{"_local_timestamp": "2026-01-25T23:37:45.127843+00:00", "data": {"market": "0xdf05643dbc763608d34bc226b096250bf1a84138c8cd0dcaaaf17e997255f38e", "price_changes": [{"asset_id": "54033749301194428028417107915177981267461869759594673805572129279965077627691", "price": "0.02", "size": "500", "side": "BUY", "hash": "27d2977271a9bf9eec3ccaa716551ff58917dc7d", "best_bid": "0.06", "best_ask": "0.07"}, {"asset_id": "43023538293333812216499804487756700300792959769060172823656702362022968756163", "price": "0.98", "size": "500", "side": "SELL", "hash": "9f6ba9d8f2fb340346c5218bc61f71937df75310", "best_bid": "0.93", "best_ask": "0.94"}], "timestamp": "1769384265042", "event_type": "price_change"}}
{"_local_timestamp": "2026-01-25T23:37:45.128356+00:00", "data": {"market": "0xdf05643dbc763608d34bc226b096250bf1a84138c8cd0dcaaaf17e997255f38e", "price_changes": [{"asset_id": "54033749301194428028417107915177981267461869759594673805572129279965077627691", "price": "0.03", "size": "250", "side": "BUY", "hash": "27d2977271a9bf9eec3ccaa716551ff58917dc7d", "best_bid": "0.06", "best_ask": "0.07"}, {"asset_id": "43023538293333812216499804487756700300792959769060172823656702362022968756163", "price": "0.97", "size": "250", "side": "SELL", "hash": "9f6ba9d8f2fb340346c5218bc61f71937df75310", "best_bid": "0.93", "best_ask": "0.94"}], "timestamp": "1769384265042", "event_type": "price_change"}}
{"_local_timestamp": "2026-01-25T23:37:45.128819+00:00", "data": {"market": "0xdf05643dbc763608d34bc226b096250bf1a84138c8cd0dcaaaf17e997255f38e", "price_changes": [{"asset_id": "54033749301194428028417107915177981267461869759594673805572129279965077627691", "price": "0.04", "size": "0", "side": "BUY", "hash": "27d2977271a9bf9eec3ccaa716551ff58917dc7d", "best_bid": "0.06", "best_ask": "0.07"}, {"asset_id": "43023538293333812216499804487756700300792959769060172823656702362022968756163", "price": "0.96", "size": "0", "side": "SELL", "hash": "9f6ba9d8f2fb340346c5218bc61f71937df75310", "best_bid": "0.93", "best_ask": "0.94"}], "timestamp": "1769384265042", "event_type": "price_change"}}
{"_local_timestamp": "2026-01-25T23:37:45.493016+00:00", "data": {"market": "0xdf05643dbc763608d34bc226b096250bf1a84138c8cd0dcaaaf17e997255f38e", "price_changes": [{"asset_id": "54033749301194428028417107915177981267461869759594673805572129279965077627691", "price": "0.03", "size": "260.88", "side": "BUY", "hash": "e53bd80a5788c20ae5532a388d04220a8cdea578", "best_bid": "0.06", "best_ask": "0.07"}, {"asset_id": "43023538293333812216499804487756700300792959769060172823656702362022968756163", "price": "0.97", "size": "260.88", "side": "SELL", "hash": "2da85c66c85bf1c6e7c9e7f4c14928a4c69361c7", "best_bid": "0.93", "best_ask": "0.94"}], "timestamp": "1769384265424", "event_type": "price_change"}}
{"_local_timestamp": "2026-01-25T23:37:45.499377+00:00", "data": {"market": "0xdf05643dbc763608d34bc226b096250bf1a84138c8cd0dcaaaf17e997255f38e", "price_changes": [{"asset_id": "54033749301194428028417107915177981267461869759594673805572129279965077627691", "price": "0.04", "size": "7.76", "side": "BUY", "hash": "861fcc5c70108b35057cc0cb35340b1a2332b52e", "best_bid": "0.06", "best_ask": "0.07"}, {"asset_id": "43023538293333812216499804487756700300792959769060172823656702362022968756163", "price": "0.96", "size": "7.76", "side": "SELL", "hash": "4ae773b5fc0dcc2ab0817c5ec94ccae1dcb1fd87", "best_bid": "0.93", "best_ask": "0.94"}], "timestamp": "1769384265425", "event_type": "price_change"}}
{"_local_timestamp": "2026-01-25T23:37:45.499804+00:00", "data": {"market": "0xdf05643dbc763608d34bc226b096250bf1a84138c8cd0dcaaaf17e997255f38e", "price_changes": [{"asset_id": "54033749301194428028417107915177981267461869759594673805572129279965077627691", "price": "0.02", "size": "517.15", "side": "BUY", "hash": "9abca7e28468aeafd1016f1af5d752c77fc00890", "best_bid": "0.06", "best_ask": "0.07"}, {"asset_id": "43023538293333812216499804487756700300792959769060172823656702362022968756163", "price": "0.98", "size": "517.15", "side": "SELL", "hash": "e1d9e4500e766b96c1ea9b6dba07578fcb239f27", "best_bid": "0.93", "best_ask": "0.94"}], "timestamp": "1769384265426", "event_type": "price_change"}}
{"_local_timestamp": "2026-01-25T23:38:17.015295+00:00", "data": {"market": "0x70faa2973143a515446a36a95f9d34efa9bc9bbf39442e21a177658657ebba08", "price_changes": [{"asset_id": "65609516077620000999206912136749570806454562507007008956560753919902115040651", "price": "0.22", "size": "1908", "side": "BUY", "hash": "2e9196378a1162cfcb48603ba1248badaa290ae1", "best_bid": "0.86", "best_ask": "0.89"}, {"asset_id": "18608970036028559160373657392306556765154646514657507810165774750998893361620", "price": "0.78", "size": "1908", "side": "SELL", "hash": "2367d2af4a27da9597e8802c7dd7324711a21c82", "best_bid": "0.11", "best_ask": "0.14"}], "timestamp": "1769384296946", "event_type": "price_change"}}
{"_local_timestamp": "2026-01-25T23:38:45.315051+00:00", "data": {"market": "0xdf05643dbc763608d34bc226b096250bf1a84138c8cd0dcaaaf17e997255f38e", "price_changes": [{"asset_id": "43023538293333812216499804487756700300792959769060172823656702362022968756163", "price": "0.25", "size": "1680", "side": "BUY", "hash": "2673d1cca930f50accb9b9070a0dc0b50d0193ab", "best_bid": "0.93", "best_ask": "0.94"}, {"asset_id": "54033749301194428028417107915177981267461869759594673805572129279965077627691", "price": "0.75", "size": "1680", "side": "SELL", "hash": "cca0abdbf7cda0fc82396a3c62e686d42c99c66b", "best_bid": "0.06", "best_ask": "0.07"}], "timestamp": "1769384325230", "event_type": "price_change"}}
{"_local_timestamp": "2026-01-25T23:38:45.816018+00:00", "data": {"market": "0x620d24e05a0839f300f9d970dd0cf742ecc25e9542720146591a7c4426deb1a5", "price_changes": [{"asset_id": "96474726578408966331514241663172702037609428534006805163072430995039661018902", "price": "0.22", "size": "1908", "side": "BUY", "hash": "d4e2c529e8cfe2d5f6f24cf289177441c371d983", "best_bid": "0.89", "best_ask": "0.92"}, {"asset_id": "63562937989606194538516926327707872978632537481944654374894817966365498120132", "price": "0.78", "size": "1908", "side": "SELL", "hash": "24f222bf5cce7e2b933d5362b10cbf6686e6a79d", "best_bid": "0.08", "best_ask": "0.11"}], "timestamp": "1769384325749", "event_type": "price_change"}}
{"_local_timestamp": "2026-01-25T23:39:20.520577+00:00", "data": {"market": "0xdf05643dbc763608d34bc226b096250bf1a84138c8cd0dcaaaf17e997255f38e", "price_changes": [{"asset_id": "43023538293333812216499804487756700300792959769060172823656702362022968756163", "price": "0.25", "size": "0", "side": "BUY", "hash": "634bf0e929779041c008eaa71bb5ca945715be4d", "best_bid": "0.93", "best_ask": "0.94"}, {"asset_id": "54033749301194428028417107915177981267461869759594673805572129279965077627691", "price": "0.75", "size": "0", "side": "SELL", "hash": "479973ab22aef8009f662262e0e25da4bf4c9f47", "best_bid": "0.06", "best_ask": "0.07"}], "timestamp": "1769384360340", "event_type": "price_change"}}
{"_local_timestamp": "2026-01-25T23:39:20.530067+00:00", "data": {"market": "0x620d24e05a0839f300f9d970dd0cf742ecc25e9542720146591a7c4426deb1a5", "price_changes": [{"asset_id": "96474726578408966331514241663172702037609428534006805163072430995039661018902", "price": "0.22", "size": "0", "side": "BUY", "hash": "7816faf843a945d2d743b1cef8117041e1848e86", "best_bid": "0.89", "best_ask": "0.92"}, {"asset_id": "63562937989606194538516926327707872978632537481944654374894817966365498120132", "price": "0.78", "size": "0", "side": "SELL", "hash": "3906c7842d294ecab1a3ff38ce5c203e36d674fe", "best_bid": "0.08", "best_ask": "0.11"}], "timestamp": "1769384360342", "event_type": "price_change"}}
{"_local_timestamp": "2026-01-25T23:39:20.540287+00:00", "data": {"market": "0x70faa2973143a515446a36a95f9d34efa9bc9bbf39442e21a177658657ebba08", "price_changes": [{"asset_id": "65609516077620000999206912136749570806454562507007008956560753919902115040651", "price": "0.22", "size": "0", "side": "BUY", "hash": "d6b663c81df52d3340923b075fe7e0591a4cd082", "best_bid": "0.86", "best_ask": "0.89"}, {"asset_id": "18608970036028559160373657392306556765154646514657507810165774750998893361620", "price": "0.78", "size": "0", "side": "SELL", "hash": "247bc4a5ca37674673cbb7f0c80932a6836fd568", "best_bid": "0.11", "best_ask": "0.14"}], "timestamp": "1769384360345", "event_type": "price_change"}}
{"_local_timestamp": "2026-01-25T23:39:22.980924+00:00", "data": {"market": "0x70faa2973143a515446a36a95f9d34efa9bc9bbf39442e21a177658657ebba08", "price_changes": [{"asset_id": "65609516077620000999206912136749570806454562507007008956560753919902115040651", "price": "0.21", "size": "1998", "side": "BUY", "hash": "444f4e685b810b976110201df562fefaa42bb66d", "best_bid": "0.86", "best_ask": "0.89"}, {"asset_id": "18608970036028559160373657392306556765154646514657507810165774750998893361620", "price": "0.79", "size": "1998", "side": "SELL", "hash": "3ba799e93fa971e8d3d4762bd9ace0579d5de4c6", "best_bid": "0.11", "best_ask": "0.14"}], "timestamp": "1769384362818", "event_type": "price_change"}}
{"_local_timestamp": "2026-01-25T23:39:37.688186+00:00", "data": {"market": "0xdf05643dbc763608d34bc226b096250bf1a84138c8cd0dcaaaf17e997255f38e", "price_changes": [{"asset_id": "54033749301194428028417107915177981267461869759594673805572129279965077627691", "price": "0.02", "size": "500", "side": "BUY", "hash": "6311418c105ef33d77c162ff8d0fdb11026f98f2", "best_bid": "0.06", "best_ask": "0.07"}, {"asset_id": "43023538293333812216499804487756700300792959769060172823656702362022968756163", "price": "0.98", "size": "500", "side": "SELL", "hash": "12807dec291db05341b07cd32f257098de2d581a", "best_bid": "0.93", "best_ask": "0.94"}], "timestamp": "1769384377620", "event_type": "price_change"}}
{"_local_timestamp": "2026-01-25T23:39:37.694597+00:00", "data": {"market": "0xdf05643dbc763608d34bc226b096250bf1a84138c8cd0dcaaaf17e997255f38e", "price_changes": [{"asset_id": "54033749301194428028417107915177981267461869759594673805572129279965077627691", "price": "0.03", "size": "250", "side": "BUY", "hash": "6311418c105ef33d77c162ff8d0fdb11026f98f2", "best_bid": "0.06", "best_ask": "0.07"}, {"asset_id": "43023538293333812216499804487756700300792959769060172823656702362022968756163", "price": "0.97", "size": "250", "side": "SELL", "hash": "12807dec291db05341b07cd32f257098de2d581a", "best_bid": "0.93", "best_ask": "0.94"}], "timestamp": "1769384377620", "event_type": "price_change"}}
{"_local_timestamp": "2026-01-25T23:39:37.695183+00:00", "data": {"market": "0xdf05643dbc763608d34bc226b096250bf1a84138c8cd0dcaaaf17e997255f38e", "price_changes": [{"asset_id": "54033749301194428028417107915177981267461869759594673805572129279965077627691", "price": "0.04", "size": "0", "side": "BUY", "hash": "6311418c105ef33d77c162ff8d0fdb11026f98f2", "best_bid": "0.06", "best_ask": "0.07"}, {"asset_id": "43023538293333812216499804487756700300792959769060172823656702362022968756163", "price": "0.96", "size": "0", "side": "SELL", "hash": "12807dec291db05341b07cd32f257098de2d581a", "best_bid": "0.93", "best_ask": "0.94"}], "timestamp": "1769384377620", "event_type": "price_change"}}
{"_local_timestamp": "2026-01-25T23:39:38.094943+00:00", "data": {"market": "0xdf05643dbc763608d34bc226b096250bf1a84138c8cd0dcaaaf17e997255f38e", "price_changes": [{"asset_id": "54033749301194428028417107915177981267461869759594673805572129279965077627691", "price": "0.04", "size": "7.76", "side": "BUY", "hash": "f7dd79127ae7e4a346918d650d89037b4830aa44", "best_bid": "0.06", "best_ask": "0.07"}, {"asset_id": "43023538293333812216499804487756700300792959769060172823656702362022968756163", "price": "0.96", "size": "7.76", "side": "SELL", "hash": "132d415fe7385671413d4325d7df69f18f6534bd", "best_bid": "0.93", "best_ask": "0.94"}], "timestamp": "1769384378014", "event_type": "price_change"}}
{"_local_timestamp": "2026-01-25T23:39:38.096236+00:00", "data": {"market": "0xdf05643dbc763608d34bc226b096250bf1a84138c8cd0dcaaaf17e997255f38e", "price_changes": [{"asset_id": "54033749301194428028417107915177981267461869759594673805572129279965077627691", "price": "0.03", "size": "260.88", "side": "BUY", "hash": "10ec9e7e501da3449939f184ac2fa78d3417a02d", "best_bid": "0.06", "best_ask": "0.07"}, {"asset_id": "43023538293333812216499804487756700300792959769060172823656702362022968756163", "price": "0.97", "size": "260.88", "side": "SELL", "hash": "dc398b78d4c6babdcd32193bcfa005af7bc1fea0", "best_bid": "0.93", "best_ask": "0.94"}], "timestamp": "1769384378015", "event_type": "price_change"}}
{"_local_timestamp": "2026-01-25T23:39:38.096942+00:00", "data": {"market": "0xdf05643dbc763608d34bc226b096250bf1a84138c8cd0dcaaaf17e997255f38e", "price_changes": [{"asset_id": "54033749301194428028417107915177981267461869759594673805572129279965077627691", "price": "0.02", "size": "517.15", "side": "BUY", "hash": "0efeed7acae64b2bba57882f09afc57ae7663c48", "best_bid": "0.06", "best_ask": "0.07"}, {"asset_id": "43023538293333812216499804487756700300792959769060172823656702362022968756163", "price": "0.98", "size": "517.15", "side": "SELL", "hash": "999cc9d27b439254e8717e076f55eadf783aa37d", "best_bid": "0.93", "best_ask": "0.94"}], "timestamp": "1769384378016", "event_type": "price_change"}}
{"_local_timestamp": "2026-01-25T23:40:14.047722+00:00", "data": {"market": "0x620d24e05a0839f300f9d970dd0cf742ecc25e9542720146591a7c4426deb1a5", "price_changes": [{"asset_id": "96474726578408966331514241663172702037609428534006805163072430995039661018902", "price": "0.21", "size": "1998", "side": "BUY", "hash": "edf916e7129fad9cae69c507cc57e8b07dcc0d68", "best_bid": "0.89", "best_ask": "0.92"}, {"asset_id": "63562937989606194538516926327707872978632537481944654374894817966365498120132", "price": "0.79", "size": "1998", "side": "SELL", "hash": "f5005504a3eb383b1c610c7e582504591bf681c1", "best_bid": "0.08", "best_ask": "0.11"}], "timestamp": "1769384413981", "event_type": "price_change"}}
{"_local_timestamp": "2026-01-25T23:40:15.130989+00:00", "data": {"market": "0xdf05643dbc763608d34bc226b096250bf1a84138c8cd0dcaaaf17e997255f38e", "price_changes": [{"asset_id": "43023538293333812216499804487756700300792959769060172823656702362022968756163", "price": "0.24", "size": "1748", "side": "BUY", "hash": "4fe7de96ec7c546888bde1c5787cf1e09e4c286c", "best_bid": "0.93", "best_ask": "0.94"}, {"asset_id": "54033749301194428028417107915177981267461869759594673805572129279965077627691", "price": "0.76", "size": "1748", "side": "SELL", "hash": "1b785210efe4540f0cafdf74e11f541cf99c3757", "best_bid": "0.06", "best_ask": "0.07"}], "timestamp": "1769384415064", "event_type": "price_change"}}
