{"_local_timestamp": "2026-01-25T23:41:29.311740+00:00", "data": [{"market": "0xe626501313cb8d66f722d125053ddf816efd4aa009dae1050f92f310fa91ff9a", "asset_id": "38685804131440997628216766545539853582198528599379591557578410900953327025699", "timestamp": "1769384436321", "hash": "fffed0a2cf6905b73a4cb68e998ca28a73f70c61", "bids": [{"price": "0.01", "size": "324.62"}, {"price": "0.02", "size": "136.46"}, {"price": "0.03", "size": "80.96"}, {"price": "0.04", "size": "50"}], "asks": [{"price": "0.99", "size": "192.84"}, {"price": "0.98", "size": "58.52"}, {"price": "0.96", "size": "25"}, {"price": "0.95", "size": "87.15"}, {"price": "0.94", "size": "33"}], "event_type": "book", "last_trade_price": ""}, {"market": "0xe144e5b2eb2d43be067754e0195e5bc3156fa2a9dafcdc5c971dea9b009f7f60", "asset_id": "45218974019212921801596498337894883064595914952289066883702678054321257285550", "timestamp": "1769384423071", "hash": "80955e43fd88fd8e55e9a3ae5da8c4ecae68c3d9", "bids": [{"price": "0.001", "size": "1180.23"}, {"price": "0.002", "size": "65"}, {"price": "0.01", "size": "150"}, {"price": "0.011", "size": "36.72"}, {"price": "0.03", "size": "33"}, {"price": "0.04", "size": "134"}, {"price": "0.041", "size": "5.86"}, {"price": "0.05", "size": "40"}, {"price": "0.06", "size": "33"}, {"price": "0.061", "size": "5.28"}, {"price": "0.062", "size": "32"}, {"price": "0.091", "size": "9.23"}, {"price": "0.55", "size": "10"}, {"price": "0.551", "size": "10.55"}, {"price": "0.95", "size": "7"}, {"price": "0.951", "size": "10.5"}], "asks": [{"price": "0.999", "size": "1163"}, {"price": "0.998", "size": "132.84"}, {"price": "0.99", "size": "330"}, {"price": "0.989", "size": "10.5"}, {"price": "0.988", "size": "11"}, {"price": "0.987", "size": "10.74"}, {"price": "0.98", "size": "100"}], "event_type": "book", "last_trade_price": "0.030"}, {"market": "0x83a2fa96505f6bee0510f9b95e717862f80d01be8ad3d866a230c0d5672f6ccf", "asset_id": "89327756797458917021871888724087464015988084588416726784514471433644934960921", "timestamp": "1769373074373", "hash": "19500f9fe97f7185cbfc47135a81523e727aff0f", "bids": [{"price": "0.01", "size": "192.84"}, {"price": "0.02", "size": "40.06"}, {"price": "0.03", "size": "100"}, {"price": "0.04", "size": "34.35"}, {"price": "0.05", "size": "87.15"}, {"price": "0.06", "size": "33"}], "asks": [{"price": "0.99", "size": "250"}, {"price": "0.98", "size": "100"}, {"price": "0.97", "size": "269"}, {"price": "0.96", "size": "50"}], "event_type": "book", "last_trade_price": ""}, {"market": "0xe98b9b2e5a2177caf5dd606d42696a8bcb9e8bf9ce22d024f37fd7f053de0254", "asset_id": "19627996996735430268045241664484968719809469150103068888743998685557628498908", "timestamp": "1769381837049", "hash": "1a4b457801224062161dc4ae20f4e474459bc706", "bids": [{"price": "0.01", "size": "318.38"}, {"price": "0.02", "size": "132.68"}, {"price": "0.03", "size": "153.64"}, {"price": "0.04", "size": "50"}], "asks": [{"price": "0.99", "size": "192.73"}, {"price": "0.98", "size": "39.95"}, {"price": "0.97", "size": "31"}, {"price": "0.96", "size": "34.33"}, {"price": "0.95", "size": "87.13"}, {"price": "0.94", "size": "33"}], "event_type": "book", "last_trade_price": ""}, {"market": "0xa7c238d9e87666505d0fc2298b28e30689351aa3044b0e4a7619d97f60dab574", "asset_id": "94064639552789175655210972803299191063071409653630071147593656611826234644225", "timestamp": "1769384436416", "hash": "d23eaeb4ecfbb3e201a9a90357c8048d17335390", "bids": [{"price": "0.01", "size": "301.14"}, {"price": "0.02", "size": "122.36"}, {"price": "0.03", "size": "80.96"}, {"price": "0.04", "size": "50"}], "asks": [{"price": "0.99", "size": "192.84"}, {"price": "0.98", "size": "40.06"}, {"price": "0.97", "size": "33"}, {"price": "0.96", "size": "59.35"}, {"price": "0.95", "size": "47.15"}, {"price": "0.94", "size": "33"}], "event_type": "book", "last_trade_price": ""}, {"market": "0xb1305430c922d28c3b42349ffe0ece0e4ac11bf830a142a3f5549f00a247aaac", "asset_id": "26161034170896050895022837974574318528912628918926426980495946827617870218011", "timestamp": "1769384450488", "hash": "f2adc2d60d72313de5979f18799d7c0f22c4597b", "bids": [{"price": "0.01", "size": "164.46"}, {"price": "0.02", "size": "19.95"}, {"price": "0.04", "size": "75"}, {"price": "0.05", "size": "86.97"}, {"price": "0.06", "size": "33"}, {"price": "0.07", "size": "28"}, {"price": "0.08", "size": "13.35"}, {"price": "0.62", "size": "10"}], "asks": [{"price": "0.99", "size": "317.62"}, {"price": "0.98", "size": "132.67"}, {"price": "0.97", "size": "290.82"}, {"price": "0.96", "size": "50"}], "event_type": "book", "last_trade_price": ""}, {"market": "0xa7c238d9e87666505d0fc2298b28e30689351aa3044b0e4a7619d97f60dab574", "asset_id": "114816144529075380229304890363951331093991529093571116224371668251815027076605", "timestamp": "1769384436416", "hash": "9c5499c6290a8bf5951538a782a643ad1ce681c2", "bids": [{"price": "0.01", "size": "192.84"}, {"price": "0.02", "size": "40.06"}, {"price": "0.03", "size": "33"}, {"price": "0.04", "size": "59.35"}, {"price": "0.05", "size": "47.15"}, {"price": "0.06", "size": "33"}], "asks": [{"price": "0.99", "size": "301.14"}, {"price": "0.98", "size": "122.36"}, {"price": "0.97", "size": "80.96"}, {"price": "0.96", "size": "50"}], "event_type": "book", "last_trade_price": ""}, {"market": "0x42559431ecd3bcbfb4753a4e69114fa6be5840fd088eb83e177977cd6c66a96d", "asset_id": "49515446886403785768758917973233614050127916221472655038643700046796866840920", "timestamp": "1769373074371", "hash": "e5bf9a658dfac61c4c5fa9452dbd8874a12981cc", "bids": [{"price": "0.01", "size": "192.84"}, {"price": "0.02", "size": "40.06"}, {"price": "0.03", "size": "100"}, {"price": "0.04", "size": "34.35"}, {"price": "0.05", "size": "87.15"}, {"price": "0.06", "size": "33"}], "asks": [{"price": "0.99", "size": "318.36"}, {"price": "0.98", "size": "132.67"}, {"price": "0.97", "size": "290.82"}, {"price": "0.96", "size": "50"}], "event_type": "book", "last_trade_price": ""}, {"market": "0xe98b9b2e5a2177caf5dd606d42696a8bcb9e8bf9ce22d024f37fd7f053de0254", "asset_id": "65791376794732438726871786720727861723350175074660379803045178237065639872102", "timestamp": "1769381837049", "hash": "eb9dcbb585f860f86d13e9729dd58e0c642a84b7", "bids": [{"price": "0.01", "size": "192.73"}, {"price": "0.02", "size": "39.95"}, {"price": "0.03", "size": "31"}, {"price": "0.04", "size": "34.33"}, {"price": "0.05", "size": "87.13"}, {"price": "0.06", "size": "33"}], "asks": [{"price": "0.99", "size": "318.38"}, {"price": "0.98", "size": "132.68"}, {"price": "0.97", "size": "153.64"}, {"price": "0.96", "size": "50"}], "event_type": "book", "last_trade_price": ""}, {"market": "0x76a7519905a700cb8ec3b999c43a4f47295707b868516911f7ca780c3a848c5c", "asset_id": "32778744816595767341471928947354418244554610655885274093588740578445508974617", "timestamp": "1769384449005", "hash": "06da481998b08cea0e1424b4a02c0c7c8134c420", "bids": [{"price": "0.01", "size": "192.86"}, {"price": "0.02", "size": "116.48"}, {"price": "0.03", "size": "25.53"}, {"price": "0.04", "size": "25"}, {"price": "0.05", "size": "87.16"}, {"price": "0.06", "size": "33"}], "asks": [{"price": "0.99", "size": "324.64"}, {"price": "0.98", "size": "136.47"}, {"price": "0.97", "size": "148.96"}, {"price": "0.96", "size": "50"}], "event_type": "book", "last_trade_price": ""}, {"market": "0x4842ca2e5c6a5ab37590f0a9acfeab97ce9fb2e88d1012f0d4d4c671d79e280e", "asset_id": "35887061083574178815751786347234247569657428793902275549362492733737059438816", "timestamp": "1769384450493", "hash": "df2cdeb523d19d154467d02abd5b07094f62c0f9", "bids": [{"price": "0.01", "size": "192.75"}, {"price": "0.02", "size": "39.97"}, {"price": "0.03", "size": "33"}, {"price": "0.04", "size": "150.33"}, {"price": "0.05", "size": "47.14"}, {"price": "0.06", "size": "33"}], "asks": [{"price": "0.99", "size": "324.61"}, {"price": "0.98", "size": "136.46"}, {"price": "0.97", "size": "285.96"}, {"price": "0.96", "size": "50"}], "event_type": "book", "last_trade_price": ""}, {"market": "0x1e84c701bd89ba6c186cc0e243f6bc84d3d128e34ee774ce671171af33876d95", "asset_id": "102798909221785581214523493369058567779370040532432084121532899910268403226122", "timestamp": "1769373074372", "hash": "6cdca65ec0e4ca364e70e9fa539df1e234a6501f", "bids": [{"price": "0.01", "size": "318.36"}, {"price": "0.02", "size": "132.67"}, {"price": "0.03", "size": "285.82"}, {"price": "0.04", "size": "50"}], "asks": [{"price": "0.99", "size": "192.84"}, {"price": "0.98", "size": "40.06"}, {"price": "0.97", "size": "100"}, {"price": "0.96", "size": "34.35"}, {"price": "0.95", "size": "87.15"}, {"price": "0.94", "size": "33"}], "event_type": "book", "last_trade_price": ""}, {"market": "0x76a7519905a700cb8ec3b999c43a4f47295707b868516911f7ca780c3a848c5c", "asset_id": "114653190955097173543685285128986272298967010021867762616945913380505368681184", "timestamp": "1769384449005", "hash": "f7c5a625482d567440fdbff6d041e99c73c81c57", "bids": [{"price": "0.01", "size": "324.64"}, {"price": "0.02", "size": "136.47"}, {"price": "0.03", "size": "148.96"}, {"price": "0.04", "size": "50"}], "asks": [{"price": "0.99", "size": "192.86"}, {"price": "0.98", "size": "116.48"}, {"price": "0.97", "size": "25.53"}, {"price": "0.96", "size": "25"}, {"price": "0.95", "size": "87.16"}, {"price": "0.94", "size": "33"}], "event_type": "book", "last_trade_price": ""}, {"market": "0xfb65da938eccfa74fe39f4a159427f7bc01d78e544a1191ed3f3ae48dfff5902", "asset_id": "42884793914496699051390107246601510941358481272547385456145293805520032625679", "timestamp": "1769378212882", "hash": "c8efe1ed6024aa755752a8a4e88a4e7d579ce7b7", "bids": [{"price": "0.001", "size": "1004"}, {"price": "0.002", "size": "66.04"}, {"price": "0.01", "size": "150"}, {"price": "0.011", "size": "36.68"}, {"price": "0.04", "size": "25"}, {"price": "0.041", "size": "8.6"}, {"price": "0.05", "size": "80"}, {"price": "0.06", "size": "33"}, {"price": "0.07", "size": "16"}, {"price": "0.071", "size": "14.87"}, {"price": "0.9", "size": "500"}, {"price": "0.91", "size": "100"}, {"price": "0.911", "size": "7.82"}, {"price": "0.975", "size": "29.98"}, {"price": "0.976", "size": "44.96"}, {"price": "0.978", "size": "9"}], "asks": [{"price": "0.999", "size": "5449"}, {"price": "0.997", "size": "121"}, {"price": "0.99", "size": "146.11"}], "event_type": "book", "last_trade_price": "0.010"}, {"market": "0x1e84c701bd89ba6c186cc0e243f6bc84d3d128e34ee774ce671171af33876d95", "asset_id": "111515375385947742803903266497974747362879269125221683371967154555977344307980", "timestamp": "1769373074372", "hash": "98f127e472be4495d98e45e3c7791d04f31f4e8e", "bids": [{"price": "0.01", "size": "192.84"}, {"price": "0.02", "size": "40.06"}, {"price": "0.03", "size": "100"}, {"price": "0.04", "size": "34.35"}, {"price": "0.05", "size": "87.15"}, {"price": "0.06", "size": "33"}], "asks": [{"price": "0.99", "size": "318.36"}, {"price": "0.98", "size": "132.67"}, {"price": "0.97", "size": "285.82"}, {"price": "0.96", "size": "50"}], "event_type": "book", "last_trade_price": ""}, {"market": "0xb1305430c922d28c3b42349ffe0ece0e4ac11bf830a142a3f5549f00a247aaac", "asset_id": "38138499157863750645613334778165467636047944903312411231543355938027027134246", "timestamp": "1769384450488", "hash": "bef1648e568b4613f8d52eea83fea6ff0a0845d1", "bids": [{"price": "0.01", "size": "317.62"}, {"price": "0.02", "size": "132.67"}, {"price": "0.03", "size": "290.82"}, {"price": "0.04", "size": "50"}], "asks": [{"price": "0.99", "size": "164.46"}, {"price": "0.98", "size": "19.95"}, {"price": "0.96", "size": "75"}, {"price": "0.95", "size": "86.97"}, {"price": "0.94", "size": "33"}, {"price": "0.93", "size": "28"}, {"price": "0.92", "size": "13.35"}, {"price": "0.38", "size": "10"}], "event_type": "book", "last_trade_price": ""}, {"market": "0x5e69218543c1f056c6f17aa55336a89c2a46dd646f13460a12a2cec7b3437315", "asset_id": "43696394640502072922989662122256009990440413358797738268484959054530051200403", "timestamp": "1769384484795", "hash": "98a5bc3dd720960450dfe29faeb21347ed107aa2", "bids": [{"price": "0.01", "size": "192.84"}, {"price": "0.02", "size": "58.52"}, {"price": "0.04", "size": "25"}, {"price": "0.05", "size": "87.15"}, {"price": "0.06", "size": "33"}], "asks": [{"price": "0.99", "size": "324.62"}, {"price": "0.98", "size": "136.46"}, {"price": "0.97", "size": "80.96"}, {"price": "0.96", "size": "50"}], "event_type": "book", "last_trade_price": ""}, {"market": "0xfbe28b1467f2d05b44dc72829e1e9177309ac0de5348a751247f09d22a334ee5", "asset_id": "61372312208592669286133886822445475369656919815922158316611217814080411225184", "timestamp": "1769373071440", "hash": "519d88f27d7a56c551f56ae6b95cc1b6d257b144", "bids": [{"price": "0.01", "size": "318.38"}, {"price": "0.02", "size": "132.68"}, {"price": "0.03", "size": "290.83"}, {"price": "0.04", "size": "50"}], "asks": [{"price": "0.99", "size": "192.86"}, {"price": "0.98", "size": "58.79"}, {"price": "0.96", "size": "137"}, {"price": "0.95", "size": "87.16"}, {"price": "0.94", "size": "33"}], "event_type": "book", "last_trade_price": ""}, {"market": "0xb42c5ccc2ac7a3afbbda9c50e86bcca2e8ecc5254ae95abaefe8765685b278b3", "asset_id": "99533302440805666535185543282169689795544372137230353013676443680013573525353", "timestamp": "1769384436603", "hash": "0e6363c984d68694060129c6cc4f6a3b13d96caa", "bids": [{"price": "0.01", "size": "192.67"}, {"price": "0.02", "size": "58.79"}, {"price": "0.04", "size": "137"}, {"price": "0.05", "size": "87.12"}, {"price": "0.06", "size": "33"}], "asks": [{"price": "0.99", "size": "301.88"}, {"price": "0.98", "size": "122.37"}, {"price": "0.97", "size": "286.78"}, {"price": "0.96", "size": "50"}], "event_type": "book", "last_trade_price": ""}, {"market": "0xe626501313cb8d66f722d125053ddf816efd4aa009dae1050f92f310fa91ff9a", "asset_id": "15761156745354731378016989303647400715769177828297398175196810030778190600703", "timestamp": "1769384436321", "hash": "013c56fe313523be129125258d7ca6f73fbe6261", "bids": [{"price": "0.01", "size": "192.84"}, {"price": "0.02", "size": "58.52"}, {"price": "0.04", "size": "25"}, {"price": "0.05", "size": "87.15"}, {"price": "0.06", "size": "33"}], "asks": [{"price": "0.99", "size": "324.62"}, {"price": "0.98", "size": "136.46"}, {"price": "0.97", "size": "80.96"}, {"price": "0.96", "size": "50"}], "event_type": "book", "last_trade_price": ""}, {"market": "0x83a2fa96505f6bee0510f9b95e717862f80d01be8ad3d866a230c0d5672f6ccf", "asset_id": "12628109840311016970032701250150134101801877232439492885896639866994032474343", "timestamp": "1769373074373", "hash": "c8a5bd87567c3fba1eb99c1eabbfd1d28f088f8e", "bids": [{"price": "0.01", "size": "250"}, {"price": "0.02", "size": "100"}, {"price": "0.03", "size": "269"}, {"price": "0.04", "size": "50"}], "asks": [{"price": "0.99", "size": "192.84"}, {"price": "0.98", "size": "40.06"}, {"price": "0.97", "size": "100"}, {"price": "0.96", "size": "34.35"}, {"price": "0.95", "size": "87.15"}, {"price": "0.94", "size": "33"}], "event_type": "book", "last_trade_price": ""}, {"market": "0x42559431ecd3bcbfb4753a4e69114fa6be5840fd088eb83e177977cd6c66a96d", "asset_id": "58585870808885936421420630911348988802563164314107193649098260276765335754262", "timestamp": "1769373074371", "hash": "880e7cf762c78966512a678d2750a03120cd94a5", "bids": [{"price": "0.01", "size": "318.36"}, {"price": "0.02", "size": "132.67"}, {"price": "0.03", "size": "290.82"}, {"price": "0.04", "size": "50"}], "asks": [{"price": "0.99", "size": "192.84"}, {"price": "0.98", "size": "40.06"}, {"price": "0.97", "size": "100"}, {"price": "0.96", "size": "34.35"}, {"price": "0.95", "size": "87.15"}, {"price": "0.94", "size": "33"}], "event_type": "book", "last_trade_price": ""}, {"market": "0xe144e5b2eb2d43be067754e0195e5bc3156fa2a9dafcdc5c971dea9b009f7f60", "asset_id": "15866814654612919603070220550702599864203959543505104317783959882987117165659", "timestamp": "1769384423071", "hash": "9ffe0865947faac944d543e51476946d8c20c768", "bids": [{"price": "0.001", "size": "1163"}, {"price": "0.002", "size": "132.84"}, {"price": "0.01", "size": "330"}, {"price": "0.011", "size": "10.5"}, {"price": "0.012", "size": "11"}, {"price": "0.013", "size": "10.74"}, {"price": "0.02", "size": "100"}], "asks": [{"price": "0.999", "size": "1180.23"}, {"price": "0.998", "size": "65"}, {"price": "0.99", "size": "150"}, {"price": "0.989", "size": "36.72"}, {"price": "0.97", "size": "33"}, {"price": "0.96", "size": "134"}, {"price": "0.959", "size": "5.86"}, {"price": "0.95", "size": "40"}, {"price": "0.94", "size": "33"}, {"price": "0.939", "size": "5.28"}, {"price": "0.938", "size": "32"}, {"price": "0.909", "size": "9.23"}, {"price": "0.45", "size": "10"}, {"price": "0.449", "size": "10.55"}, {"price": "0.05", "size": "7"}, {"price": "0.049", "size": "10.5"}], "event_type": "book", "last_trade_price": "0.030"}, {"market": "0xfb65da938eccfa74fe39f4a159427f7bc01d78e544a1191ed3f3ae48dfff5902", "asset_id": "18250096927514701391860233825644281274681126602746830572233277520329758805054", "timestamp": "1769378212882", "hash": "84081babdf3598ab1b41218e9d10bbd5461f1119", "bids": [{"price": "0.001", "size": "5449"}, {"price": "0.003", "size": "121"}, {"price": "0.01", "size": "146.11"}], "asks": [{"price": "0.999", "size": "1004"}, {"price": "0.998", "size": "66.04"}, {"price": "0.99", "size": "150"}, {"price": "0.989", "size": "36.68"}, {"price": "0.96", "size": "25"}, {"price": "0.959", "size": "8.6"}, {"price": "0.95", "size": "80"}, {"price": "0.94", "size": "33"}, {"price": "0.93", "size": "16"}, {"price": "0.929", "size": "14.87"}, {"price": "0.1", "size": "500"}, {"price": "0.09", "size": "100"}, {"price": "0.089", "size": "7.82"}, {"price": "0.025", "size": "29.98"}, {"price": "0.024", "size": "44.96"}, {"price": "0.022", "size": "9"}], "event_type": "book", "last_trade_price": "0.010"}, {"market": "0x5e69218543c1f056c6f17aa55336a89c2a46dd646f13460a12a2cec7b3437315", "asset_id": "6250880575030227990812003329903422063683420174007181563709432562611157073925", "timestamp": "1769384484795", "hash": "2be4503cfe43421e12aac6c0bd35b4c464ff01a8", "bids": [{"price": "0.01", "size": "324.62"}, {"price": "0.02", "size": "136.46"}, {"price": "0.03", "size": "80.96"}, {"price": "0.04", "size": "50"}], "asks": [{"price": "0.99", "size": "192.84"}, {"price": "0.98", "size": "58.52"}, {"price": "0.96", "size": "25"}, {"price": "0.95", "size": "87.15"}, {"price": "0.94", "size": "33"}], "event_type": "book", "last_trade_price": ""}, {"market": "0x4842ca2e5c6a5ab37590f0a9acfeab97ce9fb2e88d1012f0d4d4c671d79e280e", "asset_id": "87223641130726035407002778702912867259013568537683561597766367179605225790696", "timestamp": "1769384450493", "hash": "1bc895426ea7356f50e6acc515e8d6aca478723f", "bids": [{"price": "0.01", "size": "324.61"}, {"price": "0.02", "size": "136.46"}, {"price": "0.03", "size": "285.96"}, {"price": "0.04", "size": "50"}], "asks": [{"price": "0.99", "size": "192.75"}, {"price": "0.98", "size": "39.97"}, {"price": "0.97", "size": "33"}, {"price": "0.96", "size": "150.33"}, {"price": "0.95", "size": "47.14"}, {"price": "0.94", "size": "33"}], "event_type": "book", "last_trade_price": ""}, {"market": "0xb42c5ccc2ac7a3afbbda9c50e86bcca2e8ecc5254ae95abaefe8765685b278b3", "asset_id": "53068665614262507371787532566688972029639818994241841967520178902248981305998", "timestamp": "1769384436603", "hash": "a5a5905b548458927ed3a50963b8ea1f405bc826", "bids": [{"price": "0.01", "size": "301.88"}, {"price": "0.02", "size": "122.37"}, {"price": "0.03", "size": "286.78"}, {"price": "0.04", "size": "50"}], "asks": [{"price": "0.99", "size": "192.67"}, {"price": "0.98", "size": "58.79"}, {"price": "0.96", "size": "137"}, {"price": "0.95", "size": "87.12"}, {"price": "0.94", "size": "33"}], "event_type": "book", "last_trade_price": ""}, {"market": "0xfbe28b1467f2d05b44dc72829e1e9177309ac0de5348a751247f09d22a334ee5", "asset_id": "37548969357834354143883088681830643403912810201037063232212674173970320873157", "timestamp": "1769373071440", "hash": "bedbf64632931fac45c9fec7adfc2aa5992265f2", "bids": [{"price": "0.01", "size": "192.86"}, {"price": "0.02", "size": "58.79"}, {"price": "0.04", "size": "137"}, {"price": "0.05", "size": "87.16"}, {"price": "0.06", "size": "33"}], "asks": [{"price": "0.99", "size": "318.38"}, {"price": "0.98", "size": "132.68"}, {"price": "0.97", "size": "290.83"}, {"price": "0.96", "size": "50"}], "event_type": "book", "last_trade_price": ""}]}
{"_local_timestamp": "2026-01-25T23:42:25.762726+00:00", "data": {"market": "0xe626501313cb8d66f722d125053ddf816efd4aa009dae1050f92f310fa91ff9a", "price_changes": [{"asset_id": "38685804131440997628216766545539853582198528599379591557578410900953327025699", "price": "0.01", "size": "301.11", "side": "BUY", "hash": "c819442a84c9e853e1043b8d0367fd30702e620e", "best_bid": "0.04", "best_ask": "0.94"}, {"asset_id": "15761156745354731378016989303647400715769177828297398175196810030778190600703", "price": "0.99", "size": "301.11", "side": "SELL", "hash": "7333e5cd9dadcb01bf9523e2c295cb9244b8815c", "best_bid": "0.06", "best_ask": "0.96"}], "timestamp": "1769384545652", "event_type": "price_change"}}
{"_local_timestamp": "2026-01-25T23:42:25.763795+00:00", "data": {"market": "0xe626501313cb8d66f722d125053ddf816efd4aa009dae1050f92f310fa91ff9a", "price_changes": [{"asset_id": "38685804131440997628216766545539853582198528599379591557578410900953327025699", "price": "0.02", "size": "122.35", "side": "BUY", "hash": "c819442a84c9e853e1043b8d0367fd30702e620e", "best_bid": "0.04", "best_ask": "0.94"}, {"asset_id": "15761156745354731378016989303647400715769177828297398175196810030778190600703", "price": "0.98", "size": "122.35", "side": "SELL", "hash": "7333e5cd9dadcb01bf9523e2c295cb9244b8815c", "best_bid": "0.06", "best_ask": "0.96"}], "timestamp": "1769384545652", "event_type": "price_change"}}
{"_local_timestamp": "2026-01-25T23:42:26.640221+00:00", "data": {"market": "0xe626501313cb8d66f722d125053ddf816efd4aa009dae1050f92f310fa91ff9a", "price_changes": [{"asset_id": "38685804131440997628216766545539853582198528599379591557578410900953327025699", "price": "0.02", "size": "136.46", "side": "BUY", "hash": "9d347731ef3c00d0b1aa83474918875296af56c4", "best_bid": "0.04", "best_ask": "0.94"}, {"asset_id": "15761156745354731378016989303647400715769177828297398175196810030778190600703", "price": "0.98", "size": "136.46", "side": "SELL", "hash": "5820968952c5e711b77975929b17f95fea522b30", "best_bid": "0.06", "best_ask": "0.96"}], "timestamp": "1769384546528", "event_type": "price_change"}}
{"_local_timestamp": "2026-01-25T23:42:26.646751+00:00", "data": {"market": "0xe626501313cb8d66f722d125053ddf816efd4aa009dae1050f92f310fa91ff9a", "price_changes": [{"asset_id": "38685804131440997628216766545539853582198528599379591557578410900953327025699", "price": "0.01", "size": "324.61", "side": "BUY", "hash": "95c4b0b25832632ec7fb62275471e072264ddf8a", "best_bid": "0.04", "best_ask": "0.94"}, {"asset_id": "15761156745354731378016989303647400715769177828297398175196810030778190600703", "price": "0.99", "size": "324.61", "side": "SELL", "hash": "bb32d49a0001bfa3c73a88f699b3ed746209c88c", "best_bid": "0.06", "best_ask": "0.96"}], "timestamp": "1769384546537", "event_type": "price_change"}}
{"_local_timestamp": "2026-01-25T23:42:28.413812+00:00", "data": {"market": "0xa7c238d9e87666505d0fc2298b28e30689351aa3044b0e4a7619d97f60dab574", "price_changes": [{"asset_id": "94064639552789175655210972803299191063071409653630071147593656611826234644225", "price": "0.02", "size": "136.46", "side": "BUY", "hash": "9e9bbbe3639d54536f999da25a211379ada04251", "best_bid": "0.04", "best_ask": "0.94"}, {"asset_id": "114816144529075380229304890363951331093991529093571116224371668251815027076605", "price": "0.98", "size": "136.46", "side": "SELL", "hash": "589e0948fcd3f91453ea16351f334ff5c1c5f302", "best_bid": "0.06", "best_ask": "0.96"}], "timestamp": "1769384548322", "event_type": "price_change"}}
{"_local_timestamp": "2026-01-25T23:42:28.414172+00:00", "data": {"market": "0xb42c5ccc2ac7a3afbbda9c50e86bcca2e8ecc5254ae95abaefe8765685b278b3", "price_changes": [{"asset_id": "53068665614262507371787532566688972029639818994241841967520178902248981305998", "price": "0.02", "size": "135.87", "side": "BUY", "hash": "ad32d3aab4a6766cf4a1bf0073bb526662d48132", "best_bid": "0.04", "best_ask": "0.94"}, {"asset_id": "99533302440805666535185543282169689795544372137230353013676443680013573525353", "price": "0.98", "size": "135.87", "side": "SELL", "hash": "d023a03e6c7e00ba91a702fa38533674641158a9", "best_bid": "0.06", "best_ask": "0.96"}], "timestamp": "1769384548322", "event_type": "price_change"}}
{"_local_timestamp": "2026-01-25T23:42:28.418781+00:00", "data": {"market": "0xa7c238d9e87666505d0fc2298b28e30689351aa3044b0e4a7619d97f60dab574", "price_changes": [{"asset_id": "94064639552789175655210972803299191063071409653630071147593656611826234644225", "price": "0.01", "size": "324.61", "side": "BUY", "hash": "0a844926f1c6df511bb9702308d181a6739368d9", "best_bid": "0.04", "best_ask": "0.94"}, {"asset_id": "114816144529075380229304890363951331093991529093571116224371668251815027076605", "price": "0.99", "size": "324.61", "side": "SELL", "hash": "210abcbdc20b0dbf45593e3d8a46bc917c8a286e", "best_bid": "0.06", "best_ask": "0.96"}], "timestamp": "1769384548323", "event_type": "price_change"}}
{"_local_timestamp": "2026-01-25T23:42:28.419143+00:00", "data": {"market": "0xb42c5ccc2ac7a3afbbda9c50e86bcca2e8ecc5254ae95abaefe8765685b278b3", "price_changes": [{"asset_id": "53068665614262507371787532566688972029639818994241841967520178902248981305998", "price": "0.01", "size": "323.39", "side": "BUY", "hash": "8e68187b51c2299b29b94fee6cbf1f32f4f154db", "best_bid": "0.04", "best_ask": "0.94"}, {"asset_id": "99533302440805666535185543282169689795544372137230353013676443680013573525353", "price": "0.99", "size": "323.39", "side": "SELL", "hash": "bdfb8e062dd6d07cae8c2967721b506a3047827d", "best_bid": "0.06", "best_ask": "0.96"}], "timestamp": "1769384548323", "event_type": "price_change"}}
{"_local_timestamp": "2026-01-25T23:43:43.786189+00:00", "data": {"market": "0xb1305430c922d28c3b42349ffe0ece0e4ac11bf830a142a3f5549f00a247aaac", "price_changes": [{"asset_id": "38138499157863750645613334778165467636047944903312411231543355938027027134246", "price": "0.01", "size": "250", "side": "BUY", "hash": "abecd0f5b2c84cf203f114635815c97abbf79175", "best_bid": "0.04", "best_ask": "0.38"}, {"asset_id": "26161034170896050895022837974574318528912628918926426980495946827617870218011", "price": "0.99", "size": "250", "side": "SELL", "hash": "97e79a1e37351da147f8e2a9a511a2252ef432c1", "best_bid": "0.62", "best_ask": "0.96"}], "timestamp": "1769384623675", "event_type": "price_change"}}
{"_local_timestamp": "2026-01-25T23:43:44.691883+00:00", "data": {"market": "0xb1305430c922d28c3b42349ffe0ece0e4ac11bf830a142a3f5549f00a247aaac", "price_changes": [{"asset_id": "38138499157863750645613334778165467636047944903312411231543355938027027134246", "price": "0.01", "size": "317.61", "side": "BUY", "hash": "8a54982cbae6dc96e533e9a584c34bc8edb8dac3", "best_bid": "0.04", "best_ask": "0.38"}, {"asset_id": "26161034170896050895022837974574318528912628918926426980495946827617870218011", "price": "0.99", "size": "317.61", "side": "SELL", "hash": "51574bb01882f507908de7e746573fa00176092f", "best_bid": "0.62", "best_ask": "0.96"}], "timestamp": "1769384624584", "event_type": "price_change"}}
{"_local_timestamp": "2026-01-25T23:43:53.797013+00:00", "data": {"market": "0x5e69218543c1f056c6f17aa55336a89c2a46dd646f13460a12a2cec7b3437315", "price_changes": [{"asset_id": "6250880575030227990812003329903422063683420174007181563709432562611157073925", "price": "0.01", "size": "301.07", "side": "BUY", "hash": "35dcda8060993cd75ced4a2f414c2cd796dab321", "best_bid": "0.04", "best_ask": "0.94"}, {"asset_id": "43696394640502072922989662122256009990440413358797738268484959054530051200403", "price": "0.99", "size": "301.07", "side": "SELL", "hash": "c632934037919ed2a40c684e4412ac33af4cc529", "best_bid": "0.06", "best_ask": "0.96"}], "timestamp": "1769384633661", "event_type": "price_change"}}
{"_local_timestamp": "2026-01-25T23:43:53.797863+00:00", "data": {"market": "0x5e69218543c1f056c6f17aa55336a89c2a46dd646f13460a12a2cec7b3437315", "price_changes": [{"asset_id": "6250880575030227990812003329903422063683420174007181563709432562611157073925", "price": "0.02", "size": "122.34", "side": "BUY", "hash": "35dcda8060993cd75ced4a2f414c2cd796dab321", "best_bid": "0.04", "best_ask": "0.94"}, {"asset_id": "43696394640502072922989662122256009990440413358797738268484959054530051200403", "price": "0.98", "size": "122.34", "side": "SELL", "hash": "c632934037919ed2a40c684e4412ac33af4cc529", "best_bid": "0.06", "best_ask": "0.96"}], "timestamp": "1769384633661", "event_type": "price_change"}}
{"_local_timestamp": "2026-01-25T23:43:54.353929+00:00", "data": {"market": "0x5e69218543c1f056c6f17aa55336a89c2a46dd646f13460a12a2cec7b3437315", "price_changes": [{"asset_id": "6250880575030227990812003329903422063683420174007181563709432562611157073925", "price": "0.01", "size": "324.61", "side": "BUY", "hash": "85c4d7bada7f672d80bf46099601cd0d2f7b06ab", "best_bid": "0.04", "best_ask": "0.94"}, {"asset_id": "43696394640502072922989662122256009990440413358797738268484959054530051200403", "price": "0.99", "size": "324.61", "side": "SELL", "hash": "a73093a7ab703195f4a06ad80960b02578708f87", "best_bid": "0.06", "best_ask": "0.96"}], "timestamp": "1769384634213", "event_type": "price_change"}}
{"_local_timestamp": "2026-01-25T23:43:54.354824+00:00", "data": {"market": "0x5e69218543c1f056c6f17aa55336a89c2a46dd646f13460a12a2cec7b3437315", "price_changes": [{"asset_id": "6250880575030227990812003329903422063683420174007181563709432562611157073925", "price": "0.02", "size": "136.46", "side": "BUY", "hash": "90cda95052598508dd9402e4af3de8d795e20b81", "best_bid": "0.04", "best_ask": "0.94"}, {"asset_id": "43696394640502072922989662122256009990440413358797738268484959054530051200403", "price": "0.98", "size": "136.46", "side": "SELL", "hash": "40aab25ae7f4ecd1747d75a948a580038f265a6d", "best_bid": "0.06", "best_ask": "0.96"}], "timestamp": "1769384634214", "event_type": "price_change"}}
{"_local_timestamp": "2026-01-25T23:44:08.463695+00:00", "data": {"market": "0xb42c5ccc2ac7a3afbbda9c50e86bcca2e8ecc5254ae95abaefe8765685b278b3", "price_changes": [{"asset_id": "53068665614262507371787532566688972029639818994241841967520178902248981305998", "price": "0.01", "size": "301.88", "side": "BUY", "hash": "6bc676bc7c00b804bf2c6f05733104b86b579513", "best_bid": "0.04", "best_ask": "0.94"}, {"asset_id": "99533302440805666535185543282169689795544372137230353013676443680013573525353", "price": "0.99", "size": "301.88", "side": "SELL", "hash": "9accc55d5a17e1484fe5b213f26c7d9c1f571e34", "best_bid": "0.06", "best_ask": "0.96"}], "timestamp": "1769384648247", "event_type": "price_change"}}
{"_local_timestamp": "2026-01-25T23:44:08.464101+00:00", "data": {"market": "0xb42c5ccc2ac7a3afbbda9c50e86bcca2e8ecc5254ae95abaefe8765685b278b3", "price_changes": [{"asset_id": "53068665614262507371787532566688972029639818994241841967520178902248981305998", "price": "0.02", "size": "122.37", "side": "BUY", "hash": "6bc676bc7c00b804bf2c6f05733104b86b579513", "best_bid": "0.04", "best_ask": "0.94"}, {"asset_id": "99533302440805666535185543282169689795544372137230353013676443680013573525353", "price": "0.98", "size": "122.37", "side": "SELL", "hash": "9accc55d5a17e1484fe5b213f26c7d9c1f571e34", "best_bid": "0.06", "best_ask": "0.96"}], "timestamp": "1769384648247", "event_type": "price_change"}}
{"_local_timestamp": "2026-01-25T23:44:09.057943+00:00", "data": {"market": "0xb42c5ccc2ac7a3afbbda9c50e86bcca2e8ecc5254ae95abaefe8765685b278b3", "price_changes": [{"asset_id": "53068665614262507371787532566688972029639818994241841967520178902248981305998", "price": "0.01", "size": "323.38", "side": "BUY", "hash": "a461e540995ff36f64844d5c58a70104bdb36c90", "best_bid": "0.04", "best_ask": "0.94"}, {"asset_id": "99533302440805666535185543282169689795544372137230353013676443680013573525353", "price": "0.99", "size": "323.38", "side": "SELL", "hash": "b16cf4da9a816d1e42ed8d05725269bab21a4577", "best_bid": "0.06", "best_ask": "0.96"}], "timestamp": "1769384648823", "event_type": "price_change"}}
{"_local_timestamp": "2026-01-25T23:44:09.083037+00:00", "data": {"market": "0xb42c5ccc2ac7a3afbbda9c50e86bcca2e8ecc5254ae95abaefe8765685b278b3", "price_changes": [{"asset_id": "53068665614262507371787532566688972029639818994241841967520178902248981305998", "price": "0.02", "size": "135.86", "side": "BUY", "hash": "03cd79814132f6c68895bd20ff02209ad8d52ec6", "best_bid": "0.04", "best_ask": "0.94"}, {"asset_id": "99533302440805666535185543282169689795544372137230353013676443680013573525353", "price": "0.98", "size": "135.86", "side": "SELL", "hash": "6709615989210e5e0cfb6430594c64ce2e38e52e", "best_bid": "0.06", "best_ask": "0.96"}], "timestamp": "1769384648828", "event_type": "price_change"}}
{"_local_timestamp": "2026-01-25T23:44:12.524085+00:00", "data": {"market": "0xe144e5b2eb2d43be067754e0195e5bc3156fa2a9dafcdc5c971dea9b009f7f60", "price_changes": [{"asset_id": "15866814654612919603070220550702599864203959543505104317783959882987117165659", "price": "0.002", "size": "0", "side": "BUY", "hash": "91a685e228e418ec71e645929283f8172ce35d64", "best_bid": "0.02", "best_ask": "0.049"}, {"asset_id": "45218974019212921801596498337894883064595914952289066883702678054321257285550", "price": "0.998", "size": "0", "side": "SELL", "hash": "5914f389b3d455c040c3bc51045d6c533df78684", "best_bid": "0.951", "best_ask": "0.98"}], "timestamp": "1769384652373", "event_type": "price_change"}}
{"_local_timestamp": "2026-01-25T23:44:12.887296+00:00", "data": {"market": "0xe144e5b2eb2d43be067754e0195e5bc3156fa2a9dafcdc5c971dea9b009f7f60", "price_changes": [{"asset_id": "15866814654612919603070220550702599864203959543505104317783959882987117165659", "price": "0.002", "size": "15.02", "side": "BUY", "hash": "aa61e06abafffec5ab2a689350131f070135cc6f", "best_bid": "0.02", "best_ask": "0.049"}, {"asset_id": "45218974019212921801596498337894883064595914952289066883702678054321257285550", "price": "0.998", "size": "15.02", "side": "SELL", "hash": "8d723e36418bf9762330e4890cb79bf91096f311", "best_bid": "0.951", "best_ask": "0.98"}], "timestamp": "1769384652742", "event_type": "price_change"}}
{"_local_timestamp": "2026-01-25T23:44:12.887779+00:00", "data": {"market": "0xe144e5b2eb2d43be067754e0195e5bc3156fa2a9dafcdc5c971dea9b009f7f60", "price_changes": [{"asset_id": "15866814654612919603070220550702599864203959543505104317783959882987117165659", "price": "0.003", "size": "78.52", "side": "BUY", "hash": "3e94eda8fa7013dfdaff3ab279284b72403182ef", "best_bid": "0.02", "best_ask": "0.049"}, {"asset_id": "45218974019212921801596498337894883064595914952289066883702678054321257285550", "price": "0.997", "size": "78.52", "side": "SELL", "hash": "a73bc33ec011b55b164d7eb7aa857d1713d0d5a9", "best_bid": "0.951", "best_ask": "0.98"}], "timestamp": "1769384652744", "event_type": "price_change"}}
{"_local_timestamp": "2026-01-25T23:44:20.024696+00:00", "data": {"market": "0xe144e5b2eb2d43be067754e0195e5bc3156fa2a9dafcdc5c971dea9b009f7f60", "price_changes": [{"asset_id": "45218974019212921801596498337894883064595914952289066883702678054321257285550", "price": "0.061", "size": "0", "side": "BUY", "hash": "5b56d2f20e763aa89f4f99e10031791120d6e2c7", "best_bid": "0.951", "best_ask": "0.98"}, {"asset_id": "15866814654612919603070220550702599864203959543505104317783959882987117165659", "price": "0.939", "size": "0", "side": "SELL", "hash": "1cd460c35fc0267a22b0325465bf2cc566df5956", "best_bid": "0.02", "best_ask": "0.049"}], "timestamp": "1769384659750", "event_type": "price_change"}}
{"_local_timestamp": "2026-01-25T23:44:20.025849+00:00", "data": {"market": "0xe144e5b2eb2d43be067754e0195e5bc3156fa2a9dafcdc5c971dea9b009f7f60", "price_changes": [{"asset_id": "45218974019212921801596498337894883064595914952289066883702678054321257285550", "price": "0.091", "size": "0", "side": "BUY", "hash": "5b56d2f20e763aa89f4f99e10031791120d6e2c7", "best_bid": "0.951", "best_ask": "0.98"}, {"asset_id": "15866814654612919603070220550702599864203959543505104317783959882987117165659", "price": "0.909", "size": "0", "side": "SELL", "hash": "1cd460c35fc0267a22b0325465bf2cc566df5956", "best_bid": "0.02", "best_ask": "0.049"}], "timestamp": "1769384659750", "event_type": "price_change"}}
{"_local_timestamp": "2026-01-25T23:44:21.315786+00:00", "data": {"market": "0xe144e5b2eb2d43be067754e0195e5bc3156fa2a9dafcdc5c971dea9b009f7f60", "price_changes": [{"asset_id": "45218974019212921801596498337894883064595914952289066883702678054321257285550", "price": "0.063", "size": "18.45", "side": "BUY", "hash": "bd3fc569c1dda91fa8eac43261b4d43e02c7c71b", "best_bid": "0.951", "best_ask": "0.98"}, {"asset_id": "15866814654612919603070220550702599864203959543505104317783959882987117165659", "price": "0.937", "size": "18.45", "side": "SELL", "hash": "da7f43af05ce6f61d2ad348704dc65d92b305f03", "best_bid": "0.02", "best_ask": "0.049"}], "timestamp": "1769384660794", "event_type": "price_change"}}
{"_local_timestamp": "2026-01-25T23:45:04.661943+00:00", "data": {"market": "0x4842ca2e5c6a5ab37590f0a9acfeab97ce9fb2e88d1012f0d4d4c671d79e280e", "price_changes": [{"asset_id": "87223641130726035407002778702912867259013568537683561597766367179605225790696", "price": "0.01", "size": "301.13", "side": "BUY", "hash": "7578a60521b67539193bf5e50efb126d6c9996c3", "best_bid": "0.04", "best_ask": "0.94"}, {"asset_id": "35887061083574178815751786347234247569657428793902275549362492733737059438816", "price": "0.99", "size": "301.13", "side": "SELL", "hash": "c80e7d6f6ae60095c695172cb12f314dd2445fcc", "best_bid": "0.06", "best_ask": "0.96"}], "timestamp": "1769384704590", "event_type": "price_change"}}
{"_local_timestamp": "2026-01-25T23:45:04.662870+00:00", "data": {"market": "0x76a7519905a700cb8ec3b999c43a4f47295707b868516911f7ca780c3a848c5c", "price_changes": [{"asset_id": "114653190955097173543685285128986272298967010021867762616945913380505368681184", "price": "0.01", "size": "301.14", "side": "BUY", "hash": "4d9705f87716c8615397dee50a677cb0ff6e3c43", "best_bid": "0.04", "best_ask": "0.94"}, {"asset_id": "32778744816595767341471928947354418244554610655885274093588740578445508974617", "price": "0.99", "size": "301.14", "side": "SELL", "hash": "81ce1915e48dc092c7097f0e71ed6f9e0828c676", "best_bid": "0.06", "best_ask": "0.96"}], "timestamp": "1769384704590", "event_type": "price_change"}}
{"_local_timestamp": "2026-01-25T23:45:04.663310+00:00", "data": {"market": "0x4842ca2e5c6a5ab37590f0a9acfeab97ce9fb2e88d1012f0d4d4c671d79e280e", "price_changes": [{"asset_id": "87223641130726035407002778702912867259013568537683561597766367179605225790696", "price": "0.02", "size": "122.36", "side": "BUY", "hash": "7578a60521b67539193bf5e50efb126d6c9996c3", "best_bid": "0.04", "best_ask": "0.94"}, {"asset_id": "35887061083574178815751786347234247569657428793902275549362492733737059438816", "price": "0.98", "size": "122.36", "side": "SELL", "hash": "c80e7d6f6ae60095c695172cb12f314dd2445fcc", "best_bid": "0.06", "best_ask": "0.96"}], "timestamp": "1769384704590", "event_type": "price_change"}}
{"_local_timestamp": "2026-01-25T23:45:04.663632+00:00", "data": {"market": "0x76a7519905a700cb8ec3b999c43a4f47295707b868516911f7ca780c3a848c5c", "price_changes": [{"asset_id": "114653190955097173543685285128986272298967010021867762616945913380505368681184", "price": "0.02", "size": "122.37", "side": "BUY", "hash": "4d9705f87716c8615397dee50a677cb0ff6e3c43", "best_bid": "0.04", "best_ask": "0.94"}, {"asset_id": "32778744816595767341471928947354418244554610655885274093588740578445508974617", "price": "0.98", "size": "122.37", "side": "SELL", "hash": "81ce1915e48dc092c7097f0e71ed6f9e0828c676", "best_bid": "0.06", "best_ask": "0.96"}], "timestamp": "1769384704590", "event_type": "price_change"}}
{"_local_timestamp": "2026-01-25T23:45:05.165450+00:00", "data": {"market": "0x76a7519905a700cb8ec3b999c43a4f47295707b868516911f7ca780c3a848c5c", "price_changes": [{"asset_id": "114653190955097173543685285128986272298967010021867762616945913380505368681184", "price": "0.02", "size": "136.47", "side": "BUY", "hash": "bf3176944e8fad1c2f729137951fc85f9b37ae36", "best_bid": "0.04", "best_ask": "0.94"}, {"asset_id": "32778744816595767341471928947354418244554610655885274093588740578445508974617", "price": "0.98", "size": "136.47", "side": "SELL", "hash": "5a73db1c48004fdcb012ac6d72f177b4a0d32dd6", "best_bid": "0.06", "best_ask": "0.96"}], "timestamp": "1769384705087", "event_type": "price_change"}}
{"_local_timestamp": "2026-01-25T23:45:05.165963+00:00", "data": {"market": "0x4842ca2e5c6a5ab37590f0a9acfeab97ce9fb2e88d1012f0d4d4c671d79e280e", "price_changes": [{"asset_id": "87223641130726035407002778702912867259013568537683561597766367179605225790696", "price": "0.01", "size": "324.6", "side": "BUY", "hash": "1c1fdb536404b7d2714b48c2c9e0d489aed4efcf", "best_bid": "0.04", "best_ask": "0.94"}, {"asset_id": "35887061083574178815751786347234247569657428793902275549362492733737059438816", "price": "0.99", "size": "324.6", "side": "SELL", "hash": "762184fafeb2c64e4fa2f10764d4fbd51e104d96", "best_bid": "0.06", "best_ask": "0.96"}], "timestamp": "1769384705087", "event_type": "price_change"}}
{"_local_timestamp": "2026-01-25T23:45:05.166767+00:00", "data": {"market": "0x4842ca2e5c6a5ab37590f0a9acfeab97ce9fb2e88d1012f0d4d4c671d79e280e", "price_changes": [{"asset_id": "87223641130726035407002778702912867259013568537683561597766367179605225790696", "price": "0.02", "size": "136.46", "side": "BUY", "hash": "bbde7e1a2fb4b87483ef69a3e5b1e4f2687ba225", "best_bid": "0.04", "best_ask": "0.94"}, {"asset_id": "35887061083574178815751786347234247569657428793902275549362492733737059438816", "price": "0.98", "size": "136.46", "side": "SELL", "hash": "89e01eaaf59271df716d9e029373bc5ff30507aa", "best_bid": "0.06", "best_ask": "0.96"}], "timestamp": "1769384705092", "event_type": "price_change"}}
{"_local_timestamp": "2026-01-25T23:45:05.167127+00:00", "data": {"market": "0x76a7519905a700cb8ec3b999c43a4f47295707b868516911f7ca780c3a848c5c", "price_changes": [{"asset_id": "114653190955097173543685285128986272298967010021867762616945913380505368681184", "price": "0.01", "size": "324.63", "side": "BUY", "hash": "9735b2a3e4a372cc25a043893fba6f2a4c1d038c", "best_bid": "0.04", "best_ask": "0.94"}, {"asset_id": "32778744816595767341471928947354418244554610655885274093588740578445508974617", "price": "0.99", "size": "324.63", "side": "SELL", "hash": "68f21fabc9f4bc024cf54b228ec3ff128179e1cb", "best_bid": "0.06", "best_ask": "0.96"}], "timestamp": "1769384705093", "event_type": "price_change"}}
{"_local_timestamp": "2026-01-25T23:45:57.231609+00:00", "data": {"market": "0xe144e5b2eb2d43be067754e0195e5bc3156fa2a9dafcdc5c971dea9b009f7f60", "price_changes": [{"asset_id": "45218974019212921801596498337894883064595914952289066883702678054321257285550", "price": "0.04", "size": "50", "side": "BUY", "hash": "c42991be087ae90d939a04d66cd3e70e9b72f880", "best_bid": "0.951", "best_ask": "0.98"}, {"asset_id": "15866814654612919603070220550702599864203959543505104317783959882987117165659", "price": "0.96", "size": "50", "side": "SELL", "hash": "a5d39ea7bd13a6aed9ad3e6dc0a4b9ac3a48f381", "best_bid": "0.02", "best_ask": "0.049"}], "timestamp": "1769384756838", "event_type": "price_change"}}
{"_local_timestamp": "2026-01-25T23:46:11.891034+00:00", "data": {"market": "0xa7c238d9e87666505d0fc2298b28e30689351aa3044b0e4a7619d97f60dab574", "price_changes": [{"asset_id": "94064639552789175655210972803299191063071409653630071147593656611826234644225", "price": "0.01", "size": "301.14", "side": "BUY", "hash": "84f8c43dd5d337f9982edca8e6affd88c2586e0c", "best_bid": "0.04", "best_ask": "0.94"}, {"asset_id": "114816144529075380229304890363951331093991529093571116224371668251815027076605", "price": "0.99", "size": "301.14", "side": "SELL", "hash": "f0aaeb3b42b8994f1a655bcae8d743db942e2295", "best_bid": "0.06", "best_ask": "0.96"}], "timestamp": "1769384771825", "event_type": "price_change"}}
{"_local_timestamp": "2026-01-25T23:46:11.891475+00:00", "data": {"market": "0xa7c238d9e87666505d0fc2298b28e30689351aa3044b0e4a7619d97f60dab574", "price_changes": [{"asset_id": "94064639552789175655210972803299191063071409653630071147593656611826234644225", "price": "0.02", "size": "122.36", "side": "BUY", "hash": "84f8c43dd5d337f9982edca8e6affd88c2586e0c", "best_bid": "0.04", "best_ask": "0.94"}, {"asset_id": "114816144529075380229304890363951331093991529093571116224371668251815027076605", "price": "0.98", "size": "122.36", "side": "SELL", "hash": "f0aaeb3b42b8994f1a655bcae8d743db942e2295", "best_bid": "0.06", "best_ask": "0.96"}], "timestamp": "1769384771825", "event_type": "price_change"}}
{"_local_timestamp": "2026-01-25T23:46:11.891833+00:00", "data": {"market": "0xe626501313cb8d66f722d125053ddf816efd4aa009dae1050f92f310fa91ff9a", "price_changes": [{"asset_id": "38685804131440997628216766545539853582198528599379591557578410900953327025699", "price": "0.01", "size": "301.11", "side": "BUY", "hash": "8e73ff5e6302b45982226364d0035fdbc5b1945e", "best_bid": "0.04", "best_ask": "0.94"}, {"asset_id": "15761156745354731378016989303647400715769177828297398175196810030778190600703", "price": "0.99", "size": "301.11", "side": "SELL", "hash": "2756e208e9d9499b368644aa1b9cd1efc515337c", "best_bid": "0.06", "best_ask": "0.96"}], "timestamp": "1769384771825", "event_type": "price_change"}}
{"_local_timestamp": "2026-01-25T23:46:11.892220+00:00", "data": {"market": "0xe626501313cb8d66f722d125053ddf816efd4aa009dae1050f92f310fa91ff9a", "price_changes": [{"asset_id": "38685804131440997628216766545539853582198528599379591557578410900953327025699", "price": "0.02", "size": "122.35", "side": "BUY", "hash": "8e73ff5e6302b45982226364d0035fdbc5b1945e", "best_bid": "0.04", "best_ask": "0.94"}, {"asset_id": "15761156745354731378016989303647400715769177828297398175196810030778190600703", "price": "0.98", "size": "122.35", "side": "SELL", "hash": "2756e208e9d9499b368644aa1b9cd1efc515337c", "best_bid": "0.06", "best_ask": "0.96"}], "timestamp": "1769384771825", "event_type": "price_change"}}
{"_local_timestamp": "2026-01-25T23:46:12.336552+00:00", "data": {"market": "0xe626501313cb8d66f722d125053ddf816efd4aa009dae1050f92f310fa91ff9a", "price_changes": [{"asset_id": "38685804131440997628216766545539853582198528599379591557578410900953327025699", "price": "0.01", "size": "324.6", "side": "BUY", "hash": "0bc51e301ef73249a587562547a79ec80d7beddc", "best_bid": "0.04", "best_ask": "0.94"}, {"asset_id": "15761156745354731378016989303647400715769177828297398175196810030778190600703", "price": "0.99", "size": "324.6", "side": "SELL", "hash": "e66b52b1dac615334df7c431cb95cf38270d162b", "best_bid": "0.06", "best_ask": "0.96"}], "timestamp": "1769384772265", "event_type": "price_change"}}
{"_local_timestamp": "2026-01-25T23:46:12.336988+00:00", "data": {"market": "0xa7c238d9e87666505d0fc2298b28e30689351aa3044b0e4a7619d97f60dab574", "price_changes": [{"asset_id": "94064639552789175655210972803299191063071409653630071147593656611826234644225", "price": "0.02", "size": "136.46", "side": "BUY", "hash": "ad1b467856bed7e8274b0721bff0a03e563a69b3", "best_bid": "0.04", "best_ask": "0.94"}, {"asset_id": "114816144529075380229304890363951331093991529093571116224371668251815027076605", "price": "0.98", "size": "136.46", "side": "SELL", "hash": "59dc848a7947017f25edf2b8ce3ebe073f35e53e", "best_bid": "0.06", "best_ask": "0.96"}], "timestamp": "1769384772265", "event_type": "price_change"}}
{"_local_timestamp": "2026-01-25T23:46:12.337354+00:00", "data": {"market": "0xe626501313cb8d66f722d125053ddf816efd4aa009dae1050f92f310fa91ff9a", "price_changes": [{"asset_id": "38685804131440997628216766545539853582198528599379591557578410900953327025699", "price": "0.02", "size": "136.46", "side": "BUY", "hash": "3a645a9e6434d32f6026b6389e537c808c04bc1a", "best_bid": "0.04", "best_ask": "0.94"}, {"asset_id": "15761156745354731378016989303647400715769177828297398175196810030778190600703", "price": "0.98", "size": "136.46", "side": "SELL", "hash": "491341934f83b9a6042540563f56bd168a7ca386", "best_bid": "0.06", "best_ask": "0.96"}], "timestamp": "1769384772266", "event_type": "price_change"}}
{"_local_timestamp": "2026-01-25T23:46:12.337741+00:00", "data": {"market": "0xa7c238d9e87666505d0fc2298b28e30689351aa3044b0e4a7619d97f60dab574", "price_changes": [{"asset_id": "94064639552789175655210972803299191063071409653630071147593656611826234644225", "price": "0.01", "size": "324.6", "side": "BUY", "hash": "a0a7124557e49df1e8cb19805950717e2c9d71fc", "best_bid": "0.04", "best_ask": "0.94"}, {"asset_id": "114816144529075380229304890363951331093991529093571116224371668251815027076605", "price": "0.99", "size": "324.6", "side": "SELL", "hash": "3c901180ce3dde91e9137fc3535d1d561dbe46c4", "best_bid": "0.06", "best_ask": "0.96"}], "timestamp": "1769384772266", "event_type": "price_change"}}
{"_local_timestamp": "2026-01-25T23:46:49.206194+00:00", "data": {"market": "0xb42c5ccc2ac7a3afbbda9c50e86bcca2e8ecc5254ae95abaefe8765685b278b3", "price_changes": [{"asset_id": "53068665614262507371787532566688972029639818994241841967520178902248981305998", "price": "0.05", "size": "23.99", "side": "BUY", "hash": "5720f3fa509b44b89c7894517bd2e0718305de96", "best_bid": "0.05", "best_ask": "0.94"}, {"asset_id": "99533302440805666535185543282169689795544372137230353013676443680013573525353", "price": "0.95", "size": "23.99", "side": "SELL", "hash": "f7e7502a44dce682600448230e3f537769f571d7", "best_bid": "0.06", "best_ask": "0.95"}], "timestamp": "1769384809133", "event_type": "price_change"}}
{"_local_timestamp": "2026-01-25T23:46:49.355741+00:00", "data": {"market": "0xa7c238d9e87666505d0fc2298b28e30689351aa3044b0e4a7619d97f60dab574", "price_changes": [{"asset_id": "94064639552789175655210972803299191063071409653630071147593656611826234644225", "price": "0.05", "size": "23.99", "side": "BUY", "hash": "b48e00c23811fe5be64032f0bae5eb9e58fd3e8a", "best_bid": "0.05", "best_ask": "0.94"}, {"asset_id": "114816144529075380229304890363951331093991529093571116224371668251815027076605", "price": "0.95", "size": "23.99", "side": "SELL", "hash": "fb9433298acd4cfb5fcd5d9a3ae69c2c5ab749f0", "best_bid": "0.06", "best_ask": "0.95"}], "timestamp": "1769384809291", "event_type": "price_change"}}
{"_local_timestamp": "2026-01-25T23:46:49.462311+00:00", "data": {"market": "0xe626501313cb8d66f722d125053ddf816efd4aa009dae1050f92f310fa91ff9a", "price_changes": [{"asset_id": "38685804131440997628216766545539853582198528599379591557578410900953327025699", "price": "0.05", "size": "23.99", "side": "BUY", "hash": "c03cf01c33e0e6422995fb5a7bf9ef35f04b3a53", "best_bid": "0.05", "best_ask": "0.94"}, {"asset_id": "15761156745354731378016989303647400715769177828297398175196810030778190600703", "price": "0.95", "size": "23.99", "side": "SELL", "hash": "df0d63bb6a59cf78572b97673fd1f670ca622110", "best_bid": "0.06", "best_ask": "0.95"}], "timestamp": "1769384809393", "event_type": "price_change"}}
{"_local_timestamp": "2026-01-25T23:46:57.135323+00:00", "data": {"market": "0xe144e5b2eb2d43be067754e0195e5bc3156fa2a9dafcdc5c971dea9b009f7f60", "price_changes": [{"asset_id": "45218974019212921801596498337894883064595914952289066883702678054321257285550", "price": "0.041", "size": "72.86", "side": "BUY", "hash": "6f831ef29849e8558438c828ac19ca43f3994bb6", "best_bid": "0.951", "best_ask": "0.98"}, {"asset_id": "15866814654612919603070220550702599864203959543505104317783959882987117165659", "price": "0.959", "size": "72.86", "side": "SELL", "hash": "055b7ca45211294effd8d7d541390b6525542eb6", "best_bid": "0.02", "best_ask": "0.049"}], "timestamp": "1769384817065", "event_type": "price_change"}}
{"_local_timestamp": "2026-01-25T23:47:11.476344+00:00", "data": {"market": "0xb1305430c922d28c3b42349ffe0ece0e4ac11bf830a142a3f5549f00a247aaac", "price_changes": [{"asset_id": "38138499157863750645613334778165467636047944903312411231543355938027027134246", "price": "0.01", "size": "250", "side": "BUY", "hash": "10e2b8d543d7fa88181e071215655128487af223", "best_bid": "0.04", "best_ask": "0.38"}, {"asset_id": "26161034170896050895022837974574318528912628918926426980495946827617870218011", "price": "0.99", "size": "250", "side": "SELL", "hash": "49e519b2bfd13c2d74f6bffb8105f7032207407e", "best_bid": "0.62", "best_ask": "0.96"}], "timestamp": "1769384831411", "event_type": "price_change"}}
{"_local_timestamp": "2026-01-25T23:47:11.880359+00:00", "data": {"market": "0xb1305430c922d28c3b42349ffe0ece0e4ac11bf830a142a3f5549f00a247aaac", "price_changes": [{"asset_id": "38138499157863750645613334778165467636047944903312411231543355938027027134246", "price": "0.01", "size": "317.6", "side": "BUY", "hash": "09fc4b42eda2d8acd576a2032620fc8a7b1af222", "best_bid": "0.04", "best_ask": "0.38"}, {"asset_id": "26161034170896050895022837974574318528912628918926426980495946827617870218011", "price": "0.99", "size": "317.6", "side": "SELL", "hash": "9287ec0ec570e5043c2d575a0c01d47e06a0010b", "best_bid": "0.62", "best_ask": "0.96"}], "timestamp": "1769384831813", "event_type": "price_change"}}
{"_local_timestamp": "2026-01-25T23:47:22.660020+00:00", "data": {"market": "0x5e69218543c1f056c6f17aa55336a89c2a46dd646f13460a12a2cec7b3437315", "price_changes": [{"asset_id": "6250880575030227990812003329903422063683420174007181563709432562611157073925", "price": "0.01", "size": "301.07", "side": "BUY", "hash": "df317bb3fed7cb94530fcec158c9d4ad7dfe5125", "best_bid": "0.04", "best_ask": "0.94"}, {"asset_id": "43696394640502072922989662122256009990440413358797738268484959054530051200403", "price": "0.99", "size": "301.07", "side": "SELL", "hash": "cf14820a4728b3c4f52f3eca9e94afdd9f3b68e1", "best_bid": "0.06", "best_ask": "0.96"}], "timestamp": "1769384842595", "event_type": "price_change"}}
{"_local_timestamp": "2026-01-25T23:47:22.660452+00:00", "data": {"market": "0x5e69218543c1f056c6f17aa55336a89c2a46dd646f13460a12a2cec7b3437315", "price_changes": [{"asset_id": "6250880575030227990812003329903422063683420174007181563709432562611157073925", "price": "0.02", "size": "122.34", "side": "BUY", "hash": "df317bb3fed7cb94530fcec158c9d4ad7dfe5125", "best_bid": "0.04", "best_ask": "0.94"}, {"asset_id": "43696394640502072922989662122256009990440413358797738268484959054530051200403", "price": "0.98", "size": "122.34", "side": "SELL", "hash": "cf14820a4728b3c4f52f3eca9e94afdd9f3b68e1", "best_bid": "0.06", "best_ask": "0.96"}], "timestamp": "1769384842595", "event_type": "price_change"}}
{"_local_timestamp": "2026-01-25T23:47:23.027039+00:00", "data": {"market": "0x5e69218543c1f056c6f17aa55336a89c2a46dd646f13460a12a2cec7b3437315", "price_changes": [{"asset_id": "6250880575030227990812003329903422063683420174007181563709432562611157073925", "price": "0.01", "size": "324.6", "side": "BUY", "hash": "7f69beeed80cc1b2a138246253ecaeea551f3fa5", "best_bid": "0.04", "best_ask": "0.94"}, {"asset_id": "43696394640502072922989662122256009990440413358797738268484959054530051200403", "price": "0.99", "size": "324.6", "side": "SELL", "hash": "2d0c0b31a4dce403c070b04c14b3ebb495792829", "best_bid": "0.06", "best_ask": "0.96"}], "timestamp": "1769384842952", "event_type": "price_change"}}
{"_local_timestamp": "2026-01-25T23:47:23.027510+00:00", "data": {"market": "0x5e69218543c1f056c6f17aa55336a89c2a46dd646f13460a12a2cec7b3437315", "price_changes": [{"asset_id": "6250880575030227990812003329903422063683420174007181563709432562611157073925", "price": "0.02", "size": "136.45", "side": "BUY", "hash": "ba673fbf422e35673bd4092223c42c510f2d9dea", "best_bid": "0.04", "best_ask": "0.94"}, {"asset_id": "43696394640502072922989662122256009990440413358797738268484959054530051200403", "price": "0.98", "size": "136.45", "side": "SELL", "hash": "e1a30a84511f88fa10e56177c7ff794baeac560d", "best_bid": "0.06", "best_ask": "0.96"}], "timestamp": "1769384842953", "event_type": "price_change"}}
{"_local_timestamp": "2026-01-25T23:47:23.673821+00:00", "data": {"market": "0xe144e5b2eb2d43be067754e0195e5bc3156fa2a9dafcdc5c971dea9b009f7f60", "price_changes": [{"asset_id": "15866814654612919603070220550702599864203959543505104317783959882987117165659", "price": "0.003", "size": "0", "side": "BUY", "hash": "18e8f8f18ad29ca5d73047391707ec8b33a6ca71", "best_bid": "0.02", "best_ask": "0.049"}, {"asset_id": "45218974019212921801596498337894883064595914952289066883702678054321257285550", "price": "0.997", "size": "0", "side": "SELL", "hash": "b6da13fb6c066d1c23dcc874083662f0da9ddc12", "best_bid": "0.951", "best_ask": "0.98"}], "timestamp": "1769384843540", "event_type": "price_change"}}
{"_local_timestamp": "2026-01-25T23:47:24.028434+00:00", "data": {"market": "0xe144e5b2eb2d43be067754e0195e5bc3156fa2a9dafcdc5c971dea9b009f7f60", "price_changes": [{"asset_id": "15866814654612919603070220550702599864203959543505104317783959882987117165659", "price": "0.004", "size": "51.78", "side": "BUY", "hash": "3d428e952387e312dd9092f5390df820137084e6", "best_bid": "0.02", "best_ask": "0.049"}, {"asset_id": "45218974019212921801596498337894883064595914952289066883702678054321257285550", "price": "0.996", "size": "51.78", "side": "SELL", "hash": "34e07308a96aa53852dcb101c6882e2f6b772fd3", "best_bid": "0.951", "best_ask": "0.98"}], "timestamp": "1769384843962", "event_type": "price_change"}}
{"_local_timestamp": "2026-01-25T23:47:24.028922+00:00", "data": {"market": "0xe144e5b2eb2d43be067754e0195e5bc3156fa2a9dafcdc5c971dea9b009f7f60", "price_changes": [{"asset_id": "15866814654612919603070220550702599864203959543505104317783959882987117165659", "price": "0.002", "size": "29.2", "side": "BUY", "hash": "2c7add1f06d088a59d470ea4f6e830609d0a210a", "best_bid": "0.02", "best_ask": "0.049"}, {"asset_id": "45218974019212921801596498337894883064595914952289066883702678054321257285550", "price": "0.998", "size": "29.2", "side": "SELL", "hash": "3170d56c34fc297ac4ced9a5afe69d4f8f8f159a", "best_bid": "0.951", "best_ask": "0.98"}], "timestamp": "1769384843964", "event_type": "price_change"}}
{"_local_timestamp": "2026-01-25T23:47:27.676899+00:00", "data": {"market": "0xe144e5b2eb2d43be067754e0195e5bc3156fa2a9dafcdc5c971dea9b009f7f60", "price_changes": [{"asset_id": "15866814654612919603070220550702599864203959543505104317783959882987117165659", "price": "0.05", "size": "0", "side": "SELL", "hash": "aa9570f637fffd36c1b7993dd73c3406c3bae0ca", "best_bid": "0.02", "best_ask": "0.049"}, {"asset_id": "45218974019212921801596498337894883064595914952289066883702678054321257285550", "price": "0.95", "size": "0", "side": "BUY", "hash": "a3c7c214060f8297eaf4a0d1631337390bf89f50", "best_bid": "0.951", "best_ask": "0.98"}], "timestamp": "1769384847604", "event_type": "price_change"}}
{"_local_timestamp": "2026-01-25T23:47:27.807095+00:00", "data": {"market": "0xe144e5b2eb2d43be067754e0195e5bc3156fa2a9dafcdc5c971dea9b009f7f60", "price_changes": [{"asset_id": "15866814654612919603070220550702599864203959543505104317783959882987117165659", "price": "0.048", "size": "5", "side": "SELL", "hash": "2736ba24a8ed28b5cb047ed8a15e1be1d2f3515c", "best_bid": "0.02", "best_ask": "0.048"}, {"asset_id": "45218974019212921801596498337894883064595914952289066883702678054321257285550", "price": "0.952", "size": "5", "side": "BUY", "hash": "b42b4913c8aac91ef96773e781618dc860c62ad7", "best_bid": "0.952", "best_ask": "0.98"}], "timestamp": "1769384847742", "event_type": "price_change"}}
{"_local_timestamp": "2026-01-25T23:48:13.402702+00:00", "data": {"market": "0xb42c5ccc2ac7a3afbbda9c50e86bcca2e8ecc5254ae95abaefe8765685b278b3", "price_changes": [{"asset_id": "53068665614262507371787532566688972029639818994241841967520178902248981305998", "price": "0.01", "size": "301.88", "side": "BUY", "hash": "a048beefc01abf29c8cc1b9a036c3f19433633b1", "best_bid": "0.05", "best_ask": "0.94"}, {"asset_id": "99533302440805666535185543282169689795544372137230353013676443680013573525353", "price": "0.99", "size": "301.88", "side": "SELL", "hash": "45be2f71683bf382b5c95ecbaf6c89b88b336a9f", "best_bid": "0.06", "best_ask": "0.95"}], "timestamp": "1769384893335", "event_type": "price_change"}}
{"_local_timestamp": "2026-01-25T23:48:13.403373+00:00", "data": {"market": "0xb42c5ccc2ac7a3afbbda9c50e86bcca2e8ecc5254ae95abaefe8765685b278b3", "price_changes": [{"asset_id": "53068665614262507371787532566688972029639818994241841967520178902248981305998", "price": "0.02", "size": "122.37", "side": "BUY", "hash": "a048beefc01abf29c8cc1b9a036c3f19433633b1", "best_bid": "0.05", "best_ask": "0.94"}, {"asset_id": "99533302440805666535185543282169689795544372137230353013676443680013573525353", "price": "0.98", "size": "122.37", "side": "SELL", "hash": "45be2f71683bf382b5c95ecbaf6c89b88b336a9f", "best_bid": "0.06", "best_ask": "0.95"}], "timestamp": "1769384893335", "event_type": "price_change"}}
{"_local_timestamp": "2026-01-25T23:48:13.745516+00:00", "data": {"market": "0xb42c5ccc2ac7a3afbbda9c50e86bcca2e8ecc5254ae95abaefe8765685b278b3", "price_changes": [{"asset_id": "53068665614262507371787532566688972029639818994241841967520178902248981305998", "price": "0.04", "size": "62.12", "side": "BUY", "hash": "1983dbb49bdf0d59d5f5a840c13b83be10bbbbec", "best_bid": "0.05", "best_ask": "0.94"}, {"asset_id": "99533302440805666535185543282169689795544372137230353013676443680013573525353", "price": "0.96", "size": "62.12", "side": "SELL", "hash": "606dc0154a08c38719ff7c66e55b62b5dd4cd091", "best_bid": "0.06", "best_ask": "0.95"}], "timestamp": "1769384893682", "event_type": "price_change"}}
{"_local_timestamp": "2026-01-25T23:48:18.266384+00:00", "data": {"market": "0xb42c5ccc2ac7a3afbbda9c50e86bcca2e8ecc5254ae95abaefe8765685b278b3", "price_changes": [{"asset_id": "53068665614262507371787532566688972029639818994241841967520178902248981305998", "price": "0.05", "size": "0", "side": "BUY", "hash": "81ced29c871ebd8a516d8a5a25194557835b1a90", "best_bid": "0.04", "best_ask": "0.94"}, {"asset_id": "99533302440805666535185543282169689795544372137230353013676443680013573525353", "price": "0.95", "size": "0", "side": "SELL", "hash": "8bd8b832c1c07446ea9451dbd82319a0598c231b", "best_bid": "0.06", "best_ask": "0.96"}], "timestamp": "1769384898190", "event_type": "price_change"}}
{"_local_timestamp": "2026-01-25T23:48:18.270051+00:00", "data": {"market": "0xe626501313cb8d66f722d125053ddf816efd4aa009dae1050f92f310fa91ff9a", "price_changes": [{"asset_id": "38685804131440997628216766545539853582198528599379591557578410900953327025699", "price": "0.05", "size": "0", "side": "BUY", "hash": "030ea54fac4406c57a591289a3d937a99cd07ba9", "best_bid": "0.04", "best_ask": "0.94"}, {"asset_id": "15761156745354731378016989303647400715769177828297398175196810030778190600703", "price": "0.95", "size": "0", "side": "SELL", "hash": "3e6eca90aa2bf8a5acb91fee383b0b4c96120010", "best_bid": "0.06", "best_ask": "0.96"}], "timestamp": "1769384898190", "event_type": "price_change"}}
{"_local_timestamp": "2026-01-25T23:48:18.270531+00:00", "data": {"market": "0xa7c238d9e87666505d0fc2298b28e30689351aa3044b0e4a7619d97f60dab574", "price_changes": [{"asset_id": "94064639552789175655210972803299191063071409653630071147593656611826234644225", "price": "0.05", "size": "0", "side": "BUY", "hash": "f062a57c38c3806af3975884adfc11e6dcc61f1b", "best_bid": "0.04", "best_ask": "0.94"}, {"asset_id": "114816144529075380229304890363951331093991529093571116224371668251815027076605", "price": "0.95", "size": "0", "side": "SELL", "hash": "573a94e49b04112e12f1d1e0c5371e61efb0f59e", "best_bid": "0.06", "best_ask": "0.96"}], "timestamp": "1769384898190", "event_type": "price_change"}}
{"_local_timestamp": "2026-01-25T23:48:20.384591+00:00", "data": {"market": "0xe144e5b2eb2d43be067754e0195e5bc3156fa2a9dafcdc5c971dea9b009f7f60", "price_changes": [{"asset_id": "45218974019212921801596498337894883064595914952289066883702678054321257285550", "price": "0.041", "size": "67", "side": "BUY", "hash": "ae551ea9e925be346721a4057847eab1a4b62bf9", "best_bid": "0.952", "best_ask": "0.98"}, {"asset_id": "15866814654612919603070220550702599864203959543505104317783959882987117165659", "price": "0.959", "size": "67", "side": "SELL", "hash": "1fa560e928a49447670944fa3140cfcc72dcd399", "best_bid": "0.02", "best_ask": "0.048"}], "timestamp": "1769384900320", "event_type": "price_change"}}
{"_local_timestamp": "2026-01-25T23:48:21.266318+00:00", "data": {"market": "0xe144e5b2eb2d43be067754e0195e5bc3156fa2a9dafcdc5c971dea9b009f7f60", "price_changes": [{"asset_id": "45218974019212921801596498337894883064595914952289066883702678054321257285550", "price": "0.042", "size": "5.72", "side": "BUY", "hash": "ce4bc8cbb635e425a4b8e5bdf26fa8ffff87d5db", "best_bid": "0.952", "best_ask": "0.98"}, {"asset_id": "15866814654612919603070220550702599864203959543505104317783959882987117165659", "price": "0.958", "size": "5.72", "side": "SELL", "hash": "3ed238ae2a5359bfe9cecf28c36e2b29cc6001f9", "best_bid": "0.02", "best_ask": "0.048"}], "timestamp": "1769384901200", "event_type": "price_change"}}
{"_local_timestamp": "2026-01-25T23:48:29.764023+00:00", "data": {"market": "0x4842ca2e5c6a5ab37590f0a9acfeab97ce9fb2e88d1012f0d4d4c671d79e280e", "price_changes": [{"asset_id": "87223641130726035407002778702912867259013568537683561597766367179605225790696", "price": "0.01", "size": "301.13", "side": "BUY", "hash": "c156c7fd78ed9c95cbc921c89ea98edd7b5188b7", "best_bid": "0.04", "best_ask": "0.94"}, {"asset_id": "35887061083574178815751786347234247569657428793902275549362492733737059438816", "price": "0.99", "size": "301.13", "side": "SELL", "hash": "18fb33cafebf33ba222a70b2dbc01a4f95acbea5", "best_bid": "0.06", "best_ask": "0.96"}], "timestamp": "1769384909683", "event_type": "price_change"}}
{"_local_timestamp": "2026-01-25T23:48:29.764956+00:00", "data": {"market": "0x76a7519905a700cb8ec3b999c43a4f47295707b868516911f7ca780c3a848c5c", "price_changes": [{"asset_id": "114653190955097173543685285128986272298967010021867762616945913380505368681184", "price": "0.01", "size": "301.14", "side": "BUY", "hash": "762cebdf0fe05fdcaa77d501859857c3e2c557ee", "best_bid": "0.04", "best_ask": "0.94"}, {"asset_id": "32778744816595767341471928947354418244554610655885274093588740578445508974617", "price": "0.99", "size": "301.14", "side": "SELL", "hash": "483fc4cd3c463562692999f247732cecfd3195e2", "best_bid": "0.06", "best_ask": "0.96"}], "timestamp": "1769384909683", "event_type": "price_change"}}
{"_local_timestamp": "2026-01-25T23:48:29.765457+00:00", "data": {"market": "0x4842ca2e5c6a5ab37590f0a9acfeab97ce9fb2e88d1012f0d4d4c671d79e280e", "price_changes": [{"asset_id": "87223641130726035407002778702912867259013568537683561597766367179605225790696", "price": "0.02", "size": "122.36", "side": "BUY", "hash": "c156c7fd78ed9c95cbc921c89ea98edd7b5188b7", "best_bid": "0.04", "best_ask": "0.94"}, {"asset_id": "35887061083574178815751786347234247569657428793902275549362492733737059438816", "price": "0.98", "size": "122.36", "side": "SELL", "hash": "18fb33cafebf33ba222a70b2dbc01a4f95acbea5", "best_bid": "0.06", "best_ask": "0.96"}], "timestamp": "1769384909683", "event_type": "price_change"}}
{"_local_timestamp": "2026-01-25T23:48:29.765974+00:00", "data": {"market": "0x76a7519905a700cb8ec3b999c43a4f47295707b868516911f7ca780c3a848c5c", "price_changes": [{"asset_id": "114653190955097173543685285128986272298967010021867762616945913380505368681184", "price": "0.02", "size": "122.37", "side": "BUY", "hash": "762cebdf0fe05fdcaa77d501859857c3e2c557ee", "best_bid": "0.04", "best_ask": "0.94"}, {"asset_id": "32778744816595767341471928947354418244554610655885274093588740578445508974617", "price": "0.98", "size": "122.37", "side": "SELL", "hash": "483fc4cd3c463562692999f247732cecfd3195e2", "best_bid": "0.06", "best_ask": "0.96"}], "timestamp": "1769384909683", "event_type": "price_change"}}
{"_local_timestamp": "2026-01-25T23:48:30.060664+00:00", "data": {"market": "0x4842ca2e5c6a5ab37590f0a9acfeab97ce9fb2e88d1012f0d4d4c671d79e280e", "price_changes": [{"asset_id": "87223641130726035407002778702912867259013568537683561597766367179605225790696", "price": "0.01", "size": "324.6", "side": "BUY", "hash": "9fc32f97ccf30087aab31b20855c701e16d9d172", "best_bid": "0.04", "best_ask": "0.94"}, {"asset_id": "35887061083574178815751786347234247569657428793902275549362492733737059438816", "price": "0.99", "size": "324.6", "side": "SELL", "hash": "037017bfb962ab50d8e337eefe2af31f692fcd95", "best_bid": "0.06", "best_ask": "0.96"}], "timestamp": "1769384909983", "event_type": "price_change"}}
{"_local_timestamp": "2026-01-25T23:48:30.061171+00:00", "data": {"market": "0x4842ca2e5c6a5ab37590f0a9acfeab97ce9fb2e88d1012f0d4d4c671d79e280e", "price_changes": [{"asset_id": "87223641130726035407002778702912867259013568537683561597766367179605225790696", "price": "0.02", "size": "136.45", "side": "BUY", "hash": "ffaa9613b9c4f0be3bcd9b35d470139fc578e1a1", "best_bid": "0.04", "best_ask": "0.94"}, {"asset_id": "35887061083574178815751786347234247569657428793902275549362492733737059438816", "price": "0.98", "size": "136.45", "side": "SELL", "hash": "9b39c6a121e5cf1a9eb83a1c1b5ebb5805347380", "best_bid": "0.06", "best_ask": "0.96"}], "timestamp": "1769384909984", "event_type": "price_change"}}
{"_local_timestamp": "2026-01-25T23:48:30.110256+00:00", "data": {"market": "0x76a7519905a700cb8ec3b999c43a4f47295707b868516911f7ca780c3a848c5c", "price_changes": [{"asset_id": "114653190955097173543685285128986272298967010021867762616945913380505368681184", "price": "0.02", "size": "136.47", "side": "BUY", "hash": "07c066946885519da2018652cc650418a70e4209", "best_bid": "0.04", "best_ask": "0.94"}, {"asset_id": "32778744816595767341471928947354418244554610655885274093588740578445508974617", "price": "0.98", "size": "136.47", "side": "SELL", "hash": "eecad60e64d2f178764f857ce95a0c73e06d76cf", "best_bid": "0.06", "best_ask": "0.96"}], "timestamp": "1769384910004", "event_type": "price_change"}}
{"_local_timestamp": "2026-01-25T23:48:30.110828+00:00", "data": {"market": "0x76a7519905a700cb8ec3b999c43a4f47295707b868516911f7ca780c3a848c5c", "price_changes": [{"asset_id": "114653190955097173543685285128986272298967010021867762616945913380505368681184", "price": "0.01", "size": "324.62", "side": "BUY", "hash": "c0613879b0aeac6912a48b1ef5d1bc3d9e2bb4f1", "best_bid": "0.04", "best_ask": "0.94"}, {"asset_id": "32778744816595767341471928947354418244554610655885274093588740578445508974617", "price": "0.99", "size": "324.62", "side": "SELL", "hash": "0e2bfbb2208c11b8b62baf91fc4fc3d993e7e980", "best_bid": "0.06", "best_ask": "0.96"}], "timestamp": "1769384910005", "event_type": "price_change"}}
{"_local_timestamp": "2026-01-25T23:48:32.425363+00:00", "data": {"market": "0xe626501313cb8d66f722d125053ddf816efd4aa009dae1050f92f310fa91ff9a", "price_changes": [{"asset_id": "38685804131440997628216766545539853582198528599379591557578410900953327025699", "price": "0.01", "size": "301.11", "side": "BUY", "hash": "01be8f8f2c6b5aeb77e375a9c527f220878e296b", "best_bid": "0.04", "best_ask": "0.94"}, {"asset_id": "15761156745354731378016989303647400715769177828297398175196810030778190600703", "price": "0.99", "size": "301.11", "side": "SELL", "hash": "29adad9e01d503470af463e9101a27616a0d7365", "best_bid": "0.06", "best_ask": "0.96"}], "timestamp": "1769384912336", "event_type": "price_change"}}
{"_local_timestamp": "2026-01-25T23:48:32.426052+00:00", "data": {"market": "0xe626501313cb8d66f722d125053ddf816efd4aa009dae1050f92f310fa91ff9a", "price_changes": [{"asset_id": "38685804131440997628216766545539853582198528599379591557578410900953327025699", "price": "0.02", "size": "122.35", "side": "BUY", "hash": "01be8f8f2c6b5aeb77e375a9c527f220878e296b", "best_bid": "0.04", "best_ask": "0.94"}, {"asset_id": "15761156745354731378016989303647400715769177828297398175196810030778190600703", "price": "0.98", "size": "122.35", "side": "SELL", "hash": "29adad9e01d503470af463e9101a27616a0d7365", "best_bid": "0.06", "best_ask": "0.96"}], "timestamp": "1769384912336", "event_type": "price_change"}}
{"_local_timestamp": "2026-01-25T23:48:32.426570+00:00", "data": {"market": "0xa7c238d9e87666505d0fc2298b28e30689351aa3044b0e4a7619d97f60dab574", "price_changes": [{"asset_id": "94064639552789175655210972803299191063071409653630071147593656611826234644225", "price": "0.01", "size": "301.14", "side": "BUY", "hash": "c7512c6657f016773e5cb6ef582cee31519cf73d", "best_bid": "0.04", "best_ask": "0.94"}, {"asset_id": "114816144529075380229304890363951331093991529093571116224371668251815027076605", "price": "0.99", "size": "301.14", "side": "SELL", "hash": "2f20f873382b295dcead23cc17801f543849aea0", "best_bid": "0.06", "best_ask": "0.96"}], "timestamp": "1769384912336", "event_type": "price_change"}}
{"_local_timestamp": "2026-01-25T23:48:32.427044+00:00", "data": {"market": "0xa7c238d9e87666505d0fc2298b28e30689351aa3044b0e4a7619d97f60dab574", "price_changes": [{"asset_id": "94064639552789175655210972803299191063071409653630071147593656611826234644225", "price": "0.02", "size": "122.36", "side": "BUY", "hash": "c7512c6657f016773e5cb6ef582cee31519cf73d", "best_bid": "0.04", "best_ask": "0.94"}, {"asset_id": "114816144529075380229304890363951331093991529093571116224371668251815027076605", "price": "0.98", "size": "122.36", "side": "SELL", "hash": "2f20f873382b295dcead23cc17801f543849aea0", "best_bid": "0.06", "best_ask": "0.96"}], "timestamp": "1769384912336", "event_type": "price_change"}}
{"_local_timestamp": "2026-01-25T23:48:32.712899+00:00", "data": {"market": "0xe626501313cb8d66f722d125053ddf816efd4aa009dae1050f92f310fa91ff9a", "price_changes": [{"asset_id": "38685804131440997628216766545539853582198528599379591557578410900953327025699", "price": "0.04", "size": "62.92", "side": "BUY", "hash": "354bbdc1545e135be58e041543ad78c2577145f2", "best_bid": "0.04", "best_ask": "0.94"}, {"asset_id": "15761156745354731378016989303647400715769177828297398175196810030778190600703", "price": "0.96", "size": "62.92", "side": "SELL", "hash": "cf32a814d4701ca2ee7d197287de7f0b7c25b434", "best_bid": "0.06", "best_ask": "0.96"}], "timestamp": "1769384912628", "event_type": "price_change"}}
{"_local_timestamp": "2026-01-25T23:48:32.771654+00:00", "data": {"market": "0xa7c238d9e87666505d0fc2298b28e30689351aa3044b0e4a7619d97f60dab574", "price_changes": [{"asset_id": "94064639552789175655210972803299191063071409653630071147593656611826234644225", "price": "0.04", "size": "62.91", "side": "BUY", "hash": "7545d99785ef876c7517dbe586b27a584a981096", "best_bid": "0.04", "best_ask": "0.94"}, {"asset_id": "114816144529075380229304890363951331093991529093571116224371668251815027076605", "price": "0.96", "size": "62.91", "side": "SELL", "hash": "02f6dae13c9cfcba914d3c3b90f973bc55228d38", "best_bid": "0.06", "best_ask": "0.96"}], "timestamp": "1769384912691", "event_type": "price_change"}}
{"_local_timestamp": "2026-01-25T23:48:34.247548+00:00", "data": {"market": "0xb1305430c922d28c3b42349ffe0ece0e4ac11bf830a142a3f5549f00a247aaac", "price_changes": [{"asset_id": "38138499157863750645613334778165467636047944903312411231543355938027027134246", "price": "0.01", "size": "250", "side": "BUY", "hash": "8cb89ad47ca0a47eb6c03be17e8f07fa8de3b8eb", "best_bid": "0.04", "best_ask": "0.38"}, {"asset_id": "26161034170896050895022837974574318528912628918926426980495946827617870218011", "price": "0.99", "size": "250", "side": "SELL", "hash": "7b10e017b7f2dc5f613bc671e788eb232ce2277d", "best_bid": "0.62", "best_ask": "0.96"}], "timestamp": "1769384914163", "event_type": "price_change"}}
{"_local_timestamp": "2026-01-25T23:48:34.612853+00:00", "data": {"market": "0xb1305430c922d28c3b42349ffe0ece0e4ac11bf830a142a3f5549f00a247aaac", "price_changes": [{"asset_id": "38138499157863750645613334778165467636047944903312411231543355938027027134246", "price": "0.01", "size": "317.59", "side": "BUY", "hash": "5b553bcd5987f8c0d94088a341df10d9d56e2ab0", "best_bid": "0.04", "best_ask": "0.38"}, {"asset_id": "26161034170896050895022837974574318528912628918926426980495946827617870218011", "price": "0.99", "size": "317.59", "side": "SELL", "hash": "2df61efe2edea3144ac077c345fea78a90eaca20", "best_bid": "0.62", "best_ask": "0.96"}], "timestamp": "1769384914526", "event_type": "price_change"}}
{"_local_timestamp": "2026-01-25T23:49:29.162992+00:00", "data": {"market": "0xb42c5ccc2ac7a3afbbda9c50e86bcca2e8ecc5254ae95abaefe8765685b278b3", "price_changes": [{"asset_id": "53068665614262507371787532566688972029639818994241841967520178902248981305998", "price": "0.04", "size": "50", "side": "BUY", "hash": "1e9bd87fdac0e07b4bfd29a6bda8d0c8b788bd54", "best_bid": "0.04", "best_ask": "0.94"}, {"asset_id": "99533302440805666535185543282169689795544372137230353013676443680013573525353", "price": "0.96", "size": "50", "side": "SELL", "hash": "979525c50e6b5ace55d4cb398fb972731f72dfc2", "best_bid": "0.06", "best_ask": "0.96"}], "timestamp": "1769384969049", "event_type": "price_change"}}
{"_local_timestamp": "2026-01-25T23:49:29.163777+00:00", "data": {"market": "0xe626501313cb8d66f722d125053ddf816efd4aa009dae1050f92f310fa91ff9a", "price_changes": [{"asset_id": "38685804131440997628216766545539853582198528599379591557578410900953327025699", "price": "0.04", "size": "50", "side": "BUY", "hash": "e5040e575f31a6b1cda10cb9606f4148c75ecb54", "best_bid": "0.04", "best_ask": "0.94"}, {"asset_id": "15761156745354731378016989303647400715769177828297398175196810030778190600703", "price": "0.96", "size": "50", "side": "SELL", "hash": "53976e242f36952a8ab7f65842cb9dd06c138808", "best_bid": "0.06", "best_ask": "0.96"}], "timestamp": "1769384969049", "event_type": "price_change"}}
{"_local_timestamp": "2026-01-25T23:49:29.170453+00:00", "data": {"market": "0xa7c238d9e87666505d0fc2298b28e30689351aa3044b0e4a7619d97f60dab574", "price_changes": [{"asset_id": "94064639552789175655210972803299191063071409653630071147593656611826234644225", "price": "0.04", "size": "50", "side": "BUY", "hash": "fdac0de648de06ddcac00d518efc2ccc15763e17", "best_bid": "0.04", "best_ask": "0.94"}, {"asset_id": "114816144529075380229304890363951331093991529093571116224371668251815027076605", "price": "0.96", "size": "50", "side": "SELL", "hash": "7bdb626d87a874ec48bf792f328d3eb44f9c0d9b", "best_bid": "0.06", "best_ask": "0.96"}], "timestamp": "1769384969049", "event_type": "price_change"}}
{"_local_timestamp": "2026-01-25T23:49:44.102745+00:00", "data": {"market": "0xa7c238d9e87666505d0fc2298b28e30689351aa3044b0e4a7619d97f60dab574", "price_changes": [{"asset_id": "94064639552789175655210972803299191063071409653630071147593656611826234644225", "price": "0.05", "size": "23.99", "side": "BUY", "hash": "597646d4c875030a6da46d747b3f725ff2d11ce9", "best_bid": "0.05", "best_ask": "0.94"}, {"asset_id": "114816144529075380229304890363951331093991529093571116224371668251815027076605", "price": "0.95", "size": "23.99", "side": "SELL", "hash": "868bcee96ec6637255f4b97179b7d39e1a88d7e4", "best_bid": "0.06", "best_ask": "0.95"}], "timestamp": "1769384984024", "event_type": "price_change"}}
{"_local_timestamp": "2026-01-25T23:49:44.199891+00:00", "data": {"market": "0xe626501313cb8d66f722d125053ddf816efd4aa009dae1050f92f310fa91ff9a", "price_changes": [{"asset_id": "38685804131440997628216766545539853582198528599379591557578410900953327025699", "price": "0.05", "size": "23.99", "side": "BUY", "hash": "13537b525dfccdae08666ef57ddc06bbda10fc7f", "best_bid": "0.05", "best_ask": "0.94"}, {"asset_id": "15761156745354731378016989303647400715769177828297398175196810030778190600703", "price": "0.95", "size": "23.99", "side": "SELL", "hash": "00f572501c70e41fc6bb36581bbee0107ab8636d", "best_bid": "0.06", "best_ask": "0.95"}], "timestamp": "1769384984129", "event_type": "price_change"}}
{"_local_timestamp": "2026-01-25T23:49:44.207387+00:00", "data": {"market": "0xb42c5ccc2ac7a3afbbda9c50e86bcca2e8ecc5254ae95abaefe8765685b278b3", "price_changes": [{"asset_id": "53068665614262507371787532566688972029639818994241841967520178902248981305998", "price": "0.05", "size": "23.99", "side": "BUY", "hash": "8e83a3c492702846f865fc6dd5751b84c9770a77", "best_bid": "0.05", "best_ask": "0.94"}, {"asset_id": "99533302440805666535185543282169689795544372137230353013676443680013573525353", "price": "0.95", "size": "23.99", "side": "SELL", "hash": "50341ec603060b5483f19ee55b9de80b5662db8a", "best_bid": "0.06", "best_ask": "0.95"}], "timestamp": "1769384984129", "event_type": "price_change"}}
{"_local_timestamp": "2026-01-25T23:51:10.629195+00:00", "data": {"market": "0xe626501313cb8d66f722d125053ddf816efd4aa009dae1050f92f310fa91ff9a", "price_changes": [{"asset_id": "38685804131440997628216766545539853582198528599379591557578410900953327025699", "price": "0.05", "size": "0", "side": "BUY", "hash": "495899289118ce743ac37256a4de6d3396e19c0f", "best_bid": "0.04", "best_ask": "0.94"}, {"asset_id": "15761156745354731378016989303647400715769177828297398175196810030778190600703", "price": "0.95", "size": "0", "side": "SELL", "hash": "88bd7462fabec7db6ef63d9c62a523fdcaff42f7", "best_bid": "0.06", "best_ask": "0.96"}], "timestamp": "1769385070559", "event_type": "price_change"}}
{"_local_timestamp": "2026-01-25T23:51:10.630052+00:00", "data": {"market": "0xa7c238d9e87666505d0fc2298b28e30689351aa3044b0e4a7619d97f60dab574", "price_changes": [{"asset_id": "94064639552789175655210972803299191063071409653630071147593656611826234644225", "price": "0.05", "size": "0", "side": "BUY", "hash": "4743af6a7427139211ebf95f91fd38e04304c58e", "best_bid": "0.04", "best_ask": "0.94"}, {"asset_id": "114816144529075380229304890363951331093991529093571116224371668251815027076605", "price": "0.95", "size": "0", "side": "SELL", "hash": "aada27a4e89fc7461436505a2e6934491f3241d8", "best_bid": "0.06", "best_ask": "0.96"}], "timestamp": "1769385070559", "event_type": "price_change"}}
{"_local_timestamp": "2026-01-25T23:51:10.630543+00:00", "data": {"market": "0xb42c5ccc2ac7a3afbbda9c50e86bcca2e8ecc5254ae95abaefe8765685b278b3", "price_changes": [{"asset_id": "53068665614262507371787532566688972029639818994241841967520178902248981305998", "price": "0.05", "size": "0", "side": "BUY", "hash": "801d5063b25542faef2aa42a165f607470e368d2", "best_bid": "0.04", "best_ask": "0.94"}, {"asset_id": "99533302440805666535185543282169689795544372137230353013676443680013573525353", "price": "0.95", "size": "0", "side": "SELL", "hash": "ca1769cdccf4d6b1bd50f4749838567860fb625d", "best_bid": "0.06", "best_ask": "0.96"}], "timestamp": "1769385070559", "event_type": "price_change"}}
