{"_local_timestamp": "2026-01-25T23:40:29.828290+00:00", "data": [{"market": "0x50ddb9cd80d5c271664a2ebb7fcaed1d0a148d82c8e8d314d830f75a944c3dcc", "asset_id": "88275040060084773376557187972215267513049848642895776801789297917961077894224", "timestamp": "1769384428702", "hash": "a43e9049a6954a8c17de10ce21a41e776ca314e5", "bids": [{"price": "0.01", "size": "1107830.07"}, {"price": "0.02", "size": "11000"}, {"price": "0.03", "size": "61800"}, {"price": "0.04", "size": "23.16"}, {"price": "0.06", "size": "10900"}, {"price": "0.07", "size": "21000"}, {"price": "0.09", "size": "377.77"}, {"price": "0.1", "size": "6.08"}, {"price": "0.12", "size": "816.66"}, {"price": "0.15", "size": "186.66"}, {"price": "0.16", "size": "5450"}, {"price": "0.18", "size": "144.44"}, {"price": "0.19", "size": "3191"}, {"price": "0.2", "size": "1300"}, {"price": "0.21", "size": "214.28"}, {"price": "0.22", "size": "250"}, {"price": "0.23", "size": "100"}, {"price": "0.24", "size": "83.33"}, {"price": "0.29", "size": "649"}, {"price": "0.43", "size": "2457.4"}, {"price": "0.44", "size": "185.16"}, {"price": "0.46", "size": "124.17"}, {"price": "0.48", "size": "5.16"}, {"price": "0.49", "size": "100"}, {"price": "0.51", "size": "60"}, {"price": "0.52", "size": "39.72"}, {"price": "0.53", "size": "5.16"}], "asks": [{"price": "0.99", "size": "6510.21"}, {"price": "0.98", "size": "1600"}, {"price": "0.97", "size": "10.42"}, {"price": "0.95", "size": "1920"}, {"price": "0.94", "size": "510"}, {"price": "0.93", "size": "485.71"}, {"price": "0.92", "size": "4385"}, {"price": "0.9", "size": "320"}, {"price": "0.89", "size": "5.32"}, {"price": "0.88", "size": "233.33"}, {"price": "0.87", "size": "454"}, {"price": "0.86", "size": "185.71"}, {"price": "0.83", "size": "291.17"}, {"price": "0.82", "size": "11"}, {"price": "0.81", "size": "105.26"}, {"price": "0.75", "size": "144.99"}, {"price": "0.7", "size": "551.26"}, {"price": "0.69", "size": "100"}, {"price": "0.64", "size": "36.11"}, {"price": "0.63", "size": "29.72"}, {"price": "0.62", "size": "100"}, {"price": "0.61", "size": "29"}, {"price": "0.6", "size": "14.1"}, {"price": "0.56", "size": "17"}], "event_type": "book", "last_trade_price": "0.570"}, {"market": "0x1fad72fae204143ff1c3035e99e7c0f65ea8d5cd9bd1070987bd1a3316f772be", "asset_id": "53831553061883006530739877284105938919721408776239639687877978808906551086026", "timestamp": "1769384429002", "hash": "e235fc1b422bb51dd8374eea862198108590d232", "bids": [{"price": "0.01", "size": "7524.87"}, {"price": "0.02", "size": "1000"}, {"price": "0.03", "size": "10.26"}, {"price": "0.04", "size": "2700"}, {"price": "0.05", "size": "300"}, {"price": "0.07", "size": "985.71"}, {"price": "0.09", "size": "355.55"}, {"price": "0.1", "size": "5426"}, {"price": "0.11", "size": "259.93"}, {"price": "0.12", "size": "4050"}, {"price": "0.13", "size": "250"}, {"price": "0.14", "size": "185.71"}, {"price": "0.16", "size": "150"}, {"price": "0.18", "size": "111.11"}, {"price": "0.2", "size": "360"}, {"price": "0.23", "size": "400"}, {"price": "0.28", "size": "1000"}, {"price": "0.33", "size": "1000"}, {"price": "0.34", "size": "300"}, {"price": "0.35", "size": "237.13"}, {"price": "0.36", "size": "30.55"}, {"price": "0.4", "size": "215"}, {"price": "0.41", "size": "120"}, {"price": "0.42", "size": "403.88"}], "asks": [{"price": "0.99", "size": "1117814.94"}, {"price": "0.98", "size": "62800"}, {"price": "0.97", "size": "30000"}, {"price": "0.96", "size": "255.1"}, {"price": "0.94", "size": "1600"}, {"price": "0.92", "size": "525"}, {"price": "0.91", "size": "7.18"}, {"price": "0.89", "size": "290.9"}, {"price": "0.88", "size": "1332"}, {"price": "0.86", "size": "200"}, {"price": "0.85", "size": "6600"}, {"price": "0.84", "size": "3024"}, {"price": "0.83", "size": "152.94"}, {"price": "0.8", "size": "120"}, {"price": "0.78", "size": "5090.9"}, {"price": "0.76", "size": "9300"}, {"price": "0.75", "size": "3131"}, {"price": "0.74", "size": "2224"}, {"price": "0.73", "size": "300"}, {"price": "0.72", "size": "300"}, {"price": "0.69", "size": "450"}, {"price": "0.68", "size": "1813"}, {"price": "0.67", "size": "200"}, {"price": "0.66", "size": "200"}, {"price": "0.65", "size": "200"}, {"price": "0.64", "size": "200"}, {"price": "0.63", "size": "200"}, {"price": "0.62", "size": "200"}, {"price": "0.6", "size": "855"}, {"price": "0.52", "size": "27.08"}, {"price": "0.51", "size": "5247.44"}, {"price": "0.5", "size": "8530.49"}, {"price": "0.49", "size": "132"}, {"price": "0.47", "size": "414.93"}, {"price": "0.46", "size": "233"}, {"price": "0.45", "size": "79.81"}], "event_type": "book", "last_trade_price": "0.570"}, {"market": "0xbb57ccf5853a85487bc3d83d04d669310d28c6c810758953b9d9b91d1aee89d2", "asset_id": "91863162118308663069733924043159186005106558783397508844234610341221325526200", "timestamp": "1769384411618", "hash": "9cca06ab0928eee005b5fe858c51039097ad2739", "bids": [{"price": "0.01", "size": "1107820.24"}, {"price": "0.02", "size": "21000"}, {"price": "0.03", "size": "91800"}, {"price": "0.04", "size": "10005.2"}, {"price": "0.05", "size": "10300"}, {"price": "0.06", "size": "250"}, {"price": "0.09", "size": "2376"}, {"price": "0.1", "size": "11.39"}, {"price": "0.13", "size": "38"}, {"price": "0.15", "size": "3050"}, {"price": "0.16", "size": "2624"}, {"price": "0.19", "size": "5000"}, {"price": "0.2", "size": "10500"}, {"price": "0.21", "size": "1200"}, {"price": "0.26", "size": "500"}, {"price": "0.4", "size": "20"}, {"price": "0.41", "size": "2000"}, {"price": "0.42", "size": "1000"}, {"price": "0.43", "size": "30.23"}, {"price": "0.44", "size": "25"}, {"price": "0.49", "size": "321.16"}, {"price": "0.5", "size": "132677.52"}, {"price": "0.51", "size": "86805.58"}], "asks": [{"price": "0.99", "size": "1027815.31"}, {"price": "0.98", "size": "102805.03"}, {"price": "0.97", "size": "250"}, {"price": "0.96", "size": "7.07"}, {"price": "0.95", "size": "300"}, {"price": "0.93", "size": "1000"}, {"price": "0.91", "size": "6.25"}, {"price": "0.9", "size": "128.84"}, {"price": "0.89", "size": "1459.12"}, {"price": "0.88", "size": "275"}, {"price": "0.87", "size": "3230"}, {"price": "0.86", "size": "3572"}, {"price": "0.85", "size": "325"}, {"price": "0.84", "size": "400"}, {"price": "0.79", "size": "115"}, {"price": "0.75", "size": "5"}, {"price": "0.74", "size": "20000"}, {"price": "0.73", "size": "1852"}, {"price": "0.64", "size": "200"}, {"price": "0.63", "size": "200"}, {"price": "0.62", "size": "34.21"}, {"price": "0.6", "size": "200"}, {"price": "0.59", "size": "902.82"}, {"price": "0.58", "size": "200"}, {"price": "0.57", "size": "619"}, {"price": "0.56", "size": "2100"}, {"price": "0.55", "size": "14600"}, {"price": "0.54", "size": "361.53"}, {"price": "0.53", "size": "3549.61"}, {"price": "0.52", "size": "137505.39"}], "event_type": "book", "last_trade_price": "0.490"}, {"market": "0x0ea8005efbc460378340a2f28a6d97b0d1d9d9d7fba4d16f529b8a415dca77a2", "asset_id": "48266425622404486484896353767723266081505997963592758694068789352158715350186", "timestamp": "1769384429537", "hash": "7b0918ab3ea9fbbbba11882411f8a78242de4dc9", "bids": [{"price": "0.01", "size": "7500"}, {"price": "0.02", "size": "3805.79"}, {"price": "0.03", "size": "250"}, {"price": "0.04", "size": "906.08"}, {"price": "0.06", "size": "1866.66"}, {"price": "0.08", "size": "400"}, {"price": "0.09", "size": "7.11"}, {"price": "0.1", "size": "280"}, {"price": "0.11", "size": "151.37"}, {"price": "0.12", "size": "3941.66"}, {"price": "0.14", "size": "186.57"}, {"price": "0.16", "size": "275"}, {"price": "0.2", "size": "5"}, {"price": "0.25", "size": "472.19"}, {"price": "0.26", "size": "9900"}, {"price": "0.27", "size": "9500"}, {"price": "0.28", "size": "10000"}, {"price": "0.29", "size": "9266.82"}, {"price": "0.3", "size": "8036.66"}, {"price": "0.31", "size": "20"}, {"price": "0.32", "size": "211.37"}, {"price": "0.33", "size": "31.51"}, {"price": "0.34", "size": "20.1"}, {"price": "0.36", "size": "220"}, {"price": "0.37", "size": "890.4"}], "asks": [{"price": "0.99", "size": "1109839.79"}, {"price": "0.98", "size": "11000"}, {"price": "0.97", "size": "31800"}, {"price": "0.96", "size": "6.72"}, {"price": "0.94", "size": "1600"}, {"price": "0.93", "size": "300"}, {"price": "0.9", "size": "340"}, {"price": "0.89", "size": "9605.29"}, {"price": "0.87", "size": "496.15"}, {"price": "0.86", "size": "1142"}, {"price": "0.84", "size": "175"}, {"price": "0.81", "size": "2210"}, {"price": "0.8", "size": "580"}, {"price": "0.79", "size": "2381"}, {"price": "0.77", "size": "204.34"}, {"price": "0.74", "size": "76.92"}, {"price": "0.72", "size": "5150"}, {"price": "0.71", "size": "1397"}, {"price": "0.56", "size": "300"}, {"price": "0.55", "size": "2750"}, {"price": "0.54", "size": "2200"}, {"price": "0.53", "size": "200"}, {"price": "0.52", "size": "392"}, {"price": "0.5", "size": "5671.67"}, {"price": "0.48", "size": "1181"}, {"price": "0.47", "size": "113.52"}, {"price": "0.46", "size": "20.37"}, {"price": "0.42", "size": "170"}, {"price": "0.41", "size": "381.32"}, {"price": "0.4", "size": "144.85"}, {"price": "0.39", "size": "4.32"}], "event_type": "book", "last_trade_price": "0.630"}, {"market": "0x84f8b70331323c2fba97d7ceaa9a35fb645a0770d0dbff169d07f24f376766e9", "asset_id": "64533579809297525579033609963634939501013332859992608996100633472507000251907", "timestamp": "1769384364159", "hash": "d81c9c86ec2364ca21120919b09824e1edaebfb1", "bids": [{"price": "0.01", "size": "9510.39"}, {"price": "0.02", "size": "1600"}, {"price": "0.03", "size": "11.08"}, {"price": "0.05", "size": "1920"}, {"price": "0.08", "size": "425"}, {"price": "0.09", "size": "4171"}, {"price": "0.1", "size": "320"}, {"price": "0.11", "size": "1459.12"}, {"price": "0.12", "size": "733.33"}, {"price": "0.13", "size": "3830"}, {"price": "0.15", "size": "261.35"}, {"price": "0.17", "size": "141.17"}, {"price": "0.19", "size": "514.69"}, {"price": "0.2", "size": "222.31"}, {"price": "0.21", "size": "650"}, {"price": "0.22", "size": "150"}, {"price": "0.23", "size": "212.69"}, {"price": "0.24", "size": "8"}, {"price": "0.27", "size": "98"}, {"price": "0.28", "size": "16.92"}, {"price": "0.34", "size": "125.18"}, {"price": "0.35", "size": "84.01"}, {"price": "0.37", "size": "44"}, {"price": "0.38", "size": "34.21"}, {"price": "0.39", "size": "28.2"}, {"price": "0.41", "size": "55.02"}, {"price": "0.44", "size": "12.69"}, {"price": "0.45", "size": "200"}, {"price": "0.46", "size": "222"}, {"price": "0.47", "size": "163.23"}], "asks": [{"price": "0.99", "size": "1107815.18"}, {"price": "0.98", "size": "26000"}, {"price": "0.97", "size": "61800"}, {"price": "0.96", "size": "256.92"}, {"price": "0.95", "size": "1020"}, {"price": "0.92", "size": "845.03"}, {"price": "0.91", "size": "6.75"}, {"price": "0.9", "size": "1520"}, {"price": "0.89", "size": "5.19"}, {"price": "0.88", "size": "3570.4"}, {"price": "0.87", "size": "1445.38"}, {"price": "0.85", "size": "173.33"}, {"price": "0.84", "size": "6199"}, {"price": "0.83", "size": "3000"}, {"price": "0.82", "size": "2522.33"}, {"price": "0.8", "size": "100"}, {"price": "0.79", "size": "270.34"}, {"price": "0.64", "size": "200"}, {"price": "0.61", "size": "20.34"}, {"price": "0.6", "size": "738"}, {"price": "0.59", "size": "2200"}, {"price": "0.58", "size": "200"}, {"price": "0.57", "size": "482.23"}, {"price": "0.56", "size": "25"}, {"price": "0.55", "size": "200"}, {"price": "0.54", "size": "318"}, {"price": "0.53", "size": "200"}, {"price": "0.52", "size": "200"}, {"price": "0.51", "size": "2091"}, {"price": "0.5", "size": "17169.79"}, {"price": "0.49", "size": "10149.74"}], "event_type": "book", "last_trade_price": "0.510"}, {"market": "0x7b49b9bacb5f435bc10f3b100ff59e2fdd346f7f92a9001881bc9825a0af0f11", "asset_id": "17516427576383382756368467656206258206490015951115433065318503962238754362428", "timestamp": "1769384385863", "hash": "dcc17b20edb1637857d76ec00afdbef6c6c02e9c", "bids": [{"price": "0.01", "size": "27805.31"}, {"price": "0.02", "size": "1605.03"}, {"price": "0.03", "size": "250"}, {"price": "0.04", "size": "7.07"}, {"price": "0.05", "size": "1920"}, {"price": "0.07", "size": "1485.71"}, {"price": "0.1", "size": "820"}, {"price": "0.11", "size": "1459.12"}, {"price": "0.12", "size": "233.33"}, {"price": "0.13", "size": "3230"}, {"price": "0.15", "size": "3223.33"}, {"price": "0.17", "size": "141.17"}, {"price": "0.18", "size": "200"}, {"price": "0.19", "size": "3164"}, {"price": "0.2", "size": "1100"}, {"price": "0.21", "size": "700"}, {"price": "0.22", "size": "350"}, {"price": "0.23", "size": "350"}, {"price": "0.25", "size": "200"}, {"price": "0.26", "size": "300"}, {"price": "0.27", "size": "376.87"}, {"price": "0.28", "size": "300"}, {"price": "0.29", "size": "300"}, {"price": "0.3", "size": "300"}, {"price": "0.34", "size": "38.23"}, {"price": "0.4", "size": "10000"}, {"price": "0.41", "size": "1449.82"}, {"price": "0.47", "size": "2020.49"}, {"price": "0.48", "size": "6852.27"}], "asks": [{"price": "0.99", "size": "1117820.61"}, {"price": "0.98", "size": "102800"}, {"price": "0.97", "size": "10.88"}, {"price": "0.96", "size": "10000"}, {"price": "0.95", "size": "31020"}, {"price": "0.94", "size": "250"}, {"price": "0.92", "size": "835.65"}, {"price": "0.9", "size": "5520"}, {"price": "0.89", "size": "305.17"}, {"price": "0.88", "size": "1332"}, {"price": "0.87", "size": "5215.38"}, {"price": "0.85", "size": "16234"}, {"price": "0.84", "size": "3486.5"}, {"price": "0.83", "size": "2845"}, {"price": "0.82", "size": "383.33"}, {"price": "0.81", "size": "250"}, {"price": "0.8", "size": "200"}, {"price": "0.79", "size": "295.23"}, {"price": "0.78", "size": "220.4"}, {"price": "0.77", "size": "400"}, {"price": "0.76", "size": "200"}, {"price": "0.75", "size": "200"}, {"price": "0.72", "size": "200"}, {"price": "0.71", "size": "200"}, {"price": "0.7", "size": "200"}, {"price": "0.69", "size": "200"}, {"price": "0.68", "size": "200"}, {"price": "0.67", "size": "200"}, {"price": "0.66", "size": "200"}, {"price": "0.64", "size": "200"}, {"price": "0.62", "size": "200"}, {"price": "0.61", "size": "200"}, {"price": "0.6", "size": "200"}, {"price": "0.59", "size": "740"}, {"price": "0.58", "size": "400"}, {"price": "0.57", "size": "230.23"}, {"price": "0.56", "size": "478"}, {"price": "0.55", "size": "200"}, {"price": "0.54", "size": "400"}, {"price": "0.53", "size": "783"}, {"price": "0.52", "size": "900"}, {"price": "0.51", "size": "5097.74"}, {"price": "0.5", "size": "19135.95"}, {"price": "0.49", "size": "812.15"}], "event_type": "book", "last_trade_price": "0.490"}, {"market": "0x9c1a953fe92c8357f1b646ba25d983aa83e90c525992db14fb726fa895cb5763", "asset_id": "2527312495175492857904889758552137141356236738032676480522356889996545113869", "timestamp": "1769384417514", "hash": "359f658581703f8bcab7c265b9556d8b5a3bf5b6", "bids": [{"price": "0.01", "size": "317800"}, {"price": "0.02", "size": "1255.86"}, {"price": "0.03", "size": "50"}, {"price": "0.04", "size": "2707.21"}, {"price": "0.06", "size": "866.66"}, {"price": "0.08", "size": "400"}, {"price": "0.09", "size": "3366"}, {"price": "0.1", "size": "285.94"}, {"price": "0.11", "size": "4368"}, {"price": "0.12", "size": "8.93"}, {"price": "0.13", "size": "200"}, {"price": "0.15", "size": "160"}, {"price": "0.17", "size": "117.64"}, {"price": "0.19", "size": "2000"}, {"price": "0.28", "size": "70000"}, {"price": "0.29", "size": "6590.96"}, {"price": "0.3", "size": "1016.08"}, {"price": "0.31", "size": "1666.58"}, {"price": "0.32", "size": "3174.82"}, {"price": "0.34", "size": "550"}, {"price": "0.35", "size": "758.56"}, {"price": "0.36", "size": "453.23"}, {"price": "0.37", "size": "75.58"}], "asks": [{"price": "0.99", "size": "1027814.81"}, {"price": "0.98", "size": "11000"}, {"price": "0.97", "size": "21800"}, {"price": "0.96", "size": "3006.73"}, {"price": "0.95", "size": "2300"}, {"price": "0.94", "size": "1600"}, {"price": "0.93", "size": "1000"}, {"price": "0.92", "size": "1000"}, {"price": "0.91", "size": "1600"}, {"price": "0.9", "size": "340"}, {"price": "0.89", "size": "7105.29"}, {"price": "0.88", "size": "300"}, {"price": "0.87", "size": "846.15"}, {"price": "0.86", "size": "350"}, {"price": "0.85", "size": "1416"}, {"price": "0.84", "size": "475"}, {"price": "0.82", "size": "200"}, {"price": "0.81", "size": "2346.84"}, {"price": "0.8", "size": "2500"}, {"price": "0.79", "size": "200"}, {"price": "0.78", "size": "109.09"}, {"price": "0.77", "size": "200"}, {"price": "0.76", "size": "200"}, {"price": "0.75", "size": "3348"}, {"price": "0.74", "size": "276.92"}, {"price": "0.73", "size": "250"}, {"price": "0.72", "size": "250"}, {"price": "0.71", "size": "200"}, {"price": "0.7", "size": "300"}, {"price": "0.69", "size": "200"}, {"price": "0.68", "size": "200"}, {"price": "0.67", "size": "200"}, {"price": "0.63", "size": "1000"}, {"price": "0.62", "size": "200"}, {"price": "0.6", "size": "1574"}, {"price": "0.59", "size": "200"}, {"price": "0.58", "size": "150"}, {"price": "0.57", "size": "200"}, {"price": "0.56", "size": "200"}, {"price": "0.54", "size": "5287"}, {"price": "0.53", "size": "150"}, {"price": "0.52", "size": "200"}, {"price": "0.51", "size": "228.63"}, {"price": "0.5", "size": "5200"}, {"price": "0.48", "size": "3572"}, {"price": "0.47", "size": "2000"}, {"price": "0.46", "size": "1568.04"}, {"price": "0.45", "size": "3050.67"}, {"price": "0.44", "size": "1500"}, {"price": "0.43", "size": "3520.57"}, {"price": "0.42", "size": "875.16"}, {"price": "0.41", "size": "884.44"}, {"price": "0.39", "size": "232.79"}, {"price": "0.38", "size": "287.08"}], "event_type": "book", "last_trade_price": "0.380"}, {"market": "0x50ddb9cd80d5c271664a2ebb7fcaed1d0a148d82c8e8d314d830f75a944c3dcc", "asset_id": "94376205816022955542979635542279932967359915765455578534002478996104754801969", "timestamp": "1769384428702", "hash": "f5fe28a71574dcd77d0166326092913bcfa2e2be", "bids": [{"price": "0.01", "size": "6510.21"}, {"price": "0.02", "size": "1600"}, {"price": "0.03", "size": "10.42"}, {"price": "0.05", "size": "1920"}, {"price": "0.06", "size": "510"}, {"price": "0.07", "size": "485.71"}, {"price": "0.08", "size": "4385"}, {"price": "0.1", "size": "320"}, {"price": "0.11", "size": "5.32"}, {"price": "0.12", "size": "233.33"}, {"price": "0.13", "size": "454"}, {"price": "0.14", "size": "185.71"}, {"price": "0.17", "size": "291.17"}, {"price": "0.18", "size": "11"}, {"price": "0.19", "size": "105.26"}, {"price": "0.25", "size": "144.99"}, {"price": "0.3", "size": "551.26"}, {"price": "0.31", "size": "100"}, {"price": "0.36", "size": "36.11"}, {"price": "0.37", "size": "29.72"}, {"price": "0.38", "size": "100"}, {"price": "0.39", "size": "29"}, {"price": "0.4", "size": "14.1"}, {"price": "0.44", "size": "17"}], "asks": [{"price": "0.99", "size": "1107830.07"}, {"price": "0.98", "size": "11000"}, {"price": "0.97", "size": "61800"}, {"price": "0.96", "size": "23.16"}, {"price": "0.94", "size": "10900"}, {"price": "0.93", "size": "21000"}, {"price": "0.91", "size": "377.77"}, {"price": "0.9", "size": "6.08"}, {"price": "0.88", "size": "816.66"}, {"price": "0.85", "size": "186.66"}, {"price": "0.84", "size": "5450"}, {"price": "0.82", "size": "144.44"}, {"price": "0.81", "size": "3191"}, {"price": "0.8", "size": "1300"}, {"price": "0.79", "size": "214.28"}, {"price": "0.78", "size": "250"}, {"price": "0.77", "size": "100"}, {"price": "0.76", "size": "83.33"}, {"price": "0.71", "size": "649"}, {"price": "0.57", "size": "2457.4"}, {"price": "0.56", "size": "185.16"}, {"price": "0.54", "size": "124.17"}, {"price": "0.52", "size": "5.16"}, {"price": "0.51", "size": "100"}, {"price": "0.49", "size": "60"}, {"price": "0.48", "size": "39.72"}, {"price": "0.47", "size": "5.16"}], "event_type": "book", "last_trade_price": "0.570"}, {"market": "0x7b49b9bacb5f435bc10f3b100ff59e2fdd346f7f92a9001881bc9825a0af0f11", "asset_id": "21695138873211375451055566770107682325494206727818897067665810321709249824909", "timestamp": "1769384385863", "hash": "79260ffc6fcf87e55cbce63e1e5d174480952f69", "bids": [{"price": "0.01", "size": "1117820.61"}, {"price": "0.02", "size": "102800"}, {"price": "0.03", "size": "10.88"}, {"price": "0.04", "size": "10000"}, {"price": "0.05", "size": "31020"}, {"price": "0.06", "size": "250"}, {"price": "0.08", "size": "835.65"}, {"price": "0.1", "size": "5520"}, {"price": "0.11", "size": "305.17"}, {"price": "0.12", "size": "1332"}, {"price": "0.13", "size": "5215.38"}, {"price": "0.15", "size": "16234"}, {"price": "0.16", "size": "3486.5"}, {"price": "0.17", "size": "2845"}, {"price": "0.18", "size": "383.33"}, {"price": "0.19", "size": "250"}, {"price": "0.2", "size": "200"}, {"price": "0.21", "size": "295.23"}, {"price": "0.22", "size": "220.4"}, {"price": "0.23", "size": "400"}, {"price": "0.24", "size": "200"}, {"price": "0.25", "size": "200"}, {"price": "0.28", "size": "200"}, {"price": "0.29", "size": "200"}, {"price": "0.3", "size": "200"}, {"price": "0.31", "size": "200"}, {"price": "0.32", "size": "200"}, {"price": "0.33", "size": "200"}, {"price": "0.34", "size": "200"}, {"price": "0.36", "size": "200"}, {"price": "0.38", "size": "200"}, {"price": "0.39", "size": "200"}, {"price": "0.4", "size": "200"}, {"price": "0.41", "size": "740"}, {"price": "0.42", "size": "400"}, {"price": "0.43", "size": "230.23"}, {"price": "0.44", "size": "478"}, {"price": "0.45", "size": "200"}, {"price": "0.46", "size": "400"}, {"price": "0.47", "size": "783"}, {"price": "0.48", "size": "900"}, {"price": "0.49", "size": "5097.74"}, {"price": "0.5", "size": "19135.95"}, {"price": "0.51", "size": "812.15"}], "asks": [{"price": "0.99", "size": "27805.31"}, {"price": "0.98", "size": "1605.03"}, {"price": "0.97", "size": "250"}, {"price": "0.96", "size": "7.07"}, {"price": "0.95", "size": "1920"}, {"price": "0.93", "size": "1485.71"}, {"price": "0.9", "size": "820"}, {"price": "0.89", "size": "1459.12"}, {"price": "0.88", "size": "233.33"}, {"price": "0.87", "size": "3230"}, {"price": "0.85", "size": "3223.33"}, {"price": "0.83", "size": "141.17"}, {"price": "0.82", "size": "200"}, {"price": "0.81", "size": "3164"}, {"price": "0.8", "size": "1100"}, {"price": "0.79", "size": "700"}, {"price": "0.78", "size": "350"}, {"price": "0.77", "size": "350"}, {"price": "0.75", "size": "200"}, {"price": "0.74", "size": "300"}, {"price": "0.73", "size": "376.87"}, {"price": "0.72", "size": "300"}, {"price": "0.71", "size": "300"}, {"price": "0.7", "size": "300"}, {"price": "0.66", "size": "38.23"}, {"price": "0.6", "size": "10000"}, {"price": "0.59", "size": "1449.82"}, {"price": "0.53", "size": "2020.49"}, {"price": "0.52", "size": "6852.27"}], "event_type": "book", "last_trade_price": "0.490"}, {"market": "0x32b09f6390252b37d674501527e709016d55581b2c1e544bd4b8167f5f732f4c", "asset_id": "92388629082681805622801622703528982922543286352927708208755887536971583436902", "timestamp": "1769384424995", "hash": "d85aa0fb622502966b957cc0a0ebae0356bb6f19", "bids": [{"price": "0.01", "size": "807815.26"}, {"price": "0.02", "size": "51000"}, {"price": "0.03", "size": "101800"}, {"price": "0.04", "size": "50006.96"}, {"price": "0.05", "size": "970"}, {"price": "0.06", "size": "50300"}, {"price": "0.08", "size": "425"}, {"price": "0.09", "size": "50600"}, {"price": "0.1", "size": "320"}, {"price": "0.11", "size": "50005.17"}, {"price": "0.12", "size": "1374"}, {"price": "0.13", "size": "215.38"}, {"price": "0.15", "size": "50723.33"}, {"price": "0.16", "size": "52624"}, {"price": "0.17", "size": "90450"}, {"price": "0.18", "size": "533.33"}, {"price": "0.2", "size": "1100"}, {"price": "0.25", "size": "10200"}, {"price": "0.28", "size": "8000"}, {"price": "0.31", "size": "20000"}, {"price": "0.32", "size": "10200"}, {"price": "0.33", "size": "200"}, {"price": "0.34", "size": "10200"}, {"price": "0.35", "size": "200"}, {"price": "0.36", "size": "200"}, {"price": "0.37", "size": "200"}, {"price": "0.4", "size": "2175"}, {"price": "0.42", "size": "155.06"}, {"price": "0.43", "size": "230.23"}, {"price": "0.44", "size": "10230"}, {"price": "0.45", "size": "67"}, {"price": "0.46", "size": "145.06"}, {"price": "0.47", "size": "500"}, {"price": "0.48", "size": "20040"}, {"price": "0.49", "size": "88705.41"}, {"price": "0.5", "size": "140426.91"}, {"price": "0.51", "size": "243876.65"}], "asks": [{"price": "0.99", "size": "1161333.78"}, {"price": "0.98", "size": "1194991.04"}, {"price": "0.97", "size": "34026.66"}, {"price": "0.96", "size": "257.07"}, {"price": "0.95", "size": "740"}, {"price": "0.94", "size": "9718.56"}, {"price": "0.92", "size": "525"}, {"price": "0.9", "size": "1272.27"}, {"price": "0.89", "size": "1481.83"}, {"price": "0.88", "size": "233.33"}, {"price": "0.87", "size": "3230"}, {"price": "0.86", "size": "137.5"}, {"price": "0.85", "size": "101204.3"}, {"price": "0.83", "size": "141.17"}, {"price": "0.82", "size": "50000"}, {"price": "0.81", "size": "100400"}, {"price": "0.8", "size": "1565.64"}, {"price": "0.79", "size": "2781"}, {"price": "0.78", "size": "415.38"}, {"price": "0.75", "size": "200"}, {"price": "0.7", "size": "10"}, {"price": "0.67", "size": "5200"}, {"price": "0.66", "size": "1671"}, {"price": "0.65", "size": "209.62"}, {"price": "0.64", "size": "200"}, {"price": "0.63", "size": "300"}, {"price": "0.62", "size": "422"}, {"price": "0.61", "size": "1185"}, {"price": "0.6", "size": "232.5"}, {"price": "0.59", "size": "226.82"}, {"price": "0.58", "size": "750"}, {"price": "0.57", "size": "5300"}, {"price": "0.56", "size": "564"}, {"price": "0.55", "size": "5747.35"}, {"price": "0.54", "size": "42741.55"}, {"price": "0.53", "size": "27392.16"}, {"price": "0.52", "size": "97629.14"}], "event_type": "book", "last_trade_price": "0.520"}, {"market": "0x1fad72fae204143ff1c3035e99e7c0f65ea8d5cd9bd1070987bd1a3316f772be", "asset_id": "98022490269692409998126496127597032490334070080325855126491859374983463996227", "timestamp": "1769384429002", "hash": "96c1b496b1105aef4251fd82b9ee85f7b1876761", "bids": [{"price": "0.01", "size": "1117814.94"}, {"price": "0.02", "size": "62800"}, {"price": "0.03", "size": "30000"}, {"price": "0.04", "size": "255.1"}, {"price": "0.06", "size": "1600"}, {"price": "0.08", "size": "525"}, {"price": "0.09", "size": "7.18"}, {"price": "0.11", "size": "290.9"}, {"price": "0.12", "size": "1332"}, {"price": "0.14", "size": "200"}, {"price": "0.15", "size": "6600"}, {"price": "0.16", "size": "3024"}, {"price": "0.17", "size": "152.94"}, {"price": "0.2", "size": "120"}, {"price": "0.22", "size": "5090.9"}, {"price": "0.24", "size": "9300"}, {"price": "0.25", "size": "3131"}, {"price": "0.26", "size": "2224"}, {"price": "0.27", "size": "300"}, {"price": "0.28", "size": "300"}, {"price": "0.31", "size": "450"}, {"price": "0.32", "size": "1813"}, {"price": "0.33", "size": "200"}, {"price": "0.34", "size": "200"}, {"price": "0.35", "size": "200"}, {"price": "0.36", "size": "200"}, {"price": "0.37", "size": "200"}, {"price": "0.38", "size": "200"}, {"price": "0.4", "size": "855"}, {"price": "0.48", "size": "27.08"}, {"price": "0.49", "size": "5247.44"}, {"price": "0.5", "size": "8530.49"}, {"price": "0.51", "size": "132"}, {"price": "0.53", "size": "414.93"}, {"price": "0.54", "size": "233"}, {"price": "0.55", "size": "79.81"}], "asks": [{"price": "0.99", "size": "7524.87"}, {"price": "0.98", "size": "1000"}, {"price": "0.97", "size": "10.26"}, {"price": "0.96", "size": "2700"}, {"price": "0.95", "size": "300"}, {"price": "0.93", "size": "985.71"}, {"price": "0.91", "size": "355.55"}, {"price": "0.9", "size": "5426"}, {"price": "0.89", "size": "259.93"}, {"price": "0.88", "size": "4050"}, {"price": "0.87", "size": "250"}, {"price": "0.86", "size": "185.71"}, {"price": "0.84", "size": "150"}, {"price": "0.82", "size": "111.11"}, {"price": "0.8", "size": "360"}, {"price": "0.77", "size": "400"}, {"price": "0.72", "size": "1000"}, {"price": "0.67", "size": "1000"}, {"price": "0.66", "size": "300"}, {"price": "0.65", "size": "237.13"}, {"price": "0.64", "size": "30.55"}, {"price": "0.6", "size": "215"}, {"price": "0.59", "size": "120"}, {"price": "0.58", "size": "403.88"}], "event_type": "book", "last_trade_price": "0.570"}, {"market": "0x0ea8005efbc460378340a2f28a6d97b0d1d9d9d7fba4d16f529b8a415dca77a2", "asset_id": "71552623345730992280501476931299615437386807576519105089437764117985071980606", "timestamp": "1769384429537", "hash": "fcc377f450d97861529481b7d19e3546130d2973", "bids": [{"price": "0.01", "size": "1109839.79"}, {"price": "0.02", "size": "11000"}, {"price": "0.03", "size": "31800"}, {"price": "0.04", "size": "6.72"}, {"price": "0.06", "size": "1600"}, {"price": "0.07", "size": "300"}, {"price": "0.1", "size": "340"}, {"price": "0.11", "size": "9605.29"}, {"price": "0.13", "size": "496.15"}, {"price": "0.14", "size": "1142"}, {"price": "0.16", "size": "175"}, {"price": "0.19", "size": "2210"}, {"price": "0.2", "size": "580"}, {"price": "0.21", "size": "2381"}, {"price": "0.23", "size": "204.34"}, {"price": "0.26", "size": "76.92"}, {"price": "0.28", "size": "5150"}, {"price": "0.29", "size": "1397"}, {"price": "0.44", "size": "300"}, {"price": "0.45", "size": "2750"}, {"price": "0.46", "size": "2200"}, {"price": "0.47", "size": "200"}, {"price": "0.48", "size": "392"}, {"price": "0.5", "size": "5671.67"}, {"price": "0.52", "size": "1181"}, {"price": "0.53", "size": "113.52"}, {"price": "0.54", "size": "20.37"}, {"price": "0.58", "size": "170"}, {"price": "0.59", "size": "381.32"}, {"price": "0.6", "size": "144.85"}, {"price": "0.61", "size": "4.32"}], "asks": [{"price": "0.99", "size": "7500"}, {"price": "0.98", "size": "3805.79"}, {"price": "0.97", "size": "250"}, {"price": "0.96", "size": "906.08"}, {"price": "0.94", "size": "1866.66"}, {"price": "0.92", "size": "400"}, {"price": "0.91", "size": "7.11"}, {"price": "0.9", "size": "280"}, {"price": "0.89", "size": "151.37"}, {"price": "0.88", "size": "3941.66"}, {"price": "0.86", "size": "186.57"}, {"price": "0.84", "size": "275"}, {"price": "0.8", "size": "5"}, {"price": "0.75", "size": "472.19"}, {"price": "0.74", "size": "9900"}, {"price": "0.73", "size": "9500"}, {"price": "0.72", "size": "10000"}, {"price": "0.71", "size": "9266.82"}, {"price": "0.7", "size": "8036.66"}, {"price": "0.69", "size": "20"}, {"price": "0.68", "size": "211.37"}, {"price": "0.67", "size": "31.51"}, {"price": "0.66", "size": "20.1"}, {"price": "0.64", "size": "220"}, {"price": "0.63", "size": "890.4"}], "event_type": "book", "last_trade_price": "0.630"}, {"market": "0x84f8b70331323c2fba97d7ceaa9a35fb645a0770d0dbff169d07f24f376766e9", "asset_id": "108999723207897941876452935557011604067917389120996960199512481363958770540884", "timestamp": "1769384364159", "hash": "762b673ef0ab9bd5829609c07065c3421ee43cf3", "bids": [{"price": "0.01", "size": "1107815.18"}, {"price": "0.02", "size": "26000"}, {"price": "0.03", "size": "61800"}, {"price": "0.04", "size": "256.92"}, {"price": "0.05", "size": "1020"}, {"price": "0.08", "size": "845.03"}, {"price": "0.09", "size": "6.75"}, {"price": "0.1", "size": "1520"}, {"price": "0.11", "size": "5.19"}, {"price": "0.12", "size": "3570.4"}, {"price": "0.13", "size": "1445.38"}, {"price": "0.15", "size": "173.33"}, {"price": "0.16", "size": "6199"}, {"price": "0.17", "size": "3000"}, {"price": "0.18", "size": "2522.33"}, {"price": "0.2", "size": "100"}, {"price": "0.21", "size": "270.34"}, {"price": "0.36", "size": "200"}, {"price": "0.39", "size": "20.34"}, {"price": "0.4", "size": "738"}, {"price": "0.41", "size": "2200"}, {"price": "0.42", "size": "200"}, {"price": "0.43", "size": "482.23"}, {"price": "0.44", "size": "25"}, {"price": "0.45", "size": "200"}, {"price": "0.46", "size": "318"}, {"price": "0.47", "size": "200"}, {"price": "0.48", "size": "200"}, {"price": "0.49", "size": "2091"}, {"price": "0.5", "size": "17169.79"}, {"price": "0.51", "size": "10149.74"}], "asks": [{"price": "0.99", "size": "9510.39"}, {"price": "0.98", "size": "1600"}, {"price": "0.97", "size": "11.08"}, {"price": "0.95", "size": "1920"}, {"price": "0.92", "size": "425"}, {"price": "0.91", "size": "4171"}, {"price": "0.9", "size": "320"}, {"price": "0.89", "size": "1459.12"}, {"price": "0.88", "size": "733.33"}, {"price": "0.87", "size": "3830"}, {"price": "0.85", "size": "261.35"}, {"price": "0.83", "size": "141.17"}, {"price": "0.81", "size": "514.69"}, {"price": "0.8", "size": "222.31"}, {"price": "0.79", "size": "650"}, {"price": "0.78", "size": "150"}, {"price": "0.77", "size": "212.69"}, {"price": "0.76", "size": "8"}, {"price": "0.73", "size": "98"}, {"price": "0.72", "size": "16.92"}, {"price": "0.66", "size": "125.18"}, {"price": "0.65", "size": "84.01"}, {"price": "0.63", "size": "44"}, {"price": "0.62", "size": "34.21"}, {"price": "0.61", "size": "28.2"}, {"price": "0.59", "size": "55.02"}, {"price": "0.56", "size": "12.69"}, {"price": "0.55", "size": "200"}, {"price": "0.54", "size": "222"}, {"price": "0.53", "size": "163.23"}], "event_type": "book", "last_trade_price": "0.510"}, {"market": "0xbb57ccf5853a85487bc3d83d04d669310d28c6c810758953b9d9b91d1aee89d2", "asset_id": "105267568073659068217311993901927962476298440625043565106676088842803600775810", "timestamp": "1769384411618", "hash": "e477f48d7f3575cb4fd0052ba56454febcf88d90", "bids": [{"price": "0.01", "size": "1027815.31"}, {"price": "0.02", "size": "102805.03"}, {"price": "0.03", "size": "250"}, {"price": "0.04", "size": "7.07"}, {"price": "0.05", "size": "300"}, {"price": "0.07", "size": "1000"}, {"price": "0.09", "size": "6.25"}, {"price": "0.1", "size": "128.84"}, {"price": "0.11", "size": "1459.12"}, {"price": "0.12", "size": "275"}, {"price": "0.13", "size": "3230"}, {"price": "0.14", "size": "3572"}, {"price": "0.15", "size": "325"}, {"price": "0.16", "size": "400"}, {"price": "0.21", "size": "115"}, {"price": "0.25", "size": "5"}, {"price": "0.26", "size": "20000"}, {"price": "0.27", "size": "1852"}, {"price": "0.36", "size": "200"}, {"price": "0.37", "size": "200"}, {"price": "0.38", "size": "34.21"}, {"price": "0.4", "size": "200"}, {"price": "0.41", "size": "902.82"}, {"price": "0.42", "size": "200"}, {"price": "0.43", "size": "619"}, {"price": "0.44", "size": "2100"}, {"price": "0.45", "size": "14600"}, {"price": "0.46", "size": "361.53"}, {"price": "0.47", "size": "3549.61"}, {"price": "0.48", "size": "137505.39"}], "asks": [{"price": "0.99", "size": "1107820.24"}, {"price": "0.98", "size": "21000"}, {"price": "0.97", "size": "91800"}, {"price": "0.96", "size": "10005.2"}, {"price": "0.95", "size": "10300"}, {"price": "0.94", "size": "250"}, {"price": "0.91", "size": "2376"}, {"price": "0.9", "size": "11.39"}, {"price": "0.87", "size": "38"}, {"price": "0.85", "size": "3050"}, {"price": "0.84", "size": "2624"}, {"price": "0.81", "size": "5000"}, {"price": "0.8", "size": "10500"}, {"price": "0.79", "size": "1200"}, {"price": "0.74", "size": "500"}, {"price": "0.6", "size": "20"}, {"price": "0.59", "size": "2000"}, {"price": "0.58", "size": "1000"}, {"price": "0.57", "size": "30.23"}, {"price": "0.56", "size": "25"}, {"price": "0.51", "size": "321.16"}, {"price": "0.5", "size": "132677.52"}, {"price": "0.49", "size": "86805.58"}], "event_type": "book", "last_trade_price": "0.490"}, {"market": "0xc829edf5ca6961e441c266546064b629c29a9313694689c0768db92810db62ff", "asset_id": "40694415003591202786878279287884766002429923551809555441858630935269489320071", "timestamp": "1769384408847", "hash": "b7e8b389d21806c5d5c8970a981574cda10dc235", "bids": [{"price": "0.01", "size": "1107864.79"}, {"price": "0.02", "size": "62800"}, {"price": "0.03", "size": "9.14"}, {"price": "0.05", "size": "330"}, {"price": "0.06", "size": "33"}, {"price": "0.08", "size": "10450"}, {"price": "0.09", "size": "20600"}, {"price": "0.1", "size": "6.27"}, {"price": "0.12", "size": "550"}, {"price": "0.13", "size": "261.53"}, {"price": "0.17", "size": "5638.23"}, {"price": "0.18", "size": "888"}, {"price": "0.21", "size": "133.33"}, {"price": "0.24", "size": "300"}, {"price": "0.25", "size": "1784"}, {"price": "0.28", "size": "1100"}, {"price": "0.29", "size": "111.32"}, {"price": "0.3", "size": "41"}, {"price": "0.34", "size": "183.82"}, {"price": "0.71", "size": "68.71"}, {"price": "0.73", "size": "17.8"}, {"price": "0.75", "size": "14.66"}, {"price": "0.76", "size": "10"}, {"price": "0.8", "size": "400"}, {"price": "0.81", "size": "353.89"}, {"price": "0.82", "size": "254.95"}], "asks": [{"price": "0.99", "size": "33557.36"}, {"price": "0.98", "size": "250"}, {"price": "0.97", "size": "14.31"}, {"price": "0.96", "size": "12"}, {"price": "0.94", "size": "11"}, {"price": "0.93", "size": "157.14"}, {"price": "0.92", "size": "2174.95"}, {"price": "0.91", "size": "934"}, {"price": "0.9", "size": "131.65"}, {"price": "0.89", "size": "30.8"}, {"price": "0.88", "size": "200"}, {"price": "0.87", "size": "421"}, {"price": "0.86", "size": "130"}, {"price": "0.85", "size": "169.88"}, {"price": "0.84", "size": "15.1"}], "event_type": "book", "last_trade_price": "0.160"}, {"market": "0x32b09f6390252b37d674501527e709016d55581b2c1e544bd4b8167f5f732f4c", "asset_id": "90435811253665578014957380826505992530054077692143838383981805324273750424057", "timestamp": "1769384424995", "hash": "5938efa488579c3ed94f1498ea19d6b478f269ce", "bids": [{"price": "0.01", "size": "1161333.78"}, {"price": "0.02", "size": "1194991.04"}, {"price": "0.03", "size": "34026.66"}, {"price": "0.04", "size": "257.07"}, {"price": "0.05", "size": "740"}, {"price": "0.06", "size": "9718.56"}, {"price": "0.08", "size": "525"}, {"price": "0.1", "size": "1272.27"}, {"price": "0.11", "size": "1481.83"}, {"price": "0.12", "size": "233.33"}, {"price": "0.13", "size": "3230"}, {"price": "0.14", "size": "137.5"}, {"price": "0.15", "size": "101204.3"}, {"price": "0.17", "size": "141.17"}, {"price": "0.18", "size": "50000"}, {"price": "0.19", "size": "100400"}, {"price": "0.2", "size": "1565.64"}, {"price": "0.21", "size": "2781"}, {"price": "0.22", "size": "415.38"}, {"price": "0.25", "size": "200"}, {"price": "0.3", "size": "10"}, {"price": "0.33", "size": "5200"}, {"price": "0.34", "size": "1671"}, {"price": "0.35", "size": "209.62"}, {"price": "0.36", "size": "200"}, {"price": "0.37", "size": "300"}, {"price": "0.38", "size": "422"}, {"price": "0.39", "size": "1185"}, {"price": "0.4", "size": "232.5"}, {"price": "0.41", "size": "226.82"}, {"price": "0.42", "size": "750"}, {"price": "0.43", "size": "5300"}, {"price": "0.44", "size": "564"}, {"price": "0.45", "size": "5747.35"}, {"price": "0.46", "size": "42741.55"}, {"price": "0.47", "size": "27392.16"}, {"price": "0.48", "size": "97629.14"}], "asks": [{"price": "0.99", "size": "807815.26"}, {"price": "0.98", "size": "51000"}, {"price": "0.97", "size": "101800"}, {"price": "0.96", "size": "50006.96"}, {"price": "0.95", "size": "970"}, {"price": "0.94", "size": "50300"}, {"price": "0.92", "size": "425"}, {"price": "0.91", "size": "50600"}, {"price": "0.9", "size": "320"}, {"price": "0.89", "size": "50005.17"}, {"price": "0.88", "size": "1374"}, {"price": "0.87", "size": "215.38"}, {"price": "0.85", "size": "50723.33"}, {"price": "0.84", "size": "52624"}, {"price": "0.83", "size": "90450"}, {"price": "0.82", "size": "533.33"}, {"price": "0.8", "size": "1100"}, {"price": "0.75", "size": "10200"}, {"price": "0.72", "size": "8000"}, {"price": "0.69", "size": "20000"}, {"price": "0.68", "size": "10200"}, {"price": "0.67", "size": "200"}, {"price": "0.66", "size": "10200"}, {"price": "0.65", "size": "200"}, {"price": "0.64", "size": "200"}, {"price": "0.63", "size": "200"}, {"price": "0.6", "size": "2175"}, {"price": "0.58", "size": "155.06"}, {"price": "0.57", "size": "230.23"}, {"price": "0.56", "size": "10230"}, {"price": "0.55", "size": "67"}, {"price": "0.54", "size": "145.06"}, {"price": "0.53", "size": "500"}, {"price": "0.52", "size": "20040"}, {"price": "0.51", "size": "88705.41"}, {"price": "0.5", "size": "140426.91"}, {"price": "0.49", "size": "243876.65"}], "event_type": "book", "last_trade_price": "0.520"}, {"market": "0x9c1a953fe92c8357f1b646ba25d983aa83e90c525992db14fb726fa895cb5763", "asset_id": "8501497159083948713316135768103773293754490207922884688769443031624417212426", "timestamp": "1769384417514", "hash": "eb412fdb29c19a3038e27767ad3166bf0a341c5a", "bids": [{"price": "0.01", "size": "1027814.81"}, {"price": "0.02", "size": "11000"}, {"price": "0.03", "size": "21800"}, {"price": "0.04", "size": "3006.73"}, {"price": "0.05", "size": "2300"}, {"price": "0.06", "size": "1600"}, {"price": "0.07", "size": "1000"}, {"price": "0.08", "size": "1000"}, {"price": "0.09", "size": "1600"}, {"price": "0.1", "size": "340"}, {"price": "0.11", "size": "7105.29"}, {"price": "0.12", "size": "300"}, {"price": "0.13", "size": "846.15"}, {"price": "0.14", "size": "350"}, {"price": "0.15", "size": "1416"}, {"price": "0.16", "size": "475"}, {"price": "0.18", "size": "200"}, {"price": "0.19", "size": "2346.84"}, {"price": "0.2", "size": "2500"}, {"price": "0.21", "size": "200"}, {"price": "0.22", "size": "109.09"}, {"price": "0.23", "size": "200"}, {"price": "0.24", "size": "200"}, {"price": "0.25", "size": "3348"}, {"price": "0.26", "size": "276.92"}, {"price": "0.27", "size": "250"}, {"price": "0.28", "size": "250"}, {"price": "0.29", "size": "200"}, {"price": "0.3", "size": "300"}, {"price": "0.31", "size": "200"}, {"price": "0.32", "size": "200"}, {"price": "0.33", "size": "200"}, {"price": "0.37", "size": "1000"}, {"price": "0.38", "size": "200"}, {"price": "0.4", "size": "1574"}, {"price": "0.41", "size": "200"}, {"price": "0.42", "size": "150"}, {"price": "0.43", "size": "200"}, {"price": "0.44", "size": "200"}, {"price": "0.46", "size": "5287"}, {"price": "0.47", "size": "150"}, {"price": "0.48", "size": "200"}, {"price": "0.49", "size": "228.63"}, {"price": "0.5", "size": "5200"}, {"price": "0.52", "size": "3572"}, {"price": "0.53", "size": "2000"}, {"price": "0.54", "size": "1568.04"}, {"price": "0.55", "size": "3050.67"}, {"price": "0.56", "size": "1500"}, {"price": "0.57", "size": "3520.57"}, {"price": "0.58", "size": "875.16"}, {"price": "0.59", "size": "884.44"}, {"price": "0.61", "size": "232.79"}, {"price": "0.62", "size": "287.08"}], "asks": [{"price": "0.99", "size": "317800"}, {"price": "0.98", "size": "1255.86"}, {"price": "0.97", "size": "50"}, {"price": "0.96", "size": "2707.21"}, {"price": "0.94", "size": "866.66"}, {"price": "0.92", "size": "400"}, {"price": "0.91", "size": "3366"}, {"price": "0.9", "size": "285.94"}, {"price": "0.89", "size": "4368"}, {"price": "0.88", "size": "8.93"}, {"price": "0.87", "size": "200"}, {"price": "0.85", "size": "160"}, {"price": "0.83", "size": "117.64"}, {"price": "0.81", "size": "2000"}, {"price": "0.72", "size": "70000"}, {"price": "0.71", "size": "6590.96"}, {"price": "0.7", "size": "1016.08"}, {"price": "0.69", "size": "1666.58"}, {"price": "0.68", "size": "3174.82"}, {"price": "0.66", "size": "550"}, {"price": "0.65", "size": "758.56"}, {"price": "0.64", "size": "453.23"}, {"price": "0.63", "size": "75.58"}], "event_type": "book", "last_trade_price": "0.380"}, {"market": "0xc829edf5ca6961e441c266546064b629c29a9313694689c0768db92810db62ff", "asset_id": "31737648224640860538361785861700072557227859645060732743904381890720199497279", "timestamp": "1769384408847", "hash": "0ea816c4fc38514f73c439a35e8d3c7d87d58287", "bids": [{"price": "0.01", "size": "33557.36"}, {"price": "0.02", "size": "250"}, {"price": "0.03", "size": "14.31"}, {"price": "0.04", "size": "12"}, {"price": "0.06", "size": "11"}, {"price": "0.07", "size": "157.14"}, {"price": "0.08", "size": "2174.95"}, {"price": "0.09", "size": "934"}, {"price": "0.1", "size": "131.65"}, {"price": "0.11", "size": "30.8"}, {"price": "0.12", "size": "200"}, {"price": "0.13", "size": "421"}, {"price": "0.14", "size": "130"}, {"price": "0.15", "size": "169.88"}, {"price": "0.16", "size": "15.1"}], "asks": [{"price": "0.99", "size": "1107864.79"}, {"price": "0.98", "size": "62800"}, {"price": "0.97", "size": "9.14"}, {"price": "0.95", "size": "330"}, {"price": "0.94", "size": "33"}, {"price": "0.92", "size": "10450"}, {"price": "0.91", "size": "20600"}, {"price": "0.9", "size": "6.27"}, {"price": "0.88", "size": "550"}, {"price": "0.87", "size": "261.53"}, {"price": "0.83", "size": "5638.23"}, {"price": "0.82", "size": "888"}, {"price": "0.79", "size": "133.33"}, {"price": "0.76", "size": "300"}, {"price": "0.75", "size": "1784"}, {"price": "0.72", "size": "1100"}, {"price": "0.71", "size": "111.32"}, {"price": "0.7", "size": "41"}, {"price": "0.66", "size": "183.82"}, {"price": "0.29", "size": "68.71"}, {"price": "0.27", "size": "17.8"}, {"price": "0.25", "size": "14.66"}, {"price": "0.24", "size": "10"}, {"price": "0.2", "size": "400"}, {"price": "0.19", "size": "353.89"}, {"price": "0.18", "size": "254.95"}], "event_type": "book", "last_trade_price": "0.160"}]}
{"_local_timestamp": "2026-01-25T23:40:30.573121+00:00", "data": {"market": "0x50ddb9cd80d5c271664a2ebb7fcaed1d0a148d82c8e8d314d830f75a944c3dcc", "price_changes": [{"asset_id": "88275040060084773376557187972215267513049848642895776801789297917961077894224", "price": "0.51", "size": "30", "side": "BUY", "hash": "35d012d745f68ecfd8e9bfd7de0b4b0c5589dbdc", "best_bid": "0.53", "best_ask": "0.56"}, {"asset_id": "94376205816022955542979635542279932967359915765455578534002478996104754801969", "price": "0.49", "size": "30", "side": "SELL", "hash": "5ba4588d3b42c5a76523f465251653c5aed653e0", "best_bid": "0.44", "best_ask": "0.47"}], "timestamp": "1769384430501", "event_type": "price_change"}}
{"_local_timestamp": "2026-01-25T23:40:30.718502+00:00", "data": {"market": "0x50ddb9cd80d5c271664a2ebb7fcaed1d0a148d82c8e8d314d830f75a944c3dcc", "price_changes": [{"asset_id": "88275040060084773376557187972215267513049848642895776801789297917961077894224", "price": "0.49", "size": "130", "side": "BUY", "hash": "77bdd10c993dc252d8fd52dfd5aa473c082245bb", "best_bid": "0.53", "best_ask": "0.56"}, {"asset_id": "94376205816022955542979635542279932967359915765455578534002478996104754801969", "price": "0.51", "size": "130", "side": "SELL", "hash": "a1586e001a8b5937541cc077a6fb636e73064337", "best_bid": "0.44", "best_ask": "0.47"}], "timestamp": "1769384430644", "event_type": "price_change"}}
{"_local_timestamp": "2026-01-25T23:40:31.095996+00:00", "data": {"market": "0xbb57ccf5853a85487bc3d83d04d669310d28c6c810758953b9d9b91d1aee89d2", "price_changes": [{"asset_id": "105267568073659068217311993901927962476298440625043565106676088842803600775810", "price": "0.27", "size": "0", "side": "BUY", "hash": "a878928a9ad2a082e6c02eac6fe3eedd04bd0370", "best_bid": "0.48", "best_ask": "0.49"}, {"asset_id": "91863162118308663069733924043159186005106558783397508844234610341221325526200", "price": "0.73", "size": "0", "side": "SELL", "hash": "e8e9fabd5cdcb839e2d8b14d1896957d1e576ac1", "best_bid": "0.51", "best_ask": "0.52"}], "timestamp": "1769384431004", "event_type": "price_change"}}
{"_local_timestamp": "2026-01-25T23:40:31.506977+00:00", "data": {"market": "0x50ddb9cd80d5c271664a2ebb7fcaed1d0a148d82c8e8d314d830f75a944c3dcc", "price_changes": [{"asset_id": "88275040060084773376557187972215267513049848642895776801789297917961077894224", "price": "0.52", "size": "18", "side": "BUY", "hash": "bb7a13eb4fb8743cec87fcd74327c2a123035a2e", "best_bid": "0.53", "best_ask": "0.56"}, {"asset_id": "94376205816022955542979635542279932967359915765455578534002478996104754801969", "price": "0.48", "size": "18", "side": "SELL", "hash": "9776f2a3b20e8928ea20a60b77fe4b2b19ced733", "best_bid": "0.44", "best_ask": "0.47"}], "timestamp": "1769384431431", "event_type": "price_change"}}
{"_local_timestamp": "2026-01-25T23:40:31.689001+00:00", "data": {"market": "0x0ea8005efbc460378340a2f28a6d97b0d1d9d9d7fba4d16f529b8a415dca77a2", "price_changes": [{"asset_id": "71552623345730992280501476931299615437386807576519105089437764117985071980606", "price": "0.23", "size": "104.34", "side": "BUY", "hash": "1eaeede661c1f719e41fb719f6601807dafbebd4", "best_bid": "0.61", "best_ask": "0.63"}, {"asset_id": "48266425622404486484896353767723266081505997963592758694068789352158715350186", "price": "0.77", "size": "104.34", "side": "SELL", "hash": "4976b7b23fa60358b830d54d76b083c3f50c8caa", "best_bid": "0.37", "best_ask": "0.39"}], "timestamp": "1769384431616", "event_type": "price_change"}}
{"_local_timestamp": "2026-01-25T23:40:31.693278+00:00", "data": {"market": "0x7b49b9bacb5f435bc10f3b100ff59e2fdd346f7f92a9001881bc9825a0af0f11", "price_changes": [{"asset_id": "17516427576383382756368467656206258206490015951115433065318503962238754362428", "price": "0.2", "size": "950", "side": "BUY", "hash": "bf263f31ceee7f5ef766542934932e2ef055d17b", "best_bid": "0.48", "best_ask": "0.49"}, {"asset_id": "21695138873211375451055566770107682325494206727818897067665810321709249824909", "price": "0.8", "size": "950", "side": "SELL", "hash": "48a69b6250b2952a50f97cc257d518fef685ae5b", "best_bid": "0.51", "best_ask": "0.52"}], "timestamp": "1769384431616", "event_type": "price_change"}}
{"_local_timestamp": "2026-01-25T23:40:31.695464+00:00", "data": {"market": "0x0ea8005efbc460378340a2f28a6d97b0d1d9d9d7fba4d16f529b8a415dca77a2", "price_changes": [{"asset_id": "71552623345730992280501476931299615437386807576519105089437764117985071980606", "price": "0.2", "size": "430", "side": "BUY", "hash": "1eaeede661c1f719e41fb719f6601807dafbebd4", "best_bid": "0.61", "best_ask": "0.63"}, {"asset_id": "48266425622404486484896353767723266081505997963592758694068789352158715350186", "price": "0.8", "size": "430", "side": "SELL", "hash": "4976b7b23fa60358b830d54d76b083c3f50c8caa", "best_bid": "0.37", "best_ask": "0.39"}], "timestamp": "1769384431616", "event_type": "price_change"}}
{"_local_timestamp": "2026-01-25T23:40:31.697650+00:00", "data": {"market": "0xbb57ccf5853a85487bc3d83d04d669310d28c6c810758953b9d9b91d1aee89d2", "price_changes": [{"asset_id": "105267568073659068217311993901927962476298440625043565106676088842803600775810", "price": "0.12", "size": "50", "side": "BUY", "hash": "071de806e96d014d2ab78570f8853d34c1a84f33", "best_bid": "0.48", "best_ask": "0.49"}, {"asset_id": "91863162118308663069733924043159186005106558783397508844234610341221325526200", "price": "0.88", "size": "50", "side": "SELL", "hash": "1e66f9774bea72b8dc3376f823548282693ebef3", "best_bid": "0.51", "best_ask": "0.52"}], "timestamp": "1769384431616", "event_type": "price_change"}}
{"_local_timestamp": "2026-01-25T23:40:31.699813+00:00", "data": {"market": "0x32b09f6390252b37d674501527e709016d55581b2c1e544bd4b8167f5f732f4c", "price_changes": [{"asset_id": "90435811253665578014957380826505992530054077692143838383981805324273750424057", "price": "0.21", "size": "2681", "side": "BUY", "hash": "25c732d5b1db8999ee6ecaa8cf90ce922f309d8c", "best_bid": "0.48", "best_ask": "0.49"}, {"asset_id": "92388629082681805622801622703528982922543286352927708208755887536971583436902", "price": "0.79", "size": "2681", "side": "SELL", "hash": "ba9c7937664276b82d9074c0f7e5bd237d5025b1", "best_bid": "0.51", "best_ask": "0.52"}], "timestamp": "1769384431616", "event_type": "price_change"}}
{"_local_timestamp": "2026-01-25T23:40:31.956014+00:00", "data": {"market": "0x0ea8005efbc460378340a2f28a6d97b0d1d9d9d7fba4d16f529b8a415dca77a2", "price_changes": [{"asset_id": "71552623345730992280501476931299615437386807576519105089437764117985071980606", "price": "0.19", "size": "2360", "side": "BUY", "hash": "82dcd602e8b8a7af568a607965f135fa573072b8", "best_bid": "0.61", "best_ask": "0.63"}, {"asset_id": "48266425622404486484896353767723266081505997963592758694068789352158715350186", "price": "0.81", "size": "2360", "side": "SELL", "hash": "f3f6124a0966637bac51d46c6d7afd6443dde112", "best_bid": "0.37", "best_ask": "0.39"}], "timestamp": "1769384431887", "event_type": "price_change"}}
{"_local_timestamp": "2026-01-25T23:40:31.960414+00:00", "data": {"market": "0x7b49b9bacb5f435bc10f3b100ff59e2fdd346f7f92a9001881bc9825a0af0f11", "price_changes": [{"asset_id": "17516427576383382756368467656206258206490015951115433065318503962238754362428", "price": "0.19", "size": "3314", "side": "BUY", "hash": "a1420501199057047538dba5565a816c0ed302dd", "best_bid": "0.48", "best_ask": "0.49"}, {"asset_id": "21695138873211375451055566770107682325494206727818897067665810321709249824909", "price": "0.81", "size": "3314", "side": "SELL", "hash": "e07b15d0d90c765cd7e38366bd1b963396e02821", "best_bid": "0.51", "best_ask": "0.52"}], "timestamp": "1769384431887", "event_type": "price_change"}}
{"_local_timestamp": "2026-01-25T23:40:31.962603+00:00", "data": {"market": "0xbb57ccf5853a85487bc3d83d04d669310d28c6c810758953b9d9b91d1aee89d2", "price_changes": [{"asset_id": "105267568073659068217311993901927962476298440625043565106676088842803600775810", "price": "0.14", "size": "3797", "side": "BUY", "hash": "b514c22f4a6be4abd89a16e3e3b40249ecdf9b47", "best_bid": "0.48", "best_ask": "0.49"}, {"asset_id": "91863162118308663069733924043159186005106558783397508844234610341221325526200", "price": "0.86", "size": "3797", "side": "SELL", "hash": "aa9b6ca8fad7f625228872a4ca8c74b9bdbffbcf", "best_bid": "0.51", "best_ask": "0.52"}], "timestamp": "1769384431887", "event_type": "price_change"}}
{"_local_timestamp": "2026-01-25T23:40:31.964762+00:00", "data": {"market": "0x32b09f6390252b37d674501527e709016d55581b2c1e544bd4b8167f5f732f4c", "price_changes": [{"asset_id": "90435811253665578014957380826505992530054077692143838383981805324273750424057", "price": "0.23", "size": "100", "side": "BUY", "hash": "69c80e3036e668ad5958e4ef7976e12229b583ed", "best_bid": "0.48", "best_ask": "0.49"}, {"asset_id": "92388629082681805622801622703528982922543286352927708208755887536971583436902", "price": "0.77", "size": "100", "side": "SELL", "hash": "b07177c6740cb93c1a3233a4246087858e87efbd", "best_bid": "0.51", "best_ask": "0.52"}], "timestamp": "1769384431887", "event_type": "price_change"}}
{"_local_timestamp": "2026-01-25T23:40:31.966913+00:00", "data": {"market": "0x0ea8005efbc460378340a2f28a6d97b0d1d9d9d7fba4d16f529b8a415dca77a2", "price_changes": [{"asset_id": "71552623345730992280501476931299615437386807576519105089437764117985071980606", "price": "0.21", "size": "2481", "side": "BUY", "hash": "b4e2d787c7de22b25f4b06eaa1719abc56d2f8d8", "best_bid": "0.61", "best_ask": "0.63"}, {"asset_id": "48266425622404486484896353767723266081505997963592758694068789352158715350186", "price": "0.79", "size": "2481", "side": "SELL", "hash": "b9dddcbe6b951f02109391fdba340ab134074de8", "best_bid": "0.37", "best_ask": "0.39"}], "timestamp": "1769384431889", "event_type": "price_change"}}
{"_local_timestamp": "2026-01-25T23:40:32.226735+00:00", "data": {"market": "0x50ddb9cd80d5c271664a2ebb7fcaed1d0a148d82c8e8d314d830f75a944c3dcc", "price_changes": [{"asset_id": "88275040060084773376557187972215267513049848642895776801789297917961077894224", "price": "0.57", "size": "22.62", "side": "SELL", "hash": "a06fd5e8af062391f7b182cbe090728002ee73e8", "best_bid": "0.53", "best_ask": "0.56"}, {"asset_id": "94376205816022955542979635542279932967359915765455578534002478996104754801969", "price": "0.43", "size": "22.62", "side": "BUY", "hash": "9882625ef38ca095dd88f476f8f6d61d8c6775c5", "best_bid": "0.44", "best_ask": "0.47"}], "timestamp": "1769384432158", "event_type": "price_change"}}
{"_local_timestamp": "2026-01-25T23:40:32.250548+00:00", "data": {"market": "0x50ddb9cd80d5c271664a2ebb7fcaed1d0a148d82c8e8d314d830f75a944c3dcc", "price_changes": [{"asset_id": "88275040060084773376557187972215267513049848642895776801789297917961077894224", "price": "0.61", "size": "0", "side": "SELL", "hash": "972b6e4be30ec9eaf7029286dbe175b6a7236ed5", "best_bid": "0.53", "best_ask": "0.56"}, {"asset_id": "94376205816022955542979635542279932967359915765455578534002478996104754801969", "price": "0.39", "size": "0", "side": "BUY", "hash": "32128a3e1546d244fefe5b56a88bf45bee355149", "best_bid": "0.44", "best_ask": "0.47"}], "timestamp": "1769384432186", "event_type": "price_change"}}
{"_local_timestamp": "2026-01-25T23:40:34.549735+00:00", "data": {"market": "0x0ea8005efbc460378340a2f28a6d97b0d1d9d9d7fba4d16f529b8a415dca77a2", "price_changes": [{"asset_id": "48266425622404486484896353767723266081505997963592758694068789352158715350186", "price": "0.33", "size": "58.31", "side": "BUY", "hash": "fcb5ff24b2167a5187d6d314edbebe7e4b208441", "best_bid": "0.37", "best_ask": "0.39"}, {"asset_id": "71552623345730992280501476931299615437386807576519105089437764117985071980606", "price": "0.67", "size": "58.31", "side": "SELL", "hash": "e8f18d112dbf70244875987998c88c844a321e2d", "best_bid": "0.61", "best_ask": "0.63"}], "timestamp": "1769384434473", "event_type": "price_change"}}
{"_local_timestamp": "2026-01-25T23:40:34.661250+00:00", "data": {"market": "0x0ea8005efbc460378340a2f28a6d97b0d1d9d9d7fba4d16f529b8a415dca77a2", "price_changes": [{"asset_id": "48266425622404486484896353767723266081505997963592758694068789352158715350186", "price": "0.33", "size": "31.51", "side": "BUY", "hash": "f05c904f110aaee8213ded3f855537328cffaa7e", "best_bid": "0.37", "best_ask": "0.39"}, {"asset_id": "71552623345730992280501476931299615437386807576519105089437764117985071980606", "price": "0.67", "size": "31.51", "side": "SELL", "hash": "ba4f8fccb6b293d98f1240d724a3356d283041a5", "best_bid": "0.61", "best_ask": "0.63"}], "timestamp": "1769384434587", "event_type": "price_change"}}
{"_local_timestamp": "2026-01-25T23:40:36.666394+00:00", "data": {"market": "0x9c1a953fe92c8357f1b646ba25d983aa83e90c525992db14fb726fa895cb5763", "price_changes": [{"asset_id": "8501497159083948713316135768103773293754490207922884688769443031624417212426", "price": "0.64", "size": "557.28", "side": "SELL", "hash": "c656f4b9d4f65bae0a7b2f216e622c6fbe0c1f1b", "best_bid": "0.62", "best_ask": "0.63"}, {"asset_id": "2527312495175492857904889758552137141356236738032676480522356889996545113869", "price": "0.36", "size": "557.28", "side": "BUY", "hash": "c66b6f147d1f0c8d65a57597e447e11b1830c9cc", "best_bid": "0.37", "best_ask": "0.38"}], "timestamp": "1769384436601", "event_type": "price_change"}}
{"_local_timestamp": "2026-01-25T23:40:37.334270+00:00", "data": {"market": "0xbb57ccf5853a85487bc3d83d04d669310d28c6c810758953b9d9b91d1aee89d2", "price_changes": [{"asset_id": "91863162118308663069733924043159186005106558783397508844234610341221325526200", "price": "0.5", "size": "132777.52", "side": "BUY", "hash": "885375b2414772339a9e4010008e157ac4e91962", "best_bid": "0.51", "best_ask": "0.52"}, {"asset_id": "105267568073659068217311993901927962476298440625043565106676088842803600775810", "price": "0.5", "size": "132777.52", "side": "SELL", "hash": "f10e27626e37facd99a841e4ce7ac4a0f86efe4c", "best_bid": "0.48", "best_ask": "0.49"}], "timestamp": "1769384437267", "event_type": "price_change"}}
{"_local_timestamp": "2026-01-25T23:40:39.566085+00:00", "data": {"market": "0x0ea8005efbc460378340a2f28a6d97b0d1d9d9d7fba4d16f529b8a415dca77a2", "price_changes": [{"asset_id": "48266425622404486484896353767723266081505997963592758694068789352158715350186", "price": "0.33", "size": "58.31", "side": "BUY", "hash": "f3575cdc73a237d395528a23e8440f2eaa29b6f8", "best_bid": "0.37", "best_ask": "0.39"}, {"asset_id": "71552623345730992280501476931299615437386807576519105089437764117985071980606", "price": "0.67", "size": "58.31", "side": "SELL", "hash": "610b8c17018497180e4a6ff227e26961d5ae8068", "best_bid": "0.61", "best_ask": "0.63"}], "timestamp": "1769384439500", "event_type": "price_change"}}
{"_local_timestamp": "2026-01-25T23:40:39.730317+00:00", "data": {"market": "0x0ea8005efbc460378340a2f28a6d97b0d1d9d9d7fba4d16f529b8a415dca77a2", "price_changes": [{"asset_id": "48266425622404486484896353767723266081505997963592758694068789352158715350186", "price": "0.33", "size": "31.51", "side": "BUY", "hash": "e1258079853521de50e81a8b4ee94865739323e0", "best_bid": "0.37", "best_ask": "0.39"}, {"asset_id": "71552623345730992280501476931299615437386807576519105089437764117985071980606", "price": "0.67", "size": "31.51", "side": "SELL", "hash": "ce418802639c56c14eaa5e4cde5ba0a1bf39ca6c", "best_bid": "0.61", "best_ask": "0.63"}], "timestamp": "1769384439667", "event_type": "price_change"}}
{"_local_timestamp": "2026-01-25T23:40:40.899488+00:00", "data": {"market": "0x9c1a953fe92c8357f1b646ba25d983aa83e90c525992db14fb726fa895cb5763", "price_changes": [{"asset_id": "8501497159083948713316135768103773293754490207922884688769443031624417212426", "price": "0.63", "size": "90.58", "side": "SELL", "hash": "d9271ace48436ad7bcb6b1dfa667c5c004ccaf68", "best_bid": "0.62", "best_ask": "0.63"}, {"asset_id": "2527312495175492857904889758552137141356236738032676480522356889996545113869", "price": "0.37", "size": "90.58", "side": "BUY", "hash": "a48d50b1c5b83597650b7adde388d1eec9a24442", "best_bid": "0.37", "best_ask": "0.38"}], "timestamp": "1769384440836", "event_type": "price_change"}}
{"_local_timestamp": "2026-01-25T23:40:41.123808+00:00", "data": {"market": "0xbb57ccf5853a85487bc3d83d04d669310d28c6c810758953b9d9b91d1aee89d2", "price_changes": [{"asset_id": "91863162118308663069733924043159186005106558783397508844234610341221325526200", "price": "0.5", "size": "132877.52", "side": "BUY", "hash": "0ff1c66e98fed07189a25d571095f0acac1cbd4a", "best_bid": "0.51", "best_ask": "0.52"}, {"asset_id": "105267568073659068217311993901927962476298440625043565106676088842803600775810", "price": "0.5", "size": "132877.52", "side": "SELL", "hash": "8088ed5e4ec8e8d6da7d7f6e5f5b5cd90ef74055", "best_bid": "0.48", "best_ask": "0.49"}], "timestamp": "1769384441025", "event_type": "price_change"}}
{"_local_timestamp": "2026-01-25T23:40:44.579775+00:00", "data": {"market": "0x0ea8005efbc460378340a2f28a6d97b0d1d9d9d7fba4d16f529b8a415dca77a2", "price_changes": [{"asset_id": "48266425622404486484896353767723266081505997963592758694068789352158715350186", "price": "0.33", "size": "58.31", "side": "BUY", "hash": "3dcdb07ab8aa54e0aaf489f0ba8d4aaf3ef277af", "best_bid": "0.37", "best_ask": "0.39"}, {"asset_id": "71552623345730992280501476931299615437386807576519105089437764117985071980606", "price": "0.67", "size": "58.31", "side": "SELL", "hash": "083319233ce4b22d0ca2c8c0ec95eae2e8cf8c98", "best_bid": "0.61", "best_ask": "0.63"}], "timestamp": "1769384444516", "event_type": "price_change"}}
{"_local_timestamp": "2026-01-25T23:40:44.715645+00:00", "data": {"market": "0x0ea8005efbc460378340a2f28a6d97b0d1d9d9d7fba4d16f529b8a415dca77a2", "price_changes": [{"asset_id": "48266425622404486484896353767723266081505997963592758694068789352158715350186", "price": "0.33", "size": "31.51", "side": "BUY", "hash": "925afb07b2444cb4c5c228198fb6be77e94355e9", "best_bid": "0.37", "best_ask": "0.39"}, {"asset_id": "71552623345730992280501476931299615437386807576519105089437764117985071980606", "price": "0.67", "size": "31.51", "side": "SELL", "hash": "46349a7ba8fe74eb544dc2b150c13e074cc3fcc9", "best_bid": "0.61", "best_ask": "0.63"}], "timestamp": "1769384444636", "event_type": "price_change"}}
{"_local_timestamp": "2026-01-25T23:40:45.097548+00:00", "data": {"market": "0x32b09f6390252b37d674501527e709016d55581b2c1e544bd4b8167f5f732f4c", "price_changes": [{"asset_id": "92388629082681805622801622703528982922543286352927708208755887536971583436902", "price": "0.52", "size": "97463.54", "side": "SELL", "hash": "bf3c312a9a7d71360649dfe39a56355c62e982c0", "best_bid": "0.51", "best_ask": "0.52"}, {"asset_id": "90435811253665578014957380826505992530054077692143838383981805324273750424057", "price": "0.48", "size": "97463.54", "side": "BUY", "hash": "935a0b4344e745de5c43f85bc8d67d1d814802a3", "best_bid": "0.48", "best_ask": "0.49"}], "timestamp": "1769384445002", "event_type": "price_change"}}
{"_local_timestamp": "2026-01-25T23:40:49.606736+00:00", "data": {"market": "0x0ea8005efbc460378340a2f28a6d97b0d1d9d9d7fba4d16f529b8a415dca77a2", "price_changes": [{"asset_id": "48266425622404486484896353767723266081505997963592758694068789352158715350186", "price": "0.33", "size": "58.31", "side": "BUY", "hash": "6a654b2e492d8ca44ba4e720d6f005b3c7c0b217", "best_bid": "0.37", "best_ask": "0.39"}, {"asset_id": "71552623345730992280501476931299615437386807576519105089437764117985071980606", "price": "0.67", "size": "58.31", "side": "SELL", "hash": "0fc492b421e07dd30afd4f21666b7773c44601c0", "best_bid": "0.61", "best_ask": "0.63"}], "timestamp": "1769384449537", "event_type": "price_change"}}
{"_local_timestamp": "2026-01-25T23:40:49.744420+00:00", "data": {"market": "0x0ea8005efbc460378340a2f28a6d97b0d1d9d9d7fba4d16f529b8a415dca77a2", "price_changes": [{"asset_id": "48266425622404486484896353767723266081505997963592758694068789352158715350186", "price": "0.33", "size": "31.51", "side": "BUY", "hash": "3aecc3e963f92c98ff0f71fe6866ccd076e8de1e", "best_bid": "0.37", "best_ask": "0.39"}, {"asset_id": "71552623345730992280501476931299615437386807576519105089437764117985071980606", "price": "0.67", "size": "31.51", "side": "SELL", "hash": "a9ecd93641b7138e9e6c78af30a976b25281cceb", "best_bid": "0.61", "best_ask": "0.63"}], "timestamp": "1769384449675", "event_type": "price_change"}}
{"_local_timestamp": "2026-01-25T23:40:51.073193+00:00", "data": {"market": "0x0ea8005efbc460378340a2f28a6d97b0d1d9d9d7fba4d16f529b8a415dca77a2", "price_changes": [{"asset_id": "71552623345730992280501476931299615437386807576519105089437764117985071980606", "price": "0.52", "size": "1000", "side": "BUY", "hash": "a61d1fc220b4633c087886417b5c285c591934be", "best_bid": "0.61", "best_ask": "0.63"}, {"asset_id": "48266425622404486484896353767723266081505997963592758694068789352158715350186", "price": "0.48", "size": "1000", "side": "SELL", "hash": "d3fcaec1402587608bda03992f13dd9f3d6486df", "best_bid": "0.37", "best_ask": "0.39"}], "timestamp": "1769384451001", "event_type": "price_change"}}
{"_local_timestamp": "2026-01-25T23:40:51.192987+00:00", "data": {"market": "0xc829edf5ca6961e441c266546064b629c29a9313694689c0768db92810db62ff", "price_changes": [{"asset_id": "31737648224640860538361785861700072557227859645060732743904381890720199497279", "price": "0.08", "size": "74.95", "side": "BUY", "hash": "adb2ade7d6f94f4c925b0a2d5d908d70371e3e1f", "best_bid": "0.16", "best_ask": "0.18"}, {"asset_id": "40694415003591202786878279287884766002429923551809555441858630935269489320071", "price": "0.92", "size": "74.95", "side": "SELL", "hash": "7a5ed40127519a24c4d5e61434602825981f6b92", "best_bid": "0.82", "best_ask": "0.84"}], "timestamp": "1769384451118", "event_type": "price_change"}}
{"_local_timestamp": "2026-01-25T23:40:51.195206+00:00", "data": {"market": "0xc829edf5ca6961e441c266546064b629c29a9313694689c0768db92810db62ff", "price_changes": [{"asset_id": "31737648224640860538361785861700072557227859645060732743904381890720199497279", "price": "0.01", "size": "8257.36", "side": "BUY", "hash": "adb2ade7d6f94f4c925b0a2d5d908d70371e3e1f", "best_bid": "0.16", "best_ask": "0.18"}, {"asset_id": "40694415003591202786878279287884766002429923551809555441858630935269489320071", "price": "0.99", "size": "8257.36", "side": "SELL", "hash": "7a5ed40127519a24c4d5e61434602825981f6b92", "best_bid": "0.82", "best_ask": "0.84"}], "timestamp": "1769384451118", "event_type": "price_change"}}
{"_local_timestamp": "2026-01-25T23:40:51.197510+00:00", "data": {"market": "0xc829edf5ca6961e441c266546064b629c29a9313694689c0768db92810db62ff", "price_changes": [{"asset_id": "31737648224640860538361785861700072557227859645060732743904381890720199497279", "price": "0.09", "size": "0", "side": "BUY", "hash": "adb2ade7d6f94f4c925b0a2d5d908d70371e3e1f", "best_bid": "0.16", "best_ask": "0.18"}, {"asset_id": "40694415003591202786878279287884766002429923551809555441858630935269489320071", "price": "0.91", "size": "0", "side": "SELL", "hash": "7a5ed40127519a24c4d5e61434602825981f6b92", "best_bid": "0.82", "best_ask": "0.84"}], "timestamp": "1769384451118", "event_type": "price_change"}}
{"_local_timestamp": "2026-01-25T23:40:51.220783+00:00", "data": {"market": "0xc829edf5ca6961e441c266546064b629c29a9313694689c0768db92810db62ff", "price_changes": [{"asset_id": "31737648224640860538361785861700072557227859645060732743904381890720199497279", "price": "0.01", "size": "8557.36", "side": "BUY", "hash": "9065e8127507db0c1200d72e45120abfd121d3d6", "best_bid": "0.16", "best_ask": "0.18"}, {"asset_id": "40694415003591202786878279287884766002429923551809555441858630935269489320071", "price": "0.99", "size": "8557.36", "side": "SELL", "hash": "de5dd91ebed824e33ca8372ae37c97e0124ef4a4", "best_bid": "0.82", "best_ask": "0.84"}], "timestamp": "1769384451154", "event_type": "price_change"}}
{"_local_timestamp": "2026-01-25T23:40:52.073577+00:00", "data": {"market": "0xc829edf5ca6961e441c266546064b629c29a9313694689c0768db92810db62ff", "price_changes": [{"asset_id": "31737648224640860538361785861700072557227859645060732743904381890720199497279", "price": "0.01", "size": "8457.36", "side": "BUY", "hash": "3f1e37951c614960cd6767778fc33d344e0fb7fb", "best_bid": "0.16", "best_ask": "0.18"}, {"asset_id": "40694415003591202786878279287884766002429923551809555441858630935269489320071", "price": "0.99", "size": "8457.36", "side": "SELL", "hash": "52fe92fa2688722c1e715a58bdfc0870fde538a2", "best_bid": "0.82", "best_ask": "0.84"}], "timestamp": "1769384452001", "event_type": "price_change"}}
{"_local_timestamp": "2026-01-25T23:40:52.397402+00:00", "data": {"market": "0xbb57ccf5853a85487bc3d83d04d669310d28c6c810758953b9d9b91d1aee89d2", "price_changes": [{"asset_id": "105267568073659068217311993901927962476298440625043565106676088842803600775810", "price": "0.27", "size": "1852", "side": "BUY", "hash": "a2aab175bff01b513f21c0d1ba26030f9e242f2d", "best_bid": "0.48", "best_ask": "0.49"}, {"asset_id": "91863162118308663069733924043159186005106558783397508844234610341221325526200", "price": "0.73", "size": "1852", "side": "SELL", "hash": "f0fc5664421716732c004d2367dc34a59c88e129", "best_bid": "0.51", "best_ask": "0.52"}], "timestamp": "1769384452319", "event_type": "price_change"}}
{"_local_timestamp": "2026-01-25T23:40:53.276077+00:00", "data": {"market": "0xbb57ccf5853a85487bc3d83d04d669310d28c6c810758953b9d9b91d1aee89d2", "price_changes": [{"asset_id": "105267568073659068217311993901927962476298440625043565106676088842803600775810", "price": "0.12", "size": "0", "side": "BUY", "hash": "9c529d59dd70810bd71a4e03939da24150af0c87", "best_bid": "0.48", "best_ask": "0.49"}, {"asset_id": "91863162118308663069733924043159186005106558783397508844234610341221325526200", "price": "0.88", "size": "0", "side": "SELL", "hash": "2dc807a109021ef47f334a0d07897697b7b99aa0", "best_bid": "0.51", "best_ask": "0.52"}], "timestamp": "1769384453198", "event_type": "price_change"}}
{"_local_timestamp": "2026-01-25T23:40:53.577832+00:00", "data": {"market": "0xbb57ccf5853a85487bc3d83d04d669310d28c6c810758953b9d9b91d1aee89d2", "price_changes": [{"asset_id": "105267568073659068217311993901927962476298440625043565106676088842803600775810", "price": "0.14", "size": "3847", "side": "BUY", "hash": "e4ce1546d26e9e22af7d6be12821bebc41876d1a", "best_bid": "0.48", "best_ask": "0.49"}, {"asset_id": "91863162118308663069733924043159186005106558783397508844234610341221325526200", "price": "0.86", "size": "3847", "side": "SELL", "hash": "3f71258a5b77b06866c99ca5997f3eee895eecd6", "best_bid": "0.51", "best_ask": "0.52"}], "timestamp": "1769384453498", "event_type": "price_change"}}
{"_local_timestamp": "2026-01-25T23:40:53.954057+00:00", "data": {"market": "0x0ea8005efbc460378340a2f28a6d97b0d1d9d9d7fba4d16f529b8a415dca77a2", "price_changes": [{"asset_id": "71552623345730992280501476931299615437386807576519105089437764117985071980606", "price": "0.21", "size": "100", "side": "BUY", "hash": "fccecc277cc571c87252754d827ba43d08646111", "best_bid": "0.61", "best_ask": "0.63"}, {"asset_id": "48266425622404486484896353767723266081505997963592758694068789352158715350186", "price": "0.79", "size": "100", "side": "SELL", "hash": "de4d1c0b0e2f651d417c291b90915750ca7cf824", "best_bid": "0.37", "best_ask": "0.39"}], "timestamp": "1769384453879", "event_type": "price_change"}}
{"_local_timestamp": "2026-01-25T23:40:54.032001+00:00", "data": {"market": "0x0ea8005efbc460378340a2f28a6d97b0d1d9d9d7fba4d16f529b8a415dca77a2", "price_changes": [{"asset_id": "71552623345730992280501476931299615437386807576519105089437764117985071980606", "price": "0.2", "size": "2930", "side": "BUY", "hash": "9f1501e07cd6e45b4e9d057a718b9a9110d129de", "best_bid": "0.61", "best_ask": "0.63"}, {"asset_id": "48266425622404486484896353767723266081505997963592758694068789352158715350186", "price": "0.8", "size": "2930", "side": "SELL", "hash": "2e880546b11c32289a501c7b1e5db63b2f2b6f03", "best_bid": "0.37", "best_ask": "0.39"}], "timestamp": "1769384453963", "event_type": "price_change"}}
{"_local_timestamp": "2026-01-25T23:40:54.624748+00:00", "data": {"market": "0x0ea8005efbc460378340a2f28a6d97b0d1d9d9d7fba4d16f529b8a415dca77a2", "price_changes": [{"asset_id": "48266425622404486484896353767723266081505997963592758694068789352158715350186", "price": "0.33", "size": "58.31", "side": "BUY", "hash": "535ffd41522ff8d8c54e11d0093d83baf7927965", "best_bid": "0.37", "best_ask": "0.39"}, {"asset_id": "71552623345730992280501476931299615437386807576519105089437764117985071980606", "price": "0.67", "size": "58.31", "side": "SELL", "hash": "62bec79ac7364d13fccff48300e1d440b1f5d664", "best_bid": "0.61", "best_ask": "0.63"}], "timestamp": "1769384454553", "event_type": "price_change"}}
{"_local_timestamp": "2026-01-25T23:40:54.736767+00:00", "data": {"market": "0x0ea8005efbc460378340a2f28a6d97b0d1d9d9d7fba4d16f529b8a415dca77a2", "price_changes": [{"asset_id": "48266425622404486484896353767723266081505997963592758694068789352158715350186", "price": "0.33", "size": "31.51", "side": "BUY", "hash": "2ccb85493765dbb286372b04efdd163ab6490ac9", "best_bid": "0.37", "best_ask": "0.39"}, {"asset_id": "71552623345730992280501476931299615437386807576519105089437764117985071980606", "price": "0.67", "size": "31.51", "side": "SELL", "hash": "8465efea529244a21ba315c8aefb629837106ed4", "best_bid": "0.61", "best_ask": "0.63"}], "timestamp": "1769384454666", "event_type": "price_change"}}
{"_local_timestamp": "2026-01-25T23:40:55.973783+00:00", "data": {"market": "0x50ddb9cd80d5c271664a2ebb7fcaed1d0a148d82c8e8d314d830f75a944c3dcc", "price_changes": [{"asset_id": "88275040060084773376557187972215267513049848642895776801789297917961077894224", "price": "0.57", "size": "0", "side": "SELL", "hash": "93acfa94c0f0b5187d7db91d46bb1c14a0113f3d", "best_bid": "0.53", "best_ask": "0.56"}, {"asset_id": "94376205816022955542979635542279932967359915765455578534002478996104754801969", "price": "0.43", "size": "0", "side": "BUY", "hash": "4e6bd9c993781f310351a339edc746def0c2e5b4", "best_bid": "0.44", "best_ask": "0.47"}], "timestamp": "1769384455909", "event_type": "price_change"}}
{"_local_timestamp": "2026-01-25T23:40:56.006482+00:00", "data": {"market": "0x50ddb9cd80d5c271664a2ebb7fcaed1d0a148d82c8e8d314d830f75a944c3dcc", "price_changes": [{"asset_id": "88275040060084773376557187972215267513049848642895776801789297917961077894224", "price": "0.61", "size": "29", "side": "SELL", "hash": "0341ed0435d9d767c4eac8b741c52682e90c370f", "best_bid": "0.53", "best_ask": "0.56"}, {"asset_id": "94376205816022955542979635542279932967359915765455578534002478996104754801969", "price": "0.39", "size": "29", "side": "BUY", "hash": "174af49f47039d3b006bf986cf36278854dc663c", "best_bid": "0.44", "best_ask": "0.47"}], "timestamp": "1769384455934", "event_type": "price_change"}}
{"_local_timestamp": "2026-01-25T23:40:56.175794+00:00", "data": {"market": "0x50ddb9cd80d5c271664a2ebb7fcaed1d0a148d82c8e8d314d830f75a944c3dcc", "price_changes": [{"asset_id": "88275040060084773376557187972215267513049848642895776801789297917961077894224", "price": "0.57", "size": "20.11", "side": "SELL", "hash": "cd2b8939a0e078597adb18824369098b6354bcb4", "best_bid": "0.53", "best_ask": "0.56"}, {"asset_id": "94376205816022955542979635542279932967359915765455578534002478996104754801969", "price": "0.43", "size": "20.11", "side": "BUY", "hash": "4504be6afceb4df4fc06a9f784345cb3eb5b0432", "best_bid": "0.44", "best_ask": "0.47"}], "timestamp": "1769384456106", "event_type": "price_change"}}
{"_local_timestamp": "2026-01-25T23:40:57.440432+00:00", "data": {"market": "0x50ddb9cd80d5c271664a2ebb7fcaed1d0a148d82c8e8d314d830f75a944c3dcc", "price_changes": [{"asset_id": "88275040060084773376557187972215267513049848642895776801789297917961077894224", "price": "0.61", "size": "0", "side": "SELL", "hash": "78630ff223cae5dc4d8be25a2eb7d867f8479e1f", "best_bid": "0.53", "best_ask": "0.56"}, {"asset_id": "94376205816022955542979635542279932967359915765455578534002478996104754801969", "price": "0.39", "size": "0", "side": "BUY", "hash": "9804d727f442e632f45daf730ffa7d28f139dfdb", "best_bid": "0.44", "best_ask": "0.47"}], "timestamp": "1769384457369", "event_type": "price_change"}}
{"_local_timestamp": "2026-01-25T23:40:58.248022+00:00", "data": {"market": "0x50ddb9cd80d5c271664a2ebb7fcaed1d0a148d82c8e8d314d830f75a944c3dcc", "price_changes": [{"asset_id": "88275040060084773376557187972215267513049848642895776801789297917961077894224", "price": "0.6", "size": "0", "side": "SELL", "hash": "047a6ffb37fd580d2c30ac984a90ea7480b126b9", "best_bid": "0.53", "best_ask": "0.56"}, {"asset_id": "94376205816022955542979635542279932967359915765455578534002478996104754801969", "price": "0.4", "size": "0", "side": "BUY", "hash": "05ac98cd388754db3a9b8ac87cd613719adcd40b", "best_bid": "0.44", "best_ask": "0.47"}], "timestamp": "1769384457583", "event_type": "price_change"}}
{"_local_timestamp": "2026-01-25T23:40:58.271572+00:00", "data": {"market": "0x50ddb9cd80d5c271664a2ebb7fcaed1d0a148d82c8e8d314d830f75a944c3dcc", "price_changes": [{"asset_id": "88275040060084773376557187972215267513049848642895776801789297917961077894224", "price": "0.61", "size": "29", "side": "SELL", "hash": "068e9c8cd73a8dae663ef74b2f283a945f7269d1", "best_bid": "0.53", "best_ask": "0.56"}, {"asset_id": "94376205816022955542979635542279932967359915765455578534002478996104754801969", "price": "0.39", "size": "29", "side": "BUY", "hash": "f0a498ef2070329d72accb5151f9e66406a57446", "best_bid": "0.44", "best_ask": "0.47"}], "timestamp": "1769384457613", "event_type": "price_change"}}
{"_local_timestamp": "2026-01-25T23:40:58.275667+00:00", "data": {"market": "0x50ddb9cd80d5c271664a2ebb7fcaed1d0a148d82c8e8d314d830f75a944c3dcc", "price_changes": [{"asset_id": "88275040060084773376557187972215267513049848642895776801789297917961077894224", "price": "0.61", "size": "43.1", "side": "SELL", "hash": "21d2be50967798529f239b88552f3cd3f5917a32", "best_bid": "0.53", "best_ask": "0.56"}, {"asset_id": "94376205816022955542979635542279932967359915765455578534002478996104754801969", "price": "0.39", "size": "43.1", "side": "BUY", "hash": "868ee35facb5d38d89e8dfbda8c7b50fb8567c95", "best_bid": "0.44", "best_ask": "0.47"}], "timestamp": "1769384457660", "event_type": "price_change"}}
{"_local_timestamp": "2026-01-25T23:40:59.660121+00:00", "data": {"market": "0x0ea8005efbc460378340a2f28a6d97b0d1d9d9d7fba4d16f529b8a415dca77a2", "price_changes": [{"asset_id": "48266425622404486484896353767723266081505997963592758694068789352158715350186", "price": "0.33", "size": "58.31", "side": "BUY", "hash": "7c16e4f262758d085f7c155786ce8bb344887da7", "best_bid": "0.37", "best_ask": "0.39"}, {"asset_id": "71552623345730992280501476931299615437386807576519105089437764117985071980606", "price": "0.67", "size": "58.31", "side": "SELL", "hash": "c3b690548811cee17cdc0ffb0a04bdb581f17c3c", "best_bid": "0.61", "best_ask": "0.63"}], "timestamp": "1769384459598", "event_type": "price_change"}}
{"_local_timestamp": "2026-01-25T23:40:59.834815+00:00", "data": {"market": "0x0ea8005efbc460378340a2f28a6d97b0d1d9d9d7fba4d16f529b8a415dca77a2", "price_changes": [{"asset_id": "48266425622404486484896353767723266081505997963592758694068789352158715350186", "price": "0.33", "size": "31.51", "side": "BUY", "hash": "6e6bdf89580bdd9f991d70e588770a5263fd0165", "best_bid": "0.37", "best_ask": "0.39"}, {"asset_id": "71552623345730992280501476931299615437386807576519105089437764117985071980606", "price": "0.67", "size": "31.51", "side": "SELL", "hash": "ba5060451d57b671f1f8ee910f1e0d1392bf4aeb", "best_bid": "0.61", "best_ask": "0.63"}], "timestamp": "1769384459767", "event_type": "price_change"}}
{"_local_timestamp": "2026-01-25T23:41:02.914326+00:00", "data": {"market": "0xc829edf5ca6961e441c266546064b629c29a9313694689c0768db92810db62ff", "price_changes": [{"asset_id": "31737648224640860538361785861700072557227859645060732743904381890720199497279", "price": "0.04", "size": "1187", "side": "BUY", "hash": "fdfc93562f2a6282a52e967f7789ccb1c8810959", "best_bid": "0.16", "best_ask": "0.18"}, {"asset_id": "40694415003591202786878279287884766002429923551809555441858630935269489320071", "price": "0.96", "size": "1187", "side": "SELL", "hash": "fec7401bbcb37d9c46072b7d922f7039114784c0", "best_bid": "0.82", "best_ask": "0.84"}], "timestamp": "1769384462831", "event_type": "price_change"}}
{"_local_timestamp": "2026-01-25T23:41:02.917587+00:00", "data": {"market": "0xc829edf5ca6961e441c266546064b629c29a9313694689c0768db92810db62ff", "price_changes": [{"asset_id": "31737648224640860538361785861700072557227859645060732743904381890720199497279", "price": "0.12", "size": "591", "side": "BUY", "hash": "c4bdffa39076019900e58dacc473177dab343cae", "best_bid": "0.16", "best_ask": "0.18"}, {"asset_id": "40694415003591202786878279287884766002429923551809555441858630935269489320071", "price": "0.88", "size": "591", "side": "SELL", "hash": "dcf1a959df5a3db880e302d06e9f83a3143deb72", "best_bid": "0.82", "best_ask": "0.84"}], "timestamp": "1769384462832", "event_type": "price_change"}}
{"_local_timestamp": "2026-01-25T23:41:02.919880+00:00", "data": {"market": "0xc829edf5ca6961e441c266546064b629c29a9313694689c0768db92810db62ff", "price_changes": [{"asset_id": "31737648224640860538361785861700072557227859645060732743904381890720199497279", "price": "0.08", "size": "661.95", "side": "BUY", "hash": "552a91c135b915e7ffa22d77aaf7f4c6883ec657", "best_bid": "0.16", "best_ask": "0.18"}, {"asset_id": "40694415003591202786878279287884766002429923551809555441858630935269489320071", "price": "0.92", "size": "661.95", "side": "SELL", "hash": "aba4a96ec933ee955553313ccd071a730ccce6cd", "best_bid": "0.82", "best_ask": "0.84"}], "timestamp": "1769384462833", "event_type": "price_change"}}
{"_local_timestamp": "2026-01-25T23:41:04.690396+00:00", "data": {"market": "0x0ea8005efbc460378340a2f28a6d97b0d1d9d9d7fba4d16f529b8a415dca77a2", "price_changes": [{"asset_id": "48266425622404486484896353767723266081505997963592758694068789352158715350186", "price": "0.33", "size": "58.31", "side": "BUY", "hash": "3c6669cd23b1571b9bd840596800b473904a2ce1", "best_bid": "0.37", "best_ask": "0.39"}, {"asset_id": "71552623345730992280501476931299615437386807576519105089437764117985071980606", "price": "0.67", "size": "58.31", "side": "SELL", "hash": "5e5700e447f4b424a79c0a0d72a6c3fc65524b6d", "best_bid": "0.61", "best_ask": "0.63"}], "timestamp": "1769384464620", "event_type": "price_change"}}
{"_local_timestamp": "2026-01-25T23:41:04.842904+00:00", "data": {"market": "0x0ea8005efbc460378340a2f28a6d97b0d1d9d9d7fba4d16f529b8a415dca77a2", "price_changes": [{"asset_id": "48266425622404486484896353767723266081505997963592758694068789352158715350186", "price": "0.33", "size": "31.51", "side": "BUY", "hash": "94c94eb9e8933b84ddde0784a05150023b3ead58", "best_bid": "0.37", "best_ask": "0.39"}, {"asset_id": "71552623345730992280501476931299615437386807576519105089437764117985071980606", "price": "0.67", "size": "31.51", "side": "SELL", "hash": "a5ba5a9bfd846d377dd9745e2b4c130e8857ee64", "best_bid": "0.61", "best_ask": "0.63"}], "timestamp": "1769384464775", "event_type": "price_change"}}
{"_local_timestamp": "2026-01-25T23:41:09.605444+00:00", "data": {"market": "0xc829edf5ca6961e441c266546064b629c29a9313694689c0768db92810db62ff", "price_changes": [{"asset_id": "40694415003591202786878279287884766002429923551809555441858630935269489320071", "price": "0.24", "size": "200", "side": "BUY", "hash": "38e1d86ffb477e636797bce6f3b98a5f549abf4a", "best_bid": "0.82", "best_ask": "0.84"}, {"asset_id": "31737648224640860538361785861700072557227859645060732743904381890720199497279", "price": "0.76", "size": "200", "side": "SELL", "hash": "8fe2649eee700cf36ad84b6fa4f66e6711984e56", "best_bid": "0.16", "best_ask": "0.18"}], "timestamp": "1769384469533", "event_type": "price_change"}}
{"_local_timestamp": "2026-01-25T23:41:09.611062+00:00", "data": {"market": "0x50ddb9cd80d5c271664a2ebb7fcaed1d0a148d82c8e8d314d830f75a944c3dcc", "price_changes": [{"asset_id": "88275040060084773376557187972215267513049848642895776801789297917961077894224", "price": "0.23", "size": "0", "side": "BUY", "hash": "d1fe55164a0a10a92dbbb996960cc36107acb5e0", "best_bid": "0.53", "best_ask": "0.56"}, {"asset_id": "94376205816022955542979635542279932967359915765455578534002478996104754801969", "price": "0.77", "size": "0", "side": "SELL", "hash": "b99e292b56e8e192cbb778e31e7b994d02765786", "best_bid": "0.44", "best_ask": "0.47"}], "timestamp": "1769384469533", "event_type": "price_change"}}
{"_local_timestamp": "2026-01-25T23:41:09.617924+00:00", "data": {"market": "0x32b09f6390252b37d674501527e709016d55581b2c1e544bd4b8167f5f732f4c", "price_changes": [{"asset_id": "90435811253665578014957380826505992530054077692143838383981805324273750424057", "price": "0.23", "size": "0", "side": "BUY", "hash": "cb22234451d7ba01ff01af8d3a0cc3ccf7eda843", "best_bid": "0.48", "best_ask": "0.49"}, {"asset_id": "92388629082681805622801622703528982922543286352927708208755887536971583436902", "price": "0.77", "size": "0", "side": "SELL", "hash": "26935da03bb515456861c5e2990f4ad6f8544903", "best_bid": "0.51", "best_ask": "0.52"}], "timestamp": "1769384469533", "event_type": "price_change"}}
{"_local_timestamp": "2026-01-25T23:41:09.751347+00:00", "data": {"market": "0x0ea8005efbc460378340a2f28a6d97b0d1d9d9d7fba4d16f529b8a415dca77a2", "price_changes": [{"asset_id": "48266425622404486484896353767723266081505997963592758694068789352158715350186", "price": "0.33", "size": "58.31", "side": "BUY", "hash": "6d8e7a0ee23490702fec2f90b3b13c82d15708f9", "best_bid": "0.37", "best_ask": "0.39"}, {"asset_id": "71552623345730992280501476931299615437386807576519105089437764117985071980606", "price": "0.67", "size": "58.31", "side": "SELL", "hash": "17985482f9f82b472d53243fd3ce79a597bb24fb", "best_bid": "0.61", "best_ask": "0.63"}], "timestamp": "1769384469664", "event_type": "price_change"}}
{"_local_timestamp": "2026-01-25T23:41:09.850077+00:00", "data": {"market": "0x0ea8005efbc460378340a2f28a6d97b0d1d9d9d7fba4d16f529b8a415dca77a2", "price_changes": [{"asset_id": "48266425622404486484896353767723266081505997963592758694068789352158715350186", "price": "0.33", "size": "31.51", "side": "BUY", "hash": "276ba5eb327200e4ce78492113a1dafb11365ea8", "best_bid": "0.37", "best_ask": "0.39"}, {"asset_id": "71552623345730992280501476931299615437386807576519105089437764117985071980606", "price": "0.67", "size": "31.51", "side": "SELL", "hash": "6738af2b2158960e39e7d8e53d4ee6ba36e50876", "best_bid": "0.61", "best_ask": "0.63"}], "timestamp": "1769384469782", "event_type": "price_change"}}
{"_local_timestamp": "2026-01-25T23:41:09.904123+00:00", "data": {"market": "0x50ddb9cd80d5c271664a2ebb7fcaed1d0a148d82c8e8d314d830f75a944c3dcc", "price_changes": [{"asset_id": "88275040060084773376557187972215267513049848642895776801789297917961077894224", "price": "0.22", "size": "350", "side": "BUY", "hash": "65c094c538c41425a3a779dab1030af7468d7b28", "best_bid": "0.53", "best_ask": "0.56"}, {"asset_id": "94376205816022955542979635542279932967359915765455578534002478996104754801969", "price": "0.78", "size": "350", "side": "SELL", "hash": "614effab664c2c8a217ee9c5f764408639dea800", "best_bid": "0.44", "best_ask": "0.47"}], "timestamp": "1769384469806", "event_type": "price_change"}}
{"_local_timestamp": "2026-01-25T23:41:09.911229+00:00", "data": {"market": "0xc829edf5ca6961e441c266546064b629c29a9313694689c0768db92810db62ff", "price_changes": [{"asset_id": "40694415003591202786878279287884766002429923551809555441858630935269489320071", "price": "0.25", "size": "1884", "side": "BUY", "hash": "f45f838f5de878841086b99788ce15adf8035308", "best_bid": "0.82", "best_ask": "0.84"}, {"asset_id": "31737648224640860538361785861700072557227859645060732743904381890720199497279", "price": "0.75", "size": "1884", "side": "SELL", "hash": "c771676647ef7eebb3d6e6e082ea049e96bab507", "best_bid": "0.16", "best_ask": "0.18"}], "timestamp": "1769384469806", "event_type": "price_change"}}
{"_local_timestamp": "2026-01-25T23:41:09.914919+00:00", "data": {"market": "0x32b09f6390252b37d674501527e709016d55581b2c1e544bd4b8167f5f732f4c", "price_changes": [{"asset_id": "90435811253665578014957380826505992530054077692143838383981805324273750424057", "price": "0.21", "size": "2781", "side": "BUY", "hash": "7932ff9958240279c80871f9044312040aab8f46", "best_bid": "0.48", "best_ask": "0.49"}, {"asset_id": "92388629082681805622801622703528982922543286352927708208755887536971583436902", "price": "0.79", "size": "2781", "side": "SELL", "hash": "4e5e899935fbe2f259a32cb115da49015256be56", "best_bid": "0.51", "best_ask": "0.52"}], "timestamp": "1769384469806", "event_type": "price_change"}}
{"_local_timestamp": "2026-01-25T23:41:12.238065+00:00", "data": {"market": "0x1fad72fae204143ff1c3035e99e7c0f65ea8d5cd9bd1070987bd1a3316f772be", "price_changes": [{"asset_id": "98022490269692409998126496127597032490334070080325855126491859374983463996227", "price": "0.41", "size": "330", "side": "BUY", "hash": "d0c2383af1aa3e90f4ee00950737f165862bf93c", "best_bid": "0.55", "best_ask": "0.58"}, {"asset_id": "53831553061883006530739877284105938919721408776239639687877978808906551086026", "price": "0.59", "size": "330", "side": "SELL", "hash": "1cbb4d796b9a9be5ffa4b331bcbf9cb9176c8e99", "best_bid": "0.42", "best_ask": "0.45"}], "timestamp": "1769384472107", "event_type": "price_change"}}
{"_local_timestamp": "2026-01-25T23:41:14.246898+00:00", "data": {"market": "0x0ea8005efbc460378340a2f28a6d97b0d1d9d9d7fba4d16f529b8a415dca77a2", "price_changes": [{"asset_id": "71552623345730992280501476931299615437386807576519105089437764117985071980606", "price": "0.52", "size": "1181", "side": "BUY", "hash": "af210876e7c1ebf15fe6b3333aa5e56d2cbcdc15", "best_bid": "0.61", "best_ask": "0.63"}, {"asset_id": "48266425622404486484896353767723266081505997963592758694068789352158715350186", "price": "0.48", "size": "1181", "side": "SELL", "hash": "8f67487e254a15963861cc0cec1cb2142e51ba7f", "best_bid": "0.37", "best_ask": "0.39"}], "timestamp": "1769384474166", "event_type": "price_change"}}
{"_local_timestamp": "2026-01-25T23:41:14.713205+00:00", "data": {"market": "0xbb57ccf5853a85487bc3d83d04d669310d28c6c810758953b9d9b91d1aee89d2", "price_changes": [{"asset_id": "105267568073659068217311993901927962476298440625043565106676088842803600775810", "price": "0.13", "size": "0", "side": "BUY", "hash": "8593dbc4c30080997f9f43ac93b54164cdad4c2f", "best_bid": "0.48", "best_ask": "0.49"}, {"asset_id": "91863162118308663069733924043159186005106558783397508844234610341221325526200", "price": "0.87", "size": "0", "side": "SELL", "hash": "fb312a7f32ae2ed413373d4246c9f293c581facc", "best_bid": "0.51", "best_ask": "0.52"}], "timestamp": "1769384474532", "event_type": "price_change"}}
{"_local_timestamp": "2026-01-25T23:41:14.843081+00:00", "data": {"market": "0x0ea8005efbc460378340a2f28a6d97b0d1d9d9d7fba4d16f529b8a415dca77a2", "price_changes": [{"asset_id": "48266425622404486484896353767723266081505997963592758694068789352158715350186", "price": "0.33", "size": "58.31", "side": "BUY", "hash": "e2088f5e7ef01027cfd4bfeeb83671de4c647c57", "best_bid": "0.37", "best_ask": "0.39"}, {"asset_id": "71552623345730992280501476931299615437386807576519105089437764117985071980606", "price": "0.67", "size": "58.31", "side": "SELL", "hash": "7c2c31fed2a22900b56153e258d68bcbc278c873", "best_bid": "0.61", "best_ask": "0.63"}], "timestamp": "1769384474683", "event_type": "price_change"}}
{"_local_timestamp": "2026-01-25T23:41:14.925699+00:00", "data": {"market": "0x0ea8005efbc460378340a2f28a6d97b0d1d9d9d7fba4d16f529b8a415dca77a2", "price_changes": [{"asset_id": "48266425622404486484896353767723266081505997963592758694068789352158715350186", "price": "0.33", "size": "31.51", "side": "BUY", "hash": "6cc755d78c9b07402b6aad7b9e0cc028892d7ced", "best_bid": "0.37", "best_ask": "0.39"}, {"asset_id": "71552623345730992280501476931299615437386807576519105089437764117985071980606", "price": "0.67", "size": "31.51", "side": "SELL", "hash": "82156ae5b375b11f2e41a215366fc6bcacbae33d", "best_bid": "0.61", "best_ask": "0.63"}], "timestamp": "1769384474795", "event_type": "price_change"}}
{"_local_timestamp": "2026-01-25T23:41:15.003910+00:00", "data": {"market": "0xc829edf5ca6961e441c266546064b629c29a9313694689c0768db92810db62ff", "price_changes": [{"asset_id": "31737648224640860538361785861700072557227859645060732743904381890720199497279", "price": "0.01", "size": "33957.36", "side": "BUY", "hash": "2741cc66a453d56919eef109153a2a745a18b50b", "best_bid": "0.16", "best_ask": "0.18"}, {"asset_id": "40694415003591202786878279287884766002429923551809555441858630935269489320071", "price": "0.99", "size": "33957.36", "side": "SELL", "hash": "e1a081d527b0ab8f30a28afa6aa9f523bc9c0cfc", "best_bid": "0.82", "best_ask": "0.84"}], "timestamp": "1769384474905", "event_type": "price_change"}}
{"_local_timestamp": "2026-01-25T23:41:15.006712+00:00", "data": {"market": "0xc829edf5ca6961e441c266546064b629c29a9313694689c0768db92810db62ff", "price_changes": [{"asset_id": "31737648224640860538361785861700072557227859645060732743904381890720199497279", "price": "0.08", "size": "2786.95", "side": "BUY", "hash": "f7ecb403f15f1d7c3dd038fa10ba1a5b453e68fb", "best_bid": "0.16", "best_ask": "0.18"}, {"asset_id": "40694415003591202786878279287884766002429923551809555441858630935269489320071", "price": "0.92", "size": "2786.95", "side": "SELL", "hash": "4b59aa77310a743d6fc97ec9f57b27c63bae87e7", "best_bid": "0.82", "best_ask": "0.84"}], "timestamp": "1769384474905", "event_type": "price_change"}}
{"_local_timestamp": "2026-01-25T23:41:15.010663+00:00", "data": {"market": "0xc829edf5ca6961e441c266546064b629c29a9313694689c0768db92810db62ff", "price_changes": [{"asset_id": "31737648224640860538361785861700072557227859645060732743904381890720199497279", "price": "0.09", "size": "945", "side": "BUY", "hash": "632a1f166bef55c6f7e4e034e233e5db2ab39410", "best_bid": "0.16", "best_ask": "0.18"}, {"asset_id": "40694415003591202786878279287884766002429923551809555441858630935269489320071", "price": "0.91", "size": "945", "side": "SELL", "hash": "4b782a422a5b97dc61b5881a8adcbb2e66a553cb", "best_bid": "0.82", "best_ask": "0.84"}], "timestamp": "1769384474906", "event_type": "price_change"}}
{"_local_timestamp": "2026-01-25T23:41:15.022318+00:00", "data": {"market": "0xc829edf5ca6961e441c266546064b629c29a9313694689c0768db92810db62ff", "price_changes": [{"asset_id": "31737648224640860538361785861700072557227859645060732743904381890720199497279", "price": "0.14", "size": "227", "side": "BUY", "hash": "9690652dc8126e3031784b0f3a479d251122912a", "best_bid": "0.16", "best_ask": "0.18"}, {"asset_id": "40694415003591202786878279287884766002429923551809555441858630935269489320071", "price": "0.86", "size": "227", "side": "SELL", "hash": "94bcb4b9b5482f7dc59532d6ec24383b50944604", "best_bid": "0.82", "best_ask": "0.84"}], "timestamp": "1769384474934", "event_type": "price_change"}}
{"_local_timestamp": "2026-01-25T23:41:16.539001+00:00", "data": {"market": "0xc829edf5ca6961e441c266546064b629c29a9313694689c0768db92810db62ff", "price_changes": [{"asset_id": "31737648224640860538361785861700072557227859645060732743904381890720199497279", "price": "0.14", "size": "130", "side": "BUY", "hash": "1e83c8bdf43258259546b999ff054c029b1b1e26", "best_bid": "0.16", "best_ask": "0.18"}, {"asset_id": "40694415003591202786878279287884766002429923551809555441858630935269489320071", "price": "0.86", "size": "130", "side": "SELL", "hash": "fe7181b0239bfca78fe64ba9dfdcaea7ccd33621", "best_bid": "0.82", "best_ask": "0.84"}], "timestamp": "1769384476434", "event_type": "price_change"}}
{"_local_timestamp": "2026-01-25T23:41:16.563145+00:00", "data": {"market": "0xc829edf5ca6961e441c266546064b629c29a9313694689c0768db92810db62ff", "price_changes": [{"asset_id": "31737648224640860538361785861700072557227859645060732743904381890720199497279", "price": "0.14", "size": "227", "side": "BUY", "hash": "ae46c14f222b84900591ef87a7e29b3df0d5a3fa", "best_bid": "0.16", "best_ask": "0.18"}, {"asset_id": "40694415003591202786878279287884766002429923551809555441858630935269489320071", "price": "0.86", "size": "227", "side": "SELL", "hash": "ea60ab5ee52ccbe164e4758ecc0a642c09fd283c", "best_bid": "0.82", "best_ask": "0.84"}], "timestamp": "1769384476468", "event_type": "price_change"}}
{"_local_timestamp": "2026-01-25T23:41:16.694572+00:00", "data": {"market": "0x50ddb9cd80d5c271664a2ebb7fcaed1d0a148d82c8e8d314d830f75a944c3dcc", "price_changes": [{"asset_id": "88275040060084773376557187972215267513049848642895776801789297917961077894224", "price": "0.61", "size": "29", "side": "SELL", "hash": "7f81f527a4659dcf74745fe7942c70cfdcb6716a", "best_bid": "0.53", "best_ask": "0.56"}, {"asset_id": "94376205816022955542979635542279932967359915765455578534002478996104754801969", "price": "0.39", "size": "29", "side": "BUY", "hash": "f6537366f2e93e3ff6256c051aaf102ee2516d3b", "best_bid": "0.44", "best_ask": "0.47"}], "timestamp": "1769384476587", "event_type": "price_change"}}
{"_local_timestamp": "2026-01-25T23:41:16.743456+00:00", "data": {"market": "0x50ddb9cd80d5c271664a2ebb7fcaed1d0a148d82c8e8d314d830f75a944c3dcc", "price_changes": [{"asset_id": "88275040060084773376557187972215267513049848642895776801789297917961077894224", "price": "0.6", "size": "14.1", "side": "SELL", "hash": "c16005fd358d5295b5c520404fa7246e2e153e76", "best_bid": "0.53", "best_ask": "0.56"}, {"asset_id": "94376205816022955542979635542279932967359915765455578534002478996104754801969", "price": "0.4", "size": "14.1", "side": "BUY", "hash": "d175e97b78a965fb2096269960cc13afa3de98e6", "best_bid": "0.44", "best_ask": "0.47"}], "timestamp": "1769384476622", "event_type": "price_change"}}
{"_local_timestamp": "2026-01-25T23:41:16.765756+00:00", "data": {"market": "0x50ddb9cd80d5c271664a2ebb7fcaed1d0a148d82c8e8d314d830f75a944c3dcc", "price_changes": [{"asset_id": "88275040060084773376557187972215267513049848642895776801789297917961077894224", "price": "0.61", "size": "0", "side": "SELL", "hash": "c9460cfddea74fc053b7bcc12571dfc14bd1cb2c", "best_bid": "0.53", "best_ask": "0.56"}, {"asset_id": "94376205816022955542979635542279932967359915765455578534002478996104754801969", "price": "0.39", "size": "0", "side": "BUY", "hash": "60dee55e2b7260bf844c489fc6cac31a62cbdf8f", "best_bid": "0.44", "best_ask": "0.47"}], "timestamp": "1769384476646", "event_type": "price_change"}}
{"_local_timestamp": "2026-01-25T23:41:18.100496+00:00", "data": {"market": "0xc829edf5ca6961e441c266546064b629c29a9313694689c0768db92810db62ff", "price_changes": [{"asset_id": "31737648224640860538361785861700072557227859645060732743904381890720199497279", "price": "0.14", "size": "130", "side": "BUY", "hash": "a07334e71fe2dd5ffcc13503e9409076446c6d7c", "best_bid": "0.16", "best_ask": "0.18"}, {"asset_id": "40694415003591202786878279287884766002429923551809555441858630935269489320071", "price": "0.86", "size": "130", "side": "SELL", "hash": "39f30f63d2356eea44e30926e2c27bc03145f321", "best_bid": "0.82", "best_ask": "0.84"}], "timestamp": "1769384477934", "event_type": "price_change"}}
{"_local_timestamp": "2026-01-25T23:41:18.104247+00:00", "data": {"market": "0xc829edf5ca6961e441c266546064b629c29a9313694689c0768db92810db62ff", "price_changes": [{"asset_id": "31737648224640860538361785861700072557227859645060732743904381890720199497279", "price": "0.14", "size": "227", "side": "BUY", "hash": "15285a2c8c2b6816c967dd2570b4df91e92d26fe", "best_bid": "0.16", "best_ask": "0.18"}, {"asset_id": "40694415003591202786878279287884766002429923551809555441858630935269489320071", "price": "0.86", "size": "227", "side": "SELL", "hash": "02769ca06bc050e367d171a2a365b2fb9c106224", "best_bid": "0.82", "best_ask": "0.84"}], "timestamp": "1769384477961", "event_type": "price_change"}}
{"_local_timestamp": "2026-01-25T23:41:19.580315+00:00", "data": {"market": "0xc829edf5ca6961e441c266546064b629c29a9313694689c0768db92810db62ff", "price_changes": [{"asset_id": "31737648224640860538361785861700072557227859645060732743904381890720199497279", "price": "0.14", "size": "130", "side": "BUY", "hash": "3bf193d7493a298ea0cc98df577d98a2f73e8791", "best_bid": "0.16", "best_ask": "0.18"}, {"asset_id": "40694415003591202786878279287884766002429923551809555441858630935269489320071", "price": "0.86", "size": "130", "side": "SELL", "hash": "a5e4abce190fa63379f4e3a0d24466ba7bee2174", "best_bid": "0.82", "best_ask": "0.84"}], "timestamp": "1769384479436", "event_type": "price_change"}}
{"_local_timestamp": "2026-01-25T23:41:19.612846+00:00", "data": {"market": "0xc829edf5ca6961e441c266546064b629c29a9313694689c0768db92810db62ff", "price_changes": [{"asset_id": "31737648224640860538361785861700072557227859645060732743904381890720199497279", "price": "0.14", "size": "227", "side": "BUY", "hash": "f9e1e352f4999ca5b3ebddec2e2f05f911ea6a40", "best_bid": "0.16", "best_ask": "0.18"}, {"asset_id": "40694415003591202786878279287884766002429923551809555441858630935269489320071", "price": "0.86", "size": "227", "side": "SELL", "hash": "e47076b5577e2ec81e8d2f98a03aee6dc0184ed1", "best_bid": "0.82", "best_ask": "0.84"}], "timestamp": "1769384479462", "event_type": "price_change"}}
{"_local_timestamp": "2026-01-25T23:41:19.893787+00:00", "data": {"market": "0x0ea8005efbc460378340a2f28a6d97b0d1d9d9d7fba4d16f529b8a415dca77a2", "price_changes": [{"asset_id": "48266425622404486484896353767723266081505997963592758694068789352158715350186", "price": "0.33", "size": "58.31", "side": "BUY", "hash": "b360354b5a99d817cb35dad93ba87d632aeae443", "best_bid": "0.37", "best_ask": "0.39"}, {"asset_id": "71552623345730992280501476931299615437386807576519105089437764117985071980606", "price": "0.67", "size": "58.31", "side": "SELL", "hash": "681514b2283b70168aa10c528a034c7d339c87f0", "best_bid": "0.61", "best_ask": "0.63"}], "timestamp": "1769384479737", "event_type": "price_change"}}
{"_local_timestamp": "2026-01-25T23:41:20.300303+00:00", "data": {"market": "0x0ea8005efbc460378340a2f28a6d97b0d1d9d9d7fba4d16f529b8a415dca77a2", "price_changes": [{"asset_id": "48266425622404486484896353767723266081505997963592758694068789352158715350186", "price": "0.33", "size": "31.51", "side": "BUY", "hash": "f94ea48b47c2af4863c6d0f4c482f69428db4b4c", "best_bid": "0.37", "best_ask": "0.39"}, {"asset_id": "71552623345730992280501476931299615437386807576519105089437764117985071980606", "price": "0.67", "size": "31.51", "side": "SELL", "hash": "990fdd296ba78015cab35228e1900c84b2a70bb3", "best_bid": "0.61", "best_ask": "0.63"}], "timestamp": "1769384480152", "event_type": "price_change"}}
{"_local_timestamp": "2026-01-25T23:41:21.057436+00:00", "data": {"market": "0xc829edf5ca6961e441c266546064b629c29a9313694689c0768db92810db62ff", "price_changes": [{"asset_id": "31737648224640860538361785861700072557227859645060732743904381890720199497279", "price": "0.14", "size": "130", "side": "BUY", "hash": "0bc96a37e8e610d857b88f9863f19a8d4dc6bc17", "best_bid": "0.16", "best_ask": "0.18"}, {"asset_id": "40694415003591202786878279287884766002429923551809555441858630935269489320071", "price": "0.86", "size": "130", "side": "SELL", "hash": "15d6da54961d71e593802c8c2b12326331f36a71", "best_bid": "0.82", "best_ask": "0.84"}], "timestamp": "1769384480936", "event_type": "price_change"}}
{"_local_timestamp": "2026-01-25T23:41:21.082166+00:00", "data": {"market": "0xc829edf5ca6961e441c266546064b629c29a9313694689c0768db92810db62ff", "price_changes": [{"asset_id": "31737648224640860538361785861700072557227859645060732743904381890720199497279", "price": "0.14", "size": "227", "side": "BUY", "hash": "08e40dd1f70c311f08b430c1a9dcf06d8c731070", "best_bid": "0.16", "best_ask": "0.18"}, {"asset_id": "40694415003591202786878279287884766002429923551809555441858630935269489320071", "price": "0.86", "size": "227", "side": "SELL", "hash": "e70b6232d5e865444ef5c354b4292e3ebce6f024", "best_bid": "0.82", "best_ask": "0.84"}], "timestamp": "1769384480966", "event_type": "price_change"}}
{"_local_timestamp": "2026-01-25T23:41:21.303166+00:00", "data": {"market": "0x50ddb9cd80d5c271664a2ebb7fcaed1d0a148d82c8e8d314d830f75a944c3dcc", "price_changes": [{"asset_id": "88275040060084773376557187972215267513049848642895776801789297917961077894224", "price": "0.57", "size": "0", "side": "SELL", "hash": "271705429225001cf2e48f2b931b5255cbc0cb96", "best_bid": "0.53", "best_ask": "0.56"}, {"asset_id": "94376205816022955542979635542279932967359915765455578534002478996104754801969", "price": "0.43", "size": "0", "side": "BUY", "hash": "9c6049865accc2e553bf230925f868ea79edc009", "best_bid": "0.44", "best_ask": "0.47"}], "timestamp": "1769384481199", "event_type": "price_change"}}
{"_local_timestamp": "2026-01-25T23:41:21.325698+00:00", "data": {"market": "0x50ddb9cd80d5c271664a2ebb7fcaed1d0a148d82c8e8d314d830f75a944c3dcc", "price_changes": [{"asset_id": "88275040060084773376557187972215267513049848642895776801789297917961077894224", "price": "0.6", "size": "43.1", "side": "SELL", "hash": "f03518e87395659dea7bed455d6df489f5890f6a", "best_bid": "0.53", "best_ask": "0.56"}, {"asset_id": "94376205816022955542979635542279932967359915765455578534002478996104754801969", "price": "0.4", "size": "43.1", "side": "BUY", "hash": "3d919e95f32ed92776fe7828b98599f6e44810be", "best_bid": "0.44", "best_ask": "0.47"}], "timestamp": "1769384481226", "event_type": "price_change"}}
{"_local_timestamp": "2026-01-25T23:41:21.628962+00:00", "data": {"market": "0xbb57ccf5853a85487bc3d83d04d669310d28c6c810758953b9d9b91d1aee89d2", "price_changes": [{"asset_id": "105267568073659068217311993901927962476298440625043565106676088842803600775810", "price": "0.14", "size": "275", "side": "BUY", "hash": "c2af056e13f6db428a3ad629cb842b032cbda4aa", "best_bid": "0.48", "best_ask": "0.49"}, {"asset_id": "91863162118308663069733924043159186005106558783397508844234610341221325526200", "price": "0.86", "size": "275", "side": "SELL", "hash": "5aa2f305b1da8b89aec00dd2bc7c5e1e0713a3ef", "best_bid": "0.51", "best_ask": "0.52"}], "timestamp": "1769384481527", "event_type": "price_change"}}
{"_local_timestamp": "2026-01-25T23:41:21.647177+00:00", "data": {"market": "0xbb57ccf5853a85487bc3d83d04d669310d28c6c810758953b9d9b91d1aee89d2", "price_changes": [{"asset_id": "105267568073659068217311993901927962476298440625043565106676088842803600775810", "price": "0.12", "size": "4167", "side": "BUY", "hash": "a36269268a6a91f90a488540760ebd22b7ffe35e", "best_bid": "0.48", "best_ask": "0.49"}, {"asset_id": "91863162118308663069733924043159186005106558783397508844234610341221325526200", "price": "0.88", "size": "4167", "side": "SELL", "hash": "c70ebcdfc2698fd4127914e301a9df512b1f95e3", "best_bid": "0.51", "best_ask": "0.52"}], "timestamp": "1769384481545", "event_type": "price_change"}}
{"_local_timestamp": "2026-01-25T23:41:21.788710+00:00", "data": {"market": "0x50ddb9cd80d5c271664a2ebb7fcaed1d0a148d82c8e8d314d830f75a944c3dcc", "price_changes": [{"asset_id": "88275040060084773376557187972215267513049848642895776801789297917961077894224", "price": "0.53", "size": "27.14", "side": "BUY", "hash": "d08e8f7cbbe6b125fce567abf3b88c5ebfcddd86", "best_bid": "0.53", "best_ask": "0.56"}, {"asset_id": "94376205816022955542979635542279932967359915765455578534002478996104754801969", "price": "0.47", "size": "27.14", "side": "SELL", "hash": "929203b80c5675ad77fce8ee95702b24a87bb1aa", "best_bid": "0.44", "best_ask": "0.47"}], "timestamp": "1769384481677", "event_type": "price_change"}}
{"_local_timestamp": "2026-01-25T23:41:22.563521+00:00", "data": {"market": "0xc829edf5ca6961e441c266546064b629c29a9313694689c0768db92810db62ff", "price_changes": [{"asset_id": "31737648224640860538361785861700072557227859645060732743904381890720199497279", "price": "0.14", "size": "130", "side": "BUY", "hash": "e1e852c1c9d0deadefa8b8202b31ebcba65b5c4a", "best_bid": "0.16", "best_ask": "0.18"}, {"asset_id": "40694415003591202786878279287884766002429923551809555441858630935269489320071", "price": "0.86", "size": "130", "side": "SELL", "hash": "3ba0c65ea943126e48c82777dbbd4bf5f80c5d8a", "best_bid": "0.82", "best_ask": "0.84"}], "timestamp": "1769384482430", "event_type": "price_change"}}
{"_local_timestamp": "2026-01-25T23:41:22.600435+00:00", "data": {"market": "0xc829edf5ca6961e441c266546064b629c29a9313694689c0768db92810db62ff", "price_changes": [{"asset_id": "31737648224640860538361785861700072557227859645060732743904381890720199497279", "price": "0.14", "size": "227", "side": "BUY", "hash": "68e02dfc410ecfa1857bcb2b193abc722f799e98", "best_bid": "0.16", "best_ask": "0.18"}, {"asset_id": "40694415003591202786878279287884766002429923551809555441858630935269489320071", "price": "0.86", "size": "227", "side": "SELL", "hash": "6ae23803337373ed8f04c421dcdc8e5ef4b9afe0", "best_bid": "0.82", "best_ask": "0.84"}], "timestamp": "1769384482457", "event_type": "price_change"}}
{"_local_timestamp": "2026-01-25T23:41:24.029791+00:00", "data": {"market": "0xc829edf5ca6961e441c266546064b629c29a9313694689c0768db92810db62ff", "price_changes": [{"asset_id": "31737648224640860538361785861700072557227859645060732743904381890720199497279", "price": "0.14", "size": "130", "side": "BUY", "hash": "92fff2a223d709060a437548b0333f8fc6ca66e3", "best_bid": "0.16", "best_ask": "0.18"}, {"asset_id": "40694415003591202786878279287884766002429923551809555441858630935269489320071", "price": "0.86", "size": "130", "side": "SELL", "hash": "65f1d3f55ddb3a46cc15ea1bcf693000d4bbc633", "best_bid": "0.82", "best_ask": "0.84"}], "timestamp": "1769384483931", "event_type": "price_change"}}
{"_local_timestamp": "2026-01-25T23:41:24.059051+00:00", "data": {"market": "0xc829edf5ca6961e441c266546064b629c29a9313694689c0768db92810db62ff", "price_changes": [{"asset_id": "31737648224640860538361785861700072557227859645060732743904381890720199497279", "price": "0.14", "size": "227", "side": "BUY", "hash": "5ca039bcef8d08d0b2ac35de7508774669e8e6e3", "best_bid": "0.16", "best_ask": "0.18"}, {"asset_id": "40694415003591202786878279287884766002429923551809555441858630935269489320071", "price": "0.86", "size": "227", "side": "SELL", "hash": "5f7a43bb7f43660f6416f1346841b5fe41d3ce0f", "best_bid": "0.82", "best_ask": "0.84"}], "timestamp": "1769384483957", "event_type": "price_change"}}
{"_local_timestamp": "2026-01-25T23:41:24.812160+00:00", "data": {"market": "0x0ea8005efbc460378340a2f28a6d97b0d1d9d9d7fba4d16f529b8a415dca77a2", "price_changes": [{"asset_id": "48266425622404486484896353767723266081505997963592758694068789352158715350186", "price": "0.33", "size": "58.31", "side": "BUY", "hash": "c11eda4a49af3a2490dad27e1264f1576477a649", "best_bid": "0.37", "best_ask": "0.39"}, {"asset_id": "71552623345730992280501476931299615437386807576519105089437764117985071980606", "price": "0.67", "size": "58.31", "side": "SELL", "hash": "d527aaeab2c2cafb9eb6560956e0d86012afa691", "best_bid": "0.61", "best_ask": "0.63"}], "timestamp": "1769384484710", "event_type": "price_change"}}
{"_local_timestamp": "2026-01-25T23:41:24.887767+00:00", "data": {"market": "0x50ddb9cd80d5c271664a2ebb7fcaed1d0a148d82c8e8d314d830f75a944c3dcc", "price_changes": [{"asset_id": "88275040060084773376557187972215267513049848642895776801789297917961077894224", "price": "0.2", "size": "0", "side": "BUY", "hash": "fe59793107d76e719ecf10cd294c087e629ca0c3", "best_bid": "0.53", "best_ask": "0.6"}, {"asset_id": "94376205816022955542979635542279932967359915765455578534002478996104754801969", "price": "0.8", "size": "0", "side": "SELL", "hash": "5496e20d3da02499b0ac1565ccea91b607f861cb", "best_bid": "0.4", "best_ask": "0.47"}], "timestamp": "1769384484798", "event_type": "price_change"}}
{"_local_timestamp": "2026-01-25T23:41:24.890301+00:00", "data": {"market": "0x50ddb9cd80d5c271664a2ebb7fcaed1d0a148d82c8e8d314d830f75a944c3dcc", "price_changes": [{"asset_id": "88275040060084773376557187972215267513049848642895776801789297917961077894224", "price": "0.56", "size": "0", "side": "SELL", "hash": "fe59793107d76e719ecf10cd294c087e629ca0c3", "best_bid": "0.53", "best_ask": "0.6"}, {"asset_id": "94376205816022955542979635542279932967359915765455578534002478996104754801969", "price": "0.44", "size": "0", "side": "BUY", "hash": "5496e20d3da02499b0ac1565ccea91b607f861cb", "best_bid": "0.4", "best_ask": "0.47"}], "timestamp": "1769384484798", "event_type": "price_change"}}
{"_local_timestamp": "2026-01-25T23:41:24.921190+00:00", "data": {"market": "0x0ea8005efbc460378340a2f28a6d97b0d1d9d9d7fba4d16f529b8a415dca77a2", "price_changes": [{"asset_id": "48266425622404486484896353767723266081505997963592758694068789352158715350186", "price": "0.33", "size": "31.51", "side": "BUY", "hash": "e27bc3aedc7965b988d824ecd55c123841b0c8c9", "best_bid": "0.37", "best_ask": "0.39"}, {"asset_id": "71552623345730992280501476931299615437386807576519105089437764117985071980606", "price": "0.67", "size": "31.51", "side": "SELL", "hash": "e1760905fcc99356df285453c85c7f2e26832a74", "best_bid": "0.61", "best_ask": "0.63"}], "timestamp": "1769384484831", "event_type": "price_change"}}
{"_local_timestamp": "2026-01-25T23:41:24.939337+00:00", "data": {"market": "0x50ddb9cd80d5c271664a2ebb7fcaed1d0a148d82c8e8d314d830f75a944c3dcc", "price_changes": [{"asset_id": "88275040060084773376557187972215267513049848642895776801789297917961077894224", "price": "0.59", "size": "16", "side": "SELL", "hash": "0947603781b58fe123b4397a22b8ba7e97e8cb08", "best_bid": "0.53", "best_ask": "0.59"}, {"asset_id": "94376205816022955542979635542279932967359915765455578534002478996104754801969", "price": "0.41", "size": "16", "side": "BUY", "hash": "d95ec4dd77a4a8b13f5fe044ac73886d8d8e1f9d", "best_bid": "0.41", "best_ask": "0.47"}], "timestamp": "1769384484842", "event_type": "price_change"}}
{"_local_timestamp": "2026-01-25T23:41:24.942963+00:00", "data": {"market": "0x50ddb9cd80d5c271664a2ebb7fcaed1d0a148d82c8e8d314d830f75a944c3dcc", "price_changes": [{"asset_id": "88275040060084773376557187972215267513049848642895776801789297917961077894224", "price": "0.23", "size": "1131", "side": "BUY", "hash": "7c4f6d327a616c47c46a2502447990cfa58f79c9", "best_bid": "0.53", "best_ask": "0.59"}, {"asset_id": "94376205816022955542979635542279932967359915765455578534002478996104754801969", "price": "0.77", "size": "1131", "side": "SELL", "hash": "66c49fd11219a18c9efa44be0ad9ab83ffa55821", "best_bid": "0.41", "best_ask": "0.47"}], "timestamp": "1769384484843", "event_type": "price_change"}}
{"_local_timestamp": "2026-01-25T23:41:25.310941+00:00", "data": {"market": "0x84f8b70331323c2fba97d7ceaa9a35fb645a0770d0dbff169d07f24f376766e9", "price_changes": [{"asset_id": "108999723207897941876452935557011604067917389120996960199512481363958770540884", "price": "0.56", "size": "0", "side": "SELL", "hash": "4a45aa667d8d02c9744d333d4108a416fb0be041", "best_bid": "0.51", "best_ask": "0.53"}, {"asset_id": "64533579809297525579033609963634939501013332859992608996100633472507000251907", "price": "0.44", "size": "0", "side": "BUY", "hash": "706992e2a208664dfaeca2af0dd71a2c7aee39e2", "best_bid": "0.47", "best_ask": "0.49"}], "timestamp": "1769384485209", "event_type": "price_change"}}
{"_local_timestamp": "2026-01-25T23:41:25.316763+00:00", "data": {"market": "0x50ddb9cd80d5c271664a2ebb7fcaed1d0a148d82c8e8d314d830f75a944c3dcc", "price_changes": [{"asset_id": "94376205816022955542979635542279932967359915765455578534002478996104754801969", "price": "0.38", "size": "130", "side": "BUY", "hash": "c138b23197c1e877972b6bc8d05c1f721adfbba7", "best_bid": "0.41", "best_ask": "0.47"}, {"asset_id": "88275040060084773376557187972215267513049848642895776801789297917961077894224", "price": "0.62", "size": "130", "side": "SELL", "hash": "57dc9a4210f3cd3750e7328dfecf6392f9aa72b6", "best_bid": "0.53", "best_ask": "0.59"}], "timestamp": "1769384485211", "event_type": "price_change"}}
{"_local_timestamp": "2026-01-25T23:41:25.382776+00:00", "data": {"market": "0x84f8b70331323c2fba97d7ceaa9a35fb645a0770d0dbff169d07f24f376766e9", "price_changes": [{"asset_id": "108999723207897941876452935557011604067917389120996960199512481363958770540884", "price": "0.56", "size": "12.69", "side": "SELL", "hash": "9dc814cffefd19deca180591d34731ae31c76c4c", "best_bid": "0.51", "best_ask": "0.53"}, {"asset_id": "64533579809297525579033609963634939501013332859992608996100633472507000251907", "price": "0.44", "size": "12.69", "side": "BUY", "hash": "df8b7a7c754080924a059743778546eb6f0855b4", "best_bid": "0.47", "best_ask": "0.49"}], "timestamp": "1769384485276", "event_type": "price_change"}}
{"_local_timestamp": "2026-01-25T23:41:25.537424+00:00", "data": {"market": "0xc829edf5ca6961e441c266546064b629c29a9313694689c0768db92810db62ff", "price_changes": [{"asset_id": "31737648224640860538361785861700072557227859645060732743904381890720199497279", "price": "0.14", "size": "130", "side": "BUY", "hash": "d388f59a6ff24b8f6cde768002611560ae9e0e12", "best_bid": "0.16", "best_ask": "0.18"}, {"asset_id": "40694415003591202786878279287884766002429923551809555441858630935269489320071", "price": "0.86", "size": "130", "side": "SELL", "hash": "eec2e9006be77dcb039ecd6a5684bce7470a599d", "best_bid": "0.82", "best_ask": "0.84"}], "timestamp": "1769384485437", "event_type": "price_change"}}
{"_local_timestamp": "2026-01-25T23:41:25.563571+00:00", "data": {"market": "0xc829edf5ca6961e441c266546064b629c29a9313694689c0768db92810db62ff", "price_changes": [{"asset_id": "31737648224640860538361785861700072557227859645060732743904381890720199497279", "price": "0.14", "size": "227", "side": "BUY", "hash": "a3f653360bdebbd1aaed90c183ed011ea7869aaa", "best_bid": "0.16", "best_ask": "0.18"}, {"asset_id": "40694415003591202786878279287884766002429923551809555441858630935269489320071", "price": "0.86", "size": "227", "side": "SELL", "hash": "168e8dc4cc0d54d4b42c77202593bc1897d7075d", "best_bid": "0.82", "best_ask": "0.84"}], "timestamp": "1769384485463", "event_type": "price_change"}}
{"_local_timestamp": "2026-01-25T23:41:26.387079+00:00", "data": {"market": "0xbb57ccf5853a85487bc3d83d04d669310d28c6c810758953b9d9b91d1aee89d2", "price_changes": [{"asset_id": "105267568073659068217311993901927962476298440625043565106676088842803600775810", "price": "0.48", "size": "137492.95", "side": "BUY", "hash": "77c8e7a9ae01b77f084935433cd87733f7b0506d", "best_bid": "0.48", "best_ask": "0.49"}, {"asset_id": "91863162118308663069733924043159186005106558783397508844234610341221325526200", "price": "0.52", "size": "137492.95", "side": "SELL", "hash": "53d613b8c2cfac1a09320ecc1c380d8acf15ee06", "best_bid": "0.51", "best_ask": "0.52"}], "timestamp": "1769384486281", "event_type": "price_change"}}
{"_local_timestamp": "2026-01-25T23:41:27.047551+00:00", "data": {"market": "0xc829edf5ca6961e441c266546064b629c29a9313694689c0768db92810db62ff", "price_changes": [{"asset_id": "31737648224640860538361785861700072557227859645060732743904381890720199497279", "price": "0.14", "size": "130", "side": "BUY", "hash": "017d36fb92d976cec66f304bb73eb20cd9c7d514", "best_bid": "0.16", "best_ask": "0.18"}, {"asset_id": "40694415003591202786878279287884766002429923551809555441858630935269489320071", "price": "0.86", "size": "130", "side": "SELL", "hash": "348dfbc84b908dd0a836d4bfe383430d1d2bf89c", "best_bid": "0.82", "best_ask": "0.84"}], "timestamp": "1769384486937", "event_type": "price_change"}}
{"_local_timestamp": "2026-01-25T23:41:27.063095+00:00", "data": {"market": "0xc829edf5ca6961e441c266546064b629c29a9313694689c0768db92810db62ff", "price_changes": [{"asset_id": "31737648224640860538361785861700072557227859645060732743904381890720199497279", "price": "0.14", "size": "227", "side": "BUY", "hash": "ed9aa166ae38f7329447ddf2270c454a51f226e1", "best_bid": "0.16", "best_ask": "0.18"}, {"asset_id": "40694415003591202786878279287884766002429923551809555441858630935269489320071", "price": "0.86", "size": "227", "side": "SELL", "hash": "d1c4529722e854f330e18393ff8b1b626048cb91", "best_bid": "0.82", "best_ask": "0.84"}], "timestamp": "1769384486961", "event_type": "price_change"}}
{"_local_timestamp": "2026-01-25T23:41:28.547075+00:00", "data": {"market": "0xc829edf5ca6961e441c266546064b629c29a9313694689c0768db92810db62ff", "price_changes": [{"asset_id": "31737648224640860538361785861700072557227859645060732743904381890720199497279", "price": "0.14", "size": "130", "side": "BUY", "hash": "1fef4906dd0b30f8cf2add2d283b1d2a930aa34e", "best_bid": "0.16", "best_ask": "0.18"}, {"asset_id": "40694415003591202786878279287884766002429923551809555441858630935269489320071", "price": "0.86", "size": "130", "side": "SELL", "hash": "33e16c69ee26182926374f50ba7245c720cbfed1", "best_bid": "0.82", "best_ask": "0.84"}], "timestamp": "1769384488433", "event_type": "price_change"}}
{"_local_timestamp": "2026-01-25T23:41:28.581593+00:00", "data": {"market": "0xc829edf5ca6961e441c266546064b629c29a9313694689c0768db92810db62ff", "price_changes": [{"asset_id": "31737648224640860538361785861700072557227859645060732743904381890720199497279", "price": "0.14", "size": "227", "side": "BUY", "hash": "dfe2bf4e024da493012267a64c261245884031e8", "best_bid": "0.16", "best_ask": "0.18"}, {"asset_id": "40694415003591202786878279287884766002429923551809555441858630935269489320071", "price": "0.86", "size": "227", "side": "SELL", "hash": "1538b18820632abfc0d89ca455a097afbcf94a35", "best_bid": "0.82", "best_ask": "0.84"}], "timestamp": "1769384488466", "event_type": "price_change"}}
{"_local_timestamp": "2026-01-25T23:41:29.861941+00:00", "data": {"market": "0x0ea8005efbc460378340a2f28a6d97b0d1d9d9d7fba4d16f529b8a415dca77a2", "price_changes": [{"asset_id": "48266425622404486484896353767723266081505997963592758694068789352158715350186", "price": "0.33", "size": "58.31", "side": "BUY", "hash": "4c61b4784284c47ecdecd6c53d762e09e414fc15", "best_bid": "0.37", "best_ask": "0.39"}, {"asset_id": "71552623345730992280501476931299615437386807576519105089437764117985071980606", "price": "0.67", "size": "58.31", "side": "SELL", "hash": "b497b87fbbdf66555d532000ec88c06ca08d9611", "best_bid": "0.61", "best_ask": "0.63"}], "timestamp": "1769384489733", "event_type": "price_change"}}
{"_local_timestamp": "2026-01-25T23:41:29.978892+00:00", "data": {"market": "0x0ea8005efbc460378340a2f28a6d97b0d1d9d9d7fba4d16f529b8a415dca77a2", "price_changes": [{"asset_id": "48266425622404486484896353767723266081505997963592758694068789352158715350186", "price": "0.33", "size": "31.51", "side": "BUY", "hash": "1e81f59a5332e5f063f37c4f298ddb7a087f38c6", "best_bid": "0.37", "best_ask": "0.39"}, {"asset_id": "71552623345730992280501476931299615437386807576519105089437764117985071980606", "price": "0.67", "size": "31.51", "side": "SELL", "hash": "62e630ad9cc5e9352c7e2e616c0ecfc803082c73", "best_bid": "0.61", "best_ask": "0.63"}], "timestamp": "1769384489849", "event_type": "price_change"}}
{"_local_timestamp": "2026-01-25T23:41:30.065364+00:00", "data": {"market": "0xc829edf5ca6961e441c266546064b629c29a9313694689c0768db92810db62ff", "price_changes": [{"asset_id": "31737648224640860538361785861700072557227859645060732743904381890720199497279", "price": "0.14", "size": "130", "side": "BUY", "hash": "6251eb9c85a14666d070f6044f6b5b649f9c2ebe", "best_bid": "0.16", "best_ask": "0.18"}, {"asset_id": "40694415003591202786878279287884766002429923551809555441858630935269489320071", "price": "0.86", "size": "130", "side": "SELL", "hash": "72d0f354a680c830f2471e3b9fda93c5ccbf58c3", "best_bid": "0.82", "best_ask": "0.84"}], "timestamp": "1769384489940", "event_type": "price_change"}}
{"_local_timestamp": "2026-01-25T23:41:30.099132+00:00", "data": {"market": "0xc829edf5ca6961e441c266546064b629c29a9313694689c0768db92810db62ff", "price_changes": [{"asset_id": "31737648224640860538361785861700072557227859645060732743904381890720199497279", "price": "0.14", "size": "227", "side": "BUY", "hash": "6926df3d92ac7269051b9940286bb3143f797425", "best_bid": "0.16", "best_ask": "0.18"}, {"asset_id": "40694415003591202786878279287884766002429923551809555441858630935269489320071", "price": "0.86", "size": "227", "side": "SELL", "hash": "8e15e5279ff5a1fcea869d1b8c8962b9dbb9146f", "best_bid": "0.82", "best_ask": "0.84"}], "timestamp": "1769384489970", "event_type": "price_change"}}
{"_local_timestamp": "2026-01-25T23:41:30.975430+00:00", "data": {"market": "0xbb57ccf5853a85487bc3d83d04d669310d28c6c810758953b9d9b91d1aee89d2", "price_changes": [{"asset_id": "105267568073659068217311993901927962476298440625043565106676088842803600775810", "price": "0.15", "size": "3123", "side": "BUY", "hash": "d4737228f44bcf4f46689e4ae994ecd8866b5109", "best_bid": "0.48", "best_ask": "0.49"}, {"asset_id": "91863162118308663069733924043159186005106558783397508844234610341221325526200", "price": "0.85", "size": "3123", "side": "SELL", "hash": "d9c5a82979d450feaafc3719a1f8fef95b71b43f", "best_bid": "0.51", "best_ask": "0.52"}], "timestamp": "1769384490832", "event_type": "price_change"}}
{"_local_timestamp": "2026-01-25T23:41:31.577989+00:00", "data": {"market": "0xc829edf5ca6961e441c266546064b629c29a9313694689c0768db92810db62ff", "price_changes": [{"asset_id": "31737648224640860538361785861700072557227859645060732743904381890720199497279", "price": "0.14", "size": "130", "side": "BUY", "hash": "1f42f5d78196d5c42b2370b2986f9b267ebb0f8b", "best_bid": "0.16", "best_ask": "0.18"}, {"asset_id": "40694415003591202786878279287884766002429923551809555441858630935269489320071", "price": "0.86", "size": "130", "side": "SELL", "hash": "d776e7ac46c88f2802e8361f9f4790909ef032de", "best_bid": "0.82", "best_ask": "0.84"}], "timestamp": "1769384491432", "event_type": "price_change"}}
{"_local_timestamp": "2026-01-25T23:41:31.612835+00:00", "data": {"market": "0xc829edf5ca6961e441c266546064b629c29a9313694689c0768db92810db62ff", "price_changes": [{"asset_id": "31737648224640860538361785861700072557227859645060732743904381890720199497279", "price": "0.14", "size": "227", "side": "BUY", "hash": "4446904db07d8f23625ff348b44c869f5b73b7ba", "best_bid": "0.16", "best_ask": "0.18"}, {"asset_id": "40694415003591202786878279287884766002429923551809555441858630935269489320071", "price": "0.86", "size": "227", "side": "SELL", "hash": "0ecab8619b096ccb94d002e1ab176e0dd82b0e73", "best_bid": "0.82", "best_ask": "0.84"}], "timestamp": "1769384491457", "event_type": "price_change"}}
{"_local_timestamp": "2026-01-25T23:41:31.697703+00:00", "data": {"market": "0xbb57ccf5853a85487bc3d83d04d669310d28c6c810758953b9d9b91d1aee89d2", "price_changes": [{"asset_id": "105267568073659068217311993901927962476298440625043565106676088842803600775810", "price": "0.48", "size": "137505.39", "side": "BUY", "hash": "77d20616add39a922ea045d2877e6305c87fb245", "best_bid": "0.48", "best_ask": "0.49"}, {"asset_id": "91863162118308663069733924043159186005106558783397508844234610341221325526200", "price": "0.52", "size": "137505.39", "side": "SELL", "hash": "315e597461d000e9ee9ccbee0d80bdd289b812a1", "best_bid": "0.51", "best_ask": "0.52"}], "timestamp": "1769384491532", "event_type": "price_change"}}
{"_local_timestamp": "2026-01-25T23:41:33.099161+00:00", "data": {"market": "0xc829edf5ca6961e441c266546064b629c29a9313694689c0768db92810db62ff", "price_changes": [{"asset_id": "31737648224640860538361785861700072557227859645060732743904381890720199497279", "price": "0.14", "size": "130", "side": "BUY", "hash": "077e4d2409941f9b0333b5776ea66aad88f2e070", "best_bid": "0.16", "best_ask": "0.18"}, {"asset_id": "40694415003591202786878279287884766002429923551809555441858630935269489320071", "price": "0.86", "size": "130", "side": "SELL", "hash": "407c118d21372a5f66b0ff0035c8e669b29383ea", "best_bid": "0.82", "best_ask": "0.84"}], "timestamp": "1769384492931", "event_type": "price_change"}}
{"_local_timestamp": "2026-01-25T23:41:33.113186+00:00", "data": {"market": "0xc829edf5ca6961e441c266546064b629c29a9313694689c0768db92810db62ff", "price_changes": [{"asset_id": "31737648224640860538361785861700072557227859645060732743904381890720199497279", "price": "0.14", "size": "227", "side": "BUY", "hash": "0dc4101dd9e6a2d2a8a8bec5ce9d0dc05f0b0a22", "best_bid": "0.16", "best_ask": "0.18"}, {"asset_id": "40694415003591202786878279287884766002429923551809555441858630935269489320071", "price": "0.86", "size": "227", "side": "SELL", "hash": "b686559c994158da1c6698420ad4ba373c032835", "best_bid": "0.82", "best_ask": "0.84"}], "timestamp": "1769384492957", "event_type": "price_change"}}
{"_local_timestamp": "2026-01-25T23:41:33.286928+00:00", "data": {"market": "0xbb57ccf5853a85487bc3d83d04d669310d28c6c810758953b9d9b91d1aee89d2", "price_changes": [{"asset_id": "105267568073659068217311993901927962476298440625043565106676088842803600775810", "price": "0.12", "size": "0", "side": "BUY", "hash": "47d13f580b8494892ff4a4fbcea11cbd088f5f18", "best_bid": "0.48", "best_ask": "0.49"}, {"asset_id": "91863162118308663069733924043159186005106558783397508844234610341221325526200", "price": "0.88", "size": "0", "side": "SELL", "hash": "6dc4b70fb241b862a553ee33d2d50616262a8b35", "best_bid": "0.51", "best_ask": "0.52"}], "timestamp": "1769384493140", "event_type": "price_change"}}
{"_local_timestamp": "2026-01-25T23:41:33.307984+00:00", "data": {"market": "0xbb57ccf5853a85487bc3d83d04d669310d28c6c810758953b9d9b91d1aee89d2", "price_changes": [{"asset_id": "105267568073659068217311993901927962476298440625043565106676088842803600775810", "price": "0.16", "size": "3525", "side": "BUY", "hash": "225f48729bf90317247ee7023000b2c4c04dae90", "best_bid": "0.48", "best_ask": "0.49"}, {"asset_id": "91863162118308663069733924043159186005106558783397508844234610341221325526200", "price": "0.84", "size": "3525", "side": "SELL", "hash": "3b1a854abf32699f3bd06b39aae9c1a85539403c", "best_bid": "0.51", "best_ask": "0.52"}], "timestamp": "1769384493161", "event_type": "price_change"}}
{"_local_timestamp": "2026-01-25T23:41:34.587857+00:00", "data": {"market": "0xc829edf5ca6961e441c266546064b629c29a9313694689c0768db92810db62ff", "price_changes": [{"asset_id": "31737648224640860538361785861700072557227859645060732743904381890720199497279", "price": "0.14", "size": "130", "side": "BUY", "hash": "469e3ac1fe51d84a918925c6bfc107e9c8f0e2f5", "best_bid": "0.16", "best_ask": "0.18"}, {"asset_id": "40694415003591202786878279287884766002429923551809555441858630935269489320071", "price": "0.86", "size": "130", "side": "SELL", "hash": "66ed524b78f5664bb2e53564e87b6b7da1f58272", "best_bid": "0.82", "best_ask": "0.84"}], "timestamp": "1769384494431", "event_type": "price_change"}}
{"_local_timestamp": "2026-01-25T23:41:34.627950+00:00", "data": {"market": "0xc829edf5ca6961e441c266546064b629c29a9313694689c0768db92810db62ff", "price_changes": [{"asset_id": "31737648224640860538361785861700072557227859645060732743904381890720199497279", "price": "0.14", "size": "227", "side": "BUY", "hash": "2e80511598e6859906cd4da3a041e6d18d225462", "best_bid": "0.16", "best_ask": "0.18"}, {"asset_id": "40694415003591202786878279287884766002429923551809555441858630935269489320071", "price": "0.86", "size": "227", "side": "SELL", "hash": "b7690d61df9ff79eedf655353ecf89d47fef547a", "best_bid": "0.82", "best_ask": "0.84"}], "timestamp": "1769384494462", "event_type": "price_change"}}
{"_local_timestamp": "2026-01-25T23:41:34.911896+00:00", "data": {"market": "0x0ea8005efbc460378340a2f28a6d97b0d1d9d9d7fba4d16f529b8a415dca77a2", "price_changes": [{"asset_id": "48266425622404486484896353767723266081505997963592758694068789352158715350186", "price": "0.33", "size": "58.31", "side": "BUY", "hash": "9139932fee84ab31f825d5b709616eb68b370060", "best_bid": "0.37", "best_ask": "0.39"}, {"asset_id": "71552623345730992280501476931299615437386807576519105089437764117985071980606", "price": "0.67", "size": "58.31", "side": "SELL", "hash": "d12ce5e5e1c3620cad6322e65dfddfe7d4c10349", "best_bid": "0.61", "best_ask": "0.63"}], "timestamp": "1769384494745", "event_type": "price_change"}}
{"_local_timestamp": "2026-01-25T23:41:35.033843+00:00", "data": {"market": "0x0ea8005efbc460378340a2f28a6d97b0d1d9d9d7fba4d16f529b8a415dca77a2", "price_changes": [{"asset_id": "48266425622404486484896353767723266081505997963592758694068789352158715350186", "price": "0.33", "size": "31.51", "side": "BUY", "hash": "4bb0e081975cb68b8fb0566266c66a8eb51c58b8", "best_bid": "0.37", "best_ask": "0.39"}, {"asset_id": "71552623345730992280501476931299615437386807576519105089437764117985071980606", "price": "0.67", "size": "31.51", "side": "SELL", "hash": "b5a0c4a8904a968291d77686a48ba2e4ee605a79", "best_bid": "0.61", "best_ask": "0.63"}], "timestamp": "1769384494866", "event_type": "price_change"}}
{"_local_timestamp": "2026-01-25T23:41:36.067680+00:00", "data": {"market": "0xc829edf5ca6961e441c266546064b629c29a9313694689c0768db92810db62ff", "price_changes": [{"asset_id": "31737648224640860538361785861700072557227859645060732743904381890720199497279", "price": "0.14", "size": "130", "side": "BUY", "hash": "03abe8530a48500190df064ec6375b7ba1e1df13", "best_bid": "0.16", "best_ask": "0.18"}, {"asset_id": "40694415003591202786878279287884766002429923551809555441858630935269489320071", "price": "0.86", "size": "130", "side": "SELL", "hash": "ecb8b3f48ee92757a8d65e5c80fd6704a9e5f363", "best_bid": "0.82", "best_ask": "0.84"}], "timestamp": "1769384495937", "event_type": "price_change"}}
{"_local_timestamp": "2026-01-25T23:41:36.101688+00:00", "data": {"market": "0xc829edf5ca6961e441c266546064b629c29a9313694689c0768db92810db62ff", "price_changes": [{"asset_id": "31737648224640860538361785861700072557227859645060732743904381890720199497279", "price": "0.14", "size": "227", "side": "BUY", "hash": "4fa546b0a4c8217496a9b58fdf4ea535e260f570", "best_bid": "0.16", "best_ask": "0.18"}, {"asset_id": "40694415003591202786878279287884766002429923551809555441858630935269489320071", "price": "0.86", "size": "227", "side": "SELL", "hash": "fd8c18e029828de14face9c84025459c4e585c71", "best_bid": "0.82", "best_ask": "0.84"}], "timestamp": "1769384495964", "event_type": "price_change"}}
{"_local_timestamp": "2026-01-25T23:41:37.571916+00:00", "data": {"market": "0xc829edf5ca6961e441c266546064b629c29a9313694689c0768db92810db62ff", "price_changes": [{"asset_id": "31737648224640860538361785861700072557227859645060732743904381890720199497279", "price": "0.14", "size": "130", "side": "BUY", "hash": "8b9f870c9d1f9d7267adc09ac3e8b6641b66f0df", "best_bid": "0.16", "best_ask": "0.18"}, {"asset_id": "40694415003591202786878279287884766002429923551809555441858630935269489320071", "price": "0.86", "size": "130", "side": "SELL", "hash": "5ba41d320ecf7bc892a4112167471724664113ec", "best_bid": "0.82", "best_ask": "0.84"}], "timestamp": "1769384497431", "event_type": "price_change"}}
{"_local_timestamp": "2026-01-25T23:41:37.602962+00:00", "data": {"market": "0xc829edf5ca6961e441c266546064b629c29a9313694689c0768db92810db62ff", "price_changes": [{"asset_id": "31737648224640860538361785861700072557227859645060732743904381890720199497279", "price": "0.14", "size": "227", "side": "BUY", "hash": "b41426a718525db6f66e348250d087999ff34610", "best_bid": "0.16", "best_ask": "0.18"}, {"asset_id": "40694415003591202786878279287884766002429923551809555441858630935269489320071", "price": "0.86", "size": "227", "side": "SELL", "hash": "1e0289da7f6a4ce368b9ae8cd70bebd1f6163bf4", "best_bid": "0.82", "best_ask": "0.84"}], "timestamp": "1769384497464", "event_type": "price_change"}}
{"_local_timestamp": "2026-01-25T23:41:39.078795+00:00", "data": {"market": "0xc829edf5ca6961e441c266546064b629c29a9313694689c0768db92810db62ff", "price_changes": [{"asset_id": "31737648224640860538361785861700072557227859645060732743904381890720199497279", "price": "0.14", "size": "130", "side": "BUY", "hash": "9f7b614228b4021988dd3c4c8b3c504e59b4e23e", "best_bid": "0.16", "best_ask": "0.18"}, {"asset_id": "40694415003591202786878279287884766002429923551809555441858630935269489320071", "price": "0.86", "size": "130", "side": "SELL", "hash": "d81a36c859267152ab1539cd7c966d56083f6846", "best_bid": "0.82", "best_ask": "0.84"}], "timestamp": "1769384498932", "event_type": "price_change"}}
{"_local_timestamp": "2026-01-25T23:41:39.130164+00:00", "data": {"market": "0xc829edf5ca6961e441c266546064b629c29a9313694689c0768db92810db62ff", "price_changes": [{"asset_id": "31737648224640860538361785861700072557227859645060732743904381890720199497279", "price": "0.14", "size": "227", "side": "BUY", "hash": "8ba486ae28b384bf6a5741163ced260fd3f1e59f", "best_bid": "0.16", "best_ask": "0.18"}, {"asset_id": "40694415003591202786878279287884766002429923551809555441858630935269489320071", "price": "0.86", "size": "227", "side": "SELL", "hash": "83d087ce5c5153126eda841bc187d95ea4490fa6", "best_bid": "0.82", "best_ask": "0.84"}], "timestamp": "1769384498977", "event_type": "price_change"}}
{"_local_timestamp": "2026-01-25T23:41:39.943281+00:00", "data": {"market": "0x0ea8005efbc460378340a2f28a6d97b0d1d9d9d7fba4d16f529b8a415dca77a2", "price_changes": [{"asset_id": "48266425622404486484896353767723266081505997963592758694068789352158715350186", "price": "0.33", "size": "58.31", "side": "BUY", "hash": "082372b43918bd5733e41b913ddf647e35d1c698", "best_bid": "0.37", "best_ask": "0.39"}, {"asset_id": "71552623345730992280501476931299615437386807576519105089437764117985071980606", "price": "0.67", "size": "58.31", "side": "SELL", "hash": "437c417e3266e658f1a3790722eeac2c1d427fdd", "best_bid": "0.61", "best_ask": "0.63"}], "timestamp": "1769384499801", "event_type": "price_change"}}
{"_local_timestamp": "2026-01-25T23:41:40.033987+00:00", "data": {"market": "0x0ea8005efbc460378340a2f28a6d97b0d1d9d9d7fba4d16f529b8a415dca77a2", "price_changes": [{"asset_id": "48266425622404486484896353767723266081505997963592758694068789352158715350186", "price": "0.33", "size": "31.51", "side": "BUY", "hash": "871f69408ed855e9579b13e76eff01bcc800be58", "best_bid": "0.37", "best_ask": "0.39"}, {"asset_id": "71552623345730992280501476931299615437386807576519105089437764117985071980606", "price": "0.67", "size": "31.51", "side": "SELL", "hash": "6069dcdfa5101c37a6e24a6dda17328973a8cc65", "best_bid": "0.61", "best_ask": "0.63"}], "timestamp": "1769384499922", "event_type": "price_change"}}
{"_local_timestamp": "2026-01-25T23:41:40.500647+00:00", "data": {"market": "0xc829edf5ca6961e441c266546064b629c29a9313694689c0768db92810db62ff", "price_changes": [{"asset_id": "31737648224640860538361785861700072557227859645060732743904381890720199497279", "price": "0.14", "size": "130", "side": "BUY", "hash": "9e8b32325ea5eec25c317678bac1ded5ecd3127d", "best_bid": "0.16", "best_ask": "0.18"}, {"asset_id": "40694415003591202786878279287884766002429923551809555441858630935269489320071", "price": "0.86", "size": "130", "side": "SELL", "hash": "cb43ca10294d0f5ad0e422a6a7bcc739e763210f", "best_bid": "0.82", "best_ask": "0.84"}], "timestamp": "1769384500433", "event_type": "price_change"}}
{"_local_timestamp": "2026-01-25T23:41:40.524497+00:00", "data": {"market": "0xc829edf5ca6961e441c266546064b629c29a9313694689c0768db92810db62ff", "price_changes": [{"asset_id": "31737648224640860538361785861700072557227859645060732743904381890720199497279", "price": "0.14", "size": "227", "side": "BUY", "hash": "31a9f305f1954a1ac4e576effdf64276e50edffd", "best_bid": "0.16", "best_ask": "0.18"}, {"asset_id": "40694415003591202786878279287884766002429923551809555441858630935269489320071", "price": "0.86", "size": "227", "side": "SELL", "hash": "d2ff79a436428c5e9af58afdd1717b28b96fd773", "best_bid": "0.82", "best_ask": "0.84"}], "timestamp": "1769384500463", "event_type": "price_change"}}
{"_local_timestamp": "2026-01-25T23:41:40.805579+00:00", "data": {"market": "0x32b09f6390252b37d674501527e709016d55581b2c1e544bd4b8167f5f732f4c", "price_changes": [{"asset_id": "90435811253665578014957380826505992530054077692143838383981805324273750424057", "price": "0.48", "size": "97453.54", "side": "BUY", "hash": "b3fe03e2c46d4ceaf07eea04f24bf5d72c390d45", "best_bid": "0.48", "best_ask": "0.49"}, {"asset_id": "92388629082681805622801622703528982922543286352927708208755887536971583436902", "price": "0.52", "size": "97453.54", "side": "SELL", "hash": "e1cc5ab8dbfb71507e66be591a45a6af43f62f7c", "best_bid": "0.51", "best_ask": "0.52"}], "timestamp": "1769384500731", "event_type": "price_change"}}
{"_local_timestamp": "2026-01-25T23:41:41.094467+00:00", "data": {"market": "0x32b09f6390252b37d674501527e709016d55581b2c1e544bd4b8167f5f732f4c", "price_changes": [{"asset_id": "90435811253665578014957380826505992530054077692143838383981805324273750424057", "price": "0.48", "size": "97463.54", "side": "BUY", "hash": "8f1dd4c2edba69ca01814d85ad47499296acb52f", "best_bid": "0.48", "best_ask": "0.49"}, {"asset_id": "92388629082681805622801622703528982922543286352927708208755887536971583436902", "price": "0.52", "size": "97463.54", "side": "SELL", "hash": "3ffc7c62754096e917da02d06bdb57a63bea9958", "best_bid": "0.51", "best_ask": "0.52"}], "timestamp": "1769384501018", "event_type": "price_change"}}
{"_local_timestamp": "2026-01-25T23:41:42.026868+00:00", "data": {"market": "0xc829edf5ca6961e441c266546064b629c29a9313694689c0768db92810db62ff", "price_changes": [{"asset_id": "31737648224640860538361785861700072557227859645060732743904381890720199497279", "price": "0.14", "size": "130", "side": "BUY", "hash": "a13add139462c3a0ea8001067801c8b4c07ba747", "best_bid": "0.16", "best_ask": "0.18"}, {"asset_id": "40694415003591202786878279287884766002429923551809555441858630935269489320071", "price": "0.86", "size": "130", "side": "SELL", "hash": "69096045702b993fd1f671947db1744248f29709", "best_bid": "0.82", "best_ask": "0.84"}], "timestamp": "1769384501932", "event_type": "price_change"}}
{"_local_timestamp": "2026-01-25T23:41:42.044410+00:00", "data": {"market": "0xc829edf5ca6961e441c266546064b629c29a9313694689c0768db92810db62ff", "price_changes": [{"asset_id": "31737648224640860538361785861700072557227859645060732743904381890720199497279", "price": "0.14", "size": "227", "side": "BUY", "hash": "3f588dae66f6208df831ceefe95b0c63f176a675", "best_bid": "0.16", "best_ask": "0.18"}, {"asset_id": "40694415003591202786878279287884766002429923551809555441858630935269489320071", "price": "0.86", "size": "227", "side": "SELL", "hash": "a5afebd6e8b3301b59667af630550d48f98f151c", "best_bid": "0.82", "best_ask": "0.84"}], "timestamp": "1769384501957", "event_type": "price_change"}}
{"_local_timestamp": "2026-01-25T23:41:42.478191+00:00", "data": {"market": "0xbb57ccf5853a85487bc3d83d04d669310d28c6c810758953b9d9b91d1aee89d2", "price_changes": [{"asset_id": "105267568073659068217311993901927962476298440625043565106676088842803600775810", "price": "0.48", "size": "137492.95", "side": "BUY", "hash": "da9f355cbdbac9c6f949eb1a2a14a5d25d064466", "best_bid": "0.48", "best_ask": "0.49"}, {"asset_id": "91863162118308663069733924043159186005106558783397508844234610341221325526200", "price": "0.52", "size": "137492.95", "side": "SELL", "hash": "fd389828d33266bf454f695b0524e0ad1aa02e24", "best_bid": "0.51", "best_ask": "0.52"}], "timestamp": "1769384502412", "event_type": "price_change"}}
{"_local_timestamp": "2026-01-25T23:41:43.137971+00:00", "data": {"market": "0xbb57ccf5853a85487bc3d83d04d669310d28c6c810758953b9d9b91d1aee89d2", "price_changes": [{"asset_id": "91863162118308663069733924043159186005106558783397508844234610341221325526200", "price": "0.51", "size": "86793.87", "side": "BUY", "hash": "30fddd8f226e29731585a7fb9af9be40277cf4c2", "best_bid": "0.51", "best_ask": "0.52"}, {"asset_id": "105267568073659068217311993901927962476298440625043565106676088842803600775810", "price": "0.49", "size": "86793.87", "side": "SELL", "hash": "9ae14788911049fcdfb0389a7429b1fd5806c349", "best_bid": "0.48", "best_ask": "0.49"}], "timestamp": "1769384503074", "event_type": "price_change"}}
{"_local_timestamp": "2026-01-25T23:41:43.501933+00:00", "data": {"market": "0xc829edf5ca6961e441c266546064b629c29a9313694689c0768db92810db62ff", "price_changes": [{"asset_id": "31737648224640860538361785861700072557227859645060732743904381890720199497279", "price": "0.14", "size": "130", "side": "BUY", "hash": "d55bf59bd93605405e8afd59ef43029edff51619", "best_bid": "0.16", "best_ask": "0.18"}, {"asset_id": "40694415003591202786878279287884766002429923551809555441858630935269489320071", "price": "0.86", "size": "130", "side": "SELL", "hash": "7d8c9ddfda4e92264a7b7fb47b8bdf874e0d8a74", "best_bid": "0.82", "best_ask": "0.84"}], "timestamp": "1769384503431", "event_type": "price_change"}}
{"_local_timestamp": "2026-01-25T23:41:43.527293+00:00", "data": {"market": "0xc829edf5ca6961e441c266546064b629c29a9313694689c0768db92810db62ff", "price_changes": [{"asset_id": "31737648224640860538361785861700072557227859645060732743904381890720199497279", "price": "0.14", "size": "227", "side": "BUY", "hash": "fd580a3d0101e2353a4074aaf171d0ef3ad7c687", "best_bid": "0.16", "best_ask": "0.18"}, {"asset_id": "40694415003591202786878279287884766002429923551809555441858630935269489320071", "price": "0.86", "size": "227", "side": "SELL", "hash": "f36d92b5b92a76aaf7474eb4844685b7b51cb435", "best_bid": "0.82", "best_ask": "0.84"}], "timestamp": "1769384503460", "event_type": "price_change"}}
{"_local_timestamp": "2026-01-25T23:41:44.080051+00:00", "data": {"market": "0x84f8b70331323c2fba97d7ceaa9a35fb645a0770d0dbff169d07f24f376766e9", "price_changes": [{"asset_id": "108999723207897941876452935557011604067917389120996960199512481363958770540884", "price": "0.18", "size": "2517.33", "side": "BUY", "hash": "5aa355de7b0b83ce7f61e287d005f516d44a36d9", "best_bid": "0.51", "best_ask": "0.53"}, {"asset_id": "64533579809297525579033609963634939501013332859992608996100633472507000251907", "price": "0.82", "size": "2517.33", "side": "SELL", "hash": "340b757029c8f891b75ef235e5f216e6c1ef4950", "best_bid": "0.47", "best_ask": "0.49"}], "timestamp": "1769384504000", "event_type": "price_change"}}
{"_local_timestamp": "2026-01-25T23:41:44.394894+00:00", "data": {"market": "0x84f8b70331323c2fba97d7ceaa9a35fb645a0770d0dbff169d07f24f376766e9", "price_changes": [{"asset_id": "108999723207897941876452935557011604067917389120996960199512481363958770540884", "price": "0.56", "size": "0", "side": "SELL", "hash": "a43d77459c57768dad205f26261e179a5ce87a81", "best_bid": "0.51", "best_ask": "0.53"}, {"asset_id": "64533579809297525579033609963634939501013332859992608996100633472507000251907", "price": "0.44", "size": "0", "side": "BUY", "hash": "b4fa6f673866d2a151e54108026cbd9c499b4bfb", "best_bid": "0.47", "best_ask": "0.49"}], "timestamp": "1769384504325", "event_type": "price_change"}}
{"_local_timestamp": "2026-01-25T23:41:44.418705+00:00", "data": {"market": "0x84f8b70331323c2fba97d7ceaa9a35fb645a0770d0dbff169d07f24f376766e9", "price_changes": [{"asset_id": "108999723207897941876452935557011604067917389120996960199512481363958770540884", "price": "0.56", "size": "12.69", "side": "SELL", "hash": "f70d44326391f37af6ce4d88727eb1391e4d27f6", "best_bid": "0.51", "best_ask": "0.53"}, {"asset_id": "64533579809297525579033609963634939501013332859992608996100633472507000251907", "price": "0.44", "size": "12.69", "side": "BUY", "hash": "93ef019690ed1edfb40167a44d29361f7958dee6", "best_bid": "0.47", "best_ask": "0.49"}], "timestamp": "1769384504350", "event_type": "price_change"}}
{"_local_timestamp": "2026-01-25T23:41:44.921513+00:00", "data": {"market": "0x0ea8005efbc460378340a2f28a6d97b0d1d9d9d7fba4d16f529b8a415dca77a2", "price_changes": [{"asset_id": "48266425622404486484896353767723266081505997963592758694068789352158715350186", "price": "0.33", "size": "58.31", "side": "BUY", "hash": "173ffc1af06552fb90fc29ccc554e4fa99652b58", "best_bid": "0.37", "best_ask": "0.39"}, {"asset_id": "71552623345730992280501476931299615437386807576519105089437764117985071980606", "price": "0.67", "size": "58.31", "side": "SELL", "hash": "5371148997ff5df736924fb7ff92820c9ad78a4a", "best_bid": "0.61", "best_ask": "0.63"}], "timestamp": "1769384504852", "event_type": "price_change"}}
{"_local_timestamp": "2026-01-25T23:41:45.004044+00:00", "data": {"market": "0xc829edf5ca6961e441c266546064b629c29a9313694689c0768db92810db62ff", "price_changes": [{"asset_id": "31737648224640860538361785861700072557227859645060732743904381890720199497279", "price": "0.14", "size": "130", "side": "BUY", "hash": "afc5fbab475167c609e31861fd63bf2a0b82c514", "best_bid": "0.16", "best_ask": "0.18"}, {"asset_id": "40694415003591202786878279287884766002429923551809555441858630935269489320071", "price": "0.86", "size": "130", "side": "SELL", "hash": "b80fc451e8f1fd1df5b36176dc3b99cae283f907", "best_bid": "0.82", "best_ask": "0.84"}], "timestamp": "1769384504934", "event_type": "price_change"}}
{"_local_timestamp": "2026-01-25T23:41:45.034898+00:00", "data": {"market": "0xc829edf5ca6961e441c266546064b629c29a9313694689c0768db92810db62ff", "price_changes": [{"asset_id": "31737648224640860538361785861700072557227859645060732743904381890720199497279", "price": "0.14", "size": "227", "side": "BUY", "hash": "4f39f5800afffbaac1f988501e62d013a639e9dc", "best_bid": "0.16", "best_ask": "0.18"}, {"asset_id": "40694415003591202786878279287884766002429923551809555441858630935269489320071", "price": "0.86", "size": "227", "side": "SELL", "hash": "f2150d5d7746a179c01ae229c57edb05457dcb5a", "best_bid": "0.82", "best_ask": "0.84"}], "timestamp": "1769384504960", "event_type": "price_change"}}
{"_local_timestamp": "2026-01-25T23:41:45.048554+00:00", "data": {"market": "0x0ea8005efbc460378340a2f28a6d97b0d1d9d9d7fba4d16f529b8a415dca77a2", "price_changes": [{"asset_id": "48266425622404486484896353767723266081505997963592758694068789352158715350186", "price": "0.33", "size": "31.51", "side": "BUY", "hash": "a5525897809dad5ae97614653b2610566c5db0b5", "best_bid": "0.37", "best_ask": "0.39"}, {"asset_id": "71552623345730992280501476931299615437386807576519105089437764117985071980606", "price": "0.67", "size": "31.51", "side": "SELL", "hash": "e5a36a892f581220d14c8ccc76194fba775c9348", "best_bid": "0.61", "best_ask": "0.63"}], "timestamp": "1769384504976", "event_type": "price_change"}}
{"_local_timestamp": "2026-01-25T23:41:46.510579+00:00", "data": {"market": "0xc829edf5ca6961e441c266546064b629c29a9313694689c0768db92810db62ff", "price_changes": [{"asset_id": "31737648224640860538361785861700072557227859645060732743904381890720199497279", "price": "0.14", "size": "130", "side": "BUY", "hash": "3158c5b0565f3c3b9a5d4bbd8d3f5eeb512d2d6f", "best_bid": "0.16", "best_ask": "0.18"}, {"asset_id": "40694415003591202786878279287884766002429923551809555441858630935269489320071", "price": "0.86", "size": "130", "side": "SELL", "hash": "df4c09d3095cc7c3921781af2874482d4e517e40", "best_bid": "0.82", "best_ask": "0.84"}], "timestamp": "1769384506434", "event_type": "price_change"}}
{"_local_timestamp": "2026-01-25T23:41:46.535923+00:00", "data": {"market": "0xc829edf5ca6961e441c266546064b629c29a9313694689c0768db92810db62ff", "price_changes": [{"asset_id": "31737648224640860538361785861700072557227859645060732743904381890720199497279", "price": "0.14", "size": "227", "side": "BUY", "hash": "352fbb42fc4f90e232cd0d228736c4aa493696f4", "best_bid": "0.16", "best_ask": "0.18"}, {"asset_id": "40694415003591202786878279287884766002429923551809555441858630935269489320071", "price": "0.86", "size": "227", "side": "SELL", "hash": "eb397e8818a9416012919df225bb2815ac9485ac", "best_bid": "0.82", "best_ask": "0.84"}], "timestamp": "1769384506460", "event_type": "price_change"}}
{"_local_timestamp": "2026-01-25T23:41:47.461148+00:00", "data": {"market": "0x84f8b70331323c2fba97d7ceaa9a35fb645a0770d0dbff169d07f24f376766e9", "price_changes": [{"asset_id": "108999723207897941876452935557011604067917389120996960199512481363958770540884", "price": "0.18", "size": "2522.33", "side": "BUY", "hash": "3eadf124be10f1f5b56fce41a8e206d6d91961dc", "best_bid": "0.51", "best_ask": "0.53"}, {"asset_id": "64533579809297525579033609963634939501013332859992608996100633472507000251907", "price": "0.82", "size": "2522.33", "side": "SELL", "hash": "c3f7b33b3389fbb6b4f1d44e105e7032992e371b", "best_bid": "0.47", "best_ask": "0.49"}], "timestamp": "1769384507399", "event_type": "price_change"}}
{"_local_timestamp": "2026-01-25T23:41:47.750185+00:00", "data": {"market": "0x0ea8005efbc460378340a2f28a6d97b0d1d9d9d7fba4d16f529b8a415dca77a2", "price_changes": [{"asset_id": "71552623345730992280501476931299615437386807576519105089437764117985071980606", "price": "0.67", "size": "0", "side": "SELL", "hash": "0a151ba3a83612138d51bbc0d4abfae559540bab", "best_bid": "0.61", "best_ask": "0.63"}, {"asset_id": "48266425622404486484896353767723266081505997963592758694068789352158715350186", "price": "0.33", "size": "0", "side": "BUY", "hash": "8c3fa1eeaf774243a69312ca45acd1064f141c4a", "best_bid": "0.37", "best_ask": "0.39"}], "timestamp": "1769384507679", "event_type": "price_change"}}
{"_local_timestamp": "2026-01-25T23:41:47.769758+00:00", "data": {"market": "0x0ea8005efbc460378340a2f28a6d97b0d1d9d9d7fba4d16f529b8a415dca77a2", "price_changes": [{"asset_id": "71552623345730992280501476931299615437386807576519105089437764117985071980606", "price": "0.66", "size": "51.61", "side": "SELL", "hash": "b9302df882a90c75f705a813863055a214c2d0e9", "best_bid": "0.61", "best_ask": "0.63"}, {"asset_id": "48266425622404486484896353767723266081505997963592758694068789352158715350186", "price": "0.34", "size": "51.61", "side": "BUY", "hash": "9f07e1c4d445f6be09cbe7b4879cc1dc231e1dd2", "best_bid": "0.37", "best_ask": "0.39"}], "timestamp": "1769384507698", "event_type": "price_change"}}
{"_local_timestamp": "2026-01-25T23:41:47.899511+00:00", "data": {"market": "0x84f8b70331323c2fba97d7ceaa9a35fb645a0770d0dbff169d07f24f376766e9", "price_changes": [{"asset_id": "108999723207897941876452935557011604067917389120996960199512481363958770540884", "price": "0.56", "size": "0", "side": "SELL", "hash": "af1b88ff6e01521dd645ccbf0213a73ec34683e4", "best_bid": "0.51", "best_ask": "0.53"}, {"asset_id": "64533579809297525579033609963634939501013332859992608996100633472507000251907", "price": "0.44", "size": "0", "side": "BUY", "hash": "41bb86aad794f4c7e01da983b5cbffd03db3d1f8", "best_bid": "0.47", "best_ask": "0.49"}], "timestamp": "1769384507824", "event_type": "price_change"}}
{"_local_timestamp": "2026-01-25T23:41:47.930556+00:00", "data": {"market": "0x84f8b70331323c2fba97d7ceaa9a35fb645a0770d0dbff169d07f24f376766e9", "price_changes": [{"asset_id": "108999723207897941876452935557011604067917389120996960199512481363958770540884", "price": "0.56", "size": "12.69", "side": "SELL", "hash": "3e3d12ea150c5dbbf68ac1da9a7ee0f8c0e2c4c9", "best_bid": "0.51", "best_ask": "0.53"}, {"asset_id": "64533579809297525579033609963634939501013332859992608996100633472507000251907", "price": "0.44", "size": "12.69", "side": "BUY", "hash": "3b978d36b43e72ce19f2b72dc5056e48f319380a", "best_bid": "0.47", "best_ask": "0.49"}], "timestamp": "1769384507865", "event_type": "price_change"}}
{"_local_timestamp": "2026-01-25T23:41:48.000836+00:00", "data": {"market": "0xc829edf5ca6961e441c266546064b629c29a9313694689c0768db92810db62ff", "price_changes": [{"asset_id": "31737648224640860538361785861700072557227859645060732743904381890720199497279", "price": "0.14", "size": "130", "side": "BUY", "hash": "b2d4213bf4814f4a97af9e2693d0a586f7bce813", "best_bid": "0.16", "best_ask": "0.18"}, {"asset_id": "40694415003591202786878279287884766002429923551809555441858630935269489320071", "price": "0.86", "size": "130", "side": "SELL", "hash": "57b86b295fef8fff21de370e5041c1aa0707bb27", "best_bid": "0.82", "best_ask": "0.84"}], "timestamp": "1769384507932", "event_type": "price_change"}}
{"_local_timestamp": "2026-01-25T23:41:48.216935+00:00", "data": {"market": "0x84f8b70331323c2fba97d7ceaa9a35fb645a0770d0dbff169d07f24f376766e9", "price_changes": [{"asset_id": "108999723207897941876452935557011604067917389120996960199512481363958770540884", "price": "0.56", "size": "0", "side": "SELL", "hash": "9a969058206ef03cb6c26e8c2ee7becd1e7be3c9", "best_bid": "0.51", "best_ask": "0.53"}, {"asset_id": "64533579809297525579033609963634939501013332859992608996100633472507000251907", "price": "0.44", "size": "0", "side": "BUY", "hash": "32c1424e6dc3651f03ec45e042a9378eccfd9482", "best_bid": "0.47", "best_ask": "0.49"}], "timestamp": "1769384508146", "event_type": "price_change"}}
{"_local_timestamp": "2026-01-25T23:41:48.226241+00:00", "data": {"market": "0x84f8b70331323c2fba97d7ceaa9a35fb645a0770d0dbff169d07f24f376766e9", "price_changes": [{"asset_id": "108999723207897941876452935557011604067917389120996960199512481363958770540884", "price": "0.56", "size": "12.69", "side": "SELL", "hash": "3f3b8214cd498913ac7685a6f210d34410440123", "best_bid": "0.51", "best_ask": "0.53"}, {"asset_id": "64533579809297525579033609963634939501013332859992608996100633472507000251907", "price": "0.44", "size": "12.69", "side": "BUY", "hash": "4911d05ca193ecc8f0bc6abcd757498decd8eb93", "best_bid": "0.47", "best_ask": "0.49"}], "timestamp": "1769384508163", "event_type": "price_change"}}
{"_local_timestamp": "2026-01-25T23:41:48.761191+00:00", "data": {"market": "0xbb57ccf5853a85487bc3d83d04d669310d28c6c810758953b9d9b91d1aee89d2", "price_changes": [{"asset_id": "105267568073659068217311993901927962476298440625043565106676088842803600775810", "price": "0.48", "size": "137505.39", "side": "BUY", "hash": "ad08cfea6be597102384e5822f87a4c1daaf580a", "best_bid": "0.48", "best_ask": "0.49"}, {"asset_id": "91863162118308663069733924043159186005106558783397508844234610341221325526200", "price": "0.52", "size": "137505.39", "side": "SELL", "hash": "cc74225c20be4072f2e025b7ec3ba7248689e22d", "best_bid": "0.51", "best_ask": "0.52"}], "timestamp": "1769384508698", "event_type": "price_change"}}
{"_local_timestamp": "2026-01-25T23:41:49.446867+00:00", "data": {"market": "0x0ea8005efbc460378340a2f28a6d97b0d1d9d9d7fba4d16f529b8a415dca77a2", "price_changes": [{"asset_id": "71552623345730992280501476931299615437386807576519105089437764117985071980606", "price": "0.19", "size": "2210", "side": "BUY", "hash": "7377b830f89e973ca110fbc2922c4121a829ec6f", "best_bid": "0.61", "best_ask": "0.63"}, {"asset_id": "48266425622404486484896353767723266081505997963592758694068789352158715350186", "price": "0.81", "size": "2210", "side": "SELL", "hash": "b7c583de876bfc523a964e1c7e225170a703129c", "best_bid": "0.37", "best_ask": "0.39"}], "timestamp": "1769384509381", "event_type": "price_change"}}
{"_local_timestamp": "2026-01-25T23:41:49.450176+00:00", "data": {"market": "0x0ea8005efbc460378340a2f28a6d97b0d1d9d9d7fba4d16f529b8a415dca77a2", "price_changes": [{"asset_id": "71552623345730992280501476931299615437386807576519105089437764117985071980606", "price": "0.21", "size": "0", "side": "BUY", "hash": "7377b830f89e973ca110fbc2922c4121a829ec6f", "best_bid": "0.61", "best_ask": "0.63"}, {"asset_id": "48266425622404486484896353767723266081505997963592758694068789352158715350186", "price": "0.79", "size": "0", "side": "SELL", "hash": "b7c583de876bfc523a964e1c7e225170a703129c", "best_bid": "0.37", "best_ask": "0.39"}], "timestamp": "1769384509381", "event_type": "price_change"}}
{"_local_timestamp": "2026-01-25T23:41:49.774575+00:00", "data": {"market": "0x0ea8005efbc460378340a2f28a6d97b0d1d9d9d7fba4d16f529b8a415dca77a2", "price_changes": [{"asset_id": "71552623345730992280501476931299615437386807576519105089437764117985071980606", "price": "0.23", "size": "204.34", "side": "BUY", "hash": "6a18162e3408685a70ec4b0f4e7a5a5b41d2ddef", "best_bid": "0.61", "best_ask": "0.63"}, {"asset_id": "48266425622404486484896353767723266081505997963592758694068789352158715350186", "price": "0.77", "size": "204.34", "side": "SELL", "hash": "67ca82b50f980f1f37808eb0a5061c810f9c0bfe", "best_bid": "0.37", "best_ask": "0.39"}], "timestamp": "1769384509664", "event_type": "price_change"}}
{"_local_timestamp": "2026-01-25T23:41:49.781922+00:00", "data": {"market": "0x0ea8005efbc460378340a2f28a6d97b0d1d9d9d7fba4d16f529b8a415dca77a2", "price_changes": [{"asset_id": "71552623345730992280501476931299615437386807576519105089437764117985071980606", "price": "0.2", "size": "3080", "side": "BUY", "hash": "9a73d629a3e9273a54dd97bb29b530838de8549d", "best_bid": "0.61", "best_ask": "0.63"}, {"asset_id": "48266425622404486484896353767723266081505997963592758694068789352158715350186", "price": "0.8", "size": "3080", "side": "SELL", "hash": "60a23b0d0227d8c028f354f89dee9224ece32fa0", "best_bid": "0.37", "best_ask": "0.39"}], "timestamp": "1769384509671", "event_type": "price_change"}}
{"_local_timestamp": "2026-01-25T23:41:49.942717+00:00", "data": {"market": "0x0ea8005efbc460378340a2f28a6d97b0d1d9d9d7fba4d16f529b8a415dca77a2", "price_changes": [{"asset_id": "48266425622404486484896353767723266081505997963592758694068789352158715350186", "price": "0.33", "size": "26.8", "side": "BUY", "hash": "788b3d63109e7f4bb3a8fc29e6dd07529a6e90ca", "best_bid": "0.37", "best_ask": "0.39"}, {"asset_id": "71552623345730992280501476931299615437386807576519105089437764117985071980606", "price": "0.67", "size": "26.8", "side": "SELL", "hash": "f26e1d6213bcad3022cac166afd170d8b575a894", "best_bid": "0.61", "best_ask": "0.63"}], "timestamp": "1769384509862", "event_type": "price_change"}}
{"_local_timestamp": "2026-01-25T23:41:50.053183+00:00", "data": {"market": "0x0ea8005efbc460378340a2f28a6d97b0d1d9d9d7fba4d16f529b8a415dca77a2", "price_changes": [{"asset_id": "48266425622404486484896353767723266081505997963592758694068789352158715350186", "price": "0.33", "size": "0", "side": "BUY", "hash": "82e9be7e8e2aa7f83e0a0b16ea4b0956144d77bf", "best_bid": "0.37", "best_ask": "0.39"}, {"asset_id": "71552623345730992280501476931299615437386807576519105089437764117985071980606", "price": "0.67", "size": "0", "side": "SELL", "hash": "8eee6ad55be64daed6ae186b43efff1edd69aacb", "best_bid": "0.61", "best_ask": "0.63"}], "timestamp": "1769384509989", "event_type": "price_change"}}
{"_local_timestamp": "2026-01-25T23:41:50.661200+00:00", "data": {"market": "0xbb57ccf5853a85487bc3d83d04d669310d28c6c810758953b9d9b91d1aee89d2", "price_changes": [{"asset_id": "91863162118308663069733924043159186005106558783397508844234610341221325526200", "price": "0.51", "size": "86805.58", "side": "BUY", "hash": "ce91927c6c011a5c7755cdd94c24f6e67d94ba24", "best_bid": "0.51", "best_ask": "0.52"}, {"asset_id": "105267568073659068217311993901927962476298440625043565106676088842803600775810", "price": "0.49", "size": "86805.58", "side": "SELL", "hash": "75430e1c61920024aba6bc1a077d2efd21ca5963", "best_bid": "0.48", "best_ask": "0.49"}], "timestamp": "1769384510589", "event_type": "price_change"}}
{"_local_timestamp": "2026-01-25T23:41:51.058397+00:00", "data": {"market": "0x0ea8005efbc460378340a2f28a6d97b0d1d9d9d7fba4d16f529b8a415dca77a2", "price_changes": [{"asset_id": "71552623345730992280501476931299615437386807576519105089437764117985071980606", "price": "0.2", "size": "2930", "side": "BUY", "hash": "72ae5d4c4a83ce560d8dae114083f3a4dea78a7b", "best_bid": "0.61", "best_ask": "0.63"}, {"asset_id": "48266425622404486484896353767723266081505997963592758694068789352158715350186", "price": "0.8", "size": "2930", "side": "SELL", "hash": "c93908f5819ad61016e4ac603697bde373f8642e", "best_bid": "0.37", "best_ask": "0.39"}], "timestamp": "1769384510986", "event_type": "price_change"}}
{"_local_timestamp": "2026-01-25T23:41:51.060962+00:00", "data": {"market": "0xc829edf5ca6961e441c266546064b629c29a9313694689c0768db92810db62ff", "price_changes": [{"asset_id": "40694415003591202786878279287884766002429923551809555441858630935269489320071", "price": "0.24", "size": "100", "side": "BUY", "hash": "f44072fc502ebcb18087efe0938868e41a867aee", "best_bid": "0.82", "best_ask": "0.84"}, {"asset_id": "31737648224640860538361785861700072557227859645060732743904381890720199497279", "price": "0.76", "size": "100", "side": "SELL", "hash": "3c3a1f342f335762cfbed0bf1f64d618231e6b09", "best_bid": "0.16", "best_ask": "0.18"}], "timestamp": "1769384510986", "event_type": "price_change"}}
{"_local_timestamp": "2026-01-25T23:41:51.063368+00:00", "data": {"market": "0x50ddb9cd80d5c271664a2ebb7fcaed1d0a148d82c8e8d314d830f75a944c3dcc", "price_changes": [{"asset_id": "94376205816022955542979635542279932967359915765455578534002478996104754801969", "price": "0.08", "size": "4085", "side": "BUY", "hash": "0f84a0e8f66b118559a48ed4a6fc5c069c3adb76", "best_bid": "0.41", "best_ask": "0.47"}, {"asset_id": "88275040060084773376557187972215267513049848642895776801789297917961077894224", "price": "0.92", "size": "4085", "side": "SELL", "hash": "d7cf86597c2837cf325d0f85a731d62b3219886b", "best_bid": "0.53", "best_ask": "0.59"}], "timestamp": "1769384510986", "event_type": "price_change"}}
{"_local_timestamp": "2026-01-25T23:41:51.065782+00:00", "data": {"market": "0xbb57ccf5853a85487bc3d83d04d669310d28c6c810758953b9d9b91d1aee89d2", "price_changes": [{"asset_id": "105267568073659068217311993901927962476298440625043565106676088842803600775810", "price": "0.15", "size": "2923", "side": "BUY", "hash": "b281d6542b57d6cb6153c0f114ce6c078f4fc8a4", "best_bid": "0.48", "best_ask": "0.49"}, {"asset_id": "91863162118308663069733924043159186005106558783397508844234610341221325526200", "price": "0.85", "size": "2923", "side": "SELL", "hash": "5748cfbe133fc5c44ea9182f65cfa609bf045a9a", "best_bid": "0.51", "best_ask": "0.52"}], "timestamp": "1769384510986", "event_type": "price_change"}}
{"_local_timestamp": "2026-01-25T23:41:51.068110+00:00", "data": {"market": "0x32b09f6390252b37d674501527e709016d55581b2c1e544bd4b8167f5f732f4c", "price_changes": [{"asset_id": "90435811253665578014957380826505992530054077692143838383981805324273750424057", "price": "0.22", "size": "315.38", "side": "BUY", "hash": "2d4463cc9cc1cf121602e1fa1507173839df1524", "best_bid": "0.48", "best_ask": "0.49"}, {"asset_id": "92388629082681805622801622703528982922543286352927708208755887536971583436902", "price": "0.78", "size": "315.38", "side": "SELL", "hash": "d4ba62dcfa997bdb4777fc107ad4dbfce124986e", "best_bid": "0.51", "best_ask": "0.52"}], "timestamp": "1769384510986", "event_type": "price_change"}}
{"_local_timestamp": "2026-01-25T23:41:51.070901+00:00", "data": {"market": "0x50ddb9cd80d5c271664a2ebb7fcaed1d0a148d82c8e8d314d830f75a944c3dcc", "price_changes": [{"asset_id": "88275040060084773376557187972215267513049848642895776801789297917961077894224", "price": "0.21", "size": "114.28", "side": "BUY", "hash": "d65f838abd88b39ffd1bf685ad7dccd28cb48227", "best_bid": "0.53", "best_ask": "0.59"}, {"asset_id": "94376205816022955542979635542279932967359915765455578534002478996104754801969", "price": "0.79", "size": "114.28", "side": "SELL", "hash": "6f8af470fa7cd519d73774c4fc10ae4ac52ceaf4", "best_bid": "0.41", "best_ask": "0.47"}], "timestamp": "1769384510987", "event_type": "price_change"}}
{"_local_timestamp": "2026-01-25T23:41:51.587129+00:00", "data": {"market": "0x0ea8005efbc460378340a2f28a6d97b0d1d9d9d7fba4d16f529b8a415dca77a2", "price_changes": [{"asset_id": "71552623345730992280501476931299615437386807576519105089437764117985071980606", "price": "0.2", "size": "430", "side": "BUY", "hash": "da00f65f0c02c3dc5d93a6286737b112918cac9d", "best_bid": "0.61", "best_ask": "0.63"}, {"asset_id": "48266425622404486484896353767723266081505997963592758694068789352158715350186", "price": "0.8", "size": "430", "side": "SELL", "hash": "602c43032c234c60c2edad5dfa02bcc70c3e7a07", "best_bid": "0.37", "best_ask": "0.39"}], "timestamp": "1769384511522", "event_type": "price_change"}}
{"_local_timestamp": "2026-01-25T23:41:51.589819+00:00", "data": {"market": "0x0ea8005efbc460378340a2f28a6d97b0d1d9d9d7fba4d16f529b8a415dca77a2", "price_changes": [{"asset_id": "71552623345730992280501476931299615437386807576519105089437764117985071980606", "price": "0.66", "size": "20.1", "side": "SELL", "hash": "da00f65f0c02c3dc5d93a6286737b112918cac9d", "best_bid": "0.61", "best_ask": "0.63"}, {"asset_id": "48266425622404486484896353767723266081505997963592758694068789352158715350186", "price": "0.34", "size": "20.1", "side": "BUY", "hash": "602c43032c234c60c2edad5dfa02bcc70c3e7a07", "best_bid": "0.37", "best_ask": "0.39"}], "timestamp": "1769384511522", "event_type": "price_change"}}
{"_local_timestamp": "2026-01-25T23:41:51.646218+00:00", "data": {"market": "0x0ea8005efbc460378340a2f28a6d97b0d1d9d9d7fba4d16f529b8a415dca77a2", "price_changes": [{"asset_id": "71552623345730992280501476931299615437386807576519105089437764117985071980606", "price": "0.67", "size": "31.51", "side": "SELL", "hash": "43ca87486c6605ce9fc131cbcbdd0c39448df241", "best_bid": "0.61", "best_ask": "0.63"}, {"asset_id": "48266425622404486484896353767723266081505997963592758694068789352158715350186", "price": "0.33", "size": "31.51", "side": "BUY", "hash": "5d1929a6b68294a8f285d27676e8f22d2cb8ea06", "best_bid": "0.37", "best_ask": "0.39"}], "timestamp": "1769384511573", "event_type": "price_change"}}
{"_local_timestamp": "2026-01-25T23:41:51.663613+00:00", "data": {"market": "0x0ea8005efbc460378340a2f28a6d97b0d1d9d9d7fba4d16f529b8a415dca77a2", "price_changes": [{"asset_id": "71552623345730992280501476931299615437386807576519105089437764117985071980606", "price": "0.21", "size": "2381", "side": "BUY", "hash": "2edc3c05ddfea350a1f7b957a6c609390c5783e4", "best_bid": "0.61", "best_ask": "0.63"}, {"asset_id": "48266425622404486484896353767723266081505997963592758694068789352158715350186", "price": "0.79", "size": "2381", "side": "SELL", "hash": "b450123440691847b7564f129f07224da136f739", "best_bid": "0.37", "best_ask": "0.39"}], "timestamp": "1769384511576", "event_type": "price_change"}}
{"_local_timestamp": "2026-01-25T23:41:52.863880+00:00", "data": {"market": "0x0ea8005efbc460378340a2f28a6d97b0d1d9d9d7fba4d16f529b8a415dca77a2", "price_changes": [{"asset_id": "71552623345730992280501476931299615437386807576519105089437764117985071980606", "price": "0.19", "size": "2360", "side": "BUY", "hash": "a43fae7bf5b720562d22596412e81c0ffc1b0c51", "best_bid": "0.61", "best_ask": "0.63"}, {"asset_id": "48266425622404486484896353767723266081505997963592758694068789352158715350186", "price": "0.81", "size": "2360", "side": "SELL", "hash": "efb22de10cb49318a0e508bdf681dc5b14b59601", "best_bid": "0.37", "best_ask": "0.39"}], "timestamp": "1769384511810", "event_type": "price_change"}}
{"_local_timestamp": "2026-01-25T23:41:52.867044+00:00", "data": {"market": "0xbb57ccf5853a85487bc3d83d04d669310d28c6c810758953b9d9b91d1aee89d2", "price_changes": [{"asset_id": "105267568073659068217311993901927962476298440625043565106676088842803600775810", "price": "0.12", "size": "200", "side": "BUY", "hash": "cba55265bbf4832dea151a7ed4af3dd8bf93e02f", "best_bid": "0.48", "best_ask": "0.49"}, {"asset_id": "91863162118308663069733924043159186005106558783397508844234610341221325526200", "price": "0.88", "size": "200", "side": "SELL", "hash": "0c8fe4a0fb4d663eb5e6afa9461271f85cad3776", "best_bid": "0.51", "best_ask": "0.52"}], "timestamp": "1769384511828", "event_type": "price_change"}}
{"_local_timestamp": "2026-01-25T23:41:52.919374+00:00", "data": {"market": "0xc829edf5ca6961e441c266546064b629c29a9313694689c0768db92810db62ff", "price_changes": [{"asset_id": "40694415003591202786878279287884766002429923551809555441858630935269489320071", "price": "0.28", "size": "1200", "side": "BUY", "hash": "141f4962f8ba2e79465a12a4d31cc14d44346b7f", "best_bid": "0.82", "best_ask": "0.84"}, {"asset_id": "31737648224640860538361785861700072557227859645060732743904381890720199497279", "price": "0.72", "size": "1200", "side": "SELL", "hash": "9df4a6d3b5a3b5c0116a5320b64bd7c438264351", "best_bid": "0.16", "best_ask": "0.18"}], "timestamp": "1769384511849", "event_type": "price_change"}}
{"_local_timestamp": "2026-01-25T23:41:54.967220+00:00", "data": {"market": "0x0ea8005efbc460378340a2f28a6d97b0d1d9d9d7fba4d16f529b8a415dca77a2", "price_changes": [{"asset_id": "48266425622404486484896353767723266081505997963592758694068789352158715350186", "price": "0.33", "size": "58.31", "side": "BUY", "hash": "346cda599cb0114e85eab77577fa8f4d3c657942", "best_bid": "0.37", "best_ask": "0.39"}, {"asset_id": "71552623345730992280501476931299615437386807576519105089437764117985071980606", "price": "0.67", "size": "58.31", "side": "SELL", "hash": "6d4314264110ec33e4b2e47cc152d6109a8be32c", "best_bid": "0.61", "best_ask": "0.63"}], "timestamp": "1769384514896", "event_type": "price_change"}}
{"_local_timestamp": "2026-01-25T23:41:55.087285+00:00", "data": {"market": "0x32b09f6390252b37d674501527e709016d55581b2c1e544bd4b8167f5f732f4c", "price_changes": [{"asset_id": "92388629082681805622801622703528982922543286352927708208755887536971583436902", "price": "0.52", "size": "97629.14", "side": "SELL", "hash": "5402cca07491f436c19ea26b707c91f778812330", "best_bid": "0.51", "best_ask": "0.52"}, {"asset_id": "90435811253665578014957380826505992530054077692143838383981805324273750424057", "price": "0.48", "size": "97629.14", "side": "BUY", "hash": "eaf75c81c00115cec8104fe1583d2f0507d0f432", "best_bid": "0.48", "best_ask": "0.49"}], "timestamp": "1769384515021", "event_type": "price_change"}}
{"_local_timestamp": "2026-01-25T23:41:55.089970+00:00", "data": {"market": "0x0ea8005efbc460378340a2f28a6d97b0d1d9d9d7fba4d16f529b8a415dca77a2", "price_changes": [{"asset_id": "48266425622404486484896353767723266081505997963592758694068789352158715350186", "price": "0.33", "size": "31.51", "side": "BUY", "hash": "b8ab93a80143aa976866b679b528f8cdf6daabcc", "best_bid": "0.37", "best_ask": "0.39"}, {"asset_id": "71552623345730992280501476931299615437386807576519105089437764117985071980606", "price": "0.67", "size": "31.51", "side": "SELL", "hash": "44e31d86a6d96453cb35ddb297351a7a6cb5c7f2", "best_bid": "0.61", "best_ask": "0.63"}], "timestamp": "1769384515022", "event_type": "price_change"}}
{"_local_timestamp": "2026-01-25T23:41:59.140018+00:00", "data": {"market": "0x0ea8005efbc460378340a2f28a6d97b0d1d9d9d7fba4d16f529b8a415dca77a2", "price_changes": [{"asset_id": "71552623345730992280501476931299615437386807576519105089437764117985071980606", "price": "0.21", "size": "0", "side": "BUY", "hash": "f247aa71ea548a66e017e495443d94391c68525c", "best_bid": "0.61", "best_ask": "0.63"}, {"asset_id": "48266425622404486484896353767723266081505997963592758694068789352158715350186", "price": "0.79", "size": "0", "side": "SELL", "hash": "2516ba398d5d3cfb0439723beacaa6127c1d0cbc", "best_bid": "0.37", "best_ask": "0.39"}], "timestamp": "1769384519013", "event_type": "price_change"}}
{"_local_timestamp": "2026-01-25T23:41:59.143340+00:00", "data": {"market": "0x0ea8005efbc460378340a2f28a6d97b0d1d9d9d7fba4d16f529b8a415dca77a2", "price_changes": [{"asset_id": "71552623345730992280501476931299615437386807576519105089437764117985071980606", "price": "0.2", "size": "2930", "side": "BUY", "hash": "b63e7151739178cb0321db5918dfe44389239f98", "best_bid": "0.61", "best_ask": "0.63"}, {"asset_id": "48266425622404486484896353767723266081505997963592758694068789352158715350186", "price": "0.8", "size": "2930", "side": "SELL", "hash": "841db2062cc0dff618a91ade45b36c6fdaccbe89", "best_bid": "0.37", "best_ask": "0.39"}], "timestamp": "1769384519032", "event_type": "price_change"}}
{"_local_timestamp": "2026-01-25T23:41:59.725254+00:00", "data": {"market": "0x50ddb9cd80d5c271664a2ebb7fcaed1d0a148d82c8e8d314d830f75a944c3dcc", "price_changes": [{"asset_id": "94376205816022955542979635542279932967359915765455578534002478996104754801969", "price": "0.01", "size": "7510.21", "side": "BUY", "hash": "1a43cb0ee930d3b2b878fa6b9a23a37dfbd0c110", "best_bid": "0.41", "best_ask": "0.47"}, {"asset_id": "88275040060084773376557187972215267513049848642895776801789297917961077894224", "price": "0.99", "size": "7510.21", "side": "SELL", "hash": "b6ffd4b5360f9ec2c84029a48bcf0cf3a538a455", "best_bid": "0.53", "best_ask": "0.59"}], "timestamp": "1769384519658", "event_type": "price_change"}}
{"_local_timestamp": "2026-01-25T23:41:59.992828+00:00", "data": {"market": "0x0ea8005efbc460378340a2f28a6d97b0d1d9d9d7fba4d16f529b8a415dca77a2", "price_changes": [{"asset_id": "48266425622404486484896353767723266081505997963592758694068789352158715350186", "price": "0.33", "size": "58.31", "side": "BUY", "hash": "b87d514e480e64255024bbc57ad57a8a6bac4d69", "best_bid": "0.37", "best_ask": "0.39"}, {"asset_id": "71552623345730992280501476931299615437386807576519105089437764117985071980606", "price": "0.67", "size": "58.31", "side": "SELL", "hash": "b43e4f81fab4c5b0e7dce781751d36bbb76f9d4b", "best_bid": "0.61", "best_ask": "0.63"}], "timestamp": "1769384519923", "event_type": "price_change"}}
{"_local_timestamp": "2026-01-25T23:42:00.135648+00:00", "data": {"market": "0x0ea8005efbc460378340a2f28a6d97b0d1d9d9d7fba4d16f529b8a415dca77a2", "price_changes": [{"asset_id": "48266425622404486484896353767723266081505997963592758694068789352158715350186", "price": "0.33", "size": "31.51", "side": "BUY", "hash": "24781b06a429af63c706639e5ceaa90712aa1d44", "best_bid": "0.37", "best_ask": "0.39"}, {"asset_id": "71552623345730992280501476931299615437386807576519105089437764117985071980606", "price": "0.67", "size": "31.51", "side": "SELL", "hash": "23f4c501d204afa6b35efe2913458467baeb0a64", "best_bid": "0.61", "best_ask": "0.63"}], "timestamp": "1769384520041", "event_type": "price_change"}}
{"_local_timestamp": "2026-01-25T23:42:05.056675+00:00", "data": {"market": "0x0ea8005efbc460378340a2f28a6d97b0d1d9d9d7fba4d16f529b8a415dca77a2", "price_changes": [{"asset_id": "48266425622404486484896353767723266081505997963592758694068789352158715350186", "price": "0.33", "size": "58.31", "side": "BUY", "hash": "e3f51f7556214f0ac5717f1983250b380755adcc", "best_bid": "0.37", "best_ask": "0.39"}, {"asset_id": "71552623345730992280501476931299615437386807576519105089437764117985071980606", "price": "0.67", "size": "58.31", "side": "SELL", "hash": "8862e2a12ebf64d06fa5c38ada5ba1dff7435f9f", "best_bid": "0.61", "best_ask": "0.63"}], "timestamp": "1769384524978", "event_type": "price_change"}}
{"_local_timestamp": "2026-01-25T23:42:05.180618+00:00", "data": {"market": "0x0ea8005efbc460378340a2f28a6d97b0d1d9d9d7fba4d16f529b8a415dca77a2", "price_changes": [{"asset_id": "48266425622404486484896353767723266081505997963592758694068789352158715350186", "price": "0.33", "size": "31.51", "side": "BUY", "hash": "45ae83a90e26cea0f02e6b4d135db06eeb40e7bd", "best_bid": "0.37", "best_ask": "0.39"}, {"asset_id": "71552623345730992280501476931299615437386807576519105089437764117985071980606", "price": "0.67", "size": "31.51", "side": "SELL", "hash": "b6f7adc8626d306754c7bced8f4272574a32634c", "best_bid": "0.61", "best_ask": "0.63"}], "timestamp": "1769384525099", "event_type": "price_change"}}
{"_local_timestamp": "2026-01-25T23:42:08.116805+00:00", "data": {"market": "0x50ddb9cd80d5c271664a2ebb7fcaed1d0a148d82c8e8d314d830f75a944c3dcc", "price_changes": [{"asset_id": "94376205816022955542979635542279932967359915765455578534002478996104754801969", "price": "0.38", "size": "30", "side": "BUY", "hash": "dae3bc6c966025b33cf2ea976c9c4e366e707cab", "best_bid": "0.41", "best_ask": "0.47"}, {"asset_id": "88275040060084773376557187972215267513049848642895776801789297917961077894224", "price": "0.62", "size": "30", "side": "SELL", "hash": "ac08c577b64ab1545354b3e2739bcf24848d63ad", "best_bid": "0.53", "best_ask": "0.59"}], "timestamp": "1769384528049", "event_type": "price_change"}}
{"_local_timestamp": "2026-01-25T23:42:08.119788+00:00", "data": {"market": "0x50ddb9cd80d5c271664a2ebb7fcaed1d0a148d82c8e8d314d830f75a944c3dcc", "price_changes": [{"asset_id": "94376205816022955542979635542279932967359915765455578534002478996104754801969", "price": "0.31", "size": "0", "side": "BUY", "hash": "dae3bc6c966025b33cf2ea976c9c4e366e707cab", "best_bid": "0.41", "best_ask": "0.47"}, {"asset_id": "88275040060084773376557187972215267513049848642895776801789297917961077894224", "price": "0.69", "size": "0", "side": "SELL", "hash": "ac08c577b64ab1545354b3e2739bcf24848d63ad", "best_bid": "0.53", "best_ask": "0.59"}], "timestamp": "1769384528049", "event_type": "price_change"}}
{"_local_timestamp": "2026-01-25T23:42:09.052842+00:00", "data": {"market": "0x50ddb9cd80d5c271664a2ebb7fcaed1d0a148d82c8e8d314d830f75a944c3dcc", "price_changes": [{"asset_id": "94376205816022955542979635542279932967359915765455578534002478996104754801969", "price": "0.36", "size": "102.77", "side": "BUY", "hash": "0ceb5d5f155d91342eb324c746471b75f1396c31", "best_bid": "0.41", "best_ask": "0.47"}, {"asset_id": "88275040060084773376557187972215267513049848642895776801789297917961077894224", "price": "0.64", "size": "102.77", "side": "SELL", "hash": "4fe39e9e259dcb0bb4e91bbdc4166dd2f100141d", "best_bid": "0.53", "best_ask": "0.59"}], "timestamp": "1769384528987", "event_type": "price_change"}}
{"_local_timestamp": "2026-01-25T23:42:09.055488+00:00", "data": {"market": "0x50ddb9cd80d5c271664a2ebb7fcaed1d0a148d82c8e8d314d830f75a944c3dcc", "price_changes": [{"asset_id": "94376205816022955542979635542279932967359915765455578534002478996104754801969", "price": "0.42", "size": "66.66", "side": "BUY", "hash": "6163c2f5e706728fc0de53fa3e428f2e8156d9ab", "best_bid": "0.42", "best_ask": "0.47"}, {"asset_id": "88275040060084773376557187972215267513049848642895776801789297917961077894224", "price": "0.58", "size": "66.66", "side": "SELL", "hash": "49f208bfc0a8152eaaad8f44c7e30f8bee7eafbf", "best_bid": "0.53", "best_ask": "0.58"}], "timestamp": "1769384528988", "event_type": "price_change"}}
{"_local_timestamp": "2026-01-25T23:42:09.091955+00:00", "data": {"market": "0x50ddb9cd80d5c271664a2ebb7fcaed1d0a148d82c8e8d314d830f75a944c3dcc", "price_changes": [{"asset_id": "94376205816022955542979635542279932967359915765455578534002478996104754801969", "price": "0.31", "size": "66.66", "side": "BUY", "hash": "d7eb1fd6bc5487bf613993a33f57f85dc8ea7b4c", "best_bid": "0.42", "best_ask": "0.47"}, {"asset_id": "88275040060084773376557187972215267513049848642895776801789297917961077894224", "price": "0.69", "size": "66.66", "side": "SELL", "hash": "8e0a39b8067310d2e60dbc1fb67af0581c5920b6", "best_bid": "0.53", "best_ask": "0.58"}], "timestamp": "1769384529005", "event_type": "price_change"}}
{"_local_timestamp": "2026-01-25T23:42:09.204908+00:00", "data": {"market": "0x50ddb9cd80d5c271664a2ebb7fcaed1d0a148d82c8e8d314d830f75a944c3dcc", "price_changes": [{"asset_id": "94376205816022955542979635542279932967359915765455578534002478996104754801969", "price": "0.38", "size": "0", "side": "BUY", "hash": "82b820154f1d2ec1addcc79417999903e8a0ff5d", "best_bid": "0.42", "best_ask": "0.47"}, {"asset_id": "88275040060084773376557187972215267513049848642895776801789297917961077894224", "price": "0.62", "size": "0", "side": "SELL", "hash": "122d1ac9721bf710188cf3e326caef256e442790", "best_bid": "0.53", "best_ask": "0.58"}], "timestamp": "1769384529130", "event_type": "price_change"}}
{"_local_timestamp": "2026-01-25T23:42:09.274655+00:00", "data": {"market": "0x50ddb9cd80d5c271664a2ebb7fcaed1d0a148d82c8e8d314d830f75a944c3dcc", "price_changes": [{"asset_id": "94376205816022955542979635542279932967359915765455578534002478996104754801969", "price": "0.31", "size": "96.66", "side": "BUY", "hash": "b44457c13b275f67a52dcbdaf08588da8616ee6c", "best_bid": "0.42", "best_ask": "0.47"}, {"asset_id": "88275040060084773376557187972215267513049848642895776801789297917961077894224", "price": "0.69", "size": "96.66", "side": "SELL", "hash": "d58a870b0e03deb650d472ed80dc4121f21da0d9", "best_bid": "0.53", "best_ask": "0.58"}], "timestamp": "1769384529196", "event_type": "price_change"}}
{"_local_timestamp": "2026-01-25T23:42:10.137218+00:00", "data": {"market": "0x0ea8005efbc460378340a2f28a6d97b0d1d9d9d7fba4d16f529b8a415dca77a2", "price_changes": [{"asset_id": "48266425622404486484896353767723266081505997963592758694068789352158715350186", "price": "0.33", "size": "58.31", "side": "BUY", "hash": "db199ee75ca92c566facf35f029b484cea596a23", "best_bid": "0.37", "best_ask": "0.39"}, {"asset_id": "71552623345730992280501476931299615437386807576519105089437764117985071980606", "price": "0.67", "size": "58.31", "side": "SELL", "hash": "5dd06ce3f7efda04ef9be072bb1c78c69effaaf0", "best_bid": "0.61", "best_ask": "0.63"}], "timestamp": "1769384530010", "event_type": "price_change"}}
{"_local_timestamp": "2026-01-25T23:42:10.195143+00:00", "data": {"market": "0x0ea8005efbc460378340a2f28a6d97b0d1d9d9d7fba4d16f529b8a415dca77a2", "price_changes": [{"asset_id": "48266425622404486484896353767723266081505997963592758694068789352158715350186", "price": "0.33", "size": "31.51", "side": "BUY", "hash": "a58e9fa6fac6bf634832b9282acaa4d7e2709c95", "best_bid": "0.37", "best_ask": "0.39"}, {"asset_id": "71552623345730992280501476931299615437386807576519105089437764117985071980606", "price": "0.67", "size": "31.51", "side": "SELL", "hash": "f464b800761fa0470e555e4c6c830b6e3a103b77", "best_bid": "0.61", "best_ask": "0.63"}], "timestamp": "1769384530127", "event_type": "price_change"}}
{"_local_timestamp": "2026-01-25T23:42:10.903106+00:00", "data": {"market": "0x50ddb9cd80d5c271664a2ebb7fcaed1d0a148d82c8e8d314d830f75a944c3dcc", "price_changes": [{"asset_id": "88275040060084773376557187972215267513049848642895776801789297917961077894224", "price": "0.6", "size": "29", "side": "SELL", "hash": "a75ec4d3de93c16554eee00e3e0e02d2d17214ae", "best_bid": "0.53", "best_ask": "0.58"}, {"asset_id": "94376205816022955542979635542279932967359915765455578534002478996104754801969", "price": "0.4", "size": "29", "side": "BUY", "hash": "00d0337974cdd8f849c7e449c660e4bdadd9cb6a", "best_bid": "0.42", "best_ask": "0.47"}], "timestamp": "1769384530833", "event_type": "price_change"}}
{"_local_timestamp": "2026-01-25T23:42:10.908151+00:00", "data": {"market": "0x50ddb9cd80d5c271664a2ebb7fcaed1d0a148d82c8e8d314d830f75a944c3dcc", "price_changes": [{"asset_id": "88275040060084773376557187972215267513049848642895776801789297917961077894224", "price": "0.59", "size": "0", "side": "SELL", "hash": "a75ec4d3de93c16554eee00e3e0e02d2d17214ae", "best_bid": "0.53", "best_ask": "0.58"}, {"asset_id": "94376205816022955542979635542279932967359915765455578534002478996104754801969", "price": "0.41", "size": "0", "side": "BUY", "hash": "00d0337974cdd8f849c7e449c660e4bdadd9cb6a", "best_bid": "0.42", "best_ask": "0.47"}], "timestamp": "1769384530833", "event_type": "price_change"}}
{"_local_timestamp": "2026-01-25T23:42:10.920258+00:00", "data": {"market": "0x50ddb9cd80d5c271664a2ebb7fcaed1d0a148d82c8e8d314d830f75a944c3dcc", "price_changes": [{"asset_id": "88275040060084773376557187972215267513049848642895776801789297917961077894224", "price": "0.6", "size": "0", "side": "SELL", "hash": "897138d9b7d50299b431c0289f392573bb8d0b23", "best_bid": "0.53", "best_ask": "0.58"}, {"asset_id": "94376205816022955542979635542279932967359915765455578534002478996104754801969", "price": "0.4", "size": "0", "side": "BUY", "hash": "13d2865b8b6587248b7f76d917ea93272301bec6", "best_bid": "0.42", "best_ask": "0.47"}], "timestamp": "1769384530856", "event_type": "price_change"}}
{"_local_timestamp": "2026-01-25T23:42:10.947311+00:00", "data": {"market": "0x50ddb9cd80d5c271664a2ebb7fcaed1d0a148d82c8e8d314d830f75a944c3dcc", "price_changes": [{"asset_id": "88275040060084773376557187972215267513049848642895776801789297917961077894224", "price": "0.57", "size": "16", "side": "SELL", "hash": "a5beba38963c6c19d009d4d1c5243826c21cbcda", "best_bid": "0.53", "best_ask": "0.57"}, {"asset_id": "94376205816022955542979635542279932967359915765455578534002478996104754801969", "price": "0.43", "size": "16", "side": "BUY", "hash": "65ab474d646691617851120f1332936971fb7089", "best_bid": "0.43", "best_ask": "0.47"}], "timestamp": "1769384530866", "event_type": "price_change"}}
{"_local_timestamp": "2026-01-25T23:42:10.950178+00:00", "data": {"market": "0x50ddb9cd80d5c271664a2ebb7fcaed1d0a148d82c8e8d314d830f75a944c3dcc", "price_changes": [{"asset_id": "88275040060084773376557187972215267513049848642895776801789297917961077894224", "price": "0.59", "size": "15.1", "side": "SELL", "hash": "3e6c45fdc8ecad41bcae57628e94a14dc2ea736c", "best_bid": "0.53", "best_ask": "0.57"}, {"asset_id": "94376205816022955542979635542279932967359915765455578534002478996104754801969", "price": "0.41", "size": "15.1", "side": "BUY", "hash": "87ef49197c20342aa010dae1c1ba5bf9b31306bb", "best_bid": "0.43", "best_ask": "0.47"}], "timestamp": "1769384530867", "event_type": "price_change"}}
{"_local_timestamp": "2026-01-25T23:42:10.956925+00:00", "data": {"market": "0x50ddb9cd80d5c271664a2ebb7fcaed1d0a148d82c8e8d314d830f75a944c3dcc", "price_changes": [{"asset_id": "88275040060084773376557187972215267513049848642895776801789297917961077894224", "price": "0.63", "size": "58.72", "side": "SELL", "hash": "d846a5d346a791a9044484ea13b69c3e3c80e17c", "best_bid": "0.53", "best_ask": "0.57"}, {"asset_id": "94376205816022955542979635542279932967359915765455578534002478996104754801969", "price": "0.37", "size": "58.72", "side": "BUY", "hash": "adc14582a1fe5c20babb3accdcf93918c384e8ef", "best_bid": "0.43", "best_ask": "0.47"}], "timestamp": "1769384530882", "event_type": "price_change"}}
{"_local_timestamp": "2026-01-25T23:42:11.084049+00:00", "data": {"market": "0x50ddb9cd80d5c271664a2ebb7fcaed1d0a148d82c8e8d314d830f75a944c3dcc", "price_changes": [{"asset_id": "94376205816022955542979635542279932967359915765455578534002478996104754801969", "price": "0.31", "size": "66.66", "side": "BUY", "hash": "ebf68ba50757aedf2cc2317175846436e5fbe792", "best_bid": "0.43", "best_ask": "0.47"}, {"asset_id": "88275040060084773376557187972215267513049848642895776801789297917961077894224", "price": "0.69", "size": "66.66", "side": "SELL", "hash": "a16a1f8ec937cc72e951bf58847a9390ba0a4c0b", "best_bid": "0.53", "best_ask": "0.57"}], "timestamp": "1769384531018", "event_type": "price_change"}}
{"_local_timestamp": "2026-01-25T23:42:11.859137+00:00", "data": {"market": "0x50ddb9cd80d5c271664a2ebb7fcaed1d0a148d82c8e8d314d830f75a944c3dcc", "price_changes": [{"asset_id": "88275040060084773376557187972215267513049848642895776801789297917961077894224", "price": "0.53", "size": "5.16", "side": "BUY", "hash": "70fd3d5f74e2735f806234e2b5757f5391657953", "best_bid": "0.53", "best_ask": "0.57"}, {"asset_id": "94376205816022955542979635542279932967359915765455578534002478996104754801969", "price": "0.47", "size": "5.16", "side": "SELL", "hash": "56ea950b9d4e71fa4cf9991f8b438025f75ea15b", "best_bid": "0.43", "best_ask": "0.47"}], "timestamp": "1769384531796", "event_type": "price_change"}}
{"_local_timestamp": "2026-01-25T23:42:12.375138+00:00", "data": {"market": "0x50ddb9cd80d5c271664a2ebb7fcaed1d0a148d82c8e8d314d830f75a944c3dcc", "price_changes": [{"asset_id": "88275040060084773376557187972215267513049848642895776801789297917961077894224", "price": "0.57", "size": "37.15", "side": "SELL", "hash": "ea42615f33e7aae9f5f19bf27964f7c01bb1c939", "best_bid": "0.53", "best_ask": "0.57"}, {"asset_id": "94376205816022955542979635542279932967359915765455578534002478996104754801969", "price": "0.43", "size": "37.15", "side": "BUY", "hash": "95f37952c1867c4c443138015251bab97a3261f4", "best_bid": "0.43", "best_ask": "0.47"}], "timestamp": "1769384532302", "event_type": "price_change"}}
{"_local_timestamp": "2026-01-25T23:42:12.392200+00:00", "data": {"market": "0x50ddb9cd80d5c271664a2ebb7fcaed1d0a148d82c8e8d314d830f75a944c3dcc", "price_changes": [{"asset_id": "88275040060084773376557187972215267513049848642895776801789297917961077894224", "price": "0.63", "size": "29.72", "side": "SELL", "hash": "949286352476ae274816bc7896886c2040b9c4fb", "best_bid": "0.53", "best_ask": "0.57"}, {"asset_id": "94376205816022955542979635542279932967359915765455578534002478996104754801969", "price": "0.37", "size": "29.72", "side": "BUY", "hash": "1b693d91785a26d1d46c7acdfec5d80e4d2501ef", "best_bid": "0.43", "best_ask": "0.47"}], "timestamp": "1769384532326", "event_type": "price_change"}}
{"_local_timestamp": "2026-01-25T23:42:12.987339+00:00", "data": {"market": "0x50ddb9cd80d5c271664a2ebb7fcaed1d0a148d82c8e8d314d830f75a944c3dcc", "price_changes": [{"asset_id": "88275040060084773376557187972215267513049848642895776801789297917961077894224", "price": "0.59", "size": "0", "side": "SELL", "hash": "b725e43ee7a59c161858a7dd72995d48d6e48ba7", "best_bid": "0.53", "best_ask": "0.57"}, {"asset_id": "94376205816022955542979635542279932967359915765455578534002478996104754801969", "price": "0.41", "size": "0", "side": "BUY", "hash": "d669c0345de555593b065781ac2a5bc59ae76c28", "best_bid": "0.43", "best_ask": "0.47"}], "timestamp": "1769384532921", "event_type": "price_change"}}
{"_local_timestamp": "2026-01-25T23:42:13.012632+00:00", "data": {"market": "0x50ddb9cd80d5c271664a2ebb7fcaed1d0a148d82c8e8d314d830f75a944c3dcc", "price_changes": [{"asset_id": "88275040060084773376557187972215267513049848642895776801789297917961077894224", "price": "0.62", "size": "29", "side": "SELL", "hash": "3337f557e72ef2c90bce30bd5756b4746f89ab0a", "best_bid": "0.53", "best_ask": "0.57"}, {"asset_id": "94376205816022955542979635542279932967359915765455578534002478996104754801969", "price": "0.38", "size": "29", "side": "BUY", "hash": "9841760545b70a80d5dbc438b4380c91dff32660", "best_bid": "0.43", "best_ask": "0.47"}], "timestamp": "1769384532946", "event_type": "price_change"}}
{"_local_timestamp": "2026-01-25T23:42:13.019726+00:00", "data": {"market": "0x50ddb9cd80d5c271664a2ebb7fcaed1d0a148d82c8e8d314d830f75a944c3dcc", "price_changes": [{"asset_id": "88275040060084773376557187972215267513049848642895776801789297917961077894224", "price": "0.62", "size": "44.1", "side": "SELL", "hash": "e13cb8178e44864196a62903aa43d17e4beccb44", "best_bid": "0.53", "best_ask": "0.57"}, {"asset_id": "94376205816022955542979635542279932967359915765455578534002478996104754801969", "price": "0.38", "size": "44.1", "side": "BUY", "hash": "face99c69f59b20ccdb94eb2eade51e1acc6e534", "best_bid": "0.43", "best_ask": "0.47"}], "timestamp": "1769384532954", "event_type": "price_change"}}
{"_local_timestamp": "2026-01-25T23:42:14.116091+00:00", "data": {"market": "0x50ddb9cd80d5c271664a2ebb7fcaed1d0a148d82c8e8d314d830f75a944c3dcc", "price_changes": [{"asset_id": "88275040060084773376557187972215267513049848642895776801789297917961077894224", "price": "0.57", "size": "21.15", "side": "SELL", "hash": "147b7a81568460124a273298401564154819a449", "best_bid": "0.53", "best_ask": "0.57"}, {"asset_id": "94376205816022955542979635542279932967359915765455578534002478996104754801969", "price": "0.43", "size": "21.15", "side": "BUY", "hash": "af2c395ed5b6d135f9e2bb386d709022a8d92f39", "best_bid": "0.43", "best_ask": "0.47"}], "timestamp": "1769384534025", "event_type": "price_change"}}
{"_local_timestamp": "2026-01-25T23:42:14.118851+00:00", "data": {"market": "0x50ddb9cd80d5c271664a2ebb7fcaed1d0a148d82c8e8d314d830f75a944c3dcc", "price_changes": [{"asset_id": "88275040060084773376557187972215267513049848642895776801789297917961077894224", "price": "0.62", "size": "29", "side": "SELL", "hash": "147b7a81568460124a273298401564154819a449", "best_bid": "0.53", "best_ask": "0.57"}, {"asset_id": "94376205816022955542979635542279932967359915765455578534002478996104754801969", "price": "0.38", "size": "29", "side": "BUY", "hash": "af2c395ed5b6d135f9e2bb386d709022a8d92f39", "best_bid": "0.43", "best_ask": "0.47"}], "timestamp": "1769384534025", "event_type": "price_change"}}
{"_local_timestamp": "2026-01-25T23:42:14.144347+00:00", "data": {"market": "0x50ddb9cd80d5c271664a2ebb7fcaed1d0a148d82c8e8d314d830f75a944c3dcc", "price_changes": [{"asset_id": "88275040060084773376557187972215267513049848642895776801789297917961077894224", "price": "0.61", "size": "14.1", "side": "SELL", "hash": "679c71af0d8d26ff346e169ed58d6cd53b830c03", "best_bid": "0.53", "best_ask": "0.57"}, {"asset_id": "94376205816022955542979635542279932967359915765455578534002478996104754801969", "price": "0.39", "size": "14.1", "side": "BUY", "hash": "a5b77af52ca28be7461452f6df8137a6a2667ee0", "best_bid": "0.43", "best_ask": "0.47"}], "timestamp": "1769384534080", "event_type": "price_change"}}
{"_local_timestamp": "2026-01-25T23:42:14.151542+00:00", "data": {"market": "0x50ddb9cd80d5c271664a2ebb7fcaed1d0a148d82c8e8d314d830f75a944c3dcc", "price_changes": [{"asset_id": "88275040060084773376557187972215267513049848642895776801789297917961077894224", "price": "0.56", "size": "17", "side": "SELL", "hash": "01cc84ad4ec6cd96c1e402b6afcfb7d47feaccd2", "best_bid": "0.53", "best_ask": "0.56"}, {"asset_id": "94376205816022955542979635542279932967359915765455578534002478996104754801969", "price": "0.44", "size": "17", "side": "BUY", "hash": "4ec73e7b5f95a97d47474c31a5c9cf230c9d84c9", "best_bid": "0.44", "best_ask": "0.47"}], "timestamp": "1769384534081", "event_type": "price_change"}}
{"_local_timestamp": "2026-01-25T23:42:14.176161+00:00", "data": {"market": "0x50ddb9cd80d5c271664a2ebb7fcaed1d0a148d82c8e8d314d830f75a944c3dcc", "price_changes": [{"asset_id": "88275040060084773376557187972215267513049848642895776801789297917961077894224", "price": "0.62", "size": "0", "side": "SELL", "hash": "9dd3f626903b72104819c2f031e4494cd28afed3", "best_bid": "0.53", "best_ask": "0.56"}, {"asset_id": "94376205816022955542979635542279932967359915765455578534002478996104754801969", "price": "0.38", "size": "0", "side": "BUY", "hash": "8509e4cce1a060d95566d362967415a0b9054f09", "best_bid": "0.44", "best_ask": "0.47"}], "timestamp": "1769384534105", "event_type": "price_change"}}
{"_local_timestamp": "2026-01-25T23:42:15.079950+00:00", "data": {"market": "0x32b09f6390252b37d674501527e709016d55581b2c1e544bd4b8167f5f732f4c", "price_changes": [{"asset_id": "92388629082681805622801622703528982922543286352927708208755887536971583436902", "price": "0.52", "size": "97463.54", "side": "SELL", "hash": "96761d6513ce91762a10720528e6e5a8534182f3", "best_bid": "0.51", "best_ask": "0.52"}, {"asset_id": "90435811253665578014957380826505992530054077692143838383981805324273750424057", "price": "0.48", "size": "97463.54", "side": "BUY", "hash": "acd68f81f822894de4881081575d41bf6b1a46f7", "best_bid": "0.48", "best_ask": "0.49"}], "timestamp": "1769384535000", "event_type": "price_change"}}
{"_local_timestamp": "2026-01-25T23:42:15.111600+00:00", "data": {"market": "0x0ea8005efbc460378340a2f28a6d97b0d1d9d9d7fba4d16f529b8a415dca77a2", "price_changes": [{"asset_id": "48266425622404486484896353767723266081505997963592758694068789352158715350186", "price": "0.33", "size": "58.31", "side": "BUY", "hash": "3b9e79613ae84ec23acd0081b8f34e3408f04a65", "best_bid": "0.37", "best_ask": "0.39"}, {"asset_id": "71552623345730992280501476931299615437386807576519105089437764117985071980606", "price": "0.67", "size": "58.31", "side": "SELL", "hash": "cc38c0c138584279c4af1fe5ae29d51c732ae443", "best_bid": "0.61", "best_ask": "0.63"}], "timestamp": "1769384535037", "event_type": "price_change"}}
