{"_local_timestamp": "2026-01-25T23:33:38.535101+00:00", "data": [{"market": "0x8ff260489ea5aa78fa5b3c680b9881b6045af76d6a4f5afe6812f3967ee793a0", "asset_id": "1125211017783109589110510546210165660340648360115402691298367602660868269735", "timestamp": "1769383954065", "hash": "da322203673b09897db7f8ae14c7b01e2d3d9d5e", "bids": [{"price": "0.001", "size": "16262"}, {"price": "0.002", "size": "2010.32"}, {"price": "0.003", "size": "200"}, {"price": "0.004", "size": "12.69"}, {"price": "0.006", "size": "11.16"}, {"price": "0.008", "size": "50"}, {"price": "0.009", "size": "41.4"}, {"price": "0.01", "size": "20"}, {"price": "0.011", "size": "36.8"}, {"price": "0.012", "size": "23.3"}, {"price": "0.013", "size": "6.5"}, {"price": "0.022", "size": "61.86"}], "asks": [{"price": "0.999", "size": "2886.76"}, {"price": "0.998", "size": "360.68"}, {"price": "0.997", "size": "266"}, {"price": "0.996", "size": "7.92"}, {"price": "0.994", "size": "83"}, {"price": "0.993", "size": "5.94"}, {"price": "0.99", "size": "50"}, {"price": "0.989", "size": "23.37"}, {"price": "0.95", "size": "30"}, {"price": "0.949", "size": "39"}, {"price": "0.9", "size": "259.61"}, {"price": "0.82", "size": "152.08"}, {"price": "0.819", "size": "114.22"}, {"price": "0.28", "size": "9.44"}, {"price": "0.13", "size": "15.01"}, {"price": "0.129", "size": "83.63"}], "event_type": "book", "last_trade_price": "0.024"}, {"market": "0xb56bcce3c29679dbab4467e57810e73fccafadf46b0770942aaef66c5b74c8dc", "asset_id": "70162704708176551332494543434209796474919283850328944065576455499958010645095", "timestamp": "1769383132656", "hash": "e0ebe3f9db38cc65486e13dc8347a4703cb77a2a", "bids": [{"price": "0.001", "size": "3937.82"}, {"price": "0.002", "size": "47.62"}, {"price": "0.01", "size": "47050"}, {"price": "0.011", "size": "9.22"}, {"price": "0.02", "size": "11750"}, {"price": "0.021", "size": "7.28"}, {"price": "0.03", "size": "316"}, {"price": "0.05", "size": "6458.53"}, {"price": "0.07", "size": "15"}, {"price": "0.08", "size": "4500"}, {"price": "0.11", "size": "2250"}, {"price": "0.111", "size": "250"}, {"price": "0.223", "size": "31"}, {"price": "0.5", "size": "400"}, {"price": "0.523", "size": "201"}, {"price": "0.723", "size": "127"}, {"price": "0.823", "size": "205"}, {"price": "0.923", "size": "353"}, {"price": "0.97", "size": "25"}, {"price": "0.971", "size": "23.2"}, {"price": "0.999", "size": "8345.44"}], "asks": [], "event_type": "book", "last_trade_price": "0.001"}, {"market": "0xaa10e2c6eb8e9b49c30dfd887e568488f045c48fa8dfaaeba2b2208ba1488e05", "asset_id": "95077425162713838325885910733201226269444709994881658333525493356013517070688", "timestamp": "1769383668144", "hash": "8a148e7954040db88264fd66b8dee315457fcde9", "bids": [{"price": "0.001", "size": "3986.76"}, {"price": "0.002", "size": "260.68"}, {"price": "0.003", "size": "46166"}, {"price": "0.004", "size": "7.92"}, {"price": "0.006", "size": "83"}, {"price": "0.007", "size": "5.94"}, {"price": "0.01", "size": "50"}, {"price": "0.011", "size": "9.16"}, {"price": "0.02", "size": "11250"}, {"price": "0.021", "size": "7.68"}, {"price": "0.05", "size": "6470"}, {"price": "0.051", "size": "39"}, {"price": "0.08", "size": "4500"}, {"price": "0.11", "size": "2250"}, {"price": "0.112", "size": "9"}, {"price": "0.113", "size": "17"}, {"price": "0.85", "size": "600"}, {"price": "0.946", "size": "44"}, {"price": "0.979", "size": "92"}, {"price": "0.98", "size": "20"}, {"price": "0.981", "size": "1000"}, {"price": "0.982", "size": "220"}, {"price": "0.984", "size": "20"}, {"price": "0.985", "size": "20"}, {"price": "0.987", "size": "10"}, {"price": "0.99", "size": "81"}, {"price": "0.991", "size": "40"}, {"price": "0.992", "size": "270"}, {"price": "0.993", "size": "7.47"}, {"price": "0.995", "size": "1228.62"}, {"price": "0.996", "size": "1379.79"}], "asks": [{"price": "0.999", "size": "24265"}, {"price": "0.998", "size": "548.01"}], "event_type": "book", "last_trade_price": "0.998"}, {"market": "0xd97cea4602cceb228056d6597feed4e4805f026ec6d5e7a06dca81b6e05c8d26", "asset_id": "90370492639686279760895942864235580169627907120025687040241447968180259582385", "timestamp": "1769383997076", "hash": "ecc774eca20cfd7c50c3c7516c6f4c9a7185d9c5", "bids": [{"price": "0.001", "size": "4982.75"}, {"price": "0.002", "size": "1260.68"}, {"price": "0.003", "size": "1000"}, {"price": "0.004", "size": "18.33"}, {"price": "0.01", "size": "50"}, {"price": "0.011", "size": "23.82"}, {"price": "0.05", "size": "30"}, {"price": "0.06", "size": "33"}, {"price": "0.062", "size": "16"}, {"price": "0.063", "size": "31"}, {"price": "0.65", "size": "14.98"}, {"price": "0.74", "size": "463.87"}, {"price": "0.741", "size": "200"}, {"price": "0.742", "size": "100"}, {"price": "0.743", "size": "75"}, {"price": "0.89", "size": "5.94"}, {"price": "0.944", "size": "18.4"}, {"price": "0.97", "size": "25"}, {"price": "0.971", "size": "12"}], "asks": [{"price": "0.999", "size": "6663.39"}, {"price": "0.998", "size": "60.72"}, {"price": "0.993", "size": "145"}, {"price": "0.991", "size": "148"}, {"price": "0.989", "size": "109.09"}, {"price": "0.988", "size": "48.95"}], "event_type": "book", "last_trade_price": "0.008"}, {"market": "0xd97cea4602cceb228056d6597feed4e4805f026ec6d5e7a06dca81b6e05c8d26", "asset_id": "58440600010653306781229251941477344349383850231605820632490524164682830491653", "timestamp": "1769383997076", "hash": "7051c469bceb2b70c5874ed147f9c19a0cbf971c", "bids": [{"price": "0.001", "size": "6663.39"}, {"price": "0.002", "size": "60.72"}, {"price": "0.007", "size": "145"}, {"price": "0.009", "size": "148"}, {"price": "0.011", "size": "109.09"}, {"price": "0.012", "size": "48.95"}], "asks": [{"price": "0.999", "size": "4982.75"}, {"price": "0.998", "size": "1260.68"}, {"price": "0.997", "size": "1000"}, {"price": "0.996", "size": "18.33"}, {"price": "0.99", "size": "50"}, {"price": "0.989", "size": "23.82"}, {"price": "0.95", "size": "30"}, {"price": "0.94", "size": "33"}, {"price": "0.938", "size": "16"}, {"price": "0.937", "size": "31"}, {"price": "0.35", "size": "14.98"}, {"price": "0.26", "size": "463.87"}, {"price": "0.259", "size": "200"}, {"price": "0.258", "size": "100"}, {"price": "0.257", "size": "75"}, {"price": "0.11", "size": "5.94"}, {"price": "0.056", "size": "18.4"}, {"price": "0.03", "size": "25"}, {"price": "0.029", "size": "12"}], "event_type": "book", "last_trade_price": "0.008"}, {"market": "0x677db25f882c030e38309fdb93d95ab544092caffedf3a0753460e122533f217", "asset_id": "70962355560380333033520368609651913126821476783171408624102605215524414381982", "timestamp": "1769382767739", "hash": "83b3183e87d5cae8a689a8e6b48cab1eee5bfa33", "bids": [{"price": "0.001", "size": "2974.76"}, {"price": "0.002", "size": "255.35"}, {"price": "0.003", "size": "26.1"}, {"price": "0.009", "size": "1100"}, {"price": "0.01", "size": "50"}, {"price": "0.011", "size": "23.83"}, {"price": "0.05", "size": "30"}, {"price": "0.051", "size": "39"}, {"price": "0.111", "size": "250"}, {"price": "0.21", "size": "230.92"}, {"price": "0.211", "size": "9"}, {"price": "0.72", "size": "20"}, {"price": "0.722", "size": "20"}, {"price": "0.82", "size": "230.91"}, {"price": "0.908", "size": "5.55"}, {"price": "0.942", "size": "34"}, {"price": "0.967", "size": "100"}, {"price": "0.971", "size": "129"}, {"price": "0.98", "size": "6.18"}, {"price": "0.981", "size": "20"}, {"price": "0.985", "size": "233.56"}, {"price": "0.986", "size": "219.68"}, {"price": "0.987", "size": "12.15"}, {"price": "0.994", "size": "286.19"}, {"price": "0.995", "size": "143"}], "asks": [{"price": "0.999", "size": "30039"}, {"price": "0.998", "size": "2094.03"}, {"price": "0.997", "size": "269"}, {"price": "0.996", "size": "1202.81"}], "event_type": "book", "last_trade_price": "0.004"}, {"market": "0xdd8912727639d1273193f8b17b89fc6ec525a8dc4a7c462d7d1531a553d3b25c", "asset_id": "66760775717731849606178090046166310993448344537844873363422065730421513914311", "timestamp": "1769383749585", "hash": "988e80feeab9c0d2accbfe972b7b037dea2fa262", "bids": [{"price": "0.001", "size": "8260.99"}, {"price": "0.002", "size": "1013.28"}, {"price": "0.003", "size": "259.28"}, {"price": "0.004", "size": "13.13"}, {"price": "0.006", "size": "9.67"}], "asks": [{"price": "0.999", "size": "3012.75"}, {"price": "0.998", "size": "1262.24"}, {"price": "0.997", "size": "1000"}, {"price": "0.996", "size": "14.9"}, {"price": "0.99", "size": "50"}, {"price": "0.989", "size": "23.83"}, {"price": "0.95", "size": "30"}, {"price": "0.949", "size": "39"}, {"price": "0.947", "size": "19"}, {"price": "0.946", "size": "37"}, {"price": "0.31", "size": "100"}, {"price": "0.18", "size": "17"}, {"price": "0.052", "size": "30"}, {"price": "0.045", "size": "48.7"}, {"price": "0.037", "size": "0.67"}, {"price": "0.031", "size": "50.8"}, {"price": "0.03", "size": "334.35"}, {"price": "0.029", "size": "160.5"}, {"price": "0.011", "size": "125"}], "event_type": "book", "last_trade_price": "0.006"}, {"market": "0x824ff868f6a6935d10d3ccdc5b73c7d9cb5325f31ca80b4a5f093a3871d4ab45", "asset_id": "78856519471483111489144381430368949435602822511527338537489119566299332945125", "timestamp": "1769384018080", "hash": "ee8fb4e499bba77fbd8038f3739e809e0363897d", "bids": [{"price": "0.001", "size": "24882"}, {"price": "0.002", "size": "218.31"}, {"price": "0.003", "size": "92.83"}, {"price": "0.004", "size": "57.6"}], "asks": [{"price": "0.999", "size": "2401.42"}, {"price": "0.998", "size": "260.69"}, {"price": "0.997", "size": "166"}, {"price": "0.996", "size": "1207.92"}, {"price": "0.994", "size": "83"}, {"price": "0.993", "size": "5.94"}, {"price": "0.99", "size": "50"}, {"price": "0.989", "size": "22.66"}, {"price": "0.95", "size": "30"}, {"price": "0.949", "size": "39"}, {"price": "0.86", "size": "118.03"}, {"price": "0.859", "size": "59"}, {"price": "0.64", "size": "5"}, {"price": "0.36", "size": "118.03"}, {"price": "0.039", "size": "33.8"}], "event_type": "book", "last_trade_price": ""}, {"market": "0x8ff260489ea5aa78fa5b3c680b9881b6045af76d6a4f5afe6812f3967ee793a0", "asset_id": "34539885844990186168937654116625036865751022263351692260312783883067264034518", "timestamp": "1769383954065", "hash": "092b928dd2bcb0e605123266ad077ae26fa11854", "bids": [{"price": "0.001", "size": "2886.76"}, {"price": "0.002", "size": "360.68"}, {"price": "0.003", "size": "266"}, {"price": "0.004", "size": "7.92"}, {"price": "0.006", "size": "83"}, {"price": "0.007", "size": "5.94"}, {"price": "0.01", "size": "50"}, {"price": "0.011", "size": "23.37"}, {"price": "0.05", "size": "30"}, {"price": "0.051", "size": "39"}, {"price": "0.1", "size": "259.61"}, {"price": "0.18", "size": "152.08"}, {"price": "0.181", "size": "114.22"}, {"price": "0.72", "size": "9.44"}, {"price": "0.87", "size": "15.01"}, {"price": "0.871", "size": "83.63"}], "asks": [{"price": "0.999", "size": "16262"}, {"price": "0.998", "size": "2010.32"}, {"price": "0.997", "size": "200"}, {"price": "0.996", "size": "12.69"}, {"price": "0.994", "size": "11.16"}, {"price": "0.992", "size": "50"}, {"price": "0.991", "size": "41.4"}, {"price": "0.99", "size": "20"}, {"price": "0.989", "size": "36.8"}, {"price": "0.988", "size": "23.3"}, {"price": "0.987", "size": "6.5"}, {"price": "0.978", "size": "61.86"}], "event_type": "book", "last_trade_price": "0.024"}, {"market": "0xaa10e2c6eb8e9b49c30dfd887e568488f045c48fa8dfaaeba2b2208ba1488e05", "asset_id": "108166848559622584494345122936631693753040126959913804576549310089584451376551", "timestamp": "1769383668144", "hash": "cd8cf1e7718f2c9de86846555f665b267bebc0d3", "bids": [{"price": "0.001", "size": "24265"}, {"price": "0.002", "size": "548.01"}], "asks": [{"price": "0.999", "size": "3986.76"}, {"price": "0.998", "size": "260.68"}, {"price": "0.997", "size": "46166"}, {"price": "0.996", "size": "7.92"}, {"price": "0.994", "size": "83"}, {"price": "0.993", "size": "5.94"}, {"price": "0.99", "size": "50"}, {"price": "0.989", "size": "9.16"}, {"price": "0.98", "size": "11250"}, {"price": "0.979", "size": "7.68"}, {"price": "0.95", "size": "6470"}, {"price": "0.949", "size": "39"}, {"price": "0.92", "size": "4500"}, {"price": "0.89", "size": "2250"}, {"price": "0.888", "size": "9"}, {"price": "0.887", "size": "17"}, {"price": "0.15", "size": "600"}, {"price": "0.054", "size": "44"}, {"price": "0.021", "size": "92"}, {"price": "0.02", "size": "20"}, {"price": "0.019", "size": "1000"}, {"price": "0.018", "size": "220"}, {"price": "0.016", "size": "20"}, {"price": "0.015", "size": "20"}, {"price": "0.013", "size": "10"}, {"price": "0.01", "size": "81"}, {"price": "0.009", "size": "40"}, {"price": "0.008", "size": "270"}, {"price": "0.007", "size": "7.47"}, {"price": "0.005", "size": "1228.62"}, {"price": "0.004", "size": "1379.79"}], "event_type": "book", "last_trade_price": "0.998"}, {"market": "0xb56bcce3c29679dbab4467e57810e73fccafadf46b0770942aaef66c5b74c8dc", "asset_id": "78738246149098397928345880429189437989748486055647346887139225093279301789493", "timestamp": "1769383132656", "hash": "16eb0ba306fce23863fb7805a45d4fb1559cde12", "bids": [], "asks": [{"price": "0.999", "size": "3937.82"}, {"price": "0.998", "size": "47.62"}, {"price": "0.99", "size": "47050"}, {"price": "0.989", "size": "9.22"}, {"price": "0.98", "size": "11750"}, {"price": "0.979", "size": "7.28"}, {"price": "0.97", "size": "316"}, {"price": "0.95", "size": "6458.53"}, {"price": "0.93", "size": "15"}, {"price": "0.92", "size": "4500"}, {"price": "0.89", "size": "2250"}, {"price": "0.889", "size": "250"}, {"price": "0.777", "size": "31"}, {"price": "0.5", "size": "400"}, {"price": "0.477", "size": "201"}, {"price": "0.277", "size": "127"}, {"price": "0.177", "size": "205"}, {"price": "0.077", "size": "353"}, {"price": "0.03", "size": "25"}, {"price": "0.029", "size": "23.2"}, {"price": "0.001", "size": "8345.44"}], "event_type": "book", "last_trade_price": "0.001"}, {"market": "0x824ff868f6a6935d10d3ccdc5b73c7d9cb5325f31ca80b4a5f093a3871d4ab45", "asset_id": "2871426403404885688747962237095784039858305930578199850207892053760319086420", "timestamp": "1769384018080", "hash": "971de5fe06365e7d95cb2d2c63422a17bbecb816", "bids": [{"price": "0.001", "size": "2401.42"}, {"price": "0.002", "size": "260.69"}, {"price": "0.003", "size": "166"}, {"price": "0.004", "size": "1207.92"}, {"price": "0.006", "size": "83"}, {"price": "0.007", "size": "5.94"}, {"price": "0.01", "size": "50"}, {"price": "0.011", "size": "22.66"}, {"price": "0.05", "size": "30"}, {"price": "0.051", "size": "39"}, {"price": "0.14", "size": "118.03"}, {"price": "0.141", "size": "59"}, {"price": "0.36", "size": "5"}, {"price": "0.64", "size": "118.03"}, {"price": "0.961", "size": "33.8"}], "asks": [{"price": "0.999", "size": "24882"}, {"price": "0.998", "size": "218.31"}, {"price": "0.997", "size": "92.83"}, {"price": "0.996", "size": "57.6"}], "event_type": "book", "last_trade_price": ""}, {"market": "0x677db25f882c030e38309fdb93d95ab544092caffedf3a0753460e122533f217", "asset_id": "2000710628755694330462323874112265267979163288148760873771120885908845651232", "timestamp": "1769382767739", "hash": "6dc1d6a72bacde0e1f4fb4d81774f1399decec82", "bids": [{"price": "0.001", "size": "30039"}, {"price": "0.002", "size": "2094.03"}, {"price": "0.003", "size": "269"}, {"price": "0.004", "size": "1202.81"}], "asks": [{"price": "0.999", "size": "2974.76"}, {"price": "0.998", "size": "255.35"}, {"price": "0.997", "size": "26.1"}, {"price": "0.991", "size": "1100"}, {"price": "0.99", "size": "50"}, {"price": "0.989", "size": "23.83"}, {"price": "0.95", "size": "30"}, {"price": "0.949", "size": "39"}, {"price": "0.889", "size": "250"}, {"price": "0.79", "size": "230.92"}, {"price": "0.789", "size": "9"}, {"price": "0.28", "size": "20"}, {"price": "0.278", "size": "20"}, {"price": "0.18", "size": "230.91"}, {"price": "0.092", "size": "5.55"}, {"price": "0.058", "size": "34"}, {"price": "0.033", "size": "100"}, {"price": "0.029", "size": "129"}, {"price": "0.02", "size": "6.18"}, {"price": "0.019", "size": "20"}, {"price": "0.015", "size": "233.56"}, {"price": "0.014", "size": "219.68"}, {"price": "0.013", "size": "12.15"}, {"price": "0.006", "size": "286.19"}, {"price": "0.005", "size": "143"}], "event_type": "book", "last_trade_price": "0.004"}, {"market": "0xdd8912727639d1273193f8b17b89fc6ec525a8dc4a7c462d7d1531a553d3b25c", "asset_id": "67558471467857993358297659413470229023460175538336310590556862174269025942807", "timestamp": "1769383749585", "hash": "652184b14121cc61903f199313624a6f7cf210fd", "bids": [{"price": "0.001", "size": "3012.75"}, {"price": "0.002", "size": "1262.24"}, {"price": "0.003", "size": "1000"}, {"price": "0.004", "size": "14.9"}, {"price": "0.01", "size": "50"}, {"price": "0.011", "size": "23.83"}, {"price": "0.05", "size": "30"}, {"price": "0.051", "size": "39"}, {"price": "0.053", "size": "19"}, {"price": "0.054", "size": "37"}, {"price": "0.69", "size": "100"}, {"price": "0.82", "size": "17"}, {"price": "0.948", "size": "30"}, {"price": "0.955", "size": "48.7"}, {"price": "0.963", "size": "0.67"}, {"price": "0.969", "size": "50.8"}, {"price": "0.97", "size": "334.35"}, {"price": "0.971", "size": "160.5"}, {"price": "0.989", "size": "125"}], "asks": [{"price": "0.999", "size": "8260.99"}, {"price": "0.998", "size": "1013.28"}, {"price": "0.997", "size": "259.28"}, {"price": "0.996", "size": "13.13"}, {"price": "0.994", "size": "9.67"}], "event_type": "book", "last_trade_price": "0.006"}]}
{"_local_timestamp": "2026-01-25T23:33:47.907107+00:00", "data": {"market": "0xdd8912727639d1273193f8b17b89fc6ec525a8dc4a7c462d7d1531a553d3b25c", "price_changes": [{"asset_id": "66760775717731849606178090046166310993448344537844873363422065730421513914311", "price": "0.002", "size": "1000", "side": "BUY", "hash": "867be6c61414588e8cb2289068f1577b6d8ad710", "best_bid": "0.006", "best_ask": "0.011"}, {"asset_id": "67558471467857993358297659413470229023460175538336310590556862174269025942807", "price": "0.998", "size": "1000", "side": "SELL", "hash": "887de245c8b0ff085abb217901fa553737edc0af", "best_bid": "0.989", "best_ask": "0.994"}], "timestamp": "1769384027838", "event_type": "price_change"}}
{"_local_timestamp": "2026-01-25T23:33:47.914647+00:00", "data": {"market": "0xdd8912727639d1273193f8b17b89fc6ec525a8dc4a7c462d7d1531a553d3b25c", "price_changes": [{"asset_id": "66760775717731849606178090046166310993448344537844873363422065730421513914311", "price": "0.004", "size": "0", "side": "BUY", "hash": "867be6c61414588e8cb2289068f1577b6d8ad710", "best_bid": "0.006", "best_ask": "0.011"}, {"asset_id": "67558471467857993358297659413470229023460175538336310590556862174269025942807", "price": "0.996", "size": "0", "side": "SELL", "hash": "887de245c8b0ff085abb217901fa553737edc0af", "best_bid": "0.989", "best_ask": "0.994"}], "timestamp": "1769384027838", "event_type": "price_change"}}
{"_local_timestamp": "2026-01-25T23:33:48.191504+00:00", "data": {"market": "0xdd8912727639d1273193f8b17b89fc6ec525a8dc4a7c462d7d1531a553d3b25c", "price_changes": [{"asset_id": "66760775717731849606178090046166310993448344537844873363422065730421513914311", "price": "0.002", "size": "1013.27", "side": "BUY", "hash": "268c77ee168cb0b4fbe5744ff79570a750126b87", "best_bid": "0.006", "best_ask": "0.011"}, {"asset_id": "67558471467857993358297659413470229023460175538336310590556862174269025942807", "price": "0.998", "size": "1013.27", "side": "SELL", "hash": "73f78066be3d9690be11cd2ef90786cea626f32e", "best_bid": "0.989", "best_ask": "0.994"}], "timestamp": "1769384028122", "event_type": "price_change"}}
{"_local_timestamp": "2026-01-25T23:33:48.192258+00:00", "data": {"market": "0xdd8912727639d1273193f8b17b89fc6ec525a8dc4a7c462d7d1531a553d3b25c", "price_changes": [{"asset_id": "66760775717731849606178090046166310993448344537844873363422065730421513914311", "price": "0.004", "size": "13.12", "side": "BUY", "hash": "3fd4251d86d1dc9019387bac9f4de81aa3aa9947", "best_bid": "0.006", "best_ask": "0.011"}, {"asset_id": "67558471467857993358297659413470229023460175538336310590556862174269025942807", "price": "0.996", "size": "13.12", "side": "SELL", "hash": "cab03152baa644e662c64286651e81e7ba12e72c", "best_bid": "0.989", "best_ask": "0.994"}], "timestamp": "1769384028124", "event_type": "price_change"}}
{"_local_timestamp": "2026-01-25T23:33:55.272950+00:00", "data": {"market": "0x8ff260489ea5aa78fa5b3c680b9881b6045af76d6a4f5afe6812f3967ee793a0", "price_changes": [{"asset_id": "34539885844990186168937654116625036865751022263351692260312783883067264034518", "price": "0.871", "size": "40.01", "side": "BUY", "hash": "3f6ca1f8153527a300b935015e4355b9ba1b8737", "best_bid": "0.871", "best_ask": "0.978"}, {"asset_id": "1125211017783109589110510546210165660340648360115402691298367602660868269735", "price": "0.129", "size": "40.01", "side": "SELL", "hash": "30df4850c6cd486a9d1b822250053a2f6bedb32e", "best_bid": "0.022", "best_ask": "0.129"}], "timestamp": "1769384035176", "event_type": "price_change"}}
{"_local_timestamp": "2026-01-25T23:34:31.776221+00:00", "data": {"market": "0x8ff260489ea5aa78fa5b3c680b9881b6045af76d6a4f5afe6812f3967ee793a0", "price_changes": [{"asset_id": "34539885844990186168937654116625036865751022263351692260312783883067264034518", "price": "0.978", "size": "50", "side": "SELL", "hash": "40e25926f9e2353f6566f0b35fd864e9a11bf7dd", "best_bid": "0.871", "best_ask": "0.978"}, {"asset_id": "1125211017783109589110510546210165660340648360115402691298367602660868269735", "price": "0.022", "size": "50", "side": "BUY", "hash": "e4de091741b26c35d13082c0e9665800823ef74f", "best_bid": "0.022", "best_ask": "0.129"}], "timestamp": "1769384071001", "event_type": "price_change"}}
{"_local_timestamp": "2026-01-25T23:34:33.160811+00:00", "data": {"market": "0xd97cea4602cceb228056d6597feed4e4805f026ec6d5e7a06dca81b6e05c8d26", "price_changes": [{"asset_id": "58440600010653306781229251941477344349383850231605820632490524164682830491653", "price": "0.011", "size": "0", "side": "BUY", "hash": "b260a7b4677265ee12da108e5e666ce2fc388668", "best_bid": "0.012", "best_ask": "0.029"}, {"asset_id": "90370492639686279760895942864235580169627907120025687040241447968180259582385", "price": "0.989", "size": "0", "side": "SELL", "hash": "aff4b23eea2cab839b8f9ee61936a2d94d0e25e3", "best_bid": "0.971", "best_ask": "0.988"}], "timestamp": "1769384073093", "event_type": "price_change"}}
{"_local_timestamp": "2026-01-25T23:34:46.098932+00:00", "data": {"market": "0xd97cea4602cceb228056d6597feed4e4805f026ec6d5e7a06dca81b6e05c8d26", "price_changes": [{"asset_id": "58440600010653306781229251941477344349383850231605820632490524164682830491653", "price": "0.012", "size": "0", "side": "BUY", "hash": "3b622822b7cc69658ba360cc03d904fe55829609", "best_bid": "0.009", "best_ask": "0.029"}, {"asset_id": "90370492639686279760895942864235580169627907120025687040241447968180259582385", "price": "0.988", "size": "0", "side": "SELL", "hash": "c7667eb8c84842563410c1a6969793180c76cf5c", "best_bid": "0.971", "best_ask": "0.991"}], "timestamp": "1769384086013", "event_type": "price_change"}}
{"_local_timestamp": "2026-01-25T23:34:46.432982+00:00", "data": {"market": "0xd97cea4602cceb228056d6597feed4e4805f026ec6d5e7a06dca81b6e05c8d26", "price_changes": [{"asset_id": "58440600010653306781229251941477344349383850231605820632490524164682830491653", "price": "0.01", "size": "48.95", "side": "BUY", "hash": "b14362ba910dbdc159ebaa58eb8320a732b9720d", "best_bid": "0.01", "best_ask": "0.029"}, {"asset_id": "90370492639686279760895942864235580169627907120025687040241447968180259582385", "price": "0.99", "size": "48.95", "side": "SELL", "hash": "91a8133f22f64f5bb796f3166aaab90fe15a4f64", "best_bid": "0.971", "best_ask": "0.99"}], "timestamp": "1769384086367", "event_type": "price_change"}}
{"_local_timestamp": "2026-01-25T23:34:53.089052+00:00", "data": {"market": "0x824ff868f6a6935d10d3ccdc5b73c7d9cb5325f31ca80b4a5f093a3871d4ab45", "price_changes": [{"asset_id": "2871426403404885688747962237095784039858305930578199850207892053760319086420", "price": "0.961", "size": "13.8", "side": "BUY", "hash": "11109da37c5e9f5c05775edd25beab0216a45e4d", "best_bid": "0.961", "best_ask": "0.996"}, {"asset_id": "78856519471483111489144381430368949435602822511527338537489119566299332945125", "price": "0.039", "size": "13.8", "side": "SELL", "hash": "3055bcc287f2f355937678f46b8e0595bdc6ed08", "best_bid": "0.004", "best_ask": "0.039"}], "timestamp": "1769384093004", "event_type": "price_change"}}
{"_local_timestamp": "2026-01-25T23:35:03.088459+00:00", "data": {"market": "0x8ff260489ea5aa78fa5b3c680b9881b6045af76d6a4f5afe6812f3967ee793a0", "price_changes": [{"asset_id": "34539885844990186168937654116625036865751022263351692260312783883067264034518", "price": "0.871", "size": "20.01", "side": "BUY", "hash": "bf33c957063b725bbaa7c51d77968f21d08d5e1b", "best_bid": "0.871", "best_ask": "0.978"}, {"asset_id": "1125211017783109589110510546210165660340648360115402691298367602660868269735", "price": "0.129", "size": "20.01", "side": "SELL", "hash": "a6573524eb6a948ab69af1f7a9129c2b5f8f9fd2", "best_bid": "0.022", "best_ask": "0.129"}], "timestamp": "1769384103002", "event_type": "price_change"}}
{"_local_timestamp": "2026-01-25T23:35:04.865665+00:00", "data": {"market": "0x8ff260489ea5aa78fa5b3c680b9881b6045af76d6a4f5afe6812f3967ee793a0", "price_changes": [{"asset_id": "34539885844990186168937654116625036865751022263351692260312783883067264034518", "price": "0.871", "size": "63.63", "side": "BUY", "hash": "0a1a8e24a96080f5e621a9e8c06f33c069af3a57", "best_bid": "0.871", "best_ask": "0.978"}, {"asset_id": "1125211017783109589110510546210165660340648360115402691298367602660868269735", "price": "0.129", "size": "63.63", "side": "SELL", "hash": "ae9d4188c79e2e209984eb90ed25112bbd977d54", "best_bid": "0.022", "best_ask": "0.129"}], "timestamp": "1769384104796", "event_type": "price_change"}}
{"_local_timestamp": "2026-01-25T23:35:18.849829+00:00", "data": {"market": "0x824ff868f6a6935d10d3ccdc5b73c7d9cb5325f31ca80b4a5f093a3871d4ab45", "price_changes": [{"asset_id": "2871426403404885688747962237095784039858305930578199850207892053760319086420", "price": "0.36", "size": "0", "side": "BUY", "hash": "574e9fd09d56e9c46ec967cb55a917b17f5dd9d8", "best_bid": "0.961", "best_ask": "0.996"}, {"asset_id": "78856519471483111489144381430368949435602822511527338537489119566299332945125", "price": "0.64", "size": "0", "side": "SELL", "hash": "20a8a38e1eaa0bf8c0e10993454dab9a554b4b5d", "best_bid": "0.004", "best_ask": "0.039"}], "timestamp": "1769384118784", "event_type": "price_change"}}
{"_local_timestamp": "2026-01-25T23:35:19.190557+00:00", "data": {"market": "0x824ff868f6a6935d10d3ccdc5b73c7d9cb5325f31ca80b4a5f093a3871d4ab45", "price_changes": [{"asset_id": "2871426403404885688747962237095784039858305930578199850207892053760319086420", "price": "0.36", "size": "5", "side": "BUY", "hash": "ea3eb75f9192f403693a4d7cc9ea32cf0e959890", "best_bid": "0.961", "best_ask": "0.996"}, {"asset_id": "78856519471483111489144381430368949435602822511527338537489119566299332945125", "price": "0.64", "size": "5", "side": "SELL", "hash": "1b397c9c668594a7a86af950aee816edee6e5182", "best_bid": "0.004", "best_ask": "0.039"}], "timestamp": "1769384119118", "event_type": "price_change"}}
{"_local_timestamp": "2026-01-25T23:35:19.735254+00:00", "data": {"market": "0x824ff868f6a6935d10d3ccdc5b73c7d9cb5325f31ca80b4a5f093a3871d4ab45", "price_changes": [{"asset_id": "2871426403404885688747962237095784039858305930578199850207892053760319086420", "price": "0.36", "size": "0", "side": "BUY", "hash": "cc22a91cb07d0aa85dc0901dfe19d5ee7657a25e", "best_bid": "0.961", "best_ask": "0.996"}, {"asset_id": "78856519471483111489144381430368949435602822511527338537489119566299332945125", "price": "0.64", "size": "0", "side": "SELL", "hash": "75d6935073f84b1dbaa561d2fc3e473b162b6664", "best_bid": "0.004", "best_ask": "0.039"}], "timestamp": "1769384119669", "event_type": "price_change"}}
{"_local_timestamp": "2026-01-25T23:35:19.950137+00:00", "data": {"market": "0x824ff868f6a6935d10d3ccdc5b73c7d9cb5325f31ca80b4a5f093a3871d4ab45", "price_changes": [{"asset_id": "2871426403404885688747962237095784039858305930578199850207892053760319086420", "price": "0.36", "size": "5", "side": "BUY", "hash": "edca2a551ab2a798ae3325ed30f6097421f75562", "best_bid": "0.961", "best_ask": "0.996"}, {"asset_id": "78856519471483111489144381430368949435602822511527338537489119566299332945125", "price": "0.64", "size": "5", "side": "SELL", "hash": "169fd739787b7224465289ed9968eb4c34dba370", "best_bid": "0.004", "best_ask": "0.039"}], "timestamp": "1769384119876", "event_type": "price_change"}}
{"_local_timestamp": "2026-01-25T23:35:36.266819+00:00", "data": {"market": "0x824ff868f6a6935d10d3ccdc5b73c7d9cb5325f31ca80b4a5f093a3871d4ab45", "price_changes": [{"asset_id": "2871426403404885688747962237095784039858305930578199850207892053760319086420", "price": "0.961", "size": "33.8", "side": "BUY", "hash": "385419fc1bd51ab2b97da5dbd60b03afbf1862a8", "best_bid": "0.961", "best_ask": "0.996"}, {"asset_id": "78856519471483111489144381430368949435602822511527338537489119566299332945125", "price": "0.039", "size": "33.8", "side": "SELL", "hash": "008ee40519649b879b486bda113aae473530c7f8", "best_bid": "0.004", "best_ask": "0.039"}], "timestamp": "1769384136197", "event_type": "price_change"}}
{"_local_timestamp": "2026-01-25T23:35:43.663133+00:00", "data": {"market": "0x8ff260489ea5aa78fa5b3c680b9881b6045af76d6a4f5afe6812f3967ee793a0", "price_changes": [{"asset_id": "34539885844990186168937654116625036865751022263351692260312783883067264034518", "price": "0.978", "size": "61.86", "side": "SELL", "hash": "d3399216391badb6817c046f982343df46e93866", "best_bid": "0.871", "best_ask": "0.978"}, {"asset_id": "1125211017783109589110510546210165660340648360115402691298367602660868269735", "price": "0.022", "size": "61.86", "side": "BUY", "hash": "b6e59461f5fdaa3b9c91d5ec9257a5ebd3e90e0f", "best_bid": "0.022", "best_ask": "0.129"}], "timestamp": "1769384143593", "event_type": "price_change"}}
{"_local_timestamp": "2026-01-25T23:35:45.967132+00:00", "data": {"market": "0x8ff260489ea5aa78fa5b3c680b9881b6045af76d6a4f5afe6812f3967ee793a0", "price_changes": [{"asset_id": "34539885844990186168937654116625036865751022263351692260312783883067264034518", "price": "0.871", "size": "83.63", "side": "BUY", "hash": "48897c24c341ecbea1464731ebe5e966d916cd60", "best_bid": "0.871", "best_ask": "0.978"}, {"asset_id": "1125211017783109589110510546210165660340648360115402691298367602660868269735", "price": "0.129", "size": "83.63", "side": "SELL", "hash": "ee6d4c68380392d829a001da347c8cd343130495", "best_bid": "0.022", "best_ask": "0.129"}], "timestamp": "1769384145900", "event_type": "price_change"}}
{"_local_timestamp": "2026-01-25T23:35:54.881217+00:00", "data": {"market": "0x8ff260489ea5aa78fa5b3c680b9881b6045af76d6a4f5afe6812f3967ee793a0", "price_changes": [{"asset_id": "1125211017783109589110510546210165660340648360115402691298367602660868269735", "price": "0.006", "size": "0", "side": "BUY", "hash": "732424b1355874741b088b78961ac20a9311fb3f", "best_bid": "0.022", "best_ask": "0.129"}, {"asset_id": "34539885844990186168937654116625036865751022263351692260312783883067264034518", "price": "0.994", "size": "0", "side": "SELL", "hash": "1c8bf8288bd91dfbcd103c5e51ca9ded15095abf", "best_bid": "0.871", "best_ask": "0.978"}], "timestamp": "1769384154815", "event_type": "price_change"}}
{"_local_timestamp": "2026-01-25T23:35:55.159870+00:00", "data": {"market": "0x8ff260489ea5aa78fa5b3c680b9881b6045af76d6a4f5afe6812f3967ee793a0", "price_changes": [{"asset_id": "1125211017783109589110510546210165660340648360115402691298367602660868269735", "price": "0.007", "size": "9.55", "side": "BUY", "hash": "b95cfe0cd635b25dd374a5fc4fdec51b243f3220", "best_bid": "0.022", "best_ask": "0.129"}, {"asset_id": "34539885844990186168937654116625036865751022263351692260312783883067264034518", "price": "0.993", "size": "9.55", "side": "SELL", "hash": "665cd27c6055c877aad68ab748567979165c364d", "best_bid": "0.871", "best_ask": "0.978"}], "timestamp": "1769384155059", "event_type": "price_change"}}
{"_local_timestamp": "2026-01-25T23:36:05.277076+00:00", "data": {"market": "0xd97cea4602cceb228056d6597feed4e4805f026ec6d5e7a06dca81b6e05c8d26", "price_changes": [{"asset_id": "58440600010653306781229251941477344349383850231605820632490524164682830491653", "price": "0.011", "size": "109.09", "side": "BUY", "hash": "26427bf67a276a573a1949434598d6177778e0f9", "best_bid": "0.011", "best_ask": "0.029"}, {"asset_id": "90370492639686279760895942864235580169627907120025687040241447968180259582385", "price": "0.989", "size": "109.09", "side": "SELL", "hash": "ae2e21a30bb8962884bb96b1a8857282eb8ecbab", "best_bid": "0.971", "best_ask": "0.989"}], "timestamp": "1769384165167", "event_type": "price_change"}}
{"_local_timestamp": "2026-01-25T23:36:13.547491+00:00", "data": {"market": "0xd97cea4602cceb228056d6597feed4e4805f026ec6d5e7a06dca81b6e05c8d26", "price_changes": [{"asset_id": "58440600010653306781229251941477344349383850231605820632490524164682830491653", "price": "0.01", "size": "0", "side": "BUY", "hash": "fae94a32396ba5fbb74df805247f47333bb645a7", "best_bid": "0.011", "best_ask": "0.029"}, {"asset_id": "90370492639686279760895942864235580169627907120025687040241447968180259582385", "price": "0.99", "size": "0", "side": "SELL", "hash": "8e04a28df12933631d5b1c9bf5ddc5f453c8d596", "best_bid": "0.971", "best_ask": "0.989"}], "timestamp": "1769384173481", "event_type": "price_change"}}
{"_local_timestamp": "2026-01-25T23:36:13.842610+00:00", "data": {"market": "0xd97cea4602cceb228056d6597feed4e4805f026ec6d5e7a06dca81b6e05c8d26", "price_changes": [{"asset_id": "58440600010653306781229251941477344349383850231605820632490524164682830491653", "price": "0.012", "size": "48.95", "side": "BUY", "hash": "11c96027f4ab21886df9a352303bef3e33a0ce9e", "best_bid": "0.012", "best_ask": "0.029"}, {"asset_id": "90370492639686279760895942864235580169627907120025687040241447968180259582385", "price": "0.988", "size": "48.95", "side": "SELL", "hash": "0225a246ba46e04b4bac13f39e85b4d97cb33ed3", "best_bid": "0.971", "best_ask": "0.988"}], "timestamp": "1769384173770", "event_type": "price_change"}}
{"_local_timestamp": "2026-01-25T23:36:31.071745+00:00", "data": {"market": "0xd97cea4602cceb228056d6597feed4e4805f026ec6d5e7a06dca81b6e05c8d26", "price_changes": [{"asset_id": "90370492639686279760895942864235580169627907120025687040241447968180259582385", "price": "0.063", "size": "0", "side": "BUY", "hash": "8550fafff901a3e3de6e4bfb0726f66f31a78fd3", "best_bid": "0.971", "best_ask": "0.988"}, {"asset_id": "58440600010653306781229251941477344349383850231605820632490524164682830491653", "price": "0.937", "size": "0", "side": "SELL", "hash": "bcd953e9e1c206e8f8d55bc747ec1f953276bfcd", "best_bid": "0.012", "best_ask": "0.029"}], "timestamp": "1769384191002", "event_type": "price_change"}}
{"_local_timestamp": "2026-01-25T23:36:31.149615+00:00", "data": {"market": "0xd97cea4602cceb228056d6597feed4e4805f026ec6d5e7a06dca81b6e05c8d26", "price_changes": [{"asset_id": "90370492639686279760895942864235580169627907120025687040241447968180259582385", "price": "0.063", "size": "31", "side": "BUY", "hash": "9124bbfeea672555cb5d53aaf2965b050610ba70", "best_bid": "0.971", "best_ask": "0.988"}, {"asset_id": "58440600010653306781229251941477344349383850231605820632490524164682830491653", "price": "0.937", "size": "31", "side": "SELL", "hash": "c021e9d42b71a3c3390ec02a2817ba15a9125381", "best_bid": "0.012", "best_ask": "0.029"}], "timestamp": "1769384191078", "event_type": "price_change"}}
{"_local_timestamp": "2026-01-25T23:36:57.671056+00:00", "data": {"market": "0xd97cea4602cceb228056d6597feed4e4805f026ec6d5e7a06dca81b6e05c8d26", "price_changes": [{"asset_id": "58440600010653306781229251941477344349383850231605820632490524164682830491653", "price": "0.007", "size": "0", "side": "BUY", "hash": "00874ef67bc4592c25b3d2951facbf12572f3b2f", "best_bid": "0.012", "best_ask": "0.029"}, {"asset_id": "90370492639686279760895942864235580169627907120025687040241447968180259582385", "price": "0.993", "size": "0", "side": "SELL", "hash": "0de964b2987e2ec5fb793d1f2904a3f77f7e9b9f", "best_bid": "0.971", "best_ask": "0.988"}], "timestamp": "1769384217223", "event_type": "price_change"}}
{"_local_timestamp": "2026-01-25T23:36:58.966012+00:00", "data": {"market": "0x8ff260489ea5aa78fa5b3c680b9881b6045af76d6a4f5afe6812f3967ee793a0", "price_changes": [{"asset_id": "34539885844990186168937654116625036865751022263351692260312783883067264034518", "price": "0.002", "size": "460.68", "side": "BUY", "hash": "736504dbe373f6285b1c559b1579efcadc277846", "best_bid": "0.871", "best_ask": "0.978"}, {"asset_id": "1125211017783109589110510546210165660340648360115402691298367602660868269735", "price": "0.998", "size": "460.68", "side": "SELL", "hash": "28aed6b530f6ab12fc80ec8810c3a109c344f93e", "best_bid": "0.022", "best_ask": "0.129"}], "timestamp": "1769384218536", "event_type": "price_change"}}
{"_local_timestamp": "2026-01-25T23:36:58.981755+00:00", "data": {"market": "0x8ff260489ea5aa78fa5b3c680b9881b6045af76d6a4f5afe6812f3967ee793a0", "price_changes": [{"asset_id": "1125211017783109589110510546210165660340648360115402691298367602660868269735", "price": "0.003", "size": "300", "side": "BUY", "hash": "1772bf1301d95ca49c1d220cc3250af312433686", "best_bid": "0.022", "best_ask": "0.129"}, {"asset_id": "34539885844990186168937654116625036865751022263351692260312783883067264034518", "price": "0.997", "size": "300", "side": "SELL", "hash": "10df49bf3aac26d99a14bdd1ddac657001946a82", "best_bid": "0.871", "best_ask": "0.978"}], "timestamp": "1769384218565", "event_type": "price_change"}}
{"_local_timestamp": "2026-01-25T23:36:59.023039+00:00", "data": {"market": "0x824ff868f6a6935d10d3ccdc5b73c7d9cb5325f31ca80b4a5f093a3871d4ab45", "price_changes": [{"asset_id": "2871426403404885688747962237095784039858305930578199850207892053760319086420", "price": "0.004", "size": "1307.92", "side": "BUY", "hash": "8bfba3eff374eef9d7f2a7ddc29bc6f2af0d218e", "best_bid": "0.961", "best_ask": "0.996"}, {"asset_id": "78856519471483111489144381430368949435602822511527338537489119566299332945125", "price": "0.996", "size": "1307.92", "side": "SELL", "hash": "71dea2f24a3f99c271ee863814bed9f74dbe96ac", "best_bid": "0.004", "best_ask": "0.039"}], "timestamp": "1769384218543", "event_type": "price_change"}}
{"_local_timestamp": "2026-01-25T23:36:59.772689+00:00", "data": {"market": "0x824ff868f6a6935d10d3ccdc5b73c7d9cb5325f31ca80b4a5f093a3871d4ab45", "price_changes": [{"asset_id": "78856519471483111489144381430368949435602822511527338537489119566299332945125", "price": "0.002", "size": "318.31", "side": "BUY", "hash": "00e401fbe9ffd9656f75ca471dd8f6c603590d09", "best_bid": "0.004", "best_ask": "0.039"}, {"asset_id": "2871426403404885688747962237095784039858305930578199850207892053760319086420", "price": "0.998", "size": "318.31", "side": "SELL", "hash": "a3cc86e90b89852a005790805656c03abb2323b2", "best_bid": "0.961", "best_ask": "0.996"}], "timestamp": "1769384218569", "event_type": "price_change"}}
{"_local_timestamp": "2026-01-25T23:37:07.153640+00:00", "data": {"market": "0x8ff260489ea5aa78fa5b3c680b9881b6045af76d6a4f5afe6812f3967ee793a0", "price_changes": [{"asset_id": "34539885844990186168937654116625036865751022263351692260312783883067264034518", "price": "0.871", "size": "40.01", "side": "BUY", "hash": "fc95f4a4808268939fb5fb35cade9c561a678e56", "best_bid": "0.871", "best_ask": "0.978"}, {"asset_id": "1125211017783109589110510546210165660340648360115402691298367602660868269735", "price": "0.129", "size": "40.01", "side": "SELL", "hash": "628a85a86cc141517f9851a2a197f26aba524388", "best_bid": "0.022", "best_ask": "0.129"}], "timestamp": "1769384226962", "event_type": "price_change"}}
{"_local_timestamp": "2026-01-25T23:37:25.762828+00:00", "data": {"market": "0xd97cea4602cceb228056d6597feed4e4805f026ec6d5e7a06dca81b6e05c8d26", "price_changes": [{"asset_id": "58440600010653306781229251941477344349383850231605820632490524164682830491653", "price": "0.003", "size": "30", "side": "BUY", "hash": "8102d54d1964e9cda20e87faaa5df4d978b0006a", "best_bid": "0.012", "best_ask": "0.029"}, {"asset_id": "90370492639686279760895942864235580169627907120025687040241447968180259582385", "price": "0.997", "size": "30", "side": "SELL", "hash": "29c22b332c24a4c3140077df6fbea4286cd88899", "best_bid": "0.971", "best_ask": "0.988"}], "timestamp": "1769384245697", "event_type": "price_change"}}
{"_local_timestamp": "2026-01-25T23:37:42.872229+00:00", "data": {"market": "0xd97cea4602cceb228056d6597feed4e4805f026ec6d5e7a06dca81b6e05c8d26", "price_changes": [{"asset_id": "58440600010653306781229251941477344349383850231605820632490524164682830491653", "price": "0.011", "size": "0", "side": "BUY", "hash": "1fb38b499ded550fe84185307c4aa9c582a87fe2", "best_bid": "0.012", "best_ask": "0.029"}, {"asset_id": "90370492639686279760895942864235580169627907120025687040241447968180259582385", "price": "0.989", "size": "0", "side": "SELL", "hash": "f012ad5fef196bb09b1364331e5a4f79d5550183", "best_bid": "0.971", "best_ask": "0.988"}], "timestamp": "1769384262763", "event_type": "price_change"}}
{"_local_timestamp": "2026-01-25T23:37:50.531639+00:00", "data": {"market": "0xdd8912727639d1273193f8b17b89fc6ec525a8dc4a7c462d7d1531a553d3b25c", "price_changes": [{"asset_id": "66760775717731849606178090046166310993448344537844873363422065730421513914311", "price": "0.002", "size": "1000", "side": "BUY", "hash": "ac4793bece4f3c60680978b0b9b72b9810e0c611", "best_bid": "0.006", "best_ask": "0.011"}, {"asset_id": "67558471467857993358297659413470229023460175538336310590556862174269025942807", "price": "0.998", "size": "1000", "side": "SELL", "hash": "46fce974c89dd09d259680ba53c17dfc07ae87ef", "best_bid": "0.989", "best_ask": "0.994"}], "timestamp": "1769384270413", "event_type": "price_change"}}
{"_local_timestamp": "2026-01-25T23:37:50.532763+00:00", "data": {"market": "0xdd8912727639d1273193f8b17b89fc6ec525a8dc4a7c462d7d1531a553d3b25c", "price_changes": [{"asset_id": "66760775717731849606178090046166310993448344537844873363422065730421513914311", "price": "0.004", "size": "0", "side": "BUY", "hash": "ac4793bece4f3c60680978b0b9b72b9810e0c611", "best_bid": "0.006", "best_ask": "0.011"}, {"asset_id": "67558471467857993358297659413470229023460175538336310590556862174269025942807", "price": "0.996", "size": "0", "side": "SELL", "hash": "46fce974c89dd09d259680ba53c17dfc07ae87ef", "best_bid": "0.989", "best_ask": "0.994"}], "timestamp": "1769384270413", "event_type": "price_change"}}
{"_local_timestamp": "2026-01-25T23:37:50.812917+00:00", "data": {"market": "0xdd8912727639d1273193f8b17b89fc6ec525a8dc4a7c462d7d1531a553d3b25c", "price_changes": [{"asset_id": "66760775717731849606178090046166310993448344537844873363422065730421513914311", "price": "0.002", "size": "1013.26", "side": "BUY", "hash": "4c300e3ae2e6269fd01c92d2ef00aa2c7010f214", "best_bid": "0.006", "best_ask": "0.011"}, {"asset_id": "67558471467857993358297659413470229023460175538336310590556862174269025942807", "price": "0.998", "size": "1013.26", "side": "SELL", "hash": "4865735e460366c6e00421cb34b46e51151a4c2d", "best_bid": "0.989", "best_ask": "0.994"}], "timestamp": "1769384270692", "event_type": "price_change"}}
{"_local_timestamp": "2026-01-25T23:37:50.814932+00:00", "data": {"market": "0xdd8912727639d1273193f8b17b89fc6ec525a8dc4a7c462d7d1531a553d3b25c", "price_changes": [{"asset_id": "66760775717731849606178090046166310993448344537844873363422065730421513914311", "price": "0.004", "size": "13.11", "side": "BUY", "hash": "f6a473e16cb8846c9d25d55022776e83e678b7ea", "best_bid": "0.006", "best_ask": "0.011"}, {"asset_id": "67558471467857993358297659413470229023460175538336310590556862174269025942807", "price": "0.996", "size": "13.11", "side": "SELL", "hash": "64aa706176e6acdf8d8f5174fba3e327884ec7e0", "best_bid": "0.989", "best_ask": "0.994"}], "timestamp": "1769384270697", "event_type": "price_change"}}
{"_local_timestamp": "2026-01-25T23:37:53.899771+00:00", "data": {"market": "0xd97cea4602cceb228056d6597feed4e4805f026ec6d5e7a06dca81b6e05c8d26", "price_changes": [{"asset_id": "58440600010653306781229251941477344349383850231605820632490524164682830491653", "price": "0.012", "size": "0", "side": "BUY", "hash": "430f8200939fdad5127be5ba065c18ebd6ac1db9", "best_bid": "0.009", "best_ask": "0.029"}, {"asset_id": "90370492639686279760895942864235580169627907120025687040241447968180259582385", "price": "0.988", "size": "0", "side": "SELL", "hash": "6182ba62294067451016466275a20ed1326813d7", "best_bid": "0.971", "best_ask": "0.991"}], "timestamp": "1769384273767", "event_type": "price_change"}}
{"_local_timestamp": "2026-01-25T23:37:54.218037+00:00", "data": {"market": "0xd97cea4602cceb228056d6597feed4e4805f026ec6d5e7a06dca81b6e05c8d26", "price_changes": [{"asset_id": "58440600010653306781229251941477344349383850231605820632490524164682830491653", "price": "0.01", "size": "48.95", "side": "BUY", "hash": "5394c098d38740f6eb4efe0fa0c5644dbd0160da", "best_bid": "0.01", "best_ask": "0.029"}, {"asset_id": "90370492639686279760895942864235580169627907120025687040241447968180259582385", "price": "0.99", "size": "48.95", "side": "SELL", "hash": "43133d2dbc83194d7da34ecc726c3246f6398f87", "best_bid": "0.971", "best_ask": "0.99"}], "timestamp": "1769384274077", "event_type": "price_change"}}
{"_local_timestamp": "2026-01-25T23:37:57.498310+00:00", "data": {"market": "0x824ff868f6a6935d10d3ccdc5b73c7d9cb5325f31ca80b4a5f093a3871d4ab45", "price_changes": [{"asset_id": "2871426403404885688747962237095784039858305930578199850207892053760319086420", "price": "0.36", "size": "0", "side": "BUY", "hash": "35ece78fe276cf70fb609991736cb65d8c283784", "best_bid": "0.961", "best_ask": "0.996"}, {"asset_id": "78856519471483111489144381430368949435602822511527338537489119566299332945125", "price": "0.64", "size": "0", "side": "SELL", "hash": "176b4e9d96675d2e865dbbdb253b31d96de21e9a", "best_bid": "0.004", "best_ask": "0.039"}], "timestamp": "1769384277380", "event_type": "price_change"}}
{"_local_timestamp": "2026-01-25T23:37:57.626693+00:00", "data": {"market": "0x677db25f882c030e38309fdb93d95ab544092caffedf3a0753460e122533f217", "price_changes": [{"asset_id": "2000710628755694330462323874112265267979163288148760873771120885908845651232", "price": "0.991", "size": "1000", "side": "SELL", "hash": "b94a762e424849fd98a1f9a5a4befed645313304", "best_bid": "0.004", "best_ask": "0.005"}, {"asset_id": "70962355560380333033520368609651913126821476783171408624102605215524414381982", "price": "0.009", "size": "1000", "side": "BUY", "hash": "e522944ee26fa077fca2a00d5211a279b0b6639d", "best_bid": "0.995", "best_ask": "0.996"}], "timestamp": "1769384277513", "event_type": "price_change"}}
{"_local_timestamp": "2026-01-25T23:37:57.787173+00:00", "data": {"market": "0x824ff868f6a6935d10d3ccdc5b73c7d9cb5325f31ca80b4a5f093a3871d4ab45", "price_changes": [{"asset_id": "2871426403404885688747962237095784039858305930578199850207892053760319086420", "price": "0.36", "size": "5", "side": "BUY", "hash": "d83756650e11308b48ecb01275b87934924b2a04", "best_bid": "0.961", "best_ask": "0.996"}, {"asset_id": "78856519471483111489144381430368949435602822511527338537489119566299332945125", "price": "0.64", "size": "5", "side": "SELL", "hash": "78ff0f22b19096b1b32f3a432701058ee0fc4623", "best_bid": "0.004", "best_ask": "0.039"}], "timestamp": "1769384277657", "event_type": "price_change"}}
{"_local_timestamp": "2026-01-25T23:37:57.872338+00:00", "data": {"market": "0x677db25f882c030e38309fdb93d95ab544092caffedf3a0753460e122533f217", "price_changes": [{"asset_id": "2000710628755694330462323874112265267979163288148760873771120885908845651232", "price": "0.99", "size": "150", "side": "SELL", "hash": "7fcca70fb1bbe2868ba56a995b709eedd243e892", "best_bid": "0.004", "best_ask": "0.005"}, {"asset_id": "70962355560380333033520368609651913126821476783171408624102605215524414381982", "price": "0.01", "size": "150", "side": "BUY", "hash": "aa580b5ba249e352b910b73b280c3f868c6daa7f", "best_bid": "0.995", "best_ask": "0.996"}], "timestamp": "1769384277740", "event_type": "price_change"}}
{"_local_timestamp": "2026-01-25T23:38:21.566026+00:00", "data": {"market": "0x8ff260489ea5aa78fa5b3c680b9881b6045af76d6a4f5afe6812f3967ee793a0", "price_changes": [{"asset_id": "34539885844990186168937654116625036865751022263351692260312783883067264034518", "price": "0.871", "size": "83.63", "side": "BUY", "hash": "e3e7636dadec8ac308931f452b81057df6d78ad7", "best_bid": "0.871", "best_ask": "0.978"}, {"asset_id": "1125211017783109589110510546210165660340648360115402691298367602660868269735", "price": "0.129", "size": "83.63", "side": "SELL", "hash": "7594ee807ebb2a038454efe7a62bdcfd30b7dcac", "best_bid": "0.022", "best_ask": "0.129"}], "timestamp": "1769384301481", "event_type": "price_change"}}
{"_local_timestamp": "2026-01-25T23:38:36.423058+00:00", "data": {"market": "0xd97cea4602cceb228056d6597feed4e4805f026ec6d5e7a06dca81b6e05c8d26", "price_changes": [{"asset_id": "58440600010653306781229251941477344349383850231605820632490524164682830491653", "price": "0.009", "size": "0", "side": "BUY", "hash": "c168c0db1ee68c8c08448483a0ef97eb3659d6c1", "best_bid": "0.01", "best_ask": "0.029"}, {"asset_id": "90370492639686279760895942864235580169627907120025687040241447968180259582385", "price": "0.991", "size": "0", "side": "SELL", "hash": "edb0eb5db6620bb64a261c1ffde870e691d2adbb", "best_bid": "0.971", "best_ask": "0.99"}], "timestamp": "1769384316354", "event_type": "price_change"}}
{"_local_timestamp": "2026-01-25T23:38:37.091715+00:00", "data": {"market": "0x824ff868f6a6935d10d3ccdc5b73c7d9cb5325f31ca80b4a5f093a3871d4ab45", "price_changes": [{"asset_id": "2871426403404885688747962237095784039858305930578199850207892053760319086420", "price": "0.961", "size": "13.8", "side": "BUY", "hash": "27964929b8c475109069824d730fc29e6c7939fe", "best_bid": "0.961", "best_ask": "0.996"}, {"asset_id": "78856519471483111489144381430368949435602822511527338537489119566299332945125", "price": "0.039", "size": "13.8", "side": "SELL", "hash": "0931df82c027edf60e00df67626e69a16324cbc2", "best_bid": "0.004", "best_ask": "0.039"}], "timestamp": "1769384317003", "event_type": "price_change"}}
{"_local_timestamp": "2026-01-25T23:38:37.280457+00:00", "data": {"market": "0xd97cea4602cceb228056d6597feed4e4805f026ec6d5e7a06dca81b6e05c8d26", "price_changes": [{"asset_id": "58440600010653306781229251941477344349383850231605820632490524164682830491653", "price": "0.002", "size": "12.69", "side": "BUY", "hash": "8cee84a92cc47b0199cde4e333b20827be81f71a", "best_bid": "0.01", "best_ask": "0.029"}, {"asset_id": "90370492639686279760895942864235580169627907120025687040241447968180259582385", "price": "0.998", "size": "12.69", "side": "SELL", "hash": "52228a50c62bf1ef25cc324da185383e4c72d880", "best_bid": "0.971", "best_ask": "0.99"}], "timestamp": "1769384317209", "event_type": "price_change"}}
{"_local_timestamp": "2026-01-25T23:38:37.549302+00:00", "data": {"market": "0xd97cea4602cceb228056d6597feed4e4805f026ec6d5e7a06dca81b6e05c8d26", "price_changes": [{"asset_id": "58440600010653306781229251941477344349383850231605820632490524164682830491653", "price": "0.004", "size": "27.6", "side": "BUY", "hash": "aec64795eabd0131fa95e3a8e5249b9fef9c713c", "best_bid": "0.01", "best_ask": "0.029"}, {"asset_id": "90370492639686279760895942864235580169627907120025687040241447968180259582385", "price": "0.996", "size": "27.6", "side": "SELL", "hash": "bacb3d76b98c1dfbe1948621087a154ba49784ce", "best_bid": "0.971", "best_ask": "0.99"}], "timestamp": "1769384317481", "event_type": "price_change"}}
{"_local_timestamp": "2026-01-25T23:38:46.095153+00:00", "data": {"market": "0x8ff260489ea5aa78fa5b3c680b9881b6045af76d6a4f5afe6812f3967ee793a0", "price_changes": [{"asset_id": "34539885844990186168937654116625036865751022263351692260312783883067264034518", "price": "0.871", "size": "63.63", "side": "BUY", "hash": "6d315f71ac3caaaa998538049b295a5818177c68", "best_bid": "0.871", "best_ask": "0.978"}, {"asset_id": "1125211017783109589110510546210165660340648360115402691298367602660868269735", "price": "0.129", "size": "63.63", "side": "SELL", "hash": "4f4baaf0181d957e646b158f0013700cdb81d294", "best_bid": "0.022", "best_ask": "0.129"}], "timestamp": "1769384326003", "event_type": "price_change"}}
{"_local_timestamp": "2026-01-25T23:38:46.927654+00:00", "data": {"market": "0xd97cea4602cceb228056d6597feed4e4805f026ec6d5e7a06dca81b6e05c8d26", "price_changes": [{"asset_id": "58440600010653306781229251941477344349383850231605820632490524164682830491653", "price": "0.01", "size": "0", "side": "BUY", "hash": "86c26ea1a1fb0b50bc90524e7854e0f714a8e5e7", "best_bid": "0.004", "best_ask": "0.029"}, {"asset_id": "90370492639686279760895942864235580169627907120025687040241447968180259582385", "price": "0.99", "size": "0", "side": "SELL", "hash": "3157ad34afae826be05574949c724b32394f0041", "best_bid": "0.971", "best_ask": "0.996"}], "timestamp": "1769384326847", "event_type": "price_change"}}
{"_local_timestamp": "2026-01-25T23:38:47.107691+00:00", "data": {"market": "0x824ff868f6a6935d10d3ccdc5b73c7d9cb5325f31ca80b4a5f093a3871d4ab45", "price_changes": [{"asset_id": "78856519471483111489144381430368949435602822511527338537489119566299332945125", "price": "0.002", "size": "326.08", "side": "BUY", "hash": "a1d63c2948dbb843a86b37df46856c933f2515b3", "best_bid": "0.004", "best_ask": "0.039"}, {"asset_id": "2871426403404885688747962237095784039858305930578199850207892053760319086420", "price": "0.998", "size": "326.08", "side": "SELL", "hash": "9342f61a829b4093a479b22c0f5d1954b9a1d146", "best_bid": "0.961", "best_ask": "0.996"}], "timestamp": "1769384327018", "event_type": "price_change"}}
{"_local_timestamp": "2026-01-25T23:38:47.108275+00:00", "data": {"market": "0x824ff868f6a6935d10d3ccdc5b73c7d9cb5325f31ca80b4a5f093a3871d4ab45", "price_changes": [{"asset_id": "78856519471483111489144381430368949435602822511527338537489119566299332945125", "price": "0.003", "size": "101.98", "side": "BUY", "hash": "35e5aa9d89d30b4a4749d394edd7bcb2c7d8c38b", "best_bid": "0.004", "best_ask": "0.039"}, {"asset_id": "2871426403404885688747962237095784039858305930578199850207892053760319086420", "price": "0.997", "size": "101.98", "side": "SELL", "hash": "9ec5e6bda01997ba1be00f626ec88519ad2d7c15", "best_bid": "0.961", "best_ask": "0.996"}], "timestamp": "1769384327019", "event_type": "price_change"}}
{"_local_timestamp": "2026-01-25T23:38:47.172906+00:00", "data": {"market": "0x824ff868f6a6935d10d3ccdc5b73c7d9cb5325f31ca80b4a5f093a3871d4ab45", "price_changes": [{"asset_id": "78856519471483111489144381430368949435602822511527338537489119566299332945125", "price": "0.002", "size": "333.85", "side": "BUY", "hash": "b7e1c37a8ae17b4137bef3b26697f1a97d7bc945", "best_bid": "0.004", "best_ask": "0.039"}, {"asset_id": "2871426403404885688747962237095784039858305930578199850207892053760319086420", "price": "0.998", "size": "333.85", "side": "SELL", "hash": "73b8e46da4d6cabd0dd5720ee059a5993b7644e6", "best_bid": "0.961", "best_ask": "0.996"}], "timestamp": "1769384327104", "event_type": "price_change"}}
{"_local_timestamp": "2026-01-25T23:38:47.173415+00:00", "data": {"market": "0x824ff868f6a6935d10d3ccdc5b73c7d9cb5325f31ca80b4a5f093a3871d4ab45", "price_changes": [{"asset_id": "78856519471483111489144381430368949435602822511527338537489119566299332945125", "price": "0.003", "size": "111.13", "side": "BUY", "hash": "2afcdbb57b05a85a66bb9a2edcde52258df4a37c", "best_bid": "0.004", "best_ask": "0.039"}, {"asset_id": "2871426403404885688747962237095784039858305930578199850207892053760319086420", "price": "0.997", "size": "111.13", "side": "SELL", "hash": "9a6d6ab3bbfd38a4804db131edca319fb6616f98", "best_bid": "0.961", "best_ask": "0.996"}], "timestamp": "1769384327105", "event_type": "price_change"}}
{"_local_timestamp": "2026-01-25T23:38:47.192834+00:00", "data": {"market": "0xd97cea4602cceb228056d6597feed4e4805f026ec6d5e7a06dca81b6e05c8d26", "price_changes": [{"asset_id": "58440600010653306781229251941477344349383850231605820632490524164682830491653", "price": "0.005", "size": "48.95", "side": "BUY", "hash": "c6ff7d3327fcfc642849991f900a0c89ecd9dc3f", "best_bid": "0.005", "best_ask": "0.029"}, {"asset_id": "90370492639686279760895942864235580169627907120025687040241447968180259582385", "price": "0.995", "size": "48.95", "side": "SELL", "hash": "07c40c1b089d7e4721c976b35e807ff9a53ffd55", "best_bid": "0.971", "best_ask": "0.995"}], "timestamp": "1769384327127", "event_type": "price_change"}}
{"_local_timestamp": "2026-01-25T23:38:48.228901+00:00", "data": {"market": "0x824ff868f6a6935d10d3ccdc5b73c7d9cb5325f31ca80b4a5f093a3871d4ab45", "price_changes": [{"asset_id": "78856519471483111489144381430368949435602822511527338537489119566299332945125", "price": "0.002", "size": "318.31", "side": "BUY", "hash": "305a077d1baa6b89d899d05b06fe570485ef9c62", "best_bid": "0.004", "best_ask": "0.039"}, {"asset_id": "2871426403404885688747962237095784039858305930578199850207892053760319086420", "price": "0.998", "size": "318.31", "side": "SELL", "hash": "9f8103c1a79734bc2ecb0f7d22685c9a343efa0a", "best_bid": "0.961", "best_ask": "0.996"}], "timestamp": "1769384328152", "event_type": "price_change"}}
{"_local_timestamp": "2026-01-25T23:38:48.229399+00:00", "data": {"market": "0x824ff868f6a6935d10d3ccdc5b73c7d9cb5325f31ca80b4a5f093a3871d4ab45", "price_changes": [{"asset_id": "78856519471483111489144381430368949435602822511527338537489119566299332945125", "price": "0.003", "size": "92.83", "side": "BUY", "hash": "305a077d1baa6b89d899d05b06fe570485ef9c62", "best_bid": "0.004", "best_ask": "0.039"}, {"asset_id": "2871426403404885688747962237095784039858305930578199850207892053760319086420", "price": "0.997", "size": "92.83", "side": "SELL", "hash": "9f8103c1a79734bc2ecb0f7d22685c9a343efa0a", "best_bid": "0.961", "best_ask": "0.996"}], "timestamp": "1769384328152", "event_type": "price_change"}}
{"_local_timestamp": "2026-01-25T23:38:48.644981+00:00", "data": {"market": "0x824ff868f6a6935d10d3ccdc5b73c7d9cb5325f31ca80b4a5f093a3871d4ab45", "price_changes": [{"asset_id": "78856519471483111489144381430368949435602822511527338537489119566299332945125", "price": "0.003", "size": "101.98", "side": "BUY", "hash": "3b12ac4cf9dc12ff28edc21f56570796a93aaf5f", "best_bid": "0.004", "best_ask": "0.039"}, {"asset_id": "2871426403404885688747962237095784039858305930578199850207892053760319086420", "price": "0.997", "size": "101.98", "side": "SELL", "hash": "71ffd255be53cb1d10c950cfbb0a639d774f9c8e", "best_bid": "0.961", "best_ask": "0.996"}], "timestamp": "1769384328573", "event_type": "price_change"}}
{"_local_timestamp": "2026-01-25T23:38:48.645470+00:00", "data": {"market": "0x824ff868f6a6935d10d3ccdc5b73c7d9cb5325f31ca80b4a5f093a3871d4ab45", "price_changes": [{"asset_id": "78856519471483111489144381430368949435602822511527338537489119566299332945125", "price": "0.002", "size": "326.08", "side": "BUY", "hash": "fcb045261dee8d3fa706f26f7b6197d99736bac8", "best_bid": "0.004", "best_ask": "0.039"}, {"asset_id": "2871426403404885688747962237095784039858305930578199850207892053760319086420", "price": "0.998", "size": "326.08", "side": "SELL", "hash": "0153c5b81c1dc3b32344bd83e8a35a5753f774f4", "best_bid": "0.961", "best_ask": "0.996"}], "timestamp": "1769384328574", "event_type": "price_change"}}
{"_local_timestamp": "2026-01-25T23:38:52.093684+00:00", "data": {"market": "0xb56bcce3c29679dbab4467e57810e73fccafadf46b0770942aaef66c5b74c8dc", "price_changes": [{"asset_id": "70162704708176551332494543434209796474919283850328944065576455499958010645095", "price": "0.999", "size": "10496.73", "side": "BUY", "hash": "366803ec42206fcfed94fae1c8d3e2545d9b093e", "best_bid": "0.999", "best_ask": "1"}, {"asset_id": "78738246149098397928345880429189437989748486055647346887139225093279301789493", "price": "0.001", "size": "10496.73", "side": "SELL", "hash": "c3f159713660b534f0f2e98d03671c4eb6f15a52", "best_bid": "0", "best_ask": "0.001"}], "timestamp": "1769384332026", "event_type": "price_change"}}
{"_local_timestamp": "2026-01-25T23:38:52.592244+00:00", "data": {"market": "0x8ff260489ea5aa78fa5b3c680b9881b6045af76d6a4f5afe6812f3967ee793a0", "price_changes": [{"asset_id": "1125211017783109589110510546210165660340648360115402691298367602660868269735", "price": "0.007", "size": "0", "side": "BUY", "hash": "72eef97e5c6eb2bedeeae2f476e7a3bd5c0044ac", "best_bid": "0.022", "best_ask": "0.129"}, {"asset_id": "34539885844990186168937654116625036865751022263351692260312783883067264034518", "price": "0.993", "size": "0", "side": "SELL", "hash": "3a02cde168d6bb786538d47a75dcebef351c960f", "best_bid": "0.871", "best_ask": "0.978"}], "timestamp": "1769384332516", "event_type": "price_change"}}
{"_local_timestamp": "2026-01-25T23:38:53.102747+00:00", "data": {"market": "0x8ff260489ea5aa78fa5b3c680b9881b6045af76d6a4f5afe6812f3967ee793a0", "price_changes": [{"asset_id": "1125211017783109589110510546210165660340648360115402691298367602660868269735", "price": "0.008", "size": "58.35", "side": "BUY", "hash": "dbdbb96ae6a81bcebb600baa72df7191d5e56001", "best_bid": "0.022", "best_ask": "0.129"}, {"asset_id": "34539885844990186168937654116625036865751022263351692260312783883067264034518", "price": "0.992", "size": "58.35", "side": "SELL", "hash": "40dfd53898baaff141d0629fff26f3c891be292a", "best_bid": "0.871", "best_ask": "0.978"}], "timestamp": "1769384333011", "event_type": "price_change"}}
{"_local_timestamp": "2026-01-25T23:38:54.263665+00:00", "data": {"market": "0xb56bcce3c29679dbab4467e57810e73fccafadf46b0770942aaef66c5b74c8dc", "price_changes": [{"asset_id": "70162704708176551332494543434209796474919283850328944065576455499958010645095", "price": "0.999", "size": "15496.73", "side": "BUY", "hash": "85c740b3fa4255d7c68928520229008b9a706b74", "best_bid": "0.999", "best_ask": "1"}, {"asset_id": "78738246149098397928345880429189437989748486055647346887139225093279301789493", "price": "0.001", "size": "15496.73", "side": "SELL", "hash": "7ff836208df9c2130612f7e395894ec2661a6418", "best_bid": "0", "best_ask": "0.001"}], "timestamp": "1769384334193", "event_type": "price_change"}}
{"_local_timestamp": "2026-01-25T23:38:57.292516+00:00", "data": {"market": "0xb56bcce3c29679dbab4467e57810e73fccafadf46b0770942aaef66c5b74c8dc", "price_changes": [{"asset_id": "70162704708176551332494543434209796474919283850328944065576455499958010645095", "price": "0.999", "size": "25496.73", "side": "BUY", "hash": "104c75c54ca3849cf5343f0e69c064c9a10648f9", "best_bid": "0.999", "best_ask": "1"}, {"asset_id": "78738246149098397928345880429189437989748486055647346887139225093279301789493", "price": "0.001", "size": "25496.73", "side": "SELL", "hash": "04ace375368180d99a4f58cd3647a53e20feb4a9", "best_bid": "0", "best_ask": "0.001"}], "timestamp": "1769384337228", "event_type": "price_change"}}
{"_local_timestamp": "2026-01-25T23:38:57.640382+00:00", "data": {"market": "0xb56bcce3c29679dbab4467e57810e73fccafadf46b0770942aaef66c5b74c8dc", "price_changes": [{"asset_id": "70162704708176551332494543434209796474919283850328944065576455499958010645095", "price": "0.999", "size": "35495.73", "side": "BUY", "hash": "565fc81558b144fd873654e6cb93c22b45b578da", "best_bid": "0.999", "best_ask": "1"}, {"asset_id": "78738246149098397928345880429189437989748486055647346887139225093279301789493", "price": "0.001", "size": "35495.73", "side": "SELL", "hash": "f1df6a70ebb7780f6f426629a11fca21586f6a6b", "best_bid": "0", "best_ask": "0.001"}], "timestamp": "1769384337575", "event_type": "price_change"}}
{"_local_timestamp": "2026-01-25T23:38:58.584573+00:00", "data": {"market": "0xb56bcce3c29679dbab4467e57810e73fccafadf46b0770942aaef66c5b74c8dc", "price_changes": [{"asset_id": "70162704708176551332494543434209796474919283850328944065576455499958010645095", "price": "0.999", "size": "45493.73", "side": "BUY", "hash": "fb12b8c8f33a0605f733426fa12fec2ca0f10403", "best_bid": "0.999", "best_ask": "1"}, {"asset_id": "78738246149098397928345880429189437989748486055647346887139225093279301789493", "price": "0.001", "size": "45493.73", "side": "SELL", "hash": "13eeb7806378c9435f01c76425fccce3e215e2ae", "best_bid": "0", "best_ask": "0.001"}], "timestamp": "1769384338373", "event_type": "price_change"}}
{"_local_timestamp": "2026-01-25T23:38:58.782118+00:00", "data": {"market": "0xb56bcce3c29679dbab4467e57810e73fccafadf46b0770942aaef66c5b74c8dc", "price_changes": [{"asset_id": "70162704708176551332494543434209796474919283850328944065576455499958010645095", "price": "0.999", "size": "55490.73", "side": "BUY", "hash": "df12ffff9d2ff8855f89305f906f3a79dabf6239", "best_bid": "0.999", "best_ask": "1"}, {"asset_id": "78738246149098397928345880429189437989748486055647346887139225093279301789493", "price": "0.001", "size": "55490.73", "side": "SELL", "hash": "3a7b9a5b96ae2ae92abc21afd019573539dce62d", "best_bid": "0", "best_ask": "0.001"}], "timestamp": "1769384338709", "event_type": "price_change"}}
{"_local_timestamp": "2026-01-25T23:38:59.808952+00:00", "data": {"market": "0xb56bcce3c29679dbab4467e57810e73fccafadf46b0770942aaef66c5b74c8dc", "price_changes": [{"asset_id": "70162704708176551332494543434209796474919283850328944065576455499958010645095", "price": "0.999", "size": "65486.73", "side": "BUY", "hash": "b5da0ca3ef907ef595590b9eadd65b13ecd3545e", "best_bid": "0.999", "best_ask": "1"}, {"asset_id": "78738246149098397928345880429189437989748486055647346887139225093279301789493", "price": "0.001", "size": "65486.73", "side": "SELL", "hash": "8a8c7c3f835af044e4db83dcf6809988fbd4bd22", "best_bid": "0", "best_ask": "0.001"}], "timestamp": "1769384339745", "event_type": "price_change"}}
{"_local_timestamp": "2026-01-25T23:39:00.144370+00:00", "data": {"market": "0xb56bcce3c29679dbab4467e57810e73fccafadf46b0770942aaef66c5b74c8dc", "price_changes": [{"asset_id": "70162704708176551332494543434209796474919283850328944065576455499958010645095", "price": "0.999", "size": "75481.73", "side": "BUY", "hash": "f1671816cdb36ac6b200da099e1b90d7c0c2ea05", "best_bid": "0.999", "best_ask": "1"}, {"asset_id": "78738246149098397928345880429189437989748486055647346887139225093279301789493", "price": "0.001", "size": "75481.73", "side": "SELL", "hash": "d0ec2b05cfaea30e04124e66b69623c97777896e", "best_bid": "0", "best_ask": "0.001"}], "timestamp": "1769384340079", "event_type": "price_change"}}
{"_local_timestamp": "2026-01-25T23:39:00.705610+00:00", "data": {"market": "0xb56bcce3c29679dbab4467e57810e73fccafadf46b0770942aaef66c5b74c8dc", "price_changes": [{"asset_id": "70162704708176551332494543434209796474919283850328944065576455499958010645095", "price": "0.999", "size": "85475.73", "side": "BUY", "hash": "127c7121847314745546b0d8f71e8ce2922754bf", "best_bid": "0.999", "best_ask": "1"}, {"asset_id": "78738246149098397928345880429189437989748486055647346887139225093279301789493", "price": "0.001", "size": "85475.73", "side": "SELL", "hash": "72d19cf271ece5935f1d9f9791b4732ef85cbf5d", "best_bid": "0", "best_ask": "0.001"}], "timestamp": "1769384340623", "event_type": "price_change"}}
{"_local_timestamp": "2026-01-25T23:39:01.180783+00:00", "data": {"market": "0xb56bcce3c29679dbab4467e57810e73fccafadf46b0770942aaef66c5b74c8dc", "price_changes": [{"asset_id": "70162704708176551332494543434209796474919283850328944065576455499958010645095", "price": "0.999", "size": "95468.73", "side": "BUY", "hash": "c1148e2d364010a6d7acc58354c8eb4713980c2d", "best_bid": "0.999", "best_ask": "1"}, {"asset_id": "78738246149098397928345880429189437989748486055647346887139225093279301789493", "price": "0.001", "size": "95468.73", "side": "SELL", "hash": "c11e709988454ab986a60bf3fd9cce15715a3b25", "best_bid": "0", "best_ask": "0.001"}], "timestamp": "1769384341110", "event_type": "price_change"}}
{"_local_timestamp": "2026-01-25T23:39:02.820677+00:00", "data": {"market": "0xb56bcce3c29679dbab4467e57810e73fccafadf46b0770942aaef66c5b74c8dc", "price_changes": [{"asset_id": "70162704708176551332494543434209796474919283850328944065576455499958010645095", "price": "0.999", "size": "96092.73", "side": "BUY", "hash": "ddd125db68c581b78c2d34bb5ce56336d5302956", "best_bid": "0.999", "best_ask": "1"}, {"asset_id": "78738246149098397928345880429189437989748486055647346887139225093279301789493", "price": "0.001", "size": "96092.73", "side": "SELL", "hash": "23a4f1c4600eeba26ed00b9ade6ec96f3df4ab52", "best_bid": "0", "best_ask": "0.001"}], "timestamp": "1769384342752", "event_type": "price_change"}}
{"_local_timestamp": "2026-01-25T23:39:03.392314+00:00", "data": {"market": "0xb56bcce3c29679dbab4467e57810e73fccafadf46b0770942aaef66c5b74c8dc", "price_changes": [{"asset_id": "70162704708176551332494543434209796474919283850328944065576455499958010645095", "price": "0.999", "size": "96715.73", "side": "BUY", "hash": "9e9eb6322ff02e4ee944b0340ca019f5b6269fab", "best_bid": "0.999", "best_ask": "1"}, {"asset_id": "78738246149098397928345880429189437989748486055647346887139225093279301789493", "price": "0.001", "size": "96715.73", "side": "SELL", "hash": "9366c4c146ff7d3619a051a3c367b47b0f8b5160", "best_bid": "0", "best_ask": "0.001"}], "timestamp": "1769384343329", "event_type": "price_change"}}
{"_local_timestamp": "2026-01-25T23:39:04.647169+00:00", "data": {"market": "0xb56bcce3c29679dbab4467e57810e73fccafadf46b0770942aaef66c5b74c8dc", "price_changes": [{"asset_id": "70162704708176551332494543434209796474919283850328944065576455499958010645095", "price": "0.999", "size": "96753.73", "side": "BUY", "hash": "8f0c34f8cfa4ed907827353b8e63c312da3aabaa", "best_bid": "0.999", "best_ask": "1"}, {"asset_id": "78738246149098397928345880429189437989748486055647346887139225093279301789493", "price": "0.001", "size": "96753.73", "side": "SELL", "hash": "597a7bea684c232e019441479ba47c79e0b8eac4", "best_bid": "0", "best_ask": "0.001"}], "timestamp": "1769384344578", "event_type": "price_change"}}
{"_local_timestamp": "2026-01-25T23:39:05.236305+00:00", "data": {"market": "0xb56bcce3c29679dbab4467e57810e73fccafadf46b0770942aaef66c5b74c8dc", "price_changes": [{"asset_id": "70162704708176551332494543434209796474919283850328944065576455499958010645095", "price": "0.999", "size": "96790.73", "side": "BUY", "hash": "ae8e6ed445b1e8fa85ad09efeda9f0c0aba33db2", "best_bid": "0.999", "best_ask": "1"}, {"asset_id": "78738246149098397928345880429189437989748486055647346887139225093279301789493", "price": "0.001", "size": "96790.73", "side": "SELL", "hash": "b7072c7624ae5664762ba5ad98ecedfbcdba7de2", "best_bid": "0", "best_ask": "0.001"}], "timestamp": "1769384345173", "event_type": "price_change"}}
{"_local_timestamp": "2026-01-25T23:39:11.461883+00:00", "data": {"market": "0xd97cea4602cceb228056d6597feed4e4805f026ec6d5e7a06dca81b6e05c8d26", "price_changes": [{"asset_id": "58440600010653306781229251941477344349383850231605820632490524164682830491653", "price": "0.006", "size": "199.99", "side": "BUY", "hash": "99cba45f91511bf64ba4c2b1ac1aeb9d68f7eed3", "best_bid": "0.006", "best_ask": "0.029"}, {"asset_id": "90370492639686279760895942864235580169627907120025687040241447968180259582385", "price": "0.994", "size": "199.99", "side": "SELL", "hash": "8bdb8f893e03f44b6e4d8c70294af810d23ce777", "best_bid": "0.971", "best_ask": "0.994"}], "timestamp": "1769384351397", "event_type": "price_change"}}
{"_local_timestamp": "2026-01-25T23:39:18.011475+00:00", "data": {"market": "0xd97cea4602cceb228056d6597feed4e4805f026ec6d5e7a06dca81b6e05c8d26", "price_changes": [{"asset_id": "58440600010653306781229251941477344349383850231605820632490524164682830491653", "price": "0.005", "size": "0", "side": "BUY", "hash": "d977b3ea8816bf9581e8e492380172de347cbffe", "best_bid": "0.006", "best_ask": "0.029"}, {"asset_id": "90370492639686279760895942864235580169627907120025687040241447968180259582385", "price": "0.995", "size": "0", "side": "SELL", "hash": "2dd04f32aad66c078ac4212924a26ac29206fbf2", "best_bid": "0.971", "best_ask": "0.994"}], "timestamp": "1769384357942", "event_type": "price_change"}}
{"_local_timestamp": "2026-01-25T23:39:18.340503+00:00", "data": {"market": "0xd97cea4602cceb228056d6597feed4e4805f026ec6d5e7a06dca81b6e05c8d26", "price_changes": [{"asset_id": "58440600010653306781229251941477344349383850231605820632490524164682830491653", "price": "0.007", "size": "48.95", "side": "BUY", "hash": "911ba98a778f9bd1f393c7211d0107d73cddeece", "best_bid": "0.007", "best_ask": "0.029"}, {"asset_id": "90370492639686279760895942864235580169627907120025687040241447968180259582385", "price": "0.993", "size": "48.95", "side": "SELL", "hash": "22ff5e0f7e8a22e0ef85d11997b0b9b22f4b5b6d", "best_bid": "0.971", "best_ask": "0.993"}], "timestamp": "1769384358274", "event_type": "price_change"}}
{"_local_timestamp": "2026-01-25T23:39:20.622760+00:00", "data": {"market": "0x824ff868f6a6935d10d3ccdc5b73c7d9cb5325f31ca80b4a5f093a3871d4ab45", "price_changes": [{"asset_id": "2871426403404885688747962237095784039858305930578199850207892053760319086420", "price": "0.961", "size": "33.8", "side": "BUY", "hash": "ebd296e19c8c58a88d5e2d56d6a1c0e6b8e2f504", "best_bid": "0.961", "best_ask": "0.996"}, {"asset_id": "78856519471483111489144381430368949435602822511527338537489119566299332945125", "price": "0.039", "size": "33.8", "side": "SELL", "hash": "0b21802dabf35b9563443d66003a11e5ffd99c23", "best_bid": "0.004", "best_ask": "0.039"}], "timestamp": "1769384360405", "event_type": "price_change"}}
{"_local_timestamp": "2026-01-25T23:39:31.871720+00:00", "data": {"market": "0x8ff260489ea5aa78fa5b3c680b9881b6045af76d6a4f5afe6812f3967ee793a0", "price_changes": [{"asset_id": "34539885844990186168937654116625036865751022263351692260312783883067264034518", "price": "0.871", "size": "83.63", "side": "BUY", "hash": "9b2e43280756abc25f24b1922c8149ece860aa1f", "best_bid": "0.871", "best_ask": "0.978"}, {"asset_id": "1125211017783109589110510546210165660340648360115402691298367602660868269735", "price": "0.129", "size": "83.63", "side": "SELL", "hash": "04dd13d5e2e5b0bada0db9b2c79a49a63607fb17", "best_bid": "0.022", "best_ask": "0.129"}], "timestamp": "1769384371791", "event_type": "price_change"}}
