{"_local_timestamp": "2026-01-25T23:33:32.127072+00:00", "data": [{"market": "0x2b88daef17413d970ccfcd80042243e08c49d257b9ce916124be0c45cefa3700", "asset_id": "52524163922571923183266519099402467935730326233022494206279867476007301859150", "timestamp": "1769383925536", "hash": "fddd3b9d62bee7876aab3e7e58f3fd28b4dd8601", "bids": [{"price": "0.01", "size": "6260.34"}, {"price": "0.02", "size": "2750"}, {"price": "0.03", "size": "506.46"}, {"price": "0.04", "size": "250"}, {"price": "0.05", "size": "330"}, {"price": "0.06", "size": "33"}, {"price": "0.07", "size": "7.49"}, {"price": "0.09", "size": "1000"}, {"price": "0.14", "size": "567.85"}, {"price": "0.19", "size": "418.42"}, {"price": "0.2", "size": "5.88"}, {"price": "0.23", "size": "321.73"}, {"price": "0.24", "size": "160"}, {"price": "0.27", "size": "50"}, {"price": "0.28", "size": "92.85"}, {"price": "0.33", "size": "72.72"}, {"price": "0.34", "size": "50"}, {"price": "0.38", "size": "52.63"}, {"price": "0.45", "size": "376"}, {"price": "0.46", "size": "354"}, {"price": "0.47", "size": "5"}, {"price": "0.48", "size": "10"}, {"price": "0.49", "size": "20"}, {"price": "0.71", "size": "30"}, {"price": "0.72", "size": "20"}, {"price": "0.78", "size": "15.2"}, {"price": "0.8", "size": "756.14"}, {"price": "0.81", "size": "244"}, {"price": "0.82", "size": "90"}, {"price": "0.9", "size": "30"}], "asks": [{"price": "0.99", "size": "1005"}, {"price": "0.98", "size": "250"}, {"price": "0.95", "size": "37.47"}, {"price": "0.94", "size": "400"}, {"price": "0.92", "size": "844.03"}], "event_type": "book", "last_trade_price": ""}, {"market": "0xdfdcd530887c39781b31f164d7a5b74ba4cf3f511b05d556fde85283e67168f9", "asset_id": "62822673758473888087109044730409570258111717068753960435826531265266236629509", "timestamp": "1769383917195", "hash": "1c51c2ff529c2f3378f734bdd1e9e5d64ff89677", "bids": [{"price": "0.001", "size": "112507"}, {"price": "0.002", "size": "800.74"}], "asks": [{"price": "0.999", "size": "4832.26"}, {"price": "0.998", "size": "1255.24"}, {"price": "0.997", "size": "1400"}, {"price": "0.996", "size": "9.09"}, {"price": "0.994", "size": "200"}, {"price": "0.99", "size": "6550"}, {"price": "0.989", "size": "9.17"}, {"price": "0.98", "size": "2750"}, {"price": "0.97", "size": "500"}, {"price": "0.969", "size": "6.1"}, {"price": "0.96", "size": "250"}, {"price": "0.95", "size": "330"}, {"price": "0.949", "size": "39"}, {"price": "0.93", "size": "300"}, {"price": "0.929", "size": "7.22"}, {"price": "0.9", "size": "560"}, {"price": "0.85", "size": "551.66"}, {"price": "0.8", "size": "460"}, {"price": "0.799", "size": "5.69"}, {"price": "0.75", "size": "112"}, {"price": "0.749", "size": "281"}, {"price": "0.73", "size": "50"}, {"price": "0.7", "size": "86.66"}, {"price": "0.65", "size": "68.57"}, {"price": "0.6", "size": "100"}, {"price": "0.548", "size": "854"}, {"price": "0.547", "size": "220"}, {"price": "0.506", "size": "5"}, {"price": "0.493", "size": "60"}, {"price": "0.491", "size": "25"}, {"price": "0.49", "size": "20"}, {"price": "0.17", "size": "5"}, {"price": "0.08", "size": "5"}, {"price": "0.01", "size": "110"}, {"price": "0.005", "size": "252.5"}, {"price": "0.004", "size": "443.89"}, {"price": "0.003", "size": "402.67"}], "event_type": "book", "last_trade_price": ""}, {"market": "0x5999cfd552cbcf89bbd54c0e48b08c74182caefb18a80f1782018dcef2520d2d", "asset_id": "5430476248758985969939507303101680818848966275102949447275298704026336588828", "timestamp": "1769383929162", "hash": "94bf6cebacc0006eb69b18cebb9137e7cc630539", "bids": [{"price": "0.001", "size": "77363.27"}], "asks": [{"price": "0.999", "size": "6127.26"}, {"price": "0.998", "size": "1255.24"}, {"price": "0.997", "size": "1166"}, {"price": "0.996", "size": "9.09"}, {"price": "0.994", "size": "83"}, {"price": "0.99", "size": "6550"}, {"price": "0.989", "size": "9.17"}, {"price": "0.98", "size": "2750"}, {"price": "0.97", "size": "500"}, {"price": "0.969", "size": "6.1"}, {"price": "0.96", "size": "250"}, {"price": "0.95", "size": "330"}, {"price": "0.949", "size": "39"}, {"price": "0.93", "size": "300"}, {"price": "0.929", "size": "7.22"}, {"price": "0.9", "size": "560"}, {"price": "0.85", "size": "551.66"}, {"price": "0.8", "size": "460"}, {"price": "0.799", "size": "230"}, {"price": "0.798", "size": "5.66"}, {"price": "0.75", "size": "262"}, {"price": "0.73", "size": "50"}, {"price": "0.7", "size": "86.66"}, {"price": "0.66", "size": "50"}, {"price": "0.65", "size": "68.57"}, {"price": "0.6", "size": "50"}, {"price": "0.549", "size": "5"}, {"price": "0.547", "size": "795"}, {"price": "0.546", "size": "280"}, {"price": "0.472", "size": "5"}, {"price": "0.3", "size": "7"}, {"price": "0.251", "size": "10"}, {"price": "0.25", "size": "25"}, {"price": "0.248", "size": "20"}, {"price": "0.246", "size": "30"}, {"price": "0.245", "size": "20"}, {"price": "0.178", "size": "13.33"}, {"price": "0.005", "size": "237.5"}, {"price": "0.004", "size": "520.18"}, {"price": "0.002", "size": "19.99"}], "event_type": "book", "last_trade_price": ""}, {"market": "0xc2ac7ebd46fa81ad41a5072a14a2a77c362d18744596848500541c4406051068", "asset_id": "82937290481922399100659521402638226726618911184164616630445131262753902545289", "timestamp": "1769383924108", "hash": "df754c8d4a76d28e8a060a6ee95297ed1c742b1f", "bids": [{"price": "0.01", "size": "6555.21"}, {"price": "0.02", "size": "2755.04"}, {"price": "0.03", "size": "500"}, {"price": "0.04", "size": "255.84"}, {"price": "0.05", "size": "330"}, {"price": "0.06", "size": "33"}, {"price": "0.08", "size": "300"}, {"price": "0.09", "size": "5.57"}, {"price": "0.12", "size": "325"}, {"price": "0.18", "size": "500"}, {"price": "0.19", "size": "250"}, {"price": "0.2", "size": "50"}, {"price": "0.21", "size": "5.29"}, {"price": "0.29", "size": "419"}, {"price": "0.35", "size": "542"}, {"price": "0.36", "size": "5"}, {"price": "0.63", "size": "7.5"}, {"price": "0.65", "size": "7.5"}, {"price": "0.66", "size": "60"}, {"price": "0.69", "size": "38.84"}, {"price": "0.7", "size": "15.71"}, {"price": "0.73", "size": "66.66"}, {"price": "0.74", "size": "15"}, {"price": "0.77", "size": "66.66"}, {"price": "0.78", "size": "440.95"}, {"price": "0.79", "size": "114.76"}], "asks": [{"price": "0.99", "size": "100"}, {"price": "0.98", "size": "311.11"}, {"price": "0.96", "size": "462.5"}, {"price": "0.95", "size": "450"}, {"price": "0.94", "size": "325"}, {"price": "0.93", "size": "300"}, {"price": "0.92", "size": "214"}, {"price": "0.91", "size": "44"}, {"price": "0.9", "size": "25"}, {"price": "0.89", "size": "14"}], "event_type": "book", "last_trade_price": ""}, {"market": "0x755e71197eb78ca86e6c2e6f2dd7f3627e58a8e20e199afd6343a2f62e72fc7d", "asset_id": "15041248527212347147811488680125841745254730872155301672818398041068079601058", "timestamp": "1769383925536", "hash": "912d441b410ddc2988d747e80396ded353ddffad", "bids": [{"price": "0.01", "size": "5"}, {"price": "0.02", "size": "300"}, {"price": "0.03", "size": "307.4"}, {"price": "0.04", "size": "200"}, {"price": "0.05", "size": "150"}, {"price": "0.06", "size": "100"}, {"price": "0.08", "size": "162.5"}, {"price": "0.09", "size": "61.11"}, {"price": "0.12", "size": "109"}, {"price": "0.17", "size": "5.17"}, {"price": "0.18", "size": "54.9"}], "asks": [{"price": "0.99", "size": "6655.27"}, {"price": "0.98", "size": "2755.1"}, {"price": "0.97", "size": "500"}, {"price": "0.96", "size": "255.91"}, {"price": "0.95", "size": "310"}, {"price": "0.92", "size": "750"}, {"price": "0.91", "size": "5.63"}, {"price": "0.87", "size": "586.53"}, {"price": "0.83", "size": "438.23"}, {"price": "0.82", "size": "219"}, {"price": "0.79", "size": "183.33"}, {"price": "0.78", "size": "5"}, {"price": "0.74", "size": "100"}, {"price": "0.7", "size": "280"}, {"price": "0.66", "size": "58.82"}, {"price": "0.63", "size": "383"}, {"price": "0.62", "size": "782"}, {"price": "0.61", "size": "5"}, {"price": "0.6", "size": "10"}, {"price": "0.43", "size": "30"}, {"price": "0.41", "size": "40"}, {"price": "0.37", "size": "73.13"}, {"price": "0.36", "size": "5.55"}, {"price": "0.33", "size": "19.4"}, {"price": "0.32", "size": "16.17"}, {"price": "0.24", "size": "200"}, {"price": "0.23", "size": "5"}, {"price": "0.22", "size": "510.84"}, {"price": "0.21", "size": "56.12"}], "event_type": "book", "last_trade_price": ""}, {"market": "0xbf593af69b62768d353e7c7226255c51ed19ca32c84a54c0d49a85553b42a46d", "asset_id": "24341167601280829695615199444200891915914435646386891986504787893119831754606", "timestamp": "1769383924572", "hash": "f1a25386251002c65bbf9063a32648b8ff596423", "bids": [{"price": "0.001", "size": "4865.26"}, {"price": "0.002", "size": "1255.24"}, {"price": "0.003", "size": "1400"}, {"price": "0.004", "size": "9.09"}, {"price": "0.006", "size": "200"}, {"price": "0.01", "size": "6550"}, {"price": "0.011", "size": "9.17"}, {"price": "0.02", "size": "2750"}, {"price": "0.03", "size": "500"}, {"price": "0.031", "size": "6.1"}, {"price": "0.04", "size": "250"}, {"price": "0.05", "size": "330"}, {"price": "0.051", "size": "39"}, {"price": "0.07", "size": "300"}, {"price": "0.071", "size": "7.27"}, {"price": "0.1", "size": "560"}, {"price": "0.15", "size": "551.66"}, {"price": "0.2", "size": "210"}, {"price": "0.201", "size": "117"}, {"price": "0.202", "size": "5.65"}, {"price": "0.25", "size": "112"}, {"price": "0.27", "size": "50"}, {"price": "0.3", "size": "86.66"}, {"price": "0.34", "size": "50"}, {"price": "0.35", "size": "68.57"}, {"price": "0.4", "size": "50"}, {"price": "0.445", "size": "1122"}, {"price": "0.447", "size": "5"}, {"price": "0.448", "size": "68"}, {"price": "0.76", "size": "6.05"}, {"price": "0.761", "size": "20"}, {"price": "0.789", "size": "30"}, {"price": "0.791", "size": "20"}, {"price": "0.86", "size": "6.05"}, {"price": "0.88", "size": "10"}, {"price": "0.988", "size": "9.83"}, {"price": "0.995", "size": "44"}, {"price": "0.996", "size": "860.81"}], "asks": [{"price": "0.999", "size": "53538.17"}], "event_type": "book", "last_trade_price": ""}, {"market": "0x755e71197eb78ca86e6c2e6f2dd7f3627e58a8e20e199afd6343a2f62e72fc7d", "asset_id": "28961994487539524115483388590435047266855663289365844982134174724453599686933", "timestamp": "1769383925536", "hash": "858ca922be0a1a6ec8c7f7842695d65f896f0bdc", "bids": [{"price": "0.01", "size": "6655.27"}, {"price": "0.02", "size": "2755.1"}, {"price": "0.03", "size": "500"}, {"price": "0.04", "size": "255.91"}, {"price": "0.05", "size": "310"}, {"price": "0.08", "size": "750"}, {"price": "0.09", "size": "5.63"}, {"price": "0.13", "size": "586.53"}, {"price": "0.17", "size": "438.23"}, {"price": "0.18", "size": "219"}, {"price": "0.21", "size": "183.33"}, {"price": "0.22", "size": "5"}, {"price": "0.26", "size": "100"}, {"price": "0.3", "size": "280"}, {"price": "0.34", "size": "58.82"}, {"price": "0.37", "size": "383"}, {"price": "0.38", "size": "782"}, {"price": "0.39", "size": "5"}, {"price": "0.4", "size": "10"}, {"price": "0.57", "size": "30"}, {"price": "0.59", "size": "40"}, {"price": "0.63", "size": "73.13"}, {"price": "0.64", "size": "5.55"}, {"price": "0.67", "size": "19.4"}, {"price": "0.68", "size": "16.17"}, {"price": "0.76", "size": "200"}, {"price": "0.77", "size": "5"}, {"price": "0.78", "size": "510.84"}, {"price": "0.79", "size": "56.12"}], "asks": [{"price": "0.99", "size": "5"}, {"price": "0.98", "size": "300"}, {"price": "0.97", "size": "307.4"}, {"price": "0.96", "size": "200"}, {"price": "0.95", "size": "150"}, {"price": "0.94", "size": "100"}, {"price": "0.92", "size": "162.5"}, {"price": "0.91", "size": "61.11"}, {"price": "0.88", "size": "109"}, {"price": "0.83", "size": "5.17"}, {"price": "0.82", "size": "54.9"}], "event_type": "book", "last_trade_price": ""}, {"market": "0x3f1fcc84cfce0835e90422a970f37e9d0e4187a4c25f7fac9b4b8a1c13abaa0c", "asset_id": "80297900658960573493828276022367220412132525071135705784317878924056840421254", "timestamp": "1769383767851", "hash": "2f3593e3c97578f34ae78ec89138839c07da84bd", "bids": [{"price": "0.001", "size": "53575.91"}], "asks": [{"price": "0.999", "size": "4832.26"}, {"price": "0.998", "size": "1255.24"}, {"price": "0.997", "size": "1400"}, {"price": "0.996", "size": "9.09"}, {"price": "0.994", "size": "200"}, {"price": "0.99", "size": "6550"}, {"price": "0.989", "size": "9.17"}, {"price": "0.98", "size": "2750"}, {"price": "0.97", "size": "500"}, {"price": "0.969", "size": "6.1"}, {"price": "0.96", "size": "250"}, {"price": "0.95", "size": "330"}, {"price": "0.949", "size": "39"}, {"price": "0.93", "size": "300"}, {"price": "0.929", "size": "7.22"}, {"price": "0.9", "size": "560"}, {"price": "0.85", "size": "551.66"}, {"price": "0.8", "size": "460"}, {"price": "0.799", "size": "5.69"}, {"price": "0.75", "size": "112"}, {"price": "0.749", "size": "281"}, {"price": "0.73", "size": "50"}, {"price": "0.7", "size": "86.66"}, {"price": "0.66", "size": "50"}, {"price": "0.65", "size": "68.57"}, {"price": "0.6", "size": "50"}, {"price": "0.543", "size": "1092"}, {"price": "0.458", "size": "5"}, {"price": "0.452", "size": "10"}, {"price": "0.45", "size": "50"}, {"price": "0.449", "size": "20"}, {"price": "0.177", "size": "10"}, {"price": "0.15", "size": "5"}, {"price": "0.13", "size": "5"}, {"price": "0.06", "size": "10"}, {"price": "0.021", "size": "5"}, {"price": "0.02", "size": "130.43"}, {"price": "0.005", "size": "25"}, {"price": "0.004", "size": "576.35"}, {"price": "0.003", "size": "386.41"}], "event_type": "book", "last_trade_price": ""}, {"market": "0x0fc1398bb3cff37d77101392989d6ff065d28d7c0dc50b282bd1b5098b9d78b8", "asset_id": "76309699246141587406891686852898742630368640356883728029522206362139036530694", "timestamp": "1769383940678", "hash": "50b0c0b37bd03c7f151c29e3730f7640fd8b41f9", "bids": [{"price": "0.001", "size": "111840"}, {"price": "0.002", "size": "16509.42"}, {"price": "0.003", "size": "1000"}, {"price": "0.004", "size": "4101.62"}, {"price": "0.005", "size": "1000"}, {"price": "0.008", "size": "1024"}, {"price": "0.009", "size": "6.67"}, {"price": "0.01", "size": "1000"}, {"price": "0.012", "size": "512"}, {"price": "0.016", "size": "256"}, {"price": "0.02", "size": "628"}, {"price": "0.021", "size": "100"}, {"price": "0.022", "size": "200"}, {"price": "0.023", "size": "6.07"}, {"price": "0.024", "size": "64"}, {"price": "0.03", "size": "300"}, {"price": "0.031", "size": "300"}, {"price": "0.032", "size": "226.61"}, {"price": "0.034", "size": "100"}, {"price": "0.035", "size": "50"}, {"price": "0.049", "size": "10.61"}, {"price": "0.063", "size": "107"}, {"price": "0.064", "size": "8"}, {"price": "0.066", "size": "10.61"}], "asks": [{"price": "0.999", "size": "4887.96"}, {"price": "0.998", "size": "1250"}, {"price": "0.997", "size": "1407.03"}, {"price": "0.994", "size": "200"}, {"price": "0.993", "size": "10.34"}, {"price": "0.99", "size": "6250"}, {"price": "0.98", "size": "2750"}, {"price": "0.979", "size": "7.26"}, {"price": "0.97", "size": "500"}, {"price": "0.96", "size": "250"}, {"price": "0.95", "size": "330"}, {"price": "0.949", "size": "39"}, {"price": "0.948", "size": "10.95"}, {"price": "0.91", "size": "1000"}, {"price": "0.86", "size": "567.85"}, {"price": "0.81", "size": "418.42"}, {"price": "0.809", "size": "6.14"}, {"price": "0.77", "size": "171.73"}, {"price": "0.72", "size": "355.85"}, {"price": "0.719", "size": "83.75"}, {"price": "0.718", "size": "41"}, {"price": "0.67", "size": "72.72"}, {"price": "0.66", "size": "50"}, {"price": "0.63", "size": "54.05"}, {"price": "0.59", "size": "5"}, {"price": "0.586", "size": "301"}, {"price": "0.585", "size": "10"}, {"price": "0.584", "size": "66.66"}, {"price": "0.349", "size": "66.66"}, {"price": "0.294", "size": "20"}, {"price": "0.293", "size": "30"}, {"price": "0.292", "size": "20"}, {"price": "0.242", "size": "13.33"}, {"price": "0.113", "size": "241.35"}, {"price": "0.111", "size": "25"}, {"price": "0.109", "size": "27.09"}, {"price": "0.108", "size": "66.66"}], "event_type": "book", "last_trade_price": ""}, {"market": "0xdfdcd530887c39781b31f164d7a5b74ba4cf3f511b05d556fde85283e67168f9", "asset_id": "1636496992763537371831953986108582665416540026084425365422723872343591218546", "timestamp": "1769383917195", "hash": "9c3654edf715c3b7deb6c8a7fad5a81435157a56", "bids": [{"price": "0.001", "size": "4832.26"}, {"price": "0.002", "size": "1255.24"}, {"price": "0.003", "size": "1400"}, {"price": "0.004", "size": "9.09"}, {"price": "0.006", "size": "200"}, {"price": "0.01", "size": "6550"}, {"price": "0.011", "size": "9.17"}, {"price": "0.02", "size": "2750"}, {"price": "0.03", "size": "500"}, {"price": "0.031", "size": "6.1"}, {"price": "0.04", "size": "250"}, {"price": "0.05", "size": "330"}, {"price": "0.051", "size": "39"}, {"price": "0.07", "size": "300"}, {"price": "0.071", "size": "7.22"}, {"price": "0.1", "size": "560"}, {"price": "0.15", "size": "551.66"}, {"price": "0.2", "size": "460"}, {"price": "0.201", "size": "5.69"}, {"price": "0.25", "size": "112"}, {"price": "0.251", "size": "281"}, {"price": "0.27", "size": "50"}, {"price": "0.3", "size": "86.66"}, {"price": "0.35", "size": "68.57"}, {"price": "0.4", "size": "100"}, {"price": "0.452", "size": "854"}, {"price": "0.453", "size": "220"}, {"price": "0.494", "size": "5"}, {"price": "0.507", "size": "60"}, {"price": "0.509", "size": "25"}, {"price": "0.51", "size": "20"}, {"price": "0.83", "size": "5"}, {"price": "0.92", "size": "5"}, {"price": "0.99", "size": "110"}, {"price": "0.995", "size": "252.5"}, {"price": "0.996", "size": "443.89"}, {"price": "0.997", "size": "402.67"}], "asks": [{"price": "0.999", "size": "112507"}, {"price": "0.998", "size": "800.74"}], "event_type": "book", "last_trade_price": ""}, {"market": "0x50b7269de278116b89044eaf94f7045d5e9e85c3728ae0d651bbe5599b3f99f6", "asset_id": "283788967750103101007432353423042743776533232373505402707349699437390434257", "timestamp": "1769383602325", "hash": "98cae712bb052673de92312108cd594937df4301", "bids": [{"price": "0.01", "size": "5005"}, {"price": "0.02", "size": "1400"}, {"price": "0.03", "size": "7.4"}, {"price": "0.04", "size": "2400"}, {"price": "0.06", "size": "500"}, {"price": "0.07", "size": "485.71"}, {"price": "0.09", "size": "355.55"}, {"price": "0.11", "size": "579.54"}, {"price": "0.12", "size": "127"}, {"price": "0.14", "size": "185.71"}, {"price": "0.15", "size": "40"}, {"price": "0.16", "size": "150"}, {"price": "0.18", "size": "111.11"}, {"price": "0.29", "size": "250"}, {"price": "0.3", "size": "43.33"}, {"price": "0.32", "size": "30"}, {"price": "0.33", "size": "283.33"}, {"price": "0.34", "size": "266.99"}, {"price": "0.35", "size": "105"}, {"price": "0.36", "size": "258"}, {"price": "0.37", "size": "5"}, {"price": "0.38", "size": "105"}, {"price": "0.39", "size": "5"}, {"price": "0.4", "size": "5"}], "asks": [{"price": "0.99", "size": "6562.05"}, {"price": "0.98", "size": "2750"}, {"price": "0.97", "size": "505.7"}, {"price": "0.96", "size": "250"}, {"price": "0.95", "size": "310"}, {"price": "0.94", "size": "8.25"}, {"price": "0.92", "size": "550"}, {"price": "0.85", "size": "325"}, {"price": "0.84", "size": "7.58"}, {"price": "0.8", "size": "668"}, {"price": "0.79", "size": "9"}, {"price": "0.72", "size": "157.6"}, {"price": "0.71", "size": "10"}, {"price": "0.7", "size": "20"}, {"price": "0.61", "size": "40"}, {"price": "0.6", "size": "20"}, {"price": "0.55", "size": "400"}, {"price": "0.53", "size": "30"}, {"price": "0.52", "size": "27.08"}, {"price": "0.51", "size": "22.44"}, {"price": "0.46", "size": "550.44"}, {"price": "0.45", "size": "39.61"}, {"price": "0.44", "size": "79.22"}, {"price": "0.43", "size": "23"}], "event_type": "book", "last_trade_price": ""}, {"market": "0x0fc1398bb3cff37d77101392989d6ff065d28d7c0dc50b282bd1b5098b9d78b8", "asset_id": "89336264239989122383122704165255872699177887882264330841492281051298522223986", "timestamp": "1769383940678", "hash": "83f4d90dc12882f8d54b1a8ad652a879c261398c", "bids": [{"price": "0.001", "size": "4887.96"}, {"price": "0.002", "size": "1250"}, {"price": "0.003", "size": "1407.03"}, {"price": "0.006", "size": "200"}, {"price": "0.007", "size": "10.34"}, {"price": "0.01", "size": "6250"}, {"price": "0.02", "size": "2750"}, {"price": "0.021", "size": "7.26"}, {"price": "0.03", "size": "500"}, {"price": "0.04", "size": "250"}, {"price": "0.05", "size": "330"}, {"price": "0.051", "size": "39"}, {"price": "0.052", "size": "10.95"}, {"price": "0.09", "size": "1000"}, {"price": "0.14", "size": "567.85"}, {"price": "0.19", "size": "418.42"}, {"price": "0.191", "size": "6.14"}, {"price": "0.23", "size": "171.73"}, {"price": "0.28", "size": "355.85"}, {"price": "0.281", "size": "83.75"}, {"price": "0.282", "size": "41"}, {"price": "0.33", "size": "72.72"}, {"price": "0.34", "size": "50"}, {"price": "0.37", "size": "54.05"}, {"price": "0.41", "size": "5"}, {"price": "0.414", "size": "301"}, {"price": "0.415", "size": "10"}, {"price": "0.416", "size": "66.66"}, {"price": "0.651", "size": "66.66"}, {"price": "0.706", "size": "20"}, {"price": "0.707", "size": "30"}, {"price": "0.708", "size": "20"}, {"price": "0.758", "size": "13.33"}, {"price": "0.887", "size": "241.35"}, {"price": "0.889", "size": "25"}, {"price": "0.891", "size": "27.09"}, {"price": "0.892", "size": "66.66"}], "asks": [{"price": "0.999", "size": "111840"}, {"price": "0.998", "size": "16509.42"}, {"price": "0.997", "size": "1000"}, {"price": "0.996", "size": "4101.62"}, {"price": "0.995", "size": "1000"}, {"price": "0.992", "size": "1024"}, {"price": "0.991", "size": "6.67"}, {"price": "0.99", "size": "1000"}, {"price": "0.988", "size": "512"}, {"price": "0.984", "size": "256"}, {"price": "0.98", "size": "628"}, {"price": "0.979", "size": "100"}, {"price": "0.978", "size": "200"}, {"price": "0.977", "size": "6.07"}, {"price": "0.976", "size": "64"}, {"price": "0.97", "size": "300"}, {"price": "0.969", "size": "300"}, {"price": "0.968", "size": "226.61"}, {"price": "0.966", "size": "100"}, {"price": "0.965", "size": "50"}, {"price": "0.951", "size": "10.61"}, {"price": "0.937", "size": "107"}, {"price": "0.936", "size": "8"}, {"price": "0.934", "size": "10.61"}], "event_type": "book", "last_trade_price": ""}, {"market": "0x5999cfd552cbcf89bbd54c0e48b08c74182caefb18a80f1782018dcef2520d2d", "asset_id": "15174546601205928046556699082541161461166100492124394241054975981067833950165", "timestamp": "1769383929162", "hash": "3c2c3d270af9dbe4ab35a75bcef7616bf62fceb2", "bids": [{"price": "0.001", "size": "6127.26"}, {"price": "0.002", "size": "1255.24"}, {"price": "0.003", "size": "1166"}, {"price": "0.004", "size": "9.09"}, {"price": "0.006", "size": "83"}, {"price": "0.01", "size": "6550"}, {"price": "0.011", "size": "9.17"}, {"price": "0.02", "size": "2750"}, {"price": "0.03", "size": "500"}, {"price": "0.031", "size": "6.1"}, {"price": "0.04", "size": "250"}, {"price": "0.05", "size": "330"}, {"price": "0.051", "size": "39"}, {"price": "0.07", "size": "300"}, {"price": "0.071", "size": "7.22"}, {"price": "0.1", "size": "560"}, {"price": "0.15", "size": "551.66"}, {"price": "0.2", "size": "460"}, {"price": "0.201", "size": "230"}, {"price": "0.202", "size": "5.66"}, {"price": "0.25", "size": "262"}, {"price": "0.27", "size": "50"}, {"price": "0.3", "size": "86.66"}, {"price": "0.34", "size": "50"}, {"price": "0.35", "size": "68.57"}, {"price": "0.4", "size": "50"}, {"price": "0.451", "size": "5"}, {"price": "0.453", "size": "795"}, {"price": "0.454", "size": "280"}, {"price": "0.528", "size": "5"}, {"price": "0.7", "size": "7"}, {"price": "0.749", "size": "10"}, {"price": "0.75", "size": "25"}, {"price": "0.752", "size": "20"}, {"price": "0.754", "size": "30"}, {"price": "0.755", "size": "20"}, {"price": "0.822", "size": "13.33"}, {"price": "0.995", "size": "237.5"}, {"price": "0.996", "size": "520.18"}, {"price": "0.998", "size": "19.99"}], "asks": [{"price": "0.999", "size": "77363.27"}], "event_type": "book", "last_trade_price": ""}, {"market": "0x3f1fcc84cfce0835e90422a970f37e9d0e4187a4c25f7fac9b4b8a1c13abaa0c", "asset_id": "88740501643316642368489847410696453938131074491242982225810722843753273684210", "timestamp": "1769383767851", "hash": "a94411455ba01a14759240f0d8c7927903ced93d", "bids": [{"price": "0.001", "size": "4832.26"}, {"price": "0.002", "size": "1255.24"}, {"price": "0.003", "size": "1400"}, {"price": "0.004", "size": "9.09"}, {"price": "0.006", "size": "200"}, {"price": "0.01", "size": "6550"}, {"price": "0.011", "size": "9.17"}, {"price": "0.02", "size": "2750"}, {"price": "0.03", "size": "500"}, {"price": "0.031", "size": "6.1"}, {"price": "0.04", "size": "250"}, {"price": "0.05", "size": "330"}, {"price": "0.051", "size": "39"}, {"price": "0.07", "size": "300"}, {"price": "0.071", "size": "7.22"}, {"price": "0.1", "size": "560"}, {"price": "0.15", "size": "551.66"}, {"price": "0.2", "size": "460"}, {"price": "0.201", "size": "5.69"}, {"price": "0.25", "size": "112"}, {"price": "0.251", "size": "281"}, {"price": "0.27", "size": "50"}, {"price": "0.3", "size": "86.66"}, {"price": "0.34", "size": "50"}, {"price": "0.35", "size": "68.57"}, {"price": "0.4", "size": "50"}, {"price": "0.457", "size": "1092"}, {"price": "0.542", "size": "5"}, {"price": "0.548", "size": "10"}, {"price": "0.55", "size": "50"}, {"price": "0.551", "size": "20"}, {"price": "0.823", "size": "10"}, {"price": "0.85", "size": "5"}, {"price": "0.87", "size": "5"}, {"price": "0.94", "size": "10"}, {"price": "0.979", "size": "5"}, {"price": "0.98", "size": "130.43"}, {"price": "0.995", "size": "25"}, {"price": "0.996", "size": "576.35"}, {"price": "0.997", "size": "386.41"}], "asks": [{"price": "0.999", "size": "53575.91"}], "event_type": "book", "last_trade_price": ""}, {"market": "0xc2ac7ebd46fa81ad41a5072a14a2a77c362d18744596848500541c4406051068", "asset_id": "36008003405201249169700080930810811641068357582790575985437372346931394635255", "timestamp": "1769383924108", "hash": "1a26c1204b5369098b04816c3cfd9c027c3769a7", "bids": [{"price": "0.01", "size": "100"}, {"price": "0.02", "size": "311.11"}, {"price": "0.04", "size": "462.5"}, {"price": "0.05", "size": "450"}, {"price": "0.06", "size": "325"}, {"price": "0.07", "size": "300"}, {"price": "0.08", "size": "214"}, {"price": "0.09", "size": "44"}, {"price": "0.1", "size": "25"}, {"price": "0.11", "size": "14"}], "asks": [{"price": "0.99", "size": "6555.21"}, {"price": "0.98", "size": "2755.04"}, {"price": "0.97", "size": "500"}, {"price": "0.96", "size": "255.84"}, {"price": "0.95", "size": "330"}, {"price": "0.94", "size": "33"}, {"price": "0.92", "size": "300"}, {"price": "0.91", "size": "5.57"}, {"price": "0.88", "size": "325"}, {"price": "0.82", "size": "500"}, {"price": "0.81", "size": "250"}, {"price": "0.8", "size": "50"}, {"price": "0.79", "size": "5.29"}, {"price": "0.71", "size": "419"}, {"price": "0.65", "size": "542"}, {"price": "0.64", "size": "5"}, {"price": "0.37", "size": "7.5"}, {"price": "0.35", "size": "7.5"}, {"price": "0.34", "size": "60"}, {"price": "0.31", "size": "38.84"}, {"price": "0.3", "size": "15.71"}, {"price": "0.27", "size": "66.66"}, {"price": "0.26", "size": "15"}, {"price": "0.23", "size": "66.66"}, {"price": "0.22", "size": "440.95"}, {"price": "0.21", "size": "114.76"}], "event_type": "book", "last_trade_price": ""}, {"market": "0xbf593af69b62768d353e7c7226255c51ed19ca32c84a54c0d49a85553b42a46d", "asset_id": "2688038676615161490720640654323264340577430230677806835743854904343477854167", "timestamp": "1769383924572", "hash": "1229964e692101e161cba7dcd2b17fb9baedb33b", "bids": [{"price": "0.001", "size": "53538.17"}], "asks": [{"price": "0.999", "size": "4865.26"}, {"price": "0.998", "size": "1255.24"}, {"price": "0.997", "size": "1400"}, {"price": "0.996", "size": "9.09"}, {"price": "0.994", "size": "200"}, {"price": "0.99", "size": "6550"}, {"price": "0.989", "size": "9.17"}, {"price": "0.98", "size": "2750"}, {"price": "0.97", "size": "500"}, {"price": "0.969", "size": "6.1"}, {"price": "0.96", "size": "250"}, {"price": "0.95", "size": "330"}, {"price": "0.949", "size": "39"}, {"price": "0.93", "size": "300"}, {"price": "0.929", "size": "7.27"}, {"price": "0.9", "size": "560"}, {"price": "0.85", "size": "551.66"}, {"price": "0.8", "size": "210"}, {"price": "0.799", "size": "117"}, {"price": "0.798", "size": "5.65"}, {"price": "0.75", "size": "112"}, {"price": "0.73", "size": "50"}, {"price": "0.7", "size": "86.66"}, {"price": "0.66", "size": "50"}, {"price": "0.65", "size": "68.57"}, {"price": "0.6", "size": "50"}, {"price": "0.555", "size": "1122"}, {"price": "0.553", "size": "5"}, {"price": "0.552", "size": "68"}, {"price": "0.24", "size": "6.05"}, {"price": "0.239", "size": "20"}, {"price": "0.211", "size": "30"}, {"price": "0.209", "size": "20"}, {"price": "0.14", "size": "6.05"}, {"price": "0.12", "size": "10"}, {"price": "0.012", "size": "9.83"}, {"price": "0.005", "size": "44"}, {"price": "0.004", "size": "860.81"}], "event_type": "book", "last_trade_price": ""}, {"market": "0x2b88daef17413d970ccfcd80042243e08c49d257b9ce916124be0c45cefa3700", "asset_id": "79155825810081376702240953828322969529947608905353673983878554604270354457205", "timestamp": "1769383925536", "hash": "c33f8af2dca238f67610578c3addcfb2c9a33814", "bids": [{"price": "0.01", "size": "1005"}, {"price": "0.02", "size": "250"}, {"price": "0.05", "size": "37.47"}, {"price": "0.06", "size": "400"}, {"price": "0.08", "size": "844.03"}], "asks": [{"price": "0.99", "size": "6260.34"}, {"price": "0.98", "size": "2750"}, {"price": "0.97", "size": "506.46"}, {"price": "0.96", "size": "250"}, {"price": "0.95", "size": "330"}, {"price": "0.94", "size": "33"}, {"price": "0.93", "size": "7.49"}, {"price": "0.91", "size": "1000"}, {"price": "0.86", "size": "567.85"}, {"price": "0.81", "size": "418.42"}, {"price": "0.8", "size": "5.88"}, {"price": "0.77", "size": "321.73"}, {"price": "0.76", "size": "160"}, {"price": "0.73", "size": "50"}, {"price": "0.72", "size": "92.85"}, {"price": "0.67", "size": "72.72"}, {"price": "0.66", "size": "50"}, {"price": "0.62", "size": "52.63"}, {"price": "0.55", "size": "376"}, {"price": "0.54", "size": "354"}, {"price": "0.53", "size": "5"}, {"price": "0.52", "size": "10"}, {"price": "0.51", "size": "20"}, {"price": "0.29", "size": "30"}, {"price": "0.28", "size": "20"}, {"price": "0.22", "size": "15.2"}, {"price": "0.2", "size": "756.14"}, {"price": "0.19", "size": "244"}, {"price": "0.18", "size": "90"}, {"price": "0.1", "size": "30"}], "event_type": "book", "last_trade_price": ""}, {"market": "0x50b7269de278116b89044eaf94f7045d5e9e85c3728ae0d651bbe5599b3f99f6", "asset_id": "71308826674668002924695884681622672518892265389670898865299790136737098682652", "timestamp": "1769383602325", "hash": "ae5b7359ad51291d35d6b7570c7ba92fd87d1ca3", "bids": [{"price": "0.01", "size": "6562.05"}, {"price": "0.02", "size": "2750"}, {"price": "0.03", "size": "505.7"}, {"price": "0.04", "size": "250"}, {"price": "0.05", "size": "310"}, {"price": "0.06", "size": "8.25"}, {"price": "0.08", "size": "550"}, {"price": "0.15", "size": "325"}, {"price": "0.16", "size": "7.58"}, {"price": "0.2", "size": "668"}, {"price": "0.21", "size": "9"}, {"price": "0.28", "size": "157.6"}, {"price": "0.29", "size": "10"}, {"price": "0.3", "size": "20"}, {"price": "0.39", "size": "40"}, {"price": "0.4", "size": "20"}, {"price": "0.45", "size": "400"}, {"price": "0.47", "size": "30"}, {"price": "0.48", "size": "27.08"}, {"price": "0.49", "size": "22.44"}, {"price": "0.54", "size": "550.44"}, {"price": "0.55", "size": "39.61"}, {"price": "0.56", "size": "79.22"}, {"price": "0.57", "size": "23"}], "asks": [{"price": "0.99", "size": "5005"}, {"price": "0.98", "size": "1400"}, {"price": "0.97", "size": "7.4"}, {"price": "0.96", "size": "2400"}, {"price": "0.94", "size": "500"}, {"price": "0.93", "size": "485.71"}, {"price": "0.91", "size": "355.55"}, {"price": "0.89", "size": "579.54"}, {"price": "0.88", "size": "127"}, {"price": "0.86", "size": "185.71"}, {"price": "0.85", "size": "40"}, {"price": "0.84", "size": "150"}, {"price": "0.82", "size": "111.11"}, {"price": "0.71", "size": "250"}, {"price": "0.7", "size": "43.33"}, {"price": "0.68", "size": "30"}, {"price": "0.67", "size": "283.33"}, {"price": "0.66", "size": "266.99"}, {"price": "0.65", "size": "105"}, {"price": "0.64", "size": "258"}, {"price": "0.63", "size": "5"}, {"price": "0.62", "size": "105"}, {"price": "0.61", "size": "5"}, {"price": "0.6", "size": "5"}], "event_type": "book", "last_trade_price": ""}]}
{"_local_timestamp": "2026-01-25T23:33:33.360582+00:00", "data": {"market": "0xdfdcd530887c39781b31f164d7a5b74ba4cf3f511b05d556fde85283e67168f9", "price_changes": [{"asset_id": "1636496992763537371831953986108582665416540026084425365422723872343591218546", "price": "0.4", "size": "50", "side": "BUY", "hash": "d968fe17c36600ac20d8318e2f6f7bdca4b59572", "best_bid": "0.997", "best_ask": "0.998"}, {"asset_id": "62822673758473888087109044730409570258111717068753960435826531265266236629509", "price": "0.6", "size": "50", "side": "SELL", "hash": "18a92c664d736a9787fdba801b22d1a04cf67b96", "best_bid": "0.002", "best_ask": "0.003"}], "timestamp": "1769384013152", "event_type": "price_change"}}
{"_local_timestamp": "2026-01-25T23:33:33.495372+00:00", "data": {"market": "0x5999cfd552cbcf89bbd54c0e48b08c74182caefb18a80f1782018dcef2520d2d", "price_changes": [{"asset_id": "15174546601205928046556699082541161461166100492124394241054975981067833950165", "price": "0.75", "size": "10", "side": "BUY", "hash": "54a772912e5254071e622b64f1afb5b1e948b822", "best_bid": "0.998", "best_ask": "0.999"}, {"asset_id": "5430476248758985969939507303101680818848966275102949447275298704026336588828", "price": "0.25", "size": "10", "side": "SELL", "hash": "b3bb989961921fb815a9f78d87741f5a49db7816", "best_bid": "0.001", "best_ask": "0.002"}], "timestamp": "1769384013359", "event_type": "price_change"}}
{"_local_timestamp": "2026-01-25T23:33:33.638534+00:00", "data": {"market": "0x3f1fcc84cfce0835e90422a970f37e9d0e4187a4c25f7fac9b4b8a1c13abaa0c", "price_changes": [{"asset_id": "88740501643316642368489847410696453938131074491242982225810722843753273684210", "price": "0.548", "size": "0", "side": "BUY", "hash": "848507790d221cf7c1c34bb86a0fa6a2764f6bf2", "best_bid": "0.997", "best_ask": "0.999"}, {"asset_id": "80297900658960573493828276022367220412132525071135705784317878924056840421254", "price": "0.452", "size": "0", "side": "SELL", "hash": "dafb576f1a8a17efba327968ab7751003831481b", "best_bid": "0.001", "best_ask": "0.003"}], "timestamp": "1769384013553", "event_type": "price_change"}}
{"_local_timestamp": "2026-01-25T23:33:33.703682+00:00", "data": {"market": "0xdfdcd530887c39781b31f164d7a5b74ba4cf3f511b05d556fde85283e67168f9", "price_changes": [{"asset_id": "1636496992763537371831953986108582665416540026084425365422723872343591218546", "price": "0.34", "size": "50", "side": "BUY", "hash": "a854744168ddc97a89c5d3c14aed23b6d77c6860", "best_bid": "0.997", "best_ask": "0.998"}, {"asset_id": "62822673758473888087109044730409570258111717068753960435826531265266236629509", "price": "0.66", "size": "50", "side": "SELL", "hash": "fa32d96debadcfdd4868438588854878b24ed9ea", "best_bid": "0.002", "best_ask": "0.003"}], "timestamp": "1769384013545", "event_type": "price_change"}}
{"_local_timestamp": "2026-01-25T23:33:33.741932+00:00", "data": {"market": "0x3f1fcc84cfce0835e90422a970f37e9d0e4187a4c25f7fac9b4b8a1c13abaa0c", "price_changes": [{"asset_id": "88740501643316642368489847410696453938131074491242982225810722843753273684210", "price": "0.55", "size": "20", "side": "BUY", "hash": "0e6ee73c406de1871a17fd8c5bdbcf29f269e3a1", "best_bid": "0.997", "best_ask": "0.999"}, {"asset_id": "80297900658960573493828276022367220412132525071135705784317878924056840421254", "price": "0.45", "size": "20", "side": "SELL", "hash": "3aaef6a4e1cedeedd786da783b77c13b72cbd960", "best_bid": "0.001", "best_ask": "0.003"}], "timestamp": "1769384013608", "event_type": "price_change"}}
{"_local_timestamp": "2026-01-25T23:33:33.747740+00:00", "data": {"market": "0x3f1fcc84cfce0835e90422a970f37e9d0e4187a4c25f7fac9b4b8a1c13abaa0c", "price_changes": [{"asset_id": "88740501643316642368489847410696453938131074491242982225810722843753273684210", "price": "0.552", "size": "10", "side": "BUY", "hash": "b77fd98c94e66ffcceecd8316c90fd5479814a9a", "best_bid": "0.997", "best_ask": "0.999"}, {"asset_id": "80297900658960573493828276022367220412132525071135705784317878924056840421254", "price": "0.448", "size": "10", "side": "SELL", "hash": "284c4e0c552ddf70f8886750c506707b2edd40ac", "best_bid": "0.001", "best_ask": "0.003"}], "timestamp": "1769384013618", "event_type": "price_change"}}
{"_local_timestamp": "2026-01-25T23:33:33.748435+00:00", "data": {"market": "0x3f1fcc84cfce0835e90422a970f37e9d0e4187a4c25f7fac9b4b8a1c13abaa0c", "price_changes": [{"asset_id": "88740501643316642368489847410696453938131074491242982225810722843753273684210", "price": "0.552", "size": "69", "side": "BUY", "hash": "6349b9dd17d12b0364bd4c7378d98a51bcb8573a", "best_bid": "0.997", "best_ask": "0.999"}, {"asset_id": "80297900658960573493828276022367220412132525071135705784317878924056840421254", "price": "0.448", "size": "69", "side": "SELL", "hash": "f70266c6f212b4b67c591fcf4b0fe8d31cd5f081", "best_bid": "0.001", "best_ask": "0.003"}], "timestamp": "1769384013619", "event_type": "price_change"}}
{"_local_timestamp": "2026-01-25T23:33:33.783147+00:00", "data": {"market": "0x5999cfd552cbcf89bbd54c0e48b08c74182caefb18a80f1782018dcef2520d2d", "price_changes": [{"asset_id": "15174546601205928046556699082541161461166100492124394241054975981067833950165", "price": "0.75", "size": "0", "side": "BUY", "hash": "fa7a5a87ed6916f08c93047624deb60747f205cb", "best_bid": "0.998", "best_ask": "0.999"}, {"asset_id": "5430476248758985969939507303101680818848966275102949447275298704026336588828", "price": "0.25", "size": "0", "side": "SELL", "hash": "eb4bd0ac50707ad48222faf15643cc157ea3787d", "best_bid": "0.001", "best_ask": "0.002"}], "timestamp": "1769384013704", "event_type": "price_change"}}
{"_local_timestamp": "2026-01-25T23:33:33.808197+00:00", "data": {"market": "0x3f1fcc84cfce0835e90422a970f37e9d0e4187a4c25f7fac9b4b8a1c13abaa0c", "price_changes": [{"asset_id": "88740501643316642368489847410696453938131074491242982225810722843753273684210", "price": "0.552", "size": "99", "side": "BUY", "hash": "4142bf716eeb188254d79f0382650f4b34699b6b", "best_bid": "0.997", "best_ask": "0.999"}, {"asset_id": "80297900658960573493828276022367220412132525071135705784317878924056840421254", "price": "0.448", "size": "99", "side": "SELL", "hash": "ca07d497dd1469472846ac67aba4bdcb0a7d484b", "best_bid": "0.001", "best_ask": "0.003"}], "timestamp": "1769384013737", "event_type": "price_change"}}
{"_local_timestamp": "2026-01-25T23:33:33.897272+00:00", "data": {"market": "0xdfdcd530887c39781b31f164d7a5b74ba4cf3f511b05d556fde85283e67168f9", "price_changes": [{"asset_id": "1636496992763537371831953986108582665416540026084425365422723872343591218546", "price": "0.507", "size": "30", "side": "BUY", "hash": "4010e80d07f6bb7bd9dd3e8a2c77d2509b6e63b4", "best_bid": "0.997", "best_ask": "0.998"}, {"asset_id": "62822673758473888087109044730409570258111717068753960435826531265266236629509", "price": "0.493", "size": "30", "side": "SELL", "hash": "d9d1c56b215059dfc697e6d055c2c170bdc2e6ad", "best_bid": "0.002", "best_ask": "0.003"}], "timestamp": "1769384013807", "event_type": "price_change"}}
{"_local_timestamp": "2026-01-25T23:33:33.919190+00:00", "data": {"market": "0xdfdcd530887c39781b31f164d7a5b74ba4cf3f511b05d556fde85283e67168f9", "price_changes": [{"asset_id": "1636496992763537371831953986108582665416540026084425365422723872343591218546", "price": "0.507", "size": "10", "side": "BUY", "hash": "f8a5061491c6314b64dc36f64d7c687a5ec3380e", "best_bid": "0.997", "best_ask": "0.998"}, {"asset_id": "62822673758473888087109044730409570258111717068753960435826531265266236629509", "price": "0.493", "size": "10", "side": "SELL", "hash": "266a27bc56120619034b746d0736137f26d61cab", "best_bid": "0.002", "best_ask": "0.003"}], "timestamp": "1769384013838", "event_type": "price_change"}}
{"_local_timestamp": "2026-01-25T23:33:33.971471+00:00", "data": {"market": "0xdfdcd530887c39781b31f164d7a5b74ba4cf3f511b05d556fde85283e67168f9", "price_changes": [{"asset_id": "1636496992763537371831953986108582665416540026084425365422723872343591218546", "price": "0.511", "size": "30", "side": "BUY", "hash": "4c72c1c9e12630300649b5c2341179a15fa49c22", "best_bid": "0.997", "best_ask": "0.998"}, {"asset_id": "62822673758473888087109044730409570258111717068753960435826531265266236629509", "price": "0.489", "size": "30", "side": "SELL", "hash": "7cac1e6a45ef4ead53189956c5e9702fa3b8dae5", "best_bid": "0.002", "best_ask": "0.003"}], "timestamp": "1769384013897", "event_type": "price_change"}}
{"_local_timestamp": "2026-01-25T23:33:34.013661+00:00", "data": {"market": "0xbf593af69b62768d353e7c7226255c51ed19ca32c84a54c0d49a85553b42a46d", "price_changes": [{"asset_id": "24341167601280829695615199444200891915914435646386891986504787893119831754606", "price": "0.789", "size": "0", "side": "BUY", "hash": "72faaf1aad2ffb537a35541707e83b7395542d1f", "best_bid": "0.996", "best_ask": "0.999"}, {"asset_id": "2688038676615161490720640654323264340577430230677806835743854904343477854167", "price": "0.211", "size": "0", "side": "SELL", "hash": "e5027d60cb20f022a40aaf3f3739a9725088c7c4", "best_bid": "0.001", "best_ask": "0.004"}], "timestamp": "1769384013938", "event_type": "price_change"}}
{"_local_timestamp": "2026-01-25T23:33:34.105108+00:00", "data": {"market": "0xdfdcd530887c39781b31f164d7a5b74ba4cf3f511b05d556fde85283e67168f9", "price_changes": [{"asset_id": "1636496992763537371831953986108582665416540026084425365422723872343591218546", "price": "0.511", "size": "50", "side": "BUY", "hash": "dc3760ad05a85ceb07c8b2d0312752ea9852c50f", "best_bid": "0.997", "best_ask": "0.998"}, {"asset_id": "62822673758473888087109044730409570258111717068753960435826531265266236629509", "price": "0.489", "size": "50", "side": "SELL", "hash": "2b2a1dd68f8642b90100eae051cee48a096f99ca", "best_bid": "0.002", "best_ask": "0.003"}], "timestamp": "1769384014014", "event_type": "price_change"}}
{"_local_timestamp": "2026-01-25T23:33:34.127710+00:00", "data": {"market": "0xbf593af69b62768d353e7c7226255c51ed19ca32c84a54c0d49a85553b42a46d", "price_changes": [{"asset_id": "24341167601280829695615199444200891915914435646386891986504787893119831754606", "price": "0.792", "size": "30", "side": "BUY", "hash": "5922ddd439f8c35f49ade477bbbede0308d6b060", "best_bid": "0.996", "best_ask": "0.999"}, {"asset_id": "2688038676615161490720640654323264340577430230677806835743854904343477854167", "price": "0.208", "size": "30", "side": "SELL", "hash": "95adeaec5a5964f6eed06d1aeedea30b377079e2", "best_bid": "0.001", "best_ask": "0.004"}], "timestamp": "1769384014051", "event_type": "price_change"}}
{"_local_timestamp": "2026-01-25T23:33:34.166376+00:00", "data": {"market": "0xbf593af69b62768d353e7c7226255c51ed19ca32c84a54c0d49a85553b42a46d", "price_changes": [{"asset_id": "24341167601280829695615199444200891915914435646386891986504787893119831754606", "price": "0.448", "size": "10", "side": "BUY", "hash": "80caf0494df9285ba047f969dfed7f61af5e79f8", "best_bid": "0.996", "best_ask": "0.999"}, {"asset_id": "2688038676615161490720640654323264340577430230677806835743854904343477854167", "price": "0.552", "size": "10", "side": "SELL", "hash": "80563f1645e1e9a79cb41f6101a73b60cfc22f57", "best_bid": "0.001", "best_ask": "0.004"}], "timestamp": "1769384014093", "event_type": "price_change"}}
{"_local_timestamp": "2026-01-25T23:33:34.166812+00:00", "data": {"market": "0x3f1fcc84cfce0835e90422a970f37e9d0e4187a4c25f7fac9b4b8a1c13abaa0c", "price_changes": [{"asset_id": "88740501643316642368489847410696453938131074491242982225810722843753273684210", "price": "0.552", "size": "40", "side": "BUY", "hash": "f8271790793bacbfec02c1972330bbd26a8d1a2e", "best_bid": "0.997", "best_ask": "0.999"}, {"asset_id": "80297900658960573493828276022367220412132525071135705784317878924056840421254", "price": "0.448", "size": "40", "side": "SELL", "hash": "24262a69f471fb88b279b20a7a94226fcfb0a93b", "best_bid": "0.001", "best_ask": "0.003"}], "timestamp": "1769384014093", "event_type": "price_change"}}
{"_local_timestamp": "2026-01-25T23:33:35.074951+00:00", "data": {"market": "0x3f1fcc84cfce0835e90422a970f37e9d0e4187a4c25f7fac9b4b8a1c13abaa0c", "price_changes": [{"asset_id": "88740501643316642368489847410696453938131074491242982225810722843753273684210", "price": "0.551", "size": "0", "side": "BUY", "hash": "51ec3799bf196ece874b635123bc3f42b575af08", "best_bid": "0.997", "best_ask": "0.999"}, {"asset_id": "80297900658960573493828276022367220412132525071135705784317878924056840421254", "price": "0.449", "size": "0", "side": "SELL", "hash": "90b34cf540a688ad87ca6c2ce342a5ca93c81163", "best_bid": "0.001", "best_ask": "0.003"}], "timestamp": "1769384014992", "event_type": "price_change"}}
{"_local_timestamp": "2026-01-25T23:33:35.075349+00:00", "data": {"market": "0xdfdcd530887c39781b31f164d7a5b74ba4cf3f511b05d556fde85283e67168f9", "price_changes": [{"asset_id": "1636496992763537371831953986108582665416540026084425365422723872343591218546", "price": "0.51", "size": "0", "side": "BUY", "hash": "81630128ffda6caa865901079f6f943d1fb778f5", "best_bid": "0.997", "best_ask": "0.998"}, {"asset_id": "62822673758473888087109044730409570258111717068753960435826531265266236629509", "price": "0.49", "size": "0", "side": "SELL", "hash": "fa815beb028bbb6e1233b8310bdfa6f7755a3bfb", "best_bid": "0.002", "best_ask": "0.003"}], "timestamp": "1769384014992", "event_type": "price_change"}}
{"_local_timestamp": "2026-01-25T23:33:35.101564+00:00", "data": {"market": "0xdfdcd530887c39781b31f164d7a5b74ba4cf3f511b05d556fde85283e67168f9", "price_changes": [{"asset_id": "1636496992763537371831953986108582665416540026084425365422723872343591218546", "price": "0.512", "size": "20", "side": "BUY", "hash": "a12b186efa6aa36238a5876b015da88d26efe83c", "best_bid": "0.997", "best_ask": "0.998"}, {"asset_id": "62822673758473888087109044730409570258111717068753960435826531265266236629509", "price": "0.488", "size": "20", "side": "SELL", "hash": "27e0811bbb75687483135312bf950f5d36c0186b", "best_bid": "0.002", "best_ask": "0.003"}], "timestamp": "1769384015023", "event_type": "price_change"}}
{"_local_timestamp": "2026-01-25T23:33:35.110516+00:00", "data": {"market": "0x3f1fcc84cfce0835e90422a970f37e9d0e4187a4c25f7fac9b4b8a1c13abaa0c", "price_changes": [{"asset_id": "88740501643316642368489847410696453938131074491242982225810722843753273684210", "price": "0.553", "size": "20", "side": "BUY", "hash": "ff5cef28d4bd0785deb5167d94688925ccc53907", "best_bid": "0.997", "best_ask": "0.999"}, {"asset_id": "80297900658960573493828276022367220412132525071135705784317878924056840421254", "price": "0.447", "size": "20", "side": "SELL", "hash": "06c721ad58de922a38d2da8477267ce88219c0e2", "best_bid": "0.001", "best_ask": "0.003"}], "timestamp": "1769384015023", "event_type": "price_change"}}
{"_local_timestamp": "2026-01-25T23:33:35.113499+00:00", "data": {"market": "0x3f1fcc84cfce0835e90422a970f37e9d0e4187a4c25f7fac9b4b8a1c13abaa0c", "price_changes": [{"asset_id": "88740501643316642368489847410696453938131074491242982225810722843753273684210", "price": "0.55", "size": "0", "side": "BUY", "hash": "5e2ea9fbe06fd8a3e3210d12a93c6a4c698bb8c2", "best_bid": "0.997", "best_ask": "0.999"}, {"asset_id": "80297900658960573493828276022367220412132525071135705784317878924056840421254", "price": "0.45", "size": "0", "side": "SELL", "hash": "b5b29f3de6f109b86f36b3531ef3a44c461dd96d", "best_bid": "0.001", "best_ask": "0.003"}], "timestamp": "1769384015024", "event_type": "price_change"}}
{"_local_timestamp": "2026-01-25T23:33:35.140562+00:00", "data": {"market": "0x3f1fcc84cfce0835e90422a970f37e9d0e4187a4c25f7fac9b4b8a1c13abaa0c", "price_changes": [{"asset_id": "88740501643316642368489847410696453938131074491242982225810722843753273684210", "price": "0.554", "size": "20", "side": "BUY", "hash": "aef6c327001f749dcc5734b772fff9d8d302296c", "best_bid": "0.997", "best_ask": "0.999"}, {"asset_id": "80297900658960573493828276022367220412132525071135705784317878924056840421254", "price": "0.446", "size": "20", "side": "SELL", "hash": "80e2adf27f07cfb18d119870d6f1439bd5d3a374", "best_bid": "0.001", "best_ask": "0.003"}], "timestamp": "1769384015065", "event_type": "price_change"}}
{"_local_timestamp": "2026-01-25T23:33:35.966892+00:00", "data": {"market": "0x3f1fcc84cfce0835e90422a970f37e9d0e4187a4c25f7fac9b4b8a1c13abaa0c", "price_changes": [{"asset_id": "88740501643316642368489847410696453938131074491242982225810722843753273684210", "price": "0.553", "size": "0", "side": "BUY", "hash": "4dbfa7745881286757410bd45ddf1d33aae9fc50", "best_bid": "0.997", "best_ask": "0.999"}, {"asset_id": "80297900658960573493828276022367220412132525071135705784317878924056840421254", "price": "0.447", "size": "0", "side": "SELL", "hash": "a8e202d2a0a838f653b4a3d36e26c096b76c669c", "best_bid": "0.001", "best_ask": "0.003"}], "timestamp": "1769384015889", "event_type": "price_change"}}
{"_local_timestamp": "2026-01-25T23:33:35.982249+00:00", "data": {"market": "0x3f1fcc84cfce0835e90422a970f37e9d0e4187a4c25f7fac9b4b8a1c13abaa0c", "price_changes": [{"asset_id": "88740501643316642368489847410696453938131074491242982225810722843753273684210", "price": "0.555", "size": "20", "side": "BUY", "hash": "de76d92586325675943633f4124110a5d69153f5", "best_bid": "0.997", "best_ask": "0.999"}, {"asset_id": "80297900658960573493828276022367220412132525071135705784317878924056840421254", "price": "0.445", "size": "20", "side": "SELL", "hash": "cdbf998fc6ee803f673113ee8bbe989a7d1c1431", "best_bid": "0.001", "best_ask": "0.003"}], "timestamp": "1769384015913", "event_type": "price_change"}}
{"_local_timestamp": "2026-01-25T23:33:53.335110+00:00", "data": {"market": "0xc2ac7ebd46fa81ad41a5072a14a2a77c362d18744596848500541c4406051068", "price_changes": [{"asset_id": "82937290481922399100659521402638226726618911184164616630445131262753902545289", "price": "0.79", "size": "66.66", "side": "BUY", "hash": "0f4cd14e6d8cb3815247c22ca384bf1e0b5a9cb1", "best_bid": "0.79", "best_ask": "0.89"}, {"asset_id": "36008003405201249169700080930810811641068357582790575985437372346931394635255", "price": "0.21", "size": "66.66", "side": "SELL", "hash": "d6bf26c510491055e2be6b4818afef49937f7d8f", "best_bid": "0.11", "best_ask": "0.21"}], "timestamp": "1769384033263", "event_type": "price_change"}}
{"_local_timestamp": "2026-01-25T23:34:10.730932+00:00", "data": {"market": "0x5999cfd552cbcf89bbd54c0e48b08c74182caefb18a80f1782018dcef2520d2d", "price_changes": [{"asset_id": "15174546601205928046556699082541161461166100492124394241054975981067833950165", "price": "0.528", "size": "0", "side": "BUY", "hash": "d50bfc99118b55e370581aa7a6c2990f4030883d", "best_bid": "0.998", "best_ask": "0.999"}, {"asset_id": "5430476248758985969939507303101680818848966275102949447275298704026336588828", "price": "0.472", "size": "0", "side": "SELL", "hash": "81eeabb6279d884eda4a4fb7673c07fc093e08e7", "best_bid": "0.001", "best_ask": "0.002"}], "timestamp": "1769384050655", "event_type": "price_change"}}
{"_local_timestamp": "2026-01-25T23:34:10.897033+00:00", "data": {"market": "0x5999cfd552cbcf89bbd54c0e48b08c74182caefb18a80f1782018dcef2520d2d", "price_changes": [{"asset_id": "15174546601205928046556699082541161461166100492124394241054975981067833950165", "price": "0.528", "size": "5", "side": "BUY", "hash": "c632a8c0bced35577b8f498ab9595f2bdd069b5f", "best_bid": "0.998", "best_ask": "0.999"}, {"asset_id": "5430476248758985969939507303101680818848966275102949447275298704026336588828", "price": "0.472", "size": "5", "side": "SELL", "hash": "bbd2474d6eb700f7a9404dad5b0b921175b65599", "best_bid": "0.001", "best_ask": "0.002"}], "timestamp": "1769384050827", "event_type": "price_change"}}
{"_local_timestamp": "2026-01-25T23:34:27.888495+00:00", "data": {"market": "0x0fc1398bb3cff37d77101392989d6ff065d28d7c0dc50b282bd1b5098b9d78b8", "price_changes": [{"asset_id": "89336264239989122383122704165255872699177887882264330841492281051298522223986", "price": "0.414", "size": "241", "side": "BUY", "hash": "0d1932d67365e8f545aea39686984f0457598ce5", "best_bid": "0.892", "best_ask": "0.934"}, {"asset_id": "76309699246141587406891686852898742630368640356883728029522206362139036530694", "price": "0.586", "size": "241", "side": "SELL", "hash": "d789a279cc50f7a841677c207661b641ea2d56ad", "best_bid": "0.066", "best_ask": "0.108"}], "timestamp": "1769384067606", "event_type": "price_change"}}
{"_local_timestamp": "2026-01-25T23:34:28.367792+00:00", "data": {"market": "0x0fc1398bb3cff37d77101392989d6ff065d28d7c0dc50b282bd1b5098b9d78b8", "price_changes": [{"asset_id": "89336264239989122383122704165255872699177887882264330841492281051298522223986", "price": "0.415", "size": "70", "side": "BUY", "hash": "ba8b50afc3aa817ce789a7ccdaac285ec337cf87", "best_bid": "0.892", "best_ask": "0.934"}, {"asset_id": "76309699246141587406891686852898742630368640356883728029522206362139036530694", "price": "0.585", "size": "70", "side": "SELL", "hash": "4d67dd4af524820027af35510e584aa4fb92affb", "best_bid": "0.066", "best_ask": "0.108"}], "timestamp": "1769384068106", "event_type": "price_change"}}
{"_local_timestamp": "2026-01-25T23:34:40.282700+00:00", "data": {"market": "0xc2ac7ebd46fa81ad41a5072a14a2a77c362d18744596848500541c4406051068", "price_changes": [{"asset_id": "36008003405201249169700080930810811641068357582790575985437372346931394635255", "price": "0.02", "size": "300", "side": "BUY", "hash": "1d59a8de8368cd99dcf4c6f7175f5ded5777bb94", "best_bid": "0.11", "best_ask": "0.21"}, {"asset_id": "82937290481922399100659521402638226726618911184164616630445131262753902545289", "price": "0.98", "size": "300", "side": "SELL", "hash": "3d5a4473ae559a7c985d31ea08284d4c28976b67", "best_bid": "0.79", "best_ask": "0.89"}], "timestamp": "1769384080144", "event_type": "price_change"}}
{"_local_timestamp": "2026-01-25T23:34:40.583190+00:00", "data": {"market": "0xc2ac7ebd46fa81ad41a5072a14a2a77c362d18744596848500541c4406051068", "price_changes": [{"asset_id": "36008003405201249169700080930810811641068357582790575985437372346931394635255", "price": "0.02", "size": "311.11", "side": "BUY", "hash": "fcabe923f72a638e71fa68fc88317646a5809575", "best_bid": "0.11", "best_ask": "0.21"}, {"asset_id": "82937290481922399100659521402638226726618911184164616630445131262753902545289", "price": "0.98", "size": "311.11", "side": "SELL", "hash": "8d57013567b9e952c435c67cd2c232aa3e13582c", "best_bid": "0.79", "best_ask": "0.89"}], "timestamp": "1769384080376", "event_type": "price_change"}}
{"_local_timestamp": "2026-01-25T23:35:02.960593+00:00", "data": {"market": "0xc2ac7ebd46fa81ad41a5072a14a2a77c362d18744596848500541c4406051068", "price_changes": [{"asset_id": "82937290481922399100659521402638226726618911184164616630445131262753902545289", "price": "0.77", "size": "0", "side": "BUY", "hash": "056718bf8afb90379c4deaef8adf2e9299821376", "best_bid": "0.79", "best_ask": "0.89"}, {"asset_id": "36008003405201249169700080930810811641068357582790575985437372346931394635255", "price": "0.23", "size": "0", "side": "SELL", "hash": "61e1a30c8b4f4e9a33bd3b7ee5b199ee8d3cb4a8", "best_bid": "0.11", "best_ask": "0.21"}], "timestamp": "1769384102809", "event_type": "price_change"}}
{"_local_timestamp": "2026-01-25T23:35:03.228417+00:00", "data": {"market": "0xdfdcd530887c39781b31f164d7a5b74ba4cf3f511b05d556fde85283e67168f9", "price_changes": [{"asset_id": "1636496992763537371831953986108582665416540026084425365422723872343591218546", "price": "0.507", "size": "0", "side": "BUY", "hash": "2a2d088766f3f2d842a740e859cdf9dc30d9f488", "best_bid": "0.997", "best_ask": "0.998"}, {"asset_id": "62822673758473888087109044730409570258111717068753960435826531265266236629509", "price": "0.493", "size": "0", "side": "SELL", "hash": "6aeac628c8b0cd1433e4e7858cb2c430febb1389", "best_bid": "0.002", "best_ask": "0.003"}], "timestamp": "1769384103073", "event_type": "price_change"}}
{"_local_timestamp": "2026-01-25T23:35:03.408477+00:00", "data": {"market": "0xdfdcd530887c39781b31f164d7a5b74ba4cf3f511b05d556fde85283e67168f9", "price_changes": [{"asset_id": "1636496992763537371831953986108582665416540026084425365422723872343591218546", "price": "0.513", "size": "67", "side": "BUY", "hash": "63b18bccda38134525669f38336cc7761ad40289", "best_bid": "0.997", "best_ask": "0.998"}, {"asset_id": "62822673758473888087109044730409570258111717068753960435826531265266236629509", "price": "0.487", "size": "67", "side": "SELL", "hash": "1804721645f97d2298b93b2070dffd33f26d7a70", "best_bid": "0.002", "best_ask": "0.003"}], "timestamp": "1769384103266", "event_type": "price_change"}}
{"_local_timestamp": "2026-01-25T23:35:03.408843+00:00", "data": {"market": "0xdfdcd530887c39781b31f164d7a5b74ba4cf3f511b05d556fde85283e67168f9", "price_changes": [{"asset_id": "1636496992763537371831953986108582665416540026084425365422723872343591218546", "price": "0.513", "size": "77", "side": "BUY", "hash": "672999ad53360bcd931248ec2a1cee4f48d6745a", "best_bid": "0.997", "best_ask": "0.998"}, {"asset_id": "62822673758473888087109044730409570258111717068753960435826531265266236629509", "price": "0.487", "size": "77", "side": "SELL", "hash": "d13d028665b4a8fb51cb28d0b985322197e4d93b", "best_bid": "0.002", "best_ask": "0.003"}], "timestamp": "1769384103267", "event_type": "price_change"}}
{"_local_timestamp": "2026-01-25T23:35:03.749066+00:00", "data": {"market": "0xc2ac7ebd46fa81ad41a5072a14a2a77c362d18744596848500541c4406051068", "price_changes": [{"asset_id": "82937290481922399100659521402638226726618911184164616630445131262753902545289", "price": "0.7", "size": "82.37", "side": "BUY", "hash": "c411ab322eaf0050a7edbe228e99a424ad78ab2f", "best_bid": "0.79", "best_ask": "0.89"}, {"asset_id": "36008003405201249169700080930810811641068357582790575985437372346931394635255", "price": "0.3", "size": "82.37", "side": "SELL", "hash": "26091476e1172a0e51e185aa59c2c48fd8af2104", "best_bid": "0.11", "best_ask": "0.21"}], "timestamp": "1769384103612", "event_type": "price_change"}}
{"_local_timestamp": "2026-01-25T23:35:03.945387+00:00", "data": {"market": "0xc2ac7ebd46fa81ad41a5072a14a2a77c362d18744596848500541c4406051068", "price_changes": [{"asset_id": "82937290481922399100659521402638226726618911184164616630445131262753902545289", "price": "0.66", "size": "30", "side": "BUY", "hash": "77d4c2e76c10067e6f709c9623f249ec1cdf8996", "best_bid": "0.79", "best_ask": "0.89"}, {"asset_id": "36008003405201249169700080930810811641068357582790575985437372346931394635255", "price": "0.34", "size": "30", "side": "SELL", "hash": "6df17961a0a7ff5bacff54a0ab529a1a140501ba", "best_bid": "0.11", "best_ask": "0.21"}], "timestamp": "1769384103812", "event_type": "price_change"}}
{"_local_timestamp": "2026-01-25T23:35:04.003005+00:00", "data": {"market": "0xc2ac7ebd46fa81ad41a5072a14a2a77c362d18744596848500541c4406051068", "price_changes": [{"asset_id": "82937290481922399100659521402638226726618911184164616630445131262753902545289", "price": "0.63", "size": "37.5", "side": "BUY", "hash": "4bfe89942fc6dde30b9a3f9f235f424978e9cf66", "best_bid": "0.79", "best_ask": "0.89"}, {"asset_id": "36008003405201249169700080930810811641068357582790575985437372346931394635255", "price": "0.37", "size": "37.5", "side": "SELL", "hash": "b67fff4b576a89131905ee56904d922b7d392dcf", "best_bid": "0.11", "best_ask": "0.21"}], "timestamp": "1769384103860", "event_type": "price_change"}}
{"_local_timestamp": "2026-01-25T23:35:04.077648+00:00", "data": {"market": "0xc2ac7ebd46fa81ad41a5072a14a2a77c362d18744596848500541c4406051068", "price_changes": [{"asset_id": "82937290481922399100659521402638226726618911184164616630445131262753902545289", "price": "0.66", "size": "20", "side": "BUY", "hash": "6ce4c61b632beaa840618f72fdd7ed9cdeb2d905", "best_bid": "0.79", "best_ask": "0.89"}, {"asset_id": "36008003405201249169700080930810811641068357582790575985437372346931394635255", "price": "0.34", "size": "20", "side": "SELL", "hash": "dafbd87fca0a5cbf1ca99510b47b36eecf3453b1", "best_bid": "0.11", "best_ask": "0.21"}], "timestamp": "1769384103918", "event_type": "price_change"}}
{"_local_timestamp": "2026-01-25T23:35:04.170148+00:00", "data": {"market": "0xc2ac7ebd46fa81ad41a5072a14a2a77c362d18744596848500541c4406051068", "price_changes": [{"asset_id": "82937290481922399100659521402638226726618911184164616630445131262753902545289", "price": "0.37", "size": "10", "side": "BUY", "hash": "3e0504e0d256e675b3d2cdd4119c6ab1e90f7e5f", "best_bid": "0.79", "best_ask": "0.89"}, {"asset_id": "36008003405201249169700080930810811641068357582790575985437372346931394635255", "price": "0.63", "size": "10", "side": "SELL", "hash": "da19cf72ab02bcf3e9fffa3578604b33cb8e4a12", "best_bid": "0.11", "best_ask": "0.21"}], "timestamp": "1769384104009", "event_type": "price_change"}}
{"_local_timestamp": "2026-01-25T23:35:04.502923+00:00", "data": {"market": "0xdfdcd530887c39781b31f164d7a5b74ba4cf3f511b05d556fde85283e67168f9", "price_changes": [{"asset_id": "1636496992763537371831953986108582665416540026084425365422723872343591218546", "price": "0.512", "size": "0", "side": "BUY", "hash": "2a98ea96c2252d484e6d396317e08a888227e30c", "best_bid": "0.997", "best_ask": "0.998"}, {"asset_id": "62822673758473888087109044730409570258111717068753960435826531265266236629509", "price": "0.488", "size": "0", "side": "SELL", "hash": "9c8749eb86a782b82da11de41275a696e94178fa", "best_bid": "0.002", "best_ask": "0.003"}], "timestamp": "1769384104339", "event_type": "price_change"}}
{"_local_timestamp": "2026-01-25T23:35:04.528526+00:00", "data": {"market": "0xdfdcd530887c39781b31f164d7a5b74ba4cf3f511b05d556fde85283e67168f9", "price_changes": [{"asset_id": "1636496992763537371831953986108582665416540026084425365422723872343591218546", "price": "0.514", "size": "20", "side": "BUY", "hash": "79f0911d5d5912ce294e315cd4c5155e4a3eaad7", "best_bid": "0.997", "best_ask": "0.998"}, {"asset_id": "62822673758473888087109044730409570258111717068753960435826531265266236629509", "price": "0.486", "size": "20", "side": "SELL", "hash": "9c73676fe5972e6dfda15e8e67d450a13e0d1f76", "best_bid": "0.002", "best_ask": "0.003"}], "timestamp": "1769384104368", "event_type": "price_change"}}
{"_local_timestamp": "2026-01-25T23:35:09.166217+00:00", "data": {"market": "0xc2ac7ebd46fa81ad41a5072a14a2a77c362d18744596848500541c4406051068", "price_changes": [{"asset_id": "82937290481922399100659521402638226726618911184164616630445131262753902545289", "price": "0.79", "size": "114.76", "side": "BUY", "hash": "3eadb617b1a544f36620f691c76102ffbe8befe3", "best_bid": "0.79", "best_ask": "0.89"}, {"asset_id": "36008003405201249169700080930810811641068357582790575985437372346931394635255", "price": "0.21", "size": "114.76", "side": "SELL", "hash": "994a477ba0f1d9f07fa955716027d3d28fd7177c", "best_bid": "0.11", "best_ask": "0.21"}], "timestamp": "1769384108970", "event_type": "price_change"}}
{"_local_timestamp": "2026-01-25T23:35:54.817169+00:00", "data": {"market": "0x5999cfd552cbcf89bbd54c0e48b08c74182caefb18a80f1782018dcef2520d2d", "price_changes": [{"asset_id": "15174546601205928046556699082541161461166100492124394241054975981067833950165", "price": "0.528", "size": "0", "side": "BUY", "hash": "2d6b85db14f910e2aa4a490aa0a70c1ffb99f4cb", "best_bid": "0.998", "best_ask": "0.999"}, {"asset_id": "5430476248758985969939507303101680818848966275102949447275298704026336588828", "price": "0.472", "size": "0", "side": "SELL", "hash": "4f10c26ca988aebc2ef320098e2686bc5ad226b8", "best_bid": "0.001", "best_ask": "0.002"}], "timestamp": "1769384154716", "event_type": "price_change"}}
{"_local_timestamp": "2026-01-25T23:35:55.008424+00:00", "data": {"market": "0xdfdcd530887c39781b31f164d7a5b74ba4cf3f511b05d556fde85283e67168f9", "price_changes": [{"asset_id": "1636496992763537371831953986108582665416540026084425365422723872343591218546", "price": "0.509", "size": "15", "side": "BUY", "hash": "21eec55e2e6a04026a373e7571879643002430e8", "best_bid": "0.997", "best_ask": "0.998"}, {"asset_id": "62822673758473888087109044730409570258111717068753960435826531265266236629509", "price": "0.491", "size": "15", "side": "SELL", "hash": "586ea2fb090261a440db8006c128235b81b839ad", "best_bid": "0.002", "best_ask": "0.003"}], "timestamp": "1769384154910", "event_type": "price_change"}}
{"_local_timestamp": "2026-01-25T23:35:56.547099+00:00", "data": {"market": "0x5999cfd552cbcf89bbd54c0e48b08c74182caefb18a80f1782018dcef2520d2d", "price_changes": [{"asset_id": "15174546601205928046556699082541161461166100492124394241054975981067833950165", "price": "0.528", "size": "5", "side": "BUY", "hash": "812c6dc527d7317737e18c565aa8c1ccadcccd58", "best_bid": "0.998", "best_ask": "0.999"}, {"asset_id": "5430476248758985969939507303101680818848966275102949447275298704026336588828", "price": "0.472", "size": "5", "side": "SELL", "hash": "9d9815eb9d8906c48c6f895a88bf552962d36f4d", "best_bid": "0.001", "best_ask": "0.002"}], "timestamp": "1769384156400", "event_type": "price_change"}}
{"_local_timestamp": "2026-01-25T23:35:56.681140+00:00", "data": {"market": "0xdfdcd530887c39781b31f164d7a5b74ba4cf3f511b05d556fde85283e67168f9", "price_changes": [{"asset_id": "1636496992763537371831953986108582665416540026084425365422723872343591218546", "price": "0.509", "size": "0", "side": "BUY", "hash": "6b2dd4e58da143d03a1b750f04c29b68e78e5686", "best_bid": "0.997", "best_ask": "0.998"}, {"asset_id": "62822673758473888087109044730409570258111717068753960435826531265266236629509", "price": "0.491", "size": "0", "side": "SELL", "hash": "512b98cc10b463d18b43330c0e3da86f00ee2f07", "best_bid": "0.002", "best_ask": "0.003"}], "timestamp": "1769384156612", "event_type": "price_change"}}
{"_local_timestamp": "2026-01-25T23:36:52.360793+00:00", "data": {"market": "0xc2ac7ebd46fa81ad41a5072a14a2a77c362d18744596848500541c4406051068", "price_changes": [{"asset_id": "36008003405201249169700080930810811641068357582790575985437372346931394635255", "price": "0.02", "size": "300", "side": "BUY", "hash": "d2f6688c5ff7b55523f28d7e2f8cc20b0ba090d3", "best_bid": "0.11", "best_ask": "0.21"}, {"asset_id": "82937290481922399100659521402638226726618911184164616630445131262753902545289", "price": "0.98", "size": "300", "side": "SELL", "hash": "4482a8791987e8cc2547b869c5da708c846870a7", "best_bid": "0.79", "best_ask": "0.89"}], "timestamp": "1769384212286", "event_type": "price_change"}}
{"_local_timestamp": "2026-01-25T23:36:54.741851+00:00", "data": {"market": "0xc2ac7ebd46fa81ad41a5072a14a2a77c362d18744596848500541c4406051068", "price_changes": [{"asset_id": "36008003405201249169700080930810811641068357582790575985437372346931394635255", "price": "0.02", "size": "311.11", "side": "BUY", "hash": "62d03dee958393ee904cf772a278179f77e460f3", "best_bid": "0.11", "best_ask": "0.21"}, {"asset_id": "82937290481922399100659521402638226726618911184164616630445131262753902545289", "price": "0.98", "size": "311.11", "side": "SELL", "hash": "aa341d039f65ad612867781020509da1ab404383", "best_bid": "0.79", "best_ask": "0.89"}], "timestamp": "1769384214648", "event_type": "price_change"}}
{"_local_timestamp": "2026-01-25T23:36:55.123394+00:00", "data": {"market": "0x0fc1398bb3cff37d77101392989d6ff065d28d7c0dc50b282bd1b5098b9d78b8", "price_changes": [{"asset_id": "89336264239989122383122704165255872699177887882264330841492281051298522223986", "price": "0.415", "size": "10", "side": "BUY", "hash": "f8ba5d35efd4bd00856fa4cb8a241812c669ee49", "best_bid": "0.892", "best_ask": "0.934"}, {"asset_id": "76309699246141587406891686852898742630368640356883728029522206362139036530694", "price": "0.585", "size": "10", "side": "SELL", "hash": "1058dfd35396b15385dffe677c35e03f1861c5e5", "best_bid": "0.066", "best_ask": "0.108"}], "timestamp": "1769384215008", "event_type": "price_change"}}
{"_local_timestamp": "2026-01-25T23:36:55.950689+00:00", "data": {"market": "0x3f1fcc84cfce0835e90422a970f37e9d0e4187a4c25f7fac9b4b8a1c13abaa0c", "price_changes": [{"asset_id": "88740501643316642368489847410696453938131074491242982225810722843753273684210", "price": "0.457", "size": "1152", "side": "BUY", "hash": "506f67cf91d809a62f256ae5d6b534fe038e3a07", "best_bid": "0.997", "best_ask": "0.999"}, {"asset_id": "80297900658960573493828276022367220412132525071135705784317878924056840421254", "price": "0.543", "size": "1152", "side": "SELL", "hash": "e135676227ebb6046e7ca72f7b98af11efdc2c96", "best_bid": "0.001", "best_ask": "0.003"}], "timestamp": "1769384215648", "event_type": "price_change"}}
{"_local_timestamp": "2026-01-25T23:36:55.966589+00:00", "data": {"market": "0x0fc1398bb3cff37d77101392989d6ff065d28d7c0dc50b282bd1b5098b9d78b8", "price_changes": [{"asset_id": "89336264239989122383122704165255872699177887882264330841492281051298522223986", "price": "0.416", "size": "126.66", "side": "BUY", "hash": "4cb349cc0250696c0da7fba1ec9d42bf7c5ee511", "best_bid": "0.892", "best_ask": "0.934"}, {"asset_id": "76309699246141587406891686852898742630368640356883728029522206362139036530694", "price": "0.584", "size": "126.66", "side": "SELL", "hash": "1a2c55ced4a9d39c286d513e0def19adfb0d23cb", "best_bid": "0.066", "best_ask": "0.108"}], "timestamp": "1769384215649", "event_type": "price_change"}}
{"_local_timestamp": "2026-01-25T23:37:05.829614+00:00", "data": {"market": "0xc2ac7ebd46fa81ad41a5072a14a2a77c362d18744596848500541c4406051068", "price_changes": [{"asset_id": "82937290481922399100659521402638226726618911184164616630445131262753902545289", "price": "0.79", "size": "66.66", "side": "BUY", "hash": "a02707e4d2317155b6f36205f56ecb85a5af4d17", "best_bid": "0.79", "best_ask": "0.89"}, {"asset_id": "36008003405201249169700080930810811641068357582790575985437372346931394635255", "price": "0.21", "size": "66.66", "side": "SELL", "hash": "69fe56f40f6abccb8b8da2b647bc1a5c78983484", "best_bid": "0.11", "best_ask": "0.21"}], "timestamp": "1769384225733", "event_type": "price_change"}}
{"_local_timestamp": "2026-01-25T23:37:05.945897+00:00", "data": {"market": "0x755e71197eb78ca86e6c2e6f2dd7f3627e58a8e20e199afd6343a2f62e72fc7d", "price_changes": [{"asset_id": "28961994487539524115483388590435047266855663289365844982134174724453599686933", "price": "0.57", "size": "0", "side": "BUY", "hash": "009614d383e5436744e3ac76adaa6dc8e7f55a4c", "best_bid": "0.79", "best_ask": "0.82"}, {"asset_id": "15041248527212347147811488680125841745254730872155301672818398041068079601058", "price": "0.43", "size": "0", "side": "SELL", "hash": "d11691174766047d9e2311a2b8395e021ba3a3fa", "best_bid": "0.18", "best_ask": "0.21"}], "timestamp": "1769384225875", "event_type": "price_change"}}
{"_local_timestamp": "2026-01-25T23:37:06.012344+00:00", "data": {"market": "0x755e71197eb78ca86e6c2e6f2dd7f3627e58a8e20e199afd6343a2f62e72fc7d", "price_changes": [{"asset_id": "28961994487539524115483388590435047266855663289365844982134174724453599686933", "price": "0.6", "size": "30", "side": "BUY", "hash": "924a331a4aac58ed701132e0c4c5a35f476747cc", "best_bid": "0.79", "best_ask": "0.82"}, {"asset_id": "15041248527212347147811488680125841745254730872155301672818398041068079601058", "price": "0.4", "size": "30", "side": "SELL", "hash": "074af4c36984feb08be51a3c60f9ce0287b088c9", "best_bid": "0.18", "best_ask": "0.21"}], "timestamp": "1769384225943", "event_type": "price_change"}}
{"_local_timestamp": "2026-01-25T23:37:07.037753+00:00", "data": {"market": "0x5999cfd552cbcf89bbd54c0e48b08c74182caefb18a80f1782018dcef2520d2d", "price_changes": [{"asset_id": "15174546601205928046556699082541161461166100492124394241054975981067833950165", "price": "0.528", "size": "0", "side": "BUY", "hash": "5094fae601462a0101032644cf0be4e3919359d1", "best_bid": "0.998", "best_ask": "0.999"}, {"asset_id": "5430476248758985969939507303101680818848966275102949447275298704026336588828", "price": "0.472", "size": "0", "side": "SELL", "hash": "37846e830032db44ae213d597191d7bd44ce4de6", "best_bid": "0.001", "best_ask": "0.002"}], "timestamp": "1769384226961", "event_type": "price_change"}}
{"_local_timestamp": "2026-01-25T23:37:07.454448+00:00", "data": {"market": "0x5999cfd552cbcf89bbd54c0e48b08c74182caefb18a80f1782018dcef2520d2d", "price_changes": [{"asset_id": "15174546601205928046556699082541161461166100492124394241054975981067833950165", "price": "0.528", "size": "5", "side": "BUY", "hash": "9511fcaf4aa6f441165b0939125693eb69b60ab5", "best_bid": "0.998", "best_ask": "0.999"}, {"asset_id": "5430476248758985969939507303101680818848966275102949447275298704026336588828", "price": "0.472", "size": "5", "side": "SELL", "hash": "f7df0a063366563bfa325823a2aa511591802025", "best_bid": "0.001", "best_ask": "0.002"}], "timestamp": "1769384227383", "event_type": "price_change"}}
{"_local_timestamp": "2026-01-25T23:37:07.910834+00:00", "data": {"market": "0x5999cfd552cbcf89bbd54c0e48b08c74182caefb18a80f1782018dcef2520d2d", "price_changes": [{"asset_id": "15174546601205928046556699082541161461166100492124394241054975981067833950165", "price": "0.528", "size": "0", "side": "BUY", "hash": "84769a3edc1f089962f2c645225a4501753a3ec4", "best_bid": "0.998", "best_ask": "0.999"}, {"asset_id": "5430476248758985969939507303101680818848966275102949447275298704026336588828", "price": "0.472", "size": "0", "side": "SELL", "hash": "46c015137e2e11bb80a439297cea8b1fef050864", "best_bid": "0.001", "best_ask": "0.002"}], "timestamp": "1769384227828", "event_type": "price_change"}}
{"_local_timestamp": "2026-01-25T23:37:08.254431+00:00", "data": {"market": "0x5999cfd552cbcf89bbd54c0e48b08c74182caefb18a80f1782018dcef2520d2d", "price_changes": [{"asset_id": "15174546601205928046556699082541161461166100492124394241054975981067833950165", "price": "0.528", "size": "5", "side": "BUY", "hash": "98e4e1a89ba1171ea8eaedd0eec6e400edc3b4ea", "best_bid": "0.998", "best_ask": "0.999"}, {"asset_id": "5430476248758985969939507303101680818848966275102949447275298704026336588828", "price": "0.472", "size": "5", "side": "SELL", "hash": "c1631e5e64c16d337aee73135bc807202f35d661", "best_bid": "0.001", "best_ask": "0.002"}], "timestamp": "1769384228179", "event_type": "price_change"}}
{"_local_timestamp": "2026-01-25T23:37:09.607130+00:00", "data": {"market": "0x5999cfd552cbcf89bbd54c0e48b08c74182caefb18a80f1782018dcef2520d2d", "price_changes": [{"asset_id": "15174546601205928046556699082541161461166100492124394241054975981067833950165", "price": "0.528", "size": "0", "side": "BUY", "hash": "282630a889d3a5af9e10bef1797ca9192d689c87", "best_bid": "0.998", "best_ask": "0.999"}, {"asset_id": "5430476248758985969939507303101680818848966275102949447275298704026336588828", "price": "0.472", "size": "0", "side": "SELL", "hash": "a28bb66b9fc9ca597145bcd5eac571de20547729", "best_bid": "0.001", "best_ask": "0.002"}], "timestamp": "1769384229536", "event_type": "price_change"}}
{"_local_timestamp": "2026-01-25T23:37:09.832045+00:00", "data": {"market": "0x0fc1398bb3cff37d77101392989d6ff065d28d7c0dc50b282bd1b5098b9d78b8", "price_changes": [{"asset_id": "76309699246141587406891686852898742630368640356883728029522206362139036530694", "price": "0.109", "size": "0", "side": "SELL", "hash": "4ec08a0e120da1b2195965ed366e5bca27f0fdbe", "best_bid": "0.066", "best_ask": "0.108"}, {"asset_id": "89336264239989122383122704165255872699177887882264330841492281051298522223986", "price": "0.891", "size": "0", "side": "BUY", "hash": "13f958951e7630860ba47263d9f62e1b10e34215", "best_bid": "0.892", "best_ask": "0.934"}], "timestamp": "1769384229756", "event_type": "price_change"}}
{"_local_timestamp": "2026-01-25T23:37:09.967195+00:00", "data": {"market": "0x5999cfd552cbcf89bbd54c0e48b08c74182caefb18a80f1782018dcef2520d2d", "price_changes": [{"asset_id": "15174546601205928046556699082541161461166100492124394241054975981067833950165", "price": "0.528", "size": "5", "side": "BUY", "hash": "20a7f0535da254d827d78f124f0994da4c4121f7", "best_bid": "0.998", "best_ask": "0.999"}, {"asset_id": "5430476248758985969939507303101680818848966275102949447275298704026336588828", "price": "0.472", "size": "5", "side": "SELL", "hash": "d2f8d3d0602157fe12a97e95b23eedb895ff7be3", "best_bid": "0.001", "best_ask": "0.002"}], "timestamp": "1769384229896", "event_type": "price_change"}}
{"_local_timestamp": "2026-01-25T23:37:10.345723+00:00", "data": {"market": "0x5999cfd552cbcf89bbd54c0e48b08c74182caefb18a80f1782018dcef2520d2d", "price_changes": [{"asset_id": "15174546601205928046556699082541161461166100492124394241054975981067833950165", "price": "0.528", "size": "0", "side": "BUY", "hash": "ad9b619b4c59321efb4ec52768c31334083fae59", "best_bid": "0.998", "best_ask": "0.999"}, {"asset_id": "5430476248758985969939507303101680818848966275102949447275298704026336588828", "price": "0.472", "size": "0", "side": "SELL", "hash": "71c1b0faa5a1081a87edc68e44b23096f0abef9a", "best_bid": "0.001", "best_ask": "0.002"}], "timestamp": "1769384230261", "event_type": "price_change"}}
{"_local_timestamp": "2026-01-25T23:37:10.792609+00:00", "data": {"market": "0x5999cfd552cbcf89bbd54c0e48b08c74182caefb18a80f1782018dcef2520d2d", "price_changes": [{"asset_id": "15174546601205928046556699082541161461166100492124394241054975981067833950165", "price": "0.528", "size": "5", "side": "BUY", "hash": "b3d74d9e705c2f51cd91aa58f1dc8d9e901eeae8", "best_bid": "0.998", "best_ask": "0.999"}, {"asset_id": "5430476248758985969939507303101680818848966275102949447275298704026336588828", "price": "0.472", "size": "5", "side": "SELL", "hash": "8cd921ab6f1879d2edbc9c802c9bcae122521b90", "best_bid": "0.001", "best_ask": "0.002"}], "timestamp": "1769384230708", "event_type": "price_change"}}
{"_local_timestamp": "2026-01-25T23:37:11.094362+00:00", "data": {"market": "0x5999cfd552cbcf89bbd54c0e48b08c74182caefb18a80f1782018dcef2520d2d", "price_changes": [{"asset_id": "15174546601205928046556699082541161461166100492124394241054975981067833950165", "price": "0.528", "size": "0", "side": "BUY", "hash": "4ae666f9e030128f66ecc39a493b8f575ca2a29d", "best_bid": "0.998", "best_ask": "0.999"}, {"asset_id": "5430476248758985969939507303101680818848966275102949447275298704026336588828", "price": "0.472", "size": "0", "side": "SELL", "hash": "b25c304836e48efff577e5796f5097805ff9de39", "best_bid": "0.001", "best_ask": "0.002"}], "timestamp": "1769384231019", "event_type": "price_change"}}
{"_local_timestamp": "2026-01-25T23:37:11.510664+00:00", "data": {"market": "0x5999cfd552cbcf89bbd54c0e48b08c74182caefb18a80f1782018dcef2520d2d", "price_changes": [{"asset_id": "15174546601205928046556699082541161461166100492124394241054975981067833950165", "price": "0.528", "size": "5", "side": "BUY", "hash": "b080d7e3cc072c53bfdd2331b7bdb753e9c1f244", "best_bid": "0.998", "best_ask": "0.999"}, {"asset_id": "5430476248758985969939507303101680818848966275102949447275298704026336588828", "price": "0.472", "size": "5", "side": "SELL", "hash": "dec0d18932f1ed65981246be042d8c8a1f0cf997", "best_bid": "0.001", "best_ask": "0.002"}], "timestamp": "1769384231436", "event_type": "price_change"}}
{"_local_timestamp": "2026-01-25T23:37:12.555133+00:00", "data": {"market": "0x5999cfd552cbcf89bbd54c0e48b08c74182caefb18a80f1782018dcef2520d2d", "price_changes": [{"asset_id": "15174546601205928046556699082541161461166100492124394241054975981067833950165", "price": "0.528", "size": "0", "side": "BUY", "hash": "87e005e70dcf45749171667c7c2f8ba9e139f3cc", "best_bid": "0.998", "best_ask": "0.999"}, {"asset_id": "5430476248758985969939507303101680818848966275102949447275298704026336588828", "price": "0.472", "size": "0", "side": "SELL", "hash": "5efa1b7231c64b7dc8fa09618cd4264682e219ff", "best_bid": "0.001", "best_ask": "0.002"}], "timestamp": "1769384232481", "event_type": "price_change"}}
{"_local_timestamp": "2026-01-25T23:37:12.981957+00:00", "data": {"market": "0x5999cfd552cbcf89bbd54c0e48b08c74182caefb18a80f1782018dcef2520d2d", "price_changes": [{"asset_id": "15174546601205928046556699082541161461166100492124394241054975981067833950165", "price": "0.528", "size": "5", "side": "BUY", "hash": "df34b733aae581617e5a02959459906f1766ead5", "best_bid": "0.998", "best_ask": "0.999"}, {"asset_id": "5430476248758985969939507303101680818848966275102949447275298704026336588828", "price": "0.472", "size": "5", "side": "SELL", "hash": "79495f70c24fb0e3a5aad42e478b3bdf7f1e5252", "best_bid": "0.001", "best_ask": "0.002"}], "timestamp": "1769384232910", "event_type": "price_change"}}
{"_local_timestamp": "2026-01-25T23:37:14.035023+00:00", "data": {"market": "0x5999cfd552cbcf89bbd54c0e48b08c74182caefb18a80f1782018dcef2520d2d", "price_changes": [{"asset_id": "15174546601205928046556699082541161461166100492124394241054975981067833950165", "price": "0.528", "size": "0", "side": "BUY", "hash": "b0720d520d8539f4a7e328a748e33bd56826cf75", "best_bid": "0.998", "best_ask": "0.999"}, {"asset_id": "5430476248758985969939507303101680818848966275102949447275298704026336588828", "price": "0.472", "size": "0", "side": "SELL", "hash": "8515e7cc7651ce44ffde4b7eabfc8a4032d4401b", "best_bid": "0.001", "best_ask": "0.002"}], "timestamp": "1769384233960", "event_type": "price_change"}}
{"_local_timestamp": "2026-01-25T23:37:14.469868+00:00", "data": {"market": "0x5999cfd552cbcf89bbd54c0e48b08c74182caefb18a80f1782018dcef2520d2d", "price_changes": [{"asset_id": "15174546601205928046556699082541161461166100492124394241054975981067833950165", "price": "0.528", "size": "5", "side": "BUY", "hash": "f4ccf65acd12f44a1f062599949f62e071b11c49", "best_bid": "0.998", "best_ask": "0.999"}, {"asset_id": "5430476248758985969939507303101680818848966275102949447275298704026336588828", "price": "0.472", "size": "5", "side": "SELL", "hash": "a576edd1920188eb4f2ffc9a64c50233503321c2", "best_bid": "0.001", "best_ask": "0.002"}], "timestamp": "1769384234391", "event_type": "price_change"}}
{"_local_timestamp": "2026-01-25T23:37:15.023142+00:00", "data": {"market": "0x5999cfd552cbcf89bbd54c0e48b08c74182caefb18a80f1782018dcef2520d2d", "price_changes": [{"asset_id": "15174546601205928046556699082541161461166100492124394241054975981067833950165", "price": "0.528", "size": "0", "side": "BUY", "hash": "5bfd50cdf8cffd57278bf5c092a6d1a600a4d004", "best_bid": "0.998", "best_ask": "0.999"}, {"asset_id": "5430476248758985969939507303101680818848966275102949447275298704026336588828", "price": "0.472", "size": "0", "side": "SELL", "hash": "323d176e91d9f3f796947f4b3728c610705f05d2", "best_bid": "0.001", "best_ask": "0.002"}], "timestamp": "1769384234953", "event_type": "price_change"}}
{"_local_timestamp": "2026-01-25T23:37:15.693600+00:00", "data": {"market": "0x5999cfd552cbcf89bbd54c0e48b08c74182caefb18a80f1782018dcef2520d2d", "price_changes": [{"asset_id": "15174546601205928046556699082541161461166100492124394241054975981067833950165", "price": "0.528", "size": "5", "side": "BUY", "hash": "4770bb15de24878830993b66a1825fb200b6cbc6", "best_bid": "0.998", "best_ask": "0.999"}, {"asset_id": "5430476248758985969939507303101680818848966275102949447275298704026336588828", "price": "0.472", "size": "5", "side": "SELL", "hash": "4a9487c73d39d7fefe1359529244b39612ea4b22", "best_bid": "0.001", "best_ask": "0.002"}], "timestamp": "1769384235613", "event_type": "price_change"}}
{"_local_timestamp": "2026-01-25T23:37:16.955413+00:00", "data": {"market": "0x5999cfd552cbcf89bbd54c0e48b08c74182caefb18a80f1782018dcef2520d2d", "price_changes": [{"asset_id": "15174546601205928046556699082541161461166100492124394241054975981067833950165", "price": "0.528", "size": "0", "side": "BUY", "hash": "1d3a29d13d9dbb65e9909cff1e74bce293b1c2b1", "best_bid": "0.998", "best_ask": "0.999"}, {"asset_id": "5430476248758985969939507303101680818848966275102949447275298704026336588828", "price": "0.472", "size": "0", "side": "SELL", "hash": "aec0aa6baebba6da9acc87d8bafa481ba41b9143", "best_bid": "0.001", "best_ask": "0.002"}], "timestamp": "1769384236885", "event_type": "price_change"}}
{"_local_timestamp": "2026-01-25T23:37:17.225369+00:00", "data": {"market": "0x5999cfd552cbcf89bbd54c0e48b08c74182caefb18a80f1782018dcef2520d2d", "price_changes": [{"asset_id": "15174546601205928046556699082541161461166100492124394241054975981067833950165", "price": "0.528", "size": "5", "side": "BUY", "hash": "07fba84c039b97e809269d3fe01a1a9b7548c994", "best_bid": "0.998", "best_ask": "0.999"}, {"asset_id": "5430476248758985969939507303101680818848966275102949447275298704026336588828", "price": "0.472", "size": "5", "side": "SELL", "hash": "c4abfd6676f0e2d24004081709f3e2426d6e2506", "best_bid": "0.001", "best_ask": "0.002"}], "timestamp": "1769384237141", "event_type": "price_change"}}
{"_local_timestamp": "2026-01-25T23:37:18.278309+00:00", "data": {"market": "0x5999cfd552cbcf89bbd54c0e48b08c74182caefb18a80f1782018dcef2520d2d", "price_changes": [{"asset_id": "15174546601205928046556699082541161461166100492124394241054975981067833950165", "price": "0.528", "size": "0", "side": "BUY", "hash": "869b6e6720eedd67f3501597c28d4d7ef1fbedf4", "best_bid": "0.998", "best_ask": "0.999"}, {"asset_id": "5430476248758985969939507303101680818848966275102949447275298704026336588828", "price": "0.472", "size": "0", "side": "SELL", "hash": "d677f67613c86c6d4f627f5ed247b8cc431d13e8", "best_bid": "0.001", "best_ask": "0.002"}], "timestamp": "1769384238206", "event_type": "price_change"}}
{"_local_timestamp": "2026-01-25T23:37:18.735610+00:00", "data": {"market": "0x5999cfd552cbcf89bbd54c0e48b08c74182caefb18a80f1782018dcef2520d2d", "price_changes": [{"asset_id": "15174546601205928046556699082541161461166100492124394241054975981067833950165", "price": "0.528", "size": "5", "side": "BUY", "hash": "f79a22e86a2a02d55d4ac475f34d813915c2f8ad", "best_bid": "0.998", "best_ask": "0.999"}, {"asset_id": "5430476248758985969939507303101680818848966275102949447275298704026336588828", "price": "0.472", "size": "5", "side": "SELL", "hash": "5e3f7f27a064657788afe68dddad8797fdeb3ec0", "best_bid": "0.001", "best_ask": "0.002"}], "timestamp": "1769384238657", "event_type": "price_change"}}
{"_local_timestamp": "2026-01-25T23:37:19.934130+00:00", "data": {"market": "0x5999cfd552cbcf89bbd54c0e48b08c74182caefb18a80f1782018dcef2520d2d", "price_changes": [{"asset_id": "15174546601205928046556699082541161461166100492124394241054975981067833950165", "price": "0.528", "size": "0", "side": "BUY", "hash": "0fed1e603c5901638cca224fdab3003e5f2849ac", "best_bid": "0.998", "best_ask": "0.999"}, {"asset_id": "5430476248758985969939507303101680818848966275102949447275298704026336588828", "price": "0.472", "size": "0", "side": "SELL", "hash": "08b4d5521512b9b44c2d8bdfb6e5005118e2eb99", "best_bid": "0.001", "best_ask": "0.002"}], "timestamp": "1769384239866", "event_type": "price_change"}}
{"_local_timestamp": "2026-01-25T23:37:20.441860+00:00", "data": {"market": "0x5999cfd552cbcf89bbd54c0e48b08c74182caefb18a80f1782018dcef2520d2d", "price_changes": [{"asset_id": "15174546601205928046556699082541161461166100492124394241054975981067833950165", "price": "0.528", "size": "5", "side": "BUY", "hash": "9edf52e4e81e6adee1b79dca1e746e12c0c33dbb", "best_bid": "0.998", "best_ask": "0.999"}, {"asset_id": "5430476248758985969939507303101680818848966275102949447275298704026336588828", "price": "0.472", "size": "5", "side": "SELL", "hash": "d9525e90e06134577d516923cd71d7d4445ceb97", "best_bid": "0.001", "best_ask": "0.002"}], "timestamp": "1769384240375", "event_type": "price_change"}}
{"_local_timestamp": "2026-01-25T23:37:20.837779+00:00", "data": {"market": "0x5999cfd552cbcf89bbd54c0e48b08c74182caefb18a80f1782018dcef2520d2d", "price_changes": [{"asset_id": "15174546601205928046556699082541161461166100492124394241054975981067833950165", "price": "0.528", "size": "0", "side": "BUY", "hash": "efc32e5180f1b7ecc251e1b358295b5dca9001b8", "best_bid": "0.998", "best_ask": "0.999"}, {"asset_id": "5430476248758985969939507303101680818848966275102949447275298704026336588828", "price": "0.472", "size": "0", "side": "SELL", "hash": "dcaf33096ed5067eec866059f7e93b411ef54478", "best_bid": "0.001", "best_ask": "0.002"}], "timestamp": "1769384240767", "event_type": "price_change"}}
{"_local_timestamp": "2026-01-25T23:37:21.294307+00:00", "data": {"market": "0x5999cfd552cbcf89bbd54c0e48b08c74182caefb18a80f1782018dcef2520d2d", "price_changes": [{"asset_id": "15174546601205928046556699082541161461166100492124394241054975981067833950165", "price": "0.528", "size": "5", "side": "BUY", "hash": "2fcb7e5a9e94ce9b58c50b76dd5f3d5ab00c5bff", "best_bid": "0.998", "best_ask": "0.999"}, {"asset_id": "5430476248758985969939507303101680818848966275102949447275298704026336588828", "price": "0.472", "size": "5", "side": "SELL", "hash": "a130beaa923ee63d62ee1a355e36e4173d01cd64", "best_bid": "0.001", "best_ask": "0.002"}], "timestamp": "1769384241222", "event_type": "price_change"}}
{"_local_timestamp": "2026-01-25T23:37:22.918339+00:00", "data": {"market": "0x5999cfd552cbcf89bbd54c0e48b08c74182caefb18a80f1782018dcef2520d2d", "price_changes": [{"asset_id": "15174546601205928046556699082541161461166100492124394241054975981067833950165", "price": "0.528", "size": "0", "side": "BUY", "hash": "ecfdba732554e399e9384435fb6708958d56bcc6", "best_bid": "0.998", "best_ask": "0.999"}, {"asset_id": "5430476248758985969939507303101680818848966275102949447275298704026336588828", "price": "0.472", "size": "0", "side": "SELL", "hash": "e7f06811c59f176a86c7555e2e89d0f3911e0e02", "best_bid": "0.001", "best_ask": "0.002"}], "timestamp": "1769384242841", "event_type": "price_change"}}
{"_local_timestamp": "2026-01-25T23:37:23.296397+00:00", "data": {"market": "0x5999cfd552cbcf89bbd54c0e48b08c74182caefb18a80f1782018dcef2520d2d", "price_changes": [{"asset_id": "15174546601205928046556699082541161461166100492124394241054975981067833950165", "price": "0.528", "size": "5", "side": "BUY", "hash": "279f9ff3f902649a5e8ad6a047ad74075dbf7f63", "best_bid": "0.998", "best_ask": "0.999"}, {"asset_id": "5430476248758985969939507303101680818848966275102949447275298704026336588828", "price": "0.472", "size": "5", "side": "SELL", "hash": "7a98120b8e18de65a9d8a2446b26c6dddea13e55", "best_bid": "0.001", "best_ask": "0.002"}], "timestamp": "1769384243224", "event_type": "price_change"}}
{"_local_timestamp": "2026-01-25T23:37:24.434671+00:00", "data": {"market": "0x5999cfd552cbcf89bbd54c0e48b08c74182caefb18a80f1782018dcef2520d2d", "price_changes": [{"asset_id": "15174546601205928046556699082541161461166100492124394241054975981067833950165", "price": "0.528", "size": "0", "side": "BUY", "hash": "451b2f484598ef380a2a94f9c4a7beb0c1e1231b", "best_bid": "0.998", "best_ask": "0.999"}, {"asset_id": "5430476248758985969939507303101680818848966275102949447275298704026336588828", "price": "0.472", "size": "0", "side": "SELL", "hash": "91a358692a1362078b97b1c6de729247f8318d8a", "best_bid": "0.001", "best_ask": "0.002"}], "timestamp": "1769384244336", "event_type": "price_change"}}
{"_local_timestamp": "2026-01-25T23:37:24.805382+00:00", "data": {"market": "0x5999cfd552cbcf89bbd54c0e48b08c74182caefb18a80f1782018dcef2520d2d", "price_changes": [{"asset_id": "15174546601205928046556699082541161461166100492124394241054975981067833950165", "price": "0.528", "size": "5", "side": "BUY", "hash": "3b8c869d2d5fdec9bc1a63bb77e489fd6f9cbbac", "best_bid": "0.998", "best_ask": "0.999"}, {"asset_id": "5430476248758985969939507303101680818848966275102949447275298704026336588828", "price": "0.472", "size": "5", "side": "SELL", "hash": "46a9cc99c4c5d93a7d6761c138d5dbafccabdf9a", "best_bid": "0.001", "best_ask": "0.002"}], "timestamp": "1769384244717", "event_type": "price_change"}}
{"_local_timestamp": "2026-01-25T23:37:25.943413+00:00", "data": {"market": "0x5999cfd552cbcf89bbd54c0e48b08c74182caefb18a80f1782018dcef2520d2d", "price_changes": [{"asset_id": "15174546601205928046556699082541161461166100492124394241054975981067833950165", "price": "0.528", "size": "0", "side": "BUY", "hash": "ba9837b17d5c63e165507a45b71c481ef6a49353", "best_bid": "0.998", "best_ask": "0.999"}, {"asset_id": "5430476248758985969939507303101680818848966275102949447275298704026336588828", "price": "0.472", "size": "0", "side": "SELL", "hash": "56327474403acd9f8fbbda92d9532be009ccda6e", "best_bid": "0.001", "best_ask": "0.002"}], "timestamp": "1769384245869", "event_type": "price_change"}}
{"_local_timestamp": "2026-01-25T23:37:26.152512+00:00", "data": {"market": "0x5999cfd552cbcf89bbd54c0e48b08c74182caefb18a80f1782018dcef2520d2d", "price_changes": [{"asset_id": "15174546601205928046556699082541161461166100492124394241054975981067833950165", "price": "0.528", "size": "5", "side": "BUY", "hash": "afd22c58ca2ab58c30d9d9f8019f76cea6cd5137", "best_bid": "0.998", "best_ask": "0.999"}, {"asset_id": "5430476248758985969939507303101680818848966275102949447275298704026336588828", "price": "0.472", "size": "5", "side": "SELL", "hash": "74c70a7848623fb02119e1f310de3884f87d4856", "best_bid": "0.001", "best_ask": "0.002"}], "timestamp": "1769384246074", "event_type": "price_change"}}
{"_local_timestamp": "2026-01-25T23:37:27.441258+00:00", "data": {"market": "0x5999cfd552cbcf89bbd54c0e48b08c74182caefb18a80f1782018dcef2520d2d", "price_changes": [{"asset_id": "15174546601205928046556699082541161461166100492124394241054975981067833950165", "price": "0.528", "size": "0", "side": "BUY", "hash": "6fc57de30bdb81976f2e51ac92dbe7f7402c0af7", "best_bid": "0.998", "best_ask": "0.999"}, {"asset_id": "5430476248758985969939507303101680818848966275102949447275298704026336588828", "price": "0.472", "size": "0", "side": "SELL", "hash": "aac148f85dbb981dc15d2543403ed462b1cf400e", "best_bid": "0.001", "best_ask": "0.002"}], "timestamp": "1769384247368", "event_type": "price_change"}}
{"_local_timestamp": "2026-01-25T23:37:28.136242+00:00", "data": {"market": "0x5999cfd552cbcf89bbd54c0e48b08c74182caefb18a80f1782018dcef2520d2d", "price_changes": [{"asset_id": "15174546601205928046556699082541161461166100492124394241054975981067833950165", "price": "0.528", "size": "5", "side": "BUY", "hash": "7bcb2e288ba374224672f292311faf3ddef95320", "best_bid": "0.998", "best_ask": "0.999"}, {"asset_id": "5430476248758985969939507303101680818848966275102949447275298704026336588828", "price": "0.472", "size": "5", "side": "SELL", "hash": "fd5e8c451940991790f20aa8adc92c36a586b617", "best_bid": "0.001", "best_ask": "0.002"}], "timestamp": "1769384248062", "event_type": "price_change"}}
{"_local_timestamp": "2026-01-25T23:37:30.145535+00:00", "data": {"market": "0x5999cfd552cbcf89bbd54c0e48b08c74182caefb18a80f1782018dcef2520d2d", "price_changes": [{"asset_id": "15174546601205928046556699082541161461166100492124394241054975981067833950165", "price": "0.528", "size": "0", "side": "BUY", "hash": "f879c6af26418585b084f924f067069ae102a740", "best_bid": "0.998", "best_ask": "0.999"}, {"asset_id": "5430476248758985969939507303101680818848966275102949447275298704026336588828", "price": "0.472", "size": "0", "side": "SELL", "hash": "90340c8fcda3de5c757354fbea017c6c6928f1fa", "best_bid": "0.001", "best_ask": "0.002"}], "timestamp": "1769384250037", "event_type": "price_change"}}
{"_local_timestamp": "2026-01-25T23:37:30.575676+00:00", "data": {"market": "0x5999cfd552cbcf89bbd54c0e48b08c74182caefb18a80f1782018dcef2520d2d", "price_changes": [{"asset_id": "15174546601205928046556699082541161461166100492124394241054975981067833950165", "price": "0.528", "size": "5", "side": "BUY", "hash": "0d6d55749020e986302618e6812df48cc6a83d31", "best_bid": "0.998", "best_ask": "0.999"}, {"asset_id": "5430476248758985969939507303101680818848966275102949447275298704026336588828", "price": "0.472", "size": "5", "side": "SELL", "hash": "e6eca55805ff39dcd2721f0fedb2bfe696610a3a", "best_bid": "0.001", "best_ask": "0.002"}], "timestamp": "1769384250500", "event_type": "price_change"}}
{"_local_timestamp": "2026-01-25T23:37:31.631712+00:00", "data": {"market": "0x5999cfd552cbcf89bbd54c0e48b08c74182caefb18a80f1782018dcef2520d2d", "price_changes": [{"asset_id": "15174546601205928046556699082541161461166100492124394241054975981067833950165", "price": "0.528", "size": "0", "side": "BUY", "hash": "72b45f0f11d79991662c537bc6c12f8daeef3aac", "best_bid": "0.998", "best_ask": "0.999"}, {"asset_id": "5430476248758985969939507303101680818848966275102949447275298704026336588828", "price": "0.472", "size": "0", "side": "SELL", "hash": "57b13519f31e3287b22ab7826f83cec9fb5acb9b", "best_bid": "0.001", "best_ask": "0.002"}], "timestamp": "1769384251550", "event_type": "price_change"}}
{"_local_timestamp": "2026-01-25T23:37:32.151884+00:00", "data": {"market": "0x5999cfd552cbcf89bbd54c0e48b08c74182caefb18a80f1782018dcef2520d2d", "price_changes": [{"asset_id": "15174546601205928046556699082541161461166100492124394241054975981067833950165", "price": "0.528", "size": "5", "side": "BUY", "hash": "99e9466bb4c11aa21016f35be417ddb2e23429f3", "best_bid": "0.998", "best_ask": "0.999"}, {"asset_id": "5430476248758985969939507303101680818848966275102949447275298704026336588828", "price": "0.472", "size": "5", "side": "SELL", "hash": "2891b7783293f654a8054870ff740782b3f47481", "best_bid": "0.001", "best_ask": "0.002"}], "timestamp": "1769384252002", "event_type": "price_change"}}
{"_local_timestamp": "2026-01-25T23:37:33.116955+00:00", "data": {"market": "0x5999cfd552cbcf89bbd54c0e48b08c74182caefb18a80f1782018dcef2520d2d", "price_changes": [{"asset_id": "15174546601205928046556699082541161461166100492124394241054975981067833950165", "price": "0.528", "size": "0", "side": "BUY", "hash": "53d402e8f82df89f6473b24b8e68376e3ee344c0", "best_bid": "0.998", "best_ask": "0.999"}, {"asset_id": "5430476248758985969939507303101680818848966275102949447275298704026336588828", "price": "0.472", "size": "0", "side": "SELL", "hash": "654daa50182b9ae712a07b8ddcdb156c36d465fc", "best_bid": "0.001", "best_ask": "0.002"}], "timestamp": "1769384252984", "event_type": "price_change"}}
{"_local_timestamp": "2026-01-25T23:37:33.473404+00:00", "data": {"market": "0x5999cfd552cbcf89bbd54c0e48b08c74182caefb18a80f1782018dcef2520d2d", "price_changes": [{"asset_id": "15174546601205928046556699082541161461166100492124394241054975981067833950165", "price": "0.528", "size": "5", "side": "BUY", "hash": "ad429e109c53a4031028aa5feac0aadb93b1b8ac", "best_bid": "0.998", "best_ask": "0.999"}, {"asset_id": "5430476248758985969939507303101680818848966275102949447275298704026336588828", "price": "0.472", "size": "5", "side": "SELL", "hash": "bb736bda96363f3faf199626013653fd0f8110e7", "best_bid": "0.001", "best_ask": "0.002"}], "timestamp": "1769384253393", "event_type": "price_change"}}
{"_local_timestamp": "2026-01-25T23:37:34.356853+00:00", "data": {"market": "0x5999cfd552cbcf89bbd54c0e48b08c74182caefb18a80f1782018dcef2520d2d", "price_changes": [{"asset_id": "15174546601205928046556699082541161461166100492124394241054975981067833950165", "price": "0.528", "size": "0", "side": "BUY", "hash": "5acbc0daab69a3fa955fd19d9bf8765cac66485b", "best_bid": "0.998", "best_ask": "0.999"}, {"asset_id": "5430476248758985969939507303101680818848966275102949447275298704026336588828", "price": "0.472", "size": "0", "side": "SELL", "hash": "32d4ddb0fe4d7882c96f94b90bb2ec31f69fc8b3", "best_bid": "0.001", "best_ask": "0.002"}], "timestamp": "1769384254267", "event_type": "price_change"}}
{"_local_timestamp": "2026-01-25T23:37:34.787136+00:00", "data": {"market": "0x5999cfd552cbcf89bbd54c0e48b08c74182caefb18a80f1782018dcef2520d2d", "price_changes": [{"asset_id": "15174546601205928046556699082541161461166100492124394241054975981067833950165", "price": "0.528", "size": "5", "side": "BUY", "hash": "3b9a748d26b452c266a1bba7b40d43e77286f412", "best_bid": "0.998", "best_ask": "0.999"}, {"asset_id": "5430476248758985969939507303101680818848966275102949447275298704026336588828", "price": "0.472", "size": "5", "side": "SELL", "hash": "4d2b4be056352b6472e9725b0a19c50fcf60afb1", "best_bid": "0.001", "best_ask": "0.002"}], "timestamp": "1769384254664", "event_type": "price_change"}}
{"_local_timestamp": "2026-01-25T23:37:36.011523+00:00", "data": {"market": "0x5999cfd552cbcf89bbd54c0e48b08c74182caefb18a80f1782018dcef2520d2d", "price_changes": [{"asset_id": "15174546601205928046556699082541161461166100492124394241054975981067833950165", "price": "0.528", "size": "0", "side": "BUY", "hash": "e02c93f83ad1b62fcb13153eb9bbe233ccf6678f", "best_bid": "0.998", "best_ask": "0.999"}, {"asset_id": "5430476248758985969939507303101680818848966275102949447275298704026336588828", "price": "0.472", "size": "0", "side": "SELL", "hash": "84ac82224cab16d73f7160004c4b75f4d441e775", "best_bid": "0.001", "best_ask": "0.002"}], "timestamp": "1769384255937", "event_type": "price_change"}}
{"_local_timestamp": "2026-01-25T23:37:36.787497+00:00", "data": {"market": "0x5999cfd552cbcf89bbd54c0e48b08c74182caefb18a80f1782018dcef2520d2d", "price_changes": [{"asset_id": "15174546601205928046556699082541161461166100492124394241054975981067833950165", "price": "0.528", "size": "5", "side": "BUY", "hash": "cf66531d680a8bec72c96108561755f2aa30b4c6", "best_bid": "0.998", "best_ask": "0.999"}, {"asset_id": "5430476248758985969939507303101680818848966275102949447275298704026336588828", "price": "0.472", "size": "5", "side": "SELL", "hash": "c801f9e8bfcdc1fe3d6baddc1674007905befb91", "best_bid": "0.001", "best_ask": "0.002"}], "timestamp": "1769384256708", "event_type": "price_change"}}
{"_local_timestamp": "2026-01-25T23:37:37.642962+00:00", "data": {"market": "0x5999cfd552cbcf89bbd54c0e48b08c74182caefb18a80f1782018dcef2520d2d", "price_changes": [{"asset_id": "15174546601205928046556699082541161461166100492124394241054975981067833950165", "price": "0.528", "size": "0", "side": "BUY", "hash": "1aa468f0e51ee5a9eea5985d73920a07b841a097", "best_bid": "0.998", "best_ask": "0.999"}, {"asset_id": "5430476248758985969939507303101680818848966275102949447275298704026336588828", "price": "0.472", "size": "0", "side": "SELL", "hash": "b6ad47c1bed381a6fd3ce4f3024151689871eff5", "best_bid": "0.001", "best_ask": "0.002"}], "timestamp": "1769384257570", "event_type": "price_change"}}
{"_local_timestamp": "2026-01-25T23:37:38.100365+00:00", "data": {"market": "0x5999cfd552cbcf89bbd54c0e48b08c74182caefb18a80f1782018dcef2520d2d", "price_changes": [{"asset_id": "15174546601205928046556699082541161461166100492124394241054975981067833950165", "price": "0.528", "size": "5", "side": "BUY", "hash": "5ab71446e38e17e4709b1a7ac830df5c8d02e130", "best_bid": "0.998", "best_ask": "0.999"}, {"asset_id": "5430476248758985969939507303101680818848966275102949447275298704026336588828", "price": "0.472", "size": "5", "side": "SELL", "hash": "f5ec081369816d7e2b2e386ac657c2573be6905d", "best_bid": "0.001", "best_ask": "0.002"}], "timestamp": "1769384258023", "event_type": "price_change"}}
{"_local_timestamp": "2026-01-25T23:37:39.089303+00:00", "data": {"market": "0x5999cfd552cbcf89bbd54c0e48b08c74182caefb18a80f1782018dcef2520d2d", "price_changes": [{"asset_id": "15174546601205928046556699082541161461166100492124394241054975981067833950165", "price": "0.528", "size": "0", "side": "BUY", "hash": "82af2600f84bc05156b8f3331478680599742632", "best_bid": "0.998", "best_ask": "0.999"}, {"asset_id": "5430476248758985969939507303101680818848966275102949447275298704026336588828", "price": "0.472", "size": "0", "side": "SELL", "hash": "0aa5152fbca780b217cc68155aa0ef9c1f5f9623", "best_bid": "0.001", "best_ask": "0.002"}], "timestamp": "1769384259006", "event_type": "price_change"}}
{"_local_timestamp": "2026-01-25T23:37:39.391717+00:00", "data": {"market": "0x5999cfd552cbcf89bbd54c0e48b08c74182caefb18a80f1782018dcef2520d2d", "price_changes": [{"asset_id": "15174546601205928046556699082541161461166100492124394241054975981067833950165", "price": "0.528", "size": "5", "side": "BUY", "hash": "e7a0cc81e8f730754ab6c2c44f3ce4e7378c62d8", "best_bid": "0.998", "best_ask": "0.999"}, {"asset_id": "5430476248758985969939507303101680818848966275102949447275298704026336588828", "price": "0.472", "size": "5", "side": "SELL", "hash": "f7aa1d640f13029485889c4aefde6aa33b44841b", "best_bid": "0.001", "best_ask": "0.002"}], "timestamp": "1769384259314", "event_type": "price_change"}}
{"_local_timestamp": "2026-01-25T23:37:40.809265+00:00", "data": {"market": "0x5999cfd552cbcf89bbd54c0e48b08c74182caefb18a80f1782018dcef2520d2d", "price_changes": [{"asset_id": "15174546601205928046556699082541161461166100492124394241054975981067833950165", "price": "0.528", "size": "0", "side": "BUY", "hash": "efc6f695d22e2b44c72ef21d49cda7479412a69c", "best_bid": "0.998", "best_ask": "0.999"}, {"asset_id": "5430476248758985969939507303101680818848966275102949447275298704026336588828", "price": "0.472", "size": "0", "side": "SELL", "hash": "ecbef4f51d5beb6f42144f375c471cb196976f71", "best_bid": "0.001", "best_ask": "0.002"}], "timestamp": "1769384260727", "event_type": "price_change"}}
{"_local_timestamp": "2026-01-25T23:37:41.196833+00:00", "data": {"market": "0x5999cfd552cbcf89bbd54c0e48b08c74182caefb18a80f1782018dcef2520d2d", "price_changes": [{"asset_id": "15174546601205928046556699082541161461166100492124394241054975981067833950165", "price": "0.528", "size": "5", "side": "BUY", "hash": "2eb13c766a0be192609f00d0e60701e7e0f65fb7", "best_bid": "0.998", "best_ask": "0.999"}, {"asset_id": "5430476248758985969939507303101680818848966275102949447275298704026336588828", "price": "0.472", "size": "5", "side": "SELL", "hash": "74b9190cdbf423ab38f4128853bc39769bf0ca22", "best_bid": "0.001", "best_ask": "0.002"}], "timestamp": "1769384261070", "event_type": "price_change"}}
{"_local_timestamp": "2026-01-25T23:37:42.154484+00:00", "data": {"market": "0x5999cfd552cbcf89bbd54c0e48b08c74182caefb18a80f1782018dcef2520d2d", "price_changes": [{"asset_id": "15174546601205928046556699082541161461166100492124394241054975981067833950165", "price": "0.528", "size": "0", "side": "BUY", "hash": "d7e078affe82d0d7695c74024dcfa2a4663589e5", "best_bid": "0.998", "best_ask": "0.999"}, {"asset_id": "5430476248758985969939507303101680818848966275102949447275298704026336588828", "price": "0.472", "size": "0", "side": "SELL", "hash": "8640446e5722acd64c7bae2f197d9def6677ef03", "best_bid": "0.001", "best_ask": "0.002"}], "timestamp": "1769384262039", "event_type": "price_change"}}
{"_local_timestamp": "2026-01-25T23:37:42.383100+00:00", "data": {"market": "0x5999cfd552cbcf89bbd54c0e48b08c74182caefb18a80f1782018dcef2520d2d", "price_changes": [{"asset_id": "15174546601205928046556699082541161461166100492124394241054975981067833950165", "price": "0.528", "size": "5", "side": "BUY", "hash": "62603671c26c6943b62f178d7b10455f6968664c", "best_bid": "0.998", "best_ask": "0.999"}, {"asset_id": "5430476248758985969939507303101680818848966275102949447275298704026336588828", "price": "0.472", "size": "5", "side": "SELL", "hash": "0d18de6e2a58d698f72eaaaeed00bb5a091f5dd7", "best_bid": "0.001", "best_ask": "0.002"}], "timestamp": "1769384262305", "event_type": "price_change"}}
{"_local_timestamp": "2026-01-25T23:37:43.858373+00:00", "data": {"market": "0x5999cfd552cbcf89bbd54c0e48b08c74182caefb18a80f1782018dcef2520d2d", "price_changes": [{"asset_id": "15174546601205928046556699082541161461166100492124394241054975981067833950165", "price": "0.528", "size": "0", "side": "BUY", "hash": "50652703a5692dd7eaef953dae1ac4ca1bfa7eea", "best_bid": "0.998", "best_ask": "0.999"}, {"asset_id": "5430476248758985969939507303101680818848966275102949447275298704026336588828", "price": "0.472", "size": "0", "side": "SELL", "hash": "dd971026bd5e3e0992c4d48a20f93d7020e9c107", "best_bid": "0.001", "best_ask": "0.002"}], "timestamp": "1769384263785", "event_type": "price_change"}}
{"_local_timestamp": "2026-01-25T23:37:44.189815+00:00", "data": {"market": "0x5999cfd552cbcf89bbd54c0e48b08c74182caefb18a80f1782018dcef2520d2d", "price_changes": [{"asset_id": "15174546601205928046556699082541161461166100492124394241054975981067833950165", "price": "0.528", "size": "5", "side": "BUY", "hash": "bed272ef247c473f8d8352a493912092dee4929c", "best_bid": "0.998", "best_ask": "0.999"}, {"asset_id": "5430476248758985969939507303101680818848966275102949447275298704026336588828", "price": "0.472", "size": "5", "side": "SELL", "hash": "b9c53a5fbf7104fcb9bbbe57058286af58e1ed93", "best_bid": "0.001", "best_ask": "0.002"}], "timestamp": "1769384264121", "event_type": "price_change"}}
{"_local_timestamp": "2026-01-25T23:37:45.147616+00:00", "data": {"market": "0x5999cfd552cbcf89bbd54c0e48b08c74182caefb18a80f1782018dcef2520d2d", "price_changes": [{"asset_id": "15174546601205928046556699082541161461166100492124394241054975981067833950165", "price": "0.528", "size": "0", "side": "BUY", "hash": "344809d5a54eda53020982e9c5337dc5ff84f71f", "best_bid": "0.998", "best_ask": "0.999"}, {"asset_id": "5430476248758985969939507303101680818848966275102949447275298704026336588828", "price": "0.472", "size": "0", "side": "SELL", "hash": "ee8508b3ecd9c8c9070b11bb091a6e42d9d81353", "best_bid": "0.001", "best_ask": "0.002"}], "timestamp": "1769384265077", "event_type": "price_change"}}
{"_local_timestamp": "2026-01-25T23:37:45.515567+00:00", "data": {"market": "0x5999cfd552cbcf89bbd54c0e48b08c74182caefb18a80f1782018dcef2520d2d", "price_changes": [{"asset_id": "15174546601205928046556699082541161461166100492124394241054975981067833950165", "price": "0.528", "size": "5", "side": "BUY", "hash": "3ee62da39f874913bbb9b2885d63fc27a69c57f5", "best_bid": "0.998", "best_ask": "0.999"}, {"asset_id": "5430476248758985969939507303101680818848966275102949447275298704026336588828", "price": "0.472", "size": "5", "side": "SELL", "hash": "43644f845bf32447f8367d8d5476a616c5297dac", "best_bid": "0.001", "best_ask": "0.002"}], "timestamp": "1769384265438", "event_type": "price_change"}}
{"_local_timestamp": "2026-01-25T23:37:46.876207+00:00", "data": {"market": "0x5999cfd552cbcf89bbd54c0e48b08c74182caefb18a80f1782018dcef2520d2d", "price_changes": [{"asset_id": "15174546601205928046556699082541161461166100492124394241054975981067833950165", "price": "0.528", "size": "0", "side": "BUY", "hash": "e39c44e29ce608d9391b207534dcf65fb1943e0b", "best_bid": "0.998", "best_ask": "0.999"}, {"asset_id": "5430476248758985969939507303101680818848966275102949447275298704026336588828", "price": "0.472", "size": "0", "side": "SELL", "hash": "d1d1f7b4ea86bca822b154fd7e99b4133e0eee07", "best_bid": "0.001", "best_ask": "0.002"}], "timestamp": "1769384266804", "event_type": "price_change"}}
{"_local_timestamp": "2026-01-25T23:37:47.290537+00:00", "data": {"market": "0x5999cfd552cbcf89bbd54c0e48b08c74182caefb18a80f1782018dcef2520d2d", "price_changes": [{"asset_id": "15174546601205928046556699082541161461166100492124394241054975981067833950165", "price": "0.528", "size": "5", "side": "BUY", "hash": "014635a08bb4becb8a82eed0f16aea74cc96a30e", "best_bid": "0.998", "best_ask": "0.999"}, {"asset_id": "5430476248758985969939507303101680818848966275102949447275298704026336588828", "price": "0.472", "size": "5", "side": "SELL", "hash": "22fa00a71e1daa17ce1052bdfdcfa9202226b634", "best_bid": "0.001", "best_ask": "0.002"}], "timestamp": "1769384267218", "event_type": "price_change"}}
{"_local_timestamp": "2026-01-25T23:37:48.063584+00:00", "data": {"market": "0x0fc1398bb3cff37d77101392989d6ff065d28d7c0dc50b282bd1b5098b9d78b8", "price_changes": [{"asset_id": "89336264239989122383122704165255872699177887882264330841492281051298522223986", "price": "0.892", "size": "0", "side": "BUY", "hash": "ca203726702b463c0aa0c96b461b4b2932a9e88a", "best_bid": "0.889", "best_ask": "0.934"}, {"asset_id": "76309699246141587406891686852898742630368640356883728029522206362139036530694", "price": "0.108", "size": "0", "side": "SELL", "hash": "6657cc588f13a16ab57126cf73fc410026bcd3c3", "best_bid": "0.066", "best_ask": "0.111"}], "timestamp": "1769384267968", "event_type": "price_change"}}
{"_local_timestamp": "2026-01-25T23:37:48.665491+00:00", "data": {"market": "0x5999cfd552cbcf89bbd54c0e48b08c74182caefb18a80f1782018dcef2520d2d", "price_changes": [{"asset_id": "15174546601205928046556699082541161461166100492124394241054975981067833950165", "price": "0.528", "size": "0", "side": "BUY", "hash": "2aaa87b7eb7edcbc0734f7ee495b61923ada3911", "best_bid": "0.998", "best_ask": "0.999"}, {"asset_id": "5430476248758985969939507303101680818848966275102949447275298704026336588828", "price": "0.472", "size": "0", "side": "SELL", "hash": "77da8d83c2797dd4c9ac4ecb631cf8486e57b632", "best_bid": "0.001", "best_ask": "0.002"}], "timestamp": "1769384268589", "event_type": "price_change"}}
{"_local_timestamp": "2026-01-25T23:37:48.786233+00:00", "data": {"market": "0x0fc1398bb3cff37d77101392989d6ff065d28d7c0dc50b282bd1b5098b9d78b8", "price_changes": [{"asset_id": "89336264239989122383122704165255872699177887882264330841492281051298522223986", "price": "0.89", "size": "66.66", "side": "BUY", "hash": "ae194dd754630797bc28ae319c22456bc73ee2af", "best_bid": "0.89", "best_ask": "0.934"}, {"asset_id": "76309699246141587406891686852898742630368640356883728029522206362139036530694", "price": "0.11", "size": "66.66", "side": "SELL", "hash": "013d7e1ff99e35a11d7b0e95413e54559936f576", "best_bid": "0.066", "best_ask": "0.11"}], "timestamp": "1769384268711", "event_type": "price_change"}}
{"_local_timestamp": "2026-01-25T23:37:49.042130+00:00", "data": {"market": "0x5999cfd552cbcf89bbd54c0e48b08c74182caefb18a80f1782018dcef2520d2d", "price_changes": [{"asset_id": "15174546601205928046556699082541161461166100492124394241054975981067833950165", "price": "0.528", "size": "5", "side": "BUY", "hash": "585b2d9fb00329c2cdbcb5407fde934aa452325b", "best_bid": "0.998", "best_ask": "0.999"}, {"asset_id": "5430476248758985969939507303101680818848966275102949447275298704026336588828", "price": "0.472", "size": "5", "side": "SELL", "hash": "83a8d97a59562b86ca789fc482f79ac2e5e541dd", "best_bid": "0.001", "best_ask": "0.002"}], "timestamp": "1769384268967", "event_type": "price_change"}}
{"_local_timestamp": "2026-01-25T23:37:49.947453+00:00", "data": {"market": "0x5999cfd552cbcf89bbd54c0e48b08c74182caefb18a80f1782018dcef2520d2d", "price_changes": [{"asset_id": "15174546601205928046556699082541161461166100492124394241054975981067833950165", "price": "0.528", "size": "0", "side": "BUY", "hash": "e61d93b5b4c7b6d5d5a1fcf95947fafc8b2a5996", "best_bid": "0.998", "best_ask": "0.999"}, {"asset_id": "5430476248758985969939507303101680818848966275102949447275298704026336588828", "price": "0.472", "size": "0", "side": "SELL", "hash": "8f10095ab71e3aba12e16c43658f9d6817652a0c", "best_bid": "0.001", "best_ask": "0.002"}], "timestamp": "1769384269872", "event_type": "price_change"}}
{"_local_timestamp": "2026-01-25T23:37:50.243842+00:00", "data": {"market": "0x5999cfd552cbcf89bbd54c0e48b08c74182caefb18a80f1782018dcef2520d2d", "price_changes": [{"asset_id": "15174546601205928046556699082541161461166100492124394241054975981067833950165", "price": "0.528", "size": "5", "side": "BUY", "hash": "cda0e626f3f8cc08eca1fd4d987c12f08e0f4e61", "best_bid": "0.998", "best_ask": "0.999"}, {"asset_id": "5430476248758985969939507303101680818848966275102949447275298704026336588828", "price": "0.472", "size": "5", "side": "SELL", "hash": "0dda55b4c8b6c8897e37564e14f113dd9acad0c0", "best_bid": "0.001", "best_ask": "0.002"}], "timestamp": "1769384270170", "event_type": "price_change"}}
{"_local_timestamp": "2026-01-25T23:37:51.520105+00:00", "data": {"market": "0x5999cfd552cbcf89bbd54c0e48b08c74182caefb18a80f1782018dcef2520d2d", "price_changes": [{"asset_id": "15174546601205928046556699082541161461166100492124394241054975981067833950165", "price": "0.528", "size": "0", "side": "BUY", "hash": "bfcafeb2a758677b0b4b16bbdf334621cc6a2c03", "best_bid": "0.998", "best_ask": "0.999"}, {"asset_id": "5430476248758985969939507303101680818848966275102949447275298704026336588828", "price": "0.472", "size": "0", "side": "SELL", "hash": "ceaa9724fcd6c1d664e3f5519aa88d7a92b260c4", "best_bid": "0.001", "best_ask": "0.002"}], "timestamp": "1769384271215", "event_type": "price_change"}}
{"_local_timestamp": "2026-01-25T23:37:51.789516+00:00", "data": {"market": "0x5999cfd552cbcf89bbd54c0e48b08c74182caefb18a80f1782018dcef2520d2d", "price_changes": [{"asset_id": "15174546601205928046556699082541161461166100492124394241054975981067833950165", "price": "0.528", "size": "5", "side": "BUY", "hash": "a1553b55066451f872716b2f79f2cc8ba5c8550e", "best_bid": "0.998", "best_ask": "0.999"}, {"asset_id": "5430476248758985969939507303101680818848966275102949447275298704026336588828", "price": "0.472", "size": "5", "side": "SELL", "hash": "1ba8924b5ee2f3e4efaea9fb7e8f90150be28b7f", "best_bid": "0.001", "best_ask": "0.002"}], "timestamp": "1769384271585", "event_type": "price_change"}}
{"_local_timestamp": "2026-01-25T23:37:52.793986+00:00", "data": {"market": "0x5999cfd552cbcf89bbd54c0e48b08c74182caefb18a80f1782018dcef2520d2d", "price_changes": [{"asset_id": "15174546601205928046556699082541161461166100492124394241054975981067833950165", "price": "0.528", "size": "0", "side": "BUY", "hash": "99fc0664dee4b4c9b23ca56d278f529a0815c224", "best_bid": "0.998", "best_ask": "0.999"}, {"asset_id": "5430476248758985969939507303101680818848966275102949447275298704026336588828", "price": "0.472", "size": "0", "side": "SELL", "hash": "084629fc7849055326f1c328ba7c53052372d879", "best_bid": "0.001", "best_ask": "0.002"}], "timestamp": "1769384272684", "event_type": "price_change"}}
{"_local_timestamp": "2026-01-25T23:37:53.199504+00:00", "data": {"market": "0x5999cfd552cbcf89bbd54c0e48b08c74182caefb18a80f1782018dcef2520d2d", "price_changes": [{"asset_id": "15174546601205928046556699082541161461166100492124394241054975981067833950165", "price": "0.528", "size": "5", "side": "BUY", "hash": "08b6176c42a526d37006bb6c1da6d202aaa392c6", "best_bid": "0.998", "best_ask": "0.999"}, {"asset_id": "5430476248758985969939507303101680818848966275102949447275298704026336588828", "price": "0.472", "size": "5", "side": "SELL", "hash": "4e3917096aa5ee5b7474eff9c47e3ba8ecf60a56", "best_bid": "0.001", "best_ask": "0.002"}], "timestamp": "1769384273128", "event_type": "price_change"}}
{"_local_timestamp": "2026-01-25T23:37:54.094894+00:00", "data": {"market": "0x5999cfd552cbcf89bbd54c0e48b08c74182caefb18a80f1782018dcef2520d2d", "price_changes": [{"asset_id": "15174546601205928046556699082541161461166100492124394241054975981067833950165", "price": "0.528", "size": "0", "side": "BUY", "hash": "90369e6565109c0e1555591b3e77d39f50419802", "best_bid": "0.998", "best_ask": "0.999"}, {"asset_id": "5430476248758985969939507303101680818848966275102949447275298704026336588828", "price": "0.472", "size": "0", "side": "SELL", "hash": "716068f2da0c58a13acafab8051bdcb8c99cfd6b", "best_bid": "0.001", "best_ask": "0.002"}], "timestamp": "1769384274013", "event_type": "price_change"}}
{"_local_timestamp": "2026-01-25T23:37:54.475801+00:00", "data": {"market": "0x5999cfd552cbcf89bbd54c0e48b08c74182caefb18a80f1782018dcef2520d2d", "price_changes": [{"asset_id": "15174546601205928046556699082541161461166100492124394241054975981067833950165", "price": "0.528", "size": "5", "side": "BUY", "hash": "4c17d2ebf31e7cef335f2380380e2102a96f1fe6", "best_bid": "0.998", "best_ask": "0.999"}, {"asset_id": "5430476248758985969939507303101680818848966275102949447275298704026336588828", "price": "0.472", "size": "5", "side": "SELL", "hash": "e25bc397559033e6b20370eba3a7ee3978d65fbe", "best_bid": "0.001", "best_ask": "0.002"}], "timestamp": "1769384274400", "event_type": "price_change"}}
{"_local_timestamp": "2026-01-25T23:37:55.366531+00:00", "data": {"market": "0x5999cfd552cbcf89bbd54c0e48b08c74182caefb18a80f1782018dcef2520d2d", "price_changes": [{"asset_id": "15174546601205928046556699082541161461166100492124394241054975981067833950165", "price": "0.528", "size": "0", "side": "BUY", "hash": "61ba7b2fdc119b92b6cda26a330b7c6a1a4ce93e", "best_bid": "0.998", "best_ask": "0.999"}, {"asset_id": "5430476248758985969939507303101680818848966275102949447275298704026336588828", "price": "0.472", "size": "0", "side": "SELL", "hash": "a4fba56a1d34946dd32e04c39f5debe70cd8b2b8", "best_bid": "0.001", "best_ask": "0.002"}], "timestamp": "1769384275292", "event_type": "price_change"}}
{"_local_timestamp": "2026-01-25T23:37:56.148317+00:00", "data": {"market": "0x5999cfd552cbcf89bbd54c0e48b08c74182caefb18a80f1782018dcef2520d2d", "price_changes": [{"asset_id": "15174546601205928046556699082541161461166100492124394241054975981067833950165", "price": "0.528", "size": "5", "side": "BUY", "hash": "aeb78b08d0b567fae9f7a09e1a90cf238d4a3fde", "best_bid": "0.998", "best_ask": "0.999"}, {"asset_id": "5430476248758985969939507303101680818848966275102949447275298704026336588828", "price": "0.472", "size": "5", "side": "SELL", "hash": "7196a1e8cdc6858f805933331197423b0d73d21f", "best_bid": "0.001", "best_ask": "0.002"}], "timestamp": "1769384276047", "event_type": "price_change"}}
{"_local_timestamp": "2026-01-25T23:37:57.880369+00:00", "data": {"market": "0x5999cfd552cbcf89bbd54c0e48b08c74182caefb18a80f1782018dcef2520d2d", "price_changes": [{"asset_id": "15174546601205928046556699082541161461166100492124394241054975981067833950165", "price": "0.528", "size": "0", "side": "BUY", "hash": "fb738f5ef04bd593bbd718807411dc5481ca6f25", "best_bid": "0.998", "best_ask": "0.999"}, {"asset_id": "5430476248758985969939507303101680818848966275102949447275298704026336588828", "price": "0.472", "size": "0", "side": "SELL", "hash": "8a0d8139c42ebb46052b40b9d67c3455f277f6db", "best_bid": "0.001", "best_ask": "0.002"}], "timestamp": "1769384277807", "event_type": "price_change"}}
{"_local_timestamp": "2026-01-25T23:37:58.171585+00:00", "data": {"market": "0x5999cfd552cbcf89bbd54c0e48b08c74182caefb18a80f1782018dcef2520d2d", "price_changes": [{"asset_id": "15174546601205928046556699082541161461166100492124394241054975981067833950165", "price": "0.528", "size": "5", "side": "BUY", "hash": "362c1fc416e25b4337b6279d3c556be0da29a715", "best_bid": "0.998", "best_ask": "0.999"}, {"asset_id": "5430476248758985969939507303101680818848966275102949447275298704026336588828", "price": "0.472", "size": "5", "side": "SELL", "hash": "726e87b1216205d3e1b151428ed4ffa2115e512c", "best_bid": "0.001", "best_ask": "0.002"}], "timestamp": "1769384278096", "event_type": "price_change"}}
{"_local_timestamp": "2026-01-25T23:37:59.190644+00:00", "data": {"market": "0x5999cfd552cbcf89bbd54c0e48b08c74182caefb18a80f1782018dcef2520d2d", "price_changes": [{"asset_id": "15174546601205928046556699082541161461166100492124394241054975981067833950165", "price": "0.528", "size": "0", "side": "BUY", "hash": "5e65c89df06ff97c5d96ef959b59b10be431d099", "best_bid": "0.998", "best_ask": "0.999"}, {"asset_id": "5430476248758985969939507303101680818848966275102949447275298704026336588828", "price": "0.472", "size": "0", "side": "SELL", "hash": "673e6f095eacb6b22359456d968e931dd233e8a5", "best_bid": "0.001", "best_ask": "0.002"}], "timestamp": "1769384279107", "event_type": "price_change"}}
{"_local_timestamp": "2026-01-25T23:37:59.419300+00:00", "data": {"market": "0x5999cfd552cbcf89bbd54c0e48b08c74182caefb18a80f1782018dcef2520d2d", "price_changes": [{"asset_id": "15174546601205928046556699082541161461166100492124394241054975981067833950165", "price": "0.528", "size": "5", "side": "BUY", "hash": "c429a80c0ac5ec33e5c1a8f984ac7417d73dda93", "best_bid": "0.998", "best_ask": "0.999"}, {"asset_id": "5430476248758985969939507303101680818848966275102949447275298704026336588828", "price": "0.472", "size": "5", "side": "SELL", "hash": "401af913e51d414dda52c3bf336a8478921b55fe", "best_bid": "0.001", "best_ask": "0.002"}], "timestamp": "1769384279345", "event_type": "price_change"}}
{"_local_timestamp": "2026-01-25T23:38:00.783278+00:00", "data": {"market": "0x5999cfd552cbcf89bbd54c0e48b08c74182caefb18a80f1782018dcef2520d2d", "price_changes": [{"asset_id": "15174546601205928046556699082541161461166100492124394241054975981067833950165", "price": "0.528", "size": "0", "side": "BUY", "hash": "e8a854613b7a31657012ad3a8f8000b258a93034", "best_bid": "0.998", "best_ask": "0.999"}, {"asset_id": "5430476248758985969939507303101680818848966275102949447275298704026336588828", "price": "0.472", "size": "0", "side": "SELL", "hash": "613fd3259a17dfe1c74571752c1bf91a05c04414", "best_bid": "0.001", "best_ask": "0.002"}], "timestamp": "1769384280707", "event_type": "price_change"}}
{"_local_timestamp": "2026-01-25T23:38:01.073607+00:00", "data": {"market": "0x5999cfd552cbcf89bbd54c0e48b08c74182caefb18a80f1782018dcef2520d2d", "price_changes": [{"asset_id": "15174546601205928046556699082541161461166100492124394241054975981067833950165", "price": "0.528", "size": "5", "side": "BUY", "hash": "16344063b466b97e88b308e5331102e41ceb452f", "best_bid": "0.998", "best_ask": "0.999"}, {"asset_id": "5430476248758985969939507303101680818848966275102949447275298704026336588828", "price": "0.472", "size": "5", "side": "SELL", "hash": "d3ca75c874eb74e3d2b263ed16e5bf93d37a637e", "best_bid": "0.001", "best_ask": "0.002"}], "timestamp": "1769384280993", "event_type": "price_change"}}
{"_local_timestamp": "2026-01-25T23:38:02.089884+00:00", "data": {"market": "0x5999cfd552cbcf89bbd54c0e48b08c74182caefb18a80f1782018dcef2520d2d", "price_changes": [{"asset_id": "15174546601205928046556699082541161461166100492124394241054975981067833950165", "price": "0.528", "size": "0", "side": "BUY", "hash": "59cd975740b1b4ff7039636c1e2cc940ca605fb8", "best_bid": "0.998", "best_ask": "0.999"}, {"asset_id": "5430476248758985969939507303101680818848966275102949447275298704026336588828", "price": "0.472", "size": "0", "side": "SELL", "hash": "2b730ee85dfa8a180c592efbfbcc3733da2a669a", "best_bid": "0.001", "best_ask": "0.002"}], "timestamp": "1769384282015", "event_type": "price_change"}}
{"_local_timestamp": "2026-01-25T23:38:02.549529+00:00", "data": {"market": "0x5999cfd552cbcf89bbd54c0e48b08c74182caefb18a80f1782018dcef2520d2d", "price_changes": [{"asset_id": "15174546601205928046556699082541161461166100492124394241054975981067833950165", "price": "0.528", "size": "5", "side": "BUY", "hash": "f587d9fe9612f81471f84bd433b4eede2a5428bf", "best_bid": "0.998", "best_ask": "0.999"}, {"asset_id": "5430476248758985969939507303101680818848966275102949447275298704026336588828", "price": "0.472", "size": "5", "side": "SELL", "hash": "b8c7d5c2984c62ea963679fe18971a03bb55f534", "best_bid": "0.001", "best_ask": "0.002"}], "timestamp": "1769384282462", "event_type": "price_change"}}
{"_local_timestamp": "2026-01-25T23:38:03.741678+00:00", "data": {"market": "0x5999cfd552cbcf89bbd54c0e48b08c74182caefb18a80f1782018dcef2520d2d", "price_changes": [{"asset_id": "15174546601205928046556699082541161461166100492124394241054975981067833950165", "price": "0.528", "size": "0", "side": "BUY", "hash": "bff9dc8a38e5bef14d3d20b58ca5f047b40da687", "best_bid": "0.998", "best_ask": "0.999"}, {"asset_id": "5430476248758985969939507303101680818848966275102949447275298704026336588828", "price": "0.472", "size": "0", "side": "SELL", "hash": "46de6c93a9f74d83da85deab05d860aa0f00ae32", "best_bid": "0.001", "best_ask": "0.002"}], "timestamp": "1769384283661", "event_type": "price_change"}}
{"_local_timestamp": "2026-01-25T23:38:04.162688+00:00", "data": {"market": "0x5999cfd552cbcf89bbd54c0e48b08c74182caefb18a80f1782018dcef2520d2d", "price_changes": [{"asset_id": "15174546601205928046556699082541161461166100492124394241054975981067833950165", "price": "0.528", "size": "5", "side": "BUY", "hash": "840d627f07874065decd8887780aabed7b2a5b34", "best_bid": "0.998", "best_ask": "0.999"}, {"asset_id": "5430476248758985969939507303101680818848966275102949447275298704026336588828", "price": "0.472", "size": "5", "side": "SELL", "hash": "e3a687b54c4461600806a89134fd5a300540df05", "best_bid": "0.001", "best_ask": "0.002"}], "timestamp": "1769384284072", "event_type": "price_change"}}
{"_local_timestamp": "2026-01-25T23:38:05.463190+00:00", "data": {"market": "0x5999cfd552cbcf89bbd54c0e48b08c74182caefb18a80f1782018dcef2520d2d", "price_changes": [{"asset_id": "15174546601205928046556699082541161461166100492124394241054975981067833950165", "price": "0.528", "size": "0", "side": "BUY", "hash": "af5dac032c799694f53358928142b1f4138f3246", "best_bid": "0.998", "best_ask": "0.999"}, {"asset_id": "5430476248758985969939507303101680818848966275102949447275298704026336588828", "price": "0.472", "size": "0", "side": "SELL", "hash": "5363c656f9143713ffcd19473062e9aceaed9a40", "best_bid": "0.001", "best_ask": "0.002"}], "timestamp": "1769384285381", "event_type": "price_change"}}
{"_local_timestamp": "2026-01-25T23:38:05.758870+00:00", "data": {"market": "0x5999cfd552cbcf89bbd54c0e48b08c74182caefb18a80f1782018dcef2520d2d", "price_changes": [{"asset_id": "15174546601205928046556699082541161461166100492124394241054975981067833950165", "price": "0.528", "size": "5", "side": "BUY", "hash": "94d6265f7600d2bbc0b550906198e9936be31f05", "best_bid": "0.998", "best_ask": "0.999"}, {"asset_id": "5430476248758985969939507303101680818848966275102949447275298704026336588828", "price": "0.472", "size": "5", "side": "SELL", "hash": "7ffefa16e090bb69ed017bba81a44dd5c0a750e4", "best_bid": "0.001", "best_ask": "0.002"}], "timestamp": "1769384285678", "event_type": "price_change"}}
{"_local_timestamp": "2026-01-25T23:38:06.322643+00:00", "data": {"market": "0x5999cfd552cbcf89bbd54c0e48b08c74182caefb18a80f1782018dcef2520d2d", "price_changes": [{"asset_id": "15174546601205928046556699082541161461166100492124394241054975981067833950165", "price": "0.528", "size": "0", "side": "BUY", "hash": "fb3eae7c4fcd618aecdd2fe3d925f67ed052d594", "best_bid": "0.998", "best_ask": "0.999"}, {"asset_id": "5430476248758985969939507303101680818848966275102949447275298704026336588828", "price": "0.472", "size": "0", "side": "SELL", "hash": "6c0ec26fd9c51e65cffbe67010fe7b0fb1713ddd", "best_bid": "0.001", "best_ask": "0.002"}], "timestamp": "1769384286246", "event_type": "price_change"}}
{"_local_timestamp": "2026-01-25T23:38:06.859125+00:00", "data": {"market": "0x5999cfd552cbcf89bbd54c0e48b08c74182caefb18a80f1782018dcef2520d2d", "price_changes": [{"asset_id": "15174546601205928046556699082541161461166100492124394241054975981067833950165", "price": "0.528", "size": "5", "side": "BUY", "hash": "0bfbdada3cd7886c8b004baf747b8f503affebeb", "best_bid": "0.998", "best_ask": "0.999"}, {"asset_id": "5430476248758985969939507303101680818848966275102949447275298704026336588828", "price": "0.472", "size": "5", "side": "SELL", "hash": "180c8447c59d0638a8e374669763524d0f2ee251", "best_bid": "0.001", "best_ask": "0.002"}], "timestamp": "1769384286778", "event_type": "price_change"}}
{"_local_timestamp": "2026-01-25T23:38:08.273218+00:00", "data": {"market": "0x5999cfd552cbcf89bbd54c0e48b08c74182caefb18a80f1782018dcef2520d2d", "price_changes": [{"asset_id": "15174546601205928046556699082541161461166100492124394241054975981067833950165", "price": "0.528", "size": "0", "side": "BUY", "hash": "0315003b815fea8d2172442b847c9725e62b09ef", "best_bid": "0.998", "best_ask": "0.999"}, {"asset_id": "5430476248758985969939507303101680818848966275102949447275298704026336588828", "price": "0.472", "size": "0", "side": "SELL", "hash": "95ce25e27bf3ee85a59e4ef7b7b51f3a2e87580f", "best_bid": "0.001", "best_ask": "0.002"}], "timestamp": "1769384288201", "event_type": "price_change"}}
{"_local_timestamp": "2026-01-25T23:38:08.587112+00:00", "data": {"market": "0x5999cfd552cbcf89bbd54c0e48b08c74182caefb18a80f1782018dcef2520d2d", "price_changes": [{"asset_id": "15174546601205928046556699082541161461166100492124394241054975981067833950165", "price": "0.528", "size": "5", "side": "BUY", "hash": "0820bdf71d013b123246043fc69d44d1666aa16f", "best_bid": "0.998", "best_ask": "0.999"}, {"asset_id": "5430476248758985969939507303101680818848966275102949447275298704026336588828", "price": "0.472", "size": "5", "side": "SELL", "hash": "4577ff7fbb83c7648670aeb09e0712c616a94898", "best_bid": "0.001", "best_ask": "0.002"}], "timestamp": "1769384288497", "event_type": "price_change"}}
{"_local_timestamp": "2026-01-25T23:38:10.046140+00:00", "data": {"market": "0x5999cfd552cbcf89bbd54c0e48b08c74182caefb18a80f1782018dcef2520d2d", "price_changes": [{"asset_id": "15174546601205928046556699082541161461166100492124394241054975981067833950165", "price": "0.528", "size": "0", "side": "BUY", "hash": "9fd04384c4aa35d48f971f4c52a4d6d04ab975cd", "best_bid": "0.998", "best_ask": "0.999"}, {"asset_id": "5430476248758985969939507303101680818848966275102949447275298704026336588828", "price": "0.472", "size": "0", "side": "SELL", "hash": "cbe2bfb0878acf8eb8f3dd67f5c3ed01ceb4a51d", "best_bid": "0.001", "best_ask": "0.002"}], "timestamp": "1769384289902", "event_type": "price_change"}}
{"_local_timestamp": "2026-01-25T23:38:10.435128+00:00", "data": {"market": "0x5999cfd552cbcf89bbd54c0e48b08c74182caefb18a80f1782018dcef2520d2d", "price_changes": [{"asset_id": "15174546601205928046556699082541161461166100492124394241054975981067833950165", "price": "0.528", "size": "5", "side": "BUY", "hash": "514e3b9ac797be7d10adfbd1d68dac2fdb390606", "best_bid": "0.998", "best_ask": "0.999"}, {"asset_id": "5430476248758985969939507303101680818848966275102949447275298704026336588828", "price": "0.472", "size": "5", "side": "SELL", "hash": "bb3604c01ef18b0679aeabd349024363c86fa403", "best_bid": "0.001", "best_ask": "0.002"}], "timestamp": "1769384290299", "event_type": "price_change"}}
{"_local_timestamp": "2026-01-25T23:38:11.586555+00:00", "data": {"market": "0x5999cfd552cbcf89bbd54c0e48b08c74182caefb18a80f1782018dcef2520d2d", "price_changes": [{"asset_id": "15174546601205928046556699082541161461166100492124394241054975981067833950165", "price": "0.528", "size": "0", "side": "BUY", "hash": "417842522a06245a3b7d6536c64546664cf68cb7", "best_bid": "0.998", "best_ask": "0.999"}, {"asset_id": "5430476248758985969939507303101680818848966275102949447275298704026336588828", "price": "0.472", "size": "0", "side": "SELL", "hash": "acb78cb38ee5e0cfdf433373089d626c229e8884", "best_bid": "0.001", "best_ask": "0.002"}], "timestamp": "1769384291505", "event_type": "price_change"}}
{"_local_timestamp": "2026-01-25T23:38:12.043038+00:00", "data": {"market": "0x5999cfd552cbcf89bbd54c0e48b08c74182caefb18a80f1782018dcef2520d2d", "price_changes": [{"asset_id": "15174546601205928046556699082541161461166100492124394241054975981067833950165", "price": "0.528", "size": "5", "side": "BUY", "hash": "becc96d7b7e6d1965f2e1dfdc75f457c0d1eb561", "best_bid": "0.998", "best_ask": "0.999"}, {"asset_id": "5430476248758985969939507303101680818848966275102949447275298704026336588828", "price": "0.472", "size": "5", "side": "SELL", "hash": "593328325c57ebb408af0705a96542a4366f34ac", "best_bid": "0.001", "best_ask": "0.002"}], "timestamp": "1769384291956", "event_type": "price_change"}}
{"_local_timestamp": "2026-01-25T23:38:12.605881+00:00", "data": {"market": "0x5999cfd552cbcf89bbd54c0e48b08c74182caefb18a80f1782018dcef2520d2d", "price_changes": [{"asset_id": "15174546601205928046556699082541161461166100492124394241054975981067833950165", "price": "0.528", "size": "0", "side": "BUY", "hash": "45f7c4b652cfab578b2eed953413cbcc42ec5991", "best_bid": "0.998", "best_ask": "0.999"}, {"asset_id": "5430476248758985969939507303101680818848966275102949447275298704026336588828", "price": "0.472", "size": "0", "side": "SELL", "hash": "790e84d6e99c07449242102b1365bdc1dbb7f328", "best_bid": "0.001", "best_ask": "0.002"}], "timestamp": "1769384292532", "event_type": "price_change"}}
{"_local_timestamp": "2026-01-25T23:38:13.110009+00:00", "data": {"market": "0x5999cfd552cbcf89bbd54c0e48b08c74182caefb18a80f1782018dcef2520d2d", "price_changes": [{"asset_id": "15174546601205928046556699082541161461166100492124394241054975981067833950165", "price": "0.528", "size": "5", "side": "BUY", "hash": "6aa48d6e8976ad4043b79abed50f141753124b71", "best_bid": "0.998", "best_ask": "0.999"}, {"asset_id": "5430476248758985969939507303101680818848966275102949447275298704026336588828", "price": "0.472", "size": "5", "side": "SELL", "hash": "a9eb60a4ce796b1f050a632345ef42c0513bdcda", "best_bid": "0.001", "best_ask": "0.002"}], "timestamp": "1769384293007", "event_type": "price_change"}}
{"_local_timestamp": "2026-01-25T23:38:14.532892+00:00", "data": {"market": "0x5999cfd552cbcf89bbd54c0e48b08c74182caefb18a80f1782018dcef2520d2d", "price_changes": [{"asset_id": "15174546601205928046556699082541161461166100492124394241054975981067833950165", "price": "0.528", "size": "0", "side": "BUY", "hash": "43b90eb8a5d9b49f3ba1c33fee2ec099f3114ae8", "best_bid": "0.998", "best_ask": "0.999"}, {"asset_id": "5430476248758985969939507303101680818848966275102949447275298704026336588828", "price": "0.472", "size": "0", "side": "SELL", "hash": "d7aa1bbfed943b62bb3560dc2af2181aab984dc3", "best_bid": "0.001", "best_ask": "0.002"}], "timestamp": "1769384294464", "event_type": "price_change"}}
{"_local_timestamp": "2026-01-25T23:38:14.828831+00:00", "data": {"market": "0x5999cfd552cbcf89bbd54c0e48b08c74182caefb18a80f1782018dcef2520d2d", "price_changes": [{"asset_id": "15174546601205928046556699082541161461166100492124394241054975981067833950165", "price": "0.528", "size": "5", "side": "BUY", "hash": "fcb1594d90d2d4aff409fbfbc43b49178dcec597", "best_bid": "0.998", "best_ask": "0.999"}, {"asset_id": "5430476248758985969939507303101680818848966275102949447275298704026336588828", "price": "0.472", "size": "5", "side": "SELL", "hash": "2b254fd7ca6aee017dcc891aa7f8194fadaaae28", "best_bid": "0.001", "best_ask": "0.002"}], "timestamp": "1769384294757", "event_type": "price_change"}}
{"_local_timestamp": "2026-01-25T23:38:15.844484+00:00", "data": {"market": "0x5999cfd552cbcf89bbd54c0e48b08c74182caefb18a80f1782018dcef2520d2d", "price_changes": [{"asset_id": "15174546601205928046556699082541161461166100492124394241054975981067833950165", "price": "0.528", "size": "0", "side": "BUY", "hash": "16ba02b3fe3ea8420dde9687b623ef779e0ed5d3", "best_bid": "0.998", "best_ask": "0.999"}, {"asset_id": "5430476248758985969939507303101680818848966275102949447275298704026336588828", "price": "0.472", "size": "0", "side": "SELL", "hash": "d17e6d514c34648ba14a95c167f98bc829992c1e", "best_bid": "0.001", "best_ask": "0.002"}], "timestamp": "1769384295774", "event_type": "price_change"}}
{"_local_timestamp": "2026-01-25T23:38:16.292625+00:00", "data": {"market": "0x5999cfd552cbcf89bbd54c0e48b08c74182caefb18a80f1782018dcef2520d2d", "price_changes": [{"asset_id": "15174546601205928046556699082541161461166100492124394241054975981067833950165", "price": "0.528", "size": "5", "side": "BUY", "hash": "f45c4d4c51d9d45b11d186e49b3325ac2090f483", "best_bid": "0.998", "best_ask": "0.999"}, {"asset_id": "5430476248758985969939507303101680818848966275102949447275298704026336588828", "price": "0.472", "size": "5", "side": "SELL", "hash": "3b01b0128300382c93bb87c9044d9664b6bc7a4d", "best_bid": "0.001", "best_ask": "0.002"}], "timestamp": "1769384296222", "event_type": "price_change"}}
{"_local_timestamp": "2026-01-25T23:38:17.168748+00:00", "data": {"market": "0x5999cfd552cbcf89bbd54c0e48b08c74182caefb18a80f1782018dcef2520d2d", "price_changes": [{"asset_id": "15174546601205928046556699082541161461166100492124394241054975981067833950165", "price": "0.528", "size": "0", "side": "BUY", "hash": "0e8c1b4d4fd3c45ce45e99b42697affccd8c5418", "best_bid": "0.998", "best_ask": "0.999"}, {"asset_id": "5430476248758985969939507303101680818848966275102949447275298704026336588828", "price": "0.472", "size": "0", "side": "SELL", "hash": "e64098f5c0d47e90c1b710738748c62d70e0d335", "best_bid": "0.001", "best_ask": "0.002"}], "timestamp": "1769384297073", "event_type": "price_change"}}
{"_local_timestamp": "2026-01-25T23:38:17.397541+00:00", "data": {"market": "0x5999cfd552cbcf89bbd54c0e48b08c74182caefb18a80f1782018dcef2520d2d", "price_changes": [{"asset_id": "15174546601205928046556699082541161461166100492124394241054975981067833950165", "price": "0.528", "size": "5", "side": "BUY", "hash": "7470068daac6bd416abf1e1d175361e431a19a02", "best_bid": "0.998", "best_ask": "0.999"}, {"asset_id": "5430476248758985969939507303101680818848966275102949447275298704026336588828", "price": "0.472", "size": "5", "side": "SELL", "hash": "9be14e9d4bf3adbda474d3bf455243380f66fad5", "best_bid": "0.001", "best_ask": "0.002"}], "timestamp": "1769384297319", "event_type": "price_change"}}
{"_local_timestamp": "2026-01-25T23:38:18.439449+00:00", "data": {"market": "0x5999cfd552cbcf89bbd54c0e48b08c74182caefb18a80f1782018dcef2520d2d", "price_changes": [{"asset_id": "15174546601205928046556699082541161461166100492124394241054975981067833950165", "price": "0.528", "size": "0", "side": "BUY", "hash": "13d3786314aa6c5560b6fe4a1aeda54a5c2a5b13", "best_bid": "0.998", "best_ask": "0.999"}, {"asset_id": "5430476248758985969939507303101680818848966275102949447275298704026336588828", "price": "0.472", "size": "0", "side": "SELL", "hash": "9b3d0337763da29393598f0208a5e26e03f0b842", "best_bid": "0.001", "best_ask": "0.002"}], "timestamp": "1769384298368", "event_type": "price_change"}}
{"_local_timestamp": "2026-01-25T23:38:18.860339+00:00", "data": {"market": "0x5999cfd552cbcf89bbd54c0e48b08c74182caefb18a80f1782018dcef2520d2d", "price_changes": [{"asset_id": "15174546601205928046556699082541161461166100492124394241054975981067833950165", "price": "0.528", "size": "5", "side": "BUY", "hash": "f91b1492b6601909575c315570b27de5c390aa2d", "best_bid": "0.998", "best_ask": "0.999"}, {"asset_id": "5430476248758985969939507303101680818848966275102949447275298704026336588828", "price": "0.472", "size": "5", "side": "SELL", "hash": "dc53062d090859b41ad4db9e2d7ea601e58ccedc", "best_bid": "0.001", "best_ask": "0.002"}], "timestamp": "1769384298777", "event_type": "price_change"}}
{"_local_timestamp": "2026-01-25T23:38:19.791205+00:00", "data": {"market": "0x5999cfd552cbcf89bbd54c0e48b08c74182caefb18a80f1782018dcef2520d2d", "price_changes": [{"asset_id": "15174546601205928046556699082541161461166100492124394241054975981067833950165", "price": "0.528", "size": "0", "side": "BUY", "hash": "307974d357a357378f9e1f1d674c033ef2b686a7", "best_bid": "0.998", "best_ask": "0.999"}, {"asset_id": "5430476248758985969939507303101680818848966275102949447275298704026336588828", "price": "0.472", "size": "0", "side": "SELL", "hash": "fa3a2f166743243954a9818e7bfae9b4552f3995", "best_bid": "0.001", "best_ask": "0.002"}], "timestamp": "1769384299717", "event_type": "price_change"}}
{"_local_timestamp": "2026-01-25T23:38:20.169102+00:00", "data": {"market": "0x5999cfd552cbcf89bbd54c0e48b08c74182caefb18a80f1782018dcef2520d2d", "price_changes": [{"asset_id": "15174546601205928046556699082541161461166100492124394241054975981067833950165", "price": "0.528", "size": "5", "side": "BUY", "hash": "33d24485cc15e9721343160abd3c2136403ef1c5", "best_bid": "0.998", "best_ask": "0.999"}, {"asset_id": "5430476248758985969939507303101680818848966275102949447275298704026336588828", "price": "0.472", "size": "5", "side": "SELL", "hash": "a4c20e3ba2026707c6e381526848ca6276e6ccd0", "best_bid": "0.001", "best_ask": "0.002"}], "timestamp": "1769384300096", "event_type": "price_change"}}
{"_local_timestamp": "2026-01-25T23:38:21.557221+00:00", "data": {"market": "0x5999cfd552cbcf89bbd54c0e48b08c74182caefb18a80f1782018dcef2520d2d", "price_changes": [{"asset_id": "15174546601205928046556699082541161461166100492124394241054975981067833950165", "price": "0.528", "size": "0", "side": "BUY", "hash": "0ce7c18d06a7f086c09bafab6faf2ba3d1bb9d9e", "best_bid": "0.998", "best_ask": "0.999"}, {"asset_id": "5430476248758985969939507303101680818848966275102949447275298704026336588828", "price": "0.472", "size": "0", "side": "SELL", "hash": "146bbce56e551ea09627f6e603973e58f4c7bcce", "best_bid": "0.001", "best_ask": "0.002"}], "timestamp": "1769384301469", "event_type": "price_change"}}
{"_local_timestamp": "2026-01-25T23:38:21.949947+00:00", "data": {"market": "0x5999cfd552cbcf89bbd54c0e48b08c74182caefb18a80f1782018dcef2520d2d", "price_changes": [{"asset_id": "15174546601205928046556699082541161461166100492124394241054975981067833950165", "price": "0.528", "size": "5", "side": "BUY", "hash": "e79a93f115e320c210943843299bb0f0a3e165d2", "best_bid": "0.998", "best_ask": "0.999"}, {"asset_id": "5430476248758985969939507303101680818848966275102949447275298704026336588828", "price": "0.472", "size": "5", "side": "SELL", "hash": "523b479b9320e19310edabb3d62616ea52bc2fc2", "best_bid": "0.001", "best_ask": "0.002"}], "timestamp": "1769384301877", "event_type": "price_change"}}
{"_local_timestamp": "2026-01-25T23:38:23.169412+00:00", "data": {"market": "0x5999cfd552cbcf89bbd54c0e48b08c74182caefb18a80f1782018dcef2520d2d", "price_changes": [{"asset_id": "15174546601205928046556699082541161461166100492124394241054975981067833950165", "price": "0.528", "size": "0", "side": "BUY", "hash": "62767d5fcc8250e54036a6b3754bbb54144e68e0", "best_bid": "0.998", "best_ask": "0.999"}, {"asset_id": "5430476248758985969939507303101680818848966275102949447275298704026336588828", "price": "0.472", "size": "0", "side": "SELL", "hash": "21625f69a5d9425bc246e8260a46b85248f5f9d6", "best_bid": "0.001", "best_ask": "0.002"}], "timestamp": "1769384303091", "event_type": "price_change"}}
{"_local_timestamp": "2026-01-25T23:38:23.647173+00:00", "data": {"market": "0x5999cfd552cbcf89bbd54c0e48b08c74182caefb18a80f1782018dcef2520d2d", "price_changes": [{"asset_id": "15174546601205928046556699082541161461166100492124394241054975981067833950165", "price": "0.528", "size": "5", "side": "BUY", "hash": "f194bd8639f17a04e1c10aadaf1ffaf600c0ad21", "best_bid": "0.998", "best_ask": "0.999"}, {"asset_id": "5430476248758985969939507303101680818848966275102949447275298704026336588828", "price": "0.472", "size": "5", "side": "SELL", "hash": "effbf697ba9fa429f39667128eae0f7386e80b30", "best_bid": "0.001", "best_ask": "0.002"}], "timestamp": "1769384303578", "event_type": "price_change"}}
{"_local_timestamp": "2026-01-25T23:38:24.348010+00:00", "data": {"market": "0x5999cfd552cbcf89bbd54c0e48b08c74182caefb18a80f1782018dcef2520d2d", "price_changes": [{"asset_id": "15174546601205928046556699082541161461166100492124394241054975981067833950165", "price": "0.528", "size": "0", "side": "BUY", "hash": "83ca0bec7c3f52792179e8e24c7cb83413f2b0f5", "best_bid": "0.998", "best_ask": "0.999"}, {"asset_id": "5430476248758985969939507303101680818848966275102949447275298704026336588828", "price": "0.472", "size": "0", "side": "SELL", "hash": "81216d867631969d6d41d3187dcb73f95f5e29c0", "best_bid": "0.001", "best_ask": "0.002"}], "timestamp": "1769384304271", "event_type": "price_change"}}
{"_local_timestamp": "2026-01-25T23:38:24.663731+00:00", "data": {"market": "0x5999cfd552cbcf89bbd54c0e48b08c74182caefb18a80f1782018dcef2520d2d", "price_changes": [{"asset_id": "15174546601205928046556699082541161461166100492124394241054975981067833950165", "price": "0.528", "size": "5", "side": "BUY", "hash": "64ae117ab8651da7d565b7a3d3b31140f6281391", "best_bid": "0.998", "best_ask": "0.999"}, {"asset_id": "5430476248758985969939507303101680818848966275102949447275298704026336588828", "price": "0.472", "size": "5", "side": "SELL", "hash": "e78b15d48e17b09950e181baebaf0ea63d0c26ae", "best_bid": "0.001", "best_ask": "0.002"}], "timestamp": "1769384304592", "event_type": "price_change"}}
{"_local_timestamp": "2026-01-25T23:38:24.829319+00:00", "data": {"market": "0x0fc1398bb3cff37d77101392989d6ff065d28d7c0dc50b282bd1b5098b9d78b8", "price_changes": [{"asset_id": "89336264239989122383122704165255872699177887882264330841492281051298522223986", "price": "0.415", "size": "0", "side": "BUY", "hash": "f934033f222cb468976b8b597e28b410bddb5dc1", "best_bid": "0.89", "best_ask": "0.934"}, {"asset_id": "76309699246141587406891686852898742630368640356883728029522206362139036530694", "price": "0.585", "size": "0", "side": "SELL", "hash": "0185ad4b4857883789ff8d89b8df72ef0a7af050", "best_bid": "0.066", "best_ask": "0.11"}], "timestamp": "1769384304752", "event_type": "price_change"}}
{"_local_timestamp": "2026-01-25T23:38:24.830518+00:00", "data": {"market": "0xbf593af69b62768d353e7c7226255c51ed19ca32c84a54c0d49a85553b42a46d", "price_changes": [{"asset_id": "24341167601280829695615199444200891915914435646386891986504787893119831754606", "price": "0.448", "size": "0", "side": "BUY", "hash": "e1c835259bbf434ac1b846eaca372babe8f50d70", "best_bid": "0.996", "best_ask": "0.999"}, {"asset_id": "2688038676615161490720640654323264340577430230677806835743854904343477854167", "price": "0.552", "size": "0", "side": "SELL", "hash": "b662813c560e5508cab9930fd3d9362cfaa863ad", "best_bid": "0.001", "best_ask": "0.004"}], "timestamp": "1769384304752", "event_type": "price_change"}}
{"_local_timestamp": "2026-01-25T23:38:24.967562+00:00", "data": {"market": "0x0fc1398bb3cff37d77101392989d6ff065d28d7c0dc50b282bd1b5098b9d78b8", "price_changes": [{"asset_id": "89336264239989122383122704165255872699177887882264330841492281051298522223986", "price": "0.417", "size": "244", "side": "BUY", "hash": "d3688fa7428488707aac18d598dff369008457a1", "best_bid": "0.89", "best_ask": "0.934"}, {"asset_id": "76309699246141587406891686852898742630368640356883728029522206362139036530694", "price": "0.583", "size": "244", "side": "SELL", "hash": "2a18e66ede8e26016d27638005de79d1fd1711d1", "best_bid": "0.066", "best_ask": "0.11"}], "timestamp": "1769384304890", "event_type": "price_change"}}
{"_local_timestamp": "2026-01-25T23:38:24.967897+00:00", "data": {"market": "0x0fc1398bb3cff37d77101392989d6ff065d28d7c0dc50b282bd1b5098b9d78b8", "price_changes": [{"asset_id": "89336264239989122383122704165255872699177887882264330841492281051298522223986", "price": "0.417", "size": "254", "side": "BUY", "hash": "b1488c939c42914a1cb330a1fb6368af040da1ab", "best_bid": "0.89", "best_ask": "0.934"}, {"asset_id": "76309699246141587406891686852898742630368640356883728029522206362139036530694", "price": "0.583", "size": "254", "side": "SELL", "hash": "c77dac58b6dcb1cac0835a732f27f52c49a50854", "best_bid": "0.066", "best_ask": "0.11"}], "timestamp": "1769384304891", "event_type": "price_change"}}
{"_local_timestamp": "2026-01-25T23:38:25.269145+00:00", "data": {"market": "0xbf593af69b62768d353e7c7226255c51ed19ca32c84a54c0d49a85553b42a46d", "price_changes": [{"asset_id": "24341167601280829695615199444200891915914435646386891986504787893119831754606", "price": "0.448", "size": "10", "side": "BUY", "hash": "ee2eca827350c60f2d8a5156c8e2b90d790a5369", "best_bid": "0.996", "best_ask": "0.999"}, {"asset_id": "2688038676615161490720640654323264340577430230677806835743854904343477854167", "price": "0.552", "size": "10", "side": "SELL", "hash": "ee33c2656701407d290da99d07df7962d03eb3bc", "best_bid": "0.001", "best_ask": "0.004"}], "timestamp": "1769384305188", "event_type": "price_change"}}
{"_local_timestamp": "2026-01-25T23:38:25.269774+00:00", "data": {"market": "0xbf593af69b62768d353e7c7226255c51ed19ca32c84a54c0d49a85553b42a46d", "price_changes": [{"asset_id": "24341167601280829695615199444200891915914435646386891986504787893119831754606", "price": "0.448", "size": "68", "side": "BUY", "hash": "8b1f052c18bba6f4b8dad058f32d89ace8b40c6f", "best_bid": "0.996", "best_ask": "0.999"}, {"asset_id": "2688038676615161490720640654323264340577430230677806835743854904343477854167", "price": "0.552", "size": "68", "side": "SELL", "hash": "558b5fcd0a9772c50f1d7e64aee6c3fe7738159f", "best_bid": "0.001", "best_ask": "0.004"}], "timestamp": "1769384305189", "event_type": "price_change"}}
{"_local_timestamp": "2026-01-25T23:38:25.677990+00:00", "data": {"market": "0x2b88daef17413d970ccfcd80042243e08c49d257b9ce916124be0c45cefa3700", "price_changes": [{"asset_id": "52524163922571923183266519099402467935730326233022494206279867476007301859150", "price": "0.48", "size": "0", "side": "BUY", "hash": "878266006a0e7444fa90ac2e59ff7edc2c369a65", "best_bid": "0.9", "best_ask": "0.92"}, {"asset_id": "79155825810081376702240953828322969529947608905353673983878554604270354457205", "price": "0.52", "size": "0", "side": "SELL", "hash": "5a3fdd32ca4246021bbb8bf4574e79650bfcacd1", "best_bid": "0.08", "best_ask": "0.1"}], "timestamp": "1769384305601", "event_type": "price_change"}}
{"_local_timestamp": "2026-01-25T23:38:25.844233+00:00", "data": {"market": "0x5999cfd552cbcf89bbd54c0e48b08c74182caefb18a80f1782018dcef2520d2d", "price_changes": [{"asset_id": "15174546601205928046556699082541161461166100492124394241054975981067833950165", "price": "0.528", "size": "0", "side": "BUY", "hash": "eb656d5842c6be68d718b6fc12f3e0f3797adb35", "best_bid": "0.998", "best_ask": "0.999"}, {"asset_id": "5430476248758985969939507303101680818848966275102949447275298704026336588828", "price": "0.472", "size": "0", "side": "SELL", "hash": "cb1baab0158394063601a1167a6e35ed2e9dbb88", "best_bid": "0.001", "best_ask": "0.002"}], "timestamp": "1769384305767", "event_type": "price_change"}}
{"_local_timestamp": "2026-01-25T23:38:26.041057+00:00", "data": {"market": "0x2b88daef17413d970ccfcd80042243e08c49d257b9ce916124be0c45cefa3700", "price_changes": [{"asset_id": "52524163922571923183266519099402467935730326233022494206279867476007301859150", "price": "0.5", "size": "10", "side": "BUY", "hash": "3cbbaf912bb7690d008ae99fa32c9294b67d3926", "best_bid": "0.9", "best_ask": "0.92"}, {"asset_id": "79155825810081376702240953828322969529947608905353673983878554604270354457205", "price": "0.5", "size": "10", "side": "SELL", "hash": "bca7a9ba5bc42d104b81f54bd89444d5999fc35d", "best_bid": "0.08", "best_ask": "0.1"}], "timestamp": "1769384305962", "event_type": "price_change"}}
{"_local_timestamp": "2026-01-25T23:38:26.238926+00:00", "data": {"market": "0x5999cfd552cbcf89bbd54c0e48b08c74182caefb18a80f1782018dcef2520d2d", "price_changes": [{"asset_id": "15174546601205928046556699082541161461166100492124394241054975981067833950165", "price": "0.528", "size": "5", "side": "BUY", "hash": "97b30216a315f01aa130eab51737d69a3f3202e4", "best_bid": "0.998", "best_ask": "0.999"}, {"asset_id": "5430476248758985969939507303101680818848966275102949447275298704026336588828", "price": "0.472", "size": "5", "side": "SELL", "hash": "b6bc7f4e6dcdc1dfc52e8302fefa561ceee0fde1", "best_bid": "0.001", "best_ask": "0.002"}], "timestamp": "1769384306164", "event_type": "price_change"}}
{"_local_timestamp": "2026-01-25T23:38:26.276114+00:00", "data": {"market": "0x2b88daef17413d970ccfcd80042243e08c49d257b9ce916124be0c45cefa3700", "price_changes": [{"asset_id": "52524163922571923183266519099402467935730326233022494206279867476007301859150", "price": "0.49", "size": "0", "side": "BUY", "hash": "41a27ca2a6ac5bdd91a76357b0a39437b93af3cf", "best_bid": "0.9", "best_ask": "0.92"}, {"asset_id": "79155825810081376702240953828322969529947608905353673983878554604270354457205", "price": "0.51", "size": "0", "side": "SELL", "hash": "e6843a044cffb15aa533d7c4976b939ddc1a1790", "best_bid": "0.08", "best_ask": "0.1"}], "timestamp": "1769384306204", "event_type": "price_change"}}
{"_local_timestamp": "2026-01-25T23:38:26.303587+00:00", "data": {"market": "0x2b88daef17413d970ccfcd80042243e08c49d257b9ce916124be0c45cefa3700", "price_changes": [{"asset_id": "52524163922571923183266519099402467935730326233022494206279867476007301859150", "price": "0.47", "size": "25", "side": "BUY", "hash": "11defce387f6657bc6007bdd45b1c7bb16ced971", "best_bid": "0.9", "best_ask": "0.92"}, {"asset_id": "79155825810081376702240953828322969529947608905353673983878554604270354457205", "price": "0.53", "size": "25", "side": "SELL", "hash": "44348dad726daee4842386581c2c09a878c672fd", "best_bid": "0.08", "best_ask": "0.1"}], "timestamp": "1769384306233", "event_type": "price_change"}}
{"_local_timestamp": "2026-01-25T23:38:26.701359+00:00", "data": {"market": "0x5999cfd552cbcf89bbd54c0e48b08c74182caefb18a80f1782018dcef2520d2d", "price_changes": [{"asset_id": "15174546601205928046556699082541161461166100492124394241054975981067833950165", "price": "0.528", "size": "0", "side": "BUY", "hash": "1227eb7645911c47cbcd9f683c6e67ab1ce3497d", "best_bid": "0.998", "best_ask": "0.999"}, {"asset_id": "5430476248758985969939507303101680818848966275102949447275298704026336588828", "price": "0.472", "size": "0", "side": "SELL", "hash": "7820159de45a26df28ac6372c7e0452e67ea4b38", "best_bid": "0.001", "best_ask": "0.002"}], "timestamp": "1769384306629", "event_type": "price_change"}}
{"_local_timestamp": "2026-01-25T23:38:26.753156+00:00", "data": {"market": "0x2b88daef17413d970ccfcd80042243e08c49d257b9ce916124be0c45cefa3700", "price_changes": [{"asset_id": "52524163922571923183266519099402467935730326233022494206279867476007301859150", "price": "0.47", "size": "5", "side": "BUY", "hash": "7d0cc80222695fa11fe317568d713018ffb9e9f0", "best_bid": "0.9", "best_ask": "0.92"}, {"asset_id": "79155825810081376702240953828322969529947608905353673983878554604270354457205", "price": "0.53", "size": "5", "side": "SELL", "hash": "2402f7e1b84ecfc2b1ecc10d57193a3675c356eb", "best_bid": "0.08", "best_ask": "0.1"}], "timestamp": "1769384306683", "event_type": "price_change"}}
{"_local_timestamp": "2026-01-25T23:38:26.787930+00:00", "data": {"market": "0x2b88daef17413d970ccfcd80042243e08c49d257b9ce916124be0c45cefa3700", "price_changes": [{"asset_id": "52524163922571923183266519099402467935730326233022494206279867476007301859150", "price": "0.51", "size": "20", "side": "BUY", "hash": "da095eb32e0aa1367bd4f52a7a4dd5df4caa0c9a", "best_bid": "0.9", "best_ask": "0.92"}, {"asset_id": "79155825810081376702240953828322969529947608905353673983878554604270354457205", "price": "0.49", "size": "20", "side": "SELL", "hash": "af18a4dda7dfef7041a955f04279e32d8c26f33e", "best_bid": "0.08", "best_ask": "0.1"}], "timestamp": "1769384306715", "event_type": "price_change"}}
{"_local_timestamp": "2026-01-25T23:38:27.128497+00:00", "data": {"market": "0x5999cfd552cbcf89bbd54c0e48b08c74182caefb18a80f1782018dcef2520d2d", "price_changes": [{"asset_id": "15174546601205928046556699082541161461166100492124394241054975981067833950165", "price": "0.528", "size": "5", "side": "BUY", "hash": "54c47d96f3764a047e4c1f940c9c526cce3f8410", "best_bid": "0.998", "best_ask": "0.999"}, {"asset_id": "5430476248758985969939507303101680818848966275102949447275298704026336588828", "price": "0.472", "size": "5", "side": "SELL", "hash": "b47532861581c2610a7ed4a21d72d2927b88a189", "best_bid": "0.001", "best_ask": "0.002"}], "timestamp": "1769384307034", "event_type": "price_change"}}
{"_local_timestamp": "2026-01-25T23:38:27.184654+00:00", "data": {"market": "0xc2ac7ebd46fa81ad41a5072a14a2a77c362d18744596848500541c4406051068", "price_changes": [{"asset_id": "82937290481922399100659521402638226726618911184164616630445131262753902545289", "price": "0.79", "size": "114.76", "side": "BUY", "hash": "4112db74c53e6de29465603f905b9ce0fe73eaa9", "best_bid": "0.79", "best_ask": "0.89"}, {"asset_id": "36008003405201249169700080930810811641068357582790575985437372346931394635255", "price": "0.21", "size": "114.76", "side": "SELL", "hash": "9fbbb1a0078e3b57eff9f879e409e2455673518e", "best_bid": "0.11", "best_ask": "0.21"}], "timestamp": "1769384307104", "event_type": "price_change"}}
{"_local_timestamp": "2026-01-25T23:38:28.442873+00:00", "data": {"market": "0x5999cfd552cbcf89bbd54c0e48b08c74182caefb18a80f1782018dcef2520d2d", "price_changes": [{"asset_id": "15174546601205928046556699082541161461166100492124394241054975981067833950165", "price": "0.528", "size": "0", "side": "BUY", "hash": "9246ec440fee1a4dd47bf45cfe622b69a4358979", "best_bid": "0.998", "best_ask": "0.999"}, {"asset_id": "5430476248758985969939507303101680818848966275102949447275298704026336588828", "price": "0.472", "size": "0", "side": "SELL", "hash": "2c2b7af30b8071aa36a23e7ef6cdf01ca9e14144", "best_bid": "0.001", "best_ask": "0.002"}], "timestamp": "1769384308371", "event_type": "price_change"}}
{"_local_timestamp": "2026-01-25T23:38:28.724881+00:00", "data": {"market": "0x5999cfd552cbcf89bbd54c0e48b08c74182caefb18a80f1782018dcef2520d2d", "price_changes": [{"asset_id": "15174546601205928046556699082541161461166100492124394241054975981067833950165", "price": "0.528", "size": "5", "side": "BUY", "hash": "df921b162c939d26cab2d356f58d9617910e4d00", "best_bid": "0.998", "best_ask": "0.999"}, {"asset_id": "5430476248758985969939507303101680818848966275102949447275298704026336588828", "price": "0.472", "size": "5", "side": "SELL", "hash": "6e6eccf52b10ab86f86828e57ef305feef875c26", "best_bid": "0.001", "best_ask": "0.002"}], "timestamp": "1769384308656", "event_type": "price_change"}}
{"_local_timestamp": "2026-01-25T23:38:29.309594+00:00", "data": {"market": "0x5999cfd552cbcf89bbd54c0e48b08c74182caefb18a80f1782018dcef2520d2d", "price_changes": [{"asset_id": "15174546601205928046556699082541161461166100492124394241054975981067833950165", "price": "0.528", "size": "0", "side": "BUY", "hash": "bcffb0da7b5d0e45b06f81525c441bd1e9aec022", "best_bid": "0.998", "best_ask": "0.999"}, {"asset_id": "5430476248758985969939507303101680818848966275102949447275298704026336588828", "price": "0.472", "size": "0", "side": "SELL", "hash": "e68a6237fcabae72ef1a4e9d8666157478384580", "best_bid": "0.001", "best_ask": "0.002"}], "timestamp": "1769384309232", "event_type": "price_change"}}
{"_local_timestamp": "2026-01-25T23:38:29.741934+00:00", "data": {"market": "0x5999cfd552cbcf89bbd54c0e48b08c74182caefb18a80f1782018dcef2520d2d", "price_changes": [{"asset_id": "15174546601205928046556699082541161461166100492124394241054975981067833950165", "price": "0.528", "size": "5", "side": "BUY", "hash": "3ca95cf742a1b66a9540af8ff26ed462ff5d388b", "best_bid": "0.998", "best_ask": "0.999"}, {"asset_id": "5430476248758985969939507303101680818848966275102949447275298704026336588828", "price": "0.472", "size": "5", "side": "SELL", "hash": "7d40c30787f805d4c5ed101171d1d410d860da12", "best_bid": "0.001", "best_ask": "0.002"}], "timestamp": "1769384309657", "event_type": "price_change"}}
{"_local_timestamp": "2026-01-25T23:38:30.667864+00:00", "data": {"market": "0x5999cfd552cbcf89bbd54c0e48b08c74182caefb18a80f1782018dcef2520d2d", "price_changes": [{"asset_id": "15174546601205928046556699082541161461166100492124394241054975981067833950165", "price": "0.528", "size": "0", "side": "BUY", "hash": "06513c1803ca7049d633ad670c2a0233f24d51cd", "best_bid": "0.998", "best_ask": "0.999"}, {"asset_id": "5430476248758985969939507303101680818848966275102949447275298704026336588828", "price": "0.472", "size": "0", "side": "SELL", "hash": "ad7609bffe34f9cf5427c12d86eced1a1b29f61f", "best_bid": "0.001", "best_ask": "0.002"}], "timestamp": "1769384310597", "event_type": "price_change"}}
{"_local_timestamp": "2026-01-25T23:38:30.936350+00:00", "data": {"market": "0x5999cfd552cbcf89bbd54c0e48b08c74182caefb18a80f1782018dcef2520d2d", "price_changes": [{"asset_id": "15174546601205928046556699082541161461166100492124394241054975981067833950165", "price": "0.528", "size": "5", "side": "BUY", "hash": "e67eed5d05b6d03f44b5f2ecdacb150c7010d5bb", "best_bid": "0.998", "best_ask": "0.999"}, {"asset_id": "5430476248758985969939507303101680818848966275102949447275298704026336588828", "price": "0.472", "size": "5", "side": "SELL", "hash": "9a3855ea180b1e48c43efefb326db62cb804b10b", "best_bid": "0.001", "best_ask": "0.002"}], "timestamp": "1769384310863", "event_type": "price_change"}}
{"_local_timestamp": "2026-01-25T23:38:31.553692+00:00", "data": {"market": "0x5999cfd552cbcf89bbd54c0e48b08c74182caefb18a80f1782018dcef2520d2d", "price_changes": [{"asset_id": "15174546601205928046556699082541161461166100492124394241054975981067833950165", "price": "0.528", "size": "0", "side": "BUY", "hash": "a34d8de384c89122bf0d6b1f13cb65a1a1fd67c7", "best_bid": "0.998", "best_ask": "0.999"}, {"asset_id": "5430476248758985969939507303101680818848966275102949447275298704026336588828", "price": "0.472", "size": "0", "side": "SELL", "hash": "8ab92c97f44a87efc9d61937cbc9fd4cd8afcfd6", "best_bid": "0.001", "best_ask": "0.002"}], "timestamp": "1769384311477", "event_type": "price_change"}}
{"_local_timestamp": "2026-01-25T23:38:31.859477+00:00", "data": {"market": "0x5999cfd552cbcf89bbd54c0e48b08c74182caefb18a80f1782018dcef2520d2d", "price_changes": [{"asset_id": "15174546601205928046556699082541161461166100492124394241054975981067833950165", "price": "0.528", "size": "5", "side": "BUY", "hash": "4f803aa5e9043005ea4bad826cebc03c5ecd823b", "best_bid": "0.998", "best_ask": "0.999"}, {"asset_id": "5430476248758985969939507303101680818848966275102949447275298704026336588828", "price": "0.472", "size": "5", "side": "SELL", "hash": "19c544cd9564a812f8dda50ccee519abfbdd0494", "best_bid": "0.001", "best_ask": "0.002"}], "timestamp": "1769384311791", "event_type": "price_change"}}
{"_local_timestamp": "2026-01-25T23:38:32.430844+00:00", "data": {"market": "0x5999cfd552cbcf89bbd54c0e48b08c74182caefb18a80f1782018dcef2520d2d", "price_changes": [{"asset_id": "15174546601205928046556699082541161461166100492124394241054975981067833950165", "price": "0.528", "size": "0", "side": "BUY", "hash": "081537cfc6a66787dfc7e88b9db89087a475f25d", "best_bid": "0.998", "best_ask": "0.999"}, {"asset_id": "5430476248758985969939507303101680818848966275102949447275298704026336588828", "price": "0.472", "size": "0", "side": "SELL", "hash": "0e4ca0da3272568d1266e9c3793a2cc1fadfb3fa", "best_bid": "0.001", "best_ask": "0.002"}], "timestamp": "1769384312350", "event_type": "price_change"}}
{"_local_timestamp": "2026-01-25T23:38:33.206539+00:00", "data": {"market": "0x5999cfd552cbcf89bbd54c0e48b08c74182caefb18a80f1782018dcef2520d2d", "price_changes": [{"asset_id": "15174546601205928046556699082541161461166100492124394241054975981067833950165", "price": "0.528", "size": "5", "side": "BUY", "hash": "91743c2781de8b64b57c59dfd06d8ac0b31e6894", "best_bid": "0.998", "best_ask": "0.999"}, {"asset_id": "5430476248758985969939507303101680818848966275102949447275298704026336588828", "price": "0.472", "size": "5", "side": "SELL", "hash": "3d84663d8d264a498d5c2cdf88a7f6d1a44f04af", "best_bid": "0.001", "best_ask": "0.002"}], "timestamp": "1769384313127", "event_type": "price_change"}}
{"_local_timestamp": "2026-01-25T23:38:33.951418+00:00", "data": {"market": "0x5999cfd552cbcf89bbd54c0e48b08c74182caefb18a80f1782018dcef2520d2d", "price_changes": [{"asset_id": "15174546601205928046556699082541161461166100492124394241054975981067833950165", "price": "0.528", "size": "0", "side": "BUY", "hash": "9ad4b3420ec152b92ef7239ee2e3340c4a41f31e", "best_bid": "0.998", "best_ask": "0.999"}, {"asset_id": "5430476248758985969939507303101680818848966275102949447275298704026336588828", "price": "0.472", "size": "0", "side": "SELL", "hash": "624d36b716ec55ffc6c4aa31c8ba4e28323f08eb", "best_bid": "0.001", "best_ask": "0.002"}], "timestamp": "1769384313880", "event_type": "price_change"}}
{"_local_timestamp": "2026-01-25T23:38:34.275212+00:00", "data": {"market": "0x5999cfd552cbcf89bbd54c0e48b08c74182caefb18a80f1782018dcef2520d2d", "price_changes": [{"asset_id": "15174546601205928046556699082541161461166100492124394241054975981067833950165", "price": "0.528", "size": "5", "side": "BUY", "hash": "b45d57779a677d2adeb6027cb19c3f9556f86200", "best_bid": "0.998", "best_ask": "0.999"}, {"asset_id": "5430476248758985969939507303101680818848966275102949447275298704026336588828", "price": "0.472", "size": "5", "side": "SELL", "hash": "9edfd8ce6e09ee9a5d22219cee7e2e87b6c8fd37", "best_bid": "0.001", "best_ask": "0.002"}], "timestamp": "1769384314200", "event_type": "price_change"}}
{"_local_timestamp": "2026-01-25T23:38:36.061272+00:00", "data": {"market": "0x5999cfd552cbcf89bbd54c0e48b08c74182caefb18a80f1782018dcef2520d2d", "price_changes": [{"asset_id": "15174546601205928046556699082541161461166100492124394241054975981067833950165", "price": "0.528", "size": "0", "side": "BUY", "hash": "d72033352d8e328ee2331f127cf1ae7393f9700a", "best_bid": "0.998", "best_ask": "0.999"}, {"asset_id": "5430476248758985969939507303101680818848966275102949447275298704026336588828", "price": "0.472", "size": "0", "side": "SELL", "hash": "d2e5ce9662f83deac10a2e6b2dc844e12aad715e", "best_bid": "0.001", "best_ask": "0.002"}], "timestamp": "1769384315990", "event_type": "price_change"}}
{"_local_timestamp": "2026-01-25T23:38:36.352368+00:00", "data": {"market": "0x5999cfd552cbcf89bbd54c0e48b08c74182caefb18a80f1782018dcef2520d2d", "price_changes": [{"asset_id": "15174546601205928046556699082541161461166100492124394241054975981067833950165", "price": "0.528", "size": "5", "side": "BUY", "hash": "49f0b0d68aa0d86642d9432b74032b1314d0bbcb", "best_bid": "0.998", "best_ask": "0.999"}, {"asset_id": "5430476248758985969939507303101680818848966275102949447275298704026336588828", "price": "0.472", "size": "5", "side": "SELL", "hash": "6afd9c49b4da96f46c6cdc6854df4b8e85fb18a9", "best_bid": "0.001", "best_ask": "0.002"}], "timestamp": "1769384316282", "event_type": "price_change"}}
{"_local_timestamp": "2026-01-25T23:38:37.389666+00:00", "data": {"market": "0x5999cfd552cbcf89bbd54c0e48b08c74182caefb18a80f1782018dcef2520d2d", "price_changes": [{"asset_id": "15174546601205928046556699082541161461166100492124394241054975981067833950165", "price": "0.528", "size": "0", "side": "BUY", "hash": "354dece73a81dbfd8a540eee01389a6e8636d827", "best_bid": "0.998", "best_ask": "0.999"}, {"asset_id": "5430476248758985969939507303101680818848966275102949447275298704026336588828", "price": "0.472", "size": "0", "side": "SELL", "hash": "27c97ad096df7a8a4658cc9ed3366713eedc5940", "best_bid": "0.001", "best_ask": "0.002"}], "timestamp": "1769384317308", "event_type": "price_change"}}
{"_local_timestamp": "2026-01-25T23:38:38.032177+00:00", "data": {"market": "0x5999cfd552cbcf89bbd54c0e48b08c74182caefb18a80f1782018dcef2520d2d", "price_changes": [{"asset_id": "15174546601205928046556699082541161461166100492124394241054975981067833950165", "price": "0.528", "size": "5", "side": "BUY", "hash": "e1e02c7d74d5f5812427f2d4940617f96ae4e07a", "best_bid": "0.998", "best_ask": "0.999"}, {"asset_id": "5430476248758985969939507303101680818848966275102949447275298704026336588828", "price": "0.472", "size": "5", "side": "SELL", "hash": "4c891743585cc7532a133e1d044e17a743e332bb", "best_bid": "0.001", "best_ask": "0.002"}], "timestamp": "1769384317958", "event_type": "price_change"}}
{"_local_timestamp": "2026-01-25T23:38:38.809277+00:00", "data": {"market": "0x5999cfd552cbcf89bbd54c0e48b08c74182caefb18a80f1782018dcef2520d2d", "price_changes": [{"asset_id": "15174546601205928046556699082541161461166100492124394241054975981067833950165", "price": "0.528", "size": "0", "side": "BUY", "hash": "26e677a46c23a61d7f488f4dcb601dbd5ec2ee53", "best_bid": "0.998", "best_ask": "0.999"}, {"asset_id": "5430476248758985969939507303101680818848966275102949447275298704026336588828", "price": "0.472", "size": "0", "side": "SELL", "hash": "f9e21c1ba3ee044df5cc674249a2b25d5ce154d4", "best_bid": "0.001", "best_ask": "0.002"}], "timestamp": "1769384318729", "event_type": "price_change"}}
{"_local_timestamp": "2026-01-25T23:38:39.332655+00:00", "data": {"market": "0x5999cfd552cbcf89bbd54c0e48b08c74182caefb18a80f1782018dcef2520d2d", "price_changes": [{"asset_id": "15174546601205928046556699082541161461166100492124394241054975981067833950165", "price": "0.528", "size": "5", "side": "BUY", "hash": "d86a8950cd1fdf386b3fbd69b292d2dfed03199a", "best_bid": "0.998", "best_ask": "0.999"}, {"asset_id": "5430476248758985969939507303101680818848966275102949447275298704026336588828", "price": "0.472", "size": "5", "side": "SELL", "hash": "73aabd21fadacb5ca413808510f7a4d242f26034", "best_bid": "0.001", "best_ask": "0.002"}], "timestamp": "1769384319258", "event_type": "price_change"}}
{"_local_timestamp": "2026-01-25T23:38:40.716702+00:00", "data": {"market": "0x5999cfd552cbcf89bbd54c0e48b08c74182caefb18a80f1782018dcef2520d2d", "price_changes": [{"asset_id": "15174546601205928046556699082541161461166100492124394241054975981067833950165", "price": "0.528", "size": "0", "side": "BUY", "hash": "123f10960adb2569f8fe8b08d28d90a123f98531", "best_bid": "0.998", "best_ask": "0.999"}, {"asset_id": "5430476248758985969939507303101680818848966275102949447275298704026336588828", "price": "0.472", "size": "0", "side": "SELL", "hash": "2fde0186b3b9c82f1a86974530616349d500a7b2", "best_bid": "0.001", "best_ask": "0.002"}], "timestamp": "1769384320645", "event_type": "price_change"}}
{"_local_timestamp": "2026-01-25T23:38:41.136692+00:00", "data": {"market": "0x5999cfd552cbcf89bbd54c0e48b08c74182caefb18a80f1782018dcef2520d2d", "price_changes": [{"asset_id": "15174546601205928046556699082541161461166100492124394241054975981067833950165", "price": "0.528", "size": "5", "side": "BUY", "hash": "cee32dd8ef83e2d6f181db353490f5be692c8edc", "best_bid": "0.998", "best_ask": "0.999"}, {"asset_id": "5430476248758985969939507303101680818848966275102949447275298704026336588828", "price": "0.472", "size": "5", "side": "SELL", "hash": "97dcab576af5d29d49446a2b24b057ba58b07627", "best_bid": "0.001", "best_ask": "0.002"}], "timestamp": "1769384321061", "event_type": "price_change"}}
{"_local_timestamp": "2026-01-25T23:38:42.233091+00:00", "data": {"market": "0x5999cfd552cbcf89bbd54c0e48b08c74182caefb18a80f1782018dcef2520d2d", "price_changes": [{"asset_id": "15174546601205928046556699082541161461166100492124394241054975981067833950165", "price": "0.528", "size": "0", "side": "BUY", "hash": "55ae88cdbbbfbbf3ba8540e1e5e1aa9dad16aa97", "best_bid": "0.998", "best_ask": "0.999"}, {"asset_id": "5430476248758985969939507303101680818848966275102949447275298704026336588828", "price": "0.472", "size": "0", "side": "SELL", "hash": "486dfa2ee6330fce23e32dec8bc3a45328893cc7", "best_bid": "0.001", "best_ask": "0.002"}], "timestamp": "1769384322156", "event_type": "price_change"}}
{"_local_timestamp": "2026-01-25T23:38:42.584938+00:00", "data": {"market": "0x5999cfd552cbcf89bbd54c0e48b08c74182caefb18a80f1782018dcef2520d2d", "price_changes": [{"asset_id": "15174546601205928046556699082541161461166100492124394241054975981067833950165", "price": "0.528", "size": "5", "side": "BUY", "hash": "c975db84c92c3f1e8895a2095a6dbc4d5faaf8d7", "best_bid": "0.998", "best_ask": "0.999"}, {"asset_id": "5430476248758985969939507303101680818848966275102949447275298704026336588828", "price": "0.472", "size": "5", "side": "SELL", "hash": "6e64b30eed7fa205f098a916cd119c034a81e4e7", "best_bid": "0.001", "best_ask": "0.002"}], "timestamp": "1769384322508", "event_type": "price_change"}}
{"_local_timestamp": "2026-01-25T23:38:43.535743+00:00", "data": {"market": "0x5999cfd552cbcf89bbd54c0e48b08c74182caefb18a80f1782018dcef2520d2d", "price_changes": [{"asset_id": "15174546601205928046556699082541161461166100492124394241054975981067833950165", "price": "0.528", "size": "0", "side": "BUY", "hash": "7c4b17d181cf8393922c27750967a150089b9bca", "best_bid": "0.998", "best_ask": "0.999"}, {"asset_id": "5430476248758985969939507303101680818848966275102949447275298704026336588828", "price": "0.472", "size": "0", "side": "SELL", "hash": "b5a8d5be9cc722ecca0ada48de31953a1f26f5e2", "best_bid": "0.001", "best_ask": "0.002"}], "timestamp": "1769384323457", "event_type": "price_change"}}
{"_local_timestamp": "2026-01-25T23:38:43.898495+00:00", "data": {"market": "0x5999cfd552cbcf89bbd54c0e48b08c74182caefb18a80f1782018dcef2520d2d", "price_changes": [{"asset_id": "15174546601205928046556699082541161461166100492124394241054975981067833950165", "price": "0.528", "size": "5", "side": "BUY", "hash": "81d34f55f82df9e3e4bfbdd040c075bf7ad742c3", "best_bid": "0.998", "best_ask": "0.999"}, {"asset_id": "5430476248758985969939507303101680818848966275102949447275298704026336588828", "price": "0.472", "size": "5", "side": "SELL", "hash": "94491f790966ec13a576486aa241eb608461cd47", "best_bid": "0.001", "best_ask": "0.002"}], "timestamp": "1769384323823", "event_type": "price_change"}}
{"_local_timestamp": "2026-01-25T23:38:45.658279+00:00", "data": {"market": "0x5999cfd552cbcf89bbd54c0e48b08c74182caefb18a80f1782018dcef2520d2d", "price_changes": [{"asset_id": "15174546601205928046556699082541161461166100492124394241054975981067833950165", "price": "0.528", "size": "0", "side": "BUY", "hash": "c7232f9931eddbb845fc5f467f0a3bad596a3c3b", "best_bid": "0.998", "best_ask": "0.999"}, {"asset_id": "5430476248758985969939507303101680818848966275102949447275298704026336588828", "price": "0.472", "size": "0", "side": "SELL", "hash": "b85b028bb379596479ad79f77da37cfbcb4e9431", "best_bid": "0.001", "best_ask": "0.002"}], "timestamp": "1769384325581", "event_type": "price_change"}}
{"_local_timestamp": "2026-01-25T23:38:46.153609+00:00", "data": {"market": "0x5999cfd552cbcf89bbd54c0e48b08c74182caefb18a80f1782018dcef2520d2d", "price_changes": [{"asset_id": "15174546601205928046556699082541161461166100492124394241054975981067833950165", "price": "0.528", "size": "5", "side": "BUY", "hash": "a5029af2e4bbb3e8179a292746bbc20cb1f5d5a6", "best_bid": "0.998", "best_ask": "0.999"}, {"asset_id": "5430476248758985969939507303101680818848966275102949447275298704026336588828", "price": "0.472", "size": "5", "side": "SELL", "hash": "f211ddf7e9db212f7bbfbc3a87809941c237d1d6", "best_bid": "0.001", "best_ask": "0.002"}], "timestamp": "1769384326077", "event_type": "price_change"}}
{"_local_timestamp": "2026-01-25T23:38:48.473746+00:00", "data": {"market": "0x5999cfd552cbcf89bbd54c0e48b08c74182caefb18a80f1782018dcef2520d2d", "price_changes": [{"asset_id": "15174546601205928046556699082541161461166100492124394241054975981067833950165", "price": "0.528", "size": "0", "side": "BUY", "hash": "99108e570ca51003505dced62032d8333d25ce06", "best_bid": "0.998", "best_ask": "0.999"}, {"asset_id": "5430476248758985969939507303101680818848966275102949447275298704026336588828", "price": "0.472", "size": "0", "side": "SELL", "hash": "cf787d83bbeb7de7ed6b2ed3cd9cee6f0dcbad17", "best_bid": "0.001", "best_ask": "0.002"}], "timestamp": "1769384328399", "event_type": "price_change"}}
{"_local_timestamp": "2026-01-25T23:38:49.348039+00:00", "data": {"market": "0x5999cfd552cbcf89bbd54c0e48b08c74182caefb18a80f1782018dcef2520d2d", "price_changes": [{"asset_id": "15174546601205928046556699082541161461166100492124394241054975981067833950165", "price": "0.528", "size": "5", "side": "BUY", "hash": "e1fed1656d042c7d10f13577be31ef39b9586cc5", "best_bid": "0.998", "best_ask": "0.999"}, {"asset_id": "5430476248758985969939507303101680818848966275102949447275298704026336588828", "price": "0.472", "size": "5", "side": "SELL", "hash": "f9ff0cdd7c5d3682b8e7335e9cb042973ada10c4", "best_bid": "0.001", "best_ask": "0.002"}], "timestamp": "1769384329269", "event_type": "price_change"}}
{"_local_timestamp": "2026-01-25T23:38:50.648045+00:00", "data": {"market": "0x5999cfd552cbcf89bbd54c0e48b08c74182caefb18a80f1782018dcef2520d2d", "price_changes": [{"asset_id": "15174546601205928046556699082541161461166100492124394241054975981067833950165", "price": "0.528", "size": "0", "side": "BUY", "hash": "eec6eb4dbf6ca408438f2137d5bf696308cc7c3a", "best_bid": "0.998", "best_ask": "0.999"}, {"asset_id": "5430476248758985969939507303101680818848966275102949447275298704026336588828", "price": "0.472", "size": "0", "side": "SELL", "hash": "5e1b62183ef34ff73682cd5e2d13b6ccfe7907e0", "best_bid": "0.001", "best_ask": "0.002"}], "timestamp": "1769384330578", "event_type": "price_change"}}
{"_local_timestamp": "2026-01-25T23:38:51.007795+00:00", "data": {"market": "0x5999cfd552cbcf89bbd54c0e48b08c74182caefb18a80f1782018dcef2520d2d", "price_changes": [{"asset_id": "15174546601205928046556699082541161461166100492124394241054975981067833950165", "price": "0.528", "size": "5", "side": "BUY", "hash": "2b4041525177a8297b38b7f9eda437780e3dc9e5", "best_bid": "0.998", "best_ask": "0.999"}, {"asset_id": "5430476248758985969939507303101680818848966275102949447275298704026336588828", "price": "0.472", "size": "5", "side": "SELL", "hash": "af9eba54479f1340f0fd67d102bf1748cf56d007", "best_bid": "0.001", "best_ask": "0.002"}], "timestamp": "1769384330930", "event_type": "price_change"}}
{"_local_timestamp": "2026-01-25T23:38:52.836624+00:00", "data": {"market": "0x5999cfd552cbcf89bbd54c0e48b08c74182caefb18a80f1782018dcef2520d2d", "price_changes": [{"asset_id": "15174546601205928046556699082541161461166100492124394241054975981067833950165", "price": "0.528", "size": "0", "side": "BUY", "hash": "ce1e39b622587fa2102c1a7ac8cd1c74a620363b", "best_bid": "0.998", "best_ask": "0.999"}, {"asset_id": "5430476248758985969939507303101680818848966275102949447275298704026336588828", "price": "0.472", "size": "0", "side": "SELL", "hash": "bc73839e4d8623de87b2d9d68fa5cd4fc7123517", "best_bid": "0.001", "best_ask": "0.002"}], "timestamp": "1769384332763", "event_type": "price_change"}}
{"_local_timestamp": "2026-01-25T23:38:53.174077+00:00", "data": {"market": "0x5999cfd552cbcf89bbd54c0e48b08c74182caefb18a80f1782018dcef2520d2d", "price_changes": [{"asset_id": "15174546601205928046556699082541161461166100492124394241054975981067833950165", "price": "0.528", "size": "5", "side": "BUY", "hash": "c3c77e9a2e5e82f20f18787b76d51747e3ef54ca", "best_bid": "0.998", "best_ask": "0.999"}, {"asset_id": "5430476248758985969939507303101680818848966275102949447275298704026336588828", "price": "0.472", "size": "5", "side": "SELL", "hash": "7441ad4674f3078d1dd859e0a4e12e6dd05eb9bb", "best_bid": "0.001", "best_ask": "0.002"}], "timestamp": "1769384333097", "event_type": "price_change"}}
{"_local_timestamp": "2026-01-25T23:38:54.163764+00:00", "data": {"market": "0x5999cfd552cbcf89bbd54c0e48b08c74182caefb18a80f1782018dcef2520d2d", "price_changes": [{"asset_id": "15174546601205928046556699082541161461166100492124394241054975981067833950165", "price": "0.528", "size": "0", "side": "BUY", "hash": "9108d4f384a158906571a7e204c2e15a039add26", "best_bid": "0.998", "best_ask": "0.999"}, {"asset_id": "5430476248758985969939507303101680818848966275102949447275298704026336588828", "price": "0.472", "size": "0", "side": "SELL", "hash": "24ea74675a758108872b03802ede488fcd5d3f93", "best_bid": "0.001", "best_ask": "0.002"}], "timestamp": "1769384334081", "event_type": "price_change"}}
{"_local_timestamp": "2026-01-25T23:38:54.508946+00:00", "data": {"market": "0x5999cfd552cbcf89bbd54c0e48b08c74182caefb18a80f1782018dcef2520d2d", "price_changes": [{"asset_id": "15174546601205928046556699082541161461166100492124394241054975981067833950165", "price": "0.528", "size": "5", "side": "BUY", "hash": "6eb5c3faf3cc3d34099683b3309bf7bddc6be2b1", "best_bid": "0.998", "best_ask": "0.999"}, {"asset_id": "5430476248758985969939507303101680818848966275102949447275298704026336588828", "price": "0.472", "size": "5", "side": "SELL", "hash": "43cb0bb3d2c2d68f3c990ffc71fd2c228ab5c1fd", "best_bid": "0.001", "best_ask": "0.002"}], "timestamp": "1769384334431", "event_type": "price_change"}}
{"_local_timestamp": "2026-01-25T23:38:55.015730+00:00", "data": {"market": "0x5999cfd552cbcf89bbd54c0e48b08c74182caefb18a80f1782018dcef2520d2d", "price_changes": [{"asset_id": "15174546601205928046556699082541161461166100492124394241054975981067833950165", "price": "0.528", "size": "0", "side": "BUY", "hash": "5f48228162fdb3b99eb6c983bc388ff0f67545f6", "best_bid": "0.998", "best_ask": "0.999"}, {"asset_id": "5430476248758985969939507303101680818848966275102949447275298704026336588828", "price": "0.472", "size": "0", "side": "SELL", "hash": "67b897c1424f2128a290ec1f995a393f427a6927", "best_bid": "0.001", "best_ask": "0.002"}], "timestamp": "1769384334937", "event_type": "price_change"}}
{"_local_timestamp": "2026-01-25T23:38:55.348258+00:00", "data": {"market": "0x5999cfd552cbcf89bbd54c0e48b08c74182caefb18a80f1782018dcef2520d2d", "price_changes": [{"asset_id": "15174546601205928046556699082541161461166100492124394241054975981067833950165", "price": "0.528", "size": "5", "side": "BUY", "hash": "3e757a4bb9c884a76bf59ac529c6fdf0193745fc", "best_bid": "0.998", "best_ask": "0.999"}, {"asset_id": "5430476248758985969939507303101680818848966275102949447275298704026336588828", "price": "0.472", "size": "5", "side": "SELL", "hash": "7118eb0db5a9871122998709e9befb070c859e0b", "best_bid": "0.001", "best_ask": "0.002"}], "timestamp": "1769384335270", "event_type": "price_change"}}
{"_local_timestamp": "2026-01-25T23:38:56.600914+00:00", "data": {"market": "0x5999cfd552cbcf89bbd54c0e48b08c74182caefb18a80f1782018dcef2520d2d", "price_changes": [{"asset_id": "15174546601205928046556699082541161461166100492124394241054975981067833950165", "price": "0.528", "size": "0", "side": "BUY", "hash": "e09e6b64318b07e141815714449eaf7027b41d9c", "best_bid": "0.998", "best_ask": "0.999"}, {"asset_id": "5430476248758985969939507303101680818848966275102949447275298704026336588828", "price": "0.472", "size": "0", "side": "SELL", "hash": "172ef1a1c0f3aa1e9fa17fbc7847fbb1798ff996", "best_bid": "0.001", "best_ask": "0.002"}], "timestamp": "1769384336533", "event_type": "price_change"}}
{"_local_timestamp": "2026-01-25T23:38:56.864580+00:00", "data": {"market": "0x5999cfd552cbcf89bbd54c0e48b08c74182caefb18a80f1782018dcef2520d2d", "price_changes": [{"asset_id": "15174546601205928046556699082541161461166100492124394241054975981067833950165", "price": "0.528", "size": "5", "side": "BUY", "hash": "00a0ef18299f0c0492bc1d96e104cabc50ca99f9", "best_bid": "0.998", "best_ask": "0.999"}, {"asset_id": "5430476248758985969939507303101680818848966275102949447275298704026336588828", "price": "0.472", "size": "5", "side": "SELL", "hash": "ecb8dc937a8d406498365d28c1dd157d5244dfe4", "best_bid": "0.001", "best_ask": "0.002"}], "timestamp": "1769384336790", "event_type": "price_change"}}
{"_local_timestamp": "2026-01-25T23:38:57.782191+00:00", "data": {"market": "0x5999cfd552cbcf89bbd54c0e48b08c74182caefb18a80f1782018dcef2520d2d", "price_changes": [{"asset_id": "15174546601205928046556699082541161461166100492124394241054975981067833950165", "price": "0.528", "size": "0", "side": "BUY", "hash": "7757563bc7b042cc5eeff6b642c7035326e434aa", "best_bid": "0.998", "best_ask": "0.999"}, {"asset_id": "5430476248758985969939507303101680818848966275102949447275298704026336588828", "price": "0.472", "size": "0", "side": "SELL", "hash": "52d081f24ce6a52e9fec592a41d8d3296b33c0bb", "best_bid": "0.001", "best_ask": "0.002"}], "timestamp": "1769384337712", "event_type": "price_change"}}
{"_local_timestamp": "2026-01-25T23:38:58.642728+00:00", "data": {"market": "0x5999cfd552cbcf89bbd54c0e48b08c74182caefb18a80f1782018dcef2520d2d", "price_changes": [{"asset_id": "15174546601205928046556699082541161461166100492124394241054975981067833950165", "price": "0.528", "size": "5", "side": "BUY", "hash": "32ae4910428bd0c7d88dab8a3f132ba3cdca392e", "best_bid": "0.998", "best_ask": "0.999"}, {"asset_id": "5430476248758985969939507303101680818848966275102949447275298704026336588828", "price": "0.472", "size": "5", "side": "SELL", "hash": "a172c683061f450a1c13bc1b123cbaaf1bfd220d", "best_bid": "0.001", "best_ask": "0.002"}], "timestamp": "1769384338458", "event_type": "price_change"}}
{"_local_timestamp": "2026-01-25T23:38:58.818144+00:00", "data": {"market": "0x5999cfd552cbcf89bbd54c0e48b08c74182caefb18a80f1782018dcef2520d2d", "price_changes": [{"asset_id": "15174546601205928046556699082541161461166100492124394241054975981067833950165", "price": "0.528", "size": "0", "side": "BUY", "hash": "2b478e73ef2632860a2107751b8eb7e3827e491f", "best_bid": "0.998", "best_ask": "0.999"}, {"asset_id": "5430476248758985969939507303101680818848966275102949447275298704026336588828", "price": "0.472", "size": "0", "side": "SELL", "hash": "21643c57c1b91d268949d06f2d5bf88681d1eabc", "best_bid": "0.001", "best_ask": "0.002"}], "timestamp": "1769384338748", "event_type": "price_change"}}
{"_local_timestamp": "2026-01-25T23:38:59.219944+00:00", "data": {"market": "0x5999cfd552cbcf89bbd54c0e48b08c74182caefb18a80f1782018dcef2520d2d", "price_changes": [{"asset_id": "15174546601205928046556699082541161461166100492124394241054975981067833950165", "price": "0.528", "size": "5", "side": "BUY", "hash": "dced1dab3130d139687415872f44f952d356c6c1", "best_bid": "0.998", "best_ask": "0.999"}, {"asset_id": "5430476248758985969939507303101680818848966275102949447275298704026336588828", "price": "0.472", "size": "5", "side": "SELL", "hash": "009ef0f847cad638275285e898a381ba0b79821a", "best_bid": "0.001", "best_ask": "0.002"}], "timestamp": "1769384339078", "event_type": "price_change"}}
{"_local_timestamp": "2026-01-25T23:39:00.588500+00:00", "data": {"market": "0x5999cfd552cbcf89bbd54c0e48b08c74182caefb18a80f1782018dcef2520d2d", "price_changes": [{"asset_id": "15174546601205928046556699082541161461166100492124394241054975981067833950165", "price": "0.528", "size": "0", "side": "BUY", "hash": "54435449f3b77d13bba62c508f8a8dc0e2e0c0a0", "best_bid": "0.998", "best_ask": "0.999"}, {"asset_id": "5430476248758985969939507303101680818848966275102949447275298704026336588828", "price": "0.472", "size": "0", "side": "SELL", "hash": "dbc7e37e4212cee747f186d349c403406483a4c6", "best_bid": "0.001", "best_ask": "0.002"}], "timestamp": "1769384340522", "event_type": "price_change"}}
{"_local_timestamp": "2026-01-25T23:39:00.876632+00:00", "data": {"market": "0x5999cfd552cbcf89bbd54c0e48b08c74182caefb18a80f1782018dcef2520d2d", "price_changes": [{"asset_id": "15174546601205928046556699082541161461166100492124394241054975981067833950165", "price": "0.528", "size": "5", "side": "BUY", "hash": "ffff68319372c74388e9549bff95a6f2cd9726c1", "best_bid": "0.998", "best_ask": "0.999"}, {"asset_id": "5430476248758985969939507303101680818848966275102949447275298704026336588828", "price": "0.472", "size": "5", "side": "SELL", "hash": "3c1a029f9cb8dbd04e5ff05ae57cca25d8d21f8b", "best_bid": "0.001", "best_ask": "0.002"}], "timestamp": "1769384340809", "event_type": "price_change"}}
{"_local_timestamp": "2026-01-25T23:39:01.339184+00:00", "data": {"market": "0x5999cfd552cbcf89bbd54c0e48b08c74182caefb18a80f1782018dcef2520d2d", "price_changes": [{"asset_id": "15174546601205928046556699082541161461166100492124394241054975981067833950165", "price": "0.528", "size": "0", "side": "BUY", "hash": "28ba2f459ca445b84d55e94eb1d47db35e217661", "best_bid": "0.998", "best_ask": "0.999"}, {"asset_id": "5430476248758985969939507303101680818848966275102949447275298704026336588828", "price": "0.472", "size": "0", "side": "SELL", "hash": "5476938efe2680923eb47547331d7230112e9e03", "best_bid": "0.001", "best_ask": "0.002"}], "timestamp": "1769384341256", "event_type": "price_change"}}
{"_local_timestamp": "2026-01-25T23:39:01.730083+00:00", "data": {"market": "0x5999cfd552cbcf89bbd54c0e48b08c74182caefb18a80f1782018dcef2520d2d", "price_changes": [{"asset_id": "15174546601205928046556699082541161461166100492124394241054975981067833950165", "price": "0.528", "size": "5", "side": "BUY", "hash": "a47b2e17dc041b1e3858e650c0820d323a811efc", "best_bid": "0.998", "best_ask": "0.999"}, {"asset_id": "5430476248758985969939507303101680818848966275102949447275298704026336588828", "price": "0.472", "size": "5", "side": "SELL", "hash": "a51b9d5d72b5600a94bc21d2b6104a9636752b23", "best_bid": "0.001", "best_ask": "0.002"}], "timestamp": "1769384341655", "event_type": "price_change"}}
{"_local_timestamp": "2026-01-25T23:39:02.085299+00:00", "data": {"market": "0x5999cfd552cbcf89bbd54c0e48b08c74182caefb18a80f1782018dcef2520d2d", "price_changes": [{"asset_id": "15174546601205928046556699082541161461166100492124394241054975981067833950165", "price": "0.528", "size": "0", "side": "BUY", "hash": "771a1843530893f02eaef6d607f96384a5e92a79", "best_bid": "0.998", "best_ask": "0.999"}, {"asset_id": "5430476248758985969939507303101680818848966275102949447275298704026336588828", "price": "0.472", "size": "0", "side": "SELL", "hash": "a67de4632abdadf177c553eb4c6b3daa4c3335b8", "best_bid": "0.001", "best_ask": "0.002"}], "timestamp": "1769384341999", "event_type": "price_change"}}
{"_local_timestamp": "2026-01-25T23:39:02.370216+00:00", "data": {"market": "0x5999cfd552cbcf89bbd54c0e48b08c74182caefb18a80f1782018dcef2520d2d", "price_changes": [{"asset_id": "15174546601205928046556699082541161461166100492124394241054975981067833950165", "price": "0.528", "size": "5", "side": "BUY", "hash": "49f1178edbf62b812ee5700b8dc5f812197dca80", "best_bid": "0.998", "best_ask": "0.999"}, {"asset_id": "5430476248758985969939507303101680818848966275102949447275298704026336588828", "price": "0.472", "size": "5", "side": "SELL", "hash": "52bdb6822c3a41e830385e0e185babd3b6b87fe2", "best_bid": "0.001", "best_ask": "0.002"}], "timestamp": "1769384342295", "event_type": "price_change"}}
{"_local_timestamp": "2026-01-25T23:39:03.562505+00:00", "data": {"market": "0x5999cfd552cbcf89bbd54c0e48b08c74182caefb18a80f1782018dcef2520d2d", "price_changes": [{"asset_id": "15174546601205928046556699082541161461166100492124394241054975981067833950165", "price": "0.528", "size": "0", "side": "BUY", "hash": "2bcb82a0972cb3841ac9de6eed7756150450a4b7", "best_bid": "0.998", "best_ask": "0.999"}, {"asset_id": "5430476248758985969939507303101680818848966275102949447275298704026336588828", "price": "0.472", "size": "0", "side": "SELL", "hash": "5bb2fd1187f1acf897ec59e58362f95a10feff6a", "best_bid": "0.001", "best_ask": "0.002"}], "timestamp": "1769384343492", "event_type": "price_change"}}
{"_local_timestamp": "2026-01-25T23:39:04.310369+00:00", "data": {"market": "0x5999cfd552cbcf89bbd54c0e48b08c74182caefb18a80f1782018dcef2520d2d", "price_changes": [{"asset_id": "15174546601205928046556699082541161461166100492124394241054975981067833950165", "price": "0.528", "size": "5", "side": "BUY", "hash": "f007194606750f241d4b77777688f70b5025fa5d", "best_bid": "0.998", "best_ask": "0.999"}, {"asset_id": "5430476248758985969939507303101680818848966275102949447275298704026336588828", "price": "0.472", "size": "5", "side": "SELL", "hash": "b1e55fcfcd2b390784084a886d3d5f2265ca209f", "best_bid": "0.001", "best_ask": "0.002"}], "timestamp": "1769384344239", "event_type": "price_change"}}
{"_local_timestamp": "2026-01-25T23:39:04.622347+00:00", "data": {"market": "0x5999cfd552cbcf89bbd54c0e48b08c74182caefb18a80f1782018dcef2520d2d", "price_changes": [{"asset_id": "15174546601205928046556699082541161461166100492124394241054975981067833950165", "price": "0.528", "size": "0", "side": "BUY", "hash": "9e5965b2d140e69665d0abb18fe1e6f41d35e288", "best_bid": "0.998", "best_ask": "0.999"}, {"asset_id": "5430476248758985969939507303101680818848966275102949447275298704026336588828", "price": "0.472", "size": "0", "side": "SELL", "hash": "2ba91c8a165e54fed34bb955af3045eeb14b22d2", "best_bid": "0.001", "best_ask": "0.002"}], "timestamp": "1769384344540", "event_type": "price_change"}}
{"_local_timestamp": "2026-01-25T23:39:04.998437+00:00", "data": {"market": "0x5999cfd552cbcf89bbd54c0e48b08c74182caefb18a80f1782018dcef2520d2d", "price_changes": [{"asset_id": "15174546601205928046556699082541161461166100492124394241054975981067833950165", "price": "0.528", "size": "5", "side": "BUY", "hash": "eb2d12b476a2a04e6cc5488e730b0cdaeaf637a5", "best_bid": "0.998", "best_ask": "0.999"}, {"asset_id": "5430476248758985969939507303101680818848966275102949447275298704026336588828", "price": "0.472", "size": "5", "side": "SELL", "hash": "fb95412391c55cb03484dc48dfb0143409a4822f", "best_bid": "0.001", "best_ask": "0.002"}], "timestamp": "1769384344927", "event_type": "price_change"}}
{"_local_timestamp": "2026-01-25T23:39:05.466378+00:00", "data": {"market": "0x5999cfd552cbcf89bbd54c0e48b08c74182caefb18a80f1782018dcef2520d2d", "price_changes": [{"asset_id": "15174546601205928046556699082541161461166100492124394241054975981067833950165", "price": "0.528", "size": "0", "side": "BUY", "hash": "f9b8be1a71ee50aba01732dd7817db0af50dca16", "best_bid": "0.998", "best_ask": "0.999"}, {"asset_id": "5430476248758985969939507303101680818848966275102949447275298704026336588828", "price": "0.472", "size": "0", "side": "SELL", "hash": "96d65558b6e0d3d8f59c7a047241c42aeeb5cd73", "best_bid": "0.001", "best_ask": "0.002"}], "timestamp": "1769384345389", "event_type": "price_change"}}
{"_local_timestamp": "2026-01-25T23:39:05.835363+00:00", "data": {"market": "0x5999cfd552cbcf89bbd54c0e48b08c74182caefb18a80f1782018dcef2520d2d", "price_changes": [{"asset_id": "15174546601205928046556699082541161461166100492124394241054975981067833950165", "price": "0.528", "size": "5", "side": "BUY", "hash": "aa18b14a4403f94ea59fce3ccd0bec080f2ab0d6", "best_bid": "0.998", "best_ask": "0.999"}, {"asset_id": "5430476248758985969939507303101680818848966275102949447275298704026336588828", "price": "0.472", "size": "5", "side": "SELL", "hash": "1bed74d21a28cbc81010e48db6f113d5ff05825c", "best_bid": "0.001", "best_ask": "0.002"}], "timestamp": "1769384345763", "event_type": "price_change"}}
{"_local_timestamp": "2026-01-25T23:39:07.254732+00:00", "data": {"market": "0x5999cfd552cbcf89bbd54c0e48b08c74182caefb18a80f1782018dcef2520d2d", "price_changes": [{"asset_id": "15174546601205928046556699082541161461166100492124394241054975981067833950165", "price": "0.528", "size": "0", "side": "BUY", "hash": "4ef5f0f789edacd0ef90eff78b9d56d13c8b3acd", "best_bid": "0.998", "best_ask": "0.999"}, {"asset_id": "5430476248758985969939507303101680818848966275102949447275298704026336588828", "price": "0.472", "size": "0", "side": "SELL", "hash": "8f490d68c3e36969c844855c0e8c4f2fb20238e9", "best_bid": "0.001", "best_ask": "0.002"}], "timestamp": "1769384347183", "event_type": "price_change"}}
{"_local_timestamp": "2026-01-25T23:39:07.745799+00:00", "data": {"market": "0x5999cfd552cbcf89bbd54c0e48b08c74182caefb18a80f1782018dcef2520d2d", "price_changes": [{"asset_id": "15174546601205928046556699082541161461166100492124394241054975981067833950165", "price": "0.528", "size": "5", "side": "BUY", "hash": "af6a9f33f00eb24f57601bce0458b1b2eb46c74a", "best_bid": "0.998", "best_ask": "0.999"}, {"asset_id": "5430476248758985969939507303101680818848966275102949447275298704026336588828", "price": "0.472", "size": "5", "side": "SELL", "hash": "7a18fc38e7aaa9ade28ae41b897b53f084d7928b", "best_bid": "0.001", "best_ask": "0.002"}], "timestamp": "1769384347673", "event_type": "price_change"}}
{"_local_timestamp": "2026-01-25T23:39:08.751447+00:00", "data": {"market": "0x5999cfd552cbcf89bbd54c0e48b08c74182caefb18a80f1782018dcef2520d2d", "price_changes": [{"asset_id": "15174546601205928046556699082541161461166100492124394241054975981067833950165", "price": "0.528", "size": "0", "side": "BUY", "hash": "cf7eec2724dc5bf640250701bcd9668d1ae95475", "best_bid": "0.998", "best_ask": "0.999"}, {"asset_id": "5430476248758985969939507303101680818848966275102949447275298704026336588828", "price": "0.472", "size": "0", "side": "SELL", "hash": "5b4bdbc9eb73e1c6eb618e52c7d26d34853f6122", "best_bid": "0.001", "best_ask": "0.002"}], "timestamp": "1769384348659", "event_type": "price_change"}}
{"_local_timestamp": "2026-01-25T23:39:09.510144+00:00", "data": {"market": "0x5999cfd552cbcf89bbd54c0e48b08c74182caefb18a80f1782018dcef2520d2d", "price_changes": [{"asset_id": "15174546601205928046556699082541161461166100492124394241054975981067833950165", "price": "0.528", "size": "5", "side": "BUY", "hash": "095ad8a67f7f652f0a4d220ef0410029b4c67aa7", "best_bid": "0.998", "best_ask": "0.999"}, {"asset_id": "5430476248758985969939507303101680818848966275102949447275298704026336588828", "price": "0.472", "size": "5", "side": "SELL", "hash": "ee5488d1756353cc4e0441ed69c10b351ec8f90b", "best_bid": "0.001", "best_ask": "0.002"}], "timestamp": "1769384349435", "event_type": "price_change"}}
