{"_local_timestamp": "2026-01-25T23:33:17.621115+00:00", "data": [{"market": "0xb106a3c9d1c59ed8117493dae6459a3ff79369a8f7cddaf62f4a05828b89195e", "asset_id": "1376044590327709616459174469529480611299625159235587466149878628404281805565", "timestamp": "1769383981638", "hash": "c9c7d5f743c5e15905d971ee2af6052dbf1c76cb", "bids": [{"price": "0.01", "size": "2267961.55"}, {"price": "0.02", "size": "66536"}, {"price": "0.03", "size": "51205.74"}, {"price": "0.04", "size": "16384"}, {"price": "0.05", "size": "726.12"}, {"price": "0.07", "size": "91685.71"}, {"price": "0.08", "size": "8896"}, {"price": "0.09", "size": "20360.91"}, {"price": "0.11", "size": "50600"}, {"price": "0.12", "size": "1750.51"}, {"price": "0.13", "size": "20000"}, {"price": "0.14", "size": "185.71"}, {"price": "0.15", "size": "12798"}, {"price": "0.16", "size": "1174"}, {"price": "0.17", "size": "31705.07"}, {"price": "0.18", "size": "250"}, {"price": "0.19", "size": "105.26"}, {"price": "0.22", "size": "20000"}, {"price": "0.25", "size": "1000"}, {"price": "0.3", "size": "100"}, {"price": "0.32", "size": "256"}, {"price": "0.37", "size": "3500"}, {"price": "0.38", "size": "850"}, {"price": "0.4", "size": "300"}, {"price": "0.41", "size": "20"}, {"price": "0.42", "size": "105"}, {"price": "0.43", "size": "4065"}, {"price": "0.44", "size": "5105"}, {"price": "0.45", "size": "25511.9"}, {"price": "0.46", "size": "15359.19"}], "asks": [{"price": "0.99", "size": "2268059.17"}, {"price": "0.98", "size": "66536"}, {"price": "0.97", "size": "51200"}, {"price": "0.96", "size": "16390.07"}, {"price": "0.95", "size": "20720"}, {"price": "0.94", "size": "500"}, {"price": "0.92", "size": "5021"}, {"price": "0.91", "size": "1776"}, {"price": "0.9", "size": "6.05"}, {"price": "0.89", "size": "10290.9"}, {"price": "0.88", "size": "90600"}, {"price": "0.87", "size": "1480"}, {"price": "0.86", "size": "2800"}, {"price": "0.84", "size": "1186.5"}, {"price": "0.83", "size": "5870"}, {"price": "0.81", "size": "226.31"}, {"price": "0.78", "size": "90.9"}, {"price": "0.77", "size": "250"}, {"price": "0.68", "size": "256"}, {"price": "0.6", "size": "444"}, {"price": "0.55", "size": "10850"}, {"price": "0.54", "size": "100"}, {"price": "0.53", "size": "343"}, {"price": "0.51", "size": "2805"}, {"price": "0.5", "size": "14525"}, {"price": "0.49", "size": "7685"}, {"price": "0.48", "size": "13277.11"}, {"price": "0.47", "size": "5971.52"}], "event_type": "book", "last_trade_price": "0.540"}, {"market": "0xb106a3c9d1c59ed8117493dae6459a3ff79369a8f7cddaf62f4a05828b89195e", "asset_id": "49084048476353771153083262278964615095037480324537117350127265918750912547378", "timestamp": "1769383981638", "hash": "01fbd6db1083dad58d2b94b2c0b5891881ddff43", "bids": [{"price": "0.01", "size": "2268059.17"}, {"price": "0.02", "size": "66536"}, {"price": "0.03", "size": "51200"}, {"price": "0.04", "size": "16390.07"}, {"price": "0.05", "size": "20720"}, {"price": "0.06", "size": "500"}, {"price": "0.08", "size": "5021"}, {"price": "0.09", "size": "1776"}, {"price": "0.1", "size": "6.05"}, {"price": "0.11", "size": "10290.9"}, {"price": "0.12", "size": "90600"}, {"price": "0.13", "size": "1480"}, {"price": "0.14", "size": "2800"}, {"price": "0.16", "size": "1186.5"}, {"price": "0.17", "size": "5870"}, {"price": "0.19", "size": "226.31"}, {"price": "0.22", "size": "90.9"}, {"price": "0.23", "size": "250"}, {"price": "0.32", "size": "256"}, {"price": "0.4", "size": "444"}, {"price": "0.45", "size": "10850"}, {"price": "0.46", "size": "100"}, {"price": "0.47", "size": "343"}, {"price": "0.49", "size": "2805"}, {"price": "0.5", "size": "14525"}, {"price": "0.51", "size": "7685"}, {"price": "0.52", "size": "13277.11"}, {"price": "0.53", "size": "5971.52"}], "asks": [{"price": "0.99", "size": "2267961.55"}, {"price": "0.98", "size": "66536"}, {"price": "0.97", "size": "51205.74"}, {"price": "0.96", "size": "16384"}, {"price": "0.95", "size": "726.12"}, {"price": "0.93", "size": "91685.71"}, {"price": "0.92", "size": "8896"}, {"price": "0.91", "size": "20360.91"}, {"price": "0.89", "size": "50600"}, {"price": "0.88", "size": "1750.51"}, {"price": "0.87", "size": "20000"}, {"price": "0.86", "size": "185.71"}, {"price": "0.85", "size": "12798"}, {"price": "0.84", "size": "1174"}, {"price": "0.83", "size": "31705.07"}, {"price": "0.82", "size": "250"}, {"price": "0.81", "size": "105.26"}, {"price": "0.78", "size": "20000"}, {"price": "0.75", "size": "1000"}, {"price": "0.7", "size": "100"}, {"price": "0.68", "size": "256"}, {"price": "0.63", "size": "3500"}, {"price": "0.62", "size": "850"}, {"price": "0.6", "size": "300"}, {"price": "0.59", "size": "20"}, {"price": "0.58", "size": "105"}, {"price": "0.57", "size": "4065"}, {"price": "0.56", "size": "5105"}, {"price": "0.55", "size": "25511.9"}, {"price": "0.54", "size": "15359.19"}], "event_type": "book", "last_trade_price": "0.540"}, {"market": "0x0a99479228e93524b25676ae69b94bd3f4278a6bca8d8c265c84d24755399cf5", "asset_id": "67109747366255871599717338045111308888043498275177238365560740200996017915657", "timestamp": "1769383993000", "hash": "94e1ff6ba93ecb35fcaa0e14148622fddb77ced5", "bids": [{"price": "0.01", "size": "1268994.2"}, {"price": "0.02", "size": "66701.13"}, {"price": "0.03", "size": "50000"}, {"price": "0.04", "size": "117591.21"}, {"price": "0.05", "size": "50720"}, {"price": "0.06", "size": "51450"}, {"price": "0.07", "size": "485.71"}, {"price": "0.08", "size": "12536"}, {"price": "0.09", "size": "30355.55"}, {"price": "0.1", "size": "10030"}, {"price": "0.11", "size": "1459.05"}, {"price": "0.12", "size": "10233.33"}, {"price": "0.14", "size": "20785.71"}, {"price": "0.15", "size": "12798"}, {"price": "0.16", "size": "1174"}, {"price": "0.17", "size": "1700"}, {"price": "0.18", "size": "20"}, {"price": "0.19", "size": "105.26"}, {"price": "0.2", "size": "3400"}, {"price": "0.23", "size": "2000"}, {"price": "0.28", "size": "10"}, {"price": "0.3", "size": "105"}, {"price": "0.32", "size": "261"}, {"price": "0.33", "size": "5"}, {"price": "0.34", "size": "5"}, {"price": "0.35", "size": "5"}, {"price": "0.36", "size": "5"}, {"price": "0.37", "size": "3405"}, {"price": "0.38", "size": "860"}, {"price": "0.39", "size": "5"}, {"price": "0.4", "size": "105"}, {"price": "0.41", "size": "5"}, {"price": "0.42", "size": "105"}, {"price": "0.43", "size": "12505"}, {"price": "0.44", "size": "529787"}, {"price": "0.45", "size": "26032.67"}, {"price": "0.46", "size": "479.99"}], "asks": [{"price": "0.99", "size": "2267961.67"}, {"price": "0.98", "size": "66536"}, {"price": "0.97", "size": "201205.43"}, {"price": "0.96", "size": "116384"}, {"price": "0.95", "size": "90725.79"}, {"price": "0.94", "size": "50500"}, {"price": "0.92", "size": "4521"}, {"price": "0.91", "size": "60505.07"}, {"price": "0.9", "size": "21241"}, {"price": "0.89", "size": "290.9"}, {"price": "0.88", "size": "1332"}, {"price": "0.86", "size": "20800"}, {"price": "0.84", "size": "1186.5"}, {"price": "0.83", "size": "12875.37"}, {"price": "0.82", "size": "11042"}, {"price": "0.81", "size": "10376.31"}, {"price": "0.79", "size": "10"}, {"price": "0.78", "size": "190.9"}, {"price": "0.74", "size": "6100"}, {"price": "0.73", "size": "5000"}, {"price": "0.68", "size": "256"}, {"price": "0.6", "size": "200"}, {"price": "0.58", "size": "300"}, {"price": "0.55", "size": "3850"}, {"price": "0.53", "size": "2000"}, {"price": "0.52", "size": "30"}, {"price": "0.51", "size": "2100"}, {"price": "0.5", "size": "925"}, {"price": "0.49", "size": "8675"}, {"price": "0.48", "size": "17171.56"}, {"price": "0.47", "size": "22418.59"}], "event_type": "book", "last_trade_price": ""}, {"market": "0x0a99479228e93524b25676ae69b94bd3f4278a6bca8d8c265c84d24755399cf5", "asset_id": "103845791232328975452762372781150730610824357544180691092497335946993481308222", "timestamp": "1769383993000", "hash": "38888bad7acb2993d2c50779dbc577288a730a96", "bids": [{"price": "0.01", "size": "2267961.67"}, {"price": "0.02", "size": "66536"}, {"price": "0.03", "size": "201205.43"}, {"price": "0.04", "size": "116384"}, {"price": "0.05", "size": "90725.79"}, {"price": "0.06", "size": "50500"}, {"price": "0.08", "size": "4521"}, {"price": "0.09", "size": "60505.07"}, {"price": "0.1", "size": "21241"}, {"price": "0.11", "size": "290.9"}, {"price": "0.12", "size": "1332"}, {"price": "0.14", "size": "20800"}, {"price": "0.16", "size": "1186.5"}, {"price": "0.17", "size": "12875.37"}, {"price": "0.18", "size": "11042"}, {"price": "0.19", "size": "10376.31"}, {"price": "0.21", "size": "10"}, {"price": "0.22", "size": "190.9"}, {"price": "0.26", "size": "6100"}, {"price": "0.27", "size": "5000"}, {"price": "0.32", "size": "256"}, {"price": "0.4", "size": "200"}, {"price": "0.42", "size": "300"}, {"price": "0.45", "size": "3850"}, {"price": "0.47", "size": "2000"}, {"price": "0.48", "size": "30"}, {"price": "0.49", "size": "2100"}, {"price": "0.5", "size": "925"}, {"price": "0.51", "size": "8675"}, {"price": "0.52", "size": "17171.56"}, {"price": "0.53", "size": "22418.59"}], "asks": [{"price": "0.99", "size": "1268994.2"}, {"price": "0.98", "size": "66701.13"}, {"price": "0.97", "size": "50000"}, {"price": "0.96", "size": "117591.21"}, {"price": "0.95", "size": "50720"}, {"price": "0.94", "size": "51450"}, {"price": "0.93", "size": "485.71"}, {"price": "0.92", "size": "12536"}, {"price": "0.91", "size": "30355.55"}, {"price": "0.9", "size": "10030"}, {"price": "0.89", "size": "1459.05"}, {"price": "0.88", "size": "10233.33"}, {"price": "0.86", "size": "20785.71"}, {"price": "0.85", "size": "12798"}, {"price": "0.84", "size": "1174"}, {"price": "0.83", "size": "1700"}, {"price": "0.82", "size": "20"}, {"price": "0.81", "size": "105.26"}, {"price": "0.8", "size": "3400"}, {"price": "0.77", "size": "2000"}, {"price": "0.72", "size": "10"}, {"price": "0.7", "size": "105"}, {"price": "0.68", "size": "261"}, {"price": "0.67", "size": "5"}, {"price": "0.66", "size": "5"}, {"price": "0.65", "size": "5"}, {"price": "0.64", "size": "5"}, {"price": "0.63", "size": "3405"}, {"price": "0.62", "size": "860"}, {"price": "0.61", "size": "5"}, {"price": "0.6", "size": "105"}, {"price": "0.59", "size": "5"}, {"price": "0.58", "size": "105"}, {"price": "0.57", "size": "12505"}, {"price": "0.56", "size": "529787"}, {"price": "0.55", "size": "26032.67"}, {"price": "0.54", "size": "479.99"}], "event_type": "book", "last_trade_price": ""}]}
{"_local_timestamp": "2026-01-25T23:33:18.802911+00:00", "data": {"market": "0x0a99479228e93524b25676ae69b94bd3f4278a6bca8d8c265c84d24755399cf5", "price_changes": [{"asset_id": "67109747366255871599717338045111308888043498275177238365560740200996017915657", "price": "0.01", "size": "1268999.2", "side": "BUY", "hash": "e70e8bb6b609374b74399bfbe74942eff952d5c6", "best_bid": "0.46", "best_ask": "0.47"}, {"asset_id": "103845791232328975452762372781150730610824357544180691092497335946993481308222", "price": "0.99", "size": "1268999.2", "side": "SELL", "hash": "7111615d4585c58a3870dafa88b51a84e8207442", "best_bid": "0.53", "best_ask": "0.54"}], "timestamp": "1769383998734", "event_type": "price_change"}}
{"_local_timestamp": "2026-01-25T23:33:19.080665+00:00", "data": {"market": "0x0a99479228e93524b25676ae69b94bd3f4278a6bca8d8c265c84d24755399cf5", "price_changes": [{"asset_id": "67109747366255871599717338045111308888043498275177238365560740200996017915657", "price": "0.01", "size": "1268994.2", "side": "BUY", "hash": "583b0ea6225fac24954e4973757c64f91f264c36", "best_bid": "0.46", "best_ask": "0.47"}, {"asset_id": "103845791232328975452762372781150730610824357544180691092497335946993481308222", "price": "0.99", "size": "1268994.2", "side": "SELL", "hash": "13f96e5ad9cf5fbf51aabaa403f4452ef62291a1", "best_bid": "0.53", "best_ask": "0.54"}], "timestamp": "1769383999000", "event_type": "price_change"}}
{"_local_timestamp": "2026-01-25T23:33:20.907724+00:00", "data": {"market": "0x0a99479228e93524b25676ae69b94bd3f4278a6bca8d8c265c84d24755399cf5", "price_changes": [{"asset_id": "67109747366255871599717338045111308888043498275177238365560740200996017915657", "price": "0.01", "size": "1268999.2", "side": "BUY", "hash": "708080db7518e5d8495f8bac2a3ce1967ed1cc1e", "best_bid": "0.46", "best_ask": "0.47"}, {"asset_id": "103845791232328975452762372781150730610824357544180691092497335946993481308222", "price": "0.99", "size": "1268999.2", "side": "SELL", "hash": "c47c962b3e62dab95b4497f2a3594ad885c9aec1", "best_bid": "0.53", "best_ask": "0.54"}], "timestamp": "1769384000841", "event_type": "price_change"}}
{"_local_timestamp": "2026-01-25T23:33:21.082955+00:00", "data": {"market": "0x0a99479228e93524b25676ae69b94bd3f4278a6bca8d8c265c84d24755399cf5", "price_changes": [{"asset_id": "67109747366255871599717338045111308888043498275177238365560740200996017915657", "price": "0.01", "size": "1268994.2", "side": "BUY", "hash": "0fb7f7311787319776865515a9ef6054bca525d3", "best_bid": "0.46", "best_ask": "0.47"}, {"asset_id": "103845791232328975452762372781150730610824357544180691092497335946993481308222", "price": "0.99", "size": "1268994.2", "side": "SELL", "hash": "d30a6442c7cb5a0b050310d2e4e812a1590fcdd1", "best_bid": "0.53", "best_ask": "0.54"}], "timestamp": "1769384001000", "event_type": "price_change"}}
{"_local_timestamp": "2026-01-25T23:33:23.104246+00:00", "data": {"market": "0x0a99479228e93524b25676ae69b94bd3f4278a6bca8d8c265c84d24755399cf5", "price_changes": [{"asset_id": "67109747366255871599717338045111308888043498275177238365560740200996017915657", "price": "0.01", "size": "1268989.2", "side": "BUY", "hash": "ff563c3843588c13e920c1da9034653d16ab2664", "best_bid": "0.46", "best_ask": "0.47"}, {"asset_id": "103845791232328975452762372781150730610824357544180691092497335946993481308222", "price": "0.99", "size": "1268989.2", "side": "SELL", "hash": "161a81c809fc7301db259860e2956a7a5774a885", "best_bid": "0.53", "best_ask": "0.54"}], "timestamp": "1769384003004", "event_type": "price_change"}}
{"_local_timestamp": "2026-01-25T23:33:23.871787+00:00", "data": {"market": "0x0a99479228e93524b25676ae69b94bd3f4278a6bca8d8c265c84d24755399cf5", "price_changes": [{"asset_id": "67109747366255871599717338045111308888043498275177238365560740200996017915657", "price": "0.01", "size": "1268994.2", "side": "BUY", "hash": "76c5d71706678402a086a56e403bc5f4bd8c29ee", "best_bid": "0.46", "best_ask": "0.47"}, {"asset_id": "103845791232328975452762372781150730610824357544180691092497335946993481308222", "price": "0.99", "size": "1268994.2", "side": "SELL", "hash": "6c8ae2dbc56d4c9034a242cec91d98e0dd78ecc3", "best_bid": "0.53", "best_ask": "0.54"}], "timestamp": "1769384003782", "event_type": "price_change"}}
{"_local_timestamp": "2026-01-25T23:33:23.918116+00:00", "data": {"market": "0x0a99479228e93524b25676ae69b94bd3f4278a6bca8d8c265c84d24755399cf5", "price_changes": [{"asset_id": "67109747366255871599717338045111308888043498275177238365560740200996017915657", "price": "0.01", "size": "1268999.2", "side": "BUY", "hash": "022fcaebbf4675b14804e032b14ab94c133e2708", "best_bid": "0.46", "best_ask": "0.47"}, {"asset_id": "103845791232328975452762372781150730610824357544180691092497335946993481308222", "price": "0.99", "size": "1268999.2", "side": "SELL", "hash": "65301d5c4dda225bf640276ba830fe58b1604a4a", "best_bid": "0.53", "best_ask": "0.54"}], "timestamp": "1769384003837", "event_type": "price_change"}}
{"_local_timestamp": "2026-01-25T23:33:25.804466+00:00", "data": {"market": "0x0a99479228e93524b25676ae69b94bd3f4278a6bca8d8c265c84d24755399cf5", "price_changes": [{"asset_id": "67109747366255871599717338045111308888043498275177238365560740200996017915657", "price": "0.01", "size": "1269004.2", "side": "BUY", "hash": "540ebe9cb0e048f6536e04b322b6ba9b07f6ee3d", "best_bid": "0.46", "best_ask": "0.47"}, {"asset_id": "103845791232328975452762372781150730610824357544180691092497335946993481308222", "price": "0.99", "size": "1269004.2", "side": "SELL", "hash": "d3abe286978a36c5ea85e8c4f538ba47635ef66a", "best_bid": "0.53", "best_ask": "0.54"}], "timestamp": "1769384005731", "event_type": "price_change"}}
{"_local_timestamp": "2026-01-25T23:33:26.588180+00:00", "data": {"market": "0x0a99479228e93524b25676ae69b94bd3f4278a6bca8d8c265c84d24755399cf5", "price_changes": [{"asset_id": "67109747366255871599717338045111308888043498275177238365560740200996017915657", "price": "0.01", "size": "1269009.2", "side": "BUY", "hash": "007251e3152500c647ecb5d4d9dcead5ef2925c9", "best_bid": "0.46", "best_ask": "0.47"}, {"asset_id": "103845791232328975452762372781150730610824357544180691092497335946993481308222", "price": "0.99", "size": "1269009.2", "side": "SELL", "hash": "1d4365b5000aa8a33c1e628a232ce102451f4419", "best_bid": "0.53", "best_ask": "0.54"}], "timestamp": "1769384006521", "event_type": "price_change"}}
{"_local_timestamp": "2026-01-25T23:33:27.084694+00:00", "data": {"market": "0x0a99479228e93524b25676ae69b94bd3f4278a6bca8d8c265c84d24755399cf5", "price_changes": [{"asset_id": "67109747366255871599717338045111308888043498275177238365560740200996017915657", "price": "0.01", "size": "1269004.2", "side": "BUY", "hash": "9d78f37d6be4ec176150e1451b6485b34491dcb3", "best_bid": "0.46", "best_ask": "0.47"}, {"asset_id": "103845791232328975452762372781150730610824357544180691092497335946993481308222", "price": "0.99", "size": "1269004.2", "side": "SELL", "hash": "df5415c422dfc3b40e21cf185752e350f003a3c6", "best_bid": "0.53", "best_ask": "0.54"}], "timestamp": "1769384007000", "event_type": "price_change"}}
{"_local_timestamp": "2026-01-25T23:33:29.566776+00:00", "data": {"market": "0x0a99479228e93524b25676ae69b94bd3f4278a6bca8d8c265c84d24755399cf5", "price_changes": [{"asset_id": "67109747366255871599717338045111308888043498275177238365560740200996017915657", "price": "0.01", "size": "1269009.2", "side": "BUY", "hash": "39787bdedd5d3b137f57be6180e3413414177275", "best_bid": "0.46", "best_ask": "0.47"}, {"asset_id": "103845791232328975452762372781150730610824357544180691092497335946993481308222", "price": "0.99", "size": "1269009.2", "side": "SELL", "hash": "b6c01bdd511bc6dde5377de1b1b8ff1a1ec6493e", "best_bid": "0.53", "best_ask": "0.54"}], "timestamp": "1769384009488", "event_type": "price_change"}}
{"_local_timestamp": "2026-01-25T23:33:31.070530+00:00", "data": {"market": "0x0a99479228e93524b25676ae69b94bd3f4278a6bca8d8c265c84d24755399cf5", "price_changes": [{"asset_id": "67109747366255871599717338045111308888043498275177238365560740200996017915657", "price": "0.01", "size": "1269004.2", "side": "BUY", "hash": "3e287121e048cdaa453d6726180b0ec65b1abafa", "best_bid": "0.46", "best_ask": "0.47"}, {"asset_id": "103845791232328975452762372781150730610824357544180691092497335946993481308222", "price": "0.99", "size": "1269004.2", "side": "SELL", "hash": "f8ae8a37fe9797bd01ee0d4f824a21bfcc852cf4", "best_bid": "0.53", "best_ask": "0.54"}], "timestamp": "1769384011000", "event_type": "price_change"}}
{"_local_timestamp": "2026-01-25T23:33:32.096125+00:00", "data": {"market": "0x0a99479228e93524b25676ae69b94bd3f4278a6bca8d8c265c84d24755399cf5", "price_changes": [{"asset_id": "67109747366255871599717338045111308888043498275177238365560740200996017915657", "price": "0.01", "size": "1268999.2", "side": "BUY", "hash": "f4151adb28873b22faa4147ad9e5bd26e9ae69f3", "best_bid": "0.46", "best_ask": "0.47"}, {"asset_id": "103845791232328975452762372781150730610824357544180691092497335946993481308222", "price": "0.99", "size": "1268999.2", "side": "SELL", "hash": "26267a48219d80401c77a598b1c101f794f223e2", "best_bid": "0.53", "best_ask": "0.54"}], "timestamp": "1769384012000", "event_type": "price_change"}}
{"_local_timestamp": "2026-01-25T23:33:34.102480+00:00", "data": {"market": "0x0a99479228e93524b25676ae69b94bd3f4278a6bca8d8c265c84d24755399cf5", "price_changes": [{"asset_id": "67109747366255871599717338045111308888043498275177238365560740200996017915657", "price": "0.01", "size": "1268994.2", "side": "BUY", "hash": "0210191797fe3aabc1b096ff18b48d4ee82dc995", "best_bid": "0.46", "best_ask": "0.47"}, {"asset_id": "103845791232328975452762372781150730610824357544180691092497335946993481308222", "price": "0.99", "size": "1268994.2", "side": "SELL", "hash": "300dc1af4603c23d5148937c050078a240385f82", "best_bid": "0.53", "best_ask": "0.54"}], "timestamp": "1769384014000", "event_type": "price_change"}}
{"_local_timestamp": "2026-01-25T23:33:36.079194+00:00", "data": {"market": "0x0a99479228e93524b25676ae69b94bd3f4278a6bca8d8c265c84d24755399cf5", "price_changes": [{"asset_id": "67109747366255871599717338045111308888043498275177238365560740200996017915657", "price": "0.01", "size": "1268989.2", "side": "BUY", "hash": "73ec8573eb44dee9b8de3bc210f816796a91ee3c", "best_bid": "0.46", "best_ask": "0.47"}, {"asset_id": "103845791232328975452762372781150730610824357544180691092497335946993481308222", "price": "0.99", "size": "1268989.2", "side": "SELL", "hash": "f819a0cf0934fa1ba6b117fd15e738367099af47", "best_bid": "0.53", "best_ask": "0.54"}], "timestamp": "1769384016000", "event_type": "price_change"}}
{"_local_timestamp": "2026-01-25T23:33:37.073719+00:00", "data": {"market": "0x0a99479228e93524b25676ae69b94bd3f4278a6bca8d8c265c84d24755399cf5", "price_changes": [{"asset_id": "67109747366255871599717338045111308888043498275177238365560740200996017915657", "price": "0.01", "size": "1268979.2", "side": "BUY", "hash": "d8f6f7a79b0a2f454710b85242daebf95205c4a4", "best_bid": "0.46", "best_ask": "0.47"}, {"asset_id": "103845791232328975452762372781150730610824357544180691092497335946993481308222", "price": "0.99", "size": "1268979.2", "side": "SELL", "hash": "6fa6d6b44f87c4386194328d82bb43f856d24a3d", "best_bid": "0.53", "best_ask": "0.54"}], "timestamp": "1769384017003", "event_type": "price_change"}}
{"_local_timestamp": "2026-01-25T23:33:37.075530+00:00", "data": {"market": "0x0a99479228e93524b25676ae69b94bd3f4278a6bca8d8c265c84d24755399cf5", "price_changes": [{"asset_id": "67109747366255871599717338045111308888043498275177238365560740200996017915657", "price": "0.01", "size": "1268979.2", "side": "BUY", "hash": "acb5e0a783ffa09b425d286d0eed2d325ab8ab2a", "best_bid": "0.46", "best_ask": "0.47"}, {"asset_id": "103845791232328975452762372781150730610824357544180691092497335946993481308222", "price": "0.99", "size": "1268979.2", "side": "SELL", "hash": "b611ed0bc7e067b1254872d7be1c5968f1a4c906", "best_bid": "0.53", "best_ask": "0.54"}], "timestamp": "1769384017006", "event_type": "price_change"}}
{"_local_timestamp": "2026-01-25T23:33:38.422274+00:00", "data": {"market": "0x0a99479228e93524b25676ae69b94bd3f4278a6bca8d8c265c84d24755399cf5", "price_changes": [{"asset_id": "67109747366255871599717338045111308888043498275177238365560740200996017915657", "price": "0.01", "size": "1268984.2", "side": "BUY", "hash": "27e59ccf3b3dcfef919ef4e6952585445bd1e8c7", "best_bid": "0.46", "best_ask": "0.47"}, {"asset_id": "103845791232328975452762372781150730610824357544180691092497335946993481308222", "price": "0.99", "size": "1268984.2", "side": "SELL", "hash": "58dba1bb098a12df5d36b598b2ec82adbdc07cbc", "best_bid": "0.53", "best_ask": "0.54"}], "timestamp": "1769384018354", "event_type": "price_change"}}
{"_local_timestamp": "2026-01-25T23:33:39.072703+00:00", "data": {"market": "0x0a99479228e93524b25676ae69b94bd3f4278a6bca8d8c265c84d24755399cf5", "price_changes": [{"asset_id": "67109747366255871599717338045111308888043498275177238365560740200996017915657", "price": "0.01", "size": "1268989.2", "side": "BUY", "hash": "1165c128f758c785d9d000e867a0dea3bb0691b6", "best_bid": "0.46", "best_ask": "0.47"}, {"asset_id": "103845791232328975452762372781150730610824357544180691092497335946993481308222", "price": "0.99", "size": "1268989.2", "side": "SELL", "hash": "af124659c7c1b9b66a2f46b2aea8bb4344f036ed", "best_bid": "0.53", "best_ask": "0.54"}], "timestamp": "1769384018999", "event_type": "price_change"}}
{"_local_timestamp": "2026-01-25T23:33:39.090727+00:00", "data": {"market": "0x0a99479228e93524b25676ae69b94bd3f4278a6bca8d8c265c84d24755399cf5", "price_changes": [{"asset_id": "67109747366255871599717338045111308888043498275177238365560740200996017915657", "price": "0.01", "size": "1268984.2", "side": "BUY", "hash": "dadec1c7b201405f0f6d702c777f8e69d387aacd", "best_bid": "0.46", "best_ask": "0.47"}, {"asset_id": "103845791232328975452762372781150730610824357544180691092497335946993481308222", "price": "0.99", "size": "1268984.2", "side": "SELL", "hash": "c3f9d2d9f463d6540d36f211d3fc0d7c782c9610", "best_bid": "0.53", "best_ask": "0.54"}], "timestamp": "1769384019001", "event_type": "price_change"}}
{"_local_timestamp": "2026-01-25T23:33:40.482541+00:00", "data": {"market": "0x0a99479228e93524b25676ae69b94bd3f4278a6bca8d8c265c84d24755399cf5", "price_changes": [{"asset_id": "67109747366255871599717338045111308888043498275177238365560740200996017915657", "price": "0.01", "size": "1268989.2", "side": "BUY", "hash": "020ec35d77c6846580e753f88941eb89821e95fc", "best_bid": "0.46", "best_ask": "0.47"}, {"asset_id": "103845791232328975452762372781150730610824357544180691092497335946993481308222", "price": "0.99", "size": "1268989.2", "side": "SELL", "hash": "bfbdc16d5c40b12586fda52d82eb637952e0d2f3", "best_bid": "0.53", "best_ask": "0.54"}], "timestamp": "1769384020387", "event_type": "price_change"}}
{"_local_timestamp": "2026-01-25T23:33:42.509448+00:00", "data": {"market": "0x0a99479228e93524b25676ae69b94bd3f4278a6bca8d8c265c84d24755399cf5", "price_changes": [{"asset_id": "67109747366255871599717338045111308888043498275177238365560740200996017915657", "price": "0.01", "size": "1268994.2", "side": "BUY", "hash": "38009cfc84bc152fc30e48ba8d7e33ff2b2aa6c2", "best_bid": "0.46", "best_ask": "0.47"}, {"asset_id": "103845791232328975452762372781150730610824357544180691092497335946993481308222", "price": "0.99", "size": "1268994.2", "side": "SELL", "hash": "635971c5b7f6ea2b0aae05d991c7a6fdf68cf9bf", "best_bid": "0.53", "best_ask": "0.54"}], "timestamp": "1769384022447", "event_type": "price_change"}}
{"_local_timestamp": "2026-01-25T23:33:43.083935+00:00", "data": {"market": "0x0a99479228e93524b25676ae69b94bd3f4278a6bca8d8c265c84d24755399cf5", "price_changes": [{"asset_id": "67109747366255871599717338045111308888043498275177238365560740200996017915657", "price": "0.01", "size": "1268989.2", "side": "BUY", "hash": "8f6345dd2e9b2100fac89e6da3acb65195d13d92", "best_bid": "0.46", "best_ask": "0.47"}, {"asset_id": "103845791232328975452762372781150730610824357544180691092497335946993481308222", "price": "0.99", "size": "1268989.2", "side": "SELL", "hash": "85906fba51c74f9d002548db72a4d5509dad18ed", "best_bid": "0.53", "best_ask": "0.54"}], "timestamp": "1769384023000", "event_type": "price_change"}}
{"_local_timestamp": "2026-01-25T23:33:43.502601+00:00", "data": {"market": "0x0a99479228e93524b25676ae69b94bd3f4278a6bca8d8c265c84d24755399cf5", "price_changes": [{"asset_id": "67109747366255871599717338045111308888043498275177238365560740200996017915657", "price": "0.01", "size": "1268994.2", "side": "BUY", "hash": "3eb6e4a52684e84cc7ddbe7042097d8499585b8f", "best_bid": "0.46", "best_ask": "0.47"}, {"asset_id": "103845791232328975452762372781150730610824357544180691092497335946993481308222", "price": "0.99", "size": "1268994.2", "side": "SELL", "hash": "57567b439f39351071c82021dfb09baa82e4b256", "best_bid": "0.53", "best_ask": "0.54"}], "timestamp": "1769384023423", "event_type": "price_change"}}
{"_local_timestamp": "2026-01-25T23:33:46.214281+00:00", "data": {"market": "0x0a99479228e93524b25676ae69b94bd3f4278a6bca8d8c265c84d24755399cf5", "price_changes": [{"asset_id": "67109747366255871599717338045111308888043498275177238365560740200996017915657", "price": "0.01", "size": "1268999.2", "side": "BUY", "hash": "8e80777367486f141f07556086f500e8c476438b", "best_bid": "0.46", "best_ask": "0.47"}, {"asset_id": "103845791232328975452762372781150730610824357544180691092497335946993481308222", "price": "0.99", "size": "1268999.2", "side": "SELL", "hash": "98618d55b04434cfbbe7bae94d18a9b227f9ce17", "best_bid": "0.53", "best_ask": "0.54"}], "timestamp": "1769384026149", "event_type": "price_change"}}
{"_local_timestamp": "2026-01-25T23:33:48.075696+00:00", "data": {"market": "0x0a99479228e93524b25676ae69b94bd3f4278a6bca8d8c265c84d24755399cf5", "price_changes": [{"asset_id": "67109747366255871599717338045111308888043498275177238365560740200996017915657", "price": "0.01", "size": "1268994.2", "side": "BUY", "hash": "30615c3db7ca789cd9cbb9144f22abc41d6eee08", "best_bid": "0.46", "best_ask": "0.47"}, {"asset_id": "103845791232328975452762372781150730610824357544180691092497335946993481308222", "price": "0.99", "size": "1268994.2", "side": "SELL", "hash": "a0bb202cfdaaaab77f0d57e3ea61b2648f7c1a0b", "best_bid": "0.53", "best_ask": "0.54"}], "timestamp": "1769384028000", "event_type": "price_change"}}
{"_local_timestamp": "2026-01-25T23:33:49.891288+00:00", "data": {"market": "0x0a99479228e93524b25676ae69b94bd3f4278a6bca8d8c265c84d24755399cf5", "price_changes": [{"asset_id": "67109747366255871599717338045111308888043498275177238365560740200996017915657", "price": "0.01", "size": "1268999.2", "side": "BUY", "hash": "f0c3a4a30137ea88bd56da4c67d78da27f804fe3", "best_bid": "0.46", "best_ask": "0.47"}, {"asset_id": "103845791232328975452762372781150730610824357544180691092497335946993481308222", "price": "0.99", "size": "1268999.2", "side": "SELL", "hash": "7742e848d035112106aa384209c085ac32ba6c9c", "best_bid": "0.53", "best_ask": "0.54"}], "timestamp": "1769384029826", "event_type": "price_change"}}
{"_local_timestamp": "2026-01-25T23:33:53.085143+00:00", "data": {"market": "0x0a99479228e93524b25676ae69b94bd3f4278a6bca8d8c265c84d24755399cf5", "price_changes": [{"asset_id": "67109747366255871599717338045111308888043498275177238365560740200996017915657", "price": "0.01", "size": "1268994.2", "side": "BUY", "hash": "458087d02d8882043362ef8381ad406fe1be65b2", "best_bid": "0.46", "best_ask": "0.47"}, {"asset_id": "103845791232328975452762372781150730610824357544180691092497335946993481308222", "price": "0.99", "size": "1268994.2", "side": "SELL", "hash": "aa8042de42777a67bb1340687c9ae3f17723db09", "best_bid": "0.53", "best_ask": "0.54"}], "timestamp": "1769384033001", "event_type": "price_change"}}
{"_local_timestamp": "2026-01-25T23:33:54.091180+00:00", "data": {"market": "0x0a99479228e93524b25676ae69b94bd3f4278a6bca8d8c265c84d24755399cf5", "price_changes": [{"asset_id": "67109747366255871599717338045111308888043498275177238365560740200996017915657", "price": "0.01", "size": "1268989.2", "side": "BUY", "hash": "5f21741ae6491a3dbca6f0aeae4b85816b6ab857", "best_bid": "0.46", "best_ask": "0.47"}, {"asset_id": "103845791232328975452762372781150730610824357544180691092497335946993481308222", "price": "0.99", "size": "1268989.2", "side": "SELL", "hash": "6725107e04a4ba0c2c566bea6935aaca68367bf7", "best_bid": "0.53", "best_ask": "0.54"}], "timestamp": "1769384034000", "event_type": "price_change"}}
{"_local_timestamp": "2026-01-25T23:33:56.017358+00:00", "data": {"market": "0x0a99479228e93524b25676ae69b94bd3f4278a6bca8d8c265c84d24755399cf5", "price_changes": [{"asset_id": "67109747366255871599717338045111308888043498275177238365560740200996017915657", "price": "0.01", "size": "1268994.2", "side": "BUY", "hash": "aa4e88a8f71fd6715d7699621cfef768d4ddc874", "best_bid": "0.46", "best_ask": "0.47"}, {"asset_id": "103845791232328975452762372781150730610824357544180691092497335946993481308222", "price": "0.99", "size": "1268994.2", "side": "SELL", "hash": "b273a8b9fee9418c814f1811ca6b6c7b5df982a6", "best_bid": "0.53", "best_ask": "0.54"}], "timestamp": "1769384035948", "event_type": "price_change"}}
{"_local_timestamp": "2026-01-25T23:33:56.096189+00:00", "data": {"market": "0x0a99479228e93524b25676ae69b94bd3f4278a6bca8d8c265c84d24755399cf5", "price_changes": [{"asset_id": "67109747366255871599717338045111308888043498275177238365560740200996017915657", "price": "0.01", "size": "1268989.2", "side": "BUY", "hash": "1de80f1cb8fd3a194f0294ac49272652a8f5fb69", "best_bid": "0.46", "best_ask": "0.47"}, {"asset_id": "103845791232328975452762372781150730610824357544180691092497335946993481308222", "price": "0.99", "size": "1268989.2", "side": "SELL", "hash": "6ec0b7b400eb84de30ff362b2b8acaab8a991934", "best_bid": "0.53", "best_ask": "0.54"}], "timestamp": "1769384036005", "event_type": "price_change"}}
{"_local_timestamp": "2026-01-25T23:33:57.097332+00:00", "data": {"market": "0x0a99479228e93524b25676ae69b94bd3f4278a6bca8d8c265c84d24755399cf5", "price_changes": [{"asset_id": "67109747366255871599717338045111308888043498275177238365560740200996017915657", "price": "0.01", "size": "1268994.2", "side": "BUY", "hash": "860b85f345288ee1ee52d025792da075ba63104f", "best_bid": "0.46", "best_ask": "0.47"}, {"asset_id": "103845791232328975452762372781150730610824357544180691092497335946993481308222", "price": "0.99", "size": "1268994.2", "side": "SELL", "hash": "0113da5a701e3da9666e4082b46cff8d579f9127", "best_bid": "0.53", "best_ask": "0.54"}], "timestamp": "1769384037002", "event_type": "price_change"}}
{"_local_timestamp": "2026-01-25T23:33:57.551698+00:00", "data": {"market": "0x0a99479228e93524b25676ae69b94bd3f4278a6bca8d8c265c84d24755399cf5", "price_changes": [{"asset_id": "67109747366255871599717338045111308888043498275177238365560740200996017915657", "price": "0.01", "size": "1268999.2", "side": "BUY", "hash": "84ce42b117a970eb541f3acdad76f5b6921ab8cc", "best_bid": "0.46", "best_ask": "0.47"}, {"asset_id": "103845791232328975452762372781150730610824357544180691092497335946993481308222", "price": "0.99", "size": "1268999.2", "side": "SELL", "hash": "9487c2669fb322fb987e059a8f3529a27c6d3e0f", "best_bid": "0.53", "best_ask": "0.54"}], "timestamp": "1769384037484", "event_type": "price_change"}}
{"_local_timestamp": "2026-01-25T23:33:59.180632+00:00", "data": {"market": "0x0a99479228e93524b25676ae69b94bd3f4278a6bca8d8c265c84d24755399cf5", "price_changes": [{"asset_id": "67109747366255871599717338045111308888043498275177238365560740200996017915657", "price": "0.01", "size": "1269004.2", "side": "BUY", "hash": "39198637b68f4860dc85ae179454ccfd271d31d3", "best_bid": "0.46", "best_ask": "0.47"}, {"asset_id": "103845791232328975452762372781150730610824357544180691092497335946993481308222", "price": "0.99", "size": "1269004.2", "side": "SELL", "hash": "9f0a7fbc7820a948b4322efb0af780e127143cde", "best_bid": "0.53", "best_ask": "0.54"}], "timestamp": "1769384039108", "event_type": "price_change"}}
{"_local_timestamp": "2026-01-25T23:34:00.095075+00:00", "data": {"market": "0x0a99479228e93524b25676ae69b94bd3f4278a6bca8d8c265c84d24755399cf5", "price_changes": [{"asset_id": "67109747366255871599717338045111308888043498275177238365560740200996017915657", "price": "0.01", "size": "1268999.2", "side": "BUY", "hash": "99232b0ae57fc641656f89219e11ee074728bc6d", "best_bid": "0.46", "best_ask": "0.47"}, {"asset_id": "103845791232328975452762372781150730610824357544180691092497335946993481308222", "price": "0.99", "size": "1268999.2", "side": "SELL", "hash": "69e60aea72f561c62f163197077c361d44934349", "best_bid": "0.53", "best_ask": "0.54"}], "timestamp": "1769384040000", "event_type": "price_change"}}
{"_local_timestamp": "2026-01-25T23:34:00.420298+00:00", "data": {"market": "0x0a99479228e93524b25676ae69b94bd3f4278a6bca8d8c265c84d24755399cf5", "price_changes": [{"asset_id": "67109747366255871599717338045111308888043498275177238365560740200996017915657", "price": "0.01", "size": "1269004.2", "side": "BUY", "hash": "7275ba1967efb6a47523fbcf6f92baa2f2cf216f", "best_bid": "0.46", "best_ask": "0.47"}, {"asset_id": "103845791232328975452762372781150730610824357544180691092497335946993481308222", "price": "0.99", "size": "1269004.2", "side": "SELL", "hash": "dc34f0388d0fd3b34995cf216f47d02da633bdfc", "best_bid": "0.53", "best_ask": "0.54"}], "timestamp": "1769384040337", "event_type": "price_change"}}
{"_local_timestamp": "2026-01-25T23:34:02.896504+00:00", "data": {"market": "0x0a99479228e93524b25676ae69b94bd3f4278a6bca8d8c265c84d24755399cf5", "price_changes": [{"asset_id": "67109747366255871599717338045111308888043498275177238365560740200996017915657", "price": "0.01", "size": "1269009.2", "side": "BUY", "hash": "a237c72ba745f699f22d530035e42c8a607ad2d8", "best_bid": "0.46", "best_ask": "0.47"}, {"asset_id": "103845791232328975452762372781150730610824357544180691092497335946993481308222", "price": "0.99", "size": "1269009.2", "side": "SELL", "hash": "7e99b4ea01865ef4d32cd720e0c0bad1c88144f6", "best_bid": "0.53", "best_ask": "0.54"}], "timestamp": "1769384042724", "event_type": "price_change"}}
{"_local_timestamp": "2026-01-25T23:34:05.306525+00:00", "data": {"market": "0x0a99479228e93524b25676ae69b94bd3f4278a6bca8d8c265c84d24755399cf5", "price_changes": [{"asset_id": "67109747366255871599717338045111308888043498275177238365560740200996017915657", "price": "0.01", "size": "1269004.2", "side": "BUY", "hash": "8f78cc535aa1c90c206a1f0fc2f37522b9740d58", "best_bid": "0.46", "best_ask": "0.47"}, {"asset_id": "103845791232328975452762372781150730610824357544180691092497335946993481308222", "price": "0.99", "size": "1269004.2", "side": "SELL", "hash": "e10a16c982379d8ffbec883adaa881700af43494", "best_bid": "0.53", "best_ask": "0.54"}], "timestamp": "1769384045006", "event_type": "price_change"}}
{"_local_timestamp": "2026-01-25T23:34:06.272571+00:00", "data": {"market": "0x0a99479228e93524b25676ae69b94bd3f4278a6bca8d8c265c84d24755399cf5", "price_changes": [{"asset_id": "67109747366255871599717338045111308888043498275177238365560740200996017915657", "price": "0.01", "size": "1268994.2", "side": "BUY", "hash": "8f9dfe0a1e736c39441a33a8462929b8ea3a2aa8", "best_bid": "0.46", "best_ask": "0.47"}, {"asset_id": "103845791232328975452762372781150730610824357544180691092497335946993481308222", "price": "0.99", "size": "1268994.2", "side": "SELL", "hash": "d0ec9f96fdd34d9d2b11ff5551ffd533dcec5c7c", "best_bid": "0.53", "best_ask": "0.54"}], "timestamp": "1769384046004", "event_type": "price_change"}}
{"_local_timestamp": "2026-01-25T23:34:06.293790+00:00", "data": {"market": "0x0a99479228e93524b25676ae69b94bd3f4278a6bca8d8c265c84d24755399cf5", "price_changes": [{"asset_id": "67109747366255871599717338045111308888043498275177238365560740200996017915657", "price": "0.01", "size": "1268994.2", "side": "BUY", "hash": "c25c98c8bff3412b63e27b17f4bcdffcc23fb3fb", "best_bid": "0.46", "best_ask": "0.47"}, {"asset_id": "103845791232328975452762372781150730610824357544180691092497335946993481308222", "price": "0.99", "size": "1268994.2", "side": "SELL", "hash": "33a29bdc264d097cf96ee0bd8dd4e4bdec8e1e07", "best_bid": "0.53", "best_ask": "0.54"}], "timestamp": "1769384046008", "event_type": "price_change"}}
{"_local_timestamp": "2026-01-25T23:34:08.261312+00:00", "data": {"market": "0x0a99479228e93524b25676ae69b94bd3f4278a6bca8d8c265c84d24755399cf5", "price_changes": [{"asset_id": "67109747366255871599717338045111308888043498275177238365560740200996017915657", "price": "0.01", "size": "1268989.2", "side": "BUY", "hash": "0ef46420b1bd6451a07523ff4f5e4b1ee604a5b8", "best_bid": "0.46", "best_ask": "0.47"}, {"asset_id": "103845791232328975452762372781150730610824357544180691092497335946993481308222", "price": "0.99", "size": "1268989.2", "side": "SELL", "hash": "60a2bf3bc9613fa4d8cbe19ef40b76e8696f8b8e", "best_bid": "0.53", "best_ask": "0.54"}], "timestamp": "1769384048001", "event_type": "price_change"}}
{"_local_timestamp": "2026-01-25T23:34:10.218594+00:00", "data": {"market": "0x0a99479228e93524b25676ae69b94bd3f4278a6bca8d8c265c84d24755399cf5", "price_changes": [{"asset_id": "67109747366255871599717338045111308888043498275177238365560740200996017915657", "price": "0.01", "size": "1268994.2", "side": "BUY", "hash": "d2e199b5b247e602cea505a9d27d55d948782cbc", "best_bid": "0.46", "best_ask": "0.47"}, {"asset_id": "103845791232328975452762372781150730610824357544180691092497335946993481308222", "price": "0.99", "size": "1268994.2", "side": "SELL", "hash": "00ee1a3be241b132f6bd471586cdd693214cfcfb", "best_bid": "0.53", "best_ask": "0.54"}], "timestamp": "1769384049992", "event_type": "price_change"}}
{"_local_timestamp": "2026-01-25T23:34:10.247541+00:00", "data": {"market": "0x0a99479228e93524b25676ae69b94bd3f4278a6bca8d8c265c84d24755399cf5", "price_changes": [{"asset_id": "67109747366255871599717338045111308888043498275177238365560740200996017915657", "price": "0.01", "size": "1268984.2", "side": "BUY", "hash": "b65616269540733f454a61b0c5eff3f0c2bd58bc", "best_bid": "0.46", "best_ask": "0.47"}, {"asset_id": "103845791232328975452762372781150730610824357544180691092497335946993481308222", "price": "0.99", "size": "1268984.2", "side": "SELL", "hash": "5c382741cd3a16f53e97c43e05cbba46a425cf20", "best_bid": "0.53", "best_ask": "0.54"}], "timestamp": "1769384050000", "event_type": "price_change"}}
{"_local_timestamp": "2026-01-25T23:34:10.248862+00:00", "data": {"market": "0x0a99479228e93524b25676ae69b94bd3f4278a6bca8d8c265c84d24755399cf5", "price_changes": [{"asset_id": "67109747366255871599717338045111308888043498275177238365560740200996017915657", "price": "0.01", "size": "1268984.2", "side": "BUY", "hash": "dafd61c5cfab482bd5d4ba43ddfb34c0a7dbe79b", "best_bid": "0.46", "best_ask": "0.47"}, {"asset_id": "103845791232328975452762372781150730610824357544180691092497335946993481308222", "price": "0.99", "size": "1268984.2", "side": "SELL", "hash": "929eba537d150168248e7095d2baeb17ca8fbe64", "best_bid": "0.53", "best_ask": "0.54"}], "timestamp": "1769384050004", "event_type": "price_change"}}
{"_local_timestamp": "2026-01-25T23:34:13.404451+00:00", "data": {"market": "0x0a99479228e93524b25676ae69b94bd3f4278a6bca8d8c265c84d24755399cf5", "price_changes": [{"asset_id": "67109747366255871599717338045111308888043498275177238365560740200996017915657", "price": "0.01", "size": "1268979.2", "side": "BUY", "hash": "6a4743acb81a07234e4c546c549bc1a3b2b94f6e", "best_bid": "0.46", "best_ask": "0.47"}, {"asset_id": "103845791232328975452762372781150730610824357544180691092497335946993481308222", "price": "0.99", "size": "1268979.2", "side": "SELL", "hash": "ba8b72162b61f722e70d60443ea0d3051d5b780e", "best_bid": "0.53", "best_ask": "0.54"}], "timestamp": "1769384053001", "event_type": "price_change"}}
{"_local_timestamp": "2026-01-25T23:34:13.784026+00:00", "data": {"market": "0x0a99479228e93524b25676ae69b94bd3f4278a6bca8d8c265c84d24755399cf5", "price_changes": [{"asset_id": "67109747366255871599717338045111308888043498275177238365560740200996017915657", "price": "0.01", "size": "1268984.2", "side": "BUY", "hash": "7ace6b5b1693d6d711026973c17a3670cc46198a", "best_bid": "0.46", "best_ask": "0.47"}, {"asset_id": "103845791232328975452762372781150730610824357544180691092497335946993481308222", "price": "0.99", "size": "1268984.2", "side": "SELL", "hash": "d65bf2a9633a0b21b090f8403f850c56ce378975", "best_bid": "0.53", "best_ask": "0.54"}], "timestamp": "1769384053561", "event_type": "price_change"}}
{"_local_timestamp": "2026-01-25T23:34:13.831922+00:00", "data": {"market": "0x0a99479228e93524b25676ae69b94bd3f4278a6bca8d8c265c84d24755399cf5", "price_changes": [{"asset_id": "67109747366255871599717338045111308888043498275177238365560740200996017915657", "price": "0.01", "size": "1268989.2", "side": "BUY", "hash": "5b56e340a2fc583d99d7e74f3aeeffdaaff63ce7", "best_bid": "0.46", "best_ask": "0.47"}, {"asset_id": "103845791232328975452762372781150730610824357544180691092497335946993481308222", "price": "0.99", "size": "1268989.2", "side": "SELL", "hash": "5fb362dc2b04529f836a98d1d44bafbfefc65a19", "best_bid": "0.53", "best_ask": "0.54"}], "timestamp": "1769384053600", "event_type": "price_change"}}
{"_local_timestamp": "2026-01-25T23:34:15.996779+00:00", "data": {"market": "0x0a99479228e93524b25676ae69b94bd3f4278a6bca8d8c265c84d24755399cf5", "price_changes": [{"asset_id": "67109747366255871599717338045111308888043498275177238365560740200996017915657", "price": "0.01", "size": "1268994.2", "side": "BUY", "hash": "1e8a5b52e26d1293ac1ebbc52da7b0f995bdec53", "best_bid": "0.46", "best_ask": "0.47"}, {"asset_id": "103845791232328975452762372781150730610824357544180691092497335946993481308222", "price": "0.99", "size": "1268994.2", "side": "SELL", "hash": "426c00f726a199219dd9ac082413ada265e51ff5", "best_bid": "0.53", "best_ask": "0.54"}], "timestamp": "1769384055751", "event_type": "price_change"}}
{"_local_timestamp": "2026-01-25T23:34:16.242724+00:00", "data": {"market": "0x0a99479228e93524b25676ae69b94bd3f4278a6bca8d8c265c84d24755399cf5", "price_changes": [{"asset_id": "67109747366255871599717338045111308888043498275177238365560740200996017915657", "price": "0.01", "size": "1268989.2", "side": "BUY", "hash": "87cd77e7193ab329277b1de6ef6e7d7885e416ee", "best_bid": "0.46", "best_ask": "0.47"}, {"asset_id": "103845791232328975452762372781150730610824357544180691092497335946993481308222", "price": "0.99", "size": "1268989.2", "side": "SELL", "hash": "699201cbb1a89cd62bf12cebac7e1525a76c3935", "best_bid": "0.53", "best_ask": "0.54"}], "timestamp": "1769384056000", "event_type": "price_change"}}
{"_local_timestamp": "2026-01-25T23:34:17.843659+00:00", "data": {"market": "0x0a99479228e93524b25676ae69b94bd3f4278a6bca8d8c265c84d24755399cf5", "price_changes": [{"asset_id": "67109747366255871599717338045111308888043498275177238365560740200996017915657", "price": "0.01", "size": "1268994.2", "side": "BUY", "hash": "cee623ad809aaf63d89d3359de54ea2749e21bbc", "best_bid": "0.46", "best_ask": "0.47"}, {"asset_id": "103845791232328975452762372781150730610824357544180691092497335946993481308222", "price": "0.99", "size": "1268994.2", "side": "SELL", "hash": "c5ae5ff5a1285898a73428036289118995d36591", "best_bid": "0.53", "best_ask": "0.54"}], "timestamp": "1769384057609", "event_type": "price_change"}}
{"_local_timestamp": "2026-01-25T23:34:19.610483+00:00", "data": {"market": "0x0a99479228e93524b25676ae69b94bd3f4278a6bca8d8c265c84d24755399cf5", "price_changes": [{"asset_id": "67109747366255871599717338045111308888043498275177238365560740200996017915657", "price": "0.01", "size": "1268999.2", "side": "BUY", "hash": "4c8cd8e726ca82cc2b2da566b11053d0c1587a2a", "best_bid": "0.46", "best_ask": "0.47"}, {"asset_id": "103845791232328975452762372781150730610824357544180691092497335946993481308222", "price": "0.99", "size": "1268999.2", "side": "SELL", "hash": "d7f03cfbc497d6c02fcf3f76af376d5ea9e7c0ae", "best_bid": "0.53", "best_ask": "0.54"}], "timestamp": "1769384059403", "event_type": "price_change"}}
{"_local_timestamp": "2026-01-25T23:34:21.037273+00:00", "data": {"market": "0x0a99479228e93524b25676ae69b94bd3f4278a6bca8d8c265c84d24755399cf5", "price_changes": [{"asset_id": "67109747366255871599717338045111308888043498275177238365560740200996017915657", "price": "0.01", "size": "1269004.2", "side": "BUY", "hash": "d3f6af6fb799d4545e1b788cb5f66542fbad06c3", "best_bid": "0.46", "best_ask": "0.47"}, {"asset_id": "103845791232328975452762372781150730610824357544180691092497335946993481308222", "price": "0.99", "size": "1269004.2", "side": "SELL", "hash": "5477f781331d9bd0c89843af72e264a6e53c641c", "best_bid": "0.53", "best_ask": "0.54"}], "timestamp": "1769384060804", "event_type": "price_change"}}
{"_local_timestamp": "2026-01-25T23:34:23.232434+00:00", "data": {"market": "0x0a99479228e93524b25676ae69b94bd3f4278a6bca8d8c265c84d24755399cf5", "price_changes": [{"asset_id": "67109747366255871599717338045111308888043498275177238365560740200996017915657", "price": "0.01", "size": "1268999.2", "side": "BUY", "hash": "062caf2b87f8f50794fa9780751cc822cd83ca6f", "best_bid": "0.46", "best_ask": "0.47"}, {"asset_id": "103845791232328975452762372781150730610824357544180691092497335946993481308222", "price": "0.99", "size": "1268999.2", "side": "SELL", "hash": "14a2b3572f4ce9d3f2b9ac819cf62a24f1c93f80", "best_bid": "0.53", "best_ask": "0.54"}], "timestamp": "1769384063000", "event_type": "price_change"}}
{"_local_timestamp": "2026-01-25T23:34:27.239889+00:00", "data": {"market": "0x0a99479228e93524b25676ae69b94bd3f4278a6bca8d8c265c84d24755399cf5", "price_changes": [{"asset_id": "67109747366255871599717338045111308888043498275177238365560740200996017915657", "price": "0.01", "size": "1268989.2", "side": "BUY", "hash": "954a6bd1b2ba563771efe93837335ddfd5bf720b", "best_bid": "0.46", "best_ask": "0.47"}, {"asset_id": "103845791232328975452762372781150730610824357544180691092497335946993481308222", "price": "0.99", "size": "1268989.2", "side": "SELL", "hash": "3f66fe662b18555ffc69acf41cc6c92edc616eb5", "best_bid": "0.53", "best_ask": "0.54"}], "timestamp": "1769384067001", "event_type": "price_change"}}
{"_local_timestamp": "2026-01-25T23:34:27.266718+00:00", "data": {"market": "0x0a99479228e93524b25676ae69b94bd3f4278a6bca8d8c265c84d24755399cf5", "price_changes": [{"asset_id": "67109747366255871599717338045111308888043498275177238365560740200996017915657", "price": "0.01", "size": "1268989.2", "side": "BUY", "hash": "56f5a3d9abccaab2b8f48a1151c79c1568e78da0", "best_bid": "0.46", "best_ask": "0.47"}, {"asset_id": "103845791232328975452762372781150730610824357544180691092497335946993481308222", "price": "0.99", "size": "1268989.2", "side": "SELL", "hash": "a49028294fce92917375f0d9e1d7284c5d20ef3f", "best_bid": "0.53", "best_ask": "0.54"}], "timestamp": "1769384067005", "event_type": "price_change"}}
{"_local_timestamp": "2026-01-25T23:34:29.425867+00:00", "data": {"market": "0x0a99479228e93524b25676ae69b94bd3f4278a6bca8d8c265c84d24755399cf5", "price_changes": [{"asset_id": "67109747366255871599717338045111308888043498275177238365560740200996017915657", "price": "0.01", "size": "1268984.2", "side": "BUY", "hash": "11a54370fccb01ca0ae0ef1b1138903c91fdc4ee", "best_bid": "0.46", "best_ask": "0.47"}, {"asset_id": "103845791232328975452762372781150730610824357544180691092497335946993481308222", "price": "0.99", "size": "1268984.2", "side": "SELL", "hash": "f4cfb054ee009bc32031e5ae60f5389113dfa505", "best_bid": "0.53", "best_ask": "0.54"}], "timestamp": "1769384069003", "event_type": "price_change"}}
{"_local_timestamp": "2026-01-25T23:34:30.627469+00:00", "data": {"market": "0x0a99479228e93524b25676ae69b94bd3f4278a6bca8d8c265c84d24755399cf5", "price_changes": [{"asset_id": "67109747366255871599717338045111308888043498275177238365560740200996017915657", "price": "0.01", "size": "1268989.2", "side": "BUY", "hash": "f3fc055a5d4519d38622dd731165d148ad0b9c61", "best_bid": "0.46", "best_ask": "0.47"}, {"asset_id": "103845791232328975452762372781150730610824357544180691092497335946993481308222", "price": "0.99", "size": "1268989.2", "side": "SELL", "hash": "95f7d44dff20681199c58cd5922cedb26b4ed18d", "best_bid": "0.53", "best_ask": "0.54"}], "timestamp": "1769384070300", "event_type": "price_change"}}
{"_local_timestamp": "2026-01-25T23:34:31.444260+00:00", "data": {"market": "0x0a99479228e93524b25676ae69b94bd3f4278a6bca8d8c265c84d24755399cf5", "price_changes": [{"asset_id": "67109747366255871599717338045111308888043498275177238365560740200996017915657", "price": "0.01", "size": "1268994.2", "side": "BUY", "hash": "265f30c6cadf0f36fe5bbf2c24c57cd8afde5505", "best_bid": "0.46", "best_ask": "0.47"}, {"asset_id": "103845791232328975452762372781150730610824357544180691092497335946993481308222", "price": "0.99", "size": "1268994.2", "side": "SELL", "hash": "95e3577fbe90169c68669b042cb13c830f529561", "best_bid": "0.53", "best_ask": "0.54"}], "timestamp": "1769384071202", "event_type": "price_change"}}
{"_local_timestamp": "2026-01-25T23:34:31.480205+00:00", "data": {"market": "0x0a99479228e93524b25676ae69b94bd3f4278a6bca8d8c265c84d24755399cf5", "price_changes": [{"asset_id": "67109747366255871599717338045111308888043498275177238365560740200996017915657", "price": "0.01", "size": "1268999.2", "side": "BUY", "hash": "3555abd30885ef7893e4aa6f00c50a5d833c7a27", "best_bid": "0.46", "best_ask": "0.47"}, {"asset_id": "103845791232328975452762372781150730610824357544180691092497335946993481308222", "price": "0.99", "size": "1268999.2", "side": "SELL", "hash": "34eb5e17656e4e0ec52bbc5581230a7d65ceae84", "best_bid": "0.53", "best_ask": "0.54"}], "timestamp": "1769384071237", "event_type": "price_change"}}
{"_local_timestamp": "2026-01-25T23:34:32.697149+00:00", "data": {"market": "0x0a99479228e93524b25676ae69b94bd3f4278a6bca8d8c265c84d24755399cf5", "price_changes": [{"asset_id": "67109747366255871599717338045111308888043498275177238365560740200996017915657", "price": "0.01", "size": "1269004.2", "side": "BUY", "hash": "bbb3dbbd5fea656035d06bdf763bd94df068784a", "best_bid": "0.46", "best_ask": "0.47"}, {"asset_id": "103845791232328975452762372781150730610824357544180691092497335946993481308222", "price": "0.99", "size": "1269004.2", "side": "SELL", "hash": "7bb9849a92f65f953d265614ae90f6d34555dee6", "best_bid": "0.53", "best_ask": "0.54"}], "timestamp": "1769384072487", "event_type": "price_change"}}
{"_local_timestamp": "2026-01-25T23:34:33.247668+00:00", "data": {"market": "0x0a99479228e93524b25676ae69b94bd3f4278a6bca8d8c265c84d24755399cf5", "price_changes": [{"asset_id": "67109747366255871599717338045111308888043498275177238365560740200996017915657", "price": "0.01", "size": "1268999.2", "side": "BUY", "hash": "818b32b3eb3247fe6292b50f001bfc1ee2e90735", "best_bid": "0.46", "best_ask": "0.47"}, {"asset_id": "103845791232328975452762372781150730610824357544180691092497335946993481308222", "price": "0.99", "size": "1268999.2", "side": "SELL", "hash": "d30c755a54264d71562aa6c30066474935141d71", "best_bid": "0.53", "best_ask": "0.54"}], "timestamp": "1769384073000", "event_type": "price_change"}}
{"_local_timestamp": "2026-01-25T23:34:35.444565+00:00", "data": {"market": "0x0a99479228e93524b25676ae69b94bd3f4278a6bca8d8c265c84d24755399cf5", "price_changes": [{"asset_id": "67109747366255871599717338045111308888043498275177238365560740200996017915657", "price": "0.01", "size": "1269004.2", "side": "BUY", "hash": "c683e74b45e7598c941ac2e309f9d8913cbeecdc", "best_bid": "0.46", "best_ask": "0.47"}, {"asset_id": "103845791232328975452762372781150730610824357544180691092497335946993481308222", "price": "0.99", "size": "1269004.2", "side": "SELL", "hash": "7d0f8cc0680e691d1ef57843195d2918f436d168", "best_bid": "0.53", "best_ask": "0.54"}], "timestamp": "1769384075202", "event_type": "price_change"}}
{"_local_timestamp": "2026-01-25T23:34:36.248848+00:00", "data": {"market": "0x0a99479228e93524b25676ae69b94bd3f4278a6bca8d8c265c84d24755399cf5", "price_changes": [{"asset_id": "67109747366255871599717338045111308888043498275177238365560740200996017915657", "price": "0.01", "size": "1268999.2", "side": "BUY", "hash": "5ffb6f64899cb9c6e69b89f4c3dff5e1fd69fad1", "best_bid": "0.46", "best_ask": "0.47"}, {"asset_id": "103845791232328975452762372781150730610824357544180691092497335946993481308222", "price": "0.99", "size": "1268999.2", "side": "SELL", "hash": "5c57186a3425b9944ac43c3dbece5c4001471dfd", "best_bid": "0.53", "best_ask": "0.54"}], "timestamp": "1769384076002", "event_type": "price_change"}}
{"_local_timestamp": "2026-01-25T23:34:36.546484+00:00", "data": {"market": "0x0a99479228e93524b25676ae69b94bd3f4278a6bca8d8c265c84d24755399cf5", "price_changes": [{"asset_id": "67109747366255871599717338045111308888043498275177238365560740200996017915657", "price": "0.01", "size": "1269004.2", "side": "BUY", "hash": "343d7322db097fe08bb1d04c4fbb888c4ab4a0d4", "best_bid": "0.46", "best_ask": "0.47"}, {"asset_id": "103845791232328975452762372781150730610824357544180691092497335946993481308222", "price": "0.99", "size": "1269004.2", "side": "SELL", "hash": "c00a82cac593daaca7231aa31677e33eae8619c3", "best_bid": "0.53", "best_ask": "0.54"}], "timestamp": "1769384076304", "event_type": "price_change"}}
{"_local_timestamp": "2026-01-25T23:34:39.088851+00:00", "data": {"market": "0x0a99479228e93524b25676ae69b94bd3f4278a6bca8d8c265c84d24755399cf5", "price_changes": [{"asset_id": "67109747366255871599717338045111308888043498275177238365560740200996017915657", "price": "0.01", "size": "1268999.2", "side": "BUY", "hash": "da11b0bbedd70c98d2d832d1fda48846b6f01e22", "best_bid": "0.46", "best_ask": "0.47"}, {"asset_id": "103845791232328975452762372781150730610824357544180691092497335946993481308222", "price": "0.99", "size": "1268999.2", "side": "SELL", "hash": "a351e2a4528701400bb54902459185d84f6f0461", "best_bid": "0.53", "best_ask": "0.54"}], "timestamp": "1769384079002", "event_type": "price_change"}}
{"_local_timestamp": "2026-01-25T23:34:40.155327+00:00", "data": {"market": "0x0a99479228e93524b25676ae69b94bd3f4278a6bca8d8c265c84d24755399cf5", "price_changes": [{"asset_id": "67109747366255871599717338045111308888043498275177238365560740200996017915657", "price": "0.01", "size": "1268989.2", "side": "BUY", "hash": "4bbf6b29504b689cb881862bc73552a23bfe5983", "best_bid": "0.46", "best_ask": "0.47"}, {"asset_id": "103845791232328975452762372781150730610824357544180691092497335946993481308222", "price": "0.99", "size": "1268989.2", "side": "SELL", "hash": "acc0d5364a38d64a1e335ee663746422dc5941ce", "best_bid": "0.53", "best_ask": "0.54"}], "timestamp": "1769384080001", "event_type": "price_change"}}
{"_local_timestamp": "2026-01-25T23:34:40.155687+00:00", "data": {"market": "0x0a99479228e93524b25676ae69b94bd3f4278a6bca8d8c265c84d24755399cf5", "price_changes": [{"asset_id": "67109747366255871599717338045111308888043498275177238365560740200996017915657", "price": "0.01", "size": "1268989.2", "side": "BUY", "hash": "24a226f192570a9b3a1607da3e92ddef01759ec2", "best_bid": "0.46", "best_ask": "0.47"}, {"asset_id": "103845791232328975452762372781150730610824357544180691092497335946993481308222", "price": "0.99", "size": "1268989.2", "side": "SELL", "hash": "29f769d49f05106e950e854917d13beb041ad5de", "best_bid": "0.53", "best_ask": "0.54"}], "timestamp": "1769384080003", "event_type": "price_change"}}
{"_local_timestamp": "2026-01-25T23:34:41.162047+00:00", "data": {"market": "0x0a99479228e93524b25676ae69b94bd3f4278a6bca8d8c265c84d24755399cf5", "price_changes": [{"asset_id": "67109747366255871599717338045111308888043498275177238365560740200996017915657", "price": "0.01", "size": "1268994.2", "side": "BUY", "hash": "c3c1e255c0d07e00ea65056369f60a17a11f287f", "best_bid": "0.46", "best_ask": "0.47"}, {"asset_id": "103845791232328975452762372781150730610824357544180691092497335946993481308222", "price": "0.99", "size": "1268994.2", "side": "SELL", "hash": "e6c0e47a4e891b80ec2fb9505d066650f1a30c7f", "best_bid": "0.53", "best_ask": "0.54"}], "timestamp": "1769384081092", "event_type": "price_change"}}
{"_local_timestamp": "2026-01-25T23:34:44.083477+00:00", "data": {"market": "0x0a99479228e93524b25676ae69b94bd3f4278a6bca8d8c265c84d24755399cf5", "price_changes": [{"asset_id": "67109747366255871599717338045111308888043498275177238365560740200996017915657", "price": "0.01", "size": "1268984.2", "side": "BUY", "hash": "17bc9f6968fa46770f5107917f315ec307b5fb4d", "best_bid": "0.46", "best_ask": "0.47"}, {"asset_id": "103845791232328975452762372781150730610824357544180691092497335946993481308222", "price": "0.99", "size": "1268984.2", "side": "SELL", "hash": "667e7c3c3da23ddad948c4e974263a3014ca0f54", "best_bid": "0.53", "best_ask": "0.54"}], "timestamp": "1769384084001", "event_type": "price_change"}}
{"_local_timestamp": "2026-01-25T23:34:44.125441+00:00", "data": {"market": "0x0a99479228e93524b25676ae69b94bd3f4278a6bca8d8c265c84d24755399cf5", "price_changes": [{"asset_id": "67109747366255871599717338045111308888043498275177238365560740200996017915657", "price": "0.01", "size": "1268984.2", "side": "BUY", "hash": "93fb74c5e569ce8fb54473ff9b77b498e7e1b602", "best_bid": "0.46", "best_ask": "0.47"}, {"asset_id": "103845791232328975452762372781150730610824357544180691092497335946993481308222", "price": "0.99", "size": "1268984.2", "side": "SELL", "hash": "3dbae68b44b292145f1c0340e275426ca8df1aa4", "best_bid": "0.53", "best_ask": "0.54"}], "timestamp": "1769384084006", "event_type": "price_change"}}
{"_local_timestamp": "2026-01-25T23:34:46.086820+00:00", "data": {"market": "0x0a99479228e93524b25676ae69b94bd3f4278a6bca8d8c265c84d24755399cf5", "price_changes": [{"asset_id": "67109747366255871599717338045111308888043498275177238365560740200996017915657", "price": "0.01", "size": "1268979.2", "side": "BUY", "hash": "198b1cb345dbc9c4a0e8c56f09761126a7ce6dad", "best_bid": "0.46", "best_ask": "0.47"}, {"asset_id": "103845791232328975452762372781150730610824357544180691092497335946993481308222", "price": "0.99", "size": "1268979.2", "side": "SELL", "hash": "a89e3deae15b860562b2c99506ac0be483924600", "best_bid": "0.53", "best_ask": "0.54"}], "timestamp": "1769384086001", "event_type": "price_change"}}
{"_local_timestamp": "2026-01-25T23:34:47.315760+00:00", "data": {"market": "0x0a99479228e93524b25676ae69b94bd3f4278a6bca8d8c265c84d24755399cf5", "price_changes": [{"asset_id": "67109747366255871599717338045111308888043498275177238365560740200996017915657", "price": "0.01", "size": "1268984.2", "side": "BUY", "hash": "07f3762d9576b2bd2313277ebbd5eed94628f5d0", "best_bid": "0.46", "best_ask": "0.47"}, {"asset_id": "103845791232328975452762372781150730610824357544180691092497335946993481308222", "price": "0.99", "size": "1268984.2", "side": "SELL", "hash": "75bab3d6267355ec38209d15f6ddfd3c4d45fa6d", "best_bid": "0.53", "best_ask": "0.54"}], "timestamp": "1769384087250", "event_type": "price_change"}}
{"_local_timestamp": "2026-01-25T23:34:48.833066+00:00", "data": {"market": "0x0a99479228e93524b25676ae69b94bd3f4278a6bca8d8c265c84d24755399cf5", "price_changes": [{"asset_id": "67109747366255871599717338045111308888043498275177238365560740200996017915657", "price": "0.01", "size": "1268989.2", "side": "BUY", "hash": "68cacd95d204509e747211e15a25637aa6bd6c56", "best_bid": "0.46", "best_ask": "0.47"}, {"asset_id": "103845791232328975452762372781150730610824357544180691092497335946993481308222", "price": "0.99", "size": "1268989.2", "side": "SELL", "hash": "412f533f4f155aef0bee4bb98c4096bf3dc5aab3", "best_bid": "0.53", "best_ask": "0.54"}], "timestamp": "1769384088765", "event_type": "price_change"}}
{"_local_timestamp": "2026-01-25T23:34:49.069571+00:00", "data": {"market": "0x0a99479228e93524b25676ae69b94bd3f4278a6bca8d8c265c84d24755399cf5", "price_changes": [{"asset_id": "67109747366255871599717338045111308888043498275177238365560740200996017915657", "price": "0.01", "size": "1268984.2", "side": "BUY", "hash": "f29015750d89bce5cdbad03dae002c9a30f1bd14", "best_bid": "0.46", "best_ask": "0.47"}, {"asset_id": "103845791232328975452762372781150730610824357544180691092497335946993481308222", "price": "0.99", "size": "1268984.2", "side": "SELL", "hash": "2f8ab4d628a3be761f544a6e5ec386600ff69aa9", "best_bid": "0.53", "best_ask": "0.54"}], "timestamp": "1769384089004", "event_type": "price_change"}}
{"_local_timestamp": "2026-01-25T23:34:49.196780+00:00", "data": {"market": "0x0a99479228e93524b25676ae69b94bd3f4278a6bca8d8c265c84d24755399cf5", "price_changes": [{"asset_id": "67109747366255871599717338045111308888043498275177238365560740200996017915657", "price": "0.01", "size": "1268989.2", "side": "BUY", "hash": "ea70446af8a7dbf6d1d35b96da3ce64fe48cddeb", "best_bid": "0.46", "best_ask": "0.47"}, {"asset_id": "103845791232328975452762372781150730610824357544180691092497335946993481308222", "price": "0.99", "size": "1268989.2", "side": "SELL", "hash": "8ac37709355269eb2bf77e045cdb8c41d9e3a75f", "best_bid": "0.53", "best_ask": "0.54"}], "timestamp": "1769384089127", "event_type": "price_change"}}
{"_local_timestamp": "2026-01-25T23:34:52.109829+00:00", "data": {"market": "0x0a99479228e93524b25676ae69b94bd3f4278a6bca8d8c265c84d24755399cf5", "price_changes": [{"asset_id": "67109747366255871599717338045111308888043498275177238365560740200996017915657", "price": "0.01", "size": "1268994.2", "side": "BUY", "hash": "c3450440261ce49eb3e4c90af0ede74b0888cbe9", "best_bid": "0.46", "best_ask": "0.47"}, {"asset_id": "103845791232328975452762372781150730610824357544180691092497335946993481308222", "price": "0.99", "size": "1268994.2", "side": "SELL", "hash": "ead0a394b2d5fe79294cfd48788e939083ef1c38", "best_bid": "0.53", "best_ask": "0.54"}], "timestamp": "1769384091915", "event_type": "price_change"}}
{"_local_timestamp": "2026-01-25T23:34:52.719147+00:00", "data": {"market": "0x0a99479228e93524b25676ae69b94bd3f4278a6bca8d8c265c84d24755399cf5", "price_changes": [{"asset_id": "67109747366255871599717338045111308888043498275177238365560740200996017915657", "price": "0.01", "size": "1268999.2", "side": "BUY", "hash": "fb16f8cd5f37fd73238cb3c50a251a4d8593d68e", "best_bid": "0.46", "best_ask": "0.47"}, {"asset_id": "103845791232328975452762372781150730610824357544180691092497335946993481308222", "price": "0.99", "size": "1268999.2", "side": "SELL", "hash": "dc8c43a6c2eed3c3ceef325f1a3134ffad2ae6bb", "best_bid": "0.53", "best_ask": "0.54"}], "timestamp": "1769384092559", "event_type": "price_change"}}
{"_local_timestamp": "2026-01-25T23:34:53.197698+00:00", "data": {"market": "0x0a99479228e93524b25676ae69b94bd3f4278a6bca8d8c265c84d24755399cf5", "price_changes": [{"asset_id": "67109747366255871599717338045111308888043498275177238365560740200996017915657", "price": "0.01", "size": "1269004.2", "side": "BUY", "hash": "7622a212371ad5a5db22d58034e6c42ca1c31567", "best_bid": "0.46", "best_ask": "0.47"}, {"asset_id": "103845791232328975452762372781150730610824357544180691092497335946993481308222", "price": "0.99", "size": "1269004.2", "side": "SELL", "hash": "0fd75ee9d956e9385e1bf011f0f525a008ea0eb1", "best_bid": "0.53", "best_ask": "0.54"}], "timestamp": "1769384093012", "event_type": "price_change"}}
{"_local_timestamp": "2026-01-25T23:34:57.109692+00:00", "data": {"market": "0x0a99479228e93524b25676ae69b94bd3f4278a6bca8d8c265c84d24755399cf5", "price_changes": [{"asset_id": "67109747366255871599717338045111308888043498275177238365560740200996017915657", "price": "0.01", "size": "1268999.2", "side": "BUY", "hash": "ac9ae2099b7fa2b20a5020aa4916ebe1120951f4", "best_bid": "0.46", "best_ask": "0.47"}, {"asset_id": "103845791232328975452762372781150730610824357544180691092497335946993481308222", "price": "0.99", "size": "1268999.2", "side": "SELL", "hash": "e452f186f647b5d2b8a941dfb6dccd1a17ccade3", "best_bid": "0.53", "best_ask": "0.54"}], "timestamp": "1769384097002", "event_type": "price_change"}}
{"_local_timestamp": "2026-01-25T23:35:01.082596+00:00", "data": {"market": "0x0a99479228e93524b25676ae69b94bd3f4278a6bca8d8c265c84d24755399cf5", "price_changes": [{"asset_id": "67109747366255871599717338045111308888043498275177238365560740200996017915657", "price": "0.01", "size": "1268989.2", "side": "BUY", "hash": "5de4f772355ed8d1051dd56844ba39f4a03305c8", "best_bid": "0.46", "best_ask": "0.47"}, {"asset_id": "103845791232328975452762372781150730610824357544180691092497335946993481308222", "price": "0.99", "size": "1268989.2", "side": "SELL", "hash": "6d41f15705943c040a405136535a2bf95d3d89ff", "best_bid": "0.53", "best_ask": "0.54"}], "timestamp": "1769384101000", "event_type": "price_change"}}
{"_local_timestamp": "2026-01-25T23:35:01.090831+00:00", "data": {"market": "0x0a99479228e93524b25676ae69b94bd3f4278a6bca8d8c265c84d24755399cf5", "price_changes": [{"asset_id": "67109747366255871599717338045111308888043498275177238365560740200996017915657", "price": "0.01", "size": "1268989.2", "side": "BUY", "hash": "df018b2fddb8ab16b7b92304337563b58e20f439", "best_bid": "0.46", "best_ask": "0.47"}, {"asset_id": "103845791232328975452762372781150730610824357544180691092497335946993481308222", "price": "0.99", "size": "1268989.2", "side": "SELL", "hash": "cd6c852a3050db5bba72013528d6224e0cfdafd1", "best_bid": "0.53", "best_ask": "0.54"}], "timestamp": "1769384101002", "event_type": "price_change"}}
{"_local_timestamp": "2026-01-25T23:35:03.093996+00:00", "data": {"market": "0x0a99479228e93524b25676ae69b94bd3f4278a6bca8d8c265c84d24755399cf5", "price_changes": [{"asset_id": "67109747366255871599717338045111308888043498275177238365560740200996017915657", "price": "0.01", "size": "1268984.2", "side": "BUY", "hash": "09bee81fe290b01086591f2ebe46975d587f380b", "best_bid": "0.46", "best_ask": "0.47"}, {"asset_id": "103845791232328975452762372781150730610824357544180691092497335946993481308222", "price": "0.99", "size": "1268984.2", "side": "SELL", "hash": "ba897323c216d79f3972e5fe5019f17e0aaca1c6", "best_bid": "0.53", "best_ask": "0.54"}], "timestamp": "1769384103003", "event_type": "price_change"}}
{"_local_timestamp": "2026-01-25T23:35:03.988492+00:00", "data": {"market": "0x0a99479228e93524b25676ae69b94bd3f4278a6bca8d8c265c84d24755399cf5", "price_changes": [{"asset_id": "67109747366255871599717338045111308888043498275177238365560740200996017915657", "price": "0.01", "size": "1268989.2", "side": "BUY", "hash": "9776556e6bd3f47e75a175f03b353c59d1a91c00", "best_bid": "0.46", "best_ask": "0.47"}, {"asset_id": "103845791232328975452762372781150730610824357544180691092497335946993481308222", "price": "0.99", "size": "1268989.2", "side": "SELL", "hash": "767a7c9a1752d8259a64ff97512d7a03af50bcad", "best_bid": "0.53", "best_ask": "0.54"}], "timestamp": "1769384103918", "event_type": "price_change"}}
{"_local_timestamp": "2026-01-25T23:35:04.890456+00:00", "data": {"market": "0x0a99479228e93524b25676ae69b94bd3f4278a6bca8d8c265c84d24755399cf5", "price_changes": [{"asset_id": "67109747366255871599717338045111308888043498275177238365560740200996017915657", "price": "0.01", "size": "1268994.2", "side": "BUY", "hash": "e1273c0e638874ab7f9a6674d164439703eeba9b", "best_bid": "0.46", "best_ask": "0.47"}, {"asset_id": "103845791232328975452762372781150730610824357544180691092497335946993481308222", "price": "0.99", "size": "1268994.2", "side": "SELL", "hash": "8cfca805738f171682cd8433c89db1c748a53a6d", "best_bid": "0.53", "best_ask": "0.54"}], "timestamp": "1769384104826", "event_type": "price_change"}}
{"_local_timestamp": "2026-01-25T23:35:05.880349+00:00", "data": {"market": "0x0a99479228e93524b25676ae69b94bd3f4278a6bca8d8c265c84d24755399cf5", "price_changes": [{"asset_id": "67109747366255871599717338045111308888043498275177238365560740200996017915657", "price": "0.01", "size": "1268999.2", "side": "BUY", "hash": "fb0a5dd8c2c01b001694f2fded3a3e3a4c76b155", "best_bid": "0.46", "best_ask": "0.47"}, {"asset_id": "103845791232328975452762372781150730610824357544180691092497335946993481308222", "price": "0.99", "size": "1268999.2", "side": "SELL", "hash": "610a90c561cc96888addad48f8cc0cea308ddbd7", "best_bid": "0.53", "best_ask": "0.54"}], "timestamp": "1769384105817", "event_type": "price_change"}}
{"_local_timestamp": "2026-01-25T23:35:06.104760+00:00", "data": {"market": "0x0a99479228e93524b25676ae69b94bd3f4278a6bca8d8c265c84d24755399cf5", "price_changes": [{"asset_id": "67109747366255871599717338045111308888043498275177238365560740200996017915657", "price": "0.01", "size": "1268994.2", "side": "BUY", "hash": "4f4d5d6b079d32a2fe208624ff293dccc3538461", "best_bid": "0.46", "best_ask": "0.47"}, {"asset_id": "103845791232328975452762372781150730610824357544180691092497335946993481308222", "price": "0.99", "size": "1268994.2", "side": "SELL", "hash": "e6a66fc18874d76d952efff72c91abaaf0af5a4a", "best_bid": "0.53", "best_ask": "0.54"}], "timestamp": "1769384106007", "event_type": "price_change"}}
{"_local_timestamp": "2026-01-25T23:35:06.972538+00:00", "data": {"market": "0x0a99479228e93524b25676ae69b94bd3f4278a6bca8d8c265c84d24755399cf5", "price_changes": [{"asset_id": "67109747366255871599717338045111308888043498275177238365560740200996017915657", "price": "0.01", "size": "1268999.2", "side": "BUY", "hash": "499608c45373b7e3feccb5aff6506d8317df47d9", "best_bid": "0.46", "best_ask": "0.47"}, {"asset_id": "103845791232328975452762372781150730610824357544180691092497335946993481308222", "price": "0.99", "size": "1268999.2", "side": "SELL", "hash": "98429904cd3d75f385cfc04dea59dab668cb90f5", "best_bid": "0.53", "best_ask": "0.54"}], "timestamp": "1769384106876", "event_type": "price_change"}}
{"_local_timestamp": "2026-01-25T23:35:07.113841+00:00", "data": {"market": "0x0a99479228e93524b25676ae69b94bd3f4278a6bca8d8c265c84d24755399cf5", "price_changes": [{"asset_id": "67109747366255871599717338045111308888043498275177238365560740200996017915657", "price": "0.01", "size": "1268994.2", "side": "BUY", "hash": "c00520d980d7499c6b707952325b896853ff862a", "best_bid": "0.46", "best_ask": "0.47"}, {"asset_id": "103845791232328975452762372781150730610824357544180691092497335946993481308222", "price": "0.99", "size": "1268994.2", "side": "SELL", "hash": "03fa651cc3eb993e7261d8adf89c76992f65d9d3", "best_bid": "0.53", "best_ask": "0.54"}], "timestamp": "1769384107002", "event_type": "price_change"}}
{"_local_timestamp": "2026-01-25T23:35:10.092298+00:00", "data": {"market": "0x0a99479228e93524b25676ae69b94bd3f4278a6bca8d8c265c84d24755399cf5", "price_changes": [{"asset_id": "67109747366255871599717338045111308888043498275177238365560740200996017915657", "price": "0.01", "size": "1268999.2", "side": "BUY", "hash": "d21b4e00cbd7f13a136a747fb4e09d482a7fefd9", "best_bid": "0.46", "best_ask": "0.47"}, {"asset_id": "103845791232328975452762372781150730610824357544180691092497335946993481308222", "price": "0.99", "size": "1268999.2", "side": "SELL", "hash": "32ba68913fe77939f5a810f0d8cf90a8078d0ef5", "best_bid": "0.53", "best_ask": "0.54"}], "timestamp": "1769384109808", "event_type": "price_change"}}
{"_local_timestamp": "2026-01-25T23:35:10.092747+00:00", "data": {"market": "0x0a99479228e93524b25676ae69b94bd3f4278a6bca8d8c265c84d24755399cf5", "price_changes": [{"asset_id": "67109747366255871599717338045111308888043498275177238365560740200996017915657", "price": "0.01", "size": "1269004.2", "side": "BUY", "hash": "a4618284c58e477e08a9d14f41e2f30fca506932", "best_bid": "0.46", "best_ask": "0.47"}, {"asset_id": "103845791232328975452762372781150730610824357544180691092497335946993481308222", "price": "0.99", "size": "1269004.2", "side": "SELL", "hash": "b2ab5744cb6c929f76f53ad39c9fd9dd7bc4ce8b", "best_bid": "0.53", "best_ask": "0.54"}], "timestamp": "1769384109900", "event_type": "price_change"}}
{"_local_timestamp": "2026-01-25T23:35:10.093030+00:00", "data": {"market": "0x0a99479228e93524b25676ae69b94bd3f4278a6bca8d8c265c84d24755399cf5", "price_changes": [{"asset_id": "67109747366255871599717338045111308888043498275177238365560740200996017915657", "price": "0.01", "size": "1268999.2", "side": "BUY", "hash": "77f719c11a1dba523b1b35ab26aa88146db351d1", "best_bid": "0.46", "best_ask": "0.47"}, {"asset_id": "103845791232328975452762372781150730610824357544180691092497335946993481308222", "price": "0.99", "size": "1268999.2", "side": "SELL", "hash": "84d8f8474b95c35e5b7938b47b95c038bf7a5ce4", "best_bid": "0.53", "best_ask": "0.54"}], "timestamp": "1769384110000", "event_type": "price_change"}}
{"_local_timestamp": "2026-01-25T23:35:12.342828+00:00", "data": {"market": "0x0a99479228e93524b25676ae69b94bd3f4278a6bca8d8c265c84d24755399cf5", "price_changes": [{"asset_id": "67109747366255871599717338045111308888043498275177238365560740200996017915657", "price": "0.01", "size": "1269004.2", "side": "BUY", "hash": "9861c6c409776bbf17eadaa24537639d4f3024eb", "best_bid": "0.46", "best_ask": "0.47"}, {"asset_id": "103845791232328975452762372781150730610824357544180691092497335946993481308222", "price": "0.99", "size": "1269004.2", "side": "SELL", "hash": "de1ac1c945e9b6ca74677faba31d95fc92877bfe", "best_bid": "0.53", "best_ask": "0.54"}], "timestamp": "1769384112271", "event_type": "price_change"}}
{"_local_timestamp": "2026-01-25T23:35:14.082053+00:00", "data": {"market": "0x0a99479228e93524b25676ae69b94bd3f4278a6bca8d8c265c84d24755399cf5", "price_changes": [{"asset_id": "67109747366255871599717338045111308888043498275177238365560740200996017915657", "price": "0.01", "size": "1268999.2", "side": "BUY", "hash": "fd79324b4a2ef5ad512ff572c0eca6994a212265", "best_bid": "0.46", "best_ask": "0.47"}, {"asset_id": "103845791232328975452762372781150730610824357544180691092497335946993481308222", "price": "0.99", "size": "1268999.2", "side": "SELL", "hash": "c27740e9c780ee3b950039a2bc6175313da6ebab", "best_bid": "0.53", "best_ask": "0.54"}], "timestamp": "1769384114000", "event_type": "price_change"}}
{"_local_timestamp": "2026-01-25T23:35:15.085334+00:00", "data": {"market": "0x0a99479228e93524b25676ae69b94bd3f4278a6bca8d8c265c84d24755399cf5", "price_changes": [{"asset_id": "67109747366255871599717338045111308888043498275177238365560740200996017915657", "price": "0.01", "size": "1268994.2", "side": "BUY", "hash": "d1d8b91a5af803a784920f212735767d1cd8bb4a", "best_bid": "0.46", "best_ask": "0.47"}, {"asset_id": "103845791232328975452762372781150730610824357544180691092497335946993481308222", "price": "0.99", "size": "1268994.2", "side": "SELL", "hash": "70854897bb705943b9c601440dd5fd332c6795fb", "best_bid": "0.53", "best_ask": "0.54"}], "timestamp": "1769384115002", "event_type": "price_change"}}
{"_local_timestamp": "2026-01-25T23:35:17.067958+00:00", "data": {"market": "0x0a99479228e93524b25676ae69b94bd3f4278a6bca8d8c265c84d24755399cf5", "price_changes": [{"asset_id": "67109747366255871599717338045111308888043498275177238365560740200996017915657", "price": "0.01", "size": "1268989.2", "side": "BUY", "hash": "83080310a534083c38004a0c82c49949f470afbf", "best_bid": "0.46", "best_ask": "0.47"}, {"asset_id": "103845791232328975452762372781150730610824357544180691092497335946993481308222", "price": "0.99", "size": "1268989.2", "side": "SELL", "hash": "a50ec200d62cdba472420ebdf3f98a7cee4699fc", "best_bid": "0.53", "best_ask": "0.54"}], "timestamp": "1769384117002", "event_type": "price_change"}}
{"_local_timestamp": "2026-01-25T23:35:18.070940+00:00", "data": {"market": "0x0a99479228e93524b25676ae69b94bd3f4278a6bca8d8c265c84d24755399cf5", "price_changes": [{"asset_id": "67109747366255871599717338045111308888043498275177238365560740200996017915657", "price": "0.01", "size": "1268984.2", "side": "BUY", "hash": "1f97adf008798841cc9680eb7b5926e3b76f5054", "best_bid": "0.46", "best_ask": "0.47"}, {"asset_id": "103845791232328975452762372781150730610824357544180691092497335946993481308222", "price": "0.99", "size": "1268984.2", "side": "SELL", "hash": "9f2fc458d4659721e85808d58d5c41e55ce1a400", "best_bid": "0.53", "best_ask": "0.54"}], "timestamp": "1769384118000", "event_type": "price_change"}}
{"_local_timestamp": "2026-01-25T23:35:19.091950+00:00", "data": {"market": "0x0a99479228e93524b25676ae69b94bd3f4278a6bca8d8c265c84d24755399cf5", "price_changes": [{"asset_id": "67109747366255871599717338045111308888043498275177238365560740200996017915657", "price": "0.01", "size": "1268979.2", "side": "BUY", "hash": "f84fc3a9e9997cc0efbc5001f46972e1c1424ce5", "best_bid": "0.46", "best_ask": "0.47"}, {"asset_id": "103845791232328975452762372781150730610824357544180691092497335946993481308222", "price": "0.99", "size": "1268979.2", "side": "SELL", "hash": "87de6e9a2a72b79cbcbe68ba315a71a87c85dbc5", "best_bid": "0.53", "best_ask": "0.54"}], "timestamp": "1769384119000", "event_type": "price_change"}}
{"_local_timestamp": "2026-01-25T23:35:20.662667+00:00", "data": {"market": "0x0a99479228e93524b25676ae69b94bd3f4278a6bca8d8c265c84d24755399cf5", "price_changes": [{"asset_id": "67109747366255871599717338045111308888043498275177238365560740200996017915657", "price": "0.01", "size": "1268984.2", "side": "BUY", "hash": "4e216c4dd04a94574bafd19a7ea262d3a1305191", "best_bid": "0.46", "best_ask": "0.47"}, {"asset_id": "103845791232328975452762372781150730610824357544180691092497335946993481308222", "price": "0.99", "size": "1268984.2", "side": "SELL", "hash": "356ee83e3cc3d1236ae13b19cc8fa6dede2cbf9b", "best_bid": "0.53", "best_ask": "0.54"}], "timestamp": "1769384120598", "event_type": "price_change"}}
{"_local_timestamp": "2026-01-25T23:35:22.621893+00:00", "data": {"market": "0x0a99479228e93524b25676ae69b94bd3f4278a6bca8d8c265c84d24755399cf5", "price_changes": [{"asset_id": "67109747366255871599717338045111308888043498275177238365560740200996017915657", "price": "0.01", "size": "1268989.2", "side": "BUY", "hash": "ed8b20fea1361d4752974b132d9c4e8b42c64165", "best_bid": "0.46", "best_ask": "0.47"}, {"asset_id": "103845791232328975452762372781150730610824357544180691092497335946993481308222", "price": "0.99", "size": "1268989.2", "side": "SELL", "hash": "5efb9ff2d0ce3c8976d54130390fb19668fc80ac", "best_bid": "0.53", "best_ask": "0.54"}], "timestamp": "1769384122555", "event_type": "price_change"}}
{"_local_timestamp": "2026-01-25T23:35:22.985654+00:00", "data": {"market": "0x0a99479228e93524b25676ae69b94bd3f4278a6bca8d8c265c84d24755399cf5", "price_changes": [{"asset_id": "67109747366255871599717338045111308888043498275177238365560740200996017915657", "price": "0.01", "size": "1268994.2", "side": "BUY", "hash": "d8514338956dd668828cf6a88f708ede615ecaab", "best_bid": "0.46", "best_ask": "0.47"}, {"asset_id": "103845791232328975452762372781150730610824357544180691092497335946993481308222", "price": "0.99", "size": "1268994.2", "side": "SELL", "hash": "e77b9ce7fd9ee91588c3f0aa51c0ca2eb3876a35", "best_bid": "0.53", "best_ask": "0.54"}], "timestamp": "1769384122922", "event_type": "price_change"}}
{"_local_timestamp": "2026-01-25T23:35:23.109425+00:00", "data": {"market": "0x0a99479228e93524b25676ae69b94bd3f4278a6bca8d8c265c84d24755399cf5", "price_changes": [{"asset_id": "67109747366255871599717338045111308888043498275177238365560740200996017915657", "price": "0.01", "size": "1268989.2", "side": "BUY", "hash": "b208fd136aec375f6fc5b5f693cdb28dd2286af6", "best_bid": "0.46", "best_ask": "0.47"}, {"asset_id": "103845791232328975452762372781150730610824357544180691092497335946993481308222", "price": "0.99", "size": "1268989.2", "side": "SELL", "hash": "7217b6603d3df5c7d250aa8cdaf40d9ae6b5a22f", "best_bid": "0.53", "best_ask": "0.54"}], "timestamp": "1769384123003", "event_type": "price_change"}}
{"_local_timestamp": "2026-01-25T23:35:24.574686+00:00", "data": {"market": "0x0a99479228e93524b25676ae69b94bd3f4278a6bca8d8c265c84d24755399cf5", "price_changes": [{"asset_id": "67109747366255871599717338045111308888043498275177238365560740200996017915657", "price": "0.01", "size": "1268994.2", "side": "BUY", "hash": "0ef40b4a0d7d7897a4e1c39df280528e2e6f9fc0", "best_bid": "0.46", "best_ask": "0.47"}, {"asset_id": "103845791232328975452762372781150730610824357544180691092497335946993481308222", "price": "0.99", "size": "1268994.2", "side": "SELL", "hash": "aec9779dad3f1334ec3433ada214889f99984cc5", "best_bid": "0.53", "best_ask": "0.54"}], "timestamp": "1769384124351", "event_type": "price_change"}}
{"_local_timestamp": "2026-01-25T23:35:25.458895+00:00", "data": {"market": "0xb106a3c9d1c59ed8117493dae6459a3ff79369a8f7cddaf62f4a05828b89195e", "price_changes": [{"asset_id": "1376044590327709616459174469529480611299625159235587466149878628404281805565", "price": "0.46", "size": "15339.19", "side": "BUY", "hash": "c43df5e2024321a2c4513f1c318e236bb0404fea", "best_bid": "0.46", "best_ask": "0.47"}, {"asset_id": "49084048476353771153083262278964615095037480324537117350127265918750912547378", "price": "0.54", "size": "15339.19", "side": "SELL", "hash": "6b3872a1b69e7f6bb410ce50f58809b01d4d6384", "best_bid": "0.53", "best_ask": "0.54"}], "timestamp": "1769384125395", "event_type": "price_change"}}
{"_local_timestamp": "2026-01-25T23:35:25.459305+00:00", "data": {"market": "0x0a99479228e93524b25676ae69b94bd3f4278a6bca8d8c265c84d24755399cf5", "price_changes": [{"asset_id": "103845791232328975452762372781150730610824357544180691092497335946993481308222", "price": "0.53", "size": "22398.59", "side": "BUY", "hash": "0ddcab4bef36c113c325a9c220a77966ff73011c", "best_bid": "0.53", "best_ask": "0.54"}, {"asset_id": "67109747366255871599717338045111308888043498275177238365560740200996017915657", "price": "0.47", "size": "22398.59", "side": "SELL", "hash": "5f6b1b5533fd6d1bcbabe7d910950c1d7cd95c30", "best_bid": "0.46", "best_ask": "0.47"}], "timestamp": "1769384125394", "event_type": "price_change"}}
{"_local_timestamp": "2026-01-25T23:35:25.459563+00:00", "data": {"market": "0xb106a3c9d1c59ed8117493dae6459a3ff79369a8f7cddaf62f4a05828b89195e", "price_changes": [{"asset_id": "49084048476353771153083262278964615095037480324537117350127265918750912547378", "price": "0.5", "size": "4525", "side": "BUY", "hash": "d03b8bfd7fa1b98e94bc80817beab943b276bd2a", "best_bid": "0.53", "best_ask": "0.54"}, {"asset_id": "1376044590327709616459174469529480611299625159235587466149878628404281805565", "price": "0.5", "size": "4525", "side": "SELL", "hash": "8196e5886c1ace49471490dae56a44d86d59c056", "best_bid": "0.46", "best_ask": "0.47"}], "timestamp": "1769384125395", "event_type": "price_change"}}
{"_local_timestamp": "2026-01-25T23:35:25.459836+00:00", "data": {"market": "0x0a99479228e93524b25676ae69b94bd3f4278a6bca8d8c265c84d24755399cf5", "price_changes": [{"asset_id": "67109747366255871599717338045111308888043498275177238365560740200996017915657", "price": "0.43", "size": "2505", "side": "BUY", "hash": "49b1933a2d59c844926cd1fcf7991d32408dae26", "best_bid": "0.46", "best_ask": "0.47"}, {"asset_id": "103845791232328975452762372781150730610824357544180691092497335946993481308222", "price": "0.57", "size": "2505", "side": "SELL", "hash": "6b73e0692a350e9878f119a00b6223ec72380ef0", "best_bid": "0.53", "best_ask": "0.54"}], "timestamp": "1769384125395", "event_type": "price_change"}}
{"_local_timestamp": "2026-01-25T23:35:26.796586+00:00", "data": {"market": "0x0a99479228e93524b25676ae69b94bd3f4278a6bca8d8c265c84d24755399cf5", "price_changes": [{"asset_id": "67109747366255871599717338045111308888043498275177238365560740200996017915657", "price": "0.01", "size": "1268999.2", "side": "BUY", "hash": "9448c3371fb0597d451675bcd1eb72c97431035c", "best_bid": "0.46", "best_ask": "0.47"}, {"asset_id": "103845791232328975452762372781150730610824357544180691092497335946993481308222", "price": "0.99", "size": "1268999.2", "side": "SELL", "hash": "9d71dce5513278603e3a8b294ecacf7999201742", "best_bid": "0.53", "best_ask": "0.54"}], "timestamp": "1769384126600", "event_type": "price_change"}}
{"_local_timestamp": "2026-01-25T23:35:27.278423+00:00", "data": {"market": "0x0a99479228e93524b25676ae69b94bd3f4278a6bca8d8c265c84d24755399cf5", "price_changes": [{"asset_id": "67109747366255871599717338045111308888043498275177238365560740200996017915657", "price": "0.01", "size": "1269004.2", "side": "BUY", "hash": "e681a2c1e0c47a5afa910866efab555b0fad364e", "best_bid": "0.46", "best_ask": "0.47"}, {"asset_id": "103845791232328975452762372781150730610824357544180691092497335946993481308222", "price": "0.99", "size": "1269004.2", "side": "SELL", "hash": "fa76ec8e50f38512098eeb4c3ad0ab54fe9ce376", "best_bid": "0.53", "best_ask": "0.54"}], "timestamp": "1769384127055", "event_type": "price_change"}}
{"_local_timestamp": "2026-01-25T23:35:32.108339+00:00", "data": {"market": "0x0a99479228e93524b25676ae69b94bd3f4278a6bca8d8c265c84d24755399cf5", "price_changes": [{"asset_id": "67109747366255871599717338045111308888043498275177238365560740200996017915657", "price": "0.01", "size": "1268999.2", "side": "BUY", "hash": "6ffa8428a43e073fa5127047df8acd903670c834", "best_bid": "0.46", "best_ask": "0.47"}, {"asset_id": "103845791232328975452762372781150730610824357544180691092497335946993481308222", "price": "0.99", "size": "1268999.2", "side": "SELL", "hash": "7248bbb50e49ed152d5a05f5dc322a8081688ec9", "best_bid": "0.53", "best_ask": "0.54"}], "timestamp": "1769384132003", "event_type": "price_change"}}
{"_local_timestamp": "2026-01-25T23:35:34.098944+00:00", "data": {"market": "0x0a99479228e93524b25676ae69b94bd3f4278a6bca8d8c265c84d24755399cf5", "price_changes": [{"asset_id": "67109747366255871599717338045111308888043498275177238365560740200996017915657", "price": "0.01", "size": "1268994.2", "side": "BUY", "hash": "82c2a068a50b48e08e6c4ad9aa739d9eec51dea7", "best_bid": "0.46", "best_ask": "0.47"}, {"asset_id": "103845791232328975452762372781150730610824357544180691092497335946993481308222", "price": "0.99", "size": "1268994.2", "side": "SELL", "hash": "6a37003d0fbc44463353ef1413d0529dda30879f", "best_bid": "0.53", "best_ask": "0.54"}], "timestamp": "1769384134001", "event_type": "price_change"}}
{"_local_timestamp": "2026-01-25T23:35:36.091773+00:00", "data": {"market": "0x0a99479228e93524b25676ae69b94bd3f4278a6bca8d8c265c84d24755399cf5", "price_changes": [{"asset_id": "67109747366255871599717338045111308888043498275177238365560740200996017915657", "price": "0.01", "size": "1268984.2", "side": "BUY", "hash": "77286dbc315cc9669df9b0a7c33e1698dd6d9ce0", "best_bid": "0.46", "best_ask": "0.47"}, {"asset_id": "103845791232328975452762372781150730610824357544180691092497335946993481308222", "price": "0.99", "size": "1268984.2", "side": "SELL", "hash": "de7b86421ac51e42757f075a561541604f3d3455", "best_bid": "0.53", "best_ask": "0.54"}], "timestamp": "1769384136001", "event_type": "price_change"}}
{"_local_timestamp": "2026-01-25T23:35:36.100540+00:00", "data": {"market": "0x0a99479228e93524b25676ae69b94bd3f4278a6bca8d8c265c84d24755399cf5", "price_changes": [{"asset_id": "67109747366255871599717338045111308888043498275177238365560740200996017915657", "price": "0.01", "size": "1268984.2", "side": "BUY", "hash": "b9855eb578c536e9fa9d4907f72c86eb45025115", "best_bid": "0.46", "best_ask": "0.47"}, {"asset_id": "103845791232328975452762372781150730610824357544180691092497335946993481308222", "price": "0.99", "size": "1268984.2", "side": "SELL", "hash": "846b0aae458de0f9d864e67540f409082df690ec", "best_bid": "0.53", "best_ask": "0.54"}], "timestamp": "1769384136004", "event_type": "price_change"}}
{"_local_timestamp": "2026-01-25T23:35:37.362380+00:00", "data": {"market": "0x0a99479228e93524b25676ae69b94bd3f4278a6bca8d8c265c84d24755399cf5", "price_changes": [{"asset_id": "67109747366255871599717338045111308888043498275177238365560740200996017915657", "price": "0.01", "size": "1268989.2", "side": "BUY", "hash": "fc265c04964d6f299746b2f8d60e0faed6b7d98e", "best_bid": "0.46", "best_ask": "0.47"}, {"asset_id": "103845791232328975452762372781150730610824357544180691092497335946993481308222", "price": "0.99", "size": "1268989.2", "side": "SELL", "hash": "d155f2467e9e0602b8c2be655fc888d29baa53a4", "best_bid": "0.53", "best_ask": "0.54"}], "timestamp": "1769384137295", "event_type": "price_change"}}
{"_local_timestamp": "2026-01-25T23:35:38.077739+00:00", "data": {"market": "0x0a99479228e93524b25676ae69b94bd3f4278a6bca8d8c265c84d24755399cf5", "price_changes": [{"asset_id": "67109747366255871599717338045111308888043498275177238365560740200996017915657", "price": "0.01", "size": "1268984.2", "side": "BUY", "hash": "b55e66cff216dd4ca2e4783ca299188fe825029b", "best_bid": "0.46", "best_ask": "0.47"}, {"asset_id": "103845791232328975452762372781150730610824357544180691092497335946993481308222", "price": "0.99", "size": "1268984.2", "side": "SELL", "hash": "5745765e666d634e4cf48e18f69c6d680a610986", "best_bid": "0.53", "best_ask": "0.54"}], "timestamp": "1769384138001", "event_type": "price_change"}}
{"_local_timestamp": "2026-01-25T23:35:38.616723+00:00", "data": {"market": "0x0a99479228e93524b25676ae69b94bd3f4278a6bca8d8c265c84d24755399cf5", "price_changes": [{"asset_id": "67109747366255871599717338045111308888043498275177238365560740200996017915657", "price": "0.01", "size": "1268989.2", "side": "BUY", "hash": "651aa638bfcd14b58a07b5505e215aa520f78034", "best_bid": "0.46", "best_ask": "0.47"}, {"asset_id": "103845791232328975452762372781150730610824357544180691092497335946993481308222", "price": "0.99", "size": "1268989.2", "side": "SELL", "hash": "32e67a0612a3d1dfbfe4724e4a58ed4924518429", "best_bid": "0.53", "best_ask": "0.54"}], "timestamp": "1769384138529", "event_type": "price_change"}}
{"_local_timestamp": "2026-01-25T23:35:39.095123+00:00", "data": {"market": "0x0a99479228e93524b25676ae69b94bd3f4278a6bca8d8c265c84d24755399cf5", "price_changes": [{"asset_id": "67109747366255871599717338045111308888043498275177238365560740200996017915657", "price": "0.01", "size": "1268984.2", "side": "BUY", "hash": "c0ded803e97bf4d158b2f5b3bc17cbf218e524ba", "best_bid": "0.46", "best_ask": "0.47"}, {"asset_id": "103845791232328975452762372781150730610824357544180691092497335946993481308222", "price": "0.99", "size": "1268984.2", "side": "SELL", "hash": "3d001219aabc64058396046d29101f9f39157a52", "best_bid": "0.53", "best_ask": "0.54"}], "timestamp": "1769384139001", "event_type": "price_change"}}
{"_local_timestamp": "2026-01-25T23:35:39.286211+00:00", "data": {"market": "0x0a99479228e93524b25676ae69b94bd3f4278a6bca8d8c265c84d24755399cf5", "price_changes": [{"asset_id": "67109747366255871599717338045111308888043498275177238365560740200996017915657", "price": "0.01", "size": "1268989.2", "side": "BUY", "hash": "e4e6d658bcecc2ca339aaa28e493d2e07c2f79c9", "best_bid": "0.46", "best_ask": "0.47"}, {"asset_id": "103845791232328975452762372781150730610824357544180691092497335946993481308222", "price": "0.99", "size": "1268989.2", "side": "SELL", "hash": "90657067a4ba9ea8a1f6b310ccdcffdeef179101", "best_bid": "0.53", "best_ask": "0.54"}], "timestamp": "1769384139197", "event_type": "price_change"}}
{"_local_timestamp": "2026-01-25T23:35:42.083981+00:00", "data": {"market": "0x0a99479228e93524b25676ae69b94bd3f4278a6bca8d8c265c84d24755399cf5", "price_changes": [{"asset_id": "67109747366255871599717338045111308888043498275177238365560740200996017915657", "price": "0.01", "size": "1268984.2", "side": "BUY", "hash": "bb6e20730b7af1d9bbdff88ddc3b87ca55a5e392", "best_bid": "0.46", "best_ask": "0.47"}, {"asset_id": "103845791232328975452762372781150730610824357544180691092497335946993481308222", "price": "0.99", "size": "1268984.2", "side": "SELL", "hash": "195c2e375efb6bfc8c6137b02bc25140bddf5ae1", "best_bid": "0.53", "best_ask": "0.54"}], "timestamp": "1769384142000", "event_type": "price_change"}}
{"_local_timestamp": "2026-01-25T23:35:42.096567+00:00", "data": {"market": "0x0a99479228e93524b25676ae69b94bd3f4278a6bca8d8c265c84d24755399cf5", "price_changes": [{"asset_id": "67109747366255871599717338045111308888043498275177238365560740200996017915657", "price": "0.01", "size": "1268989.2", "side": "BUY", "hash": "a14f22a3c2d2ad616eb861f0d0c56d2abe6c0808", "best_bid": "0.46", "best_ask": "0.47"}, {"asset_id": "103845791232328975452762372781150730610824357544180691092497335946993481308222", "price": "0.99", "size": "1268989.2", "side": "SELL", "hash": "2ade14ed86f33727716899561efc9596603c5b3c", "best_bid": "0.53", "best_ask": "0.54"}], "timestamp": "1769384142021", "event_type": "price_change"}}
{"_local_timestamp": "2026-01-25T23:35:43.293317+00:00", "data": {"market": "0x0a99479228e93524b25676ae69b94bd3f4278a6bca8d8c265c84d24755399cf5", "price_changes": [{"asset_id": "67109747366255871599717338045111308888043498275177238365560740200996017915657", "price": "0.01", "size": "1268994.2", "side": "BUY", "hash": "0f1e07465de5f52421197096429b85a142cc6642", "best_bid": "0.46", "best_ask": "0.47"}, {"asset_id": "103845791232328975452762372781150730610824357544180691092497335946993481308222", "price": "0.99", "size": "1268994.2", "side": "SELL", "hash": "916c1c42f50cd49e8f433d28acb208f0d3db03ab", "best_bid": "0.53", "best_ask": "0.54"}], "timestamp": "1769384143224", "event_type": "price_change"}}
{"_local_timestamp": "2026-01-25T23:35:43.340989+00:00", "data": {"market": "0x0a99479228e93524b25676ae69b94bd3f4278a6bca8d8c265c84d24755399cf5", "price_changes": [{"asset_id": "67109747366255871599717338045111308888043498275177238365560740200996017915657", "price": "0.01", "size": "1268999.2", "side": "BUY", "hash": "bdc737be06a1a1f73243d0992d77970531f0e9c4", "best_bid": "0.46", "best_ask": "0.47"}, {"asset_id": "103845791232328975452762372781150730610824357544180691092497335946993481308222", "price": "0.99", "size": "1268999.2", "side": "SELL", "hash": "725e9c1d978c07e1e54938fdffc3eafa8acc21a6", "best_bid": "0.53", "best_ask": "0.54"}], "timestamp": "1769384143274", "event_type": "price_change"}}
{"_local_timestamp": "2026-01-25T23:35:44.206750+00:00", "data": {"market": "0x0a99479228e93524b25676ae69b94bd3f4278a6bca8d8c265c84d24755399cf5", "price_changes": [{"asset_id": "67109747366255871599717338045111308888043498275177238365560740200996017915657", "price": "0.01", "size": "1269004.2", "side": "BUY", "hash": "73036ba8df549e45454c2eb03502bcc10f4c368e", "best_bid": "0.46", "best_ask": "0.47"}, {"asset_id": "103845791232328975452762372781150730610824357544180691092497335946993481308222", "price": "0.99", "size": "1269004.2", "side": "SELL", "hash": "476e8394b8f5024ceded70c45a40572952254612", "best_bid": "0.53", "best_ask": "0.54"}], "timestamp": "1769384144140", "event_type": "price_change"}}
{"_local_timestamp": "2026-01-25T23:35:47.086541+00:00", "data": {"market": "0x0a99479228e93524b25676ae69b94bd3f4278a6bca8d8c265c84d24755399cf5", "price_changes": [{"asset_id": "67109747366255871599717338045111308888043498275177238365560740200996017915657", "price": "0.01", "size": "1268999.2", "side": "BUY", "hash": "8370642c39c45e4f6081ec38854336cfc813a9b4", "best_bid": "0.46", "best_ask": "0.47"}, {"asset_id": "103845791232328975452762372781150730610824357544180691092497335946993481308222", "price": "0.99", "size": "1268999.2", "side": "SELL", "hash": "58ce8fc7720b95921668031084556d0062eb8b1b", "best_bid": "0.53", "best_ask": "0.54"}], "timestamp": "1769384147003", "event_type": "price_change"}}
{"_local_timestamp": "2026-01-25T23:35:49.115416+00:00", "data": {"market": "0x0a99479228e93524b25676ae69b94bd3f4278a6bca8d8c265c84d24755399cf5", "price_changes": [{"asset_id": "67109747366255871599717338045111308888043498275177238365560740200996017915657", "price": "0.01", "size": "1268994.2", "side": "BUY", "hash": "5e4af66cf417571ac930c1a7e48c334357fca7be", "best_bid": "0.46", "best_ask": "0.47"}, {"asset_id": "103845791232328975452762372781150730610824357544180691092497335946993481308222", "price": "0.99", "size": "1268994.2", "side": "SELL", "hash": "42758793b72eb6e3014fd109c572bfba03c93405", "best_bid": "0.53", "best_ask": "0.54"}], "timestamp": "1769384149002", "event_type": "price_change"}}
{"_local_timestamp": "2026-01-25T23:35:50.121623+00:00", "data": {"market": "0x0a99479228e93524b25676ae69b94bd3f4278a6bca8d8c265c84d24755399cf5", "price_changes": [{"asset_id": "67109747366255871599717338045111308888043498275177238365560740200996017915657", "price": "0.01", "size": "1268989.2", "side": "BUY", "hash": "ef7b8ad915eb7263bae359f72c9a21cfb08d1e21", "best_bid": "0.46", "best_ask": "0.47"}, {"asset_id": "103845791232328975452762372781150730610824357544180691092497335946993481308222", "price": "0.99", "size": "1268989.2", "side": "SELL", "hash": "064c3437463dc7667cb6f5a4c18326ba281af5da", "best_bid": "0.53", "best_ask": "0.54"}], "timestamp": "1769384150001", "event_type": "price_change"}}
{"_local_timestamp": "2026-01-25T23:35:53.072306+00:00", "data": {"market": "0x0a99479228e93524b25676ae69b94bd3f4278a6bca8d8c265c84d24755399cf5", "price_changes": [{"asset_id": "67109747366255871599717338045111308888043498275177238365560740200996017915657", "price": "0.01", "size": "1268979.2", "side": "BUY", "hash": "5a1dcde27360533a025c85ee61ac4aa8191d29eb", "best_bid": "0.46", "best_ask": "0.47"}, {"asset_id": "103845791232328975452762372781150730610824357544180691092497335946993481308222", "price": "0.99", "size": "1268979.2", "side": "SELL", "hash": "6b5efff0cee179e6367a81b6bc1a3c146a437661", "best_bid": "0.53", "best_ask": "0.54"}], "timestamp": "1769384153000", "event_type": "price_change"}}
{"_local_timestamp": "2026-01-25T23:35:53.080437+00:00", "data": {"market": "0x0a99479228e93524b25676ae69b94bd3f4278a6bca8d8c265c84d24755399cf5", "price_changes": [{"asset_id": "67109747366255871599717338045111308888043498275177238365560740200996017915657", "price": "0.01", "size": "1268979.2", "side": "BUY", "hash": "c67d98d60e1d1f3eaffbffd8916c0096b53597c5", "best_bid": "0.46", "best_ask": "0.47"}, {"asset_id": "103845791232328975452762372781150730610824357544180691092497335946993481308222", "price": "0.99", "size": "1268979.2", "side": "SELL", "hash": "a24d1cbb1b2f7719d267ee43e1766d02485ccfa1", "best_bid": "0.53", "best_ask": "0.54"}], "timestamp": "1769384153002", "event_type": "price_change"}}
{"_local_timestamp": "2026-01-25T23:35:54.060421+00:00", "data": {"market": "0x0a99479228e93524b25676ae69b94bd3f4278a6bca8d8c265c84d24755399cf5", "price_changes": [{"asset_id": "67109747366255871599717338045111308888043498275177238365560740200996017915657", "price": "0.01", "size": "1268984.2", "side": "BUY", "hash": "2db5d2b8de76542651dc23935de6a518d8b8ae2d", "best_bid": "0.46", "best_ask": "0.47"}, {"asset_id": "103845791232328975452762372781150730610824357544180691092497335946993481308222", "price": "0.99", "size": "1268984.2", "side": "SELL", "hash": "27533b549f7283330af713a9ada047b95682cf22", "best_bid": "0.53", "best_ask": "0.54"}], "timestamp": "1769384153989", "event_type": "price_change"}}
{"_local_timestamp": "2026-01-25T23:35:54.197665+00:00", "data": {"market": "0x0a99479228e93524b25676ae69b94bd3f4278a6bca8d8c265c84d24755399cf5", "price_changes": [{"asset_id": "67109747366255871599717338045111308888043498275177238365560740200996017915657", "price": "0.01", "size": "1268989.2", "side": "BUY", "hash": "ace2aa7d8a9b1d601cf51eaac5b80e55938548c4", "best_bid": "0.46", "best_ask": "0.47"}, {"asset_id": "103845791232328975452762372781150730610824357544180691092497335946993481308222", "price": "0.99", "size": "1268989.2", "side": "SELL", "hash": "d8ae98f68868a5bb884be71fd95dae1d2c998a28", "best_bid": "0.53", "best_ask": "0.54"}], "timestamp": "1769384154121", "event_type": "price_change"}}
{"_local_timestamp": "2026-01-25T23:35:55.092092+00:00", "data": {"market": "0x0a99479228e93524b25676ae69b94bd3f4278a6bca8d8c265c84d24755399cf5", "price_changes": [{"asset_id": "67109747366255871599717338045111308888043498275177238365560740200996017915657", "price": "0.01", "size": "1268984.2", "side": "BUY", "hash": "681b9202f46e49e569da7bf934659ae191fb1418", "best_bid": "0.46", "best_ask": "0.47"}, {"asset_id": "103845791232328975452762372781150730610824357544180691092497335946993481308222", "price": "0.99", "size": "1268984.2", "side": "SELL", "hash": "b7db4343400aa619daeded6f410af7cad69dafd3", "best_bid": "0.53", "best_ask": "0.54"}], "timestamp": "1769384155001", "event_type": "price_change"}}
{"_local_timestamp": "2026-01-25T23:35:55.884470+00:00", "data": {"market": "0x0a99479228e93524b25676ae69b94bd3f4278a6bca8d8c265c84d24755399cf5", "price_changes": [{"asset_id": "67109747366255871599717338045111308888043498275177238365560740200996017915657", "price": "0.01", "size": "1268989.2", "side": "BUY", "hash": "338ce1079c34a776e303a7f71f346ec9d6afeba9", "best_bid": "0.46", "best_ask": "0.47"}, {"asset_id": "103845791232328975452762372781150730610824357544180691092497335946993481308222", "price": "0.99", "size": "1268989.2", "side": "SELL", "hash": "881cf1a20961b0edb60c4e92812468155b094826", "best_bid": "0.53", "best_ask": "0.54"}], "timestamp": "1769384155811", "event_type": "price_change"}}
{"_local_timestamp": "2026-01-25T23:35:59.579059+00:00", "data": {"market": "0x0a99479228e93524b25676ae69b94bd3f4278a6bca8d8c265c84d24755399cf5", "price_changes": [{"asset_id": "67109747366255871599717338045111308888043498275177238365560740200996017915657", "price": "0.01", "size": "1268994.2", "side": "BUY", "hash": "5a947c150edac97c3d3f594a7b40d643bfbcf47f", "best_bid": "0.46", "best_ask": "0.47"}, {"asset_id": "103845791232328975452762372781150730610824357544180691092497335946993481308222", "price": "0.99", "size": "1268994.2", "side": "SELL", "hash": "c738e58099174f99f38dfd4b184c10c1eae99f87", "best_bid": "0.53", "best_ask": "0.54"}], "timestamp": "1769384159514", "event_type": "price_change"}}
{"_local_timestamp": "2026-01-25T23:35:59.935185+00:00", "data": {"market": "0x0a99479228e93524b25676ae69b94bd3f4278a6bca8d8c265c84d24755399cf5", "price_changes": [{"asset_id": "67109747366255871599717338045111308888043498275177238365560740200996017915657", "price": "0.01", "size": "1268999.2", "side": "BUY", "hash": "c58220cfb00f6215f5bcb8a02b887bc800facd6e", "best_bid": "0.46", "best_ask": "0.47"}, {"asset_id": "103845791232328975452762372781150730610824357544180691092497335946993481308222", "price": "0.99", "size": "1268999.2", "side": "SELL", "hash": "3c67ac183ea330e64b88d0661031b68ae416006e", "best_bid": "0.53", "best_ask": "0.54"}], "timestamp": "1769384159866", "event_type": "price_change"}}
{"_local_timestamp": "2026-01-25T23:36:01.404856+00:00", "data": {"market": "0x0a99479228e93524b25676ae69b94bd3f4278a6bca8d8c265c84d24755399cf5", "price_changes": [{"asset_id": "67109747366255871599717338045111308888043498275177238365560740200996017915657", "price": "0.01", "size": "1269004.2", "side": "BUY", "hash": "2d9be2578867efd7a5c3e9c1ea1e4c96208eafa9", "best_bid": "0.46", "best_ask": "0.47"}, {"asset_id": "103845791232328975452762372781150730610824357544180691092497335946993481308222", "price": "0.99", "size": "1269004.2", "side": "SELL", "hash": "d2551b31110b97bca0050a9a15a5a6d9f3e309e2", "best_bid": "0.53", "best_ask": "0.54"}], "timestamp": "1769384161338", "event_type": "price_change"}}
{"_local_timestamp": "2026-01-25T23:36:07.079835+00:00", "data": {"market": "0x0a99479228e93524b25676ae69b94bd3f4278a6bca8d8c265c84d24755399cf5", "price_changes": [{"asset_id": "67109747366255871599717338045111308888043498275177238365560740200996017915657", "price": "0.01", "size": "1268994.2", "side": "BUY", "hash": "b1c993e209734fc88d9c63f7edd6839cd073fd93", "best_bid": "0.46", "best_ask": "0.47"}, {"asset_id": "103845791232328975452762372781150730610824357544180691092497335946993481308222", "price": "0.99", "size": "1268994.2", "side": "SELL", "hash": "c5267291c2560728caad92635602712e6f7f0ba2", "best_bid": "0.53", "best_ask": "0.54"}], "timestamp": "1769384167000", "event_type": "price_change"}}
{"_local_timestamp": "2026-01-25T23:36:07.086880+00:00", "data": {"market": "0x0a99479228e93524b25676ae69b94bd3f4278a6bca8d8c265c84d24755399cf5", "price_changes": [{"asset_id": "67109747366255871599717338045111308888043498275177238365560740200996017915657", "price": "0.01", "size": "1268994.2", "side": "BUY", "hash": "32e054eaf95cdb789ccd51eb0ac1a8473c8216c6", "best_bid": "0.46", "best_ask": "0.47"}, {"asset_id": "103845791232328975452762372781150730610824357544180691092497335946993481308222", "price": "0.99", "size": "1268994.2", "side": "SELL", "hash": "2c562570d7b27c4ba06c03575c3614e8d831233e", "best_bid": "0.53", "best_ask": "0.54"}], "timestamp": "1769384167003", "event_type": "price_change"}}
{"_local_timestamp": "2026-01-25T23:36:09.078153+00:00", "data": {"market": "0x0a99479228e93524b25676ae69b94bd3f4278a6bca8d8c265c84d24755399cf5", "price_changes": [{"asset_id": "67109747366255871599717338045111308888043498275177238365560740200996017915657", "price": "0.01", "size": "1268984.2", "side": "BUY", "hash": "a728192ad1a80c1c24427ff27ea8e9072686d368", "best_bid": "0.46", "best_ask": "0.47"}, {"asset_id": "103845791232328975452762372781150730610824357544180691092497335946993481308222", "price": "0.99", "size": "1268984.2", "side": "SELL", "hash": "b60a8ab256ecdc97b11a64d5e4a5ab7fbc9923b7", "best_bid": "0.53", "best_ask": "0.54"}], "timestamp": "1769384169001", "event_type": "price_change"}}
{"_local_timestamp": "2026-01-25T23:36:09.090567+00:00", "data": {"market": "0x0a99479228e93524b25676ae69b94bd3f4278a6bca8d8c265c84d24755399cf5", "price_changes": [{"asset_id": "67109747366255871599717338045111308888043498275177238365560740200996017915657", "price": "0.01", "size": "1268984.2", "side": "BUY", "hash": "5c7576e3b26c96284831467bf1aa52fc02a2861e", "best_bid": "0.46", "best_ask": "0.47"}, {"asset_id": "103845791232328975452762372781150730610824357544180691092497335946993481308222", "price": "0.99", "size": "1268984.2", "side": "SELL", "hash": "e0246bf37f188f59f25f66a0b853d1bbd580b736", "best_bid": "0.53", "best_ask": "0.54"}], "timestamp": "1769384169002", "event_type": "price_change"}}
{"_local_timestamp": "2026-01-25T23:36:10.081101+00:00", "data": {"market": "0x0a99479228e93524b25676ae69b94bd3f4278a6bca8d8c265c84d24755399cf5", "price_changes": [{"asset_id": "67109747366255871599717338045111308888043498275177238365560740200996017915657", "price": "0.01", "size": "1268979.2", "side": "BUY", "hash": "b2237a9f87c6c93b2898c8868522cf6fdc05e729", "best_bid": "0.46", "best_ask": "0.47"}, {"asset_id": "103845791232328975452762372781150730610824357544180691092497335946993481308222", "price": "0.99", "size": "1268979.2", "side": "SELL", "hash": "d35cb8f1771e0fed1412f5ef9df2dcc4027ba212", "best_bid": "0.53", "best_ask": "0.54"}], "timestamp": "1769384170001", "event_type": "price_change"}}
{"_local_timestamp": "2026-01-25T23:36:10.893363+00:00", "data": {"market": "0x0a99479228e93524b25676ae69b94bd3f4278a6bca8d8c265c84d24755399cf5", "price_changes": [{"asset_id": "67109747366255871599717338045111308888043498275177238365560740200996017915657", "price": "0.01", "size": "1268984.2", "side": "BUY", "hash": "8797913f9a7689e67c52a5a8c5fb5a143e16c8c4", "best_bid": "0.46", "best_ask": "0.47"}, {"asset_id": "103845791232328975452762372781150730610824357544180691092497335946993481308222", "price": "0.99", "size": "1268984.2", "side": "SELL", "hash": "16d778e4f2861215d209c6ba635054af8211b584", "best_bid": "0.53", "best_ask": "0.54"}], "timestamp": "1769384170827", "event_type": "price_change"}}
{"_local_timestamp": "2026-01-25T23:36:12.097169+00:00", "data": {"market": "0x0a99479228e93524b25676ae69b94bd3f4278a6bca8d8c265c84d24755399cf5", "price_changes": [{"asset_id": "67109747366255871599717338045111308888043498275177238365560740200996017915657", "price": "0.01", "size": "1268979.2", "side": "BUY", "hash": "73be073effbad8bef1089e24d86bcbb129a4e702", "best_bid": "0.46", "best_ask": "0.47"}, {"asset_id": "103845791232328975452762372781150730610824357544180691092497335946993481308222", "price": "0.99", "size": "1268979.2", "side": "SELL", "hash": "d90697666fbbdbb86b3e95cafdeeac14f993f516", "best_bid": "0.53", "best_ask": "0.54"}], "timestamp": "1769384172001", "event_type": "price_change"}}
{"_local_timestamp": "2026-01-25T23:36:12.291842+00:00", "data": {"market": "0x0a99479228e93524b25676ae69b94bd3f4278a6bca8d8c265c84d24755399cf5", "price_changes": [{"asset_id": "67109747366255871599717338045111308888043498275177238365560740200996017915657", "price": "0.01", "size": "1268984.2", "side": "BUY", "hash": "a07d4f1059e3e0c7b06aaed1f1e8936e5c12da95", "best_bid": "0.46", "best_ask": "0.47"}, {"asset_id": "103845791232328975452762372781150730610824357544180691092497335946993481308222", "price": "0.99", "size": "1268984.2", "side": "SELL", "hash": "23813b4cf860220e96a974b584b0fb09909ef8f8", "best_bid": "0.53", "best_ask": "0.54"}], "timestamp": "1769384172226", "event_type": "price_change"}}
{"_local_timestamp": "2026-01-25T23:36:12.626189+00:00", "data": {"market": "0x0a99479228e93524b25676ae69b94bd3f4278a6bca8d8c265c84d24755399cf5", "price_changes": [{"asset_id": "67109747366255871599717338045111308888043498275177238365560740200996017915657", "price": "0.01", "size": "1268989.2", "side": "BUY", "hash": "698e34da141c970258e1b97d7ddf18ef25e56eb4", "best_bid": "0.46", "best_ask": "0.47"}, {"asset_id": "103845791232328975452762372781150730610824357544180691092497335946993481308222", "price": "0.99", "size": "1268989.2", "side": "SELL", "hash": "5b016db6bd0f6efb7eef5bd9f8b72bc61c1f37bd", "best_bid": "0.53", "best_ask": "0.54"}], "timestamp": "1769384172563", "event_type": "price_change"}}
{"_local_timestamp": "2026-01-25T23:36:13.097843+00:00", "data": {"market": "0x0a99479228e93524b25676ae69b94bd3f4278a6bca8d8c265c84d24755399cf5", "price_changes": [{"asset_id": "67109747366255871599717338045111308888043498275177238365560740200996017915657", "price": "0.01", "size": "1268984.2", "side": "BUY", "hash": "16eee6f059223e771e53c3f091e9148603d7ca9e", "best_bid": "0.46", "best_ask": "0.47"}, {"asset_id": "103845791232328975452762372781150730610824357544180691092497335946993481308222", "price": "0.99", "size": "1268984.2", "side": "SELL", "hash": "941555d6f202dddf82ee7c8b934cfdcee43839a1", "best_bid": "0.53", "best_ask": "0.54"}], "timestamp": "1769384173003", "event_type": "price_change"}}
{"_local_timestamp": "2026-01-25T23:36:14.351579+00:00", "data": {"market": "0x0a99479228e93524b25676ae69b94bd3f4278a6bca8d8c265c84d24755399cf5", "price_changes": [{"asset_id": "67109747366255871599717338045111308888043498275177238365560740200996017915657", "price": "0.01", "size": "1268989.2", "side": "BUY", "hash": "d72a6797ce27043f8db2180e1324105016461bea", "best_bid": "0.46", "best_ask": "0.47"}, {"asset_id": "103845791232328975452762372781150730610824357544180691092497335946993481308222", "price": "0.99", "size": "1268989.2", "side": "SELL", "hash": "4300dd505aef77024ada0c709505d376c5141175", "best_bid": "0.53", "best_ask": "0.54"}], "timestamp": "1769384174270", "event_type": "price_change"}}
{"_local_timestamp": "2026-01-25T23:36:16.535170+00:00", "data": {"market": "0x0a99479228e93524b25676ae69b94bd3f4278a6bca8d8c265c84d24755399cf5", "price_changes": [{"asset_id": "67109747366255871599717338045111308888043498275177238365560740200996017915657", "price": "0.01", "size": "1268994.2", "side": "BUY", "hash": "0fa40b6ca88b6500e9cb07c7463fb9a217fc969e", "best_bid": "0.46", "best_ask": "0.47"}, {"asset_id": "103845791232328975452762372781150730610824357544180691092497335946993481308222", "price": "0.99", "size": "1268994.2", "side": "SELL", "hash": "8acb4841fb9be588a856a897418fc762403273af", "best_bid": "0.53", "best_ask": "0.54"}], "timestamp": "1769384176472", "event_type": "price_change"}}
{"_local_timestamp": "2026-01-25T23:36:17.110549+00:00", "data": {"market": "0x0a99479228e93524b25676ae69b94bd3f4278a6bca8d8c265c84d24755399cf5", "price_changes": [{"asset_id": "67109747366255871599717338045111308888043498275177238365560740200996017915657", "price": "0.01", "size": "1268999.2", "side": "BUY", "hash": "de868e862f4f8ec2b3691ca5beb8e017ab8a209a", "best_bid": "0.46", "best_ask": "0.47"}, {"asset_id": "103845791232328975452762372781150730610824357544180691092497335946993481308222", "price": "0.99", "size": "1268999.2", "side": "SELL", "hash": "982f9897f7acb0a63838e0a19c4a595c697f44da", "best_bid": "0.53", "best_ask": "0.54"}], "timestamp": "1769384177045", "event_type": "price_change"}}
{"_local_timestamp": "2026-01-25T23:36:18.447654+00:00", "data": {"market": "0x0a99479228e93524b25676ae69b94bd3f4278a6bca8d8c265c84d24755399cf5", "price_changes": [{"asset_id": "67109747366255871599717338045111308888043498275177238365560740200996017915657", "price": "0.01", "size": "1269004.2", "side": "BUY", "hash": "bd59686c7267d9e1dd3977aa2fed4dd05de048a3", "best_bid": "0.46", "best_ask": "0.47"}, {"asset_id": "103845791232328975452762372781150730610824357544180691092497335946993481308222", "price": "0.99", "size": "1269004.2", "side": "SELL", "hash": "15fb953c5caf0fb8d9ebfa0e9863e519cab1edfc", "best_bid": "0.53", "best_ask": "0.54"}], "timestamp": "1769384178378", "event_type": "price_change"}}
{"_local_timestamp": "2026-01-25T23:36:21.077981+00:00", "data": {"market": "0x0a99479228e93524b25676ae69b94bd3f4278a6bca8d8c265c84d24755399cf5", "price_changes": [{"asset_id": "67109747366255871599717338045111308888043498275177238365560740200996017915657", "price": "0.01", "size": "1268999.2", "side": "BUY", "hash": "bb2470be8f604f6d43476f055598ae032da56d67", "best_bid": "0.46", "best_ask": "0.47"}, {"asset_id": "103845791232328975452762372781150730610824357544180691092497335946993481308222", "price": "0.99", "size": "1268999.2", "side": "SELL", "hash": "2d72930409c9a47f832b7428914ac34dfa0307b4", "best_bid": "0.53", "best_ask": "0.54"}], "timestamp": "1769384181000", "event_type": "price_change"}}
{"_local_timestamp": "2026-01-25T23:36:23.084549+00:00", "data": {"market": "0x0a99479228e93524b25676ae69b94bd3f4278a6bca8d8c265c84d24755399cf5", "price_changes": [{"asset_id": "67109747366255871599717338045111308888043498275177238365560740200996017915657", "price": "0.01", "size": "1268994.2", "side": "BUY", "hash": "1420982cad62e1d1e99e54d495f5c03f430e7324", "best_bid": "0.46", "best_ask": "0.47"}, {"asset_id": "103845791232328975452762372781150730610824357544180691092497335946993481308222", "price": "0.99", "size": "1268994.2", "side": "SELL", "hash": "5270ed104eacf31e7478f6cefc04a40d8c12e80d", "best_bid": "0.53", "best_ask": "0.54"}], "timestamp": "1769384183000", "event_type": "price_change"}}
{"_local_timestamp": "2026-01-25T23:36:24.089622+00:00", "data": {"market": "0x0a99479228e93524b25676ae69b94bd3f4278a6bca8d8c265c84d24755399cf5", "price_changes": [{"asset_id": "67109747366255871599717338045111308888043498275177238365560740200996017915657", "price": "0.01", "size": "1268989.2", "side": "BUY", "hash": "8b03c1818c6f5465dc4568f33de94676e79bc626", "best_bid": "0.46", "best_ask": "0.47"}, {"asset_id": "103845791232328975452762372781150730610824357544180691092497335946993481308222", "price": "0.99", "size": "1268989.2", "side": "SELL", "hash": "b250414aefa3494ba5fea56cff3207fed933ad3c", "best_bid": "0.53", "best_ask": "0.54"}], "timestamp": "1769384184002", "event_type": "price_change"}}
{"_local_timestamp": "2026-01-25T23:36:25.132679+00:00", "data": {"market": "0x0a99479228e93524b25676ae69b94bd3f4278a6bca8d8c265c84d24755399cf5", "price_changes": [{"asset_id": "67109747366255871599717338045111308888043498275177238365560740200996017915657", "price": "0.01", "size": "1268994.2", "side": "BUY", "hash": "eebb4669cdc832a216bf2820b6f63f8b737fa85e", "best_bid": "0.46", "best_ask": "0.47"}, {"asset_id": "103845791232328975452762372781150730610824357544180691092497335946993481308222", "price": "0.99", "size": "1268994.2", "side": "SELL", "hash": "ff006ba44580a2178a573d4d20561d194bc677dd", "best_bid": "0.53", "best_ask": "0.54"}], "timestamp": "1769384185029", "event_type": "price_change"}}
{"_local_timestamp": "2026-01-25T23:36:26.107636+00:00", "data": {"market": "0x0a99479228e93524b25676ae69b94bd3f4278a6bca8d8c265c84d24755399cf5", "price_changes": [{"asset_id": "67109747366255871599717338045111308888043498275177238365560740200996017915657", "price": "0.01", "size": "1268989.2", "side": "BUY", "hash": "76c6054c20eebc02d7c47d687e58e26b4716cce8", "best_bid": "0.46", "best_ask": "0.47"}, {"asset_id": "103845791232328975452762372781150730610824357544180691092497335946993481308222", "price": "0.99", "size": "1268989.2", "side": "SELL", "hash": "1ec6bee822942b9f473aafdc6ed79ff76be33fbf", "best_bid": "0.53", "best_ask": "0.54"}], "timestamp": "1769384186001", "event_type": "price_change"}}
{"_local_timestamp": "2026-01-25T23:36:27.634454+00:00", "data": {"market": "0x0a99479228e93524b25676ae69b94bd3f4278a6bca8d8c265c84d24755399cf5", "price_changes": [{"asset_id": "67109747366255871599717338045111308888043498275177238365560740200996017915657", "price": "0.01", "size": "1268994.2", "side": "BUY", "hash": "1a6bcfdcee1536bb0a8dd505a357eeecb9e90938", "best_bid": "0.46", "best_ask": "0.47"}, {"asset_id": "103845791232328975452762372781150730610824357544180691092497335946993481308222", "price": "0.99", "size": "1268994.2", "side": "SELL", "hash": "a88ff07523c6f94b1913e35ce303d167f63d631d", "best_bid": "0.53", "best_ask": "0.54"}], "timestamp": "1769384187568", "event_type": "price_change"}}
{"_local_timestamp": "2026-01-25T23:36:28.095135+00:00", "data": {"market": "0x0a99479228e93524b25676ae69b94bd3f4278a6bca8d8c265c84d24755399cf5", "price_changes": [{"asset_id": "67109747366255871599717338045111308888043498275177238365560740200996017915657", "price": "0.01", "size": "1268989.2", "side": "BUY", "hash": "72aabc3623b8df5555f558fc78bf37cc3688dcbe", "best_bid": "0.46", "best_ask": "0.47"}, {"asset_id": "103845791232328975452762372781150730610824357544180691092497335946993481308222", "price": "0.99", "size": "1268989.2", "side": "SELL", "hash": "ab05be785b74d6fcdcb9a48de36c7d8f3a850b45", "best_bid": "0.53", "best_ask": "0.54"}], "timestamp": "1769384188002", "event_type": "price_change"}}
{"_local_timestamp": "2026-01-25T23:36:29.148825+00:00", "data": {"market": "0x0a99479228e93524b25676ae69b94bd3f4278a6bca8d8c265c84d24755399cf5", "price_changes": [{"asset_id": "67109747366255871599717338045111308888043498275177238365560740200996017915657", "price": "0.01", "size": "1268984.2", "side": "BUY", "hash": "343666e5d32aa0ee0ebfc1d5f6224c99ad2cb90d", "best_bid": "0.46", "best_ask": "0.47"}, {"asset_id": "103845791232328975452762372781150730610824357544180691092497335946993481308222", "price": "0.99", "size": "1268984.2", "side": "SELL", "hash": "30af1edd23570f0d67ba4be9cf6d9975898284a2", "best_bid": "0.53", "best_ask": "0.54"}], "timestamp": "1769384189001", "event_type": "price_change"}}
{"_local_timestamp": "2026-01-25T23:36:29.247692+00:00", "data": {"market": "0x0a99479228e93524b25676ae69b94bd3f4278a6bca8d8c265c84d24755399cf5", "price_changes": [{"asset_id": "67109747366255871599717338045111308888043498275177238365560740200996017915657", "price": "0.01", "size": "1268989.2", "side": "BUY", "hash": "5ba7070cbf9ee9db03f2a514fe7c38fecaab3fbf", "best_bid": "0.46", "best_ask": "0.47"}, {"asset_id": "103845791232328975452762372781150730610824357544180691092497335946993481308222", "price": "0.99", "size": "1268989.2", "side": "SELL", "hash": "81ba6fe3890ce452bf056e86989e46c24a9d35ab", "best_bid": "0.53", "best_ask": "0.54"}], "timestamp": "1769384189178", "event_type": "price_change"}}
{"_local_timestamp": "2026-01-25T23:36:33.180637+00:00", "data": {"market": "0x0a99479228e93524b25676ae69b94bd3f4278a6bca8d8c265c84d24755399cf5", "price_changes": [{"asset_id": "67109747366255871599717338045111308888043498275177238365560740200996017915657", "price": "0.01", "size": "1268994.2", "side": "BUY", "hash": "8f59c902caf72b927540568ae6d972a9f56570bc", "best_bid": "0.46", "best_ask": "0.47"}, {"asset_id": "103845791232328975452762372781150730610824357544180691092497335946993481308222", "price": "0.99", "size": "1268994.2", "side": "SELL", "hash": "64e2d5df55d7d29f8e4b8827a951318ee87b1dc2", "best_bid": "0.53", "best_ask": "0.54"}], "timestamp": "1769384193103", "event_type": "price_change"}}
{"_local_timestamp": "2026-01-25T23:36:34.604009+00:00", "data": {"market": "0x0a99479228e93524b25676ae69b94bd3f4278a6bca8d8c265c84d24755399cf5", "price_changes": [{"asset_id": "67109747366255871599717338045111308888043498275177238365560740200996017915657", "price": "0.01", "size": "1268999.2", "side": "BUY", "hash": "6160114077d1e239a0f279062e3c53a83fde7c58", "best_bid": "0.46", "best_ask": "0.47"}, {"asset_id": "103845791232328975452762372781150730610824357544180691092497335946993481308222", "price": "0.99", "size": "1268999.2", "side": "SELL", "hash": "1d07fb667dfe93bb6ddc113975b7e43b563e5616", "best_bid": "0.53", "best_ask": "0.54"}], "timestamp": "1769384194533", "event_type": "price_change"}}
{"_local_timestamp": "2026-01-25T23:36:35.637790+00:00", "data": {"market": "0x0a99479228e93524b25676ae69b94bd3f4278a6bca8d8c265c84d24755399cf5", "price_changes": [{"asset_id": "67109747366255871599717338045111308888043498275177238365560740200996017915657", "price": "0.01", "size": "1269004.2", "side": "BUY", "hash": "72d34babf92213e66ad3bf2b66e2c1ebf4b7d6dd", "best_bid": "0.46", "best_ask": "0.47"}, {"asset_id": "103845791232328975452762372781150730610824357544180691092497335946993481308222", "price": "0.99", "size": "1269004.2", "side": "SELL", "hash": "fe966f03b98e1e0280806c32fbf27788d78d11de", "best_bid": "0.53", "best_ask": "0.54"}], "timestamp": "1769384195571", "event_type": "price_change"}}
{"_local_timestamp": "2026-01-25T23:36:40.097547+00:00", "data": {"market": "0x0a99479228e93524b25676ae69b94bd3f4278a6bca8d8c265c84d24755399cf5", "price_changes": [{"asset_id": "67109747366255871599717338045111308888043498275177238365560740200996017915657", "price": "0.01", "size": "1268994.2", "side": "BUY", "hash": "5eee6559e461d34ef65187f27e3abf6556377c2d", "best_bid": "0.46", "best_ask": "0.47"}, {"asset_id": "103845791232328975452762372781150730610824357544180691092497335946993481308222", "price": "0.99", "size": "1268994.2", "side": "SELL", "hash": "f3fd84404c179185fa6083eb6fbeb68af6acee24", "best_bid": "0.53", "best_ask": "0.54"}], "timestamp": "1769384200000", "event_type": "price_change"}}
{"_local_timestamp": "2026-01-25T23:36:40.109043+00:00", "data": {"market": "0x0a99479228e93524b25676ae69b94bd3f4278a6bca8d8c265c84d24755399cf5", "price_changes": [{"asset_id": "67109747366255871599717338045111308888043498275177238365560740200996017915657", "price": "0.01", "size": "1268994.2", "side": "BUY", "hash": "bbc76ec1aff36aafb3fc506674545b747208db44", "best_bid": "0.46", "best_ask": "0.47"}, {"asset_id": "103845791232328975452762372781150730610824357544180691092497335946993481308222", "price": "0.99", "size": "1268994.2", "side": "SELL", "hash": "acf8225deb8fab4d9c7e9566b4b1efa82c83740a", "best_bid": "0.53", "best_ask": "0.54"}], "timestamp": "1769384200003", "event_type": "price_change"}}
{"_local_timestamp": "2026-01-25T23:36:41.082391+00:00", "data": {"market": "0x0a99479228e93524b25676ae69b94bd3f4278a6bca8d8c265c84d24755399cf5", "price_changes": [{"asset_id": "67109747366255871599717338045111308888043498275177238365560740200996017915657", "price": "0.01", "size": "1268989.2", "side": "BUY", "hash": "da92937d29279ad80f1fd25b9896488b3a4d587e", "best_bid": "0.46", "best_ask": "0.47"}, {"asset_id": "103845791232328975452762372781150730610824357544180691092497335946993481308222", "price": "0.99", "size": "1268989.2", "side": "SELL", "hash": "25a2491af47f81d853cc19cc18e5d9958e20178f", "best_bid": "0.53", "best_ask": "0.54"}], "timestamp": "1769384201000", "event_type": "price_change"}}
{"_local_timestamp": "2026-01-25T23:36:43.064963+00:00", "data": {"market": "0x0a99479228e93524b25676ae69b94bd3f4278a6bca8d8c265c84d24755399cf5", "price_changes": [{"asset_id": "67109747366255871599717338045111308888043498275177238365560740200996017915657", "price": "0.01", "size": "1268984.2", "side": "BUY", "hash": "e99ff0bc8b75a3ed58c9d6d6c27c59e4bf8a8985", "best_bid": "0.46", "best_ask": "0.47"}, {"asset_id": "103845791232328975452762372781150730610824357544180691092497335946993481308222", "price": "0.99", "size": "1268984.2", "side": "SELL", "hash": "e0ace5c95fd8d1c537cd2eaffffb9d7a5c32a8e0", "best_bid": "0.53", "best_ask": "0.54"}], "timestamp": "1769384203000", "event_type": "price_change"}}
{"_local_timestamp": "2026-01-25T23:36:44.070225+00:00", "data": {"market": "0x0a99479228e93524b25676ae69b94bd3f4278a6bca8d8c265c84d24755399cf5", "price_changes": [{"asset_id": "67109747366255871599717338045111308888043498275177238365560740200996017915657", "price": "0.01", "size": "1268979.2", "side": "BUY", "hash": "cae2e1c1c66ee2a0c6b6337f90aca0d36d5ea1f4", "best_bid": "0.46", "best_ask": "0.47"}, {"asset_id": "103845791232328975452762372781150730610824357544180691092497335946993481308222", "price": "0.99", "size": "1268979.2", "side": "SELL", "hash": "aa794db19aa28b003bb15dc553a6465224b10dd0", "best_bid": "0.53", "best_ask": "0.54"}], "timestamp": "1769384204000", "event_type": "price_change"}}
{"_local_timestamp": "2026-01-25T23:36:44.255294+00:00", "data": {"market": "0x0a99479228e93524b25676ae69b94bd3f4278a6bca8d8c265c84d24755399cf5", "price_changes": [{"asset_id": "67109747366255871599717338045111308888043498275177238365560740200996017915657", "price": "0.01", "size": "1268984.2", "side": "BUY", "hash": "1f20cbca29fc22c2b171e372e079ed3ace6eda18", "best_bid": "0.46", "best_ask": "0.47"}, {"asset_id": "103845791232328975452762372781150730610824357544180691092497335946993481308222", "price": "0.99", "size": "1268984.2", "side": "SELL", "hash": "c4d8c21a3986c848e7580400a518f361c047fdd8", "best_bid": "0.53", "best_ask": "0.54"}], "timestamp": "1769384204186", "event_type": "price_change"}}
{"_local_timestamp": "2026-01-25T23:36:45.077890+00:00", "data": {"market": "0x0a99479228e93524b25676ae69b94bd3f4278a6bca8d8c265c84d24755399cf5", "price_changes": [{"asset_id": "67109747366255871599717338045111308888043498275177238365560740200996017915657", "price": "0.01", "size": "1268974.2", "side": "BUY", "hash": "79c56e9e760c73adc71634d81af698e200f13403", "best_bid": "0.46", "best_ask": "0.47"}, {"asset_id": "103845791232328975452762372781150730610824357544180691092497335946993481308222", "price": "0.99", "size": "1268974.2", "side": "SELL", "hash": "1e0214ec239eafd224be877b384409aeffb4b738", "best_bid": "0.53", "best_ask": "0.54"}], "timestamp": "1769384205001", "event_type": "price_change"}}
{"_local_timestamp": "2026-01-25T23:36:45.081681+00:00", "data": {"market": "0x0a99479228e93524b25676ae69b94bd3f4278a6bca8d8c265c84d24755399cf5", "price_changes": [{"asset_id": "67109747366255871599717338045111308888043498275177238365560740200996017915657", "price": "0.01", "size": "1268974.2", "side": "BUY", "hash": "ac791499e8c8b40aa3e0940e88b37b289d5f7cc3", "best_bid": "0.46", "best_ask": "0.47"}, {"asset_id": "103845791232328975452762372781150730610824357544180691092497335946993481308222", "price": "0.99", "size": "1268974.2", "side": "SELL", "hash": "bc8bc95ac165f6338c2312ea1340caf7458f2cd3", "best_bid": "0.53", "best_ask": "0.54"}], "timestamp": "1769384205002", "event_type": "price_change"}}
{"_local_timestamp": "2026-01-25T23:36:45.330353+00:00", "data": {"market": "0x0a99479228e93524b25676ae69b94bd3f4278a6bca8d8c265c84d24755399cf5", "price_changes": [{"asset_id": "67109747366255871599717338045111308888043498275177238365560740200996017915657", "price": "0.01", "size": "1268979.2", "side": "BUY", "hash": "06c85c22be89366be51db12eb85688280e7728cd", "best_bid": "0.46", "best_ask": "0.47"}, {"asset_id": "103845791232328975452762372781150730610824357544180691092497335946993481308222", "price": "0.99", "size": "1268979.2", "side": "SELL", "hash": "58870c97bc022cb4ca3deb36e4d44206f1794ec8", "best_bid": "0.53", "best_ask": "0.54"}], "timestamp": "1769384205263", "event_type": "price_change"}}
{"_local_timestamp": "2026-01-25T23:36:45.860940+00:00", "data": {"market": "0x0a99479228e93524b25676ae69b94bd3f4278a6bca8d8c265c84d24755399cf5", "price_changes": [{"asset_id": "67109747366255871599717338045111308888043498275177238365560740200996017915657", "price": "0.01", "size": "1268984.2", "side": "BUY", "hash": "34610f229e0aadf5097000adc457a1ae17c1f14f", "best_bid": "0.46", "best_ask": "0.47"}, {"asset_id": "103845791232328975452762372781150730610824357544180691092497335946993481308222", "price": "0.99", "size": "1268984.2", "side": "SELL", "hash": "481cadd0d9be38c4481f62f3e46a9e0a10319759", "best_bid": "0.53", "best_ask": "0.54"}], "timestamp": "1769384205789", "event_type": "price_change"}}
{"_local_timestamp": "2026-01-25T23:36:45.917733+00:00", "data": {"market": "0x0a99479228e93524b25676ae69b94bd3f4278a6bca8d8c265c84d24755399cf5", "price_changes": [{"asset_id": "67109747366255871599717338045111308888043498275177238365560740200996017915657", "price": "0.01", "size": "1268989.2", "side": "BUY", "hash": "6043965f63410423f33533b4e3fa8aa41dd27997", "best_bid": "0.46", "best_ask": "0.47"}, {"asset_id": "103845791232328975452762372781150730610824357544180691092497335946993481308222", "price": "0.99", "size": "1268989.2", "side": "SELL", "hash": "831e20f33ec13dc2625d3ce15c04869a5860b52e", "best_bid": "0.53", "best_ask": "0.54"}], "timestamp": "1769384205855", "event_type": "price_change"}}
{"_local_timestamp": "2026-01-25T23:36:49.786082+00:00", "data": {"market": "0x0a99479228e93524b25676ae69b94bd3f4278a6bca8d8c265c84d24755399cf5", "price_changes": [{"asset_id": "67109747366255871599717338045111308888043498275177238365560740200996017915657", "price": "0.01", "size": "1268994.2", "side": "BUY", "hash": "567dfa01bd77fb7549d6510cdd61c2badaf13f19", "best_bid": "0.46", "best_ask": "0.47"}, {"asset_id": "103845791232328975452762372781150730610824357544180691092497335946993481308222", "price": "0.99", "size": "1268994.2", "side": "SELL", "hash": "b7b632ca5ba820a655b7b2c161f640528c4bcb3e", "best_bid": "0.53", "best_ask": "0.54"}], "timestamp": "1769384209714", "event_type": "price_change"}}
{"_local_timestamp": "2026-01-25T23:36:51.990186+00:00", "data": {"market": "0x0a99479228e93524b25676ae69b94bd3f4278a6bca8d8c265c84d24755399cf5", "price_changes": [{"asset_id": "67109747366255871599717338045111308888043498275177238365560740200996017915657", "price": "0.01", "size": "1268999.2", "side": "BUY", "hash": "2b315358a6362bb746dc0068f0b9a0bccc5b61f5", "best_bid": "0.46", "best_ask": "0.47"}, {"asset_id": "103845791232328975452762372781150730610824357544180691092497335946993481308222", "price": "0.99", "size": "1268999.2", "side": "SELL", "hash": "387cf64977818863a43ec4c648c958e262ad2217", "best_bid": "0.53", "best_ask": "0.54"}], "timestamp": "1769384211922", "event_type": "price_change"}}
{"_local_timestamp": "2026-01-25T23:36:52.610158+00:00", "data": {"market": "0x0a99479228e93524b25676ae69b94bd3f4278a6bca8d8c265c84d24755399cf5", "price_changes": [{"asset_id": "67109747366255871599717338045111308888043498275177238365560740200996017915657", "price": "0.01", "size": "1269004.2", "side": "BUY", "hash": "ae2d520135545b9531b3bc07812aeb703aefe7e1", "best_bid": "0.46", "best_ask": "0.47"}, {"asset_id": "103845791232328975452762372781150730610824357544180691092497335946993481308222", "price": "0.99", "size": "1269004.2", "side": "SELL", "hash": "6ff618f0302745c44cc6072d9383d454d42ce858", "best_bid": "0.53", "best_ask": "0.54"}], "timestamp": "1769384212531", "event_type": "price_change"}}
{"_local_timestamp": "2026-01-25T23:36:55.106811+00:00", "data": {"market": "0x0a99479228e93524b25676ae69b94bd3f4278a6bca8d8c265c84d24755399cf5", "price_changes": [{"asset_id": "67109747366255871599717338045111308888043498275177238365560740200996017915657", "price": "0.01", "size": "1268999.2", "side": "BUY", "hash": "b823a7132a54136e4a2535bfcc36549f5abc44f9", "best_bid": "0.46", "best_ask": "0.47"}, {"asset_id": "103845791232328975452762372781150730610824357544180691092497335946993481308222", "price": "0.99", "size": "1268999.2", "side": "SELL", "hash": "681c5330f6e809537c1a227f67da9f4ed2b88b93", "best_bid": "0.53", "best_ask": "0.54"}], "timestamp": "1769384215001", "event_type": "price_change"}}
{"_local_timestamp": "2026-01-25T23:36:56.392853+00:00", "data": {"market": "0x0a99479228e93524b25676ae69b94bd3f4278a6bca8d8c265c84d24755399cf5", "price_changes": [{"asset_id": "67109747366255871599717338045111308888043498275177238365560740200996017915657", "price": "0.01", "size": "1268994.2", "side": "BUY", "hash": "083e03e7c4aa23a9dbbd5cb46c2c61fb01c4d92b", "best_bid": "0.46", "best_ask": "0.47"}, {"asset_id": "103845791232328975452762372781150730610824357544180691092497335946993481308222", "price": "0.99", "size": "1268994.2", "side": "SELL", "hash": "938e2fca237d9bdd1bf8979ba8d42c7003e61716", "best_bid": "0.53", "best_ask": "0.54"}], "timestamp": "1769384216001", "event_type": "price_change"}}
{"_local_timestamp": "2026-01-25T23:36:56.393247+00:00", "data": {"market": "0x0a99479228e93524b25676ae69b94bd3f4278a6bca8d8c265c84d24755399cf5", "price_changes": [{"asset_id": "67109747366255871599717338045111308888043498275177238365560740200996017915657", "price": "0.01", "size": "1268999.2", "side": "BUY", "hash": "f587f848a1ff87e990c9d380ddbb2cc521ba9c75", "best_bid": "0.46", "best_ask": "0.47"}, {"asset_id": "103845791232328975452762372781150730610824357544180691092497335946993481308222", "price": "0.99", "size": "1268999.2", "side": "SELL", "hash": "56114b0594bd41c22cefbb6edb56574df9d9874d", "best_bid": "0.53", "best_ask": "0.54"}], "timestamp": "1769384216047", "event_type": "price_change"}}
{"_local_timestamp": "2026-01-25T23:36:58.080194+00:00", "data": {"market": "0x0a99479228e93524b25676ae69b94bd3f4278a6bca8d8c265c84d24755399cf5", "price_changes": [{"asset_id": "67109747366255871599717338045111308888043498275177238365560740200996017915657", "price": "0.01", "size": "1268994.2", "side": "BUY", "hash": "aa1185f94504e5bd1ba986da0308f1de15909032", "best_bid": "0.46", "best_ask": "0.47"}, {"asset_id": "103845791232328975452762372781150730610824357544180691092497335946993481308222", "price": "0.99", "size": "1268994.2", "side": "SELL", "hash": "f5eaaacb7009d2e1fec5f3b77cd5537e6a2b206f", "best_bid": "0.53", "best_ask": "0.54"}], "timestamp": "1769384218004", "event_type": "price_change"}}
{"_local_timestamp": "2026-01-25T23:36:59.116673+00:00", "data": {"market": "0x0a99479228e93524b25676ae69b94bd3f4278a6bca8d8c265c84d24755399cf5", "price_changes": [{"asset_id": "67109747366255871599717338045111308888043498275177238365560740200996017915657", "price": "0.01", "size": "1268989.2", "side": "BUY", "hash": "f690b3cf3d0d759f962cecc1d823b54814934a1c", "best_bid": "0.46", "best_ask": "0.47"}, {"asset_id": "103845791232328975452762372781150730610824357544180691092497335946993481308222", "price": "0.99", "size": "1268989.2", "side": "SELL", "hash": "b860ff12d506c2aacff834c755acfa685eee92d8", "best_bid": "0.53", "best_ask": "0.54"}], "timestamp": "1769384219000", "event_type": "price_change"}}
{"_local_timestamp": "2026-01-25T23:37:00.710444+00:00", "data": {"market": "0x0a99479228e93524b25676ae69b94bd3f4278a6bca8d8c265c84d24755399cf5", "price_changes": [{"asset_id": "67109747366255871599717338045111308888043498275177238365560740200996017915657", "price": "0.01", "size": "1268994.2", "side": "BUY", "hash": "32f9b1bbf7b89e8eae6b7f6b6147f0641fbf319c", "best_bid": "0.46", "best_ask": "0.47"}, {"asset_id": "103845791232328975452762372781150730610824357544180691092497335946993481308222", "price": "0.99", "size": "1268994.2", "side": "SELL", "hash": "b3ed62f7184d7482a601777332813911d3866c18", "best_bid": "0.53", "best_ask": "0.54"}], "timestamp": "1769384220642", "event_type": "price_change"}}
{"_local_timestamp": "2026-01-25T23:37:01.088948+00:00", "data": {"market": "0x0a99479228e93524b25676ae69b94bd3f4278a6bca8d8c265c84d24755399cf5", "price_changes": [{"asset_id": "67109747366255871599717338045111308888043498275177238365560740200996017915657", "price": "0.01", "size": "1268989.2", "side": "BUY", "hash": "5925ef7fe01bdeb60fbcb2303829a40d579837b9", "best_bid": "0.46", "best_ask": "0.47"}, {"asset_id": "103845791232328975452762372781150730610824357544180691092497335946993481308222", "price": "0.99", "size": "1268989.2", "side": "SELL", "hash": "0e131a41b80ae5dbef8d656547e568bca94fc0ea", "best_bid": "0.53", "best_ask": "0.54"}], "timestamp": "1769384221003", "event_type": "price_change"}}
{"_local_timestamp": "2026-01-25T23:37:02.105062+00:00", "data": {"market": "0x0a99479228e93524b25676ae69b94bd3f4278a6bca8d8c265c84d24755399cf5", "price_changes": [{"asset_id": "67109747366255871599717338045111308888043498275177238365560740200996017915657", "price": "0.01", "size": "1268984.2", "side": "BUY", "hash": "b5e4c88c21a5300ab9d6d239dabec124f39ab029", "best_bid": "0.46", "best_ask": "0.47"}, {"asset_id": "103845791232328975452762372781150730610824357544180691092497335946993481308222", "price": "0.99", "size": "1268984.2", "side": "SELL", "hash": "de617ba3f66572cda3883672cded3346a9774877", "best_bid": "0.53", "best_ask": "0.54"}], "timestamp": "1769384222004", "event_type": "price_change"}}
{"_local_timestamp": "2026-01-25T23:37:02.608866+00:00", "data": {"market": "0x0a99479228e93524b25676ae69b94bd3f4278a6bca8d8c265c84d24755399cf5", "price_changes": [{"asset_id": "67109747366255871599717338045111308888043498275177238365560740200996017915657", "price": "0.01", "size": "1268989.2", "side": "BUY", "hash": "1e753f4b913e9ece3158c028eceaf203f4822bf5", "best_bid": "0.46", "best_ask": "0.47"}, {"asset_id": "103845791232328975452762372781150730610824357544180691092497335946993481308222", "price": "0.99", "size": "1268989.2", "side": "SELL", "hash": "ad495a3eebe3ce1b14db21ffc06a4954400e1ad8", "best_bid": "0.53", "best_ask": "0.54"}], "timestamp": "1769384222541", "event_type": "price_change"}}
{"_local_timestamp": "2026-01-25T23:37:06.354096+00:00", "data": {"market": "0x0a99479228e93524b25676ae69b94bd3f4278a6bca8d8c265c84d24755399cf5", "price_changes": [{"asset_id": "67109747366255871599717338045111308888043498275177238365560740200996017915657", "price": "0.01", "size": "1268994.2", "side": "BUY", "hash": "96bc41cb6bc4a341c225c520ee7390a3e098ffaa", "best_bid": "0.46", "best_ask": "0.47"}, {"asset_id": "103845791232328975452762372781150730610824357544180691092497335946993481308222", "price": "0.99", "size": "1268994.2", "side": "SELL", "hash": "1ae68e81975a07860852a3f88a56e518812abbbb", "best_bid": "0.53", "best_ask": "0.54"}], "timestamp": "1769384226279", "event_type": "price_change"}}
{"_local_timestamp": "2026-01-25T23:37:09.381357+00:00", "data": {"market": "0x0a99479228e93524b25676ae69b94bd3f4278a6bca8d8c265c84d24755399cf5", "price_changes": [{"asset_id": "67109747366255871599717338045111308888043498275177238365560740200996017915657", "price": "0.01", "size": "1268999.2", "side": "BUY", "hash": "6d93b5d499c9c0463ee2c819581820b9078648e7", "best_bid": "0.46", "best_ask": "0.47"}, {"asset_id": "103845791232328975452762372781150730610824357544180691092497335946993481308222", "price": "0.99", "size": "1268999.2", "side": "SELL", "hash": "dabec6dd8cb2b33dc4c0ae910c7b3cb8d38f0e66", "best_bid": "0.53", "best_ask": "0.54"}], "timestamp": "1769384229309", "event_type": "price_change"}}
{"_local_timestamp": "2026-01-25T23:37:09.492691+00:00", "data": {"market": "0x0a99479228e93524b25676ae69b94bd3f4278a6bca8d8c265c84d24755399cf5", "price_changes": [{"asset_id": "67109747366255871599717338045111308888043498275177238365560740200996017915657", "price": "0.01", "size": "1269004.2", "side": "BUY", "hash": "b2521885a2f9d9450f8c85c5373dd1083e9b23fd", "best_bid": "0.46", "best_ask": "0.47"}, {"asset_id": "103845791232328975452762372781150730610824357544180691092497335946993481308222", "price": "0.99", "size": "1269004.2", "side": "SELL", "hash": "af8e89ae5792b046c5511cca55566cab2aa3a948", "best_bid": "0.53", "best_ask": "0.54"}], "timestamp": "1769384229420", "event_type": "price_change"}}
{"_local_timestamp": "2026-01-25T23:37:09.852800+00:00", "data": {"market": "0xb106a3c9d1c59ed8117493dae6459a3ff79369a8f7cddaf62f4a05828b89195e", "price_changes": [{"asset_id": "1376044590327709616459174469529480611299625159235587466149878628404281805565", "price": "0.42", "size": "505", "side": "BUY", "hash": "5f184d2d2dec15cf64715ee0534692ae34e82b23", "best_bid": "0.46", "best_ask": "0.47"}, {"asset_id": "49084048476353771153083262278964615095037480324537117350127265918750912547378", "price": "0.58", "size": "505", "side": "SELL", "hash": "5d0a55e461c1c649f55c7449fa32e8bb2a5ead82", "best_bid": "0.53", "best_ask": "0.54"}], "timestamp": "1769384229777", "event_type": "price_change"}}
{"_local_timestamp": "2026-01-25T23:37:11.078445+00:00", "data": {"market": "0x0a99479228e93524b25676ae69b94bd3f4278a6bca8d8c265c84d24755399cf5", "price_changes": [{"asset_id": "67109747366255871599717338045111308888043498275177238365560740200996017915657", "price": "0.01", "size": "1268999.2", "side": "BUY", "hash": "9809257d6498393ce9408244fe8f1d2cec8255b9", "best_bid": "0.46", "best_ask": "0.47"}, {"asset_id": "103845791232328975452762372781150730610824357544180691092497335946993481308222", "price": "0.99", "size": "1268999.2", "side": "SELL", "hash": "0823805790db9eaab38999d56a335864cb3ceb7e", "best_bid": "0.53", "best_ask": "0.54"}], "timestamp": "1769384231001", "event_type": "price_change"}}
{"_local_timestamp": "2026-01-25T23:37:13.105760+00:00", "data": {"market": "0x0a99479228e93524b25676ae69b94bd3f4278a6bca8d8c265c84d24755399cf5", "price_changes": [{"asset_id": "67109747366255871599717338045111308888043498275177238365560740200996017915657", "price": "0.01", "size": "1268994.2", "side": "BUY", "hash": "5cee4731236ff8070491a2836f6f3c9a0a9bdc2d", "best_bid": "0.46", "best_ask": "0.47"}, {"asset_id": "103845791232328975452762372781150730610824357544180691092497335946993481308222", "price": "0.99", "size": "1268994.2", "side": "SELL", "hash": "962e5f6a54e12b36e1052b2323127576d1e2ea7a", "best_bid": "0.53", "best_ask": "0.54"}], "timestamp": "1769384233001", "event_type": "price_change"}}
{"_local_timestamp": "2026-01-25T23:37:15.079115+00:00", "data": {"market": "0x0a99479228e93524b25676ae69b94bd3f4278a6bca8d8c265c84d24755399cf5", "price_changes": [{"asset_id": "67109747366255871599717338045111308888043498275177238365560740200996017915657", "price": "0.01", "size": "1268984.2", "side": "BUY", "hash": "04dd72dae71881d6f56653b78c7c2fdbbd0cfb9f", "best_bid": "0.46", "best_ask": "0.47"}, {"asset_id": "103845791232328975452762372781150730610824357544180691092497335946993481308222", "price": "0.99", "size": "1268984.2", "side": "SELL", "hash": "5b56725c1e2eefcd57cef6fbf1d5adc4380d9208", "best_bid": "0.53", "best_ask": "0.54"}], "timestamp": "1769384235002", "event_type": "price_change"}}
{"_local_timestamp": "2026-01-25T23:37:15.090140+00:00", "data": {"market": "0x0a99479228e93524b25676ae69b94bd3f4278a6bca8d8c265c84d24755399cf5", "price_changes": [{"asset_id": "67109747366255871599717338045111308888043498275177238365560740200996017915657", "price": "0.01", "size": "1268984.2", "side": "BUY", "hash": "289d0ba67dec5c70b193cc521fecd2fbdd2b2825", "best_bid": "0.46", "best_ask": "0.47"}, {"asset_id": "103845791232328975452762372781150730610824357544180691092497335946993481308222", "price": "0.99", "size": "1268984.2", "side": "SELL", "hash": "35831f4d27269f790c912c3e699a79a04dbd8399", "best_bid": "0.53", "best_ask": "0.54"}], "timestamp": "1769384235006", "event_type": "price_change"}}
{"_local_timestamp": "2026-01-25T23:37:16.098550+00:00", "data": {"market": "0x0a99479228e93524b25676ae69b94bd3f4278a6bca8d8c265c84d24755399cf5", "price_changes": [{"asset_id": "67109747366255871599717338045111308888043498275177238365560740200996017915657", "price": "0.01", "size": "1268979.2", "side": "BUY", "hash": "68467791da74b23e01c6eca0910d32f8f4c74e50", "best_bid": "0.46", "best_ask": "0.47"}, {"asset_id": "103845791232328975452762372781150730610824357544180691092497335946993481308222", "price": "0.99", "size": "1268979.2", "side": "SELL", "hash": "510d3120f5aa25c99f05e86121f7137e26c0138d", "best_bid": "0.53", "best_ask": "0.54"}], "timestamp": "1769384236002", "event_type": "price_change"}}
{"_local_timestamp": "2026-01-25T23:37:16.437220+00:00", "data": {"market": "0x0a99479228e93524b25676ae69b94bd3f4278a6bca8d8c265c84d24755399cf5", "price_changes": [{"asset_id": "67109747366255871599717338045111308888043498275177238365560740200996017915657", "price": "0.01", "size": "1268984.2", "side": "BUY", "hash": "115384443a6ac9630ad42d9fd347078acf05b27b", "best_bid": "0.46", "best_ask": "0.47"}, {"asset_id": "103845791232328975452762372781150730610824357544180691092497335946993481308222", "price": "0.99", "size": "1268984.2", "side": "SELL", "hash": "401957a4d2d3e60054659d501ff8d8b14c00120c", "best_bid": "0.53", "best_ask": "0.54"}], "timestamp": "1769384236374", "event_type": "price_change"}}
{"_local_timestamp": "2026-01-25T23:37:17.504716+00:00", "data": {"market": "0x0a99479228e93524b25676ae69b94bd3f4278a6bca8d8c265c84d24755399cf5", "price_changes": [{"asset_id": "67109747366255871599717338045111308888043498275177238365560740200996017915657", "price": "0.01", "size": "1268989.2", "side": "BUY", "hash": "09c025a2eeb48a07c95cd2e0ab5e715248687cdd", "best_bid": "0.46", "best_ask": "0.47"}, {"asset_id": "103845791232328975452762372781150730610824357544180691092497335946993481308222", "price": "0.99", "size": "1268989.2", "side": "SELL", "hash": "4102dc445c05dabd4ed074588af0abc060620067", "best_bid": "0.53", "best_ask": "0.54"}], "timestamp": "1769384237419", "event_type": "price_change"}}
{"_local_timestamp": "2026-01-25T23:37:18.092385+00:00", "data": {"market": "0x0a99479228e93524b25676ae69b94bd3f4278a6bca8d8c265c84d24755399cf5", "price_changes": [{"asset_id": "67109747366255871599717338045111308888043498275177238365560740200996017915657", "price": "0.01", "size": "1268984.2", "side": "BUY", "hash": "998c335ce25093e10bb045ec6ac47b9e33749763", "best_bid": "0.46", "best_ask": "0.47"}, {"asset_id": "103845791232328975452762372781150730610824357544180691092497335946993481308222", "price": "0.99", "size": "1268984.2", "side": "SELL", "hash": "4ca980653484588fd09c26323f8555b358758aae", "best_bid": "0.53", "best_ask": "0.54"}], "timestamp": "1769384238003", "event_type": "price_change"}}
{"_local_timestamp": "2026-01-25T23:37:19.075564+00:00", "data": {"market": "0x0a99479228e93524b25676ae69b94bd3f4278a6bca8d8c265c84d24755399cf5", "price_changes": [{"asset_id": "67109747366255871599717338045111308888043498275177238365560740200996017915657", "price": "0.01", "size": "1268979.2", "side": "BUY", "hash": "684c4b205e460068075cea1af153eef727761951", "best_bid": "0.46", "best_ask": "0.47"}, {"asset_id": "103845791232328975452762372781150730610824357544180691092497335946993481308222", "price": "0.99", "size": "1268979.2", "side": "SELL", "hash": "5af264d071cda06b1431da399d3b49e74a6d955a", "best_bid": "0.53", "best_ask": "0.54"}], "timestamp": "1769384239002", "event_type": "price_change"}}
{"_local_timestamp": "2026-01-25T23:37:19.222328+00:00", "data": {"market": "0x0a99479228e93524b25676ae69b94bd3f4278a6bca8d8c265c84d24755399cf5", "price_changes": [{"asset_id": "67109747366255871599717338045111308888043498275177238365560740200996017915657", "price": "0.01", "size": "1268984.2", "side": "BUY", "hash": "a267d423704f00e7b059648d44c6c25198237b45", "best_bid": "0.46", "best_ask": "0.47"}, {"asset_id": "103845791232328975452762372781150730610824357544180691092497335946993481308222", "price": "0.99", "size": "1268984.2", "side": "SELL", "hash": "00ae1d44057b4f78cb72ca7f21b84f0a75c50c1c", "best_bid": "0.53", "best_ask": "0.54"}], "timestamp": "1769384239159", "event_type": "price_change"}}
{"_local_timestamp": "2026-01-25T23:37:19.563714+00:00", "data": {"market": "0x0a99479228e93524b25676ae69b94bd3f4278a6bca8d8c265c84d24755399cf5", "price_changes": [{"asset_id": "67109747366255871599717338045111308888043498275177238365560740200996017915657", "price": "0.01", "size": "1268989.2", "side": "BUY", "hash": "38bafacaa49e07b15b109212a44ce1720d830380", "best_bid": "0.46", "best_ask": "0.47"}, {"asset_id": "103845791232328975452762372781150730610824357544180691092497335946993481308222", "price": "0.99", "size": "1268989.2", "side": "SELL", "hash": "304c3be4a256401995330082a44b9728f693b727", "best_bid": "0.53", "best_ask": "0.54"}], "timestamp": "1769384239487", "event_type": "price_change"}}
{"_local_timestamp": "2026-01-25T23:37:23.134463+00:00", "data": {"market": "0x0a99479228e93524b25676ae69b94bd3f4278a6bca8d8c265c84d24755399cf5", "price_changes": [{"asset_id": "67109747366255871599717338045111308888043498275177238365560740200996017915657", "price": "0.01", "size": "1268994.2", "side": "BUY", "hash": "ceab6674a15a21f6c9b5f34d097ed7d1d293a830", "best_bid": "0.46", "best_ask": "0.47"}, {"asset_id": "103845791232328975452762372781150730610824357544180691092497335946993481308222", "price": "0.99", "size": "1268994.2", "side": "SELL", "hash": "31c3624eb09f2251ffd0bc07fddb53bbc9816291", "best_bid": "0.53", "best_ask": "0.54"}], "timestamp": "1769384243056", "event_type": "price_change"}}
{"_local_timestamp": "2026-01-25T23:37:26.885695+00:00", "data": {"market": "0x0a99479228e93524b25676ae69b94bd3f4278a6bca8d8c265c84d24755399cf5", "price_changes": [{"asset_id": "67109747366255871599717338045111308888043498275177238365560740200996017915657", "price": "0.01", "size": "1268999.2", "side": "BUY", "hash": "38118de93e5de2c3dc6ac411790ffe6d9729f96a", "best_bid": "0.46", "best_ask": "0.47"}, {"asset_id": "103845791232328975452762372781150730610824357544180691092497335946993481308222", "price": "0.99", "size": "1268999.2", "side": "SELL", "hash": "1f34e4a8422985fe863455f2c4141274e9441a86", "best_bid": "0.53", "best_ask": "0.54"}], "timestamp": "1769384246797", "event_type": "price_change"}}
{"_local_timestamp": "2026-01-25T23:37:27.061894+00:00", "data": {"market": "0x0a99479228e93524b25676ae69b94bd3f4278a6bca8d8c265c84d24755399cf5", "price_changes": [{"asset_id": "67109747366255871599717338045111308888043498275177238365560740200996017915657", "price": "0.01", "size": "1269004.2", "side": "BUY", "hash": "d8990da10fc5a613d2649962f8186578e9f9cc74", "best_bid": "0.46", "best_ask": "0.47"}, {"asset_id": "103845791232328975452762372781150730610824357544180691092497335946993481308222", "price": "0.99", "size": "1269004.2", "side": "SELL", "hash": "015da0d23eadfe4f6884d1eab3a71f5e978632e8", "best_bid": "0.53", "best_ask": "0.54"}], "timestamp": "1769384246987", "event_type": "price_change"}}
{"_local_timestamp": "2026-01-25T23:37:27.211936+00:00", "data": {"market": "0x0a99479228e93524b25676ae69b94bd3f4278a6bca8d8c265c84d24755399cf5", "price_changes": [{"asset_id": "67109747366255871599717338045111308888043498275177238365560740200996017915657", "price": "0.01", "size": "1269009.2", "side": "BUY", "hash": "ecd1e4640a2f9893793db805f89acebc34b123fd", "best_bid": "0.46", "best_ask": "0.47"}, {"asset_id": "103845791232328975452762372781150730610824357544180691092497335946993481308222", "price": "0.99", "size": "1269009.2", "side": "SELL", "hash": "127fe2a6b8681c85d0de63b671acf14bcb88e837", "best_bid": "0.53", "best_ask": "0.54"}], "timestamp": "1769384247132", "event_type": "price_change"}}
{"_local_timestamp": "2026-01-25T23:37:28.077973+00:00", "data": {"market": "0x0a99479228e93524b25676ae69b94bd3f4278a6bca8d8c265c84d24755399cf5", "price_changes": [{"asset_id": "67109747366255871599717338045111308888043498275177238365560740200996017915657", "price": "0.01", "size": "1269004.2", "side": "BUY", "hash": "93b654dbb32b572315d8d4f01e257a21b8d7b9af", "best_bid": "0.46", "best_ask": "0.47"}, {"asset_id": "103845791232328975452762372781150730610824357544180691092497335946993481308222", "price": "0.99", "size": "1269004.2", "side": "SELL", "hash": "355406476181998325b79411a4e0fcd8138d0cd3", "best_bid": "0.53", "best_ask": "0.54"}], "timestamp": "1769384248001", "event_type": "price_change"}}
{"_local_timestamp": "2026-01-25T23:37:29.088201+00:00", "data": {"market": "0x0a99479228e93524b25676ae69b94bd3f4278a6bca8d8c265c84d24755399cf5", "price_changes": [{"asset_id": "67109747366255871599717338045111308888043498275177238365560740200996017915657", "price": "0.01", "size": "1268999.2", "side": "BUY", "hash": "e1d35c69d1106445f5450e8ef8e72f44d062bcba", "best_bid": "0.46", "best_ask": "0.47"}, {"asset_id": "103845791232328975452762372781150730610824357544180691092497335946993481308222", "price": "0.99", "size": "1268999.2", "side": "SELL", "hash": "953bd37c1f19d6075a8c66f1600c67778c01dd7c", "best_bid": "0.53", "best_ask": "0.54"}], "timestamp": "1769384249000", "event_type": "price_change"}}
{"_local_timestamp": "2026-01-25T23:37:31.809367+00:00", "data": {"market": "0xb106a3c9d1c59ed8117493dae6459a3ff79369a8f7cddaf62f4a05828b89195e", "price_changes": [{"asset_id": "1376044590327709616459174469529480611299625159235587466149878628404281805565", "price": "0.42", "size": "105", "side": "BUY", "hash": "4ef74ac46c78e48b138a9c199fbdd11ef0296a19", "best_bid": "0.46", "best_ask": "0.47"}, {"asset_id": "49084048476353771153083262278964615095037480324537117350127265918750912547378", "price": "0.58", "size": "105", "side": "SELL", "hash": "05de5a7571d0bae64b8bc7ac577b0d5d160d1570", "best_bid": "0.53", "best_ask": "0.54"}], "timestamp": "1769384251707", "event_type": "price_change"}}
{"_local_timestamp": "2026-01-25T23:37:32.188818+00:00", "data": {"market": "0x0a99479228e93524b25676ae69b94bd3f4278a6bca8d8c265c84d24755399cf5", "price_changes": [{"asset_id": "67109747366255871599717338045111308888043498275177238365560740200996017915657", "price": "0.01", "size": "1268994.2", "side": "BUY", "hash": "c96ff25676ba78f67681669a1392620d63dfdfbb", "best_bid": "0.46", "best_ask": "0.47"}, {"asset_id": "103845791232328975452762372781150730610824357544180691092497335946993481308222", "price": "0.99", "size": "1268994.2", "side": "SELL", "hash": "70dda3019acd23bcfd8127fbffb9a09b81ea4e41", "best_bid": "0.53", "best_ask": "0.54"}], "timestamp": "1769384252008", "event_type": "price_change"}}
{"_local_timestamp": "2026-01-25T23:37:33.139108+00:00", "data": {"market": "0x0a99479228e93524b25676ae69b94bd3f4278a6bca8d8c265c84d24755399cf5", "price_changes": [{"asset_id": "67109747366255871599717338045111308888043498275177238365560740200996017915657", "price": "0.01", "size": "1268989.2", "side": "BUY", "hash": "5130e20b2b0b4a8cbcc5306da8a2faaa6bb99391", "best_bid": "0.46", "best_ask": "0.47"}, {"asset_id": "103845791232328975452762372781150730610824357544180691092497335946993481308222", "price": "0.99", "size": "1268989.2", "side": "SELL", "hash": "ff9dc73b72c8a55515d665c4927c51edb4998cc0", "best_bid": "0.53", "best_ask": "0.54"}], "timestamp": "1769384253002", "event_type": "price_change"}}
{"_local_timestamp": "2026-01-25T23:37:34.080579+00:00", "data": {"market": "0x0a99479228e93524b25676ae69b94bd3f4278a6bca8d8c265c84d24755399cf5", "price_changes": [{"asset_id": "67109747366255871599717338045111308888043498275177238365560740200996017915657", "price": "0.01", "size": "1268984.2", "side": "BUY", "hash": "0588cd2396b2199f3140c92694d90c5a46676c2e", "best_bid": "0.46", "best_ask": "0.47"}, {"asset_id": "103845791232328975452762372781150730610824357544180691092497335946993481308222", "price": "0.99", "size": "1268984.2", "side": "SELL", "hash": "6d07d7eed2d78218ee737e72c7b54e0553f8a11e", "best_bid": "0.53", "best_ask": "0.54"}], "timestamp": "1769384254000", "event_type": "price_change"}}
{"_local_timestamp": "2026-01-25T23:37:34.204097+00:00", "data": {"market": "0x0a99479228e93524b25676ae69b94bd3f4278a6bca8d8c265c84d24755399cf5", "price_changes": [{"asset_id": "67109747366255871599717338045111308888043498275177238365560740200996017915657", "price": "0.01", "size": "1268989.2", "side": "BUY", "hash": "cb0fdec11b385f20eff42468d223fcf25bf40470", "best_bid": "0.46", "best_ask": "0.47"}, {"asset_id": "103845791232328975452762372781150730610824357544180691092497335946993481308222", "price": "0.99", "size": "1268989.2", "side": "SELL", "hash": "c4b4c0ddf651d92bbe942f9830f5cae5ab694e4d", "best_bid": "0.53", "best_ask": "0.54"}], "timestamp": "1769384254137", "event_type": "price_change"}}
{"_local_timestamp": "2026-01-25T23:37:35.868537+00:00", "data": {"market": "0x0a99479228e93524b25676ae69b94bd3f4278a6bca8d8c265c84d24755399cf5", "price_changes": [{"asset_id": "67109747366255871599717338045111308888043498275177238365560740200996017915657", "price": "0.01", "size": "1268994.2", "side": "BUY", "hash": "d1417ccfffead33d984b73df3fd7f53befcba496", "best_bid": "0.46", "best_ask": "0.47"}, {"asset_id": "103845791232328975452762372781150730610824357544180691092497335946993481308222", "price": "0.99", "size": "1268994.2", "side": "SELL", "hash": "80e047b196cf3774dfc2555f866627df67c030b4", "best_bid": "0.53", "best_ask": "0.54"}], "timestamp": "1769384255799", "event_type": "price_change"}}
{"_local_timestamp": "2026-01-25T23:37:36.072646+00:00", "data": {"market": "0x0a99479228e93524b25676ae69b94bd3f4278a6bca8d8c265c84d24755399cf5", "price_changes": [{"asset_id": "67109747366255871599717338045111308888043498275177238365560740200996017915657", "price": "0.01", "size": "1268989.2", "side": "BUY", "hash": "48ae48891892023a44fa5c805488aa998ddb7837", "best_bid": "0.46", "best_ask": "0.47"}, {"asset_id": "103845791232328975452762372781150730610824357544180691092497335946993481308222", "price": "0.99", "size": "1268989.2", "side": "SELL", "hash": "7761ddf0d7f559349808745f807057588fcac774", "best_bid": "0.53", "best_ask": "0.54"}], "timestamp": "1769384256000", "event_type": "price_change"}}
{"_local_timestamp": "2026-01-25T23:37:39.621292+00:00", "data": {"market": "0x0a99479228e93524b25676ae69b94bd3f4278a6bca8d8c265c84d24755399cf5", "price_changes": [{"asset_id": "67109747366255871599717338045111308888043498275177238365560740200996017915657", "price": "0.01", "size": "1268994.2", "side": "BUY", "hash": "707021da5e95917ca0d80d8239db96d28f243a30", "best_bid": "0.46", "best_ask": "0.47"}, {"asset_id": "103845791232328975452762372781150730610824357544180691092497335946993481308222", "price": "0.99", "size": "1268994.2", "side": "SELL", "hash": "4cdd02e59b15352d02c0798cdf9cf8e37e5f1593", "best_bid": "0.53", "best_ask": "0.54"}], "timestamp": "1769384259557", "event_type": "price_change"}}
{"_local_timestamp": "2026-01-25T23:37:42.108630+00:00", "data": {"market": "0x0a99479228e93524b25676ae69b94bd3f4278a6bca8d8c265c84d24755399cf5", "price_changes": [{"asset_id": "67109747366255871599717338045111308888043498275177238365560740200996017915657", "price": "0.01", "size": "1268989.2", "side": "BUY", "hash": "c242c7ead8d7309dae44dac45115ede1796eaa62", "best_bid": "0.46", "best_ask": "0.47"}, {"asset_id": "103845791232328975452762372781150730610824357544180691092497335946993481308222", "price": "0.99", "size": "1268989.2", "side": "SELL", "hash": "4dd44c3b10b0ba71ede1ed1d54d7b727bcf1ea67", "best_bid": "0.53", "best_ask": "0.54"}], "timestamp": "1769384262005", "event_type": "price_change"}}
{"_local_timestamp": "2026-01-25T23:37:43.894105+00:00", "data": {"market": "0x0a99479228e93524b25676ae69b94bd3f4278a6bca8d8c265c84d24755399cf5", "price_changes": [{"asset_id": "67109747366255871599717338045111308888043498275177238365560740200996017915657", "price": "0.01", "size": "1268994.2", "side": "BUY", "hash": "95abf812ced06c62c3e3488ee4496f161e8e20b2", "best_bid": "0.46", "best_ask": "0.47"}, {"asset_id": "103845791232328975452762372781150730610824357544180691092497335946993481308222", "price": "0.99", "size": "1268994.2", "side": "SELL", "hash": "26f4336df5f2d99fe56b4a734923fc797e12123e", "best_bid": "0.53", "best_ask": "0.54"}], "timestamp": "1769384263827", "event_type": "price_change"}}
{"_local_timestamp": "2026-01-25T23:37:44.407968+00:00", "data": {"market": "0x0a99479228e93524b25676ae69b94bd3f4278a6bca8d8c265c84d24755399cf5", "price_changes": [{"asset_id": "67109747366255871599717338045111308888043498275177238365560740200996017915657", "price": "0.01", "size": "1268999.2", "side": "BUY", "hash": "62734141b438d04370688f7075cd3d8cbbb2728a", "best_bid": "0.46", "best_ask": "0.47"}, {"asset_id": "103845791232328975452762372781150730610824357544180691092497335946993481308222", "price": "0.99", "size": "1268999.2", "side": "SELL", "hash": "77eddf36ffcd17c38405bee341c83f1d06fe22ed", "best_bid": "0.53", "best_ask": "0.54"}], "timestamp": "1769384264331", "event_type": "price_change"}}
{"_local_timestamp": "2026-01-25T23:37:45.108562+00:00", "data": {"market": "0x0a99479228e93524b25676ae69b94bd3f4278a6bca8d8c265c84d24755399cf5", "price_changes": [{"asset_id": "67109747366255871599717338045111308888043498275177238365560740200996017915657", "price": "0.01", "size": "1268994.2", "side": "BUY", "hash": "14cc31399eeb4a01b0f12d74b7d85e2195ae073e", "best_bid": "0.46", "best_ask": "0.47"}, {"asset_id": "103845791232328975452762372781150730610824357544180691092497335946993481308222", "price": "0.99", "size": "1268994.2", "side": "SELL", "hash": "c0a3320173dbb130b68dd5104042a78309603ba7", "best_bid": "0.53", "best_ask": "0.54"}], "timestamp": "1769384265004", "event_type": "price_change"}}
{"_local_timestamp": "2026-01-25T23:37:46.077922+00:00", "data": {"market": "0x0a99479228e93524b25676ae69b94bd3f4278a6bca8d8c265c84d24755399cf5", "price_changes": [{"asset_id": "67109747366255871599717338045111308888043498275177238365560740200996017915657", "price": "0.01", "size": "1268989.2", "side": "BUY", "hash": "399e72f0608a28ec17bdd0556f280f19cc802243", "best_bid": "0.46", "best_ask": "0.47"}, {"asset_id": "103845791232328975452762372781150730610824357544180691092497335946993481308222", "price": "0.99", "size": "1268989.2", "side": "SELL", "hash": "ffd29783ee399362026dd161aa16541678c0bc56", "best_bid": "0.53", "best_ask": "0.54"}], "timestamp": "1769384266000", "event_type": "price_change"}}
{"_local_timestamp": "2026-01-25T23:37:47.464847+00:00", "data": {"market": "0x0a99479228e93524b25676ae69b94bd3f4278a6bca8d8c265c84d24755399cf5", "price_changes": [{"asset_id": "67109747366255871599717338045111308888043498275177238365560740200996017915657", "price": "0.01", "size": "1268994.2", "side": "BUY", "hash": "c35023afa433bac83c13a26b237407e7a09dc4c5", "best_bid": "0.46", "best_ask": "0.47"}, {"asset_id": "103845791232328975452762372781150730610824357544180691092497335946993481308222", "price": "0.99", "size": "1268994.2", "side": "SELL", "hash": "8583af1221ba3a99bd3da9e376c47e7bb49ea529", "best_bid": "0.53", "best_ask": "0.54"}], "timestamp": "1769384267402", "event_type": "price_change"}}
{"_local_timestamp": "2026-01-25T23:37:49.079513+00:00", "data": {"market": "0x0a99479228e93524b25676ae69b94bd3f4278a6bca8d8c265c84d24755399cf5", "price_changes": [{"asset_id": "67109747366255871599717338045111308888043498275177238365560740200996017915657", "price": "0.01", "size": "1268989.2", "side": "BUY", "hash": "2c2f2414a8045a6408b284fb817b1b74c5003b72", "best_bid": "0.46", "best_ask": "0.47"}, {"asset_id": "103845791232328975452762372781150730610824357544180691092497335946993481308222", "price": "0.99", "size": "1268989.2", "side": "SELL", "hash": "a9bd095421e9b9e8ffdd160a4c72f936fe5438a1", "best_bid": "0.53", "best_ask": "0.54"}], "timestamp": "1769384269001", "event_type": "price_change"}}
{"_local_timestamp": "2026-01-25T23:37:50.094281+00:00", "data": {"market": "0x0a99479228e93524b25676ae69b94bd3f4278a6bca8d8c265c84d24755399cf5", "price_changes": [{"asset_id": "67109747366255871599717338045111308888043498275177238365560740200996017915657", "price": "0.01", "size": "1268984.2", "side": "BUY", "hash": "5d61df88fe4a575fc3832eaaf5c1829767c30b17", "best_bid": "0.46", "best_ask": "0.47"}, {"asset_id": "103845791232328975452762372781150730610824357544180691092497335946993481308222", "price": "0.99", "size": "1268984.2", "side": "SELL", "hash": "5e858eefd78bd5ad638eb9201fb84ab2105f4859", "best_bid": "0.53", "best_ask": "0.54"}], "timestamp": "1769384270003", "event_type": "price_change"}}
{"_local_timestamp": "2026-01-25T23:37:50.844147+00:00", "data": {"market": "0x0a99479228e93524b25676ae69b94bd3f4278a6bca8d8c265c84d24755399cf5", "price_changes": [{"asset_id": "67109747366255871599717338045111308888043498275177238365560740200996017915657", "price": "0.01", "size": "1268989.2", "side": "BUY", "hash": "242961785328a84ac23b187df8b6f461ebb01ade", "best_bid": "0.46", "best_ask": "0.47"}, {"asset_id": "103845791232328975452762372781150730610824357544180691092497335946993481308222", "price": "0.99", "size": "1268989.2", "side": "SELL", "hash": "54b4a4c5673c2ff712d752209418e97fb9519d4d", "best_bid": "0.53", "best_ask": "0.54"}], "timestamp": "1769384270759", "event_type": "price_change"}}
{"_local_timestamp": "2026-01-25T23:37:51.139451+00:00", "data": {"market": "0x0a99479228e93524b25676ae69b94bd3f4278a6bca8d8c265c84d24755399cf5", "price_changes": [{"asset_id": "67109747366255871599717338045111308888043498275177238365560740200996017915657", "price": "0.01", "size": "1268984.2", "side": "BUY", "hash": "e99dc13891c16f0a081c131a0f389e7f5a617ce0", "best_bid": "0.46", "best_ask": "0.47"}, {"asset_id": "103845791232328975452762372781150730610824357544180691092497335946993481308222", "price": "0.99", "size": "1268984.2", "side": "SELL", "hash": "472d04dea3ce09eab450bea757286dcf4b3031a2", "best_bid": "0.53", "best_ask": "0.54"}], "timestamp": "1769384271005", "event_type": "price_change"}}
{"_local_timestamp": "2026-01-25T23:37:52.599445+00:00", "data": {"market": "0x0a99479228e93524b25676ae69b94bd3f4278a6bca8d8c265c84d24755399cf5", "price_changes": [{"asset_id": "67109747366255871599717338045111308888043498275177238365560740200996017915657", "price": "0.01", "size": "1268989.2", "side": "BUY", "hash": "5fa7cb3bc036e36808d00d4a25558c927ad40470", "best_bid": "0.46", "best_ask": "0.47"}, {"asset_id": "103845791232328975452762372781150730610824357544180691092497335946993481308222", "price": "0.99", "size": "1268989.2", "side": "SELL", "hash": "e8751a3225d8396d716b389402623d535012957b", "best_bid": "0.53", "best_ask": "0.54"}], "timestamp": "1769384272532", "event_type": "price_change"}}
{"_local_timestamp": "2026-01-25T23:37:53.087837+00:00", "data": {"market": "0x0a99479228e93524b25676ae69b94bd3f4278a6bca8d8c265c84d24755399cf5", "price_changes": [{"asset_id": "67109747366255871599717338045111308888043498275177238365560740200996017915657", "price": "0.01", "size": "1268984.2", "side": "BUY", "hash": "1bfce1dbabb9c226f50ea52744eb0aea8cf85d90", "best_bid": "0.46", "best_ask": "0.47"}, {"asset_id": "103845791232328975452762372781150730610824357544180691092497335946993481308222", "price": "0.99", "size": "1268984.2", "side": "SELL", "hash": "f1614a3cf7af78dcad50f03e04809cee654d920a", "best_bid": "0.53", "best_ask": "0.54"}], "timestamp": "1769384273000", "event_type": "price_change"}}
{"_local_timestamp": "2026-01-25T23:37:53.298082+00:00", "data": {"market": "0x0a99479228e93524b25676ae69b94bd3f4278a6bca8d8c265c84d24755399cf5", "price_changes": [{"asset_id": "67109747366255871599717338045111308888043498275177238365560740200996017915657", "price": "0.01", "size": "1268989.2", "side": "BUY", "hash": "f2037086de95a6a1e195d139600f9c18fe19c1eb", "best_bid": "0.46", "best_ask": "0.47"}, {"asset_id": "103845791232328975452762372781150730610824357544180691092497335946993481308222", "price": "0.99", "size": "1268989.2", "side": "SELL", "hash": "cb10fcfec9484af435587c263ff8518eadc9dab9", "best_bid": "0.53", "best_ask": "0.54"}], "timestamp": "1769384273227", "event_type": "price_change"}}
{"_local_timestamp": "2026-01-25T23:37:56.307386+00:00", "data": {"market": "0x0a99479228e93524b25676ae69b94bd3f4278a6bca8d8c265c84d24755399cf5", "price_changes": [{"asset_id": "67109747366255871599717338045111308888043498275177238365560740200996017915657", "price": "0.01", "size": "1268994.2", "side": "BUY", "hash": "664887bbab9390bfd5aeec0aefaae01189fb7b86", "best_bid": "0.46", "best_ask": "0.47"}, {"asset_id": "103845791232328975452762372781150730610824357544180691092497335946993481308222", "price": "0.99", "size": "1268994.2", "side": "SELL", "hash": "c1de88cdafd2110513dedd69589e8e376b69b1b5", "best_bid": "0.53", "best_ask": "0.54"}], "timestamp": "1769384276241", "event_type": "price_change"}}
{"_local_timestamp": "2026-01-25T23:37:58.218722+00:00", "data": {"market": "0x0a99479228e93524b25676ae69b94bd3f4278a6bca8d8c265c84d24755399cf5", "price_changes": [{"asset_id": "67109747366255871599717338045111308888043498275177238365560740200996017915657", "price": "0.01", "size": "1268999.2", "side": "BUY", "hash": "4dd63b9a4315e3576a17958034774a266f81125e", "best_bid": "0.46", "best_ask": "0.47"}, {"asset_id": "103845791232328975452762372781150730610824357544180691092497335946993481308222", "price": "0.99", "size": "1268999.2", "side": "SELL", "hash": "4a6503c48d0892de6688d1e979a6b6de602ccdfa", "best_bid": "0.53", "best_ask": "0.54"}], "timestamp": "1769384278147", "event_type": "price_change"}}
{"_local_timestamp": "2026-01-25T23:38:01.476219+00:00", "data": {"market": "0x0a99479228e93524b25676ae69b94bd3f4278a6bca8d8c265c84d24755399cf5", "price_changes": [{"asset_id": "67109747366255871599717338045111308888043498275177238365560740200996017915657", "price": "0.01", "size": "1269004.2", "side": "BUY", "hash": "a1d2da4cd45e9169a935cbb1993a743f24e385ae", "best_bid": "0.46", "best_ask": "0.47"}, {"asset_id": "103845791232328975452762372781150730610824357544180691092497335946993481308222", "price": "0.99", "size": "1269004.2", "side": "SELL", "hash": "6436f533455fef31ddd0b8c1a394f1a512a1e4e9", "best_bid": "0.53", "best_ask": "0.54"}], "timestamp": "1769384281406", "event_type": "price_change"}}
{"_local_timestamp": "2026-01-25T23:38:02.041042+00:00", "data": {"market": "0x0a99479228e93524b25676ae69b94bd3f4278a6bca8d8c265c84d24755399cf5", "price_changes": [{"asset_id": "67109747366255871599717338045111308888043498275177238365560740200996017915657", "price": "0.01", "size": "1269009.2", "side": "BUY", "hash": "19304591b8e99a846f31dc60056b7126cfc63c5d", "best_bid": "0.46", "best_ask": "0.47"}, {"asset_id": "103845791232328975452762372781150730610824357544180691092497335946993481308222", "price": "0.99", "size": "1269009.2", "side": "SELL", "hash": "55889cf2dbbd269a2423c5aa47929d3fa46a2f97", "best_bid": "0.53", "best_ask": "0.54"}], "timestamp": "1769384281950", "event_type": "price_change"}}
{"_local_timestamp": "2026-01-25T23:38:02.086647+00:00", "data": {"market": "0x0a99479228e93524b25676ae69b94bd3f4278a6bca8d8c265c84d24755399cf5", "price_changes": [{"asset_id": "67109747366255871599717338045111308888043498275177238365560740200996017915657", "price": "0.01", "size": "1269004.2", "side": "BUY", "hash": "709a2b11d34d932343acc43671974e4fc3cabbaa", "best_bid": "0.46", "best_ask": "0.47"}, {"asset_id": "103845791232328975452762372781150730610824357544180691092497335946993481308222", "price": "0.99", "size": "1269004.2", "side": "SELL", "hash": "2a77d566a9dc2ff5d5e0026d57b6ccacfa4f281a", "best_bid": "0.53", "best_ask": "0.54"}], "timestamp": "1769384282002", "event_type": "price_change"}}
{"_local_timestamp": "2026-01-25T23:38:06.086843+00:00", "data": {"market": "0x0a99479228e93524b25676ae69b94bd3f4278a6bca8d8c265c84d24755399cf5", "price_changes": [{"asset_id": "67109747366255871599717338045111308888043498275177238365560740200996017915657", "price": "0.01", "size": "1268994.2", "side": "BUY", "hash": "f083471907a96565c5aab8641ca3ecca0f60df9e", "best_bid": "0.46", "best_ask": "0.47"}, {"asset_id": "103845791232328975452762372781150730610824357544180691092497335946993481308222", "price": "0.99", "size": "1268994.2", "side": "SELL", "hash": "efbbada21c10ebb516b95c70dace441965a83a78", "best_bid": "0.53", "best_ask": "0.54"}], "timestamp": "1769384286001", "event_type": "price_change"}}
{"_local_timestamp": "2026-01-25T23:38:06.087248+00:00", "data": {"market": "0x0a99479228e93524b25676ae69b94bd3f4278a6bca8d8c265c84d24755399cf5", "price_changes": [{"asset_id": "67109747366255871599717338045111308888043498275177238365560740200996017915657", "price": "0.01", "size": "1268994.2", "side": "BUY", "hash": "10ec5351bbc63c7ff97aa313f33aa630ba49e0bf", "best_bid": "0.46", "best_ask": "0.47"}, {"asset_id": "103845791232328975452762372781150730610824357544180691092497335946993481308222", "price": "0.99", "size": "1268994.2", "side": "SELL", "hash": "d798b45f6aca3f615493e8fcebffdc65beffe57b", "best_bid": "0.53", "best_ask": "0.54"}], "timestamp": "1769384286003", "event_type": "price_change"}}
{"_local_timestamp": "2026-01-25T23:38:07.659471+00:00", "data": {"market": "0x0a99479228e93524b25676ae69b94bd3f4278a6bca8d8c265c84d24755399cf5", "price_changes": [{"asset_id": "67109747366255871599717338045111308888043498275177238365560740200996017915657", "price": "0.01", "size": "1268999.2", "side": "BUY", "hash": "7fb4e8dbe56526008ae66256f7d4afa2e387f799", "best_bid": "0.46", "best_ask": "0.47"}, {"asset_id": "103845791232328975452762372781150730610824357544180691092497335946993481308222", "price": "0.99", "size": "1268999.2", "side": "SELL", "hash": "ff81749cc684c7766867279fc4d2b821da8aec49", "best_bid": "0.53", "best_ask": "0.54"}], "timestamp": "1769384287584", "event_type": "price_change"}}
{"_local_timestamp": "2026-01-25T23:38:09.238760+00:00", "data": {"market": "0x0a99479228e93524b25676ae69b94bd3f4278a6bca8d8c265c84d24755399cf5", "price_changes": [{"asset_id": "67109747366255871599717338045111308888043498275177238365560740200996017915657", "price": "0.01", "size": "1269004.2", "side": "BUY", "hash": "01f15fce0c64ae6e32651f8a390877eb5ba7a31b", "best_bid": "0.46", "best_ask": "0.47"}, {"asset_id": "103845791232328975452762372781150730610824357544180691092497335946993481308222", "price": "0.99", "size": "1269004.2", "side": "SELL", "hash": "8874d92f18b5b3ccdfd67f3768142f848e742b8e", "best_bid": "0.53", "best_ask": "0.54"}], "timestamp": "1769384289168", "event_type": "price_change"}}
{"_local_timestamp": "2026-01-25T23:38:10.149003+00:00", "data": {"market": "0x0a99479228e93524b25676ae69b94bd3f4278a6bca8d8c265c84d24755399cf5", "price_changes": [{"asset_id": "67109747366255871599717338045111308888043498275177238365560740200996017915657", "price": "0.01", "size": "1268994.2", "side": "BUY", "hash": "0019e33888b5da43e9300c024246d1e9f6add390", "best_bid": "0.46", "best_ask": "0.47"}, {"asset_id": "103845791232328975452762372781150730610824357544180691092497335946993481308222", "price": "0.99", "size": "1268994.2", "side": "SELL", "hash": "117c97734c00e3dd214d7e763b0a331c9f75a460", "best_bid": "0.53", "best_ask": "0.54"}], "timestamp": "1769384290000", "event_type": "price_change"}}
{"_local_timestamp": "2026-01-25T23:38:10.170789+00:00", "data": {"market": "0x0a99479228e93524b25676ae69b94bd3f4278a6bca8d8c265c84d24755399cf5", "price_changes": [{"asset_id": "67109747366255871599717338045111308888043498275177238365560740200996017915657", "price": "0.01", "size": "1268994.2", "side": "BUY", "hash": "0c42b1950935278e20306fd6b1ad48119d660ffe", "best_bid": "0.46", "best_ask": "0.47"}, {"asset_id": "103845791232328975452762372781150730610824357544180691092497335946993481308222", "price": "0.99", "size": "1268994.2", "side": "SELL", "hash": "8bd47a32690d0e9306f8e6d91f241509cab0d143", "best_bid": "0.53", "best_ask": "0.54"}], "timestamp": "1769384290002", "event_type": "price_change"}}
{"_local_timestamp": "2026-01-25T23:38:11.090623+00:00", "data": {"market": "0x0a99479228e93524b25676ae69b94bd3f4278a6bca8d8c265c84d24755399cf5", "price_changes": [{"asset_id": "67109747366255871599717338045111308888043498275177238365560740200996017915657", "price": "0.01", "size": "1268989.2", "side": "BUY", "hash": "d0cdbbb4a966f2494e8a85ef3b4a67e023309256", "best_bid": "0.46", "best_ask": "0.47"}, {"asset_id": "103845791232328975452762372781150730610824357544180691092497335946993481308222", "price": "0.99", "size": "1268989.2", "side": "SELL", "hash": "db550ea574b9064c4e09be2cbd28a1b2cb842cbe", "best_bid": "0.53", "best_ask": "0.54"}], "timestamp": "1769384291000", "event_type": "price_change"}}
{"_local_timestamp": "2026-01-25T23:38:12.964392+00:00", "data": {"market": "0x0a99479228e93524b25676ae69b94bd3f4278a6bca8d8c265c84d24755399cf5", "price_changes": [{"asset_id": "67109747366255871599717338045111308888043498275177238365560740200996017915657", "price": "0.01", "size": "1268994.2", "side": "BUY", "hash": "0b8b4ae0456764d0482285a32d92d18ff9fd1cf8", "best_bid": "0.46", "best_ask": "0.47"}, {"asset_id": "103845791232328975452762372781150730610824357544180691092497335946993481308222", "price": "0.99", "size": "1268994.2", "side": "SELL", "hash": "45d8376a5d7d6a37a2d99006e73f7eaccc0d5b22", "best_bid": "0.53", "best_ask": "0.54"}], "timestamp": "1769384292894", "event_type": "price_change"}}
{"_local_timestamp": "2026-01-25T23:38:13.093154+00:00", "data": {"market": "0x0a99479228e93524b25676ae69b94bd3f4278a6bca8d8c265c84d24755399cf5", "price_changes": [{"asset_id": "67109747366255871599717338045111308888043498275177238365560740200996017915657", "price": "0.01", "size": "1268989.2", "side": "BUY", "hash": "ed02c8cb0d8e55fe9e6e22fc9506f056d78cad30", "best_bid": "0.46", "best_ask": "0.47"}, {"asset_id": "103845791232328975452762372781150730610824357544180691092497335946993481308222", "price": "0.99", "size": "1268989.2", "side": "SELL", "hash": "e3ca3f0072366e0d58f1dd345a6d3955749d371a", "best_bid": "0.53", "best_ask": "0.54"}], "timestamp": "1769384293000", "event_type": "price_change"}}
{"_local_timestamp": "2026-01-25T23:38:17.111549+00:00", "data": {"market": "0x0a99479228e93524b25676ae69b94bd3f4278a6bca8d8c265c84d24755399cf5", "price_changes": [{"asset_id": "67109747366255871599717338045111308888043498275177238365560740200996017915657", "price": "0.01", "size": "1268984.2", "side": "BUY", "hash": "cc15ff66ffd9a1be84162893a4b847fb2e97832a", "best_bid": "0.46", "best_ask": "0.47"}, {"asset_id": "103845791232328975452762372781150730610824357544180691092497335946993481308222", "price": "0.99", "size": "1268984.2", "side": "SELL", "hash": "942d2793b7a796d2a4c56292cf85ad3ab7a674d8", "best_bid": "0.53", "best_ask": "0.54"}], "timestamp": "1769384297036", "event_type": "price_change"}}
{"_local_timestamp": "2026-01-25T23:38:18.475804+00:00", "data": {"market": "0x0a99479228e93524b25676ae69b94bd3f4278a6bca8d8c265c84d24755399cf5", "price_changes": [{"asset_id": "67109747366255871599717338045111308888043498275177238365560740200996017915657", "price": "0.01", "size": "1268989.2", "side": "BUY", "hash": "243e6fc75a3d8c699531a5428e03b4e292da94ff", "best_bid": "0.46", "best_ask": "0.47"}, {"asset_id": "103845791232328975452762372781150730610824357544180691092497335946993481308222", "price": "0.99", "size": "1268989.2", "side": "SELL", "hash": "ee28362302a8cc85057b945d4888679ec279d3df", "best_bid": "0.53", "best_ask": "0.54"}], "timestamp": "1769384298402", "event_type": "price_change"}}
{"_local_timestamp": "2026-01-25T23:38:18.516547+00:00", "data": {"market": "0x0a99479228e93524b25676ae69b94bd3f4278a6bca8d8c265c84d24755399cf5", "price_changes": [{"asset_id": "67109747366255871599717338045111308888043498275177238365560740200996017915657", "price": "0.01", "size": "1268994.2", "side": "BUY", "hash": "8c00e02510e9348fac60b9ed8575fbc18bea2057", "best_bid": "0.46", "best_ask": "0.47"}, {"asset_id": "103845791232328975452762372781150730610824357544180691092497335946993481308222", "price": "0.99", "size": "1268994.2", "side": "SELL", "hash": "971611800b78000ae13cc42a89f55af3c7768c60", "best_bid": "0.53", "best_ask": "0.54"}], "timestamp": "1769384298445", "event_type": "price_change"}}
{"_local_timestamp": "2026-01-25T23:38:19.337644+00:00", "data": {"market": "0x0a99479228e93524b25676ae69b94bd3f4278a6bca8d8c265c84d24755399cf5", "price_changes": [{"asset_id": "67109747366255871599717338045111308888043498275177238365560740200996017915657", "price": "0.01", "size": "1268999.2", "side": "BUY", "hash": "ef7157e7850ec1a1682a5f39f9fa0aed731a33f0", "best_bid": "0.46", "best_ask": "0.47"}, {"asset_id": "103845791232328975452762372781150730610824357544180691092497335946993481308222", "price": "0.99", "size": "1268999.2", "side": "SELL", "hash": "d9c2a9d4a545d7524afc2b29d471fd007694cf14", "best_bid": "0.53", "best_ask": "0.54"}], "timestamp": "1769384299269", "event_type": "price_change"}}
{"_local_timestamp": "2026-01-25T23:38:22.085534+00:00", "data": {"market": "0x0a99479228e93524b25676ae69b94bd3f4278a6bca8d8c265c84d24755399cf5", "price_changes": [{"asset_id": "67109747366255871599717338045111308888043498275177238365560740200996017915657", "price": "0.01", "size": "1268994.2", "side": "BUY", "hash": "cddd3724505b5f1210dccd22fb5a070199ceab7e", "best_bid": "0.46", "best_ask": "0.47"}, {"asset_id": "103845791232328975452762372781150730610824357544180691092497335946993481308222", "price": "0.99", "size": "1268994.2", "side": "SELL", "hash": "52669a616e0cdbaef091f832f95d839d9f99f697", "best_bid": "0.53", "best_ask": "0.54"}], "timestamp": "1769384302000", "event_type": "price_change"}}
{"_local_timestamp": "2026-01-25T23:38:23.091242+00:00", "data": {"market": "0x0a99479228e93524b25676ae69b94bd3f4278a6bca8d8c265c84d24755399cf5", "price_changes": [{"asset_id": "67109747366255871599717338045111308888043498275177238365560740200996017915657", "price": "0.01", "size": "1268989.2", "side": "BUY", "hash": "8bfe29e65bf71c12a4615ae66175f1fec4f5a238", "best_bid": "0.46", "best_ask": "0.47"}, {"asset_id": "103845791232328975452762372781150730610824357544180691092497335946993481308222", "price": "0.99", "size": "1268989.2", "side": "SELL", "hash": "87ccf1defc53627cdbce30ca0e98b93d1f0a592b", "best_bid": "0.53", "best_ask": "0.54"}], "timestamp": "1769384303001", "event_type": "price_change"}}
{"_local_timestamp": "2026-01-25T23:38:24.298248+00:00", "data": {"market": "0x0a99479228e93524b25676ae69b94bd3f4278a6bca8d8c265c84d24755399cf5", "price_changes": [{"asset_id": "67109747366255871599717338045111308888043498275177238365560740200996017915657", "price": "0.01", "size": "1268994.2", "side": "BUY", "hash": "1c73fff488953ffa717cbc58e3364407c4800191", "best_bid": "0.46", "best_ask": "0.47"}, {"asset_id": "103845791232328975452762372781150730610824357544180691092497335946993481308222", "price": "0.99", "size": "1268994.2", "side": "SELL", "hash": "b484e476ea10d658e2dc8ce6be85ac0dc05ee4b0", "best_bid": "0.53", "best_ask": "0.54"}], "timestamp": "1769384304227", "event_type": "price_change"}}
{"_local_timestamp": "2026-01-25T23:38:25.874410+00:00", "data": {"market": "0x0a99479228e93524b25676ae69b94bd3f4278a6bca8d8c265c84d24755399cf5", "price_changes": [{"asset_id": "67109747366255871599717338045111308888043498275177238365560740200996017915657", "price": "0.01", "size": "1268999.2", "side": "BUY", "hash": "187e3765810eaa7393058e4f62f1f73f25bb1bb1", "best_bid": "0.46", "best_ask": "0.47"}, {"asset_id": "103845791232328975452762372781150730610824357544180691092497335946993481308222", "price": "0.99", "size": "1268999.2", "side": "SELL", "hash": "532d82ad1f231660ced11f5a1ad23c531fcc8362", "best_bid": "0.53", "best_ask": "0.54"}], "timestamp": "1769384305791", "event_type": "price_change"}}
{"_local_timestamp": "2026-01-25T23:38:27.033576+00:00", "data": {"market": "0x0a99479228e93524b25676ae69b94bd3f4278a6bca8d8c265c84d24755399cf5", "price_changes": [{"asset_id": "67109747366255871599717338045111308888043498275177238365560740200996017915657", "price": "0.01", "size": "1269004.2", "side": "BUY", "hash": "e8a7679a5f73486cf227b75afa9088ba082e3a16", "best_bid": "0.46", "best_ask": "0.47"}, {"asset_id": "103845791232328975452762372781150730610824357544180691092497335946993481308222", "price": "0.99", "size": "1269004.2", "side": "SELL", "hash": "f2238c1b537325ea795beca5e450e0a296975055", "best_bid": "0.53", "best_ask": "0.54"}], "timestamp": "1769384306936", "event_type": "price_change"}}
{"_local_timestamp": "2026-01-25T23:38:27.080386+00:00", "data": {"market": "0x0a99479228e93524b25676ae69b94bd3f4278a6bca8d8c265c84d24755399cf5", "price_changes": [{"asset_id": "67109747366255871599717338045111308888043498275177238365560740200996017915657", "price": "0.01", "size": "1268994.2", "side": "BUY", "hash": "9de304f405fede341d1ed06c62cc98bc0ac72218", "best_bid": "0.46", "best_ask": "0.47"}, {"asset_id": "103845791232328975452762372781150730610824357544180691092497335946993481308222", "price": "0.99", "size": "1268994.2", "side": "SELL", "hash": "f028e393b8fb646abcc38477534773f08e9a1f91", "best_bid": "0.53", "best_ask": "0.54"}], "timestamp": "1769384307000", "event_type": "price_change"}}
{"_local_timestamp": "2026-01-25T23:38:27.088855+00:00", "data": {"market": "0x0a99479228e93524b25676ae69b94bd3f4278a6bca8d8c265c84d24755399cf5", "price_changes": [{"asset_id": "67109747366255871599717338045111308888043498275177238365560740200996017915657", "price": "0.01", "size": "1268994.2", "side": "BUY", "hash": "b8f4017e0fd8b707a5f44fdb45e5af3c0e474a80", "best_bid": "0.46", "best_ask": "0.47"}, {"asset_id": "103845791232328975452762372781150730610824357544180691092497335946993481308222", "price": "0.99", "size": "1268994.2", "side": "SELL", "hash": "70c4898950b4062da551f5f62b48581c474508cc", "best_bid": "0.53", "best_ask": "0.54"}], "timestamp": "1769384307002", "event_type": "price_change"}}
{"_local_timestamp": "2026-01-25T23:38:28.100726+00:00", "data": {"market": "0x0a99479228e93524b25676ae69b94bd3f4278a6bca8d8c265c84d24755399cf5", "price_changes": [{"asset_id": "67109747366255871599717338045111308888043498275177238365560740200996017915657", "price": "0.01", "size": "1268989.2", "side": "BUY", "hash": "90afae816bc04107b59e2d8d399896f4a1385ff1", "best_bid": "0.46", "best_ask": "0.47"}, {"asset_id": "103845791232328975452762372781150730610824357544180691092497335946993481308222", "price": "0.99", "size": "1268989.2", "side": "SELL", "hash": "6f630d1038ec6cf86f1f1afe1b1636decc3082f5", "best_bid": "0.53", "best_ask": "0.54"}], "timestamp": "1769384308002", "event_type": "price_change"}}
{"_local_timestamp": "2026-01-25T23:38:29.313844+00:00", "data": {"market": "0x0a99479228e93524b25676ae69b94bd3f4278a6bca8d8c265c84d24755399cf5", "price_changes": [{"asset_id": "67109747366255871599717338045111308888043498275177238365560740200996017915657", "price": "0.01", "size": "1268994.2", "side": "BUY", "hash": "3025ee8c3a82597b67528875b724a32aa5f5889d", "best_bid": "0.46", "best_ask": "0.47"}, {"asset_id": "103845791232328975452762372781150730610824357544180691092497335946993481308222", "price": "0.99", "size": "1268994.2", "side": "SELL", "hash": "91c9bdffe870d888a14f244fd578d77974dc10fe", "best_bid": "0.53", "best_ask": "0.54"}], "timestamp": "1769384309240", "event_type": "price_change"}}
{"_local_timestamp": "2026-01-25T23:38:29.368046+00:00", "data": {"market": "0x0a99479228e93524b25676ae69b94bd3f4278a6bca8d8c265c84d24755399cf5", "price_changes": [{"asset_id": "67109747366255871599717338045111308888043498275177238365560740200996017915657", "price": "0.01", "size": "1268999.2", "side": "BUY", "hash": "9141a2bbbfcbe67c4efeb900aaf5fb32eb504b55", "best_bid": "0.46", "best_ask": "0.47"}, {"asset_id": "103845791232328975452762372781150730610824357544180691092497335946993481308222", "price": "0.99", "size": "1268999.2", "side": "SELL", "hash": "ad920daa63d785c623ced7cecb6bc1578384c92b", "best_bid": "0.53", "best_ask": "0.54"}], "timestamp": "1769384309304", "event_type": "price_change"}}
{"_local_timestamp": "2026-01-25T23:38:35.380467+00:00", "data": {"market": "0x0a99479228e93524b25676ae69b94bd3f4278a6bca8d8c265c84d24755399cf5", "price_changes": [{"asset_id": "67109747366255871599717338045111308888043498275177238365560740200996017915657", "price": "0.01", "size": "1269004.2", "side": "BUY", "hash": "12eb7d81f3f34ddb158fade2ac3c32361bfce1f8", "best_bid": "0.46", "best_ask": "0.47"}, {"asset_id": "103845791232328975452762372781150730610824357544180691092497335946993481308222", "price": "0.99", "size": "1269004.2", "side": "SELL", "hash": "7bccd273e39f1a8f6744dd2a632aac61e09d68a7", "best_bid": "0.53", "best_ask": "0.54"}], "timestamp": "1769384315312", "event_type": "price_change"}}
{"_local_timestamp": "2026-01-25T23:38:36.089042+00:00", "data": {"market": "0x0a99479228e93524b25676ae69b94bd3f4278a6bca8d8c265c84d24755399cf5", "price_changes": [{"asset_id": "67109747366255871599717338045111308888043498275177238365560740200996017915657", "price": "0.01", "size": "1268999.2", "side": "BUY", "hash": "d53c4101eb0e810fbc6338bdf23b06bca921956a", "best_bid": "0.46", "best_ask": "0.47"}, {"asset_id": "103845791232328975452762372781150730610824357544180691092497335946993481308222", "price": "0.99", "size": "1268999.2", "side": "SELL", "hash": "22b2bfc605d51dfd36ad8a92908673462e20762b", "best_bid": "0.53", "best_ask": "0.54"}], "timestamp": "1769384316001", "event_type": "price_change"}}
{"_local_timestamp": "2026-01-25T23:38:36.655517+00:00", "data": {"market": "0x0a99479228e93524b25676ae69b94bd3f4278a6bca8d8c265c84d24755399cf5", "price_changes": [{"asset_id": "67109747366255871599717338045111308888043498275177238365560740200996017915657", "price": "0.01", "size": "1269004.2", "side": "BUY", "hash": "d98b5fbefe8f72cb7c557184b64421f167cc48ed", "best_bid": "0.46", "best_ask": "0.47"}, {"asset_id": "103845791232328975452762372781150730610824357544180691092497335946993481308222", "price": "0.99", "size": "1269004.2", "side": "SELL", "hash": "d6510c55a799da7566e4300df8ec96c824f6fe13", "best_bid": "0.53", "best_ask": "0.54"}], "timestamp": "1769384316588", "event_type": "price_change"}}
{"_local_timestamp": "2026-01-25T23:38:39.104029+00:00", "data": {"market": "0x0a99479228e93524b25676ae69b94bd3f4278a6bca8d8c265c84d24755399cf5", "price_changes": [{"asset_id": "67109747366255871599717338045111308888043498275177238365560740200996017915657", "price": "0.01", "size": "1268994.2", "side": "BUY", "hash": "3633b930ed19a9b3042d2d2ed8cc36236a6cf1bd", "best_bid": "0.46", "best_ask": "0.47"}, {"asset_id": "103845791232328975452762372781150730610824357544180691092497335946993481308222", "price": "0.99", "size": "1268994.2", "side": "SELL", "hash": "56332d29c24ed1bc2fd83f8a837fed95a8a494b5", "best_bid": "0.53", "best_ask": "0.54"}], "timestamp": "1769384319000", "event_type": "price_change"}}
{"_local_timestamp": "2026-01-25T23:38:39.137780+00:00", "data": {"market": "0x0a99479228e93524b25676ae69b94bd3f4278a6bca8d8c265c84d24755399cf5", "price_changes": [{"asset_id": "67109747366255871599717338045111308888043498275177238365560740200996017915657", "price": "0.01", "size": "1268994.2", "side": "BUY", "hash": "504c92d0ad32162e2ac2cc2c56abc2c8c673fe33", "best_bid": "0.46", "best_ask": "0.47"}, {"asset_id": "103845791232328975452762372781150730610824357544180691092497335946993481308222", "price": "0.99", "size": "1268994.2", "side": "SELL", "hash": "fa92bf9139a9103ec98989171d9ec94e926ed776", "best_bid": "0.53", "best_ask": "0.54"}], "timestamp": "1769384319004", "event_type": "price_change"}}
{"_local_timestamp": "2026-01-25T23:38:40.840743+00:00", "data": {"market": "0x0a99479228e93524b25676ae69b94bd3f4278a6bca8d8c265c84d24755399cf5", "price_changes": [{"asset_id": "67109747366255871599717338045111308888043498275177238365560740200996017915657", "price": "0.01", "size": "1268999.2", "side": "BUY", "hash": "c249b552450a4057cffdfc7c56f215f491ad7c12", "best_bid": "0.46", "best_ask": "0.47"}, {"asset_id": "103845791232328975452762372781150730610824357544180691092497335946993481308222", "price": "0.99", "size": "1268999.2", "side": "SELL", "hash": "a6db73bec9e5a31016fe9822d73ee78a39bcac37", "best_bid": "0.53", "best_ask": "0.54"}], "timestamp": "1769384320776", "event_type": "price_change"}}
{"_local_timestamp": "2026-01-25T23:38:42.548635+00:00", "data": {"market": "0x0a99479228e93524b25676ae69b94bd3f4278a6bca8d8c265c84d24755399cf5", "price_changes": [{"asset_id": "67109747366255871599717338045111308888043498275177238365560740200996017915657", "price": "0.01", "size": "1269004.2", "side": "BUY", "hash": "cc432e9d47e47f1e63f93025f4ba177b5e9ac4ab", "best_bid": "0.46", "best_ask": "0.47"}, {"asset_id": "103845791232328975452762372781150730610824357544180691092497335946993481308222", "price": "0.99", "size": "1269004.2", "side": "SELL", "hash": "ae71e5473c9f4baf325cd66e52357b72a3ab2f13", "best_bid": "0.53", "best_ask": "0.54"}], "timestamp": "1769384322476", "event_type": "price_change"}}
{"_local_timestamp": "2026-01-25T23:38:44.083709+00:00", "data": {"market": "0x0a99479228e93524b25676ae69b94bd3f4278a6bca8d8c265c84d24755399cf5", "price_changes": [{"asset_id": "67109747366255871599717338045111308888043498275177238365560740200996017915657", "price": "0.01", "size": "1268989.2", "side": "BUY", "hash": "79c1b4f425605096823c9b5d0fd32d572cb4b074", "best_bid": "0.46", "best_ask": "0.47"}, {"asset_id": "103845791232328975452762372781150730610824357544180691092497335946993481308222", "price": "0.99", "size": "1268989.2", "side": "SELL", "hash": "919fe20bca9377f00a896be5bf7aca54e29380e4", "best_bid": "0.53", "best_ask": "0.54"}], "timestamp": "1769384324000", "event_type": "price_change"}}
{"_local_timestamp": "2026-01-25T23:38:44.089619+00:00", "data": {"market": "0x0a99479228e93524b25676ae69b94bd3f4278a6bca8d8c265c84d24755399cf5", "price_changes": [{"asset_id": "67109747366255871599717338045111308888043498275177238365560740200996017915657", "price": "0.01", "size": "1268989.2", "side": "BUY", "hash": "f21b89e130afa2ca03a1bc35f8fa3059b6aad048", "best_bid": "0.46", "best_ask": "0.47"}, {"asset_id": "103845791232328975452762372781150730610824357544180691092497335946993481308222", "price": "0.99", "size": "1268989.2", "side": "SELL", "hash": "b51b571a1cbea090bb2b0a7286062c10184c0a53", "best_bid": "0.53", "best_ask": "0.54"}], "timestamp": "1769384324002", "event_type": "price_change"}}
{"_local_timestamp": "2026-01-25T23:38:44.090032+00:00", "data": {"market": "0x0a99479228e93524b25676ae69b94bd3f4278a6bca8d8c265c84d24755399cf5", "price_changes": [{"asset_id": "67109747366255871599717338045111308888043498275177238365560740200996017915657", "price": "0.01", "size": "1268989.2", "side": "BUY", "hash": "6cc32c18c38622161903d66eabaa1725a02ef5a0", "best_bid": "0.46", "best_ask": "0.47"}, {"asset_id": "103845791232328975452762372781150730610824357544180691092497335946993481308222", "price": "0.99", "size": "1268989.2", "side": "SELL", "hash": "293ec41576cb54674d5964ee930a1edf2194ac67", "best_bid": "0.53", "best_ask": "0.54"}], "timestamp": "1769384324003", "event_type": "price_change"}}
{"_local_timestamp": "2026-01-25T23:38:45.088902+00:00", "data": {"market": "0x0a99479228e93524b25676ae69b94bd3f4278a6bca8d8c265c84d24755399cf5", "price_changes": [{"asset_id": "67109747366255871599717338045111308888043498275177238365560740200996017915657", "price": "0.01", "size": "1268984.2", "side": "BUY", "hash": "c4fc3dd8e906fc6e708186ef8bd6f89aa451db98", "best_bid": "0.46", "best_ask": "0.47"}, {"asset_id": "103845791232328975452762372781150730610824357544180691092497335946993481308222", "price": "0.99", "size": "1268984.2", "side": "SELL", "hash": "bca5250fd7cd6fc6914751ea9496b1807649dcf5", "best_bid": "0.53", "best_ask": "0.54"}], "timestamp": "1769384325000", "event_type": "price_change"}}
{"_local_timestamp": "2026-01-25T23:38:45.972296+00:00", "data": {"market": "0x0a99479228e93524b25676ae69b94bd3f4278a6bca8d8c265c84d24755399cf5", "price_changes": [{"asset_id": "67109747366255871599717338045111308888043498275177238365560740200996017915657", "price": "0.01", "size": "1268989.2", "side": "BUY", "hash": "32706fa3610f71edcc3285f38d27d5f3d742cf23", "best_bid": "0.46", "best_ask": "0.47"}, {"asset_id": "103845791232328975452762372781150730610824357544180691092497335946993481308222", "price": "0.99", "size": "1268989.2", "side": "SELL", "hash": "77596833d63ac7090329912892e7f7feaf7d3365", "best_bid": "0.53", "best_ask": "0.54"}], "timestamp": "1769384325904", "event_type": "price_change"}}
{"_local_timestamp": "2026-01-25T23:38:48.095116+00:00", "data": {"market": "0x0a99479228e93524b25676ae69b94bd3f4278a6bca8d8c265c84d24755399cf5", "price_changes": [{"asset_id": "67109747366255871599717338045111308888043498275177238365560740200996017915657", "price": "0.01", "size": "1268984.2", "side": "BUY", "hash": "d9cd5964c9d8e2d7baa3bc2a50671c9499d23519", "best_bid": "0.46", "best_ask": "0.47"}, {"asset_id": "103845791232328975452762372781150730610824357544180691092497335946993481308222", "price": "0.99", "size": "1268984.2", "side": "SELL", "hash": "4fd267bfc859d7a97e78a4ec008656f4a56049ee", "best_bid": "0.53", "best_ask": "0.54"}], "timestamp": "1769384328002", "event_type": "price_change"}}
{"_local_timestamp": "2026-01-25T23:38:49.488602+00:00", "data": {"market": "0x0a99479228e93524b25676ae69b94bd3f4278a6bca8d8c265c84d24755399cf5", "price_changes": [{"asset_id": "67109747366255871599717338045111308888043498275177238365560740200996017915657", "price": "0.01", "size": "1268989.2", "side": "BUY", "hash": "b09edfc47dfa35ce7ca85216c0203b129204a175", "best_bid": "0.46", "best_ask": "0.47"}, {"asset_id": "103845791232328975452762372781150730610824357544180691092497335946993481308222", "price": "0.99", "size": "1268989.2", "side": "SELL", "hash": "df143d0bfc50a7f83e7d4e362cc7278a1ecf428c", "best_bid": "0.53", "best_ask": "0.54"}], "timestamp": "1769384329405", "event_type": "price_change"}}
