{"_local_timestamp": "2026-01-25T23:33:17.552661+00:00", "data": [{"market": "0x4e4f77e7dbf4cab666e9a1943674d7ae66348e862df03ea6f44b11eb95731928", "asset_id": "65139230827417363158752884968303867495725894165574887635816574090175320800482", "timestamp": "1769383982805", "hash": "7b6d87472c673af5210f6390efd8cdc2ec8b876e", "bids": [{"price": "0.01", "size": "510018"}, {"price": "0.02", "size": "300008.31"}, {"price": "0.03", "size": "200000"}, {"price": "0.04", "size": "40005.5"}, {"price": "0.05", "size": "2000"}, {"price": "0.06", "size": "15000"}, {"price": "0.07", "size": "8.76"}, {"price": "0.1", "size": "1000"}, {"price": "0.14", "size": "10100"}, {"price": "0.16", "size": "6687.5"}, {"price": "0.17", "size": "8795.68"}, {"price": "0.18", "size": "9300"}, {"price": "0.19", "size": "12300"}, {"price": "0.2", "size": "26877.71"}, {"price": "0.21", "size": "30984"}], "asks": [{"price": "0.99", "size": "1100020.95"}, {"price": "0.98", "size": "400011.47"}, {"price": "0.97", "size": "300000"}, {"price": "0.96", "size": "200000"}, {"price": "0.95", "size": "755.32"}, {"price": "0.92", "size": "450"}, {"price": "0.91", "size": "3337.14"}, {"price": "0.88", "size": "283.33"}, {"price": "0.85", "size": "500"}, {"price": "0.84", "size": "1200"}, {"price": "0.83", "size": "940"}, {"price": "0.82", "size": "5.34"}, {"price": "0.8", "size": "10140"}, {"price": "0.79", "size": "1998"}, {"price": "0.76", "size": "108.33"}, {"price": "0.72", "size": "85.71"}, {"price": "0.7", "size": "5000"}, {"price": "0.68", "size": "62.5"}, {"price": "0.67", "size": "28.78"}, {"price": "0.66", "size": "500"}, {"price": "0.6", "size": "2500"}, {"price": "0.59", "size": "2816.87"}, {"price": "0.55", "size": "42.7"}, {"price": "0.5", "size": "2885.01"}, {"price": "0.48", "size": "100"}, {"price": "0.45", "size": "250"}, {"price": "0.43", "size": "1676.97"}, {"price": "0.41", "size": "50"}, {"price": "0.4", "size": "574.15"}, {"price": "0.39", "size": "1000"}, {"price": "0.38", "size": "10"}, {"price": "0.36", "size": "18423.77"}, {"price": "0.35", "size": "2543.06"}, {"price": "0.34", "size": "2754.16"}, {"price": "0.33", "size": "5551.26"}, {"price": "0.32", "size": "1315"}, {"price": "0.3", "size": "250"}, {"price": "0.29", "size": "47978.91"}, {"price": "0.28", "size": "5200"}, {"price": "0.27", "size": "7520"}, {"price": "0.26", "size": "1428.8"}, {"price": "0.25", "size": "5522.12"}, {"price": "0.24", "size": "3200"}, {"price": "0.23", "size": "16960.23"}, {"price": "0.22", "size": "15919.84"}], "event_type": "book", "last_trade_price": "0.210"}, {"market": "0xd5d9fc47718bd553592d126b1fa5e87183d27f3936975b0c04cc0f2dec1f1bb4", "asset_id": "33156410999665902694791064431724433042010245771106314074312009703157423879038", "timestamp": "1769383984035", "hash": "192c00fd17e2373a7f9db39363b03266f96db040", "bids": [{"price": "0.01", "size": "510324.58"}, {"price": "0.02", "size": "500014.5"}, {"price": "0.03", "size": "200000"}, {"price": "0.04", "size": "200006.69"}, {"price": "0.05", "size": "20"}, {"price": "0.06", "size": "9.69"}, {"price": "0.07", "size": "30000"}, {"price": "0.08", "size": "12000"}, {"price": "0.1", "size": "6000"}, {"price": "0.11", "size": "7.21"}, {"price": "0.14", "size": "2000"}, {"price": "0.15", "size": "213.1"}, {"price": "0.16", "size": "87.1"}, {"price": "0.17", "size": "1066"}, {"price": "0.18", "size": "1165"}, {"price": "0.19", "size": "13107.39"}, {"price": "0.2", "size": "11377.1"}], "asks": [{"price": "0.99", "size": "1100125.58"}, {"price": "0.98", "size": "500000"}, {"price": "0.97", "size": "9.14"}, {"price": "0.95", "size": "100000"}, {"price": "0.92", "size": "50450"}, {"price": "0.91", "size": "3332"}, {"price": "0.9", "size": "6.28"}, {"price": "0.88", "size": "283.33"}, {"price": "0.87", "size": "1230"}, {"price": "0.84", "size": "200"}, {"price": "0.83", "size": "5000"}, {"price": "0.82", "size": "888"}, {"price": "0.8", "size": "192"}, {"price": "0.78", "size": "1000"}, {"price": "0.77", "size": "1826"}, {"price": "0.76", "size": "108.33"}, {"price": "0.72", "size": "85.71"}, {"price": "0.68", "size": "62.5"}, {"price": "0.67", "size": "15.15"}, {"price": "0.65", "size": "200"}, {"price": "0.6", "size": "10"}, {"price": "0.55", "size": "100"}, {"price": "0.5", "size": "1609"}, {"price": "0.45", "size": "4618.93"}, {"price": "0.44", "size": "45.45"}, {"price": "0.4", "size": "40"}, {"price": "0.39", "size": "38220"}, {"price": "0.38", "size": "2720"}, {"price": "0.37", "size": "20"}, {"price": "0.36", "size": "20"}, {"price": "0.35", "size": "1632.9"}, {"price": "0.34", "size": "20"}, {"price": "0.33", "size": "1053"}, {"price": "0.32", "size": "658"}, {"price": "0.31", "size": "2302"}, {"price": "0.3", "size": "12020"}, {"price": "0.29", "size": "12549.95"}, {"price": "0.28", "size": "3620"}, {"price": "0.27", "size": "20"}, {"price": "0.26", "size": "230"}, {"price": "0.25", "size": "15946.93"}, {"price": "0.24", "size": "130678.75"}, {"price": "0.23", "size": "41605.01"}, {"price": "0.22", "size": "26421.73"}], "event_type": "book", "last_trade_price": "0.780"}, {"market": "0xd5d9fc47718bd553592d126b1fa5e87183d27f3936975b0c04cc0f2dec1f1bb4", "asset_id": "83247781037352156539108067944461291821683755894607244160607042790356561625563", "timestamp": "1769383984035", "hash": "591b9044145ed130f70db6f7481ab5b4870df2fa", "bids": [{"price": "0.01", "size": "1100125.58"}, {"price": "0.02", "size": "500000"}, {"price": "0.03", "size": "9.14"}, {"price": "0.05", "size": "100000"}, {"price": "0.08", "size": "50450"}, {"price": "0.09", "size": "3332"}, {"price": "0.1", "size": "6.28"}, {"price": "0.12", "size": "283.33"}, {"price": "0.13", "size": "1230"}, {"price": "0.16", "size": "200"}, {"price": "0.17", "size": "5000"}, {"price": "0.18", "size": "888"}, {"price": "0.2", "size": "192"}, {"price": "0.22", "size": "1000"}, {"price": "0.23", "size": "1826"}, {"price": "0.24", "size": "108.33"}, {"price": "0.28", "size": "85.71"}, {"price": "0.32", "size": "62.5"}, {"price": "0.33", "size": "15.15"}, {"price": "0.35", "size": "200"}, {"price": "0.4", "size": "10"}, {"price": "0.45", "size": "100"}, {"price": "0.5", "size": "1609"}, {"price": "0.55", "size": "4618.93"}, {"price": "0.56", "size": "45.45"}, {"price": "0.6", "size": "40"}, {"price": "0.61", "size": "38220"}, {"price": "0.62", "size": "2720"}, {"price": "0.63", "size": "20"}, {"price": "0.64", "size": "20"}, {"price": "0.65", "size": "1632.9"}, {"price": "0.66", "size": "20"}, {"price": "0.67", "size": "1053"}, {"price": "0.68", "size": "658"}, {"price": "0.69", "size": "2302"}, {"price": "0.7", "size": "12020"}, {"price": "0.71", "size": "12549.95"}, {"price": "0.72", "size": "3620"}, {"price": "0.73", "size": "20"}, {"price": "0.74", "size": "230"}, {"price": "0.75", "size": "15946.93"}, {"price": "0.76", "size": "130678.75"}, {"price": "0.77", "size": "41605.01"}, {"price": "0.78", "size": "26421.73"}], "asks": [{"price": "0.99", "size": "510324.58"}, {"price": "0.98", "size": "500014.5"}, {"price": "0.97", "size": "200000"}, {"price": "0.96", "size": "200006.69"}, {"price": "0.95", "size": "20"}, {"price": "0.94", "size": "9.69"}, {"price": "0.93", "size": "30000"}, {"price": "0.92", "size": "12000"}, {"price": "0.9", "size": "6000"}, {"price": "0.89", "size": "7.21"}, {"price": "0.86", "size": "2000"}, {"price": "0.85", "size": "213.1"}, {"price": "0.84", "size": "87.1"}, {"price": "0.83", "size": "1066"}, {"price": "0.82", "size": "1165"}, {"price": "0.81", "size": "13107.39"}, {"price": "0.8", "size": "11377.1"}], "event_type": "book", "last_trade_price": "0.780"}, {"market": "0x4e4f77e7dbf4cab666e9a1943674d7ae66348e862df03ea6f44b11eb95731928", "asset_id": "17371217118862125782438074585166210555214661810823929795910191856905580975576", "timestamp": "1769383982805", "hash": "9ff4f23aaa1e09907ec1781fa304571a5722af36", "bids": [{"price": "0.01", "size": "1100020.95"}, {"price": "0.02", "size": "400011.47"}, {"price": "0.03", "size": "300000"}, {"price": "0.04", "size": "200000"}, {"price": "0.05", "size": "755.32"}, {"price": "0.08", "size": "450"}, {"price": "0.09", "size": "3337.14"}, {"price": "0.12", "size": "283.33"}, {"price": "0.15", "size": "500"}, {"price": "0.16", "size": "1200"}, {"price": "0.17", "size": "940"}, {"price": "0.18", "size": "5.34"}, {"price": "0.2", "size": "10140"}, {"price": "0.21", "size": "1998"}, {"price": "0.24", "size": "108.33"}, {"price": "0.28", "size": "85.71"}, {"price": "0.3", "size": "5000"}, {"price": "0.32", "size": "62.5"}, {"price": "0.33", "size": "28.78"}, {"price": "0.34", "size": "500"}, {"price": "0.4", "size": "2500"}, {"price": "0.41", "size": "2816.87"}, {"price": "0.45", "size": "42.7"}, {"price": "0.5", "size": "2885.01"}, {"price": "0.52", "size": "100"}, {"price": "0.55", "size": "250"}, {"price": "0.57", "size": "1676.97"}, {"price": "0.59", "size": "50"}, {"price": "0.6", "size": "574.15"}, {"price": "0.61", "size": "1000"}, {"price": "0.62", "size": "10"}, {"price": "0.64", "size": "18423.77"}, {"price": "0.65", "size": "2543.06"}, {"price": "0.66", "size": "2754.16"}, {"price": "0.67", "size": "5551.26"}, {"price": "0.68", "size": "1315"}, {"price": "0.7", "size": "250"}, {"price": "0.71", "size": "47978.91"}, {"price": "0.72", "size": "5200"}, {"price": "0.73", "size": "7520"}, {"price": "0.74", "size": "1428.8"}, {"price": "0.75", "size": "5522.12"}, {"price": "0.76", "size": "3200"}, {"price": "0.77", "size": "16960.23"}, {"price": "0.78", "size": "15919.84"}], "asks": [{"price": "0.99", "size": "510018"}, {"price": "0.98", "size": "300008.31"}, {"price": "0.97", "size": "200000"}, {"price": "0.96", "size": "40005.5"}, {"price": "0.95", "size": "2000"}, {"price": "0.94", "size": "15000"}, {"price": "0.93", "size": "8.76"}, {"price": "0.9", "size": "1000"}, {"price": "0.86", "size": "10100"}, {"price": "0.84", "size": "6687.5"}, {"price": "0.83", "size": "8795.68"}, {"price": "0.82", "size": "9300"}, {"price": "0.81", "size": "12300"}, {"price": "0.8", "size": "26877.71"}, {"price": "0.79", "size": "30984"}], "event_type": "book", "last_trade_price": "0.210"}]}
{"_local_timestamp": "2026-01-25T23:33:19.985922+00:00", "data": {"market": "0xd5d9fc47718bd553592d126b1fa5e87183d27f3936975b0c04cc0f2dec1f1bb4", "price_changes": [{"asset_id": "83247781037352156539108067944461291821683755894607244160607042790356561625563", "price": "0.77", "size": "41405.01", "side": "BUY", "hash": "6159bb3c6083ee54f758b546d7ac20955d4a4693", "best_bid": "0.78", "best_ask": "0.8"}, {"asset_id": "33156410999665902694791064431724433042010245771106314074312009703157423879038", "price": "0.23", "size": "41405.01", "side": "SELL", "hash": "41e82c9ee1b4f7dcc534b5291b691b0310f00de9", "best_bid": "0.2", "best_ask": "0.22"}], "timestamp": "1769383999916", "event_type": "price_change"}}
{"_local_timestamp": "2026-01-25T23:33:20.015798+00:00", "data": {"market": "0xd5d9fc47718bd553592d126b1fa5e87183d27f3936975b0c04cc0f2dec1f1bb4", "price_changes": [{"asset_id": "83247781037352156539108067944461291821683755894607244160607042790356561625563", "price": "0.77", "size": "41605.01", "side": "BUY", "hash": "820ef210ff29b5a522cdba91d1860001871228a3", "best_bid": "0.78", "best_ask": "0.8"}, {"asset_id": "33156410999665902694791064431724433042010245771106314074312009703157423879038", "price": "0.23", "size": "41605.01", "side": "SELL", "hash": "277d1ebd02435a415ea82eb506e41c047043d35d", "best_bid": "0.2", "best_ask": "0.22"}], "timestamp": "1769383999947", "event_type": "price_change"}}
{"_local_timestamp": "2026-01-25T23:33:20.086343+00:00", "data": {"market": "0x4e4f77e7dbf4cab666e9a1943674d7ae66348e862df03ea6f44b11eb95731928", "price_changes": [{"asset_id": "17371217118862125782438074585166210555214661810823929795910191856905580975576", "price": "0.77", "size": "18809.33", "side": "BUY", "hash": "c28bb923b0d0fae1fcd64aa17e3afc7bd26cdf9a", "best_bid": "0.78", "best_ask": "0.79"}, {"asset_id": "65139230827417363158752884968303867495725894165574887635816574090175320800482", "price": "0.23", "size": "18809.33", "side": "SELL", "hash": "85e468b77e0c590f749c3d6addfbe7d12b8a6b01", "best_bid": "0.21", "best_ask": "0.22"}], "timestamp": "1769384000003", "event_type": "price_change"}}
{"_local_timestamp": "2026-01-25T23:33:20.086800+00:00", "data": {"market": "0xd5d9fc47718bd553592d126b1fa5e87183d27f3936975b0c04cc0f2dec1f1bb4", "price_changes": [{"asset_id": "33156410999665902694791064431724433042010245771106314074312009703157423879038", "price": "0.2", "size": "13226.2", "side": "BUY", "hash": "bcd5b4e4ce6f0e79bc575aa5bd5694bfb80cec61", "best_bid": "0.2", "best_ask": "0.22"}, {"asset_id": "83247781037352156539108067944461291821683755894607244160607042790356561625563", "price": "0.8", "size": "13226.2", "side": "SELL", "hash": "2d250fc0a46d2c2886c1b64976c9119a061a3a24", "best_bid": "0.78", "best_ask": "0.8"}], "timestamp": "1769384000007", "event_type": "price_change"}}
{"_local_timestamp": "2026-01-25T23:33:20.089372+00:00", "data": {"market": "0x4e4f77e7dbf4cab666e9a1943674d7ae66348e862df03ea6f44b11eb95731928", "price_changes": [{"asset_id": "65139230827417363158752884968303867495725894165574887635816574090175320800482", "price": "0.21", "size": "30784", "side": "BUY", "hash": "17e941b8baea5a804eef9fc0bbcf373fd871a00d", "best_bid": "0.21", "best_ask": "0.22"}, {"asset_id": "17371217118862125782438074585166210555214661810823929795910191856905580975576", "price": "0.79", "size": "30784", "side": "SELL", "hash": "cfe5417cbd3fe2961fd5b226e3c49480d19b0508", "best_bid": "0.78", "best_ask": "0.79"}], "timestamp": "1769384000011", "event_type": "price_change"}}
{"_local_timestamp": "2026-01-25T23:33:20.125940+00:00", "data": {"market": "0x4e4f77e7dbf4cab666e9a1943674d7ae66348e862df03ea6f44b11eb95731928", "price_changes": [{"asset_id": "65139230827417363158752884968303867495725894165574887635816574090175320800482", "price": "0.21", "size": "30984", "side": "BUY", "hash": "154dd335297b1290b594898be4e92201c8e780a3", "best_bid": "0.21", "best_ask": "0.22"}, {"asset_id": "17371217118862125782438074585166210555214661810823929795910191856905580975576", "price": "0.79", "size": "30984", "side": "SELL", "hash": "f14623356e4f34ad43634deb8f6b94be3481bda5", "best_bid": "0.78", "best_ask": "0.79"}], "timestamp": "1769384000042", "event_type": "price_change"}}
{"_local_timestamp": "2026-01-25T23:33:20.139700+00:00", "data": {"market": "0x4e4f77e7dbf4cab666e9a1943674d7ae66348e862df03ea6f44b11eb95731928", "price_changes": [{"asset_id": "17371217118862125782438074585166210555214661810823929795910191856905580975576", "price": "0.76", "size": "3000", "side": "BUY", "hash": "bbfdcd6bf50d3c46af3b4f34e3d3ac5199dcd2c7", "best_bid": "0.78", "best_ask": "0.79"}, {"asset_id": "65139230827417363158752884968303867495725894165574887635816574090175320800482", "price": "0.24", "size": "3000", "side": "SELL", "hash": "152bd3ab84321e504f2e5ddc46f8d11a2fc24ec1", "best_bid": "0.21", "best_ask": "0.22"}], "timestamp": "1769384000066", "event_type": "price_change"}}
{"_local_timestamp": "2026-01-25T23:33:20.174243+00:00", "data": {"market": "0x4e4f77e7dbf4cab666e9a1943674d7ae66348e862df03ea6f44b11eb95731928", "price_changes": [{"asset_id": "17371217118862125782438074585166210555214661810823929795910191856905580975576", "price": "0.76", "size": "3200", "side": "BUY", "hash": "abc1b827ec195c8ffe2a4871627bebc12bd8d555", "best_bid": "0.78", "best_ask": "0.79"}, {"asset_id": "65139230827417363158752884968303867495725894165574887635816574090175320800482", "price": "0.24", "size": "3200", "side": "SELL", "hash": "b6c182fb8b024317d713c2f97ddb76ebbba2200c", "best_bid": "0.21", "best_ask": "0.22"}], "timestamp": "1769384000100", "event_type": "price_change"}}
{"_local_timestamp": "2026-01-25T23:33:20.327459+00:00", "data": {"market": "0xd5d9fc47718bd553592d126b1fa5e87183d27f3936975b0c04cc0f2dec1f1bb4", "price_changes": [{"asset_id": "33156410999665902694791064431724433042010245771106314074312009703157423879038", "price": "0.2", "size": "11377.1", "side": "BUY", "hash": "0c440a8e0ac88cc1afca3b48ca5e3f21450f2caf", "best_bid": "0.2", "best_ask": "0.22"}, {"asset_id": "83247781037352156539108067944461291821683755894607244160607042790356561625563", "price": "0.8", "size": "11377.1", "side": "SELL", "hash": "787c9d2912f432f2bd06db7731a7da06f274e860", "best_bid": "0.78", "best_ask": "0.8"}], "timestamp": "1769384000254", "event_type": "price_change"}}
{"_local_timestamp": "2026-01-25T23:33:20.329901+00:00", "data": {"market": "0x4e4f77e7dbf4cab666e9a1943674d7ae66348e862df03ea6f44b11eb95731928", "price_changes": [{"asset_id": "17371217118862125782438074585166210555214661810823929795910191856905580975576", "price": "0.77", "size": "16960.23", "side": "BUY", "hash": "fda911b89060d0c24bca90e9fa9301f93976b7d6", "best_bid": "0.78", "best_ask": "0.79"}, {"asset_id": "65139230827417363158752884968303867495725894165574887635816574090175320800482", "price": "0.23", "size": "16960.23", "side": "SELL", "hash": "87deac1cb0ff78f755138f24623e335dfed8449e", "best_bid": "0.21", "best_ask": "0.22"}], "timestamp": "1769384000254", "event_type": "price_change"}}
{"_local_timestamp": "2026-01-25T23:33:42.505612+00:00", "data": {"market": "0xd5d9fc47718bd553592d126b1fa5e87183d27f3936975b0c04cc0f2dec1f1bb4", "price_changes": [{"asset_id": "83247781037352156539108067944461291821683755894607244160607042790356561625563", "price": "0.74", "size": "220", "side": "BUY", "hash": "5bc7da4cda12be1e599a88cefb640dff6d2b6139", "best_bid": "0.78", "best_ask": "0.8"}, {"asset_id": "33156410999665902694791064431724433042010245771106314074312009703157423879038", "price": "0.26", "size": "220", "side": "SELL", "hash": "dff2cfe58630cbebfb92c2e72e3e2e75f265b203", "best_bid": "0.2", "best_ask": "0.22"}], "timestamp": "1769384022438", "event_type": "price_change"}}
{"_local_timestamp": "2026-01-25T23:33:42.562125+00:00", "data": {"market": "0xd5d9fc47718bd553592d126b1fa5e87183d27f3936975b0c04cc0f2dec1f1bb4", "price_changes": [{"asset_id": "83247781037352156539108067944461291821683755894607244160607042790356561625563", "price": "0.75", "size": "15936.93", "side": "BUY", "hash": "eda88d45a1fae6032cfe7cac20157b024cd49d88", "best_bid": "0.78", "best_ask": "0.8"}, {"asset_id": "33156410999665902694791064431724433042010245771106314074312009703157423879038", "price": "0.25", "size": "15936.93", "side": "SELL", "hash": "5f0e8b54a0dbc658b1b6f72039c52e32c26bbdb6", "best_bid": "0.2", "best_ask": "0.22"}], "timestamp": "1769384022484", "event_type": "price_change"}}
{"_local_timestamp": "2026-01-25T23:33:42.605949+00:00", "data": {"market": "0xd5d9fc47718bd553592d126b1fa5e87183d27f3936975b0c04cc0f2dec1f1bb4", "price_changes": [{"asset_id": "33156410999665902694791064431724433042010245771106314074312009703157423879038", "price": "0.2", "size": "13249.79", "side": "BUY", "hash": "22b0880aade896c3a4832e04bb30e25fdfd4464d", "best_bid": "0.2", "best_ask": "0.22"}, {"asset_id": "83247781037352156539108067944461291821683755894607244160607042790356561625563", "price": "0.8", "size": "13249.79", "side": "SELL", "hash": "d5bd4774a5173d2aff2c7e346d7335bb40472fb4", "best_bid": "0.78", "best_ask": "0.8"}], "timestamp": "1769384022540", "event_type": "price_change"}}
{"_local_timestamp": "2026-01-25T23:33:42.616130+00:00", "data": {"market": "0x4e4f77e7dbf4cab666e9a1943674d7ae66348e862df03ea6f44b11eb95731928", "price_changes": [{"asset_id": "17371217118862125782438074585166210555214661810823929795910191856905580975576", "price": "0.77", "size": "18832.92", "side": "BUY", "hash": "27b0eaba0932e6a940d8a008cb68dde3067415ee", "best_bid": "0.78", "best_ask": "0.79"}, {"asset_id": "65139230827417363158752884968303867495725894165574887635816574090175320800482", "price": "0.23", "size": "18832.92", "side": "SELL", "hash": "72cd05574d67217867459deb8fa7d165781a2f89", "best_bid": "0.21", "best_ask": "0.22"}], "timestamp": "1769384022545", "event_type": "price_change"}}
{"_local_timestamp": "2026-01-25T23:33:42.623811+00:00", "data": {"market": "0xd5d9fc47718bd553592d126b1fa5e87183d27f3936975b0c04cc0f2dec1f1bb4", "price_changes": [{"asset_id": "83247781037352156539108067944461291821683755894607244160607042790356561625563", "price": "0.76", "size": "130668.75", "side": "BUY", "hash": "41ec85fd5c0ccd741424c2790feec454065c2a61", "best_bid": "0.78", "best_ask": "0.8"}, {"asset_id": "33156410999665902694791064431724433042010245771106314074312009703157423879038", "price": "0.24", "size": "130668.75", "side": "SELL", "hash": "95b1d6c3da19a387af276e902ce3c82acc584189", "best_bid": "0.2", "best_ask": "0.22"}], "timestamp": "1769384022554", "event_type": "price_change"}}
{"_local_timestamp": "2026-01-25T23:33:42.669602+00:00", "data": {"market": "0xd5d9fc47718bd553592d126b1fa5e87183d27f3936975b0c04cc0f2dec1f1bb4", "price_changes": [{"asset_id": "83247781037352156539108067944461291821683755894607244160607042790356561625563", "price": "0.77", "size": "41595.01", "side": "BUY", "hash": "759bd33d0b65922d802bfc57273214fb1d6a5713", "best_bid": "0.78", "best_ask": "0.8"}, {"asset_id": "33156410999665902694791064431724433042010245771106314074312009703157423879038", "price": "0.23", "size": "41595.01", "side": "SELL", "hash": "62a19fbf44344af41261d096907193e048d34fe2", "best_bid": "0.2", "best_ask": "0.22"}], "timestamp": "1769384022602", "event_type": "price_change"}}
{"_local_timestamp": "2026-01-25T23:33:42.710114+00:00", "data": {"market": "0xd5d9fc47718bd553592d126b1fa5e87183d27f3936975b0c04cc0f2dec1f1bb4", "price_changes": [{"asset_id": "83247781037352156539108067944461291821683755894607244160607042790356561625563", "price": "0.78", "size": "26411.73", "side": "BUY", "hash": "ae943131e71971200be1b24cca06918029710684", "best_bid": "0.78", "best_ask": "0.8"}, {"asset_id": "33156410999665902694791064431724433042010245771106314074312009703157423879038", "price": "0.22", "size": "26411.73", "side": "SELL", "hash": "8c535370e195e76a02f057a672a08af0dd2266b2", "best_bid": "0.2", "best_ask": "0.22"}], "timestamp": "1769384022640", "event_type": "price_change"}}
{"_local_timestamp": "2026-01-25T23:33:42.737642+00:00", "data": {"market": "0xd5d9fc47718bd553592d126b1fa5e87183d27f3936975b0c04cc0f2dec1f1bb4", "price_changes": [{"asset_id": "33156410999665902694791064431724433042010245771106314074312009703157423879038", "price": "0.16", "size": "77.1", "side": "BUY", "hash": "126d7637e1a460198df89b24522b6dbde69cf0b8", "best_bid": "0.2", "best_ask": "0.22"}, {"asset_id": "83247781037352156539108067944461291821683755894607244160607042790356561625563", "price": "0.84", "size": "77.1", "side": "SELL", "hash": "500b30fc3833d26f24aca31fa209d1581b95a706", "best_bid": "0.78", "best_ask": "0.8"}], "timestamp": "1769384022666", "event_type": "price_change"}}
{"_local_timestamp": "2026-01-25T23:33:42.761821+00:00", "data": {"market": "0xd5d9fc47718bd553592d126b1fa5e87183d27f3936975b0c04cc0f2dec1f1bb4", "price_changes": [{"asset_id": "33156410999665902694791064431724433042010245771106314074312009703157423879038", "price": "0.17", "size": "1056", "side": "BUY", "hash": "a1386e0e3e4cf49294b9c72532ac91720a7ec239", "best_bid": "0.2", "best_ask": "0.22"}, {"asset_id": "83247781037352156539108067944461291821683755894607244160607042790356561625563", "price": "0.83", "size": "1056", "side": "SELL", "hash": "949a992680f8afb5156adb4717adc6915c1fdcb4", "best_bid": "0.78", "best_ask": "0.8"}], "timestamp": "1769384022693", "event_type": "price_change"}}
{"_local_timestamp": "2026-01-25T23:33:42.789889+00:00", "data": {"market": "0xd5d9fc47718bd553592d126b1fa5e87183d27f3936975b0c04cc0f2dec1f1bb4", "price_changes": [{"asset_id": "33156410999665902694791064431724433042010245771106314074312009703157423879038", "price": "0.18", "size": "1155", "side": "BUY", "hash": "1e65a42e185209179095a5bd7806d12531bea143", "best_bid": "0.2", "best_ask": "0.22"}, {"asset_id": "83247781037352156539108067944461291821683755894607244160607042790356561625563", "price": "0.82", "size": "1155", "side": "SELL", "hash": "3887d0bf3640f4f30ddd3cfd2c89ff6e531731f7", "best_bid": "0.78", "best_ask": "0.8"}], "timestamp": "1769384022720", "event_type": "price_change"}}
{"_local_timestamp": "2026-01-25T23:33:42.802461+00:00", "data": {"market": "0xd5d9fc47718bd553592d126b1fa5e87183d27f3936975b0c04cc0f2dec1f1bb4", "price_changes": [{"asset_id": "33156410999665902694791064431724433042010245771106314074312009703157423879038", "price": "0.2", "size": "11377.1", "side": "BUY", "hash": "d9510955598ed3c0cbaabad2fb13d49999e0db66", "best_bid": "0.2", "best_ask": "0.22"}, {"asset_id": "83247781037352156539108067944461291821683755894607244160607042790356561625563", "price": "0.8", "size": "11377.1", "side": "SELL", "hash": "7a7f228bf61eb46dc4150c6718185216b6754850", "best_bid": "0.78", "best_ask": "0.8"}], "timestamp": "1769384022734", "event_type": "price_change"}}
{"_local_timestamp": "2026-01-25T23:33:42.803080+00:00", "data": {"market": "0x4e4f77e7dbf4cab666e9a1943674d7ae66348e862df03ea6f44b11eb95731928", "price_changes": [{"asset_id": "17371217118862125782438074585166210555214661810823929795910191856905580975576", "price": "0.77", "size": "16960.23", "side": "BUY", "hash": "13ef7afc3956aa413b0aab0bf08bf47276f1f96a", "best_bid": "0.78", "best_ask": "0.79"}, {"asset_id": "65139230827417363158752884968303867495725894165574887635816574090175320800482", "price": "0.23", "size": "16960.23", "side": "SELL", "hash": "03ea5b21e70623a3423bbc5d6bf28d138d1537a9", "best_bid": "0.21", "best_ask": "0.22"}], "timestamp": "1769384022734", "event_type": "price_change"}}
{"_local_timestamp": "2026-01-25T23:33:42.821530+00:00", "data": {"market": "0xd5d9fc47718bd553592d126b1fa5e87183d27f3936975b0c04cc0f2dec1f1bb4", "price_changes": [{"asset_id": "33156410999665902694791064431724433042010245771106314074312009703157423879038", "price": "0.19", "size": "13097.39", "side": "BUY", "hash": "e5411e59fbcbca40fb2d1a66067b8d38d46928b9", "best_bid": "0.2", "best_ask": "0.22"}, {"asset_id": "83247781037352156539108067944461291821683755894607244160607042790356561625563", "price": "0.81", "size": "13097.39", "side": "SELL", "hash": "f91646621da54749aedc3a75709f41bb98a255b4", "best_bid": "0.78", "best_ask": "0.8"}], "timestamp": "1769384022745", "event_type": "price_change"}}
{"_local_timestamp": "2026-01-25T23:33:42.857368+00:00", "data": {"market": "0xd5d9fc47718bd553592d126b1fa5e87183d27f3936975b0c04cc0f2dec1f1bb4", "price_changes": [{"asset_id": "33156410999665902694791064431724433042010245771106314074312009703157423879038", "price": "0.2", "size": "11367.1", "side": "BUY", "hash": "04f34d46e1e12f62f38bef61a65ca9856af0b925", "best_bid": "0.2", "best_ask": "0.22"}, {"asset_id": "83247781037352156539108067944461291821683755894607244160607042790356561625563", "price": "0.8", "size": "11367.1", "side": "SELL", "hash": "cb6003067bbeace4d1cf4c4f1f36fadd7e322d1e", "best_bid": "0.78", "best_ask": "0.8"}], "timestamp": "1769384022782", "event_type": "price_change"}}
{"_local_timestamp": "2026-01-25T23:33:49.109986+00:00", "data": {"market": "0xd5d9fc47718bd553592d126b1fa5e87183d27f3936975b0c04cc0f2dec1f1bb4", "price_changes": [{"asset_id": "33156410999665902694791064431724433042010245771106314074312009703157423879038", "price": "0.2", "size": "11167.1", "side": "BUY", "hash": "c252981ca1476b3dcc429eac3c51a60462556d3a", "best_bid": "0.2", "best_ask": "0.22"}, {"asset_id": "83247781037352156539108067944461291821683755894607244160607042790356561625563", "price": "0.8", "size": "11167.1", "side": "SELL", "hash": "4a18ba38d359a755ea34fe10d721761eb38cfab6", "best_bid": "0.78", "best_ask": "0.8"}], "timestamp": "1769384029010", "event_type": "price_change"}}
{"_local_timestamp": "2026-01-25T23:33:49.129418+00:00", "data": {"market": "0xd5d9fc47718bd553592d126b1fa5e87183d27f3936975b0c04cc0f2dec1f1bb4", "price_changes": [{"asset_id": "33156410999665902694791064431724433042010245771106314074312009703157423879038", "price": "0.2", "size": "11367.1", "side": "BUY", "hash": "89e5eb6cf72de3deb4e4e4953761dac5598f8070", "best_bid": "0.2", "best_ask": "0.22"}, {"asset_id": "83247781037352156539108067944461291821683755894607244160607042790356561625563", "price": "0.8", "size": "11367.1", "side": "SELL", "hash": "12082ad53bb0b441c129c660cbb17bf9e4964124", "best_bid": "0.78", "best_ask": "0.8"}], "timestamp": "1769384029043", "event_type": "price_change"}}
{"_local_timestamp": "2026-01-25T23:34:05.212354+00:00", "data": {"market": "0x4e4f77e7dbf4cab666e9a1943674d7ae66348e862df03ea6f44b11eb95731928", "price_changes": [{"asset_id": "65139230827417363158752884968303867495725894165574887635816574090175320800482", "price": "0.21", "size": "30784", "side": "BUY", "hash": "94a4e46dd47ecee4874aee2da4bb7c6eeceaba1a", "best_bid": "0.21", "best_ask": "0.22"}, {"asset_id": "17371217118862125782438074585166210555214661810823929795910191856905580975576", "price": "0.79", "size": "30784", "side": "SELL", "hash": "36ed481da961434a77f1f82a587a01c0081b0f0d", "best_bid": "0.78", "best_ask": "0.79"}], "timestamp": "1769384045066", "event_type": "price_change"}}
{"_local_timestamp": "2026-01-25T23:34:05.232647+00:00", "data": {"market": "0x4e4f77e7dbf4cab666e9a1943674d7ae66348e862df03ea6f44b11eb95731928", "price_changes": [{"asset_id": "65139230827417363158752884968303867495725894165574887635816574090175320800482", "price": "0.21", "size": "30984", "side": "BUY", "hash": "42ab1e1d0b1fdea89f2a2a4fe14c7d786c5d016e", "best_bid": "0.21", "best_ask": "0.22"}, {"asset_id": "17371217118862125782438074585166210555214661810823929795910191856905580975576", "price": "0.79", "size": "30984", "side": "SELL", "hash": "d788b5415a8faba28b42821f100496711edce695", "best_bid": "0.78", "best_ask": "0.79"}], "timestamp": "1769384045100", "event_type": "price_change"}}
{"_local_timestamp": "2026-01-25T23:34:05.254814+00:00", "data": {"market": "0x4e4f77e7dbf4cab666e9a1943674d7ae66348e862df03ea6f44b11eb95731928", "price_changes": [{"asset_id": "17371217118862125782438074585166210555214661810823929795910191856905580975576", "price": "0.76", "size": "3000", "side": "BUY", "hash": "10bab24e5fa141530b21a55c6adddff9d68edb7c", "best_bid": "0.78", "best_ask": "0.79"}, {"asset_id": "65139230827417363158752884968303867495725894165574887635816574090175320800482", "price": "0.24", "size": "3000", "side": "SELL", "hash": "acc0b924ab007a7ded40bad6b5f265e6afc8a23d", "best_bid": "0.21", "best_ask": "0.22"}], "timestamp": "1769384045128", "event_type": "price_change"}}
{"_local_timestamp": "2026-01-25T23:34:05.271037+00:00", "data": {"market": "0x4e4f77e7dbf4cab666e9a1943674d7ae66348e862df03ea6f44b11eb95731928", "price_changes": [{"asset_id": "17371217118862125782438074585166210555214661810823929795910191856905580975576", "price": "0.76", "size": "3200", "side": "BUY", "hash": "c63c4dfc10ea4674734f8edd2f21c79f880a748b", "best_bid": "0.78", "best_ask": "0.79"}, {"asset_id": "65139230827417363158752884968303867495725894165574887635816574090175320800482", "price": "0.24", "size": "3200", "side": "SELL", "hash": "930d352c6eadb32641892023fabf5dd2f29261bd", "best_bid": "0.21", "best_ask": "0.22"}], "timestamp": "1769384045161", "event_type": "price_change"}}
{"_local_timestamp": "2026-01-25T23:34:05.276700+00:00", "data": {"market": "0xd5d9fc47718bd553592d126b1fa5e87183d27f3936975b0c04cc0f2dec1f1bb4", "price_changes": [{"asset_id": "83247781037352156539108067944461291821683755894607244160607042790356561625563", "price": "0.77", "size": "41395.01", "side": "BUY", "hash": "ed54e94d9f8f03c3dcbfbc9b20d2a955249ba4c6", "best_bid": "0.78", "best_ask": "0.8"}, {"asset_id": "33156410999665902694791064431724433042010245771106314074312009703157423879038", "price": "0.23", "size": "41395.01", "side": "SELL", "hash": "3111531e8cd0aaf58e29321ce16b421469c41cc0", "best_bid": "0.2", "best_ask": "0.22"}], "timestamp": "1769384045187", "event_type": "price_change"}}
{"_local_timestamp": "2026-01-25T23:34:05.293287+00:00", "data": {"market": "0xd5d9fc47718bd553592d126b1fa5e87183d27f3936975b0c04cc0f2dec1f1bb4", "price_changes": [{"asset_id": "83247781037352156539108067944461291821683755894607244160607042790356561625563", "price": "0.77", "size": "41595.01", "side": "BUY", "hash": "fc31becebced30cf601b081acda6e330febe59b0", "best_bid": "0.78", "best_ask": "0.8"}, {"asset_id": "33156410999665902694791064431724433042010245771106314074312009703157423879038", "price": "0.23", "size": "41595.01", "side": "SELL", "hash": "96b815c74ba20c68e124d7e3fe16d992d17fbe60", "best_bid": "0.2", "best_ask": "0.22"}], "timestamp": "1769384045227", "event_type": "price_change"}}
{"_local_timestamp": "2026-01-25T23:34:05.908415+00:00", "data": {"market": "0xd5d9fc47718bd553592d126b1fa5e87183d27f3936975b0c04cc0f2dec1f1bb4", "price_changes": [{"asset_id": "33156410999665902694791064431724433042010245771106314074312009703157423879038", "price": "0.2", "size": "11167.1", "side": "BUY", "hash": "872fe7dc696c83526a6d191f4f1613d6499a22ba", "best_bid": "0.2", "best_ask": "0.22"}, {"asset_id": "83247781037352156539108067944461291821683755894607244160607042790356561625563", "price": "0.8", "size": "11167.1", "side": "SELL", "hash": "8653b7b6388b893b1ffc0652b935c0ad9d2cef6b", "best_bid": "0.78", "best_ask": "0.8"}], "timestamp": "1769384045835", "event_type": "price_change"}}
{"_local_timestamp": "2026-01-25T23:34:05.930512+00:00", "data": {"market": "0xd5d9fc47718bd553592d126b1fa5e87183d27f3936975b0c04cc0f2dec1f1bb4", "price_changes": [{"asset_id": "83247781037352156539108067944461291821683755894607244160607042790356561625563", "price": "0.77", "size": "41395.01", "side": "BUY", "hash": "86aecb529ae36ee782105208c9e4282df0ca5cea", "best_bid": "0.78", "best_ask": "0.8"}, {"asset_id": "33156410999665902694791064431724433042010245771106314074312009703157423879038", "price": "0.23", "size": "41395.01", "side": "SELL", "hash": "acbe0ece34972ff9222b67fe7fcad06d200ba526", "best_bid": "0.2", "best_ask": "0.22"}], "timestamp": "1769384045859", "event_type": "price_change"}}
{"_local_timestamp": "2026-01-25T23:34:31.516424+00:00", "data": {"market": "0x4e4f77e7dbf4cab666e9a1943674d7ae66348e862df03ea6f44b11eb95731928", "price_changes": [{"asset_id": "17371217118862125782438074585166210555214661810823929795910191856905580975576", "price": "0.76", "size": "3600", "side": "BUY", "hash": "34010f5b19de0917049b537710ea12421daed8c3", "best_bid": "0.78", "best_ask": "0.79"}, {"asset_id": "65139230827417363158752884968303867495725894165574887635816574090175320800482", "price": "0.24", "size": "3600", "side": "SELL", "hash": "dab7735fb5804f0183007b155d84f5b429af0e0a", "best_bid": "0.21", "best_ask": "0.22"}], "timestamp": "1769384071280", "event_type": "price_change"}}
{"_local_timestamp": "2026-01-25T23:34:50.192317+00:00", "data": {"market": "0x4e4f77e7dbf4cab666e9a1943674d7ae66348e862df03ea6f44b11eb95731928", "price_changes": [{"asset_id": "65139230827417363158752884968303867495725894165574887635816574090175320800482", "price": "0.21", "size": "30784", "side": "BUY", "hash": "d71dc5952e436a74894a861dbba015c6ed4cb823", "best_bid": "0.21", "best_ask": "0.22"}, {"asset_id": "17371217118862125782438074585166210555214661810823929795910191856905580975576", "price": "0.79", "size": "30784", "side": "SELL", "hash": "f0c4c204c6354356f65de173962ffd32906690ec", "best_bid": "0.78", "best_ask": "0.79"}], "timestamp": "1769384090065", "event_type": "price_change"}}
{"_local_timestamp": "2026-01-25T23:34:50.220934+00:00", "data": {"market": "0x4e4f77e7dbf4cab666e9a1943674d7ae66348e862df03ea6f44b11eb95731928", "price_changes": [{"asset_id": "65139230827417363158752884968303867495725894165574887635816574090175320800482", "price": "0.21", "size": "30984", "side": "BUY", "hash": "6acae961d0a13fc8ed50cc99672d1bbd3471de4c", "best_bid": "0.21", "best_ask": "0.22"}, {"asset_id": "17371217118862125782438074585166210555214661810823929795910191856905580975576", "price": "0.79", "size": "30984", "side": "SELL", "hash": "aab2dc66ce8c2c55f47d76c131dcd7795e6dace3", "best_bid": "0.78", "best_ask": "0.79"}], "timestamp": "1769384090099", "event_type": "price_change"}}
{"_local_timestamp": "2026-01-25T23:34:50.246456+00:00", "data": {"market": "0x4e4f77e7dbf4cab666e9a1943674d7ae66348e862df03ea6f44b11eb95731928", "price_changes": [{"asset_id": "17371217118862125782438074585166210555214661810823929795910191856905580975576", "price": "0.76", "size": "3400", "side": "BUY", "hash": "7729c57442367b195c9b8d1a92676a39ef91b50c", "best_bid": "0.78", "best_ask": "0.79"}, {"asset_id": "65139230827417363158752884968303867495725894165574887635816574090175320800482", "price": "0.24", "size": "3400", "side": "SELL", "hash": "1e9902c15aaa31e47130dd1fcd8b8e02bfb4ed60", "best_bid": "0.21", "best_ask": "0.22"}], "timestamp": "1769384090125", "event_type": "price_change"}}
{"_local_timestamp": "2026-01-25T23:34:50.283676+00:00", "data": {"market": "0x4e4f77e7dbf4cab666e9a1943674d7ae66348e862df03ea6f44b11eb95731928", "price_changes": [{"asset_id": "17371217118862125782438074585166210555214661810823929795910191856905580975576", "price": "0.76", "size": "3600", "side": "BUY", "hash": "bf1d0fed8acab63a081d84090c16e31033510be9", "best_bid": "0.78", "best_ask": "0.79"}, {"asset_id": "65139230827417363158752884968303867495725894165574887635816574090175320800482", "price": "0.24", "size": "3600", "side": "SELL", "hash": "b0d1c34a6046f12b2921bd94fdbc933fef4d6dcb", "best_bid": "0.21", "best_ask": "0.22"}], "timestamp": "1769384090159", "event_type": "price_change"}}
{"_local_timestamp": "2026-01-25T23:35:05.505924+00:00", "data": {"market": "0xd5d9fc47718bd553592d126b1fa5e87183d27f3936975b0c04cc0f2dec1f1bb4", "price_changes": [{"asset_id": "83247781037352156539108067944461291821683755894607244160607042790356561625563", "price": "0.77", "size": "41595.01", "side": "BUY", "hash": "0d46bb03b6c7709a21cdcd13342d6da0e7bd4c6d", "best_bid": "0.78", "best_ask": "0.8"}, {"asset_id": "33156410999665902694791064431724433042010245771106314074312009703157423879038", "price": "0.23", "size": "41595.01", "side": "SELL", "hash": "84c2e612f759f3111f3885eec42c3bd5d291db64", "best_bid": "0.2", "best_ask": "0.22"}], "timestamp": "1769384105416", "event_type": "price_change"}}
{"_local_timestamp": "2026-01-25T23:35:05.525657+00:00", "data": {"market": "0xd5d9fc47718bd553592d126b1fa5e87183d27f3936975b0c04cc0f2dec1f1bb4", "price_changes": [{"asset_id": "33156410999665902694791064431724433042010245771106314074312009703157423879038", "price": "0.2", "size": "11367.1", "side": "BUY", "hash": "a3ba6387e6018c10421206b830b85b3c8db105d0", "best_bid": "0.2", "best_ask": "0.22"}, {"asset_id": "83247781037352156539108067944461291821683755894607244160607042790356561625563", "price": "0.8", "size": "11367.1", "side": "SELL", "hash": "a0fabe57823e68dba55289d992fb6ed16d257801", "best_bid": "0.78", "best_ask": "0.8"}], "timestamp": "1769384105450", "event_type": "price_change"}}
{"_local_timestamp": "2026-01-25T23:35:35.208526+00:00", "data": {"market": "0x4e4f77e7dbf4cab666e9a1943674d7ae66348e862df03ea6f44b11eb95731928", "price_changes": [{"asset_id": "65139230827417363158752884968303867495725894165574887635816574090175320800482", "price": "0.21", "size": "30784", "side": "BUY", "hash": "f4822859fa5e025b6bff7e39ca4878ea448efb0b", "best_bid": "0.21", "best_ask": "0.22"}, {"asset_id": "17371217118862125782438074585166210555214661810823929795910191856905580975576", "price": "0.79", "size": "30784", "side": "SELL", "hash": "a71052dcfbc905f3f939b9f51e06a70d31a5b82d", "best_bid": "0.78", "best_ask": "0.79"}], "timestamp": "1769384135118", "event_type": "price_change"}}
{"_local_timestamp": "2026-01-25T23:35:35.222372+00:00", "data": {"market": "0x4e4f77e7dbf4cab666e9a1943674d7ae66348e862df03ea6f44b11eb95731928", "price_changes": [{"asset_id": "65139230827417363158752884968303867495725894165574887635816574090175320800482", "price": "0.21", "size": "30984", "side": "BUY", "hash": "407d16bc046d0403c68f825c46e3f337b0cedf48", "best_bid": "0.21", "best_ask": "0.22"}, {"asset_id": "17371217118862125782438074585166210555214661810823929795910191856905580975576", "price": "0.79", "size": "30984", "side": "SELL", "hash": "063bd01ed287c9163d4600e260b328a7a99d5c8f", "best_bid": "0.78", "best_ask": "0.79"}], "timestamp": "1769384135152", "event_type": "price_change"}}
{"_local_timestamp": "2026-01-25T23:35:35.251983+00:00", "data": {"market": "0x4e4f77e7dbf4cab666e9a1943674d7ae66348e862df03ea6f44b11eb95731928", "price_changes": [{"asset_id": "17371217118862125782438074585166210555214661810823929795910191856905580975576", "price": "0.76", "size": "3400", "side": "BUY", "hash": "f17bb0a27a669cd2c5f023c53d4bb10a62451c04", "best_bid": "0.78", "best_ask": "0.79"}, {"asset_id": "65139230827417363158752884968303867495725894165574887635816574090175320800482", "price": "0.24", "size": "3400", "side": "SELL", "hash": "a92a6af83c8a6b7df43da37e33438c52698cf6d3", "best_bid": "0.21", "best_ask": "0.22"}], "timestamp": "1769384135177", "event_type": "price_change"}}
{"_local_timestamp": "2026-01-25T23:35:35.298070+00:00", "data": {"market": "0x4e4f77e7dbf4cab666e9a1943674d7ae66348e862df03ea6f44b11eb95731928", "price_changes": [{"asset_id": "17371217118862125782438074585166210555214661810823929795910191856905580975576", "price": "0.76", "size": "3600", "side": "BUY", "hash": "09bcb641768cf5817f97a464b8dc00eec508ebca", "best_bid": "0.78", "best_ask": "0.79"}, {"asset_id": "65139230827417363158752884968303867495725894165574887635816574090175320800482", "price": "0.24", "size": "3600", "side": "SELL", "hash": "e4657fb28e5dbbf0168e137f9bf3101a6aac925f", "best_bid": "0.21", "best_ask": "0.22"}], "timestamp": "1769384135232", "event_type": "price_change"}}
{"_local_timestamp": "2026-01-25T23:35:50.497050+00:00", "data": {"market": "0xd5d9fc47718bd553592d126b1fa5e87183d27f3936975b0c04cc0f2dec1f1bb4", "price_changes": [{"asset_id": "83247781037352156539108067944461291821683755894607244160607042790356561625563", "price": "0.77", "size": "41395.01", "side": "BUY", "hash": "0411d19d9905e2fe9e5713ef3ddd295363c75bf7", "best_bid": "0.78", "best_ask": "0.8"}, {"asset_id": "33156410999665902694791064431724433042010245771106314074312009703157423879038", "price": "0.23", "size": "41395.01", "side": "SELL", "hash": "e433def1eca821402627dd813506fa7f3ee7d926", "best_bid": "0.2", "best_ask": "0.22"}], "timestamp": "1769384150417", "event_type": "price_change"}}
{"_local_timestamp": "2026-01-25T23:35:50.597624+00:00", "data": {"market": "0xd5d9fc47718bd553592d126b1fa5e87183d27f3936975b0c04cc0f2dec1f1bb4", "price_changes": [{"asset_id": "83247781037352156539108067944461291821683755894607244160607042790356561625563", "price": "0.77", "size": "41595.01", "side": "BUY", "hash": "fab894ad3816bebc22f780f31c05a011bfe7708f", "best_bid": "0.78", "best_ask": "0.8"}, {"asset_id": "33156410999665902694791064431724433042010245771106314074312009703157423879038", "price": "0.23", "size": "41595.01", "side": "SELL", "hash": "ec5bda8c8bf0dda26db8f9e3890cf189d82e551f", "best_bid": "0.2", "best_ask": "0.22"}], "timestamp": "1769384150488", "event_type": "price_change"}}
{"_local_timestamp": "2026-01-25T23:35:50.626334+00:00", "data": {"market": "0xd5d9fc47718bd553592d126b1fa5e87183d27f3936975b0c04cc0f2dec1f1bb4", "price_changes": [{"asset_id": "33156410999665902694791064431724433042010245771106314074312009703157423879038", "price": "0.2", "size": "11167.1", "side": "BUY", "hash": "0773594ae54cd484528841c415be15dcf00e5e63", "best_bid": "0.2", "best_ask": "0.22"}, {"asset_id": "83247781037352156539108067944461291821683755894607244160607042790356561625563", "price": "0.8", "size": "11167.1", "side": "SELL", "hash": "62a9acaabcb7cac94172c1292cc0a3dbaf79592a", "best_bid": "0.78", "best_ask": "0.8"}], "timestamp": "1769384150512", "event_type": "price_change"}}
{"_local_timestamp": "2026-01-25T23:35:50.632988+00:00", "data": {"market": "0xd5d9fc47718bd553592d126b1fa5e87183d27f3936975b0c04cc0f2dec1f1bb4", "price_changes": [{"asset_id": "33156410999665902694791064431724433042010245771106314074312009703157423879038", "price": "0.2", "size": "11367.1", "side": "BUY", "hash": "6ce7fc794a18c8564de04b9d714240cb451e332e", "best_bid": "0.2", "best_ask": "0.22"}, {"asset_id": "83247781037352156539108067944461291821683755894607244160607042790356561625563", "price": "0.8", "size": "11367.1", "side": "SELL", "hash": "3dc3bead877c468e2a3906b3818304505d5bc099", "best_bid": "0.78", "best_ask": "0.8"}], "timestamp": "1769384150542", "event_type": "price_change"}}
{"_local_timestamp": "2026-01-25T23:35:50.927472+00:00", "data": {"market": "0x4e4f77e7dbf4cab666e9a1943674d7ae66348e862df03ea6f44b11eb95731928", "price_changes": [{"asset_id": "17371217118862125782438074585166210555214661810823929795910191856905580975576", "price": "0.77", "size": "18015.43", "side": "BUY", "hash": "16cad1733c33f1fd8410a3267f4de8613ba4b30a", "best_bid": "0.78", "best_ask": "0.79"}, {"asset_id": "65139230827417363158752884968303867495725894165574887635816574090175320800482", "price": "0.23", "size": "18015.43", "side": "SELL", "hash": "54078977cba7822b036a12fbce71dba65ecd07fe", "best_bid": "0.21", "best_ask": "0.22"}], "timestamp": "1769384150861", "event_type": "price_change"}}
{"_local_timestamp": "2026-01-25T23:35:50.975418+00:00", "data": {"market": "0xd5d9fc47718bd553592d126b1fa5e87183d27f3936975b0c04cc0f2dec1f1bb4", "price_changes": [{"asset_id": "33156410999665902694791064431724433042010245771106314074312009703157423879038", "price": "0.2", "size": "12422.3", "side": "BUY", "hash": "15ecb10439fb1e6b85046c0d4af7b011200308c9", "best_bid": "0.2", "best_ask": "0.22"}, {"asset_id": "83247781037352156539108067944461291821683755894607244160607042790356561625563", "price": "0.8", "size": "12422.3", "side": "SELL", "hash": "6fb84ee09dbfd651f78f14097bbf19203b599e51", "best_bid": "0.78", "best_ask": "0.8"}], "timestamp": "1769384150903", "event_type": "price_change"}}
{"_local_timestamp": "2026-01-25T23:35:51.418426+00:00", "data": {"market": "0xd5d9fc47718bd553592d126b1fa5e87183d27f3936975b0c04cc0f2dec1f1bb4", "price_changes": [{"asset_id": "33156410999665902694791064431724433042010245771106314074312009703157423879038", "price": "0.2", "size": "11367.1", "side": "BUY", "hash": "19dca75b38ddd04c101bf95f3018ca22efe61a4c", "best_bid": "0.2", "best_ask": "0.22"}, {"asset_id": "83247781037352156539108067944461291821683755894607244160607042790356561625563", "price": "0.8", "size": "11367.1", "side": "SELL", "hash": "a9ca0e96ad2cfa8a55d702056532e96b09668a40", "best_bid": "0.78", "best_ask": "0.8"}], "timestamp": "1769384151335", "event_type": "price_change"}}
{"_local_timestamp": "2026-01-25T23:35:51.439885+00:00", "data": {"market": "0x4e4f77e7dbf4cab666e9a1943674d7ae66348e862df03ea6f44b11eb95731928", "price_changes": [{"asset_id": "17371217118862125782438074585166210555214661810823929795910191856905580975576", "price": "0.77", "size": "16960.23", "side": "BUY", "hash": "7ed202ed90233450aea3fb4de967e158c71cb1e7", "best_bid": "0.78", "best_ask": "0.79"}, {"asset_id": "65139230827417363158752884968303867495725894165574887635816574090175320800482", "price": "0.23", "size": "16960.23", "side": "SELL", "hash": "a300304954f46cec958470abb7e167bf693d1b17", "best_bid": "0.21", "best_ask": "0.22"}], "timestamp": "1769384151335", "event_type": "price_change"}}
{"_local_timestamp": "2026-01-25T23:35:51.621464+00:00", "data": {"market": "0x4e4f77e7dbf4cab666e9a1943674d7ae66348e862df03ea6f44b11eb95731928", "price_changes": [{"asset_id": "17371217118862125782438074585166210555214661810823929795910191856905580975576", "price": "0.77", "size": "18015.43", "side": "BUY", "hash": "bc405a46d95f808a34ea1a07d801d0a2e860fd4e", "best_bid": "0.78", "best_ask": "0.79"}, {"asset_id": "65139230827417363158752884968303867495725894165574887635816574090175320800482", "price": "0.23", "size": "18015.43", "side": "SELL", "hash": "a5c6819810b78b8085d7db0acf7782f31e8715bc", "best_bid": "0.21", "best_ask": "0.22"}], "timestamp": "1769384151553", "event_type": "price_change"}}
{"_local_timestamp": "2026-01-25T23:35:51.678409+00:00", "data": {"market": "0xd5d9fc47718bd553592d126b1fa5e87183d27f3936975b0c04cc0f2dec1f1bb4", "price_changes": [{"asset_id": "33156410999665902694791064431724433042010245771106314074312009703157423879038", "price": "0.2", "size": "12422.3", "side": "BUY", "hash": "e24891cfd3ff9726d84decad5940e26f5ce9cfd0", "best_bid": "0.2", "best_ask": "0.22"}, {"asset_id": "83247781037352156539108067944461291821683755894607244160607042790356561625563", "price": "0.8", "size": "12422.3", "side": "SELL", "hash": "1e014471cf8a7981b80a2ca74db9f886dc3c9a4a", "best_bid": "0.78", "best_ask": "0.8"}], "timestamp": "1769384151614", "event_type": "price_change"}}
{"_local_timestamp": "2026-01-25T23:35:52.016822+00:00", "data": {"market": "0xd5d9fc47718bd553592d126b1fa5e87183d27f3936975b0c04cc0f2dec1f1bb4", "price_changes": [{"asset_id": "33156410999665902694791064431724433042010245771106314074312009703157423879038", "price": "0.2", "size": "11367.1", "side": "BUY", "hash": "8154f7bbfc93ffd19aa2d22bc9f2b45121442f4f", "best_bid": "0.2", "best_ask": "0.22"}, {"asset_id": "83247781037352156539108067944461291821683755894607244160607042790356561625563", "price": "0.8", "size": "11367.1", "side": "SELL", "hash": "cf1eaf0f86d07056695c6eaa93aa95dbfdc03815", "best_bid": "0.78", "best_ask": "0.8"}], "timestamp": "1769384151944", "event_type": "price_change"}}
{"_local_timestamp": "2026-01-25T23:35:52.017217+00:00", "data": {"market": "0x4e4f77e7dbf4cab666e9a1943674d7ae66348e862df03ea6f44b11eb95731928", "price_changes": [{"asset_id": "17371217118862125782438074585166210555214661810823929795910191856905580975576", "price": "0.77", "size": "16960.23", "side": "BUY", "hash": "99c372240da917c1aec1103fc76444649b72420f", "best_bid": "0.78", "best_ask": "0.79"}, {"asset_id": "65139230827417363158752884968303867495725894165574887635816574090175320800482", "price": "0.23", "size": "16960.23", "side": "SELL", "hash": "f36767fd93f1ac452c71b0b27825ab4775d3e3f3", "best_bid": "0.21", "best_ask": "0.22"}], "timestamp": "1769384151944", "event_type": "price_change"}}
{"_local_timestamp": "2026-01-25T23:35:58.203892+00:00", "data": {"market": "0x4e4f77e7dbf4cab666e9a1943674d7ae66348e862df03ea6f44b11eb95731928", "price_changes": [{"asset_id": "17371217118862125782438074585166210555214661810823929795910191856905580975576", "price": "0.21", "size": "0", "side": "BUY", "hash": "e9bee451162018ab38dbe7d7775470a427618009", "best_bid": "0.78", "best_ask": "0.79"}, {"asset_id": "65139230827417363158752884968303867495725894165574887635816574090175320800482", "price": "0.79", "size": "0", "side": "SELL", "hash": "b07ef348f4ea45152bfd4d7501a12dcc7d1e6ebe", "best_bid": "0.21", "best_ask": "0.22"}], "timestamp": "1769384158074", "event_type": "price_change"}}
{"_local_timestamp": "2026-01-25T23:36:00.822322+00:00", "data": {"market": "0x4e4f77e7dbf4cab666e9a1943674d7ae66348e862df03ea6f44b11eb95731928", "price_changes": [{"asset_id": "17371217118862125782438074585166210555214661810823929795910191856905580975576", "price": "0.76", "size": "4000", "side": "BUY", "hash": "e64ff9e9f0ec44a53eda93115ea8709800ab2602", "best_bid": "0.78", "best_ask": "0.79"}, {"asset_id": "65139230827417363158752884968303867495725894165574887635816574090175320800482", "price": "0.24", "size": "4000", "side": "SELL", "hash": "845941acfc74dca4c9ff4c18a1171762db6dcf88", "best_bid": "0.21", "best_ask": "0.22"}], "timestamp": "1769384160749", "event_type": "price_change"}}
{"_local_timestamp": "2026-01-25T23:36:03.945375+00:00", "data": {"market": "0x4e4f77e7dbf4cab666e9a1943674d7ae66348e862df03ea6f44b11eb95731928", "price_changes": [{"asset_id": "17371217118862125782438074585166210555214661810823929795910191856905580975576", "price": "0.22", "size": "1908", "side": "BUY", "hash": "5eeb56d6276424ac547e4ed14e4d818b07cca6d5", "best_bid": "0.78", "best_ask": "0.79"}, {"asset_id": "65139230827417363158752884968303867495725894165574887635816574090175320800482", "price": "0.78", "size": "1908", "side": "SELL", "hash": "6d7b9814606405e438c53a47848deb7d1d152218", "best_bid": "0.21", "best_ask": "0.22"}], "timestamp": "1769384163864", "event_type": "price_change"}}
{"_local_timestamp": "2026-01-25T23:36:03.968895+00:00", "data": {"market": "0x4e4f77e7dbf4cab666e9a1943674d7ae66348e862df03ea6f44b11eb95731928", "price_changes": [{"asset_id": "17371217118862125782438074585166210555214661810823929795910191856905580975576", "price": "0.77", "size": "16966.45", "side": "BUY", "hash": "56784873e233007d9d07bb288b1e36b5a0e07eb6", "best_bid": "0.78", "best_ask": "0.79"}, {"asset_id": "65139230827417363158752884968303867495725894165574887635816574090175320800482", "price": "0.23", "size": "16966.45", "side": "SELL", "hash": "da7e3cfbd2e1c594e3ad802f53c9223e6664a31b", "best_bid": "0.21", "best_ask": "0.22"}], "timestamp": "1769384163900", "event_type": "price_change"}}
{"_local_timestamp": "2026-01-25T23:36:03.981273+00:00", "data": {"market": "0xd5d9fc47718bd553592d126b1fa5e87183d27f3936975b0c04cc0f2dec1f1bb4", "price_changes": [{"asset_id": "33156410999665902694791064431724433042010245771106314074312009703157423879038", "price": "0.2", "size": "11373.32", "side": "BUY", "hash": "5494f8355784d0f129438a999b5b6020676c6c0b", "best_bid": "0.2", "best_ask": "0.22"}, {"asset_id": "83247781037352156539108067944461291821683755894607244160607042790356561625563", "price": "0.8", "size": "11373.32", "side": "SELL", "hash": "25c1cde3fa801c54cb280aa348ee4750474f4e14", "best_bid": "0.78", "best_ask": "0.8"}], "timestamp": "1769384163915", "event_type": "price_change"}}
{"_local_timestamp": "2026-01-25T23:36:04.181572+00:00", "data": {"market": "0xd5d9fc47718bd553592d126b1fa5e87183d27f3936975b0c04cc0f2dec1f1bb4", "price_changes": [{"asset_id": "33156410999665902694791064431724433042010245771106314074312009703157423879038", "price": "0.2", "size": "11367.1", "side": "BUY", "hash": "2cd145e43cfd12d1e24c0b1268727f33cdf1e729", "best_bid": "0.2", "best_ask": "0.22"}, {"asset_id": "83247781037352156539108067944461291821683755894607244160607042790356561625563", "price": "0.8", "size": "11367.1", "side": "SELL", "hash": "380977548b8f6572e065c9c27cabb4f42ec5a4ce", "best_bid": "0.78", "best_ask": "0.8"}], "timestamp": "1769384164111", "event_type": "price_change"}}
{"_local_timestamp": "2026-01-25T23:36:04.182570+00:00", "data": {"market": "0x4e4f77e7dbf4cab666e9a1943674d7ae66348e862df03ea6f44b11eb95731928", "price_changes": [{"asset_id": "17371217118862125782438074585166210555214661810823929795910191856905580975576", "price": "0.77", "size": "16960.23", "side": "BUY", "hash": "8367976573022c1ba7ce523930d375bfdacf09ec", "best_bid": "0.78", "best_ask": "0.79"}, {"asset_id": "65139230827417363158752884968303867495725894165574887635816574090175320800482", "price": "0.23", "size": "16960.23", "side": "SELL", "hash": "2ee8e87b3fa6f0a4081701c35b53d290079a8589", "best_bid": "0.21", "best_ask": "0.22"}], "timestamp": "1769384164111", "event_type": "price_change"}}
{"_local_timestamp": "2026-01-25T23:36:04.265041+00:00", "data": {"market": "0xd5d9fc47718bd553592d126b1fa5e87183d27f3936975b0c04cc0f2dec1f1bb4", "price_changes": [{"asset_id": "33156410999665902694791064431724433042010245771106314074312009703157423879038", "price": "0.2", "size": "11373.32", "side": "BUY", "hash": "2e1ac5217145d5edfc3625dcf29022921c4a2521", "best_bid": "0.2", "best_ask": "0.22"}, {"asset_id": "83247781037352156539108067944461291821683755894607244160607042790356561625563", "price": "0.8", "size": "11373.32", "side": "SELL", "hash": "fb885705dc0af133d0b4adec668379538cda2114", "best_bid": "0.78", "best_ask": "0.8"}], "timestamp": "1769384164191", "event_type": "price_change"}}
{"_local_timestamp": "2026-01-25T23:36:04.273396+00:00", "data": {"market": "0x4e4f77e7dbf4cab666e9a1943674d7ae66348e862df03ea6f44b11eb95731928", "price_changes": [{"asset_id": "17371217118862125782438074585166210555214661810823929795910191856905580975576", "price": "0.77", "size": "16966.45", "side": "BUY", "hash": "659739c1b3f534ce5a5fc008e8b8a0a17e79b52c", "best_bid": "0.78", "best_ask": "0.79"}, {"asset_id": "65139230827417363158752884968303867495725894165574887635816574090175320800482", "price": "0.23", "size": "16966.45", "side": "SELL", "hash": "04f9f71b921d44123eba9562b167ea01d7f49e7c", "best_bid": "0.21", "best_ask": "0.22"}], "timestamp": "1769384164200", "event_type": "price_change"}}
{"_local_timestamp": "2026-01-25T23:36:04.437145+00:00", "data": {"market": "0xd5d9fc47718bd553592d126b1fa5e87183d27f3936975b0c04cc0f2dec1f1bb4", "price_changes": [{"asset_id": "33156410999665902694791064431724433042010245771106314074312009703157423879038", "price": "0.2", "size": "11367.1", "side": "BUY", "hash": "d5134d124af7e608ee9f4aed5f92bb2dd223fc4b", "best_bid": "0.2", "best_ask": "0.22"}, {"asset_id": "83247781037352156539108067944461291821683755894607244160607042790356561625563", "price": "0.8", "size": "11367.1", "side": "SELL", "hash": "9ae87f6dfe04d47bbfec20a729b68c2d1c5570f9", "best_bid": "0.78", "best_ask": "0.8"}], "timestamp": "1769384164367", "event_type": "price_change"}}
{"_local_timestamp": "2026-01-25T23:36:04.437592+00:00", "data": {"market": "0x4e4f77e7dbf4cab666e9a1943674d7ae66348e862df03ea6f44b11eb95731928", "price_changes": [{"asset_id": "17371217118862125782438074585166210555214661810823929795910191856905580975576", "price": "0.77", "size": "16960.23", "side": "BUY", "hash": "1b8292210c5dba878c62e52c810262cece71f112", "best_bid": "0.78", "best_ask": "0.79"}, {"asset_id": "65139230827417363158752884968303867495725894165574887635816574090175320800482", "price": "0.23", "size": "16960.23", "side": "SELL", "hash": "010bf4d7173b568bb3200324a09aef3d9423e160", "best_bid": "0.21", "best_ask": "0.22"}], "timestamp": "1769384164367", "event_type": "price_change"}}
{"_local_timestamp": "2026-01-25T23:36:20.188326+00:00", "data": {"market": "0x4e4f77e7dbf4cab666e9a1943674d7ae66348e862df03ea6f44b11eb95731928", "price_changes": [{"asset_id": "65139230827417363158752884968303867495725894165574887635816574090175320800482", "price": "0.21", "size": "30784", "side": "BUY", "hash": "580a58a3ab0b9a497a1b04943c9dbb91b858a334", "best_bid": "0.21", "best_ask": "0.22"}, {"asset_id": "17371217118862125782438074585166210555214661810823929795910191856905580975576", "price": "0.79", "size": "30784", "side": "SELL", "hash": "6c469e03c4a7e800f81f5f73f11776d98e51a71d", "best_bid": "0.78", "best_ask": "0.79"}], "timestamp": "1769384180116", "event_type": "price_change"}}
{"_local_timestamp": "2026-01-25T23:36:20.219749+00:00", "data": {"market": "0x4e4f77e7dbf4cab666e9a1943674d7ae66348e862df03ea6f44b11eb95731928", "price_changes": [{"asset_id": "65139230827417363158752884968303867495725894165574887635816574090175320800482", "price": "0.21", "size": "30984", "side": "BUY", "hash": "2be6dab1aeb3f8ce98e68c8e53aabe3762394b62", "best_bid": "0.21", "best_ask": "0.22"}, {"asset_id": "17371217118862125782438074585166210555214661810823929795910191856905580975576", "price": "0.79", "size": "30984", "side": "SELL", "hash": "0ae147b0c1184c4daee5b44272c9b01b6f472932", "best_bid": "0.78", "best_ask": "0.79"}], "timestamp": "1769384180149", "event_type": "price_change"}}
{"_local_timestamp": "2026-01-25T23:36:20.222394+00:00", "data": {"market": "0xd5d9fc47718bd553592d126b1fa5e87183d27f3936975b0c04cc0f2dec1f1bb4", "price_changes": [{"asset_id": "33156410999665902694791064431724433042010245771106314074312009703157423879038", "price": "0.2", "size": "11373.32", "side": "BUY", "hash": "55d03967e6fe9fa1987e504509116136e1ac275a", "best_bid": "0.2", "best_ask": "0.22"}, {"asset_id": "83247781037352156539108067944461291821683755894607244160607042790356561625563", "price": "0.8", "size": "11373.32", "side": "SELL", "hash": "ee8d1dbda5fe7d175320d58c1b8e3a3d853e7fb5", "best_bid": "0.78", "best_ask": "0.8"}], "timestamp": "1769384180151", "event_type": "price_change"}}
{"_local_timestamp": "2026-01-25T23:36:20.231507+00:00", "data": {"market": "0x4e4f77e7dbf4cab666e9a1943674d7ae66348e862df03ea6f44b11eb95731928", "price_changes": [{"asset_id": "17371217118862125782438074585166210555214661810823929795910191856905580975576", "price": "0.77", "size": "16966.45", "side": "BUY", "hash": "65fc4102fe4ce2213b8647f93196c19d3cdb18a8", "best_bid": "0.78", "best_ask": "0.79"}, {"asset_id": "65139230827417363158752884968303867495725894165574887635816574090175320800482", "price": "0.23", "size": "16966.45", "side": "SELL", "hash": "d46b6e2974a50b6f751c7bba38c1df5bbad48d4b", "best_bid": "0.21", "best_ask": "0.22"}], "timestamp": "1769384180159", "event_type": "price_change"}}
{"_local_timestamp": "2026-01-25T23:36:20.247585+00:00", "data": {"market": "0x4e4f77e7dbf4cab666e9a1943674d7ae66348e862df03ea6f44b11eb95731928", "price_changes": [{"asset_id": "17371217118862125782438074585166210555214661810823929795910191856905580975576", "price": "0.76", "size": "3800", "side": "BUY", "hash": "4764f6ba4e76b207bcf896a8f714eab44417fcd5", "best_bid": "0.78", "best_ask": "0.79"}, {"asset_id": "65139230827417363158752884968303867495725894165574887635816574090175320800482", "price": "0.24", "size": "3800", "side": "SELL", "hash": "51afbccd9ffe18880d6aab896a4ff9efb3966b07", "best_bid": "0.21", "best_ask": "0.22"}], "timestamp": "1769384180174", "event_type": "price_change"}}
{"_local_timestamp": "2026-01-25T23:36:20.277962+00:00", "data": {"market": "0x4e4f77e7dbf4cab666e9a1943674d7ae66348e862df03ea6f44b11eb95731928", "price_changes": [{"asset_id": "17371217118862125782438074585166210555214661810823929795910191856905580975576", "price": "0.76", "size": "4000", "side": "BUY", "hash": "56b347e559e5c7b69faf6b5f6c269aac42b8e36c", "best_bid": "0.78", "best_ask": "0.79"}, {"asset_id": "65139230827417363158752884968303867495725894165574887635816574090175320800482", "price": "0.24", "size": "4000", "side": "SELL", "hash": "c3b5689a7566996d3be53df3482028c3ac49e7bf", "best_bid": "0.21", "best_ask": "0.22"}], "timestamp": "1769384180205", "event_type": "price_change"}}
{"_local_timestamp": "2026-01-25T23:36:20.423428+00:00", "data": {"market": "0xd5d9fc47718bd553592d126b1fa5e87183d27f3936975b0c04cc0f2dec1f1bb4", "price_changes": [{"asset_id": "33156410999665902694791064431724433042010245771106314074312009703157423879038", "price": "0.2", "size": "11367.1", "side": "BUY", "hash": "5c23bce9e339b625be95939d599bf20e82657ce6", "best_bid": "0.2", "best_ask": "0.22"}, {"asset_id": "83247781037352156539108067944461291821683755894607244160607042790356561625563", "price": "0.8", "size": "11367.1", "side": "SELL", "hash": "a3d1f0bef0410fd62af358c81a701725fb192155", "best_bid": "0.78", "best_ask": "0.8"}], "timestamp": "1769384180355", "event_type": "price_change"}}
{"_local_timestamp": "2026-01-25T23:36:20.431340+00:00", "data": {"market": "0x4e4f77e7dbf4cab666e9a1943674d7ae66348e862df03ea6f44b11eb95731928", "price_changes": [{"asset_id": "17371217118862125782438074585166210555214661810823929795910191856905580975576", "price": "0.77", "size": "16960.23", "side": "BUY", "hash": "c107494b5e1cfabc0ad3e359099ba78d1e4f1389", "best_bid": "0.78", "best_ask": "0.79"}, {"asset_id": "65139230827417363158752884968303867495725894165574887635816574090175320800482", "price": "0.23", "size": "16960.23", "side": "SELL", "hash": "1155ebcfa868b1696902c151287d3e61911edcc8", "best_bid": "0.21", "best_ask": "0.22"}], "timestamp": "1769384180355", "event_type": "price_change"}}
{"_local_timestamp": "2026-01-25T23:36:20.479563+00:00", "data": {"market": "0xd5d9fc47718bd553592d126b1fa5e87183d27f3936975b0c04cc0f2dec1f1bb4", "price_changes": [{"asset_id": "33156410999665902694791064431724433042010245771106314074312009703157423879038", "price": "0.2", "size": "11373.32", "side": "BUY", "hash": "5214db032e0bb2766a677bbb3300b5126b4b9b03", "best_bid": "0.2", "best_ask": "0.22"}, {"asset_id": "83247781037352156539108067944461291821683755894607244160607042790356561625563", "price": "0.8", "size": "11373.32", "side": "SELL", "hash": "a13e4eddf28c997ba28418523f59a880eb0daa42", "best_bid": "0.78", "best_ask": "0.8"}], "timestamp": "1769384180409", "event_type": "price_change"}}
{"_local_timestamp": "2026-01-25T23:36:20.487775+00:00", "data": {"market": "0x4e4f77e7dbf4cab666e9a1943674d7ae66348e862df03ea6f44b11eb95731928", "price_changes": [{"asset_id": "17371217118862125782438074585166210555214661810823929795910191856905580975576", "price": "0.77", "size": "16966.45", "side": "BUY", "hash": "34dc7794618080ea133a0d990a7157b0ea9f12f9", "best_bid": "0.78", "best_ask": "0.79"}, {"asset_id": "65139230827417363158752884968303867495725894165574887635816574090175320800482", "price": "0.23", "size": "16966.45", "side": "SELL", "hash": "00e734c45b9b1d0a33144518751ee4b887cec343", "best_bid": "0.21", "best_ask": "0.22"}], "timestamp": "1769384180412", "event_type": "price_change"}}
{"_local_timestamp": "2026-01-25T23:36:20.658015+00:00", "data": {"market": "0xd5d9fc47718bd553592d126b1fa5e87183d27f3936975b0c04cc0f2dec1f1bb4", "price_changes": [{"asset_id": "33156410999665902694791064431724433042010245771106314074312009703157423879038", "price": "0.2", "size": "11367.1", "side": "BUY", "hash": "906c45faec670ef957e347f87526e649cc5b5b97", "best_bid": "0.2", "best_ask": "0.22"}, {"asset_id": "83247781037352156539108067944461291821683755894607244160607042790356561625563", "price": "0.8", "size": "11367.1", "side": "SELL", "hash": "7169b5cf2b70a8e7aca87e10bd7d540b7d205a98", "best_bid": "0.78", "best_ask": "0.8"}], "timestamp": "1769384180588", "event_type": "price_change"}}
{"_local_timestamp": "2026-01-25T23:36:20.658431+00:00", "data": {"market": "0x4e4f77e7dbf4cab666e9a1943674d7ae66348e862df03ea6f44b11eb95731928", "price_changes": [{"asset_id": "17371217118862125782438074585166210555214661810823929795910191856905580975576", "price": "0.77", "size": "16960.23", "side": "BUY", "hash": "ea189410558165b3de0c52d7b83c08559385094f", "best_bid": "0.78", "best_ask": "0.79"}, {"asset_id": "65139230827417363158752884968303867495725894165574887635816574090175320800482", "price": "0.23", "size": "16960.23", "side": "SELL", "hash": "6044b8a76eafa74ddffae683223773409db3c784", "best_bid": "0.21", "best_ask": "0.22"}], "timestamp": "1769384180588", "event_type": "price_change"}}
{"_local_timestamp": "2026-01-25T23:36:20.731007+00:00", "data": {"market": "0xd5d9fc47718bd553592d126b1fa5e87183d27f3936975b0c04cc0f2dec1f1bb4", "price_changes": [{"asset_id": "33156410999665902694791064431724433042010245771106314074312009703157423879038", "price": "0.2", "size": "11373.32", "side": "BUY", "hash": "6079465503d159ea283cb3c0011f42a1b4ec7acb", "best_bid": "0.2", "best_ask": "0.22"}, {"asset_id": "83247781037352156539108067944461291821683755894607244160607042790356561625563", "price": "0.8", "size": "11373.32", "side": "SELL", "hash": "bc938ccd59aa30586d222706c1e8d1d665e2e999", "best_bid": "0.78", "best_ask": "0.8"}], "timestamp": "1769384180653", "event_type": "price_change"}}
{"_local_timestamp": "2026-01-25T23:36:20.731458+00:00", "data": {"market": "0x4e4f77e7dbf4cab666e9a1943674d7ae66348e862df03ea6f44b11eb95731928", "price_changes": [{"asset_id": "17371217118862125782438074585166210555214661810823929795910191856905580975576", "price": "0.77", "size": "16966.45", "side": "BUY", "hash": "86c402f7a0f2ddf143f7669b853b51f45db44a17", "best_bid": "0.78", "best_ask": "0.79"}, {"asset_id": "65139230827417363158752884968303867495725894165574887635816574090175320800482", "price": "0.23", "size": "16966.45", "side": "SELL", "hash": "17ae7fef23a2f3893803da7daeaf03f66a84a28d", "best_bid": "0.21", "best_ask": "0.22"}], "timestamp": "1769384180655", "event_type": "price_change"}}
{"_local_timestamp": "2026-01-25T23:36:20.942141+00:00", "data": {"market": "0xd5d9fc47718bd553592d126b1fa5e87183d27f3936975b0c04cc0f2dec1f1bb4", "price_changes": [{"asset_id": "33156410999665902694791064431724433042010245771106314074312009703157423879038", "price": "0.2", "size": "11367.1", "side": "BUY", "hash": "6e9ddc642139693bf35842eb47a5c68fba6071ef", "best_bid": "0.2", "best_ask": "0.22"}, {"asset_id": "83247781037352156539108067944461291821683755894607244160607042790356561625563", "price": "0.8", "size": "11367.1", "side": "SELL", "hash": "9183839e35eab4bd06d5343fd34f16efd7a919f2", "best_bid": "0.78", "best_ask": "0.8"}], "timestamp": "1769384180875", "event_type": "price_change"}}
{"_local_timestamp": "2026-01-25T23:36:20.942520+00:00", "data": {"market": "0x4e4f77e7dbf4cab666e9a1943674d7ae66348e862df03ea6f44b11eb95731928", "price_changes": [{"asset_id": "17371217118862125782438074585166210555214661810823929795910191856905580975576", "price": "0.77", "size": "16960.23", "side": "BUY", "hash": "2379a2435cf7b2e030ab42d7238ca12d1bc4b748", "best_bid": "0.78", "best_ask": "0.79"}, {"asset_id": "65139230827417363158752884968303867495725894165574887635816574090175320800482", "price": "0.23", "size": "16960.23", "side": "SELL", "hash": "282b2a70c909b5d828d34d274056b7f9591c5a8e", "best_bid": "0.21", "best_ask": "0.22"}], "timestamp": "1769384180875", "event_type": "price_change"}}
{"_local_timestamp": "2026-01-25T23:36:21.318850+00:00", "data": {"market": "0xd5d9fc47718bd553592d126b1fa5e87183d27f3936975b0c04cc0f2dec1f1bb4", "price_changes": [{"asset_id": "33156410999665902694791064431724433042010245771106314074312009703157423879038", "price": "0.2", "size": "11373.32", "side": "BUY", "hash": "dfc37173722ee0b013c1fe61befafacbc0b26e5f", "best_bid": "0.2", "best_ask": "0.22"}, {"asset_id": "83247781037352156539108067944461291821683755894607244160607042790356561625563", "price": "0.8", "size": "11373.32", "side": "SELL", "hash": "17121e68b5feb55bd30a06db171bf2362a1fd5e5", "best_bid": "0.78", "best_ask": "0.8"}], "timestamp": "1769384181251", "event_type": "price_change"}}
{"_local_timestamp": "2026-01-25T23:36:21.406264+00:00", "data": {"market": "0x4e4f77e7dbf4cab666e9a1943674d7ae66348e862df03ea6f44b11eb95731928", "price_changes": [{"asset_id": "17371217118862125782438074585166210555214661810823929795910191856905580975576", "price": "0.77", "size": "16966.45", "side": "BUY", "hash": "cb691465a8b57d63eb96823ff1a807c81093cb17", "best_bid": "0.78", "best_ask": "0.79"}, {"asset_id": "65139230827417363158752884968303867495725894165574887635816574090175320800482", "price": "0.23", "size": "16966.45", "side": "SELL", "hash": "8d049b8760bb729e9f2c4e54cb098caf010ac079", "best_bid": "0.21", "best_ask": "0.22"}], "timestamp": "1769384181320", "event_type": "price_change"}}
{"_local_timestamp": "2026-01-25T23:36:21.802089+00:00", "data": {"market": "0xd5d9fc47718bd553592d126b1fa5e87183d27f3936975b0c04cc0f2dec1f1bb4", "price_changes": [{"asset_id": "33156410999665902694791064431724433042010245771106314074312009703157423879038", "price": "0.2", "size": "11367.1", "side": "BUY", "hash": "dbc551f3bef4b24dccdd96ff7822856836a2ba02", "best_bid": "0.2", "best_ask": "0.22"}, {"asset_id": "83247781037352156539108067944461291821683755894607244160607042790356561625563", "price": "0.8", "size": "11367.1", "side": "SELL", "hash": "d9942860436611392f1a8dd5a9b3250c3be65c65", "best_bid": "0.78", "best_ask": "0.8"}], "timestamp": "1769384181734", "event_type": "price_change"}}
{"_local_timestamp": "2026-01-25T23:36:21.802659+00:00", "data": {"market": "0x4e4f77e7dbf4cab666e9a1943674d7ae66348e862df03ea6f44b11eb95731928", "price_changes": [{"asset_id": "17371217118862125782438074585166210555214661810823929795910191856905580975576", "price": "0.77", "size": "16960.23", "side": "BUY", "hash": "0e31ee4be6248ce1ccbca74e16c8c905e03ebe78", "best_bid": "0.78", "best_ask": "0.79"}, {"asset_id": "65139230827417363158752884968303867495725894165574887635816574090175320800482", "price": "0.23", "size": "16960.23", "side": "SELL", "hash": "859e497a2b2f5c6de24333891fb5182cdf890f3b", "best_bid": "0.21", "best_ask": "0.22"}], "timestamp": "1769384181734", "event_type": "price_change"}}
{"_local_timestamp": "2026-01-25T23:36:35.655400+00:00", "data": {"market": "0xd5d9fc47718bd553592d126b1fa5e87183d27f3936975b0c04cc0f2dec1f1bb4", "price_changes": [{"asset_id": "83247781037352156539108067944461291821683755894607244160607042790356561625563", "price": "0.77", "size": "41395.01", "side": "BUY", "hash": "ebe5efee3d7b118660bfd100573210d941f48a90", "best_bid": "0.78", "best_ask": "0.8"}, {"asset_id": "33156410999665902694791064431724433042010245771106314074312009703157423879038", "price": "0.23", "size": "41395.01", "side": "SELL", "hash": "7ca8a547edbeef72681efec2e2192eef0866efbc", "best_bid": "0.2", "best_ask": "0.22"}], "timestamp": "1769384195577", "event_type": "price_change"}}
{"_local_timestamp": "2026-01-25T23:36:35.682877+00:00", "data": {"market": "0xd5d9fc47718bd553592d126b1fa5e87183d27f3936975b0c04cc0f2dec1f1bb4", "price_changes": [{"asset_id": "83247781037352156539108067944461291821683755894607244160607042790356561625563", "price": "0.77", "size": "41595.01", "side": "BUY", "hash": "38fca4311d69eaa727247eebf5f0595e48736cd1", "best_bid": "0.78", "best_ask": "0.8"}, {"asset_id": "33156410999665902694791064431724433042010245771106314074312009703157423879038", "price": "0.23", "size": "41595.01", "side": "SELL", "hash": "05a994bd64fa15a273772c360f69f0311f42b4d7", "best_bid": "0.2", "best_ask": "0.22"}], "timestamp": "1769384195610", "event_type": "price_change"}}
{"_local_timestamp": "2026-01-25T23:36:35.703021+00:00", "data": {"market": "0xd5d9fc47718bd553592d126b1fa5e87183d27f3936975b0c04cc0f2dec1f1bb4", "price_changes": [{"asset_id": "33156410999665902694791064431724433042010245771106314074312009703157423879038", "price": "0.2", "size": "11167.1", "side": "BUY", "hash": "047b83a4aef0e7386a360a42691c26a15bb8778c", "best_bid": "0.2", "best_ask": "0.22"}, {"asset_id": "83247781037352156539108067944461291821683755894607244160607042790356561625563", "price": "0.8", "size": "11167.1", "side": "SELL", "hash": "6f2f0a01cffbb20a21312b2f28d64d111c411c2a", "best_bid": "0.78", "best_ask": "0.8"}], "timestamp": "1769384195636", "event_type": "price_change"}}
{"_local_timestamp": "2026-01-25T23:36:35.738654+00:00", "data": {"market": "0xd5d9fc47718bd553592d126b1fa5e87183d27f3936975b0c04cc0f2dec1f1bb4", "price_changes": [{"asset_id": "33156410999665902694791064431724433042010245771106314074312009703157423879038", "price": "0.2", "size": "11367.1", "side": "BUY", "hash": "890f0f8c28e83b575c5f5da0090a9db87fa61d60", "best_bid": "0.2", "best_ask": "0.22"}, {"asset_id": "83247781037352156539108067944461291821683755894607244160607042790356561625563", "price": "0.8", "size": "11367.1", "side": "SELL", "hash": "4488277f9543d566467e9c1439e9d6e9fbf2a109", "best_bid": "0.78", "best_ask": "0.8"}], "timestamp": "1769384195667", "event_type": "price_change"}}
{"_local_timestamp": "2026-01-25T23:37:05.532853+00:00", "data": {"market": "0x4e4f77e7dbf4cab666e9a1943674d7ae66348e862df03ea6f44b11eb95731928", "price_changes": [{"asset_id": "65139230827417363158752884968303867495725894165574887635816574090175320800482", "price": "0.21", "size": "30784", "side": "BUY", "hash": "6b8ac6a9f1a9463f4ed380ee1806da19e77ef2bf", "best_bid": "0.21", "best_ask": "0.22"}, {"asset_id": "17371217118862125782438074585166210555214661810823929795910191856905580975576", "price": "0.79", "size": "30784", "side": "SELL", "hash": "838a6c3ac9ce270aa06d92723b4623e6a9381107", "best_bid": "0.78", "best_ask": "0.79"}], "timestamp": "1769384225468", "event_type": "price_change"}}
{"_local_timestamp": "2026-01-25T23:37:05.572866+00:00", "data": {"market": "0x4e4f77e7dbf4cab666e9a1943674d7ae66348e862df03ea6f44b11eb95731928", "price_changes": [{"asset_id": "65139230827417363158752884968303867495725894165574887635816574090175320800482", "price": "0.21", "size": "30984", "side": "BUY", "hash": "326ab11a5de8f4b1c38d417dd78d4e2414fc1531", "best_bid": "0.21", "best_ask": "0.22"}, {"asset_id": "17371217118862125782438074585166210555214661810823929795910191856905580975576", "price": "0.79", "size": "30984", "side": "SELL", "hash": "436ae190df461f4d7161c5d16254d0a669ceed47", "best_bid": "0.78", "best_ask": "0.79"}], "timestamp": "1769384225499", "event_type": "price_change"}}
{"_local_timestamp": "2026-01-25T23:37:05.595942+00:00", "data": {"market": "0x4e4f77e7dbf4cab666e9a1943674d7ae66348e862df03ea6f44b11eb95731928", "price_changes": [{"asset_id": "17371217118862125782438074585166210555214661810823929795910191856905580975576", "price": "0.76", "size": "3800", "side": "BUY", "hash": "2f07992fd62ea1883afa1167fac77ad20bf74beb", "best_bid": "0.78", "best_ask": "0.79"}, {"asset_id": "65139230827417363158752884968303867495725894165574887635816574090175320800482", "price": "0.24", "size": "3800", "side": "SELL", "hash": "e31cd0424b2662b485adf2a8d39ebda5325e1a05", "best_bid": "0.21", "best_ask": "0.22"}], "timestamp": "1769384225524", "event_type": "price_change"}}
{"_local_timestamp": "2026-01-25T23:37:05.634695+00:00", "data": {"market": "0x4e4f77e7dbf4cab666e9a1943674d7ae66348e862df03ea6f44b11eb95731928", "price_changes": [{"asset_id": "17371217118862125782438074585166210555214661810823929795910191856905580975576", "price": "0.76", "size": "4000", "side": "BUY", "hash": "c98f2c3f1c4d535e65a8e3ee073c0aa8e30b6438", "best_bid": "0.78", "best_ask": "0.79"}, {"asset_id": "65139230827417363158752884968303867495725894165574887635816574090175320800482", "price": "0.24", "size": "4000", "side": "SELL", "hash": "037d8984ef0b5aaac7fde805ae40e5d25a4e03e1", "best_bid": "0.21", "best_ask": "0.22"}], "timestamp": "1769384225555", "event_type": "price_change"}}
{"_local_timestamp": "2026-01-25T23:37:08.021738+00:00", "data": {"market": "0xd5d9fc47718bd553592d126b1fa5e87183d27f3936975b0c04cc0f2dec1f1bb4", "price_changes": [{"asset_id": "33156410999665902694791064431724433042010245771106314074312009703157423879038", "price": "0.17", "size": "1456", "side": "BUY", "hash": "12d39565eeacfea70f31faea3f1cbfdcb133f82c", "best_bid": "0.2", "best_ask": "0.22"}, {"asset_id": "83247781037352156539108067944461291821683755894607244160607042790356561625563", "price": "0.83", "size": "1456", "side": "SELL", "hash": "becad9ded302ee2baf2ad5fdd1c1b967d7427137", "best_bid": "0.78", "best_ask": "0.8"}], "timestamp": "1769384227941", "event_type": "price_change"}}
{"_local_timestamp": "2026-01-25T23:37:08.022103+00:00", "data": {"market": "0x4e4f77e7dbf4cab666e9a1943674d7ae66348e862df03ea6f44b11eb95731928", "price_changes": [{"asset_id": "17371217118862125782438074585166210555214661810823929795910191856905580975576", "price": "0.74", "size": "1828.8", "side": "BUY", "hash": "052210f3d89895e59676b98042e368b6e4068874", "best_bid": "0.78", "best_ask": "0.79"}, {"asset_id": "65139230827417363158752884968303867495725894165574887635816574090175320800482", "price": "0.26", "size": "1828.8", "side": "SELL", "hash": "b22397449b6de86813880b1f3557ad34dc1905ae", "best_bid": "0.21", "best_ask": "0.22"}], "timestamp": "1769384227941", "event_type": "price_change"}}
{"_local_timestamp": "2026-01-25T23:37:08.022399+00:00", "data": {"market": "0xd5d9fc47718bd553592d126b1fa5e87183d27f3936975b0c04cc0f2dec1f1bb4", "price_changes": [{"asset_id": "33156410999665902694791064431724433042010245771106314074312009703157423879038", "price": "0.18", "size": "1555", "side": "BUY", "hash": "f3891077a5b14c4826f0935da1351c1d7c020557", "best_bid": "0.2", "best_ask": "0.22"}, {"asset_id": "83247781037352156539108067944461291821683755894607244160607042790356561625563", "price": "0.82", "size": "1555", "side": "SELL", "hash": "18b23ccbdd629cfe8990fa2964a4e4ceb1567854", "best_bid": "0.78", "best_ask": "0.8"}], "timestamp": "1769384227942", "event_type": "price_change"}}
{"_local_timestamp": "2026-01-25T23:37:20.674310+00:00", "data": {"market": "0xd5d9fc47718bd553592d126b1fa5e87183d27f3936975b0c04cc0f2dec1f1bb4", "price_changes": [{"asset_id": "83247781037352156539108067944461291821683755894607244160607042790356561625563", "price": "0.77", "size": "41395.01", "side": "BUY", "hash": "d5851f79eb7380ce30e77ea302572f1b984d97c0", "best_bid": "0.78", "best_ask": "0.8"}, {"asset_id": "33156410999665902694791064431724433042010245771106314074312009703157423879038", "price": "0.23", "size": "41395.01", "side": "SELL", "hash": "f21c3d16ed93a535bf88468b0651c42c234508f1", "best_bid": "0.2", "best_ask": "0.22"}], "timestamp": "1769384240600", "event_type": "price_change"}}
{"_local_timestamp": "2026-01-25T23:37:20.709285+00:00", "data": {"market": "0xd5d9fc47718bd553592d126b1fa5e87183d27f3936975b0c04cc0f2dec1f1bb4", "price_changes": [{"asset_id": "83247781037352156539108067944461291821683755894607244160607042790356561625563", "price": "0.77", "size": "41595.01", "side": "BUY", "hash": "26f1354c0228243e5e22d4b8aa7d2118c66ff365", "best_bid": "0.78", "best_ask": "0.8"}, {"asset_id": "33156410999665902694791064431724433042010245771106314074312009703157423879038", "price": "0.23", "size": "41595.01", "side": "SELL", "hash": "64cae33c35e31ce34aed93ce70d5bda23870e892", "best_bid": "0.2", "best_ask": "0.22"}], "timestamp": "1769384240634", "event_type": "price_change"}}
{"_local_timestamp": "2026-01-25T23:37:20.732103+00:00", "data": {"market": "0xd5d9fc47718bd553592d126b1fa5e87183d27f3936975b0c04cc0f2dec1f1bb4", "price_changes": [{"asset_id": "33156410999665902694791064431724433042010245771106314074312009703157423879038", "price": "0.2", "size": "11167.1", "side": "BUY", "hash": "a4439bd2b7a952e1d90a8a118354eceaefb138d8", "best_bid": "0.2", "best_ask": "0.22"}, {"asset_id": "83247781037352156539108067944461291821683755894607244160607042790356561625563", "price": "0.8", "size": "11167.1", "side": "SELL", "hash": "7701e3f8f3a27df62fa38c49adb1223df97479f3", "best_bid": "0.78", "best_ask": "0.8"}], "timestamp": "1769384240658", "event_type": "price_change"}}
{"_local_timestamp": "2026-01-25T23:37:20.758465+00:00", "data": {"market": "0xd5d9fc47718bd553592d126b1fa5e87183d27f3936975b0c04cc0f2dec1f1bb4", "price_changes": [{"asset_id": "33156410999665902694791064431724433042010245771106314074312009703157423879038", "price": "0.2", "size": "11367.1", "side": "BUY", "hash": "bab870462e1f7c9afb917b7ed52d45362a73ce21", "best_bid": "0.2", "best_ask": "0.22"}, {"asset_id": "83247781037352156539108067944461291821683755894607244160607042790356561625563", "price": "0.8", "size": "11367.1", "side": "SELL", "hash": "07c15ba98113cc626ba45c3a0d873ad8cbffbbe6", "best_bid": "0.78", "best_ask": "0.8"}], "timestamp": "1769384240690", "event_type": "price_change"}}
{"_local_timestamp": "2026-01-25T23:37:31.833076+00:00", "data": {"market": "0xd5d9fc47718bd553592d126b1fa5e87183d27f3936975b0c04cc0f2dec1f1bb4", "price_changes": [{"asset_id": "33156410999665902694791064431724433042010245771106314074312009703157423879038", "price": "0.18", "size": "1155", "side": "BUY", "hash": "fb594a686940545a854d8c02c96eb2f4ab5cbc23", "best_bid": "0.2", "best_ask": "0.22"}, {"asset_id": "83247781037352156539108067944461291821683755894607244160607042790356561625563", "price": "0.82", "size": "1155", "side": "SELL", "hash": "ded63c9d1959483342891c972739551de185a3a9", "best_bid": "0.78", "best_ask": "0.8"}], "timestamp": "1769384251708", "event_type": "price_change"}}
{"_local_timestamp": "2026-01-25T23:37:31.833446+00:00", "data": {"market": "0xd5d9fc47718bd553592d126b1fa5e87183d27f3936975b0c04cc0f2dec1f1bb4", "price_changes": [{"asset_id": "33156410999665902694791064431724433042010245771106314074312009703157423879038", "price": "0.17", "size": "1056", "side": "BUY", "hash": "fb594a686940545a854d8c02c96eb2f4ab5cbc23", "best_bid": "0.2", "best_ask": "0.22"}, {"asset_id": "83247781037352156539108067944461291821683755894607244160607042790356561625563", "price": "0.83", "size": "1056", "side": "SELL", "hash": "ded63c9d1959483342891c972739551de185a3a9", "best_bid": "0.78", "best_ask": "0.8"}], "timestamp": "1769384251708", "event_type": "price_change"}}
{"_local_timestamp": "2026-01-25T23:37:31.833708+00:00", "data": {"market": "0x4e4f77e7dbf4cab666e9a1943674d7ae66348e862df03ea6f44b11eb95731928", "price_changes": [{"asset_id": "17371217118862125782438074585166210555214661810823929795910191856905580975576", "price": "0.74", "size": "1428.8", "side": "BUY", "hash": "408ae026275cbbfd6e559a975992e522124b8bee", "best_bid": "0.78", "best_ask": "0.79"}, {"asset_id": "65139230827417363158752884968303867495725894165574887635816574090175320800482", "price": "0.26", "size": "1428.8", "side": "SELL", "hash": "5f1f45d9111b2b956f74d1faa35317881810d5a7", "best_bid": "0.21", "best_ask": "0.22"}], "timestamp": "1769384251708", "event_type": "price_change"}}
{"_local_timestamp": "2026-01-25T23:37:31.961507+00:00", "data": {"market": "0x4e4f77e7dbf4cab666e9a1943674d7ae66348e862df03ea6f44b11eb95731928", "price_changes": [{"asset_id": "17371217118862125782438074585166210555214661810823929795910191856905580975576", "price": "0.77", "size": "18730.16", "side": "BUY", "hash": "deb28976bf71466ad39a612bc6d9f9964129c459", "best_bid": "0.78", "best_ask": "0.79"}, {"asset_id": "65139230827417363158752884968303867495725894165574887635816574090175320800482", "price": "0.23", "size": "18730.16", "side": "SELL", "hash": "78bdcbdf7d625a38a90f0b4efbe96c94fa298447", "best_bid": "0.21", "best_ask": "0.22"}], "timestamp": "1769384251818", "event_type": "price_change"}}
{"_local_timestamp": "2026-01-25T23:37:31.961871+00:00", "data": {"market": "0xd5d9fc47718bd553592d126b1fa5e87183d27f3936975b0c04cc0f2dec1f1bb4", "price_changes": [{"asset_id": "33156410999665902694791064431724433042010245771106314074312009703157423879038", "price": "0.2", "size": "13137.03", "side": "BUY", "hash": "25ab541c333350eae875b589892240a0ac332cb2", "best_bid": "0.2", "best_ask": "0.22"}, {"asset_id": "83247781037352156539108067944461291821683755894607244160607042790356561625563", "price": "0.8", "size": "13137.03", "side": "SELL", "hash": "feb5875f03db52e2f4d97c1d82a0db51d69b0012", "best_bid": "0.78", "best_ask": "0.8"}], "timestamp": "1769384251827", "event_type": "price_change"}}
{"_local_timestamp": "2026-01-25T23:37:32.320995+00:00", "data": {"market": "0xd5d9fc47718bd553592d126b1fa5e87183d27f3936975b0c04cc0f2dec1f1bb4", "price_changes": [{"asset_id": "33156410999665902694791064431724433042010245771106314074312009703157423879038", "price": "0.2", "size": "11367.1", "side": "BUY", "hash": "ed3bebed1ec2eb636d2c15a3ab15fc295d5397d9", "best_bid": "0.2", "best_ask": "0.22"}, {"asset_id": "83247781037352156539108067944461291821683755894607244160607042790356561625563", "price": "0.8", "size": "11367.1", "side": "SELL", "hash": "d8a4ebfb4e3c0a25baa1e0bdec1cbb0191266fed", "best_bid": "0.78", "best_ask": "0.8"}], "timestamp": "1769384252197", "event_type": "price_change"}}
{"_local_timestamp": "2026-01-25T23:37:32.321405+00:00", "data": {"market": "0x4e4f77e7dbf4cab666e9a1943674d7ae66348e862df03ea6f44b11eb95731928", "price_changes": [{"asset_id": "17371217118862125782438074585166210555214661810823929795910191856905580975576", "price": "0.77", "size": "16960.23", "side": "BUY", "hash": "73f0f7e4ad71f1ad8c79f3354512b641ca4c0468", "best_bid": "0.78", "best_ask": "0.79"}, {"asset_id": "65139230827417363158752884968303867495725894165574887635816574090175320800482", "price": "0.23", "size": "16960.23", "side": "SELL", "hash": "e53da9f389072f4f2711081d2885923a8cfbc0c1", "best_bid": "0.21", "best_ask": "0.22"}], "timestamp": "1769384252197", "event_type": "price_change"}}
{"_local_timestamp": "2026-01-25T23:37:32.383762+00:00", "data": {"market": "0x4e4f77e7dbf4cab666e9a1943674d7ae66348e862df03ea6f44b11eb95731928", "price_changes": [{"asset_id": "17371217118862125782438074585166210555214661810823929795910191856905580975576", "price": "0.77", "size": "18730.16", "side": "BUY", "hash": "72f201a14740b655804fd451b8585eb00176b2d6", "best_bid": "0.78", "best_ask": "0.79"}, {"asset_id": "65139230827417363158752884968303867495725894165574887635816574090175320800482", "price": "0.23", "size": "18730.16", "side": "SELL", "hash": "ee69722fb101063632d86e8b23f7cc2e952e1306", "best_bid": "0.21", "best_ask": "0.22"}], "timestamp": "1769384252297", "event_type": "price_change"}}
{"_local_timestamp": "2026-01-25T23:37:32.408760+00:00", "data": {"market": "0xd5d9fc47718bd553592d126b1fa5e87183d27f3936975b0c04cc0f2dec1f1bb4", "price_changes": [{"asset_id": "33156410999665902694791064431724433042010245771106314074312009703157423879038", "price": "0.2", "size": "13137.03", "side": "BUY", "hash": "fbfe4c2f42fc6e1e43ad0632d4aa2b241f69c294", "best_bid": "0.2", "best_ask": "0.22"}, {"asset_id": "83247781037352156539108067944461291821683755894607244160607042790356561625563", "price": "0.8", "size": "13137.03", "side": "SELL", "hash": "408a0b853fee585545b706e2eeeba96f241f366d", "best_bid": "0.78", "best_ask": "0.8"}], "timestamp": "1769384252336", "event_type": "price_change"}}
{"_local_timestamp": "2026-01-25T23:37:32.638111+00:00", "data": {"market": "0xd5d9fc47718bd553592d126b1fa5e87183d27f3936975b0c04cc0f2dec1f1bb4", "price_changes": [{"asset_id": "33156410999665902694791064431724433042010245771106314074312009703157423879038", "price": "0.2", "size": "11367.1", "side": "BUY", "hash": "145d7a96152f99d4bd7ac68479fec099b1452fc8", "best_bid": "0.2", "best_ask": "0.22"}, {"asset_id": "83247781037352156539108067944461291821683755894607244160607042790356561625563", "price": "0.8", "size": "11367.1", "side": "SELL", "hash": "aa6742986865e0947ba2adb9a3ff272429a9a65e", "best_bid": "0.78", "best_ask": "0.8"}], "timestamp": "1769384252545", "event_type": "price_change"}}
{"_local_timestamp": "2026-01-25T23:37:32.644957+00:00", "data": {"market": "0x4e4f77e7dbf4cab666e9a1943674d7ae66348e862df03ea6f44b11eb95731928", "price_changes": [{"asset_id": "17371217118862125782438074585166210555214661810823929795910191856905580975576", "price": "0.77", "size": "16960.23", "side": "BUY", "hash": "37e1f11ade5acf961691f740dca13ee974cdc67c", "best_bid": "0.78", "best_ask": "0.79"}, {"asset_id": "65139230827417363158752884968303867495725894165574887635816574090175320800482", "price": "0.23", "size": "16960.23", "side": "SELL", "hash": "5b444f4b2a36ec3b667afd7a6149a418b5074b22", "best_bid": "0.21", "best_ask": "0.22"}], "timestamp": "1769384252545", "event_type": "price_change"}}
{"_local_timestamp": "2026-01-25T23:37:34.509824+00:00", "data": {"market": "0xd5d9fc47718bd553592d126b1fa5e87183d27f3936975b0c04cc0f2dec1f1bb4", "price_changes": [{"asset_id": "83247781037352156539108067944461291821683755894607244160607042790356561625563", "price": "0.78", "size": "28449.73", "side": "BUY", "hash": "4876dd4cfec8aa32062e7974efa9c1e6b2493e15", "best_bid": "0.78", "best_ask": "0.8"}, {"asset_id": "33156410999665902694791064431724433042010245771106314074312009703157423879038", "price": "0.22", "size": "28449.73", "side": "SELL", "hash": "c77dc4cc00fcc37830ed318f4a154cbef9f1ffc2", "best_bid": "0.2", "best_ask": "0.22"}], "timestamp": "1769384254435", "event_type": "price_change"}}
{"_local_timestamp": "2026-01-25T23:37:35.208482+00:00", "data": {"market": "0x4e4f77e7dbf4cab666e9a1943674d7ae66348e862df03ea6f44b11eb95731928", "price_changes": [{"asset_id": "17371217118862125782438074585166210555214661810823929795910191856905580975576", "price": "0.22", "size": "0", "side": "BUY", "hash": "8358a5f3f04e0e60ea485e6f579927f8dd38ee50", "best_bid": "0.78", "best_ask": "0.79"}, {"asset_id": "65139230827417363158752884968303867495725894165574887635816574090175320800482", "price": "0.78", "size": "0", "side": "SELL", "hash": "baae3eff4f177a57491f45bb5e422ed254509bc7", "best_bid": "0.21", "best_ask": "0.22"}], "timestamp": "1769384255116", "event_type": "price_change"}}
{"_local_timestamp": "2026-01-25T23:37:35.400063+00:00", "data": {"market": "0xd5d9fc47718bd553592d126b1fa5e87183d27f3936975b0c04cc0f2dec1f1bb4", "price_changes": [{"asset_id": "33156410999665902694791064431724433042010245771106314074312009703157423879038", "price": "0.2", "size": "13137.03", "side": "BUY", "hash": "064f74be134079ca074559233dbe8b48c5e95453", "best_bid": "0.2", "best_ask": "0.22"}, {"asset_id": "83247781037352156539108067944461291821683755894607244160607042790356561625563", "price": "0.8", "size": "13137.03", "side": "SELL", "hash": "4b2c421d32a97a4546df9319309b9fbc15bca54e", "best_bid": "0.78", "best_ask": "0.8"}], "timestamp": "1769384255260", "event_type": "price_change"}}
{"_local_timestamp": "2026-01-25T23:37:35.400405+00:00", "data": {"market": "0x4e4f77e7dbf4cab666e9a1943674d7ae66348e862df03ea6f44b11eb95731928", "price_changes": [{"asset_id": "17371217118862125782438074585166210555214661810823929795910191856905580975576", "price": "0.77", "size": "18730.16", "side": "BUY", "hash": "d559195f54c255f4f435561aa5334e1b38937aae", "best_bid": "0.78", "best_ask": "0.79"}, {"asset_id": "65139230827417363158752884968303867495725894165574887635816574090175320800482", "price": "0.23", "size": "18730.16", "side": "SELL", "hash": "d322fceb434fec6ebecd09d1b09370404493c1b8", "best_bid": "0.21", "best_ask": "0.22"}], "timestamp": "1769384255261", "event_type": "price_change"}}
{"_local_timestamp": "2026-01-25T23:37:35.560645+00:00", "data": {"market": "0xd5d9fc47718bd553592d126b1fa5e87183d27f3936975b0c04cc0f2dec1f1bb4", "price_changes": [{"asset_id": "33156410999665902694791064431724433042010245771106314074312009703157423879038", "price": "0.2", "size": "11367.1", "side": "BUY", "hash": "e1744f9d3b07e618905301bc68f0d5266ea30b8b", "best_bid": "0.2", "best_ask": "0.22"}, {"asset_id": "83247781037352156539108067944461291821683755894607244160607042790356561625563", "price": "0.8", "size": "11367.1", "side": "SELL", "hash": "6b96b8a7236a5e43025541cefceee73e2ff8c35c", "best_bid": "0.78", "best_ask": "0.8"}], "timestamp": "1769384255477", "event_type": "price_change"}}
{"_local_timestamp": "2026-01-25T23:37:35.560971+00:00", "data": {"market": "0x4e4f77e7dbf4cab666e9a1943674d7ae66348e862df03ea6f44b11eb95731928", "price_changes": [{"asset_id": "17371217118862125782438074585166210555214661810823929795910191856905580975576", "price": "0.77", "size": "16960.23", "side": "BUY", "hash": "312b800063cf6366d0c79c9b8765e3c307ed88c1", "best_bid": "0.78", "best_ask": "0.79"}, {"asset_id": "65139230827417363158752884968303867495725894165574887635816574090175320800482", "price": "0.23", "size": "16960.23", "side": "SELL", "hash": "9e16b8fda03f6a7010f0d78426546a1bac60b8a3", "best_bid": "0.21", "best_ask": "0.22"}], "timestamp": "1769384255477", "event_type": "price_change"}}
{"_local_timestamp": "2026-01-25T23:37:50.548347+00:00", "data": {"market": "0x4e4f77e7dbf4cab666e9a1943674d7ae66348e862df03ea6f44b11eb95731928", "price_changes": [{"asset_id": "65139230827417363158752884968303867495725894165574887635816574090175320800482", "price": "0.21", "size": "30784", "side": "BUY", "hash": "1fb23037182320c6d0f0c6f438d9adba75517c33", "best_bid": "0.21", "best_ask": "0.22"}, {"asset_id": "17371217118862125782438074585166210555214661810823929795910191856905580975576", "price": "0.79", "size": "30784", "side": "SELL", "hash": "65427877cd3df0d7d561f09d50e124cd6680af7d", "best_bid": "0.78", "best_ask": "0.79"}], "timestamp": "1769384270475", "event_type": "price_change"}}
{"_local_timestamp": "2026-01-25T23:37:50.578257+00:00", "data": {"market": "0x4e4f77e7dbf4cab666e9a1943674d7ae66348e862df03ea6f44b11eb95731928", "price_changes": [{"asset_id": "65139230827417363158752884968303867495725894165574887635816574090175320800482", "price": "0.21", "size": "30984", "side": "BUY", "hash": "5e285be7e47e34d7d36b5702c571c1317ec9bbe4", "best_bid": "0.21", "best_ask": "0.22"}, {"asset_id": "17371217118862125782438074585166210555214661810823929795910191856905580975576", "price": "0.79", "size": "30984", "side": "SELL", "hash": "fedb4b25c5ac5f24664923b33d6c7d545d911166", "best_bid": "0.78", "best_ask": "0.79"}], "timestamp": "1769384270507", "event_type": "price_change"}}
{"_local_timestamp": "2026-01-25T23:37:50.625696+00:00", "data": {"market": "0x4e4f77e7dbf4cab666e9a1943674d7ae66348e862df03ea6f44b11eb95731928", "price_changes": [{"asset_id": "17371217118862125782438074585166210555214661810823929795910191856905580975576", "price": "0.76", "size": "3800", "side": "BUY", "hash": "584899a6f34a341ac918aac80188edf4b5992dd9", "best_bid": "0.78", "best_ask": "0.79"}, {"asset_id": "65139230827417363158752884968303867495725894165574887635816574090175320800482", "price": "0.24", "size": "3800", "side": "SELL", "hash": "6bd72c20c36bb7d5a6c4671f6f185d94519daa29", "best_bid": "0.21", "best_ask": "0.22"}], "timestamp": "1769384270544", "event_type": "price_change"}}
{"_local_timestamp": "2026-01-25T23:37:50.648547+00:00", "data": {"market": "0x4e4f77e7dbf4cab666e9a1943674d7ae66348e862df03ea6f44b11eb95731928", "price_changes": [{"asset_id": "17371217118862125782438074585166210555214661810823929795910191856905580975576", "price": "0.76", "size": "4000", "side": "BUY", "hash": "0784e9fd98622be8a29ee4f93470de896549cefc", "best_bid": "0.78", "best_ask": "0.79"}, {"asset_id": "65139230827417363158752884968303867495725894165574887635816574090175320800482", "price": "0.24", "size": "4000", "side": "SELL", "hash": "7fb27ae670fdc783bc591eceeb640c1864b2f17c", "best_bid": "0.21", "best_ask": "0.22"}], "timestamp": "1769384270578", "event_type": "price_change"}}
{"_local_timestamp": "2026-01-25T23:37:50.655602+00:00", "data": {"market": "0xd5d9fc47718bd553592d126b1fa5e87183d27f3936975b0c04cc0f2dec1f1bb4", "price_changes": [{"asset_id": "33156410999665902694791064431724433042010245771106314074312009703157423879038", "price": "0.2", "size": "13217.03", "side": "BUY", "hash": "1269a3a91e37dd75ab7891c0f9689e106000c1cd", "best_bid": "0.2", "best_ask": "0.22"}, {"asset_id": "83247781037352156539108067944461291821683755894607244160607042790356561625563", "price": "0.8", "size": "13217.03", "side": "SELL", "hash": "2ae175aaf2ed250c94bf17e5ecb8a8a0f83bef5e", "best_bid": "0.78", "best_ask": "0.8"}], "timestamp": "1769384270586", "event_type": "price_change"}}
{"_local_timestamp": "2026-01-25T23:37:50.668148+00:00", "data": {"market": "0x4e4f77e7dbf4cab666e9a1943674d7ae66348e862df03ea6f44b11eb95731928", "price_changes": [{"asset_id": "17371217118862125782438074585166210555214661810823929795910191856905580975576", "price": "0.77", "size": "18810.16", "side": "BUY", "hash": "9088b36e213e6c10dad2773fff13d10bbda40cc4", "best_bid": "0.78", "best_ask": "0.79"}, {"asset_id": "65139230827417363158752884968303867495725894165574887635816574090175320800482", "price": "0.23", "size": "18810.16", "side": "SELL", "hash": "e6561b71fbd2b35b7bf754f915f8f16ddfcb1a1d", "best_bid": "0.21", "best_ask": "0.22"}], "timestamp": "1769384270594", "event_type": "price_change"}}
{"_local_timestamp": "2026-01-25T23:37:50.867641+00:00", "data": {"market": "0xd5d9fc47718bd553592d126b1fa5e87183d27f3936975b0c04cc0f2dec1f1bb4", "price_changes": [{"asset_id": "33156410999665902694791064431724433042010245771106314074312009703157423879038", "price": "0.2", "size": "11367.1", "side": "BUY", "hash": "735b496beae82a4ece115811bea49f2ea87b2ca5", "best_bid": "0.2", "best_ask": "0.22"}, {"asset_id": "83247781037352156539108067944461291821683755894607244160607042790356561625563", "price": "0.8", "size": "11367.1", "side": "SELL", "hash": "f6797b25609a8306a40f3d1a6fecf44cc973ec3c", "best_bid": "0.78", "best_ask": "0.8"}], "timestamp": "1769384270777", "event_type": "price_change"}}
{"_local_timestamp": "2026-01-25T23:37:50.868840+00:00", "data": {"market": "0x4e4f77e7dbf4cab666e9a1943674d7ae66348e862df03ea6f44b11eb95731928", "price_changes": [{"asset_id": "17371217118862125782438074585166210555214661810823929795910191856905580975576", "price": "0.77", "size": "16960.23", "side": "BUY", "hash": "4538104a1aa6b2b6bb0a82cef952292a40e20825", "best_bid": "0.78", "best_ask": "0.79"}, {"asset_id": "65139230827417363158752884968303867495725894165574887635816574090175320800482", "price": "0.23", "size": "16960.23", "side": "SELL", "hash": "4df110b86d71c5f9f4f9af62d020478795c1335f", "best_bid": "0.21", "best_ask": "0.22"}], "timestamp": "1769384270777", "event_type": "price_change"}}
{"_local_timestamp": "2026-01-25T23:37:51.002830+00:00", "data": {"market": "0x4e4f77e7dbf4cab666e9a1943674d7ae66348e862df03ea6f44b11eb95731928", "price_changes": [{"asset_id": "17371217118862125782438074585166210555214661810823929795910191856905580975576", "price": "0.77", "size": "18810.16", "side": "BUY", "hash": "bffcc68db1d4da1703ec4b72a4d29c2d5a66c640", "best_bid": "0.78", "best_ask": "0.79"}, {"asset_id": "65139230827417363158752884968303867495725894165574887635816574090175320800482", "price": "0.23", "size": "18810.16", "side": "SELL", "hash": "54d6f687651e55c74888b24b556b2a7c2d2c00c6", "best_bid": "0.21", "best_ask": "0.22"}], "timestamp": "1769384270930", "event_type": "price_change"}}
{"_local_timestamp": "2026-01-25T23:37:51.003223+00:00", "data": {"market": "0xd5d9fc47718bd553592d126b1fa5e87183d27f3936975b0c04cc0f2dec1f1bb4", "price_changes": [{"asset_id": "33156410999665902694791064431724433042010245771106314074312009703157423879038", "price": "0.2", "size": "13217.03", "side": "BUY", "hash": "d7f2a57f13673505cc27afb90efd34f111f7780b", "best_bid": "0.2", "best_ask": "0.22"}, {"asset_id": "83247781037352156539108067944461291821683755894607244160607042790356561625563", "price": "0.8", "size": "13217.03", "side": "SELL", "hash": "bbce53c6c0a7b5bffd5fac6e7c27e3938f24b916", "best_bid": "0.78", "best_ask": "0.8"}], "timestamp": "1769384270930", "event_type": "price_change"}}
{"_local_timestamp": "2026-01-25T23:37:51.483415+00:00", "data": {"market": "0xd5d9fc47718bd553592d126b1fa5e87183d27f3936975b0c04cc0f2dec1f1bb4", "price_changes": [{"asset_id": "33156410999665902694791064431724433042010245771106314074312009703157423879038", "price": "0.2", "size": "11367.1", "side": "BUY", "hash": "83adffa82e634e6f2a56a38cd1886bead8711a88", "best_bid": "0.2", "best_ask": "0.22"}, {"asset_id": "83247781037352156539108067944461291821683755894607244160607042790356561625563", "price": "0.8", "size": "11367.1", "side": "SELL", "hash": "66e8428194eea6b2b438b1981c04c0b26b27d964", "best_bid": "0.78", "best_ask": "0.8"}], "timestamp": "1769384271190", "event_type": "price_change"}}
{"_local_timestamp": "2026-01-25T23:37:51.483907+00:00", "data": {"market": "0x4e4f77e7dbf4cab666e9a1943674d7ae66348e862df03ea6f44b11eb95731928", "price_changes": [{"asset_id": "17371217118862125782438074585166210555214661810823929795910191856905580975576", "price": "0.77", "size": "16960.23", "side": "BUY", "hash": "26d800065eb88be9f0429c22d07da7a43f1d0688", "best_bid": "0.78", "best_ask": "0.79"}, {"asset_id": "65139230827417363158752884968303867495725894165574887635816574090175320800482", "price": "0.23", "size": "16960.23", "side": "SELL", "hash": "c26c69bd7fd60119877b3d07c4f89233bd0ebd1d", "best_bid": "0.21", "best_ask": "0.22"}], "timestamp": "1769384271190", "event_type": "price_change"}}
{"_local_timestamp": "2026-01-25T23:37:51.722345+00:00", "data": {"market": "0x4e4f77e7dbf4cab666e9a1943674d7ae66348e862df03ea6f44b11eb95731928", "price_changes": [{"asset_id": "17371217118862125782438074585166210555214661810823929795910191856905580975576", "price": "0.77", "size": "18810.16", "side": "BUY", "hash": "ee7f4cf260558150c047a03cea67246a8895f2cf", "best_bid": "0.78", "best_ask": "0.79"}, {"asset_id": "65139230827417363158752884968303867495725894165574887635816574090175320800482", "price": "0.23", "size": "18810.16", "side": "SELL", "hash": "8d05712ccec27cd9348938a8a23e7c4890325f32", "best_bid": "0.21", "best_ask": "0.22"}], "timestamp": "1769384271450", "event_type": "price_change"}}
{"_local_timestamp": "2026-01-25T23:37:51.722802+00:00", "data": {"market": "0xd5d9fc47718bd553592d126b1fa5e87183d27f3936975b0c04cc0f2dec1f1bb4", "price_changes": [{"asset_id": "33156410999665902694791064431724433042010245771106314074312009703157423879038", "price": "0.2", "size": "13217.03", "side": "BUY", "hash": "5d02bfbc76b0385a2ae8069f116727f480f22ac9", "best_bid": "0.2", "best_ask": "0.22"}, {"asset_id": "83247781037352156539108067944461291821683755894607244160607042790356561625563", "price": "0.8", "size": "13217.03", "side": "SELL", "hash": "34c922593c24c832103d88327d13b6c7a81b468c", "best_bid": "0.78", "best_ask": "0.8"}], "timestamp": "1769384271452", "event_type": "price_change"}}
{"_local_timestamp": "2026-01-25T23:37:51.864116+00:00", "data": {"market": "0xd5d9fc47718bd553592d126b1fa5e87183d27f3936975b0c04cc0f2dec1f1bb4", "price_changes": [{"asset_id": "33156410999665902694791064431724433042010245771106314074312009703157423879038", "price": "0.2", "size": "11367.1", "side": "BUY", "hash": "d53581da42978b4a9b297d30bc460df216b5389e", "best_bid": "0.2", "best_ask": "0.22"}, {"asset_id": "83247781037352156539108067944461291821683755894607244160607042790356561625563", "price": "0.8", "size": "11367.1", "side": "SELL", "hash": "ef6df7fcb3716e959396709117a540acb2f9361d", "best_bid": "0.78", "best_ask": "0.8"}], "timestamp": "1769384271731", "event_type": "price_change"}}
{"_local_timestamp": "2026-01-25T23:37:51.871574+00:00", "data": {"market": "0x4e4f77e7dbf4cab666e9a1943674d7ae66348e862df03ea6f44b11eb95731928", "price_changes": [{"asset_id": "17371217118862125782438074585166210555214661810823929795910191856905580975576", "price": "0.77", "size": "16960.23", "side": "BUY", "hash": "95f5287d8126b44f430a744eb7c313cad2c09738", "best_bid": "0.78", "best_ask": "0.79"}, {"asset_id": "65139230827417363158752884968303867495725894165574887635816574090175320800482", "price": "0.23", "size": "16960.23", "side": "SELL", "hash": "f0b79b6dbdd968d38f7c909d1211c75d85c0d54d", "best_bid": "0.21", "best_ask": "0.22"}], "timestamp": "1769384271731", "event_type": "price_change"}}
{"_local_timestamp": "2026-01-25T23:38:05.732603+00:00", "data": {"market": "0xd5d9fc47718bd553592d126b1fa5e87183d27f3936975b0c04cc0f2dec1f1bb4", "price_changes": [{"asset_id": "83247781037352156539108067944461291821683755894607244160607042790356561625563", "price": "0.77", "size": "41395.01", "side": "BUY", "hash": "d3a5cd876a811be9ec2eff5b9a52dba9028a24d8", "best_bid": "0.78", "best_ask": "0.8"}, {"asset_id": "33156410999665902694791064431724433042010245771106314074312009703157423879038", "price": "0.23", "size": "41395.01", "side": "SELL", "hash": "63590993f6c83a77fa156de03fbbf2b623a494a3", "best_bid": "0.2", "best_ask": "0.22"}], "timestamp": "1769384285665", "event_type": "price_change"}}
{"_local_timestamp": "2026-01-25T23:38:05.774920+00:00", "data": {"market": "0xd5d9fc47718bd553592d126b1fa5e87183d27f3936975b0c04cc0f2dec1f1bb4", "price_changes": [{"asset_id": "83247781037352156539108067944461291821683755894607244160607042790356561625563", "price": "0.77", "size": "41595.01", "side": "BUY", "hash": "0ad301bb4d71a2f180e51d1276ddd03bf980586f", "best_bid": "0.78", "best_ask": "0.8"}, {"asset_id": "33156410999665902694791064431724433042010245771106314074312009703157423879038", "price": "0.23", "size": "41595.01", "side": "SELL", "hash": "522dc951f901e10dbf22d8c6ff099766a39d595d", "best_bid": "0.2", "best_ask": "0.22"}], "timestamp": "1769384285706", "event_type": "price_change"}}
{"_local_timestamp": "2026-01-25T23:38:05.806017+00:00", "data": {"market": "0xd5d9fc47718bd553592d126b1fa5e87183d27f3936975b0c04cc0f2dec1f1bb4", "price_changes": [{"asset_id": "33156410999665902694791064431724433042010245771106314074312009703157423879038", "price": "0.2", "size": "11167.1", "side": "BUY", "hash": "28daec21a3dbb219f5a488fe38b3d0c627f6a065", "best_bid": "0.2", "best_ask": "0.22"}, {"asset_id": "83247781037352156539108067944461291821683755894607244160607042790356561625563", "price": "0.8", "size": "11167.1", "side": "SELL", "hash": "a72ce95b32a59a55cb4afb34c481329cd67c613b", "best_bid": "0.78", "best_ask": "0.8"}], "timestamp": "1769384285730", "event_type": "price_change"}}
{"_local_timestamp": "2026-01-25T23:38:05.842969+00:00", "data": {"market": "0xd5d9fc47718bd553592d126b1fa5e87183d27f3936975b0c04cc0f2dec1f1bb4", "price_changes": [{"asset_id": "33156410999665902694791064431724433042010245771106314074312009703157423879038", "price": "0.2", "size": "11367.1", "side": "BUY", "hash": "98a9488a282b2e354465f2073217a36e57478ecd", "best_bid": "0.2", "best_ask": "0.22"}, {"asset_id": "83247781037352156539108067944461291821683755894607244160607042790356561625563", "price": "0.8", "size": "11367.1", "side": "SELL", "hash": "7da5008228ca319ffd6c526f324f435ecb8d091a", "best_bid": "0.78", "best_ask": "0.8"}], "timestamp": "1769384285762", "event_type": "price_change"}}
{"_local_timestamp": "2026-01-25T23:38:08.224594+00:00", "data": {"market": "0x4e4f77e7dbf4cab666e9a1943674d7ae66348e862df03ea6f44b11eb95731928", "price_changes": [{"asset_id": "17371217118862125782438074585166210555214661810823929795910191856905580975576", "price": "0.21", "size": "1998", "side": "BUY", "hash": "06ea85d7609869966ad74faa479f5f82e7dbecb6", "best_bid": "0.78", "best_ask": "0.79"}, {"asset_id": "65139230827417363158752884968303867495725894165574887635816574090175320800482", "price": "0.79", "size": "1998", "side": "SELL", "hash": "26404aa796e4cad6a3abd7946c9599d373d8bea2", "best_bid": "0.21", "best_ask": "0.22"}], "timestamp": "1769384288143", "event_type": "price_change"}}
{"_local_timestamp": "2026-01-25T23:38:08.273743+00:00", "data": {"market": "0xd5d9fc47718bd553592d126b1fa5e87183d27f3936975b0c04cc0f2dec1f1bb4", "price_changes": [{"asset_id": "33156410999665902694791064431724433042010245771106314074312009703157423879038", "price": "0.2", "size": "13262.03", "side": "BUY", "hash": "29ed404338b8a1e44809103188b4418d6879c495", "best_bid": "0.2", "best_ask": "0.22"}, {"asset_id": "83247781037352156539108067944461291821683755894607244160607042790356561625563", "price": "0.8", "size": "13262.03", "side": "SELL", "hash": "f9bc842818637805eb466974ead262cf8d16d2fa", "best_bid": "0.78", "best_ask": "0.8"}], "timestamp": "1769384288200", "event_type": "price_change"}}
{"_local_timestamp": "2026-01-25T23:38:08.289264+00:00", "data": {"market": "0x4e4f77e7dbf4cab666e9a1943674d7ae66348e862df03ea6f44b11eb95731928", "price_changes": [{"asset_id": "17371217118862125782438074585166210555214661810823929795910191856905580975576", "price": "0.77", "size": "18855.16", "side": "BUY", "hash": "dc1134c5988ca632002ac4af029becf3bacc7061", "best_bid": "0.78", "best_ask": "0.79"}, {"asset_id": "65139230827417363158752884968303867495725894165574887635816574090175320800482", "price": "0.23", "size": "18855.16", "side": "SELL", "hash": "808b57ed5cb7a80e0af34a59d20fab1323b08514", "best_bid": "0.21", "best_ask": "0.22"}], "timestamp": "1769384288222", "event_type": "price_change"}}
{"_local_timestamp": "2026-01-25T23:38:08.466283+00:00", "data": {"market": "0xd5d9fc47718bd553592d126b1fa5e87183d27f3936975b0c04cc0f2dec1f1bb4", "price_changes": [{"asset_id": "33156410999665902694791064431724433042010245771106314074312009703157423879038", "price": "0.2", "size": "11367.1", "side": "BUY", "hash": "bec4d9acf4a2ef154e263128b948637c679f2c79", "best_bid": "0.2", "best_ask": "0.22"}, {"asset_id": "83247781037352156539108067944461291821683755894607244160607042790356561625563", "price": "0.8", "size": "11367.1", "side": "SELL", "hash": "2180ac0a7aad5b34d5433283291a7d6600c66da1", "best_bid": "0.78", "best_ask": "0.8"}], "timestamp": "1769384288398", "event_type": "price_change"}}
{"_local_timestamp": "2026-01-25T23:38:08.746578+00:00", "data": {"market": "0x4e4f77e7dbf4cab666e9a1943674d7ae66348e862df03ea6f44b11eb95731928", "price_changes": [{"asset_id": "17371217118862125782438074585166210555214661810823929795910191856905580975576", "price": "0.77", "size": "16960.23", "side": "BUY", "hash": "f8ecfdab0ce15921b8698c23bf913c9f074ee52c", "best_bid": "0.78", "best_ask": "0.79"}, {"asset_id": "65139230827417363158752884968303867495725894165574887635816574090175320800482", "price": "0.23", "size": "16960.23", "side": "SELL", "hash": "005b7ab25f9d19248ede2e3b7783dd1d44ec13c8", "best_bid": "0.21", "best_ask": "0.22"}], "timestamp": "1769384288632", "event_type": "price_change"}}
{"_local_timestamp": "2026-01-25T23:38:35.736396+00:00", "data": {"market": "0x4e4f77e7dbf4cab666e9a1943674d7ae66348e862df03ea6f44b11eb95731928", "price_changes": [{"asset_id": "65139230827417363158752884968303867495725894165574887635816574090175320800482", "price": "0.21", "size": "30784", "side": "BUY", "hash": "4f3d320f24e829aba3b6ad6d0a9da7f59d0524d1", "best_bid": "0.21", "best_ask": "0.22"}, {"asset_id": "17371217118862125782438074585166210555214661810823929795910191856905580975576", "price": "0.79", "size": "30784", "side": "SELL", "hash": "3af2b72759b905717411ee5ea6e71b14a50b8621", "best_bid": "0.78", "best_ask": "0.79"}], "timestamp": "1769384315669", "event_type": "price_change"}}
{"_local_timestamp": "2026-01-25T23:38:35.777244+00:00", "data": {"market": "0x4e4f77e7dbf4cab666e9a1943674d7ae66348e862df03ea6f44b11eb95731928", "price_changes": [{"asset_id": "65139230827417363158752884968303867495725894165574887635816574090175320800482", "price": "0.21", "size": "30984", "side": "BUY", "hash": "47f28820621b2179c1cf1f9dcbb7ed54055225e1", "best_bid": "0.21", "best_ask": "0.22"}, {"asset_id": "17371217118862125782438074585166210555214661810823929795910191856905580975576", "price": "0.79", "size": "30984", "side": "SELL", "hash": "222cd2426f23681368519cd6e0e3c65ad71226ce", "best_bid": "0.78", "best_ask": "0.79"}], "timestamp": "1769384315701", "event_type": "price_change"}}
{"_local_timestamp": "2026-01-25T23:38:35.792962+00:00", "data": {"market": "0x4e4f77e7dbf4cab666e9a1943674d7ae66348e862df03ea6f44b11eb95731928", "price_changes": [{"asset_id": "17371217118862125782438074585166210555214661810823929795910191856905580975576", "price": "0.76", "size": "3800", "side": "BUY", "hash": "4bbf5284796c987bd714d8c08a2413e898461f7b", "best_bid": "0.78", "best_ask": "0.79"}, {"asset_id": "65139230827417363158752884968303867495725894165574887635816574090175320800482", "price": "0.24", "size": "3800", "side": "SELL", "hash": "b25b1396168b8c7b877eeb6aaa5949a4b1b9d161", "best_bid": "0.21", "best_ask": "0.22"}], "timestamp": "1769384315724", "event_type": "price_change"}}
{"_local_timestamp": "2026-01-25T23:38:35.832727+00:00", "data": {"market": "0x4e4f77e7dbf4cab666e9a1943674d7ae66348e862df03ea6f44b11eb95731928", "price_changes": [{"asset_id": "17371217118862125782438074585166210555214661810823929795910191856905580975576", "price": "0.76", "size": "4000", "side": "BUY", "hash": "9d4d10f03805468aa32ddf3377a9d7653cdb1aaa", "best_bid": "0.78", "best_ask": "0.79"}, {"asset_id": "65139230827417363158752884968303867495725894165574887635816574090175320800482", "price": "0.24", "size": "4000", "side": "SELL", "hash": "329ce4c8ca63dde34fe3085e391b56037a93501d", "best_bid": "0.21", "best_ask": "0.22"}], "timestamp": "1769384315756", "event_type": "price_change"}}
{"_local_timestamp": "2026-01-25T23:38:36.233830+00:00", "data": {"market": "0x4e4f77e7dbf4cab666e9a1943674d7ae66348e862df03ea6f44b11eb95731928", "price_changes": [{"asset_id": "17371217118862125782438074585166210555214661810823929795910191856905580975576", "price": "0.75", "size": "3522.12", "side": "BUY", "hash": "355103e569223e972d34d5e6ce8ba83dd5953caf", "best_bid": "0.78", "best_ask": "0.79"}, {"asset_id": "65139230827417363158752884968303867495725894165574887635816574090175320800482", "price": "0.25", "size": "3522.12", "side": "SELL", "hash": "ce6d829ca440498942643fb1adac2a2cf00a2d9d", "best_bid": "0.21", "best_ask": "0.22"}], "timestamp": "1769384316161", "event_type": "price_change"}}
{"_local_timestamp": "2026-01-25T23:38:36.240915+00:00", "data": {"market": "0x4e4f77e7dbf4cab666e9a1943674d7ae66348e862df03ea6f44b11eb95731928", "price_changes": [{"asset_id": "17371217118862125782438074585166210555214661810823929795910191856905580975576", "price": "0.75", "size": "4522.12", "side": "BUY", "hash": "98488363a5ae3ac91026bc65c15d3af8d4a0be07", "best_bid": "0.78", "best_ask": "0.79"}, {"asset_id": "65139230827417363158752884968303867495725894165574887635816574090175320800482", "price": "0.25", "size": "4522.12", "side": "SELL", "hash": "11d62df7c5d087c9bf6c31e4dad3c4a28bf1c823", "best_bid": "0.21", "best_ask": "0.22"}], "timestamp": "1769384316170", "event_type": "price_change"}}
{"_local_timestamp": "2026-01-25T23:38:38.844545+00:00", "data": {"market": "0xd5d9fc47718bd553592d126b1fa5e87183d27f3936975b0c04cc0f2dec1f1bb4", "price_changes": [{"asset_id": "83247781037352156539108067944461291821683755894607244160607042790356561625563", "price": "0.75", "size": "13936.93", "side": "BUY", "hash": "d7e472a7686ab87290d30e6c7d8d083f52e4ba78", "best_bid": "0.78", "best_ask": "0.8"}, {"asset_id": "33156410999665902694791064431724433042010245771106314074312009703157423879038", "price": "0.25", "size": "13936.93", "side": "SELL", "hash": "5e65ee32290c1bae7bdb3caccc9362e97d5f39c7", "best_bid": "0.2", "best_ask": "0.22"}], "timestamp": "1769384318772", "event_type": "price_change"}}
{"_local_timestamp": "2026-01-25T23:38:38.859134+00:00", "data": {"market": "0xd5d9fc47718bd553592d126b1fa5e87183d27f3936975b0c04cc0f2dec1f1bb4", "price_changes": [{"asset_id": "83247781037352156539108067944461291821683755894607244160607042790356561625563", "price": "0.75", "size": "14936.93", "side": "BUY", "hash": "f3c63a8b9efb7ae2d8773a54e78b63f50fcf8f75", "best_bid": "0.78", "best_ask": "0.8"}, {"asset_id": "33156410999665902694791064431724433042010245771106314074312009703157423879038", "price": "0.25", "size": "14936.93", "side": "SELL", "hash": "df7dbe74c234b422f2468be0b9330172e1d25263", "best_bid": "0.2", "best_ask": "0.22"}], "timestamp": "1769384318788", "event_type": "price_change"}}
{"_local_timestamp": "2026-01-25T23:38:38.885711+00:00", "data": {"market": "0x4e4f77e7dbf4cab666e9a1943674d7ae66348e862df03ea6f44b11eb95731928", "price_changes": [{"asset_id": "17371217118862125782438074585166210555214661810823929795910191856905580975576", "price": "0.77", "size": "18771.67", "side": "BUY", "hash": "22efcce366d8a1a4b2e48d60f8bdbb944cbeb05b", "best_bid": "0.78", "best_ask": "0.79"}, {"asset_id": "65139230827417363158752884968303867495725894165574887635816574090175320800482", "price": "0.23", "size": "18771.67", "side": "SELL", "hash": "54a0c277f28d4dde892d49f85a709d0c1e0f159c", "best_bid": "0.21", "best_ask": "0.22"}], "timestamp": "1769384318811", "event_type": "price_change"}}
{"_local_timestamp": "2026-01-25T23:38:38.902785+00:00", "data": {"market": "0xd5d9fc47718bd553592d126b1fa5e87183d27f3936975b0c04cc0f2dec1f1bb4", "price_changes": [{"asset_id": "33156410999665902694791064431724433042010245771106314074312009703157423879038", "price": "0.2", "size": "13178.54", "side": "BUY", "hash": "5956e311d3fcf86eea4e5e8db64dab443749eb43", "best_bid": "0.2", "best_ask": "0.22"}, {"asset_id": "83247781037352156539108067944461291821683755894607244160607042790356561625563", "price": "0.8", "size": "13178.54", "side": "SELL", "hash": "7d3c13cf77df48829e981632ad93a8fb091644b9", "best_bid": "0.78", "best_ask": "0.8"}], "timestamp": "1769384318830", "event_type": "price_change"}}
{"_local_timestamp": "2026-01-25T23:38:39.158199+00:00", "data": {"market": "0xd5d9fc47718bd553592d126b1fa5e87183d27f3936975b0c04cc0f2dec1f1bb4", "price_changes": [{"asset_id": "33156410999665902694791064431724433042010245771106314074312009703157423879038", "price": "0.2", "size": "11367.1", "side": "BUY", "hash": "db84a9daf1e84ced7d1da2eab5291bda094e19c5", "best_bid": "0.2", "best_ask": "0.22"}, {"asset_id": "83247781037352156539108067944461291821683755894607244160607042790356561625563", "price": "0.8", "size": "11367.1", "side": "SELL", "hash": "011795fcca2bf02b7b4b56e74c8edcb300de0fb5", "best_bid": "0.78", "best_ask": "0.8"}], "timestamp": "1769384319023", "event_type": "price_change"}}
{"_local_timestamp": "2026-01-25T23:38:39.165103+00:00", "data": {"market": "0x4e4f77e7dbf4cab666e9a1943674d7ae66348e862df03ea6f44b11eb95731928", "price_changes": [{"asset_id": "17371217118862125782438074585166210555214661810823929795910191856905580975576", "price": "0.77", "size": "16960.23", "side": "BUY", "hash": "9e1d30b64ac3c4e502697ff06184f2f6c9bc32e7", "best_bid": "0.78", "best_ask": "0.79"}, {"asset_id": "65139230827417363158752884968303867495725894165574887635816574090175320800482", "price": "0.23", "size": "16960.23", "side": "SELL", "hash": "4f6f7b4758456c6990a749127678dae35a19642a", "best_bid": "0.21", "best_ask": "0.22"}], "timestamp": "1769384319023", "event_type": "price_change"}}
{"_local_timestamp": "2026-01-25T23:38:50.925334+00:00", "data": {"market": "0xd5d9fc47718bd553592d126b1fa5e87183d27f3936975b0c04cc0f2dec1f1bb4", "price_changes": [{"asset_id": "83247781037352156539108067944461291821683755894607244160607042790356561625563", "price": "0.77", "size": "41395.01", "side": "BUY", "hash": "56b0584abd47ec3615f1ad0b56e46043c8acec30", "best_bid": "0.78", "best_ask": "0.8"}, {"asset_id": "33156410999665902694791064431724433042010245771106314074312009703157423879038", "price": "0.23", "size": "41395.01", "side": "SELL", "hash": "89523490e338be4f5626cf2eb5d1eb571ac88010", "best_bid": "0.2", "best_ask": "0.22"}], "timestamp": "1769384330852", "event_type": "price_change"}}
{"_local_timestamp": "2026-01-25T23:38:50.953329+00:00", "data": {"market": "0xd5d9fc47718bd553592d126b1fa5e87183d27f3936975b0c04cc0f2dec1f1bb4", "price_changes": [{"asset_id": "83247781037352156539108067944461291821683755894607244160607042790356561625563", "price": "0.77", "size": "41595.01", "side": "BUY", "hash": "6d22961ff09ee6788920318d942431b31e05d6a1", "best_bid": "0.78", "best_ask": "0.8"}, {"asset_id": "33156410999665902694791064431724433042010245771106314074312009703157423879038", "price": "0.23", "size": "41595.01", "side": "SELL", "hash": "700a2fd81c9b2d15c58a7125db5baa1a4dca81b4", "best_bid": "0.2", "best_ask": "0.22"}], "timestamp": "1769384330884", "event_type": "price_change"}}
{"_local_timestamp": "2026-01-25T23:38:50.996797+00:00", "data": {"market": "0xd5d9fc47718bd553592d126b1fa5e87183d27f3936975b0c04cc0f2dec1f1bb4", "price_changes": [{"asset_id": "33156410999665902694791064431724433042010245771106314074312009703157423879038", "price": "0.2", "size": "11167.1", "side": "BUY", "hash": "db594d87795e5053b6fc4cb7ee05fd9292ac0a82", "best_bid": "0.2", "best_ask": "0.22"}, {"asset_id": "83247781037352156539108067944461291821683755894607244160607042790356561625563", "price": "0.8", "size": "11167.1", "side": "SELL", "hash": "6b06600c14cea6ac1aee7317c8ed06e137ff4629", "best_bid": "0.78", "best_ask": "0.8"}], "timestamp": "1769384330913", "event_type": "price_change"}}
{"_local_timestamp": "2026-01-25T23:38:51.028030+00:00", "data": {"market": "0xd5d9fc47718bd553592d126b1fa5e87183d27f3936975b0c04cc0f2dec1f1bb4", "price_changes": [{"asset_id": "33156410999665902694791064431724433042010245771106314074312009703157423879038", "price": "0.2", "size": "11367.1", "side": "BUY", "hash": "d05e668b2bf15e2861594e9004d2b204d6afa2f0", "best_bid": "0.2", "best_ask": "0.22"}, {"asset_id": "83247781037352156539108067944461291821683755894607244160607042790356561625563", "price": "0.8", "size": "11367.1", "side": "SELL", "hash": "d88a39684330d2672d36e96caef9eeb6afa09a76", "best_bid": "0.78", "best_ask": "0.8"}], "timestamp": "1769384330944", "event_type": "price_change"}}
{"_local_timestamp": "2026-01-25T23:39:20.470733+00:00", "data": {"market": "0x4e4f77e7dbf4cab666e9a1943674d7ae66348e862df03ea6f44b11eb95731928", "price_changes": [{"asset_id": "17371217118862125782438074585166210555214661810823929795910191856905580975576", "price": "0.21", "size": "0", "side": "BUY", "hash": "715964a5f3fef060d74de5162995fd0228255e6b", "best_bid": "0.78", "best_ask": "0.79"}, {"asset_id": "65139230827417363158752884968303867495725894165574887635816574090175320800482", "price": "0.79", "size": "0", "side": "SELL", "hash": "fc4db22bb10256d2f90c3e25a84d8eddce368e03", "best_bid": "0.21", "best_ask": "0.22"}], "timestamp": "1769384360340", "event_type": "price_change"}}
{"_local_timestamp": "2026-01-25T23:39:20.724072+00:00", "data": {"market": "0x4e4f77e7dbf4cab666e9a1943674d7ae66348e862df03ea6f44b11eb95731928", "price_changes": [{"asset_id": "65139230827417363158752884968303867495725894165574887635816574090175320800482", "price": "0.21", "size": "30784", "side": "BUY", "hash": "80c8b781a65735f4752fdb8a7bbcea99354fe7ee", "best_bid": "0.21", "best_ask": "0.22"}, {"asset_id": "17371217118862125782438074585166210555214661810823929795910191856905580975576", "price": "0.79", "size": "30784", "side": "SELL", "hash": "d3037281792aceff00f353d9e1634ed67aa16a9b", "best_bid": "0.78", "best_ask": "0.79"}], "timestamp": "1769384360614", "event_type": "price_change"}}
{"_local_timestamp": "2026-01-25T23:39:20.746723+00:00", "data": {"market": "0x4e4f77e7dbf4cab666e9a1943674d7ae66348e862df03ea6f44b11eb95731928", "price_changes": [{"asset_id": "65139230827417363158752884968303867495725894165574887635816574090175320800482", "price": "0.21", "size": "30984", "side": "BUY", "hash": "d570904031342b641d2f98c6ec5a365395051acc", "best_bid": "0.21", "best_ask": "0.22"}, {"asset_id": "17371217118862125782438074585166210555214661810823929795910191856905580975576", "price": "0.79", "size": "30984", "side": "SELL", "hash": "5847be143c29b37ece82398e2047d80ff145c26f", "best_bid": "0.78", "best_ask": "0.79"}], "timestamp": "1769384360647", "event_type": "price_change"}}
{"_local_timestamp": "2026-01-25T23:39:20.758370+00:00", "data": {"market": "0x4e4f77e7dbf4cab666e9a1943674d7ae66348e862df03ea6f44b11eb95731928", "price_changes": [{"asset_id": "17371217118862125782438074585166210555214661810823929795910191856905580975576", "price": "0.76", "size": "3800", "side": "BUY", "hash": "650681e7a77a5f09249e61b4ea11e2bb8761fe2b", "best_bid": "0.78", "best_ask": "0.79"}, {"asset_id": "65139230827417363158752884968303867495725894165574887635816574090175320800482", "price": "0.24", "size": "3800", "side": "SELL", "hash": "34768fe7e2515b26a11847061987d4720b8febf5", "best_bid": "0.21", "best_ask": "0.22"}], "timestamp": "1769384360671", "event_type": "price_change"}}
{"_local_timestamp": "2026-01-25T23:39:20.768326+00:00", "data": {"market": "0x4e4f77e7dbf4cab666e9a1943674d7ae66348e862df03ea6f44b11eb95731928", "price_changes": [{"asset_id": "17371217118862125782438074585166210555214661810823929795910191856905580975576", "price": "0.76", "size": "4000", "side": "BUY", "hash": "cde0446737736e80e2a5a3f5a41f6c36f7565a4c", "best_bid": "0.78", "best_ask": "0.79"}, {"asset_id": "65139230827417363158752884968303867495725894165574887635816574090175320800482", "price": "0.24", "size": "4000", "side": "SELL", "hash": "ae3334cbea2386dafd39ae1f56d148cf57340e96", "best_bid": "0.21", "best_ask": "0.22"}], "timestamp": "1769384360701", "event_type": "price_change"}}
{"_local_timestamp": "2026-01-25T23:39:36.133162+00:00", "data": {"market": "0xd5d9fc47718bd553592d126b1fa5e87183d27f3936975b0c04cc0f2dec1f1bb4", "price_changes": [{"asset_id": "83247781037352156539108067944461291821683755894607244160607042790356561625563", "price": "0.77", "size": "41395.01", "side": "BUY", "hash": "0c5da83019ddb39f3fedbf96688fac6b349540ba", "best_bid": "0.78", "best_ask": "0.8"}, {"asset_id": "33156410999665902694791064431724433042010245771106314074312009703157423879038", "price": "0.23", "size": "41395.01", "side": "SELL", "hash": "29778193716dddf835a73e7b7f61075b660bdf32", "best_bid": "0.2", "best_ask": "0.22"}], "timestamp": "1769384376064", "event_type": "price_change"}}
{"_local_timestamp": "2026-01-25T23:39:36.177767+00:00", "data": {"market": "0xd5d9fc47718bd553592d126b1fa5e87183d27f3936975b0c04cc0f2dec1f1bb4", "price_changes": [{"asset_id": "83247781037352156539108067944461291821683755894607244160607042790356561625563", "price": "0.77", "size": "41595.01", "side": "BUY", "hash": "b8cb44461c7c805b5965e0b5096281850220f686", "best_bid": "0.78", "best_ask": "0.8"}, {"asset_id": "33156410999665902694791064431724433042010245771106314074312009703157423879038", "price": "0.23", "size": "41595.01", "side": "SELL", "hash": "feca5ac6ecfea07c3e944bd8d5d8590e7fcdbaea", "best_bid": "0.2", "best_ask": "0.22"}], "timestamp": "1769384376103", "event_type": "price_change"}}
{"_local_timestamp": "2026-01-25T23:39:36.194978+00:00", "data": {"market": "0xd5d9fc47718bd553592d126b1fa5e87183d27f3936975b0c04cc0f2dec1f1bb4", "price_changes": [{"asset_id": "33156410999665902694791064431724433042010245771106314074312009703157423879038", "price": "0.2", "size": "13325.06", "side": "BUY", "hash": "32c0c1921e65d2f785e7d9af948a2f92cd29d044", "best_bid": "0.2", "best_ask": "0.22"}, {"asset_id": "83247781037352156539108067944461291821683755894607244160607042790356561625563", "price": "0.8", "size": "13325.06", "side": "SELL", "hash": "057eb29cb1c708dd93594aa3c07c417527be43c7", "best_bid": "0.78", "best_ask": "0.8"}], "timestamp": "1769384376120", "event_type": "price_change"}}
{"_local_timestamp": "2026-01-25T23:39:36.200665+00:00", "data": {"market": "0xd5d9fc47718bd553592d126b1fa5e87183d27f3936975b0c04cc0f2dec1f1bb4", "price_changes": [{"asset_id": "33156410999665902694791064431724433042010245771106314074312009703157423879038", "price": "0.2", "size": "13125.06", "side": "BUY", "hash": "8311f7d8cebf52e7a625e1c0b76955363b1636e3", "best_bid": "0.2", "best_ask": "0.22"}, {"asset_id": "83247781037352156539108067944461291821683755894607244160607042790356561625563", "price": "0.8", "size": "13125.06", "side": "SELL", "hash": "164a8a8352dbafab3579e8b1fa80c46372a482a3", "best_bid": "0.78", "best_ask": "0.8"}], "timestamp": "1769384376129", "event_type": "price_change"}}
{"_local_timestamp": "2026-01-25T23:39:36.201044+00:00", "data": {"market": "0x4e4f77e7dbf4cab666e9a1943674d7ae66348e862df03ea6f44b11eb95731928", "price_changes": [{"asset_id": "17371217118862125782438074585166210555214661810823929795910191856905580975576", "price": "0.77", "size": "18918.19", "side": "BUY", "hash": "9a30917633d3e8bd9fed55a72d4a40a0fd9ffbe8", "best_bid": "0.78", "best_ask": "0.79"}, {"asset_id": "65139230827417363158752884968303867495725894165574887635816574090175320800482", "price": "0.23", "size": "18918.19", "side": "SELL", "hash": "60530558fd0b98bd38ce447165ccfb6b87f055e0", "best_bid": "0.21", "best_ask": "0.22"}], "timestamp": "1769384376131", "event_type": "price_change"}}
{"_local_timestamp": "2026-01-25T23:39:36.235296+00:00", "data": {"market": "0xd5d9fc47718bd553592d126b1fa5e87183d27f3936975b0c04cc0f2dec1f1bb4", "price_changes": [{"asset_id": "33156410999665902694791064431724433042010245771106314074312009703157423879038", "price": "0.2", "size": "13325.06", "side": "BUY", "hash": "b54ee0b32cd45456edb5b9b81f826e787f24ccd5", "best_bid": "0.2", "best_ask": "0.22"}, {"asset_id": "83247781037352156539108067944461291821683755894607244160607042790356561625563", "price": "0.8", "size": "13325.06", "side": "SELL", "hash": "55f7e46e423132c8373fb67f69a39fb56ef7b449", "best_bid": "0.78", "best_ask": "0.8"}], "timestamp": "1769384376165", "event_type": "price_change"}}
{"_local_timestamp": "2026-01-25T23:39:36.391786+00:00", "data": {"market": "0xd5d9fc47718bd553592d126b1fa5e87183d27f3936975b0c04cc0f2dec1f1bb4", "price_changes": [{"asset_id": "33156410999665902694791064431724433042010245771106314074312009703157423879038", "price": "0.2", "size": "11367.1", "side": "BUY", "hash": "92d7d10433fa31ab376dcd25de898f4ed9d14033", "best_bid": "0.2", "best_ask": "0.22"}, {"asset_id": "83247781037352156539108067944461291821683755894607244160607042790356561625563", "price": "0.8", "size": "11367.1", "side": "SELL", "hash": "7cfa20bd6e4f8808a9a657b2335d3525e7434fbc", "best_bid": "0.78", "best_ask": "0.8"}], "timestamp": "1769384376318", "event_type": "price_change"}}
{"_local_timestamp": "2026-01-25T23:39:36.392278+00:00", "data": {"market": "0x4e4f77e7dbf4cab666e9a1943674d7ae66348e862df03ea6f44b11eb95731928", "price_changes": [{"asset_id": "17371217118862125782438074585166210555214661810823929795910191856905580975576", "price": "0.77", "size": "16960.23", "side": "BUY", "hash": "04463d0d91e5f3acf271282173d9f75d233c269f", "best_bid": "0.78", "best_ask": "0.79"}, {"asset_id": "65139230827417363158752884968303867495725894165574887635816574090175320800482", "price": "0.23", "size": "16960.23", "side": "SELL", "hash": "4e2870e0c9e1fe425a3fa9e5c874c5101c16ecae", "best_bid": "0.21", "best_ask": "0.22"}], "timestamp": "1769384376318", "event_type": "price_change"}}
{"_local_timestamp": "2026-01-25T23:39:36.470496+00:00", "data": {"market": "0xd5d9fc47718bd553592d126b1fa5e87183d27f3936975b0c04cc0f2dec1f1bb4", "price_changes": [{"asset_id": "33156410999665902694791064431724433042010245771106314074312009703157423879038", "price": "0.2", "size": "13325.06", "side": "BUY", "hash": "aa7186c302e558b3f7d89c7def8d1acc513d5f7e", "best_bid": "0.2", "best_ask": "0.22"}, {"asset_id": "83247781037352156539108067944461291821683755894607244160607042790356561625563", "price": "0.8", "size": "13325.06", "side": "SELL", "hash": "60b076af1f67b5bff7ebde532501e746d4e2b799", "best_bid": "0.78", "best_ask": "0.8"}], "timestamp": "1769384376395", "event_type": "price_change"}}
{"_local_timestamp": "2026-01-25T23:39:36.653488+00:00", "data": {"market": "0xd5d9fc47718bd553592d126b1fa5e87183d27f3936975b0c04cc0f2dec1f1bb4", "price_changes": [{"asset_id": "33156410999665902694791064431724433042010245771106314074312009703157423879038", "price": "0.2", "size": "11367.1", "side": "BUY", "hash": "b40e6dcc8695961bf3707ffb1db3c4ffaf41cb5b", "best_bid": "0.2", "best_ask": "0.22"}, {"asset_id": "83247781037352156539108067944461291821683755894607244160607042790356561625563", "price": "0.8", "size": "11367.1", "side": "SELL", "hash": "0d8e7bfee893cb29419cc3f0c4f813633194e7f9", "best_bid": "0.78", "best_ask": "0.8"}], "timestamp": "1769384376583", "event_type": "price_change"}}
{"_local_timestamp": "2026-01-25T23:40:05.691935+00:00", "data": {"market": "0x4e4f77e7dbf4cab666e9a1943674d7ae66348e862df03ea6f44b11eb95731928", "price_changes": [{"asset_id": "65139230827417363158752884968303867495725894165574887635816574090175320800482", "price": "0.21", "size": "30784", "side": "BUY", "hash": "1624190444dfac235c6e7028411bad380d511360", "best_bid": "0.21", "best_ask": "0.22"}, {"asset_id": "17371217118862125782438074585166210555214661810823929795910191856905580975576", "price": "0.79", "size": "30784", "side": "SELL", "hash": "7d6e6a6958bca6a256e5de6537c83242f2c2f9ed", "best_bid": "0.78", "best_ask": "0.79"}], "timestamp": "1769384405622", "event_type": "price_change"}}
{"_local_timestamp": "2026-01-25T23:40:05.738208+00:00", "data": {"market": "0x4e4f77e7dbf4cab666e9a1943674d7ae66348e862df03ea6f44b11eb95731928", "price_changes": [{"asset_id": "65139230827417363158752884968303867495725894165574887635816574090175320800482", "price": "0.21", "size": "30984", "side": "BUY", "hash": "448afc4af26c5c1140aa12127a15c2b9fc4bc9d4", "best_bid": "0.21", "best_ask": "0.22"}, {"asset_id": "17371217118862125782438074585166210555214661810823929795910191856905580975576", "price": "0.79", "size": "30984", "side": "SELL", "hash": "fe809b586ed33f6e99e6ed775f4974172a4df9c4", "best_bid": "0.78", "best_ask": "0.79"}], "timestamp": "1769384405673", "event_type": "price_change"}}
{"_local_timestamp": "2026-01-25T23:40:05.767950+00:00", "data": {"market": "0x4e4f77e7dbf4cab666e9a1943674d7ae66348e862df03ea6f44b11eb95731928", "price_changes": [{"asset_id": "17371217118862125782438074585166210555214661810823929795910191856905580975576", "price": "0.76", "size": "3800", "side": "BUY", "hash": "83488ad54f27b762569206f7fc74a83f5279d11f", "best_bid": "0.78", "best_ask": "0.79"}, {"asset_id": "65139230827417363158752884968303867495725894165574887635816574090175320800482", "price": "0.24", "size": "3800", "side": "SELL", "hash": "ce03fdf597a2386ca4e81eababe54f3ec2518266", "best_bid": "0.21", "best_ask": "0.22"}], "timestamp": "1769384405698", "event_type": "price_change"}}
{"_local_timestamp": "2026-01-25T23:40:05.800062+00:00", "data": {"market": "0x4e4f77e7dbf4cab666e9a1943674d7ae66348e862df03ea6f44b11eb95731928", "price_changes": [{"asset_id": "17371217118862125782438074585166210555214661810823929795910191856905580975576", "price": "0.76", "size": "4000", "side": "BUY", "hash": "af1751afe6d1d7816fd6c245dd0610507b03c023", "best_bid": "0.78", "best_ask": "0.79"}, {"asset_id": "65139230827417363158752884968303867495725894165574887635816574090175320800482", "price": "0.24", "size": "4000", "side": "SELL", "hash": "6a97b454cc8f36ef3d37e7bcde0d2a3a7e3c4b6e", "best_bid": "0.21", "best_ask": "0.22"}], "timestamp": "1769384405733", "event_type": "price_change"}}
{"_local_timestamp": "2026-01-25T23:40:05.846543+00:00", "data": {"market": "0xd5d9fc47718bd553592d126b1fa5e87183d27f3936975b0c04cc0f2dec1f1bb4", "price_changes": [{"asset_id": "33156410999665902694791064431724433042010245771106314074312009703157423879038", "price": "0.21", "size": "20", "side": "BUY", "hash": "3a415d8c897b7e6c8995ce8f090248257c918f16", "best_bid": "0.21", "best_ask": "0.22"}, {"asset_id": "83247781037352156539108067944461291821683755894607244160607042790356561625563", "price": "0.79", "size": "20", "side": "SELL", "hash": "65206af146eb66a3535b5cfa888a6614748b6415", "best_bid": "0.78", "best_ask": "0.79"}], "timestamp": "1769384405779", "event_type": "price_change"}}
{"_local_timestamp": "2026-01-25T23:40:05.880848+00:00", "data": {"market": "0x4e4f77e7dbf4cab666e9a1943674d7ae66348e862df03ea6f44b11eb95731928", "price_changes": [{"asset_id": "17371217118862125782438074585166210555214661810823929795910191856905580975576", "price": "0.78", "size": "15939.84", "side": "BUY", "hash": "c1edbb078d37bb6bf6d60deeb2cfb15c1bbf1ee3", "best_bid": "0.78", "best_ask": "0.79"}, {"asset_id": "65139230827417363158752884968303867495725894165574887635816574090175320800482", "price": "0.22", "size": "15939.84", "side": "SELL", "hash": "ddb8963dafa2cc1106016d1671fe3ff1996d6e05", "best_bid": "0.21", "best_ask": "0.22"}], "timestamp": "1769384405808", "event_type": "price_change"}}
{"_local_timestamp": "2026-01-25T23:40:05.970655+00:00", "data": {"market": "0xd5d9fc47718bd553592d126b1fa5e87183d27f3936975b0c04cc0f2dec1f1bb4", "price_changes": [{"asset_id": "33156410999665902694791064431724433042010245771106314074312009703157423879038", "price": "0.19", "size": "12847.39", "side": "BUY", "hash": "fb5332766ab24ae847a4511ac986501e95afa80b", "best_bid": "0.21", "best_ask": "0.22"}, {"asset_id": "83247781037352156539108067944461291821683755894607244160607042790356561625563", "price": "0.81", "size": "12847.39", "side": "SELL", "hash": "532cdc5d5826482ce9f5cb55e2ab6fcba5954e34", "best_bid": "0.78", "best_ask": "0.79"}], "timestamp": "1769384405902", "event_type": "price_change"}}
{"_local_timestamp": "2026-01-25T23:40:06.023580+00:00", "data": {"market": "0xd5d9fc47718bd553592d126b1fa5e87183d27f3936975b0c04cc0f2dec1f1bb4", "price_changes": [{"asset_id": "33156410999665902694791064431724433042010245771106314074312009703157423879038", "price": "0.2", "size": "11617.1", "side": "BUY", "hash": "559bc286c027c919f2de23b61217125a28e33df6", "best_bid": "0.21", "best_ask": "0.22"}, {"asset_id": "83247781037352156539108067944461291821683755894607244160607042790356561625563", "price": "0.8", "size": "11617.1", "side": "SELL", "hash": "a9700fbb1a64990cb2f1e5e248c379e3eed08d40", "best_bid": "0.78", "best_ask": "0.79"}], "timestamp": "1769384405954", "event_type": "price_change"}}
{"_local_timestamp": "2026-01-25T23:40:07.009399+00:00", "data": {"market": "0x4e4f77e7dbf4cab666e9a1943674d7ae66348e862df03ea6f44b11eb95731928", "price_changes": [{"asset_id": "65139230827417363158752884968303867495725894165574887635816574090175320800482", "price": "0.18", "size": "9320", "side": "BUY", "hash": "a4d53d0b3a80f67e6f0c847e4c98d8d3ceaad392", "best_bid": "0.21", "best_ask": "0.22"}, {"asset_id": "17371217118862125782438074585166210555214661810823929795910191856905580975576", "price": "0.82", "size": "9320", "side": "SELL", "hash": "2c6c56b61fd40431674585eb34298af6bef25b5c", "best_bid": "0.78", "best_ask": "0.79"}], "timestamp": "1769384406935", "event_type": "price_change"}}
{"_local_timestamp": "2026-01-25T23:40:07.055906+00:00", "data": {"market": "0xd5d9fc47718bd553592d126b1fa5e87183d27f3936975b0c04cc0f2dec1f1bb4", "price_changes": [{"asset_id": "33156410999665902694791064431724433042010245771106314074312009703157423879038", "price": "0.2", "size": "13575.06", "side": "BUY", "hash": "ac37c52824c1bacb9753626a2fbea9026ca1dceb", "best_bid": "0.21", "best_ask": "0.22"}, {"asset_id": "83247781037352156539108067944461291821683755894607244160607042790356561625563", "price": "0.8", "size": "13575.06", "side": "SELL", "hash": "fa4e032d47e9cc100861f924899643fb0f4f8385", "best_bid": "0.78", "best_ask": "0.79"}], "timestamp": "1769384406988", "event_type": "price_change"}}
{"_local_timestamp": "2026-01-25T23:40:07.073043+00:00", "data": {"market": "0x4e4f77e7dbf4cab666e9a1943674d7ae66348e862df03ea6f44b11eb95731928", "price_changes": [{"asset_id": "17371217118862125782438074585166210555214661810823929795910191856905580975576", "price": "0.77", "size": "18918.19", "side": "BUY", "hash": "e93a5e6b6e3465b21ea4c057532ec17aa8b15863", "best_bid": "0.78", "best_ask": "0.79"}, {"asset_id": "65139230827417363158752884968303867495725894165574887635816574090175320800482", "price": "0.23", "size": "18918.19", "side": "SELL", "hash": "34e2e3defcbc9209af54f6921afe6547173daff0", "best_bid": "0.21", "best_ask": "0.22"}], "timestamp": "1769384406999", "event_type": "price_change"}}
{"_local_timestamp": "2026-01-25T23:40:07.140205+00:00", "data": {"market": "0xd5d9fc47718bd553592d126b1fa5e87183d27f3936975b0c04cc0f2dec1f1bb4", "price_changes": [{"asset_id": "83247781037352156539108067944461291821683755894607244160607042790356561625563", "price": "0.75", "size": "24936.93", "side": "BUY", "hash": "06cc854405a5d744c1d58ec98fc019aca4c81995", "best_bid": "0.78", "best_ask": "0.79"}, {"asset_id": "33156410999665902694791064431724433042010245771106314074312009703157423879038", "price": "0.25", "size": "24936.93", "side": "SELL", "hash": "41b190ff7d5b67d8e1f8df17cec979f566b39420", "best_bid": "0.21", "best_ask": "0.22"}], "timestamp": "1769384407012", "event_type": "price_change"}}
{"_local_timestamp": "2026-01-25T23:40:07.258239+00:00", "data": {"market": "0xd5d9fc47718bd553592d126b1fa5e87183d27f3936975b0c04cc0f2dec1f1bb4", "price_changes": [{"asset_id": "33156410999665902694791064431724433042010245771106314074312009703157423879038", "price": "0.2", "size": "11617.1", "side": "BUY", "hash": "3674696c141dcae025aea0362ded3a26f4c1b1bf", "best_bid": "0.21", "best_ask": "0.22"}, {"asset_id": "83247781037352156539108067944461291821683755894607244160607042790356561625563", "price": "0.8", "size": "11617.1", "side": "SELL", "hash": "499e272becf7986ad7376ab419503bd5b74b657d", "best_bid": "0.78", "best_ask": "0.79"}], "timestamp": "1769384407192", "event_type": "price_change"}}
{"_local_timestamp": "2026-01-25T23:40:07.258641+00:00", "data": {"market": "0x4e4f77e7dbf4cab666e9a1943674d7ae66348e862df03ea6f44b11eb95731928", "price_changes": [{"asset_id": "17371217118862125782438074585166210555214661810823929795910191856905580975576", "price": "0.77", "size": "16960.23", "side": "BUY", "hash": "8f77a6be808d8b757044bfa758bbbacf7b32ff20", "best_bid": "0.78", "best_ask": "0.79"}, {"asset_id": "65139230827417363158752884968303867495725894165574887635816574090175320800482", "price": "0.23", "size": "16960.23", "side": "SELL", "hash": "0d1be6f0297ff23bfd3e4bd78de714f8ed37ebdd", "best_bid": "0.21", "best_ask": "0.22"}], "timestamp": "1769384407192", "event_type": "price_change"}}
{"_local_timestamp": "2026-01-25T23:40:07.881754+00:00", "data": {"market": "0xd5d9fc47718bd553592d126b1fa5e87183d27f3936975b0c04cc0f2dec1f1bb4", "price_changes": [{"asset_id": "33156410999665902694791064431724433042010245771106314074312009703157423879038", "price": "0.18", "size": "955", "side": "BUY", "hash": "c3641714dfaf785aeb7b22c75c463e78151e02c0", "best_bid": "0.21", "best_ask": "0.22"}, {"asset_id": "83247781037352156539108067944461291821683755894607244160607042790356561625563", "price": "0.82", "size": "955", "side": "SELL", "hash": "4886dc45d6efdcac733434a8e30de3d23b887491", "best_bid": "0.78", "best_ask": "0.79"}], "timestamp": "1769384407814", "event_type": "price_change"}}
{"_local_timestamp": "2026-01-25T23:40:07.925085+00:00", "data": {"market": "0xd5d9fc47718bd553592d126b1fa5e87183d27f3936975b0c04cc0f2dec1f1bb4", "price_changes": [{"asset_id": "33156410999665902694791064431724433042010245771106314074312009703157423879038", "price": "0.2", "size": "13575.06", "side": "BUY", "hash": "ea7ba081823bea86f24a83d7b1583a96afa90e44", "best_bid": "0.21", "best_ask": "0.22"}, {"asset_id": "83247781037352156539108067944461291821683755894607244160607042790356561625563", "price": "0.8", "size": "13575.06", "side": "SELL", "hash": "efd377bc26738554d9a253b77760068f194aab93", "best_bid": "0.78", "best_ask": "0.79"}], "timestamp": "1769384407856", "event_type": "price_change"}}
{"_local_timestamp": "2026-01-25T23:40:07.929996+00:00", "data": {"market": "0x4e4f77e7dbf4cab666e9a1943674d7ae66348e862df03ea6f44b11eb95731928", "price_changes": [{"asset_id": "17371217118862125782438074585166210555214661810823929795910191856905580975576", "price": "0.77", "size": "18918.19", "side": "BUY", "hash": "252f717aef10e2f344117fe0ddf80144a34f3e8b", "best_bid": "0.78", "best_ask": "0.79"}, {"asset_id": "65139230827417363158752884968303867495725894165574887635816574090175320800482", "price": "0.23", "size": "18918.19", "side": "SELL", "hash": "09c0f5e3bd77f091dbdf0e90392ab6230ed995c9", "best_bid": "0.21", "best_ask": "0.22"}], "timestamp": "1769384407856", "event_type": "price_change"}}
{"_local_timestamp": "2026-01-25T23:40:08.028410+00:00", "data": {"market": "0xd5d9fc47718bd553592d126b1fa5e87183d27f3936975b0c04cc0f2dec1f1bb4", "price_changes": [{"asset_id": "33156410999665902694791064431724433042010245771106314074312009703157423879038", "price": "0.2", "size": "11617.1", "side": "BUY", "hash": "ab06b5ec47c414c198b94939dd05d621ae3d0b78", "best_bid": "0.21", "best_ask": "0.22"}, {"asset_id": "83247781037352156539108067944461291821683755894607244160607042790356561625563", "price": "0.8", "size": "11617.1", "side": "SELL", "hash": "655d2fa6ae7e174041b68f8d6c09a5add480878a", "best_bid": "0.78", "best_ask": "0.79"}], "timestamp": "1769384407948", "event_type": "price_change"}}
{"_local_timestamp": "2026-01-25T23:40:08.030520+00:00", "data": {"market": "0x4e4f77e7dbf4cab666e9a1943674d7ae66348e862df03ea6f44b11eb95731928", "price_changes": [{"asset_id": "17371217118862125782438074585166210555214661810823929795910191856905580975576", "price": "0.77", "size": "16960.23", "side": "BUY", "hash": "738e41a6ff75e54c481b33751e1bcb372e0fb015", "best_bid": "0.78", "best_ask": "0.79"}, {"asset_id": "65139230827417363158752884968303867495725894165574887635816574090175320800482", "price": "0.23", "size": "16960.23", "side": "SELL", "hash": "a6f62b5931fb9da69e352b8245c07d64d1b18eea", "best_bid": "0.21", "best_ask": "0.22"}], "timestamp": "1769384407948", "event_type": "price_change"}}
{"_local_timestamp": "2026-01-25T23:40:10.963920+00:00", "data": {"market": "0xd5d9fc47718bd553592d126b1fa5e87183d27f3936975b0c04cc0f2dec1f1bb4", "price_changes": [{"asset_id": "33156410999665902694791064431724433042010245771106314074312009703157423879038", "price": "0.19", "size": "13047.39", "side": "BUY", "hash": "b77baad1d85f2369c6a6251535b7d65e2bcaaf9b", "best_bid": "0.21", "best_ask": "0.22"}, {"asset_id": "83247781037352156539108067944461291821683755894607244160607042790356561625563", "price": "0.81", "size": "13047.39", "side": "SELL", "hash": "9e5d007abea1cf3240c8caaf831689c1c0aa481d", "best_bid": "0.78", "best_ask": "0.79"}], "timestamp": "1769384410887", "event_type": "price_change"}}
{"_local_timestamp": "2026-01-25T23:40:14.924046+00:00", "data": {"market": "0x4e4f77e7dbf4cab666e9a1943674d7ae66348e862df03ea6f44b11eb95731928", "price_changes": [{"asset_id": "17371217118862125782438074585166210555214661810823929795910191856905580975576", "price": "0.22", "size": "1908", "side": "BUY", "hash": "e8b25473c9277cbb06bb459acd8ba6b71411547b", "best_bid": "0.78", "best_ask": "0.79"}, {"asset_id": "65139230827417363158752884968303867495725894165574887635816574090175320800482", "price": "0.78", "size": "1908", "side": "SELL", "hash": "c350ea3f4ba1729542dcd772afc53eb022784372", "best_bid": "0.21", "best_ask": "0.22"}], "timestamp": "1769384414857", "event_type": "price_change"}}
{"_local_timestamp": "2026-01-25T23:40:14.963301+00:00", "data": {"market": "0xd5d9fc47718bd553592d126b1fa5e87183d27f3936975b0c04cc0f2dec1f1bb4", "price_changes": [{"asset_id": "33156410999665902694791064431724433042010245771106314074312009703157423879038", "price": "0.2", "size": "13575.06", "side": "BUY", "hash": "223b63beee1b5b18c3e84b985c3e28e63159c33a", "best_bid": "0.21", "best_ask": "0.22"}, {"asset_id": "83247781037352156539108067944461291821683755894607244160607042790356561625563", "price": "0.8", "size": "13575.06", "side": "SELL", "hash": "bb9bc04304f5a7c86c94801e272ce39b464c6995", "best_bid": "0.78", "best_ask": "0.79"}], "timestamp": "1769384414895", "event_type": "price_change"}}
{"_local_timestamp": "2026-01-25T23:40:14.963698+00:00", "data": {"market": "0x4e4f77e7dbf4cab666e9a1943674d7ae66348e862df03ea6f44b11eb95731928", "price_changes": [{"asset_id": "17371217118862125782438074585166210555214661810823929795910191856905580975576", "price": "0.77", "size": "18918.19", "side": "BUY", "hash": "a4341a22b495b6a030304900e9ef35d6b3a2a3d6", "best_bid": "0.78", "best_ask": "0.79"}, {"asset_id": "65139230827417363158752884968303867495725894165574887635816574090175320800482", "price": "0.23", "size": "18918.19", "side": "SELL", "hash": "610f4fcf4d08d75b75fc6da4e32775326a0b4641", "best_bid": "0.21", "best_ask": "0.22"}], "timestamp": "1769384414895", "event_type": "price_change"}}
{"_local_timestamp": "2026-01-25T23:40:15.125642+00:00", "data": {"market": "0x4e4f77e7dbf4cab666e9a1943674d7ae66348e862df03ea6f44b11eb95731928", "price_changes": [{"asset_id": "17371217118862125782438074585166210555214661810823929795910191856905580975576", "price": "0.77", "size": "16960.23", "side": "BUY", "hash": "4287b2a54589fe85e6637fd510a4e47fb3c9febf", "best_bid": "0.78", "best_ask": "0.79"}, {"asset_id": "65139230827417363158752884968303867495725894165574887635816574090175320800482", "price": "0.23", "size": "16960.23", "side": "SELL", "hash": "c6bcd4f760601fd6c8e616062fe8cc4b62097856", "best_bid": "0.21", "best_ask": "0.22"}], "timestamp": "1769384415058", "event_type": "price_change"}}
{"_local_timestamp": "2026-01-25T23:40:15.126058+00:00", "data": {"market": "0xd5d9fc47718bd553592d126b1fa5e87183d27f3936975b0c04cc0f2dec1f1bb4", "price_changes": [{"asset_id": "33156410999665902694791064431724433042010245771106314074312009703157423879038", "price": "0.2", "size": "11617.1", "side": "BUY", "hash": "807976672c29e89782e33db5fed64ac88a2904c5", "best_bid": "0.21", "best_ask": "0.22"}, {"asset_id": "83247781037352156539108067944461291821683755894607244160607042790356561625563", "price": "0.8", "size": "11617.1", "side": "SELL", "hash": "9d9f780d5aca8f81890ecf6f05b78193e48da893", "best_bid": "0.78", "best_ask": "0.79"}], "timestamp": "1769384415058", "event_type": "price_change"}}
{"_local_timestamp": "2026-01-25T23:40:15.264354+00:00", "data": {"market": "0x4e4f77e7dbf4cab666e9a1943674d7ae66348e862df03ea6f44b11eb95731928", "price_changes": [{"asset_id": "17371217118862125782438074585166210555214661810823929795910191856905580975576", "price": "0.77", "size": "18918.19", "side": "BUY", "hash": "e52eca90823148a7cb1758f7039ced370d5be86a", "best_bid": "0.78", "best_ask": "0.79"}, {"asset_id": "65139230827417363158752884968303867495725894165574887635816574090175320800482", "price": "0.23", "size": "18918.19", "side": "SELL", "hash": "6db181215b6d173db1c403b97a1ad83a0721e535", "best_bid": "0.21", "best_ask": "0.22"}], "timestamp": "1769384415190", "event_type": "price_change"}}
{"_local_timestamp": "2026-01-25T23:40:15.283962+00:00", "data": {"market": "0xd5d9fc47718bd553592d126b1fa5e87183d27f3936975b0c04cc0f2dec1f1bb4", "price_changes": [{"asset_id": "33156410999665902694791064431724433042010245771106314074312009703157423879038", "price": "0.2", "size": "13575.06", "side": "BUY", "hash": "7ec9d5622bb8af9054d337282adde9ee3137f376", "best_bid": "0.21", "best_ask": "0.22"}, {"asset_id": "83247781037352156539108067944461291821683755894607244160607042790356561625563", "price": "0.8", "size": "13575.06", "side": "SELL", "hash": "8f8f911e340fa5d695e3e9f392dd6669586ecd7c", "best_bid": "0.78", "best_ask": "0.79"}], "timestamp": "1769384415218", "event_type": "price_change"}}
{"_local_timestamp": "2026-01-25T23:40:15.460341+00:00", "data": {"market": "0xd5d9fc47718bd553592d126b1fa5e87183d27f3936975b0c04cc0f2dec1f1bb4", "price_changes": [{"asset_id": "33156410999665902694791064431724433042010245771106314074312009703157423879038", "price": "0.2", "size": "11617.1", "side": "BUY", "hash": "7849b58438fb3a2df8cc821dc357fddcffaf48f5", "best_bid": "0.21", "best_ask": "0.22"}, {"asset_id": "83247781037352156539108067944461291821683755894607244160607042790356561625563", "price": "0.8", "size": "11617.1", "side": "SELL", "hash": "e2885a711437736c82537ff4ee4268ba60074a0b", "best_bid": "0.78", "best_ask": "0.79"}], "timestamp": "1769384415389", "event_type": "price_change"}}
{"_local_timestamp": "2026-01-25T23:40:15.460769+00:00", "data": {"market": "0x4e4f77e7dbf4cab666e9a1943674d7ae66348e862df03ea6f44b11eb95731928", "price_changes": [{"asset_id": "17371217118862125782438074585166210555214661810823929795910191856905580975576", "price": "0.77", "size": "16960.23", "side": "BUY", "hash": "db5575add9e92124fd7fb983d8d511d8fc9fe5dc", "best_bid": "0.78", "best_ask": "0.79"}, {"asset_id": "65139230827417363158752884968303867495725894165574887635816574090175320800482", "price": "0.23", "size": "16960.23", "side": "SELL", "hash": "239bbffbe5ce668262b29336a8d36a88918c5e8c", "best_bid": "0.21", "best_ask": "0.22"}], "timestamp": "1769384415389", "event_type": "price_change"}}
