{"_local_timestamp": "2026-01-25T23:33:32.126049+00:00", "data": [{"market": "0xad1d3f37d4b3e994cf6e345342e4c6d77b847c125d222144c583ef5c4bd2f84a", "asset_id": "80861576758208246291858186808740958603555626246511495793257831406422094470572", "timestamp": "1769383924179", "hash": "cefb8ab82952d6a3b89463eae938c8a3e26af229", "bids": [{"price": "0.001", "size": "28538"}, {"price": "0.002", "size": "2742.63"}], "asks": [{"price": "0.999", "size": "116962.59"}, {"price": "0.998", "size": "27255.24"}, {"price": "0.997", "size": "1400"}, {"price": "0.996", "size": "9.09"}, {"price": "0.994", "size": "200"}, {"price": "0.99", "size": "3250"}, {"price": "0.989", "size": "9.17"}, {"price": "0.98", "size": "1750"}, {"price": "0.979", "size": "7000"}, {"price": "0.97", "size": "500"}, {"price": "0.969", "size": "6.1"}, {"price": "0.96", "size": "250"}, {"price": "0.95", "size": "30"}, {"price": "0.949", "size": "3639"}, {"price": "0.93", "size": "300"}, {"price": "0.929", "size": "7.22"}, {"price": "0.9", "size": "560"}, {"price": "0.899", "size": "180"}, {"price": "0.85", "size": "551.66"}, {"price": "0.8", "size": "460"}, {"price": "0.799", "size": "5.69"}, {"price": "0.75", "size": "262"}, {"price": "0.73", "size": "50"}, {"price": "0.7", "size": "86.66"}, {"price": "0.65", "size": "68.57"}, {"price": "0.6", "size": "175"}, {"price": "0.599", "size": "5"}, {"price": "0.238", "size": "378.06"}, {"price": "0.237", "size": "277"}, {"price": "0.236", "size": "10"}, {"price": "0.143", "size": "11.11"}, {"price": "0.141", "size": "20"}, {"price": "0.139", "size": "30"}, {"price": "0.138", "size": "20"}, {"price": "0.092", "size": "121.91"}, {"price": "0.038", "size": "700"}, {"price": "0.015", "size": "835.37"}, {"price": "0.013", "size": "417.35"}, {"price": "0.012", "size": "114.64"}, {"price": "0.009", "size": "190.94"}, {"price": "0.005", "size": "30"}], "event_type": "book", "last_trade_price": ""}, {"market": "0xc7982ab943183b14a136538b1943a99f0b783266c46647ac5d93a53145c1a7b5", "asset_id": "109831253762520485632120158952131204631888758680701510579735402842471158516644", "timestamp": "1769383924605", "hash": "b79a19ca0fff23dcc621500fbe819d67d3ebffc4", "bids": [{"price": "0.001", "size": "63538"}, {"price": "0.002", "size": "3403.72"}, {"price": "0.003", "size": "250"}, {"price": "0.006", "size": "1100"}], "asks": [{"price": "0.999", "size": "1107232.27"}, {"price": "0.998", "size": "21255.25"}, {"price": "0.997", "size": "1400"}, {"price": "0.996", "size": "10.39"}, {"price": "0.994", "size": "200"}, {"price": "0.99", "size": "3250"}, {"price": "0.989", "size": "6000"}, {"price": "0.988", "size": "7.99"}, {"price": "0.98", "size": "1750"}, {"price": "0.979", "size": "7000"}, {"price": "0.97", "size": "500"}, {"price": "0.969", "size": "6.1"}, {"price": "0.96", "size": "250"}, {"price": "0.95", "size": "330"}, {"price": "0.949", "size": "39"}, {"price": "0.93", "size": "300"}, {"price": "0.929", "size": "7.22"}, {"price": "0.9", "size": "560"}, {"price": "0.899", "size": "180"}, {"price": "0.85", "size": "551.66"}, {"price": "0.8", "size": "460"}, {"price": "0.799", "size": "5.69"}, {"price": "0.75", "size": "262"}, {"price": "0.73", "size": "50"}, {"price": "0.7", "size": "86.66"}, {"price": "0.66", "size": "50"}, {"price": "0.65", "size": "68.57"}, {"price": "0.6", "size": "50"}, {"price": "0.598", "size": "227"}, {"price": "0.597", "size": "5"}, {"price": "0.24", "size": "6.7"}, {"price": "0.18", "size": "6.7"}, {"price": "0.146", "size": "877.04"}, {"price": "0.145", "size": "61"}, {"price": "0.144", "size": "13.33"}, {"price": "0.142", "size": "10"}, {"price": "0.14", "size": "20"}, {"price": "0.139", "size": "30"}, {"price": "0.138", "size": "20"}, {"price": "0.059", "size": "877.04"}, {"price": "0.057", "size": "307.33"}, {"price": "0.018", "size": "94.9"}, {"price": "0.01", "size": "482.5"}], "event_type": "book", "last_trade_price": ""}, {"market": "0x9203a698f9fa14be61cfdb6bfef9deddd0aa7d2b2907d93a619702683087b3da", "asset_id": "78105936059580066886637010200879176612465407936158598378531832410898792072331", "timestamp": "1769383924179", "hash": "7c75873668ad5849215b50c657904ebb94414897", "bids": [{"price": "0.001", "size": "87962"}, {"price": "0.002", "size": "3837.12"}, {"price": "0.003", "size": "293"}], "asks": [{"price": "0.999", "size": "1107265.27"}, {"price": "0.998", "size": "67255.26"}, {"price": "0.997", "size": "1400"}, {"price": "0.996", "size": "10.4"}, {"price": "0.994", "size": "200"}, {"price": "0.99", "size": "3250"}, {"price": "0.989", "size": "6006"}, {"price": "0.988", "size": "8"}, {"price": "0.98", "size": "1750"}, {"price": "0.979", "size": "10000"}, {"price": "0.97", "size": "500"}, {"price": "0.969", "size": "6.11"}, {"price": "0.96", "size": "250"}, {"price": "0.95", "size": "330"}, {"price": "0.949", "size": "39"}, {"price": "0.93", "size": "300"}, {"price": "0.929", "size": "7.23"}, {"price": "0.9", "size": "560"}, {"price": "0.899", "size": "180"}, {"price": "0.85", "size": "551.66"}, {"price": "0.8", "size": "460"}, {"price": "0.799", "size": "5.68"}, {"price": "0.75", "size": "262"}, {"price": "0.73", "size": "50"}, {"price": "0.7", "size": "86.66"}, {"price": "0.65", "size": "68.57"}, {"price": "0.6", "size": "175"}, {"price": "0.432", "size": "440"}, {"price": "0.431", "size": "702"}, {"price": "0.43", "size": "5"}, {"price": "0.15", "size": "6.4"}, {"price": "0.146", "size": "203.5"}, {"price": "0.134", "size": "10"}, {"price": "0.132", "size": "20"}, {"price": "0.131", "size": "30"}, {"price": "0.13", "size": "20"}, {"price": "0.048", "size": "380"}, {"price": "0.034", "size": "800"}, {"price": "0.025", "size": "852.98"}, {"price": "0.024", "size": "48"}, {"price": "0.012", "size": "517.27"}, {"price": "0.011", "size": "69.94"}], "event_type": "book", "last_trade_price": "0.007"}, {"market": "0xdf3aed600715b8cc4a23e3d7e6caad79791de8dcd5af48f450dc1b8dc52128c3", "asset_id": "115200191337492844563805575089118887672911159979117742424196868043770660979378", "timestamp": "1769383921292", "hash": "b1afa3a6d13add31de0e70b4a9071f5795e8f859", "bids": [{"price": "0.001", "size": "3952.61"}, {"price": "0.002", "size": "1255.27"}, {"price": "0.003", "size": "1400"}, {"price": "0.004", "size": "9.14"}, {"price": "0.006", "size": "200"}, {"price": "0.01", "size": "117550"}, {"price": "0.011", "size": "9.22"}, {"price": "0.02", "size": "5750"}, {"price": "0.03", "size": "500"}, {"price": "0.031", "size": "6.13"}, {"price": "0.04", "size": "250"}, {"price": "0.05", "size": "930"}, {"price": "0.051", "size": "39"}, {"price": "0.07", "size": "300"}, {"price": "0.071", "size": "6.8"}, {"price": "0.1", "size": "560"}, {"price": "0.15", "size": "551.66"}, {"price": "0.19", "size": "418.42"}, {"price": "0.191", "size": "6.14"}, {"price": "0.24", "size": "316.66"}, {"price": "0.27", "size": "50"}, {"price": "0.29", "size": "89.65"}, {"price": "0.3", "size": "50"}, {"price": "0.34", "size": "70.58"}, {"price": "0.39", "size": "51.28"}, {"price": "0.395", "size": "5"}, {"price": "0.4", "size": "1050"}, {"price": "0.401", "size": "249"}, {"price": "0.402", "size": "277"}, {"price": "0.681", "size": "10"}, {"price": "0.685", "size": "20"}, {"price": "0.686", "size": "30"}, {"price": "0.687", "size": "20"}, {"price": "0.906", "size": "330.33"}, {"price": "0.907", "size": "114.12"}, {"price": "0.938", "size": "266.18"}, {"price": "0.939", "size": "36"}, {"price": "0.964", "size": "34.08"}], "asks": [{"price": "0.999", "size": "51304"}, {"price": "0.998", "size": "16166"}, {"price": "0.997", "size": "2009.11"}, {"price": "0.995", "size": "1000"}, {"price": "0.994", "size": "11.81"}, {"price": "0.99", "size": "2750"}, {"price": "0.988", "size": "1500"}, {"price": "0.987", "size": "250"}, {"price": "0.986", "size": "7.22"}, {"price": "0.98", "size": "700"}, {"price": "0.978", "size": "421.51"}, {"price": "0.973", "size": "261.61"}, {"price": "0.965", "size": "600"}], "event_type": "book", "last_trade_price": ""}, {"market": "0x5ed8142bfb7dedd29123c51d93e78d41bb11347a9dc99af028f8c26d379f7991", "asset_id": "21074627447851722982583017164862562903762903675957478566509692359288711223560", "timestamp": "1769383969962", "hash": "ef828aec32810bd0272bf7fb5d6b25ea281b5ef5", "bids": [{"price": "0.01", "size": "7550"}, {"price": "0.02", "size": "2400"}, {"price": "0.03", "size": "7.4"}, {"price": "0.05", "size": "1420"}, {"price": "0.07", "size": "985.71"}, {"price": "0.09", "size": "355.55"}, {"price": "0.1", "size": "200"}, {"price": "0.12", "size": "558.33"}, {"price": "0.13", "size": "166"}, {"price": "0.14", "size": "185.71"}, {"price": "0.16", "size": "400"}, {"price": "0.19", "size": "105.26"}, {"price": "0.25", "size": "200"}, {"price": "0.27", "size": "97.21"}, {"price": "0.32", "size": "200"}, {"price": "0.41", "size": "120"}, {"price": "0.42", "size": "90.95"}, {"price": "0.43", "size": "25.58"}, {"price": "0.47", "size": "1800"}, {"price": "0.48", "size": "37.16"}, {"price": "0.49", "size": "62.16"}, {"price": "0.51", "size": "37.16"}], "asks": [{"price": "0.99", "size": "116556.76"}, {"price": "0.98", "size": "1756.54"}, {"price": "0.97", "size": "7500"}, {"price": "0.96", "size": "857.57"}, {"price": "0.95", "size": "1030"}, {"price": "0.94", "size": "10"}, {"price": "0.92", "size": "625"}, {"price": "0.91", "size": "5.19"}, {"price": "0.9", "size": "238"}, {"price": "0.89", "size": "615.9"}, {"price": "0.88", "size": "16"}, {"price": "0.86", "size": "200"}, {"price": "0.83", "size": "402.94"}, {"price": "0.82", "size": "5.72"}, {"price": "0.81", "size": "126.31"}, {"price": "0.78", "size": "90.9"}, {"price": "0.75", "size": "15"}, {"price": "0.74", "size": "50"}, {"price": "0.68", "size": "250"}, {"price": "0.67", "size": "10"}, {"price": "0.65", "size": "15.11"}, {"price": "0.63", "size": "55.13"}, {"price": "0.62", "size": "28.94"}, {"price": "0.6", "size": "900"}, {"price": "0.58", "size": "170"}, {"price": "0.55", "size": "650"}, {"price": "0.54", "size": "200"}], "event_type": "book", "last_trade_price": ""}, {"market": "0x4a0cc84209df8e25f2651148c15ca45841bf02133903a990ad2be56d8337efe5", "asset_id": "102020588502400806287117347702632611550727753557718799166708590001374539810273", "timestamp": "1769383946856", "hash": "75e7129d0f80f66b886a841d983d63d09a024d2b", "bids": [{"price": "0.01", "size": "116555.42"}, {"price": "0.02", "size": "1755.33"}, {"price": "0.03", "size": "4500"}, {"price": "0.04", "size": "244.05"}, {"price": "0.05", "size": "300"}, {"price": "0.07", "size": "1014.28"}, {"price": "0.09", "size": "5.48"}, {"price": "0.11", "size": "804.09"}, {"price": "0.15", "size": "213.33"}, {"price": "0.19", "size": "397.36"}, {"price": "0.2", "size": "10"}, {"price": "0.21", "size": "5.23"}, {"price": "0.23", "size": "263.04"}, {"price": "0.26", "size": "99.78"}, {"price": "0.3", "size": "66.66"}, {"price": "0.33", "size": "550"}, {"price": "0.34", "size": "50"}, {"price": "0.41", "size": "131.42"}, {"price": "0.42", "size": "10"}, {"price": "0.58", "size": "5"}, {"price": "0.6", "size": "1014.98"}, {"price": "0.61", "size": "155.45"}, {"price": "0.62", "size": "30"}, {"price": "0.63", "size": "85.63"}, {"price": "0.64", "size": "17.18"}, {"price": "0.66", "size": "199.09"}, {"price": "0.67", "size": "69"}, {"price": "0.68", "size": "50"}, {"price": "0.69", "size": "6"}, {"price": "0.71", "size": "30"}], "asks": [{"price": "0.99", "size": "3005"}, {"price": "0.98", "size": "505"}, {"price": "0.97", "size": "307.4"}, {"price": "0.94", "size": "200"}, {"price": "0.92", "size": "250"}, {"price": "0.91", "size": "100"}, {"price": "0.9", "size": "6"}, {"price": "0.85", "size": "150"}, {"price": "0.83", "size": "6"}, {"price": "0.82", "size": "100"}, {"price": "0.81", "size": "13.31"}, {"price": "0.8", "size": "65"}, {"price": "0.79", "size": "27.93"}, {"price": "0.78", "size": "160.38"}, {"price": "0.77", "size": "6"}, {"price": "0.75", "size": "36"}], "event_type": "book", "last_trade_price": "0.220"}, {"market": "0xb5f410ce6db52b387d5e3c9aa386f1cf2c6d9603d4ffbb59d7b3ad78c6ce54bc", "asset_id": "90311555114079332121873713225331719655517167698979277482922143777516026157644", "timestamp": "1769383924451", "hash": "67a0d8a643ce3c428d385ecfee761d2495cfa82e", "bids": [{"price": "0.001", "size": "53488"}, {"price": "0.002", "size": "250"}, {"price": "0.003", "size": "1000"}, {"price": "0.004", "size": "397"}, {"price": "0.008", "size": "125"}], "asks": [{"price": "0.999", "size": "1107271.07"}, {"price": "0.998", "size": "16255.25"}, {"price": "0.997", "size": "1400"}, {"price": "0.996", "size": "10.4"}, {"price": "0.994", "size": "200"}, {"price": "0.99", "size": "3250"}, {"price": "0.989", "size": "6000"}, {"price": "0.988", "size": "7.99"}, {"price": "0.98", "size": "1750"}, {"price": "0.979", "size": "4000"}, {"price": "0.97", "size": "500"}, {"price": "0.969", "size": "6.11"}, {"price": "0.96", "size": "250"}, {"price": "0.95", "size": "330"}, {"price": "0.949", "size": "39"}, {"price": "0.93", "size": "300"}, {"price": "0.929", "size": "7.22"}, {"price": "0.9", "size": "560"}, {"price": "0.899", "size": "180"}, {"price": "0.85", "size": "551.66"}, {"price": "0.8", "size": "460"}, {"price": "0.799", "size": "5.69"}, {"price": "0.75", "size": "262"}, {"price": "0.73", "size": "50"}, {"price": "0.7", "size": "86.66"}, {"price": "0.65", "size": "68.57"}, {"price": "0.6", "size": "175"}, {"price": "0.494", "size": "977"}, {"price": "0.487", "size": "5"}, {"price": "0.16", "size": "5"}, {"price": "0.14", "size": "5"}, {"price": "0.137", "size": "33.39"}, {"price": "0.135", "size": "589.24"}, {"price": "0.134", "size": "10"}, {"price": "0.132", "size": "50"}, {"price": "0.131", "size": "20"}, {"price": "0.068", "size": "24.99"}, {"price": "0.067", "size": "18.75"}, {"price": "0.066", "size": "28.12"}, {"price": "0.065", "size": "28.13"}, {"price": "0.062", "size": "638.01"}, {"price": "0.021", "size": "638.01"}, {"price": "0.013", "size": "201.37"}, {"price": "0.012", "size": "547.34"}, {"price": "0.01", "size": "41.07"}, {"price": "0.009", "size": "13"}], "event_type": "book", "last_trade_price": "0.008"}, {"market": "0x9203a698f9fa14be61cfdb6bfef9deddd0aa7d2b2907d93a619702683087b3da", "asset_id": "90609029279195192521610502880224098677548237969581172515290357666786312674233", "timestamp": "1769383924179", "hash": "0f7b01dc7434bc5ac4843a543b1d46d743dbe410", "bids": [{"price": "0.001", "size": "1107265.27"}, {"price": "0.002", "size": "67255.26"}, {"price": "0.003", "size": "1400"}, {"price": "0.004", "size": "10.4"}, {"price": "0.006", "size": "200"}, {"price": "0.01", "size": "3250"}, {"price": "0.011", "size": "6006"}, {"price": "0.012", "size": "8"}, {"price": "0.02", "size": "1750"}, {"price": "0.021", "size": "10000"}, {"price": "0.03", "size": "500"}, {"price": "0.031", "size": "6.11"}, {"price": "0.04", "size": "250"}, {"price": "0.05", "size": "330"}, {"price": "0.051", "size": "39"}, {"price": "0.07", "size": "300"}, {"price": "0.071", "size": "7.23"}, {"price": "0.1", "size": "560"}, {"price": "0.101", "size": "180"}, {"price": "0.15", "size": "551.66"}, {"price": "0.2", "size": "460"}, {"price": "0.201", "size": "5.68"}, {"price": "0.25", "size": "262"}, {"price": "0.27", "size": "50"}, {"price": "0.3", "size": "86.66"}, {"price": "0.35", "size": "68.57"}, {"price": "0.4", "size": "175"}, {"price": "0.568", "size": "440"}, {"price": "0.569", "size": "702"}, {"price": "0.57", "size": "5"}, {"price": "0.85", "size": "6.4"}, {"price": "0.854", "size": "203.5"}, {"price": "0.866", "size": "10"}, {"price": "0.868", "size": "20"}, {"price": "0.869", "size": "30"}, {"price": "0.87", "size": "20"}, {"price": "0.952", "size": "380"}, {"price": "0.966", "size": "800"}, {"price": "0.975", "size": "852.98"}, {"price": "0.976", "size": "48"}, {"price": "0.988", "size": "517.27"}, {"price": "0.989", "size": "69.94"}], "asks": [{"price": "0.999", "size": "87962"}, {"price": "0.998", "size": "3837.12"}, {"price": "0.997", "size": "293"}], "event_type": "book", "last_trade_price": "0.007"}, {"market": "0x5ed8142bfb7dedd29123c51d93e78d41bb11347a9dc99af028f8c26d379f7991", "asset_id": "87806309463368545105535948349282475480949630203592970860801199564395401037228", "timestamp": "1769383969962", "hash": "385008a192fded7eb845b4b7a559bc0dd0303036", "bids": [{"price": "0.01", "size": "116556.76"}, {"price": "0.02", "size": "1756.54"}, {"price": "0.03", "size": "7500"}, {"price": "0.04", "size": "857.57"}, {"price": "0.05", "size": "1030"}, {"price": "0.06", "size": "10"}, {"price": "0.08", "size": "625"}, {"price": "0.09", "size": "5.19"}, {"price": "0.1", "size": "238"}, {"price": "0.11", "size": "615.9"}, {"price": "0.12", "size": "16"}, {"price": "0.14", "size": "200"}, {"price": "0.17", "size": "402.94"}, {"price": "0.18", "size": "5.72"}, {"price": "0.19", "size": "126.31"}, {"price": "0.22", "size": "90.9"}, {"price": "0.25", "size": "15"}, {"price": "0.26", "size": "50"}, {"price": "0.32", "size": "250"}, {"price": "0.33", "size": "10"}, {"price": "0.35", "size": "15.11"}, {"price": "0.37", "size": "55.13"}, {"price": "0.38", "size": "28.94"}, {"price": "0.4", "size": "900"}, {"price": "0.42", "size": "170"}, {"price": "0.45", "size": "650"}, {"price": "0.46", "size": "200"}], "asks": [{"price": "0.99", "size": "7550"}, {"price": "0.98", "size": "2400"}, {"price": "0.97", "size": "7.4"}, {"price": "0.95", "size": "1420"}, {"price": "0.93", "size": "985.71"}, {"price": "0.91", "size": "355.55"}, {"price": "0.9", "size": "200"}, {"price": "0.88", "size": "558.33"}, {"price": "0.87", "size": "166"}, {"price": "0.86", "size": "185.71"}, {"price": "0.84", "size": "400"}, {"price": "0.81", "size": "105.26"}, {"price": "0.75", "size": "200"}, {"price": "0.73", "size": "97.21"}, {"price": "0.68", "size": "200"}, {"price": "0.59", "size": "120"}, {"price": "0.58", "size": "90.95"}, {"price": "0.57", "size": "25.58"}, {"price": "0.53", "size": "1800"}, {"price": "0.52", "size": "37.16"}, {"price": "0.51", "size": "62.16"}, {"price": "0.49", "size": "37.16"}], "event_type": "book", "last_trade_price": ""}, {"market": "0xad1d3f37d4b3e994cf6e345342e4c6d77b847c125d222144c583ef5c4bd2f84a", "asset_id": "77654714676170984534448970834577345438216226056033824875092030167273571185616", "timestamp": "1769383924179", "hash": "570280f2d73c66e263fbd32708ea8f08561e7d49", "bids": [{"price": "0.001", "size": "116962.59"}, {"price": "0.002", "size": "27255.24"}, {"price": "0.003", "size": "1400"}, {"price": "0.004", "size": "9.09"}, {"price": "0.006", "size": "200"}, {"price": "0.01", "size": "3250"}, {"price": "0.011", "size": "9.17"}, {"price": "0.02", "size": "1750"}, {"price": "0.021", "size": "7000"}, {"price": "0.03", "size": "500"}, {"price": "0.031", "size": "6.1"}, {"price": "0.04", "size": "250"}, {"price": "0.05", "size": "30"}, {"price": "0.051", "size": "3639"}, {"price": "0.07", "size": "300"}, {"price": "0.071", "size": "7.22"}, {"price": "0.1", "size": "560"}, {"price": "0.101", "size": "180"}, {"price": "0.15", "size": "551.66"}, {"price": "0.2", "size": "460"}, {"price": "0.201", "size": "5.69"}, {"price": "0.25", "size": "262"}, {"price": "0.27", "size": "50"}, {"price": "0.3", "size": "86.66"}, {"price": "0.35", "size": "68.57"}, {"price": "0.4", "size": "175"}, {"price": "0.401", "size": "5"}, {"price": "0.762", "size": "378.06"}, {"price": "0.763", "size": "277"}, {"price": "0.764", "size": "10"}, {"price": "0.857", "size": "11.11"}, {"price": "0.859", "size": "20"}, {"price": "0.861", "size": "30"}, {"price": "0.862", "size": "20"}, {"price": "0.908", "size": "121.91"}, {"price": "0.962", "size": "700"}, {"price": "0.985", "size": "835.37"}, {"price": "0.987", "size": "417.35"}, {"price": "0.988", "size": "114.64"}, {"price": "0.991", "size": "190.94"}, {"price": "0.995", "size": "30"}], "asks": [{"price": "0.999", "size": "28538"}, {"price": "0.998", "size": "2742.63"}], "event_type": "book", "last_trade_price": ""}, {"market": "0xaec744acc776760b5ae4ea624392701e5be37f226030347437abdb6df9c1d184", "asset_id": "101982479106085743672801224611352854881298304403358116970444362116404081985491", "timestamp": "1769383974963", "hash": "788433d3cb8f03397e9aacad996694eeae717faa", "bids": [{"price": "0.01", "size": "2250"}, {"price": "0.02", "size": "800"}, {"price": "0.03", "size": "550"}, {"price": "0.04", "size": "650"}, {"price": "0.06", "size": "234.64"}, {"price": "0.07", "size": "289.9"}], "asks": [{"price": "0.99", "size": "116629.44"}, {"price": "0.98", "size": "1750"}, {"price": "0.97", "size": "7506.45"}, {"price": "0.96", "size": "250"}, {"price": "0.95", "size": "330"}, {"price": "0.94", "size": "33"}, {"price": "0.93", "size": "7.49"}, {"price": "0.91", "size": "700"}, {"price": "0.86", "size": "567.85"}, {"price": "0.81", "size": "418.42"}, {"price": "0.8", "size": "5.89"}, {"price": "0.77", "size": "271.73"}, {"price": "0.72", "size": "92.85"}, {"price": "0.69", "size": "884"}, {"price": "0.68", "size": "250"}, {"price": "0.67", "size": "72.72"}, {"price": "0.63", "size": "179.05"}, {"price": "0.62", "size": "5"}, {"price": "0.6", "size": "33"}, {"price": "0.59", "size": "10"}, {"price": "0.29", "size": "124.43"}, {"price": "0.28", "size": "20"}, {"price": "0.27", "size": "20"}, {"price": "0.17", "size": "89.42"}, {"price": "0.16", "size": "330.21"}, {"price": "0.15", "size": "13.33"}, {"price": "0.14", "size": "107.3"}, {"price": "0.13", "size": "130"}, {"price": "0.12", "size": "40"}, {"price": "0.11", "size": "15"}], "event_type": "book", "last_trade_price": "0.080"}, {"market": "0xb5f410ce6db52b387d5e3c9aa386f1cf2c6d9603d4ffbb59d7b3ad78c6ce54bc", "asset_id": "30496684424734941608873174390104887181463986142171585340038809175815196271014", "timestamp": "1769383924451", "hash": "56b34e5ba640f4c94642b7f4c983042d4def2b70", "bids": [{"price": "0.001", "size": "1107271.07"}, {"price": "0.002", "size": "16255.25"}, {"price": "0.003", "size": "1400"}, {"price": "0.004", "size": "10.4"}, {"price": "0.006", "size": "200"}, {"price": "0.01", "size": "3250"}, {"price": "0.011", "size": "6000"}, {"price": "0.012", "size": "7.99"}, {"price": "0.02", "size": "1750"}, {"price": "0.021", "size": "4000"}, {"price": "0.03", "size": "500"}, {"price": "0.031", "size": "6.11"}, {"price": "0.04", "size": "250"}, {"price": "0.05", "size": "330"}, {"price": "0.051", "size": "39"}, {"price": "0.07", "size": "300"}, {"price": "0.071", "size": "7.22"}, {"price": "0.1", "size": "560"}, {"price": "0.101", "size": "180"}, {"price": "0.15", "size": "551.66"}, {"price": "0.2", "size": "460"}, {"price": "0.201", "size": "5.69"}, {"price": "0.25", "size": "262"}, {"price": "0.27", "size": "50"}, {"price": "0.3", "size": "86.66"}, {"price": "0.35", "size": "68.57"}, {"price": "0.4", "size": "175"}, {"price": "0.506", "size": "977"}, {"price": "0.513", "size": "5"}, {"price": "0.84", "size": "5"}, {"price": "0.86", "size": "5"}, {"price": "0.863", "size": "33.39"}, {"price": "0.865", "size": "589.24"}, {"price": "0.866", "size": "10"}, {"price": "0.868", "size": "50"}, {"price": "0.869", "size": "20"}, {"price": "0.932", "size": "24.99"}, {"price": "0.933", "size": "18.75"}, {"price": "0.934", "size": "28.12"}, {"price": "0.935", "size": "28.13"}, {"price": "0.938", "size": "638.01"}, {"price": "0.979", "size": "638.01"}, {"price": "0.987", "size": "201.37"}, {"price": "0.988", "size": "547.34"}, {"price": "0.99", "size": "41.07"}, {"price": "0.991", "size": "13"}], "asks": [{"price": "0.999", "size": "53488"}, {"price": "0.998", "size": "250"}, {"price": "0.997", "size": "1000"}, {"price": "0.996", "size": "397"}, {"price": "0.992", "size": "125"}], "event_type": "book", "last_trade_price": "0.008"}, {"market": "0xaec744acc776760b5ae4ea624392701e5be37f226030347437abdb6df9c1d184", "asset_id": "65011365813876110503762705278234990534834069077237893699433240754014665936821", "timestamp": "1769383974963", "hash": "7844ac92906d14e2b9e7e560681f4ee7a81e26a8", "bids": [{"price": "0.01", "size": "116629.44"}, {"price": "0.02", "size": "1750"}, {"price": "0.03", "size": "7506.45"}, {"price": "0.04", "size": "250"}, {"price": "0.05", "size": "330"}, {"price": "0.06", "size": "33"}, {"price": "0.07", "size": "7.49"}, {"price": "0.09", "size": "700"}, {"price": "0.14", "size": "567.85"}, {"price": "0.19", "size": "418.42"}, {"price": "0.2", "size": "5.89"}, {"price": "0.23", "size": "271.73"}, {"price": "0.28", "size": "92.85"}, {"price": "0.31", "size": "884"}, {"price": "0.32", "size": "250"}, {"price": "0.33", "size": "72.72"}, {"price": "0.37", "size": "179.05"}, {"price": "0.38", "size": "5"}, {"price": "0.4", "size": "33"}, {"price": "0.41", "size": "10"}, {"price": "0.71", "size": "124.43"}, {"price": "0.72", "size": "20"}, {"price": "0.73", "size": "20"}, {"price": "0.83", "size": "89.42"}, {"price": "0.84", "size": "330.21"}, {"price": "0.85", "size": "13.33"}, {"price": "0.86", "size": "107.3"}, {"price": "0.87", "size": "130"}, {"price": "0.88", "size": "40"}, {"price": "0.89", "size": "15"}], "asks": [{"price": "0.99", "size": "2250"}, {"price": "0.98", "size": "800"}, {"price": "0.97", "size": "550"}, {"price": "0.96", "size": "650"}, {"price": "0.94", "size": "234.64"}, {"price": "0.93", "size": "289.9"}], "event_type": "book", "last_trade_price": "0.080"}, {"market": "0xc7982ab943183b14a136538b1943a99f0b783266c46647ac5d93a53145c1a7b5", "asset_id": "13851803203597462164946196938589176900313976487295955127267529584815353328811", "timestamp": "1769383924605", "hash": "a4ba9f35a404b6ebae785a87bd4001dd415685dc", "bids": [{"price": "0.001", "size": "1107232.27"}, {"price": "0.002", "size": "21255.25"}, {"price": "0.003", "size": "1400"}, {"price": "0.004", "size": "10.39"}, {"price": "0.006", "size": "200"}, {"price": "0.01", "size": "3250"}, {"price": "0.011", "size": "6000"}, {"price": "0.012", "size": "7.99"}, {"price": "0.02", "size": "1750"}, {"price": "0.021", "size": "7000"}, {"price": "0.03", "size": "500"}, {"price": "0.031", "size": "6.1"}, {"price": "0.04", "size": "250"}, {"price": "0.05", "size": "330"}, {"price": "0.051", "size": "39"}, {"price": "0.07", "size": "300"}, {"price": "0.071", "size": "7.22"}, {"price": "0.1", "size": "560"}, {"price": "0.101", "size": "180"}, {"price": "0.15", "size": "551.66"}, {"price": "0.2", "size": "460"}, {"price": "0.201", "size": "5.69"}, {"price": "0.25", "size": "262"}, {"price": "0.27", "size": "50"}, {"price": "0.3", "size": "86.66"}, {"price": "0.34", "size": "50"}, {"price": "0.35", "size": "68.57"}, {"price": "0.4", "size": "50"}, {"price": "0.402", "size": "227"}, {"price": "0.403", "size": "5"}, {"price": "0.76", "size": "6.7"}, {"price": "0.82", "size": "6.7"}, {"price": "0.854", "size": "877.04"}, {"price": "0.855", "size": "61"}, {"price": "0.856", "size": "13.33"}, {"price": "0.858", "size": "10"}, {"price": "0.86", "size": "20"}, {"price": "0.861", "size": "30"}, {"price": "0.862", "size": "20"}, {"price": "0.941", "size": "877.04"}, {"price": "0.943", "size": "307.33"}, {"price": "0.982", "size": "94.9"}, {"price": "0.99", "size": "482.5"}], "asks": [{"price": "0.999", "size": "63538"}, {"price": "0.998", "size": "3403.72"}, {"price": "0.997", "size": "250"}, {"price": "0.994", "size": "1100"}], "event_type": "book", "last_trade_price": ""}, {"market": "0x90301098126f955f3ce5a03b7fe4c35a3641b233f4c56e88b11070a1b414c61a", "asset_id": "39312012332144445223325894231881456670645569993721035335222112552139635422119", "timestamp": "1769383941794", "hash": "23e4fa3ed2421783be417b0c96b06f57786d0565", "bids": [{"price": "0.001", "size": "1369276.26"}, {"price": "0.002", "size": "66793.86"}, {"price": "0.003", "size": "1400"}, {"price": "0.004", "size": "17384"}, {"price": "0.005", "size": "7.26"}, {"price": "0.006", "size": "200"}, {"price": "0.008", "size": "4096"}, {"price": "0.01", "size": "2250"}, {"price": "0.011", "size": "15000"}, {"price": "0.012", "size": "8.83"}, {"price": "0.016", "size": "1024"}, {"price": "0.02", "size": "2750"}, {"price": "0.03", "size": "500"}, {"price": "0.032", "size": "256"}, {"price": "0.033", "size": "5.45"}, {"price": "0.04", "size": "250"}, {"price": "0.05", "size": "330"}, {"price": "0.06", "size": "33"}, {"price": "0.064", "size": "64"}, {"price": "0.07", "size": "300"}, {"price": "0.071", "size": "6.73"}, {"price": "0.1", "size": "560"}, {"price": "0.12", "size": "150.19"}, {"price": "0.128", "size": "16"}, {"price": "0.14", "size": "567.85"}, {"price": "0.19", "size": "418.42"}, {"price": "0.191", "size": "209"}, {"price": "0.192", "size": "6.14"}, {"price": "0.24", "size": "316.66"}, {"price": "0.256", "size": "5"}, {"price": "0.27", "size": "50"}, {"price": "0.29", "size": "89.65"}, {"price": "0.34", "size": "70.58"}, {"price": "0.38", "size": "1196.63"}, {"price": "0.512", "size": "5"}, {"price": "0.514", "size": "346"}, {"price": "0.515", "size": "5"}, {"price": "0.6", "size": "10"}, {"price": "0.65", "size": "10"}, {"price": "0.651", "size": "10"}, {"price": "0.75", "size": "10"}, {"price": "0.769", "size": "200"}, {"price": "0.8", "size": "10"}, {"price": "0.801", "size": "20"}, {"price": "0.802", "size": "30"}, {"price": "0.82", "size": "10"}, {"price": "0.821", "size": "20"}, {"price": "0.84", "size": "10"}, {"price": "0.85", "size": "11"}, {"price": "0.86", "size": "10"}, {"price": "0.88", "size": "9.8"}, {"price": "0.886", "size": "237.14"}, {"price": "0.887", "size": "100"}, {"price": "0.913", "size": "100"}, {"price": "0.924", "size": "30"}, {"price": "0.94", "size": "253.69"}, {"price": "0.941", "size": "45.64"}], "asks": [{"price": "0.999", "size": "102386"}, {"price": "0.998", "size": "14867.12"}, {"price": "0.997", "size": "2000"}, {"price": "0.996", "size": "2048"}, {"price": "0.995", "size": "1007.13"}, {"price": "0.994", "size": "1700"}, {"price": "0.993", "size": "981.24"}, {"price": "0.992", "size": "512"}, {"price": "0.99", "size": "1765.19"}, {"price": "0.989", "size": "255.19"}, {"price": "0.988", "size": "233.8"}, {"price": "0.984", "size": "128"}, {"price": "0.983", "size": "1000"}, {"price": "0.982", "size": "1000"}, {"price": "0.981", "size": "1000"}, {"price": "0.98", "size": "500"}, {"price": "0.979", "size": "5.29"}, {"price": "0.97", "size": "2300"}, {"price": "0.969", "size": "300"}, {"price": "0.968", "size": "32"}, {"price": "0.967", "size": "200"}, {"price": "0.96", "size": "325"}, {"price": "0.958", "size": "166.5"}, {"price": "0.955", "size": "240"}, {"price": "0.954", "size": "299.23"}, {"price": "0.953", "size": "36"}, {"price": "0.952", "size": "32.61"}], "event_type": "book", "last_trade_price": "0.051"}, {"market": "0x90301098126f955f3ce5a03b7fe4c35a3641b233f4c56e88b11070a1b414c61a", "asset_id": "79853007977105815624113941534992494565347323884772610518298707804471039732081", "timestamp": "1769383941794", "hash": "859d48e670cd93a676452ebfa1d18e52aabe5ae7", "bids": [{"price": "0.001", "size": "102386"}, {"price": "0.002", "size": "14867.12"}, {"price": "0.003", "size": "2000"}, {"price": "0.004", "size": "2048"}, {"price": "0.005", "size": "1007.13"}, {"price": "0.006", "size": "1700"}, {"price": "0.007", "size": "981.24"}, {"price": "0.008", "size": "512"}, {"price": "0.01", "size": "1765.19"}, {"price": "0.011", "size": "255.19"}, {"price": "0.012", "size": "233.8"}, {"price": "0.016", "size": "128"}, {"price": "0.017", "size": "1000"}, {"price": "0.018", "size": "1000"}, {"price": "0.019", "size": "1000"}, {"price": "0.02", "size": "500"}, {"price": "0.021", "size": "5.29"}, {"price": "0.03", "size": "2300"}, {"price": "0.031", "size": "300"}, {"price": "0.032", "size": "32"}, {"price": "0.033", "size": "200"}, {"price": "0.04", "size": "325"}, {"price": "0.042", "size": "166.5"}, {"price": "0.045", "size": "240"}, {"price": "0.046", "size": "299.23"}, {"price": "0.047", "size": "36"}, {"price": "0.048", "size": "32.61"}], "asks": [{"price": "0.999", "size": "1369276.26"}, {"price": "0.998", "size": "66793.86"}, {"price": "0.997", "size": "1400"}, {"price": "0.996", "size": "17384"}, {"price": "0.995", "size": "7.26"}, {"price": "0.994", "size": "200"}, {"price": "0.992", "size": "4096"}, {"price": "0.99", "size": "2250"}, {"price": "0.989", "size": "15000"}, {"price": "0.988", "size": "8.83"}, {"price": "0.984", "size": "1024"}, {"price": "0.98", "size": "2750"}, {"price": "0.97", "size": "500"}, {"price": "0.968", "size": "256"}, {"price": "0.967", "size": "5.45"}, {"price": "0.96", "size": "250"}, {"price": "0.95", "size": "330"}, {"price": "0.94", "size": "33"}, {"price": "0.936", "size": "64"}, {"price": "0.93", "size": "300"}, {"price": "0.929", "size": "6.73"}, {"price": "0.9", "size": "560"}, {"price": "0.88", "size": "150.19"}, {"price": "0.872", "size": "16"}, {"price": "0.86", "size": "567.85"}, {"price": "0.81", "size": "418.42"}, {"price": "0.809", "size": "209"}, {"price": "0.808", "size": "6.14"}, {"price": "0.76", "size": "316.66"}, {"price": "0.744", "size": "5"}, {"price": "0.73", "size": "50"}, {"price": "0.71", "size": "89.65"}, {"price": "0.66", "size": "70.58"}, {"price": "0.62", "size": "1196.63"}, {"price": "0.488", "size": "5"}, {"price": "0.486", "size": "346"}, {"price": "0.485", "size": "5"}, {"price": "0.4", "size": "10"}, {"price": "0.35", "size": "10"}, {"price": "0.349", "size": "10"}, {"price": "0.25", "size": "10"}, {"price": "0.231", "size": "200"}, {"price": "0.2", "size": "10"}, {"price": "0.199", "size": "20"}, {"price": "0.198", "size": "30"}, {"price": "0.18", "size": "10"}, {"price": "0.179", "size": "20"}, {"price": "0.16", "size": "10"}, {"price": "0.15", "size": "11"}, {"price": "0.14", "size": "10"}, {"price": "0.12", "size": "9.8"}, {"price": "0.114", "size": "237.14"}, {"price": "0.113", "size": "100"}, {"price": "0.087", "size": "100"}, {"price": "0.076", "size": "30"}, {"price": "0.06", "size": "253.69"}, {"price": "0.059", "size": "45.64"}], "event_type": "book", "last_trade_price": "0.051"}, {"market": "0xdf3aed600715b8cc4a23e3d7e6caad79791de8dcd5af48f450dc1b8dc52128c3", "asset_id": "111955058608111392596805821148637930362581269673097069733693799539148925173769", "timestamp": "1769383921292", "hash": "d63c68f8299ff0ffae58e45e0c775758c24cd29e", "bids": [{"price": "0.001", "size": "51304"}, {"price": "0.002", "size": "16166"}, {"price": "0.003", "size": "2009.11"}, {"price": "0.005", "size": "1000"}, {"price": "0.006", "size": "11.81"}, {"price": "0.01", "size": "2750"}, {"price": "0.012", "size": "1500"}, {"price": "0.013", "size": "250"}, {"price": "0.014", "size": "7.22"}, {"price": "0.02", "size": "700"}, {"price": "0.022", "size": "421.51"}, {"price": "0.027", "size": "261.61"}, {"price": "0.035", "size": "600"}], "asks": [{"price": "0.999", "size": "3952.61"}, {"price": "0.998", "size": "1255.27"}, {"price": "0.997", "size": "1400"}, {"price": "0.996", "size": "9.14"}, {"price": "0.994", "size": "200"}, {"price": "0.99", "size": "117550"}, {"price": "0.989", "size": "9.22"}, {"price": "0.98", "size": "5750"}, {"price": "0.97", "size": "500"}, {"price": "0.969", "size": "6.13"}, {"price": "0.96", "size": "250"}, {"price": "0.95", "size": "930"}, {"price": "0.949", "size": "39"}, {"price": "0.93", "size": "300"}, {"price": "0.929", "size": "6.8"}, {"price": "0.9", "size": "560"}, {"price": "0.85", "size": "551.66"}, {"price": "0.81", "size": "418.42"}, {"price": "0.809", "size": "6.14"}, {"price": "0.76", "size": "316.66"}, {"price": "0.73", "size": "50"}, {"price": "0.71", "size": "89.65"}, {"price": "0.7", "size": "50"}, {"price": "0.66", "size": "70.58"}, {"price": "0.61", "size": "51.28"}, {"price": "0.605", "size": "5"}, {"price": "0.6", "size": "1050"}, {"price": "0.599", "size": "249"}, {"price": "0.598", "size": "277"}, {"price": "0.319", "size": "10"}, {"price": "0.315", "size": "20"}, {"price": "0.314", "size": "30"}, {"price": "0.313", "size": "20"}, {"price": "0.094", "size": "330.33"}, {"price": "0.093", "size": "114.12"}, {"price": "0.062", "size": "266.18"}, {"price": "0.061", "size": "36"}, {"price": "0.036", "size": "34.08"}], "event_type": "book", "last_trade_price": ""}, {"market": "0x4a0cc84209df8e25f2651148c15ca45841bf02133903a990ad2be56d8337efe5", "asset_id": "61649988503359407770258418097615151606970415315192585742996814749095348840604", "timestamp": "1769383946856", "hash": "b43ca7721bf8939b8b12eb0397c0a2c659f98fd9", "bids": [{"price": "0.01", "size": "3005"}, {"price": "0.02", "size": "505"}, {"price": "0.03", "size": "307.4"}, {"price": "0.06", "size": "200"}, {"price": "0.08", "size": "250"}, {"price": "0.09", "size": "100"}, {"price": "0.1", "size": "6"}, {"price": "0.15", "size": "150"}, {"price": "0.17", "size": "6"}, {"price": "0.18", "size": "100"}, {"price": "0.19", "size": "13.31"}, {"price": "0.2", "size": "65"}, {"price": "0.21", "size": "27.93"}, {"price": "0.22", "size": "160.38"}, {"price": "0.23", "size": "6"}, {"price": "0.25", "size": "36"}], "asks": [{"price": "0.99", "size": "116555.42"}, {"price": "0.98", "size": "1755.33"}, {"price": "0.97", "size": "4500"}, {"price": "0.96", "size": "244.05"}, {"price": "0.95", "size": "300"}, {"price": "0.93", "size": "1014.28"}, {"price": "0.91", "size": "5.48"}, {"price": "0.89", "size": "804.09"}, {"price": "0.85", "size": "213.33"}, {"price": "0.81", "size": "397.36"}, {"price": "0.8", "size": "10"}, {"price": "0.79", "size": "5.23"}, {"price": "0.77", "size": "263.04"}, {"price": "0.74", "size": "99.78"}, {"price": "0.7", "size": "66.66"}, {"price": "0.67", "size": "550"}, {"price": "0.66", "size": "50"}, {"price": "0.59", "size": "131.42"}, {"price": "0.58", "size": "10"}, {"price": "0.42", "size": "5"}, {"price": "0.4", "size": "1014.98"}, {"price": "0.39", "size": "155.45"}, {"price": "0.38", "size": "30"}, {"price": "0.37", "size": "85.63"}, {"price": "0.36", "size": "17.18"}, {"price": "0.34", "size": "199.09"}, {"price": "0.33", "size": "69"}, {"price": "0.32", "size": "50"}, {"price": "0.31", "size": "6"}, {"price": "0.29", "size": "30"}], "event_type": "book", "last_trade_price": "0.220"}]}
{"_local_timestamp": "2026-01-25T23:33:38.181720+00:00", "data": {"market": "0x4a0cc84209df8e25f2651148c15ca45841bf02133903a990ad2be56d8337efe5", "price_changes": [{"asset_id": "61649988503359407770258418097615151606970415315192585742996814749095348840604", "price": "0.39", "size": "110", "side": "SELL", "hash": "acd6722deb4a9f385c5d9cbb4fe4f5f6c5cf5028", "best_bid": "0.25", "best_ask": "0.29"}, {"asset_id": "102020588502400806287117347702632611550727753557718799166708590001374539810273", "price": "0.61", "size": "110", "side": "BUY", "hash": "cbc59d77d3fccd9935b6180eaff221b7ec532ce2", "best_bid": "0.71", "best_ask": "0.75"}], "timestamp": "1769384018105", "event_type": "price_change"}}
{"_local_timestamp": "2026-01-25T23:33:46.712015+00:00", "data": {"market": "0x4a0cc84209df8e25f2651148c15ca45841bf02133903a990ad2be56d8337efe5", "price_changes": [{"asset_id": "61649988503359407770258418097615151606970415315192585742996814749095348840604", "price": "0.39", "size": "155.45", "side": "SELL", "hash": "863352bc7bd14bf8c20404aa9a656412708b7d3a", "best_bid": "0.25", "best_ask": "0.29"}, {"asset_id": "102020588502400806287117347702632611550727753557718799166708590001374539810273", "price": "0.61", "size": "155.45", "side": "BUY", "hash": "d3cd5cb072b3e46e38accb53c782de388e8cdd4e", "best_bid": "0.71", "best_ask": "0.75"}], "timestamp": "1769384026639", "event_type": "price_change"}}
{"_local_timestamp": "2026-01-25T23:34:18.130259+00:00", "data": {"market": "0x4a0cc84209df8e25f2651148c15ca45841bf02133903a990ad2be56d8337efe5", "price_changes": [{"asset_id": "61649988503359407770258418097615151606970415315192585742996814749095348840604", "price": "0.29", "size": "0", "side": "SELL", "hash": "24a88b74bc9f30290715e6fe16e30809501097a9", "best_bid": "0.25", "best_ask": "0.31"}, {"asset_id": "102020588502400806287117347702632611550727753557718799166708590001374539810273", "price": "0.71", "size": "0", "side": "BUY", "hash": "6cc643f8d6798544dd87edb4b9fae0f429364a87", "best_bid": "0.69", "best_ask": "0.75"}], "timestamp": "1769384058047", "event_type": "price_change"}}
{"_local_timestamp": "2026-01-25T23:34:18.168367+00:00", "data": {"market": "0xdf3aed600715b8cc4a23e3d7e6caad79791de8dcd5af48f450dc1b8dc52128c3", "price_changes": [{"asset_id": "115200191337492844563805575089118887672911159979117742424196868043770660979378", "price": "0.4", "size": "550", "side": "BUY", "hash": "6ec7ef508da5942e9b9a3655ba43ca1b66a71d58", "best_bid": "0.964", "best_ask": "0.965"}, {"asset_id": "111955058608111392596805821148637930362581269673097069733693799539148925173769", "price": "0.6", "size": "550", "side": "SELL", "hash": "a20a7182c08d15234f94a89a65588c820be5e59c", "best_bid": "0.035", "best_ask": "0.036"}], "timestamp": "1769384058103", "event_type": "price_change"}}
{"_local_timestamp": "2026-01-25T23:34:18.269431+00:00", "data": {"market": "0xdf3aed600715b8cc4a23e3d7e6caad79791de8dcd5af48f450dc1b8dc52128c3", "price_changes": [{"asset_id": "115200191337492844563805575089118887672911159979117742424196868043770660979378", "price": "0.4", "size": "50", "side": "BUY", "hash": "8f304eeff40e83aa99535fc90f03c24e6e4b8126", "best_bid": "0.964", "best_ask": "0.965"}, {"asset_id": "111955058608111392596805821148637930362581269673097069733693799539148925173769", "price": "0.6", "size": "50", "side": "SELL", "hash": "57d7dfb33f614f9a10ebb3caab6f8468a6e8845c", "best_bid": "0.035", "best_ask": "0.036"}], "timestamp": "1769384058179", "event_type": "price_change"}}
{"_local_timestamp": "2026-01-25T23:34:18.367913+00:00", "data": {"market": "0xdf3aed600715b8cc4a23e3d7e6caad79791de8dcd5af48f450dc1b8dc52128c3", "price_changes": [{"asset_id": "115200191337492844563805575089118887672911159979117742424196868043770660979378", "price": "0.402", "size": "774", "side": "BUY", "hash": "d297b1dd87f1fea872ca3ef89bbd44b5c3667bf2", "best_bid": "0.964", "best_ask": "0.965"}, {"asset_id": "111955058608111392596805821148637930362581269673097069733693799539148925173769", "price": "0.598", "size": "774", "side": "SELL", "hash": "48dadf1030d7fdbff8830bbfafbbfce6b7acb1a3", "best_bid": "0.035", "best_ask": "0.036"}], "timestamp": "1769384058298", "event_type": "price_change"}}
{"_local_timestamp": "2026-01-25T23:34:18.388796+00:00", "data": {"market": "0xdf3aed600715b8cc4a23e3d7e6caad79791de8dcd5af48f450dc1b8dc52128c3", "price_changes": [{"asset_id": "115200191337492844563805575089118887672911159979117742424196868043770660979378", "price": "0.402", "size": "1271", "side": "BUY", "hash": "7451a9085422159cb9db5057637b81266058ab6d", "best_bid": "0.964", "best_ask": "0.965"}, {"asset_id": "111955058608111392596805821148637930362581269673097069733693799539148925173769", "price": "0.598", "size": "1271", "side": "SELL", "hash": "e76abd4691c536ed217b75f64f8ed9c1a1d4190f", "best_bid": "0.035", "best_ask": "0.036"}], "timestamp": "1769384058322", "event_type": "price_change"}}
{"_local_timestamp": "2026-01-25T23:34:18.513289+00:00", "data": {"market": "0x5ed8142bfb7dedd29123c51d93e78d41bb11347a9dc99af028f8c26d379f7991", "price_changes": [{"asset_id": "87806309463368545105535948349282475480949630203592970860801199564395401037228", "price": "0.25", "size": "0", "side": "BUY", "hash": "9372727c443aba01d860f0c1101ed828946aae19", "best_bid": "0.46", "best_ask": "0.49"}, {"asset_id": "21074627447851722982583017164862562903762903675957478566509692359288711223560", "price": "0.75", "size": "0", "side": "SELL", "hash": "6feb745176b84de98b69c73f778f4411dcfcd51b", "best_bid": "0.51", "best_ask": "0.54"}], "timestamp": "1769384058442", "event_type": "price_change"}}
{"_local_timestamp": "2026-01-25T23:34:18.513738+00:00", "data": {"market": "0xdf3aed600715b8cc4a23e3d7e6caad79791de8dcd5af48f450dc1b8dc52128c3", "price_changes": [{"asset_id": "115200191337492844563805575089118887672911159979117742424196868043770660979378", "price": "0.401", "size": "0", "side": "BUY", "hash": "cfb69c662bdb57ac8e880333d6ab0a98c1ac8341", "best_bid": "0.964", "best_ask": "0.965"}, {"asset_id": "111955058608111392596805821148637930362581269673097069733693799539148925173769", "price": "0.599", "size": "0", "side": "SELL", "hash": "023ff5cf8447f9bc4e480bb3c50277e1f189e566", "best_bid": "0.035", "best_ask": "0.036"}], "timestamp": "1769384058442", "event_type": "price_change"}}
{"_local_timestamp": "2026-01-25T23:34:18.920432+00:00", "data": {"market": "0x4a0cc84209df8e25f2651148c15ca45841bf02133903a990ad2be56d8337efe5", "price_changes": [{"asset_id": "61649988503359407770258418097615151606970415315192585742996814749095348840604", "price": "0.31", "size": "36", "side": "SELL", "hash": "6a87f54420e98ec19d2f55d97cdaade52468c9b9", "best_bid": "0.25", "best_ask": "0.31"}, {"asset_id": "102020588502400806287117347702632611550727753557718799166708590001374539810273", "price": "0.69", "size": "36", "side": "BUY", "hash": "8fd86fe61f8e8d006b7bb5a62287e377b1096c88", "best_bid": "0.69", "best_ask": "0.75"}], "timestamp": "1769384058855", "event_type": "price_change"}}
{"_local_timestamp": "2026-01-25T23:34:19.055886+00:00", "data": {"market": "0xdf3aed600715b8cc4a23e3d7e6caad79791de8dcd5af48f450dc1b8dc52128c3", "price_changes": [{"asset_id": "115200191337492844563805575089118887672911159979117742424196868043770660979378", "price": "0.403", "size": "248", "side": "BUY", "hash": "336ddc7234ad174f727075beecb449cd1cb3769d", "best_bid": "0.964", "best_ask": "0.965"}, {"asset_id": "111955058608111392596805821148637930362581269673097069733693799539148925173769", "price": "0.597", "size": "248", "side": "SELL", "hash": "cdfc14a87f36bb7fcf3f0421f4ca1daf34efd7f3", "best_bid": "0.035", "best_ask": "0.036"}], "timestamp": "1769384058983", "event_type": "price_change"}}
{"_local_timestamp": "2026-01-25T23:34:19.058608+00:00", "data": {"market": "0xdf3aed600715b8cc4a23e3d7e6caad79791de8dcd5af48f450dc1b8dc52128c3", "price_changes": [{"asset_id": "115200191337492844563805575089118887672911159979117742424196868043770660979378", "price": "0.688", "size": "15", "side": "BUY", "hash": "a0b596276ba83b3ed627990c04badea0ce160987", "best_bid": "0.964", "best_ask": "0.965"}, {"asset_id": "111955058608111392596805821148637930362581269673097069733693799539148925173769", "price": "0.312", "size": "15", "side": "SELL", "hash": "cd0647215b931cf9e7b6890fb9d953e3949bef68", "best_bid": "0.035", "best_ask": "0.036"}], "timestamp": "1769384058984", "event_type": "price_change"}}
{"_local_timestamp": "2026-01-25T23:34:19.059156+00:00", "data": {"market": "0xdf3aed600715b8cc4a23e3d7e6caad79791de8dcd5af48f450dc1b8dc52128c3", "price_changes": [{"asset_id": "115200191337492844563805575089118887672911159979117742424196868043770660979378", "price": "0.688", "size": "25", "side": "BUY", "hash": "ef6f310d68fb64f5c1d85b1a1a21f887611ab7d3", "best_bid": "0.964", "best_ask": "0.965"}, {"asset_id": "111955058608111392596805821148637930362581269673097069733693799539148925173769", "price": "0.312", "size": "25", "side": "SELL", "hash": "8da494ae58792b735bda02c57132ea0a2fff0d24", "best_bid": "0.035", "best_ask": "0.036"}], "timestamp": "1769384058985", "event_type": "price_change"}}
{"_local_timestamp": "2026-01-25T23:34:19.926394+00:00", "data": {"market": "0x4a0cc84209df8e25f2651148c15ca45841bf02133903a990ad2be56d8337efe5", "price_changes": [{"asset_id": "61649988503359407770258418097615151606970415315192585742996814749095348840604", "price": "0.25", "size": "0", "side": "BUY", "hash": "8a3898aa660fbe3768335b8c34d5430d2b821f9a", "best_bid": "0.23", "best_ask": "0.31"}, {"asset_id": "102020588502400806287117347702632611550727753557718799166708590001374539810273", "price": "0.75", "size": "0", "side": "SELL", "hash": "fabad011c3f2b07406ab3ccaf6e9042209a2c948", "best_bid": "0.69", "best_ask": "0.77"}], "timestamp": "1769384059852", "event_type": "price_change"}}
{"_local_timestamp": "2026-01-25T23:34:19.958406+00:00", "data": {"market": "0xaec744acc776760b5ae4ea624392701e5be37f226030347437abdb6df9c1d184", "price_changes": [{"asset_id": "65011365813876110503762705278234990534834069077237893699433240754014665936821", "price": "0.86", "size": "87.3", "side": "BUY", "hash": "0cf79a7712fa158dc4b609094d995bab998c7d62", "best_bid": "0.89", "best_ask": "0.93"}, {"asset_id": "101982479106085743672801224611352854881298304403358116970444362116404081985491", "price": "0.14", "size": "87.3", "side": "SELL", "hash": "7106933795889f129e3452c611f6a1415d24514a", "best_bid": "0.07", "best_ask": "0.11"}], "timestamp": "1769384059885", "event_type": "price_change"}}
{"_local_timestamp": "2026-01-25T23:34:19.964223+00:00", "data": {"market": "0x5ed8142bfb7dedd29123c51d93e78d41bb11347a9dc99af028f8c26d379f7991", "price_changes": [{"asset_id": "87806309463368545105535948349282475480949630203592970860801199564395401037228", "price": "0.42", "size": "150", "side": "BUY", "hash": "e49cd5edace355a8c1dfcc35bb05ffa167d26cf6", "best_bid": "0.46", "best_ask": "0.49"}, {"asset_id": "21074627447851722982583017164862562903762903675957478566509692359288711223560", "price": "0.58", "size": "150", "side": "SELL", "hash": "2b6e76388058b0ec0459e7d523403f9210262495", "best_bid": "0.51", "best_ask": "0.54"}], "timestamp": "1769384059885", "event_type": "price_change"}}
{"_local_timestamp": "2026-01-25T23:34:20.057857+00:00", "data": {"market": "0x5ed8142bfb7dedd29123c51d93e78d41bb11347a9dc99af028f8c26d379f7991", "price_changes": [{"asset_id": "87806309463368545105535948349282475480949630203592970860801199564395401037228", "price": "0.33", "size": "0", "side": "BUY", "hash": "f47ffd77a1d7d8b1f0bda6cdc9639211cdeb7954", "best_bid": "0.46", "best_ask": "0.49"}, {"asset_id": "21074627447851722982583017164862562903762903675957478566509692359288711223560", "price": "0.67", "size": "0", "side": "SELL", "hash": "4b4221f3a90b9fc3de6b3f9eb167745b8105b6db", "best_bid": "0.51", "best_ask": "0.54"}], "timestamp": "1769384059990", "event_type": "price_change"}}
{"_local_timestamp": "2026-01-25T23:34:20.117824+00:00", "data": {"market": "0x5ed8142bfb7dedd29123c51d93e78d41bb11347a9dc99af028f8c26d379f7991", "price_changes": [{"asset_id": "87806309463368545105535948349282475480949630203592970860801199564395401037228", "price": "0.06", "size": "0", "side": "BUY", "hash": "0c84c6c54e3ae876889f60c70cda864c40ec4944", "best_bid": "0.46", "best_ask": "0.49"}, {"asset_id": "21074627447851722982583017164862562903762903675957478566509692359288711223560", "price": "0.94", "size": "0", "side": "SELL", "hash": "3fa2bc4cfc1f5e9cf036eecb49e339b5eeab4cab", "best_bid": "0.51", "best_ask": "0.54"}], "timestamp": "1769384060036", "event_type": "price_change"}}
{"_local_timestamp": "2026-01-25T23:34:20.119297+00:00", "data": {"market": "0xc7982ab943183b14a136538b1943a99f0b783266c46647ac5d93a53145c1a7b5", "price_changes": [{"asset_id": "13851803203597462164946196938589176900313976487295955127267529584815353328811", "price": "0.858", "size": "0", "side": "BUY", "hash": "171a626e912ff009c8f726ab497d35e5feed8aa4", "best_bid": "0.99", "best_ask": "0.994"}, {"asset_id": "109831253762520485632120158952131204631888758680701510579735402842471158516644", "price": "0.142", "size": "0", "side": "SELL", "hash": "4a3da7aa11c7af5134e8db9cf7b6137e8bbefe35", "best_bid": "0.006", "best_ask": "0.01"}], "timestamp": "1769384060036", "event_type": "price_change"}}
{"_local_timestamp": "2026-01-25T23:34:20.122334+00:00", "data": {"market": "0x9203a698f9fa14be61cfdb6bfef9deddd0aa7d2b2907d93a619702683087b3da", "price_changes": [{"asset_id": "90609029279195192521610502880224098677548237969581172515290357666786312674233", "price": "0.866", "size": "0", "side": "BUY", "hash": "f1209d732277dfbafc5bbd8bdc03539dd2b864fd", "best_bid": "0.989", "best_ask": "0.997"}, {"asset_id": "78105936059580066886637010200879176612465407936158598378531832410898792072331", "price": "0.134", "size": "0", "side": "SELL", "hash": "721982f872d17521da991a23082e4a63e2d56443", "best_bid": "0.003", "best_ask": "0.011"}], "timestamp": "1769384060036", "event_type": "price_change"}}
{"_local_timestamp": "2026-01-25T23:34:20.125652+00:00", "data": {"market": "0xb5f410ce6db52b387d5e3c9aa386f1cf2c6d9603d4ffbb59d7b3ad78c6ce54bc", "price_changes": [{"asset_id": "30496684424734941608873174390104887181463986142171585340038809175815196271014", "price": "0.866", "size": "0", "side": "BUY", "hash": "905d01cb46d4bc0218197893d5c1a877706f36d5", "best_bid": "0.991", "best_ask": "0.992"}, {"asset_id": "90311555114079332121873713225331719655517167698979277482922143777516026157644", "price": "0.134", "size": "0", "side": "SELL", "hash": "4f97777f9b059511572b9203ff11f7bed6caebfd", "best_bid": "0.008", "best_ask": "0.009"}], "timestamp": "1769384060036", "event_type": "price_change"}}
{"_local_timestamp": "2026-01-25T23:34:20.163079+00:00", "data": {"market": "0x4a0cc84209df8e25f2651148c15ca45841bf02133903a990ad2be56d8337efe5", "price_changes": [{"asset_id": "61649988503359407770258418097615151606970415315192585742996814749095348840604", "price": "0.23", "size": "42", "side": "BUY", "hash": "1e1278b2bf34045a4af5846495d5a445729fda00", "best_bid": "0.23", "best_ask": "0.31"}, {"asset_id": "102020588502400806287117347702632611550727753557718799166708590001374539810273", "price": "0.77", "size": "42", "side": "SELL", "hash": "597e9ac9714f324040451959178e3ac81402d5fa", "best_bid": "0.69", "best_ask": "0.77"}], "timestamp": "1769384060089", "event_type": "price_change"}}
{"_local_timestamp": "2026-01-25T23:34:20.180924+00:00", "data": {"market": "0xaec744acc776760b5ae4ea624392701e5be37f226030347437abdb6df9c1d184", "price_changes": [{"asset_id": "65011365813876110503762705278234990534834069077237893699433240754014665936821", "price": "0.84", "size": "350.21", "side": "BUY", "hash": "d42e03c46e7d82d235bb57748030297f6a24cfce", "best_bid": "0.89", "best_ask": "0.93"}, {"asset_id": "101982479106085743672801224611352854881298304403358116970444362116404081985491", "price": "0.16", "size": "350.21", "side": "SELL", "hash": "4dc609c8db6591a6b91366be81c826faeb9e8e2b", "best_bid": "0.07", "best_ask": "0.11"}], "timestamp": "1769384060112", "event_type": "price_change"}}
{"_local_timestamp": "2026-01-25T23:34:20.202357+00:00", "data": {"market": "0x5ed8142bfb7dedd29123c51d93e78d41bb11347a9dc99af028f8c26d379f7991", "price_changes": [{"asset_id": "87806309463368545105535948349282475480949630203592970860801199564395401037228", "price": "0.4", "size": "920", "side": "BUY", "hash": "5904ecd4ebd06bd9c601f5b12817398e88e016bd", "best_bid": "0.46", "best_ask": "0.49"}, {"asset_id": "21074627447851722982583017164862562903762903675957478566509692359288711223560", "price": "0.6", "size": "920", "side": "SELL", "hash": "56ce347924b42ef37be5c4c6cf3d69b8047455c3", "best_bid": "0.51", "best_ask": "0.54"}], "timestamp": "1769384060131", "event_type": "price_change"}}
{"_local_timestamp": "2026-01-25T23:34:20.220841+00:00", "data": {"market": "0x5ed8142bfb7dedd29123c51d93e78d41bb11347a9dc99af028f8c26d379f7991", "price_changes": [{"asset_id": "87806309463368545105535948349282475480949630203592970860801199564395401037228", "price": "0.33", "size": "20", "side": "BUY", "hash": "8fd78c78e937f6bb78d6706baf86c0032ce5f26e", "best_bid": "0.46", "best_ask": "0.49"}, {"asset_id": "21074627447851722982583017164862562903762903675957478566509692359288711223560", "price": "0.67", "size": "20", "side": "SELL", "hash": "d5ce3ad28e91da4062f7c916075573d12f7eecbb", "best_bid": "0.51", "best_ask": "0.54"}], "timestamp": "1769384060155", "event_type": "price_change"}}
{"_local_timestamp": "2026-01-25T23:34:20.221520+00:00", "data": {"market": "0xc7982ab943183b14a136538b1943a99f0b783266c46647ac5d93a53145c1a7b5", "price_changes": [{"asset_id": "13851803203597462164946196938589176900313976487295955127267529584815353328811", "price": "0.404", "size": "10", "side": "BUY", "hash": "f7cd58609534bb8b652a70bcd8adcbd435c3434c", "best_bid": "0.99", "best_ask": "0.994"}, {"asset_id": "109831253762520485632120158952131204631888758680701510579735402842471158516644", "price": "0.596", "size": "10", "side": "SELL", "hash": "2b3d7da96bf901ca06e6b46d5c7344245e50b056", "best_bid": "0.006", "best_ask": "0.01"}], "timestamp": "1769384060155", "event_type": "price_change"}}
{"_local_timestamp": "2026-01-25T23:34:20.221866+00:00", "data": {"market": "0xb5f410ce6db52b387d5e3c9aa386f1cf2c6d9603d4ffbb59d7b3ad78c6ce54bc", "price_changes": [{"asset_id": "30496684424734941608873174390104887181463986142171585340038809175815196271014", "price": "0.514", "size": "10", "side": "BUY", "hash": "2b3dde8b46900ea6a78ce219c8bebbd6de9da139", "best_bid": "0.991", "best_ask": "0.992"}, {"asset_id": "90311555114079332121873713225331719655517167698979277482922143777516026157644", "price": "0.486", "size": "10", "side": "SELL", "hash": "928ebcb8e8e78881778f3efbe8f0ce2a2fa5f34a", "best_bid": "0.008", "best_ask": "0.009"}], "timestamp": "1769384060155", "event_type": "price_change"}}
{"_local_timestamp": "2026-01-25T23:34:20.222196+00:00", "data": {"market": "0x9203a698f9fa14be61cfdb6bfef9deddd0aa7d2b2907d93a619702683087b3da", "price_changes": [{"asset_id": "90609029279195192521610502880224098677548237969581172515290357666786312674233", "price": "0.571", "size": "10", "side": "BUY", "hash": "2bdc7b13f6e6075b7b3a92b62fdb6ba95a6085a1", "best_bid": "0.989", "best_ask": "0.997"}, {"asset_id": "78105936059580066886637010200879176612465407936158598378531832410898792072331", "price": "0.429", "size": "10", "side": "SELL", "hash": "8416c6409247b3cd372e111e00502057f67b2efb", "best_bid": "0.003", "best_ask": "0.011"}], "timestamp": "1769384060155", "event_type": "price_change"}}
{"_local_timestamp": "2026-01-25T23:34:20.244046+00:00", "data": {"market": "0x5ed8142bfb7dedd29123c51d93e78d41bb11347a9dc99af028f8c26d379f7991", "price_changes": [{"asset_id": "87806309463368545105535948349282475480949630203592970860801199564395401037228", "price": "0.27", "size": "20", "side": "BUY", "hash": "749bf6a03fd8f11f5938a1cec821dbae0f0a4a5c", "best_bid": "0.46", "best_ask": "0.49"}, {"asset_id": "21074627447851722982583017164862562903762903675957478566509692359288711223560", "price": "0.73", "size": "20", "side": "SELL", "hash": "850f9c5a26252281e037bd4a53dd760c9ee30e43", "best_bid": "0.51", "best_ask": "0.54"}], "timestamp": "1769384060167", "event_type": "price_change"}}
{"_local_timestamp": "2026-01-25T23:34:20.245462+00:00", "data": {"market": "0x5ed8142bfb7dedd29123c51d93e78d41bb11347a9dc99af028f8c26d379f7991", "price_changes": [{"asset_id": "87806309463368545105535948349282475480949630203592970860801199564395401037228", "price": "0.27", "size": "45", "side": "BUY", "hash": "955203abe04500add2dab64b888ea42ec261277c", "best_bid": "0.46", "best_ask": "0.49"}, {"asset_id": "21074627447851722982583017164862562903762903675957478566509692359288711223560", "price": "0.73", "size": "45", "side": "SELL", "hash": "b99b9f861d90f828186554f491bb43b8cf294c6d", "best_bid": "0.51", "best_ask": "0.54"}], "timestamp": "1769384060168", "event_type": "price_change"}}
{"_local_timestamp": "2026-01-25T23:34:20.617626+00:00", "data": {"market": "0x4a0cc84209df8e25f2651148c15ca45841bf02133903a990ad2be56d8337efe5", "price_changes": [{"asset_id": "102020588502400806287117347702632611550727753557718799166708590001374539810273", "price": "0.11", "size": "495", "side": "BUY", "hash": "569ec2b1d822ad6f8d73f3dd74b8950544ee773f", "best_bid": "0.69", "best_ask": "0.77"}, {"asset_id": "61649988503359407770258418097615151606970415315192585742996814749095348840604", "price": "0.89", "size": "495", "side": "SELL", "hash": "255c86e79a29e8e5ee27245365c9daa9335e1258", "best_bid": "0.23", "best_ask": "0.31"}], "timestamp": "1769384060551", "event_type": "price_change"}}
{"_local_timestamp": "2026-01-25T23:34:20.618571+00:00", "data": {"market": "0x4a0cc84209df8e25f2651148c15ca45841bf02133903a990ad2be56d8337efe5", "price_changes": [{"asset_id": "102020588502400806287117347702632611550727753557718799166708590001374539810273", "price": "0.07", "size": "500", "side": "BUY", "hash": "569ec2b1d822ad6f8d73f3dd74b8950544ee773f", "best_bid": "0.69", "best_ask": "0.77"}, {"asset_id": "61649988503359407770258418097615151606970415315192585742996814749095348840604", "price": "0.93", "size": "500", "side": "SELL", "hash": "255c86e79a29e8e5ee27245365c9daa9335e1258", "best_bid": "0.23", "best_ask": "0.31"}], "timestamp": "1769384060551", "event_type": "price_change"}}
{"_local_timestamp": "2026-01-25T23:34:20.618921+00:00", "data": {"market": "0x4a0cc84209df8e25f2651148c15ca45841bf02133903a990ad2be56d8337efe5", "price_changes": [{"asset_id": "102020588502400806287117347702632611550727753557718799166708590001374539810273", "price": "0.15", "size": "0", "side": "BUY", "hash": "569ec2b1d822ad6f8d73f3dd74b8950544ee773f", "best_bid": "0.69", "best_ask": "0.77"}, {"asset_id": "61649988503359407770258418097615151606970415315192585742996814749095348840604", "price": "0.85", "size": "0", "side": "SELL", "hash": "255c86e79a29e8e5ee27245365c9daa9335e1258", "best_bid": "0.23", "best_ask": "0.31"}], "timestamp": "1769384060551", "event_type": "price_change"}}
{"_local_timestamp": "2026-01-25T23:34:20.619247+00:00", "data": {"market": "0x4a0cc84209df8e25f2651148c15ca45841bf02133903a990ad2be56d8337efe5", "price_changes": [{"asset_id": "102020588502400806287117347702632611550727753557718799166708590001374539810273", "price": "0.19", "size": "250", "side": "BUY", "hash": "569ec2b1d822ad6f8d73f3dd74b8950544ee773f", "best_bid": "0.69", "best_ask": "0.77"}, {"asset_id": "61649988503359407770258418097615151606970415315192585742996814749095348840604", "price": "0.81", "size": "250", "side": "SELL", "hash": "255c86e79a29e8e5ee27245365c9daa9335e1258", "best_bid": "0.23", "best_ask": "0.31"}], "timestamp": "1769384060551", "event_type": "price_change"}}
{"_local_timestamp": "2026-01-25T23:34:20.619872+00:00", "data": {"market": "0x4a0cc84209df8e25f2651148c15ca45841bf02133903a990ad2be56d8337efe5", "price_changes": [{"asset_id": "102020588502400806287117347702632611550727753557718799166708590001374539810273", "price": "0.3", "size": "0", "side": "BUY", "hash": "569ec2b1d822ad6f8d73f3dd74b8950544ee773f", "best_bid": "0.69", "best_ask": "0.77"}, {"asset_id": "61649988503359407770258418097615151606970415315192585742996814749095348840604", "price": "0.7", "size": "0", "side": "SELL", "hash": "255c86e79a29e8e5ee27245365c9daa9335e1258", "best_bid": "0.23", "best_ask": "0.31"}], "timestamp": "1769384060551", "event_type": "price_change"}}
{"_local_timestamp": "2026-01-25T23:34:20.620331+00:00", "data": {"market": "0x4a0cc84209df8e25f2651148c15ca45841bf02133903a990ad2be56d8337efe5", "price_changes": [{"asset_id": "102020588502400806287117347702632611550727753557718799166708590001374539810273", "price": "0.23", "size": "150", "side": "BUY", "hash": "569ec2b1d822ad6f8d73f3dd74b8950544ee773f", "best_bid": "0.69", "best_ask": "0.77"}, {"asset_id": "61649988503359407770258418097615151606970415315192585742996814749095348840604", "price": "0.77", "size": "150", "side": "SELL", "hash": "255c86e79a29e8e5ee27245365c9daa9335e1258", "best_bid": "0.23", "best_ask": "0.31"}], "timestamp": "1769384060551", "event_type": "price_change"}}
{"_local_timestamp": "2026-01-25T23:34:20.620725+00:00", "data": {"market": "0x4a0cc84209df8e25f2651148c15ca45841bf02133903a990ad2be56d8337efe5", "price_changes": [{"asset_id": "102020588502400806287117347702632611550727753557718799166708590001374539810273", "price": "0.26", "size": "7.48", "side": "BUY", "hash": "569ec2b1d822ad6f8d73f3dd74b8950544ee773f", "best_bid": "0.69", "best_ask": "0.77"}, {"asset_id": "61649988503359407770258418097615151606970415315192585742996814749095348840604", "price": "0.74", "size": "7.48", "side": "SELL", "hash": "255c86e79a29e8e5ee27245365c9daa9335e1258", "best_bid": "0.23", "best_ask": "0.31"}], "timestamp": "1769384060551", "event_type": "price_change"}}
{"_local_timestamp": "2026-01-25T23:34:20.670042+00:00", "data": {"market": "0x4a0cc84209df8e25f2651148c15ca45841bf02133903a990ad2be56d8337efe5", "price_changes": [{"asset_id": "102020588502400806287117347702632611550727753557718799166708590001374539810273", "price": "0.31", "size": "64.51", "side": "BUY", "hash": "bb6ba8eff96481e63692f2be2c83b1cf3a562c24", "best_bid": "0.69", "best_ask": "0.77"}, {"asset_id": "61649988503359407770258418097615151606970415315192585742996814749095348840604", "price": "0.69", "size": "64.51", "side": "SELL", "hash": "2fe7f40c0a9ea06330a5e1d36a648e94afd66125", "best_bid": "0.23", "best_ask": "0.31"}], "timestamp": "1769384060601", "event_type": "price_change"}}
{"_local_timestamp": "2026-01-25T23:34:20.717209+00:00", "data": {"market": "0x4a0cc84209df8e25f2651148c15ca45841bf02133903a990ad2be56d8337efe5", "price_changes": [{"asset_id": "102020588502400806287117347702632611550727753557718799166708590001374539810273", "price": "0.27", "size": "88.88", "side": "BUY", "hash": "cbc28948f4b083be3377cadbe5048688c7a6bfa5", "best_bid": "0.69", "best_ask": "0.77"}, {"asset_id": "61649988503359407770258418097615151606970415315192585742996814749095348840604", "price": "0.73", "size": "88.88", "side": "SELL", "hash": "f7f2d12dbfd35aac36f0a59457bfd78c4a552bae", "best_bid": "0.23", "best_ask": "0.31"}], "timestamp": "1769384060649", "event_type": "price_change"}}
{"_local_timestamp": "2026-01-25T23:34:20.762484+00:00", "data": {"market": "0x4a0cc84209df8e25f2651148c15ca45841bf02133903a990ad2be56d8337efe5", "price_changes": [{"asset_id": "102020588502400806287117347702632611550727753557718799166708590001374539810273", "price": "0.23", "size": "263.04", "side": "BUY", "hash": "78c6d87fd120221cc1513863e6b15c131a48524a", "best_bid": "0.69", "best_ask": "0.77"}, {"asset_id": "61649988503359407770258418097615151606970415315192585742996814749095348840604", "price": "0.77", "size": "263.04", "side": "SELL", "hash": "481fcc5a1ecbb7b1363be15669dbed3d31be953b", "best_bid": "0.23", "best_ask": "0.31"}], "timestamp": "1769384060693", "event_type": "price_change"}}
{"_local_timestamp": "2026-01-25T23:34:20.811718+00:00", "data": {"market": "0x4a0cc84209df8e25f2651148c15ca45841bf02133903a990ad2be56d8337efe5", "price_changes": [{"asset_id": "102020588502400806287117347702632611550727753557718799166708590001374539810273", "price": "0.19", "size": "397.36", "side": "BUY", "hash": "4882625abdf3911c2b5c4bd6164f308056671047", "best_bid": "0.69", "best_ask": "0.77"}, {"asset_id": "61649988503359407770258418097615151606970415315192585742996814749095348840604", "price": "0.81", "size": "397.36", "side": "SELL", "hash": "f7ac2592e568c86bba91889a1a01aba5dde1374d", "best_bid": "0.23", "best_ask": "0.31"}], "timestamp": "1769384060746", "event_type": "price_change"}}
{"_local_timestamp": "2026-01-25T23:34:20.869379+00:00", "data": {"market": "0x4a0cc84209df8e25f2651148c15ca45841bf02133903a990ad2be56d8337efe5", "price_changes": [{"asset_id": "102020588502400806287117347702632611550727753557718799166708590001374539810273", "price": "0.15", "size": "213.33", "side": "BUY", "hash": "1ce57b89e393c599515d942e03e8e23f7e7a64bc", "best_bid": "0.69", "best_ask": "0.77"}, {"asset_id": "61649988503359407770258418097615151606970415315192585742996814749095348840604", "price": "0.85", "size": "213.33", "side": "SELL", "hash": "c3121ebf6c0824ddc4130f90edba9d9ebdad5622", "best_bid": "0.23", "best_ask": "0.31"}], "timestamp": "1769384060796", "event_type": "price_change"}}
{"_local_timestamp": "2026-01-25T23:34:20.913885+00:00", "data": {"market": "0x4a0cc84209df8e25f2651148c15ca45841bf02133903a990ad2be56d8337efe5", "price_changes": [{"asset_id": "102020588502400806287117347702632611550727753557718799166708590001374539810273", "price": "0.12", "size": "283.33", "side": "BUY", "hash": "f19ef881f051bcf687d163b4f74a6a739dd02978", "best_bid": "0.69", "best_ask": "0.77"}, {"asset_id": "61649988503359407770258418097615151606970415315192585742996814749095348840604", "price": "0.88", "size": "283.33", "side": "SELL", "hash": "3e7ebbd389ff24da8b0b53165e44779ab9aaa243", "best_bid": "0.23", "best_ask": "0.31"}], "timestamp": "1769384060846", "event_type": "price_change"}}
{"_local_timestamp": "2026-01-25T23:34:20.960643+00:00", "data": {"market": "0x4a0cc84209df8e25f2651148c15ca45841bf02133903a990ad2be56d8337efe5", "price_changes": [{"asset_id": "102020588502400806287117347702632611550727753557718799166708590001374539810273", "price": "0.08", "size": "450", "side": "BUY", "hash": "8a02b5f59aa8b8e8b717f7bd9e82a1bba6a65957", "best_bid": "0.69", "best_ask": "0.77"}, {"asset_id": "61649988503359407770258418097615151606970415315192585742996814749095348840604", "price": "0.92", "size": "450", "side": "SELL", "hash": "6726c063fadd03423116413fcd1446f6d281a047", "best_bid": "0.23", "best_ask": "0.31"}], "timestamp": "1769384060896", "event_type": "price_change"}}
{"_local_timestamp": "2026-01-25T23:34:20.999444+00:00", "data": {"market": "0xc7982ab943183b14a136538b1943a99f0b783266c46647ac5d93a53145c1a7b5", "price_changes": [{"asset_id": "13851803203597462164946196938589176900313976487295955127267529584815353328811", "price": "0.862", "size": "0", "side": "BUY", "hash": "a7004278033bbb2dc38cd36921065beb30ecd353", "best_bid": "0.99", "best_ask": "0.994"}, {"asset_id": "109831253762520485632120158952131204631888758680701510579735402842471158516644", "price": "0.138", "size": "0", "side": "SELL", "hash": "285355cce9a9584a0030cdfe9796fcf35d1560cd", "best_bid": "0.006", "best_ask": "0.01"}], "timestamp": "1769384060929", "event_type": "price_change"}}
{"_local_timestamp": "2026-01-25T23:34:21.000516+00:00", "data": {"market": "0x5ed8142bfb7dedd29123c51d93e78d41bb11347a9dc99af028f8c26d379f7991", "price_changes": [{"asset_id": "87806309463368545105535948349282475480949630203592970860801199564395401037228", "price": "0.37", "size": "35.13", "side": "BUY", "hash": "94bb6a0c091b77cde72110b0f0fa92aae85bc54f", "best_bid": "0.46", "best_ask": "0.49"}, {"asset_id": "21074627447851722982583017164862562903762903675957478566509692359288711223560", "price": "0.63", "size": "35.13", "side": "SELL", "hash": "b8c7b24d49e07231528444fbdc4a027a162eda22", "best_bid": "0.51", "best_ask": "0.54"}], "timestamp": "1769384060929", "event_type": "price_change"}}
{"_local_timestamp": "2026-01-25T23:34:21.001492+00:00", "data": {"market": "0xdf3aed600715b8cc4a23e3d7e6caad79791de8dcd5af48f450dc1b8dc52128c3", "price_changes": [{"asset_id": "115200191337492844563805575089118887672911159979117742424196868043770660979378", "price": "0.687", "size": "0", "side": "BUY", "hash": "ed40c5e7c3736e609603b6428bc8b7cfa9d24fc1", "best_bid": "0.964", "best_ask": "0.965"}, {"asset_id": "111955058608111392596805821148637930362581269673097069733693799539148925173769", "price": "0.313", "size": "0", "side": "SELL", "hash": "a1676955f1f69843266887bee5d37b0624a8aa8b", "best_bid": "0.035", "best_ask": "0.036"}], "timestamp": "1769384060929", "event_type": "price_change"}}
{"_local_timestamp": "2026-01-25T23:34:21.002443+00:00", "data": {"market": "0x90301098126f955f3ce5a03b7fe4c35a3641b233f4c56e88b11070a1b414c61a", "price_changes": [{"asset_id": "39312012332144445223325894231881456670645569993721035335222112552139635422119", "price": "0.821", "size": "0", "side": "BUY", "hash": "ed59d4e3a1f004ab7d7509a1bc5ed86f318bbc5e", "best_bid": "0.941", "best_ask": "0.952"}, {"asset_id": "79853007977105815624113941534992494565347323884772610518298707804471039732081", "price": "0.179", "size": "0", "side": "SELL", "hash": "b00e2aae941ee567ecda30ff449198e4aff55ff7", "best_bid": "0.048", "best_ask": "0.059"}], "timestamp": "1769384060929", "event_type": "price_change"}}
{"_local_timestamp": "2026-01-25T23:34:21.004003+00:00", "data": {"market": "0xad1d3f37d4b3e994cf6e345342e4c6d77b847c125d222144c583ef5c4bd2f84a", "price_changes": [{"asset_id": "77654714676170984534448970834577345438216226056033824875092030167273571185616", "price": "0.862", "size": "0", "side": "BUY", "hash": "8b59febe1a3d5e8210654ae8d98196b63b69b27f", "best_bid": "0.995", "best_ask": "0.998"}, {"asset_id": "80861576758208246291858186808740958603555626246511495793257831406422094470572", "price": "0.138", "size": "0", "side": "SELL", "hash": "aef868bfab8a471379497d53b901cdbb1401ed8f", "best_bid": "0.002", "best_ask": "0.005"}], "timestamp": "1769384060929", "event_type": "price_change"}}
{"_local_timestamp": "2026-01-25T23:34:21.011185+00:00", "data": {"market": "0xb5f410ce6db52b387d5e3c9aa386f1cf2c6d9603d4ffbb59d7b3ad78c6ce54bc", "price_changes": [{"asset_id": "30496684424734941608873174390104887181463986142171585340038809175815196271014", "price": "0.869", "size": "0", "side": "BUY", "hash": "3be56da5da51c04a2fb83cf19cd581cfc3112dde", "best_bid": "0.991", "best_ask": "0.992"}, {"asset_id": "90311555114079332121873713225331719655517167698979277482922143777516026157644", "price": "0.131", "size": "0", "side": "SELL", "hash": "b57cd1dbc888c221380dc08b2eb8731777785f7e", "best_bid": "0.008", "best_ask": "0.009"}], "timestamp": "1769384060929", "event_type": "price_change"}}
{"_local_timestamp": "2026-01-25T23:34:21.016115+00:00", "data": {"market": "0x9203a698f9fa14be61cfdb6bfef9deddd0aa7d2b2907d93a619702683087b3da", "price_changes": [{"asset_id": "90609029279195192521610502880224098677548237969581172515290357666786312674233", "price": "0.87", "size": "0", "side": "BUY", "hash": "d0d1678f6e513f430621d80218605d884cd7a3fe", "best_bid": "0.989", "best_ask": "0.997"}, {"asset_id": "78105936059580066886637010200879176612465407936158598378531832410898792072331", "price": "0.13", "size": "0", "side": "SELL", "hash": "436c64ef4a73624278dd2a8404289d545f844121", "best_bid": "0.003", "best_ask": "0.011"}], "timestamp": "1769384060929", "event_type": "price_change"}}
{"_local_timestamp": "2026-01-25T23:34:21.029476+00:00", "data": {"market": "0xdf3aed600715b8cc4a23e3d7e6caad79791de8dcd5af48f450dc1b8dc52128c3", "price_changes": [{"asset_id": "115200191337492844563805575089118887672911159979117742424196868043770660979378", "price": "0.689", "size": "20", "side": "BUY", "hash": "82911c0260d306d5d933314ebffa2ecd7c3110fb", "best_bid": "0.964", "best_ask": "0.965"}, {"asset_id": "111955058608111392596805821148637930362581269673097069733693799539148925173769", "price": "0.311", "size": "20", "side": "SELL", "hash": "90e1e1c606b789a87f63a9332d78de99b22f8a90", "best_bid": "0.035", "best_ask": "0.036"}], "timestamp": "1769384060964", "event_type": "price_change"}}
{"_local_timestamp": "2026-01-25T23:34:21.030194+00:00", "data": {"market": "0xc7982ab943183b14a136538b1943a99f0b783266c46647ac5d93a53145c1a7b5", "price_changes": [{"asset_id": "13851803203597462164946196938589176900313976487295955127267529584815353328811", "price": "0.856", "size": "33.33", "side": "BUY", "hash": "8e64746d956c1d3a02ee6038713822baf50e6c7e", "best_bid": "0.99", "best_ask": "0.994"}, {"asset_id": "109831253762520485632120158952131204631888758680701510579735402842471158516644", "price": "0.144", "size": "33.33", "side": "SELL", "hash": "cbc088616d9346ba48f3bce2107df22281c2e0aa", "best_bid": "0.006", "best_ask": "0.01"}], "timestamp": "1769384060964", "event_type": "price_change"}}
{"_local_timestamp": "2026-01-25T23:34:21.031298+00:00", "data": {"market": "0x5ed8142bfb7dedd29123c51d93e78d41bb11347a9dc99af028f8c26d379f7991", "price_changes": [{"asset_id": "87806309463368545105535948349282475480949630203592970860801199564395401037228", "price": "0.35", "size": "35.11", "side": "BUY", "hash": "2ecc47d983a0036cf0759b8ad4d1a80993d23a11", "best_bid": "0.46", "best_ask": "0.49"}, {"asset_id": "21074627447851722982583017164862562903762903675957478566509692359288711223560", "price": "0.65", "size": "35.11", "side": "SELL", "hash": "819a0f38b62ea34711f97bb584a7b784cd584de9", "best_bid": "0.51", "best_ask": "0.54"}], "timestamp": "1769384060964", "event_type": "price_change"}}
{"_local_timestamp": "2026-01-25T23:34:21.032143+00:00", "data": {"market": "0xb5f410ce6db52b387d5e3c9aa386f1cf2c6d9603d4ffbb59d7b3ad78c6ce54bc", "price_changes": [{"asset_id": "30496684424734941608873174390104887181463986142171585340038809175815196271014", "price": "0.515", "size": "20", "side": "BUY", "hash": "7bb602d9eaa672226d35e23d9bbba7218bc378fd", "best_bid": "0.991", "best_ask": "0.992"}, {"asset_id": "90311555114079332121873713225331719655517167698979277482922143777516026157644", "price": "0.485", "size": "20", "side": "SELL", "hash": "a64addefaae3c78db27b6ea9668afe882e7eb0db", "best_bid": "0.008", "best_ask": "0.009"}], "timestamp": "1769384060964", "event_type": "price_change"}}
{"_local_timestamp": "2026-01-25T23:34:21.032590+00:00", "data": {"market": "0xad1d3f37d4b3e994cf6e345342e4c6d77b847c125d222144c583ef5c4bd2f84a", "price_changes": [{"asset_id": "77654714676170984534448970834577345438216226056033824875092030167273571185616", "price": "0.86", "size": "20", "side": "BUY", "hash": "2e6371057307e82073d7fff09a3e08073cfcdc67", "best_bid": "0.995", "best_ask": "0.998"}, {"asset_id": "80861576758208246291858186808740958603555626246511495793257831406422094470572", "price": "0.14", "size": "20", "side": "SELL", "hash": "f5e46ab2a4aba8ad1ad17315876d004904f5bd07", "best_bid": "0.002", "best_ask": "0.005"}], "timestamp": "1769384060964", "event_type": "price_change"}}
{"_local_timestamp": "2026-01-25T23:34:21.033070+00:00", "data": {"market": "0x90301098126f955f3ce5a03b7fe4c35a3641b233f4c56e88b11070a1b414c61a", "price_changes": [{"asset_id": "39312012332144445223325894231881456670645569993721035335222112552139635422119", "price": "0.803", "size": "20", "side": "BUY", "hash": "c6e18ebced83386f530d38325a809565e1194668", "best_bid": "0.941", "best_ask": "0.952"}, {"asset_id": "79853007977105815624113941534992494565347323884772610518298707804471039732081", "price": "0.197", "size": "20", "side": "SELL", "hash": "4d38270ce368bbfafa28ba2d916334e615ab7523", "best_bid": "0.048", "best_ask": "0.059"}], "timestamp": "1769384060964", "event_type": "price_change"}}
{"_local_timestamp": "2026-01-25T23:34:21.035875+00:00", "data": {"market": "0x9203a698f9fa14be61cfdb6bfef9deddd0aa7d2b2907d93a619702683087b3da", "price_changes": [{"asset_id": "90609029279195192521610502880224098677548237969581172515290357666786312674233", "price": "0.855", "size": "20", "side": "BUY", "hash": "f19e7704046753920186edc7e78a5ecc5c2539aa", "best_bid": "0.989", "best_ask": "0.997"}, {"asset_id": "78105936059580066886637010200879176612465407936158598378531832410898792072331", "price": "0.145", "size": "20", "side": "SELL", "hash": "0513585999357484b1ecdc0362bfaffce75fecb3", "best_bid": "0.003", "best_ask": "0.011"}], "timestamp": "1769384060964", "event_type": "price_change"}}
{"_local_timestamp": "2026-01-25T23:34:25.575710+00:00", "data": {"market": "0x4a0cc84209df8e25f2651148c15ca45841bf02133903a990ad2be56d8337efe5", "price_changes": [{"asset_id": "61649988503359407770258418097615151606970415315192585742996814749095348840604", "price": "0.23", "size": "67", "side": "BUY", "hash": "c41fd60d33ce385a7ea45dbfb7b7af6a684c0410", "best_bid": "0.23", "best_ask": "0.31"}, {"asset_id": "102020588502400806287117347702632611550727753557718799166708590001374539810273", "price": "0.77", "size": "67", "side": "SELL", "hash": "20dc2c3d66f87c912d9031aaf10d3d7ba4f5a107", "best_bid": "0.69", "best_ask": "0.77"}], "timestamp": "1769384065468", "event_type": "price_change"}}
{"_local_timestamp": "2026-01-25T23:34:26.694202+00:00", "data": {"market": "0x4a0cc84209df8e25f2651148c15ca45841bf02133903a990ad2be56d8337efe5", "price_changes": [{"asset_id": "61649988503359407770258418097615151606970415315192585742996814749095348840604", "price": "0.22", "size": "130.38", "side": "BUY", "hash": "24a1642b10562703cfe9b2f540d7290450446e23", "best_bid": "0.23", "best_ask": "0.31"}, {"asset_id": "102020588502400806287117347702632611550727753557718799166708590001374539810273", "price": "0.78", "size": "130.38", "side": "SELL", "hash": "77de973b1f9227329a73759c57b364b4ae14ea46", "best_bid": "0.69", "best_ask": "0.77"}], "timestamp": "1769384066590", "event_type": "price_change"}}
{"_local_timestamp": "2026-01-25T23:34:26.757665+00:00", "data": {"market": "0x4a0cc84209df8e25f2651148c15ca45841bf02133903a990ad2be56d8337efe5", "price_changes": [{"asset_id": "61649988503359407770258418097615151606970415315192585742996814749095348840604", "price": "0.23", "size": "97", "side": "BUY", "hash": "9833d40ae6298bd7e1328d28d2a610011f9220d6", "best_bid": "0.23", "best_ask": "0.31"}, {"asset_id": "102020588502400806287117347702632611550727753557718799166708590001374539810273", "price": "0.77", "size": "97", "side": "SELL", "hash": "a68d7055435f501a092fcf2df289344c5a7816f9", "best_bid": "0.69", "best_ask": "0.77"}], "timestamp": "1769384066688", "event_type": "price_change"}}
{"_local_timestamp": "2026-01-25T23:34:38.970632+00:00", "data": {"market": "0x4a0cc84209df8e25f2651148c15ca45841bf02133903a990ad2be56d8337efe5", "price_changes": [{"asset_id": "102020588502400806287117347702632611550727753557718799166708590001374539810273", "price": "0.07", "size": "200", "side": "BUY", "hash": "2429ddfeba5efe12e45f10d62a6fd08ccb1c7659", "best_bid": "0.69", "best_ask": "0.77"}, {"asset_id": "61649988503359407770258418097615151606970415315192585742996814749095348840604", "price": "0.93", "size": "200", "side": "SELL", "hash": "3d575f8adf197bcc00ee43358017c2dd6cf8dc6a", "best_bid": "0.23", "best_ask": "0.31"}], "timestamp": "1769384078900", "event_type": "price_change"}}
{"_local_timestamp": "2026-01-25T23:34:39.161715+00:00", "data": {"market": "0xdf3aed600715b8cc4a23e3d7e6caad79791de8dcd5af48f450dc1b8dc52128c3", "price_changes": [{"asset_id": "115200191337492844563805575089118887672911159979117742424196868043770660979378", "price": "0.681", "size": "0", "side": "BUY", "hash": "98f2eb24587c63ed9c9befd992477ead10b2c31e", "best_bid": "0.964", "best_ask": "0.965"}, {"asset_id": "111955058608111392596805821148637930362581269673097069733693799539148925173769", "price": "0.319", "size": "0", "side": "SELL", "hash": "644b5a11d8acafb32fa1e0912014eae7fa093349", "best_bid": "0.035", "best_ask": "0.036"}], "timestamp": "1769384079064", "event_type": "price_change"}}
{"_local_timestamp": "2026-01-25T23:34:39.162247+00:00", "data": {"market": "0xad1d3f37d4b3e994cf6e345342e4c6d77b847c125d222144c583ef5c4bd2f84a", "price_changes": [{"asset_id": "77654714676170984534448970834577345438216226056033824875092030167273571185616", "price": "0.764", "size": "0", "side": "BUY", "hash": "e899a76eaed79e46d10d500149300c712817692e", "best_bid": "0.995", "best_ask": "0.998"}, {"asset_id": "80861576758208246291858186808740958603555626246511495793257831406422094470572", "price": "0.236", "size": "0", "side": "SELL", "hash": "0eb7d8a831bc5cf165f70032fbcfa3b82b81f284", "best_bid": "0.002", "best_ask": "0.005"}], "timestamp": "1769384079064", "event_type": "price_change"}}
{"_local_timestamp": "2026-01-25T23:34:39.305170+00:00", "data": {"market": "0x4a0cc84209df8e25f2651148c15ca45841bf02133903a990ad2be56d8337efe5", "price_changes": [{"asset_id": "102020588502400806287117347702632611550727753557718799166708590001374539810273", "price": "0.08", "size": "550", "side": "BUY", "hash": "67598897c4e1d1b5f904f0b6b31f7f317ba5c76f", "best_bid": "0.69", "best_ask": "0.77"}, {"asset_id": "61649988503359407770258418097615151606970415315192585742996814749095348840604", "price": "0.92", "size": "550", "side": "SELL", "hash": "046fd8b7b1f1c9738603bcc2b0542a8cbba1d771", "best_bid": "0.23", "best_ask": "0.31"}], "timestamp": "1769384079183", "event_type": "price_change"}}
{"_local_timestamp": "2026-01-25T23:34:39.331316+00:00", "data": {"market": "0xdf3aed600715b8cc4a23e3d7e6caad79791de8dcd5af48f450dc1b8dc52128c3", "price_changes": [{"asset_id": "115200191337492844563805575089118887672911159979117742424196868043770660979378", "price": "0.686", "size": "0", "side": "BUY", "hash": "32037f70ce524102f8f61d7dbda0af4a0a620455", "best_bid": "0.964", "best_ask": "0.965"}, {"asset_id": "111955058608111392596805821148637930362581269673097069733693799539148925173769", "price": "0.314", "size": "0", "side": "SELL", "hash": "b33350030c77036fe53a38088a520e9b81a25bee", "best_bid": "0.035", "best_ask": "0.036"}], "timestamp": "1769384079202", "event_type": "price_change"}}
{"_local_timestamp": "2026-01-25T23:34:39.366138+00:00", "data": {"market": "0xdf3aed600715b8cc4a23e3d7e6caad79791de8dcd5af48f450dc1b8dc52128c3", "price_changes": [{"asset_id": "115200191337492844563805575089118887672911159979117742424196868043770660979378", "price": "0.69", "size": "10", "side": "BUY", "hash": "e31005a22b81c5c6e66052f96d8ea182c48f99eb", "best_bid": "0.964", "best_ask": "0.965"}, {"asset_id": "111955058608111392596805821148637930362581269673097069733693799539148925173769", "price": "0.31", "size": "10", "side": "SELL", "hash": "a5c498e42054dc337d2c344eca66c19d794f4cb6", "best_bid": "0.035", "best_ask": "0.036"}], "timestamp": "1769384079234", "event_type": "price_change"}}
{"_local_timestamp": "2026-01-25T23:34:39.372225+00:00", "data": {"market": "0xad1d3f37d4b3e994cf6e345342e4c6d77b847c125d222144c583ef5c4bd2f84a", "price_changes": [{"asset_id": "77654714676170984534448970834577345438216226056033824875092030167273571185616", "price": "0.862", "size": "10", "side": "BUY", "hash": "a150284e64e52f4f26875bd3b227fa96e8b50588", "best_bid": "0.995", "best_ask": "0.998"}, {"asset_id": "80861576758208246291858186808740958603555626246511495793257831406422094470572", "price": "0.138", "size": "10", "side": "SELL", "hash": "f4a324617a5efaba8813d7be01a89f65aeddfccb", "best_bid": "0.002", "best_ask": "0.005"}], "timestamp": "1769384079235", "event_type": "price_change"}}
{"_local_timestamp": "2026-01-25T23:34:39.373309+00:00", "data": {"market": "0xdf3aed600715b8cc4a23e3d7e6caad79791de8dcd5af48f450dc1b8dc52128c3", "price_changes": [{"asset_id": "115200191337492844563805575089118887672911159979117742424196868043770660979378", "price": "0.69", "size": "174", "side": "BUY", "hash": "79a26fb10f62ba5ae5682f6c9fc032788ade3cdd", "best_bid": "0.964", "best_ask": "0.965"}, {"asset_id": "111955058608111392596805821148637930362581269673097069733693799539148925173769", "price": "0.31", "size": "174", "side": "SELL", "hash": "bc8616eb7baf70a2519da44107e318fa04c46696", "best_bid": "0.035", "best_ask": "0.036"}], "timestamp": "1769384079237", "event_type": "price_change"}}
{"_local_timestamp": "2026-01-25T23:34:39.474491+00:00", "data": {"market": "0xdf3aed600715b8cc4a23e3d7e6caad79791de8dcd5af48f450dc1b8dc52128c3", "price_changes": [{"asset_id": "115200191337492844563805575089118887672911159979117742424196868043770660979378", "price": "0.69", "size": "204", "side": "BUY", "hash": "78116c174b1a01507c190d568359ebcf9230c221", "best_bid": "0.964", "best_ask": "0.965"}, {"asset_id": "111955058608111392596805821148637930362581269673097069733693799539148925173769", "price": "0.31", "size": "204", "side": "SELL", "hash": "7d9452edf8847923146a28b6a366e66970833644", "best_bid": "0.035", "best_ask": "0.036"}], "timestamp": "1769384079388", "event_type": "price_change"}}
{"_local_timestamp": "2026-01-25T23:34:39.475094+00:00", "data": {"market": "0xdf3aed600715b8cc4a23e3d7e6caad79791de8dcd5af48f450dc1b8dc52128c3", "price_changes": [{"asset_id": "115200191337492844563805575089118887672911159979117742424196868043770660979378", "price": "0.685", "size": "0", "side": "BUY", "hash": "79ef60d4c353bb43db94098f28ddab31de5a0733", "best_bid": "0.964", "best_ask": "0.965"}, {"asset_id": "111955058608111392596805821148637930362581269673097069733693799539148925173769", "price": "0.315", "size": "0", "side": "SELL", "hash": "d39a5bf36a2b43447b639b0abfb44cd20a2aa68f", "best_bid": "0.035", "best_ask": "0.036"}], "timestamp": "1769384079389", "event_type": "price_change"}}
{"_local_timestamp": "2026-01-25T23:34:39.492901+00:00", "data": {"market": "0xad1d3f37d4b3e994cf6e345342e4c6d77b847c125d222144c583ef5c4bd2f84a", "price_changes": [{"asset_id": "77654714676170984534448970834577345438216226056033824875092030167273571185616", "price": "0.859", "size": "0", "side": "BUY", "hash": "f8d87e5c8f564a28d0cb393abc5e68239c5fe48d", "best_bid": "0.995", "best_ask": "0.998"}, {"asset_id": "80861576758208246291858186808740958603555626246511495793257831406422094470572", "price": "0.141", "size": "0", "side": "SELL", "hash": "29869f3e9e4cbbff73ac9fbee12db7e7b33ebfbd", "best_bid": "0.002", "best_ask": "0.005"}], "timestamp": "1769384079386", "event_type": "price_change"}}
{"_local_timestamp": "2026-01-25T23:34:39.582068+00:00", "data": {"market": "0xad1d3f37d4b3e994cf6e345342e4c6d77b847c125d222144c583ef5c4bd2f84a", "price_changes": [{"asset_id": "77654714676170984534448970834577345438216226056033824875092030167273571185616", "price": "0.861", "size": "50", "side": "BUY", "hash": "1bdec9942f3d866890f7ae0c843c99ca8657c41a", "best_bid": "0.995", "best_ask": "0.998"}, {"asset_id": "80861576758208246291858186808740958603555626246511495793257831406422094470572", "price": "0.139", "size": "50", "side": "SELL", "hash": "da5f10e0e5fe073ff9f09d3f3e438cceb7fef486", "best_bid": "0.002", "best_ask": "0.005"}], "timestamp": "1769384079513", "event_type": "price_change"}}
{"_local_timestamp": "2026-01-25T23:34:39.582770+00:00", "data": {"market": "0xdf3aed600715b8cc4a23e3d7e6caad79791de8dcd5af48f450dc1b8dc52128c3", "price_changes": [{"asset_id": "115200191337492844563805575089118887672911159979117742424196868043770660979378", "price": "0.691", "size": "20", "side": "BUY", "hash": "a136e79aca8960759ab10977492f7b4b29b240d4", "best_bid": "0.964", "best_ask": "0.965"}, {"asset_id": "111955058608111392596805821148637930362581269673097069733693799539148925173769", "price": "0.309", "size": "20", "side": "SELL", "hash": "eca6950e5448fce39b4dfd4c5b095b6c0bc3d0c0", "best_bid": "0.035", "best_ask": "0.036"}], "timestamp": "1769384079513", "event_type": "price_change"}}
{"_local_timestamp": "2026-01-25T23:34:42.993137+00:00", "data": {"market": "0xdf3aed600715b8cc4a23e3d7e6caad79791de8dcd5af48f450dc1b8dc52128c3", "price_changes": [{"asset_id": "115200191337492844563805575089118887672911159979117742424196868043770660979378", "price": "0.689", "size": "0", "side": "BUY", "hash": "bd7203cd4e405a352c0e07e863f67d2083246abc", "best_bid": "0.964", "best_ask": "0.965"}, {"asset_id": "111955058608111392596805821148637930362581269673097069733693799539148925173769", "price": "0.311", "size": "0", "side": "SELL", "hash": "86f3f299655ffcb9e0f10bee2edfc121cb560640", "best_bid": "0.035", "best_ask": "0.036"}], "timestamp": "1769384082904", "event_type": "price_change"}}
{"_local_timestamp": "2026-01-25T23:34:42.993744+00:00", "data": {"market": "0xad1d3f37d4b3e994cf6e345342e4c6d77b847c125d222144c583ef5c4bd2f84a", "price_changes": [{"asset_id": "77654714676170984534448970834577345438216226056033824875092030167273571185616", "price": "0.86", "size": "0", "side": "BUY", "hash": "970760a69ff654dcb1bb1f58955286e7e0cf095c", "best_bid": "0.995", "best_ask": "0.998"}, {"asset_id": "80861576758208246291858186808740958603555626246511495793257831406422094470572", "price": "0.14", "size": "0", "side": "SELL", "hash": "2b9ef1e8a5e222548bfafad3f5ff7fe3c2bc7644", "best_bid": "0.002", "best_ask": "0.005"}], "timestamp": "1769384082904", "event_type": "price_change"}}
{"_local_timestamp": "2026-01-25T23:34:43.057597+00:00", "data": {"market": "0xdf3aed600715b8cc4a23e3d7e6caad79791de8dcd5af48f450dc1b8dc52128c3", "price_changes": [{"asset_id": "115200191337492844563805575089118887672911159979117742424196868043770660979378", "price": "0.692", "size": "20", "side": "BUY", "hash": "0c01fc1e252ed47fb965af07096dc63a48831fd4", "best_bid": "0.964", "best_ask": "0.965"}, {"asset_id": "111955058608111392596805821148637930362581269673097069733693799539148925173769", "price": "0.308", "size": "20", "side": "SELL", "hash": "c736f00364f9a0822132996e8c0a9d82654f20f2", "best_bid": "0.035", "best_ask": "0.036"}], "timestamp": "1769384082991", "event_type": "price_change"}}
{"_local_timestamp": "2026-01-25T23:34:43.058203+00:00", "data": {"market": "0xad1d3f37d4b3e994cf6e345342e4c6d77b847c125d222144c583ef5c4bd2f84a", "price_changes": [{"asset_id": "77654714676170984534448970834577345438216226056033824875092030167273571185616", "price": "0.858", "size": "20", "side": "BUY", "hash": "e8d233cc258523ce606bf092513edc0bf3fae6b8", "best_bid": "0.995", "best_ask": "0.998"}, {"asset_id": "80861576758208246291858186808740958603555626246511495793257831406422094470572", "price": "0.142", "size": "20", "side": "SELL", "hash": "d7eff9996998032094a40b75cb6079b0c88f0714", "best_bid": "0.002", "best_ask": "0.005"}], "timestamp": "1769384082991", "event_type": "price_change"}}
{"_local_timestamp": "2026-01-25T23:34:43.182903+00:00", "data": {"market": "0x90301098126f955f3ce5a03b7fe4c35a3641b233f4c56e88b11070a1b414c61a", "price_changes": [{"asset_id": "39312012332144445223325894231881456670645569993721035335222112552139635422119", "price": "0.801", "size": "0", "side": "BUY", "hash": "15ec1b45bfa358e1a79d9cee6866277c4d974b11", "best_bid": "0.941", "best_ask": "0.952"}, {"asset_id": "79853007977105815624113941534992494565347323884772610518298707804471039732081", "price": "0.199", "size": "0", "side": "SELL", "hash": "8f3844370757621e0d71c41804681a4a3a1019e0", "best_bid": "0.048", "best_ask": "0.059"}], "timestamp": "1769384083111", "event_type": "price_change"}}
{"_local_timestamp": "2026-01-25T23:34:43.345001+00:00", "data": {"market": "0x90301098126f955f3ce5a03b7fe4c35a3641b233f4c56e88b11070a1b414c61a", "price_changes": [{"asset_id": "39312012332144445223325894231881456670645569993721035335222112552139635422119", "price": "0.804", "size": "20", "side": "BUY", "hash": "1ebfe643078d8891001308ec8b3a6eb34b09a3be", "best_bid": "0.941", "best_ask": "0.952"}, {"asset_id": "79853007977105815624113941534992494565347323884772610518298707804471039732081", "price": "0.196", "size": "20", "side": "SELL", "hash": "694553f3053fb2e58df4ccca8b80af52a7cb3d6c", "best_bid": "0.048", "best_ask": "0.059"}], "timestamp": "1769384083275", "event_type": "price_change"}}
{"_local_timestamp": "2026-01-25T23:34:47.109428+00:00", "data": {"market": "0x90301098126f955f3ce5a03b7fe4c35a3641b233f4c56e88b11070a1b414c61a", "price_changes": [{"asset_id": "39312012332144445223325894231881456670645569993721035335222112552139635422119", "price": "0.803", "size": "0", "side": "BUY", "hash": "292d49742a020da8177a3a92441b9141a0c059e1", "best_bid": "0.941", "best_ask": "0.952"}, {"asset_id": "79853007977105815624113941534992494565347323884772610518298707804471039732081", "price": "0.197", "size": "0", "side": "SELL", "hash": "a1d2559feaaf5f133f4378c8ac100b63864f7352", "best_bid": "0.048", "best_ask": "0.059"}], "timestamp": "1769384087022", "event_type": "price_change"}}
{"_local_timestamp": "2026-01-25T23:34:47.120828+00:00", "data": {"market": "0x90301098126f955f3ce5a03b7fe4c35a3641b233f4c56e88b11070a1b414c61a", "price_changes": [{"asset_id": "39312012332144445223325894231881456670645569993721035335222112552139635422119", "price": "0.805", "size": "20", "side": "BUY", "hash": "1e8b802f9e7ecf6d9aacadccd8d7269acb3cd8b5", "best_bid": "0.941", "best_ask": "0.952"}, {"asset_id": "79853007977105815624113941534992494565347323884772610518298707804471039732081", "price": "0.195", "size": "20", "side": "SELL", "hash": "75d5a98fa5b2d369467caacebd82296b5588fc71", "best_bid": "0.048", "best_ask": "0.059"}], "timestamp": "1769384087051", "event_type": "price_change"}}
{"_local_timestamp": "2026-01-25T23:35:02.881867+00:00", "data": {"market": "0x4a0cc84209df8e25f2651148c15ca45841bf02133903a990ad2be56d8337efe5", "price_changes": [{"asset_id": "102020588502400806287117347702632611550727753557718799166708590001374539810273", "price": "0.66", "size": "99.09", "side": "BUY", "hash": "4d88d91cc17db7a16da2870714b577fd3d7a5d39", "best_bid": "0.69", "best_ask": "0.77"}, {"asset_id": "61649988503359407770258418097615151606970415315192585742996814749095348840604", "price": "0.34", "size": "99.09", "side": "SELL", "hash": "36bccaad52481323ebfc995ffd040225a3aaaf73", "best_bid": "0.23", "best_ask": "0.31"}], "timestamp": "1769384102810", "event_type": "price_change"}}
{"_local_timestamp": "2026-01-25T23:35:02.884017+00:00", "data": {"market": "0x4a0cc84209df8e25f2651148c15ca45841bf02133903a990ad2be56d8337efe5", "price_changes": [{"asset_id": "102020588502400806287117347702632611550727753557718799166708590001374539810273", "price": "0.61", "size": "55.45", "side": "BUY", "hash": "4d88d91cc17db7a16da2870714b577fd3d7a5d39", "best_bid": "0.69", "best_ask": "0.77"}, {"asset_id": "61649988503359407770258418097615151606970415315192585742996814749095348840604", "price": "0.39", "size": "55.45", "side": "SELL", "hash": "36bccaad52481323ebfc995ffd040225a3aaaf73", "best_bid": "0.23", "best_ask": "0.31"}], "timestamp": "1769384102810", "event_type": "price_change"}}
{"_local_timestamp": "2026-01-25T23:35:02.884617+00:00", "data": {"market": "0x4a0cc84209df8e25f2651148c15ca45841bf02133903a990ad2be56d8337efe5", "price_changes": [{"asset_id": "61649988503359407770258418097615151606970415315192585742996814749095348840604", "price": "0.18", "size": "0", "side": "BUY", "hash": "236da9a4c24a7ddfdb8d7243dcaa939ff8a743b2", "best_bid": "0.23", "best_ask": "0.31"}, {"asset_id": "102020588502400806287117347702632611550727753557718799166708590001374539810273", "price": "0.82", "size": "0", "side": "SELL", "hash": "cb0e3f3c692fe8c07978228b5ee6e4a999aff150", "best_bid": "0.69", "best_ask": "0.77"}], "timestamp": "1769384102810", "event_type": "price_change"}}
{"_local_timestamp": "2026-01-25T23:35:02.885378+00:00", "data": {"market": "0x4a0cc84209df8e25f2651148c15ca45841bf02133903a990ad2be56d8337efe5", "price_changes": [{"asset_id": "61649988503359407770258418097615151606970415315192585742996814749095348840604", "price": "0.09", "size": "0", "side": "BUY", "hash": "236da9a4c24a7ddfdb8d7243dcaa939ff8a743b2", "best_bid": "0.23", "best_ask": "0.31"}, {"asset_id": "102020588502400806287117347702632611550727753557718799166708590001374539810273", "price": "0.91", "size": "0", "side": "SELL", "hash": "cb0e3f3c692fe8c07978228b5ee6e4a999aff150", "best_bid": "0.69", "best_ask": "0.77"}], "timestamp": "1769384102810", "event_type": "price_change"}}
{"_local_timestamp": "2026-01-25T23:35:03.138361+00:00", "data": {"market": "0xdf3aed600715b8cc4a23e3d7e6caad79791de8dcd5af48f450dc1b8dc52128c3", "price_changes": [{"asset_id": "115200191337492844563805575089118887672911159979117742424196868043770660979378", "price": "0.69", "size": "40", "side": "BUY", "hash": "cfb13ceb49ae6053d5542fc8bd8ba459ae4e89e8", "best_bid": "0.964", "best_ask": "0.965"}, {"asset_id": "111955058608111392596805821148637930362581269673097069733693799539148925173769", "price": "0.31", "size": "40", "side": "SELL", "hash": "01c28dd11215cad0a0f7e08095bd4ecde4ad91bd", "best_bid": "0.035", "best_ask": "0.036"}], "timestamp": "1769384103073", "event_type": "price_change"}}
{"_local_timestamp": "2026-01-25T23:35:03.138962+00:00", "data": {"market": "0x90301098126f955f3ce5a03b7fe4c35a3641b233f4c56e88b11070a1b414c61a", "price_changes": [{"asset_id": "39312012332144445223325894231881456670645569993721035335222112552139635422119", "price": "0.651", "size": "0", "side": "BUY", "hash": "8c407bd79708083625169675dd470f09a84759e0", "best_bid": "0.941", "best_ask": "0.952"}, {"asset_id": "79853007977105815624113941534992494565347323884772610518298707804471039732081", "price": "0.349", "size": "0", "side": "SELL", "hash": "364b084c57d509a7413063283c3fc4c96cdf3fec", "best_bid": "0.048", "best_ask": "0.059"}], "timestamp": "1769384103073", "event_type": "price_change"}}
{"_local_timestamp": "2026-01-25T23:35:03.337620+00:00", "data": {"market": "0x90301098126f955f3ce5a03b7fe4c35a3641b233f4c56e88b11070a1b414c61a", "price_changes": [{"asset_id": "39312012332144445223325894231881456670645569993721035335222112552139635422119", "price": "0.806", "size": "10", "side": "BUY", "hash": "f0bb15cf8bbb1b3f75b0c9a6083f9aa963deac83", "best_bid": "0.941", "best_ask": "0.952"}, {"asset_id": "79853007977105815624113941534992494565347323884772610518298707804471039732081", "price": "0.194", "size": "10", "side": "SELL", "hash": "e1c35a65643979db0728db1b9510fe8b6c55b3e6", "best_bid": "0.048", "best_ask": "0.059"}], "timestamp": "1769384103266", "event_type": "price_change"}}
{"_local_timestamp": "2026-01-25T23:35:03.449880+00:00", "data": {"market": "0x4a0cc84209df8e25f2651148c15ca45841bf02133903a990ad2be56d8337efe5", "price_changes": [{"asset_id": "102020588502400806287117347702632611550727753557718799166708590001374539810273", "price": "0.7", "size": "66.66", "side": "BUY", "hash": "674995ef241fa8e77efd1afbb1e44439617ad7f2", "best_bid": "0.7", "best_ask": "0.77"}, {"asset_id": "61649988503359407770258418097615151606970415315192585742996814749095348840604", "price": "0.3", "size": "66.66", "side": "SELL", "hash": "95f25b7ef3b133c53a9fab70f1e9c8f739e4fd36", "best_bid": "0.23", "best_ask": "0.3"}], "timestamp": "1769384103385", "event_type": "price_change"}}
{"_local_timestamp": "2026-01-25T23:35:03.465273+00:00", "data": {"market": "0x4a0cc84209df8e25f2651148c15ca45841bf02133903a990ad2be56d8337efe5", "price_changes": [{"asset_id": "61649988503359407770258418097615151606970415315192585742996814749095348840604", "price": "0.24", "size": "66.66", "side": "BUY", "hash": "ff48647152b0d42f095fe7e8e7ec48dae19dd670", "best_bid": "0.24", "best_ask": "0.3"}, {"asset_id": "102020588502400806287117347702632611550727753557718799166708590001374539810273", "price": "0.76", "size": "66.66", "side": "SELL", "hash": "1c6360ae4e1d92520b5a641f48e7e5737c6a944a", "best_bid": "0.7", "best_ask": "0.76"}], "timestamp": "1769384103398", "event_type": "price_change"}}
{"_local_timestamp": "2026-01-25T23:35:03.541150+00:00", "data": {"market": "0x4a0cc84209df8e25f2651148c15ca45841bf02133903a990ad2be56d8337efe5", "price_changes": [{"asset_id": "102020588502400806287117347702632611550727753557718799166708590001374539810273", "price": "0.65", "size": "66.66", "side": "BUY", "hash": "78f34bb974761a4cd1248c1f1f6c30a4bf438f55", "best_bid": "0.7", "best_ask": "0.76"}, {"asset_id": "61649988503359407770258418097615151606970415315192585742996814749095348840604", "price": "0.35", "size": "66.66", "side": "SELL", "hash": "f5b8a895a51ad89338e232bb49f94144025530a8", "best_bid": "0.24", "best_ask": "0.3"}], "timestamp": "1769384103471", "event_type": "price_change"}}
{"_local_timestamp": "2026-01-25T23:35:03.621395+00:00", "data": {"market": "0x4a0cc84209df8e25f2651148c15ca45841bf02133903a990ad2be56d8337efe5", "price_changes": [{"asset_id": "102020588502400806287117347702632611550727753557718799166708590001374539810273", "price": "0.61", "size": "122.11", "side": "BUY", "hash": "2aa53000e0fceadc5710df34e1d2136a75a88e5a", "best_bid": "0.7", "best_ask": "0.76"}, {"asset_id": "61649988503359407770258418097615151606970415315192585742996814749095348840604", "price": "0.39", "size": "122.11", "side": "SELL", "hash": "a61b9fa99a82cbc5397499134160552a0ebfba26", "best_bid": "0.24", "best_ask": "0.3"}], "timestamp": "1769384103557", "event_type": "price_change"}}
{"_local_timestamp": "2026-01-25T23:35:03.626355+00:00", "data": {"market": "0x4a0cc84209df8e25f2651148c15ca45841bf02133903a990ad2be56d8337efe5", "price_changes": [{"asset_id": "61649988503359407770258418097615151606970415315192585742996814749095348840604", "price": "0.16", "size": "66.66", "side": "BUY", "hash": "5917624b2aa6f5f538661d54b78db92a1bc14151", "best_bid": "0.24", "best_ask": "0.3"}, {"asset_id": "102020588502400806287117347702632611550727753557718799166708590001374539810273", "price": "0.84", "size": "66.66", "side": "SELL", "hash": "8e5befa0a3850f1fd6dad84c6957e4cff05a50ca", "best_bid": "0.7", "best_ask": "0.76"}], "timestamp": "1769384103560", "event_type": "price_change"}}
{"_local_timestamp": "2026-01-25T23:35:03.644964+00:00", "data": {"market": "0x5ed8142bfb7dedd29123c51d93e78d41bb11347a9dc99af028f8c26d379f7991", "price_changes": [{"asset_id": "87806309463368545105535948349282475480949630203592970860801199564395401037228", "price": "0.33", "size": "0", "side": "BUY", "hash": "1d3b70bc25586ecbacb0dc58b5b5af08eca0083a", "best_bid": "0.46", "best_ask": "0.49"}, {"asset_id": "21074627447851722982583017164862562903762903675957478566509692359288711223560", "price": "0.67", "size": "0", "side": "SELL", "hash": "119f2efdc8ba6730b70241585223e0e8f08ed767", "best_bid": "0.51", "best_ask": "0.54"}], "timestamp": "1769384103580", "event_type": "price_change"}}
{"_local_timestamp": "2026-01-25T23:35:03.648515+00:00", "data": {"market": "0xad1d3f37d4b3e994cf6e345342e4c6d77b847c125d222144c583ef5c4bd2f84a", "price_changes": [{"asset_id": "77654714676170984534448970834577345438216226056033824875092030167273571185616", "price": "0.862", "size": "0", "side": "BUY", "hash": "dc20c70f6d9eaf5334aaf6d55e6aed090b64b766", "best_bid": "0.995", "best_ask": "0.998"}, {"asset_id": "80861576758208246291858186808740958603555626246511495793257831406422094470572", "price": "0.138", "size": "0", "side": "SELL", "hash": "5d29e51ebdc2e2e5f8d65288e0125a112122ade9", "best_bid": "0.002", "best_ask": "0.005"}], "timestamp": "1769384103580", "event_type": "price_change"}}
{"_local_timestamp": "2026-01-25T23:35:03.709194+00:00", "data": {"market": "0x4a0cc84209df8e25f2651148c15ca45841bf02133903a990ad2be56d8337efe5", "price_changes": [{"asset_id": "102020588502400806287117347702632611550727753557718799166708590001374539810273", "price": "0.62", "size": "0", "side": "BUY", "hash": "2bb99714128ea5632758bfc3e904df59bca1c991", "best_bid": "0.7", "best_ask": "0.76"}, {"asset_id": "61649988503359407770258418097615151606970415315192585742996814749095348840604", "price": "0.38", "size": "0", "side": "SELL", "hash": "3354e34575762194f5f532a637ee364073316aa6", "best_bid": "0.24", "best_ask": "0.3"}], "timestamp": "1769384103638", "event_type": "price_change"}}
{"_local_timestamp": "2026-01-25T23:35:03.732728+00:00", "data": {"market": "0x4a0cc84209df8e25f2651148c15ca45841bf02133903a990ad2be56d8337efe5", "price_changes": [{"asset_id": "61649988503359407770258418097615151606970415315192585742996814749095348840604", "price": "0.09", "size": "66.66", "side": "BUY", "hash": "986488ec97a7e696ec1ca9189c4ecdf6d636c8e4", "best_bid": "0.24", "best_ask": "0.3"}, {"asset_id": "102020588502400806287117347702632611550727753557718799166708590001374539810273", "price": "0.91", "size": "66.66", "side": "SELL", "hash": "006187660ae8bde6ab32aaaae1bfe5cef964d2cc", "best_bid": "0.7", "best_ask": "0.76"}], "timestamp": "1769384103664", "event_type": "price_change"}}
{"_local_timestamp": "2026-01-25T23:35:03.772203+00:00", "data": {"market": "0x4a0cc84209df8e25f2651148c15ca45841bf02133903a990ad2be56d8337efe5", "price_changes": [{"asset_id": "102020588502400806287117347702632611550727753557718799166708590001374539810273", "price": "0.63", "size": "115.63", "side": "BUY", "hash": "cf3c90aa0463e71f6e9636dc41cf4c227d5839e7", "best_bid": "0.7", "best_ask": "0.76"}, {"asset_id": "61649988503359407770258418097615151606970415315192585742996814749095348840604", "price": "0.37", "size": "115.63", "side": "SELL", "hash": "1d26540f4d119481fd10bb96bdd94974da3cea99", "best_bid": "0.24", "best_ask": "0.3"}], "timestamp": "1769384103707", "event_type": "price_change"}}
{"_local_timestamp": "2026-01-25T23:35:03.918667+00:00", "data": {"market": "0x5ed8142bfb7dedd29123c51d93e78d41bb11347a9dc99af028f8c26d379f7991", "price_changes": [{"asset_id": "87806309463368545105535948349282475480949630203592970860801199564395401037228", "price": "0.2", "size": "20", "side": "BUY", "hash": "7c290ddc6dabcf3c5100a929cadb53c97e21615d", "best_bid": "0.46", "best_ask": "0.49"}, {"asset_id": "21074627447851722982583017164862562903762903675957478566509692359288711223560", "price": "0.8", "size": "20", "side": "SELL", "hash": "c0cef979fed213e1124d07cd94e0699ddf417785", "best_bid": "0.51", "best_ask": "0.54"}], "timestamp": "1769384103853", "event_type": "price_change"}}
{"_local_timestamp": "2026-01-25T23:35:03.919903+00:00", "data": {"market": "0xad1d3f37d4b3e994cf6e345342e4c6d77b847c125d222144c583ef5c4bd2f84a", "price_changes": [{"asset_id": "77654714676170984534448970834577345438216226056033824875092030167273571185616", "price": "0.764", "size": "10", "side": "BUY", "hash": "a7d05bca9351288f7f8078e6663cefafad566a0a", "best_bid": "0.995", "best_ask": "0.998"}, {"asset_id": "80861576758208246291858186808740958603555626246511495793257831406422094470572", "price": "0.236", "size": "10", "side": "SELL", "hash": "d07708319b3ed26b32e7f702e24b33d793bb854d", "best_bid": "0.002", "best_ask": "0.005"}], "timestamp": "1769384103853", "event_type": "price_change"}}
{"_local_timestamp": "2026-01-25T23:35:04.192343+00:00", "data": {"market": "0x4a0cc84209df8e25f2651148c15ca45841bf02133903a990ad2be56d8337efe5", "price_changes": [{"asset_id": "61649988503359407770258418097615151606970415315192585742996814749095348840604", "price": "0.23", "size": "67", "side": "BUY", "hash": "bc00bee99f1146ea9ffb3e722ecf400447ce207a", "best_bid": "0.24", "best_ask": "0.3"}, {"asset_id": "102020588502400806287117347702632611550727753557718799166708590001374539810273", "price": "0.77", "size": "67", "side": "SELL", "hash": "a1af60908c2f0e035d7ac6172769769bdb52c5ca", "best_bid": "0.7", "best_ask": "0.76"}], "timestamp": "1769384104123", "event_type": "price_change"}}
{"_local_timestamp": "2026-01-25T23:35:04.361010+00:00", "data": {"market": "0x4a0cc84209df8e25f2651148c15ca45841bf02133903a990ad2be56d8337efe5", "price_changes": [{"asset_id": "61649988503359407770258418097615151606970415315192585742996814749095348840604", "price": "0.24", "size": "96.66", "side": "BUY", "hash": "9fbcef496d4a24362046293d7cc01fe1954d1a44", "best_bid": "0.24", "best_ask": "0.3"}, {"asset_id": "102020588502400806287117347702632611550727753557718799166708590001374539810273", "price": "0.76", "size": "96.66", "side": "SELL", "hash": "522c72d4f7b868dbb5780a98014d715afd3f468f", "best_bid": "0.7", "best_ask": "0.76"}], "timestamp": "1769384104295", "event_type": "price_change"}}
{"_local_timestamp": "2026-01-25T23:35:05.186117+00:00", "data": {"market": "0x4a0cc84209df8e25f2651148c15ca45841bf02133903a990ad2be56d8337efe5", "price_changes": [{"asset_id": "102020588502400806287117347702632611550727753557718799166708590001374539810273", "price": "0.67", "size": "39", "side": "BUY", "hash": "d44cab4125e6d6c128640381ad30fe702bc23466", "best_bid": "0.7", "best_ask": "0.76"}, {"asset_id": "61649988503359407770258418097615151606970415315192585742996814749095348840604", "price": "0.33", "size": "39", "side": "SELL", "hash": "4414bd991b268411c22022bf2a4e14fd4a6dfee5", "best_bid": "0.24", "best_ask": "0.3"}], "timestamp": "1769384105117", "event_type": "price_change"}}
{"_local_timestamp": "2026-01-25T23:35:05.241370+00:00", "data": {"market": "0x4a0cc84209df8e25f2651148c15ca45841bf02133903a990ad2be56d8337efe5", "price_changes": [{"asset_id": "102020588502400806287117347702632611550727753557718799166708590001374539810273", "price": "0.7", "size": "96.66", "side": "BUY", "hash": "5054db8ea7d9fc47c5d14d831cc19a3b030a85e6", "best_bid": "0.7", "best_ask": "0.76"}, {"asset_id": "61649988503359407770258418097615151606970415315192585742996814749095348840604", "price": "0.3", "size": "96.66", "side": "SELL", "hash": "17492835dde1c07bffe188e4dc09d3f72803f431", "best_bid": "0.24", "best_ask": "0.3"}], "timestamp": "1769384105165", "event_type": "price_change"}}
{"_local_timestamp": "2026-01-25T23:35:05.694795+00:00", "data": {"market": "0x5ed8142bfb7dedd29123c51d93e78d41bb11347a9dc99af028f8c26d379f7991", "price_changes": [{"asset_id": "87806309463368545105535948349282475480949630203592970860801199564395401037228", "price": "0.35", "size": "15.11", "side": "BUY", "hash": "fb720181fa96e338055e6bc8bf0b47a02194e18f", "best_bid": "0.46", "best_ask": "0.49"}, {"asset_id": "21074627447851722982583017164862562903762903675957478566509692359288711223560", "price": "0.65", "size": "15.11", "side": "SELL", "hash": "a2a75470059b3c045276b53872c71a9021c2be04", "best_bid": "0.51", "best_ask": "0.54"}], "timestamp": "1769384105622", "event_type": "price_change"}}
{"_local_timestamp": "2026-01-25T23:35:05.695406+00:00", "data": {"market": "0xad1d3f37d4b3e994cf6e345342e4c6d77b847c125d222144c583ef5c4bd2f84a", "price_changes": [{"asset_id": "77654714676170984534448970834577345438216226056033824875092030167273571185616", "price": "0.858", "size": "0", "side": "BUY", "hash": "4b94d4c7b59709e303db4bca645ac0f7918ed285", "best_bid": "0.995", "best_ask": "0.998"}, {"asset_id": "80861576758208246291858186808740958603555626246511495793257831406422094470572", "price": "0.142", "size": "0", "side": "SELL", "hash": "64d082d4350163cdaf3be685d331cbf5e954bde3", "best_bid": "0.002", "best_ask": "0.005"}], "timestamp": "1769384105622", "event_type": "price_change"}}
{"_local_timestamp": "2026-01-25T23:35:05.695937+00:00", "data": {"market": "0x90301098126f955f3ce5a03b7fe4c35a3641b233f4c56e88b11070a1b414c61a", "price_changes": [{"asset_id": "39312012332144445223325894231881456670645569993721035335222112552139635422119", "price": "0.805", "size": "0", "side": "BUY", "hash": "20db62ee42bf883ea67ec3f002a123524dbe2b2b", "best_bid": "0.941", "best_ask": "0.952"}, {"asset_id": "79853007977105815624113941534992494565347323884772610518298707804471039732081", "price": "0.195", "size": "0", "side": "SELL", "hash": "44bea6d346a8750d13cedfcff30273752d7f13bc", "best_bid": "0.048", "best_ask": "0.059"}], "timestamp": "1769384105622", "event_type": "price_change"}}
{"_local_timestamp": "2026-01-25T23:35:05.696446+00:00", "data": {"market": "0xc7982ab943183b14a136538b1943a99f0b783266c46647ac5d93a53145c1a7b5", "price_changes": [{"asset_id": "13851803203597462164946196938589176900313976487295955127267529584815353328811", "price": "0.856", "size": "13.33", "side": "BUY", "hash": "d577631c12017139971f5c66b7c172832019a8f7", "best_bid": "0.99", "best_ask": "0.994"}, {"asset_id": "109831253762520485632120158952131204631888758680701510579735402842471158516644", "price": "0.144", "size": "13.33", "side": "SELL", "hash": "41b8650d91e44be33991daf9188d697c8a379706", "best_bid": "0.006", "best_ask": "0.01"}], "timestamp": "1769384105622", "event_type": "price_change"}}
{"_local_timestamp": "2026-01-25T23:35:05.696954+00:00", "data": {"market": "0xb5f410ce6db52b387d5e3c9aa386f1cf2c6d9603d4ffbb59d7b3ad78c6ce54bc", "price_changes": [{"asset_id": "30496684424734941608873174390104887181463986142171585340038809175815196271014", "price": "0.515", "size": "0", "side": "BUY", "hash": "455eba8411e9fd68ca444782159fddbc79cbbf18", "best_bid": "0.991", "best_ask": "0.992"}, {"asset_id": "90311555114079332121873713225331719655517167698979277482922143777516026157644", "price": "0.485", "size": "0", "side": "SELL", "hash": "be6f501f9f22a3bd6ced3f6c0f3023713ccfce9a", "best_bid": "0.008", "best_ask": "0.009"}], "timestamp": "1769384105622", "event_type": "price_change"}}
{"_local_timestamp": "2026-01-25T23:35:05.697465+00:00", "data": {"market": "0x9203a698f9fa14be61cfdb6bfef9deddd0aa7d2b2907d93a619702683087b3da", "price_changes": [{"asset_id": "90609029279195192521610502880224098677548237969581172515290357666786312674233", "price": "0.855", "size": "0", "side": "BUY", "hash": "1b93e74b5c1bfa09ca079b50a3b20fee05836fab", "best_bid": "0.989", "best_ask": "0.997"}, {"asset_id": "78105936059580066886637010200879176612465407936158598378531832410898792072331", "price": "0.145", "size": "0", "side": "SELL", "hash": "818a795ec575c32e95054114cafbddcc15b2511d", "best_bid": "0.003", "best_ask": "0.011"}], "timestamp": "1769384105622", "event_type": "price_change"}}
{"_local_timestamp": "2026-01-25T23:35:05.735072+00:00", "data": {"market": "0xb5f410ce6db52b387d5e3c9aa386f1cf2c6d9603d4ffbb59d7b3ad78c6ce54bc", "price_changes": [{"asset_id": "30496684424734941608873174390104887181463986142171585340038809175815196271014", "price": "0.864", "size": "20", "side": "BUY", "hash": "3b8cbbbceb0fd9d042a29d6b92bca62c3c472be8", "best_bid": "0.991", "best_ask": "0.992"}, {"asset_id": "90311555114079332121873713225331719655517167698979277482922143777516026157644", "price": "0.136", "size": "20", "side": "SELL", "hash": "cf144f61256f80c11cc542dcf82d354fe9ac6875", "best_bid": "0.008", "best_ask": "0.009"}], "timestamp": "1769384105664", "event_type": "price_change"}}
{"_local_timestamp": "2026-01-25T23:35:05.735820+00:00", "data": {"market": "0xc7982ab943183b14a136538b1943a99f0b783266c46647ac5d93a53145c1a7b5", "price_changes": [{"asset_id": "13851803203597462164946196938589176900313976487295955127267529584815353328811", "price": "0.862", "size": "20", "side": "BUY", "hash": "fc2799f2b1a6b882713739af106d8edd346e7a66", "best_bid": "0.99", "best_ask": "0.994"}, {"asset_id": "109831253762520485632120158952131204631888758680701510579735402842471158516644", "price": "0.138", "size": "20", "side": "SELL", "hash": "25211f5bf7c9b64a6cda7dcba692793198b6b19e", "best_bid": "0.006", "best_ask": "0.01"}], "timestamp": "1769384105664", "event_type": "price_change"}}
{"_local_timestamp": "2026-01-25T23:35:05.736484+00:00", "data": {"market": "0xad1d3f37d4b3e994cf6e345342e4c6d77b847c125d222144c583ef5c4bd2f84a", "price_changes": [{"asset_id": "77654714676170984534448970834577345438216226056033824875092030167273571185616", "price": "0.862", "size": "20", "side": "BUY", "hash": "1032f44f116dbf528d61494e872ce844a499cae4", "best_bid": "0.995", "best_ask": "0.998"}, {"asset_id": "80861576758208246291858186808740958603555626246511495793257831406422094470572", "price": "0.138", "size": "20", "side": "SELL", "hash": "a3966fc256956e0ae8f3eac5abefabd4143bb0ac", "best_bid": "0.002", "best_ask": "0.005"}], "timestamp": "1769384105664", "event_type": "price_change"}}
{"_local_timestamp": "2026-01-25T23:35:05.737324+00:00", "data": {"market": "0x9203a698f9fa14be61cfdb6bfef9deddd0aa7d2b2907d93a619702683087b3da", "price_changes": [{"asset_id": "90609029279195192521610502880224098677548237969581172515290357666786312674233", "price": "0.869", "size": "50", "side": "BUY", "hash": "84b9d4a2178ad59ba5942f32d8beb664374e95bc", "best_bid": "0.989", "best_ask": "0.997"}, {"asset_id": "78105936059580066886637010200879176612465407936158598378531832410898792072331", "price": "0.131", "size": "50", "side": "SELL", "hash": "d3c4ef55c9767ea0a52443715802e52620012132", "best_bid": "0.003", "best_ask": "0.011"}], "timestamp": "1769384105664", "event_type": "price_change"}}
{"_local_timestamp": "2026-01-25T23:35:05.737953+00:00", "data": {"market": "0x90301098126f955f3ce5a03b7fe4c35a3641b233f4c56e88b11070a1b414c61a", "price_changes": [{"asset_id": "39312012332144445223325894231881456670645569993721035335222112552139635422119", "price": "0.821", "size": "20", "side": "BUY", "hash": "69804bc1d8ec97cc36845c9d4f45c34e7a899a04", "best_bid": "0.941", "best_ask": "0.952"}, {"asset_id": "79853007977105815624113941534992494565347323884772610518298707804471039732081", "price": "0.179", "size": "20", "side": "SELL", "hash": "60f7092c16457b48febc99db556754b17228010d", "best_bid": "0.048", "best_ask": "0.059"}], "timestamp": "1769384105664", "event_type": "price_change"}}
{"_local_timestamp": "2026-01-25T23:35:05.812278+00:00", "data": {"market": "0x5ed8142bfb7dedd29123c51d93e78d41bb11347a9dc99af028f8c26d379f7991", "price_changes": [{"asset_id": "87806309463368545105535948349282475480949630203592970860801199564395401037228", "price": "0.36", "size": "20", "side": "BUY", "hash": "8fe065d26fe541baa4fa754aa982a7b5428e9d2e", "best_bid": "0.46", "best_ask": "0.49"}, {"asset_id": "21074627447851722982583017164862562903762903675957478566509692359288711223560", "price": "0.64", "size": "20", "side": "SELL", "hash": "cd3dc17358022899c18d8f6fcc227cb6a4b2830b", "best_bid": "0.51", "best_ask": "0.54"}], "timestamp": "1769384105665", "event_type": "price_change"}}
{"_local_timestamp": "2026-01-25T23:35:11.163513+00:00", "data": {"market": "0x4a0cc84209df8e25f2651148c15ca45841bf02133903a990ad2be56d8337efe5", "price_changes": [{"asset_id": "102020588502400806287117347702632611550727753557718799166708590001374539810273", "price": "0.69", "size": "91.07", "side": "BUY", "hash": "655d3b79f9b88ae7fb74c4eefdc552e68fac879d", "best_bid": "0.7", "best_ask": "0.76"}, {"asset_id": "61649988503359407770258418097615151606970415315192585742996814749095348840604", "price": "0.31", "size": "91.07", "side": "SELL", "hash": "c850516cf413ae06237fd44730f9f96e79b0ffbf", "best_bid": "0.24", "best_ask": "0.3"}], "timestamp": "1769384111060", "event_type": "price_change"}}
{"_local_timestamp": "2026-01-25T23:35:11.432160+00:00", "data": {"market": "0x9203a698f9fa14be61cfdb6bfef9deddd0aa7d2b2907d93a619702683087b3da", "price_changes": [{"asset_id": "90609029279195192521610502880224098677548237969581172515290357666786312674233", "price": "0.568", "size": "0", "side": "BUY", "hash": "7da0d15601232171067ee99e2179c8914ff892fe", "best_bid": "0.989", "best_ask": "0.997"}, {"asset_id": "78105936059580066886637010200879176612465407936158598378531832410898792072331", "price": "0.432", "size": "0", "side": "SELL", "hash": "4fee03254947f505b5bbb7437640e14a9f6c6a00", "best_bid": "0.003", "best_ask": "0.011"}], "timestamp": "1769384111367", "event_type": "price_change"}}
{"_local_timestamp": "2026-01-25T23:35:11.509141+00:00", "data": {"market": "0x4a0cc84209df8e25f2651148c15ca45841bf02133903a990ad2be56d8337efe5", "price_changes": [{"asset_id": "102020588502400806287117347702632611550727753557718799166708590001374539810273", "price": "0.68", "size": "20", "side": "BUY", "hash": "e10d4c2bb7e4d78e795848a858c64b6e43eec4b4", "best_bid": "0.7", "best_ask": "0.76"}, {"asset_id": "61649988503359407770258418097615151606970415315192585742996814749095348840604", "price": "0.32", "size": "20", "side": "SELL", "hash": "615ff64656fb4adac618da3a9a7556892d978fa9", "best_bid": "0.24", "best_ask": "0.3"}], "timestamp": "1769384111441", "event_type": "price_change"}}
{"_local_timestamp": "2026-01-25T23:35:11.553580+00:00", "data": {"market": "0x4a0cc84209df8e25f2651148c15ca45841bf02133903a990ad2be56d8337efe5", "price_changes": [{"asset_id": "102020588502400806287117347702632611550727753557718799166708590001374539810273", "price": "0.71", "size": "30", "side": "BUY", "hash": "53297342ffa41796467c913972cea514641265b1", "best_bid": "0.71", "best_ask": "0.76"}, {"asset_id": "61649988503359407770258418097615151606970415315192585742996814749095348840604", "price": "0.29", "size": "30", "side": "SELL", "hash": "7a932cdbffba62b7760a24c16f431742e7ba99c5", "best_bid": "0.24", "best_ask": "0.29"}], "timestamp": "1769384111482", "event_type": "price_change"}}
{"_local_timestamp": "2026-01-25T23:35:11.580696+00:00", "data": {"market": "0x9203a698f9fa14be61cfdb6bfef9deddd0aa7d2b2907d93a619702683087b3da", "price_changes": [{"asset_id": "90609029279195192521610502880224098677548237969581172515290357666786312674233", "price": "0.572", "size": "15", "side": "BUY", "hash": "36593473103c6e47a1d6cb3ff4349b0ca4883c29", "best_bid": "0.989", "best_ask": "0.997"}, {"asset_id": "78105936059580066886637010200879176612465407936158598378531832410898792072331", "price": "0.428", "size": "15", "side": "SELL", "hash": "537289abc8ce4bcb869b50d9f9a7323a1ac00c78", "best_bid": "0.003", "best_ask": "0.011"}], "timestamp": "1769384111505", "event_type": "price_change"}}
{"_local_timestamp": "2026-01-25T23:35:11.581378+00:00", "data": {"market": "0x9203a698f9fa14be61cfdb6bfef9deddd0aa7d2b2907d93a619702683087b3da", "price_changes": [{"asset_id": "90609029279195192521610502880224098677548237969581172515290357666786312674233", "price": "0.57", "size": "443", "side": "BUY", "hash": "432ecf9ef5bc683014b8da44833bfd8a88fa45f6", "best_bid": "0.989", "best_ask": "0.997"}, {"asset_id": "78105936059580066886637010200879176612465407936158598378531832410898792072331", "price": "0.43", "size": "443", "side": "SELL", "hash": "78ceeea4488dc9f82d6f9dae3e81abbb2c18fec6", "best_bid": "0.003", "best_ask": "0.011"}], "timestamp": "1769384111506", "event_type": "price_change"}}
{"_local_timestamp": "2026-01-25T23:35:11.581970+00:00", "data": {"market": "0x9203a698f9fa14be61cfdb6bfef9deddd0aa7d2b2907d93a619702683087b3da", "price_changes": [{"asset_id": "90609029279195192521610502880224098677548237969581172515290357666786312674233", "price": "0.855", "size": "10", "side": "BUY", "hash": "e13efbd4aa7c6184107d1f85485426ff319e78b7", "best_bid": "0.989", "best_ask": "0.997"}, {"asset_id": "78105936059580066886637010200879176612465407936158598378531832410898792072331", "price": "0.145", "size": "10", "side": "SELL", "hash": "66ab636857708a09795990b9463dbdd65dd668e0", "best_bid": "0.003", "best_ask": "0.011"}], "timestamp": "1769384111507", "event_type": "price_change"}}
{"_local_timestamp": "2026-01-25T23:35:11.636538+00:00", "data": {"market": "0x9203a698f9fa14be61cfdb6bfef9deddd0aa7d2b2907d93a619702683087b3da", "price_changes": [{"asset_id": "90609029279195192521610502880224098677548237969581172515290357666786312674233", "price": "0.569", "size": "351", "side": "BUY", "hash": "7fdaff65f1fde1d163f2dfdeead82a4e169b97cb", "best_bid": "0.989", "best_ask": "0.997"}, {"asset_id": "78105936059580066886637010200879176612465407936158598378531832410898792072331", "price": "0.431", "size": "351", "side": "SELL", "hash": "2625d2a7e63b517d12491842d0a5fd3106b62a1a", "best_bid": "0.003", "best_ask": "0.011"}], "timestamp": "1769384111573", "event_type": "price_change"}}
{"_local_timestamp": "2026-01-25T23:35:11.752550+00:00", "data": {"market": "0x9203a698f9fa14be61cfdb6bfef9deddd0aa7d2b2907d93a619702683087b3da", "price_changes": [{"asset_id": "90609029279195192521610502880224098677548237969581172515290357666786312674233", "price": "0.569", "size": "0", "side": "BUY", "hash": "973345e1569bf68eb72dbcc2b277da5680d6f9e2", "best_bid": "0.989", "best_ask": "0.997"}, {"asset_id": "78105936059580066886637010200879176612465407936158598378531832410898792072331", "price": "0.431", "size": "0", "side": "SELL", "hash": "00278f4736be887a9562eeb41edc67cc9aadb93b", "best_bid": "0.003", "best_ask": "0.011"}], "timestamp": "1769384111688", "event_type": "price_change"}}
{"_local_timestamp": "2026-01-25T23:35:11.760301+00:00", "data": {"market": "0x9203a698f9fa14be61cfdb6bfef9deddd0aa7d2b2907d93a619702683087b3da", "price_changes": [{"asset_id": "90609029279195192521610502880224098677548237969581172515290357666786312674233", "price": "0.571", "size": "360", "side": "BUY", "hash": "463c631f2b146adf3f13f3b9c06c1426c8d2a06a", "best_bid": "0.989", "best_ask": "0.997"}, {"asset_id": "78105936059580066886637010200879176612465407936158598378531832410898792072331", "price": "0.429", "size": "360", "side": "SELL", "hash": "47e333537d9926afdb0fc4abd08786eb2c6d33c0", "best_bid": "0.003", "best_ask": "0.011"}], "timestamp": "1769384111697", "event_type": "price_change"}}
{"_local_timestamp": "2026-01-25T23:35:11.854862+00:00", "data": {"market": "0x9203a698f9fa14be61cfdb6bfef9deddd0aa7d2b2907d93a619702683087b3da", "price_changes": [{"asset_id": "90609029279195192521610502880224098677548237969581172515290357666786312674233", "price": "0.572", "size": "364", "side": "BUY", "hash": "f2289fc923c2400bdf8cef565f0ce128fa188867", "best_bid": "0.989", "best_ask": "0.997"}, {"asset_id": "78105936059580066886637010200879176612465407936158598378531832410898792072331", "price": "0.428", "size": "364", "side": "SELL", "hash": "7c8c17b62793d0d1da6b52fc0cdced1747ce2f3d", "best_bid": "0.003", "best_ask": "0.011"}], "timestamp": "1769384111784", "event_type": "price_change"}}
{"_local_timestamp": "2026-01-25T23:35:18.240959+00:00", "data": {"market": "0x4a0cc84209df8e25f2651148c15ca45841bf02133903a990ad2be56d8337efe5", "price_changes": [{"asset_id": "61649988503359407770258418097615151606970415315192585742996814749095348840604", "price": "0.31", "size": "61.07", "side": "SELL", "hash": "3d711f7a422db110f72239376de7df0fd192b25d", "best_bid": "0.24", "best_ask": "0.29"}, {"asset_id": "102020588502400806287117347702632611550727753557718799166708590001374539810273", "price": "0.69", "size": "61.07", "side": "BUY", "hash": "a659aeff9ebb283cf8d9cbd0017933f492031ca8", "best_bid": "0.71", "best_ask": "0.76"}], "timestamp": "1769384118163", "event_type": "price_change"}}
{"_local_timestamp": "2026-01-25T23:35:18.988334+00:00", "data": {"market": "0x4a0cc84209df8e25f2651148c15ca45841bf02133903a990ad2be56d8337efe5", "price_changes": [{"asset_id": "61649988503359407770258418097615151606970415315192585742996814749095348840604", "price": "0.29", "size": "60", "side": "SELL", "hash": "1ddab841bc59228c2cadfe8e915734ad723e7ad3", "best_bid": "0.24", "best_ask": "0.29"}, {"asset_id": "102020588502400806287117347702632611550727753557718799166708590001374539810273", "price": "0.71", "size": "60", "side": "BUY", "hash": "53d3622b74a1f613e3910565081b1d44ece663d0", "best_bid": "0.71", "best_ask": "0.76"}], "timestamp": "1769384118912", "event_type": "price_change"}}
{"_local_timestamp": "2026-01-25T23:35:19.320684+00:00", "data": {"market": "0x4a0cc84209df8e25f2651148c15ca45841bf02133903a990ad2be56d8337efe5", "price_changes": [{"asset_id": "102020588502400806287117347702632611550727753557718799166708590001374539810273", "price": "0.7", "size": "66.66", "side": "BUY", "hash": "486d660349fd11b2593ebfc12828dc4646447b42", "best_bid": "0.71", "best_ask": "0.76"}, {"asset_id": "61649988503359407770258418097615151606970415315192585742996814749095348840604", "price": "0.3", "size": "66.66", "side": "SELL", "hash": "626ff3dafc9df105c548416eed868701aaaba461", "best_bid": "0.24", "best_ask": "0.29"}], "timestamp": "1769384119246", "event_type": "price_change"}}
{"_local_timestamp": "2026-01-25T23:35:19.379082+00:00", "data": {"market": "0x4a0cc84209df8e25f2651148c15ca45841bf02133903a990ad2be56d8337efe5", "price_changes": [{"asset_id": "102020588502400806287117347702632611550727753557718799166708590001374539810273", "price": "0.71", "size": "90", "side": "BUY", "hash": "5d5a65400a06ccdae599f5e9c6c9f429dcdb66e3", "best_bid": "0.71", "best_ask": "0.76"}, {"asset_id": "61649988503359407770258418097615151606970415315192585742996814749095348840604", "price": "0.29", "size": "90", "side": "SELL", "hash": "24b5c622f43d7ad0ef0306dc669734ae1ad85b99", "best_bid": "0.24", "best_ask": "0.29"}], "timestamp": "1769384119312", "event_type": "price_change"}}
{"_local_timestamp": "2026-01-25T23:35:31.397232+00:00", "data": {"market": "0x90301098126f955f3ce5a03b7fe4c35a3641b233f4c56e88b11070a1b414c61a", "price_changes": [{"asset_id": "79853007977105815624113941534992494565347323884772610518298707804471039732081", "price": "0.046", "size": "104.23", "side": "BUY", "hash": "dc85ea038ae1b1c88f24a00cdfd582b9e3220688", "best_bid": "0.048", "best_ask": "0.059"}, {"asset_id": "39312012332144445223325894231881456670645569993721035335222112552139635422119", "price": "0.954", "size": "104.23", "side": "SELL", "hash": "c5ab2fbad7349911e328654e61b3aba687ec6758", "best_bid": "0.941", "best_ask": "0.952"}], "timestamp": "1769384131244", "event_type": "price_change"}}
{"_local_timestamp": "2026-01-25T23:36:11.079669+00:00", "data": {"market": "0x4a0cc84209df8e25f2651148c15ca45841bf02133903a990ad2be56d8337efe5", "price_changes": [{"asset_id": "102020588502400806287117347702632611550727753557718799166708590001374539810273", "price": "0.68", "size": "0", "side": "BUY", "hash": "7c1bb97e34d2df32d22edb2cf5f3724e5c3aa638", "best_bid": "0.71", "best_ask": "0.76"}, {"asset_id": "61649988503359407770258418097615151606970415315192585742996814749095348840604", "price": "0.32", "size": "0", "side": "SELL", "hash": "4ad8c2340ac88df33b2c9fc26dba2c084e2b5dff", "best_bid": "0.24", "best_ask": "0.29"}], "timestamp": "1769384171001", "event_type": "price_change"}}
{"_local_timestamp": "2026-01-25T23:36:15.025890+00:00", "data": {"market": "0x4a0cc84209df8e25f2651148c15ca45841bf02133903a990ad2be56d8337efe5", "price_changes": [{"asset_id": "102020588502400806287117347702632611550727753557718799166708590001374539810273", "price": "0.68", "size": "20", "side": "BUY", "hash": "d49fb3c2381e703e22688ecbfd03a42c640e300b", "best_bid": "0.71", "best_ask": "0.76"}, {"asset_id": "61649988503359407770258418097615151606970415315192585742996814749095348840604", "price": "0.32", "size": "20", "side": "SELL", "hash": "36774ec37da7a22bca61d8705806997ffef747f6", "best_bid": "0.24", "best_ask": "0.29"}], "timestamp": "1769384174963", "event_type": "price_change"}}
{"_local_timestamp": "2026-01-25T23:36:28.573550+00:00", "data": {"market": "0x5ed8142bfb7dedd29123c51d93e78d41bb11347a9dc99af028f8c26d379f7991", "price_changes": [{"asset_id": "87806309463368545105535948349282475480949630203592970860801199564395401037228", "price": "0.51", "size": "42.16", "side": "SELL", "hash": "9d38713a492ef8bf2017c5fe045762c92c11518e", "best_bid": "0.46", "best_ask": "0.49"}, {"asset_id": "21074627447851722982583017164862562903762903675957478566509692359288711223560", "price": "0.49", "size": "42.16", "side": "BUY", "hash": "48f15dd53f1cd454bfd6a200f131501ebd1444f4", "best_bid": "0.51", "best_ask": "0.54"}], "timestamp": "1769384188501", "event_type": "price_change"}}
{"_local_timestamp": "2026-01-25T23:36:28.768439+00:00", "data": {"market": "0x5ed8142bfb7dedd29123c51d93e78d41bb11347a9dc99af028f8c26d379f7991", "price_changes": [{"asset_id": "87806309463368545105535948349282475480949630203592970860801199564395401037228", "price": "0.51", "size": "62.16", "side": "SELL", "hash": "8a469ca23deab93486245b98213512b06007d1cb", "best_bid": "0.46", "best_ask": "0.49"}, {"asset_id": "21074627447851722982583017164862562903762903675957478566509692359288711223560", "price": "0.49", "size": "62.16", "side": "BUY", "hash": "4dc30d1f006e3d2711cde42ddf29d99d640f6ace", "best_bid": "0.51", "best_ask": "0.54"}], "timestamp": "1769384188683", "event_type": "price_change"}}
{"_local_timestamp": "2026-01-25T23:36:28.950706+00:00", "data": {"market": "0x4a0cc84209df8e25f2651148c15ca45841bf02133903a990ad2be56d8337efe5", "price_changes": [{"asset_id": "61649988503359407770258418097615151606970415315192585742996814749095348840604", "price": "0.23", "size": "31", "side": "BUY", "hash": "0dbd05c9a09b2f117a4632945fd2e08be8bb56d8", "best_bid": "0.24", "best_ask": "0.29"}, {"asset_id": "102020588502400806287117347702632611550727753557718799166708590001374539810273", "price": "0.77", "size": "31", "side": "SELL", "hash": "7bb32e6e85de3b9e66b0e94623a4b8c4938572c0", "best_bid": "0.71", "best_ask": "0.76"}], "timestamp": "1769384188848", "event_type": "price_change"}}
{"_local_timestamp": "2026-01-25T23:36:33.452144+00:00", "data": {"market": "0x90301098126f955f3ce5a03b7fe4c35a3641b233f4c56e88b11070a1b414c61a", "price_changes": [{"asset_id": "79853007977105815624113941534992494565347323884772610518298707804471039732081", "price": "0.046", "size": "299.23", "side": "BUY", "hash": "e1857b4e88cdcbc2c75962313870633fcbc40bf2", "best_bid": "0.048", "best_ask": "0.059"}, {"asset_id": "39312012332144445223325894231881456670645569993721035335222112552139635422119", "price": "0.954", "size": "299.23", "side": "SELL", "hash": "59ce44ea52e6660a5b323e5ba242478b216fcd16", "best_bid": "0.941", "best_ask": "0.952"}], "timestamp": "1769384193382", "event_type": "price_change"}}
{"_local_timestamp": "2026-01-25T23:36:55.242541+00:00", "data": {"market": "0xdf3aed600715b8cc4a23e3d7e6caad79791de8dcd5af48f450dc1b8dc52128c3", "price_changes": [{"asset_id": "115200191337492844563805575089118887672911159979117742424196868043770660979378", "price": "0.402", "size": "1211", "side": "BUY", "hash": "5452fc6151fd6350b43575011c98c4d94109bbe8", "best_bid": "0.964", "best_ask": "0.965"}, {"asset_id": "111955058608111392596805821148637930362581269673097069733693799539148925173769", "price": "0.598", "size": "1211", "side": "SELL", "hash": "0aca09a54b50fc9a97e36dd19f38329fb0ba0457", "best_bid": "0.035", "best_ask": "0.036"}], "timestamp": "1769384215008", "event_type": "price_change"}}
{"_local_timestamp": "2026-01-25T23:36:55.244733+00:00", "data": {"market": "0x4a0cc84209df8e25f2651148c15ca45841bf02133903a990ad2be56d8337efe5", "price_changes": [{"asset_id": "102020588502400806287117347702632611550727753557718799166708590001374539810273", "price": "0.11", "size": "295", "side": "BUY", "hash": "7707fb0c151901af1ac3fe72047d641b8ec3c9b8", "best_bid": "0.71", "best_ask": "0.76"}, {"asset_id": "61649988503359407770258418097615151606970415315192585742996814749095348840604", "price": "0.89", "size": "295", "side": "SELL", "hash": "ee016edb528d9c41e31360e88e86f19b1172d6e3", "best_bid": "0.24", "best_ask": "0.29"}], "timestamp": "1769384215009", "event_type": "price_change"}}
{"_local_timestamp": "2026-01-25T23:36:56.076706+00:00", "data": {"market": "0xdf3aed600715b8cc4a23e3d7e6caad79791de8dcd5af48f450dc1b8dc52128c3", "price_changes": [{"asset_id": "115200191337492844563805575089118887672911159979117742424196868043770660979378", "price": "0.403", "size": "308", "side": "BUY", "hash": "4d6d4b8667477dfece76e797120cfca2d326ac4b", "best_bid": "0.964", "best_ask": "0.965"}, {"asset_id": "111955058608111392596805821148637930362581269673097069733693799539148925173769", "price": "0.597", "size": "308", "side": "SELL", "hash": "8e674a603d9bb855e3fb5d206c1cefc4ba501b0c", "best_bid": "0.035", "best_ask": "0.036"}], "timestamp": "1769384215644", "event_type": "price_change"}}
{"_local_timestamp": "2026-01-25T23:36:56.102160+00:00", "data": {"market": "0x4a0cc84209df8e25f2651148c15ca45841bf02133903a990ad2be56d8337efe5", "price_changes": [{"asset_id": "102020588502400806287117347702632611550727753557718799166708590001374539810273", "price": "0.12", "size": "483.33", "side": "BUY", "hash": "a58319080fee09afdd2d5ad03ce8a647e5d23e1f", "best_bid": "0.71", "best_ask": "0.76"}, {"asset_id": "61649988503359407770258418097615151606970415315192585742996814749095348840604", "price": "0.88", "size": "483.33", "side": "SELL", "hash": "5e8a7ac99e24793a9acaea0698dcafad169fe38e", "best_bid": "0.24", "best_ask": "0.29"}], "timestamp": "1769384215648", "event_type": "price_change"}}
{"_local_timestamp": "2026-01-25T23:36:57.502168+00:00", "data": {"market": "0xdf3aed600715b8cc4a23e3d7e6caad79791de8dcd5af48f450dc1b8dc52128c3", "price_changes": [{"asset_id": "115200191337492844563805575089118887672911159979117742424196868043770660979378", "price": "0.402", "size": "994", "side": "BUY", "hash": "2d971a39f6f4c1081dde115eb3a40778f949dea3", "best_bid": "0.964", "best_ask": "0.965"}, {"asset_id": "111955058608111392596805821148637930362581269673097069733693799539148925173769", "price": "0.598", "size": "994", "side": "SELL", "hash": "3c3514604aff65ee81c4f681b1f796d2e4207a03", "best_bid": "0.035", "best_ask": "0.036"}], "timestamp": "1769384217219", "event_type": "price_change"}}
{"_local_timestamp": "2026-01-25T23:36:59.126515+00:00", "data": {"market": "0xad1d3f37d4b3e994cf6e345342e4c6d77b847c125d222144c583ef5c4bd2f84a", "price_changes": [{"asset_id": "80861576758208246291858186808740958603555626246511495793257831406422094470572", "price": "0.002", "size": "2842.63", "side": "BUY", "hash": "e32fddb14a7ab03e6fb1ebb4503e087586422a88", "best_bid": "0.002", "best_ask": "0.005"}, {"asset_id": "77654714676170984534448970834577345438216226056033824875092030167273571185616", "price": "0.998", "size": "2842.63", "side": "SELL", "hash": "df63e556ed41433bc4db6a6a6b6ebcc22001894f", "best_bid": "0.995", "best_ask": "0.998"}], "timestamp": "1769384218751", "event_type": "price_change"}}
{"_local_timestamp": "2026-01-25T23:36:59.127206+00:00", "data": {"market": "0xc7982ab943183b14a136538b1943a99f0b783266c46647ac5d93a53145c1a7b5", "price_changes": [{"asset_id": "109831253762520485632120158952131204631888758680701510579735402842471158516644", "price": "0.006", "size": "1200", "side": "BUY", "hash": "8e5a2c81ee60314e5dcaaf356658e524f7cfdb34", "best_bid": "0.006", "best_ask": "0.01"}, {"asset_id": "13851803203597462164946196938589176900313976487295955127267529584815353328811", "price": "0.994", "size": "1200", "side": "SELL", "hash": "f30a5a100ba6aaa758e46d3a102a68a026a6da1d", "best_bid": "0.99", "best_ask": "0.994"}], "timestamp": "1769384218751", "event_type": "price_change"}}
{"_local_timestamp": "2026-01-25T23:37:05.290134+00:00", "data": {"market": "0x4a0cc84209df8e25f2651148c15ca45841bf02133903a990ad2be56d8337efe5", "price_changes": [{"asset_id": "102020588502400806287117347702632611550727753557718799166708590001374539810273", "price": "0.69", "size": "6", "side": "BUY", "hash": "2043ad7268c54740b9cb733ed3420efcfea4030d", "best_bid": "0.71", "best_ask": "0.76"}, {"asset_id": "61649988503359407770258418097615151606970415315192585742996814749095348840604", "price": "0.31", "size": "6", "side": "SELL", "hash": "7dc7482ad8a5f5b3c649aa6a0fa527848b75381c", "best_bid": "0.24", "best_ask": "0.29"}], "timestamp": "1769384225050", "event_type": "price_change"}}
{"_local_timestamp": "2026-01-25T23:37:19.315561+00:00", "data": {"market": "0xdf3aed600715b8cc4a23e3d7e6caad79791de8dcd5af48f450dc1b8dc52128c3", "price_changes": [{"asset_id": "115200191337492844563805575089118887672911159979117742424196868043770660979378", "price": "0.404", "size": "124", "side": "BUY", "hash": "3a457e03c89d5d388c01d4deb92e65f42ac4d9b5", "best_bid": "0.964", "best_ask": "0.965"}, {"asset_id": "111955058608111392596805821148637930362581269673097069733693799539148925173769", "price": "0.596", "size": "124", "side": "SELL", "hash": "e1cb682a13d62c7c6a9f62aee768a96660f8a2a8", "best_bid": "0.035", "best_ask": "0.036"}], "timestamp": "1769384239248", "event_type": "price_change"}}
{"_local_timestamp": "2026-01-25T23:37:32.052797+00:00", "data": {"market": "0xaec744acc776760b5ae4ea624392701e5be37f226030347437abdb6df9c1d184", "price_changes": [{"asset_id": "65011365813876110503762705278234990534834069077237893699433240754014665936821", "price": "0.84", "size": "330.21", "side": "BUY", "hash": "b1b2325fb8a6e5c96c6c7e450672d6342f38e82a", "best_bid": "0.89", "best_ask": "0.93"}, {"asset_id": "101982479106085743672801224611352854881298304403358116970444362116404081985491", "price": "0.16", "size": "330.21", "side": "SELL", "hash": "b6455d8f13bef596546cadca3ecda624f2d6749c", "best_bid": "0.07", "best_ask": "0.11"}], "timestamp": "1769384251913", "event_type": "price_change"}}
{"_local_timestamp": "2026-01-25T23:37:32.053509+00:00", "data": {"market": "0x4a0cc84209df8e25f2651148c15ca45841bf02133903a990ad2be56d8337efe5", "price_changes": [{"asset_id": "102020588502400806287117347702632611550727753557718799166708590001374539810273", "price": "0.68", "size": "0", "side": "BUY", "hash": "1e70d6781f40575af6cd522598963e52a5f66ca0", "best_bid": "0.71", "best_ask": "0.76"}, {"asset_id": "61649988503359407770258418097615151606970415315192585742996814749095348840604", "price": "0.32", "size": "0", "side": "SELL", "hash": "fea5f2e3913178f40935aae806eda78e87f902ea", "best_bid": "0.24", "best_ask": "0.29"}], "timestamp": "1769384251913", "event_type": "price_change"}}
{"_local_timestamp": "2026-01-25T23:37:32.077788+00:00", "data": {"market": "0x5ed8142bfb7dedd29123c51d93e78d41bb11347a9dc99af028f8c26d379f7991", "price_changes": [{"asset_id": "87806309463368545105535948349282475480949630203592970860801199564395401037228", "price": "0.4", "size": "900", "side": "BUY", "hash": "14c50e4382867bdddc1b55dcfc29e6f8aa7e0da0", "best_bid": "0.46", "best_ask": "0.49"}, {"asset_id": "21074627447851722982583017164862562903762903675957478566509692359288711223560", "price": "0.6", "size": "900", "side": "SELL", "hash": "b4aa8a37ae2e3bccc9661e7e809d6e0a1060a4e5", "best_bid": "0.51", "best_ask": "0.54"}], "timestamp": "1769384251914", "event_type": "price_change"}}
{"_local_timestamp": "2026-01-25T23:37:32.638091+00:00", "data": {"market": "0x4a0cc84209df8e25f2651148c15ca45841bf02133903a990ad2be56d8337efe5", "price_changes": [{"asset_id": "102020588502400806287117347702632611550727753557718799166708590001374539810273", "price": "0.07", "size": "0", "side": "BUY", "hash": "dbb33e08cb5a614a44aafeedaa64de9168b8fdb2", "best_bid": "0.71", "best_ask": "0.76"}, {"asset_id": "61649988503359407770258418097615151606970415315192585742996814749095348840604", "price": "0.93", "size": "0", "side": "SELL", "hash": "541c1024e0183c75c1dbc1ca118934624982b2ba", "best_bid": "0.24", "best_ask": "0.29"}], "timestamp": "1769384252544", "event_type": "price_change"}}
{"_local_timestamp": "2026-01-25T23:37:32.972563+00:00", "data": {"market": "0x4a0cc84209df8e25f2651148c15ca45841bf02133903a990ad2be56d8337efe5", "price_changes": [{"asset_id": "102020588502400806287117347702632611550727753557718799166708590001374539810273", "price": "0.08", "size": "750", "side": "BUY", "hash": "f71cb592886ba1af1fcacb52e7e9f488444f0ad9", "best_bid": "0.71", "best_ask": "0.76"}, {"asset_id": "61649988503359407770258418097615151606970415315192585742996814749095348840604", "price": "0.92", "size": "750", "side": "SELL", "hash": "86234cba34286cb1f771610e9a8a32c4020cbfad", "best_bid": "0.24", "best_ask": "0.29"}], "timestamp": "1769384252870", "event_type": "price_change"}}
{"_local_timestamp": "2026-01-25T23:37:48.088135+00:00", "data": {"market": "0x4a0cc84209df8e25f2651148c15ca45841bf02133903a990ad2be56d8337efe5", "price_changes": [{"asset_id": "102020588502400806287117347702632611550727753557718799166708590001374539810273", "price": "0.7", "size": "0", "side": "BUY", "hash": "be3e7cb5ed8cfdbc53d50736cf394de81b510bf1", "best_bid": "0.71", "best_ask": "0.76"}, {"asset_id": "61649988503359407770258418097615151606970415315192585742996814749095348840604", "price": "0.3", "size": "0", "side": "SELL", "hash": "11b3ab5075df4aba8bebb4701ee9762a4a7dd9ba", "best_bid": "0.24", "best_ask": "0.29"}], "timestamp": "1769384267968", "event_type": "price_change"}}
{"_local_timestamp": "2026-01-25T23:37:49.019461+00:00", "data": {"market": "0x4a0cc84209df8e25f2651148c15ca45841bf02133903a990ad2be56d8337efe5", "price_changes": [{"asset_id": "102020588502400806287117347702632611550727753557718799166708590001374539810273", "price": "0.72", "size": "66.66", "side": "BUY", "hash": "9bb1bac8c657002c8142e30bf23f5cae01fb0c24", "best_bid": "0.72", "best_ask": "0.76"}, {"asset_id": "61649988503359407770258418097615151606970415315192585742996814749095348840604", "price": "0.28", "size": "66.66", "side": "SELL", "hash": "2adce4bcb779602cb99f5e0346aac2fe9df6445b", "best_bid": "0.24", "best_ask": "0.28"}], "timestamp": "1769384268931", "event_type": "price_change"}}
{"_local_timestamp": "2026-01-25T23:37:49.692765+00:00", "data": {"market": "0x4a0cc84209df8e25f2651148c15ca45841bf02133903a990ad2be56d8337efe5", "price_changes": [{"asset_id": "102020588502400806287117347702632611550727753557718799166708590001374539810273", "price": "0.71", "size": "60", "side": "BUY", "hash": "30d1fe20ec9ad1b9cde05e50b8964dbde1db64df", "best_bid": "0.72", "best_ask": "0.76"}, {"asset_id": "61649988503359407770258418097615151606970415315192585742996814749095348840604", "price": "0.29", "size": "60", "side": "SELL", "hash": "53c1d87e1007c123a5b4e12435f8bd80d9d3954d", "best_bid": "0.24", "best_ask": "0.28"}], "timestamp": "1769384269579", "event_type": "price_change"}}
{"_local_timestamp": "2026-01-25T23:37:49.743808+00:00", "data": {"market": "0x4a0cc84209df8e25f2651148c15ca45841bf02133903a990ad2be56d8337efe5", "price_changes": [{"asset_id": "102020588502400806287117347702632611550727753557718799166708590001374539810273", "price": "0.72", "size": "96.66", "side": "BUY", "hash": "8b076e68f3f34c6fb9dd5693be7831df060edce6", "best_bid": "0.72", "best_ask": "0.76"}, {"asset_id": "61649988503359407770258418097615151606970415315192585742996814749095348840604", "price": "0.28", "size": "96.66", "side": "SELL", "hash": "da9dd6e38f99d0b815553a067a79726188c359bd", "best_bid": "0.24", "best_ask": "0.28"}], "timestamp": "1769384269629", "event_type": "price_change"}}
{"_local_timestamp": "2026-01-25T23:37:50.691982+00:00", "data": {"market": "0x4a0cc84209df8e25f2651148c15ca45841bf02133903a990ad2be56d8337efe5", "price_changes": [{"asset_id": "102020588502400806287117347702632611550727753557718799166708590001374539810273", "price": "0.71", "size": "30", "side": "BUY", "hash": "d0b75e8dfa1107f4127834d52111918b2c28c93c", "best_bid": "0.72", "best_ask": "0.76"}, {"asset_id": "61649988503359407770258418097615151606970415315192585742996814749095348840604", "price": "0.29", "size": "30", "side": "SELL", "hash": "87f82c78e88aa3cc8af093aae927667f839efc0a", "best_bid": "0.24", "best_ask": "0.28"}], "timestamp": "1769384270570", "event_type": "price_change"}}
{"_local_timestamp": "2026-01-25T23:38:09.198113+00:00", "data": {"market": "0xc7982ab943183b14a136538b1943a99f0b783266c46647ac5d93a53145c1a7b5", "price_changes": [{"asset_id": "13851803203597462164946196938589176900313976487295955127267529584815353328811", "price": "0.403", "size": "0", "side": "BUY", "hash": "41f07bb9de82336d89af3266b0feebc50d55fe8a", "best_bid": "0.99", "best_ask": "0.994"}, {"asset_id": "109831253762520485632120158952131204631888758680701510579735402842471158516644", "price": "0.597", "size": "0", "side": "SELL", "hash": "89fbcefa7b885b55af5c6aca7fb4878092a3b539", "best_bid": "0.006", "best_ask": "0.01"}], "timestamp": "1769384289130", "event_type": "price_change"}}
{"_local_timestamp": "2026-01-25T23:38:09.255984+00:00", "data": {"market": "0xc7982ab943183b14a136538b1943a99f0b783266c46647ac5d93a53145c1a7b5", "price_changes": [{"asset_id": "13851803203597462164946196938589176900313976487295955127267529584815353328811", "price": "0.405", "size": "5", "side": "BUY", "hash": "1118ecb8d30907337c7d4c61682cde13133cfc2f", "best_bid": "0.99", "best_ask": "0.994"}, {"asset_id": "109831253762520485632120158952131204631888758680701510579735402842471158516644", "price": "0.595", "size": "5", "side": "SELL", "hash": "082dbdc2c17edb8abc122226d993accf6a31f40d", "best_bid": "0.006", "best_ask": "0.01"}], "timestamp": "1769384289185", "event_type": "price_change"}}
{"_local_timestamp": "2026-01-25T23:38:17.857221+00:00", "data": {"market": "0x4a0cc84209df8e25f2651148c15ca45841bf02133903a990ad2be56d8337efe5", "price_changes": [{"asset_id": "61649988503359407770258418097615151606970415315192585742996814749095348840604", "price": "0.29", "size": "0", "side": "SELL", "hash": "586505dc1f96db70f03faa111ff6d36045714edb", "best_bid": "0.24", "best_ask": "0.28"}, {"asset_id": "102020588502400806287117347702632611550727753557718799166708590001374539810273", "price": "0.71", "size": "0", "side": "BUY", "hash": "e2cc5b9d0aca99e0559c039c1a922a998160571c", "best_bid": "0.72", "best_ask": "0.76"}], "timestamp": "1769384297767", "event_type": "price_change"}}
{"_local_timestamp": "2026-01-25T23:38:18.772321+00:00", "data": {"market": "0x4a0cc84209df8e25f2651148c15ca45841bf02133903a990ad2be56d8337efe5", "price_changes": [{"asset_id": "102020588502400806287117347702632611550727753557718799166708590001374539810273", "price": "0.72", "size": "66.66", "side": "BUY", "hash": "55c20fe5d3440b1c3b20378f01e6e29122b5b5a9", "best_bid": "0.72", "best_ask": "0.76"}, {"asset_id": "61649988503359407770258418097615151606970415315192585742996814749095348840604", "price": "0.28", "size": "66.66", "side": "SELL", "hash": "3d381fda580da14e138d4e98d01e2d1d4ea00967", "best_bid": "0.24", "best_ask": "0.28"}], "timestamp": "1769384298705", "event_type": "price_change"}}
{"_local_timestamp": "2026-01-25T23:38:18.966930+00:00", "data": {"market": "0xdf3aed600715b8cc4a23e3d7e6caad79791de8dcd5af48f450dc1b8dc52128c3", "price_changes": [{"asset_id": "115200191337492844563805575089118887672911159979117742424196868043770660979378", "price": "0.688", "size": "15", "side": "BUY", "hash": "bb68ad7dac39d99d1685c74d51a2690e901e915f", "best_bid": "0.964", "best_ask": "0.965"}, {"asset_id": "111955058608111392596805821148637930362581269673097069733693799539148925173769", "price": "0.312", "size": "15", "side": "SELL", "hash": "c66251e790f8dd30d1973c5ede06ec5f45c66325", "best_bid": "0.035", "best_ask": "0.036"}], "timestamp": "1769384298893", "event_type": "price_change"}}
{"_local_timestamp": "2026-01-25T23:38:21.229936+00:00", "data": {"market": "0xdf3aed600715b8cc4a23e3d7e6caad79791de8dcd5af48f450dc1b8dc52128c3", "price_changes": [{"asset_id": "115200191337492844563805575089118887672911159979117742424196868043770660979378", "price": "0.4", "size": "0", "side": "BUY", "hash": "d7b6ac5458d530e9f49fd9b3693f571d3ae83fad", "best_bid": "0.964", "best_ask": "0.965"}, {"asset_id": "111955058608111392596805821148637930362581269673097069733693799539148925173769", "price": "0.6", "size": "0", "side": "SELL", "hash": "e7dfaa09c027689c21ccbd057900edfbf1074111", "best_bid": "0.035", "best_ask": "0.036"}], "timestamp": "1769384301116", "event_type": "price_change"}}
{"_local_timestamp": "2026-01-25T23:38:21.231620+00:00", "data": {"market": "0x4a0cc84209df8e25f2651148c15ca45841bf02133903a990ad2be56d8337efe5", "price_changes": [{"asset_id": "102020588502400806287117347702632611550727753557718799166708590001374539810273", "price": "0.34", "size": "0", "side": "BUY", "hash": "3b67192728573729a095192b0a5586ea08a9f594", "best_bid": "0.72", "best_ask": "0.76"}, {"asset_id": "61649988503359407770258418097615151606970415315192585742996814749095348840604", "price": "0.66", "size": "0", "side": "SELL", "hash": "b761a6559df732b8a56e46298eedd44ae26ef1a6", "best_bid": "0.24", "best_ask": "0.28"}], "timestamp": "1769384301116", "event_type": "price_change"}}
{"_local_timestamp": "2026-01-25T23:38:21.391411+00:00", "data": {"market": "0x5ed8142bfb7dedd29123c51d93e78d41bb11347a9dc99af028f8c26d379f7991", "price_changes": [{"asset_id": "87806309463368545105535948349282475480949630203592970860801199564395401037228", "price": "0.27", "size": "20", "side": "BUY", "hash": "1e46f8c083d461647d2b42d955287f79362e76c3", "best_bid": "0.46", "best_ask": "0.49"}, {"asset_id": "21074627447851722982583017164862562903762903675957478566509692359288711223560", "price": "0.73", "size": "20", "side": "SELL", "hash": "50ad957b33d888e7f56a67e136086ea1593e6775", "best_bid": "0.51", "best_ask": "0.54"}], "timestamp": "1769384301239", "event_type": "price_change"}}
{"_local_timestamp": "2026-01-25T23:38:21.646107+00:00", "data": {"market": "0xdf3aed600715b8cc4a23e3d7e6caad79791de8dcd5af48f450dc1b8dc52128c3", "price_changes": [{"asset_id": "115200191337492844563805575089118887672911159979117742424196868043770660979378", "price": "0.34", "size": "120.58", "side": "BUY", "hash": "732387541f56fdb401c8f55e64f699cd937d5f37", "best_bid": "0.964", "best_ask": "0.965"}, {"asset_id": "111955058608111392596805821148637930362581269673097069733693799539148925173769", "price": "0.66", "size": "120.58", "side": "SELL", "hash": "342b4966f2790ed40c03d6eb5ac9f3e4570bee13", "best_bid": "0.035", "best_ask": "0.036"}], "timestamp": "1769384301464", "event_type": "price_change"}}
{"_local_timestamp": "2026-01-25T23:38:58.384556+00:00", "data": {"market": "0x4a0cc84209df8e25f2651148c15ca45841bf02133903a990ad2be56d8337efe5", "price_changes": [{"asset_id": "102020588502400806287117347702632611550727753557718799166708590001374539810273", "price": "0.11", "size": "170", "side": "BUY", "hash": "34685ddad6cc19812c720de23a2e3d4c7786fcad", "best_bid": "0.72", "best_ask": "0.76"}, {"asset_id": "61649988503359407770258418097615151606970415315192585742996814749095348840604", "price": "0.89", "size": "170", "side": "SELL", "hash": "074f4336e2f4aca5cf53768d6448f4eacd18c22e", "best_bid": "0.24", "best_ask": "0.28"}], "timestamp": "1769384338217", "event_type": "price_change"}}
{"_local_timestamp": "2026-01-25T23:38:58.630050+00:00", "data": {"market": "0xaec744acc776760b5ae4ea624392701e5be37f226030347437abdb6df9c1d184", "price_changes": [{"asset_id": "65011365813876110503762705278234990534834069077237893699433240754014665936821", "price": "0.41", "size": "0", "side": "BUY", "hash": "b08fd82c8e7bf51c4d89d30a4806c56fa18f446f", "best_bid": "0.89", "best_ask": "0.93"}, {"asset_id": "101982479106085743672801224611352854881298304403358116970444362116404081985491", "price": "0.59", "size": "0", "side": "SELL", "hash": "26cfb7362ce5ff2f917725f6c9ef151b72ff17a2", "best_bid": "0.07", "best_ask": "0.11"}], "timestamp": "1769384338453", "event_type": "price_change"}}
{"_local_timestamp": "2026-01-25T23:38:59.117904+00:00", "data": {"market": "0x4a0cc84209df8e25f2651148c15ca45841bf02133903a990ad2be56d8337efe5", "price_changes": [{"asset_id": "102020588502400806287117347702632611550727753557718799166708590001374539810273", "price": "0.12", "size": "608.33", "side": "BUY", "hash": "5b5c66868eccad9213188b23c1ef86e0eb7e1358", "best_bid": "0.72", "best_ask": "0.76"}, {"asset_id": "61649988503359407770258418097615151606970415315192585742996814749095348840604", "price": "0.88", "size": "608.33", "side": "SELL", "hash": "baebdc7d5d6081d39c7af899c7d3bc347592b3eb", "best_bid": "0.24", "best_ask": "0.28"}], "timestamp": "1769384338690", "event_type": "price_change"}}
{"_local_timestamp": "2026-01-25T23:38:59.165962+00:00", "data": {"market": "0xaec744acc776760b5ae4ea624392701e5be37f226030347437abdb6df9c1d184", "price_changes": [{"asset_id": "65011365813876110503762705278234990534834069077237893699433240754014665936821", "price": "0.73", "size": "30", "side": "BUY", "hash": "a2e7ea081942cf508e12c0d47fb33add71ac20e3", "best_bid": "0.89", "best_ask": "0.93"}, {"asset_id": "101982479106085743672801224611352854881298304403358116970444362116404081985491", "price": "0.27", "size": "30", "side": "SELL", "hash": "5311ad042b71e88f295580e3ccdaddc08147da2a", "best_bid": "0.07", "best_ask": "0.11"}], "timestamp": "1769384338981", "event_type": "price_change"}}
{"_local_timestamp": "2026-01-25T23:39:01.639482+00:00", "data": {"market": "0xaec744acc776760b5ae4ea624392701e5be37f226030347437abdb6df9c1d184", "price_changes": [{"asset_id": "65011365813876110503762705278234990534834069077237893699433240754014665936821", "price": "0.73", "size": "10", "side": "BUY", "hash": "e5841c21cabd783504d22ec16403bf86ad4c5926", "best_bid": "0.89", "best_ask": "0.93"}, {"asset_id": "101982479106085743672801224611352854881298304403358116970444362116404081985491", "price": "0.27", "size": "10", "side": "SELL", "hash": "444e3a646b02b102727282bbb74fd67df7197957", "best_bid": "0.07", "best_ask": "0.11"}], "timestamp": "1769384341572", "event_type": "price_change"}}
{"_local_timestamp": "2026-01-25T23:39:01.673518+00:00", "data": {"market": "0xaec744acc776760b5ae4ea624392701e5be37f226030347437abdb6df9c1d184", "price_changes": [{"asset_id": "65011365813876110503762705278234990534834069077237893699433240754014665936821", "price": "0.74", "size": "20", "side": "BUY", "hash": "14be4b10743b284dbb7742a88f54eca216b88e53", "best_bid": "0.89", "best_ask": "0.93"}, {"asset_id": "101982479106085743672801224611352854881298304403358116970444362116404081985491", "price": "0.26", "size": "20", "side": "SELL", "hash": "82d6a7e6725d4dbaf05bed14a8cd8a10482bf01d", "best_bid": "0.07", "best_ask": "0.11"}], "timestamp": "1769384341603", "event_type": "price_change"}}
