{"_local_timestamp": "2026-01-25T23:40:38.242489+00:00", "data": [{"market": "0x576b5f5f1ec1fb585d195f3310148efabbd11ec45679b7835228fb3431c648a4", "asset_id": "70963008880021254228771190647726911759536509259304029983946935833811359615992", "timestamp": "1769384436160", "hash": "a01a88d8b7e1849be3e25d2d5d2ff952ad7ff35a", "bids": [{"price": "0.01", "size": "3578.03"}, {"price": "0.02", "size": "1311.61"}, {"price": "0.03", "size": "166"}, {"price": "0.04", "size": "255.41"}, {"price": "0.05", "size": "30"}, {"price": "0.06", "size": "33"}, {"price": "0.07", "size": "5.77"}, {"price": "0.08", "size": "125"}, {"price": "0.09", "size": "200"}, {"price": "0.1", "size": "400"}, {"price": "0.11", "size": "9.39"}, {"price": "0.14", "size": "66.66"}, {"price": "0.17", "size": "39"}, {"price": "0.19", "size": "19"}, {"price": "0.2", "size": "20"}, {"price": "0.23", "size": "145.66"}], "asks": [{"price": "0.99", "size": "130.82"}, {"price": "0.98", "size": "27.25"}, {"price": "0.97", "size": "48.33"}], "event_type": "book", "last_trade_price": ""}, {"market": "0x3aa954bfa31f711f5931faf1c10c348c836489775295df087999120eeacccd55", "asset_id": "84130229918953255589546529005358461415977072942576966891079344531781581735938", "timestamp": "1769384079680", "hash": "06ec8cb338cf019fb6833ba5cce92a5878847f4e", "bids": [{"price": "0.01", "size": "5607.34"}, {"price": "0.02", "size": "2307.21"}, {"price": "0.03", "size": "200"}, {"price": "0.04", "size": "357.96"}, {"price": "0.05", "size": "230"}, {"price": "0.06", "size": "733"}, {"price": "0.07", "size": "100"}, {"price": "0.08", "size": "125"}, {"price": "0.09", "size": "5.43"}, {"price": "0.11", "size": "225"}, {"price": "0.16", "size": "200"}, {"price": "0.18", "size": "10"}, {"price": "0.19", "size": "25.12"}, {"price": "0.37", "size": "100"}, {"price": "0.38", "size": "5"}, {"price": "0.72", "size": "5"}], "asks": [{"price": "0.99", "size": "72.58"}, {"price": "0.98", "size": "25.75"}, {"price": "0.97", "size": "79.54"}, {"price": "0.95", "size": "56.16"}], "event_type": "book", "last_trade_price": ""}, {"market": "0xd426b5e37b1adeb4a30ed0ece09fe70b5ca0aee2392a43c97b18af26b3fec447", "asset_id": "31903753668568580194519745519436307034343004688882823786562874898525719905121", "timestamp": "1769384421401", "hash": "4ed8e90b645c196a7240840a5e0e17256de935f2", "bids": [{"price": "0.01", "size": "2505"}, {"price": "0.02", "size": "100"}, {"price": "0.03", "size": "373.86"}, {"price": "0.04", "size": "100"}, {"price": "0.05", "size": "720"}, {"price": "0.06", "size": "33"}, {"price": "0.07", "size": "5.72"}, {"price": "0.11", "size": "66.66"}, {"price": "0.12", "size": "33"}, {"price": "0.21", "size": "100"}, {"price": "0.22", "size": "66.66"}], "asks": [{"price": "0.99", "size": "1016.93"}, {"price": "0.98", "size": "669.61"}, {"price": "0.97", "size": "330.32"}, {"price": "0.96", "size": "350"}, {"price": "0.95", "size": "315.76"}, {"price": "0.94", "size": "152.18"}, {"price": "0.93", "size": "7.4"}, {"price": "0.92", "size": "125"}, {"price": "0.9", "size": "103.18"}, {"price": "0.89", "size": "5.01"}, {"price": "0.86", "size": "59.32"}], "event_type": "book", "last_trade_price": ""}, {"market": "0xd426b5e37b1adeb4a30ed0ece09fe70b5ca0aee2392a43c97b18af26b3fec447", "asset_id": "52087909301984001009522958878332816194878042148980764948870893996379225172213", "timestamp": "1769384421401", "hash": "683b0fa394b57c91d6bd9b3e054f67fcdf762068", "bids": [{"price": "0.01", "size": "1016.93"}, {"price": "0.02", "size": "669.61"}, {"price": "0.03", "size": "330.32"}, {"price": "0.04", "size": "350"}, {"price": "0.05", "size": "315.76"}, {"price": "0.06", "size": "152.18"}, {"price": "0.07", "size": "7.4"}, {"price": "0.08", "size": "125"}, {"price": "0.1", "size": "103.18"}, {"price": "0.11", "size": "5.01"}, {"price": "0.14", "size": "59.32"}], "asks": [{"price": "0.99", "size": "2505"}, {"price": "0.98", "size": "100"}, {"price": "0.97", "size": "373.86"}, {"price": "0.96", "size": "100"}, {"price": "0.95", "size": "720"}, {"price": "0.94", "size": "33"}, {"price": "0.93", "size": "5.72"}, {"price": "0.89", "size": "66.66"}, {"price": "0.88", "size": "33"}, {"price": "0.79", "size": "100"}, {"price": "0.78", "size": "66.66"}], "event_type": "book", "last_trade_price": ""}, {"market": "0x3aa954bfa31f711f5931faf1c10c348c836489775295df087999120eeacccd55", "asset_id": "31950047046821617093336746536010818826785645498651968760645249476800296107002", "timestamp": "1769384079680", "hash": "08c7a01f8648e1bcb44ebc6d0b79b3ec5ce511fe", "bids": [{"price": "0.01", "size": "72.58"}, {"price": "0.02", "size": "25.75"}, {"price": "0.03", "size": "79.54"}, {"price": "0.05", "size": "56.16"}], "asks": [{"price": "0.99", "size": "5607.34"}, {"price": "0.98", "size": "2307.21"}, {"price": "0.97", "size": "200"}, {"price": "0.96", "size": "357.96"}, {"price": "0.95", "size": "230"}, {"price": "0.94", "size": "733"}, {"price": "0.93", "size": "100"}, {"price": "0.92", "size": "125"}, {"price": "0.91", "size": "5.43"}, {"price": "0.89", "size": "225"}, {"price": "0.84", "size": "200"}, {"price": "0.82", "size": "10"}, {"price": "0.81", "size": "25.12"}, {"price": "0.63", "size": "100"}, {"price": "0.62", "size": "5"}, {"price": "0.28", "size": "5"}], "event_type": "book", "last_trade_price": ""}, {"market": "0x576b5f5f1ec1fb585d195f3310148efabbd11ec45679b7835228fb3431c648a4", "asset_id": "41480954438913063970197792021573332585554410838284506333996743209224990064024", "timestamp": "1769384436160", "hash": "24a13b44988e7a7b6243b410400f25681b8dd136", "bids": [{"price": "0.01", "size": "130.82"}, {"price": "0.02", "size": "27.25"}, {"price": "0.03", "size": "48.33"}], "asks": [{"price": "0.99", "size": "3578.03"}, {"price": "0.98", "size": "1311.61"}, {"price": "0.97", "size": "166"}, {"price": "0.96", "size": "255.41"}, {"price": "0.95", "size": "30"}, {"price": "0.94", "size": "33"}, {"price": "0.93", "size": "5.77"}, {"price": "0.92", "size": "125"}, {"price": "0.91", "size": "200"}, {"price": "0.9", "size": "400"}, {"price": "0.89", "size": "9.39"}, {"price": "0.86", "size": "66.66"}, {"price": "0.83", "size": "39"}, {"price": "0.81", "size": "19"}, {"price": "0.8", "size": "20"}, {"price": "0.77", "size": "145.66"}], "event_type": "book", "last_trade_price": ""}]}
{"_local_timestamp": "2026-01-25T23:40:43.183413+00:00", "data": {"market": "0x576b5f5f1ec1fb585d195f3310148efabbd11ec45679b7835228fb3431c648a4", "price_changes": [{"asset_id": "70963008880021254228771190647726911759536509259304029983946935833811359615992", "price": "0.25", "size": "20", "side": "BUY", "hash": "41636af48f555702590377750a981bd9af504da3", "best_bid": "0.25", "best_ask": "0.97"}, {"asset_id": "41480954438913063970197792021573332585554410838284506333996743209224990064024", "price": "0.75", "size": "20", "side": "SELL", "hash": "94cbdcfdd3be462a594a19e356787d140dac7b7b", "best_bid": "0.03", "best_ask": "0.75"}], "timestamp": "1769384443116", "event_type": "price_change"}}
{"_local_timestamp": "2026-01-25T23:40:52.965313+00:00", "data": {"market": "0x576b5f5f1ec1fb585d195f3310148efabbd11ec45679b7835228fb3431c648a4", "price_changes": [{"asset_id": "70963008880021254228771190647726911759536509259304029983946935833811359615992", "price": "0.19", "size": "0", "side": "BUY", "hash": "c798e75ac392f3c75a1e3565128b2ddce6ae8871", "best_bid": "0.25", "best_ask": "0.97"}, {"asset_id": "41480954438913063970197792021573332585554410838284506333996743209224990064024", "price": "0.81", "size": "0", "side": "SELL", "hash": "ee944fe93079c14707f76d39483ae0508da61c19", "best_bid": "0.03", "best_ask": "0.75"}], "timestamp": "1769384452899", "event_type": "price_change"}}
{"_local_timestamp": "2026-01-25T23:40:54.769650+00:00", "data": {"market": "0x576b5f5f1ec1fb585d195f3310148efabbd11ec45679b7835228fb3431c648a4", "price_changes": [{"asset_id": "70963008880021254228771190647726911759536509259304029983946935833811359615992", "price": "0.2", "size": "0", "side": "BUY", "hash": "d086c176d6c0ada3aceaab6793080957e661891d", "best_bid": "0.25", "best_ask": "0.97"}, {"asset_id": "41480954438913063970197792021573332585554410838284506333996743209224990064024", "price": "0.8", "size": "0", "side": "SELL", "hash": "69ad0174087e831feeb5b93dce194af607b29b85", "best_bid": "0.03", "best_ask": "0.75"}], "timestamp": "1769384454704", "event_type": "price_change"}}
{"_local_timestamp": "2026-01-25T23:40:54.799454+00:00", "data": {"market": "0x576b5f5f1ec1fb585d195f3310148efabbd11ec45679b7835228fb3431c648a4", "price_changes": [{"asset_id": "70963008880021254228771190647726911759536509259304029983946935833811359615992", "price": "0.18", "size": "20", "side": "BUY", "hash": "25ceb78705b36f2603b4089b6fbe7e6812acd6cf", "best_bid": "0.25", "best_ask": "0.97"}, {"asset_id": "41480954438913063970197792021573332585554410838284506333996743209224990064024", "price": "0.82", "size": "20", "side": "SELL", "hash": "45bee416cee92db87bae27961c56f0303b953f9e", "best_bid": "0.03", "best_ask": "0.75"}], "timestamp": "1769384454733", "event_type": "price_change"}}
{"_local_timestamp": "2026-01-25T23:42:47.547256+00:00", "data": {"market": "0x576b5f5f1ec1fb585d195f3310148efabbd11ec45679b7835228fb3431c648a4", "price_changes": [{"asset_id": "70963008880021254228771190647726911759536509259304029983946935833811359615992", "price": "0.23", "size": "79", "side": "BUY", "hash": "938dc1a77ddd1cfe19ece436862da943f16b6ff9", "best_bid": "0.25", "best_ask": "0.97"}, {"asset_id": "41480954438913063970197792021573332585554410838284506333996743209224990064024", "price": "0.77", "size": "79", "side": "SELL", "hash": "945e38cde65d0579f1bdaae882fb96f898856cfd", "best_bid": "0.03", "best_ask": "0.75"}], "timestamp": "1769384567429", "event_type": "price_change"}}
{"_local_timestamp": "2026-01-25T23:42:48.109838+00:00", "data": {"market": "0x576b5f5f1ec1fb585d195f3310148efabbd11ec45679b7835228fb3431c648a4", "price_changes": [{"asset_id": "70963008880021254228771190647726911759536509259304029983946935833811359615992", "price": "0.26", "size": "66.66", "side": "BUY", "hash": "95e66b88481124e73c87c44b692cb8d91797f961", "best_bid": "0.26", "best_ask": "0.97"}, {"asset_id": "41480954438913063970197792021573332585554410838284506333996743209224990064024", "price": "0.74", "size": "66.66", "side": "SELL", "hash": "f2d82411fc5c8d0c54ef48ffa8466e7c6cebbf38", "best_bid": "0.03", "best_ask": "0.74"}], "timestamp": "1769384567996", "event_type": "price_change"}}
{"_local_timestamp": "2026-01-25T23:42:48.151557+00:00", "data": {"market": "0x576b5f5f1ec1fb585d195f3310148efabbd11ec45679b7835228fb3431c648a4", "price_changes": [{"asset_id": "70963008880021254228771190647726911759536509259304029983946935833811359615992", "price": "0.25", "size": "0", "side": "BUY", "hash": "a733158339e07403bd9dddc8b0129ab199323e7f", "best_bid": "0.26", "best_ask": "0.97"}, {"asset_id": "41480954438913063970197792021573332585554410838284506333996743209224990064024", "price": "0.75", "size": "0", "side": "SELL", "hash": "2591706bc84a380c565c5651488767d6e94c1a66", "best_bid": "0.03", "best_ask": "0.74"}], "timestamp": "1769384568016", "event_type": "price_change"}}
{"_local_timestamp": "2026-01-25T23:42:48.157640+00:00", "data": {"market": "0x576b5f5f1ec1fb585d195f3310148efabbd11ec45679b7835228fb3431c648a4", "price_changes": [{"asset_id": "70963008880021254228771190647726911759536509259304029983946935833811359615992", "price": "0.26", "size": "86.66", "side": "BUY", "hash": "3d487540defd638ce946be4a288089f1fc18cabe", "best_bid": "0.26", "best_ask": "0.97"}, {"asset_id": "41480954438913063970197792021573332585554410838284506333996743209224990064024", "price": "0.74", "size": "86.66", "side": "SELL", "hash": "c9a554feed13b3a4c3ca232394e073318a9fd56b", "best_bid": "0.03", "best_ask": "0.74"}], "timestamp": "1769384568036", "event_type": "price_change"}}
{"_local_timestamp": "2026-01-25T23:43:18.807322+00:00", "data": {"market": "0x576b5f5f1ec1fb585d195f3310148efabbd11ec45679b7835228fb3431c648a4", "price_changes": [{"asset_id": "70963008880021254228771190647726911759536509259304029983946935833811359615992", "price": "0.23", "size": "0", "side": "BUY", "hash": "adc4998f1757c6944393e0465d8ba3d9aa3f3575", "best_bid": "0.26", "best_ask": "0.97"}, {"asset_id": "41480954438913063970197792021573332585554410838284506333996743209224990064024", "price": "0.77", "size": "0", "side": "SELL", "hash": "232f28fc72125621ccc92062aa6e00559df3aea5", "best_bid": "0.03", "best_ask": "0.74"}], "timestamp": "1769384598683", "event_type": "price_change"}}
{"_local_timestamp": "2026-01-25T23:43:52.520976+00:00", "data": {"market": "0x576b5f5f1ec1fb585d195f3310148efabbd11ec45679b7835228fb3431c648a4", "price_changes": [{"asset_id": "70963008880021254228771190647726911759536509259304029983946935833811359615992", "price": "0.01", "size": "1078.03", "side": "BUY", "hash": "5f64b02025639d4727e344e68eaac15fb089d4bc", "best_bid": "0.26", "best_ask": "0.97"}, {"asset_id": "41480954438913063970197792021573332585554410838284506333996743209224990064024", "price": "0.99", "size": "1078.03", "side": "SELL", "hash": "9840a0c15db5e0be5e1bd6cb5e08b91af3f3c018", "best_bid": "0.03", "best_ask": "0.74"}], "timestamp": "1769384632325", "event_type": "price_change"}}
{"_local_timestamp": "2026-01-25T23:43:52.521369+00:00", "data": {"market": "0x576b5f5f1ec1fb585d195f3310148efabbd11ec45679b7835228fb3431c648a4", "price_changes": [{"asset_id": "70963008880021254228771190647726911759536509259304029983946935833811359615992", "price": "0.02", "size": "511.61", "side": "BUY", "hash": "6179ccfaeefd450d235845bf1c6cb332c80f436d", "best_bid": "0.26", "best_ask": "0.97"}, {"asset_id": "41480954438913063970197792021573332585554410838284506333996743209224990064024", "price": "0.98", "size": "511.61", "side": "SELL", "hash": "be8c19d5781d8bdb9d40d5fbdf65c18559a91271", "best_bid": "0.03", "best_ask": "0.74"}], "timestamp": "1769384632329", "event_type": "price_change"}}
{"_local_timestamp": "2026-01-25T23:43:52.521654+00:00", "data": {"market": "0x576b5f5f1ec1fb585d195f3310148efabbd11ec45679b7835228fb3431c648a4", "price_changes": [{"asset_id": "70963008880021254228771190647726911759536509259304029983946935833811359615992", "price": "0.1", "size": "100", "side": "BUY", "hash": "6179ccfaeefd450d235845bf1c6cb332c80f436d", "best_bid": "0.26", "best_ask": "0.97"}, {"asset_id": "41480954438913063970197792021573332585554410838284506333996743209224990064024", "price": "0.9", "size": "100", "side": "SELL", "hash": "be8c19d5781d8bdb9d40d5fbdf65c18559a91271", "best_bid": "0.03", "best_ask": "0.74"}], "timestamp": "1769384632329", "event_type": "price_change"}}
{"_local_timestamp": "2026-01-25T23:45:33.027489+00:00", "data": {"market": "0xd426b5e37b1adeb4a30ed0ece09fe70b5ca0aee2392a43c97b18af26b3fec447", "price_changes": [{"asset_id": "31903753668568580194519745519436307034343004688882823786562874898525719905121", "price": "0.05", "size": "620", "side": "BUY", "hash": "7155e9179ae77a9da777d08dd6fea27ee57b37d7", "best_bid": "0.22", "best_ask": "0.86"}, {"asset_id": "52087909301984001009522958878332816194878042148980764948870893996379225172213", "price": "0.95", "size": "620", "side": "SELL", "hash": "629f1e5ed807bc362627476d3b5191bcbf0241ef", "best_bid": "0.14", "best_ask": "0.78"}], "timestamp": "1769384732950", "event_type": "price_change"}}
{"_local_timestamp": "2026-01-25T23:45:33.357343+00:00", "data": {"market": "0xd426b5e37b1adeb4a30ed0ece09fe70b5ca0aee2392a43c97b18af26b3fec447", "price_changes": [{"asset_id": "31903753668568580194519745519436307034343004688882823786562874898525719905121", "price": "0.06", "size": "133", "side": "BUY", "hash": "8394fe94848a34ef6ac059739a71e327060b6ea4", "best_bid": "0.22", "best_ask": "0.86"}, {"asset_id": "52087909301984001009522958878332816194878042148980764948870893996379225172213", "price": "0.94", "size": "133", "side": "SELL", "hash": "ab08b61427b8abc84a0506fad3e2c67ec6bfe740", "best_bid": "0.14", "best_ask": "0.78"}], "timestamp": "1769384733267", "event_type": "price_change"}}
{"_local_timestamp": "2026-01-25T23:46:12.354286+00:00", "data": {"market": "0xd426b5e37b1adeb4a30ed0ece09fe70b5ca0aee2392a43c97b18af26b3fec447", "price_changes": [{"asset_id": "31903753668568580194519745519436307034343004688882823786562874898525719905121", "price": "0.05", "size": "120", "side": "BUY", "hash": "1c6ea518c7f108484923c6b91d9e5ca20bf719c2", "best_bid": "0.22", "best_ask": "0.86"}, {"asset_id": "52087909301984001009522958878332816194878042148980764948870893996379225172213", "price": "0.95", "size": "120", "side": "SELL", "hash": "b098ce8b0d1d1cffdb7aab8aa1290944533795da", "best_bid": "0.14", "best_ask": "0.78"}], "timestamp": "1769384772285", "event_type": "price_change"}}
{"_local_timestamp": "2026-01-25T23:46:12.773158+00:00", "data": {"market": "0xd426b5e37b1adeb4a30ed0ece09fe70b5ca0aee2392a43c97b18af26b3fec447", "price_changes": [{"asset_id": "31903753668568580194519745519436307034343004688882823786562874898525719905121", "price": "0.06", "size": "633", "side": "BUY", "hash": "3bd0209703658958ac17584fb3576373f5f8cf38", "best_bid": "0.22", "best_ask": "0.86"}, {"asset_id": "52087909301984001009522958878332816194878042148980764948870893996379225172213", "price": "0.94", "size": "633", "side": "SELL", "hash": "97aad769461202ca2c00124579e81bc7d5eaa118", "best_bid": "0.14", "best_ask": "0.78"}], "timestamp": "1769384772696", "event_type": "price_change"}}
{"_local_timestamp": "2026-01-25T23:46:30.221169+00:00", "data": {"market": "0x576b5f5f1ec1fb585d195f3310148efabbd11ec45679b7835228fb3431c648a4", "price_changes": [{"asset_id": "70963008880021254228771190647726911759536509259304029983946935833811359615992", "price": "0.07", "size": "0", "side": "BUY", "hash": "3517ed3449167676a201ab5760eb968c60d2734d", "best_bid": "0.26", "best_ask": "0.97"}, {"asset_id": "41480954438913063970197792021573332585554410838284506333996743209224990064024", "price": "0.93", "size": "0", "side": "SELL", "hash": "644ed7afae4619037f43ea8752ce438129a54d5c", "best_bid": "0.03", "best_ask": "0.74"}], "timestamp": "1769384790139", "event_type": "price_change"}}
{"_local_timestamp": "2026-01-25T23:46:31.095170+00:00", "data": {"market": "0x576b5f5f1ec1fb585d195f3310148efabbd11ec45679b7835228fb3431c648a4", "price_changes": [{"asset_id": "70963008880021254228771190647726911759536509259304029983946935833811359615992", "price": "0.06", "size": "39.74", "side": "BUY", "hash": "78847bfa45175ee0cbbbf3e773e39ac2572974f2", "best_bid": "0.26", "best_ask": "0.97"}, {"asset_id": "41480954438913063970197792021573332585554410838284506333996743209224990064024", "price": "0.94", "size": "39.74", "side": "SELL", "hash": "77b2f94c244fccb039711cc7061734ccde5cc6ed", "best_bid": "0.03", "best_ask": "0.74"}], "timestamp": "1769384791008", "event_type": "price_change"}}
{"_local_timestamp": "2026-01-25T23:46:48.346390+00:00", "data": {"market": "0xd426b5e37b1adeb4a30ed0ece09fe70b5ca0aee2392a43c97b18af26b3fec447", "price_changes": [{"asset_id": "31903753668568580194519745519436307034343004688882823786562874898525719905121", "price": "0.03", "size": "273.86", "side": "BUY", "hash": "72dd43e932132d9e3a68da4c6b61d2ad1cd569a3", "best_bid": "0.22", "best_ask": "0.86"}, {"asset_id": "52087909301984001009522958878332816194878042148980764948870893996379225172213", "price": "0.97", "size": "273.86", "side": "SELL", "hash": "84bd6a947c54a8fae4b7fbe1418ae6e2f3ba75af", "best_bid": "0.14", "best_ask": "0.78"}], "timestamp": "1769384808281", "event_type": "price_change"}}
{"_local_timestamp": "2026-01-25T23:46:48.352224+00:00", "data": {"market": "0x3aa954bfa31f711f5931faf1c10c348c836489775295df087999120eeacccd55", "price_changes": [{"asset_id": "84130229918953255589546529005358461415977072942576966891079344531781581735938", "price": "0.05", "size": "130", "side": "BUY", "hash": "293657fc87bfa62fb00152de56bc33d28e8ce47a", "best_bid": "0.72", "best_ask": "0.95"}, {"asset_id": "31950047046821617093336746536010818826785645498651968760645249476800296107002", "price": "0.95", "size": "130", "side": "SELL", "hash": "ddb63a2eb4308b44020544089aaa17896b017939", "best_bid": "0.05", "best_ask": "0.28"}], "timestamp": "1769384808281", "event_type": "price_change"}}
{"_local_timestamp": "2026-01-25T23:46:48.650273+00:00", "data": {"market": "0xd426b5e37b1adeb4a30ed0ece09fe70b5ca0aee2392a43c97b18af26b3fec447", "price_changes": [{"asset_id": "31903753668568580194519745519436307034343004688882823786562874898525719905121", "price": "0.07", "size": "105.72", "side": "BUY", "hash": "dd25dd2a2a4f91b218acb368e3243e5116366616", "best_bid": "0.22", "best_ask": "0.86"}, {"asset_id": "52087909301984001009522958878332816194878042148980764948870893996379225172213", "price": "0.93", "size": "105.72", "side": "SELL", "hash": "518f50c9870deaff699ebafc7df3fbd514f02ffd", "best_bid": "0.14", "best_ask": "0.78"}], "timestamp": "1769384808572", "event_type": "price_change"}}
{"_local_timestamp": "2026-01-25T23:46:48.650628+00:00", "data": {"market": "0x576b5f5f1ec1fb585d195f3310148efabbd11ec45679b7835228fb3431c648a4", "price_changes": [{"asset_id": "70963008880021254228771190647726911759536509259304029983946935833811359615992", "price": "0.03", "size": "266", "side": "BUY", "hash": "1e8e5e223b49b70eccd484e7bba06bec4d73d2f2", "best_bid": "0.26", "best_ask": "0.97"}, {"asset_id": "41480954438913063970197792021573332585554410838284506333996743209224990064024", "price": "0.97", "size": "266", "side": "SELL", "hash": "69e6981561dc55475487bb7aa0f0e5a26485cb86", "best_bid": "0.03", "best_ask": "0.74"}], "timestamp": "1769384808573", "event_type": "price_change"}}
{"_local_timestamp": "2026-01-25T23:46:48.650932+00:00", "data": {"market": "0x3aa954bfa31f711f5931faf1c10c348c836489775295df087999120eeacccd55", "price_changes": [{"asset_id": "84130229918953255589546529005358461415977072942576966891079344531781581735938", "price": "0.07", "size": "200", "side": "BUY", "hash": "307cb1bb5a0458ac7230c61694ce21ef5152e352", "best_bid": "0.72", "best_ask": "0.95"}, {"asset_id": "31950047046821617093336746536010818826785645498651968760645249476800296107002", "price": "0.93", "size": "200", "side": "SELL", "hash": "067864f070c5e386710a83e74a2a200168b05eb8", "best_bid": "0.05", "best_ask": "0.28"}], "timestamp": "1769384808572", "event_type": "price_change"}}
{"_local_timestamp": "2026-01-25T23:47:45.618277+00:00", "data": {"market": "0xd426b5e37b1adeb4a30ed0ece09fe70b5ca0aee2392a43c97b18af26b3fec447", "price_changes": [{"asset_id": "31903753668568580194519745519436307034343004688882823786562874898525719905121", "price": "0.06", "size": "133", "side": "BUY", "hash": "2efb0eb659f90e6e821dd3ad597f21ab04e8df65", "best_bid": "0.22", "best_ask": "0.86"}, {"asset_id": "52087909301984001009522958878332816194878042148980764948870893996379225172213", "price": "0.94", "size": "133", "side": "SELL", "hash": "4ff77d8d528f4b7cb7f4395904445348fe5713bb", "best_bid": "0.14", "best_ask": "0.78"}], "timestamp": "1769384865520", "event_type": "price_change"}}
{"_local_timestamp": "2026-01-25T23:47:45.619011+00:00", "data": {"market": "0x3aa954bfa31f711f5931faf1c10c348c836489775295df087999120eeacccd55", "price_changes": [{"asset_id": "84130229918953255589546529005358461415977072942576966891079344531781581735938", "price": "0.06", "size": "233", "side": "BUY", "hash": "457b7b02aa633e98b0d315254dea0e3441c72aed", "best_bid": "0.72", "best_ask": "0.95"}, {"asset_id": "31950047046821617093336746536010818826785645498651968760645249476800296107002", "price": "0.94", "size": "233", "side": "SELL", "hash": "4828cea3b245dd3a69d03392d0dd559a38fb0966", "best_bid": "0.05", "best_ask": "0.28"}], "timestamp": "1769384865520", "event_type": "price_change"}}
{"_local_timestamp": "2026-01-25T23:47:45.936192+00:00", "data": {"market": "0x3aa954bfa31f711f5931faf1c10c348c836489775295df087999120eeacccd55", "price_changes": [{"asset_id": "84130229918953255589546529005358461415977072942576966891079344531781581735938", "price": "0.07", "size": "700", "side": "BUY", "hash": "8140401fa8dc6bbac9f0493482ce11c49e1c7307", "best_bid": "0.72", "best_ask": "0.95"}, {"asset_id": "31950047046821617093336746536010818826785645498651968760645249476800296107002", "price": "0.93", "size": "700", "side": "SELL", "hash": "11359e5ae6ab567d5380e1e3b3db9057950336a4", "best_bid": "0.05", "best_ask": "0.28"}], "timestamp": "1769384865845", "event_type": "price_change"}}
{"_local_timestamp": "2026-01-25T23:47:45.936633+00:00", "data": {"market": "0xd426b5e37b1adeb4a30ed0ece09fe70b5ca0aee2392a43c97b18af26b3fec447", "price_changes": [{"asset_id": "31903753668568580194519745519436307034343004688882823786562874898525719905121", "price": "0.07", "size": "605.72", "side": "BUY", "hash": "0d2747954bf9427982f2ae040707a4542181522f", "best_bid": "0.22", "best_ask": "0.86"}, {"asset_id": "52087909301984001009522958878332816194878042148980764948870893996379225172213", "price": "0.93", "size": "605.72", "side": "SELL", "hash": "188c2e0ac775af3dee3fe2968a5cf12d593b25ae", "best_bid": "0.14", "best_ask": "0.78"}], "timestamp": "1769384865845", "event_type": "price_change"}}
{"_local_timestamp": "2026-01-25T23:48:12.316496+00:00", "data": {"market": "0xd426b5e37b1adeb4a30ed0ece09fe70b5ca0aee2392a43c97b18af26b3fec447", "price_changes": [{"asset_id": "31903753668568580194519745519436307034343004688882823786562874898525719905121", "price": "0.11", "size": "0", "side": "BUY", "hash": "a86aeeb99db15d77b7d142e816ebd797d97d8dec", "best_bid": "0.22", "best_ask": "0.86"}, {"asset_id": "52087909301984001009522958878332816194878042148980764948870893996379225172213", "price": "0.89", "size": "0", "side": "SELL", "hash": "b688ff29af527a571c4e7e92bfcaedd137b987a6", "best_bid": "0.14", "best_ask": "0.78"}], "timestamp": "1769384892243", "event_type": "price_change"}}
{"_local_timestamp": "2026-01-25T23:48:12.317103+00:00", "data": {"market": "0xd426b5e37b1adeb4a30ed0ece09fe70b5ca0aee2392a43c97b18af26b3fec447", "price_changes": [{"asset_id": "31903753668568580194519745519436307034343004688882823786562874898525719905121", "price": "0.03", "size": "207.2", "side": "BUY", "hash": "a86aeeb99db15d77b7d142e816ebd797d97d8dec", "best_bid": "0.22", "best_ask": "0.86"}, {"asset_id": "52087909301984001009522958878332816194878042148980764948870893996379225172213", "price": "0.97", "size": "207.2", "side": "SELL", "hash": "b688ff29af527a571c4e7e92bfcaedd137b987a6", "best_bid": "0.14", "best_ask": "0.78"}], "timestamp": "1769384892243", "event_type": "price_change"}}
{"_local_timestamp": "2026-01-25T23:48:12.826096+00:00", "data": {"market": "0xd426b5e37b1adeb4a30ed0ece09fe70b5ca0aee2392a43c97b18af26b3fec447", "price_changes": [{"asset_id": "31903753668568580194519745519436307034343004688882823786562874898525719905121", "price": "0.15", "size": "66.66", "side": "BUY", "hash": "6fdfc8c4fd162d37609f9bf00d92e9367c4093ea", "best_bid": "0.22", "best_ask": "0.86"}, {"asset_id": "52087909301984001009522958878332816194878042148980764948870893996379225172213", "price": "0.85", "size": "66.66", "side": "SELL", "hash": "f9eda9908d07708fdc8b4c45ef2cd0499ed3663e", "best_bid": "0.14", "best_ask": "0.78"}], "timestamp": "1769384892764", "event_type": "price_change"}}
{"_local_timestamp": "2026-01-25T23:48:12.832920+00:00", "data": {"market": "0xd426b5e37b1adeb4a30ed0ece09fe70b5ca0aee2392a43c97b18af26b3fec447", "price_changes": [{"asset_id": "31903753668568580194519745519436307034343004688882823786562874898525719905121", "price": "0.07", "size": "672.38", "side": "BUY", "hash": "94501567d6daf3cafa628f12569e9bd112a44b03", "best_bid": "0.22", "best_ask": "0.86"}, {"asset_id": "52087909301984001009522958878332816194878042148980764948870893996379225172213", "price": "0.93", "size": "672.38", "side": "SELL", "hash": "3ce0552ec1cf322443a67d20b50e232e491440a8", "best_bid": "0.14", "best_ask": "0.78"}], "timestamp": "1769384892766", "event_type": "price_change"}}
{"_local_timestamp": "2026-01-25T23:48:54.109448+00:00", "data": {"market": "0x576b5f5f1ec1fb585d195f3310148efabbd11ec45679b7835228fb3431c648a4", "price_changes": [{"asset_id": "70963008880021254228771190647726911759536509259304029983946935833811359615992", "price": "0.19", "size": "158", "side": "BUY", "hash": "f441d8f8710bc520074b52d7bf1afdf640e033e0", "best_bid": "0.26", "best_ask": "0.97"}, {"asset_id": "41480954438913063970197792021573332585554410838284506333996743209224990064024", "price": "0.81", "size": "158", "side": "SELL", "hash": "e796fbb7e2cb9930571932fe92f1310776a403b0", "best_bid": "0.03", "best_ask": "0.74"}], "timestamp": "1769384934036", "event_type": "price_change"}}
{"_local_timestamp": "2026-01-25T23:48:54.110515+00:00", "data": {"market": "0x576b5f5f1ec1fb585d195f3310148efabbd11ec45679b7835228fb3431c648a4", "price_changes": [{"asset_id": "70963008880021254228771190647726911759536509259304029983946935833811359615992", "price": "0.18", "size": "178", "side": "BUY", "hash": "461e72cf1d8f8fc446d74d15bdf6edbc22e57845", "best_bid": "0.26", "best_ask": "0.97"}, {"asset_id": "41480954438913063970197792021573332585554410838284506333996743209224990064024", "price": "0.82", "size": "178", "side": "SELL", "hash": "67c99a159a28400e86422f153f50bcdb947add83", "best_bid": "0.03", "best_ask": "0.74"}], "timestamp": "1769384934037", "event_type": "price_change"}}
{"_local_timestamp": "2026-01-25T23:49:00.191929+00:00", "data": {"market": "0x576b5f5f1ec1fb585d195f3310148efabbd11ec45679b7835228fb3431c648a4", "price_changes": [{"asset_id": "70963008880021254228771190647726911759536509259304029983946935833811359615992", "price": "0.18", "size": "158", "side": "BUY", "hash": "c07dea75ed2c0ebb5789192151dbe05550f54cf3", "best_bid": "0.26", "best_ask": "0.97"}, {"asset_id": "41480954438913063970197792021573332585554410838284506333996743209224990064024", "price": "0.82", "size": "158", "side": "SELL", "hash": "4b65552e871d479e946a41d2611c03d061fa3fdb", "best_bid": "0.03", "best_ask": "0.74"}], "timestamp": "1769384940126", "event_type": "price_change"}}
{"_local_timestamp": "2026-01-25T23:49:00.217306+00:00", "data": {"market": "0x576b5f5f1ec1fb585d195f3310148efabbd11ec45679b7835228fb3431c648a4", "price_changes": [{"asset_id": "70963008880021254228771190647726911759536509259304029983946935833811359615992", "price": "0.2", "size": "20", "side": "BUY", "hash": "63de69dc32ae04d4784ed9cac20f9634e94f5785", "best_bid": "0.26", "best_ask": "0.97"}, {"asset_id": "41480954438913063970197792021573332585554410838284506333996743209224990064024", "price": "0.8", "size": "20", "side": "SELL", "hash": "5a737c499154a96d0627b0f918b8d50c619186d5", "best_bid": "0.03", "best_ask": "0.74"}], "timestamp": "1769384940152", "event_type": "price_change"}}
{"_local_timestamp": "2026-01-25T23:49:10.659858+00:00", "data": {"market": "0x576b5f5f1ec1fb585d195f3310148efabbd11ec45679b7835228fb3431c648a4", "price_changes": [{"asset_id": "70963008880021254228771190647726911759536509259304029983946935833811359615992", "price": "0.18", "size": "0", "side": "BUY", "hash": "c1c75c9efa6a57a5bce6b59172ff27fa6a3dba29", "best_bid": "0.26", "best_ask": "0.97"}, {"asset_id": "41480954438913063970197792021573332585554410838284506333996743209224990064024", "price": "0.82", "size": "0", "side": "SELL", "hash": "a46895c1e86ec3051dbb4eb4e72739f039257ae5", "best_bid": "0.03", "best_ask": "0.74"}], "timestamp": "1769384950580", "event_type": "price_change"}}
{"_local_timestamp": "2026-01-25T23:49:23.292517+00:00", "data": {"market": "0x576b5f5f1ec1fb585d195f3310148efabbd11ec45679b7835228fb3431c648a4", "price_changes": [{"asset_id": "70963008880021254228771190647726911759536509259304029983946935833811359615992", "price": "0.19", "size": "0", "side": "BUY", "hash": "56ea8a206e4e4d59ac501449279de857552b5afd", "best_bid": "0.26", "best_ask": "0.97"}, {"asset_id": "41480954438913063970197792021573332585554410838284506333996743209224990064024", "price": "0.81", "size": "0", "side": "SELL", "hash": "79b0b6a6dcb1d7b7dbc59ce17c971a9dc6075a75", "best_bid": "0.03", "best_ask": "0.74"}], "timestamp": "1769384963227", "event_type": "price_change"}}
{"_local_timestamp": "2026-01-25T23:49:27.587814+00:00", "data": {"market": "0x576b5f5f1ec1fb585d195f3310148efabbd11ec45679b7835228fb3431c648a4", "price_changes": [{"asset_id": "70963008880021254228771190647726911759536509259304029983946935833811359615992", "price": "0.2", "size": "0", "side": "BUY", "hash": "01711e2d4c727910dfc3ccc462da74122e10bb3c", "best_bid": "0.26", "best_ask": "0.97"}, {"asset_id": "41480954438913063970197792021573332585554410838284506333996743209224990064024", "price": "0.8", "size": "0", "side": "SELL", "hash": "c4834a4dc2fcacbeba4e568dacfca0802b8d9c45", "best_bid": "0.03", "best_ask": "0.74"}], "timestamp": "1769384967523", "event_type": "price_change"}}
{"_local_timestamp": "2026-01-25T23:49:27.638784+00:00", "data": {"market": "0x576b5f5f1ec1fb585d195f3310148efabbd11ec45679b7835228fb3431c648a4", "price_changes": [{"asset_id": "70963008880021254228771190647726911759536509259304029983946935833811359615992", "price": "0.18", "size": "20", "side": "BUY", "hash": "2f6c71dda4c9a86bdc90e8e7cecf0fbeefa79123", "best_bid": "0.26", "best_ask": "0.97"}, {"asset_id": "41480954438913063970197792021573332585554410838284506333996743209224990064024", "price": "0.82", "size": "20", "side": "SELL", "hash": "6669f7f370f531729cdcce7b0d02aca2b71143ab", "best_bid": "0.03", "best_ask": "0.74"}], "timestamp": "1769384967560", "event_type": "price_change"}}
{"_local_timestamp": "2026-01-25T23:49:36.169647+00:00", "data": {"market": "0x576b5f5f1ec1fb585d195f3310148efabbd11ec45679b7835228fb3431c648a4", "price_changes": [{"asset_id": "70963008880021254228771190647726911759536509259304029983946935833811359615992", "price": "0.09", "size": "100", "side": "BUY", "hash": "02d87d89acfb767d409190792539f152e8060d0e", "best_bid": "0.26", "best_ask": "0.97"}, {"asset_id": "41480954438913063970197792021573332585554410838284506333996743209224990064024", "price": "0.91", "size": "100", "side": "SELL", "hash": "484d6577bb640637a2fa2909dbdfbb8a99c1d608", "best_bid": "0.03", "best_ask": "0.74"}], "timestamp": "1769384976087", "event_type": "price_change"}}
{"_local_timestamp": "2026-01-25T23:49:36.455327+00:00", "data": {"market": "0x576b5f5f1ec1fb585d195f3310148efabbd11ec45679b7835228fb3431c648a4", "price_changes": [{"asset_id": "70963008880021254228771190647726911759536509259304029983946935833811359615992", "price": "0.03", "size": "366", "side": "BUY", "hash": "c046b26680da57436a2aa071120323bcc279dca5", "best_bid": "0.26", "best_ask": "0.97"}, {"asset_id": "41480954438913063970197792021573332585554410838284506333996743209224990064024", "price": "0.97", "size": "366", "side": "SELL", "hash": "6d57acf603b4df0941ad592cdca04ab3a960ed5d", "best_bid": "0.03", "best_ask": "0.74"}], "timestamp": "1769384976378", "event_type": "price_change"}}
{"_local_timestamp": "2026-01-25T23:50:39.702277+00:00", "data": {"market": "0x576b5f5f1ec1fb585d195f3310148efabbd11ec45679b7835228fb3431c648a4", "price_changes": [{"asset_id": "70963008880021254228771190647726911759536509259304029983946935833811359615992", "price": "0.03", "size": "300", "side": "BUY", "hash": "9f9eb811be2021587f1b944e29f8ba50b511d20c", "best_bid": "0.26", "best_ask": "0.97"}, {"asset_id": "41480954438913063970197792021573332585554410838284506333996743209224990064024", "price": "0.97", "size": "300", "side": "SELL", "hash": "5a1ff6a77de831cb16a7dc80656e25f057f3d6cd", "best_bid": "0.03", "best_ask": "0.74"}], "timestamp": "1769385039474", "event_type": "price_change"}}
{"_local_timestamp": "2026-01-25T23:50:40.071372+00:00", "data": {"market": "0x576b5f5f1ec1fb585d195f3310148efabbd11ec45679b7835228fb3431c648a4", "price_changes": [{"asset_id": "70963008880021254228771190647726911759536509259304029983946935833811359615992", "price": "0.05", "size": "70", "side": "BUY", "hash": "0487d2e4fe9a920f2d108f2f110bf0441cff6b60", "best_bid": "0.26", "best_ask": "0.97"}, {"asset_id": "41480954438913063970197792021573332585554410838284506333996743209224990064024", "price": "0.95", "size": "70", "side": "SELL", "hash": "8dab70c02f5c66fe0c34c35bb3926eb9fe05b1c1", "best_bid": "0.03", "best_ask": "0.74"}], "timestamp": "1769385039528", "event_type": "price_change"}}
{"_local_timestamp": "2026-01-25T23:50:51.096361+00:00", "data": {"market": "0x576b5f5f1ec1fb585d195f3310148efabbd11ec45679b7835228fb3431c648a4", "price_changes": [{"asset_id": "70963008880021254228771190647726911759536509259304029983946935833811359615992", "price": "0.26", "size": "66.66", "side": "BUY", "hash": "1384b47d858420fcd40d8961c6c72179ef5473c6", "best_bid": "0.26", "best_ask": "0.97"}, {"asset_id": "41480954438913063970197792021573332585554410838284506333996743209224990064024", "price": "0.74", "size": "66.66", "side": "SELL", "hash": "354b8edfb9dc4e99e356d8f5169267cc48550d85", "best_bid": "0.03", "best_ask": "0.74"}], "timestamp": "1769385051001", "event_type": "price_change"}}
{"_local_timestamp": "2026-01-25T23:50:51.144577+00:00", "data": {"market": "0x576b5f5f1ec1fb585d195f3310148efabbd11ec45679b7835228fb3431c648a4", "price_changes": [{"asset_id": "70963008880021254228771190647726911759536509259304029983946935833811359615992", "price": "0.26", "size": "86.66", "side": "BUY", "hash": "7bce66122ec02bc9c284e5ef948a628b31eeae82", "best_bid": "0.26", "best_ask": "0.97"}, {"asset_id": "41480954438913063970197792021573332585554410838284506333996743209224990064024", "price": "0.74", "size": "86.66", "side": "SELL", "hash": "17d64adb4705137e240c93424f0975298c947e09", "best_bid": "0.03", "best_ask": "0.74"}], "timestamp": "1769385051055", "event_type": "price_change"}}
