{"_local_timestamp": "2026-01-25T23:40:42.074535+00:00", "data": [{"market": "0x0edc31cc586c65726249da0c698ce2b0dc3acac65a7b96574b7a8a89321ecf9e", "asset_id": "86948609484193076545604092003532216745788551371556780169247204971522981358794", "timestamp": "1769384304630", "hash": "2c7cf378f2b46ab4022d004363317c77d9a918ef", "bids": [{"price": "0.001", "size": "14058.99"}, {"price": "0.002", "size": "4520.04"}, {"price": "0.003", "size": "263.28"}, {"price": "0.004", "size": "19.75"}, {"price": "0.005", "size": "500"}, {"price": "0.006", "size": "31.68"}, {"price": "0.01", "size": "700"}, {"price": "0.011", "size": "843.76"}, {"price": "0.012", "size": "400"}, {"price": "0.013", "size": "5.76"}, {"price": "0.014", "size": "100"}, {"price": "0.016", "size": "355.27"}, {"price": "0.018", "size": "100"}, {"price": "0.019", "size": "6.4"}, {"price": "0.02", "size": "117.19"}], "asks": [{"price": "0.999", "size": "7265.83"}, {"price": "0.998", "size": "5.79"}, {"price": "0.997", "size": "1000"}, {"price": "0.996", "size": "23.32"}, {"price": "0.99", "size": "6006"}, {"price": "0.98", "size": "2200"}, {"price": "0.979", "size": "15.91"}, {"price": "0.95", "size": "165.4"}, {"price": "0.94", "size": "466"}, {"price": "0.9", "size": "560"}, {"price": "0.899", "size": "5.49"}, {"price": "0.89", "size": "250"}, {"price": "0.86", "size": "5"}, {"price": "0.85", "size": "776.66"}, {"price": "0.8", "size": "660"}, {"price": "0.78", "size": "5"}, {"price": "0.76", "size": "366.66"}, {"price": "0.759", "size": "8"}, {"price": "0.71", "size": "189.65"}, {"price": "0.66", "size": "70.58"}, {"price": "0.64", "size": "5"}, {"price": "0.63", "size": "5"}, {"price": "0.61", "size": "176.28"}, {"price": "0.44", "size": "5"}, {"price": "0.3", "size": "1000"}, {"price": "0.2", "size": "5"}, {"price": "0.15", "size": "5"}, {"price": "0.13", "size": "7000"}, {"price": "0.12", "size": "2000"}, {"price": "0.084", "size": "500"}, {"price": "0.058", "size": "1.43"}, {"price": "0.047", "size": "300"}, {"price": "0.045", "size": "500"}, {"price": "0.044", "size": "20"}, {"price": "0.035", "size": "200"}, {"price": "0.029", "size": "744.23"}, {"price": "0.028", "size": "200"}, {"price": "0.027", "size": "6.82"}, {"price": "0.026", "size": "9.69"}], "event_type": "book", "last_trade_price": "0.980"}, {"market": "0x830532ef53004df7522d7c56cad9af92f4b323590e7712302efdd99fa04cc078", "asset_id": "76159445949516107531196937780408758100497431686502173729855321957977280983930", "timestamp": "1769384295670", "hash": "4dcfedc24cbeb74e04067c551546a168d972f042", "bids": [{"price": "0.001", "size": "15425.99"}, {"price": "0.002", "size": "2524.71"}, {"price": "0.003", "size": "266.5"}, {"price": "0.004", "size": "77.19"}, {"price": "0.01", "size": "1250"}, {"price": "0.011", "size": "827.2"}, {"price": "0.012", "size": "517"}, {"price": "0.013", "size": "107.7"}, {"price": "0.015", "size": "26.05"}, {"price": "0.016", "size": "233"}, {"price": "0.021", "size": "123.63"}], "asks": [{"price": "0.999", "size": "4632.16"}, {"price": "0.998", "size": "1255.13"}, {"price": "0.997", "size": "1000"}, {"price": "0.996", "size": "20.78"}, {"price": "0.99", "size": "5000"}, {"price": "0.98", "size": "2200"}, {"price": "0.979", "size": "14.64"}, {"price": "0.95", "size": "30"}, {"price": "0.94", "size": "433"}, {"price": "0.9", "size": "860"}, {"price": "0.899", "size": "5.87"}, {"price": "0.85", "size": "776.66"}, {"price": "0.81", "size": "5"}, {"price": "0.8", "size": "660"}, {"price": "0.799", "size": "192"}, {"price": "0.78", "size": "5"}, {"price": "0.75", "size": "362"}, {"price": "0.72", "size": "5"}, {"price": "0.7", "size": "191.66"}, {"price": "0.65", "size": "68.57"}, {"price": "0.61", "size": "176.28"}, {"price": "0.609", "size": "5"}, {"price": "0.41", "size": "30"}, {"price": "0.29", "size": "40"}, {"price": "0.23", "size": "30"}, {"price": "0.19", "size": "908"}, {"price": "0.16", "size": "10"}, {"price": "0.13", "size": "5"}, {"price": "0.1", "size": "782"}, {"price": "0.07", "size": "44.72"}, {"price": "0.049", "size": "500"}, {"price": "0.046", "size": "300"}, {"price": "0.045", "size": "312.59"}, {"price": "0.044", "size": "280.09"}, {"price": "0.04", "size": "5"}, {"price": "0.039", "size": "100"}, {"price": "0.036", "size": "60.92"}, {"price": "0.034", "size": "222"}, {"price": "0.033", "size": "254.8"}, {"price": "0.03", "size": "200"}, {"price": "0.029", "size": "20.39"}], "event_type": "book", "last_trade_price": "0.021"}, {"market": "0xddda6004eefcf0ab8f542faa9856efec647d63bbbe70feb4c5dca376df32e8d7", "asset_id": "105357237982191656127719049458930828486417245494585420518830232261954691323810", "timestamp": "1769384305154", "hash": "3a65e53434dedd2f842ffb2a3fcb56a71db237a9", "bids": [{"price": "0.001", "size": "18282.65"}, {"price": "0.002", "size": "417.5"}, {"price": "0.003", "size": "1111.11"}, {"price": "0.004", "size": "1619.96"}, {"price": "0.005", "size": "70"}], "asks": [{"price": "0.999", "size": "6075.08"}, {"price": "0.998", "size": "1255.05"}, {"price": "0.997", "size": "1000"}, {"price": "0.996", "size": "20.49"}, {"price": "0.99", "size": "5000"}, {"price": "0.98", "size": "2200"}, {"price": "0.979", "size": "14.64"}, {"price": "0.95", "size": "30"}, {"price": "0.949", "size": "39"}, {"price": "0.94", "size": "400"}, {"price": "0.9", "size": "860"}, {"price": "0.899", "size": "250"}, {"price": "0.898", "size": "5.83"}, {"price": "0.85", "size": "776.66"}, {"price": "0.8", "size": "660"}, {"price": "0.75", "size": "212"}, {"price": "0.709", "size": "450"}, {"price": "0.7", "size": "86.66"}, {"price": "0.65", "size": "68.57"}, {"price": "0.6", "size": "175"}, {"price": "0.34", "size": "1000"}, {"price": "0.339", "size": "300"}, {"price": "0.25", "size": "24.39"}, {"price": "0.219", "size": "800"}, {"price": "0.217", "size": "500"}, {"price": "0.2", "size": "1834.72"}, {"price": "0.199", "size": "500"}, {"price": "0.157", "size": "300"}, {"price": "0.156", "size": "500"}, {"price": "0.143", "size": "200"}, {"price": "0.096", "size": "100"}, {"price": "0.094", "size": "500"}, {"price": "0.086", "size": "100"}, {"price": "0.085", "size": "100"}, {"price": "0.083", "size": "300"}, {"price": "0.049", "size": "350"}, {"price": "0.048", "size": "300"}, {"price": "0.027", "size": "500"}, {"price": "0.02", "size": "350"}, {"price": "0.019", "size": "500"}, {"price": "0.01", "size": "150"}, {"price": "0.007", "size": "987.49"}], "event_type": "book", "last_trade_price": "0.993"}, {"market": "0xddda6004eefcf0ab8f542faa9856efec647d63bbbe70feb4c5dca376df32e8d7", "asset_id": "60727132855373489262818696860770549261966005006541840363443788706996682318728", "timestamp": "1769384305154", "hash": "8d1ac261bd963013f95bfda4746d17dd6b5912c9", "bids": [{"price": "0.001", "size": "6075.08"}, {"price": "0.002", "size": "1255.05"}, {"price": "0.003", "size": "1000"}, {"price": "0.004", "size": "20.49"}, {"price": "0.01", "size": "5000"}, {"price": "0.02", "size": "2200"}, {"price": "0.021", "size": "14.64"}, {"price": "0.05", "size": "30"}, {"price": "0.051", "size": "39"}, {"price": "0.06", "size": "400"}, {"price": "0.1", "size": "860"}, {"price": "0.101", "size": "250"}, {"price": "0.102", "size": "5.83"}, {"price": "0.15", "size": "776.66"}, {"price": "0.2", "size": "660"}, {"price": "0.25", "size": "212"}, {"price": "0.291", "size": "450"}, {"price": "0.3", "size": "86.66"}, {"price": "0.35", "size": "68.57"}, {"price": "0.4", "size": "175"}, {"price": "0.66", "size": "1000"}, {"price": "0.661", "size": "300"}, {"price": "0.75", "size": "24.39"}, {"price": "0.781", "size": "800"}, {"price": "0.783", "size": "500"}, {"price": "0.8", "size": "1834.72"}, {"price": "0.801", "size": "500"}, {"price": "0.843", "size": "300"}, {"price": "0.844", "size": "500"}, {"price": "0.857", "size": "200"}, {"price": "0.904", "size": "100"}, {"price": "0.906", "size": "500"}, {"price": "0.914", "size": "100"}, {"price": "0.915", "size": "100"}, {"price": "0.917", "size": "300"}, {"price": "0.951", "size": "350"}, {"price": "0.952", "size": "300"}, {"price": "0.973", "size": "500"}, {"price": "0.98", "size": "350"}, {"price": "0.981", "size": "500"}, {"price": "0.99", "size": "150"}, {"price": "0.993", "size": "987.49"}], "asks": [{"price": "0.999", "size": "18282.65"}, {"price": "0.998", "size": "417.5"}, {"price": "0.997", "size": "1111.11"}, {"price": "0.996", "size": "1619.96"}, {"price": "0.995", "size": "70"}], "event_type": "book", "last_trade_price": "0.993"}, {"market": "0xc8944bb47818c0957fbeedcef9832d31927bd5d3f92912d08ae7db507ee851de", "asset_id": "115373591989130727514457065197328696865580700117510285020088208107086541485978", "timestamp": "1769384261109", "hash": "f6aca302a1112b43372d1029d7c403bb99c4be2a", "bids": [{"price": "0.001", "size": "4029.26"}, {"price": "0.002", "size": "1250"}, {"price": "0.003", "size": "1406.66"}, {"price": "0.006", "size": "200"}, {"price": "0.007", "size": "9.55"}, {"price": "0.01", "size": "5000"}, {"price": "0.02", "size": "2200"}, {"price": "0.021", "size": "15.77"}, {"price": "0.05", "size": "30"}, {"price": "0.051", "size": "39"}, {"price": "0.06", "size": "400"}, {"price": "0.1", "size": "1377.21"}, {"price": "0.108", "size": "258.22"}, {"price": "0.109", "size": "129"}, {"price": "0.11", "size": "5.19"}, {"price": "0.124", "size": "100"}, {"price": "0.15", "size": "776.66"}, {"price": "0.2", "size": "789.04"}, {"price": "0.25", "size": "362"}, {"price": "0.3", "size": "186.66"}, {"price": "0.35", "size": "68.57"}, {"price": "0.4", "size": "175"}, {"price": "0.401", "size": "5"}, {"price": "0.55", "size": "129.04"}, {"price": "0.91", "size": "94.97"}, {"price": "0.912", "size": "120"}, {"price": "0.913", "size": "100"}, {"price": "0.932", "size": "10"}, {"price": "0.961", "size": "5"}, {"price": "0.974", "size": "5"}, {"price": "0.976", "size": "5"}, {"price": "0.978", "size": "2222"}, {"price": "0.979", "size": "5"}, {"price": "0.981", "size": "5"}, {"price": "0.984", "size": "5"}, {"price": "0.985", "size": "2000"}, {"price": "0.986", "size": "560"}, {"price": "0.988", "size": "527.02"}, {"price": "0.991", "size": "693.71"}, {"price": "0.992", "size": "57.01"}, {"price": "0.993", "size": "11.06"}, {"price": "0.994", "size": "49"}], "asks": [{"price": "0.999", "size": "24893"}, {"price": "0.998", "size": "1432.91"}, {"price": "0.997", "size": "493.65"}, {"price": "0.996", "size": "95.6"}, {"price": "0.995", "size": "1080.91"}], "event_type": "book", "last_trade_price": "0.995"}, {"market": "0xb10aef4e56904ddab4f634b3bef36e878522d174ffb49688d3bca4e225516689", "asset_id": "67794036975373042160958042377401666699501615403692529610067934475766181787521", "timestamp": "1769384434971", "hash": "36a1b60624f397cf09f77979cbb12b21c376b398", "bids": [{"price": "0.001", "size": "4381.19"}, {"price": "0.002", "size": "1250"}, {"price": "0.003", "size": "1172.7"}, {"price": "0.006", "size": "83"}, {"price": "0.007", "size": "9.6"}, {"price": "0.01", "size": "5000"}, {"price": "0.02", "size": "2200"}, {"price": "0.021", "size": "14.68"}, {"price": "0.05", "size": "30"}, {"price": "0.051", "size": "39"}, {"price": "0.06", "size": "400"}, {"price": "0.1", "size": "860"}, {"price": "0.101", "size": "250"}, {"price": "0.102", "size": "5.82"}, {"price": "0.15", "size": "776.66"}, {"price": "0.2", "size": "660"}, {"price": "0.25", "size": "362"}, {"price": "0.3", "size": "186.66"}, {"price": "0.35", "size": "68.57"}, {"price": "0.4", "size": "246.42"}, {"price": "0.401", "size": "5"}, {"price": "0.934", "size": "39.06"}, {"price": "0.95", "size": "1111"}, {"price": "0.96", "size": "1111"}, {"price": "0.963", "size": "500"}, {"price": "0.983", "size": "200"}, {"price": "0.984", "size": "125.71"}, {"price": "0.985", "size": "435"}, {"price": "0.993", "size": "3134.76"}, {"price": "0.994", "size": "647.22"}, {"price": "0.995", "size": "667.27"}], "asks": [{"price": "0.999", "size": "18120.99"}, {"price": "0.998", "size": "1428.87"}, {"price": "0.996", "size": "420.99"}], "event_type": "book", "last_trade_price": "0.004"}, {"market": "0x33825080bc810aa756a361298627cdf64d58dbd651a647bd0a29b8a68a7308fe", "asset_id": "108112487379868796554191891208463687446351004748640934416300530966194496905118", "timestamp": "1769384425551", "hash": "0a2350f62b6effd26102d2f9619a46f79d1ad2cf", "bids": [{"price": "0.001", "size": "4779.8"}, {"price": "0.002", "size": "5.76"}, {"price": "0.003", "size": "1000"}, {"price": "0.004", "size": "9.83"}, {"price": "0.01", "size": "5000"}, {"price": "0.011", "size": "5.32"}, {"price": "0.02", "size": "2200"}, {"price": "0.021", "size": "250"}, {"price": "0.022", "size": "15.04"}, {"price": "0.05", "size": "215.6"}, {"price": "0.06", "size": "433"}, {"price": "0.1", "size": "1031.69"}, {"price": "0.101", "size": "5.48"}, {"price": "0.15", "size": "826.66"}, {"price": "0.19", "size": "168.42"}, {"price": "0.2", "size": "400"}, {"price": "0.201", "size": "846"}, {"price": "0.24", "size": "321.66"}, {"price": "0.27", "size": "5"}, {"price": "0.29", "size": "89.65"}, {"price": "0.3", "size": "150"}, {"price": "0.301", "size": "1494"}, {"price": "0.34", "size": "70.58"}, {"price": "0.39", "size": "51.28"}, {"price": "0.395", "size": "1643"}, {"price": "0.396", "size": "5"}, {"price": "0.47", "size": "15"}, {"price": "0.5", "size": "20"}, {"price": "0.53", "size": "85.33"}, {"price": "0.55", "size": "5"}, {"price": "0.67", "size": "10"}, {"price": "0.7", "size": "177.21"}, {"price": "0.728", "size": "18.52"}, {"price": "0.824", "size": "9.99"}, {"price": "0.85", "size": "205"}, {"price": "0.86", "size": "1100"}, {"price": "0.87", "size": "1126.14"}, {"price": "0.88", "size": "415.75"}, {"price": "0.881", "size": "7043.3"}, {"price": "0.882", "size": "25"}, {"price": "0.9", "size": "5"}, {"price": "0.925", "size": "5"}, {"price": "0.93", "size": "200"}, {"price": "0.938", "size": "115.35"}, {"price": "0.94", "size": "300"}, {"price": "0.944", "size": "100"}, {"price": "0.951", "size": "397.91"}, {"price": "0.953", "size": "403.28"}, {"price": "0.954", "size": "303.53"}, {"price": "0.955", "size": "231.9"}, {"price": "0.959", "size": "200"}, {"price": "0.96", "size": "20.71"}], "asks": [{"price": "0.999", "size": "13461.99"}, {"price": "0.998", "size": "3382.42"}, {"price": "0.997", "size": "54.15"}, {"price": "0.994", "size": "2291"}, {"price": "0.993", "size": "572"}, {"price": "0.992", "size": "13.43"}, {"price": "0.99", "size": "2760"}, {"price": "0.989", "size": "5.49"}, {"price": "0.988", "size": "693.83"}, {"price": "0.987", "size": "924"}, {"price": "0.986", "size": "17.99"}, {"price": "0.98", "size": "500"}, {"price": "0.979", "size": "477"}, {"price": "0.978", "size": "315.5"}, {"price": "0.97", "size": "644.43"}, {"price": "0.969", "size": "200"}, {"price": "0.968", "size": "100"}, {"price": "0.967", "size": "62.93"}, {"price": "0.966", "size": "32.41"}], "event_type": "book", "last_trade_price": "0.966"}, {"market": "0x0edc31cc586c65726249da0c698ce2b0dc3acac65a7b96574b7a8a89321ecf9e", "asset_id": "40204010519879025056259875406560264981469631264230376751093889691606763270485", "timestamp": "1769384304630", "hash": "e2727722cc210d4b8fccb42f9bd69e9446dff160", "bids": [{"price": "0.001", "size": "7265.83"}, {"price": "0.002", "size": "5.79"}, {"price": "0.003", "size": "1000"}, {"price": "0.004", "size": "23.32"}, {"price": "0.01", "size": "6006"}, {"price": "0.02", "size": "2200"}, {"price": "0.021", "size": "15.91"}, {"price": "0.05", "size": "165.4"}, {"price": "0.06", "size": "466"}, {"price": "0.1", "size": "560"}, {"price": "0.101", "size": "5.49"}, {"price": "0.11", "size": "250"}, {"price": "0.14", "size": "5"}, {"price": "0.15", "size": "776.66"}, {"price": "0.2", "size": "660"}, {"price": "0.22", "size": "5"}, {"price": "0.24", "size": "366.66"}, {"price": "0.241", "size": "8"}, {"price": "0.29", "size": "189.65"}, {"price": "0.34", "size": "70.58"}, {"price": "0.36", "size": "5"}, {"price": "0.37", "size": "5"}, {"price": "0.39", "size": "176.28"}, {"price": "0.56", "size": "5"}, {"price": "0.7", "size": "1000"}, {"price": "0.8", "size": "5"}, {"price": "0.85", "size": "5"}, {"price": "0.87", "size": "7000"}, {"price": "0.88", "size": "2000"}, {"price": "0.916", "size": "500"}, {"price": "0.942", "size": "1.43"}, {"price": "0.953", "size": "300"}, {"price": "0.955", "size": "500"}, {"price": "0.956", "size": "20"}, {"price": "0.965", "size": "200"}, {"price": "0.971", "size": "744.23"}, {"price": "0.972", "size": "200"}, {"price": "0.973", "size": "6.82"}, {"price": "0.974", "size": "9.69"}], "asks": [{"price": "0.999", "size": "14058.99"}, {"price": "0.998", "size": "4520.04"}, {"price": "0.997", "size": "263.28"}, {"price": "0.996", "size": "19.75"}, {"price": "0.995", "size": "500"}, {"price": "0.994", "size": "31.68"}, {"price": "0.99", "size": "700"}, {"price": "0.989", "size": "843.76"}, {"price": "0.988", "size": "400"}, {"price": "0.987", "size": "5.76"}, {"price": "0.986", "size": "100"}, {"price": "0.984", "size": "355.27"}, {"price": "0.982", "size": "100"}, {"price": "0.981", "size": "6.4"}, {"price": "0.98", "size": "117.19"}], "event_type": "book", "last_trade_price": "0.980"}, {"market": "0xcfe8947073d9333a6f767ed0c46713361aa4c34f75b35f1636622210356b2ba4", "asset_id": "21753818038149716958441586952364965978994113536903636754979518045886497078801", "timestamp": "1769384438435", "hash": "ff97cb2add09d5f4cfd68241c97b5c4950c82723", "bids": [{"price": "0.001", "size": "23000"}, {"price": "0.002", "size": "1828.96"}], "asks": [{"price": "0.999", "size": "3836.13"}, {"price": "0.998", "size": "1250"}, {"price": "0.997", "size": "1406.65"}, {"price": "0.994", "size": "200"}, {"price": "0.993", "size": "9.54"}, {"price": "0.99", "size": "5000"}, {"price": "0.98", "size": "2200"}, {"price": "0.979", "size": "14.47"}, {"price": "0.95", "size": "30"}, {"price": "0.949", "size": "39"}, {"price": "0.94", "size": "400"}, {"price": "0.9", "size": "860"}, {"price": "0.899", "size": "5.93"}, {"price": "0.85", "size": "776.66"}, {"price": "0.8", "size": "660"}, {"price": "0.75", "size": "312"}, {"price": "0.7", "size": "136.66"}, {"price": "0.699", "size": "1386.95"}, {"price": "0.695", "size": "50"}, {"price": "0.65", "size": "68.57"}, {"price": "0.6", "size": "175"}, {"price": "0.599", "size": "83.47"}, {"price": "0.598", "size": "5"}, {"price": "0.061", "size": "5"}, {"price": "0.057", "size": "5"}, {"price": "0.013", "size": "59.99"}, {"price": "0.012", "size": "416.66"}, {"price": "0.011", "size": "128.03"}, {"price": "0.006", "size": "449.55"}, {"price": "0.004", "size": "494.3"}, {"price": "0.003", "size": "39.48"}], "event_type": "book", "last_trade_price": "0.002"}, {"market": "0xb10aef4e56904ddab4f634b3bef36e878522d174ffb49688d3bca4e225516689", "asset_id": "53465481540932825427341404444568633780573546459375828539216440845324863999390", "timestamp": "1769384434971", "hash": "7eda7670ca0dd8195d58fd46bc44d6190a337c9f", "bids": [{"price": "0.001", "size": "18120.99"}, {"price": "0.002", "size": "1428.87"}, {"price": "0.004", "size": "420.99"}], "asks": [{"price": "0.999", "size": "4381.19"}, {"price": "0.998", "size": "1250"}, {"price": "0.997", "size": "1172.7"}, {"price": "0.994", "size": "83"}, {"price": "0.993", "size": "9.6"}, {"price": "0.99", "size": "5000"}, {"price": "0.98", "size": "2200"}, {"price": "0.979", "size": "14.68"}, {"price": "0.95", "size": "30"}, {"price": "0.949", "size": "39"}, {"price": "0.94", "size": "400"}, {"price": "0.9", "size": "860"}, {"price": "0.899", "size": "250"}, {"price": "0.898", "size": "5.82"}, {"price": "0.85", "size": "776.66"}, {"price": "0.8", "size": "660"}, {"price": "0.75", "size": "362"}, {"price": "0.7", "size": "186.66"}, {"price": "0.65", "size": "68.57"}, {"price": "0.6", "size": "246.42"}, {"price": "0.599", "size": "5"}, {"price": "0.066", "size": "39.06"}, {"price": "0.05", "size": "1111"}, {"price": "0.04", "size": "1111"}, {"price": "0.037", "size": "500"}, {"price": "0.017", "size": "200"}, {"price": "0.016", "size": "125.71"}, {"price": "0.015", "size": "435"}, {"price": "0.007", "size": "3134.76"}, {"price": "0.006", "size": "647.22"}, {"price": "0.005", "size": "667.27"}], "event_type": "book", "last_trade_price": "0.004"}, {"market": "0xf3161b6068bb9e8375c3c39788b213dfb912b1ecaf8e64a1957ec523eaf36f65", "asset_id": "18366541475247027354633521822685544012377744301234973068071847554908746172103", "timestamp": "1769384345732", "hash": "de13c9e5f1119778b531febbd9e02b0284306b5f", "bids": [{"price": "0.001", "size": "3719.12"}, {"price": "0.002", "size": "1255.09"}, {"price": "0.003", "size": "1000"}, {"price": "0.004", "size": "20.64"}, {"price": "0.01", "size": "5000"}, {"price": "0.02", "size": "2200"}, {"price": "0.021", "size": "14.71"}, {"price": "0.05", "size": "70"}, {"price": "0.06", "size": "433"}, {"price": "0.1", "size": "860"}, {"price": "0.101", "size": "250"}, {"price": "0.102", "size": "5.81"}, {"price": "0.125", "size": "500"}, {"price": "0.15", "size": "776.66"}, {"price": "0.16", "size": "10"}, {"price": "0.2", "size": "670"}, {"price": "0.23", "size": "25.85"}, {"price": "0.25", "size": "362"}, {"price": "0.3", "size": "196.66"}, {"price": "0.35", "size": "68.57"}, {"price": "0.4", "size": "175"}, {"price": "0.401", "size": "5"}, {"price": "0.64", "size": "5"}, {"price": "0.72", "size": "5"}, {"price": "0.75", "size": "20"}, {"price": "0.8", "size": "19.21"}, {"price": "0.83", "size": "200"}, {"price": "0.93", "size": "210"}, {"price": "0.94", "size": "201.71"}, {"price": "0.956", "size": "300"}, {"price": "0.957", "size": "236.99"}, {"price": "0.97", "size": "3000"}, {"price": "0.975", "size": "999"}, {"price": "0.98", "size": "200"}, {"price": "0.982", "size": "1284.58"}], "asks": [{"price": "0.999", "size": "13512.99"}, {"price": "0.998", "size": "2535.58"}, {"price": "0.997", "size": "270.22"}, {"price": "0.996", "size": "1264.66"}, {"price": "0.995", "size": "363.56"}, {"price": "0.994", "size": "108.84"}, {"price": "0.993", "size": "21"}, {"price": "0.991", "size": "17.41"}, {"price": "0.99", "size": "100"}, {"price": "0.989", "size": "207.07"}, {"price": "0.988", "size": "256.44"}, {"price": "0.987", "size": "17.68"}, {"price": "0.984", "size": "67.06"}, {"price": "0.983", "size": "7.23"}], "event_type": "book", "last_trade_price": "0.983"}, {"market": "0x3d00e2266a6fce1d78d52dc99ad65a6e0b1d4b126608f9b57a57a9e64e14538b", "asset_id": "111295934648931540975810135936206324404031729488235714793836466636975428917888", "timestamp": "1769384440680", "hash": "49eb9d1f47709282e85f0de82a1730c0d367d10e", "bids": [{"price": "0.001", "size": "3846.83"}, {"price": "0.002", "size": "1255.79"}, {"price": "0.003", "size": "1166"}, {"price": "0.004", "size": "9.87"}, {"price": "0.006", "size": "83"}, {"price": "0.01", "size": "5700"}, {"price": "0.011", "size": "5.35"}, {"price": "0.02", "size": "2205"}, {"price": "0.021", "size": "250"}, {"price": "0.022", "size": "14.93"}, {"price": "0.051", "size": "39"}, {"price": "0.06", "size": "400"}, {"price": "0.1", "size": "932.99"}, {"price": "0.101", "size": "5.5"}, {"price": "0.14", "size": "242.85"}, {"price": "0.15", "size": "550"}, {"price": "0.19", "size": "623.42"}, {"price": "0.24", "size": "421.66"}, {"price": "0.241", "size": "8"}, {"price": "0.25", "size": "5"}, {"price": "0.29", "size": "189.65"}, {"price": "0.3", "size": "20"}, {"price": "0.34", "size": "70.58"}, {"price": "0.38", "size": "52.63"}, {"price": "0.381", "size": "225"}, {"price": "0.803", "size": "5.19"}, {"price": "0.868", "size": "19.23"}, {"price": "0.869", "size": "7000"}, {"price": "0.87", "size": "300"}, {"price": "0.871", "size": "300"}, {"price": "0.873", "size": "66.66"}, {"price": "0.875", "size": "6"}, {"price": "0.9", "size": "5"}, {"price": "0.911", "size": "66.66"}, {"price": "0.912", "size": "6"}, {"price": "0.946", "size": "22.89"}, {"price": "0.947", "size": "6"}, {"price": "0.949", "size": "66.66"}, {"price": "0.95", "size": "218.16"}, {"price": "0.951", "size": "69.39"}], "asks": [{"price": "0.999", "size": "18690.99"}, {"price": "0.998", "size": "7426.35"}, {"price": "0.997", "size": "288.82"}, {"price": "0.996", "size": "59.89"}, {"price": "0.99", "size": "1950"}, {"price": "0.989", "size": "910"}, {"price": "0.988", "size": "250"}, {"price": "0.987", "size": "17.32"}, {"price": "0.98", "size": "500"}, {"price": "0.979", "size": "772"}, {"price": "0.978", "size": "106.31"}, {"price": "0.976", "size": "292"}, {"price": "0.974", "size": "291.27"}, {"price": "0.973", "size": "242.43"}, {"price": "0.972", "size": "113"}, {"price": "0.97", "size": "6"}, {"price": "0.968", "size": "6.32"}, {"price": "0.967", "size": "19.62"}, {"price": "0.965", "size": "6"}, {"price": "0.961", "size": "81.63"}, {"price": "0.96", "size": "10.61"}, {"price": "0.959", "size": "8.9"}], "event_type": "book", "last_trade_price": "0.954"}, {"market": "0xc8944bb47818c0957fbeedcef9832d31927bd5d3f92912d08ae7db507ee851de", "asset_id": "43475483477872222798871077137471314754383343074234425453922242101872923868514", "timestamp": "1769384261109", "hash": "eefc22304e29014780f80579c543b5b2604b41cb", "bids": [{"price": "0.001", "size": "24893"}, {"price": "0.002", "size": "1432.91"}, {"price": "0.003", "size": "493.65"}, {"price": "0.004", "size": "95.6"}, {"price": "0.005", "size": "1080.91"}], "asks": [{"price": "0.999", "size": "4029.26"}, {"price": "0.998", "size": "1250"}, {"price": "0.997", "size": "1406.66"}, {"price": "0.994", "size": "200"}, {"price": "0.993", "size": "9.55"}, {"price": "0.99", "size": "5000"}, {"price": "0.98", "size": "2200"}, {"price": "0.979", "size": "15.77"}, {"price": "0.95", "size": "30"}, {"price": "0.949", "size": "39"}, {"price": "0.94", "size": "400"}, {"price": "0.9", "size": "1377.21"}, {"price": "0.892", "size": "258.22"}, {"price": "0.891", "size": "129"}, {"price": "0.89", "size": "5.19"}, {"price": "0.876", "size": "100"}, {"price": "0.85", "size": "776.66"}, {"price": "0.8", "size": "789.04"}, {"price": "0.75", "size": "362"}, {"price": "0.7", "size": "186.66"}, {"price": "0.65", "size": "68.57"}, {"price": "0.6", "size": "175"}, {"price": "0.599", "size": "5"}, {"price": "0.45", "size": "129.04"}, {"price": "0.09", "size": "94.97"}, {"price": "0.088", "size": "120"}, {"price": "0.087", "size": "100"}, {"price": "0.068", "size": "10"}, {"price": "0.039", "size": "5"}, {"price": "0.026", "size": "5"}, {"price": "0.024", "size": "5"}, {"price": "0.022", "size": "2222"}, {"price": "0.021", "size": "5"}, {"price": "0.019", "size": "5"}, {"price": "0.016", "size": "5"}, {"price": "0.015", "size": "2000"}, {"price": "0.014", "size": "560"}, {"price": "0.012", "size": "527.02"}, {"price": "0.009", "size": "693.71"}, {"price": "0.008", "size": "57.01"}, {"price": "0.007", "size": "11.06"}, {"price": "0.006", "size": "49"}], "event_type": "book", "last_trade_price": "0.995"}, {"market": "0x45e914a8f5597714dfacecd335e013a3a53d0d4cbd687c85e1cc48c9047d285a", "asset_id": "110200527661363090969678046788357688179423234656139810394834278614636056974775", "timestamp": "1769384284214", "hash": "21fb9d7f4c13bff4c2a2480b4c601000f6130fbb", "bids": [{"price": "0.001", "size": "21515.68"}, {"price": "0.002", "size": "2587.45"}, {"price": "0.003", "size": "91.31"}], "asks": [{"price": "0.999", "size": "5837.14"}, {"price": "0.998", "size": "1250"}, {"price": "0.997", "size": "1172.65"}, {"price": "0.994", "size": "83"}, {"price": "0.993", "size": "9.55"}, {"price": "0.99", "size": "5000"}, {"price": "0.98", "size": "2200"}, {"price": "0.979", "size": "15.2"}, {"price": "0.95", "size": "30"}, {"price": "0.949", "size": "39"}, {"price": "0.94", "size": "400"}, {"price": "0.9", "size": "860"}, {"price": "0.899", "size": "250"}, {"price": "0.895", "size": "24.56"}, {"price": "0.894", "size": "5.5"}, {"price": "0.85", "size": "776.66"}, {"price": "0.8", "size": "660"}, {"price": "0.75", "size": "362"}, {"price": "0.7", "size": "186.66"}, {"price": "0.65", "size": "68.57"}, {"price": "0.6", "size": "175"}, {"price": "0.4", "size": "616.62"}, {"price": "0.399", "size": "50"}, {"price": "0.398", "size": "5"}, {"price": "0.23", "size": "0.65"}, {"price": "0.12", "size": "5"}, {"price": "0.049", "size": "350"}, {"price": "0.02", "size": "300"}, {"price": "0.019", "size": "496.32"}, {"price": "0.017", "size": "1000"}, {"price": "0.01", "size": "5000"}, {"price": "0.009", "size": "30"}, {"price": "0.007", "size": "845"}, {"price": "0.006", "size": "913.22"}, {"price": "0.005", "size": "1745.81"}], "event_type": "book", "last_trade_price": "0.003"}, {"market": "0x7c663472136f5db9dbc0a223ed26f9e586864d9d4d0d40cb28a8157e279feff4", "asset_id": "94146194619680623124956731256954660746880239065654088591536542002260568253245", "timestamp": "1769384244505", "hash": "fc2ac5811a8b39eef8f6684c65a2af2cd1705727", "bids": [{"price": "0.001", "size": "9617.99"}, {"price": "0.002", "size": "264.97"}, {"price": "0.003", "size": "344.41"}, {"price": "0.004", "size": "57.32"}, {"price": "0.01", "size": "1305"}, {"price": "0.011", "size": "100"}, {"price": "0.012", "size": "7.22"}, {"price": "0.016", "size": "37.27"}], "asks": [{"price": "0.999", "size": "5046.19"}, {"price": "0.998", "size": "5.16"}, {"price": "0.997", "size": "1000"}, {"price": "0.996", "size": "20.91"}, {"price": "0.99", "size": "5050"}, {"price": "0.98", "size": "2200"}, {"price": "0.979", "size": "14.71"}, {"price": "0.95", "size": "20"}, {"price": "0.94", "size": "433"}, {"price": "0.9", "size": "860"}, {"price": "0.899", "size": "5.85"}, {"price": "0.85", "size": "826.66"}, {"price": "0.809", "size": "400"}, {"price": "0.8", "size": "160"}, {"price": "0.75", "size": "362"}, {"price": "0.7", "size": "136.66"}, {"price": "0.697", "size": "734.14"}, {"price": "0.696", "size": "349.99"}, {"price": "0.65", "size": "68.57"}, {"price": "0.61", "size": "176.28"}, {"price": "0.609", "size": "5"}, {"price": "0.05", "size": "262.93"}, {"price": "0.04", "size": "300"}, {"price": "0.039", "size": "301.82"}, {"price": "0.038", "size": "213.03"}, {"price": "0.037", "size": "202.36"}, {"price": "0.029", "size": "6.79"}, {"price": "0.027", "size": "33.4"}, {"price": "0.026", "size": "6"}, {"price": "0.024", "size": "10"}, {"price": "0.023", "size": "25"}, {"price": "0.018", "size": "90.01"}, {"price": "0.017", "size": "41.32"}], "event_type": "book", "last_trade_price": "0.016"}, {"market": "0xdbe11c5e6f73ef5d263963afc409b06d9b41d025a2c9f95c87720466bb1e3b9f", "asset_id": "46607955083051909007838461227284420919060143738233439834136338543437466189799", "timestamp": "1769384344621", "hash": "c8173fcc410b303e04f5111ff3ee521bf8a659a2", "bids": [{"price": "0.001", "size": "8391.79"}, {"price": "0.002", "size": "1255.75"}, {"price": "0.003", "size": "1000"}, {"price": "0.004", "size": "23.16"}, {"price": "0.01", "size": "5900"}, {"price": "0.02", "size": "2200"}, {"price": "0.021", "size": "15.83"}, {"price": "0.05", "size": "20"}, {"price": "0.06", "size": "438"}, {"price": "0.1", "size": "560"}, {"price": "0.101", "size": "5.51"}, {"price": "0.11", "size": "5"}, {"price": "0.125", "size": "250"}, {"price": "0.15", "size": "826.66"}, {"price": "0.17", "size": "5"}, {"price": "0.19", "size": "568.42"}, {"price": "0.191", "size": "234"}, {"price": "0.2", "size": "5"}, {"price": "0.22", "size": "5"}, {"price": "0.24", "size": "416.66"}, {"price": "0.241", "size": "8"}, {"price": "0.29", "size": "189.65"}, {"price": "0.3", "size": "5"}, {"price": "0.34", "size": "70.58"}, {"price": "0.39", "size": "176.28"}, {"price": "0.42", "size": "5"}, {"price": "0.871", "size": "7000"}, {"price": "0.88", "size": "5"}, {"price": "0.902", "size": "100"}, {"price": "0.903", "size": "25"}, {"price": "0.92", "size": "5"}, {"price": "0.958", "size": "1080.88"}, {"price": "0.959", "size": "350"}, {"price": "0.963", "size": "542.06"}, {"price": "0.965", "size": "199.97"}], "asks": [{"price": "0.999", "size": "20739.99"}, {"price": "0.998", "size": "6019.28"}, {"price": "0.997", "size": "23.85"}, {"price": "0.996", "size": "1250"}, {"price": "0.995", "size": "257.58"}, {"price": "0.994", "size": "34.02"}, {"price": "0.99", "size": "805"}, {"price": "0.989", "size": "910"}, {"price": "0.988", "size": "28.99"}, {"price": "0.978", "size": "326.23"}, {"price": "0.977", "size": "6.61"}, {"price": "0.976", "size": "634"}, {"price": "0.975", "size": "115.1"}, {"price": "0.974", "size": "323"}, {"price": "0.973", "size": "323"}, {"price": "0.972", "size": "5.28"}, {"price": "0.967", "size": "84.45"}], "event_type": "book", "last_trade_price": "0.033"}, {"market": "0x3d00e2266a6fce1d78d52dc99ad65a6e0b1d4b126608f9b57a57a9e64e14538b", "asset_id": "53186315788060762043972018184166502971471689613114984035234259092608911832812", "timestamp": "1769384440680", "hash": "a529ae520ba20b05aa30bcb0298026b6767f633c", "bids": [{"price": "0.001", "size": "18690.99"}, {"price": "0.002", "size": "7426.35"}, {"price": "0.003", "size": "288.82"}, {"price": "0.004", "size": "59.89"}, {"price": "0.01", "size": "1950"}, {"price": "0.011", "size": "910"}, {"price": "0.012", "size": "250"}, {"price": "0.013", "size": "17.32"}, {"price": "0.02", "size": "500"}, {"price": "0.021", "size": "772"}, {"price": "0.022", "size": "106.31"}, {"price": "0.024", "size": "292"}, {"price": "0.026", "size": "291.27"}, {"price": "0.027", "size": "242.43"}, {"price": "0.028", "size": "113"}, {"price": "0.03", "size": "6"}, {"price": "0.032", "size": "6.32"}, {"price": "0.033", "size": "19.62"}, {"price": "0.035", "size": "6"}, {"price": "0.039", "size": "81.63"}, {"price": "0.04", "size": "10.61"}, {"price": "0.041", "size": "8.9"}], "asks": [{"price": "0.999", "size": "3846.83"}, {"price": "0.998", "size": "1255.79"}, {"price": "0.997", "size": "1166"}, {"price": "0.996", "size": "9.87"}, {"price": "0.994", "size": "83"}, {"price": "0.99", "size": "5700"}, {"price": "0.989", "size": "5.35"}, {"price": "0.98", "size": "2205"}, {"price": "0.979", "size": "250"}, {"price": "0.978", "size": "14.93"}, {"price": "0.949", "size": "39"}, {"price": "0.94", "size": "400"}, {"price": "0.9", "size": "932.99"}, {"price": "0.899", "size": "5.5"}, {"price": "0.86", "size": "242.85"}, {"price": "0.85", "size": "550"}, {"price": "0.81", "size": "623.42"}, {"price": "0.76", "size": "421.66"}, {"price": "0.759", "size": "8"}, {"price": "0.75", "size": "5"}, {"price": "0.71", "size": "189.65"}, {"price": "0.7", "size": "20"}, {"price": "0.66", "size": "70.58"}, {"price": "0.62", "size": "52.63"}, {"price": "0.619", "size": "225"}, {"price": "0.197", "size": "5.19"}, {"price": "0.132", "size": "19.23"}, {"price": "0.131", "size": "7000"}, {"price": "0.13", "size": "300"}, {"price": "0.129", "size": "300"}, {"price": "0.127", "size": "66.66"}, {"price": "0.125", "size": "6"}, {"price": "0.1", "size": "5"}, {"price": "0.089", "size": "66.66"}, {"price": "0.088", "size": "6"}, {"price": "0.054", "size": "22.89"}, {"price": "0.053", "size": "6"}, {"price": "0.051", "size": "66.66"}, {"price": "0.05", "size": "218.16"}, {"price": "0.049", "size": "69.39"}], "event_type": "book", "last_trade_price": "0.954"}, {"market": "0x3e0f3863b4ed9dcabd7bbf9d03089e64bcfe5be6fd96284e58c772806823c60e", "asset_id": "58240812112472573224618301580190009078083222467735667648538851344040750074390", "timestamp": "1769384240995", "hash": "c98f37fec36d94bc665c1366a61b9060a9b3e91b", "bids": [{"price": "0.001", "size": "3937.19"}, {"price": "0.002", "size": "1250"}, {"price": "0.003", "size": "1406.69"}, {"price": "0.006", "size": "200"}, {"price": "0.007", "size": "9.6"}, {"price": "0.01", "size": "5000"}, {"price": "0.02", "size": "2200"}, {"price": "0.021", "size": "14.53"}, {"price": "0.05", "size": "30"}, {"price": "0.051", "size": "39"}, {"price": "0.06", "size": "400"}, {"price": "0.1", "size": "860"}, {"price": "0.101", "size": "5.91"}, {"price": "0.15", "size": "776.66"}, {"price": "0.2", "size": "660"}, {"price": "0.201", "size": "250"}, {"price": "0.25", "size": "362"}, {"price": "0.3", "size": "186.66"}, {"price": "0.35", "size": "68.57"}, {"price": "0.4", "size": "175"}, {"price": "0.401", "size": "5"}, {"price": "0.9", "size": "33.28"}, {"price": "0.958", "size": "7"}, {"price": "0.988", "size": "742.65"}, {"price": "0.99", "size": "700"}, {"price": "0.991", "size": "217"}, {"price": "0.992", "size": "34.64"}], "asks": [{"price": "0.999", "size": "27226"}, {"price": "0.998", "size": "2870.14"}, {"price": "0.997", "size": "315.31"}, {"price": "0.996", "size": "93.19"}, {"price": "0.995", "size": "500"}], "event_type": "book", "last_trade_price": "0.009"}, {"market": "0x7c663472136f5db9dbc0a223ed26f9e586864d9d4d0d40cb28a8157e279feff4", "asset_id": "80500705406858794154333907699858742630939624339510163743458445359324900544624", "timestamp": "1769384244505", "hash": "a31973fe10673fb1849f4b98f30c15846bed75fa", "bids": [{"price": "0.001", "size": "5046.19"}, {"price": "0.002", "size": "5.16"}, {"price": "0.003", "size": "1000"}, {"price": "0.004", "size": "20.91"}, {"price": "0.01", "size": "5050"}, {"price": "0.02", "size": "2200"}, {"price": "0.021", "size": "14.71"}, {"price": "0.05", "size": "20"}, {"price": "0.06", "size": "433"}, {"price": "0.1", "size": "860"}, {"price": "0.101", "size": "5.85"}, {"price": "0.15", "size": "826.66"}, {"price": "0.191", "size": "400"}, {"price": "0.2", "size": "160"}, {"price": "0.25", "size": "362"}, {"price": "0.3", "size": "136.66"}, {"price": "0.303", "size": "734.14"}, {"price": "0.304", "size": "349.99"}, {"price": "0.35", "size": "68.57"}, {"price": "0.39", "size": "176.28"}, {"price": "0.391", "size": "5"}, {"price": "0.95", "size": "262.93"}, {"price": "0.96", "size": "300"}, {"price": "0.961", "size": "301.82"}, {"price": "0.962", "size": "213.03"}, {"price": "0.963", "size": "202.36"}, {"price": "0.971", "size": "6.79"}, {"price": "0.973", "size": "33.4"}, {"price": "0.974", "size": "6"}, {"price": "0.976", "size": "10"}, {"price": "0.977", "size": "25"}, {"price": "0.982", "size": "90.01"}, {"price": "0.983", "size": "41.32"}], "asks": [{"price": "0.999", "size": "9617.99"}, {"price": "0.998", "size": "264.97"}, {"price": "0.997", "size": "344.41"}, {"price": "0.996", "size": "57.32"}, {"price": "0.99", "size": "1305"}, {"price": "0.989", "size": "100"}, {"price": "0.988", "size": "7.22"}, {"price": "0.984", "size": "37.27"}], "event_type": "book", "last_trade_price": "0.016"}, {"market": "0x33825080bc810aa756a361298627cdf64d58dbd651a647bd0a29b8a68a7308fe", "asset_id": "27476096571833974040484538127433399463608736639971094747870629065388427932028", "timestamp": "1769384425551", "hash": "590af2b140e58057d8e9069985eacd5b3c842c9d", "bids": [{"price": "0.001", "size": "13461.99"}, {"price": "0.002", "size": "3382.42"}, {"price": "0.003", "size": "54.15"}, {"price": "0.006", "size": "2291"}, {"price": "0.007", "size": "572"}, {"price": "0.008", "size": "13.43"}, {"price": "0.01", "size": "2760"}, {"price": "0.011", "size": "5.49"}, {"price": "0.012", "size": "693.83"}, {"price": "0.013", "size": "924"}, {"price": "0.014", "size": "17.99"}, {"price": "0.02", "size": "500"}, {"price": "0.021", "size": "477"}, {"price": "0.022", "size": "315.5"}, {"price": "0.03", "size": "644.43"}, {"price": "0.031", "size": "200"}, {"price": "0.032", "size": "100"}, {"price": "0.033", "size": "62.93"}, {"price": "0.034", "size": "32.41"}], "asks": [{"price": "0.999", "size": "4779.8"}, {"price": "0.998", "size": "5.76"}, {"price": "0.997", "size": "1000"}, {"price": "0.996", "size": "9.83"}, {"price": "0.99", "size": "5000"}, {"price": "0.989", "size": "5.32"}, {"price": "0.98", "size": "2200"}, {"price": "0.979", "size": "250"}, {"price": "0.978", "size": "15.04"}, {"price": "0.95", "size": "215.6"}, {"price": "0.94", "size": "433"}, {"price": "0.9", "size": "1031.69"}, {"price": "0.899", "size": "5.48"}, {"price": "0.85", "size": "826.66"}, {"price": "0.81", "size": "168.42"}, {"price": "0.8", "size": "400"}, {"price": "0.799", "size": "846"}, {"price": "0.76", "size": "321.66"}, {"price": "0.73", "size": "5"}, {"price": "0.71", "size": "89.65"}, {"price": "0.7", "size": "150"}, {"price": "0.699", "size": "1494"}, {"price": "0.66", "size": "70.58"}, {"price": "0.61", "size": "51.28"}, {"price": "0.605", "size": "1643"}, {"price": "0.604", "size": "5"}, {"price": "0.53", "size": "15"}, {"price": "0.5", "size": "20"}, {"price": "0.47", "size": "85.33"}, {"price": "0.45", "size": "5"}, {"price": "0.33", "size": "10"}, {"price": "0.3", "size": "177.21"}, {"price": "0.272", "size": "18.52"}, {"price": "0.176", "size": "9.99"}, {"price": "0.15", "size": "205"}, {"price": "0.14", "size": "1100"}, {"price": "0.13", "size": "1126.14"}, {"price": "0.12", "size": "415.75"}, {"price": "0.119", "size": "7043.3"}, {"price": "0.118", "size": "25"}, {"price": "0.1", "size": "5"}, {"price": "0.075", "size": "5"}, {"price": "0.07", "size": "200"}, {"price": "0.062", "size": "115.35"}, {"price": "0.06", "size": "300"}, {"price": "0.056", "size": "100"}, {"price": "0.049", "size": "397.91"}, {"price": "0.047", "size": "403.28"}, {"price": "0.046", "size": "303.53"}, {"price": "0.045", "size": "231.9"}, {"price": "0.041", "size": "200"}, {"price": "0.04", "size": "20.71"}], "event_type": "book", "last_trade_price": "0.966"}, {"market": "0x830532ef53004df7522d7c56cad9af92f4b323590e7712302efdd99fa04cc078", "asset_id": "55889977023103749239654252466433022405707563507479932528448213571367486700989", "timestamp": "1769384295670", "hash": "16f4e751728337e6b6489c4370361aaaa1cd6a14", "bids": [{"price": "0.001", "size": "4632.16"}, {"price": "0.002", "size": "1255.13"}, {"price": "0.003", "size": "1000"}, {"price": "0.004", "size": "20.78"}, {"price": "0.01", "size": "5000"}, {"price": "0.02", "size": "2200"}, {"price": "0.021", "size": "14.64"}, {"price": "0.05", "size": "30"}, {"price": "0.06", "size": "433"}, {"price": "0.1", "size": "860"}, {"price": "0.101", "size": "5.87"}, {"price": "0.15", "size": "776.66"}, {"price": "0.19", "size": "5"}, {"price": "0.2", "size": "660"}, {"price": "0.201", "size": "192"}, {"price": "0.22", "size": "5"}, {"price": "0.25", "size": "362"}, {"price": "0.28", "size": "5"}, {"price": "0.3", "size": "191.66"}, {"price": "0.35", "size": "68.57"}, {"price": "0.39", "size": "176.28"}, {"price": "0.391", "size": "5"}, {"price": "0.59", "size": "30"}, {"price": "0.71", "size": "40"}, {"price": "0.77", "size": "30"}, {"price": "0.81", "size": "908"}, {"price": "0.84", "size": "10"}, {"price": "0.87", "size": "5"}, {"price": "0.9", "size": "782"}, {"price": "0.93", "size": "44.72"}, {"price": "0.951", "size": "500"}, {"price": "0.954", "size": "300"}, {"price": "0.955", "size": "312.59"}, {"price": "0.956", "size": "280.09"}, {"price": "0.96", "size": "5"}, {"price": "0.961", "size": "100"}, {"price": "0.964", "size": "60.92"}, {"price": "0.966", "size": "222"}, {"price": "0.967", "size": "254.8"}, {"price": "0.97", "size": "200"}, {"price": "0.971", "size": "20.39"}], "asks": [{"price": "0.999", "size": "15425.99"}, {"price": "0.998", "size": "2524.71"}, {"price": "0.997", "size": "266.5"}, {"price": "0.996", "size": "77.19"}, {"price": "0.99", "size": "1250"}, {"price": "0.989", "size": "827.2"}, {"price": "0.988", "size": "517"}, {"price": "0.987", "size": "107.7"}, {"price": "0.985", "size": "26.05"}, {"price": "0.984", "size": "233"}, {"price": "0.979", "size": "123.63"}], "event_type": "book", "last_trade_price": "0.021"}, {"market": "0xdbe11c5e6f73ef5d263963afc409b06d9b41d025a2c9f95c87720466bb1e3b9f", "asset_id": "80045575232657959607697270409089815535212408747135442892163239419937820236517", "timestamp": "1769384344621", "hash": "2c9ec6a0131278605e854b29baf2a985f8e3af38", "bids": [{"price": "0.001", "size": "20739.99"}, {"price": "0.002", "size": "6019.28"}, {"price": "0.003", "size": "23.85"}, {"price": "0.004", "size": "1250"}, {"price": "0.005", "size": "257.58"}, {"price": "0.006", "size": "34.02"}, {"price": "0.01", "size": "805"}, {"price": "0.011", "size": "910"}, {"price": "0.012", "size": "28.99"}, {"price": "0.022", "size": "326.23"}, {"price": "0.023", "size": "6.61"}, {"price": "0.024", "size": "634"}, {"price": "0.025", "size": "115.1"}, {"price": "0.026", "size": "323"}, {"price": "0.027", "size": "323"}, {"price": "0.028", "size": "5.28"}, {"price": "0.033", "size": "84.45"}], "asks": [{"price": "0.999", "size": "8391.79"}, {"price": "0.998", "size": "1255.75"}, {"price": "0.997", "size": "1000"}, {"price": "0.996", "size": "23.16"}, {"price": "0.99", "size": "5900"}, {"price": "0.98", "size": "2200"}, {"price": "0.979", "size": "15.83"}, {"price": "0.95", "size": "20"}, {"price": "0.94", "size": "438"}, {"price": "0.9", "size": "560"}, {"price": "0.899", "size": "5.51"}, {"price": "0.89", "size": "5"}, {"price": "0.875", "size": "250"}, {"price": "0.85", "size": "826.66"}, {"price": "0.83", "size": "5"}, {"price": "0.81", "size": "568.42"}, {"price": "0.809", "size": "234"}, {"price": "0.8", "size": "5"}, {"price": "0.78", "size": "5"}, {"price": "0.76", "size": "416.66"}, {"price": "0.759", "size": "8"}, {"price": "0.71", "size": "189.65"}, {"price": "0.7", "size": "5"}, {"price": "0.66", "size": "70.58"}, {"price": "0.61", "size": "176.28"}, {"price": "0.58", "size": "5"}, {"price": "0.129", "size": "7000"}, {"price": "0.12", "size": "5"}, {"price": "0.098", "size": "100"}, {"price": "0.097", "size": "25"}, {"price": "0.08", "size": "5"}, {"price": "0.042", "size": "1080.88"}, {"price": "0.041", "size": "350"}, {"price": "0.037", "size": "542.06"}, {"price": "0.035", "size": "199.97"}], "event_type": "book", "last_trade_price": "0.033"}, {"market": "0x45e914a8f5597714dfacecd335e013a3a53d0d4cbd687c85e1cc48c9047d285a", "asset_id": "68995509148146939312377551876533796789260737522245408918282961840521284671106", "timestamp": "1769384284214", "hash": "e1261c34d995a889853631cf424b4f6cb519b7a3", "bids": [{"price": "0.001", "size": "5837.14"}, {"price": "0.002", "size": "1250"}, {"price": "0.003", "size": "1172.65"}, {"price": "0.006", "size": "83"}, {"price": "0.007", "size": "9.55"}, {"price": "0.01", "size": "5000"}, {"price": "0.02", "size": "2200"}, {"price": "0.021", "size": "15.2"}, {"price": "0.05", "size": "30"}, {"price": "0.051", "size": "39"}, {"price": "0.06", "size": "400"}, {"price": "0.1", "size": "860"}, {"price": "0.101", "size": "250"}, {"price": "0.105", "size": "24.56"}, {"price": "0.106", "size": "5.5"}, {"price": "0.15", "size": "776.66"}, {"price": "0.2", "size": "660"}, {"price": "0.25", "size": "362"}, {"price": "0.3", "size": "186.66"}, {"price": "0.35", "size": "68.57"}, {"price": "0.4", "size": "175"}, {"price": "0.6", "size": "616.62"}, {"price": "0.601", "size": "50"}, {"price": "0.602", "size": "5"}, {"price": "0.77", "size": "0.65"}, {"price": "0.88", "size": "5"}, {"price": "0.951", "size": "350"}, {"price": "0.98", "size": "300"}, {"price": "0.981", "size": "496.32"}, {"price": "0.983", "size": "1000"}, {"price": "0.99", "size": "5000"}, {"price": "0.991", "size": "30"}, {"price": "0.993", "size": "845"}, {"price": "0.994", "size": "913.22"}, {"price": "0.995", "size": "1745.81"}], "asks": [{"price": "0.999", "size": "21515.68"}, {"price": "0.998", "size": "2587.45"}, {"price": "0.997", "size": "91.31"}], "event_type": "book", "last_trade_price": "0.003"}, {"market": "0xcfe8947073d9333a6f767ed0c46713361aa4c34f75b35f1636622210356b2ba4", "asset_id": "38409601990353197105461643021341338172518659365214781641813884172364820064219", "timestamp": "1769384438435", "hash": "477e33f6f4695adb1fde97c3c0c64cb04131bb95", "bids": [{"price": "0.001", "size": "3836.13"}, {"price": "0.002", "size": "1250"}, {"price": "0.003", "size": "1406.65"}, {"price": "0.006", "size": "200"}, {"price": "0.007", "size": "9.54"}, {"price": "0.01", "size": "5000"}, {"price": "0.02", "size": "2200"}, {"price": "0.021", "size": "14.47"}, {"price": "0.05", "size": "30"}, {"price": "0.051", "size": "39"}, {"price": "0.06", "size": "400"}, {"price": "0.1", "size": "860"}, {"price": "0.101", "size": "5.93"}, {"price": "0.15", "size": "776.66"}, {"price": "0.2", "size": "660"}, {"price": "0.25", "size": "312"}, {"price": "0.3", "size": "136.66"}, {"price": "0.301", "size": "1386.95"}, {"price": "0.305", "size": "50"}, {"price": "0.35", "size": "68.57"}, {"price": "0.4", "size": "175"}, {"price": "0.401", "size": "83.47"}, {"price": "0.402", "size": "5"}, {"price": "0.939", "size": "5"}, {"price": "0.943", "size": "5"}, {"price": "0.987", "size": "59.99"}, {"price": "0.988", "size": "416.66"}, {"price": "0.989", "size": "128.03"}, {"price": "0.994", "size": "449.55"}, {"price": "0.996", "size": "494.3"}, {"price": "0.997", "size": "39.48"}], "asks": [{"price": "0.999", "size": "23000"}, {"price": "0.998", "size": "1828.96"}], "event_type": "book", "last_trade_price": "0.002"}, {"market": "0xb6f9798af5a77bd36105be5663461aead7db6e4a1578ac06a6c504fa74e451f8", "asset_id": "40840766563757154287731849847874327357871279547621006248373770096528139371759", "timestamp": "1769384196467", "hash": "c04ecc7c7ac458a92a5c6ad819ee51e75851d79e", "bids": [{"price": "0.001", "size": "11263.99"}, {"price": "0.002", "size": "3694.26"}, {"price": "0.003", "size": "2690.12"}, {"price": "0.004", "size": "1264.26"}, {"price": "0.005", "size": "261.58"}, {"price": "0.006", "size": "54.25"}, {"price": "0.01", "size": "715"}, {"price": "0.011", "size": "595.12"}, {"price": "0.012", "size": "465.9"}, {"price": "0.013", "size": "100.33"}, {"price": "0.014", "size": "39.23"}], "asks": [{"price": "0.999", "size": "3692.67"}, {"price": "0.998", "size": "5.63"}, {"price": "0.997", "size": "1000"}, {"price": "0.996", "size": "22.7"}, {"price": "0.99", "size": "5700"}, {"price": "0.98", "size": "2200"}, {"price": "0.979", "size": "15.61"}, {"price": "0.94", "size": "433"}, {"price": "0.9", "size": "960"}, {"price": "0.899", "size": "5.58"}, {"price": "0.89", "size": "254"}, {"price": "0.875", "size": "250"}, {"price": "0.85", "size": "776.66"}, {"price": "0.8", "size": "660"}, {"price": "0.79", "size": "5"}, {"price": "0.76", "size": "350"}, {"price": "0.75", "size": "112"}, {"price": "0.71", "size": "200"}, {"price": "0.7", "size": "91.66"}, {"price": "0.699", "size": "6"}, {"price": "0.69", "size": "14.33"}, {"price": "0.65", "size": "68.57"}, {"price": "0.6", "size": "175"}, {"price": "0.57", "size": "20"}, {"price": "0.252", "size": "10"}, {"price": "0.24", "size": "5"}, {"price": "0.18", "size": "5"}, {"price": "0.16", "size": "100"}, {"price": "0.14", "size": "5"}, {"price": "0.12", "size": "7005"}, {"price": "0.119", "size": "100.25"}, {"price": "0.1", "size": "5"}, {"price": "0.06", "size": "200"}, {"price": "0.05", "size": "250"}, {"price": "0.046", "size": "200"}, {"price": "0.038", "size": "300"}, {"price": "0.037", "size": "300"}, {"price": "0.036", "size": "275.01"}, {"price": "0.035", "size": "89.88"}, {"price": "0.028", "size": "200"}, {"price": "0.026", "size": "200"}, {"price": "0.025", "size": "34.71"}, {"price": "0.018", "size": "25"}, {"price": "0.017", "size": "7.2"}], "event_type": "book", "last_trade_price": "0.986"}, {"market": "0x3e0f3863b4ed9dcabd7bbf9d03089e64bcfe5be6fd96284e58c772806823c60e", "asset_id": "110865594744159968267498282218512778667662344467377910002492558627771354011913", "timestamp": "1769384240995", "hash": "b836bd025ec144339e527e213958ef0c26585d61", "bids": [{"price": "0.001", "size": "27226"}, {"price": "0.002", "size": "2870.14"}, {"price": "0.003", "size": "315.31"}, {"price": "0.004", "size": "93.19"}, {"price": "0.005", "size": "500"}], "asks": [{"price": "0.999", "size": "3937.19"}, {"price": "0.998", "size": "1250"}, {"price": "0.997", "size": "1406.69"}, {"price": "0.994", "size": "200"}, {"price": "0.993", "size": "9.6"}, {"price": "0.99", "size": "5000"}, {"price": "0.98", "size": "2200"}, {"price": "0.979", "size": "14.53"}, {"price": "0.95", "size": "30"}, {"price": "0.949", "size": "39"}, {"price": "0.94", "size": "400"}, {"price": "0.9", "size": "860"}, {"price": "0.899", "size": "5.91"}, {"price": "0.85", "size": "776.66"}, {"price": "0.8", "size": "660"}, {"price": "0.799", "size": "250"}, {"price": "0.75", "size": "362"}, {"price": "0.7", "size": "186.66"}, {"price": "0.65", "size": "68.57"}, {"price": "0.6", "size": "175"}, {"price": "0.599", "size": "5"}, {"price": "0.1", "size": "33.28"}, {"price": "0.042", "size": "7"}, {"price": "0.012", "size": "742.65"}, {"price": "0.01", "size": "700"}, {"price": "0.009", "size": "217"}, {"price": "0.008", "size": "34.64"}], "event_type": "book", "last_trade_price": "0.009"}, {"market": "0xf3161b6068bb9e8375c3c39788b213dfb912b1ecaf8e64a1957ec523eaf36f65", "asset_id": "69376091146113194498094624279536929726823646994979580456392762592249313854175", "timestamp": "1769384345732", "hash": "2a4a9dcab8fabdf6bfd10d2d0add3473371e87b8", "bids": [{"price": "0.001", "size": "13512.99"}, {"price": "0.002", "size": "2535.58"}, {"price": "0.003", "size": "270.22"}, {"price": "0.004", "size": "1264.66"}, {"price": "0.005", "size": "363.56"}, {"price": "0.006", "size": "108.84"}, {"price": "0.007", "size": "21"}, {"price": "0.009", "size": "17.41"}, {"price": "0.01", "size": "100"}, {"price": "0.011", "size": "207.07"}, {"price": "0.012", "size": "256.44"}, {"price": "0.013", "size": "17.68"}, {"price": "0.016", "size": "67.06"}, {"price": "0.017", "size": "7.23"}], "asks": [{"price": "0.999", "size": "3719.12"}, {"price": "0.998", "size": "1255.09"}, {"price": "0.997", "size": "1000"}, {"price": "0.996", "size": "20.64"}, {"price": "0.99", "size": "5000"}, {"price": "0.98", "size": "2200"}, {"price": "0.979", "size": "14.71"}, {"price": "0.95", "size": "70"}, {"price": "0.94", "size": "433"}, {"price": "0.9", "size": "860"}, {"price": "0.899", "size": "250"}, {"price": "0.898", "size": "5.81"}, {"price": "0.875", "size": "500"}, {"price": "0.85", "size": "776.66"}, {"price": "0.84", "size": "10"}, {"price": "0.8", "size": "670"}, {"price": "0.77", "size": "25.85"}, {"price": "0.75", "size": "362"}, {"price": "0.7", "size": "196.66"}, {"price": "0.65", "size": "68.57"}, {"price": "0.6", "size": "175"}, {"price": "0.599", "size": "5"}, {"price": "0.36", "size": "5"}, {"price": "0.28", "size": "5"}, {"price": "0.25", "size": "20"}, {"price": "0.2", "size": "19.21"}, {"price": "0.17", "size": "200"}, {"price": "0.07", "size": "210"}, {"price": "0.06", "size": "201.71"}, {"price": "0.044", "size": "300"}, {"price": "0.043", "size": "236.99"}, {"price": "0.03", "size": "3000"}, {"price": "0.025", "size": "999"}, {"price": "0.02", "size": "200"}, {"price": "0.018", "size": "1284.58"}], "event_type": "book", "last_trade_price": "0.983"}, {"market": "0xb6f9798af5a77bd36105be5663461aead7db6e4a1578ac06a6c504fa74e451f8", "asset_id": "1197536345798262728158279113980109336582594308361699248279763512814446420519", "timestamp": "1769384196467", "hash": "22bb4fec7be22076f90f1be7d2bfb9b53478e3b2", "bids": [{"price": "0.001", "size": "3692.67"}, {"price": "0.002", "size": "5.63"}, {"price": "0.003", "size": "1000"}, {"price": "0.004", "size": "22.7"}, {"price": "0.01", "size": "5700"}, {"price": "0.02", "size": "2200"}, {"price": "0.021", "size": "15.61"}, {"price": "0.06", "size": "433"}, {"price": "0.1", "size": "960"}, {"price": "0.101", "size": "5.58"}, {"price": "0.11", "size": "254"}, {"price": "0.125", "size": "250"}, {"price": "0.15", "size": "776.66"}, {"price": "0.2", "size": "660"}, {"price": "0.21", "size": "5"}, {"price": "0.24", "size": "350"}, {"price": "0.25", "size": "112"}, {"price": "0.29", "size": "200"}, {"price": "0.3", "size": "91.66"}, {"price": "0.301", "size": "6"}, {"price": "0.31", "size": "14.33"}, {"price": "0.35", "size": "68.57"}, {"price": "0.4", "size": "175"}, {"price": "0.43", "size": "20"}, {"price": "0.748", "size": "10"}, {"price": "0.76", "size": "5"}, {"price": "0.82", "size": "5"}, {"price": "0.84", "size": "100"}, {"price": "0.86", "size": "5"}, {"price": "0.88", "size": "7005"}, {"price": "0.881", "size": "100.25"}, {"price": "0.9", "size": "5"}, {"price": "0.94", "size": "200"}, {"price": "0.95", "size": "250"}, {"price": "0.954", "size": "200"}, {"price": "0.962", "size": "300"}, {"price": "0.963", "size": "300"}, {"price": "0.964", "size": "275.01"}, {"price": "0.965", "size": "89.88"}, {"price": "0.972", "size": "200"}, {"price": "0.974", "size": "200"}, {"price": "0.975", "size": "34.71"}, {"price": "0.982", "size": "25"}, {"price": "0.983", "size": "7.2"}], "asks": [{"price": "0.999", "size": "11263.99"}, {"price": "0.998", "size": "3694.26"}, {"price": "0.997", "size": "2690.12"}, {"price": "0.996", "size": "1264.26"}, {"price": "0.995", "size": "261.58"}, {"price": "0.994", "size": "54.25"}, {"price": "0.99", "size": "715"}, {"price": "0.989", "size": "595.12"}, {"price": "0.988", "size": "465.9"}, {"price": "0.987", "size": "100.33"}, {"price": "0.986", "size": "39.23"}], "event_type": "book", "last_trade_price": "0.986"}]}
{"_local_timestamp": "2026-01-25T23:40:42.451074+00:00", "data": {"market": "0x3e0f3863b4ed9dcabd7bbf9d03089e64bcfe5be6fd96284e58c772806823c60e", "price_changes": [{"asset_id": "110865594744159968267498282218512778667662344467377910002492558627771354011913", "price": "0.002", "size": "2758.4", "side": "BUY", "hash": "26678b04b73ae56f17f77b22ae1cf2306882a2f8", "best_bid": "0.005", "best_ask": "0.008"}, {"asset_id": "58240812112472573224618301580190009078083222467735667648538851344040750074390", "price": "0.998", "size": "2758.4", "side": "SELL", "hash": "8239ce68846026161c8cb3f418ad3ea234e96cbc", "best_bid": "0.992", "best_ask": "0.995"}], "timestamp": "1769384442383", "event_type": "price_change"}}
{"_local_timestamp": "2026-01-25T23:40:42.452141+00:00", "data": {"market": "0x3e0f3863b4ed9dcabd7bbf9d03089e64bcfe5be6fd96284e58c772806823c60e", "price_changes": [{"asset_id": "110865594744159968267498282218512778667662344467377910002492558627771354011913", "price": "0.003", "size": "271.82", "side": "BUY", "hash": "26678b04b73ae56f17f77b22ae1cf2306882a2f8", "best_bid": "0.005", "best_ask": "0.008"}, {"asset_id": "58240812112472573224618301580190009078083222467735667648538851344040750074390", "price": "0.997", "size": "271.82", "side": "SELL", "hash": "8239ce68846026161c8cb3f418ad3ea234e96cbc", "best_bid": "0.992", "best_ask": "0.995"}], "timestamp": "1769384442383", "event_type": "price_change"}}
{"_local_timestamp": "2026-01-25T23:40:42.452471+00:00", "data": {"market": "0x3e0f3863b4ed9dcabd7bbf9d03089e64bcfe5be6fd96284e58c772806823c60e", "price_changes": [{"asset_id": "110865594744159968267498282218512778667662344467377910002492558627771354011913", "price": "0.004", "size": "42.53", "side": "BUY", "hash": "26678b04b73ae56f17f77b22ae1cf2306882a2f8", "best_bid": "0.005", "best_ask": "0.008"}, {"asset_id": "58240812112472573224618301580190009078083222467735667648538851344040750074390", "price": "0.996", "size": "42.53", "side": "SELL", "hash": "8239ce68846026161c8cb3f418ad3ea234e96cbc", "best_bid": "0.992", "best_ask": "0.995"}], "timestamp": "1769384442383", "event_type": "price_change"}}
{"_local_timestamp": "2026-01-25T23:40:42.820801+00:00", "data": {"market": "0x3e0f3863b4ed9dcabd7bbf9d03089e64bcfe5be6fd96284e58c772806823c60e", "price_changes": [{"asset_id": "110865594744159968267498282218512778667662344467377910002492558627771354011913", "price": "0.002", "size": "2870.14", "side": "BUY", "hash": "f9caf4005da4ca160bb317eabfc52ebba3f65adb", "best_bid": "0.005", "best_ask": "0.008"}, {"asset_id": "58240812112472573224618301580190009078083222467735667648538851344040750074390", "price": "0.998", "size": "2870.14", "side": "SELL", "hash": "6db4375776cb21366eaf7ac06de581827b0be415", "best_bid": "0.992", "best_ask": "0.995"}], "timestamp": "1769384442749", "event_type": "price_change"}}
{"_local_timestamp": "2026-01-25T23:40:42.823641+00:00", "data": {"market": "0x3e0f3863b4ed9dcabd7bbf9d03089e64bcfe5be6fd96284e58c772806823c60e", "price_changes": [{"asset_id": "110865594744159968267498282218512778667662344467377910002492558627771354011913", "price": "0.004", "size": "93.19", "side": "BUY", "hash": "7f4bf638e7953b8821f88f61d0f9f78872cd6cc6", "best_bid": "0.005", "best_ask": "0.008"}, {"asset_id": "58240812112472573224618301580190009078083222467735667648538851344040750074390", "price": "0.996", "size": "93.19", "side": "SELL", "hash": "8046da0c7d3c9410904c938a30809f5b009d513f", "best_bid": "0.992", "best_ask": "0.995"}], "timestamp": "1769384442750", "event_type": "price_change"}}
{"_local_timestamp": "2026-01-25T23:40:42.824836+00:00", "data": {"market": "0x3e0f3863b4ed9dcabd7bbf9d03089e64bcfe5be6fd96284e58c772806823c60e", "price_changes": [{"asset_id": "110865594744159968267498282218512778667662344467377910002492558627771354011913", "price": "0.003", "size": "315.31", "side": "BUY", "hash": "f6f578cfd062f4d8f9b5b84aa2c3d82c13002d3d", "best_bid": "0.005", "best_ask": "0.008"}, {"asset_id": "58240812112472573224618301580190009078083222467735667648538851344040750074390", "price": "0.997", "size": "315.31", "side": "SELL", "hash": "1a6b0fbcd52b728a6e45e2b4511d543c3a8a9075", "best_bid": "0.992", "best_ask": "0.995"}], "timestamp": "1769384442751", "event_type": "price_change"}}
{"_local_timestamp": "2026-01-25T23:40:45.079469+00:00", "data": {"market": "0x33825080bc810aa756a361298627cdf64d58dbd651a647bd0a29b8a68a7308fe", "price_changes": [{"asset_id": "27476096571833974040484538127433399463608736639971094747870629065388427932028", "price": "0.119", "size": "7000", "side": "SELL", "hash": "a964b21c45e0c9164a2475f3cf5a12d40295bdcd", "best_bid": "0.034", "best_ask": "0.04"}, {"asset_id": "108112487379868796554191891208463687446351004748640934416300530966194496905118", "price": "0.881", "size": "7000", "side": "BUY", "hash": "86fdc20eb488dcac33b9ef8a4d9d4ed717111f6a", "best_bid": "0.96", "best_ask": "0.966"}], "timestamp": "1769384445000", "event_type": "price_change"}}
{"_local_timestamp": "2026-01-25T23:40:45.505155+00:00", "data": {"market": "0xb10aef4e56904ddab4f634b3bef36e878522d174ffb49688d3bca4e225516689", "price_changes": [{"asset_id": "53465481540932825427341404444568633780573546459375828539216440845324863999390", "price": "0.015", "size": "0", "side": "SELL", "hash": "a385d89de5da8b9ef1510668f721e89655b0d820", "best_bid": "0.004", "best_ask": "0.005"}, {"asset_id": "67794036975373042160958042377401666699501615403692529610067934475766181787521", "price": "0.985", "size": "0", "side": "BUY", "hash": "deb5245e185ee27d50d4981fe35ea5fb54bfcfce", "best_bid": "0.995", "best_ask": "0.996"}], "timestamp": "1769384445439", "event_type": "price_change"}}
{"_local_timestamp": "2026-01-25T23:40:45.539883+00:00", "data": {"market": "0xb10aef4e56904ddab4f634b3bef36e878522d174ffb49688d3bca4e225516689", "price_changes": [{"asset_id": "53465481540932825427341404444568633780573546459375828539216440845324863999390", "price": "0.015", "size": "452", "side": "SELL", "hash": "0bf97ca6326ba0aaaf5258563075f9e53a51780d", "best_bid": "0.004", "best_ask": "0.005"}, {"asset_id": "67794036975373042160958042377401666699501615403692529610067934475766181787521", "price": "0.985", "size": "452", "side": "BUY", "hash": "a0556366ac9e42867489091c04ba048698167363", "best_bid": "0.995", "best_ask": "0.996"}], "timestamp": "1769384445472", "event_type": "price_change"}}
{"_local_timestamp": "2026-01-25T23:40:49.638092+00:00", "data": {"market": "0x7c663472136f5db9dbc0a223ed26f9e586864d9d4d0d40cb28a8157e279feff4", "price_changes": [{"asset_id": "94146194619680623124956731256954660746880239065654088591536542002260568253245", "price": "0.004", "size": "5.44", "side": "BUY", "hash": "dbe6f34c71d56ec9897a8799b968358b88d8a062", "best_bid": "0.016", "best_ask": "0.017"}, {"asset_id": "80500705406858794154333907699858742630939624339510163743458445359324900544624", "price": "0.996", "size": "5.44", "side": "SELL", "hash": "3ea7472438e1dfcc305f2cc20cafe974c1f0086e", "best_bid": "0.983", "best_ask": "0.984"}], "timestamp": "1769384449568", "event_type": "price_change"}}
{"_local_timestamp": "2026-01-25T23:40:49.979690+00:00", "data": {"market": "0x7c663472136f5db9dbc0a223ed26f9e586864d9d4d0d40cb28a8157e279feff4", "price_changes": [{"asset_id": "94146194619680623124956731256954660746880239065654088591536542002260568253245", "price": "0.004", "size": "57.32", "side": "BUY", "hash": "43d9aaac63e5ad739268c0686298e29cd534988e", "best_bid": "0.016", "best_ask": "0.017"}, {"asset_id": "80500705406858794154333907699858742630939624339510163743458445359324900544624", "price": "0.996", "size": "57.32", "side": "SELL", "hash": "c92fe330265cf2249d8bba9f9c1c6ab678e1bb55", "best_bid": "0.983", "best_ask": "0.984"}], "timestamp": "1769384449898", "event_type": "price_change"}}
{"_local_timestamp": "2026-01-25T23:40:55.414005+00:00", "data": {"market": "0x33825080bc810aa756a361298627cdf64d58dbd651a647bd0a29b8a68a7308fe", "price_changes": [{"asset_id": "27476096571833974040484538127433399463608736639971094747870629065388427932028", "price": "0.007", "size": "2715", "side": "BUY", "hash": "dda90ba1969dc61e05a53ba49f5e4119196d4ba6", "best_bid": "0.034", "best_ask": "0.04"}, {"asset_id": "108112487379868796554191891208463687446351004748640934416300530966194496905118", "price": "0.993", "size": "2715", "side": "SELL", "hash": "812f6da8dc632944f105c99a3ba00c7e230296c9", "best_bid": "0.96", "best_ask": "0.966"}], "timestamp": "1769384455343", "event_type": "price_change"}}
{"_local_timestamp": "2026-01-25T23:40:55.414566+00:00", "data": {"market": "0x33825080bc810aa756a361298627cdf64d58dbd651a647bd0a29b8a68a7308fe", "price_changes": [{"asset_id": "27476096571833974040484538127433399463608736639971094747870629065388427932028", "price": "0.002", "size": "12882.42", "side": "BUY", "hash": "b75c5d1c97c3270d6277223f03866df6ae286adf", "best_bid": "0.034", "best_ask": "0.04"}, {"asset_id": "108112487379868796554191891208463687446351004748640934416300530966194496905118", "price": "0.998", "size": "12882.42", "side": "SELL", "hash": "bde3e7da3690bcf56b39d2829d511f71cb8f7374", "best_bid": "0.96", "best_ask": "0.966"}], "timestamp": "1769384455343", "event_type": "price_change"}}
{"_local_timestamp": "2026-01-25T23:40:55.441731+00:00", "data": {"market": "0x33825080bc810aa756a361298627cdf64d58dbd651a647bd0a29b8a68a7308fe", "price_changes": [{"asset_id": "27476096571833974040484538127433399463608736639971094747870629065388427932028", "price": "0.033", "size": "224.93", "side": "BUY", "hash": "1d40e6bee3a56df20debab5604c45c78883448a9", "best_bid": "0.034", "best_ask": "0.04"}, {"asset_id": "108112487379868796554191891208463687446351004748640934416300530966194496905118", "price": "0.967", "size": "224.93", "side": "SELL", "hash": "451bf3471fb746e6a93fae9f9658d5d30ec36629", "best_bid": "0.96", "best_ask": "0.966"}], "timestamp": "1769384455370", "event_type": "price_change"}}
{"_local_timestamp": "2026-01-25T23:40:56.332265+00:00", "data": {"market": "0x3d00e2266a6fce1d78d52dc99ad65a6e0b1d4b126608f9b57a57a9e64e14538b", "price_changes": [{"asset_id": "53186315788060762043972018184166502971471689613114984035234259092608911832812", "price": "0.021", "size": "391", "side": "BUY", "hash": "994a50c6bdedc65d8ad7994b279f180c759faab2", "best_bid": "0.041", "best_ask": "0.049"}, {"asset_id": "111295934648931540975810135936206324404031729488235714793836466636975428917888", "price": "0.979", "size": "391", "side": "SELL", "hash": "cecc0f57ff8a259b0cac68be67a49518d79a1ebc", "best_bid": "0.951", "best_ask": "0.959"}], "timestamp": "1769384456266", "event_type": "price_change"}}
{"_local_timestamp": "2026-01-25T23:40:56.333576+00:00", "data": {"market": "0x3d00e2266a6fce1d78d52dc99ad65a6e0b1d4b126608f9b57a57a9e64e14538b", "price_changes": [{"asset_id": "53186315788060762043972018184166502971471689613114984035234259092608911832812", "price": "0.002", "size": "6426.35", "side": "BUY", "hash": "994a50c6bdedc65d8ad7994b279f180c759faab2", "best_bid": "0.041", "best_ask": "0.049"}, {"asset_id": "111295934648931540975810135936206324404031729488235714793836466636975428917888", "price": "0.998", "size": "6426.35", "side": "SELL", "hash": "cecc0f57ff8a259b0cac68be67a49518d79a1ebc", "best_bid": "0.951", "best_ask": "0.959"}], "timestamp": "1769384456266", "event_type": "price_change"}}
{"_local_timestamp": "2026-01-25T23:40:56.334012+00:00", "data": {"market": "0x3d00e2266a6fce1d78d52dc99ad65a6e0b1d4b126608f9b57a57a9e64e14538b", "price_changes": [{"asset_id": "53186315788060762043972018184166502971471689613114984035234259092608911832812", "price": "0.011", "size": "637", "side": "BUY", "hash": "994a50c6bdedc65d8ad7994b279f180c759faab2", "best_bid": "0.041", "best_ask": "0.049"}, {"asset_id": "111295934648931540975810135936206324404031729488235714793836466636975428917888", "price": "0.989", "size": "637", "side": "SELL", "hash": "cecc0f57ff8a259b0cac68be67a49518d79a1ebc", "best_bid": "0.951", "best_ask": "0.959"}], "timestamp": "1769384456266", "event_type": "price_change"}}
{"_local_timestamp": "2026-01-25T23:40:56.334828+00:00", "data": {"market": "0x3d00e2266a6fce1d78d52dc99ad65a6e0b1d4b126608f9b57a57a9e64e14538b", "price_changes": [{"asset_id": "53186315788060762043972018184166502971471689613114984035234259092608911832812", "price": "0.024", "size": "0", "side": "BUY", "hash": "994a50c6bdedc65d8ad7994b279f180c759faab2", "best_bid": "0.041", "best_ask": "0.049"}, {"asset_id": "111295934648931540975810135936206324404031729488235714793836466636975428917888", "price": "0.976", "size": "0", "side": "SELL", "hash": "cecc0f57ff8a259b0cac68be67a49518d79a1ebc", "best_bid": "0.951", "best_ask": "0.959"}], "timestamp": "1769384456266", "event_type": "price_change"}}
{"_local_timestamp": "2026-01-25T23:40:56.497150+00:00", "data": {"market": "0x3d00e2266a6fce1d78d52dc99ad65a6e0b1d4b126608f9b57a57a9e64e14538b", "price_changes": [{"asset_id": "53186315788060762043972018184166502971471689613114984035234259092608911832812", "price": "0.022", "size": "425.31", "side": "BUY", "hash": "583023cc2cdb6478b852c6ca725b46f1ab29fc06", "best_bid": "0.041", "best_ask": "0.049"}, {"asset_id": "111295934648931540975810135936206324404031729488235714793836466636975428917888", "price": "0.978", "size": "425.31", "side": "SELL", "hash": "28659ff9137c97e5917024afaee57ba7eff0fd59", "best_bid": "0.951", "best_ask": "0.959"}], "timestamp": "1769384456427", "event_type": "price_change"}}
{"_local_timestamp": "2026-01-25T23:40:56.500438+00:00", "data": {"market": "0x3d00e2266a6fce1d78d52dc99ad65a6e0b1d4b126608f9b57a57a9e64e14538b", "price_changes": [{"asset_id": "53186315788060762043972018184166502971471689613114984035234259092608911832812", "price": "0.011", "size": "728", "side": "BUY", "hash": "17faa0e5b743a990a9df8f434a0faa6e1f44c8d0", "best_bid": "0.041", "best_ask": "0.049"}, {"asset_id": "111295934648931540975810135936206324404031729488235714793836466636975428917888", "price": "0.989", "size": "728", "side": "SELL", "hash": "1c612bf8be785057a9014457dbf19cbf1a34287e", "best_bid": "0.951", "best_ask": "0.959"}], "timestamp": "1769384456428", "event_type": "price_change"}}
{"_local_timestamp": "2026-01-25T23:41:03.171694+00:00", "data": {"market": "0xcfe8947073d9333a6f767ed0c46713361aa4c34f75b35f1636622210356b2ba4", "price_changes": [{"asset_id": "21753818038149716958441586952364965978994113536903636754979518045886497078801", "price": "0.012", "size": "0", "side": "SELL", "hash": "2a8f8274ac612e86c0a17a7d5888cb6e25e836f6", "best_bid": "0.002", "best_ask": "0.003"}, {"asset_id": "38409601990353197105461643021341338172518659365214781641813884172364820064219", "price": "0.988", "size": "0", "side": "BUY", "hash": "1ecc186784dc5639f9bab053c0e4b20e18dbedf1", "best_bid": "0.997", "best_ask": "0.998"}], "timestamp": "1769384463104", "event_type": "price_change"}}
{"_local_timestamp": "2026-01-25T23:41:03.190783+00:00", "data": {"market": "0xcfe8947073d9333a6f767ed0c46713361aa4c34f75b35f1636622210356b2ba4", "price_changes": [{"asset_id": "21753818038149716958441586952364965978994113536903636754979518045886497078801", "price": "0.699", "size": "100", "side": "SELL", "hash": "2a8f8274ac612e86c0a17a7d5888cb6e25e836f6", "best_bid": "0.002", "best_ask": "0.003"}, {"asset_id": "38409601990353197105461643021341338172518659365214781641813884172364820064219", "price": "0.301", "size": "100", "side": "BUY", "hash": "1ecc186784dc5639f9bab053c0e4b20e18dbedf1", "best_bid": "0.997", "best_ask": "0.998"}], "timestamp": "1769384463104", "event_type": "price_change"}}
{"_local_timestamp": "2026-01-25T23:41:03.254122+00:00", "data": {"market": "0xcfe8947073d9333a6f767ed0c46713361aa4c34f75b35f1636622210356b2ba4", "price_changes": [{"asset_id": "21753818038149716958441586952364965978994113536903636754979518045886497078801", "price": "0.056", "size": "89.28", "side": "SELL", "hash": "fa224fd38e0411d3be4c4f77eed8bc210eb6b8f9", "best_bid": "0.002", "best_ask": "0.003"}, {"asset_id": "38409601990353197105461643021341338172518659365214781641813884172364820064219", "price": "0.944", "size": "89.28", "side": "BUY", "hash": "89f81a6012824d19bbd9f10089b14ac29337aaa3", "best_bid": "0.997", "best_ask": "0.998"}], "timestamp": "1769384463192", "event_type": "price_change"}}
{"_local_timestamp": "2026-01-25T23:41:03.342824+00:00", "data": {"market": "0xcfe8947073d9333a6f767ed0c46713361aa4c34f75b35f1636622210356b2ba4", "price_changes": [{"asset_id": "21753818038149716958441586952364965978994113536903636754979518045886497078801", "price": "0.699", "size": "1714.33", "side": "SELL", "hash": "5de67b0e19dab869439ac8212903d85c2aa0cb1f", "best_bid": "0.002", "best_ask": "0.003"}, {"asset_id": "38409601990353197105461643021341338172518659365214781641813884172364820064219", "price": "0.301", "size": "1714.33", "side": "BUY", "hash": "695b8053fa679627453c0a5291e8093a21b4adb9", "best_bid": "0.997", "best_ask": "0.998"}], "timestamp": "1769384463277", "event_type": "price_change"}}
{"_local_timestamp": "2026-01-25T23:41:06.784509+00:00", "data": {"market": "0x45e914a8f5597714dfacecd335e013a3a53d0d4cbd687c85e1cc48c9047d285a", "price_changes": [{"asset_id": "110200527661363090969678046788357688179423234656139810394834278614636056974775", "price": "0.002", "size": "2487.45", "side": "BUY", "hash": "7430ac304b7cfc0bbee3781c0649a24cfd9b0119", "best_bid": "0.003", "best_ask": "0.005"}, {"asset_id": "68995509148146939312377551876533796789260737522245408918282961840521284671106", "price": "0.998", "size": "2487.45", "side": "SELL", "hash": "760e42f15c558cbf9bf1d78df310ea972429aea2", "best_bid": "0.995", "best_ask": "0.997"}], "timestamp": "1769384466650", "event_type": "price_change"}}
{"_local_timestamp": "2026-01-25T23:41:06.812019+00:00", "data": {"market": "0x0edc31cc586c65726249da0c698ce2b0dc3acac65a7b96574b7a8a89321ecf9e", "price_changes": [{"asset_id": "86948609484193076545604092003532216745788551371556780169247204971522981358794", "price": "0.012", "size": "300", "side": "BUY", "hash": "84f7e561c8d2ec258e435692e8e83be8f661fc53", "best_bid": "0.02", "best_ask": "0.026"}, {"asset_id": "40204010519879025056259875406560264981469631264230376751093889691606763270485", "price": "0.988", "size": "300", "side": "SELL", "hash": "3c2372b16d4b4781b1272f964b331f0aae591be5", "best_bid": "0.974", "best_ask": "0.98"}], "timestamp": "1769384466645", "event_type": "price_change"}}
{"_local_timestamp": "2026-01-25T23:41:06.812511+00:00", "data": {"market": "0xf3161b6068bb9e8375c3c39788b213dfb912b1ecaf8e64a1957ec523eaf36f65", "price_changes": [{"asset_id": "69376091146113194498094624279536929726823646994979580456392762592249313854175", "price": "0.005", "size": "263.56", "side": "BUY", "hash": "b2553663f2e45228f78c55c08cee4150fd31e5b1", "best_bid": "0.017", "best_ask": "0.018"}, {"asset_id": "18366541475247027354633521822685544012377744301234973068071847554908746172103", "price": "0.995", "size": "263.56", "side": "SELL", "hash": "8e21f9b949bb4931d3b24e5e2ebc5d2f28db50bb", "best_bid": "0.982", "best_ask": "0.983"}], "timestamp": "1769384466641", "event_type": "price_change"}}
{"_local_timestamp": "2026-01-25T23:41:06.812915+00:00", "data": {"market": "0xcfe8947073d9333a6f767ed0c46713361aa4c34f75b35f1636622210356b2ba4", "price_changes": [{"asset_id": "21753818038149716958441586952364965978994113536903636754979518045886497078801", "price": "0.002", "size": "1728.96", "side": "BUY", "hash": "5c8bad9ba6a1325249e984df1065c7f6cd1a9acb", "best_bid": "0.002", "best_ask": "0.003"}, {"asset_id": "38409601990353197105461643021341338172518659365214781641813884172364820064219", "price": "0.998", "size": "1728.96", "side": "SELL", "hash": "179b3eb10fb407e96e76b786305c49fbca4a4d58", "best_bid": "0.997", "best_ask": "0.998"}], "timestamp": "1769384466652", "event_type": "price_change"}}
{"_local_timestamp": "2026-01-25T23:41:06.945259+00:00", "data": {"market": "0x7c663472136f5db9dbc0a223ed26f9e586864d9d4d0d40cb28a8157e279feff4", "price_changes": [{"asset_id": "94146194619680623124956731256954660746880239065654088591536542002260568253245", "price": "0.011", "size": "0", "side": "BUY", "hash": "0aed0b5ac140a6b297c7888ebe95077f8a80818b", "best_bid": "0.016", "best_ask": "0.017"}, {"asset_id": "80500705406858794154333907699858742630939624339510163743458445359324900544624", "price": "0.989", "size": "0", "side": "SELL", "hash": "70b41db89eebca42a222273c7a6a84539bac44d8", "best_bid": "0.983", "best_ask": "0.984"}], "timestamp": "1769384466653", "event_type": "price_change"}}
{"_local_timestamp": "2026-01-25T23:41:06.945757+00:00", "data": {"market": "0xddda6004eefcf0ab8f542faa9856efec647d63bbbe70feb4c5dca376df32e8d7", "price_changes": [{"asset_id": "105357237982191656127719049458930828486417245494585420518830232261954691323810", "price": "0.004", "size": "1519.96", "side": "BUY", "hash": "7a380a6134172bb12343d4afb1a0013aec03c42f", "best_bid": "0.005", "best_ask": "0.007"}, {"asset_id": "60727132855373489262818696860770549261966005006541840363443788706996682318728", "price": "0.996", "size": "1519.96", "side": "SELL", "hash": "b4a98a690853fb31d82abdb68e88f46b275afa36", "best_bid": "0.993", "best_ask": "0.995"}], "timestamp": "1769384466653", "event_type": "price_change"}}
{"_local_timestamp": "2026-01-25T23:41:06.946148+00:00", "data": {"market": "0xf3161b6068bb9e8375c3c39788b213dfb912b1ecaf8e64a1957ec523eaf36f65", "price_changes": [{"asset_id": "69376091146113194498094624279536929726823646994979580456392762592249313854175", "price": "0.025", "size": "750", "side": "SELL", "hash": "0279bc0c14748fcacd3d4e452324642acabac0ba", "best_bid": "0.017", "best_ask": "0.018"}, {"asset_id": "18366541475247027354633521822685544012377744301234973068071847554908746172103", "price": "0.975", "size": "750", "side": "BUY", "hash": "313b1eb45f929e914bc51f9b817ea690f704536f", "best_bid": "0.982", "best_ask": "0.983"}], "timestamp": "1769384466748", "event_type": "price_change"}}
{"_local_timestamp": "2026-01-25T23:41:06.947197+00:00", "data": {"market": "0xf3161b6068bb9e8375c3c39788b213dfb912b1ecaf8e64a1957ec523eaf36f65", "price_changes": [{"asset_id": "69376091146113194498094624279536929726823646994979580456392762592249313854175", "price": "0.025", "size": "998", "side": "SELL", "hash": "272e012a96464916efe58c93ed21406d1f2867fc", "best_bid": "0.017", "best_ask": "0.018"}, {"asset_id": "18366541475247027354633521822685544012377744301234973068071847554908746172103", "price": "0.975", "size": "998", "side": "BUY", "hash": "0067ec33cd95b6e968203c792219b99ce47fc748", "best_bid": "0.982", "best_ask": "0.983"}], "timestamp": "1769384466774", "event_type": "price_change"}}
{"_local_timestamp": "2026-01-25T23:41:06.958230+00:00", "data": {"market": "0x7c663472136f5db9dbc0a223ed26f9e586864d9d4d0d40cb28a8157e279feff4", "price_changes": [{"asset_id": "94146194619680623124956731256954660746880239065654088591536542002260568253245", "price": "0.004", "size": "214.32", "side": "BUY", "hash": "92ee59a3fb791abd526c2af6d365968b17e3a24e", "best_bid": "0.016", "best_ask": "0.017"}, {"asset_id": "80500705406858794154333907699858742630939624339510163743458445359324900544624", "price": "0.996", "size": "214.32", "side": "SELL", "hash": "7cab9ca101959ef6c4de22682701c78836a3e07e", "best_bid": "0.983", "best_ask": "0.984"}], "timestamp": "1769384466880", "event_type": "price_change"}}
{"_local_timestamp": "2026-01-25T23:41:07.566385+00:00", "data": {"market": "0x33825080bc810aa756a361298627cdf64d58dbd651a647bd0a29b8a68a7308fe", "price_changes": [{"asset_id": "27476096571833974040484538127433399463608736639971094747870629065388427932028", "price": "0.022", "size": "17.5", "side": "BUY", "hash": "8c2c9382dfd84d8711daee10251e0537e84863e8", "best_bid": "0.034", "best_ask": "0.04"}, {"asset_id": "108112487379868796554191891208463687446351004748640934416300530966194496905118", "price": "0.978", "size": "17.5", "side": "SELL", "hash": "d2c84cbee39dc854807af239171a45727c058667", "best_bid": "0.96", "best_ask": "0.966"}], "timestamp": "1769384467497", "event_type": "price_change"}}
{"_local_timestamp": "2026-01-25T23:41:07.658866+00:00", "data": {"market": "0x33825080bc810aa756a361298627cdf64d58dbd651a647bd0a29b8a68a7308fe", "price_changes": [{"asset_id": "27476096571833974040484538127433399463608736639971094747870629065388427932028", "price": "0.031", "size": "411", "side": "BUY", "hash": "0b63cbc082dbc5a614d221e5cc4e9f9cdf192899", "best_bid": "0.034", "best_ask": "0.04"}, {"asset_id": "108112487379868796554191891208463687446351004748640934416300530966194496905118", "price": "0.969", "size": "411", "side": "SELL", "hash": "199ea5c9a1dc3556b52358befc2e5c89783bdb66", "best_bid": "0.96", "best_ask": "0.966"}], "timestamp": "1769384467586", "event_type": "price_change"}}
{"_local_timestamp": "2026-01-25T23:41:14.871025+00:00", "data": {"market": "0xc8944bb47818c0957fbeedcef9832d31927bd5d3f92912d08ae7db507ee851de", "price_changes": [{"asset_id": "43475483477872222798871077137471314754383343074234425453922242101872923868514", "price": "0.002", "size": "1166", "side": "BUY", "hash": "0baeb82a7c3e226201a12cb225f55a6cf3136f08", "best_bid": "0.005", "best_ask": "0.006"}, {"asset_id": "115373591989130727514457065197328696865580700117510285020088208107086541485978", "price": "0.998", "size": "1166", "side": "SELL", "hash": "db5d872a2d448bd12ec82b705fb4a2b67c8db849", "best_bid": "0.994", "best_ask": "0.995"}], "timestamp": "1769384474750", "event_type": "price_change"}}
{"_local_timestamp": "2026-01-25T23:41:14.872645+00:00", "data": {"market": "0xc8944bb47818c0957fbeedcef9832d31927bd5d3f92912d08ae7db507ee851de", "price_changes": [{"asset_id": "43475483477872222798871077137471314754383343074234425453922242101872923868514", "price": "0.003", "size": "414.37", "side": "BUY", "hash": "0baeb82a7c3e226201a12cb225f55a6cf3136f08", "best_bid": "0.005", "best_ask": "0.006"}, {"asset_id": "115373591989130727514457065197328696865580700117510285020088208107086541485978", "price": "0.997", "size": "414.37", "side": "SELL", "hash": "db5d872a2d448bd12ec82b705fb4a2b67c8db849", "best_bid": "0.994", "best_ask": "0.995"}], "timestamp": "1769384474750", "event_type": "price_change"}}
{"_local_timestamp": "2026-01-25T23:41:15.105018+00:00", "data": {"market": "0xc8944bb47818c0957fbeedcef9832d31927bd5d3f92912d08ae7db507ee851de", "price_changes": [{"asset_id": "43475483477872222798871077137471314754383343074234425453922242101872923868514", "price": "0.002", "size": "1432.91", "side": "BUY", "hash": "fa48255a26c3c788a50da4216cfbff8170e4364e", "best_bid": "0.005", "best_ask": "0.006"}, {"asset_id": "115373591989130727514457065197328696865580700117510285020088208107086541485978", "price": "0.998", "size": "1432.91", "side": "SELL", "hash": "d9d240197e825fb6a75321860295c24c6f97858b", "best_bid": "0.994", "best_ask": "0.995"}], "timestamp": "1769384475032", "event_type": "price_change"}}
{"_local_timestamp": "2026-01-25T23:41:15.109976+00:00", "data": {"market": "0xc8944bb47818c0957fbeedcef9832d31927bd5d3f92912d08ae7db507ee851de", "price_changes": [{"asset_id": "43475483477872222798871077137471314754383343074234425453922242101872923868514", "price": "0.003", "size": "493.65", "side": "BUY", "hash": "af73f1977bef487dfde780662c292b4356342560", "best_bid": "0.005", "best_ask": "0.006"}, {"asset_id": "115373591989130727514457065197328696865580700117510285020088208107086541485978", "price": "0.997", "size": "493.65", "side": "SELL", "hash": "6dbc6c7ea921b48316a83b04bf5e2c647dec699c", "best_bid": "0.994", "best_ask": "0.995"}], "timestamp": "1769384475033", "event_type": "price_change"}}
{"_local_timestamp": "2026-01-25T23:41:19.066331+00:00", "data": {"market": "0x0edc31cc586c65726249da0c698ce2b0dc3acac65a7b96574b7a8a89321ecf9e", "price_changes": [{"asset_id": "86948609484193076545604092003532216745788551371556780169247204971522981358794", "price": "0.016", "size": "345", "side": "BUY", "hash": "d0675e58b64f44ca46bc4a0e49a0ebdfbca0a93d", "best_bid": "0.02", "best_ask": "0.026"}, {"asset_id": "40204010519879025056259875406560264981469631264230376751093889691606763270485", "price": "0.984", "size": "345", "side": "SELL", "hash": "64b79fb21a199940ad145cecf538095cd8d14515", "best_bid": "0.974", "best_ask": "0.98"}], "timestamp": "1769384478992", "event_type": "price_change"}}
{"_local_timestamp": "2026-01-25T23:41:19.097162+00:00", "data": {"market": "0x0edc31cc586c65726249da0c698ce2b0dc3acac65a7b96574b7a8a89321ecf9e", "price_changes": [{"asset_id": "86948609484193076545604092003532216745788551371556780169247204971522981358794", "price": "0.016", "size": "0", "side": "BUY", "hash": "874db75d2cff73497fac25e2ee6e99b58a7492a4", "best_bid": "0.02", "best_ask": "0.026"}, {"asset_id": "40204010519879025056259875406560264981469631264230376751093889691606763270485", "price": "0.984", "size": "0", "side": "SELL", "hash": "34c8eaa724dd90be6b24dc65e6189a1d8c3b439e", "best_bid": "0.974", "best_ask": "0.98"}], "timestamp": "1769384479022", "event_type": "price_change"}}
{"_local_timestamp": "2026-01-25T23:41:19.119204+00:00", "data": {"market": "0x0edc31cc586c65726249da0c698ce2b0dc3acac65a7b96574b7a8a89321ecf9e", "price_changes": [{"asset_id": "86948609484193076545604092003532216745788551371556780169247204971522981358794", "price": "0.015", "size": "358", "side": "BUY", "hash": "7ee09b238829c56061297b051c9d84bf73dcf863", "best_bid": "0.02", "best_ask": "0.026"}, {"asset_id": "40204010519879025056259875406560264981469631264230376751093889691606763270485", "price": "0.985", "size": "358", "side": "SELL", "hash": "c9fe4101a7c9d601836c7c69418e200f04e48efa", "best_bid": "0.974", "best_ask": "0.98"}], "timestamp": "1769384479051", "event_type": "price_change"}}
{"_local_timestamp": "2026-01-25T23:41:19.550373+00:00", "data": {"market": "0x0edc31cc586c65726249da0c698ce2b0dc3acac65a7b96574b7a8a89321ecf9e", "price_changes": [{"asset_id": "86948609484193076545604092003532216745788551371556780169247204971522981358794", "price": "0.015", "size": "368.95", "side": "BUY", "hash": "f7ff81e854d96e2776a3eb8b5a523abe8b801419", "best_bid": "0.02", "best_ask": "0.026"}, {"asset_id": "40204010519879025056259875406560264981469631264230376751093889691606763270485", "price": "0.985", "size": "368.95", "side": "SELL", "hash": "a399115457621a9a7902e26416abe9432f51db46", "best_bid": "0.974", "best_ask": "0.98"}], "timestamp": "1769384479481", "event_type": "price_change"}}
{"_local_timestamp": "2026-01-25T23:41:40.099762+00:00", "data": {"market": "0x3d00e2266a6fce1d78d52dc99ad65a6e0b1d4b126608f9b57a57a9e64e14538b", "price_changes": [{"asset_id": "53186315788060762043972018184166502971471689613114984035234259092608911832812", "price": "0.002", "size": "4926.35", "side": "BUY", "hash": "0a6523f88e5dc744313d486e0fcc91bfcfe83a59", "best_bid": "0.041", "best_ask": "0.049"}, {"asset_id": "111295934648931540975810135936206324404031729488235714793836466636975428917888", "price": "0.998", "size": "4926.35", "side": "SELL", "hash": "e4664e45101aae1ee5a6c8613432166ae5c914a2", "best_bid": "0.951", "best_ask": "0.959"}], "timestamp": "1769384500007", "event_type": "price_change"}}
{"_local_timestamp": "2026-01-25T23:41:42.705689+00:00", "data": {"market": "0x3d00e2266a6fce1d78d52dc99ad65a6e0b1d4b126608f9b57a57a9e64e14538b", "price_changes": [{"asset_id": "53186315788060762043972018184166502971471689613114984035234259092608911832812", "price": "0.002", "size": "6426.35", "side": "BUY", "hash": "8f309cde05d9b4c26a7032b04197f8650a32236d", "best_bid": "0.041", "best_ask": "0.049"}, {"asset_id": "111295934648931540975810135936206324404031729488235714793836466636975428917888", "price": "0.998", "size": "6426.35", "side": "SELL", "hash": "6640f6a089e80730f0f634a7ae2fedc06a939163", "best_bid": "0.951", "best_ask": "0.959"}], "timestamp": "1769384502638", "event_type": "price_change"}}
{"_local_timestamp": "2026-01-25T23:41:48.162836+00:00", "data": {"market": "0xcfe8947073d9333a6f767ed0c46713361aa4c34f75b35f1636622210356b2ba4", "price_changes": [{"asset_id": "21753818038149716958441586952364965978994113536903636754979518045886497078801", "price": "0.006", "size": "85.9", "side": "SELL", "hash": "a0045b14897152ba2a88159f9582c18e05a82c88", "best_bid": "0.002", "best_ask": "0.003"}, {"asset_id": "38409601990353197105461643021341338172518659365214781641813884172364820064219", "price": "0.994", "size": "85.9", "side": "BUY", "hash": "2baf6da8e29f3dd5aec368e50c0c1a7f718ee807", "best_bid": "0.997", "best_ask": "0.998"}], "timestamp": "1769384508084", "event_type": "price_change"}}
{"_local_timestamp": "2026-01-25T23:41:48.246725+00:00", "data": {"market": "0xcfe8947073d9333a6f767ed0c46713361aa4c34f75b35f1636622210356b2ba4", "price_changes": [{"asset_id": "21753818038149716958441586952364965978994113536903636754979518045886497078801", "price": "0.028", "size": "363.65", "side": "SELL", "hash": "d300b395d6da41f060990c0674425d28496dbd2d", "best_bid": "0.002", "best_ask": "0.003"}, {"asset_id": "38409601990353197105461643021341338172518659365214781641813884172364820064219", "price": "0.972", "size": "363.65", "side": "BUY", "hash": "9f60620f3661937997053b93c5fa781e9699cf71", "best_bid": "0.997", "best_ask": "0.998"}], "timestamp": "1769384508179", "event_type": "price_change"}}
{"_local_timestamp": "2026-01-25T23:41:49.496225+00:00", "data": {"market": "0x45e914a8f5597714dfacecd335e013a3a53d0d4cbd687c85e1cc48c9047d285a", "price_changes": [{"asset_id": "110200527661363090969678046788357688179423234656139810394834278614636056974775", "price": "0.001", "size": "21515.68", "side": "BUY", "hash": "5984252e0685efe9f5e4d24e91fcbc5875729410", "best_bid": "0.003", "best_ask": "0.005"}, {"asset_id": "68995509148146939312377551876533796789260737522245408918282961840521284671106", "price": "0.999", "size": "21515.68", "side": "SELL", "hash": "f378fd1e6a78465157ffc7a85904d5849a857f1d", "best_bid": "0.995", "best_ask": "0.997"}], "timestamp": "1769384509356", "event_type": "price_change"}}
{"_local_timestamp": "2026-01-25T23:41:49.497071+00:00", "data": {"market": "0x45e914a8f5597714dfacecd335e013a3a53d0d4cbd687c85e1cc48c9047d285a", "price_changes": [{"asset_id": "110200527661363090969678046788357688179423234656139810394834278614636056974775", "price": "0.002", "size": "1992.43", "side": "BUY", "hash": "5984252e0685efe9f5e4d24e91fcbc5875729410", "best_bid": "0.003", "best_ask": "0.005"}, {"asset_id": "68995509148146939312377551876533796789260737522245408918282961840521284671106", "price": "0.998", "size": "1992.43", "side": "SELL", "hash": "f378fd1e6a78465157ffc7a85904d5849a857f1d", "best_bid": "0.995", "best_ask": "0.997"}], "timestamp": "1769384509356", "event_type": "price_change"}}
{"_local_timestamp": "2026-01-25T23:41:49.746869+00:00", "data": {"market": "0x45e914a8f5597714dfacecd335e013a3a53d0d4cbd687c85e1cc48c9047d285a", "price_changes": [{"asset_id": "110200527661363090969678046788357688179423234656139810394834278614636056974775", "price": "0.002", "size": "2487.45", "side": "BUY", "hash": "712e0b0ae2bfa97acab1a7b348dae982dadf3d46", "best_bid": "0.003", "best_ask": "0.005"}, {"asset_id": "68995509148146939312377551876533796789260737522245408918282961840521284671106", "price": "0.998", "size": "2487.45", "side": "SELL", "hash": "14a2342471f696fe77158756e95d2bbee7af509a", "best_bid": "0.995", "best_ask": "0.997"}], "timestamp": "1769384509661", "event_type": "price_change"}}
{"_local_timestamp": "2026-01-25T23:41:49.747416+00:00", "data": {"market": "0x45e914a8f5597714dfacecd335e013a3a53d0d4cbd687c85e1cc48c9047d285a", "price_changes": [{"asset_id": "110200527661363090969678046788357688179423234656139810394834278614636056974775", "price": "0.001", "size": "21525.63", "side": "BUY", "hash": "1fca0be1e7850ab0bdd26e6168e286de2390beb5", "best_bid": "0.003", "best_ask": "0.005"}, {"asset_id": "68995509148146939312377551876533796789260737522245408918282961840521284671106", "price": "0.999", "size": "21525.63", "side": "SELL", "hash": "7b20ecba033a89ecad5023c31ffe106c7ae3d8af", "best_bid": "0.995", "best_ask": "0.997"}], "timestamp": "1769384509662", "event_type": "price_change"}}
{"_local_timestamp": "2026-01-25T23:41:50.900079+00:00", "data": {"market": "0xcfe8947073d9333a6f767ed0c46713361aa4c34f75b35f1636622210356b2ba4", "price_changes": [{"asset_id": "38409601990353197105461643021341338172518659365214781641813884172364820064219", "price": "0.4", "size": "100", "side": "BUY", "hash": "56b4b2e3ed36bab009187aeebfa2e2943d5dd3d5", "best_bid": "0.997", "best_ask": "0.998"}, {"asset_id": "21753818038149716958441586952364965978994113536903636754979518045886497078801", "price": "0.6", "size": "100", "side": "SELL", "hash": "35b9d76cfa8d097684601261997278c304acd6b0", "best_bid": "0.002", "best_ask": "0.003"}], "timestamp": "1769384510752", "event_type": "price_change"}}
{"_local_timestamp": "2026-01-25T23:41:52.023239+00:00", "data": {"market": "0x3d00e2266a6fce1d78d52dc99ad65a6e0b1d4b126608f9b57a57a9e64e14538b", "price_changes": [{"asset_id": "53186315788060762043972018184166502971471689613114984035234259092608911832812", "price": "0.032", "size": "0", "side": "BUY", "hash": "49253375c5b03674bd4d754efddb73e29f5c109b", "best_bid": "0.041", "best_ask": "0.049"}, {"asset_id": "111295934648931540975810135936206324404031729488235714793836466636975428917888", "price": "0.968", "size": "0", "side": "SELL", "hash": "4d3d667b4555400baaadd22c90bd0946ba764365", "best_bid": "0.951", "best_ask": "0.959"}], "timestamp": "1769384511939", "event_type": "price_change"}}
{"_local_timestamp": "2026-01-25T23:41:52.023932+00:00", "data": {"market": "0x830532ef53004df7522d7c56cad9af92f4b323590e7712302efdd99fa04cc078", "price_changes": [{"asset_id": "76159445949516107531196937780408758100497431686502173729855321957977280983930", "price": "0.011", "size": "818", "side": "BUY", "hash": "160377fe44452ab6bf06cf6a02fad159963c221d", "best_bid": "0.021", "best_ask": "0.029"}, {"asset_id": "55889977023103749239654252466433022405707563507479932528448213571367486700989", "price": "0.989", "size": "818", "side": "SELL", "hash": "97add90e6d985d9a0e82d8f03f98799b201642b1", "best_bid": "0.971", "best_ask": "0.979"}], "timestamp": "1769384511940", "event_type": "price_change"}}
{"_local_timestamp": "2026-01-25T23:41:52.024355+00:00", "data": {"market": "0x830532ef53004df7522d7c56cad9af92f4b323590e7712302efdd99fa04cc078", "price_changes": [{"asset_id": "76159445949516107531196937780408758100497431686502173729855321957977280983930", "price": "0.013", "size": "100", "side": "BUY", "hash": "160377fe44452ab6bf06cf6a02fad159963c221d", "best_bid": "0.021", "best_ask": "0.029"}, {"asset_id": "55889977023103749239654252466433022405707563507479932528448213571367486700989", "price": "0.987", "size": "100", "side": "SELL", "hash": "97add90e6d985d9a0e82d8f03f98799b201642b1", "best_bid": "0.971", "best_ask": "0.979"}], "timestamp": "1769384511940", "event_type": "price_change"}}
{"_local_timestamp": "2026-01-25T23:41:52.024754+00:00", "data": {"market": "0x830532ef53004df7522d7c56cad9af92f4b323590e7712302efdd99fa04cc078", "price_changes": [{"asset_id": "76159445949516107531196937780408758100497431686502173729855321957977280983930", "price": "0.015", "size": "0", "side": "BUY", "hash": "160377fe44452ab6bf06cf6a02fad159963c221d", "best_bid": "0.021", "best_ask": "0.029"}, {"asset_id": "55889977023103749239654252466433022405707563507479932528448213571367486700989", "price": "0.985", "size": "0", "side": "SELL", "hash": "97add90e6d985d9a0e82d8f03f98799b201642b1", "best_bid": "0.971", "best_ask": "0.979"}], "timestamp": "1769384511940", "event_type": "price_change"}}
{"_local_timestamp": "2026-01-25T23:41:52.050518+00:00", "data": {"market": "0x830532ef53004df7522d7c56cad9af92f4b323590e7712302efdd99fa04cc078", "price_changes": [{"asset_id": "76159445949516107531196937780408758100497431686502173729855321957977280983930", "price": "0.016", "size": "0", "side": "BUY", "hash": "fc3de3c8126c64cd3444f2c47d49dfc20d0455b7", "best_bid": "0.021", "best_ask": "0.029"}, {"asset_id": "55889977023103749239654252466433022405707563507479932528448213571367486700989", "price": "0.984", "size": "0", "side": "SELL", "hash": "d5aad724aabfca05a1a5364976fcd5ee94dfa2ad", "best_bid": "0.971", "best_ask": "0.979"}], "timestamp": "1769384511974", "event_type": "price_change"}}
{"_local_timestamp": "2026-01-25T23:41:52.051077+00:00", "data": {"market": "0x3d00e2266a6fce1d78d52dc99ad65a6e0b1d4b126608f9b57a57a9e64e14538b", "price_changes": [{"asset_id": "53186315788060762043972018184166502971471689613114984035234259092608911832812", "price": "0.035", "size": "119", "side": "BUY", "hash": "dbedc538aa04acdffb9ab6cc39cd2da07c557e7e", "best_bid": "0.041", "best_ask": "0.049"}, {"asset_id": "111295934648931540975810135936206324404031729488235714793836466636975428917888", "price": "0.965", "size": "119", "side": "SELL", "hash": "7ff453125a43bccc519e8a323bdee8b0035d0382", "best_bid": "0.951", "best_ask": "0.959"}], "timestamp": "1769384511976", "event_type": "price_change"}}
{"_local_timestamp": "2026-01-25T23:41:52.077485+00:00", "data": {"market": "0x830532ef53004df7522d7c56cad9af92f4b323590e7712302efdd99fa04cc078", "price_changes": [{"asset_id": "76159445949516107531196937780408758100497431686502173729855321957977280983930", "price": "0.014", "size": "243", "side": "BUY", "hash": "c85b6249f2fc830915dfa065319547a2efb373cc", "best_bid": "0.021", "best_ask": "0.029"}, {"asset_id": "55889977023103749239654252466433022405707563507479932528448213571367486700989", "price": "0.986", "size": "243", "side": "SELL", "hash": "d60fc6ac8497a408786a6f2e59d97607fb55828c", "best_bid": "0.971", "best_ask": "0.979"}], "timestamp": "1769384512002", "event_type": "price_change"}}
{"_local_timestamp": "2026-01-25T23:41:52.378293+00:00", "data": {"market": "0x3d00e2266a6fce1d78d52dc99ad65a6e0b1d4b126608f9b57a57a9e64e14538b", "price_changes": [{"asset_id": "53186315788060762043972018184166502971471689613114984035234259092608911832812", "price": "0.034", "size": "5.95", "side": "BUY", "hash": "76ecd17a8f33161ed576813ea5bbfc026037923a", "best_bid": "0.041", "best_ask": "0.049"}, {"asset_id": "111295934648931540975810135936206324404031729488235714793836466636975428917888", "price": "0.966", "size": "5.95", "side": "SELL", "hash": "92a2619b59ea2fce13a7687a021373881637331f", "best_bid": "0.951", "best_ask": "0.959"}], "timestamp": "1769384512305", "event_type": "price_change"}}
{"_local_timestamp": "2026-01-25T23:41:52.378818+00:00", "data": {"market": "0x830532ef53004df7522d7c56cad9af92f4b323590e7712302efdd99fa04cc078", "price_changes": [{"asset_id": "76159445949516107531196937780408758100497431686502173729855321957977280983930", "price": "0.014", "size": "253.33", "side": "BUY", "hash": "5469f955bd38d26257d3bada42b06e4c8d3234a6", "best_bid": "0.021", "best_ask": "0.029"}, {"asset_id": "55889977023103749239654252466433022405707563507479932528448213571367486700989", "price": "0.986", "size": "253.33", "side": "SELL", "hash": "0b24858841150a982f7e459a4b3eba3bcae71fe7", "best_bid": "0.971", "best_ask": "0.979"}], "timestamp": "1769384512306", "event_type": "price_change"}}
{"_local_timestamp": "2026-01-25T23:41:52.382513+00:00", "data": {"market": "0x830532ef53004df7522d7c56cad9af92f4b323590e7712302efdd99fa04cc078", "price_changes": [{"asset_id": "76159445949516107531196937780408758100497431686502173729855321957977280983930", "price": "0.017", "size": "16.63", "side": "BUY", "hash": "078421012f0e33df3ca9b1aefb1a430efbc3f32d", "best_bid": "0.021", "best_ask": "0.029"}, {"asset_id": "55889977023103749239654252466433022405707563507479932528448213571367486700989", "price": "0.983", "size": "16.63", "side": "SELL", "hash": "8f2f14c68244e6f23a6fd0550269f1988dd78421", "best_bid": "0.971", "best_ask": "0.979"}], "timestamp": "1769384512311", "event_type": "price_change"}}
{"_local_timestamp": "2026-01-25T23:41:52.393391+00:00", "data": {"market": "0x830532ef53004df7522d7c56cad9af92f4b323590e7712302efdd99fa04cc078", "price_changes": [{"asset_id": "76159445949516107531196937780408758100497431686502173729855321957977280983930", "price": "0.012", "size": "525.13", "side": "BUY", "hash": "77dd6b1824b2e35ee639e413619708d4e8830207", "best_bid": "0.021", "best_ask": "0.029"}, {"asset_id": "55889977023103749239654252466433022405707563507479932528448213571367486700989", "price": "0.988", "size": "525.13", "side": "SELL", "hash": "d2a50ad6e610da943c8094c81fc482ac4a6a0272", "best_bid": "0.971", "best_ask": "0.979"}], "timestamp": "1769384512317", "event_type": "price_change"}}
{"_local_timestamp": "2026-01-25T23:41:52.394210+00:00", "data": {"market": "0x830532ef53004df7522d7c56cad9af92f4b323590e7712302efdd99fa04cc078", "price_changes": [{"asset_id": "76159445949516107531196937780408758100497431686502173729855321957977280983930", "price": "0.004", "size": "93.99", "side": "BUY", "hash": "df9a36c8cebd59ca18e9cec6da7e4fcbe3c408ce", "best_bid": "0.021", "best_ask": "0.029"}, {"asset_id": "55889977023103749239654252466433022405707563507479932528448213571367486700989", "price": "0.996", "size": "93.99", "side": "SELL", "hash": "6bac8b5798d26b439d890007d25ee1a3fc55f1f3", "best_bid": "0.971", "best_ask": "0.979"}], "timestamp": "1769384512320", "event_type": "price_change"}}
{"_local_timestamp": "2026-01-25T23:41:52.767918+00:00", "data": {"market": "0xcfe8947073d9333a6f767ed0c46713361aa4c34f75b35f1636622210356b2ba4", "price_changes": [{"asset_id": "38409601990353197105461643021341338172518659365214781641813884172364820064219", "price": "0.401", "size": "143.47", "side": "BUY", "hash": "31c31f826ad14b2e90829c998315ad96c8317ce1", "best_bid": "0.997", "best_ask": "0.998"}, {"asset_id": "21753818038149716958441586952364965978994113536903636754979518045886497078801", "price": "0.599", "size": "143.47", "side": "SELL", "hash": "f2deea077e64d8e641646b5efaea6d6217768ce2", "best_bid": "0.002", "best_ask": "0.003"}], "timestamp": "1769384511781", "event_type": "price_change"}}
{"_local_timestamp": "2026-01-25T23:41:53.363275+00:00", "data": {"market": "0x3d00e2266a6fce1d78d52dc99ad65a6e0b1d4b126608f9b57a57a9e64e14538b", "price_changes": [{"asset_id": "53186315788060762043972018184166502971471689613114984035234259092608911832812", "price": "0.035", "size": "6", "side": "BUY", "hash": "812acba27fedd2f38e376f592535e5810114f103", "best_bid": "0.041", "best_ask": "0.049"}, {"asset_id": "111295934648931540975810135936206324404031729488235714793836466636975428917888", "price": "0.965", "size": "6", "side": "SELL", "hash": "cc2f4998d4fe5bf4a4d13242985d7a80aa0fd508", "best_bid": "0.951", "best_ask": "0.959"}], "timestamp": "1769384513295", "event_type": "price_change"}}
{"_local_timestamp": "2026-01-25T23:41:55.651052+00:00", "data": {"market": "0x33825080bc810aa756a361298627cdf64d58dbd651a647bd0a29b8a68a7308fe", "price_changes": [{"asset_id": "27476096571833974040484538127433399463608736639971094747870629065388427932028", "price": "0.119", "size": "7043.3", "side": "SELL", "hash": "6ae10b62a541baea0f519ed755415323a93cd599", "best_bid": "0.034", "best_ask": "0.04"}, {"asset_id": "108112487379868796554191891208463687446351004748640934416300530966194496905118", "price": "0.881", "size": "7043.3", "side": "BUY", "hash": "f731ee327b1f305e63cc103b3b7b1a3b95a5fac5", "best_bid": "0.96", "best_ask": "0.966"}], "timestamp": "1769384515573", "event_type": "price_change"}}
{"_local_timestamp": "2026-01-25T23:41:59.039377+00:00", "data": {"market": "0xf3161b6068bb9e8375c3c39788b213dfb912b1ecaf8e64a1957ec523eaf36f65", "price_changes": [{"asset_id": "69376091146113194498094624279536929726823646994979580456392762592249313854175", "price": "0.009", "size": "0", "side": "BUY", "hash": "20cc70f84ec3d3f1ae3266154e3245aafa3fdd50", "best_bid": "0.017", "best_ask": "0.018"}, {"asset_id": "18366541475247027354633521822685544012377744301234973068071847554908746172103", "price": "0.991", "size": "0", "side": "SELL", "hash": "bdc3f4906c4ab521a93572bbe30894392e56bdac", "best_bid": "0.982", "best_ask": "0.983"}], "timestamp": "1769384518969", "event_type": "price_change"}}
{"_local_timestamp": "2026-01-25T23:41:59.040023+00:00", "data": {"market": "0xf3161b6068bb9e8375c3c39788b213dfb912b1ecaf8e64a1957ec523eaf36f65", "price_changes": [{"asset_id": "69376091146113194498094624279536929726823646994979580456392762592249313854175", "price": "0.013", "size": "0", "side": "BUY", "hash": "20cc70f84ec3d3f1ae3266154e3245aafa3fdd50", "best_bid": "0.017", "best_ask": "0.018"}, {"asset_id": "18366541475247027354633521822685544012377744301234973068071847554908746172103", "price": "0.987", "size": "0", "side": "SELL", "hash": "bdc3f4906c4ab521a93572bbe30894392e56bdac", "best_bid": "0.982", "best_ask": "0.983"}], "timestamp": "1769384518969", "event_type": "price_change"}}
{"_local_timestamp": "2026-01-25T23:41:59.060163+00:00", "data": {"market": "0xf3161b6068bb9e8375c3c39788b213dfb912b1ecaf8e64a1957ec523eaf36f65", "price_changes": [{"asset_id": "69376091146113194498094624279536929726823646994979580456392762592249313854175", "price": "0.025", "size": "750", "side": "SELL", "hash": "8059cf39bb2b2186484c4a197cb9213a486dbacc", "best_bid": "0.017", "best_ask": "0.018"}, {"asset_id": "18366541475247027354633521822685544012377744301234973068071847554908746172103", "price": "0.975", "size": "750", "side": "BUY", "hash": "eff13449778e70349b529ab9c08a331d75c27351", "best_bid": "0.982", "best_ask": "0.983"}], "timestamp": "1769384518993", "event_type": "price_change"}}
{"_local_timestamp": "2026-01-25T23:41:59.141766+00:00", "data": {"market": "0xf3161b6068bb9e8375c3c39788b213dfb912b1ecaf8e64a1957ec523eaf36f65", "price_changes": [{"asset_id": "69376091146113194498094624279536929726823646994979580456392762592249313854175", "price": "0.025", "size": "1013", "side": "SELL", "hash": "899fd796bbf4116fb9aaf5d6b7e91087f8650753", "best_bid": "0.017", "best_ask": "0.018"}, {"asset_id": "18366541475247027354633521822685544012377744301234973068071847554908746172103", "price": "0.975", "size": "1013", "side": "BUY", "hash": "881ce429c9ac04f50058fde8a82a2bb2c23178b7", "best_bid": "0.982", "best_ask": "0.983"}], "timestamp": "1769384519025", "event_type": "price_change"}}
{"_local_timestamp": "2026-01-25T23:41:59.368192+00:00", "data": {"market": "0xf3161b6068bb9e8375c3c39788b213dfb912b1ecaf8e64a1957ec523eaf36f65", "price_changes": [{"asset_id": "69376091146113194498094624279536929726823646994979580456392762592249313854175", "price": "0.007", "size": "41.99", "side": "BUY", "hash": "4ac9d8997d0fbc861d2e29f567331717e9efc27d", "best_bid": "0.017", "best_ask": "0.018"}, {"asset_id": "18366541475247027354633521822685544012377744301234973068071847554908746172103", "price": "0.993", "size": "41.99", "side": "SELL", "hash": "803a571cc1ec1d40760162ea8683677563ae7136", "best_bid": "0.982", "best_ask": "0.983"}], "timestamp": "1769384519303", "event_type": "price_change"}}
{"_local_timestamp": "2026-01-25T23:41:59.368941+00:00", "data": {"market": "0xf3161b6068bb9e8375c3c39788b213dfb912b1ecaf8e64a1957ec523eaf36f65", "price_changes": [{"asset_id": "69376091146113194498094624279536929726823646994979580456392762592249313854175", "price": "0.013", "size": "18.43", "side": "BUY", "hash": "75e6d8c950a0f51db87fbfe0d14b4bde69965bc5", "best_bid": "0.017", "best_ask": "0.018"}, {"asset_id": "18366541475247027354633521822685544012377744301234973068071847554908746172103", "price": "0.987", "size": "18.43", "side": "SELL", "hash": "5ebd4562a19aa7d8c73663064be2a0a59e9cfdae", "best_bid": "0.982", "best_ask": "0.983"}], "timestamp": "1769384519305", "event_type": "price_change"}}
{"_local_timestamp": "2026-01-25T23:42:00.268937+00:00", "data": {"market": "0xf3161b6068bb9e8375c3c39788b213dfb912b1ecaf8e64a1957ec523eaf36f65", "price_changes": [{"asset_id": "69376091146113194498094624279536929726823646994979580456392762592249313854175", "price": "0.025", "size": "750", "side": "SELL", "hash": "817f7d593bff7a9bcba07ff3d997b134bb3b0215", "best_bid": "0.017", "best_ask": "0.018"}, {"asset_id": "18366541475247027354633521822685544012377744301234973068071847554908746172103", "price": "0.975", "size": "750", "side": "BUY", "hash": "b7292c733fa02840047276d518ccc3382d58e1c5", "best_bid": "0.982", "best_ask": "0.983"}], "timestamp": "1769384520204", "event_type": "price_change"}}
{"_local_timestamp": "2026-01-25T23:42:00.300686+00:00", "data": {"market": "0xf3161b6068bb9e8375c3c39788b213dfb912b1ecaf8e64a1957ec523eaf36f65", "price_changes": [{"asset_id": "69376091146113194498094624279536929726823646994979580456392762592249313854175", "price": "0.025", "size": "1007", "side": "SELL", "hash": "8e1ba13e8626cbb96955625d5a0f5a7b847becf5", "best_bid": "0.017", "best_ask": "0.018"}, {"asset_id": "18366541475247027354633521822685544012377744301234973068071847554908746172103", "price": "0.975", "size": "1007", "side": "BUY", "hash": "f1a0f659e03986fa0129012a8648488ed050119d", "best_bid": "0.982", "best_ask": "0.983"}], "timestamp": "1769384520234", "event_type": "price_change"}}
{"_local_timestamp": "2026-01-25T23:42:03.700219+00:00", "data": {"market": "0xcfe8947073d9333a6f767ed0c46713361aa4c34f75b35f1636622210356b2ba4", "price_changes": [{"asset_id": "21753818038149716958441586952364965978994113536903636754979518045886497078801", "price": "0.599", "size": "118.43", "side": "SELL", "hash": "c861b9a68e63512c913659ffee0702a6fed3b3ab", "best_bid": "0.002", "best_ask": "0.003"}, {"asset_id": "38409601990353197105461643021341338172518659365214781641813884172364820064219", "price": "0.401", "size": "118.43", "side": "BUY", "hash": "f7415324e7b03e57b7396ff80ffdfa8c58079b42", "best_bid": "0.997", "best_ask": "0.998"}], "timestamp": "1769384523636", "event_type": "price_change"}}
{"_local_timestamp": "2026-01-25T23:42:03.700821+00:00", "data": {"market": "0xcfe8947073d9333a6f767ed0c46713361aa4c34f75b35f1636622210356b2ba4", "price_changes": [{"asset_id": "21753818038149716958441586952364965978994113536903636754979518045886497078801", "price": "0.056", "size": "0", "side": "SELL", "hash": "c861b9a68e63512c913659ffee0702a6fed3b3ab", "best_bid": "0.002", "best_ask": "0.003"}, {"asset_id": "38409601990353197105461643021341338172518659365214781641813884172364820064219", "price": "0.944", "size": "0", "side": "BUY", "hash": "f7415324e7b03e57b7396ff80ffdfa8c58079b42", "best_bid": "0.997", "best_ask": "0.998"}], "timestamp": "1769384523636", "event_type": "price_change"}}
{"_local_timestamp": "2026-01-25T23:42:03.705497+00:00", "data": {"market": "0xcfe8947073d9333a6f767ed0c46713361aa4c34f75b35f1636622210356b2ba4", "price_changes": [{"asset_id": "21753818038149716958441586952364965978994113536903636754979518045886497078801", "price": "0.699", "size": "100", "side": "SELL", "hash": "c861b9a68e63512c913659ffee0702a6fed3b3ab", "best_bid": "0.002", "best_ask": "0.003"}, {"asset_id": "38409601990353197105461643021341338172518659365214781641813884172364820064219", "price": "0.301", "size": "100", "side": "BUY", "hash": "f7415324e7b03e57b7396ff80ffdfa8c58079b42", "best_bid": "0.997", "best_ask": "0.998"}], "timestamp": "1769384523636", "event_type": "price_change"}}
{"_local_timestamp": "2026-01-25T23:42:03.783768+00:00", "data": {"market": "0xcfe8947073d9333a6f767ed0c46713361aa4c34f75b35f1636622210356b2ba4", "price_changes": [{"asset_id": "21753818038149716958441586952364965978994113536903636754979518045886497078801", "price": "0.027", "size": "185.18", "side": "SELL", "hash": "575e11c838ccb258e5f9ea0157d56d08ad0f61d3", "best_bid": "0.002", "best_ask": "0.003"}, {"asset_id": "38409601990353197105461643021341338172518659365214781641813884172364820064219", "price": "0.973", "size": "185.18", "side": "BUY", "hash": "1f04020e8900ad84d3146c5c2bd1c4718ba63c3a", "best_bid": "0.997", "best_ask": "0.998"}], "timestamp": "1769384523721", "event_type": "price_change"}}
{"_local_timestamp": "2026-01-25T23:42:03.878796+00:00", "data": {"market": "0xcfe8947073d9333a6f767ed0c46713361aa4c34f75b35f1636622210356b2ba4", "price_changes": [{"asset_id": "21753818038149716958441586952364965978994113536903636754979518045886497078801", "price": "0.598", "size": "30.08", "side": "SELL", "hash": "182ba6c107b955e2c90fd59fe9a58b3f0818ee2d", "best_bid": "0.002", "best_ask": "0.003"}, {"asset_id": "38409601990353197105461643021341338172518659365214781641813884172364820064219", "price": "0.402", "size": "30.08", "side": "BUY", "hash": "588415e4d50addc694637b56648f7f6a6f593611", "best_bid": "0.997", "best_ask": "0.998"}], "timestamp": "1769384523803", "event_type": "price_change"}}
{"_local_timestamp": "2026-01-25T23:42:03.960109+00:00", "data": {"market": "0xcfe8947073d9333a6f767ed0c46713361aa4c34f75b35f1636622210356b2ba4", "price_changes": [{"asset_id": "21753818038149716958441586952364965978994113536903636754979518045886497078801", "price": "0.699", "size": "1618.39", "side": "SELL", "hash": "63695a290b5dd3a6e55724ddd0c3a24fee5bf206", "best_bid": "0.002", "best_ask": "0.003"}, {"asset_id": "38409601990353197105461643021341338172518659365214781641813884172364820064219", "price": "0.301", "size": "1618.39", "side": "BUY", "hash": "f76f458e488ce42ecc9c5ab9cc77f9727aeb00b1", "best_bid": "0.997", "best_ask": "0.998"}], "timestamp": "1769384523886", "event_type": "price_change"}}
{"_local_timestamp": "2026-01-25T23:42:15.113882+00:00", "data": {"market": "0x33825080bc810aa756a361298627cdf64d58dbd651a647bd0a29b8a68a7308fe", "price_changes": [{"asset_id": "27476096571833974040484538127433399463608736639971094747870629065388427932028", "price": "0.119", "size": "7000", "side": "SELL", "hash": "565ad76c0f343474d984ae86d98d109b6b3fb352", "best_bid": "0.034", "best_ask": "0.04"}, {"asset_id": "108112487379868796554191891208463687446351004748640934416300530966194496905118", "price": "0.881", "size": "7000", "side": "BUY", "hash": "d5a47b4877d15967b98793e03a9e706aade58b0e", "best_bid": "0.96", "best_ask": "0.966"}], "timestamp": "1769384535000", "event_type": "price_change"}}
{"_local_timestamp": "2026-01-25T23:42:19.435702+00:00", "data": {"market": "0xddda6004eefcf0ab8f542faa9856efec647d63bbbe70feb4c5dca376df32e8d7", "price_changes": [{"asset_id": "105357237982191656127719049458930828486417245494585420518830232261954691323810", "price": "0.002", "size": "250", "side": "BUY", "hash": "8ca63041d545939ee29c591c9efbcba1bf3f8274", "best_bid": "0.005", "best_ask": "0.007"}, {"asset_id": "60727132855373489262818696860770549261966005006541840363443788706996682318728", "price": "0.998", "size": "250", "side": "SELL", "hash": "f8689a3e9d635aee4f2476c6a50bef1dc60533ef", "best_bid": "0.993", "best_ask": "0.995"}], "timestamp": "1769384539347", "event_type": "price_change"}}
{"_local_timestamp": "2026-01-25T23:42:19.442563+00:00", "data": {"market": "0xddda6004eefcf0ab8f542faa9856efec647d63bbbe70feb4c5dca376df32e8d7", "price_changes": [{"asset_id": "105357237982191656127719049458930828486417245494585420518830232261954691323810", "price": "0.003", "size": "1000", "side": "BUY", "hash": "8ca63041d545939ee29c591c9efbcba1bf3f8274", "best_bid": "0.005", "best_ask": "0.007"}, {"asset_id": "60727132855373489262818696860770549261966005006541840363443788706996682318728", "price": "0.997", "size": "1000", "side": "SELL", "hash": "f8689a3e9d635aee4f2476c6a50bef1dc60533ef", "best_bid": "0.993", "best_ask": "0.995"}], "timestamp": "1769384539347", "event_type": "price_change"}}
{"_local_timestamp": "2026-01-25T23:42:19.443312+00:00", "data": {"market": "0xddda6004eefcf0ab8f542faa9856efec647d63bbbe70feb4c5dca376df32e8d7", "price_changes": [{"asset_id": "105357237982191656127719049458930828486417245494585420518830232261954691323810", "price": "0.004", "size": "1437.05", "side": "BUY", "hash": "8ca63041d545939ee29c591c9efbcba1bf3f8274", "best_bid": "0.005", "best_ask": "0.007"}, {"asset_id": "60727132855373489262818696860770549261966005006541840363443788706996682318728", "price": "0.996", "size": "1437.05", "side": "SELL", "hash": "f8689a3e9d635aee4f2476c6a50bef1dc60533ef", "best_bid": "0.993", "best_ask": "0.995"}], "timestamp": "1769384539347", "event_type": "price_change"}}
{"_local_timestamp": "2026-01-25T23:42:20.155450+00:00", "data": {"market": "0xddda6004eefcf0ab8f542faa9856efec647d63bbbe70feb4c5dca376df32e8d7", "price_changes": [{"asset_id": "105357237982191656127719049458930828486417245494585420518830232261954691323810", "price": "0.002", "size": "417.5", "side": "BUY", "hash": "eaa264231499a331cb537c25036be62de367cc64", "best_bid": "0.005", "best_ask": "0.007"}, {"asset_id": "60727132855373489262818696860770549261966005006541840363443788706996682318728", "price": "0.998", "size": "417.5", "side": "SELL", "hash": "08e51b3d47046bd97cd6e6a380a22a752372cae9", "best_bid": "0.993", "best_ask": "0.995"}], "timestamp": "1769384540028", "event_type": "price_change"}}
{"_local_timestamp": "2026-01-25T23:42:20.156110+00:00", "data": {"market": "0xddda6004eefcf0ab8f542faa9856efec647d63bbbe70feb4c5dca376df32e8d7", "price_changes": [{"asset_id": "105357237982191656127719049458930828486417245494585420518830232261954691323810", "price": "0.004", "size": "1519.96", "side": "BUY", "hash": "e87f5d84dee313cdd2ca538165f93a98cc55da7c", "best_bid": "0.005", "best_ask": "0.007"}, {"asset_id": "60727132855373489262818696860770549261966005006541840363443788706996682318728", "price": "0.996", "size": "1519.96", "side": "SELL", "hash": "40433267854bd3a7a2aa35e84fe69a903326dacc", "best_bid": "0.993", "best_ask": "0.995"}], "timestamp": "1769384540029", "event_type": "price_change"}}
{"_local_timestamp": "2026-01-25T23:42:20.156598+00:00", "data": {"market": "0xddda6004eefcf0ab8f542faa9856efec647d63bbbe70feb4c5dca376df32e8d7", "price_changes": [{"asset_id": "105357237982191656127719049458930828486417245494585420518830232261954691323810", "price": "0.003", "size": "1111.11", "side": "BUY", "hash": "b4cdc86e95e53e1008fa9c138d2b54d0442e0a90", "best_bid": "0.005", "best_ask": "0.007"}, {"asset_id": "60727132855373489262818696860770549261966005006541840363443788706996682318728", "price": "0.997", "size": "1111.11", "side": "SELL", "hash": "e89cb3e6691c2e5f3343fd84bee27873c4316bb0", "best_bid": "0.993", "best_ask": "0.995"}], "timestamp": "1769384540030", "event_type": "price_change"}}
{"_local_timestamp": "2026-01-25T23:42:21.954606+00:00", "data": {"market": "0x33825080bc810aa756a361298627cdf64d58dbd651a647bd0a29b8a68a7308fe", "price_changes": [{"asset_id": "27476096571833974040484538127433399463608736639971094747870629065388427932028", "price": "0.003", "size": "32.09", "side": "BUY", "hash": "dd874365f1d5489f91536fdc3e57d0081e396fdc", "best_bid": "0.034", "best_ask": "0.04"}, {"asset_id": "108112487379868796554191891208463687446351004748640934416300530966194496905118", "price": "0.997", "size": "32.09", "side": "SELL", "hash": "4fa135140b956ec7aaa2f74e22617455c8b04989", "best_bid": "0.96", "best_ask": "0.966"}], "timestamp": "1769384541792", "event_type": "price_change"}}
{"_local_timestamp": "2026-01-25T23:42:22.324170+00:00", "data": {"market": "0x33825080bc810aa756a361298627cdf64d58dbd651a647bd0a29b8a68a7308fe", "price_changes": [{"asset_id": "27476096571833974040484538127433399463608736639971094747870629065388427932028", "price": "0.003", "size": "54.15", "side": "BUY", "hash": "79809994a87e5136b0d773fe5701c6ae6daba51e", "best_bid": "0.034", "best_ask": "0.04"}, {"asset_id": "108112487379868796554191891208463687446351004748640934416300530966194496905118", "price": "0.997", "size": "54.15", "side": "SELL", "hash": "6b79d1c643ccb457fc599a237c8c4edd31a72946", "best_bid": "0.96", "best_ask": "0.966"}], "timestamp": "1769384542175", "event_type": "price_change"}}
{"_local_timestamp": "2026-01-25T23:43:12.994344+00:00", "data": {"market": "0x0edc31cc586c65726249da0c698ce2b0dc3acac65a7b96574b7a8a89321ecf9e", "price_changes": [{"asset_id": "86948609484193076545604092003532216745788551371556780169247204971522981358794", "price": "0.018", "size": "0", "side": "BUY", "hash": "47145f78965eaeb707c1057c620cd5b8879b02b2", "best_bid": "0.02", "best_ask": "0.026"}, {"asset_id": "40204010519879025056259875406560264981469631264230376751093889691606763270485", "price": "0.982", "size": "0", "side": "SELL", "hash": "508678f26f0209fa9aa449d4b8e5a464c52c63dc", "best_bid": "0.974", "best_ask": "0.98"}], "timestamp": "1769384592868", "event_type": "price_change"}}
{"_local_timestamp": "2026-01-25T23:43:13.448946+00:00", "data": {"market": "0x0edc31cc586c65726249da0c698ce2b0dc3acac65a7b96574b7a8a89321ecf9e", "price_changes": [{"asset_id": "86948609484193076545604092003532216745788551371556780169247204971522981358794", "price": "0.017", "size": "100", "side": "BUY", "hash": "112c38b8d7218b7bd85a8c9748da24eecf9c1b85", "best_bid": "0.02", "best_ask": "0.026"}, {"asset_id": "40204010519879025056259875406560264981469631264230376751093889691606763270485", "price": "0.983", "size": "100", "side": "SELL", "hash": "8137326516da88f1523956ce5ccf9925b24717d8", "best_bid": "0.974", "best_ask": "0.98"}], "timestamp": "1769384593150", "event_type": "price_change"}}
{"_local_timestamp": "2026-01-25T23:43:13.478917+00:00", "data": {"market": "0x0edc31cc586c65726249da0c698ce2b0dc3acac65a7b96574b7a8a89321ecf9e", "price_changes": [{"asset_id": "86948609484193076545604092003532216745788551371556780169247204971522981358794", "price": "0.015", "size": "10.95", "side": "BUY", "hash": "3a0b7747c146f24f45ef5616df326370a0b3c011", "best_bid": "0.02", "best_ask": "0.026"}, {"asset_id": "40204010519879025056259875406560264981469631264230376751093889691606763270485", "price": "0.985", "size": "10.95", "side": "SELL", "hash": "2c752b17e3e646590966c1b68a8a75272d389286", "best_bid": "0.974", "best_ask": "0.98"}], "timestamp": "1769384593180", "event_type": "price_change"}}
{"_local_timestamp": "2026-01-25T23:43:13.479670+00:00", "data": {"market": "0x0edc31cc586c65726249da0c698ce2b0dc3acac65a7b96574b7a8a89321ecf9e", "price_changes": [{"asset_id": "86948609484193076545604092003532216745788551371556780169247204971522981358794", "price": "0.017", "size": "378", "side": "BUY", "hash": "9585ec1c6a5b71a1f5b6a8a4ec61518a7d7cdd81", "best_bid": "0.02", "best_ask": "0.026"}, {"asset_id": "40204010519879025056259875406560264981469631264230376751093889691606763270485", "price": "0.983", "size": "378", "side": "SELL", "hash": "b4e09997001fa3bea98c7ccad18d34c073aa298b", "best_bid": "0.974", "best_ask": "0.98"}], "timestamp": "1769384593208", "event_type": "price_change"}}
{"_local_timestamp": "2026-01-25T23:43:15.289201+00:00", "data": {"market": "0x0edc31cc586c65726249da0c698ce2b0dc3acac65a7b96574b7a8a89321ecf9e", "price_changes": [{"asset_id": "86948609484193076545604092003532216745788551371556780169247204971522981358794", "price": "0.002", "size": "5520.04", "side": "BUY", "hash": "810273efce00d1683b47fd90eedffbb379c0d3bf", "best_bid": "0.02", "best_ask": "0.026"}, {"asset_id": "40204010519879025056259875406560264981469631264230376751093889691606763270485", "price": "0.998", "size": "5520.04", "side": "SELL", "hash": "4832cc66a0b78f70933c35975f2c77c6a3f9563b", "best_bid": "0.974", "best_ask": "0.98"}], "timestamp": "1769384595146", "event_type": "price_change"}}
{"_local_timestamp": "2026-01-25T23:43:15.289944+00:00", "data": {"market": "0x0edc31cc586c65726249da0c698ce2b0dc3acac65a7b96574b7a8a89321ecf9e", "price_changes": [{"asset_id": "86948609484193076545604092003532216745788551371556780169247204971522981358794", "price": "0.011", "size": "1025.76", "side": "BUY", "hash": "c26c3f52d592720ffdfd6246799d2dc66e75980f", "best_bid": "0.02", "best_ask": "0.026"}, {"asset_id": "40204010519879025056259875406560264981469631264230376751093889691606763270485", "price": "0.989", "size": "1025.76", "side": "SELL", "hash": "b4bb9913ab3d4a70881fea4ddb6bef6f90195b8f", "best_bid": "0.974", "best_ask": "0.98"}], "timestamp": "1769384595146", "event_type": "price_change"}}
{"_local_timestamp": "2026-01-25T23:43:15.290473+00:00", "data": {"market": "0x0edc31cc586c65726249da0c698ce2b0dc3acac65a7b96574b7a8a89321ecf9e", "price_changes": [{"asset_id": "86948609484193076545604092003532216745788551371556780169247204971522981358794", "price": "0.018", "size": "389", "side": "BUY", "hash": "fec7bd36d2447a87448df4ca81693108fdd260dd", "best_bid": "0.02", "best_ask": "0.026"}, {"asset_id": "40204010519879025056259875406560264981469631264230376751093889691606763270485", "price": "0.982", "size": "389", "side": "SELL", "hash": "766beb7e88267bcbdd734d71c865317b787bb2d5", "best_bid": "0.974", "best_ask": "0.98"}], "timestamp": "1769384595147", "event_type": "price_change"}}
{"_local_timestamp": "2026-01-25T23:43:15.308998+00:00", "data": {"market": "0x0edc31cc586c65726249da0c698ce2b0dc3acac65a7b96574b7a8a89321ecf9e", "price_changes": [{"asset_id": "86948609484193076545604092003532216745788551371556780169247204971522981358794", "price": "0.017", "size": "100", "side": "BUY", "hash": "5cd651f73444cbe8f6c3aeeb724648742eac4b24", "best_bid": "0.02", "best_ask": "0.026"}, {"asset_id": "40204010519879025056259875406560264981469631264230376751093889691606763270485", "price": "0.983", "size": "100", "side": "SELL", "hash": "43308c54b672c119ed0a786c25b8d6fdc8e78789", "best_bid": "0.974", "best_ask": "0.98"}], "timestamp": "1769384595171", "event_type": "price_change"}}
{"_local_timestamp": "2026-01-25T23:43:15.336500+00:00", "data": {"market": "0x0edc31cc586c65726249da0c698ce2b0dc3acac65a7b96574b7a8a89321ecf9e", "price_changes": [{"asset_id": "86948609484193076545604092003532216745788551371556780169247204971522981358794", "price": "0.019", "size": "176.4", "side": "BUY", "hash": "b2accf8f8bd73bead982344eae49c95fe8e6d606", "best_bid": "0.02", "best_ask": "0.026"}, {"asset_id": "40204010519879025056259875406560264981469631264230376751093889691606763270485", "price": "0.981", "size": "176.4", "side": "SELL", "hash": "d640ba8587e0e5bdbde208e6798e7ff5a5ccf2e5", "best_bid": "0.974", "best_ask": "0.98"}], "timestamp": "1769384595199", "event_type": "price_change"}}
{"_local_timestamp": "2026-01-25T23:43:17.165545+00:00", "data": {"market": "0x0edc31cc586c65726249da0c698ce2b0dc3acac65a7b96574b7a8a89321ecf9e", "price_changes": [{"asset_id": "86948609484193076545604092003532216745788551371556780169247204971522981358794", "price": "0.002", "size": "4520.04", "side": "BUY", "hash": "09a3248accecdfc535a42d16f2eb18ad8ca60c87", "best_bid": "0.02", "best_ask": "0.026"}, {"asset_id": "40204010519879025056259875406560264981469631264230376751093889691606763270485", "price": "0.998", "size": "4520.04", "side": "SELL", "hash": "2fec6d097d7a528dbe3d3d1dc4d0c06ee1804463", "best_bid": "0.974", "best_ask": "0.98"}], "timestamp": "1769384597024", "event_type": "price_change"}}
{"_local_timestamp": "2026-01-25T23:43:17.166202+00:00", "data": {"market": "0x0edc31cc586c65726249da0c698ce2b0dc3acac65a7b96574b7a8a89321ecf9e", "price_changes": [{"asset_id": "86948609484193076545604092003532216745788551371556780169247204971522981358794", "price": "0.011", "size": "843.76", "side": "BUY", "hash": "09a3248accecdfc535a42d16f2eb18ad8ca60c87", "best_bid": "0.02", "best_ask": "0.026"}, {"asset_id": "40204010519879025056259875406560264981469631264230376751093889691606763270485", "price": "0.989", "size": "843.76", "side": "SELL", "hash": "2fec6d097d7a528dbe3d3d1dc4d0c06ee1804463", "best_bid": "0.974", "best_ask": "0.98"}], "timestamp": "1769384597024", "event_type": "price_change"}}
{"_local_timestamp": "2026-01-25T23:43:17.166750+00:00", "data": {"market": "0x0edc31cc586c65726249da0c698ce2b0dc3acac65a7b96574b7a8a89321ecf9e", "price_changes": [{"asset_id": "86948609484193076545604092003532216745788551371556780169247204971522981358794", "price": "0.018", "size": "0", "side": "BUY", "hash": "09a3248accecdfc535a42d16f2eb18ad8ca60c87", "best_bid": "0.02", "best_ask": "0.026"}, {"asset_id": "40204010519879025056259875406560264981469631264230376751093889691606763270485", "price": "0.982", "size": "0", "side": "SELL", "hash": "2fec6d097d7a528dbe3d3d1dc4d0c06ee1804463", "best_bid": "0.974", "best_ask": "0.98"}], "timestamp": "1769384597024", "event_type": "price_change"}}
{"_local_timestamp": "2026-01-25T23:43:17.221842+00:00", "data": {"market": "0x0edc31cc586c65726249da0c698ce2b0dc3acac65a7b96574b7a8a89321ecf9e", "price_changes": [{"asset_id": "86948609484193076545604092003532216745788551371556780169247204971522981358794", "price": "0.019", "size": "6.4", "side": "BUY", "hash": "f95d1d6bf4222fddbec9ef39ae7d22957d2ed636", "best_bid": "0.02", "best_ask": "0.026"}, {"asset_id": "40204010519879025056259875406560264981469631264230376751093889691606763270485", "price": "0.981", "size": "6.4", "side": "SELL", "hash": "a0f586601ea84ed32f1977cd6f6540ec54ffac4c", "best_bid": "0.974", "best_ask": "0.98"}], "timestamp": "1769384597097", "event_type": "price_change"}}
{"_local_timestamp": "2026-01-25T23:43:17.244479+00:00", "data": {"market": "0x0edc31cc586c65726249da0c698ce2b0dc3acac65a7b96574b7a8a89321ecf9e", "price_changes": [{"asset_id": "86948609484193076545604092003532216745788551371556780169247204971522981358794", "price": "0.017", "size": "378", "side": "BUY", "hash": "52a1e2992d4e75cde05047e273c73415a747f0dd", "best_bid": "0.02", "best_ask": "0.026"}, {"asset_id": "40204010519879025056259875406560264981469631264230376751093889691606763270485", "price": "0.983", "size": "378", "side": "SELL", "hash": "78d2da57aee24fe61812368e00e000ce732cf46d", "best_bid": "0.974", "best_ask": "0.98"}], "timestamp": "1769384597124", "event_type": "price_change"}}
{"_local_timestamp": "2026-01-25T23:43:19.174069+00:00", "data": {"market": "0x0edc31cc586c65726249da0c698ce2b0dc3acac65a7b96574b7a8a89321ecf9e", "price_changes": [{"asset_id": "86948609484193076545604092003532216745788551371556780169247204971522981358794", "price": "0.018", "size": "389", "side": "BUY", "hash": "a59b34e5695271a9cb11447f980158c41f816a18", "best_bid": "0.02", "best_ask": "0.026"}, {"asset_id": "40204010519879025056259875406560264981469631264230376751093889691606763270485", "price": "0.982", "size": "389", "side": "SELL", "hash": "1f6a0141f652c2e69d12cd95f9146be95bcf37b9", "best_bid": "0.974", "best_ask": "0.98"}], "timestamp": "1769384599005", "event_type": "price_change"}}
{"_local_timestamp": "2026-01-25T23:43:19.175089+00:00", "data": {"market": "0x0edc31cc586c65726249da0c698ce2b0dc3acac65a7b96574b7a8a89321ecf9e", "price_changes": [{"asset_id": "86948609484193076545604092003532216745788551371556780169247204971522981358794", "price": "0.011", "size": "1025.76", "side": "BUY", "hash": "4c38f6b0409c45aabb01d2de58405363f11832ce", "best_bid": "0.02", "best_ask": "0.026"}, {"asset_id": "40204010519879025056259875406560264981469631264230376751093889691606763270485", "price": "0.989", "size": "1025.76", "side": "SELL", "hash": "67d93ceb7cd587668a1b768640189efaf010a5ba", "best_bid": "0.974", "best_ask": "0.98"}], "timestamp": "1769384599006", "event_type": "price_change"}}
{"_local_timestamp": "2026-01-25T23:43:19.175701+00:00", "data": {"market": "0x0edc31cc586c65726249da0c698ce2b0dc3acac65a7b96574b7a8a89321ecf9e", "price_changes": [{"asset_id": "86948609484193076545604092003532216745788551371556780169247204971522981358794", "price": "0.002", "size": "5520.04", "side": "BUY", "hash": "df44b2cc79af6f4314ed692fa15ced615618bc2d", "best_bid": "0.02", "best_ask": "0.026"}, {"asset_id": "40204010519879025056259875406560264981469631264230376751093889691606763270485", "price": "0.998", "size": "5520.04", "side": "SELL", "hash": "390fecc389fd92b3e3ba8500b1cce79fec98274d", "best_bid": "0.974", "best_ask": "0.98"}], "timestamp": "1769384599007", "event_type": "price_change"}}
{"_local_timestamp": "2026-01-25T23:43:19.198623+00:00", "data": {"market": "0x0edc31cc586c65726249da0c698ce2b0dc3acac65a7b96574b7a8a89321ecf9e", "price_changes": [{"asset_id": "86948609484193076545604092003532216745788551371556780169247204971522981358794", "price": "0.017", "size": "100", "side": "BUY", "hash": "efd2e5c2fa34ce05c8bfe23988750ade1685bc18", "best_bid": "0.02", "best_ask": "0.026"}, {"asset_id": "40204010519879025056259875406560264981469631264230376751093889691606763270485", "price": "0.983", "size": "100", "side": "SELL", "hash": "99c8859c6499e49247cc3670d1767e8244eab307", "best_bid": "0.974", "best_ask": "0.98"}], "timestamp": "1769384599067", "event_type": "price_change"}}
{"_local_timestamp": "2026-01-25T23:43:19.224415+00:00", "data": {"market": "0x0edc31cc586c65726249da0c698ce2b0dc3acac65a7b96574b7a8a89321ecf9e", "price_changes": [{"asset_id": "86948609484193076545604092003532216745788551371556780169247204971522981358794", "price": "0.019", "size": "176.4", "side": "BUY", "hash": "35f8fb33681465565b784f1d81de42b0ebbccc9f", "best_bid": "0.02", "best_ask": "0.026"}, {"asset_id": "40204010519879025056259875406560264981469631264230376751093889691606763270485", "price": "0.981", "size": "176.4", "side": "SELL", "hash": "877ab5a44569a55071c1071d4b99743159c67e04", "best_bid": "0.974", "best_ask": "0.98"}], "timestamp": "1769384599095", "event_type": "price_change"}}
{"_local_timestamp": "2026-01-25T23:43:19.584592+00:00", "data": {"market": "0xcfe8947073d9333a6f767ed0c46713361aa4c34f75b35f1636622210356b2ba4", "price_changes": [{"asset_id": "21753818038149716958441586952364965978994113536903636754979518045886497078801", "price": "0.028", "size": "0", "side": "SELL", "hash": "049d94ef8dbd178af277364051a5513d4c1fb58e", "best_bid": "0.002", "best_ask": "0.003"}, {"asset_id": "38409601990353197105461643021341338172518659365214781641813884172364820064219", "price": "0.972", "size": "0", "side": "BUY", "hash": "ba11f064a9c0a723d33d9f40c6f30226a1475f51", "best_bid": "0.997", "best_ask": "0.998"}], "timestamp": "1769384599456", "event_type": "price_change"}}
{"_local_timestamp": "2026-01-25T23:43:19.744564+00:00", "data": {"market": "0xcfe8947073d9333a6f767ed0c46713361aa4c34f75b35f1636622210356b2ba4", "price_changes": [{"asset_id": "21753818038149716958441586952364965978994113536903636754979518045886497078801", "price": "0.014", "size": "363.65", "side": "SELL", "hash": "3030c715e8f9fb522e879dc5d5bd4d817948f1c2", "best_bid": "0.002", "best_ask": "0.003"}, {"asset_id": "38409601990353197105461643021341338172518659365214781641813884172364820064219", "price": "0.986", "size": "363.65", "side": "BUY", "hash": "67f2564353a0c820b9164b2a460e71af6b54942d", "best_bid": "0.997", "best_ask": "0.998"}], "timestamp": "1769384599623", "event_type": "price_change"}}
{"_local_timestamp": "2026-01-25T23:43:21.011513+00:00", "data": {"market": "0x0edc31cc586c65726249da0c698ce2b0dc3acac65a7b96574b7a8a89321ecf9e", "price_changes": [{"asset_id": "86948609484193076545604092003532216745788551371556780169247204971522981358794", "price": "0.018", "size": "0", "side": "BUY", "hash": "1e6ef34a5d0d46a1852863718a024cc4c78bbb9a", "best_bid": "0.02", "best_ask": "0.026"}, {"asset_id": "40204010519879025056259875406560264981469631264230376751093889691606763270485", "price": "0.982", "size": "0", "side": "SELL", "hash": "22ce5da481b855abeecc60475b69602ae8a70042", "best_bid": "0.974", "best_ask": "0.98"}], "timestamp": "1769384600884", "event_type": "price_change"}}
{"_local_timestamp": "2026-01-25T23:43:21.019593+00:00", "data": {"market": "0x0edc31cc586c65726249da0c698ce2b0dc3acac65a7b96574b7a8a89321ecf9e", "price_changes": [{"asset_id": "86948609484193076545604092003532216745788551371556780169247204971522981358794", "price": "0.011", "size": "843.76", "side": "BUY", "hash": "1e6ef34a5d0d46a1852863718a024cc4c78bbb9a", "best_bid": "0.02", "best_ask": "0.026"}, {"asset_id": "40204010519879025056259875406560264981469631264230376751093889691606763270485", "price": "0.989", "size": "843.76", "side": "SELL", "hash": "22ce5da481b855abeecc60475b69602ae8a70042", "best_bid": "0.974", "best_ask": "0.98"}], "timestamp": "1769384600884", "event_type": "price_change"}}
{"_local_timestamp": "2026-01-25T23:43:21.020326+00:00", "data": {"market": "0x0edc31cc586c65726249da0c698ce2b0dc3acac65a7b96574b7a8a89321ecf9e", "price_changes": [{"asset_id": "86948609484193076545604092003532216745788551371556780169247204971522981358794", "price": "0.002", "size": "4520.04", "side": "BUY", "hash": "1e6ef34a5d0d46a1852863718a024cc4c78bbb9a", "best_bid": "0.02", "best_ask": "0.026"}, {"asset_id": "40204010519879025056259875406560264981469631264230376751093889691606763270485", "price": "0.998", "size": "4520.04", "side": "SELL", "hash": "22ce5da481b855abeecc60475b69602ae8a70042", "best_bid": "0.974", "best_ask": "0.98"}], "timestamp": "1769384600884", "event_type": "price_change"}}
{"_local_timestamp": "2026-01-25T23:43:21.052536+00:00", "data": {"market": "0x0edc31cc586c65726249da0c698ce2b0dc3acac65a7b96574b7a8a89321ecf9e", "price_changes": [{"asset_id": "86948609484193076545604092003532216745788551371556780169247204971522981358794", "price": "0.019", "size": "6.4", "side": "BUY", "hash": "411062fe59f54e770d026162c2b52fe0934dac5a", "best_bid": "0.02", "best_ask": "0.026"}, {"asset_id": "40204010519879025056259875406560264981469631264230376751093889691606763270485", "price": "0.981", "size": "6.4", "side": "SELL", "hash": "f92e5bbfda94c79340397ea84fc28384ab564ab9", "best_bid": "0.974", "best_ask": "0.98"}], "timestamp": "1769384600915", "event_type": "price_change"}}
{"_local_timestamp": "2026-01-25T23:43:21.080138+00:00", "data": {"market": "0x0edc31cc586c65726249da0c698ce2b0dc3acac65a7b96574b7a8a89321ecf9e", "price_changes": [{"asset_id": "86948609484193076545604092003532216745788551371556780169247204971522981358794", "price": "0.017", "size": "378", "side": "BUY", "hash": "d5bb7c0172d94be4f89647710106c31d0b48e1dc", "best_bid": "0.02", "best_ask": "0.026"}, {"asset_id": "40204010519879025056259875406560264981469631264230376751093889691606763270485", "price": "0.983", "size": "378", "side": "SELL", "hash": "a92bf2758978d3363c5416ec5927d40a7fea6524", "best_bid": "0.974", "best_ask": "0.98"}], "timestamp": "1769384600942", "event_type": "price_change"}}
{"_local_timestamp": "2026-01-25T23:43:22.419343+00:00", "data": {"market": "0x0edc31cc586c65726249da0c698ce2b0dc3acac65a7b96574b7a8a89321ecf9e", "price_changes": [{"asset_id": "86948609484193076545604092003532216745788551371556780169247204971522981358794", "price": "0.011", "size": "1025.76", "side": "BUY", "hash": "8988b324a170680ee32b539580e959c0e8cf42b7", "best_bid": "0.02", "best_ask": "0.026"}, {"asset_id": "40204010519879025056259875406560264981469631264230376751093889691606763270485", "price": "0.989", "size": "1025.76", "side": "SELL", "hash": "5fa3cb96874b31ccbf46c8636448a54e2833da2c", "best_bid": "0.974", "best_ask": "0.98"}], "timestamp": "1769384602293", "event_type": "price_change"}}
{"_local_timestamp": "2026-01-25T23:43:22.420190+00:00", "data": {"market": "0x0edc31cc586c65726249da0c698ce2b0dc3acac65a7b96574b7a8a89321ecf9e", "price_changes": [{"asset_id": "86948609484193076545604092003532216745788551371556780169247204971522981358794", "price": "0.002", "size": "5520.04", "side": "BUY", "hash": "9d2fbfc15516bf5e0101a03603adca6acd59c41f", "best_bid": "0.02", "best_ask": "0.026"}, {"asset_id": "40204010519879025056259875406560264981469631264230376751093889691606763270485", "price": "0.998", "size": "5520.04", "side": "SELL", "hash": "b109a090e7fc3dab3672f7cbb1d5028d02f66c95", "best_bid": "0.974", "best_ask": "0.98"}], "timestamp": "1769384602294", "event_type": "price_change"}}
{"_local_timestamp": "2026-01-25T23:43:22.420878+00:00", "data": {"market": "0x0edc31cc586c65726249da0c698ce2b0dc3acac65a7b96574b7a8a89321ecf9e", "price_changes": [{"asset_id": "86948609484193076545604092003532216745788551371556780169247204971522981358794", "price": "0.018", "size": "389", "side": "BUY", "hash": "428f148cc364107650491499b545d57c2e018d23", "best_bid": "0.02", "best_ask": "0.026"}, {"asset_id": "40204010519879025056259875406560264981469631264230376751093889691606763270485", "price": "0.982", "size": "389", "side": "SELL", "hash": "262260619f6a80ca0ca5e2af54a815934f9ad46e", "best_bid": "0.974", "best_ask": "0.98"}], "timestamp": "1769384602294", "event_type": "price_change"}}
{"_local_timestamp": "2026-01-25T23:43:22.448821+00:00", "data": {"market": "0x0edc31cc586c65726249da0c698ce2b0dc3acac65a7b96574b7a8a89321ecf9e", "price_changes": [{"asset_id": "86948609484193076545604092003532216745788551371556780169247204971522981358794", "price": "0.017", "size": "100", "side": "BUY", "hash": "5dba47781713833d944f9ca89cc6c4367a34b09b", "best_bid": "0.02", "best_ask": "0.026"}, {"asset_id": "40204010519879025056259875406560264981469631264230376751093889691606763270485", "price": "0.983", "size": "100", "side": "SELL", "hash": "83b591c8683590b4b9c5f7e4bb54085bed7ca1d8", "best_bid": "0.974", "best_ask": "0.98"}], "timestamp": "1769384602319", "event_type": "price_change"}}
{"_local_timestamp": "2026-01-25T23:43:22.490406+00:00", "data": {"market": "0x0edc31cc586c65726249da0c698ce2b0dc3acac65a7b96574b7a8a89321ecf9e", "price_changes": [{"asset_id": "86948609484193076545604092003532216745788551371556780169247204971522981358794", "price": "0.019", "size": "176.4", "side": "BUY", "hash": "4f481de7c3e71bcf9113f3534510213513f8131f", "best_bid": "0.02", "best_ask": "0.026"}, {"asset_id": "40204010519879025056259875406560264981469631264230376751093889691606763270485", "price": "0.981", "size": "176.4", "side": "SELL", "hash": "9d30ce3adfda6a5a54272379b17db4e85901981c", "best_bid": "0.974", "best_ask": "0.98"}], "timestamp": "1769384602349", "event_type": "price_change"}}
{"_local_timestamp": "2026-01-25T23:43:23.403545+00:00", "data": {"market": "0x0edc31cc586c65726249da0c698ce2b0dc3acac65a7b96574b7a8a89321ecf9e", "price_changes": [{"asset_id": "86948609484193076545604092003532216745788551371556780169247204971522981358794", "price": "0.011", "size": "843.76", "side": "BUY", "hash": "43044be5ebc2c08d7e599107277a55c680a0f846", "best_bid": "0.02", "best_ask": "0.026"}, {"asset_id": "40204010519879025056259875406560264981469631264230376751093889691606763270485", "price": "0.989", "size": "843.76", "side": "SELL", "hash": "d0a3b0e689e49cf955b5e4a991bb26248ceb6553", "best_bid": "0.974", "best_ask": "0.98"}], "timestamp": "1769384603267", "event_type": "price_change"}}
{"_local_timestamp": "2026-01-25T23:43:23.404363+00:00", "data": {"market": "0x0edc31cc586c65726249da0c698ce2b0dc3acac65a7b96574b7a8a89321ecf9e", "price_changes": [{"asset_id": "86948609484193076545604092003532216745788551371556780169247204971522981358794", "price": "0.002", "size": "4520.04", "side": "BUY", "hash": "43044be5ebc2c08d7e599107277a55c680a0f846", "best_bid": "0.02", "best_ask": "0.026"}, {"asset_id": "40204010519879025056259875406560264981469631264230376751093889691606763270485", "price": "0.998", "size": "4520.04", "side": "SELL", "hash": "d0a3b0e689e49cf955b5e4a991bb26248ceb6553", "best_bid": "0.974", "best_ask": "0.98"}], "timestamp": "1769384603267", "event_type": "price_change"}}
{"_local_timestamp": "2026-01-25T23:43:23.404956+00:00", "data": {"market": "0x0edc31cc586c65726249da0c698ce2b0dc3acac65a7b96574b7a8a89321ecf9e", "price_changes": [{"asset_id": "86948609484193076545604092003532216745788551371556780169247204971522981358794", "price": "0.018", "size": "0", "side": "BUY", "hash": "43044be5ebc2c08d7e599107277a55c680a0f846", "best_bid": "0.02", "best_ask": "0.026"}, {"asset_id": "40204010519879025056259875406560264981469631264230376751093889691606763270485", "price": "0.982", "size": "0", "side": "SELL", "hash": "d0a3b0e689e49cf955b5e4a991bb26248ceb6553", "best_bid": "0.974", "best_ask": "0.98"}], "timestamp": "1769384603267", "event_type": "price_change"}}
{"_local_timestamp": "2026-01-25T23:43:23.628146+00:00", "data": {"market": "0x0edc31cc586c65726249da0c698ce2b0dc3acac65a7b96574b7a8a89321ecf9e", "price_changes": [{"asset_id": "86948609484193076545604092003532216745788551371556780169247204971522981358794", "price": "0.019", "size": "6.4", "side": "BUY", "hash": "0c6df6d9923717e6a6999cea4f450f1ad6e841dd", "best_bid": "0.02", "best_ask": "0.026"}, {"asset_id": "40204010519879025056259875406560264981469631264230376751093889691606763270485", "price": "0.981", "size": "6.4", "side": "SELL", "hash": "efbcb50d8fa23334d1d1c0551a11e6da1ebbc2f5", "best_bid": "0.974", "best_ask": "0.98"}], "timestamp": "1769384603521", "event_type": "price_change"}}
{"_local_timestamp": "2026-01-25T23:43:23.651365+00:00", "data": {"market": "0x0edc31cc586c65726249da0c698ce2b0dc3acac65a7b96574b7a8a89321ecf9e", "price_changes": [{"asset_id": "86948609484193076545604092003532216745788551371556780169247204971522981358794", "price": "0.017", "size": "378", "side": "BUY", "hash": "170b487dcba90d9add5a2b274eca87cee021f4aa", "best_bid": "0.02", "best_ask": "0.026"}, {"asset_id": "40204010519879025056259875406560264981469631264230376751093889691606763270485", "price": "0.983", "size": "378", "side": "SELL", "hash": "603e4e59dbdf04a8afea4d719131ca267c293c6a", "best_bid": "0.974", "best_ask": "0.98"}], "timestamp": "1769384603546", "event_type": "price_change"}}
{"_local_timestamp": "2026-01-25T23:43:25.643772+00:00", "data": {"market": "0x33825080bc810aa756a361298627cdf64d58dbd651a647bd0a29b8a68a7308fe", "price_changes": [{"asset_id": "27476096571833974040484538127433399463608736639971094747870629065388427932028", "price": "0.119", "size": "7043.3", "side": "SELL", "hash": "c561f3d2e66b57d0ec5e1d1bad1e64049cfb207b", "best_bid": "0.034", "best_ask": "0.04"}, {"asset_id": "108112487379868796554191891208463687446351004748640934416300530966194496905118", "price": "0.881", "size": "7043.3", "side": "BUY", "hash": "793492eccc25b00e03acbe77adaba40ad53c49e8", "best_bid": "0.96", "best_ask": "0.966"}], "timestamp": "1769384605528", "event_type": "price_change"}}
{"_local_timestamp": "2026-01-25T23:43:25.976426+00:00", "data": {"market": "0x0edc31cc586c65726249da0c698ce2b0dc3acac65a7b96574b7a8a89321ecf9e", "price_changes": [{"asset_id": "86948609484193076545604092003532216745788551371556780169247204971522981358794", "price": "0.002", "size": "5520.04", "side": "BUY", "hash": "cfaa290dc065999c7ca6fde7691aeb969d003e96", "best_bid": "0.02", "best_ask": "0.026"}, {"asset_id": "40204010519879025056259875406560264981469631264230376751093889691606763270485", "price": "0.998", "size": "5520.04", "side": "SELL", "hash": "1b73456fc768850329a7fb70caa80fa5abc67fef", "best_bid": "0.974", "best_ask": "0.98"}], "timestamp": "1769384605869", "event_type": "price_change"}}
{"_local_timestamp": "2026-01-25T23:43:25.978018+00:00", "data": {"market": "0x0edc31cc586c65726249da0c698ce2b0dc3acac65a7b96574b7a8a89321ecf9e", "price_changes": [{"asset_id": "86948609484193076545604092003532216745788551371556780169247204971522981358794", "price": "0.018", "size": "389", "side": "BUY", "hash": "2c68577b70113e34a82140225cf296297ea4ffab", "best_bid": "0.02", "best_ask": "0.026"}, {"asset_id": "40204010519879025056259875406560264981469631264230376751093889691606763270485", "price": "0.982", "size": "389", "side": "SELL", "hash": "c7c78ae47acacf61f1a073b72e7fe335270e1ecc", "best_bid": "0.974", "best_ask": "0.98"}], "timestamp": "1769384605870", "event_type": "price_change"}}
{"_local_timestamp": "2026-01-25T23:43:25.978716+00:00", "data": {"market": "0x0edc31cc586c65726249da0c698ce2b0dc3acac65a7b96574b7a8a89321ecf9e", "price_changes": [{"asset_id": "86948609484193076545604092003532216745788551371556780169247204971522981358794", "price": "0.011", "size": "1025.76", "side": "BUY", "hash": "90f0f0470c827eff86261eb0509504f41254c49e", "best_bid": "0.02", "best_ask": "0.026"}, {"asset_id": "40204010519879025056259875406560264981469631264230376751093889691606763270485", "price": "0.989", "size": "1025.76", "side": "SELL", "hash": "e1daf6e0a9ba86a7dec9f75bcd727dfe82d7cdf7", "best_bid": "0.974", "best_ask": "0.98"}], "timestamp": "1769384605871", "event_type": "price_change"}}
{"_local_timestamp": "2026-01-25T23:43:25.998864+00:00", "data": {"market": "0x0edc31cc586c65726249da0c698ce2b0dc3acac65a7b96574b7a8a89321ecf9e", "price_changes": [{"asset_id": "86948609484193076545604092003532216745788551371556780169247204971522981358794", "price": "0.017", "size": "100", "side": "BUY", "hash": "60e9b2307c0a2a195e53b24257fd52eb22566143", "best_bid": "0.02", "best_ask": "0.026"}, {"asset_id": "40204010519879025056259875406560264981469631264230376751093889691606763270485", "price": "0.983", "size": "100", "side": "SELL", "hash": "aae8e8845c22b9d13bdf0aaf3c80c57b8c07fb86", "best_bid": "0.974", "best_ask": "0.98"}], "timestamp": "1769384605895", "event_type": "price_change"}}
{"_local_timestamp": "2026-01-25T23:43:26.026625+00:00", "data": {"market": "0x0edc31cc586c65726249da0c698ce2b0dc3acac65a7b96574b7a8a89321ecf9e", "price_changes": [{"asset_id": "86948609484193076545604092003532216745788551371556780169247204971522981358794", "price": "0.019", "size": "176.4", "side": "BUY", "hash": "d0c6edf40a4e01784a12c2ace87fc734860cb513", "best_bid": "0.02", "best_ask": "0.026"}, {"asset_id": "40204010519879025056259875406560264981469631264230376751093889691606763270485", "price": "0.981", "size": "176.4", "side": "SELL", "hash": "b235d2382a09ddcbd771214bb7aab99d8cbb64d1", "best_bid": "0.974", "best_ask": "0.98"}], "timestamp": "1769384605922", "event_type": "price_change"}}
{"_local_timestamp": "2026-01-25T23:43:28.015314+00:00", "data": {"market": "0x0edc31cc586c65726249da0c698ce2b0dc3acac65a7b96574b7a8a89321ecf9e", "price_changes": [{"asset_id": "86948609484193076545604092003532216745788551371556780169247204971522981358794", "price": "0.002", "size": "4520.04", "side": "BUY", "hash": "4e03666cb8b8a48dc3c4286e68083a6c50ffc1e0", "best_bid": "0.02", "best_ask": "0.026"}, {"asset_id": "40204010519879025056259875406560264981469631264230376751093889691606763270485", "price": "0.998", "size": "4520.04", "side": "SELL", "hash": "e0f34fca5622293205ef5778cfcfe236fd803f68", "best_bid": "0.974", "best_ask": "0.98"}], "timestamp": "1769384607917", "event_type": "price_change"}}
{"_local_timestamp": "2026-01-25T23:43:28.016383+00:00", "data": {"market": "0x0edc31cc586c65726249da0c698ce2b0dc3acac65a7b96574b7a8a89321ecf9e", "price_changes": [{"asset_id": "86948609484193076545604092003532216745788551371556780169247204971522981358794", "price": "0.018", "size": "0", "side": "BUY", "hash": "4e03666cb8b8a48dc3c4286e68083a6c50ffc1e0", "best_bid": "0.02", "best_ask": "0.026"}, {"asset_id": "40204010519879025056259875406560264981469631264230376751093889691606763270485", "price": "0.982", "size": "0", "side": "SELL", "hash": "e0f34fca5622293205ef5778cfcfe236fd803f68", "best_bid": "0.974", "best_ask": "0.98"}], "timestamp": "1769384607917", "event_type": "price_change"}}
{"_local_timestamp": "2026-01-25T23:43:28.017023+00:00", "data": {"market": "0x0edc31cc586c65726249da0c698ce2b0dc3acac65a7b96574b7a8a89321ecf9e", "price_changes": [{"asset_id": "86948609484193076545604092003532216745788551371556780169247204971522981358794", "price": "0.011", "size": "843.76", "side": "BUY", "hash": "4e03666cb8b8a48dc3c4286e68083a6c50ffc1e0", "best_bid": "0.02", "best_ask": "0.026"}, {"asset_id": "40204010519879025056259875406560264981469631264230376751093889691606763270485", "price": "0.989", "size": "843.76", "side": "SELL", "hash": "e0f34fca5622293205ef5778cfcfe236fd803f68", "best_bid": "0.974", "best_ask": "0.98"}], "timestamp": "1769384607917", "event_type": "price_change"}}
{"_local_timestamp": "2026-01-25T23:43:28.033047+00:00", "data": {"market": "0x0edc31cc586c65726249da0c698ce2b0dc3acac65a7b96574b7a8a89321ecf9e", "price_changes": [{"asset_id": "86948609484193076545604092003532216745788551371556780169247204971522981358794", "price": "0.019", "size": "6.4", "side": "BUY", "hash": "caed1354e9a22e9ae5a7fd115c5a7fa47a61ac6c", "best_bid": "0.02", "best_ask": "0.026"}, {"asset_id": "40204010519879025056259875406560264981469631264230376751093889691606763270485", "price": "0.981", "size": "6.4", "side": "SELL", "hash": "b4c4f79268cab8f0f505f6e32af4801a6dcd6f9c", "best_bid": "0.974", "best_ask": "0.98"}], "timestamp": "1769384607942", "event_type": "price_change"}}
{"_local_timestamp": "2026-01-25T23:43:28.070374+00:00", "data": {"market": "0x0edc31cc586c65726249da0c698ce2b0dc3acac65a7b96574b7a8a89321ecf9e", "price_changes": [{"asset_id": "86948609484193076545604092003532216745788551371556780169247204971522981358794", "price": "0.017", "size": "378", "side": "BUY", "hash": "40cec6b5ec1710d9cbd88e8db65689516f25d306", "best_bid": "0.02", "best_ask": "0.026"}, {"asset_id": "40204010519879025056259875406560264981469631264230376751093889691606763270485", "price": "0.983", "size": "378", "side": "SELL", "hash": "eccb41823b8150fa659e0f107f0056f61f825a7c", "best_bid": "0.974", "best_ask": "0.98"}], "timestamp": "1769384607973", "event_type": "price_change"}}
{"_local_timestamp": "2026-01-25T23:43:28.927726+00:00", "data": {"market": "0x3d00e2266a6fce1d78d52dc99ad65a6e0b1d4b126608f9b57a57a9e64e14538b", "price_changes": [{"asset_id": "53186315788060762043972018184166502971471689613114984035234259092608911832812", "price": "0.021", "size": "0", "side": "BUY", "hash": "15381ae2d19369b7e14a7e7d42f11b8d6613a8f0", "best_bid": "0.041", "best_ask": "0.049"}, {"asset_id": "111295934648931540975810135936206324404031729488235714793836466636975428917888", "price": "0.979", "size": "0", "side": "SELL", "hash": "776abb18540a8f046899cfbc4a2e61410812d925", "best_bid": "0.951", "best_ask": "0.959"}], "timestamp": "1769384608783", "event_type": "price_change"}}
{"_local_timestamp": "2026-01-25T23:43:28.990655+00:00", "data": {"market": "0x3d00e2266a6fce1d78d52dc99ad65a6e0b1d4b126608f9b57a57a9e64e14538b", "price_changes": [{"asset_id": "53186315788060762043972018184166502971471689613114984035234259092608911832812", "price": "0.035", "size": "18", "side": "BUY", "hash": "52dd272ea203a377844d40d423bd26b229ee434a", "best_bid": "0.041", "best_ask": "0.049"}, {"asset_id": "111295934648931540975810135936206324404031729488235714793836466636975428917888", "price": "0.965", "size": "18", "side": "SELL", "hash": "d32e9999fb2942f82f79ce4520bb05d424b54c27", "best_bid": "0.951", "best_ask": "0.959"}], "timestamp": "1769384608862", "event_type": "price_change"}}
{"_local_timestamp": "2026-01-25T23:43:30.010541+00:00", "data": {"market": "0x0edc31cc586c65726249da0c698ce2b0dc3acac65a7b96574b7a8a89321ecf9e", "price_changes": [{"asset_id": "86948609484193076545604092003532216745788551371556780169247204971522981358794", "price": "0.011", "size": "1025.76", "side": "BUY", "hash": "6c68e5e42a00350566437c66e6b8b22970ea8512", "best_bid": "0.02", "best_ask": "0.026"}, {"asset_id": "40204010519879025056259875406560264981469631264230376751093889691606763270485", "price": "0.989", "size": "1025.76", "side": "SELL", "hash": "52f9c3479053fbfca2ac699c93aecc90c894f2f6", "best_bid": "0.974", "best_ask": "0.98"}], "timestamp": "1769384609915", "event_type": "price_change"}}
{"_local_timestamp": "2026-01-25T23:43:30.019730+00:00", "data": {"market": "0x0edc31cc586c65726249da0c698ce2b0dc3acac65a7b96574b7a8a89321ecf9e", "price_changes": [{"asset_id": "86948609484193076545604092003532216745788551371556780169247204971522981358794", "price": "0.018", "size": "389", "side": "BUY", "hash": "df47faa0c3610c79105d35932977027511278e7d", "best_bid": "0.02", "best_ask": "0.026"}, {"asset_id": "40204010519879025056259875406560264981469631264230376751093889691606763270485", "price": "0.982", "size": "389", "side": "SELL", "hash": "8e39b23efb301423faf930f29d176fd0fcae073e", "best_bid": "0.974", "best_ask": "0.98"}], "timestamp": "1769384609917", "event_type": "price_change"}}
{"_local_timestamp": "2026-01-25T23:43:30.020455+00:00", "data": {"market": "0x0edc31cc586c65726249da0c698ce2b0dc3acac65a7b96574b7a8a89321ecf9e", "price_changes": [{"asset_id": "86948609484193076545604092003532216745788551371556780169247204971522981358794", "price": "0.002", "size": "5520.04", "side": "BUY", "hash": "64cd8c6b79321924120b32e969cba2b784ce0130", "best_bid": "0.02", "best_ask": "0.026"}, {"asset_id": "40204010519879025056259875406560264981469631264230376751093889691606763270485", "price": "0.998", "size": "5520.04", "side": "SELL", "hash": "0547bdd4b3d2c2216ce4f75f523a38870a9357c1", "best_bid": "0.974", "best_ask": "0.98"}], "timestamp": "1769384609920", "event_type": "price_change"}}
{"_local_timestamp": "2026-01-25T23:43:30.037156+00:00", "data": {"market": "0x0edc31cc586c65726249da0c698ce2b0dc3acac65a7b96574b7a8a89321ecf9e", "price_changes": [{"asset_id": "86948609484193076545604092003532216745788551371556780169247204971522981358794", "price": "0.017", "size": "100", "side": "BUY", "hash": "5af8798c0b709a0e7cb0ff538d1c3394f7f91d22", "best_bid": "0.02", "best_ask": "0.026"}, {"asset_id": "40204010519879025056259875406560264981469631264230376751093889691606763270485", "price": "0.983", "size": "100", "side": "SELL", "hash": "89f7cbcbdbecf3d6736e271948c5b6ae3c8d7ed1", "best_bid": "0.974", "best_ask": "0.98"}], "timestamp": "1769384609941", "event_type": "price_change"}}
{"_local_timestamp": "2026-01-25T23:43:30.061712+00:00", "data": {"market": "0x0edc31cc586c65726249da0c698ce2b0dc3acac65a7b96574b7a8a89321ecf9e", "price_changes": [{"asset_id": "86948609484193076545604092003532216745788551371556780169247204971522981358794", "price": "0.019", "size": "176.4", "side": "BUY", "hash": "b4101e8ee7a4179ea1ad565ba6f482c8e7afe07c", "best_bid": "0.02", "best_ask": "0.026"}, {"asset_id": "40204010519879025056259875406560264981469631264230376751093889691606763270485", "price": "0.981", "size": "176.4", "side": "SELL", "hash": "1fac29a899baa9f5287a245dee1b485663c5bad4", "best_bid": "0.974", "best_ask": "0.98"}], "timestamp": "1769384609968", "event_type": "price_change"}}
{"_local_timestamp": "2026-01-25T23:43:30.949796+00:00", "data": {"market": "0x3d00e2266a6fce1d78d52dc99ad65a6e0b1d4b126608f9b57a57a9e64e14538b", "price_changes": [{"asset_id": "53186315788060762043972018184166502971471689613114984035234259092608911832812", "price": "0.023", "size": "391", "side": "BUY", "hash": "172460e55f136b411a3538e5391e019b6bda8830", "best_bid": "0.041", "best_ask": "0.049"}, {"asset_id": "111295934648931540975810135936206324404031729488235714793836466636975428917888", "price": "0.977", "size": "391", "side": "SELL", "hash": "dd870a965879b531641a358c5c9e60aa27d0e3e6", "best_bid": "0.951", "best_ask": "0.959"}], "timestamp": "1769384610854", "event_type": "price_change"}}
{"_local_timestamp": "2026-01-25T23:43:30.985796+00:00", "data": {"market": "0x3d00e2266a6fce1d78d52dc99ad65a6e0b1d4b126608f9b57a57a9e64e14538b", "price_changes": [{"asset_id": "53186315788060762043972018184166502971471689613114984035234259092608911832812", "price": "0.035", "size": "6", "side": "BUY", "hash": "7dc8675b7daa1de228f320cd56706e99621e72d1", "best_bid": "0.041", "best_ask": "0.049"}, {"asset_id": "111295934648931540975810135936206324404031729488235714793836466636975428917888", "price": "0.965", "size": "6", "side": "SELL", "hash": "7490f9c955752357df3c32c2957a5729a23e469d", "best_bid": "0.951", "best_ask": "0.959"}], "timestamp": "1769384610879", "event_type": "price_change"}}
{"_local_timestamp": "2026-01-25T23:43:31.025664+00:00", "data": {"market": "0x3d00e2266a6fce1d78d52dc99ad65a6e0b1d4b126608f9b57a57a9e64e14538b", "price_changes": [{"asset_id": "53186315788060762043972018184166502971471689613114984035234259092608911832812", "price": "0.022", "size": "106.31", "side": "BUY", "hash": "2f493358a4d7812dfbe53de60b5e9054512bb168", "best_bid": "0.041", "best_ask": "0.049"}, {"asset_id": "111295934648931540975810135936206324404031729488235714793836466636975428917888", "price": "0.978", "size": "106.31", "side": "SELL", "hash": "70d83ae9efcc6bbac112cca584e1d33b62e25183", "best_bid": "0.951", "best_ask": "0.959"}], "timestamp": "1769384610930", "event_type": "price_change"}}
{"_local_timestamp": "2026-01-25T23:43:31.057645+00:00", "data": {"market": "0x3d00e2266a6fce1d78d52dc99ad65a6e0b1d4b126608f9b57a57a9e64e14538b", "price_changes": [{"asset_id": "53186315788060762043972018184166502971471689613114984035234259092608911832812", "price": "0.021", "size": "334", "side": "BUY", "hash": "78d5a0d09f1d88c2a6d9fb5c181e66e35630996d", "best_bid": "0.041", "best_ask": "0.049"}, {"asset_id": "111295934648931540975810135936206324404031729488235714793836466636975428917888", "price": "0.979", "size": "334", "side": "SELL", "hash": "90b64555acfdba1b21833c09ac2c0970b56ea2b4", "best_bid": "0.951", "best_ask": "0.959"}], "timestamp": "1769384610961", "event_type": "price_change"}}
{"_local_timestamp": "2026-01-25T23:43:32.243203+00:00", "data": {"market": "0x0edc31cc586c65726249da0c698ce2b0dc3acac65a7b96574b7a8a89321ecf9e", "price_changes": [{"asset_id": "86948609484193076545604092003532216745788551371556780169247204971522981358794", "price": "0.011", "size": "843.76", "side": "BUY", "hash": "ae598752fff4cd87e4062c96362b26ca78ebeae7", "best_bid": "0.02", "best_ask": "0.026"}, {"asset_id": "40204010519879025056259875406560264981469631264230376751093889691606763270485", "price": "0.989", "size": "843.76", "side": "SELL", "hash": "ae257def5a2d3c1855bc9cc369a07d1e49ab16f0", "best_bid": "0.974", "best_ask": "0.98"}], "timestamp": "1769384612151", "event_type": "price_change"}}
{"_local_timestamp": "2026-01-25T23:43:32.243939+00:00", "data": {"market": "0x0edc31cc586c65726249da0c698ce2b0dc3acac65a7b96574b7a8a89321ecf9e", "price_changes": [{"asset_id": "86948609484193076545604092003532216745788551371556780169247204971522981358794", "price": "0.018", "size": "0", "side": "BUY", "hash": "ae598752fff4cd87e4062c96362b26ca78ebeae7", "best_bid": "0.02", "best_ask": "0.026"}, {"asset_id": "40204010519879025056259875406560264981469631264230376751093889691606763270485", "price": "0.982", "size": "0", "side": "SELL", "hash": "ae257def5a2d3c1855bc9cc369a07d1e49ab16f0", "best_bid": "0.974", "best_ask": "0.98"}], "timestamp": "1769384612151", "event_type": "price_change"}}
{"_local_timestamp": "2026-01-25T23:43:32.244581+00:00", "data": {"market": "0x0edc31cc586c65726249da0c698ce2b0dc3acac65a7b96574b7a8a89321ecf9e", "price_changes": [{"asset_id": "86948609484193076545604092003532216745788551371556780169247204971522981358794", "price": "0.002", "size": "4520.04", "side": "BUY", "hash": "ae598752fff4cd87e4062c96362b26ca78ebeae7", "best_bid": "0.02", "best_ask": "0.026"}, {"asset_id": "40204010519879025056259875406560264981469631264230376751093889691606763270485", "price": "0.998", "size": "4520.04", "side": "SELL", "hash": "ae257def5a2d3c1855bc9cc369a07d1e49ab16f0", "best_bid": "0.974", "best_ask": "0.98"}], "timestamp": "1769384612151", "event_type": "price_change"}}
{"_local_timestamp": "2026-01-25T23:43:32.268532+00:00", "data": {"market": "0x0edc31cc586c65726249da0c698ce2b0dc3acac65a7b96574b7a8a89321ecf9e", "price_changes": [{"asset_id": "86948609484193076545604092003532216745788551371556780169247204971522981358794", "price": "0.019", "size": "6.4", "side": "BUY", "hash": "6d0bf3295a3facded9628398271b39affed97263", "best_bid": "0.02", "best_ask": "0.026"}, {"asset_id": "40204010519879025056259875406560264981469631264230376751093889691606763270485", "price": "0.981", "size": "6.4", "side": "SELL", "hash": "be75c06f2eeda65de2ea9da59846a4afdb0b7803", "best_bid": "0.974", "best_ask": "0.98"}], "timestamp": "1769384612176", "event_type": "price_change"}}
{"_local_timestamp": "2026-01-25T23:43:32.294474+00:00", "data": {"market": "0x0edc31cc586c65726249da0c698ce2b0dc3acac65a7b96574b7a8a89321ecf9e", "price_changes": [{"asset_id": "86948609484193076545604092003532216745788551371556780169247204971522981358794", "price": "0.017", "size": "378", "side": "BUY", "hash": "b8b87964ebff54aaf74cffdf899f682a43e34d8b", "best_bid": "0.02", "best_ask": "0.026"}, {"asset_id": "40204010519879025056259875406560264981469631264230376751093889691606763270485", "price": "0.983", "size": "378", "side": "SELL", "hash": "32a0a2d648a1765d5ffeaa987a541e011df7d0ae", "best_bid": "0.974", "best_ask": "0.98"}], "timestamp": "1769384612201", "event_type": "price_change"}}
{"_local_timestamp": "2026-01-25T23:43:33.382668+00:00", "data": {"market": "0x3d00e2266a6fce1d78d52dc99ad65a6e0b1d4b126608f9b57a57a9e64e14538b", "price_changes": [{"asset_id": "53186315788060762043972018184166502971471689613114984035234259092608911832812", "price": "0.021", "size": "381", "side": "BUY", "hash": "c9df50fa8d6eb46277044969054ceed678f49029", "best_bid": "0.041", "best_ask": "0.049"}, {"asset_id": "111295934648931540975810135936206324404031729488235714793836466636975428917888", "price": "0.979", "size": "381", "side": "SELL", "hash": "225567dcf9e2a0b1d110cf6aceed451166ebb73d", "best_bid": "0.951", "best_ask": "0.959"}], "timestamp": "1769384613295", "event_type": "price_change"}}
{"_local_timestamp": "2026-01-25T23:43:33.383517+00:00", "data": {"market": "0x3d00e2266a6fce1d78d52dc99ad65a6e0b1d4b126608f9b57a57a9e64e14538b", "price_changes": [{"asset_id": "53186315788060762043972018184166502971471689613114984035234259092608911832812", "price": "0.024", "size": "292", "side": "BUY", "hash": "196749f568a14cbe13c7973593716f563c01c453", "best_bid": "0.041", "best_ask": "0.049"}, {"asset_id": "111295934648931540975810135936206324404031729488235714793836466636975428917888", "price": "0.976", "size": "292", "side": "SELL", "hash": "3790473764dc377e4fe6b26ad5d7773e7c7614c9", "best_bid": "0.951", "best_ask": "0.959"}], "timestamp": "1769384613296", "event_type": "price_change"}}
{"_local_timestamp": "2026-01-25T23:43:33.384896+00:00", "data": {"market": "0x3d00e2266a6fce1d78d52dc99ad65a6e0b1d4b126608f9b57a57a9e64e14538b", "price_changes": [{"asset_id": "53186315788060762043972018184166502971471689613114984035234259092608911832812", "price": "0.002", "size": "7426.35", "side": "BUY", "hash": "89a43ea827b029ccec084bb412f7f7964c431243", "best_bid": "0.041", "best_ask": "0.049"}, {"asset_id": "111295934648931540975810135936206324404031729488235714793836466636975428917888", "price": "0.998", "size": "7426.35", "side": "SELL", "hash": "9348d7ab14263afa987de84c481c5e1cacdef309", "best_bid": "0.951", "best_ask": "0.959"}], "timestamp": "1769384613297", "event_type": "price_change"}}
{"_local_timestamp": "2026-01-25T23:43:33.388611+00:00", "data": {"market": "0x3d00e2266a6fce1d78d52dc99ad65a6e0b1d4b126608f9b57a57a9e64e14538b", "price_changes": [{"asset_id": "53186315788060762043972018184166502971471689613114984035234259092608911832812", "price": "0.011", "size": "1001", "side": "BUY", "hash": "da77848d5bde091a9d62c88ee965b31ba85ed4cd", "best_bid": "0.041", "best_ask": "0.049"}, {"asset_id": "111295934648931540975810135936206324404031729488235714793836466636975428917888", "price": "0.989", "size": "1001", "side": "SELL", "hash": "0725a22f0153e264bb357d99d664ee4238777b0c", "best_bid": "0.951", "best_ask": "0.959"}], "timestamp": "1769384613297", "event_type": "price_change"}}
{"_local_timestamp": "2026-01-25T23:43:34.557016+00:00", "data": {"market": "0xcfe8947073d9333a6f767ed0c46713361aa4c34f75b35f1636622210356b2ba4", "price_changes": [{"asset_id": "21753818038149716958441586952364965978994113536903636754979518045886497078801", "price": "0.027", "size": "0", "side": "SELL", "hash": "10b3403cfd2ae5c0a0839e021049f6a22961f6ed", "best_bid": "0.002", "best_ask": "0.003"}, {"asset_id": "38409601990353197105461643021341338172518659365214781641813884172364820064219", "price": "0.973", "size": "0", "side": "BUY", "hash": "88ee0dff6b2fb1066481f73a0be74f6beadec58a", "best_bid": "0.997", "best_ask": "0.998"}], "timestamp": "1769384614474", "event_type": "price_change"}}
{"_local_timestamp": "2026-01-25T23:43:34.557863+00:00", "data": {"market": "0xcfe8947073d9333a6f767ed0c46713361aa4c34f75b35f1636622210356b2ba4", "price_changes": [{"asset_id": "21753818038149716958441586952364965978994113536903636754979518045886497078801", "price": "0.699", "size": "100", "side": "SELL", "hash": "10b3403cfd2ae5c0a0839e021049f6a22961f6ed", "best_bid": "0.002", "best_ask": "0.003"}, {"asset_id": "38409601990353197105461643021341338172518659365214781641813884172364820064219", "price": "0.301", "size": "100", "side": "BUY", "hash": "88ee0dff6b2fb1066481f73a0be74f6beadec58a", "best_bid": "0.997", "best_ask": "0.998"}], "timestamp": "1769384614474", "event_type": "price_change"}}
{"_local_timestamp": "2026-01-25T23:43:34.658379+00:00", "data": {"market": "0xcfe8947073d9333a6f767ed0c46713361aa4c34f75b35f1636622210356b2ba4", "price_changes": [{"asset_id": "21753818038149716958441586952364965978994113536903636754979518045886497078801", "price": "0.013", "size": "444.6", "side": "SELL", "hash": "f62814fbec96d69dd344eb9151cd935688991bcc", "best_bid": "0.002", "best_ask": "0.003"}, {"asset_id": "38409601990353197105461643021341338172518659365214781641813884172364820064219", "price": "0.987", "size": "444.6", "side": "BUY", "hash": "af7e5529389e8cccc77b986d1158a050b3d37f05", "best_bid": "0.997", "best_ask": "0.998"}], "timestamp": "1769384614562", "event_type": "price_change"}}
{"_local_timestamp": "2026-01-25T23:43:34.734038+00:00", "data": {"market": "0xcfe8947073d9333a6f767ed0c46713361aa4c34f75b35f1636622210356b2ba4", "price_changes": [{"asset_id": "21753818038149716958441586952364965978994113536903636754979518045886497078801", "price": "0.699", "size": "1418.96", "side": "SELL", "hash": "4d52f8fe5a9ff2d008ce1c9094b8ce716f0a7dc7", "best_bid": "0.002", "best_ask": "0.003"}, {"asset_id": "38409601990353197105461643021341338172518659365214781641813884172364820064219", "price": "0.301", "size": "1418.96", "side": "BUY", "hash": "848b83e73be94e3b12fd73875ffb8bd40fcdb6d1", "best_bid": "0.997", "best_ask": "0.998"}], "timestamp": "1769384614643", "event_type": "price_change"}}
{"_local_timestamp": "2026-01-25T23:43:45.093523+00:00", "data": {"market": "0x33825080bc810aa756a361298627cdf64d58dbd651a647bd0a29b8a68a7308fe", "price_changes": [{"asset_id": "27476096571833974040484538127433399463608736639971094747870629065388427932028", "price": "0.119", "size": "7000", "side": "SELL", "hash": "5a76def00d5385e29affd91e00fb656039c2f1e7", "best_bid": "0.034", "best_ask": "0.04"}, {"asset_id": "108112487379868796554191891208463687446351004748640934416300530966194496905118", "price": "0.881", "size": "7000", "side": "BUY", "hash": "188f4d5400c31bf480eacb72259ff4e633485e34", "best_bid": "0.96", "best_ask": "0.966"}], "timestamp": "1769384625000", "event_type": "price_change"}}
{"_local_timestamp": "2026-01-25T23:44:03.465537+00:00", "data": {"market": "0x830532ef53004df7522d7c56cad9af92f4b323590e7712302efdd99fa04cc078", "price_changes": [{"asset_id": "76159445949516107531196937780408758100497431686502173729855321957977280983930", "price": "0.045", "size": "211.56", "side": "SELL", "hash": "98c6a8ce4734836ccc8b8e536d7f17754c319a1a", "best_bid": "0.021", "best_ask": "0.029"}, {"asset_id": "55889977023103749239654252466433022405707563507479932528448213571367486700989", "price": "0.955", "size": "211.56", "side": "BUY", "hash": "9a5932f93d07fc0aa82e7d3d68bd0ab78ee2d547", "best_bid": "0.971", "best_ask": "0.979"}], "timestamp": "1769384643172", "event_type": "price_change"}}
{"_local_timestamp": "2026-01-25T23:44:03.732308+00:00", "data": {"market": "0x830532ef53004df7522d7c56cad9af92f4b323590e7712302efdd99fa04cc078", "price_changes": [{"asset_id": "76159445949516107531196937780408758100497431686502173729855321957977280983930", "price": "0.046", "size": "401.03", "side": "SELL", "hash": "f976bb3b201daf1276ce618679cb32103ba68560", "best_bid": "0.021", "best_ask": "0.029"}, {"asset_id": "55889977023103749239654252466433022405707563507479932528448213571367486700989", "price": "0.954", "size": "401.03", "side": "BUY", "hash": "0cf55e621c2d2e13e74f56cc34aca51b7b01314a", "best_bid": "0.971", "best_ask": "0.979"}], "timestamp": "1769384643423", "event_type": "price_change"}}
{"_local_timestamp": "2026-01-25T23:44:04.350376+00:00", "data": {"market": "0xb10aef4e56904ddab4f634b3bef36e878522d174ffb49688d3bca4e225516689", "price_changes": [{"asset_id": "53465481540932825427341404444568633780573546459375828539216440845324863999390", "price": "0.016", "size": "0", "side": "SELL", "hash": "6933957a9335a0a12e2d8f87da5e6d4d6ca4e5ea", "best_bid": "0.004", "best_ask": "0.005"}, {"asset_id": "67794036975373042160958042377401666699501615403692529610067934475766181787521", "price": "0.984", "size": "0", "side": "BUY", "hash": "a98376fafeeb0f049a24d696d71ddeae33e04e1f", "best_bid": "0.995", "best_ask": "0.996"}], "timestamp": "1769384644038", "event_type": "price_change"}}
{"_local_timestamp": "2026-01-25T23:44:04.372263+00:00", "data": {"market": "0xb10aef4e56904ddab4f634b3bef36e878522d174ffb49688d3bca4e225516689", "price_changes": [{"asset_id": "53465481540932825427341404444568633780573546459375828539216440845324863999390", "price": "0.015", "size": "0", "side": "SELL", "hash": "5d0cb894808d539f0a2bcdfa065aa130e2933b69", "best_bid": "0.004", "best_ask": "0.005"}, {"asset_id": "67794036975373042160958042377401666699501615403692529610067934475766181787521", "price": "0.985", "size": "0", "side": "BUY", "hash": "9d60c8ae58da883074dc79fdbc067a6b382af974", "best_bid": "0.995", "best_ask": "0.996"}], "timestamp": "1769384644082", "event_type": "price_change"}}
{"_local_timestamp": "2026-01-25T23:44:04.396408+00:00", "data": {"market": "0xb10aef4e56904ddab4f634b3bef36e878522d174ffb49688d3bca4e225516689", "price_changes": [{"asset_id": "53465481540932825427341404444568633780573546459375828539216440845324863999390", "price": "0.017", "size": "655", "side": "SELL", "hash": "30488aa4b6b3d0e629da96909ac41c40be062ee9", "best_bid": "0.004", "best_ask": "0.005"}, {"asset_id": "67794036975373042160958042377401666699501615403692529610067934475766181787521", "price": "0.983", "size": "655", "side": "BUY", "hash": "9cd76156d667ac3d579df14cb05381d7f8da4e79", "best_bid": "0.995", "best_ask": "0.996"}], "timestamp": "1769384644108", "event_type": "price_change"}}
{"_local_timestamp": "2026-01-25T23:44:04.637596+00:00", "data": {"market": "0xb10aef4e56904ddab4f634b3bef36e878522d174ffb49688d3bca4e225516689", "price_changes": [{"asset_id": "53465481540932825427341404444568633780573546459375828539216440845324863999390", "price": "0.014", "size": "125.71", "side": "SELL", "hash": "df24fb6f47362bd5658012bdd28731d3f4f23c8c", "best_bid": "0.004", "best_ask": "0.005"}, {"asset_id": "67794036975373042160958042377401666699501615403692529610067934475766181787521", "price": "0.986", "size": "125.71", "side": "BUY", "hash": "94d0a53f5a0e46c280affeb77fb8f7390d6623fc", "best_bid": "0.995", "best_ask": "0.996"}], "timestamp": "1769384644315", "event_type": "price_change"}}
{"_local_timestamp": "2026-01-25T23:44:05.193948+00:00", "data": {"market": "0xb10aef4e56904ddab4f634b3bef36e878522d174ffb49688d3bca4e225516689", "price_changes": [{"asset_id": "53465481540932825427341404444568633780573546459375828539216440845324863999390", "price": "0.002", "size": "1321.93", "side": "BUY", "hash": "a6244125b75f526acee1aff3ceb0807bc27506de", "best_bid": "0.004", "best_ask": "0.005"}, {"asset_id": "67794036975373042160958042377401666699501615403692529610067934475766181787521", "price": "0.998", "size": "1321.93", "side": "SELL", "hash": "5a168b3418a98030869f448b0fc98d44bcb642aa", "best_bid": "0.995", "best_ask": "0.996"}], "timestamp": "1769384644908", "event_type": "price_change"}}
{"_local_timestamp": "2026-01-25T23:44:05.548586+00:00", "data": {"market": "0xb10aef4e56904ddab4f634b3bef36e878522d174ffb49688d3bca4e225516689", "price_changes": [{"asset_id": "53465481540932825427341404444568633780573546459375828539216440845324863999390", "price": "0.002", "size": "1428.87", "side": "BUY", "hash": "4bda83c686e16146fe0876e0594e13467d05bda7", "best_bid": "0.004", "best_ask": "0.005"}, {"asset_id": "67794036975373042160958042377401666699501615403692529610067934475766181787521", "price": "0.998", "size": "1428.87", "side": "SELL", "hash": "a725d9ff4cca9955e117d6a3bb29c7c4af9d6770", "best_bid": "0.995", "best_ask": "0.996"}], "timestamp": "1769384645278", "event_type": "price_change"}}
{"_local_timestamp": "2026-01-25T23:44:05.573318+00:00", "data": {"market": "0xb10aef4e56904ddab4f634b3bef36e878522d174ffb49688d3bca4e225516689", "price_changes": [{"asset_id": "53465481540932825427341404444568633780573546459375828539216440845324863999390", "price": "0.017", "size": "200", "side": "SELL", "hash": "11cb1c474882dd0943c21555a2451566e068a9fe", "best_bid": "0.004", "best_ask": "0.005"}, {"asset_id": "67794036975373042160958042377401666699501615403692529610067934475766181787521", "price": "0.983", "size": "200", "side": "BUY", "hash": "f3935b8d6b165a3eb5103f9e0fc5814363b3e2ad", "best_bid": "0.995", "best_ask": "0.996"}], "timestamp": "1769384645304", "event_type": "price_change"}}
{"_local_timestamp": "2026-01-25T23:44:05.600878+00:00", "data": {"market": "0xb10aef4e56904ddab4f634b3bef36e878522d174ffb49688d3bca4e225516689", "price_changes": [{"asset_id": "53465481540932825427341404444568633780573546459375828539216440845324863999390", "price": "0.014", "size": "560.71", "side": "SELL", "hash": "0967d1c1e8c79ec5cae48e856107f576b8c56b90", "best_bid": "0.004", "best_ask": "0.005"}, {"asset_id": "67794036975373042160958042377401666699501615403692529610067934475766181787521", "price": "0.986", "size": "560.71", "side": "BUY", "hash": "9e6dcfc234b665d0b4011aa0d017ee8c484ee489", "best_bid": "0.995", "best_ask": "0.996"}], "timestamp": "1769384645329", "event_type": "price_change"}}
{"_local_timestamp": "2026-01-25T23:44:06.896618+00:00", "data": {"market": "0xcfe8947073d9333a6f767ed0c46713361aa4c34f75b35f1636622210356b2ba4", "price_changes": [{"asset_id": "21753818038149716958441586952364965978994113536903636754979518045886497078801", "price": "0.011", "size": "0", "side": "SELL", "hash": "63c4f2b1eb6e7dcfb104aa81a877646d5db402ff", "best_bid": "0.002", "best_ask": "0.003"}, {"asset_id": "38409601990353197105461643021341338172518659365214781641813884172364820064219", "price": "0.989", "size": "0", "side": "BUY", "hash": "028a0d79b08b9b41a2fe36d99daf7baf315959b6", "best_bid": "0.997", "best_ask": "0.998"}], "timestamp": "1769384646632", "event_type": "price_change"}}
{"_local_timestamp": "2026-01-25T23:44:07.198342+00:00", "data": {"market": "0xcfe8947073d9333a6f767ed0c46713361aa4c34f75b35f1636622210356b2ba4", "price_changes": [{"asset_id": "21753818038149716958441586952364965978994113536903636754979518045886497078801", "price": "0.012", "size": "128.03", "side": "SELL", "hash": "ea943ef17dc685e9e1beef62fbb7a6a51f2817f2", "best_bid": "0.002", "best_ask": "0.003"}, {"asset_id": "38409601990353197105461643021341338172518659365214781641813884172364820064219", "price": "0.988", "size": "128.03", "side": "BUY", "hash": "1eae986639aa451e5585569f7d6d4d271b3fd2a3", "best_bid": "0.997", "best_ask": "0.998"}], "timestamp": "1769384646932", "event_type": "price_change"}}
{"_local_timestamp": "2026-01-25T23:44:08.366135+00:00", "data": {"market": "0x3e0f3863b4ed9dcabd7bbf9d03089e64bcfe5be6fd96284e58c772806823c60e", "price_changes": [{"asset_id": "110865594744159968267498282218512778667662344467377910002492558627771354011913", "price": "0.002", "size": "2758.4", "side": "BUY", "hash": "3ceea1659ca818ffbe71245151686f68b11413af", "best_bid": "0.005", "best_ask": "0.008"}, {"asset_id": "58240812112472573224618301580190009078083222467735667648538851344040750074390", "price": "0.998", "size": "2758.4", "side": "SELL", "hash": "2fff6a69dbd7ce2c4fc474170a4ac3b36d2c9264", "best_bid": "0.992", "best_ask": "0.995"}], "timestamp": "1769384648013", "event_type": "price_change"}}
{"_local_timestamp": "2026-01-25T23:44:08.366977+00:00", "data": {"market": "0x3e0f3863b4ed9dcabd7bbf9d03089e64bcfe5be6fd96284e58c772806823c60e", "price_changes": [{"asset_id": "110865594744159968267498282218512778667662344467377910002492558627771354011913", "price": "0.003", "size": "271.82", "side": "BUY", "hash": "3ceea1659ca818ffbe71245151686f68b11413af", "best_bid": "0.005", "best_ask": "0.008"}, {"asset_id": "58240812112472573224618301580190009078083222467735667648538851344040750074390", "price": "0.997", "size": "271.82", "side": "SELL", "hash": "2fff6a69dbd7ce2c4fc474170a4ac3b36d2c9264", "best_bid": "0.992", "best_ask": "0.995"}], "timestamp": "1769384648013", "event_type": "price_change"}}
{"_local_timestamp": "2026-01-25T23:44:08.369350+00:00", "data": {"market": "0x3e0f3863b4ed9dcabd7bbf9d03089e64bcfe5be6fd96284e58c772806823c60e", "price_changes": [{"asset_id": "110865594744159968267498282218512778667662344467377910002492558627771354011913", "price": "0.004", "size": "42.53", "side": "BUY", "hash": "3ceea1659ca818ffbe71245151686f68b11413af", "best_bid": "0.005", "best_ask": "0.008"}, {"asset_id": "58240812112472573224618301580190009078083222467735667648538851344040750074390", "price": "0.996", "size": "42.53", "side": "SELL", "hash": "2fff6a69dbd7ce2c4fc474170a4ac3b36d2c9264", "best_bid": "0.992", "best_ask": "0.995"}], "timestamp": "1769384648013", "event_type": "price_change"}}
{"_local_timestamp": "2026-01-25T23:44:08.793658+00:00", "data": {"market": "0x3e0f3863b4ed9dcabd7bbf9d03089e64bcfe5be6fd96284e58c772806823c60e", "price_changes": [{"asset_id": "110865594744159968267498282218512778667662344467377910002492558627771354011913", "price": "0.003", "size": "313.99", "side": "BUY", "hash": "943c2e39a060bacd177c678103362852806e0e4a", "best_bid": "0.005", "best_ask": "0.008"}, {"asset_id": "58240812112472573224618301580190009078083222467735667648538851344040750074390", "price": "0.997", "size": "313.99", "side": "SELL", "hash": "fa3961293533da155185367ed48c65e4a1d04b50", "best_bid": "0.992", "best_ask": "0.995"}], "timestamp": "1769384648391", "event_type": "price_change"}}
{"_local_timestamp": "2026-01-25T23:44:08.794370+00:00", "data": {"market": "0x3e0f3863b4ed9dcabd7bbf9d03089e64bcfe5be6fd96284e58c772806823c60e", "price_changes": [{"asset_id": "110865594744159968267498282218512778667662344467377910002492558627771354011913", "price": "0.005", "size": "542.68", "side": "BUY", "hash": "9fb0fe2ea0bc7c942009eeeea7a2ff5238fc4f0d", "best_bid": "0.005", "best_ask": "0.008"}, {"asset_id": "58240812112472573224618301580190009078083222467735667648538851344040750074390", "price": "0.995", "size": "542.68", "side": "SELL", "hash": "782d2cde62ea0db07c5a2e442e32756a63b34822", "best_bid": "0.992", "best_ask": "0.995"}], "timestamp": "1769384648394", "event_type": "price_change"}}
{"_local_timestamp": "2026-01-25T23:44:08.795016+00:00", "data": {"market": "0x3e0f3863b4ed9dcabd7bbf9d03089e64bcfe5be6fd96284e58c772806823c60e", "price_changes": [{"asset_id": "110865594744159968267498282218512778667662344467377910002492558627771354011913", "price": "0.002", "size": "2866.73", "side": "BUY", "hash": "a28b298b869f3ce71d3a07b55f85542a5a3289a1", "best_bid": "0.005", "best_ask": "0.008"}, {"asset_id": "58240812112472573224618301580190009078083222467735667648538851344040750074390", "price": "0.998", "size": "2866.73", "side": "SELL", "hash": "ca95e42bff82a55e6aff7895cf9fa5aeaf4972b1", "best_bid": "0.992", "best_ask": "0.995"}], "timestamp": "1769384648397", "event_type": "price_change"}}
{"_local_timestamp": "2026-01-25T23:44:17.818574+00:00", "data": {"market": "0x7c663472136f5db9dbc0a223ed26f9e586864d9d4d0d40cb28a8157e279feff4", "price_changes": [{"asset_id": "94146194619680623124956731256954660746880239065654088591536542002260568253245", "price": "0.004", "size": "162.44", "side": "BUY", "hash": "2ba8e41ce21ee1b8c78467e2323c16537374af1a", "best_bid": "0.016", "best_ask": "0.017"}, {"asset_id": "80500705406858794154333907699858742630939624339510163743458445359324900544624", "price": "0.996", "size": "162.44", "side": "SELL", "hash": "6e3f733cf069df8e1a9b40a18a0b9b1cb0ee0711", "best_bid": "0.983", "best_ask": "0.984"}], "timestamp": "1769384657752", "event_type": "price_change"}}
{"_local_timestamp": "2026-01-25T23:44:17.819307+00:00", "data": {"market": "0x7c663472136f5db9dbc0a223ed26f9e586864d9d4d0d40cb28a8157e279feff4", "price_changes": [{"asset_id": "94146194619680623124956731256954660746880239065654088591536542002260568253245", "price": "0.012", "size": "0", "side": "BUY", "hash": "2ba8e41ce21ee1b8c78467e2323c16537374af1a", "best_bid": "0.016", "best_ask": "0.017"}, {"asset_id": "80500705406858794154333907699858742630939624339510163743458445359324900544624", "price": "0.988", "size": "0", "side": "SELL", "hash": "6e3f733cf069df8e1a9b40a18a0b9b1cb0ee0711", "best_bid": "0.983", "best_ask": "0.984"}], "timestamp": "1769384657752", "event_type": "price_change"}}
{"_local_timestamp": "2026-01-25T23:44:18.158829+00:00", "data": {"market": "0x7c663472136f5db9dbc0a223ed26f9e586864d9d4d0d40cb28a8157e279feff4", "price_changes": [{"asset_id": "94146194619680623124956731256954660746880239065654088591536542002260568253245", "price": "0.011", "size": "10.53", "side": "BUY", "hash": "3d86ff92ee8940a8765cae40f9fd75c71a2b95a0", "best_bid": "0.016", "best_ask": "0.017"}, {"asset_id": "80500705406858794154333907699858742630939624339510163743458445359324900544624", "price": "0.989", "size": "10.53", "side": "SELL", "hash": "c070131edb745a499026833fa401dffec6d6881b", "best_bid": "0.983", "best_ask": "0.984"}], "timestamp": "1769384658092", "event_type": "price_change"}}
{"_local_timestamp": "2026-01-25T23:44:18.159572+00:00", "data": {"market": "0x7c663472136f5db9dbc0a223ed26f9e586864d9d4d0d40cb28a8157e279feff4", "price_changes": [{"asset_id": "94146194619680623124956731256954660746880239065654088591536542002260568253245", "price": "0.005", "size": "35.65", "side": "BUY", "hash": "22e04aafb88dfc45705b547546d537616f0f5474", "best_bid": "0.016", "best_ask": "0.017"}, {"asset_id": "80500705406858794154333907699858742630939624339510163743458445359324900544624", "price": "0.995", "size": "35.65", "side": "SELL", "hash": "564a9793c611683ba7a3d31963bd755a357e03af", "best_bid": "0.983", "best_ask": "0.984"}], "timestamp": "1769384658093", "event_type": "price_change"}}
{"_local_timestamp": "2026-01-25T23:44:18.195800+00:00", "data": {"market": "0x7c663472136f5db9dbc0a223ed26f9e586864d9d4d0d40cb28a8157e279feff4", "price_changes": [{"asset_id": "94146194619680623124956731256954660746880239065654088591536542002260568253245", "price": "0.004", "size": "5.44", "side": "BUY", "hash": "3452567f9aa4f5d8fa191a4f2756e315c2f66db9", "best_bid": "0.016", "best_ask": "0.017"}, {"asset_id": "80500705406858794154333907699858742630939624339510163743458445359324900544624", "price": "0.996", "size": "5.44", "side": "SELL", "hash": "76f46ae378f33bb26c84d0354a38b76bdb32d3dc", "best_bid": "0.983", "best_ask": "0.984"}], "timestamp": "1769384658119", "event_type": "price_change"}}
{"_local_timestamp": "2026-01-25T23:44:19.591300+00:00", "data": {"market": "0x3d00e2266a6fce1d78d52dc99ad65a6e0b1d4b126608f9b57a57a9e64e14538b", "price_changes": [{"asset_id": "53186315788060762043972018184166502971471689613114984035234259092608911832812", "price": "0.023", "size": "0", "side": "BUY", "hash": "5e3b88bcb589163ed84e7d27b68bd2148a393483", "best_bid": "0.041", "best_ask": "0.049"}, {"asset_id": "111295934648931540975810135936206324404031729488235714793836466636975428917888", "price": "0.977", "size": "0", "side": "SELL", "hash": "d08f76eae29c02a26de3fc2048d4d11b9b2eb508", "best_bid": "0.951", "best_ask": "0.959"}], "timestamp": "1769384659523", "event_type": "price_change"}}
{"_local_timestamp": "2026-01-25T23:44:19.881259+00:00", "data": {"market": "0x3d00e2266a6fce1d78d52dc99ad65a6e0b1d4b126608f9b57a57a9e64e14538b", "price_changes": [{"asset_id": "53186315788060762043972018184166502971471689613114984035234259092608911832812", "price": "0.021", "size": "772", "side": "BUY", "hash": "5f15a7714ba143d07eb3f9a622e251759f42cdaf", "best_bid": "0.041", "best_ask": "0.049"}, {"asset_id": "111295934648931540975810135936206324404031729488235714793836466636975428917888", "price": "0.979", "size": "772", "side": "SELL", "hash": "5bc2f7303c71955ec6327bb828e1e0133ce56503", "best_bid": "0.951", "best_ask": "0.959"}], "timestamp": "1769384659810", "event_type": "price_change"}}
{"_local_timestamp": "2026-01-25T23:44:22.356406+00:00", "data": {"market": "0x3d00e2266a6fce1d78d52dc99ad65a6e0b1d4b126608f9b57a57a9e64e14538b", "price_changes": [{"asset_id": "53186315788060762043972018184166502971471689613114984035234259092608911832812", "price": "0.021", "size": "391", "side": "BUY", "hash": "2634afe684aa3889614aa80db96e23d0aa535721", "best_bid": "0.041", "best_ask": "0.049"}, {"asset_id": "111295934648931540975810135936206324404031729488235714793836466636975428917888", "price": "0.979", "size": "391", "side": "SELL", "hash": "77d4cd7c14070da2c7f06e64dd95c2cac95fd89b", "best_bid": "0.951", "best_ask": "0.959"}], "timestamp": "1769384662210", "event_type": "price_change"}}
{"_local_timestamp": "2026-01-25T23:44:22.443157+00:00", "data": {"market": "0x3d00e2266a6fce1d78d52dc99ad65a6e0b1d4b126608f9b57a57a9e64e14538b", "price_changes": [{"asset_id": "53186315788060762043972018184166502971471689613114984035234259092608911832812", "price": "0.024", "size": "0", "side": "BUY", "hash": "2634afe684aa3889614aa80db96e23d0aa535721", "best_bid": "0.041", "best_ask": "0.049"}, {"asset_id": "111295934648931540975810135936206324404031729488235714793836466636975428917888", "price": "0.976", "size": "0", "side": "SELL", "hash": "77d4cd7c14070da2c7f06e64dd95c2cac95fd89b", "best_bid": "0.951", "best_ask": "0.959"}], "timestamp": "1769384662210", "event_type": "price_change"}}
{"_local_timestamp": "2026-01-25T23:44:22.446679+00:00", "data": {"market": "0x3d00e2266a6fce1d78d52dc99ad65a6e0b1d4b126608f9b57a57a9e64e14538b", "price_changes": [{"asset_id": "53186315788060762043972018184166502971471689613114984035234259092608911832812", "price": "0.002", "size": "6426.35", "side": "BUY", "hash": "2634afe684aa3889614aa80db96e23d0aa535721", "best_bid": "0.041", "best_ask": "0.049"}, {"asset_id": "111295934648931540975810135936206324404031729488235714793836466636975428917888", "price": "0.998", "size": "6426.35", "side": "SELL", "hash": "77d4cd7c14070da2c7f06e64dd95c2cac95fd89b", "best_bid": "0.951", "best_ask": "0.959"}], "timestamp": "1769384662210", "event_type": "price_change"}}
{"_local_timestamp": "2026-01-25T23:44:22.453386+00:00", "data": {"market": "0x3d00e2266a6fce1d78d52dc99ad65a6e0b1d4b126608f9b57a57a9e64e14538b", "price_changes": [{"asset_id": "53186315788060762043972018184166502971471689613114984035234259092608911832812", "price": "0.011", "size": "728", "side": "BUY", "hash": "2634afe684aa3889614aa80db96e23d0aa535721", "best_bid": "0.041", "best_ask": "0.049"}, {"asset_id": "111295934648931540975810135936206324404031729488235714793836466636975428917888", "price": "0.989", "size": "728", "side": "SELL", "hash": "77d4cd7c14070da2c7f06e64dd95c2cac95fd89b", "best_bid": "0.951", "best_ask": "0.959"}], "timestamp": "1769384662210", "event_type": "price_change"}}
{"_local_timestamp": "2026-01-25T23:44:22.461783+00:00", "data": {"market": "0x3d00e2266a6fce1d78d52dc99ad65a6e0b1d4b126608f9b57a57a9e64e14538b", "price_changes": [{"asset_id": "53186315788060762043972018184166502971471689613114984035234259092608911832812", "price": "0.022", "size": "425.31", "side": "BUY", "hash": "a16d575042401dbbb93a6cc97663dc8d2cf2b453", "best_bid": "0.041", "best_ask": "0.049"}, {"asset_id": "111295934648931540975810135936206324404031729488235714793836466636975428917888", "price": "0.978", "size": "425.31", "side": "SELL", "hash": "6593240bc6ed2445ad7f0e5ef6d5546cf71cb0af", "best_bid": "0.951", "best_ask": "0.959"}], "timestamp": "1769384662231", "event_type": "price_change"}}
{"_local_timestamp": "2026-01-25T23:44:46.305962+00:00", "data": {"market": "0xc8944bb47818c0957fbeedcef9832d31927bd5d3f92912d08ae7db507ee851de", "price_changes": [{"asset_id": "43475483477872222798871077137471314754383343074234425453922242101872923868514", "price": "0.002", "size": "1166", "side": "BUY", "hash": "9f83273e61beb7614df899baeb64374db59ef912", "best_bid": "0.005", "best_ask": "0.006"}, {"asset_id": "115373591989130727514457065197328696865580700117510285020088208107086541485978", "price": "0.998", "size": "1166", "side": "SELL", "hash": "9b81281544d5aa44af087a4783205a1063f8098c", "best_bid": "0.994", "best_ask": "0.995"}], "timestamp": "1769384686245", "event_type": "price_change"}}
{"_local_timestamp": "2026-01-25T23:44:46.316537+00:00", "data": {"market": "0xc8944bb47818c0957fbeedcef9832d31927bd5d3f92912d08ae7db507ee851de", "price_changes": [{"asset_id": "43475483477872222798871077137471314754383343074234425453922242101872923868514", "price": "0.003", "size": "414.37", "side": "BUY", "hash": "9f83273e61beb7614df899baeb64374db59ef912", "best_bid": "0.005", "best_ask": "0.006"}, {"asset_id": "115373591989130727514457065197328696865580700117510285020088208107086541485978", "price": "0.997", "size": "414.37", "side": "SELL", "hash": "9b81281544d5aa44af087a4783205a1063f8098c", "best_bid": "0.994", "best_ask": "0.995"}], "timestamp": "1769384686245", "event_type": "price_change"}}
{"_local_timestamp": "2026-01-25T23:44:46.670087+00:00", "data": {"market": "0xc8944bb47818c0957fbeedcef9832d31927bd5d3f92912d08ae7db507ee851de", "price_changes": [{"asset_id": "43475483477872222798871077137471314754383343074234425453922242101872923868514", "price": "0.003", "size": "493.65", "side": "BUY", "hash": "c49b8fb0e4dbce53c43d82351c058f640086693b", "best_bid": "0.005", "best_ask": "0.006"}, {"asset_id": "115373591989130727514457065197328696865580700117510285020088208107086541485978", "price": "0.997", "size": "493.65", "side": "SELL", "hash": "cf0e09beaa8ce4d89df951a226f0e249d944f58c", "best_bid": "0.994", "best_ask": "0.995"}], "timestamp": "1769384686595", "event_type": "price_change"}}
{"_local_timestamp": "2026-01-25T23:44:46.670946+00:00", "data": {"market": "0xc8944bb47818c0957fbeedcef9832d31927bd5d3f92912d08ae7db507ee851de", "price_changes": [{"asset_id": "43475483477872222798871077137471314754383343074234425453922242101872923868514", "price": "0.002", "size": "1432.91", "side": "BUY", "hash": "1a56c95b890a987330bf7a4db154cbb939b3b48a", "best_bid": "0.005", "best_ask": "0.006"}, {"asset_id": "115373591989130727514457065197328696865580700117510285020088208107086541485978", "price": "0.998", "size": "1432.91", "side": "SELL", "hash": "545f9fdf44504b75341da38a99c9dfcfaab503d3", "best_bid": "0.994", "best_ask": "0.995"}], "timestamp": "1769384686596", "event_type": "price_change"}}
{"_local_timestamp": "2026-01-25T23:44:51.294544+00:00", "data": {"market": "0xcfe8947073d9333a6f767ed0c46713361aa4c34f75b35f1636622210356b2ba4", "price_changes": [{"asset_id": "21753818038149716958441586952364965978994113536903636754979518045886497078801", "price": "0.014", "size": "0", "side": "SELL", "hash": "830e2f2e67661fb337efd8b9813cbf1dba1c4273", "best_bid": "0.002", "best_ask": "0.003"}, {"asset_id": "38409601990353197105461643021341338172518659365214781641813884172364820064219", "price": "0.986", "size": "0", "side": "BUY", "hash": "a7dcfb0e023f6b26f1eb91604e9152d08952638c", "best_bid": "0.997", "best_ask": "0.998"}], "timestamp": "1769384691232", "event_type": "price_change"}}
{"_local_timestamp": "2026-01-25T23:44:51.539413+00:00", "data": {"market": "0xcfe8947073d9333a6f767ed0c46713361aa4c34f75b35f1636622210356b2ba4", "price_changes": [{"asset_id": "21753818038149716958441586952364965978994113536903636754979518045886497078801", "price": "0.007", "size": "363.65", "side": "SELL", "hash": "a25b4b22344f2ca8b7b1c38ac2a533eaabc7bab8", "best_bid": "0.002", "best_ask": "0.003"}, {"asset_id": "38409601990353197105461643021341338172518659365214781641813884172364820064219", "price": "0.993", "size": "363.65", "side": "BUY", "hash": "3f80cf2e317ac78fddea9e3dc5ba3b383f43cec0", "best_bid": "0.997", "best_ask": "0.998"}], "timestamp": "1769384691454", "event_type": "price_change"}}
{"_local_timestamp": "2026-01-25T23:44:54.034418+00:00", "data": {"market": "0x0edc31cc586c65726249da0c698ce2b0dc3acac65a7b96574b7a8a89321ecf9e", "price_changes": [{"asset_id": "86948609484193076545604092003532216745788551371556780169247204971522981358794", "price": "0.015", "size": "0", "side": "BUY", "hash": "961fce0a050160d6f8689c2ed0d3de93b668cb1d", "best_bid": "0.02", "best_ask": "0.026"}, {"asset_id": "40204010519879025056259875406560264981469631264230376751093889691606763270485", "price": "0.985", "size": "0", "side": "SELL", "hash": "e0f8aba4999bac8274901e53850a4392b0041b1d", "best_bid": "0.974", "best_ask": "0.98"}], "timestamp": "1769384693970", "event_type": "price_change"}}
{"_local_timestamp": "2026-01-25T23:44:54.035271+00:00", "data": {"market": "0x0edc31cc586c65726249da0c698ce2b0dc3acac65a7b96574b7a8a89321ecf9e", "price_changes": [{"asset_id": "86948609484193076545604092003532216745788551371556780169247204971522981358794", "price": "0.019", "size": "0", "side": "BUY", "hash": "961fce0a050160d6f8689c2ed0d3de93b668cb1d", "best_bid": "0.02", "best_ask": "0.026"}, {"asset_id": "40204010519879025056259875406560264981469631264230376751093889691606763270485", "price": "0.981", "size": "0", "side": "SELL", "hash": "e0f8aba4999bac8274901e53850a4392b0041b1d", "best_bid": "0.974", "best_ask": "0.98"}], "timestamp": "1769384693970", "event_type": "price_change"}}
{"_local_timestamp": "2026-01-25T23:44:54.066305+00:00", "data": {"market": "0x0edc31cc586c65726249da0c698ce2b0dc3acac65a7b96574b7a8a89321ecf9e", "price_changes": [{"asset_id": "86948609484193076545604092003532216745788551371556780169247204971522981358794", "price": "0.017", "size": "100", "side": "BUY", "hash": "ba18d11e5ede6cebe6f88be475c271c02219b6ef", "best_bid": "0.02", "best_ask": "0.026"}, {"asset_id": "40204010519879025056259875406560264981469631264230376751093889691606763270485", "price": "0.983", "size": "100", "side": "SELL", "hash": "c9a45c4690ac00795618f0d0b61318c25dc6554a", "best_bid": "0.974", "best_ask": "0.98"}], "timestamp": "1769384694000", "event_type": "price_change"}}
{"_local_timestamp": "2026-01-25T23:44:54.095759+00:00", "data": {"market": "0x0edc31cc586c65726249da0c698ce2b0dc3acac65a7b96574b7a8a89321ecf9e", "price_changes": [{"asset_id": "86948609484193076545604092003532216745788551371556780169247204971522981358794", "price": "0.015", "size": "374", "side": "BUY", "hash": "d76ce21bb57bcdd353326794404161575afedd71", "best_bid": "0.02", "best_ask": "0.026"}, {"asset_id": "40204010519879025056259875406560264981469631264230376751093889691606763270485", "price": "0.985", "size": "374", "side": "SELL", "hash": "78e223e22120031a95c9f826542d638fb50c2aa6", "best_bid": "0.974", "best_ask": "0.98"}], "timestamp": "1769384694026", "event_type": "price_change"}}
{"_local_timestamp": "2026-01-25T23:44:54.211978+00:00", "data": {"market": "0x0edc31cc586c65726249da0c698ce2b0dc3acac65a7b96574b7a8a89321ecf9e", "price_changes": [{"asset_id": "86948609484193076545604092003532216745788551371556780169247204971522981358794", "price": "0.015", "size": "382.26", "side": "BUY", "hash": "0f0707ba396a4838ab14c6c6addd43ea9fed8c19", "best_bid": "0.02", "best_ask": "0.026"}, {"asset_id": "40204010519879025056259875406560264981469631264230376751093889691606763270485", "price": "0.985", "size": "382.26", "side": "SELL", "hash": "270a89df09e050e5031b611baec693549e2c5ed0", "best_bid": "0.974", "best_ask": "0.98"}], "timestamp": "1769384694144", "event_type": "price_change"}}
