{"_local_timestamp": "2026-01-25T23:33:42.858636+00:00", "data": [{"market": "0x1cc14846bee31efbd7c2016ca1c17664684ead0c7f3b8bd91876033a546128d8", "asset_id": "32668102469816119620746811427740823831434256980467530534403997191651163337906", "timestamp": "1769384015841", "hash": "fa5614f0e7b3c0401c0c10c3949f53cb307111ac", "bids": [{"price": "0.01", "size": "2356.28"}, {"price": "0.02", "size": "250"}, {"price": "0.03", "size": "13.34"}, {"price": "0.04", "size": "900"}, {"price": "0.06", "size": "599.66"}, {"price": "0.07", "size": "100"}, {"price": "0.08", "size": "400"}, {"price": "0.09", "size": "200"}, {"price": "0.1", "size": "300"}, {"price": "0.12", "size": "216.66"}, {"price": "0.14", "size": "171.42"}, {"price": "0.15", "size": "133.32"}, {"price": "0.17", "size": "194.11"}, {"price": "0.18", "size": "158.11"}, {"price": "0.19", "size": "8.5"}, {"price": "0.2", "size": "66.66"}, {"price": "0.3", "size": "50"}], "asks": [{"price": "0.99", "size": "110.32"}, {"price": "0.97", "size": "10.82"}, {"price": "0.95", "size": "20"}, {"price": "0.94", "size": "600"}, {"price": "0.93", "size": "320"}, {"price": "0.91", "size": "377.77"}, {"price": "0.9", "size": "300"}, {"price": "0.89", "size": "5.2"}, {"price": "0.88", "size": "266.66"}, {"price": "0.85", "size": "186.66"}, {"price": "0.83", "size": "152.94"}, {"price": "0.8", "size": "153.33"}, {"price": "0.77", "size": "786.95"}, {"price": "0.75", "size": "141"}, {"price": "0.69", "size": "150"}, {"price": "0.64", "size": "33.33"}, {"price": "0.59", "size": "31.7"}, {"price": "0.58", "size": "26.19"}, {"price": "0.57", "size": "8.5"}, {"price": "0.5", "size": "50"}, {"price": "0.49", "size": "30"}, {"price": "0.48", "size": "83.33"}], "event_type": "book", "last_trade_price": ""}, {"market": "0x1cc14846bee31efbd7c2016ca1c17664684ead0c7f3b8bd91876033a546128d8", "asset_id": "60596582874731501900696294615290867175277482143370610111416633979822519113254", "timestamp": "1769384015841", "hash": "8e4c332954df7d512293bf141e17a6296716d37d", "bids": [{"price": "0.01", "size": "110.32"}, {"price": "0.03", "size": "10.82"}, {"price": "0.05", "size": "20"}, {"price": "0.06", "size": "600"}, {"price": "0.07", "size": "320"}, {"price": "0.09", "size": "377.77"}, {"price": "0.1", "size": "300"}, {"price": "0.11", "size": "5.2"}, {"price": "0.12", "size": "266.66"}, {"price": "0.15", "size": "186.66"}, {"price": "0.17", "size": "152.94"}, {"price": "0.2", "size": "153.33"}, {"price": "0.23", "size": "786.95"}, {"price": "0.25", "size": "141"}, {"price": "0.31", "size": "150"}, {"price": "0.36", "size": "33.33"}, {"price": "0.41", "size": "31.7"}, {"price": "0.42", "size": "26.19"}, {"price": "0.43", "size": "8.5"}, {"price": "0.5", "size": "50"}, {"price": "0.51", "size": "30"}, {"price": "0.52", "size": "83.33"}], "asks": [{"price": "0.99", "size": "2356.28"}, {"price": "0.98", "size": "250"}, {"price": "0.97", "size": "13.34"}, {"price": "0.96", "size": "900"}, {"price": "0.94", "size": "599.66"}, {"price": "0.93", "size": "100"}, {"price": "0.92", "size": "400"}, {"price": "0.91", "size": "200"}, {"price": "0.9", "size": "300"}, {"price": "0.88", "size": "216.66"}, {"price": "0.86", "size": "171.42"}, {"price": "0.85", "size": "133.32"}, {"price": "0.83", "size": "194.11"}, {"price": "0.82", "size": "158.11"}, {"price": "0.81", "size": "8.5"}, {"price": "0.8", "size": "66.66"}, {"price": "0.7", "size": "50"}], "event_type": "book", "last_trade_price": ""}, {"market": "0x01ad0cec215d379cf4954c08a5ac7afcd2342ff7342d138dff158ecf6c3a640b", "asset_id": "63493468661893317763102938837141130049667113153921302098928511271509275738088", "timestamp": "1769383901937", "hash": "6d9a38f7f1f27876937daaed4ea56a855a56dce7", "bids": [{"price": "0.001", "size": "1892.99"}, {"price": "0.002", "size": "2500"}, {"price": "0.003", "size": "13.51"}, {"price": "0.004", "size": "2500"}, {"price": "0.005", "size": "250"}, {"price": "0.006", "size": "19.61"}, {"price": "0.007", "size": "1400"}, {"price": "0.008", "size": "218.34"}, {"price": "0.009", "size": "10.95"}, {"price": "0.01", "size": "120.34"}, {"price": "0.011", "size": "32.85"}], "asks": [{"price": "0.999", "size": "6120.59"}, {"price": "0.998", "size": "1255.55"}, {"price": "0.997", "size": "1000"}, {"price": "0.996", "size": "22.4"}, {"price": "0.99", "size": "100"}, {"price": "0.98", "size": "400"}, {"price": "0.979", "size": "15.46"}, {"price": "0.95", "size": "20"}, {"price": "0.94", "size": "33"}, {"price": "0.9", "size": "860"}, {"price": "0.899", "size": "5.63"}, {"price": "0.85", "size": "551.66"}, {"price": "0.849", "size": "300"}, {"price": "0.848", "size": "200"}, {"price": "0.8", "size": "260"}, {"price": "0.75", "size": "112"}, {"price": "0.7", "size": "86.66"}, {"price": "0.699", "size": "43"}, {"price": "0.65", "size": "68.57"}, {"price": "0.6", "size": "50"}, {"price": "0.408", "size": "100"}, {"price": "0.03", "size": "9.86"}, {"price": "0.024", "size": "35.97"}, {"price": "0.023", "size": "8.57"}, {"price": "0.017", "size": "8.57"}, {"price": "0.016", "size": "35.13"}], "event_type": "book", "last_trade_price": ""}, {"market": "0x40a82f1c7eb272cb89a71a9866b825a5b768955126678151770176c5f0238271", "asset_id": "45519542328880128648708358427981839318599846343514485569528454911282685270363", "timestamp": "1769383901937", "hash": "4f549ff345ddb8c545ef5f5e59df34a273c0d390", "bids": [{"price": "0.001", "size": "1907.99"}, {"price": "0.002", "size": "2506.26"}, {"price": "0.003", "size": "7.82"}, {"price": "0.004", "size": "2500"}, {"price": "0.005", "size": "207.48"}, {"price": "0.006", "size": "366.66"}, {"price": "0.007", "size": "100"}, {"price": "0.008", "size": "7.62"}, {"price": "0.01", "size": "50"}, {"price": "0.012", "size": "66.66"}, {"price": "0.013", "size": "38.37"}, {"price": "0.014", "size": "200"}, {"price": "0.017", "size": "79.96"}], "asks": [{"price": "0.999", "size": "6704.46"}, {"price": "0.998", "size": "1255.42"}, {"price": "0.997", "size": "1000"}, {"price": "0.996", "size": "21.92"}, {"price": "0.99", "size": "50"}, {"price": "0.98", "size": "400"}, {"price": "0.979", "size": "15.22"}, {"price": "0.95", "size": "30"}, {"price": "0.94", "size": "33"}, {"price": "0.9", "size": "860"}, {"price": "0.899", "size": "5.7"}, {"price": "0.85", "size": "551.66"}, {"price": "0.8", "size": "410"}, {"price": "0.75", "size": "262"}, {"price": "0.749", "size": "100"}, {"price": "0.7", "size": "86.66"}, {"price": "0.699", "size": "43"}, {"price": "0.65", "size": "68.57"}, {"price": "0.6", "size": "50"}, {"price": "0.404", "size": "100"}, {"price": "0.06", "size": "25"}, {"price": "0.059", "size": "68.75"}], "event_type": "book", "last_trade_price": ""}, {"market": "0x38bfda8d805cb774e2e579c35edd20a45d9cfd6726abba3936912ce7d31d01e5", "asset_id": "56252791199604096838839177402352148524634251898931099525802077679531074519272", "timestamp": "1769383901924", "hash": "74d6980b9751a1fc0080a04f4b06647807d58702", "bids": [{"price": "0.01", "size": "110.25"}, {"price": "0.02", "size": "22.05"}, {"price": "0.04", "size": "325"}, {"price": "0.05", "size": "330"}, {"price": "0.06", "size": "299.66"}, {"price": "0.07", "size": "106.51"}, {"price": "0.08", "size": "66.66"}, {"price": "0.11", "size": "146"}, {"price": "0.12", "size": "73.32"}], "asks": [{"price": "0.99", "size": "2562.43"}, {"price": "0.98", "size": "536.52"}, {"price": "0.97", "size": "300"}, {"price": "0.96", "size": "371.86"}, {"price": "0.95", "size": "220"}, {"price": "0.94", "size": "106.93"}, {"price": "0.93", "size": "69"}, {"price": "0.91", "size": "77.76"}], "event_type": "book", "last_trade_price": ""}, {"market": "0xa96f3bae6635e8f42628c39ce7b61fd566b9253d4f2699c3cac08be6d17ca723", "asset_id": "49976858258828287893504382876186665182729041451625761701208418053508589757916", "timestamp": "1769383901938", "hash": "e3543473bce2fd62449eca393ab141085757a0b8", "bids": [{"price": "0.01", "size": "1059.7"}, {"price": "0.02", "size": "400"}, {"price": "0.03", "size": "10.13"}, {"price": "0.05", "size": "30"}, {"price": "0.06", "size": "33"}, {"price": "0.09", "size": "400"}, {"price": "0.1", "size": "4000"}, {"price": "0.11", "size": "5.44"}, {"price": "0.14", "size": "242.85"}, {"price": "0.18", "size": "177.77"}, {"price": "0.19", "size": "200"}, {"price": "0.23", "size": "121.73"}, {"price": "0.28", "size": "92.85"}, {"price": "0.29", "size": "46"}, {"price": "0.32", "size": "75"}, {"price": "0.37", "size": "54.05"}, {"price": "0.54", "size": "24.07"}, {"price": "0.55", "size": "20"}, {"price": "0.82", "size": "7.42"}], "asks": [{"price": "0.99", "size": "2756.29"}, {"price": "0.98", "size": "464.43"}, {"price": "0.97", "size": "200"}, {"price": "0.96", "size": "206.52"}, {"price": "0.95", "size": "348.92"}, {"price": "0.94", "size": "136.46"}], "event_type": "book", "last_trade_price": ""}, {"market": "0x40a82f1c7eb272cb89a71a9866b825a5b768955126678151770176c5f0238271", "asset_id": "91417351034457389328213996961715046272281153995277672880388168030404378537332", "timestamp": "1769383901937", "hash": "9bc05c5a06ea3979c6dde992b41886ca52937b8c", "bids": [{"price": "0.001", "size": "6704.46"}, {"price": "0.002", "size": "1255.42"}, {"price": "0.003", "size": "1000"}, {"price": "0.004", "size": "21.92"}, {"price": "0.01", "size": "50"}, {"price": "0.02", "size": "400"}, {"price": "0.021", "size": "15.22"}, {"price": "0.05", "size": "30"}, {"price": "0.06", "size": "33"}, {"price": "0.1", "size": "860"}, {"price": "0.101", "size": "5.7"}, {"price": "0.15", "size": "551.66"}, {"price": "0.2", "size": "410"}, {"price": "0.25", "size": "262"}, {"price": "0.251", "size": "100"}, {"price": "0.3", "size": "86.66"}, {"price": "0.301", "size": "43"}, {"price": "0.35", "size": "68.57"}, {"price": "0.4", "size": "50"}, {"price": "0.596", "size": "100"}, {"price": "0.94", "size": "25"}, {"price": "0.941", "size": "68.75"}], "asks": [{"price": "0.999", "size": "1907.99"}, {"price": "0.998", "size": "2506.26"}, {"price": "0.997", "size": "7.82"}, {"price": "0.996", "size": "2500"}, {"price": "0.995", "size": "207.48"}, {"price": "0.994", "size": "366.66"}, {"price": "0.993", "size": "100"}, {"price": "0.992", "size": "7.62"}, {"price": "0.99", "size": "50"}, {"price": "0.988", "size": "66.66"}, {"price": "0.987", "size": "38.37"}, {"price": "0.986", "size": "200"}, {"price": "0.983", "size": "79.96"}], "event_type": "book", "last_trade_price": ""}, {"market": "0xe9cd6563ed540dae9cd820d8deb6080a33fbc3a589b238493519a4a96a1386e1", "asset_id": "46611422896979296181480968455950153385868875385647034766198731891278167221454", "timestamp": "1769383901915", "hash": "f502c1847d4170646a2ff359f6a51252b4088ac8", "bids": [{"price": "0.01", "size": "2361.57"}, {"price": "0.02", "size": "458.41"}, {"price": "0.03", "size": "300"}, {"price": "0.04", "size": "372.21"}, {"price": "0.05", "size": "86.66"}, {"price": "0.06", "size": "41.23"}, {"price": "0.07", "size": "16"}, {"price": "0.09", "size": "66.66"}], "asks": [{"price": "0.99", "size": "179.09"}, {"price": "0.98", "size": "21.91"}, {"price": "0.96", "size": "66.66"}, {"price": "0.95", "size": "53"}, {"price": "0.94", "size": "40.29"}, {"price": "0.92", "size": "66.66"}, {"price": "0.91", "size": "100"}], "event_type": "book", "last_trade_price": ""}, {"market": "0xe571fd2f2457d52b26ce8fdb65cfe8a12caeaafe8e056e2d9593d29fc730a758", "asset_id": "23394055358964290402162545163015593689857765681772277962977750139921172995759", "timestamp": "1769383901915", "hash": "dcee0fe82ec51b2494d98fbf76c79a34b96d4d89", "bids": [{"price": "0.001", "size": "6704.51"}, {"price": "0.002", "size": "1255.47"}, {"price": "0.003", "size": "1000"}, {"price": "0.004", "size": "22.11"}, {"price": "0.01", "size": "100"}, {"price": "0.02", "size": "400"}, {"price": "0.021", "size": "15.32"}, {"price": "0.05", "size": "20"}, {"price": "0.09", "size": "20"}, {"price": "0.1", "size": "860"}, {"price": "0.101", "size": "5.67"}, {"price": "0.15", "size": "551.66"}, {"price": "0.2", "size": "410"}, {"price": "0.25", "size": "262"}, {"price": "0.3", "size": "86.66"}, {"price": "0.305", "size": "50"}, {"price": "0.35", "size": "68.57"}, {"price": "0.39", "size": "126.28"}, {"price": "0.425", "size": "9.99"}, {"price": "0.97", "size": "500"}, {"price": "0.971", "size": "300"}, {"price": "0.973", "size": "220"}, {"price": "0.981", "size": "47.98"}, {"price": "0.982", "size": "14.33"}, {"price": "0.983", "size": "18.53"}], "asks": [{"price": "0.999", "size": "1898.99"}, {"price": "0.998", "size": "2508.66"}, {"price": "0.997", "size": "11.46"}, {"price": "0.996", "size": "2500"}, {"price": "0.995", "size": "206.8"}, {"price": "0.994", "size": "265.2"}, {"price": "0.993", "size": "16.59"}, {"price": "0.988", "size": "36.46"}], "event_type": "book", "last_trade_price": ""}, {"market": "0xd8d3819d0166dcce22f68fd24315205f4b8be323803ac55fae013032745499f7", "asset_id": "110039030678047835827290477479682636180706221087707522635871765904720785066494", "timestamp": "1769384014025", "hash": "d1e1e84423ccb3d5395dcb3b528f858b29cfea82", "bids": [{"price": "0.01", "size": "128.22"}, {"price": "0.02", "size": "23.3"}, {"price": "0.05", "size": "20"}, {"price": "0.06", "size": "99.66"}, {"price": "0.07", "size": "132.97"}, {"price": "0.09", "size": "10"}, {"price": "0.12", "size": "116.66"}], "asks": [{"price": "0.99", "size": "3315.51"}, {"price": "0.98", "size": "450"}, {"price": "0.97", "size": "350"}, {"price": "0.96", "size": "706.85"}, {"price": "0.95", "size": "30"}, {"price": "0.94", "size": "133"}, {"price": "0.93", "size": "100"}, {"price": "0.91", "size": "22"}, {"price": "0.9", "size": "10"}, {"price": "0.89", "size": "10.19"}, {"price": "0.71", "size": "100"}, {"price": "0.47", "size": "50"}], "event_type": "book", "last_trade_price": ""}, {"market": "0x90a6d406570f273840bd2e39e25dbd0a91655cd347dbb2bc381863743044bf32", "asset_id": "36331391317493054259843206160279589805054745072393638988521393636953188108839", "timestamp": "1769383901916", "hash": "ab8762bb6097adf200310ae503d2aef1f245c1e4", "bids": [{"price": "0.01", "size": "2313.74"}, {"price": "0.02", "size": "250"}, {"price": "0.03", "size": "407.91"}, {"price": "0.04", "size": "350"}, {"price": "0.05", "size": "330"}, {"price": "0.06", "size": "266.66"}, {"price": "0.07", "size": "8.93"}, {"price": "0.11", "size": "100"}, {"price": "0.14", "size": "66.66"}, {"price": "0.16", "size": "138.25"}, {"price": "0.17", "size": "66.66"}], "asks": [{"price": "0.99", "size": "123.82"}, {"price": "0.98", "size": "20.6"}, {"price": "0.94", "size": "33"}, {"price": "0.92", "size": "9.67"}, {"price": "0.91", "size": "5.73"}, {"price": "0.89", "size": "66.66"}, {"price": "0.87", "size": "100"}, {"price": "0.86", "size": "78.57"}, {"price": "0.85", "size": "72"}, {"price": "0.79", "size": "60"}, {"price": "0.78", "size": "66.66"}], "event_type": "book", "last_trade_price": ""}, {"market": "0xbf7f7047fa5719e010b9c35abab4d1510f80d78998ede7928dee762b842fd8fa", "asset_id": "99317080920004040908110146285425334348796704558628502185978368700992863001849", "timestamp": "1769383998511", "hash": "0a08c1cf58b0031d51dc25d4c83503f2cd08d525", "bids": [{"price": "0.01", "size": "65.43"}, {"price": "0.03", "size": "100"}, {"price": "0.04", "size": "55.64"}, {"price": "0.05", "size": "30"}, {"price": "0.06", "size": "33"}, {"price": "0.07", "size": "20"}, {"price": "0.08", "size": "10"}, {"price": "0.09", "size": "7.08"}, {"price": "0.31", "size": "50.43"}, {"price": "0.36", "size": "36.11"}, {"price": "0.37", "size": "29.72"}, {"price": "0.5", "size": "200"}, {"price": "0.56", "size": "40"}, {"price": "0.58", "size": "12.63"}, {"price": "0.59", "size": "8.47"}], "asks": [{"price": "0.99", "size": "2511.2"}, {"price": "0.98", "size": "300.46"}], "event_type": "book", "last_trade_price": "0.020"}, {"market": "0xa0854c2762c1df42faf2c90aadaa10001e178ecf825e974831fca1f9057bde3a", "asset_id": "81361358501706511004740839843252490883981210252691871169371735381123779679747", "timestamp": "1769383620195", "hash": "120505cfa3d78b6a293cee67248ce4077f1c5404", "bids": [{"price": "0.01", "size": "2012.53"}, {"price": "0.02", "size": "530.3"}, {"price": "0.03", "size": "7.3"}, {"price": "0.04", "size": "76"}, {"price": "0.05", "size": "10.63"}, {"price": "0.06", "size": "82.37"}, {"price": "0.09", "size": "55.99"}], "asks": [{"price": "0.99", "size": "60.42"}, {"price": "0.98", "size": "22.22"}, {"price": "0.96", "size": "325"}, {"price": "0.95", "size": "206.66"}, {"price": "0.94", "size": "33"}, {"price": "0.93", "size": "6.44"}, {"price": "0.92", "size": "66.66"}, {"price": "0.9", "size": "100"}, {"price": "0.89", "size": "79.09"}, {"price": "0.88", "size": "66.66"}], "event_type": "book", "last_trade_price": "0.110"}, {"market": "0xe16bfa632e3cde9d098182de828e7245e0cf4f8750c84abd3baac6991eec0726", "asset_id": "100749488309973909349839325632625226928519343319252966251802066191844854675345", "timestamp": "1769383917518", "hash": "ab59a1b6c267e1bed4db57115856f56797e703c8", "bids": [{"price": "0.001", "size": "6704.55"}, {"price": "0.002", "size": "1255.52"}, {"price": "0.003", "size": "1000"}, {"price": "0.004", "size": "22.27"}, {"price": "0.01", "size": "100"}, {"price": "0.02", "size": "400"}, {"price": "0.021", "size": "15.4"}, {"price": "0.05", "size": "20"}, {"price": "0.06", "size": "33"}, {"price": "0.1", "size": "860"}, {"price": "0.101", "size": "5.65"}, {"price": "0.15", "size": "551.66"}, {"price": "0.2", "size": "410"}, {"price": "0.21", "size": "449.01"}, {"price": "0.211", "size": "100"}, {"price": "0.25", "size": "112"}, {"price": "0.3", "size": "186.66"}, {"price": "0.301", "size": "200"}, {"price": "0.302", "size": "200"}, {"price": "0.313", "size": "50"}, {"price": "0.35", "size": "68.57"}, {"price": "0.4", "size": "50"}, {"price": "0.642", "size": "100"}, {"price": "0.97", "size": "258.4"}, {"price": "0.982", "size": "47.98"}, {"price": "0.983", "size": "24.06"}], "asks": [{"price": "0.999", "size": "1896.99"}, {"price": "0.998", "size": "3512.16"}, {"price": "0.997", "size": "16.08"}, {"price": "0.996", "size": "2500"}, {"price": "0.995", "size": "209.54"}, {"price": "0.994", "size": "183.67"}, {"price": "0.993", "size": "16.72"}, {"price": "0.991", "size": "56.67"}, {"price": "0.99", "size": "122.34"}, {"price": "0.989", "size": "36"}, {"price": "0.988", "size": "5.72"}, {"price": "0.987", "size": "76.67"}], "event_type": "book", "last_trade_price": ""}, {"market": "0x853c21fec9164c04490f6716b39a20faf739a54b94600a07a17925167524d24a", "asset_id": "15979230411596646053680509080157208292023265223198192295881115295360839707181", "timestamp": "1769384018106", "hash": "2c2a1c0ad0d03698b8da76edb9e0d8ef6960f48f", "bids": [{"price": "0.001", "size": "1762.99"}, {"price": "0.002", "size": "2500"}, {"price": "0.003", "size": "250"}, {"price": "0.01", "size": "600"}, {"price": "0.011", "size": "233.4"}, {"price": "0.012", "size": "30"}], "asks": [{"price": "0.999", "size": "8120.58"}, {"price": "0.998", "size": "1255.54"}, {"price": "0.997", "size": "1000"}, {"price": "0.996", "size": "22.37"}, {"price": "0.99", "size": "50"}, {"price": "0.98", "size": "400"}, {"price": "0.979", "size": "15.44"}, {"price": "0.95", "size": "30"}, {"price": "0.949", "size": "39"}, {"price": "0.92", "size": "17"}, {"price": "0.9", "size": "860"}, {"price": "0.899", "size": "5.63"}, {"price": "0.87", "size": "10"}, {"price": "0.85", "size": "561.66"}, {"price": "0.8", "size": "410"}, {"price": "0.757", "size": "7"}, {"price": "0.75", "size": "262"}, {"price": "0.7", "size": "86.66"}, {"price": "0.65", "size": "68.57"}, {"price": "0.609", "size": "20"}, {"price": "0.6", "size": "125"}, {"price": "0.089", "size": "11.99"}, {"price": "0.082", "size": "6.25"}, {"price": "0.081", "size": "20"}, {"price": "0.05", "size": "250"}, {"price": "0.018", "size": "496.07"}, {"price": "0.016", "size": "728.95"}, {"price": "0.015", "size": "53.15"}], "event_type": "book", "last_trade_price": ""}, {"market": "0xadd7737a947ee4b404262bd268a7dad202a7b93a853e59eb29c3770bdf5a3c5e", "asset_id": "34873810304813988618460030655204351211024364269964394342687234411411922138015", "timestamp": "1769383972546", "hash": "10333605b24f6dc05b7ef951ade19338d7921c2b", "bids": [{"price": "0.01", "size": "2377.23"}, {"price": "0.02", "size": "450"}, {"price": "0.03", "size": "355.83"}, {"price": "0.04", "size": "300"}, {"price": "0.05", "size": "130"}, {"price": "0.06", "size": "33"}, {"price": "0.07", "size": "10.27"}, {"price": "0.16", "size": "125"}, {"price": "0.21", "size": "66.66"}, {"price": "0.4", "size": "5"}, {"price": "0.45", "size": "6"}, {"price": "0.46", "size": "66.66"}], "asks": [{"price": "0.99", "size": "35.67"}, {"price": "0.98", "size": "45.49"}, {"price": "0.97", "size": "30"}, {"price": "0.96", "size": "17.33"}, {"price": "0.92", "size": "30"}, {"price": "0.91", "size": "111.1"}], "event_type": "book", "last_trade_price": ""}, {"market": "0x6032e72cb2b4ee54f6c27cc8b155d0233eb5c9e772de85c60e51797b1431ddf8", "asset_id": "7118736781522601355910469975087663596245621357309025148622476783856987875477", "timestamp": "1769383972617", "hash": "ffdbcee852ede033e5ca798e49d5307e6e5e2b96", "bids": [{"price": "0.01", "size": "198.66"}, {"price": "0.02", "size": "55.01"}, {"price": "0.03", "size": "50.16"}, {"price": "0.04", "size": "9.65"}, {"price": "0.05", "size": "10"}, {"price": "0.06", "size": "33"}, {"price": "0.07", "size": "60.16"}], "asks": [{"price": "0.99", "size": "2426.95"}, {"price": "0.98", "size": "450"}, {"price": "0.97", "size": "205.89"}, {"price": "0.95", "size": "20"}, {"price": "0.94", "size": "133"}, {"price": "0.93", "size": "200"}, {"price": "0.92", "size": "9"}, {"price": "0.87", "size": "143"}, {"price": "0.78", "size": "66.66"}, {"price": "0.59", "size": "5"}, {"price": "0.58", "size": "5.48"}, {"price": "0.57", "size": "66.66"}], "event_type": "book", "last_trade_price": ""}, {"market": "0x146def8be2d4ec270cac5e8cae1d60cf8ea7064200594d10e74104db6b9a60fd", "asset_id": "76512560903138059195694921143552469386897971398516938467610044078742285307792", "timestamp": "1769384015813", "hash": "66384fb8fab7f14875ffc832064f42dccd3e19a5", "bids": [{"price": "0.01", "size": "172.54"}, {"price": "0.02", "size": "20.03"}, {"price": "0.05", "size": "20"}, {"price": "0.09", "size": "172.66"}, {"price": "0.12", "size": "108.33"}, {"price": "0.13", "size": "84.61"}, {"price": "0.14", "size": "42"}, {"price": "0.19", "size": "70"}, {"price": "0.2", "size": "66.66"}], "asks": [{"price": "0.99", "size": "2355.77"}, {"price": "0.98", "size": "456"}, {"price": "0.97", "size": "300"}, {"price": "0.96", "size": "206.29"}, {"price": "0.95", "size": "186.66"}, {"price": "0.94", "size": "33"}, {"price": "0.92", "size": "14"}, {"price": "0.91", "size": "6.34"}, {"price": "0.88", "size": "66.66"}, {"price": "0.84", "size": "81.25"}, {"price": "0.82", "size": "61.11"}, {"price": "0.81", "size": "66.66"}], "event_type": "book", "last_trade_price": ""}, {"market": "0x6f14e52f6a1502a35406feea3f0e8d42502bbf1199e42c73a743fe1745ccc12c", "asset_id": "17811605278785499666964340297379704435403265198212995098387642426099375215061", "timestamp": "1769384020577", "hash": "d2d41ebb81e17611a5476eb9880decc04d6a04e9", "bids": [{"price": "0.01", "size": "3360.28"}, {"price": "0.02", "size": "250"}, {"price": "0.03", "size": "5.87"}, {"price": "0.05", "size": "655"}, {"price": "0.06", "size": "899.66"}, {"price": "0.07", "size": "10.29"}, {"price": "0.08", "size": "30"}, {"price": "0.1", "size": "340"}, {"price": "0.11", "size": "125"}, {"price": "0.13", "size": "246.15"}, {"price": "0.16", "size": "275"}, {"price": "0.19", "size": "136.84"}, {"price": "0.22", "size": "109.09"}, {"price": "0.26", "size": "76.92"}, {"price": "0.31", "size": "66.66"}, {"price": "0.37", "size": "10"}, {"price": "0.39", "size": "33.33"}, {"price": "0.4", "size": "27.5"}, {"price": "0.55", "size": "119.09"}, {"price": "0.56", "size": "66.66"}, {"price": "0.57", "size": "16.12"}], "asks": [{"price": "0.99", "size": "105.06"}, {"price": "0.98", "size": "20.97"}, {"price": "0.96", "size": "325"}, {"price": "0.95", "size": "300"}, {"price": "0.94", "size": "233.32"}, {"price": "0.93", "size": "100"}, {"price": "0.91", "size": "157.99"}, {"price": "0.9", "size": "66.66"}, {"price": "0.77", "size": "50"}], "event_type": "book", "last_trade_price": ""}, {"market": "0xf916b98c173470389af02fa32236bea1333cf05199ee997bc64a39ad6bd589ee", "asset_id": "91462927649974781483669557862921344444854660701074121664666696309988647910790", "timestamp": "1769384014025", "hash": "d45367349230f549833ae1afc98a7705717e9033", "bids": [{"price": "0.01", "size": "66.66"}, {"price": "0.02", "size": "112.96"}, {"price": "0.03", "size": "66.66"}, {"price": "0.04", "size": "75"}, {"price": "0.05", "size": "8.23"}, {"price": "0.08", "size": "66.66"}, {"price": "0.09", "size": "111.1"}], "asks": [{"price": "0.99", "size": "3310.09"}, {"price": "0.98", "size": "450"}, {"price": "0.97", "size": "706.98"}, {"price": "0.95", "size": "130"}, {"price": "0.94", "size": "233"}, {"price": "0.93", "size": "9.85"}, {"price": "0.89", "size": "125"}, {"price": "0.78", "size": "98"}, {"price": "0.58", "size": "100"}, {"price": "0.57", "size": "5"}, {"price": "0.23", "size": "55.48"}], "event_type": "book", "last_trade_price": ""}, {"market": "0x853c21fec9164c04490f6716b39a20faf739a54b94600a07a17925167524d24a", "asset_id": "67943936326411950699380754459398390458771532481725144845477238890627646410860", "timestamp": "1769384018106", "hash": "3eade60ceeec045d4bbde95b9f427d540e4086fe", "bids": [{"price": "0.001", "size": "8120.58"}, {"price": "0.002", "size": "1255.54"}, {"price": "0.003", "size": "1000"}, {"price": "0.004", "size": "22.37"}, {"price": "0.01", "size": "50"}, {"price": "0.02", "size": "400"}, {"price": "0.021", "size": "15.44"}, {"price": "0.05", "size": "30"}, {"price": "0.051", "size": "39"}, {"price": "0.08", "size": "17"}, {"price": "0.1", "size": "860"}, {"price": "0.101", "size": "5.63"}, {"price": "0.13", "size": "10"}, {"price": "0.15", "size": "561.66"}, {"price": "0.2", "size": "410"}, {"price": "0.243", "size": "7"}, {"price": "0.25", "size": "262"}, {"price": "0.3", "size": "86.66"}, {"price": "0.35", "size": "68.57"}, {"price": "0.391", "size": "20"}, {"price": "0.4", "size": "125"}, {"price": "0.911", "size": "11.99"}, {"price": "0.918", "size": "6.25"}, {"price": "0.919", "size": "20"}, {"price": "0.95", "size": "250"}, {"price": "0.982", "size": "496.07"}, {"price": "0.984", "size": "728.95"}, {"price": "0.985", "size": "53.15"}], "asks": [{"price": "0.999", "size": "1762.99"}, {"price": "0.998", "size": "2500"}, {"price": "0.997", "size": "250"}, {"price": "0.99", "size": "600"}, {"price": "0.989", "size": "233.4"}, {"price": "0.988", "size": "30"}], "event_type": "book", "last_trade_price": ""}, {"market": "0xeafa01c5d48d6b7826e91f7b31e4a61a05b3fc8a1ad8ccdb2ccbad91b616ae40", "asset_id": "97279369561823536114577996580038127500018967849090745350406495876539022297477", "timestamp": "1769384022054", "hash": "2c285083e4e18bca7265aee495a108f66efe66ee", "bids": [{"price": "0.01", "size": "105.62"}, {"price": "0.02", "size": "40.04"}, {"price": "0.03", "size": "19.94"}, {"price": "0.04", "size": "45.78"}, {"price": "0.1", "size": "50"}], "asks": [{"price": "0.99", "size": "2905.1"}, {"price": "0.98", "size": "400"}, {"price": "0.97", "size": "9.79"}, {"price": "0.95", "size": "20"}, {"price": "0.94", "size": "33"}, {"price": "0.92", "size": "750"}, {"price": "0.91", "size": "7.28"}, {"price": "0.89", "size": "634.09"}, {"price": "0.85", "size": "213.33"}, {"price": "0.81", "size": "147.36"}, {"price": "0.77", "size": "113.04"}, {"price": "0.73", "size": "88.88"}, {"price": "0.7", "size": "66.66"}, {"price": "0.69", "size": "33"}, {"price": "0.64", "size": "100"}, {"price": "0.63", "size": "5"}, {"price": "0.5", "size": "5"}, {"price": "0.4", "size": "5"}, {"price": "0.35", "size": "58.46"}, {"price": "0.29", "size": "56.3"}], "event_type": "book", "last_trade_price": ""}, {"market": "0xd8d3819d0166dcce22f68fd24315205f4b8be323803ac55fae013032745499f7", "asset_id": "66248863053233981483390075184660170267560753276478697725455087633235785089364", "timestamp": "1769384014025", "hash": "c9e0992bf936e04f0a58a9978d99b6c183bfd3e1", "bids": [{"price": "0.01", "size": "3315.51"}, {"price": "0.02", "size": "450"}, {"price": "0.03", "size": "350"}, {"price": "0.04", "size": "706.85"}, {"price": "0.05", "size": "30"}, {"price": "0.06", "size": "133"}, {"price": "0.07", "size": "100"}, {"price": "0.09", "size": "22"}, {"price": "0.1", "size": "10"}, {"price": "0.11", "size": "10.19"}, {"price": "0.29", "size": "100"}, {"price": "0.53", "size": "50"}], "asks": [{"price": "0.99", "size": "128.22"}, {"price": "0.98", "size": "23.3"}, {"price": "0.95", "size": "20"}, {"price": "0.94", "size": "99.66"}, {"price": "0.93", "size": "132.97"}, {"price": "0.91", "size": "10"}, {"price": "0.88", "size": "116.66"}], "event_type": "book", "last_trade_price": ""}, {"market": "0x00df4f2883a699f69eda6a02d040dd6c17a0cfbfc75b0324b97e309455a630ca", "asset_id": "81078558306986282344667326985050749711978067313168619570309625100888817734475", "timestamp": "1769383901923", "hash": "4d0129ca5ce9472923aef18ddb486758b9483ab5", "bids": [{"price": "0.001", "size": "1616"}, {"price": "0.002", "size": "350"}, {"price": "0.003", "size": "309.06"}, {"price": "0.004", "size": "254.86"}, {"price": "0.005", "size": "69.2"}, {"price": "0.006", "size": "69.2"}, {"price": "0.007", "size": "24.4"}], "asks": [{"price": "0.999", "size": "6704.19"}, {"price": "0.998", "size": "1255.16"}, {"price": "0.997", "size": "1000"}, {"price": "0.996", "size": "20.92"}, {"price": "0.99", "size": "50"}, {"price": "0.98", "size": "400"}, {"price": "0.979", "size": "14.71"}, {"price": "0.95", "size": "30"}, {"price": "0.94", "size": "33"}, {"price": "0.9", "size": "860"}, {"price": "0.899", "size": "5.85"}, {"price": "0.85", "size": "551.66"}, {"price": "0.8", "size": "160"}, {"price": "0.777", "size": "17"}, {"price": "0.75", "size": "112"}, {"price": "0.749", "size": "100"}, {"price": "0.7", "size": "86.66"}, {"price": "0.65", "size": "68.57"}, {"price": "0.649", "size": "34"}, {"price": "0.6", "size": "50"}, {"price": "0.477", "size": "5"}, {"price": "0.381", "size": "130"}, {"price": "0.02", "size": "29.98"}, {"price": "0.019", "size": "29.95"}, {"price": "0.017", "size": "4.04"}, {"price": "0.015", "size": "25"}, {"price": "0.014", "size": "42.47"}, {"price": "0.013", "size": "8.99"}], "event_type": "book", "last_trade_price": ""}, {"market": "0xbf7f7047fa5719e010b9c35abab4d1510f80d78998ede7928dee762b842fd8fa", "asset_id": "80475936180674486630534655774036670401396382603097237786734519090691938222605", "timestamp": "1769383998511", "hash": "5ecfe28bb0f15fd56ed80de2c8b94732c6751f03", "bids": [{"price": "0.01", "size": "2511.2"}, {"price": "0.02", "size": "300.46"}], "asks": [{"price": "0.99", "size": "65.43"}, {"price": "0.97", "size": "100"}, {"price": "0.96", "size": "55.64"}, {"price": "0.95", "size": "30"}, {"price": "0.94", "size": "33"}, {"price": "0.93", "size": "20"}, {"price": "0.92", "size": "10"}, {"price": "0.91", "size": "7.08"}, {"price": "0.69", "size": "50.43"}, {"price": "0.64", "size": "36.11"}, {"price": "0.63", "size": "29.72"}, {"price": "0.5", "size": "200"}, {"price": "0.44", "size": "40"}, {"price": "0.42", "size": "12.63"}, {"price": "0.41", "size": "8.47"}], "event_type": "book", "last_trade_price": "0.020"}, {"market": "0x335a07913dc4afbc345e5a87410ed1cde3c0b168df2627733d49b081526fd002", "asset_id": "87400156771035739647299903622267629973291296986678621415627996460491040207279", "timestamp": "1769384016562", "hash": "517b4e9bc1870c371802121a4c13d2a56bf2c97d", "bids": [{"price": "0.001", "size": "4048.17"}, {"price": "0.002", "size": "1255.14"}, {"price": "0.003", "size": "1000"}, {"price": "0.004", "size": "21.09"}, {"price": "0.01", "size": "100"}, {"price": "0.02", "size": "500"}, {"price": "0.021", "size": "14.68"}, {"price": "0.05", "size": "20"}, {"price": "0.051", "size": "39"}, {"price": "0.07", "size": "20"}, {"price": "0.1", "size": "860"}, {"price": "0.101", "size": "5.86"}, {"price": "0.15", "size": "551.66"}, {"price": "0.2", "size": "160"}, {"price": "0.201", "size": "155"}, {"price": "0.22", "size": "5"}, {"price": "0.25", "size": "112"}, {"price": "0.3", "size": "86.66"}, {"price": "0.35", "size": "73.57"}, {"price": "0.4", "size": "237"}, {"price": "0.913", "size": "19.99"}, {"price": "0.958", "size": "19.99"}], "asks": [{"price": "0.999", "size": "1927.99"}, {"price": "0.998", "size": "2842.55"}, {"price": "0.997", "size": "405.61"}, {"price": "0.996", "size": "261.88"}], "event_type": "book", "last_trade_price": "0.007"}, {"market": "0x679bcdd7ed5e81e87f560a516b2ff3b419be87aeb995550b728c75a222bbfd14", "asset_id": "20310121731492329356556661175693279243075784612953975064227117258195086943533", "timestamp": "1769384014025", "hash": "ba6cf4ec33f0db51dde210fc5c600f595a4e2e0d", "bids": [{"price": "0.01", "size": "2423.03"}, {"price": "0.02", "size": "350"}, {"price": "0.03", "size": "206.25"}, {"price": "0.05", "size": "200"}, {"price": "0.06", "size": "133"}, {"price": "0.07", "size": "100"}, {"price": "0.08", "size": "9.36"}, {"price": "0.17", "size": "141.66"}, {"price": "0.32", "size": "6"}, {"price": "0.34", "size": "66.66"}, {"price": "0.62", "size": "50"}], "asks": [{"price": "0.99", "size": "128.57"}, {"price": "0.98", "size": "24.33"}, {"price": "0.96", "size": "66.66"}, {"price": "0.95", "size": "30"}, {"price": "0.94", "size": "104.57"}, {"price": "0.93", "size": "110"}, {"price": "0.92", "size": "79.16"}], "event_type": "book", "last_trade_price": ""}, {"market": "0xd2b2d52f7b03ee5ddc6f79596f8e058eedf95af2c9df32fc5a9d6b3f7d4de949", "asset_id": "77757001671665002605821663755609213754761394915884653403308048610819412553431", "timestamp": "1769384000842", "hash": "487e2209c512e42cdffa513f71a059cd794629d1", "bids": [{"price": "0.01", "size": "2426.94"}, {"price": "0.02", "size": "450"}, {"price": "0.03", "size": "7.5"}, {"price": "0.05", "size": "20"}, {"price": "0.06", "size": "33"}, {"price": "0.08", "size": "25"}, {"price": "0.09", "size": "7.46"}, {"price": "0.18", "size": "112"}, {"price": "0.25", "size": "66.66"}, {"price": "0.33", "size": "33.33"}, {"price": "0.43", "size": "2.63"}, {"price": "0.44", "size": "29.54"}, {"price": "0.45", "size": "66.66"}], "asks": [{"price": "0.99", "size": "66.37"}, {"price": "0.97", "size": "9"}, {"price": "0.96", "size": "7.33"}, {"price": "0.95", "size": "10"}, {"price": "0.94", "size": "9.05"}, {"price": "0.82", "size": "72.22"}, {"price": "0.79", "size": "52.38"}, {"price": "0.72", "size": "50"}, {"price": "0.71", "size": "32.76"}], "event_type": "book", "last_trade_price": "0.640"}, {"market": "0x90a6d406570f273840bd2e39e25dbd0a91655cd347dbb2bc381863743044bf32", "asset_id": "92143930323152159931232014367424593746113767612080401756819785961080544448740", "timestamp": "1769383901916", "hash": "7c412bd89a465da37bada58605f120a7f2e13941", "bids": [{"price": "0.01", "size": "123.82"}, {"price": "0.02", "size": "20.6"}, {"price": "0.06", "size": "33"}, {"price": "0.08", "size": "9.67"}, {"price": "0.09", "size": "5.73"}, {"price": "0.11", "size": "66.66"}, {"price": "0.13", "size": "100"}, {"price": "0.14", "size": "78.57"}, {"price": "0.15", "size": "72"}, {"price": "0.21", "size": "60"}, {"price": "0.22", "size": "66.66"}], "asks": [{"price": "0.99", "size": "2313.74"}, {"price": "0.98", "size": "250"}, {"price": "0.97", "size": "407.91"}, {"price": "0.96", "size": "350"}, {"price": "0.95", "size": "330"}, {"price": "0.94", "size": "266.66"}, {"price": "0.93", "size": "8.93"}, {"price": "0.89", "size": "100"}, {"price": "0.86", "size": "66.66"}, {"price": "0.84", "size": "138.25"}, {"price": "0.83", "size": "66.66"}], "event_type": "book", "last_trade_price": ""}, {"market": "0x438cec99837cc33e85826174eb25751662a4e9e60789da929036919364982ea9", "asset_id": "98451237227420325374437189264809152820462048575747897033376086871833682035193", "timestamp": "1769383891642", "hash": "6f2e25c655faf93b257be70887b44dde8efe0cb4", "bids": [{"price": "0.001", "size": "5553.99"}, {"price": "0.002", "size": "2511.43"}, {"price": "0.003", "size": "257.57"}, {"price": "0.004", "size": "44.4"}, {"price": "0.01", "size": "544.66"}, {"price": "0.011", "size": "79.96"}, {"price": "0.012", "size": "79.96"}, {"price": "0.013", "size": "74.75"}], "asks": [{"price": "0.999", "size": "6704.4"}, {"price": "0.998", "size": "1255.37"}, {"price": "0.997", "size": "1000"}, {"price": "0.996", "size": "21.71"}, {"price": "0.99", "size": "50"}, {"price": "0.98", "size": "400"}, {"price": "0.979", "size": "15.11"}, {"price": "0.95", "size": "30"}, {"price": "0.94", "size": "33"}, {"price": "0.9", "size": "860"}, {"price": "0.899", "size": "5.73"}, {"price": "0.85", "size": "551.66"}, {"price": "0.842", "size": "100"}, {"price": "0.841", "size": "400"}, {"price": "0.84", "size": "200"}, {"price": "0.831", "size": "299.3"}, {"price": "0.8", "size": "160"}, {"price": "0.799", "size": "100"}, {"price": "0.75", "size": "112"}, {"price": "0.7", "size": "86.66"}, {"price": "0.697", "size": "25"}, {"price": "0.65", "size": "68.57"}, {"price": "0.6", "size": "50"}, {"price": "0.406", "size": "100"}, {"price": "0.019", "size": "39.99"}, {"price": "0.018", "size": "18.37"}, {"price": "0.015", "size": "32"}, {"price": "0.014", "size": "15"}], "event_type": "book", "last_trade_price": "0.013"}, {"market": "0x01ad0cec215d379cf4954c08a5ac7afcd2342ff7342d138dff158ecf6c3a640b", "asset_id": "77683472718848385225652140478634600509100493592611938673765294225562480203195", "timestamp": "1769383901937", "hash": "a497fc549f8c6344598b97de1d8a0b40e5d2232e", "bids": [{"price": "0.001", "size": "6120.59"}, {"price": "0.002", "size": "1255.55"}, {"price": "0.003", "size": "1000"}, {"price": "0.004", "size": "22.4"}, {"price": "0.01", "size": "100"}, {"price": "0.02", "size": "400"}, {"price": "0.021", "size": "15.46"}, {"price": "0.05", "size": "20"}, {"price": "0.06", "size": "33"}, {"price": "0.1", "size": "860"}, {"price": "0.101", "size": "5.63"}, {"price": "0.15", "size": "551.66"}, {"price": "0.151", "size": "300"}, {"price": "0.152", "size": "200"}, {"price": "0.2", "size": "260"}, {"price": "0.25", "size": "112"}, {"price": "0.3", "size": "86.66"}, {"price": "0.301", "size": "43"}, {"price": "0.35", "size": "68.57"}, {"price": "0.4", "size": "50"}, {"price": "0.592", "size": "100"}, {"price": "0.97", "size": "9.86"}, {"price": "0.976", "size": "35.97"}, {"price": "0.977", "size": "8.57"}, {"price": "0.983", "size": "8.57"}, {"price": "0.984", "size": "35.13"}], "asks": [{"price": "0.999", "size": "1892.99"}, {"price": "0.998", "size": "2500"}, {"price": "0.997", "size": "13.51"}, {"price": "0.996", "size": "2500"}, {"price": "0.995", "size": "250"}, {"price": "0.994", "size": "19.61"}, {"price": "0.993", "size": "1400"}, {"price": "0.992", "size": "218.34"}, {"price": "0.991", "size": "10.95"}, {"price": "0.99", "size": "120.34"}, {"price": "0.989", "size": "32.85"}], "event_type": "book", "last_trade_price": ""}, {"market": "0x5b17571f0687e9ef62aead3a3e57bfc617f16e4806865d8b7cc609a680ac9892", "asset_id": "54672482098306675309495708206879727568512955356356264682879888123590518385092", "timestamp": "1769384020577", "hash": "04bd23353297f08a5d18dec08685f35f9bb9fa3b", "bids": [{"price": "0.01", "size": "1061.13"}, {"price": "0.02", "size": "400"}, {"price": "0.03", "size": "7.61"}, {"price": "0.05", "size": "30"}, {"price": "0.06", "size": "33"}, {"price": "0.09", "size": "900"}, {"price": "0.1", "size": "300"}, {"price": "0.11", "size": "6"}, {"price": "0.14", "size": "325"}, {"price": "0.15", "size": "162"}, {"price": "0.17", "size": "100"}, {"price": "0.21", "size": "50"}, {"price": "0.4", "size": "32.5"}, {"price": "0.41", "size": "126.82"}, {"price": "0.58", "size": "100"}, {"price": "0.6", "size": "30"}, {"price": "0.63", "size": "13.1"}, {"price": "0.66", "size": "11.53"}, {"price": "0.67", "size": "7.46"}], "asks": [{"price": "0.99", "size": "2550"}, {"price": "0.98", "size": "25.02"}], "event_type": "book", "last_trade_price": "0.020"}, {"market": "0x7a3a3ab1573e95640462d73202fcee6d6ff66f91630d14296a1f71fa5b918bfa", "asset_id": "22238013475081219064410839764368731545802811151601899423291363232635951279796", "timestamp": "1769383901922", "hash": "e85398e22d49cfd0d1e9f56779370456f77ef6dd", "bids": [{"price": "0.001", "size": "2110.38"}, {"price": "0.002", "size": "1255.34"}, {"price": "0.003", "size": "2000"}, {"price": "0.004", "size": "21.61"}, {"price": "0.02", "size": "400"}, {"price": "0.021", "size": "15.07"}, {"price": "0.05", "size": "20"}, {"price": "0.051", "size": "39"}, {"price": "0.1", "size": "860"}, {"price": "0.101", "size": "5.75"}, {"price": "0.15", "size": "551.66"}, {"price": "0.2", "size": "410"}, {"price": "0.25", "size": "262"}, {"price": "0.251", "size": "106"}, {"price": "0.3", "size": "86.66"}, {"price": "0.35", "size": "68.57"}, {"price": "0.4", "size": "125"}, {"price": "0.534", "size": "7.5"}, {"price": "0.536", "size": "7.5"}, {"price": "0.951", "size": "121.53"}, {"price": "0.97", "size": "629.5"}, {"price": "0.972", "size": "25"}, {"price": "0.973", "size": "14.81"}], "asks": [{"price": "0.999", "size": "3488.99"}, {"price": "0.998", "size": "4776.31"}, {"price": "0.997", "size": "183.44"}, {"price": "0.996", "size": "2613.01"}, {"price": "0.995", "size": "312.35"}, {"price": "0.994", "size": "293.24"}, {"price": "0.993", "size": "308.73"}, {"price": "0.992", "size": "291.6"}, {"price": "0.991", "size": "23.82"}, {"price": "0.99", "size": "44.44"}, {"price": "0.989", "size": "9.09"}], "event_type": "book", "last_trade_price": ""}, {"market": "0x6032e72cb2b4ee54f6c27cc8b155d0233eb5c9e772de85c60e51797b1431ddf8", "asset_id": "44848013696493898639828007101683655834417396378616727747692199122767015662748", "timestamp": "1769383972617", "hash": "fbdbc934025b1f2dffc3d3a19424284e1ef4b79e", "bids": [{"price": "0.01", "size": "2426.95"}, {"price": "0.02", "size": "450"}, {"price": "0.03", "size": "205.89"}, {"price": "0.05", "size": "20"}, {"price": "0.06", "size": "133"}, {"price": "0.07", "size": "200"}, {"price": "0.08", "size": "9"}, {"price": "0.13", "size": "143"}, {"price": "0.22", "size": "66.66"}, {"price": "0.41", "size": "5"}, {"price": "0.42", "size": "5.48"}, {"price": "0.43", "size": "66.66"}], "asks": [{"price": "0.99", "size": "198.66"}, {"price": "0.98", "size": "55.01"}, {"price": "0.97", "size": "50.16"}, {"price": "0.96", "size": "9.65"}, {"price": "0.95", "size": "10"}, {"price": "0.94", "size": "33"}, {"price": "0.93", "size": "60.16"}], "event_type": "book", "last_trade_price": ""}, {"market": "0x21fcddff254ff0337ac03ec276927cc90e5228ac1c5b16c36300589318197fc4", "asset_id": "41605452123604733553647691830638760854992806694633100987207040539420095696757", "timestamp": "1769384014025", "hash": "6e85c7ea64c4b378186d0c0d6a66d9538f405d10", "bids": [{"price": "0.01", "size": "105.04"}, {"price": "0.02", "size": "14.27"}, {"price": "0.03", "size": "55.33"}, {"price": "0.04", "size": "6.43"}, {"price": "0.05", "size": "20"}, {"price": "0.06", "size": "81.99"}], "asks": [{"price": "0.99", "size": "3378.69"}, {"price": "0.98", "size": "850"}, {"price": "0.97", "size": "250"}, {"price": "0.96", "size": "105.33"}, {"price": "0.95", "size": "30"}, {"price": "0.94", "size": "33"}, {"price": "0.93", "size": "300"}, {"price": "0.92", "size": "200"}, {"price": "0.91", "size": "50"}, {"price": "0.89", "size": "6.05"}, {"price": "0.68", "size": "66.66"}, {"price": "0.67", "size": "6"}, {"price": "0.37", "size": "116.66"}], "event_type": "book", "last_trade_price": ""}, {"market": "0x6f14e52f6a1502a35406feea3f0e8d42502bbf1199e42c73a743fe1745ccc12c", "asset_id": "64289097521554308111154900994757912304033484898403308857843640646685729282110", "timestamp": "1769384020577", "hash": "5333c4a849862ee378cbb6b9bb97d0c02b8cb886", "bids": [{"price": "0.01", "size": "105.06"}, {"price": "0.02", "size": "20.97"}, {"price": "0.04", "size": "325"}, {"price": "0.05", "size": "300"}, {"price": "0.06", "size": "233.32"}, {"price": "0.07", "size": "100"}, {"price": "0.09", "size": "157.99"}, {"price": "0.1", "size": "66.66"}, {"price": "0.23", "size": "50"}], "asks": [{"price": "0.99", "size": "3360.28"}, {"price": "0.98", "size": "250"}, {"price": "0.97", "size": "5.87"}, {"price": "0.95", "size": "655"}, {"price": "0.94", "size": "899.66"}, {"price": "0.93", "size": "10.29"}, {"price": "0.92", "size": "30"}, {"price": "0.9", "size": "340"}, {"price": "0.89", "size": "125"}, {"price": "0.87", "size": "246.15"}, {"price": "0.84", "size": "275"}, {"price": "0.81", "size": "136.84"}, {"price": "0.78", "size": "109.09"}, {"price": "0.74", "size": "76.92"}, {"price": "0.69", "size": "66.66"}, {"price": "0.63", "size": "10"}, {"price": "0.61", "size": "33.33"}, {"price": "0.6", "size": "27.5"}, {"price": "0.45", "size": "119.09"}, {"price": "0.44", "size": "66.66"}, {"price": "0.43", "size": "16.12"}], "event_type": "book", "last_trade_price": ""}, {"market": "0x68e08317aa8d51a5b697eb56de90fa23e4c344d4ff28d73255068e9d8640178f", "asset_id": "88335759156597932599134335662153790300542900810978918405965535730553193972843", "timestamp": "1769383901933", "hash": "a9b98e93d4a3b7f4c07666481695fd7dd4bc049e", "bids": [{"price": "0.01", "size": "124.16"}, {"price": "0.02", "size": "21.61"}, {"price": "0.05", "size": "20"}, {"price": "0.06", "size": "33"}, {"price": "0.08", "size": "12.5"}, {"price": "0.09", "size": "5.47"}, {"price": "0.11", "size": "66.66"}, {"price": "0.12", "size": "91.66"}, {"price": "0.13", "size": "100"}, {"price": "0.14", "size": "50"}, {"price": "0.19", "size": "70"}, {"price": "0.2", "size": "66.66"}], "asks": [{"price": "0.99", "size": "2310.2"}, {"price": "0.98", "size": "459.47"}, {"price": "0.97", "size": "350"}, {"price": "0.96", "size": "331.27"}, {"price": "0.95", "size": "340"}, {"price": "0.94", "size": "299.66"}, {"price": "0.93", "size": "106.53"}, {"price": "0.92", "size": "193.66"}, {"price": "0.88", "size": "74.99"}], "event_type": "book", "last_trade_price": ""}, {"market": "0xd2b2d52f7b03ee5ddc6f79596f8e058eedf95af2c9df32fc5a9d6b3f7d4de949", "asset_id": "49722951406964623396190322027929924958979018653915811865810011588719564539488", "timestamp": "1769384000842", "hash": "b8604bed631abdc3fe1544e16da10beb495f7021", "bids": [{"price": "0.01", "size": "66.37"}, {"price": "0.03", "size": "9"}, {"price": "0.04", "size": "7.33"}, {"price": "0.05", "size": "10"}, {"price": "0.06", "size": "9.05"}, {"price": "0.18", "size": "72.22"}, {"price": "0.21", "size": "52.38"}, {"price": "0.28", "size": "50"}, {"price": "0.29", "size": "32.76"}], "asks": [{"price": "0.99", "size": "2426.94"}, {"price": "0.98", "size": "450"}, {"price": "0.97", "size": "7.5"}, {"price": "0.95", "size": "20"}, {"price": "0.94", "size": "33"}, {"price": "0.92", "size": "25"}, {"price": "0.91", "size": "7.46"}, {"price": "0.82", "size": "112"}, {"price": "0.75", "size": "66.66"}, {"price": "0.67", "size": "33.33"}, {"price": "0.57", "size": "2.63"}, {"price": "0.56", "size": "29.54"}, {"price": "0.55", "size": "66.66"}], "event_type": "book", "last_trade_price": "0.640"}, {"market": "0xe571fd2f2457d52b26ce8fdb65cfe8a12caeaafe8e056e2d9593d29fc730a758", "asset_id": "41132525161236780028361472461115170294668351550323666177187658714179089570569", "timestamp": "1769383901915", "hash": "cd3e35a351d047ac7e7d50159bdc197faeefabe2", "bids": [{"price": "0.001", "size": "1898.99"}, {"price": "0.002", "size": "2508.66"}, {"price": "0.003", "size": "11.46"}, {"price": "0.004", "size": "2500"}, {"price": "0.005", "size": "206.8"}, {"price": "0.006", "size": "265.2"}, {"price": "0.007", "size": "16.59"}, {"price": "0.012", "size": "36.46"}], "asks": [{"price": "0.999", "size": "6704.51"}, {"price": "0.998", "size": "1255.47"}, {"price": "0.997", "size": "1000"}, {"price": "0.996", "size": "22.11"}, {"price": "0.99", "size": "100"}, {"price": "0.98", "size": "400"}, {"price": "0.979", "size": "15.32"}, {"price": "0.95", "size": "20"}, {"price": "0.91", "size": "20"}, {"price": "0.9", "size": "860"}, {"price": "0.899", "size": "5.67"}, {"price": "0.85", "size": "551.66"}, {"price": "0.8", "size": "410"}, {"price": "0.75", "size": "262"}, {"price": "0.7", "size": "86.66"}, {"price": "0.695", "size": "50"}, {"price": "0.65", "size": "68.57"}, {"price": "0.61", "size": "126.28"}, {"price": "0.575", "size": "9.99"}, {"price": "0.03", "size": "500"}, {"price": "0.029", "size": "300"}, {"price": "0.027", "size": "220"}, {"price": "0.019", "size": "47.98"}, {"price": "0.018", "size": "14.33"}, {"price": "0.017", "size": "18.53"}], "event_type": "book", "last_trade_price": ""}, {"market": "0x70d9be5faefbfdef38512a6d9e4392db3084d813ea56f989bd23400fda437b5d", "asset_id": "98030581449575327310479171744260311446081913603336917524388058189639018780846", "timestamp": "1769383935332", "hash": "c44ad6d4bdbcca63947d1de8abe66ca772d91fc1", "bids": [{"price": "0.01", "size": "3319.44"}, {"price": "0.02", "size": "850"}, {"price": "0.03", "size": "209.49"}, {"price": "0.04", "size": "113.02"}, {"price": "0.05", "size": "30"}, {"price": "0.06", "size": "233"}, {"price": "0.07", "size": "20"}, {"price": "0.14", "size": "92.85"}, {"price": "0.19", "size": "81"}, {"price": "0.38", "size": "100"}, {"price": "0.4", "size": "27.5"}, {"price": "0.43", "size": "5"}, {"price": "0.71", "size": "50"}], "asks": [{"price": "0.99", "size": "56.15"}, {"price": "0.98", "size": "10.57"}, {"price": "0.97", "size": "463.33"}, {"price": "0.96", "size": "444.49"}, {"price": "0.95", "size": "320"}, {"price": "0.94", "size": "299.66"}, {"price": "0.93", "size": "169"}, {"price": "0.92", "size": "72.25"}, {"price": "0.9", "size": "100"}, {"price": "0.89", "size": "59.09"}, {"price": "0.87", "size": "66.66"}], "event_type": "book", "last_trade_price": ""}, {"market": "0xf916b98c173470389af02fa32236bea1333cf05199ee997bc64a39ad6bd589ee", "asset_id": "41743802686443315505082888602082131066672260628700340336384534887243556020231", "timestamp": "1769384014025", "hash": "7b0296701e15055274abc57789c37e8f444b24fc", "bids": [{"price": "0.01", "size": "3310.09"}, {"price": "0.02", "size": "450"}, {"price": "0.03", "size": "706.98"}, {"price": "0.05", "size": "130"}, {"price": "0.06", "size": "233"}, {"price": "0.07", "size": "9.85"}, {"price": "0.11", "size": "125"}, {"price": "0.22", "size": "98"}, {"price": "0.42", "size": "100"}, {"price": "0.43", "size": "5"}, {"price": "0.77", "size": "55.48"}], "asks": [{"price": "0.99", "size": "66.66"}, {"price": "0.98", "size": "112.96"}, {"price": "0.97", "size": "66.66"}, {"price": "0.96", "size": "75"}, {"price": "0.95", "size": "8.23"}, {"price": "0.92", "size": "66.66"}, {"price": "0.91", "size": "111.1"}], "event_type": "book", "last_trade_price": ""}, {"market": "0xe9cd6563ed540dae9cd820d8deb6080a33fbc3a589b238493519a4a96a1386e1", "asset_id": "113376900619893687034938245776304374252728745783907649375498285356692355344325", "timestamp": "1769383901915", "hash": "5bedff569f2b589608966f9268fee9486c93a670", "bids": [{"price": "0.01", "size": "179.09"}, {"price": "0.02", "size": "21.91"}, {"price": "0.04", "size": "66.66"}, {"price": "0.05", "size": "53"}, {"price": "0.06", "size": "40.29"}, {"price": "0.08", "size": "66.66"}, {"price": "0.09", "size": "100"}], "asks": [{"price": "0.99", "size": "2361.57"}, {"price": "0.98", "size": "458.41"}, {"price": "0.97", "size": "300"}, {"price": "0.96", "size": "372.21"}, {"price": "0.95", "size": "86.66"}, {"price": "0.94", "size": "41.23"}, {"price": "0.93", "size": "16"}, {"price": "0.91", "size": "66.66"}], "event_type": "book", "last_trade_price": ""}, {"market": "0x38bfda8d805cb774e2e579c35edd20a45d9cfd6726abba3936912ce7d31d01e5", "asset_id": "82984493553960547995768645993390544042265848130155655928734798493724954060593", "timestamp": "1769383901924", "hash": "8cb8ba71eadf3af2bc7a6bccf49050a324b1bdbd", "bids": [{"price": "0.01", "size": "2562.43"}, {"price": "0.02", "size": "536.52"}, {"price": "0.03", "size": "300"}, {"price": "0.04", "size": "371.86"}, {"price": "0.05", "size": "220"}, {"price": "0.06", "size": "106.93"}, {"price": "0.07", "size": "69"}, {"price": "0.09", "size": "77.76"}], "asks": [{"price": "0.99", "size": "110.25"}, {"price": "0.98", "size": "22.05"}, {"price": "0.96", "size": "325"}, {"price": "0.95", "size": "330"}, {"price": "0.94", "size": "299.66"}, {"price": "0.93", "size": "106.51"}, {"price": "0.92", "size": "66.66"}, {"price": "0.89", "size": "146"}, {"price": "0.88", "size": "73.32"}], "event_type": "book", "last_trade_price": ""}, {"market": "0x70d9be5faefbfdef38512a6d9e4392db3084d813ea56f989bd23400fda437b5d", "asset_id": "21591156070974184450803575087108412438346440628447753978089378794451962462635", "timestamp": "1769383935332", "hash": "8f8b56ca0fa3218ed9ad3b46941e6ecd08b90c29", "bids": [{"price": "0.01", "size": "56.15"}, {"price": "0.02", "size": "10.57"}, {"price": "0.03", "size": "463.33"}, {"price": "0.04", "size": "444.49"}, {"price": "0.05", "size": "320"}, {"price": "0.06", "size": "299.66"}, {"price": "0.07", "size": "169"}, {"price": "0.08", "size": "72.25"}, {"price": "0.1", "size": "100"}, {"price": "0.11", "size": "59.09"}, {"price": "0.13", "size": "66.66"}], "asks": [{"price": "0.99", "size": "3319.44"}, {"price": "0.98", "size": "850"}, {"price": "0.97", "size": "209.49"}, {"price": "0.96", "size": "113.02"}, {"price": "0.95", "size": "30"}, {"price": "0.94", "size": "233"}, {"price": "0.93", "size": "20"}, {"price": "0.86", "size": "92.85"}, {"price": "0.81", "size": "81"}, {"price": "0.62", "size": "100"}, {"price": "0.6", "size": "27.5"}, {"price": "0.57", "size": "5"}, {"price": "0.29", "size": "50"}], "event_type": "book", "last_trade_price": ""}, {"market": "0xe16bfa632e3cde9d098182de828e7245e0cf4f8750c84abd3baac6991eec0726", "asset_id": "109381568779384865822632347902276013195234118338727432096785122435925016975410", "timestamp": "1769383917518", "hash": "e27a44ca3c53aaeb14ac4bd149feb08b9ae82373", "bids": [{"price": "0.001", "size": "1896.99"}, {"price": "0.002", "size": "3512.16"}, {"price": "0.003", "size": "16.08"}, {"price": "0.004", "size": "2500"}, {"price": "0.005", "size": "209.54"}, {"price": "0.006", "size": "183.67"}, {"price": "0.007", "size": "16.72"}, {"price": "0.009", "size": "56.67"}, {"price": "0.01", "size": "122.34"}, {"price": "0.011", "size": "36"}, {"price": "0.012", "size": "5.72"}, {"price": "0.013", "size": "76.67"}], "asks": [{"price": "0.999", "size": "6704.55"}, {"price": "0.998", "size": "1255.52"}, {"price": "0.997", "size": "1000"}, {"price": "0.996", "size": "22.27"}, {"price": "0.99", "size": "100"}, {"price": "0.98", "size": "400"}, {"price": "0.979", "size": "15.4"}, {"price": "0.95", "size": "20"}, {"price": "0.94", "size": "33"}, {"price": "0.9", "size": "860"}, {"price": "0.899", "size": "5.65"}, {"price": "0.85", "size": "551.66"}, {"price": "0.8", "size": "410"}, {"price": "0.79", "size": "449.01"}, {"price": "0.789", "size": "100"}, {"price": "0.75", "size": "112"}, {"price": "0.7", "size": "186.66"}, {"price": "0.699", "size": "200"}, {"price": "0.698", "size": "200"}, {"price": "0.687", "size": "50"}, {"price": "0.65", "size": "68.57"}, {"price": "0.6", "size": "50"}, {"price": "0.358", "size": "100"}, {"price": "0.03", "size": "258.4"}, {"price": "0.018", "size": "47.98"}, {"price": "0.017", "size": "24.06"}], "event_type": "book", "last_trade_price": ""}, {"market": "0x14b8bb6d97ed2a787801ba2f20fa5956fc0801295aafe6d8c7067fe94fd42452", "asset_id": "75337171247095055987130655941065971331450507526359756863407368625723919726491", "timestamp": "1769383901917", "hash": "8614faf8ea884c1858a5117c9b5e18dfe599e369", "bids": [{"price": "0.01", "size": "55.44"}, {"price": "0.02", "size": "20.89"}, {"price": "0.05", "size": "290"}, {"price": "0.06", "size": "197.32"}, {"price": "0.07", "size": "7.53"}, {"price": "0.08", "size": "6"}, {"price": "0.1", "size": "136.66"}, {"price": "0.11", "size": "9.09"}, {"price": "0.13", "size": "66.66"}], "asks": [{"price": "0.99", "size": "2355.45"}, {"price": "0.98", "size": "455.4"}, {"price": "0.97", "size": "300"}, {"price": "0.96", "size": "273.24"}, {"price": "0.95", "size": "140"}, {"price": "0.94", "size": "20"}, {"price": "0.93", "size": "28"}, {"price": "0.91", "size": "6"}, {"price": "0.9", "size": "5.74"}, {"price": "0.89", "size": "9.09"}, {"price": "0.82", "size": "61.11"}, {"price": "0.81", "size": "6"}, {"price": "0.78", "size": "66.66"}, {"price": "0.76", "size": "6"}, {"price": "0.6", "size": "32.5"}, {"price": "0.59", "size": "66.66"}], "event_type": "book", "last_trade_price": "0.410"}, {"market": "0xa96f3bae6635e8f42628c39ce7b61fd566b9253d4f2699c3cac08be6d17ca723", "asset_id": "31555074014428326614377030963919393145120116674000147512977361328627463258713", "timestamp": "1769383901938", "hash": "092743527bf469de30df15c1e2fa4d49c239f789", "bids": [{"price": "0.01", "size": "2756.29"}, {"price": "0.02", "size": "464.43"}, {"price": "0.03", "size": "200"}, {"price": "0.04", "size": "206.52"}, {"price": "0.05", "size": "348.92"}, {"price": "0.06", "size": "136.46"}], "asks": [{"price": "0.99", "size": "1059.7"}, {"price": "0.98", "size": "400"}, {"price": "0.97", "size": "10.13"}, {"price": "0.95", "size": "30"}, {"price": "0.94", "size": "33"}, {"price": "0.91", "size": "400"}, {"price": "0.9", "size": "4000"}, {"price": "0.89", "size": "5.44"}, {"price": "0.86", "size": "242.85"}, {"price": "0.82", "size": "177.77"}, {"price": "0.81", "size": "200"}, {"price": "0.77", "size": "121.73"}, {"price": "0.72", "size": "92.85"}, {"price": "0.71", "size": "46"}, {"price": "0.68", "size": "75"}, {"price": "0.63", "size": "54.05"}, {"price": "0.46", "size": "24.07"}, {"price": "0.45", "size": "20"}, {"price": "0.18", "size": "7.42"}], "event_type": "book", "last_trade_price": ""}, {"market": "0x438cec99837cc33e85826174eb25751662a4e9e60789da929036919364982ea9", "asset_id": "3077099271373784681485715131002592536988795036957918664830629354519157921999", "timestamp": "1769383891642", "hash": "64422f040f55df137c536e6713473130c272bfcd", "bids": [{"price": "0.001", "size": "6704.4"}, {"price": "0.002", "size": "1255.37"}, {"price": "0.003", "size": "1000"}, {"price": "0.004", "size": "21.71"}, {"price": "0.01", "size": "50"}, {"price": "0.02", "size": "400"}, {"price": "0.021", "size": "15.11"}, {"price": "0.05", "size": "30"}, {"price": "0.06", "size": "33"}, {"price": "0.1", "size": "860"}, {"price": "0.101", "size": "5.73"}, {"price": "0.15", "size": "551.66"}, {"price": "0.158", "size": "100"}, {"price": "0.159", "size": "400"}, {"price": "0.16", "size": "200"}, {"price": "0.169", "size": "299.3"}, {"price": "0.2", "size": "160"}, {"price": "0.201", "size": "100"}, {"price": "0.25", "size": "112"}, {"price": "0.3", "size": "86.66"}, {"price": "0.303", "size": "25"}, {"price": "0.35", "size": "68.57"}, {"price": "0.4", "size": "50"}, {"price": "0.594", "size": "100"}, {"price": "0.981", "size": "39.99"}, {"price": "0.982", "size": "18.37"}, {"price": "0.985", "size": "32"}, {"price": "0.986", "size": "15"}], "asks": [{"price": "0.999", "size": "5553.99"}, {"price": "0.998", "size": "2511.43"}, {"price": "0.997", "size": "257.57"}, {"price": "0.996", "size": "44.4"}, {"price": "0.99", "size": "544.66"}, {"price": "0.989", "size": "79.96"}, {"price": "0.988", "size": "79.96"}, {"price": "0.987", "size": "74.75"}], "event_type": "book", "last_trade_price": "0.013"}, {"market": "0xa0854c2762c1df42faf2c90aadaa10001e178ecf825e974831fca1f9057bde3a", "asset_id": "60550083326204794269737137491607222132106322354419495461322838021831787662334", "timestamp": "1769383620195", "hash": "1210290ccc0b95ab04d9910dd49ee0400e075002", "bids": [{"price": "0.01", "size": "60.42"}, {"price": "0.02", "size": "22.22"}, {"price": "0.04", "size": "325"}, {"price": "0.05", "size": "206.66"}, {"price": "0.06", "size": "33"}, {"price": "0.07", "size": "6.44"}, {"price": "0.08", "size": "66.66"}, {"price": "0.1", "size": "100"}, {"price": "0.11", "size": "79.09"}, {"price": "0.12", "size": "66.66"}], "asks": [{"price": "0.99", "size": "2012.53"}, {"price": "0.98", "size": "530.3"}, {"price": "0.97", "size": "7.3"}, {"price": "0.96", "size": "76"}, {"price": "0.95", "size": "10.63"}, {"price": "0.94", "size": "82.37"}, {"price": "0.91", "size": "55.99"}], "event_type": "book", "last_trade_price": "0.110"}, {"market": "0x335a07913dc4afbc345e5a87410ed1cde3c0b168df2627733d49b081526fd002", "asset_id": "62781326014506627625925193711099656595304017608816070575558990777003703808712", "timestamp": "1769384016562", "hash": "eaa360f29633d0a9d79640c1d942dc204996c84d", "bids": [{"price": "0.001", "size": "1927.99"}, {"price": "0.002", "size": "2842.55"}, {"price": "0.003", "size": "405.61"}, {"price": "0.004", "size": "261.88"}], "asks": [{"price": "0.999", "size": "4048.17"}, {"price": "0.998", "size": "1255.14"}, {"price": "0.997", "size": "1000"}, {"price": "0.996", "size": "21.09"}, {"price": "0.99", "size": "100"}, {"price": "0.98", "size": "500"}, {"price": "0.979", "size": "14.68"}, {"price": "0.95", "size": "20"}, {"price": "0.949", "size": "39"}, {"price": "0.93", "size": "20"}, {"price": "0.9", "size": "860"}, {"price": "0.899", "size": "5.86"}, {"price": "0.85", "size": "551.66"}, {"price": "0.8", "size": "160"}, {"price": "0.799", "size": "155"}, {"price": "0.78", "size": "5"}, {"price": "0.75", "size": "112"}, {"price": "0.7", "size": "86.66"}, {"price": "0.65", "size": "73.57"}, {"price": "0.6", "size": "237"}, {"price": "0.087", "size": "19.99"}, {"price": "0.042", "size": "19.99"}], "event_type": "book", "last_trade_price": "0.007"}, {"market": "0x00df4f2883a699f69eda6a02d040dd6c17a0cfbfc75b0324b97e309455a630ca", "asset_id": "22051924742275915497590049977236441411376667493984134023218155707089439076196", "timestamp": "1769383901923", "hash": "ed44c8e271408d08600ee8728d3a23238987238f", "bids": [{"price": "0.001", "size": "6704.19"}, {"price": "0.002", "size": "1255.16"}, {"price": "0.003", "size": "1000"}, {"price": "0.004", "size": "20.92"}, {"price": "0.01", "size": "50"}, {"price": "0.02", "size": "400"}, {"price": "0.021", "size": "14.71"}, {"price": "0.05", "size": "30"}, {"price": "0.06", "size": "33"}, {"price": "0.1", "size": "860"}, {"price": "0.101", "size": "5.85"}, {"price": "0.15", "size": "551.66"}, {"price": "0.2", "size": "160"}, {"price": "0.223", "size": "17"}, {"price": "0.25", "size": "112"}, {"price": "0.251", "size": "100"}, {"price": "0.3", "size": "86.66"}, {"price": "0.35", "size": "68.57"}, {"price": "0.351", "size": "34"}, {"price": "0.4", "size": "50"}, {"price": "0.523", "size": "5"}, {"price": "0.619", "size": "130"}, {"price": "0.98", "size": "29.98"}, {"price": "0.981", "size": "29.95"}, {"price": "0.983", "size": "4.04"}, {"price": "0.985", "size": "25"}, {"price": "0.986", "size": "42.47"}, {"price": "0.987", "size": "8.99"}], "asks": [{"price": "0.999", "size": "1616"}, {"price": "0.998", "size": "350"}, {"price": "0.997", "size": "309.06"}, {"price": "0.996", "size": "254.86"}, {"price": "0.995", "size": "69.2"}, {"price": "0.994", "size": "69.2"}, {"price": "0.993", "size": "24.4"}], "event_type": "book", "last_trade_price": ""}, {"market": "0x146def8be2d4ec270cac5e8cae1d60cf8ea7064200594d10e74104db6b9a60fd", "asset_id": "59834485698328047678505195191113741956543908658984089284407908730537452141550", "timestamp": "1769384015813", "hash": "93d08859b8cffa319e6249c98261cd3ddfd494bd", "bids": [{"price": "0.01", "size": "2355.77"}, {"price": "0.02", "size": "456"}, {"price": "0.03", "size": "300"}, {"price": "0.04", "size": "206.29"}, {"price": "0.05", "size": "186.66"}, {"price": "0.06", "size": "33"}, {"price": "0.08", "size": "14"}, {"price": "0.09", "size": "6.34"}, {"price": "0.12", "size": "66.66"}, {"price": "0.16", "size": "81.25"}, {"price": "0.18", "size": "61.11"}, {"price": "0.19", "size": "66.66"}], "asks": [{"price": "0.99", "size": "172.54"}, {"price": "0.98", "size": "20.03"}, {"price": "0.95", "size": "20"}, {"price": "0.91", "size": "172.66"}, {"price": "0.88", "size": "108.33"}, {"price": "0.87", "size": "84.61"}, {"price": "0.86", "size": "42"}, {"price": "0.81", "size": "70"}, {"price": "0.8", "size": "66.66"}], "event_type": "book", "last_trade_price": ""}, {"market": "0xeafa01c5d48d6b7826e91f7b31e4a61a05b3fc8a1ad8ccdb2ccbad91b616ae40", "asset_id": "83862627090039829837897753251638021110482606851285352212547333342638917195954", "timestamp": "1769384022054", "hash": "494d456301c39a67b8c20c5b6b4eeb0e620e8f2a", "bids": [{"price": "0.01", "size": "2905.1"}, {"price": "0.02", "size": "400"}, {"price": "0.03", "size": "9.79"}, {"price": "0.05", "size": "20"}, {"price": "0.06", "size": "33"}, {"price": "0.08", "size": "750"}, {"price": "0.09", "size": "7.28"}, {"price": "0.11", "size": "634.09"}, {"price": "0.15", "size": "213.33"}, {"price": "0.19", "size": "147.36"}, {"price": "0.23", "size": "113.04"}, {"price": "0.27", "size": "88.88"}, {"price": "0.3", "size": "66.66"}, {"price": "0.31", "size": "33"}, {"price": "0.36", "size": "100"}, {"price": "0.37", "size": "5"}, {"price": "0.5", "size": "5"}, {"price": "0.6", "size": "5"}, {"price": "0.65", "size": "58.46"}, {"price": "0.71", "size": "56.3"}], "asks": [{"price": "0.99", "size": "105.62"}, {"price": "0.98", "size": "40.04"}, {"price": "0.97", "size": "19.94"}, {"price": "0.96", "size": "45.78"}, {"price": "0.9", "size": "50"}], "event_type": "book", "last_trade_price": ""}, {"market": "0x55ff220b6cc2ccf789410dfc778cb1f261c6966118f36378b79cafd46a675a4b", "asset_id": "18329461286102208031559948157756808008602749374920030433285753294739330222203", "timestamp": "1769382922509", "hash": "966211eea51671787ca8b00525744e36aac04b39", "bids": [{"price": "0.01", "size": "1856.64"}, {"price": "0.02", "size": "14.26"}, {"price": "0.04", "size": "28"}, {"price": "0.06", "size": "11.91"}, {"price": "0.1", "size": "56.64"}, {"price": "0.11", "size": "118.18"}, {"price": "0.12", "size": "91.66"}, {"price": "0.18", "size": "5.55"}, {"price": "0.19", "size": "71.64"}], "asks": [{"price": "0.99", "size": "155.06"}, {"price": "0.98", "size": "12.77"}, {"price": "0.95", "size": "30"}, {"price": "0.94", "size": "33"}, {"price": "0.93", "size": "16"}, {"price": "0.92", "size": "8.67"}, {"price": "0.64", "size": "100"}, {"price": "0.4", "size": "5"}, {"price": "0.39", "size": "21.31"}, {"price": "0.38", "size": "17.74"}, {"price": "0.35", "size": "20"}, {"price": "0.3", "size": "10"}], "event_type": "book", "last_trade_price": ""}, {"market": "0x21fcddff254ff0337ac03ec276927cc90e5228ac1c5b16c36300589318197fc4", "asset_id": "108893558475396584780619998257373148912765768914968487436636153030532224366680", "timestamp": "1769384014025", "hash": "929ed66d75759b93e19f796f9728f3c2743dd189", "bids": [{"price": "0.01", "size": "3378.69"}, {"price": "0.02", "size": "850"}, {"price": "0.03", "size": "250"}, {"price": "0.04", "size": "105.33"}, {"price": "0.05", "size": "30"}, {"price": "0.06", "size": "33"}, {"price": "0.07", "size": "300"}, {"price": "0.08", "size": "200"}, {"price": "0.09", "size": "50"}, {"price": "0.11", "size": "6.05"}, {"price": "0.32", "size": "66.66"}, {"price": "0.33", "size": "6"}, {"price": "0.63", "size": "116.66"}], "asks": [{"price": "0.99", "size": "105.04"}, {"price": "0.98", "size": "14.27"}, {"price": "0.97", "size": "55.33"}, {"price": "0.96", "size": "6.43"}, {"price": "0.95", "size": "20"}, {"price": "0.94", "size": "81.99"}], "event_type": "book", "last_trade_price": ""}, {"market": "0x679bcdd7ed5e81e87f560a516b2ff3b419be87aeb995550b728c75a222bbfd14", "asset_id": "2072906368234015194389249304629942211650401137671103595040092908842803594601", "timestamp": "1769384014025", "hash": "1b14e25a5fb89efa3c28f35a543a5da64d165c26", "bids": [{"price": "0.01", "size": "128.57"}, {"price": "0.02", "size": "24.33"}, {"price": "0.04", "size": "66.66"}, {"price": "0.05", "size": "30"}, {"price": "0.06", "size": "104.57"}, {"price": "0.07", "size": "110"}, {"price": "0.08", "size": "79.16"}], "asks": [{"price": "0.99", "size": "2423.03"}, {"price": "0.98", "size": "350"}, {"price": "0.97", "size": "206.25"}, {"price": "0.95", "size": "200"}, {"price": "0.94", "size": "133"}, {"price": "0.93", "size": "100"}, {"price": "0.92", "size": "9.36"}, {"price": "0.83", "size": "141.66"}, {"price": "0.68", "size": "6"}, {"price": "0.66", "size": "66.66"}, {"price": "0.38", "size": "50"}], "event_type": "book", "last_trade_price": ""}, {"market": "0x5b17571f0687e9ef62aead3a3e57bfc617f16e4806865d8b7cc609a680ac9892", "asset_id": "30934121158421236234732376879006750136278688549793740923122711845308054079491", "timestamp": "1769384020577", "hash": "d23e7f40fc0815beabd3c48c342e10612d8b3719", "bids": [{"price": "0.01", "size": "2550"}, {"price": "0.02", "size": "25.02"}], "asks": [{"price": "0.99", "size": "1061.13"}, {"price": "0.98", "size": "400"}, {"price": "0.97", "size": "7.61"}, {"price": "0.95", "size": "30"}, {"price": "0.94", "size": "33"}, {"price": "0.91", "size": "900"}, {"price": "0.9", "size": "300"}, {"price": "0.89", "size": "6"}, {"price": "0.86", "size": "325"}, {"price": "0.85", "size": "162"}, {"price": "0.83", "size": "100"}, {"price": "0.79", "size": "50"}, {"price": "0.6", "size": "32.5"}, {"price": "0.59", "size": "126.82"}, {"price": "0.42", "size": "100"}, {"price": "0.4", "size": "30"}, {"price": "0.37", "size": "13.1"}, {"price": "0.34", "size": "11.53"}, {"price": "0.33", "size": "7.46"}], "event_type": "book", "last_trade_price": "0.020"}, {"market": "0x55ff220b6cc2ccf789410dfc778cb1f261c6966118f36378b79cafd46a675a4b", "asset_id": "44668787002852120393153062169122124357021282959241952545625186442878833364808", "timestamp": "1769382922509", "hash": "e6e250a110fe02774ca412d01ec5c63bbe1acd73", "bids": [{"price": "0.01", "size": "155.06"}, {"price": "0.02", "size": "12.77"}, {"price": "0.05", "size": "30"}, {"price": "0.06", "size": "33"}, {"price": "0.07", "size": "16"}, {"price": "0.08", "size": "8.67"}, {"price": "0.36", "size": "100"}, {"price": "0.6", "size": "5"}, {"price": "0.61", "size": "21.31"}, {"price": "0.62", "size": "17.74"}, {"price": "0.65", "size": "20"}, {"price": "0.7", "size": "10"}], "asks": [{"price": "0.99", "size": "1856.64"}, {"price": "0.98", "size": "14.26"}, {"price": "0.96", "size": "28"}, {"price": "0.94", "size": "11.91"}, {"price": "0.9", "size": "56.64"}, {"price": "0.89", "size": "118.18"}, {"price": "0.88", "size": "91.66"}, {"price": "0.82", "size": "5.55"}, {"price": "0.81", "size": "71.64"}], "event_type": "book", "last_trade_price": ""}, {"market": "0x7a3a3ab1573e95640462d73202fcee6d6ff66f91630d14296a1f71fa5b918bfa", "asset_id": "1916547748102919386528896303234847953491748301328504422346327816950157210420", "timestamp": "1769383901922", "hash": "176d9d0664690efea4f782fcfb768430c1bd1c56", "bids": [{"price": "0.001", "size": "3488.99"}, {"price": "0.002", "size": "4776.31"}, {"price": "0.003", "size": "183.44"}, {"price": "0.004", "size": "2613.01"}, {"price": "0.005", "size": "312.35"}, {"price": "0.006", "size": "293.24"}, {"price": "0.007", "size": "308.73"}, {"price": "0.008", "size": "291.6"}, {"price": "0.009", "size": "23.82"}, {"price": "0.01", "size": "44.44"}, {"price": "0.011", "size": "9.09"}], "asks": [{"price": "0.999", "size": "2110.38"}, {"price": "0.998", "size": "1255.34"}, {"price": "0.997", "size": "2000"}, {"price": "0.996", "size": "21.61"}, {"price": "0.98", "size": "400"}, {"price": "0.979", "size": "15.07"}, {"price": "0.95", "size": "20"}, {"price": "0.949", "size": "39"}, {"price": "0.9", "size": "860"}, {"price": "0.899", "size": "5.75"}, {"price": "0.85", "size": "551.66"}, {"price": "0.8", "size": "410"}, {"price": "0.75", "size": "262"}, {"price": "0.749", "size": "106"}, {"price": "0.7", "size": "86.66"}, {"price": "0.65", "size": "68.57"}, {"price": "0.6", "size": "125"}, {"price": "0.466", "size": "7.5"}, {"price": "0.464", "size": "7.5"}, {"price": "0.049", "size": "121.53"}, {"price": "0.03", "size": "629.5"}, {"price": "0.028", "size": "25"}, {"price": "0.027", "size": "14.81"}], "event_type": "book", "last_trade_price": ""}, {"market": "0xadd7737a947ee4b404262bd268a7dad202a7b93a853e59eb29c3770bdf5a3c5e", "asset_id": "61947573105398885505676981136106310455132935973656038313589742543062489249520", "timestamp": "1769383972546", "hash": "8d7467732bb721e0b503b232e620c52cb0483670", "bids": [{"price": "0.01", "size": "35.67"}, {"price": "0.02", "size": "45.49"}, {"price": "0.03", "size": "30"}, {"price": "0.04", "size": "17.33"}, {"price": "0.08", "size": "30"}, {"price": "0.09", "size": "111.1"}], "asks": [{"price": "0.99", "size": "2377.23"}, {"price": "0.98", "size": "450"}, {"price": "0.97", "size": "355.83"}, {"price": "0.96", "size": "300"}, {"price": "0.95", "size": "130"}, {"price": "0.94", "size": "33"}, {"price": "0.93", "size": "10.27"}, {"price": "0.84", "size": "125"}, {"price": "0.79", "size": "66.66"}, {"price": "0.6", "size": "5"}, {"price": "0.55", "size": "6"}, {"price": "0.54", "size": "66.66"}], "event_type": "book", "last_trade_price": ""}, {"market": "0x14b8bb6d97ed2a787801ba2f20fa5956fc0801295aafe6d8c7067fe94fd42452", "asset_id": "50399511646793793920236172406822989948670236754561909965641916889345886741518", "timestamp": "1769383901917", "hash": "b69318b763bad21682294943e01dc4098aef5c57", "bids": [{"price": "0.01", "size": "2355.45"}, {"price": "0.02", "size": "455.4"}, {"price": "0.03", "size": "300"}, {"price": "0.04", "size": "273.24"}, {"price": "0.05", "size": "140"}, {"price": "0.06", "size": "20"}, {"price": "0.07", "size": "28"}, {"price": "0.09", "size": "6"}, {"price": "0.1", "size": "5.74"}, {"price": "0.11", "size": "9.09"}, {"price": "0.18", "size": "61.11"}, {"price": "0.19", "size": "6"}, {"price": "0.22", "size": "66.66"}, {"price": "0.24", "size": "6"}, {"price": "0.4", "size": "32.5"}, {"price": "0.41", "size": "66.66"}], "asks": [{"price": "0.99", "size": "55.44"}, {"price": "0.98", "size": "20.89"}, {"price": "0.95", "size": "290"}, {"price": "0.94", "size": "197.32"}, {"price": "0.93", "size": "7.53"}, {"price": "0.92", "size": "6"}, {"price": "0.9", "size": "136.66"}, {"price": "0.89", "size": "9.09"}, {"price": "0.87", "size": "66.66"}], "event_type": "book", "last_trade_price": "0.410"}, {"market": "0x68e08317aa8d51a5b697eb56de90fa23e4c344d4ff28d73255068e9d8640178f", "asset_id": "17716452293139511517441185538753753078769606352898415844469806261075806697711", "timestamp": "1769383901933", "hash": "861d09fde4f43c4060a1468ae2586ea665e99307", "bids": [{"price": "0.01", "size": "2310.2"}, {"price": "0.02", "size": "459.47"}, {"price": "0.03", "size": "350"}, {"price": "0.04", "size": "331.27"}, {"price": "0.05", "size": "340"}, {"price": "0.06", "size": "299.66"}, {"price": "0.07", "size": "106.53"}, {"price": "0.08", "size": "193.66"}, {"price": "0.12", "size": "74.99"}], "asks": [{"price": "0.99", "size": "124.16"}, {"price": "0.98", "size": "21.61"}, {"price": "0.95", "size": "20"}, {"price": "0.94", "size": "33"}, {"price": "0.92", "size": "12.5"}, {"price": "0.91", "size": "5.47"}, {"price": "0.89", "size": "66.66"}, {"price": "0.88", "size": "91.66"}, {"price": "0.87", "size": "100"}, {"price": "0.86", "size": "50"}, {"price": "0.81", "size": "70"}, {"price": "0.8", "size": "66.66"}], "event_type": "book", "last_trade_price": ""}]}
{"_local_timestamp": "2026-01-25T23:33:46.488957+00:00", "data": {"market": "0x335a07913dc4afbc345e5a87410ed1cde3c0b168df2627733d49b081526fd002", "price_changes": [{"asset_id": "62781326014506627625925193711099656595304017608816070575558990777003703808712", "price": "0.004", "size": "1011.88", "side": "BUY", "hash": "42d96646a77a3e9c7db4eadfa0c3ad73d81cee86", "best_bid": "0.004", "best_ask": "0.042"}, {"asset_id": "87400156771035739647299903622267629973291296986678621415627996460491040207279", "price": "0.996", "size": "1011.88", "side": "SELL", "hash": "fcc6bcfec0758cfc766b0d166d2dca53b6bf55d2", "best_bid": "0.958", "best_ask": "0.996"}], "timestamp": "1769384026422", "event_type": "price_change"}}
{"_local_timestamp": "2026-01-25T23:33:47.069433+00:00", "data": {"market": "0x70d9be5faefbfdef38512a6d9e4392db3084d813ea56f989bd23400fda437b5d", "price_changes": [{"asset_id": "98030581449575327310479171744260311446081913603336917524388058189639018780846", "price": "0.71", "size": "0", "side": "BUY", "hash": "cf8df4079882449bd5650da98d4d7496e02dba47", "best_bid": "0.43", "best_ask": "0.87"}, {"asset_id": "21591156070974184450803575087108412438346440628447753978089378794451962462635", "price": "0.29", "size": "0", "side": "SELL", "hash": "dc408254fff95f5dfb199378306a77d2ea05068d", "best_bid": "0.13", "best_ask": "0.57"}], "timestamp": "1769384027000", "event_type": "price_change"}}
{"_local_timestamp": "2026-01-25T23:33:47.071249+00:00", "data": {"market": "0x70d9be5faefbfdef38512a6d9e4392db3084d813ea56f989bd23400fda437b5d", "price_changes": [{"asset_id": "21591156070974184450803575087108412438346440628447753978089378794451962462635", "price": "0.11", "size": "9.09", "side": "BUY", "hash": "85aeabb8f005ca4c97341cc61fc2054fd3b14127", "best_bid": "0.13", "best_ask": "0.57"}, {"asset_id": "98030581449575327310479171744260311446081913603336917524388058189639018780846", "price": "0.89", "size": "9.09", "side": "SELL", "hash": "85f128d27dd098892308a90b775e67751c6a3d7d", "best_bid": "0.43", "best_ask": "0.87"}], "timestamp": "1769384027000", "event_type": "price_change"}}
{"_local_timestamp": "2026-01-25T23:33:47.694178+00:00", "data": {"market": "0x5b17571f0687e9ef62aead3a3e57bfc617f16e4806865d8b7cc609a680ac9892", "price_changes": [{"asset_id": "30934121158421236234732376879006750136278688549793740923122711845308054079491", "price": "0.02", "size": "0", "side": "BUY", "hash": "a5c80e07982d6cc23fa66984f279a5ad815e3634", "best_bid": "0.01", "best_ask": "0.33"}, {"asset_id": "54672482098306675309495708206879727568512955356356264682879888123590518385092", "price": "0.98", "size": "0", "side": "SELL", "hash": "9509bbd39155f5e6b583e1170556905b08469bfa", "best_bid": "0.67", "best_ask": "0.99"}], "timestamp": "1769384027631", "event_type": "price_change"}}
{"_local_timestamp": "2026-01-25T23:33:47.698513+00:00", "data": {"market": "0x5b17571f0687e9ef62aead3a3e57bfc617f16e4806865d8b7cc609a680ac9892", "asset_id": "54672482098306675309495708206879727568512955356356264682879888123590518385092", "bids": [{"price": "0.01", "size": "1061.13"}, {"price": "0.02", "size": "400"}, {"price": "0.03", "size": "7.61"}, {"price": "0.05", "size": "30"}, {"price": "0.06", "size": "33"}, {"price": "0.09", "size": "900"}, {"price": "0.1", "size": "300"}, {"price": "0.11", "size": "6"}, {"price": "0.14", "size": "325"}, {"price": "0.15", "size": "162"}, {"price": "0.17", "size": "100"}, {"price": "0.21", "size": "50"}, {"price": "0.4", "size": "32.5"}, {"price": "0.41", "size": "126.82"}, {"price": "0.58", "size": "100"}, {"price": "0.6", "size": "30"}, {"price": "0.63", "size": "13.1"}, {"price": "0.66", "size": "11.53"}, {"price": "0.67", "size": "7.46"}], "asks": [{"price": "0.99", "size": "2550"}], "hash": "9509bbd39155f5e6b583e1170556905b08469bfa", "timestamp": "1769384027631", "event_type": "book"}}
{"_local_timestamp": "2026-01-25T23:33:47.702739+00:00", "data": {"market": "0x5b17571f0687e9ef62aead3a3e57bfc617f16e4806865d8b7cc609a680ac9892", "asset_id": "30934121158421236234732376879006750136278688549793740923122711845308054079491", "bids": [{"price": "0.01", "size": "2550"}], "asks": [{"price": "0.99", "size": "1061.13"}, {"price": "0.98", "size": "400"}, {"price": "0.97", "size": "7.61"}, {"price": "0.95", "size": "30"}, {"price": "0.94", "size": "33"}, {"price": "0.91", "size": "900"}, {"price": "0.9", "size": "300"}, {"price": "0.89", "size": "6"}, {"price": "0.86", "size": "325"}, {"price": "0.85", "size": "162"}, {"price": "0.83", "size": "100"}, {"price": "0.79", "size": "50"}, {"price": "0.6", "size": "32.5"}, {"price": "0.59", "size": "126.82"}, {"price": "0.42", "size": "100"}, {"price": "0.4", "size": "30"}, {"price": "0.37", "size": "13.1"}, {"price": "0.34", "size": "11.53"}, {"price": "0.33", "size": "7.46"}], "hash": "a5c80e07982d6cc23fa66984f279a5ad815e3634", "timestamp": "1769384027631", "event_type": "book"}}
{"_local_timestamp": "2026-01-25T23:33:47.729822+00:00", "data": {"market": "0x5b17571f0687e9ef62aead3a3e57bfc617f16e4806865d8b7cc609a680ac9892", "asset_id": "54672482098306675309495708206879727568512955356356264682879888123590518385092", "price": "0.98", "size": "25.02", "fee_rate_bps": "0", "side": "BUY", "timestamp": "1769384027660", "event_type": "last_trade_price", "transaction_hash": "0xd4e7325b0b65d14c0341e83b50e2f46dad2ae239310b2952891dd0ee9a2b55e5"}}
{"_local_timestamp": "2026-01-25T23:33:48.345373+00:00", "data": {"market": "0x853c21fec9164c04490f6716b39a20faf739a54b94600a07a17925167524d24a", "price_changes": [{"asset_id": "15979230411596646053680509080157208292023265223198192295881115295360839707181", "price": "0.015", "size": "84.4", "side": "SELL", "hash": "c1a1b7c961ddf2f971dba7132bb74fa74d4b56ac", "best_bid": "0.012", "best_ask": "0.015"}, {"asset_id": "67943936326411950699380754459398390458771532481725144845477238890627646410860", "price": "0.985", "size": "84.4", "side": "BUY", "hash": "b922a007528dd9c8102342768f59e0ff0b1c5eab", "best_bid": "0.985", "best_ask": "0.988"}], "timestamp": "1769384028281", "event_type": "price_change"}}
{"_local_timestamp": "2026-01-25T23:33:48.381919+00:00", "data": {"market": "0x5b17571f0687e9ef62aead3a3e57bfc617f16e4806865d8b7cc609a680ac9892", "price_changes": [{"asset_id": "30934121158421236234732376879006750136278688549793740923122711845308054079491", "price": "0.36", "size": "275", "side": "SELL", "hash": "b772a1ba3f12a64476fce9c07a44cc338812fabd", "best_bid": "0.01", "best_ask": "0.33"}, {"asset_id": "54672482098306675309495708206879727568512955356356264682879888123590518385092", "price": "0.64", "size": "275", "side": "BUY", "hash": "434d9d0734facb9efbeb7a33ee0f562ab2500145", "best_bid": "0.67", "best_ask": "0.99"}], "timestamp": "1769384028304", "event_type": "price_change"}}
{"_local_timestamp": "2026-01-25T23:33:49.453611+00:00", "data": {"market": "0xeafa01c5d48d6b7826e91f7b31e4a61a05b3fc8a1ad8ccdb2ccbad91b616ae40", "price_changes": [{"asset_id": "83862627090039829837897753251638021110482606851285352212547333342638917195954", "price": "0.65", "size": "0", "side": "BUY", "hash": "839c126fca3fc793a7af70bca91a5077c762c3eb", "best_bid": "0.71", "best_ask": "0.9"}, {"asset_id": "97279369561823536114577996580038127500018967849090745350406495876539022297477", "price": "0.35", "size": "0", "side": "SELL", "hash": "900dd1dc89f15756e116868aa7287ba4cd8ca64a", "best_bid": "0.1", "best_ask": "0.29"}], "timestamp": "1769384029387", "event_type": "price_change"}}
{"_local_timestamp": "2026-01-25T23:33:50.974537+00:00", "data": {"market": "0xbf7f7047fa5719e010b9c35abab4d1510f80d78998ede7928dee762b842fd8fa", "price_changes": [{"asset_id": "80475936180674486630534655774036670401396382603097237786734519090691938222605", "price": "0.02", "size": "0", "side": "BUY", "hash": "9ab2e41cac4734fe8f2e4ee02c95822bbaf5d4ca", "best_bid": "0.01", "best_ask": "0.41"}, {"asset_id": "99317080920004040908110146285425334348796704558628502185978368700992863001849", "price": "0.98", "size": "0", "side": "SELL", "hash": "48b73d707fb3f6ae1ceb60b8fdf7c69990f0ef91", "best_bid": "0.59", "best_ask": "0.99"}], "timestamp": "1769384030896", "event_type": "price_change"}}
{"_local_timestamp": "2026-01-25T23:33:50.997259+00:00", "data": {"market": "0xbf7f7047fa5719e010b9c35abab4d1510f80d78998ede7928dee762b842fd8fa", "asset_id": "99317080920004040908110146285425334348796704558628502185978368700992863001849", "bids": [{"price": "0.01", "size": "65.43"}, {"price": "0.03", "size": "100"}, {"price": "0.04", "size": "55.64"}, {"price": "0.05", "size": "30"}, {"price": "0.06", "size": "33"}, {"price": "0.07", "size": "20"}, {"price": "0.08", "size": "10"}, {"price": "0.09", "size": "7.08"}, {"price": "0.31", "size": "50.43"}, {"price": "0.36", "size": "36.11"}, {"price": "0.37", "size": "29.72"}, {"price": "0.5", "size": "200"}, {"price": "0.56", "size": "40"}, {"price": "0.58", "size": "12.63"}, {"price": "0.59", "size": "8.47"}], "asks": [{"price": "0.99", "size": "2511.2"}], "hash": "48b73d707fb3f6ae1ceb60b8fdf7c69990f0ef91", "timestamp": "1769384030896", "event_type": "book"}}
{"_local_timestamp": "2026-01-25T23:33:51.001127+00:00", "data": {"market": "0xbf7f7047fa5719e010b9c35abab4d1510f80d78998ede7928dee762b842fd8fa", "asset_id": "80475936180674486630534655774036670401396382603097237786734519090691938222605", "bids": [{"price": "0.01", "size": "2511.2"}], "asks": [{"price": "0.99", "size": "65.43"}, {"price": "0.97", "size": "100"}, {"price": "0.96", "size": "55.64"}, {"price": "0.95", "size": "30"}, {"price": "0.94", "size": "33"}, {"price": "0.93", "size": "20"}, {"price": "0.92", "size": "10"}, {"price": "0.91", "size": "7.08"}, {"price": "0.69", "size": "50.43"}, {"price": "0.64", "size": "36.11"}, {"price": "0.63", "size": "29.72"}, {"price": "0.5", "size": "200"}, {"price": "0.44", "size": "40"}, {"price": "0.42", "size": "12.63"}, {"price": "0.41", "size": "8.47"}], "hash": "9ab2e41cac4734fe8f2e4ee02c95822bbaf5d4ca", "timestamp": "1769384030896", "event_type": "book"}}
{"_local_timestamp": "2026-01-25T23:33:51.001625+00:00", "data": {"market": "0xbf7f7047fa5719e010b9c35abab4d1510f80d78998ede7928dee762b842fd8fa", "asset_id": "99317080920004040908110146285425334348796704558628502185978368700992863001849", "price": "0.98", "size": "300.46", "fee_rate_bps": "0", "side": "BUY", "timestamp": "1769384030924", "event_type": "last_trade_price", "transaction_hash": "0xa4c8aa7685162078d3c67341ce70dc489c286ba3314d3ed897ee66dd10281eb5"}}
{"_local_timestamp": "2026-01-25T23:33:56.461819+00:00", "data": {"market": "0x6f14e52f6a1502a35406feea3f0e8d42502bbf1199e42c73a743fe1745ccc12c", "price_changes": [{"asset_id": "17811605278785499666964340297379704435403265198212995098387642426099375215061", "price": "0.55", "size": "50", "side": "BUY", "hash": "a29c4f26b2994b988f9bb9dae5aff0aeab27f554", "best_bid": "0.57", "best_ask": "0.77"}, {"asset_id": "64289097521554308111154900994757912304033484898403308857843640646685729282110", "price": "0.45", "size": "50", "side": "SELL", "hash": "573cf678323a3d59a96c1804dd9a21253d0ed704", "best_bid": "0.23", "best_ask": "0.43"}], "timestamp": "1769384036397", "event_type": "price_change"}}
{"_local_timestamp": "2026-01-25T23:34:00.092815+00:00", "data": {"market": "0x1cc14846bee31efbd7c2016ca1c17664684ead0c7f3b8bd91876033a546128d8", "price_changes": [{"asset_id": "60596582874731501900696294615290867175277482143370610111416633979822519113254", "price": "0.23", "size": "86.95", "side": "BUY", "hash": "008e7b33486bca9f5f2a342f1b74511162c29c5d", "best_bid": "0.52", "best_ask": "0.7"}, {"asset_id": "32668102469816119620746811427740823831434256980467530534403997191651163337906", "price": "0.77", "size": "86.95", "side": "SELL", "hash": "15ef1fba23a8794e68d1a038030625d8e43a473b", "best_bid": "0.3", "best_ask": "0.48"}], "timestamp": "1769384039982", "event_type": "price_change"}}
{"_local_timestamp": "2026-01-25T23:34:00.105758+00:00", "data": {"market": "0x1cc14846bee31efbd7c2016ca1c17664684ead0c7f3b8bd91876033a546128d8", "price_changes": [{"asset_id": "60596582874731501900696294615290867175277482143370610111416633979822519113254", "price": "0.31", "size": "0", "side": "BUY", "hash": "008e7b33486bca9f5f2a342f1b74511162c29c5d", "best_bid": "0.52", "best_ask": "0.7"}, {"asset_id": "32668102469816119620746811427740823831434256980467530534403997191651163337906", "price": "0.69", "size": "0", "side": "SELL", "hash": "15ef1fba23a8794e68d1a038030625d8e43a473b", "best_bid": "0.3", "best_ask": "0.48"}], "timestamp": "1769384039982", "event_type": "price_change"}}
{"_local_timestamp": "2026-01-25T23:34:01.697460+00:00", "data": {"market": "0x6f14e52f6a1502a35406feea3f0e8d42502bbf1199e42c73a743fe1745ccc12c", "price_changes": [{"asset_id": "17811605278785499666964340297379704435403265198212995098387642426099375215061", "price": "0.06", "size": "1099.66", "side": "BUY", "hash": "662dfd75e19ef1571493f951f30c941eb025257d", "best_bid": "0.57", "best_ask": "0.77"}, {"asset_id": "64289097521554308111154900994757912304033484898403308857843640646685729282110", "price": "0.94", "size": "1099.66", "side": "SELL", "hash": "34e3a7ff26f2d5a10806e81364406e3fd82b8655", "best_bid": "0.23", "best_ask": "0.43"}], "timestamp": "1769384041632", "event_type": "price_change"}}
{"_local_timestamp": "2026-01-25T23:34:05.414538+00:00", "data": {"market": "0xbf7f7047fa5719e010b9c35abab4d1510f80d78998ede7928dee762b842fd8fa", "price_changes": [{"asset_id": "80475936180674486630534655774036670401396382603097237786734519090691938222605", "price": "0.42", "size": "0", "side": "SELL", "hash": "720e01ede1f90a337bb6d3bfaec17f21eb36ebdb", "best_bid": "0.01", "best_ask": "0.41"}, {"asset_id": "99317080920004040908110146285425334348796704558628502185978368700992863001849", "price": "0.58", "size": "0", "side": "BUY", "hash": "ae92441b09b0847716a1c38be4bdac50a4137afa", "best_bid": "0.59", "best_ask": "0.99"}], "timestamp": "1769384045139", "event_type": "price_change"}}
{"_local_timestamp": "2026-01-25T23:34:05.629959+00:00", "data": {"market": "0xbf7f7047fa5719e010b9c35abab4d1510f80d78998ede7928dee762b842fd8fa", "price_changes": [{"asset_id": "80475936180674486630534655774036670401396382603097237786734519090691938222605", "price": "0.43", "size": "11.68", "side": "SELL", "hash": "1f9203813a48a76fc34aba5d0eee9d4e621f5c8e", "best_bid": "0.01", "best_ask": "0.41"}, {"asset_id": "99317080920004040908110146285425334348796704558628502185978368700992863001849", "price": "0.57", "size": "11.68", "side": "BUY", "hash": "3f0843433832682ca48afbe1f28760eb032aba6b", "best_bid": "0.59", "best_ask": "0.99"}], "timestamp": "1769384045385", "event_type": "price_change"}}
{"_local_timestamp": "2026-01-25T23:34:05.630978+00:00", "data": {"market": "0xbf7f7047fa5719e010b9c35abab4d1510f80d78998ede7928dee762b842fd8fa", "price_changes": [{"asset_id": "80475936180674486630534655774036670401396382603097237786734519090691938222605", "price": "0.4", "size": "12.7", "side": "SELL", "hash": "a6eb1331cd31c68e3501c897adc8ca18e3d84e91", "best_bid": "0.01", "best_ask": "0.4"}, {"asset_id": "99317080920004040908110146285425334348796704558628502185978368700992863001849", "price": "0.6", "size": "12.7", "side": "BUY", "hash": "e7b2a3aae3ea4c1d9e3c402a3ff0b639710af777", "best_bid": "0.6", "best_ask": "0.99"}], "timestamp": "1769384045391", "event_type": "price_change"}}
{"_local_timestamp": "2026-01-25T23:34:05.814111+00:00", "data": {"market": "0xbf7f7047fa5719e010b9c35abab4d1510f80d78998ede7928dee762b842fd8fa", "price_changes": [{"asset_id": "80475936180674486630534655774036670401396382603097237786734519090691938222605", "price": "0.01", "size": "2500", "side": "BUY", "hash": "f993fb6ad9a08ba3bae642b7f6f6f96f395c8a31", "best_bid": "0.01", "best_ask": "0.4"}, {"asset_id": "99317080920004040908110146285425334348796704558628502185978368700992863001849", "price": "0.99", "size": "2500", "side": "SELL", "hash": "24a9f023f51e67634e9a999af5f1770d63793614", "best_bid": "0.6", "best_ask": "0.99"}], "timestamp": "1769384045568", "event_type": "price_change"}}
{"_local_timestamp": "2026-01-25T23:34:12.704466+00:00", "data": {"market": "0xbf7f7047fa5719e010b9c35abab4d1510f80d78998ede7928dee762b842fd8fa", "price_changes": [{"asset_id": "80475936180674486630534655774036670401396382603097237786734519090691938222605", "price": "0.99", "size": "165.43", "side": "SELL", "hash": "66acb305646d88afb60da8ef5582546016a2c1a7", "best_bid": "0.01", "best_ask": "0.4"}, {"asset_id": "99317080920004040908110146285425334348796704558628502185978368700992863001849", "price": "0.01", "size": "165.43", "side": "BUY", "hash": "0e4e411d0be4235500ed53e0bc682322f6a3892f", "best_bid": "0.6", "best_ask": "0.99"}], "timestamp": "1769384052458", "event_type": "price_change"}}
{"_local_timestamp": "2026-01-25T23:34:13.093513+00:00", "data": {"market": "0x7a3a3ab1573e95640462d73202fcee6d6ff66f91630d14296a1f71fa5b918bfa", "price_changes": [{"asset_id": "1916547748102919386528896303234847953491748301328504422346327816950157210420", "price": "0.006", "size": "193.24", "side": "BUY", "hash": "c0511aac606bfcd21165457d57384efc89ebff9b", "best_bid": "0.011", "best_ask": "0.027"}, {"asset_id": "22238013475081219064410839764368731545802811151601899423291363232635951279796", "price": "0.994", "size": "193.24", "side": "SELL", "hash": "6c4333c66d0562256250655f648ebd4fb582fe1b", "best_bid": "0.973", "best_ask": "0.989"}], "timestamp": "1769384052807", "event_type": "price_change"}}
{"_local_timestamp": "2026-01-25T23:34:13.098334+00:00", "data": {"market": "0x6f14e52f6a1502a35406feea3f0e8d42502bbf1199e42c73a743fe1745ccc12c", "price_changes": [{"asset_id": "17811605278785499666964340297379704435403265198212995098387642426099375215061", "price": "0.05", "size": "555", "side": "BUY", "hash": "d056e1c6a66553ded6e60e595cae306954683d0e", "best_bid": "0.57", "best_ask": "0.77"}, {"asset_id": "64289097521554308111154900994757912304033484898403308857843640646685729282110", "price": "0.95", "size": "555", "side": "SELL", "hash": "7e8cf7a6a0ee37b8f75bba42b6f3528a43b3310f", "best_bid": "0.23", "best_ask": "0.43"}], "timestamp": "1769384052807", "event_type": "price_change"}}
{"_local_timestamp": "2026-01-25T23:34:13.107813+00:00", "data": {"market": "0x21fcddff254ff0337ac03ec276927cc90e5228ac1c5b16c36300589318197fc4", "price_changes": [{"asset_id": "108893558475396584780619998257373148912765768914968487436636153030532224366680", "price": "0.07", "size": "200", "side": "BUY", "hash": "2b23189651d935426e6f4cfd4862d2929de964dd", "best_bid": "0.63", "best_ask": "0.94"}, {"asset_id": "41605452123604733553647691830638760854992806694633100987207040539420095696757", "price": "0.93", "size": "200", "side": "SELL", "hash": "a9e17cb5fbc64d0e8486e7ea393b434096f52e5c", "best_bid": "0.06", "best_ask": "0.37"}], "timestamp": "1769384052808", "event_type": "price_change"}}
{"_local_timestamp": "2026-01-25T23:34:13.117041+00:00", "data": {"market": "0x6f14e52f6a1502a35406feea3f0e8d42502bbf1199e42c73a743fe1745ccc12c", "price_changes": [{"asset_id": "64289097521554308111154900994757912304033484898403308857843640646685729282110", "price": "0.07", "size": "0", "side": "BUY", "hash": "5247981e0a8be3a7c32b82eed60ebe623a8f6eaa", "best_bid": "0.23", "best_ask": "0.43"}, {"asset_id": "17811605278785499666964340297379704435403265198212995098387642426099375215061", "price": "0.93", "size": "0", "side": "SELL", "hash": "d1323f0426e22f0e282f2638878f84413fad3f2d", "best_bid": "0.57", "best_ask": "0.77"}], "timestamp": "1769384052807", "event_type": "price_change"}}
{"_local_timestamp": "2026-01-25T23:34:13.151671+00:00", "data": {"market": "0x146def8be2d4ec270cac5e8cae1d60cf8ea7064200594d10e74104db6b9a60fd", "price_changes": [{"asset_id": "76512560903138059195694921143552469386897971398516938467610044078742285307792", "price": "0.09", "size": "72.66", "side": "BUY", "hash": "35c95be7645226871aa4cbc599ac44cfba97b265", "best_bid": "0.2", "best_ask": "0.81"}, {"asset_id": "59834485698328047678505195191113741956543908658984089284407908730537452141550", "price": "0.91", "size": "72.66", "side": "SELL", "hash": "79bdf38a035899b27601bda6f9cfc7111c1dbe1a", "best_bid": "0.19", "best_ask": "0.8"}], "timestamp": "1769384052809", "event_type": "price_change"}}
{"_local_timestamp": "2026-01-25T23:34:13.188425+00:00", "data": {"market": "0xa96f3bae6635e8f42628c39ce7b61fd566b9253d4f2699c3cac08be6d17ca723", "price_changes": [{"asset_id": "31555074014428326614377030963919393145120116674000147512977361328627463258713", "price": "0.04", "size": "106.52", "side": "BUY", "hash": "d37be725e02fed778ff3f40a4c2b21abb36c9e94", "best_bid": "0.06", "best_ask": "0.18"}, {"asset_id": "49976858258828287893504382876186665182729041451625761701208418053508589757916", "price": "0.96", "size": "106.52", "side": "SELL", "hash": "b6ef3e0b2a5a5f4a992bfce47e8d79300c6baa22", "best_bid": "0.82", "best_ask": "0.94"}], "timestamp": "1769384052809", "event_type": "price_change"}}
{"_local_timestamp": "2026-01-25T23:34:13.193915+00:00", "data": {"market": "0x6032e72cb2b4ee54f6c27cc8b155d0233eb5c9e772de85c60e51797b1431ddf8", "price_changes": [{"asset_id": "44848013696493898639828007101683655834417396378616727747692199122767015662748", "price": "0.07", "size": "100", "side": "BUY", "hash": "e2b2a0d77f083ade2416b4d7ba5d5ad92ed11990", "best_bid": "0.43", "best_ask": "0.93"}, {"asset_id": "7118736781522601355910469975087663596245621357309025148622476783856987875477", "price": "0.93", "size": "100", "side": "SELL", "hash": "482b861e70cc3467a50995f3b9789ccf67befa94", "best_bid": "0.07", "best_ask": "0.57"}], "timestamp": "1769384052809", "event_type": "price_change"}}
{"_local_timestamp": "2026-01-25T23:34:13.194991+00:00", "data": {"market": "0xd8d3819d0166dcce22f68fd24315205f4b8be323803ac55fae013032745499f7", "price_changes": [{"asset_id": "66248863053233981483390075184660170267560753276478697725455087633235785089364", "price": "0.07", "size": "0", "side": "BUY", "hash": "44ecdb07e0ca6554105b2c3be4272c7cfdf1cd6b", "best_bid": "0.53", "best_ask": "0.88"}, {"asset_id": "110039030678047835827290477479682636180706221087707522635871765904720785066494", "price": "0.93", "size": "0", "side": "SELL", "hash": "3305fb31b90ddf844e46905fc0346be1854870aa", "best_bid": "0.12", "best_ask": "0.47"}], "timestamp": "1769384052809", "event_type": "price_change"}}
{"_local_timestamp": "2026-01-25T23:34:13.195803+00:00", "data": {"market": "0xe9cd6563ed540dae9cd820d8deb6080a33fbc3a589b238493519a4a96a1386e1", "price_changes": [{"asset_id": "46611422896979296181480968455950153385868875385647034766198731891278167221454", "price": "0.03", "size": "200", "side": "BUY", "hash": "b340ed2f7406cf9599b00e3373bbb85691b185a8", "best_bid": "0.09", "best_ask": "0.91"}, {"asset_id": "113376900619893687034938245776304374252728745783907649375498285356692355344325", "price": "0.97", "size": "200", "side": "SELL", "hash": "b1d568d0343c14645c7af4a1ec352a202c27cd38", "best_bid": "0.09", "best_ask": "0.91"}], "timestamp": "1769384052809", "event_type": "price_change"}}
{"_local_timestamp": "2026-01-25T23:34:13.196230+00:00", "data": {"market": "0x335a07913dc4afbc345e5a87410ed1cde3c0b168df2627733d49b081526fd002", "price_changes": [{"asset_id": "62781326014506627625925193711099656595304017608816070575558990777003703808712", "price": "0.003", "size": "305.61", "side": "BUY", "hash": "8ebf96f75d6d4b99f9370369cc47868548bc30f0", "best_bid": "0.004", "best_ask": "0.042"}, {"asset_id": "87400156771035739647299903622267629973291296986678621415627996460491040207279", "price": "0.997", "size": "305.61", "side": "SELL", "hash": "e6087c528d65ea4b35d3c3a16e6d43a1a8c1ebb0", "best_bid": "0.958", "best_ask": "0.996"}], "timestamp": "1769384052809", "event_type": "price_change"}}
{"_local_timestamp": "2026-01-25T23:34:13.383364+00:00", "data": {"market": "0x6f14e52f6a1502a35406feea3f0e8d42502bbf1199e42c73a743fe1745ccc12c", "price_changes": [{"asset_id": "64289097521554308111154900994757912304033484898403308857843640646685729282110", "price": "0.95", "size": "520", "side": "SELL", "hash": "2bb341d84b6ca5bb7fde00f0f3fcecfdef61a67a", "best_bid": "0.23", "best_ask": "0.43"}, {"asset_id": "17811605278785499666964340297379704435403265198212995098387642426099375215061", "price": "0.05", "size": "520", "side": "BUY", "hash": "0371c06a974ac36ea4013ad345ba8a3f29d5bdbf", "best_bid": "0.57", "best_ask": "0.77"}], "timestamp": "1769384052809", "event_type": "price_change"}}
{"_local_timestamp": "2026-01-25T23:34:13.392843+00:00", "data": {"market": "0x40a82f1c7eb272cb89a71a9866b825a5b768955126678151770176c5f0238271", "price_changes": [{"asset_id": "45519542328880128648708358427981839318599846343514485569528454911282685270363", "price": "0.006", "size": "266.66", "side": "BUY", "hash": "f3b096257437bcdc16cda3a03593d636d509cd2c", "best_bid": "0.017", "best_ask": "0.059"}, {"asset_id": "91417351034457389328213996961715046272281153995277672880388168030404378537332", "price": "0.994", "size": "266.66", "side": "SELL", "hash": "314a6904ac56ce5aa32e4ccf89711ddc122812de", "best_bid": "0.941", "best_ask": "0.983"}], "timestamp": "1769384052809", "event_type": "price_change"}}
{"_local_timestamp": "2026-01-25T23:34:13.393524+00:00", "data": {"market": "0x1cc14846bee31efbd7c2016ca1c17664684ead0c7f3b8bd91876033a546128d8", "price_changes": [{"asset_id": "60596582874731501900696294615290867175277482143370610111416633979822519113254", "price": "0.1", "size": "200", "side": "BUY", "hash": "76cf6a4767d841a5b3caca10be9503077f66c450", "best_bid": "0.52", "best_ask": "0.7"}, {"asset_id": "32668102469816119620746811427740823831434256980467530534403997191651163337906", "price": "0.9", "size": "200", "side": "SELL", "hash": "9c3c972b59d605b93f1bdd0a6a0fe4e87f531443", "best_bid": "0.3", "best_ask": "0.48"}], "timestamp": "1769384052809", "event_type": "price_change"}}
{"_local_timestamp": "2026-01-25T23:34:13.396914+00:00", "data": {"market": "0x679bcdd7ed5e81e87f560a516b2ff3b419be87aeb995550b728c75a222bbfd14", "price_changes": [{"asset_id": "20310121731492329356556661175693279243075784612953975064227117258195086943533", "price": "0.05", "size": "100", "side": "BUY", "hash": "55f63997dc4ef5bc33d91c55f3d5b88d7cbe702f", "best_bid": "0.62", "best_ask": "0.92"}, {"asset_id": "2072906368234015194389249304629942211650401137671103595040092908842803594601", "price": "0.95", "size": "100", "side": "SELL", "hash": "2620defdd5454166ecee34639573a3d166bd301f", "best_bid": "0.08", "best_ask": "0.38"}], "timestamp": "1769384052809", "event_type": "price_change"}}
{"_local_timestamp": "2026-01-25T23:34:13.397309+00:00", "data": {"market": "0xeafa01c5d48d6b7826e91f7b31e4a61a05b3fc8a1ad8ccdb2ccbad91b616ae40", "price_changes": [{"asset_id": "97279369561823536114577996580038127500018967849090745350406495876539022297477", "price": "0.1", "size": "0", "side": "BUY", "hash": "31644e58e37a2306b80ce97a80982b654ecc1175", "best_bid": "0.04", "best_ask": "0.29"}, {"asset_id": "83862627090039829837897753251638021110482606851285352212547333342638917195954", "price": "0.9", "size": "0", "side": "SELL", "hash": "aec25a3079ee1e53decbdc36c105ef8721dfa3fe", "best_bid": "0.71", "best_ask": "0.96"}], "timestamp": "1769384052976", "event_type": "price_change"}}
{"_local_timestamp": "2026-01-25T23:34:13.403444+00:00", "data": {"market": "0x1cc14846bee31efbd7c2016ca1c17664684ead0c7f3b8bd91876033a546128d8", "price_changes": [{"asset_id": "32668102469816119620746811427740823831434256980467530534403997191651163337906", "price": "0.3", "size": "0", "side": "BUY", "hash": "2eed203efb30e0f6a9c9ac41b54dd7b27709c79e", "best_bid": "0.2", "best_ask": "0.48"}, {"asset_id": "60596582874731501900696294615290867175277482143370610111416633979822519113254", "price": "0.7", "size": "0", "side": "SELL", "hash": "1ad69627e11c5c17a2ce6a25aec5cbc443989d76", "best_bid": "0.52", "best_ask": "0.8"}], "timestamp": "1769384052976", "event_type": "price_change"}}
{"_local_timestamp": "2026-01-25T23:34:13.485306+00:00", "data": {"market": "0xadd7737a947ee4b404262bd268a7dad202a7b93a853e59eb29c3770bdf5a3c5e", "price_changes": [{"asset_id": "34873810304813988618460030655204351211024364269964394342687234411411922138015", "price": "0.05", "size": "230", "side": "BUY", "hash": "056161b7e008d29251d674414a1d957b06980a4f", "best_bid": "0.46", "best_ask": "0.91"}, {"asset_id": "61947573105398885505676981136106310455132935973656038313589742543062489249520", "price": "0.95", "size": "230", "side": "SELL", "hash": "005ae6331dba3f2a0dc04bebc7514b2d9418af11", "best_bid": "0.09", "best_ask": "0.54"}], "timestamp": "1769384053264", "event_type": "price_change"}}
{"_local_timestamp": "2026-01-25T23:34:13.523806+00:00", "data": {"market": "0x6032e72cb2b4ee54f6c27cc8b155d0233eb5c9e772de85c60e51797b1431ddf8", "price_changes": [{"asset_id": "44848013696493898639828007101683655834417396378616727747692199122767015662748", "price": "0.03", "size": "305.89", "side": "BUY", "hash": "058c1d3a259069c2fc9f80ccc689c71a6f01e5b9", "best_bid": "0.43", "best_ask": "0.93"}, {"asset_id": "7118736781522601355910469975087663596245621357309025148622476783856987875477", "price": "0.97", "size": "305.89", "side": "SELL", "hash": "147682ceafd982ba91f2fd300a34656575cadfb2", "best_bid": "0.07", "best_ask": "0.57"}], "timestamp": "1769384053264", "event_type": "price_change"}}
{"_local_timestamp": "2026-01-25T23:34:13.527146+00:00", "data": {"market": "0x335a07913dc4afbc345e5a87410ed1cde3c0b168df2627733d49b081526fd002", "price_changes": [{"asset_id": "62781326014506627625925193711099656595304017608816070575558990777003703808712", "price": "0.005", "size": "100", "side": "BUY", "hash": "b21c90894898b0a0499d7d0232d5bc5cda907767", "best_bid": "0.005", "best_ask": "0.042"}, {"asset_id": "87400156771035739647299903622267629973291296986678621415627996460491040207279", "price": "0.995", "size": "100", "side": "SELL", "hash": "aba9bedeaa5644b07142443d10be299225de8ed6", "best_bid": "0.958", "best_ask": "0.995"}], "timestamp": "1769384053265", "event_type": "price_change"}}
{"_local_timestamp": "2026-01-25T23:34:13.528594+00:00", "data": {"market": "0xf916b98c173470389af02fa32236bea1333cf05199ee997bc64a39ad6bd589ee", "price_changes": [{"asset_id": "41743802686443315505082888602082131066672260628700340336384534887243556020231", "price": "0.04", "size": "100", "side": "BUY", "hash": "70b71a2bb2eaf18a8d7d095533e823f322a3139b", "best_bid": "0.77", "best_ask": "0.91"}, {"asset_id": "91462927649974781483669557862921344444854660701074121664666696309988647910790", "price": "0.96", "size": "100", "side": "SELL", "hash": "23a3c52f909e5d3429fcc237f9a5b502649762a0", "best_bid": "0.09", "best_ask": "0.23"}], "timestamp": "1769384053264", "event_type": "price_change"}}
{"_local_timestamp": "2026-01-25T23:34:13.529111+00:00", "data": {"market": "0x40a82f1c7eb272cb89a71a9866b825a5b768955126678151770176c5f0238271", "price_changes": [{"asset_id": "45519542328880128648708358427981839318599846343514485569528454911282685270363", "price": "0.005", "size": "307.48", "side": "BUY", "hash": "c263b78e854fabc2e3e061f90cb65ceab480f17f", "best_bid": "0.017", "best_ask": "0.059"}, {"asset_id": "91417351034457389328213996961715046272281153995277672880388168030404378537332", "price": "0.995", "size": "307.48", "side": "SELL", "hash": "54c9f69b804518bbc28a0fed74de672e34853051", "best_bid": "0.941", "best_ask": "0.983"}], "timestamp": "1769384053264", "event_type": "price_change"}}
{"_local_timestamp": "2026-01-25T23:34:13.529532+00:00", "data": {"market": "0xa96f3bae6635e8f42628c39ce7b61fd566b9253d4f2699c3cac08be6d17ca723", "price_changes": [{"asset_id": "31555074014428326614377030963919393145120116674000147512977361328627463258713", "price": "0.06", "size": "236.46", "side": "BUY", "hash": "cb94be8e6cb532d6eaa2f3ddd02c5d42b8ebdad8", "best_bid": "0.06", "best_ask": "0.18"}, {"asset_id": "49976858258828287893504382876186665182729041451625761701208418053508589757916", "price": "0.94", "size": "236.46", "side": "SELL", "hash": "a5dbce32cbfd02409e18c08ea31646c4c314c510", "best_bid": "0.82", "best_ask": "0.94"}], "timestamp": "1769384053264", "event_type": "price_change"}}
{"_local_timestamp": "2026-01-25T23:34:13.532172+00:00", "data": {"market": "0x70d9be5faefbfdef38512a6d9e4392db3084d813ea56f989bd23400fda437b5d", "price_changes": [{"asset_id": "98030581449575327310479171744260311446081913603336917524388058189639018780846", "price": "0.03", "size": "309.49", "side": "BUY", "hash": "de642e934171322ece8a676e9242bd293c36e758", "best_bid": "0.43", "best_ask": "0.87"}, {"asset_id": "21591156070974184450803575087108412438346440628447753978089378794451962462635", "price": "0.97", "size": "309.49", "side": "SELL", "hash": "a533384143f74f79c67413e3f93837635a1a2510", "best_bid": "0.13", "best_ask": "0.57"}], "timestamp": "1769384053269", "event_type": "price_change"}}
{"_local_timestamp": "2026-01-25T23:34:13.589312+00:00", "data": {"market": "0x7a3a3ab1573e95640462d73202fcee6d6ff66f91630d14296a1f71fa5b918bfa", "price_changes": [{"asset_id": "1916547748102919386528896303234847953491748301328504422346327816950157210420", "price": "0.008", "size": "391.6", "side": "BUY", "hash": "16cf9aa9b2b41fad9b32756872727966112c8729", "best_bid": "0.011", "best_ask": "0.027"}, {"asset_id": "22238013475081219064410839764368731545802811151601899423291363232635951279796", "price": "0.992", "size": "391.6", "side": "SELL", "hash": "83c16f860f65e3bb2d376a8d3667d3b3ca235cad", "best_bid": "0.973", "best_ask": "0.989"}], "timestamp": "1769384053278", "event_type": "price_change"}}
{"_local_timestamp": "2026-01-25T23:34:13.594230+00:00", "data": {"market": "0x21fcddff254ff0337ac03ec276927cc90e5228ac1c5b16c36300589318197fc4", "price_changes": [{"asset_id": "108893558475396584780619998257373148912765768914968487436636153030532224366680", "price": "0.03", "size": "350", "side": "BUY", "hash": "2ba13bc895507748b30935e3aac888c1f5430291", "best_bid": "0.63", "best_ask": "0.94"}, {"asset_id": "41605452123604733553647691830638760854992806694633100987207040539420095696757", "price": "0.97", "size": "350", "side": "SELL", "hash": "ae08ade098d2a1aa5a176a72e067e30a4d9f5398", "best_bid": "0.06", "best_ask": "0.37"}], "timestamp": "1769384053279", "event_type": "price_change"}}
{"_local_timestamp": "2026-01-25T23:34:13.628159+00:00", "data": {"market": "0x679bcdd7ed5e81e87f560a516b2ff3b419be87aeb995550b728c75a222bbfd14", "price_changes": [{"asset_id": "20310121731492329356556661175693279243075784612953975064227117258195086943533", "price": "0.03", "size": "306.25", "side": "BUY", "hash": "3f57e26e20c254ff4bc8a1d7cbeb6bd10539cfef", "best_bid": "0.62", "best_ask": "0.92"}, {"asset_id": "2072906368234015194389249304629942211650401137671103595040092908842803594601", "price": "0.97", "size": "306.25", "side": "SELL", "hash": "c4726a101bcb81b0c70f3b90c5609bc32a4e3660", "best_bid": "0.08", "best_ask": "0.38"}], "timestamp": "1769384053282", "event_type": "price_change"}}
{"_local_timestamp": "2026-01-25T23:34:13.636778+00:00", "data": {"market": "0xe9cd6563ed540dae9cd820d8deb6080a33fbc3a589b238493519a4a96a1386e1", "price_changes": [{"asset_id": "46611422896979296181480968455950153385868875385647034766198731891278167221454", "price": "0.05", "size": "186.66", "side": "BUY", "hash": "1dd742d0d5acc3f0645e0f363f389e539490af86", "best_bid": "0.09", "best_ask": "0.91"}, {"asset_id": "113376900619893687034938245776304374252728745783907649375498285356692355344325", "price": "0.95", "size": "186.66", "side": "SELL", "hash": "0f7c5bc919c5e4fb260e7237d3306d74a208e61d", "best_bid": "0.09", "best_ask": "0.91"}], "timestamp": "1769384053282", "event_type": "price_change"}}
{"_local_timestamp": "2026-01-25T23:34:13.638221+00:00", "data": {"market": "0x6f14e52f6a1502a35406feea3f0e8d42502bbf1199e42c73a743fe1745ccc12c", "price_changes": [{"asset_id": "64289097521554308111154900994757912304033484898403308857843640646685729282110", "price": "0.06", "size": "333.32", "side": "BUY", "hash": "f4b6052596b9716aabdf27571ccf0724729c89e6", "best_bid": "0.23", "best_ask": "0.43"}, {"asset_id": "17811605278785499666964340297379704435403265198212995098387642426099375215061", "price": "0.94", "size": "333.32", "side": "SELL", "hash": "617c29a2f656571ae32f798a905d5177ce1abe90", "best_bid": "0.57", "best_ask": "0.77"}], "timestamp": "1769384053282", "event_type": "price_change"}}
{"_local_timestamp": "2026-01-25T23:34:13.638733+00:00", "data": {"market": "0xd8d3819d0166dcce22f68fd24315205f4b8be323803ac55fae013032745499f7", "price_changes": [{"asset_id": "66248863053233981483390075184660170267560753276478697725455087633235785089364", "price": "0.05", "size": "130", "side": "BUY", "hash": "d2eeeeb30d3af90b3b8770b1aceae6c35b6fc5e6", "best_bid": "0.53", "best_ask": "0.88"}, {"asset_id": "110039030678047835827290477479682636180706221087707522635871765904720785066494", "price": "0.95", "size": "130", "side": "SELL", "hash": "e7ab0727ee8a5ec29dde9d2c967ac32bfa69ca14", "best_bid": "0.12", "best_ask": "0.47"}], "timestamp": "1769384053281", "event_type": "price_change"}}
{"_local_timestamp": "2026-01-25T23:34:13.639180+00:00", "data": {"market": "0x6f14e52f6a1502a35406feea3f0e8d42502bbf1199e42c73a743fe1745ccc12c", "price_changes": [{"asset_id": "64289097521554308111154900994757912304033484898403308857843640646685729282110", "price": "0.89", "size": "160", "side": "SELL", "hash": "b5d171703d19007d8ee4c31c2bb0f9e05bf40c2f", "best_bid": "0.23", "best_ask": "0.43"}, {"asset_id": "17811605278785499666964340297379704435403265198212995098387642426099375215061", "price": "0.11", "size": "160", "side": "BUY", "hash": "c16a4022cc42b60cadf4535635864a952af6700b", "best_bid": "0.57", "best_ask": "0.77"}], "timestamp": "1769384053296", "event_type": "price_change"}}
{"_local_timestamp": "2026-01-25T23:34:13.667598+00:00", "data": {"market": "0x335a07913dc4afbc345e5a87410ed1cde3c0b168df2627733d49b081526fd002", "price_changes": [{"asset_id": "62781326014506627625925193711099656595304017608816070575558990777003703808712", "price": "0.004", "size": "832.88", "side": "BUY", "hash": "76aeb6dd1f0a4ea59a3dbd358c25cf6bf865d381", "best_bid": "0.005", "best_ask": "0.042"}, {"asset_id": "87400156771035739647299903622267629973291296986678621415627996460491040207279", "price": "0.996", "size": "832.88", "side": "SELL", "hash": "7c6a9e2725d464caeb2261a7fd3063c86b095894", "best_bid": "0.958", "best_ask": "0.995"}], "timestamp": "1769384053325", "event_type": "price_change"}}
{"_local_timestamp": "2026-01-25T23:34:13.683347+00:00", "data": {"market": "0x335a07913dc4afbc345e5a87410ed1cde3c0b168df2627733d49b081526fd002", "price_changes": [{"asset_id": "62781326014506627625925193711099656595304017608816070575558990777003703808712", "price": "0.006", "size": "179", "side": "BUY", "hash": "ca5952b4303f664b95378d17b43fb997d1fc104c", "best_bid": "0.006", "best_ask": "0.042"}, {"asset_id": "87400156771035739647299903622267629973291296986678621415627996460491040207279", "price": "0.994", "size": "179", "side": "SELL", "hash": "1ba3182a2423887c70731f3bf674304c0b212c75", "best_bid": "0.958", "best_ask": "0.994"}], "timestamp": "1769384053351", "event_type": "price_change"}}
{"_local_timestamp": "2026-01-25T23:34:14.097150+00:00", "data": {"market": "0x1cc14846bee31efbd7c2016ca1c17664684ead0c7f3b8bd91876033a546128d8", "price_changes": [{"asset_id": "32668102469816119620746811427740823831434256980467530534403997191651163337906", "price": "0.2", "size": "96.66", "side": "BUY", "hash": "f330f55bd39225897d3d2a32ef9d9e53630028af", "best_bid": "0.2", "best_ask": "0.48"}, {"asset_id": "60596582874731501900696294615290867175277482143370610111416633979822519113254", "price": "0.8", "size": "96.66", "side": "SELL", "hash": "9e47a57b33f077637afe6c355c6c5dae7f099521", "best_bid": "0.52", "best_ask": "0.8"}], "timestamp": "1769384053871", "event_type": "price_change"}}
{"_local_timestamp": "2026-01-25T23:34:14.256460+00:00", "data": {"market": "0xa96f3bae6635e8f42628c39ce7b61fd566b9253d4f2699c3cac08be6d17ca723", "price_changes": [{"asset_id": "31555074014428326614377030963919393145120116674000147512977361328627463258713", "price": "0.06", "size": "206.46", "side": "BUY", "hash": "65d98e65e39d5e5d0b22141e171dffbe8001ffa6", "best_bid": "0.06", "best_ask": "0.18"}, {"asset_id": "49976858258828287893504382876186665182729041451625761701208418053508589757916", "price": "0.94", "size": "206.46", "side": "SELL", "hash": "effb0cffbec97aab706974e1c46f5d56d1481604", "best_bid": "0.82", "best_ask": "0.94"}], "timestamp": "1769384054029", "event_type": "price_change"}}
{"_local_timestamp": "2026-01-25T23:34:14.320596+00:00", "data": {"market": "0xa96f3bae6635e8f42628c39ce7b61fd566b9253d4f2699c3cac08be6d17ca723", "price_changes": [{"asset_id": "31555074014428326614377030963919393145120116674000147512977361328627463258713", "price": "0.07", "size": "30", "side": "BUY", "hash": "ffd864c93757aecdfb23efef267c75d45bcf128d", "best_bid": "0.07", "best_ask": "0.18"}, {"asset_id": "49976858258828287893504382876186665182729041451625761701208418053508589757916", "price": "0.93", "size": "30", "side": "SELL", "hash": "161c732c3d5d9e6d399a9ad802471b73f745988b", "best_bid": "0.82", "best_ask": "0.93"}], "timestamp": "1769384054080", "event_type": "price_change"}}
{"_local_timestamp": "2026-01-25T23:34:16.743105+00:00", "data": {"market": "0xeafa01c5d48d6b7826e91f7b31e4a61a05b3fc8a1ad8ccdb2ccbad91b616ae40", "price_changes": [{"asset_id": "97279369561823536114577996580038127500018967849090745350406495876539022297477", "price": "0.12", "size": "50", "side": "BUY", "hash": "fe6b62c814aa574a1bfbb6229615d323d90e53eb", "best_bid": "0.12", "best_ask": "0.29"}, {"asset_id": "83862627090039829837897753251638021110482606851285352212547333342638917195954", "price": "0.88", "size": "50", "side": "SELL", "hash": "54062dba064d8ba96bd829923529118d1d099b29", "best_bid": "0.71", "best_ask": "0.88"}], "timestamp": "1769384056520", "event_type": "price_change"}}
{"_local_timestamp": "2026-01-25T23:34:17.629167+00:00", "data": {"market": "0xbf7f7047fa5719e010b9c35abab4d1510f80d78998ede7928dee762b842fd8fa", "price_changes": [{"asset_id": "99317080920004040908110146285425334348796704558628502185978368700992863001849", "price": "0.59", "size": "0", "side": "BUY", "hash": "4f1974e568ee409a2886c6c79b833c8987f6372e", "best_bid": "0.6", "best_ask": "0.99"}, {"asset_id": "80475936180674486630534655774036670401396382603097237786734519090691938222605", "price": "0.41", "size": "0", "side": "SELL", "hash": "9d232088f8784f78fba9690cc8b82695cbb7fcdc", "best_bid": "0.01", "best_ask": "0.4"}], "timestamp": "1769384057406", "event_type": "price_change"}}
{"_local_timestamp": "2026-01-25T23:34:17.668267+00:00", "data": {"market": "0xd8d3819d0166dcce22f68fd24315205f4b8be323803ac55fae013032745499f7", "price_changes": [{"asset_id": "66248863053233981483390075184660170267560753276478697725455087633235785089364", "price": "0.54", "size": "9.25", "side": "BUY", "hash": "2bdc1e503a3347cec85e558cd07d385981fa309b", "best_bid": "0.54", "best_ask": "0.88"}, {"asset_id": "110039030678047835827290477479682636180706221087707522635871765904720785066494", "price": "0.46", "size": "9.25", "side": "SELL", "hash": "13a4c001fb0b938505c4f383960ee647d1d16a92", "best_bid": "0.12", "best_ask": "0.46"}], "timestamp": "1769384057433", "event_type": "price_change"}}
{"_local_timestamp": "2026-01-25T23:34:17.668957+00:00", "data": {"market": "0x6032e72cb2b4ee54f6c27cc8b155d0233eb5c9e772de85c60e51797b1431ddf8", "price_changes": [{"asset_id": "44848013696493898639828007101683655834417396378616727747692199122767015662748", "price": "0.44", "size": "11.36", "side": "BUY", "hash": "117ac313a381af12c82724fe1d5e56b56e95267c", "best_bid": "0.44", "best_ask": "0.93"}, {"asset_id": "7118736781522601355910469975087663596245621357309025148622476783856987875477", "price": "0.56", "size": "11.36", "side": "SELL", "hash": "1f02e65c770eac89e52d592b2b6caf4e230e1140", "best_bid": "0.07", "best_ask": "0.56"}], "timestamp": "1769384057433", "event_type": "price_change"}}
{"_local_timestamp": "2026-01-25T23:34:17.669451+00:00", "data": {"market": "0x335a07913dc4afbc345e5a87410ed1cde3c0b168df2627733d49b081526fd002", "price_changes": [{"asset_id": "62781326014506627625925193711099656595304017608816070575558990777003703808712", "price": "0.004", "size": "82.88", "side": "BUY", "hash": "8bd32b91aed229fa59b8f1166e07642e39cef196", "best_bid": "0.006", "best_ask": "0.042"}, {"asset_id": "87400156771035739647299903622267629973291296986678621415627996460491040207279", "price": "0.996", "size": "82.88", "side": "SELL", "hash": "ebda926ffa97fd2523b62c96d91465de6e21b9bf", "best_bid": "0.958", "best_ask": "0.994"}], "timestamp": "1769384057433", "event_type": "price_change"}}
{"_local_timestamp": "2026-01-25T23:34:17.670382+00:00", "data": {"market": "0xbf7f7047fa5719e010b9c35abab4d1510f80d78998ede7928dee762b842fd8fa", "price_changes": [{"asset_id": "99317080920004040908110146285425334348796704558628502185978368700992863001849", "price": "0.61", "size": "8.19", "side": "BUY", "hash": "52b3943928ef628c1c849d9f28c27ebdc6384a4b", "best_bid": "0.61", "best_ask": "0.99"}, {"asset_id": "80475936180674486630534655774036670401396382603097237786734519090691938222605", "price": "0.39", "size": "8.19", "side": "SELL", "hash": "90175bc4eb5f786633559a7215e5584965432879", "best_bid": "0.01", "best_ask": "0.39"}], "timestamp": "1769384057433", "event_type": "price_change"}}
{"_local_timestamp": "2026-01-25T23:34:17.690802+00:00", "data": {"market": "0xadd7737a947ee4b404262bd268a7dad202a7b93a853e59eb29c3770bdf5a3c5e", "price_changes": [{"asset_id": "34873810304813988618460030655204351211024364269964394342687234411411922138015", "price": "0.47", "size": "10.63", "side": "BUY", "hash": "d30956423c6d641190c6d52cbada7eb8b7141a27", "best_bid": "0.47", "best_ask": "0.91"}, {"asset_id": "61947573105398885505676981136106310455132935973656038313589742543062489249520", "price": "0.53", "size": "10.63", "side": "SELL", "hash": "bee3b90cd337d674838ddfd52011cd5fbf5ad1c2", "best_bid": "0.09", "best_ask": "0.53"}], "timestamp": "1769384057459", "event_type": "price_change"}}
{"_local_timestamp": "2026-01-25T23:34:17.693257+00:00", "data": {"market": "0x21fcddff254ff0337ac03ec276927cc90e5228ac1c5b16c36300589318197fc4", "price_changes": [{"asset_id": "108893558475396584780619998257373148912765768914968487436636153030532224366680", "price": "0.64", "size": "7.81", "side": "BUY", "hash": "cd319abde5bc53103a2f56ca04ba4f10dbc17aed", "best_bid": "0.64", "best_ask": "0.94"}, {"asset_id": "41605452123604733553647691830638760854992806694633100987207040539420095696757", "price": "0.36", "size": "7.81", "side": "SELL", "hash": "627d7c5d541255c85acf9161d4ce9581f318a533", "best_bid": "0.06", "best_ask": "0.36"}], "timestamp": "1769384057459", "event_type": "price_change"}}
{"_local_timestamp": "2026-01-25T23:34:17.780028+00:00", "data": {"market": "0x335a07913dc4afbc345e5a87410ed1cde3c0b168df2627733d49b081526fd002", "price_changes": [{"asset_id": "62781326014506627625925193711099656595304017608816070575558990777003703808712", "price": "0.006", "size": "679", "side": "BUY", "hash": "6ac1ed486f6ca2dd1e40d5b1bbc5aab49d864883", "best_bid": "0.006", "best_ask": "0.042"}, {"asset_id": "87400156771035739647299903622267629973291296986678621415627996460491040207279", "price": "0.994", "size": "679", "side": "SELL", "hash": "e3cb6410f7a913fbcbde7019cb919b78e3dddd11", "best_bid": "0.958", "best_ask": "0.994"}], "timestamp": "1769384057533", "event_type": "price_change"}}
{"_local_timestamp": "2026-01-25T23:34:24.736376+00:00", "data": {"market": "0x146def8be2d4ec270cac5e8cae1d60cf8ea7064200594d10e74104db6b9a60fd", "price_changes": [{"asset_id": "59834485698328047678505195191113741956543908658984089284407908730537452141550", "price": "0.29", "size": "50", "side": "BUY", "hash": "a7d90fe6d4fe2f4ebf0e3d5c60248f637d42c23a", "best_bid": "0.29", "best_ask": "0.8"}, {"asset_id": "76512560903138059195694921143552469386897971398516938467610044078742285307792", "price": "0.71", "size": "50", "side": "SELL", "hash": "8fe446a41787dad9955ce590c3ed1038d3da24aa", "best_bid": "0.2", "best_ask": "0.71"}], "timestamp": "1769384064511", "event_type": "price_change"}}
{"_local_timestamp": "2026-01-25T23:34:24.737274+00:00", "data": {"market": "0x6032e72cb2b4ee54f6c27cc8b155d0233eb5c9e772de85c60e51797b1431ddf8", "price_changes": [{"asset_id": "44848013696493898639828007101683655834417396378616727747692199122767015662748", "price": "0.77", "size": "50", "side": "BUY", "hash": "49ba92c72be57fb084522c322544e9e0f24598ba", "best_bid": "0.77", "best_ask": "0.93"}, {"asset_id": "7118736781522601355910469975087663596245621357309025148622476783856987875477", "price": "0.23", "size": "50", "side": "SELL", "hash": "66910905889d1793cb6feb8d1ee200e614bac76a", "best_bid": "0.07", "best_ask": "0.23"}], "timestamp": "1769384064511", "event_type": "price_change"}}
{"_local_timestamp": "2026-01-25T23:34:26.780967+00:00", "data": {"market": "0xd2b2d52f7b03ee5ddc6f79596f8e058eedf95af2c9df32fc5a9d6b3f7d4de949", "price_changes": [{"asset_id": "77757001671665002605821663755609213754761394915884653403308048610819412553431", "price": "0.53", "size": "50", "side": "BUY", "hash": "7eada758184bf68de002d9844ec3a5cf022365ac", "best_bid": "0.53", "best_ask": "0.71"}, {"asset_id": "49722951406964623396190322027929924958979018653915811865810011588719564539488", "price": "0.47", "size": "50", "side": "SELL", "hash": "52bf728a8035b518270591d9d3dd37dcdfee6563", "best_bid": "0.29", "best_ask": "0.47"}], "timestamp": "1769384066540", "event_type": "price_change"}}
{"_local_timestamp": "2026-01-25T23:34:26.781554+00:00", "data": {"market": "0xadd7737a947ee4b404262bd268a7dad202a7b93a853e59eb29c3770bdf5a3c5e", "price_changes": [{"asset_id": "34873810304813988618460030655204351211024364269964394342687234411411922138015", "price": "0.79", "size": "50", "side": "BUY", "hash": "67ce692376a8ca1868361a5926b43bb84942db26", "best_bid": "0.79", "best_ask": "0.91"}, {"asset_id": "61947573105398885505676981136106310455132935973656038313589742543062489249520", "price": "0.21", "size": "50", "side": "SELL", "hash": "b258a982e77595fa47ddfa0ca54e544427be9127", "best_bid": "0.09", "best_ask": "0.21"}], "timestamp": "1769384066540", "event_type": "price_change"}}
{"_local_timestamp": "2026-01-25T23:34:26.782057+00:00", "data": {"market": "0x90a6d406570f273840bd2e39e25dbd0a91655cd347dbb2bc381863743044bf32", "price_changes": [{"asset_id": "36331391317493054259843206160279589805054745072393638988521393636953188108839", "price": "0.24", "size": "50", "side": "BUY", "hash": "caece03b75676707fd7fb11d8acc1c784b212d5f", "best_bid": "0.24", "best_ask": "0.78"}, {"asset_id": "92143930323152159931232014367424593746113767612080401756819785961080544448740", "price": "0.76", "size": "50", "side": "SELL", "hash": "9b0cc83a4290fb3399fafa179fee338080885289", "best_bid": "0.22", "best_ask": "0.76"}], "timestamp": "1769384066540", "event_type": "price_change"}}
{"_local_timestamp": "2026-01-25T23:34:26.782504+00:00", "data": {"market": "0x1cc14846bee31efbd7c2016ca1c17664684ead0c7f3b8bd91876033a546128d8", "price_changes": [{"asset_id": "32668102469816119620746811427740823831434256980467530534403997191651163337906", "price": "0.32", "size": "50", "side": "BUY", "hash": "6f3bfb6bc66e83071322956aef6882908a074805", "best_bid": "0.32", "best_ask": "0.48"}, {"asset_id": "60596582874731501900696294615290867175277482143370610111416633979822519113254", "price": "0.68", "size": "50", "side": "SELL", "hash": "3ba454213d4caa3a91e5eff8128cd735fa8de0d0", "best_bid": "0.52", "best_ask": "0.68"}], "timestamp": "1769384066540", "event_type": "price_change"}}
{"_local_timestamp": "2026-01-25T23:34:27.757260+00:00", "data": {"market": "0x1cc14846bee31efbd7c2016ca1c17664684ead0c7f3b8bd91876033a546128d8", "price_changes": [{"asset_id": "32668102469816119620746811427740823831434256980467530534403997191651163337906", "price": "0.2", "size": "66.66", "side": "BUY", "hash": "dcd71f1ee8f25e8b595a5c1b1e0405a08686fa24", "best_bid": "0.32", "best_ask": "0.48"}, {"asset_id": "60596582874731501900696294615290867175277482143370610111416633979822519113254", "price": "0.8", "size": "66.66", "side": "SELL", "hash": "5eb848380474374bbe10ba6595181857083ecc72", "best_bid": "0.52", "best_ask": "0.68"}], "timestamp": "1769384067546", "event_type": "price_change"}}
{"_local_timestamp": "2026-01-25T23:34:27.924547+00:00", "data": {"market": "0x5b17571f0687e9ef62aead3a3e57bfc617f16e4806865d8b7cc609a680ac9892", "price_changes": [{"asset_id": "54672482098306675309495708206879727568512955356356264682879888123590518385092", "price": "0.14", "size": "125", "side": "BUY", "hash": "6fe781d2b5114a6390d88cb976ae69db99861262", "best_bid": "0.67", "best_ask": "0.99"}, {"asset_id": "30934121158421236234732376879006750136278688549793740923122711845308054079491", "price": "0.86", "size": "125", "side": "SELL", "hash": "b959a3773f482b898de925aa4eb56e63761c618f", "best_bid": "0.01", "best_ask": "0.33"}], "timestamp": "1769384067583", "event_type": "price_change"}}
{"_local_timestamp": "2026-01-25T23:34:28.019243+00:00", "data": {"market": "0x1cc14846bee31efbd7c2016ca1c17664684ead0c7f3b8bd91876033a546128d8", "price_changes": [{"asset_id": "60596582874731501900696294615290867175277482143370610111416633979822519113254", "price": "0.31", "size": "150", "side": "BUY", "hash": "2e83a6c4d0028f00b4cf80f78d2f704eeb4a4c66", "best_bid": "0.52", "best_ask": "0.68"}, {"asset_id": "32668102469816119620746811427740823831434256980467530534403997191651163337906", "price": "0.69", "size": "150", "side": "SELL", "hash": "7483d96c035a58e790aa5696d14e1769d1753241", "best_bid": "0.32", "best_ask": "0.48"}], "timestamp": "1769384067612", "event_type": "price_change"}}
{"_local_timestamp": "2026-01-25T23:34:28.019828+00:00", "data": {"market": "0x1cc14846bee31efbd7c2016ca1c17664684ead0c7f3b8bd91876033a546128d8", "price_changes": [{"asset_id": "60596582874731501900696294615290867175277482143370610111416633979822519113254", "price": "0.23", "size": "786.95", "side": "BUY", "hash": "f0fe43b6b7b3ff5e99c0e524bd59f264eb959b16", "best_bid": "0.52", "best_ask": "0.68"}, {"asset_id": "32668102469816119620746811427740823831434256980467530534403997191651163337906", "price": "0.77", "size": "786.95", "side": "SELL", "hash": "73963f2c42301a1e82da2266cf0e1d328c24b0a1", "best_bid": "0.32", "best_ask": "0.48"}], "timestamp": "1769384067617", "event_type": "price_change"}}
{"_local_timestamp": "2026-01-25T23:34:28.723350+00:00", "data": {"market": "0xf916b98c173470389af02fa32236bea1333cf05199ee997bc64a39ad6bd589ee", "price_changes": [{"asset_id": "41743802686443315505082888602082131066672260628700340336384534887243556020231", "price": "0.11", "size": "325", "side": "BUY", "hash": "598222ab22954ba00fd4286760105ec77f0f6640", "best_bid": "0.77", "best_ask": "0.91"}, {"asset_id": "91462927649974781483669557862921344444854660701074121664666696309988647910790", "price": "0.89", "size": "325", "side": "SELL", "hash": "9d4a3fbdf662b8ee83bd892873eb4ff1a8d5c8dd", "best_bid": "0.09", "best_ask": "0.23"}], "timestamp": "1769384068154", "event_type": "price_change"}}
{"_local_timestamp": "2026-01-25T23:34:28.730511+00:00", "data": {"market": "0x5b17571f0687e9ef62aead3a3e57bfc617f16e4806865d8b7cc609a680ac9892", "price_changes": [{"asset_id": "54672482098306675309495708206879727568512955356356264682879888123590518385092", "price": "0.16", "size": "150", "side": "BUY", "hash": "77a37c62414880532b65dd708c7e33445f3bd275", "best_bid": "0.67", "best_ask": "0.99"}, {"asset_id": "30934121158421236234732376879006750136278688549793740923122711845308054079491", "price": "0.84", "size": "150", "side": "SELL", "hash": "2a31ced18b26778e18841072a29b7e3a23d622ff", "best_bid": "0.01", "best_ask": "0.33"}], "timestamp": "1769384068152", "event_type": "price_change"}}
{"_local_timestamp": "2026-01-25T23:34:28.739284+00:00", "data": {"market": "0x6f14e52f6a1502a35406feea3f0e8d42502bbf1199e42c73a743fe1745ccc12c", "price_changes": [{"asset_id": "17811605278785499666964340297379704435403265198212995098387642426099375215061", "price": "0.06", "size": "1399.66", "side": "BUY", "hash": "e3b31709e2b8749025ae855cc47621653e87e84f", "best_bid": "0.57", "best_ask": "0.77"}, {"asset_id": "64289097521554308111154900994757912304033484898403308857843640646685729282110", "price": "0.94", "size": "1399.66", "side": "SELL", "hash": "8143912dfc96f267761dbc6df7299290b3aaba2a", "best_bid": "0.23", "best_ask": "0.43"}], "timestamp": "1769384068156", "event_type": "price_change"}}
{"_local_timestamp": "2026-01-25T23:34:28.741557+00:00", "data": {"market": "0x70d9be5faefbfdef38512a6d9e4392db3084d813ea56f989bd23400fda437b5d", "price_changes": [{"asset_id": "98030581449575327310479171744260311446081913603336917524388058189639018780846", "price": "0.01", "size": "3619.44", "side": "BUY", "hash": "6b87cd98976b7ab9a488cfb7c00b5521a1e54ccb", "best_bid": "0.43", "best_ask": "0.87"}, {"asset_id": "21591156070974184450803575087108412438346440628447753978089378794451962462635", "price": "0.99", "size": "3619.44", "side": "SELL", "hash": "d9fda5d21c2b975eb7e2f6b32960aa9cc189fe71", "best_bid": "0.13", "best_ask": "0.57"}], "timestamp": "1769384068165", "event_type": "price_change"}}
{"_local_timestamp": "2026-01-25T23:34:28.751361+00:00", "data": {"market": "0xd8d3819d0166dcce22f68fd24315205f4b8be323803ac55fae013032745499f7", "price_changes": [{"asset_id": "66248863053233981483390075184660170267560753276478697725455087633235785089364", "price": "0.01", "size": "3615.51", "side": "BUY", "hash": "594ab1a326d0e081a9ba81342bdb8419a6d679c6", "best_bid": "0.54", "best_ask": "0.88"}, {"asset_id": "110039030678047835827290477479682636180706221087707522635871765904720785066494", "price": "0.99", "size": "3615.51", "side": "SELL", "hash": "58509c93c3d33594db87695e1acd71c1a5e34787", "best_bid": "0.12", "best_ask": "0.46"}], "timestamp": "1769384068170", "event_type": "price_change"}}
{"_local_timestamp": "2026-01-25T23:34:28.753368+00:00", "data": {"market": "0x21fcddff254ff0337ac03ec276927cc90e5228ac1c5b16c36300589318197fc4", "price_changes": [{"asset_id": "108893558475396584780619998257373148912765768914968487436636153030532224366680", "price": "0.01", "size": "3678.69", "side": "BUY", "hash": "952ecfcb6f494e2fd7165a7ee1281beed9702953", "best_bid": "0.64", "best_ask": "0.94"}, {"asset_id": "41605452123604733553647691830638760854992806694633100987207040539420095696757", "price": "0.99", "size": "3678.69", "side": "SELL", "hash": "190012eb6dcfe4a45cff1088a5177d5ef1004ce8", "best_bid": "0.06", "best_ask": "0.36"}], "timestamp": "1769384068171", "event_type": "price_change"}}
{"_local_timestamp": "2026-01-25T23:34:28.841904+00:00", "data": {"market": "0xf916b98c173470389af02fa32236bea1333cf05199ee997bc64a39ad6bd589ee", "price_changes": [{"asset_id": "41743802686443315505082888602082131066672260628700340336384534887243556020231", "price": "0.01", "size": "3610.09", "side": "BUY", "hash": "fc0782a2ba52cd9edc58c511ea25e0438d520337", "best_bid": "0.77", "best_ask": "0.91"}, {"asset_id": "91462927649974781483669557862921344444854660701074121664666696309988647910790", "price": "0.99", "size": "3610.09", "side": "SELL", "hash": "ec18846c51a8ac86e89b8d7292e2225c76a7bb7a", "best_bid": "0.09", "best_ask": "0.23"}], "timestamp": "1769384068233", "event_type": "price_change"}}
{"_local_timestamp": "2026-01-25T23:34:28.843224+00:00", "data": {"market": "0x5b17571f0687e9ef62aead3a3e57bfc617f16e4806865d8b7cc609a680ac9892", "price_changes": [{"asset_id": "54672482098306675309495708206879727568512955356356264682879888123590518385092", "price": "0.11", "size": "206", "side": "BUY", "hash": "f659fd567bd60a3c21bb4dff13eb9f2dcb9ba116", "best_bid": "0.67", "best_ask": "0.99"}, {"asset_id": "30934121158421236234732376879006750136278688549793740923122711845308054079491", "price": "0.89", "size": "206", "side": "SELL", "hash": "01a104f6b6e239bf931841f67c17e44a49bd9c04", "best_bid": "0.01", "best_ask": "0.33"}], "timestamp": "1769384068236", "event_type": "price_change"}}
{"_local_timestamp": "2026-01-25T23:34:28.845835+00:00", "data": {"market": "0x6f14e52f6a1502a35406feea3f0e8d42502bbf1199e42c73a743fe1745ccc12c", "price_changes": [{"asset_id": "17811605278785499666964340297379704435403265198212995098387642426099375215061", "price": "0.11", "size": "360", "side": "BUY", "hash": "ab74b2d98152c1d8f363655d57c27948ba3874b0", "best_bid": "0.57", "best_ask": "0.77"}, {"asset_id": "64289097521554308111154900994757912304033484898403308857843640646685729282110", "price": "0.89", "size": "360", "side": "SELL", "hash": "fa403ecb3b9958e3f9c1b684d19770956bab3171", "best_bid": "0.23", "best_ask": "0.43"}], "timestamp": "1769384068238", "event_type": "price_change"}}
{"_local_timestamp": "2026-01-25T23:34:28.848946+00:00", "data": {"market": "0x5b17571f0687e9ef62aead3a3e57bfc617f16e4806865d8b7cc609a680ac9892", "price_changes": [{"asset_id": "54672482098306675309495708206879727568512955356356264682879888123590518385092", "price": "0.21", "size": "150", "side": "BUY", "hash": "787c733e6b82c6dae48b1b8fc7124da38dbdfd7a", "best_bid": "0.67", "best_ask": "0.99"}, {"asset_id": "30934121158421236234732376879006750136278688549793740923122711845308054079491", "price": "0.79", "size": "150", "side": "SELL", "hash": "9b46195b1c886ef61b55b08ba099bb4acff0c12b", "best_bid": "0.01", "best_ask": "0.33"}], "timestamp": "1769384068275", "event_type": "price_change"}}
{"_local_timestamp": "2026-01-25T23:34:28.865705+00:00", "data": {"market": "0x6f14e52f6a1502a35406feea3f0e8d42502bbf1199e42c73a743fe1745ccc12c", "price_changes": [{"asset_id": "17811605278785499666964340297379704435403265198212995098387642426099375215061", "price": "0.16", "size": "425", "side": "BUY", "hash": "48e7f731fd7be8460e65361a73a8a9b679991156", "best_bid": "0.57", "best_ask": "0.77"}, {"asset_id": "64289097521554308111154900994757912304033484898403308857843640646685729282110", "price": "0.84", "size": "425", "side": "SELL", "hash": "ebc3df90aadb452299dfa300889ee551e1d6ee2d", "best_bid": "0.23", "best_ask": "0.43"}], "timestamp": "1769384068274", "event_type": "price_change"}}
{"_local_timestamp": "2026-01-25T23:34:29.013403+00:00", "data": {"market": "0x6f14e52f6a1502a35406feea3f0e8d42502bbf1199e42c73a743fe1745ccc12c", "price_changes": [{"asset_id": "17811605278785499666964340297379704435403265198212995098387642426099375215061", "price": "0.21", "size": "100", "side": "BUY", "hash": "f20cec827cd56be9b39485cdf22df3ace8bf2f7d", "best_bid": "0.57", "best_ask": "0.77"}, {"asset_id": "64289097521554308111154900994757912304033484898403308857843640646685729282110", "price": "0.79", "size": "100", "side": "SELL", "hash": "be762168f2c62da609da79e874e0e1c8f0032eb5", "best_bid": "0.23", "best_ask": "0.43"}], "timestamp": "1769384068278", "event_type": "price_change"}}
{"_local_timestamp": "2026-01-25T23:34:42.541608+00:00", "data": {"market": "0xadd7737a947ee4b404262bd268a7dad202a7b93a853e59eb29c3770bdf5a3c5e", "price_changes": [{"asset_id": "61947573105398885505676981136106310455132935973656038313589742543062489249520", "price": "0.55", "size": "0", "side": "SELL", "hash": "5031791140109ccb176fb5d9a48fe2aa217edf42", "best_bid": "0.09", "best_ask": "0.21"}, {"asset_id": "34873810304813988618460030655204351211024364269964394342687234411411922138015", "price": "0.45", "size": "0", "side": "BUY", "hash": "726a40ea7a2a4357560bc64aef12a2ee77aa803c", "best_bid": "0.79", "best_ask": "0.91"}], "timestamp": "1769384082474", "event_type": "price_change"}}
{"_local_timestamp": "2026-01-25T23:34:43.330475+00:00", "data": {"market": "0xadd7737a947ee4b404262bd268a7dad202a7b93a853e59eb29c3770bdf5a3c5e", "price_changes": [{"asset_id": "61947573105398885505676981136106310455132935973656038313589742543062489249520", "price": "0.52", "size": "6", "side": "SELL", "hash": "39b5454cc78e05dcade8c4ba730f9a4caf99a06a", "best_bid": "0.09", "best_ask": "0.21"}, {"asset_id": "34873810304813988618460030655204351211024364269964394342687234411411922138015", "price": "0.48", "size": "6", "side": "BUY", "hash": "e53c0fe759558f0eced878a473bc911073a162d3", "best_bid": "0.79", "best_ask": "0.91"}], "timestamp": "1769384083261", "event_type": "price_change"}}
{"_local_timestamp": "2026-01-25T23:34:44.648583+00:00", "data": {"market": "0x6032e72cb2b4ee54f6c27cc8b155d0233eb5c9e772de85c60e51797b1431ddf8", "price_changes": [{"asset_id": "44848013696493898639828007101683655834417396378616727747692199122767015662748", "price": "0.44", "size": "0", "side": "BUY", "hash": "2b1adfa611fba34ab908ac765d6622ba2abfeecc", "best_bid": "0.77", "best_ask": "0.93"}, {"asset_id": "7118736781522601355910469975087663596245621357309025148622476783856987875477", "price": "0.56", "size": "0", "side": "SELL", "hash": "6a55dc07b12f722c0cd72fe3d68d0414636431e1", "best_bid": "0.07", "best_ask": "0.23"}], "timestamp": "1769384084582", "event_type": "price_change"}}
{"_local_timestamp": "2026-01-25T23:34:44.649199+00:00", "data": {"market": "0xadd7737a947ee4b404262bd268a7dad202a7b93a853e59eb29c3770bdf5a3c5e", "price_changes": [{"asset_id": "34873810304813988618460030655204351211024364269964394342687234411411922138015", "price": "0.47", "size": "0", "side": "BUY", "hash": "159b78f3f49e5d93cb8783e75596e9e39952e334", "best_bid": "0.79", "best_ask": "0.91"}, {"asset_id": "61947573105398885505676981136106310455132935973656038313589742543062489249520", "price": "0.53", "size": "0", "side": "SELL", "hash": "bbf07c8e317ee0d0eee1fb9e467d8d8bd2bea547", "best_bid": "0.09", "best_ask": "0.21"}], "timestamp": "1769384084582", "event_type": "price_change"}}
{"_local_timestamp": "2026-01-25T23:34:45.033553+00:00", "data": {"market": "0x6f14e52f6a1502a35406feea3f0e8d42502bbf1199e42c73a743fe1745ccc12c", "price_changes": [{"asset_id": "64289097521554308111154900994757912304033484898403308857843640646685729282110", "price": "0.23", "size": "0", "side": "BUY", "hash": "56ec619125211efe874c0f48b6a8bdf70161d219", "best_bid": "0.1", "best_ask": "0.43"}, {"asset_id": "17811605278785499666964340297379704435403265198212995098387642426099375215061", "price": "0.77", "size": "0", "side": "SELL", "hash": "47500356cadad8f8d8c363983a0ffd04ee3faa29", "best_bid": "0.57", "best_ask": "0.9"}], "timestamp": "1769384084959", "event_type": "price_change"}}
{"_local_timestamp": "2026-01-25T23:34:45.146267+00:00", "data": {"market": "0x6f14e52f6a1502a35406feea3f0e8d42502bbf1199e42c73a743fe1745ccc12c", "price_changes": [{"asset_id": "17811605278785499666964340297379704435403265198212995098387642426099375215061", "price": "0.16", "size": "250", "side": "BUY", "hash": "63396a701328790c378e0107b77df87b8b2870ff", "best_bid": "0.57", "best_ask": "0.9"}, {"asset_id": "64289097521554308111154900994757912304033484898403308857843640646685729282110", "price": "0.84", "size": "250", "side": "SELL", "hash": "3958b0134d855fec9c24bf43302ddefd01b363ed", "best_bid": "0.1", "best_ask": "0.43"}], "timestamp": "1769384085040", "event_type": "price_change"}}
{"_local_timestamp": "2026-01-25T23:34:45.146928+00:00", "data": {"market": "0x6f14e52f6a1502a35406feea3f0e8d42502bbf1199e42c73a743fe1745ccc12c", "price_changes": [{"asset_id": "17811605278785499666964340297379704435403265198212995098387642426099375215061", "price": "0.06", "size": "799.66", "side": "BUY", "hash": "63396a701328790c378e0107b77df87b8b2870ff", "best_bid": "0.57", "best_ask": "0.9"}, {"asset_id": "64289097521554308111154900994757912304033484898403308857843640646685729282110", "price": "0.94", "size": "799.66", "side": "SELL", "hash": "3958b0134d855fec9c24bf43302ddefd01b363ed", "best_bid": "0.1", "best_ask": "0.43"}], "timestamp": "1769384085040", "event_type": "price_change"}}
{"_local_timestamp": "2026-01-25T23:34:45.147481+00:00", "data": {"market": "0x6f14e52f6a1502a35406feea3f0e8d42502bbf1199e42c73a743fe1745ccc12c", "price_changes": [{"asset_id": "17811605278785499666964340297379704435403265198212995098387642426099375215061", "price": "0.26", "size": "0", "side": "BUY", "hash": "63396a701328790c378e0107b77df87b8b2870ff", "best_bid": "0.57", "best_ask": "0.9"}, {"asset_id": "64289097521554308111154900994757912304033484898403308857843640646685729282110", "price": "0.74", "size": "0", "side": "SELL", "hash": "3958b0134d855fec9c24bf43302ddefd01b363ed", "best_bid": "0.1", "best_ask": "0.43"}], "timestamp": "1769384085040", "event_type": "price_change"}}
{"_local_timestamp": "2026-01-25T23:34:45.148094+00:00", "data": {"market": "0x6f14e52f6a1502a35406feea3f0e8d42502bbf1199e42c73a743fe1745ccc12c", "price_changes": [{"asset_id": "17811605278785499666964340297379704435403265198212995098387642426099375215061", "price": "0.1", "size": "0", "side": "BUY", "hash": "63396a701328790c378e0107b77df87b8b2870ff", "best_bid": "0.57", "best_ask": "0.9"}, {"asset_id": "64289097521554308111154900994757912304033484898403308857843640646685729282110", "price": "0.9", "size": "0", "side": "SELL", "hash": "3958b0134d855fec9c24bf43302ddefd01b363ed", "best_bid": "0.1", "best_ask": "0.43"}], "timestamp": "1769384085040", "event_type": "price_change"}}
{"_local_timestamp": "2026-01-25T23:34:45.148615+00:00", "data": {"market": "0x6f14e52f6a1502a35406feea3f0e8d42502bbf1199e42c73a743fe1745ccc12c", "price_changes": [{"asset_id": "17811605278785499666964340297379704435403265198212995098387642426099375215061", "price": "0.13", "size": "0", "side": "BUY", "hash": "63396a701328790c378e0107b77df87b8b2870ff", "best_bid": "0.57", "best_ask": "0.9"}, {"asset_id": "64289097521554308111154900994757912304033484898403308857843640646685729282110", "price": "0.87", "size": "0", "side": "SELL", "hash": "3958b0134d855fec9c24bf43302ddefd01b363ed", "best_bid": "0.1", "best_ask": "0.43"}], "timestamp": "1769384085040", "event_type": "price_change"}}
{"_local_timestamp": "2026-01-25T23:34:45.149097+00:00", "data": {"market": "0x6f14e52f6a1502a35406feea3f0e8d42502bbf1199e42c73a743fe1745ccc12c", "price_changes": [{"asset_id": "17811605278785499666964340297379704435403265198212995098387642426099375215061", "price": "0.22", "size": "0", "side": "BUY", "hash": "63396a701328790c378e0107b77df87b8b2870ff", "best_bid": "0.57", "best_ask": "0.9"}, {"asset_id": "64289097521554308111154900994757912304033484898403308857843640646685729282110", "price": "0.78", "size": "0", "side": "SELL", "hash": "3958b0134d855fec9c24bf43302ddefd01b363ed", "best_bid": "0.1", "best_ask": "0.43"}], "timestamp": "1769384085040", "event_type": "price_change"}}
{"_local_timestamp": "2026-01-25T23:34:45.156014+00:00", "data": {"market": "0x6f14e52f6a1502a35406feea3f0e8d42502bbf1199e42c73a743fe1745ccc12c", "price_changes": [{"asset_id": "17811605278785499666964340297379704435403265198212995098387642426099375215061", "price": "0.19", "size": "0", "side": "BUY", "hash": "63396a701328790c378e0107b77df87b8b2870ff", "best_bid": "0.57", "best_ask": "0.9"}, {"asset_id": "64289097521554308111154900994757912304033484898403308857843640646685729282110", "price": "0.81", "size": "0", "side": "SELL", "hash": "3958b0134d855fec9c24bf43302ddefd01b363ed", "best_bid": "0.1", "best_ask": "0.43"}], "timestamp": "1769384085040", "event_type": "price_change"}}
{"_local_timestamp": "2026-01-25T23:34:50.076729+00:00", "data": {"market": "0x90a6d406570f273840bd2e39e25dbd0a91655cd347dbb2bc381863743044bf32", "price_changes": [{"asset_id": "36331391317493054259843206160279589805054745072393638988521393636953188108839", "price": "0.04", "size": "250", "side": "BUY", "hash": "0bbb10fe64faf6d383c2fdd2c2b15f7f5886dbcc", "best_bid": "0.24", "best_ask": "0.78"}, {"asset_id": "92143930323152159931232014367424593746113767612080401756819785961080544448740", "price": "0.96", "size": "250", "side": "SELL", "hash": "5b36d980164e6b441bc862da9fff4c08848227bd", "best_bid": "0.22", "best_ask": "0.76"}], "timestamp": "1769384089934", "event_type": "price_change"}}
{"_local_timestamp": "2026-01-25T23:34:50.391319+00:00", "data": {"market": "0x90a6d406570f273840bd2e39e25dbd0a91655cd347dbb2bc381863743044bf32", "price_changes": [{"asset_id": "36331391317493054259843206160279589805054745072393638988521393636953188108839", "price": "0.02", "size": "350", "side": "BUY", "hash": "84ec38cc44a1fdf74717454709f6d0dd733b54ce", "best_bid": "0.24", "best_ask": "0.78"}, {"asset_id": "92143930323152159931232014367424593746113767612080401756819785961080544448740", "price": "0.98", "size": "350", "side": "SELL", "hash": "89033c0d24d2f784d368baa132db19f7967a057f", "best_bid": "0.22", "best_ask": "0.76"}], "timestamp": "1769384090252", "event_type": "price_change"}}
{"_local_timestamp": "2026-01-25T23:34:53.030946+00:00", "data": {"market": "0x6f14e52f6a1502a35406feea3f0e8d42502bbf1199e42c73a743fe1745ccc12c", "price_changes": [{"asset_id": "64289097521554308111154900994757912304033484898403308857843640646685729282110", "price": "0.25", "size": "50", "side": "BUY", "hash": "09d0eb4a947243e7a2fbf2962d756ca6f0da5ec1", "best_bid": "0.25", "best_ask": "0.43"}, {"asset_id": "17811605278785499666964340297379704435403265198212995098387642426099375215061", "price": "0.75", "size": "50", "side": "SELL", "hash": "dca08ce66dd27e5efbff2818f2467e55cfcffd1c", "best_bid": "0.57", "best_ask": "0.75"}], "timestamp": "1769384092872", "event_type": "price_change"}}
{"_local_timestamp": "2026-01-25T23:34:53.116978+00:00", "data": {"market": "0x6f14e52f6a1502a35406feea3f0e8d42502bbf1199e42c73a743fe1745ccc12c", "price_changes": [{"asset_id": "17811605278785499666964340297379704435403265198212995098387642426099375215061", "price": "0.25", "size": "80", "side": "BUY", "hash": "1eb56ddb5941d497e14e03e6d86db87196fb5234", "best_bid": "0.57", "best_ask": "0.75"}, {"asset_id": "64289097521554308111154900994757912304033484898403308857843640646685729282110", "price": "0.75", "size": "80", "side": "SELL", "hash": "05b3ef45f99edd0e4a144ce5259a705e8ca34ec9", "best_bid": "0.25", "best_ask": "0.43"}], "timestamp": "1769384092965", "event_type": "price_change"}}
{"_local_timestamp": "2026-01-25T23:34:53.217293+00:00", "data": {"market": "0x6f14e52f6a1502a35406feea3f0e8d42502bbf1199e42c73a743fe1745ccc12c", "price_changes": [{"asset_id": "17811605278785499666964340297379704435403265198212995098387642426099375215061", "price": "0.22", "size": "109.09", "side": "BUY", "hash": "0be01de9343f9dc480ab6ef46d9852bf51058e9c", "best_bid": "0.57", "best_ask": "0.75"}, {"asset_id": "64289097521554308111154900994757912304033484898403308857843640646685729282110", "price": "0.78", "size": "109.09", "side": "SELL", "hash": "de00f298c7466dcaebbf0e967e8a8fdc0e81b914", "best_bid": "0.25", "best_ask": "0.43"}], "timestamp": "1769384093020", "event_type": "price_change"}}
{"_local_timestamp": "2026-01-25T23:34:53.229084+00:00", "data": {"market": "0x6f14e52f6a1502a35406feea3f0e8d42502bbf1199e42c73a743fe1745ccc12c", "price_changes": [{"asset_id": "17811605278785499666964340297379704435403265198212995098387642426099375215061", "price": "0.19", "size": "136.84", "side": "BUY", "hash": "f29d632a2084665cd05761bc37f1b047e69878b7", "best_bid": "0.57", "best_ask": "0.75"}, {"asset_id": "64289097521554308111154900994757912304033484898403308857843640646685729282110", "price": "0.81", "size": "136.84", "side": "SELL", "hash": "d2e50d06f20783d053ae1f4a899fa4f5eab95f14", "best_bid": "0.25", "best_ask": "0.43"}], "timestamp": "1769384093073", "event_type": "price_change"}}
{"_local_timestamp": "2026-01-25T23:34:53.276761+00:00", "data": {"market": "0x6f14e52f6a1502a35406feea3f0e8d42502bbf1199e42c73a743fe1745ccc12c", "price_changes": [{"asset_id": "17811605278785499666964340297379704435403265198212995098387642426099375215061", "price": "0.16", "size": "425", "side": "BUY", "hash": "08f8c5302002cb1436c9a05cdc78e15100a55f11", "best_bid": "0.57", "best_ask": "0.75"}, {"asset_id": "64289097521554308111154900994757912304033484898403308857843640646685729282110", "price": "0.84", "size": "425", "side": "SELL", "hash": "1ca20ddb74ad8a91823d658f52799bf926b16f08", "best_bid": "0.25", "best_ask": "0.43"}], "timestamp": "1769384093125", "event_type": "price_change"}}
{"_local_timestamp": "2026-01-25T23:34:53.324585+00:00", "data": {"market": "0x6f14e52f6a1502a35406feea3f0e8d42502bbf1199e42c73a743fe1745ccc12c", "price_changes": [{"asset_id": "17811605278785499666964340297379704435403265198212995098387642426099375215061", "price": "0.13", "size": "246.15", "side": "BUY", "hash": "5ce30970cf40a59564702e7ba93805178aa76ea1", "best_bid": "0.57", "best_ask": "0.75"}, {"asset_id": "64289097521554308111154900994757912304033484898403308857843640646685729282110", "price": "0.87", "size": "246.15", "side": "SELL", "hash": "ce832e59119814a2fbe3d4aefbc28f689a66f1b7", "best_bid": "0.25", "best_ask": "0.43"}], "timestamp": "1769384093177", "event_type": "price_change"}}
{"_local_timestamp": "2026-01-25T23:34:53.376419+00:00", "data": {"market": "0x6f14e52f6a1502a35406feea3f0e8d42502bbf1199e42c73a743fe1745ccc12c", "price_changes": [{"asset_id": "17811605278785499666964340297379704435403265198212995098387642426099375215061", "price": "0.1", "size": "340", "side": "BUY", "hash": "14ecc790e2b79162957fc2420864c20eb70c3aa3", "best_bid": "0.57", "best_ask": "0.75"}, {"asset_id": "64289097521554308111154900994757912304033484898403308857843640646685729282110", "price": "0.9", "size": "340", "side": "SELL", "hash": "bfe2ae7e46836f3bb53ff03a6c3b88f7aed09f97", "best_bid": "0.25", "best_ask": "0.43"}], "timestamp": "1769384093230", "event_type": "price_change"}}
{"_local_timestamp": "2026-01-25T23:34:53.428750+00:00", "data": {"market": "0x6f14e52f6a1502a35406feea3f0e8d42502bbf1199e42c73a743fe1745ccc12c", "price_changes": [{"asset_id": "17811605278785499666964340297379704435403265198212995098387642426099375215061", "price": "0.06", "size": "1399.66", "side": "BUY", "hash": "68e409276fb0b2627ab1e16a4f6ce12ac241653c", "best_bid": "0.57", "best_ask": "0.75"}, {"asset_id": "64289097521554308111154900994757912304033484898403308857843640646685729282110", "price": "0.94", "size": "1399.66", "side": "SELL", "hash": "3487d10a9738af6e62d9e5b78daf6c68682d2c25", "best_bid": "0.25", "best_ask": "0.43"}], "timestamp": "1769384093282", "event_type": "price_change"}}
{"_local_timestamp": "2026-01-25T23:34:54.623070+00:00", "data": {"market": "0xe16bfa632e3cde9d098182de828e7245e0cf4f8750c84abd3baac6991eec0726", "price_changes": [{"asset_id": "109381568779384865822632347902276013195234118338727432096785122435925016975410", "price": "0.698", "size": "100", "side": "SELL", "hash": "c073185729404a34b335134065452c3612b9383e", "best_bid": "0.013", "best_ask": "0.017"}, {"asset_id": "100749488309973909349839325632625226928519343319252966251802066191844854675345", "price": "0.302", "size": "100", "side": "BUY", "hash": "43ad0b0537a1f8994d1ab03a714ac9ece807686a", "best_bid": "0.983", "best_ask": "0.987"}], "timestamp": "1769384094546", "event_type": "price_change"}}
{"_local_timestamp": "2026-01-25T23:34:54.962381+00:00", "data": {"market": "0xe16bfa632e3cde9d098182de828e7245e0cf4f8750c84abd3baac6991eec0726", "price_changes": [{"asset_id": "109381568779384865822632347902276013195234118338727432096785122435925016975410", "price": "0.789", "size": "200", "side": "SELL", "hash": "7b1c0e06bd67468aa6c628e8a8070e6922a351c6", "best_bid": "0.013", "best_ask": "0.017"}, {"asset_id": "100749488309973909349839325632625226928519343319252966251802066191844854675345", "price": "0.211", "size": "200", "side": "BUY", "hash": "00f56951c9856c9ce68276204fc7886e050e0789", "best_bid": "0.983", "best_ask": "0.987"}], "timestamp": "1769384094884", "event_type": "price_change"}}
{"_local_timestamp": "2026-01-25T23:34:54.970635+00:00", "data": {"market": "0x5b17571f0687e9ef62aead3a3e57bfc617f16e4806865d8b7cc609a680ac9892", "price_changes": [{"asset_id": "30934121158421236234732376879006750136278688549793740923122711845308054079491", "price": "0.04", "size": "100", "side": "BUY", "hash": "be5077c5f95312ca3c270640d16c105bab4c302f", "best_bid": "0.04", "best_ask": "0.33"}, {"asset_id": "54672482098306675309495708206879727568512955356356264682879888123590518385092", "price": "0.96", "size": "100", "side": "SELL", "hash": "36b94d21721a754f445e8085c6d840ab2a7447c4", "best_bid": "0.67", "best_ask": "0.96"}], "timestamp": "1769384094881", "event_type": "price_change"}}
{"_local_timestamp": "2026-01-25T23:34:59.656354+00:00", "data": {"market": "0x5b17571f0687e9ef62aead3a3e57bfc617f16e4806865d8b7cc609a680ac9892", "price_changes": [{"asset_id": "54672482098306675309495708206879727568512955356356264682879888123590518385092", "price": "0.67", "size": "64.17", "side": "BUY", "hash": "10d3e0a2bdf3724ada192723873752bf3eed7a6a", "best_bid": "0.67", "best_ask": "0.96"}, {"asset_id": "30934121158421236234732376879006750136278688549793740923122711845308054079491", "price": "0.33", "size": "64.17", "side": "SELL", "hash": "08c0816e016530a50d8337db3cebc326116e8b9e", "best_bid": "0.04", "best_ask": "0.33"}], "timestamp": "1769384099587", "event_type": "price_change"}}
{"_local_timestamp": "2026-01-25T23:34:59.658218+00:00", "data": {"market": "0x679bcdd7ed5e81e87f560a516b2ff3b419be87aeb995550b728c75a222bbfd14", "price_changes": [{"asset_id": "20310121731492329356556661175693279243075784612953975064227117258195086943533", "price": "0.62", "size": "111.29", "side": "BUY", "hash": "17647738a9c47bd72e4d5c0ba751e3af96a1926b", "best_bid": "0.62", "best_ask": "0.92"}, {"asset_id": "2072906368234015194389249304629942211650401137671103595040092908842803594601", "price": "0.38", "size": "111.29", "side": "SELL", "hash": "93ef91ee335a7bc02891ed6c73d8bd660d936e36", "best_bid": "0.08", "best_ask": "0.38"}], "timestamp": "1769384099587", "event_type": "price_change"}}
{"_local_timestamp": "2026-01-25T23:35:00.690517+00:00", "data": {"market": "0x6f14e52f6a1502a35406feea3f0e8d42502bbf1199e42c73a743fe1745ccc12c", "price_changes": [{"asset_id": "17811605278785499666964340297379704435403265198212995098387642426099375215061", "price": "0.56", "size": "134.51", "side": "BUY", "hash": "46facc4c7f1e43ee567fba351c91287990af1415", "best_bid": "0.57", "best_ask": "0.75"}, {"asset_id": "64289097521554308111154900994757912304033484898403308857843640646685729282110", "price": "0.44", "size": "134.51", "side": "SELL", "hash": "6f37b55eb17c9ce729286f6b34ad4979391c4935", "best_bid": "0.25", "best_ask": "0.43"}], "timestamp": "1769384100615", "event_type": "price_change"}}
{"_local_timestamp": "2026-01-25T23:35:09.393761+00:00", "data": {"market": "0x70d9be5faefbfdef38512a6d9e4392db3084d813ea56f989bd23400fda437b5d", "price_changes": [{"asset_id": "98030581449575327310479171744260311446081913603336917524388058189639018780846", "price": "0.71", "size": "50", "side": "BUY", "hash": "7457ae4725cb1f925140bbc04832845fefb77674", "best_bid": "0.71", "best_ask": "0.87"}, {"asset_id": "21591156070974184450803575087108412438346440628447753978089378794451962462635", "price": "0.29", "size": "50", "side": "SELL", "hash": "c04edfafcbd6ae2274755c807064e47c2d795c93", "best_bid": "0.13", "best_ask": "0.29"}], "timestamp": "1769384109331", "event_type": "price_change"}}
{"_local_timestamp": "2026-01-25T23:35:09.407006+00:00", "data": {"market": "0x70d9be5faefbfdef38512a6d9e4392db3084d813ea56f989bd23400fda437b5d", "price_changes": [{"asset_id": "21591156070974184450803575087108412438346440628447753978089378794451962462635", "price": "0.11", "size": "59.09", "side": "BUY", "hash": "ac8bb94f8ca7e52e26527be35f5725cd3b8e3409", "best_bid": "0.13", "best_ask": "0.29"}, {"asset_id": "98030581449575327310479171744260311446081913603336917524388058189639018780846", "price": "0.89", "size": "59.09", "side": "SELL", "hash": "94b01a9c6aa715ecaa48395ed36a6c8010444b55", "best_bid": "0.71", "best_ask": "0.87"}], "timestamp": "1769384109332", "event_type": "price_change"}}
{"_local_timestamp": "2026-01-25T23:35:19.841630+00:00", "data": {"market": "0xeafa01c5d48d6b7826e91f7b31e4a61a05b3fc8a1ad8ccdb2ccbad91b616ae40", "price_changes": [{"asset_id": "83862627090039829837897753251638021110482606851285352212547333342638917195954", "price": "0.61", "size": "62.29", "side": "BUY", "hash": "9b4a37a34e2909d2de1d6df083cab6d020b7a5d1", "best_bid": "0.71", "best_ask": "0.88"}, {"asset_id": "97279369561823536114577996580038127500018967849090745350406495876539022297477", "price": "0.39", "size": "62.29", "side": "SELL", "hash": "2e16a468821721cd06dff39dc55e63f30a6d6b4e", "best_bid": "0.12", "best_ask": "0.29"}], "timestamp": "1769384119779", "event_type": "price_change"}}
{"_local_timestamp": "2026-01-25T23:35:26.663212+00:00", "data": {"market": "0x5b17571f0687e9ef62aead3a3e57bfc617f16e4806865d8b7cc609a680ac9892", "price_changes": [{"asset_id": "54672482098306675309495708206879727568512955356356264682879888123590518385092", "price": "0.17", "size": "0", "side": "BUY", "hash": "c049d53b9ba6e2aac0bbb3c4cd73243b04347877", "best_bid": "0.67", "best_ask": "0.96"}, {"asset_id": "30934121158421236234732376879006750136278688549793740923122711845308054079491", "price": "0.83", "size": "0", "side": "SELL", "hash": "2cb14d29b4a5186fb44f7262bb3abfaa6555f50e", "best_bid": "0.04", "best_ask": "0.33"}], "timestamp": "1769384126563", "event_type": "price_change"}}
{"_local_timestamp": "2026-01-25T23:35:26.663973+00:00", "data": {"market": "0x335a07913dc4afbc345e5a87410ed1cde3c0b168df2627733d49b081526fd002", "price_changes": [{"asset_id": "87400156771035739647299903622267629973291296986678621415627996460491040207279", "price": "0.15", "size": "426.66", "side": "BUY", "hash": "c1d53a9df7636fa8148d60809ab1a583392fe704", "best_bid": "0.958", "best_ask": "0.994"}, {"asset_id": "62781326014506627625925193711099656595304017608816070575558990777003703808712", "price": "0.85", "size": "426.66", "side": "SELL", "hash": "c680763aec552f40b7f4e5ae1455529b47422822", "best_bid": "0.006", "best_ask": "0.042"}], "timestamp": "1769384126563", "event_type": "price_change"}}
{"_local_timestamp": "2026-01-25T23:35:26.665840+00:00", "data": {"market": "0x6f14e52f6a1502a35406feea3f0e8d42502bbf1199e42c73a743fe1745ccc12c", "price_changes": [{"asset_id": "17811605278785499666964340297379704435403265198212995098387642426099375215061", "price": "0.11", "size": "235", "side": "BUY", "hash": "2443f33d3375fafe358096397f1f805a7797cfdc", "best_bid": "0.57", "best_ask": "0.75"}, {"asset_id": "64289097521554308111154900994757912304033484898403308857843640646685729282110", "price": "0.89", "size": "235", "side": "SELL", "hash": "775dc6d3902078c2a4211476982650427b842022", "best_bid": "0.25", "best_ask": "0.43"}], "timestamp": "1769384126563", "event_type": "price_change"}}
{"_local_timestamp": "2026-01-25T23:35:27.041229+00:00", "data": {"market": "0x6f14e52f6a1502a35406feea3f0e8d42502bbf1199e42c73a743fe1745ccc12c", "price_changes": [{"asset_id": "17811605278785499666964340297379704435403265198212995098387642426099375215061", "price": "0.13", "size": "371.15", "side": "BUY", "hash": "8602cedd9c4a099357406f99e82e557167cfddf3", "best_bid": "0.57", "best_ask": "0.75"}, {"asset_id": "64289097521554308111154900994757912304033484898403308857843640646685729282110", "price": "0.87", "size": "371.15", "side": "SELL", "hash": "453e9eef87fa3b95ada912b2e094ac5c14c6d1d9", "best_bid": "0.25", "best_ask": "0.43"}], "timestamp": "1769384126875", "event_type": "price_change"}}
{"_local_timestamp": "2026-01-25T23:35:27.041983+00:00", "data": {"market": "0x5b17571f0687e9ef62aead3a3e57bfc617f16e4806865d8b7cc609a680ac9892", "price_changes": [{"asset_id": "54672482098306675309495708206879727568512955356356264682879888123590518385092", "price": "0.16", "size": "250", "side": "BUY", "hash": "56408eecf791a06cd153ff8a5c9b4b47c5b0b6fc", "best_bid": "0.67", "best_ask": "0.96"}, {"asset_id": "30934121158421236234732376879006750136278688549793740923122711845308054079491", "price": "0.84", "size": "250", "side": "SELL", "hash": "1fbcd9978e7e0120976c2179349ede142e85a19d", "best_bid": "0.04", "best_ask": "0.33"}], "timestamp": "1769384126875", "event_type": "price_change"}}
{"_local_timestamp": "2026-01-25T23:35:27.058725+00:00", "data": {"market": "0x1cc14846bee31efbd7c2016ca1c17664684ead0c7f3b8bd91876033a546128d8", "price_changes": [{"asset_id": "60596582874731501900696294615290867175277482143370610111416633979822519113254", "price": "0.2", "size": "253.33", "side": "BUY", "hash": "e5de7aa0eca844ce55d80e42982d46818303b2ce", "best_bid": "0.52", "best_ask": "0.68"}, {"asset_id": "32668102469816119620746811427740823831434256980467530534403997191651163337906", "price": "0.8", "size": "253.33", "side": "SELL", "hash": "b2fd6a48b465d7ad7e32e8707b2f54cb70768d54", "best_bid": "0.32", "best_ask": "0.48"}], "timestamp": "1769384126875", "event_type": "price_change"}}
{"_local_timestamp": "2026-01-25T23:35:27.059761+00:00", "data": {"market": "0xf916b98c173470389af02fa32236bea1333cf05199ee997bc64a39ad6bd589ee", "price_changes": [{"asset_id": "41743802686443315505082888602082131066672260628700340336384534887243556020231", "price": "0.16", "size": "100", "side": "BUY", "hash": "ae309b5815802aedcf6904cf2565891a2f4ed98d", "best_bid": "0.77", "best_ask": "0.91"}, {"asset_id": "91462927649974781483669557862921344444854660701074121664666696309988647910790", "price": "0.84", "size": "100", "side": "SELL", "hash": "24569b5b28733f29d82d6de580ced15a4a271d25", "best_bid": "0.09", "best_ask": "0.23"}], "timestamp": "1769384126885", "event_type": "price_change"}}
{"_local_timestamp": "2026-01-25T23:35:27.060402+00:00", "data": {"market": "0x1cc14846bee31efbd7c2016ca1c17664684ead0c7f3b8bd91876033a546128d8", "price_changes": [{"asset_id": "60596582874731501900696294615290867175277482143370610111416633979822519113254", "price": "0.12", "size": "391.66", "side": "BUY", "hash": "a646a97e9ef870141b3ce503a87c2376a5bc3593", "best_bid": "0.52", "best_ask": "0.68"}, {"asset_id": "32668102469816119620746811427740823831434256980467530534403997191651163337906", "price": "0.88", "size": "391.66", "side": "SELL", "hash": "bc820415df8fe7cb2ee8ee70e02fc8adde85e4cb", "best_bid": "0.32", "best_ask": "0.48"}], "timestamp": "1769384126915", "event_type": "price_change"}}
{"_local_timestamp": "2026-01-25T23:35:27.147898+00:00", "data": {"market": "0x6f14e52f6a1502a35406feea3f0e8d42502bbf1199e42c73a743fe1745ccc12c", "price_changes": [{"asset_id": "17811605278785499666964340297379704435403265198212995098387642426099375215061", "price": "0.22", "size": "159.09", "side": "BUY", "hash": "51633fb8fc509917963500baf57812d66972fe8b", "best_bid": "0.57", "best_ask": "0.75"}, {"asset_id": "64289097521554308111154900994757912304033484898403308857843640646685729282110", "price": "0.78", "size": "159.09", "side": "SELL", "hash": "4ef1d39943f767ecc9b0644a6565410ffce4953f", "best_bid": "0.25", "best_ask": "0.43"}], "timestamp": "1769384126913", "event_type": "price_change"}}
{"_local_timestamp": "2026-01-25T23:35:34.248406+00:00", "data": {"market": "0x21fcddff254ff0337ac03ec276927cc90e5228ac1c5b16c36300589318197fc4", "price_changes": [{"asset_id": "108893558475396584780619998257373148912765768914968487436636153030532224366680", "price": "0.63", "size": "50", "side": "BUY", "hash": "86c17cb2356cf87b7bcc2e5bb2e20eb9b9e189bc", "best_bid": "0.64", "best_ask": "0.94"}, {"asset_id": "41605452123604733553647691830638760854992806694633100987207040539420095696757", "price": "0.37", "size": "50", "side": "SELL", "hash": "bd36aca73b438fd4789dacb356f1f311001ce936", "best_bid": "0.06", "best_ask": "0.36"}], "timestamp": "1769384134172", "event_type": "price_change"}}
{"_local_timestamp": "2026-01-25T23:35:34.249623+00:00", "data": {"market": "0x21fcddff254ff0337ac03ec276927cc90e5228ac1c5b16c36300589318197fc4", "price_changes": [{"asset_id": "108893558475396584780619998257373148912765768914968487436636153030532224366680", "price": "0.32", "size": "0", "side": "BUY", "hash": "86c17cb2356cf87b7bcc2e5bb2e20eb9b9e189bc", "best_bid": "0.64", "best_ask": "0.94"}, {"asset_id": "41605452123604733553647691830638760854992806694633100987207040539420095696757", "price": "0.68", "size": "0", "side": "SELL", "hash": "bd36aca73b438fd4789dacb356f1f311001ce936", "best_bid": "0.06", "best_ask": "0.36"}], "timestamp": "1769384134172", "event_type": "price_change"}}
{"_local_timestamp": "2026-01-25T23:35:34.250428+00:00", "data": {"market": "0x21fcddff254ff0337ac03ec276927cc90e5228ac1c5b16c36300589318197fc4", "price_changes": [{"asset_id": "108893558475396584780619998257373148912765768914968487436636153030532224366680", "price": "0.01", "size": "3612.03", "side": "BUY", "hash": "86c17cb2356cf87b7bcc2e5bb2e20eb9b9e189bc", "best_bid": "0.64", "best_ask": "0.94"}, {"asset_id": "41605452123604733553647691830638760854992806694633100987207040539420095696757", "price": "0.99", "size": "3612.03", "side": "SELL", "hash": "bd36aca73b438fd4789dacb356f1f311001ce936", "best_bid": "0.06", "best_ask": "0.36"}], "timestamp": "1769384134172", "event_type": "price_change"}}
{"_local_timestamp": "2026-01-25T23:35:35.333453+00:00", "data": {"market": "0x21fcddff254ff0337ac03ec276927cc90e5228ac1c5b16c36300589318197fc4", "price_changes": [{"asset_id": "108893558475396584780619998257373148912765768914968487436636153030532224366680", "price": "0.01", "size": "3712.03", "side": "BUY", "hash": "25572faf16d28582474b70c36a56c7494c5e3d4a", "best_bid": "0.64", "best_ask": "0.94"}, {"asset_id": "41605452123604733553647691830638760854992806694633100987207040539420095696757", "price": "0.99", "size": "3712.03", "side": "SELL", "hash": "4c415dbdc1fd923193184f58c8ed0bd2d8368ddf", "best_bid": "0.06", "best_ask": "0.36"}], "timestamp": "1769384135263", "event_type": "price_change"}}
{"_local_timestamp": "2026-01-25T23:35:35.347705+00:00", "data": {"market": "0x21fcddff254ff0337ac03ec276927cc90e5228ac1c5b16c36300589318197fc4", "price_changes": [{"asset_id": "108893558475396584780619998257373148912765768914968487436636153030532224366680", "price": "0.33", "size": "106", "side": "BUY", "hash": "2f2a54dfefe822f5c0af5f7a811dcff9dd4fbdb3", "best_bid": "0.64", "best_ask": "0.94"}, {"asset_id": "41605452123604733553647691830638760854992806694633100987207040539420095696757", "price": "0.67", "size": "106", "side": "SELL", "hash": "f5b68cbf9cd34e0ce0e8f3bfe4e22a532af8ec70", "best_bid": "0.06", "best_ask": "0.36"}], "timestamp": "1769384135277", "event_type": "price_change"}}
{"_local_timestamp": "2026-01-25T23:35:35.476441+00:00", "data": {"market": "0x90a6d406570f273840bd2e39e25dbd0a91655cd347dbb2bc381863743044bf32", "price_changes": [{"asset_id": "36331391317493054259843206160279589805054745072393638988521393636953188108839", "price": "0.17", "size": "0", "side": "BUY", "hash": "df7b85ce46dd9ce9823be017e09d94c931f59115", "best_bid": "0.24", "best_ask": "0.78"}, {"asset_id": "92143930323152159931232014367424593746113767612080401756819785961080544448740", "price": "0.83", "size": "0", "side": "SELL", "hash": "1aea96ef9e4ced0dd47eac7eff3aa81ddcb20f67", "best_bid": "0.22", "best_ask": "0.76"}], "timestamp": "1769384135398", "event_type": "price_change"}}
{"_local_timestamp": "2026-01-25T23:35:35.477205+00:00", "data": {"market": "0xa96f3bae6635e8f42628c39ce7b61fd566b9253d4f2699c3cac08be6d17ca723", "price_changes": [{"asset_id": "31555074014428326614377030963919393145120116674000147512977361328627463258713", "price": "0.05", "size": "227", "side": "BUY", "hash": "70be010f61db3651ad565f6b56ac0da0b5a59a40", "best_bid": "0.07", "best_ask": "0.18"}, {"asset_id": "49976858258828287893504382876186665182729041451625761701208418053508589757916", "price": "0.95", "size": "227", "side": "SELL", "hash": "d190a20b26725b292e1f5504398cd21cea2b069a", "best_bid": "0.82", "best_ask": "0.93"}], "timestamp": "1769384135399", "event_type": "price_change"}}
{"_local_timestamp": "2026-01-25T23:35:35.477910+00:00", "data": {"market": "0xeafa01c5d48d6b7826e91f7b31e4a61a05b3fc8a1ad8ccdb2ccbad91b616ae40", "price_changes": [{"asset_id": "83862627090039829837897753251638021110482606851285352212547333342638917195954", "price": "0.36", "size": "0", "side": "BUY", "hash": "9e31f1f75d1a5f7e6ce4c0cae8cea02f941d17da", "best_bid": "0.71", "best_ask": "0.88"}, {"asset_id": "97279369561823536114577996580038127500018967849090745350406495876539022297477", "price": "0.64", "size": "0", "side": "SELL", "hash": "1a2d69fc7e1ebe20e79cf9edfad8c247feb1b6b6", "best_bid": "0.12", "best_ask": "0.29"}], "timestamp": "1769384135399", "event_type": "price_change"}}
{"_local_timestamp": "2026-01-25T23:35:35.478542+00:00", "data": {"market": "0xeafa01c5d48d6b7826e91f7b31e4a61a05b3fc8a1ad8ccdb2ccbad91b616ae40", "price_changes": [{"asset_id": "83862627090039829837897753251638021110482606851285352212547333342638917195954", "price": "0.01", "size": "2805.1", "side": "BUY", "hash": "9e31f1f75d1a5f7e6ce4c0cae8cea02f941d17da", "best_bid": "0.71", "best_ask": "0.88"}, {"asset_id": "97279369561823536114577996580038127500018967849090745350406495876539022297477", "price": "0.99", "size": "2805.1", "side": "SELL", "hash": "1a2d69fc7e1ebe20e79cf9edfad8c247feb1b6b6", "best_bid": "0.12", "best_ask": "0.29"}], "timestamp": "1769384135399", "event_type": "price_change"}}
{"_local_timestamp": "2026-01-25T23:35:35.479167+00:00", "data": {"market": "0x679bcdd7ed5e81e87f560a516b2ff3b419be87aeb995550b728c75a222bbfd14", "price_changes": [{"asset_id": "20310121731492329356556661175693279243075784612953975064227117258195086943533", "price": "0.17", "size": "75", "side": "BUY", "hash": "54fbd28a463bcfdb788f862abb1490d6daeee6bf", "best_bid": "0.62", "best_ask": "0.92"}, {"asset_id": "2072906368234015194389249304629942211650401137671103595040092908842803594601", "price": "0.83", "size": "75", "side": "SELL", "hash": "873ed7bc965da4ec3a06437feb334e62f733d204", "best_bid": "0.08", "best_ask": "0.38"}], "timestamp": "1769384135399", "event_type": "price_change"}}
{"_local_timestamp": "2026-01-25T23:35:35.479739+00:00", "data": {"market": "0x5b17571f0687e9ef62aead3a3e57bfc617f16e4806865d8b7cc609a680ac9892", "price_changes": [{"asset_id": "54672482098306675309495708206879727568512955356356264682879888123590518385092", "price": "0.15", "size": "62", "side": "BUY", "hash": "e6fb957886035f02015a8e4e4a0b80b6d7341f27", "best_bid": "0.67", "best_ask": "0.96"}, {"asset_id": "30934121158421236234732376879006750136278688549793740923122711845308054079491", "price": "0.85", "size": "62", "side": "SELL", "hash": "6417351c7e8c079805fc199474629db472f6c4d1", "best_bid": "0.04", "best_ask": "0.33"}], "timestamp": "1769384135399", "event_type": "price_change"}}
{"_local_timestamp": "2026-01-25T23:35:35.480453+00:00", "data": {"market": "0x679bcdd7ed5e81e87f560a516b2ff3b419be87aeb995550b728c75a222bbfd14", "price_changes": [{"asset_id": "20310121731492329356556661175693279243075784612953975064227117258195086943533", "price": "0.01", "size": "2356.37", "side": "BUY", "hash": "54fbd28a463bcfdb788f862abb1490d6daeee6bf", "best_bid": "0.62", "best_ask": "0.92"}, {"asset_id": "2072906368234015194389249304629942211650401137671103595040092908842803594601", "price": "0.99", "size": "2356.37", "side": "SELL", "hash": "873ed7bc965da4ec3a06437feb334e62f733d204", "best_bid": "0.08", "best_ask": "0.38"}], "timestamp": "1769384135399", "event_type": "price_change"}}
{"_local_timestamp": "2026-01-25T23:35:35.481096+00:00", "data": {"market": "0x1cc14846bee31efbd7c2016ca1c17664684ead0c7f3b8bd91876033a546128d8", "price_changes": [{"asset_id": "32668102469816119620746811427740823831434256980467530534403997191651163337906", "price": "0.2", "size": "0", "side": "BUY", "hash": "7e8d42048fabc7c12f453cdba60a926f28d99918", "best_bid": "0.32", "best_ask": "0.48"}, {"asset_id": "60596582874731501900696294615290867175277482143370610111416633979822519113254", "price": "0.8", "size": "0", "side": "SELL", "hash": "38189c8b21f8b47d776ac95a44451691222b7508", "best_bid": "0.52", "best_ask": "0.68"}], "timestamp": "1769384135399", "event_type": "price_change"}}
{"_local_timestamp": "2026-01-25T23:35:35.481697+00:00", "data": {"market": "0x5b17571f0687e9ef62aead3a3e57bfc617f16e4806865d8b7cc609a680ac9892", "price_changes": [{"asset_id": "54672482098306675309495708206879727568512955356356264682879888123590518385092", "price": "0.41", "size": "26.82", "side": "BUY", "hash": "e6fb957886035f02015a8e4e4a0b80b6d7341f27", "best_bid": "0.67", "best_ask": "0.96"}, {"asset_id": "30934121158421236234732376879006750136278688549793740923122711845308054079491", "price": "0.59", "size": "26.82", "side": "SELL", "hash": "6417351c7e8c079805fc199474629db472f6c4d1", "best_bid": "0.04", "best_ask": "0.33"}], "timestamp": "1769384135399", "event_type": "price_change"}}
{"_local_timestamp": "2026-01-25T23:35:35.482318+00:00", "data": {"market": "0x679bcdd7ed5e81e87f560a516b2ff3b419be87aeb995550b728c75a222bbfd14", "price_changes": [{"asset_id": "20310121731492329356556661175693279243075784612953975064227117258195086943533", "price": "0.34", "size": "0", "side": "BUY", "hash": "54fbd28a463bcfdb788f862abb1490d6daeee6bf", "best_bid": "0.62", "best_ask": "0.92"}, {"asset_id": "2072906368234015194389249304629942211650401137671103595040092908842803594601", "price": "0.66", "size": "0", "side": "SELL", "hash": "873ed7bc965da4ec3a06437feb334e62f733d204", "best_bid": "0.08", "best_ask": "0.38"}], "timestamp": "1769384135399", "event_type": "price_change"}}
{"_local_timestamp": "2026-01-25T23:35:35.600968+00:00", "data": {"market": "0xbf7f7047fa5719e010b9c35abab4d1510f80d78998ede7928dee762b842fd8fa", "price_changes": [{"asset_id": "99317080920004040908110146285425334348796704558628502185978368700992863001849", "price": "0.31", "size": "0", "side": "BUY", "hash": "f071e859521aa6700f36490d24e3863a90c27d10", "best_bid": "0.61", "best_ask": "0.99"}, {"asset_id": "80475936180674486630534655774036670401396382603097237786734519090691938222605", "price": "0.69", "size": "0", "side": "SELL", "hash": "1670feb45d823191caa906e66ea38d98553b4ddf", "best_bid": "0.01", "best_ask": "0.39"}], "timestamp": "1769384135399", "event_type": "price_change"}}
{"_local_timestamp": "2026-01-25T23:35:35.601749+00:00", "data": {"market": "0x1cc14846bee31efbd7c2016ca1c17664684ead0c7f3b8bd91876033a546128d8", "price_changes": [{"asset_id": "32668102469816119620746811427740823831434256980467530534403997191651163337906", "price": "0.15", "size": "66.66", "side": "BUY", "hash": "7e8d42048fabc7c12f453cdba60a926f28d99918", "best_bid": "0.32", "best_ask": "0.48"}, {"asset_id": "60596582874731501900696294615290867175277482143370610111416633979822519113254", "price": "0.85", "size": "66.66", "side": "SELL", "hash": "38189c8b21f8b47d776ac95a44451691222b7508", "best_bid": "0.52", "best_ask": "0.68"}], "timestamp": "1769384135399", "event_type": "price_change"}}
{"_local_timestamp": "2026-01-25T23:35:35.602377+00:00", "data": {"market": "0xbf7f7047fa5719e010b9c35abab4d1510f80d78998ede7928dee762b842fd8fa", "price_changes": [{"asset_id": "99317080920004040908110146285425334348796704558628502185978368700992863001849", "price": "0.04", "size": "5.21", "side": "BUY", "hash": "f071e859521aa6700f36490d24e3863a90c27d10", "best_bid": "0.61", "best_ask": "0.99"}, {"asset_id": "80475936180674486630534655774036670401396382603097237786734519090691938222605", "price": "0.96", "size": "5.21", "side": "SELL", "hash": "1670feb45d823191caa906e66ea38d98553b4ddf", "best_bid": "0.01", "best_ask": "0.39"}], "timestamp": "1769384135399", "event_type": "price_change"}}
{"_local_timestamp": "2026-01-25T23:35:35.602972+00:00", "data": {"market": "0xf916b98c173470389af02fa32236bea1333cf05199ee997bc64a39ad6bd589ee", "price_changes": [{"asset_id": "41743802686443315505082888602082131066672260628700340336384534887243556020231", "price": "0.42", "size": "0", "side": "BUY", "hash": "074f751f1e92aa5f51b17d0e51c714c4adb01875", "best_bid": "0.77", "best_ask": "0.91"}, {"asset_id": "91462927649974781483669557862921344444854660701074121664666696309988647910790", "price": "0.58", "size": "0", "side": "SELL", "hash": "a0dff5a49a1384a9a5a0a3754823fd6f353e6b35", "best_bid": "0.09", "best_ask": "0.23"}], "timestamp": "1769384135399", "event_type": "price_change"}}
{"_local_timestamp": "2026-01-25T23:35:35.603611+00:00", "data": {"market": "0x146def8be2d4ec270cac5e8cae1d60cf8ea7064200594d10e74104db6b9a60fd", "price_changes": [{"asset_id": "59834485698328047678505195191113741956543908658984089284407908730537452141550", "price": "0.12", "size": "0", "side": "BUY", "hash": "fc5c5e66539e26a6ef7948b0e906c30a106c7ba8", "best_bid": "0.29", "best_ask": "0.8"}, {"asset_id": "76512560903138059195694921143552469386897971398516938467610044078742285307792", "price": "0.88", "size": "0", "side": "SELL", "hash": "6b7fd36a51438875154eb04779a6b50647c2f3d0", "best_bid": "0.2", "best_ask": "0.71"}], "timestamp": "1769384135399", "event_type": "price_change"}}
{"_local_timestamp": "2026-01-25T23:35:35.604206+00:00", "data": {"market": "0xf916b98c173470389af02fa32236bea1333cf05199ee997bc64a39ad6bd589ee", "price_changes": [{"asset_id": "41743802686443315505082888602082131066672260628700340336384534887243556020231", "price": "0.03", "size": "606.98", "side": "BUY", "hash": "074f751f1e92aa5f51b17d0e51c714c4adb01875", "best_bid": "0.77", "best_ask": "0.91"}, {"asset_id": "91462927649974781483669557862921344444854660701074121664666696309988647910790", "price": "0.97", "size": "606.98", "side": "SELL", "hash": "a0dff5a49a1384a9a5a0a3754823fd6f353e6b35", "best_bid": "0.09", "best_ask": "0.23"}], "timestamp": "1769384135399", "event_type": "price_change"}}
{"_local_timestamp": "2026-01-25T23:35:35.604787+00:00", "data": {"market": "0x6032e72cb2b4ee54f6c27cc8b155d0233eb5c9e772de85c60e51797b1431ddf8", "price_changes": [{"asset_id": "44848013696493898639828007101683655834417396378616727747692199122767015662748", "price": "0.43", "size": "0", "side": "BUY", "hash": "c9b921789fe932a35e25147ee5710958c49f6c21", "best_bid": "0.77", "best_ask": "0.93"}, {"asset_id": "7118736781522601355910469975087663596245621357309025148622476783856987875477", "price": "0.57", "size": "0", "side": "SELL", "hash": "cfe7a3f221c5033ba76d6fa893d45c9c18aa3770", "best_bid": "0.07", "best_ask": "0.23"}], "timestamp": "1769384135399", "event_type": "price_change"}}
{"_local_timestamp": "2026-01-25T23:35:35.605408+00:00", "data": {"market": "0xeafa01c5d48d6b7826e91f7b31e4a61a05b3fc8a1ad8ccdb2ccbad91b616ae40", "price_changes": [{"asset_id": "97279369561823536114577996580038127500018967849090745350406495876539022297477", "price": "0.01", "size": "84.84", "side": "BUY", "hash": "75c4574989b5afc958e820eb48389a36b5741a5c", "best_bid": "0.12", "best_ask": "0.29"}, {"asset_id": "83862627090039829837897753251638021110482606851285352212547333342638917195954", "price": "0.99", "size": "84.84", "side": "SELL", "hash": "aa5b72eaba77a82f9ae668439cce677021a28051", "best_bid": "0.71", "best_ask": "0.88"}], "timestamp": "1769384135399", "event_type": "price_change"}}
{"_local_timestamp": "2026-01-25T23:35:35.606081+00:00", "data": {"market": "0x6032e72cb2b4ee54f6c27cc8b155d0233eb5c9e772de85c60e51797b1431ddf8", "price_changes": [{"asset_id": "44848013696493898639828007101683655834417396378616727747692199122767015662748", "price": "0.22", "size": "0", "side": "BUY", "hash": "c9b921789fe932a35e25147ee5710958c49f6c21", "best_bid": "0.77", "best_ask": "0.93"}, {"asset_id": "7118736781522601355910469975087663596245621357309025148622476783856987875477", "price": "0.78", "size": "0", "side": "SELL", "hash": "cfe7a3f221c5033ba76d6fa893d45c9c18aa3770", "best_bid": "0.07", "best_ask": "0.23"}], "timestamp": "1769384135399", "event_type": "price_change"}}
{"_local_timestamp": "2026-01-25T23:35:35.606764+00:00", "data": {"market": "0x6032e72cb2b4ee54f6c27cc8b155d0233eb5c9e772de85c60e51797b1431ddf8", "price_changes": [{"asset_id": "44848013696493898639828007101683655834417396378616727747692199122767015662748", "price": "0.01", "size": "2360.29", "side": "BUY", "hash": "c9b921789fe932a35e25147ee5710958c49f6c21", "best_bid": "0.77", "best_ask": "0.93"}, {"asset_id": "7118736781522601355910469975087663596245621357309025148622476783856987875477", "price": "0.99", "size": "2360.29", "side": "SELL", "hash": "cfe7a3f221c5033ba76d6fa893d45c9c18aa3770", "best_bid": "0.07", "best_ask": "0.23"}], "timestamp": "1769384135399", "event_type": "price_change"}}
{"_local_timestamp": "2026-01-25T23:35:35.607378+00:00", "data": {"market": "0xadd7737a947ee4b404262bd268a7dad202a7b93a853e59eb29c3770bdf5a3c5e", "price_changes": [{"asset_id": "34873810304813988618460030655204351211024364269964394342687234411411922138015", "price": "0.46", "size": "0", "side": "BUY", "hash": "7bb54633aafa80e037c2ddfd260f16ae369bfa04", "best_bid": "0.79", "best_ask": "0.91"}, {"asset_id": "61947573105398885505676981136106310455132935973656038313589742543062489249520", "price": "0.54", "size": "0", "side": "SELL", "hash": "950559387f31cb315ed74485c61c0d7846c7a76a", "best_bid": "0.09", "best_ask": "0.21"}], "timestamp": "1769384135399", "event_type": "price_change"}}
{"_local_timestamp": "2026-01-25T23:35:35.607972+00:00", "data": {"market": "0x6f14e52f6a1502a35406feea3f0e8d42502bbf1199e42c73a743fe1745ccc12c", "price_changes": [{"asset_id": "64289097521554308111154900994757912304033484898403308857843640646685729282110", "price": "0.1", "size": "0", "side": "BUY", "hash": "807feada83086d756fc5fc88b4017306ba4e76f1", "best_bid": "0.25", "best_ask": "0.43"}, {"asset_id": "17811605278785499666964340297379704435403265198212995098387642426099375215061", "price": "0.9", "size": "0", "side": "SELL", "hash": "5fcd17f908b3d2c0058d593b6c6e23275888fb24", "best_bid": "0.57", "best_ask": "0.75"}], "timestamp": "1769384135399", "event_type": "price_change"}}
{"_local_timestamp": "2026-01-25T23:35:35.608598+00:00", "data": {"market": "0xadd7737a947ee4b404262bd268a7dad202a7b93a853e59eb29c3770bdf5a3c5e", "price_changes": [{"asset_id": "34873810304813988618460030655204351211024364269964394342687234411411922138015", "price": "0.21", "size": "0", "side": "BUY", "hash": "7bb54633aafa80e037c2ddfd260f16ae369bfa04", "best_bid": "0.79", "best_ask": "0.91"}, {"asset_id": "61947573105398885505676981136106310455132935973656038313589742543062489249520", "price": "0.79", "size": "0", "side": "SELL", "hash": "950559387f31cb315ed74485c61c0d7846c7a76a", "best_bid": "0.09", "best_ask": "0.21"}], "timestamp": "1769384135399", "event_type": "price_change"}}
{"_local_timestamp": "2026-01-25T23:35:35.609245+00:00", "data": {"market": "0x6f14e52f6a1502a35406feea3f0e8d42502bbf1199e42c73a743fe1745ccc12c", "price_changes": [{"asset_id": "64289097521554308111154900994757912304033484898403308857843640646685729282110", "price": "0.06", "size": "266.66", "side": "BUY", "hash": "807feada83086d756fc5fc88b4017306ba4e76f1", "best_bid": "0.25", "best_ask": "0.43"}, {"asset_id": "17811605278785499666964340297379704435403265198212995098387642426099375215061", "price": "0.94", "size": "266.66", "side": "SELL", "hash": "5fcd17f908b3d2c0058d593b6c6e23275888fb24", "best_bid": "0.57", "best_ask": "0.75"}], "timestamp": "1769384135399", "event_type": "price_change"}}
{"_local_timestamp": "2026-01-25T23:35:35.609877+00:00", "data": {"market": "0xadd7737a947ee4b404262bd268a7dad202a7b93a853e59eb29c3770bdf5a3c5e", "price_changes": [{"asset_id": "34873810304813988618460030655204351211024364269964394342687234411411922138015", "price": "0.01", "size": "2310.57", "side": "BUY", "hash": "7bb54633aafa80e037c2ddfd260f16ae369bfa04", "best_bid": "0.79", "best_ask": "0.91"}, {"asset_id": "61947573105398885505676981136106310455132935973656038313589742543062489249520", "price": "0.99", "size": "2310.57", "side": "SELL", "hash": "950559387f31cb315ed74485c61c0d7846c7a76a", "best_bid": "0.09", "best_ask": "0.21"}], "timestamp": "1769384135399", "event_type": "price_change"}}
{"_local_timestamp": "2026-01-25T23:35:35.610560+00:00", "data": {"market": "0xd2b2d52f7b03ee5ddc6f79596f8e058eedf95af2c9df32fc5a9d6b3f7d4de949", "price_changes": [{"asset_id": "77757001671665002605821663755609213754761394915884653403308048610819412553431", "price": "0.45", "size": "0", "side": "BUY", "hash": "cc0328dea9a1f0c199a2b8853f6b397ff547bff4", "best_bid": "0.53", "best_ask": "0.71"}, {"asset_id": "49722951406964623396190322027929924958979018653915811865810011588719564539488", "price": "0.55", "size": "0", "side": "SELL", "hash": "5124191adfcadc7e48147a7df0d87b11f50b4b64", "best_bid": "0.29", "best_ask": "0.47"}], "timestamp": "1769384135399", "event_type": "price_change"}}
{"_local_timestamp": "2026-01-25T23:35:35.611227+00:00", "data": {"market": "0x1cc14846bee31efbd7c2016ca1c17664684ead0c7f3b8bd91876033a546128d8", "price_changes": [{"asset_id": "60596582874731501900696294615290867175277482143370610111416633979822519113254", "price": "0.2", "size": "220", "side": "BUY", "hash": "a3a413055bbd3180302204e98f92167bd4ef84bd", "best_bid": "0.52", "best_ask": "0.68"}, {"asset_id": "32668102469816119620746811427740823831434256980467530534403997191651163337906", "price": "0.8", "size": "220", "side": "SELL", "hash": "c21ad1ccca3c3049df30c66ec42757b71b8e9a87", "best_bid": "0.32", "best_ask": "0.48"}], "timestamp": "1769384135400", "event_type": "price_change"}}
{"_local_timestamp": "2026-01-25T23:35:35.611911+00:00", "data": {"market": "0x6f14e52f6a1502a35406feea3f0e8d42502bbf1199e42c73a743fe1745ccc12c", "price_changes": [{"asset_id": "17811605278785499666964340297379704435403265198212995098387642426099375215061", "price": "0.31", "size": "0", "side": "BUY", "hash": "2aebe95bf14aa35f9e5f325cace31a7398960627", "best_bid": "0.57", "best_ask": "0.75"}, {"asset_id": "64289097521554308111154900994757912304033484898403308857843640646685729282110", "price": "0.69", "size": "0", "side": "SELL", "hash": "466c936af6df6ab9c926abc3b194c2ec3ea685ee", "best_bid": "0.25", "best_ask": "0.43"}], "timestamp": "1769384135400", "event_type": "price_change"}}
{"_local_timestamp": "2026-01-25T23:35:35.612669+00:00", "data": {"market": "0x6f14e52f6a1502a35406feea3f0e8d42502bbf1199e42c73a743fe1745ccc12c", "price_changes": [{"asset_id": "17811605278785499666964340297379704435403265198212995098387642426099375215061", "price": "0.06", "size": "1333", "side": "BUY", "hash": "2aebe95bf14aa35f9e5f325cace31a7398960627", "best_bid": "0.57", "best_ask": "0.75"}, {"asset_id": "64289097521554308111154900994757912304033484898403308857843640646685729282110", "price": "0.94", "size": "1333", "side": "SELL", "hash": "466c936af6df6ab9c926abc3b194c2ec3ea685ee", "best_bid": "0.25", "best_ask": "0.43"}], "timestamp": "1769384135400", "event_type": "price_change"}}
{"_local_timestamp": "2026-01-25T23:35:35.931891+00:00", "data": {"market": "0xd2b2d52f7b03ee5ddc6f79596f8e058eedf95af2c9df32fc5a9d6b3f7d4de949", "price_changes": [{"asset_id": "77757001671665002605821663755609213754761394915884653403308048610819412553431", "price": "0.54", "size": "66.66", "side": "BUY", "hash": "0aa4bcc42821307c8bc681743f6251ca1526a3a8", "best_bid": "0.54", "best_ask": "0.71"}, {"asset_id": "49722951406964623396190322027929924958979018653915811865810011588719564539488", "price": "0.46", "size": "66.66", "side": "SELL", "hash": "e0c5c4e0593a939c1ef5e4bcb974d51fe93d7fb3", "best_bid": "0.29", "best_ask": "0.46"}], "timestamp": "1769384135863", "event_type": "price_change"}}
{"_local_timestamp": "2026-01-25T23:35:36.038378+00:00", "data": {"market": "0xadd7737a947ee4b404262bd268a7dad202a7b93a853e59eb29c3770bdf5a3c5e", "price_changes": [{"asset_id": "34873810304813988618460030655204351211024364269964394342687234411411922138015", "price": "0.01", "size": "2410.57", "side": "BUY", "hash": "cdd8e777edb648375b7671440f59eca783495b18", "best_bid": "0.79", "best_ask": "0.91"}, {"asset_id": "61947573105398885505676981136106310455132935973656038313589742543062489249520", "price": "0.99", "size": "2410.57", "side": "SELL", "hash": "95cf683abae6e20615489fb394b666fb6858f2a1", "best_bid": "0.09", "best_ask": "0.21"}], "timestamp": "1769384135974", "event_type": "price_change"}}
{"_local_timestamp": "2026-01-25T23:35:36.139683+00:00", "data": {"market": "0xadd7737a947ee4b404262bd268a7dad202a7b93a853e59eb29c3770bdf5a3c5e", "price_changes": [{"asset_id": "34873810304813988618460030655204351211024364269964394342687234411411922138015", "price": "0.4", "size": "105", "side": "BUY", "hash": "afc253749a0196b4f9255c84edaeb7b08aa79a28", "best_bid": "0.79", "best_ask": "0.91"}, {"asset_id": "61947573105398885505676981136106310455132935973656038313589742543062489249520", "price": "0.6", "size": "105", "side": "SELL", "hash": "86dd76edfa2278c818a8399bb02787c33628da96", "best_bid": "0.09", "best_ask": "0.21"}], "timestamp": "1769384136022", "event_type": "price_change"}}
{"_local_timestamp": "2026-01-25T23:35:36.140434+00:00", "data": {"market": "0xbf7f7047fa5719e010b9c35abab4d1510f80d78998ede7928dee762b842fd8fa", "price_changes": [{"asset_id": "99317080920004040908110146285425334348796704558628502185978368700992863001849", "price": "0.04", "size": "105.21", "side": "BUY", "hash": "df630bdff966c89c442995154098bd0c71b62c9f", "best_bid": "0.61", "best_ask": "0.99"}, {"asset_id": "80475936180674486630534655774036670401396382603097237786734519090691938222605", "price": "0.96", "size": "105.21", "side": "SELL", "hash": "1ffad4e1ae70665b1da3f7f87698cd807f10bffc", "best_bid": "0.01", "best_ask": "0.39"}], "timestamp": "1769384136022", "event_type": "price_change"}}
{"_local_timestamp": "2026-01-25T23:35:36.141067+00:00", "data": {"market": "0xbf7f7047fa5719e010b9c35abab4d1510f80d78998ede7928dee762b842fd8fa", "price_changes": [{"asset_id": "99317080920004040908110146285425334348796704558628502185978368700992863001849", "price": "0.33", "size": "100", "side": "BUY", "hash": "d0555692c277b2189ad649583fe203c07fdea764", "best_bid": "0.61", "best_ask": "0.99"}, {"asset_id": "80475936180674486630534655774036670401396382603097237786734519090691938222605", "price": "0.67", "size": "100", "side": "SELL", "hash": "b4dc69a54c53389369bb4921b9de91e6c7fc64e2", "best_bid": "0.01", "best_ask": "0.39"}], "timestamp": "1769384136030", "event_type": "price_change"}}
{"_local_timestamp": "2026-01-25T23:35:36.214599+00:00", "data": {"market": "0x5b17571f0687e9ef62aead3a3e57bfc617f16e4806865d8b7cc609a680ac9892", "price_changes": [{"asset_id": "54672482098306675309495708206879727568512955356356264682879888123590518385092", "price": "0.55", "size": "66.66", "side": "BUY", "hash": "6e9f26057fa6dde95a5a1141af85d9c845f3176b", "best_bid": "0.67", "best_ask": "0.96"}, {"asset_id": "30934121158421236234732376879006750136278688549793740923122711845308054079491", "price": "0.45", "size": "66.66", "side": "SELL", "hash": "9a60068661834009673158ded661cacdc3313b96", "best_bid": "0.04", "best_ask": "0.33"}], "timestamp": "1769384136148", "event_type": "price_change"}}
{"_local_timestamp": "2026-01-25T23:35:36.230159+00:00", "data": {"market": "0xeafa01c5d48d6b7826e91f7b31e4a61a05b3fc8a1ad8ccdb2ccbad91b616ae40", "price_changes": [{"asset_id": "83862627090039829837897753251638021110482606851285352212547333342638917195954", "price": "0.36", "size": "66.66", "side": "BUY", "hash": "edfc1f25115e31091f35624ba88eacb0d2d2c6cc", "best_bid": "0.71", "best_ask": "0.88"}, {"asset_id": "97279369561823536114577996580038127500018967849090745350406495876539022297477", "price": "0.64", "size": "66.66", "side": "SELL", "hash": "fd2ff9d6ccaf6e343f1498e23c3e07d24ed3c01d", "best_bid": "0.12", "best_ask": "0.29"}], "timestamp": "1769384136160", "event_type": "price_change"}}
{"_local_timestamp": "2026-01-25T23:35:36.230847+00:00", "data": {"market": "0xeafa01c5d48d6b7826e91f7b31e4a61a05b3fc8a1ad8ccdb2ccbad91b616ae40", "price_changes": [{"asset_id": "83862627090039829837897753251638021110482606851285352212547333342638917195954", "price": "0.01", "size": "2871.76", "side": "BUY", "hash": "179b991be83a14121daa34c6767c2aadfe740dc2", "best_bid": "0.71", "best_ask": "0.88"}, {"asset_id": "97279369561823536114577996580038127500018967849090745350406495876539022297477", "price": "0.99", "size": "2871.76", "side": "SELL", "hash": "e948348433bf734fba5a1b48934137701ec94246", "best_bid": "0.12", "best_ask": "0.29"}], "timestamp": "1769384136162", "event_type": "price_change"}}
{"_local_timestamp": "2026-01-25T23:35:36.257391+00:00", "data": {"market": "0x146def8be2d4ec270cac5e8cae1d60cf8ea7064200594d10e74104db6b9a60fd", "price_changes": [{"asset_id": "59834485698328047678505195191113741956543908658984089284407908730537452141550", "price": "0.3", "size": "66.66", "side": "BUY", "hash": "a117363cb5f45ee399f25dd201184ac83ffa645a", "best_bid": "0.3", "best_ask": "0.8"}, {"asset_id": "76512560903138059195694921143552469386897971398516938467610044078742285307792", "price": "0.7", "size": "66.66", "side": "SELL", "hash": "8d125fb4b41b85a818f405b1946b5440cc4b19db", "best_bid": "0.2", "best_ask": "0.7"}], "timestamp": "1769384136184", "event_type": "price_change"}}
{"_local_timestamp": "2026-01-25T23:35:36.314416+00:00", "data": {"market": "0xeafa01c5d48d6b7826e91f7b31e4a61a05b3fc8a1ad8ccdb2ccbad91b616ae40", "price_changes": [{"asset_id": "97279369561823536114577996580038127500018967849090745350406495876539022297477", "price": "0.13", "size": "20.78", "side": "BUY", "hash": "aed9988f20497f27d21aca8b792c05d98878b07d", "best_bid": "0.13", "best_ask": "0.29"}, {"asset_id": "83862627090039829837897753251638021110482606851285352212547333342638917195954", "price": "0.87", "size": "20.78", "side": "SELL", "hash": "5c01542a5917524deb7e31d30d7e066cb257d635", "best_bid": "0.71", "best_ask": "0.87"}], "timestamp": "1769384136249", "event_type": "price_change"}}
{"_local_timestamp": "2026-01-25T23:35:36.315353+00:00", "data": {"market": "0x90a6d406570f273840bd2e39e25dbd0a91655cd347dbb2bc381863743044bf32", "price_changes": [{"asset_id": "36331391317493054259843206160279589805054745072393638988521393636953188108839", "price": "0.25", "size": "66.66", "side": "BUY", "hash": "d663816c7b32eee1427784d8aa21e01e59160673", "best_bid": "0.25", "best_ask": "0.78"}, {"asset_id": "92143930323152159931232014367424593746113767612080401756819785961080544448740", "price": "0.75", "size": "66.66", "side": "SELL", "hash": "1fdbc6938ac12f45227b97b21e7409452a27da50", "best_bid": "0.22", "best_ask": "0.75"}], "timestamp": "1769384136251", "event_type": "price_change"}}
{"_local_timestamp": "2026-01-25T23:35:36.339881+00:00", "data": {"market": "0xa96f3bae6635e8f42628c39ce7b61fd566b9253d4f2699c3cac08be6d17ca723", "price_changes": [{"asset_id": "31555074014428326614377030963919393145120116674000147512977361328627463258713", "price": "0.05", "size": "267.64", "side": "BUY", "hash": "0cfa51d26ffbfc53fabd02d68082a08d257a91b2", "best_bid": "0.07", "best_ask": "0.18"}, {"asset_id": "49976858258828287893504382876186665182729041451625761701208418053508589757916", "price": "0.95", "size": "267.64", "side": "SELL", "hash": "1c047a594238a12faab93b981edec0d01cd23842", "best_bid": "0.82", "best_ask": "0.93"}], "timestamp": "1769384136270", "event_type": "price_change"}}
{"_local_timestamp": "2026-01-25T23:35:36.340720+00:00", "data": {"market": "0x1cc14846bee31efbd7c2016ca1c17664684ead0c7f3b8bd91876033a546128d8", "price_changes": [{"asset_id": "60596582874731501900696294615290867175277482143370610111416633979822519113254", "price": "0.24", "size": "33.33", "side": "BUY", "hash": "bde08936efc45a2c9e79bdfd1e51de525929c825", "best_bid": "0.52", "best_ask": "0.68"}, {"asset_id": "32668102469816119620746811427740823831434256980467530534403997191651163337906", "price": "0.76", "size": "33.33", "side": "SELL", "hash": "98b85bdd319ffed0e21a74f140210a3dec3f70f8", "best_bid": "0.32", "best_ask": "0.48"}], "timestamp": "1769384136273", "event_type": "price_change"}}
{"_local_timestamp": "2026-01-25T23:35:36.347015+00:00", "data": {"market": "0x1cc14846bee31efbd7c2016ca1c17664684ead0c7f3b8bd91876033a546128d8", "price_changes": [{"asset_id": "32668102469816119620746811427740823831434256980467530534403997191651163337906", "price": "0.24", "size": "66.66", "side": "BUY", "hash": "2a793ded3ff3513022467c3a42947a286fdb4056", "best_bid": "0.32", "best_ask": "0.48"}, {"asset_id": "60596582874731501900696294615290867175277482143370610111416633979822519113254", "price": "0.76", "size": "66.66", "side": "SELL", "hash": "55743cc288d90c8f9b3cffb98a273d6853b04390", "best_bid": "0.52", "best_ask": "0.68"}], "timestamp": "1769384136276", "event_type": "price_change"}}
{"_local_timestamp": "2026-01-25T23:35:36.366481+00:00", "data": {"market": "0xeafa01c5d48d6b7826e91f7b31e4a61a05b3fc8a1ad8ccdb2ccbad91b616ae40", "price_changes": [{"asset_id": "83862627090039829837897753251638021110482606851285352212547333342638917195954", "price": "0.15", "size": "0", "side": "BUY", "hash": "90ed7303e5cb734d2c694fdb9161b4a4b92e2fcb", "best_bid": "0.71", "best_ask": "0.87"}, {"asset_id": "97279369561823536114577996580038127500018967849090745350406495876539022297477", "price": "0.85", "size": "0", "side": "SELL", "hash": "f51a0c42a302d6a698f88b4068d8ebd2b28c7cf8", "best_bid": "0.13", "best_ask": "0.29"}], "timestamp": "1769384136286", "event_type": "price_change"}}
