{"_local_timestamp": "2026-01-25T23:33:32.127623+00:00", "data": [{"market": "0x12d1b41c90a2ff07173ab2469aad97fb9e80f781b36c32f99fbf4ae28a28b42a", "asset_id": "36737124956681902477833012015613017711780279541938574794261768841905170092613", "timestamp": "1769383913968", "hash": "b02a2442e0a3301107da9c5a86e6ec3968484cab", "bids": [{"price": "0.01", "size": "3005.53"}, {"price": "0.02", "size": "2255.11"}, {"price": "0.03", "size": "5700"}, {"price": "0.04", "size": "507.06"}, {"price": "0.05", "size": "35"}, {"price": "0.06", "size": "1300"}, {"price": "0.09", "size": "377.77"}, {"price": "0.1", "size": "5.6"}, {"price": "0.12", "size": "266.66"}, {"price": "0.14", "size": "200"}, {"price": "0.15", "size": "1321.44"}, {"price": "0.16", "size": "968.14"}, {"price": "0.17", "size": "152.94"}, {"price": "0.2", "size": "270"}, {"price": "0.23", "size": "86.95"}, {"price": "0.25", "size": "1600"}, {"price": "0.26", "size": "918.13"}, {"price": "0.3", "size": "21.03"}, {"price": "0.36", "size": "9"}, {"price": "0.4", "size": "1000"}, {"price": "0.41", "size": "50"}, {"price": "0.45", "size": "200"}, {"price": "0.46", "size": "300"}, {"price": "0.47", "size": "1200"}, {"price": "0.48", "size": "227.08"}, {"price": "0.49", "size": "282.44"}, {"price": "0.5", "size": "2450"}, {"price": "0.51", "size": "519.92"}, {"price": "0.52", "size": "246"}, {"price": "0.53", "size": "1121.71"}, {"price": "0.54", "size": "156.85"}], "asks": [{"price": "0.99", "size": "3310.2"}, {"price": "0.98", "size": "2950"}, {"price": "0.97", "size": "10.58"}, {"price": "0.96", "size": "50"}, {"price": "0.95", "size": "970"}, {"price": "0.93", "size": "685.71"}, {"price": "0.91", "size": "355.55"}, {"price": "0.9", "size": "5.79"}, {"price": "0.88", "size": "783.33"}, {"price": "0.86", "size": "185.71"}, {"price": "0.84", "size": "150"}, {"price": "0.82", "size": "2822.97"}, {"price": "0.81", "size": "349.86"}, {"price": "0.8", "size": "1020"}, {"price": "0.79", "size": "9"}, {"price": "0.7", "size": "56.04"}, {"price": "0.69", "size": "50"}, {"price": "0.68", "size": "50"}, {"price": "0.66", "size": "299.87"}, {"price": "0.65", "size": "30.01"}, {"price": "0.64", "size": "420.11"}, {"price": "0.63", "size": "167.72"}, {"price": "0.6", "size": "100"}, {"price": "0.59", "size": "264"}, {"price": "0.58", "size": "100"}, {"price": "0.57", "size": "31"}, {"price": "0.56", "size": "20"}], "event_type": "book", "last_trade_price": "0.540"}, {"market": "0x29fcb3cb3301dde656aaaf7d185bb56c9b6948968b9d95f87f3942355b6bf360", "asset_id": "91783318584258680143008562461721551652033317272474793227511040505886797754334", "timestamp": "1769383925856", "hash": "91ef930718064a3114fbf78f59c8ad7edec32c90", "bids": [{"price": "0.001", "size": "28173.99"}, {"price": "0.002", "size": "3441.02"}, {"price": "0.003", "size": "127.52"}, {"price": "0.004", "size": "98"}, {"price": "0.005", "size": "79.24"}, {"price": "0.017", "size": "20"}, {"price": "0.018", "size": "9.51"}, {"price": "0.02", "size": "500"}, {"price": "0.021", "size": "433.66"}], "asks": [{"price": "0.999", "size": "3887.11"}, {"price": "0.998", "size": "1257.69"}, {"price": "0.997", "size": "1166"}, {"price": "0.996", "size": "15.19"}, {"price": "0.994", "size": "83"}, {"price": "0.99", "size": "3000"}, {"price": "0.989", "size": "6.34"}, {"price": "0.98", "size": "1400"}, {"price": "0.968", "size": "8.73"}, {"price": "0.967", "size": "12"}, {"price": "0.95", "size": "30"}, {"price": "0.949", "size": "39"}, {"price": "0.948", "size": "8"}, {"price": "0.9", "size": "660"}, {"price": "0.899", "size": "7"}, {"price": "0.898", "size": "5.82"}, {"price": "0.85", "size": "451.66"}, {"price": "0.849", "size": "6"}, {"price": "0.81", "size": "318.42"}, {"price": "0.809", "size": "7"}, {"price": "0.76", "size": "266.66"}, {"price": "0.759", "size": "7"}, {"price": "0.71", "size": "97.65"}, {"price": "0.709", "size": "200"}, {"price": "0.708", "size": "39.12"}, {"price": "0.707", "size": "8"}, {"price": "0.66", "size": "70.58"}, {"price": "0.659", "size": "8"}, {"price": "0.61", "size": "51.28"}, {"price": "0.609", "size": "66.47"}, {"price": "0.607", "size": "33"}, {"price": "0.606", "size": "9"}, {"price": "0.376", "size": "100"}, {"price": "0.375", "size": "40"}, {"price": "0.374", "size": "19"}, {"price": "0.373", "size": "13.4"}, {"price": "0.139", "size": "20"}, {"price": "0.053", "size": "7.64"}, {"price": "0.05", "size": "48"}, {"price": "0.045", "size": "8.93"}], "event_type": "book", "last_trade_price": "0.045"}, {"market": "0x5abe3287197d0a924707ce99130643c92751c209fc0e376c6700d6673b43ada5", "asset_id": "2791138143012434753446657502011224259420532252815498101697790519791539429743", "timestamp": "1769383954172", "hash": "3e31cd0be38f7c9571f3f8bdf938b0f3564e5a8e", "bids": [{"price": "0.01", "size": "3077.13"}, {"price": "0.02", "size": "1400"}, {"price": "0.03", "size": "9.36"}, {"price": "0.08", "size": "950"}, {"price": "0.09", "size": "6.86"}, {"price": "0.13", "size": "811.53"}, {"price": "0.17", "size": "588.23"}, {"price": "0.21", "size": "383.33"}, {"price": "0.22", "size": "216"}, {"price": "0.26", "size": "150"}, {"price": "0.27", "size": "50"}, {"price": "0.3", "size": "80"}, {"price": "0.31", "size": "50"}, {"price": "0.34", "size": "133.82"}, {"price": "0.35", "size": "100"}, {"price": "0.36", "size": "299.99"}, {"price": "0.38", "size": "5"}, {"price": "0.55", "size": "23.63"}, {"price": "0.56", "size": "119.64"}, {"price": "0.57", "size": "30"}, {"price": "0.58", "size": "30"}, {"price": "0.61", "size": "113"}, {"price": "0.74", "size": "20"}, {"price": "0.75", "size": "50"}, {"price": "0.76", "size": "13.62"}], "asks": [{"price": "0.99", "size": "17.51"}, {"price": "0.98", "size": "1255"}, {"price": "0.97", "size": "250"}, {"price": "0.96", "size": "257.48"}, {"price": "0.95", "size": "410"}, {"price": "0.94", "size": "703.3"}, {"price": "0.93", "size": "143"}, {"price": "0.92", "size": "6.57"}, {"price": "0.91", "size": "61.11"}, {"price": "0.9", "size": "130"}, {"price": "0.89", "size": "1046"}, {"price": "0.86", "size": "531.66"}, {"price": "0.84", "size": "52"}, {"price": "0.83", "size": "133"}], "event_type": "book", "last_trade_price": "0.240"}, {"market": "0xf3b4662d12f86894b31d52b454428c91733c166ba05c4e3bccc375f78411601a", "asset_id": "30441349073423271296409239412402830197110444658615254085853491470932508604811", "timestamp": "1769383955368", "hash": "987e1e2171f40f6dc17268209e94dec59dd82d8e", "bids": [{"price": "0.001", "size": "37095.87"}, {"price": "0.002", "size": "916"}, {"price": "0.003", "size": "115.58"}, {"price": "0.02", "size": "1250"}, {"price": "0.021", "size": "13.4"}, {"price": "0.04", "size": "250"}, {"price": "0.041", "size": "7.02"}, {"price": "0.05", "size": "199.25"}, {"price": "0.051", "size": "99"}, {"price": "0.086", "size": "151.16"}, {"price": "0.088", "size": "68.5"}, {"price": "0.089", "size": "91"}, {"price": "0.09", "size": "6"}, {"price": "0.185", "size": "6"}, {"price": "0.211", "size": "15.92"}, {"price": "0.213", "size": "6"}, {"price": "0.214", "size": "42.83"}, {"price": "0.215", "size": "54.18"}], "asks": [{"price": "0.999", "size": "6698.55"}, {"price": "0.998", "size": "1250"}, {"price": "0.997", "size": "1173.76"}, {"price": "0.994", "size": "83"}, {"price": "0.993", "size": "11.06"}, {"price": "0.99", "size": "1000"}, {"price": "0.98", "size": "400"}, {"price": "0.979", "size": "12.87"}, {"price": "0.961", "size": "94.8"}, {"price": "0.949", "size": "39"}, {"price": "0.92", "size": "950"}, {"price": "0.919", "size": "7.62"}, {"price": "0.88", "size": "833.33"}, {"price": "0.84", "size": "600"}, {"price": "0.8", "size": "140"}, {"price": "0.76", "size": "258.33"}, {"price": "0.759", "size": "66.66"}, {"price": "0.737", "size": "30"}, {"price": "0.72", "size": "135.71"}, {"price": "0.716", "size": "25"}, {"price": "0.68", "size": "62.5"}, {"price": "0.679", "size": "6"}, {"price": "0.518", "size": "66.66"}, {"price": "0.517", "size": "10"}, {"price": "0.45", "size": "10"}, {"price": "0.357", "size": "30"}, {"price": "0.355", "size": "20.15"}, {"price": "0.353", "size": "17"}, {"price": "0.352", "size": "15"}, {"price": "0.351", "size": "6"}, {"price": "0.306", "size": "8.81"}, {"price": "0.29", "size": "6"}, {"price": "0.284", "size": "6"}, {"price": "0.278", "size": "15"}, {"price": "0.276", "size": "45"}, {"price": "0.274", "size": "66.66"}, {"price": "0.273", "size": "50"}], "event_type": "book", "last_trade_price": "0.249"}, {"market": "0xf3b4662d12f86894b31d52b454428c91733c166ba05c4e3bccc375f78411601a", "asset_id": "55382819090443168507206409119841525953451022223003224583889620760999266943524", "timestamp": "1769383955368", "hash": "3ad9b3f5b9ae0ff5839bb1304c4a2a5a576690b7", "bids": [{"price": "0.001", "size": "6698.55"}, {"price": "0.002", "size": "1250"}, {"price": "0.003", "size": "1173.76"}, {"price": "0.006", "size": "83"}, {"price": "0.007", "size": "11.06"}, {"price": "0.01", "size": "1000"}, {"price": "0.02", "size": "400"}, {"price": "0.021", "size": "12.87"}, {"price": "0.039", "size": "94.8"}, {"price": "0.051", "size": "39"}, {"price": "0.08", "size": "950"}, {"price": "0.081", "size": "7.62"}, {"price": "0.12", "size": "833.33"}, {"price": "0.16", "size": "600"}, {"price": "0.2", "size": "140"}, {"price": "0.24", "size": "258.33"}, {"price": "0.241", "size": "66.66"}, {"price": "0.263", "size": "30"}, {"price": "0.28", "size": "135.71"}, {"price": "0.284", "size": "25"}, {"price": "0.32", "size": "62.5"}, {"price": "0.321", "size": "6"}, {"price": "0.482", "size": "66.66"}, {"price": "0.483", "size": "10"}, {"price": "0.55", "size": "10"}, {"price": "0.643", "size": "30"}, {"price": "0.645", "size": "20.15"}, {"price": "0.647", "size": "17"}, {"price": "0.648", "size": "15"}, {"price": "0.649", "size": "6"}, {"price": "0.694", "size": "8.81"}, {"price": "0.71", "size": "6"}, {"price": "0.716", "size": "6"}, {"price": "0.722", "size": "15"}, {"price": "0.724", "size": "45"}, {"price": "0.726", "size": "66.66"}, {"price": "0.727", "size": "50"}], "asks": [{"price": "0.999", "size": "37095.87"}, {"price": "0.998", "size": "916"}, {"price": "0.997", "size": "115.58"}, {"price": "0.98", "size": "1250"}, {"price": "0.979", "size": "13.4"}, {"price": "0.96", "size": "250"}, {"price": "0.959", "size": "7.02"}, {"price": "0.95", "size": "199.25"}, {"price": "0.949", "size": "99"}, {"price": "0.914", "size": "151.16"}, {"price": "0.912", "size": "68.5"}, {"price": "0.911", "size": "91"}, {"price": "0.91", "size": "6"}, {"price": "0.815", "size": "6"}, {"price": "0.789", "size": "15.92"}, {"price": "0.787", "size": "6"}, {"price": "0.786", "size": "42.83"}, {"price": "0.785", "size": "54.18"}], "event_type": "book", "last_trade_price": "0.249"}, {"market": "0x43aad651177544538b5b35dc3239d1631fca344147c0ffe0e416cd0eb51fca6d", "asset_id": "76997947933304274428562592491730603768950795614322500110266632020523223203438", "timestamp": "1769383946460", "hash": "c9bea699f27588fe36adedb382f838c9f7273cbd", "bids": [{"price": "0.01", "size": "2580"}, {"price": "0.02", "size": "1512.07"}, {"price": "0.03", "size": "428.79"}, {"price": "0.04", "size": "179.87"}, {"price": "0.05", "size": "33.09"}], "asks": [{"price": "0.99", "size": "3049.9"}, {"price": "0.98", "size": "1400"}, {"price": "0.97", "size": "10.2"}, {"price": "0.95", "size": "30"}, {"price": "0.94", "size": "33"}, {"price": "0.9", "size": "860"}, {"price": "0.89", "size": "5.41"}, {"price": "0.86", "size": "792.85"}, {"price": "0.81", "size": "568.42"}, {"price": "0.76", "size": "416.66"}, {"price": "0.75", "size": "100"}, {"price": "0.71", "size": "139.65"}, {"price": "0.69", "size": "264"}, {"price": "0.66", "size": "70.58"}, {"price": "0.62", "size": "52.63"}, {"price": "0.61", "size": "225"}, {"price": "0.6", "size": "5"}, {"price": "0.35", "size": "100"}, {"price": "0.25", "size": "200"}, {"price": "0.19", "size": "100"}, {"price": "0.18", "size": "94.44"}, {"price": "0.17", "size": "23.68"}, {"price": "0.14", "size": "36"}, {"price": "0.1", "size": "15.73"}, {"price": "0.09", "size": "20"}], "event_type": "book", "last_trade_price": "0.100"}, {"market": "0xc954c52447b5856106b45c55df1003b48a583af3b4772bda1de20e0a95ad5f45", "asset_id": "52417019033358898530053799473085644762541010045525203660683879224996320434909", "timestamp": "1769383980564", "hash": "0dfa2ff6844e01770dbaedb2fc3fc003d33ec338", "bids": [{"price": "0.001", "size": "3891.13"}, {"price": "0.002", "size": "1250"}, {"price": "0.003", "size": "1172.66"}, {"price": "0.006", "size": "83"}, {"price": "0.007", "size": "9.55"}, {"price": "0.01", "size": "3000"}, {"price": "0.02", "size": "1400"}, {"price": "0.021", "size": "14.47"}, {"price": "0.05", "size": "30"}, {"price": "0.051", "size": "39"}, {"price": "0.1", "size": "860"}, {"price": "0.101", "size": "5.93"}, {"price": "0.15", "size": "776.66"}, {"price": "0.2", "size": "610"}, {"price": "0.25", "size": "362"}, {"price": "0.251", "size": "156"}, {"price": "0.252", "size": "5.27"}, {"price": "0.3", "size": "186.66"}, {"price": "0.301", "size": "8"}, {"price": "0.34", "size": "70.58"}, {"price": "0.341", "size": "8"}, {"price": "0.39", "size": "110.28"}, {"price": "0.392", "size": "146.66"}, {"price": "0.393", "size": "9"}, {"price": "0.668", "size": "66.66"}, {"price": "0.669", "size": "16"}, {"price": "0.901", "size": "101.84"}, {"price": "0.902", "size": "180"}, {"price": "0.903", "size": "52"}, {"price": "0.934", "size": "5.97"}, {"price": "0.936", "size": "48.38"}, {"price": "0.944", "size": "15"}, {"price": "0.947", "size": "66.66"}, {"price": "0.948", "size": "50"}], "asks": [{"price": "0.999", "size": "17011.17"}, {"price": "0.998", "size": "4347"}, {"price": "0.997", "size": "1684.02"}, {"price": "0.996", "size": "25.39"}, {"price": "0.995", "size": "28"}, {"price": "0.994", "size": "8.09"}, {"price": "0.993", "size": "13.78"}, {"price": "0.992", "size": "77.26"}, {"price": "0.991", "size": "36.66"}, {"price": "0.988", "size": "27.09"}, {"price": "0.982", "size": "166"}, {"price": "0.98", "size": "59.99"}, {"price": "0.979", "size": "46.39"}], "event_type": "book", "last_trade_price": "0.063"}, {"market": "0xcc25bf2f9c735a18c35969e330c0d917eec97fb93ea9422a0a0ed2b3f0eada54", "asset_id": "41699891447566493678062566391348854695286848129234610508637427753139123056608", "timestamp": "1769384010184", "hash": "d3e060855cbacd2df07779d6dc76f6084512a8d8", "bids": [{"price": "0.01", "size": "3010.46"}, {"price": "0.02", "size": "2950"}, {"price": "0.03", "size": "7.24"}, {"price": "0.04", "size": "450"}, {"price": "0.05", "size": "30"}, {"price": "0.06", "size": "200"}, {"price": "0.07", "size": "9.68"}, {"price": "0.11", "size": "550"}, {"price": "0.17", "size": "400"}, {"price": "0.19", "size": "77"}, {"price": "0.21", "size": "50"}, {"price": "0.23", "size": "150"}, {"price": "0.28", "size": "150"}, {"price": "0.4", "size": "100"}, {"price": "0.45", "size": "20"}, {"price": "0.46", "size": "28.26"}, {"price": "0.5", "size": "123.61"}, {"price": "0.51", "size": "66.66"}, {"price": "0.52", "size": "199.99"}, {"price": "0.56", "size": "91.66"}, {"price": "0.62", "size": "66.66"}, {"price": "0.63", "size": "30"}, {"price": "0.64", "size": "30"}, {"price": "0.65", "size": "8.5"}], "asks": [{"price": "0.99", "size": "13.93"}, {"price": "0.98", "size": "250"}, {"price": "0.97", "size": "1328"}, {"price": "0.96", "size": "153.55"}, {"price": "0.95", "size": "680"}, {"price": "0.93", "size": "457.14"}, {"price": "0.91", "size": "311.11"}, {"price": "0.9", "size": "105.98"}, {"price": "0.89", "size": "236.36"}, {"price": "0.88", "size": "616"}, {"price": "0.87", "size": "616"}, {"price": "0.86", "size": "142.85"}, {"price": "0.85", "size": "8"}, {"price": "0.84", "size": "97.84"}, {"price": "0.83", "size": "242"}, {"price": "0.82", "size": "31.81"}, {"price": "0.8", "size": "55"}, {"price": "0.79", "size": "26"}, {"price": "0.78", "size": "181.9"}, {"price": "0.77", "size": "68.95"}, {"price": "0.75", "size": "6"}, {"price": "0.73", "size": "52"}, {"price": "0.72", "size": "18"}, {"price": "0.69", "size": "31.81"}], "event_type": "book", "last_trade_price": "0.330"}, {"market": "0x29fcb3cb3301dde656aaaf7d185bb56c9b6948968b9d95f87f3942355b6bf360", "asset_id": "92691123413763856836301118436801979285373127205354327950605601494440683568501", "timestamp": "1769383925856", "hash": "591231afde8d9a203191554a89aab44b8a6e84c2", "bids": [{"price": "0.001", "size": "3887.11"}, {"price": "0.002", "size": "1257.69"}, {"price": "0.003", "size": "1166"}, {"price": "0.004", "size": "15.19"}, {"price": "0.006", "size": "83"}, {"price": "0.01", "size": "3000"}, {"price": "0.011", "size": "6.34"}, {"price": "0.02", "size": "1400"}, {"price": "0.032", "size": "8.73"}, {"price": "0.033", "size": "12"}, {"price": "0.05", "size": "30"}, {"price": "0.051", "size": "39"}, {"price": "0.052", "size": "8"}, {"price": "0.1", "size": "660"}, {"price": "0.101", "size": "7"}, {"price": "0.102", "size": "5.82"}, {"price": "0.15", "size": "451.66"}, {"price": "0.151", "size": "6"}, {"price": "0.19", "size": "318.42"}, {"price": "0.191", "size": "7"}, {"price": "0.24", "size": "266.66"}, {"price": "0.241", "size": "7"}, {"price": "0.29", "size": "97.65"}, {"price": "0.291", "size": "200"}, {"price": "0.292", "size": "39.12"}, {"price": "0.293", "size": "8"}, {"price": "0.34", "size": "70.58"}, {"price": "0.341", "size": "8"}, {"price": "0.39", "size": "51.28"}, {"price": "0.391", "size": "66.47"}, {"price": "0.393", "size": "33"}, {"price": "0.394", "size": "9"}, {"price": "0.624", "size": "100"}, {"price": "0.625", "size": "40"}, {"price": "0.626", "size": "19"}, {"price": "0.627", "size": "13.4"}, {"price": "0.861", "size": "20"}, {"price": "0.947", "size": "7.64"}, {"price": "0.95", "size": "48"}, {"price": "0.955", "size": "8.93"}], "asks": [{"price": "0.999", "size": "28173.99"}, {"price": "0.998", "size": "3441.02"}, {"price": "0.997", "size": "127.52"}, {"price": "0.996", "size": "98"}, {"price": "0.995", "size": "79.24"}, {"price": "0.983", "size": "20"}, {"price": "0.982", "size": "9.51"}, {"price": "0.98", "size": "500"}, {"price": "0.979", "size": "433.66"}], "event_type": "book", "last_trade_price": "0.045"}, {"market": "0xf487886d421ef02ec6b1d9545ac23b1d1186fd7e9cc1131f7a940e2b88c77254", "asset_id": "108625585990345450370600586761911493642226239230661931449761915709706711737069", "timestamp": "1769383885716", "hash": "c9f762c81222429fb2e7299bef21f3370ebbc5c2", "bids": [{"price": "0.001", "size": "7024"}, {"price": "0.002", "size": "123.13"}, {"price": "0.01", "size": "872"}, {"price": "0.011", "size": "455"}, {"price": "0.013", "size": "113"}, {"price": "0.014", "size": "5.63"}, {"price": "0.02", "size": "239.32"}, {"price": "0.021", "size": "36"}], "asks": [{"price": "0.999", "size": "6569.36"}, {"price": "0.998", "size": "5.09"}, {"price": "0.997", "size": "1000"}, {"price": "0.996", "size": "21.52"}, {"price": "0.99", "size": "3000"}, {"price": "0.98", "size": "1400"}, {"price": "0.979", "size": "15.07"}, {"price": "0.95", "size": "30"}, {"price": "0.94", "size": "33"}, {"price": "0.9", "size": "660"}, {"price": "0.899", "size": "5.76"}, {"price": "0.85", "size": "451.66"}, {"price": "0.81", "size": "318.42"}, {"price": "0.76", "size": "266.66"}, {"price": "0.759", "size": "100"}, {"price": "0.73", "size": "50"}, {"price": "0.71", "size": "89.65"}, {"price": "0.709", "size": "8"}, {"price": "0.66", "size": "70.58"}, {"price": "0.659", "size": "35"}, {"price": "0.658", "size": "8"}, {"price": "0.61", "size": "51.28"}, {"price": "0.609", "size": "9"}, {"price": "0.415", "size": "100"}, {"price": "0.414", "size": "34.13"}, {"price": "0.413", "size": "23.85"}, {"price": "0.412", "size": "12.13"}, {"price": "0.09", "size": "5.39"}, {"price": "0.08", "size": "7.71"}, {"price": "0.072", "size": "12.96"}, {"price": "0.071", "size": "22.05"}], "event_type": "book", "last_trade_price": "0.070"}, {"market": "0x918793929e71481f12f5e6c4b3ad7361995bfdbeab1b85af5fc4ecfff531d9d1", "asset_id": "7423169052544528825731765453022968140891867685105274004608537078132007089554", "timestamp": "1769383904497", "hash": "41c1b193004755bbeb85d1d1b3cd475fd193ee0d", "bids": [{"price": "0.01", "size": "80"}, {"price": "0.02", "size": "3271.93"}, {"price": "0.03", "size": "258.53"}, {"price": "0.04", "size": "750"}, {"price": "0.05", "size": "229.3"}, {"price": "0.06", "size": "229.26"}, {"price": "0.07", "size": "158.66"}, {"price": "0.08", "size": "66.66"}], "asks": [{"price": "0.99", "size": "3356.57"}, {"price": "0.98", "size": "1400"}, {"price": "0.97", "size": "9.27"}, {"price": "0.95", "size": "30"}, {"price": "0.94", "size": "66"}, {"price": "0.91", "size": "900"}, {"price": "0.9", "size": "6.21"}, {"price": "0.87", "size": "10"}, {"price": "0.86", "size": "902.85"}, {"price": "0.81", "size": "568.42"}, {"price": "0.77", "size": "671.73"}, {"price": "0.72", "size": "192.85"}, {"price": "0.67", "size": "72.72"}, {"price": "0.63", "size": "179.05"}, {"price": "0.62", "size": "5"}, {"price": "0.48", "size": "30"}, {"price": "0.17", "size": "150"}, {"price": "0.15", "size": "1020"}, {"price": "0.14", "size": "71.93"}, {"price": "0.11", "size": "71.93"}, {"price": "0.1", "size": "45.84"}, {"price": "0.09", "size": "137.45"}], "event_type": "book", "last_trade_price": "0.910"}, {"market": "0x918793929e71481f12f5e6c4b3ad7361995bfdbeab1b85af5fc4ecfff531d9d1", "asset_id": "92053064463962583320527973844244970612550294266784653309985020480987419053712", "timestamp": "1769383904497", "hash": "68905e8c0bb7af8925f72df84bc8dd5da8816f56", "bids": [{"price": "0.01", "size": "3356.57"}, {"price": "0.02", "size": "1400"}, {"price": "0.03", "size": "9.27"}, {"price": "0.05", "size": "30"}, {"price": "0.06", "size": "66"}, {"price": "0.09", "size": "900"}, {"price": "0.1", "size": "6.21"}, {"price": "0.13", "size": "10"}, {"price": "0.14", "size": "902.85"}, {"price": "0.19", "size": "568.42"}, {"price": "0.23", "size": "671.73"}, {"price": "0.28", "size": "192.85"}, {"price": "0.33", "size": "72.72"}, {"price": "0.37", "size": "179.05"}, {"price": "0.38", "size": "5"}, {"price": "0.52", "size": "30"}, {"price": "0.83", "size": "150"}, {"price": "0.85", "size": "1020"}, {"price": "0.86", "size": "71.93"}, {"price": "0.89", "size": "71.93"}, {"price": "0.9", "size": "45.84"}, {"price": "0.91", "size": "137.45"}], "asks": [{"price": "0.99", "size": "80"}, {"price": "0.98", "size": "3271.93"}, {"price": "0.97", "size": "258.53"}, {"price": "0.96", "size": "750"}, {"price": "0.95", "size": "229.3"}, {"price": "0.94", "size": "229.26"}, {"price": "0.93", "size": "158.66"}, {"price": "0.92", "size": "66.66"}], "event_type": "book", "last_trade_price": "0.910"}, {"market": "0x12d1b41c90a2ff07173ab2469aad97fb9e80f781b36c32f99fbf4ae28a28b42a", "asset_id": "22835304185425644675451740820217338241663141495608098477495460677942947224804", "timestamp": "1769383913968", "hash": "8f6ee9068de04325df6da3bf00d24069135ddbcb", "bids": [{"price": "0.01", "size": "3310.2"}, {"price": "0.02", "size": "2950"}, {"price": "0.03", "size": "10.58"}, {"price": "0.04", "size": "50"}, {"price": "0.05", "size": "970"}, {"price": "0.07", "size": "685.71"}, {"price": "0.09", "size": "355.55"}, {"price": "0.1", "size": "5.79"}, {"price": "0.12", "size": "783.33"}, {"price": "0.14", "size": "185.71"}, {"price": "0.16", "size": "150"}, {"price": "0.18", "size": "2822.97"}, {"price": "0.19", "size": "349.86"}, {"price": "0.2", "size": "1020"}, {"price": "0.21", "size": "9"}, {"price": "0.3", "size": "56.04"}, {"price": "0.31", "size": "50"}, {"price": "0.32", "size": "50"}, {"price": "0.34", "size": "299.87"}, {"price": "0.35", "size": "30.01"}, {"price": "0.36", "size": "420.11"}, {"price": "0.37", "size": "167.72"}, {"price": "0.4", "size": "100"}, {"price": "0.41", "size": "264"}, {"price": "0.42", "size": "100"}, {"price": "0.43", "size": "31"}, {"price": "0.44", "size": "20"}], "asks": [{"price": "0.99", "size": "3005.53"}, {"price": "0.98", "size": "2255.11"}, {"price": "0.97", "size": "5700"}, {"price": "0.96", "size": "507.06"}, {"price": "0.95", "size": "35"}, {"price": "0.94", "size": "1300"}, {"price": "0.91", "size": "377.77"}, {"price": "0.9", "size": "5.6"}, {"price": "0.88", "size": "266.66"}, {"price": "0.86", "size": "200"}, {"price": "0.85", "size": "1321.44"}, {"price": "0.84", "size": "968.14"}, {"price": "0.83", "size": "152.94"}, {"price": "0.8", "size": "270"}, {"price": "0.77", "size": "86.95"}, {"price": "0.75", "size": "1600"}, {"price": "0.74", "size": "918.13"}, {"price": "0.7", "size": "21.03"}, {"price": "0.64", "size": "9"}, {"price": "0.6", "size": "1000"}, {"price": "0.59", "size": "50"}, {"price": "0.55", "size": "200"}, {"price": "0.54", "size": "300"}, {"price": "0.53", "size": "1200"}, {"price": "0.52", "size": "227.08"}, {"price": "0.51", "size": "282.44"}, {"price": "0.5", "size": "2450"}, {"price": "0.49", "size": "519.92"}, {"price": "0.48", "size": "246"}, {"price": "0.47", "size": "1121.71"}, {"price": "0.46", "size": "156.85"}], "event_type": "book", "last_trade_price": "0.540"}, {"market": "0xf487886d421ef02ec6b1d9545ac23b1d1186fd7e9cc1131f7a940e2b88c77254", "asset_id": "32299964279291975502088934125199181742042967532787071650763696447515971539636", "timestamp": "1769383885716", "hash": "faaf8e9d30f4e57c6996f82b9317d878ae5230c8", "bids": [{"price": "0.001", "size": "6569.36"}, {"price": "0.002", "size": "5.09"}, {"price": "0.003", "size": "1000"}, {"price": "0.004", "size": "21.52"}, {"price": "0.01", "size": "3000"}, {"price": "0.02", "size": "1400"}, {"price": "0.021", "size": "15.07"}, {"price": "0.05", "size": "30"}, {"price": "0.06", "size": "33"}, {"price": "0.1", "size": "660"}, {"price": "0.101", "size": "5.76"}, {"price": "0.15", "size": "451.66"}, {"price": "0.19", "size": "318.42"}, {"price": "0.24", "size": "266.66"}, {"price": "0.241", "size": "100"}, {"price": "0.27", "size": "50"}, {"price": "0.29", "size": "89.65"}, {"price": "0.291", "size": "8"}, {"price": "0.34", "size": "70.58"}, {"price": "0.341", "size": "35"}, {"price": "0.342", "size": "8"}, {"price": "0.39", "size": "51.28"}, {"price": "0.391", "size": "9"}, {"price": "0.585", "size": "100"}, {"price": "0.586", "size": "34.13"}, {"price": "0.587", "size": "23.85"}, {"price": "0.588", "size": "12.13"}, {"price": "0.91", "size": "5.39"}, {"price": "0.92", "size": "7.71"}, {"price": "0.928", "size": "12.96"}, {"price": "0.929", "size": "22.05"}], "asks": [{"price": "0.999", "size": "7024"}, {"price": "0.998", "size": "123.13"}, {"price": "0.99", "size": "872"}, {"price": "0.989", "size": "455"}, {"price": "0.987", "size": "113"}, {"price": "0.986", "size": "5.63"}, {"price": "0.98", "size": "239.32"}, {"price": "0.979", "size": "36"}], "event_type": "book", "last_trade_price": "0.070"}, {"market": "0xcc25bf2f9c735a18c35969e330c0d917eec97fb93ea9422a0a0ed2b3f0eada54", "asset_id": "65578135623666125364690190525767126679774364994694102050152165807381694053320", "timestamp": "1769384010184", "hash": "3cc5324c93ac4745ff26e3dc580cca63164455e2", "bids": [{"price": "0.01", "size": "13.93"}, {"price": "0.02", "size": "250"}, {"price": "0.03", "size": "1328"}, {"price": "0.04", "size": "153.55"}, {"price": "0.05", "size": "680"}, {"price": "0.07", "size": "457.14"}, {"price": "0.09", "size": "311.11"}, {"price": "0.1", "size": "105.98"}, {"price": "0.11", "size": "236.36"}, {"price": "0.12", "size": "616"}, {"price": "0.13", "size": "616"}, {"price": "0.14", "size": "142.85"}, {"price": "0.15", "size": "8"}, {"price": "0.16", "size": "97.84"}, {"price": "0.17", "size": "242"}, {"price": "0.18", "size": "31.81"}, {"price": "0.2", "size": "55"}, {"price": "0.21", "size": "26"}, {"price": "0.22", "size": "181.9"}, {"price": "0.23", "size": "68.95"}, {"price": "0.25", "size": "6"}, {"price": "0.27", "size": "52"}, {"price": "0.28", "size": "18"}, {"price": "0.31", "size": "31.81"}], "asks": [{"price": "0.99", "size": "3010.46"}, {"price": "0.98", "size": "2950"}, {"price": "0.97", "size": "7.24"}, {"price": "0.96", "size": "450"}, {"price": "0.95", "size": "30"}, {"price": "0.94", "size": "200"}, {"price": "0.93", "size": "9.68"}, {"price": "0.89", "size": "550"}, {"price": "0.83", "size": "400"}, {"price": "0.81", "size": "77"}, {"price": "0.79", "size": "50"}, {"price": "0.77", "size": "150"}, {"price": "0.72", "size": "150"}, {"price": "0.6", "size": "100"}, {"price": "0.55", "size": "20"}, {"price": "0.54", "size": "28.26"}, {"price": "0.5", "size": "123.61"}, {"price": "0.49", "size": "66.66"}, {"price": "0.48", "size": "199.99"}, {"price": "0.44", "size": "91.66"}, {"price": "0.38", "size": "66.66"}, {"price": "0.37", "size": "30"}, {"price": "0.36", "size": "30"}, {"price": "0.35", "size": "8.5"}], "event_type": "book", "last_trade_price": "0.330"}, {"market": "0x8d9b74d39735dd0b76542c31b81b9544c3eb954060b3c5790d24957538638145", "asset_id": "587316473157103098403959848063967316493748298547115564222712976431944570953", "timestamp": "1769384011104", "hash": "1dd66478a84b270e7a2fae437dc27f06692693cf", "bids": [{"price": "0.001", "size": "5291.08"}, {"price": "0.002", "size": "1255.05"}, {"price": "0.003", "size": "1000"}, {"price": "0.004", "size": "20.48"}, {"price": "0.01", "size": "3262.54"}, {"price": "0.02", "size": "1000"}, {"price": "0.021", "size": "14.48"}, {"price": "0.05", "size": "2480"}, {"price": "0.051", "size": "39"}, {"price": "0.052", "size": "19"}, {"price": "0.1", "size": "560"}, {"price": "0.101", "size": "5.92"}, {"price": "0.15", "size": "1026.66"}, {"price": "0.2", "size": "610"}, {"price": "0.25", "size": "212"}, {"price": "0.3", "size": "586.66"}, {"price": "0.301", "size": "6"}, {"price": "0.35", "size": "68.57"}, {"price": "0.4", "size": "175"}, {"price": "0.5", "size": "300"}, {"price": "0.51", "size": "57.5"}, {"price": "0.52", "size": "71.11"}, {"price": "0.57", "size": "57.5"}, {"price": "0.6", "size": "250"}, {"price": "0.61", "size": "15"}, {"price": "0.63", "size": "205"}, {"price": "0.79", "size": "25"}, {"price": "0.8", "size": "946.86"}, {"price": "0.951", "size": "300"}, {"price": "0.962", "size": "97.19"}, {"price": "0.98", "size": "2300"}, {"price": "0.981", "size": "90.04"}, {"price": "0.983", "size": "100"}], "asks": [{"price": "0.999", "size": "19639.99"}, {"price": "0.998", "size": "701.18"}, {"price": "0.997", "size": "50"}, {"price": "0.996", "size": "4500"}, {"price": "0.995", "size": "1013.86"}, {"price": "0.994", "size": "313.33"}, {"price": "0.993", "size": "22.29"}, {"price": "0.992", "size": "9.07"}, {"price": "0.991", "size": "28.89"}, {"price": "0.99", "size": "87.1"}, {"price": "0.989", "size": "48.41"}, {"price": "0.988", "size": "16.85"}, {"price": "0.987", "size": "500"}, {"price": "0.986", "size": "1585.92"}, {"price": "0.985", "size": "303"}], "event_type": "book", "last_trade_price": "0.013"}, {"market": "0xfdd952522d15cd0d4be8f340c5a249f0b25bb5e92716437002037e899d65195f", "asset_id": "100684009992995172968426231771405309069841941067041831232587523024554691306802", "timestamp": "1769383982723", "hash": "6057d25a280a045213f8fa75eb990fbed1f78932", "bids": [{"price": "0.001", "size": "4804.12"}, {"price": "0.002", "size": "1250"}, {"price": "0.003", "size": "1172.65"}, {"price": "0.006", "size": "83"}, {"price": "0.007", "size": "9.54"}, {"price": "0.01", "size": "3000"}, {"price": "0.02", "size": "1400"}, {"price": "0.021", "size": "14.47"}, {"price": "0.05", "size": "30"}, {"price": "0.051", "size": "39"}, {"price": "0.1", "size": "860"}, {"price": "0.101", "size": "5.93"}, {"price": "0.15", "size": "776.66"}, {"price": "0.2", "size": "610"}, {"price": "0.25", "size": "362"}, {"price": "0.251", "size": "131"}, {"price": "0.3", "size": "186.66"}, {"price": "0.35", "size": "68.57"}, {"price": "0.4", "size": "175"}, {"price": "0.401", "size": "5"}, {"price": "0.9", "size": "50"}, {"price": "0.979", "size": "37.4"}, {"price": "0.985", "size": "598.96"}, {"price": "0.986", "size": "335.5"}], "asks": [{"price": "0.999", "size": "26465.99"}, {"price": "0.998", "size": "2182.09"}, {"price": "0.997", "size": "370"}, {"price": "0.996", "size": "493.24"}, {"price": "0.995", "size": "60"}, {"price": "0.994", "size": "20"}, {"price": "0.993", "size": "38.37"}, {"price": "0.991", "size": "393.45"}], "event_type": "book", "last_trade_price": "0.007"}, {"market": "0x43aad651177544538b5b35dc3239d1631fca344147c0ffe0e416cd0eb51fca6d", "asset_id": "63034252779590173880584393179377300106700707654931663433396190240990856358223", "timestamp": "1769383946460", "hash": "68338580b17303836a6bf98ecbab8d179dd28bc5", "bids": [{"price": "0.01", "size": "3049.9"}, {"price": "0.02", "size": "1400"}, {"price": "0.03", "size": "10.2"}, {"price": "0.05", "size": "30"}, {"price": "0.06", "size": "33"}, {"price": "0.1", "size": "860"}, {"price": "0.11", "size": "5.41"}, {"price": "0.14", "size": "792.85"}, {"price": "0.19", "size": "568.42"}, {"price": "0.24", "size": "416.66"}, {"price": "0.25", "size": "100"}, {"price": "0.29", "size": "139.65"}, {"price": "0.31", "size": "264"}, {"price": "0.34", "size": "70.58"}, {"price": "0.38", "size": "52.63"}, {"price": "0.39", "size": "225"}, {"price": "0.4", "size": "5"}, {"price": "0.65", "size": "100"}, {"price": "0.75", "size": "200"}, {"price": "0.81", "size": "100"}, {"price": "0.82", "size": "94.44"}, {"price": "0.83", "size": "23.68"}, {"price": "0.86", "size": "36"}, {"price": "0.9", "size": "15.73"}, {"price": "0.91", "size": "20"}], "asks": [{"price": "0.99", "size": "2580"}, {"price": "0.98", "size": "1512.07"}, {"price": "0.97", "size": "428.79"}, {"price": "0.96", "size": "179.87"}, {"price": "0.95", "size": "33.09"}], "event_type": "book", "last_trade_price": "0.100"}, {"market": "0xc954c52447b5856106b45c55df1003b48a583af3b4772bda1de20e0a95ad5f45", "asset_id": "9302610255531462617274536528837506482521823261381921527179585793339878975949", "timestamp": "1769383980564", "hash": "664995d6fe604277821f437741e37bb3f2d9535a", "bids": [{"price": "0.001", "size": "17011.17"}, {"price": "0.002", "size": "4347"}, {"price": "0.003", "size": "1684.02"}, {"price": "0.004", "size": "25.39"}, {"price": "0.005", "size": "28"}, {"price": "0.006", "size": "8.09"}, {"price": "0.007", "size": "13.78"}, {"price": "0.008", "size": "77.26"}, {"price": "0.009", "size": "36.66"}, {"price": "0.012", "size": "27.09"}, {"price": "0.018", "size": "166"}, {"price": "0.02", "size": "59.99"}, {"price": "0.021", "size": "46.39"}], "asks": [{"price": "0.999", "size": "3891.13"}, {"price": "0.998", "size": "1250"}, {"price": "0.997", "size": "1172.66"}, {"price": "0.994", "size": "83"}, {"price": "0.993", "size": "9.55"}, {"price": "0.99", "size": "3000"}, {"price": "0.98", "size": "1400"}, {"price": "0.979", "size": "14.47"}, {"price": "0.95", "size": "30"}, {"price": "0.949", "size": "39"}, {"price": "0.9", "size": "860"}, {"price": "0.899", "size": "5.93"}, {"price": "0.85", "size": "776.66"}, {"price": "0.8", "size": "610"}, {"price": "0.75", "size": "362"}, {"price": "0.749", "size": "156"}, {"price": "0.748", "size": "5.27"}, {"price": "0.7", "size": "186.66"}, {"price": "0.699", "size": "8"}, {"price": "0.66", "size": "70.58"}, {"price": "0.659", "size": "8"}, {"price": "0.61", "size": "110.28"}, {"price": "0.608", "size": "146.66"}, {"price": "0.607", "size": "9"}, {"price": "0.332", "size": "66.66"}, {"price": "0.331", "size": "16"}, {"price": "0.099", "size": "101.84"}, {"price": "0.098", "size": "180"}, {"price": "0.097", "size": "52"}, {"price": "0.066", "size": "5.97"}, {"price": "0.064", "size": "48.38"}, {"price": "0.056", "size": "15"}, {"price": "0.053", "size": "66.66"}, {"price": "0.052", "size": "50"}], "event_type": "book", "last_trade_price": "0.063"}, {"market": "0x8d9b74d39735dd0b76542c31b81b9544c3eb954060b3c5790d24957538638145", "asset_id": "66829232893940327662461037379134988031891083237936281380951338917389315110298", "timestamp": "1769384011104", "hash": "25a19df65614d7fdfaca6cbc3e93d67d7d6fce7e", "bids": [{"price": "0.001", "size": "19639.99"}, {"price": "0.002", "size": "701.18"}, {"price": "0.003", "size": "50"}, {"price": "0.004", "size": "4500"}, {"price": "0.005", "size": "1013.86"}, {"price": "0.006", "size": "313.33"}, {"price": "0.007", "size": "22.29"}, {"price": "0.008", "size": "9.07"}, {"price": "0.009", "size": "28.89"}, {"price": "0.01", "size": "87.1"}, {"price": "0.011", "size": "48.41"}, {"price": "0.012", "size": "16.85"}, {"price": "0.013", "size": "500"}, {"price": "0.014", "size": "1585.92"}, {"price": "0.015", "size": "303"}], "asks": [{"price": "0.999", "size": "5291.08"}, {"price": "0.998", "size": "1255.05"}, {"price": "0.997", "size": "1000"}, {"price": "0.996", "size": "20.48"}, {"price": "0.99", "size": "3262.54"}, {"price": "0.98", "size": "1000"}, {"price": "0.979", "size": "14.48"}, {"price": "0.95", "size": "2480"}, {"price": "0.949", "size": "39"}, {"price": "0.948", "size": "19"}, {"price": "0.9", "size": "560"}, {"price": "0.899", "size": "5.92"}, {"price": "0.85", "size": "1026.66"}, {"price": "0.8", "size": "610"}, {"price": "0.75", "size": "212"}, {"price": "0.7", "size": "586.66"}, {"price": "0.699", "size": "6"}, {"price": "0.65", "size": "68.57"}, {"price": "0.6", "size": "175"}, {"price": "0.5", "size": "300"}, {"price": "0.49", "size": "57.5"}, {"price": "0.48", "size": "71.11"}, {"price": "0.43", "size": "57.5"}, {"price": "0.4", "size": "250"}, {"price": "0.39", "size": "15"}, {"price": "0.37", "size": "205"}, {"price": "0.21", "size": "25"}, {"price": "0.2", "size": "946.86"}, {"price": "0.049", "size": "300"}, {"price": "0.038", "size": "97.19"}, {"price": "0.02", "size": "2300"}, {"price": "0.019", "size": "90.04"}, {"price": "0.017", "size": "100"}], "event_type": "book", "last_trade_price": "0.013"}, {"market": "0x5abe3287197d0a924707ce99130643c92751c209fc0e376c6700d6673b43ada5", "asset_id": "15631821676887099899145118278843400257602269360221049118391374890586669885976", "timestamp": "1769383954172", "hash": "8d3c28f1806b02899d68dc3d34ef9f5edfb0d2b7", "bids": [{"price": "0.01", "size": "17.51"}, {"price": "0.02", "size": "1255"}, {"price": "0.03", "size": "250"}, {"price": "0.04", "size": "257.48"}, {"price": "0.05", "size": "410"}, {"price": "0.06", "size": "703.3"}, {"price": "0.07", "size": "143"}, {"price": "0.08", "size": "6.57"}, {"price": "0.09", "size": "61.11"}, {"price": "0.1", "size": "130"}, {"price": "0.11", "size": "1046"}, {"price": "0.14", "size": "531.66"}, {"price": "0.16", "size": "52"}, {"price": "0.17", "size": "133"}], "asks": [{"price": "0.99", "size": "3077.13"}, {"price": "0.98", "size": "1400"}, {"price": "0.97", "size": "9.36"}, {"price": "0.92", "size": "950"}, {"price": "0.91", "size": "6.86"}, {"price": "0.87", "size": "811.53"}, {"price": "0.83", "size": "588.23"}, {"price": "0.79", "size": "383.33"}, {"price": "0.78", "size": "216"}, {"price": "0.74", "size": "150"}, {"price": "0.73", "size": "50"}, {"price": "0.7", "size": "80"}, {"price": "0.69", "size": "50"}, {"price": "0.66", "size": "133.82"}, {"price": "0.65", "size": "100"}, {"price": "0.64", "size": "299.99"}, {"price": "0.62", "size": "5"}, {"price": "0.45", "size": "23.63"}, {"price": "0.44", "size": "119.64"}, {"price": "0.43", "size": "30"}, {"price": "0.42", "size": "30"}, {"price": "0.39", "size": "113"}, {"price": "0.26", "size": "20"}, {"price": "0.25", "size": "50"}, {"price": "0.24", "size": "13.62"}], "event_type": "book", "last_trade_price": "0.240"}, {"market": "0xfdd952522d15cd0d4be8f340c5a249f0b25bb5e92716437002037e899d65195f", "asset_id": "71439979369081433769877908436626697830533226033387852251824796378263454719432", "timestamp": "1769383982723", "hash": "2b501fd81db40d42439fd0aaf1527acee582e451", "bids": [{"price": "0.001", "size": "26465.99"}, {"price": "0.002", "size": "2182.09"}, {"price": "0.003", "size": "370"}, {"price": "0.004", "size": "493.24"}, {"price": "0.005", "size": "60"}, {"price": "0.006", "size": "20"}, {"price": "0.007", "size": "38.37"}, {"price": "0.009", "size": "393.45"}], "asks": [{"price": "0.999", "size": "4804.12"}, {"price": "0.998", "size": "1250"}, {"price": "0.997", "size": "1172.65"}, {"price": "0.994", "size": "83"}, {"price": "0.993", "size": "9.54"}, {"price": "0.99", "size": "3000"}, {"price": "0.98", "size": "1400"}, {"price": "0.979", "size": "14.47"}, {"price": "0.95", "size": "30"}, {"price": "0.949", "size": "39"}, {"price": "0.9", "size": "860"}, {"price": "0.899", "size": "5.93"}, {"price": "0.85", "size": "776.66"}, {"price": "0.8", "size": "610"}, {"price": "0.75", "size": "362"}, {"price": "0.749", "size": "131"}, {"price": "0.7", "size": "186.66"}, {"price": "0.65", "size": "68.57"}, {"price": "0.6", "size": "175"}, {"price": "0.599", "size": "5"}, {"price": "0.1", "size": "50"}, {"price": "0.021", "size": "37.4"}, {"price": "0.015", "size": "598.96"}, {"price": "0.014", "size": "335.5"}], "event_type": "book", "last_trade_price": "0.007"}]}
{"_local_timestamp": "2026-01-25T23:33:32.649140+00:00", "data": {"market": "0x8d9b74d39735dd0b76542c31b81b9544c3eb954060b3c5790d24957538638145", "price_changes": [{"asset_id": "66829232893940327662461037379134988031891083237936281380951338917389315110298", "price": "0.015", "size": "0", "side": "BUY", "hash": "5ad205bb2bcd5271e862ff398f9dc473e52a0945", "best_bid": "0.014", "best_ask": "0.017"}, {"asset_id": "587316473157103098403959848063967316493748298547115564222712976431944570953", "price": "0.985", "size": "0", "side": "SELL", "hash": "bde81a1a1c183bb70db00eae8fa8aaa36cc53cd7", "best_bid": "0.983", "best_ask": "0.986"}], "timestamp": "1769384012577", "event_type": "price_change"}}
{"_local_timestamp": "2026-01-25T23:33:32.675633+00:00", "data": {"market": "0x8d9b74d39735dd0b76542c31b81b9544c3eb954060b3c5790d24957538638145", "price_changes": [{"asset_id": "66829232893940327662461037379134988031891083237936281380951338917389315110298", "price": "0.015", "size": "303", "side": "BUY", "hash": "f57c4d8885ebfd9b12ea357b363ae7ad99b714f5", "best_bid": "0.015", "best_ask": "0.017"}, {"asset_id": "587316473157103098403959848063967316493748298547115564222712976431944570953", "price": "0.985", "size": "303", "side": "SELL", "hash": "a5c456d89782cde874cb40d8a569fe8740f1f5d9", "best_bid": "0.983", "best_ask": "0.985"}], "timestamp": "1769384012605", "event_type": "price_change"}}
{"_local_timestamp": "2026-01-25T23:33:33.360291+00:00", "data": {"market": "0xc954c52447b5856106b45c55df1003b48a583af3b4772bda1de20e0a95ad5f45", "price_changes": [{"asset_id": "52417019033358898530053799473085644762541010045525203660683879224996320434909", "price": "0.39", "size": "60.28", "side": "BUY", "hash": "8fa038bd5428ffe40c0c72671a9618b871d46585", "best_bid": "0.948", "best_ask": "0.979"}, {"asset_id": "9302610255531462617274536528837506482521823261381921527179585793339878975949", "price": "0.61", "size": "60.28", "side": "SELL", "hash": "56e96cc2de72126d2febb49d23078561607ffe84", "best_bid": "0.021", "best_ask": "0.052"}], "timestamp": "1769384013156", "event_type": "price_change"}}
{"_local_timestamp": "2026-01-25T23:33:33.360740+00:00", "data": {"market": "0x5abe3287197d0a924707ce99130643c92751c209fc0e376c6700d6673b43ada5", "price_changes": [{"asset_id": "2791138143012434753446657502011224259420532252815498101697790519791539429743", "price": "0.27", "size": "0", "side": "BUY", "hash": "4ab5090138d1cd1e4a6eadf9f9fb21cb868e8361", "best_bid": "0.76", "best_ask": "0.83"}, {"asset_id": "15631821676887099899145118278843400257602269360221049118391374890586669885976", "price": "0.73", "size": "0", "side": "SELL", "hash": "907ff22d4a20b5e93ea27c6081ca05b7e220a408", "best_bid": "0.17", "best_ask": "0.24"}], "timestamp": "1769384013155", "event_type": "price_change"}}
{"_local_timestamp": "2026-01-25T23:33:33.364010+00:00", "data": {"market": "0xcc25bf2f9c735a18c35969e330c0d917eec97fb93ea9422a0a0ed2b3f0eada54", "price_changes": [{"asset_id": "41699891447566493678062566391348854695286848129234610508637427753139123056608", "price": "0.21", "size": "0", "side": "BUY", "hash": "dc4dfc492f6ba3818892a2d6e4bcc13ca915353f", "best_bid": "0.65", "best_ask": "0.69"}, {"asset_id": "65578135623666125364690190525767126679774364994694102050152165807381694053320", "price": "0.79", "size": "0", "side": "SELL", "hash": "19de6b2d5d8911570f7a97ce069ba384bf57f569", "best_bid": "0.31", "best_ask": "0.35"}], "timestamp": "1769384013155", "event_type": "price_change"}}
{"_local_timestamp": "2026-01-25T23:33:33.473305+00:00", "data": {"market": "0x5abe3287197d0a924707ce99130643c92751c209fc0e376c6700d6673b43ada5", "price_changes": [{"asset_id": "15631821676887099899145118278843400257602269360221049118391374890586669885976", "price": "0.39", "size": "0", "side": "SELL", "hash": "f8af6c26cccae33665ed8c337fb6a5814f77423f", "best_bid": "0.17", "best_ask": "0.24"}, {"asset_id": "2791138143012434753446657502011224259420532252815498101697790519791539429743", "price": "0.61", "size": "0", "side": "BUY", "hash": "d20e3711ed92caeef1ca5f856c44f261e0f19e90", "best_bid": "0.76", "best_ask": "0.83"}], "timestamp": "1769384013319", "event_type": "price_change"}}
{"_local_timestamp": "2026-01-25T23:33:33.485479+00:00", "data": {"market": "0x5abe3287197d0a924707ce99130643c92751c209fc0e376c6700d6673b43ada5", "price_changes": [{"asset_id": "15631821676887099899145118278843400257602269360221049118391374890586669885976", "price": "0.42", "size": "146", "side": "SELL", "hash": "208e96147eb10f166bdd88c412b2f83e6526c49c", "best_bid": "0.17", "best_ask": "0.24"}, {"asset_id": "2791138143012434753446657502011224259420532252815498101697790519791539429743", "price": "0.58", "size": "146", "side": "BUY", "hash": "de83c1b683fb0dc0c4c28e2ccdd90eda85bdf744", "best_bid": "0.76", "best_ask": "0.83"}], "timestamp": "1769384013345", "event_type": "price_change"}}
{"_local_timestamp": "2026-01-25T23:33:33.642728+00:00", "data": {"market": "0x5abe3287197d0a924707ce99130643c92751c209fc0e376c6700d6673b43ada5", "price_changes": [{"asset_id": "2791138143012434753446657502011224259420532252815498101697790519791539429743", "price": "0.31", "size": "100", "side": "BUY", "hash": "bb183c1d05f97ff4688d2844f0f63118f9fb7416", "best_bid": "0.76", "best_ask": "0.83"}, {"asset_id": "15631821676887099899145118278843400257602269360221049118391374890586669885976", "price": "0.69", "size": "100", "side": "SELL", "hash": "2a4afde871c8df3e6a69a19bd3b230a29f2447c1", "best_bid": "0.17", "best_ask": "0.24"}], "timestamp": "1769384013547", "event_type": "price_change"}}
{"_local_timestamp": "2026-01-25T23:33:33.722718+00:00", "data": {"market": "0xc954c52447b5856106b45c55df1003b48a583af3b4772bda1de20e0a95ad5f45", "price_changes": [{"asset_id": "52417019033358898530053799473085644762541010045525203660683879224996320434909", "price": "0.392", "size": "196.66", "side": "BUY", "hash": "b2f8b8dad317b1a2d7cde30afcf4ea3c51319d4b", "best_bid": "0.948", "best_ask": "0.979"}, {"asset_id": "9302610255531462617274536528837506482521823261381921527179585793339878975949", "price": "0.608", "size": "196.66", "side": "SELL", "hash": "e6077fe675313134ae341712dd71adc8016aa38e", "best_bid": "0.021", "best_ask": "0.052"}], "timestamp": "1769384013558", "event_type": "price_change"}}
{"_local_timestamp": "2026-01-25T23:33:33.733815+00:00", "data": {"market": "0x5abe3287197d0a924707ce99130643c92751c209fc0e376c6700d6673b43ada5", "price_changes": [{"asset_id": "2791138143012434753446657502011224259420532252815498101697790519791539429743", "price": "0.34", "size": "183.82", "side": "BUY", "hash": "3e8d4a338b80329e5fbe3ea2da3d6b120b90120f", "best_bid": "0.76", "best_ask": "0.83"}, {"asset_id": "15631821676887099899145118278843400257602269360221049118391374890586669885976", "price": "0.66", "size": "183.82", "side": "SELL", "hash": "eb8af8459c1952f8903013fcfbb641dbde404c74", "best_bid": "0.17", "best_ask": "0.24"}], "timestamp": "1769384013558", "event_type": "price_change"}}
{"_local_timestamp": "2026-01-25T23:33:34.153725+00:00", "data": {"market": "0x8d9b74d39735dd0b76542c31b81b9544c3eb954060b3c5790d24957538638145", "price_changes": [{"asset_id": "66829232893940327662461037379134988031891083237936281380951338917389315110298", "price": "0.015", "size": "0", "side": "BUY", "hash": "83c55b4d7aefa643f40a6b2f45e42bb9210de3cf", "best_bid": "0.014", "best_ask": "0.017"}, {"asset_id": "587316473157103098403959848063967316493748298547115564222712976431944570953", "price": "0.985", "size": "0", "side": "SELL", "hash": "b12923814af79d82b38a4f1496dd38afe4b0b239", "best_bid": "0.983", "best_ask": "0.986"}], "timestamp": "1769384014084", "event_type": "price_change"}}
{"_local_timestamp": "2026-01-25T23:33:34.180768+00:00", "data": {"market": "0x8d9b74d39735dd0b76542c31b81b9544c3eb954060b3c5790d24957538638145", "price_changes": [{"asset_id": "66829232893940327662461037379134988031891083237936281380951338917389315110298", "price": "0.015", "size": "303", "side": "BUY", "hash": "0d84d349cca965e6c8947f297f9980cde83414f6", "best_bid": "0.015", "best_ask": "0.017"}, {"asset_id": "587316473157103098403959848063967316493748298547115564222712976431944570953", "price": "0.985", "size": "303", "side": "SELL", "hash": "589d087d99900ce87d5dc34a5934deffe33f8dfb", "best_bid": "0.983", "best_ask": "0.985"}], "timestamp": "1769384014111", "event_type": "price_change"}}
{"_local_timestamp": "2026-01-25T23:33:35.423616+00:00", "data": {"market": "0x5abe3287197d0a924707ce99130643c92751c209fc0e376c6700d6673b43ada5", "price_changes": [{"asset_id": "15631821676887099899145118278843400257602269360221049118391374890586669885976", "price": "0.64", "size": "100", "side": "SELL", "hash": "94935286d83e3fbfe51679924f37b33079ccfe58", "best_bid": "0.17", "best_ask": "0.24"}, {"asset_id": "2791138143012434753446657502011224259420532252815498101697790519791539429743", "price": "0.36", "size": "100", "side": "BUY", "hash": "0d770066a25c9ccc5e4809782f0710ebd074f101", "best_bid": "0.76", "best_ask": "0.83"}], "timestamp": "1769384015347", "event_type": "price_change"}}
{"_local_timestamp": "2026-01-25T23:33:35.659221+00:00", "data": {"market": "0x5abe3287197d0a924707ce99130643c92751c209fc0e376c6700d6673b43ada5", "price_changes": [{"asset_id": "2791138143012434753446657502011224259420532252815498101697790519791539429743", "price": "0.36", "size": "0", "side": "BUY", "hash": "ea2dd14dd14efbf072e986ddcc0dde8105f6f105", "best_bid": "0.76", "best_ask": "0.83"}, {"asset_id": "15631821676887099899145118278843400257602269360221049118391374890586669885976", "price": "0.64", "size": "0", "side": "SELL", "hash": "ac3761de51f491a15280229dc2af84cfb6214801", "best_bid": "0.17", "best_ask": "0.24"}], "timestamp": "1769384015567", "event_type": "price_change"}}
{"_local_timestamp": "2026-01-25T23:33:35.659821+00:00", "data": {"market": "0x8d9b74d39735dd0b76542c31b81b9544c3eb954060b3c5790d24957538638145", "price_changes": [{"asset_id": "66829232893940327662461037379134988031891083237936281380951338917389315110298", "price": "0.015", "size": "0", "side": "BUY", "hash": "8ee469f75a9192e7734e0061a66e07027be1eb91", "best_bid": "0.014", "best_ask": "0.017"}, {"asset_id": "587316473157103098403959848063967316493748298547115564222712976431944570953", "price": "0.985", "size": "0", "side": "SELL", "hash": "b6ad4a922134ad7e6a3caaddf6a7c00c17a7b92f", "best_bid": "0.983", "best_ask": "0.986"}], "timestamp": "1769384015580", "event_type": "price_change"}}
{"_local_timestamp": "2026-01-25T23:33:35.678914+00:00", "data": {"market": "0x8d9b74d39735dd0b76542c31b81b9544c3eb954060b3c5790d24957538638145", "price_changes": [{"asset_id": "66829232893940327662461037379134988031891083237936281380951338917389315110298", "price": "0.015", "size": "303", "side": "BUY", "hash": "d5cd7617d9f909f98dc04edd660813b3188411aa", "best_bid": "0.015", "best_ask": "0.017"}, {"asset_id": "587316473157103098403959848063967316493748298547115564222712976431944570953", "price": "0.985", "size": "303", "side": "SELL", "hash": "779cf514819420ed7829eae6ec830521fc8c95e8", "best_bid": "0.983", "best_ask": "0.985"}], "timestamp": "1769384015606", "event_type": "price_change"}}
{"_local_timestamp": "2026-01-25T23:33:35.803071+00:00", "data": {"market": "0x5abe3287197d0a924707ce99130643c92751c209fc0e376c6700d6673b43ada5", "price_changes": [{"asset_id": "15631821676887099899145118278843400257602269360221049118391374890586669885976", "price": "0.41", "size": "199.99", "side": "SELL", "hash": "701167ad994fcec3eb4bbcf6d12e86c24b976b16", "best_bid": "0.17", "best_ask": "0.24"}, {"asset_id": "2791138143012434753446657502011224259420532252815498101697790519791539429743", "price": "0.59", "size": "199.99", "side": "BUY", "hash": "ef5fd5c50d4ab32bd10cf4159715fabc6017e62d", "best_bid": "0.76", "best_ask": "0.83"}], "timestamp": "1769384015728", "event_type": "price_change"}}
{"_local_timestamp": "2026-01-25T23:33:35.823838+00:00", "data": {"market": "0x5abe3287197d0a924707ce99130643c92751c209fc0e376c6700d6673b43ada5", "price_changes": [{"asset_id": "15631821676887099899145118278843400257602269360221049118391374890586669885976", "price": "0.42", "size": "30", "side": "SELL", "hash": "c17d58a2e9dc6e1b851186237033d4fec06c0a71", "best_bid": "0.17", "best_ask": "0.24"}, {"asset_id": "2791138143012434753446657502011224259420532252815498101697790519791539429743", "price": "0.58", "size": "30", "side": "BUY", "hash": "d39d2ee56afe16a913adf34f2e21328a95f3b2a9", "best_bid": "0.76", "best_ask": "0.83"}], "timestamp": "1769384015755", "event_type": "price_change"}}
{"_local_timestamp": "2026-01-25T23:33:35.854066+00:00", "data": {"market": "0x5abe3287197d0a924707ce99130643c92751c209fc0e376c6700d6673b43ada5", "price_changes": [{"asset_id": "15631821676887099899145118278843400257602269360221049118391374890586669885976", "price": "0.4", "size": "126", "side": "SELL", "hash": "b7155c260bcd7c5e06874203a409584ab94363a3", "best_bid": "0.17", "best_ask": "0.24"}, {"asset_id": "2791138143012434753446657502011224259420532252815498101697790519791539429743", "price": "0.6", "size": "126", "side": "BUY", "hash": "051be85ff79953a0a6527e5cc51726e2a314fcda", "best_bid": "0.76", "best_ask": "0.83"}], "timestamp": "1769384015781", "event_type": "price_change"}}
{"_local_timestamp": "2026-01-25T23:33:36.419615+00:00", "data": {"market": "0x5abe3287197d0a924707ce99130643c92751c209fc0e376c6700d6673b43ada5", "price_changes": [{"asset_id": "2791138143012434753446657502011224259420532252815498101697790519791539429743", "price": "0.59", "size": "299.99", "side": "BUY", "hash": "dfd4bc639ba7f68df3bd7d18066ea6c5815837a9", "best_bid": "0.76", "best_ask": "0.83"}, {"asset_id": "15631821676887099899145118278843400257602269360221049118391374890586669885976", "price": "0.41", "size": "299.99", "side": "SELL", "hash": "54e0ddd2aa44e8f657f21e6da483ff2ce19a8a86", "best_bid": "0.17", "best_ask": "0.24"}], "timestamp": "1769384016345", "event_type": "price_change"}}
{"_local_timestamp": "2026-01-25T23:33:37.152257+00:00", "data": {"market": "0x8d9b74d39735dd0b76542c31b81b9544c3eb954060b3c5790d24957538638145", "price_changes": [{"asset_id": "66829232893940327662461037379134988031891083237936281380951338917389315110298", "price": "0.015", "size": "0", "side": "BUY", "hash": "f58da19468376efcff8fbda0782ee26b5c2b0a52", "best_bid": "0.014", "best_ask": "0.017"}, {"asset_id": "587316473157103098403959848063967316493748298547115564222712976431944570953", "price": "0.985", "size": "0", "side": "SELL", "hash": "7ad2a74cbbeb0b5cee468717fa01c535473b4ea2", "best_bid": "0.983", "best_ask": "0.986"}], "timestamp": "1769384017077", "event_type": "price_change"}}
{"_local_timestamp": "2026-01-25T23:33:37.176872+00:00", "data": {"market": "0x8d9b74d39735dd0b76542c31b81b9544c3eb954060b3c5790d24957538638145", "price_changes": [{"asset_id": "66829232893940327662461037379134988031891083237936281380951338917389315110298", "price": "0.015", "size": "303", "side": "BUY", "hash": "e8feb5c3a8e0542be5cb1be16af87028d839dddc", "best_bid": "0.015", "best_ask": "0.017"}, {"asset_id": "587316473157103098403959848063967316493748298547115564222712976431944570953", "price": "0.985", "size": "303", "side": "SELL", "hash": "321498142879a434d8e36be05dc54872df4a8105", "best_bid": "0.983", "best_ask": "0.985"}], "timestamp": "1769384017107", "event_type": "price_change"}}
{"_local_timestamp": "2026-01-25T23:33:38.180201+00:00", "data": {"market": "0xcc25bf2f9c735a18c35969e330c0d917eec97fb93ea9422a0a0ed2b3f0eada54", "price_changes": [{"asset_id": "41699891447566493678062566391348854695286848129234610508637427753139123056608", "price": "0.77", "size": "50", "side": "SELL", "hash": "4777e9f3c35275b3fda3c73c5e5d522b5197a8b5", "best_bid": "0.65", "best_ask": "0.69"}, {"asset_id": "65578135623666125364690190525767126679774364994694102050152165807381694053320", "price": "0.23", "size": "50", "side": "BUY", "hash": "f1f4db6b82bd142ea80ef9481bbc211166530680", "best_bid": "0.31", "best_ask": "0.35"}], "timestamp": "1769384018105", "event_type": "price_change"}}
{"_local_timestamp": "2026-01-25T23:33:38.194183+00:00", "data": {"market": "0xf487886d421ef02ec6b1d9545ac23b1d1186fd7e9cc1131f7a940e2b88c77254", "price_changes": [{"asset_id": "108625585990345450370600586761911493642226239230661931449761915709706711737069", "price": "0.413", "size": "18", "side": "SELL", "hash": "39d9a9ca0c93bcc05859f30629ac94031d290e2f", "best_bid": "0.021", "best_ask": "0.071"}, {"asset_id": "32299964279291975502088934125199181742042967532787071650763696447515971539636", "price": "0.587", "size": "18", "side": "BUY", "hash": "f70f5e5ae5b9cf94b34f9f564c0b13efb59f95f1", "best_bid": "0.929", "best_ask": "0.979"}], "timestamp": "1769384018106", "event_type": "price_change"}}
{"_local_timestamp": "2026-01-25T23:33:38.661364+00:00", "data": {"market": "0x8d9b74d39735dd0b76542c31b81b9544c3eb954060b3c5790d24957538638145", "price_changes": [{"asset_id": "66829232893940327662461037379134988031891083237936281380951338917389315110298", "price": "0.015", "size": "0", "side": "BUY", "hash": "a57e75aaeea627db59f1a756c7ff1d73d4a20d12", "best_bid": "0.014", "best_ask": "0.017"}, {"asset_id": "587316473157103098403959848063967316493748298547115564222712976431944570953", "price": "0.985", "size": "0", "side": "SELL", "hash": "cc295eec9602c7a91791c14733db21eab63410de", "best_bid": "0.983", "best_ask": "0.986"}], "timestamp": "1769384018582", "event_type": "price_change"}}
{"_local_timestamp": "2026-01-25T23:33:38.689198+00:00", "data": {"market": "0x8d9b74d39735dd0b76542c31b81b9544c3eb954060b3c5790d24957538638145", "price_changes": [{"asset_id": "66829232893940327662461037379134988031891083237936281380951338917389315110298", "price": "0.015", "size": "303", "side": "BUY", "hash": "423c0a54590397c99e26287311512da8b7be4381", "best_bid": "0.015", "best_ask": "0.017"}, {"asset_id": "587316473157103098403959848063967316493748298547115564222712976431944570953", "price": "0.985", "size": "303", "side": "SELL", "hash": "132520eed503f9f8271624082c65d3a1fbc72556", "best_bid": "0.983", "best_ask": "0.985"}], "timestamp": "1769384018609", "event_type": "price_change"}}
{"_local_timestamp": "2026-01-25T23:33:39.415573+00:00", "data": {"market": "0x5abe3287197d0a924707ce99130643c92751c209fc0e376c6700d6673b43ada5", "price_changes": [{"asset_id": "2791138143012434753446657502011224259420532252815498101697790519791539429743", "price": "0.61", "size": "30", "side": "BUY", "hash": "805709241ff14629fb4803294b9a53f077dd9126", "best_bid": "0.76", "best_ask": "0.83"}, {"asset_id": "15631821676887099899145118278843400257602269360221049118391374890586669885976", "price": "0.39", "size": "30", "side": "SELL", "hash": "8573c092db90d2cda3f3f19e489de1dc6ba4da4c", "best_bid": "0.17", "best_ask": "0.24"}], "timestamp": "1769384019340", "event_type": "price_change"}}
{"_local_timestamp": "2026-01-25T23:33:39.438018+00:00", "data": {"market": "0x5abe3287197d0a924707ce99130643c92751c209fc0e376c6700d6673b43ada5", "price_changes": [{"asset_id": "15631821676887099899145118278843400257602269360221049118391374890586669885976", "price": "0.17", "size": "20", "side": "BUY", "hash": "83fc81b43fc852bb571886780606101450652121", "best_bid": "0.17", "best_ask": "0.24"}, {"asset_id": "2791138143012434753446657502011224259420532252815498101697790519791539429743", "price": "0.83", "size": "20", "side": "SELL", "hash": "802c4a8beca2516ee7dbbed8debfe887e96a9d7c", "best_bid": "0.76", "best_ask": "0.83"}], "timestamp": "1769384019367", "event_type": "price_change"}}
{"_local_timestamp": "2026-01-25T23:33:39.443556+00:00", "data": {"market": "0x5abe3287197d0a924707ce99130643c92751c209fc0e376c6700d6673b43ada5", "price_changes": [{"asset_id": "15631821676887099899145118278843400257602269360221049118391374890586669885976", "price": "0.4", "size": "0", "side": "SELL", "hash": "83fc81b43fc852bb571886780606101450652121", "best_bid": "0.17", "best_ask": "0.24"}, {"asset_id": "2791138143012434753446657502011224259420532252815498101697790519791539429743", "price": "0.6", "size": "0", "side": "BUY", "hash": "802c4a8beca2516ee7dbbed8debfe887e96a9d7c", "best_bid": "0.76", "best_ask": "0.83"}], "timestamp": "1769384019367", "event_type": "price_change"}}
{"_local_timestamp": "2026-01-25T23:33:39.462617+00:00", "data": {"market": "0x5abe3287197d0a924707ce99130643c92751c209fc0e376c6700d6673b43ada5", "price_changes": [{"asset_id": "15631821676887099899145118278843400257602269360221049118391374890586669885976", "price": "0.15", "size": "86", "side": "BUY", "hash": "0c7edf489ee981a6f6b6cdb03b81228e6ed2738f", "best_bid": "0.17", "best_ask": "0.24"}, {"asset_id": "2791138143012434753446657502011224259420532252815498101697790519791539429743", "price": "0.85", "size": "86", "side": "SELL", "hash": "b20db9b527fdb0b0f64ba93d7bbe3414ab9cac93", "best_bid": "0.76", "best_ask": "0.83"}], "timestamp": "1769384019392", "event_type": "price_change"}}
{"_local_timestamp": "2026-01-25T23:33:39.464915+00:00", "data": {"market": "0x5abe3287197d0a924707ce99130643c92751c209fc0e376c6700d6673b43ada5", "price_changes": [{"asset_id": "15631821676887099899145118278843400257602269360221049118391374890586669885976", "price": "0.38", "size": "118", "side": "SELL", "hash": "a46dbb36ede4fa758dfdbf730f82c48e3e0c3f13", "best_bid": "0.17", "best_ask": "0.24"}, {"asset_id": "2791138143012434753446657502011224259420532252815498101697790519791539429743", "price": "0.62", "size": "118", "side": "BUY", "hash": "ff822e039e7a4e7f987aa5fb8d5d9c7184b49a19", "best_bid": "0.76", "best_ask": "0.83"}], "timestamp": "1769384019393", "event_type": "price_change"}}
{"_local_timestamp": "2026-01-25T23:33:39.710474+00:00", "data": {"market": "0x5abe3287197d0a924707ce99130643c92751c209fc0e376c6700d6673b43ada5", "price_changes": [{"asset_id": "15631821676887099899145118278843400257602269360221049118391374890586669885976", "price": "0.41", "size": "100", "side": "SELL", "hash": "625551f2de0c5180c7d8d418af642742a4c41f67", "best_bid": "0.17", "best_ask": "0.24"}, {"asset_id": "2791138143012434753446657502011224259420532252815498101697790519791539429743", "price": "0.59", "size": "100", "side": "BUY", "hash": "bd0de0068dc9773dc702a0fecf9980b7d0f73e3b", "best_bid": "0.76", "best_ask": "0.83"}], "timestamp": "1769384019639", "event_type": "price_change"}}
{"_local_timestamp": "2026-01-25T23:33:39.747070+00:00", "data": {"market": "0x5abe3287197d0a924707ce99130643c92751c209fc0e376c6700d6673b43ada5", "price_changes": [{"asset_id": "2791138143012434753446657502011224259420532252815498101697790519791539429743", "price": "0.58", "size": "0", "side": "BUY", "hash": "3162b82eb38d66e8c44c112a667a85ab2f687400", "best_bid": "0.76", "best_ask": "0.83"}, {"asset_id": "15631821676887099899145118278843400257602269360221049118391374890586669885976", "price": "0.42", "size": "0", "side": "SELL", "hash": "d6274cc919b3bc7f590023ef0230fa95d7022224", "best_bid": "0.17", "best_ask": "0.24"}], "timestamp": "1769384019672", "event_type": "price_change"}}
{"_local_timestamp": "2026-01-25T23:33:40.068871+00:00", "data": {"market": "0x5abe3287197d0a924707ce99130643c92751c209fc0e376c6700d6673b43ada5", "price_changes": [{"asset_id": "15631821676887099899145118278843400257602269360221049118391374890586669885976", "price": "0.64", "size": "199.99", "side": "SELL", "hash": "3231a1cf4228b9ce96f91cd51eb78572a5de2b60", "best_bid": "0.17", "best_ask": "0.24"}, {"asset_id": "2791138143012434753446657502011224259420532252815498101697790519791539429743", "price": "0.36", "size": "199.99", "side": "BUY", "hash": "1f315842c9ea1deb33b3da5d4f60382447b9981a", "best_bid": "0.76", "best_ask": "0.83"}], "timestamp": "1769384019996", "event_type": "price_change"}}
{"_local_timestamp": "2026-01-25T23:33:40.128250+00:00", "data": {"market": "0x5abe3287197d0a924707ce99130643c92751c209fc0e376c6700d6673b43ada5", "price_changes": [{"asset_id": "2791138143012434753446657502011224259420532252815498101697790519791539429743", "price": "0.59", "size": "0", "side": "BUY", "hash": "d58643dbe78689b5260e8aca36bcc05375315160", "best_bid": "0.76", "best_ask": "0.83"}, {"asset_id": "15631821676887099899145118278843400257602269360221049118391374890586669885976", "price": "0.41", "size": "0", "side": "SELL", "hash": "c8d6618beeb36de58f8c5e5767ad9844b1b45da7", "best_bid": "0.17", "best_ask": "0.24"}], "timestamp": "1769384020031", "event_type": "price_change"}}
{"_local_timestamp": "2026-01-25T23:33:40.160880+00:00", "data": {"market": "0x8d9b74d39735dd0b76542c31b81b9544c3eb954060b3c5790d24957538638145", "price_changes": [{"asset_id": "66829232893940327662461037379134988031891083237936281380951338917389315110298", "price": "0.015", "size": "0", "side": "BUY", "hash": "d612dcff863b1c988650c7dea1ef93a9056b49f3", "best_bid": "0.014", "best_ask": "0.017"}, {"asset_id": "587316473157103098403959848063967316493748298547115564222712976431944570953", "price": "0.985", "size": "0", "side": "SELL", "hash": "fe5eba3eef6f43471a2f6f83f9d9ad42062e758f", "best_bid": "0.983", "best_ask": "0.986"}], "timestamp": "1769384020077", "event_type": "price_change"}}
{"_local_timestamp": "2026-01-25T23:33:40.194120+00:00", "data": {"market": "0xcc25bf2f9c735a18c35969e330c0d917eec97fb93ea9422a0a0ed2b3f0eada54", "price_changes": [{"asset_id": "41699891447566493678062566391348854695286848129234610508637427753139123056608", "price": "0.23", "size": "100", "side": "BUY", "hash": "cb76b188814b14b073d721ce4e533bc41a0292bf", "best_bid": "0.65", "best_ask": "0.69"}, {"asset_id": "65578135623666125364690190525767126679774364994694102050152165807381694053320", "price": "0.77", "size": "100", "side": "SELL", "hash": "38935067820b6834d9e27661ad96208976153f44", "best_bid": "0.31", "best_ask": "0.35"}], "timestamp": "1769384020085", "event_type": "price_change"}}
{"_local_timestamp": "2026-01-25T23:33:40.195040+00:00", "data": {"market": "0x5abe3287197d0a924707ce99130643c92751c209fc0e376c6700d6673b43ada5", "price_changes": [{"asset_id": "2791138143012434753446657502011224259420532252815498101697790519791539429743", "price": "0.31", "size": "50", "side": "BUY", "hash": "4827ff97680129cc4b948168289d27a829e7d7d4", "best_bid": "0.76", "best_ask": "0.83"}, {"asset_id": "15631821676887099899145118278843400257602269360221049118391374890586669885976", "price": "0.69", "size": "50", "side": "SELL", "hash": "421215599daa305bab71939bc260f7e252e6a041", "best_bid": "0.17", "best_ask": "0.24"}], "timestamp": "1769384020085", "event_type": "price_change"}}
{"_local_timestamp": "2026-01-25T23:33:40.367274+00:00", "data": {"market": "0x8d9b74d39735dd0b76542c31b81b9544c3eb954060b3c5790d24957538638145", "price_changes": [{"asset_id": "66829232893940327662461037379134988031891083237936281380951338917389315110298", "price": "0.015", "size": "303", "side": "BUY", "hash": "598383af17ec2c563f7ae06fffd111fa2efffe67", "best_bid": "0.015", "best_ask": "0.017"}, {"asset_id": "587316473157103098403959848063967316493748298547115564222712976431944570953", "price": "0.985", "size": "303", "side": "SELL", "hash": "331b50c15266c4f630c4ba97789df262fb1034e0", "best_bid": "0.983", "best_ask": "0.985"}], "timestamp": "1769384020111", "event_type": "price_change"}}
{"_local_timestamp": "2026-01-25T23:33:40.811551+00:00", "data": {"market": "0x5abe3287197d0a924707ce99130643c92751c209fc0e376c6700d6673b43ada5", "price_changes": [{"asset_id": "2791138143012434753446657502011224259420532252815498101697790519791539429743", "price": "0.35", "size": "150", "side": "BUY", "hash": "4a1344a753de6aae3f48a29f46f09859ad10f75c", "best_bid": "0.76", "best_ask": "0.83"}, {"asset_id": "15631821676887099899145118278843400257602269360221049118391374890586669885976", "price": "0.65", "size": "150", "side": "SELL", "hash": "5f693a4f3053cb09fa6dc3a4365d41adc0c71ad4", "best_bid": "0.17", "best_ask": "0.24"}], "timestamp": "1769384020561", "event_type": "price_change"}}
{"_local_timestamp": "2026-01-25T23:33:40.905395+00:00", "data": {"market": "0x5abe3287197d0a924707ce99130643c92751c209fc0e376c6700d6673b43ada5", "price_changes": [{"asset_id": "15631821676887099899145118278843400257602269360221049118391374890586669885976", "price": "0.15", "size": "0", "side": "BUY", "hash": "4070a2d02a3faf90712b93252994302683828a77", "best_bid": "0.17", "best_ask": "0.24"}, {"asset_id": "2791138143012434753446657502011224259420532252815498101697790519791539429743", "price": "0.85", "size": "0", "side": "SELL", "hash": "77eb9cca5337c322a49d7ccf9573fbda3348aea2", "best_bid": "0.76", "best_ask": "0.83"}], "timestamp": "1769384020765", "event_type": "price_change"}}
{"_local_timestamp": "2026-01-25T23:33:40.918550+00:00", "data": {"market": "0x5abe3287197d0a924707ce99130643c92751c209fc0e376c6700d6673b43ada5", "price_changes": [{"asset_id": "15631821676887099899145118278843400257602269360221049118391374890586669885976", "price": "0.17", "size": "136", "side": "BUY", "hash": "9978b71dcd6adbe6cda33b7e4d27bfd7286d7841", "best_bid": "0.17", "best_ask": "0.24"}, {"asset_id": "2791138143012434753446657502011224259420532252815498101697790519791539429743", "price": "0.83", "size": "136", "side": "SELL", "hash": "f01bc3e5a458d7aac1769e740da89d0b55ca8f5b", "best_bid": "0.76", "best_ask": "0.83"}], "timestamp": "1769384020794", "event_type": "price_change"}}
{"_local_timestamp": "2026-01-25T23:33:40.936435+00:00", "data": {"market": "0x5abe3287197d0a924707ce99130643c92751c209fc0e376c6700d6673b43ada5", "price_changes": [{"asset_id": "2791138143012434753446657502011224259420532252815498101697790519791539429743", "price": "0.36", "size": "299.99", "side": "BUY", "hash": "d013b2572899e6f165865651aeec5ae016a53826", "best_bid": "0.76", "best_ask": "0.83"}, {"asset_id": "15631821676887099899145118278843400257602269360221049118391374890586669885976", "price": "0.64", "size": "299.99", "side": "SELL", "hash": "e3b6b8da86bc55750de1a99059547f8bf6ce51a4", "best_bid": "0.17", "best_ask": "0.24"}], "timestamp": "1769384020848", "event_type": "price_change"}}
{"_local_timestamp": "2026-01-25T23:33:41.497015+00:00", "data": {"market": "0x12d1b41c90a2ff07173ab2469aad97fb9e80f781b36c32f99fbf4ae28a28b42a", "price_changes": [{"asset_id": "22835304185425644675451740820217338241663141495608098477495460677942947224804", "price": "0.64", "size": "0", "side": "SELL", "hash": "f4f52fe32a0f4908c898bcd092168559c3d9e7e2", "best_bid": "0.44", "best_ask": "0.46"}, {"asset_id": "36737124956681902477833012015613017711780279541938574794261768841905170092613", "price": "0.36", "size": "0", "side": "BUY", "hash": "dee521c5f8bff1cd762d8326660e47e4f60b15a8", "best_bid": "0.54", "best_ask": "0.56"}], "timestamp": "1769384021424", "event_type": "price_change"}}
{"_local_timestamp": "2026-01-25T23:33:41.530709+00:00", "data": {"market": "0x12d1b41c90a2ff07173ab2469aad97fb9e80f781b36c32f99fbf4ae28a28b42a", "price_changes": [{"asset_id": "36737124956681902477833012015613017711780279541938574794261768841905170092613", "price": "0.52", "size": "200", "side": "BUY", "hash": "6fce48f245d4c9af5a9090c8ce8d5727a8436dc9", "best_bid": "0.54", "best_ask": "0.56"}, {"asset_id": "22835304185425644675451740820217338241663141495608098477495460677942947224804", "price": "0.48", "size": "200", "side": "SELL", "hash": "ce25187b7f45fd536c3fc26c50f9e18629f3c483", "best_bid": "0.44", "best_ask": "0.46"}], "timestamp": "1769384021451", "event_type": "price_change"}}
{"_local_timestamp": "2026-01-25T23:33:41.570894+00:00", "data": {"market": "0x12d1b41c90a2ff07173ab2469aad97fb9e80f781b36c32f99fbf4ae28a28b42a", "price_changes": [{"asset_id": "36737124956681902477833012015613017711780279541938574794261768841905170092613", "price": "0.54", "size": "199.85", "side": "BUY", "hash": "ba49c0390fd5794c8084bfaa63de71322489aff6", "best_bid": "0.54", "best_ask": "0.56"}, {"asset_id": "22835304185425644675451740820217338241663141495608098477495460677942947224804", "price": "0.46", "size": "199.85", "side": "SELL", "hash": "f9c5866a7e49252f0cf54108b1595b3e93c78224", "best_bid": "0.44", "best_ask": "0.46"}], "timestamp": "1769384021489", "event_type": "price_change"}}
{"_local_timestamp": "2026-01-25T23:33:41.660575+00:00", "data": {"market": "0x8d9b74d39735dd0b76542c31b81b9544c3eb954060b3c5790d24957538638145", "price_changes": [{"asset_id": "66829232893940327662461037379134988031891083237936281380951338917389315110298", "price": "0.015", "size": "0", "side": "BUY", "hash": "bfe88309b617e2e6a4f62043e74967ca38544598", "best_bid": "0.014", "best_ask": "0.017"}, {"asset_id": "587316473157103098403959848063967316493748298547115564222712976431944570953", "price": "0.985", "size": "0", "side": "SELL", "hash": "de95e740a02f7a79a35f8cfb475f15eb401819bb", "best_bid": "0.983", "best_ask": "0.986"}], "timestamp": "1769384021581", "event_type": "price_change"}}
{"_local_timestamp": "2026-01-25T23:33:41.699658+00:00", "data": {"market": "0x8d9b74d39735dd0b76542c31b81b9544c3eb954060b3c5790d24957538638145", "price_changes": [{"asset_id": "66829232893940327662461037379134988031891083237936281380951338917389315110298", "price": "0.015", "size": "303", "side": "BUY", "hash": "3dc83565e9b4f290d500a4a82ae87af4138de2d0", "best_bid": "0.015", "best_ask": "0.017"}, {"asset_id": "587316473157103098403959848063967316493748298547115564222712976431944570953", "price": "0.985", "size": "303", "side": "SELL", "hash": "c83e8c64d7b35051eaa94d7f894ac0abc959c5ef", "best_bid": "0.983", "best_ask": "0.985"}], "timestamp": "1769384021612", "event_type": "price_change"}}
{"_local_timestamp": "2026-01-25T23:33:43.145226+00:00", "data": {"market": "0x8d9b74d39735dd0b76542c31b81b9544c3eb954060b3c5790d24957538638145", "price_changes": [{"asset_id": "66829232893940327662461037379134988031891083237936281380951338917389315110298", "price": "0.015", "size": "0", "side": "BUY", "hash": "9c755948ccb99ed80494d452abc560c8f6b067d8", "best_bid": "0.014", "best_ask": "0.017"}, {"asset_id": "587316473157103098403959848063967316493748298547115564222712976431944570953", "price": "0.985", "size": "0", "side": "SELL", "hash": "687aed9f81f0debc28ba212aaff74c3364c66c6e", "best_bid": "0.983", "best_ask": "0.986"}], "timestamp": "1769384023076", "event_type": "price_change"}}
{"_local_timestamp": "2026-01-25T23:33:43.175714+00:00", "data": {"market": "0x8d9b74d39735dd0b76542c31b81b9544c3eb954060b3c5790d24957538638145", "price_changes": [{"asset_id": "66829232893940327662461037379134988031891083237936281380951338917389315110298", "price": "0.015", "size": "303", "side": "BUY", "hash": "d1b721f947b5893f630b3d8e867653c068417f9f", "best_bid": "0.015", "best_ask": "0.017"}, {"asset_id": "587316473157103098403959848063967316493748298547115564222712976431944570953", "price": "0.985", "size": "303", "side": "SELL", "hash": "2b90527788b7d07010409ff1baea624d55da10bf", "best_bid": "0.983", "best_ask": "0.985"}], "timestamp": "1769384023105", "event_type": "price_change"}}
{"_local_timestamp": "2026-01-25T23:33:44.650431+00:00", "data": {"market": "0x8d9b74d39735dd0b76542c31b81b9544c3eb954060b3c5790d24957538638145", "price_changes": [{"asset_id": "66829232893940327662461037379134988031891083237936281380951338917389315110298", "price": "0.015", "size": "0", "side": "BUY", "hash": "872a8a3a090104c1386ef12e0eca4933e7edec39", "best_bid": "0.014", "best_ask": "0.017"}, {"asset_id": "587316473157103098403959848063967316493748298547115564222712976431944570953", "price": "0.985", "size": "0", "side": "SELL", "hash": "561a9fa58190ab5c9392878531aa5fce2053bdee", "best_bid": "0.983", "best_ask": "0.986"}], "timestamp": "1769384024583", "event_type": "price_change"}}
{"_local_timestamp": "2026-01-25T23:33:44.693191+00:00", "data": {"market": "0x8d9b74d39735dd0b76542c31b81b9544c3eb954060b3c5790d24957538638145", "price_changes": [{"asset_id": "66829232893940327662461037379134988031891083237936281380951338917389315110298", "price": "0.015", "size": "303", "side": "BUY", "hash": "16fc783402978e2db4d1f52c5b44a6520862aaf6", "best_bid": "0.015", "best_ask": "0.017"}, {"asset_id": "587316473157103098403959848063967316493748298547115564222712976431944570953", "price": "0.985", "size": "303", "side": "SELL", "hash": "4f47a3419e4734a7dfa5b9cf7c6b8372a658749c", "best_bid": "0.983", "best_ask": "0.985"}], "timestamp": "1769384024623", "event_type": "price_change"}}
{"_local_timestamp": "2026-01-25T23:33:44.990510+00:00", "data": {"market": "0xcc25bf2f9c735a18c35969e330c0d917eec97fb93ea9422a0a0ed2b3f0eada54", "price_changes": [{"asset_id": "41699891447566493678062566391348854695286848129234610508637427753139123056608", "price": "0.71", "size": "18.95", "side": "SELL", "hash": "61281a73c9071836c557b6b8d25f4395afa26f16", "best_bid": "0.65", "best_ask": "0.69"}, {"asset_id": "65578135623666125364690190525767126679774364994694102050152165807381694053320", "price": "0.29", "size": "18.95", "side": "BUY", "hash": "f875e19a0302b45ccb4157ca6242d341938c2d14", "best_bid": "0.31", "best_ask": "0.35"}], "timestamp": "1769384024913", "event_type": "price_change"}}
{"_local_timestamp": "2026-01-25T23:33:45.403105+00:00", "data": {"market": "0x5abe3287197d0a924707ce99130643c92751c209fc0e376c6700d6673b43ada5", "price_changes": [{"asset_id": "2791138143012434753446657502011224259420532252815498101697790519791539429743", "price": "0.58", "size": "30", "side": "BUY", "hash": "570c7fb4ca38ae925529861574a5f44030a5be07", "best_bid": "0.76", "best_ask": "0.83"}, {"asset_id": "15631821676887099899145118278843400257602269360221049118391374890586669885976", "price": "0.42", "size": "30", "side": "SELL", "hash": "78f118ca4bacfda7ae44e737b7a088e98f0ce415", "best_bid": "0.17", "best_ask": "0.24"}], "timestamp": "1769384025331", "event_type": "price_change"}}
{"_local_timestamp": "2026-01-25T23:33:45.694489+00:00", "data": {"market": "0x5abe3287197d0a924707ce99130643c92751c209fc0e376c6700d6673b43ada5", "price_changes": [{"asset_id": "2791138143012434753446657502011224259420532252815498101697790519791539429743", "price": "0.61", "size": "0", "side": "BUY", "hash": "9a36a74b6073f77b92ff1a8cbe329763bf7e9125", "best_bid": "0.76", "best_ask": "0.83"}, {"asset_id": "15631821676887099899145118278843400257602269360221049118391374890586669885976", "price": "0.39", "size": "0", "side": "SELL", "hash": "63693916b02f878c7ac4b5d17b85b1326dfb03c6", "best_bid": "0.17", "best_ask": "0.24"}], "timestamp": "1769384025627", "event_type": "price_change"}}
{"_local_timestamp": "2026-01-25T23:33:46.145724+00:00", "data": {"market": "0x8d9b74d39735dd0b76542c31b81b9544c3eb954060b3c5790d24957538638145", "price_changes": [{"asset_id": "66829232893940327662461037379134988031891083237936281380951338917389315110298", "price": "0.015", "size": "0", "side": "BUY", "hash": "2d5fd51bfdf192e1502d431da9246f2a236ba266", "best_bid": "0.014", "best_ask": "0.017"}, {"asset_id": "587316473157103098403959848063967316493748298547115564222712976431944570953", "price": "0.985", "size": "0", "side": "SELL", "hash": "2b61355ba6dde9d96cf17a88afee9f26c01c4d42", "best_bid": "0.983", "best_ask": "0.986"}], "timestamp": "1769384026078", "event_type": "price_change"}}
{"_local_timestamp": "2026-01-25T23:33:46.186125+00:00", "data": {"market": "0x8d9b74d39735dd0b76542c31b81b9544c3eb954060b3c5790d24957538638145", "price_changes": [{"asset_id": "66829232893940327662461037379134988031891083237936281380951338917389315110298", "price": "0.015", "size": "303", "side": "BUY", "hash": "796bccb2bd44a5a1420f44fba2c3878fe4811fe7", "best_bid": "0.015", "best_ask": "0.017"}, {"asset_id": "587316473157103098403959848063967316493748298547115564222712976431944570953", "price": "0.985", "size": "303", "side": "SELL", "hash": "d3a13af2538cba37b9a2b1ef139c9e7c10d4691a", "best_bid": "0.983", "best_ask": "0.985"}], "timestamp": "1769384026119", "event_type": "price_change"}}
{"_local_timestamp": "2026-01-25T23:33:47.646563+00:00", "data": {"market": "0x8d9b74d39735dd0b76542c31b81b9544c3eb954060b3c5790d24957538638145", "price_changes": [{"asset_id": "66829232893940327662461037379134988031891083237936281380951338917389315110298", "price": "0.015", "size": "0", "side": "BUY", "hash": "f67ea087b08ef9f803dbb329be4a42ed31239113", "best_bid": "0.014", "best_ask": "0.017"}, {"asset_id": "587316473157103098403959848063967316493748298547115564222712976431944570953", "price": "0.985", "size": "0", "side": "SELL", "hash": "7f41bb16826f9b0e8e17bcde46f12856a2224ba5", "best_bid": "0.983", "best_ask": "0.986"}], "timestamp": "1769384027577", "event_type": "price_change"}}
{"_local_timestamp": "2026-01-25T23:33:47.678708+00:00", "data": {"market": "0x8d9b74d39735dd0b76542c31b81b9544c3eb954060b3c5790d24957538638145", "price_changes": [{"asset_id": "66829232893940327662461037379134988031891083237936281380951338917389315110298", "price": "0.015", "size": "303", "side": "BUY", "hash": "cee616f45a46d8885d751400dcf1dc4cf241b524", "best_bid": "0.015", "best_ask": "0.017"}, {"asset_id": "587316473157103098403959848063967316493748298547115564222712976431944570953", "price": "0.985", "size": "303", "side": "SELL", "hash": "2067d60729d4f608e1d601d29992fe42219d524c", "best_bid": "0.983", "best_ask": "0.985"}], "timestamp": "1769384027605", "event_type": "price_change"}}
{"_local_timestamp": "2026-01-25T23:33:48.948965+00:00", "data": {"market": "0xf487886d421ef02ec6b1d9545ac23b1d1186fd7e9cc1131f7a940e2b88c77254", "price_changes": [{"asset_id": "108625585990345450370600586761911493642226239230661931449761915709706711737069", "price": "0.413", "size": "23.85", "side": "SELL", "hash": "2a2c085b1be285e9e84d97b1bcd39cc326946a76", "best_bid": "0.021", "best_ask": "0.071"}, {"asset_id": "32299964279291975502088934125199181742042967532787071650763696447515971539636", "price": "0.587", "size": "23.85", "side": "BUY", "hash": "25c78a324c6ae963a99810d8bb32232e592d5709", "best_bid": "0.929", "best_ask": "0.979"}], "timestamp": "1769384028874", "event_type": "price_change"}}
{"_local_timestamp": "2026-01-25T23:33:49.154566+00:00", "data": {"market": "0x8d9b74d39735dd0b76542c31b81b9544c3eb954060b3c5790d24957538638145", "price_changes": [{"asset_id": "66829232893940327662461037379134988031891083237936281380951338917389315110298", "price": "0.015", "size": "0", "side": "BUY", "hash": "f7d6233a3846d8b34a77bc0cb870c17571eb6cdd", "best_bid": "0.014", "best_ask": "0.017"}, {"asset_id": "587316473157103098403959848063967316493748298547115564222712976431944570953", "price": "0.985", "size": "0", "side": "SELL", "hash": "f504ee9e23ebb016ada1e1517d8047a76fdd2f4b", "best_bid": "0.983", "best_ask": "0.986"}], "timestamp": "1769384029075", "event_type": "price_change"}}
{"_local_timestamp": "2026-01-25T23:33:49.188687+00:00", "data": {"market": "0x8d9b74d39735dd0b76542c31b81b9544c3eb954060b3c5790d24957538638145", "price_changes": [{"asset_id": "66829232893940327662461037379134988031891083237936281380951338917389315110298", "price": "0.015", "size": "303", "side": "BUY", "hash": "6c5608237d7bb2bb63e4ba4126b7ab79a4c6a52a", "best_bid": "0.015", "best_ask": "0.017"}, {"asset_id": "587316473157103098403959848063967316493748298547115564222712976431944570953", "price": "0.985", "size": "303", "side": "SELL", "hash": "a1a8a592da2a9ac3d9daf27aafab5ad6bbd6e899", "best_bid": "0.983", "best_ask": "0.985"}], "timestamp": "1769384029121", "event_type": "price_change"}}
{"_local_timestamp": "2026-01-25T23:33:50.671426+00:00", "data": {"market": "0x8d9b74d39735dd0b76542c31b81b9544c3eb954060b3c5790d24957538638145", "price_changes": [{"asset_id": "66829232893940327662461037379134988031891083237936281380951338917389315110298", "price": "0.015", "size": "0", "side": "BUY", "hash": "6323e4fd2d5de5ee375eff447939da228f02bb72", "best_bid": "0.014", "best_ask": "0.017"}, {"asset_id": "587316473157103098403959848063967316493748298547115564222712976431944570953", "price": "0.985", "size": "0", "side": "SELL", "hash": "b86a9f39e7d4bd348694f6c7f8fe2a2968a39e3e", "best_bid": "0.983", "best_ask": "0.986"}], "timestamp": "1769384030576", "event_type": "price_change"}}
{"_local_timestamp": "2026-01-25T23:33:50.693406+00:00", "data": {"market": "0x8d9b74d39735dd0b76542c31b81b9544c3eb954060b3c5790d24957538638145", "price_changes": [{"asset_id": "66829232893940327662461037379134988031891083237936281380951338917389315110298", "price": "0.015", "size": "303", "side": "BUY", "hash": "f3e9b5877f6718966380d4c74360778a2e978978", "best_bid": "0.015", "best_ask": "0.017"}, {"asset_id": "587316473157103098403959848063967316493748298547115564222712976431944570953", "price": "0.985", "size": "303", "side": "SELL", "hash": "1f7a3323da07f168fed710372182ee553e65293d", "best_bid": "0.983", "best_ask": "0.985"}], "timestamp": "1769384030604", "event_type": "price_change"}}
{"_local_timestamp": "2026-01-25T23:33:52.146585+00:00", "data": {"market": "0x8d9b74d39735dd0b76542c31b81b9544c3eb954060b3c5790d24957538638145", "price_changes": [{"asset_id": "66829232893940327662461037379134988031891083237936281380951338917389315110298", "price": "0.015", "size": "0", "side": "BUY", "hash": "3df1fab76f5c44b77ea6c28fc71bda7447cb586a", "best_bid": "0.014", "best_ask": "0.017"}, {"asset_id": "587316473157103098403959848063967316493748298547115564222712976431944570953", "price": "0.985", "size": "0", "side": "SELL", "hash": "fa814650b668c4d730c6ae39bfa825f828c80a24", "best_bid": "0.983", "best_ask": "0.986"}], "timestamp": "1769384032075", "event_type": "price_change"}}
{"_local_timestamp": "2026-01-25T23:33:52.177598+00:00", "data": {"market": "0x8d9b74d39735dd0b76542c31b81b9544c3eb954060b3c5790d24957538638145", "price_changes": [{"asset_id": "66829232893940327662461037379134988031891083237936281380951338917389315110298", "price": "0.015", "size": "303", "side": "BUY", "hash": "3427e59e931a75132b38481534709e3b7eabba5f", "best_bid": "0.015", "best_ask": "0.017"}, {"asset_id": "587316473157103098403959848063967316493748298547115564222712976431944570953", "price": "0.985", "size": "303", "side": "SELL", "hash": "2671174f2e17ffdee4fc1f6b990d787407f9c3e3", "best_bid": "0.983", "best_ask": "0.985"}], "timestamp": "1769384032103", "event_type": "price_change"}}
{"_local_timestamp": "2026-01-25T23:33:53.656709+00:00", "data": {"market": "0x8d9b74d39735dd0b76542c31b81b9544c3eb954060b3c5790d24957538638145", "price_changes": [{"asset_id": "66829232893940327662461037379134988031891083237936281380951338917389315110298", "price": "0.015", "size": "0", "side": "BUY", "hash": "dec6d877d750337cca78dd7830861808d7f2e6fc", "best_bid": "0.014", "best_ask": "0.017"}, {"asset_id": "587316473157103098403959848063967316493748298547115564222712976431944570953", "price": "0.985", "size": "0", "side": "SELL", "hash": "7f7a8140957275c8ef1a2a8191125a0d6ba833a3", "best_bid": "0.983", "best_ask": "0.986"}], "timestamp": "1769384033578", "event_type": "price_change"}}
{"_local_timestamp": "2026-01-25T23:33:53.674419+00:00", "data": {"market": "0x8d9b74d39735dd0b76542c31b81b9544c3eb954060b3c5790d24957538638145", "price_changes": [{"asset_id": "66829232893940327662461037379134988031891083237936281380951338917389315110298", "price": "0.015", "size": "303", "side": "BUY", "hash": "7e21fdc28dec05d77fa669ca43dcaadaa1d20537", "best_bid": "0.015", "best_ask": "0.017"}, {"asset_id": "587316473157103098403959848063967316493748298547115564222712976431944570953", "price": "0.985", "size": "303", "side": "SELL", "hash": "248a3e043b409fb91b367f4686a72d5a4a5a15c6", "best_bid": "0.983", "best_ask": "0.985"}], "timestamp": "1769384033606", "event_type": "price_change"}}
{"_local_timestamp": "2026-01-25T23:33:54.881707+00:00", "data": {"market": "0xc954c52447b5856106b45c55df1003b48a583af3b4772bda1de20e0a95ad5f45", "price_changes": [{"asset_id": "9302610255531462617274536528837506482521823261381921527179585793339878975949", "price": "0.018", "size": "0", "side": "BUY", "hash": "a13f4cafd4bd0f0d068cf033c5064ef003305de0", "best_bid": "0.021", "best_ask": "0.052"}, {"asset_id": "52417019033358898530053799473085644762541010045525203660683879224996320434909", "price": "0.982", "size": "0", "side": "SELL", "hash": "67473ccf7005e000923486df6dedfccbc0afbdaf", "best_bid": "0.948", "best_ask": "0.979"}], "timestamp": "1769384034815", "event_type": "price_change"}}
{"_local_timestamp": "2026-01-25T23:33:54.979661+00:00", "data": {"market": "0xc954c52447b5856106b45c55df1003b48a583af3b4772bda1de20e0a95ad5f45", "price_changes": [{"asset_id": "9302610255531462617274536528837506482521823261381921527179585793339878975949", "price": "0.02", "size": "209.99", "side": "BUY", "hash": "740ea0ad5e0ce430359a61fc89bfa78d61fca2f5", "best_bid": "0.021", "best_ask": "0.052"}, {"asset_id": "52417019033358898530053799473085644762541010045525203660683879224996320434909", "price": "0.98", "size": "209.99", "side": "SELL", "hash": "1a9c6960f25edd18f5994db61d37359e881e57ab", "best_bid": "0.948", "best_ask": "0.979"}], "timestamp": "1769384034908", "event_type": "price_change"}}
{"_local_timestamp": "2026-01-25T23:33:55.149226+00:00", "data": {"market": "0x8d9b74d39735dd0b76542c31b81b9544c3eb954060b3c5790d24957538638145", "price_changes": [{"asset_id": "66829232893940327662461037379134988031891083237936281380951338917389315110298", "price": "0.015", "size": "0", "side": "BUY", "hash": "e93dce5944bfcc94cf68f41ed43384758765ce82", "best_bid": "0.014", "best_ask": "0.017"}, {"asset_id": "587316473157103098403959848063967316493748298547115564222712976431944570953", "price": "0.985", "size": "0", "side": "SELL", "hash": "02c44d0237ddebc92eb6fbcbe832affaa31b8991", "best_bid": "0.983", "best_ask": "0.986"}], "timestamp": "1769384035078", "event_type": "price_change"}}
{"_local_timestamp": "2026-01-25T23:33:55.250966+00:00", "data": {"market": "0x8d9b74d39735dd0b76542c31b81b9544c3eb954060b3c5790d24957538638145", "price_changes": [{"asset_id": "66829232893940327662461037379134988031891083237936281380951338917389315110298", "price": "0.015", "size": "303", "side": "BUY", "hash": "602709bb36f7829c7054e44830a5fe91893b842e", "best_bid": "0.015", "best_ask": "0.017"}, {"asset_id": "587316473157103098403959848063967316493748298547115564222712976431944570953", "price": "0.985", "size": "303", "side": "SELL", "hash": "ebe367d2855d7de6dc135be445447eedd58ec522", "best_bid": "0.983", "best_ask": "0.985"}], "timestamp": "1769384035148", "event_type": "price_change"}}
{"_local_timestamp": "2026-01-25T23:33:56.646174+00:00", "data": {"market": "0x8d9b74d39735dd0b76542c31b81b9544c3eb954060b3c5790d24957538638145", "price_changes": [{"asset_id": "66829232893940327662461037379134988031891083237936281380951338917389315110298", "price": "0.015", "size": "0", "side": "BUY", "hash": "45d7a33412a612d66b21ab96601e43590af32954", "best_bid": "0.014", "best_ask": "0.017"}, {"asset_id": "587316473157103098403959848063967316493748298547115564222712976431944570953", "price": "0.985", "size": "0", "side": "SELL", "hash": "d1e3c3d9e9aad1ac04db3239ccb3365ddc61ded0", "best_bid": "0.983", "best_ask": "0.986"}], "timestamp": "1769384036578", "event_type": "price_change"}}
{"_local_timestamp": "2026-01-25T23:33:56.677508+00:00", "data": {"market": "0x8d9b74d39735dd0b76542c31b81b9544c3eb954060b3c5790d24957538638145", "price_changes": [{"asset_id": "66829232893940327662461037379134988031891083237936281380951338917389315110298", "price": "0.015", "size": "303", "side": "BUY", "hash": "fbe4228cc0d2cb3eeb63e53ee0ca822233e15a36", "best_bid": "0.015", "best_ask": "0.017"}, {"asset_id": "587316473157103098403959848063967316493748298547115564222712976431944570953", "price": "0.985", "size": "303", "side": "SELL", "hash": "faf63630c0b3979649abe327b47d5d6cb1dfc67b", "best_bid": "0.983", "best_ask": "0.985"}], "timestamp": "1769384036609", "event_type": "price_change"}}
{"_local_timestamp": "2026-01-25T23:33:58.159099+00:00", "data": {"market": "0x8d9b74d39735dd0b76542c31b81b9544c3eb954060b3c5790d24957538638145", "price_changes": [{"asset_id": "66829232893940327662461037379134988031891083237936281380951338917389315110298", "price": "0.015", "size": "0", "side": "BUY", "hash": "60ae41f3bdf4042f1a53c0c9229579e23221da68", "best_bid": "0.014", "best_ask": "0.017"}, {"asset_id": "587316473157103098403959848063967316493748298547115564222712976431944570953", "price": "0.985", "size": "0", "side": "SELL", "hash": "7033b0814af282267df6f1ab5a0fbcfd9c9feeb7", "best_bid": "0.983", "best_ask": "0.986"}], "timestamp": "1769384038079", "event_type": "price_change"}}
{"_local_timestamp": "2026-01-25T23:33:58.174121+00:00", "data": {"market": "0x8d9b74d39735dd0b76542c31b81b9544c3eb954060b3c5790d24957538638145", "price_changes": [{"asset_id": "66829232893940327662461037379134988031891083237936281380951338917389315110298", "price": "0.015", "size": "303", "side": "BUY", "hash": "9812985763aed660db6e9037cd4a16994a29126d", "best_bid": "0.015", "best_ask": "0.017"}, {"asset_id": "587316473157103098403959848063967316493748298547115564222712976431944570953", "price": "0.985", "size": "303", "side": "SELL", "hash": "73d2aab3fe7599c917fed87e36ddb46f3416de15", "best_bid": "0.983", "best_ask": "0.985"}], "timestamp": "1769384038105", "event_type": "price_change"}}
{"_local_timestamp": "2026-01-25T23:33:59.655370+00:00", "data": {"market": "0x8d9b74d39735dd0b76542c31b81b9544c3eb954060b3c5790d24957538638145", "price_changes": [{"asset_id": "66829232893940327662461037379134988031891083237936281380951338917389315110298", "price": "0.015", "size": "0", "side": "BUY", "hash": "a45e878aceb255a8e226b0e35cd36b31d20af8b9", "best_bid": "0.014", "best_ask": "0.017"}, {"asset_id": "587316473157103098403959848063967316493748298547115564222712976431944570953", "price": "0.985", "size": "0", "side": "SELL", "hash": "8477fcc06d4395b89f605ea2e7a1b6cb59a919f7", "best_bid": "0.983", "best_ask": "0.986"}], "timestamp": "1769384039579", "event_type": "price_change"}}
{"_local_timestamp": "2026-01-25T23:33:59.676952+00:00", "data": {"market": "0x8d9b74d39735dd0b76542c31b81b9544c3eb954060b3c5790d24957538638145", "price_changes": [{"asset_id": "66829232893940327662461037379134988031891083237936281380951338917389315110298", "price": "0.015", "size": "303", "side": "BUY", "hash": "8e6f26c47f7a0b64dd7b75e1c4ff5c4b9498f334", "best_bid": "0.015", "best_ask": "0.017"}, {"asset_id": "587316473157103098403959848063967316493748298547115564222712976431944570953", "price": "0.985", "size": "303", "side": "SELL", "hash": "4eb9740323b67cddeb3abffd16cdac7e36ca5a22", "best_bid": "0.983", "best_ask": "0.985"}], "timestamp": "1769384039604", "event_type": "price_change"}}
{"_local_timestamp": "2026-01-25T23:34:01.149356+00:00", "data": {"market": "0x8d9b74d39735dd0b76542c31b81b9544c3eb954060b3c5790d24957538638145", "price_changes": [{"asset_id": "66829232893940327662461037379134988031891083237936281380951338917389315110298", "price": "0.015", "size": "0", "side": "BUY", "hash": "443c5338946c17fe57ed30356bd2070a194035da", "best_bid": "0.014", "best_ask": "0.017"}, {"asset_id": "587316473157103098403959848063967316493748298547115564222712976431944570953", "price": "0.985", "size": "0", "side": "SELL", "hash": "e2a9381cc46f53f401a3aa45e899becd628bfa3a", "best_bid": "0.983", "best_ask": "0.986"}], "timestamp": "1769384041077", "event_type": "price_change"}}
{"_local_timestamp": "2026-01-25T23:34:01.174487+00:00", "data": {"market": "0x8d9b74d39735dd0b76542c31b81b9544c3eb954060b3c5790d24957538638145", "price_changes": [{"asset_id": "66829232893940327662461037379134988031891083237936281380951338917389315110298", "price": "0.015", "size": "303", "side": "BUY", "hash": "28c0ea2c807124d654d35ba1b8da6162cd5802e5", "best_bid": "0.015", "best_ask": "0.017"}, {"asset_id": "587316473157103098403959848063967316493748298547115564222712976431944570953", "price": "0.985", "size": "303", "side": "SELL", "hash": "020a481d873f954c4412dde00539df19db5a8260", "best_bid": "0.983", "best_ask": "0.985"}], "timestamp": "1769384041104", "event_type": "price_change"}}
{"_local_timestamp": "2026-01-25T23:34:01.319597+00:00", "data": {"market": "0xf3b4662d12f86894b31d52b454428c91733c166ba05c4e3bccc375f78411601a", "price_changes": [{"asset_id": "55382819090443168507206409119841525953451022223003224583889620760999266943524", "price": "0.02", "size": "0", "side": "BUY", "hash": "eaed24f885b3b85118ee69ad306ed7b19b737602", "best_bid": "0.727", "best_ask": "0.785"}, {"asset_id": "30441349073423271296409239412402830197110444658615254085853491470932508604811", "price": "0.98", "size": "0", "side": "SELL", "hash": "18ca08061b526fa8e966958fdf13b0073fb01b73", "best_bid": "0.215", "best_ask": "0.273"}], "timestamp": "1769384041235", "event_type": "price_change"}}
{"_local_timestamp": "2026-01-25T23:34:01.646571+00:00", "data": {"market": "0xf3b4662d12f86894b31d52b454428c91733c166ba05c4e3bccc375f78411601a", "price_changes": [{"asset_id": "55382819090443168507206409119841525953451022223003224583889620760999266943524", "price": "0.039", "size": "494.8", "side": "BUY", "hash": "332039c3c1862813396fc709d591b8c2859e4cfe", "best_bid": "0.727", "best_ask": "0.785"}, {"asset_id": "30441349073423271296409239412402830197110444658615254085853491470932508604811", "price": "0.961", "size": "494.8", "side": "SELL", "hash": "ae50948d94510722f9094b9beb423daba8610c48", "best_bid": "0.215", "best_ask": "0.273"}], "timestamp": "1769384041559", "event_type": "price_change"}}
{"_local_timestamp": "2026-01-25T23:34:02.664968+00:00", "data": {"market": "0x8d9b74d39735dd0b76542c31b81b9544c3eb954060b3c5790d24957538638145", "price_changes": [{"asset_id": "66829232893940327662461037379134988031891083237936281380951338917389315110298", "price": "0.015", "size": "0", "side": "BUY", "hash": "5536737871ded03e927ad0b34412ee50ca2827bb", "best_bid": "0.014", "best_ask": "0.017"}, {"asset_id": "587316473157103098403959848063967316493748298547115564222712976431944570953", "price": "0.985", "size": "0", "side": "SELL", "hash": "fe4e2d3b4fd47b169b5b48ab4dbd39e25424d879", "best_bid": "0.983", "best_ask": "0.986"}], "timestamp": "1769384042581", "event_type": "price_change"}}
{"_local_timestamp": "2026-01-25T23:34:02.685396+00:00", "data": {"market": "0x8d9b74d39735dd0b76542c31b81b9544c3eb954060b3c5790d24957538638145", "price_changes": [{"asset_id": "66829232893940327662461037379134988031891083237936281380951338917389315110298", "price": "0.015", "size": "303", "side": "BUY", "hash": "37e4f477d0678a1ad169fd122623c1a857d9a152", "best_bid": "0.015", "best_ask": "0.017"}, {"asset_id": "587316473157103098403959848063967316493748298547115564222712976431944570953", "price": "0.985", "size": "303", "side": "SELL", "hash": "af01163d7c8b86da316fdefb529180bdb3a5dc32", "best_bid": "0.983", "best_ask": "0.985"}], "timestamp": "1769384042619", "event_type": "price_change"}}
{"_local_timestamp": "2026-01-25T23:34:03.672657+00:00", "data": {"market": "0xf487886d421ef02ec6b1d9545ac23b1d1186fd7e9cc1131f7a940e2b88c77254", "price_changes": [{"asset_id": "108625585990345450370600586761911493642226239230661931449761915709706711737069", "price": "0.002", "size": "66.05", "side": "BUY", "hash": "8f00221da6025b39ca334843daece3bc4f50e351", "best_bid": "0.021", "best_ask": "0.071"}, {"asset_id": "32299964279291975502088934125199181742042967532787071650763696447515971539636", "price": "0.998", "size": "66.05", "side": "SELL", "hash": "6b51fd9ab8a0d67f1525a6022850ae70a8229557", "best_bid": "0.929", "best_ask": "0.979"}], "timestamp": "1769384043604", "event_type": "price_change"}}
{"_local_timestamp": "2026-01-25T23:34:04.152829+00:00", "data": {"market": "0x8d9b74d39735dd0b76542c31b81b9544c3eb954060b3c5790d24957538638145", "price_changes": [{"asset_id": "66829232893940327662461037379134988031891083237936281380951338917389315110298", "price": "0.015", "size": "0", "side": "BUY", "hash": "b614f75932a26e8da4b24aec99acfc0b6043e304", "best_bid": "0.014", "best_ask": "0.017"}, {"asset_id": "587316473157103098403959848063967316493748298547115564222712976431944570953", "price": "0.985", "size": "0", "side": "SELL", "hash": "377f0b458f187de82a33a121f79f500c87a61410", "best_bid": "0.983", "best_ask": "0.986"}], "timestamp": "1769384044077", "event_type": "price_change"}}
{"_local_timestamp": "2026-01-25T23:34:04.172856+00:00", "data": {"market": "0x8d9b74d39735dd0b76542c31b81b9544c3eb954060b3c5790d24957538638145", "price_changes": [{"asset_id": "66829232893940327662461037379134988031891083237936281380951338917389315110298", "price": "0.015", "size": "303", "side": "BUY", "hash": "720e2de431f1e91ce81df553907400fb7a8d80af", "best_bid": "0.015", "best_ask": "0.017"}, {"asset_id": "587316473157103098403959848063967316493748298547115564222712976431944570953", "price": "0.985", "size": "303", "side": "SELL", "hash": "19aa5f4329dec610a622ae2f917d8fb754da31da", "best_bid": "0.983", "best_ask": "0.985"}], "timestamp": "1769384044106", "event_type": "price_change"}}
{"_local_timestamp": "2026-01-25T23:34:05.647882+00:00", "data": {"market": "0x8d9b74d39735dd0b76542c31b81b9544c3eb954060b3c5790d24957538638145", "price_changes": [{"asset_id": "66829232893940327662461037379134988031891083237936281380951338917389315110298", "price": "0.015", "size": "0", "side": "BUY", "hash": "a7ccb8249b73db34b22d9b69212a097aceecce0a", "best_bid": "0.014", "best_ask": "0.017"}, {"asset_id": "587316473157103098403959848063967316493748298547115564222712976431944570953", "price": "0.985", "size": "0", "side": "SELL", "hash": "530b248381c74bc4d5e5367c33e979ad82834382", "best_bid": "0.983", "best_ask": "0.986"}], "timestamp": "1769384045576", "event_type": "price_change"}}
{"_local_timestamp": "2026-01-25T23:34:05.677473+00:00", "data": {"market": "0x8d9b74d39735dd0b76542c31b81b9544c3eb954060b3c5790d24957538638145", "price_changes": [{"asset_id": "66829232893940327662461037379134988031891083237936281380951338917389315110298", "price": "0.015", "size": "303", "side": "BUY", "hash": "d7d82217abd9dad663b81f5cf375588f8458de85", "best_bid": "0.015", "best_ask": "0.017"}, {"asset_id": "587316473157103098403959848063967316493748298547115564222712976431944570953", "price": "0.985", "size": "303", "side": "SELL", "hash": "70005889ebf3755fdb4b76721f817ba2cd201c01", "best_bid": "0.983", "best_ask": "0.985"}], "timestamp": "1769384045607", "event_type": "price_change"}}
{"_local_timestamp": "2026-01-25T23:34:06.502715+00:00", "data": {"market": "0x12d1b41c90a2ff07173ab2469aad97fb9e80f781b36c32f99fbf4ae28a28b42a", "price_changes": [{"asset_id": "22835304185425644675451740820217338241663141495608098477495460677942947224804", "price": "0.64", "size": "9", "side": "SELL", "hash": "5479f51de43c9534e87436d00d59da175c27fe62", "best_bid": "0.44", "best_ask": "0.46"}, {"asset_id": "36737124956681902477833012015613017711780279541938574794261768841905170092613", "price": "0.36", "size": "9", "side": "BUY", "hash": "e591032aa90ae7c33d2fcff8fe045c9d544b7abe", "best_bid": "0.54", "best_ask": "0.56"}], "timestamp": "1769384046433", "event_type": "price_change"}}
{"_local_timestamp": "2026-01-25T23:34:06.529587+00:00", "data": {"market": "0x12d1b41c90a2ff07173ab2469aad97fb9e80f781b36c32f99fbf4ae28a28b42a", "price_changes": [{"asset_id": "36737124956681902477833012015613017711780279541938574794261768841905170092613", "price": "0.54", "size": "156.85", "side": "BUY", "hash": "f29b51144739d02f52082e4771e7d324ebab3584", "best_bid": "0.54", "best_ask": "0.56"}, {"asset_id": "22835304185425644675451740820217338241663141495608098477495460677942947224804", "price": "0.46", "size": "156.85", "side": "SELL", "hash": "09c424cf394c152a4185eb4df8ee80e26a54f7da", "best_bid": "0.44", "best_ask": "0.46"}], "timestamp": "1769384046460", "event_type": "price_change"}}
{"_local_timestamp": "2026-01-25T23:34:06.562612+00:00", "data": {"market": "0x12d1b41c90a2ff07173ab2469aad97fb9e80f781b36c32f99fbf4ae28a28b42a", "price_changes": [{"asset_id": "36737124956681902477833012015613017711780279541938574794261768841905170092613", "price": "0.52", "size": "246", "side": "BUY", "hash": "853622aafe55d46abead576d4fb4c14edbdd19f0", "best_bid": "0.54", "best_ask": "0.56"}, {"asset_id": "22835304185425644675451740820217338241663141495608098477495460677942947224804", "price": "0.48", "size": "246", "side": "SELL", "hash": "1bace3868dac6dd1119bd9e466c742444194e808", "best_bid": "0.44", "best_ask": "0.46"}], "timestamp": "1769384046488", "event_type": "price_change"}}
{"_local_timestamp": "2026-01-25T23:34:06.780709+00:00", "data": {"market": "0xf487886d421ef02ec6b1d9545ac23b1d1186fd7e9cc1131f7a940e2b88c77254", "price_changes": [{"asset_id": "108625585990345450370600586761911493642226239230661931449761915709706711737069", "price": "0.003", "size": "38.05", "side": "BUY", "hash": "aff619a0791b0749c937dad2140bf962d409b76f", "best_bid": "0.021", "best_ask": "0.071"}, {"asset_id": "32299964279291975502088934125199181742042967532787071650763696447515971539636", "price": "0.997", "size": "38.05", "side": "SELL", "hash": "3d27d20bdf1b87d920fcb6bffb9a2bfc9f56e906", "best_bid": "0.929", "best_ask": "0.979"}], "timestamp": "1769384046711", "event_type": "price_change"}}
{"_local_timestamp": "2026-01-25T23:34:07.146545+00:00", "data": {"market": "0x8d9b74d39735dd0b76542c31b81b9544c3eb954060b3c5790d24957538638145", "price_changes": [{"asset_id": "66829232893940327662461037379134988031891083237936281380951338917389315110298", "price": "0.015", "size": "0", "side": "BUY", "hash": "0f2f9946089f6ae294e832e045202de540bf53af", "best_bid": "0.014", "best_ask": "0.017"}, {"asset_id": "587316473157103098403959848063967316493748298547115564222712976431944570953", "price": "0.985", "size": "0", "side": "SELL", "hash": "18303e34cad4e857f292adb79c3aeb58d380ad59", "best_bid": "0.983", "best_ask": "0.986"}], "timestamp": "1769384047076", "event_type": "price_change"}}
{"_local_timestamp": "2026-01-25T23:34:07.174508+00:00", "data": {"market": "0x8d9b74d39735dd0b76542c31b81b9544c3eb954060b3c5790d24957538638145", "price_changes": [{"asset_id": "66829232893940327662461037379134988031891083237936281380951338917389315110298", "price": "0.015", "size": "303", "side": "BUY", "hash": "e13ab8ad985e5e9d5adb115ede590b53f5379115", "best_bid": "0.015", "best_ask": "0.017"}, {"asset_id": "587316473157103098403959848063967316493748298547115564222712976431944570953", "price": "0.985", "size": "303", "side": "SELL", "hash": "8cdf7d57f46e627c44199dbe802e969b94637477", "best_bid": "0.983", "best_ask": "0.985"}], "timestamp": "1769384047102", "event_type": "price_change"}}
{"_local_timestamp": "2026-01-25T23:34:08.689096+00:00", "data": {"market": "0x8d9b74d39735dd0b76542c31b81b9544c3eb954060b3c5790d24957538638145", "price_changes": [{"asset_id": "66829232893940327662461037379134988031891083237936281380951338917389315110298", "price": "0.015", "size": "0", "side": "BUY", "hash": "49bceeeb3abfa62037ffdc4ac33ff01e8caa0442", "best_bid": "0.014", "best_ask": "0.017"}, {"asset_id": "587316473157103098403959848063967316493748298547115564222712976431944570953", "price": "0.985", "size": "0", "side": "SELL", "hash": "32d1ad8c0b941696d3e36138308576e96454bf48", "best_bid": "0.983", "best_ask": "0.986"}], "timestamp": "1769384048577", "event_type": "price_change"}}
{"_local_timestamp": "2026-01-25T23:34:08.730249+00:00", "data": {"market": "0x8d9b74d39735dd0b76542c31b81b9544c3eb954060b3c5790d24957538638145", "price_changes": [{"asset_id": "66829232893940327662461037379134988031891083237936281380951338917389315110298", "price": "0.015", "size": "303", "side": "BUY", "hash": "d302a4b68c68f0f90d542488344d736f28a0e166", "best_bid": "0.015", "best_ask": "0.017"}, {"asset_id": "587316473157103098403959848063967316493748298547115564222712976431944570953", "price": "0.985", "size": "303", "side": "SELL", "hash": "06211fd72fbb76b32f685f86112824cd964f8822", "best_bid": "0.983", "best_ask": "0.985"}], "timestamp": "1769384048639", "event_type": "price_change"}}
{"_local_timestamp": "2026-01-25T23:34:09.004796+00:00", "data": {"market": "0xfdd952522d15cd0d4be8f340c5a249f0b25bb5e92716437002037e899d65195f", "price_changes": [{"asset_id": "71439979369081433769877908436626697830533226033387852251824796378263454719432", "price": "0.002", "size": "2166", "side": "BUY", "hash": "c452c9cf3a2aa1f366aa004c7a3fa2fa786e13c8", "best_bid": "0.009", "best_ask": "0.014"}, {"asset_id": "100684009992995172968426231771405309069841941067041831232587523024554691306802", "price": "0.998", "size": "2166", "side": "SELL", "hash": "9421f51f5959ec71f51499e123b5721f8a6fbabf", "best_bid": "0.986", "best_ask": "0.991"}], "timestamp": "1769384048937", "event_type": "price_change"}}
{"_local_timestamp": "2026-01-25T23:34:10.151557+00:00", "data": {"market": "0x8d9b74d39735dd0b76542c31b81b9544c3eb954060b3c5790d24957538638145", "price_changes": [{"asset_id": "66829232893940327662461037379134988031891083237936281380951338917389315110298", "price": "0.015", "size": "0", "side": "BUY", "hash": "5ecbaf6a78289bb47297cf5fde4be22775cf9d34", "best_bid": "0.014", "best_ask": "0.017"}, {"asset_id": "587316473157103098403959848063967316493748298547115564222712976431944570953", "price": "0.985", "size": "0", "side": "SELL", "hash": "e08b457352add211758bfbb66c109037f126b4b6", "best_bid": "0.983", "best_ask": "0.986"}], "timestamp": "1769384050080", "event_type": "price_change"}}
{"_local_timestamp": "2026-01-25T23:34:10.178996+00:00", "data": {"market": "0x8d9b74d39735dd0b76542c31b81b9544c3eb954060b3c5790d24957538638145", "price_changes": [{"asset_id": "66829232893940327662461037379134988031891083237936281380951338917389315110298", "price": "0.015", "size": "303", "side": "BUY", "hash": "6268272ce182431fa2b7a4bb38007fa6469aa57a", "best_bid": "0.015", "best_ask": "0.017"}, {"asset_id": "587316473157103098403959848063967316493748298547115564222712976431944570953", "price": "0.985", "size": "303", "side": "SELL", "hash": "d5894d319636b19f527a1c01b8f173ee919e0e84", "best_bid": "0.983", "best_ask": "0.985"}], "timestamp": "1769384050106", "event_type": "price_change"}}
{"_local_timestamp": "2026-01-25T23:34:10.761119+00:00", "data": {"market": "0xfdd952522d15cd0d4be8f340c5a249f0b25bb5e92716437002037e899d65195f", "price_changes": [{"asset_id": "71439979369081433769877908436626697830533226033387852251824796378263454719432", "price": "0.002", "size": "2182.09", "side": "BUY", "hash": "ab039a69493abbe06f83f17f250964da91a37a93", "best_bid": "0.009", "best_ask": "0.014"}, {"asset_id": "100684009992995172968426231771405309069841941067041831232587523024554691306802", "price": "0.998", "size": "2182.09", "side": "SELL", "hash": "f0f0b589723d1aaea32dea3781d20c44fba9b7a0", "best_bid": "0.986", "best_ask": "0.991"}], "timestamp": "1769384050692", "event_type": "price_change"}}
{"_local_timestamp": "2026-01-25T23:34:11.654087+00:00", "data": {"market": "0x8d9b74d39735dd0b76542c31b81b9544c3eb954060b3c5790d24957538638145", "price_changes": [{"asset_id": "66829232893940327662461037379134988031891083237936281380951338917389315110298", "price": "0.015", "size": "0", "side": "BUY", "hash": "93f254051dcd89853239224246d2b9fd3af65bde", "best_bid": "0.014", "best_ask": "0.017"}, {"asset_id": "587316473157103098403959848063967316493748298547115564222712976431944570953", "price": "0.985", "size": "0", "side": "SELL", "hash": "064797f711b905ca7e1fd3592f091fada0ae03eb", "best_bid": "0.983", "best_ask": "0.986"}], "timestamp": "1769384051578", "event_type": "price_change"}}
{"_local_timestamp": "2026-01-25T23:34:11.681484+00:00", "data": {"market": "0x8d9b74d39735dd0b76542c31b81b9544c3eb954060b3c5790d24957538638145", "price_changes": [{"asset_id": "66829232893940327662461037379134988031891083237936281380951338917389315110298", "price": "0.015", "size": "303", "side": "BUY", "hash": "9f735ba96ee4d248ad9b6e1ec91f672c7d167f03", "best_bid": "0.015", "best_ask": "0.017"}, {"asset_id": "587316473157103098403959848063967316493748298547115564222712976431944570953", "price": "0.985", "size": "303", "side": "SELL", "hash": "2a4ad4f3abdc23b201e300e6b3d1eb66e9e92227", "best_bid": "0.983", "best_ask": "0.985"}], "timestamp": "1769384051605", "event_type": "price_change"}}
{"_local_timestamp": "2026-01-25T23:34:13.189667+00:00", "data": {"market": "0x8d9b74d39735dd0b76542c31b81b9544c3eb954060b3c5790d24957538638145", "price_changes": [{"asset_id": "66829232893940327662461037379134988031891083237936281380951338917389315110298", "price": "0.015", "size": "0", "side": "BUY", "hash": "82fcaca3d5a6558db072dabb9eba1d8df3d0d779", "best_bid": "0.014", "best_ask": "0.017"}, {"asset_id": "587316473157103098403959848063967316493748298547115564222712976431944570953", "price": "0.985", "size": "0", "side": "SELL", "hash": "558ec7dfb30c3e8ccd3001e9d10c0447b069bc66", "best_bid": "0.983", "best_ask": "0.986"}], "timestamp": "1769384053076", "event_type": "price_change"}}
{"_local_timestamp": "2026-01-25T23:34:13.223939+00:00", "data": {"market": "0x8d9b74d39735dd0b76542c31b81b9544c3eb954060b3c5790d24957538638145", "price_changes": [{"asset_id": "66829232893940327662461037379134988031891083237936281380951338917389315110298", "price": "0.015", "size": "303", "side": "BUY", "hash": "fc2335f4ded0bc1794fbaea9822043af1cd67171", "best_bid": "0.015", "best_ask": "0.017"}, {"asset_id": "587316473157103098403959848063967316493748298547115564222712976431944570953", "price": "0.985", "size": "303", "side": "SELL", "hash": "36b7b8eedc05f542b4d141b94dc6220e4c87c9f4", "best_bid": "0.983", "best_ask": "0.985"}], "timestamp": "1769384053141", "event_type": "price_change"}}
{"_local_timestamp": "2026-01-25T23:34:14.668270+00:00", "data": {"market": "0x8d9b74d39735dd0b76542c31b81b9544c3eb954060b3c5790d24957538638145", "price_changes": [{"asset_id": "66829232893940327662461037379134988031891083237936281380951338917389315110298", "price": "0.015", "size": "0", "side": "BUY", "hash": "413ec8dc8265b32a3d1e3ceefe38416f7037c73e", "best_bid": "0.014", "best_ask": "0.017"}, {"asset_id": "587316473157103098403959848063967316493748298547115564222712976431944570953", "price": "0.985", "size": "0", "side": "SELL", "hash": "8e03ffedcb3745b51b8f9bc4ce5d8956084a67b2", "best_bid": "0.983", "best_ask": "0.986"}], "timestamp": "1769384054586", "event_type": "price_change"}}
{"_local_timestamp": "2026-01-25T23:34:14.682316+00:00", "data": {"market": "0x8d9b74d39735dd0b76542c31b81b9544c3eb954060b3c5790d24957538638145", "price_changes": [{"asset_id": "66829232893940327662461037379134988031891083237936281380951338917389315110298", "price": "0.015", "size": "303", "side": "BUY", "hash": "2d9e28be509c0bb29a35ce377140c82a386cb2f6", "best_bid": "0.015", "best_ask": "0.017"}, {"asset_id": "587316473157103098403959848063967316493748298547115564222712976431944570953", "price": "0.985", "size": "303", "side": "SELL", "hash": "c3dc4397da9b84e3ae1f29ee813e7e48d17bf3d1", "best_bid": "0.983", "best_ask": "0.985"}], "timestamp": "1769384054612", "event_type": "price_change"}}
{"_local_timestamp": "2026-01-25T23:34:16.147885+00:00", "data": {"market": "0x8d9b74d39735dd0b76542c31b81b9544c3eb954060b3c5790d24957538638145", "price_changes": [{"asset_id": "66829232893940327662461037379134988031891083237936281380951338917389315110298", "price": "0.015", "size": "0", "side": "BUY", "hash": "3b42c847e94bb4fc4e761209a59dc200cd46d299", "best_bid": "0.014", "best_ask": "0.017"}, {"asset_id": "587316473157103098403959848063967316493748298547115564222712976431944570953", "price": "0.985", "size": "0", "side": "SELL", "hash": "920bda25251bbf9139385a90efb9c6967b351dac", "best_bid": "0.983", "best_ask": "0.986"}], "timestamp": "1769384056076", "event_type": "price_change"}}
{"_local_timestamp": "2026-01-25T23:34:16.188788+00:00", "data": {"market": "0x8d9b74d39735dd0b76542c31b81b9544c3eb954060b3c5790d24957538638145", "price_changes": [{"asset_id": "66829232893940327662461037379134988031891083237936281380951338917389315110298", "price": "0.015", "size": "303", "side": "BUY", "hash": "7fe2248bda5aceef3e19c38d15004b7e527a09c9", "best_bid": "0.015", "best_ask": "0.017"}, {"asset_id": "587316473157103098403959848063967316493748298547115564222712976431944570953", "price": "0.985", "size": "303", "side": "SELL", "hash": "cae8c0df19b781adb621155a2dbd81b6e0b083bb", "best_bid": "0.983", "best_ask": "0.985"}], "timestamp": "1769384056118", "event_type": "price_change"}}
{"_local_timestamp": "2026-01-25T23:34:17.646739+00:00", "data": {"market": "0x8d9b74d39735dd0b76542c31b81b9544c3eb954060b3c5790d24957538638145", "price_changes": [{"asset_id": "66829232893940327662461037379134988031891083237936281380951338917389315110298", "price": "0.015", "size": "0", "side": "BUY", "hash": "8ffd0eea8d95e8cd41056257eadb16c9789fdbaa", "best_bid": "0.014", "best_ask": "0.017"}, {"asset_id": "587316473157103098403959848063967316493748298547115564222712976431944570953", "price": "0.985", "size": "0", "side": "SELL", "hash": "de16eb2e7e6b20eb7135b2f222474bb7e85d1d7c", "best_bid": "0.983", "best_ask": "0.986"}], "timestamp": "1769384057576", "event_type": "price_change"}}
{"_local_timestamp": "2026-01-25T23:34:17.677365+00:00", "data": {"market": "0x8d9b74d39735dd0b76542c31b81b9544c3eb954060b3c5790d24957538638145", "price_changes": [{"asset_id": "66829232893940327662461037379134988031891083237936281380951338917389315110298", "price": "0.015", "size": "303", "side": "BUY", "hash": "4b115c83456f0f26cfa40f06e6bd4cef62317fcc", "best_bid": "0.015", "best_ask": "0.017"}, {"asset_id": "587316473157103098403959848063967316493748298547115564222712976431944570953", "price": "0.985", "size": "303", "side": "SELL", "hash": "3f9c17571e64af019a5a83f4242902f4e69543de", "best_bid": "0.983", "best_ask": "0.985"}], "timestamp": "1769384057602", "event_type": "price_change"}}
{"_local_timestamp": "2026-01-25T23:34:18.115489+00:00", "data": {"market": "0xcc25bf2f9c735a18c35969e330c0d917eec97fb93ea9422a0a0ed2b3f0eada54", "price_changes": [{"asset_id": "65578135623666125364690190525767126679774364994694102050152165807381694053320", "price": "0.44", "size": "66.66", "side": "SELL", "hash": "79b1f722d671d56880e7066a97aeebb119a51c35", "best_bid": "0.31", "best_ask": "0.35"}, {"asset_id": "41699891447566493678062566391348854695286848129234610508637427753139123056608", "price": "0.56", "size": "66.66", "side": "BUY", "hash": "310427fb4b8cbd97fd6259ec58f3a5689ca8e433", "best_bid": "0.65", "best_ask": "0.69"}], "timestamp": "1769384058046", "event_type": "price_change"}}
{"_local_timestamp": "2026-01-25T23:34:18.935270+00:00", "data": {"market": "0xcc25bf2f9c735a18c35969e330c0d917eec97fb93ea9422a0a0ed2b3f0eada54", "price_changes": [{"asset_id": "65578135623666125364690190525767126679774364994694102050152165807381694053320", "price": "0.36", "size": "55", "side": "SELL", "hash": "1effd2b2b465667bfeca6e80b2b5a484b483d9e8", "best_bid": "0.31", "best_ask": "0.35"}, {"asset_id": "41699891447566493678062566391348854695286848129234610508637427753139123056608", "price": "0.64", "size": "55", "side": "BUY", "hash": "7386ffda7b460b482bcccc143229ba9c1b2810e6", "best_bid": "0.65", "best_ask": "0.69"}], "timestamp": "1769384058856", "event_type": "price_change"}}
{"_local_timestamp": "2026-01-25T23:34:19.153808+00:00", "data": {"market": "0x8d9b74d39735dd0b76542c31b81b9544c3eb954060b3c5790d24957538638145", "price_changes": [{"asset_id": "66829232893940327662461037379134988031891083237936281380951338917389315110298", "price": "0.015", "size": "0", "side": "BUY", "hash": "a00007a3742b9fe1f84f12acbc6ad2ba4cfa10e2", "best_bid": "0.014", "best_ask": "0.017"}, {"asset_id": "587316473157103098403959848063967316493748298547115564222712976431944570953", "price": "0.985", "size": "0", "side": "SELL", "hash": "db9ec5938b1e62ba9973489d08c60c45c618f862", "best_bid": "0.983", "best_ask": "0.986"}], "timestamp": "1769384059077", "event_type": "price_change"}}
{"_local_timestamp": "2026-01-25T23:34:19.179630+00:00", "data": {"market": "0x8d9b74d39735dd0b76542c31b81b9544c3eb954060b3c5790d24957538638145", "price_changes": [{"asset_id": "66829232893940327662461037379134988031891083237936281380951338917389315110298", "price": "0.015", "size": "303", "side": "BUY", "hash": "694e01ffec32e74a287553e94d78e8847b9c6d3f", "best_bid": "0.015", "best_ask": "0.017"}, {"asset_id": "587316473157103098403959848063967316493748298547115564222712976431944570953", "price": "0.985", "size": "303", "side": "SELL", "hash": "05c3059c9f9074493d937b703f2d8f429eda3cea", "best_bid": "0.983", "best_ask": "0.985"}], "timestamp": "1769384059106", "event_type": "price_change"}}
{"_local_timestamp": "2026-01-25T23:34:19.535397+00:00", "data": {"market": "0xcc25bf2f9c735a18c35969e330c0d917eec97fb93ea9422a0a0ed2b3f0eada54", "price_changes": [{"asset_id": "65578135623666125364690190525767126679774364994694102050152165807381694053320", "price": "0.48", "size": "0", "side": "SELL", "hash": "e021d7fbecd02a00630c7029e7fb437d4768c757", "best_bid": "0.31", "best_ask": "0.35"}, {"asset_id": "41699891447566493678062566391348854695286848129234610508637427753139123056608", "price": "0.52", "size": "0", "side": "BUY", "hash": "77379faea0ba385aa5041ead652b2f8dd9776883", "best_bid": "0.65", "best_ask": "0.69"}], "timestamp": "1769384059466", "event_type": "price_change"}}
{"_local_timestamp": "2026-01-25T23:34:19.930221+00:00", "data": {"market": "0xcc25bf2f9c735a18c35969e330c0d917eec97fb93ea9422a0a0ed2b3f0eada54", "price_changes": [{"asset_id": "65578135623666125364690190525767126679774364994694102050152165807381694053320", "price": "0.27", "size": "19", "side": "BUY", "hash": "d549418bfd15537dcf906b66c84bfebc72ecced1", "best_bid": "0.31", "best_ask": "0.35"}, {"asset_id": "41699891447566493678062566391348854695286848129234610508637427753139123056608", "price": "0.73", "size": "19", "side": "SELL", "hash": "1613007ad4a5bc268dc33f7f73bea04126721315", "best_bid": "0.65", "best_ask": "0.69"}], "timestamp": "1769384059852", "event_type": "price_change"}}
{"_local_timestamp": "2026-01-25T23:34:19.994413+00:00", "data": {"market": "0xcc25bf2f9c735a18c35969e330c0d917eec97fb93ea9422a0a0ed2b3f0eada54", "price_changes": [{"asset_id": "65578135623666125364690190525767126679774364994694102050152165807381694053320", "price": "0.35", "size": "208.49", "side": "SELL", "hash": "8dd221964c583fde93626aa296e9c426386da84c", "best_bid": "0.31", "best_ask": "0.35"}, {"asset_id": "41699891447566493678062566391348854695286848129234610508637427753139123056608", "price": "0.65", "size": "208.49", "side": "BUY", "hash": "a5f36227e0295345b3b3aabffa22a04db2973f0f", "best_bid": "0.65", "best_ask": "0.69"}], "timestamp": "1769384059921", "event_type": "price_change"}}
{"_local_timestamp": "2026-01-25T23:34:20.165263+00:00", "data": {"market": "0xcc25bf2f9c735a18c35969e330c0d917eec97fb93ea9422a0a0ed2b3f0eada54", "price_changes": [{"asset_id": "65578135623666125364690190525767126679774364994694102050152165807381694053320", "price": "0.24", "size": "33", "side": "BUY", "hash": "ab24271a7134f615a90e31ee9f265a3f5a31f436", "best_bid": "0.31", "best_ask": "0.35"}, {"asset_id": "41699891447566493678062566391348854695286848129234610508637427753139123056608", "price": "0.76", "size": "33", "side": "SELL", "hash": "3d269fc5c81254b2e178a3f6e49cb765f67cc67a", "best_bid": "0.65", "best_ask": "0.69"}], "timestamp": "1769384060089", "event_type": "price_change"}}
{"_local_timestamp": "2026-01-25T23:34:20.303832+00:00", "data": {"market": "0xcc25bf2f9c735a18c35969e330c0d917eec97fb93ea9422a0a0ed2b3f0eada54", "price_changes": [{"asset_id": "65578135623666125364690190525767126679774364994694102050152165807381694053320", "price": "0.37", "size": "0", "side": "SELL", "hash": "994c80ca6fda8f3514f11635efe017ab6491f9a5", "best_bid": "0.31", "best_ask": "0.35"}, {"asset_id": "41699891447566493678062566391348854695286848129234610508637427753139123056608", "price": "0.63", "size": "0", "side": "BUY", "hash": "2e61319a585da88c5338a81f9e270441e062e8e7", "best_bid": "0.65", "best_ask": "0.69"}], "timestamp": "1769384060232", "event_type": "price_change"}}
{"_local_timestamp": "2026-01-25T23:34:20.385107+00:00", "data": {"market": "0xcc25bf2f9c735a18c35969e330c0d917eec97fb93ea9422a0a0ed2b3f0eada54", "price_changes": [{"asset_id": "65578135623666125364690190525767126679774364994694102050152165807381694053320", "price": "0.35", "size": "238.49", "side": "SELL", "hash": "476cf4bd794a9526cfb412287b80ba3a4a20dcf3", "best_bid": "0.31", "best_ask": "0.35"}, {"asset_id": "41699891447566493678062566391348854695286848129234610508637427753139123056608", "price": "0.65", "size": "238.49", "side": "BUY", "hash": "7ce65dd6b30e76e64dfdc903e0829937b05d0718", "best_bid": "0.65", "best_ask": "0.69"}], "timestamp": "1769384060299", "event_type": "price_change"}}
{"_local_timestamp": "2026-01-25T23:34:20.647885+00:00", "data": {"market": "0x8d9b74d39735dd0b76542c31b81b9544c3eb954060b3c5790d24957538638145", "price_changes": [{"asset_id": "66829232893940327662461037379134988031891083237936281380951338917389315110298", "price": "0.015", "size": "0", "side": "BUY", "hash": "4a95faf8e5c8b99f463f66f24cc690f73cf56bce", "best_bid": "0.014", "best_ask": "0.017"}, {"asset_id": "587316473157103098403959848063967316493748298547115564222712976431944570953", "price": "0.985", "size": "0", "side": "SELL", "hash": "18056bd9412457fb8bd77f2f94deae8025885451", "best_bid": "0.983", "best_ask": "0.986"}], "timestamp": "1769384060576", "event_type": "price_change"}}
{"_local_timestamp": "2026-01-25T23:34:20.675955+00:00", "data": {"market": "0x8d9b74d39735dd0b76542c31b81b9544c3eb954060b3c5790d24957538638145", "price_changes": [{"asset_id": "66829232893940327662461037379134988031891083237936281380951338917389315110298", "price": "0.015", "size": "303", "side": "BUY", "hash": "1d43126618c72adb907bf97d7ee8ca773021f501", "best_bid": "0.015", "best_ask": "0.017"}, {"asset_id": "587316473157103098403959848063967316493748298547115564222712976431944570953", "price": "0.985", "size": "303", "side": "SELL", "hash": "62601640bd1758d9d0c9fed970f8aa2bce96222c", "best_bid": "0.983", "best_ask": "0.985"}], "timestamp": "1769384060606", "event_type": "price_change"}}
{"_local_timestamp": "2026-01-25T23:34:21.813186+00:00", "data": {"market": "0xcc25bf2f9c735a18c35969e330c0d917eec97fb93ea9422a0a0ed2b3f0eada54", "price_changes": [{"asset_id": "41699891447566493678062566391348854695286848129234610508637427753139123056608", "price": "0.66", "size": "30", "side": "BUY", "hash": "44b349a34bf432c52e1ac95318eacd0e5e8e7eeb", "best_bid": "0.66", "best_ask": "0.69"}, {"asset_id": "65578135623666125364690190525767126679774364994694102050152165807381694053320", "price": "0.34", "size": "30", "side": "SELL", "hash": "e43ff3fcc69f0e3f153131549482d139e2f106b4", "best_bid": "0.31", "best_ask": "0.34"}], "timestamp": "1769384061730", "event_type": "price_change"}}
{"_local_timestamp": "2026-01-25T23:34:22.093310+00:00", "data": {"market": "0xcc25bf2f9c735a18c35969e330c0d917eec97fb93ea9422a0a0ed2b3f0eada54", "price_changes": [{"asset_id": "41699891447566493678062566391348854695286848129234610508637427753139123056608", "price": "0.64", "size": "25", "side": "BUY", "hash": "9cedee4dbacee9e91dd436c1ecca79e00dd41afb", "best_bid": "0.66", "best_ask": "0.69"}, {"asset_id": "65578135623666125364690190525767126679774364994694102050152165807381694053320", "price": "0.36", "size": "25", "side": "SELL", "hash": "745b014df1704d8488ed247cca980904ab628661", "best_bid": "0.31", "best_ask": "0.34"}], "timestamp": "1769384062014", "event_type": "price_change"}}
{"_local_timestamp": "2026-01-25T23:34:22.143421+00:00", "data": {"market": "0x8d9b74d39735dd0b76542c31b81b9544c3eb954060b3c5790d24957538638145", "price_changes": [{"asset_id": "66829232893940327662461037379134988031891083237936281380951338917389315110298", "price": "0.015", "size": "0", "side": "BUY", "hash": "07456ada9acb8f4455f23aae01ec44c24224d0eb", "best_bid": "0.014", "best_ask": "0.017"}, {"asset_id": "587316473157103098403959848063967316493748298547115564222712976431944570953", "price": "0.985", "size": "0", "side": "SELL", "hash": "05a30048f3ba1aef5d0506234810d0d5eca50bb4", "best_bid": "0.983", "best_ask": "0.986"}], "timestamp": "1769384062076", "event_type": "price_change"}}
{"_local_timestamp": "2026-01-25T23:34:22.175244+00:00", "data": {"market": "0xcc25bf2f9c735a18c35969e330c0d917eec97fb93ea9422a0a0ed2b3f0eada54", "price_changes": [{"asset_id": "65578135623666125364690190525767126679774364994694102050152165807381694053320", "price": "0.28", "size": "0", "side": "BUY", "hash": "e0c533785f1a6519d0eca54a93a357e1df144716", "best_bid": "0.31", "best_ask": "0.34"}, {"asset_id": "41699891447566493678062566391348854695286848129234610508637427753139123056608", "price": "0.72", "size": "0", "side": "SELL", "hash": "6469c9d748d759d16fb76decf42d918d51387fbb", "best_bid": "0.66", "best_ask": "0.69"}], "timestamp": "1769384062101", "event_type": "price_change"}}
{"_local_timestamp": "2026-01-25T23:34:22.175970+00:00", "data": {"market": "0xcc25bf2f9c735a18c35969e330c0d917eec97fb93ea9422a0a0ed2b3f0eada54", "price_changes": [{"asset_id": "65578135623666125364690190525767126679774364994694102050152165807381694053320", "price": "0.27", "size": "0", "side": "BUY", "hash": "e0c533785f1a6519d0eca54a93a357e1df144716", "best_bid": "0.31", "best_ask": "0.34"}, {"asset_id": "41699891447566493678062566391348854695286848129234610508637427753139123056608", "price": "0.73", "size": "0", "side": "SELL", "hash": "6469c9d748d759d16fb76decf42d918d51387fbb", "best_bid": "0.66", "best_ask": "0.69"}], "timestamp": "1769384062101", "event_type": "price_change"}}
{"_local_timestamp": "2026-01-25T23:34:22.176562+00:00", "data": {"market": "0x8d9b74d39735dd0b76542c31b81b9544c3eb954060b3c5790d24957538638145", "price_changes": [{"asset_id": "66829232893940327662461037379134988031891083237936281380951338917389315110298", "price": "0.015", "size": "303", "side": "BUY", "hash": "159cf00a50c5c6a8476fb7e235376fd6c35a51bd", "best_bid": "0.015", "best_ask": "0.017"}, {"asset_id": "587316473157103098403959848063967316493748298547115564222712976431944570953", "price": "0.985", "size": "303", "side": "SELL", "hash": "aad871159d85ddc7ddac71dccee2e0fd1ebb2204", "best_bid": "0.983", "best_ask": "0.985"}], "timestamp": "1769384062103", "event_type": "price_change"}}
{"_local_timestamp": "2026-01-25T23:34:22.236937+00:00", "data": {"market": "0xcc25bf2f9c735a18c35969e330c0d917eec97fb93ea9422a0a0ed2b3f0eada54", "price_changes": [{"asset_id": "65578135623666125364690190525767126679774364994694102050152165807381694053320", "price": "0.24", "size": "54", "side": "BUY", "hash": "c7d0bd85eadd637b5986b82f22e0e2a1b2ab0dcb", "best_bid": "0.31", "best_ask": "0.34"}, {"asset_id": "41699891447566493678062566391348854695286848129234610508637427753139123056608", "price": "0.76", "size": "54", "side": "SELL", "hash": "c7f6261a1eea07c642654315d0bf7073c442e3c4", "best_bid": "0.66", "best_ask": "0.69"}], "timestamp": "1769384062164", "event_type": "price_change"}}
{"_local_timestamp": "2026-01-25T23:34:22.237724+00:00", "data": {"market": "0xcc25bf2f9c735a18c35969e330c0d917eec97fb93ea9422a0a0ed2b3f0eada54", "price_changes": [{"asset_id": "65578135623666125364690190525767126679774364994694102050152165807381694053320", "price": "0.25", "size": "26", "side": "BUY", "hash": "eb2dd2bef761d47608965f301da2cf816d8df441", "best_bid": "0.31", "best_ask": "0.34"}, {"asset_id": "41699891447566493678062566391348854695286848129234610508637427753139123056608", "price": "0.75", "size": "26", "side": "SELL", "hash": "aa423ae026969f7ef80735418867fcaf434b724e", "best_bid": "0.66", "best_ask": "0.69"}], "timestamp": "1769384062165", "event_type": "price_change"}}
{"_local_timestamp": "2026-01-25T23:34:23.254184+00:00", "data": {"market": "0xcc25bf2f9c735a18c35969e330c0d917eec97fb93ea9422a0a0ed2b3f0eada54", "price_changes": [{"asset_id": "65578135623666125364690190525767126679774364994694102050152165807381694053320", "price": "0.11", "size": "0", "side": "BUY", "hash": "d2386671526f9f275586713b03065050a66402ff", "best_bid": "0.31", "best_ask": "0.34"}, {"asset_id": "41699891447566493678062566391348854695286848129234610508637427753139123056608", "price": "0.89", "size": "0", "side": "SELL", "hash": "2221a38de2ea71f2cef9fcd09927d6bb1e30dfcc", "best_bid": "0.66", "best_ask": "0.69"}], "timestamp": "1769384063182", "event_type": "price_change"}}
{"_local_timestamp": "2026-01-25T23:34:23.256289+00:00", "data": {"market": "0xcc25bf2f9c735a18c35969e330c0d917eec97fb93ea9422a0a0ed2b3f0eada54", "price_changes": [{"asset_id": "65578135623666125364690190525767126679774364994694102050152165807381694053320", "price": "0.12", "size": "416", "side": "BUY", "hash": "d2386671526f9f275586713b03065050a66402ff", "best_bid": "0.31", "best_ask": "0.34"}, {"asset_id": "41699891447566493678062566391348854695286848129234610508637427753139123056608", "price": "0.88", "size": "416", "side": "SELL", "hash": "2221a38de2ea71f2cef9fcd09927d6bb1e30dfcc", "best_bid": "0.66", "best_ask": "0.69"}], "timestamp": "1769384063182", "event_type": "price_change"}}
{"_local_timestamp": "2026-01-25T23:34:23.256952+00:00", "data": {"market": "0xcc25bf2f9c735a18c35969e330c0d917eec97fb93ea9422a0a0ed2b3f0eada54", "price_changes": [{"asset_id": "65578135623666125364690190525767126679774364994694102050152165807381694053320", "price": "0.03", "size": "128", "side": "BUY", "hash": "d2386671526f9f275586713b03065050a66402ff", "best_bid": "0.31", "best_ask": "0.34"}, {"asset_id": "41699891447566493678062566391348854695286848129234610508637427753139123056608", "price": "0.97", "size": "128", "side": "SELL", "hash": "2221a38de2ea71f2cef9fcd09927d6bb1e30dfcc", "best_bid": "0.66", "best_ask": "0.69"}], "timestamp": "1769384063182", "event_type": "price_change"}}
{"_local_timestamp": "2026-01-25T23:34:23.257669+00:00", "data": {"market": "0xcc25bf2f9c735a18c35969e330c0d917eec97fb93ea9422a0a0ed2b3f0eada54", "price_changes": [{"asset_id": "65578135623666125364690190525767126679774364994694102050152165807381694053320", "price": "0.07", "size": "0", "side": "BUY", "hash": "d2386671526f9f275586713b03065050a66402ff", "best_bid": "0.31", "best_ask": "0.34"}, {"asset_id": "41699891447566493678062566391348854695286848129234610508637427753139123056608", "price": "0.93", "size": "0", "side": "SELL", "hash": "2221a38de2ea71f2cef9fcd09927d6bb1e30dfcc", "best_bid": "0.66", "best_ask": "0.69"}], "timestamp": "1769384063182", "event_type": "price_change"}}
{"_local_timestamp": "2026-01-25T23:34:23.258718+00:00", "data": {"market": "0xcc25bf2f9c735a18c35969e330c0d917eec97fb93ea9422a0a0ed2b3f0eada54", "price_changes": [{"asset_id": "65578135623666125364690190525767126679774364994694102050152165807381694053320", "price": "0.09", "size": "0", "side": "BUY", "hash": "d2386671526f9f275586713b03065050a66402ff", "best_bid": "0.31", "best_ask": "0.34"}, {"asset_id": "41699891447566493678062566391348854695286848129234610508637427753139123056608", "price": "0.91", "size": "0", "side": "SELL", "hash": "2221a38de2ea71f2cef9fcd09927d6bb1e30dfcc", "best_bid": "0.66", "best_ask": "0.69"}], "timestamp": "1769384063182", "event_type": "price_change"}}
{"_local_timestamp": "2026-01-25T23:34:23.259509+00:00", "data": {"market": "0xcc25bf2f9c735a18c35969e330c0d917eec97fb93ea9422a0a0ed2b3f0eada54", "price_changes": [{"asset_id": "65578135623666125364690190525767126679774364994694102050152165807381694053320", "price": "0.05", "size": "0", "side": "BUY", "hash": "d2386671526f9f275586713b03065050a66402ff", "best_bid": "0.31", "best_ask": "0.34"}, {"asset_id": "41699891447566493678062566391348854695286848129234610508637427753139123056608", "price": "0.95", "size": "0", "side": "SELL", "hash": "2221a38de2ea71f2cef9fcd09927d6bb1e30dfcc", "best_bid": "0.66", "best_ask": "0.69"}], "timestamp": "1769384063182", "event_type": "price_change"}}
{"_local_timestamp": "2026-01-25T23:34:23.260150+00:00", "data": {"market": "0xcc25bf2f9c735a18c35969e330c0d917eec97fb93ea9422a0a0ed2b3f0eada54", "price_changes": [{"asset_id": "65578135623666125364690190525767126679774364994694102050152165807381694053320", "price": "0.14", "size": "0", "side": "BUY", "hash": "d2386671526f9f275586713b03065050a66402ff", "best_bid": "0.31", "best_ask": "0.34"}, {"asset_id": "41699891447566493678062566391348854695286848129234610508637427753139123056608", "price": "0.86", "size": "0", "side": "SELL", "hash": "2221a38de2ea71f2cef9fcd09927d6bb1e30dfcc", "best_bid": "0.66", "best_ask": "0.69"}], "timestamp": "1769384063182", "event_type": "price_change"}}
{"_local_timestamp": "2026-01-25T23:34:23.643915+00:00", "data": {"market": "0x8d9b74d39735dd0b76542c31b81b9544c3eb954060b3c5790d24957538638145", "price_changes": [{"asset_id": "66829232893940327662461037379134988031891083237936281380951338917389315110298", "price": "0.015", "size": "0", "side": "BUY", "hash": "844e33a6259bfe99c21da2ea6ebb18b8a0262c85", "best_bid": "0.014", "best_ask": "0.017"}, {"asset_id": "587316473157103098403959848063967316493748298547115564222712976431944570953", "price": "0.985", "size": "0", "side": "SELL", "hash": "09224e7c3a8ab6c9a7792e86e9d44c2627663da5", "best_bid": "0.983", "best_ask": "0.986"}], "timestamp": "1769384063575", "event_type": "price_change"}}
{"_local_timestamp": "2026-01-25T23:34:23.672713+00:00", "data": {"market": "0x8d9b74d39735dd0b76542c31b81b9544c3eb954060b3c5790d24957538638145", "price_changes": [{"asset_id": "66829232893940327662461037379134988031891083237936281380951338917389315110298", "price": "0.015", "size": "303", "side": "BUY", "hash": "c48af4420700c424f88e3c27aa081a1029c79621", "best_bid": "0.015", "best_ask": "0.017"}, {"asset_id": "587316473157103098403959848063967316493748298547115564222712976431944570953", "price": "0.985", "size": "303", "side": "SELL", "hash": "1080ee7af5fa2f33048dc991c497ee14b2ab2e33", "best_bid": "0.983", "best_ask": "0.985"}], "timestamp": "1769384063600", "event_type": "price_change"}}
{"_local_timestamp": "2026-01-25T23:34:24.095132+00:00", "data": {"market": "0xcc25bf2f9c735a18c35969e330c0d917eec97fb93ea9422a0a0ed2b3f0eada54", "price_changes": [{"asset_id": "65578135623666125364690190525767126679774364994694102050152165807381694053320", "price": "0.35", "size": "38.5", "side": "SELL", "hash": "dd2b1e294160615b64692c16fcdd8c863ff075c4", "best_bid": "0.31", "best_ask": "0.34"}, {"asset_id": "41699891447566493678062566391348854695286848129234610508637427753139123056608", "price": "0.65", "size": "38.5", "side": "BUY", "hash": "6d54c74ff721abc77f518aeddf8ce34f26559c74", "best_bid": "0.66", "best_ask": "0.69"}], "timestamp": "1769384064006", "event_type": "price_change"}}
{"_local_timestamp": "2026-01-25T23:34:24.531306+00:00", "data": {"market": "0xcc25bf2f9c735a18c35969e330c0d917eec97fb93ea9422a0a0ed2b3f0eada54", "price_changes": [{"asset_id": "65578135623666125364690190525767126679774364994694102050152165807381694053320", "price": "0.34", "size": "229.99", "side": "SELL", "hash": "abfe279ebc41c952b45c45438925f5a966210ff5", "best_bid": "0.31", "best_ask": "0.34"}, {"asset_id": "41699891447566493678062566391348854695286848129234610508637427753139123056608", "price": "0.66", "size": "229.99", "side": "BUY", "hash": "44b4a520da30f4ee48e75596743cb164ad1bdf5c", "best_bid": "0.66", "best_ask": "0.69"}], "timestamp": "1769384064455", "event_type": "price_change"}}
{"_local_timestamp": "2026-01-25T23:34:25.039749+00:00", "data": {"market": "0xcc25bf2f9c735a18c35969e330c0d917eec97fb93ea9422a0a0ed2b3f0eada54", "price_changes": [{"asset_id": "65578135623666125364690190525767126679774364994694102050152165807381694053320", "price": "0.35", "size": "8.5", "side": "SELL", "hash": "c3730b5942fe1255368ca032fc84ba70ec8154bc", "best_bid": "0.31", "best_ask": "0.34"}, {"asset_id": "41699891447566493678062566391348854695286848129234610508637427753139123056608", "price": "0.65", "size": "8.5", "side": "BUY", "hash": "62057b892d757b2caad76f9e9c89a6815bc37822", "best_bid": "0.66", "best_ask": "0.69"}], "timestamp": "1769384064968", "event_type": "price_change"}}
{"_local_timestamp": "2026-01-25T23:34:25.134284+00:00", "data": {"market": "0xcc25bf2f9c735a18c35969e330c0d917eec97fb93ea9422a0a0ed2b3f0eada54", "price_changes": [{"asset_id": "65578135623666125364690190525767126679774364994694102050152165807381694053320", "price": "0.33", "size": "30", "side": "SELL", "hash": "78eb7c64c747a43eba327883cbd8803817fce696", "best_bid": "0.31", "best_ask": "0.33"}, {"asset_id": "41699891447566493678062566391348854695286848129234610508637427753139123056608", "price": "0.67", "size": "30", "side": "BUY", "hash": "ac5545d7118486458f0fe1911fd7092aba188a9f", "best_bid": "0.67", "best_ask": "0.69"}], "timestamp": "1769384065060", "event_type": "price_change"}}
{"_local_timestamp": "2026-01-25T23:34:25.148848+00:00", "data": {"market": "0x8d9b74d39735dd0b76542c31b81b9544c3eb954060b3c5790d24957538638145", "price_changes": [{"asset_id": "66829232893940327662461037379134988031891083237936281380951338917389315110298", "price": "0.015", "size": "0", "side": "BUY", "hash": "8bfe5226a1609b198dbbaf5633cc6db293fb1c6c", "best_bid": "0.014", "best_ask": "0.017"}, {"asset_id": "587316473157103098403959848063967316493748298547115564222712976431944570953", "price": "0.985", "size": "0", "side": "SELL", "hash": "343e9e02f350f29019cdeae2933d8d8b91a4eef7", "best_bid": "0.983", "best_ask": "0.986"}], "timestamp": "1769384065077", "event_type": "price_change"}}
{"_local_timestamp": "2026-01-25T23:34:25.176670+00:00", "data": {"market": "0x8d9b74d39735dd0b76542c31b81b9544c3eb954060b3c5790d24957538638145", "price_changes": [{"asset_id": "66829232893940327662461037379134988031891083237936281380951338917389315110298", "price": "0.015", "size": "303", "side": "BUY", "hash": "22dc5705fe6c9f2b640274539e0249ae1dd1a868", "best_bid": "0.015", "best_ask": "0.017"}, {"asset_id": "587316473157103098403959848063967316493748298547115564222712976431944570953", "price": "0.985", "size": "303", "side": "SELL", "hash": "792ef3259e7e1c832de460cfb4973e3778959023", "best_bid": "0.983", "best_ask": "0.985"}], "timestamp": "1769384065108", "event_type": "price_change"}}
{"_local_timestamp": "2026-01-25T23:34:26.663268+00:00", "data": {"market": "0x8d9b74d39735dd0b76542c31b81b9544c3eb954060b3c5790d24957538638145", "price_changes": [{"asset_id": "66829232893940327662461037379134988031891083237936281380951338917389315110298", "price": "0.015", "size": "0", "side": "BUY", "hash": "15cc704772d939685b636bc153ad2f8657a7ef3f", "best_bid": "0.014", "best_ask": "0.017"}, {"asset_id": "587316473157103098403959848063967316493748298547115564222712976431944570953", "price": "0.985", "size": "0", "side": "SELL", "hash": "dbaee3c301a9b53957a1abf520aa5122a433001f", "best_bid": "0.983", "best_ask": "0.986"}], "timestamp": "1769384066576", "event_type": "price_change"}}
{"_local_timestamp": "2026-01-25T23:34:26.723626+00:00", "data": {"market": "0x8d9b74d39735dd0b76542c31b81b9544c3eb954060b3c5790d24957538638145", "price_changes": [{"asset_id": "66829232893940327662461037379134988031891083237936281380951338917389315110298", "price": "0.015", "size": "303", "side": "BUY", "hash": "5dd9fe0637c3ca68d483feafb00ecf0ca59b20d2", "best_bid": "0.015", "best_ask": "0.017"}, {"asset_id": "587316473157103098403959848063967316493748298547115564222712976431944570953", "price": "0.985", "size": "303", "side": "SELL", "hash": "4e7d0a661ae9f88d8900707fe48e0f3bb2473473", "best_bid": "0.983", "best_ask": "0.985"}], "timestamp": "1769384066637", "event_type": "price_change"}}
{"_local_timestamp": "2026-01-25T23:34:27.851198+00:00", "data": {"market": "0x5abe3287197d0a924707ce99130643c92751c209fc0e376c6700d6673b43ada5", "price_changes": [{"asset_id": "2791138143012434753446657502011224259420532252815498101697790519791539429743", "price": "0.34", "size": "108.82", "side": "BUY", "hash": "095cf1578c8d936486c0fa5d606171aff577c278", "best_bid": "0.76", "best_ask": "0.83"}, {"asset_id": "15631821676887099899145118278843400257602269360221049118391374890586669885976", "price": "0.66", "size": "108.82", "side": "SELL", "hash": "11b0f85c90dacd8d233d0bd01432b483b1e04958", "best_bid": "0.17", "best_ask": "0.24"}], "timestamp": "1769384067594", "event_type": "price_change"}}
{"_local_timestamp": "2026-01-25T23:34:27.852283+00:00", "data": {"market": "0xcc25bf2f9c735a18c35969e330c0d917eec97fb93ea9422a0a0ed2b3f0eada54", "price_changes": [{"asset_id": "41699891447566493678062566391348854695286848129234610508637427753139123056608", "price": "0.28", "size": "50", "side": "BUY", "hash": "eae0b51c87cacfa7c95fb3bbe398a229f2778b51", "best_bid": "0.67", "best_ask": "0.69"}, {"asset_id": "65578135623666125364690190525767126679774364994694102050152165807381694053320", "price": "0.72", "size": "50", "side": "SELL", "hash": "bbe8fc5c78137bf8234223828961ddc2ff3a8e36", "best_bid": "0.31", "best_ask": "0.33"}], "timestamp": "1769384067603", "event_type": "price_change"}}
{"_local_timestamp": "2026-01-25T23:34:27.915030+00:00", "data": {"market": "0xcc25bf2f9c735a18c35969e330c0d917eec97fb93ea9422a0a0ed2b3f0eada54", "price_changes": [{"asset_id": "41699891447566493678062566391348854695286848129234610508637427753139123056608", "price": "0.52", "size": "30", "side": "BUY", "hash": "4c244514b4717622e600930d7b8662d9ff019286", "best_bid": "0.67", "best_ask": "0.69"}, {"asset_id": "65578135623666125364690190525767126679774364994694102050152165807381694053320", "price": "0.48", "size": "30", "side": "SELL", "hash": "d122af122c62c7c42370acf8f5efa86d67dcd496", "best_bid": "0.31", "best_ask": "0.33"}], "timestamp": "1769384067696", "event_type": "price_change"}}
{"_local_timestamp": "2026-01-25T23:34:27.948710+00:00", "data": {"market": "0x5abe3287197d0a924707ce99130643c92751c209fc0e376c6700d6673b43ada5", "price_changes": [{"asset_id": "15631821676887099899145118278843400257602269360221049118391374890586669885976", "price": "0.38", "size": "0", "side": "SELL", "hash": "ea7c3b7e984bd51fc4aef401573ff9df24869fad", "best_bid": "0.17", "best_ask": "0.24"}, {"asset_id": "2791138143012434753446657502011224259420532252815498101697790519791539429743", "price": "0.62", "size": "0", "side": "BUY", "hash": "9e70f16003de26adc532796cdf48a43b1378ad9d", "best_bid": "0.76", "best_ask": "0.83"}], "timestamp": "1769384067791", "event_type": "price_change"}}
{"_local_timestamp": "2026-01-25T23:34:27.976335+00:00", "data": {"market": "0x5abe3287197d0a924707ce99130643c92751c209fc0e376c6700d6673b43ada5", "price_changes": [{"asset_id": "15631821676887099899145118278843400257602269360221049118391374890586669885976", "price": "0.42", "size": "146", "side": "SELL", "hash": "7522741212734d12b8cb94677d9a36d5d4079aab", "best_bid": "0.17", "best_ask": "0.24"}, {"asset_id": "2791138143012434753446657502011224259420532252815498101697790519791539429743", "price": "0.58", "size": "146", "side": "BUY", "hash": "ed5e85217bd40e7ee7904ff6e2c7de2b2496c20e", "best_bid": "0.76", "best_ask": "0.83"}], "timestamp": "1769384067833", "event_type": "price_change"}}
{"_local_timestamp": "2026-01-25T23:34:28.079713+00:00", "data": {"market": "0xcc25bf2f9c735a18c35969e330c0d917eec97fb93ea9422a0a0ed2b3f0eada54", "price_changes": [{"asset_id": "41699891447566493678062566391348854695286848129234610508637427753139123056608", "price": "0.66", "size": "199.99", "side": "BUY", "hash": "5dc1177c7d827fbe06152c60fa004e0c887d6099", "best_bid": "0.67", "best_ask": "0.69"}, {"asset_id": "65578135623666125364690190525767126679774364994694102050152165807381694053320", "price": "0.34", "size": "199.99", "side": "SELL", "hash": "18f0981d0a62ed878cf7972241c00b9126ced914", "best_bid": "0.31", "best_ask": "0.33"}], "timestamp": "1769384067996", "event_type": "price_change"}}
{"_local_timestamp": "2026-01-25T23:34:28.165117+00:00", "data": {"market": "0x8d9b74d39735dd0b76542c31b81b9544c3eb954060b3c5790d24957538638145", "price_changes": [{"asset_id": "66829232893940327662461037379134988031891083237936281380951338917389315110298", "price": "0.015", "size": "0", "side": "BUY", "hash": "bf5ae149a65a3de493cc7cb4f82f9ce6bce38534", "best_bid": "0.014", "best_ask": "0.017"}, {"asset_id": "587316473157103098403959848063967316493748298547115564222712976431944570953", "price": "0.985", "size": "0", "side": "SELL", "hash": "4af982c29ac374838cdf960c416c2821cf4e3cff", "best_bid": "0.983", "best_ask": "0.986"}], "timestamp": "1769384068076", "event_type": "price_change"}}
{"_local_timestamp": "2026-01-25T23:34:28.214408+00:00", "data": {"market": "0x8d9b74d39735dd0b76542c31b81b9544c3eb954060b3c5790d24957538638145", "price_changes": [{"asset_id": "66829232893940327662461037379134988031891083237936281380951338917389315110298", "price": "0.015", "size": "303", "side": "BUY", "hash": "e9024dc42126cfd849e64aba6e5b6453ab27753b", "best_bid": "0.015", "best_ask": "0.017"}, {"asset_id": "587316473157103098403959848063967316493748298547115564222712976431944570953", "price": "0.985", "size": "303", "side": "SELL", "hash": "4028791954043fb7918cd49e22ae5e91eee9ffa3", "best_bid": "0.983", "best_ask": "0.985"}], "timestamp": "1769384068132", "event_type": "price_change"}}
{"_local_timestamp": "2026-01-25T23:34:28.474068+00:00", "data": {"market": "0x5abe3287197d0a924707ce99130643c92751c209fc0e376c6700d6673b43ada5", "price_changes": [{"asset_id": "2791138143012434753446657502011224259420532252815498101697790519791539429743", "price": "0.35", "size": "225", "side": "BUY", "hash": "43952a9077b2ad2a5e34bf251278a4b27be408db", "best_bid": "0.76", "best_ask": "0.83"}, {"asset_id": "15631821676887099899145118278843400257602269360221049118391374890586669885976", "price": "0.65", "size": "225", "side": "SELL", "hash": "a26e76e73456087288d3a8b7b6afb762e99da155", "best_bid": "0.17", "best_ask": "0.24"}], "timestamp": "1769384068140", "event_type": "price_change"}}
{"_local_timestamp": "2026-01-25T23:34:28.485367+00:00", "data": {"market": "0xf3b4662d12f86894b31d52b454428c91733c166ba05c4e3bccc375f78411601a", "price_changes": [{"asset_id": "55382819090443168507206409119841525953451022223003224583889620760999266943524", "price": "0.24", "size": "358.33", "side": "BUY", "hash": "d3c3ec5d99342970877a5205cd3a4c2dd873099f", "best_bid": "0.727", "best_ask": "0.785"}, {"asset_id": "30441349073423271296409239412402830197110444658615254085853491470932508604811", "price": "0.76", "size": "358.33", "side": "SELL", "hash": "54143c20a068fa9c3d0395e7e035e7d46f1070d9", "best_bid": "0.215", "best_ask": "0.273"}], "timestamp": "1769384068145", "event_type": "price_change"}}
{"_local_timestamp": "2026-01-25T23:34:28.693878+00:00", "data": {"market": "0xf3b4662d12f86894b31d52b454428c91733c166ba05c4e3bccc375f78411601a", "price_changes": [{"asset_id": "55382819090443168507206409119841525953451022223003224583889620760999266943524", "price": "0.32", "size": "137.5", "side": "BUY", "hash": "319846608974abc247bcf0ba252bf80a77ebd814", "best_bid": "0.727", "best_ask": "0.785"}, {"asset_id": "30441349073423271296409239412402830197110444658615254085853491470932508604811", "price": "0.68", "size": "137.5", "side": "SELL", "hash": "872a5c4f3a70d70581f689f5170777e43b5be027", "best_bid": "0.215", "best_ask": "0.273"}], "timestamp": "1769384068223", "event_type": "price_change"}}
{"_local_timestamp": "2026-01-25T23:34:28.891843+00:00", "data": {"market": "0xc954c52447b5856106b45c55df1003b48a583af3b4772bda1de20e0a95ad5f45", "price_changes": [{"asset_id": "9302610255531462617274536528837506482521823261381921527179585793339878975949", "price": "0.001", "size": "17005.99", "side": "BUY", "hash": "1541b4b926a0d1483d9f98090002cac017b5aadd", "best_bid": "0.021", "best_ask": "0.052"}, {"asset_id": "52417019033358898530053799473085644762541010045525203660683879224996320434909", "price": "0.999", "size": "17005.99", "side": "SELL", "hash": "e2cf0ee1bbfcbdeab49487aaf46d19a03d54ca19", "best_bid": "0.948", "best_ask": "0.979"}], "timestamp": "1769384068473", "event_type": "price_change"}}
{"_local_timestamp": "2026-01-25T23:34:28.894567+00:00", "data": {"market": "0xc954c52447b5856106b45c55df1003b48a583af3b4772bda1de20e0a95ad5f45", "price_changes": [{"asset_id": "9302610255531462617274536528837506482521823261381921527179585793339878975949", "price": "0.007", "size": "0", "side": "BUY", "hash": "1541b4b926a0d1483d9f98090002cac017b5aadd", "best_bid": "0.021", "best_ask": "0.052"}, {"asset_id": "52417019033358898530053799473085644762541010045525203660683879224996320434909", "price": "0.993", "size": "0", "side": "SELL", "hash": "e2cf0ee1bbfcbdeab49487aaf46d19a03d54ca19", "best_bid": "0.948", "best_ask": "0.979"}], "timestamp": "1769384068473", "event_type": "price_change"}}
{"_local_timestamp": "2026-01-25T23:34:28.895723+00:00", "data": {"market": "0xc954c52447b5856106b45c55df1003b48a583af3b4772bda1de20e0a95ad5f45", "price_changes": [{"asset_id": "9302610255531462617274536528837506482521823261381921527179585793339878975949", "price": "0.012", "size": "0", "side": "BUY", "hash": "1541b4b926a0d1483d9f98090002cac017b5aadd", "best_bid": "0.021", "best_ask": "0.052"}, {"asset_id": "52417019033358898530053799473085644762541010045525203660683879224996320434909", "price": "0.988", "size": "0", "side": "SELL", "hash": "e2cf0ee1bbfcbdeab49487aaf46d19a03d54ca19", "best_bid": "0.948", "best_ask": "0.979"}], "timestamp": "1769384068473", "event_type": "price_change"}}
{"_local_timestamp": "2026-01-25T23:34:28.896517+00:00", "data": {"market": "0xcc25bf2f9c735a18c35969e330c0d917eec97fb93ea9422a0a0ed2b3f0eada54", "price_changes": [{"asset_id": "65578135623666125364690190525767126679774364994694102050152165807381694053320", "price": "0.34", "size": "0", "side": "SELL", "hash": "e030f9dd58d546f847e60010e782b8e3931c02c9", "best_bid": "0.31", "best_ask": "0.33"}, {"asset_id": "41699891447566493678062566391348854695286848129234610508637427753139123056608", "price": "0.66", "size": "0", "side": "BUY", "hash": "e4923d68205a23e28bb70ba08662eb3b5c7509fd", "best_bid": "0.67", "best_ask": "0.69"}], "timestamp": "1769384068476", "event_type": "price_change"}}
{"_local_timestamp": "2026-01-25T23:34:28.902114+00:00", "data": {"market": "0x5abe3287197d0a924707ce99130643c92751c209fc0e376c6700d6673b43ada5", "price_changes": [{"asset_id": "15631821676887099899145118278843400257602269360221049118391374890586669885976", "price": "0.64", "size": "100", "side": "SELL", "hash": "7e62c24761e69ec166cda96175ee9315b75ad499", "best_bid": "0.17", "best_ask": "0.24"}, {"asset_id": "2791138143012434753446657502011224259420532252815498101697790519791539429743", "price": "0.36", "size": "100", "side": "BUY", "hash": "3a26cf1d13494ba0d0d83ca32ac397120c28eaac", "best_bid": "0.76", "best_ask": "0.83"}], "timestamp": "1769384068476", "event_type": "price_change"}}
{"_local_timestamp": "2026-01-25T23:34:29.135530+00:00", "data": {"market": "0x5abe3287197d0a924707ce99130643c92751c209fc0e376c6700d6673b43ada5", "price_changes": [{"asset_id": "15631821676887099899145118278843400257602269360221049118391374890586669885976", "price": "0.41", "size": "199.99", "side": "SELL", "hash": "f7ec854787c52d74a2010cd2bdef9fb0227b066f", "best_bid": "0.17", "best_ask": "0.24"}, {"asset_id": "2791138143012434753446657502011224259420532252815498101697790519791539429743", "price": "0.59", "size": "199.99", "side": "BUY", "hash": "94b17db8ed52f4a5ebd3bf44de7b529dfe56f9b0", "best_bid": "0.76", "best_ask": "0.83"}], "timestamp": "1769384068899", "event_type": "price_change"}}
{"_local_timestamp": "2026-01-25T23:34:29.136680+00:00", "data": {"market": "0x29fcb3cb3301dde656aaaf7d185bb56c9b6948968b9d95f87f3942355b6bf360", "price_changes": [{"asset_id": "91783318584258680143008562461721551652033317272474793227511040505886797754334", "price": "0.003", "size": "64.5", "side": "BUY", "hash": "72572ac6c97efbd946d9b55237914159b3aecd8e", "best_bid": "0.021", "best_ask": "0.045"}, {"asset_id": "92691123413763856836301118436801979285373127205354327950605601494440683568501", "price": "0.997", "size": "64.5", "side": "SELL", "hash": "09e0be628037fb5e54a5c8f86d67bd9cd21e5a2c", "best_bid": "0.955", "best_ask": "0.979"}], "timestamp": "1769384068903", "event_type": "price_change"}}
{"_local_timestamp": "2026-01-25T23:34:29.138393+00:00", "data": {"market": "0x43aad651177544538b5b35dc3239d1631fca344147c0ffe0e416cd0eb51fca6d", "price_changes": [{"asset_id": "76997947933304274428562592491730603768950795614322500110266632020523223203438", "price": "0.02", "size": "1500", "side": "BUY", "hash": "b55e26e69bdb8a3b6f30418c589817104cd4aed6", "best_bid": "0.05", "best_ask": "0.09"}, {"asset_id": "63034252779590173880584393179377300106700707654931663433396190240990856358223", "price": "0.98", "size": "1500", "side": "SELL", "hash": "ebe0074cfaa1e69eea6aeabfae6467668be0723e", "best_bid": "0.91", "best_ask": "0.95"}], "timestamp": "1769384068904", "event_type": "price_change"}}
{"_local_timestamp": "2026-01-25T23:34:29.139151+00:00", "data": {"market": "0x43aad651177544538b5b35dc3239d1631fca344147c0ffe0e416cd0eb51fca6d", "price_changes": [{"asset_id": "76997947933304274428562592491730603768950795614322500110266632020523223203438", "price": "0.05", "size": "25", "side": "BUY", "hash": "b55e26e69bdb8a3b6f30418c589817104cd4aed6", "best_bid": "0.05", "best_ask": "0.09"}, {"asset_id": "63034252779590173880584393179377300106700707654931663433396190240990856358223", "price": "0.95", "size": "25", "side": "SELL", "hash": "ebe0074cfaa1e69eea6aeabfae6467668be0723e", "best_bid": "0.91", "best_ask": "0.95"}], "timestamp": "1769384068904", "event_type": "price_change"}}
{"_local_timestamp": "2026-01-25T23:34:29.139840+00:00", "data": {"market": "0xcc25bf2f9c735a18c35969e330c0d917eec97fb93ea9422a0a0ed2b3f0eada54", "price_changes": [{"asset_id": "65578135623666125364690190525767126679774364994694102050152165807381694053320", "price": "0.48", "size": "229.99", "side": "SELL", "hash": "fad50b40b83cd4711aa0e1c9cc64dd8d8ebff44b", "best_bid": "0.31", "best_ask": "0.33"}, {"asset_id": "41699891447566493678062566391348854695286848129234610508637427753139123056608", "price": "0.52", "size": "229.99", "side": "BUY", "hash": "f4bc2a1e96dda685063cd1e4d870ff444ae9cf8e", "best_bid": "0.67", "best_ask": "0.69"}], "timestamp": "1769384068912", "event_type": "price_change"}}
{"_local_timestamp": "2026-01-25T23:34:29.142775+00:00", "data": {"market": "0x5abe3287197d0a924707ce99130643c92751c209fc0e376c6700d6673b43ada5", "price_changes": [{"asset_id": "2791138143012434753446657502011224259420532252815498101697790519791539429743", "price": "0.36", "size": "0", "side": "BUY", "hash": "58d427c58a2fe6570f0b9006b64cd736c753f99f", "best_bid": "0.76", "best_ask": "0.83"}, {"asset_id": "15631821676887099899145118278843400257602269360221049118391374890586669885976", "price": "0.64", "size": "0", "side": "SELL", "hash": "67cd15e6176a576d2a6601a832dffbb54663dc8a", "best_bid": "0.17", "best_ask": "0.24"}], "timestamp": "1769384068947", "event_type": "price_change"}}
{"_local_timestamp": "2026-01-25T23:34:29.198446+00:00", "data": {"market": "0x5abe3287197d0a924707ce99130643c92751c209fc0e376c6700d6673b43ada5", "price_changes": [{"asset_id": "15631821676887099899145118278843400257602269360221049118391374890586669885976", "price": "0.42", "size": "30", "side": "SELL", "hash": "dfca0a97ea7b3123bef29380904be7673a70fe71", "best_bid": "0.17", "best_ask": "0.24"}, {"asset_id": "2791138143012434753446657502011224259420532252815498101697790519791539429743", "price": "0.58", "size": "30", "side": "BUY", "hash": "b18ca70cc14eea4f56ba2ddfd918c84851b9857d", "best_bid": "0.76", "best_ask": "0.83"}], "timestamp": "1769384069087", "event_type": "price_change"}}
{"_local_timestamp": "2026-01-25T23:34:29.200073+00:00", "data": {"market": "0x5abe3287197d0a924707ce99130643c92751c209fc0e376c6700d6673b43ada5", "price_changes": [{"asset_id": "15631821676887099899145118278843400257602269360221049118391374890586669885976", "price": "0.4", "size": "126", "side": "SELL", "hash": "9011c760a1f064a1e2e077c66e524ec94e786f4a", "best_bid": "0.17", "best_ask": "0.24"}, {"asset_id": "2791138143012434753446657502011224259420532252815498101697790519791539429743", "price": "0.6", "size": "126", "side": "BUY", "hash": "34250e6cca2c5563471c0325afa3d22780f7c3f4", "best_bid": "0.76", "best_ask": "0.83"}], "timestamp": "1769384069114", "event_type": "price_change"}}
{"_local_timestamp": "2026-01-25T23:34:29.656494+00:00", "data": {"market": "0x8d9b74d39735dd0b76542c31b81b9544c3eb954060b3c5790d24957538638145", "price_changes": [{"asset_id": "66829232893940327662461037379134988031891083237936281380951338917389315110298", "price": "0.015", "size": "0", "side": "BUY", "hash": "ed3444a888ada7919969f2590cea913a015243ca", "best_bid": "0.014", "best_ask": "0.017"}, {"asset_id": "587316473157103098403959848063967316493748298547115564222712976431944570953", "price": "0.985", "size": "0", "side": "SELL", "hash": "41ee1be4e652311d1c92540c1b5e4e9f02aeed0d", "best_bid": "0.983", "best_ask": "0.986"}], "timestamp": "1769384069579", "event_type": "price_change"}}
{"_local_timestamp": "2026-01-25T23:34:29.710871+00:00", "data": {"market": "0x8d9b74d39735dd0b76542c31b81b9544c3eb954060b3c5790d24957538638145", "price_changes": [{"asset_id": "66829232893940327662461037379134988031891083237936281380951338917389315110298", "price": "0.015", "size": "303", "side": "BUY", "hash": "72d08cd4608c1ba34475d0aa3f899d65b42cec72", "best_bid": "0.015", "best_ask": "0.017"}, {"asset_id": "587316473157103098403959848063967316493748298547115564222712976431944570953", "price": "0.985", "size": "303", "side": "SELL", "hash": "fe0a9e2efb2e07085870898a6bb7e061d33f8acd", "best_bid": "0.983", "best_ask": "0.985"}], "timestamp": "1769384069610", "event_type": "price_change"}}
{"_local_timestamp": "2026-01-25T23:34:29.761553+00:00", "data": {"market": "0x5abe3287197d0a924707ce99130643c92751c209fc0e376c6700d6673b43ada5", "price_changes": [{"asset_id": "2791138143012434753446657502011224259420532252815498101697790519791539429743", "price": "0.59", "size": "299.99", "side": "BUY", "hash": "bf76d77226ab960381b1ad2b836cad29e550d1a1", "best_bid": "0.76", "best_ask": "0.83"}, {"asset_id": "15631821676887099899145118278843400257602269360221049118391374890586669885976", "price": "0.41", "size": "299.99", "side": "SELL", "hash": "cbe0008b3aea1a80097857728eb79cef25bfdcb6", "best_bid": "0.17", "best_ask": "0.24"}], "timestamp": "1769384069634", "event_type": "price_change"}}
{"_local_timestamp": "2026-01-25T23:34:29.949124+00:00", "data": {"market": "0xcc25bf2f9c735a18c35969e330c0d917eec97fb93ea9422a0a0ed2b3f0eada54", "price_changes": [{"asset_id": "65578135623666125364690190525767126679774364994694102050152165807381694053320", "price": "0.33", "size": "0", "side": "SELL", "hash": "f2e35fc6dadbc358a78702b648986bee6f908dbd", "best_bid": "0.31", "best_ask": "0.35"}, {"asset_id": "41699891447566493678062566391348854695286848129234610508637427753139123056608", "price": "0.67", "size": "0", "side": "BUY", "hash": "81d77cb53be905b01b40f8339d41d1c83458eb0b", "best_bid": "0.65", "best_ask": "0.69"}], "timestamp": "1769384069759", "event_type": "price_change"}}
{"_local_timestamp": "2026-01-25T23:34:30.010546+00:00", "data": {"market": "0xcc25bf2f9c735a18c35969e330c0d917eec97fb93ea9422a0a0ed2b3f0eada54", "price_changes": [{"asset_id": "65578135623666125364690190525767126679774364994694102050152165807381694053320", "price": "0.37", "size": "30", "side": "SELL", "hash": "c9484c3edbf49fd9f4c809663b1b5f939f60fd00", "best_bid": "0.31", "best_ask": "0.35"}, {"asset_id": "41699891447566493678062566391348854695286848129234610508637427753139123056608", "price": "0.63", "size": "30", "side": "BUY", "hash": "b31d0aa289436063cd486fc0a386ce038a6cf3f0", "best_bid": "0.65", "best_ask": "0.69"}], "timestamp": "1769384069827", "event_type": "price_change"}}
{"_local_timestamp": "2026-01-25T23:34:30.260540+00:00", "data": {"market": "0xcc25bf2f9c735a18c35969e330c0d917eec97fb93ea9422a0a0ed2b3f0eada54", "price_changes": [{"asset_id": "65578135623666125364690190525767126679774364994694102050152165807381694053320", "price": "0.14", "size": "142.85", "side": "BUY", "hash": "a7705c576ed573c31d9e78895977fa4dcee9a24f", "best_bid": "0.31", "best_ask": "0.35"}, {"asset_id": "41699891447566493678062566391348854695286848129234610508637427753139123056608", "price": "0.86", "size": "142.85", "side": "SELL", "hash": "ba199552993a4b907e71f58607b249dc5745578b", "best_bid": "0.65", "best_ask": "0.69"}], "timestamp": "1769384070104", "event_type": "price_change"}}
{"_local_timestamp": "2026-01-25T23:34:30.326189+00:00", "data": {"market": "0xcc25bf2f9c735a18c35969e330c0d917eec97fb93ea9422a0a0ed2b3f0eada54", "price_changes": [{"asset_id": "65578135623666125364690190525767126679774364994694102050152165807381694053320", "price": "0.12", "size": "616", "side": "BUY", "hash": "5f95391967f516bca063e4227313f6695e2aa443", "best_bid": "0.31", "best_ask": "0.35"}, {"asset_id": "41699891447566493678062566391348854695286848129234610508637427753139123056608", "price": "0.88", "size": "616", "side": "SELL", "hash": "d03b31006530e38ddfc74264bf8ba227e5c630bf", "best_bid": "0.65", "best_ask": "0.69"}], "timestamp": "1769384070154", "event_type": "price_change"}}
{"_local_timestamp": "2026-01-25T23:34:30.393448+00:00", "data": {"market": "0xcc25bf2f9c735a18c35969e330c0d917eec97fb93ea9422a0a0ed2b3f0eada54", "price_changes": [{"asset_id": "65578135623666125364690190525767126679774364994694102050152165807381694053320", "price": "0.11", "size": "236.36", "side": "BUY", "hash": "8c0ebe35c1ad29386b19361155ab03b972ce0090", "best_bid": "0.31", "best_ask": "0.35"}, {"asset_id": "41699891447566493678062566391348854695286848129234610508637427753139123056608", "price": "0.89", "size": "236.36", "side": "SELL", "hash": "f37d1911fb432cfe065939c7d79e23b6e4821cd8", "best_bid": "0.65", "best_ask": "0.69"}], "timestamp": "1769384070210", "event_type": "price_change"}}
{"_local_timestamp": "2026-01-25T23:34:30.433394+00:00", "data": {"market": "0xcc25bf2f9c735a18c35969e330c0d917eec97fb93ea9422a0a0ed2b3f0eada54", "price_changes": [{"asset_id": "65578135623666125364690190525767126679774364994694102050152165807381694053320", "price": "0.09", "size": "311.11", "side": "BUY", "hash": "f80f9d657cd675cc6d0172b70b945831abc80c30", "best_bid": "0.31", "best_ask": "0.35"}, {"asset_id": "41699891447566493678062566391348854695286848129234610508637427753139123056608", "price": "0.91", "size": "311.11", "side": "SELL", "hash": "f906d433affb72835af79832fef20933df011329", "best_bid": "0.65", "best_ask": "0.69"}], "timestamp": "1769384070251", "event_type": "price_change"}}
{"_local_timestamp": "2026-01-25T23:34:30.472564+00:00", "data": {"market": "0xcc25bf2f9c735a18c35969e330c0d917eec97fb93ea9422a0a0ed2b3f0eada54", "price_changes": [{"asset_id": "65578135623666125364690190525767126679774364994694102050152165807381694053320", "price": "0.07", "size": "457.14", "side": "BUY", "hash": "b19bef4e8e7d1a423f913bb97fa24fbeda61db0e", "best_bid": "0.31", "best_ask": "0.35"}, {"asset_id": "41699891447566493678062566391348854695286848129234610508637427753139123056608", "price": "0.93", "size": "457.14", "side": "SELL", "hash": "135b96d8559897aff3286f7946ba63fe3f3731ec", "best_bid": "0.65", "best_ask": "0.69"}], "timestamp": "1769384070302", "event_type": "price_change"}}
{"_local_timestamp": "2026-01-25T23:34:30.525406+00:00", "data": {"market": "0xcc25bf2f9c735a18c35969e330c0d917eec97fb93ea9422a0a0ed2b3f0eada54", "price_changes": [{"asset_id": "65578135623666125364690190525767126679774364994694102050152165807381694053320", "price": "0.05", "size": "680", "side": "BUY", "hash": "3de48f26c69f3d3dd0c2cf274bf32663bfa25b85", "best_bid": "0.31", "best_ask": "0.35"}, {"asset_id": "41699891447566493678062566391348854695286848129234610508637427753139123056608", "price": "0.95", "size": "680", "side": "SELL", "hash": "0eced9ca6e31d32802a81f1d9b6f439e0d8b4350", "best_bid": "0.65", "best_ask": "0.69"}], "timestamp": "1769384070355", "event_type": "price_change"}}
{"_local_timestamp": "2026-01-25T23:34:30.607484+00:00", "data": {"market": "0xcc25bf2f9c735a18c35969e330c0d917eec97fb93ea9422a0a0ed2b3f0eada54", "price_changes": [{"asset_id": "65578135623666125364690190525767126679774364994694102050152165807381694053320", "price": "0.03", "size": "1328", "side": "BUY", "hash": "e092c44c914ac3595b18165e9f7c2ad77c684cc9", "best_bid": "0.31", "best_ask": "0.35"}, {"asset_id": "41699891447566493678062566391348854695286848129234610508637427753139123056608", "price": "0.97", "size": "1328", "side": "SELL", "hash": "d795750f5cf840b6a3ea4d6432f517af6be8888d", "best_bid": "0.65", "best_ask": "0.69"}], "timestamp": "1769384070403", "event_type": "price_change"}}
{"_local_timestamp": "2026-01-25T23:34:30.644659+00:00", "data": {"market": "0xcc25bf2f9c735a18c35969e330c0d917eec97fb93ea9422a0a0ed2b3f0eada54", "price_changes": [{"asset_id": "41699891447566493678062566391348854695286848129234610508637427753139123056608", "price": "0.65", "size": "0", "side": "BUY", "hash": "b5caa478c42a8332a58cbb3b94becc52a96df0f4", "best_bid": "0.64", "best_ask": "0.69"}, {"asset_id": "65578135623666125364690190525767126679774364994694102050152165807381694053320", "price": "0.35", "size": "0", "side": "SELL", "hash": "7a734a53e7d4eb1f12af28d725c8010582ec6c95", "best_bid": "0.31", "best_ask": "0.36"}], "timestamp": "1769384070497", "event_type": "price_change"}}
{"_local_timestamp": "2026-01-25T23:34:30.664728+00:00", "data": {"market": "0xcc25bf2f9c735a18c35969e330c0d917eec97fb93ea9422a0a0ed2b3f0eada54", "price_changes": [{"asset_id": "41699891447566493678062566391348854695286848129234610508637427753139123056608", "price": "0.67", "size": "8.5", "side": "BUY", "hash": "f94e5f1a2f2776613cf28b890354fe2ee831de03", "best_bid": "0.67", "best_ask": "0.69"}, {"asset_id": "65578135623666125364690190525767126679774364994694102050152165807381694053320", "price": "0.33", "size": "8.5", "side": "SELL", "hash": "a64ecbcc89b93aad972c5063b4db3867755d00bb", "best_bid": "0.31", "best_ask": "0.33"}], "timestamp": "1769384070535", "event_type": "price_change"}}
{"_local_timestamp": "2026-01-25T23:34:30.775065+00:00", "data": {"market": "0xcc25bf2f9c735a18c35969e330c0d917eec97fb93ea9422a0a0ed2b3f0eada54", "price_changes": [{"asset_id": "65578135623666125364690190525767126679774364994694102050152165807381694053320", "price": "0.14", "size": "0", "side": "BUY", "hash": "6280b8e32c6c228b5874ba14e51d4f6e074c5015", "best_bid": "0.31", "best_ask": "0.33"}, {"asset_id": "41699891447566493678062566391348854695286848129234610508637427753139123056608", "price": "0.86", "size": "0", "side": "SELL", "hash": "88e8447f639a913cd6913a6d36f35eb9ce3cc61a", "best_bid": "0.67", "best_ask": "0.69"}], "timestamp": "1769384070689", "event_type": "price_change"}}
{"_local_timestamp": "2026-01-25T23:34:30.777712+00:00", "data": {"market": "0xcc25bf2f9c735a18c35969e330c0d917eec97fb93ea9422a0a0ed2b3f0eada54", "price_changes": [{"asset_id": "65578135623666125364690190525767126679774364994694102050152165807381694053320", "price": "0.09", "size": "0", "side": "BUY", "hash": "6280b8e32c6c228b5874ba14e51d4f6e074c5015", "best_bid": "0.31", "best_ask": "0.33"}, {"asset_id": "41699891447566493678062566391348854695286848129234610508637427753139123056608", "price": "0.91", "size": "0", "side": "SELL", "hash": "88e8447f639a913cd6913a6d36f35eb9ce3cc61a", "best_bid": "0.67", "best_ask": "0.69"}], "timestamp": "1769384070689", "event_type": "price_change"}}
{"_local_timestamp": "2026-01-25T23:34:30.778481+00:00", "data": {"market": "0xcc25bf2f9c735a18c35969e330c0d917eec97fb93ea9422a0a0ed2b3f0eada54", "price_changes": [{"asset_id": "65578135623666125364690190525767126679774364994694102050152165807381694053320", "price": "0.05", "size": "0", "side": "BUY", "hash": "6280b8e32c6c228b5874ba14e51d4f6e074c5015", "best_bid": "0.31", "best_ask": "0.33"}, {"asset_id": "41699891447566493678062566391348854695286848129234610508637427753139123056608", "price": "0.95", "size": "0", "side": "SELL", "hash": "88e8447f639a913cd6913a6d36f35eb9ce3cc61a", "best_bid": "0.67", "best_ask": "0.69"}], "timestamp": "1769384070689", "event_type": "price_change"}}
{"_local_timestamp": "2026-01-25T23:34:30.779655+00:00", "data": {"market": "0xcc25bf2f9c735a18c35969e330c0d917eec97fb93ea9422a0a0ed2b3f0eada54", "price_changes": [{"asset_id": "65578135623666125364690190525767126679774364994694102050152165807381694053320", "price": "0.03", "size": "128", "side": "BUY", "hash": "6280b8e32c6c228b5874ba14e51d4f6e074c5015", "best_bid": "0.31", "best_ask": "0.33"}, {"asset_id": "41699891447566493678062566391348854695286848129234610508637427753139123056608", "price": "0.97", "size": "128", "side": "SELL", "hash": "88e8447f639a913cd6913a6d36f35eb9ce3cc61a", "best_bid": "0.67", "best_ask": "0.69"}], "timestamp": "1769384070689", "event_type": "price_change"}}
{"_local_timestamp": "2026-01-25T23:34:30.781105+00:00", "data": {"market": "0xcc25bf2f9c735a18c35969e330c0d917eec97fb93ea9422a0a0ed2b3f0eada54", "price_changes": [{"asset_id": "65578135623666125364690190525767126679774364994694102050152165807381694053320", "price": "0.12", "size": "416", "side": "BUY", "hash": "6280b8e32c6c228b5874ba14e51d4f6e074c5015", "best_bid": "0.31", "best_ask": "0.33"}, {"asset_id": "41699891447566493678062566391348854695286848129234610508637427753139123056608", "price": "0.88", "size": "416", "side": "SELL", "hash": "88e8447f639a913cd6913a6d36f35eb9ce3cc61a", "best_bid": "0.67", "best_ask": "0.69"}], "timestamp": "1769384070689", "event_type": "price_change"}}
{"_local_timestamp": "2026-01-25T23:34:30.781886+00:00", "data": {"market": "0xcc25bf2f9c735a18c35969e330c0d917eec97fb93ea9422a0a0ed2b3f0eada54", "price_changes": [{"asset_id": "65578135623666125364690190525767126679774364994694102050152165807381694053320", "price": "0.11", "size": "0", "side": "BUY", "hash": "6280b8e32c6c228b5874ba14e51d4f6e074c5015", "best_bid": "0.31", "best_ask": "0.33"}, {"asset_id": "41699891447566493678062566391348854695286848129234610508637427753139123056608", "price": "0.89", "size": "0", "side": "SELL", "hash": "88e8447f639a913cd6913a6d36f35eb9ce3cc61a", "best_bid": "0.67", "best_ask": "0.69"}], "timestamp": "1769384070689", "event_type": "price_change"}}
{"_local_timestamp": "2026-01-25T23:34:30.783908+00:00", "data": {"market": "0xcc25bf2f9c735a18c35969e330c0d917eec97fb93ea9422a0a0ed2b3f0eada54", "price_changes": [{"asset_id": "65578135623666125364690190525767126679774364994694102050152165807381694053320", "price": "0.07", "size": "0", "side": "BUY", "hash": "6280b8e32c6c228b5874ba14e51d4f6e074c5015", "best_bid": "0.31", "best_ask": "0.33"}, {"asset_id": "41699891447566493678062566391348854695286848129234610508637427753139123056608", "price": "0.93", "size": "0", "side": "SELL", "hash": "88e8447f639a913cd6913a6d36f35eb9ce3cc61a", "best_bid": "0.67", "best_ask": "0.69"}], "timestamp": "1769384070689", "event_type": "price_change"}}
{"_local_timestamp": "2026-01-25T23:34:30.825711+00:00", "data": {"market": "0xc954c52447b5856106b45c55df1003b48a583af3b4772bda1de20e0a95ad5f45", "price_changes": [{"asset_id": "9302610255531462617274536528837506482521823261381921527179585793339878975949", "price": "0.008", "size": "83.19", "side": "BUY", "hash": "7d829b1943e4c4422285f7cd1268e6c315402633", "best_bid": "0.021", "best_ask": "0.052"}, {"asset_id": "52417019033358898530053799473085644762541010045525203660683879224996320434909", "price": "0.992", "size": "83.19", "side": "SELL", "hash": "afc88aa5d9f33452e9b87332b989fef1890963e1", "best_bid": "0.948", "best_ask": "0.979"}], "timestamp": "1769384070755", "event_type": "price_change"}}
{"_local_timestamp": "2026-01-25T23:34:30.831627+00:00", "data": {"market": "0xc954c52447b5856106b45c55df1003b48a583af3b4772bda1de20e0a95ad5f45", "price_changes": [{"asset_id": "9302610255531462617274536528837506482521823261381921527179585793339878975949", "price": "0.006", "size": "15.72", "side": "BUY", "hash": "18c5a8c5bac1e33a0c11e6c5bc262904a3e87538", "best_bid": "0.021", "best_ask": "0.052"}, {"asset_id": "52417019033358898530053799473085644762541010045525203660683879224996320434909", "price": "0.994", "size": "15.72", "side": "SELL", "hash": "651cc3a84a3ea41331137796feefb17ccb4d2ad8", "best_bid": "0.948", "best_ask": "0.979"}], "timestamp": "1769384070756", "event_type": "price_change"}}
{"_local_timestamp": "2026-01-25T23:34:30.832494+00:00", "data": {"market": "0xc954c52447b5856106b45c55df1003b48a583af3b4772bda1de20e0a95ad5f45", "price_changes": [{"asset_id": "9302610255531462617274536528837506482521823261381921527179585793339878975949", "price": "0.013", "size": "25.66", "side": "BUY", "hash": "511b6b0a102e0655f42f4349516ffaaab975d76d", "best_bid": "0.021", "best_ask": "0.052"}, {"asset_id": "52417019033358898530053799473085644762541010045525203660683879224996320434909", "price": "0.987", "size": "25.66", "side": "SELL", "hash": "021b92dd7fc64863e6bad62010634f27903980b8", "best_bid": "0.948", "best_ask": "0.979"}], "timestamp": "1769384070757", "event_type": "price_change"}}
{"_local_timestamp": "2026-01-25T23:34:31.105046+00:00", "data": {"market": "0x29fcb3cb3301dde656aaaf7d185bb56c9b6948968b9d95f87f3942355b6bf360", "price_changes": [{"asset_id": "91783318584258680143008562461721551652033317272474793227511040505886797754334", "price": "0.004", "size": "145.26", "side": "BUY", "hash": "69e2b4d4a2c33cd7dc49b5d5089fa368bda382dd", "best_bid": "0.021", "best_ask": "0.045"}, {"asset_id": "92691123413763856836301118436801979285373127205354327950605601494440683568501", "price": "0.996", "size": "145.26", "side": "SELL", "hash": "bf297e5b8d11be51f7868c579a344d9e8c1f7042", "best_bid": "0.955", "best_ask": "0.979"}], "timestamp": "1769384071007", "event_type": "price_change"}}
{"_local_timestamp": "2026-01-25T23:34:31.106351+00:00", "data": {"market": "0x43aad651177544538b5b35dc3239d1631fca344147c0ffe0e416cd0eb51fca6d", "price_changes": [{"asset_id": "76997947933304274428562592491730603768950795614322500110266632020523223203438", "price": "0.02", "size": "1512.07", "side": "BUY", "hash": "ded83957eaa2c21bc42357640a3f5059d14380c3", "best_bid": "0.05", "best_ask": "0.09"}, {"asset_id": "63034252779590173880584393179377300106700707654931663433396190240990856358223", "price": "0.98", "size": "1512.07", "side": "SELL", "hash": "3af0e5c8c1132510f13bbb1cafcdc9846744de5b", "best_bid": "0.91", "best_ask": "0.95"}], "timestamp": "1769384071007", "event_type": "price_change"}}
{"_local_timestamp": "2026-01-25T23:34:31.107839+00:00", "data": {"market": "0x43aad651177544538b5b35dc3239d1631fca344147c0ffe0e416cd0eb51fca6d", "price_changes": [{"asset_id": "76997947933304274428562592491730603768950795614322500110266632020523223203438", "price": "0.05", "size": "33.09", "side": "BUY", "hash": "6ec8fd4363adebf525ce23f599739760be352c02", "best_bid": "0.05", "best_ask": "0.09"}, {"asset_id": "63034252779590173880584393179377300106700707654931663433396190240990856358223", "price": "0.95", "size": "33.09", "side": "SELL", "hash": "d5d67c3abcc3cfe183277c92bfee43b3c014c877", "best_bid": "0.91", "best_ask": "0.95"}], "timestamp": "1769384071008", "event_type": "price_change"}}
{"_local_timestamp": "2026-01-25T23:34:31.149577+00:00", "data": {"market": "0x8d9b74d39735dd0b76542c31b81b9544c3eb954060b3c5790d24957538638145", "price_changes": [{"asset_id": "66829232893940327662461037379134988031891083237936281380951338917389315110298", "price": "0.015", "size": "0", "side": "BUY", "hash": "8acec1bb3fef47d59b0427ef1bea58143cfa690d", "best_bid": "0.014", "best_ask": "0.017"}, {"asset_id": "587316473157103098403959848063967316493748298547115564222712976431944570953", "price": "0.985", "size": "0", "side": "SELL", "hash": "fff6abe992ab12cad9c3d130f56da4de0043894f", "best_bid": "0.983", "best_ask": "0.986"}], "timestamp": "1769384071076", "event_type": "price_change"}}
{"_local_timestamp": "2026-01-25T23:34:31.174539+00:00", "data": {"market": "0x8d9b74d39735dd0b76542c31b81b9544c3eb954060b3c5790d24957538638145", "price_changes": [{"asset_id": "66829232893940327662461037379134988031891083237936281380951338917389315110298", "price": "0.015", "size": "303", "side": "BUY", "hash": "a099fc0ab403ce8aaf90e3d6d782fd59e10c416f", "best_bid": "0.015", "best_ask": "0.017"}, {"asset_id": "587316473157103098403959848063967316493748298547115564222712976431944570953", "price": "0.985", "size": "303", "side": "SELL", "hash": "2862b857398452e0daa0434933cd42595840f5d9", "best_bid": "0.983", "best_ask": "0.985"}], "timestamp": "1769384071106", "event_type": "price_change"}}
{"_local_timestamp": "2026-01-25T23:34:31.209447+00:00", "data": {"market": "0xf3b4662d12f86894b31d52b454428c91733c166ba05c4e3bccc375f78411601a", "price_changes": [{"asset_id": "30441349073423271296409239412402830197110444658615254085853491470932508604811", "price": "0.001", "size": "37018.2", "side": "BUY", "hash": "186a5d1b9a04b3dc8557eea3475d8c26e42b26bf", "best_bid": "0.215", "best_ask": "0.273"}, {"asset_id": "55382819090443168507206409119841525953451022223003224583889620760999266943524", "price": "0.999", "size": "37018.2", "side": "SELL", "hash": "e111f3acf679190fed78f394cdfd249649efe89c", "best_bid": "0.727", "best_ask": "0.785"}], "timestamp": "1769384071137", "event_type": "price_change"}}
{"_local_timestamp": "2026-01-25T23:34:31.210293+00:00", "data": {"market": "0xf3b4662d12f86894b31d52b454428c91733c166ba05c4e3bccc375f78411601a", "price_changes": [{"asset_id": "30441349073423271296409239412402830197110444658615254085853491470932508604811", "price": "0.003", "size": "42.91", "side": "BUY", "hash": "186a5d1b9a04b3dc8557eea3475d8c26e42b26bf", "best_bid": "0.215", "best_ask": "0.273"}, {"asset_id": "55382819090443168507206409119841525953451022223003224583889620760999266943524", "price": "0.997", "size": "42.91", "side": "SELL", "hash": "e111f3acf679190fed78f394cdfd249649efe89c", "best_bid": "0.727", "best_ask": "0.785"}], "timestamp": "1769384071137", "event_type": "price_change"}}
{"_local_timestamp": "2026-01-25T23:34:31.211077+00:00", "data": {"market": "0xf3b4662d12f86894b31d52b454428c91733c166ba05c4e3bccc375f78411601a", "price_changes": [{"asset_id": "30441349073423271296409239412402830197110444658615254085853491470932508604811", "price": "0.021", "size": "6.22", "side": "BUY", "hash": "186a5d1b9a04b3dc8557eea3475d8c26e42b26bf", "best_bid": "0.215", "best_ask": "0.273"}, {"asset_id": "55382819090443168507206409119841525953451022223003224583889620760999266943524", "price": "0.979", "size": "6.22", "side": "SELL", "hash": "e111f3acf679190fed78f394cdfd249649efe89c", "best_bid": "0.727", "best_ask": "0.785"}], "timestamp": "1769384071137", "event_type": "price_change"}}
{"_local_timestamp": "2026-01-25T23:34:31.211849+00:00", "data": {"market": "0xf3b4662d12f86894b31d52b454428c91733c166ba05c4e3bccc375f78411601a", "price_changes": [{"asset_id": "55382819090443168507206409119841525953451022223003224583889620760999266943524", "price": "0.001", "size": "6691.93", "side": "BUY", "hash": "18b808602068468db4df0821e79d6dd69ed62081", "best_bid": "0.727", "best_ask": "0.785"}, {"asset_id": "30441349073423271296409239412402830197110444658615254085853491470932508604811", "price": "0.999", "size": "6691.93", "side": "SELL", "hash": "4e0a678f78ae286c20d8783e131a9c29638d9bcc", "best_bid": "0.215", "best_ask": "0.273"}], "timestamp": "1769384071138", "event_type": "price_change"}}
{"_local_timestamp": "2026-01-25T23:34:31.215036+00:00", "data": {"market": "0xf3b4662d12f86894b31d52b454428c91733c166ba05c4e3bccc375f78411601a", "price_changes": [{"asset_id": "55382819090443168507206409119841525953451022223003224583889620760999266943524", "price": "0.003", "size": "1166", "side": "BUY", "hash": "18b808602068468db4df0821e79d6dd69ed62081", "best_bid": "0.727", "best_ask": "0.785"}, {"asset_id": "30441349073423271296409239412402830197110444658615254085853491470932508604811", "price": "0.997", "size": "1166", "side": "SELL", "hash": "4e0a678f78ae286c20d8783e131a9c29638d9bcc", "best_bid": "0.215", "best_ask": "0.273"}], "timestamp": "1769384071138", "event_type": "price_change"}}
{"_local_timestamp": "2026-01-25T23:34:31.215911+00:00", "data": {"market": "0xf3b4662d12f86894b31d52b454428c91733c166ba05c4e3bccc375f78411601a", "price_changes": [{"asset_id": "55382819090443168507206409119841525953451022223003224583889620760999266943524", "price": "0.007", "size": "0", "side": "BUY", "hash": "18b808602068468db4df0821e79d6dd69ed62081", "best_bid": "0.727", "best_ask": "0.785"}, {"asset_id": "30441349073423271296409239412402830197110444658615254085853491470932508604811", "price": "0.993", "size": "0", "side": "SELL", "hash": "4e0a678f78ae286c20d8783e131a9c29638d9bcc", "best_bid": "0.215", "best_ask": "0.273"}], "timestamp": "1769384071138", "event_type": "price_change"}}
{"_local_timestamp": "2026-01-25T23:34:31.216699+00:00", "data": {"market": "0xf3b4662d12f86894b31d52b454428c91733c166ba05c4e3bccc375f78411601a", "price_changes": [{"asset_id": "55382819090443168507206409119841525953451022223003224583889620760999266943524", "price": "0.021", "size": "0", "side": "BUY", "hash": "18b808602068468db4df0821e79d6dd69ed62081", "best_bid": "0.727", "best_ask": "0.785"}, {"asset_id": "30441349073423271296409239412402830197110444658615254085853491470932508604811", "price": "0.979", "size": "0", "side": "SELL", "hash": "4e0a678f78ae286c20d8783e131a9c29638d9bcc", "best_bid": "0.215", "best_ask": "0.273"}], "timestamp": "1769384071138", "event_type": "price_change"}}
{"_local_timestamp": "2026-01-25T23:34:32.420881+00:00", "data": {"market": "0x12d1b41c90a2ff07173ab2469aad97fb9e80f781b36c32f99fbf4ae28a28b42a", "price_changes": [{"asset_id": "22835304185425644675451740820217338241663141495608098477495460677942947224804", "price": "0.64", "size": "0", "side": "SELL", "hash": "2e372de7091cac01967bb06bb0207190a6481937", "best_bid": "0.44", "best_ask": "0.46"}, {"asset_id": "36737124956681902477833012015613017711780279541938574794261768841905170092613", "price": "0.36", "size": "0", "side": "BUY", "hash": "6e910ca06b606d54d55ec58f36944cc1f48aa6b1", "best_bid": "0.54", "best_ask": "0.56"}], "timestamp": "1769384072328", "event_type": "price_change"}}
{"_local_timestamp": "2026-01-25T23:34:32.454140+00:00", "data": {"market": "0x12d1b41c90a2ff07173ab2469aad97fb9e80f781b36c32f99fbf4ae28a28b42a", "price_changes": [{"asset_id": "36737124956681902477833012015613017711780279541938574794261768841905170092613", "price": "0.52", "size": "200", "side": "BUY", "hash": "b9c04cdf176d2c810a2b40e22d96962108b990a6", "best_bid": "0.54", "best_ask": "0.56"}, {"asset_id": "22835304185425644675451740820217338241663141495608098477495460677942947224804", "price": "0.48", "size": "200", "side": "SELL", "hash": "7197fa31470c86c376c7440744fe2253a1ffcdfa", "best_bid": "0.44", "best_ask": "0.46"}], "timestamp": "1769384072380", "event_type": "price_change"}}
{"_local_timestamp": "2026-01-25T23:34:32.481791+00:00", "data": {"market": "0x12d1b41c90a2ff07173ab2469aad97fb9e80f781b36c32f99fbf4ae28a28b42a", "price_changes": [{"asset_id": "36737124956681902477833012015613017711780279541938574794261768841905170092613", "price": "0.54", "size": "199.85", "side": "BUY", "hash": "e6f57fc2522e360fe0d7387e56ebc1fc12c56e3b", "best_bid": "0.54", "best_ask": "0.56"}, {"asset_id": "22835304185425644675451740820217338241663141495608098477495460677942947224804", "price": "0.46", "size": "199.85", "side": "SELL", "hash": "55b5d1927d76199407f081242e2ca60bcb90c796", "best_bid": "0.44", "best_ask": "0.46"}], "timestamp": "1769384072408", "event_type": "price_change"}}
{"_local_timestamp": "2026-01-25T23:34:32.644878+00:00", "data": {"market": "0x8d9b74d39735dd0b76542c31b81b9544c3eb954060b3c5790d24957538638145", "price_changes": [{"asset_id": "66829232893940327662461037379134988031891083237936281380951338917389315110298", "price": "0.015", "size": "0", "side": "BUY", "hash": "fb4788b88bc9ccaa60f15923147d4644ca441f5a", "best_bid": "0.014", "best_ask": "0.017"}, {"asset_id": "587316473157103098403959848063967316493748298547115564222712976431944570953", "price": "0.985", "size": "0", "side": "SELL", "hash": "c1ddb37e6ed001eabb1fd1ba4ce0dba825143258", "best_bid": "0.983", "best_ask": "0.986"}], "timestamp": "1769384072576", "event_type": "price_change"}}
{"_local_timestamp": "2026-01-25T23:34:32.685039+00:00", "data": {"market": "0x8d9b74d39735dd0b76542c31b81b9544c3eb954060b3c5790d24957538638145", "price_changes": [{"asset_id": "66829232893940327662461037379134988031891083237936281380951338917389315110298", "price": "0.015", "size": "303", "side": "BUY", "hash": "aa7095fbe4529b727c5b72910330538386ac99df", "best_bid": "0.015", "best_ask": "0.017"}, {"asset_id": "587316473157103098403959848063967316493748298547115564222712976431944570953", "price": "0.985", "size": "303", "side": "SELL", "hash": "13b6e951ec5fc73f470389c85b58556e5d93e989", "best_bid": "0.983", "best_ask": "0.985"}], "timestamp": "1769384072605", "event_type": "price_change"}}
{"_local_timestamp": "2026-01-25T23:34:32.837564+00:00", "data": {"market": "0x12d1b41c90a2ff07173ab2469aad97fb9e80f781b36c32f99fbf4ae28a28b42a", "price_changes": [{"asset_id": "22835304185425644675451740820217338241663141495608098477495460677942947224804", "price": "0.61", "size": "9", "side": "SELL", "hash": "3271e776d8c654692b6eabc1f521a8160b313bb4", "best_bid": "0.44", "best_ask": "0.46"}, {"asset_id": "36737124956681902477833012015613017711780279541938574794261768841905170092613", "price": "0.39", "size": "9", "side": "BUY", "hash": "7cc7f374f9ecfe3537185a9f6e75ff66523840b2", "best_bid": "0.54", "best_ask": "0.56"}], "timestamp": "1769384072767", "event_type": "price_change"}}
{"_local_timestamp": "2026-01-25T23:34:33.025229+00:00", "data": {"market": "0x5abe3287197d0a924707ce99130643c92751c209fc0e376c6700d6673b43ada5", "price_changes": [{"asset_id": "15631821676887099899145118278843400257602269360221049118391374890586669885976", "price": "0.41", "size": "100", "side": "SELL", "hash": "36a1885fff85e84cd818e49ec6fa25920a4470e9", "best_bid": "0.17", "best_ask": "0.24"}, {"asset_id": "2791138143012434753446657502011224259420532252815498101697790519791539429743", "price": "0.59", "size": "100", "side": "BUY", "hash": "75f3e109fb397e565b0f4e7a0d41792f67f020c9", "best_bid": "0.76", "best_ask": "0.83"}], "timestamp": "1769384072952", "event_type": "price_change"}}
{"_local_timestamp": "2026-01-25T23:34:33.160232+00:00", "data": {"market": "0xc954c52447b5856106b45c55df1003b48a583af3b4772bda1de20e0a95ad5f45", "price_changes": [{"asset_id": "9302610255531462617274536528837506482521823261381921527179585793339878975949", "price": "0.02", "size": "150", "side": "BUY", "hash": "70a8d66c2850777849230e6de3d180fec6fc299d", "best_bid": "0.021", "best_ask": "0.052"}, {"asset_id": "52417019033358898530053799473085644762541010045525203660683879224996320434909", "price": "0.98", "size": "150", "side": "SELL", "hash": "48fa9a9007f89362ad7e2b246431fc3df218f9ef", "best_bid": "0.948", "best_ask": "0.979"}], "timestamp": "1769384073093", "event_type": "price_change"}}
{"_local_timestamp": "2026-01-25T23:34:33.246756+00:00", "data": {"market": "0x5abe3287197d0a924707ce99130643c92751c209fc0e376c6700d6673b43ada5", "price_changes": [{"asset_id": "2791138143012434753446657502011224259420532252815498101697790519791539429743", "price": "0.59", "size": "0", "side": "BUY", "hash": "2202c24b09b39d7ce09577180117f2ffe7a6c735", "best_bid": "0.76", "best_ask": "0.83"}, {"asset_id": "15631821676887099899145118278843400257602269360221049118391374890586669885976", "price": "0.41", "size": "0", "side": "SELL", "hash": "2e0fe7e787148cb5e3706b945d23e048048b9210", "best_bid": "0.17", "best_ask": "0.24"}], "timestamp": "1769384073172", "event_type": "price_change"}}
{"_local_timestamp": "2026-01-25T23:34:33.360658+00:00", "data": {"market": "0x5abe3287197d0a924707ce99130643c92751c209fc0e376c6700d6673b43ada5", "price_changes": [{"asset_id": "15631821676887099899145118278843400257602269360221049118391374890586669885976", "price": "0.64", "size": "199.99", "side": "SELL", "hash": "8e063aa6bc8d1886a0c0ebc576cd7208fbe8eb5e", "best_bid": "0.17", "best_ask": "0.24"}, {"asset_id": "2791138143012434753446657502011224259420532252815498101697790519791539429743", "price": "0.36", "size": "199.99", "side": "BUY", "hash": "6a1b52ff8aa2df5a0fd993d4b14bef38ddbc3941", "best_bid": "0.76", "best_ask": "0.83"}], "timestamp": "1769384073286", "event_type": "price_change"}}
{"_local_timestamp": "2026-01-25T23:34:33.745855+00:00", "data": {"market": "0xcc25bf2f9c735a18c35969e330c0d917eec97fb93ea9422a0a0ed2b3f0eada54", "price_changes": [{"asset_id": "41699891447566493678062566391348854695286848129234610508637427753139123056608", "price": "0.64", "size": "55", "side": "BUY", "hash": "9fa08160a2be1462028de073d9964ebb8e51cf3a", "best_bid": "0.67", "best_ask": "0.69"}, {"asset_id": "65578135623666125364690190525767126679774364994694102050152165807381694053320", "price": "0.36", "size": "55", "side": "SELL", "hash": "d014cbe48cafad1c5618c66b99927f85d5be8557", "best_bid": "0.31", "best_ask": "0.33"}], "timestamp": "1769384073676", "event_type": "price_change"}}
{"_local_timestamp": "2026-01-25T23:34:33.769198+00:00", "data": {"market": "0x5abe3287197d0a924707ce99130643c92751c209fc0e376c6700d6673b43ada5", "price_changes": [{"asset_id": "2791138143012434753446657502011224259420532252815498101697790519791539429743", "price": "0.61", "size": "30", "side": "BUY", "hash": "a91ebe9ecadcde8c9b48c3da364e205abc4f97ef", "best_bid": "0.76", "best_ask": "0.83"}, {"asset_id": "15631821676887099899145118278843400257602269360221049118391374890586669885976", "price": "0.39", "size": "30", "side": "SELL", "hash": "4a549cd5ec612c46b8011a213f30aeee8e583e16", "best_bid": "0.17", "best_ask": "0.24"}], "timestamp": "1769384073682", "event_type": "price_change"}}
{"_local_timestamp": "2026-01-25T23:34:33.779240+00:00", "data": {"market": "0x5abe3287197d0a924707ce99130643c92751c209fc0e376c6700d6673b43ada5", "price_changes": [{"asset_id": "15631821676887099899145118278843400257602269360221049118391374890586669885976", "price": "0.4", "size": "0", "side": "SELL", "hash": "30f1be411158bfa061080fb75d5bd288ba2edd0d", "best_bid": "0.17", "best_ask": "0.24"}, {"asset_id": "2791138143012434753446657502011224259420532252815498101697790519791539429743", "price": "0.6", "size": "0", "side": "BUY", "hash": "c68fd610efbcf566d958663e20e94320f31b7ac0", "best_bid": "0.76", "best_ask": "0.83"}], "timestamp": "1769384073708", "event_type": "price_change"}}
{"_local_timestamp": "2026-01-25T23:34:33.780276+00:00", "data": {"market": "0x12d1b41c90a2ff07173ab2469aad97fb9e80f781b36c32f99fbf4ae28a28b42a", "price_changes": [{"asset_id": "36737124956681902477833012015613017711780279541938574794261768841905170092613", "price": "0.54", "size": "156.85", "side": "BUY", "hash": "01ef5606c1eb59eb9c7751265b487785ad042e77", "best_bid": "0.54", "best_ask": "0.56"}, {"asset_id": "22835304185425644675451740820217338241663141495608098477495460677942947224804", "price": "0.46", "size": "156.85", "side": "SELL", "hash": "ec3b9ea3af5606bc14408e5c3c86b7d230ba0a20", "best_bid": "0.44", "best_ask": "0.46"}], "timestamp": "1769384073709", "event_type": "price_change"}}
{"_local_timestamp": "2026-01-25T23:34:33.805783+00:00", "data": {"market": "0x5abe3287197d0a924707ce99130643c92751c209fc0e376c6700d6673b43ada5", "price_changes": [{"asset_id": "2791138143012434753446657502011224259420532252815498101697790519791539429743", "price": "0.36", "size": "299.99", "side": "BUY", "hash": "b6a4c80bb84f10da9e04be92296bd4dc5f2cd75b", "best_bid": "0.76", "best_ask": "0.83"}, {"asset_id": "15631821676887099899145118278843400257602269360221049118391374890586669885976", "price": "0.64", "size": "299.99", "side": "SELL", "hash": "95605ba34615a5aa253d60dd820e1cd35296c309", "best_bid": "0.17", "best_ask": "0.24"}], "timestamp": "1769384073727", "event_type": "price_change"}}
{"_local_timestamp": "2026-01-25T23:34:33.808885+00:00", "data": {"market": "0x5abe3287197d0a924707ce99130643c92751c209fc0e376c6700d6673b43ada5", "price_changes": [{"asset_id": "15631821676887099899145118278843400257602269360221049118391374890586669885976", "price": "0.39", "size": "143", "side": "SELL", "hash": "79cfefa9293e1a2f217ba8027bf08b682d966130", "best_bid": "0.17", "best_ask": "0.24"}, {"asset_id": "2791138143012434753446657502011224259420532252815498101697790519791539429743", "price": "0.61", "size": "143", "side": "BUY", "hash": "341bfc60166a93833a79abb41259ede2094ea423", "best_bid": "0.76", "best_ask": "0.83"}], "timestamp": "1769384073734", "event_type": "price_change"}}
{"_local_timestamp": "2026-01-25T23:34:33.823418+00:00", "data": {"market": "0x12d1b41c90a2ff07173ab2469aad97fb9e80f781b36c32f99fbf4ae28a28b42a", "price_changes": [{"asset_id": "36737124956681902477833012015613017711780279541938574794261768841905170092613", "price": "0.52", "size": "246", "side": "BUY", "hash": "815ff83b91c65a7f2cd56efca3896137041a9395", "best_bid": "0.54", "best_ask": "0.56"}, {"asset_id": "22835304185425644675451740820217338241663141495608098477495460677942947224804", "price": "0.48", "size": "246", "side": "SELL", "hash": "f879f522d86830e98082f04f4622c60cbedf13b3", "best_bid": "0.44", "best_ask": "0.46"}], "timestamp": "1769384073736", "event_type": "price_change"}}
{"_local_timestamp": "2026-01-25T23:34:33.833737+00:00", "data": {"market": "0xf3b4662d12f86894b31d52b454428c91733c166ba05c4e3bccc375f78411601a", "price_changes": [{"asset_id": "30441349073423271296409239412402830197110444658615254085853491470932508604811", "price": "0.022", "size": "17.94", "side": "BUY", "hash": "ad37e401cb88ab4bb9c819927b3c1d38c4d99024", "best_bid": "0.215", "best_ask": "0.273"}, {"asset_id": "55382819090443168507206409119841525953451022223003224583889620760999266943524", "price": "0.978", "size": "17.94", "side": "SELL", "hash": "be1af37e725624781056b8d9dac1e3d4e83e3f1b", "best_bid": "0.727", "best_ask": "0.785"}], "timestamp": "1769384073762", "event_type": "price_change"}}
{"_local_timestamp": "2026-01-25T23:34:33.834822+00:00", "data": {"market": "0xf3b4662d12f86894b31d52b454428c91733c166ba05c4e3bccc375f78411601a", "price_changes": [{"asset_id": "30441349073423271296409239412402830197110444658615254085853491470932508604811", "price": "0.001", "size": "37025.93", "side": "BUY", "hash": "f14c2f58704d91a177b71b97ca3edb50ce3e4227", "best_bid": "0.215", "best_ask": "0.273"}, {"asset_id": "55382819090443168507206409119841525953451022223003224583889620760999266943524", "price": "0.999", "size": "37025.93", "side": "SELL", "hash": "5476592634005e86f7cab96f3e494f40eac99edd", "best_bid": "0.727", "best_ask": "0.785"}], "timestamp": "1769384073763", "event_type": "price_change"}}
{"_local_timestamp": "2026-01-25T23:34:33.835808+00:00", "data": {"market": "0xf3b4662d12f86894b31d52b454428c91733c166ba05c4e3bccc375f78411601a", "price_changes": [{"asset_id": "55382819090443168507206409119841525953451022223003224583889620760999266943524", "price": "0.011", "size": "29.6", "side": "BUY", "hash": "fd20ace9e6176ffb34034a934f7040ff508bbf5c", "best_bid": "0.727", "best_ask": "0.785"}, {"asset_id": "30441349073423271296409239412402830197110444658615254085853491470932508604811", "price": "0.989", "size": "29.6", "side": "SELL", "hash": "88e34f56f9791b9af6e0b941d2f8605443a0507f", "best_bid": "0.215", "best_ask": "0.273"}], "timestamp": "1769384073764", "event_type": "price_change"}}
