{"_local_timestamp": "2026-01-25T23:33:27.575295+00:00", "data": [{"market": "0x33c3b9a093ed165a022c0cece1dfbc75aacfc7d02b32ec2b60f33b83a83b584e", "asset_id": "5231604723025762452457801154824477655145557185223041567948353301271250253045", "timestamp": "1769383958105", "hash": "2573028e45c426af6a2e9ba61cbd215e64d6f211", "bids": [{"price": "0.01", "size": "3517.82"}, {"price": "0.02", "size": "500"}, {"price": "0.03", "size": "405.51"}, {"price": "0.04", "size": "350"}, {"price": "0.05", "size": "725.9"}, {"price": "0.08", "size": "550"}, {"price": "0.09", "size": "205.22"}, {"price": "0.1", "size": "100"}, {"price": "0.11", "size": "290.9"}, {"price": "0.14", "size": "200"}, {"price": "0.16", "size": "162.5"}, {"price": "0.17", "size": "86.24"}, {"price": "0.19", "size": "126.31"}, {"price": "0.2", "size": "38"}, {"price": "0.22", "size": "90.9"}, {"price": "0.23", "size": "8"}, {"price": "0.24", "size": "190"}, {"price": "0.28", "size": "8.5"}, {"price": "0.32", "size": "38"}, {"price": "0.33", "size": "20"}, {"price": "0.41", "size": "24.43"}, {"price": "0.42", "size": "35"}, {"price": "0.43", "size": "26.79"}, {"price": "0.44", "size": "38"}], "asks": [{"price": "0.99", "size": "5800"}, {"price": "0.98", "size": "6.94"}, {"price": "0.95", "size": "930"}, {"price": "0.94", "size": "300"}, {"price": "0.93", "size": "7.54"}, {"price": "0.88", "size": "66.66"}, {"price": "0.87", "size": "370"}, {"price": "0.8", "size": "200"}, {"price": "0.77", "size": "8.5"}, {"price": "0.71", "size": "66.66"}, {"price": "0.7", "size": "32.5"}, {"price": "0.69", "size": "128.24"}, {"price": "0.55", "size": "73.33"}, {"price": "0.54", "size": "5"}], "event_type": "book", "last_trade_price": ""}, {"market": "0x33c3b9a093ed165a022c0cece1dfbc75aacfc7d02b32ec2b60f33b83a83b584e", "asset_id": "88558823758350777717721635627914660172648618934795254748210502992209900330496", "timestamp": "1769383958105", "hash": "15c525dc88a7752d3bf2a6a9195118ad2dd09590", "bids": [{"price": "0.01", "size": "5800"}, {"price": "0.02", "size": "6.94"}, {"price": "0.05", "size": "930"}, {"price": "0.06", "size": "300"}, {"price": "0.07", "size": "7.54"}, {"price": "0.12", "size": "66.66"}, {"price": "0.13", "size": "370"}, {"price": "0.2", "size": "200"}, {"price": "0.23", "size": "8.5"}, {"price": "0.29", "size": "66.66"}, {"price": "0.3", "size": "32.5"}, {"price": "0.31", "size": "128.24"}, {"price": "0.45", "size": "73.33"}, {"price": "0.46", "size": "5"}], "asks": [{"price": "0.99", "size": "3517.82"}, {"price": "0.98", "size": "500"}, {"price": "0.97", "size": "405.51"}, {"price": "0.96", "size": "350"}, {"price": "0.95", "size": "725.9"}, {"price": "0.92", "size": "550"}, {"price": "0.91", "size": "205.22"}, {"price": "0.9", "size": "100"}, {"price": "0.89", "size": "290.9"}, {"price": "0.86", "size": "200"}, {"price": "0.84", "size": "162.5"}, {"price": "0.83", "size": "86.24"}, {"price": "0.81", "size": "126.31"}, {"price": "0.8", "size": "38"}, {"price": "0.78", "size": "90.9"}, {"price": "0.77", "size": "8"}, {"price": "0.76", "size": "190"}, {"price": "0.72", "size": "8.5"}, {"price": "0.68", "size": "38"}, {"price": "0.67", "size": "20"}, {"price": "0.59", "size": "24.43"}, {"price": "0.58", "size": "35"}, {"price": "0.57", "size": "26.79"}, {"price": "0.56", "size": "38"}], "event_type": "book", "last_trade_price": ""}, {"market": "0x268f4042d495b0a3ea61e794c664f1d3796f3a0fc5dab7bf1ad5bfdbf7850d7c", "asset_id": "63670917573484538535387075608707689209446344899693197294786093921650274225968", "timestamp": "1769383834249", "hash": "11a691fb053aa09c7993cb94527f19deb59a126f", "bids": [{"price": "0.01", "size": "6884.85"}, {"price": "0.02", "size": "2700"}, {"price": "0.03", "size": "10.9"}, {"price": "0.04", "size": "250"}, {"price": "0.05", "size": "30"}, {"price": "0.06", "size": "33"}, {"price": "0.07", "size": "6.55"}, {"price": "0.08", "size": "625"}, {"price": "0.11", "size": "550"}, {"price": "0.16", "size": "450"}, {"price": "0.17", "size": "6.27"}, {"price": "0.23", "size": "300"}, {"price": "0.24", "size": "125"}, {"price": "0.27", "size": "100"}, {"price": "0.34", "size": "125"}, {"price": "0.44", "size": "130"}, {"price": "0.45", "size": "5"}, {"price": "0.67", "size": "200"}, {"price": "0.68", "size": "20"}, {"price": "0.78", "size": "5"}, {"price": "0.86", "size": "70.81"}, {"price": "0.87", "size": "136"}], "asks": [{"price": "0.99", "size": "190"}], "event_type": "book", "last_trade_price": ""}, {"market": "0x822409787697144b96f53af76e6419655f5704d5a1382c0604aa01fb331e2ca5", "asset_id": "20814542776422534757806032422681843083114551625252466804013971546488759714912", "timestamp": "1769383999613", "hash": "05c3b0129a2ba8892953a2cd502f693cce192180", "bids": [{"price": "0.01", "size": "4517.03"}, {"price": "0.02", "size": "1500"}, {"price": "0.03", "size": "5.18"}, {"price": "0.04", "size": "250"}, {"price": "0.05", "size": "1655.55"}, {"price": "0.08", "size": "1050"}, {"price": "0.09", "size": "5.44"}, {"price": "0.11", "size": "840.9"}, {"price": "0.14", "size": "200"}, {"price": "0.16", "size": "562.5"}, {"price": "0.17", "size": "250"}, {"price": "0.18", "size": "5.03"}, {"price": "0.19", "size": "126.31"}, {"price": "0.2", "size": "100"}, {"price": "0.22", "size": "90.9"}, {"price": "0.23", "size": "108"}, {"price": "0.24", "size": "30"}, {"price": "0.35", "size": "100"}, {"price": "0.36", "size": "20"}, {"price": "0.45", "size": "25"}, {"price": "0.46", "size": "77.77"}, {"price": "0.5", "size": "40"}], "asks": [{"price": "0.99", "size": "5500"}, {"price": "0.98", "size": "7.16"}, {"price": "0.96", "size": "400"}, {"price": "0.95", "size": "1220"}, {"price": "0.93", "size": "671"}, {"price": "0.92", "size": "431.54"}, {"price": "0.9", "size": "320"}, {"price": "0.89", "size": "427"}, {"price": "0.88", "size": "233.33"}, {"price": "0.85", "size": "486.33"}, {"price": "0.83", "size": "141.17"}, {"price": "0.82", "size": "137.54"}, {"price": "0.8", "size": "150"}, {"price": "0.7", "size": "122.68"}, {"price": "0.69", "size": "67.54"}, {"price": "0.68", "size": "125"}, {"price": "0.58", "size": "13.33"}, {"price": "0.57", "size": "6.97"}], "event_type": "book", "last_trade_price": "0.460"}, {"market": "0x268f4042d495b0a3ea61e794c664f1d3796f3a0fc5dab7bf1ad5bfdbf7850d7c", "asset_id": "8063468361343945193901601443622223592937597768285686368444925226215635999992", "timestamp": "1769383834249", "hash": "79c153f3f1f137595744e168bc7d982246a82206", "bids": [{"price": "0.01", "size": "190"}], "asks": [{"price": "0.99", "size": "6884.85"}, {"price": "0.98", "size": "2700"}, {"price": "0.97", "size": "10.9"}, {"price": "0.96", "size": "250"}, {"price": "0.95", "size": "30"}, {"price": "0.94", "size": "33"}, {"price": "0.93", "size": "6.55"}, {"price": "0.92", "size": "625"}, {"price": "0.89", "size": "550"}, {"price": "0.84", "size": "450"}, {"price": "0.83", "size": "6.27"}, {"price": "0.77", "size": "300"}, {"price": "0.76", "size": "125"}, {"price": "0.73", "size": "100"}, {"price": "0.66", "size": "125"}, {"price": "0.56", "size": "130"}, {"price": "0.55", "size": "5"}, {"price": "0.33", "size": "200"}, {"price": "0.32", "size": "20"}, {"price": "0.22", "size": "5"}, {"price": "0.14", "size": "70.81"}, {"price": "0.13", "size": "136"}], "event_type": "book", "last_trade_price": ""}, {"market": "0x822409787697144b96f53af76e6419655f5704d5a1382c0604aa01fb331e2ca5", "asset_id": "48505873629919993069307707366966856150423552939624109422369276111454667757058", "timestamp": "1769383999613", "hash": "14216b0b35acfc857a0fcd96ecc072c5fa006fb7", "bids": [{"price": "0.01", "size": "5500"}, {"price": "0.02", "size": "7.16"}, {"price": "0.04", "size": "400"}, {"price": "0.05", "size": "1220"}, {"price": "0.07", "size": "671"}, {"price": "0.08", "size": "431.54"}, {"price": "0.1", "size": "320"}, {"price": "0.11", "size": "427"}, {"price": "0.12", "size": "233.33"}, {"price": "0.15", "size": "486.33"}, {"price": "0.17", "size": "141.17"}, {"price": "0.18", "size": "137.54"}, {"price": "0.2", "size": "150"}, {"price": "0.3", "size": "122.68"}, {"price": "0.31", "size": "67.54"}, {"price": "0.32", "size": "125"}, {"price": "0.42", "size": "13.33"}, {"price": "0.43", "size": "6.97"}], "asks": [{"price": "0.99", "size": "4517.03"}, {"price": "0.98", "size": "1500"}, {"price": "0.97", "size": "5.18"}, {"price": "0.96", "size": "250"}, {"price": "0.95", "size": "1655.55"}, {"price": "0.92", "size": "1050"}, {"price": "0.91", "size": "5.44"}, {"price": "0.89", "size": "840.9"}, {"price": "0.86", "size": "200"}, {"price": "0.84", "size": "562.5"}, {"price": "0.83", "size": "250"}, {"price": "0.82", "size": "5.03"}, {"price": "0.81", "size": "126.31"}, {"price": "0.8", "size": "100"}, {"price": "0.78", "size": "90.9"}, {"price": "0.77", "size": "108"}, {"price": "0.76", "size": "30"}, {"price": "0.65", "size": "100"}, {"price": "0.64", "size": "20"}, {"price": "0.55", "size": "25"}, {"price": "0.54", "size": "77.77"}, {"price": "0.5", "size": "40"}], "event_type": "book", "last_trade_price": "0.460"}]}
{"_local_timestamp": "2026-01-25T23:33:40.276994+00:00", "data": {"market": "0x822409787697144b96f53af76e6419655f5704d5a1382c0604aa01fb331e2ca5", "price_changes": [{"asset_id": "20814542776422534757806032422681843083114551625252466804013971546488759714912", "price": "0.11", "size": "715.9", "side": "BUY", "hash": "5d2d8549a1c27a32f93ea778bfcbf3f4bb411805", "best_bid": "0.5", "best_ask": "0.57"}, {"asset_id": "48505873629919993069307707366966856150423552939624109422369276111454667757058", "price": "0.89", "size": "715.9", "side": "SELL", "hash": "9f99ef6f7ab612f388e403335802af96d3eea1df", "best_bid": "0.43", "best_ask": "0.5"}], "timestamp": "1769384020096", "event_type": "price_change"}}
{"_local_timestamp": "2026-01-25T23:33:40.314432+00:00", "data": {"market": "0x822409787697144b96f53af76e6419655f5704d5a1382c0604aa01fb331e2ca5", "price_changes": [{"asset_id": "20814542776422534757806032422681843083114551625252466804013971546488759714912", "price": "0.16", "size": "462.5", "side": "BUY", "hash": "5d2d8549a1c27a32f93ea778bfcbf3f4bb411805", "best_bid": "0.5", "best_ask": "0.57"}, {"asset_id": "48505873629919993069307707366966856150423552939624109422369276111454667757058", "price": "0.84", "size": "462.5", "side": "SELL", "hash": "9f99ef6f7ab612f388e403335802af96d3eea1df", "best_bid": "0.43", "best_ask": "0.5"}], "timestamp": "1769384020096", "event_type": "price_change"}}
{"_local_timestamp": "2026-01-25T23:33:40.444376+00:00", "data": {"market": "0x268f4042d495b0a3ea61e794c664f1d3796f3a0fc5dab7bf1ad5bfdbf7850d7c", "price_changes": [{"asset_id": "63670917573484538535387075608707689209446344899693197294786093921650274225968", "price": "0.76", "size": "25", "side": "BUY", "hash": "cb276ba1164b352de8ccf05903a28aa224e84aed", "best_bid": "0.87", "best_ask": "0.99"}, {"asset_id": "8063468361343945193901601443622223592937597768285686368444925226215635999992", "price": "0.24", "size": "25", "side": "SELL", "hash": "0ba5f12af53da1b1bd1a591ec9d3ba6456e83c53", "best_bid": "0.01", "best_ask": "0.13"}], "timestamp": "1769384020317", "event_type": "price_change"}}
{"_local_timestamp": "2026-01-25T23:33:42.883252+00:00", "data": {"market": "0x268f4042d495b0a3ea61e794c664f1d3796f3a0fc5dab7bf1ad5bfdbf7850d7c", "price_changes": [{"asset_id": "63670917573484538535387075608707689209446344899693197294786093921650274225968", "price": "0.68", "size": "0", "side": "BUY", "hash": "48153c6a73c808bd22a7fe330f946e8c2567be71", "best_bid": "0.87", "best_ask": "0.99"}, {"asset_id": "8063468361343945193901601443622223592937597768285686368444925226215635999992", "price": "0.32", "size": "0", "side": "SELL", "hash": "df23e1dd872d523919f23b43fe1b672387f10965", "best_bid": "0.01", "best_ask": "0.13"}], "timestamp": "1769384022816", "event_type": "price_change"}}
{"_local_timestamp": "2026-01-25T23:33:42.907344+00:00", "data": {"market": "0x268f4042d495b0a3ea61e794c664f1d3796f3a0fc5dab7bf1ad5bfdbf7850d7c", "price_changes": [{"asset_id": "63670917573484538535387075608707689209446344899693197294786093921650274225968", "price": "0.77", "size": "20", "side": "BUY", "hash": "838fba0a27f2f00945085ddcef5ee03e4721e155", "best_bid": "0.87", "best_ask": "0.99"}, {"asset_id": "8063468361343945193901601443622223592937597768285686368444925226215635999992", "price": "0.23", "size": "20", "side": "SELL", "hash": "814d75e18e2d0f271ee0ee465d755e37e0ec1e49", "best_bid": "0.01", "best_ask": "0.13"}], "timestamp": "1769384022843", "event_type": "price_change"}}
{"_local_timestamp": "2026-01-25T23:33:42.993904+00:00", "data": {"market": "0x268f4042d495b0a3ea61e794c664f1d3796f3a0fc5dab7bf1ad5bfdbf7850d7c", "price_changes": [{"asset_id": "63670917573484538535387075608707689209446344899693197294786093921650274225968", "price": "0.76", "size": "0", "side": "BUY", "hash": "5889ee53d41f3d11cf6efd797a355f2be2d9d0a6", "best_bid": "0.87", "best_ask": "0.99"}, {"asset_id": "8063468361343945193901601443622223592937597768285686368444925226215635999992", "price": "0.24", "size": "0", "side": "SELL", "hash": "ea15d6f4ba5d34318a1b3b02e76123caa97a70e7", "best_bid": "0.01", "best_ask": "0.13"}], "timestamp": "1769384022923", "event_type": "price_change"}}
{"_local_timestamp": "2026-01-25T23:33:47.326135+00:00", "data": {"market": "0x268f4042d495b0a3ea61e794c664f1d3796f3a0fc5dab7bf1ad5bfdbf7850d7c", "price_changes": [{"asset_id": "63670917573484538535387075608707689209446344899693197294786093921650274225968", "price": "0.77", "size": "0", "side": "BUY", "hash": "885db758ce1aa9c64a48239ad755610687b68a32", "best_bid": "0.87", "best_ask": "0.99"}, {"asset_id": "8063468361343945193901601443622223592937597768285686368444925226215635999992", "price": "0.23", "size": "0", "side": "SELL", "hash": "37944967850110403576a98d3d99a2f46b545dce", "best_bid": "0.01", "best_ask": "0.13"}], "timestamp": "1769384027252", "event_type": "price_change"}}
{"_local_timestamp": "2026-01-25T23:33:47.347070+00:00", "data": {"market": "0x268f4042d495b0a3ea61e794c664f1d3796f3a0fc5dab7bf1ad5bfdbf7850d7c", "price_changes": [{"asset_id": "63670917573484538535387075608707689209446344899693197294786093921650274225968", "price": "0.68", "size": "20", "side": "BUY", "hash": "ba89eaf3bafcd5fd537a5fabcc4269b0eb786cd2", "best_bid": "0.87", "best_ask": "0.99"}, {"asset_id": "8063468361343945193901601443622223592937597768285686368444925226215635999992", "price": "0.32", "size": "20", "side": "SELL", "hash": "14b75e4265e2d555fc5eabea4d9e1e36ead34e43", "best_bid": "0.01", "best_ask": "0.13"}], "timestamp": "1769384027276", "event_type": "price_change"}}
{"_local_timestamp": "2026-01-25T23:33:47.471564+00:00", "data": {"market": "0x268f4042d495b0a3ea61e794c664f1d3796f3a0fc5dab7bf1ad5bfdbf7850d7c", "price_changes": [{"asset_id": "63670917573484538535387075608707689209446344899693197294786093921650274225968", "price": "0.76", "size": "25", "side": "BUY", "hash": "9f7fa0982509814cd1e8a812bf15c9464a6651c1", "best_bid": "0.87", "best_ask": "0.99"}, {"asset_id": "8063468361343945193901601443622223592937597768285686368444925226215635999992", "price": "0.24", "size": "25", "side": "SELL", "hash": "c21823f032385f89816936628f5647472393ea33", "best_bid": "0.01", "best_ask": "0.13"}], "timestamp": "1769384027408", "event_type": "price_change"}}
{"_local_timestamp": "2026-01-25T23:33:49.566080+00:00", "data": {"market": "0x268f4042d495b0a3ea61e794c664f1d3796f3a0fc5dab7bf1ad5bfdbf7850d7c", "price_changes": [{"asset_id": "63670917573484538535387075608707689209446344899693197294786093921650274225968", "price": "0.68", "size": "0", "side": "BUY", "hash": "bc506a673bb65c27914a976ce8a94250fc3e4a23", "best_bid": "0.87", "best_ask": "0.99"}, {"asset_id": "8063468361343945193901601443622223592937597768285686368444925226215635999992", "price": "0.32", "size": "0", "side": "SELL", "hash": "9c980a04cae070c45166b4ce74965a2c262bb30b", "best_bid": "0.01", "best_ask": "0.13"}], "timestamp": "1769384029503", "event_type": "price_change"}}
{"_local_timestamp": "2026-01-25T23:33:49.611873+00:00", "data": {"market": "0x268f4042d495b0a3ea61e794c664f1d3796f3a0fc5dab7bf1ad5bfdbf7850d7c", "price_changes": [{"asset_id": "63670917573484538535387075608707689209446344899693197294786093921650274225968", "price": "0.77", "size": "20", "side": "BUY", "hash": "09e3639248d2b6abc7f8fea8783039c2cdbd7ae1", "best_bid": "0.87", "best_ask": "0.99"}, {"asset_id": "8063468361343945193901601443622223592937597768285686368444925226215635999992", "price": "0.23", "size": "20", "side": "SELL", "hash": "98dc5f9028d7c2ab7d0238886fd61cc48e8d31ed", "best_bid": "0.01", "best_ask": "0.13"}], "timestamp": "1769384029547", "event_type": "price_change"}}
{"_local_timestamp": "2026-01-25T23:33:49.681953+00:00", "data": {"market": "0x268f4042d495b0a3ea61e794c664f1d3796f3a0fc5dab7bf1ad5bfdbf7850d7c", "price_changes": [{"asset_id": "63670917573484538535387075608707689209446344899693197294786093921650274225968", "price": "0.76", "size": "0", "side": "BUY", "hash": "f3796b8b302a6412025fbeb22240e4702a30d849", "best_bid": "0.87", "best_ask": "0.99"}, {"asset_id": "8063468361343945193901601443622223592937597768285686368444925226215635999992", "price": "0.24", "size": "0", "side": "SELL", "hash": "347b5ff5abc8e68f8c7bda504a5123ca097ed9c1", "best_bid": "0.01", "best_ask": "0.13"}], "timestamp": "1769384029617", "event_type": "price_change"}}
{"_local_timestamp": "2026-01-25T23:33:50.398010+00:00", "data": {"market": "0x822409787697144b96f53af76e6419655f5704d5a1382c0604aa01fb331e2ca5", "price_changes": [{"asset_id": "48505873629919993069307707366966856150423552939624109422369276111454667757058", "price": "0.32", "size": "62.5", "side": "BUY", "hash": "d87ccf511b27959752de1492e3cd95879c74ab28", "best_bid": "0.43", "best_ask": "0.5"}, {"asset_id": "20814542776422534757806032422681843083114551625252466804013971546488759714912", "price": "0.68", "size": "62.5", "side": "SELL", "hash": "ecd4f0b37da45b7ade47b5a1a4faa96dd4be7706", "best_bid": "0.5", "best_ask": "0.57"}], "timestamp": "1769384030323", "event_type": "price_change"}}
{"_local_timestamp": "2026-01-25T23:33:53.377619+00:00", "data": {"market": "0x268f4042d495b0a3ea61e794c664f1d3796f3a0fc5dab7bf1ad5bfdbf7850d7c", "price_changes": [{"asset_id": "63670917573484538535387075608707689209446344899693197294786093921650274225968", "price": "0.77", "size": "0", "side": "BUY", "hash": "ed27628609d13fb5960f6193e67142575143782f", "best_bid": "0.87", "best_ask": "0.99"}, {"asset_id": "8063468361343945193901601443622223592937597768285686368444925226215635999992", "price": "0.23", "size": "0", "side": "SELL", "hash": "f96cc6392ed3b5e560cab45b6dcbd6344f4f46c5", "best_bid": "0.01", "best_ask": "0.13"}], "timestamp": "1769384033316", "event_type": "price_change"}}
{"_local_timestamp": "2026-01-25T23:33:53.406684+00:00", "data": {"market": "0x268f4042d495b0a3ea61e794c664f1d3796f3a0fc5dab7bf1ad5bfdbf7850d7c", "price_changes": [{"asset_id": "63670917573484538535387075608707689209446344899693197294786093921650274225968", "price": "0.68", "size": "20", "side": "BUY", "hash": "e8772fb37bf78ab32676b0e430164ebe4d382c06", "best_bid": "0.87", "best_ask": "0.99"}, {"asset_id": "8063468361343945193901601443622223592937597768285686368444925226215635999992", "price": "0.32", "size": "20", "side": "SELL", "hash": "5ffcc9f93902fa8e1bfebd611a3123f189c3c89d", "best_bid": "0.01", "best_ask": "0.13"}], "timestamp": "1769384033344", "event_type": "price_change"}}
{"_local_timestamp": "2026-01-25T23:33:53.517912+00:00", "data": {"market": "0x268f4042d495b0a3ea61e794c664f1d3796f3a0fc5dab7bf1ad5bfdbf7850d7c", "price_changes": [{"asset_id": "63670917573484538535387075608707689209446344899693197294786093921650274225968", "price": "0.76", "size": "25", "side": "BUY", "hash": "0fcba3e3cea171d2728407c40d90db55daf5378a", "best_bid": "0.87", "best_ask": "0.99"}, {"asset_id": "8063468361343945193901601443622223592937597768285686368444925226215635999992", "price": "0.24", "size": "25", "side": "SELL", "hash": "dd6cc737784a764fe3486d2482ecbcbf3b8a11b9", "best_bid": "0.01", "best_ask": "0.13"}], "timestamp": "1769384033455", "event_type": "price_change"}}
{"_local_timestamp": "2026-01-25T23:33:56.582723+00:00", "data": {"market": "0x268f4042d495b0a3ea61e794c664f1d3796f3a0fc5dab7bf1ad5bfdbf7850d7c", "price_changes": [{"asset_id": "63670917573484538535387075608707689209446344899693197294786093921650274225968", "price": "0.68", "size": "0", "side": "BUY", "hash": "803719bad1623f8a9c016761a930e24510ecc499", "best_bid": "0.87", "best_ask": "0.99"}, {"asset_id": "8063468361343945193901601443622223592937597768285686368444925226215635999992", "price": "0.32", "size": "0", "side": "SELL", "hash": "50d222a59ce068e319046278c88e78e8520b9c6a", "best_bid": "0.01", "best_ask": "0.13"}], "timestamp": "1769384036508", "event_type": "price_change"}}
{"_local_timestamp": "2026-01-25T23:33:56.610326+00:00", "data": {"market": "0x268f4042d495b0a3ea61e794c664f1d3796f3a0fc5dab7bf1ad5bfdbf7850d7c", "price_changes": [{"asset_id": "63670917573484538535387075608707689209446344899693197294786093921650274225968", "price": "0.77", "size": "20", "side": "BUY", "hash": "b9eed3f90ddb6c142107764060b2793056adc659", "best_bid": "0.87", "best_ask": "0.99"}, {"asset_id": "8063468361343945193901601443622223592937597768285686368444925226215635999992", "price": "0.23", "size": "20", "side": "SELL", "hash": "5bb908ccbc605110772906f905e214b89e299c4f", "best_bid": "0.01", "best_ask": "0.13"}], "timestamp": "1769384036542", "event_type": "price_change"}}
{"_local_timestamp": "2026-01-25T23:33:56.679915+00:00", "data": {"market": "0x268f4042d495b0a3ea61e794c664f1d3796f3a0fc5dab7bf1ad5bfdbf7850d7c", "price_changes": [{"asset_id": "63670917573484538535387075608707689209446344899693197294786093921650274225968", "price": "0.76", "size": "0", "side": "BUY", "hash": "b4359d068946597deac7903c9370fd9c7296d157", "best_bid": "0.87", "best_ask": "0.99"}, {"asset_id": "8063468361343945193901601443622223592937597768285686368444925226215635999992", "price": "0.24", "size": "0", "side": "SELL", "hash": "2b98e42cea24fc89b0f8fab9e58a0bc508c9db1e", "best_bid": "0.01", "best_ask": "0.13"}], "timestamp": "1769384036614", "event_type": "price_change"}}
{"_local_timestamp": "2026-01-25T23:33:59.612200+00:00", "data": {"market": "0x268f4042d495b0a3ea61e794c664f1d3796f3a0fc5dab7bf1ad5bfdbf7850d7c", "price_changes": [{"asset_id": "63670917573484538535387075608707689209446344899693197294786093921650274225968", "price": "0.77", "size": "0", "side": "BUY", "hash": "5849b771bfe1c0b0510c5daa41c1ee1bb23c0a1e", "best_bid": "0.87", "best_ask": "0.99"}, {"asset_id": "8063468361343945193901601443622223592937597768285686368444925226215635999992", "price": "0.23", "size": "0", "side": "SELL", "hash": "3d8e784591cc0a31d2d0a1289a12d314eafad443", "best_bid": "0.01", "best_ask": "0.13"}], "timestamp": "1769384039541", "event_type": "price_change"}}
{"_local_timestamp": "2026-01-25T23:33:59.644342+00:00", "data": {"market": "0x268f4042d495b0a3ea61e794c664f1d3796f3a0fc5dab7bf1ad5bfdbf7850d7c", "price_changes": [{"asset_id": "63670917573484538535387075608707689209446344899693197294786093921650274225968", "price": "0.68", "size": "20", "side": "BUY", "hash": "f6898c410817b84fc3c9796df4504e005234c688", "best_bid": "0.87", "best_ask": "0.99"}, {"asset_id": "8063468361343945193901601443622223592937597768285686368444925226215635999992", "price": "0.32", "size": "20", "side": "SELL", "hash": "7fd5f6aa9af147e4e0b432e41491849f7adbb877", "best_bid": "0.01", "best_ask": "0.13"}], "timestamp": "1769384039572", "event_type": "price_change"}}
{"_local_timestamp": "2026-01-25T23:33:59.744289+00:00", "data": {"market": "0x268f4042d495b0a3ea61e794c664f1d3796f3a0fc5dab7bf1ad5bfdbf7850d7c", "price_changes": [{"asset_id": "63670917573484538535387075608707689209446344899693197294786093921650274225968", "price": "0.76", "size": "25", "side": "BUY", "hash": "447839f93a450081707b2a5e51f1572c63f6bf89", "best_bid": "0.87", "best_ask": "0.99"}, {"asset_id": "8063468361343945193901601443622223592937597768285686368444925226215635999992", "price": "0.24", "size": "25", "side": "SELL", "hash": "0eb4990d9e9399eedd87f50bd98c911da828a5fd", "best_bid": "0.01", "best_ask": "0.13"}], "timestamp": "1769384039676", "event_type": "price_change"}}
{"_local_timestamp": "2026-01-25T23:34:01.310207+00:00", "data": {"market": "0x822409787697144b96f53af76e6419655f5704d5a1382c0604aa01fb331e2ca5", "price_changes": [{"asset_id": "20814542776422534757806032422681843083114551625252466804013971546488759714912", "price": "0.08", "size": "850", "side": "BUY", "hash": "b42b10462ba53aa9040072f388d42cbb1f54655b", "best_bid": "0.5", "best_ask": "0.57"}, {"asset_id": "48505873629919993069307707366966856150423552939624109422369276111454667757058", "price": "0.92", "size": "850", "side": "SELL", "hash": "fca33dada23472dd3520c8ff40b81784b11ac68f", "best_bid": "0.43", "best_ask": "0.5"}], "timestamp": "1769384041241", "event_type": "price_change"}}
{"_local_timestamp": "2026-01-25T23:34:01.318436+00:00", "data": {"market": "0x822409787697144b96f53af76e6419655f5704d5a1382c0604aa01fb331e2ca5", "price_changes": [{"asset_id": "48505873629919993069307707366966856150423552939624109422369276111454667757058", "price": "0.04", "size": "0", "side": "BUY", "hash": "e9fe7991394b9147c6be9370d06b1aa14d352ee7", "best_bid": "0.43", "best_ask": "0.5"}, {"asset_id": "20814542776422534757806032422681843083114551625252466804013971546488759714912", "price": "0.96", "size": "0", "side": "SELL", "hash": "b9cf09ce6d1576e7c6e3fd40f3ab20cf3b876527", "best_bid": "0.5", "best_ask": "0.57"}], "timestamp": "1769384041242", "event_type": "price_change"}}
{"_local_timestamp": "2026-01-25T23:34:01.399663+00:00", "data": {"market": "0x268f4042d495b0a3ea61e794c664f1d3796f3a0fc5dab7bf1ad5bfdbf7850d7c", "price_changes": [{"asset_id": "63670917573484538535387075608707689209446344899693197294786093921650274225968", "price": "0.68", "size": "0", "side": "BUY", "hash": "ea76c112af94e6ba2091c1d9709d81bc9ab26125", "best_bid": "0.87", "best_ask": "0.99"}, {"asset_id": "8063468361343945193901601443622223592937597768285686368444925226215635999992", "price": "0.32", "size": "0", "side": "SELL", "hash": "49ecbe766f11b72c4e25e87bad5ede8af5c07a7a", "best_bid": "0.01", "best_ask": "0.13"}], "timestamp": "1769384041323", "event_type": "price_change"}}
{"_local_timestamp": "2026-01-25T23:34:01.444736+00:00", "data": {"market": "0x268f4042d495b0a3ea61e794c664f1d3796f3a0fc5dab7bf1ad5bfdbf7850d7c", "price_changes": [{"asset_id": "63670917573484538535387075608707689209446344899693197294786093921650274225968", "price": "0.77", "size": "20", "side": "BUY", "hash": "43a9bd7e84bd8b2199e2211f217f494c0be9357d", "best_bid": "0.87", "best_ask": "0.99"}, {"asset_id": "8063468361343945193901601443622223592937597768285686368444925226215635999992", "price": "0.23", "size": "20", "side": "SELL", "hash": "4d2088c85d03a191647b20d661935f83900823be", "best_bid": "0.01", "best_ask": "0.13"}], "timestamp": "1769384041356", "event_type": "price_change"}}
{"_local_timestamp": "2026-01-25T23:34:01.515048+00:00", "data": {"market": "0x268f4042d495b0a3ea61e794c664f1d3796f3a0fc5dab7bf1ad5bfdbf7850d7c", "price_changes": [{"asset_id": "63670917573484538535387075608707689209446344899693197294786093921650274225968", "price": "0.76", "size": "0", "side": "BUY", "hash": "63b2e62353a36606072e4c3b23a94785be4dcb3f", "best_bid": "0.87", "best_ask": "0.99"}, {"asset_id": "8063468361343945193901601443622223592937597768285686368444925226215635999992", "price": "0.24", "size": "0", "side": "SELL", "hash": "33583e02522bc808294c9166b8370040397472cc", "best_bid": "0.01", "best_ask": "0.13"}], "timestamp": "1769384041432", "event_type": "price_change"}}
{"_local_timestamp": "2026-01-25T23:34:01.629755+00:00", "data": {"market": "0x822409787697144b96f53af76e6419655f5704d5a1382c0604aa01fb331e2ca5", "price_changes": [{"asset_id": "48505873629919993069307707366966856150423552939624109422369276111454667757058", "price": "0.05", "size": "1620", "side": "BUY", "hash": "9f8fa86c7d85429cb43b9a82f16337df5128df7e", "best_bid": "0.43", "best_ask": "0.5"}, {"asset_id": "20814542776422534757806032422681843083114551625252466804013971546488759714912", "price": "0.95", "size": "1620", "side": "SELL", "hash": "d01fd4d79e0ccdfba69c20526d47a4cc5901c03c", "best_bid": "0.5", "best_ask": "0.57"}], "timestamp": "1769384041553", "event_type": "price_change"}}
{"_local_timestamp": "2026-01-25T23:34:01.818145+00:00", "data": {"market": "0x268f4042d495b0a3ea61e794c664f1d3796f3a0fc5dab7bf1ad5bfdbf7850d7c", "price_changes": [{"asset_id": "63670917573484538535387075608707689209446344899693197294786093921650274225968", "price": "0.77", "size": "0", "side": "BUY", "hash": "7c0effbe222ec93e3922593f9d0050356c9e6df9", "best_bid": "0.87", "best_ask": "0.99"}, {"asset_id": "8063468361343945193901601443622223592937597768285686368444925226215635999992", "price": "0.23", "size": "0", "side": "SELL", "hash": "5e9122d984408ac60b8056b52e0f2f990f885b75", "best_bid": "0.01", "best_ask": "0.13"}], "timestamp": "1769384041755", "event_type": "price_change"}}
{"_local_timestamp": "2026-01-25T23:34:01.850299+00:00", "data": {"market": "0x268f4042d495b0a3ea61e794c664f1d3796f3a0fc5dab7bf1ad5bfdbf7850d7c", "price_changes": [{"asset_id": "63670917573484538535387075608707689209446344899693197294786093921650274225968", "price": "0.68", "size": "20", "side": "BUY", "hash": "fcb5c0d6dacdc5c805108a3856e4b1a2819a8756", "best_bid": "0.87", "best_ask": "0.99"}, {"asset_id": "8063468361343945193901601443622223592937597768285686368444925226215635999992", "price": "0.32", "size": "20", "side": "SELL", "hash": "487a302286755b873b6940c9afbcb2cfb48dc9d1", "best_bid": "0.01", "best_ask": "0.13"}], "timestamp": "1769384041783", "event_type": "price_change"}}
{"_local_timestamp": "2026-01-25T23:34:01.986820+00:00", "data": {"market": "0x268f4042d495b0a3ea61e794c664f1d3796f3a0fc5dab7bf1ad5bfdbf7850d7c", "price_changes": [{"asset_id": "63670917573484538535387075608707689209446344899693197294786093921650274225968", "price": "0.76", "size": "25", "side": "BUY", "hash": "70dd777973ef12fcccc2603a2f1eae6564052336", "best_bid": "0.87", "best_ask": "0.99"}, {"asset_id": "8063468361343945193901601443622223592937597768285686368444925226215635999992", "price": "0.24", "size": "25", "side": "SELL", "hash": "130b6111dc4df764c96dcd259fb0a70c078e0e3c", "best_bid": "0.01", "best_ask": "0.13"}], "timestamp": "1769384041919", "event_type": "price_change"}}
{"_local_timestamp": "2026-01-25T23:34:05.346836+00:00", "data": {"market": "0x268f4042d495b0a3ea61e794c664f1d3796f3a0fc5dab7bf1ad5bfdbf7850d7c", "price_changes": [{"asset_id": "63670917573484538535387075608707689209446344899693197294786093921650274225968", "price": "0.68", "size": "0", "side": "BUY", "hash": "5a874bfe9aed087729fbe83fe271d62f12f3bce4", "best_bid": "0.87", "best_ask": "0.99"}, {"asset_id": "8063468361343945193901601443622223592937597768285686368444925226215635999992", "price": "0.32", "size": "0", "side": "SELL", "hash": "98dc3e603ce8aacee183b8f3ffc1069d82956daf", "best_bid": "0.01", "best_ask": "0.13"}], "timestamp": "1769384045276", "event_type": "price_change"}}
{"_local_timestamp": "2026-01-25T23:34:05.376084+00:00", "data": {"market": "0x268f4042d495b0a3ea61e794c664f1d3796f3a0fc5dab7bf1ad5bfdbf7850d7c", "price_changes": [{"asset_id": "63670917573484538535387075608707689209446344899693197294786093921650274225968", "price": "0.77", "size": "20", "side": "BUY", "hash": "c26594f121fbee451584c4f783ece3f28385f6ec", "best_bid": "0.87", "best_ask": "0.99"}, {"asset_id": "8063468361343945193901601443622223592937597768285686368444925226215635999992", "price": "0.23", "size": "20", "side": "SELL", "hash": "92ec74ddcae168b2cf8931081796ba2ce9c7e438", "best_bid": "0.01", "best_ask": "0.13"}], "timestamp": "1769384045304", "event_type": "price_change"}}
{"_local_timestamp": "2026-01-25T23:34:05.453095+00:00", "data": {"market": "0x268f4042d495b0a3ea61e794c664f1d3796f3a0fc5dab7bf1ad5bfdbf7850d7c", "price_changes": [{"asset_id": "63670917573484538535387075608707689209446344899693197294786093921650274225968", "price": "0.76", "size": "0", "side": "BUY", "hash": "58fed1efd1ecfea91efd05da79f9eaa8ea6b7b45", "best_bid": "0.87", "best_ask": "0.99"}, {"asset_id": "8063468361343945193901601443622223592937597768285686368444925226215635999992", "price": "0.24", "size": "0", "side": "SELL", "hash": "723c1ffd805e901cb699f4407f95ee443f5e68f9", "best_bid": "0.01", "best_ask": "0.13"}], "timestamp": "1769384045389", "event_type": "price_change"}}
{"_local_timestamp": "2026-01-25T23:34:08.126465+00:00", "data": {"market": "0x268f4042d495b0a3ea61e794c664f1d3796f3a0fc5dab7bf1ad5bfdbf7850d7c", "price_changes": [{"asset_id": "63670917573484538535387075608707689209446344899693197294786093921650274225968", "price": "0.77", "size": "0", "side": "BUY", "hash": "44d8ee762b8d7cea90da68150cc74bb600ac09c6", "best_bid": "0.87", "best_ask": "0.99"}, {"asset_id": "8063468361343945193901601443622223592937597768285686368444925226215635999992", "price": "0.23", "size": "0", "side": "SELL", "hash": "07f232708c051a851dd2740b28a5b8e3292a1270", "best_bid": "0.01", "best_ask": "0.13"}], "timestamp": "1769384048043", "event_type": "price_change"}}
{"_local_timestamp": "2026-01-25T23:34:08.144094+00:00", "data": {"market": "0x268f4042d495b0a3ea61e794c664f1d3796f3a0fc5dab7bf1ad5bfdbf7850d7c", "price_changes": [{"asset_id": "63670917573484538535387075608707689209446344899693197294786093921650274225968", "price": "0.68", "size": "20", "side": "BUY", "hash": "b517116ebf024cf7ad903fa71cd3d851f32e9eb1", "best_bid": "0.87", "best_ask": "0.99"}, {"asset_id": "8063468361343945193901601443622223592937597768285686368444925226215635999992", "price": "0.32", "size": "20", "side": "SELL", "hash": "8f18f96ef7923da8b79ee243f1112e92ffa3c396", "best_bid": "0.01", "best_ask": "0.13"}], "timestamp": "1769384048071", "event_type": "price_change"}}
{"_local_timestamp": "2026-01-25T23:34:08.254123+00:00", "data": {"market": "0x268f4042d495b0a3ea61e794c664f1d3796f3a0fc5dab7bf1ad5bfdbf7850d7c", "price_changes": [{"asset_id": "63670917573484538535387075608707689209446344899693197294786093921650274225968", "price": "0.76", "size": "25", "side": "BUY", "hash": "42d59bfe0e57261a56de2845bb27259e36ef5112", "best_bid": "0.87", "best_ask": "0.99"}, {"asset_id": "8063468361343945193901601443622223592937597768285686368444925226215635999992", "price": "0.24", "size": "25", "side": "SELL", "hash": "cc95533461ee82f76ff515c782629e59e5f13858", "best_bid": "0.01", "best_ask": "0.13"}], "timestamp": "1769384048189", "event_type": "price_change"}}
{"_local_timestamp": "2026-01-25T23:34:09.339858+00:00", "data": {"market": "0x268f4042d495b0a3ea61e794c664f1d3796f3a0fc5dab7bf1ad5bfdbf7850d7c", "price_changes": [{"asset_id": "63670917573484538535387075608707689209446344899693197294786093921650274225968", "price": "0.68", "size": "0", "side": "BUY", "hash": "a5570b01368715d7b22b64c3f50261ac9ca43ed8", "best_bid": "0.87", "best_ask": "0.99"}, {"asset_id": "8063468361343945193901601443622223592937597768285686368444925226215635999992", "price": "0.32", "size": "0", "side": "SELL", "hash": "25ea47213fa59f2fab54cb19001c1ab6cd7d1639", "best_bid": "0.01", "best_ask": "0.13"}], "timestamp": "1769384049263", "event_type": "price_change"}}
{"_local_timestamp": "2026-01-25T23:34:09.357355+00:00", "data": {"market": "0x268f4042d495b0a3ea61e794c664f1d3796f3a0fc5dab7bf1ad5bfdbf7850d7c", "price_changes": [{"asset_id": "63670917573484538535387075608707689209446344899693197294786093921650274225968", "price": "0.77", "size": "20", "side": "BUY", "hash": "985c175150d87ffc0aad577c1c3d5bcacc7f207a", "best_bid": "0.87", "best_ask": "0.99"}, {"asset_id": "8063468361343945193901601443622223592937597768285686368444925226215635999992", "price": "0.23", "size": "20", "side": "SELL", "hash": "db4b24a81e444964b06194a29febcf13d2b4c6a9", "best_bid": "0.01", "best_ask": "0.13"}], "timestamp": "1769384049288", "event_type": "price_change"}}
{"_local_timestamp": "2026-01-25T23:34:09.460979+00:00", "data": {"market": "0x268f4042d495b0a3ea61e794c664f1d3796f3a0fc5dab7bf1ad5bfdbf7850d7c", "price_changes": [{"asset_id": "63670917573484538535387075608707689209446344899693197294786093921650274225968", "price": "0.76", "size": "0", "side": "BUY", "hash": "bc0b2f23c4a3cdc316aaaea3fe1452525ee8e119", "best_bid": "0.87", "best_ask": "0.99"}, {"asset_id": "8063468361343945193901601443622223592937597768285686368444925226215635999992", "price": "0.24", "size": "0", "side": "SELL", "hash": "c988275f04d37e7c02ae0d6f852bc61d3f5a307a", "best_bid": "0.01", "best_ask": "0.13"}], "timestamp": "1769384049391", "event_type": "price_change"}}
{"_local_timestamp": "2026-01-25T23:34:11.153681+00:00", "data": {"market": "0x268f4042d495b0a3ea61e794c664f1d3796f3a0fc5dab7bf1ad5bfdbf7850d7c", "price_changes": [{"asset_id": "63670917573484538535387075608707689209446344899693197294786093921650274225968", "price": "0.77", "size": "0", "side": "BUY", "hash": "2d0630a6841733e79e3eea369d0cddeeeb451a8f", "best_bid": "0.87", "best_ask": "0.99"}, {"asset_id": "8063468361343945193901601443622223592937597768285686368444925226215635999992", "price": "0.23", "size": "0", "side": "SELL", "hash": "7878f7d937251a94d5c20fe1ca85456bff181c63", "best_bid": "0.01", "best_ask": "0.13"}], "timestamp": "1769384051089", "event_type": "price_change"}}
{"_local_timestamp": "2026-01-25T23:34:11.176869+00:00", "data": {"market": "0x268f4042d495b0a3ea61e794c664f1d3796f3a0fc5dab7bf1ad5bfdbf7850d7c", "price_changes": [{"asset_id": "63670917573484538535387075608707689209446344899693197294786093921650274225968", "price": "0.68", "size": "20", "side": "BUY", "hash": "39f60e7e192bc0bf9ea37b211da3880ea7b44788", "best_bid": "0.87", "best_ask": "0.99"}, {"asset_id": "8063468361343945193901601443622223592937597768285686368444925226215635999992", "price": "0.32", "size": "20", "side": "SELL", "hash": "85adbd92171e2638c09e283f4f8e23e139a414fb", "best_bid": "0.01", "best_ask": "0.13"}], "timestamp": "1769384051114", "event_type": "price_change"}}
{"_local_timestamp": "2026-01-25T23:34:11.285753+00:00", "data": {"market": "0x268f4042d495b0a3ea61e794c664f1d3796f3a0fc5dab7bf1ad5bfdbf7850d7c", "price_changes": [{"asset_id": "63670917573484538535387075608707689209446344899693197294786093921650274225968", "price": "0.76", "size": "25", "side": "BUY", "hash": "a8864852d40f7fef482b62e6f6d4bcb2866ad32d", "best_bid": "0.87", "best_ask": "0.99"}, {"asset_id": "8063468361343945193901601443622223592937597768285686368444925226215635999992", "price": "0.24", "size": "25", "side": "SELL", "hash": "1d91f97e99764841cee79bd83a24c2ab5f8c1dd8", "best_bid": "0.01", "best_ask": "0.13"}], "timestamp": "1769384051221", "event_type": "price_change"}}
{"_local_timestamp": "2026-01-25T23:34:12.128044+00:00", "data": {"market": "0x268f4042d495b0a3ea61e794c664f1d3796f3a0fc5dab7bf1ad5bfdbf7850d7c", "price_changes": [{"asset_id": "63670917573484538535387075608707689209446344899693197294786093921650274225968", "price": "0.68", "size": "0", "side": "BUY", "hash": "63c60d89f7519b78b34d5f6498db43adc509b80a", "best_bid": "0.87", "best_ask": "0.99"}, {"asset_id": "8063468361343945193901601443622223592937597768285686368444925226215635999992", "price": "0.32", "size": "0", "side": "SELL", "hash": "7e061e53ac78a4db2ac173277bd8d230d250557c", "best_bid": "0.01", "best_ask": "0.13"}], "timestamp": "1769384052044", "event_type": "price_change"}}
{"_local_timestamp": "2026-01-25T23:34:12.137286+00:00", "data": {"market": "0x268f4042d495b0a3ea61e794c664f1d3796f3a0fc5dab7bf1ad5bfdbf7850d7c", "price_changes": [{"asset_id": "63670917573484538535387075608707689209446344899693197294786093921650274225968", "price": "0.77", "size": "20", "side": "BUY", "hash": "e372dc445165811ac5613ef9ef503e9712ff06e5", "best_bid": "0.87", "best_ask": "0.99"}, {"asset_id": "8063468361343945193901601443622223592937597768285686368444925226215635999992", "price": "0.23", "size": "20", "side": "SELL", "hash": "aaa1ee741950d2013b3270b0afdfd503c30305ae", "best_bid": "0.01", "best_ask": "0.13"}], "timestamp": "1769384052071", "event_type": "price_change"}}
{"_local_timestamp": "2026-01-25T23:34:12.257724+00:00", "data": {"market": "0x268f4042d495b0a3ea61e794c664f1d3796f3a0fc5dab7bf1ad5bfdbf7850d7c", "price_changes": [{"asset_id": "63670917573484538535387075608707689209446344899693197294786093921650274225968", "price": "0.76", "size": "0", "side": "BUY", "hash": "6672c61fcd59d513946ddb0c8d904380657a751f", "best_bid": "0.87", "best_ask": "0.99"}, {"asset_id": "8063468361343945193901601443622223592937597768285686368444925226215635999992", "price": "0.24", "size": "0", "side": "SELL", "hash": "bcc6fadcbd21b4b1837c793f9a6f4c1a5a85d0f1", "best_bid": "0.01", "best_ask": "0.13"}], "timestamp": "1769384052190", "event_type": "price_change"}}
{"_local_timestamp": "2026-01-25T23:34:12.670433+00:00", "data": {"market": "0x33c3b9a093ed165a022c0cece1dfbc75aacfc7d02b32ec2b60f33b83a83b584e", "price_changes": [{"asset_id": "88558823758350777717721635627914660172648618934795254748210502992209900330496", "price": "0.23", "size": "0", "side": "BUY", "hash": "61808c7f3f467a3096a9072e22a261a2f8650b99", "best_bid": "0.46", "best_ask": "0.56"}, {"asset_id": "5231604723025762452457801154824477655145557185223041567948353301271250253045", "price": "0.77", "size": "0", "side": "SELL", "hash": "a71df42faf53097c00cefc92a5a5d05bbc1fac81", "best_bid": "0.44", "best_ask": "0.54"}], "timestamp": "1769384052600", "event_type": "price_change"}}
{"_local_timestamp": "2026-01-25T23:34:12.706190+00:00", "data": {"market": "0x33c3b9a093ed165a022c0cece1dfbc75aacfc7d02b32ec2b60f33b83a83b584e", "price_changes": [{"asset_id": "88558823758350777717721635627914660172648618934795254748210502992209900330496", "price": "0.22", "size": "8.5", "side": "BUY", "hash": "f5c5d84e9b5667071cc1d2126376674cab9cd8b7", "best_bid": "0.46", "best_ask": "0.56"}, {"asset_id": "5231604723025762452457801154824477655145557185223041567948353301271250253045", "price": "0.78", "size": "8.5", "side": "SELL", "hash": "ef0292a7e4dbb4b692d4743b225b7db852f77a01", "best_bid": "0.44", "best_ask": "0.54"}], "timestamp": "1769384052636", "event_type": "price_change"}}
{"_local_timestamp": "2026-01-25T23:34:13.190040+00:00", "data": {"market": "0x268f4042d495b0a3ea61e794c664f1d3796f3a0fc5dab7bf1ad5bfdbf7850d7c", "price_changes": [{"asset_id": "63670917573484538535387075608707689209446344899693197294786093921650274225968", "price": "0.77", "size": "0", "side": "BUY", "hash": "bb2686b4b435aaaa0e373262071c0299779f8f84", "best_bid": "0.87", "best_ask": "0.99"}, {"asset_id": "8063468361343945193901601443622223592937597768285686368444925226215635999992", "price": "0.23", "size": "0", "side": "SELL", "hash": "3169b7722d35e33aa470d5fe3ca83822428c042b", "best_bid": "0.01", "best_ask": "0.13"}], "timestamp": "1769384053085", "event_type": "price_change"}}
{"_local_timestamp": "2026-01-25T23:34:13.203815+00:00", "data": {"market": "0x268f4042d495b0a3ea61e794c664f1d3796f3a0fc5dab7bf1ad5bfdbf7850d7c", "price_changes": [{"asset_id": "63670917573484538535387075608707689209446344899693197294786093921650274225968", "price": "0.68", "size": "20", "side": "BUY", "hash": "bbfad57d13031510d5366e516325055e450496ee", "best_bid": "0.87", "best_ask": "0.99"}, {"asset_id": "8063468361343945193901601443622223592937597768285686368444925226215635999992", "price": "0.32", "size": "20", "side": "SELL", "hash": "0af07dda1644245be08f29687500ebac2985801f", "best_bid": "0.01", "best_ask": "0.13"}], "timestamp": "1769384053112", "event_type": "price_change"}}
{"_local_timestamp": "2026-01-25T23:34:13.320259+00:00", "data": {"market": "0x268f4042d495b0a3ea61e794c664f1d3796f3a0fc5dab7bf1ad5bfdbf7850d7c", "price_changes": [{"asset_id": "63670917573484538535387075608707689209446344899693197294786093921650274225968", "price": "0.76", "size": "25", "side": "BUY", "hash": "df1452326e2928af95af5554e9e688ca85ce4650", "best_bid": "0.87", "best_ask": "0.99"}, {"asset_id": "8063468361343945193901601443622223592937597768285686368444925226215635999992", "price": "0.24", "size": "25", "side": "SELL", "hash": "155142554ffd787ec7cf7236e8bef2cc986050a7", "best_bid": "0.01", "best_ask": "0.13"}], "timestamp": "1769384053242", "event_type": "price_change"}}
{"_local_timestamp": "2026-01-25T23:34:14.113521+00:00", "data": {"market": "0x268f4042d495b0a3ea61e794c664f1d3796f3a0fc5dab7bf1ad5bfdbf7850d7c", "price_changes": [{"asset_id": "63670917573484538535387075608707689209446344899693197294786093921650274225968", "price": "0.68", "size": "0", "side": "BUY", "hash": "93e9eab28bf4bf5e3f3617ab8cd4bb3d7acbaecc", "best_bid": "0.87", "best_ask": "0.99"}, {"asset_id": "8063468361343945193901601443622223592937597768285686368444925226215635999992", "price": "0.32", "size": "0", "side": "SELL", "hash": "96e10c77e7cafd34542d4d28367e80996a3ec4a0", "best_bid": "0.01", "best_ask": "0.13"}], "timestamp": "1769384054047", "event_type": "price_change"}}
{"_local_timestamp": "2026-01-25T23:34:14.141659+00:00", "data": {"market": "0x268f4042d495b0a3ea61e794c664f1d3796f3a0fc5dab7bf1ad5bfdbf7850d7c", "price_changes": [{"asset_id": "63670917573484538535387075608707689209446344899693197294786093921650274225968", "price": "0.77", "size": "20", "side": "BUY", "hash": "06caee838dbae6d6c640b8b9599b31e385e3b32f", "best_bid": "0.87", "best_ask": "0.99"}, {"asset_id": "8063468361343945193901601443622223592937597768285686368444925226215635999992", "price": "0.23", "size": "20", "side": "SELL", "hash": "3b42cb516bfbc7b6fdcb9e557b92f00a1c26f779", "best_bid": "0.01", "best_ask": "0.13"}], "timestamp": "1769384054074", "event_type": "price_change"}}
{"_local_timestamp": "2026-01-25T23:34:14.251870+00:00", "data": {"market": "0x268f4042d495b0a3ea61e794c664f1d3796f3a0fc5dab7bf1ad5bfdbf7850d7c", "price_changes": [{"asset_id": "63670917573484538535387075608707689209446344899693197294786093921650274225968", "price": "0.76", "size": "0", "side": "BUY", "hash": "7f39e4f8217655a91281adb9d4d2564efeac80eb", "best_bid": "0.87", "best_ask": "0.99"}, {"asset_id": "8063468361343945193901601443622223592937597768285686368444925226215635999992", "price": "0.24", "size": "0", "side": "SELL", "hash": "cf8893b189ae0f76675be4e5aa07d7703f572fd7", "best_bid": "0.01", "best_ask": "0.13"}], "timestamp": "1769384054179", "event_type": "price_change"}}
{"_local_timestamp": "2026-01-25T23:34:17.189448+00:00", "data": {"market": "0x822409787697144b96f53af76e6419655f5704d5a1382c0604aa01fb331e2ca5", "price_changes": [{"asset_id": "20814542776422534757806032422681843083114551625252466804013971546488759714912", "price": "0.18", "size": "0", "side": "BUY", "hash": "b33cd61cb671f052479af5e2ca6259d1ca13126d", "best_bid": "0.5", "best_ask": "0.57"}, {"asset_id": "48505873629919993069307707366966856150423552939624109422369276111454667757058", "price": "0.82", "size": "0", "side": "SELL", "hash": "c4d3eea80a9d6ecef399e47d6b30e09a033652e6", "best_bid": "0.43", "best_ask": "0.5"}], "timestamp": "1769384057120", "event_type": "price_change"}}
{"_local_timestamp": "2026-01-25T23:34:17.857354+00:00", "data": {"market": "0x268f4042d495b0a3ea61e794c664f1d3796f3a0fc5dab7bf1ad5bfdbf7850d7c", "price_changes": [{"asset_id": "63670917573484538535387075608707689209446344899693197294786093921650274225968", "price": "0.77", "size": "0", "side": "BUY", "hash": "e700a7a98778adedbb4168ae5cee89d1b27a0806", "best_bid": "0.87", "best_ask": "0.99"}, {"asset_id": "8063468361343945193901601443622223592937597768285686368444925226215635999992", "price": "0.23", "size": "0", "side": "SELL", "hash": "b62f505574e5c552dd5b3210ab77d0146c3f8f74", "best_bid": "0.01", "best_ask": "0.13"}], "timestamp": "1769384057789", "event_type": "price_change"}}
{"_local_timestamp": "2026-01-25T23:34:17.889582+00:00", "data": {"market": "0x268f4042d495b0a3ea61e794c664f1d3796f3a0fc5dab7bf1ad5bfdbf7850d7c", "price_changes": [{"asset_id": "63670917573484538535387075608707689209446344899693197294786093921650274225968", "price": "0.68", "size": "20", "side": "BUY", "hash": "b8274b8b442f3c60316e94a8e05cc3ef3ba0a6df", "best_bid": "0.87", "best_ask": "0.99"}, {"asset_id": "8063468361343945193901601443622223592937597768285686368444925226215635999992", "price": "0.32", "size": "20", "side": "SELL", "hash": "880875a6aa2a247660f879b7966de2e46c09c16f", "best_bid": "0.01", "best_ask": "0.13"}], "timestamp": "1769384057817", "event_type": "price_change"}}
{"_local_timestamp": "2026-01-25T23:34:18.024908+00:00", "data": {"market": "0x822409787697144b96f53af76e6419655f5704d5a1382c0604aa01fb331e2ca5", "price_changes": [{"asset_id": "20814542776422534757806032422681843083114551625252466804013971546488759714912", "price": "0.17", "size": "255.33", "side": "BUY", "hash": "e691a23aecab0fbdd7e33bef3219f97b04ff0400", "best_bid": "0.5", "best_ask": "0.57"}, {"asset_id": "48505873629919993069307707366966856150423552939624109422369276111454667757058", "price": "0.83", "size": "255.33", "side": "SELL", "hash": "fd8a374fcd9849a83dedaffe5a2fbdb5fa515470", "best_bid": "0.43", "best_ask": "0.5"}], "timestamp": "1769384057942", "event_type": "price_change"}}
{"_local_timestamp": "2026-01-25T23:34:18.025360+00:00", "data": {"market": "0x268f4042d495b0a3ea61e794c664f1d3796f3a0fc5dab7bf1ad5bfdbf7850d7c", "price_changes": [{"asset_id": "63670917573484538535387075608707689209446344899693197294786093921650274225968", "price": "0.76", "size": "25", "side": "BUY", "hash": "dd8673780d94ba881a48e6ec6bc9a16d1ee05c83", "best_bid": "0.87", "best_ask": "0.99"}, {"asset_id": "8063468361343945193901601443622223592937597768285686368444925226215635999992", "price": "0.24", "size": "25", "side": "SELL", "hash": "43384c1089cf3ac2a203bac7efeccf553c45aeee", "best_bid": "0.01", "best_ask": "0.13"}], "timestamp": "1769384057947", "event_type": "price_change"}}
{"_local_timestamp": "2026-01-25T23:34:19.933170+00:00", "data": {"market": "0x268f4042d495b0a3ea61e794c664f1d3796f3a0fc5dab7bf1ad5bfdbf7850d7c", "price_changes": [{"asset_id": "63670917573484538535387075608707689209446344899693197294786093921650274225968", "price": "0.68", "size": "0", "side": "BUY", "hash": "a57ffc9b58037a1c3713855b256865574e279c03", "best_bid": "0.87", "best_ask": "0.99"}, {"asset_id": "8063468361343945193901601443622223592937597768285686368444925226215635999992", "price": "0.32", "size": "0", "side": "SELL", "hash": "171009686d064af0a43cfa8b77b1c6a578b15ecf", "best_bid": "0.01", "best_ask": "0.13"}], "timestamp": "1769384059857", "event_type": "price_change"}}
{"_local_timestamp": "2026-01-25T23:34:19.951903+00:00", "data": {"market": "0x268f4042d495b0a3ea61e794c664f1d3796f3a0fc5dab7bf1ad5bfdbf7850d7c", "price_changes": [{"asset_id": "63670917573484538535387075608707689209446344899693197294786093921650274225968", "price": "0.77", "size": "20", "side": "BUY", "hash": "ef651d78756f18f1409aed7b0620828a9a268b8f", "best_bid": "0.87", "best_ask": "0.99"}, {"asset_id": "8063468361343945193901601443622223592937597768285686368444925226215635999992", "price": "0.23", "size": "20", "side": "SELL", "hash": "38a25e2d7248155b7849f8531c657a16eda82dca", "best_bid": "0.01", "best_ask": "0.13"}], "timestamp": "1769384059884", "event_type": "price_change"}}
{"_local_timestamp": "2026-01-25T23:34:20.036711+00:00", "data": {"market": "0x268f4042d495b0a3ea61e794c664f1d3796f3a0fc5dab7bf1ad5bfdbf7850d7c", "price_changes": [{"asset_id": "63670917573484538535387075608707689209446344899693197294786093921650274225968", "price": "0.76", "size": "0", "side": "BUY", "hash": "5216d46121b9a15c92713536eec56c7ef3fb7961", "best_bid": "0.87", "best_ask": "0.99"}, {"asset_id": "8063468361343945193901601443622223592937597768285686368444925226215635999992", "price": "0.24", "size": "0", "side": "SELL", "hash": "df141f67357dcbf0f418d72f7bb11aa2bf39978d", "best_bid": "0.01", "best_ask": "0.13"}], "timestamp": "1769384059964", "event_type": "price_change"}}
{"_local_timestamp": "2026-01-25T23:34:25.008387+00:00", "data": {"market": "0x268f4042d495b0a3ea61e794c664f1d3796f3a0fc5dab7bf1ad5bfdbf7850d7c", "price_changes": [{"asset_id": "63670917573484538535387075608707689209446344899693197294786093921650274225968", "price": "0.77", "size": "0", "side": "BUY", "hash": "9560a0cbcc5bc29de16cbf4339f4f1ac1e75d57b", "best_bid": "0.87", "best_ask": "0.99"}, {"asset_id": "8063468361343945193901601443622223592937597768285686368444925226215635999992", "price": "0.23", "size": "0", "side": "SELL", "hash": "b5099d963d7c463f5e30cf5f7551dd92a1deaca8", "best_bid": "0.01", "best_ask": "0.13"}], "timestamp": "1769384064941", "event_type": "price_change"}}
{"_local_timestamp": "2026-01-25T23:34:25.031460+00:00", "data": {"market": "0x268f4042d495b0a3ea61e794c664f1d3796f3a0fc5dab7bf1ad5bfdbf7850d7c", "price_changes": [{"asset_id": "63670917573484538535387075608707689209446344899693197294786093921650274225968", "price": "0.68", "size": "20", "side": "BUY", "hash": "f2678fe84e6b1aebb214e77348fad7d04d04b8ca", "best_bid": "0.87", "best_ask": "0.99"}, {"asset_id": "8063468361343945193901601443622223592937597768285686368444925226215635999992", "price": "0.32", "size": "20", "side": "SELL", "hash": "1735f07f57b9e82299aaeaeb2e551344aec6e142", "best_bid": "0.01", "best_ask": "0.13"}], "timestamp": "1769384064967", "event_type": "price_change"}}
{"_local_timestamp": "2026-01-25T23:34:25.151879+00:00", "data": {"market": "0x268f4042d495b0a3ea61e794c664f1d3796f3a0fc5dab7bf1ad5bfdbf7850d7c", "price_changes": [{"asset_id": "63670917573484538535387075608707689209446344899693197294786093921650274225968", "price": "0.76", "size": "25", "side": "BUY", "hash": "44eeef2cba5d966223448af2fc9012f70e3100b5", "best_bid": "0.87", "best_ask": "0.99"}, {"asset_id": "8063468361343945193901601443622223592937597768285686368444925226215635999992", "price": "0.24", "size": "25", "side": "SELL", "hash": "c48ff711821087e82a6e6b64444b0a6e20f2b6bd", "best_bid": "0.01", "best_ask": "0.13"}], "timestamp": "1769384065086", "event_type": "price_change"}}
{"_local_timestamp": "2026-01-25T23:34:27.874468+00:00", "data": {"market": "0x822409787697144b96f53af76e6419655f5704d5a1382c0604aa01fb331e2ca5", "price_changes": [{"asset_id": "20814542776422534757806032422681843083114551625252466804013971546488759714912", "price": "0.11", "size": "515.9", "side": "BUY", "hash": "004caf9eadad1c98affbd9128b6171990d1ef245", "best_bid": "0.5", "best_ask": "0.57"}, {"asset_id": "48505873629919993069307707366966856150423552939624109422369276111454667757058", "price": "0.89", "size": "515.9", "side": "SELL", "hash": "6c8123e24675372c3e5d766adc7b18ca035a1495", "best_bid": "0.43", "best_ask": "0.5"}], "timestamp": "1769384067604", "event_type": "price_change"}}
{"_local_timestamp": "2026-01-25T23:34:27.874912+00:00", "data": {"market": "0x822409787697144b96f53af76e6419655f5704d5a1382c0604aa01fb331e2ca5", "price_changes": [{"asset_id": "20814542776422534757806032422681843083114551625252466804013971546488759714912", "price": "0.16", "size": "312.5", "side": "BUY", "hash": "004caf9eadad1c98affbd9128b6171990d1ef245", "best_bid": "0.5", "best_ask": "0.57"}, {"asset_id": "48505873629919993069307707366966856150423552939624109422369276111454667757058", "price": "0.84", "size": "312.5", "side": "SELL", "hash": "6c8123e24675372c3e5d766adc7b18ca035a1495", "best_bid": "0.43", "best_ask": "0.5"}], "timestamp": "1769384067604", "event_type": "price_change"}}
{"_local_timestamp": "2026-01-25T23:34:27.876290+00:00", "data": {"market": "0x822409787697144b96f53af76e6419655f5704d5a1382c0604aa01fb331e2ca5", "price_changes": [{"asset_id": "20814542776422534757806032422681843083114551625252466804013971546488759714912", "price": "0.08", "size": "550", "side": "BUY", "hash": "004caf9eadad1c98affbd9128b6171990d1ef245", "best_bid": "0.5", "best_ask": "0.57"}, {"asset_id": "48505873629919993069307707366966856150423552939624109422369276111454667757058", "price": "0.92", "size": "550", "side": "SELL", "hash": "6c8123e24675372c3e5d766adc7b18ca035a1495", "best_bid": "0.43", "best_ask": "0.5"}], "timestamp": "1769384067604", "event_type": "price_change"}}
{"_local_timestamp": "2026-01-25T23:34:28.496747+00:00", "data": {"market": "0x822409787697144b96f53af76e6419655f5704d5a1382c0604aa01fb331e2ca5", "price_changes": [{"asset_id": "48505873629919993069307707366966856150423552939624109422369276111454667757058", "price": "0.05", "size": "1920", "side": "BUY", "hash": "0004047bddb2f1ec07764198f05fba59324f7028", "best_bid": "0.43", "best_ask": "0.5"}, {"asset_id": "20814542776422534757806032422681843083114551625252466804013971546488759714912", "price": "0.95", "size": "1920", "side": "SELL", "hash": "efb5b6565fb84d0d76de0071eac38ef1bf0ce3d5", "best_bid": "0.5", "best_ask": "0.57"}], "timestamp": "1769384068142", "event_type": "price_change"}}
{"_local_timestamp": "2026-01-25T23:34:28.531403+00:00", "data": {"market": "0x822409787697144b96f53af76e6419655f5704d5a1382c0604aa01fb331e2ca5", "price_changes": [{"asset_id": "20814542776422534757806032422681843083114551625252466804013971546488759714912", "price": "0.01", "size": "4817.03", "side": "BUY", "hash": "a8dfb513ef8b2873e411a95ef9d86822651c5f5e", "best_bid": "0.5", "best_ask": "0.57"}, {"asset_id": "48505873629919993069307707366966856150423552939624109422369276111454667757058", "price": "0.99", "size": "4817.03", "side": "SELL", "hash": "08a999a3f7052f215d758d87b37d2b4c4bf8575c", "best_bid": "0.43", "best_ask": "0.5"}], "timestamp": "1769384068224", "event_type": "price_change"}}
{"_local_timestamp": "2026-01-25T23:34:28.786778+00:00", "data": {"market": "0x268f4042d495b0a3ea61e794c664f1d3796f3a0fc5dab7bf1ad5bfdbf7850d7c", "price_changes": [{"asset_id": "63670917573484538535387075608707689209446344899693197294786093921650274225968", "price": "0.68", "size": "0", "side": "BUY", "hash": "42ef190b719072629d1ba16b23c04eb8a431d271", "best_bid": "0.87", "best_ask": "0.99"}, {"asset_id": "8063468361343945193901601443622223592937597768285686368444925226215635999992", "price": "0.32", "size": "0", "side": "SELL", "hash": "72dc410bb70dc298bbc8f5aa83e55062dcae57ff", "best_bid": "0.01", "best_ask": "0.13"}], "timestamp": "1769384068362", "event_type": "price_change"}}
{"_local_timestamp": "2026-01-25T23:34:28.816732+00:00", "data": {"market": "0x268f4042d495b0a3ea61e794c664f1d3796f3a0fc5dab7bf1ad5bfdbf7850d7c", "price_changes": [{"asset_id": "63670917573484538535387075608707689209446344899693197294786093921650274225968", "price": "0.77", "size": "20", "side": "BUY", "hash": "55b4a9a4db89cd9df29d18b2f7202ef3051c717e", "best_bid": "0.87", "best_ask": "0.99"}, {"asset_id": "8063468361343945193901601443622223592937597768285686368444925226215635999992", "price": "0.23", "size": "20", "side": "SELL", "hash": "5bff9be08bddaf73fc0c5c40494bba9d15ec0601", "best_bid": "0.01", "best_ask": "0.13"}], "timestamp": "1769384068389", "event_type": "price_change"}}
{"_local_timestamp": "2026-01-25T23:34:29.099399+00:00", "data": {"market": "0x268f4042d495b0a3ea61e794c664f1d3796f3a0fc5dab7bf1ad5bfdbf7850d7c", "price_changes": [{"asset_id": "63670917573484538535387075608707689209446344899693197294786093921650274225968", "price": "0.76", "size": "0", "side": "BUY", "hash": "345573f1b38e16ef4c910604b7af401110e02baa", "best_bid": "0.87", "best_ask": "0.99"}, {"asset_id": "8063468361343945193901601443622223592937597768285686368444925226215635999992", "price": "0.24", "size": "0", "side": "SELL", "hash": "45061fba93fc002e63afb91a2eec4c21091aa1a2", "best_bid": "0.01", "best_ask": "0.13"}], "timestamp": "1769384068830", "event_type": "price_change"}}
{"_local_timestamp": "2026-01-25T23:34:30.907229+00:00", "data": {"market": "0x268f4042d495b0a3ea61e794c664f1d3796f3a0fc5dab7bf1ad5bfdbf7850d7c", "price_changes": [{"asset_id": "63670917573484538535387075608707689209446344899693197294786093921650274225968", "price": "0.77", "size": "0", "side": "BUY", "hash": "2717e983b4d6bfc0c3c735f5af05a145192598f6", "best_bid": "0.87", "best_ask": "0.99"}, {"asset_id": "8063468361343945193901601443622223592937597768285686368444925226215635999992", "price": "0.23", "size": "0", "side": "SELL", "hash": "055252c4de02446cca651c15803fe1427897f2c5", "best_bid": "0.01", "best_ask": "0.13"}], "timestamp": "1769384070819", "event_type": "price_change"}}
{"_local_timestamp": "2026-01-25T23:34:30.919189+00:00", "data": {"market": "0x268f4042d495b0a3ea61e794c664f1d3796f3a0fc5dab7bf1ad5bfdbf7850d7c", "price_changes": [{"asset_id": "63670917573484538535387075608707689209446344899693197294786093921650274225968", "price": "0.68", "size": "20", "side": "BUY", "hash": "286fec0032be3d59cd58f22c66e8e3d738eedf8b", "best_bid": "0.87", "best_ask": "0.99"}, {"asset_id": "8063468361343945193901601443622223592937597768285686368444925226215635999992", "price": "0.32", "size": "20", "side": "SELL", "hash": "55f3fa84769f649de1468fbad3e34d965f2dd489", "best_bid": "0.01", "best_ask": "0.13"}], "timestamp": "1769384070846", "event_type": "price_change"}}
{"_local_timestamp": "2026-01-25T23:34:31.044654+00:00", "data": {"market": "0x268f4042d495b0a3ea61e794c664f1d3796f3a0fc5dab7bf1ad5bfdbf7850d7c", "price_changes": [{"asset_id": "63670917573484538535387075608707689209446344899693197294786093921650274225968", "price": "0.76", "size": "25", "side": "BUY", "hash": "5750965fd2a9a44b28c3c9d87eb23d8b5e8bef95", "best_bid": "0.87", "best_ask": "0.99"}, {"asset_id": "8063468361343945193901601443622223592937597768285686368444925226215635999992", "price": "0.24", "size": "25", "side": "SELL", "hash": "d33d7f7e03837b03f3fd1e3ac8885a8ca4938db1", "best_bid": "0.01", "best_ask": "0.13"}], "timestamp": "1769384070979", "event_type": "price_change"}}
{"_local_timestamp": "2026-01-25T23:34:36.566859+00:00", "data": {"market": "0x268f4042d495b0a3ea61e794c664f1d3796f3a0fc5dab7bf1ad5bfdbf7850d7c", "price_changes": [{"asset_id": "63670917573484538535387075608707689209446344899693197294786093921650274225968", "price": "0.68", "size": "0", "side": "BUY", "hash": "b9710ca8b6e704b26e44ea3bd084275b0f06631c", "best_bid": "0.87", "best_ask": "0.99"}, {"asset_id": "8063468361343945193901601443622223592937597768285686368444925226215635999992", "price": "0.32", "size": "0", "side": "SELL", "hash": "323c6a6a3c7213001e62bd702a1b01b7fdbec028", "best_bid": "0.01", "best_ask": "0.13"}], "timestamp": "1769384076494", "event_type": "price_change"}}
{"_local_timestamp": "2026-01-25T23:34:36.585634+00:00", "data": {"market": "0x268f4042d495b0a3ea61e794c664f1d3796f3a0fc5dab7bf1ad5bfdbf7850d7c", "price_changes": [{"asset_id": "63670917573484538535387075608707689209446344899693197294786093921650274225968", "price": "0.77", "size": "20", "side": "BUY", "hash": "f025597866d9f5aeed118fa17cd8b0866379b666", "best_bid": "0.87", "best_ask": "0.99"}, {"asset_id": "8063468361343945193901601443622223592937597768285686368444925226215635999992", "price": "0.23", "size": "20", "side": "SELL", "hash": "af7b64a49f3aa2ed2ac84ecc3b361f107424453a", "best_bid": "0.01", "best_ask": "0.13"}], "timestamp": "1769384076521", "event_type": "price_change"}}
{"_local_timestamp": "2026-01-25T23:34:36.689406+00:00", "data": {"market": "0x268f4042d495b0a3ea61e794c664f1d3796f3a0fc5dab7bf1ad5bfdbf7850d7c", "price_changes": [{"asset_id": "63670917573484538535387075608707689209446344899693197294786093921650274225968", "price": "0.76", "size": "0", "side": "BUY", "hash": "19d54d4b8f117caa605433ebb91b96943f0d5858", "best_bid": "0.87", "best_ask": "0.99"}, {"asset_id": "8063468361343945193901601443622223592937597768285686368444925226215635999992", "price": "0.24", "size": "0", "side": "SELL", "hash": "6439c54fa48c42d4ee8c5c4408a556d24fd59ef6", "best_bid": "0.01", "best_ask": "0.13"}], "timestamp": "1769384076621", "event_type": "price_change"}}
{"_local_timestamp": "2026-01-25T23:34:39.475366+00:00", "data": {"market": "0x33c3b9a093ed165a022c0cece1dfbc75aacfc7d02b32ec2b60f33b83a83b584e", "price_changes": [{"asset_id": "5231604723025762452457801154824477655145557185223041567948353301271250253045", "price": "0.1", "size": "0", "side": "BUY", "hash": "1b6f021a4bf1824c17f297f34cdda6007d81e14b", "best_bid": "0.44", "best_ask": "0.54"}, {"asset_id": "88558823758350777717721635627914660172648618934795254748210502992209900330496", "price": "0.9", "size": "0", "side": "SELL", "hash": "23ae9785ef739fd45078f70bb8ab309180d5c14c", "best_bid": "0.46", "best_ask": "0.56"}], "timestamp": "1769384079399", "event_type": "price_change"}}
{"_local_timestamp": "2026-01-25T23:34:39.752283+00:00", "data": {"market": "0x33c3b9a093ed165a022c0cece1dfbc75aacfc7d02b32ec2b60f33b83a83b584e", "price_changes": [{"asset_id": "5231604723025762452457801154824477655145557185223041567948353301271250253045", "price": "0.09", "size": "305.22", "side": "BUY", "hash": "7d62c7f4d7cb7c58fd6a5b243b62e8b95d71ca8f", "best_bid": "0.44", "best_ask": "0.54"}, {"asset_id": "88558823758350777717721635627914660172648618934795254748210502992209900330496", "price": "0.91", "size": "305.22", "side": "SELL", "hash": "1adb5e05745f73e18ae7a5c7b9a179cc3fd56e55", "best_bid": "0.46", "best_ask": "0.56"}], "timestamp": "1769384079680", "event_type": "price_change"}}
{"_local_timestamp": "2026-01-25T23:34:41.193619+00:00", "data": {"market": "0x268f4042d495b0a3ea61e794c664f1d3796f3a0fc5dab7bf1ad5bfdbf7850d7c", "price_changes": [{"asset_id": "63670917573484538535387075608707689209446344899693197294786093921650274225968", "price": "0.77", "size": "0", "side": "BUY", "hash": "755b59acc132a2133e43c0f08f3b1dfa533e27e3", "best_bid": "0.87", "best_ask": "0.99"}, {"asset_id": "8063468361343945193901601443622223592937597768285686368444925226215635999992", "price": "0.23", "size": "0", "side": "SELL", "hash": "aab4bad6a0c969d4c50dd39341795dbfec034d5d", "best_bid": "0.01", "best_ask": "0.13"}], "timestamp": "1769384081129", "event_type": "price_change"}}
{"_local_timestamp": "2026-01-25T23:34:41.237774+00:00", "data": {"market": "0x268f4042d495b0a3ea61e794c664f1d3796f3a0fc5dab7bf1ad5bfdbf7850d7c", "price_changes": [{"asset_id": "63670917573484538535387075608707689209446344899693197294786093921650274225968", "price": "0.68", "size": "20", "side": "BUY", "hash": "eb8cf44f8ebd44cbefe1947e2daddd3a59680389", "best_bid": "0.87", "best_ask": "0.99"}, {"asset_id": "8063468361343945193901601443622223592937597768285686368444925226215635999992", "price": "0.32", "size": "20", "side": "SELL", "hash": "ed859eef36d112a514c17c2c73bfb1b58f3ba9f6", "best_bid": "0.01", "best_ask": "0.13"}], "timestamp": "1769384081155", "event_type": "price_change"}}
{"_local_timestamp": "2026-01-25T23:34:41.346126+00:00", "data": {"market": "0x268f4042d495b0a3ea61e794c664f1d3796f3a0fc5dab7bf1ad5bfdbf7850d7c", "price_changes": [{"asset_id": "63670917573484538535387075608707689209446344899693197294786093921650274225968", "price": "0.76", "size": "25", "side": "BUY", "hash": "da0ae44e9c22354ccaa99f721f623a5457b60235", "best_bid": "0.87", "best_ask": "0.99"}, {"asset_id": "8063468361343945193901601443622223592937597768285686368444925226215635999992", "price": "0.24", "size": "25", "side": "SELL", "hash": "6f7db7505ce05fb062b1ba69fa5e4e5158875ce2", "best_bid": "0.01", "best_ask": "0.13"}], "timestamp": "1769384081278", "event_type": "price_change"}}
{"_local_timestamp": "2026-01-25T23:34:44.529684+00:00", "data": {"market": "0x822409787697144b96f53af76e6419655f5704d5a1382c0604aa01fb331e2ca5", "price_changes": [{"asset_id": "20814542776422534757806032422681843083114551625252466804013971546488759714912", "price": "0.35", "size": "0", "side": "BUY", "hash": "37d31a359998b15459acf9fd23380092ae87746d", "best_bid": "0.5", "best_ask": "0.57"}, {"asset_id": "48505873629919993069307707366966856150423552939624109422369276111454667757058", "price": "0.65", "size": "0", "side": "SELL", "hash": "aaf3be7999b105570304b87ae43cfca9c857ea4d", "best_bid": "0.43", "best_ask": "0.5"}], "timestamp": "1769384084464", "event_type": "price_change"}}
{"_local_timestamp": "2026-01-25T23:34:44.530068+00:00", "data": {"market": "0x822409787697144b96f53af76e6419655f5704d5a1382c0604aa01fb331e2ca5", "price_changes": [{"asset_id": "20814542776422534757806032422681843083114551625252466804013971546488759714912", "price": "0.2", "size": "0", "side": "BUY", "hash": "37d31a359998b15459acf9fd23380092ae87746d", "best_bid": "0.5", "best_ask": "0.57"}, {"asset_id": "48505873629919993069307707366966856150423552939624109422369276111454667757058", "price": "0.8", "size": "0", "side": "SELL", "hash": "aaf3be7999b105570304b87ae43cfca9c857ea4d", "best_bid": "0.43", "best_ask": "0.5"}], "timestamp": "1769384084464", "event_type": "price_change"}}
{"_local_timestamp": "2026-01-25T23:34:44.603030+00:00", "data": {"market": "0x822409787697144b96f53af76e6419655f5704d5a1382c0604aa01fb331e2ca5", "price_changes": [{"asset_id": "20814542776422534757806032422681843083114551625252466804013971546488759714912", "price": "0.36", "size": "0", "side": "BUY", "hash": "6167794025aed9eeed31e077f7f7361babb90a48", "best_bid": "0.5", "best_ask": "0.57"}, {"asset_id": "48505873629919993069307707366966856150423552939624109422369276111454667757058", "price": "0.64", "size": "0", "side": "SELL", "hash": "924c4356d8d68eda8f7dfc9591b3084984a3d57d", "best_bid": "0.43", "best_ask": "0.5"}], "timestamp": "1769384084538", "event_type": "price_change"}}
{"_local_timestamp": "2026-01-25T23:34:44.603375+00:00", "data": {"market": "0x268f4042d495b0a3ea61e794c664f1d3796f3a0fc5dab7bf1ad5bfdbf7850d7c", "price_changes": [{"asset_id": "63670917573484538535387075608707689209446344899693197294786093921650274225968", "price": "0.68", "size": "0", "side": "BUY", "hash": "2108e5169a2d8db755826e2f793aea7233c4578d", "best_bid": "0.87", "best_ask": "0.99"}, {"asset_id": "8063468361343945193901601443622223592937597768285686368444925226215635999992", "price": "0.32", "size": "0", "side": "SELL", "hash": "f9e6c75656e7f3852bf3775b8053cf3abbd4e230", "best_bid": "0.01", "best_ask": "0.13"}], "timestamp": "1769384084538", "event_type": "price_change"}}
{"_local_timestamp": "2026-01-25T23:34:44.630591+00:00", "data": {"market": "0x268f4042d495b0a3ea61e794c664f1d3796f3a0fc5dab7bf1ad5bfdbf7850d7c", "price_changes": [{"asset_id": "63670917573484538535387075608707689209446344899693197294786093921650274225968", "price": "0.77", "size": "20", "side": "BUY", "hash": "d6d02f747287591e1c340bed14b67e89b7d898d5", "best_bid": "0.87", "best_ask": "0.99"}, {"asset_id": "8063468361343945193901601443622223592937597768285686368444925226215635999992", "price": "0.23", "size": "20", "side": "SELL", "hash": "ee41a4fad25a427447c28218f31e99b1333e6aa1", "best_bid": "0.01", "best_ask": "0.13"}], "timestamp": "1769384084563", "event_type": "price_change"}}
{"_local_timestamp": "2026-01-25T23:34:44.630934+00:00", "data": {"market": "0x822409787697144b96f53af76e6419655f5704d5a1382c0604aa01fb331e2ca5", "price_changes": [{"asset_id": "20814542776422534757806032422681843083114551625252466804013971546488759714912", "price": "0.25", "size": "20", "side": "BUY", "hash": "35c77e0c08065aca97a00e93be7b8451920afacb", "best_bid": "0.5", "best_ask": "0.57"}, {"asset_id": "48505873629919993069307707366966856150423552939624109422369276111454667757058", "price": "0.75", "size": "20", "side": "SELL", "hash": "a630d2a6865dbbb24b84bc786bf77fa80642c296", "best_bid": "0.43", "best_ask": "0.5"}], "timestamp": "1769384084563", "event_type": "price_change"}}
{"_local_timestamp": "2026-01-25T23:34:44.714594+00:00", "data": {"market": "0x822409787697144b96f53af76e6419655f5704d5a1382c0604aa01fb331e2ca5", "price_changes": [{"asset_id": "20814542776422534757806032422681843083114551625252466804013971546488759714912", "price": "0.45", "size": "0", "side": "BUY", "hash": "2a8cf67dc5548307f8f8472662033cbdb14b35ce", "best_bid": "0.5", "best_ask": "0.57"}, {"asset_id": "48505873629919993069307707366966856150423552939624109422369276111454667757058", "price": "0.55", "size": "0", "side": "SELL", "hash": "7e8fe32c2d81e85615830cc3bf5a9d9cd8ae9874", "best_bid": "0.43", "best_ask": "0.5"}], "timestamp": "1769384084643", "event_type": "price_change"}}
{"_local_timestamp": "2026-01-25T23:34:44.715055+00:00", "data": {"market": "0x268f4042d495b0a3ea61e794c664f1d3796f3a0fc5dab7bf1ad5bfdbf7850d7c", "price_changes": [{"asset_id": "63670917573484538535387075608707689209446344899693197294786093921650274225968", "price": "0.76", "size": "0", "side": "BUY", "hash": "52598f5a09f39ef751a789ef424d1899b11eabf0", "best_bid": "0.87", "best_ask": "0.99"}, {"asset_id": "8063468361343945193901601443622223592937597768285686368444925226215635999992", "price": "0.24", "size": "0", "side": "SELL", "hash": "d5251da4c17251a56670b12e2145313f1ef948b9", "best_bid": "0.01", "best_ask": "0.13"}], "timestamp": "1769384084648", "event_type": "price_change"}}
{"_local_timestamp": "2026-01-25T23:34:44.785287+00:00", "data": {"market": "0x822409787697144b96f53af76e6419655f5704d5a1382c0604aa01fb331e2ca5", "price_changes": [{"asset_id": "20814542776422534757806032422681843083114551625252466804013971546488759714912", "price": "0.31", "size": "50", "side": "BUY", "hash": "d3dc83b7596a73ad5b9200d53a6d309b0ab70467", "best_bid": "0.5", "best_ask": "0.57"}, {"asset_id": "48505873629919993069307707366966856150423552939624109422369276111454667757058", "price": "0.69", "size": "50", "side": "SELL", "hash": "9a49f9630db6bc6cc6610e3e604139a0505e85b9", "best_bid": "0.43", "best_ask": "0.5"}], "timestamp": "1769384084717", "event_type": "price_change"}}
{"_local_timestamp": "2026-01-25T23:34:45.033551+00:00", "data": {"market": "0x822409787697144b96f53af76e6419655f5704d5a1382c0604aa01fb331e2ca5", "price_changes": [{"asset_id": "20814542776422534757806032422681843083114551625252466804013971546488759714912", "price": "0.51", "size": "66.66", "side": "BUY", "hash": "f35792925929a7e9f480572d67d9c017ea6455e0", "best_bid": "0.51", "best_ask": "0.57"}, {"asset_id": "48505873629919993069307707366966856150423552939624109422369276111454667757058", "price": "0.49", "size": "66.66", "side": "SELL", "hash": "e73a817fd3f9c2c1525b30d62d57c38989129d51", "best_bid": "0.43", "best_ask": "0.49"}], "timestamp": "1769384084964", "event_type": "price_change"}}
{"_local_timestamp": "2026-01-25T23:34:45.045337+00:00", "data": {"market": "0x822409787697144b96f53af76e6419655f5704d5a1382c0604aa01fb331e2ca5", "price_changes": [{"asset_id": "20814542776422534757806032422681843083114551625252466804013971546488759714912", "price": "0.35", "size": "66.66", "side": "BUY", "hash": "c51506138462557f99a5f8271911a72bd8d9d6a8", "best_bid": "0.51", "best_ask": "0.57"}, {"asset_id": "48505873629919993069307707366966856150423552939624109422369276111454667757058", "price": "0.65", "size": "66.66", "side": "SELL", "hash": "2deeea40667d904a8270633a596f3d6b1c5c7ee6", "best_bid": "0.43", "best_ask": "0.49"}], "timestamp": "1769384084983", "event_type": "price_change"}}
{"_local_timestamp": "2026-01-25T23:34:45.049151+00:00", "data": {"market": "0x822409787697144b96f53af76e6419655f5704d5a1382c0604aa01fb331e2ca5", "price_changes": [{"asset_id": "20814542776422534757806032422681843083114551625252466804013971546488759714912", "price": "0.2", "size": "66.66", "side": "BUY", "hash": "61d5920a840c0d745cabc2bd96dbf27519a28be5", "best_bid": "0.51", "best_ask": "0.57"}, {"asset_id": "48505873629919993069307707366966856150423552939624109422369276111454667757058", "price": "0.8", "size": "66.66", "side": "SELL", "hash": "72242c2d63992d1c4d020e2c5d5a7beff1f033bf", "best_bid": "0.43", "best_ask": "0.49"}], "timestamp": "1769384084985", "event_type": "price_change"}}
{"_local_timestamp": "2026-01-25T23:34:45.904959+00:00", "data": {"market": "0x822409787697144b96f53af76e6419655f5704d5a1382c0604aa01fb331e2ca5", "price_changes": [{"asset_id": "20814542776422534757806032422681843083114551625252466804013971546488759714912", "price": "0.52", "size": "30", "side": "BUY", "hash": "5a98a9cb0289d4a5120a522410d4e9f946ac3e6d", "best_bid": "0.52", "best_ask": "0.57"}, {"asset_id": "48505873629919993069307707366966856150423552939624109422369276111454667757058", "price": "0.48", "size": "30", "side": "SELL", "hash": "870a0bdeef90556e82d6b9fce1fa7ad39ebe5789", "best_bid": "0.43", "best_ask": "0.48"}], "timestamp": "1769384085841", "event_type": "price_change"}}
{"_local_timestamp": "2026-01-25T23:34:46.021239+00:00", "data": {"market": "0x822409787697144b96f53af76e6419655f5704d5a1382c0604aa01fb331e2ca5", "price_changes": [{"asset_id": "20814542776422534757806032422681843083114551625252466804013971546488759714912", "price": "0.31", "size": "0", "side": "BUY", "hash": "878f31c3fac5bb450a2fdba2b4aec1294c7dcf10", "best_bid": "0.52", "best_ask": "0.57"}, {"asset_id": "48505873629919993069307707366966856150423552939624109422369276111454667757058", "price": "0.69", "size": "0", "side": "SELL", "hash": "6e3fcae6e8274da309ad194c09aef5ed65b15570", "best_bid": "0.43", "best_ask": "0.48"}], "timestamp": "1769384085959", "event_type": "price_change"}}
{"_local_timestamp": "2026-01-25T23:34:46.565519+00:00", "data": {"market": "0x822409787697144b96f53af76e6419655f5704d5a1382c0604aa01fb331e2ca5", "price_changes": [{"asset_id": "20814542776422534757806032422681843083114551625252466804013971546488759714912", "price": "0.24", "size": "0", "side": "BUY", "hash": "1e7dbeae4d72f31909ede7c7162b1902806760e9", "best_bid": "0.52", "best_ask": "0.57"}, {"asset_id": "48505873629919993069307707366966856150423552939624109422369276111454667757058", "price": "0.76", "size": "0", "side": "SELL", "hash": "e4eebcedf9fbebb8153f6f7b63811ddedc17fd34", "best_bid": "0.43", "best_ask": "0.48"}], "timestamp": "1769384086489", "event_type": "price_change"}}
{"_local_timestamp": "2026-01-25T23:34:46.604754+00:00", "data": {"market": "0x822409787697144b96f53af76e6419655f5704d5a1382c0604aa01fb331e2ca5", "price_changes": [{"asset_id": "20814542776422534757806032422681843083114551625252466804013971546488759714912", "price": "0.23", "size": "8", "side": "BUY", "hash": "05074377a5aa0144cfa1055861455db22c6f6b43", "best_bid": "0.52", "best_ask": "0.57"}, {"asset_id": "48505873629919993069307707366966856150423552939624109422369276111454667757058", "price": "0.77", "size": "8", "side": "SELL", "hash": "5296781d7e03b29d877a77cef08782863b0febcf", "best_bid": "0.43", "best_ask": "0.48"}], "timestamp": "1769384086532", "event_type": "price_change"}}
{"_local_timestamp": "2026-01-25T23:34:47.444293+00:00", "data": {"market": "0x822409787697144b96f53af76e6419655f5704d5a1382c0604aa01fb331e2ca5", "price_changes": [{"asset_id": "20814542776422534757806032422681843083114551625252466804013971546488759714912", "price": "0.52", "size": "130", "side": "BUY", "hash": "b503fb337a11cbb53d39cc02282eafb4227a8bd3", "best_bid": "0.52", "best_ask": "0.57"}, {"asset_id": "48505873629919993069307707366966856150423552939624109422369276111454667757058", "price": "0.48", "size": "130", "side": "SELL", "hash": "597ff6a4e319726a4950da5bf217ff7dd45d62bc", "best_bid": "0.43", "best_ask": "0.48"}], "timestamp": "1769384087362", "event_type": "price_change"}}
{"_local_timestamp": "2026-01-25T23:34:47.737281+00:00", "data": {"market": "0x822409787697144b96f53af76e6419655f5704d5a1382c0604aa01fb331e2ca5", "price_changes": [{"asset_id": "20814542776422534757806032422681843083114551625252466804013971546488759714912", "price": "0.25", "size": "0", "side": "BUY", "hash": "e4407e94540526e04ac026c88cf950a8ebe17552", "best_bid": "0.52", "best_ask": "0.57"}, {"asset_id": "48505873629919993069307707366966856150423552939624109422369276111454667757058", "price": "0.75", "size": "0", "side": "SELL", "hash": "8c09368235523f39b0fc1af119273c013c2e88eb", "best_bid": "0.43", "best_ask": "0.48"}], "timestamp": "1769384087674", "event_type": "price_change"}}
{"_local_timestamp": "2026-01-25T23:34:47.737635+00:00", "data": {"market": "0x268f4042d495b0a3ea61e794c664f1d3796f3a0fc5dab7bf1ad5bfdbf7850d7c", "price_changes": [{"asset_id": "63670917573484538535387075608707689209446344899693197294786093921650274225968", "price": "0.77", "size": "0", "side": "BUY", "hash": "419f4c0a710ac72505ca17709adb78d21d44a602", "best_bid": "0.87", "best_ask": "0.99"}, {"asset_id": "8063468361343945193901601443622223592937597768285686368444925226215635999992", "price": "0.23", "size": "0", "side": "SELL", "hash": "80878e3d5bc0fd30c48b28710fe5981c207181ac", "best_bid": "0.01", "best_ask": "0.13"}], "timestamp": "1769384087674", "event_type": "price_change"}}
{"_local_timestamp": "2026-01-25T23:34:47.766364+00:00", "data": {"market": "0x822409787697144b96f53af76e6419655f5704d5a1382c0604aa01fb331e2ca5", "price_changes": [{"asset_id": "20814542776422534757806032422681843083114551625252466804013971546488759714912", "price": "0.36", "size": "20", "side": "BUY", "hash": "6a2225ed80a9ee7a732823709317bbc63f9e2db8", "best_bid": "0.52", "best_ask": "0.57"}, {"asset_id": "48505873629919993069307707366966856150423552939624109422369276111454667757058", "price": "0.64", "size": "20", "side": "SELL", "hash": "567278104aa658bdbdb16c2eb4ad0de15c9879e1", "best_bid": "0.43", "best_ask": "0.48"}], "timestamp": "1769384087701", "event_type": "price_change"}}
{"_local_timestamp": "2026-01-25T23:34:47.768633+00:00", "data": {"market": "0x268f4042d495b0a3ea61e794c664f1d3796f3a0fc5dab7bf1ad5bfdbf7850d7c", "price_changes": [{"asset_id": "63670917573484538535387075608707689209446344899693197294786093921650274225968", "price": "0.68", "size": "20", "side": "BUY", "hash": "add70955f1b372a13207d8825477892e207ff82e", "best_bid": "0.87", "best_ask": "0.99"}, {"asset_id": "8063468361343945193901601443622223592937597768285686368444925226215635999992", "price": "0.32", "size": "20", "side": "SELL", "hash": "5982f11fcdec77c3b84554cf728cd01718b86010", "best_bid": "0.01", "best_ask": "0.13"}], "timestamp": "1769384087702", "event_type": "price_change"}}
{"_local_timestamp": "2026-01-25T23:34:47.876924+00:00", "data": {"market": "0x268f4042d495b0a3ea61e794c664f1d3796f3a0fc5dab7bf1ad5bfdbf7850d7c", "price_changes": [{"asset_id": "63670917573484538535387075608707689209446344899693197294786093921650274225968", "price": "0.76", "size": "25", "side": "BUY", "hash": "ec1324b3e23a37c2663bee04138951cc67d6df10", "best_bid": "0.87", "best_ask": "0.99"}, {"asset_id": "8063468361343945193901601443622223592937597768285686368444925226215635999992", "price": "0.24", "size": "25", "side": "SELL", "hash": "b1b9a8358e4586a884e74932b8116242233d6632", "best_bid": "0.01", "best_ask": "0.13"}], "timestamp": "1769384087814", "event_type": "price_change"}}
{"_local_timestamp": "2026-01-25T23:34:49.752615+00:00", "data": {"market": "0x268f4042d495b0a3ea61e794c664f1d3796f3a0fc5dab7bf1ad5bfdbf7850d7c", "price_changes": [{"asset_id": "63670917573484538535387075608707689209446344899693197294786093921650274225968", "price": "0.68", "size": "0", "side": "BUY", "hash": "7c22dd77df92596dd2adb0c27bc2f99a580feb1c", "best_bid": "0.87", "best_ask": "0.99"}, {"asset_id": "8063468361343945193901601443622223592937597768285686368444925226215635999992", "price": "0.32", "size": "0", "side": "SELL", "hash": "6d6b5ff5785d5327560a0f7c3437b49fa865a539", "best_bid": "0.01", "best_ask": "0.13"}], "timestamp": "1769384089454", "event_type": "price_change"}}
{"_local_timestamp": "2026-01-25T23:34:49.752981+00:00", "data": {"market": "0x268f4042d495b0a3ea61e794c664f1d3796f3a0fc5dab7bf1ad5bfdbf7850d7c", "price_changes": [{"asset_id": "63670917573484538535387075608707689209446344899693197294786093921650274225968", "price": "0.77", "size": "20", "side": "BUY", "hash": "f8da79cf83e193d45b162ea20473bd1294932779", "best_bid": "0.87", "best_ask": "0.99"}, {"asset_id": "8063468361343945193901601443622223592937597768285686368444925226215635999992", "price": "0.23", "size": "20", "side": "SELL", "hash": "10cb1416061e33c410ed861567a795a832ee6819", "best_bid": "0.01", "best_ask": "0.13"}], "timestamp": "1769384089482", "event_type": "price_change"}}
{"_local_timestamp": "2026-01-25T23:34:49.753267+00:00", "data": {"market": "0x268f4042d495b0a3ea61e794c664f1d3796f3a0fc5dab7bf1ad5bfdbf7850d7c", "price_changes": [{"asset_id": "63670917573484538535387075608707689209446344899693197294786093921650274225968", "price": "0.76", "size": "0", "side": "BUY", "hash": "d2131bd9a08a96a696cfcc134c667cdb11cf6448", "best_bid": "0.87", "best_ask": "0.99"}, {"asset_id": "8063468361343945193901601443622223592937597768285686368444925226215635999992", "price": "0.24", "size": "0", "side": "SELL", "hash": "03ca0599b72127aa662f389390198a8483f00857", "best_bid": "0.01", "best_ask": "0.13"}], "timestamp": "1769384089563", "event_type": "price_change"}}
{"_local_timestamp": "2026-01-25T23:34:52.836702+00:00", "data": {"market": "0x268f4042d495b0a3ea61e794c664f1d3796f3a0fc5dab7bf1ad5bfdbf7850d7c", "price_changes": [{"asset_id": "63670917573484538535387075608707689209446344899693197294786093921650274225968", "price": "0.77", "size": "0", "side": "BUY", "hash": "2c7c1e0d5aa70971c72e3ae63c6572bafcf5c80a", "best_bid": "0.87", "best_ask": "0.99"}, {"asset_id": "8063468361343945193901601443622223592937597768285686368444925226215635999992", "price": "0.23", "size": "0", "side": "SELL", "hash": "ca3ca0dc94869bc5b849dcc85bc828b849bc2169", "best_bid": "0.01", "best_ask": "0.13"}], "timestamp": "1769384092769", "event_type": "price_change"}}
{"_local_timestamp": "2026-01-25T23:34:52.857123+00:00", "data": {"market": "0x268f4042d495b0a3ea61e794c664f1d3796f3a0fc5dab7bf1ad5bfdbf7850d7c", "price_changes": [{"asset_id": "63670917573484538535387075608707689209446344899693197294786093921650274225968", "price": "0.68", "size": "20", "side": "BUY", "hash": "8e492783402a9f13219f97ef39c1c120614f0a0c", "best_bid": "0.87", "best_ask": "0.99"}, {"asset_id": "8063468361343945193901601443622223592937597768285686368444925226215635999992", "price": "0.32", "size": "20", "side": "SELL", "hash": "a59b895f39465cd02f71e8075314b1efb2a5325a", "best_bid": "0.01", "best_ask": "0.13"}], "timestamp": "1769384092795", "event_type": "price_change"}}
{"_local_timestamp": "2026-01-25T23:34:52.969044+00:00", "data": {"market": "0x268f4042d495b0a3ea61e794c664f1d3796f3a0fc5dab7bf1ad5bfdbf7850d7c", "price_changes": [{"asset_id": "63670917573484538535387075608707689209446344899693197294786093921650274225968", "price": "0.76", "size": "25", "side": "BUY", "hash": "f1c6f790cb58a606001a6f43eec9298a77954037", "best_bid": "0.87", "best_ask": "0.99"}, {"asset_id": "8063468361343945193901601443622223592937597768285686368444925226215635999992", "price": "0.24", "size": "25", "side": "SELL", "hash": "be01fa841bfdb5442049502ee345c21d37ba3c94", "best_bid": "0.01", "best_ask": "0.13"}], "timestamp": "1769384092904", "event_type": "price_change"}}
{"_local_timestamp": "2026-01-25T23:34:55.164672+00:00", "data": {"market": "0x268f4042d495b0a3ea61e794c664f1d3796f3a0fc5dab7bf1ad5bfdbf7850d7c", "price_changes": [{"asset_id": "63670917573484538535387075608707689209446344899693197294786093921650274225968", "price": "0.68", "size": "0", "side": "BUY", "hash": "5fe0c1bfabdfe5190e55a9db5b8993a2a82a75ab", "best_bid": "0.87", "best_ask": "0.99"}, {"asset_id": "8063468361343945193901601443622223592937597768285686368444925226215635999992", "price": "0.32", "size": "0", "side": "SELL", "hash": "c7063cca7ed24697fa5a20a202f9f685796fb8bd", "best_bid": "0.01", "best_ask": "0.13"}], "timestamp": "1769384095101", "event_type": "price_change"}}
{"_local_timestamp": "2026-01-25T23:34:55.194561+00:00", "data": {"market": "0x268f4042d495b0a3ea61e794c664f1d3796f3a0fc5dab7bf1ad5bfdbf7850d7c", "price_changes": [{"asset_id": "63670917573484538535387075608707689209446344899693197294786093921650274225968", "price": "0.77", "size": "20", "side": "BUY", "hash": "4e4056b1338dd17e8c1ac5b45bba55560031078d", "best_bid": "0.87", "best_ask": "0.99"}, {"asset_id": "8063468361343945193901601443622223592937597768285686368444925226215635999992", "price": "0.23", "size": "20", "side": "SELL", "hash": "c0ca6a7d2f6de7eaae6f36d2b521b6852d604944", "best_bid": "0.01", "best_ask": "0.13"}], "timestamp": "1769384095126", "event_type": "price_change"}}
{"_local_timestamp": "2026-01-25T23:34:55.298687+00:00", "data": {"market": "0x268f4042d495b0a3ea61e794c664f1d3796f3a0fc5dab7bf1ad5bfdbf7850d7c", "price_changes": [{"asset_id": "63670917573484538535387075608707689209446344899693197294786093921650274225968", "price": "0.76", "size": "0", "side": "BUY", "hash": "73f8b30b4bdbc87ca726c5d365fa703d0cf2464b", "best_bid": "0.87", "best_ask": "0.99"}, {"asset_id": "8063468361343945193901601443622223592937597768285686368444925226215635999992", "price": "0.24", "size": "0", "side": "SELL", "hash": "19efa6fee9f7e1025bb94e61329c2b5bb3520941", "best_bid": "0.01", "best_ask": "0.13"}], "timestamp": "1769384095213", "event_type": "price_change"}}
{"_local_timestamp": "2026-01-25T23:34:57.035970+00:00", "data": {"market": "0x268f4042d495b0a3ea61e794c664f1d3796f3a0fc5dab7bf1ad5bfdbf7850d7c", "price_changes": [{"asset_id": "63670917573484538535387075608707689209446344899693197294786093921650274225968", "price": "0.77", "size": "0", "side": "BUY", "hash": "30810902662280402124bf13b9ab344e5046ace0", "best_bid": "0.87", "best_ask": "0.99"}, {"asset_id": "8063468361343945193901601443622223592937597768285686368444925226215635999992", "price": "0.23", "size": "0", "side": "SELL", "hash": "58f36ff5fb6e9771785d26a5439472b35be8c32f", "best_bid": "0.01", "best_ask": "0.13"}], "timestamp": "1769384096919", "event_type": "price_change"}}
{"_local_timestamp": "2026-01-25T23:34:57.046387+00:00", "data": {"market": "0x268f4042d495b0a3ea61e794c664f1d3796f3a0fc5dab7bf1ad5bfdbf7850d7c", "price_changes": [{"asset_id": "63670917573484538535387075608707689209446344899693197294786093921650274225968", "price": "0.68", "size": "20", "side": "BUY", "hash": "1d4c998d879d51e90a2439991c68e00473e9f47a", "best_bid": "0.87", "best_ask": "0.99"}, {"asset_id": "8063468361343945193901601443622223592937597768285686368444925226215635999992", "price": "0.32", "size": "20", "side": "SELL", "hash": "b96e19e9e328b8895ca8340bcf8316f82b23014d", "best_bid": "0.01", "best_ask": "0.13"}], "timestamp": "1769384096945", "event_type": "price_change"}}
{"_local_timestamp": "2026-01-25T23:34:57.149469+00:00", "data": {"market": "0x268f4042d495b0a3ea61e794c664f1d3796f3a0fc5dab7bf1ad5bfdbf7850d7c", "price_changes": [{"asset_id": "63670917573484538535387075608707689209446344899693197294786093921650274225968", "price": "0.76", "size": "25", "side": "BUY", "hash": "e3e4a3186435e156b10b78b57cca6baf14459de3", "best_bid": "0.87", "best_ask": "0.99"}, {"asset_id": "8063468361343945193901601443622223592937597768285686368444925226215635999992", "price": "0.24", "size": "25", "side": "SELL", "hash": "8ef15a9b00f7c00864be9c7bf72e5af136137700", "best_bid": "0.01", "best_ask": "0.13"}], "timestamp": "1769384097080", "event_type": "price_change"}}
{"_local_timestamp": "2026-01-25T23:35:00.061895+00:00", "data": {"market": "0x822409787697144b96f53af76e6419655f5704d5a1382c0604aa01fb331e2ca5", "price_changes": [{"asset_id": "20814542776422534757806032422681843083114551625252466804013971546488759714912", "price": "0.01", "size": "5817.03", "side": "BUY", "hash": "53764a599f5d03ead2f337c56632050023fcbd32", "best_bid": "0.52", "best_ask": "0.57"}, {"asset_id": "48505873629919993069307707366966856150423552939624109422369276111454667757058", "price": "0.99", "size": "5817.03", "side": "SELL", "hash": "d77514c2bdc0aa4fe918b1199a3c35da8c648182", "best_bid": "0.43", "best_ask": "0.48"}], "timestamp": "1769384099981", "event_type": "price_change"}}
{"_local_timestamp": "2026-01-25T23:35:01.726742+00:00", "data": {"market": "0x268f4042d495b0a3ea61e794c664f1d3796f3a0fc5dab7bf1ad5bfdbf7850d7c", "price_changes": [{"asset_id": "63670917573484538535387075608707689209446344899693197294786093921650274225968", "price": "0.68", "size": "0", "side": "BUY", "hash": "1f6869f34034cb56bf5838a2cd72c97be819b92e", "best_bid": "0.87", "best_ask": "0.99"}, {"asset_id": "8063468361343945193901601443622223592937597768285686368444925226215635999992", "price": "0.32", "size": "0", "side": "SELL", "hash": "ebe10199e097dcd3f1f2c771d3075825da01f411", "best_bid": "0.01", "best_ask": "0.13"}], "timestamp": "1769384101648", "event_type": "price_change"}}
{"_local_timestamp": "2026-01-25T23:35:01.744448+00:00", "data": {"market": "0x268f4042d495b0a3ea61e794c664f1d3796f3a0fc5dab7bf1ad5bfdbf7850d7c", "price_changes": [{"asset_id": "63670917573484538535387075608707689209446344899693197294786093921650274225968", "price": "0.77", "size": "20", "side": "BUY", "hash": "38ff7760a135e85f8646b118afb1c155e966dc64", "best_bid": "0.87", "best_ask": "0.99"}, {"asset_id": "8063468361343945193901601443622223592937597768285686368444925226215635999992", "price": "0.23", "size": "20", "side": "SELL", "hash": "802871c2bd1a4d9f9370c0bc4a7f1497b4e87ea4", "best_bid": "0.01", "best_ask": "0.13"}], "timestamp": "1769384101672", "event_type": "price_change"}}
{"_local_timestamp": "2026-01-25T23:35:01.824336+00:00", "data": {"market": "0x268f4042d495b0a3ea61e794c664f1d3796f3a0fc5dab7bf1ad5bfdbf7850d7c", "price_changes": [{"asset_id": "63670917573484538535387075608707689209446344899693197294786093921650274225968", "price": "0.76", "size": "0", "side": "BUY", "hash": "261324d33837491e2ed33103104d749c8893bc61", "best_bid": "0.87", "best_ask": "0.99"}, {"asset_id": "8063468361343945193901601443622223592937597768285686368444925226215635999992", "price": "0.24", "size": "0", "side": "SELL", "hash": "3a720453b45c874e68686bf8eba3f245d640501b", "best_bid": "0.01", "best_ask": "0.13"}], "timestamp": "1769384101753", "event_type": "price_change"}}
{"_local_timestamp": "2026-01-25T23:35:02.078098+00:00", "data": {"market": "0x822409787697144b96f53af76e6419655f5704d5a1382c0604aa01fb331e2ca5", "price_changes": [{"asset_id": "48505873629919993069307707366966856150423552939624109422369276111454667757058", "price": "0.08", "size": "425", "side": "BUY", "hash": "27dda4b1b0cf0f8bb34af1aa41f3e8712f412e04", "best_bid": "0.43", "best_ask": "0.48"}, {"asset_id": "20814542776422534757806032422681843083114551625252466804013971546488759714912", "price": "0.92", "size": "425", "side": "SELL", "hash": "7c8efb2b6db5673a405d69ce108d58efa9453b47", "best_bid": "0.52", "best_ask": "0.57"}], "timestamp": "1769384102002", "event_type": "price_change"}}
{"_local_timestamp": "2026-01-25T23:35:02.372184+00:00", "data": {"market": "0x822409787697144b96f53af76e6419655f5704d5a1382c0604aa01fb331e2ca5", "price_changes": [{"asset_id": "48505873629919993069307707366966856150423552939624109422369276111454667757058", "price": "0.08", "size": "431.54", "side": "BUY", "hash": "4bf86a9bd26b594bd6a0a0b928ca941b06c13121", "best_bid": "0.43", "best_ask": "0.48"}, {"asset_id": "20814542776422534757806032422681843083114551625252466804013971546488759714912", "price": "0.92", "size": "431.54", "side": "SELL", "hash": "b70eae881aa2ef0c56f85983afbab1f02a78ac34", "best_bid": "0.52", "best_ask": "0.57"}], "timestamp": "1769384102310", "event_type": "price_change"}}
{"_local_timestamp": "2026-01-25T23:35:04.260052+00:00", "data": {"market": "0x268f4042d495b0a3ea61e794c664f1d3796f3a0fc5dab7bf1ad5bfdbf7850d7c", "price_changes": [{"asset_id": "63670917573484538535387075608707689209446344899693197294786093921650274225968", "price": "0.77", "size": "0", "side": "BUY", "hash": "4a7969bbd4b8fd870901ded7877a2f6438fa4518", "best_bid": "0.87", "best_ask": "0.99"}, {"asset_id": "8063468361343945193901601443622223592937597768285686368444925226215635999992", "price": "0.23", "size": "0", "side": "SELL", "hash": "ac107a742ea5797a0d3088a0dec06398d94314df", "best_bid": "0.01", "best_ask": "0.13"}], "timestamp": "1769384104196", "event_type": "price_change"}}
{"_local_timestamp": "2026-01-25T23:35:04.292404+00:00", "data": {"market": "0x268f4042d495b0a3ea61e794c664f1d3796f3a0fc5dab7bf1ad5bfdbf7850d7c", "price_changes": [{"asset_id": "63670917573484538535387075608707689209446344899693197294786093921650274225968", "price": "0.68", "size": "20", "side": "BUY", "hash": "03cc679328e3bbde349f7624e08a2a6d858ec32d", "best_bid": "0.87", "best_ask": "0.99"}, {"asset_id": "8063468361343945193901601443622223592937597768285686368444925226215635999992", "price": "0.32", "size": "20", "side": "SELL", "hash": "83aacccee7517e431b67c89afea805c982f30136", "best_bid": "0.01", "best_ask": "0.13"}], "timestamp": "1769384104222", "event_type": "price_change"}}
{"_local_timestamp": "2026-01-25T23:35:04.392284+00:00", "data": {"market": "0x268f4042d495b0a3ea61e794c664f1d3796f3a0fc5dab7bf1ad5bfdbf7850d7c", "price_changes": [{"asset_id": "63670917573484538535387075608707689209446344899693197294786093921650274225968", "price": "0.76", "size": "25", "side": "BUY", "hash": "ae743db9d9c4c109420eb404051b5ed657f0530d", "best_bid": "0.87", "best_ask": "0.99"}, {"asset_id": "8063468361343945193901601443622223592937597768285686368444925226215635999992", "price": "0.24", "size": "25", "side": "SELL", "hash": "3f9a9f6e634e37fc022f2878bc8af7711115db20", "best_bid": "0.01", "best_ask": "0.13"}], "timestamp": "1769384104330", "event_type": "price_change"}}
{"_local_timestamp": "2026-01-25T23:35:06.849901+00:00", "data": {"market": "0x268f4042d495b0a3ea61e794c664f1d3796f3a0fc5dab7bf1ad5bfdbf7850d7c", "price_changes": [{"asset_id": "63670917573484538535387075608707689209446344899693197294786093921650274225968", "price": "0.68", "size": "0", "side": "BUY", "hash": "dd272782bac1953e3fbb43d6b0e3a80916dbdd39", "best_bid": "0.87", "best_ask": "0.99"}, {"asset_id": "8063468361343945193901601443622223592937597768285686368444925226215635999992", "price": "0.32", "size": "0", "side": "SELL", "hash": "f6644cd37434dd814190621bc614aca62fdc5267", "best_bid": "0.01", "best_ask": "0.13"}], "timestamp": "1769384106784", "event_type": "price_change"}}
{"_local_timestamp": "2026-01-25T23:35:06.876043+00:00", "data": {"market": "0x268f4042d495b0a3ea61e794c664f1d3796f3a0fc5dab7bf1ad5bfdbf7850d7c", "price_changes": [{"asset_id": "63670917573484538535387075608707689209446344899693197294786093921650274225968", "price": "0.77", "size": "20", "side": "BUY", "hash": "f7a2c86f436ac33358b8ec26d759fa74a3344551", "best_bid": "0.87", "best_ask": "0.99"}, {"asset_id": "8063468361343945193901601443622223592937597768285686368444925226215635999992", "price": "0.23", "size": "20", "side": "SELL", "hash": "5c0446ad2e3a55a46db37da84de1c7a635a34a16", "best_bid": "0.01", "best_ask": "0.13"}], "timestamp": "1769384106810", "event_type": "price_change"}}
{"_local_timestamp": "2026-01-25T23:35:06.985564+00:00", "data": {"market": "0x268f4042d495b0a3ea61e794c664f1d3796f3a0fc5dab7bf1ad5bfdbf7850d7c", "price_changes": [{"asset_id": "63670917573484538535387075608707689209446344899693197294786093921650274225968", "price": "0.76", "size": "0", "side": "BUY", "hash": "e672e5251c6832154cbc7cbad335b3a17c8dfcc5", "best_bid": "0.87", "best_ask": "0.99"}, {"asset_id": "8063468361343945193901601443622223592937597768285686368444925226215635999992", "price": "0.24", "size": "0", "side": "SELL", "hash": "600700fcccd9e63a8a52ab082a5a6fca9e3d4c4c", "best_bid": "0.01", "best_ask": "0.13"}], "timestamp": "1769384106911", "event_type": "price_change"}}
{"_local_timestamp": "2026-01-25T23:35:11.411358+00:00", "data": {"market": "0x268f4042d495b0a3ea61e794c664f1d3796f3a0fc5dab7bf1ad5bfdbf7850d7c", "price_changes": [{"asset_id": "63670917573484538535387075608707689209446344899693197294786093921650274225968", "price": "0.77", "size": "0", "side": "BUY", "hash": "e1fc096e3caf86086135da6eefba660e7f7fd75d", "best_bid": "0.87", "best_ask": "0.99"}, {"asset_id": "8063468361343945193901601443622223592937597768285686368444925226215635999992", "price": "0.23", "size": "0", "side": "SELL", "hash": "8d0163ef21c4f737114e7d30218b86d2543bc17d", "best_bid": "0.01", "best_ask": "0.13"}], "timestamp": "1769384111340", "event_type": "price_change"}}
{"_local_timestamp": "2026-01-25T23:35:11.428411+00:00", "data": {"market": "0x268f4042d495b0a3ea61e794c664f1d3796f3a0fc5dab7bf1ad5bfdbf7850d7c", "price_changes": [{"asset_id": "63670917573484538535387075608707689209446344899693197294786093921650274225968", "price": "0.68", "size": "20", "side": "BUY", "hash": "13a633d2c5d3b8a018b3a5390d38cdd03e81e8fd", "best_bid": "0.87", "best_ask": "0.99"}, {"asset_id": "8063468361343945193901601443622223592937597768285686368444925226215635999992", "price": "0.32", "size": "20", "side": "SELL", "hash": "8ca0adacad3688e22bf1da9fb91f63bbd72e640b", "best_bid": "0.01", "best_ask": "0.13"}], "timestamp": "1769384111365", "event_type": "price_change"}}
{"_local_timestamp": "2026-01-25T23:35:11.544331+00:00", "data": {"market": "0x268f4042d495b0a3ea61e794c664f1d3796f3a0fc5dab7bf1ad5bfdbf7850d7c", "price_changes": [{"asset_id": "63670917573484538535387075608707689209446344899693197294786093921650274225968", "price": "0.76", "size": "25", "side": "BUY", "hash": "002ecd253a9ad1996f346e32635d671e73c6e94e", "best_bid": "0.87", "best_ask": "0.99"}, {"asset_id": "8063468361343945193901601443622223592937597768285686368444925226215635999992", "price": "0.24", "size": "25", "side": "SELL", "hash": "4909f395aff25f24f30413eec827cb56ca2675dd", "best_bid": "0.01", "best_ask": "0.13"}], "timestamp": "1769384111481", "event_type": "price_change"}}
{"_local_timestamp": "2026-01-25T23:35:13.503513+00:00", "data": {"market": "0x268f4042d495b0a3ea61e794c664f1d3796f3a0fc5dab7bf1ad5bfdbf7850d7c", "price_changes": [{"asset_id": "63670917573484538535387075608707689209446344899693197294786093921650274225968", "price": "0.68", "size": "0", "side": "BUY", "hash": "c72eb15ad79332b3cfb8c10450041b32e2d194f2", "best_bid": "0.87", "best_ask": "0.99"}, {"asset_id": "8063468361343945193901601443622223592937597768285686368444925226215635999992", "price": "0.32", "size": "0", "side": "SELL", "hash": "194bf577f023f267ea7414fb0db5146254c87a54", "best_bid": "0.01", "best_ask": "0.13"}], "timestamp": "1769384113372", "event_type": "price_change"}}
{"_local_timestamp": "2026-01-25T23:35:13.538494+00:00", "data": {"market": "0x268f4042d495b0a3ea61e794c664f1d3796f3a0fc5dab7bf1ad5bfdbf7850d7c", "price_changes": [{"asset_id": "63670917573484538535387075608707689209446344899693197294786093921650274225968", "price": "0.77", "size": "20", "side": "BUY", "hash": "6296933304c1bc7c3c6c519de88b40be664dbcc6", "best_bid": "0.87", "best_ask": "0.99"}, {"asset_id": "8063468361343945193901601443622223592937597768285686368444925226215635999992", "price": "0.23", "size": "20", "side": "SELL", "hash": "1b940b7ea7033e94146e17542c001192cfa73242", "best_bid": "0.01", "best_ask": "0.13"}], "timestamp": "1769384113408", "event_type": "price_change"}}
{"_local_timestamp": "2026-01-25T23:35:13.742792+00:00", "data": {"market": "0x268f4042d495b0a3ea61e794c664f1d3796f3a0fc5dab7bf1ad5bfdbf7850d7c", "price_changes": [{"asset_id": "63670917573484538535387075608707689209446344899693197294786093921650274225968", "price": "0.76", "size": "0", "side": "BUY", "hash": "b1e5a63baa70a62813d5c90d23ea4e51608c9d34", "best_bid": "0.87", "best_ask": "0.99"}, {"asset_id": "8063468361343945193901601443622223592937597768285686368444925226215635999992", "price": "0.24", "size": "0", "side": "SELL", "hash": "c05c5722a875e19f1fbeb61e71173fd1901cf50d", "best_bid": "0.01", "best_ask": "0.13"}], "timestamp": "1769384113635", "event_type": "price_change"}}
{"_local_timestamp": "2026-01-25T23:35:15.743665+00:00", "data": {"market": "0x268f4042d495b0a3ea61e794c664f1d3796f3a0fc5dab7bf1ad5bfdbf7850d7c", "price_changes": [{"asset_id": "63670917573484538535387075608707689209446344899693197294786093921650274225968", "price": "0.77", "size": "0", "side": "BUY", "hash": "9431d0e4960239a13a6f3d62458dd11edb8e1251", "best_bid": "0.87", "best_ask": "0.99"}, {"asset_id": "8063468361343945193901601443622223592937597768285686368444925226215635999992", "price": "0.23", "size": "0", "side": "SELL", "hash": "75fbc246f49d2c37e8aeb9413fd8c5a76dc6f0e4", "best_bid": "0.01", "best_ask": "0.13"}], "timestamp": "1769384115673", "event_type": "price_change"}}
{"_local_timestamp": "2026-01-25T23:35:15.766400+00:00", "data": {"market": "0x268f4042d495b0a3ea61e794c664f1d3796f3a0fc5dab7bf1ad5bfdbf7850d7c", "price_changes": [{"asset_id": "63670917573484538535387075608707689209446344899693197294786093921650274225968", "price": "0.68", "size": "20", "side": "BUY", "hash": "97563c874bb0bd173d300fe7d3a94c3725089ce8", "best_bid": "0.87", "best_ask": "0.99"}, {"asset_id": "8063468361343945193901601443622223592937597768285686368444925226215635999992", "price": "0.32", "size": "20", "side": "SELL", "hash": "5a871e2763e5f4f0f538e9c51eddaf43ec680180", "best_bid": "0.01", "best_ask": "0.13"}], "timestamp": "1769384115699", "event_type": "price_change"}}
{"_local_timestamp": "2026-01-25T23:35:15.903181+00:00", "data": {"market": "0x268f4042d495b0a3ea61e794c664f1d3796f3a0fc5dab7bf1ad5bfdbf7850d7c", "price_changes": [{"asset_id": "63670917573484538535387075608707689209446344899693197294786093921650274225968", "price": "0.76", "size": "25", "side": "BUY", "hash": "98c0675f33b69c87f47acba7a2f868d683aee085", "best_bid": "0.87", "best_ask": "0.99"}, {"asset_id": "8063468361343945193901601443622223592937597768285686368444925226215635999992", "price": "0.24", "size": "25", "side": "SELL", "hash": "09c0fd650900fd91ad0a2d77d2f66e476a12beae", "best_bid": "0.01", "best_ask": "0.13"}], "timestamp": "1769384115836", "event_type": "price_change"}}
{"_local_timestamp": "2026-01-25T23:35:20.230518+00:00", "data": {"market": "0x268f4042d495b0a3ea61e794c664f1d3796f3a0fc5dab7bf1ad5bfdbf7850d7c", "price_changes": [{"asset_id": "63670917573484538535387075608707689209446344899693197294786093921650274225968", "price": "0.68", "size": "0", "side": "BUY", "hash": "3324d64711c9f9cfd686d654ee09bc37d91d56eb", "best_bid": "0.87", "best_ask": "0.99"}, {"asset_id": "8063468361343945193901601443622223592937597768285686368444925226215635999992", "price": "0.32", "size": "0", "side": "SELL", "hash": "b3c2a6b2f4574f284482e80077a309d10177f3c9", "best_bid": "0.01", "best_ask": "0.13"}], "timestamp": "1769384120151", "event_type": "price_change"}}
{"_local_timestamp": "2026-01-25T23:35:20.251984+00:00", "data": {"market": "0x268f4042d495b0a3ea61e794c664f1d3796f3a0fc5dab7bf1ad5bfdbf7850d7c", "price_changes": [{"asset_id": "63670917573484538535387075608707689209446344899693197294786093921650274225968", "price": "0.77", "size": "20", "side": "BUY", "hash": "7ec636b55d916263cec9bb7eedfea1bb418566e8", "best_bid": "0.87", "best_ask": "0.99"}, {"asset_id": "8063468361343945193901601443622223592937597768285686368444925226215635999992", "price": "0.23", "size": "20", "side": "SELL", "hash": "e8a463fedbc9e69ed00e2997792b188971f09431", "best_bid": "0.01", "best_ask": "0.13"}], "timestamp": "1769384120176", "event_type": "price_change"}}
{"_local_timestamp": "2026-01-25T23:35:20.337399+00:00", "data": {"market": "0x268f4042d495b0a3ea61e794c664f1d3796f3a0fc5dab7bf1ad5bfdbf7850d7c", "price_changes": [{"asset_id": "63670917573484538535387075608707689209446344899693197294786093921650274225968", "price": "0.76", "size": "0", "side": "BUY", "hash": "c7567e2e29a5c2bd0968738080415fd5faab836b", "best_bid": "0.87", "best_ask": "0.99"}, {"asset_id": "8063468361343945193901601443622223592937597768285686368444925226215635999992", "price": "0.24", "size": "0", "side": "SELL", "hash": "df37db9ecb7eb59ce601d457075f848ced98ac22", "best_bid": "0.01", "best_ask": "0.13"}], "timestamp": "1769384120274", "event_type": "price_change"}}
{"_local_timestamp": "2026-01-25T23:35:23.751480+00:00", "data": {"market": "0x822409787697144b96f53af76e6419655f5704d5a1382c0604aa01fb331e2ca5", "price_changes": [{"asset_id": "20814542776422534757806032422681843083114551625252466804013971546488759714912", "price": "0.16", "size": "162.5", "side": "BUY", "hash": "cc050e460b73a9d45680390ae8c786adf08b6bd9", "best_bid": "0.52", "best_ask": "0.57"}, {"asset_id": "48505873629919993069307707366966856150423552939624109422369276111454667757058", "price": "0.84", "size": "162.5", "side": "SELL", "hash": "7cb3ba4ca98f6190cb898cdeb458902682fd81ef", "best_bid": "0.43", "best_ask": "0.48"}], "timestamp": "1769384123670", "event_type": "price_change"}}
{"_local_timestamp": "2026-01-25T23:35:24.184226+00:00", "data": {"market": "0x822409787697144b96f53af76e6419655f5704d5a1382c0604aa01fb331e2ca5", "price_changes": [{"asset_id": "20814542776422534757806032422681843083114551625252466804013971546488759714912", "price": "0.22", "size": "190.9", "side": "BUY", "hash": "845d8b3c584f8ae97286142f0272cd0447a3d49e", "best_bid": "0.52", "best_ask": "0.57"}, {"asset_id": "48505873629919993069307707366966856150423552939624109422369276111454667757058", "price": "0.78", "size": "190.9", "side": "SELL", "hash": "65b198f3b3ffdd015a01438a2508a90d7ee35ff3", "best_bid": "0.43", "best_ask": "0.48"}], "timestamp": "1769384123936", "event_type": "price_change"}}
{"_local_timestamp": "2026-01-25T23:35:24.199781+00:00", "data": {"market": "0x822409787697144b96f53af76e6419655f5704d5a1382c0604aa01fb331e2ca5", "price_changes": [{"asset_id": "20814542776422534757806032422681843083114551625252466804013971546488759714912", "price": "0.17", "size": "405.33", "side": "BUY", "hash": "6d3f68dd75bc7c9026b4d2a850a6c92d64408fd9", "best_bid": "0.52", "best_ask": "0.57"}, {"asset_id": "48505873629919993069307707366966856150423552939624109422369276111454667757058", "price": "0.83", "size": "405.33", "side": "SELL", "hash": "4e0778246a41a231740b55dd914ac98305c20528", "best_bid": "0.43", "best_ask": "0.48"}], "timestamp": "1769384124049", "event_type": "price_change"}}
{"_local_timestamp": "2026-01-25T23:35:25.104594+00:00", "data": {"market": "0x268f4042d495b0a3ea61e794c664f1d3796f3a0fc5dab7bf1ad5bfdbf7850d7c", "price_changes": [{"asset_id": "63670917573484538535387075608707689209446344899693197294786093921650274225968", "price": "0.77", "size": "0", "side": "BUY", "hash": "a190d99efa73b546b53a2edd79e6b0f6bf523280", "best_bid": "0.87", "best_ask": "0.99"}, {"asset_id": "8063468361343945193901601443622223592937597768285686368444925226215635999992", "price": "0.23", "size": "0", "side": "SELL", "hash": "11eda1ec6648fd46647a6d8de65ec2f86fef1a87", "best_bid": "0.01", "best_ask": "0.13"}], "timestamp": "1769384125018", "event_type": "price_change"}}
{"_local_timestamp": "2026-01-25T23:35:25.111736+00:00", "data": {"market": "0x268f4042d495b0a3ea61e794c664f1d3796f3a0fc5dab7bf1ad5bfdbf7850d7c", "price_changes": [{"asset_id": "63670917573484538535387075608707689209446344899693197294786093921650274225968", "price": "0.68", "size": "20", "side": "BUY", "hash": "35b26b44bd7df33eefdbc16769373b964ee9e801", "best_bid": "0.87", "best_ask": "0.99"}, {"asset_id": "8063468361343945193901601443622223592937597768285686368444925226215635999992", "price": "0.32", "size": "20", "side": "SELL", "hash": "31aa58f485a2d5e71bbf571f7373db0681a024bb", "best_bid": "0.01", "best_ask": "0.13"}], "timestamp": "1769384125045", "event_type": "price_change"}}
{"_local_timestamp": "2026-01-25T23:35:25.225179+00:00", "data": {"market": "0x268f4042d495b0a3ea61e794c664f1d3796f3a0fc5dab7bf1ad5bfdbf7850d7c", "price_changes": [{"asset_id": "63670917573484538535387075608707689209446344899693197294786093921650274225968", "price": "0.76", "size": "25", "side": "BUY", "hash": "2c8c2b4f3dbedd49c8d2d33da945e2dc21f492f0", "best_bid": "0.87", "best_ask": "0.99"}, {"asset_id": "8063468361343945193901601443622223592937597768285686368444925226215635999992", "price": "0.24", "size": "25", "side": "SELL", "hash": "a0630383050f718ba7a985ba65e71bfe30b3115a", "best_bid": "0.01", "best_ask": "0.13"}], "timestamp": "1769384125163", "event_type": "price_change"}}
{"_local_timestamp": "2026-01-25T23:35:29.658777+00:00", "data": {"market": "0x268f4042d495b0a3ea61e794c664f1d3796f3a0fc5dab7bf1ad5bfdbf7850d7c", "price_changes": [{"asset_id": "63670917573484538535387075608707689209446344899693197294786093921650274225968", "price": "0.68", "size": "0", "side": "BUY", "hash": "87271e936fabf653decbde9ddeabd20150c58f46", "best_bid": "0.87", "best_ask": "0.99"}, {"asset_id": "8063468361343945193901601443622223592937597768285686368444925226215635999992", "price": "0.32", "size": "0", "side": "SELL", "hash": "1141079072998106f762507951c950edbedf860c", "best_bid": "0.01", "best_ask": "0.13"}], "timestamp": "1769384129591", "event_type": "price_change"}}
{"_local_timestamp": "2026-01-25T23:35:29.678768+00:00", "data": {"market": "0x268f4042d495b0a3ea61e794c664f1d3796f3a0fc5dab7bf1ad5bfdbf7850d7c", "price_changes": [{"asset_id": "63670917573484538535387075608707689209446344899693197294786093921650274225968", "price": "0.77", "size": "20", "side": "BUY", "hash": "766b664d8332824dd2c90367b5ede1da6bb78b79", "best_bid": "0.87", "best_ask": "0.99"}, {"asset_id": "8063468361343945193901601443622223592937597768285686368444925226215635999992", "price": "0.23", "size": "20", "side": "SELL", "hash": "d5d76184022cafd80c6f37cab8c2a3507917b021", "best_bid": "0.01", "best_ask": "0.13"}], "timestamp": "1769384129615", "event_type": "price_change"}}
{"_local_timestamp": "2026-01-25T23:35:29.766850+00:00", "data": {"market": "0x268f4042d495b0a3ea61e794c664f1d3796f3a0fc5dab7bf1ad5bfdbf7850d7c", "price_changes": [{"asset_id": "63670917573484538535387075608707689209446344899693197294786093921650274225968", "price": "0.76", "size": "0", "side": "BUY", "hash": "5180e626517709985d392da40e118a01f4cdd098", "best_bid": "0.87", "best_ask": "0.99"}, {"asset_id": "8063468361343945193901601443622223592937597768285686368444925226215635999992", "price": "0.24", "size": "0", "side": "SELL", "hash": "9c4fd3f2a2d1373aceafb768a35343a28b000186", "best_bid": "0.01", "best_ask": "0.13"}], "timestamp": "1769384129703", "event_type": "price_change"}}
{"_local_timestamp": "2026-01-25T23:35:31.101243+00:00", "data": {"market": "0x822409787697144b96f53af76e6419655f5704d5a1382c0604aa01fb331e2ca5", "price_changes": [{"asset_id": "20814542776422534757806032422681843083114551625252466804013971546488759714912", "price": "0.19", "size": "176.31", "side": "BUY", "hash": "44c7a3b332e66652cabfbf91236a5c92d07e9966", "best_bid": "0.52", "best_ask": "0.57"}, {"asset_id": "48505873629919993069307707366966856150423552939624109422369276111454667757058", "price": "0.81", "size": "176.31", "side": "SELL", "hash": "abe3922e2b9f41dbd5a5cd4ba2bfecf7cde9c948", "best_bid": "0.43", "best_ask": "0.48"}], "timestamp": "1769384131025", "event_type": "price_change"}}
{"_local_timestamp": "2026-01-25T23:35:31.118774+00:00", "data": {"market": "0x822409787697144b96f53af76e6419655f5704d5a1382c0604aa01fb331e2ca5", "price_changes": [{"asset_id": "20814542776422534757806032422681843083114551625252466804013971546488759714912", "price": "0.08", "size": "850", "side": "BUY", "hash": "c7ca2a009a8c8a9734e6177bd5130315ba208cd5", "best_bid": "0.52", "best_ask": "0.57"}, {"asset_id": "48505873629919993069307707366966856150423552939624109422369276111454667757058", "price": "0.92", "size": "850", "side": "SELL", "hash": "4106170e001002207b3208750a9654a1d8692c5f", "best_bid": "0.43", "best_ask": "0.48"}], "timestamp": "1769384131047", "event_type": "price_change"}}
{"_local_timestamp": "2026-01-25T23:35:33.565371+00:00", "data": {"market": "0x822409787697144b96f53af76e6419655f5704d5a1382c0604aa01fb331e2ca5", "price_changes": [{"asset_id": "48505873629919993069307707366966856150423552939624109422369276111454667757058", "price": "0.33", "size": "27", "side": "BUY", "hash": "8944dba28b3fd9a7b925d128e101ca74c6646e7a", "best_bid": "0.43", "best_ask": "0.48"}, {"asset_id": "20814542776422534757806032422681843083114551625252466804013971546488759714912", "price": "0.67", "size": "27", "side": "SELL", "hash": "b31ab8ce4d08b5332b5c14bdfc5ce60ccebaf299", "best_bid": "0.52", "best_ask": "0.57"}], "timestamp": "1769384133486", "event_type": "price_change"}}
{"_local_timestamp": "2026-01-25T23:35:37.399212+00:00", "data": {"market": "0x268f4042d495b0a3ea61e794c664f1d3796f3a0fc5dab7bf1ad5bfdbf7850d7c", "price_changes": [{"asset_id": "63670917573484538535387075608707689209446344899693197294786093921650274225968", "price": "0.77", "size": "0", "side": "BUY", "hash": "c58c45b03acc3dbeb5d13925e663d03cf155c943", "best_bid": "0.87", "best_ask": "0.99"}, {"asset_id": "8063468361343945193901601443622223592937597768285686368444925226215635999992", "price": "0.23", "size": "0", "side": "SELL", "hash": "88d4c6c0151ed2533e89962c39a322b70f0c38c4", "best_bid": "0.01", "best_ask": "0.13"}], "timestamp": "1769384137327", "event_type": "price_change"}}
{"_local_timestamp": "2026-01-25T23:35:37.418910+00:00", "data": {"market": "0x268f4042d495b0a3ea61e794c664f1d3796f3a0fc5dab7bf1ad5bfdbf7850d7c", "price_changes": [{"asset_id": "63670917573484538535387075608707689209446344899693197294786093921650274225968", "price": "0.68", "size": "20", "side": "BUY", "hash": "e43e0e39d77c5d7a56b6e393593e2253d704f3c6", "best_bid": "0.87", "best_ask": "0.99"}, {"asset_id": "8063468361343945193901601443622223592937597768285686368444925226215635999992", "price": "0.32", "size": "20", "side": "SELL", "hash": "5425fc525f499d568eefcb0b682a94d0149c749e", "best_bid": "0.01", "best_ask": "0.13"}], "timestamp": "1769384137354", "event_type": "price_change"}}
{"_local_timestamp": "2026-01-25T23:35:37.539423+00:00", "data": {"market": "0x268f4042d495b0a3ea61e794c664f1d3796f3a0fc5dab7bf1ad5bfdbf7850d7c", "price_changes": [{"asset_id": "63670917573484538535387075608707689209446344899693197294786093921650274225968", "price": "0.76", "size": "25", "side": "BUY", "hash": "80299a30a37147b9b374014124f48660b9a8fea6", "best_bid": "0.87", "best_ask": "0.99"}, {"asset_id": "8063468361343945193901601443622223592937597768285686368444925226215635999992", "price": "0.24", "size": "25", "side": "SELL", "hash": "29237b8960355d23e83ed40a77bd8343e203cad2", "best_bid": "0.01", "best_ask": "0.13"}], "timestamp": "1769384137470", "event_type": "price_change"}}
{"_local_timestamp": "2026-01-25T23:35:41.281251+00:00", "data": {"market": "0x268f4042d495b0a3ea61e794c664f1d3796f3a0fc5dab7bf1ad5bfdbf7850d7c", "price_changes": [{"asset_id": "63670917573484538535387075608707689209446344899693197294786093921650274225968", "price": "0.68", "size": "0", "side": "BUY", "hash": "a0c269bfe7462d9bc268890590b0bc953ff39efb", "best_bid": "0.87", "best_ask": "0.99"}, {"asset_id": "8063468361343945193901601443622223592937597768285686368444925226215635999992", "price": "0.32", "size": "0", "side": "SELL", "hash": "34533a83ffd8e69696f29278b3b677996a33dc70", "best_bid": "0.01", "best_ask": "0.13"}], "timestamp": "1769384141214", "event_type": "price_change"}}
{"_local_timestamp": "2026-01-25T23:35:41.311187+00:00", "data": {"market": "0x268f4042d495b0a3ea61e794c664f1d3796f3a0fc5dab7bf1ad5bfdbf7850d7c", "price_changes": [{"asset_id": "63670917573484538535387075608707689209446344899693197294786093921650274225968", "price": "0.77", "size": "20", "side": "BUY", "hash": "c1a4d8c31d762829c5e04a78dfe1d8c21b660f3b", "best_bid": "0.87", "best_ask": "0.99"}, {"asset_id": "8063468361343945193901601443622223592937597768285686368444925226215635999992", "price": "0.23", "size": "20", "side": "SELL", "hash": "7a397d1fb1c56b017aa4fff80095bb65c9f55cc0", "best_bid": "0.01", "best_ask": "0.13"}], "timestamp": "1769384141243", "event_type": "price_change"}}
{"_local_timestamp": "2026-01-25T23:35:41.383389+00:00", "data": {"market": "0x268f4042d495b0a3ea61e794c664f1d3796f3a0fc5dab7bf1ad5bfdbf7850d7c", "price_changes": [{"asset_id": "63670917573484538535387075608707689209446344899693197294786093921650274225968", "price": "0.76", "size": "0", "side": "BUY", "hash": "b23135df4d24d9506ee9d95e2f4e55d426cf5ef5", "best_bid": "0.87", "best_ask": "0.99"}, {"asset_id": "8063468361343945193901601443622223592937597768285686368444925226215635999992", "price": "0.24", "size": "0", "side": "SELL", "hash": "cac0ddef3623dfa071be5ba0b9f10f4e5fbf8e6a", "best_bid": "0.01", "best_ask": "0.13"}], "timestamp": "1769384141318", "event_type": "price_change"}}
{"_local_timestamp": "2026-01-25T23:35:45.755136+00:00", "data": {"market": "0x268f4042d495b0a3ea61e794c664f1d3796f3a0fc5dab7bf1ad5bfdbf7850d7c", "price_changes": [{"asset_id": "63670917573484538535387075608707689209446344899693197294786093921650274225968", "price": "0.77", "size": "0", "side": "BUY", "hash": "4aebb257b4fefc8434e9b1aaf665afbf46a8074b", "best_bid": "0.87", "best_ask": "0.99"}, {"asset_id": "8063468361343945193901601443622223592937597768285686368444925226215635999992", "price": "0.23", "size": "0", "side": "SELL", "hash": "f6e675bdf03f0322bdb43e2bfa7c559f1808fdd4", "best_bid": "0.01", "best_ask": "0.13"}], "timestamp": "1769384145692", "event_type": "price_change"}}
{"_local_timestamp": "2026-01-25T23:35:45.789279+00:00", "data": {"market": "0x268f4042d495b0a3ea61e794c664f1d3796f3a0fc5dab7bf1ad5bfdbf7850d7c", "price_changes": [{"asset_id": "63670917573484538535387075608707689209446344899693197294786093921650274225968", "price": "0.68", "size": "20", "side": "BUY", "hash": "5968c82044e725fb786e2258b477e6c374077b52", "best_bid": "0.87", "best_ask": "0.99"}, {"asset_id": "8063468361343945193901601443622223592937597768285686368444925226215635999992", "price": "0.32", "size": "20", "side": "SELL", "hash": "627fbffe0f1b219b6d22be1e27a30ba98d1b1610", "best_bid": "0.01", "best_ask": "0.13"}], "timestamp": "1769384145723", "event_type": "price_change"}}
{"_local_timestamp": "2026-01-25T23:35:45.895129+00:00", "data": {"market": "0x268f4042d495b0a3ea61e794c664f1d3796f3a0fc5dab7bf1ad5bfdbf7850d7c", "price_changes": [{"asset_id": "63670917573484538535387075608707689209446344899693197294786093921650274225968", "price": "0.76", "size": "25", "side": "BUY", "hash": "e9f634735847ffd91870181b424e77b941687d85", "best_bid": "0.87", "best_ask": "0.99"}, {"asset_id": "8063468361343945193901601443622223592937597768285686368444925226215635999992", "price": "0.24", "size": "25", "side": "SELL", "hash": "124aa7ccc60379c5a046bf201316edc1a2c67da3", "best_bid": "0.01", "best_ask": "0.13"}], "timestamp": "1769384145833", "event_type": "price_change"}}
{"_local_timestamp": "2026-01-25T23:35:45.949193+00:00", "data": {"market": "0x822409787697144b96f53af76e6419655f5704d5a1382c0604aa01fb331e2ca5", "price_changes": [{"asset_id": "48505873629919993069307707366966856150423552939624109422369276111454667757058", "price": "0.02", "size": "1007.16", "side": "BUY", "hash": "3e98437d5fa3af845131e4cc35be1b40769acb31", "best_bid": "0.43", "best_ask": "0.48"}, {"asset_id": "20814542776422534757806032422681843083114551625252466804013971546488759714912", "price": "0.98", "size": "1007.16", "side": "SELL", "hash": "e98058fae96a03a0a393ce1fe8e41c898241b8ff", "best_bid": "0.52", "best_ask": "0.57"}], "timestamp": "1769384145880", "event_type": "price_change"}}
{"_local_timestamp": "2026-01-25T23:35:47.583890+00:00", "data": {"market": "0x268f4042d495b0a3ea61e794c664f1d3796f3a0fc5dab7bf1ad5bfdbf7850d7c", "price_changes": [{"asset_id": "63670917573484538535387075608707689209446344899693197294786093921650274225968", "price": "0.68", "size": "0", "side": "BUY", "hash": "df5c1fe78ce74e59b8d2d730b39e8c597240ed02", "best_bid": "0.87", "best_ask": "0.99"}, {"asset_id": "8063468361343945193901601443622223592937597768285686368444925226215635999992", "price": "0.32", "size": "0", "side": "SELL", "hash": "5c7c0c857efd31994a5b38e2f25bcc8dbd064053", "best_bid": "0.01", "best_ask": "0.13"}], "timestamp": "1769384147513", "event_type": "price_change"}}
{"_local_timestamp": "2026-01-25T23:35:47.606918+00:00", "data": {"market": "0x268f4042d495b0a3ea61e794c664f1d3796f3a0fc5dab7bf1ad5bfdbf7850d7c", "price_changes": [{"asset_id": "63670917573484538535387075608707689209446344899693197294786093921650274225968", "price": "0.77", "size": "20", "side": "BUY", "hash": "3a3ae7b023cfde249692b43f94b811794571188c", "best_bid": "0.87", "best_ask": "0.99"}, {"asset_id": "8063468361343945193901601443622223592937597768285686368444925226215635999992", "price": "0.23", "size": "20", "side": "SELL", "hash": "703d2b5af2ee9a6e09e1ced7fda2a399a9fc4e44", "best_bid": "0.01", "best_ask": "0.13"}], "timestamp": "1769384147542", "event_type": "price_change"}}
{"_local_timestamp": "2026-01-25T23:35:47.695746+00:00", "data": {"market": "0x268f4042d495b0a3ea61e794c664f1d3796f3a0fc5dab7bf1ad5bfdbf7850d7c", "price_changes": [{"asset_id": "63670917573484538535387075608707689209446344899693197294786093921650274225968", "price": "0.76", "size": "0", "side": "BUY", "hash": "38ca6aa3f7a1cdf0146adf046dad95f63c2672d7", "best_bid": "0.87", "best_ask": "0.99"}, {"asset_id": "8063468361343945193901601443622223592937597768285686368444925226215635999992", "price": "0.24", "size": "0", "side": "SELL", "hash": "b664a3fd8ef14cdb977736d026d40d8008a10035", "best_bid": "0.01", "best_ask": "0.13"}], "timestamp": "1769384147622", "event_type": "price_change"}}
{"_local_timestamp": "2026-01-25T23:35:51.983828+00:00", "data": {"market": "0x268f4042d495b0a3ea61e794c664f1d3796f3a0fc5dab7bf1ad5bfdbf7850d7c", "price_changes": [{"asset_id": "63670917573484538535387075608707689209446344899693197294786093921650274225968", "price": "0.77", "size": "0", "side": "BUY", "hash": "8c9eb13cc9f30db56212fb9fed87a79ec5f5aad1", "best_bid": "0.87", "best_ask": "0.99"}, {"asset_id": "8063468361343945193901601443622223592937597768285686368444925226215635999992", "price": "0.23", "size": "0", "side": "SELL", "hash": "76b0f5b25f37a0b77946adad312fa325ad97647e", "best_bid": "0.01", "best_ask": "0.13"}], "timestamp": "1769384151916", "event_type": "price_change"}}
{"_local_timestamp": "2026-01-25T23:35:52.008099+00:00", "data": {"market": "0x268f4042d495b0a3ea61e794c664f1d3796f3a0fc5dab7bf1ad5bfdbf7850d7c", "price_changes": [{"asset_id": "63670917573484538535387075608707689209446344899693197294786093921650274225968", "price": "0.68", "size": "20", "side": "BUY", "hash": "5f8b6735ef89758026d1ba8b604d1ec648a0c257", "best_bid": "0.87", "best_ask": "0.99"}, {"asset_id": "8063468361343945193901601443622223592937597768285686368444925226215635999992", "price": "0.32", "size": "20", "side": "SELL", "hash": "56e6e90f4fa1d95287d5cdae7b2a7d0a66ed7d76", "best_bid": "0.01", "best_ask": "0.13"}], "timestamp": "1769384151943", "event_type": "price_change"}}
{"_local_timestamp": "2026-01-25T23:35:52.135198+00:00", "data": {"market": "0x268f4042d495b0a3ea61e794c664f1d3796f3a0fc5dab7bf1ad5bfdbf7850d7c", "price_changes": [{"asset_id": "63670917573484538535387075608707689209446344899693197294786093921650274225968", "price": "0.76", "size": "25", "side": "BUY", "hash": "deb167c93514198811b254935b487387d6853ad0", "best_bid": "0.87", "best_ask": "0.99"}, {"asset_id": "8063468361343945193901601443622223592937597768285686368444925226215635999992", "price": "0.24", "size": "25", "side": "SELL", "hash": "03bef37998a77ae2c12f1f1c40f2370c920669f9", "best_bid": "0.01", "best_ask": "0.13"}], "timestamp": "1769384152051", "event_type": "price_change"}}
{"_local_timestamp": "2026-01-25T23:35:55.047529+00:00", "data": {"market": "0x268f4042d495b0a3ea61e794c664f1d3796f3a0fc5dab7bf1ad5bfdbf7850d7c", "price_changes": [{"asset_id": "63670917573484538535387075608707689209446344899693197294786093921650274225968", "price": "0.68", "size": "0", "side": "BUY", "hash": "717522f77a24e137e6fa5a9b668248833173f26d", "best_bid": "0.87", "best_ask": "0.99"}, {"asset_id": "8063468361343945193901601443622223592937597768285686368444925226215635999992", "price": "0.32", "size": "0", "side": "SELL", "hash": "6b02cb21d08de696eb8be8a47576f9edc85dfe9f", "best_bid": "0.01", "best_ask": "0.13"}], "timestamp": "1769384154965", "event_type": "price_change"}}
{"_local_timestamp": "2026-01-25T23:35:55.070514+00:00", "data": {"market": "0x268f4042d495b0a3ea61e794c664f1d3796f3a0fc5dab7bf1ad5bfdbf7850d7c", "price_changes": [{"asset_id": "63670917573484538535387075608707689209446344899693197294786093921650274225968", "price": "0.77", "size": "20", "side": "BUY", "hash": "aa2b11ed42bf5416905da9039916863566e4d3b7", "best_bid": "0.87", "best_ask": "0.99"}, {"asset_id": "8063468361343945193901601443622223592937597768285686368444925226215635999992", "price": "0.23", "size": "20", "side": "SELL", "hash": "6c9f5069191b19df1931e652d9d3e5916c6a4344", "best_bid": "0.01", "best_ask": "0.13"}], "timestamp": "1769384154998", "event_type": "price_change"}}
{"_local_timestamp": "2026-01-25T23:35:55.184001+00:00", "data": {"market": "0x268f4042d495b0a3ea61e794c664f1d3796f3a0fc5dab7bf1ad5bfdbf7850d7c", "price_changes": [{"asset_id": "63670917573484538535387075608707689209446344899693197294786093921650274225968", "price": "0.76", "size": "0", "side": "BUY", "hash": "c6bc0282360ff238166607f015547c7a2cf4cd7b", "best_bid": "0.87", "best_ask": "0.99"}, {"asset_id": "8063468361343945193901601443622223592937597768285686368444925226215635999992", "price": "0.24", "size": "0", "side": "SELL", "hash": "bc0bb0101cd1fe5f5d1aa369409ff8e9d47ab98c", "best_bid": "0.01", "best_ask": "0.13"}], "timestamp": "1769384155095", "event_type": "price_change"}}
{"_local_timestamp": "2026-01-25T23:35:55.508360+00:00", "data": {"market": "0x822409787697144b96f53af76e6419655f5704d5a1382c0604aa01fb331e2ca5", "price_changes": [{"asset_id": "48505873629919993069307707366966856150423552939624109422369276111454667757058", "price": "0.32", "size": "125", "side": "BUY", "hash": "22523388b4bae26e97716c728f51a54028b31c95", "best_bid": "0.43", "best_ask": "0.48"}, {"asset_id": "20814542776422534757806032422681843083114551625252466804013971546488759714912", "price": "0.68", "size": "125", "side": "SELL", "hash": "c44f3e3d3a1504707e5ad602dab8b5e8df4418a3", "best_bid": "0.52", "best_ask": "0.57"}], "timestamp": "1769384155435", "event_type": "price_change"}}
{"_local_timestamp": "2026-01-25T23:35:57.882053+00:00", "data": {"market": "0x268f4042d495b0a3ea61e794c664f1d3796f3a0fc5dab7bf1ad5bfdbf7850d7c", "price_changes": [{"asset_id": "63670917573484538535387075608707689209446344899693197294786093921650274225968", "price": "0.77", "size": "0", "side": "BUY", "hash": "1729136b07f1c2f13938ce1f2ba2fd9601dd63c8", "best_bid": "0.87", "best_ask": "0.99"}, {"asset_id": "8063468361343945193901601443622223592937597768285686368444925226215635999992", "price": "0.23", "size": "0", "side": "SELL", "hash": "efeda964beaad1d7943e2f603741766fec4020cc", "best_bid": "0.01", "best_ask": "0.13"}], "timestamp": "1769384157785", "event_type": "price_change"}}
{"_local_timestamp": "2026-01-25T23:35:57.912692+00:00", "data": {"market": "0x268f4042d495b0a3ea61e794c664f1d3796f3a0fc5dab7bf1ad5bfdbf7850d7c", "price_changes": [{"asset_id": "63670917573484538535387075608707689209446344899693197294786093921650274225968", "price": "0.68", "size": "20", "side": "BUY", "hash": "23452b008438d3aceb47c9647d2de80a6b4764a2", "best_bid": "0.87", "best_ask": "0.99"}, {"asset_id": "8063468361343945193901601443622223592937597768285686368444925226215635999992", "price": "0.32", "size": "20", "side": "SELL", "hash": "97dd7171c4f7e474a3cbe0646a2a772b16fb215b", "best_bid": "0.01", "best_ask": "0.13"}], "timestamp": "1769384157812", "event_type": "price_change"}}
{"_local_timestamp": "2026-01-25T23:35:58.035339+00:00", "data": {"market": "0x268f4042d495b0a3ea61e794c664f1d3796f3a0fc5dab7bf1ad5bfdbf7850d7c", "price_changes": [{"asset_id": "63670917573484538535387075608707689209446344899693197294786093921650274225968", "price": "0.76", "size": "25", "side": "BUY", "hash": "ec85b7720cde700f6cc49235312d40883a5f1b57", "best_bid": "0.87", "best_ask": "0.99"}, {"asset_id": "8063468361343945193901601443622223592937597768285686368444925226215635999992", "price": "0.24", "size": "25", "side": "SELL", "hash": "f46366d6317f7d1584c72b331fcae5693c6c41dd", "best_bid": "0.01", "best_ask": "0.13"}], "timestamp": "1769384157967", "event_type": "price_change"}}
{"_local_timestamp": "2026-01-25T23:36:02.156327+00:00", "data": {"market": "0x268f4042d495b0a3ea61e794c664f1d3796f3a0fc5dab7bf1ad5bfdbf7850d7c", "price_changes": [{"asset_id": "63670917573484538535387075608707689209446344899693197294786093921650274225968", "price": "0.68", "size": "0", "side": "BUY", "hash": "6999b86cc971b9ff71b5b94eef5e4051b5d0bae4", "best_bid": "0.87", "best_ask": "0.99"}, {"asset_id": "8063468361343945193901601443622223592937597768285686368444925226215635999992", "price": "0.32", "size": "0", "side": "SELL", "hash": "4149ddbdb1da11ac23ec747b161616dd39cac7da", "best_bid": "0.01", "best_ask": "0.13"}], "timestamp": "1769384162082", "event_type": "price_change"}}
{"_local_timestamp": "2026-01-25T23:36:02.193909+00:00", "data": {"market": "0x268f4042d495b0a3ea61e794c664f1d3796f3a0fc5dab7bf1ad5bfdbf7850d7c", "price_changes": [{"asset_id": "63670917573484538535387075608707689209446344899693197294786093921650274225968", "price": "0.77", "size": "20", "side": "BUY", "hash": "29ec54fa11a960e12fd94faa4d40d9b62c4d0e92", "best_bid": "0.87", "best_ask": "0.99"}, {"asset_id": "8063468361343945193901601443622223592937597768285686368444925226215635999992", "price": "0.23", "size": "20", "side": "SELL", "hash": "f5aebc942ebd491f4afafa80a253ea4f853afefb", "best_bid": "0.01", "best_ask": "0.13"}], "timestamp": "1769384162116", "event_type": "price_change"}}
{"_local_timestamp": "2026-01-25T23:36:02.337116+00:00", "data": {"market": "0x268f4042d495b0a3ea61e794c664f1d3796f3a0fc5dab7bf1ad5bfdbf7850d7c", "price_changes": [{"asset_id": "63670917573484538535387075608707689209446344899693197294786093921650274225968", "price": "0.76", "size": "0", "side": "BUY", "hash": "80dda5dfe47ac062eedf1f77d330e701e17720da", "best_bid": "0.87", "best_ask": "0.99"}, {"asset_id": "8063468361343945193901601443622223592937597768285686368444925226215635999992", "price": "0.24", "size": "0", "side": "SELL", "hash": "68b2a2ab6d54eadf27cceaf46b6bc6e6748bc46e", "best_bid": "0.01", "best_ask": "0.13"}], "timestamp": "1769384162258", "event_type": "price_change"}}
{"_local_timestamp": "2026-01-25T23:36:04.942263+00:00", "data": {"market": "0x268f4042d495b0a3ea61e794c664f1d3796f3a0fc5dab7bf1ad5bfdbf7850d7c", "price_changes": [{"asset_id": "63670917573484538535387075608707689209446344899693197294786093921650274225968", "price": "0.77", "size": "0", "side": "BUY", "hash": "77fd43642b01fec83a13aad67cd6a5a1de48571e", "best_bid": "0.87", "best_ask": "0.99"}, {"asset_id": "8063468361343945193901601443622223592937597768285686368444925226215635999992", "price": "0.23", "size": "0", "side": "SELL", "hash": "ff1988eab62626a75c05664aa2956d01cd43db4e", "best_bid": "0.01", "best_ask": "0.13"}], "timestamp": "1769384164873", "event_type": "price_change"}}
{"_local_timestamp": "2026-01-25T23:36:04.968695+00:00", "data": {"market": "0x268f4042d495b0a3ea61e794c664f1d3796f3a0fc5dab7bf1ad5bfdbf7850d7c", "price_changes": [{"asset_id": "63670917573484538535387075608707689209446344899693197294786093921650274225968", "price": "0.68", "size": "20", "side": "BUY", "hash": "ddf4e03b3dda81414cf0068e39df67d91641b979", "best_bid": "0.87", "best_ask": "0.99"}, {"asset_id": "8063468361343945193901601443622223592937597768285686368444925226215635999992", "price": "0.32", "size": "20", "side": "SELL", "hash": "a5744932b478e31aee88d61160cfc22448185806", "best_bid": "0.01", "best_ask": "0.13"}], "timestamp": "1769384164905", "event_type": "price_change"}}
{"_local_timestamp": "2026-01-25T23:36:05.092995+00:00", "data": {"market": "0x268f4042d495b0a3ea61e794c664f1d3796f3a0fc5dab7bf1ad5bfdbf7850d7c", "price_changes": [{"asset_id": "63670917573484538535387075608707689209446344899693197294786093921650274225968", "price": "0.76", "size": "25", "side": "BUY", "hash": "5bfac3c786f4749cb3a815ec1734dcbc0e9b87d9", "best_bid": "0.87", "best_ask": "0.99"}, {"asset_id": "8063468361343945193901601443622223592937597768285686368444925226215635999992", "price": "0.24", "size": "25", "side": "SELL", "hash": "47fe147e70f82d78db2ca15bb16bce2cd9c875ab", "best_bid": "0.01", "best_ask": "0.13"}], "timestamp": "1769384165023", "event_type": "price_change"}}
{"_local_timestamp": "2026-01-25T23:36:08.444959+00:00", "data": {"market": "0x268f4042d495b0a3ea61e794c664f1d3796f3a0fc5dab7bf1ad5bfdbf7850d7c", "price_changes": [{"asset_id": "63670917573484538535387075608707689209446344899693197294786093921650274225968", "price": "0.68", "size": "0", "side": "BUY", "hash": "ed8e8fb2d6a597117e0dfea45802be1813df129c", "best_bid": "0.87", "best_ask": "0.99"}, {"asset_id": "8063468361343945193901601443622223592937597768285686368444925226215635999992", "price": "0.32", "size": "0", "side": "SELL", "hash": "61dad1693cbd9bd0f4a7ff2cb660c82630d14565", "best_bid": "0.01", "best_ask": "0.13"}], "timestamp": "1769384168377", "event_type": "price_change"}}
{"_local_timestamp": "2026-01-25T23:36:08.469078+00:00", "data": {"market": "0x268f4042d495b0a3ea61e794c664f1d3796f3a0fc5dab7bf1ad5bfdbf7850d7c", "price_changes": [{"asset_id": "63670917573484538535387075608707689209446344899693197294786093921650274225968", "price": "0.77", "size": "20", "side": "BUY", "hash": "e6f26a3c82a490355828904546941cfb6e0bad7a", "best_bid": "0.87", "best_ask": "0.99"}, {"asset_id": "8063468361343945193901601443622223592937597768285686368444925226215635999992", "price": "0.23", "size": "20", "side": "SELL", "hash": "83ce3710e6252ee7bb2c91ee1b67e5bfaf6cb2dd", "best_bid": "0.01", "best_ask": "0.13"}], "timestamp": "1769384168404", "event_type": "price_change"}}
{"_local_timestamp": "2026-01-25T23:36:08.549720+00:00", "data": {"market": "0x268f4042d495b0a3ea61e794c664f1d3796f3a0fc5dab7bf1ad5bfdbf7850d7c", "price_changes": [{"asset_id": "63670917573484538535387075608707689209446344899693197294786093921650274225968", "price": "0.76", "size": "0", "side": "BUY", "hash": "d41abc3bc1d21d27a5110bfae8789dee1109edb7", "best_bid": "0.87", "best_ask": "0.99"}, {"asset_id": "8063468361343945193901601443622223592937597768285686368444925226215635999992", "price": "0.24", "size": "0", "side": "SELL", "hash": "301e3cbf8a411adf639922f681437c2b73fa5fe1", "best_bid": "0.01", "best_ask": "0.13"}], "timestamp": "1769384168487", "event_type": "price_change"}}
{"_local_timestamp": "2026-01-25T23:36:11.047697+00:00", "data": {"market": "0x268f4042d495b0a3ea61e794c664f1d3796f3a0fc5dab7bf1ad5bfdbf7850d7c", "price_changes": [{"asset_id": "63670917573484538535387075608707689209446344899693197294786093921650274225968", "price": "0.77", "size": "0", "side": "BUY", "hash": "865db57dab43a3ce09491909e45d73c398cb773d", "best_bid": "0.87", "best_ask": "0.99"}, {"asset_id": "8063468361343945193901601443622223592937597768285686368444925226215635999992", "price": "0.23", "size": "0", "side": "SELL", "hash": "6c6ff92465573c3714b1431ec2de80b7d5c1378b", "best_bid": "0.01", "best_ask": "0.13"}], "timestamp": "1769384170982", "event_type": "price_change"}}
{"_local_timestamp": "2026-01-25T23:36:11.114629+00:00", "data": {"market": "0x268f4042d495b0a3ea61e794c664f1d3796f3a0fc5dab7bf1ad5bfdbf7850d7c", "price_changes": [{"asset_id": "63670917573484538535387075608707689209446344899693197294786093921650274225968", "price": "0.68", "size": "20", "side": "BUY", "hash": "a04d2d800bfa0dc56127af05fb6864b0f87a2293", "best_bid": "0.87", "best_ask": "0.99"}, {"asset_id": "8063468361343945193901601443622223592937597768285686368444925226215635999992", "price": "0.32", "size": "20", "side": "SELL", "hash": "deabab494da9d3742a11cac0519206674cbad614", "best_bid": "0.01", "best_ask": "0.13"}], "timestamp": "1769384171011", "event_type": "price_change"}}
{"_local_timestamp": "2026-01-25T23:36:11.258750+00:00", "data": {"market": "0x268f4042d495b0a3ea61e794c664f1d3796f3a0fc5dab7bf1ad5bfdbf7850d7c", "price_changes": [{"asset_id": "63670917573484538535387075608707689209446344899693197294786093921650274225968", "price": "0.76", "size": "25", "side": "BUY", "hash": "cf548b717a147e15b1244f68928e91bf757707f4", "best_bid": "0.87", "best_ask": "0.99"}, {"asset_id": "8063468361343945193901601443622223592937597768285686368444925226215635999992", "price": "0.24", "size": "25", "side": "SELL", "hash": "2251ba8354a940a70ecdbbc46229282f6493bfc3", "best_bid": "0.01", "best_ask": "0.13"}], "timestamp": "1769384171194", "event_type": "price_change"}}
{"_local_timestamp": "2026-01-25T23:36:11.342571+00:00", "data": {"market": "0x822409787697144b96f53af76e6419655f5704d5a1382c0604aa01fb331e2ca5", "price_changes": [{"asset_id": "20814542776422534757806032422681843083114551625252466804013971546488759714912", "price": "0.19", "size": "126.31", "side": "BUY", "hash": "f89fcceeaddf82a54fe5e4a0c7d8befdf3ee6fab", "best_bid": "0.52", "best_ask": "0.57"}, {"asset_id": "48505873629919993069307707366966856150423552939624109422369276111454667757058", "price": "0.81", "size": "126.31", "side": "SELL", "hash": "a1c31ae84b304b649feeb33c53a13b26c47eb99b", "best_bid": "0.43", "best_ask": "0.48"}], "timestamp": "1769384171272", "event_type": "price_change"}}
{"_local_timestamp": "2026-01-25T23:36:11.638844+00:00", "data": {"market": "0x822409787697144b96f53af76e6419655f5704d5a1382c0604aa01fb331e2ca5", "price_changes": [{"asset_id": "20814542776422534757806032422681843083114551625252466804013971546488759714912", "price": "0.17", "size": "455.33", "side": "BUY", "hash": "dbfce248f389f32f55e82d7d258e2558c2976ce9", "best_bid": "0.52", "best_ask": "0.57"}, {"asset_id": "48505873629919993069307707366966856150423552939624109422369276111454667757058", "price": "0.83", "size": "455.33", "side": "SELL", "hash": "fd4ad32be46b77d2afdc9deaf22240e9e78659eb", "best_bid": "0.43", "best_ask": "0.48"}], "timestamp": "1769384171566", "event_type": "price_change"}}
{"_local_timestamp": "2026-01-25T23:36:11.917399+00:00", "data": {"market": "0x268f4042d495b0a3ea61e794c664f1d3796f3a0fc5dab7bf1ad5bfdbf7850d7c", "price_changes": [{"asset_id": "63670917573484538535387075608707689209446344899693197294786093921650274225968", "price": "0.68", "size": "0", "side": "BUY", "hash": "bcbd30551366136f7ae2625d78deff9e80a5a5ba", "best_bid": "0.87", "best_ask": "0.99"}, {"asset_id": "8063468361343945193901601443622223592937597768285686368444925226215635999992", "price": "0.32", "size": "0", "side": "SELL", "hash": "ec9edb04bc5089164fb7878d2e9281129a849237", "best_bid": "0.01", "best_ask": "0.13"}], "timestamp": "1769384171854", "event_type": "price_change"}}
{"_local_timestamp": "2026-01-25T23:36:11.958583+00:00", "data": {"market": "0x268f4042d495b0a3ea61e794c664f1d3796f3a0fc5dab7bf1ad5bfdbf7850d7c", "price_changes": [{"asset_id": "63670917573484538535387075608707689209446344899693197294786093921650274225968", "price": "0.77", "size": "20", "side": "BUY", "hash": "42b05f53393cbc001807461757dd9bc08246b33e", "best_bid": "0.87", "best_ask": "0.99"}, {"asset_id": "8063468361343945193901601443622223592937597768285686368444925226215635999992", "price": "0.23", "size": "20", "side": "SELL", "hash": "7fe39b3a0d84b4f9c7049e73019de215a6eedac8", "best_bid": "0.01", "best_ask": "0.13"}], "timestamp": "1769384171886", "event_type": "price_change"}}
{"_local_timestamp": "2026-01-25T23:36:12.032943+00:00", "data": {"market": "0x268f4042d495b0a3ea61e794c664f1d3796f3a0fc5dab7bf1ad5bfdbf7850d7c", "price_changes": [{"asset_id": "63670917573484538535387075608707689209446344899693197294786093921650274225968", "price": "0.76", "size": "0", "side": "BUY", "hash": "3a26a3e4498abd7902e079deda6a28de9b562156", "best_bid": "0.87", "best_ask": "0.99"}, {"asset_id": "8063468361343945193901601443622223592937597768285686368444925226215635999992", "price": "0.24", "size": "0", "side": "SELL", "hash": "5dd4435a178547b80487ec3e150c9e88b2bff16e", "best_bid": "0.01", "best_ask": "0.13"}], "timestamp": "1769384171958", "event_type": "price_change"}}
{"_local_timestamp": "2026-01-25T23:36:13.335296+00:00", "data": {"market": "0x268f4042d495b0a3ea61e794c664f1d3796f3a0fc5dab7bf1ad5bfdbf7850d7c", "price_changes": [{"asset_id": "63670917573484538535387075608707689209446344899693197294786093921650274225968", "price": "0.77", "size": "0", "side": "BUY", "hash": "826404ca1aa0d59b3a4dc1c9b453ea030f663993", "best_bid": "0.87", "best_ask": "0.99"}, {"asset_id": "8063468361343945193901601443622223592937597768285686368444925226215635999992", "price": "0.23", "size": "0", "side": "SELL", "hash": "fc6c40282ea95548f5baa8b236cb677b790ef713", "best_bid": "0.01", "best_ask": "0.13"}], "timestamp": "1769384173271", "event_type": "price_change"}}
{"_local_timestamp": "2026-01-25T23:36:13.372735+00:00", "data": {"market": "0x268f4042d495b0a3ea61e794c664f1d3796f3a0fc5dab7bf1ad5bfdbf7850d7c", "price_changes": [{"asset_id": "63670917573484538535387075608707689209446344899693197294786093921650274225968", "price": "0.68", "size": "20", "side": "BUY", "hash": "8f576f562d45b6dade2a780e0362701ff24ef417", "best_bid": "0.87", "best_ask": "0.99"}, {"asset_id": "8063468361343945193901601443622223592937597768285686368444925226215635999992", "price": "0.32", "size": "20", "side": "SELL", "hash": "e9efd7eb108e26bce76712f2e42022d26b5e8d43", "best_bid": "0.01", "best_ask": "0.13"}], "timestamp": "1769384173299", "event_type": "price_change"}}
{"_local_timestamp": "2026-01-25T23:36:13.470991+00:00", "data": {"market": "0x268f4042d495b0a3ea61e794c664f1d3796f3a0fc5dab7bf1ad5bfdbf7850d7c", "price_changes": [{"asset_id": "63670917573484538535387075608707689209446344899693197294786093921650274225968", "price": "0.76", "size": "25", "side": "BUY", "hash": "af37156ebb2e2118fde4c949d378714e0c457041", "best_bid": "0.87", "best_ask": "0.99"}, {"asset_id": "8063468361343945193901601443622223592937597768285686368444925226215635999992", "price": "0.24", "size": "25", "side": "SELL", "hash": "6b293b09dfc396dcc42f2e006a71ff839d98ba32", "best_bid": "0.01", "best_ask": "0.13"}], "timestamp": "1769384173404", "event_type": "price_change"}}
{"_local_timestamp": "2026-01-25T23:36:17.741253+00:00", "data": {"market": "0x268f4042d495b0a3ea61e794c664f1d3796f3a0fc5dab7bf1ad5bfdbf7850d7c", "price_changes": [{"asset_id": "63670917573484538535387075608707689209446344899693197294786093921650274225968", "price": "0.68", "size": "0", "side": "BUY", "hash": "25473877c38393000f2fef7ff9dde326ca0ac422", "best_bid": "0.87", "best_ask": "0.99"}, {"asset_id": "8063468361343945193901601443622223592937597768285686368444925226215635999992", "price": "0.32", "size": "0", "side": "SELL", "hash": "e28c1018922e32aed7d39403e0ef91c60d1e9a0e", "best_bid": "0.01", "best_ask": "0.13"}], "timestamp": "1769384177660", "event_type": "price_change"}}
{"_local_timestamp": "2026-01-25T23:36:17.755769+00:00", "data": {"market": "0x268f4042d495b0a3ea61e794c664f1d3796f3a0fc5dab7bf1ad5bfdbf7850d7c", "price_changes": [{"asset_id": "63670917573484538535387075608707689209446344899693197294786093921650274225968", "price": "0.77", "size": "20", "side": "BUY", "hash": "ef794ae8a22aaafbff98f25c0ad8520e4a899e4b", "best_bid": "0.87", "best_ask": "0.99"}, {"asset_id": "8063468361343945193901601443622223592937597768285686368444925226215635999992", "price": "0.23", "size": "20", "side": "SELL", "hash": "1d98b5181afd91e1d720815f4932f7f8ca3e663d", "best_bid": "0.01", "best_ask": "0.13"}], "timestamp": "1769384177687", "event_type": "price_change"}}
{"_local_timestamp": "2026-01-25T23:36:17.835814+00:00", "data": {"market": "0x268f4042d495b0a3ea61e794c664f1d3796f3a0fc5dab7bf1ad5bfdbf7850d7c", "price_changes": [{"asset_id": "63670917573484538535387075608707689209446344899693197294786093921650274225968", "price": "0.76", "size": "0", "side": "BUY", "hash": "ead80dcafe042d5ece20189bd0471feb63ed00b6", "best_bid": "0.87", "best_ask": "0.99"}, {"asset_id": "8063468361343945193901601443622223592937597768285686368444925226215635999992", "price": "0.24", "size": "0", "side": "SELL", "hash": "18bbcac6f0bd33e9f575fb8d9dc42d46dee52845", "best_bid": "0.01", "best_ask": "0.13"}], "timestamp": "1769384177768", "event_type": "price_change"}}
{"_local_timestamp": "2026-01-25T23:36:20.009729+00:00", "data": {"market": "0x268f4042d495b0a3ea61e794c664f1d3796f3a0fc5dab7bf1ad5bfdbf7850d7c", "price_changes": [{"asset_id": "63670917573484538535387075608707689209446344899693197294786093921650274225968", "price": "0.77", "size": "0", "side": "BUY", "hash": "4f6b2d2b0e97f31a407aa1c7f84f9f4244cb8aa0", "best_bid": "0.87", "best_ask": "0.99"}, {"asset_id": "8063468361343945193901601443622223592937597768285686368444925226215635999992", "price": "0.23", "size": "0", "side": "SELL", "hash": "fa7d4b644054231338f0a6f7aea6cc915a64d2a1", "best_bid": "0.01", "best_ask": "0.13"}], "timestamp": "1769384179947", "event_type": "price_change"}}
{"_local_timestamp": "2026-01-25T23:36:20.042114+00:00", "data": {"market": "0x268f4042d495b0a3ea61e794c664f1d3796f3a0fc5dab7bf1ad5bfdbf7850d7c", "price_changes": [{"asset_id": "63670917573484538535387075608707689209446344899693197294786093921650274225968", "price": "0.68", "size": "20", "side": "BUY", "hash": "0260beae8378de486755ad3975af9d81ac845e44", "best_bid": "0.87", "best_ask": "0.99"}, {"asset_id": "8063468361343945193901601443622223592937597768285686368444925226215635999992", "price": "0.32", "size": "20", "side": "SELL", "hash": "ddd041011a0a5e3b0094a586eadce7e60ea692e9", "best_bid": "0.01", "best_ask": "0.13"}], "timestamp": "1769384179978", "event_type": "price_change"}}
{"_local_timestamp": "2026-01-25T23:36:20.154130+00:00", "data": {"market": "0x268f4042d495b0a3ea61e794c664f1d3796f3a0fc5dab7bf1ad5bfdbf7850d7c", "price_changes": [{"asset_id": "63670917573484538535387075608707689209446344899693197294786093921650274225968", "price": "0.76", "size": "25", "side": "BUY", "hash": "7506d2cfad0a16e3a430a598acd24a11c8c40c79", "best_bid": "0.87", "best_ask": "0.99"}, {"asset_id": "8063468361343945193901601443622223592937597768285686368444925226215635999992", "price": "0.24", "size": "25", "side": "SELL", "hash": "549966133af185b62222408904e30d07d5fa3472", "best_bid": "0.01", "best_ask": "0.13"}], "timestamp": "1769384180086", "event_type": "price_change"}}
{"_local_timestamp": "2026-01-25T23:36:23.324645+00:00", "data": {"market": "0x268f4042d495b0a3ea61e794c664f1d3796f3a0fc5dab7bf1ad5bfdbf7850d7c", "price_changes": [{"asset_id": "63670917573484538535387075608707689209446344899693197294786093921650274225968", "price": "0.68", "size": "0", "side": "BUY", "hash": "c62ebb5497de753642b9364465437e7dbb5620c3", "best_bid": "0.87", "best_ask": "0.99"}, {"asset_id": "8063468361343945193901601443622223592937597768285686368444925226215635999992", "price": "0.32", "size": "0", "side": "SELL", "hash": "7cd250116d81ee485689224eb5b4c66698e24437", "best_bid": "0.01", "best_ask": "0.13"}], "timestamp": "1769384183258", "event_type": "price_change"}}
{"_local_timestamp": "2026-01-25T23:36:23.359201+00:00", "data": {"market": "0x268f4042d495b0a3ea61e794c664f1d3796f3a0fc5dab7bf1ad5bfdbf7850d7c", "price_changes": [{"asset_id": "63670917573484538535387075608707689209446344899693197294786093921650274225968", "price": "0.77", "size": "20", "side": "BUY", "hash": "2b2e2dee464a8c3c92b81660f3ea130ec5a63511", "best_bid": "0.87", "best_ask": "0.99"}, {"asset_id": "8063468361343945193901601443622223592937597768285686368444925226215635999992", "price": "0.23", "size": "20", "side": "SELL", "hash": "74a1b161fcde97f6fbbfda5f1b5c55bde229b8d9", "best_bid": "0.01", "best_ask": "0.13"}], "timestamp": "1769384183288", "event_type": "price_change"}}
{"_local_timestamp": "2026-01-25T23:36:23.469490+00:00", "data": {"market": "0x268f4042d495b0a3ea61e794c664f1d3796f3a0fc5dab7bf1ad5bfdbf7850d7c", "price_changes": [{"asset_id": "63670917573484538535387075608707689209446344899693197294786093921650274225968", "price": "0.76", "size": "0", "side": "BUY", "hash": "aa1f318ef568cca36d699c1d722c0c9fdc2904fe", "best_bid": "0.87", "best_ask": "0.99"}, {"asset_id": "8063468361343945193901601443622223592937597768285686368444925226215635999992", "price": "0.24", "size": "0", "side": "SELL", "hash": "bc542dcc14ae19ffdae525cb9761b30e00987cc8", "best_bid": "0.01", "best_ask": "0.13"}], "timestamp": "1769384183377", "event_type": "price_change"}}
{"_local_timestamp": "2026-01-25T23:36:26.236434+00:00", "data": {"market": "0x268f4042d495b0a3ea61e794c664f1d3796f3a0fc5dab7bf1ad5bfdbf7850d7c", "price_changes": [{"asset_id": "63670917573484538535387075608707689209446344899693197294786093921650274225968", "price": "0.77", "size": "0", "side": "BUY", "hash": "d0bbd0833adfef5fd150d5f67a9715b7f58b2ed1", "best_bid": "0.87", "best_ask": "0.99"}, {"asset_id": "8063468361343945193901601443622223592937597768285686368444925226215635999992", "price": "0.23", "size": "0", "side": "SELL", "hash": "88fa601b3e10520c1d7956d7ce4f44e369b2de22", "best_bid": "0.01", "best_ask": "0.13"}], "timestamp": "1769384186167", "event_type": "price_change"}}
{"_local_timestamp": "2026-01-25T23:36:26.259691+00:00", "data": {"market": "0x268f4042d495b0a3ea61e794c664f1d3796f3a0fc5dab7bf1ad5bfdbf7850d7c", "price_changes": [{"asset_id": "63670917573484538535387075608707689209446344899693197294786093921650274225968", "price": "0.68", "size": "20", "side": "BUY", "hash": "936c63950b86428a6ce4e4a1ce56895ecff6e97c", "best_bid": "0.87", "best_ask": "0.99"}, {"asset_id": "8063468361343945193901601443622223592937597768285686368444925226215635999992", "price": "0.32", "size": "20", "side": "SELL", "hash": "d9768ddadcf05f4da5b15ad782f81a94ab33c4dd", "best_bid": "0.01", "best_ask": "0.13"}], "timestamp": "1769384186196", "event_type": "price_change"}}
{"_local_timestamp": "2026-01-25T23:36:26.522483+00:00", "data": {"market": "0x268f4042d495b0a3ea61e794c664f1d3796f3a0fc5dab7bf1ad5bfdbf7850d7c", "price_changes": [{"asset_id": "63670917573484538535387075608707689209446344899693197294786093921650274225968", "price": "0.76", "size": "25", "side": "BUY", "hash": "386ddbfc5a55543ab3a1794e39645f451829a423", "best_bid": "0.87", "best_ask": "0.99"}, {"asset_id": "8063468361343945193901601443622223592937597768285686368444925226215635999992", "price": "0.24", "size": "25", "side": "SELL", "hash": "f52754778dab309581e8271c03e3788ddfc5b9ae", "best_bid": "0.01", "best_ask": "0.13"}], "timestamp": "1769384186448", "event_type": "price_change"}}
{"_local_timestamp": "2026-01-25T23:36:29.226772+00:00", "data": {"market": "0x268f4042d495b0a3ea61e794c664f1d3796f3a0fc5dab7bf1ad5bfdbf7850d7c", "price_changes": [{"asset_id": "63670917573484538535387075608707689209446344899693197294786093921650274225968", "price": "0.68", "size": "0", "side": "BUY", "hash": "2c0b98bc9ae13d42f103a4c4838cb84b43f672c4", "best_bid": "0.87", "best_ask": "0.99"}, {"asset_id": "8063468361343945193901601443622223592937597768285686368444925226215635999992", "price": "0.32", "size": "0", "side": "SELL", "hash": "b23e0eb658ab5319b92c5ed315bf7fa0b27c71b9", "best_bid": "0.01", "best_ask": "0.13"}], "timestamp": "1769384189156", "event_type": "price_change"}}
{"_local_timestamp": "2026-01-25T23:36:29.260512+00:00", "data": {"market": "0x268f4042d495b0a3ea61e794c664f1d3796f3a0fc5dab7bf1ad5bfdbf7850d7c", "price_changes": [{"asset_id": "63670917573484538535387075608707689209446344899693197294786093921650274225968", "price": "0.77", "size": "20", "side": "BUY", "hash": "5d126534f5528819443fd2e9204dd7b02a8422ad", "best_bid": "0.87", "best_ask": "0.99"}, {"asset_id": "8063468361343945193901601443622223592937597768285686368444925226215635999992", "price": "0.23", "size": "20", "side": "SELL", "hash": "6b5417f38d433a902d694b1d6e2e9f04f2d8ce38", "best_bid": "0.01", "best_ask": "0.13"}], "timestamp": "1769384189186", "event_type": "price_change"}}
{"_local_timestamp": "2026-01-25T23:36:29.324000+00:00", "data": {"market": "0x268f4042d495b0a3ea61e794c664f1d3796f3a0fc5dab7bf1ad5bfdbf7850d7c", "price_changes": [{"asset_id": "63670917573484538535387075608707689209446344899693197294786093921650274225968", "price": "0.76", "size": "0", "side": "BUY", "hash": "dc684e9ba3349e47b45fbd57992b4f98ba4f8131", "best_bid": "0.87", "best_ask": "0.99"}, {"asset_id": "8063468361343945193901601443622223592937597768285686368444925226215635999992", "price": "0.24", "size": "0", "side": "SELL", "hash": "f26eefcb07ad77564b91ce88d8c8d78ae77d9c33", "best_bid": "0.01", "best_ask": "0.13"}], "timestamp": "1769384189261", "event_type": "price_change"}}
{"_local_timestamp": "2026-01-25T23:36:30.983246+00:00", "data": {"market": "0x268f4042d495b0a3ea61e794c664f1d3796f3a0fc5dab7bf1ad5bfdbf7850d7c", "price_changes": [{"asset_id": "63670917573484538535387075608707689209446344899693197294786093921650274225968", "price": "0.77", "size": "0", "side": "BUY", "hash": "7e979d91c42d1c1cd7a675b9d68a25ac49f5d0e6", "best_bid": "0.87", "best_ask": "0.99"}, {"asset_id": "8063468361343945193901601443622223592937597768285686368444925226215635999992", "price": "0.23", "size": "0", "side": "SELL", "hash": "f3fb677576218460d9fa31d07a56e48bac7a9ddb", "best_bid": "0.01", "best_ask": "0.13"}], "timestamp": "1769384190911", "event_type": "price_change"}}
{"_local_timestamp": "2026-01-25T23:36:31.008993+00:00", "data": {"market": "0x268f4042d495b0a3ea61e794c664f1d3796f3a0fc5dab7bf1ad5bfdbf7850d7c", "price_changes": [{"asset_id": "63670917573484538535387075608707689209446344899693197294786093921650274225968", "price": "0.68", "size": "20", "side": "BUY", "hash": "aee7fb528fcecccfcfb2e68b7ba6bba68ae6a51e", "best_bid": "0.87", "best_ask": "0.99"}, {"asset_id": "8063468361343945193901601443622223592937597768285686368444925226215635999992", "price": "0.32", "size": "20", "side": "SELL", "hash": "ac1ad8849c941e651c000bd90a47be572951aea5", "best_bid": "0.01", "best_ask": "0.13"}], "timestamp": "1769384190945", "event_type": "price_change"}}
{"_local_timestamp": "2026-01-25T23:36:31.154218+00:00", "data": {"market": "0x268f4042d495b0a3ea61e794c664f1d3796f3a0fc5dab7bf1ad5bfdbf7850d7c", "price_changes": [{"asset_id": "63670917573484538535387075608707689209446344899693197294786093921650274225968", "price": "0.76", "size": "25", "side": "BUY", "hash": "b4cf6bc9981f8dbfb8cffe2874b6fa378b6d3c13", "best_bid": "0.87", "best_ask": "0.99"}, {"asset_id": "8063468361343945193901601443622223592937597768285686368444925226215635999992", "price": "0.24", "size": "25", "side": "SELL", "hash": "bc5876ef5493c4a50182d3ae056ec40262e4b1ef", "best_bid": "0.01", "best_ask": "0.13"}], "timestamp": "1769384191085", "event_type": "price_change"}}
{"_local_timestamp": "2026-01-25T23:36:34.486887+00:00", "data": {"market": "0x268f4042d495b0a3ea61e794c664f1d3796f3a0fc5dab7bf1ad5bfdbf7850d7c", "price_changes": [{"asset_id": "63670917573484538535387075608707689209446344899693197294786093921650274225968", "price": "0.68", "size": "0", "side": "BUY", "hash": "4b26da0593990d310e4be0653337ed49787dd2a7", "best_bid": "0.87", "best_ask": "0.99"}, {"asset_id": "8063468361343945193901601443622223592937597768285686368444925226215635999992", "price": "0.32", "size": "0", "side": "SELL", "hash": "7954daf4249a83e217ff92aa4f0d59cc42219466", "best_bid": "0.01", "best_ask": "0.13"}], "timestamp": "1769384194421", "event_type": "price_change"}}
{"_local_timestamp": "2026-01-25T23:36:34.524473+00:00", "data": {"market": "0x268f4042d495b0a3ea61e794c664f1d3796f3a0fc5dab7bf1ad5bfdbf7850d7c", "price_changes": [{"asset_id": "63670917573484538535387075608707689209446344899693197294786093921650274225968", "price": "0.77", "size": "20", "side": "BUY", "hash": "2f5579ab774dd3311e71912f68eb1f1fdef4c205", "best_bid": "0.87", "best_ask": "0.99"}, {"asset_id": "8063468361343945193901601443622223592937597768285686368444925226215635999992", "price": "0.23", "size": "20", "side": "SELL", "hash": "b44732f625a6031ba8322e64241572a0dce209c5", "best_bid": "0.01", "best_ask": "0.13"}], "timestamp": "1769384194450", "event_type": "price_change"}}
{"_local_timestamp": "2026-01-25T23:36:34.600911+00:00", "data": {"market": "0x268f4042d495b0a3ea61e794c664f1d3796f3a0fc5dab7bf1ad5bfdbf7850d7c", "price_changes": [{"asset_id": "63670917573484538535387075608707689209446344899693197294786093921650274225968", "price": "0.76", "size": "0", "side": "BUY", "hash": "843f9b0d0e83ed0ac2655378a869bc153c0ba044", "best_bid": "0.87", "best_ask": "0.99"}, {"asset_id": "8063468361343945193901601443622223592937597768285686368444925226215635999992", "price": "0.24", "size": "0", "side": "SELL", "hash": "5a5cb5721697095361ccce0f5399cd282ec649b3", "best_bid": "0.01", "best_ask": "0.13"}], "timestamp": "1769384194531", "event_type": "price_change"}}
{"_local_timestamp": "2026-01-25T23:36:37.226134+00:00", "data": {"market": "0x268f4042d495b0a3ea61e794c664f1d3796f3a0fc5dab7bf1ad5bfdbf7850d7c", "price_changes": [{"asset_id": "63670917573484538535387075608707689209446344899693197294786093921650274225968", "price": "0.77", "size": "0", "side": "BUY", "hash": "633c38e9f356f4049986c82b3cbd90ed29793d5d", "best_bid": "0.87", "best_ask": "0.99"}, {"asset_id": "8063468361343945193901601443622223592937597768285686368444925226215635999992", "price": "0.23", "size": "0", "side": "SELL", "hash": "e332b1bdc27f7bce46b1085229acaf4f2bad17cd", "best_bid": "0.01", "best_ask": "0.13"}], "timestamp": "1769384197159", "event_type": "price_change"}}
{"_local_timestamp": "2026-01-25T23:36:37.259365+00:00", "data": {"market": "0x268f4042d495b0a3ea61e794c664f1d3796f3a0fc5dab7bf1ad5bfdbf7850d7c", "price_changes": [{"asset_id": "63670917573484538535387075608707689209446344899693197294786093921650274225968", "price": "0.68", "size": "20", "side": "BUY", "hash": "1a4e95ffb093cfe8e8c9db7ad0c3e0a732b8fbd8", "best_bid": "0.87", "best_ask": "0.99"}, {"asset_id": "8063468361343945193901601443622223592937597768285686368444925226215635999992", "price": "0.32", "size": "20", "side": "SELL", "hash": "4a783d138e23f1b77404c61ed44ac23068338d51", "best_bid": "0.01", "best_ask": "0.13"}], "timestamp": "1769384197191", "event_type": "price_change"}}
{"_local_timestamp": "2026-01-25T23:36:37.398700+00:00", "data": {"market": "0x268f4042d495b0a3ea61e794c664f1d3796f3a0fc5dab7bf1ad5bfdbf7850d7c", "price_changes": [{"asset_id": "63670917573484538535387075608707689209446344899693197294786093921650274225968", "price": "0.76", "size": "25", "side": "BUY", "hash": "888aec95c569d23e056ff98c8f45dc02dc354a3d", "best_bid": "0.87", "best_ask": "0.99"}, {"asset_id": "8063468361343945193901601443622223592937597768285686368444925226215635999992", "price": "0.24", "size": "25", "side": "SELL", "hash": "70626cdfab9488d6bbb371ea2ab7b8ba0a326f8a", "best_bid": "0.01", "best_ask": "0.13"}], "timestamp": "1769384197298", "event_type": "price_change"}}
{"_local_timestamp": "2026-01-25T23:36:40.893288+00:00", "data": {"market": "0x268f4042d495b0a3ea61e794c664f1d3796f3a0fc5dab7bf1ad5bfdbf7850d7c", "price_changes": [{"asset_id": "63670917573484538535387075608707689209446344899693197294786093921650274225968", "price": "0.68", "size": "0", "side": "BUY", "hash": "f5afe059f3b838920f43c5031c1244c3afae61e8", "best_bid": "0.87", "best_ask": "0.99"}, {"asset_id": "8063468361343945193901601443622223592937597768285686368444925226215635999992", "price": "0.32", "size": "0", "side": "SELL", "hash": "2cbff4ce5dc5868d85044f5f84c0ca25bdd0ec01", "best_bid": "0.01", "best_ask": "0.13"}], "timestamp": "1769384200818", "event_type": "price_change"}}
{"_local_timestamp": "2026-01-25T23:36:40.925181+00:00", "data": {"market": "0x268f4042d495b0a3ea61e794c664f1d3796f3a0fc5dab7bf1ad5bfdbf7850d7c", "price_changes": [{"asset_id": "63670917573484538535387075608707689209446344899693197294786093921650274225968", "price": "0.77", "size": "20", "side": "BUY", "hash": "378f4de210967247138776d465f2c329cad035ae", "best_bid": "0.87", "best_ask": "0.99"}, {"asset_id": "8063468361343945193901601443622223592937597768285686368444925226215635999992", "price": "0.23", "size": "20", "side": "SELL", "hash": "ce77592d9e4c6a39ced4209cb6af688e72cb63c7", "best_bid": "0.01", "best_ask": "0.13"}], "timestamp": "1769384200849", "event_type": "price_change"}}
{"_local_timestamp": "2026-01-25T23:36:41.014080+00:00", "data": {"market": "0x268f4042d495b0a3ea61e794c664f1d3796f3a0fc5dab7bf1ad5bfdbf7850d7c", "price_changes": [{"asset_id": "63670917573484538535387075608707689209446344899693197294786093921650274225968", "price": "0.76", "size": "0", "side": "BUY", "hash": "35a6cbbcc5766aa6c875484b12113595b3b2d37f", "best_bid": "0.87", "best_ask": "0.99"}, {"asset_id": "8063468361343945193901601443622223592937597768285686368444925226215635999992", "price": "0.24", "size": "0", "side": "SELL", "hash": "2103aa959cdafa44573c26161b486514213f733b", "best_bid": "0.01", "best_ask": "0.13"}], "timestamp": "1769384200925", "event_type": "price_change"}}
{"_local_timestamp": "2026-01-25T23:36:44.045943+00:00", "data": {"market": "0x268f4042d495b0a3ea61e794c664f1d3796f3a0fc5dab7bf1ad5bfdbf7850d7c", "price_changes": [{"asset_id": "63670917573484538535387075608707689209446344899693197294786093921650274225968", "price": "0.77", "size": "0", "side": "BUY", "hash": "919d6cd42f28b961d11f4cec8f2fd1cef44b2abf", "best_bid": "0.87", "best_ask": "0.99"}, {"asset_id": "8063468361343945193901601443622223592937597768285686368444925226215635999992", "price": "0.23", "size": "0", "side": "SELL", "hash": "11de96b16fb168e09ae1e4013ce05e49dcc3b2d1", "best_bid": "0.01", "best_ask": "0.13"}], "timestamp": "1769384203881", "event_type": "price_change"}}
{"_local_timestamp": "2026-01-25T23:36:44.070221+00:00", "data": {"market": "0x268f4042d495b0a3ea61e794c664f1d3796f3a0fc5dab7bf1ad5bfdbf7850d7c", "price_changes": [{"asset_id": "63670917573484538535387075608707689209446344899693197294786093921650274225968", "price": "0.68", "size": "20", "side": "BUY", "hash": "97e7dff66e7067aa50c84c9be850b2199a412e3e", "best_bid": "0.87", "best_ask": "0.99"}, {"asset_id": "8063468361343945193901601443622223592937597768285686368444925226215635999992", "price": "0.32", "size": "20", "side": "SELL", "hash": "21a9e39f669ef4d0f0a31fbac4bea78317bde90b", "best_bid": "0.01", "best_ask": "0.13"}], "timestamp": "1769384203906", "event_type": "price_change"}}
{"_local_timestamp": "2026-01-25T23:36:44.183047+00:00", "data": {"market": "0x268f4042d495b0a3ea61e794c664f1d3796f3a0fc5dab7bf1ad5bfdbf7850d7c", "price_changes": [{"asset_id": "63670917573484538535387075608707689209446344899693197294786093921650274225968", "price": "0.76", "size": "25", "side": "BUY", "hash": "1c27c3483e944fe845739d39f63119ae98115883", "best_bid": "0.87", "best_ask": "0.99"}, {"asset_id": "8063468361343945193901601443622223592937597768285686368444925226215635999992", "price": "0.24", "size": "25", "side": "SELL", "hash": "392eb0af72f39511f8d258132287b5c7df82b4d3", "best_bid": "0.01", "best_ask": "0.13"}], "timestamp": "1769384204022", "event_type": "price_change"}}
{"_local_timestamp": "2026-01-25T23:36:47.413027+00:00", "data": {"market": "0x268f4042d495b0a3ea61e794c664f1d3796f3a0fc5dab7bf1ad5bfdbf7850d7c", "price_changes": [{"asset_id": "63670917573484538535387075608707689209446344899693197294786093921650274225968", "price": "0.68", "size": "0", "side": "BUY", "hash": "080d92fad6ab8045f64ac3e43dc2c975c6541144", "best_bid": "0.87", "best_ask": "0.99"}, {"asset_id": "8063468361343945193901601443622223592937597768285686368444925226215635999992", "price": "0.32", "size": "0", "side": "SELL", "hash": "9eb88534bf238e1ca96e555e1bae1d044999b3b7", "best_bid": "0.01", "best_ask": "0.13"}], "timestamp": "1769384207250", "event_type": "price_change"}}
{"_local_timestamp": "2026-01-25T23:36:47.454687+00:00", "data": {"market": "0x268f4042d495b0a3ea61e794c664f1d3796f3a0fc5dab7bf1ad5bfdbf7850d7c", "price_changes": [{"asset_id": "63670917573484538535387075608707689209446344899693197294786093921650274225968", "price": "0.77", "size": "20", "side": "BUY", "hash": "fdaa8cd2beadc69985f04534772afc7012e2b3e0", "best_bid": "0.87", "best_ask": "0.99"}, {"asset_id": "8063468361343945193901601443622223592937597768285686368444925226215635999992", "price": "0.23", "size": "20", "side": "SELL", "hash": "8b688e629e887d220ec04bd0de02e3ff4403c6e7", "best_bid": "0.01", "best_ask": "0.13"}], "timestamp": "1769384207288", "event_type": "price_change"}}
{"_local_timestamp": "2026-01-25T23:36:47.514579+00:00", "data": {"market": "0x268f4042d495b0a3ea61e794c664f1d3796f3a0fc5dab7bf1ad5bfdbf7850d7c", "price_changes": [{"asset_id": "63670917573484538535387075608707689209446344899693197294786093921650274225968", "price": "0.76", "size": "0", "side": "BUY", "hash": "2eba8288472fdff1757d0cb9853a864f97a056d0", "best_bid": "0.87", "best_ask": "0.99"}, {"asset_id": "8063468361343945193901601443622223592937597768285686368444925226215635999992", "price": "0.24", "size": "0", "side": "SELL", "hash": "7a3b9ce17f4004892fc930f722afd28afdcb2440", "best_bid": "0.01", "best_ask": "0.13"}], "timestamp": "1769384207357", "event_type": "price_change"}}
{"_local_timestamp": "2026-01-25T23:36:51.948945+00:00", "data": {"market": "0x268f4042d495b0a3ea61e794c664f1d3796f3a0fc5dab7bf1ad5bfdbf7850d7c", "price_changes": [{"asset_id": "63670917573484538535387075608707689209446344899693197294786093921650274225968", "price": "0.77", "size": "0", "side": "BUY", "hash": "72b184c9dc7eb8a7e2b2ebd190a73ceff0010334", "best_bid": "0.87", "best_ask": "0.99"}, {"asset_id": "8063468361343945193901601443622223592937597768285686368444925226215635999992", "price": "0.23", "size": "0", "side": "SELL", "hash": "e5c3ac27c98518c5009944bede9e26057f8beda7", "best_bid": "0.01", "best_ask": "0.13"}], "timestamp": "1769384211761", "event_type": "price_change"}}
{"_local_timestamp": "2026-01-25T23:36:51.981184+00:00", "data": {"market": "0x268f4042d495b0a3ea61e794c664f1d3796f3a0fc5dab7bf1ad5bfdbf7850d7c", "price_changes": [{"asset_id": "63670917573484538535387075608707689209446344899693197294786093921650274225968", "price": "0.68", "size": "20", "side": "BUY", "hash": "7c223975c571975cba35015efd468c04b71ea48f", "best_bid": "0.87", "best_ask": "0.99"}, {"asset_id": "8063468361343945193901601443622223592937597768285686368444925226215635999992", "price": "0.32", "size": "20", "side": "SELL", "hash": "62084458843cc9b11dc724c5f725f109563d08e3", "best_bid": "0.01", "best_ask": "0.13"}], "timestamp": "1769384211790", "event_type": "price_change"}}
{"_local_timestamp": "2026-01-25T23:36:52.101041+00:00", "data": {"market": "0x268f4042d495b0a3ea61e794c664f1d3796f3a0fc5dab7bf1ad5bfdbf7850d7c", "price_changes": [{"asset_id": "63670917573484538535387075608707689209446344899693197294786093921650274225968", "price": "0.76", "size": "25", "side": "BUY", "hash": "262cf409efdc344271999ee74d8bede5d8c72dd0", "best_bid": "0.87", "best_ask": "0.99"}, {"asset_id": "8063468361343945193901601443622223592937597768285686368444925226215635999992", "price": "0.24", "size": "25", "side": "SELL", "hash": "53c4ffde83e3b95d24c51c92ffb15e62e4cafa08", "best_bid": "0.01", "best_ask": "0.13"}], "timestamp": "1769384211911", "event_type": "price_change"}}
{"_local_timestamp": "2026-01-25T23:36:55.272731+00:00", "data": {"market": "0x822409787697144b96f53af76e6419655f5704d5a1382c0604aa01fb331e2ca5", "price_changes": [{"asset_id": "20814542776422534757806032422681843083114551625252466804013971546488759714912", "price": "0.01", "size": "5517.03", "side": "BUY", "hash": "236ebcfc54517a09d299f01c4c2fc8473f42d44f", "best_bid": "0.52", "best_ask": "0.57"}, {"asset_id": "48505873629919993069307707366966856150423552939624109422369276111454667757058", "price": "0.99", "size": "5517.03", "side": "SELL", "hash": "6ae166411ad9c19853abe0615dc0335f86646d0e", "best_bid": "0.43", "best_ask": "0.48"}], "timestamp": "1769384215017", "event_type": "price_change"}}
{"_local_timestamp": "2026-01-25T23:36:55.557661+00:00", "data": {"market": "0x268f4042d495b0a3ea61e794c664f1d3796f3a0fc5dab7bf1ad5bfdbf7850d7c", "price_changes": [{"asset_id": "63670917573484538535387075608707689209446344899693197294786093921650274225968", "price": "0.68", "size": "0", "side": "BUY", "hash": "71e24f56d7f3932775040c451c8bae01c81177ad", "best_bid": "0.87", "best_ask": "0.99"}, {"asset_id": "8063468361343945193901601443622223592937597768285686368444925226215635999992", "price": "0.32", "size": "0", "side": "SELL", "hash": "38bb9a9801da52afacec84e16e93c4bbd13cc118", "best_bid": "0.01", "best_ask": "0.13"}], "timestamp": "1769384215347", "event_type": "price_change"}}
{"_local_timestamp": "2026-01-25T23:36:55.593930+00:00", "data": {"market": "0x268f4042d495b0a3ea61e794c664f1d3796f3a0fc5dab7bf1ad5bfdbf7850d7c", "price_changes": [{"asset_id": "63670917573484538535387075608707689209446344899693197294786093921650274225968", "price": "0.77", "size": "20", "side": "BUY", "hash": "f3816f5babb2e6d899d3270d34a2069c533445e1", "best_bid": "0.87", "best_ask": "0.99"}, {"asset_id": "8063468361343945193901601443622223592937597768285686368444925226215635999992", "price": "0.23", "size": "20", "side": "SELL", "hash": "d4958515afbdb7df9fd0e5ca1345db1c71e93cb9", "best_bid": "0.01", "best_ask": "0.13"}], "timestamp": "1769384215376", "event_type": "price_change"}}
{"_local_timestamp": "2026-01-25T23:36:55.685371+00:00", "data": {"market": "0x268f4042d495b0a3ea61e794c664f1d3796f3a0fc5dab7bf1ad5bfdbf7850d7c", "price_changes": [{"asset_id": "63670917573484538535387075608707689209446344899693197294786093921650274225968", "price": "0.76", "size": "0", "side": "BUY", "hash": "1363941f9e87d3872978c598476d983845afcc0d", "best_bid": "0.87", "best_ask": "0.99"}, {"asset_id": "8063468361343945193901601443622223592937597768285686368444925226215635999992", "price": "0.24", "size": "0", "side": "SELL", "hash": "e75963d0e784a18dd7d6d006656a1ef04b7d5731", "best_bid": "0.01", "best_ask": "0.13"}], "timestamp": "1769384215470", "event_type": "price_change"}}
{"_local_timestamp": "2026-01-25T23:36:56.206842+00:00", "data": {"market": "0x822409787697144b96f53af76e6419655f5704d5a1382c0604aa01fb331e2ca5", "price_changes": [{"asset_id": "20814542776422534757806032422681843083114551625252466804013971546488759714912", "price": "0.05", "size": "1955.55", "side": "BUY", "hash": "cf5dd41340eab979f78be136210403d6ee915d37", "best_bid": "0.52", "best_ask": "0.57"}, {"asset_id": "48505873629919993069307707366966856150423552939624109422369276111454667757058", "price": "0.95", "size": "1955.55", "side": "SELL", "hash": "876c916d5b2c4b7042b5e40a02a47b66b2fb39d4", "best_bid": "0.43", "best_ask": "0.48"}], "timestamp": "1769384215672", "event_type": "price_change"}}
{"_local_timestamp": "2026-01-25T23:36:57.769708+00:00", "data": {"market": "0x33c3b9a093ed165a022c0cece1dfbc75aacfc7d02b32ec2b60f33b83a83b584e", "price_changes": [{"asset_id": "88558823758350777717721635627914660172648618934795254748210502992209900330496", "price": "0.13", "size": "225", "side": "BUY", "hash": "2b1c1da69c024b25ecca5833f5050bcd165e60dc", "best_bid": "0.46", "best_ask": "0.56"}, {"asset_id": "5231604723025762452457801154824477655145557185223041567948353301271250253045", "price": "0.87", "size": "225", "side": "SELL", "hash": "159f1df77c001330220ba40146bf6831a349c4f7", "best_bid": "0.44", "best_ask": "0.54"}], "timestamp": "1769384217232", "event_type": "price_change"}}
{"_local_timestamp": "2026-01-25T23:36:57.782481+00:00", "data": {"market": "0x822409787697144b96f53af76e6419655f5704d5a1382c0604aa01fb331e2ca5", "price_changes": [{"asset_id": "20814542776422534757806032422681843083114551625252466804013971546488759714912", "price": "0.17", "size": "205.33", "side": "BUY", "hash": "2bf0a9a9460f4c930ed7575c9d8c8763716bdf56", "best_bid": "0.52", "best_ask": "0.57"}, {"asset_id": "48505873629919993069307707366966856150423552939624109422369276111454667757058", "price": "0.83", "size": "205.33", "side": "SELL", "hash": "a480189c0fea0cdd87b5fa1c4142f028cfeaff5f", "best_bid": "0.43", "best_ask": "0.48"}], "timestamp": "1769384217237", "event_type": "price_change"}}
{"_local_timestamp": "2026-01-25T23:36:58.592558+00:00", "data": {"market": "0x268f4042d495b0a3ea61e794c664f1d3796f3a0fc5dab7bf1ad5bfdbf7850d7c", "price_changes": [{"asset_id": "63670917573484538535387075608707689209446344899693197294786093921650274225968", "price": "0.77", "size": "0", "side": "BUY", "hash": "1420912e437300def25b166d5fe98bcca62aa8b3", "best_bid": "0.87", "best_ask": "0.99"}, {"asset_id": "8063468361343945193901601443622223592937597768285686368444925226215635999992", "price": "0.23", "size": "0", "side": "SELL", "hash": "7295628a773b020815ea0527146b4398b259e748", "best_bid": "0.01", "best_ask": "0.13"}], "timestamp": "1769384218327", "event_type": "price_change"}}
{"_local_timestamp": "2026-01-25T23:36:58.601457+00:00", "data": {"market": "0x268f4042d495b0a3ea61e794c664f1d3796f3a0fc5dab7bf1ad5bfdbf7850d7c", "price_changes": [{"asset_id": "63670917573484538535387075608707689209446344899693197294786093921650274225968", "price": "0.68", "size": "20", "side": "BUY", "hash": "96e7a0a6ca4164489d6deb0966c5680fde1b9d7e", "best_bid": "0.87", "best_ask": "0.99"}, {"asset_id": "8063468361343945193901601443622223592937597768285686368444925226215635999992", "price": "0.32", "size": "20", "side": "SELL", "hash": "87fc24fe2afed2fa6e2c8352dbcff983a2cc51c1", "best_bid": "0.01", "best_ask": "0.13"}], "timestamp": "1769384218354", "event_type": "price_change"}}
{"_local_timestamp": "2026-01-25T23:36:58.762471+00:00", "data": {"market": "0x268f4042d495b0a3ea61e794c664f1d3796f3a0fc5dab7bf1ad5bfdbf7850d7c", "price_changes": [{"asset_id": "63670917573484538535387075608707689209446344899693197294786093921650274225968", "price": "0.76", "size": "25", "side": "BUY", "hash": "b58a223889863d3e5946929fb60e95db68f495fb", "best_bid": "0.87", "best_ask": "0.99"}, {"asset_id": "8063468361343945193901601443622223592937597768285686368444925226215635999992", "price": "0.24", "size": "25", "side": "SELL", "hash": "a631be332fbe935bad413789f36e3059bb9ceeef", "best_bid": "0.01", "best_ask": "0.13"}], "timestamp": "1769384218522", "event_type": "price_change"}}
{"_local_timestamp": "2026-01-25T23:37:04.165744+00:00", "data": {"market": "0x822409787697144b96f53af76e6419655f5704d5a1382c0604aa01fb331e2ca5", "price_changes": [{"asset_id": "48505873629919993069307707366966856150423552939624109422369276111454667757058", "price": "0.32", "size": "62.5", "side": "BUY", "hash": "2bd6f39cf48fb47ca437910912347d22219834a1", "best_bid": "0.43", "best_ask": "0.48"}, {"asset_id": "20814542776422534757806032422681843083114551625252466804013971546488759714912", "price": "0.68", "size": "62.5", "side": "SELL", "hash": "12c52153362ddde3fd4e3e77b90643329872ec8f", "best_bid": "0.52", "best_ask": "0.57"}], "timestamp": "1769384223985", "event_type": "price_change"}}
{"_local_timestamp": "2026-01-25T23:37:04.790395+00:00", "data": {"market": "0x268f4042d495b0a3ea61e794c664f1d3796f3a0fc5dab7bf1ad5bfdbf7850d7c", "price_changes": [{"asset_id": "63670917573484538535387075608707689209446344899693197294786093921650274225968", "price": "0.68", "size": "0", "side": "BUY", "hash": "4c7724cd5f52c0eb667c783ff828d170733508a5", "best_bid": "0.87", "best_ask": "0.99"}, {"asset_id": "8063468361343945193901601443622223592937597768285686368444925226215635999992", "price": "0.32", "size": "0", "side": "SELL", "hash": "441c7ed5f643a1a815750de6bf1cc615e2cb4553", "best_bid": "0.01", "best_ask": "0.13"}], "timestamp": "1769384224580", "event_type": "price_change"}}
{"_local_timestamp": "2026-01-25T23:37:04.816085+00:00", "data": {"market": "0x268f4042d495b0a3ea61e794c664f1d3796f3a0fc5dab7bf1ad5bfdbf7850d7c", "price_changes": [{"asset_id": "63670917573484538535387075608707689209446344899693197294786093921650274225968", "price": "0.77", "size": "20", "side": "BUY", "hash": "f8eb0ffd53123ccb8e8ef35f6b24869244edfaa5", "best_bid": "0.87", "best_ask": "0.99"}, {"asset_id": "8063468361343945193901601443622223592937597768285686368444925226215635999992", "price": "0.23", "size": "20", "side": "SELL", "hash": "2c4690954f8f99eb93e06a2ecbbe06be391cf2ed", "best_bid": "0.01", "best_ask": "0.13"}], "timestamp": "1769384224608", "event_type": "price_change"}}
{"_local_timestamp": "2026-01-25T23:37:04.907808+00:00", "data": {"market": "0x268f4042d495b0a3ea61e794c664f1d3796f3a0fc5dab7bf1ad5bfdbf7850d7c", "price_changes": [{"asset_id": "63670917573484538535387075608707689209446344899693197294786093921650274225968", "price": "0.76", "size": "0", "side": "BUY", "hash": "7d988761cb3681da49f49608e50f539880a876a5", "best_bid": "0.87", "best_ask": "0.99"}, {"asset_id": "8063468361343945193901601443622223592937597768285686368444925226215635999992", "price": "0.24", "size": "0", "side": "SELL", "hash": "c433f7aca614af02b881fe54873c731257cac0f1", "best_bid": "0.01", "best_ask": "0.13"}], "timestamp": "1769384224692", "event_type": "price_change"}}
{"_local_timestamp": "2026-01-25T23:37:08.218422+00:00", "data": {"market": "0x268f4042d495b0a3ea61e794c664f1d3796f3a0fc5dab7bf1ad5bfdbf7850d7c", "price_changes": [{"asset_id": "63670917573484538535387075608707689209446344899693197294786093921650274225968", "price": "0.77", "size": "0", "side": "BUY", "hash": "80a8180fd6ade72c7115fb1412e27c63d726dcb7", "best_bid": "0.87", "best_ask": "0.99"}, {"asset_id": "8063468361343945193901601443622223592937597768285686368444925226215635999992", "price": "0.23", "size": "0", "side": "SELL", "hash": "b13f0cbbd65011a065eefebd1f71dc7228f61225", "best_bid": "0.01", "best_ask": "0.13"}], "timestamp": "1769384228024", "event_type": "price_change"}}
{"_local_timestamp": "2026-01-25T23:37:08.233034+00:00", "data": {"market": "0x268f4042d495b0a3ea61e794c664f1d3796f3a0fc5dab7bf1ad5bfdbf7850d7c", "price_changes": [{"asset_id": "63670917573484538535387075608707689209446344899693197294786093921650274225968", "price": "0.68", "size": "20", "side": "BUY", "hash": "5b0faeeda040d9b8eed7892ae48676c811bc4504", "best_bid": "0.87", "best_ask": "0.99"}, {"asset_id": "8063468361343945193901601443622223592937597768285686368444925226215635999992", "price": "0.32", "size": "20", "side": "SELL", "hash": "3b70bedbc633971f12bb8c33839f6a320a45fa43", "best_bid": "0.01", "best_ask": "0.13"}], "timestamp": "1769384228057", "event_type": "price_change"}}
{"_local_timestamp": "2026-01-25T23:37:08.354363+00:00", "data": {"market": "0x268f4042d495b0a3ea61e794c664f1d3796f3a0fc5dab7bf1ad5bfdbf7850d7c", "price_changes": [{"asset_id": "63670917573484538535387075608707689209446344899693197294786093921650274225968", "price": "0.76", "size": "25", "side": "BUY", "hash": "da53890e3327a681baf1d51d905dea3958e0d8b6", "best_bid": "0.87", "best_ask": "0.99"}, {"asset_id": "8063468361343945193901601443622223592937597768285686368444925226215635999992", "price": "0.24", "size": "25", "side": "SELL", "hash": "d54bcf88fbbb92fc6870cbf3ba0d7853a334d191", "best_bid": "0.01", "best_ask": "0.13"}], "timestamp": "1769384228187", "event_type": "price_change"}}
{"_local_timestamp": "2026-01-25T23:37:12.094815+00:00", "data": {"market": "0x268f4042d495b0a3ea61e794c664f1d3796f3a0fc5dab7bf1ad5bfdbf7850d7c", "price_changes": [{"asset_id": "63670917573484538535387075608707689209446344899693197294786093921650274225968", "price": "0.68", "size": "0", "side": "BUY", "hash": "86f92913c1470aacab80c646c0bbb28ee26e8c6f", "best_bid": "0.87", "best_ask": "0.99"}, {"asset_id": "8063468361343945193901601443622223592937597768285686368444925226215635999992", "price": "0.32", "size": "0", "side": "SELL", "hash": "24b973cd0e778101615f2cdd2272724748bbf164", "best_bid": "0.01", "best_ask": "0.13"}], "timestamp": "1769384232015", "event_type": "price_change"}}
{"_local_timestamp": "2026-01-25T23:37:12.111136+00:00", "data": {"market": "0x268f4042d495b0a3ea61e794c664f1d3796f3a0fc5dab7bf1ad5bfdbf7850d7c", "price_changes": [{"asset_id": "63670917573484538535387075608707689209446344899693197294786093921650274225968", "price": "0.77", "size": "20", "side": "BUY", "hash": "d1d9763ecf3e2b02cc357351d0da5a6c3bbc721e", "best_bid": "0.87", "best_ask": "0.99"}, {"asset_id": "8063468361343945193901601443622223592937597768285686368444925226215635999992", "price": "0.23", "size": "20", "side": "SELL", "hash": "4b1dc7c8b7c6d4f019f7fec878816e6b46506e2a", "best_bid": "0.01", "best_ask": "0.13"}], "timestamp": "1769384232042", "event_type": "price_change"}}
{"_local_timestamp": "2026-01-25T23:37:12.192816+00:00", "data": {"market": "0x268f4042d495b0a3ea61e794c664f1d3796f3a0fc5dab7bf1ad5bfdbf7850d7c", "price_changes": [{"asset_id": "63670917573484538535387075608707689209446344899693197294786093921650274225968", "price": "0.76", "size": "0", "side": "BUY", "hash": "e4142e632c67cbd356a27b54972293f5e317b230", "best_bid": "0.87", "best_ask": "0.99"}, {"asset_id": "8063468361343945193901601443622223592937597768285686368444925226215635999992", "price": "0.24", "size": "0", "side": "SELL", "hash": "16dbd00e0ae14bcdc67cd1beb87523e8952dfebb", "best_bid": "0.01", "best_ask": "0.13"}], "timestamp": "1769384232129", "event_type": "price_change"}}
{"_local_timestamp": "2026-01-25T23:37:13.369219+00:00", "data": {"market": "0x33c3b9a093ed165a022c0cece1dfbc75aacfc7d02b32ec2b60f33b83a83b584e", "price_changes": [{"asset_id": "88558823758350777717721635627914660172648618934795254748210502992209900330496", "price": "0.14", "size": "185", "side": "BUY", "hash": "9a059e7156f09a55a16a584359ea6441d40365a5", "best_bid": "0.46", "best_ask": "0.56"}, {"asset_id": "5231604723025762452457801154824477655145557185223041567948353301271250253045", "price": "0.86", "size": "185", "side": "SELL", "hash": "eed2e39ed67f5362e042e87a8ff6a54faf5a9efa", "best_bid": "0.44", "best_ask": "0.54"}], "timestamp": "1769384233288", "event_type": "price_change"}}
{"_local_timestamp": "2026-01-25T23:37:13.369648+00:00", "data": {"market": "0x822409787697144b96f53af76e6419655f5704d5a1382c0604aa01fb331e2ca5", "price_changes": [{"asset_id": "20814542776422534757806032422681843083114551625252466804013971546488759714912", "price": "0.23", "size": "103", "side": "BUY", "hash": "c9a774e25461e6548490709a287553ecc53a2e40", "best_bid": "0.52", "best_ask": "0.57"}, {"asset_id": "48505873629919993069307707366966856150423552939624109422369276111454667757058", "price": "0.77", "size": "103", "side": "SELL", "hash": "228215e30f9de6de0c85203b2440f95041ec1331", "best_bid": "0.43", "best_ask": "0.48"}], "timestamp": "1769384233288", "event_type": "price_change"}}
{"_local_timestamp": "2026-01-25T23:37:13.552348+00:00", "data": {"market": "0x822409787697144b96f53af76e6419655f5704d5a1382c0604aa01fb331e2ca5", "price_changes": [{"asset_id": "20814542776422534757806032422681843083114551625252466804013971546488759714912", "price": "0.11", "size": "640.9", "side": "BUY", "hash": "72f65f4c85c4a9198e6083df0a72994108ab16e6", "best_bid": "0.52", "best_ask": "0.57"}, {"asset_id": "48505873629919993069307707366966856150423552939624109422369276111454667757058", "price": "0.89", "size": "640.9", "side": "SELL", "hash": "f691c7977cf3bdac340eba64a7f4502280ac2e98", "best_bid": "0.43", "best_ask": "0.48"}], "timestamp": "1769384233406", "event_type": "price_change"}}
{"_local_timestamp": "2026-01-25T23:37:13.579583+00:00", "data": {"market": "0x822409787697144b96f53af76e6419655f5704d5a1382c0604aa01fb331e2ca5", "price_changes": [{"asset_id": "20814542776422534757806032422681843083114551625252466804013971546488759714912", "price": "0.17", "size": "305.33", "side": "BUY", "hash": "e5567a1468e1afb9510c607bd2da5d19b60dbb31", "best_bid": "0.52", "best_ask": "0.57"}, {"asset_id": "48505873629919993069307707366966856150423552939624109422369276111454667757058", "price": "0.83", "size": "305.33", "side": "SELL", "hash": "797b63696e77a43b2f2a247f0acb4dd0fa499a30", "best_bid": "0.43", "best_ask": "0.48"}], "timestamp": "1769384233427", "event_type": "price_change"}}
{"_local_timestamp": "2026-01-25T23:37:15.983162+00:00", "data": {"market": "0x268f4042d495b0a3ea61e794c664f1d3796f3a0fc5dab7bf1ad5bfdbf7850d7c", "price_changes": [{"asset_id": "63670917573484538535387075608707689209446344899693197294786093921650274225968", "price": "0.77", "size": "0", "side": "BUY", "hash": "c040010d6be04b58c2ce51730bc3d553cde3b9c0", "best_bid": "0.87", "best_ask": "0.99"}, {"asset_id": "8063468361343945193901601443622223592937597768285686368444925226215635999992", "price": "0.23", "size": "0", "side": "SELL", "hash": "ba731f812b61cc4a70b0e079e047953332f59c8d", "best_bid": "0.01", "best_ask": "0.13"}], "timestamp": "1769384235911", "event_type": "price_change"}}
{"_local_timestamp": "2026-01-25T23:37:16.006568+00:00", "data": {"market": "0x268f4042d495b0a3ea61e794c664f1d3796f3a0fc5dab7bf1ad5bfdbf7850d7c", "price_changes": [{"asset_id": "63670917573484538535387075608707689209446344899693197294786093921650274225968", "price": "0.68", "size": "20", "side": "BUY", "hash": "181a55e88b415fdd5f7cfafbb0794b08f65102fe", "best_bid": "0.87", "best_ask": "0.99"}, {"asset_id": "8063468361343945193901601443622223592937597768285686368444925226215635999992", "price": "0.32", "size": "20", "side": "SELL", "hash": "e923e228a96fe8d2ffa5d8602a3ec85507df28a8", "best_bid": "0.01", "best_ask": "0.13"}], "timestamp": "1769384235940", "event_type": "price_change"}}
{"_local_timestamp": "2026-01-25T23:37:16.152413+00:00", "data": {"market": "0x268f4042d495b0a3ea61e794c664f1d3796f3a0fc5dab7bf1ad5bfdbf7850d7c", "price_changes": [{"asset_id": "63670917573484538535387075608707689209446344899693197294786093921650274225968", "price": "0.76", "size": "25", "side": "BUY", "hash": "9433825c0141b5eb24ce0acb07ba6a7e10ec915b", "best_bid": "0.87", "best_ask": "0.99"}, {"asset_id": "8063468361343945193901601443622223592937597768285686368444925226215635999992", "price": "0.24", "size": "25", "side": "SELL", "hash": "01bfd1b166151ae24a6bad3ae405a238833da2a5", "best_bid": "0.01", "best_ask": "0.13"}], "timestamp": "1769384236085", "event_type": "price_change"}}
{"_local_timestamp": "2026-01-25T23:37:19.925480+00:00", "data": {"market": "0x268f4042d495b0a3ea61e794c664f1d3796f3a0fc5dab7bf1ad5bfdbf7850d7c", "price_changes": [{"asset_id": "63670917573484538535387075608707689209446344899693197294786093921650274225968", "price": "0.68", "size": "0", "side": "BUY", "hash": "f644dc3e17dd9ad1461ccf26488677a4b4e82cd7", "best_bid": "0.87", "best_ask": "0.99"}, {"asset_id": "8063468361343945193901601443622223592937597768285686368444925226215635999992", "price": "0.32", "size": "0", "side": "SELL", "hash": "d617653bbad5b531570ca216baaa5d4ecbd14718", "best_bid": "0.01", "best_ask": "0.13"}], "timestamp": "1769384239858", "event_type": "price_change"}}
{"_local_timestamp": "2026-01-25T23:37:19.953306+00:00", "data": {"market": "0x268f4042d495b0a3ea61e794c664f1d3796f3a0fc5dab7bf1ad5bfdbf7850d7c", "price_changes": [{"asset_id": "63670917573484538535387075608707689209446344899693197294786093921650274225968", "price": "0.77", "size": "20", "side": "BUY", "hash": "c4652cd8f1da04707fed8f9fe63def7c8614b235", "best_bid": "0.87", "best_ask": "0.99"}, {"asset_id": "8063468361343945193901601443622223592937597768285686368444925226215635999992", "price": "0.23", "size": "20", "side": "SELL", "hash": "0fa00a07c1ad69c29d1491e773a4caa3ca7b0042", "best_bid": "0.01", "best_ask": "0.13"}], "timestamp": "1769384239887", "event_type": "price_change"}}
{"_local_timestamp": "2026-01-25T23:37:20.034935+00:00", "data": {"market": "0x268f4042d495b0a3ea61e794c664f1d3796f3a0fc5dab7bf1ad5bfdbf7850d7c", "price_changes": [{"asset_id": "63670917573484538535387075608707689209446344899693197294786093921650274225968", "price": "0.76", "size": "0", "side": "BUY", "hash": "6db0711d07a0fe50d92c5c31fb34a4d58984d53f", "best_bid": "0.87", "best_ask": "0.99"}, {"asset_id": "8063468361343945193901601443622223592937597768285686368444925226215635999992", "price": "0.24", "size": "0", "side": "SELL", "hash": "d216ec13d755cbd56ead55857761c688c3b55835", "best_bid": "0.01", "best_ask": "0.13"}], "timestamp": "1769384239969", "event_type": "price_change"}}
{"_local_timestamp": "2026-01-25T23:37:21.558847+00:00", "data": {"market": "0x822409787697144b96f53af76e6419655f5704d5a1382c0604aa01fb331e2ca5", "price_changes": [{"asset_id": "48505873629919993069307707366966856150423552939624109422369276111454667757058", "price": "0.01", "size": "4500", "side": "BUY", "hash": "13457b9888be0046a67d7e4179d9024f1b6bb0fb", "best_bid": "0.43", "best_ask": "0.48"}, {"asset_id": "20814542776422534757806032422681843083114551625252466804013971546488759714912", "price": "0.99", "size": "4500", "side": "SELL", "hash": "af61562c17a693151cc2e31afe1b29c31e3f1ce7", "best_bid": "0.52", "best_ask": "0.57"}], "timestamp": "1769384241490", "event_type": "price_change"}}
{"_local_timestamp": "2026-01-25T23:37:24.285442+00:00", "data": {"market": "0x268f4042d495b0a3ea61e794c664f1d3796f3a0fc5dab7bf1ad5bfdbf7850d7c", "price_changes": [{"asset_id": "63670917573484538535387075608707689209446344899693197294786093921650274225968", "price": "0.77", "size": "0", "side": "BUY", "hash": "b5e288236f2cb316b5a12bbb2d5a141df9d16bbd", "best_bid": "0.87", "best_ask": "0.99"}, {"asset_id": "8063468361343945193901601443622223592937597768285686368444925226215635999992", "price": "0.23", "size": "0", "side": "SELL", "hash": "4614dc63e3e1ef43ad3b94ed20aa9c98f8cf1f70", "best_bid": "0.01", "best_ask": "0.13"}], "timestamp": "1769384244220", "event_type": "price_change"}}
{"_local_timestamp": "2026-01-25T23:37:24.310299+00:00", "data": {"market": "0x268f4042d495b0a3ea61e794c664f1d3796f3a0fc5dab7bf1ad5bfdbf7850d7c", "price_changes": [{"asset_id": "63670917573484538535387075608707689209446344899693197294786093921650274225968", "price": "0.68", "size": "20", "side": "BUY", "hash": "027718f51656a058b8f4c142343f88866c7acf92", "best_bid": "0.87", "best_ask": "0.99"}, {"asset_id": "8063468361343945193901601443622223592937597768285686368444925226215635999992", "price": "0.32", "size": "20", "side": "SELL", "hash": "950d588db43dfa9943856b1d6c6a5714ca33ae0a", "best_bid": "0.01", "best_ask": "0.13"}], "timestamp": "1769384244245", "event_type": "price_change"}}
{"_local_timestamp": "2026-01-25T23:37:24.427216+00:00", "data": {"market": "0x268f4042d495b0a3ea61e794c664f1d3796f3a0fc5dab7bf1ad5bfdbf7850d7c", "price_changes": [{"asset_id": "63670917573484538535387075608707689209446344899693197294786093921650274225968", "price": "0.76", "size": "25", "side": "BUY", "hash": "27e101605c352b1152046df8f9c2b520caec1449", "best_bid": "0.87", "best_ask": "0.99"}, {"asset_id": "8063468361343945193901601443622223592937597768285686368444925226215635999992", "price": "0.24", "size": "25", "side": "SELL", "hash": "e844dd7df10da67e3cc8e3b81a0dfda4483d9269", "best_bid": "0.01", "best_ask": "0.13"}], "timestamp": "1769384244358", "event_type": "price_change"}}
{"_local_timestamp": "2026-01-25T23:37:26.752577+00:00", "data": {"market": "0x268f4042d495b0a3ea61e794c664f1d3796f3a0fc5dab7bf1ad5bfdbf7850d7c", "price_changes": [{"asset_id": "63670917573484538535387075608707689209446344899693197294786093921650274225968", "price": "0.68", "size": "0", "side": "BUY", "hash": "b1b413d1fe017528889dd15792568b332873a203", "best_bid": "0.87", "best_ask": "0.99"}, {"asset_id": "8063468361343945193901601443622223592937597768285686368444925226215635999992", "price": "0.32", "size": "0", "side": "SELL", "hash": "a4ada63a24ab47ae1a2415c5df0fea723866e267", "best_bid": "0.01", "best_ask": "0.13"}], "timestamp": "1769384246684", "event_type": "price_change"}}
{"_local_timestamp": "2026-01-25T23:37:26.785496+00:00", "data": {"market": "0x268f4042d495b0a3ea61e794c664f1d3796f3a0fc5dab7bf1ad5bfdbf7850d7c", "price_changes": [{"asset_id": "63670917573484538535387075608707689209446344899693197294786093921650274225968", "price": "0.77", "size": "20", "side": "BUY", "hash": "98e94b0ad253e6ca04ac299a044d208ab95a4830", "best_bid": "0.87", "best_ask": "0.99"}, {"asset_id": "8063468361343945193901601443622223592937597768285686368444925226215635999992", "price": "0.23", "size": "20", "side": "SELL", "hash": "e9076b8ea41d1cbf65a03f59765bc5efc44a691f", "best_bid": "0.01", "best_ask": "0.13"}], "timestamp": "1769384246713", "event_type": "price_change"}}
{"_local_timestamp": "2026-01-25T23:37:26.868262+00:00", "data": {"market": "0x268f4042d495b0a3ea61e794c664f1d3796f3a0fc5dab7bf1ad5bfdbf7850d7c", "price_changes": [{"asset_id": "63670917573484538535387075608707689209446344899693197294786093921650274225968", "price": "0.76", "size": "0", "side": "BUY", "hash": "fd12771d57893936bebccb35c73d797737bc0080", "best_bid": "0.87", "best_ask": "0.99"}, {"asset_id": "8063468361343945193901601443622223592937597768285686368444925226215635999992", "price": "0.24", "size": "0", "side": "SELL", "hash": "7e18a338484dbeceee85f14f2fef9ffda611e1f3", "best_bid": "0.01", "best_ask": "0.13"}], "timestamp": "1769384246802", "event_type": "price_change"}}
{"_local_timestamp": "2026-01-25T23:37:27.702538+00:00", "data": {"market": "0x822409787697144b96f53af76e6419655f5704d5a1382c0604aa01fb331e2ca5", "price_changes": [{"asset_id": "20814542776422534757806032422681843083114551625252466804013971546488759714912", "price": "0.51", "size": "0", "side": "BUY", "hash": "9e29128f2288f9c045ec6214d0cbfae2cdf67a55", "best_bid": "0.52", "best_ask": "0.57"}, {"asset_id": "48505873629919993069307707366966856150423552939624109422369276111454667757058", "price": "0.49", "size": "0", "side": "SELL", "hash": "7833b2736f1fe1c496e9bb6c7fb2f25ed5380982", "best_bid": "0.43", "best_ask": "0.48"}], "timestamp": "1769384247603", "event_type": "price_change"}}
{"_local_timestamp": "2026-01-25T23:37:27.847354+00:00", "data": {"market": "0x822409787697144b96f53af76e6419655f5704d5a1382c0604aa01fb331e2ca5", "price_changes": [{"asset_id": "20814542776422534757806032422681843083114551625252466804013971546488759714912", "price": "0.45", "size": "25", "side": "BUY", "hash": "6d7ab235442427ca5d1402c4170821f48c1d27bc", "best_bid": "0.52", "best_ask": "0.57"}, {"asset_id": "48505873629919993069307707366966856150423552939624109422369276111454667757058", "price": "0.55", "size": "25", "side": "SELL", "hash": "97b11e183c2e461bd3053290798bcf69c3f59479", "best_bid": "0.43", "best_ask": "0.48"}], "timestamp": "1769384247758", "event_type": "price_change"}}
{"_local_timestamp": "2026-01-25T23:37:28.133989+00:00", "data": {"market": "0x822409787697144b96f53af76e6419655f5704d5a1382c0604aa01fb331e2ca5", "price_changes": [{"asset_id": "20814542776422534757806032422681843083114551625252466804013971546488759714912", "price": "0.24", "size": "30", "side": "BUY", "hash": "f2a1598e42cc0992000e3975873a4c2a647372f8", "best_bid": "0.52", "best_ask": "0.57"}, {"asset_id": "48505873629919993069307707366966856150423552939624109422369276111454667757058", "price": "0.76", "size": "30", "side": "SELL", "hash": "9150e980b35b6a6e1030465891a4e59eb3380f42", "best_bid": "0.43", "best_ask": "0.48"}], "timestamp": "1769384248064", "event_type": "price_change"}}
{"_local_timestamp": "2026-01-25T23:37:28.158858+00:00", "data": {"market": "0x822409787697144b96f53af76e6419655f5704d5a1382c0604aa01fb331e2ca5", "price_changes": [{"asset_id": "20814542776422534757806032422681843083114551625252466804013971546488759714912", "price": "0.53", "size": "66.66", "side": "BUY", "hash": "514e3d6879c7af3772c22ea5eca5af6b5b49b72e", "best_bid": "0.53", "best_ask": "0.57"}, {"asset_id": "48505873629919993069307707366966856150423552939624109422369276111454667757058", "price": "0.47", "size": "66.66", "side": "SELL", "hash": "3d1b26a79190a6716455ebb987c084719652b658", "best_bid": "0.43", "best_ask": "0.47"}], "timestamp": "1769384248097", "event_type": "price_change"}}
{"_local_timestamp": "2026-01-25T23:37:28.595907+00:00", "data": {"market": "0x822409787697144b96f53af76e6419655f5704d5a1382c0604aa01fb331e2ca5", "price_changes": [{"asset_id": "20814542776422534757806032422681843083114551625252466804013971546488759714912", "price": "0.52", "size": "100", "side": "BUY", "hash": "7acfa955b69dc53ece3e116a2f4309918c19ab8f", "best_bid": "0.53", "best_ask": "0.57"}, {"asset_id": "48505873629919993069307707366966856150423552939624109422369276111454667757058", "price": "0.48", "size": "100", "side": "SELL", "hash": "a817fb09d59c55adc40b60ee3ad9e54dce854e4c", "best_bid": "0.43", "best_ask": "0.47"}], "timestamp": "1769384248526", "event_type": "price_change"}}
