{"_local_timestamp": "2026-01-25T23:40:33.357158+00:00", "data": [{"market": "0xe0acd0255dbd9274d22d8c1b226c9a2b60bad9098507ce8e7d72dede580cd57a", "asset_id": "22106921341196818050439524942994162234430181387513131058873085228908007365669", "timestamp": "1769384427468", "hash": "b0b732630622e920fbc523bb2779cc681822c27e", "bids": [{"price": "0.01", "size": "5010.1"}, {"price": "0.02", "size": "3750"}, {"price": "0.03", "size": "9.45"}, {"price": "0.04", "size": "750"}, {"price": "0.05", "size": "530"}, {"price": "0.06", "size": "600"}, {"price": "0.09", "size": "80"}, {"price": "0.1", "size": "6.15"}, {"price": "0.12", "size": "550"}, {"price": "0.17", "size": "400"}, {"price": "0.22", "size": "300"}, {"price": "0.23", "size": "8"}, {"price": "0.26", "size": "50"}, {"price": "0.36", "size": "5"}, {"price": "0.4", "size": "500"}, {"price": "0.41", "size": "65.04"}, {"price": "0.42", "size": "8.5"}, {"price": "0.49", "size": "65.04"}, {"price": "0.5", "size": "48"}, {"price": "0.56", "size": "65.04"}, {"price": "0.57", "size": "35"}], "asks": [{"price": "0.99", "size": "10006.01"}, {"price": "0.98", "size": "8756.48"}, {"price": "0.97", "size": "3400"}, {"price": "0.96", "size": "505.58"}, {"price": "0.95", "size": "500"}, {"price": "0.94", "size": "300"}, {"price": "0.93", "size": "309.02"}, {"price": "0.92", "size": "206.01"}, {"price": "0.91", "size": "168.28"}, {"price": "0.9", "size": "130"}, {"price": "0.89", "size": "9.19"}, {"price": "0.88", "size": "181.66"}, {"price": "0.86", "size": "66.66"}, {"price": "0.81", "size": "71.92"}], "event_type": "book", "last_trade_price": ""}, {"market": "0xe0acd0255dbd9274d22d8c1b226c9a2b60bad9098507ce8e7d72dede580cd57a", "asset_id": "2867209803492313176891970118649987905930881752970311413869425427415611673771", "timestamp": "1769384427468", "hash": "f04fdeab504fff0cf33e66a33a5406aa45244fb1", "bids": [{"price": "0.01", "size": "10006.01"}, {"price": "0.02", "size": "8756.48"}, {"price": "0.03", "size": "3400"}, {"price": "0.04", "size": "505.58"}, {"price": "0.05", "size": "500"}, {"price": "0.06", "size": "300"}, {"price": "0.07", "size": "309.02"}, {"price": "0.08", "size": "206.01"}, {"price": "0.09", "size": "168.28"}, {"price": "0.1", "size": "130"}, {"price": "0.11", "size": "9.19"}, {"price": "0.12", "size": "181.66"}, {"price": "0.14", "size": "66.66"}, {"price": "0.19", "size": "71.92"}], "asks": [{"price": "0.99", "size": "5010.1"}, {"price": "0.98", "size": "3750"}, {"price": "0.97", "size": "9.45"}, {"price": "0.96", "size": "750"}, {"price": "0.95", "size": "530"}, {"price": "0.94", "size": "600"}, {"price": "0.91", "size": "80"}, {"price": "0.9", "size": "6.15"}, {"price": "0.88", "size": "550"}, {"price": "0.83", "size": "400"}, {"price": "0.78", "size": "300"}, {"price": "0.77", "size": "8"}, {"price": "0.74", "size": "50"}, {"price": "0.64", "size": "5"}, {"price": "0.6", "size": "500"}, {"price": "0.59", "size": "65.04"}, {"price": "0.58", "size": "8.5"}, {"price": "0.51", "size": "65.04"}, {"price": "0.5", "size": "48"}, {"price": "0.44", "size": "65.04"}, {"price": "0.43", "size": "35"}], "event_type": "book", "last_trade_price": ""}]}
{"_local_timestamp": "2026-01-25T23:40:34.724681+00:00", "data": {"market": "0xe0acd0255dbd9274d22d8c1b226c9a2b60bad9098507ce8e7d72dede580cd57a", "price_changes": [{"asset_id": "22106921341196818050439524942994162234430181387513131058873085228908007365669", "price": "0.36", "size": "0", "side": "BUY", "hash": "ec177dc689cd79ca23e990e5c70ab9aa6be8f976", "best_bid": "0.57", "best_ask": "0.81"}, {"asset_id": "2867209803492313176891970118649987905930881752970311413869425427415611673771", "price": "0.64", "size": "0", "side": "SELL", "hash": "d3d7c316dd52edc7a5284f83b22d6ba8fd2ac2f8", "best_bid": "0.19", "best_ask": "0.43"}], "timestamp": "1769384434653", "event_type": "price_change"}}
{"_local_timestamp": "2026-01-25T23:40:34.995436+00:00", "data": {"market": "0xe0acd0255dbd9274d22d8c1b226c9a2b60bad9098507ce8e7d72dede580cd57a", "price_changes": [{"asset_id": "22106921341196818050439524942994162234430181387513131058873085228908007365669", "price": "0.36", "size": "5", "side": "BUY", "hash": "6885143847729d10d5a93eed6238906651ef345f", "best_bid": "0.57", "best_ask": "0.81"}, {"asset_id": "2867209803492313176891970118649987905930881752970311413869425427415611673771", "price": "0.64", "size": "5", "side": "SELL", "hash": "82e9d6a674cfcffc05018e3fa53e44012db6844a", "best_bid": "0.19", "best_ask": "0.43"}], "timestamp": "1769384434920", "event_type": "price_change"}}
{"_local_timestamp": "2026-01-25T23:40:43.051719+00:00", "data": {"market": "0xe0acd0255dbd9274d22d8c1b226c9a2b60bad9098507ce8e7d72dede580cd57a", "price_changes": [{"asset_id": "22106921341196818050439524942994162234430181387513131058873085228908007365669", "price": "0.36", "size": "0", "side": "BUY", "hash": "97daa3c9c0f5ad1723b464375256489dcb151cae", "best_bid": "0.57", "best_ask": "0.81"}, {"asset_id": "2867209803492313176891970118649987905930881752970311413869425427415611673771", "price": "0.64", "size": "0", "side": "SELL", "hash": "082fa8a5d1ec2f36c3546c4eba06b60003cf17ba", "best_bid": "0.19", "best_ask": "0.43"}], "timestamp": "1769384442976", "event_type": "price_change"}}
{"_local_timestamp": "2026-01-25T23:40:43.293545+00:00", "data": {"market": "0xe0acd0255dbd9274d22d8c1b226c9a2b60bad9098507ce8e7d72dede580cd57a", "price_changes": [{"asset_id": "22106921341196818050439524942994162234430181387513131058873085228908007365669", "price": "0.36", "size": "5", "side": "BUY", "hash": "a573eb51bba852638693fa30d3f81740dfae7d13", "best_bid": "0.57", "best_ask": "0.81"}, {"asset_id": "2867209803492313176891970118649987905930881752970311413869425427415611673771", "price": "0.64", "size": "5", "side": "SELL", "hash": "287ca21cf6c87175a77a2f86a5ea8147dcdda102", "best_bid": "0.19", "best_ask": "0.43"}], "timestamp": "1769384443225", "event_type": "price_change"}}
{"_local_timestamp": "2026-01-25T23:40:52.064555+00:00", "data": {"market": "0xe0acd0255dbd9274d22d8c1b226c9a2b60bad9098507ce8e7d72dede580cd57a", "price_changes": [{"asset_id": "22106921341196818050439524942994162234430181387513131058873085228908007365669", "price": "0.36", "size": "0", "side": "BUY", "hash": "4ee15b8f1f15b32b6567e9edcc15de3c017d2853", "best_bid": "0.57", "best_ask": "0.81"}, {"asset_id": "2867209803492313176891970118649987905930881752970311413869425427415611673771", "price": "0.64", "size": "0", "side": "SELL", "hash": "dd699bb5342ee9b7b18b954cb5e05c6d7533cc68", "best_bid": "0.19", "best_ask": "0.43"}], "timestamp": "1769384451987", "event_type": "price_change"}}
{"_local_timestamp": "2026-01-25T23:40:52.513671+00:00", "data": {"market": "0xe0acd0255dbd9274d22d8c1b226c9a2b60bad9098507ce8e7d72dede580cd57a", "price_changes": [{"asset_id": "22106921341196818050439524942994162234430181387513131058873085228908007365669", "price": "0.36", "size": "5", "side": "BUY", "hash": "c5868a6ffd0772d4097904622f06af11e9f2e308", "best_bid": "0.57", "best_ask": "0.81"}, {"asset_id": "2867209803492313176891970118649987905930881752970311413869425427415611673771", "price": "0.64", "size": "5", "side": "SELL", "hash": "c1ae8c73c1c687dff776cab01cb9df17be5e3376", "best_bid": "0.19", "best_ask": "0.43"}], "timestamp": "1769384452445", "event_type": "price_change"}}
{"_local_timestamp": "2026-01-25T23:41:00.112828+00:00", "data": {"market": "0xe0acd0255dbd9274d22d8c1b226c9a2b60bad9098507ce8e7d72dede580cd57a", "price_changes": [{"asset_id": "22106921341196818050439524942994162234430181387513131058873085228908007365669", "price": "0.36", "size": "0", "side": "BUY", "hash": "5153534b47ef6485bbb5efaf0022e9e29c2c20e3", "best_bid": "0.57", "best_ask": "0.81"}, {"asset_id": "2867209803492313176891970118649987905930881752970311413869425427415611673771", "price": "0.64", "size": "0", "side": "SELL", "hash": "691335a1a3d94c72d6526b73db8e56497c87ddd8", "best_bid": "0.19", "best_ask": "0.43"}], "timestamp": "1769384460045", "event_type": "price_change"}}
{"_local_timestamp": "2026-01-25T23:41:00.360056+00:00", "data": {"market": "0xe0acd0255dbd9274d22d8c1b226c9a2b60bad9098507ce8e7d72dede580cd57a", "price_changes": [{"asset_id": "22106921341196818050439524942994162234430181387513131058873085228908007365669", "price": "0.36", "size": "5", "side": "BUY", "hash": "9cab016672f7bf298e544434e28580ab5ed4d043", "best_bid": "0.57", "best_ask": "0.81"}, {"asset_id": "2867209803492313176891970118649987905930881752970311413869425427415611673771", "price": "0.64", "size": "5", "side": "SELL", "hash": "8bebba13c7894e1f8fdad14308b54335ab2bb3b8", "best_bid": "0.19", "best_ask": "0.43"}], "timestamp": "1769384460281", "event_type": "price_change"}}
{"_local_timestamp": "2026-01-25T23:41:09.556686+00:00", "data": {"market": "0xe0acd0255dbd9274d22d8c1b226c9a2b60bad9098507ce8e7d72dede580cd57a", "price_changes": [{"asset_id": "22106921341196818050439524942994162234430181387513131058873085228908007365669", "price": "0.36", "size": "0", "side": "BUY", "hash": "dc5c63c2dce6624517d449aeac7f67195510cf53", "best_bid": "0.57", "best_ask": "0.81"}, {"asset_id": "2867209803492313176891970118649987905930881752970311413869425427415611673771", "price": "0.64", "size": "0", "side": "SELL", "hash": "5c223d46cd73358871c5f6a86e16770e46f889d6", "best_bid": "0.19", "best_ask": "0.43"}], "timestamp": "1769384469487", "event_type": "price_change"}}
{"_local_timestamp": "2026-01-25T23:41:09.942028+00:00", "data": {"market": "0xe0acd0255dbd9274d22d8c1b226c9a2b60bad9098507ce8e7d72dede580cd57a", "price_changes": [{"asset_id": "22106921341196818050439524942994162234430181387513131058873085228908007365669", "price": "0.36", "size": "5", "side": "BUY", "hash": "75e58e8ebe0d545b0eb30eecabf9c82d59baec65", "best_bid": "0.57", "best_ask": "0.81"}, {"asset_id": "2867209803492313176891970118649987905930881752970311413869425427415611673771", "price": "0.64", "size": "5", "side": "SELL", "hash": "06cbb6d73cea957191b1768a54f6c7627a1fe438", "best_bid": "0.19", "best_ask": "0.43"}], "timestamp": "1769384469866", "event_type": "price_change"}}
{"_local_timestamp": "2026-01-25T23:41:18.395559+00:00", "data": {"market": "0xe0acd0255dbd9274d22d8c1b226c9a2b60bad9098507ce8e7d72dede580cd57a", "price_changes": [{"asset_id": "22106921341196818050439524942994162234430181387513131058873085228908007365669", "price": "0.36", "size": "0", "side": "BUY", "hash": "d7624c4bf77b7a96b754f1746d1ee742d878b56b", "best_bid": "0.57", "best_ask": "0.81"}, {"asset_id": "2867209803492313176891970118649987905930881752970311413869425427415611673771", "price": "0.64", "size": "0", "side": "SELL", "hash": "7bf93587c0a92588d62522981d477b57bfe0798e", "best_bid": "0.19", "best_ask": "0.43"}], "timestamp": "1769384478266", "event_type": "price_change"}}
{"_local_timestamp": "2026-01-25T23:41:18.680729+00:00", "data": {"market": "0xe0acd0255dbd9274d22d8c1b226c9a2b60bad9098507ce8e7d72dede580cd57a", "price_changes": [{"asset_id": "22106921341196818050439524942994162234430181387513131058873085228908007365669", "price": "0.36", "size": "5", "side": "BUY", "hash": "57a3dfe68cd49463c004f60d2e7d8315e4963bd2", "best_bid": "0.57", "best_ask": "0.81"}, {"asset_id": "2867209803492313176891970118649987905930881752970311413869425427415611673771", "price": "0.64", "size": "5", "side": "SELL", "hash": "1fa511f363f2c906647f7a1c83702f303d732305", "best_bid": "0.19", "best_ask": "0.43"}], "timestamp": "1769384478602", "event_type": "price_change"}}
{"_local_timestamp": "2026-01-25T23:41:27.985887+00:00", "data": {"market": "0xe0acd0255dbd9274d22d8c1b226c9a2b60bad9098507ce8e7d72dede580cd57a", "price_changes": [{"asset_id": "22106921341196818050439524942994162234430181387513131058873085228908007365669", "price": "0.36", "size": "0", "side": "BUY", "hash": "92a139b0b297668831350cd8e4ef77b2975794ba", "best_bid": "0.57", "best_ask": "0.81"}, {"asset_id": "2867209803492313176891970118649987905930881752970311413869425427415611673771", "price": "0.64", "size": "0", "side": "SELL", "hash": "825277240eae2c0e9fc0d53541ebcf43b3cfe1b4", "best_bid": "0.19", "best_ask": "0.43"}], "timestamp": "1769384487897", "event_type": "price_change"}}
{"_local_timestamp": "2026-01-25T23:41:28.390103+00:00", "data": {"market": "0xe0acd0255dbd9274d22d8c1b226c9a2b60bad9098507ce8e7d72dede580cd57a", "price_changes": [{"asset_id": "22106921341196818050439524942994162234430181387513131058873085228908007365669", "price": "0.36", "size": "5", "side": "BUY", "hash": "53d8c3a4eca671e628a695d6e4e8f891b7fd0f14", "best_bid": "0.57", "best_ask": "0.81"}, {"asset_id": "2867209803492313176891970118649987905930881752970311413869425427415611673771", "price": "0.64", "size": "5", "side": "SELL", "hash": "1eb6b8ad1432ec0fde89cd600e9c783e356d0336", "best_bid": "0.19", "best_ask": "0.43"}], "timestamp": "1769384488318", "event_type": "price_change"}}
{"_local_timestamp": "2026-01-25T23:41:41.841749+00:00", "data": {"market": "0xe0acd0255dbd9274d22d8c1b226c9a2b60bad9098507ce8e7d72dede580cd57a", "price_changes": [{"asset_id": "22106921341196818050439524942994162234430181387513131058873085228908007365669", "price": "0.36", "size": "0", "side": "BUY", "hash": "2bc6b1191d8d8ce675fd221d0abe6023d2bf292c", "best_bid": "0.57", "best_ask": "0.81"}, {"asset_id": "2867209803492313176891970118649987905930881752970311413869425427415611673771", "price": "0.64", "size": "0", "side": "SELL", "hash": "71f71f534bc7afceb2b64f3d50c9b86c1384ba2e", "best_bid": "0.19", "best_ask": "0.43"}], "timestamp": "1769384501769", "event_type": "price_change"}}
{"_local_timestamp": "2026-01-25T23:41:42.162727+00:00", "data": {"market": "0xe0acd0255dbd9274d22d8c1b226c9a2b60bad9098507ce8e7d72dede580cd57a", "price_changes": [{"asset_id": "22106921341196818050439524942994162234430181387513131058873085228908007365669", "price": "0.36", "size": "5", "side": "BUY", "hash": "c11c75a5efcc7fb648dcd16c8afc1bef146a160e", "best_bid": "0.57", "best_ask": "0.81"}, {"asset_id": "2867209803492313176891970118649987905930881752970311413869425427415611673771", "price": "0.64", "size": "5", "side": "SELL", "hash": "caeec07eccd14229a86f2329386373c4838400a9", "best_bid": "0.19", "best_ask": "0.43"}], "timestamp": "1769384502092", "event_type": "price_change"}}
{"_local_timestamp": "2026-01-25T23:41:56.886358+00:00", "data": {"market": "0xe0acd0255dbd9274d22d8c1b226c9a2b60bad9098507ce8e7d72dede580cd57a", "price_changes": [{"asset_id": "22106921341196818050439524942994162234430181387513131058873085228908007365669", "price": "0.36", "size": "0", "side": "BUY", "hash": "0b19653dfcbc2346aaac445c251f81b6ec5849d5", "best_bid": "0.57", "best_ask": "0.81"}, {"asset_id": "2867209803492313176891970118649987905930881752970311413869425427415611673771", "price": "0.64", "size": "0", "side": "SELL", "hash": "248f2f4863bb82755a708398bf32f4ab60f5443b", "best_bid": "0.19", "best_ask": "0.43"}], "timestamp": "1769384516809", "event_type": "price_change"}}
{"_local_timestamp": "2026-01-25T23:41:57.116243+00:00", "data": {"market": "0xe0acd0255dbd9274d22d8c1b226c9a2b60bad9098507ce8e7d72dede580cd57a", "price_changes": [{"asset_id": "22106921341196818050439524942994162234430181387513131058873085228908007365669", "price": "0.36", "size": "5", "side": "BUY", "hash": "39e669fe49e356b05f7fef5cb35229067c1d4c85", "best_bid": "0.57", "best_ask": "0.81"}, {"asset_id": "2867209803492313176891970118649987905930881752970311413869425427415611673771", "price": "0.64", "size": "5", "side": "SELL", "hash": "b5ca2058ca034e8a5b966fa90c999606516488d1", "best_bid": "0.19", "best_ask": "0.43"}], "timestamp": "1769384517006", "event_type": "price_change"}}
{"_local_timestamp": "2026-01-25T23:42:16.203255+00:00", "data": {"market": "0xe0acd0255dbd9274d22d8c1b226c9a2b60bad9098507ce8e7d72dede580cd57a", "price_changes": [{"asset_id": "22106921341196818050439524942994162234430181387513131058873085228908007365669", "price": "0.36", "size": "0", "side": "BUY", "hash": "69a3fbc6677bc599202cb05657ada8ea8ef6507b", "best_bid": "0.57", "best_ask": "0.81"}, {"asset_id": "2867209803492313176891970118649987905930881752970311413869425427415611673771", "price": "0.64", "size": "0", "side": "SELL", "hash": "e8348f21b579b7051529e96886af8fec101a09b4", "best_bid": "0.19", "best_ask": "0.43"}], "timestamp": "1769384536102", "event_type": "price_change"}}
{"_local_timestamp": "2026-01-25T23:42:16.447014+00:00", "data": {"market": "0xe0acd0255dbd9274d22d8c1b226c9a2b60bad9098507ce8e7d72dede580cd57a", "price_changes": [{"asset_id": "22106921341196818050439524942994162234430181387513131058873085228908007365669", "price": "0.36", "size": "5", "side": "BUY", "hash": "978e27b6b05c20bcc8a17419943072f8f598a3e3", "best_bid": "0.57", "best_ask": "0.81"}, {"asset_id": "2867209803492313176891970118649987905930881752970311413869425427415611673771", "price": "0.64", "size": "5", "side": "SELL", "hash": "06da12c1b842eeb5bd679a81262ae0471fec07bc", "best_bid": "0.19", "best_ask": "0.43"}], "timestamp": "1769384536343", "event_type": "price_change"}}
{"_local_timestamp": "2026-01-25T23:42:41.441365+00:00", "data": {"market": "0xe0acd0255dbd9274d22d8c1b226c9a2b60bad9098507ce8e7d72dede580cd57a", "price_changes": [{"asset_id": "22106921341196818050439524942994162234430181387513131058873085228908007365669", "price": "0.36", "size": "0", "side": "BUY", "hash": "d591a82232fd0324ff2cc19aad2bfbbef334aca5", "best_bid": "0.57", "best_ask": "0.81"}, {"asset_id": "2867209803492313176891970118649987905930881752970311413869425427415611673771", "price": "0.64", "size": "0", "side": "SELL", "hash": "c67d66efdf3dccbcf3a1e7e5e10d8dc08de5331e", "best_bid": "0.19", "best_ask": "0.43"}], "timestamp": "1769384561301", "event_type": "price_change"}}
{"_local_timestamp": "2026-01-25T23:42:42.174380+00:00", "data": {"market": "0xe0acd0255dbd9274d22d8c1b226c9a2b60bad9098507ce8e7d72dede580cd57a", "price_changes": [{"asset_id": "22106921341196818050439524942994162234430181387513131058873085228908007365669", "price": "0.36", "size": "5", "side": "BUY", "hash": "bb01dcd893df2c5e7d9da147348f3130b8bfa91d", "best_bid": "0.57", "best_ask": "0.81"}, {"asset_id": "2867209803492313176891970118649987905930881752970311413869425427415611673771", "price": "0.64", "size": "5", "side": "SELL", "hash": "026f0462921b841c66ebe71c8900e9a3e62883c7", "best_bid": "0.19", "best_ask": "0.43"}], "timestamp": "1769384562034", "event_type": "price_change"}}
{"_local_timestamp": "2026-01-25T23:43:09.120069+00:00", "data": {"market": "0xe0acd0255dbd9274d22d8c1b226c9a2b60bad9098507ce8e7d72dede580cd57a", "price_changes": [{"asset_id": "22106921341196818050439524942994162234430181387513131058873085228908007365669", "price": "0.36", "size": "0", "side": "BUY", "hash": "4a25cfaf5b44885b7c06e73a600cac3974d8c7d8", "best_bid": "0.57", "best_ask": "0.81"}, {"asset_id": "2867209803492313176891970118649987905930881752970311413869425427415611673771", "price": "0.64", "size": "0", "side": "SELL", "hash": "d2c3a8eb26f080898fe8dca4b74993f90c9f323c", "best_bid": "0.19", "best_ask": "0.43"}], "timestamp": "1769384588979", "event_type": "price_change"}}
{"_local_timestamp": "2026-01-25T23:43:09.464627+00:00", "data": {"market": "0xe0acd0255dbd9274d22d8c1b226c9a2b60bad9098507ce8e7d72dede580cd57a", "price_changes": [{"asset_id": "22106921341196818050439524942994162234430181387513131058873085228908007365669", "price": "0.36", "size": "5", "side": "BUY", "hash": "38deed8c265870533c39bc4be79530816e124dae", "best_bid": "0.57", "best_ask": "0.81"}, {"asset_id": "2867209803492313176891970118649987905930881752970311413869425427415611673771", "price": "0.64", "size": "5", "side": "SELL", "hash": "4c184aa608d0cf5c941f31b94100c1a0716962b9", "best_bid": "0.19", "best_ask": "0.43"}], "timestamp": "1769384589331", "event_type": "price_change"}}
{"_local_timestamp": "2026-01-25T23:43:36.436973+00:00", "data": {"market": "0xe0acd0255dbd9274d22d8c1b226c9a2b60bad9098507ce8e7d72dede580cd57a", "price_changes": [{"asset_id": "22106921341196818050439524942994162234430181387513131058873085228908007365669", "price": "0.36", "size": "0", "side": "BUY", "hash": "7b85e8166a473aab4ad0059b27ac556e0cbc77b2", "best_bid": "0.57", "best_ask": "0.81"}, {"asset_id": "2867209803492313176891970118649987905930881752970311413869425427415611673771", "price": "0.64", "size": "0", "side": "SELL", "hash": "c5834bdb61715ef844c8a5a4df6f78c3c15d91a4", "best_bid": "0.19", "best_ask": "0.43"}], "timestamp": "1769384616354", "event_type": "price_change"}}
{"_local_timestamp": "2026-01-25T23:43:36.682206+00:00", "data": {"market": "0xe0acd0255dbd9274d22d8c1b226c9a2b60bad9098507ce8e7d72dede580cd57a", "price_changes": [{"asset_id": "22106921341196818050439524942994162234430181387513131058873085228908007365669", "price": "0.36", "size": "5", "side": "BUY", "hash": "7307e8c91f2c677ac200d0e8823b2e964b979c69", "best_bid": "0.57", "best_ask": "0.81"}, {"asset_id": "2867209803492313176891970118649987905930881752970311413869425427415611673771", "price": "0.64", "size": "5", "side": "SELL", "hash": "b165c32d80abb634465632650fa7d110e0737e9a", "best_bid": "0.19", "best_ask": "0.43"}], "timestamp": "1769384616595", "event_type": "price_change"}}
{"_local_timestamp": "2026-01-25T23:43:59.897278+00:00", "data": {"market": "0xe0acd0255dbd9274d22d8c1b226c9a2b60bad9098507ce8e7d72dede580cd57a", "price_changes": [{"asset_id": "22106921341196818050439524942994162234430181387513131058873085228908007365669", "price": "0.36", "size": "0", "side": "BUY", "hash": "527d5133e2a66a1409b57ee71327ead46f1ecbcf", "best_bid": "0.57", "best_ask": "0.81"}, {"asset_id": "2867209803492313176891970118649987905930881752970311413869425427415611673771", "price": "0.64", "size": "0", "side": "SELL", "hash": "8f0235d8da030f70d54ec540b357fed124b2106f", "best_bid": "0.19", "best_ask": "0.43"}], "timestamp": "1769384639786", "event_type": "price_change"}}
{"_local_timestamp": "2026-01-25T23:44:00.155796+00:00", "data": {"market": "0xe0acd0255dbd9274d22d8c1b226c9a2b60bad9098507ce8e7d72dede580cd57a", "price_changes": [{"asset_id": "22106921341196818050439524942994162234430181387513131058873085228908007365669", "price": "0.36", "size": "5", "side": "BUY", "hash": "d7ea62627def8a59507d56b9c31d78fc06639bcf", "best_bid": "0.57", "best_ask": "0.81"}, {"asset_id": "2867209803492313176891970118649987905930881752970311413869425427415611673771", "price": "0.64", "size": "5", "side": "SELL", "hash": "b5d142f4679bff5129390e8c3d6e921f8d7395d5", "best_bid": "0.19", "best_ask": "0.43"}], "timestamp": "1769384640028", "event_type": "price_change"}}
{"_local_timestamp": "2026-01-25T23:44:15.329650+00:00", "data": {"market": "0xe0acd0255dbd9274d22d8c1b226c9a2b60bad9098507ce8e7d72dede580cd57a", "price_changes": [{"asset_id": "22106921341196818050439524942994162234430181387513131058873085228908007365669", "price": "0.36", "size": "0", "side": "BUY", "hash": "99c101d13a341abf145fd3ac0c11372eb1b9dc4a", "best_bid": "0.57", "best_ask": "0.81"}, {"asset_id": "2867209803492313176891970118649987905930881752970311413869425427415611673771", "price": "0.64", "size": "0", "side": "SELL", "hash": "47f55611e555491efbd4d6d86784be212eeb1059", "best_bid": "0.19", "best_ask": "0.43"}], "timestamp": "1769384655178", "event_type": "price_change"}}
{"_local_timestamp": "2026-01-25T23:44:15.716211+00:00", "data": {"market": "0xe0acd0255dbd9274d22d8c1b226c9a2b60bad9098507ce8e7d72dede580cd57a", "price_changes": [{"asset_id": "22106921341196818050439524942994162234430181387513131058873085228908007365669", "price": "0.36", "size": "5", "side": "BUY", "hash": "0137728a39f24f1dcf7dbfe2e9335b62fa80b7be", "best_bid": "0.57", "best_ask": "0.81"}, {"asset_id": "2867209803492313176891970118649987905930881752970311413869425427415611673771", "price": "0.64", "size": "5", "side": "SELL", "hash": "27495b293c815463f3177b8c96778839c07be39f", "best_bid": "0.19", "best_ask": "0.43"}], "timestamp": "1769384655574", "event_type": "price_change"}}
{"_local_timestamp": "2026-01-25T23:44:23.629384+00:00", "data": {"market": "0xe0acd0255dbd9274d22d8c1b226c9a2b60bad9098507ce8e7d72dede580cd57a", "price_changes": [{"asset_id": "22106921341196818050439524942994162234430181387513131058873085228908007365669", "price": "0.36", "size": "0", "side": "BUY", "hash": "66073236a7daaa9587a91fdf91a82a4e39712bfe", "best_bid": "0.57", "best_ask": "0.81"}, {"asset_id": "2867209803492313176891970118649987905930881752970311413869425427415611673771", "price": "0.64", "size": "0", "side": "SELL", "hash": "4b44f24bc40e1cf7b19226efd0e0ecd3881c3e8d", "best_bid": "0.19", "best_ask": "0.43"}], "timestamp": "1769384663560", "event_type": "price_change"}}
{"_local_timestamp": "2026-01-25T23:44:23.827917+00:00", "data": {"market": "0xe0acd0255dbd9274d22d8c1b226c9a2b60bad9098507ce8e7d72dede580cd57a", "price_changes": [{"asset_id": "22106921341196818050439524942994162234430181387513131058873085228908007365669", "price": "0.36", "size": "5", "side": "BUY", "hash": "29157e037a87436dd75b22a4c6080f52bc29e890", "best_bid": "0.57", "best_ask": "0.81"}, {"asset_id": "2867209803492313176891970118649987905930881752970311413869425427415611673771", "price": "0.64", "size": "5", "side": "SELL", "hash": "76fc305659c260044e798f56184dc56e911a5d7c", "best_bid": "0.19", "best_ask": "0.43"}], "timestamp": "1769384663753", "event_type": "price_change"}}
{"_local_timestamp": "2026-01-25T23:44:31.413791+00:00", "data": {"market": "0xe0acd0255dbd9274d22d8c1b226c9a2b60bad9098507ce8e7d72dede580cd57a", "price_changes": [{"asset_id": "22106921341196818050439524942994162234430181387513131058873085228908007365669", "price": "0.36", "size": "0", "side": "BUY", "hash": "436f62892682df82f431aec2f935ceee585967e2", "best_bid": "0.57", "best_ask": "0.81"}, {"asset_id": "2867209803492313176891970118649987905930881752970311413869425427415611673771", "price": "0.64", "size": "0", "side": "SELL", "hash": "79822e028e912bd87b96813ac60af36477e2dbe2", "best_bid": "0.19", "best_ask": "0.43"}], "timestamp": "1769384671347", "event_type": "price_change"}}
{"_local_timestamp": "2026-01-25T23:44:31.654843+00:00", "data": {"market": "0xe0acd0255dbd9274d22d8c1b226c9a2b60bad9098507ce8e7d72dede580cd57a", "price_changes": [{"asset_id": "22106921341196818050439524942994162234430181387513131058873085228908007365669", "price": "0.36", "size": "5", "side": "BUY", "hash": "de1abb267ab740fb3d7fc40e1ecdb43c51815efe", "best_bid": "0.57", "best_ask": "0.81"}, {"asset_id": "2867209803492313176891970118649987905930881752970311413869425427415611673771", "price": "0.64", "size": "5", "side": "SELL", "hash": "516e4c86f6f50dd22670f0971376d1f48bada82e", "best_bid": "0.19", "best_ask": "0.43"}], "timestamp": "1769384671586", "event_type": "price_change"}}
{"_local_timestamp": "2026-01-25T23:44:41.969134+00:00", "data": {"market": "0xe0acd0255dbd9274d22d8c1b226c9a2b60bad9098507ce8e7d72dede580cd57a", "price_changes": [{"asset_id": "22106921341196818050439524942994162234430181387513131058873085228908007365669", "price": "0.36", "size": "0", "side": "BUY", "hash": "4747e49df79025eb6374fff1b33b1d5e87ce58f6", "best_bid": "0.57", "best_ask": "0.81"}, {"asset_id": "2867209803492313176891970118649987905930881752970311413869425427415611673771", "price": "0.64", "size": "0", "side": "SELL", "hash": "6516234842bb2dd504218ffb6f8083227f87dc7b", "best_bid": "0.19", "best_ask": "0.43"}], "timestamp": "1769384681902", "event_type": "price_change"}}
{"_local_timestamp": "2026-01-25T23:44:42.392043+00:00", "data": {"market": "0xe0acd0255dbd9274d22d8c1b226c9a2b60bad9098507ce8e7d72dede580cd57a", "price_changes": [{"asset_id": "22106921341196818050439524942994162234430181387513131058873085228908007365669", "price": "0.36", "size": "5", "side": "BUY", "hash": "a6bf018d789de6e197614c74e25d61a837671555", "best_bid": "0.57", "best_ask": "0.81"}, {"asset_id": "2867209803492313176891970118649987905930881752970311413869425427415611673771", "price": "0.64", "size": "5", "side": "SELL", "hash": "63584f7dd82f998f13da1a8b32e1cbbce00c52a0", "best_bid": "0.19", "best_ask": "0.43"}], "timestamp": "1769384682315", "event_type": "price_change"}}
{"_local_timestamp": "2026-01-25T23:44:52.642567+00:00", "data": {"market": "0xe0acd0255dbd9274d22d8c1b226c9a2b60bad9098507ce8e7d72dede580cd57a", "price_changes": [{"asset_id": "22106921341196818050439524942994162234430181387513131058873085228908007365669", "price": "0.36", "size": "0", "side": "BUY", "hash": "d986aff3a108c93a83515d2817552a848ebde1e3", "best_bid": "0.57", "best_ask": "0.81"}, {"asset_id": "2867209803492313176891970118649987905930881752970311413869425427415611673771", "price": "0.64", "size": "0", "side": "SELL", "hash": "56454c5058d45e19d784cfbfe1867aa5bb0475ae", "best_bid": "0.19", "best_ask": "0.43"}], "timestamp": "1769384692557", "event_type": "price_change"}}
{"_local_timestamp": "2026-01-25T23:44:52.858947+00:00", "data": {"market": "0xe0acd0255dbd9274d22d8c1b226c9a2b60bad9098507ce8e7d72dede580cd57a", "price_changes": [{"asset_id": "22106921341196818050439524942994162234430181387513131058873085228908007365669", "price": "0.36", "size": "5", "side": "BUY", "hash": "c32f74f428523bcf6ccf18d120584b2a32ad8621", "best_bid": "0.57", "best_ask": "0.81"}, {"asset_id": "2867209803492313176891970118649987905930881752970311413869425427415611673771", "price": "0.64", "size": "5", "side": "SELL", "hash": "c7185753a23d9498e3253cb4a537a437657212b0", "best_bid": "0.19", "best_ask": "0.43"}], "timestamp": "1769384692795", "event_type": "price_change"}}
{"_local_timestamp": "2026-01-25T23:45:01.594429+00:00", "data": {"market": "0xe0acd0255dbd9274d22d8c1b226c9a2b60bad9098507ce8e7d72dede580cd57a", "price_changes": [{"asset_id": "22106921341196818050439524942994162234430181387513131058873085228908007365669", "price": "0.36", "size": "0", "side": "BUY", "hash": "31b9d398028603f4ee4b5af72f7d89565481b252", "best_bid": "0.57", "best_ask": "0.81"}, {"asset_id": "2867209803492313176891970118649987905930881752970311413869425427415611673771", "price": "0.64", "size": "0", "side": "SELL", "hash": "6c66f2e03d96180af889409398bd970529672b3e", "best_bid": "0.19", "best_ask": "0.43"}], "timestamp": "1769384701498", "event_type": "price_change"}}
{"_local_timestamp": "2026-01-25T23:45:01.786822+00:00", "data": {"market": "0xe0acd0255dbd9274d22d8c1b226c9a2b60bad9098507ce8e7d72dede580cd57a", "price_changes": [{"asset_id": "22106921341196818050439524942994162234430181387513131058873085228908007365669", "price": "0.36", "size": "5", "side": "BUY", "hash": "6b8edff743465bb97f58fb6b3c0a33919b1e19a8", "best_bid": "0.57", "best_ask": "0.81"}, {"asset_id": "2867209803492313176891970118649987905930881752970311413869425427415611673771", "price": "0.64", "size": "5", "side": "SELL", "hash": "6ef3576e16b452038fb3c9afaece8000f306bb96", "best_bid": "0.19", "best_ask": "0.43"}], "timestamp": "1769384701700", "event_type": "price_change"}}
{"_local_timestamp": "2026-01-25T23:45:12.236205+00:00", "data": {"market": "0xe0acd0255dbd9274d22d8c1b226c9a2b60bad9098507ce8e7d72dede580cd57a", "price_changes": [{"asset_id": "22106921341196818050439524942994162234430181387513131058873085228908007365669", "price": "0.36", "size": "0", "side": "BUY", "hash": "2077bbf64e75c91293d5bcc6a8e55500f112ec8e", "best_bid": "0.57", "best_ask": "0.81"}, {"asset_id": "2867209803492313176891970118649987905930881752970311413869425427415611673771", "price": "0.64", "size": "0", "side": "SELL", "hash": "c789c4a30894eac9601be1529fc8a1ba6d23be40", "best_bid": "0.19", "best_ask": "0.43"}], "timestamp": "1769384712166", "event_type": "price_change"}}
{"_local_timestamp": "2026-01-25T23:45:12.642012+00:00", "data": {"market": "0xe0acd0255dbd9274d22d8c1b226c9a2b60bad9098507ce8e7d72dede580cd57a", "price_changes": [{"asset_id": "22106921341196818050439524942994162234430181387513131058873085228908007365669", "price": "0.36", "size": "5", "side": "BUY", "hash": "4c9cc3ab937c7389212761f9567948043076e481", "best_bid": "0.57", "best_ask": "0.81"}, {"asset_id": "2867209803492313176891970118649987905930881752970311413869425427415611673771", "price": "0.64", "size": "5", "side": "SELL", "hash": "3b4da2dbe56556153333cc65db8e11b0e96554c3", "best_bid": "0.19", "best_ask": "0.43"}], "timestamp": "1769384712569", "event_type": "price_change"}}
{"_local_timestamp": "2026-01-25T23:45:23.882807+00:00", "data": {"market": "0xe0acd0255dbd9274d22d8c1b226c9a2b60bad9098507ce8e7d72dede580cd57a", "price_changes": [{"asset_id": "22106921341196818050439524942994162234430181387513131058873085228908007365669", "price": "0.36", "size": "0", "side": "BUY", "hash": "e3f5137da20e5272c203b68fbd1ee89402c475de", "best_bid": "0.57", "best_ask": "0.81"}, {"asset_id": "2867209803492313176891970118649987905930881752970311413869425427415611673771", "price": "0.64", "size": "0", "side": "SELL", "hash": "d591007b4ae02a2e08918bfd1daadfc1a451d4a9", "best_bid": "0.19", "best_ask": "0.43"}], "timestamp": "1769384723817", "event_type": "price_change"}}
{"_local_timestamp": "2026-01-25T23:45:24.271471+00:00", "data": {"market": "0xe0acd0255dbd9274d22d8c1b226c9a2b60bad9098507ce8e7d72dede580cd57a", "price_changes": [{"asset_id": "22106921341196818050439524942994162234430181387513131058873085228908007365669", "price": "0.36", "size": "5", "side": "BUY", "hash": "4ee1b2f47f88944863afa669e898c769b3b5e898", "best_bid": "0.57", "best_ask": "0.81"}, {"asset_id": "2867209803492313176891970118649987905930881752970311413869425427415611673771", "price": "0.64", "size": "5", "side": "SELL", "hash": "90254a34721f77cac732545eff7740b1d4118e10", "best_bid": "0.19", "best_ask": "0.43"}], "timestamp": "1769384724199", "event_type": "price_change"}}
{"_local_timestamp": "2026-01-25T23:45:39.003703+00:00", "data": {"market": "0xe0acd0255dbd9274d22d8c1b226c9a2b60bad9098507ce8e7d72dede580cd57a", "price_changes": [{"asset_id": "22106921341196818050439524942994162234430181387513131058873085228908007365669", "price": "0.36", "size": "0", "side": "BUY", "hash": "d51ac0e40ed8de1109b10ecfa946f53c1f4495a7", "best_bid": "0.57", "best_ask": "0.81"}, {"asset_id": "2867209803492313176891970118649987905930881752970311413869425427415611673771", "price": "0.64", "size": "0", "side": "SELL", "hash": "d3a75f2b0ffb91cdc999521459a6b1e755408838", "best_bid": "0.19", "best_ask": "0.43"}], "timestamp": "1769384738933", "event_type": "price_change"}}
{"_local_timestamp": "2026-01-25T23:45:39.378317+00:00", "data": {"market": "0xe0acd0255dbd9274d22d8c1b226c9a2b60bad9098507ce8e7d72dede580cd57a", "price_changes": [{"asset_id": "22106921341196818050439524942994162234430181387513131058873085228908007365669", "price": "0.36", "size": "5", "side": "BUY", "hash": "30bd6eae7bcfb188748841635f2f7468e64c863d", "best_bid": "0.57", "best_ask": "0.81"}, {"asset_id": "2867209803492313176891970118649987905930881752970311413869425427415611673771", "price": "0.64", "size": "5", "side": "SELL", "hash": "8a9219095cdd3128be379590f599f37e2599cb95", "best_bid": "0.19", "best_ask": "0.43"}], "timestamp": "1769384739313", "event_type": "price_change"}}
{"_local_timestamp": "2026-01-25T23:46:09.357944+00:00", "data": {"market": "0xe0acd0255dbd9274d22d8c1b226c9a2b60bad9098507ce8e7d72dede580cd57a", "price_changes": [{"asset_id": "22106921341196818050439524942994162234430181387513131058873085228908007365669", "price": "0.36", "size": "0", "side": "BUY", "hash": "9aa95cb36f1343ea5c60f1d5db476ba200e97e9d", "best_bid": "0.57", "best_ask": "0.81"}, {"asset_id": "2867209803492313176891970118649987905930881752970311413869425427415611673771", "price": "0.64", "size": "0", "side": "SELL", "hash": "ae22df530f6e5b053cb8a5ea5d5370d3a4724d40", "best_bid": "0.19", "best_ask": "0.43"}], "timestamp": "1769384769280", "event_type": "price_change"}}
{"_local_timestamp": "2026-01-25T23:46:09.358388+00:00", "data": {"market": "0xe0acd0255dbd9274d22d8c1b226c9a2b60bad9098507ce8e7d72dede580cd57a", "price_changes": [{"asset_id": "22106921341196818050439524942994162234430181387513131058873085228908007365669", "price": "0.1", "size": "0", "side": "BUY", "hash": "9aa95cb36f1343ea5c60f1d5db476ba200e97e9d", "best_bid": "0.57", "best_ask": "0.81"}, {"asset_id": "2867209803492313176891970118649987905930881752970311413869425427415611673771", "price": "0.9", "size": "0", "side": "SELL", "hash": "ae22df530f6e5b053cb8a5ea5d5370d3a4724d40", "best_bid": "0.19", "best_ask": "0.43"}], "timestamp": "1769384769280", "event_type": "price_change"}}
{"_local_timestamp": "2026-01-25T23:46:09.358791+00:00", "data": {"market": "0xe0acd0255dbd9274d22d8c1b226c9a2b60bad9098507ce8e7d72dede580cd57a", "price_changes": [{"asset_id": "22106921341196818050439524942994162234430181387513131058873085228908007365669", "price": "0.01", "size": "5000", "side": "BUY", "hash": "9aa95cb36f1343ea5c60f1d5db476ba200e97e9d", "best_bid": "0.57", "best_ask": "0.81"}, {"asset_id": "2867209803492313176891970118649987905930881752970311413869425427415611673771", "price": "0.99", "size": "5000", "side": "SELL", "hash": "ae22df530f6e5b053cb8a5ea5d5370d3a4724d40", "best_bid": "0.19", "best_ask": "0.43"}], "timestamp": "1769384769280", "event_type": "price_change"}}
{"_local_timestamp": "2026-01-25T23:46:09.359197+00:00", "data": {"market": "0xe0acd0255dbd9274d22d8c1b226c9a2b60bad9098507ce8e7d72dede580cd57a", "price_changes": [{"asset_id": "22106921341196818050439524942994162234430181387513131058873085228908007365669", "price": "0.03", "size": "0", "side": "BUY", "hash": "9aa95cb36f1343ea5c60f1d5db476ba200e97e9d", "best_bid": "0.57", "best_ask": "0.81"}, {"asset_id": "2867209803492313176891970118649987905930881752970311413869425427415611673771", "price": "0.97", "size": "0", "side": "SELL", "hash": "ae22df530f6e5b053cb8a5ea5d5370d3a4724d40", "best_bid": "0.19", "best_ask": "0.43"}], "timestamp": "1769384769280", "event_type": "price_change"}}
