{"_local_timestamp": "2026-01-25T23:40:49.570138+00:00", "data": [{"market": "0x7b5c576ee07b4e95934b114634af0b8c7002cdced133e4d03db8fdb5dad7efc9", "asset_id": "58522802851851118793855155558916400893498205325121134941799318021764167337515", "timestamp": "1769384446006", "hash": "89e8dc81dc3769e502939dbd6f1101743bd765a6", "bids": [{"price": "0.01", "size": "118100"}, {"price": "0.02", "size": "15407.77"}, {"price": "0.03", "size": "500"}, {"price": "0.04", "size": "3256.69"}, {"price": "0.05", "size": "905"}, {"price": "0.06", "size": "250"}, {"price": "0.07", "size": "185.71"}, {"price": "0.08", "size": "7.2"}, {"price": "0.13", "size": "100"}, {"price": "0.14", "size": "148.57"}, {"price": "0.16", "size": "4138.89"}, {"price": "0.18", "size": "2066"}, {"price": "0.19", "size": "4972.9"}, {"price": "0.2", "size": "1919.45"}, {"price": "0.21", "size": "186.28"}], "asks": [{"price": "0.99", "size": "5114.79"}, {"price": "0.98", "size": "2200"}, {"price": "0.97", "size": "27.03"}, {"price": "0.92", "size": "1150"}, {"price": "0.91", "size": "7.34"}, {"price": "0.88", "size": "833.33"}, {"price": "0.84", "size": "200"}, {"price": "0.82", "size": "1338"}, {"price": "0.8", "size": "340"}, {"price": "0.79", "size": "100"}, {"price": "0.78", "size": "1908"}, {"price": "0.77", "size": "100"}, {"price": "0.76", "size": "108.33"}, {"price": "0.75", "size": "350"}, {"price": "0.74", "size": "7"}, {"price": "0.72", "size": "185.71"}, {"price": "0.68", "size": "62.5"}, {"price": "0.65", "size": "200"}, {"price": "0.59", "size": "160"}, {"price": "0.49", "size": "75"}, {"price": "0.36", "size": "146.45"}, {"price": "0.35", "size": "11"}, {"price": "0.32", "size": "18"}, {"price": "0.31", "size": "15.94"}, {"price": "0.3", "size": "140.57"}, {"price": "0.29", "size": "11"}, {"price": "0.27", "size": "500"}, {"price": "0.26", "size": "521"}, {"price": "0.25", "size": "700"}, {"price": "0.24", "size": "1350"}, {"price": "0.23", "size": "329.74"}], "event_type": "book", "last_trade_price": "0.210"}, {"market": "0x7b5c576ee07b4e95934b114634af0b8c7002cdced133e4d03db8fdb5dad7efc9", "asset_id": "97336036946990892589126446221607202585647626122722486163761162882902175162098", "timestamp": "1769384446006", "hash": "70e059434cd7662e342192615f19e37d3b7cbc0d", "bids": [{"price": "0.01", "size": "5114.79"}, {"price": "0.02", "size": "2200"}, {"price": "0.03", "size": "27.03"}, {"price": "0.08", "size": "1150"}, {"price": "0.09", "size": "7.34"}, {"price": "0.12", "size": "833.33"}, {"price": "0.16", "size": "200"}, {"price": "0.18", "size": "1338"}, {"price": "0.2", "size": "340"}, {"price": "0.21", "size": "100"}, {"price": "0.22", "size": "1908"}, {"price": "0.23", "size": "100"}, {"price": "0.24", "size": "108.33"}, {"price": "0.25", "size": "350"}, {"price": "0.26", "size": "7"}, {"price": "0.28", "size": "185.71"}, {"price": "0.32", "size": "62.5"}, {"price": "0.35", "size": "200"}, {"price": "0.41", "size": "160"}, {"price": "0.51", "size": "75"}, {"price": "0.64", "size": "146.45"}, {"price": "0.65", "size": "11"}, {"price": "0.68", "size": "18"}, {"price": "0.69", "size": "15.94"}, {"price": "0.7", "size": "140.57"}, {"price": "0.71", "size": "11"}, {"price": "0.73", "size": "500"}, {"price": "0.74", "size": "521"}, {"price": "0.75", "size": "700"}, {"price": "0.76", "size": "1350"}, {"price": "0.77", "size": "329.74"}], "asks": [{"price": "0.99", "size": "118100"}, {"price": "0.98", "size": "15407.77"}, {"price": "0.97", "size": "500"}, {"price": "0.96", "size": "3256.69"}, {"price": "0.95", "size": "905"}, {"price": "0.94", "size": "250"}, {"price": "0.93", "size": "185.71"}, {"price": "0.92", "size": "7.2"}, {"price": "0.87", "size": "100"}, {"price": "0.86", "size": "148.57"}, {"price": "0.84", "size": "4138.89"}, {"price": "0.82", "size": "2066"}, {"price": "0.81", "size": "4972.9"}, {"price": "0.8", "size": "1919.45"}, {"price": "0.79", "size": "186.28"}], "event_type": "book", "last_trade_price": "0.210"}]}
{"_local_timestamp": "2026-01-25T23:40:51.629146+00:00", "data": {"market": "0x7b5c576ee07b4e95934b114634af0b8c7002cdced133e4d03db8fdb5dad7efc9", "price_changes": [{"asset_id": "58522802851851118793855155558916400893498205325121134941799318021764167337515", "price": "0.05", "size": "8245", "side": "BUY", "hash": "def11e8fe9dabe304ddaacd0d518c9255ceccaca", "best_bid": "0.21", "best_ask": "0.23"}, {"asset_id": "97336036946990892589126446221607202585647626122722486163761162882902175162098", "price": "0.95", "size": "8245", "side": "SELL", "hash": "939bb44b551b10253ae592080d3d2c26b6e67543", "best_bid": "0.77", "best_ask": "0.79"}], "timestamp": "1769384451563", "event_type": "price_change"}}
{"_local_timestamp": "2026-01-25T23:40:51.629622+00:00", "data": {"market": "0x7b5c576ee07b4e95934b114634af0b8c7002cdced133e4d03db8fdb5dad7efc9", "price_changes": [{"asset_id": "58522802851851118793855155558916400893498205325121134941799318021764167337515", "price": "0.19", "size": "5072.9", "side": "BUY", "hash": "2e276cf4e00c5bdfff91d664ce70f3b79c191a07", "best_bid": "0.21", "best_ask": "0.23"}, {"asset_id": "97336036946990892589126446221607202585647626122722486163761162882902175162098", "price": "0.81", "size": "5072.9", "side": "SELL", "hash": "33fd15817e9ee26e91fa596bd8e75aa1da074d32", "best_bid": "0.77", "best_ask": "0.79"}], "timestamp": "1769384451563", "event_type": "price_change"}}
{"_local_timestamp": "2026-01-25T23:40:51.629941+00:00", "data": {"market": "0x7b5c576ee07b4e95934b114634af0b8c7002cdced133e4d03db8fdb5dad7efc9", "price_changes": [{"asset_id": "58522802851851118793855155558916400893498205325121134941799318021764167337515", "price": "0.18", "size": "2583", "side": "BUY", "hash": "15aaf50cd55a2585940a6e895b371d7ee4311129", "best_bid": "0.21", "best_ask": "0.23"}, {"asset_id": "97336036946990892589126446221607202585647626122722486163761162882902175162098", "price": "0.82", "size": "2583", "side": "SELL", "hash": "029152db4532bb24097dad3ba46503fc3d6500a5", "best_bid": "0.77", "best_ask": "0.79"}], "timestamp": "1769384451564", "event_type": "price_change"}}
{"_local_timestamp": "2026-01-25T23:40:51.630215+00:00", "data": {"market": "0x7b5c576ee07b4e95934b114634af0b8c7002cdced133e4d03db8fdb5dad7efc9", "price_changes": [{"asset_id": "58522802851851118793855155558916400893498205325121134941799318021764167337515", "price": "0.16", "size": "5287.89", "side": "BUY", "hash": "fb70bbeee25ffa7fe820dec0527e3926166925a3", "best_bid": "0.21", "best_ask": "0.23"}, {"asset_id": "97336036946990892589126446221607202585647626122722486163761162882902175162098", "price": "0.84", "size": "5287.89", "side": "SELL", "hash": "92a18aa58d0da32f6433b48656bb3db13c8df99f", "best_bid": "0.77", "best_ask": "0.79"}], "timestamp": "1769384451565", "event_type": "price_change"}}
{"_local_timestamp": "2026-01-25T23:40:58.851642+00:00", "data": {"market": "0x7b5c576ee07b4e95934b114634af0b8c7002cdced133e4d03db8fdb5dad7efc9", "price_changes": [{"asset_id": "58522802851851118793855155558916400893498205325121134941799318021764167337515", "price": "0.25", "size": "944.9", "side": "SELL", "hash": "405a30eb04fa49f5ac8ddb7a2c124321351de429", "best_bid": "0.21", "best_ask": "0.23"}, {"asset_id": "97336036946990892589126446221607202585647626122722486163761162882902175162098", "price": "0.75", "size": "944.9", "side": "BUY", "hash": "d500601c27ee53f02b15646a07ea691bd17951b0", "best_bid": "0.77", "best_ask": "0.79"}], "timestamp": "1769384458784", "event_type": "price_change"}}
{"_local_timestamp": "2026-01-25T23:41:06.516812+00:00", "data": {"market": "0x7b5c576ee07b4e95934b114634af0b8c7002cdced133e4d03db8fdb5dad7efc9", "price_changes": [{"asset_id": "58522802851851118793855155558916400893498205325121134941799318021764167337515", "price": "0.23", "size": "226.65", "side": "SELL", "hash": "213011aea0eb160ca9cec05a36f9c6d93388ba55", "best_bid": "0.21", "best_ask": "0.23"}, {"asset_id": "97336036946990892589126446221607202585647626122722486163761162882902175162098", "price": "0.77", "size": "226.65", "side": "BUY", "hash": "5c83feca48c44a5b63f413648d51f6f5edcb2cd0", "best_bid": "0.77", "best_ask": "0.79"}], "timestamp": "1769384466196", "event_type": "price_change"}}
{"_local_timestamp": "2026-01-25T23:41:06.629625+00:00", "data": {"market": "0x7b5c576ee07b4e95934b114634af0b8c7002cdced133e4d03db8fdb5dad7efc9", "price_changes": [{"asset_id": "97336036946990892589126446221607202585647626122722486163761162882902175162098", "price": "0.75", "size": "844.9", "side": "BUY", "hash": "0dd6ae1c061fb2499aa8f39e420f8a31e5520d54", "best_bid": "0.77", "best_ask": "0.79"}, {"asset_id": "58522802851851118793855155558916400893498205325121134941799318021764167337515", "price": "0.25", "size": "844.9", "side": "SELL", "hash": "eeac8c3f0786fdacc22952d3d0520884b8d274fb", "best_bid": "0.21", "best_ask": "0.23"}], "timestamp": "1769384466200", "event_type": "price_change"}}
{"_local_timestamp": "2026-01-25T23:41:08.229393+00:00", "data": {"market": "0x7b5c576ee07b4e95934b114634af0b8c7002cdced133e4d03db8fdb5dad7efc9", "price_changes": [{"asset_id": "58522802851851118793855155558916400893498205325121134941799318021764167337515", "price": "0.23", "size": "329.74", "side": "SELL", "hash": "0d5376d2bca1e40aa7542b52cb3109c17fc9aa3b", "best_bid": "0.21", "best_ask": "0.23"}, {"asset_id": "97336036946990892589126446221607202585647626122722486163761162882902175162098", "price": "0.77", "size": "329.74", "side": "BUY", "hash": "f5d768f8a3b285b2d88106fb450b9aab5434cee6", "best_bid": "0.77", "best_ask": "0.79"}], "timestamp": "1769384468159", "event_type": "price_change"}}
{"_local_timestamp": "2026-01-25T23:41:14.656313+00:00", "data": {"market": "0x7b5c576ee07b4e95934b114634af0b8c7002cdced133e4d03db8fdb5dad7efc9", "price_changes": [{"asset_id": "97336036946990892589126446221607202585647626122722486163761162882902175162098", "price": "0.22", "size": "0", "side": "BUY", "hash": "8fa94c66af47c063c4941221946b26119f61a68f", "best_bid": "0.77", "best_ask": "0.79"}, {"asset_id": "58522802851851118793855155558916400893498205325121134941799318021764167337515", "price": "0.78", "size": "0", "side": "SELL", "hash": "71fef59132b725038d1bf4a8ce91a66c93e8040e", "best_bid": "0.21", "best_ask": "0.23"}], "timestamp": "1769384474531", "event_type": "price_change"}}
{"_local_timestamp": "2026-01-25T23:41:15.107384+00:00", "data": {"market": "0x7b5c576ee07b4e95934b114634af0b8c7002cdced133e4d03db8fdb5dad7efc9", "price_changes": [{"asset_id": "58522802851851118793855155558916400893498205325121134941799318021764167337515", "price": "0.25", "size": "600", "side": "SELL", "hash": "05be7ab55883fa0b11014a8c4873871967ce38bd", "best_bid": "0.21", "best_ask": "0.23"}, {"asset_id": "97336036946990892589126446221607202585647626122722486163761162882902175162098", "price": "0.75", "size": "600", "side": "BUY", "hash": "d5a91d1845e7dd9e8a35e6386f6d627ce3deadfb", "best_bid": "0.77", "best_ask": "0.79"}], "timestamp": "1769384475033", "event_type": "price_change"}}
{"_local_timestamp": "2026-01-25T23:41:17.606822+00:00", "data": {"market": "0x7b5c576ee07b4e95934b114634af0b8c7002cdced133e4d03db8fdb5dad7efc9", "price_changes": [{"asset_id": "58522802851851118793855155558916400893498205325121134941799318021764167337515", "price": "0.25", "size": "742.51", "side": "SELL", "hash": "10b3133f6b74c75329bc54059aa087111c762a5f", "best_bid": "0.21", "best_ask": "0.23"}, {"asset_id": "97336036946990892589126446221607202585647626122722486163761162882902175162098", "price": "0.75", "size": "742.51", "side": "BUY", "hash": "8f6395a967725c01a13b4fc9a5a14cdab081d856", "best_bid": "0.77", "best_ask": "0.79"}], "timestamp": "1769384477535", "event_type": "price_change"}}
{"_local_timestamp": "2026-01-25T23:41:20.040879+00:00", "data": {"market": "0x7b5c576ee07b4e95934b114634af0b8c7002cdced133e4d03db8fdb5dad7efc9", "price_changes": [{"asset_id": "58522802851851118793855155558916400893498205325121134941799318021764167337515", "price": "0.26", "size": "623.38", "side": "SELL", "hash": "e321d8bfb45d7e314a6f7f30eb7c8a3cec4e7948", "best_bid": "0.21", "best_ask": "0.23"}, {"asset_id": "97336036946990892589126446221607202585647626122722486163761162882902175162098", "price": "0.74", "size": "623.38", "side": "BUY", "hash": "cf1c798472988e050bb1182a29ab0bee0765596e", "best_bid": "0.77", "best_ask": "0.79"}], "timestamp": "1769384479973", "event_type": "price_change"}}
{"_local_timestamp": "2026-01-25T23:41:25.963446+00:00", "data": {"market": "0x7b5c576ee07b4e95934b114634af0b8c7002cdced133e4d03db8fdb5dad7efc9", "price_changes": [{"asset_id": "58522802851851118793855155558916400893498205325121134941799318021764167337515", "price": "0.25", "size": "600", "side": "SELL", "hash": "e80ec1be9fefd4ed0d7fa938164f9f81810dfccc", "best_bid": "0.21", "best_ask": "0.23"}, {"asset_id": "97336036946990892589126446221607202585647626122722486163761162882902175162098", "price": "0.75", "size": "600", "side": "BUY", "hash": "ac2a39bb21878453221112733f275a008fe9c146", "best_bid": "0.77", "best_ask": "0.79"}], "timestamp": "1769384485885", "event_type": "price_change"}}
{"_local_timestamp": "2026-01-25T23:41:25.967517+00:00", "data": {"market": "0x7b5c576ee07b4e95934b114634af0b8c7002cdced133e4d03db8fdb5dad7efc9", "price_changes": [{"asset_id": "58522802851851118793855155558916400893498205325121134941799318021764167337515", "price": "0.26", "size": "521", "side": "SELL", "hash": "e80ec1be9fefd4ed0d7fa938164f9f81810dfccc", "best_bid": "0.21", "best_ask": "0.23"}, {"asset_id": "97336036946990892589126446221607202585647626122722486163761162882902175162098", "price": "0.74", "size": "521", "side": "BUY", "hash": "ac2a39bb21878453221112733f275a008fe9c146", "best_bid": "0.77", "best_ask": "0.79"}], "timestamp": "1769384485885", "event_type": "price_change"}}
{"_local_timestamp": "2026-01-25T23:41:38.077480+00:00", "data": {"market": "0x7b5c576ee07b4e95934b114634af0b8c7002cdced133e4d03db8fdb5dad7efc9", "price_changes": [{"asset_id": "58522802851851118793855155558916400893498205325121134941799318021764167337515", "price": "0.19", "size": "5061.9", "side": "BUY", "hash": "92f578c9081f01f3a1b50e52bf6d7f4297c1c5aa", "best_bid": "0.21", "best_ask": "0.23"}, {"asset_id": "97336036946990892589126446221607202585647626122722486163761162882902175162098", "price": "0.81", "size": "5061.9", "side": "SELL", "hash": "565819a221cb20e151da6f5679130347705418ec", "best_bid": "0.77", "best_ask": "0.79"}], "timestamp": "1769384498000", "event_type": "price_change"}}
{"_local_timestamp": "2026-01-25T23:41:39.973251+00:00", "data": {"market": "0x7b5c576ee07b4e95934b114634af0b8c7002cdced133e4d03db8fdb5dad7efc9", "price_changes": [{"asset_id": "58522802851851118793855155558916400893498205325121134941799318021764167337515", "price": "0.19", "size": "5072.9", "side": "BUY", "hash": "0d951374c6f2007459195d965d98cf95485c5aba", "best_bid": "0.21", "best_ask": "0.23"}, {"asset_id": "97336036946990892589126446221607202585647626122722486163761162882902175162098", "price": "0.81", "size": "5072.9", "side": "SELL", "hash": "029b631db9ee64d77a8642fe4eb145ca419c1ad5", "best_bid": "0.77", "best_ask": "0.79"}], "timestamp": "1769384499870", "event_type": "price_change"}}
{"_local_timestamp": "2026-01-25T23:41:48.147277+00:00", "data": {"market": "0x7b5c576ee07b4e95934b114634af0b8c7002cdced133e4d03db8fdb5dad7efc9", "price_changes": [{"asset_id": "97336036946990892589126446221607202585647626122722486163761162882902175162098", "price": "0.75", "size": "700", "side": "BUY", "hash": "57a0fd11463e4bf2c31241d82f5b3eb070e3f697", "best_bid": "0.77", "best_ask": "0.79"}, {"asset_id": "58522802851851118793855155558916400893498205325121134941799318021764167337515", "price": "0.25", "size": "700", "side": "SELL", "hash": "ec307ab01bd1cf8d75ff0042976dee4eb119bbd0", "best_bid": "0.21", "best_ask": "0.23"}], "timestamp": "1769384508056", "event_type": "price_change"}}
{"_local_timestamp": "2026-01-25T23:41:50.949888+00:00", "data": {"market": "0x7b5c576ee07b4e95934b114634af0b8c7002cdced133e4d03db8fdb5dad7efc9", "price_changes": [{"asset_id": "97336036946990892589126446221607202585647626122722486163761162882902175162098", "price": "0.23", "size": "0", "side": "BUY", "hash": "d7133afcf6561d6f0778e99cd6026cb4b77cadf9", "best_bid": "0.77", "best_ask": "0.79"}, {"asset_id": "58522802851851118793855155558916400893498205325121134941799318021764167337515", "price": "0.77", "size": "0", "side": "SELL", "hash": "45546656b15491a252297ce1448b028bb471ed67", "best_bid": "0.21", "best_ask": "0.23"}], "timestamp": "1769384510759", "event_type": "price_change"}}
{"_local_timestamp": "2026-01-25T23:41:52.734129+00:00", "data": {"market": "0x7b5c576ee07b4e95934b114634af0b8c7002cdced133e4d03db8fdb5dad7efc9", "price_changes": [{"asset_id": "97336036946990892589126446221607202585647626122722486163761162882902175162098", "price": "0.25", "size": "450", "side": "BUY", "hash": "4a04ec9c559da4b0a04a13c6f9d1289b995a7bd9", "best_bid": "0.77", "best_ask": "0.79"}, {"asset_id": "58522802851851118793855155558916400893498205325121134941799318021764167337515", "price": "0.75", "size": "450", "side": "SELL", "hash": "4a1aa7eaec01fc4834ca202d667167a226f15675", "best_bid": "0.21", "best_ask": "0.23"}], "timestamp": "1769384511769", "event_type": "price_change"}}
{"_local_timestamp": "2026-01-25T23:41:56.015424+00:00", "data": {"market": "0x7b5c576ee07b4e95934b114634af0b8c7002cdced133e4d03db8fdb5dad7efc9", "price_changes": [{"asset_id": "58522802851851118793855155558916400893498205325121134941799318021764167337515", "price": "0.26", "size": "765.9", "side": "SELL", "hash": "5c1452d8b0c60b0f87668c3a081250b20cf5789e", "best_bid": "0.21", "best_ask": "0.23"}, {"asset_id": "97336036946990892589126446221607202585647626122722486163761162882902175162098", "price": "0.74", "size": "765.9", "side": "BUY", "hash": "6f5ad6daf767e33acf8e7790db2496f2f4062ad6", "best_bid": "0.77", "best_ask": "0.79"}], "timestamp": "1769384515944", "event_type": "price_change"}}
{"_local_timestamp": "2026-01-25T23:42:06.608104+00:00", "data": {"market": "0x7b5c576ee07b4e95934b114634af0b8c7002cdced133e4d03db8fdb5dad7efc9", "price_changes": [{"asset_id": "97336036946990892589126446221607202585647626122722486163761162882902175162098", "price": "0.21", "size": "2098", "side": "BUY", "hash": "8671843871831a27919515b7b2983258cd26afea", "best_bid": "0.77", "best_ask": "0.79"}, {"asset_id": "58522802851851118793855155558916400893498205325121134941799318021764167337515", "price": "0.79", "size": "2098", "side": "SELL", "hash": "5916f77c3255f6677451c35aeece0f172591c91d", "best_bid": "0.21", "best_ask": "0.23"}], "timestamp": "1769384526536", "event_type": "price_change"}}
{"_local_timestamp": "2026-01-25T23:42:24.739497+00:00", "data": {"market": "0x7b5c576ee07b4e95934b114634af0b8c7002cdced133e4d03db8fdb5dad7efc9", "price_changes": [{"asset_id": "97336036946990892589126446221607202585647626122722486163761162882902175162098", "price": "0.21", "size": "2048", "side": "BUY", "hash": "ae8e13b063876c92b3a3908f6c759c08e482e964", "best_bid": "0.77", "best_ask": "0.79"}, {"asset_id": "58522802851851118793855155558916400893498205325121134941799318021764167337515", "price": "0.79", "size": "2048", "side": "SELL", "hash": "62c95e28bc8a052eb4ccbb3ff6a94fec4beb71bb", "best_bid": "0.21", "best_ask": "0.23"}], "timestamp": "1769384544486", "event_type": "price_change"}}
{"_local_timestamp": "2026-01-25T23:42:25.156758+00:00", "data": {"market": "0x7b5c576ee07b4e95934b114634af0b8c7002cdced133e4d03db8fdb5dad7efc9", "price_changes": [{"asset_id": "97336036946990892589126446221607202585647626122722486163761162882902175162098", "price": "0.22", "size": "50", "side": "BUY", "hash": "87a1a53781ee624b90eb768c16b5b49df87ec635", "best_bid": "0.77", "best_ask": "0.79"}, {"asset_id": "58522802851851118793855155558916400893498205325121134941799318021764167337515", "price": "0.78", "size": "50", "side": "SELL", "hash": "f1af17ec200cbf03e468318cb3912c8181bd9190", "best_bid": "0.21", "best_ask": "0.23"}], "timestamp": "1769384544927", "event_type": "price_change"}}
{"_local_timestamp": "2026-01-25T23:42:45.417414+00:00", "data": {"market": "0x7b5c576ee07b4e95934b114634af0b8c7002cdced133e4d03db8fdb5dad7efc9", "price_changes": [{"asset_id": "97336036946990892589126446221607202585647626122722486163761162882902175162098", "price": "0.21", "size": "1998", "side": "BUY", "hash": "1bc225e6101465dce2d1d4e5403b84013c6d8dee", "best_bid": "0.77", "best_ask": "0.79"}, {"asset_id": "58522802851851118793855155558916400893498205325121134941799318021764167337515", "price": "0.79", "size": "1998", "side": "SELL", "hash": "777a8d67614452993ccde024c4a485eae7dae778", "best_bid": "0.21", "best_ask": "0.23"}], "timestamp": "1769384565215", "event_type": "price_change"}}
{"_local_timestamp": "2026-01-25T23:42:45.751776+00:00", "data": {"market": "0x7b5c576ee07b4e95934b114634af0b8c7002cdced133e4d03db8fdb5dad7efc9", "price_changes": [{"asset_id": "97336036946990892589126446221607202585647626122722486163761162882902175162098", "price": "0.22", "size": "100", "side": "BUY", "hash": "23f48caa3156b1a133250aafa8d9d331bd80d523", "best_bid": "0.77", "best_ask": "0.79"}, {"asset_id": "58522802851851118793855155558916400893498205325121134941799318021764167337515", "price": "0.78", "size": "100", "side": "SELL", "hash": "31d901afc7b7a4aee822178acfc5848f661b75cc", "best_bid": "0.21", "best_ask": "0.23"}], "timestamp": "1769384565589", "event_type": "price_change"}}
{"_local_timestamp": "2026-01-25T23:42:47.259741+00:00", "data": {"market": "0x7b5c576ee07b4e95934b114634af0b8c7002cdced133e4d03db8fdb5dad7efc9", "price_changes": [{"asset_id": "97336036946990892589126446221607202585647626122722486163761162882902175162098", "price": "0.21", "size": "0", "side": "BUY", "hash": "d774391274894c10193a9f083659ff4e4c92d361", "best_bid": "0.77", "best_ask": "0.79"}, {"asset_id": "58522802851851118793855155558916400893498205325121134941799318021764167337515", "price": "0.79", "size": "0", "side": "SELL", "hash": "15029234327ee451aa783727b15d1c12f167cc0a", "best_bid": "0.21", "best_ask": "0.23"}], "timestamp": "1769384566988", "event_type": "price_change"}}
{"_local_timestamp": "2026-01-25T23:42:58.843359+00:00", "data": {"market": "0x7b5c576ee07b4e95934b114634af0b8c7002cdced133e4d03db8fdb5dad7efc9", "price_changes": [{"asset_id": "97336036946990892589126446221607202585647626122722486163761162882902175162098", "price": "0.25", "size": "350", "side": "BUY", "hash": "315844d4019932b824e081fdf6ba0b90c153d114", "best_bid": "0.77", "best_ask": "0.79"}, {"asset_id": "58522802851851118793855155558916400893498205325121134941799318021764167337515", "price": "0.75", "size": "350", "side": "SELL", "hash": "b9b8f8cdaf8ea2ff224be7ec05239a2972400f89", "best_bid": "0.21", "best_ask": "0.23"}], "timestamp": "1769384578722", "event_type": "price_change"}}
{"_local_timestamp": "2026-01-25T23:42:59.124282+00:00", "data": {"market": "0x7b5c576ee07b4e95934b114634af0b8c7002cdced133e4d03db8fdb5dad7efc9", "price_changes": [{"asset_id": "97336036946990892589126446221607202585647626122722486163761162882902175162098", "price": "0.21", "size": "100", "side": "BUY", "hash": "c2276a32cde5d2706af3d0511481fbf57b7dd722", "best_bid": "0.77", "best_ask": "0.79"}, {"asset_id": "58522802851851118793855155558916400893498205325121134941799318021764167337515", "price": "0.79", "size": "100", "side": "SELL", "hash": "eabc16fdd8578ef1f12287e3ee071cbe07e74004", "best_bid": "0.21", "best_ask": "0.23"}], "timestamp": "1769384578985", "event_type": "price_change"}}
{"_local_timestamp": "2026-01-25T23:43:34.207277+00:00", "data": {"market": "0x7b5c576ee07b4e95934b114634af0b8c7002cdced133e4d03db8fdb5dad7efc9", "price_changes": [{"asset_id": "97336036946990892589126446221607202585647626122722486163761162882902175162098", "price": "0.22", "size": "2008", "side": "BUY", "hash": "ee11bf7977c1a16327267c74218d9bfc2dcee255", "best_bid": "0.77", "best_ask": "0.79"}, {"asset_id": "58522802851851118793855155558916400893498205325121134941799318021764167337515", "price": "0.78", "size": "2008", "side": "SELL", "hash": "8488949c008b06910b4009387feee9d4d2b7064b", "best_bid": "0.21", "best_ask": "0.23"}], "timestamp": "1769384614106", "event_type": "price_change"}}
{"_local_timestamp": "2026-01-25T23:43:38.541946+00:00", "data": {"market": "0x7b5c576ee07b4e95934b114634af0b8c7002cdced133e4d03db8fdb5dad7efc9", "price_changes": [{"asset_id": "97336036946990892589126446221607202585647626122722486163761162882902175162098", "price": "0.21", "size": "0", "side": "BUY", "hash": "745b75dd0cb9402487c43697741d5d755efd9f0a", "best_bid": "0.77", "best_ask": "0.79"}, {"asset_id": "58522802851851118793855155558916400893498205325121134941799318021764167337515", "price": "0.79", "size": "0", "side": "SELL", "hash": "62d2d7f8d71f4782fb16973a109ec4f746e833e8", "best_bid": "0.21", "best_ask": "0.23"}], "timestamp": "1769384618452", "event_type": "price_change"}}
{"_local_timestamp": "2026-01-25T23:43:38.833137+00:00", "data": {"market": "0x7b5c576ee07b4e95934b114634af0b8c7002cdced133e4d03db8fdb5dad7efc9", "price_changes": [{"asset_id": "97336036946990892589126446221607202585647626122722486163761162882902175162098", "price": "0.25", "size": "450", "side": "BUY", "hash": "897162ca6322e074b6ce0bd8a146e6ed57d9d198", "best_bid": "0.77", "best_ask": "0.79"}, {"asset_id": "58522802851851118793855155558916400893498205325121134941799318021764167337515", "price": "0.75", "size": "450", "side": "SELL", "hash": "bdd72241088b55eb08da5a44e3874f908b2226d4", "best_bid": "0.21", "best_ask": "0.23"}], "timestamp": "1769384618723", "event_type": "price_change"}}
{"_local_timestamp": "2026-01-25T23:44:08.674329+00:00", "data": {"market": "0x7b5c576ee07b4e95934b114634af0b8c7002cdced133e4d03db8fdb5dad7efc9", "price_changes": [{"asset_id": "97336036946990892589126446221607202585647626122722486163761162882902175162098", "price": "0.22", "size": "1958", "side": "BUY", "hash": "4c6beff341e812459a9712d440f3e78a05b9717f", "best_bid": "0.77", "best_ask": "0.79"}, {"asset_id": "58522802851851118793855155558916400893498205325121134941799318021764167337515", "price": "0.78", "size": "1958", "side": "SELL", "hash": "d3d799434a3be3102c99249f48b9f55c05e58398", "best_bid": "0.21", "best_ask": "0.23"}], "timestamp": "1769384648426", "event_type": "price_change"}}
{"_local_timestamp": "2026-01-25T23:44:09.089245+00:00", "data": {"market": "0x7b5c576ee07b4e95934b114634af0b8c7002cdced133e4d03db8fdb5dad7efc9", "price_changes": [{"asset_id": "97336036946990892589126446221607202585647626122722486163761162882902175162098", "price": "0.21", "size": "50", "side": "BUY", "hash": "6ee79a8a708fc5bfddc247667cd2d3c7ce5aa8ea", "best_bid": "0.77", "best_ask": "0.79"}, {"asset_id": "58522802851851118793855155558916400893498205325121134941799318021764167337515", "price": "0.79", "size": "50", "side": "SELL", "hash": "2c51549f988ea7235905bf8f22c8ccfa96b44c14", "best_bid": "0.21", "best_ask": "0.23"}], "timestamp": "1769384648777", "event_type": "price_change"}}
{"_local_timestamp": "2026-01-25T23:44:18.018225+00:00", "data": {"market": "0x7b5c576ee07b4e95934b114634af0b8c7002cdced133e4d03db8fdb5dad7efc9", "price_changes": [{"asset_id": "97336036946990892589126446221607202585647626122722486163761162882902175162098", "price": "0.25", "size": "350", "side": "BUY", "hash": "3eb2117814da08f1c8b54ffb9f08971d08323fed", "best_bid": "0.77", "best_ask": "0.79"}, {"asset_id": "58522802851851118793855155558916400893498205325121134941799318021764167337515", "price": "0.75", "size": "350", "side": "SELL", "hash": "611446678e3536822a096d83eeb26109d1088b89", "best_bid": "0.21", "best_ask": "0.23"}], "timestamp": "1769384657934", "event_type": "price_change"}}
{"_local_timestamp": "2026-01-25T23:44:18.268855+00:00", "data": {"market": "0x7b5c576ee07b4e95934b114634af0b8c7002cdced133e4d03db8fdb5dad7efc9", "price_changes": [{"asset_id": "97336036946990892589126446221607202585647626122722486163761162882902175162098", "price": "0.22", "size": "2058", "side": "BUY", "hash": "ad8b398f9c9fcb4c0748ce5da9b3fd629f123bfa", "best_bid": "0.77", "best_ask": "0.79"}, {"asset_id": "58522802851851118793855155558916400893498205325121134941799318021764167337515", "price": "0.78", "size": "2058", "side": "SELL", "hash": "fc3442dbf79dcdac04b35a41837278a834eff3ad", "best_bid": "0.21", "best_ask": "0.23"}], "timestamp": "1769384658180", "event_type": "price_change"}}
{"_local_timestamp": "2026-01-25T23:44:32.439561+00:00", "data": {"market": "0x7b5c576ee07b4e95934b114634af0b8c7002cdced133e4d03db8fdb5dad7efc9", "price_changes": [{"asset_id": "97336036946990892589126446221607202585647626122722486163761162882902175162098", "price": "0.22", "size": "150", "side": "BUY", "hash": "304c0a93066fea04769488988a06fb5e05437af2", "best_bid": "0.77", "best_ask": "0.79"}, {"asset_id": "58522802851851118793855155558916400893498205325121134941799318021764167337515", "price": "0.78", "size": "150", "side": "SELL", "hash": "9a7743078e7618387176194f085d34d788d49f79", "best_bid": "0.21", "best_ask": "0.23"}], "timestamp": "1769384672295", "event_type": "price_change"}}
{"_local_timestamp": "2026-01-25T23:44:56.091876+00:00", "data": {"market": "0x7b5c576ee07b4e95934b114634af0b8c7002cdced133e4d03db8fdb5dad7efc9", "price_changes": [{"asset_id": "58522802851851118793855155558916400893498205325121134941799318021764167337515", "price": "0.05", "size": "8045", "side": "BUY", "hash": "0c09b6c5fdccf0d0b646cf1c58c58ff25653ab1d", "best_bid": "0.21", "best_ask": "0.23"}, {"asset_id": "97336036946990892589126446221607202585647626122722486163761162882902175162098", "price": "0.95", "size": "8045", "side": "SELL", "hash": "bf036338ece03d27b44524a815cf375f8345ea52", "best_bid": "0.77", "best_ask": "0.79"}], "timestamp": "1769384696002", "event_type": "price_change"}}
{"_local_timestamp": "2026-01-25T23:44:56.101724+00:00", "data": {"market": "0x7b5c576ee07b4e95934b114634af0b8c7002cdced133e4d03db8fdb5dad7efc9", "price_changes": [{"asset_id": "58522802851851118793855155558916400893498205325121134941799318021764167337515", "price": "0.16", "size": "5261.89", "side": "BUY", "hash": "4fd68c92d48d9f5ab673b0ac43f97417ca5f9b73", "best_bid": "0.21", "best_ask": "0.23"}, {"asset_id": "97336036946990892589126446221607202585647626122722486163761162882902175162098", "price": "0.84", "size": "5261.89", "side": "SELL", "hash": "1c710d1b39d80291c0f2f7e5fefc1b8f2a4a24a7", "best_bid": "0.77", "best_ask": "0.79"}], "timestamp": "1769384696006", "event_type": "price_change"}}
{"_local_timestamp": "2026-01-25T23:44:56.102399+00:00", "data": {"market": "0x7b5c576ee07b4e95934b114634af0b8c7002cdced133e4d03db8fdb5dad7efc9", "price_changes": [{"asset_id": "58522802851851118793855155558916400893498205325121134941799318021764167337515", "price": "0.18", "size": "2572", "side": "BUY", "hash": "2daa5fc499f9eaf00494644d272fc2af56f17393", "best_bid": "0.21", "best_ask": "0.23"}, {"asset_id": "97336036946990892589126446221607202585647626122722486163761162882902175162098", "price": "0.82", "size": "2572", "side": "SELL", "hash": "cc496e4464c400c30fc722025f932104be79de56", "best_bid": "0.77", "best_ask": "0.79"}], "timestamp": "1769384696007", "event_type": "price_change"}}
{"_local_timestamp": "2026-01-25T23:44:57.831254+00:00", "data": {"market": "0x7b5c576ee07b4e95934b114634af0b8c7002cdced133e4d03db8fdb5dad7efc9", "price_changes": [{"asset_id": "97336036946990892589126446221607202585647626122722486163761162882902175162098", "price": "0.22", "size": "100", "side": "BUY", "hash": "f48d52168808ba2faadbcfbad94a7e3b765eb561", "best_bid": "0.77", "best_ask": "0.79"}, {"asset_id": "58522802851851118793855155558916400893498205325121134941799318021764167337515", "price": "0.78", "size": "100", "side": "SELL", "hash": "05da9f0b3df0c8a6c53a7ec8ddd75e8a29ae2363", "best_bid": "0.21", "best_ask": "0.23"}], "timestamp": "1769384697730", "event_type": "price_change"}}
{"_local_timestamp": "2026-01-25T23:44:58.282320+00:00", "data": {"market": "0x7b5c576ee07b4e95934b114634af0b8c7002cdced133e4d03db8fdb5dad7efc9", "price_changes": [{"asset_id": "97336036946990892589126446221607202585647626122722486163761162882902175162098", "price": "0.25", "size": "400", "side": "BUY", "hash": "3ca3b5dd7a13439542a5ab97cffe268a0c0f7b04", "best_bid": "0.77", "best_ask": "0.79"}, {"asset_id": "58522802851851118793855155558916400893498205325121134941799318021764167337515", "price": "0.75", "size": "400", "side": "SELL", "hash": "23765c84ebf7571e2c6257d089b6fe2e6348545c", "best_bid": "0.21", "best_ask": "0.23"}], "timestamp": "1769384698212", "event_type": "price_change"}}
{"_local_timestamp": "2026-01-25T23:45:04.791748+00:00", "data": {"market": "0x7b5c576ee07b4e95934b114634af0b8c7002cdced133e4d03db8fdb5dad7efc9", "price_changes": [{"asset_id": "58522802851851118793855155558916400893498205325121134941799318021764167337515", "price": "0.16", "size": "5287.89", "side": "BUY", "hash": "7fa68d72c381d7597705111297896bb436aebedc", "best_bid": "0.21", "best_ask": "0.23"}, {"asset_id": "97336036946990892589126446221607202585647626122722486163761162882902175162098", "price": "0.84", "size": "5287.89", "side": "SELL", "hash": "2019d2d18961386f421a4f088b710edda7605eb8", "best_bid": "0.77", "best_ask": "0.79"}], "timestamp": "1769384704727", "event_type": "price_change"}}
{"_local_timestamp": "2026-01-25T23:45:04.796263+00:00", "data": {"market": "0x7b5c576ee07b4e95934b114634af0b8c7002cdced133e4d03db8fdb5dad7efc9", "price_changes": [{"asset_id": "58522802851851118793855155558916400893498205325121134941799318021764167337515", "price": "0.18", "size": "2583", "side": "BUY", "hash": "3582aa3407be67453c5104ac25c83348b21c84ea", "best_bid": "0.21", "best_ask": "0.23"}, {"asset_id": "97336036946990892589126446221607202585647626122722486163761162882902175162098", "price": "0.82", "size": "2583", "side": "SELL", "hash": "616d06c74776156c5cdb7727db57d369a2dad442", "best_bid": "0.77", "best_ask": "0.79"}], "timestamp": "1769384704728", "event_type": "price_change"}}
{"_local_timestamp": "2026-01-25T23:45:04.796675+00:00", "data": {"market": "0x7b5c576ee07b4e95934b114634af0b8c7002cdced133e4d03db8fdb5dad7efc9", "price_changes": [{"asset_id": "58522802851851118793855155558916400893498205325121134941799318021764167337515", "price": "0.05", "size": "8245", "side": "BUY", "hash": "fe5fea8006c5633b0a9495c1cd1bb2b8c2761ae0", "best_bid": "0.21", "best_ask": "0.23"}, {"asset_id": "97336036946990892589126446221607202585647626122722486163761162882902175162098", "price": "0.95", "size": "8245", "side": "SELL", "hash": "71c2c49154f2a28b4c8520c6647ddf59e8892de2", "best_bid": "0.77", "best_ask": "0.79"}], "timestamp": "1769384704729", "event_type": "price_change"}}
{"_local_timestamp": "2026-01-25T23:45:21.178500+00:00", "data": {"market": "0x7b5c576ee07b4e95934b114634af0b8c7002cdced133e4d03db8fdb5dad7efc9", "price_changes": [{"asset_id": "97336036946990892589126446221607202585647626122722486163761162882902175162098", "price": "0.21", "size": "2048", "side": "BUY", "hash": "db722ed3e03ef5703dcfe1fa3be83f8bdd9ff361", "best_bid": "0.77", "best_ask": "0.79"}, {"asset_id": "58522802851851118793855155558916400893498205325121134941799318021764167337515", "price": "0.79", "size": "2048", "side": "SELL", "hash": "90dce7b3316380f69c15af9742cf384f3748bbc8", "best_bid": "0.21", "best_ask": "0.23"}], "timestamp": "1769384721110", "event_type": "price_change"}}
{"_local_timestamp": "2026-01-25T23:45:38.930644+00:00", "data": {"market": "0x7b5c576ee07b4e95934b114634af0b8c7002cdced133e4d03db8fdb5dad7efc9", "price_changes": [{"asset_id": "97336036946990892589126446221607202585647626122722486163761162882902175162098", "price": "0.22", "size": "0", "side": "BUY", "hash": "e27a452531d2218869bc78e77bb1cf05babfaea2", "best_bid": "0.77", "best_ask": "0.79"}, {"asset_id": "58522802851851118793855155558916400893498205325121134941799318021764167337515", "price": "0.78", "size": "0", "side": "SELL", "hash": "cf177ee202465d353b2b4386dbe386fc0ad110be", "best_bid": "0.21", "best_ask": "0.23"}], "timestamp": "1769384738820", "event_type": "price_change"}}
{"_local_timestamp": "2026-01-25T23:45:39.213169+00:00", "data": {"market": "0x7b5c576ee07b4e95934b114634af0b8c7002cdced133e4d03db8fdb5dad7efc9", "price_changes": [{"asset_id": "97336036946990892589126446221607202585647626122722486163761162882902175162098", "price": "0.25", "size": "500", "side": "BUY", "hash": "9511c95bd6e0e029cc4263e840c840f26685c873", "best_bid": "0.77", "best_ask": "0.79"}, {"asset_id": "58522802851851118793855155558916400893498205325121134941799318021764167337515", "price": "0.75", "size": "500", "side": "SELL", "hash": "a852cbe5c3abb57ae47bdf27472e26e450299233", "best_bid": "0.21", "best_ask": "0.23"}], "timestamp": "1769384739078", "event_type": "price_change"}}
{"_local_timestamp": "2026-01-25T23:45:53.185249+00:00", "data": {"market": "0x7b5c576ee07b4e95934b114634af0b8c7002cdced133e4d03db8fdb5dad7efc9", "price_changes": [{"asset_id": "97336036946990892589126446221607202585647626122722486163761162882902175162098", "price": "0.21", "size": "1998", "side": "BUY", "hash": "452614cbd370e7471ab506aa5de5861b407d0005", "best_bid": "0.77", "best_ask": "0.79"}, {"asset_id": "58522802851851118793855155558916400893498205325121134941799318021764167337515", "price": "0.79", "size": "1998", "side": "SELL", "hash": "5283151bc231bc88f5a655311fab5f2c5cd2a324", "best_bid": "0.21", "best_ask": "0.23"}], "timestamp": "1769384753010", "event_type": "price_change"}}
{"_local_timestamp": "2026-01-25T23:45:53.708531+00:00", "data": {"market": "0x7b5c576ee07b4e95934b114634af0b8c7002cdced133e4d03db8fdb5dad7efc9", "price_changes": [{"asset_id": "97336036946990892589126446221607202585647626122722486163761162882902175162098", "price": "0.22", "size": "50", "side": "BUY", "hash": "4efa486db434e6bc996ed29325634a339719e78c", "best_bid": "0.77", "best_ask": "0.79"}, {"asset_id": "58522802851851118793855155558916400893498205325121134941799318021764167337515", "price": "0.78", "size": "50", "side": "SELL", "hash": "7038774ce8e076363d21f069860845171317fe77", "best_bid": "0.21", "best_ask": "0.23"}], "timestamp": "1769384753531", "event_type": "price_change"}}
{"_local_timestamp": "2026-01-25T23:45:55.529222+00:00", "data": {"market": "0x7b5c576ee07b4e95934b114634af0b8c7002cdced133e4d03db8fdb5dad7efc9", "price_changes": [{"asset_id": "58522802851851118793855155558916400893498205325121134941799318021764167337515", "price": "0.26", "size": "521", "side": "SELL", "hash": "aeefb2a4f676b7ed9c1eb66e13daebe772b8efd1", "best_bid": "0.21", "best_ask": "0.23"}, {"asset_id": "97336036946990892589126446221607202585647626122722486163761162882902175162098", "price": "0.74", "size": "521", "side": "BUY", "hash": "84dbd77520d76247040f236ce1954572e63f7a14", "best_bid": "0.77", "best_ask": "0.79"}], "timestamp": "1769384755462", "event_type": "price_change"}}
{"_local_timestamp": "2026-01-25T23:45:59.752139+00:00", "data": {"market": "0x7b5c576ee07b4e95934b114634af0b8c7002cdced133e4d03db8fdb5dad7efc9", "price_changes": [{"asset_id": "58522802851851118793855155558916400893498205325121134941799318021764167337515", "price": "0.25", "size": "944.9", "side": "SELL", "hash": "449863ee744957214b11ccca65b3099b64e44929", "best_bid": "0.21", "best_ask": "0.23"}, {"asset_id": "97336036946990892589126446221607202585647626122722486163761162882902175162098", "price": "0.75", "size": "944.9", "side": "BUY", "hash": "7ae59dbdeacb8fbe01fca617b970003eabb9e430", "best_bid": "0.77", "best_ask": "0.79"}], "timestamp": "1769384759672", "event_type": "price_change"}}
{"_local_timestamp": "2026-01-25T23:46:10.586357+00:00", "data": {"market": "0x7b5c576ee07b4e95934b114634af0b8c7002cdced133e4d03db8fdb5dad7efc9", "price_changes": [{"asset_id": "97336036946990892589126446221607202585647626122722486163761162882902175162098", "price": "0.21", "size": "0", "side": "BUY", "hash": "50a42cf3b2cc17c8376b2dcd1ab9ef921fe12133", "best_bid": "0.77", "best_ask": "0.79"}, {"asset_id": "58522802851851118793855155558916400893498205325121134941799318021764167337515", "price": "0.79", "size": "0", "side": "SELL", "hash": "0779ac812288c4f75a651cf6a203e37d5139495a", "best_bid": "0.21", "best_ask": "0.23"}], "timestamp": "1769384770459", "event_type": "price_change"}}
{"_local_timestamp": "2026-01-25T23:46:17.457679+00:00", "data": {"market": "0x7b5c576ee07b4e95934b114634af0b8c7002cdced133e4d03db8fdb5dad7efc9", "price_changes": [{"asset_id": "97336036946990892589126446221607202585647626122722486163761162882902175162098", "price": "0.25", "size": "400", "side": "BUY", "hash": "5ec19f8b70140089149a9256c9aee7d7df711797", "best_bid": "0.77", "best_ask": "0.79"}, {"asset_id": "58522802851851118793855155558916400893498205325121134941799318021764167337515", "price": "0.75", "size": "400", "side": "SELL", "hash": "c792a5a06df3d6a2c3c19268c73312bf07fd29f0", "best_bid": "0.21", "best_ask": "0.23"}], "timestamp": "1769384777374", "event_type": "price_change"}}
{"_local_timestamp": "2026-01-25T23:46:17.729126+00:00", "data": {"market": "0x7b5c576ee07b4e95934b114634af0b8c7002cdced133e4d03db8fdb5dad7efc9", "price_changes": [{"asset_id": "97336036946990892589126446221607202585647626122722486163761162882902175162098", "price": "0.21", "size": "100", "side": "BUY", "hash": "23abff3af741f22327a9f56f983f9371c7dcefa6", "best_bid": "0.77", "best_ask": "0.79"}, {"asset_id": "58522802851851118793855155558916400893498205325121134941799318021764167337515", "price": "0.79", "size": "100", "side": "SELL", "hash": "832779694cd690f054e88aa57a37d405fd5de700", "best_bid": "0.21", "best_ask": "0.23"}], "timestamp": "1769384777645", "event_type": "price_change"}}
{"_local_timestamp": "2026-01-25T23:46:35.083141+00:00", "data": {"market": "0x7b5c576ee07b4e95934b114634af0b8c7002cdced133e4d03db8fdb5dad7efc9", "price_changes": [{"asset_id": "58522802851851118793855155558916400893498205325121134941799318021764167337515", "price": "0.19", "size": "5067.9", "side": "BUY", "hash": "bf51bc8fa06f27457f184e81c1dfdec07bd3bc44", "best_bid": "0.21", "best_ask": "0.23"}, {"asset_id": "97336036946990892589126446221607202585647626122722486163761162882902175162098", "price": "0.81", "size": "5067.9", "side": "SELL", "hash": "629a6f359e13164182e620458725feb78e860f3a", "best_bid": "0.77", "best_ask": "0.79"}], "timestamp": "1769384795000", "event_type": "price_change"}}
{"_local_timestamp": "2026-01-25T23:46:35.103041+00:00", "data": {"market": "0x7b5c576ee07b4e95934b114634af0b8c7002cdced133e4d03db8fdb5dad7efc9", "price_changes": [{"asset_id": "58522802851851118793855155558916400893498205325121134941799318021764167337515", "price": "0.18", "size": "2561", "side": "BUY", "hash": "0a3e01fe2a793fbc1b3f69cba9325b8c88078242", "best_bid": "0.21", "best_ask": "0.23"}, {"asset_id": "97336036946990892589126446221607202585647626122722486163761162882902175162098", "price": "0.82", "size": "2561", "side": "SELL", "hash": "86c29dec13064497a602c4b09846f13d624c566d", "best_bid": "0.77", "best_ask": "0.79"}], "timestamp": "1769384795001", "event_type": "price_change"}}
{"_local_timestamp": "2026-01-25T23:46:35.107068+00:00", "data": {"market": "0x7b5c576ee07b4e95934b114634af0b8c7002cdced133e4d03db8fdb5dad7efc9", "price_changes": [{"asset_id": "58522802851851118793855155558916400893498205325121134941799318021764167337515", "price": "0.16", "size": "5232.89", "side": "BUY", "hash": "7a42b822aecb18f1e93f422c048788777ca496df", "best_bid": "0.21", "best_ask": "0.23"}, {"asset_id": "97336036946990892589126446221607202585647626122722486163761162882902175162098", "price": "0.84", "size": "5232.89", "side": "SELL", "hash": "f1a188c0d2d010a28408a11e20fec92f67540315", "best_bid": "0.77", "best_ask": "0.79"}], "timestamp": "1769384795004", "event_type": "price_change"}}
{"_local_timestamp": "2026-01-25T23:46:35.107473+00:00", "data": {"market": "0x7b5c576ee07b4e95934b114634af0b8c7002cdced133e4d03db8fdb5dad7efc9", "price_changes": [{"asset_id": "58522802851851118793855155558916400893498205325121134941799318021764167337515", "price": "0.05", "size": "7885", "side": "BUY", "hash": "3efa5497c5590ee743bb7ec1ace2cb13fa4376ea", "best_bid": "0.21", "best_ask": "0.23"}, {"asset_id": "97336036946990892589126446221607202585647626122722486163761162882902175162098", "price": "0.95", "size": "7885", "side": "SELL", "hash": "acf26e23077a56db164d3a08ce14bd5daf0a6fc1", "best_bid": "0.77", "best_ask": "0.79"}], "timestamp": "1769384795005", "event_type": "price_change"}}
{"_local_timestamp": "2026-01-25T23:46:36.626890+00:00", "data": {"market": "0x7b5c576ee07b4e95934b114634af0b8c7002cdced133e4d03db8fdb5dad7efc9", "price_changes": [{"asset_id": "58522802851851118793855155558916400893498205325121134941799318021764167337515", "price": "0.25", "size": "700", "side": "SELL", "hash": "49f5b50cc533e6712d599abd46025881918d7a0a", "best_bid": "0.21", "best_ask": "0.23"}, {"asset_id": "97336036946990892589126446221607202585647626122722486163761162882902175162098", "price": "0.75", "size": "700", "side": "BUY", "hash": "7dc53ec31a8b70eb7aff20b10b00eb8f94b51471", "best_bid": "0.77", "best_ask": "0.79"}], "timestamp": "1769384796552", "event_type": "price_change"}}
{"_local_timestamp": "2026-01-25T23:46:38.755086+00:00", "data": {"market": "0x7b5c576ee07b4e95934b114634af0b8c7002cdced133e4d03db8fdb5dad7efc9", "price_changes": [{"asset_id": "58522802851851118793855155558916400893498205325121134941799318021764167337515", "price": "0.19", "size": "5072.9", "side": "BUY", "hash": "767684d018c642c219135dd18c03172a427b43e6", "best_bid": "0.21", "best_ask": "0.23"}, {"asset_id": "97336036946990892589126446221607202585647626122722486163761162882902175162098", "price": "0.81", "size": "5072.9", "side": "SELL", "hash": "17cdf369f67e27a11ed9614a2b1d8c2f99689f2c", "best_bid": "0.77", "best_ask": "0.79"}], "timestamp": "1769384798683", "event_type": "price_change"}}
{"_local_timestamp": "2026-01-25T23:46:38.755612+00:00", "data": {"market": "0x7b5c576ee07b4e95934b114634af0b8c7002cdced133e4d03db8fdb5dad7efc9", "price_changes": [{"asset_id": "58522802851851118793855155558916400893498205325121134941799318021764167337515", "price": "0.16", "size": "5287.89", "side": "BUY", "hash": "a6de0b9507a1c94fa58f112a307dfbd8292c5317", "best_bid": "0.21", "best_ask": "0.23"}, {"asset_id": "97336036946990892589126446221607202585647626122722486163761162882902175162098", "price": "0.84", "size": "5287.89", "side": "SELL", "hash": "98f8c845099ce9eb8e60f8d847fa02c151deedc0", "best_bid": "0.77", "best_ask": "0.79"}], "timestamp": "1769384798684", "event_type": "price_change"}}
{"_local_timestamp": "2026-01-25T23:46:38.764707+00:00", "data": {"market": "0x7b5c576ee07b4e95934b114634af0b8c7002cdced133e4d03db8fdb5dad7efc9", "price_changes": [{"asset_id": "58522802851851118793855155558916400893498205325121134941799318021764167337515", "price": "0.18", "size": "2583", "side": "BUY", "hash": "2a920cdf0327337962cb670d54684bb3c43ac269", "best_bid": "0.21", "best_ask": "0.23"}, {"asset_id": "97336036946990892589126446221607202585647626122722486163761162882902175162098", "price": "0.82", "size": "2583", "side": "SELL", "hash": "d97a17529c316e0ddc5833de923546ea38b05bc2", "best_bid": "0.77", "best_ask": "0.79"}], "timestamp": "1769384798685", "event_type": "price_change"}}
{"_local_timestamp": "2026-01-25T23:46:38.765200+00:00", "data": {"market": "0x7b5c576ee07b4e95934b114634af0b8c7002cdced133e4d03db8fdb5dad7efc9", "price_changes": [{"asset_id": "58522802851851118793855155558916400893498205325121134941799318021764167337515", "price": "0.05", "size": "8245", "side": "BUY", "hash": "f32c0c3eeddcc8778078341fae9b1514a6961aa4", "best_bid": "0.21", "best_ask": "0.23"}, {"asset_id": "97336036946990892589126446221607202585647626122722486163761162882902175162098", "price": "0.95", "size": "8245", "side": "SELL", "hash": "4afdd6119dd53f030148d3cfedc4af8493961d7d", "best_bid": "0.77", "best_ask": "0.79"}], "timestamp": "1769384798686", "event_type": "price_change"}}
{"_local_timestamp": "2026-01-25T23:46:45.217669+00:00", "data": {"market": "0x7b5c576ee07b4e95934b114634af0b8c7002cdced133e4d03db8fdb5dad7efc9", "price_changes": [{"asset_id": "97336036946990892589126446221607202585647626122722486163761162882902175162098", "price": "0.22", "size": "1958", "side": "BUY", "hash": "510eff248194b88fe814dd84107436a99cacd06c", "best_bid": "0.77", "best_ask": "0.79"}, {"asset_id": "58522802851851118793855155558916400893498205325121134941799318021764167337515", "price": "0.78", "size": "1958", "side": "SELL", "hash": "3fcb3a4fc88e540589f2c8317b58a542aa5601d2", "best_bid": "0.21", "best_ask": "0.23"}], "timestamp": "1769384805139", "event_type": "price_change"}}
{"_local_timestamp": "2026-01-25T23:46:50.860092+00:00", "data": {"market": "0x7b5c576ee07b4e95934b114634af0b8c7002cdced133e4d03db8fdb5dad7efc9", "price_changes": [{"asset_id": "97336036946990892589126446221607202585647626122722486163761162882902175162098", "price": "0.25", "size": "300", "side": "BUY", "hash": "f0ebf6313f6f6f9e1c50b8dd4e7372b10faa1b5b", "best_bid": "0.77", "best_ask": "0.79"}, {"asset_id": "58522802851851118793855155558916400893498205325121134941799318021764167337515", "price": "0.75", "size": "300", "side": "SELL", "hash": "8b55ca12c2afe33b1858cd3b3f23ae4cf4d50c32", "best_bid": "0.21", "best_ask": "0.23"}], "timestamp": "1769384810657", "event_type": "price_change"}}
{"_local_timestamp": "2026-01-25T23:46:51.574228+00:00", "data": {"market": "0x7b5c576ee07b4e95934b114634af0b8c7002cdced133e4d03db8fdb5dad7efc9", "price_changes": [{"asset_id": "97336036946990892589126446221607202585647626122722486163761162882902175162098", "price": "0.22", "size": "2058", "side": "BUY", "hash": "f52783b29e8b250184d58450e005618b2e12ca5d", "best_bid": "0.77", "best_ask": "0.79"}, {"asset_id": "58522802851851118793855155558916400893498205325121134941799318021764167337515", "price": "0.78", "size": "2058", "side": "SELL", "hash": "2d9904f150bbe3c79a956529fd3e8c3eaea5b9a2", "best_bid": "0.21", "best_ask": "0.23"}], "timestamp": "1769384811223", "event_type": "price_change"}}
{"_local_timestamp": "2026-01-25T23:46:51.713185+00:00", "data": {"market": "0x7b5c576ee07b4e95934b114634af0b8c7002cdced133e4d03db8fdb5dad7efc9", "price_changes": [{"asset_id": "58522802851851118793855155558916400893498205325121134941799318021764167337515", "price": "0.25", "size": "842.51", "side": "SELL", "hash": "7ee546e5650fca9bece3f53df90a595b1860b415", "best_bid": "0.21", "best_ask": "0.23"}, {"asset_id": "97336036946990892589126446221607202585647626122722486163761162882902175162098", "price": "0.75", "size": "842.51", "side": "BUY", "hash": "1db96441bcdfc274c66a2ae7a175fa42c74382a0", "best_bid": "0.77", "best_ask": "0.79"}], "timestamp": "1769384811402", "event_type": "price_change"}}
{"_local_timestamp": "2026-01-25T23:46:53.846923+00:00", "data": {"market": "0x7b5c576ee07b4e95934b114634af0b8c7002cdced133e4d03db8fdb5dad7efc9", "price_changes": [{"asset_id": "58522802851851118793855155558916400893498205325121134941799318021764167337515", "price": "0.26", "size": "623.38", "side": "SELL", "hash": "1cd45e46ebede550a4c87223af68f7711d9e9930", "best_bid": "0.21", "best_ask": "0.23"}, {"asset_id": "97336036946990892589126446221607202585647626122722486163761162882902175162098", "price": "0.74", "size": "623.38", "side": "BUY", "hash": "bbc9402a8268cffdead8added86c1c680741b7a6", "best_bid": "0.77", "best_ask": "0.79"}], "timestamp": "1769384813768", "event_type": "price_change"}}
{"_local_timestamp": "2026-01-25T23:46:58.954419+00:00", "data": {"market": "0x7b5c576ee07b4e95934b114634af0b8c7002cdced133e4d03db8fdb5dad7efc9", "price_changes": [{"asset_id": "97336036946990892589126446221607202585647626122722486163761162882902175162098", "price": "0.21", "size": "0", "side": "BUY", "hash": "52775c161977f7b956b32067c7ef8829c50803db", "best_bid": "0.77", "best_ask": "0.79"}, {"asset_id": "58522802851851118793855155558916400893498205325121134941799318021764167337515", "price": "0.79", "size": "0", "side": "SELL", "hash": "540b781d42e22525a292c1dd282545c27dfa40ba", "best_bid": "0.21", "best_ask": "0.23"}], "timestamp": "1769384818854", "event_type": "price_change"}}
{"_local_timestamp": "2026-01-25T23:46:59.366295+00:00", "data": {"market": "0x7b5c576ee07b4e95934b114634af0b8c7002cdced133e4d03db8fdb5dad7efc9", "price_changes": [{"asset_id": "97336036946990892589126446221607202585647626122722486163761162882902175162098", "price": "0.25", "size": "400", "side": "BUY", "hash": "330b97740627aa5017fb1b8611210d90da4a8c30", "best_bid": "0.77", "best_ask": "0.79"}, {"asset_id": "58522802851851118793855155558916400893498205325121134941799318021764167337515", "price": "0.75", "size": "400", "side": "SELL", "hash": "bbbd06ba21621fde9b66b59b495c29906740a838", "best_bid": "0.21", "best_ask": "0.23"}], "timestamp": "1769384819293", "event_type": "price_change"}}
{"_local_timestamp": "2026-01-25T23:47:06.718641+00:00", "data": {"market": "0x7b5c576ee07b4e95934b114634af0b8c7002cdced133e4d03db8fdb5dad7efc9", "price_changes": [{"asset_id": "58522802851851118793855155558916400893498205325121134941799318021764167337515", "price": "0.26", "size": "521", "side": "SELL", "hash": "16c72c3c3840ea52226ce1d6e4b163e7cc4c2317", "best_bid": "0.21", "best_ask": "0.23"}, {"asset_id": "97336036946990892589126446221607202585647626122722486163761162882902175162098", "price": "0.74", "size": "521", "side": "BUY", "hash": "f4da0dc9fb7069d3fa9cf430042e11acf6751c56", "best_bid": "0.77", "best_ask": "0.79"}], "timestamp": "1769384826651", "event_type": "price_change"}}
{"_local_timestamp": "2026-01-25T23:47:23.557587+00:00", "data": {"market": "0x7b5c576ee07b4e95934b114634af0b8c7002cdced133e4d03db8fdb5dad7efc9", "price_changes": [{"asset_id": "97336036946990892589126446221607202585647626122722486163761162882902175162098", "price": "0.25", "size": "350", "side": "BUY", "hash": "489eabbb7e6b24fc5ec1bc236906486f31182a2d", "best_bid": "0.77", "best_ask": "0.79"}, {"asset_id": "58522802851851118793855155558916400893498205325121134941799318021764167337515", "price": "0.75", "size": "350", "side": "SELL", "hash": "9384f9ab21f6d50ec2e394341741b7659b5b9bdb", "best_bid": "0.21", "best_ask": "0.23"}], "timestamp": "1769384843405", "event_type": "price_change"}}
{"_local_timestamp": "2026-01-25T23:47:23.925958+00:00", "data": {"market": "0x7b5c576ee07b4e95934b114634af0b8c7002cdced133e4d03db8fdb5dad7efc9", "price_changes": [{"asset_id": "97336036946990892589126446221607202585647626122722486163761162882902175162098", "price": "0.21", "size": "50", "side": "BUY", "hash": "ec7e292337c2e2f74c5e992e661c51cd7354484d", "best_bid": "0.77", "best_ask": "0.79"}, {"asset_id": "58522802851851118793855155558916400893498205325121134941799318021764167337515", "price": "0.79", "size": "50", "side": "SELL", "hash": "a253897c70a8550546fa9813f8c61e7320cfcc1d", "best_bid": "0.21", "best_ask": "0.23"}], "timestamp": "1769384843823", "event_type": "price_change"}}
{"_local_timestamp": "2026-01-25T23:47:37.390846+00:00", "data": {"market": "0x7b5c576ee07b4e95934b114634af0b8c7002cdced133e4d03db8fdb5dad7efc9", "price_changes": [{"asset_id": "97336036946990892589126446221607202585647626122722486163761162882902175162098", "price": "0.25", "size": "250", "side": "BUY", "hash": "fc13ee85a60dd3fbc8c6fa373d6a862763264fa4", "best_bid": "0.77", "best_ask": "0.79"}, {"asset_id": "58522802851851118793855155558916400893498205325121134941799318021764167337515", "price": "0.75", "size": "250", "side": "SELL", "hash": "4352ffce680347fae91497a8928de4c3fb5c5066", "best_bid": "0.21", "best_ask": "0.23"}], "timestamp": "1769384857297", "event_type": "price_change"}}
{"_local_timestamp": "2026-01-25T23:47:37.752494+00:00", "data": {"market": "0x7b5c576ee07b4e95934b114634af0b8c7002cdced133e4d03db8fdb5dad7efc9", "price_changes": [{"asset_id": "97336036946990892589126446221607202585647626122722486163761162882902175162098", "price": "0.22", "size": "2008", "side": "BUY", "hash": "f1c7bfe266ddc141180caf4e58ee613c6d7be399", "best_bid": "0.77", "best_ask": "0.79"}, {"asset_id": "58522802851851118793855155558916400893498205325121134941799318021764167337515", "price": "0.78", "size": "2008", "side": "SELL", "hash": "1967be8df6989bf36c07a88c575b818dbede9749", "best_bid": "0.21", "best_ask": "0.23"}], "timestamp": "1769384857541", "event_type": "price_change"}}
{"_local_timestamp": "2026-01-25T23:47:37.940170+00:00", "data": {"market": "0x7b5c576ee07b4e95934b114634af0b8c7002cdced133e4d03db8fdb5dad7efc9", "price_changes": [{"asset_id": "97336036946990892589126446221607202585647626122722486163761162882902175162098", "price": "0.22", "size": "2108", "side": "BUY", "hash": "1444c7ece034576c06ea3687125869ecf4deae84", "best_bid": "0.77", "best_ask": "0.79"}, {"asset_id": "58522802851851118793855155558916400893498205325121134941799318021764167337515", "price": "0.78", "size": "2108", "side": "SELL", "hash": "d5e58c6fe82e4c9f66fc4af07512105045b77b29", "best_bid": "0.21", "best_ask": "0.23"}], "timestamp": "1769384857605", "event_type": "price_change"}}
{"_local_timestamp": "2026-01-25T23:47:38.436996+00:00", "data": {"market": "0x7b5c576ee07b4e95934b114634af0b8c7002cdced133e4d03db8fdb5dad7efc9", "price_changes": [{"asset_id": "97336036946990892589126446221607202585647626122722486163761162882902175162098", "price": "0.21", "size": "100", "side": "BUY", "hash": "ced3ba9cd4054c916a5c534017e9feda20e214e9", "best_bid": "0.77", "best_ask": "0.79"}, {"asset_id": "58522802851851118793855155558916400893498205325121134941799318021764167337515", "price": "0.79", "size": "100", "side": "SELL", "hash": "96f10c6ce181e38cad2f968b50dcaa1035aba831", "best_bid": "0.21", "best_ask": "0.23"}], "timestamp": "1769384858094", "event_type": "price_change"}}
{"_local_timestamp": "2026-01-25T23:47:49.081612+00:00", "data": {"market": "0x7b5c576ee07b4e95934b114634af0b8c7002cdced133e4d03db8fdb5dad7efc9", "price_changes": [{"asset_id": "58522802851851118793855155558916400893498205325121134941799318021764167337515", "price": "0.18", "size": "2560", "side": "BUY", "hash": "5f1f437ad01e2f04e7e2ba076559d4b6b3706c32", "best_bid": "0.21", "best_ask": "0.23"}, {"asset_id": "97336036946990892589126446221607202585647626122722486163761162882902175162098", "price": "0.82", "size": "2560", "side": "SELL", "hash": "28ee02fa358cbbbd480c500f0166f5360cf36de7", "best_bid": "0.77", "best_ask": "0.79"}], "timestamp": "1769384869000", "event_type": "price_change"}}
{"_local_timestamp": "2026-01-25T23:47:49.089199+00:00", "data": {"market": "0x7b5c576ee07b4e95934b114634af0b8c7002cdced133e4d03db8fdb5dad7efc9", "price_changes": [{"asset_id": "58522802851851118793855155558916400893498205325121134941799318021764167337515", "price": "0.19", "size": "5051.9", "side": "BUY", "hash": "5dfcbe7aa06373542e1b139c5d6c684a344ef051", "best_bid": "0.21", "best_ask": "0.23"}, {"asset_id": "97336036946990892589126446221607202585647626122722486163761162882902175162098", "price": "0.81", "size": "5051.9", "side": "SELL", "hash": "f77839508ad00012407b32ff7b2c709ce89aa8fe", "best_bid": "0.77", "best_ask": "0.79"}], "timestamp": "1769384869002", "event_type": "price_change"}}
{"_local_timestamp": "2026-01-25T23:47:49.098050+00:00", "data": {"market": "0x7b5c576ee07b4e95934b114634af0b8c7002cdced133e4d03db8fdb5dad7efc9", "price_changes": [{"asset_id": "58522802851851118793855155558916400893498205325121134941799318021764167337515", "price": "0.05", "size": "7905", "side": "BUY", "hash": "f8535353b0b1a2de911995151b65eea2a9ed654f", "best_bid": "0.21", "best_ask": "0.23"}, {"asset_id": "97336036946990892589126446221607202585647626122722486163761162882902175162098", "price": "0.95", "size": "7905", "side": "SELL", "hash": "6e10eff7e0e365f65cde4e2c2d1951644f8ca4a9", "best_bid": "0.77", "best_ask": "0.79"}], "timestamp": "1769384869006", "event_type": "price_change"}}
{"_local_timestamp": "2026-01-25T23:47:49.105339+00:00", "data": {"market": "0x7b5c576ee07b4e95934b114634af0b8c7002cdced133e4d03db8fdb5dad7efc9", "price_changes": [{"asset_id": "58522802851851118793855155558916400893498205325121134941799318021764167337515", "price": "0.16", "size": "5229.89", "side": "BUY", "hash": "f8535353b0b1a2de911995151b65eea2a9ed654f", "best_bid": "0.21", "best_ask": "0.23"}, {"asset_id": "97336036946990892589126446221607202585647626122722486163761162882902175162098", "price": "0.84", "size": "5229.89", "side": "SELL", "hash": "6e10eff7e0e365f65cde4e2c2d1951644f8ca4a9", "best_bid": "0.77", "best_ask": "0.79"}], "timestamp": "1769384869006", "event_type": "price_change"}}
{"_local_timestamp": "2026-01-25T23:47:55.650323+00:00", "data": {"market": "0x7b5c576ee07b4e95934b114634af0b8c7002cdced133e4d03db8fdb5dad7efc9", "price_changes": [{"asset_id": "97336036946990892589126446221607202585647626122722486163761162882902175162098", "price": "0.22", "size": "200", "side": "BUY", "hash": "f585ae1d5382fa7ecab7091c1c183b7d1bd115ba", "best_bid": "0.77", "best_ask": "0.79"}, {"asset_id": "58522802851851118793855155558916400893498205325121134941799318021764167337515", "price": "0.78", "size": "200", "side": "SELL", "hash": "2c3eb1a259d0e8a57978700566957f4d34b8abc7", "best_bid": "0.21", "best_ask": "0.23"}], "timestamp": "1769384875422", "event_type": "price_change"}}
{"_local_timestamp": "2026-01-25T23:48:48.684596+00:00", "data": {"market": "0x7b5c576ee07b4e95934b114634af0b8c7002cdced133e4d03db8fdb5dad7efc9", "price_changes": [{"asset_id": "97336036946990892589126446221607202585647626122722486163761162882902175162098", "price": "0.22", "size": "100", "side": "BUY", "hash": "2b70f430c4c28bc3bd368e6aaa1d399f848c6459", "best_bid": "0.77", "best_ask": "0.79"}, {"asset_id": "58522802851851118793855155558916400893498205325121134941799318021764167337515", "price": "0.78", "size": "100", "side": "SELL", "hash": "2352f01b8e5ac97e44647b4e748c24c2645a03a5", "best_bid": "0.21", "best_ask": "0.23"}], "timestamp": "1769384928586", "event_type": "price_change"}}
{"_local_timestamp": "2026-01-25T23:48:48.963167+00:00", "data": {"market": "0x7b5c576ee07b4e95934b114634af0b8c7002cdced133e4d03db8fdb5dad7efc9", "price_changes": [{"asset_id": "97336036946990892589126446221607202585647626122722486163761162882902175162098", "price": "0.25", "size": "350", "side": "BUY", "hash": "2d7618ee98fae58915c48c88ee3b85bc88f6bcfa", "best_bid": "0.77", "best_ask": "0.79"}, {"asset_id": "58522802851851118793855155558916400893498205325121134941799318021764167337515", "price": "0.75", "size": "350", "side": "SELL", "hash": "8ec04d84d6da4b0cfddc2d07b31d91119c671d07", "best_bid": "0.21", "best_ask": "0.23"}], "timestamp": "1769384928857", "event_type": "price_change"}}
{"_local_timestamp": "2026-01-25T23:48:52.270319+00:00", "data": {"market": "0x7b5c576ee07b4e95934b114634af0b8c7002cdced133e4d03db8fdb5dad7efc9", "price_changes": [{"asset_id": "58522802851851118793855155558916400893498205325121134941799318021764167337515", "price": "0.18", "size": "2583", "side": "BUY", "hash": "8325ae58c7007b5bdebf3218d0a3dc31fc96ad15", "best_bid": "0.21", "best_ask": "0.23"}, {"asset_id": "97336036946990892589126446221607202585647626122722486163761162882902175162098", "price": "0.82", "size": "2583", "side": "SELL", "hash": "9578c841fc48c8beb84598564ef297cc0dfc0f7c", "best_bid": "0.77", "best_ask": "0.79"}], "timestamp": "1769384932192", "event_type": "price_change"}}
{"_local_timestamp": "2026-01-25T23:48:52.270970+00:00", "data": {"market": "0x7b5c576ee07b4e95934b114634af0b8c7002cdced133e4d03db8fdb5dad7efc9", "price_changes": [{"asset_id": "58522802851851118793855155558916400893498205325121134941799318021764167337515", "price": "0.19", "size": "5072.9", "side": "BUY", "hash": "83b803e8edf83fc75407661bcce8aa7390e0a70f", "best_bid": "0.21", "best_ask": "0.23"}, {"asset_id": "97336036946990892589126446221607202585647626122722486163761162882902175162098", "price": "0.81", "size": "5072.9", "side": "SELL", "hash": "ff4ad51ce70f2d61eed4144559231f3ccad12113", "best_bid": "0.77", "best_ask": "0.79"}], "timestamp": "1769384932192", "event_type": "price_change"}}
{"_local_timestamp": "2026-01-25T23:48:52.271494+00:00", "data": {"market": "0x7b5c576ee07b4e95934b114634af0b8c7002cdced133e4d03db8fdb5dad7efc9", "price_changes": [{"asset_id": "58522802851851118793855155558916400893498205325121134941799318021764167337515", "price": "0.05", "size": "8245", "side": "BUY", "hash": "c6ddb65dc0b9b19725d23685a0ca155bb71fb0b9", "best_bid": "0.21", "best_ask": "0.23"}, {"asset_id": "97336036946990892589126446221607202585647626122722486163761162882902175162098", "price": "0.95", "size": "8245", "side": "SELL", "hash": "a832d0550b18befec195709232050e4135559c76", "best_bid": "0.77", "best_ask": "0.79"}], "timestamp": "1769384932193", "event_type": "price_change"}}
{"_local_timestamp": "2026-01-25T23:48:52.272088+00:00", "data": {"market": "0x7b5c576ee07b4e95934b114634af0b8c7002cdced133e4d03db8fdb5dad7efc9", "price_changes": [{"asset_id": "58522802851851118793855155558916400893498205325121134941799318021764167337515", "price": "0.16", "size": "5287.89", "side": "BUY", "hash": "9d8a1e831ed1c02c9ac21ce4f88076fd0ef28206", "best_bid": "0.21", "best_ask": "0.23"}, {"asset_id": "97336036946990892589126446221607202585647626122722486163761162882902175162098", "price": "0.84", "size": "5287.89", "side": "SELL", "hash": "a2a04c59ca79b6d87783e7108bb9a9d7a3ae44a8", "best_bid": "0.77", "best_ask": "0.79"}], "timestamp": "1769384932194", "event_type": "price_change"}}
{"_local_timestamp": "2026-01-25T23:48:52.321103+00:00", "data": {"market": "0x7b5c576ee07b4e95934b114634af0b8c7002cdced133e4d03db8fdb5dad7efc9", "price_changes": [{"asset_id": "58522802851851118793855155558916400893498205325121134941799318021764167337515", "price": "0.19", "size": "5757.11", "side": "BUY", "hash": "1869f43db630ff56de129a5d40db4d72f677b462", "best_bid": "0.21", "best_ask": "0.23"}, {"asset_id": "97336036946990892589126446221607202585647626122722486163761162882902175162098", "price": "0.81", "size": "5757.11", "side": "SELL", "hash": "32f004e9720a0c843846f6faf77faf0244addeb0", "best_bid": "0.77", "best_ask": "0.79"}], "timestamp": "1769384932250", "event_type": "price_change"}}
{"_local_timestamp": "2026-01-25T23:49:19.200624+00:00", "data": {"market": "0x7b5c576ee07b4e95934b114634af0b8c7002cdced133e4d03db8fdb5dad7efc9", "price_changes": [{"asset_id": "97336036946990892589126446221607202585647626122722486163761162882902175162098", "price": "0.21", "size": "2098", "side": "BUY", "hash": "1f2a8837b59f7c6bad1c1979597a70e3fdcbdd7c", "best_bid": "0.77", "best_ask": "0.79"}, {"asset_id": "58522802851851118793855155558916400893498205325121134941799318021764167337515", "price": "0.79", "size": "2098", "side": "SELL", "hash": "a43cb03f7422615d01fd4672aaeec4d18d7afe05", "best_bid": "0.21", "best_ask": "0.23"}], "timestamp": "1769384959133", "event_type": "price_change"}}
{"_local_timestamp": "2026-01-25T23:49:19.251113+00:00", "data": {"market": "0x7b5c576ee07b4e95934b114634af0b8c7002cdced133e4d03db8fdb5dad7efc9", "price_changes": [{"asset_id": "58522802851851118793855155558916400893498205325121134941799318021764167337515", "price": "0.19", "size": "5072.9", "side": "BUY", "hash": "2f6c8614be6b15f79a5573bd56e92edf0f98c52f", "best_bid": "0.21", "best_ask": "0.23"}, {"asset_id": "97336036946990892589126446221607202585647626122722486163761162882902175162098", "price": "0.81", "size": "5072.9", "side": "SELL", "hash": "14cc83bb04c662390604b874ed791b0712a22321", "best_bid": "0.77", "best_ask": "0.79"}], "timestamp": "1769384959182", "event_type": "price_change"}}
{"_local_timestamp": "2026-01-25T23:49:25.410046+00:00", "data": {"market": "0x7b5c576ee07b4e95934b114634af0b8c7002cdced133e4d03db8fdb5dad7efc9", "price_changes": [{"asset_id": "97336036946990892589126446221607202585647626122722486163761162882902175162098", "price": "0.21", "size": "2048", "side": "BUY", "hash": "7dd2ec42f606d2b3f99eda37514f7dee03fd1110", "best_bid": "0.77", "best_ask": "0.79"}, {"asset_id": "58522802851851118793855155558916400893498205325121134941799318021764167337515", "price": "0.79", "size": "2048", "side": "SELL", "hash": "f14143bc2d328f6ff5e7d3bcaa64abfb0841edcf", "best_bid": "0.21", "best_ask": "0.23"}], "timestamp": "1769384965278", "event_type": "price_change"}}
{"_local_timestamp": "2026-01-25T23:49:25.980196+00:00", "data": {"market": "0x7b5c576ee07b4e95934b114634af0b8c7002cdced133e4d03db8fdb5dad7efc9", "price_changes": [{"asset_id": "97336036946990892589126446221607202585647626122722486163761162882902175162098", "price": "0.22", "size": "150", "side": "BUY", "hash": "8b6186c9cef1c42998b3a28bd715ebddec0ea345", "best_bid": "0.77", "best_ask": "0.79"}, {"asset_id": "58522802851851118793855155558916400893498205325121134941799318021764167337515", "price": "0.78", "size": "150", "side": "SELL", "hash": "4a09f379418dd36c0f906fc8dc788d9548c28fd9", "best_bid": "0.21", "best_ask": "0.23"}], "timestamp": "1769384965791", "event_type": "price_change"}}
{"_local_timestamp": "2026-01-25T23:49:41.824291+00:00", "data": {"market": "0x7b5c576ee07b4e95934b114634af0b8c7002cdced133e4d03db8fdb5dad7efc9", "price_changes": [{"asset_id": "97336036946990892589126446221607202585647626122722486163761162882902175162098", "price": "0.21", "size": "1998", "side": "BUY", "hash": "97be16077fc9ccbba9878b74ce5a80714d680a40", "best_bid": "0.77", "best_ask": "0.79"}, {"asset_id": "58522802851851118793855155558916400893498205325121134941799318021764167337515", "price": "0.79", "size": "1998", "side": "SELL", "hash": "fa88f466a38c70c2c64c1f95934e2df5b401d7ac", "best_bid": "0.21", "best_ask": "0.23"}], "timestamp": "1769384981673", "event_type": "price_change"}}
{"_local_timestamp": "2026-01-25T23:49:42.432390+00:00", "data": {"market": "0x7b5c576ee07b4e95934b114634af0b8c7002cdced133e4d03db8fdb5dad7efc9", "price_changes": [{"asset_id": "97336036946990892589126446221607202585647626122722486163761162882902175162098", "price": "0.22", "size": "200", "side": "BUY", "hash": "4e33b567d8732ff395e28cf0db08638a1c80328e", "best_bid": "0.77", "best_ask": "0.79"}, {"asset_id": "58522802851851118793855155558916400893498205325121134941799318021764167337515", "price": "0.78", "size": "200", "side": "SELL", "hash": "c4688a433f0abc9ff2c33359db6e1ae86410ab84", "best_bid": "0.21", "best_ask": "0.23"}], "timestamp": "1769384982239", "event_type": "price_change"}}
{"_local_timestamp": "2026-01-25T23:49:51.215705+00:00", "data": {"market": "0x7b5c576ee07b4e95934b114634af0b8c7002cdced133e4d03db8fdb5dad7efc9", "price_changes": [{"asset_id": "97336036946990892589126446221607202585647626122722486163761162882902175162098", "price": "0.21", "size": "0", "side": "BUY", "hash": "fae6507b70f98b36f30cac316c7404ab89d2f05c", "best_bid": "0.77", "best_ask": "0.79"}, {"asset_id": "58522802851851118793855155558916400893498205325121134941799318021764167337515", "price": "0.79", "size": "0", "side": "SELL", "hash": "fb0f47e02aacf7375bdf4bb0bcdbaa295262db6b", "best_bid": "0.21", "best_ask": "0.23"}], "timestamp": "1769384991039", "event_type": "price_change"}}
{"_local_timestamp": "2026-01-25T23:49:52.090897+00:00", "data": {"market": "0x7b5c576ee07b4e95934b114634af0b8c7002cdced133e4d03db8fdb5dad7efc9", "price_changes": [{"asset_id": "58522802851851118793855155558916400893498205325121134941799318021764167337515", "price": "0.19", "size": "4972.9", "side": "BUY", "hash": "9f988791cf4d05a290d51da93439161f1bce96ff", "best_bid": "0.21", "best_ask": "0.23"}, {"asset_id": "97336036946990892589126446221607202585647626122722486163761162882902175162098", "price": "0.81", "size": "4972.9", "side": "SELL", "hash": "8858b389b68ffc4d1a8c3e54afb7517fc73bc040", "best_bid": "0.77", "best_ask": "0.79"}], "timestamp": "1769384992004", "event_type": "price_change"}}
{"_local_timestamp": "2026-01-25T23:49:52.097614+00:00", "data": {"market": "0x7b5c576ee07b4e95934b114634af0b8c7002cdced133e4d03db8fdb5dad7efc9", "price_changes": [{"asset_id": "58522802851851118793855155558916400893498205325121134941799318021764167337515", "price": "0.18", "size": "2066", "side": "BUY", "hash": "41215f715035380ac50aa88988dfba5ed69a5976", "best_bid": "0.21", "best_ask": "0.23"}, {"asset_id": "97336036946990892589126446221607202585647626122722486163761162882902175162098", "price": "0.82", "size": "2066", "side": "SELL", "hash": "b86a9fb82076168d60a4d633ad45eb16ab428694", "best_bid": "0.77", "best_ask": "0.79"}], "timestamp": "1769384992005", "event_type": "price_change"}}
{"_local_timestamp": "2026-01-25T23:49:52.103466+00:00", "data": {"market": "0x7b5c576ee07b4e95934b114634af0b8c7002cdced133e4d03db8fdb5dad7efc9", "price_changes": [{"asset_id": "58522802851851118793855155558916400893498205325121134941799318021764167337515", "price": "0.05", "size": "905", "side": "BUY", "hash": "722d894ef9fbe0694cd25d724db6140c1361281b", "best_bid": "0.21", "best_ask": "0.23"}, {"asset_id": "97336036946990892589126446221607202585647626122722486163761162882902175162098", "price": "0.95", "size": "905", "side": "SELL", "hash": "1c1847c3d5be98aeb38bccf5a8ea10ca3e6fbba5", "best_bid": "0.77", "best_ask": "0.79"}], "timestamp": "1769384992006", "event_type": "price_change"}}
{"_local_timestamp": "2026-01-25T23:49:52.104051+00:00", "data": {"market": "0x7b5c576ee07b4e95934b114634af0b8c7002cdced133e4d03db8fdb5dad7efc9", "price_changes": [{"asset_id": "58522802851851118793855155558916400893498205325121134941799318021764167337515", "price": "0.16", "size": "4138.89", "side": "BUY", "hash": "4b0744bd75e52ac364b3632751d8f5597002c4c7", "best_bid": "0.21", "best_ask": "0.23"}, {"asset_id": "97336036946990892589126446221607202585647626122722486163761162882902175162098", "price": "0.84", "size": "4138.89", "side": "SELL", "hash": "e72af4bee1c37d07ac994156580271329ab4a40b", "best_bid": "0.77", "best_ask": "0.79"}], "timestamp": "1769384992007", "event_type": "price_change"}}
{"_local_timestamp": "2026-01-25T23:49:55.297180+00:00", "data": {"market": "0x7b5c576ee07b4e95934b114634af0b8c7002cdced133e4d03db8fdb5dad7efc9", "price_changes": [{"asset_id": "58522802851851118793855155558916400893498205325121134941799318021764167337515", "price": "0.19", "size": "5072.9", "side": "BUY", "hash": "f28e8c967f5202ca07819ad257055f28d5074723", "best_bid": "0.21", "best_ask": "0.23"}, {"asset_id": "97336036946990892589126446221607202585647626122722486163761162882902175162098", "price": "0.81", "size": "5072.9", "side": "SELL", "hash": "231abadb066eec29a3c7202c0081afa0a61a46c3", "best_bid": "0.77", "best_ask": "0.79"}], "timestamp": "1769384995228", "event_type": "price_change"}}
{"_local_timestamp": "2026-01-25T23:49:55.299247+00:00", "data": {"market": "0x7b5c576ee07b4e95934b114634af0b8c7002cdced133e4d03db8fdb5dad7efc9", "price_changes": [{"asset_id": "58522802851851118793855155558916400893498205325121134941799318021764167337515", "price": "0.16", "size": "5287.89", "side": "BUY", "hash": "0943753d1efb63bf4f4bfaae6814a61909c9bcea", "best_bid": "0.21", "best_ask": "0.23"}, {"asset_id": "97336036946990892589126446221607202585647626122722486163761162882902175162098", "price": "0.84", "size": "5287.89", "side": "SELL", "hash": "abb7efc3349e84bc643e270293b29954ee37bdc8", "best_bid": "0.77", "best_ask": "0.79"}], "timestamp": "1769384995229", "event_type": "price_change"}}
{"_local_timestamp": "2026-01-25T23:49:55.299853+00:00", "data": {"market": "0x7b5c576ee07b4e95934b114634af0b8c7002cdced133e4d03db8fdb5dad7efc9", "price_changes": [{"asset_id": "58522802851851118793855155558916400893498205325121134941799318021764167337515", "price": "0.05", "size": "8245", "side": "BUY", "hash": "f64bd5a3ea1a7b8a9fa243b42dd0eb6b9fddf3ad", "best_bid": "0.21", "best_ask": "0.23"}, {"asset_id": "97336036946990892589126446221607202585647626122722486163761162882902175162098", "price": "0.95", "size": "8245", "side": "SELL", "hash": "77baa085890dfa14be7d165e3d02b6b3e09eaf4f", "best_bid": "0.77", "best_ask": "0.79"}], "timestamp": "1769384995230", "event_type": "price_change"}}
{"_local_timestamp": "2026-01-25T23:49:55.300369+00:00", "data": {"market": "0x7b5c576ee07b4e95934b114634af0b8c7002cdced133e4d03db8fdb5dad7efc9", "price_changes": [{"asset_id": "58522802851851118793855155558916400893498205325121134941799318021764167337515", "price": "0.18", "size": "2583", "side": "BUY", "hash": "cb96cf1c1449da82cd8bfc898f73fbfc17cd3ce1", "best_bid": "0.21", "best_ask": "0.23"}, {"asset_id": "97336036946990892589126446221607202585647626122722486163761162882902175162098", "price": "0.82", "size": "2583", "side": "SELL", "hash": "6af304d48c44368cbdb04faccf1d0e4a558cd50d", "best_bid": "0.77", "best_ask": "0.79"}], "timestamp": "1769384995231", "event_type": "price_change"}}
{"_local_timestamp": "2026-01-25T23:50:02.465754+00:00", "data": {"market": "0x7b5c576ee07b4e95934b114634af0b8c7002cdced133e4d03db8fdb5dad7efc9", "price_changes": [{"asset_id": "97336036946990892589126446221607202585647626122722486163761162882902175162098", "price": "0.18", "size": "450", "side": "BUY", "hash": "c0b1812062714a0833b7b2b6a4b2c6c3ba3da6fc", "best_bid": "0.77", "best_ask": "0.79"}, {"asset_id": "58522802851851118793855155558916400893498205325121134941799318021764167337515", "price": "0.82", "size": "450", "side": "SELL", "hash": "49400a1f8e1a9aa10ac54d7c65b2210daffda2fc", "best_bid": "0.21", "best_ask": "0.23"}], "timestamp": "1769385002271", "event_type": "price_change"}}
{"_local_timestamp": "2026-01-25T23:50:05.580716+00:00", "data": {"market": "0x7b5c576ee07b4e95934b114634af0b8c7002cdced133e4d03db8fdb5dad7efc9", "price_changes": [{"asset_id": "97336036946990892589126446221607202585647626122722486163761162882902175162098", "price": "0.25", "size": "250", "side": "BUY", "hash": "b51705b56c7bf49b820b72acccea3b502fcfd658", "best_bid": "0.77", "best_ask": "0.79"}, {"asset_id": "58522802851851118793855155558916400893498205325121134941799318021764167337515", "price": "0.75", "size": "250", "side": "SELL", "hash": "638ad2f88bf7e943a65e09e2b68def04f19482e1", "best_bid": "0.21", "best_ask": "0.23"}], "timestamp": "1769385005465", "event_type": "price_change"}}
{"_local_timestamp": "2026-01-25T23:50:05.844247+00:00", "data": {"market": "0x7b5c576ee07b4e95934b114634af0b8c7002cdced133e4d03db8fdb5dad7efc9", "price_changes": [{"asset_id": "97336036946990892589126446221607202585647626122722486163761162882902175162098", "price": "0.21", "size": "100", "side": "BUY", "hash": "8178fdccbbba40038fca2afc426ede56d586b4f7", "best_bid": "0.77", "best_ask": "0.79"}, {"asset_id": "58522802851851118793855155558916400893498205325121134941799318021764167337515", "price": "0.79", "size": "100", "side": "SELL", "hash": "4b0b53c0d2b4a3d5573db1c882f6c7d2b1af34f6", "best_bid": "0.21", "best_ask": "0.23"}], "timestamp": "1769385005732", "event_type": "price_change"}}
{"_local_timestamp": "2026-01-25T23:50:18.498386+00:00", "data": {"market": "0x7b5c576ee07b4e95934b114634af0b8c7002cdced133e4d03db8fdb5dad7efc9", "price_changes": [{"asset_id": "97336036946990892589126446221607202585647626122722486163761162882902175162098", "price": "0.18", "size": "400", "side": "BUY", "hash": "26a7a9a86dc1922a9899e9ec285d945181d9d054", "best_bid": "0.77", "best_ask": "0.79"}, {"asset_id": "58522802851851118793855155558916400893498205325121134941799318021764167337515", "price": "0.82", "size": "400", "side": "SELL", "hash": "e5947910e46c391d3afaa6be0dde3d4bc137e911", "best_bid": "0.21", "best_ask": "0.23"}], "timestamp": "1769385018280", "event_type": "price_change"}}
{"_local_timestamp": "2026-01-25T23:50:18.644274+00:00", "data": {"market": "0x7b5c576ee07b4e95934b114634af0b8c7002cdced133e4d03db8fdb5dad7efc9", "price_changes": [{"asset_id": "97336036946990892589126446221607202585647626122722486163761162882902175162098", "price": "0.12", "size": "883.33", "side": "BUY", "hash": "25fd07f00142c91c34011302e06f7044e33ea057", "best_bid": "0.77", "best_ask": "0.79"}, {"asset_id": "58522802851851118793855155558916400893498205325121134941799318021764167337515", "price": "0.88", "size": "883.33", "side": "SELL", "hash": "4a6b77496b469805b5152c6733352e560caedd1e", "best_bid": "0.21", "best_ask": "0.23"}], "timestamp": "1769385018553", "event_type": "price_change"}}
{"_local_timestamp": "2026-01-25T23:50:29.801603+00:00", "data": {"market": "0x7b5c576ee07b4e95934b114634af0b8c7002cdced133e4d03db8fdb5dad7efc9", "price_changes": [{"asset_id": "97336036946990892589126446221607202585647626122722486163761162882902175162098", "price": "0.23", "size": "1826", "side": "BUY", "hash": "bc0d783c8bee38c8925b8ff2934232feeb93693c", "best_bid": "0.77", "best_ask": "0.79"}, {"asset_id": "58522802851851118793855155558916400893498205325121134941799318021764167337515", "price": "0.77", "size": "1826", "side": "SELL", "hash": "1513e30eac7ff9dc738fd94a0f3d628cb39ae71e", "best_bid": "0.21", "best_ask": "0.23"}], "timestamp": "1769385029636", "event_type": "price_change"}}
{"_local_timestamp": "2026-01-25T23:50:41.229535+00:00", "data": {"market": "0x7b5c576ee07b4e95934b114634af0b8c7002cdced133e4d03db8fdb5dad7efc9", "price_changes": [{"asset_id": "58522802851851118793855155558916400893498205325121134941799318021764167337515", "price": "0.19", "size": "5061.9", "side": "BUY", "hash": "4d5af47d3c2df864dbe2f18e48f37f596d4499ae", "best_bid": "0.21", "best_ask": "0.23"}, {"asset_id": "97336036946990892589126446221607202585647626122722486163761162882902175162098", "price": "0.81", "size": "5061.9", "side": "SELL", "hash": "939a6c8891672110908bb98f52d830539e6bb93d", "best_bid": "0.77", "best_ask": "0.79"}], "timestamp": "1769385041003", "event_type": "price_change"}}
{"_local_timestamp": "2026-01-25T23:50:46.356483+00:00", "data": {"market": "0x7b5c576ee07b4e95934b114634af0b8c7002cdced133e4d03db8fdb5dad7efc9", "price_changes": [{"asset_id": "97336036946990892589126446221607202585647626122722486163761162882902175162098", "price": "0.18", "size": "250", "side": "BUY", "hash": "d55c74edda1df2b6c2609ca5c7262a2f84195325", "best_bid": "0.77", "best_ask": "0.79"}, {"asset_id": "58522802851851118793855155558916400893498205325121134941799318021764167337515", "price": "0.82", "size": "250", "side": "SELL", "hash": "d2229abf7fd7039e7942eceb4b82243418430199", "best_bid": "0.21", "best_ask": "0.23"}], "timestamp": "1769385046264", "event_type": "price_change"}}
{"_local_timestamp": "2026-01-25T23:50:46.357809+00:00", "data": {"market": "0x7b5c576ee07b4e95934b114634af0b8c7002cdced133e4d03db8fdb5dad7efc9", "price_changes": [{"asset_id": "97336036946990892589126446221607202585647626122722486163761162882902175162098", "price": "0.21", "size": "0", "side": "BUY", "hash": "d55c74edda1df2b6c2609ca5c7262a2f84195325", "best_bid": "0.77", "best_ask": "0.79"}, {"asset_id": "58522802851851118793855155558916400893498205325121134941799318021764167337515", "price": "0.79", "size": "0", "side": "SELL", "hash": "d2229abf7fd7039e7942eceb4b82243418430199", "best_bid": "0.21", "best_ask": "0.23"}], "timestamp": "1769385046264", "event_type": "price_change"}}
{"_local_timestamp": "2026-01-25T23:50:46.812319+00:00", "data": {"market": "0x7b5c576ee07b4e95934b114634af0b8c7002cdced133e4d03db8fdb5dad7efc9", "price_changes": [{"asset_id": "97336036946990892589126446221607202585647626122722486163761162882902175162098", "price": "0.25", "size": "350", "side": "BUY", "hash": "6a6d27a0ddede9536a2e22d38e7b18cc41f4ceee", "best_bid": "0.77", "best_ask": "0.79"}, {"asset_id": "58522802851851118793855155558916400893498205325121134941799318021764167337515", "price": "0.75", "size": "350", "side": "SELL", "hash": "053ce1d728e23e3d4771bb5aee17b58ce28173d6", "best_bid": "0.21", "best_ask": "0.23"}], "timestamp": "1769385046644", "event_type": "price_change"}}
{"_local_timestamp": "2026-01-25T23:50:46.823675+00:00", "data": {"market": "0x7b5c576ee07b4e95934b114634af0b8c7002cdced133e4d03db8fdb5dad7efc9", "price_changes": [{"asset_id": "97336036946990892589126446221607202585647626122722486163761162882902175162098", "price": "0.2", "size": "490", "side": "BUY", "hash": "ab2c89244d993f8f6cb19aa8ad9e644212330214", "best_bid": "0.77", "best_ask": "0.79"}, {"asset_id": "58522802851851118793855155558916400893498205325121134941799318021764167337515", "price": "0.8", "size": "490", "side": "SELL", "hash": "d66d5e3e570558f1392f4c1c6d732b6096c7e158", "best_bid": "0.21", "best_ask": "0.23"}], "timestamp": "1769385046655", "event_type": "price_change"}}
{"_local_timestamp": "2026-01-25T23:51:05.622975+00:00", "data": {"market": "0x7b5c576ee07b4e95934b114634af0b8c7002cdced133e4d03db8fdb5dad7efc9", "price_changes": [{"asset_id": "97336036946990892589126446221607202585647626122722486163761162882902175162098", "price": "0.22", "size": "150", "side": "BUY", "hash": "3ae8cf591c922b2110fe5bf096f1c173e01cd2e3", "best_bid": "0.77", "best_ask": "0.79"}, {"asset_id": "58522802851851118793855155558916400893498205325121134941799318021764167337515", "price": "0.78", "size": "150", "side": "SELL", "hash": "ea3ec5e0d7abe0b527c6a1bb9a74cb7e0cd1f129", "best_bid": "0.21", "best_ask": "0.23"}], "timestamp": "1769385065434", "event_type": "price_change"}}
{"_local_timestamp": "2026-01-25T23:51:06.013321+00:00", "data": {"market": "0x7b5c576ee07b4e95934b114634af0b8c7002cdced133e4d03db8fdb5dad7efc9", "price_changes": [{"asset_id": "97336036946990892589126446221607202585647626122722486163761162882902175162098", "price": "0.21", "size": "50", "side": "BUY", "hash": "514dac2b53f8beca3451d68049c5f0ecc8b3821e", "best_bid": "0.77", "best_ask": "0.79"}, {"asset_id": "58522802851851118793855155558916400893498205325121134941799318021764167337515", "price": "0.79", "size": "50", "side": "SELL", "hash": "5b777c3ea29fb428fb0be698ed54806e88ddeeb7", "best_bid": "0.21", "best_ask": "0.23"}], "timestamp": "1769385065790", "event_type": "price_change"}}
{"_local_timestamp": "2026-01-25T23:51:06.213240+00:00", "data": {"market": "0x7b5c576ee07b4e95934b114634af0b8c7002cdced133e4d03db8fdb5dad7efc9", "price_changes": [{"asset_id": "58522802851851118793855155558916400893498205325121134941799318021764167337515", "price": "0.2", "size": "1909.45", "side": "BUY", "hash": "afa3fbee351a0a4927b312d17da838f7ad37e354", "best_bid": "0.21", "best_ask": "0.23"}, {"asset_id": "97336036946990892589126446221607202585647626122722486163761162882902175162098", "price": "0.8", "size": "1909.45", "side": "SELL", "hash": "34da1e75b0f8c660e34ebc1ee0e77ed482e283bb", "best_bid": "0.77", "best_ask": "0.79"}], "timestamp": "1769385066134", "event_type": "price_change"}}
{"_local_timestamp": "2026-01-25T23:51:06.213897+00:00", "data": {"market": "0x7b5c576ee07b4e95934b114634af0b8c7002cdced133e4d03db8fdb5dad7efc9", "price_changes": [{"asset_id": "58522802851851118793855155558916400893498205325121134941799318021764167337515", "price": "0.18", "size": "2066", "side": "BUY", "hash": "afa3fbee351a0a4927b312d17da838f7ad37e354", "best_bid": "0.21", "best_ask": "0.23"}, {"asset_id": "97336036946990892589126446221607202585647626122722486163761162882902175162098", "price": "0.82", "size": "2066", "side": "SELL", "hash": "34da1e75b0f8c660e34ebc1ee0e77ed482e283bb", "best_bid": "0.77", "best_ask": "0.79"}], "timestamp": "1769385066134", "event_type": "price_change"}}
{"_local_timestamp": "2026-01-25T23:51:06.214536+00:00", "data": {"market": "0x7b5c576ee07b4e95934b114634af0b8c7002cdced133e4d03db8fdb5dad7efc9", "price_changes": [{"asset_id": "58522802851851118793855155558916400893498205325121134941799318021764167337515", "price": "0.05", "size": "905", "side": "BUY", "hash": "afa3fbee351a0a4927b312d17da838f7ad37e354", "best_bid": "0.21", "best_ask": "0.23"}, {"asset_id": "97336036946990892589126446221607202585647626122722486163761162882902175162098", "price": "0.95", "size": "905", "side": "SELL", "hash": "34da1e75b0f8c660e34ebc1ee0e77ed482e283bb", "best_bid": "0.77", "best_ask": "0.79"}], "timestamp": "1769385066134", "event_type": "price_change"}}
{"_local_timestamp": "2026-01-25T23:51:06.215133+00:00", "data": {"market": "0x7b5c576ee07b4e95934b114634af0b8c7002cdced133e4d03db8fdb5dad7efc9", "price_changes": [{"asset_id": "58522802851851118793855155558916400893498205325121134941799318021764167337515", "price": "0.16", "size": "4138.89", "side": "BUY", "hash": "afa3fbee351a0a4927b312d17da838f7ad37e354", "best_bid": "0.21", "best_ask": "0.23"}, {"asset_id": "97336036946990892589126446221607202585647626122722486163761162882902175162098", "price": "0.84", "size": "4138.89", "side": "SELL", "hash": "34da1e75b0f8c660e34ebc1ee0e77ed482e283bb", "best_bid": "0.77", "best_ask": "0.79"}], "timestamp": "1769385066134", "event_type": "price_change"}}
{"_local_timestamp": "2026-01-25T23:51:06.215727+00:00", "data": {"market": "0x7b5c576ee07b4e95934b114634af0b8c7002cdced133e4d03db8fdb5dad7efc9", "price_changes": [{"asset_id": "58522802851851118793855155558916400893498205325121134941799318021764167337515", "price": "0.19", "size": "4961.9", "side": "BUY", "hash": "afa3fbee351a0a4927b312d17da838f7ad37e354", "best_bid": "0.21", "best_ask": "0.23"}, {"asset_id": "97336036946990892589126446221607202585647626122722486163761162882902175162098", "price": "0.81", "size": "4961.9", "side": "SELL", "hash": "34da1e75b0f8c660e34ebc1ee0e77ed482e283bb", "best_bid": "0.77", "best_ask": "0.79"}], "timestamp": "1769385066134", "event_type": "price_change"}}
{"_local_timestamp": "2026-01-25T23:51:06.291105+00:00", "data": {"market": "0x7b5c576ee07b4e95934b114634af0b8c7002cdced133e4d03db8fdb5dad7efc9", "price_changes": [{"asset_id": "58522802851851118793855155558916400893498205325121134941799318021764167337515", "price": "0.18", "size": "2555", "side": "BUY", "hash": "176f0a1cc0c8c8a248b6c793197050f5e1e15fdb", "best_bid": "0.21", "best_ask": "0.23"}, {"asset_id": "97336036946990892589126446221607202585647626122722486163761162882902175162098", "price": "0.82", "size": "2555", "side": "SELL", "hash": "aa7c0d7301ef7ee12d0317ba62ef1e01f79ee9eb", "best_bid": "0.77", "best_ask": "0.79"}], "timestamp": "1769385066218", "event_type": "price_change"}}
{"_local_timestamp": "2026-01-25T23:51:06.291783+00:00", "data": {"market": "0x7b5c576ee07b4e95934b114634af0b8c7002cdced133e4d03db8fdb5dad7efc9", "price_changes": [{"asset_id": "58522802851851118793855155558916400893498205325121134941799318021764167337515", "price": "0.19", "size": "5056.9", "side": "BUY", "hash": "9c7575594204217018a55537f953acf886f3f504", "best_bid": "0.21", "best_ask": "0.23"}, {"asset_id": "97336036946990892589126446221607202585647626122722486163761162882902175162098", "price": "0.81", "size": "5056.9", "side": "SELL", "hash": "4a7e323b8b5dce9be484cbbfbfcc5143fbca3e7d", "best_bid": "0.77", "best_ask": "0.79"}], "timestamp": "1769385066219", "event_type": "price_change"}}
{"_local_timestamp": "2026-01-25T23:51:06.292370+00:00", "data": {"market": "0x7b5c576ee07b4e95934b114634af0b8c7002cdced133e4d03db8fdb5dad7efc9", "price_changes": [{"asset_id": "58522802851851118793855155558916400893498205325121134941799318021764167337515", "price": "0.2", "size": "1914.45", "side": "BUY", "hash": "906b656ea01014062ee2580227b26f84497ab6c3", "best_bid": "0.21", "best_ask": "0.23"}, {"asset_id": "97336036946990892589126446221607202585647626122722486163761162882902175162098", "price": "0.8", "size": "1914.45", "side": "SELL", "hash": "ed8ffcb569f324af02c543ce896913053a32aae0", "best_bid": "0.77", "best_ask": "0.79"}], "timestamp": "1769385066220", "event_type": "price_change"}}
{"_local_timestamp": "2026-01-25T23:51:06.292920+00:00", "data": {"market": "0x7b5c576ee07b4e95934b114634af0b8c7002cdced133e4d03db8fdb5dad7efc9", "price_changes": [{"asset_id": "58522802851851118793855155558916400893498205325121134941799318021764167337515", "price": "0.16", "size": "5224.89", "side": "BUY", "hash": "2d5dc90debddf92125652ccd6a2393115142039f", "best_bid": "0.21", "best_ask": "0.23"}, {"asset_id": "97336036946990892589126446221607202585647626122722486163761162882902175162098", "price": "0.84", "size": "5224.89", "side": "SELL", "hash": "19e0873bf3ca10c19629a2a39e58b969c230f89a", "best_bid": "0.77", "best_ask": "0.79"}], "timestamp": "1769385066221", "event_type": "price_change"}}
{"_local_timestamp": "2026-01-25T23:51:06.293529+00:00", "data": {"market": "0x7b5c576ee07b4e95934b114634af0b8c7002cdced133e4d03db8fdb5dad7efc9", "price_changes": [{"asset_id": "58522802851851118793855155558916400893498205325121134941799318021764167337515", "price": "0.05", "size": "7845", "side": "BUY", "hash": "30d98723c1971172d228e7f98c090cf6187a8f42", "best_bid": "0.21", "best_ask": "0.23"}, {"asset_id": "97336036946990892589126446221607202585647626122722486163761162882902175162098", "price": "0.95", "size": "7845", "side": "SELL", "hash": "de58eb469760284780b1d0cfb24e51977b12ac35", "best_bid": "0.77", "best_ask": "0.79"}], "timestamp": "1769385066221", "event_type": "price_change"}}
{"_local_timestamp": "2026-01-25T23:51:22.473487+00:00", "data": {"market": "0x7b5c576ee07b4e95934b114634af0b8c7002cdced133e4d03db8fdb5dad7efc9", "price_changes": [{"asset_id": "58522802851851118793855155558916400893498205325121134941799318021764167337515", "price": "0.25", "size": "944.9", "side": "SELL", "hash": "8b24376a5d9b9002c90a1df0a0f2b36cb5758a98", "best_bid": "0.21", "best_ask": "0.23"}, {"asset_id": "97336036946990892589126446221607202585647626122722486163761162882902175162098", "price": "0.75", "size": "944.9", "side": "BUY", "hash": "67ec7ddb6ea792e5c19c433a8d2babcd4e059d05", "best_bid": "0.77", "best_ask": "0.79"}], "timestamp": "1769385082400", "event_type": "price_change"}}
{"_local_timestamp": "2026-01-25T23:51:26.449452+00:00", "data": {"market": "0x7b5c576ee07b4e95934b114634af0b8c7002cdced133e4d03db8fdb5dad7efc9", "price_changes": [{"asset_id": "97336036946990892589126446221607202585647626122722486163761162882902175162098", "price": "0.25", "size": "250", "side": "BUY", "hash": "d2c5c336fbf73953c9f7754e1cecd560121a4d4d", "best_bid": "0.77", "best_ask": "0.79"}, {"asset_id": "58522802851851118793855155558916400893498205325121134941799318021764167337515", "price": "0.75", "size": "250", "side": "SELL", "hash": "3aeccf8ed807be0a5276bc9eaed3e42b1ac6f95c", "best_bid": "0.21", "best_ask": "0.23"}], "timestamp": "1769385086376", "event_type": "price_change"}}
{"_local_timestamp": "2026-01-25T23:51:26.740481+00:00", "data": {"market": "0x7b5c576ee07b4e95934b114634af0b8c7002cdced133e4d03db8fdb5dad7efc9", "price_changes": [{"asset_id": "97336036946990892589126446221607202585647626122722486163761162882902175162098", "price": "0.23", "size": "1926", "side": "BUY", "hash": "87b69ea9c5fd3c8494eb81f7f05a23750cc21022", "best_bid": "0.77", "best_ask": "0.79"}, {"asset_id": "58522802851851118793855155558916400893498205325121134941799318021764167337515", "price": "0.77", "size": "1926", "side": "SELL", "hash": "98c75ba58fec867600828eeed4722145bbaa6ff1", "best_bid": "0.21", "best_ask": "0.23"}], "timestamp": "1769385086640", "event_type": "price_change"}}
