{"_local_timestamp": "2026-01-25T23:40:29.911588+00:00", "data": [{"market": "0x6987d084de71031819f82051ea62b29a354628c3e4a22076a2acc197c776080a", "asset_id": "94521268801533640253484626268475643884882213091508756864952897781498391313602", "timestamp": "1769384428702", "hash": "e1a94aa7f9a79d72ec30f684912e1c630acd884a", "bids": [{"price": "0.01", "size": "5509.89"}, {"price": "0.02", "size": "2250"}, {"price": "0.03", "size": "2006.93"}, {"price": "0.05", "size": "2323.46"}, {"price": "0.06", "size": "1000"}, {"price": "0.07", "size": "514.28"}, {"price": "0.08", "size": "8.66"}, {"price": "0.11", "size": "388.86"}, {"price": "0.15", "size": "463.33"}, {"price": "0.16", "size": "1000"}, {"price": "0.18", "size": "155.55"}, {"price": "0.19", "size": "5000"}, {"price": "0.2", "size": "2100"}, {"price": "0.22", "size": "118.18"}, {"price": "0.25", "size": "90.97"}, {"price": "0.26", "size": "92.3"}, {"price": "0.27", "size": "277.77"}, {"price": "0.28", "size": "3262"}, {"price": "0.3", "size": "66.66"}, {"price": "0.33", "size": "5000"}, {"price": "0.4", "size": "80.87"}, {"price": "0.5", "size": "60.65"}, {"price": "0.55", "size": "375"}, {"price": "0.56", "size": "3250"}, {"price": "0.58", "size": "2000"}, {"price": "0.59", "size": "2000"}, {"price": "0.6", "size": "2192"}, {"price": "0.61", "size": "2025"}, {"price": "0.62", "size": "2125"}, {"price": "0.63", "size": "8700.18"}, {"price": "0.64", "size": "4013.32"}, {"price": "0.65", "size": "2063.32"}, {"price": "0.66", "size": "1504.22"}, {"price": "0.67", "size": "223.78"}, {"price": "0.68", "size": "860.82"}, {"price": "0.69", "size": "1414.87"}], "asks": [{"price": "0.99", "size": "20000"}, {"price": "0.98", "size": "706.46"}, {"price": "0.97", "size": "9999.51"}, {"price": "0.96", "size": "257.96"}, {"price": "0.95", "size": "33.89"}, {"price": "0.94", "size": "100"}, {"price": "0.91", "size": "30"}, {"price": "0.9", "size": "25.52"}, {"price": "0.85", "size": "2089.01"}, {"price": "0.84", "size": "2161.82"}, {"price": "0.83", "size": "1790"}, {"price": "0.82", "size": "1550.88"}, {"price": "0.81", "size": "141.32"}, {"price": "0.8", "size": "1750"}, {"price": "0.79", "size": "50"}, {"price": "0.78", "size": "200"}, {"price": "0.73", "size": "25"}, {"price": "0.72", "size": "605.72"}, {"price": "0.71", "size": "797.07"}, {"price": "0.7", "size": "316.37"}], "event_type": "book", "last_trade_price": "0.700"}, {"market": "0x6987d084de71031819f82051ea62b29a354628c3e4a22076a2acc197c776080a", "asset_id": "63761293627321054794056701530662561252253979399794304476663814039986928052742", "timestamp": "1769384428702", "hash": "7c3818a7762962c17cb9f5befa8a9a5284eb65eb", "bids": [{"price": "0.01", "size": "20000"}, {"price": "0.02", "size": "706.46"}, {"price": "0.03", "size": "9999.51"}, {"price": "0.04", "size": "257.96"}, {"price": "0.05", "size": "33.89"}, {"price": "0.06", "size": "100"}, {"price": "0.09", "size": "30"}, {"price": "0.1", "size": "25.52"}, {"price": "0.15", "size": "2089.01"}, {"price": "0.16", "size": "2161.82"}, {"price": "0.17", "size": "1790"}, {"price": "0.18", "size": "1550.88"}, {"price": "0.19", "size": "141.32"}, {"price": "0.2", "size": "1750"}, {"price": "0.21", "size": "50"}, {"price": "0.22", "size": "200"}, {"price": "0.27", "size": "25"}, {"price": "0.28", "size": "605.72"}, {"price": "0.29", "size": "797.07"}, {"price": "0.3", "size": "316.37"}], "asks": [{"price": "0.99", "size": "5509.89"}, {"price": "0.98", "size": "2250"}, {"price": "0.97", "size": "2006.93"}, {"price": "0.95", "size": "2323.46"}, {"price": "0.94", "size": "1000"}, {"price": "0.93", "size": "514.28"}, {"price": "0.92", "size": "8.66"}, {"price": "0.89", "size": "388.86"}, {"price": "0.85", "size": "463.33"}, {"price": "0.84", "size": "1000"}, {"price": "0.82", "size": "155.55"}, {"price": "0.81", "size": "5000"}, {"price": "0.8", "size": "2100"}, {"price": "0.78", "size": "118.18"}, {"price": "0.75", "size": "90.97"}, {"price": "0.74", "size": "92.3"}, {"price": "0.73", "size": "277.77"}, {"price": "0.72", "size": "3262"}, {"price": "0.7", "size": "66.66"}, {"price": "0.67", "size": "5000"}, {"price": "0.6", "size": "80.87"}, {"price": "0.5", "size": "60.65"}, {"price": "0.45", "size": "375"}, {"price": "0.44", "size": "3250"}, {"price": "0.42", "size": "2000"}, {"price": "0.41", "size": "2000"}, {"price": "0.4", "size": "2192"}, {"price": "0.39", "size": "2025"}, {"price": "0.38", "size": "2125"}, {"price": "0.37", "size": "8700.18"}, {"price": "0.36", "size": "4013.32"}, {"price": "0.35", "size": "2063.32"}, {"price": "0.34", "size": "1504.22"}, {"price": "0.33", "size": "223.78"}, {"price": "0.32", "size": "860.82"}, {"price": "0.31", "size": "1414.87"}], "event_type": "book", "last_trade_price": "0.700"}, {"market": "0x7e50b661a2bedc670bcf32fc9ece12616f6fc4fba5dbe8526292bf3447374009", "asset_id": "83552904656813968939383082097054433404653657244784709614448703928529504455469", "timestamp": "1769384403046", "hash": "bda3f672cc56a48a6c38596b91401b13404607ad", "bids": [{"price": "0.01", "size": "12509.71"}, {"price": "0.02", "size": "5000"}, {"price": "0.03", "size": "9.08"}, {"price": "0.04", "size": "2500"}, {"price": "0.05", "size": "50030"}, {"price": "0.06", "size": "1033"}, {"price": "0.08", "size": "1000"}, {"price": "0.09", "size": "400"}, {"price": "0.1", "size": "6.3"}, {"price": "0.12", "size": "500"}, {"price": "0.14", "size": "20242.85"}, {"price": "0.15", "size": "250"}, {"price": "0.16", "size": "500"}, {"price": "0.18", "size": "677.77"}, {"price": "0.2", "size": "500"}, {"price": "0.21", "size": "760"}, {"price": "0.23", "size": "121.73"}, {"price": "0.25", "size": "500"}, {"price": "0.27", "size": "5230.29"}, {"price": "0.28", "size": "1498"}, {"price": "0.32", "size": "75"}, {"price": "0.36", "size": "55.55"}, {"price": "0.48", "size": "5"}, {"price": "0.5", "size": "20000"}, {"price": "0.51", "size": "50000"}, {"price": "0.68", "size": "200"}, {"price": "0.7", "size": "65.08"}, {"price": "0.81", "size": "500"}, {"price": "0.82", "size": "10"}, {"price": "0.85", "size": "3072.93"}, {"price": "0.87", "size": "5400"}, {"price": "0.88", "size": "1955.88"}, {"price": "0.89", "size": "142.68"}], "asks": [{"price": "0.99", "size": "25488.5"}, {"price": "0.98", "size": "466.11"}, {"price": "0.97", "size": "1000"}, {"price": "0.96", "size": "407.28"}, {"price": "0.95", "size": "1455"}, {"price": "0.94", "size": "9852.39"}, {"price": "0.93", "size": "1410.55"}, {"price": "0.92", "size": "907.99"}, {"price": "0.91", "size": "645.08"}], "event_type": "book", "last_trade_price": "0.110"}, {"market": "0x5f33f46fa571836f090ef8f3e62caee237f8f73c36a711e757a6f71bf8ef9c6a", "asset_id": "3464795463763108108909057219187376740735691886447931192725079515654033695019", "timestamp": "1769384286741", "hash": "976391e3299b47f1900577e19712501ce3c66f81", "bids": [{"price": "0.01", "size": "2260.33"}, {"price": "0.02", "size": "1000"}, {"price": "0.03", "size": "11.21"}, {"price": "0.05", "size": "885.41"}, {"price": "0.06", "size": "1000"}, {"price": "0.07", "size": "10485.71"}, {"price": "0.09", "size": "5355.55"}, {"price": "0.1", "size": "177.11"}, {"price": "0.11", "size": "1459.09"}, {"price": "0.12", "size": "483.33"}, {"price": "0.13", "size": "3230"}, {"price": "0.14", "size": "185.71"}, {"price": "0.16", "size": "150"}, {"price": "0.18", "size": "111.11"}, {"price": "0.2", "size": "10087.51"}, {"price": "0.22", "size": "100"}, {"price": "0.23", "size": "70"}, {"price": "0.25", "size": "15"}, {"price": "0.3", "size": "23.73"}, {"price": "0.33", "size": "3030"}, {"price": "0.34", "size": "310"}, {"price": "0.35", "size": "5000"}, {"price": "0.36", "size": "100"}, {"price": "0.37", "size": "380"}, {"price": "0.38", "size": "100"}, {"price": "0.39", "size": "355.45"}, {"price": "0.4", "size": "1405"}, {"price": "0.41", "size": "250"}, {"price": "0.42", "size": "1856.14"}, {"price": "0.43", "size": "5311.18"}, {"price": "0.44", "size": "454.17"}, {"price": "0.45", "size": "12.69"}], "asks": [{"price": "0.99", "size": "2760.4"}, {"price": "0.98", "size": "461.14"}, {"price": "0.97", "size": "10.84"}, {"price": "0.94", "size": "600"}, {"price": "0.92", "size": "425"}, {"price": "0.9", "size": "10"}, {"price": "0.89", "size": "296.08"}, {"price": "0.88", "size": "1332"}, {"price": "0.86", "size": "200"}, {"price": "0.85", "size": "2798"}, {"price": "0.83", "size": "152.94"}, {"price": "0.81", "size": "5"}, {"price": "0.8", "size": "125"}, {"price": "0.79", "size": "5"}, {"price": "0.78", "size": "90.9"}, {"price": "0.76", "size": "30"}, {"price": "0.74", "size": "100"}, {"price": "0.72", "size": "2015"}, {"price": "0.71", "size": "6"}, {"price": "0.68", "size": "200"}, {"price": "0.64", "size": "200"}, {"price": "0.62", "size": "250"}, {"price": "0.61", "size": "2851.93"}, {"price": "0.6", "size": "100"}, {"price": "0.58", "size": "29.86"}, {"price": "0.57", "size": "871.66"}, {"price": "0.55", "size": "50"}, {"price": "0.54", "size": "597.87"}, {"price": "0.53", "size": "45.07"}, {"price": "0.51", "size": "100"}, {"price": "0.5", "size": "68.26"}, {"price": "0.49", "size": "1045.51"}, {"price": "0.48", "size": "110.78"}, {"price": "0.47", "size": "67.72"}], "event_type": "book", "last_trade_price": "0.450"}, {"market": "0x5f33f46fa571836f090ef8f3e62caee237f8f73c36a711e757a6f71bf8ef9c6a", "asset_id": "96229871085374132303116376471322311695842738677806841162553339355812305824040", "timestamp": "1769384286741", "hash": "c35231f3cc74711c0be665be4761484922ddb5c0", "bids": [{"price": "0.01", "size": "2760.4"}, {"price": "0.02", "size": "461.14"}, {"price": "0.03", "size": "10.84"}, {"price": "0.06", "size": "600"}, {"price": "0.08", "size": "425"}, {"price": "0.1", "size": "10"}, {"price": "0.11", "size": "296.08"}, {"price": "0.12", "size": "1332"}, {"price": "0.14", "size": "200"}, {"price": "0.15", "size": "2798"}, {"price": "0.17", "size": "152.94"}, {"price": "0.19", "size": "5"}, {"price": "0.2", "size": "125"}, {"price": "0.21", "size": "5"}, {"price": "0.22", "size": "90.9"}, {"price": "0.24", "size": "30"}, {"price": "0.26", "size": "100"}, {"price": "0.28", "size": "2015"}, {"price": "0.29", "size": "6"}, {"price": "0.32", "size": "200"}, {"price": "0.36", "size": "200"}, {"price": "0.38", "size": "250"}, {"price": "0.39", "size": "2851.93"}, {"price": "0.4", "size": "100"}, {"price": "0.42", "size": "29.86"}, {"price": "0.43", "size": "871.66"}, {"price": "0.45", "size": "50"}, {"price": "0.46", "size": "597.87"}, {"price": "0.47", "size": "45.07"}, {"price": "0.49", "size": "100"}, {"price": "0.5", "size": "68.26"}, {"price": "0.51", "size": "1045.51"}, {"price": "0.52", "size": "110.78"}, {"price": "0.53", "size": "67.72"}], "asks": [{"price": "0.99", "size": "2260.33"}, {"price": "0.98", "size": "1000"}, {"price": "0.97", "size": "11.21"}, {"price": "0.95", "size": "885.41"}, {"price": "0.94", "size": "1000"}, {"price": "0.93", "size": "10485.71"}, {"price": "0.91", "size": "5355.55"}, {"price": "0.9", "size": "177.11"}, {"price": "0.89", "size": "1459.09"}, {"price": "0.88", "size": "483.33"}, {"price": "0.87", "size": "3230"}, {"price": "0.86", "size": "185.71"}, {"price": "0.84", "size": "150"}, {"price": "0.82", "size": "111.11"}, {"price": "0.8", "size": "10087.51"}, {"price": "0.78", "size": "100"}, {"price": "0.77", "size": "70"}, {"price": "0.75", "size": "15"}, {"price": "0.7", "size": "23.73"}, {"price": "0.67", "size": "3030"}, {"price": "0.66", "size": "310"}, {"price": "0.65", "size": "5000"}, {"price": "0.64", "size": "100"}, {"price": "0.63", "size": "380"}, {"price": "0.62", "size": "100"}, {"price": "0.61", "size": "355.45"}, {"price": "0.6", "size": "1405"}, {"price": "0.59", "size": "250"}, {"price": "0.58", "size": "1856.14"}, {"price": "0.57", "size": "5311.18"}, {"price": "0.56", "size": "454.17"}, {"price": "0.55", "size": "12.69"}], "event_type": "book", "last_trade_price": "0.450"}, {"market": "0xa65fe234ac3808801290874c631e55bcfee30e437c78239808729a89d9f2de22", "asset_id": "11132544244839265378732084165256379227175677028258955804895976429843086532411", "timestamp": "1769384421810", "hash": "690cf5e19103d3f6f6c0d5a43acd04bbc8c02a9f", "bids": [{"price": "0.01", "size": "9500"}, {"price": "0.02", "size": "18.49"}, {"price": "0.05", "size": "30"}, {"price": "0.06", "size": "283"}, {"price": "0.09", "size": "400"}, {"price": "0.1", "size": "6.3"}, {"price": "0.11", "size": "1072.58"}, {"price": "0.14", "size": "242.85"}, {"price": "0.15", "size": "5"}, {"price": "0.19", "size": "168.42"}, {"price": "0.2", "size": "805"}, {"price": "0.23", "size": "1194.3"}, {"price": "0.24", "size": "1748"}, {"price": "0.28", "size": "92.85"}, {"price": "0.33", "size": "72.72"}, {"price": "0.35", "size": "660.8"}, {"price": "0.37", "size": "2871.55"}, {"price": "0.38", "size": "1578"}, {"price": "0.4", "size": "55.55"}, {"price": "0.55", "size": "100"}, {"price": "0.57", "size": "41.25"}, {"price": "0.65", "size": "125.49"}, {"price": "0.66", "size": "41.25"}, {"price": "0.67", "size": "1022.37"}, {"price": "0.74", "size": "40"}, {"price": "0.75", "size": "2137.5"}, {"price": "0.76", "size": "2250"}, {"price": "0.77", "size": "2044.73"}, {"price": "0.8", "size": "5"}, {"price": "0.82", "size": "566.16"}, {"price": "0.84", "size": "100"}, {"price": "0.85", "size": "1696.01"}, {"price": "0.86", "size": "1022.37"}, {"price": "0.88", "size": "1238"}, {"price": "0.89", "size": "3923.05"}, {"price": "0.9", "size": "2785.21"}, {"price": "0.91", "size": "2544.5"}, {"price": "0.92", "size": "25.94"}], "asks": [{"price": "0.99", "size": "907.73"}, {"price": "0.98", "size": "261.02"}, {"price": "0.97", "size": "109.09"}, {"price": "0.96", "size": "14756.12"}, {"price": "0.95", "size": "5153.36"}, {"price": "0.94", "size": "449"}, {"price": "0.93", "size": "2400.36"}], "event_type": "book", "last_trade_price": "0.920"}, {"market": "0x7e50b661a2bedc670bcf32fc9ece12616f6fc4fba5dbe8526292bf3447374009", "asset_id": "47029152085101973226255505664149277121974669906212969183902148537312535402801", "timestamp": "1769384403046", "hash": "d6e6bf010a7ace1a876c1c2098953328283bbdfe", "bids": [{"price": "0.01", "size": "25488.5"}, {"price": "0.02", "size": "466.11"}, {"price": "0.03", "size": "1000"}, {"price": "0.04", "size": "407.28"}, {"price": "0.05", "size": "1455"}, {"price": "0.06", "size": "9852.39"}, {"price": "0.07", "size": "1410.55"}, {"price": "0.08", "size": "907.99"}, {"price": "0.09", "size": "645.08"}], "asks": [{"price": "0.99", "size": "12509.71"}, {"price": "0.98", "size": "5000"}, {"price": "0.97", "size": "9.08"}, {"price": "0.96", "size": "2500"}, {"price": "0.95", "size": "50030"}, {"price": "0.94", "size": "1033"}, {"price": "0.92", "size": "1000"}, {"price": "0.91", "size": "400"}, {"price": "0.9", "size": "6.3"}, {"price": "0.88", "size": "500"}, {"price": "0.86", "size": "20242.85"}, {"price": "0.85", "size": "250"}, {"price": "0.84", "size": "500"}, {"price": "0.82", "size": "677.77"}, {"price": "0.8", "size": "500"}, {"price": "0.79", "size": "760"}, {"price": "0.77", "size": "121.73"}, {"price": "0.75", "size": "500"}, {"price": "0.73", "size": "5230.29"}, {"price": "0.72", "size": "1498"}, {"price": "0.68", "size": "75"}, {"price": "0.64", "size": "55.55"}, {"price": "0.52", "size": "5"}, {"price": "0.5", "size": "20000"}, {"price": "0.49", "size": "50000"}, {"price": "0.32", "size": "200"}, {"price": "0.3", "size": "65.08"}, {"price": "0.19", "size": "500"}, {"price": "0.18", "size": "10"}, {"price": "0.15", "size": "3072.93"}, {"price": "0.13", "size": "5400"}, {"price": "0.12", "size": "1955.88"}, {"price": "0.11", "size": "142.68"}], "event_type": "book", "last_trade_price": "0.110"}, {"market": "0xa65fe234ac3808801290874c631e55bcfee30e437c78239808729a89d9f2de22", "asset_id": "37281046158137671889895383499164526727881692321679587626659940834369685019496", "timestamp": "1769384421810", "hash": "4dd7b6c5ba08ba78f034a3a4eac428af9ce6f48a", "bids": [{"price": "0.01", "size": "907.73"}, {"price": "0.02", "size": "261.02"}, {"price": "0.03", "size": "109.09"}, {"price": "0.04", "size": "14756.12"}, {"price": "0.05", "size": "5153.36"}, {"price": "0.06", "size": "449"}, {"price": "0.07", "size": "2400.36"}], "asks": [{"price": "0.99", "size": "9500"}, {"price": "0.98", "size": "18.49"}, {"price": "0.95", "size": "30"}, {"price": "0.94", "size": "283"}, {"price": "0.91", "size": "400"}, {"price": "0.9", "size": "6.3"}, {"price": "0.89", "size": "1072.58"}, {"price": "0.86", "size": "242.85"}, {"price": "0.85", "size": "5"}, {"price": "0.81", "size": "168.42"}, {"price": "0.8", "size": "805"}, {"price": "0.77", "size": "1194.3"}, {"price": "0.76", "size": "1748"}, {"price": "0.72", "size": "92.85"}, {"price": "0.67", "size": "72.72"}, {"price": "0.65", "size": "660.8"}, {"price": "0.63", "size": "2871.55"}, {"price": "0.62", "size": "1578"}, {"price": "0.6", "size": "55.55"}, {"price": "0.45", "size": "100"}, {"price": "0.43", "size": "41.25"}, {"price": "0.35", "size": "125.49"}, {"price": "0.34", "size": "41.25"}, {"price": "0.33", "size": "1022.37"}, {"price": "0.26", "size": "40"}, {"price": "0.25", "size": "2137.5"}, {"price": "0.24", "size": "2250"}, {"price": "0.23", "size": "2044.73"}, {"price": "0.2", "size": "5"}, {"price": "0.18", "size": "566.16"}, {"price": "0.16", "size": "100"}, {"price": "0.15", "size": "1696.01"}, {"price": "0.14", "size": "1022.37"}, {"price": "0.12", "size": "1238"}, {"price": "0.11", "size": "3923.05"}, {"price": "0.1", "size": "2785.21"}, {"price": "0.09", "size": "2544.5"}, {"price": "0.08", "size": "25.94"}], "event_type": "book", "last_trade_price": "0.920"}]}
{"_local_timestamp": "2026-01-25T23:40:55.899871+00:00", "data": {"market": "0xa65fe234ac3808801290874c631e55bcfee30e437c78239808729a89d9f2de22", "price_changes": [{"asset_id": "37281046158137671889895383499164526727881692321679587626659940834369685019496", "price": "0.1", "size": "2697.58", "side": "SELL", "hash": "bcd92ebac5958e7cfc2a22134086a28faf6ab962", "best_bid": "0.07", "best_ask": "0.08"}, {"asset_id": "11132544244839265378732084165256379227175677028258955804895976429843086532411", "price": "0.9", "size": "2697.58", "side": "BUY", "hash": "4d36a971fef16e30412427c0ef837588713dce3e", "best_bid": "0.92", "best_ask": "0.93"}], "timestamp": "1769384455824", "event_type": "price_change"}}
{"_local_timestamp": "2026-01-25T23:41:02.906493+00:00", "data": {"market": "0x7e50b661a2bedc670bcf32fc9ece12616f6fc4fba5dbe8526292bf3447374009", "price_changes": [{"asset_id": "47029152085101973226255505664149277121974669906212969183902148537312535402801", "price": "0.03", "size": "2566", "side": "BUY", "hash": "be33b4ac15353aafc8fcb1efdf3722ffcc5c7055", "best_bid": "0.09", "best_ask": "0.11"}, {"asset_id": "83552904656813968939383082097054433404653657244784709614448703928529504455469", "price": "0.97", "size": "2566", "side": "SELL", "hash": "bd414a3ba6145e3a9862f7669374234ae7da774f", "best_bid": "0.89", "best_ask": "0.91"}], "timestamp": "1769384462831", "event_type": "price_change"}}
{"_local_timestamp": "2026-01-25T23:41:02.914021+00:00", "data": {"market": "0x7e50b661a2bedc670bcf32fc9ece12616f6fc4fba5dbe8526292bf3447374009", "price_changes": [{"asset_id": "47029152085101973226255505664149277121974669906212969183902148537312535402801", "price": "0.07", "size": "2081.55", "side": "BUY", "hash": "72a3701e69520f6db2cf1fdc7a756ce65f370a74", "best_bid": "0.09", "best_ask": "0.11"}, {"asset_id": "83552904656813968939383082097054433404653657244784709614448703928529504455469", "price": "0.93", "size": "2081.55", "side": "SELL", "hash": "82bb3d00deb47642b2e1136b22a9cfafa4da829b", "best_bid": "0.89", "best_ask": "0.91"}], "timestamp": "1769384462832", "event_type": "price_change"}}
{"_local_timestamp": "2026-01-25T23:41:11.829988+00:00", "data": {"market": "0x6987d084de71031819f82051ea62b29a354628c3e4a22076a2acc197c776080a", "price_changes": [{"asset_id": "63761293627321054794056701530662561252253979399794304476663814039986928052742", "price": "0.31", "size": "1379.92", "side": "SELL", "hash": "9634956ee2a6642946858044750a277cbb6becaa", "best_bid": "0.3", "best_ask": "0.31"}, {"asset_id": "94521268801533640253484626268475643884882213091508756864952897781498391313602", "price": "0.69", "size": "1379.92", "side": "BUY", "hash": "00fc2edf08a90d04a7418309151f46d9e8b10922", "best_bid": "0.69", "best_ask": "0.7"}], "timestamp": "1769384471758", "event_type": "price_change"}}
{"_local_timestamp": "2026-01-25T23:41:14.646686+00:00", "data": {"market": "0xa65fe234ac3808801290874c631e55bcfee30e437c78239808729a89d9f2de22", "price_changes": [{"asset_id": "11132544244839265378732084165256379227175677028258955804895976429843086532411", "price": "0.24", "size": "0", "side": "BUY", "hash": "ded966f4c1dde7eb3cbd5a02ecaa2f43e952d184", "best_bid": "0.92", "best_ask": "0.93"}, {"asset_id": "37281046158137671889895383499164526727881692321679587626659940834369685019496", "price": "0.76", "size": "0", "side": "SELL", "hash": "c7b6e6e3731bdf703aa4d149847f965cd6736d77", "best_bid": "0.07", "best_ask": "0.08"}], "timestamp": "1769384474531", "event_type": "price_change"}}
{"_local_timestamp": "2026-01-25T23:41:14.717988+00:00", "data": {"market": "0x5f33f46fa571836f090ef8f3e62caee237f8f73c36a711e757a6f71bf8ef9c6a", "price_changes": [{"asset_id": "96229871085374132303116376471322311695842738677806841162553339355812305824040", "price": "0.15", "size": "0", "side": "BUY", "hash": "aabcae967b1b144100d6e2aeb47d50c6bcbfeb13", "best_bid": "0.53", "best_ask": "0.55"}, {"asset_id": "3464795463763108108909057219187376740735691886447931192725079515654033695019", "price": "0.85", "size": "0", "side": "SELL", "hash": "5e5c2afe36fee3a1eee0cf6eda7cabe39fa6f4f1", "best_bid": "0.45", "best_ask": "0.47"}], "timestamp": "1769384474536", "event_type": "price_change"}}
{"_local_timestamp": "2026-01-25T23:41:16.987035+00:00", "data": {"market": "0xa65fe234ac3808801290874c631e55bcfee30e437c78239808729a89d9f2de22", "price_changes": [{"asset_id": "37281046158137671889895383499164526727881692321679587626659940834369685019496", "price": "0.1", "size": "2860.02", "side": "SELL", "hash": "41a26874e4fb421440ea60af69bf6124bce56e7d", "best_bid": "0.07", "best_ask": "0.08"}, {"asset_id": "11132544244839265378732084165256379227175677028258955804895976429843086532411", "price": "0.9", "size": "2860.02", "side": "BUY", "hash": "ebb6cc257cf0b4942f902060f37e9753c9a0f75f", "best_bid": "0.92", "best_ask": "0.93"}], "timestamp": "1769384476910", "event_type": "price_change"}}
{"_local_timestamp": "2026-01-25T23:41:25.373717+00:00", "data": {"market": "0xa65fe234ac3808801290874c631e55bcfee30e437c78239808729a89d9f2de22", "price_changes": [{"asset_id": "37281046158137671889895383499164526727881692321679587626659940834369685019496", "price": "0.1", "size": "2697.58", "side": "SELL", "hash": "375c7e5e0b5dd1640f08ec7909493f89843f4cac", "best_bid": "0.07", "best_ask": "0.08"}, {"asset_id": "11132544244839265378732084165256379227175677028258955804895976429843086532411", "price": "0.9", "size": "2697.58", "side": "BUY", "hash": "b8f52cb8f84a5b1011f74b79c3c7b1bf1ef90680", "best_bid": "0.92", "best_ask": "0.93"}], "timestamp": "1769384485299", "event_type": "price_change"}}
{"_local_timestamp": "2026-01-25T23:41:25.656131+00:00", "data": {"market": "0x6987d084de71031819f82051ea62b29a354628c3e4a22076a2acc197c776080a", "price_changes": [{"asset_id": "63761293627321054794056701530662561252253979399794304476663814039986928052742", "price": "0.31", "size": "1391.57", "side": "SELL", "hash": "00706569f6e07c60ec13e40229497121370fe7ac", "best_bid": "0.3", "best_ask": "0.31"}, {"asset_id": "94521268801533640253484626268475643884882213091508756864952897781498391313602", "price": "0.69", "size": "1391.57", "side": "BUY", "hash": "1234799d4e7caabd0216d2b9c700092fb630106e", "best_bid": "0.69", "best_ask": "0.7"}], "timestamp": "1769384485574", "event_type": "price_change"}}
{"_local_timestamp": "2026-01-25T23:41:25.657995+00:00", "data": {"market": "0x6987d084de71031819f82051ea62b29a354628c3e4a22076a2acc197c776080a", "price_changes": [{"asset_id": "63761293627321054794056701530662561252253979399794304476663814039986928052742", "price": "0.31", "size": "1403.22", "side": "SELL", "hash": "959dc2be1eca5894773a0ba4a1b635e7733273ec", "best_bid": "0.3", "best_ask": "0.31"}, {"asset_id": "94521268801533640253484626268475643884882213091508756864952897781498391313602", "price": "0.69", "size": "1403.22", "side": "BUY", "hash": "5248a6aa159dfd5ba7049b2e2b44e1c87ab58223", "best_bid": "0.69", "best_ask": "0.7"}], "timestamp": "1769384485575", "event_type": "price_change"}}
{"_local_timestamp": "2026-01-25T23:41:25.658296+00:00", "data": {"market": "0x6987d084de71031819f82051ea62b29a354628c3e4a22076a2acc197c776080a", "price_changes": [{"asset_id": "63761293627321054794056701530662561252253979399794304476663814039986928052742", "price": "0.31", "size": "1414.87", "side": "SELL", "hash": "ebc978fd4ded3044849759016bd3534b16666046", "best_bid": "0.3", "best_ask": "0.31"}, {"asset_id": "94521268801533640253484626268475643884882213091508756864952897781498391313602", "price": "0.69", "size": "1414.87", "side": "BUY", "hash": "15de9bc502dbb68a7cacc6c3c569d879adc3c6f1", "best_bid": "0.69", "best_ask": "0.7"}], "timestamp": "1769384485576", "event_type": "price_change"}}
{"_local_timestamp": "2026-01-25T23:41:37.269787+00:00", "data": {"market": "0xa65fe234ac3808801290874c631e55bcfee30e437c78239808729a89d9f2de22", "price_changes": [{"asset_id": "11132544244839265378732084165256379227175677028258955804895976429843086532411", "price": "0.25", "size": "1680", "side": "BUY", "hash": "44b76e1fa12a92b5209d6a9cb6b43ab18b9cf9b3", "best_bid": "0.92", "best_ask": "0.93"}, {"asset_id": "37281046158137671889895383499164526727881692321679587626659940834369685019496", "price": "0.75", "size": "1680", "side": "SELL", "hash": "5a30524c62ec623e6764c4b65f9448247d99c268", "best_bid": "0.07", "best_ask": "0.08"}], "timestamp": "1769384497196", "event_type": "price_change"}}
{"_local_timestamp": "2026-01-25T23:41:39.510501+00:00", "data": {"market": "0x5f33f46fa571836f090ef8f3e62caee237f8f73c36a711e757a6f71bf8ef9c6a", "price_changes": [{"asset_id": "96229871085374132303116376471322311695842738677806841162553339355812305824040", "price": "0.16", "size": "2624", "side": "BUY", "hash": "0813d179ff1147dc3c28bdb8ebd15bbae4dccb7c", "best_bid": "0.53", "best_ask": "0.55"}, {"asset_id": "3464795463763108108909057219187376740735691886447931192725079515654033695019", "price": "0.84", "size": "2624", "side": "SELL", "hash": "78309d165a30d338fcfcd37b74c9d94908883dbb", "best_bid": "0.45", "best_ask": "0.47"}], "timestamp": "1769384499438", "event_type": "price_change"}}
{"_local_timestamp": "2026-01-25T23:41:54.594107+00:00", "data": {"market": "0xa65fe234ac3808801290874c631e55bcfee30e437c78239808729a89d9f2de22", "price_changes": [{"asset_id": "37281046158137671889895383499164526727881692321679587626659940834369685019496", "price": "0.11", "size": "4085.49", "side": "SELL", "hash": "3cba09a05d7b0586e6392091b6fae3dc97ce777e", "best_bid": "0.07", "best_ask": "0.08"}, {"asset_id": "11132544244839265378732084165256379227175677028258955804895976429843086532411", "price": "0.89", "size": "4085.49", "side": "BUY", "hash": "ebca89034c6d8de8da46c39b8596407638aa101f", "best_bid": "0.92", "best_ask": "0.93"}], "timestamp": "1769384514516", "event_type": "price_change"}}
{"_local_timestamp": "2026-01-25T23:42:29.292887+00:00", "data": {"market": "0x6987d084de71031819f82051ea62b29a354628c3e4a22076a2acc197c776080a", "price_changes": [{"asset_id": "94521268801533640253484626268475643884882213091508756864952897781498391313602", "price": "0.66", "size": "1554.22", "side": "BUY", "hash": "aae2216a9297d49c8c6cf1891c2818ed6146b590", "best_bid": "0.69", "best_ask": "0.7"}, {"asset_id": "63761293627321054794056701530662561252253979399794304476663814039986928052742", "price": "0.34", "size": "1554.22", "side": "SELL", "hash": "f4c0c2903a45ae1c46b573994eef0ce4c907c7d4", "best_bid": "0.3", "best_ask": "0.31"}], "timestamp": "1769384549185", "event_type": "price_change"}}
{"_local_timestamp": "2026-01-25T23:42:29.293900+00:00", "data": {"market": "0x6987d084de71031819f82051ea62b29a354628c3e4a22076a2acc197c776080a", "price_changes": [{"asset_id": "94521268801533640253484626268475643884882213091508756864952897781498391313602", "price": "0.67", "size": "273.78", "side": "BUY", "hash": "68f7ad7da534401b51e7a81541d7294472dd7283", "best_bid": "0.69", "best_ask": "0.7"}, {"asset_id": "63761293627321054794056701530662561252253979399794304476663814039986928052742", "price": "0.33", "size": "273.78", "side": "SELL", "hash": "f7ddb21b7994ad8786713b4525df54f68d0e773c", "best_bid": "0.3", "best_ask": "0.31"}], "timestamp": "1769384549186", "event_type": "price_change"}}
{"_local_timestamp": "2026-01-25T23:42:47.203339+00:00", "data": {"market": "0xa65fe234ac3808801290874c631e55bcfee30e437c78239808729a89d9f2de22", "price_changes": [{"asset_id": "11132544244839265378732084165256379227175677028258955804895976429843086532411", "price": "0.25", "size": "0", "side": "BUY", "hash": "d3aa6b644a1d7f3f644a4205c8f0826441dce600", "best_bid": "0.92", "best_ask": "0.93"}, {"asset_id": "37281046158137671889895383499164526727881692321679587626659940834369685019496", "price": "0.75", "size": "0", "side": "SELL", "hash": "6a5bef1363cec3cd1d95f26b3ced81e6b473dea7", "best_bid": "0.07", "best_ask": "0.08"}], "timestamp": "1769384566988", "event_type": "price_change"}}
{"_local_timestamp": "2026-01-25T23:42:47.206831+00:00", "data": {"market": "0x5f33f46fa571836f090ef8f3e62caee237f8f73c36a711e757a6f71bf8ef9c6a", "price_changes": [{"asset_id": "96229871085374132303116376471322311695842738677806841162553339355812305824040", "price": "0.16", "size": "0", "side": "BUY", "hash": "eb3fbd6004358c4417b3067943e13b7a011b3d8f", "best_bid": "0.53", "best_ask": "0.55"}, {"asset_id": "3464795463763108108909057219187376740735691886447931192725079515654033695019", "price": "0.84", "size": "0", "side": "SELL", "hash": "292c838c13177f2862d8c3112eafd79217adf9fb", "best_bid": "0.45", "best_ask": "0.47"}], "timestamp": "1769384566989", "event_type": "price_change"}}
{"_local_timestamp": "2026-01-25T23:42:56.072505+00:00", "data": {"market": "0x6987d084de71031819f82051ea62b29a354628c3e4a22076a2acc197c776080a", "price_changes": [{"asset_id": "94521268801533640253484626268475643884882213091508756864952897781498391313602", "price": "0.67", "size": "223.78", "side": "BUY", "hash": "10d1229979b88d82ffb0dd2fb3d6357c645202c2", "best_bid": "0.69", "best_ask": "0.7"}, {"asset_id": "63761293627321054794056701530662561252253979399794304476663814039986928052742", "price": "0.33", "size": "223.78", "side": "SELL", "hash": "20c53569305e4e3dee44d1a6e099db8edf64f220", "best_bid": "0.3", "best_ask": "0.31"}], "timestamp": "1769384575966", "event_type": "price_change"}}
{"_local_timestamp": "2026-01-25T23:42:56.073270+00:00", "data": {"market": "0x6987d084de71031819f82051ea62b29a354628c3e4a22076a2acc197c776080a", "price_changes": [{"asset_id": "94521268801533640253484626268475643884882213091508756864952897781498391313602", "price": "0.66", "size": "1504.22", "side": "BUY", "hash": "10d1229979b88d82ffb0dd2fb3d6357c645202c2", "best_bid": "0.69", "best_ask": "0.7"}, {"asset_id": "63761293627321054794056701530662561252253979399794304476663814039986928052742", "price": "0.34", "size": "1504.22", "side": "SELL", "hash": "20c53569305e4e3dee44d1a6e099db8edf64f220", "best_bid": "0.3", "best_ask": "0.31"}], "timestamp": "1769384575966", "event_type": "price_change"}}
{"_local_timestamp": "2026-01-25T23:43:08.846114+00:00", "data": {"market": "0xa65fe234ac3808801290874c631e55bcfee30e437c78239808729a89d9f2de22", "price_changes": [{"asset_id": "37281046158137671889895383499164526727881692321679587626659940834369685019496", "price": "0.04", "size": "14743.45", "side": "BUY", "hash": "8152c968f247f831681fdc9ed18d829a946d7cbe", "best_bid": "0.07", "best_ask": "0.08"}, {"asset_id": "11132544244839265378732084165256379227175677028258955804895976429843086532411", "price": "0.96", "size": "14743.45", "side": "SELL", "hash": "b3df41d5f7a5123b5b69482dc98a1e1736cafd6c", "best_bid": "0.92", "best_ask": "0.93"}], "timestamp": "1769384588738", "event_type": "price_change"}}
{"_local_timestamp": "2026-01-25T23:43:08.846533+00:00", "data": {"market": "0xa65fe234ac3808801290874c631e55bcfee30e437c78239808729a89d9f2de22", "price_changes": [{"asset_id": "11132544244839265378732084165256379227175677028258955804895976429843086532411", "price": "0.02", "size": "0", "side": "BUY", "hash": "2064588ac02fb267a6e9a5caf53d0ef8139283f1", "best_bid": "0.92", "best_ask": "0.93"}, {"asset_id": "37281046158137671889895383499164526727881692321679587626659940834369685019496", "price": "0.98", "size": "0", "side": "SELL", "hash": "80fedffb0cdea7a785d630fe737981f642fd3845", "best_bid": "0.07", "best_ask": "0.08"}], "timestamp": "1769384588738", "event_type": "price_change"}}
{"_local_timestamp": "2026-01-25T23:43:09.237811+00:00", "data": {"market": "0xa65fe234ac3808801290874c631e55bcfee30e437c78239808729a89d9f2de22", "price_changes": [{"asset_id": "37281046158137671889895383499164526727881692321679587626659940834369685019496", "price": "0.04", "size": "14756.12", "side": "BUY", "hash": "d6dda7964e73dc4037f82952b244f91bf3e2ee0a", "best_bid": "0.07", "best_ask": "0.08"}, {"asset_id": "11132544244839265378732084165256379227175677028258955804895976429843086532411", "price": "0.96", "size": "14756.12", "side": "SELL", "hash": "53a4d150ff4a3d5ef001826eb88a9f854e041529", "best_bid": "0.92", "best_ask": "0.93"}], "timestamp": "1769384589127", "event_type": "price_change"}}
{"_local_timestamp": "2026-01-25T23:43:09.238302+00:00", "data": {"market": "0xa65fe234ac3808801290874c631e55bcfee30e437c78239808729a89d9f2de22", "price_changes": [{"asset_id": "11132544244839265378732084165256379227175677028258955804895976429843086532411", "price": "0.02", "size": "18.49", "side": "BUY", "hash": "ba4dafb3bf1ee9fa731f3a25949d27fb70d43b3d", "best_bid": "0.92", "best_ask": "0.93"}, {"asset_id": "37281046158137671889895383499164526727881692321679587626659940834369685019496", "price": "0.98", "size": "18.49", "side": "SELL", "hash": "b1214fca73610067772c4b309314b3d5d5d482b0", "best_bid": "0.07", "best_ask": "0.08"}], "timestamp": "1769384589128", "event_type": "price_change"}}
{"_local_timestamp": "2026-01-25T23:43:14.512958+00:00", "data": {"market": "0x5f33f46fa571836f090ef8f3e62caee237f8f73c36a711e757a6f71bf8ef9c6a", "price_changes": [{"asset_id": "96229871085374132303116376471322311695842738677806841162553339355812305824040", "price": "0.15", "size": "2798", "side": "BUY", "hash": "7e6c338c0d69a1957062d25636a6a21c942945bf", "best_bid": "0.53", "best_ask": "0.55"}, {"asset_id": "3464795463763108108909057219187376740735691886447931192725079515654033695019", "price": "0.85", "size": "2798", "side": "SELL", "hash": "9981516c40710817bd90e662c0657be345796aea", "best_bid": "0.45", "best_ask": "0.47"}], "timestamp": "1769384594373", "event_type": "price_change"}}
{"_local_timestamp": "2026-01-25T23:43:18.985720+00:00", "data": {"market": "0xa65fe234ac3808801290874c631e55bcfee30e437c78239808729a89d9f2de22", "price_changes": [{"asset_id": "37281046158137671889895383499164526727881692321679587626659940834369685019496", "price": "0.06", "size": "199", "side": "BUY", "hash": "ec2cc9be58e1633abb4fc2202cfb1075ccb34c65", "best_bid": "0.07", "best_ask": "0.08"}, {"asset_id": "11132544244839265378732084165256379227175677028258955804895976429843086532411", "price": "0.94", "size": "199", "side": "SELL", "hash": "3e7c457ddc023c632301044adefacc7c89af7092", "best_bid": "0.92", "best_ask": "0.93"}], "timestamp": "1769384598863", "event_type": "price_change"}}
{"_local_timestamp": "2026-01-25T23:43:19.028153+00:00", "data": {"market": "0xa65fe234ac3808801290874c631e55bcfee30e437c78239808729a89d9f2de22", "price_changes": [{"asset_id": "11132544244839265378732084165256379227175677028258955804895976429843086532411", "price": "0.91", "size": "2419.5", "side": "BUY", "hash": "6836b903f095ffbe7045f687d2d0c32b81c4edb9", "best_bid": "0.92", "best_ask": "0.93"}, {"asset_id": "37281046158137671889895383499164526727881692321679587626659940834369685019496", "price": "0.09", "size": "2419.5", "side": "SELL", "hash": "8aad9971fa13ee42bed532608533895d58394168", "best_bid": "0.07", "best_ask": "0.08"}], "timestamp": "1769384598903", "event_type": "price_change"}}
{"_local_timestamp": "2026-01-25T23:43:19.173621+00:00", "data": {"market": "0xa65fe234ac3808801290874c631e55bcfee30e437c78239808729a89d9f2de22", "price_changes": [{"asset_id": "11132544244839265378732084165256379227175677028258955804895976429843086532411", "price": "0.9", "size": "2597.58", "side": "BUY", "hash": "24e5f8d1ac86361d93b8c164ac23f1d1e902a15a", "best_bid": "0.92", "best_ask": "0.93"}, {"asset_id": "37281046158137671889895383499164526727881692321679587626659940834369685019496", "price": "0.1", "size": "2597.58", "side": "SELL", "hash": "04e89df43844444100f1fd00f3f2644a9bebcadf", "best_bid": "0.07", "best_ask": "0.08"}], "timestamp": "1769384599007", "event_type": "price_change"}}
{"_local_timestamp": "2026-01-25T23:43:19.174099+00:00", "data": {"market": "0xa65fe234ac3808801290874c631e55bcfee30e437c78239808729a89d9f2de22", "price_changes": [{"asset_id": "37281046158137671889895383499164526727881692321679587626659940834369685019496", "price": "0.06", "size": "99", "side": "BUY", "hash": "ece7e76a3d5146c64ff92439b0de4c27026bdd89", "best_bid": "0.07", "best_ask": "0.08"}, {"asset_id": "11132544244839265378732084165256379227175677028258955804895976429843086532411", "price": "0.94", "size": "99", "side": "SELL", "hash": "9244af9f074f6d8530710698f6da0c06d1f7b246", "best_bid": "0.92", "best_ask": "0.93"}], "timestamp": "1769384599008", "event_type": "price_change"}}
{"_local_timestamp": "2026-01-25T23:43:19.315776+00:00", "data": {"market": "0xa65fe234ac3808801290874c631e55bcfee30e437c78239808729a89d9f2de22", "price_changes": [{"asset_id": "11132544244839265378732084165256379227175677028258955804895976429843086532411", "price": "0.9", "size": "2697.58", "side": "BUY", "hash": "4f1633c86705954d352017579bbb773e99b8c236", "best_bid": "0.92", "best_ask": "0.93"}, {"asset_id": "37281046158137671889895383499164526727881692321679587626659940834369685019496", "price": "0.1", "size": "2697.58", "side": "SELL", "hash": "6756dfb4346590ed379cb2ec32591527593ddf88", "best_bid": "0.07", "best_ask": "0.08"}], "timestamp": "1769384599191", "event_type": "price_change"}}
{"_local_timestamp": "2026-01-25T23:43:19.316268+00:00", "data": {"market": "0xa65fe234ac3808801290874c631e55bcfee30e437c78239808729a89d9f2de22", "price_changes": [{"asset_id": "37281046158137671889895383499164526727881692321679587626659940834369685019496", "price": "0.05", "size": "5253.36", "side": "BUY", "hash": "b0445fcef477a88c62e3c44d2f42b575f7f492a8", "best_bid": "0.07", "best_ask": "0.08"}, {"asset_id": "11132544244839265378732084165256379227175677028258955804895976429843086532411", "price": "0.95", "size": "5253.36", "side": "SELL", "hash": "2de5f3a5638ba40fd2a3dbdf738c366b2bc6ad3a", "best_bid": "0.92", "best_ask": "0.93"}], "timestamp": "1769384599192", "event_type": "price_change"}}
{"_local_timestamp": "2026-01-25T23:43:52.344928+00:00", "data": {"market": "0xa65fe234ac3808801290874c631e55bcfee30e437c78239808729a89d9f2de22", "price_changes": [{"asset_id": "11132544244839265378732084165256379227175677028258955804895976429843086532411", "price": "0.24", "size": "1748", "side": "BUY", "hash": "033cb18d401d8480c3cf49ffb5536b06c22e9a07", "best_bid": "0.92", "best_ask": "0.93"}, {"asset_id": "37281046158137671889895383499164526727881692321679587626659940834369685019496", "price": "0.76", "size": "1748", "side": "SELL", "hash": "b89ef3fa2411843a2bf4ad1ec38df4b37135247a", "best_bid": "0.07", "best_ask": "0.08"}], "timestamp": "1769384632179", "event_type": "price_change"}}
{"_local_timestamp": "2026-01-25T23:44:09.537401+00:00", "data": {"market": "0x6987d084de71031819f82051ea62b29a354628c3e4a22076a2acc197c776080a", "price_changes": [{"asset_id": "94521268801533640253484626268475643884882213091508756864952897781498391313602", "price": "0.65", "size": "2073.32", "side": "BUY", "hash": "4187b9ba439e6b5f52a7cd87fa38365152663abe", "best_bid": "0.69", "best_ask": "0.7"}, {"asset_id": "63761293627321054794056701530662561252253979399794304476663814039986928052742", "price": "0.35", "size": "2073.32", "side": "SELL", "hash": "60148b37579dd433ebf2cbf73a46831aebb40dc1", "best_bid": "0.3", "best_ask": "0.31"}], "timestamp": "1769384649390", "event_type": "price_change"}}
{"_local_timestamp": "2026-01-25T23:44:09.568252+00:00", "data": {"market": "0x6987d084de71031819f82051ea62b29a354628c3e4a22076a2acc197c776080a", "price_changes": [{"asset_id": "94521268801533640253484626268475643884882213091508756864952897781498391313602", "price": "0.66", "size": "1514.22", "side": "BUY", "hash": "f65735b09c398164ecee6f6872c925824e2129bd", "best_bid": "0.69", "best_ask": "0.7"}, {"asset_id": "63761293627321054794056701530662561252253979399794304476663814039986928052742", "price": "0.34", "size": "1514.22", "side": "SELL", "hash": "e391713a47820a275552d7bd1743e83a3249aedf", "best_bid": "0.3", "best_ask": "0.31"}], "timestamp": "1769384649420", "event_type": "price_change"}}
{"_local_timestamp": "2026-01-25T23:44:09.595859+00:00", "data": {"market": "0x6987d084de71031819f82051ea62b29a354628c3e4a22076a2acc197c776080a", "price_changes": [{"asset_id": "94521268801533640253484626268475643884882213091508756864952897781498391313602", "price": "0.67", "size": "233.78", "side": "BUY", "hash": "b3b1619201b0afc64cc557d1935ba9d839e066f1", "best_bid": "0.69", "best_ask": "0.7"}, {"asset_id": "63761293627321054794056701530662561252253979399794304476663814039986928052742", "price": "0.33", "size": "233.78", "side": "SELL", "hash": "f8e6985b0fe6e8c3c983f59004f021a4fca4368e", "best_bid": "0.3", "best_ask": "0.31"}], "timestamp": "1769384649448", "event_type": "price_change"}}
{"_local_timestamp": "2026-01-25T23:44:09.619954+00:00", "data": {"market": "0x6987d084de71031819f82051ea62b29a354628c3e4a22076a2acc197c776080a", "price_changes": [{"asset_id": "94521268801533640253484626268475643884882213091508756864952897781498391313602", "price": "0.68", "size": "870.82", "side": "BUY", "hash": "b492be9b7e89f492579fbcd2f641f0f655c6e896", "best_bid": "0.69", "best_ask": "0.7"}, {"asset_id": "63761293627321054794056701530662561252253979399794304476663814039986928052742", "price": "0.32", "size": "870.82", "side": "SELL", "hash": "c0fac12e5074371a1b4e702475aefdcf5955e8dd", "best_bid": "0.3", "best_ask": "0.31"}], "timestamp": "1769384649476", "event_type": "price_change"}}
{"_local_timestamp": "2026-01-25T23:44:09.658542+00:00", "data": {"market": "0x6987d084de71031819f82051ea62b29a354628c3e4a22076a2acc197c776080a", "price_changes": [{"asset_id": "94521268801533640253484626268475643884882213091508756864952897781498391313602", "price": "0.69", "size": "1424.87", "side": "BUY", "hash": "cb433001e7e1ddf4a9f4112a14c2d668cdfe5fe4", "best_bid": "0.69", "best_ask": "0.7"}, {"asset_id": "63761293627321054794056701530662561252253979399794304476663814039986928052742", "price": "0.31", "size": "1424.87", "side": "SELL", "hash": "70843312a51a822ff231067058bd097b7f24bc48", "best_bid": "0.3", "best_ask": "0.31"}], "timestamp": "1769384649507", "event_type": "price_change"}}
{"_local_timestamp": "2026-01-25T23:44:09.688764+00:00", "data": {"market": "0x6987d084de71031819f82051ea62b29a354628c3e4a22076a2acc197c776080a", "price_changes": [{"asset_id": "63761293627321054794056701530662561252253979399794304476663814039986928052742", "price": "0.26", "size": "10", "side": "BUY", "hash": "47c5622afd9e527aa0f4ff8b79e2b823eaaac597", "best_bid": "0.3", "best_ask": "0.31"}, {"asset_id": "94521268801533640253484626268475643884882213091508756864952897781498391313602", "price": "0.74", "size": "10", "side": "SELL", "hash": "a011e457dff9c0b94f25a7a303efa41b646f5c26", "best_bid": "0.69", "best_ask": "0.7"}], "timestamp": "1769384649537", "event_type": "price_change"}}
{"_local_timestamp": "2026-01-25T23:44:09.722411+00:00", "data": {"market": "0x6987d084de71031819f82051ea62b29a354628c3e4a22076a2acc197c776080a", "price_changes": [{"asset_id": "63761293627321054794056701530662561252253979399794304476663814039986928052742", "price": "0.27", "size": "35", "side": "BUY", "hash": "02ec077628de2ba4cd9572d0f354302eee583673", "best_bid": "0.3", "best_ask": "0.31"}, {"asset_id": "94521268801533640253484626268475643884882213091508756864952897781498391313602", "price": "0.73", "size": "35", "side": "SELL", "hash": "52aae6f800a1081f6cebcbcfb4d67596907d641b", "best_bid": "0.69", "best_ask": "0.7"}], "timestamp": "1769384649569", "event_type": "price_change"}}
{"_local_timestamp": "2026-01-25T23:44:09.745948+00:00", "data": {"market": "0x6987d084de71031819f82051ea62b29a354628c3e4a22076a2acc197c776080a", "price_changes": [{"asset_id": "63761293627321054794056701530662561252253979399794304476663814039986928052742", "price": "0.28", "size": "615.72", "side": "BUY", "hash": "23efb2981067ffb8f760e77f847394f706fd45af", "best_bid": "0.3", "best_ask": "0.31"}, {"asset_id": "94521268801533640253484626268475643884882213091508756864952897781498391313602", "price": "0.72", "size": "615.72", "side": "SELL", "hash": "48962c2f366ef7f92bba16a5cd68770c4e4373b4", "best_bid": "0.69", "best_ask": "0.7"}], "timestamp": "1769384649600", "event_type": "price_change"}}
{"_local_timestamp": "2026-01-25T23:44:09.797862+00:00", "data": {"market": "0x6987d084de71031819f82051ea62b29a354628c3e4a22076a2acc197c776080a", "price_changes": [{"asset_id": "63761293627321054794056701530662561252253979399794304476663814039986928052742", "price": "0.29", "size": "807.07", "side": "BUY", "hash": "a9b914d58b5df8114e8d1428cc76a28e3175628b", "best_bid": "0.3", "best_ask": "0.31"}, {"asset_id": "94521268801533640253484626268475643884882213091508756864952897781498391313602", "price": "0.71", "size": "807.07", "side": "SELL", "hash": "73d7d1e603d2148a79eb14c531b38048ed294c66", "best_bid": "0.69", "best_ask": "0.7"}], "timestamp": "1769384649645", "event_type": "price_change"}}
{"_local_timestamp": "2026-01-25T23:44:09.824163+00:00", "data": {"market": "0x6987d084de71031819f82051ea62b29a354628c3e4a22076a2acc197c776080a", "price_changes": [{"asset_id": "63761293627321054794056701530662561252253979399794304476663814039986928052742", "price": "0.3", "size": "326.37", "side": "BUY", "hash": "66587131e370e674d4d8e51b947141b5b3928e9a", "best_bid": "0.3", "best_ask": "0.31"}, {"asset_id": "94521268801533640253484626268475643884882213091508756864952897781498391313602", "price": "0.7", "size": "326.37", "side": "SELL", "hash": "b51a636d556648f1ab07179c098a5b843486e510", "best_bid": "0.69", "best_ask": "0.7"}], "timestamp": "1769384649676", "event_type": "price_change"}}
{"_local_timestamp": "2026-01-25T23:44:32.597533+00:00", "data": {"market": "0x5f33f46fa571836f090ef8f3e62caee237f8f73c36a711e757a6f71bf8ef9c6a", "price_changes": [{"asset_id": "96229871085374132303116376471322311695842738677806841162553339355812305824040", "price": "0.15", "size": "0", "side": "BUY", "hash": "adb45b5e4d2ad8d0fec9df1bcc7e20810a9f81e6", "best_bid": "0.53", "best_ask": "0.55"}, {"asset_id": "3464795463763108108909057219187376740735691886447931192725079515654033695019", "price": "0.85", "size": "0", "side": "SELL", "hash": "084267544cbc8e5b8b988e5d45aa39b4d853139c", "best_bid": "0.45", "best_ask": "0.47"}], "timestamp": "1769384672290", "event_type": "price_change"}}
{"_local_timestamp": "2026-01-25T23:44:32.607030+00:00", "data": {"market": "0xa65fe234ac3808801290874c631e55bcfee30e437c78239808729a89d9f2de22", "price_changes": [{"asset_id": "11132544244839265378732084165256379227175677028258955804895976429843086532411", "price": "0.24", "size": "0", "side": "BUY", "hash": "ba9a950221417a190eed06384ecb7b1bdc8d37fc", "best_bid": "0.92", "best_ask": "0.93"}, {"asset_id": "37281046158137671889895383499164526727881692321679587626659940834369685019496", "price": "0.76", "size": "0", "side": "SELL", "hash": "5f12909850d2dfb0ceaedbabf179d6af30e11b87", "best_bid": "0.07", "best_ask": "0.08"}], "timestamp": "1769384672291", "event_type": "price_change"}}
{"_local_timestamp": "2026-01-25T23:44:32.797933+00:00", "data": {"market": "0xa65fe234ac3808801290874c631e55bcfee30e437c78239808729a89d9f2de22", "price_changes": [{"asset_id": "37281046158137671889895383499164526727881692321679587626659940834369685019496", "price": "0.06", "size": "349", "side": "BUY", "hash": "3f622a0d4fb50187a4643f3ca45fe6624ac05e0e", "best_bid": "0.07", "best_ask": "0.08"}, {"asset_id": "11132544244839265378732084165256379227175677028258955804895976429843086532411", "price": "0.94", "size": "349", "side": "SELL", "hash": "4fe28d234efb3bea31dddb7552d7c53ce673a9be", "best_bid": "0.92", "best_ask": "0.93"}], "timestamp": "1769384672515", "event_type": "price_change"}}
{"_local_timestamp": "2026-01-25T23:44:32.964399+00:00", "data": {"market": "0xa65fe234ac3808801290874c631e55bcfee30e437c78239808729a89d9f2de22", "price_changes": [{"asset_id": "11132544244839265378732084165256379227175677028258955804895976429843086532411", "price": "0.91", "size": "2544.5", "side": "BUY", "hash": "37aec47208629e324e4a3838bcc7fa20d9924760", "best_bid": "0.92", "best_ask": "0.93"}, {"asset_id": "37281046158137671889895383499164526727881692321679587626659940834369685019496", "price": "0.09", "size": "2544.5", "side": "SELL", "hash": "c8b1f169ba14985f2bd7084e903502b5c968db84", "best_bid": "0.07", "best_ask": "0.08"}], "timestamp": "1769384672680", "event_type": "price_change"}}
{"_local_timestamp": "2026-01-25T23:44:33.540977+00:00", "data": {"market": "0xa65fe234ac3808801290874c631e55bcfee30e437c78239808729a89d9f2de22", "price_changes": [{"asset_id": "11132544244839265378732084165256379227175677028258955804895976429843086532411", "price": "0.9", "size": "2597.58", "side": "BUY", "hash": "c515169c102bfcf0c2d62bdecb1d080291333ac6", "best_bid": "0.92", "best_ask": "0.93"}, {"asset_id": "37281046158137671889895383499164526727881692321679587626659940834369685019496", "price": "0.1", "size": "2597.58", "side": "SELL", "hash": "9d3c361e05827bf08bf21119e81d9d25290f47ff", "best_bid": "0.07", "best_ask": "0.08"}], "timestamp": "1769384673246", "event_type": "price_change"}}
{"_local_timestamp": "2026-01-25T23:44:33.541293+00:00", "data": {"market": "0xa65fe234ac3808801290874c631e55bcfee30e437c78239808729a89d9f2de22", "price_changes": [{"asset_id": "37281046158137671889895383499164526727881692321679587626659940834369685019496", "price": "0.05", "size": "5153.36", "side": "BUY", "hash": "0b176dc458363994e6f9fef1896e91598653ec51", "best_bid": "0.07", "best_ask": "0.08"}, {"asset_id": "11132544244839265378732084165256379227175677028258955804895976429843086532411", "price": "0.95", "size": "5153.36", "side": "SELL", "hash": "86ac56ee5bf502a15272f36cd23ca41fe8884d14", "best_bid": "0.92", "best_ask": "0.93"}], "timestamp": "1769384673247", "event_type": "price_change"}}
{"_local_timestamp": "2026-01-25T23:44:33.680970+00:00", "data": {"market": "0xa65fe234ac3808801290874c631e55bcfee30e437c78239808729a89d9f2de22", "price_changes": [{"asset_id": "11132544244839265378732084165256379227175677028258955804895976429843086532411", "price": "0.9", "size": "2697.58", "side": "BUY", "hash": "7f492f627fedb41d195c170f0b53f7b671876c91", "best_bid": "0.92", "best_ask": "0.93"}, {"asset_id": "37281046158137671889895383499164526727881692321679587626659940834369685019496", "price": "0.1", "size": "2697.58", "side": "SELL", "hash": "b8b05dae48136690d19a5d73a3374d19b26f305b", "best_bid": "0.07", "best_ask": "0.08"}], "timestamp": "1769384673399", "event_type": "price_change"}}
{"_local_timestamp": "2026-01-25T23:44:33.681366+00:00", "data": {"market": "0xa65fe234ac3808801290874c631e55bcfee30e437c78239808729a89d9f2de22", "price_changes": [{"asset_id": "37281046158137671889895383499164526727881692321679587626659940834369685019496", "price": "0.06", "size": "449", "side": "BUY", "hash": "db112f5a8536b6974db7901eb20c902ad84d9787", "best_bid": "0.07", "best_ask": "0.08"}, {"asset_id": "11132544244839265378732084165256379227175677028258955804895976429843086532411", "price": "0.94", "size": "449", "side": "SELL", "hash": "b4fe563121921ef3387289fafce43f32f60efb67", "best_bid": "0.92", "best_ask": "0.93"}], "timestamp": "1769384673400", "event_type": "price_change"}}
{"_local_timestamp": "2026-01-25T23:44:49.766699+00:00", "data": {"market": "0x5f33f46fa571836f090ef8f3e62caee237f8f73c36a711e757a6f71bf8ef9c6a", "price_changes": [{"asset_id": "96229871085374132303116376471322311695842738677806841162553339355812305824040", "price": "0.16", "size": "2624", "side": "BUY", "hash": "bbf5ae5c30e9cc4505f775875bb080335ffdf819", "best_bid": "0.53", "best_ask": "0.55"}, {"asset_id": "3464795463763108108909057219187376740735691886447931192725079515654033695019", "price": "0.84", "size": "2624", "side": "SELL", "hash": "01c1d31df5149f971b73f12bc78a8f8803f92e26", "best_bid": "0.45", "best_ask": "0.47"}], "timestamp": "1769384689586", "event_type": "price_change"}}
{"_local_timestamp": "2026-01-25T23:44:57.042813+00:00", "data": {"market": "0x6987d084de71031819f82051ea62b29a354628c3e4a22076a2acc197c776080a", "price_changes": [{"asset_id": "63761293627321054794056701530662561252253979399794304476663814039986928052742", "price": "0.28", "size": "565.72", "side": "BUY", "hash": "b6058364b2254856a2b0a580ec08e8e14ff9b657", "best_bid": "0.3", "best_ask": "0.31"}, {"asset_id": "94521268801533640253484626268475643884882213091508756864952897781498391313602", "price": "0.72", "size": "565.72", "side": "SELL", "hash": "9a6aa1206f7e61b6f6708b689ec7172b11daf36b", "best_bid": "0.69", "best_ask": "0.7"}], "timestamp": "1769384696918", "event_type": "price_change"}}
{"_local_timestamp": "2026-01-25T23:44:57.057078+00:00", "data": {"market": "0x6987d084de71031819f82051ea62b29a354628c3e4a22076a2acc197c776080a", "price_changes": [{"asset_id": "94521268801533640253484626268475643884882213091508756864952897781498391313602", "price": "0.67", "size": "183.78", "side": "BUY", "hash": "8deca41755b061482442e3c6e4c73cb55dce7e33", "best_bid": "0.69", "best_ask": "0.7"}, {"asset_id": "63761293627321054794056701530662561252253979399794304476663814039986928052742", "price": "0.33", "size": "183.78", "side": "SELL", "hash": "a43e67361953ab5c5e1a5eb205b3fa93c3515098", "best_bid": "0.3", "best_ask": "0.31"}], "timestamp": "1769384696921", "event_type": "price_change"}}
{"_local_timestamp": "2026-01-25T23:44:57.604572+00:00", "data": {"market": "0x6987d084de71031819f82051ea62b29a354628c3e4a22076a2acc197c776080a", "price_changes": [{"asset_id": "94521268801533640253484626268475643884882213091508756864952897781498391313602", "price": "0.67", "size": "233.78", "side": "BUY", "hash": "9738331f31a068d32d39f1295a850be3011d780c", "best_bid": "0.69", "best_ask": "0.7"}, {"asset_id": "63761293627321054794056701530662561252253979399794304476663814039986928052742", "price": "0.33", "size": "233.78", "side": "SELL", "hash": "db39b81515ff99be354deec1d957da922c1555ad", "best_bid": "0.3", "best_ask": "0.31"}], "timestamp": "1769384697524", "event_type": "price_change"}}
{"_local_timestamp": "2026-01-25T23:44:57.620046+00:00", "data": {"market": "0x6987d084de71031819f82051ea62b29a354628c3e4a22076a2acc197c776080a", "price_changes": [{"asset_id": "94521268801533640253484626268475643884882213091508756864952897781498391313602", "price": "0.66", "size": "1564.22", "side": "BUY", "hash": "0e32328e2ef3038b95d7cd3a7e56fec19e1e7716", "best_bid": "0.69", "best_ask": "0.7"}, {"asset_id": "63761293627321054794056701530662561252253979399794304476663814039986928052742", "price": "0.34", "size": "1564.22", "side": "SELL", "hash": "722204586bf55a39d0e0dcc014a97252d4e620a5", "best_bid": "0.3", "best_ask": "0.31"}], "timestamp": "1769384697525", "event_type": "price_change"}}
{"_local_timestamp": "2026-01-25T23:45:16.167939+00:00", "data": {"market": "0x6987d084de71031819f82051ea62b29a354628c3e4a22076a2acc197c776080a", "price_changes": [{"asset_id": "63761293627321054794056701530662561252253979399794304476663814039986928052742", "price": "0.28", "size": "615.72", "side": "BUY", "hash": "6e4287353f8ed11428db706e75b18cd357c4ac2a", "best_bid": "0.3", "best_ask": "0.31"}, {"asset_id": "94521268801533640253484626268475643884882213091508756864952897781498391313602", "price": "0.72", "size": "615.72", "side": "SELL", "hash": "b25087f9f62f144e565aea71e618d701f7e36b29", "best_bid": "0.69", "best_ask": "0.7"}], "timestamp": "1769384716088", "event_type": "price_change"}}
{"_local_timestamp": "2026-01-25T23:45:24.162491+00:00", "data": {"market": "0x6987d084de71031819f82051ea62b29a354628c3e4a22076a2acc197c776080a", "price_changes": [{"asset_id": "94521268801533640253484626268475643884882213091508756864952897781498391313602", "price": "0.67", "size": "283.78", "side": "BUY", "hash": "9fb7f93673a6e98553179ecbbfb7b4d11d9723bb", "best_bid": "0.69", "best_ask": "0.7"}, {"asset_id": "63761293627321054794056701530662561252253979399794304476663814039986928052742", "price": "0.33", "size": "283.78", "side": "SELL", "hash": "87b30adbade8f5e178c7bc2d0f50c0e827f87d14", "best_bid": "0.3", "best_ask": "0.31"}], "timestamp": "1769384724094", "event_type": "price_change"}}
{"_local_timestamp": "2026-01-25T23:45:24.912953+00:00", "data": {"market": "0x6987d084de71031819f82051ea62b29a354628c3e4a22076a2acc197c776080a", "price_changes": [{"asset_id": "94521268801533640253484626268475643884882213091508756864952897781498391313602", "price": "0.66", "size": "1514.22", "side": "BUY", "hash": "562a862f799579af156b7f009349129da00a7e63", "best_bid": "0.69", "best_ask": "0.7"}, {"asset_id": "63761293627321054794056701530662561252253979399794304476663814039986928052742", "price": "0.34", "size": "1514.22", "side": "SELL", "hash": "3e000e18ebaaf9f5c33541c8d01c78cd057cac01", "best_bid": "0.3", "best_ask": "0.31"}], "timestamp": "1769384724838", "event_type": "price_change"}}
{"_local_timestamp": "2026-01-25T23:45:24.913344+00:00", "data": {"market": "0x6987d084de71031819f82051ea62b29a354628c3e4a22076a2acc197c776080a", "price_changes": [{"asset_id": "94521268801533640253484626268475643884882213091508756864952897781498391313602", "price": "0.67", "size": "233.78", "side": "BUY", "hash": "562a862f799579af156b7f009349129da00a7e63", "best_bid": "0.69", "best_ask": "0.7"}, {"asset_id": "63761293627321054794056701530662561252253979399794304476663814039986928052742", "price": "0.33", "size": "233.78", "side": "SELL", "hash": "3e000e18ebaaf9f5c33541c8d01c78cd057cac01", "best_bid": "0.3", "best_ask": "0.31"}], "timestamp": "1769384724838", "event_type": "price_change"}}
{"_local_timestamp": "2026-01-25T23:45:29.714746+00:00", "data": {"market": "0xa65fe234ac3808801290874c631e55bcfee30e437c78239808729a89d9f2de22", "price_changes": [{"asset_id": "11132544244839265378732084165256379227175677028258955804895976429843086532411", "price": "0.26", "size": "1614", "side": "BUY", "hash": "769297a0932abf66fc5e026d02c65b057f332cd8", "best_bid": "0.92", "best_ask": "0.93"}, {"asset_id": "37281046158137671889895383499164526727881692321679587626659940834369685019496", "price": "0.74", "size": "1614", "side": "SELL", "hash": "2d355eb8ddd7b2805e71eb3ecd8ea075bf9898fe", "best_bid": "0.07", "best_ask": "0.08"}], "timestamp": "1769384729640", "event_type": "price_change"}}
{"_local_timestamp": "2026-01-25T23:45:48.442237+00:00", "data": {"market": "0x7e50b661a2bedc670bcf32fc9ece12616f6fc4fba5dbe8526292bf3447374009", "price_changes": [{"asset_id": "47029152085101973226255505664149277121974669906212969183902148537312535402801", "price": "0.07", "size": "1981.55", "side": "BUY", "hash": "a8ca6962bf94829d80c93127fd0868a5bf68705c", "best_bid": "0.09", "best_ask": "0.11"}, {"asset_id": "83552904656813968939383082097054433404653657244784709614448703928529504455469", "price": "0.93", "size": "1981.55", "side": "SELL", "hash": "f8f4ffd38dc6e67b526b2ce2c3d86decf5cab3c1", "best_bid": "0.89", "best_ask": "0.91"}], "timestamp": "1769384748353", "event_type": "price_change"}}
{"_local_timestamp": "2026-01-25T23:45:48.454656+00:00", "data": {"market": "0x7e50b661a2bedc670bcf32fc9ece12616f6fc4fba5dbe8526292bf3447374009", "price_changes": [{"asset_id": "83552904656813968939383082097054433404653657244784709614448703928529504455469", "price": "0.87", "size": "5300", "side": "BUY", "hash": "71a97c9a0c3a54f5d991373fb3228d98d6e09917", "best_bid": "0.89", "best_ask": "0.91"}, {"asset_id": "47029152085101973226255505664149277121974669906212969183902148537312535402801", "price": "0.13", "size": "5300", "side": "SELL", "hash": "15a30b491529fe2efce899a7438936950a652e9c", "best_bid": "0.09", "best_ask": "0.11"}], "timestamp": "1769384748354", "event_type": "price_change"}}
{"_local_timestamp": "2026-01-25T23:45:55.317095+00:00", "data": {"market": "0xa65fe234ac3808801290874c631e55bcfee30e437c78239808729a89d9f2de22", "price_changes": [{"asset_id": "37281046158137671889895383499164526727881692321679587626659940834369685019496", "price": "0.11", "size": "3923.05", "side": "SELL", "hash": "f5cca327d57d4ce95e9113af0028a968264df714", "best_bid": "0.07", "best_ask": "0.08"}, {"asset_id": "11132544244839265378732084165256379227175677028258955804895976429843086532411", "price": "0.89", "size": "3923.05", "side": "BUY", "hash": "b8cb02f38454f9361dd061a71a608717e33515ae", "best_bid": "0.92", "best_ask": "0.93"}], "timestamp": "1769384755245", "event_type": "price_change"}}
{"_local_timestamp": "2026-01-25T23:45:55.810621+00:00", "data": {"market": "0x6987d084de71031819f82051ea62b29a354628c3e4a22076a2acc197c776080a", "price_changes": [{"asset_id": "94521268801533640253484626268475643884882213091508756864952897781498391313602", "price": "0.28", "size": "0", "side": "BUY", "hash": "1704ffec54d43fd17e0ea0315c85b2e4d72fe577", "best_bid": "0.69", "best_ask": "0.7"}, {"asset_id": "63761293627321054794056701530662561252253979399794304476663814039986928052742", "price": "0.72", "size": "0", "side": "SELL", "hash": "d36fae7fbdab81dd2b75f2d3c1d0e10ff9447afb", "best_bid": "0.3", "best_ask": "0.31"}], "timestamp": "1769384755736", "event_type": "price_change"}}
{"_local_timestamp": "2026-01-25T23:45:55.984014+00:00", "data": {"market": "0x6987d084de71031819f82051ea62b29a354628c3e4a22076a2acc197c776080a", "price_changes": [{"asset_id": "94521268801533640253484626268475643884882213091508756864952897781498391313602", "price": "0.28", "size": "3235", "side": "BUY", "hash": "f55937d191e2199cbccf7119e5d85d80e384c8d3", "best_bid": "0.69", "best_ask": "0.7"}, {"asset_id": "63761293627321054794056701530662561252253979399794304476663814039986928052742", "price": "0.72", "size": "3235", "side": "SELL", "hash": "a549c2966016e8943df979f9defb0e3996f845ec", "best_bid": "0.3", "best_ask": "0.31"}], "timestamp": "1769384755906", "event_type": "price_change"}}
{"_local_timestamp": "2026-01-25T23:45:56.269450+00:00", "data": {"market": "0x7e50b661a2bedc670bcf32fc9ece12616f6fc4fba5dbe8526292bf3447374009", "price_changes": [{"asset_id": "83552904656813968939383082097054433404653657244784709614448703928529504455469", "price": "0.27", "size": "96.29", "side": "BUY", "hash": "03d99487fa2b70a69fbb12c531b8349e87712127", "best_bid": "0.89", "best_ask": "0.91"}, {"asset_id": "47029152085101973226255505664149277121974669906212969183902148537312535402801", "price": "0.73", "size": "96.29", "side": "SELL", "hash": "d960ecde7cfb5945ac01e3eb078756f153e9207f", "best_bid": "0.09", "best_ask": "0.11"}], "timestamp": "1769384756104", "event_type": "price_change"}}
{"_local_timestamp": "2026-01-25T23:45:56.941532+00:00", "data": {"market": "0x7e50b661a2bedc670bcf32fc9ece12616f6fc4fba5dbe8526292bf3447374009", "price_changes": [{"asset_id": "83552904656813968939383082097054433404653657244784709614448703928529504455469", "price": "0.29", "size": "4768", "side": "BUY", "hash": "cb9fa11094be86d26a4b21eb7353b04b9e78159b", "best_bid": "0.89", "best_ask": "0.91"}, {"asset_id": "47029152085101973226255505664149277121974669906212969183902148537312535402801", "price": "0.71", "size": "4768", "side": "SELL", "hash": "46bbc01b5b9cca57f7ad6d58b61f8e31a4816238", "best_bid": "0.09", "best_ask": "0.11"}], "timestamp": "1769384756288", "event_type": "price_change"}}
{"_local_timestamp": "2026-01-25T23:45:58.708900+00:00", "data": {"market": "0xa65fe234ac3808801290874c631e55bcfee30e437c78239808729a89d9f2de22", "price_changes": [{"asset_id": "37281046158137671889895383499164526727881692321679587626659940834369685019496", "price": "0.1", "size": "2860.02", "side": "SELL", "hash": "b22207d97c174e613da8ed4a89081b1277407753", "best_bid": "0.07", "best_ask": "0.08"}, {"asset_id": "11132544244839265378732084165256379227175677028258955804895976429843086532411", "price": "0.9", "size": "2860.02", "side": "BUY", "hash": "2a677f23ec94cb7e74499e38a0384a91f2a87f57", "best_bid": "0.92", "best_ask": "0.93"}], "timestamp": "1769384758637", "event_type": "price_change"}}
{"_local_timestamp": "2026-01-25T23:46:03.868006+00:00", "data": {"market": "0xa65fe234ac3808801290874c631e55bcfee30e437c78239808729a89d9f2de22", "price_changes": [{"asset_id": "37281046158137671889895383499164526727881692321679587626659940834369685019496", "price": "0.1", "size": "2697.58", "side": "SELL", "hash": "7335ffea4a94ca74eed4bdedfe781cb3370d7135", "best_bid": "0.07", "best_ask": "0.08"}, {"asset_id": "11132544244839265378732084165256379227175677028258955804895976429843086532411", "price": "0.9", "size": "2697.58", "side": "BUY", "hash": "6d1d2c95639f165c4ed0a27de38030a5118a7d17", "best_bid": "0.92", "best_ask": "0.93"}], "timestamp": "1769384763793", "event_type": "price_change"}}
{"_local_timestamp": "2026-01-25T23:46:03.921737+00:00", "data": {"market": "0x7e50b661a2bedc670bcf32fc9ece12616f6fc4fba5dbe8526292bf3447374009", "price_changes": [{"asset_id": "47029152085101973226255505664149277121974669906212969183902148537312535402801", "price": "0.07", "size": "2081.55", "side": "BUY", "hash": "5faf23ab31f3d7d7f1b075556ecd415e6bfcc744", "best_bid": "0.09", "best_ask": "0.11"}, {"asset_id": "83552904656813968939383082097054433404653657244784709614448703928529504455469", "price": "0.93", "size": "2081.55", "side": "SELL", "hash": "fbc5013747fa7a979abd812cfe7c9541d4597de2", "best_bid": "0.89", "best_ask": "0.91"}], "timestamp": "1769384763851", "event_type": "price_change"}}
{"_local_timestamp": "2026-01-25T23:46:07.695096+00:00", "data": {"market": "0xa65fe234ac3808801290874c631e55bcfee30e437c78239808729a89d9f2de22", "price_changes": [{"asset_id": "37281046158137671889895383499164526727881692321679587626659940834369685019496", "price": "0.1", "size": "2860.02", "side": "SELL", "hash": "8ec017436f2f362fb7061747e953c4dd6a554bff", "best_bid": "0.07", "best_ask": "0.08"}, {"asset_id": "11132544244839265378732084165256379227175677028258955804895976429843086532411", "price": "0.9", "size": "2860.02", "side": "BUY", "hash": "21299ff96de63acd793327f5afd65225bd48b968", "best_bid": "0.92", "best_ask": "0.93"}], "timestamp": "1769384767623", "event_type": "price_change"}}
{"_local_timestamp": "2026-01-25T23:46:10.627441+00:00", "data": {"market": "0xa65fe234ac3808801290874c631e55bcfee30e437c78239808729a89d9f2de22", "price_changes": [{"asset_id": "11132544244839265378732084165256379227175677028258955804895976429843086532411", "price": "0.26", "size": "0", "side": "BUY", "hash": "2bc333992e9ef833dd261e2bd7ee3a761434bca5", "best_bid": "0.92", "best_ask": "0.93"}, {"asset_id": "37281046158137671889895383499164526727881692321679587626659940834369685019496", "price": "0.74", "size": "0", "side": "SELL", "hash": "2a0fbcfff52ebc1fbf7d81fe185c17e49d690114", "best_bid": "0.07", "best_ask": "0.08"}], "timestamp": "1769384770469", "event_type": "price_change"}}
{"_local_timestamp": "2026-01-25T23:46:10.679974+00:00", "data": {"market": "0x5f33f46fa571836f090ef8f3e62caee237f8f73c36a711e757a6f71bf8ef9c6a", "price_changes": [{"asset_id": "96229871085374132303116376471322311695842738677806841162553339355812305824040", "price": "0.16", "size": "0", "side": "BUY", "hash": "a538490c4b209ae635a5764328c44e47ef1bd8a7", "best_bid": "0.53", "best_ask": "0.55"}, {"asset_id": "3464795463763108108909057219187376740735691886447931192725079515654033695019", "price": "0.84", "size": "0", "side": "SELL", "hash": "5b65f471d7b1e242864a6587edd4c5a8ee49e8a1", "best_bid": "0.45", "best_ask": "0.47"}], "timestamp": "1769384770467", "event_type": "price_change"}}
{"_local_timestamp": "2026-01-25T23:46:11.830972+00:00", "data": {"market": "0x7e50b661a2bedc670bcf32fc9ece12616f6fc4fba5dbe8526292bf3447374009", "price_changes": [{"asset_id": "83552904656813968939383082097054433404653657244784709614448703928529504455469", "price": "0.87", "size": "5400", "side": "BUY", "hash": "dbe720e2dff947c14f34b0e01c8d5cf5d772b37c", "best_bid": "0.89", "best_ask": "0.91"}, {"asset_id": "47029152085101973226255505664149277121974669906212969183902148537312535402801", "price": "0.13", "size": "5400", "side": "SELL", "hash": "20246c89c9964433b2d176f911b80e5f2dfd073f", "best_bid": "0.09", "best_ask": "0.11"}], "timestamp": "1769384771759", "event_type": "price_change"}}
{"_local_timestamp": "2026-01-25T23:46:37.009311+00:00", "data": {"market": "0xa65fe234ac3808801290874c631e55bcfee30e437c78239808729a89d9f2de22", "price_changes": [{"asset_id": "37281046158137671889895383499164526727881692321679587626659940834369685019496", "price": "0.1", "size": "2697.58", "side": "SELL", "hash": "9faa5393b560d242f984e99438881577f4bf1567", "best_bid": "0.07", "best_ask": "0.08"}, {"asset_id": "11132544244839265378732084165256379227175677028258955804895976429843086532411", "price": "0.9", "size": "2697.58", "side": "BUY", "hash": "c6b413c1e573c5b7250ea78bc68937df21db31a9", "best_bid": "0.92", "best_ask": "0.93"}], "timestamp": "1769384796927", "event_type": "price_change"}}
{"_local_timestamp": "2026-01-25T23:46:39.294879+00:00", "data": {"market": "0xa65fe234ac3808801290874c631e55bcfee30e437c78239808729a89d9f2de22", "price_changes": [{"asset_id": "11132544244839265378732084165256379227175677028258955804895976429843086532411", "price": "0.24", "size": "1748", "side": "BUY", "hash": "a37129e718a1f4c9d72f54f1be9e5413eb81c6bf", "best_bid": "0.92", "best_ask": "0.93"}, {"asset_id": "37281046158137671889895383499164526727881692321679587626659940834369685019496", "price": "0.76", "size": "1748", "side": "SELL", "hash": "e018fa59ea88c17a34362e1b14acb2d7d32fcbdf", "best_bid": "0.07", "best_ask": "0.08"}], "timestamp": "1769384799212", "event_type": "price_change"}}
{"_local_timestamp": "2026-01-25T23:46:47.205380+00:00", "data": {"market": "0xa65fe234ac3808801290874c631e55bcfee30e437c78239808729a89d9f2de22", "price_changes": [{"asset_id": "37281046158137671889895383499164526727881692321679587626659940834369685019496", "price": "0.11", "size": "4085.49", "side": "SELL", "hash": "997405aba86e5e491379227f82a2acf0ce8e9cf8", "best_bid": "0.07", "best_ask": "0.08"}, {"asset_id": "11132544244839265378732084165256379227175677028258955804895976429843086532411", "price": "0.89", "size": "4085.49", "side": "BUY", "hash": "8c353419027cf9cdb1c4d093d1225fd0f0afb527", "best_bid": "0.92", "best_ask": "0.93"}], "timestamp": "1769384807139", "event_type": "price_change"}}
{"_local_timestamp": "2026-01-25T23:47:06.639372+00:00", "data": {"market": "0xa65fe234ac3808801290874c631e55bcfee30e437c78239808729a89d9f2de22", "price_changes": [{"asset_id": "37281046158137671889895383499164526727881692321679587626659940834369685019496", "price": "0.11", "size": "3923.05", "side": "SELL", "hash": "087b639be5fbea01b2ff8d14461b50104562c14b", "best_bid": "0.07", "best_ask": "0.08"}, {"asset_id": "11132544244839265378732084165256379227175677028258955804895976429843086532411", "price": "0.89", "size": "3923.05", "side": "BUY", "hash": "3cc5a97a87f6e3b00ffbb9ee01c1d949fb2a57da", "best_bid": "0.92", "best_ask": "0.93"}], "timestamp": "1769384826568", "event_type": "price_change"}}
{"_local_timestamp": "2026-01-25T23:47:13.635240+00:00", "data": {"market": "0x5f33f46fa571836f090ef8f3e62caee237f8f73c36a711e757a6f71bf8ef9c6a", "price_changes": [{"asset_id": "96229871085374132303116376471322311695842738677806841162553339355812305824040", "price": "0.15", "size": "2798", "side": "BUY", "hash": "a82d607f7bf074b477f70e97c9ad9b6179eb3cb2", "best_bid": "0.53", "best_ask": "0.55"}, {"asset_id": "3464795463763108108909057219187376740735691886447931192725079515654033695019", "price": "0.85", "size": "2798", "side": "SELL", "hash": "413b70f064080b326cce2e74532c998848164884", "best_bid": "0.45", "best_ask": "0.47"}], "timestamp": "1769384833560", "event_type": "price_change"}}
{"_local_timestamp": "2026-01-25T23:47:16.128643+00:00", "data": {"market": "0xa65fe234ac3808801290874c631e55bcfee30e437c78239808729a89d9f2de22", "price_changes": [{"asset_id": "11132544244839265378732084165256379227175677028258955804895976429843086532411", "price": "0.02", "size": "0", "side": "BUY", "hash": "17aefa40357e1ffece14dbbc74228800eb3cc9b4", "best_bid": "0.92", "best_ask": "0.93"}, {"asset_id": "37281046158137671889895383499164526727881692321679587626659940834369685019496", "price": "0.98", "size": "0", "side": "SELL", "hash": "1a1063b30f743bacb07358f2ee53140658f8c51d", "best_bid": "0.07", "best_ask": "0.08"}], "timestamp": "1769384836039", "event_type": "price_change"}}
{"_local_timestamp": "2026-01-25T23:47:16.129043+00:00", "data": {"market": "0xa65fe234ac3808801290874c631e55bcfee30e437c78239808729a89d9f2de22", "price_changes": [{"asset_id": "37281046158137671889895383499164526727881692321679587626659940834369685019496", "price": "0.04", "size": "14743.45", "side": "BUY", "hash": "c303419157821a6c802c09b16c0e2a3218b376ee", "best_bid": "0.07", "best_ask": "0.08"}, {"asset_id": "11132544244839265378732084165256379227175677028258955804895976429843086532411", "price": "0.96", "size": "14743.45", "side": "SELL", "hash": "958b9fcf099d4f76db23ebca133a11bcdd8f8d22", "best_bid": "0.92", "best_ask": "0.93"}], "timestamp": "1769384836040", "event_type": "price_change"}}
{"_local_timestamp": "2026-01-25T23:47:16.372001+00:00", "data": {"market": "0xa65fe234ac3808801290874c631e55bcfee30e437c78239808729a89d9f2de22", "price_changes": [{"asset_id": "11132544244839265378732084165256379227175677028258955804895976429843086532411", "price": "0.02", "size": "18.49", "side": "BUY", "hash": "a81be9a54973ebbeb2524e05d6f5d93270e3bd93", "best_bid": "0.92", "best_ask": "0.93"}, {"asset_id": "37281046158137671889895383499164526727881692321679587626659940834369685019496", "price": "0.98", "size": "18.49", "side": "SELL", "hash": "68aa1c6a730ff3461acd76fd19d44fda23b0ec22", "best_bid": "0.07", "best_ask": "0.08"}], "timestamp": "1769384836297", "event_type": "price_change"}}
{"_local_timestamp": "2026-01-25T23:47:16.585415+00:00", "data": {"market": "0xa65fe234ac3808801290874c631e55bcfee30e437c78239808729a89d9f2de22", "price_changes": [{"asset_id": "37281046158137671889895383499164526727881692321679587626659940834369685019496", "price": "0.04", "size": "14756.12", "side": "BUY", "hash": "a48ed4deebc6933a8439dc288b37c080184355c8", "best_bid": "0.07", "best_ask": "0.08"}, {"asset_id": "11132544244839265378732084165256379227175677028258955804895976429843086532411", "price": "0.96", "size": "14756.12", "side": "SELL", "hash": "8819eae165960251c11fea65b722570aca99ba52", "best_bid": "0.92", "best_ask": "0.93"}], "timestamp": "1769384836518", "event_type": "price_change"}}
{"_local_timestamp": "2026-01-25T23:47:25.912697+00:00", "data": {"market": "0x6987d084de71031819f82051ea62b29a354628c3e4a22076a2acc197c776080a", "price_changes": [{"asset_id": "94521268801533640253484626268475643884882213091508756864952897781498391313602", "price": "0.66", "size": "1564.22", "side": "BUY", "hash": "27e535d2260ae17b4772db2d4f12a859e7425028", "best_bid": "0.69", "best_ask": "0.7"}, {"asset_id": "63761293627321054794056701530662561252253979399794304476663814039986928052742", "price": "0.34", "size": "1564.22", "side": "SELL", "hash": "90c82f8f3deb64d98badebafd9ad43538d10dc7d", "best_bid": "0.3", "best_ask": "0.31"}], "timestamp": "1769384845839", "event_type": "price_change"}}
{"_local_timestamp": "2026-01-25T23:47:25.913074+00:00", "data": {"market": "0x6987d084de71031819f82051ea62b29a354628c3e4a22076a2acc197c776080a", "price_changes": [{"asset_id": "94521268801533640253484626268475643884882213091508756864952897781498391313602", "price": "0.67", "size": "283.78", "side": "BUY", "hash": "3ceb5eaec7403418db35ea588d7d61549ea7d961", "best_bid": "0.69", "best_ask": "0.7"}, {"asset_id": "63761293627321054794056701530662561252253979399794304476663814039986928052742", "price": "0.33", "size": "283.78", "side": "SELL", "hash": "6c27cd59b9970a478f7bab4a619ffb70dbe38a23", "best_bid": "0.3", "best_ask": "0.31"}], "timestamp": "1769384845839", "event_type": "price_change"}}
{"_local_timestamp": "2026-01-25T23:47:33.856599+00:00", "data": {"market": "0xa65fe234ac3808801290874c631e55bcfee30e437c78239808729a89d9f2de22", "price_changes": [{"asset_id": "11132544244839265378732084165256379227175677028258955804895976429843086532411", "price": "0.93", "size": "2440.36", "side": "SELL", "hash": "cae798c85e32bd1ed2f77344a117c1fbfe2d3e5c", "best_bid": "0.92", "best_ask": "0.93"}, {"asset_id": "37281046158137671889895383499164526727881692321679587626659940834369685019496", "price": "0.07", "size": "2440.36", "side": "BUY", "hash": "cb7762240d8cbc97ce31462505034459bb19189e", "best_bid": "0.07", "best_ask": "0.08"}], "timestamp": "1769384853743", "event_type": "price_change"}}
{"_local_timestamp": "2026-01-25T23:47:53.049770+00:00", "data": {"market": "0x6987d084de71031819f82051ea62b29a354628c3e4a22076a2acc197c776080a", "price_changes": [{"asset_id": "94521268801533640253484626268475643884882213091508756864952897781498391313602", "price": "0.67", "size": "233.78", "side": "BUY", "hash": "a854c23e1441c54ac35a22494728a4b2a836dc97", "best_bid": "0.69", "best_ask": "0.7"}, {"asset_id": "63761293627321054794056701530662561252253979399794304476663814039986928052742", "price": "0.33", "size": "233.78", "side": "SELL", "hash": "d69afe369a5538efb8d2539ed93947ef8bbc09fa", "best_bid": "0.3", "best_ask": "0.31"}], "timestamp": "1769384872972", "event_type": "price_change"}}
{"_local_timestamp": "2026-01-25T23:47:53.050115+00:00", "data": {"market": "0x6987d084de71031819f82051ea62b29a354628c3e4a22076a2acc197c776080a", "price_changes": [{"asset_id": "94521268801533640253484626268475643884882213091508756864952897781498391313602", "price": "0.66", "size": "1514.22", "side": "BUY", "hash": "a854c23e1441c54ac35a22494728a4b2a836dc97", "best_bid": "0.69", "best_ask": "0.7"}, {"asset_id": "63761293627321054794056701530662561252253979399794304476663814039986928052742", "price": "0.34", "size": "1514.22", "side": "SELL", "hash": "d69afe369a5538efb8d2539ed93947ef8bbc09fa", "best_bid": "0.3", "best_ask": "0.31"}], "timestamp": "1769384872972", "event_type": "price_change"}}
{"_local_timestamp": "2026-01-25T23:47:55.634035+00:00", "data": {"market": "0x5f33f46fa571836f090ef8f3e62caee237f8f73c36a711e757a6f71bf8ef9c6a", "price_changes": [{"asset_id": "96229871085374132303116376471322311695842738677806841162553339355812305824040", "price": "0.15", "size": "0", "side": "BUY", "hash": "a3d4344a41570a0af55961299169f965e9e54c6a", "best_bid": "0.53", "best_ask": "0.55"}, {"asset_id": "3464795463763108108909057219187376740735691886447931192725079515654033695019", "price": "0.85", "size": "0", "side": "SELL", "hash": "d477210c356eda19b414df138d448ac1e02c398f", "best_bid": "0.45", "best_ask": "0.47"}], "timestamp": "1769384875411", "event_type": "price_change"}}
{"_local_timestamp": "2026-01-25T23:47:55.651840+00:00", "data": {"market": "0xa65fe234ac3808801290874c631e55bcfee30e437c78239808729a89d9f2de22", "price_changes": [{"asset_id": "11132544244839265378732084165256379227175677028258955804895976429843086532411", "price": "0.24", "size": "0", "side": "BUY", "hash": "4461771b338b271a2c133b4490a9a4eabe4e5670", "best_bid": "0.92", "best_ask": "0.93"}, {"asset_id": "37281046158137671889895383499164526727881692321679587626659940834369685019496", "price": "0.76", "size": "0", "side": "SELL", "hash": "13cbd51acb0d9397006c20183003402db8c6ce02", "best_bid": "0.07", "best_ask": "0.08"}], "timestamp": "1769384875420", "event_type": "price_change"}}
{"_local_timestamp": "2026-01-25T23:49:02.151534+00:00", "data": {"market": "0xa65fe234ac3808801290874c631e55bcfee30e437c78239808729a89d9f2de22", "price_changes": [{"asset_id": "11132544244839265378732084165256379227175677028258955804895976429843086532411", "price": "0.27", "size": "1554", "side": "BUY", "hash": "976c50995c6209602094858414a7c35a99bff66b", "best_bid": "0.92", "best_ask": "0.93"}, {"asset_id": "37281046158137671889895383499164526727881692321679587626659940834369685019496", "price": "0.73", "size": "1554", "side": "SELL", "hash": "54d3174bfa80fee9365514983aa65603df2a5633", "best_bid": "0.07", "best_ask": "0.08"}], "timestamp": "1769384942019", "event_type": "price_change"}}
{"_local_timestamp": "2026-01-25T23:49:21.553836+00:00", "data": {"market": "0x5f33f46fa571836f090ef8f3e62caee237f8f73c36a711e757a6f71bf8ef9c6a", "price_changes": [{"asset_id": "96229871085374132303116376471322311695842738677806841162553339355812305824040", "price": "0.16", "size": "2624", "side": "BUY", "hash": "a2003f01957723928bddd068cf8b93b51546df95", "best_bid": "0.53", "best_ask": "0.55"}, {"asset_id": "3464795463763108108909057219187376740735691886447931192725079515654033695019", "price": "0.84", "size": "2624", "side": "SELL", "hash": "6daf6a7e0075c03c8f26cba0802b3917d7771547", "best_bid": "0.45", "best_ask": "0.47"}], "timestamp": "1769384961481", "event_type": "price_change"}}
{"_local_timestamp": "2026-01-25T23:49:51.170179+00:00", "data": {"market": "0x5f33f46fa571836f090ef8f3e62caee237f8f73c36a711e757a6f71bf8ef9c6a", "price_changes": [{"asset_id": "96229871085374132303116376471322311695842738677806841162553339355812305824040", "price": "0.16", "size": "0", "side": "BUY", "hash": "63112d2bd8069151da1f1555059332fd03c9bf69", "best_bid": "0.53", "best_ask": "0.55"}, {"asset_id": "3464795463763108108909057219187376740735691886447931192725079515654033695019", "price": "0.84", "size": "0", "side": "SELL", "hash": "914d18a68f5a240342e856fae7d9375ec068b88a", "best_bid": "0.45", "best_ask": "0.47"}], "timestamp": "1769384991038", "event_type": "price_change"}}
{"_local_timestamp": "2026-01-25T23:49:51.187819+00:00", "data": {"market": "0xa65fe234ac3808801290874c631e55bcfee30e437c78239808729a89d9f2de22", "price_changes": [{"asset_id": "11132544244839265378732084165256379227175677028258955804895976429843086532411", "price": "0.27", "size": "0", "side": "BUY", "hash": "0450bfebb7cdcd853a5f41d88afe920b61de666f", "best_bid": "0.92", "best_ask": "0.93"}, {"asset_id": "37281046158137671889895383499164526727881692321679587626659940834369685019496", "price": "0.73", "size": "0", "side": "SELL", "hash": "548fbde0400330ef553737456bb41b09db3a39f6", "best_bid": "0.07", "best_ask": "0.08"}], "timestamp": "1769384991040", "event_type": "price_change"}}
{"_local_timestamp": "2026-01-25T23:49:51.237663+00:00", "data": {"market": "0x7e50b661a2bedc670bcf32fc9ece12616f6fc4fba5dbe8526292bf3447374009", "price_changes": [{"asset_id": "83552904656813968939383082097054433404653657244784709614448703928529504455469", "price": "0.28", "size": "0", "side": "BUY", "hash": "c2a53f8fd4024d40a377206efa628b63dae15e43", "best_bid": "0.89", "best_ask": "0.91"}, {"asset_id": "47029152085101973226255505664149277121974669906212969183902148537312535402801", "price": "0.72", "size": "0", "side": "SELL", "hash": "ea9bf88b9b400da55d971ce322fbc4a2cae8b96c", "best_bid": "0.09", "best_ask": "0.11"}], "timestamp": "1769384991045", "event_type": "price_change"}}
{"_local_timestamp": "2026-01-25T23:49:55.105829+00:00", "data": {"market": "0x6987d084de71031819f82051ea62b29a354628c3e4a22076a2acc197c776080a", "price_changes": [{"asset_id": "94521268801533640253484626268475643884882213091508756864952897781498391313602", "price": "0.66", "size": "1564.22", "side": "BUY", "hash": "1756569d5b967e110977e763ef2799788a5faa17", "best_bid": "0.69", "best_ask": "0.7"}, {"asset_id": "63761293627321054794056701530662561252253979399794304476663814039986928052742", "price": "0.34", "size": "1564.22", "side": "SELL", "hash": "3468b63bfdb36772704c9d0c77ada1beb95596b2", "best_bid": "0.3", "best_ask": "0.31"}], "timestamp": "1769384995022", "event_type": "price_change"}}
{"_local_timestamp": "2026-01-25T23:49:55.109708+00:00", "data": {"market": "0x6987d084de71031819f82051ea62b29a354628c3e4a22076a2acc197c776080a", "price_changes": [{"asset_id": "94521268801533640253484626268475643884882213091508756864952897781498391313602", "price": "0.67", "size": "283.78", "side": "BUY", "hash": "920e3e266646c968ef45f1a5cb76b581251e4322", "best_bid": "0.69", "best_ask": "0.7"}, {"asset_id": "63761293627321054794056701530662561252253979399794304476663814039986928052742", "price": "0.33", "size": "283.78", "side": "SELL", "hash": "a8f082398601ffc38c4b71fb9132ed0224926b82", "best_bid": "0.3", "best_ask": "0.31"}], "timestamp": "1769384995023", "event_type": "price_change"}}
{"_local_timestamp": "2026-01-25T23:50:02.597229+00:00", "data": {"market": "0xa65fe234ac3808801290874c631e55bcfee30e437c78239808729a89d9f2de22", "price_changes": [{"asset_id": "11132544244839265378732084165256379227175677028258955804895976429843086532411", "price": "0.2", "size": "5", "side": "BUY", "hash": "87cad4ed196ea5c80fbb9cc61b62a89cb4d38ca4", "best_bid": "0.92", "best_ask": "0.93"}, {"asset_id": "37281046158137671889895383499164526727881692321679587626659940834369685019496", "price": "0.8", "size": "5", "side": "SELL", "hash": "c579fa98e268ba020dccb2145e47888adde2c469", "best_bid": "0.07", "best_ask": "0.08"}], "timestamp": "1769385002287", "event_type": "price_change"}}
{"_local_timestamp": "2026-01-25T23:50:02.630715+00:00", "data": {"market": "0x7e50b661a2bedc670bcf32fc9ece12616f6fc4fba5dbe8526292bf3447374009", "price_changes": [{"asset_id": "83552904656813968939383082097054433404653657244784709614448703928529504455469", "price": "0.21", "size": "0", "side": "BUY", "hash": "f13f6380d44d5f8d69fe41ced186fc93cbddf956", "best_bid": "0.89", "best_ask": "0.91"}, {"asset_id": "47029152085101973226255505664149277121974669906212969183902148537312535402801", "price": "0.79", "size": "0", "side": "SELL", "hash": "f21545a09b430227829942e8edc5bb6b520c0f86", "best_bid": "0.09", "best_ask": "0.11"}], "timestamp": "1769385002283", "event_type": "price_change"}}
{"_local_timestamp": "2026-01-25T23:50:02.679084+00:00", "data": {"market": "0x5f33f46fa571836f090ef8f3e62caee237f8f73c36a711e757a6f71bf8ef9c6a", "price_changes": [{"asset_id": "3464795463763108108909057219187376740735691886447931192725079515654033695019", "price": "0.11", "size": "5.09", "side": "BUY", "hash": "9c4a5878ea70a124ac73e5f2ca7e86798850fd7b", "best_bid": "0.45", "best_ask": "0.47"}, {"asset_id": "96229871085374132303116376471322311695842738677806841162553339355812305824040", "price": "0.89", "size": "5.09", "side": "SELL", "hash": "24adcb74a990f9309f2e856294d5e000727413b9", "best_bid": "0.53", "best_ask": "0.55"}], "timestamp": "1769385002280", "event_type": "price_change"}}
{"_local_timestamp": "2026-01-25T23:50:02.708491+00:00", "data": {"market": "0x6987d084de71031819f82051ea62b29a354628c3e4a22076a2acc197c776080a", "price_changes": [{"asset_id": "94521268801533640253484626268475643884882213091508756864952897781498391313602", "price": "0.16", "size": "0", "side": "BUY", "hash": "300ed2a0028ca6b3f07c1cfb02a0c22aa0c049ca", "best_bid": "0.69", "best_ask": "0.7"}, {"asset_id": "63761293627321054794056701530662561252253979399794304476663814039986928052742", "price": "0.84", "size": "0", "side": "SELL", "hash": "c2361a8a4e6569288bced9d28d55e807a70a5671", "best_bid": "0.3", "best_ask": "0.31"}], "timestamp": "1769385002278", "event_type": "price_change"}}
{"_local_timestamp": "2026-01-25T23:50:02.737583+00:00", "data": {"market": "0x5f33f46fa571836f090ef8f3e62caee237f8f73c36a711e757a6f71bf8ef9c6a", "price_changes": [{"asset_id": "96229871085374132303116376471322311695842738677806841162553339355812305824040", "price": "0.12", "size": "0", "side": "BUY", "hash": "4d85b0cb4cbf608120d7d69c3af2d0969f598167", "best_bid": "0.53", "best_ask": "0.55"}, {"asset_id": "3464795463763108108909057219187376740735691886447931192725079515654033695019", "price": "0.88", "size": "0", "side": "SELL", "hash": "a642b194a6d78f13cfef82616383350eb887cc2c", "best_bid": "0.45", "best_ask": "0.47"}], "timestamp": "1769385002314", "event_type": "price_change"}}
{"_local_timestamp": "2026-01-25T23:50:02.950196+00:00", "data": {"market": "0xa65fe234ac3808801290874c631e55bcfee30e437c78239808729a89d9f2de22", "price_changes": [{"asset_id": "11132544244839265378732084165256379227175677028258955804895976429843086532411", "price": "0.38", "size": "0", "side": "BUY", "hash": "7c5075331f0a9ba1a272d8dfee2d8303beeea28e", "best_bid": "0.92", "best_ask": "0.93"}, {"asset_id": "37281046158137671889895383499164526727881692321679587626659940834369685019496", "price": "0.62", "size": "0", "side": "SELL", "hash": "58a270da5a0d00d61903ee16bee20083380cdc56", "best_bid": "0.07", "best_ask": "0.08"}], "timestamp": "1769385002368", "event_type": "price_change"}}
{"_local_timestamp": "2026-01-25T23:50:03.960550+00:00", "data": {"market": "0xa65fe234ac3808801290874c631e55bcfee30e437c78239808729a89d9f2de22", "price_changes": [{"asset_id": "37281046158137671889895383499164526727881692321679587626659940834369685019496", "price": "0.1", "size": "2860.02", "side": "SELL", "hash": "6b7b20cb51563a10fcb1eea7324f225245fe1bb0", "best_bid": "0.07", "best_ask": "0.08"}, {"asset_id": "11132544244839265378732084165256379227175677028258955804895976429843086532411", "price": "0.9", "size": "2860.02", "side": "BUY", "hash": "238b54ec14de9de7ec8d1810f09a1080cab8527f", "best_bid": "0.92", "best_ask": "0.93"}], "timestamp": "1769385003879", "event_type": "price_change"}}
{"_local_timestamp": "2026-01-25T23:50:09.451129+00:00", "data": {"market": "0x5f33f46fa571836f090ef8f3e62caee237f8f73c36a711e757a6f71bf8ef9c6a", "price_changes": [{"asset_id": "96229871085374132303116376471322311695842738677806841162553339355812305824040", "price": "0.15", "size": "2798", "side": "BUY", "hash": "f79a5e51e12884768e8575d41c80359bfd7de8f9", "best_bid": "0.53", "best_ask": "0.55"}, {"asset_id": "3464795463763108108909057219187376740735691886447931192725079515654033695019", "price": "0.85", "size": "2798", "side": "SELL", "hash": "370a0892cbf608da46bdac886a3def51102bd0d9", "best_bid": "0.45", "best_ask": "0.47"}], "timestamp": "1769385009369", "event_type": "price_change"}}
{"_local_timestamp": "2026-01-25T23:50:17.156377+00:00", "data": {"market": "0x7e50b661a2bedc670bcf32fc9ece12616f6fc4fba5dbe8526292bf3447374009", "price_changes": [{"asset_id": "83552904656813968939383082097054433404653657244784709614448703928529504455469", "price": "0.26", "size": "1614", "side": "BUY", "hash": "a4eef42f995c57aa183a84713627f3afa1ad7dec", "best_bid": "0.89", "best_ask": "0.91"}, {"asset_id": "47029152085101973226255505664149277121974669906212969183902148537312535402801", "price": "0.74", "size": "1614", "side": "SELL", "hash": "b625d83f6e613899987fdd1a7c9fba72d0ca8614", "best_bid": "0.09", "best_ask": "0.11"}], "timestamp": "1769385017044", "event_type": "price_change"}}
{"_local_timestamp": "2026-01-25T23:50:18.311443+00:00", "data": {"market": "0x7e50b661a2bedc670bcf32fc9ece12616f6fc4fba5dbe8526292bf3447374009", "price_changes": [{"asset_id": "83552904656813968939383082097054433404653657244784709614448703928529504455469", "price": "0.89", "size": "242.68", "side": "BUY", "hash": "5fce23ff781c196e71fd52a41248d8465925f634", "best_bid": "0.89", "best_ask": "0.91"}, {"asset_id": "47029152085101973226255505664149277121974669906212969183902148537312535402801", "price": "0.11", "size": "242.68", "side": "SELL", "hash": "c9ae50a1cc108811fed369939e63b02c0c3bd65f", "best_bid": "0.09", "best_ask": "0.11"}], "timestamp": "1769385018203", "event_type": "price_change"}}
{"_local_timestamp": "2026-01-25T23:50:19.986639+00:00", "data": {"market": "0x7e50b661a2bedc670bcf32fc9ece12616f6fc4fba5dbe8526292bf3447374009", "price_changes": [{"asset_id": "47029152085101973226255505664149277121974669906212969183902148537312535402801", "price": "0.12", "size": "1876", "side": "SELL", "hash": "bfd8103bce9812e02a4d40557b829ba291fd7838", "best_bid": "0.09", "best_ask": "0.11"}, {"asset_id": "83552904656813968939383082097054433404653657244784709614448703928529504455469", "price": "0.88", "size": "1876", "side": "BUY", "hash": "16698aec11e554bee83f55a2bfff8c5622e7b9a9", "best_bid": "0.89", "best_ask": "0.91"}], "timestamp": "1769385019892", "event_type": "price_change"}}
{"_local_timestamp": "2026-01-25T23:50:20.227907+00:00", "data": {"market": "0x7e50b661a2bedc670bcf32fc9ece12616f6fc4fba5dbe8526292bf3447374009", "price_changes": [{"asset_id": "47029152085101973226255505664149277121974669906212969183902148537312535402801", "price": "0.11", "size": "330.68", "side": "SELL", "hash": "a9783f75fe03a141112cae834eec8a7c55793798", "best_bid": "0.09", "best_ask": "0.11"}, {"asset_id": "83552904656813968939383082097054433404653657244784709614448703928529504455469", "price": "0.89", "size": "330.68", "side": "BUY", "hash": "fe9f0f60ddff63afba995678f0d03149508ed2ef", "best_bid": "0.89", "best_ask": "0.91"}], "timestamp": "1769385020127", "event_type": "price_change"}}
{"_local_timestamp": "2026-01-25T23:50:21.928012+00:00", "data": {"market": "0x6987d084de71031819f82051ea62b29a354628c3e4a22076a2acc197c776080a", "price_changes": [{"asset_id": "94521268801533640253484626268475643884882213091508756864952897781498391313602", "price": "0.67", "size": "233.78", "side": "BUY", "hash": "7336be4352dda3cee13f5abd2632bdd444bb703c", "best_bid": "0.69", "best_ask": "0.7"}, {"asset_id": "63761293627321054794056701530662561252253979399794304476663814039986928052742", "price": "0.33", "size": "233.78", "side": "SELL", "hash": "6e1d117ad7f70da5923c3903857ecff86cde5bad", "best_bid": "0.3", "best_ask": "0.31"}], "timestamp": "1769385021843", "event_type": "price_change"}}
{"_local_timestamp": "2026-01-25T23:50:21.928543+00:00", "data": {"market": "0x6987d084de71031819f82051ea62b29a354628c3e4a22076a2acc197c776080a", "price_changes": [{"asset_id": "94521268801533640253484626268475643884882213091508756864952897781498391313602", "price": "0.66", "size": "1514.22", "side": "BUY", "hash": "7336be4352dda3cee13f5abd2632bdd444bb703c", "best_bid": "0.69", "best_ask": "0.7"}, {"asset_id": "63761293627321054794056701530662561252253979399794304476663814039986928052742", "price": "0.34", "size": "1514.22", "side": "SELL", "hash": "6e1d117ad7f70da5923c3903857ecff86cde5bad", "best_bid": "0.3", "best_ask": "0.31"}], "timestamp": "1769385021843", "event_type": "price_change"}}
{"_local_timestamp": "2026-01-25T23:50:30.171705+00:00", "data": {"market": "0x7e50b661a2bedc670bcf32fc9ece12616f6fc4fba5dbe8526292bf3447374009", "price_changes": [{"asset_id": "83552904656813968939383082097054433404653657244784709614448703928529504455469", "price": "0.92", "size": "661.99", "side": "SELL", "hash": "6830d35d7e29cce8f20c6a4628f78d2453c387cd", "best_bid": "0.89", "best_ask": "0.91"}, {"asset_id": "47029152085101973226255505664149277121974669906212969183902148537312535402801", "price": "0.08", "size": "661.99", "side": "BUY", "hash": "ea45e4fea29c08a35301106df625167c3f20b1e7", "best_bid": "0.09", "best_ask": "0.11"}], "timestamp": "1769385029999", "event_type": "price_change"}}
{"_local_timestamp": "2026-01-25T23:50:40.487640+00:00", "data": {"market": "0x7e50b661a2bedc670bcf32fc9ece12616f6fc4fba5dbe8526292bf3447374009", "price_changes": [{"asset_id": "83552904656813968939383082097054433404653657244784709614448703928529504455469", "price": "0.92", "size": "907.99", "side": "SELL", "hash": "5ce67bd93ce8d2903bf04226c42487fcb1e7686f", "best_bid": "0.89", "best_ask": "0.91"}, {"asset_id": "47029152085101973226255505664149277121974669906212969183902148537312535402801", "price": "0.08", "size": "907.99", "side": "BUY", "hash": "2353342b0b9e8ca521b7312e640293d1b5946257", "best_bid": "0.09", "best_ask": "0.11"}], "timestamp": "1769385040282", "event_type": "price_change"}}
{"_local_timestamp": "2026-01-25T23:50:44.253732+00:00", "data": {"market": "0xa65fe234ac3808801290874c631e55bcfee30e437c78239808729a89d9f2de22", "price_changes": [{"asset_id": "11132544244839265378732084165256379227175677028258955804895976429843086532411", "price": "0.02", "size": "0", "side": "BUY", "hash": "8448f37e9df294105a910382c52ef0c7024243c9", "best_bid": "0.92", "best_ask": "0.93"}, {"asset_id": "37281046158137671889895383499164526727881692321679587626659940834369685019496", "price": "0.98", "size": "0", "side": "SELL", "hash": "1711d958ede5a598961e734025745ccc3b630e3f", "best_bid": "0.07", "best_ask": "0.08"}], "timestamp": "1769385044144", "event_type": "price_change"}}
{"_local_timestamp": "2026-01-25T23:50:44.254141+00:00", "data": {"market": "0xa65fe234ac3808801290874c631e55bcfee30e437c78239808729a89d9f2de22", "price_changes": [{"asset_id": "37281046158137671889895383499164526727881692321679587626659940834369685019496", "price": "0.04", "size": "14743.45", "side": "BUY", "hash": "95fb008df5f28a6e322ea8681802d8d640c83534", "best_bid": "0.07", "best_ask": "0.08"}, {"asset_id": "11132544244839265378732084165256379227175677028258955804895976429843086532411", "price": "0.96", "size": "14743.45", "side": "SELL", "hash": "9e81aca95cf8a18ee9f7a3c17a0e79c7f20b5852", "best_bid": "0.92", "best_ask": "0.93"}], "timestamp": "1769385044145", "event_type": "price_change"}}
{"_local_timestamp": "2026-01-25T23:50:44.592145+00:00", "data": {"market": "0xa65fe234ac3808801290874c631e55bcfee30e437c78239808729a89d9f2de22", "price_changes": [{"asset_id": "11132544244839265378732084165256379227175677028258955804895976429843086532411", "price": "0.02", "size": "18.49", "side": "BUY", "hash": "f46c745503813e1ca5ee2458e9e5ec45db5fe1f2", "best_bid": "0.92", "best_ask": "0.93"}, {"asset_id": "37281046158137671889895383499164526727881692321679587626659940834369685019496", "price": "0.98", "size": "18.49", "side": "SELL", "hash": "b9a70bb4dcfe86ef48b2ef160175424ab0ad70bd", "best_bid": "0.07", "best_ask": "0.08"}], "timestamp": "1769385044498", "event_type": "price_change"}}
{"_local_timestamp": "2026-01-25T23:50:44.592493+00:00", "data": {"market": "0xa65fe234ac3808801290874c631e55bcfee30e437c78239808729a89d9f2de22", "price_changes": [{"asset_id": "37281046158137671889895383499164526727881692321679587626659940834369685019496", "price": "0.04", "size": "14756.12", "side": "BUY", "hash": "e8e23b5ce3a8849834f692c691f83e9f040da4d7", "best_bid": "0.07", "best_ask": "0.08"}, {"asset_id": "11132544244839265378732084165256379227175677028258955804895976429843086532411", "price": "0.96", "size": "14756.12", "side": "SELL", "hash": "7df0d35ea44d363f443a96f900120039963233ae", "best_bid": "0.92", "best_ask": "0.93"}], "timestamp": "1769385044499", "event_type": "price_change"}}
{"_local_timestamp": "2026-01-25T23:50:45.507265+00:00", "data": {"market": "0xa65fe234ac3808801290874c631e55bcfee30e437c78239808729a89d9f2de22", "price_changes": [{"asset_id": "11132544244839265378732084165256379227175677028258955804895976429843086532411", "price": "0.24", "size": "1748", "side": "BUY", "hash": "03d33258f6e10a6443b30195aa7f4d722dc66733", "best_bid": "0.92", "best_ask": "0.93"}, {"asset_id": "37281046158137671889895383499164526727881692321679587626659940834369685019496", "price": "0.76", "size": "1748", "side": "SELL", "hash": "0dc575ce849c39f538a24e429f5f0a2ec69a702a", "best_bid": "0.07", "best_ask": "0.08"}], "timestamp": "1769385045433", "event_type": "price_change"}}
{"_local_timestamp": "2026-01-25T23:50:52.276900+00:00", "data": {"market": "0x6987d084de71031819f82051ea62b29a354628c3e4a22076a2acc197c776080a", "price_changes": [{"asset_id": "63761293627321054794056701530662561252253979399794304476663814039986928052742", "price": "0.31", "size": "1389.92", "side": "SELL", "hash": "6f433e1cfa277b5ddda847e8015dfb64a36d0594", "best_bid": "0.3", "best_ask": "0.31"}, {"asset_id": "94521268801533640253484626268475643884882213091508756864952897781498391313602", "price": "0.69", "size": "1389.92", "side": "BUY", "hash": "01ec0cbf847eed7a014889f91f1fb7cc39eda54e", "best_bid": "0.69", "best_ask": "0.7"}], "timestamp": "1769385052198", "event_type": "price_change"}}
{"_local_timestamp": "2026-01-25T23:51:02.514840+00:00", "data": {"market": "0xa65fe234ac3808801290874c631e55bcfee30e437c78239808729a89d9f2de22", "price_changes": [{"asset_id": "37281046158137671889895383499164526727881692321679587626659940834369685019496", "price": "0.1", "size": "2697.58", "side": "SELL", "hash": "4e9a6d4bc6fd21bd8c8376f6893bc5a7b5ddc7e7", "best_bid": "0.07", "best_ask": "0.08"}, {"asset_id": "11132544244839265378732084165256379227175677028258955804895976429843086532411", "price": "0.9", "size": "2697.58", "side": "BUY", "hash": "fc1f6f1b043f25e6404b28472c8e504f0c1edf10", "best_bid": "0.92", "best_ask": "0.93"}], "timestamp": "1769385062448", "event_type": "price_change"}}
{"_local_timestamp": "2026-01-25T23:51:06.944291+00:00", "data": {"market": "0xa65fe234ac3808801290874c631e55bcfee30e437c78239808729a89d9f2de22", "price_changes": [{"asset_id": "37281046158137671889895383499164526727881692321679587626659940834369685019496", "price": "0.11", "size": "4085.49", "side": "SELL", "hash": "a7fd1c605e0a8fc0cb63865aafc0da34fd2cfce4", "best_bid": "0.07", "best_ask": "0.08"}, {"asset_id": "11132544244839265378732084165256379227175677028258955804895976429843086532411", "price": "0.89", "size": "4085.49", "side": "BUY", "hash": "9e6af2e2eaa5effd7b254908f70b1850b60b3a3e", "best_bid": "0.92", "best_ask": "0.93"}], "timestamp": "1769385066867", "event_type": "price_change"}}
{"_local_timestamp": "2026-01-25T23:51:08.059863+00:00", "data": {"market": "0x6987d084de71031819f82051ea62b29a354628c3e4a22076a2acc197c776080a", "price_changes": [{"asset_id": "63761293627321054794056701530662561252253979399794304476663814039986928052742", "price": "0.31", "size": "1401.57", "side": "SELL", "hash": "cdcfb918335bee0612243925bc1832177a36cc3e", "best_bid": "0.3", "best_ask": "0.31"}, {"asset_id": "94521268801533640253484626268475643884882213091508756864952897781498391313602", "price": "0.69", "size": "1401.57", "side": "BUY", "hash": "87da61a9dae6041ff798ee2248feacd9cd08f8d9", "best_bid": "0.69", "best_ask": "0.7"}], "timestamp": "1769385067978", "event_type": "price_change"}}
{"_local_timestamp": "2026-01-25T23:51:08.060178+00:00", "data": {"market": "0x6987d084de71031819f82051ea62b29a354628c3e4a22076a2acc197c776080a", "price_changes": [{"asset_id": "63761293627321054794056701530662561252253979399794304476663814039986928052742", "price": "0.31", "size": "1413.22", "side": "SELL", "hash": "dbea4e7189ebde3736c4b6fc2b5c80914ff69c03", "best_bid": "0.3", "best_ask": "0.31"}, {"asset_id": "94521268801533640253484626268475643884882213091508756864952897781498391313602", "price": "0.69", "size": "1413.22", "side": "BUY", "hash": "9f759927c5fdf8b2586130128d53c123258ad2e2", "best_bid": "0.69", "best_ask": "0.7"}], "timestamp": "1769385067979", "event_type": "price_change"}}
{"_local_timestamp": "2026-01-25T23:51:08.060418+00:00", "data": {"market": "0x6987d084de71031819f82051ea62b29a354628c3e4a22076a2acc197c776080a", "price_changes": [{"asset_id": "63761293627321054794056701530662561252253979399794304476663814039986928052742", "price": "0.31", "size": "1424.87", "side": "SELL", "hash": "0e486fe7b3bfd0d0147efedfa4390cddeaab43ad", "best_bid": "0.3", "best_ask": "0.31"}, {"asset_id": "94521268801533640253484626268475643884882213091508756864952897781498391313602", "price": "0.69", "size": "1424.87", "side": "BUY", "hash": "d296dfcbbb283535b09fa7ff8d9639e33c982382", "best_bid": "0.69", "best_ask": "0.7"}], "timestamp": "1769385067979", "event_type": "price_change"}}
{"_local_timestamp": "2026-01-25T23:51:12.255081+00:00", "data": {"market": "0xa65fe234ac3808801290874c631e55bcfee30e437c78239808729a89d9f2de22", "price_changes": [{"asset_id": "11132544244839265378732084165256379227175677028258955804895976429843086532411", "price": "0.38", "size": "1578", "side": "BUY", "hash": "94b376bb1242b683924196b3886bc7559735b2ed", "best_bid": "0.92", "best_ask": "0.93"}, {"asset_id": "37281046158137671889895383499164526727881692321679587626659940834369685019496", "price": "0.62", "size": "1578", "side": "SELL", "hash": "58e0c49b9a58fc3f3c38c0e0a8bb6cf659c2f6f7", "best_bid": "0.07", "best_ask": "0.08"}], "timestamp": "1769385072185", "event_type": "price_change"}}
{"_local_timestamp": "2026-01-25T23:51:20.505379+00:00", "data": {"market": "0xa65fe234ac3808801290874c631e55bcfee30e437c78239808729a89d9f2de22", "price_changes": [{"asset_id": "37281046158137671889895383499164526727881692321679587626659940834369685019496", "price": "0.11", "size": "3923.05", "side": "SELL", "hash": "fae24950a6b0bae4f18a971895bdc87b0fe2fd25", "best_bid": "0.07", "best_ask": "0.08"}, {"asset_id": "11132544244839265378732084165256379227175677028258955804895976429843086532411", "price": "0.89", "size": "3923.05", "side": "BUY", "hash": "53387db9827144504f9afb96d1b1687e3a5ef2f0", "best_bid": "0.92", "best_ask": "0.93"}], "timestamp": "1769385080438", "event_type": "price_change"}}
{"_local_timestamp": "2026-01-25T23:51:24.249733+00:00", "data": {"market": "0xa65fe234ac3808801290874c631e55bcfee30e437c78239808729a89d9f2de22", "price_changes": [{"asset_id": "37281046158137671889895383499164526727881692321679587626659940834369685019496", "price": "0.1", "size": "2860.02", "side": "SELL", "hash": "11d185a9e7bce4d6d761c9983f454e81d15e42fc", "best_bid": "0.07", "best_ask": "0.08"}, {"asset_id": "11132544244839265378732084165256379227175677028258955804895976429843086532411", "price": "0.9", "size": "2860.02", "side": "BUY", "hash": "01f1f04989c40809fe48997e6ca4c0afff493a3c", "best_bid": "0.92", "best_ask": "0.93"}], "timestamp": "1769385084181", "event_type": "price_change"}}
{"_local_timestamp": "2026-01-25T23:51:27.984051+00:00", "data": {"market": "0xa65fe234ac3808801290874c631e55bcfee30e437c78239808729a89d9f2de22", "price_changes": [{"asset_id": "11132544244839265378732084165256379227175677028258955804895976429843086532411", "price": "0.24", "size": "0", "side": "BUY", "hash": "bd8dc3195740e35a89bf92995a72e7c539113c9a", "best_bid": "0.92", "best_ask": "0.93"}, {"asset_id": "37281046158137671889895383499164526727881692321679587626659940834369685019496", "price": "0.76", "size": "0", "side": "SELL", "hash": "89d97dadc353c361b7761ac098a5d73ddc92e07e", "best_bid": "0.07", "best_ask": "0.08"}], "timestamp": "1769385087766", "event_type": "price_change"}}
{"_local_timestamp": "2026-01-25T23:51:28.073987+00:00", "data": {"market": "0x5f33f46fa571836f090ef8f3e62caee237f8f73c36a711e757a6f71bf8ef9c6a", "price_changes": [{"asset_id": "96229871085374132303116376471322311695842738677806841162553339355812305824040", "price": "0.15", "size": "0", "side": "BUY", "hash": "c81937539c4c649f37fb08bea4e593f2412fbe84", "best_bid": "0.53", "best_ask": "0.55"}, {"asset_id": "3464795463763108108909057219187376740735691886447931192725079515654033695019", "price": "0.85", "size": "0", "side": "SELL", "hash": "e444bde73444b89c04e017b7ff3ea77a13449cb2", "best_bid": "0.45", "best_ask": "0.47"}], "timestamp": "1769385087774", "event_type": "price_change"}}
