{"_local_timestamp": "2026-01-25T23:40:48.291698+00:00", "data": [{"market": "0x74a960f6e74324d124183f786467b089beebaaa34b075181c55e823b18bde048", "asset_id": "78793947695488461906291194696651727856206095791749037634142632859804304098517", "timestamp": "1769382721186", "hash": "e94c6f8c1b6deebc1a56074f5a02565cdbec5390", "bids": [{"price": "0.001", "size": "120295"}, {"price": "0.002", "size": "1328.18"}], "asks": [{"price": "0.999", "size": "3842.07"}, {"price": "0.998", "size": "1255.04"}, {"price": "0.997", "size": "1166"}, {"price": "0.996", "size": "8.63"}, {"price": "0.994", "size": "83"}, {"price": "0.99", "size": "5550"}, {"price": "0.989", "size": "8.38"}, {"price": "0.98", "size": "102500"}, {"price": "0.97", "size": "5000"}, {"price": "0.969", "size": "8.35"}, {"price": "0.95", "size": "30"}, {"price": "0.949", "size": "39"}, {"price": "0.94", "size": "500"}, {"price": "0.9", "size": "1860"}, {"price": "0.899", "size": "5.93"}, {"price": "0.85", "size": "776.66"}, {"price": "0.8", "size": "560"}, {"price": "0.75", "size": "50412"}, {"price": "0.749", "size": "250"}, {"price": "0.748", "size": "7"}, {"price": "0.7", "size": "186.66"}, {"price": "0.66", "size": "50"}, {"price": "0.65", "size": "68.57"}, {"price": "0.6", "size": "50"}, {"price": "0.55", "size": "560"}, {"price": "0.45", "size": "800"}, {"price": "0.15", "size": "2808.91"}, {"price": "0.09", "size": "640"}, {"price": "0.07", "size": "300"}, {"price": "0.069", "size": "2000"}, {"price": "0.06", "size": "600"}, {"price": "0.059", "size": "1500"}, {"price": "0.05", "size": "325"}, {"price": "0.049", "size": "1000"}, {"price": "0.039", "size": "200"}, {"price": "0.019", "size": "5000"}, {"price": "0.018", "size": "5000"}, {"price": "0.017", "size": "5000"}, {"price": "0.016", "size": "5158.37"}, {"price": "0.015", "size": "5079.18"}, {"price": "0.014", "size": "4799.22"}, {"price": "0.013", "size": "4279.6"}, {"price": "0.012", "size": "3000"}, {"price": "0.011", "size": "3000"}, {"price": "0.01", "size": "3000"}, {"price": "0.009", "size": "1291.71"}, {"price": "0.008", "size": "3490.42"}, {"price": "0.007", "size": "2000"}, {"price": "0.006", "size": "2010"}, {"price": "0.005", "size": "1298"}, {"price": "0.004", "size": "1596.11"}, {"price": "0.003", "size": "1736.62"}], "event_type": "book", "last_trade_price": "0.002"}, {"market": "0x74a960f6e74324d124183f786467b089beebaaa34b075181c55e823b18bde048", "asset_id": "53492410658013589906025024789262884004829357354045647893742495711330889023510", "timestamp": "1769382721186", "hash": "c1179471de5a5ece7b109c35283092c64c450ba6", "bids": [{"price": "0.001", "size": "3842.07"}, {"price": "0.002", "size": "1255.04"}, {"price": "0.003", "size": "1166"}, {"price": "0.004", "size": "8.63"}, {"price": "0.006", "size": "83"}, {"price": "0.01", "size": "5550"}, {"price": "0.011", "size": "8.38"}, {"price": "0.02", "size": "102500"}, {"price": "0.03", "size": "5000"}, {"price": "0.031", "size": "8.35"}, {"price": "0.05", "size": "30"}, {"price": "0.051", "size": "39"}, {"price": "0.06", "size": "500"}, {"price": "0.1", "size": "1860"}, {"price": "0.101", "size": "5.93"}, {"price": "0.15", "size": "776.66"}, {"price": "0.2", "size": "560"}, {"price": "0.25", "size": "50412"}, {"price": "0.251", "size": "250"}, {"price": "0.252", "size": "7"}, {"price": "0.3", "size": "186.66"}, {"price": "0.34", "size": "50"}, {"price": "0.35", "size": "68.57"}, {"price": "0.4", "size": "50"}, {"price": "0.45", "size": "560"}, {"price": "0.55", "size": "800"}, {"price": "0.85", "size": "2808.91"}, {"price": "0.91", "size": "640"}, {"price": "0.93", "size": "300"}, {"price": "0.931", "size": "2000"}, {"price": "0.94", "size": "600"}, {"price": "0.941", "size": "1500"}, {"price": "0.95", "size": "325"}, {"price": "0.951", "size": "1000"}, {"price": "0.961", "size": "200"}, {"price": "0.981", "size": "5000"}, {"price": "0.982", "size": "5000"}, {"price": "0.983", "size": "5000"}, {"price": "0.984", "size": "5158.37"}, {"price": "0.985", "size": "5079.18"}, {"price": "0.986", "size": "4799.22"}, {"price": "0.987", "size": "4279.6"}, {"price": "0.988", "size": "3000"}, {"price": "0.989", "size": "3000"}, {"price": "0.99", "size": "3000"}, {"price": "0.991", "size": "1291.71"}, {"price": "0.992", "size": "3490.42"}, {"price": "0.993", "size": "2000"}, {"price": "0.994", "size": "2010"}, {"price": "0.995", "size": "1298"}, {"price": "0.996", "size": "1596.11"}, {"price": "0.997", "size": "1736.62"}], "asks": [{"price": "0.999", "size": "120295"}, {"price": "0.998", "size": "1328.18"}], "event_type": "book", "last_trade_price": "0.002"}, {"market": "0x60ecb823bb667a51ccf9ffcb1cab2c48899cd16410687874887dab9df9f4e1bf", "asset_id": "19998490588165385691634000405206222117826113177925708815328988090662305366225", "timestamp": "1769384438000", "hash": "2fcfb703931104fcd00229a4cab6d0bf7a13431f", "bids": [{"price": "0.01", "size": "116347.51"}, {"price": "0.02", "size": "5348"}, {"price": "0.03", "size": "817.3"}, {"price": "0.04", "size": "567.17"}], "asks": [{"price": "0.99", "size": "10664.21"}, {"price": "0.98", "size": "105000"}, {"price": "0.97", "size": "4000"}, {"price": "0.96", "size": "1256.48"}, {"price": "0.95", "size": "280"}, {"price": "0.94", "size": "533"}, {"price": "0.9", "size": "560"}, {"price": "0.89", "size": "5.44"}, {"price": "0.86", "size": "242.85"}, {"price": "0.85", "size": "600"}, {"price": "0.81", "size": "168.42"}, {"price": "0.8", "size": "400"}, {"price": "0.77", "size": "694"}, {"price": "0.76", "size": "1964.66"}, {"price": "0.75", "size": "150"}, {"price": "0.71", "size": "89.65"}, {"price": "0.7", "size": "600"}, {"price": "0.66", "size": "70.58"}, {"price": "0.65", "size": "1814"}, {"price": "0.62", "size": "127.63"}, {"price": "0.44", "size": "30000"}, {"price": "0.43", "size": "5000"}, {"price": "0.42", "size": "5"}, {"price": "0.26", "size": "600"}, {"price": "0.08", "size": "250"}, {"price": "0.06", "size": "11161"}, {"price": "0.05", "size": "996.03"}], "event_type": "book", "last_trade_price": ""}, {"market": "0x60ecb823bb667a51ccf9ffcb1cab2c48899cd16410687874887dab9df9f4e1bf", "asset_id": "6727724717965804812582437828646736972344757795103515098740782022977766715112", "timestamp": "1769384438000", "hash": "76421530fae038538f60822c5820e2be9369a670", "bids": [{"price": "0.01", "size": "10664.21"}, {"price": "0.02", "size": "105000"}, {"price": "0.03", "size": "4000"}, {"price": "0.04", "size": "1256.48"}, {"price": "0.05", "size": "280"}, {"price": "0.06", "size": "533"}, {"price": "0.1", "size": "560"}, {"price": "0.11", "size": "5.44"}, {"price": "0.14", "size": "242.85"}, {"price": "0.15", "size": "600"}, {"price": "0.19", "size": "168.42"}, {"price": "0.2", "size": "400"}, {"price": "0.23", "size": "694"}, {"price": "0.24", "size": "1964.66"}, {"price": "0.25", "size": "150"}, {"price": "0.29", "size": "89.65"}, {"price": "0.3", "size": "600"}, {"price": "0.34", "size": "70.58"}, {"price": "0.35", "size": "1814"}, {"price": "0.38", "size": "127.63"}, {"price": "0.56", "size": "30000"}, {"price": "0.57", "size": "5000"}, {"price": "0.58", "size": "5"}, {"price": "0.74", "size": "600"}, {"price": "0.92", "size": "250"}, {"price": "0.94", "size": "11161"}, {"price": "0.95", "size": "996.03"}], "asks": [{"price": "0.99", "size": "116347.51"}, {"price": "0.98", "size": "5348"}, {"price": "0.97", "size": "817.3"}, {"price": "0.96", "size": "567.17"}], "event_type": "book", "last_trade_price": ""}]}
{"_local_timestamp": "2026-01-25T23:41:06.363007+00:00", "data": {"market": "0x60ecb823bb667a51ccf9ffcb1cab2c48899cd16410687874887dab9df9f4e1bf", "price_changes": [{"asset_id": "19998490588165385691634000405206222117826113177925708815328988090662305366225", "price": "0.02", "size": "5298", "side": "BUY", "hash": "8113fd88397268ba6c33ef00fd435205690cabb7", "best_bid": "0.04", "best_ask": "0.05"}, {"asset_id": "6727724717965804812582437828646736972344757795103515098740782022977766715112", "price": "0.98", "size": "5298", "side": "SELL", "hash": "3f27cfcfaf3d72ea50f2f6fb9a941675da5da51a", "best_bid": "0.95", "best_ask": "0.96"}], "timestamp": "1769384466196", "event_type": "price_change"}}
{"_local_timestamp": "2026-01-25T23:41:06.427753+00:00", "data": {"market": "0x60ecb823bb667a51ccf9ffcb1cab2c48899cd16410687874887dab9df9f4e1bf", "price_changes": [{"asset_id": "6727724717965804812582437828646736972344757795103515098740782022977766715112", "price": "0.92", "size": "200", "side": "BUY", "hash": "93c4287ffe92aa7cc344ba9008665f2820800932", "best_bid": "0.95", "best_ask": "0.96"}, {"asset_id": "19998490588165385691634000405206222117826113177925708815328988090662305366225", "price": "0.08", "size": "200", "side": "SELL", "hash": "fd87d7c6ecbcb81234974bb3110e591e21be5877", "best_bid": "0.04", "best_ask": "0.05"}], "timestamp": "1769384466199", "event_type": "price_change"}}
{"_local_timestamp": "2026-01-25T23:41:12.367298+00:00", "data": {"market": "0x60ecb823bb667a51ccf9ffcb1cab2c48899cd16410687874887dab9df9f4e1bf", "price_changes": [{"asset_id": "19998490588165385691634000405206222117826113177925708815328988090662305366225", "price": "0.01", "size": "116847.51", "side": "BUY", "hash": "e75502db363b39f6a90f8aa895a7a7ea2ef5efe1", "best_bid": "0.04", "best_ask": "0.05"}, {"asset_id": "6727724717965804812582437828646736972344757795103515098740782022977766715112", "price": "0.99", "size": "116847.51", "side": "SELL", "hash": "a5f57b9589c2217060436f55a25d4ecd32f49fa8", "best_bid": "0.95", "best_ask": "0.96"}], "timestamp": "1769384472305", "event_type": "price_change"}}
{"_local_timestamp": "2026-01-25T23:41:14.736279+00:00", "data": {"market": "0x60ecb823bb667a51ccf9ffcb1cab2c48899cd16410687874887dab9df9f4e1bf", "price_changes": [{"asset_id": "6727724717965804812582437828646736972344757795103515098740782022977766715112", "price": "0.24", "size": "216.66", "side": "BUY", "hash": "5646029049cb7ec2d3ba4e44eeeef4f907cbcc87", "best_bid": "0.95", "best_ask": "0.96"}, {"asset_id": "19998490588165385691634000405206222117826113177925708815328988090662305366225", "price": "0.76", "size": "216.66", "side": "SELL", "hash": "39252b019d17db1e264c9a8b50197b04661f4197", "best_bid": "0.04", "best_ask": "0.05"}], "timestamp": "1769384474537", "event_type": "price_change"}}
{"_local_timestamp": "2026-01-25T23:41:18.816910+00:00", "data": {"market": "0x60ecb823bb667a51ccf9ffcb1cab2c48899cd16410687874887dab9df9f4e1bf", "price_changes": [{"asset_id": "19998490588165385691634000405206222117826113177925708815328988090662305366225", "price": "0.02", "size": "5348", "side": "BUY", "hash": "30bc11df91381dbcb4dc259e85722584c1d82a5a", "best_bid": "0.04", "best_ask": "0.05"}, {"asset_id": "6727724717965804812582437828646736972344757795103515098740782022977766715112", "price": "0.98", "size": "5348", "side": "SELL", "hash": "b9937ef738e9a61e87dc61abcbbff41f2ce8176f", "best_bid": "0.95", "best_ask": "0.96"}], "timestamp": "1769384478709", "event_type": "price_change"}}
{"_local_timestamp": "2026-01-25T23:41:36.891582+00:00", "data": {"market": "0x60ecb823bb667a51ccf9ffcb1cab2c48899cd16410687874887dab9df9f4e1bf", "price_changes": [{"asset_id": "6727724717965804812582437828646736972344757795103515098740782022977766715112", "price": "0.92", "size": "250", "side": "BUY", "hash": "3a7cab097b9337384dd3221417e503235d6909e4", "best_bid": "0.95", "best_ask": "0.96"}, {"asset_id": "19998490588165385691634000405206222117826113177925708815328988090662305366225", "price": "0.08", "size": "250", "side": "SELL", "hash": "783d854bd66430ae598d16732c848fd56a55f301", "best_bid": "0.04", "best_ask": "0.05"}], "timestamp": "1769384496822", "event_type": "price_change"}}
{"_local_timestamp": "2026-01-25T23:41:45.303102+00:00", "data": {"market": "0x60ecb823bb667a51ccf9ffcb1cab2c48899cd16410687874887dab9df9f4e1bf", "price_changes": [{"asset_id": "6727724717965804812582437828646736972344757795103515098740782022977766715112", "price": "0.26", "size": "1614", "side": "BUY", "hash": "15f9cf94a2e02d8f503c2450463c8542701dcd11", "best_bid": "0.95", "best_ask": "0.96"}, {"asset_id": "19998490588165385691634000405206222117826113177925708815328988090662305366225", "price": "0.74", "size": "1614", "side": "SELL", "hash": "ecc9002fc34a0451bf0dc293810f2a81dde7298f", "best_bid": "0.04", "best_ask": "0.05"}], "timestamp": "1769384505234", "event_type": "price_change"}}
{"_local_timestamp": "2026-01-25T23:41:47.075354+00:00", "data": {"market": "0x60ecb823bb667a51ccf9ffcb1cab2c48899cd16410687874887dab9df9f4e1bf", "price_changes": [{"asset_id": "19998490588165385691634000405206222117826113177925708815328988090662305366225", "price": "0.01", "size": "110947.51", "side": "BUY", "hash": "3538336f995dcd91dc9ad6439b65156d553779db", "best_bid": "0.04", "best_ask": "0.05"}, {"asset_id": "6727724717965804812582437828646736972344757795103515098740782022977766715112", "price": "0.99", "size": "110947.51", "side": "SELL", "hash": "9667b109788890ef5358d5e216197dc1a8986e75", "best_bid": "0.95", "best_ask": "0.96"}], "timestamp": "1769384507001", "event_type": "price_change"}}
{"_local_timestamp": "2026-01-25T23:41:48.850208+00:00", "data": {"market": "0x60ecb823bb667a51ccf9ffcb1cab2c48899cd16410687874887dab9df9f4e1bf", "price_changes": [{"asset_id": "19998490588165385691634000405206222117826113177925708815328988090662305366225", "price": "0.01", "size": "116847.51", "side": "BUY", "hash": "80b002e73776c3cefcd552a5118f02703552d649", "best_bid": "0.04", "best_ask": "0.05"}, {"asset_id": "6727724717965804812582437828646736972344757795103515098740782022977766715112", "price": "0.99", "size": "116847.51", "side": "SELL", "hash": "1b45bc56a1ed4297be3f88549d40159f327567e5", "best_bid": "0.95", "best_ask": "0.96"}], "timestamp": "1769384508774", "event_type": "price_change"}}
{"_local_timestamp": "2026-01-25T23:41:49.463346+00:00", "data": {"market": "0x60ecb823bb667a51ccf9ffcb1cab2c48899cd16410687874887dab9df9f4e1bf", "price_changes": [{"asset_id": "6727724717965804812582437828646736972344757795103515098740782022977766715112", "price": "0.24", "size": "116.66", "side": "BUY", "hash": "dd0c6348e164d96db597bf9f65204d16ebc27f92", "best_bid": "0.95", "best_ask": "0.96"}, {"asset_id": "19998490588165385691634000405206222117826113177925708815328988090662305366225", "price": "0.76", "size": "116.66", "side": "SELL", "hash": "b07c180a393b41ed3e34a89a1ea8f64d764333ef", "best_bid": "0.04", "best_ask": "0.05"}], "timestamp": "1769384509394", "event_type": "price_change"}}
{"_local_timestamp": "2026-01-25T23:41:49.727298+00:00", "data": {"market": "0x60ecb823bb667a51ccf9ffcb1cab2c48899cd16410687874887dab9df9f4e1bf", "price_changes": [{"asset_id": "6727724717965804812582437828646736972344757795103515098740782022977766715112", "price": "0.23", "size": "794", "side": "BUY", "hash": "595560fddf7fed084ced9cc543627ef41495eafb", "best_bid": "0.95", "best_ask": "0.96"}, {"asset_id": "19998490588165385691634000405206222117826113177925708815328988090662305366225", "price": "0.77", "size": "794", "side": "SELL", "hash": "776a0ebb334581d81ddbe740464ad9329f2d3564", "best_bid": "0.04", "best_ask": "0.05"}], "timestamp": "1769384509660", "event_type": "price_change"}}
{"_local_timestamp": "2026-01-25T23:41:50.867544+00:00", "data": {"market": "0x60ecb823bb667a51ccf9ffcb1cab2c48899cd16410687874887dab9df9f4e1bf", "price_changes": [{"asset_id": "6727724717965804812582437828646736972344757795103515098740782022977766715112", "price": "0.25", "size": "50", "side": "BUY", "hash": "235ddb170edca28d439ba9847a9084fc13b206ee", "best_bid": "0.95", "best_ask": "0.96"}, {"asset_id": "19998490588165385691634000405206222117826113177925708815328988090662305366225", "price": "0.75", "size": "50", "side": "SELL", "hash": "51819abeb2a94c0c5d8bd54f499dd9ee34e956f6", "best_bid": "0.04", "best_ask": "0.05"}], "timestamp": "1769384510741", "event_type": "price_change"}}
{"_local_timestamp": "2026-01-25T23:41:52.800022+00:00", "data": {"market": "0x60ecb823bb667a51ccf9ffcb1cab2c48899cd16410687874887dab9df9f4e1bf", "price_changes": [{"asset_id": "6727724717965804812582437828646736972344757795103515098740782022977766715112", "price": "0.3", "size": "700", "side": "BUY", "hash": "d149d083710646bdc42d6e98f079d6e57c489cc2", "best_bid": "0.95", "best_ask": "0.96"}, {"asset_id": "19998490588165385691634000405206222117826113177925708815328988090662305366225", "price": "0.7", "size": "700", "side": "SELL", "hash": "4ed8c8043ea5e354a02ee2bc01957ecae675fcbf", "best_bid": "0.04", "best_ask": "0.05"}], "timestamp": "1769384511785", "event_type": "price_change"}}
{"_local_timestamp": "2026-01-25T23:42:24.997020+00:00", "data": {"market": "0x60ecb823bb667a51ccf9ffcb1cab2c48899cd16410687874887dab9df9f4e1bf", "price_changes": [{"asset_id": "6727724717965804812582437828646736972344757795103515098740782022977766715112", "price": "0.3", "size": "650", "side": "BUY", "hash": "7177834bf625ce78390c79cad9c38ea6e09a2a8d", "best_bid": "0.95", "best_ask": "0.96"}, {"asset_id": "19998490588165385691634000405206222117826113177925708815328988090662305366225", "price": "0.7", "size": "650", "side": "SELL", "hash": "b95834b10b9806832563d182f6c9323d62a188a9", "best_bid": "0.04", "best_ask": "0.05"}], "timestamp": "1769384544882", "event_type": "price_change"}}
{"_local_timestamp": "2026-01-25T23:42:25.300773+00:00", "data": {"market": "0x60ecb823bb667a51ccf9ffcb1cab2c48899cd16410687874887dab9df9f4e1bf", "price_changes": [{"asset_id": "6727724717965804812582437828646736972344757795103515098740782022977766715112", "price": "0.26", "size": "1664", "side": "BUY", "hash": "b6a426d8f5217d1ed5b14fe908c60a3aa3645290", "best_bid": "0.95", "best_ask": "0.96"}, {"asset_id": "19998490588165385691634000405206222117826113177925708815328988090662305366225", "price": "0.74", "size": "1664", "side": "SELL", "hash": "820432634a1703288a1f0e16f893b4f70a7a080a", "best_bid": "0.04", "best_ask": "0.05"}], "timestamp": "1769384545158", "event_type": "price_change"}}
{"_local_timestamp": "2026-01-25T23:42:45.417977+00:00", "data": {"market": "0x60ecb823bb667a51ccf9ffcb1cab2c48899cd16410687874887dab9df9f4e1bf", "price_changes": [{"asset_id": "6727724717965804812582437828646736972344757795103515098740782022977766715112", "price": "0.25", "size": "0", "side": "BUY", "hash": "16f3051e4970850c0448733000bce06627b5c2b9", "best_bid": "0.95", "best_ask": "0.96"}, {"asset_id": "19998490588165385691634000405206222117826113177925708815328988090662305366225", "price": "0.75", "size": "0", "side": "SELL", "hash": "3a911a1aaebe4b8fc8cb32002c412c3c940953cc", "best_bid": "0.04", "best_ask": "0.05"}], "timestamp": "1769384565220", "event_type": "price_change"}}
{"_local_timestamp": "2026-01-25T23:42:45.805162+00:00", "data": {"market": "0x60ecb823bb667a51ccf9ffcb1cab2c48899cd16410687874887dab9df9f4e1bf", "price_changes": [{"asset_id": "6727724717965804812582437828646736972344757795103515098740782022977766715112", "price": "0.24", "size": "166.66", "side": "BUY", "hash": "11a3f7f832899c30210657a6938724facda16e4f", "best_bid": "0.95", "best_ask": "0.96"}, {"asset_id": "19998490588165385691634000405206222117826113177925708815328988090662305366225", "price": "0.76", "size": "166.66", "side": "SELL", "hash": "2cc92643896a7f3cab10e23d13b723156a3cd2aa", "best_bid": "0.04", "best_ask": "0.05"}], "timestamp": "1769384565615", "event_type": "price_change"}}
{"_local_timestamp": "2026-01-25T23:42:47.246049+00:00", "data": {"market": "0x60ecb823bb667a51ccf9ffcb1cab2c48899cd16410687874887dab9df9f4e1bf", "price_changes": [{"asset_id": "6727724717965804812582437828646736972344757795103515098740782022977766715112", "price": "0.26", "size": "50", "side": "BUY", "hash": "7115b2b6a49e1c197e6c402a76b1b20be004321f", "best_bid": "0.95", "best_ask": "0.96"}, {"asset_id": "19998490588165385691634000405206222117826113177925708815328988090662305366225", "price": "0.74", "size": "50", "side": "SELL", "hash": "1bebb4f5033e20963fb1f369804fcafc87c711e5", "best_bid": "0.04", "best_ask": "0.05"}], "timestamp": "1769384566990", "event_type": "price_change"}}
{"_local_timestamp": "2026-01-25T23:42:52.163783+00:00", "data": {"market": "0x60ecb823bb667a51ccf9ffcb1cab2c48899cd16410687874887dab9df9f4e1bf", "price_changes": [{"asset_id": "19998490588165385691634000405206222117826113177925708815328988090662305366225", "price": "0.01", "size": "116838", "side": "BUY", "hash": "f9d0278dad0f10986357db2ab5b6f8b75ca0e23f", "best_bid": "0.04", "best_ask": "0.05"}, {"asset_id": "6727724717965804812582437828646736972344757795103515098740782022977766715112", "price": "0.99", "size": "116838", "side": "SELL", "hash": "2affeecfcdcc734f8b530b16017fe98fcbc93e0e", "best_bid": "0.95", "best_ask": "0.96"}], "timestamp": "1769384572028", "event_type": "price_change"}}
{"_local_timestamp": "2026-01-25T23:42:52.164375+00:00", "data": {"market": "0x60ecb823bb667a51ccf9ffcb1cab2c48899cd16410687874887dab9df9f4e1bf", "price_changes": [{"asset_id": "19998490588165385691634000405206222117826113177925708815328988090662305366225", "price": "0.02", "size": "5302.76", "side": "BUY", "hash": "f9d0278dad0f10986357db2ab5b6f8b75ca0e23f", "best_bid": "0.04", "best_ask": "0.05"}, {"asset_id": "6727724717965804812582437828646736972344757795103515098740782022977766715112", "price": "0.98", "size": "5302.76", "side": "SELL", "hash": "2affeecfcdcc734f8b530b16017fe98fcbc93e0e", "best_bid": "0.95", "best_ask": "0.96"}], "timestamp": "1769384572028", "event_type": "price_change"}}
{"_local_timestamp": "2026-01-25T23:42:52.531697+00:00", "data": {"market": "0x60ecb823bb667a51ccf9ffcb1cab2c48899cd16410687874887dab9df9f4e1bf", "price_changes": [{"asset_id": "19998490588165385691634000405206222117826113177925708815328988090662305366225", "price": "0.02", "size": "5348", "side": "BUY", "hash": "d326990a82e4199f990bc83fb89087bef3cb02c6", "best_bid": "0.04", "best_ask": "0.05"}, {"asset_id": "6727724717965804812582437828646736972344757795103515098740782022977766715112", "price": "0.98", "size": "5348", "side": "SELL", "hash": "d654860c9d8532f1972d9cfaddae8d94ec730b2f", "best_bid": "0.95", "best_ask": "0.96"}], "timestamp": "1769384572426", "event_type": "price_change"}}
{"_local_timestamp": "2026-01-25T23:42:52.532231+00:00", "data": {"market": "0x60ecb823bb667a51ccf9ffcb1cab2c48899cd16410687874887dab9df9f4e1bf", "price_changes": [{"asset_id": "19998490588165385691634000405206222117826113177925708815328988090662305366225", "price": "0.01", "size": "116847.51", "side": "BUY", "hash": "1498262e06dddb049c6f360bd8f0137bfd874b9a", "best_bid": "0.04", "best_ask": "0.05"}, {"asset_id": "6727724717965804812582437828646736972344757795103515098740782022977766715112", "price": "0.99", "size": "116847.51", "side": "SELL", "hash": "dbaf143d4920d20ef31f41850e5c4a8301443337", "best_bid": "0.95", "best_ask": "0.96"}], "timestamp": "1769384572428", "event_type": "price_change"}}
{"_local_timestamp": "2026-01-25T23:43:24.164351+00:00", "data": {"market": "0x60ecb823bb667a51ccf9ffcb1cab2c48899cd16410687874887dab9df9f4e1bf", "price_changes": [{"asset_id": "6727724717965804812582437828646736972344757795103515098740782022977766715112", "price": "0.24", "size": "1914.66", "side": "BUY", "hash": "8ec984a970a2c2b36af0e857f3f159a76f591900", "best_bid": "0.95", "best_ask": "0.96"}, {"asset_id": "19998490588165385691634000405206222117826113177925708815328988090662305366225", "price": "0.76", "size": "1914.66", "side": "SELL", "hash": "f1aab1b34e01edf40460575d190568f191dd0f19", "best_bid": "0.04", "best_ask": "0.05"}], "timestamp": "1769384604032", "event_type": "price_change"}}
{"_local_timestamp": "2026-01-25T23:43:38.607353+00:00", "data": {"market": "0x60ecb823bb667a51ccf9ffcb1cab2c48899cd16410687874887dab9df9f4e1bf", "price_changes": [{"asset_id": "6727724717965804812582437828646736972344757795103515098740782022977766715112", "price": "0.26", "size": "0", "side": "BUY", "hash": "309f1ae8c023763b081bc82d046563b05e470f95", "best_bid": "0.95", "best_ask": "0.96"}, {"asset_id": "19998490588165385691634000405206222117826113177925708815328988090662305366225", "price": "0.74", "size": "0", "side": "SELL", "hash": "bf2e04c27178bdfa36f2234ce3493c8401a8f593", "best_bid": "0.04", "best_ask": "0.05"}], "timestamp": "1769384618456", "event_type": "price_change"}}
{"_local_timestamp": "2026-01-25T23:43:38.899937+00:00", "data": {"market": "0x60ecb823bb667a51ccf9ffcb1cab2c48899cd16410687874887dab9df9f4e1bf", "price_changes": [{"asset_id": "6727724717965804812582437828646736972344757795103515098740782022977766715112", "price": "0.3", "size": "700", "side": "BUY", "hash": "0441c668b0e3f36849c4c608253c537af6cf8dcb", "best_bid": "0.95", "best_ask": "0.96"}, {"asset_id": "19998490588165385691634000405206222117826113177925708815328988090662305366225", "price": "0.7", "size": "700", "side": "SELL", "hash": "d6cfaa9afbfce25e13104ca27d9bf724bfa239be", "best_bid": "0.04", "best_ask": "0.05"}], "timestamp": "1769384618734", "event_type": "price_change"}}
{"_local_timestamp": "2026-01-25T23:44:18.203620+00:00", "data": {"market": "0x60ecb823bb667a51ccf9ffcb1cab2c48899cd16410687874887dab9df9f4e1bf", "price_changes": [{"asset_id": "6727724717965804812582437828646736972344757795103515098740782022977766715112", "price": "0.23", "size": "694", "side": "BUY", "hash": "717c7ce33692963f77443e8c61d86efbe5661584", "best_bid": "0.95", "best_ask": "0.96"}, {"asset_id": "19998490588165385691634000405206222117826113177925708815328988090662305366225", "price": "0.77", "size": "694", "side": "SELL", "hash": "85bfb086903bde98a8a7ee11af4f2a0425626fd5", "best_bid": "0.04", "best_ask": "0.05"}], "timestamp": "1769384657934", "event_type": "price_change"}}
{"_local_timestamp": "2026-01-25T23:44:18.426338+00:00", "data": {"market": "0x60ecb823bb667a51ccf9ffcb1cab2c48899cd16410687874887dab9df9f4e1bf", "price_changes": [{"asset_id": "6727724717965804812582437828646736972344757795103515098740782022977766715112", "price": "0.24", "size": "2014.66", "side": "BUY", "hash": "e115c7445ee6d1e2cfd642a5cb478fb89581886e", "best_bid": "0.95", "best_ask": "0.96"}, {"asset_id": "19998490588165385691634000405206222117826113177925708815328988090662305366225", "price": "0.76", "size": "2014.66", "side": "SELL", "hash": "2ce268d26ac9ccae72e6d6e385fc621379e2a195", "best_bid": "0.04", "best_ask": "0.05"}], "timestamp": "1769384658174", "event_type": "price_change"}}
{"_local_timestamp": "2026-01-25T23:44:21.025879+00:00", "data": {"market": "0x60ecb823bb667a51ccf9ffcb1cab2c48899cd16410687874887dab9df9f4e1bf", "price_changes": [{"asset_id": "6727724717965804812582437828646736972344757795103515098740782022977766715112", "price": "0.3", "size": "600", "side": "BUY", "hash": "e1dbbee7f40e479c8755be37a889fffff902db39", "best_bid": "0.95", "best_ask": "0.96"}, {"asset_id": "19998490588165385691634000405206222117826113177925708815328988090662305366225", "price": "0.7", "size": "600", "side": "SELL", "hash": "57b55a54af7de37c63c59a51fa5a42358eaff8fb", "best_bid": "0.04", "best_ask": "0.05"}], "timestamp": "1769384660486", "event_type": "price_change"}}
{"_local_timestamp": "2026-01-25T23:44:21.498783+00:00", "data": {"market": "0x60ecb823bb667a51ccf9ffcb1cab2c48899cd16410687874887dab9df9f4e1bf", "price_changes": [{"asset_id": "6727724717965804812582437828646736972344757795103515098740782022977766715112", "price": "0.26", "size": "100", "side": "BUY", "hash": "b18ccaf3dd0483dc7a0a86ca8553fdd231388aba", "best_bid": "0.95", "best_ask": "0.96"}, {"asset_id": "19998490588165385691634000405206222117826113177925708815328988090662305366225", "price": "0.74", "size": "100", "side": "SELL", "hash": "83152413ac61a34f4fbf0953c8f13d7bbd2a0453", "best_bid": "0.04", "best_ask": "0.05"}], "timestamp": "1769384660840", "event_type": "price_change"}}
{"_local_timestamp": "2026-01-25T23:44:32.687538+00:00", "data": {"market": "0x60ecb823bb667a51ccf9ffcb1cab2c48899cd16410687874887dab9df9f4e1bf", "price_changes": [{"asset_id": "6727724717965804812582437828646736972344757795103515098740782022977766715112", "price": "0.24", "size": "266.66", "side": "BUY", "hash": "3066ef6ab7c6d4dd652f040c0b7ecffee0ee707f", "best_bid": "0.95", "best_ask": "0.96"}, {"asset_id": "19998490588165385691634000405206222117826113177925708815328988090662305366225", "price": "0.76", "size": "266.66", "side": "SELL", "hash": "84c2d20d3412f8e613fca5f5a84047c18dd0d708", "best_bid": "0.04", "best_ask": "0.05"}], "timestamp": "1769384672301", "event_type": "price_change"}}
{"_local_timestamp": "2026-01-25T23:44:57.845352+00:00", "data": {"market": "0x60ecb823bb667a51ccf9ffcb1cab2c48899cd16410687874887dab9df9f4e1bf", "price_changes": [{"asset_id": "6727724717965804812582437828646736972344757795103515098740782022977766715112", "price": "0.24", "size": "216.66", "side": "BUY", "hash": "045face860e595b8d205e40a905eb52910adc563", "best_bid": "0.95", "best_ask": "0.96"}, {"asset_id": "19998490588165385691634000405206222117826113177925708815328988090662305366225", "price": "0.76", "size": "216.66", "side": "SELL", "hash": "caff49bcff8582e1fd498e9a996e34c5420d0dbf", "best_bid": "0.04", "best_ask": "0.05"}], "timestamp": "1769384697738", "event_type": "price_change"}}
{"_local_timestamp": "2026-01-25T23:44:58.332925+00:00", "data": {"market": "0x60ecb823bb667a51ccf9ffcb1cab2c48899cd16410687874887dab9df9f4e1bf", "price_changes": [{"asset_id": "6727724717965804812582437828646736972344757795103515098740782022977766715112", "price": "0.23", "size": "744", "side": "BUY", "hash": "3f07ee8a89529a34aac6d0cb4255135b86685dad", "best_bid": "0.95", "best_ask": "0.96"}, {"asset_id": "19998490588165385691634000405206222117826113177925708815328988090662305366225", "price": "0.77", "size": "744", "side": "SELL", "hash": "28d1587c59b52d2c2ccc8b74b6dd8349159d7348", "best_bid": "0.04", "best_ask": "0.05"}], "timestamp": "1769384698219", "event_type": "price_change"}}
{"_local_timestamp": "2026-01-25T23:45:36.942341+00:00", "data": {"market": "0x60ecb823bb667a51ccf9ffcb1cab2c48899cd16410687874887dab9df9f4e1bf", "price_changes": [{"asset_id": "6727724717965804812582437828646736972344757795103515098740782022977766715112", "price": "0.25", "size": "1680", "side": "BUY", "hash": "bc4cceb0c2b4a99fa37d4a918ba8362305e21475", "best_bid": "0.95", "best_ask": "0.96"}, {"asset_id": "19998490588165385691634000405206222117826113177925708815328988090662305366225", "price": "0.75", "size": "1680", "side": "SELL", "hash": "98d3c0c0d0dc866d0091d6d91d7d05a63f927609", "best_bid": "0.04", "best_ask": "0.05"}], "timestamp": "1769384736866", "event_type": "price_change"}}
{"_local_timestamp": "2026-01-25T23:45:38.930664+00:00", "data": {"market": "0x60ecb823bb667a51ccf9ffcb1cab2c48899cd16410687874887dab9df9f4e1bf", "price_changes": [{"asset_id": "6727724717965804812582437828646736972344757795103515098740782022977766715112", "price": "0.24", "size": "116.66", "side": "BUY", "hash": "ec8d648d0b4359d01fb2b73dc88368a076613ef4", "best_bid": "0.95", "best_ask": "0.96"}, {"asset_id": "19998490588165385691634000405206222117826113177925708815328988090662305366225", "price": "0.76", "size": "116.66", "side": "SELL", "hash": "3a1208cc980a5441e6cf7ba1fd810d889a744695", "best_bid": "0.04", "best_ask": "0.05"}], "timestamp": "1769384738821", "event_type": "price_change"}}
{"_local_timestamp": "2026-01-25T23:45:39.173658+00:00", "data": {"market": "0x60ecb823bb667a51ccf9ffcb1cab2c48899cd16410687874887dab9df9f4e1bf", "price_changes": [{"asset_id": "6727724717965804812582437828646736972344757795103515098740782022977766715112", "price": "0.23", "size": "844", "side": "BUY", "hash": "9f51666c0ee3aa307c0a61183b5549c7d71e098b", "best_bid": "0.95", "best_ask": "0.96"}, {"asset_id": "19998490588165385691634000405206222117826113177925708815328988090662305366225", "price": "0.77", "size": "844", "side": "SELL", "hash": "80d6566e2bfe9d52fce5dc72ac06cb46245ded32", "best_bid": "0.04", "best_ask": "0.05"}], "timestamp": "1769384739076", "event_type": "price_change"}}
{"_local_timestamp": "2026-01-25T23:46:10.537509+00:00", "data": {"market": "0x60ecb823bb667a51ccf9ffcb1cab2c48899cd16410687874887dab9df9f4e1bf", "price_changes": [{"asset_id": "6727724717965804812582437828646736972344757795103515098740782022977766715112", "price": "0.25", "size": "0", "side": "BUY", "hash": "b0f7319cdef9e5d17bfd58d035aed290242f34fb", "best_bid": "0.95", "best_ask": "0.96"}, {"asset_id": "19998490588165385691634000405206222117826113177925708815328988090662305366225", "price": "0.75", "size": "0", "side": "SELL", "hash": "bf828f5b7b2f14ab4195fcb272da9bcfd0c6424c", "best_bid": "0.04", "best_ask": "0.05"}], "timestamp": "1769384770458", "event_type": "price_change"}}
{"_local_timestamp": "2026-01-25T23:46:17.451919+00:00", "data": {"market": "0x60ecb823bb667a51ccf9ffcb1cab2c48899cd16410687874887dab9df9f4e1bf", "price_changes": [{"asset_id": "6727724717965804812582437828646736972344757795103515098740782022977766715112", "price": "0.23", "size": "744", "side": "BUY", "hash": "5386ba1b5e2cbc6574bdfd4be8ca7524eded701e", "best_bid": "0.95", "best_ask": "0.96"}, {"asset_id": "19998490588165385691634000405206222117826113177925708815328988090662305366225", "price": "0.77", "size": "744", "side": "SELL", "hash": "10fc86fd47c968478f8c91072b9324171ac01b97", "best_bid": "0.04", "best_ask": "0.05"}], "timestamp": "1769384777374", "event_type": "price_change"}}
{"_local_timestamp": "2026-01-25T23:46:17.701225+00:00", "data": {"market": "0x60ecb823bb667a51ccf9ffcb1cab2c48899cd16410687874887dab9df9f4e1bf", "price_changes": [{"asset_id": "6727724717965804812582437828646736972344757795103515098740782022977766715112", "price": "0.25", "size": "100", "side": "BUY", "hash": "9c35fafc78a44505b751adf6371a1f2a214ee6bc", "best_bid": "0.95", "best_ask": "0.96"}, {"asset_id": "19998490588165385691634000405206222117826113177925708815328988090662305366225", "price": "0.75", "size": "100", "side": "SELL", "hash": "535cb23814f797360a9899f5313d948de951950a", "best_bid": "0.04", "best_ask": "0.05"}], "timestamp": "1769384777629", "event_type": "price_change"}}
{"_local_timestamp": "2026-01-25T23:46:50.816831+00:00", "data": {"market": "0x60ecb823bb667a51ccf9ffcb1cab2c48899cd16410687874887dab9df9f4e1bf", "price_changes": [{"asset_id": "6727724717965804812582437828646736972344757795103515098740782022977766715112", "price": "0.26", "size": "0", "side": "BUY", "hash": "afa326328b462152e0fb6b8f1d487f033bb35325", "best_bid": "0.95", "best_ask": "0.96"}, {"asset_id": "19998490588165385691634000405206222117826113177925708815328988090662305366225", "price": "0.74", "size": "0", "side": "SELL", "hash": "6748e91018cd10e1846576e0c194f7e040d16fcd", "best_bid": "0.04", "best_ask": "0.05"}], "timestamp": "1769384810651", "event_type": "price_change"}}
{"_local_timestamp": "2026-01-25T23:46:51.537733+00:00", "data": {"market": "0x60ecb823bb667a51ccf9ffcb1cab2c48899cd16410687874887dab9df9f4e1bf", "price_changes": [{"asset_id": "6727724717965804812582437828646736972344757795103515098740782022977766715112", "price": "0.24", "size": "216.66", "side": "BUY", "hash": "948774f7a6b2b7acd44d08540b68bcbacc4cd5e6", "best_bid": "0.95", "best_ask": "0.96"}, {"asset_id": "19998490588165385691634000405206222117826113177925708815328988090662305366225", "price": "0.76", "size": "216.66", "side": "SELL", "hash": "680d37eb92f250d152432e5ea4019862e670d419", "best_bid": "0.04", "best_ask": "0.05"}], "timestamp": "1769384811209", "event_type": "price_change"}}
{"_local_timestamp": "2026-01-25T23:46:54.324263+00:00", "data": {"market": "0x60ecb823bb667a51ccf9ffcb1cab2c48899cd16410687874887dab9df9f4e1bf", "price_changes": [{"asset_id": "19998490588165385691634000405206222117826113177925708815328988090662305366225", "price": "0.01", "size": "116838", "side": "BUY", "hash": "41dd0b4427a43bf234f3b634680d462900355e0f", "best_bid": "0.04", "best_ask": "0.05"}, {"asset_id": "6727724717965804812582437828646736972344757795103515098740782022977766715112", "price": "0.99", "size": "116838", "side": "SELL", "hash": "e7716ab036a18dc5fade22d63db686ab319a17a0", "best_bid": "0.95", "best_ask": "0.96"}], "timestamp": "1769384814262", "event_type": "price_change"}}
{"_local_timestamp": "2026-01-25T23:46:54.324964+00:00", "data": {"market": "0x60ecb823bb667a51ccf9ffcb1cab2c48899cd16410687874887dab9df9f4e1bf", "price_changes": [{"asset_id": "19998490588165385691634000405206222117826113177925708815328988090662305366225", "price": "0.02", "size": "5302.76", "side": "BUY", "hash": "41dd0b4427a43bf234f3b634680d462900355e0f", "best_bid": "0.04", "best_ask": "0.05"}, {"asset_id": "6727724717965804812582437828646736972344757795103515098740782022977766715112", "price": "0.98", "size": "5302.76", "side": "SELL", "hash": "e7716ab036a18dc5fade22d63db686ab319a17a0", "best_bid": "0.95", "best_ask": "0.96"}], "timestamp": "1769384814262", "event_type": "price_change"}}
{"_local_timestamp": "2026-01-25T23:46:55.197375+00:00", "data": {"market": "0x60ecb823bb667a51ccf9ffcb1cab2c48899cd16410687874887dab9df9f4e1bf", "price_changes": [{"asset_id": "19998490588165385691634000405206222117826113177925708815328988090662305366225", "price": "0.01", "size": "116847.51", "side": "BUY", "hash": "ca82efea0305d48380dff7f72efc2bab94e2bd71", "best_bid": "0.04", "best_ask": "0.05"}, {"asset_id": "6727724717965804812582437828646736972344757795103515098740782022977766715112", "price": "0.99", "size": "116847.51", "side": "SELL", "hash": "0c6c632d1eb238274f5d06ffad59e71ad71213df", "best_bid": "0.95", "best_ask": "0.96"}], "timestamp": "1769384815129", "event_type": "price_change"}}
{"_local_timestamp": "2026-01-25T23:46:55.199829+00:00", "data": {"market": "0x60ecb823bb667a51ccf9ffcb1cab2c48899cd16410687874887dab9df9f4e1bf", "price_changes": [{"asset_id": "19998490588165385691634000405206222117826113177925708815328988090662305366225", "price": "0.02", "size": "5348", "side": "BUY", "hash": "7061e60417f86b4291f4c6e5450be33ce82cc008", "best_bid": "0.04", "best_ask": "0.05"}, {"asset_id": "6727724717965804812582437828646736972344757795103515098740782022977766715112", "price": "0.98", "size": "5348", "side": "SELL", "hash": "29ef23438ae84d2003bd9749fd2a1006a298f251", "best_bid": "0.95", "best_ask": "0.96"}], "timestamp": "1769384815130", "event_type": "price_change"}}
{"_local_timestamp": "2026-01-25T23:46:58.965596+00:00", "data": {"market": "0x60ecb823bb667a51ccf9ffcb1cab2c48899cd16410687874887dab9df9f4e1bf", "price_changes": [{"asset_id": "6727724717965804812582437828646736972344757795103515098740782022977766715112", "price": "0.25", "size": "0", "side": "BUY", "hash": "522e703c929bc3ae4eb5360b2c6dad3016d1a95a", "best_bid": "0.95", "best_ask": "0.96"}, {"asset_id": "19998490588165385691634000405206222117826113177925708815328988090662305366225", "price": "0.75", "size": "0", "side": "SELL", "hash": "33ae392dbedd55f1d1dced24291b8793039c5b1a", "best_bid": "0.04", "best_ask": "0.05"}], "timestamp": "1769384818862", "event_type": "price_change"}}
{"_local_timestamp": "2026-01-25T23:46:59.295096+00:00", "data": {"market": "0x60ecb823bb667a51ccf9ffcb1cab2c48899cd16410687874887dab9df9f4e1bf", "price_changes": [{"asset_id": "6727724717965804812582437828646736972344757795103515098740782022977766715112", "price": "0.23", "size": "844", "side": "BUY", "hash": "aa5f8343ed031340e68ad41cdc8ab93e36629ec0", "best_bid": "0.95", "best_ask": "0.96"}, {"asset_id": "19998490588165385691634000405206222117826113177925708815328988090662305366225", "price": "0.77", "size": "844", "side": "SELL", "hash": "6255c04783e3c172b8c3eb1fa7f1d25dbf3be359", "best_bid": "0.04", "best_ask": "0.05"}], "timestamp": "1769384819163", "event_type": "price_change"}}
{"_local_timestamp": "2026-01-25T23:47:20.604037+00:00", "data": {"market": "0x60ecb823bb667a51ccf9ffcb1cab2c48899cd16410687874887dab9df9f4e1bf", "price_changes": [{"asset_id": "6727724717965804812582437828646736972344757795103515098740782022977766715112", "price": "0.24", "size": "1964.66", "side": "BUY", "hash": "49e4c919b9cdbaaab306d111ec015fd081505a40", "best_bid": "0.95", "best_ask": "0.96"}, {"asset_id": "19998490588165385691634000405206222117826113177925708815328988090662305366225", "price": "0.76", "size": "1964.66", "side": "SELL", "hash": "c8590c31ef7a709a07ffc61750084f4ff10dc099", "best_bid": "0.04", "best_ask": "0.05"}], "timestamp": "1769384840541", "event_type": "price_change"}}
{"_local_timestamp": "2026-01-25T23:47:55.541719+00:00", "data": {"market": "0x60ecb823bb667a51ccf9ffcb1cab2c48899cd16410687874887dab9df9f4e1bf", "price_changes": [{"asset_id": "6727724717965804812582437828646736972344757795103515098740782022977766715112", "price": "0.24", "size": "216.66", "side": "BUY", "hash": "1b4c9770aef86f3e5eb2df89e6c0b7426e460b94", "best_bid": "0.95", "best_ask": "0.96"}, {"asset_id": "19998490588165385691634000405206222117826113177925708815328988090662305366225", "price": "0.76", "size": "216.66", "side": "SELL", "hash": "edab6d395f6ba02ed30dae87f2f13a4398f78e0a", "best_bid": "0.04", "best_ask": "0.05"}], "timestamp": "1769384875412", "event_type": "price_change"}}
{"_local_timestamp": "2026-01-25T23:48:11.530464+00:00", "data": {"market": "0x60ecb823bb667a51ccf9ffcb1cab2c48899cd16410687874887dab9df9f4e1bf", "price_changes": [{"asset_id": "6727724717965804812582437828646736972344757795103515098740782022977766715112", "price": "0.23", "size": "744", "side": "BUY", "hash": "cc86d741444fcff7f795961d01a9e9aeda44dc22", "best_bid": "0.95", "best_ask": "0.96"}, {"asset_id": "19998490588165385691634000405206222117826113177925708815328988090662305366225", "price": "0.77", "size": "744", "side": "SELL", "hash": "d1460ecb7fedca76c92df9751464b25978ed50ff", "best_bid": "0.04", "best_ask": "0.05"}], "timestamp": "1769384891444", "event_type": "price_change"}}
{"_local_timestamp": "2026-01-25T23:48:11.769558+00:00", "data": {"market": "0x60ecb823bb667a51ccf9ffcb1cab2c48899cd16410687874887dab9df9f4e1bf", "price_changes": [{"asset_id": "6727724717965804812582437828646736972344757795103515098740782022977766715112", "price": "0.24", "size": "316.66", "side": "BUY", "hash": "572784e93a5e9c7cbb275607f6ad8ca8cdd03761", "best_bid": "0.95", "best_ask": "0.96"}, {"asset_id": "19998490588165385691634000405206222117826113177925708815328988090662305366225", "price": "0.76", "size": "316.66", "side": "SELL", "hash": "04bb33cb63b1c5050b2a639f16edc7eac7775041", "best_bid": "0.04", "best_ask": "0.05"}], "timestamp": "1769384891688", "event_type": "price_change"}}
{"_local_timestamp": "2026-01-25T23:48:48.700797+00:00", "data": {"market": "0x60ecb823bb667a51ccf9ffcb1cab2c48899cd16410687874887dab9df9f4e1bf", "price_changes": [{"asset_id": "6727724717965804812582437828646736972344757795103515098740782022977766715112", "price": "0.24", "size": "216.66", "side": "BUY", "hash": "cf0d8c8f27c4e13684a407488912a7d50cffe153", "best_bid": "0.95", "best_ask": "0.96"}, {"asset_id": "19998490588165385691634000405206222117826113177925708815328988090662305366225", "price": "0.76", "size": "216.66", "side": "SELL", "hash": "956c0b811515d7bf0cbc2e629ea37dfd56cc72c3", "best_bid": "0.04", "best_ask": "0.05"}], "timestamp": "1769384928593", "event_type": "price_change"}}
{"_local_timestamp": "2026-01-25T23:48:48.917767+00:00", "data": {"market": "0x60ecb823bb667a51ccf9ffcb1cab2c48899cd16410687874887dab9df9f4e1bf", "price_changes": [{"asset_id": "6727724717965804812582437828646736972344757795103515098740782022977766715112", "price": "0.23", "size": "844", "side": "BUY", "hash": "51ca9ec276ac456605f2fa90bcd07413d40da8c3", "best_bid": "0.95", "best_ask": "0.96"}, {"asset_id": "19998490588165385691634000405206222117826113177925708815328988090662305366225", "price": "0.77", "size": "844", "side": "SELL", "hash": "3dd7900dd0dd67efe5f98b6bb303495974a71c89", "best_bid": "0.04", "best_ask": "0.05"}], "timestamp": "1769384928840", "event_type": "price_change"}}
{"_local_timestamp": "2026-01-25T23:49:00.217325+00:00", "data": {"market": "0x60ecb823bb667a51ccf9ffcb1cab2c48899cd16410687874887dab9df9f4e1bf", "price_changes": [{"asset_id": "6727724717965804812582437828646736972344757795103515098740782022977766715112", "price": "0.25", "size": "1680", "side": "BUY", "hash": "1666c75d7b940545f836fb34cb683b4c032a6c69", "best_bid": "0.95", "best_ask": "0.96"}, {"asset_id": "19998490588165385691634000405206222117826113177925708815328988090662305366225", "price": "0.75", "size": "1680", "side": "SELL", "hash": "7f2742d70b9d1fd266376fc3e153a34379adbf1b", "best_bid": "0.04", "best_ask": "0.05"}], "timestamp": "1769384940150", "event_type": "price_change"}}
{"_local_timestamp": "2026-01-25T23:49:30.281763+00:00", "data": {"market": "0x60ecb823bb667a51ccf9ffcb1cab2c48899cd16410687874887dab9df9f4e1bf", "price_changes": [{"asset_id": "6727724717965804812582437828646736972344757795103515098740782022977766715112", "price": "0.24", "size": "116.66", "side": "BUY", "hash": "7c01b9430878cd7f20e11830e390a054c0abe3c0", "best_bid": "0.95", "best_ask": "0.96"}, {"asset_id": "19998490588165385691634000405206222117826113177925708815328988090662305366225", "price": "0.76", "size": "116.66", "side": "SELL", "hash": "18f831e2fcf714e2388ba92a980d8462d0b6e3b9", "best_bid": "0.04", "best_ask": "0.05"}], "timestamp": "1769384970051", "event_type": "price_change"}}
{"_local_timestamp": "2026-01-25T23:49:30.957087+00:00", "data": {"market": "0x60ecb823bb667a51ccf9ffcb1cab2c48899cd16410687874887dab9df9f4e1bf", "price_changes": [{"asset_id": "6727724717965804812582437828646736972344757795103515098740782022977766715112", "price": "0.23", "size": "944", "side": "BUY", "hash": "22f1b113c8bbf16c57a286b16314dc2b239615f3", "best_bid": "0.95", "best_ask": "0.96"}, {"asset_id": "19998490588165385691634000405206222117826113177925708815328988090662305366225", "price": "0.77", "size": "944", "side": "SELL", "hash": "4b33d2e4e9d8a5ea6eaa8412835e28b36116fdbb", "best_bid": "0.04", "best_ask": "0.05"}], "timestamp": "1769384970620", "event_type": "price_change"}}
{"_local_timestamp": "2026-01-25T23:49:41.850562+00:00", "data": {"market": "0x60ecb823bb667a51ccf9ffcb1cab2c48899cd16410687874887dab9df9f4e1bf", "price_changes": [{"asset_id": "6727724717965804812582437828646736972344757795103515098740782022977766715112", "price": "0.23", "size": "894", "side": "BUY", "hash": "185dabdd19d92e8654ea1ab251544768794ad910", "best_bid": "0.95", "best_ask": "0.96"}, {"asset_id": "19998490588165385691634000405206222117826113177925708815328988090662305366225", "price": "0.77", "size": "894", "side": "SELL", "hash": "b1d8b03031559051055f0466e786ced7366593e7", "best_bid": "0.04", "best_ask": "0.05"}], "timestamp": "1769384981713", "event_type": "price_change"}}
{"_local_timestamp": "2026-01-25T23:49:42.408424+00:00", "data": {"market": "0x60ecb823bb667a51ccf9ffcb1cab2c48899cd16410687874887dab9df9f4e1bf", "price_changes": [{"asset_id": "6727724717965804812582437828646736972344757795103515098740782022977766715112", "price": "0.24", "size": "166.66", "side": "BUY", "hash": "43afd8e64b8243f678cdfd70528b2ac776568c40", "best_bid": "0.95", "best_ask": "0.96"}, {"asset_id": "19998490588165385691634000405206222117826113177925708815328988090662305366225", "price": "0.76", "size": "166.66", "side": "SELL", "hash": "a5dac8c92775e2945ddfc215dbebc6694bdb122a", "best_bid": "0.04", "best_ask": "0.05"}], "timestamp": "1769384982230", "event_type": "price_change"}}
{"_local_timestamp": "2026-01-25T23:49:51.270388+00:00", "data": {"market": "0x60ecb823bb667a51ccf9ffcb1cab2c48899cd16410687874887dab9df9f4e1bf", "price_changes": [{"asset_id": "6727724717965804812582437828646736972344757795103515098740782022977766715112", "price": "0.25", "size": "0", "side": "BUY", "hash": "f77fbdaa11f5b38644b59ccfde3b1eb6c34156a6", "best_bid": "0.95", "best_ask": "0.96"}, {"asset_id": "19998490588165385691634000405206222117826113177925708815328988090662305366225", "price": "0.75", "size": "0", "side": "SELL", "hash": "adec64500d93736a7debe6f5b3eb34f600507c77", "best_bid": "0.04", "best_ask": "0.05"}], "timestamp": "1769384991053", "event_type": "price_change"}}
{"_local_timestamp": "2026-01-25T23:50:02.678798+00:00", "data": {"market": "0x60ecb823bb667a51ccf9ffcb1cab2c48899cd16410687874887dab9df9f4e1bf", "price_changes": [{"asset_id": "6727724717965804812582437828646736972344757795103515098740782022977766715112", "price": "0.23", "size": "200", "side": "BUY", "hash": "d7a596f8af5a2be8ae915e909dc9105f51ea35d0", "best_bid": "0.95", "best_ask": "0.96"}, {"asset_id": "19998490588165385691634000405206222117826113177925708815328988090662305366225", "price": "0.77", "size": "200", "side": "SELL", "hash": "ec7761db83c7db9db8e40a3b300be170d96e1198", "best_bid": "0.04", "best_ask": "0.05"}], "timestamp": "1769385002277", "event_type": "price_change"}}
{"_local_timestamp": "2026-01-25T23:50:02.921466+00:00", "data": {"market": "0x60ecb823bb667a51ccf9ffcb1cab2c48899cd16410687874887dab9df9f4e1bf", "price_changes": [{"asset_id": "6727724717965804812582437828646736972344757795103515098740782022977766715112", "price": "0.35", "size": "100", "side": "BUY", "hash": "53724071d5cd338fb1c207f9bfdca00b9a8e166c", "best_bid": "0.95", "best_ask": "0.96"}, {"asset_id": "19998490588165385691634000405206222117826113177925708815328988090662305366225", "price": "0.65", "size": "100", "side": "SELL", "hash": "d7bce07f08bcf24c3e55c17918617f3413c3b77c", "best_bid": "0.04", "best_ask": "0.05"}], "timestamp": "1769385002361", "event_type": "price_change"}}
{"_local_timestamp": "2026-01-25T23:50:05.129154+00:00", "data": {"market": "0x60ecb823bb667a51ccf9ffcb1cab2c48899cd16410687874887dab9df9f4e1bf", "price_changes": [{"asset_id": "19998490588165385691634000405206222117826113177925708815328988090662305366225", "price": "0.01", "size": "116347.51", "side": "BUY", "hash": "0eead0ef9a21e84f6ea8937839afc7490bd41281", "best_bid": "0.04", "best_ask": "0.05"}, {"asset_id": "6727724717965804812582437828646736972344757795103515098740782022977766715112", "price": "0.99", "size": "116347.51", "side": "SELL", "hash": "3f65ef435b4c64f5e156ad0e59a25624f7026519", "best_bid": "0.95", "best_ask": "0.96"}], "timestamp": "1769385005013", "event_type": "price_change"}}
{"_local_timestamp": "2026-01-25T23:50:05.544905+00:00", "data": {"market": "0x60ecb823bb667a51ccf9ffcb1cab2c48899cd16410687874887dab9df9f4e1bf", "price_changes": [{"asset_id": "6727724717965804812582437828646736972344757795103515098740782022977766715112", "price": "0.23", "size": "100", "side": "BUY", "hash": "fcd8fdb9447a980c5e7408fab259d782451f7150", "best_bid": "0.95", "best_ask": "0.96"}, {"asset_id": "19998490588165385691634000405206222117826113177925708815328988090662305366225", "price": "0.77", "size": "100", "side": "SELL", "hash": "76a57e5411e1dd832054e97d7d1bb713a523d455", "best_bid": "0.04", "best_ask": "0.05"}], "timestamp": "1769385005465", "event_type": "price_change"}}
{"_local_timestamp": "2026-01-25T23:50:05.808293+00:00", "data": {"market": "0x60ecb823bb667a51ccf9ffcb1cab2c48899cd16410687874887dab9df9f4e1bf", "price_changes": [{"asset_id": "6727724717965804812582437828646736972344757795103515098740782022977766715112", "price": "0.25", "size": "100", "side": "BUY", "hash": "dc7c9a444109a519618d45d1dca7d2d32b827ca8", "best_bid": "0.95", "best_ask": "0.96"}, {"asset_id": "19998490588165385691634000405206222117826113177925708815328988090662305366225", "price": "0.75", "size": "100", "side": "SELL", "hash": "0bbd46ba669a0240f2fdbe16781e6d2564bdc6da", "best_bid": "0.04", "best_ask": "0.05"}], "timestamp": "1769385005717", "event_type": "price_change"}}
{"_local_timestamp": "2026-01-25T23:50:19.364697+00:00", "data": {"market": "0x60ecb823bb667a51ccf9ffcb1cab2c48899cd16410687874887dab9df9f4e1bf", "price_changes": [{"asset_id": "19998490588165385691634000405206222117826113177925708815328988090662305366225", "price": "0.01", "size": "116338", "side": "BUY", "hash": "eb6994dad4f1c7b1cd37ff1f3fe7861e13d59753", "best_bid": "0.04", "best_ask": "0.05"}, {"asset_id": "6727724717965804812582437828646736972344757795103515098740782022977766715112", "price": "0.99", "size": "116338", "side": "SELL", "hash": "6f0ca66a3ea764b6dfd801c0a0d6123ed5c7bcaa", "best_bid": "0.95", "best_ask": "0.96"}], "timestamp": "1769385019270", "event_type": "price_change"}}
{"_local_timestamp": "2026-01-25T23:50:19.365444+00:00", "data": {"market": "0x60ecb823bb667a51ccf9ffcb1cab2c48899cd16410687874887dab9df9f4e1bf", "price_changes": [{"asset_id": "19998490588165385691634000405206222117826113177925708815328988090662305366225", "price": "0.02", "size": "5302.76", "side": "BUY", "hash": "eb6994dad4f1c7b1cd37ff1f3fe7861e13d59753", "best_bid": "0.04", "best_ask": "0.05"}, {"asset_id": "6727724717965804812582437828646736972344757795103515098740782022977766715112", "price": "0.98", "size": "5302.76", "side": "SELL", "hash": "6f0ca66a3ea764b6dfd801c0a0d6123ed5c7bcaa", "best_bid": "0.95", "best_ask": "0.96"}], "timestamp": "1769385019270", "event_type": "price_change"}}
{"_local_timestamp": "2026-01-25T23:50:19.677375+00:00", "data": {"market": "0x60ecb823bb667a51ccf9ffcb1cab2c48899cd16410687874887dab9df9f4e1bf", "price_changes": [{"asset_id": "19998490588165385691634000405206222117826113177925708815328988090662305366225", "price": "0.02", "size": "5348", "side": "BUY", "hash": "db7cc31824df062c755a4c8ca0b26ca127c38f73", "best_bid": "0.04", "best_ask": "0.05"}, {"asset_id": "6727724717965804812582437828646736972344757795103515098740782022977766715112", "price": "0.98", "size": "5348", "side": "SELL", "hash": "7b4bc540ba57abff67b0c9bbb8f324cc528f9cb8", "best_bid": "0.95", "best_ask": "0.96"}], "timestamp": "1769385019585", "event_type": "price_change"}}
{"_local_timestamp": "2026-01-25T23:50:19.678003+00:00", "data": {"market": "0x60ecb823bb667a51ccf9ffcb1cab2c48899cd16410687874887dab9df9f4e1bf", "price_changes": [{"asset_id": "19998490588165385691634000405206222117826113177925708815328988090662305366225", "price": "0.01", "size": "116347.51", "side": "BUY", "hash": "4da7a04a9f77c18b3d378e88791a242317f6dd14", "best_bid": "0.04", "best_ask": "0.05"}, {"asset_id": "6727724717965804812582437828646736972344757795103515098740782022977766715112", "price": "0.99", "size": "116347.51", "side": "SELL", "hash": "4827640ece6eb3e06c97ed2ae7f7d433c35c520e", "best_bid": "0.95", "best_ask": "0.96"}], "timestamp": "1769385019586", "event_type": "price_change"}}
{"_local_timestamp": "2026-01-25T23:50:46.377965+00:00", "data": {"market": "0x60ecb823bb667a51ccf9ffcb1cab2c48899cd16410687874887dab9df9f4e1bf", "price_changes": [{"asset_id": "6727724717965804812582437828646736972344757795103515098740782022977766715112", "price": "0.25", "size": "0", "side": "BUY", "hash": "4a4657d30efb288607ac0c3e7677339bf16bc779", "best_bid": "0.95", "best_ask": "0.96"}, {"asset_id": "19998490588165385691634000405206222117826113177925708815328988090662305366225", "price": "0.75", "size": "0", "side": "SELL", "hash": "03ac397df6e2c373b90af52ab8c773ae70777d49", "best_bid": "0.04", "best_ask": "0.05"}], "timestamp": "1769385046267", "event_type": "price_change"}}
{"_local_timestamp": "2026-01-25T23:50:46.785219+00:00", "data": {"market": "0x60ecb823bb667a51ccf9ffcb1cab2c48899cd16410687874887dab9df9f4e1bf", "price_changes": [{"asset_id": "6727724717965804812582437828646736972344757795103515098740782022977766715112", "price": "0.24", "size": "266.66", "side": "BUY", "hash": "474502bd1da91a2d06220ea2ef2029c48ac0d896", "best_bid": "0.95", "best_ask": "0.96"}, {"asset_id": "19998490588165385691634000405206222117826113177925708815328988090662305366225", "price": "0.76", "size": "266.66", "side": "SELL", "hash": "a63c6d3dda221593aef9ad4e8f342637a146224b", "best_bid": "0.04", "best_ask": "0.05"}], "timestamp": "1769385046639", "event_type": "price_change"}}
{"_local_timestamp": "2026-01-25T23:50:50.083457+00:00", "data": {"market": "0x60ecb823bb667a51ccf9ffcb1cab2c48899cd16410687874887dab9df9f4e1bf", "price_changes": [{"asset_id": "19998490588165385691634000405206222117826113177925708815328988090662305366225", "price": "0.01", "size": "110447.51", "side": "BUY", "hash": "09b7b6ad1dddf0ef06cbcbf2eed6e006fecb98a0", "best_bid": "0.04", "best_ask": "0.05"}, {"asset_id": "6727724717965804812582437828646736972344757795103515098740782022977766715112", "price": "0.99", "size": "110447.51", "side": "SELL", "hash": "834542add03f30c2064ee900709a99c0149a48af", "best_bid": "0.95", "best_ask": "0.96"}], "timestamp": "1769385050000", "event_type": "price_change"}}
{"_local_timestamp": "2026-01-25T23:50:55.830663+00:00", "data": {"market": "0x60ecb823bb667a51ccf9ffcb1cab2c48899cd16410687874887dab9df9f4e1bf", "price_changes": [{"asset_id": "6727724717965804812582437828646736972344757795103515098740782022977766715112", "price": "0.24", "size": "2014.66", "side": "BUY", "hash": "5fa8dc43163f0b7a38b741dc489560e20761176e", "best_bid": "0.95", "best_ask": "0.96"}, {"asset_id": "19998490588165385691634000405206222117826113177925708815328988090662305366225", "price": "0.76", "size": "2014.66", "side": "SELL", "hash": "c4659fee7c08ae203ea14a41643de73298d7eb53", "best_bid": "0.04", "best_ask": "0.05"}], "timestamp": "1769385055762", "event_type": "price_change"}}
{"_local_timestamp": "2026-01-25T23:51:13.183068+00:00", "data": {"market": "0x60ecb823bb667a51ccf9ffcb1cab2c48899cd16410687874887dab9df9f4e1bf", "price_changes": [{"asset_id": "6727724717965804812582437828646736972344757795103515098740782022977766715112", "price": "0.39", "size": "1538", "side": "BUY", "hash": "712f5d2b3df148c89f978422c97ea260e2e0dfed", "best_bid": "0.95", "best_ask": "0.96"}, {"asset_id": "19998490588165385691634000405206222117826113177925708815328988090662305366225", "price": "0.61", "size": "1538", "side": "SELL", "hash": "4da286305e6a6fe3d8e47b67619a2822fedc9104", "best_bid": "0.04", "best_ask": "0.05"}], "timestamp": "1769385073111", "event_type": "price_change"}}
