{"_local_timestamp": "2026-01-25T23:33:31.660140+00:00", "data": [{"market": "0x6f78c32173200382d096375527c65d41a789d77bd5a4548b98a9f7b0fce00715", "asset_id": "69246447231752827512933699840480180437823793525805489511863618486291912208735", "timestamp": "1769383923063", "hash": "fe1dd43af6f4160d1bac3f4ee049c3fbf463cd57", "bids": [{"price": "0.001", "size": "4424.07"}, {"price": "0.002", "size": "1255.04"}, {"price": "0.003", "size": "1000"}, {"price": "0.004", "size": "20.45"}, {"price": "0.01", "size": "5000"}, {"price": "0.02", "size": "2030.26"}, {"price": "0.021", "size": "14.47"}, {"price": "0.05", "size": "330"}, {"price": "0.051", "size": "39"}, {"price": "0.07", "size": "300"}, {"price": "0.1", "size": "860"}, {"price": "0.101", "size": "2970"}, {"price": "0.102", "size": "5.87"}, {"price": "0.15", "size": "551.66"}, {"price": "0.19", "size": "168.42"}, {"price": "0.196", "size": "1066"}, {"price": "0.24", "size": "116.66"}, {"price": "0.241", "size": "1742"}, {"price": "0.243", "size": "200"}, {"price": "0.244", "size": "100"}, {"price": "0.27", "size": "50"}, {"price": "0.29", "size": "89.65"}, {"price": "0.34", "size": "120.58"}, {"price": "0.39", "size": "51.28"}, {"price": "0.451", "size": "1390"}, {"price": "0.452", "size": "3609"}, {"price": "0.63", "size": "150"}, {"price": "0.81", "size": "200"}, {"price": "0.82", "size": "100"}, {"price": "0.88", "size": "200"}, {"price": "0.92", "size": "200"}, {"price": "0.93", "size": "289.85"}, {"price": "0.94", "size": "200"}, {"price": "0.943", "size": "118.58"}, {"price": "0.949", "size": "449.53"}, {"price": "0.95", "size": "150"}, {"price": "0.955", "size": "198.52"}, {"price": "0.956", "size": "33.33"}, {"price": "0.97", "size": "16.43"}, {"price": "0.971", "size": "11.36"}], "asks": [{"price": "0.999", "size": "56642.99"}, {"price": "0.998", "size": "25.94"}, {"price": "0.997", "size": "342.98"}, {"price": "0.996", "size": "307.08"}, {"price": "0.995", "size": "100.73"}, {"price": "0.994", "size": "9.32"}, {"price": "0.993", "size": "66"}, {"price": "0.992", "size": "40.22"}, {"price": "0.984", "size": "204.14"}, {"price": "0.983", "size": "5.9"}, {"price": "0.981", "size": "51.25"}, {"price": "0.979", "size": "6.99"}, {"price": "0.974", "size": "150.2"}, {"price": "0.973", "size": "546.44"}], "event_type": "book", "last_trade_price": "0.029"}, {"market": "0x6f78c32173200382d096375527c65d41a789d77bd5a4548b98a9f7b0fce00715", "asset_id": "94049353662994981741959410783261511597724385909066936434965918931114004265849", "timestamp": "1769383923063", "hash": "817a8c6353377c7db57995915f45cf39d82c1271", "bids": [{"price": "0.001", "size": "56642.99"}, {"price": "0.002", "size": "25.94"}, {"price": "0.003", "size": "342.98"}, {"price": "0.004", "size": "307.08"}, {"price": "0.005", "size": "100.73"}, {"price": "0.006", "size": "9.32"}, {"price": "0.007", "size": "66"}, {"price": "0.008", "size": "40.22"}, {"price": "0.016", "size": "204.14"}, {"price": "0.017", "size": "5.9"}, {"price": "0.019", "size": "51.25"}, {"price": "0.021", "size": "6.99"}, {"price": "0.026", "size": "150.2"}, {"price": "0.027", "size": "546.44"}], "asks": [{"price": "0.999", "size": "4424.07"}, {"price": "0.998", "size": "1255.04"}, {"price": "0.997", "size": "1000"}, {"price": "0.996", "size": "20.45"}, {"price": "0.99", "size": "5000"}, {"price": "0.98", "size": "2030.26"}, {"price": "0.979", "size": "14.47"}, {"price": "0.95", "size": "330"}, {"price": "0.949", "size": "39"}, {"price": "0.93", "size": "300"}, {"price": "0.9", "size": "860"}, {"price": "0.899", "size": "2970"}, {"price": "0.898", "size": "5.87"}, {"price": "0.85", "size": "551.66"}, {"price": "0.81", "size": "168.42"}, {"price": "0.804", "size": "1066"}, {"price": "0.76", "size": "116.66"}, {"price": "0.759", "size": "1742"}, {"price": "0.757", "size": "200"}, {"price": "0.756", "size": "100"}, {"price": "0.73", "size": "50"}, {"price": "0.71", "size": "89.65"}, {"price": "0.66", "size": "120.58"}, {"price": "0.61", "size": "51.28"}, {"price": "0.549", "size": "1390"}, {"price": "0.548", "size": "3609"}, {"price": "0.37", "size": "150"}, {"price": "0.19", "size": "200"}, {"price": "0.18", "size": "100"}, {"price": "0.12", "size": "200"}, {"price": "0.08", "size": "200"}, {"price": "0.07", "size": "289.85"}, {"price": "0.06", "size": "200"}, {"price": "0.057", "size": "118.58"}, {"price": "0.051", "size": "449.53"}, {"price": "0.05", "size": "150"}, {"price": "0.045", "size": "198.52"}, {"price": "0.044", "size": "33.33"}, {"price": "0.03", "size": "16.43"}, {"price": "0.029", "size": "11.36"}], "event_type": "book", "last_trade_price": "0.029"}]}
{"_local_timestamp": "2026-01-25T23:33:33.348462+00:00", "data": {"market": "0x6f78c32173200382d096375527c65d41a789d77bd5a4548b98a9f7b0fce00715", "price_changes": [{"asset_id": "69246447231752827512933699840480180437823793525805489511863618486291912208735", "price": "0.243", "size": "150", "side": "BUY", "hash": "6acd174a623d909484429100b093be46acd63e79", "best_bid": "0.971", "best_ask": "0.973"}, {"asset_id": "94049353662994981741959410783261511597724385909066936434965918931114004265849", "price": "0.757", "size": "150", "side": "SELL", "hash": "1d39a519507da60bbc6e970cb4fd61bcf3a7c4c5", "best_bid": "0.027", "best_ask": "0.029"}], "timestamp": "1769384013152", "event_type": "price_change"}}
{"_local_timestamp": "2026-01-25T23:33:33.704179+00:00", "data": {"market": "0x6f78c32173200382d096375527c65d41a789d77bd5a4548b98a9f7b0fce00715", "price_changes": [{"asset_id": "69246447231752827512933699840480180437823793525805489511863618486291912208735", "price": "0.24", "size": "166.66", "side": "BUY", "hash": "7fcc783a2f847e1ba8080821c55034933805c806", "best_bid": "0.971", "best_ask": "0.973"}, {"asset_id": "94049353662994981741959410783261511597724385909066936434965918931114004265849", "price": "0.76", "size": "166.66", "side": "SELL", "hash": "b48be3d32bb1711cb101a3ea805c58045fe6aceb", "best_bid": "0.027", "best_ask": "0.029"}], "timestamp": "1769384013540", "event_type": "price_change"}}
{"_local_timestamp": "2026-01-25T23:33:40.348449+00:00", "data": {"market": "0x6f78c32173200382d096375527c65d41a789d77bd5a4548b98a9f7b0fce00715", "price_changes": [{"asset_id": "69246447231752827512933699840480180437823793525805489511863618486291912208735", "price": "0.243", "size": "100", "side": "BUY", "hash": "9f136a56195b23779d59f6b289b914b064ac63d1", "best_bid": "0.971", "best_ask": "0.973"}, {"asset_id": "94049353662994981741959410783261511597724385909066936434965918931114004265849", "price": "0.757", "size": "100", "side": "SELL", "hash": "80420241b4788d6fe23ae95549940d94192312e0", "best_bid": "0.027", "best_ask": "0.029"}], "timestamp": "1769384020105", "event_type": "price_change"}}
{"_local_timestamp": "2026-01-25T23:33:40.676700+00:00", "data": {"market": "0x6f78c32173200382d096375527c65d41a789d77bd5a4548b98a9f7b0fce00715", "price_changes": [{"asset_id": "69246447231752827512933699840480180437823793525805489511863618486291912208735", "price": "0.241", "size": "1792", "side": "BUY", "hash": "9a2d72cd1e3a007bfccf2ac7fe49cdb857932d01", "best_bid": "0.971", "best_ask": "0.973"}, {"asset_id": "94049353662994981741959410783261511597724385909066936434965918931114004265849", "price": "0.759", "size": "1792", "side": "SELL", "hash": "876b80228dbb3df3a92f8e04bdfb3e35a9d2d8ed", "best_bid": "0.027", "best_ask": "0.029"}], "timestamp": "1769384020528", "event_type": "price_change"}}
{"_local_timestamp": "2026-01-25T23:34:27.881963+00:00", "data": {"market": "0x6f78c32173200382d096375527c65d41a789d77bd5a4548b98a9f7b0fce00715", "price_changes": [{"asset_id": "69246447231752827512933699840480180437823793525805489511863618486291912208735", "price": "0.451", "size": "1330", "side": "BUY", "hash": "f276ba94b07a0cffe500d01e455feac9f9a9a27a", "best_bid": "0.971", "best_ask": "0.973"}, {"asset_id": "94049353662994981741959410783261511597724385909066936434965918931114004265849", "price": "0.549", "size": "1330", "side": "SELL", "hash": "599431b9681557496ba0ba252cf33e222f08169b", "best_bid": "0.027", "best_ask": "0.029"}], "timestamp": "1769384067591", "event_type": "price_change"}}
{"_local_timestamp": "2026-01-25T23:34:27.886346+00:00", "data": {"market": "0x6f78c32173200382d096375527c65d41a789d77bd5a4548b98a9f7b0fce00715", "price_changes": [{"asset_id": "69246447231752827512933699840480180437823793525805489511863618486291912208735", "price": "0.243", "size": "0", "side": "BUY", "hash": "f276ba94b07a0cffe500d01e455feac9f9a9a27a", "best_bid": "0.971", "best_ask": "0.973"}, {"asset_id": "94049353662994981741959410783261511597724385909066936434965918931114004265849", "price": "0.757", "size": "0", "side": "SELL", "hash": "599431b9681557496ba0ba252cf33e222f08169b", "best_bid": "0.027", "best_ask": "0.029"}], "timestamp": "1769384067591", "event_type": "price_change"}}
{"_local_timestamp": "2026-01-25T23:34:28.203861+00:00", "data": {"market": "0x6f78c32173200382d096375527c65d41a789d77bd5a4548b98a9f7b0fce00715", "price_changes": [{"asset_id": "69246447231752827512933699840480180437823793525805489511863618486291912208735", "price": "0.241", "size": "1892", "side": "BUY", "hash": "48e2bf589734ca112f76d8ae966308e8c87a3775", "best_bid": "0.971", "best_ask": "0.973"}, {"asset_id": "94049353662994981741959410783261511597724385909066936434965918931114004265849", "price": "0.759", "size": "1892", "side": "SELL", "hash": "611e6e7e803e361bee9b42654f17fdd61ba745f4", "best_bid": "0.027", "best_ask": "0.029"}], "timestamp": "1769384068106", "event_type": "price_change"}}
{"_local_timestamp": "2026-01-25T23:34:28.471168+00:00", "data": {"market": "0x6f78c32173200382d096375527c65d41a789d77bd5a4548b98a9f7b0fce00715", "price_changes": [{"asset_id": "69246447231752827512933699840480180437823793525805489511863618486291912208735", "price": "0.452", "size": "3669", "side": "BUY", "hash": "99cc8ae858ba375acbe40ab08e6e245a66263d8d", "best_bid": "0.971", "best_ask": "0.973"}, {"asset_id": "94049353662994981741959410783261511597724385909066936434965918931114004265849", "price": "0.548", "size": "3669", "side": "SELL", "hash": "d8a02044fd96c8eadf6f960d65131257aac5fa45", "best_bid": "0.027", "best_ask": "0.029"}], "timestamp": "1769384068121", "event_type": "price_change"}}
{"_local_timestamp": "2026-01-25T23:35:48.261531+00:00", "data": {"market": "0x6f78c32173200382d096375527c65d41a789d77bd5a4548b98a9f7b0fce00715", "price_changes": [{"asset_id": "94049353662994981741959410783261511597724385909066936434965918931114004265849", "price": "0.017", "size": "0", "side": "BUY", "hash": "4b774db3f9ace54a64b23e03a71d326b7accbc6a", "best_bid": "0.027", "best_ask": "0.029"}, {"asset_id": "69246447231752827512933699840480180437823793525805489511863618486291912208735", "price": "0.983", "size": "0", "side": "SELL", "hash": "c845c88fbf6f7c4d439d0a9e6cbeb148f9dcd487", "best_bid": "0.971", "best_ask": "0.973"}], "timestamp": "1769384148191", "event_type": "price_change"}}
{"_local_timestamp": "2026-01-25T23:35:48.262477+00:00", "data": {"market": "0x6f78c32173200382d096375527c65d41a789d77bd5a4548b98a9f7b0fce00715", "price_changes": [{"asset_id": "94049353662994981741959410783261511597724385909066936434965918931114004265849", "price": "0.021", "size": "0", "side": "BUY", "hash": "4b774db3f9ace54a64b23e03a71d326b7accbc6a", "best_bid": "0.027", "best_ask": "0.029"}, {"asset_id": "69246447231752827512933699840480180437823793525805489511863618486291912208735", "price": "0.979", "size": "0", "side": "SELL", "hash": "c845c88fbf6f7c4d439d0a9e6cbeb148f9dcd487", "best_bid": "0.971", "best_ask": "0.973"}], "timestamp": "1769384148191", "event_type": "price_change"}}
{"_local_timestamp": "2026-01-25T23:35:49.529900+00:00", "data": {"market": "0x6f78c32173200382d096375527c65d41a789d77bd5a4548b98a9f7b0fce00715", "price_changes": [{"asset_id": "94049353662994981741959410783261511597724385909066936434965918931114004265849", "price": "0.02", "size": "12.36", "side": "BUY", "hash": "50f44664b40ae7ebd3a099c12ae1721e7542e62c", "best_bid": "0.027", "best_ask": "0.029"}, {"asset_id": "69246447231752827512933699840480180437823793525805489511863618486291912208735", "price": "0.98", "size": "12.36", "side": "SELL", "hash": "e78ffc68cc1822acc834bf0be8513ed9e8d04863", "best_bid": "0.971", "best_ask": "0.973"}], "timestamp": "1769384149458", "event_type": "price_change"}}
{"_local_timestamp": "2026-01-25T23:35:56.401838+00:00", "data": {"market": "0x6f78c32173200382d096375527c65d41a789d77bd5a4548b98a9f7b0fce00715", "price_changes": [{"asset_id": "69246447231752827512933699840480180437823793525805489511863618486291912208735", "price": "0.24", "size": "116.66", "side": "BUY", "hash": "16e257f7894398d902c96031764b603d8f77bde5", "best_bid": "0.971", "best_ask": "0.973"}, {"asset_id": "94049353662994981741959410783261511597724385909066936434965918931114004265849", "price": "0.76", "size": "116.66", "side": "SELL", "hash": "6f4388db884938c8ffde865d40e96487ec9a2fbc", "best_bid": "0.027", "best_ask": "0.029"}], "timestamp": "1769384156285", "event_type": "price_change"}}
{"_local_timestamp": "2026-01-25T23:35:56.859284+00:00", "data": {"market": "0x6f78c32173200382d096375527c65d41a789d77bd5a4548b98a9f7b0fce00715", "price_changes": [{"asset_id": "69246447231752827512933699840480180437823793525805489511863618486291912208735", "price": "0.241", "size": "1942", "side": "BUY", "hash": "88e6234948f992bdc58048f26a68a74b46d4ffc3", "best_bid": "0.971", "best_ask": "0.973"}, {"asset_id": "94049353662994981741959410783261511597724385909066936434965918931114004265849", "price": "0.759", "size": "1942", "side": "SELL", "hash": "38231f8951927904f7faf890dccb4f1e6a491701", "best_bid": "0.027", "best_ask": "0.029"}], "timestamp": "1769384156734", "event_type": "price_change"}}
{"_local_timestamp": "2026-01-25T23:37:35.323225+00:00", "data": {"market": "0x6f78c32173200382d096375527c65d41a789d77bd5a4548b98a9f7b0fce00715", "price_changes": [{"asset_id": "69246447231752827512933699840480180437823793525805489511863618486291912208735", "price": "0.241", "size": "200", "side": "BUY", "hash": "ff44e141bdeaf0548079cb64f5852b22e9d0d7ed", "best_bid": "0.971", "best_ask": "0.973"}, {"asset_id": "94049353662994981741959410783261511597724385909066936434965918931114004265849", "price": "0.759", "size": "200", "side": "SELL", "hash": "271c79a125bc0f108f90fe50042ab376fbbf1fe8", "best_bid": "0.027", "best_ask": "0.029"}], "timestamp": "1769384255124", "event_type": "price_change"}}
{"_local_timestamp": "2026-01-25T23:37:50.378351+00:00", "data": {"market": "0x6f78c32173200382d096375527c65d41a789d77bd5a4548b98a9f7b0fce00715", "price_changes": [{"asset_id": "94049353662994981741959410783261511597724385909066936434965918931114004265849", "price": "0.02", "size": "0", "side": "BUY", "hash": "3b53a50375445da8f7bd0698b8e05042c1ab78b8", "best_bid": "0.027", "best_ask": "0.029"}, {"asset_id": "69246447231752827512933699840480180437823793525805489511863618486291912208735", "price": "0.98", "size": "0", "side": "SELL", "hash": "d9f735db7dfc27c5c6d6dd1fb221fb0f05ad7d14", "best_bid": "0.971", "best_ask": "0.973"}], "timestamp": "1769384270297", "event_type": "price_change"}}
{"_local_timestamp": "2026-01-25T23:37:50.819492+00:00", "data": {"market": "0x6f78c32173200382d096375527c65d41a789d77bd5a4548b98a9f7b0fce00715", "price_changes": [{"asset_id": "94049353662994981741959410783261511597724385909066936434965918931114004265849", "price": "0.02", "size": "12.36", "side": "BUY", "hash": "9faa9c6d505e84c062c3f54a3171a2bd175d29f5", "best_bid": "0.027", "best_ask": "0.029"}, {"asset_id": "69246447231752827512933699840480180437823793525805489511863618486291912208735", "price": "0.98", "size": "12.36", "side": "SELL", "hash": "87b552fe004750335d183fa73718faeb2006561e", "best_bid": "0.971", "best_ask": "0.973"}], "timestamp": "1769384270738", "event_type": "price_change"}}
{"_local_timestamp": "2026-01-25T23:37:52.023575+00:00", "data": {"market": "0x6f78c32173200382d096375527c65d41a789d77bd5a4548b98a9f7b0fce00715", "price_changes": [{"asset_id": "94049353662994981741959410783261511597724385909066936434965918931114004265849", "price": "0.02", "size": "0", "side": "BUY", "hash": "8ad8b989ae24313cdebf3c5eb00745c1cf47a7be", "best_bid": "0.027", "best_ask": "0.029"}, {"asset_id": "69246447231752827512933699840480180437823793525805489511863618486291912208735", "price": "0.98", "size": "0", "side": "SELL", "hash": "a4f053a1b221143498061f8752a0e09a4b51e62c", "best_bid": "0.971", "best_ask": "0.973"}], "timestamp": "1769384271951", "event_type": "price_change"}}
{"_local_timestamp": "2026-01-25T23:37:52.850299+00:00", "data": {"market": "0x6f78c32173200382d096375527c65d41a789d77bd5a4548b98a9f7b0fce00715", "price_changes": [{"asset_id": "94049353662994981741959410783261511597724385909066936434965918931114004265849", "price": "0.017", "size": "5.9", "side": "BUY", "hash": "fa13d4b9ed461aff0a3b5c5927573a65e6d08978", "best_bid": "0.027", "best_ask": "0.029"}, {"asset_id": "69246447231752827512933699840480180437823793525805489511863618486291912208735", "price": "0.983", "size": "5.9", "side": "SELL", "hash": "92dffd620a0abbd47ad8129754c7934747d074a8", "best_bid": "0.971", "best_ask": "0.973"}], "timestamp": "1769384272744", "event_type": "price_change"}}
{"_local_timestamp": "2026-01-25T23:37:52.850699+00:00", "data": {"market": "0x6f78c32173200382d096375527c65d41a789d77bd5a4548b98a9f7b0fce00715", "price_changes": [{"asset_id": "94049353662994981741959410783261511597724385909066936434965918931114004265849", "price": "0.021", "size": "6.99", "side": "BUY", "hash": "9f5393223ba51f2b7e8df3ccb1fb998796618061", "best_bid": "0.027", "best_ask": "0.029"}, {"asset_id": "69246447231752827512933699840480180437823793525805489511863618486291912208735", "price": "0.979", "size": "6.99", "side": "SELL", "hash": "19efcac2eddf926cb17f8253512cdf3b3ed490de", "best_bid": "0.971", "best_ask": "0.973"}], "timestamp": "1769384272745", "event_type": "price_change"}}
{"_local_timestamp": "2026-01-25T23:38:18.175980+00:00", "data": {"market": "0x6f78c32173200382d096375527c65d41a789d77bd5a4548b98a9f7b0fce00715", "price_changes": [{"asset_id": "69246447231752827512933699840480180437823793525805489511863618486291912208735", "price": "0.197", "size": "2130", "side": "BUY", "hash": "1ad0c4633a63a6ee3a79180482cd1b8c2aa8ea32", "best_bid": "0.971", "best_ask": "0.973"}, {"asset_id": "94049353662994981741959410783261511597724385909066936434965918931114004265849", "price": "0.803", "size": "2130", "side": "SELL", "hash": "f67f9648df07a4964208e5a6231b08aaf32de6fa", "best_bid": "0.027", "best_ask": "0.029"}], "timestamp": "1769384298072", "event_type": "price_change"}}
{"_local_timestamp": "2026-01-25T23:39:20.428632+00:00", "data": {"market": "0x6f78c32173200382d096375527c65d41a789d77bd5a4548b98a9f7b0fce00715", "price_changes": [{"asset_id": "69246447231752827512933699840480180437823793525805489511863618486291912208735", "price": "0.197", "size": "0", "side": "BUY", "hash": "723a4cd4de14358e8811429bf9180a2b2f0be8fb", "best_bid": "0.971", "best_ask": "0.973"}, {"asset_id": "94049353662994981741959410783261511597724385909066936434965918931114004265849", "price": "0.803", "size": "0", "side": "SELL", "hash": "5bf147f51c138be83e5a92316705e50b4d7c3240", "best_bid": "0.027", "best_ask": "0.029"}], "timestamp": "1769384360332", "event_type": "price_change"}}
{"_local_timestamp": "2026-01-25T23:39:57.913827+00:00", "data": {"market": "0x6f78c32173200382d096375527c65d41a789d77bd5a4548b98a9f7b0fce00715", "price_changes": [{"asset_id": "69246447231752827512933699840480180437823793525805489511863618486291912208735", "price": "0.242", "size": "1734", "side": "BUY", "hash": "e3b67a07f0ba9c61604623316954f77dc6c4cbfe", "best_bid": "0.971", "best_ask": "0.973"}, {"asset_id": "94049353662994981741959410783261511597724385909066936434965918931114004265849", "price": "0.758", "size": "1734", "side": "SELL", "hash": "b0538db3f79805f3985651071dae4b97adf82738", "best_bid": "0.027", "best_ask": "0.029"}], "timestamp": "1769384397847", "event_type": "price_change"}}
