{"_local_timestamp": "2026-01-25T23:33:24.868551+00:00", "data": [{"market": "0xb5fb3fd4dbc7fdc70e3666ed4193e3171ecc257dcd43e01b36dbd4efa01d777e", "asset_id": "57073863691050176858693353000197608096498121614576538982509295418934497382921", "timestamp": "1769384004569", "hash": "a4db46bb06f48011d9e0894c04e4a6954d3aaed6", "bids": [{"price": "0.01", "size": "500"}, {"price": "0.02", "size": "665.09"}, {"price": "0.03", "size": "286.65"}, {"price": "0.04", "size": "103.48"}, {"price": "0.05", "size": "86.11"}, {"price": "0.06", "size": "114.28"}], "asks": [{"price": "0.99", "size": "7509.71"}, {"price": "0.98", "size": "6300"}, {"price": "0.97", "size": "10.14"}, {"price": "0.96", "size": "1250"}, {"price": "0.95", "size": "30"}, {"price": "0.94", "size": "33"}, {"price": "0.93", "size": "1600"}, {"price": "0.91", "size": "400"}, {"price": "0.9", "size": "500"}, {"price": "0.89", "size": "255.43"}, {"price": "0.86", "size": "792.85"}, {"price": "0.82", "size": "182.77"}, {"price": "0.8", "size": "1050"}, {"price": "0.77", "size": "371.73"}, {"price": "0.76", "size": "8"}, {"price": "0.72", "size": "192.85"}, {"price": "0.68", "size": "75"}, {"price": "0.63", "size": "179.05"}, {"price": "0.4", "size": "100"}, {"price": "0.35", "size": "500"}, {"price": "0.3", "size": "500"}, {"price": "0.29", "size": "500"}, {"price": "0.25", "size": "1200"}, {"price": "0.24", "size": "600"}, {"price": "0.23", "size": "405"}, {"price": "0.22", "size": "5"}, {"price": "0.2", "size": "300"}, {"price": "0.19", "size": "298.46"}, {"price": "0.15", "size": "68.46"}, {"price": "0.11", "size": "222.1"}, {"price": "0.1", "size": "188.39"}], "event_type": "book", "last_trade_price": ""}, {"market": "0xb5fb3fd4dbc7fdc70e3666ed4193e3171ecc257dcd43e01b36dbd4efa01d777e", "asset_id": "8786566038915392046446786086504563210301842572125705765733243466035321540191", "timestamp": "1769384004569", "hash": "dfa63e07849ac1fa5665cea95a286d158fba90af", "bids": [{"price": "0.01", "size": "7509.71"}, {"price": "0.02", "size": "6300"}, {"price": "0.03", "size": "10.14"}, {"price": "0.04", "size": "1250"}, {"price": "0.05", "size": "30"}, {"price": "0.06", "size": "33"}, {"price": "0.07", "size": "1600"}, {"price": "0.09", "size": "400"}, {"price": "0.1", "size": "500"}, {"price": "0.11", "size": "255.43"}, {"price": "0.14", "size": "792.85"}, {"price": "0.18", "size": "182.77"}, {"price": "0.2", "size": "1050"}, {"price": "0.23", "size": "371.73"}, {"price": "0.24", "size": "8"}, {"price": "0.28", "size": "192.85"}, {"price": "0.32", "size": "75"}, {"price": "0.37", "size": "179.05"}, {"price": "0.6", "size": "100"}, {"price": "0.65", "size": "500"}, {"price": "0.7", "size": "500"}, {"price": "0.71", "size": "500"}, {"price": "0.75", "size": "1200"}, {"price": "0.76", "size": "600"}, {"price": "0.77", "size": "405"}, {"price": "0.78", "size": "5"}, {"price": "0.8", "size": "300"}, {"price": "0.81", "size": "298.46"}, {"price": "0.85", "size": "68.46"}, {"price": "0.89", "size": "222.1"}, {"price": "0.9", "size": "188.39"}], "asks": [{"price": "0.99", "size": "500"}, {"price": "0.98", "size": "665.09"}, {"price": "0.97", "size": "286.65"}, {"price": "0.96", "size": "103.48"}, {"price": "0.95", "size": "86.11"}, {"price": "0.94", "size": "114.28"}], "event_type": "book", "last_trade_price": ""}]}
{"_local_timestamp": "2026-01-25T23:33:26.497024+00:00", "data": {"market": "0xb5fb3fd4dbc7fdc70e3666ed4193e3171ecc257dcd43e01b36dbd4efa01d777e", "price_changes": [{"asset_id": "8786566038915392046446786086504563210301842572125705765733243466035321540191", "price": "0.18", "size": "177.77", "side": "BUY", "hash": "4397bd4ee943542ca5d3873b2c141a02231c45c4", "best_bid": "0.9", "best_ask": "0.94"}, {"asset_id": "57073863691050176858693353000197608096498121614576538982509295418934497382921", "price": "0.82", "size": "177.77", "side": "SELL", "hash": "b094847a7a7da671fdc23d27edd932dc0c66f911", "best_bid": "0.06", "best_ask": "0.1"}], "timestamp": "1769384006424", "event_type": "price_change"}}
{"_local_timestamp": "2026-01-25T23:33:26.817185+00:00", "data": {"market": "0xb5fb3fd4dbc7fdc70e3666ed4193e3171ecc257dcd43e01b36dbd4efa01d777e", "price_changes": [{"asset_id": "8786566038915392046446786086504563210301842572125705765733243466035321540191", "price": "0.18", "size": "182.77", "side": "BUY", "hash": "c9b4c7fcf02b468f2c55f514489c7c2f529d996e", "best_bid": "0.9", "best_ask": "0.94"}, {"asset_id": "57073863691050176858693353000197608096498121614576538982509295418934497382921", "price": "0.82", "size": "182.77", "side": "SELL", "hash": "b1e7cb70f9f75a35c6cc73a21c88ec09d2c370e1", "best_bid": "0.06", "best_ask": "0.1"}], "timestamp": "1769384006744", "event_type": "price_change"}}
{"_local_timestamp": "2026-01-25T23:33:28.811869+00:00", "data": {"market": "0xb5fb3fd4dbc7fdc70e3666ed4193e3171ecc257dcd43e01b36dbd4efa01d777e", "price_changes": [{"asset_id": "8786566038915392046446786086504563210301842572125705765733243466035321540191", "price": "0.18", "size": "177.77", "side": "BUY", "hash": "a48a4590f9f4a90d44c831d147909966c4d67a65", "best_bid": "0.9", "best_ask": "0.94"}, {"asset_id": "57073863691050176858693353000197608096498121614576538982509295418934497382921", "price": "0.82", "size": "177.77", "side": "SELL", "hash": "ca43bddfefdb17f870bb731e0108ba568bd958ed", "best_bid": "0.06", "best_ask": "0.1"}], "timestamp": "1769384008739", "event_type": "price_change"}}
{"_local_timestamp": "2026-01-25T23:33:29.502769+00:00", "data": {"market": "0xb5fb3fd4dbc7fdc70e3666ed4193e3171ecc257dcd43e01b36dbd4efa01d777e", "price_changes": [{"asset_id": "8786566038915392046446786086504563210301842572125705765733243466035321540191", "price": "0.18", "size": "182.77", "side": "BUY", "hash": "323f3623812a2648e9e69ed731b4d01900404c60", "best_bid": "0.9", "best_ask": "0.94"}, {"asset_id": "57073863691050176858693353000197608096498121614576538982509295418934497382921", "price": "0.82", "size": "182.77", "side": "SELL", "hash": "306b50d5dc7bff48140c24e55ca9d221c9e4565b", "best_bid": "0.06", "best_ask": "0.1"}], "timestamp": "1769384009415", "event_type": "price_change"}}
{"_local_timestamp": "2026-01-25T23:33:30.825349+00:00", "data": {"market": "0xb5fb3fd4dbc7fdc70e3666ed4193e3171ecc257dcd43e01b36dbd4efa01d777e", "price_changes": [{"asset_id": "8786566038915392046446786086504563210301842572125705765733243466035321540191", "price": "0.18", "size": "177.77", "side": "BUY", "hash": "8707e5772fb79ef8ae92ffcb4e10452c3633f4e1", "best_bid": "0.9", "best_ask": "0.94"}, {"asset_id": "57073863691050176858693353000197608096498121614576538982509295418934497382921", "price": "0.82", "size": "177.77", "side": "SELL", "hash": "b5f0a07aa5b65ce4a75aca06d66d964b1c5b9fd9", "best_bid": "0.06", "best_ask": "0.1"}], "timestamp": "1769384010754", "event_type": "price_change"}}
{"_local_timestamp": "2026-01-25T23:33:31.279914+00:00", "data": {"market": "0xb5fb3fd4dbc7fdc70e3666ed4193e3171ecc257dcd43e01b36dbd4efa01d777e", "price_changes": [{"asset_id": "8786566038915392046446786086504563210301842572125705765733243466035321540191", "price": "0.18", "size": "182.77", "side": "BUY", "hash": "d12cc5dad6aabda8b46c9ebf62462fde49b19a6c", "best_bid": "0.9", "best_ask": "0.94"}, {"asset_id": "57073863691050176858693353000197608096498121614576538982509295418934497382921", "price": "0.82", "size": "182.77", "side": "SELL", "hash": "03cd993f98ef29d2ea7e9fb5ccf533a6df110a96", "best_bid": "0.06", "best_ask": "0.1"}], "timestamp": "1769384011206", "event_type": "price_change"}}
{"_local_timestamp": "2026-01-25T23:33:32.601322+00:00", "data": {"market": "0xb5fb3fd4dbc7fdc70e3666ed4193e3171ecc257dcd43e01b36dbd4efa01d777e", "price_changes": [{"asset_id": "8786566038915392046446786086504563210301842572125705765733243466035321540191", "price": "0.18", "size": "177.77", "side": "BUY", "hash": "a0652dbeadad6b7606d81c1a0c1d3716f1aafef8", "best_bid": "0.9", "best_ask": "0.94"}, {"asset_id": "57073863691050176858693353000197608096498121614576538982509295418934497382921", "price": "0.82", "size": "177.77", "side": "SELL", "hash": "ed72cbc4f89d944142c19ced96ac44c77945e41f", "best_bid": "0.06", "best_ask": "0.1"}], "timestamp": "1769384012526", "event_type": "price_change"}}
{"_local_timestamp": "2026-01-25T23:33:33.023888+00:00", "data": {"market": "0xb5fb3fd4dbc7fdc70e3666ed4193e3171ecc257dcd43e01b36dbd4efa01d777e", "price_changes": [{"asset_id": "8786566038915392046446786086504563210301842572125705765733243466035321540191", "price": "0.18", "size": "182.77", "side": "BUY", "hash": "cd7001c3e73cb6a3bc9682d173f26a464c9fcc0d", "best_bid": "0.9", "best_ask": "0.94"}, {"asset_id": "57073863691050176858693353000197608096498121614576538982509295418934497382921", "price": "0.82", "size": "182.77", "side": "SELL", "hash": "f3383ed13d128d16c6b5c5e734e8c19a2ee52ae3", "best_bid": "0.06", "best_ask": "0.1"}], "timestamp": "1769384012938", "event_type": "price_change"}}
{"_local_timestamp": "2026-01-25T23:33:35.366829+00:00", "data": {"market": "0xb5fb3fd4dbc7fdc70e3666ed4193e3171ecc257dcd43e01b36dbd4efa01d777e", "price_changes": [{"asset_id": "8786566038915392046446786086504563210301842572125705765733243466035321540191", "price": "0.18", "size": "177.77", "side": "BUY", "hash": "9861cb263b193e61e01a1ffb2d76a2fac1457c10", "best_bid": "0.9", "best_ask": "0.94"}, {"asset_id": "57073863691050176858693353000197608096498121614576538982509295418934497382921", "price": "0.82", "size": "177.77", "side": "SELL", "hash": "f0467e655c9867b9f8fc77efd8fd5dcf02c4fecd", "best_bid": "0.06", "best_ask": "0.1"}], "timestamp": "1769384015296", "event_type": "price_change"}}
{"_local_timestamp": "2026-01-25T23:33:35.771114+00:00", "data": {"market": "0xb5fb3fd4dbc7fdc70e3666ed4193e3171ecc257dcd43e01b36dbd4efa01d777e", "price_changes": [{"asset_id": "8786566038915392046446786086504563210301842572125705765733243466035321540191", "price": "0.18", "size": "182.77", "side": "BUY", "hash": "c56a153f35c4f855e2c6124a42c5e9f196977ea0", "best_bid": "0.9", "best_ask": "0.94"}, {"asset_id": "57073863691050176858693353000197608096498121614576538982509295418934497382921", "price": "0.82", "size": "182.77", "side": "SELL", "hash": "e3f846d7607b58517f744910ef5b0ef6f803513b", "best_bid": "0.06", "best_ask": "0.1"}], "timestamp": "1769384015698", "event_type": "price_change"}}
{"_local_timestamp": "2026-01-25T23:33:37.069298+00:00", "data": {"market": "0xb5fb3fd4dbc7fdc70e3666ed4193e3171ecc257dcd43e01b36dbd4efa01d777e", "price_changes": [{"asset_id": "8786566038915392046446786086504563210301842572125705765733243466035321540191", "price": "0.18", "size": "177.77", "side": "BUY", "hash": "1afadacb6efe1476457febd6939ac312eeed2d97", "best_bid": "0.9", "best_ask": "0.94"}, {"asset_id": "57073863691050176858693353000197608096498121614576538982509295418934497382921", "price": "0.82", "size": "177.77", "side": "SELL", "hash": "1e999bd80b85832c0abaa992903fd71a665b6431", "best_bid": "0.06", "best_ask": "0.1"}], "timestamp": "1769384016988", "event_type": "price_change"}}
{"_local_timestamp": "2026-01-25T23:33:37.495691+00:00", "data": {"market": "0xb5fb3fd4dbc7fdc70e3666ed4193e3171ecc257dcd43e01b36dbd4efa01d777e", "price_changes": [{"asset_id": "8786566038915392046446786086504563210301842572125705765733243466035321540191", "price": "0.18", "size": "182.77", "side": "BUY", "hash": "edf146747668258c654a057219d7e8e4d6d33a88", "best_bid": "0.9", "best_ask": "0.94"}, {"asset_id": "57073863691050176858693353000197608096498121614576538982509295418934497382921", "price": "0.82", "size": "182.77", "side": "SELL", "hash": "cdc4bd23fec8ca71df71a190a75a9bc09672c25c", "best_bid": "0.06", "best_ask": "0.1"}], "timestamp": "1769384017391", "event_type": "price_change"}}
{"_local_timestamp": "2026-01-25T23:33:38.751413+00:00", "data": {"market": "0xb5fb3fd4dbc7fdc70e3666ed4193e3171ecc257dcd43e01b36dbd4efa01d777e", "price_changes": [{"asset_id": "8786566038915392046446786086504563210301842572125705765733243466035321540191", "price": "0.18", "size": "177.77", "side": "BUY", "hash": "55085e6364fcc3c92a6474e7ef4753c48f800762", "best_bid": "0.9", "best_ask": "0.94"}, {"asset_id": "57073863691050176858693353000197608096498121614576538982509295418934497382921", "price": "0.82", "size": "177.77", "side": "SELL", "hash": "0f1d8473d380551f05794a255d8550adf6098ec1", "best_bid": "0.06", "best_ask": "0.1"}], "timestamp": "1769384018682", "event_type": "price_change"}}
{"_local_timestamp": "2026-01-25T23:33:39.035869+00:00", "data": {"market": "0xb5fb3fd4dbc7fdc70e3666ed4193e3171ecc257dcd43e01b36dbd4efa01d777e", "price_changes": [{"asset_id": "8786566038915392046446786086504563210301842572125705765733243466035321540191", "price": "0.18", "size": "182.77", "side": "BUY", "hash": "c01427d9fd24dbf5a2c6ff8f03fb1ae9c8b899cb", "best_bid": "0.9", "best_ask": "0.94"}, {"asset_id": "57073863691050176858693353000197608096498121614576538982509295418934497382921", "price": "0.82", "size": "182.77", "side": "SELL", "hash": "fa8237041018cc31c66036ef17dd779bb1cb9025", "best_bid": "0.06", "best_ask": "0.1"}], "timestamp": "1769384018964", "event_type": "price_change"}}
{"_local_timestamp": "2026-01-25T23:33:39.621998+00:00", "data": {"market": "0xb5fb3fd4dbc7fdc70e3666ed4193e3171ecc257dcd43e01b36dbd4efa01d777e", "price_changes": [{"asset_id": "8786566038915392046446786086504563210301842572125705765733243466035321540191", "price": "0.18", "size": "177.77", "side": "BUY", "hash": "6f66c461fe1852f5385a7e4eea09ea2b60c4ffe9", "best_bid": "0.9", "best_ask": "0.94"}, {"asset_id": "57073863691050176858693353000197608096498121614576538982509295418934497382921", "price": "0.82", "size": "177.77", "side": "SELL", "hash": "edbbbf3caf66090775af8c13e84549b291c59855", "best_bid": "0.06", "best_ask": "0.1"}], "timestamp": "1769384019544", "event_type": "price_change"}}
{"_local_timestamp": "2026-01-25T23:33:39.980560+00:00", "data": {"market": "0xb5fb3fd4dbc7fdc70e3666ed4193e3171ecc257dcd43e01b36dbd4efa01d777e", "price_changes": [{"asset_id": "8786566038915392046446786086504563210301842572125705765733243466035321540191", "price": "0.18", "size": "182.77", "side": "BUY", "hash": "f4a6ebfe2f93a77eb5c4e70635ff2b2d84c8f32c", "best_bid": "0.9", "best_ask": "0.94"}, {"asset_id": "57073863691050176858693353000197608096498121614576538982509295418934497382921", "price": "0.82", "size": "182.77", "side": "SELL", "hash": "e7b8dfc47b512db2ede0f458b5c81ab3616452e1", "best_bid": "0.06", "best_ask": "0.1"}], "timestamp": "1769384019908", "event_type": "price_change"}}
{"_local_timestamp": "2026-01-25T23:33:40.515554+00:00", "data": {"market": "0xb5fb3fd4dbc7fdc70e3666ed4193e3171ecc257dcd43e01b36dbd4efa01d777e", "price_changes": [{"asset_id": "8786566038915392046446786086504563210301842572125705765733243466035321540191", "price": "0.18", "size": "177.77", "side": "BUY", "hash": "89634517480027546533e19a804da90e7423eb19", "best_bid": "0.9", "best_ask": "0.94"}, {"asset_id": "57073863691050176858693353000197608096498121614576538982509295418934497382921", "price": "0.82", "size": "177.77", "side": "SELL", "hash": "503a2f2e0860c9fc6ebd9b519b24a36cbed68821", "best_bid": "0.06", "best_ask": "0.1"}], "timestamp": "1769384020440", "event_type": "price_change"}}
{"_local_timestamp": "2026-01-25T23:33:40.941794+00:00", "data": {"market": "0xb5fb3fd4dbc7fdc70e3666ed4193e3171ecc257dcd43e01b36dbd4efa01d777e", "price_changes": [{"asset_id": "8786566038915392046446786086504563210301842572125705765733243466035321540191", "price": "0.18", "size": "182.77", "side": "BUY", "hash": "fac9ac857ba7811e3077560699c3d850bab9e5cc", "best_bid": "0.9", "best_ask": "0.94"}, {"asset_id": "57073863691050176858693353000197608096498121614576538982509295418934497382921", "price": "0.82", "size": "182.77", "side": "SELL", "hash": "3b8e5253d16b9dd019babe032b20dc426dba710c", "best_bid": "0.06", "best_ask": "0.1"}], "timestamp": "1769384020823", "event_type": "price_change"}}
{"_local_timestamp": "2026-01-25T23:33:42.245171+00:00", "data": {"market": "0xb5fb3fd4dbc7fdc70e3666ed4193e3171ecc257dcd43e01b36dbd4efa01d777e", "price_changes": [{"asset_id": "8786566038915392046446786086504563210301842572125705765733243466035321540191", "price": "0.18", "size": "177.77", "side": "BUY", "hash": "8eb9cf0aa1edf5c220beb3f9535b5627c63e2c18", "best_bid": "0.9", "best_ask": "0.94"}, {"asset_id": "57073863691050176858693353000197608096498121614576538982509295418934497382921", "price": "0.82", "size": "177.77", "side": "SELL", "hash": "010cf926419e9a8b884c7561c430f8da4220152f", "best_bid": "0.06", "best_ask": "0.1"}], "timestamp": "1769384022169", "event_type": "price_change"}}
{"_local_timestamp": "2026-01-25T23:33:42.623810+00:00", "data": {"market": "0xb5fb3fd4dbc7fdc70e3666ed4193e3171ecc257dcd43e01b36dbd4efa01d777e", "price_changes": [{"asset_id": "8786566038915392046446786086504563210301842572125705765733243466035321540191", "price": "0.18", "size": "182.77", "side": "BUY", "hash": "cf9255d3549d2c57dc1b0677055e3c8d84bcd7a4", "best_bid": "0.9", "best_ask": "0.94"}, {"asset_id": "57073863691050176858693353000197608096498121614576538982509295418934497382921", "price": "0.82", "size": "182.77", "side": "SELL", "hash": "b09380090dcfa4ad6430f6ed0089cc5c0d107e7e", "best_bid": "0.06", "best_ask": "0.1"}], "timestamp": "1769384022553", "event_type": "price_change"}}
{"_local_timestamp": "2026-01-25T23:33:43.524893+00:00", "data": {"market": "0xb5fb3fd4dbc7fdc70e3666ed4193e3171ecc257dcd43e01b36dbd4efa01d777e", "price_changes": [{"asset_id": "8786566038915392046446786086504563210301842572125705765733243466035321540191", "price": "0.18", "size": "177.77", "side": "BUY", "hash": "1fde50e1543100ce03c47bbb0e2452e92f45cd7a", "best_bid": "0.9", "best_ask": "0.94"}, {"asset_id": "57073863691050176858693353000197608096498121614576538982509295418934497382921", "price": "0.82", "size": "177.77", "side": "SELL", "hash": "8b2743274d9034c6027ea16a797d78ca6a691b5b", "best_bid": "0.06", "best_ask": "0.1"}], "timestamp": "1769384023457", "event_type": "price_change"}}
{"_local_timestamp": "2026-01-25T23:33:43.889824+00:00", "data": {"market": "0xb5fb3fd4dbc7fdc70e3666ed4193e3171ecc257dcd43e01b36dbd4efa01d777e", "price_changes": [{"asset_id": "8786566038915392046446786086504563210301842572125705765733243466035321540191", "price": "0.18", "size": "182.77", "side": "BUY", "hash": "c642526f09002e1f8296a5528e8ac22cf46d7ace", "best_bid": "0.9", "best_ask": "0.94"}, {"asset_id": "57073863691050176858693353000197608096498121614576538982509295418934497382921", "price": "0.82", "size": "182.77", "side": "SELL", "hash": "fe36aefc4a46c406b43ce562560bd5baa932260e", "best_bid": "0.06", "best_ask": "0.1"}], "timestamp": "1769384023801", "event_type": "price_change"}}
{"_local_timestamp": "2026-01-25T23:33:45.235533+00:00", "data": {"market": "0xb5fb3fd4dbc7fdc70e3666ed4193e3171ecc257dcd43e01b36dbd4efa01d777e", "price_changes": [{"asset_id": "8786566038915392046446786086504563210301842572125705765733243466035321540191", "price": "0.18", "size": "177.77", "side": "BUY", "hash": "18f26920679cc5069623ee77ce53afb7094098bf", "best_bid": "0.9", "best_ask": "0.94"}, {"asset_id": "57073863691050176858693353000197608096498121614576538982509295418934497382921", "price": "0.82", "size": "177.77", "side": "SELL", "hash": "c20868e35eedbe04e04e83edaa244f236035aa01", "best_bid": "0.06", "best_ask": "0.1"}], "timestamp": "1769384025164", "event_type": "price_change"}}
{"_local_timestamp": "2026-01-25T23:33:45.490426+00:00", "data": {"market": "0xb5fb3fd4dbc7fdc70e3666ed4193e3171ecc257dcd43e01b36dbd4efa01d777e", "price_changes": [{"asset_id": "8786566038915392046446786086504563210301842572125705765733243466035321540191", "price": "0.18", "size": "182.77", "side": "BUY", "hash": "40fdcd618ff9591dc72df1571880f6b8237be8bc", "best_bid": "0.9", "best_ask": "0.94"}, {"asset_id": "57073863691050176858693353000197608096498121614576538982509295418934497382921", "price": "0.82", "size": "182.77", "side": "SELL", "hash": "41f9138edd8571f703f82cd8dfa6edb8e58de83a", "best_bid": "0.06", "best_ask": "0.1"}], "timestamp": "1769384025423", "event_type": "price_change"}}
{"_local_timestamp": "2026-01-25T23:33:45.574245+00:00", "data": {"market": "0xb5fb3fd4dbc7fdc70e3666ed4193e3171ecc257dcd43e01b36dbd4efa01d777e", "price_changes": [{"asset_id": "8786566038915392046446786086504563210301842572125705765733243466035321540191", "price": "0.18", "size": "187.77", "side": "BUY", "hash": "740f2740b94196eac9d0443291a4df0e065a09a6", "best_bid": "0.9", "best_ask": "0.94"}, {"asset_id": "57073863691050176858693353000197608096498121614576538982509295418934497382921", "price": "0.82", "size": "187.77", "side": "SELL", "hash": "73b1543a4195b1c9e4e6d3d0b89019b0d8f1231d", "best_bid": "0.06", "best_ask": "0.1"}], "timestamp": "1769384025504", "event_type": "price_change"}}
{"_local_timestamp": "2026-01-25T23:33:47.786675+00:00", "data": {"market": "0xb5fb3fd4dbc7fdc70e3666ed4193e3171ecc257dcd43e01b36dbd4efa01d777e", "price_changes": [{"asset_id": "8786566038915392046446786086504563210301842572125705765733243466035321540191", "price": "0.18", "size": "182.77", "side": "BUY", "hash": "de5945b2ff9379406a3e256d8fe69ef9355394c3", "best_bid": "0.9", "best_ask": "0.94"}, {"asset_id": "57073863691050176858693353000197608096498121614576538982509295418934497382921", "price": "0.82", "size": "182.77", "side": "SELL", "hash": "3e8e54a581e690e57943e5ed98d0b96f68b43d5c", "best_bid": "0.06", "best_ask": "0.1"}], "timestamp": "1769384027714", "event_type": "price_change"}}
{"_local_timestamp": "2026-01-25T23:33:48.709694+00:00", "data": {"market": "0xb5fb3fd4dbc7fdc70e3666ed4193e3171ecc257dcd43e01b36dbd4efa01d777e", "price_changes": [{"asset_id": "8786566038915392046446786086504563210301842572125705765733243466035321540191", "price": "0.18", "size": "177.77", "side": "BUY", "hash": "4a74b035e7dfa2ba91e713bde7dc09ae8908ab72", "best_bid": "0.9", "best_ask": "0.94"}, {"asset_id": "57073863691050176858693353000197608096498121614576538982509295418934497382921", "price": "0.82", "size": "177.77", "side": "SELL", "hash": "6732ac3b1a5aede610f5befa61cd9a47c59a70be", "best_bid": "0.06", "best_ask": "0.1"}], "timestamp": "1769384028639", "event_type": "price_change"}}
{"_local_timestamp": "2026-01-25T23:33:48.965967+00:00", "data": {"market": "0xb5fb3fd4dbc7fdc70e3666ed4193e3171ecc257dcd43e01b36dbd4efa01d777e", "price_changes": [{"asset_id": "8786566038915392046446786086504563210301842572125705765733243466035321540191", "price": "0.18", "size": "182.77", "side": "BUY", "hash": "4e3397cded5d2482b8c045e9f5a1609c5a3d076e", "best_bid": "0.9", "best_ask": "0.94"}, {"asset_id": "57073863691050176858693353000197608096498121614576538982509295418934497382921", "price": "0.82", "size": "182.77", "side": "SELL", "hash": "02f72ae3ea05363dc39140bfb4a9958328322989", "best_bid": "0.06", "best_ask": "0.1"}], "timestamp": "1769384028900", "event_type": "price_change"}}
{"_local_timestamp": "2026-01-25T23:34:01.540855+00:00", "data": {"market": "0xb5fb3fd4dbc7fdc70e3666ed4193e3171ecc257dcd43e01b36dbd4efa01d777e", "price_changes": [{"asset_id": "8786566038915392046446786086504563210301842572125705765733243466035321540191", "price": "0.18", "size": "177.77", "side": "BUY", "hash": "c3e5e0dea80571e31758f9eef2c8daf8042ff9e0", "best_bid": "0.9", "best_ask": "0.94"}, {"asset_id": "57073863691050176858693353000197608096498121614576538982509295418934497382921", "price": "0.82", "size": "177.77", "side": "SELL", "hash": "4822b68a11d12413d659a59859679bc5e6c9f55f", "best_bid": "0.06", "best_ask": "0.1"}], "timestamp": "1769384041451", "event_type": "price_change"}}
{"_local_timestamp": "2026-01-25T23:34:05.240574+00:00", "data": {"market": "0xb5fb3fd4dbc7fdc70e3666ed4193e3171ecc257dcd43e01b36dbd4efa01d777e", "price_changes": [{"asset_id": "8786566038915392046446786086504563210301842572125705765733243466035321540191", "price": "0.18", "size": "182.77", "side": "BUY", "hash": "d67523c469e2d8c5a52dab2db6d45be139b68cdc", "best_bid": "0.9", "best_ask": "0.94"}, {"asset_id": "57073863691050176858693353000197608096498121614576538982509295418934497382921", "price": "0.82", "size": "182.77", "side": "SELL", "hash": "b75b68f1798b12efea50846903b335df6e65e7d6", "best_bid": "0.06", "best_ask": "0.1"}], "timestamp": "1769384045107", "event_type": "price_change"}}
{"_local_timestamp": "2026-01-25T23:35:10.597135+00:00", "data": {"market": "0xb5fb3fd4dbc7fdc70e3666ed4193e3171ecc257dcd43e01b36dbd4efa01d777e", "price_changes": [{"asset_id": "8786566038915392046446786086504563210301842572125705765733243466035321540191", "price": "0.18", "size": "177.77", "side": "BUY", "hash": "9516ae5540c1f426fe566c44720094e148fece19", "best_bid": "0.9", "best_ask": "0.94"}, {"asset_id": "57073863691050176858693353000197608096498121614576538982509295418934497382921", "price": "0.82", "size": "177.77", "side": "SELL", "hash": "981b9a02ee678258d3b466bcbe43e7526ec87ca8", "best_bid": "0.06", "best_ask": "0.1"}], "timestamp": "1769384110512", "event_type": "price_change"}}
{"_local_timestamp": "2026-01-25T23:35:10.980067+00:00", "data": {"market": "0xb5fb3fd4dbc7fdc70e3666ed4193e3171ecc257dcd43e01b36dbd4efa01d777e", "price_changes": [{"asset_id": "8786566038915392046446786086504563210301842572125705765733243466035321540191", "price": "0.18", "size": "182.77", "side": "BUY", "hash": "e2159e50a6280e9c3a9bc2a758bd4032c3fc2783", "best_bid": "0.9", "best_ask": "0.94"}, {"asset_id": "57073863691050176858693353000197608096498121614576538982509295418934497382921", "price": "0.82", "size": "182.77", "side": "SELL", "hash": "f3996eba314a3414b69f1ed9b265d86f798a9e8a", "best_bid": "0.06", "best_ask": "0.1"}], "timestamp": "1769384110790", "event_type": "price_change"}}
{"_local_timestamp": "2026-01-25T23:35:13.335203+00:00", "data": {"market": "0xb5fb3fd4dbc7fdc70e3666ed4193e3171ecc257dcd43e01b36dbd4efa01d777e", "price_changes": [{"asset_id": "8786566038915392046446786086504563210301842572125705765733243466035321540191", "price": "0.18", "size": "177.77", "side": "BUY", "hash": "f0da256139d9b7ea82a62a92f94bceefc173522a", "best_bid": "0.9", "best_ask": "0.94"}, {"asset_id": "57073863691050176858693353000197608096498121614576538982509295418934497382921", "price": "0.82", "size": "177.77", "side": "SELL", "hash": "37e2151a8a6869dd9d466140c58eb85b13783290", "best_bid": "0.06", "best_ask": "0.1"}], "timestamp": "1769384113225", "event_type": "price_change"}}
{"_local_timestamp": "2026-01-25T23:35:13.760905+00:00", "data": {"market": "0xb5fb3fd4dbc7fdc70e3666ed4193e3171ecc257dcd43e01b36dbd4efa01d777e", "price_changes": [{"asset_id": "8786566038915392046446786086504563210301842572125705765733243466035321540191", "price": "0.18", "size": "182.77", "side": "BUY", "hash": "be20fa944ed64f56daa12fadc1fd5385401e834b", "best_bid": "0.9", "best_ask": "0.94"}, {"asset_id": "57073863691050176858693353000197608096498121614576538982509295418934497382921", "price": "0.82", "size": "182.77", "side": "SELL", "hash": "b54d310c1733cb9b7a9888dad5f17b4bc3849e57", "best_bid": "0.06", "best_ask": "0.1"}], "timestamp": "1769384113656", "event_type": "price_change"}}
{"_local_timestamp": "2026-01-25T23:35:16.061445+00:00", "data": {"market": "0xb5fb3fd4dbc7fdc70e3666ed4193e3171ecc257dcd43e01b36dbd4efa01d777e", "price_changes": [{"asset_id": "8786566038915392046446786086504563210301842572125705765733243466035321540191", "price": "0.18", "size": "177.77", "side": "BUY", "hash": "bcaaab04c7db816f395ff748c5b9a30c4280a974", "best_bid": "0.9", "best_ask": "0.94"}, {"asset_id": "57073863691050176858693353000197608096498121614576538982509295418934497382921", "price": "0.82", "size": "177.77", "side": "SELL", "hash": "9fb38893f5cdaee2d527a5170cd7550f6b481760", "best_bid": "0.06", "best_ask": "0.1"}], "timestamp": "1769384115991", "event_type": "price_change"}}
{"_local_timestamp": "2026-01-25T23:35:16.311024+00:00", "data": {"market": "0xb5fb3fd4dbc7fdc70e3666ed4193e3171ecc257dcd43e01b36dbd4efa01d777e", "price_changes": [{"asset_id": "8786566038915392046446786086504563210301842572125705765733243466035321540191", "price": "0.18", "size": "182.77", "side": "BUY", "hash": "7ae7f5f0b44a0fa60df8a3fd635ba8652e929cc0", "best_bid": "0.9", "best_ask": "0.94"}, {"asset_id": "57073863691050176858693353000197608096498121614576538982509295418934497382921", "price": "0.82", "size": "182.77", "side": "SELL", "hash": "846fdc60b74e13fdd155b368ea6d524aa7174345", "best_bid": "0.06", "best_ask": "0.1"}], "timestamp": "1769384116243", "event_type": "price_change"}}
{"_local_timestamp": "2026-01-25T23:35:18.668004+00:00", "data": {"market": "0xb5fb3fd4dbc7fdc70e3666ed4193e3171ecc257dcd43e01b36dbd4efa01d777e", "price_changes": [{"asset_id": "8786566038915392046446786086504563210301842572125705765733243466035321540191", "price": "0.18", "size": "177.77", "side": "BUY", "hash": "5f7415e7760c19cdb6d6442de400069599bfa003", "best_bid": "0.9", "best_ask": "0.94"}, {"asset_id": "57073863691050176858693353000197608096498121614576538982509295418934497382921", "price": "0.82", "size": "177.77", "side": "SELL", "hash": "dffef779e1ab87fe7f96058321edbb4750166c92", "best_bid": "0.06", "best_ask": "0.1"}], "timestamp": "1769384118545", "event_type": "price_change"}}
{"_local_timestamp": "2026-01-25T23:35:18.994293+00:00", "data": {"market": "0xb5fb3fd4dbc7fdc70e3666ed4193e3171ecc257dcd43e01b36dbd4efa01d777e", "price_changes": [{"asset_id": "8786566038915392046446786086504563210301842572125705765733243466035321540191", "price": "0.18", "size": "182.77", "side": "BUY", "hash": "913d91a1f227211cae3e7a38372262d49a7ca607", "best_bid": "0.9", "best_ask": "0.94"}, {"asset_id": "57073863691050176858693353000197608096498121614576538982509295418934497382921", "price": "0.82", "size": "182.77", "side": "SELL", "hash": "5a6dda8ac0a93d665fcae3d7c01e9c6a2581b054", "best_bid": "0.06", "best_ask": "0.1"}], "timestamp": "1769384118893", "event_type": "price_change"}}
{"_local_timestamp": "2026-01-25T23:35:20.186738+00:00", "data": {"market": "0xb5fb3fd4dbc7fdc70e3666ed4193e3171ecc257dcd43e01b36dbd4efa01d777e", "price_changes": [{"asset_id": "8786566038915392046446786086504563210301842572125705765733243466035321540191", "price": "0.18", "size": "177.77", "side": "BUY", "hash": "06c44ff6b550f8a8da7982a8e56952e7038806e7", "best_bid": "0.9", "best_ask": "0.94"}, {"asset_id": "57073863691050176858693353000197608096498121614576538982509295418934497382921", "price": "0.82", "size": "177.77", "side": "SELL", "hash": "02f885d4c65d5f27645b697c88df7e6688fcc2dd", "best_bid": "0.06", "best_ask": "0.1"}], "timestamp": "1769384120116", "event_type": "price_change"}}
{"_local_timestamp": "2026-01-25T23:35:20.648162+00:00", "data": {"market": "0xb5fb3fd4dbc7fdc70e3666ed4193e3171ecc257dcd43e01b36dbd4efa01d777e", "price_changes": [{"asset_id": "8786566038915392046446786086504563210301842572125705765733243466035321540191", "price": "0.18", "size": "182.77", "side": "BUY", "hash": "902de2a8f369800665b0382d81f93f99b70b4a83", "best_bid": "0.9", "best_ask": "0.94"}, {"asset_id": "57073863691050176858693353000197608096498121614576538982509295418934497382921", "price": "0.82", "size": "182.77", "side": "SELL", "hash": "bd1b87cecde609603566b48d1cc1ecdb00ae65a2", "best_bid": "0.06", "best_ask": "0.1"}], "timestamp": "1769384120578", "event_type": "price_change"}}
{"_local_timestamp": "2026-01-25T23:35:23.191757+00:00", "data": {"market": "0xb5fb3fd4dbc7fdc70e3666ed4193e3171ecc257dcd43e01b36dbd4efa01d777e", "price_changes": [{"asset_id": "8786566038915392046446786086504563210301842572125705765733243466035321540191", "price": "0.18", "size": "177.77", "side": "BUY", "hash": "356cee13940e7e4b088ddfada8a2e4f2e4199778", "best_bid": "0.9", "best_ask": "0.94"}, {"asset_id": "57073863691050176858693353000197608096498121614576538982509295418934497382921", "price": "0.82", "size": "177.77", "side": "SELL", "hash": "f68a4accdbfe57a519aaf07c93050e88749e5c4a", "best_bid": "0.06", "best_ask": "0.1"}], "timestamp": "1769384123122", "event_type": "price_change"}}
{"_local_timestamp": "2026-01-25T23:35:23.664796+00:00", "data": {"market": "0xb5fb3fd4dbc7fdc70e3666ed4193e3171ecc257dcd43e01b36dbd4efa01d777e", "price_changes": [{"asset_id": "8786566038915392046446786086504563210301842572125705765733243466035321540191", "price": "0.18", "size": "182.77", "side": "BUY", "hash": "3f5fc741527c4d1e819a547698e34ffda962f3c5", "best_bid": "0.9", "best_ask": "0.94"}, {"asset_id": "57073863691050176858693353000197608096498121614576538982509295418934497382921", "price": "0.82", "size": "182.77", "side": "SELL", "hash": "a938d00d48b12d2615fb3480fde25d56d2ee1c88", "best_bid": "0.06", "best_ask": "0.1"}], "timestamp": "1769384123537", "event_type": "price_change"}}
{"_local_timestamp": "2026-01-25T23:35:25.672676+00:00", "data": {"market": "0xb5fb3fd4dbc7fdc70e3666ed4193e3171ecc257dcd43e01b36dbd4efa01d777e", "price_changes": [{"asset_id": "8786566038915392046446786086504563210301842572125705765733243466035321540191", "price": "0.18", "size": "177.77", "side": "BUY", "hash": "3166e2def0479891211a55d886e23eb97db4d60a", "best_bid": "0.9", "best_ask": "0.94"}, {"asset_id": "57073863691050176858693353000197608096498121614576538982509295418934497382921", "price": "0.82", "size": "177.77", "side": "SELL", "hash": "95eb84e042a2a4eb85fab81bc77383f3095c58bc", "best_bid": "0.06", "best_ask": "0.1"}], "timestamp": "1769384125596", "event_type": "price_change"}}
{"_local_timestamp": "2026-01-25T23:35:26.022010+00:00", "data": {"market": "0xb5fb3fd4dbc7fdc70e3666ed4193e3171ecc257dcd43e01b36dbd4efa01d777e", "price_changes": [{"asset_id": "8786566038915392046446786086504563210301842572125705765733243466035321540191", "price": "0.18", "size": "182.77", "side": "BUY", "hash": "ff50286a104e7db848def5529d18f1045835c02d", "best_bid": "0.9", "best_ask": "0.94"}, {"asset_id": "57073863691050176858693353000197608096498121614576538982509295418934497382921", "price": "0.82", "size": "182.77", "side": "SELL", "hash": "17ddfce8aea30b917d0faa8fea56b45151b1248b", "best_bid": "0.06", "best_ask": "0.1"}], "timestamp": "1769384125951", "event_type": "price_change"}}
{"_local_timestamp": "2026-01-25T23:35:28.051861+00:00", "data": {"market": "0xb5fb3fd4dbc7fdc70e3666ed4193e3171ecc257dcd43e01b36dbd4efa01d777e", "price_changes": [{"asset_id": "8786566038915392046446786086504563210301842572125705765733243466035321540191", "price": "0.18", "size": "177.77", "side": "BUY", "hash": "3b3477ec86a87b4ee79b579125cf3f6e8f4d7e48", "best_bid": "0.9", "best_ask": "0.94"}, {"asset_id": "57073863691050176858693353000197608096498121614576538982509295418934497382921", "price": "0.82", "size": "177.77", "side": "SELL", "hash": "3c6a8867e2536fee0566805a37c28dc01fb1e5e3", "best_bid": "0.06", "best_ask": "0.1"}], "timestamp": "1769384127982", "event_type": "price_change"}}
{"_local_timestamp": "2026-01-25T23:35:28.508400+00:00", "data": {"market": "0xb5fb3fd4dbc7fdc70e3666ed4193e3171ecc257dcd43e01b36dbd4efa01d777e", "price_changes": [{"asset_id": "8786566038915392046446786086504563210301842572125705765733243466035321540191", "price": "0.18", "size": "182.77", "side": "BUY", "hash": "1efaf3998b9d49143ad5e4ad1bd80ef4215a7ae3", "best_bid": "0.9", "best_ask": "0.94"}, {"asset_id": "57073863691050176858693353000197608096498121614576538982509295418934497382921", "price": "0.82", "size": "182.77", "side": "SELL", "hash": "37789f2c27012045b41b2594b8ffb9e117eb8b7c", "best_bid": "0.06", "best_ask": "0.1"}], "timestamp": "1769384128439", "event_type": "price_change"}}
{"_local_timestamp": "2026-01-25T23:35:30.664863+00:00", "data": {"market": "0xb5fb3fd4dbc7fdc70e3666ed4193e3171ecc257dcd43e01b36dbd4efa01d777e", "price_changes": [{"asset_id": "8786566038915392046446786086504563210301842572125705765733243466035321540191", "price": "0.18", "size": "177.77", "side": "BUY", "hash": "2148d6429ae93bb02a2b48a0ce0f019680a773c0", "best_bid": "0.9", "best_ask": "0.94"}, {"asset_id": "57073863691050176858693353000197608096498121614576538982509295418934497382921", "price": "0.82", "size": "177.77", "side": "SELL", "hash": "3e99be163b0dbb42619aee575c223eac3c6b2cbb", "best_bid": "0.06", "best_ask": "0.1"}], "timestamp": "1769384130593", "event_type": "price_change"}}
{"_local_timestamp": "2026-01-25T23:35:31.003745+00:00", "data": {"market": "0xb5fb3fd4dbc7fdc70e3666ed4193e3171ecc257dcd43e01b36dbd4efa01d777e", "price_changes": [{"asset_id": "8786566038915392046446786086504563210301842572125705765733243466035321540191", "price": "0.18", "size": "182.77", "side": "BUY", "hash": "68f6470e08c7dc3943fc772961db920742fcb089", "best_bid": "0.9", "best_ask": "0.94"}, {"asset_id": "57073863691050176858693353000197608096498121614576538982509295418934497382921", "price": "0.82", "size": "182.77", "side": "SELL", "hash": "184d2ad4c99cd3b1d0ca75fbce0bb0336fc6e4ff", "best_bid": "0.06", "best_ask": "0.1"}], "timestamp": "1769384130924", "event_type": "price_change"}}
{"_local_timestamp": "2026-01-25T23:35:32.794413+00:00", "data": {"market": "0xb5fb3fd4dbc7fdc70e3666ed4193e3171ecc257dcd43e01b36dbd4efa01d777e", "price_changes": [{"asset_id": "8786566038915392046446786086504563210301842572125705765733243466035321540191", "price": "0.18", "size": "177.77", "side": "BUY", "hash": "cd045c5cdb2f3554cfa0c46fb7275010db9171e1", "best_bid": "0.9", "best_ask": "0.94"}, {"asset_id": "57073863691050176858693353000197608096498121614576538982509295418934497382921", "price": "0.82", "size": "177.77", "side": "SELL", "hash": "955476510a6111fdc09f45fcadd5483e11660269", "best_bid": "0.06", "best_ask": "0.1"}], "timestamp": "1769384132728", "event_type": "price_change"}}
{"_local_timestamp": "2026-01-25T23:35:33.148235+00:00", "data": {"market": "0xb5fb3fd4dbc7fdc70e3666ed4193e3171ecc257dcd43e01b36dbd4efa01d777e", "price_changes": [{"asset_id": "8786566038915392046446786086504563210301842572125705765733243466035321540191", "price": "0.18", "size": "182.77", "side": "BUY", "hash": "dac85ac80a493fd988500b24e806c4af4f4348e4", "best_bid": "0.9", "best_ask": "0.94"}, {"asset_id": "57073863691050176858693353000197608096498121614576538982509295418934497382921", "price": "0.82", "size": "182.77", "side": "SELL", "hash": "9a5d2747fdccceb57c2d6e0e2c35fecf4fba5d26", "best_bid": "0.06", "best_ask": "0.1"}], "timestamp": "1769384133050", "event_type": "price_change"}}
{"_local_timestamp": "2026-01-25T23:35:34.228125+00:00", "data": {"market": "0xb5fb3fd4dbc7fdc70e3666ed4193e3171ecc257dcd43e01b36dbd4efa01d777e", "price_changes": [{"asset_id": "8786566038915392046446786086504563210301842572125705765733243466035321540191", "price": "0.18", "size": "177.77", "side": "BUY", "hash": "1e5f5f3f4dd24af5d47a0597eae67479020904da", "best_bid": "0.9", "best_ask": "0.94"}, {"asset_id": "57073863691050176858693353000197608096498121614576538982509295418934497382921", "price": "0.82", "size": "177.77", "side": "SELL", "hash": "9ba063996b4a0a1d2e181ae1ed451c09182703f2", "best_bid": "0.06", "best_ask": "0.1"}], "timestamp": "1769384134158", "event_type": "price_change"}}
{"_local_timestamp": "2026-01-25T23:35:34.526850+00:00", "data": {"market": "0xb5fb3fd4dbc7fdc70e3666ed4193e3171ecc257dcd43e01b36dbd4efa01d777e", "price_changes": [{"asset_id": "8786566038915392046446786086504563210301842572125705765733243466035321540191", "price": "0.18", "size": "182.77", "side": "BUY", "hash": "01249688732138a74088178c59285894775cc1c7", "best_bid": "0.9", "best_ask": "0.94"}, {"asset_id": "57073863691050176858693353000197608096498121614576538982509295418934497382921", "price": "0.82", "size": "182.77", "side": "SELL", "hash": "4fa940671c0e4aa0e8ab558f2fbeddbea8f4a371", "best_bid": "0.06", "best_ask": "0.1"}], "timestamp": "1769384134450", "event_type": "price_change"}}
{"_local_timestamp": "2026-01-25T23:35:35.952762+00:00", "data": {"market": "0xb5fb3fd4dbc7fdc70e3666ed4193e3171ecc257dcd43e01b36dbd4efa01d777e", "price_changes": [{"asset_id": "8786566038915392046446786086504563210301842572125705765733243466035321540191", "price": "0.18", "size": "177.77", "side": "BUY", "hash": "9e15140bd7f0908ffecaa59de3087289e85b4e43", "best_bid": "0.9", "best_ask": "0.94"}, {"asset_id": "57073863691050176858693353000197608096498121614576538982509295418934497382921", "price": "0.82", "size": "177.77", "side": "SELL", "hash": "63fe53d4b12e2cbee826db96745befce8bed6acf", "best_bid": "0.06", "best_ask": "0.1"}], "timestamp": "1769384135873", "event_type": "price_change"}}
{"_local_timestamp": "2026-01-25T23:35:36.263290+00:00", "data": {"market": "0xb5fb3fd4dbc7fdc70e3666ed4193e3171ecc257dcd43e01b36dbd4efa01d777e", "price_changes": [{"asset_id": "8786566038915392046446786086504563210301842572125705765733243466035321540191", "price": "0.18", "size": "182.77", "side": "BUY", "hash": "bdbedeba65feac3cb5221b604691faedd329e264", "best_bid": "0.9", "best_ask": "0.94"}, {"asset_id": "57073863691050176858693353000197608096498121614576538982509295418934497382921", "price": "0.82", "size": "182.77", "side": "SELL", "hash": "29f9f18d57bb792585d0a30bd0343f17dd6e3e70", "best_bid": "0.06", "best_ask": "0.1"}], "timestamp": "1769384136188", "event_type": "price_change"}}
{"_local_timestamp": "2026-01-25T23:35:38.491140+00:00", "data": {"market": "0xb5fb3fd4dbc7fdc70e3666ed4193e3171ecc257dcd43e01b36dbd4efa01d777e", "price_changes": [{"asset_id": "8786566038915392046446786086504563210301842572125705765733243466035321540191", "price": "0.18", "size": "177.77", "side": "BUY", "hash": "80e990b5cc1b41d6f913b3619f0d76ee16e5448c", "best_bid": "0.9", "best_ask": "0.94"}, {"asset_id": "57073863691050176858693353000197608096498121614576538982509295418934497382921", "price": "0.82", "size": "177.77", "side": "SELL", "hash": "a621ebd2c14170de64b05b876a4b820188d27e42", "best_bid": "0.06", "best_ask": "0.1"}], "timestamp": "1769384138072", "event_type": "price_change"}}
{"_local_timestamp": "2026-01-25T23:35:39.027916+00:00", "data": {"market": "0xb5fb3fd4dbc7fdc70e3666ed4193e3171ecc257dcd43e01b36dbd4efa01d777e", "price_changes": [{"asset_id": "8786566038915392046446786086504563210301842572125705765733243466035321540191", "price": "0.18", "size": "182.77", "side": "BUY", "hash": "2501aa6c2862ead80dee4e6b100dd28339dba2af", "best_bid": "0.9", "best_ask": "0.94"}, {"asset_id": "57073863691050176858693353000197608096498121614576538982509295418934497382921", "price": "0.82", "size": "182.77", "side": "SELL", "hash": "fec6f8d164fdac25075df961b300339145ed068c", "best_bid": "0.06", "best_ask": "0.1"}], "timestamp": "1769384138571", "event_type": "price_change"}}
{"_local_timestamp": "2026-01-25T23:35:40.512359+00:00", "data": {"market": "0xb5fb3fd4dbc7fdc70e3666ed4193e3171ecc257dcd43e01b36dbd4efa01d777e", "price_changes": [{"asset_id": "8786566038915392046446786086504563210301842572125705765733243466035321540191", "price": "0.18", "size": "177.77", "side": "BUY", "hash": "47ec04e233094df8a1a7f790cd61457e36bce79a", "best_bid": "0.9", "best_ask": "0.94"}, {"asset_id": "57073863691050176858693353000197608096498121614576538982509295418934497382921", "price": "0.82", "size": "177.77", "side": "SELL", "hash": "9f3a7ffbe521658301c3eae1157bc9ba373d99ee", "best_bid": "0.06", "best_ask": "0.1"}], "timestamp": "1769384140443", "event_type": "price_change"}}
{"_local_timestamp": "2026-01-25T23:35:41.069913+00:00", "data": {"market": "0xb5fb3fd4dbc7fdc70e3666ed4193e3171ecc257dcd43e01b36dbd4efa01d777e", "price_changes": [{"asset_id": "8786566038915392046446786086504563210301842572125705765733243466035321540191", "price": "0.18", "size": "182.77", "side": "BUY", "hash": "a4cb290e0005b270abf6b8602316988cd3137caa", "best_bid": "0.9", "best_ask": "0.94"}, {"asset_id": "57073863691050176858693353000197608096498121614576538982509295418934497382921", "price": "0.82", "size": "182.77", "side": "SELL", "hash": "47ed58826d0ade241f4c0ff96d4d972a3e40a744", "best_bid": "0.06", "best_ask": "0.1"}], "timestamp": "1769384140989", "event_type": "price_change"}}
{"_local_timestamp": "2026-01-25T23:35:43.348282+00:00", "data": {"market": "0xb5fb3fd4dbc7fdc70e3666ed4193e3171ecc257dcd43e01b36dbd4efa01d777e", "price_changes": [{"asset_id": "8786566038915392046446786086504563210301842572125705765733243466035321540191", "price": "0.18", "size": "177.77", "side": "BUY", "hash": "9d292fd71f20f2e563eb9d0ba348b994f3b2a15d", "best_bid": "0.9", "best_ask": "0.94"}, {"asset_id": "57073863691050176858693353000197608096498121614576538982509295418934497382921", "price": "0.82", "size": "177.77", "side": "SELL", "hash": "3f2befe7acb2d84f972a8e98962db9066852451d", "best_bid": "0.06", "best_ask": "0.1"}], "timestamp": "1769384143273", "event_type": "price_change"}}
{"_local_timestamp": "2026-01-25T23:35:43.656940+00:00", "data": {"market": "0xb5fb3fd4dbc7fdc70e3666ed4193e3171ecc257dcd43e01b36dbd4efa01d777e", "price_changes": [{"asset_id": "8786566038915392046446786086504563210301842572125705765733243466035321540191", "price": "0.18", "size": "182.77", "side": "BUY", "hash": "1137ef1bdf3eddeab6e4268433723e6eecfb620a", "best_bid": "0.9", "best_ask": "0.94"}, {"asset_id": "57073863691050176858693353000197608096498121614576538982509295418934497382921", "price": "0.82", "size": "182.77", "side": "SELL", "hash": "76d3306b7185b4d44e1c45a30ae05d61f682ddc6", "best_bid": "0.06", "best_ask": "0.1"}], "timestamp": "1769384143586", "event_type": "price_change"}}
{"_local_timestamp": "2026-01-25T23:35:45.296014+00:00", "data": {"market": "0xb5fb3fd4dbc7fdc70e3666ed4193e3171ecc257dcd43e01b36dbd4efa01d777e", "price_changes": [{"asset_id": "8786566038915392046446786086504563210301842572125705765733243466035321540191", "price": "0.18", "size": "177.77", "side": "BUY", "hash": "393e74888b9d30e5c53e4b92abbaf46c8c2d4547", "best_bid": "0.9", "best_ask": "0.94"}, {"asset_id": "57073863691050176858693353000197608096498121614576538982509295418934497382921", "price": "0.82", "size": "177.77", "side": "SELL", "hash": "6b9524615def773b5cbfea3ea14a1fa5c6db2135", "best_bid": "0.06", "best_ask": "0.1"}], "timestamp": "1769384145227", "event_type": "price_change"}}
{"_local_timestamp": "2026-01-25T23:35:45.523296+00:00", "data": {"market": "0xb5fb3fd4dbc7fdc70e3666ed4193e3171ecc257dcd43e01b36dbd4efa01d777e", "price_changes": [{"asset_id": "8786566038915392046446786086504563210301842572125705765733243466035321540191", "price": "0.18", "size": "182.77", "side": "BUY", "hash": "6b2f660dbab6c7eba3ffebbffcf60f585b9b72bf", "best_bid": "0.9", "best_ask": "0.94"}, {"asset_id": "57073863691050176858693353000197608096498121614576538982509295418934497382921", "price": "0.82", "size": "182.77", "side": "SELL", "hash": "c8a561b6882b829b867e7c72c22a507e364935e0", "best_bid": "0.06", "best_ask": "0.1"}], "timestamp": "1769384145454", "event_type": "price_change"}}
{"_local_timestamp": "2026-01-25T23:35:47.432232+00:00", "data": {"market": "0xb5fb3fd4dbc7fdc70e3666ed4193e3171ecc257dcd43e01b36dbd4efa01d777e", "price_changes": [{"asset_id": "8786566038915392046446786086504563210301842572125705765733243466035321540191", "price": "0.18", "size": "177.77", "side": "BUY", "hash": "ec98ca0d96eec56905a105f311ddd7013b337309", "best_bid": "0.9", "best_ask": "0.94"}, {"asset_id": "57073863691050176858693353000197608096498121614576538982509295418934497382921", "price": "0.82", "size": "177.77", "side": "SELL", "hash": "c561442c2238188e8d0247484d2201188e0f7968", "best_bid": "0.06", "best_ask": "0.1"}], "timestamp": "1769384147366", "event_type": "price_change"}}
{"_local_timestamp": "2026-01-25T23:35:47.723230+00:00", "data": {"market": "0xb5fb3fd4dbc7fdc70e3666ed4193e3171ecc257dcd43e01b36dbd4efa01d777e", "price_changes": [{"asset_id": "8786566038915392046446786086504563210301842572125705765733243466035321540191", "price": "0.18", "size": "182.77", "side": "BUY", "hash": "1e912d04963eeafdb35a3bae27863fa283ad2994", "best_bid": "0.9", "best_ask": "0.94"}, {"asset_id": "57073863691050176858693353000197608096498121614576538982509295418934497382921", "price": "0.82", "size": "182.77", "side": "SELL", "hash": "41e880fe9c9a5eea8e7b62c3b466e4fa5c109b42", "best_bid": "0.06", "best_ask": "0.1"}], "timestamp": "1769384147651", "event_type": "price_change"}}
{"_local_timestamp": "2026-01-25T23:35:49.899380+00:00", "data": {"market": "0xb5fb3fd4dbc7fdc70e3666ed4193e3171ecc257dcd43e01b36dbd4efa01d777e", "price_changes": [{"asset_id": "8786566038915392046446786086504563210301842572125705765733243466035321540191", "price": "0.18", "size": "177.77", "side": "BUY", "hash": "b44ded3845ad3e05e52e803c5e7d1d916378c2ac", "best_bid": "0.9", "best_ask": "0.94"}, {"asset_id": "57073863691050176858693353000197608096498121614576538982509295418934497382921", "price": "0.82", "size": "177.77", "side": "SELL", "hash": "b75a587d1a92b341afb48fd9f9926d440d05f87e", "best_bid": "0.06", "best_ask": "0.1"}], "timestamp": "1769384149823", "event_type": "price_change"}}
{"_local_timestamp": "2026-01-25T23:35:50.292991+00:00", "data": {"market": "0xb5fb3fd4dbc7fdc70e3666ed4193e3171ecc257dcd43e01b36dbd4efa01d777e", "price_changes": [{"asset_id": "8786566038915392046446786086504563210301842572125705765733243466035321540191", "price": "0.18", "size": "182.77", "side": "BUY", "hash": "43b2ffddcd2b4e9052ee321d7a91dd936958ebf8", "best_bid": "0.9", "best_ask": "0.94"}, {"asset_id": "57073863691050176858693353000197608096498121614576538982509295418934497382921", "price": "0.82", "size": "182.77", "side": "SELL", "hash": "05bbf7d1912d995cc103fe9f2168992833306a78", "best_bid": "0.06", "best_ask": "0.1"}], "timestamp": "1769384150209", "event_type": "price_change"}}
{"_local_timestamp": "2026-01-25T23:35:51.347370+00:00", "data": {"market": "0xb5fb3fd4dbc7fdc70e3666ed4193e3171ecc257dcd43e01b36dbd4efa01d777e", "price_changes": [{"asset_id": "8786566038915392046446786086504563210301842572125705765733243466035321540191", "price": "0.18", "size": "177.77", "side": "BUY", "hash": "6477b3b6dfe19113061a0ec9c016c51602bac337", "best_bid": "0.9", "best_ask": "0.94"}, {"asset_id": "57073863691050176858693353000197608096498121614576538982509295418934497382921", "price": "0.82", "size": "177.77", "side": "SELL", "hash": "69274e573f34313c7f53b50c1be4952dfd880e0c", "best_bid": "0.06", "best_ask": "0.1"}], "timestamp": "1769384151279", "event_type": "price_change"}}
{"_local_timestamp": "2026-01-25T23:35:51.763665+00:00", "data": {"market": "0xb5fb3fd4dbc7fdc70e3666ed4193e3171ecc257dcd43e01b36dbd4efa01d777e", "price_changes": [{"asset_id": "8786566038915392046446786086504563210301842572125705765733243466035321540191", "price": "0.18", "size": "182.77", "side": "BUY", "hash": "016cedb5cb77d94362d574e586671246cc279105", "best_bid": "0.9", "best_ask": "0.94"}, {"asset_id": "57073863691050176858693353000197608096498121614576538982509295418934497382921", "price": "0.82", "size": "182.77", "side": "SELL", "hash": "889ed32261d94a76f1555d08c9b025a59a5cc46c", "best_bid": "0.06", "best_ask": "0.1"}], "timestamp": "1769384151677", "event_type": "price_change"}}
{"_local_timestamp": "2026-01-25T23:35:53.832071+00:00", "data": {"market": "0xb5fb3fd4dbc7fdc70e3666ed4193e3171ecc257dcd43e01b36dbd4efa01d777e", "price_changes": [{"asset_id": "8786566038915392046446786086504563210301842572125705765733243466035321540191", "price": "0.18", "size": "177.77", "side": "BUY", "hash": "cc37913d06d7d9921dddb651505264017f488cba", "best_bid": "0.9", "best_ask": "0.94"}, {"asset_id": "57073863691050176858693353000197608096498121614576538982509295418934497382921", "price": "0.82", "size": "177.77", "side": "SELL", "hash": "b4b8661ffaed16a8c7ee2516daf60e973399727b", "best_bid": "0.06", "best_ask": "0.1"}], "timestamp": "1769384153753", "event_type": "price_change"}}
{"_local_timestamp": "2026-01-25T23:35:54.309176+00:00", "data": {"market": "0xb5fb3fd4dbc7fdc70e3666ed4193e3171ecc257dcd43e01b36dbd4efa01d777e", "price_changes": [{"asset_id": "8786566038915392046446786086504563210301842572125705765733243466035321540191", "price": "0.18", "size": "182.77", "side": "BUY", "hash": "8e3f6a59112a6a51563d7444dec6c63411b1d426", "best_bid": "0.9", "best_ask": "0.94"}, {"asset_id": "57073863691050176858693353000197608096498121614576538982509295418934497382921", "price": "0.82", "size": "182.77", "side": "SELL", "hash": "6f46c64aad633d5b0fa5370b5da07625ec33149f", "best_bid": "0.06", "best_ask": "0.1"}], "timestamp": "1769384154242", "event_type": "price_change"}}
{"_local_timestamp": "2026-01-25T23:35:56.299326+00:00", "data": {"market": "0xb5fb3fd4dbc7fdc70e3666ed4193e3171ecc257dcd43e01b36dbd4efa01d777e", "price_changes": [{"asset_id": "8786566038915392046446786086504563210301842572125705765733243466035321540191", "price": "0.18", "size": "177.77", "side": "BUY", "hash": "0c95a94b096359057a23cfcf1924d38239d0fa8a", "best_bid": "0.9", "best_ask": "0.94"}, {"asset_id": "57073863691050176858693353000197608096498121614576538982509295418934497382921", "price": "0.82", "size": "177.77", "side": "SELL", "hash": "00d0ac7b534c20e4b9f478f633f60191a756dff0", "best_bid": "0.06", "best_ask": "0.1"}], "timestamp": "1769384156225", "event_type": "price_change"}}
{"_local_timestamp": "2026-01-25T23:35:56.711693+00:00", "data": {"market": "0xb5fb3fd4dbc7fdc70e3666ed4193e3171ecc257dcd43e01b36dbd4efa01d777e", "price_changes": [{"asset_id": "8786566038915392046446786086504563210301842572125705765733243466035321540191", "price": "0.18", "size": "182.77", "side": "BUY", "hash": "2160cc9ff00de8bda48b2784a116fd37d71a04f2", "best_bid": "0.9", "best_ask": "0.94"}, {"asset_id": "57073863691050176858693353000197608096498121614576538982509295418934497382921", "price": "0.82", "size": "182.77", "side": "SELL", "hash": "2afde74358f23b2e12782db09bbb2ba027da2bf1", "best_bid": "0.06", "best_ask": "0.1"}], "timestamp": "1769384156636", "event_type": "price_change"}}
{"_local_timestamp": "2026-01-25T23:35:57.909008+00:00", "data": {"market": "0xb5fb3fd4dbc7fdc70e3666ed4193e3171ecc257dcd43e01b36dbd4efa01d777e", "price_changes": [{"asset_id": "8786566038915392046446786086504563210301842572125705765733243466035321540191", "price": "0.18", "size": "177.77", "side": "BUY", "hash": "bda1f5a5eab8bd447810e1388876d6cc1a82ee89", "best_bid": "0.9", "best_ask": "0.94"}, {"asset_id": "57073863691050176858693353000197608096498121614576538982509295418934497382921", "price": "0.82", "size": "177.77", "side": "SELL", "hash": "162ad9ce99089537e6b428e35ae5bba52221e091", "best_bid": "0.06", "best_ask": "0.1"}], "timestamp": "1769384157805", "event_type": "price_change"}}
{"_local_timestamp": "2026-01-25T23:35:58.317252+00:00", "data": {"market": "0xb5fb3fd4dbc7fdc70e3666ed4193e3171ecc257dcd43e01b36dbd4efa01d777e", "price_changes": [{"asset_id": "8786566038915392046446786086504563210301842572125705765733243466035321540191", "price": "0.18", "size": "182.77", "side": "BUY", "hash": "e7eabd7c8dc1416fd37599ef9c06c1be0d306ca6", "best_bid": "0.9", "best_ask": "0.94"}, {"asset_id": "57073863691050176858693353000197608096498121614576538982509295418934497382921", "price": "0.82", "size": "182.77", "side": "SELL", "hash": "4c36f95b7637f0cb0e6822922f72e918af6e02c7", "best_bid": "0.06", "best_ask": "0.1"}], "timestamp": "1769384158241", "event_type": "price_change"}}
{"_local_timestamp": "2026-01-25T23:36:00.349048+00:00", "data": {"market": "0xb5fb3fd4dbc7fdc70e3666ed4193e3171ecc257dcd43e01b36dbd4efa01d777e", "price_changes": [{"asset_id": "8786566038915392046446786086504563210301842572125705765733243466035321540191", "price": "0.18", "size": "177.77", "side": "BUY", "hash": "6d2f67ac2106dbec2e6e6ea8b90e508c4782c3bd", "best_bid": "0.9", "best_ask": "0.94"}, {"asset_id": "57073863691050176858693353000197608096498121614576538982509295418934497382921", "price": "0.82", "size": "177.77", "side": "SELL", "hash": "c30601085de989f5f3eff7a5bc07f094b4828bff", "best_bid": "0.06", "best_ask": "0.1"}], "timestamp": "1769384160280", "event_type": "price_change"}}
{"_local_timestamp": "2026-01-25T23:36:00.694226+00:00", "data": {"market": "0xb5fb3fd4dbc7fdc70e3666ed4193e3171ecc257dcd43e01b36dbd4efa01d777e", "price_changes": [{"asset_id": "8786566038915392046446786086504563210301842572125705765733243466035321540191", "price": "0.18", "size": "182.77", "side": "BUY", "hash": "36548e0becf126f319646532aa8445fe000c6414", "best_bid": "0.9", "best_ask": "0.94"}, {"asset_id": "57073863691050176858693353000197608096498121614576538982509295418934497382921", "price": "0.82", "size": "182.77", "side": "SELL", "hash": "2a0b827c8089f0daed4b2c1cac396f8329e6c042", "best_bid": "0.06", "best_ask": "0.1"}], "timestamp": "1769384160624", "event_type": "price_change"}}
{"_local_timestamp": "2026-01-25T23:36:02.017575+00:00", "data": {"market": "0xb5fb3fd4dbc7fdc70e3666ed4193e3171ecc257dcd43e01b36dbd4efa01d777e", "price_changes": [{"asset_id": "8786566038915392046446786086504563210301842572125705765733243466035321540191", "price": "0.18", "size": "177.77", "side": "BUY", "hash": "20373e49fbb57dd55496ce79282ce25986543329", "best_bid": "0.9", "best_ask": "0.94"}, {"asset_id": "57073863691050176858693353000197608096498121614576538982509295418934497382921", "price": "0.82", "size": "177.77", "side": "SELL", "hash": "faa9f19e31ba694e1f06969de68832841e41a556", "best_bid": "0.06", "best_ask": "0.1"}], "timestamp": "1769384161945", "event_type": "price_change"}}
{"_local_timestamp": "2026-01-25T23:36:02.487369+00:00", "data": {"market": "0xb5fb3fd4dbc7fdc70e3666ed4193e3171ecc257dcd43e01b36dbd4efa01d777e", "price_changes": [{"asset_id": "8786566038915392046446786086504563210301842572125705765733243466035321540191", "price": "0.18", "size": "182.77", "side": "BUY", "hash": "6067fbc2103a40debf2192154c733b98a3ae07e3", "best_bid": "0.9", "best_ask": "0.94"}, {"asset_id": "57073863691050176858693353000197608096498121614576538982509295418934497382921", "price": "0.82", "size": "182.77", "side": "SELL", "hash": "2b70d3eee2fe41928114d8cbf4864fc07db82b1d", "best_bid": "0.06", "best_ask": "0.1"}], "timestamp": "1769384162416", "event_type": "price_change"}}
{"_local_timestamp": "2026-01-25T23:36:04.218332+00:00", "data": {"market": "0xb5fb3fd4dbc7fdc70e3666ed4193e3171ecc257dcd43e01b36dbd4efa01d777e", "price_changes": [{"asset_id": "8786566038915392046446786086504563210301842572125705765733243466035321540191", "price": "0.18", "size": "177.77", "side": "BUY", "hash": "48cf39a902bfac37b10c3839dc6ffe6b6ab74a4d", "best_bid": "0.9", "best_ask": "0.94"}, {"asset_id": "57073863691050176858693353000197608096498121614576538982509295418934497382921", "price": "0.82", "size": "177.77", "side": "SELL", "hash": "ef3697812556c8ed2e43352b5aff45b275e714af", "best_bid": "0.06", "best_ask": "0.1"}], "timestamp": "1769384164136", "event_type": "price_change"}}
{"_local_timestamp": "2026-01-25T23:36:04.456990+00:00", "data": {"market": "0xb5fb3fd4dbc7fdc70e3666ed4193e3171ecc257dcd43e01b36dbd4efa01d777e", "price_changes": [{"asset_id": "8786566038915392046446786086504563210301842572125705765733243466035321540191", "price": "0.18", "size": "182.77", "side": "BUY", "hash": "e64a1b28a56689ac63aaba3a2eec8f39bdd6d3de", "best_bid": "0.9", "best_ask": "0.94"}, {"asset_id": "57073863691050176858693353000197608096498121614576538982509295418934497382921", "price": "0.82", "size": "182.77", "side": "SELL", "hash": "e7ff439fbe6764c7830bb7bbbdfceb01adfd650e", "best_bid": "0.06", "best_ask": "0.1"}], "timestamp": "1769384164391", "event_type": "price_change"}}
{"_local_timestamp": "2026-01-25T23:36:06.367110+00:00", "data": {"market": "0xb5fb3fd4dbc7fdc70e3666ed4193e3171ecc257dcd43e01b36dbd4efa01d777e", "price_changes": [{"asset_id": "8786566038915392046446786086504563210301842572125705765733243466035321540191", "price": "0.18", "size": "177.77", "side": "BUY", "hash": "174d43fd6fc8029dd764c1cd83547e295d86765d", "best_bid": "0.9", "best_ask": "0.94"}, {"asset_id": "57073863691050176858693353000197608096498121614576538982509295418934497382921", "price": "0.82", "size": "177.77", "side": "SELL", "hash": "bd09b1366a1507bc1c785ec4e36c85706ee282db", "best_bid": "0.06", "best_ask": "0.1"}], "timestamp": "1769384166293", "event_type": "price_change"}}
{"_local_timestamp": "2026-01-25T23:36:06.801165+00:00", "data": {"market": "0xb5fb3fd4dbc7fdc70e3666ed4193e3171ecc257dcd43e01b36dbd4efa01d777e", "price_changes": [{"asset_id": "8786566038915392046446786086504563210301842572125705765733243466035321540191", "price": "0.18", "size": "182.77", "side": "BUY", "hash": "930d30011eb5e30f4debed22c07dbed0e0436e72", "best_bid": "0.9", "best_ask": "0.94"}, {"asset_id": "57073863691050176858693353000197608096498121614576538982509295418934497382921", "price": "0.82", "size": "182.77", "side": "SELL", "hash": "f497d673fa49cf9f141f46a047facf0a21c574f7", "best_bid": "0.06", "best_ask": "0.1"}], "timestamp": "1769384166732", "event_type": "price_change"}}
{"_local_timestamp": "2026-01-25T23:36:08.648971+00:00", "data": {"market": "0xb5fb3fd4dbc7fdc70e3666ed4193e3171ecc257dcd43e01b36dbd4efa01d777e", "price_changes": [{"asset_id": "8786566038915392046446786086504563210301842572125705765733243466035321540191", "price": "0.18", "size": "177.77", "side": "BUY", "hash": "5797cc0d9285d8627a7ac82df5a12f1c77052c68", "best_bid": "0.9", "best_ask": "0.94"}, {"asset_id": "57073863691050176858693353000197608096498121614576538982509295418934497382921", "price": "0.82", "size": "177.77", "side": "SELL", "hash": "de2652c0bddb6f25eeafcc14d0b31e72361d6204", "best_bid": "0.06", "best_ask": "0.1"}], "timestamp": "1769384168577", "event_type": "price_change"}}
{"_local_timestamp": "2026-01-25T23:36:08.938310+00:00", "data": {"market": "0xb5fb3fd4dbc7fdc70e3666ed4193e3171ecc257dcd43e01b36dbd4efa01d777e", "price_changes": [{"asset_id": "8786566038915392046446786086504563210301842572125705765733243466035321540191", "price": "0.18", "size": "182.77", "side": "BUY", "hash": "96c334255af6bb4b3c308002cd9a56fab7e15827", "best_bid": "0.9", "best_ask": "0.94"}, {"asset_id": "57073863691050176858693353000197608096498121614576538982509295418934497382921", "price": "0.82", "size": "182.77", "side": "SELL", "hash": "2f307ef3cf2dcd5a7f3db14bb8f666d0026d7d4f", "best_bid": "0.06", "best_ask": "0.1"}], "timestamp": "1769384168871", "event_type": "price_change"}}
{"_local_timestamp": "2026-01-25T23:36:10.795866+00:00", "data": {"market": "0xb5fb3fd4dbc7fdc70e3666ed4193e3171ecc257dcd43e01b36dbd4efa01d777e", "price_changes": [{"asset_id": "8786566038915392046446786086504563210301842572125705765733243466035321540191", "price": "0.18", "size": "177.77", "side": "BUY", "hash": "78d792c497d890576baa2ca2d297df584f4491e0", "best_bid": "0.9", "best_ask": "0.94"}, {"asset_id": "57073863691050176858693353000197608096498121614576538982509295418934497382921", "price": "0.82", "size": "177.77", "side": "SELL", "hash": "5e62856a8d898dc76a593eaf4dbba77dad61b4e9", "best_bid": "0.06", "best_ask": "0.1"}], "timestamp": "1769384170725", "event_type": "price_change"}}
{"_local_timestamp": "2026-01-25T23:36:11.134679+00:00", "data": {"market": "0xb5fb3fd4dbc7fdc70e3666ed4193e3171ecc257dcd43e01b36dbd4efa01d777e", "price_changes": [{"asset_id": "8786566038915392046446786086504563210301842572125705765733243466035321540191", "price": "0.18", "size": "182.77", "side": "BUY", "hash": "fe40de91f50579cce091ae6a425768a65f10c1fd", "best_bid": "0.9", "best_ask": "0.94"}, {"asset_id": "57073863691050176858693353000197608096498121614576538982509295418934497382921", "price": "0.82", "size": "182.77", "side": "SELL", "hash": "129f723a66e54ab5aa7b078c205651aac4197aa4", "best_bid": "0.06", "best_ask": "0.1"}], "timestamp": "1769384171058", "event_type": "price_change"}}
{"_local_timestamp": "2026-01-25T23:36:12.960441+00:00", "data": {"market": "0xb5fb3fd4dbc7fdc70e3666ed4193e3171ecc257dcd43e01b36dbd4efa01d777e", "price_changes": [{"asset_id": "8786566038915392046446786086504563210301842572125705765733243466035321540191", "price": "0.18", "size": "177.77", "side": "BUY", "hash": "921d2721cb51e74c937dd6bc006e2a91fb2e4298", "best_bid": "0.9", "best_ask": "0.94"}, {"asset_id": "57073863691050176858693353000197608096498121614576538982509295418934497382921", "price": "0.82", "size": "177.77", "side": "SELL", "hash": "58bb6667062970e1f5544b912d0f6f07b6a7a71a", "best_bid": "0.06", "best_ask": "0.1"}], "timestamp": "1769384172892", "event_type": "price_change"}}
{"_local_timestamp": "2026-01-25T23:36:13.298471+00:00", "data": {"market": "0xb5fb3fd4dbc7fdc70e3666ed4193e3171ecc257dcd43e01b36dbd4efa01d777e", "price_changes": [{"asset_id": "8786566038915392046446786086504563210301842572125705765733243466035321540191", "price": "0.18", "size": "182.77", "side": "BUY", "hash": "11a67c268a505d63760276e6857b6587e7babd8d", "best_bid": "0.9", "best_ask": "0.94"}, {"asset_id": "57073863691050176858693353000197608096498121614576538982509295418934497382921", "price": "0.82", "size": "182.77", "side": "SELL", "hash": "87e1350ad60376cf18894a1d4762f0d221ba8693", "best_bid": "0.06", "best_ask": "0.1"}], "timestamp": "1769384173230", "event_type": "price_change"}}
{"_local_timestamp": "2026-01-25T23:36:15.580619+00:00", "data": {"market": "0xb5fb3fd4dbc7fdc70e3666ed4193e3171ecc257dcd43e01b36dbd4efa01d777e", "price_changes": [{"asset_id": "8786566038915392046446786086504563210301842572125705765733243466035321540191", "price": "0.18", "size": "177.77", "side": "BUY", "hash": "9aa143ecd4508bce73977b70fba013474e3ba40c", "best_bid": "0.9", "best_ask": "0.94"}, {"asset_id": "57073863691050176858693353000197608096498121614576538982509295418934497382921", "price": "0.82", "size": "177.77", "side": "SELL", "hash": "1056b78efb45c0f39b44c37026c0b680d44c0b08", "best_bid": "0.06", "best_ask": "0.1"}], "timestamp": "1769384175501", "event_type": "price_change"}}
{"_local_timestamp": "2026-01-25T23:36:15.811609+00:00", "data": {"market": "0xb5fb3fd4dbc7fdc70e3666ed4193e3171ecc257dcd43e01b36dbd4efa01d777e", "price_changes": [{"asset_id": "8786566038915392046446786086504563210301842572125705765733243466035321540191", "price": "0.18", "size": "182.77", "side": "BUY", "hash": "1f4ddbd41361fcf95c31473a0b806c1fbaa297fd", "best_bid": "0.9", "best_ask": "0.94"}, {"asset_id": "57073863691050176858693353000197608096498121614576538982509295418934497382921", "price": "0.82", "size": "182.77", "side": "SELL", "hash": "983e0ec442c6cad68bf6555e55d01c3965718f5f", "best_bid": "0.06", "best_ask": "0.1"}], "timestamp": "1769384175731", "event_type": "price_change"}}
{"_local_timestamp": "2026-01-25T23:36:17.726499+00:00", "data": {"market": "0xb5fb3fd4dbc7fdc70e3666ed4193e3171ecc257dcd43e01b36dbd4efa01d777e", "price_changes": [{"asset_id": "8786566038915392046446786086504563210301842572125705765733243466035321540191", "price": "0.18", "size": "177.77", "side": "BUY", "hash": "67ca56c8cb190b2480c522f954dff6039e313343", "best_bid": "0.9", "best_ask": "0.94"}, {"asset_id": "57073863691050176858693353000197608096498121614576538982509295418934497382921", "price": "0.82", "size": "177.77", "side": "SELL", "hash": "809b6f01a6d20fe46312b4e25d7c377b05abab20", "best_bid": "0.06", "best_ask": "0.1"}], "timestamp": "1769384177654", "event_type": "price_change"}}
{"_local_timestamp": "2026-01-25T23:36:18.183572+00:00", "data": {"market": "0xb5fb3fd4dbc7fdc70e3666ed4193e3171ecc257dcd43e01b36dbd4efa01d777e", "price_changes": [{"asset_id": "8786566038915392046446786086504563210301842572125705765733243466035321540191", "price": "0.18", "size": "182.77", "side": "BUY", "hash": "1797a6d0913efcdf4c78e39d283078ed59864e04", "best_bid": "0.9", "best_ask": "0.94"}, {"asset_id": "57073863691050176858693353000197608096498121614576538982509295418934497382921", "price": "0.82", "size": "182.77", "side": "SELL", "hash": "07c8c93ca00c5dc0175afe3b3e01adffddf5b288", "best_bid": "0.06", "best_ask": "0.1"}], "timestamp": "1769384178088", "event_type": "price_change"}}
{"_local_timestamp": "2026-01-25T23:36:20.781868+00:00", "data": {"market": "0xb5fb3fd4dbc7fdc70e3666ed4193e3171ecc257dcd43e01b36dbd4efa01d777e", "price_changes": [{"asset_id": "8786566038915392046446786086504563210301842572125705765733243466035321540191", "price": "0.18", "size": "177.77", "side": "BUY", "hash": "946f1e62ab95ef68712995364a33b6c39304c2be", "best_bid": "0.9", "best_ask": "0.94"}, {"asset_id": "57073863691050176858693353000197608096498121614576538982509295418934497382921", "price": "0.82", "size": "177.77", "side": "SELL", "hash": "054755f6517f3dd9f5e4bf68b237537825b6f02a", "best_bid": "0.06", "best_ask": "0.1"}], "timestamp": "1769384180712", "event_type": "price_change"}}
{"_local_timestamp": "2026-01-25T23:36:21.170112+00:00", "data": {"market": "0xb5fb3fd4dbc7fdc70e3666ed4193e3171ecc257dcd43e01b36dbd4efa01d777e", "price_changes": [{"asset_id": "8786566038915392046446786086504563210301842572125705765733243466035321540191", "price": "0.18", "size": "182.77", "side": "BUY", "hash": "bbc1060852952ac0eaec3765a0bac7f98cb8d0a2", "best_bid": "0.9", "best_ask": "0.94"}, {"asset_id": "57073863691050176858693353000197608096498121614576538982509295418934497382921", "price": "0.82", "size": "182.77", "side": "SELL", "hash": "96fa1ac08fa749f739b3678d1fa1c750a0d9ea64", "best_bid": "0.06", "best_ask": "0.1"}], "timestamp": "1769384181097", "event_type": "price_change"}}
{"_local_timestamp": "2026-01-25T23:36:22.935092+00:00", "data": {"market": "0xb5fb3fd4dbc7fdc70e3666ed4193e3171ecc257dcd43e01b36dbd4efa01d777e", "price_changes": [{"asset_id": "8786566038915392046446786086504563210301842572125705765733243466035321540191", "price": "0.18", "size": "177.77", "side": "BUY", "hash": "88a4051269425efaeff3f94ee79e02c9a6d6ef4d", "best_bid": "0.9", "best_ask": "0.94"}, {"asset_id": "57073863691050176858693353000197608096498121614576538982509295418934497382921", "price": "0.82", "size": "177.77", "side": "SELL", "hash": "48351a16a57d1e2e8540676651210a32a39f7700", "best_bid": "0.06", "best_ask": "0.1"}], "timestamp": "1769384182865", "event_type": "price_change"}}
{"_local_timestamp": "2026-01-25T23:36:23.152364+00:00", "data": {"market": "0xb5fb3fd4dbc7fdc70e3666ed4193e3171ecc257dcd43e01b36dbd4efa01d777e", "price_changes": [{"asset_id": "8786566038915392046446786086504563210301842572125705765733243466035321540191", "price": "0.18", "size": "182.77", "side": "BUY", "hash": "bac56905d40a63563832e550421874ecb25e804e", "best_bid": "0.9", "best_ask": "0.94"}, {"asset_id": "57073863691050176858693353000197608096498121614576538982509295418934497382921", "price": "0.82", "size": "182.77", "side": "SELL", "hash": "14d49b1d935fffc9eb24ccdbee8f087407fa0e66", "best_bid": "0.06", "best_ask": "0.1"}], "timestamp": "1769384183081", "event_type": "price_change"}}
{"_local_timestamp": "2026-01-25T23:36:25.314262+00:00", "data": {"market": "0xb5fb3fd4dbc7fdc70e3666ed4193e3171ecc257dcd43e01b36dbd4efa01d777e", "price_changes": [{"asset_id": "8786566038915392046446786086504563210301842572125705765733243466035321540191", "price": "0.18", "size": "177.77", "side": "BUY", "hash": "e5b65b264b1f32702a09bc32b78160b14c39a2e5", "best_bid": "0.9", "best_ask": "0.94"}, {"asset_id": "57073863691050176858693353000197608096498121614576538982509295418934497382921", "price": "0.82", "size": "177.77", "side": "SELL", "hash": "f34b43feb6758686b6346ace3623b756d16ee620", "best_bid": "0.06", "best_ask": "0.1"}], "timestamp": "1769384185222", "event_type": "price_change"}}
{"_local_timestamp": "2026-01-25T23:36:25.563759+00:00", "data": {"market": "0xb5fb3fd4dbc7fdc70e3666ed4193e3171ecc257dcd43e01b36dbd4efa01d777e", "price_changes": [{"asset_id": "8786566038915392046446786086504563210301842572125705765733243466035321540191", "price": "0.18", "size": "182.77", "side": "BUY", "hash": "1ff4e1675090a9eee0c9a4336b078dab390c0fc9", "best_bid": "0.9", "best_ask": "0.94"}, {"asset_id": "57073863691050176858693353000197608096498121614576538982509295418934497382921", "price": "0.82", "size": "182.77", "side": "SELL", "hash": "f59a022f2f57e53621b76a735ffb41e8a50db4d1", "best_bid": "0.06", "best_ask": "0.1"}], "timestamp": "1769384185491", "event_type": "price_change"}}
{"_local_timestamp": "2026-01-25T23:36:27.798984+00:00", "data": {"market": "0xb5fb3fd4dbc7fdc70e3666ed4193e3171ecc257dcd43e01b36dbd4efa01d777e", "price_changes": [{"asset_id": "8786566038915392046446786086504563210301842572125705765733243466035321540191", "price": "0.18", "size": "177.77", "side": "BUY", "hash": "f8640fc1b05a8813b5800d659b7eef3eedf52397", "best_bid": "0.9", "best_ask": "0.94"}, {"asset_id": "57073863691050176858693353000197608096498121614576538982509295418934497382921", "price": "0.82", "size": "177.77", "side": "SELL", "hash": "8ac668b62a402b7230ba400eb7987cb81c1b8c78", "best_bid": "0.06", "best_ask": "0.1"}], "timestamp": "1769384187727", "event_type": "price_change"}}
{"_local_timestamp": "2026-01-25T23:36:28.229346+00:00", "data": {"market": "0xb5fb3fd4dbc7fdc70e3666ed4193e3171ecc257dcd43e01b36dbd4efa01d777e", "price_changes": [{"asset_id": "8786566038915392046446786086504563210301842572125705765733243466035321540191", "price": "0.18", "size": "182.77", "side": "BUY", "hash": "20288a73abce4cf5e05466ff9b971f93f1244b0e", "best_bid": "0.9", "best_ask": "0.94"}, {"asset_id": "57073863691050176858693353000197608096498121614576538982509295418934497382921", "price": "0.82", "size": "182.77", "side": "SELL", "hash": "c1a7d715df30f695b09769ed2fd6a4ee84a66892", "best_bid": "0.06", "best_ask": "0.1"}], "timestamp": "1769384188157", "event_type": "price_change"}}
{"_local_timestamp": "2026-01-25T23:36:30.796324+00:00", "data": {"market": "0xb5fb3fd4dbc7fdc70e3666ed4193e3171ecc257dcd43e01b36dbd4efa01d777e", "price_changes": [{"asset_id": "8786566038915392046446786086504563210301842572125705765733243466035321540191", "price": "0.18", "size": "177.77", "side": "BUY", "hash": "c72356d54ff6816d63027ac7dff17ae48e3b30b3", "best_bid": "0.9", "best_ask": "0.94"}, {"asset_id": "57073863691050176858693353000197608096498121614576538982509295418934497382921", "price": "0.82", "size": "177.77", "side": "SELL", "hash": "77b35fc3ad4e9c5d2a3b4ed06fa1b0da8f54b413", "best_bid": "0.06", "best_ask": "0.1"}], "timestamp": "1769384190722", "event_type": "price_change"}}
{"_local_timestamp": "2026-01-25T23:36:31.113162+00:00", "data": {"market": "0xb5fb3fd4dbc7fdc70e3666ed4193e3171ecc257dcd43e01b36dbd4efa01d777e", "price_changes": [{"asset_id": "8786566038915392046446786086504563210301842572125705765733243466035321540191", "price": "0.18", "size": "182.77", "side": "BUY", "hash": "6ce22b10b93a3c8d09cdc4d7aba4adb523e547b2", "best_bid": "0.9", "best_ask": "0.94"}, {"asset_id": "57073863691050176858693353000197608096498121614576538982509295418934497382921", "price": "0.82", "size": "182.77", "side": "SELL", "hash": "5fd26266942a1e1e8d1d7e7e0b84f6b87c440299", "best_bid": "0.06", "best_ask": "0.1"}], "timestamp": "1769384191030", "event_type": "price_change"}}
{"_local_timestamp": "2026-01-25T23:36:32.934568+00:00", "data": {"market": "0xb5fb3fd4dbc7fdc70e3666ed4193e3171ecc257dcd43e01b36dbd4efa01d777e", "price_changes": [{"asset_id": "8786566038915392046446786086504563210301842572125705765733243466035321540191", "price": "0.18", "size": "177.77", "side": "BUY", "hash": "220d0a796ce156b358ac5c01d4a89c0684d94024", "best_bid": "0.9", "best_ask": "0.94"}, {"asset_id": "57073863691050176858693353000197608096498121614576538982509295418934497382921", "price": "0.82", "size": "177.77", "side": "SELL", "hash": "b857dc32565b0c18b614fa385009f2f34ad5bc60", "best_bid": "0.06", "best_ask": "0.1"}], "timestamp": "1769384192854", "event_type": "price_change"}}
{"_local_timestamp": "2026-01-25T23:36:33.133139+00:00", "data": {"market": "0xb5fb3fd4dbc7fdc70e3666ed4193e3171ecc257dcd43e01b36dbd4efa01d777e", "price_changes": [{"asset_id": "8786566038915392046446786086504563210301842572125705765733243466035321540191", "price": "0.18", "size": "182.77", "side": "BUY", "hash": "31127aa52f33d03f8644211ae11c939af40855cc", "best_bid": "0.9", "best_ask": "0.94"}, {"asset_id": "57073863691050176858693353000197608096498121614576538982509295418934497382921", "price": "0.82", "size": "182.77", "side": "SELL", "hash": "6dc7179cb32dc148bd4f87ac5e411b9d8862a06f", "best_bid": "0.06", "best_ask": "0.1"}], "timestamp": "1769384193055", "event_type": "price_change"}}
{"_local_timestamp": "2026-01-25T23:36:35.047794+00:00", "data": {"market": "0xb5fb3fd4dbc7fdc70e3666ed4193e3171ecc257dcd43e01b36dbd4efa01d777e", "price_changes": [{"asset_id": "8786566038915392046446786086504563210301842572125705765733243466035321540191", "price": "0.18", "size": "177.77", "side": "BUY", "hash": "e92befbdbab5a58da1f26cf509416e3a2f633d68", "best_bid": "0.9", "best_ask": "0.94"}, {"asset_id": "57073863691050176858693353000197608096498121614576538982509295418934497382921", "price": "0.82", "size": "177.77", "side": "SELL", "hash": "eeab4c5b4f8de9cf8402c1bbc25eb36fcbaa94f7", "best_bid": "0.06", "best_ask": "0.1"}], "timestamp": "1769384194975", "event_type": "price_change"}}
{"_local_timestamp": "2026-01-25T23:36:35.363568+00:00", "data": {"market": "0xb5fb3fd4dbc7fdc70e3666ed4193e3171ecc257dcd43e01b36dbd4efa01d777e", "price_changes": [{"asset_id": "8786566038915392046446786086504563210301842572125705765733243466035321540191", "price": "0.18", "size": "182.77", "side": "BUY", "hash": "9df0e9b84298f173cca0c4213e0472e2e9e27883", "best_bid": "0.9", "best_ask": "0.94"}, {"asset_id": "57073863691050176858693353000197608096498121614576538982509295418934497382921", "price": "0.82", "size": "182.77", "side": "SELL", "hash": "72b3063bb93175bd3bae6f3edc8fd4502c2cc864", "best_bid": "0.06", "best_ask": "0.1"}], "timestamp": "1769384195290", "event_type": "price_change"}}
{"_local_timestamp": "2026-01-25T23:36:36.965066+00:00", "data": {"market": "0xb5fb3fd4dbc7fdc70e3666ed4193e3171ecc257dcd43e01b36dbd4efa01d777e", "price_changes": [{"asset_id": "8786566038915392046446786086504563210301842572125705765733243466035321540191", "price": "0.18", "size": "177.77", "side": "BUY", "hash": "dbcef3bc4f19834fbcd2e2a4542f07d4e5dd630b", "best_bid": "0.9", "best_ask": "0.94"}, {"asset_id": "57073863691050176858693353000197608096498121614576538982509295418934497382921", "price": "0.82", "size": "177.77", "side": "SELL", "hash": "ae1fef8614fc7bb502b734e174c2e810bc199e55", "best_bid": "0.06", "best_ask": "0.1"}], "timestamp": "1769384196896", "event_type": "price_change"}}
{"_local_timestamp": "2026-01-25T23:36:37.239053+00:00", "data": {"market": "0xb5fb3fd4dbc7fdc70e3666ed4193e3171ecc257dcd43e01b36dbd4efa01d777e", "price_changes": [{"asset_id": "8786566038915392046446786086504563210301842572125705765733243466035321540191", "price": "0.18", "size": "182.77", "side": "BUY", "hash": "318f909a7ed6af6497dcb7ece435e08522a25562", "best_bid": "0.9", "best_ask": "0.94"}, {"asset_id": "57073863691050176858693353000197608096498121614576538982509295418934497382921", "price": "0.82", "size": "182.77", "side": "SELL", "hash": "842390a27ce97b47bbf3d0f89197db9bf534dc5e", "best_bid": "0.06", "best_ask": "0.1"}], "timestamp": "1769384197167", "event_type": "price_change"}}
{"_local_timestamp": "2026-01-25T23:36:39.447239+00:00", "data": {"market": "0xb5fb3fd4dbc7fdc70e3666ed4193e3171ecc257dcd43e01b36dbd4efa01d777e", "price_changes": [{"asset_id": "8786566038915392046446786086504563210301842572125705765733243466035321540191", "price": "0.18", "size": "177.77", "side": "BUY", "hash": "d6d2ec4a1032306ab337026f1b4203888d347f8e", "best_bid": "0.9", "best_ask": "0.94"}, {"asset_id": "57073863691050176858693353000197608096498121614576538982509295418934497382921", "price": "0.82", "size": "177.77", "side": "SELL", "hash": "70260f6297ad3e66a23eca5fc068b274049027d4", "best_bid": "0.06", "best_ask": "0.1"}], "timestamp": "1769384199371", "event_type": "price_change"}}
{"_local_timestamp": "2026-01-25T23:36:39.755733+00:00", "data": {"market": "0xb5fb3fd4dbc7fdc70e3666ed4193e3171ecc257dcd43e01b36dbd4efa01d777e", "price_changes": [{"asset_id": "8786566038915392046446786086504563210301842572125705765733243466035321540191", "price": "0.18", "size": "182.77", "side": "BUY", "hash": "04f4fb9c2167c3048143a688dd5038e4d93c1bc3", "best_bid": "0.9", "best_ask": "0.94"}, {"asset_id": "57073863691050176858693353000197608096498121614576538982509295418934497382921", "price": "0.82", "size": "182.77", "side": "SELL", "hash": "64d39229ff505f0cb9e002948b6bb1581e19faf1", "best_bid": "0.06", "best_ask": "0.1"}], "timestamp": "1769384199682", "event_type": "price_change"}}
{"_local_timestamp": "2026-01-25T23:36:41.416392+00:00", "data": {"market": "0xb5fb3fd4dbc7fdc70e3666ed4193e3171ecc257dcd43e01b36dbd4efa01d777e", "price_changes": [{"asset_id": "8786566038915392046446786086504563210301842572125705765733243466035321540191", "price": "0.18", "size": "177.77", "side": "BUY", "hash": "b81f98d3281b053653bdfa4b1a12ebfe908a1413", "best_bid": "0.9", "best_ask": "0.94"}, {"asset_id": "57073863691050176858693353000197608096498121614576538982509295418934497382921", "price": "0.82", "size": "177.77", "side": "SELL", "hash": "8ad850fd4ca7843abcd51e2643a090bd3e5173e8", "best_bid": "0.06", "best_ask": "0.1"}], "timestamp": "1769384201294", "event_type": "price_change"}}
{"_local_timestamp": "2026-01-25T23:36:41.671668+00:00", "data": {"market": "0xb5fb3fd4dbc7fdc70e3666ed4193e3171ecc257dcd43e01b36dbd4efa01d777e", "price_changes": [{"asset_id": "8786566038915392046446786086504563210301842572125705765733243466035321540191", "price": "0.18", "size": "182.77", "side": "BUY", "hash": "7ca75391228bb422da5ca584a7f363c85b0fbc8c", "best_bid": "0.9", "best_ask": "0.94"}, {"asset_id": "57073863691050176858693353000197608096498121614576538982509295418934497382921", "price": "0.82", "size": "182.77", "side": "SELL", "hash": "44b3ad296db58c6b5ee5d3e6f0d6858189d22bfa", "best_bid": "0.06", "best_ask": "0.1"}], "timestamp": "1769384201551", "event_type": "price_change"}}
{"_local_timestamp": "2026-01-25T23:36:43.681707+00:00", "data": {"market": "0xb5fb3fd4dbc7fdc70e3666ed4193e3171ecc257dcd43e01b36dbd4efa01d777e", "price_changes": [{"asset_id": "8786566038915392046446786086504563210301842572125705765733243466035321540191", "price": "0.18", "size": "177.77", "side": "BUY", "hash": "38879d6e83802ff503a80b90295cac3477077a41", "best_bid": "0.9", "best_ask": "0.94"}, {"asset_id": "57073863691050176858693353000197608096498121614576538982509295418934497382921", "price": "0.82", "size": "177.77", "side": "SELL", "hash": "0a0604349404b47e44e3c93f5de21ae6ac335597", "best_bid": "0.06", "best_ask": "0.1"}], "timestamp": "1769384203488", "event_type": "price_change"}}
{"_local_timestamp": "2026-01-25T23:36:43.950089+00:00", "data": {"market": "0xb5fb3fd4dbc7fdc70e3666ed4193e3171ecc257dcd43e01b36dbd4efa01d777e", "price_changes": [{"asset_id": "8786566038915392046446786086504563210301842572125705765733243466035321540191", "price": "0.18", "size": "182.77", "side": "BUY", "hash": "e3c771501f004053e8cdda58dc411cceacd8c038", "best_bid": "0.9", "best_ask": "0.94"}, {"asset_id": "57073863691050176858693353000197608096498121614576538982509295418934497382921", "price": "0.82", "size": "182.77", "side": "SELL", "hash": "fe77f006e3f0afe3e3adaa12822ab2e463354a9a", "best_bid": "0.06", "best_ask": "0.1"}], "timestamp": "1769384203776", "event_type": "price_change"}}
{"_local_timestamp": "2026-01-25T23:36:45.797018+00:00", "data": {"market": "0xb5fb3fd4dbc7fdc70e3666ed4193e3171ecc257dcd43e01b36dbd4efa01d777e", "price_changes": [{"asset_id": "8786566038915392046446786086504563210301842572125705765733243466035321540191", "price": "0.18", "size": "177.77", "side": "BUY", "hash": "7314faf48f7a0ebb938c8f789118cb34d7f3e065", "best_bid": "0.9", "best_ask": "0.94"}, {"asset_id": "57073863691050176858693353000197608096498121614576538982509295418934497382921", "price": "0.82", "size": "177.77", "side": "SELL", "hash": "1458e760bc63d37b46a2458e2b86b19c7c2300ff", "best_bid": "0.06", "best_ask": "0.1"}], "timestamp": "1769384205641", "event_type": "price_change"}}
{"_local_timestamp": "2026-01-25T23:36:46.098452+00:00", "data": {"market": "0xb5fb3fd4dbc7fdc70e3666ed4193e3171ecc257dcd43e01b36dbd4efa01d777e", "price_changes": [{"asset_id": "8786566038915392046446786086504563210301842572125705765733243466035321540191", "price": "0.18", "size": "182.77", "side": "BUY", "hash": "762acb804c9a225e471a62ae61dafd963e0ca939", "best_bid": "0.9", "best_ask": "0.94"}, {"asset_id": "57073863691050176858693353000197608096498121614576538982509295418934497382921", "price": "0.82", "size": "182.77", "side": "SELL", "hash": "10bd01331e6099f251ae782a2bcb2a9de035b0bb", "best_bid": "0.06", "best_ask": "0.1"}], "timestamp": "1769384205934", "event_type": "price_change"}}
{"_local_timestamp": "2026-01-25T23:36:48.422323+00:00", "data": {"market": "0xb5fb3fd4dbc7fdc70e3666ed4193e3171ecc257dcd43e01b36dbd4efa01d777e", "price_changes": [{"asset_id": "8786566038915392046446786086504563210301842572125705765733243466035321540191", "price": "0.18", "size": "177.77", "side": "BUY", "hash": "5b0eba765feaff649ccf87cc6ab43aedc771ebda", "best_bid": "0.9", "best_ask": "0.94"}, {"asset_id": "57073863691050176858693353000197608096498121614576538982509295418934497382921", "price": "0.82", "size": "177.77", "side": "SELL", "hash": "fa4450c19cb1355e590cb2f1bd633f270a8db530", "best_bid": "0.06", "best_ask": "0.1"}], "timestamp": "1769384208279", "event_type": "price_change"}}
{"_local_timestamp": "2026-01-25T23:36:48.772928+00:00", "data": {"market": "0xb5fb3fd4dbc7fdc70e3666ed4193e3171ecc257dcd43e01b36dbd4efa01d777e", "price_changes": [{"asset_id": "8786566038915392046446786086504563210301842572125705765733243466035321540191", "price": "0.18", "size": "182.77", "side": "BUY", "hash": "512fa0cf57a61dd67855a110ab93bc5e753839a5", "best_bid": "0.9", "best_ask": "0.94"}, {"asset_id": "57073863691050176858693353000197608096498121614576538982509295418934497382921", "price": "0.82", "size": "182.77", "side": "SELL", "hash": "c0325def5044a8b8c06d5436d75933fabdbf168e", "best_bid": "0.06", "best_ask": "0.1"}], "timestamp": "1769384208626", "event_type": "price_change"}}
{"_local_timestamp": "2026-01-25T23:36:51.128945+00:00", "data": {"market": "0xb5fb3fd4dbc7fdc70e3666ed4193e3171ecc257dcd43e01b36dbd4efa01d777e", "price_changes": [{"asset_id": "8786566038915392046446786086504563210301842572125705765733243466035321540191", "price": "0.18", "size": "177.77", "side": "BUY", "hash": "564c4ab3bf5c8f486e46cdb0ae2177459c39ffaf", "best_bid": "0.9", "best_ask": "0.94"}, {"asset_id": "57073863691050176858693353000197608096498121614576538982509295418934497382921", "price": "0.82", "size": "177.77", "side": "SELL", "hash": "b34005c7566442d781990f42a7ce87d402716886", "best_bid": "0.06", "best_ask": "0.1"}], "timestamp": "1769384210981", "event_type": "price_change"}}
{"_local_timestamp": "2026-01-25T23:36:51.538269+00:00", "data": {"market": "0xb5fb3fd4dbc7fdc70e3666ed4193e3171ecc257dcd43e01b36dbd4efa01d777e", "price_changes": [{"asset_id": "8786566038915392046446786086504563210301842572125705765733243466035321540191", "price": "0.18", "size": "182.77", "side": "BUY", "hash": "2e57d9673fcdd6482ad7285732324afcb889a5f8", "best_bid": "0.9", "best_ask": "0.94"}, {"asset_id": "57073863691050176858693353000197608096498121614576538982509295418934497382921", "price": "0.82", "size": "182.77", "side": "SELL", "hash": "ec8ac6e5a3cd41862ab3abb4e437eafbf488beaf", "best_bid": "0.06", "best_ask": "0.1"}], "timestamp": "1769384211361", "event_type": "price_change"}}
{"_local_timestamp": "2026-01-25T23:36:53.798440+00:00", "data": {"market": "0xb5fb3fd4dbc7fdc70e3666ed4193e3171ecc257dcd43e01b36dbd4efa01d777e", "price_changes": [{"asset_id": "8786566038915392046446786086504563210301842572125705765733243466035321540191", "price": "0.18", "size": "177.77", "side": "BUY", "hash": "8fea6699c34aca239e985848350824385a179d8c", "best_bid": "0.9", "best_ask": "0.94"}, {"asset_id": "57073863691050176858693353000197608096498121614576538982509295418934497382921", "price": "0.82", "size": "177.77", "side": "SELL", "hash": "da943ae04e59d20045a0782a94d763474a33ef92", "best_bid": "0.06", "best_ask": "0.1"}], "timestamp": "1769384213615", "event_type": "price_change"}}
{"_local_timestamp": "2026-01-25T23:36:54.196339+00:00", "data": {"market": "0xb5fb3fd4dbc7fdc70e3666ed4193e3171ecc257dcd43e01b36dbd4efa01d777e", "price_changes": [{"asset_id": "8786566038915392046446786086504563210301842572125705765733243466035321540191", "price": "0.18", "size": "182.77", "side": "BUY", "hash": "b36e17dc75a2513ba2f58703194f7f15a3febe40", "best_bid": "0.9", "best_ask": "0.94"}, {"asset_id": "57073863691050176858693353000197608096498121614576538982509295418934497382921", "price": "0.82", "size": "182.77", "side": "SELL", "hash": "b30ca9b9b1880c0b77ff5f37c38bf7fac2149638", "best_bid": "0.06", "best_ask": "0.1"}], "timestamp": "1769384213999", "event_type": "price_change"}}
{"_local_timestamp": "2026-01-25T23:36:56.579273+00:00", "data": {"market": "0xb5fb3fd4dbc7fdc70e3666ed4193e3171ecc257dcd43e01b36dbd4efa01d777e", "price_changes": [{"asset_id": "8786566038915392046446786086504563210301842572125705765733243466035321540191", "price": "0.18", "size": "177.77", "side": "BUY", "hash": "42a300121b5cd5d6b8239b01a4b00024c196aa16", "best_bid": "0.9", "best_ask": "0.94"}, {"asset_id": "57073863691050176858693353000197608096498121614576538982509295418934497382921", "price": "0.82", "size": "177.77", "side": "SELL", "hash": "e12e1a3d6fadf458165fab7db03264fedb27984f", "best_bid": "0.06", "best_ask": "0.1"}], "timestamp": "1769384216231", "event_type": "price_change"}}
{"_local_timestamp": "2026-01-25T23:36:56.793889+00:00", "data": {"market": "0xb5fb3fd4dbc7fdc70e3666ed4193e3171ecc257dcd43e01b36dbd4efa01d777e", "price_changes": [{"asset_id": "8786566038915392046446786086504563210301842572125705765733243466035321540191", "price": "0.18", "size": "182.77", "side": "BUY", "hash": "121e179624c7c46997899e3b198356d601b2373a", "best_bid": "0.9", "best_ask": "0.94"}, {"asset_id": "57073863691050176858693353000197608096498121614576538982509295418934497382921", "price": "0.82", "size": "182.77", "side": "SELL", "hash": "5e5745673a72fbe62796fb7968a8f6d958cf9f23", "best_bid": "0.06", "best_ask": "0.1"}], "timestamp": "1769384216565", "event_type": "price_change"}}
{"_local_timestamp": "2026-01-25T23:36:59.189741+00:00", "data": {"market": "0xb5fb3fd4dbc7fdc70e3666ed4193e3171ecc257dcd43e01b36dbd4efa01d777e", "price_changes": [{"asset_id": "8786566038915392046446786086504563210301842572125705765733243466035321540191", "price": "0.18", "size": "177.77", "side": "BUY", "hash": "e841f10e9c3297cef74b2c8c22ab5bc209bbc2d8", "best_bid": "0.9", "best_ask": "0.94"}, {"asset_id": "57073863691050176858693353000197608096498121614576538982509295418934497382921", "price": "0.82", "size": "177.77", "side": "SELL", "hash": "5890a0137c8672a9141f76659de9cd780a401149", "best_bid": "0.06", "best_ask": "0.1"}], "timestamp": "1769384218849", "event_type": "price_change"}}
{"_local_timestamp": "2026-01-25T23:36:59.370035+00:00", "data": {"market": "0xb5fb3fd4dbc7fdc70e3666ed4193e3171ecc257dcd43e01b36dbd4efa01d777e", "price_changes": [{"asset_id": "8786566038915392046446786086504563210301842572125705765733243466035321540191", "price": "0.18", "size": "182.77", "side": "BUY", "hash": "1ae950f9185003231351ef90237c7a65690f8fbf", "best_bid": "0.9", "best_ask": "0.94"}, {"asset_id": "57073863691050176858693353000197608096498121614576538982509295418934497382921", "price": "0.82", "size": "182.77", "side": "SELL", "hash": "23517538b2b564779cc721ace1e8d7ec87cbbb13", "best_bid": "0.06", "best_ask": "0.1"}], "timestamp": "1769384219175", "event_type": "price_change"}}
{"_local_timestamp": "2026-01-25T23:37:01.766920+00:00", "data": {"market": "0xb5fb3fd4dbc7fdc70e3666ed4193e3171ecc257dcd43e01b36dbd4efa01d777e", "price_changes": [{"asset_id": "8786566038915392046446786086504563210301842572125705765733243466035321540191", "price": "0.18", "size": "177.77", "side": "BUY", "hash": "4ea202c3e8e3798299267bb3a51ae54474f31d3c", "best_bid": "0.9", "best_ask": "0.94"}, {"asset_id": "57073863691050176858693353000197608096498121614576538982509295418934497382921", "price": "0.82", "size": "177.77", "side": "SELL", "hash": "243fd584c0e9619d0003737c6b011af3cd650c98", "best_bid": "0.06", "best_ask": "0.1"}], "timestamp": "1769384221541", "event_type": "price_change"}}
{"_local_timestamp": "2026-01-25T23:37:02.022980+00:00", "data": {"market": "0xb5fb3fd4dbc7fdc70e3666ed4193e3171ecc257dcd43e01b36dbd4efa01d777e", "price_changes": [{"asset_id": "8786566038915392046446786086504563210301842572125705765733243466035321540191", "price": "0.18", "size": "182.77", "side": "BUY", "hash": "8c0b351b7fab291b16f61b22cfb4289e06b395bf", "best_bid": "0.9", "best_ask": "0.94"}, {"asset_id": "57073863691050176858693353000197608096498121614576538982509295418934497382921", "price": "0.82", "size": "182.77", "side": "SELL", "hash": "3869cb7c2e35bed9a39c052f1df775e4543272c4", "best_bid": "0.06", "best_ask": "0.1"}], "timestamp": "1769384221846", "event_type": "price_change"}}
{"_local_timestamp": "2026-01-25T23:37:03.454468+00:00", "data": {"market": "0xb5fb3fd4dbc7fdc70e3666ed4193e3171ecc257dcd43e01b36dbd4efa01d777e", "price_changes": [{"asset_id": "8786566038915392046446786086504563210301842572125705765733243466035321540191", "price": "0.18", "size": "177.77", "side": "BUY", "hash": "5e922bd5da6c5574c9c2916259dd70ded30161f9", "best_bid": "0.9", "best_ask": "0.94"}, {"asset_id": "57073863691050176858693353000197608096498121614576538982509295418934497382921", "price": "0.82", "size": "177.77", "side": "SELL", "hash": "677bf61c149dbc148b7292e7184cf230147f6cf3", "best_bid": "0.06", "best_ask": "0.1"}], "timestamp": "1769384223269", "event_type": "price_change"}}
{"_local_timestamp": "2026-01-25T23:37:03.795870+00:00", "data": {"market": "0xb5fb3fd4dbc7fdc70e3666ed4193e3171ecc257dcd43e01b36dbd4efa01d777e", "price_changes": [{"asset_id": "8786566038915392046446786086504563210301842572125705765733243466035321540191", "price": "0.18", "size": "182.77", "side": "BUY", "hash": "f4dbd25ffeceb813d7ecf4f59c104e075c55706b", "best_bid": "0.9", "best_ask": "0.94"}, {"asset_id": "57073863691050176858693353000197608096498121614576538982509295418934497382921", "price": "0.82", "size": "182.77", "side": "SELL", "hash": "90b190720d36d7493eab48c7e282972c0bed7841", "best_bid": "0.06", "best_ask": "0.1"}], "timestamp": "1769384223591", "event_type": "price_change"}}
{"_local_timestamp": "2026-01-25T23:37:05.996509+00:00", "data": {"market": "0xb5fb3fd4dbc7fdc70e3666ed4193e3171ecc257dcd43e01b36dbd4efa01d777e", "price_changes": [{"asset_id": "8786566038915392046446786086504563210301842572125705765733243466035321540191", "price": "0.18", "size": "177.77", "side": "BUY", "hash": "cd3520f24fda4a26dc7ad449923dfd7425357dd9", "best_bid": "0.9", "best_ask": "0.94"}, {"asset_id": "57073863691050176858693353000197608096498121614576538982509295418934497382921", "price": "0.82", "size": "177.77", "side": "SELL", "hash": "0d4ad322ce47bfa8be2c4b7f38c8612520d29581", "best_bid": "0.06", "best_ask": "0.1"}], "timestamp": "1769384225782", "event_type": "price_change"}}
{"_local_timestamp": "2026-01-25T23:37:06.287110+00:00", "data": {"market": "0xb5fb3fd4dbc7fdc70e3666ed4193e3171ecc257dcd43e01b36dbd4efa01d777e", "price_changes": [{"asset_id": "8786566038915392046446786086504563210301842572125705765733243466035321540191", "price": "0.18", "size": "182.77", "side": "BUY", "hash": "f7854c1a6a7dd06bd81c17fb4313e42645241f37", "best_bid": "0.9", "best_ask": "0.94"}, {"asset_id": "57073863691050176858693353000197608096498121614576538982509295418934497382921", "price": "0.82", "size": "182.77", "side": "SELL", "hash": "2e3879fcfced215b135ca9c46d778d36d98d2081", "best_bid": "0.06", "best_ask": "0.1"}], "timestamp": "1769384226068", "event_type": "price_change"}}
{"_local_timestamp": "2026-01-25T23:37:08.121216+00:00", "data": {"market": "0xb5fb3fd4dbc7fdc70e3666ed4193e3171ecc257dcd43e01b36dbd4efa01d777e", "price_changes": [{"asset_id": "8786566038915392046446786086504563210301842572125705765733243466035321540191", "price": "0.18", "size": "177.77", "side": "BUY", "hash": "96653006bbe2afbeda19a78e64712ce09818814d", "best_bid": "0.9", "best_ask": "0.94"}, {"asset_id": "57073863691050176858693353000197608096498121614576538982509295418934497382921", "price": "0.82", "size": "177.77", "side": "SELL", "hash": "1f1f6e9ee8888015b535d4c95e029f97c269b47e", "best_bid": "0.06", "best_ask": "0.1"}], "timestamp": "1769384227941", "event_type": "price_change"}}
{"_local_timestamp": "2026-01-25T23:37:08.400983+00:00", "data": {"market": "0xb5fb3fd4dbc7fdc70e3666ed4193e3171ecc257dcd43e01b36dbd4efa01d777e", "price_changes": [{"asset_id": "8786566038915392046446786086504563210301842572125705765733243466035321540191", "price": "0.18", "size": "182.77", "side": "BUY", "hash": "47c16121f7513f32dd94ba7d9dcf02a39a2938b5", "best_bid": "0.9", "best_ask": "0.94"}, {"asset_id": "57073863691050176858693353000197608096498121614576538982509295418934497382921", "price": "0.82", "size": "182.77", "side": "SELL", "hash": "91da7768f7525d75feaeaf28631f50e6c13a9094", "best_bid": "0.06", "best_ask": "0.1"}], "timestamp": "1769384228229", "event_type": "price_change"}}
{"_local_timestamp": "2026-01-25T23:37:10.471980+00:00", "data": {"market": "0xb5fb3fd4dbc7fdc70e3666ed4193e3171ecc257dcd43e01b36dbd4efa01d777e", "price_changes": [{"asset_id": "8786566038915392046446786086504563210301842572125705765733243466035321540191", "price": "0.18", "size": "177.77", "side": "BUY", "hash": "1e7ae36ffcd8ee0ef952b6df14d7be8f2f99e217", "best_bid": "0.9", "best_ask": "0.94"}, {"asset_id": "57073863691050176858693353000197608096498121614576538982509295418934497382921", "price": "0.82", "size": "177.77", "side": "SELL", "hash": "afd6af0e91a8b22a63d026624a6da4d30602e21d", "best_bid": "0.06", "best_ask": "0.1"}], "timestamp": "1769384230395", "event_type": "price_change"}}
{"_local_timestamp": "2026-01-25T23:37:11.680386+00:00", "data": {"market": "0xb5fb3fd4dbc7fdc70e3666ed4193e3171ecc257dcd43e01b36dbd4efa01d777e", "price_changes": [{"asset_id": "8786566038915392046446786086504563210301842572125705765733243466035321540191", "price": "0.18", "size": "182.77", "side": "BUY", "hash": "75a160b5fc42283a83d7cd09f48cbda40d7db850", "best_bid": "0.9", "best_ask": "0.94"}, {"asset_id": "57073863691050176858693353000197608096498121614576538982509295418934497382921", "price": "0.82", "size": "182.77", "side": "SELL", "hash": "250c83e9fea48c7932b39fd18f12ad421c349548", "best_bid": "0.06", "best_ask": "0.1"}], "timestamp": "1769384231613", "event_type": "price_change"}}
{"_local_timestamp": "2026-01-25T23:37:14.159007+00:00", "data": {"market": "0xb5fb3fd4dbc7fdc70e3666ed4193e3171ecc257dcd43e01b36dbd4efa01d777e", "price_changes": [{"asset_id": "8786566038915392046446786086504563210301842572125705765733243466035321540191", "price": "0.18", "size": "177.77", "side": "BUY", "hash": "748fdea9e5643e1c18f6bd0941f26ef238c8ea85", "best_bid": "0.9", "best_ask": "0.94"}, {"asset_id": "57073863691050176858693353000197608096498121614576538982509295418934497382921", "price": "0.82", "size": "177.77", "side": "SELL", "hash": "9777517096ba77c67f2a7e1245d1fb22b2a3ab8e", "best_bid": "0.06", "best_ask": "0.1"}], "timestamp": "1769384234038", "event_type": "price_change"}}
{"_local_timestamp": "2026-01-25T23:37:14.574050+00:00", "data": {"market": "0xb5fb3fd4dbc7fdc70e3666ed4193e3171ecc257dcd43e01b36dbd4efa01d777e", "price_changes": [{"asset_id": "8786566038915392046446786086504563210301842572125705765733243466035321540191", "price": "0.18", "size": "182.77", "side": "BUY", "hash": "899da083dc8e88314c04f7b16e12bdf364aa778a", "best_bid": "0.9", "best_ask": "0.94"}, {"asset_id": "57073863691050176858693353000197608096498121614576538982509295418934497382921", "price": "0.82", "size": "182.77", "side": "SELL", "hash": "20a351575384b816dcaa75cc9fee1f4cdb9f3597", "best_bid": "0.06", "best_ask": "0.1"}], "timestamp": "1769384234494", "event_type": "price_change"}}
{"_local_timestamp": "2026-01-25T23:37:16.043306+00:00", "data": {"market": "0xb5fb3fd4dbc7fdc70e3666ed4193e3171ecc257dcd43e01b36dbd4efa01d777e", "price_changes": [{"asset_id": "8786566038915392046446786086504563210301842572125705765733243466035321540191", "price": "0.18", "size": "177.77", "side": "BUY", "hash": "7d65f5c10d5b557e5efe731efcee00ac6a9d1aba", "best_bid": "0.9", "best_ask": "0.94"}, {"asset_id": "57073863691050176858693353000197608096498121614576538982509295418934497382921", "price": "0.82", "size": "177.77", "side": "SELL", "hash": "f43e17158a4618cd6dc0362e2476b5da3ad742b4", "best_bid": "0.06", "best_ask": "0.1"}], "timestamp": "1769384235974", "event_type": "price_change"}}
{"_local_timestamp": "2026-01-25T23:37:16.329392+00:00", "data": {"market": "0xb5fb3fd4dbc7fdc70e3666ed4193e3171ecc257dcd43e01b36dbd4efa01d777e", "price_changes": [{"asset_id": "8786566038915392046446786086504563210301842572125705765733243466035321540191", "price": "0.18", "size": "182.77", "side": "BUY", "hash": "eb74a0fe4076c88797e754f15f47f10c768bd918", "best_bid": "0.9", "best_ask": "0.94"}, {"asset_id": "57073863691050176858693353000197608096498121614576538982509295418934497382921", "price": "0.82", "size": "182.77", "side": "SELL", "hash": "081b388e82260318e6751b9ae8920cb3c3db9ffe", "best_bid": "0.06", "best_ask": "0.1"}], "timestamp": "1769384236256", "event_type": "price_change"}}
{"_local_timestamp": "2026-01-25T23:37:19.254587+00:00", "data": {"market": "0xb5fb3fd4dbc7fdc70e3666ed4193e3171ecc257dcd43e01b36dbd4efa01d777e", "price_changes": [{"asset_id": "8786566038915392046446786086504563210301842572125705765733243466035321540191", "price": "0.18", "size": "177.77", "side": "BUY", "hash": "3fdff54b71993d9c3ccd98071c7bee8ef09a37cd", "best_bid": "0.9", "best_ask": "0.94"}, {"asset_id": "57073863691050176858693353000197608096498121614576538982509295418934497382921", "price": "0.82", "size": "177.77", "side": "SELL", "hash": "c7426fef6333f837fd5414cf6931c095e0ee8aec", "best_bid": "0.06", "best_ask": "0.1"}], "timestamp": "1769384239186", "event_type": "price_change"}}
{"_local_timestamp": "2026-01-25T23:37:19.570350+00:00", "data": {"market": "0xb5fb3fd4dbc7fdc70e3666ed4193e3171ecc257dcd43e01b36dbd4efa01d777e", "price_changes": [{"asset_id": "8786566038915392046446786086504563210301842572125705765733243466035321540191", "price": "0.18", "size": "182.77", "side": "BUY", "hash": "1669eeeb75c54a6d64baf7d52f2b5a3efe6cd626", "best_bid": "0.9", "best_ask": "0.94"}, {"asset_id": "57073863691050176858693353000197608096498121614576538982509295418934497382921", "price": "0.82", "size": "182.77", "side": "SELL", "hash": "c1bbe47267a6f39ffe6088067749add8483fa68c", "best_bid": "0.06", "best_ask": "0.1"}], "timestamp": "1769384239491", "event_type": "price_change"}}
{"_local_timestamp": "2026-01-25T23:37:21.595605+00:00", "data": {"market": "0xb5fb3fd4dbc7fdc70e3666ed4193e3171ecc257dcd43e01b36dbd4efa01d777e", "price_changes": [{"asset_id": "8786566038915392046446786086504563210301842572125705765733243466035321540191", "price": "0.18", "size": "177.77", "side": "BUY", "hash": "99393a994d2b3ccac03922cb1ee63f0ab1420ff6", "best_bid": "0.9", "best_ask": "0.94"}, {"asset_id": "57073863691050176858693353000197608096498121614576538982509295418934497382921", "price": "0.82", "size": "177.77", "side": "SELL", "hash": "df003130886f92f16810051d78fae03db40bfadc", "best_bid": "0.06", "best_ask": "0.1"}], "timestamp": "1769384241515", "event_type": "price_change"}}
{"_local_timestamp": "2026-01-25T23:37:21.895809+00:00", "data": {"market": "0xb5fb3fd4dbc7fdc70e3666ed4193e3171ecc257dcd43e01b36dbd4efa01d777e", "price_changes": [{"asset_id": "8786566038915392046446786086504563210301842572125705765733243466035321540191", "price": "0.18", "size": "182.77", "side": "BUY", "hash": "2f125ff9834bcff06cdc5e70210b77a567558333", "best_bid": "0.9", "best_ask": "0.94"}, {"asset_id": "57073863691050176858693353000197608096498121614576538982509295418934497382921", "price": "0.82", "size": "182.77", "side": "SELL", "hash": "921d3548efab78393ef8bb98f76c7ee0c71d9a46", "best_bid": "0.06", "best_ask": "0.1"}], "timestamp": "1769384241824", "event_type": "price_change"}}
{"_local_timestamp": "2026-01-25T23:37:23.820200+00:00", "data": {"market": "0xb5fb3fd4dbc7fdc70e3666ed4193e3171ecc257dcd43e01b36dbd4efa01d777e", "price_changes": [{"asset_id": "8786566038915392046446786086504563210301842572125705765733243466035321540191", "price": "0.18", "size": "177.77", "side": "BUY", "hash": "4da20f25415c6c048fb368177da8acffc37d989b", "best_bid": "0.9", "best_ask": "0.94"}, {"asset_id": "57073863691050176858693353000197608096498121614576538982509295418934497382921", "price": "0.82", "size": "177.77", "side": "SELL", "hash": "1c53730f610006dd34e0d951a3a53de6de455eb7", "best_bid": "0.06", "best_ask": "0.1"}], "timestamp": "1769384243753", "event_type": "price_change"}}
{"_local_timestamp": "2026-01-25T23:37:24.092345+00:00", "data": {"market": "0xb5fb3fd4dbc7fdc70e3666ed4193e3171ecc257dcd43e01b36dbd4efa01d777e", "price_changes": [{"asset_id": "8786566038915392046446786086504563210301842572125705765733243466035321540191", "price": "0.18", "size": "182.77", "side": "BUY", "hash": "8868459447303a145b59054c7bc65c83df89ce9b", "best_bid": "0.9", "best_ask": "0.94"}, {"asset_id": "57073863691050176858693353000197608096498121614576538982509295418934497382921", "price": "0.82", "size": "182.77", "side": "SELL", "hash": "185c2bb4a0abd21c42dd46de61e6f9b521099d4e", "best_bid": "0.06", "best_ask": "0.1"}], "timestamp": "1769384244022", "event_type": "price_change"}}
{"_local_timestamp": "2026-01-25T23:37:26.529339+00:00", "data": {"market": "0xb5fb3fd4dbc7fdc70e3666ed4193e3171ecc257dcd43e01b36dbd4efa01d777e", "price_changes": [{"asset_id": "8786566038915392046446786086504563210301842572125705765733243466035321540191", "price": "0.18", "size": "177.77", "side": "BUY", "hash": "306077033b26036b98a64590715a5bc5bc00f08f", "best_bid": "0.9", "best_ask": "0.94"}, {"asset_id": "57073863691050176858693353000197608096498121614576538982509295418934497382921", "price": "0.82", "size": "177.77", "side": "SELL", "hash": "ab7564c4b0ffc1b89bc63a7a30d5074e7599dc03", "best_bid": "0.06", "best_ask": "0.1"}], "timestamp": "1769384246462", "event_type": "price_change"}}
{"_local_timestamp": "2026-01-25T23:37:26.901672+00:00", "data": {"market": "0xb5fb3fd4dbc7fdc70e3666ed4193e3171ecc257dcd43e01b36dbd4efa01d777e", "price_changes": [{"asset_id": "8786566038915392046446786086504563210301842572125705765733243466035321540191", "price": "0.18", "size": "182.77", "side": "BUY", "hash": "16d02cc2622f47d2dbb2543ef51b3b38081d1e77", "best_bid": "0.9", "best_ask": "0.94"}, {"asset_id": "57073863691050176858693353000197608096498121614576538982509295418934497382921", "price": "0.82", "size": "182.77", "side": "SELL", "hash": "8966b66f7f857e3002598c8aaaa55889765934ac", "best_bid": "0.06", "best_ask": "0.1"}], "timestamp": "1769384246830", "event_type": "price_change"}}
{"_local_timestamp": "2026-01-25T23:37:29.552863+00:00", "data": {"market": "0xb5fb3fd4dbc7fdc70e3666ed4193e3171ecc257dcd43e01b36dbd4efa01d777e", "price_changes": [{"asset_id": "8786566038915392046446786086504563210301842572125705765733243466035321540191", "price": "0.18", "size": "177.77", "side": "BUY", "hash": "e575fca39d4a59b4970851f1d2a69b3d6df46a24", "best_bid": "0.9", "best_ask": "0.94"}, {"asset_id": "57073863691050176858693353000197608096498121614576538982509295418934497382921", "price": "0.82", "size": "177.77", "side": "SELL", "hash": "c03af2bb2e4d6166952cd8683a3fd2b69b4d6c7a", "best_bid": "0.06", "best_ask": "0.1"}], "timestamp": "1769384249482", "event_type": "price_change"}}
{"_local_timestamp": "2026-01-25T23:37:29.787260+00:00", "data": {"market": "0xb5fb3fd4dbc7fdc70e3666ed4193e3171ecc257dcd43e01b36dbd4efa01d777e", "price_changes": [{"asset_id": "8786566038915392046446786086504563210301842572125705765733243466035321540191", "price": "0.18", "size": "182.77", "side": "BUY", "hash": "6d7fff03026fdd65f4011d23978599871a3d4222", "best_bid": "0.9", "best_ask": "0.94"}, {"asset_id": "57073863691050176858693353000197608096498121614576538982509295418934497382921", "price": "0.82", "size": "182.77", "side": "SELL", "hash": "84e19ba09b7103a1e5b8756da98249881fe1627b", "best_bid": "0.06", "best_ask": "0.1"}], "timestamp": "1769384249718", "event_type": "price_change"}}
{"_local_timestamp": "2026-01-25T23:37:32.342381+00:00", "data": {"market": "0xb5fb3fd4dbc7fdc70e3666ed4193e3171ecc257dcd43e01b36dbd4efa01d777e", "price_changes": [{"asset_id": "8786566038915392046446786086504563210301842572125705765733243466035321540191", "price": "0.18", "size": "177.77", "side": "BUY", "hash": "041de95c21d48136386e82f6db8f18cb551145c7", "best_bid": "0.9", "best_ask": "0.94"}, {"asset_id": "57073863691050176858693353000197608096498121614576538982509295418934497382921", "price": "0.82", "size": "177.77", "side": "SELL", "hash": "98cbe08f514af68a1dda68cca454215ea9985a80", "best_bid": "0.06", "best_ask": "0.1"}], "timestamp": "1769384252220", "event_type": "price_change"}}
{"_local_timestamp": "2026-01-25T23:37:32.678104+00:00", "data": {"market": "0xb5fb3fd4dbc7fdc70e3666ed4193e3171ecc257dcd43e01b36dbd4efa01d777e", "price_changes": [{"asset_id": "8786566038915392046446786086504563210301842572125705765733243466035321540191", "price": "0.18", "size": "182.77", "side": "BUY", "hash": "e6f780a2e3c12a1a9e7bed62deff9cfa68b44519", "best_bid": "0.9", "best_ask": "0.94"}, {"asset_id": "57073863691050176858693353000197608096498121614576538982509295418934497382921", "price": "0.82", "size": "182.77", "side": "SELL", "hash": "a647fe6cc05e7dc27b8572e256cad79f631315e0", "best_bid": "0.06", "best_ask": "0.1"}], "timestamp": "1769384252554", "event_type": "price_change"}}
{"_local_timestamp": "2026-01-25T23:37:34.906571+00:00", "data": {"market": "0xb5fb3fd4dbc7fdc70e3666ed4193e3171ecc257dcd43e01b36dbd4efa01d777e", "price_changes": [{"asset_id": "8786566038915392046446786086504563210301842572125705765733243466035321540191", "price": "0.18", "size": "177.77", "side": "BUY", "hash": "b36528ed394326e6a69ac1b3cd6aca476b36f812", "best_bid": "0.9", "best_ask": "0.94"}, {"asset_id": "57073863691050176858693353000197608096498121614576538982509295418934497382921", "price": "0.82", "size": "177.77", "side": "SELL", "hash": "66e3563f4d16ae5925752edd91b54444414f6435", "best_bid": "0.06", "best_ask": "0.1"}], "timestamp": "1769384254834", "event_type": "price_change"}}
{"_local_timestamp": "2026-01-25T23:37:35.346055+00:00", "data": {"market": "0xb5fb3fd4dbc7fdc70e3666ed4193e3171ecc257dcd43e01b36dbd4efa01d777e", "price_changes": [{"asset_id": "8786566038915392046446786086504563210301842572125705765733243466035321540191", "price": "0.18", "size": "182.77", "side": "BUY", "hash": "d9a852f4e06a88fee91c379e52c62dd58313108a", "best_bid": "0.9", "best_ask": "0.94"}, {"asset_id": "57073863691050176858693353000197608096498121614576538982509295418934497382921", "price": "0.82", "size": "182.77", "side": "SELL", "hash": "dfce11d9fad9b444a488f0f51696fd04b632421e", "best_bid": "0.06", "best_ask": "0.1"}], "timestamp": "1769384255152", "event_type": "price_change"}}
{"_local_timestamp": "2026-01-25T23:37:37.567521+00:00", "data": {"market": "0xb5fb3fd4dbc7fdc70e3666ed4193e3171ecc257dcd43e01b36dbd4efa01d777e", "price_changes": [{"asset_id": "8786566038915392046446786086504563210301842572125705765733243466035321540191", "price": "0.18", "size": "177.77", "side": "BUY", "hash": "8c90dd98df485b95a30b72f5aa75a6050cc9930f", "best_bid": "0.9", "best_ask": "0.94"}, {"asset_id": "57073863691050176858693353000197608096498121614576538982509295418934497382921", "price": "0.82", "size": "177.77", "side": "SELL", "hash": "2f129ec7741cd5b571cc3362a3dae19073185bdc", "best_bid": "0.06", "best_ask": "0.1"}], "timestamp": "1769384257495", "event_type": "price_change"}}
{"_local_timestamp": "2026-01-25T23:37:37.796139+00:00", "data": {"market": "0xb5fb3fd4dbc7fdc70e3666ed4193e3171ecc257dcd43e01b36dbd4efa01d777e", "price_changes": [{"asset_id": "8786566038915392046446786086504563210301842572125705765733243466035321540191", "price": "0.18", "size": "182.77", "side": "BUY", "hash": "3afed4e6bfff28dcdbeb9c64601814943b1241ad", "best_bid": "0.9", "best_ask": "0.94"}, {"asset_id": "57073863691050176858693353000197608096498121614576538982509295418934497382921", "price": "0.82", "size": "182.77", "side": "SELL", "hash": "d8b336ba295143f1d2d117ba276dedded18050e2", "best_bid": "0.06", "best_ask": "0.1"}], "timestamp": "1769384257724", "event_type": "price_change"}}
{"_local_timestamp": "2026-01-25T23:37:40.366307+00:00", "data": {"market": "0xb5fb3fd4dbc7fdc70e3666ed4193e3171ecc257dcd43e01b36dbd4efa01d777e", "price_changes": [{"asset_id": "8786566038915392046446786086504563210301842572125705765733243466035321540191", "price": "0.18", "size": "177.77", "side": "BUY", "hash": "002610396856c95d405fa182ea298772d0222c3b", "best_bid": "0.9", "best_ask": "0.94"}, {"asset_id": "57073863691050176858693353000197608096498121614576538982509295418934497382921", "price": "0.82", "size": "177.77", "side": "SELL", "hash": "aae81b6b8fdba8ed295f3008e456b4be00758268", "best_bid": "0.06", "best_ask": "0.1"}], "timestamp": "1769384260261", "event_type": "price_change"}}
{"_local_timestamp": "2026-01-25T23:37:40.681527+00:00", "data": {"market": "0xb5fb3fd4dbc7fdc70e3666ed4193e3171ecc257dcd43e01b36dbd4efa01d777e", "price_changes": [{"asset_id": "8786566038915392046446786086504563210301842572125705765733243466035321540191", "price": "0.18", "size": "182.77", "side": "BUY", "hash": "93faae1b28579fa3c6212a860607ae6f0a829a4e", "best_bid": "0.9", "best_ask": "0.94"}, {"asset_id": "57073863691050176858693353000197608096498121614576538982509295418934497382921", "price": "0.82", "size": "182.77", "side": "SELL", "hash": "0635108261dbb4d0e8f7a2250deef9a8780a26b4", "best_bid": "0.06", "best_ask": "0.1"}], "timestamp": "1769384260511", "event_type": "price_change"}}
{"_local_timestamp": "2026-01-25T23:37:42.623636+00:00", "data": {"market": "0xb5fb3fd4dbc7fdc70e3666ed4193e3171ecc257dcd43e01b36dbd4efa01d777e", "price_changes": [{"asset_id": "8786566038915392046446786086504563210301842572125705765733243466035321540191", "price": "0.18", "size": "177.77", "side": "BUY", "hash": "e4c2e09009ce7cbde28412878b7ea3cb423787af", "best_bid": "0.9", "best_ask": "0.94"}, {"asset_id": "57073863691050176858693353000197608096498121614576538982509295418934497382921", "price": "0.82", "size": "177.77", "side": "SELL", "hash": "96f5c4c395d64a137b352e601aba73228e4af1f0", "best_bid": "0.06", "best_ask": "0.1"}], "timestamp": "1769384262520", "event_type": "price_change"}}
{"_local_timestamp": "2026-01-25T23:37:43.034054+00:00", "data": {"market": "0xb5fb3fd4dbc7fdc70e3666ed4193e3171ecc257dcd43e01b36dbd4efa01d777e", "price_changes": [{"asset_id": "8786566038915392046446786086504563210301842572125705765733243466035321540191", "price": "0.18", "size": "182.77", "side": "BUY", "hash": "c06cd0582652367c75b160004d5285d49ca884a9", "best_bid": "0.9", "best_ask": "0.94"}, {"asset_id": "57073863691050176858693353000197608096498121614576538982509295418934497382921", "price": "0.82", "size": "182.77", "side": "SELL", "hash": "0af220e1ec7a69dd51cd960cedb7292240f61b48", "best_bid": "0.06", "best_ask": "0.1"}], "timestamp": "1769384262928", "event_type": "price_change"}}
{"_local_timestamp": "2026-01-25T23:37:44.823850+00:00", "data": {"market": "0xb5fb3fd4dbc7fdc70e3666ed4193e3171ecc257dcd43e01b36dbd4efa01d777e", "price_changes": [{"asset_id": "8786566038915392046446786086504563210301842572125705765733243466035321540191", "price": "0.18", "size": "177.77", "side": "BUY", "hash": "7b0cdf7ad5b527691b41bd276744174f4d2b2e21", "best_bid": "0.9", "best_ask": "0.94"}, {"asset_id": "57073863691050176858693353000197608096498121614576538982509295418934497382921", "price": "0.82", "size": "177.77", "side": "SELL", "hash": "3bfa4d918992a32edc086f60d30e78738783fd53", "best_bid": "0.06", "best_ask": "0.1"}], "timestamp": "1769384264722", "event_type": "price_change"}}
{"_local_timestamp": "2026-01-25T23:37:45.083417+00:00", "data": {"market": "0xb5fb3fd4dbc7fdc70e3666ed4193e3171ecc257dcd43e01b36dbd4efa01d777e", "price_changes": [{"asset_id": "8786566038915392046446786086504563210301842572125705765733243466035321540191", "price": "0.18", "size": "182.77", "side": "BUY", "hash": "c9a9a023558374a0829b8390dbf3244c0ed8ff65", "best_bid": "0.9", "best_ask": "0.94"}, {"asset_id": "57073863691050176858693353000197608096498121614576538982509295418934497382921", "price": "0.82", "size": "182.77", "side": "SELL", "hash": "20b99eedc6cac7086c554a76a410c03ed7df3df4", "best_bid": "0.06", "best_ask": "0.1"}], "timestamp": "1769384264981", "event_type": "price_change"}}
{"_local_timestamp": "2026-01-25T23:37:47.173407+00:00", "data": {"market": "0xb5fb3fd4dbc7fdc70e3666ed4193e3171ecc257dcd43e01b36dbd4efa01d777e", "price_changes": [{"asset_id": "8786566038915392046446786086504563210301842572125705765733243466035321540191", "price": "0.18", "size": "177.77", "side": "BUY", "hash": "e4b1d29f31400d637e421b74d49d18ceef8578df", "best_bid": "0.9", "best_ask": "0.94"}, {"asset_id": "57073863691050176858693353000197608096498121614576538982509295418934497382921", "price": "0.82", "size": "177.77", "side": "SELL", "hash": "a50829d143cf9eedd8c039cb735d5bf0e36170ed", "best_bid": "0.06", "best_ask": "0.1"}], "timestamp": "1769384267052", "event_type": "price_change"}}
{"_local_timestamp": "2026-01-25T23:37:47.627593+00:00", "data": {"market": "0xb5fb3fd4dbc7fdc70e3666ed4193e3171ecc257dcd43e01b36dbd4efa01d777e", "price_changes": [{"asset_id": "8786566038915392046446786086504563210301842572125705765733243466035321540191", "price": "0.18", "size": "182.77", "side": "BUY", "hash": "3e03756df5ca3267af45c30d40e7b7f8d5c0bef5", "best_bid": "0.9", "best_ask": "0.94"}, {"asset_id": "57073863691050176858693353000197608096498121614576538982509295418934497382921", "price": "0.82", "size": "182.77", "side": "SELL", "hash": "d7c2f0d371b40948268e1d0b6e59d62336adf3ea", "best_bid": "0.06", "best_ask": "0.1"}], "timestamp": "1769384267467", "event_type": "price_change"}}
{"_local_timestamp": "2026-01-25T23:37:49.765844+00:00", "data": {"market": "0xb5fb3fd4dbc7fdc70e3666ed4193e3171ecc257dcd43e01b36dbd4efa01d777e", "price_changes": [{"asset_id": "8786566038915392046446786086504563210301842572125705765733243466035321540191", "price": "0.18", "size": "177.77", "side": "BUY", "hash": "f3a97bbd7a1c3b64928423303584d4938dea9ae8", "best_bid": "0.9", "best_ask": "0.94"}, {"asset_id": "57073863691050176858693353000197608096498121614576538982509295418934497382921", "price": "0.82", "size": "177.77", "side": "SELL", "hash": "949c7c585ad57141ebfe7c5836203f84ff0af9e8", "best_bid": "0.06", "best_ask": "0.1"}], "timestamp": "1769384269653", "event_type": "price_change"}}
{"_local_timestamp": "2026-01-25T23:37:50.169416+00:00", "data": {"market": "0xb5fb3fd4dbc7fdc70e3666ed4193e3171ecc257dcd43e01b36dbd4efa01d777e", "price_changes": [{"asset_id": "8786566038915392046446786086504563210301842572125705765733243466035321540191", "price": "0.18", "size": "182.77", "side": "BUY", "hash": "15bf9d20fb3922c0d094168a21c092337057cfee", "best_bid": "0.9", "best_ask": "0.94"}, {"asset_id": "57073863691050176858693353000197608096498121614576538982509295418934497382921", "price": "0.82", "size": "182.77", "side": "SELL", "hash": "150d80c6404fbc8f92e651926302d2678ebff0e8", "best_bid": "0.06", "best_ask": "0.1"}], "timestamp": "1769384270015", "event_type": "price_change"}}
{"_local_timestamp": "2026-01-25T23:37:51.999663+00:00", "data": {"market": "0xb5fb3fd4dbc7fdc70e3666ed4193e3171ecc257dcd43e01b36dbd4efa01d777e", "price_changes": [{"asset_id": "8786566038915392046446786086504563210301842572125705765733243466035321540191", "price": "0.18", "size": "177.77", "side": "BUY", "hash": "32ae72b692ba58c7b6936ac70e21ffc5fd52a5aa", "best_bid": "0.9", "best_ask": "0.94"}, {"asset_id": "57073863691050176858693353000197608096498121614576538982509295418934497382921", "price": "0.82", "size": "177.77", "side": "SELL", "hash": "fa194b7edbe36eeb44736826c6fb406509e8bdb5", "best_bid": "0.06", "best_ask": "0.1"}], "timestamp": "1769384271843", "event_type": "price_change"}}
{"_local_timestamp": "2026-01-25T23:37:52.355259+00:00", "data": {"market": "0xb5fb3fd4dbc7fdc70e3666ed4193e3171ecc257dcd43e01b36dbd4efa01d777e", "price_changes": [{"asset_id": "8786566038915392046446786086504563210301842572125705765733243466035321540191", "price": "0.18", "size": "182.77", "side": "BUY", "hash": "5f989bb11750b79fe7ec668e73ac93632ef91878", "best_bid": "0.9", "best_ask": "0.94"}, {"asset_id": "57073863691050176858693353000197608096498121614576538982509295418934497382921", "price": "0.82", "size": "182.77", "side": "SELL", "hash": "d2db5019dc76fbc3584b9113c98ada93829e18cd", "best_bid": "0.06", "best_ask": "0.1"}], "timestamp": "1769384272220", "event_type": "price_change"}}
{"_local_timestamp": "2026-01-25T23:37:54.625567+00:00", "data": {"market": "0xb5fb3fd4dbc7fdc70e3666ed4193e3171ecc257dcd43e01b36dbd4efa01d777e", "price_changes": [{"asset_id": "8786566038915392046446786086504563210301842572125705765733243466035321540191", "price": "0.18", "size": "177.77", "side": "BUY", "hash": "aa22a3413888a19cc8740fcb2fe2875bebac1c31", "best_bid": "0.9", "best_ask": "0.94"}, {"asset_id": "57073863691050176858693353000197608096498121614576538982509295418934497382921", "price": "0.82", "size": "177.77", "side": "SELL", "hash": "b3e041481cc526cbeedcefcb9fa9ae73e3501968", "best_bid": "0.06", "best_ask": "0.1"}], "timestamp": "1769384274500", "event_type": "price_change"}}
{"_local_timestamp": "2026-01-25T23:37:54.893435+00:00", "data": {"market": "0xb5fb3fd4dbc7fdc70e3666ed4193e3171ecc257dcd43e01b36dbd4efa01d777e", "price_changes": [{"asset_id": "8786566038915392046446786086504563210301842572125705765733243466035321540191", "price": "0.18", "size": "182.77", "side": "BUY", "hash": "9a2dee7f403db6040cbb2225dc6d0a925c87f046", "best_bid": "0.9", "best_ask": "0.94"}, {"asset_id": "57073863691050176858693353000197608096498121614576538982509295418934497382921", "price": "0.82", "size": "182.77", "side": "SELL", "hash": "8a7ee1f982ea8e8e00bbc4aa219ee4de0b40bcaa", "best_bid": "0.06", "best_ask": "0.1"}], "timestamp": "1769384274764", "event_type": "price_change"}}
{"_local_timestamp": "2026-01-25T23:37:56.865340+00:00", "data": {"market": "0xb5fb3fd4dbc7fdc70e3666ed4193e3171ecc257dcd43e01b36dbd4efa01d777e", "price_changes": [{"asset_id": "8786566038915392046446786086504563210301842572125705765733243466035321540191", "price": "0.18", "size": "177.77", "side": "BUY", "hash": "91f407bd35f0d81119a30c55c2c8a24b05dfaf7e", "best_bid": "0.9", "best_ask": "0.94"}, {"asset_id": "57073863691050176858693353000197608096498121614576538982509295418934497382921", "price": "0.82", "size": "177.77", "side": "SELL", "hash": "21ecf9972666c1611842e330f0d146905ad380b6", "best_bid": "0.06", "best_ask": "0.1"}], "timestamp": "1769384276722", "event_type": "price_change"}}
{"_local_timestamp": "2026-01-25T23:37:57.247027+00:00", "data": {"market": "0xb5fb3fd4dbc7fdc70e3666ed4193e3171ecc257dcd43e01b36dbd4efa01d777e", "price_changes": [{"asset_id": "8786566038915392046446786086504563210301842572125705765733243466035321540191", "price": "0.18", "size": "182.77", "side": "BUY", "hash": "9a6a51e2a190cf9ac96f1bd41ced1a8ff9524dbf", "best_bid": "0.9", "best_ask": "0.94"}, {"asset_id": "57073863691050176858693353000197608096498121614576538982509295418934497382921", "price": "0.82", "size": "182.77", "side": "SELL", "hash": "f1cc51c874184628ad9d579185ee484ae471c74b", "best_bid": "0.06", "best_ask": "0.1"}], "timestamp": "1769384277121", "event_type": "price_change"}}
{"_local_timestamp": "2026-01-25T23:37:59.473272+00:00", "data": {"market": "0xb5fb3fd4dbc7fdc70e3666ed4193e3171ecc257dcd43e01b36dbd4efa01d777e", "price_changes": [{"asset_id": "8786566038915392046446786086504563210301842572125705765733243466035321540191", "price": "0.18", "size": "177.77", "side": "BUY", "hash": "8107a7dfe6433aaa945e6e6ccfe1e448fb5aad3f", "best_bid": "0.9", "best_ask": "0.94"}, {"asset_id": "57073863691050176858693353000197608096498121614576538982509295418934497382921", "price": "0.82", "size": "177.77", "side": "SELL", "hash": "6fe77dd1a7c908623f2668348fe2cb2291c579ea", "best_bid": "0.06", "best_ask": "0.1"}], "timestamp": "1769384279365", "event_type": "price_change"}}
{"_local_timestamp": "2026-01-25T23:37:59.738116+00:00", "data": {"market": "0xb5fb3fd4dbc7fdc70e3666ed4193e3171ecc257dcd43e01b36dbd4efa01d777e", "price_changes": [{"asset_id": "8786566038915392046446786086504563210301842572125705765733243466035321540191", "price": "0.18", "size": "182.77", "side": "BUY", "hash": "60d3677bb6a265f67f18b15562ddd9144fc38da9", "best_bid": "0.9", "best_ask": "0.94"}, {"asset_id": "57073863691050176858693353000197608096498121614576538982509295418934497382921", "price": "0.82", "size": "182.77", "side": "SELL", "hash": "90cd023e0b815427c777433c8bd2f4124c67cebc", "best_bid": "0.06", "best_ask": "0.1"}], "timestamp": "1769384279650", "event_type": "price_change"}}
{"_local_timestamp": "2026-01-25T23:38:02.058563+00:00", "data": {"market": "0xb5fb3fd4dbc7fdc70e3666ed4193e3171ecc257dcd43e01b36dbd4efa01d777e", "price_changes": [{"asset_id": "8786566038915392046446786086504563210301842572125705765733243466035321540191", "price": "0.18", "size": "177.77", "side": "BUY", "hash": "266fff3828d59eb8d1938c81bb467f79f3c53f9a", "best_bid": "0.9", "best_ask": "0.94"}, {"asset_id": "57073863691050176858693353000197608096498121614576538982509295418934497382921", "price": "0.82", "size": "177.77", "side": "SELL", "hash": "e0725e4a8f6890302b3f014ab0a3a8d8ae0c9160", "best_bid": "0.06", "best_ask": "0.1"}], "timestamp": "1769384281920", "event_type": "price_change"}}
{"_local_timestamp": "2026-01-25T23:38:02.439111+00:00", "data": {"market": "0xb5fb3fd4dbc7fdc70e3666ed4193e3171ecc257dcd43e01b36dbd4efa01d777e", "price_changes": [{"asset_id": "8786566038915392046446786086504563210301842572125705765733243466035321540191", "price": "0.18", "size": "182.77", "side": "BUY", "hash": "58ed07153ad66bbdc44337a483e48879f4f726e6", "best_bid": "0.9", "best_ask": "0.94"}, {"asset_id": "57073863691050176858693353000197608096498121614576538982509295418934497382921", "price": "0.82", "size": "182.77", "side": "SELL", "hash": "94338a0a0bcc8b8126824fdbf2920c5f30eb71ea", "best_bid": "0.06", "best_ask": "0.1"}], "timestamp": "1769384282303", "event_type": "price_change"}}
{"_local_timestamp": "2026-01-25T23:38:04.696475+00:00", "data": {"market": "0xb5fb3fd4dbc7fdc70e3666ed4193e3171ecc257dcd43e01b36dbd4efa01d777e", "price_changes": [{"asset_id": "8786566038915392046446786086504563210301842572125705765733243466035321540191", "price": "0.18", "size": "177.77", "side": "BUY", "hash": "cf5fcdd62bd1b8b2d5d3ca91225c727fbe7cfe43", "best_bid": "0.9", "best_ask": "0.94"}, {"asset_id": "57073863691050176858693353000197608096498121614576538982509295418934497382921", "price": "0.82", "size": "177.77", "side": "SELL", "hash": "f130599b217c1887b1385cd861619f6c2cdc6160", "best_bid": "0.06", "best_ask": "0.1"}], "timestamp": "1769384284530", "event_type": "price_change"}}
{"_local_timestamp": "2026-01-25T23:38:04.978589+00:00", "data": {"market": "0xb5fb3fd4dbc7fdc70e3666ed4193e3171ecc257dcd43e01b36dbd4efa01d777e", "price_changes": [{"asset_id": "8786566038915392046446786086504563210301842572125705765733243466035321540191", "price": "0.18", "size": "182.77", "side": "BUY", "hash": "d0d2d5c8838f0c4a1d9a033562a87c77bbc7656f", "best_bid": "0.9", "best_ask": "0.94"}, {"asset_id": "57073863691050176858693353000197608096498121614576538982509295418934497382921", "price": "0.82", "size": "182.77", "side": "SELL", "hash": "0fb89143b83523f072fda451b5acc03b6ce4d686", "best_bid": "0.06", "best_ask": "0.1"}], "timestamp": "1769384284833", "event_type": "price_change"}}
{"_local_timestamp": "2026-01-25T23:38:06.846150+00:00", "data": {"market": "0xb5fb3fd4dbc7fdc70e3666ed4193e3171ecc257dcd43e01b36dbd4efa01d777e", "price_changes": [{"asset_id": "8786566038915392046446786086504563210301842572125705765733243466035321540191", "price": "0.18", "size": "177.77", "side": "BUY", "hash": "75d09569ebf7f45a17970c8d6a26b27ee2246dca", "best_bid": "0.9", "best_ask": "0.94"}, {"asset_id": "57073863691050176858693353000197608096498121614576538982509295418934497382921", "price": "0.82", "size": "177.77", "side": "SELL", "hash": "13e42949046dec8d8337df9ee7cfe89b7b87c8c6", "best_bid": "0.06", "best_ask": "0.1"}], "timestamp": "1769384286714", "event_type": "price_change"}}
{"_local_timestamp": "2026-01-25T23:38:07.185242+00:00", "data": {"market": "0xb5fb3fd4dbc7fdc70e3666ed4193e3171ecc257dcd43e01b36dbd4efa01d777e", "price_changes": [{"asset_id": "8786566038915392046446786086504563210301842572125705765733243466035321540191", "price": "0.18", "size": "182.77", "side": "BUY", "hash": "96d1fb55a4aed0156c616f42c2e1d9eb2d44ffbe", "best_bid": "0.9", "best_ask": "0.94"}, {"asset_id": "57073863691050176858693353000197608096498121614576538982509295418934497382921", "price": "0.82", "size": "182.77", "side": "SELL", "hash": "0ee0ea6c8811a1aaf621fdf68e71ff7b6ee20e94", "best_bid": "0.06", "best_ask": "0.1"}], "timestamp": "1769384287054", "event_type": "price_change"}}
{"_local_timestamp": "2026-01-25T23:38:09.182514+00:00", "data": {"market": "0xb5fb3fd4dbc7fdc70e3666ed4193e3171ecc257dcd43e01b36dbd4efa01d777e", "price_changes": [{"asset_id": "8786566038915392046446786086504563210301842572125705765733243466035321540191", "price": "0.18", "size": "177.77", "side": "BUY", "hash": "54b62e691a2dd1db836656411df45c16cc9893e1", "best_bid": "0.9", "best_ask": "0.94"}, {"asset_id": "57073863691050176858693353000197608096498121614576538982509295418934497382921", "price": "0.82", "size": "177.77", "side": "SELL", "hash": "e4fa70a208d4ffaa8ec7b727f28b51006b587d0c", "best_bid": "0.06", "best_ask": "0.1"}], "timestamp": "1769384289107", "event_type": "price_change"}}
{"_local_timestamp": "2026-01-25T23:38:09.588927+00:00", "data": {"market": "0xb5fb3fd4dbc7fdc70e3666ed4193e3171ecc257dcd43e01b36dbd4efa01d777e", "price_changes": [{"asset_id": "8786566038915392046446786086504563210301842572125705765733243466035321540191", "price": "0.18", "size": "182.77", "side": "BUY", "hash": "baec670c095f92809d364a20106d70bc4d4918e3", "best_bid": "0.9", "best_ask": "0.94"}, {"asset_id": "57073863691050176858693353000197608096498121614576538982509295418934497382921", "price": "0.82", "size": "182.77", "side": "SELL", "hash": "10756a1e2dd1edd4c2e71a644757dde7cd0d588b", "best_bid": "0.06", "best_ask": "0.1"}], "timestamp": "1769384289507", "event_type": "price_change"}}
{"_local_timestamp": "2026-01-25T23:38:11.331386+00:00", "data": {"market": "0xb5fb3fd4dbc7fdc70e3666ed4193e3171ecc257dcd43e01b36dbd4efa01d777e", "price_changes": [{"asset_id": "8786566038915392046446786086504563210301842572125705765733243466035321540191", "price": "0.18", "size": "177.77", "side": "BUY", "hash": "47f563be8021eab6e5a6ee4eeb6207d32dbd1de3", "best_bid": "0.9", "best_ask": "0.94"}, {"asset_id": "57073863691050176858693353000197608096498121614576538982509295418934497382921", "price": "0.82", "size": "177.77", "side": "SELL", "hash": "162ace4cd461636ee3ab7da144e0178e08b3ab7b", "best_bid": "0.06", "best_ask": "0.1"}], "timestamp": "1769384291260", "event_type": "price_change"}}
{"_local_timestamp": "2026-01-25T23:38:11.627279+00:00", "data": {"market": "0xb5fb3fd4dbc7fdc70e3666ed4193e3171ecc257dcd43e01b36dbd4efa01d777e", "price_changes": [{"asset_id": "8786566038915392046446786086504563210301842572125705765733243466035321540191", "price": "0.18", "size": "182.77", "side": "BUY", "hash": "ae1eaa04cdee1e4831372ecc68b482bd958df70b", "best_bid": "0.9", "best_ask": "0.94"}, {"asset_id": "57073863691050176858693353000197608096498121614576538982509295418934497382921", "price": "0.82", "size": "182.77", "side": "SELL", "hash": "df7bbb9fdcd8397a381fb3e339ae8aadeda353a5", "best_bid": "0.06", "best_ask": "0.1"}], "timestamp": "1769384291554", "event_type": "price_change"}}
{"_local_timestamp": "2026-01-25T23:38:13.513216+00:00", "data": {"market": "0xb5fb3fd4dbc7fdc70e3666ed4193e3171ecc257dcd43e01b36dbd4efa01d777e", "price_changes": [{"asset_id": "8786566038915392046446786086504563210301842572125705765733243466035321540191", "price": "0.18", "size": "177.77", "side": "BUY", "hash": "1f14f556eb16fee106521102cc7a059ef664c572", "best_bid": "0.9", "best_ask": "0.94"}, {"asset_id": "57073863691050176858693353000197608096498121614576538982509295418934497382921", "price": "0.82", "size": "177.77", "side": "SELL", "hash": "a795e9fb11ade2f4f3049e4a1eb847857c5888e8", "best_bid": "0.06", "best_ask": "0.1"}], "timestamp": "1769384293420", "event_type": "price_change"}}
{"_local_timestamp": "2026-01-25T23:38:13.917358+00:00", "data": {"market": "0xb5fb3fd4dbc7fdc70e3666ed4193e3171ecc257dcd43e01b36dbd4efa01d777e", "price_changes": [{"asset_id": "8786566038915392046446786086504563210301842572125705765733243466035321540191", "price": "0.18", "size": "182.77", "side": "BUY", "hash": "06ccbfcbdf9f62f05d162760adee29ba845a7c73", "best_bid": "0.9", "best_ask": "0.94"}, {"asset_id": "57073863691050176858693353000197608096498121614576538982509295418934497382921", "price": "0.82", "size": "182.77", "side": "SELL", "hash": "9baf7f2382c81fb6087af5ee94c5d07d07601dbf", "best_bid": "0.06", "best_ask": "0.1"}], "timestamp": "1769384293844", "event_type": "price_change"}}
{"_local_timestamp": "2026-01-25T23:38:16.109975+00:00", "data": {"market": "0xb5fb3fd4dbc7fdc70e3666ed4193e3171ecc257dcd43e01b36dbd4efa01d777e", "price_changes": [{"asset_id": "8786566038915392046446786086504563210301842572125705765733243466035321540191", "price": "0.18", "size": "177.77", "side": "BUY", "hash": "f06d2509d991e44cd7160bd98d186e901b44ced6", "best_bid": "0.9", "best_ask": "0.94"}, {"asset_id": "57073863691050176858693353000197608096498121614576538982509295418934497382921", "price": "0.82", "size": "177.77", "side": "SELL", "hash": "a3bf9327864cda9d45a20267c1be8a06bb754ddd", "best_bid": "0.06", "best_ask": "0.1"}], "timestamp": "1769384296023", "event_type": "price_change"}}
{"_local_timestamp": "2026-01-25T23:38:16.447555+00:00", "data": {"market": "0xb5fb3fd4dbc7fdc70e3666ed4193e3171ecc257dcd43e01b36dbd4efa01d777e", "price_changes": [{"asset_id": "8786566038915392046446786086504563210301842572125705765733243466035321540191", "price": "0.18", "size": "182.77", "side": "BUY", "hash": "9f8b93fd57066722ed9248e5f0115ed00a4abca3", "best_bid": "0.9", "best_ask": "0.94"}, {"asset_id": "57073863691050176858693353000197608096498121614576538982509295418934497382921", "price": "0.82", "size": "182.77", "side": "SELL", "hash": "c2aedc298a057c1400ef00d71f3fe68f7d452945", "best_bid": "0.06", "best_ask": "0.1"}], "timestamp": "1769384296380", "event_type": "price_change"}}
{"_local_timestamp": "2026-01-25T23:38:18.320880+00:00", "data": {"market": "0xb5fb3fd4dbc7fdc70e3666ed4193e3171ecc257dcd43e01b36dbd4efa01d777e", "price_changes": [{"asset_id": "8786566038915392046446786086504563210301842572125705765733243466035321540191", "price": "0.18", "size": "177.77", "side": "BUY", "hash": "e61605edbd1a97b716268b128eb717208ae79420", "best_bid": "0.9", "best_ask": "0.94"}, {"asset_id": "57073863691050176858693353000197608096498121614576538982509295418934497382921", "price": "0.82", "size": "177.77", "side": "SELL", "hash": "a5e1f28209087b033ef335cd03e2ac6d9a811427", "best_bid": "0.06", "best_ask": "0.1"}], "timestamp": "1769384298248", "event_type": "price_change"}}
{"_local_timestamp": "2026-01-25T23:38:18.716328+00:00", "data": {"market": "0xb5fb3fd4dbc7fdc70e3666ed4193e3171ecc257dcd43e01b36dbd4efa01d777e", "price_changes": [{"asset_id": "8786566038915392046446786086504563210301842572125705765733243466035321540191", "price": "0.18", "size": "182.77", "side": "BUY", "hash": "3d3f2ab010602b2f4c23a26d71cb1f17ac8901c2", "best_bid": "0.9", "best_ask": "0.94"}, {"asset_id": "57073863691050176858693353000197608096498121614576538982509295418934497382921", "price": "0.82", "size": "182.77", "side": "SELL", "hash": "ff1e065ffe957925d1af7dcd08154c9d7e06a9c3", "best_bid": "0.06", "best_ask": "0.1"}], "timestamp": "1769384298643", "event_type": "price_change"}}
{"_local_timestamp": "2026-01-25T23:38:25.031267+00:00", "data": {"market": "0xb5fb3fd4dbc7fdc70e3666ed4193e3171ecc257dcd43e01b36dbd4efa01d777e", "price_changes": [{"asset_id": "8786566038915392046446786086504563210301842572125705765733243466035321540191", "price": "0.18", "size": "177.77", "side": "BUY", "hash": "79b6ac0e232082dfb90f1abc26d6ffd76f5dbb67", "best_bid": "0.9", "best_ask": "0.94"}, {"asset_id": "57073863691050176858693353000197608096498121614576538982509295418934497382921", "price": "0.82", "size": "177.77", "side": "SELL", "hash": "a3c5de21217817eb5d113b4f00f1c21702b81cf0", "best_bid": "0.06", "best_ask": "0.1"}], "timestamp": "1769384304960", "event_type": "price_change"}}
{"_local_timestamp": "2026-01-25T23:38:25.425963+00:00", "data": {"market": "0xb5fb3fd4dbc7fdc70e3666ed4193e3171ecc257dcd43e01b36dbd4efa01d777e", "price_changes": [{"asset_id": "8786566038915392046446786086504563210301842572125705765733243466035321540191", "price": "0.18", "size": "182.77", "side": "BUY", "hash": "ee444ef468c365666bbc00c9a38ca2e203e11b39", "best_bid": "0.9", "best_ask": "0.94"}, {"asset_id": "57073863691050176858693353000197608096498121614576538982509295418934497382921", "price": "0.82", "size": "182.77", "side": "SELL", "hash": "29531deb04c3cd776963cec93232956ec6adf529", "best_bid": "0.06", "best_ask": "0.1"}], "timestamp": "1769384305337", "event_type": "price_change"}}
{"_local_timestamp": "2026-01-25T23:38:32.139008+00:00", "data": {"market": "0xb5fb3fd4dbc7fdc70e3666ed4193e3171ecc257dcd43e01b36dbd4efa01d777e", "price_changes": [{"asset_id": "8786566038915392046446786086504563210301842572125705765733243466035321540191", "price": "0.18", "size": "177.77", "side": "BUY", "hash": "171e860c0f9485569cfe542bbf786a22466ca774", "best_bid": "0.9", "best_ask": "0.94"}, {"asset_id": "57073863691050176858693353000197608096498121614576538982509295418934497382921", "price": "0.82", "size": "177.77", "side": "SELL", "hash": "7633ffe864340dfd3a779d0d7e4bd581e89a3278", "best_bid": "0.06", "best_ask": "0.1"}], "timestamp": "1769384312070", "event_type": "price_change"}}
{"_local_timestamp": "2026-01-25T23:38:32.500497+00:00", "data": {"market": "0xb5fb3fd4dbc7fdc70e3666ed4193e3171ecc257dcd43e01b36dbd4efa01d777e", "price_changes": [{"asset_id": "8786566038915392046446786086504563210301842572125705765733243466035321540191", "price": "0.18", "size": "182.77", "side": "BUY", "hash": "395a88702ad6f7704acb7d490349cfd1a1f5cf09", "best_bid": "0.9", "best_ask": "0.94"}, {"asset_id": "57073863691050176858693353000197608096498121614576538982509295418934497382921", "price": "0.82", "size": "182.77", "side": "SELL", "hash": "58cc4338409afcff45f33351932e84513d94822a", "best_bid": "0.06", "best_ask": "0.1"}], "timestamp": "1769384312429", "event_type": "price_change"}}
{"_local_timestamp": "2026-01-25T23:38:40.632821+00:00", "data": {"market": "0xb5fb3fd4dbc7fdc70e3666ed4193e3171ecc257dcd43e01b36dbd4efa01d777e", "price_changes": [{"asset_id": "8786566038915392046446786086504563210301842572125705765733243466035321540191", "price": "0.18", "size": "177.77", "side": "BUY", "hash": "4e8e25d580dfe715880da58856019b622ecb837f", "best_bid": "0.9", "best_ask": "0.94"}, {"asset_id": "57073863691050176858693353000197608096498121614576538982509295418934497382921", "price": "0.82", "size": "177.77", "side": "SELL", "hash": "018d02f4c2c77974cca95ff302f14a311e355b0d", "best_bid": "0.06", "best_ask": "0.1"}], "timestamp": "1769384320562", "event_type": "price_change"}}
{"_local_timestamp": "2026-01-25T23:38:40.993115+00:00", "data": {"market": "0xb5fb3fd4dbc7fdc70e3666ed4193e3171ecc257dcd43e01b36dbd4efa01d777e", "price_changes": [{"asset_id": "8786566038915392046446786086504563210301842572125705765733243466035321540191", "price": "0.18", "size": "182.77", "side": "BUY", "hash": "6ba7b9a4e287d92484aa2e082bdbbc39f559bb3b", "best_bid": "0.9", "best_ask": "0.94"}, {"asset_id": "57073863691050176858693353000197608096498121614576538982509295418934497382921", "price": "0.82", "size": "182.77", "side": "SELL", "hash": "808f85de1d269a809535e5c697b589dd62b448cc", "best_bid": "0.06", "best_ask": "0.1"}], "timestamp": "1769384320916", "event_type": "price_change"}}
{"_local_timestamp": "2026-01-25T23:38:51.438907+00:00", "data": {"market": "0xb5fb3fd4dbc7fdc70e3666ed4193e3171ecc257dcd43e01b36dbd4efa01d777e", "price_changes": [{"asset_id": "8786566038915392046446786086504563210301842572125705765733243466035321540191", "price": "0.18", "size": "177.77", "side": "BUY", "hash": "76f7b81cbaf006879742165a9a40c735b7c78a78", "best_bid": "0.9", "best_ask": "0.94"}, {"asset_id": "57073863691050176858693353000197608096498121614576538982509295418934497382921", "price": "0.82", "size": "177.77", "side": "SELL", "hash": "b31ddf85811354efdd908758f80f5a32ad7d6f11", "best_bid": "0.06", "best_ask": "0.1"}], "timestamp": "1769384331367", "event_type": "price_change"}}
{"_local_timestamp": "2026-01-25T23:38:51.903126+00:00", "data": {"market": "0xb5fb3fd4dbc7fdc70e3666ed4193e3171ecc257dcd43e01b36dbd4efa01d777e", "price_changes": [{"asset_id": "8786566038915392046446786086504563210301842572125705765733243466035321540191", "price": "0.18", "size": "182.77", "side": "BUY", "hash": "d0ffc765ac05e286bde5e9389f6fac7d34ecb0f1", "best_bid": "0.9", "best_ask": "0.94"}, {"asset_id": "57073863691050176858693353000197608096498121614576538982509295418934497382921", "price": "0.82", "size": "182.77", "side": "SELL", "hash": "9cdff4f56d90f9f9363bc98801fd81b827391473", "best_bid": "0.06", "best_ask": "0.1"}], "timestamp": "1769384331813", "event_type": "price_change"}}
{"_local_timestamp": "2026-01-25T23:39:04.636968+00:00", "data": {"market": "0xb5fb3fd4dbc7fdc70e3666ed4193e3171ecc257dcd43e01b36dbd4efa01d777e", "price_changes": [{"asset_id": "8786566038915392046446786086504563210301842572125705765733243466035321540191", "price": "0.18", "size": "177.77", "side": "BUY", "hash": "eaa1d947d2ba3a3d9382e60b8cf6ef69979e4090", "best_bid": "0.9", "best_ask": "0.94"}, {"asset_id": "57073863691050176858693353000197608096498121614576538982509295418934497382921", "price": "0.82", "size": "177.77", "side": "SELL", "hash": "e00ab886bfa83cf887ccec23969cd7cb18fb4844", "best_bid": "0.06", "best_ask": "0.1"}], "timestamp": "1769384344571", "event_type": "price_change"}}
{"_local_timestamp": "2026-01-25T23:39:04.914636+00:00", "data": {"market": "0xb5fb3fd4dbc7fdc70e3666ed4193e3171ecc257dcd43e01b36dbd4efa01d777e", "price_changes": [{"asset_id": "8786566038915392046446786086504563210301842572125705765733243466035321540191", "price": "0.18", "size": "182.77", "side": "BUY", "hash": "90e0668fef7e890c2f4cc475d615641abaae1ea7", "best_bid": "0.9", "best_ask": "0.94"}, {"asset_id": "57073863691050176858693353000197608096498121614576538982509295418934497382921", "price": "0.82", "size": "182.77", "side": "SELL", "hash": "ab617fd27b7d13e1647f227f1f2ea5e9c2010bd4", "best_bid": "0.06", "best_ask": "0.1"}], "timestamp": "1769384344831", "event_type": "price_change"}}
{"_local_timestamp": "2026-01-25T23:39:12.566065+00:00", "data": {"market": "0xb5fb3fd4dbc7fdc70e3666ed4193e3171ecc257dcd43e01b36dbd4efa01d777e", "price_changes": [{"asset_id": "8786566038915392046446786086504563210301842572125705765733243466035321540191", "price": "0.18", "size": "177.77", "side": "BUY", "hash": "2fa79ea2ddffb13bc3af4ad4e5fdc70b34395787", "best_bid": "0.9", "best_ask": "0.94"}, {"asset_id": "57073863691050176858693353000197608096498121614576538982509295418934497382921", "price": "0.82", "size": "177.77", "side": "SELL", "hash": "72d23904388289961af2ed58f97ab6ad770a5d40", "best_bid": "0.06", "best_ask": "0.1"}], "timestamp": "1769384352491", "event_type": "price_change"}}
{"_local_timestamp": "2026-01-25T23:39:12.875671+00:00", "data": {"market": "0xb5fb3fd4dbc7fdc70e3666ed4193e3171ecc257dcd43e01b36dbd4efa01d777e", "price_changes": [{"asset_id": "8786566038915392046446786086504563210301842572125705765733243466035321540191", "price": "0.18", "size": "182.77", "side": "BUY", "hash": "daf4be749bd6edb8f51f354cfb644b0d496ec1d8", "best_bid": "0.9", "best_ask": "0.94"}, {"asset_id": "57073863691050176858693353000197608096498121614576538982509295418934497382921", "price": "0.82", "size": "182.77", "side": "SELL", "hash": "d72e08e4daf8d848d9ec8234f5116cf0568e5f7d", "best_bid": "0.06", "best_ask": "0.1"}], "timestamp": "1769384352806", "event_type": "price_change"}}
{"_local_timestamp": "2026-01-25T23:39:15.638420+00:00", "data": {"market": "0xb5fb3fd4dbc7fdc70e3666ed4193e3171ecc257dcd43e01b36dbd4efa01d777e", "price_changes": [{"asset_id": "8786566038915392046446786086504563210301842572125705765733243466035321540191", "price": "0.18", "size": "177.77", "side": "BUY", "hash": "62f1290bcb054fcb2a0b3ae755fab59c797987a2", "best_bid": "0.9", "best_ask": "0.94"}, {"asset_id": "57073863691050176858693353000197608096498121614576538982509295418934497382921", "price": "0.82", "size": "177.77", "side": "SELL", "hash": "c1db3c7a9313526db25ed63e2c32e7e85dfbb2ef", "best_bid": "0.06", "best_ask": "0.1"}], "timestamp": "1769384355566", "event_type": "price_change"}}
{"_local_timestamp": "2026-01-25T23:39:16.343838+00:00", "data": {"market": "0xb5fb3fd4dbc7fdc70e3666ed4193e3171ecc257dcd43e01b36dbd4efa01d777e", "price_changes": [{"asset_id": "8786566038915392046446786086504563210301842572125705765733243466035321540191", "price": "0.18", "size": "182.77", "side": "BUY", "hash": "85e0e437f51fef99db377e9aed5345b1d288140a", "best_bid": "0.9", "best_ask": "0.94"}, {"asset_id": "57073863691050176858693353000197608096498121614576538982509295418934497382921", "price": "0.82", "size": "182.77", "side": "SELL", "hash": "1de28d07982be224a465d87bdef8c3926153afdd", "best_bid": "0.06", "best_ask": "0.1"}], "timestamp": "1769384356268", "event_type": "price_change"}}
{"_local_timestamp": "2026-01-25T23:39:18.836276+00:00", "data": {"market": "0xb5fb3fd4dbc7fdc70e3666ed4193e3171ecc257dcd43e01b36dbd4efa01d777e", "price_changes": [{"asset_id": "8786566038915392046446786086504563210301842572125705765733243466035321540191", "price": "0.18", "size": "177.77", "side": "BUY", "hash": "3e6ecad785f518f87a5b898c7f1cbad497aa8c7f", "best_bid": "0.9", "best_ask": "0.94"}, {"asset_id": "57073863691050176858693353000197608096498121614576538982509295418934497382921", "price": "0.82", "size": "177.77", "side": "SELL", "hash": "aee6083079fcc7fdc8a4633544c2abe91c68a1c6", "best_bid": "0.06", "best_ask": "0.1"}], "timestamp": "1769384358761", "event_type": "price_change"}}
{"_local_timestamp": "2026-01-25T23:39:19.233743+00:00", "data": {"market": "0xb5fb3fd4dbc7fdc70e3666ed4193e3171ecc257dcd43e01b36dbd4efa01d777e", "price_changes": [{"asset_id": "8786566038915392046446786086504563210301842572125705765733243466035321540191", "price": "0.18", "size": "182.77", "side": "BUY", "hash": "775252058261d4c593fe3afeecbd1cad5a760228", "best_bid": "0.9", "best_ask": "0.94"}, {"asset_id": "57073863691050176858693353000197608096498121614576538982509295418934497382921", "price": "0.82", "size": "182.77", "side": "SELL", "hash": "5aa868cb4e099904999e2bb1ad6520076b63fc84", "best_bid": "0.06", "best_ask": "0.1"}], "timestamp": "1769384359162", "event_type": "price_change"}}
{"_local_timestamp": "2026-01-25T23:39:21.257513+00:00", "data": {"market": "0xb5fb3fd4dbc7fdc70e3666ed4193e3171ecc257dcd43e01b36dbd4efa01d777e", "price_changes": [{"asset_id": "8786566038915392046446786086504563210301842572125705765733243466035321540191", "price": "0.18", "size": "177.77", "side": "BUY", "hash": "fc9e565166213837d37da20a22bba85f3ce502a2", "best_bid": "0.9", "best_ask": "0.94"}, {"asset_id": "57073863691050176858693353000197608096498121614576538982509295418934497382921", "price": "0.82", "size": "177.77", "side": "SELL", "hash": "eecfc883778e2a87706c5d640b1cc834ca207af8", "best_bid": "0.06", "best_ask": "0.1"}], "timestamp": "1769384361184", "event_type": "price_change"}}
{"_local_timestamp": "2026-01-25T23:39:21.576761+00:00", "data": {"market": "0xb5fb3fd4dbc7fdc70e3666ed4193e3171ecc257dcd43e01b36dbd4efa01d777e", "price_changes": [{"asset_id": "8786566038915392046446786086504563210301842572125705765733243466035321540191", "price": "0.18", "size": "182.77", "side": "BUY", "hash": "a1b21f05562c37b76aa1d29dc8a4e9f2c3b61e91", "best_bid": "0.9", "best_ask": "0.94"}, {"asset_id": "57073863691050176858693353000197608096498121614576538982509295418934497382921", "price": "0.82", "size": "182.77", "side": "SELL", "hash": "59e51cf24f068bd4cd86169139ced8b126f1e362", "best_bid": "0.06", "best_ask": "0.1"}], "timestamp": "1769384361504", "event_type": "price_change"}}
{"_local_timestamp": "2026-01-25T23:39:23.090384+00:00", "data": {"market": "0xb5fb3fd4dbc7fdc70e3666ed4193e3171ecc257dcd43e01b36dbd4efa01d777e", "price_changes": [{"asset_id": "8786566038915392046446786086504563210301842572125705765733243466035321540191", "price": "0.18", "size": "177.77", "side": "BUY", "hash": "f32cf24768ea48df8017a003b8dc5814f5f0ee96", "best_bid": "0.9", "best_ask": "0.94"}, {"asset_id": "57073863691050176858693353000197608096498121614576538982509295418934497382921", "price": "0.82", "size": "177.77", "side": "SELL", "hash": "ea5fdf1db19b9545853e03e4c77b33031db7bb66", "best_bid": "0.06", "best_ask": "0.1"}], "timestamp": "1769384362945", "event_type": "price_change"}}
{"_local_timestamp": "2026-01-25T23:39:23.389114+00:00", "data": {"market": "0xb5fb3fd4dbc7fdc70e3666ed4193e3171ecc257dcd43e01b36dbd4efa01d777e", "price_changes": [{"asset_id": "8786566038915392046446786086504563210301842572125705765733243466035321540191", "price": "0.18", "size": "182.77", "side": "BUY", "hash": "8e42d8b441858107fd29b9c11e90c19c01308f09", "best_bid": "0.9", "best_ask": "0.94"}, {"asset_id": "57073863691050176858693353000197608096498121614576538982509295418934497382921", "price": "0.82", "size": "182.77", "side": "SELL", "hash": "bb2c53992c313808802e0a0c132bad2a9874df9d", "best_bid": "0.06", "best_ask": "0.1"}], "timestamp": "1769384363303", "event_type": "price_change"}}
{"_local_timestamp": "2026-01-25T23:39:25.318845+00:00", "data": {"market": "0xb5fb3fd4dbc7fdc70e3666ed4193e3171ecc257dcd43e01b36dbd4efa01d777e", "price_changes": [{"asset_id": "8786566038915392046446786086504563210301842572125705765733243466035321540191", "price": "0.18", "size": "177.77", "side": "BUY", "hash": "3be863771b3d7fcd8b0456ddb24b7bd9feac1f10", "best_bid": "0.9", "best_ask": "0.94"}, {"asset_id": "57073863691050176858693353000197608096498121614576538982509295418934497382921", "price": "0.82", "size": "177.77", "side": "SELL", "hash": "a7b2a9a8cc9b7de8fb43307cb19c44bd22f335ab", "best_bid": "0.06", "best_ask": "0.1"}], "timestamp": "1769384365248", "event_type": "price_change"}}
{"_local_timestamp": "2026-01-25T23:39:26.253377+00:00", "data": {"market": "0xb5fb3fd4dbc7fdc70e3666ed4193e3171ecc257dcd43e01b36dbd4efa01d777e", "price_changes": [{"asset_id": "8786566038915392046446786086504563210301842572125705765733243466035321540191", "price": "0.18", "size": "182.77", "side": "BUY", "hash": "5b06fd87b7c839708ccdad65722a48f118031bf9", "best_bid": "0.9", "best_ask": "0.94"}, {"asset_id": "57073863691050176858693353000197608096498121614576538982509295418934497382921", "price": "0.82", "size": "182.77", "side": "SELL", "hash": "ca73562761dbff2058f549c698c856ef30bacf43", "best_bid": "0.06", "best_ask": "0.1"}], "timestamp": "1769384366178", "event_type": "price_change"}}
{"_local_timestamp": "2026-01-25T23:39:28.321326+00:00", "data": {"market": "0xb5fb3fd4dbc7fdc70e3666ed4193e3171ecc257dcd43e01b36dbd4efa01d777e", "price_changes": [{"asset_id": "8786566038915392046446786086504563210301842572125705765733243466035321540191", "price": "0.18", "size": "177.77", "side": "BUY", "hash": "b4830a6b4f694fd92340353e49c340c522192f2c", "best_bid": "0.9", "best_ask": "0.94"}, {"asset_id": "57073863691050176858693353000197608096498121614576538982509295418934497382921", "price": "0.82", "size": "177.77", "side": "SELL", "hash": "b067f39e408b2f8d9cd40f8c360cee37c6b9f015", "best_bid": "0.06", "best_ask": "0.1"}], "timestamp": "1769384368248", "event_type": "price_change"}}
{"_local_timestamp": "2026-01-25T23:39:28.694343+00:00", "data": {"market": "0xb5fb3fd4dbc7fdc70e3666ed4193e3171ecc257dcd43e01b36dbd4efa01d777e", "price_changes": [{"asset_id": "8786566038915392046446786086504563210301842572125705765733243466035321540191", "price": "0.18", "size": "182.77", "side": "BUY", "hash": "27ea850cff0fbced1cc4b2317fd28deaa71508eb", "best_bid": "0.9", "best_ask": "0.94"}, {"asset_id": "57073863691050176858693353000197608096498121614576538982509295418934497382921", "price": "0.82", "size": "182.77", "side": "SELL", "hash": "ccf2120a7c7091ef33ffb7a159480d41e7843dfb", "best_bid": "0.06", "best_ask": "0.1"}], "timestamp": "1769384368612", "event_type": "price_change"}}
{"_local_timestamp": "2026-01-25T23:39:31.651509+00:00", "data": {"market": "0xb5fb3fd4dbc7fdc70e3666ed4193e3171ecc257dcd43e01b36dbd4efa01d777e", "price_changes": [{"asset_id": "8786566038915392046446786086504563210301842572125705765733243466035321540191", "price": "0.18", "size": "177.77", "side": "BUY", "hash": "4ed21faa9b78d534656306716e9cec6b3a10ff21", "best_bid": "0.9", "best_ask": "0.94"}, {"asset_id": "57073863691050176858693353000197608096498121614576538982509295418934497382921", "price": "0.82", "size": "177.77", "side": "SELL", "hash": "782103606c5cc50fb818f1306c2e28ed02bd2f8f", "best_bid": "0.06", "best_ask": "0.1"}], "timestamp": "1769384371577", "event_type": "price_change"}}
{"_local_timestamp": "2026-01-25T23:39:32.067480+00:00", "data": {"market": "0xb5fb3fd4dbc7fdc70e3666ed4193e3171ecc257dcd43e01b36dbd4efa01d777e", "price_changes": [{"asset_id": "8786566038915392046446786086504563210301842572125705765733243466035321540191", "price": "0.18", "size": "182.77", "side": "BUY", "hash": "3dff456aeaf2718a0d279c23b419907e630c5128", "best_bid": "0.9", "best_ask": "0.94"}, {"asset_id": "57073863691050176858693353000197608096498121614576538982509295418934497382921", "price": "0.82", "size": "182.77", "side": "SELL", "hash": "95a9adc9d4fa67838e10819d33d9cdb5e56fc45a", "best_bid": "0.06", "best_ask": "0.1"}], "timestamp": "1769384371994", "event_type": "price_change"}}
{"_local_timestamp": "2026-01-25T23:39:34.274109+00:00", "data": {"market": "0xb5fb3fd4dbc7fdc70e3666ed4193e3171ecc257dcd43e01b36dbd4efa01d777e", "price_changes": [{"asset_id": "8786566038915392046446786086504563210301842572125705765733243466035321540191", "price": "0.18", "size": "177.77", "side": "BUY", "hash": "55d154cbe52879266d5a29d8a36d9381d673b441", "best_bid": "0.9", "best_ask": "0.94"}, {"asset_id": "57073863691050176858693353000197608096498121614576538982509295418934497382921", "price": "0.82", "size": "177.77", "side": "SELL", "hash": "f9625782918b690856d8a70be37a672d32605915", "best_bid": "0.06", "best_ask": "0.1"}], "timestamp": "1769384374196", "event_type": "price_change"}}
{"_local_timestamp": "2026-01-25T23:39:34.583601+00:00", "data": {"market": "0xb5fb3fd4dbc7fdc70e3666ed4193e3171ecc257dcd43e01b36dbd4efa01d777e", "price_changes": [{"asset_id": "8786566038915392046446786086504563210301842572125705765733243466035321540191", "price": "0.18", "size": "182.77", "side": "BUY", "hash": "7f64213bb88205a28a8ba505cc467b02c8a0a58f", "best_bid": "0.9", "best_ask": "0.94"}, {"asset_id": "57073863691050176858693353000197608096498121614576538982509295418934497382921", "price": "0.82", "size": "182.77", "side": "SELL", "hash": "b23b7c844940cebb63177eaff0f48f65c9b8de27", "best_bid": "0.06", "best_ask": "0.1"}], "timestamp": "1769384374512", "event_type": "price_change"}}
{"_local_timestamp": "2026-01-25T23:39:36.454623+00:00", "data": {"market": "0xb5fb3fd4dbc7fdc70e3666ed4193e3171ecc257dcd43e01b36dbd4efa01d777e", "price_changes": [{"asset_id": "8786566038915392046446786086504563210301842572125705765733243466035321540191", "price": "0.18", "size": "177.77", "side": "BUY", "hash": "226c87dd74e43b28151df4367859dae2344b810a", "best_bid": "0.9", "best_ask": "0.94"}, {"asset_id": "57073863691050176858693353000197608096498121614576538982509295418934497382921", "price": "0.82", "size": "177.77", "side": "SELL", "hash": "690a033425bd4398d462c048ba9b0dcd0b1abbd6", "best_bid": "0.06", "best_ask": "0.1"}], "timestamp": "1769384376387", "event_type": "price_change"}}
{"_local_timestamp": "2026-01-25T23:39:36.675874+00:00", "data": {"market": "0xb5fb3fd4dbc7fdc70e3666ed4193e3171ecc257dcd43e01b36dbd4efa01d777e", "price_changes": [{"asset_id": "8786566038915392046446786086504563210301842572125705765733243466035321540191", "price": "0.18", "size": "182.77", "side": "BUY", "hash": "8707d4e11a3a82849caf1bc91deb524ac533a2a0", "best_bid": "0.9", "best_ask": "0.94"}, {"asset_id": "57073863691050176858693353000197608096498121614576538982509295418934497382921", "price": "0.82", "size": "182.77", "side": "SELL", "hash": "b02f2889de37b04bba220dea768918459276665e", "best_bid": "0.06", "best_ask": "0.1"}], "timestamp": "1769384376603", "event_type": "price_change"}}
{"_local_timestamp": "2026-01-25T23:39:38.834874+00:00", "data": {"market": "0xb5fb3fd4dbc7fdc70e3666ed4193e3171ecc257dcd43e01b36dbd4efa01d777e", "price_changes": [{"asset_id": "8786566038915392046446786086504563210301842572125705765733243466035321540191", "price": "0.18", "size": "177.77", "side": "BUY", "hash": "5b85c964925b48ef5f95a11a660821a8f95e649a", "best_bid": "0.9", "best_ask": "0.94"}, {"asset_id": "57073863691050176858693353000197608096498121614576538982509295418934497382921", "price": "0.82", "size": "177.77", "side": "SELL", "hash": "ffe7d10e7c7ba0c69f79fee95f305cc9b017ddb1", "best_bid": "0.06", "best_ask": "0.1"}], "timestamp": "1769384378767", "event_type": "price_change"}}
{"_local_timestamp": "2026-01-25T23:39:39.206545+00:00", "data": {"market": "0xb5fb3fd4dbc7fdc70e3666ed4193e3171ecc257dcd43e01b36dbd4efa01d777e", "price_changes": [{"asset_id": "8786566038915392046446786086504563210301842572125705765733243466035321540191", "price": "0.18", "size": "182.77", "side": "BUY", "hash": "29cfed385b79285a725d000471a1bdbce627581c", "best_bid": "0.9", "best_ask": "0.94"}, {"asset_id": "57073863691050176858693353000197608096498121614576538982509295418934497382921", "price": "0.82", "size": "182.77", "side": "SELL", "hash": "6182c981a00dd91fc902eff7f6517c0b4bff45b3", "best_bid": "0.06", "best_ask": "0.1"}], "timestamp": "1769384379135", "event_type": "price_change"}}
{"_local_timestamp": "2026-01-25T23:39:41.410910+00:00", "data": {"market": "0xb5fb3fd4dbc7fdc70e3666ed4193e3171ecc257dcd43e01b36dbd4efa01d777e", "price_changes": [{"asset_id": "8786566038915392046446786086504563210301842572125705765733243466035321540191", "price": "0.18", "size": "177.77", "side": "BUY", "hash": "f820743bd0b938b0d2dcfaac402dc676ffc45627", "best_bid": "0.9", "best_ask": "0.94"}, {"asset_id": "57073863691050176858693353000197608096498121614576538982509295418934497382921", "price": "0.82", "size": "177.77", "side": "SELL", "hash": "e2d6e7d6db315742662245ca933d58f51d7beb7c", "best_bid": "0.06", "best_ask": "0.1"}], "timestamp": "1769384381338", "event_type": "price_change"}}
{"_local_timestamp": "2026-01-25T23:39:41.699296+00:00", "data": {"market": "0xb5fb3fd4dbc7fdc70e3666ed4193e3171ecc257dcd43e01b36dbd4efa01d777e", "price_changes": [{"asset_id": "8786566038915392046446786086504563210301842572125705765733243466035321540191", "price": "0.18", "size": "182.77", "side": "BUY", "hash": "5dff78ff15e285deefb56b5a1ebfafbc92f16259", "best_bid": "0.9", "best_ask": "0.94"}, {"asset_id": "57073863691050176858693353000197608096498121614576538982509295418934497382921", "price": "0.82", "size": "182.77", "side": "SELL", "hash": "fc9d7c0b59d60fb15649c7eb32fb2559ad223d33", "best_bid": "0.06", "best_ask": "0.1"}], "timestamp": "1769384381630", "event_type": "price_change"}}
{"_local_timestamp": "2026-01-25T23:39:43.438888+00:00", "data": {"market": "0xb5fb3fd4dbc7fdc70e3666ed4193e3171ecc257dcd43e01b36dbd4efa01d777e", "price_changes": [{"asset_id": "8786566038915392046446786086504563210301842572125705765733243466035321540191", "price": "0.18", "size": "177.77", "side": "BUY", "hash": "5ddcb41902fcd7acb4f9e892c28e8988cd7cac48", "best_bid": "0.9", "best_ask": "0.94"}, {"asset_id": "57073863691050176858693353000197608096498121614576538982509295418934497382921", "price": "0.82", "size": "177.77", "side": "SELL", "hash": "244d610581ba017a8e6c825637fe98864d349b2d", "best_bid": "0.06", "best_ask": "0.1"}], "timestamp": "1769384383367", "event_type": "price_change"}}
{"_local_timestamp": "2026-01-25T23:39:43.837410+00:00", "data": {"market": "0xb5fb3fd4dbc7fdc70e3666ed4193e3171ecc257dcd43e01b36dbd4efa01d777e", "price_changes": [{"asset_id": "8786566038915392046446786086504563210301842572125705765733243466035321540191", "price": "0.18", "size": "182.77", "side": "BUY", "hash": "5268761ab930e6780c5cd1b2bf0e77bf18f1d57f", "best_bid": "0.9", "best_ask": "0.94"}, {"asset_id": "57073863691050176858693353000197608096498121614576538982509295418934497382921", "price": "0.82", "size": "182.77", "side": "SELL", "hash": "052d19d265b1485f60dc07cb1f4c809a264246bd", "best_bid": "0.06", "best_ask": "0.1"}], "timestamp": "1769384383768", "event_type": "price_change"}}
{"_local_timestamp": "2026-01-25T23:39:46.306380+00:00", "data": {"market": "0xb5fb3fd4dbc7fdc70e3666ed4193e3171ecc257dcd43e01b36dbd4efa01d777e", "price_changes": [{"asset_id": "8786566038915392046446786086504563210301842572125705765733243466035321540191", "price": "0.18", "size": "177.77", "side": "BUY", "hash": "168668486ed508468d97f4790162fb6a98bb71af", "best_bid": "0.9", "best_ask": "0.94"}, {"asset_id": "57073863691050176858693353000197608096498121614576538982509295418934497382921", "price": "0.82", "size": "177.77", "side": "SELL", "hash": "321cb79d697708ee5771f5548c9ce5806c0872f8", "best_bid": "0.06", "best_ask": "0.1"}], "timestamp": "1769384386208", "event_type": "price_change"}}
{"_local_timestamp": "2026-01-25T23:39:46.666175+00:00", "data": {"market": "0xb5fb3fd4dbc7fdc70e3666ed4193e3171ecc257dcd43e01b36dbd4efa01d777e", "price_changes": [{"asset_id": "8786566038915392046446786086504563210301842572125705765733243466035321540191", "price": "0.18", "size": "182.77", "side": "BUY", "hash": "a09fa99acb4f61315724c94679fc5169c1c569b5", "best_bid": "0.9", "best_ask": "0.94"}, {"asset_id": "57073863691050176858693353000197608096498121614576538982509295418934497382921", "price": "0.82", "size": "182.77", "side": "SELL", "hash": "531050356f1331336e11da6e4dd76e016c46e5d6", "best_bid": "0.06", "best_ask": "0.1"}], "timestamp": "1769384386574", "event_type": "price_change"}}
{"_local_timestamp": "2026-01-25T23:39:48.911145+00:00", "data": {"market": "0xb5fb3fd4dbc7fdc70e3666ed4193e3171ecc257dcd43e01b36dbd4efa01d777e", "price_changes": [{"asset_id": "8786566038915392046446786086504563210301842572125705765733243466035321540191", "price": "0.18", "size": "177.77", "side": "BUY", "hash": "94150398ee1532b13dafcfc32537dbfe6cd9190b", "best_bid": "0.9", "best_ask": "0.94"}, {"asset_id": "57073863691050176858693353000197608096498121614576538982509295418934497382921", "price": "0.82", "size": "177.77", "side": "SELL", "hash": "6dd9ae1c55f65ccb35bac3d18867759f34fc2e4d", "best_bid": "0.06", "best_ask": "0.1"}], "timestamp": "1769384388840", "event_type": "price_change"}}
{"_local_timestamp": "2026-01-25T23:39:49.213105+00:00", "data": {"market": "0xb5fb3fd4dbc7fdc70e3666ed4193e3171ecc257dcd43e01b36dbd4efa01d777e", "price_changes": [{"asset_id": "8786566038915392046446786086504563210301842572125705765733243466035321540191", "price": "0.18", "size": "182.77", "side": "BUY", "hash": "faa24b6c5b01f056e294ae519638a30aef2c3dd1", "best_bid": "0.9", "best_ask": "0.94"}, {"asset_id": "57073863691050176858693353000197608096498121614576538982509295418934497382921", "price": "0.82", "size": "182.77", "side": "SELL", "hash": "e42d893844cc0afc956cbf2a67b6e6c21dfefdfb", "best_bid": "0.06", "best_ask": "0.1"}], "timestamp": "1769384389143", "event_type": "price_change"}}
{"_local_timestamp": "2026-01-25T23:39:51.779107+00:00", "data": {"market": "0xb5fb3fd4dbc7fdc70e3666ed4193e3171ecc257dcd43e01b36dbd4efa01d777e", "price_changes": [{"asset_id": "8786566038915392046446786086504563210301842572125705765733243466035321540191", "price": "0.18", "size": "177.77", "side": "BUY", "hash": "fb140986a7dc66a09d70fa93e984d506a2809c76", "best_bid": "0.9", "best_ask": "0.94"}, {"asset_id": "57073863691050176858693353000197608096498121614576538982509295418934497382921", "price": "0.82", "size": "177.77", "side": "SELL", "hash": "98ffbab07fec667b77300b956e8e98ae5564e759", "best_bid": "0.06", "best_ask": "0.1"}], "timestamp": "1769384391697", "event_type": "price_change"}}
{"_local_timestamp": "2026-01-25T23:39:52.135280+00:00", "data": {"market": "0xb5fb3fd4dbc7fdc70e3666ed4193e3171ecc257dcd43e01b36dbd4efa01d777e", "price_changes": [{"asset_id": "8786566038915392046446786086504563210301842572125705765733243466035321540191", "price": "0.18", "size": "182.77", "side": "BUY", "hash": "f45dea3ea67c9e2e17af80b01ae9ae101008d556", "best_bid": "0.9", "best_ask": "0.94"}, {"asset_id": "57073863691050176858693353000197608096498121614576538982509295418934497382921", "price": "0.82", "size": "182.77", "side": "SELL", "hash": "6dfab408f74c4b5c99fde1bb0ad0bb8e3c5d9c81", "best_bid": "0.06", "best_ask": "0.1"}], "timestamp": "1769384392068", "event_type": "price_change"}}
{"_local_timestamp": "2026-01-25T23:39:54.003348+00:00", "data": {"market": "0xb5fb3fd4dbc7fdc70e3666ed4193e3171ecc257dcd43e01b36dbd4efa01d777e", "price_changes": [{"asset_id": "8786566038915392046446786086504563210301842572125705765733243466035321540191", "price": "0.18", "size": "177.77", "side": "BUY", "hash": "721878773dac27ffeb2f6c7635453ddbb4c9858a", "best_bid": "0.9", "best_ask": "0.94"}, {"asset_id": "57073863691050176858693353000197608096498121614576538982509295418934497382921", "price": "0.82", "size": "177.77", "side": "SELL", "hash": "3301e36065f8d2a37045aaf4280d35105b1a289f", "best_bid": "0.06", "best_ask": "0.1"}], "timestamp": "1769384393922", "event_type": "price_change"}}
{"_local_timestamp": "2026-01-25T23:39:54.806351+00:00", "data": {"market": "0xb5fb3fd4dbc7fdc70e3666ed4193e3171ecc257dcd43e01b36dbd4efa01d777e", "price_changes": [{"asset_id": "8786566038915392046446786086504563210301842572125705765733243466035321540191", "price": "0.18", "size": "182.77", "side": "BUY", "hash": "beb5b739210a7acaa2bf2db10411ca7856a611a4", "best_bid": "0.9", "best_ask": "0.94"}, {"asset_id": "57073863691050176858693353000197608096498121614576538982509295418934497382921", "price": "0.82", "size": "182.77", "side": "SELL", "hash": "9687f13176d331575c3ef4dfb2df06076e4354eb", "best_bid": "0.06", "best_ask": "0.1"}], "timestamp": "1769384394704", "event_type": "price_change"}}
{"_local_timestamp": "2026-01-25T23:39:57.239672+00:00", "data": {"market": "0xb5fb3fd4dbc7fdc70e3666ed4193e3171ecc257dcd43e01b36dbd4efa01d777e", "price_changes": [{"asset_id": "8786566038915392046446786086504563210301842572125705765733243466035321540191", "price": "0.18", "size": "177.77", "side": "BUY", "hash": "434ffff0dae9cd525f087eb4f2e444a67139e50e", "best_bid": "0.9", "best_ask": "0.94"}, {"asset_id": "57073863691050176858693353000197608096498121614576538982509295418934497382921", "price": "0.82", "size": "177.77", "side": "SELL", "hash": "9473fa3a697aa96e310da5ec5261326ebd56b813", "best_bid": "0.06", "best_ask": "0.1"}], "timestamp": "1769384397173", "event_type": "price_change"}}
{"_local_timestamp": "2026-01-25T23:39:57.621158+00:00", "data": {"market": "0xb5fb3fd4dbc7fdc70e3666ed4193e3171ecc257dcd43e01b36dbd4efa01d777e", "price_changes": [{"asset_id": "8786566038915392046446786086504563210301842572125705765733243466035321540191", "price": "0.18", "size": "182.77", "side": "BUY", "hash": "c20439f7a849741e27a8798c9dd3905d11a31c09", "best_bid": "0.9", "best_ask": "0.94"}, {"asset_id": "57073863691050176858693353000197608096498121614576538982509295418934497382921", "price": "0.82", "size": "182.77", "side": "SELL", "hash": "9c98b5b18487bad075824ecb522c351e31508102", "best_bid": "0.06", "best_ask": "0.1"}], "timestamp": "1769384397551", "event_type": "price_change"}}
{"_local_timestamp": "2026-01-25T23:40:00.627758+00:00", "data": {"market": "0xb5fb3fd4dbc7fdc70e3666ed4193e3171ecc257dcd43e01b36dbd4efa01d777e", "price_changes": [{"asset_id": "8786566038915392046446786086504563210301842572125705765733243466035321540191", "price": "0.18", "size": "177.77", "side": "BUY", "hash": "3927409699afab5de1682ac9807be42933f30cef", "best_bid": "0.9", "best_ask": "0.94"}, {"asset_id": "57073863691050176858693353000197608096498121614576538982509295418934497382921", "price": "0.82", "size": "177.77", "side": "SELL", "hash": "44a0d789f899312d4adf51d6202188492d28c37b", "best_bid": "0.06", "best_ask": "0.1"}], "timestamp": "1769384400556", "event_type": "price_change"}}
{"_local_timestamp": "2026-01-25T23:40:00.971494+00:00", "data": {"market": "0xb5fb3fd4dbc7fdc70e3666ed4193e3171ecc257dcd43e01b36dbd4efa01d777e", "price_changes": [{"asset_id": "8786566038915392046446786086504563210301842572125705765733243466035321540191", "price": "0.18", "size": "182.77", "side": "BUY", "hash": "039827ffa1456e83cbef18b52286ad8368df9f2c", "best_bid": "0.9", "best_ask": "0.94"}, {"asset_id": "57073863691050176858693353000197608096498121614576538982509295418934497382921", "price": "0.82", "size": "182.77", "side": "SELL", "hash": "8a3aa15091951a2fba55930f84375d10483ae836", "best_bid": "0.06", "best_ask": "0.1"}], "timestamp": "1769384400899", "event_type": "price_change"}}
{"_local_timestamp": "2026-01-25T23:40:01.011692+00:00", "data": {"market": "0xb5fb3fd4dbc7fdc70e3666ed4193e3171ecc257dcd43e01b36dbd4efa01d777e", "price_changes": [{"asset_id": "8786566038915392046446786086504563210301842572125705765733243466035321540191", "price": "0.18", "size": "187.77", "side": "BUY", "hash": "8d7a177738696654976ae39e4feb01e482824544", "best_bid": "0.9", "best_ask": "0.94"}, {"asset_id": "57073863691050176858693353000197608096498121614576538982509295418934497382921", "price": "0.82", "size": "187.77", "side": "SELL", "hash": "65369e78b472b4cfa1c40488ae8ce179e36e9f11", "best_bid": "0.06", "best_ask": "0.1"}], "timestamp": "1769384400937", "event_type": "price_change"}}
{"_local_timestamp": "2026-01-25T23:40:02.788316+00:00", "data": {"market": "0xb5fb3fd4dbc7fdc70e3666ed4193e3171ecc257dcd43e01b36dbd4efa01d777e", "price_changes": [{"asset_id": "8786566038915392046446786086504563210301842572125705765733243466035321540191", "price": "0.18", "size": "182.77", "side": "BUY", "hash": "4213db6ae344d2434566445fbf4b03c1fd5aa951", "best_bid": "0.9", "best_ask": "0.94"}, {"asset_id": "57073863691050176858693353000197608096498121614576538982509295418934497382921", "price": "0.82", "size": "182.77", "side": "SELL", "hash": "95f0682348fb400a27a6563fa8366d6d8f565300", "best_bid": "0.06", "best_ask": "0.1"}], "timestamp": "1769384402718", "event_type": "price_change"}}
{"_local_timestamp": "2026-01-25T23:40:05.179789+00:00", "data": {"market": "0xb5fb3fd4dbc7fdc70e3666ed4193e3171ecc257dcd43e01b36dbd4efa01d777e", "price_changes": [{"asset_id": "8786566038915392046446786086504563210301842572125705765733243466035321540191", "price": "0.18", "size": "177.77", "side": "BUY", "hash": "6026ed4981f576e84088c248bd66d2adef5df3df", "best_bid": "0.9", "best_ask": "0.94"}, {"asset_id": "57073863691050176858693353000197608096498121614576538982509295418934497382921", "price": "0.82", "size": "177.77", "side": "SELL", "hash": "d813404f40ed97046b75690fe158479332b60463", "best_bid": "0.06", "best_ask": "0.1"}], "timestamp": "1769384405108", "event_type": "price_change"}}
{"_local_timestamp": "2026-01-25T23:40:05.460384+00:00", "data": {"market": "0xb5fb3fd4dbc7fdc70e3666ed4193e3171ecc257dcd43e01b36dbd4efa01d777e", "price_changes": [{"asset_id": "8786566038915392046446786086504563210301842572125705765733243466035321540191", "price": "0.18", "size": "182.77", "side": "BUY", "hash": "d7ca96656dc34d74ca63c31ea2916bc97ee482f8", "best_bid": "0.9", "best_ask": "0.94"}, {"asset_id": "57073863691050176858693353000197608096498121614576538982509295418934497382921", "price": "0.82", "size": "182.77", "side": "SELL", "hash": "52a82cf6de05d4e9bfd0b6e1f05afa2d1c35f4ce", "best_bid": "0.06", "best_ask": "0.1"}], "timestamp": "1769384405390", "event_type": "price_change"}}
{"_local_timestamp": "2026-01-25T23:40:07.171676+00:00", "data": {"market": "0xb5fb3fd4dbc7fdc70e3666ed4193e3171ecc257dcd43e01b36dbd4efa01d777e", "price_changes": [{"asset_id": "8786566038915392046446786086504563210301842572125705765733243466035321540191", "price": "0.18", "size": "177.77", "side": "BUY", "hash": "0e6684e158b64a8a1f8b4025a035098adb4ebab0", "best_bid": "0.9", "best_ask": "0.94"}, {"asset_id": "57073863691050176858693353000197608096498121614576538982509295418934497382921", "price": "0.82", "size": "177.77", "side": "SELL", "hash": "9c2bdb9d7f75f3960837576aaf8f51bb7ce03b78", "best_bid": "0.06", "best_ask": "0.1"}], "timestamp": "1769384407091", "event_type": "price_change"}}
{"_local_timestamp": "2026-01-25T23:40:07.850211+00:00", "data": {"market": "0xb5fb3fd4dbc7fdc70e3666ed4193e3171ecc257dcd43e01b36dbd4efa01d777e", "price_changes": [{"asset_id": "8786566038915392046446786086504563210301842572125705765733243466035321540191", "price": "0.18", "size": "182.77", "side": "BUY", "hash": "a1cb9184af78d8effe242f2c8881595c507f2d21", "best_bid": "0.9", "best_ask": "0.94"}, {"asset_id": "57073863691050176858693353000197608096498121614576538982509295418934497382921", "price": "0.82", "size": "182.77", "side": "SELL", "hash": "a662094ef0dd44b45d87084d1059af23f8d31222", "best_bid": "0.06", "best_ask": "0.1"}], "timestamp": "1769384407768", "event_type": "price_change"}}
{"_local_timestamp": "2026-01-25T23:40:09.908298+00:00", "data": {"market": "0xb5fb3fd4dbc7fdc70e3666ed4193e3171ecc257dcd43e01b36dbd4efa01d777e", "price_changes": [{"asset_id": "8786566038915392046446786086504563210301842572125705765733243466035321540191", "price": "0.18", "size": "177.77", "side": "BUY", "hash": "7052ed3d09e392bd072047070aca84fb0450b98d", "best_bid": "0.9", "best_ask": "0.94"}, {"asset_id": "57073863691050176858693353000197608096498121614576538982509295418934497382921", "price": "0.82", "size": "177.77", "side": "SELL", "hash": "1d53e7a8bb6dd728922f4efda64a6b5827c43abd", "best_bid": "0.06", "best_ask": "0.1"}], "timestamp": "1769384409840", "event_type": "price_change"}}
{"_local_timestamp": "2026-01-25T23:40:10.343232+00:00", "data": {"market": "0xb5fb3fd4dbc7fdc70e3666ed4193e3171ecc257dcd43e01b36dbd4efa01d777e", "price_changes": [{"asset_id": "8786566038915392046446786086504563210301842572125705765733243466035321540191", "price": "0.18", "size": "182.77", "side": "BUY", "hash": "3fcc4e0ba61e2584a9013e4f317c3cf2fc52ba84", "best_bid": "0.9", "best_ask": "0.94"}, {"asset_id": "57073863691050176858693353000197608096498121614576538982509295418934497382921", "price": "0.82", "size": "182.77", "side": "SELL", "hash": "67ae08402f4ea7fdda4859e1a1c90b3ab77e5977", "best_bid": "0.06", "best_ask": "0.1"}], "timestamp": "1769384410276", "event_type": "price_change"}}
{"_local_timestamp": "2026-01-25T23:40:11.748461+00:00", "data": {"market": "0xb5fb3fd4dbc7fdc70e3666ed4193e3171ecc257dcd43e01b36dbd4efa01d777e", "price_changes": [{"asset_id": "8786566038915392046446786086504563210301842572125705765733243466035321540191", "price": "0.18", "size": "177.77", "side": "BUY", "hash": "e6e4fd25fecef281c909955d58d6b2e8b19b9c73", "best_bid": "0.9", "best_ask": "0.94"}, {"asset_id": "57073863691050176858693353000197608096498121614576538982509295418934497382921", "price": "0.82", "size": "177.77", "side": "SELL", "hash": "55d54d6cc92401aa8509a1f425b9a575d440b4f7", "best_bid": "0.06", "best_ask": "0.1"}], "timestamp": "1769384411671", "event_type": "price_change"}}
{"_local_timestamp": "2026-01-25T23:40:12.056938+00:00", "data": {"market": "0xb5fb3fd4dbc7fdc70e3666ed4193e3171ecc257dcd43e01b36dbd4efa01d777e", "price_changes": [{"asset_id": "8786566038915392046446786086504563210301842572125705765733243466035321540191", "price": "0.18", "size": "182.77", "side": "BUY", "hash": "587eab44b28beb7116f0837ff639862541a47ac7", "best_bid": "0.9", "best_ask": "0.94"}, {"asset_id": "57073863691050176858693353000197608096498121614576538982509295418934497382921", "price": "0.82", "size": "182.77", "side": "SELL", "hash": "ca1ffbed27d831f8437ba2b32745ba910b1609f2", "best_bid": "0.06", "best_ask": "0.1"}], "timestamp": "1769384411985", "event_type": "price_change"}}
{"_local_timestamp": "2026-01-25T23:40:14.281077+00:00", "data": {"market": "0xb5fb3fd4dbc7fdc70e3666ed4193e3171ecc257dcd43e01b36dbd4efa01d777e", "price_changes": [{"asset_id": "8786566038915392046446786086504563210301842572125705765733243466035321540191", "price": "0.18", "size": "177.77", "side": "BUY", "hash": "75b703b0673ce1e88a32633a43d0bc48275664ca", "best_bid": "0.9", "best_ask": "0.94"}, {"asset_id": "57073863691050176858693353000197608096498121614576538982509295418934497382921", "price": "0.82", "size": "177.77", "side": "SELL", "hash": "abf20c806ab8ac9a9e19d0d17af8883090b84f44", "best_bid": "0.06", "best_ask": "0.1"}], "timestamp": "1769384414214", "event_type": "price_change"}}
{"_local_timestamp": "2026-01-25T23:40:14.564932+00:00", "data": {"market": "0xb5fb3fd4dbc7fdc70e3666ed4193e3171ecc257dcd43e01b36dbd4efa01d777e", "price_changes": [{"asset_id": "8786566038915392046446786086504563210301842572125705765733243466035321540191", "price": "0.18", "size": "182.77", "side": "BUY", "hash": "c690a4049c0c71a8df1335cdb9438b56a7448c7b", "best_bid": "0.9", "best_ask": "0.94"}, {"asset_id": "57073863691050176858693353000197608096498121614576538982509295418934497382921", "price": "0.82", "size": "182.77", "side": "SELL", "hash": "c5c0c2d9484ddfd5910a4a6e05d3b0d9ed4ed444", "best_bid": "0.06", "best_ask": "0.1"}], "timestamp": "1769384414498", "event_type": "price_change"}}
