{"_local_timestamp": "2026-01-25T23:40:55.346664+00:00", "data": [{"market": "0xefc69f5f48827e331957acbcc2339eb3b15e27e32453b8e6f29b5de67474c986", "asset_id": "19619851020796345517172409566066997550761738782112746767326655871669350897686", "timestamp": "1769384453498", "hash": "3642225580c2332763927eedf241255265f71e95", "bids": [{"price": "0.01", "size": "12114.83"}, {"price": "0.02", "size": "3250"}, {"price": "0.03", "size": "7300"}, {"price": "0.04", "size": "1005.93"}, {"price": "0.06", "size": "600"}, {"price": "0.09", "size": "1077.77"}, {"price": "0.1", "size": "6.14"}, {"price": "0.11", "size": "290.9"}, {"price": "0.12", "size": "100"}, {"price": "0.13", "size": "1555"}, {"price": "0.14", "size": "200"}, {"price": "0.15", "size": "3123"}, {"price": "0.17", "size": "402.94"}, {"price": "0.19", "size": "300"}, {"price": "0.2", "size": "320"}, {"price": "0.21", "size": "1010"}, {"price": "0.23", "size": "86.95"}, {"price": "0.25", "size": "645.73"}, {"price": "0.41", "size": "92.82"}, {"price": "0.42", "size": "127"}, {"price": "0.44", "size": "6"}, {"price": "0.46", "size": "87.26"}, {"price": "0.48", "size": "28.91"}, {"price": "0.49", "size": "27"}, {"price": "0.5", "size": "1784.14"}, {"price": "0.52", "size": "810"}, {"price": "0.53", "size": "100"}, {"price": "0.55", "size": "15"}], "asks": [{"price": "0.99", "size": "12505.51"}, {"price": "0.98", "size": "3505.56"}, {"price": "0.97", "size": "300"}, {"price": "0.96", "size": "4457.08"}, {"price": "0.95", "size": "250"}, {"price": "0.93", "size": "485.71"}, {"price": "0.92", "size": "1325"}, {"price": "0.91", "size": "355.55"}, {"price": "0.9", "size": "5.5"}, {"price": "0.89", "size": "1708.54"}, {"price": "0.88", "size": "250"}, {"price": "0.87", "size": "3780"}, {"price": "0.86", "size": "185.71"}, {"price": "0.84", "size": "150"}, {"price": "0.83", "size": "250"}, {"price": "0.82", "size": "611.11"}, {"price": "0.81", "size": "10"}, {"price": "0.79", "size": "6"}, {"price": "0.75", "size": "3.19"}, {"price": "0.74", "size": "12.88"}, {"price": "0.73", "size": "28.25"}, {"price": "0.58", "size": "765.52"}, {"price": "0.57", "size": "809"}, {"price": "0.56", "size": "57.02"}], "event_type": "book", "last_trade_price": "0.560"}, {"market": "0xefc69f5f48827e331957acbcc2339eb3b15e27e32453b8e6f29b5de67474c986", "asset_id": "108798918614128027361814219314538484133284583608074596451665946577336361445917", "timestamp": "1769384453498", "hash": "46c0e2c6babfcb9a05f2e249afa9b61a5ed71ded", "bids": [{"price": "0.01", "size": "12505.51"}, {"price": "0.02", "size": "3505.56"}, {"price": "0.03", "size": "300"}, {"price": "0.04", "size": "4457.08"}, {"price": "0.05", "size": "250"}, {"price": "0.07", "size": "485.71"}, {"price": "0.08", "size": "1325"}, {"price": "0.09", "size": "355.55"}, {"price": "0.1", "size": "5.5"}, {"price": "0.11", "size": "1708.54"}, {"price": "0.12", "size": "250"}, {"price": "0.13", "size": "3780"}, {"price": "0.14", "size": "185.71"}, {"price": "0.16", "size": "150"}, {"price": "0.17", "size": "250"}, {"price": "0.18", "size": "611.11"}, {"price": "0.19", "size": "10"}, {"price": "0.21", "size": "6"}, {"price": "0.25", "size": "3.19"}, {"price": "0.26", "size": "12.88"}, {"price": "0.27", "size": "28.25"}, {"price": "0.42", "size": "765.52"}, {"price": "0.43", "size": "809"}, {"price": "0.44", "size": "57.02"}], "asks": [{"price": "0.99", "size": "12114.83"}, {"price": "0.98", "size": "3250"}, {"price": "0.97", "size": "7300"}, {"price": "0.96", "size": "1005.93"}, {"price": "0.94", "size": "600"}, {"price": "0.91", "size": "1077.77"}, {"price": "0.9", "size": "6.14"}, {"price": "0.89", "size": "290.9"}, {"price": "0.88", "size": "100"}, {"price": "0.87", "size": "1555"}, {"price": "0.86", "size": "200"}, {"price": "0.85", "size": "3123"}, {"price": "0.83", "size": "402.94"}, {"price": "0.81", "size": "300"}, {"price": "0.8", "size": "320"}, {"price": "0.79", "size": "1010"}, {"price": "0.77", "size": "86.95"}, {"price": "0.75", "size": "645.73"}, {"price": "0.59", "size": "92.82"}, {"price": "0.58", "size": "127"}, {"price": "0.56", "size": "6"}, {"price": "0.54", "size": "87.26"}, {"price": "0.52", "size": "28.91"}, {"price": "0.51", "size": "27"}, {"price": "0.5", "size": "1784.14"}, {"price": "0.48", "size": "810"}, {"price": "0.47", "size": "100"}, {"price": "0.45", "size": "15"}], "event_type": "book", "last_trade_price": "0.560"}]}
{"_local_timestamp": "2026-01-25T23:41:06.279275+00:00", "data": {"market": "0xefc69f5f48827e331957acbcc2339eb3b15e27e32453b8e6f29b5de67474c986", "price_changes": [{"asset_id": "108798918614128027361814219314538484133284583608074596451665946577336361445917", "price": "0.42", "size": "665.52", "side": "BUY", "hash": "15816e9fa481fbdd4823988a6de97f80f51f3e66", "best_bid": "0.44", "best_ask": "0.45"}, {"asset_id": "19619851020796345517172409566066997550761738782112746767326655871669350897686", "price": "0.58", "size": "665.52", "side": "SELL", "hash": "7e417656100db992ac1ad9d1e94518bf8bf83837", "best_bid": "0.55", "best_ask": "0.56"}], "timestamp": "1769384466195", "event_type": "price_change"}}
{"_local_timestamp": "2026-01-25T23:41:06.319558+00:00", "data": {"market": "0xefc69f5f48827e331957acbcc2339eb3b15e27e32453b8e6f29b5de67474c986", "price_changes": [{"asset_id": "19619851020796345517172409566066997550761738782112746767326655871669350897686", "price": "0.52", "size": "710", "side": "BUY", "hash": "9d18a9d4640f1f6b986e93d186bcf18d9bd923cd", "best_bid": "0.55", "best_ask": "0.56"}, {"asset_id": "108798918614128027361814219314538484133284583608074596451665946577336361445917", "price": "0.48", "size": "710", "side": "SELL", "hash": "8ef7c38d1adbfc0af8e535a0498da4ea7c91e773", "best_bid": "0.44", "best_ask": "0.45"}], "timestamp": "1769384466199", "event_type": "price_change"}}
{"_local_timestamp": "2026-01-25T23:41:09.637831+00:00", "data": {"market": "0xefc69f5f48827e331957acbcc2339eb3b15e27e32453b8e6f29b5de67474c986", "price_changes": [{"asset_id": "19619851020796345517172409566066997550761738782112746767326655871669350897686", "price": "0.25", "size": "545.73", "side": "BUY", "hash": "7efb3cdb747c3e55d7c08510b3f27bfd021d077a", "best_bid": "0.55", "best_ask": "0.56"}, {"asset_id": "108798918614128027361814219314538484133284583608074596451665946577336361445917", "price": "0.75", "size": "545.73", "side": "SELL", "hash": "b844d5ca7100f4654b41df27733ad284eb6ec241", "best_bid": "0.44", "best_ask": "0.45"}], "timestamp": "1769384469552", "event_type": "price_change"}}
{"_local_timestamp": "2026-01-25T23:41:09.640064+00:00", "data": {"market": "0xefc69f5f48827e331957acbcc2339eb3b15e27e32453b8e6f29b5de67474c986", "price_changes": [{"asset_id": "19619851020796345517172409566066997550761738782112746767326655871669350897686", "price": "0.2", "size": "170", "side": "BUY", "hash": "7efb3cdb747c3e55d7c08510b3f27bfd021d077a", "best_bid": "0.55", "best_ask": "0.56"}, {"asset_id": "108798918614128027361814219314538484133284583608074596451665946577336361445917", "price": "0.8", "size": "170", "side": "SELL", "hash": "b844d5ca7100f4654b41df27733ad284eb6ec241", "best_bid": "0.44", "best_ask": "0.45"}], "timestamp": "1769384469552", "event_type": "price_change"}}
{"_local_timestamp": "2026-01-25T23:41:09.893167+00:00", "data": {"market": "0xefc69f5f48827e331957acbcc2339eb3b15e27e32453b8e6f29b5de67474c986", "price_changes": [{"asset_id": "19619851020796345517172409566066997550761738782112746767326655871669350897686", "price": "0.21", "size": "1110", "side": "BUY", "hash": "eadb6113853c5ec5c58aa5a03148d95fc9393f00", "best_bid": "0.55", "best_ask": "0.56"}, {"asset_id": "108798918614128027361814219314538484133284583608074596451665946577336361445917", "price": "0.79", "size": "1110", "side": "SELL", "hash": "767f62584776130a94c2b43a324e2375739f0da9", "best_bid": "0.44", "best_ask": "0.45"}], "timestamp": "1769384469804", "event_type": "price_change"}}
{"_local_timestamp": "2026-01-25T23:41:09.911938+00:00", "data": {"market": "0xefc69f5f48827e331957acbcc2339eb3b15e27e32453b8e6f29b5de67474c986", "price_changes": [{"asset_id": "19619851020796345517172409566066997550761738782112746767326655871669350897686", "price": "0.17", "size": "552.94", "side": "BUY", "hash": "f7f5993ea44ac846a1361a7c3cf4aca3db8d6182", "best_bid": "0.55", "best_ask": "0.56"}, {"asset_id": "108798918614128027361814219314538484133284583608074596451665946577336361445917", "price": "0.83", "size": "552.94", "side": "SELL", "hash": "d1a78d357a1743fae4143572f38f97af97bfb57e", "best_bid": "0.44", "best_ask": "0.45"}], "timestamp": "1769384469808", "event_type": "price_change"}}
{"_local_timestamp": "2026-01-25T23:41:12.921082+00:00", "data": {"market": "0xefc69f5f48827e331957acbcc2339eb3b15e27e32453b8e6f29b5de67474c986", "price_changes": [{"asset_id": "108798918614128027361814219314538484133284583608074596451665946577336361445917", "price": "0.42", "size": "765.52", "side": "BUY", "hash": "d866cf9609cf4a2cab3d8fc70b95a71873251144", "best_bid": "0.44", "best_ask": "0.45"}, {"asset_id": "19619851020796345517172409566066997550761738782112746767326655871669350897686", "price": "0.58", "size": "765.52", "side": "SELL", "hash": "41076aeb95aedae2134c87478b39d486941ac43d", "best_bid": "0.55", "best_ask": "0.56"}], "timestamp": "1769384472854", "event_type": "price_change"}}
{"_local_timestamp": "2026-01-25T23:41:14.707565+00:00", "data": {"market": "0xefc69f5f48827e331957acbcc2339eb3b15e27e32453b8e6f29b5de67474c986", "price_changes": [{"asset_id": "19619851020796345517172409566066997550761738782112746767326655871669350897686", "price": "0.15", "size": "325", "side": "BUY", "hash": "efc36769633fa85cffe03115848426d78317347d", "best_bid": "0.55", "best_ask": "0.56"}, {"asset_id": "108798918614128027361814219314538484133284583608074596451665946577336361445917", "price": "0.85", "size": "325", "side": "SELL", "hash": "cb3bf1b4b0b2694ecb96a7b161d46dd572d2787b", "best_bid": "0.44", "best_ask": "0.45"}], "timestamp": "1769384474538", "event_type": "price_change"}}
{"_local_timestamp": "2026-01-25T23:41:18.803100+00:00", "data": {"market": "0xefc69f5f48827e331957acbcc2339eb3b15e27e32453b8e6f29b5de67474c986", "price_changes": [{"asset_id": "19619851020796345517172409566066997550761738782112746767326655871669350897686", "price": "0.52", "size": "810", "side": "BUY", "hash": "9d0e5c9ee40b69260c783ce83a4fa55211113c9b", "best_bid": "0.55", "best_ask": "0.56"}, {"asset_id": "108798918614128027361814219314538484133284583608074596451665946577336361445917", "price": "0.48", "size": "810", "side": "SELL", "hash": "b95cc6026a41f5936c2c87631798e62892d336a1", "best_bid": "0.44", "best_ask": "0.45"}], "timestamp": "1769384478709", "event_type": "price_change"}}
{"_local_timestamp": "2026-01-25T23:41:19.521581+00:00", "data": {"market": "0xefc69f5f48827e331957acbcc2339eb3b15e27e32453b8e6f29b5de67474c986", "price_changes": [{"asset_id": "19619851020796345517172409566066997550761738782112746767326655871669350897686", "price": "0.52", "size": "1010", "side": "BUY", "hash": "485fb66c4f59882d4b1c6f58d91753a257ca54e3", "best_bid": "0.55", "best_ask": "0.56"}, {"asset_id": "108798918614128027361814219314538484133284583608074596451665946577336361445917", "price": "0.48", "size": "1010", "side": "SELL", "hash": "85e2b40f9decbc543c419a9222e4e7fa32ca9d10", "best_bid": "0.44", "best_ask": "0.45"}], "timestamp": "1769384479455", "event_type": "price_change"}}
{"_local_timestamp": "2026-01-25T23:41:19.530140+00:00", "data": {"market": "0xefc69f5f48827e331957acbcc2339eb3b15e27e32453b8e6f29b5de67474c986", "price_changes": [{"asset_id": "108798918614128027361814219314538484133284583608074596451665946577336361445917", "price": "0.42", "size": "965.51", "side": "BUY", "hash": "0986a9c229188d02f42b532c3c3b562cb1838eaa", "best_bid": "0.44", "best_ask": "0.45"}, {"asset_id": "19619851020796345517172409566066997550761738782112746767326655871669350897686", "price": "0.58", "size": "965.51", "side": "SELL", "hash": "169a9c5ae6e86564b18405a85ea43c0245543fca", "best_bid": "0.55", "best_ask": "0.56"}], "timestamp": "1769384479456", "event_type": "price_change"}}
{"_local_timestamp": "2026-01-25T23:41:19.589521+00:00", "data": {"market": "0xefc69f5f48827e331957acbcc2339eb3b15e27e32453b8e6f29b5de67474c986", "price_changes": [{"asset_id": "19619851020796345517172409566066997550761738782112746767326655871669350897686", "price": "0.21", "size": "100", "side": "BUY", "hash": "42631ff297340d025579acd6aa3f8a9ea56b0889", "best_bid": "0.55", "best_ask": "0.56"}, {"asset_id": "108798918614128027361814219314538484133284583608074596451665946577336361445917", "price": "0.79", "size": "100", "side": "SELL", "hash": "af19d6f2ea05b5dd1732ed75a24be7b0b8c23d28", "best_bid": "0.44", "best_ask": "0.45"}], "timestamp": "1769384479522", "event_type": "price_change"}}
{"_local_timestamp": "2026-01-25T23:41:19.647160+00:00", "data": {"market": "0xefc69f5f48827e331957acbcc2339eb3b15e27e32453b8e6f29b5de67474c986", "price_changes": [{"asset_id": "19619851020796345517172409566066997550761738782112746767326655871669350897686", "price": "0.2", "size": "1230", "side": "BUY", "hash": "37bda38b6b078cf5d6694b729efdbec6b5adac14", "best_bid": "0.55", "best_ask": "0.56"}, {"asset_id": "108798918614128027361814219314538484133284583608074596451665946577336361445917", "price": "0.8", "size": "1230", "side": "SELL", "hash": "0e2b3f20a5ad2d244694e278d3a994dce7fff18c", "best_bid": "0.44", "best_ask": "0.45"}], "timestamp": "1769384479582", "event_type": "price_change"}}
{"_local_timestamp": "2026-01-25T23:41:39.372188+00:00", "data": {"market": "0xefc69f5f48827e331957acbcc2339eb3b15e27e32453b8e6f29b5de67474c986", "price_changes": [{"asset_id": "19619851020796345517172409566066997550761738782112746767326655871669350897686", "price": "0.15", "size": "275", "side": "BUY", "hash": "df660a84fac2403feda13d25fdd276a2d7a1e14f", "best_bid": "0.55", "best_ask": "0.56"}, {"asset_id": "108798918614128027361814219314538484133284583608074596451665946577336361445917", "price": "0.85", "size": "275", "side": "SELL", "hash": "1aee93b3af142c0a214eca16258f8177ae44b318", "best_bid": "0.44", "best_ask": "0.45"}], "timestamp": "1769384499290", "event_type": "price_change"}}
{"_local_timestamp": "2026-01-25T23:41:39.681632+00:00", "data": {"market": "0xefc69f5f48827e331957acbcc2339eb3b15e27e32453b8e6f29b5de67474c986", "price_changes": [{"asset_id": "19619851020796345517172409566066997550761738782112746767326655871669350897686", "price": "0.2", "size": "1280", "side": "BUY", "hash": "421c31f00f2a638e81f0a8c7e474bb77475f7cc2", "best_bid": "0.55", "best_ask": "0.56"}, {"asset_id": "108798918614128027361814219314538484133284583608074596451665946577336361445917", "price": "0.8", "size": "1280", "side": "SELL", "hash": "6c274fffdf8e4baa45737d969e5ccaf0283f4ab4", "best_bid": "0.44", "best_ask": "0.45"}], "timestamp": "1769384499596", "event_type": "price_change"}}
{"_local_timestamp": "2026-01-25T23:41:48.092076+00:00", "data": {"market": "0xefc69f5f48827e331957acbcc2339eb3b15e27e32453b8e6f29b5de67474c986", "price_changes": [{"asset_id": "19619851020796345517172409566066997550761738782112746767326655871669350897686", "price": "0.42", "size": "115", "side": "BUY", "hash": "09e6e45f6344fe3e575a0919129c4bd732959c63", "best_bid": "0.55", "best_ask": "0.56"}, {"asset_id": "108798918614128027361814219314538484133284583608074596451665946577336361445917", "price": "0.58", "size": "115", "side": "SELL", "hash": "4bf7637ef2c348008ffbbcd57678ff0067c81dcf", "best_bid": "0.44", "best_ask": "0.45"}], "timestamp": "1769384508000", "event_type": "price_change"}}
{"_local_timestamp": "2026-01-25T23:41:49.479434+00:00", "data": {"market": "0xefc69f5f48827e331957acbcc2339eb3b15e27e32453b8e6f29b5de67474c986", "price_changes": [{"asset_id": "19619851020796345517172409566066997550761738782112746767326655871669350897686", "price": "0.15", "size": "50", "side": "BUY", "hash": "e13b5400bfea8ec221e26b377c0211f50545e977", "best_bid": "0.55", "best_ask": "0.56"}, {"asset_id": "108798918614128027361814219314538484133284583608074596451665946577336361445917", "price": "0.85", "size": "50", "side": "SELL", "hash": "9daf8aa90b97f22af3ae5cfd205349c99795b8e0", "best_bid": "0.44", "best_ask": "0.45"}], "timestamp": "1769384509398", "event_type": "price_change"}}
{"_local_timestamp": "2026-01-25T23:41:49.766345+00:00", "data": {"market": "0xefc69f5f48827e331957acbcc2339eb3b15e27e32453b8e6f29b5de67474c986", "price_changes": [{"asset_id": "19619851020796345517172409566066997550761738782112746767326655871669350897686", "price": "0.13", "size": "1780", "side": "BUY", "hash": "5542cac9f4ac80b5616a1e8386d088be300835d3", "best_bid": "0.55", "best_ask": "0.56"}, {"asset_id": "108798918614128027361814219314538484133284583608074596451665946577336361445917", "price": "0.87", "size": "1780", "side": "SELL", "hash": "0ea20baeb9db2a4d402fa8469356dc7b6e3e4e8c", "best_bid": "0.44", "best_ask": "0.45"}], "timestamp": "1769384509662", "event_type": "price_change"}}
{"_local_timestamp": "2026-01-25T23:41:50.956824+00:00", "data": {"market": "0xefc69f5f48827e331957acbcc2339eb3b15e27e32453b8e6f29b5de67474c986", "price_changes": [{"asset_id": "19619851020796345517172409566066997550761738782112746767326655871669350897686", "price": "0.17", "size": "402.94", "side": "BUY", "hash": "9ba45f69c30aa64a7e2e957323e5d98213e1eb4f", "best_bid": "0.55", "best_ask": "0.56"}, {"asset_id": "108798918614128027361814219314538484133284583608074596451665946577336361445917", "price": "0.83", "size": "402.94", "side": "SELL", "hash": "d8dabc7711415b0fa08e3f59706b4ab14cc0ff92", "best_bid": "0.44", "best_ask": "0.45"}], "timestamp": "1769384510760", "event_type": "price_change"}}
{"_local_timestamp": "2026-01-25T23:41:52.774420+00:00", "data": {"market": "0xefc69f5f48827e331957acbcc2339eb3b15e27e32453b8e6f29b5de67474c986", "price_changes": [{"asset_id": "19619851020796345517172409566066997550761738782112746767326655871669350897686", "price": "0.2", "size": "1430", "side": "BUY", "hash": "eee45e32e668923d63bd0b5b17f023e4fc342b25", "best_bid": "0.55", "best_ask": "0.56"}, {"asset_id": "108798918614128027361814219314538484133284583608074596451665946577336361445917", "price": "0.8", "size": "1430", "side": "SELL", "hash": "aaa22fc26dc0022b6636a1f2360d99dd08be6263", "best_bid": "0.44", "best_ask": "0.45"}], "timestamp": "1769384511782", "event_type": "price_change"}}
{"_local_timestamp": "2026-01-25T23:41:52.774957+00:00", "data": {"market": "0xefc69f5f48827e331957acbcc2339eb3b15e27e32453b8e6f29b5de67474c986", "price_changes": [{"asset_id": "19619851020796345517172409566066997550761738782112746767326655871669350897686", "price": "0.42", "size": "127", "side": "BUY", "hash": "e1dc49079bd4aac1548a2d1c220ea4b18b4b00ab", "best_bid": "0.55", "best_ask": "0.56"}, {"asset_id": "108798918614128027361814219314538484133284583608074596451665946577336361445917", "price": "0.58", "size": "127", "side": "SELL", "hash": "2f23f2af407dca0804b6f2752ce25a6c66c4f870", "best_bid": "0.44", "best_ask": "0.45"}], "timestamp": "1769384512653", "event_type": "price_change"}}
{"_local_timestamp": "2026-01-25T23:41:57.034417+00:00", "data": {"market": "0xefc69f5f48827e331957acbcc2339eb3b15e27e32453b8e6f29b5de67474c986", "price_changes": [{"asset_id": "19619851020796345517172409566066997550761738782112746767326655871669350897686", "price": "0.2", "size": "370", "side": "BUY", "hash": "af918361549301045b686bd6d7658e3c98b1539d", "best_bid": "0.55", "best_ask": "0.56"}, {"asset_id": "108798918614128027361814219314538484133284583608074596451665946577336361445917", "price": "0.8", "size": "370", "side": "SELL", "hash": "e1c0d6d29cd21fbf4fe067f4be4d3fb74389cc0d", "best_bid": "0.44", "best_ask": "0.45"}], "timestamp": "1769384516912", "event_type": "price_change"}}
{"_local_timestamp": "2026-01-25T23:41:57.040657+00:00", "data": {"market": "0xefc69f5f48827e331957acbcc2339eb3b15e27e32453b8e6f29b5de67474c986", "price_changes": [{"asset_id": "19619851020796345517172409566066997550761738782112746767326655871669350897686", "price": "0.21", "size": "1110", "side": "BUY", "hash": "6657841fa47a02b4f7b49e688b4d61cb926ab275", "best_bid": "0.55", "best_ask": "0.56"}, {"asset_id": "108798918614128027361814219314538484133284583608074596451665946577336361445917", "price": "0.79", "size": "1110", "side": "SELL", "hash": "c31d5ff2d2bbb6878f1825b3f30324fc389afd72", "best_bid": "0.44", "best_ask": "0.45"}], "timestamp": "1769384516960", "event_type": "price_change"}}
{"_local_timestamp": "2026-01-25T23:42:16.921854+00:00", "data": {"market": "0xefc69f5f48827e331957acbcc2339eb3b15e27e32453b8e6f29b5de67474c986", "price_changes": [{"asset_id": "19619851020796345517172409566066997550761738782112746767326655871669350897686", "price": "0.16", "size": "2624", "side": "BUY", "hash": "a5ac7674c633483100274f36f6be6f17c1488344", "best_bid": "0.55", "best_ask": "0.56"}, {"asset_id": "108798918614128027361814219314538484133284583608074596451665946577336361445917", "price": "0.84", "size": "2624", "side": "SELL", "hash": "6f656683006399a35424b3e6c649af10d6103601", "best_bid": "0.44", "best_ask": "0.45"}], "timestamp": "1769384536829", "event_type": "price_change"}}
{"_local_timestamp": "2026-01-25T23:42:22.360517+00:00", "data": {"market": "0xefc69f5f48827e331957acbcc2339eb3b15e27e32453b8e6f29b5de67474c986", "price_changes": [{"asset_id": "19619851020796345517172409566066997550761738782112746767326655871669350897686", "price": "0.15", "size": "0", "side": "BUY", "hash": "c45057d9e2344cb9be37051c40b042c5998bb648", "best_bid": "0.55", "best_ask": "0.56"}, {"asset_id": "108798918614128027361814219314538484133284583608074596451665946577336361445917", "price": "0.85", "size": "0", "side": "SELL", "hash": "d9a39807c4704d4a3de2c30f06c9e73bc6079abc", "best_bid": "0.44", "best_ask": "0.45"}], "timestamp": "1769384542226", "event_type": "price_change"}}
{"_local_timestamp": "2026-01-25T23:42:22.658484+00:00", "data": {"market": "0xefc69f5f48827e331957acbcc2339eb3b15e27e32453b8e6f29b5de67474c986", "price_changes": [{"asset_id": "19619851020796345517172409566066997550761738782112746767326655871669350897686", "price": "0.2", "size": "420", "side": "BUY", "hash": "655b4f42161a2799e7264b2494cce8fd69bf240f", "best_bid": "0.55", "best_ask": "0.56"}, {"asset_id": "108798918614128027361814219314538484133284583608074596451665946577336361445917", "price": "0.8", "size": "420", "side": "SELL", "hash": "8df1e6dca7ddbf5ed448577bcbea5775a69fa3b1", "best_bid": "0.44", "best_ask": "0.45"}], "timestamp": "1769384542531", "event_type": "price_change"}}
{"_local_timestamp": "2026-01-25T23:42:24.749957+00:00", "data": {"market": "0xefc69f5f48827e331957acbcc2339eb3b15e27e32453b8e6f29b5de67474c986", "price_changes": [{"asset_id": "19619851020796345517172409566066997550761738782112746767326655871669350897686", "price": "0.17", "size": "302.94", "side": "BUY", "hash": "a866639369af2b65f11efec54b9f628777ec2713", "best_bid": "0.55", "best_ask": "0.56"}, {"asset_id": "108798918614128027361814219314538484133284583608074596451665946577336361445917", "price": "0.83", "size": "302.94", "side": "SELL", "hash": "d800160d8fd9c9f626efbb2acf0d31bf0d7b9f35", "best_bid": "0.44", "best_ask": "0.45"}], "timestamp": "1769384544491", "event_type": "price_change"}}
{"_local_timestamp": "2026-01-25T23:42:24.750429+00:00", "data": {"market": "0xefc69f5f48827e331957acbcc2339eb3b15e27e32453b8e6f29b5de67474c986", "price_changes": [{"asset_id": "19619851020796345517172409566066997550761738782112746767326655871669350897686", "price": "0.13", "size": "1655", "side": "BUY", "hash": "a866639369af2b65f11efec54b9f628777ec2713", "best_bid": "0.55", "best_ask": "0.56"}, {"asset_id": "108798918614128027361814219314538484133284583608074596451665946577336361445917", "price": "0.87", "size": "1655", "side": "SELL", "hash": "d800160d8fd9c9f626efbb2acf0d31bf0d7b9f35", "best_bid": "0.44", "best_ask": "0.45"}], "timestamp": "1769384544491", "event_type": "price_change"}}
{"_local_timestamp": "2026-01-25T23:42:25.046734+00:00", "data": {"market": "0xefc69f5f48827e331957acbcc2339eb3b15e27e32453b8e6f29b5de67474c986", "price_changes": [{"asset_id": "19619851020796345517172409566066997550761738782112746767326655871669350897686", "price": "0.21", "size": "1010", "side": "BUY", "hash": "e9425e70515f025ac311da78f969760572a13f74", "best_bid": "0.55", "best_ask": "0.56"}, {"asset_id": "108798918614128027361814219314538484133284583608074596451665946577336361445917", "price": "0.79", "size": "1010", "side": "SELL", "hash": "be35754aeab63f34527a20cac9a6eb7818e9cb9f", "best_bid": "0.44", "best_ask": "0.45"}], "timestamp": "1769384544891", "event_type": "price_change"}}
{"_local_timestamp": "2026-01-25T23:42:25.047341+00:00", "data": {"market": "0xefc69f5f48827e331957acbcc2339eb3b15e27e32453b8e6f29b5de67474c986", "price_changes": [{"asset_id": "19619851020796345517172409566066997550761738782112746767326655871669350897686", "price": "0.17", "size": "152.94", "side": "BUY", "hash": "e9425e70515f025ac311da78f969760572a13f74", "best_bid": "0.55", "best_ask": "0.56"}, {"asset_id": "108798918614128027361814219314538484133284583608074596451665946577336361445917", "price": "0.83", "size": "152.94", "side": "SELL", "hash": "be35754aeab63f34527a20cac9a6eb7818e9cb9f", "best_bid": "0.44", "best_ask": "0.45"}], "timestamp": "1769384544891", "event_type": "price_change"}}
{"_local_timestamp": "2026-01-25T23:42:25.237334+00:00", "data": {"market": "0xefc69f5f48827e331957acbcc2339eb3b15e27e32453b8e6f29b5de67474c986", "price_changes": [{"asset_id": "19619851020796345517172409566066997550761738782112746767326655871669350897686", "price": "0.2", "size": "520", "side": "BUY", "hash": "bc9adb635f3bff97e70de7e2be6e3d05cc3161fb", "best_bid": "0.55", "best_ask": "0.56"}, {"asset_id": "108798918614128027361814219314538484133284583608074596451665946577336361445917", "price": "0.8", "size": "520", "side": "SELL", "hash": "26b636ddc20320eec3cf45d4932173ca1be90cb5", "best_bid": "0.44", "best_ask": "0.45"}], "timestamp": "1769384545078", "event_type": "price_change"}}
{"_local_timestamp": "2026-01-25T23:42:25.237849+00:00", "data": {"market": "0xefc69f5f48827e331957acbcc2339eb3b15e27e32453b8e6f29b5de67474c986", "price_changes": [{"asset_id": "19619851020796345517172409566066997550761738782112746767326655871669350897686", "price": "0.21", "size": "1060", "side": "BUY", "hash": "91f123d24260a22b08499b1c56458d6b5e27ac30", "best_bid": "0.55", "best_ask": "0.56"}, {"asset_id": "108798918614128027361814219314538484133284583608074596451665946577336361445917", "price": "0.79", "size": "1060", "side": "SELL", "hash": "29e61217055c10b44f1b6b3610185467dfdc6bcc", "best_bid": "0.44", "best_ask": "0.45"}], "timestamp": "1769384545079", "event_type": "price_change"}}
{"_local_timestamp": "2026-01-25T23:42:25.239853+00:00", "data": {"market": "0xefc69f5f48827e331957acbcc2339eb3b15e27e32453b8e6f29b5de67474c986", "price_changes": [{"asset_id": "19619851020796345517172409566066997550761738782112746767326655871669350897686", "price": "0.15", "size": "125", "side": "BUY", "hash": "4c9a5b8930eea5925d2bb680432bdcc129faa01b", "best_bid": "0.55", "best_ask": "0.56"}, {"asset_id": "108798918614128027361814219314538484133284583608074596451665946577336361445917", "price": "0.85", "size": "125", "side": "SELL", "hash": "018b9bcf1941a5159a025a3268da36b47123cc1f", "best_bid": "0.44", "best_ask": "0.45"}], "timestamp": "1769384545080", "event_type": "price_change"}}
{"_local_timestamp": "2026-01-25T23:42:25.354377+00:00", "data": {"market": "0xefc69f5f48827e331957acbcc2339eb3b15e27e32453b8e6f29b5de67474c986", "price_changes": [{"asset_id": "19619851020796345517172409566066997550761738782112746767326655871669350897686", "price": "0.2", "size": "670", "side": "BUY", "hash": "99bce17b309ddbc6a44c0192e1c69892a1bb25d8", "best_bid": "0.55", "best_ask": "0.56"}, {"asset_id": "108798918614128027361814219314538484133284583608074596451665946577336361445917", "price": "0.8", "size": "670", "side": "SELL", "hash": "ceb8e2bb52b601b38b16bd4cd5d95705c3b8fbeb", "best_bid": "0.44", "best_ask": "0.45"}], "timestamp": "1769384545163", "event_type": "price_change"}}
{"_local_timestamp": "2026-01-25T23:42:25.364815+00:00", "data": {"market": "0xefc69f5f48827e331957acbcc2339eb3b15e27e32453b8e6f29b5de67474c986", "price_changes": [{"asset_id": "19619851020796345517172409566066997550761738782112746767326655871669350897686", "price": "0.25", "size": "645.73", "side": "BUY", "hash": "b6a87297f1ecd4c4d28fc6de85463279d1d43f14", "best_bid": "0.55", "best_ask": "0.56"}, {"asset_id": "108798918614128027361814219314538484133284583608074596451665946577336361445917", "price": "0.75", "size": "645.73", "side": "SELL", "hash": "f239f5f5d00d1e14ecb490f3fe6c6b3f29b7659b", "best_bid": "0.44", "best_ask": "0.45"}], "timestamp": "1769384545168", "event_type": "price_change"}}
{"_local_timestamp": "2026-01-25T23:42:26.667266+00:00", "data": {"market": "0xefc69f5f48827e331957acbcc2339eb3b15e27e32453b8e6f29b5de67474c986", "price_changes": [{"asset_id": "19619851020796345517172409566066997550761738782112746767326655871669350897686", "price": "0.2", "size": "620", "side": "BUY", "hash": "7c2dc73825e5830527162c68fbd653e1b1b518ca", "best_bid": "0.55", "best_ask": "0.56"}, {"asset_id": "108798918614128027361814219314538484133284583608074596451665946577336361445917", "price": "0.8", "size": "620", "side": "SELL", "hash": "47f477f1bc42ef31b5ad91991cd4eaa5dba0ec6b", "best_bid": "0.44", "best_ask": "0.45"}], "timestamp": "1769384546539", "event_type": "price_change"}}
{"_local_timestamp": "2026-01-25T23:42:26.956531+00:00", "data": {"market": "0xefc69f5f48827e331957acbcc2339eb3b15e27e32453b8e6f29b5de67474c986", "price_changes": [{"asset_id": "19619851020796345517172409566066997550761738782112746767326655871669350897686", "price": "0.13", "size": "1705", "side": "BUY", "hash": "8673c0f164c41f2111989d82fdc03247974d4561", "best_bid": "0.55", "best_ask": "0.56"}, {"asset_id": "108798918614128027361814219314538484133284583608074596451665946577336361445917", "price": "0.87", "size": "1705", "side": "SELL", "hash": "822253c84b99b5a23967938499008c4a1605e3ed", "best_bid": "0.44", "best_ask": "0.45"}], "timestamp": "1769384546823", "event_type": "price_change"}}
{"_local_timestamp": "2026-01-25T23:42:45.469481+00:00", "data": {"market": "0xefc69f5f48827e331957acbcc2339eb3b15e27e32453b8e6f29b5de67474c986", "price_changes": [{"asset_id": "19619851020796345517172409566066997550761738782112746767326655871669350897686", "price": "0.2", "size": "570", "side": "BUY", "hash": "5227a996f04a7474bdc750bfafc202bd4cb502ed", "best_bid": "0.55", "best_ask": "0.56"}, {"asset_id": "108798918614128027361814219314538484133284583608074596451665946577336361445917", "price": "0.8", "size": "570", "side": "SELL", "hash": "5b119208ffebffec46521eefe518c43c75b3da18", "best_bid": "0.44", "best_ask": "0.45"}], "timestamp": "1769384565223", "event_type": "price_change"}}
{"_local_timestamp": "2026-01-25T23:42:45.795796+00:00", "data": {"market": "0xefc69f5f48827e331957acbcc2339eb3b15e27e32453b8e6f29b5de67474c986", "price_changes": [{"asset_id": "19619851020796345517172409566066997550761738782112746767326655871669350897686", "price": "0.21", "size": "1110", "side": "BUY", "hash": "0c0d42640b0718306d33accda343ec1d1a22b5f0", "best_bid": "0.55", "best_ask": "0.56"}, {"asset_id": "108798918614128027361814219314538484133284583608074596451665946577336361445917", "price": "0.79", "size": "1110", "side": "SELL", "hash": "3f8640c3efed7d6b165b1fec630695e5f913cfb7", "best_bid": "0.44", "best_ask": "0.45"}], "timestamp": "1769384565613", "event_type": "price_change"}}
{"_local_timestamp": "2026-01-25T23:42:47.167382+00:00", "data": {"market": "0xefc69f5f48827e331957acbcc2339eb3b15e27e32453b8e6f29b5de67474c986", "price_changes": [{"asset_id": "19619851020796345517172409566066997550761738782112746767326655871669350897686", "price": "0.16", "size": "0", "side": "BUY", "hash": "4371b6e8912345a302f3a2706219ddeac8deee79", "best_bid": "0.55", "best_ask": "0.56"}, {"asset_id": "108798918614128027361814219314538484133284583608074596451665946577336361445917", "price": "0.84", "size": "0", "side": "SELL", "hash": "d51ba7914b5a23cf4ee6c53101c6c0122c3850ee", "best_bid": "0.44", "best_ask": "0.45"}], "timestamp": "1769384566994", "event_type": "price_change"}}
{"_local_timestamp": "2026-01-25T23:42:48.838119+00:00", "data": {"market": "0xefc69f5f48827e331957acbcc2339eb3b15e27e32453b8e6f29b5de67474c986", "price_changes": [{"asset_id": "19619851020796345517172409566066997550761738782112746767326655871669350897686", "price": "0.13", "size": "1655", "side": "BUY", "hash": "beb4a88a1d2a8b72078481373b253c64a03c3976", "best_bid": "0.55", "best_ask": "0.56"}, {"asset_id": "108798918614128027361814219314538484133284583608074596451665946577336361445917", "price": "0.87", "size": "1655", "side": "SELL", "hash": "992857e53a61d3dfe3ff2d5ace1ffc8a1139d51b", "best_bid": "0.44", "best_ask": "0.45"}], "timestamp": "1769384568708", "event_type": "price_change"}}
{"_local_timestamp": "2026-01-25T23:42:49.091918+00:00", "data": {"market": "0xefc69f5f48827e331957acbcc2339eb3b15e27e32453b8e6f29b5de67474c986", "price_changes": [{"asset_id": "19619851020796345517172409566066997550761738782112746767326655871669350897686", "price": "0.16", "size": "50", "side": "BUY", "hash": "eaac6dd9332ae95e46e1a0af4def9ff47ed4769f", "best_bid": "0.55", "best_ask": "0.56"}, {"asset_id": "108798918614128027361814219314538484133284583608074596451665946577336361445917", "price": "0.84", "size": "50", "side": "SELL", "hash": "0defea8ed32b2373b434817ec8728e1dbb98ec31", "best_bid": "0.44", "best_ask": "0.45"}], "timestamp": "1769384568968", "event_type": "price_change"}}
{"_local_timestamp": "2026-01-25T23:42:58.851398+00:00", "data": {"market": "0xefc69f5f48827e331957acbcc2339eb3b15e27e32453b8e6f29b5de67474c986", "price_changes": [{"asset_id": "19619851020796345517172409566066997550761738782112746767326655871669350897686", "price": "0.2", "size": "420", "side": "BUY", "hash": "aae16729596ba198b9042d8e2d66f4e6959c50e4", "best_bid": "0.55", "best_ask": "0.56"}, {"asset_id": "108798918614128027361814219314538484133284583608074596451665946577336361445917", "price": "0.8", "size": "420", "side": "SELL", "hash": "f3ae5273cc2490a89c783dfeca0b72c4ac3127ad", "best_bid": "0.44", "best_ask": "0.45"}], "timestamp": "1769384578723", "event_type": "price_change"}}
{"_local_timestamp": "2026-01-25T23:42:58.852039+00:00", "data": {"market": "0xefc69f5f48827e331957acbcc2339eb3b15e27e32453b8e6f29b5de67474c986", "price_changes": [{"asset_id": "19619851020796345517172409566066997550761738782112746767326655871669350897686", "price": "0.25", "size": "545.73", "side": "BUY", "hash": "aae16729596ba198b9042d8e2d66f4e6959c50e4", "best_bid": "0.55", "best_ask": "0.56"}, {"asset_id": "108798918614128027361814219314538484133284583608074596451665946577336361445917", "price": "0.75", "size": "545.73", "side": "SELL", "hash": "f3ae5273cc2490a89c783dfeca0b72c4ac3127ad", "best_bid": "0.44", "best_ask": "0.45"}], "timestamp": "1769384578723", "event_type": "price_change"}}
{"_local_timestamp": "2026-01-25T23:42:59.103843+00:00", "data": {"market": "0xefc69f5f48827e331957acbcc2339eb3b15e27e32453b8e6f29b5de67474c986", "price_changes": [{"asset_id": "19619851020796345517172409566066997550761738782112746767326655871669350897686", "price": "0.21", "size": "1210", "side": "BUY", "hash": "c5f2edb9ed974a4a7ce50e096e61679cf473cc55", "best_bid": "0.55", "best_ask": "0.56"}, {"asset_id": "108798918614128027361814219314538484133284583608074596451665946577336361445917", "price": "0.79", "size": "1210", "side": "SELL", "hash": "c27ac1837a4c05434d8248377b44e8c70c0bdf14", "best_bid": "0.44", "best_ask": "0.45"}], "timestamp": "1769384578976", "event_type": "price_change"}}
{"_local_timestamp": "2026-01-25T23:42:59.124719+00:00", "data": {"market": "0xefc69f5f48827e331957acbcc2339eb3b15e27e32453b8e6f29b5de67474c986", "price_changes": [{"asset_id": "19619851020796345517172409566066997550761738782112746767326655871669350897686", "price": "0.16", "size": "200", "side": "BUY", "hash": "77220bfad4d3125efdd8a19578cafe3018a197e0", "best_bid": "0.55", "best_ask": "0.56"}, {"asset_id": "108798918614128027361814219314538484133284583608074596451665946577336361445917", "price": "0.84", "size": "200", "side": "SELL", "hash": "002144550eace94775a222f17a80c343c4d0034f", "best_bid": "0.44", "best_ask": "0.45"}], "timestamp": "1769384578985", "event_type": "price_change"}}
{"_local_timestamp": "2026-01-25T23:43:09.127890+00:00", "data": {"market": "0xefc69f5f48827e331957acbcc2339eb3b15e27e32453b8e6f29b5de67474c986", "price_changes": [{"asset_id": "19619851020796345517172409566066997550761738782112746767326655871669350897686", "price": "0.2", "size": "370", "side": "BUY", "hash": "c59a8bd3e545d9b5f1a3a1afdb004b72b671d286", "best_bid": "0.55", "best_ask": "0.56"}, {"asset_id": "108798918614128027361814219314538484133284583608074596451665946577336361445917", "price": "0.8", "size": "370", "side": "SELL", "hash": "14078e457db62b539acdecf326fe80387fd2cdae", "best_bid": "0.44", "best_ask": "0.45"}], "timestamp": "1769384588985", "event_type": "price_change"}}
{"_local_timestamp": "2026-01-25T23:43:09.485290+00:00", "data": {"market": "0xefc69f5f48827e331957acbcc2339eb3b15e27e32453b8e6f29b5de67474c986", "price_changes": [{"asset_id": "19619851020796345517172409566066997550761738782112746767326655871669350897686", "price": "0.16", "size": "250", "side": "BUY", "hash": "67852e53e826d7fb10c040923bc8259da07ee6b4", "best_bid": "0.55", "best_ask": "0.56"}, {"asset_id": "108798918614128027361814219314538484133284583608074596451665946577336361445917", "price": "0.84", "size": "250", "side": "SELL", "hash": "2ca15add3d290278bc9e0e60cf479126035d28b4", "best_bid": "0.44", "best_ask": "0.45"}], "timestamp": "1769384589348", "event_type": "price_change"}}
{"_local_timestamp": "2026-01-25T23:43:11.832292+00:00", "data": {"market": "0xefc69f5f48827e331957acbcc2339eb3b15e27e32453b8e6f29b5de67474c986", "price_changes": [{"asset_id": "19619851020796345517172409566066997550761738782112746767326655871669350897686", "price": "0.16", "size": "200", "side": "BUY", "hash": "8072635531abe967b79fd0de9004b4dd9f958c4b", "best_bid": "0.55", "best_ask": "0.56"}, {"asset_id": "108798918614128027361814219314538484133284583608074596451665946577336361445917", "price": "0.84", "size": "200", "side": "SELL", "hash": "837b8935725483423b2f346db8ba4701f081594d", "best_bid": "0.44", "best_ask": "0.45"}], "timestamp": "1769384591691", "event_type": "price_change"}}
{"_local_timestamp": "2026-01-25T23:43:12.084138+00:00", "data": {"market": "0xefc69f5f48827e331957acbcc2339eb3b15e27e32453b8e6f29b5de67474c986", "price_changes": [{"asset_id": "19619851020796345517172409566066997550761738782112746767326655871669350897686", "price": "0.13", "size": "1705", "side": "BUY", "hash": "ecfc9198b3fc2607f725c03c53e51bd6eef26bd1", "best_bid": "0.55", "best_ask": "0.56"}, {"asset_id": "108798918614128027361814219314538484133284583608074596451665946577336361445917", "price": "0.87", "size": "1705", "side": "SELL", "hash": "2a19dbe7aa818c734ac9ce554b2e9729979c39ed", "best_bid": "0.44", "best_ask": "0.45"}], "timestamp": "1769384591949", "event_type": "price_change"}}
{"_local_timestamp": "2026-01-25T23:43:38.515603+00:00", "data": {"market": "0xefc69f5f48827e331957acbcc2339eb3b15e27e32453b8e6f29b5de67474c986", "price_changes": [{"asset_id": "19619851020796345517172409566066997550761738782112746767326655871669350897686", "price": "0.16", "size": "50", "side": "BUY", "hash": "580ef4c07feb658de9c2d93f1b2304f487aafb02", "best_bid": "0.55", "best_ask": "0.56"}, {"asset_id": "108798918614128027361814219314538484133284583608074596451665946577336361445917", "price": "0.84", "size": "50", "side": "SELL", "hash": "05abdab346934ae28b46fec029f238c7623c8460", "best_bid": "0.44", "best_ask": "0.45"}], "timestamp": "1769384618445", "event_type": "price_change"}}
{"_local_timestamp": "2026-01-25T23:43:38.799202+00:00", "data": {"market": "0xefc69f5f48827e331957acbcc2339eb3b15e27e32453b8e6f29b5de67474c986", "price_changes": [{"asset_id": "19619851020796345517172409566066997550761738782112746767326655871669350897686", "price": "0.2", "size": "520", "side": "BUY", "hash": "5dc851d75072c3baad82ff735d942de8ce1de2e7", "best_bid": "0.55", "best_ask": "0.56"}, {"asset_id": "108798918614128027361814219314538484133284583608074596451665946577336361445917", "price": "0.8", "size": "520", "side": "SELL", "hash": "2f01eea10adfec973c29603c58dd01bccdb652b6", "best_bid": "0.44", "best_ask": "0.45"}], "timestamp": "1769384618716", "event_type": "price_change"}}
{"_local_timestamp": "2026-01-25T23:43:52.479934+00:00", "data": {"market": "0xefc69f5f48827e331957acbcc2339eb3b15e27e32453b8e6f29b5de67474c986", "price_changes": [{"asset_id": "19619851020796345517172409566066997550761738782112746767326655871669350897686", "price": "0.16", "size": "0", "side": "BUY", "hash": "0833f6f54cf91d8c3973f34fc3a04e3c0632e23b", "best_bid": "0.55", "best_ask": "0.56"}, {"asset_id": "108798918614128027361814219314538484133284583608074596451665946577336361445917", "price": "0.84", "size": "0", "side": "SELL", "hash": "b622126cb0b6c45c7c9269b5aa3164616d22691c", "best_bid": "0.44", "best_ask": "0.45"}], "timestamp": "1769384632324", "event_type": "price_change"}}
{"_local_timestamp": "2026-01-25T23:43:52.780389+00:00", "data": {"market": "0xefc69f5f48827e331957acbcc2339eb3b15e27e32453b8e6f29b5de67474c986", "price_changes": [{"asset_id": "19619851020796345517172409566066997550761738782112746767326655871669350897686", "price": "0.13", "size": "1755", "side": "BUY", "hash": "8038c54598db0f6e0ae3f2fa56036b4f3bf39907", "best_bid": "0.55", "best_ask": "0.56"}, {"asset_id": "108798918614128027361814219314538484133284583608074596451665946577336361445917", "price": "0.87", "size": "1755", "side": "SELL", "hash": "6170fd3fc2e16aaaaf8f1a462717e28562693d0b", "best_bid": "0.44", "best_ask": "0.45"}], "timestamp": "1769384632638", "event_type": "price_change"}}
{"_local_timestamp": "2026-01-25T23:44:01.783907+00:00", "data": {"market": "0xefc69f5f48827e331957acbcc2339eb3b15e27e32453b8e6f29b5de67474c986", "price_changes": [{"asset_id": "19619851020796345517172409566066997550761738782112746767326655871669350897686", "price": "0.15", "size": "2923", "side": "BUY", "hash": "9dc757b69ce00a9e0dc988bb18fb34ea6c03a205", "best_bid": "0.55", "best_ask": "0.56"}, {"asset_id": "108798918614128027361814219314538484133284583608074596451665946577336361445917", "price": "0.85", "size": "2923", "side": "SELL", "hash": "9f1600bcaffbddc426943df1b887a5ee2a19e6ec", "best_bid": "0.44", "best_ask": "0.45"}], "timestamp": "1769384641651", "event_type": "price_change"}}
{"_local_timestamp": "2026-01-25T23:44:08.601945+00:00", "data": {"market": "0xefc69f5f48827e331957acbcc2339eb3b15e27e32453b8e6f29b5de67474c986", "price_changes": [{"asset_id": "19619851020796345517172409566066997550761738782112746767326655871669350897686", "price": "0.2", "size": "420", "side": "BUY", "hash": "189fe5345bd97152371b1841c7dec6caa0e56add", "best_bid": "0.55", "best_ask": "0.56"}, {"asset_id": "108798918614128027361814219314538484133284583608074596451665946577336361445917", "price": "0.8", "size": "420", "side": "SELL", "hash": "7433ae4294e19cefe70ee765c6642dad40887516", "best_bid": "0.44", "best_ask": "0.45"}], "timestamp": "1769384648366", "event_type": "price_change"}}
{"_local_timestamp": "2026-01-25T23:44:08.602594+00:00", "data": {"market": "0xefc69f5f48827e331957acbcc2339eb3b15e27e32453b8e6f29b5de67474c986", "price_changes": [{"asset_id": "19619851020796345517172409566066997550761738782112746767326655871669350897686", "price": "0.15", "size": "2798", "side": "BUY", "hash": "189fe5345bd97152371b1841c7dec6caa0e56add", "best_bid": "0.55", "best_ask": "0.56"}, {"asset_id": "108798918614128027361814219314538484133284583608074596451665946577336361445917", "price": "0.85", "size": "2798", "side": "SELL", "hash": "7433ae4294e19cefe70ee765c6642dad40887516", "best_bid": "0.44", "best_ask": "0.45"}], "timestamp": "1769384648366", "event_type": "price_change"}}
{"_local_timestamp": "2026-01-25T23:44:09.098413+00:00", "data": {"market": "0xefc69f5f48827e331957acbcc2339eb3b15e27e32453b8e6f29b5de67474c986", "price_changes": [{"asset_id": "19619851020796345517172409566066997550761738782112746767326655871669350897686", "price": "0.13", "size": "1880", "side": "BUY", "hash": "5a3795e669027a1ef034fceb96ef74dfd648bdf3", "best_bid": "0.55", "best_ask": "0.56"}, {"asset_id": "108798918614128027361814219314538484133284583608074596451665946577336361445917", "price": "0.87", "size": "1880", "side": "SELL", "hash": "300679af058fd0c6bfc06f9099f474eb6c0af563", "best_bid": "0.44", "best_ask": "0.45"}], "timestamp": "1769384648772", "event_type": "price_change"}}
{"_local_timestamp": "2026-01-25T23:44:09.153621+00:00", "data": {"market": "0xefc69f5f48827e331957acbcc2339eb3b15e27e32453b8e6f29b5de67474c986", "price_changes": [{"asset_id": "19619851020796345517172409566066997550761738782112746767326655871669350897686", "price": "0.16", "size": "100", "side": "BUY", "hash": "5719cf3b3f613392fac917f76c8ac593667d03e8", "best_bid": "0.55", "best_ask": "0.56"}, {"asset_id": "108798918614128027361814219314538484133284583608074596451665946577336361445917", "price": "0.84", "size": "100", "side": "SELL", "hash": "6b47dc32affdfcf31716da59e3bd4500cfce1ce2", "best_bid": "0.44", "best_ask": "0.45"}], "timestamp": "1769384648856", "event_type": "price_change"}}
{"_local_timestamp": "2026-01-25T23:44:17.698549+00:00", "data": {"market": "0xefc69f5f48827e331957acbcc2339eb3b15e27e32453b8e6f29b5de67474c986", "price_changes": [{"asset_id": "19619851020796345517172409566066997550761738782112746767326655871669350897686", "price": "0.13", "size": "1830", "side": "BUY", "hash": "919fde323b4424bf2acafa8a6c612176025431ea", "best_bid": "0.55", "best_ask": "0.56"}, {"asset_id": "108798918614128027361814219314538484133284583608074596451665946577336361445917", "price": "0.87", "size": "1830", "side": "SELL", "hash": "b5ac53a6a5cf8f42fccdf43f0bfd194ca4171cc3", "best_bid": "0.44", "best_ask": "0.45"}], "timestamp": "1769384657629", "event_type": "price_change"}}
{"_local_timestamp": "2026-01-25T23:44:17.971709+00:00", "data": {"market": "0xefc69f5f48827e331957acbcc2339eb3b15e27e32453b8e6f29b5de67474c986", "price_changes": [{"asset_id": "19619851020796345517172409566066997550761738782112746767326655871669350897686", "price": "0.15", "size": "2848", "side": "BUY", "hash": "c0e903fda76aeca685bf05e7dbdfee52904c03c1", "best_bid": "0.55", "best_ask": "0.56"}, {"asset_id": "108798918614128027361814219314538484133284583608074596451665946577336361445917", "price": "0.85", "size": "2848", "side": "SELL", "hash": "bc90922f37b1fb4479e832399628a41e1f3c8ee1", "best_bid": "0.44", "best_ask": "0.45"}], "timestamp": "1769384657900", "event_type": "price_change"}}
{"_local_timestamp": "2026-01-25T23:44:20.662825+00:00", "data": {"market": "0xefc69f5f48827e331957acbcc2339eb3b15e27e32453b8e6f29b5de67474c986", "price_changes": [{"asset_id": "19619851020796345517172409566066997550761738782112746767326655871669350897686", "price": "0.2", "size": "270", "side": "BUY", "hash": "5186825049827434845af32c00d5a9e32e0fadd8", "best_bid": "0.55", "best_ask": "0.56"}, {"asset_id": "108798918614128027361814219314538484133284583608074596451665946577336361445917", "price": "0.8", "size": "270", "side": "SELL", "hash": "d2a15a9dda15c9b9630bddeb94d88799c6dc9703", "best_bid": "0.44", "best_ask": "0.45"}], "timestamp": "1769384660476", "event_type": "price_change"}}
{"_local_timestamp": "2026-01-25T23:44:21.390497+00:00", "data": {"market": "0xefc69f5f48827e331957acbcc2339eb3b15e27e32453b8e6f29b5de67474c986", "price_changes": [{"asset_id": "19619851020796345517172409566066997550761738782112746767326655871669350897686", "price": "0.17", "size": "302.94", "side": "BUY", "hash": "59e1b53ff27597612add00968374e128cea01eb2", "best_bid": "0.55", "best_ask": "0.56"}, {"asset_id": "108798918614128027361814219314538484133284583608074596451665946577336361445917", "price": "0.83", "size": "302.94", "side": "SELL", "hash": "63578cc55989b101e932c9599106cc678c2ddeff", "best_bid": "0.44", "best_ask": "0.45"}], "timestamp": "1769384660873", "event_type": "price_change"}}
{"_local_timestamp": "2026-01-25T23:44:32.405524+00:00", "data": {"market": "0xefc69f5f48827e331957acbcc2339eb3b15e27e32453b8e6f29b5de67474c986", "price_changes": [{"asset_id": "19619851020796345517172409566066997550761738782112746767326655871669350897686", "price": "0.15", "size": "50", "side": "BUY", "hash": "cf5bbfcaeaa784bf33dc9993a154974750ca3f29", "best_bid": "0.55", "best_ask": "0.56"}, {"asset_id": "108798918614128027361814219314538484133284583608074596451665946577336361445917", "price": "0.85", "size": "50", "side": "SELL", "hash": "a22f4c15a468abfaf7224b5c48c73c9f842f2f86", "best_bid": "0.44", "best_ask": "0.45"}], "timestamp": "1769384672293", "event_type": "price_change"}}
{"_local_timestamp": "2026-01-25T23:44:37.482779+00:00", "data": {"market": "0xefc69f5f48827e331957acbcc2339eb3b15e27e32453b8e6f29b5de67474c986", "price_changes": [{"asset_id": "19619851020796345517172409566066997550761738782112746767326655871669350897686", "price": "0.13", "size": "1780", "side": "BUY", "hash": "a4ea73055f1410f54ff6332758f60ab77828b858", "best_bid": "0.55", "best_ask": "0.56"}, {"asset_id": "108798918614128027361814219314538484133284583608074596451665946577336361445917", "price": "0.87", "size": "1780", "side": "SELL", "hash": "07db55f4cb3aa766aa1aee542ed414102c75cbf0", "best_bid": "0.44", "best_ask": "0.45"}], "timestamp": "1769384677409", "event_type": "price_change"}}
{"_local_timestamp": "2026-01-25T23:44:37.773268+00:00", "data": {"market": "0xefc69f5f48827e331957acbcc2339eb3b15e27e32453b8e6f29b5de67474c986", "price_changes": [{"asset_id": "19619851020796345517172409566066997550761738782112746767326655871669350897686", "price": "0.15", "size": "100", "side": "BUY", "hash": "f397ffac3b2e16ee45dec7cc56ee259c7162f861", "best_bid": "0.55", "best_ask": "0.56"}, {"asset_id": "108798918614128027361814219314538484133284583608074596451665946577336361445917", "price": "0.85", "size": "100", "side": "SELL", "hash": "2962749a9a11a27ca9d230fcf0f129460630b4f0", "best_bid": "0.44", "best_ask": "0.45"}], "timestamp": "1769384677692", "event_type": "price_change"}}
{"_local_timestamp": "2026-01-25T23:44:57.539316+00:00", "data": {"market": "0xefc69f5f48827e331957acbcc2339eb3b15e27e32453b8e6f29b5de67474c986", "price_changes": [{"asset_id": "19619851020796345517172409566066997550761738782112746767326655871669350897686", "price": "0.13", "size": "1555", "side": "BUY", "hash": "23aac2526ebb5d30273f72ca07c814831b735bdb", "best_bid": "0.55", "best_ask": "0.56"}, {"asset_id": "108798918614128027361814219314538484133284583608074596451665946577336361445917", "price": "0.87", "size": "1555", "side": "SELL", "hash": "3eb776acdb4a18bb230bc9b160d9e05798a8d5bd", "best_bid": "0.44", "best_ask": "0.45"}], "timestamp": "1769384697460", "event_type": "price_change"}}
{"_local_timestamp": "2026-01-25T23:44:57.540041+00:00", "data": {"market": "0xefc69f5f48827e331957acbcc2339eb3b15e27e32453b8e6f29b5de67474c986", "price_changes": [{"asset_id": "19619851020796345517172409566066997550761738782112746767326655871669350897686", "price": "0.2", "size": "120", "side": "BUY", "hash": "23aac2526ebb5d30273f72ca07c814831b735bdb", "best_bid": "0.55", "best_ask": "0.56"}, {"asset_id": "108798918614128027361814219314538484133284583608074596451665946577336361445917", "price": "0.8", "size": "120", "side": "SELL", "hash": "3eb776acdb4a18bb230bc9b160d9e05798a8d5bd", "best_bid": "0.44", "best_ask": "0.45"}], "timestamp": "1769384697460", "event_type": "price_change"}}
{"_local_timestamp": "2026-01-25T23:44:57.868058+00:00", "data": {"market": "0xefc69f5f48827e331957acbcc2339eb3b15e27e32453b8e6f29b5de67474c986", "price_changes": [{"asset_id": "19619851020796345517172409566066997550761738782112746767326655871669350897686", "price": "0.15", "size": "325", "side": "BUY", "hash": "6894a14220cb848bac20bde2f45a68c1b2fefc4f", "best_bid": "0.55", "best_ask": "0.56"}, {"asset_id": "108798918614128027361814219314538484133284583608074596451665946577336361445917", "price": "0.85", "size": "325", "side": "SELL", "hash": "024a38760044a9419056bb851b13946637fe61ea", "best_bid": "0.44", "best_ask": "0.45"}], "timestamp": "1769384697743", "event_type": "price_change"}}
{"_local_timestamp": "2026-01-25T23:44:57.890160+00:00", "data": {"market": "0xefc69f5f48827e331957acbcc2339eb3b15e27e32453b8e6f29b5de67474c986", "price_changes": [{"asset_id": "19619851020796345517172409566066997550761738782112746767326655871669350897686", "price": "0.19", "size": "450", "side": "BUY", "hash": "4805dab6ebf28b3f8902f36f2ad351f305e0bd5b", "best_bid": "0.55", "best_ask": "0.56"}, {"asset_id": "108798918614128027361814219314538484133284583608074596451665946577336361445917", "price": "0.81", "size": "450", "side": "SELL", "hash": "e369faf7d171a323c31118ca170bd818e8e2723e", "best_bid": "0.44", "best_ask": "0.45"}], "timestamp": "1769384697750", "event_type": "price_change"}}
{"_local_timestamp": "2026-01-25T23:45:00.806851+00:00", "data": {"market": "0xefc69f5f48827e331957acbcc2339eb3b15e27e32453b8e6f29b5de67474c986", "price_changes": [{"asset_id": "19619851020796345517172409566066997550761738782112746767326655871669350897686", "price": "0.15", "size": "275", "side": "BUY", "hash": "069dfcc0ef145586ed5d90baa238b78f36a0191d", "best_bid": "0.55", "best_ask": "0.56"}, {"asset_id": "108798918614128027361814219314538484133284583608074596451665946577336361445917", "price": "0.85", "size": "275", "side": "SELL", "hash": "8a924e067778aa5e4c95dcf2444e159103008f85", "best_bid": "0.44", "best_ask": "0.45"}], "timestamp": "1769384700715", "event_type": "price_change"}}
{"_local_timestamp": "2026-01-25T23:45:01.160556+00:00", "data": {"market": "0xefc69f5f48827e331957acbcc2339eb3b15e27e32453b8e6f29b5de67474c986", "price_changes": [{"asset_id": "19619851020796345517172409566066997550761738782112746767326655871669350897686", "price": "0.13", "size": "1605", "side": "BUY", "hash": "11bf072c4871c609ead656fca4399bd52bfe01a7", "best_bid": "0.55", "best_ask": "0.56"}, {"asset_id": "108798918614128027361814219314538484133284583608074596451665946577336361445917", "price": "0.87", "size": "1605", "side": "SELL", "hash": "879da68c4c4f1510f773c214e05d1cd7d5af6db3", "best_bid": "0.44", "best_ask": "0.45"}], "timestamp": "1769384701082", "event_type": "price_change"}}
{"_local_timestamp": "2026-01-25T23:45:01.374625+00:00", "data": {"market": "0xefc69f5f48827e331957acbcc2339eb3b15e27e32453b8e6f29b5de67474c986", "price_changes": [{"asset_id": "19619851020796345517172409566066997550761738782112746767326655871669350897686", "price": "0.16", "size": "2724", "side": "BUY", "hash": "7465cbda7717bc59cee62bca20fd55b28f4f0719", "best_bid": "0.55", "best_ask": "0.56"}, {"asset_id": "108798918614128027361814219314538484133284583608074596451665946577336361445917", "price": "0.84", "size": "2724", "side": "SELL", "hash": "2b9be45d6c4240b44c13a48f57251afca97475bc", "best_bid": "0.44", "best_ask": "0.45"}], "timestamp": "1769384701303", "event_type": "price_change"}}
{"_local_timestamp": "2026-01-25T23:45:06.574535+00:00", "data": {"market": "0xefc69f5f48827e331957acbcc2339eb3b15e27e32453b8e6f29b5de67474c986", "price_changes": [{"asset_id": "19619851020796345517172409566066997550761738782112746767326655871669350897686", "price": "0.21", "size": "200", "side": "BUY", "hash": "ee7f7bb37be83626b2d0053599ef32a6a97e56d1", "best_bid": "0.55", "best_ask": "0.56"}, {"asset_id": "108798918614128027361814219314538484133284583608074596451665946577336361445917", "price": "0.79", "size": "200", "side": "SELL", "hash": "42d3bbd915198d49cbe5afca7e64fd7579570387", "best_bid": "0.44", "best_ask": "0.45"}], "timestamp": "1769384706508", "event_type": "price_change"}}
{"_local_timestamp": "2026-01-25T23:45:21.084080+00:00", "data": {"market": "0xefc69f5f48827e331957acbcc2339eb3b15e27e32453b8e6f29b5de67474c986", "price_changes": [{"asset_id": "19619851020796345517172409566066997550761738782112746767326655871669350897686", "price": "0.13", "size": "1555", "side": "BUY", "hash": "3e48df3ea8f4368cc5c3d387c570cbab799be67b", "best_bid": "0.55", "best_ask": "0.56"}, {"asset_id": "108798918614128027361814219314538484133284583608074596451665946577336361445917", "price": "0.87", "size": "1555", "side": "SELL", "hash": "3140c2d0599fac0c2fa7b4d137a7e0a6ea7ae4bb", "best_bid": "0.44", "best_ask": "0.45"}], "timestamp": "1769384720999", "event_type": "price_change"}}
{"_local_timestamp": "2026-01-25T23:45:21.322027+00:00", "data": {"market": "0xefc69f5f48827e331957acbcc2339eb3b15e27e32453b8e6f29b5de67474c986", "price_changes": [{"asset_id": "19619851020796345517172409566066997550761738782112746767326655871669350897686", "price": "0.16", "size": "2774", "side": "BUY", "hash": "9f2efd2c8958371428833c2a805acde12d10e784", "best_bid": "0.55", "best_ask": "0.56"}, {"asset_id": "108798918614128027361814219314538484133284583608074596451665946577336361445917", "price": "0.84", "size": "2774", "side": "SELL", "hash": "f2a55844b4b1f153d4825f2917ca6f633e80a2af", "best_bid": "0.44", "best_ask": "0.45"}], "timestamp": "1769384721250", "event_type": "price_change"}}
{"_local_timestamp": "2026-01-25T23:45:23.839350+00:00", "data": {"market": "0xefc69f5f48827e331957acbcc2339eb3b15e27e32453b8e6f29b5de67474c986", "price_changes": [{"asset_id": "19619851020796345517172409566066997550761738782112746767326655871669350897686", "price": "0.15", "size": "225", "side": "BUY", "hash": "8665b7c2926625c256bf95ec6f093080cace961d", "best_bid": "0.55", "best_ask": "0.56"}, {"asset_id": "108798918614128027361814219314538484133284583608074596451665946577336361445917", "price": "0.85", "size": "225", "side": "SELL", "hash": "8267c364932e71a803c4066bca60e4a4c293f384", "best_bid": "0.44", "best_ask": "0.45"}], "timestamp": "1769384723757", "event_type": "price_change"}}
{"_local_timestamp": "2026-01-25T23:45:24.122531+00:00", "data": {"market": "0xefc69f5f48827e331957acbcc2339eb3b15e27e32453b8e6f29b5de67474c986", "price_changes": [{"asset_id": "19619851020796345517172409566066997550761738782112746767326655871669350897686", "price": "0.13", "size": "1605", "side": "BUY", "hash": "6d6a2575b537991f18ccdc7d7e2377b5d8d30990", "best_bid": "0.55", "best_ask": "0.56"}, {"asset_id": "108798918614128027361814219314538484133284583608074596451665946577336361445917", "price": "0.87", "size": "1605", "side": "SELL", "hash": "03ff71540ec89759241011ec6c204a8b2472e557", "best_bid": "0.44", "best_ask": "0.45"}], "timestamp": "1769384724046", "event_type": "price_change"}}
{"_local_timestamp": "2026-01-25T23:45:38.915464+00:00", "data": {"market": "0xefc69f5f48827e331957acbcc2339eb3b15e27e32453b8e6f29b5de67474c986", "price_changes": [{"asset_id": "19619851020796345517172409566066997550761738782112746767326655871669350897686", "price": "0.15", "size": "0", "side": "BUY", "hash": "5ad570382e0a5ac83c4596e5dfc56b42a744b11b", "best_bid": "0.55", "best_ask": "0.56"}, {"asset_id": "108798918614128027361814219314538484133284583608074596451665946577336361445917", "price": "0.85", "size": "0", "side": "SELL", "hash": "9ca2cdec1fbacb5841ac80ca7878c09892a07176", "best_bid": "0.44", "best_ask": "0.45"}], "timestamp": "1769384738814", "event_type": "price_change"}}
{"_local_timestamp": "2026-01-25T23:45:38.916354+00:00", "data": {"market": "0xefc69f5f48827e331957acbcc2339eb3b15e27e32453b8e6f29b5de67474c986", "price_changes": [{"asset_id": "19619851020796345517172409566066997550761738782112746767326655871669350897686", "price": "0.19", "size": "300", "side": "BUY", "hash": "5ad570382e0a5ac83c4596e5dfc56b42a744b11b", "best_bid": "0.55", "best_ask": "0.56"}, {"asset_id": "108798918614128027361814219314538484133284583608074596451665946577336361445917", "price": "0.81", "size": "300", "side": "SELL", "hash": "9ca2cdec1fbacb5841ac80ca7878c09892a07176", "best_bid": "0.44", "best_ask": "0.45"}], "timestamp": "1769384738814", "event_type": "price_change"}}
{"_local_timestamp": "2026-01-25T23:45:39.179867+00:00", "data": {"market": "0xefc69f5f48827e331957acbcc2339eb3b15e27e32453b8e6f29b5de67474c986", "price_changes": [{"asset_id": "19619851020796345517172409566066997550761738782112746767326655871669350897686", "price": "0.16", "size": "2924", "side": "BUY", "hash": "5b56091465c630cae33932fb64a79b4adb44881a", "best_bid": "0.55", "best_ask": "0.56"}, {"asset_id": "108798918614128027361814219314538484133284583608074596451665946577336361445917", "price": "0.84", "size": "2924", "side": "SELL", "hash": "c9c0dd045c224b510d64e9dadbfbaf8ab17838d5", "best_bid": "0.44", "best_ask": "0.45"}], "timestamp": "1769384739076", "event_type": "price_change"}}
{"_local_timestamp": "2026-01-25T23:45:39.209600+00:00", "data": {"market": "0xefc69f5f48827e331957acbcc2339eb3b15e27e32453b8e6f29b5de67474c986", "price_changes": [{"asset_id": "19619851020796345517172409566066997550761738782112746767326655871669350897686", "price": "0.13", "size": "1830", "side": "BUY", "hash": "1876328b350cab3bfe13548fc277fa1afe6fc063", "best_bid": "0.55", "best_ask": "0.56"}, {"asset_id": "108798918614128027361814219314538484133284583608074596451665946577336361445917", "price": "0.87", "size": "1830", "side": "SELL", "hash": "dae6f14466fbb2450819212a50c40c808a9b8f6e", "best_bid": "0.44", "best_ask": "0.45"}], "timestamp": "1769384739087", "event_type": "price_change"}}
{"_local_timestamp": "2026-01-25T23:45:53.201153+00:00", "data": {"market": "0xefc69f5f48827e331957acbcc2339eb3b15e27e32453b8e6f29b5de67474c986", "price_changes": [{"asset_id": "19619851020796345517172409566066997550761738782112746767326655871669350897686", "price": "0.13", "size": "1705", "side": "BUY", "hash": "110fccfb9110dd07797671d2956c9cd6b5d61bc4", "best_bid": "0.55", "best_ask": "0.56"}, {"asset_id": "108798918614128027361814219314538484133284583608074596451665946577336361445917", "price": "0.87", "size": "1705", "side": "SELL", "hash": "789a7e12c78968129a4fca018ebddb7d9eee080e", "best_bid": "0.44", "best_ask": "0.45"}], "timestamp": "1769384753013", "event_type": "price_change"}}
{"_local_timestamp": "2026-01-25T23:45:53.201923+00:00", "data": {"market": "0xefc69f5f48827e331957acbcc2339eb3b15e27e32453b8e6f29b5de67474c986", "price_changes": [{"asset_id": "19619851020796345517172409566066997550761738782112746767326655871669350897686", "price": "0.16", "size": "2824", "side": "BUY", "hash": "110fccfb9110dd07797671d2956c9cd6b5d61bc4", "best_bid": "0.55", "best_ask": "0.56"}, {"asset_id": "108798918614128027361814219314538484133284583608074596451665946577336361445917", "price": "0.84", "size": "2824", "side": "SELL", "hash": "789a7e12c78968129a4fca018ebddb7d9eee080e", "best_bid": "0.44", "best_ask": "0.45"}], "timestamp": "1769384753013", "event_type": "price_change"}}
{"_local_timestamp": "2026-01-25T23:45:53.742610+00:00", "data": {"market": "0xefc69f5f48827e331957acbcc2339eb3b15e27e32453b8e6f29b5de67474c986", "price_changes": [{"asset_id": "19619851020796345517172409566066997550761738782112746767326655871669350897686", "price": "0.19", "size": "400", "side": "BUY", "hash": "c7ffb502637b56c8fd9d9a2b96649f602ba7b4d4", "best_bid": "0.55", "best_ask": "0.56"}, {"asset_id": "108798918614128027361814219314538484133284583608074596451665946577336361445917", "price": "0.81", "size": "400", "side": "SELL", "hash": "ff217708fd75b2e4298f740a0b72d7c74671cc98", "best_bid": "0.44", "best_ask": "0.45"}], "timestamp": "1769384753536", "event_type": "price_change"}}
{"_local_timestamp": "2026-01-25T23:45:53.755120+00:00", "data": {"market": "0xefc69f5f48827e331957acbcc2339eb3b15e27e32453b8e6f29b5de67474c986", "price_changes": [{"asset_id": "19619851020796345517172409566066997550761738782112746767326655871669350897686", "price": "0.15", "size": "125", "side": "BUY", "hash": "3b667dc1a3e9f38149841789401c1e6738d7c5c0", "best_bid": "0.55", "best_ask": "0.56"}, {"asset_id": "108798918614128027361814219314538484133284583608074596451665946577336361445917", "price": "0.85", "size": "125", "side": "SELL", "hash": "a6a6890e753a90711d48e57c7457734350ed7a82", "best_bid": "0.44", "best_ask": "0.45"}], "timestamp": "1769384753561", "event_type": "price_change"}}
{"_local_timestamp": "2026-01-25T23:45:56.420895+00:00", "data": {"market": "0xefc69f5f48827e331957acbcc2339eb3b15e27e32453b8e6f29b5de67474c986", "price_changes": [{"asset_id": "19619851020796345517172409566066997550761738782112746767326655871669350897686", "price": "0.19", "size": "100", "side": "BUY", "hash": "8dd5e7d938d46e4e6df7adf491fa69c6a1eb94d8", "best_bid": "0.55", "best_ask": "0.56"}, {"asset_id": "108798918614128027361814219314538484133284583608074596451665946577336361445917", "price": "0.81", "size": "100", "side": "SELL", "hash": "c05d3e5b5c9521053c0c82ce130fe147db93cdc4", "best_bid": "0.44", "best_ask": "0.45"}], "timestamp": "1769384756076", "event_type": "price_change"}}
{"_local_timestamp": "2026-01-25T23:45:56.430892+00:00", "data": {"market": "0xefc69f5f48827e331957acbcc2339eb3b15e27e32453b8e6f29b5de67474c986", "price_changes": [{"asset_id": "108798918614128027361814219314538484133284583608074596451665946577336361445917", "price": "0.17", "size": "0", "side": "BUY", "hash": "e667e9aa64c5b42018c77343c4b86a89d06b89f9", "best_bid": "0.44", "best_ask": "0.45"}, {"asset_id": "19619851020796345517172409566066997550761738782112746767326655871669350897686", "price": "0.83", "size": "0", "side": "SELL", "hash": "8a20ed607b5b40396aad7cf124788c57b302d0e7", "best_bid": "0.55", "best_ask": "0.56"}], "timestamp": "1769384756118", "event_type": "price_change"}}
{"_local_timestamp": "2026-01-25T23:45:57.231591+00:00", "data": {"market": "0xefc69f5f48827e331957acbcc2339eb3b15e27e32453b8e6f29b5de67474c986", "price_changes": [{"asset_id": "19619851020796345517172409566066997550761738782112746767326655871669350897686", "price": "0.56", "size": "15.02", "side": "SELL", "hash": "fe80ec717d7a1d36c6e69baea7952dce84ef7677", "best_bid": "0.55", "best_ask": "0.56"}, {"asset_id": "108798918614128027361814219314538484133284583608074596451665946577336361445917", "price": "0.44", "size": "15.02", "side": "BUY", "hash": "98cae296b28ff10c32857ce7c18626aba423d695", "best_bid": "0.44", "best_ask": "0.45"}], "timestamp": "1769384756390", "event_type": "price_change"}}
{"_local_timestamp": "2026-01-25T23:45:57.933826+00:00", "data": {"market": "0xefc69f5f48827e331957acbcc2339eb3b15e27e32453b8e6f29b5de67474c986", "price_changes": [{"asset_id": "19619851020796345517172409566066997550761738782112746767326655871669350897686", "price": "0.53", "size": "389", "side": "BUY", "hash": "7b1248b70cea2401b08bd206dcb22b828d584efe", "best_bid": "0.55", "best_ask": "0.56"}, {"asset_id": "108798918614128027361814219314538484133284583608074596451665946577336361445917", "price": "0.47", "size": "389", "side": "SELL", "hash": "90081152263cdd81f17fd1ca1359197c7d7e3b06", "best_bid": "0.44", "best_ask": "0.45"}], "timestamp": "1769384757817", "event_type": "price_change"}}
{"_local_timestamp": "2026-01-25T23:45:57.934437+00:00", "data": {"market": "0xefc69f5f48827e331957acbcc2339eb3b15e27e32453b8e6f29b5de67474c986", "price_changes": [{"asset_id": "108798918614128027361814219314538484133284583608074596451665946577336361445917", "price": "0.44", "size": "125.02", "side": "BUY", "hash": "5289d1bd40de3e8df9646237547057fa4e7e5cce", "best_bid": "0.44", "best_ask": "0.45"}, {"asset_id": "19619851020796345517172409566066997550761738782112746767326655871669350897686", "price": "0.56", "size": "125.02", "side": "SELL", "hash": "cab3420e51f51158be5f1a17d53e17b20310f883", "best_bid": "0.55", "best_ask": "0.56"}], "timestamp": "1769384757830", "event_type": "price_change"}}
{"_local_timestamp": "2026-01-25T23:45:58.087479+00:00", "data": {"market": "0xefc69f5f48827e331957acbcc2339eb3b15e27e32453b8e6f29b5de67474c986", "price_changes": [{"asset_id": "19619851020796345517172409566066997550761738782112746767326655871669350897686", "price": "0.42", "size": "122", "side": "BUY", "hash": "1184344bf4a70c75f69736a6e81474fecfc142f1", "best_bid": "0.55", "best_ask": "0.56"}, {"asset_id": "108798918614128027361814219314538484133284583608074596451665946577336361445917", "price": "0.58", "size": "122", "side": "SELL", "hash": "7e1c90c513349bec96a72de07f52db70781ce73c", "best_bid": "0.44", "best_ask": "0.45"}], "timestamp": "1769384758000", "event_type": "price_change"}}
{"_local_timestamp": "2026-01-25T23:45:58.100259+00:00", "data": {"market": "0xefc69f5f48827e331957acbcc2339eb3b15e27e32453b8e6f29b5de67474c986", "price_changes": [{"asset_id": "19619851020796345517172409566066997550761738782112746767326655871669350897686", "price": "0.25", "size": "525.73", "side": "BUY", "hash": "1c42160568f496ce977e87b3c4d0ed9b9e1d9c72", "best_bid": "0.55", "best_ask": "0.56"}, {"asset_id": "108798918614128027361814219314538484133284583608074596451665946577336361445917", "price": "0.75", "size": "525.73", "side": "SELL", "hash": "d4922354c8d91dea25b816cab700a971f8ebd94f", "best_bid": "0.44", "best_ask": "0.45"}], "timestamp": "1769384758003", "event_type": "price_change"}}
{"_local_timestamp": "2026-01-25T23:46:01.601212+00:00", "data": {"market": "0xefc69f5f48827e331957acbcc2339eb3b15e27e32453b8e6f29b5de67474c986", "price_changes": [{"asset_id": "19619851020796345517172409566066997550761738782112746767326655871669350897686", "price": "0.53", "size": "289", "side": "BUY", "hash": "1b31a4e7af9c7a0e2de606edbc0a5267bdd3eefa", "best_bid": "0.55", "best_ask": "0.56"}, {"asset_id": "108798918614128027361814219314538484133284583608074596451665946577336361445917", "price": "0.47", "size": "289", "side": "SELL", "hash": "90b8d6762e1f3f4e8fc690caec596df0ae2bbe2b", "best_bid": "0.44", "best_ask": "0.45"}], "timestamp": "1769384761526", "event_type": "price_change"}}
{"_local_timestamp": "2026-01-25T23:46:01.621534+00:00", "data": {"market": "0xefc69f5f48827e331957acbcc2339eb3b15e27e32453b8e6f29b5de67474c986", "price_changes": [{"asset_id": "108798918614128027361814219314538484133284583608074596451665946577336361445917", "price": "0.44", "size": "15.02", "side": "BUY", "hash": "4870d712a1c62acd415adeec9ff3dab65badcbed", "best_bid": "0.44", "best_ask": "0.45"}, {"asset_id": "19619851020796345517172409566066997550761738782112746767326655871669350897686", "price": "0.56", "size": "15.02", "side": "SELL", "hash": "ee9668be19564acaab442d1bfe543d408da80db0", "best_bid": "0.55", "best_ask": "0.56"}], "timestamp": "1769384761554", "event_type": "price_change"}}
{"_local_timestamp": "2026-01-25T23:46:01.653237+00:00", "data": {"market": "0xefc69f5f48827e331957acbcc2339eb3b15e27e32453b8e6f29b5de67474c986", "price_changes": [{"asset_id": "108798918614128027361814219314538484133284583608074596451665946577336361445917", "price": "0.44", "size": "218.02", "side": "BUY", "hash": "4354d86c570caf403a9716d59be8d9b0dd2f70d1", "best_bid": "0.44", "best_ask": "0.45"}, {"asset_id": "19619851020796345517172409566066997550761738782112746767326655871669350897686", "price": "0.56", "size": "218.02", "side": "SELL", "hash": "dbdca231cb246be302194b5c2f63d30379fa7d11", "best_bid": "0.55", "best_ask": "0.56"}], "timestamp": "1769384761580", "event_type": "price_change"}}
{"_local_timestamp": "2026-01-25T23:46:10.632286+00:00", "data": {"market": "0xefc69f5f48827e331957acbcc2339eb3b15e27e32453b8e6f29b5de67474c986", "price_changes": [{"asset_id": "19619851020796345517172409566066997550761738782112746767326655871669350897686", "price": "0.16", "size": "200", "side": "BUY", "hash": "4958165926604c31a0214053d099c5e50d4b9dac", "best_bid": "0.55", "best_ask": "0.56"}, {"asset_id": "108798918614128027361814219314538484133284583608074596451665946577336361445917", "price": "0.84", "size": "200", "side": "SELL", "hash": "15549906c3951aa2214bae8e04ef341d1b62a1bc", "best_bid": "0.44", "best_ask": "0.45"}], "timestamp": "1769384770462", "event_type": "price_change"}}
{"_local_timestamp": "2026-01-25T23:46:12.358498+00:00", "data": {"market": "0xefc69f5f48827e331957acbcc2339eb3b15e27e32453b8e6f29b5de67474c986", "price_changes": [{"asset_id": "19619851020796345517172409566066997550761738782112746767326655871669350897686", "price": "0.13", "size": "1655", "side": "BUY", "hash": "2d75e558c1c6101306697eb94af19409580f793a", "best_bid": "0.55", "best_ask": "0.56"}, {"asset_id": "108798918614128027361814219314538484133284583608074596451665946577336361445917", "price": "0.87", "size": "1655", "side": "SELL", "hash": "9da9514838ce8f2b4f54a35ba31677d742a96926", "best_bid": "0.44", "best_ask": "0.45"}], "timestamp": "1769384772292", "event_type": "price_change"}}
{"_local_timestamp": "2026-01-25T23:46:12.760743+00:00", "data": {"market": "0xefc69f5f48827e331957acbcc2339eb3b15e27e32453b8e6f29b5de67474c986", "price_changes": [{"asset_id": "19619851020796345517172409566066997550761738782112746767326655871669350897686", "price": "0.16", "size": "250", "side": "BUY", "hash": "8b41f4f1e44e4f7daa1d5fb0e7a552c8847b9c6f", "best_bid": "0.55", "best_ask": "0.56"}, {"asset_id": "108798918614128027361814219314538484133284583608074596451665946577336361445917", "price": "0.84", "size": "250", "side": "SELL", "hash": "1c4f437577c436047541b14c58276e44eb0add45", "best_bid": "0.44", "best_ask": "0.45"}], "timestamp": "1769384772688", "event_type": "price_change"}}
{"_local_timestamp": "2026-01-25T23:46:15.635909+00:00", "data": {"market": "0xefc69f5f48827e331957acbcc2339eb3b15e27e32453b8e6f29b5de67474c986", "price_changes": [{"asset_id": "19619851020796345517172409566066997550761738782112746767326655871669350897686", "price": "0.52", "size": "1000", "side": "BUY", "hash": "f52593845651f5047e25ed03f1288af43e11802f", "best_bid": "0.55", "best_ask": "0.56"}, {"asset_id": "108798918614128027361814219314538484133284583608074596451665946577336361445917", "price": "0.48", "size": "1000", "side": "SELL", "hash": "dc237696018decf59b26d2dea0c0bbf3d367e8ac", "best_bid": "0.44", "best_ask": "0.45"}], "timestamp": "1769384775547", "event_type": "price_change"}}
{"_local_timestamp": "2026-01-25T23:46:15.636541+00:00", "data": {"market": "0xefc69f5f48827e331957acbcc2339eb3b15e27e32453b8e6f29b5de67474c986", "price_changes": [{"asset_id": "19619851020796345517172409566066997550761738782112746767326655871669350897686", "price": "0.49", "size": "0", "side": "BUY", "hash": "f52593845651f5047e25ed03f1288af43e11802f", "best_bid": "0.55", "best_ask": "0.56"}, {"asset_id": "108798918614128027361814219314538484133284583608074596451665946577336361445917", "price": "0.51", "size": "0", "side": "SELL", "hash": "dc237696018decf59b26d2dea0c0bbf3d367e8ac", "best_bid": "0.44", "best_ask": "0.45"}], "timestamp": "1769384775547", "event_type": "price_change"}}
{"_local_timestamp": "2026-01-25T23:46:15.637081+00:00", "data": {"market": "0xefc69f5f48827e331957acbcc2339eb3b15e27e32453b8e6f29b5de67474c986", "price_changes": [{"asset_id": "19619851020796345517172409566066997550761738782112746767326655871669350897686", "price": "0.25", "size": "121.73", "side": "BUY", "hash": "f52593845651f5047e25ed03f1288af43e11802f", "best_bid": "0.55", "best_ask": "0.56"}, {"asset_id": "108798918614128027361814219314538484133284583608074596451665946577336361445917", "price": "0.75", "size": "121.73", "side": "SELL", "hash": "dc237696018decf59b26d2dea0c0bbf3d367e8ac", "best_bid": "0.44", "best_ask": "0.45"}], "timestamp": "1769384775547", "event_type": "price_change"}}
{"_local_timestamp": "2026-01-25T23:46:15.637584+00:00", "data": {"market": "0xefc69f5f48827e331957acbcc2339eb3b15e27e32453b8e6f29b5de67474c986", "price_changes": [{"asset_id": "19619851020796345517172409566066997550761738782112746767326655871669350897686", "price": "0.46", "size": "28.26", "side": "BUY", "hash": "f52593845651f5047e25ed03f1288af43e11802f", "best_bid": "0.55", "best_ask": "0.56"}, {"asset_id": "108798918614128027361814219314538484133284583608074596451665946577336361445917", "price": "0.54", "size": "28.26", "side": "SELL", "hash": "dc237696018decf59b26d2dea0c0bbf3d367e8ac", "best_bid": "0.44", "best_ask": "0.45"}], "timestamp": "1769384775547", "event_type": "price_change"}}
{"_local_timestamp": "2026-01-25T23:46:15.745603+00:00", "data": {"market": "0xefc69f5f48827e331957acbcc2339eb3b15e27e32453b8e6f29b5de67474c986", "price_changes": [{"asset_id": "19619851020796345517172409566066997550761738782112746767326655871669350897686", "price": "0.26", "size": "424", "side": "BUY", "hash": "2a7bc5e8c77525a77fe8ad4a0323d5604adbff93", "best_bid": "0.55", "best_ask": "0.56"}, {"asset_id": "108798918614128027361814219314538484133284583608074596451665946577336361445917", "price": "0.74", "size": "424", "side": "SELL", "hash": "711cc1c5b71c5cda40c5b6dd053d6839591d54e4", "best_bid": "0.44", "best_ask": "0.45"}], "timestamp": "1769384775660", "event_type": "price_change"}}
{"_local_timestamp": "2026-01-25T23:46:15.746159+00:00", "data": {"market": "0xefc69f5f48827e331957acbcc2339eb3b15e27e32453b8e6f29b5de67474c986", "price_changes": [{"asset_id": "19619851020796345517172409566066997550761738782112746767326655871669350897686", "price": "0.5", "size": "1812.14", "side": "BUY", "hash": "aecdb47dccaa00e6a14b3f3cb145678bfe36d600", "best_bid": "0.55", "best_ask": "0.56"}, {"asset_id": "108798918614128027361814219314538484133284583608074596451665946577336361445917", "price": "0.5", "size": "1812.14", "side": "SELL", "hash": "018cfdef012230d4edcda8a1a6d5931a8c807567", "best_bid": "0.44", "best_ask": "0.45"}], "timestamp": "1769384775661", "event_type": "price_change"}}
{"_local_timestamp": "2026-01-25T23:46:15.746647+00:00", "data": {"market": "0xefc69f5f48827e331957acbcc2339eb3b15e27e32453b8e6f29b5de67474c986", "price_changes": [{"asset_id": "19619851020796345517172409566066997550761738782112746767326655871669350897686", "price": "0.53", "size": "303", "side": "BUY", "hash": "acc1531f499f71b0f25518ef6675a17d547f170d", "best_bid": "0.55", "best_ask": "0.56"}, {"asset_id": "108798918614128027361814219314538484133284583608074596451665946577336361445917", "price": "0.47", "size": "303", "side": "SELL", "hash": "b3e12fdd91a9dc56595a142bc7b2a99d9b65ead9", "best_bid": "0.44", "best_ask": "0.45"}], "timestamp": "1769384775661", "event_type": "price_change"}}
{"_local_timestamp": "2026-01-25T23:46:15.747167+00:00", "data": {"market": "0xefc69f5f48827e331957acbcc2339eb3b15e27e32453b8e6f29b5de67474c986", "price_changes": [{"asset_id": "19619851020796345517172409566066997550761738782112746767326655871669350897686", "price": "0.18", "size": "1217", "side": "BUY", "hash": "d0247b7f5d4368174905f6333a12f830a386c067", "best_bid": "0.55", "best_ask": "0.56"}, {"asset_id": "108798918614128027361814219314538484133284583608074596451665946577336361445917", "price": "0.82", "size": "1217", "side": "SELL", "hash": "2d8a4ae6c39d61d547d992cde83cdb814e2a5325", "best_bid": "0.44", "best_ask": "0.45"}], "timestamp": "1769384775662", "event_type": "price_change"}}
{"_local_timestamp": "2026-01-25T23:46:15.754395+00:00", "data": {"market": "0xefc69f5f48827e331957acbcc2339eb3b15e27e32453b8e6f29b5de67474c986", "price_changes": [{"asset_id": "19619851020796345517172409566066997550761738782112746767326655871669350897686", "price": "0.42", "size": "131", "side": "BUY", "hash": "29f0d49055bdc21c823c3c17cafae69063501096", "best_bid": "0.55", "best_ask": "0.56"}, {"asset_id": "108798918614128027361814219314538484133284583608074596451665946577336361445917", "price": "0.58", "size": "131", "side": "SELL", "hash": "eb4a40af31a7ae7a73d99520bffce045d79f5562", "best_bid": "0.44", "best_ask": "0.45"}], "timestamp": "1769384775663", "event_type": "price_change"}}
{"_local_timestamp": "2026-01-25T23:46:15.754991+00:00", "data": {"market": "0xefc69f5f48827e331957acbcc2339eb3b15e27e32453b8e6f29b5de67474c986", "price_changes": [{"asset_id": "19619851020796345517172409566066997550761738782112746767326655871669350897686", "price": "0.47", "size": "60", "side": "BUY", "hash": "142782468b11b86b8a5a110f11311a3ee4a9583a", "best_bid": "0.55", "best_ask": "0.56"}, {"asset_id": "108798918614128027361814219314538484133284583608074596451665946577336361445917", "price": "0.53", "size": "60", "side": "SELL", "hash": "77b6187ddf67e4ed8cff08edc3abdedc05305fe3", "best_bid": "0.44", "best_ask": "0.45"}], "timestamp": "1769384775664", "event_type": "price_change"}}
{"_local_timestamp": "2026-01-25T23:46:17.474870+00:00", "data": {"market": "0xefc69f5f48827e331957acbcc2339eb3b15e27e32453b8e6f29b5de67474c986", "price_changes": [{"asset_id": "19619851020796345517172409566066997550761738782112746767326655871669350897686", "price": "0.21", "size": "100", "side": "BUY", "hash": "87d0000272f8027a7f6a7597e5fa4a0455300f93", "best_bid": "0.55", "best_ask": "0.56"}, {"asset_id": "108798918614128027361814219314538484133284583608074596451665946577336361445917", "price": "0.79", "size": "100", "side": "SELL", "hash": "0fb508d7c82501d01e925797c15acac30bd384f7", "best_bid": "0.44", "best_ask": "0.45"}], "timestamp": "1769384777378", "event_type": "price_change"}}
{"_local_timestamp": "2026-01-25T23:46:17.719444+00:00", "data": {"market": "0xefc69f5f48827e331957acbcc2339eb3b15e27e32453b8e6f29b5de67474c986", "price_changes": [{"asset_id": "19619851020796345517172409566066997550761738782112746767326655871669350897686", "price": "0.25", "size": "221.73", "side": "BUY", "hash": "3d2977e2988b2346bb00341387c06fd3c9d1ff83", "best_bid": "0.55", "best_ask": "0.56"}, {"asset_id": "108798918614128027361814219314538484133284583608074596451665946577336361445917", "price": "0.75", "size": "221.73", "side": "SELL", "hash": "c3a8e7da33b7515373d587f5816f8792c1f062e2", "best_bid": "0.44", "best_ask": "0.45"}], "timestamp": "1769384777642", "event_type": "price_change"}}
{"_local_timestamp": "2026-01-25T23:46:27.757019+00:00", "data": {"market": "0xefc69f5f48827e331957acbcc2339eb3b15e27e32453b8e6f29b5de67474c986", "price_changes": [{"asset_id": "19619851020796345517172409566066997550761738782112746767326655871669350897686", "price": "0.15", "size": "2923", "side": "BUY", "hash": "b0a5a2d7bb80aa18cab9e50df1ab2e3ffeada182", "best_bid": "0.55", "best_ask": "0.56"}, {"asset_id": "108798918614128027361814219314538484133284583608074596451665946577336361445917", "price": "0.85", "size": "2923", "side": "SELL", "hash": "29b483c2b96acc4d64f2fbc5a7bbee3d08c64bf7", "best_bid": "0.44", "best_ask": "0.45"}], "timestamp": "1769384787663", "event_type": "price_change"}}
{"_local_timestamp": "2026-01-25T23:46:31.111274+00:00", "data": {"market": "0xefc69f5f48827e331957acbcc2339eb3b15e27e32453b8e6f29b5de67474c986", "price_changes": [{"asset_id": "19619851020796345517172409566066997550761738782112746767326655871669350897686", "price": "0.14", "size": "500", "side": "BUY", "hash": "3a9f0b4606d8ec978f275a8f99228325afff0135", "best_bid": "0.55", "best_ask": "0.56"}, {"asset_id": "108798918614128027361814219314538484133284583608074596451665946577336361445917", "price": "0.86", "size": "500", "side": "SELL", "hash": "a6c9c9bcdbfbf5311cfc4fac7729f515feedcc4b", "best_bid": "0.44", "best_ask": "0.45"}], "timestamp": "1769384791013", "event_type": "price_change"}}
{"_local_timestamp": "2026-01-25T23:46:31.111867+00:00", "data": {"market": "0xefc69f5f48827e331957acbcc2339eb3b15e27e32453b8e6f29b5de67474c986", "price_changes": [{"asset_id": "108798918614128027361814219314538484133284583608074596451665946577336361445917", "price": "0.14", "size": "485.71", "side": "BUY", "hash": "a860236e498f841367b7b181a6d22bc1d902f7c3", "best_bid": "0.44", "best_ask": "0.45"}, {"asset_id": "19619851020796345517172409566066997550761738782112746767326655871669350897686", "price": "0.86", "size": "485.71", "side": "SELL", "hash": "529f75c17825e2e78d53611a466aa7977804ae20", "best_bid": "0.55", "best_ask": "0.56"}], "timestamp": "1769384791015", "event_type": "price_change"}}
{"_local_timestamp": "2026-01-25T23:46:32.425648+00:00", "data": {"market": "0xefc69f5f48827e331957acbcc2339eb3b15e27e32453b8e6f29b5de67474c986", "price_changes": [{"asset_id": "19619851020796345517172409566066997550761738782112746767326655871669350897686", "price": "0.16", "size": "200", "side": "BUY", "hash": "0ee07cc9069d32b6b222926fbae839292d73dc8f", "best_bid": "0.55", "best_ask": "0.56"}, {"asset_id": "108798918614128027361814219314538484133284583608074596451665946577336361445917", "price": "0.84", "size": "200", "side": "SELL", "hash": "30e03af1ee1d370142920c32900c48865a0ce40a", "best_bid": "0.44", "best_ask": "0.45"}], "timestamp": "1769384792336", "event_type": "price_change"}}
{"_local_timestamp": "2026-01-25T23:46:32.700372+00:00", "data": {"market": "0xefc69f5f48827e331957acbcc2339eb3b15e27e32453b8e6f29b5de67474c986", "price_changes": [{"asset_id": "19619851020796345517172409566066997550761738782112746767326655871669350897686", "price": "0.13", "size": "1705", "side": "BUY", "hash": "50dd66a167440b95566300dd2945d305ec696cd1", "best_bid": "0.55", "best_ask": "0.56"}, {"asset_id": "108798918614128027361814219314538484133284583608074596451665946577336361445917", "price": "0.87", "size": "1705", "side": "SELL", "hash": "3a2950b8534fccb159887dc2eab0ded18b27cd06", "best_bid": "0.44", "best_ask": "0.45"}], "timestamp": "1769384792620", "event_type": "price_change"}}
{"_local_timestamp": "2026-01-25T23:46:50.838383+00:00", "data": {"market": "0xefc69f5f48827e331957acbcc2339eb3b15e27e32453b8e6f29b5de67474c986", "price_changes": [{"asset_id": "19619851020796345517172409566066997550761738782112746767326655871669350897686", "price": "0.13", "size": "1505", "side": "BUY", "hash": "95ff2844ec583b2f5cb87d83b87967f07b1eff8d", "best_bid": "0.55", "best_ask": "0.56"}, {"asset_id": "108798918614128027361814219314538484133284583608074596451665946577336361445917", "price": "0.87", "size": "1505", "side": "SELL", "hash": "6d89e558b2d37b4cdb5771a5f67418e9b92d29ae", "best_bid": "0.44", "best_ask": "0.45"}], "timestamp": "1769384810653", "event_type": "price_change"}}
{"_local_timestamp": "2026-01-25T23:46:50.839247+00:00", "data": {"market": "0xefc69f5f48827e331957acbcc2339eb3b15e27e32453b8e6f29b5de67474c986", "price_changes": [{"asset_id": "19619851020796345517172409566066997550761738782112746767326655871669350897686", "price": "0.17", "size": "152.94", "side": "BUY", "hash": "95ff2844ec583b2f5cb87d83b87967f07b1eff8d", "best_bid": "0.55", "best_ask": "0.56"}, {"asset_id": "108798918614128027361814219314538484133284583608074596451665946577336361445917", "price": "0.83", "size": "152.94", "side": "SELL", "hash": "6d89e558b2d37b4cdb5771a5f67418e9b92d29ae", "best_bid": "0.44", "best_ask": "0.45"}], "timestamp": "1769384810653", "event_type": "price_change"}}
{"_local_timestamp": "2026-01-25T23:46:51.469119+00:00", "data": {"market": "0xefc69f5f48827e331957acbcc2339eb3b15e27e32453b8e6f29b5de67474c986", "price_changes": [{"asset_id": "19619851020796345517172409566066997550761738782112746767326655871669350897686", "price": "0.15", "size": "3123", "side": "BUY", "hash": "dc172397616c494cbbca598f435b4e0632827a28", "best_bid": "0.55", "best_ask": "0.56"}, {"asset_id": "108798918614128027361814219314538484133284583608074596451665946577336361445917", "price": "0.85", "size": "3123", "side": "SELL", "hash": "ec2c383de6011be9967decf61ed0e14673a5cdc5", "best_bid": "0.44", "best_ask": "0.45"}], "timestamp": "1769384811246", "event_type": "price_change"}}
{"_local_timestamp": "2026-01-25T23:46:51.651421+00:00", "data": {"market": "0xefc69f5f48827e331957acbcc2339eb3b15e27e32453b8e6f29b5de67474c986", "price_changes": [{"asset_id": "19619851020796345517172409566066997550761738782112746767326655871669350897686", "price": "0.19", "size": "250", "side": "BUY", "hash": "9ed7a9d1b24ae1f691f0d63d0588458b01d92c0e", "best_bid": "0.55", "best_ask": "0.56"}, {"asset_id": "108798918614128027361814219314538484133284583608074596451665946577336361445917", "price": "0.81", "size": "250", "side": "SELL", "hash": "f2bc2a3043b63056dfa853f4f3a851f64eee5983", "best_bid": "0.44", "best_ask": "0.45"}], "timestamp": "1769384811254", "event_type": "price_change"}}
{"_local_timestamp": "2026-01-25T23:46:54.154005+00:00", "data": {"market": "0xefc69f5f48827e331957acbcc2339eb3b15e27e32453b8e6f29b5de67474c986", "price_changes": [{"asset_id": "19619851020796345517172409566066997550761738782112746767326655871669350897686", "price": "0.18", "size": "0", "side": "BUY", "hash": "91acc356ad022cb18db2e0006aa28655860b4e6d", "best_bid": "0.55", "best_ask": "0.56"}, {"asset_id": "108798918614128027361814219314538484133284583608074596451665946577336361445917", "price": "0.82", "size": "0", "side": "SELL", "hash": "8a4ebce06b2abacff52017838feca6b9f554ab91", "best_bid": "0.44", "best_ask": "0.45"}], "timestamp": "1769384814085", "event_type": "price_change"}}
{"_local_timestamp": "2026-01-25T23:46:54.177700+00:00", "data": {"market": "0xefc69f5f48827e331957acbcc2339eb3b15e27e32453b8e6f29b5de67474c986", "price_changes": [{"asset_id": "19619851020796345517172409566066997550761738782112746767326655871669350897686", "price": "0.16", "size": "1569", "side": "BUY", "hash": "78bf87cdb4a2d10e7d587b2980b2037792b73ef2", "best_bid": "0.55", "best_ask": "0.56"}, {"asset_id": "108798918614128027361814219314538484133284583608074596451665946577336361445917", "price": "0.84", "size": "1569", "side": "SELL", "hash": "d4f6944c815a43bd5115fe9d9ba6bdfdf2352165", "best_bid": "0.44", "best_ask": "0.45"}], "timestamp": "1769384814104", "event_type": "price_change"}}
{"_local_timestamp": "2026-01-25T23:46:55.297198+00:00", "data": {"market": "0xefc69f5f48827e331957acbcc2339eb3b15e27e32453b8e6f29b5de67474c986", "price_changes": [{"asset_id": "19619851020796345517172409566066997550761738782112746767326655871669350897686", "price": "0.13", "size": "1455", "side": "BUY", "hash": "c40680779b31a38f364dbb418984b0629a7b1eeb", "best_bid": "0.55", "best_ask": "0.56"}, {"asset_id": "108798918614128027361814219314538484133284583608074596451665946577336361445917", "price": "0.87", "size": "1455", "side": "SELL", "hash": "58af7624f0810a2c291658dd83238f0c48b19f92", "best_bid": "0.44", "best_ask": "0.45"}], "timestamp": "1769384815225", "event_type": "price_change"}}
{"_local_timestamp": "2026-01-25T23:46:55.559018+00:00", "data": {"market": "0xefc69f5f48827e331957acbcc2339eb3b15e27e32453b8e6f29b5de67474c986", "price_changes": [{"asset_id": "19619851020796345517172409566066997550761738782112746767326655871669350897686", "price": "0.15", "size": "3173", "side": "BUY", "hash": "7c7a7149beca0d963acfb2a80bad8b4312996d37", "best_bid": "0.55", "best_ask": "0.56"}, {"asset_id": "108798918614128027361814219314538484133284583608074596451665946577336361445917", "price": "0.85", "size": "3173", "side": "SELL", "hash": "9a18ebbc26c2f5065405c1860ea2575dc8539bbf", "best_bid": "0.44", "best_ask": "0.45"}], "timestamp": "1769384815491", "event_type": "price_change"}}
{"_local_timestamp": "2026-01-25T23:46:58.515282+00:00", "data": {"market": "0xefc69f5f48827e331957acbcc2339eb3b15e27e32453b8e6f29b5de67474c986", "price_changes": [{"asset_id": "19619851020796345517172409566066997550761738782112746767326655871669350897686", "price": "0.16", "size": "1519", "side": "BUY", "hash": "73b30529098ca5432ed6a1e65b80cf734c85ef66", "best_bid": "0.55", "best_ask": "0.56"}, {"asset_id": "108798918614128027361814219314538484133284583608074596451665946577336361445917", "price": "0.84", "size": "1519", "side": "SELL", "hash": "07149f6541e84fae53a3e628e3669ccba1135270", "best_bid": "0.44", "best_ask": "0.45"}], "timestamp": "1769384818400", "event_type": "price_change"}}
{"_local_timestamp": "2026-01-25T23:46:58.793927+00:00", "data": {"market": "0xefc69f5f48827e331957acbcc2339eb3b15e27e32453b8e6f29b5de67474c986", "price_changes": [{"asset_id": "19619851020796345517172409566066997550761738782112746767326655871669350897686", "price": "0.18", "size": "50", "side": "BUY", "hash": "55839ec9a8c65abceb6a21c012094471fde9f145", "best_bid": "0.55", "best_ask": "0.56"}, {"asset_id": "108798918614128027361814219314538484133284583608074596451665946577336361445917", "price": "0.82", "size": "50", "side": "SELL", "hash": "a8f7d6daa2e5d0fb6a46844ca5d39b735c572403", "best_bid": "0.44", "best_ask": "0.45"}], "timestamp": "1769384818708", "event_type": "price_change"}}
{"_local_timestamp": "2026-01-25T23:46:58.966065+00:00", "data": {"market": "0xefc69f5f48827e331957acbcc2339eb3b15e27e32453b8e6f29b5de67474c986", "price_changes": [{"asset_id": "19619851020796345517172409566066997550761738782112746767326655871669350897686", "price": "0.16", "size": "1369", "side": "BUY", "hash": "5b2755eb17ae3c6e473a71c0cd3fc809534828a5", "best_bid": "0.55", "best_ask": "0.56"}, {"asset_id": "108798918614128027361814219314538484133284583608074596451665946577336361445917", "price": "0.84", "size": "1369", "side": "SELL", "hash": "d21e4bec14b2abdbbf6ae3e7f620f8ec23b0f108", "best_bid": "0.44", "best_ask": "0.45"}], "timestamp": "1769384818863", "event_type": "price_change"}}
{"_local_timestamp": "2026-01-25T23:46:59.332403+00:00", "data": {"market": "0xefc69f5f48827e331957acbcc2339eb3b15e27e32453b8e6f29b5de67474c986", "price_changes": [{"asset_id": "19619851020796345517172409566066997550761738782112746767326655871669350897686", "price": "0.18", "size": "200", "side": "BUY", "hash": "adff2c5fdda32b447dc1ee0d3e91f4e1fabbe0e1", "best_bid": "0.55", "best_ask": "0.56"}, {"asset_id": "108798918614128027361814219314538484133284583608074596451665946577336361445917", "price": "0.82", "size": "200", "side": "SELL", "hash": "1c5cf675563d99694d7625da4aef8bb5c24f25a9", "best_bid": "0.44", "best_ask": "0.45"}], "timestamp": "1769384819184", "event_type": "price_change"}}
{"_local_timestamp": "2026-01-25T23:46:59.449871+00:00", "data": {"market": "0xefc69f5f48827e331957acbcc2339eb3b15e27e32453b8e6f29b5de67474c986", "price_changes": [{"asset_id": "108798918614128027361814219314538484133284583608074596451665946577336361445917", "price": "0.42", "size": "765.52", "side": "BUY", "hash": "3aa39a9abdfb2157904e9c7c867affa506257b0b", "best_bid": "0.44", "best_ask": "0.45"}, {"asset_id": "19619851020796345517172409566066997550761738782112746767326655871669350897686", "price": "0.58", "size": "765.52", "side": "SELL", "hash": "2b42a6cdadfa87636b54f90c57867b89b8ceb633", "best_bid": "0.55", "best_ask": "0.56"}], "timestamp": "1769384819380", "event_type": "price_change"}}
{"_local_timestamp": "2026-01-25T23:47:00.744952+00:00", "data": {"market": "0xefc69f5f48827e331957acbcc2339eb3b15e27e32453b8e6f29b5de67474c986", "price_changes": [{"asset_id": "108798918614128027361814219314538484133284583608074596451665946577336361445917", "price": "0.43", "size": "1008.99", "side": "BUY", "hash": "a6c982e2434f4e825588ec3b3d6de3db329565e8", "best_bid": "0.44", "best_ask": "0.45"}, {"asset_id": "19619851020796345517172409566066997550761738782112746767326655871669350897686", "price": "0.57", "size": "1008.99", "side": "SELL", "hash": "a86cd26f1e5d7a1a5be3ab21c77caf7e6fd5153d", "best_bid": "0.55", "best_ask": "0.56"}], "timestamp": "1769384820674", "event_type": "price_change"}}
{"_local_timestamp": "2026-01-25T23:47:23.573347+00:00", "data": {"market": "0xefc69f5f48827e331957acbcc2339eb3b15e27e32453b8e6f29b5de67474c986", "price_changes": [{"asset_id": "19619851020796345517172409566066997550761738782112746767326655871669350897686", "price": "0.21", "size": "50", "side": "BUY", "hash": "62ddab68895fb9732a7220048fd66bad064f83fb", "best_bid": "0.55", "best_ask": "0.56"}, {"asset_id": "108798918614128027361814219314538484133284583608074596451665946577336361445917", "price": "0.79", "size": "50", "side": "SELL", "hash": "195576732e75247ec22e7427372f7d1607bf4383", "best_bid": "0.44", "best_ask": "0.45"}], "timestamp": "1769384843406", "event_type": "price_change"}}
{"_local_timestamp": "2026-01-25T23:47:37.444059+00:00", "data": {"market": "0xefc69f5f48827e331957acbcc2339eb3b15e27e32453b8e6f29b5de67474c986", "price_changes": [{"asset_id": "19619851020796345517172409566066997550761738782112746767326655871669350897686", "price": "0.13", "size": "1230", "side": "BUY", "hash": "a5d49347324ac70978b77e37b0521bcd71b3d5c5", "best_bid": "0.55", "best_ask": "0.56"}, {"asset_id": "108798918614128027361814219314538484133284583608074596451665946577336361445917", "price": "0.87", "size": "1230", "side": "SELL", "hash": "42ddb86ff7795ac14e9d6450a75641a56f6c9c0b", "best_bid": "0.44", "best_ask": "0.45"}], "timestamp": "1769384857306", "event_type": "price_change"}}
{"_local_timestamp": "2026-01-25T23:47:37.447806+00:00", "data": {"market": "0xefc69f5f48827e331957acbcc2339eb3b15e27e32453b8e6f29b5de67474c986", "price_changes": [{"asset_id": "19619851020796345517172409566066997550761738782112746767326655871669350897686", "price": "0.18", "size": "50", "side": "BUY", "hash": "a5d49347324ac70978b77e37b0521bcd71b3d5c5", "best_bid": "0.55", "best_ask": "0.56"}, {"asset_id": "108798918614128027361814219314538484133284583608074596451665946577336361445917", "price": "0.82", "size": "50", "side": "SELL", "hash": "42ddb86ff7795ac14e9d6450a75641a56f6c9c0b", "best_bid": "0.44", "best_ask": "0.45"}], "timestamp": "1769384857306", "event_type": "price_change"}}
{"_local_timestamp": "2026-01-25T23:47:37.680399+00:00", "data": {"market": "0xefc69f5f48827e331957acbcc2339eb3b15e27e32453b8e6f29b5de67474c986", "price_changes": [{"asset_id": "19619851020796345517172409566066997550761738782112746767326655871669350897686", "price": "0.21", "size": "0", "side": "BUY", "hash": "37ee6fa5badd69cb231d0f47ee5f33134151e2d5", "best_bid": "0.55", "best_ask": "0.56"}, {"asset_id": "108798918614128027361814219314538484133284583608074596451665946577336361445917", "price": "0.79", "size": "0", "side": "SELL", "hash": "9862ed9de56ac0e34552eb48d0adb6346d0834c1", "best_bid": "0.44", "best_ask": "0.45"}], "timestamp": "1769384857533", "event_type": "price_change"}}
{"_local_timestamp": "2026-01-25T23:47:37.682656+00:00", "data": {"market": "0xefc69f5f48827e331957acbcc2339eb3b15e27e32453b8e6f29b5de67474c986", "price_changes": [{"asset_id": "19619851020796345517172409566066997550761738782112746767326655871669350897686", "price": "0.19", "size": "150", "side": "BUY", "hash": "37ee6fa5badd69cb231d0f47ee5f33134151e2d5", "best_bid": "0.55", "best_ask": "0.56"}, {"asset_id": "108798918614128027361814219314538484133284583608074596451665946577336361445917", "price": "0.81", "size": "150", "side": "SELL", "hash": "9862ed9de56ac0e34552eb48d0adb6346d0834c1", "best_bid": "0.44", "best_ask": "0.45"}], "timestamp": "1769384857533", "event_type": "price_change"}}
{"_local_timestamp": "2026-01-25T23:47:37.683254+00:00", "data": {"market": "0xefc69f5f48827e331957acbcc2339eb3b15e27e32453b8e6f29b5de67474c986", "price_changes": [{"asset_id": "19619851020796345517172409566066997550761738782112746767326655871669350897686", "price": "0.15", "size": "3048", "side": "BUY", "hash": "37ee6fa5badd69cb231d0f47ee5f33134151e2d5", "best_bid": "0.55", "best_ask": "0.56"}, {"asset_id": "108798918614128027361814219314538484133284583608074596451665946577336361445917", "price": "0.85", "size": "3048", "side": "SELL", "hash": "9862ed9de56ac0e34552eb48d0adb6346d0834c1", "best_bid": "0.44", "best_ask": "0.45"}], "timestamp": "1769384857533", "event_type": "price_change"}}
{"_local_timestamp": "2026-01-25T23:47:37.915460+00:00", "data": {"market": "0xefc69f5f48827e331957acbcc2339eb3b15e27e32453b8e6f29b5de67474c986", "price_changes": [{"asset_id": "19619851020796345517172409566066997550761738782112746767326655871669350897686", "price": "0.15", "size": "3273", "side": "BUY", "hash": "99cdb96b26d8c8cd6d21f3eef7f01718f99c9479", "best_bid": "0.55", "best_ask": "0.56"}, {"asset_id": "108798918614128027361814219314538484133284583608074596451665946577336361445917", "price": "0.85", "size": "3273", "side": "SELL", "hash": "12d90339c1638ded404e9171108e482e056cb3bc", "best_bid": "0.44", "best_ask": "0.45"}], "timestamp": "1769384857601", "event_type": "price_change"}}
{"_local_timestamp": "2026-01-25T23:47:37.956095+00:00", "data": {"market": "0xefc69f5f48827e331957acbcc2339eb3b15e27e32453b8e6f29b5de67474c986", "price_changes": [{"asset_id": "19619851020796345517172409566066997550761738782112746767326655871669350897686", "price": "0.16", "size": "1519", "side": "BUY", "hash": "6afe732d06ca89fd0a1d9b2e75ec3117a8c91fc4", "best_bid": "0.55", "best_ask": "0.56"}, {"asset_id": "108798918614128027361814219314538484133284583608074596451665946577336361445917", "price": "0.84", "size": "1519", "side": "SELL", "hash": "5eaeca0c55747323aa58ee9e1fb1fe433f580869", "best_bid": "0.44", "best_ask": "0.45"}], "timestamp": "1769384857662", "event_type": "price_change"}}
{"_local_timestamp": "2026-01-25T23:47:38.284752+00:00", "data": {"market": "0xefc69f5f48827e331957acbcc2339eb3b15e27e32453b8e6f29b5de67474c986", "price_changes": [{"asset_id": "19619851020796345517172409566066997550761738782112746767326655871669350897686", "price": "0.13", "size": "1355", "side": "BUY", "hash": "3c051adf6787cfa74ea8eef030cc2462ca05dc9a", "best_bid": "0.55", "best_ask": "0.56"}, {"asset_id": "108798918614128027361814219314538484133284583608074596451665946577336361445917", "price": "0.87", "size": "1355", "side": "SELL", "hash": "91ce2e17cb20702d84407ea910b2676f50eeb532", "best_bid": "0.44", "best_ask": "0.45"}], "timestamp": "1769384858042", "event_type": "price_change"}}
{"_local_timestamp": "2026-01-25T23:47:38.462436+00:00", "data": {"market": "0xefc69f5f48827e331957acbcc2339eb3b15e27e32453b8e6f29b5de67474c986", "price_changes": [{"asset_id": "19619851020796345517172409566066997550761738782112746767326655871669350897686", "price": "0.16", "size": "1619", "side": "BUY", "hash": "91f7678596cedc94541b924ba9177c297e6ad2fc", "best_bid": "0.55", "best_ask": "0.56"}, {"asset_id": "108798918614128027361814219314538484133284583608074596451665946577336361445917", "price": "0.84", "size": "1619", "side": "SELL", "hash": "e85e7f11bb6726e67d13c19a7fb9507b31fbb3b6", "best_bid": "0.44", "best_ask": "0.45"}], "timestamp": "1769384858172", "event_type": "price_change"}}
{"_local_timestamp": "2026-01-25T23:47:45.610030+00:00", "data": {"market": "0xefc69f5f48827e331957acbcc2339eb3b15e27e32453b8e6f29b5de67474c986", "price_changes": [{"asset_id": "19619851020796345517172409566066997550761738782112746767326655871669350897686", "price": "0.18", "size": "0", "side": "BUY", "hash": "6f6d86818d5b33d1a60d59861f78b8d57c8f1027", "best_bid": "0.55", "best_ask": "0.56"}, {"asset_id": "108798918614128027361814219314538484133284583608074596451665946577336361445917", "price": "0.82", "size": "0", "side": "SELL", "hash": "d738ea80784b5e1c1d8e20fafbe11ff200977600", "best_bid": "0.44", "best_ask": "0.45"}], "timestamp": "1769384865514", "event_type": "price_change"}}
{"_local_timestamp": "2026-01-25T23:47:45.921337+00:00", "data": {"market": "0xefc69f5f48827e331957acbcc2339eb3b15e27e32453b8e6f29b5de67474c986", "price_changes": [{"asset_id": "19619851020796345517172409566066997550761738782112746767326655871669350897686", "price": "0.15", "size": "3323", "side": "BUY", "hash": "83c9f9ca39e5d710f2e9e54a0a75c44117ca926f", "best_bid": "0.55", "best_ask": "0.56"}, {"asset_id": "108798918614128027361814219314538484133284583608074596451665946577336361445917", "price": "0.85", "size": "3323", "side": "SELL", "hash": "39c29376466c1fffd0a6d84b5feeb20f7e048b16", "best_bid": "0.44", "best_ask": "0.45"}], "timestamp": "1769384865837", "event_type": "price_change"}}
{"_local_timestamp": "2026-01-25T23:47:55.633771+00:00", "data": {"market": "0xefc69f5f48827e331957acbcc2339eb3b15e27e32453b8e6f29b5de67474c986", "price_changes": [{"asset_id": "19619851020796345517172409566066997550761738782112746767326655871669350897686", "price": "0.15", "size": "525", "side": "BUY", "hash": "6396153f77f12737e1631b2b8af143a63208e589", "best_bid": "0.55", "best_ask": "0.56"}, {"asset_id": "108798918614128027361814219314538484133284583608074596451665946577336361445917", "price": "0.85", "size": "525", "side": "SELL", "hash": "82ebbb74bffeeac2ac1b3c7169ea024662f4c101", "best_bid": "0.44", "best_ask": "0.45"}], "timestamp": "1769384875420", "event_type": "price_change"}}
{"_local_timestamp": "2026-01-25T23:48:02.086392+00:00", "data": {"market": "0xefc69f5f48827e331957acbcc2339eb3b15e27e32453b8e6f29b5de67474c986", "price_changes": [{"asset_id": "19619851020796345517172409566066997550761738782112746767326655871669350897686", "price": "0.42", "size": "52", "side": "BUY", "hash": "01568ad0b158e69e63792379cd80b212d6ea864c", "best_bid": "0.55", "best_ask": "0.56"}, {"asset_id": "108798918614128027361814219314538484133284583608074596451665946577336361445917", "price": "0.58", "size": "52", "side": "SELL", "hash": "5c3d8b7562dc9b40a2dd2bfd9462927aee7863ce", "best_bid": "0.44", "best_ask": "0.45"}], "timestamp": "1769384882000", "event_type": "price_change"}}
{"_local_timestamp": "2026-01-25T23:48:23.713282+00:00", "data": {"market": "0xefc69f5f48827e331957acbcc2339eb3b15e27e32453b8e6f29b5de67474c986", "price_changes": [{"asset_id": "19619851020796345517172409566066997550761738782112746767326655871669350897686", "price": "0.15", "size": "475", "side": "BUY", "hash": "9bcd21c58bf1beff772f5adb4c0afc7466a734c8", "best_bid": "0.55", "best_ask": "0.56"}, {"asset_id": "108798918614128027361814219314538484133284583608074596451665946577336361445917", "price": "0.85", "size": "475", "side": "SELL", "hash": "73057cb13d0fe26711e90d6ebd8820b0db2bdd78", "best_bid": "0.44", "best_ask": "0.45"}], "timestamp": "1769384903649", "event_type": "price_change"}}
{"_local_timestamp": "2026-01-25T23:48:24.004997+00:00", "data": {"market": "0xefc69f5f48827e331957acbcc2339eb3b15e27e32453b8e6f29b5de67474c986", "price_changes": [{"asset_id": "19619851020796345517172409566066997550761738782112746767326655871669350897686", "price": "0.16", "size": "1669", "side": "BUY", "hash": "1e2a52475852b8e242b7ad63308e7d718b9d41c9", "best_bid": "0.55", "best_ask": "0.56"}, {"asset_id": "108798918614128027361814219314538484133284583608074596451665946577336361445917", "price": "0.84", "size": "1669", "side": "SELL", "hash": "184779bbf1608e06286cbee564f6ae87d491d91b", "best_bid": "0.44", "best_ask": "0.45"}], "timestamp": "1769384903942", "event_type": "price_change"}}
{"_local_timestamp": "2026-01-25T23:48:26.119928+00:00", "data": {"market": "0xefc69f5f48827e331957acbcc2339eb3b15e27e32453b8e6f29b5de67474c986", "price_changes": [{"asset_id": "19619851020796345517172409566066997550761738782112746767326655871669350897686", "price": "0.15", "size": "425", "side": "BUY", "hash": "ce625939d79903f3c11552ef176da9f9b8bfde0e", "best_bid": "0.55", "best_ask": "0.56"}, {"asset_id": "108798918614128027361814219314538484133284583608074596451665946577336361445917", "price": "0.85", "size": "425", "side": "SELL", "hash": "1a8186f90061cc678967dc31cf2988e62a61514c", "best_bid": "0.44", "best_ask": "0.45"}], "timestamp": "1769384906026", "event_type": "price_change"}}
{"_local_timestamp": "2026-01-25T23:48:26.366852+00:00", "data": {"market": "0xefc69f5f48827e331957acbcc2339eb3b15e27e32453b8e6f29b5de67474c986", "price_changes": [{"asset_id": "19619851020796345517172409566066997550761738782112746767326655871669350897686", "price": "0.16", "size": "1719", "side": "BUY", "hash": "d87470ab18d709ec1c8eeb44bde389c2ccc09646", "best_bid": "0.55", "best_ask": "0.56"}, {"asset_id": "108798918614128027361814219314538484133284583608074596451665946577336361445917", "price": "0.84", "size": "1719", "side": "SELL", "hash": "027622046ae5287fc8b2c956ab15ed52222bab32", "best_bid": "0.44", "best_ask": "0.45"}], "timestamp": "1769384906300", "event_type": "price_change"}}
{"_local_timestamp": "2026-01-25T23:48:36.476752+00:00", "data": {"market": "0xefc69f5f48827e331957acbcc2339eb3b15e27e32453b8e6f29b5de67474c986", "price_changes": [{"asset_id": "19619851020796345517172409566066997550761738782112746767326655871669350897686", "price": "0.17", "size": "2622.94", "side": "BUY", "hash": "ff24f51fb60e7fb3bec8ad4a1b121d7d791a25ca", "best_bid": "0.55", "best_ask": "0.56"}, {"asset_id": "108798918614128027361814219314538484133284583608074596451665946577336361445917", "price": "0.83", "size": "2622.94", "side": "SELL", "hash": "b3236e3f9f783982a1732f1d1e51f6a1f9fad1db", "best_bid": "0.44", "best_ask": "0.45"}], "timestamp": "1769384916406", "event_type": "price_change"}}
{"_local_timestamp": "2026-01-25T23:48:48.667766+00:00", "data": {"market": "0xefc69f5f48827e331957acbcc2339eb3b15e27e32453b8e6f29b5de67474c986", "price_changes": [{"asset_id": "19619851020796345517172409566066997550761738782112746767326655871669350897686", "price": "0.15", "size": "200", "side": "BUY", "hash": "1fe9e9a3053932c579cb2adea34da44a88b300bc", "best_bid": "0.55", "best_ask": "0.56"}, {"asset_id": "108798918614128027361814219314538484133284583608074596451665946577336361445917", "price": "0.85", "size": "200", "side": "SELL", "hash": "e9b3592ac2e23b99d3fc86521a26a27526cfb8a1", "best_bid": "0.44", "best_ask": "0.45"}], "timestamp": "1769384928579", "event_type": "price_change"}}
{"_local_timestamp": "2026-01-25T23:48:48.917788+00:00", "data": {"market": "0xefc69f5f48827e331957acbcc2339eb3b15e27e32453b8e6f29b5de67474c986", "price_changes": [{"asset_id": "19619851020796345517172409566066997550761738782112746767326655871669350897686", "price": "0.13", "size": "1580", "side": "BUY", "hash": "a34539ab97c84fd8083913869cb960d34cb41d7f", "best_bid": "0.55", "best_ask": "0.56"}, {"asset_id": "108798918614128027361814219314538484133284583608074596451665946577336361445917", "price": "0.87", "size": "1580", "side": "SELL", "hash": "31a91e4686f0d1a57f62ff0023ff47ee54491a70", "best_bid": "0.44", "best_ask": "0.45"}], "timestamp": "1769384928841", "event_type": "price_change"}}
{"_local_timestamp": "2026-01-25T23:48:57.086705+00:00", "data": {"market": "0xefc69f5f48827e331957acbcc2339eb3b15e27e32453b8e6f29b5de67474c986", "price_changes": [{"asset_id": "19619851020796345517172409566066997550761738782112746767326655871669350897686", "price": "0.42", "size": "21", "side": "BUY", "hash": "6b2c4d4ce932bed1987ca558cc59654dd86c0761", "best_bid": "0.55", "best_ask": "0.56"}, {"asset_id": "108798918614128027361814219314538484133284583608074596451665946577336361445917", "price": "0.58", "size": "21", "side": "SELL", "hash": "050aa76959628e1dd58dfc6296f8e128c704f2ad", "best_bid": "0.44", "best_ask": "0.45"}], "timestamp": "1769384937001", "event_type": "price_change"}}
{"_local_timestamp": "2026-01-25T23:49:00.209890+00:00", "data": {"market": "0xefc69f5f48827e331957acbcc2339eb3b15e27e32453b8e6f29b5de67474c986", "price_changes": [{"asset_id": "19619851020796345517172409566066997550761738782112746767326655871669350897686", "price": "0.16", "size": "350", "side": "BUY", "hash": "b6a3bc0f7d47c1d344241774c64fd63215fe19f0", "best_bid": "0.55", "best_ask": "0.56"}, {"asset_id": "108798918614128027361814219314538484133284583608074596451665946577336361445917", "price": "0.84", "size": "350", "side": "SELL", "hash": "53f726cf11b86c48f5e2ef2db1fbdd7d8b33824f", "best_bid": "0.44", "best_ask": "0.45"}], "timestamp": "1769384940139", "event_type": "price_change"}}
{"_local_timestamp": "2026-01-25T23:49:00.259497+00:00", "data": {"market": "0xefc69f5f48827e331957acbcc2339eb3b15e27e32453b8e6f29b5de67474c986", "price_changes": [{"asset_id": "19619851020796345517172409566066997550761738782112746767326655871669350897686", "price": "0.18", "size": "1217", "side": "BUY", "hash": "c4efeecf57762fbf427a1fc79936cbf444acb9a4", "best_bid": "0.55", "best_ask": "0.56"}, {"asset_id": "108798918614128027361814219314538484133284583608074596451665946577336361445917", "price": "0.82", "size": "1217", "side": "SELL", "hash": "adfb99c1920cbad1b45fb0eb058e82e20e1806f0", "best_bid": "0.44", "best_ask": "0.45"}], "timestamp": "1769384940193", "event_type": "price_change"}}
{"_local_timestamp": "2026-01-25T23:49:00.260273+00:00", "data": {"market": "0xefc69f5f48827e331957acbcc2339eb3b15e27e32453b8e6f29b5de67474c986", "price_changes": [{"asset_id": "19619851020796345517172409566066997550761738782112746767326655871669350897686", "price": "0.42", "size": "131", "side": "BUY", "hash": "0bcffd6d0df378edaed4a0731567e88218922978", "best_bid": "0.55", "best_ask": "0.56"}, {"asset_id": "108798918614128027361814219314538484133284583608074596451665946577336361445917", "price": "0.58", "size": "131", "side": "SELL", "hash": "5f33108a3c6b33866b640dcde88717c8064ab5a4", "best_bid": "0.44", "best_ask": "0.45"}], "timestamp": "1769384940194", "event_type": "price_change"}}
{"_local_timestamp": "2026-01-25T23:49:07.504134+00:00", "data": {"market": "0xefc69f5f48827e331957acbcc2339eb3b15e27e32453b8e6f29b5de67474c986", "price_changes": [{"asset_id": "19619851020796345517172409566066997550761738782112746767326655871669350897686", "price": "0.16", "size": "300", "side": "BUY", "hash": "d63447d2c8c409f82dabb18d37ca2552a313454b", "best_bid": "0.55", "best_ask": "0.56"}, {"asset_id": "108798918614128027361814219314538484133284583608074596451665946577336361445917", "price": "0.84", "size": "300", "side": "SELL", "hash": "2e472e3a8e8d4acbf3a581d379decf8c0e8ee5a0", "best_bid": "0.44", "best_ask": "0.45"}], "timestamp": "1769384947438", "event_type": "price_change"}}
{"_local_timestamp": "2026-01-25T23:49:07.792978+00:00", "data": {"market": "0xefc69f5f48827e331957acbcc2339eb3b15e27e32453b8e6f29b5de67474c986", "price_changes": [{"asset_id": "19619851020796345517172409566066997550761738782112746767326655871669350897686", "price": "0.17", "size": "2672.94", "side": "BUY", "hash": "43b0ec64e37f2463b189eb0cf0b38bf05be7ffc0", "best_bid": "0.55", "best_ask": "0.56"}, {"asset_id": "108798918614128027361814219314538484133284583608074596451665946577336361445917", "price": "0.83", "size": "2672.94", "side": "SELL", "hash": "168249abdfae8deff9b13b173f940e08eeddd36c", "best_bid": "0.44", "best_ask": "0.45"}], "timestamp": "1769384947706", "event_type": "price_change"}}
{"_local_timestamp": "2026-01-25T23:49:09.169756+00:00", "data": {"market": "0xefc69f5f48827e331957acbcc2339eb3b15e27e32453b8e6f29b5de67474c986", "price_changes": [{"asset_id": "19619851020796345517172409566066997550761738782112746767326655871669350897686", "price": "0.16", "size": "250", "side": "BUY", "hash": "9061637f70f15e446142100b7ea45628636f3bb6", "best_bid": "0.55", "best_ask": "0.56"}, {"asset_id": "108798918614128027361814219314538484133284583608074596451665946577336361445917", "price": "0.84", "size": "250", "side": "SELL", "hash": "e7281adb55962dc1a3178b017b6d01f0547504dd", "best_bid": "0.44", "best_ask": "0.45"}], "timestamp": "1769384949091", "event_type": "price_change"}}
{"_local_timestamp": "2026-01-25T23:49:09.509201+00:00", "data": {"market": "0xefc69f5f48827e331957acbcc2339eb3b15e27e32453b8e6f29b5de67474c986", "price_changes": [{"asset_id": "19619851020796345517172409566066997550761738782112746767326655871669350897686", "price": "0.17", "size": "2722.94", "side": "BUY", "hash": "0bf25c7235a1153def0cb315458738256c79cf9f", "best_bid": "0.55", "best_ask": "0.56"}, {"asset_id": "108798918614128027361814219314538484133284583608074596451665946577336361445917", "price": "0.83", "size": "2722.94", "side": "SELL", "hash": "0009ae687b00081fe16da8a624474da57f31043a", "best_bid": "0.44", "best_ask": "0.45"}], "timestamp": "1769384949416", "event_type": "price_change"}}
{"_local_timestamp": "2026-01-25T23:49:24.497509+00:00", "data": {"market": "0xefc69f5f48827e331957acbcc2339eb3b15e27e32453b8e6f29b5de67474c986", "price_changes": [{"asset_id": "19619851020796345517172409566066997550761738782112746767326655871669350897686", "price": "0.16", "size": "100", "side": "BUY", "hash": "b1ac69eb34bc980dbb41b857fddffb5705c79495", "best_bid": "0.55", "best_ask": "0.56"}, {"asset_id": "108798918614128027361814219314538484133284583608074596451665946577336361445917", "price": "0.84", "size": "100", "side": "SELL", "hash": "6888595de588e728512149a6c74fc3daeb447e37", "best_bid": "0.44", "best_ask": "0.45"}], "timestamp": "1769384964413", "event_type": "price_change"}}
{"_local_timestamp": "2026-01-25T23:49:24.789552+00:00", "data": {"market": "0xefc69f5f48827e331957acbcc2339eb3b15e27e32453b8e6f29b5de67474c986", "price_changes": [{"asset_id": "19619851020796345517172409566066997550761738782112746767326655871669350897686", "price": "0.17", "size": "2872.94", "side": "BUY", "hash": "bb5fa18c2e47e606c10152111f45fb6cf3e7ec5e", "best_bid": "0.55", "best_ask": "0.56"}, {"asset_id": "108798918614128027361814219314538484133284583608074596451665946577336361445917", "price": "0.83", "size": "2872.94", "side": "SELL", "hash": "c5a0550941b21de86b55484488887bba4370bd58", "best_bid": "0.44", "best_ask": "0.45"}], "timestamp": "1769384964687", "event_type": "price_change"}}
{"_local_timestamp": "2026-01-25T23:49:25.370863+00:00", "data": {"market": "0xefc69f5f48827e331957acbcc2339eb3b15e27e32453b8e6f29b5de67474c986", "price_changes": [{"asset_id": "19619851020796345517172409566066997550761738782112746767326655871669350897686", "price": "0.13", "size": "1455", "side": "BUY", "hash": "9982853755d1485e6b47fafcdb7f9f6fff31f430", "best_bid": "0.55", "best_ask": "0.56"}, {"asset_id": "108798918614128027361814219314538484133284583608074596451665946577336361445917", "price": "0.87", "size": "1455", "side": "SELL", "hash": "756e1128c503ca7e3680244bcb386e80fd468b0d", "best_bid": "0.44", "best_ask": "0.45"}], "timestamp": "1769384965270", "event_type": "price_change"}}
{"_local_timestamp": "2026-01-25T23:49:25.980343+00:00", "data": {"market": "0xefc69f5f48827e331957acbcc2339eb3b15e27e32453b8e6f29b5de67474c986", "price_changes": [{"asset_id": "19619851020796345517172409566066997550761738782112746767326655871669350897686", "price": "0.15", "size": "325", "side": "BUY", "hash": "a2e03e10622dc6a595d3c43262c5fbc19a1227b6", "best_bid": "0.55", "best_ask": "0.56"}, {"asset_id": "108798918614128027361814219314538484133284583608074596451665946577336361445917", "price": "0.85", "size": "325", "side": "SELL", "hash": "31b40d989cb29e718040e678a98b707706bf4afb", "best_bid": "0.44", "best_ask": "0.45"}], "timestamp": "1769384965792", "event_type": "price_change"}}
{"_local_timestamp": "2026-01-25T23:49:30.456617+00:00", "data": {"market": "0xefc69f5f48827e331957acbcc2339eb3b15e27e32453b8e6f29b5de67474c986", "price_changes": [{"asset_id": "19619851020796345517172409566066997550761738782112746767326655871669350897686", "price": "0.25", "size": "121.73", "side": "BUY", "hash": "f88e313e2259657da51c8408487027c099eb9258", "best_bid": "0.55", "best_ask": "0.56"}, {"asset_id": "108798918614128027361814219314538484133284583608074596451665946577336361445917", "price": "0.75", "size": "121.73", "side": "SELL", "hash": "30d1e8063bc3d9de459310c7bbdbbe93243e25e9", "best_bid": "0.44", "best_ask": "0.45"}], "timestamp": "1769384970059", "event_type": "price_change"}}
{"_local_timestamp": "2026-01-25T23:49:30.457596+00:00", "data": {"market": "0xefc69f5f48827e331957acbcc2339eb3b15e27e32453b8e6f29b5de67474c986", "price_changes": [{"asset_id": "19619851020796345517172409566066997550761738782112746767326655871669350897686", "price": "0.19", "size": "0", "side": "BUY", "hash": "f88e313e2259657da51c8408487027c099eb9258", "best_bid": "0.55", "best_ask": "0.56"}, {"asset_id": "108798918614128027361814219314538484133284583608074596451665946577336361445917", "price": "0.81", "size": "0", "side": "SELL", "hash": "30d1e8063bc3d9de459310c7bbdbbe93243e25e9", "best_bid": "0.44", "best_ask": "0.45"}], "timestamp": "1769384970059", "event_type": "price_change"}}
{"_local_timestamp": "2026-01-25T23:49:31.107674+00:00", "data": {"market": "0xefc69f5f48827e331957acbcc2339eb3b15e27e32453b8e6f29b5de67474c986", "price_changes": [{"asset_id": "19619851020796345517172409566066997550761738782112746767326655871669350897686", "price": "0.16", "size": "250", "side": "BUY", "hash": "093ba230974fd25fa8dcf27c8b2a502a11ec4d40", "best_bid": "0.55", "best_ask": "0.56"}, {"asset_id": "108798918614128027361814219314538484133284583608074596451665946577336361445917", "price": "0.84", "size": "250", "side": "SELL", "hash": "2d5e92cf8433ed76e7d7d36bd5601044451f5daa", "best_bid": "0.44", "best_ask": "0.45"}], "timestamp": "1769384970683", "event_type": "price_change"}}
{"_local_timestamp": "2026-01-25T23:49:31.158859+00:00", "data": {"market": "0xefc69f5f48827e331957acbcc2339eb3b15e27e32453b8e6f29b5de67474c986", "price_changes": [{"asset_id": "19619851020796345517172409566066997550761738782112746767326655871669350897686", "price": "0.26", "size": "524", "side": "BUY", "hash": "16fb39f0ec6ac1bb6ad1ae5fded58abfe285089d", "best_bid": "0.55", "best_ask": "0.56"}, {"asset_id": "108798918614128027361814219314538484133284583608074596451665946577336361445917", "price": "0.74", "size": "524", "side": "SELL", "hash": "84571eb50f1ab8018a7a916a3cceb4c6bb926332", "best_bid": "0.44", "best_ask": "0.45"}], "timestamp": "1769384970780", "event_type": "price_change"}}
{"_local_timestamp": "2026-01-25T23:50:02.772398+00:00", "data": {"market": "0xefc69f5f48827e331957acbcc2339eb3b15e27e32453b8e6f29b5de67474c986", "price_changes": [{"asset_id": "108798918614128027361814219314538484133284583608074596451665946577336361445917", "price": "0.11", "size": "254.54", "side": "BUY", "hash": "1ea8f20ddbf05be3b0913ad3545bbddd0ec356dd", "best_bid": "0.44", "best_ask": "0.45"}, {"asset_id": "19619851020796345517172409566066997550761738782112746767326655871669350897686", "price": "0.89", "size": "254.54", "side": "SELL", "hash": "740bbf43a7a963a282c51b3f85b02005e14bfa85", "best_bid": "0.55", "best_ask": "0.56"}], "timestamp": "1769385002286", "event_type": "price_change"}}
{"_local_timestamp": "2026-01-25T23:50:02.788363+00:00", "data": {"market": "0xefc69f5f48827e331957acbcc2339eb3b15e27e32453b8e6f29b5de67474c986", "price_changes": [{"asset_id": "19619851020796345517172409566066997550761738782112746767326655871669350897686", "price": "0.13", "size": "225", "side": "BUY", "hash": "a4d581e792c9e2957813751b5c6d3573f42e13ed", "best_bid": "0.55", "best_ask": "0.56"}, {"asset_id": "108798918614128027361814219314538484133284583608074596451665946577336361445917", "price": "0.87", "size": "225", "side": "SELL", "hash": "40827ec7c52067c735712565e3f026d3cab91e60", "best_bid": "0.44", "best_ask": "0.45"}], "timestamp": "1769385002316", "event_type": "price_change"}}
{"_local_timestamp": "2026-01-25T23:50:05.545252+00:00", "data": {"market": "0xefc69f5f48827e331957acbcc2339eb3b15e27e32453b8e6f29b5de67474c986", "price_changes": [{"asset_id": "19619851020796345517172409566066997550761738782112746767326655871669350897686", "price": "0.25", "size": "21.73", "side": "BUY", "hash": "3ab1b24a8e19f57db8d33e3f38bcf106cb9f61d1", "best_bid": "0.55", "best_ask": "0.56"}, {"asset_id": "108798918614128027361814219314538484133284583608074596451665946577336361445917", "price": "0.75", "size": "21.73", "side": "SELL", "hash": "d4648a1b60c33f481597b3168299aff2c955dad5", "best_bid": "0.44", "best_ask": "0.45"}], "timestamp": "1769385005466", "event_type": "price_change"}}
{"_local_timestamp": "2026-01-25T23:50:05.830366+00:00", "data": {"market": "0xefc69f5f48827e331957acbcc2339eb3b15e27e32453b8e6f29b5de67474c986", "price_changes": [{"asset_id": "19619851020796345517172409566066997550761738782112746767326655871669350897686", "price": "0.23", "size": "186.95", "side": "BUY", "hash": "9e181df6319e1ed79a06438bcd309cbdb3d0b898", "best_bid": "0.55", "best_ask": "0.56"}, {"asset_id": "108798918614128027361814219314538484133284583608074596451665946577336361445917", "price": "0.77", "size": "186.95", "side": "SELL", "hash": "aee4e535204b4f9b63b1b1e63c1b09daac308fbf", "best_bid": "0.44", "best_ask": "0.45"}], "timestamp": "1769385005719", "event_type": "price_change"}}
{"_local_timestamp": "2026-01-25T23:50:46.356735+00:00", "data": {"market": "0xefc69f5f48827e331957acbcc2339eb3b15e27e32453b8e6f29b5de67474c986", "price_changes": [{"asset_id": "19619851020796345517172409566066997550761738782112746767326655871669350897686", "price": "0.13", "size": "0", "side": "BUY", "hash": "73c2b31ae6374a0ee45d2ee8311d981e466002a2", "best_bid": "0.55", "best_ask": "0.56"}, {"asset_id": "108798918614128027361814219314538484133284583608074596451665946577336361445917", "price": "0.87", "size": "0", "side": "SELL", "hash": "53cd9234af2d3ff8217768a8d6572ffd37318b5f", "best_bid": "0.44", "best_ask": "0.45"}], "timestamp": "1769385046266", "event_type": "price_change"}}
{"_local_timestamp": "2026-01-25T23:50:46.787199+00:00", "data": {"market": "0xefc69f5f48827e331957acbcc2339eb3b15e27e32453b8e6f29b5de67474c986", "price_changes": [{"asset_id": "19619851020796345517172409566066997550761738782112746767326655871669350897686", "price": "0.14", "size": "725", "side": "BUY", "hash": "e6b087f0a17f69585ac94231af62f49f9bd73fe1", "best_bid": "0.55", "best_ask": "0.56"}, {"asset_id": "108798918614128027361814219314538484133284583608074596451665946577336361445917", "price": "0.86", "size": "725", "side": "SELL", "hash": "0d9eb5904cb3926cdd5bdda8ce2209c1325063c3", "best_bid": "0.44", "best_ask": "0.45"}], "timestamp": "1769385046641", "event_type": "price_change"}}
{"_local_timestamp": "2026-01-25T23:50:52.078076+00:00", "data": {"market": "0xefc69f5f48827e331957acbcc2339eb3b15e27e32453b8e6f29b5de67474c986", "price_changes": [{"asset_id": "19619851020796345517172409566066997550761738782112746767326655871669350897686", "price": "0.42", "size": "119", "side": "BUY", "hash": "774f3eca82ab3e656444c3855ac97db7f022a3a2", "best_bid": "0.55", "best_ask": "0.56"}, {"asset_id": "108798918614128027361814219314538484133284583608074596451665946577336361445917", "price": "0.58", "size": "119", "side": "SELL", "hash": "b5ba2298867a0f70477687c56bc426af920ede67", "best_bid": "0.44", "best_ask": "0.45"}], "timestamp": "1769385052001", "event_type": "price_change"}}
{"_local_timestamp": "2026-01-25T23:51:05.495029+00:00", "data": {"market": "0xefc69f5f48827e331957acbcc2339eb3b15e27e32453b8e6f29b5de67474c986", "price_changes": [{"asset_id": "19619851020796345517172409566066997550761738782112746767326655871669350897686", "price": "0.16", "size": "150", "side": "BUY", "hash": "18a0aed821e084665b1fc0585db00e5af1e96514", "best_bid": "0.55", "best_ask": "0.56"}, {"asset_id": "108798918614128027361814219314538484133284583608074596451665946577336361445917", "price": "0.84", "size": "150", "side": "SELL", "hash": "cd1acc551ce1f7dee45d84024c5ba233ad9f754f", "best_bid": "0.44", "best_ask": "0.45"}], "timestamp": "1769385065408", "event_type": "price_change"}}
{"_local_timestamp": "2026-01-25T23:51:05.497286+00:00", "data": {"market": "0xefc69f5f48827e331957acbcc2339eb3b15e27e32453b8e6f29b5de67474c986", "price_changes": [{"asset_id": "19619851020796345517172409566066997550761738782112746767326655871669350897686", "price": "0.15", "size": "200", "side": "BUY", "hash": "18a0aed821e084665b1fc0585db00e5af1e96514", "best_bid": "0.55", "best_ask": "0.56"}, {"asset_id": "108798918614128027361814219314538484133284583608074596451665946577336361445917", "price": "0.85", "size": "200", "side": "SELL", "hash": "cd1acc551ce1f7dee45d84024c5ba233ad9f754f", "best_bid": "0.44", "best_ask": "0.45"}], "timestamp": "1769385065408", "event_type": "price_change"}}
{"_local_timestamp": "2026-01-25T23:51:06.018626+00:00", "data": {"market": "0xefc69f5f48827e331957acbcc2339eb3b15e27e32453b8e6f29b5de67474c986", "price_changes": [{"asset_id": "19619851020796345517172409566066997550761738782112746767326655871669350897686", "price": "0.17", "size": "2972.94", "side": "BUY", "hash": "e457ed221502f91b13cdecf375776510a8ca381a", "best_bid": "0.55", "best_ask": "0.56"}, {"asset_id": "108798918614128027361814219314538484133284583608074596451665946577336361445917", "price": "0.83", "size": "2972.94", "side": "SELL", "hash": "c37a69a2dd6bad2e5cca48df56fdb537925ef435", "best_bid": "0.44", "best_ask": "0.45"}], "timestamp": "1769385065797", "event_type": "price_change"}}
{"_local_timestamp": "2026-01-25T23:51:06.069710+00:00", "data": {"market": "0xefc69f5f48827e331957acbcc2339eb3b15e27e32453b8e6f29b5de67474c986", "price_changes": [{"asset_id": "19619851020796345517172409566066997550761738782112746767326655871669350897686", "price": "0.13", "size": "125", "side": "BUY", "hash": "9a49768726ed8f953d855f89b0817db5e95ed5ce", "best_bid": "0.55", "best_ask": "0.56"}, {"asset_id": "108798918614128027361814219314538484133284583608074596451665946577336361445917", "price": "0.87", "size": "125", "side": "SELL", "hash": "10d8512f52edcb31ee0f0872cb1ad7b825b8498e", "best_bid": "0.44", "best_ask": "0.45"}], "timestamp": "1769385065816", "event_type": "price_change"}}
{"_local_timestamp": "2026-01-25T23:51:06.497980+00:00", "data": {"market": "0xefc69f5f48827e331957acbcc2339eb3b15e27e32453b8e6f29b5de67474c986", "price_changes": [{"asset_id": "19619851020796345517172409566066997550761738782112746767326655871669350897686", "price": "0.47", "size": "0", "side": "BUY", "hash": "37828900b8c5e93914462d2a4956cbd62e655ddc", "best_bid": "0.55", "best_ask": "0.56"}, {"asset_id": "108798918614128027361814219314538484133284583608074596451665946577336361445917", "price": "0.53", "size": "0", "side": "SELL", "hash": "98136b3c95ac2749738ae88eb245892c6f59197a", "best_bid": "0.44", "best_ask": "0.45"}], "timestamp": "1769385066433", "event_type": "price_change"}}
{"_local_timestamp": "2026-01-25T23:51:06.498742+00:00", "data": {"market": "0xefc69f5f48827e331957acbcc2339eb3b15e27e32453b8e6f29b5de67474c986", "price_changes": [{"asset_id": "19619851020796345517172409566066997550761738782112746767326655871669350897686", "price": "0.53", "size": "289", "side": "BUY", "hash": "37828900b8c5e93914462d2a4956cbd62e655ddc", "best_bid": "0.55", "best_ask": "0.56"}, {"asset_id": "108798918614128027361814219314538484133284583608074596451665946577336361445917", "price": "0.47", "size": "289", "side": "SELL", "hash": "98136b3c95ac2749738ae88eb245892c6f59197a", "best_bid": "0.44", "best_ask": "0.45"}], "timestamp": "1769385066433", "event_type": "price_change"}}
{"_local_timestamp": "2026-01-25T23:51:06.499389+00:00", "data": {"market": "0xefc69f5f48827e331957acbcc2339eb3b15e27e32453b8e6f29b5de67474c986", "price_changes": [{"asset_id": "19619851020796345517172409566066997550761738782112746767326655871669350897686", "price": "0.5", "size": "1784.14", "side": "BUY", "hash": "37828900b8c5e93914462d2a4956cbd62e655ddc", "best_bid": "0.55", "best_ask": "0.56"}, {"asset_id": "108798918614128027361814219314538484133284583608074596451665946577336361445917", "price": "0.5", "size": "1784.14", "side": "SELL", "hash": "98136b3c95ac2749738ae88eb245892c6f59197a", "best_bid": "0.44", "best_ask": "0.45"}], "timestamp": "1769385066433", "event_type": "price_change"}}
{"_local_timestamp": "2026-01-25T23:51:06.500024+00:00", "data": {"market": "0xefc69f5f48827e331957acbcc2339eb3b15e27e32453b8e6f29b5de67474c986", "price_changes": [{"asset_id": "19619851020796345517172409566066997550761738782112746767326655871669350897686", "price": "0.26", "size": "100", "side": "BUY", "hash": "37828900b8c5e93914462d2a4956cbd62e655ddc", "best_bid": "0.55", "best_ask": "0.56"}, {"asset_id": "108798918614128027361814219314538484133284583608074596451665946577336361445917", "price": "0.74", "size": "100", "side": "SELL", "hash": "98136b3c95ac2749738ae88eb245892c6f59197a", "best_bid": "0.44", "best_ask": "0.45"}], "timestamp": "1769385066433", "event_type": "price_change"}}
{"_local_timestamp": "2026-01-25T23:51:06.500675+00:00", "data": {"market": "0xefc69f5f48827e331957acbcc2339eb3b15e27e32453b8e6f29b5de67474c986", "price_changes": [{"asset_id": "19619851020796345517172409566066997550761738782112746767326655871669350897686", "price": "0.42", "size": "9", "side": "BUY", "hash": "37828900b8c5e93914462d2a4956cbd62e655ddc", "best_bid": "0.55", "best_ask": "0.56"}, {"asset_id": "108798918614128027361814219314538484133284583608074596451665946577336361445917", "price": "0.58", "size": "9", "side": "SELL", "hash": "98136b3c95ac2749738ae88eb245892c6f59197a", "best_bid": "0.44", "best_ask": "0.45"}], "timestamp": "1769385066433", "event_type": "price_change"}}
{"_local_timestamp": "2026-01-25T23:51:06.501326+00:00", "data": {"market": "0xefc69f5f48827e331957acbcc2339eb3b15e27e32453b8e6f29b5de67474c986", "price_changes": [{"asset_id": "19619851020796345517172409566066997550761738782112746767326655871669350897686", "price": "0.18", "size": "0", "side": "BUY", "hash": "37828900b8c5e93914462d2a4956cbd62e655ddc", "best_bid": "0.55", "best_ask": "0.56"}, {"asset_id": "108798918614128027361814219314538484133284583608074596451665946577336361445917", "price": "0.82", "size": "0", "side": "SELL", "hash": "98136b3c95ac2749738ae88eb245892c6f59197a", "best_bid": "0.44", "best_ask": "0.45"}], "timestamp": "1769385066433", "event_type": "price_change"}}
{"_local_timestamp": "2026-01-25T23:51:06.776948+00:00", "data": {"market": "0xefc69f5f48827e331957acbcc2339eb3b15e27e32453b8e6f29b5de67474c986", "price_changes": [{"asset_id": "19619851020796345517172409566066997550761738782112746767326655871669350897686", "price": "0.52", "size": "1012", "side": "BUY", "hash": "0f37de628bbf43a6e1e6ec8b32db9ee546f18b0e", "best_bid": "0.55", "best_ask": "0.56"}, {"asset_id": "108798918614128027361814219314538484133284583608074596451665946577336361445917", "price": "0.48", "size": "1012", "side": "SELL", "hash": "8af62057992c7870ea1e9ede2d14cb4dd210a321", "best_bid": "0.44", "best_ask": "0.45"}], "timestamp": "1769385066706", "event_type": "price_change"}}
{"_local_timestamp": "2026-01-25T23:51:06.777729+00:00", "data": {"market": "0xefc69f5f48827e331957acbcc2339eb3b15e27e32453b8e6f29b5de67474c986", "price_changes": [{"asset_id": "19619851020796345517172409566066997550761738782112746767326655871669350897686", "price": "0.72", "size": "5.36", "side": "SELL", "hash": "71227505dc02d78bc3b81e8cddef19a618541b42", "best_bid": "0.55", "best_ask": "0.56"}, {"asset_id": "108798918614128027361814219314538484133284583608074596451665946577336361445917", "price": "0.28", "size": "5.36", "side": "BUY", "hash": "476cd821dab00d2ec2fda7231e4749469448a221", "best_bid": "0.44", "best_ask": "0.45"}], "timestamp": "1769385066707", "event_type": "price_change"}}
{"_local_timestamp": "2026-01-25T23:51:06.778415+00:00", "data": {"market": "0xefc69f5f48827e331957acbcc2339eb3b15e27e32453b8e6f29b5de67474c986", "price_changes": [{"asset_id": "19619851020796345517172409566066997550761738782112746767326655871669350897686", "price": "0.46", "size": "78.26", "side": "BUY", "hash": "ddeeda331c208ea2d4000ff68366fb4b88ee14c8", "best_bid": "0.55", "best_ask": "0.56"}, {"asset_id": "108798918614128027361814219314538484133284583608074596451665946577336361445917", "price": "0.54", "size": "78.26", "side": "SELL", "hash": "ab575ad4b3402763ba83e77177296517606c7e2d", "best_bid": "0.44", "best_ask": "0.45"}], "timestamp": "1769385066707", "event_type": "price_change"}}
{"_local_timestamp": "2026-01-25T23:51:06.779084+00:00", "data": {"market": "0xefc69f5f48827e331957acbcc2339eb3b15e27e32453b8e6f29b5de67474c986", "price_changes": [{"asset_id": "19619851020796345517172409566066997550761738782112746767326655871669350897686", "price": "0.49", "size": "25", "side": "BUY", "hash": "740042cc0bb1d7858653973dd87216a8fd81d27c", "best_bid": "0.55", "best_ask": "0.56"}, {"asset_id": "108798918614128027361814219314538484133284583608074596451665946577336361445917", "price": "0.51", "size": "25", "side": "SELL", "hash": "9b97a0e827040c2dd403d026b5c950c09f7b7035", "best_bid": "0.44", "best_ask": "0.45"}], "timestamp": "1769385066708", "event_type": "price_change"}}
{"_local_timestamp": "2026-01-25T23:51:06.779775+00:00", "data": {"market": "0xefc69f5f48827e331957acbcc2339eb3b15e27e32453b8e6f29b5de67474c986", "price_changes": [{"asset_id": "19619851020796345517172409566066997550761738782112746767326655871669350897686", "price": "0.24", "size": "742", "side": "BUY", "hash": "36640116c09ed0bd891f025aa8c069d08fabc2d2", "best_bid": "0.55", "best_ask": "0.56"}, {"asset_id": "108798918614128027361814219314538484133284583608074596451665946577336361445917", "price": "0.76", "size": "742", "side": "SELL", "hash": "8481a8bb51cc86fc1f260085dbf14f4fec021faa", "best_bid": "0.44", "best_ask": "0.45"}], "timestamp": "1769385066709", "event_type": "price_change"}}
{"_local_timestamp": "2026-01-25T23:51:06.780436+00:00", "data": {"market": "0xefc69f5f48827e331957acbcc2339eb3b15e27e32453b8e6f29b5de67474c986", "price_changes": [{"asset_id": "19619851020796345517172409566066997550761738782112746767326655871669350897686", "price": "0.26", "size": "443", "side": "BUY", "hash": "6f00d38302e6922100bc065f917031b60b07de8a", "best_bid": "0.55", "best_ask": "0.56"}, {"asset_id": "108798918614128027361814219314538484133284583608074596451665946577336361445917", "price": "0.74", "size": "443", "side": "SELL", "hash": "3628b05d5f74d2eb549adc780c17bc36999a7fec", "best_bid": "0.44", "best_ask": "0.45"}], "timestamp": "1769385066710", "event_type": "price_change"}}
{"_local_timestamp": "2026-01-25T23:51:06.781096+00:00", "data": {"market": "0xefc69f5f48827e331957acbcc2339eb3b15e27e32453b8e6f29b5de67474c986", "price_changes": [{"asset_id": "19619851020796345517172409566066997550761738782112746767326655871669350897686", "price": "0.42", "size": "108", "side": "BUY", "hash": "775fb1b7228e6dc7419fbe6277e1b7d5f81bcdce", "best_bid": "0.55", "best_ask": "0.56"}, {"asset_id": "108798918614128027361814219314538484133284583608074596451665946577336361445917", "price": "0.58", "size": "108", "side": "SELL", "hash": "43a7a602e9c06649513d556a7fcbea4b2345c6cc", "best_bid": "0.44", "best_ask": "0.45"}], "timestamp": "1769385066710", "event_type": "price_change"}}
{"_local_timestamp": "2026-01-25T23:51:06.805375+00:00", "data": {"market": "0xefc69f5f48827e331957acbcc2339eb3b15e27e32453b8e6f29b5de67474c986", "price_changes": [{"asset_id": "108798918614128027361814219314538484133284583608074596451665946577336361445917", "price": "0.44", "size": "15.02", "side": "BUY", "hash": "42eb4c5b637a6d153a43d4b2b5cd0d00c2ad9344", "best_bid": "0.44", "best_ask": "0.45"}, {"asset_id": "19619851020796345517172409566066997550761738782112746767326655871669350897686", "price": "0.56", "size": "15.02", "side": "SELL", "hash": "0d6ec6749dc793e35c2568e4662ba703e5b3a038", "best_bid": "0.55", "best_ask": "0.56"}], "timestamp": "1769385066742", "event_type": "price_change"}}
{"_local_timestamp": "2026-01-25T23:51:06.837809+00:00", "data": {"market": "0xefc69f5f48827e331957acbcc2339eb3b15e27e32453b8e6f29b5de67474c986", "price_changes": [{"asset_id": "108798918614128027361814219314538484133284583608074596451665946577336361445917", "price": "0.44", "size": "75.02", "side": "BUY", "hash": "099f7c135f5ab5daf6d30dbfbfce055d943df883", "best_bid": "0.44", "best_ask": "0.45"}, {"asset_id": "19619851020796345517172409566066997550761738782112746767326655871669350897686", "price": "0.56", "size": "75.02", "side": "SELL", "hash": "5391656c29dd1c4abc5364409d70417717c8835c", "best_bid": "0.55", "best_ask": "0.56"}], "timestamp": "1769385066769", "event_type": "price_change"}}
{"_local_timestamp": "2026-01-25T23:51:12.075044+00:00", "data": {"market": "0xefc69f5f48827e331957acbcc2339eb3b15e27e32453b8e6f29b5de67474c986", "price_changes": [{"asset_id": "19619851020796345517172409566066997550761738782112746767326655871669350897686", "price": "0.48", "size": "22.91", "side": "BUY", "hash": "e866b3f328e0cf53d6342643bf15f7cc73153cee", "best_bid": "0.55", "best_ask": "0.56"}, {"asset_id": "108798918614128027361814219314538484133284583608074596451665946577336361445917", "price": "0.52", "size": "22.91", "side": "SELL", "hash": "79415e77aa3793f186a3a1e1294e89b7da8f2067", "best_bid": "0.44", "best_ask": "0.45"}], "timestamp": "1769385072000", "event_type": "price_change"}}
{"_local_timestamp": "2026-01-25T23:51:13.070078+00:00", "data": {"market": "0xefc69f5f48827e331957acbcc2339eb3b15e27e32453b8e6f29b5de67474c986", "price_changes": [{"asset_id": "108798918614128027361814219314538484133284583608074596451665946577336361445917", "price": "0.21", "size": "0", "side": "BUY", "hash": "c944a79d5c30c4f74a56df51fbdc3eecd5ab16fe", "best_bid": "0.44", "best_ask": "0.45"}, {"asset_id": "19619851020796345517172409566066997550761738782112746767326655871669350897686", "price": "0.79", "size": "0", "side": "SELL", "hash": "8f7fe83dd8cd3e68fd85f9a549799974f6cf85be", "best_bid": "0.55", "best_ask": "0.56"}], "timestamp": "1769385073000", "event_type": "price_change"}}
{"_local_timestamp": "2026-01-25T23:51:13.070903+00:00", "data": {"market": "0xefc69f5f48827e331957acbcc2339eb3b15e27e32453b8e6f29b5de67474c986", "price_changes": [{"asset_id": "19619851020796345517172409566066997550761738782112746767326655871669350897686", "price": "0.44", "size": "0", "side": "BUY", "hash": "fa7c88a30e9e6ae3c3fede5911bc9beb2c790b8b", "best_bid": "0.55", "best_ask": "0.56"}, {"asset_id": "108798918614128027361814219314538484133284583608074596451665946577336361445917", "price": "0.56", "size": "0", "side": "SELL", "hash": "33af346157e38be4e583688e4cd297c081152df1", "best_bid": "0.44", "best_ask": "0.45"}], "timestamp": "1769385073001", "event_type": "price_change"}}
{"_local_timestamp": "2026-01-25T23:51:13.094251+00:00", "data": {"market": "0xefc69f5f48827e331957acbcc2339eb3b15e27e32453b8e6f29b5de67474c986", "price_changes": [{"asset_id": "108798918614128027361814219314538484133284583608074596451665946577336361445917", "price": "0.44", "size": "15.02", "side": "BUY", "hash": "f0494cbba0bcd40d71e64d36e6a6cf8d8dde17a1", "best_bid": "0.44", "best_ask": "0.45"}, {"asset_id": "19619851020796345517172409566066997550761738782112746767326655871669350897686", "price": "0.56", "size": "15.02", "side": "SELL", "hash": "d00e818d422e76c93ac5ee1f58e72166a3cba039", "best_bid": "0.55", "best_ask": "0.56"}], "timestamp": "1769385073026", "event_type": "price_change"}}
{"_local_timestamp": "2026-01-25T23:51:13.126683+00:00", "data": {"market": "0xefc69f5f48827e331957acbcc2339eb3b15e27e32453b8e6f29b5de67474c986", "price_changes": [{"asset_id": "108798918614128027361814219314538484133284583608074596451665946577336361445917", "price": "0.44", "size": "178.02", "side": "BUY", "hash": "bd69474bfc759f9f27920c73fbba769e9e50c761", "best_bid": "0.44", "best_ask": "0.45"}, {"asset_id": "19619851020796345517172409566066997550761738782112746767326655871669350897686", "price": "0.56", "size": "178.02", "side": "SELL", "hash": "dbae87b8e6433137bb06387359496389eae19512", "best_bid": "0.55", "best_ask": "0.56"}], "timestamp": "1769385073057", "event_type": "price_change"}}
