{"_local_timestamp": "2026-01-25T23:40:44.702988+00:00", "data": [{"market": "0x5bc23ef1d55fb8d4a1b21b7c8780aa1b6b019262dda806da8a79dc8ada217f33", "asset_id": "56888387443153290473779399645893214898197325618962871997813882665583407269175", "timestamp": "1769384440604", "hash": "a1641f1cb21a2767c278d80592913f4ee185c446", "bids": [{"price": "0.01", "size": "5534.95"}, {"price": "0.02", "size": "1500"}, {"price": "0.03", "size": "10.4"}, {"price": "0.05", "size": "1610"}, {"price": "0.06", "size": "250"}, {"price": "0.07", "size": "1514.28"}, {"price": "0.09", "size": "150"}, {"price": "0.1", "size": "340"}, {"price": "0.11", "size": "5.34"}, {"price": "0.13", "size": "246.15"}, {"price": "0.15", "size": "550"}, {"price": "0.16", "size": "1320"}, {"price": "0.17", "size": "164.7"}, {"price": "0.19", "size": "100"}, {"price": "0.2", "size": "280"}, {"price": "0.21", "size": "2098"}, {"price": "0.23", "size": "154.34"}, {"price": "0.27", "size": "324.07"}, {"price": "0.36", "size": "59.52"}, {"price": "0.37", "size": "5"}, {"price": "0.4", "size": "588"}, {"price": "0.41", "size": "900"}, {"price": "0.42", "size": "600"}, {"price": "0.43", "size": "500"}, {"price": "0.44", "size": "688"}, {"price": "0.45", "size": "588"}, {"price": "0.5", "size": "506.67"}, {"price": "0.51", "size": "444"}, {"price": "0.52", "size": "174.99"}, {"price": "0.53", "size": "24.52"}, {"price": "0.54", "size": "20.37"}, {"price": "0.6", "size": "730"}, {"price": "0.61", "size": "555"}, {"price": "0.62", "size": "106.5"}, {"price": "0.63", "size": "508.79"}, {"price": "0.64", "size": "1002.33"}, {"price": "0.65", "size": "278"}], "asks": [{"price": "0.99", "size": "7190.99"}, {"price": "0.98", "size": "2806.22"}, {"price": "0.97", "size": "1200"}, {"price": "0.96", "size": "7.66"}, {"price": "0.95", "size": "730.58"}, {"price": "0.93", "size": "457.14"}, {"price": "0.91", "size": "4772.51"}, {"price": "0.9", "size": "755.69"}, {"price": "0.89", "size": "661.36"}, {"price": "0.88", "size": "350"}, {"price": "0.86", "size": "142.85"}, {"price": "0.85", "size": "100"}, {"price": "0.84", "size": "500"}, {"price": "0.81", "size": "2965"}, {"price": "0.8", "size": "347"}, {"price": "0.79", "size": "126"}, {"price": "0.77", "size": "1248.6"}, {"price": "0.76", "size": "600"}, {"price": "0.75", "size": "622.75"}, {"price": "0.74", "size": "110"}, {"price": "0.73", "size": "473.74"}, {"price": "0.72", "size": "4353.9"}, {"price": "0.71", "size": "594"}, {"price": "0.69", "size": "341"}, {"price": "0.68", "size": "1584.1"}, {"price": "0.67", "size": "143"}], "event_type": "book", "last_trade_price": "0.330"}, {"market": "0x5bc23ef1d55fb8d4a1b21b7c8780aa1b6b019262dda806da8a79dc8ada217f33", "asset_id": "44152243636867873932593431458048174258413868830357636196802887961839805767798", "timestamp": "1769384440604", "hash": "ebbb1ca8156dfdebae4b5da0902afdb2dd422cd0", "bids": [{"price": "0.01", "size": "7190.99"}, {"price": "0.02", "size": "2806.22"}, {"price": "0.03", "size": "1200"}, {"price": "0.04", "size": "7.66"}, {"price": "0.05", "size": "730.58"}, {"price": "0.07", "size": "457.14"}, {"price": "0.09", "size": "4772.51"}, {"price": "0.1", "size": "755.69"}, {"price": "0.11", "size": "661.36"}, {"price": "0.12", "size": "350"}, {"price": "0.14", "size": "142.85"}, {"price": "0.15", "size": "100"}, {"price": "0.16", "size": "500"}, {"price": "0.19", "size": "2965"}, {"price": "0.2", "size": "347"}, {"price": "0.21", "size": "126"}, {"price": "0.23", "size": "1248.6"}, {"price": "0.24", "size": "600"}, {"price": "0.25", "size": "622.75"}, {"price": "0.26", "size": "110"}, {"price": "0.27", "size": "473.74"}, {"price": "0.28", "size": "4353.9"}, {"price": "0.29", "size": "594"}, {"price": "0.31", "size": "341"}, {"price": "0.32", "size": "1584.1"}, {"price": "0.33", "size": "143"}], "asks": [{"price": "0.99", "size": "5534.95"}, {"price": "0.98", "size": "1500"}, {"price": "0.97", "size": "10.4"}, {"price": "0.95", "size": "1610"}, {"price": "0.94", "size": "250"}, {"price": "0.93", "size": "1514.28"}, {"price": "0.91", "size": "150"}, {"price": "0.9", "size": "340"}, {"price": "0.89", "size": "5.34"}, {"price": "0.87", "size": "246.15"}, {"price": "0.85", "size": "550"}, {"price": "0.84", "size": "1320"}, {"price": "0.83", "size": "164.7"}, {"price": "0.81", "size": "100"}, {"price": "0.8", "size": "280"}, {"price": "0.79", "size": "2098"}, {"price": "0.77", "size": "154.34"}, {"price": "0.73", "size": "324.07"}, {"price": "0.64", "size": "59.52"}, {"price": "0.63", "size": "5"}, {"price": "0.6", "size": "588"}, {"price": "0.59", "size": "900"}, {"price": "0.58", "size": "600"}, {"price": "0.57", "size": "500"}, {"price": "0.56", "size": "688"}, {"price": "0.55", "size": "588"}, {"price": "0.5", "size": "506.67"}, {"price": "0.49", "size": "444"}, {"price": "0.48", "size": "174.99"}, {"price": "0.47", "size": "24.52"}, {"price": "0.46", "size": "20.37"}, {"price": "0.4", "size": "730"}, {"price": "0.39", "size": "555"}, {"price": "0.38", "size": "106.5"}, {"price": "0.37", "size": "508.79"}, {"price": "0.36", "size": "1002.33"}, {"price": "0.35", "size": "278"}], "event_type": "book", "last_trade_price": "0.330"}]}
{"_local_timestamp": "2026-01-25T23:40:59.193585+00:00", "data": {"market": "0x5bc23ef1d55fb8d4a1b21b7c8780aa1b6b019262dda806da8a79dc8ada217f33", "price_changes": [{"asset_id": "44152243636867873932593431458048174258413868830357636196802887961839805767798", "price": "0.02", "size": "2406.22", "side": "BUY", "hash": "483442e5f85a4be6ebd25c6b456a26eb521fa68c", "best_bid": "0.33", "best_ask": "0.35"}, {"asset_id": "56888387443153290473779399645893214898197325618962871997813882665583407269175", "price": "0.98", "size": "2406.22", "side": "SELL", "hash": "6c6215063a7866f0b8112af514dc1f2223a7ee39", "best_bid": "0.65", "best_ask": "0.67"}], "timestamp": "1769384459097", "event_type": "price_change"}}
{"_local_timestamp": "2026-01-25T23:40:59.568114+00:00", "data": {"market": "0x5bc23ef1d55fb8d4a1b21b7c8780aa1b6b019262dda806da8a79dc8ada217f33", "price_changes": [{"asset_id": "44152243636867873932593431458048174258413868830357636196802887961839805767798", "price": "0.05", "size": "1130.58", "side": "BUY", "hash": "364e8b2109ee862c4b9480a7ec671227829d8bc8", "best_bid": "0.33", "best_ask": "0.35"}, {"asset_id": "56888387443153290473779399645893214898197325618962871997813882665583407269175", "price": "0.95", "size": "1130.58", "side": "SELL", "hash": "2590859da4a1314d2f78d7871eede3d395dd9b88", "best_bid": "0.65", "best_ask": "0.67"}], "timestamp": "1769384459457", "event_type": "price_change"}}
{"_local_timestamp": "2026-01-25T23:41:00.076319+00:00", "data": {"market": "0x5bc23ef1d55fb8d4a1b21b7c8780aa1b6b019262dda806da8a79dc8ada217f33", "price_changes": [{"asset_id": "44152243636867873932593431458048174258413868830357636196802887961839805767798", "price": "0.19", "size": "970", "side": "BUY", "hash": "257234ab09f18905b15e76d3f4342579eccaa396", "best_bid": "0.33", "best_ask": "0.35"}, {"asset_id": "56888387443153290473779399645893214898197325618962871997813882665583407269175", "price": "0.81", "size": "970", "side": "SELL", "hash": "38cc22059bc66e52cedc9d4383da9fdea11c476f", "best_bid": "0.65", "best_ask": "0.67"}], "timestamp": "1769384460001", "event_type": "price_change"}}
{"_local_timestamp": "2026-01-25T23:41:00.079975+00:00", "data": {"market": "0x5bc23ef1d55fb8d4a1b21b7c8780aa1b6b019262dda806da8a79dc8ada217f33", "price_changes": [{"asset_id": "44152243636867873932593431458048174258413868830357636196802887961839805767798", "price": "0.23", "size": "466.6", "side": "BUY", "hash": "e349b78cb0da9ae5d8268109819f491afa7a3eb0", "best_bid": "0.33", "best_ask": "0.35"}, {"asset_id": "56888387443153290473779399645893214898197325618962871997813882665583407269175", "price": "0.77", "size": "466.6", "side": "SELL", "hash": "73322f6fb423253aa417a9c6824c4f0fa874d9db", "best_bid": "0.65", "best_ask": "0.67"}], "timestamp": "1769384460002", "event_type": "price_change"}}
{"_local_timestamp": "2026-01-25T23:41:40.222324+00:00", "data": {"market": "0x5bc23ef1d55fb8d4a1b21b7c8780aa1b6b019262dda806da8a79dc8ada217f33", "price_changes": [{"asset_id": "44152243636867873932593431458048174258413868830357636196802887961839805767798", "price": "0.02", "size": "1606.22", "side": "BUY", "hash": "98bacdd126e0cbec991845c11c0de52c4f32c370", "best_bid": "0.33", "best_ask": "0.35"}, {"asset_id": "56888387443153290473779399645893214898197325618962871997813882665583407269175", "price": "0.98", "size": "1606.22", "side": "SELL", "hash": "beb0cd5808749e4a397b2f52b0b17a73c7f59613", "best_bid": "0.65", "best_ask": "0.67"}], "timestamp": "1769384500142", "event_type": "price_change"}}
{"_local_timestamp": "2026-01-25T23:41:40.562321+00:00", "data": {"market": "0x5bc23ef1d55fb8d4a1b21b7c8780aa1b6b019262dda806da8a79dc8ada217f33", "price_changes": [{"asset_id": "44152243636867873932593431458048174258413868830357636196802887961839805767798", "price": "0.05", "size": "1630.58", "side": "BUY", "hash": "5b5ea3b8c4efe10e12e13b7d9e9e7786e7df852f", "best_bid": "0.33", "best_ask": "0.35"}, {"asset_id": "56888387443153290473779399645893214898197325618962871997813882665583407269175", "price": "0.95", "size": "1630.58", "side": "SELL", "hash": "529281953f14e4c3c81c9cacc1b368a3a193aaee", "best_bid": "0.65", "best_ask": "0.67"}], "timestamp": "1769384500482", "event_type": "price_change"}}
{"_local_timestamp": "2026-01-25T23:41:50.895346+00:00", "data": {"market": "0x5bc23ef1d55fb8d4a1b21b7c8780aa1b6b019262dda806da8a79dc8ada217f33", "price_changes": [{"asset_id": "56888387443153290473779399645893214898197325618962871997813882665583407269175", "price": "0.2", "size": "130", "side": "BUY", "hash": "1e7d69bae28d034852c75778370319aa02fac98f", "best_bid": "0.65", "best_ask": "0.67"}, {"asset_id": "44152243636867873932593431458048174258413868830357636196802887961839805767798", "price": "0.8", "size": "130", "side": "SELL", "hash": "ead0074c17f5274b8f5db5ddbf6a932efc0d5475", "best_bid": "0.33", "best_ask": "0.35"}], "timestamp": "1769384510745", "event_type": "price_change"}}
{"_local_timestamp": "2026-01-25T23:41:52.716784+00:00", "data": {"market": "0x5bc23ef1d55fb8d4a1b21b7c8780aa1b6b019262dda806da8a79dc8ada217f33", "price_changes": [{"asset_id": "56888387443153290473779399645893214898197325618962871997813882665583407269175", "price": "0.16", "size": "1470", "side": "BUY", "hash": "387a341749255fe2b1a07446568a7b73fef176a2", "best_bid": "0.65", "best_ask": "0.67"}, {"asset_id": "44152243636867873932593431458048174258413868830357636196802887961839805767798", "price": "0.84", "size": "1470", "side": "SELL", "hash": "3c1e12749a0bfb4a800173a75f5661fa8f37a3a7", "best_bid": "0.33", "best_ask": "0.35"}], "timestamp": "1769384511765", "event_type": "price_change"}}
{"_local_timestamp": "2026-01-25T23:42:24.779726+00:00", "data": {"market": "0x5bc23ef1d55fb8d4a1b21b7c8780aa1b6b019262dda806da8a79dc8ada217f33", "price_changes": [{"asset_id": "56888387443153290473779399645893214898197325618962871997813882665583407269175", "price": "0.27", "size": "274.07", "side": "BUY", "hash": "74096b9acc2dc4bc8603534840ee0dcc4e8cc16b", "best_bid": "0.65", "best_ask": "0.67"}, {"asset_id": "44152243636867873932593431458048174258413868830357636196802887961839805767798", "price": "0.73", "size": "274.07", "side": "SELL", "hash": "f8afbac83bbd7cfb90205bb8367424a425ccb631", "best_bid": "0.33", "best_ask": "0.35"}], "timestamp": "1769384544485", "event_type": "price_change"}}
{"_local_timestamp": "2026-01-25T23:42:24.780593+00:00", "data": {"market": "0x5bc23ef1d55fb8d4a1b21b7c8780aa1b6b019262dda806da8a79dc8ada217f33", "price_changes": [{"asset_id": "56888387443153290473779399645893214898197325618962871997813882665583407269175", "price": "0.19", "size": "0", "side": "BUY", "hash": "74096b9acc2dc4bc8603534840ee0dcc4e8cc16b", "best_bid": "0.65", "best_ask": "0.67"}, {"asset_id": "44152243636867873932593431458048174258413868830357636196802887961839805767798", "price": "0.81", "size": "0", "side": "SELL", "hash": "f8afbac83bbd7cfb90205bb8367424a425ccb631", "best_bid": "0.33", "best_ask": "0.35"}], "timestamp": "1769384544485", "event_type": "price_change"}}
{"_local_timestamp": "2026-01-25T23:42:25.148748+00:00", "data": {"market": "0x5bc23ef1d55fb8d4a1b21b7c8780aa1b6b019262dda806da8a79dc8ada217f33", "price_changes": [{"asset_id": "56888387443153290473779399645893214898197325618962871997813882665583407269175", "price": "0.16", "size": "1570", "side": "BUY", "hash": "3b5e5953dd7581e1ada7ee6e3489ca15f7a24d51", "best_bid": "0.65", "best_ask": "0.67"}, {"asset_id": "44152243636867873932593431458048174258413868830357636196802887961839805767798", "price": "0.84", "size": "1570", "side": "SELL", "hash": "bdf195d8d96e19256e78169f5399102f1a943bbe", "best_bid": "0.33", "best_ask": "0.35"}], "timestamp": "1769384544903", "event_type": "price_change"}}
{"_local_timestamp": "2026-01-25T23:42:25.188581+00:00", "data": {"market": "0x5bc23ef1d55fb8d4a1b21b7c8780aa1b6b019262dda806da8a79dc8ada217f33", "price_changes": [{"asset_id": "56888387443153290473779399645893214898197325618962871997813882665583407269175", "price": "0.21", "size": "2148", "side": "BUY", "hash": "8a8da7abb6bdf4bf35f7882bbe524da11df11d95", "best_bid": "0.65", "best_ask": "0.67"}, {"asset_id": "44152243636867873932593431458048174258413868830357636196802887961839805767798", "price": "0.79", "size": "2148", "side": "SELL", "hash": "db712c2d9b061e54c44257d61eda263b947a429f", "best_bid": "0.33", "best_ask": "0.35"}], "timestamp": "1769384544913", "event_type": "price_change"}}
{"_local_timestamp": "2026-01-25T23:42:27.996763+00:00", "data": {"market": "0x5bc23ef1d55fb8d4a1b21b7c8780aa1b6b019262dda806da8a79dc8ada217f33", "price_changes": [{"asset_id": "44152243636867873932593431458048174258413868830357636196802887961839805767798", "price": "0.27", "size": "54.74", "side": "BUY", "hash": "1aeaae2c8b35789ecec46a757e59104c58805d91", "best_bid": "0.33", "best_ask": "0.35"}, {"asset_id": "56888387443153290473779399645893214898197325618962871997813882665583407269175", "price": "0.73", "size": "54.74", "side": "SELL", "hash": "f4b1c479c57ffbe13822146d7fb9a07d5a8da5a9", "best_bid": "0.65", "best_ask": "0.67"}], "timestamp": "1769384547780", "event_type": "price_change"}}
{"_local_timestamp": "2026-01-25T23:42:27.997146+00:00", "data": {"market": "0x5bc23ef1d55fb8d4a1b21b7c8780aa1b6b019262dda806da8a79dc8ada217f33", "price_changes": [{"asset_id": "44152243636867873932593431458048174258413868830357636196802887961839805767798", "price": "0.38", "size": "100", "side": "SELL", "hash": "1aeaae2c8b35789ecec46a757e59104c58805d91", "best_bid": "0.33", "best_ask": "0.35"}, {"asset_id": "56888387443153290473779399645893214898197325618962871997813882665583407269175", "price": "0.62", "size": "100", "side": "BUY", "hash": "f4b1c479c57ffbe13822146d7fb9a07d5a8da5a9", "best_bid": "0.65", "best_ask": "0.67"}], "timestamp": "1769384547780", "event_type": "price_change"}}
{"_local_timestamp": "2026-01-25T23:42:28.071774+00:00", "data": {"market": "0x5bc23ef1d55fb8d4a1b21b7c8780aa1b6b019262dda806da8a79dc8ada217f33", "price_changes": [{"asset_id": "44152243636867873932593431458048174258413868830357636196802887961839805767798", "price": "0.36", "size": "1008.33", "side": "SELL", "hash": "28a21f8886e2c4247340c9fb26ee1a800a8e956c", "best_bid": "0.33", "best_ask": "0.35"}, {"asset_id": "56888387443153290473779399645893214898197325618962871997813882665583407269175", "price": "0.64", "size": "1008.33", "side": "BUY", "hash": "9fcc3bd84711ce50c9c8472a6bfb4e050fb932a2", "best_bid": "0.65", "best_ask": "0.67"}], "timestamp": "1769384547853", "event_type": "price_change"}}
{"_local_timestamp": "2026-01-25T23:42:28.074438+00:00", "data": {"market": "0x5bc23ef1d55fb8d4a1b21b7c8780aa1b6b019262dda806da8a79dc8ada217f33", "price_changes": [{"asset_id": "44152243636867873932593431458048174258413868830357636196802887961839805767798", "price": "0.33", "size": "149", "side": "BUY", "hash": "ffebf4a68e5d326f3404833ac667549e53568152", "best_bid": "0.33", "best_ask": "0.35"}, {"asset_id": "56888387443153290473779399645893214898197325618962871997813882665583407269175", "price": "0.67", "size": "149", "side": "SELL", "hash": "933f8f02bc39717369c8cbcc572fbdc5749cc440", "best_bid": "0.65", "best_ask": "0.67"}], "timestamp": "1769384547854", "event_type": "price_change"}}
{"_local_timestamp": "2026-01-25T23:42:28.074810+00:00", "data": {"market": "0x5bc23ef1d55fb8d4a1b21b7c8780aa1b6b019262dda806da8a79dc8ada217f33", "price_changes": [{"asset_id": "44152243636867873932593431458048174258413868830357636196802887961839805767798", "price": "0.31", "size": "350", "side": "BUY", "hash": "24c331cc8c687f58defb9366990c3a39779d5403", "best_bid": "0.33", "best_ask": "0.35"}, {"asset_id": "56888387443153290473779399645893214898197325618962871997813882665583407269175", "price": "0.69", "size": "350", "side": "SELL", "hash": "f884fd6acb028a934c99d4b48ae107a08ff0d66b", "best_bid": "0.65", "best_ask": "0.67"}], "timestamp": "1769384547855", "event_type": "price_change"}}
{"_local_timestamp": "2026-01-25T23:42:28.075182+00:00", "data": {"market": "0x5bc23ef1d55fb8d4a1b21b7c8780aa1b6b019262dda806da8a79dc8ada217f33", "price_changes": [{"asset_id": "44152243636867873932593431458048174258413868830357636196802887961839805767798", "price": "0.26", "size": "580", "side": "BUY", "hash": "68f4ce2c2fdb2faf62aa271a9f9f8713445e441a", "best_bid": "0.33", "best_ask": "0.35"}, {"asset_id": "56888387443153290473779399645893214898197325618962871997813882665583407269175", "price": "0.74", "size": "580", "side": "SELL", "hash": "33d662a47e3e2edc9596cfcadd49718a9d56ea76", "best_bid": "0.65", "best_ask": "0.67"}], "timestamp": "1769384547856", "event_type": "price_change"}}
{"_local_timestamp": "2026-01-25T23:42:28.081963+00:00", "data": {"market": "0x5bc23ef1d55fb8d4a1b21b7c8780aa1b6b019262dda806da8a79dc8ada217f33", "price_changes": [{"asset_id": "44152243636867873932593431458048174258413868830357636196802887961839805767798", "price": "0.29", "size": "608", "side": "BUY", "hash": "42dbaaf0b0c2da85e5b915341de3c7aeb55d632f", "best_bid": "0.33", "best_ask": "0.35"}, {"asset_id": "56888387443153290473779399645893214898197325618962871997813882665583407269175", "price": "0.71", "size": "608", "side": "SELL", "hash": "10ef0e3621994f126d974178cf003be048e25372", "best_bid": "0.65", "best_ask": "0.67"}], "timestamp": "1769384547857", "event_type": "price_change"}}
{"_local_timestamp": "2026-01-25T23:42:28.082372+00:00", "data": {"market": "0x5bc23ef1d55fb8d4a1b21b7c8780aa1b6b019262dda806da8a79dc8ada217f33", "price_changes": [{"asset_id": "44152243636867873932593431458048174258413868830357636196802887961839805767798", "price": "0.19", "size": "3149", "side": "BUY", "hash": "69576b9b01818e327f1eb72be43941fa2db0cbf2", "best_bid": "0.33", "best_ask": "0.35"}, {"asset_id": "56888387443153290473779399645893214898197325618962871997813882665583407269175", "price": "0.81", "size": "3149", "side": "SELL", "hash": "c401816a38c6a0eab58df172f26c2a1847f91fc5", "best_bid": "0.65", "best_ask": "0.67"}], "timestamp": "1769384547858", "event_type": "price_change"}}
{"_local_timestamp": "2026-01-25T23:42:28.082685+00:00", "data": {"market": "0x5bc23ef1d55fb8d4a1b21b7c8780aa1b6b019262dda806da8a79dc8ada217f33", "price_changes": [{"asset_id": "44152243636867873932593431458048174258413868830357636196802887961839805767798", "price": "0.23", "size": "1326.6", "side": "BUY", "hash": "22e4696f7094e1d78045425077941562cb3ba086", "best_bid": "0.33", "best_ask": "0.35"}, {"asset_id": "56888387443153290473779399645893214898197325618962871997813882665583407269175", "price": "0.77", "size": "1326.6", "side": "SELL", "hash": "8408afe255fe0686ea517c6137f8ea221434bf76", "best_bid": "0.65", "best_ask": "0.67"}], "timestamp": "1769384547859", "event_type": "price_change"}}
{"_local_timestamp": "2026-01-25T23:42:39.865615+00:00", "data": {"market": "0x5bc23ef1d55fb8d4a1b21b7c8780aa1b6b019262dda806da8a79dc8ada217f33", "price_changes": [{"asset_id": "44152243636867873932593431458048174258413868830357636196802887961839805767798", "price": "0.05", "size": "1230.58", "side": "BUY", "hash": "d41397970d7442dbc0c6c118b5457e80d3c4b96f", "best_bid": "0.33", "best_ask": "0.35"}, {"asset_id": "56888387443153290473779399645893214898197325618962871997813882665583407269175", "price": "0.95", "size": "1230.58", "side": "SELL", "hash": "09a8478631262a95798585a93d99c3b25edb7cfd", "best_bid": "0.65", "best_ask": "0.67"}], "timestamp": "1769384559594", "event_type": "price_change"}}
{"_local_timestamp": "2026-01-25T23:42:40.244339+00:00", "data": {"market": "0x5bc23ef1d55fb8d4a1b21b7c8780aa1b6b019262dda806da8a79dc8ada217f33", "price_changes": [{"asset_id": "44152243636867873932593431458048174258413868830357636196802887961839805767798", "price": "0.02", "size": "2006.22", "side": "BUY", "hash": "e9d18c5ac3ac3689dbd4e6e230a050b7a3b007bc", "best_bid": "0.33", "best_ask": "0.35"}, {"asset_id": "56888387443153290473779399645893214898197325618962871997813882665583407269175", "price": "0.98", "size": "2006.22", "side": "SELL", "hash": "6f167e27425ff9a998ccbc60b54c97eeb05f4888", "best_bid": "0.65", "best_ask": "0.67"}], "timestamp": "1769384559924", "event_type": "price_change"}}
{"_local_timestamp": "2026-01-25T23:42:45.445318+00:00", "data": {"market": "0x5bc23ef1d55fb8d4a1b21b7c8780aa1b6b019262dda806da8a79dc8ada217f33", "price_changes": [{"asset_id": "56888387443153290473779399645893214898197325618962871997813882665583407269175", "price": "0.23", "size": "104.34", "side": "BUY", "hash": "905a49b275b4100c95c3f624aed89c47edcb3ee5", "best_bid": "0.65", "best_ask": "0.67"}, {"asset_id": "44152243636867873932593431458048174258413868830357636196802887961839805767798", "price": "0.77", "size": "104.34", "side": "SELL", "hash": "a17bc0d5ea28b1027aa53d51fe845848e7d668f4", "best_bid": "0.33", "best_ask": "0.35"}], "timestamp": "1769384565220", "event_type": "price_change"}}
{"_local_timestamp": "2026-01-25T23:42:45.751769+00:00", "data": {"market": "0x5bc23ef1d55fb8d4a1b21b7c8780aa1b6b019262dda806da8a79dc8ada217f33", "price_changes": [{"asset_id": "56888387443153290473779399645893214898197325618962871997813882665583407269175", "price": "0.21", "size": "2198", "side": "BUY", "hash": "8049bdd5949e2db70d0edf429f169d16b9c611b0", "best_bid": "0.65", "best_ask": "0.67"}, {"asset_id": "44152243636867873932593431458048174258413868830357636196802887961839805767798", "price": "0.79", "size": "2198", "side": "SELL", "hash": "14be9568859743d8c7b7d43928a2c24c7982fb42", "best_bid": "0.33", "best_ask": "0.35"}], "timestamp": "1769384565608", "event_type": "price_change"}}
{"_local_timestamp": "2026-01-25T23:42:47.189508+00:00", "data": {"market": "0x5bc23ef1d55fb8d4a1b21b7c8780aa1b6b019262dda806da8a79dc8ada217f33", "price_changes": [{"asset_id": "56888387443153290473779399645893214898197325618962871997813882665583407269175", "price": "0.21", "size": "200", "side": "BUY", "hash": "04d374c48ce36f6f02b58e7afbad788848bbaf68", "best_bid": "0.65", "best_ask": "0.67"}, {"asset_id": "44152243636867873932593431458048174258413868830357636196802887961839805767798", "price": "0.79", "size": "200", "side": "SELL", "hash": "25b6cf11772a638d5ff89b1bef10619dc083e3f0", "best_bid": "0.33", "best_ask": "0.35"}], "timestamp": "1769384566996", "event_type": "price_change"}}
{"_local_timestamp": "2026-01-25T23:43:05.153042+00:00", "data": {"market": "0x5bc23ef1d55fb8d4a1b21b7c8780aa1b6b019262dda806da8a79dc8ada217f33", "price_changes": [{"asset_id": "56888387443153290473779399645893214898197325618962871997813882665583407269175", "price": "0.64", "size": "908.33", "side": "BUY", "hash": "d6bd557921021cbe82374eb265dc5ad9d90e8264", "best_bid": "0.65", "best_ask": "0.67"}, {"asset_id": "44152243636867873932593431458048174258413868830357636196802887961839805767798", "price": "0.36", "size": "908.33", "side": "SELL", "hash": "73966184ceeff28968286181addf91196b0dca8d", "best_bid": "0.33", "best_ask": "0.35"}], "timestamp": "1769384585002", "event_type": "price_change"}}
{"_local_timestamp": "2026-01-25T23:43:05.176753+00:00", "data": {"market": "0x5bc23ef1d55fb8d4a1b21b7c8780aa1b6b019262dda806da8a79dc8ada217f33", "price_changes": [{"asset_id": "44152243636867873932593431458048174258413868830357636196802887961839805767798", "price": "0.32", "size": "1484.1", "side": "BUY", "hash": "d7f3487bf9afe9a927d23673b79f74a7ce5a36a2", "best_bid": "0.33", "best_ask": "0.35"}, {"asset_id": "56888387443153290473779399645893214898197325618962871997813882665583407269175", "price": "0.68", "size": "1484.1", "side": "SELL", "hash": "2405e576732129f1032d142bae20c75b2282df8a", "best_bid": "0.65", "best_ask": "0.67"}], "timestamp": "1769384585004", "event_type": "price_change"}}
{"_local_timestamp": "2026-01-25T23:43:38.592025+00:00", "data": {"market": "0x5bc23ef1d55fb8d4a1b21b7c8780aa1b6b019262dda806da8a79dc8ada217f33", "price_changes": [{"asset_id": "56888387443153290473779399645893214898197325618962871997813882665583407269175", "price": "0.21", "size": "100", "side": "BUY", "hash": "523ea30a456c50977689c9f89b60ed886bf30325", "best_bid": "0.65", "best_ask": "0.67"}, {"asset_id": "44152243636867873932593431458048174258413868830357636196802887961839805767798", "price": "0.79", "size": "100", "side": "SELL", "hash": "397bdb16abaca157399d9ed8469a2807a2747871", "best_bid": "0.33", "best_ask": "0.35"}], "timestamp": "1769384618458", "event_type": "price_change"}}
{"_local_timestamp": "2026-01-25T23:43:38.853325+00:00", "data": {"market": "0x5bc23ef1d55fb8d4a1b21b7c8780aa1b6b019262dda806da8a79dc8ada217f33", "price_changes": [{"asset_id": "56888387443153290473779399645893214898197325618962871997813882665583407269175", "price": "0.23", "size": "204.34", "side": "BUY", "hash": "212aa143a810248c4c5618032029658e321c4725", "best_bid": "0.65", "best_ask": "0.67"}, {"asset_id": "44152243636867873932593431458048174258413868830357636196802887961839805767798", "price": "0.77", "size": "204.34", "side": "SELL", "hash": "e331667c2b82b4e911404c20209c7c79728d6fc2", "best_bid": "0.33", "best_ask": "0.35"}], "timestamp": "1769384618719", "event_type": "price_change"}}
{"_local_timestamp": "2026-01-25T23:43:52.440312+00:00", "data": {"market": "0x5bc23ef1d55fb8d4a1b21b7c8780aa1b6b019262dda806da8a79dc8ada217f33", "price_changes": [{"asset_id": "44152243636867873932593431458048174258413868830357636196802887961839805767798", "price": "0.05", "size": "730.58", "side": "BUY", "hash": "b4e061c5d32722b8dba42ae6ce2ebc18ef0f25e0", "best_bid": "0.33", "best_ask": "0.35"}, {"asset_id": "56888387443153290473779399645893214898197325618962871997813882665583407269175", "price": "0.95", "size": "730.58", "side": "SELL", "hash": "1aaf3cc051ce0878667d47b78019d27e0bc046c3", "best_bid": "0.65", "best_ask": "0.67"}], "timestamp": "1769384632182", "event_type": "price_change"}}
{"_local_timestamp": "2026-01-25T23:43:52.905124+00:00", "data": {"market": "0x5bc23ef1d55fb8d4a1b21b7c8780aa1b6b019262dda806da8a79dc8ada217f33", "price_changes": [{"asset_id": "44152243636867873932593431458048174258413868830357636196802887961839805767798", "price": "0.02", "size": "2806.22", "side": "BUY", "hash": "0becedd0a589815c585a1e8039942532d4c5cdc9", "best_bid": "0.33", "best_ask": "0.35"}, {"asset_id": "56888387443153290473779399645893214898197325618962871997813882665583407269175", "price": "0.98", "size": "2806.22", "side": "SELL", "hash": "9b7167affd5830283bb22ed5548acf8801c06934", "best_bid": "0.65", "best_ask": "0.67"}], "timestamp": "1769384632638", "event_type": "price_change"}}
{"_local_timestamp": "2026-01-25T23:43:59.053358+00:00", "data": {"market": "0x5bc23ef1d55fb8d4a1b21b7c8780aa1b6b019262dda806da8a79dc8ada217f33", "price_changes": [{"asset_id": "56888387443153290473779399645893214898197325618962871997813882665583407269175", "price": "0.18", "size": "2332", "side": "BUY", "hash": "43d879a2a8712074773c52c571016e9ce373454d", "best_bid": "0.65", "best_ask": "0.67"}, {"asset_id": "44152243636867873932593431458048174258413868830357636196802887961839805767798", "price": "0.82", "size": "2332", "side": "SELL", "hash": "75043f1b26d420103fb8f83b4c4ab05e2be39723", "best_bid": "0.33", "best_ask": "0.35"}], "timestamp": "1769384638762", "event_type": "price_change"}}
{"_local_timestamp": "2026-01-25T23:44:20.912045+00:00", "data": {"market": "0x5bc23ef1d55fb8d4a1b21b7c8780aa1b6b019262dda806da8a79dc8ada217f33", "price_changes": [{"asset_id": "56888387443153290473779399645893214898197325618962871997813882665583407269175", "price": "0.27", "size": "174.07", "side": "BUY", "hash": "d9708760d6e4b0b1a453ce56f53a503bcd276ab1", "best_bid": "0.65", "best_ask": "0.67"}, {"asset_id": "44152243636867873932593431458048174258413868830357636196802887961839805767798", "price": "0.73", "size": "174.07", "side": "SELL", "hash": "cf108e031fee32e7db502bd83d1ff14e57db71db", "best_bid": "0.33", "best_ask": "0.35"}], "timestamp": "1769384660483", "event_type": "price_change"}}
{"_local_timestamp": "2026-01-25T23:44:21.242565+00:00", "data": {"market": "0x5bc23ef1d55fb8d4a1b21b7c8780aa1b6b019262dda806da8a79dc8ada217f33", "price_changes": [{"asset_id": "56888387443153290473779399645893214898197325618962871997813882665583407269175", "price": "0.21", "size": "200", "side": "BUY", "hash": "0e26235bc1ddba8958101c2447ac0f15c365c1cb", "best_bid": "0.65", "best_ask": "0.67"}, {"asset_id": "44152243636867873932593431458048174258413868830357636196802887961839805767798", "price": "0.79", "size": "200", "side": "SELL", "hash": "a87da4633e90400109418e52fd5ecfea7d724133", "best_bid": "0.33", "best_ask": "0.35"}], "timestamp": "1769384660851", "event_type": "price_change"}}
{"_local_timestamp": "2026-01-25T23:44:32.494794+00:00", "data": {"market": "0x5bc23ef1d55fb8d4a1b21b7c8780aa1b6b019262dda806da8a79dc8ada217f33", "price_changes": [{"asset_id": "56888387443153290473779399645893214898197325618962871997813882665583407269175", "price": "0.18", "size": "0", "side": "BUY", "hash": "8085f740581462aa2a59134a4e4a7f1c6eda9583", "best_bid": "0.65", "best_ask": "0.67"}, {"asset_id": "44152243636867873932593431458048174258413868830357636196802887961839805767798", "price": "0.82", "size": "0", "side": "SELL", "hash": "c20c80572fbf7b58b432524468898c4ab064b3d3", "best_bid": "0.33", "best_ask": "0.35"}], "timestamp": "1769384672292", "event_type": "price_change"}}
{"_local_timestamp": "2026-01-25T23:44:35.633452+00:00", "data": {"market": "0x5bc23ef1d55fb8d4a1b21b7c8780aa1b6b019262dda806da8a79dc8ada217f33", "price_changes": [{"asset_id": "44152243636867873932593431458048174258413868830357636196802887961839805767798", "price": "0.02", "size": "2406.22", "side": "BUY", "hash": "3a2db24521061231ed54dd4bdccbc73a080aad3b", "best_bid": "0.33", "best_ask": "0.35"}, {"asset_id": "56888387443153290473779399645893214898197325618962871997813882665583407269175", "price": "0.98", "size": "2406.22", "side": "SELL", "hash": "4ea3d7a91ac2efde928229a47958ae4c24b520b0", "best_bid": "0.65", "best_ask": "0.67"}], "timestamp": "1769384675510", "event_type": "price_change"}}
{"_local_timestamp": "2026-01-25T23:44:35.889877+00:00", "data": {"market": "0x5bc23ef1d55fb8d4a1b21b7c8780aa1b6b019262dda806da8a79dc8ada217f33", "price_changes": [{"asset_id": "44152243636867873932593431458048174258413868830357636196802887961839805767798", "price": "0.05", "size": "1130.58", "side": "BUY", "hash": "3326dec40b7187caa1759aed44645d8db351921f", "best_bid": "0.33", "best_ask": "0.35"}, {"asset_id": "56888387443153290473779399645893214898197325618962871997813882665583407269175", "price": "0.95", "size": "1130.58", "side": "SELL", "hash": "b0577555d88b471b4f7f7b0188a14050510c55c3", "best_bid": "0.65", "best_ask": "0.67"}], "timestamp": "1769384675795", "event_type": "price_change"}}
{"_local_timestamp": "2026-01-25T23:44:37.482868+00:00", "data": {"market": "0x5bc23ef1d55fb8d4a1b21b7c8780aa1b6b019262dda806da8a79dc8ada217f33", "price_changes": [{"asset_id": "56888387443153290473779399645893214898197325618962871997813882665583407269175", "price": "0.16", "size": "1520", "side": "BUY", "hash": "78fb8ff9b6bb5f923e0d8f58309292ec52044777", "best_bid": "0.65", "best_ask": "0.67"}, {"asset_id": "44152243636867873932593431458048174258413868830357636196802887961839805767798", "price": "0.84", "size": "1520", "side": "SELL", "hash": "51333c3343221af9d6aa3171755f2610e2a10e40", "best_bid": "0.33", "best_ask": "0.35"}], "timestamp": "1769384677404", "event_type": "price_change"}}
{"_local_timestamp": "2026-01-25T23:44:37.754087+00:00", "data": {"market": "0x5bc23ef1d55fb8d4a1b21b7c8780aa1b6b019262dda806da8a79dc8ada217f33", "price_changes": [{"asset_id": "56888387443153290473779399645893214898197325618962871997813882665583407269175", "price": "0.18", "size": "50", "side": "BUY", "hash": "dd58be45e207ad524c69a8d02cbe771acd7fd1b1", "best_bid": "0.65", "best_ask": "0.67"}, {"asset_id": "44152243636867873932593431458048174258413868830357636196802887961839805767798", "price": "0.82", "size": "50", "side": "SELL", "hash": "0aca8e609a5934e9cb391b5161a83a0770c7f230", "best_bid": "0.33", "best_ask": "0.35"}], "timestamp": "1769384677680", "event_type": "price_change"}}
{"_local_timestamp": "2026-01-25T23:44:53.079797+00:00", "data": {"market": "0x5bc23ef1d55fb8d4a1b21b7c8780aa1b6b019262dda806da8a79dc8ada217f33", "price_changes": [{"asset_id": "44152243636867873932593431458048174258413868830357636196802887961839805767798", "price": "0.23", "size": "1317.6", "side": "BUY", "hash": "3c8bf0a910b88bccf5f62a81a90de336049ad07e", "best_bid": "0.33", "best_ask": "0.35"}, {"asset_id": "56888387443153290473779399645893214898197325618962871997813882665583407269175", "price": "0.77", "size": "1317.6", "side": "SELL", "hash": "744533f080f6273a1ee0e187d8dbb3ec4479c954", "best_bid": "0.65", "best_ask": "0.67"}], "timestamp": "1769384693000", "event_type": "price_change"}}
{"_local_timestamp": "2026-01-25T23:44:53.086097+00:00", "data": {"market": "0x5bc23ef1d55fb8d4a1b21b7c8780aa1b6b019262dda806da8a79dc8ada217f33", "price_changes": [{"asset_id": "44152243636867873932593431458048174258413868830357636196802887961839805767798", "price": "0.19", "size": "3128", "side": "BUY", "hash": "c1709c100e2eb60676dd1f791a591078b9543f01", "best_bid": "0.33", "best_ask": "0.35"}, {"asset_id": "56888387443153290473779399645893214898197325618962871997813882665583407269175", "price": "0.81", "size": "3128", "side": "SELL", "hash": "5c1824e0bfb65986c65eac6a26a04e6d685944fd", "best_bid": "0.65", "best_ask": "0.67"}], "timestamp": "1769384693002", "event_type": "price_change"}}
{"_local_timestamp": "2026-01-25T23:44:57.580682+00:00", "data": {"market": "0x5bc23ef1d55fb8d4a1b21b7c8780aa1b6b019262dda806da8a79dc8ada217f33", "price_changes": [{"asset_id": "56888387443153290473779399645893214898197325618962871997813882665583407269175", "price": "0.16", "size": "1370", "side": "BUY", "hash": "9ed8bf6e54b9f04f91dfaca34643fb04e27cc304", "best_bid": "0.65", "best_ask": "0.67"}, {"asset_id": "44152243636867873932593431458048174258413868830357636196802887961839805767798", "price": "0.84", "size": "1370", "side": "SELL", "hash": "1da9300b57ced6dcaf982bc80e83d9f9681f1d9c", "best_bid": "0.33", "best_ask": "0.35"}], "timestamp": "1769384697482", "event_type": "price_change"}}
{"_local_timestamp": "2026-01-25T23:44:57.581143+00:00", "data": {"market": "0x5bc23ef1d55fb8d4a1b21b7c8780aa1b6b019262dda806da8a79dc8ada217f33", "price_changes": [{"asset_id": "56888387443153290473779399645893214898197325618962871997813882665583407269175", "price": "0.23", "size": "104.34", "side": "BUY", "hash": "9ed8bf6e54b9f04f91dfaca34643fb04e27cc304", "best_bid": "0.65", "best_ask": "0.67"}, {"asset_id": "44152243636867873932593431458048174258413868830357636196802887961839805767798", "price": "0.77", "size": "104.34", "side": "SELL", "hash": "1da9300b57ced6dcaf982bc80e83d9f9681f1d9c", "best_bid": "0.33", "best_ask": "0.35"}], "timestamp": "1769384697482", "event_type": "price_change"}}
{"_local_timestamp": "2026-01-25T23:44:57.836999+00:00", "data": {"market": "0x5bc23ef1d55fb8d4a1b21b7c8780aa1b6b019262dda806da8a79dc8ada217f33", "price_changes": [{"asset_id": "56888387443153290473779399645893214898197325618962871997813882665583407269175", "price": "0.21", "size": "300", "side": "BUY", "hash": "4fbf2a39298d9ed2294a36573213dc0969c679a5", "best_bid": "0.65", "best_ask": "0.67"}, {"asset_id": "44152243636867873932593431458048174258413868830357636196802887961839805767798", "price": "0.79", "size": "300", "side": "SELL", "hash": "979a20d163ba5f13362dfe86fa51e2bd2675bd10", "best_bid": "0.33", "best_ask": "0.35"}], "timestamp": "1769384697729", "event_type": "price_change"}}
{"_local_timestamp": "2026-01-25T23:44:57.852549+00:00", "data": {"market": "0x5bc23ef1d55fb8d4a1b21b7c8780aa1b6b019262dda806da8a79dc8ada217f33", "price_changes": [{"asset_id": "56888387443153290473779399645893214898197325618962871997813882665583407269175", "price": "0.18", "size": "200", "side": "BUY", "hash": "e715ce17a4eee4405f54636b1d133cd5de7a40f9", "best_bid": "0.65", "best_ask": "0.67"}, {"asset_id": "44152243636867873932593431458048174258413868830357636196802887961839805767798", "price": "0.82", "size": "200", "side": "SELL", "hash": "de1220b664a89c1faf8becfd0cb2b51da1c47c4a", "best_bid": "0.33", "best_ask": "0.35"}], "timestamp": "1769384697745", "event_type": "price_change"}}
{"_local_timestamp": "2026-01-25T23:45:10.378647+00:00", "data": {"market": "0x5bc23ef1d55fb8d4a1b21b7c8780aa1b6b019262dda806da8a79dc8ada217f33", "price_changes": [{"asset_id": "56888387443153290473779399645893214898197325618962871997813882665583407269175", "price": "0.19", "size": "2210", "side": "BUY", "hash": "617da1805ecb00319f970850fe590f4aafab7eb7", "best_bid": "0.65", "best_ask": "0.67"}, {"asset_id": "44152243636867873932593431458048174258413868830357636196802887961839805767798", "price": "0.81", "size": "2210", "side": "SELL", "hash": "54151ed9e1d2684b828ea24b7e2b2742905682a5", "best_bid": "0.33", "best_ask": "0.35"}], "timestamp": "1769384710310", "event_type": "price_change"}}
{"_local_timestamp": "2026-01-25T23:45:20.073835+00:00", "data": {"market": "0x5bc23ef1d55fb8d4a1b21b7c8780aa1b6b019262dda806da8a79dc8ada217f33", "price_changes": [{"asset_id": "44152243636867873932593431458048174258413868830357636196802887961839805767798", "price": "0.19", "size": "3043", "side": "BUY", "hash": "c8d57aa0871d99fcdbcf87430ceff8e86bab4003", "best_bid": "0.33", "best_ask": "0.35"}, {"asset_id": "56888387443153290473779399645893214898197325618962871997813882665583407269175", "price": "0.81", "size": "3043", "side": "SELL", "hash": "bc19e05e4bd96b1c5b07bcb1cc95f3311d9c30a6", "best_bid": "0.65", "best_ask": "0.67"}], "timestamp": "1769384720000", "event_type": "price_change"}}
{"_local_timestamp": "2026-01-25T23:45:20.098748+00:00", "data": {"market": "0x5bc23ef1d55fb8d4a1b21b7c8780aa1b6b019262dda806da8a79dc8ada217f33", "price_changes": [{"asset_id": "44152243636867873932593431458048174258413868830357636196802887961839805767798", "price": "0.23", "size": "1238.6", "side": "BUY", "hash": "7432fab351bee31bc81c42b5682411d250bdcf0c", "best_bid": "0.33", "best_ask": "0.35"}, {"asset_id": "56888387443153290473779399645893214898197325618962871997813882665583407269175", "price": "0.77", "size": "1238.6", "side": "SELL", "hash": "a7fedba24e41f1bc1e57babfccbc706c9ecc1ed9", "best_bid": "0.65", "best_ask": "0.67"}], "timestamp": "1769384720003", "event_type": "price_change"}}
{"_local_timestamp": "2026-01-25T23:45:22.860225+00:00", "data": {"market": "0x5bc23ef1d55fb8d4a1b21b7c8780aa1b6b019262dda806da8a79dc8ada217f33", "price_changes": [{"asset_id": "44152243636867873932593431458048174258413868830357636196802887961839805767798", "price": "0.31", "size": "250", "side": "BUY", "hash": "693484f41cd408b13af83fb31dcb440230121b53", "best_bid": "0.33", "best_ask": "0.35"}, {"asset_id": "56888387443153290473779399645893214898197325618962871997813882665583407269175", "price": "0.69", "size": "250", "side": "SELL", "hash": "9630898c498f059ce2cdca59494d94fbb935ffb3", "best_bid": "0.65", "best_ask": "0.67"}], "timestamp": "1769384722772", "event_type": "price_change"}}
{"_local_timestamp": "2026-01-25T23:45:22.882122+00:00", "data": {"market": "0x5bc23ef1d55fb8d4a1b21b7c8780aa1b6b019262dda806da8a79dc8ada217f33", "price_changes": [{"asset_id": "56888387443153290473779399645893214898197325618962871997813882665583407269175", "price": "0.63", "size": "408.79", "side": "BUY", "hash": "63c136da72ab3d9152fadad6061ac116c64cb680", "best_bid": "0.65", "best_ask": "0.67"}, {"asset_id": "44152243636867873932593431458048174258413868830357636196802887961839805767798", "price": "0.37", "size": "408.79", "side": "SELL", "hash": "1afc57f03e7da789c4a3880104a84fff0b037f81", "best_bid": "0.33", "best_ask": "0.35"}], "timestamp": "1769384722775", "event_type": "price_change"}}
{"_local_timestamp": "2026-01-25T23:45:23.814708+00:00", "data": {"market": "0x5bc23ef1d55fb8d4a1b21b7c8780aa1b6b019262dda806da8a79dc8ada217f33", "price_changes": [{"asset_id": "44152243636867873932593431458048174258413868830357636196802887961839805767798", "price": "0.02", "size": "1606.22", "side": "BUY", "hash": "6212131e7a5997406c007b774d62b9e026b73f0c", "best_bid": "0.33", "best_ask": "0.35"}, {"asset_id": "56888387443153290473779399645893214898197325618962871997813882665583407269175", "price": "0.98", "size": "1606.22", "side": "SELL", "hash": "595b7e4973c5a51422f5b586f0e79bdc961327e7", "best_bid": "0.65", "best_ask": "0.67"}], "timestamp": "1769384723745", "event_type": "price_change"}}
{"_local_timestamp": "2026-01-25T23:45:23.815259+00:00", "data": {"market": "0x5bc23ef1d55fb8d4a1b21b7c8780aa1b6b019262dda806da8a79dc8ada217f33", "price_changes": [{"asset_id": "56888387443153290473779399645893214898197325618962871997813882665583407269175", "price": "0.18", "size": "150", "side": "BUY", "hash": "68322265ef1b164b36dbdb8f68ae68f2f1bdfb51", "best_bid": "0.65", "best_ask": "0.67"}, {"asset_id": "44152243636867873932593431458048174258413868830357636196802887961839805767798", "price": "0.82", "size": "150", "side": "SELL", "hash": "de95daa923a2b7d5fb5c2f5082011199c0de4e79", "best_bid": "0.33", "best_ask": "0.35"}], "timestamp": "1769384723746", "event_type": "price_change"}}
{"_local_timestamp": "2026-01-25T23:45:24.143822+00:00", "data": {"market": "0x5bc23ef1d55fb8d4a1b21b7c8780aa1b6b019262dda806da8a79dc8ada217f33", "price_changes": [{"asset_id": "44152243636867873932593431458048174258413868830357636196802887961839805767798", "price": "0.05", "size": "1630.58", "side": "BUY", "hash": "96852485de4036eb7b0d53ee502fc9b1b610ce9a", "best_bid": "0.33", "best_ask": "0.35"}, {"asset_id": "56888387443153290473779399645893214898197325618962871997813882665583407269175", "price": "0.95", "size": "1630.58", "side": "SELL", "hash": "d3be711322acfbb4759266addbf7b29d5aa697f0", "best_bid": "0.65", "best_ask": "0.67"}], "timestamp": "1769384724065", "event_type": "price_change"}}
{"_local_timestamp": "2026-01-25T23:45:24.152493+00:00", "data": {"market": "0x5bc23ef1d55fb8d4a1b21b7c8780aa1b6b019262dda806da8a79dc8ada217f33", "price_changes": [{"asset_id": "56888387443153290473779399645893214898197325618962871997813882665583407269175", "price": "0.16", "size": "1420", "side": "BUY", "hash": "5bbf4cca66e92aa0ee44d2936af486d85bcae65e", "best_bid": "0.65", "best_ask": "0.67"}, {"asset_id": "44152243636867873932593431458048174258413868830357636196802887961839805767798", "price": "0.84", "size": "1420", "side": "SELL", "hash": "0d4a3c2cdf9dcdab982826e7cd999d9e61dde010", "best_bid": "0.33", "best_ask": "0.35"}], "timestamp": "1769384724078", "event_type": "price_change"}}
{"_local_timestamp": "2026-01-25T23:45:38.907089+00:00", "data": {"market": "0x5bc23ef1d55fb8d4a1b21b7c8780aa1b6b019262dda806da8a79dc8ada217f33", "price_changes": [{"asset_id": "56888387443153290473779399645893214898197325618962871997813882665583407269175", "price": "0.18", "size": "0", "side": "BUY", "hash": "203120ec2955e3dd5eaa485961deb7a607d0d97b", "best_bid": "0.65", "best_ask": "0.67"}, {"asset_id": "44152243636867873932593431458048174258413868830357636196802887961839805767798", "price": "0.82", "size": "0", "side": "SELL", "hash": "ee80d19d6d3146fac7eab277ea78e7ac2836f4c7", "best_bid": "0.33", "best_ask": "0.35"}], "timestamp": "1769384738812", "event_type": "price_change"}}
{"_local_timestamp": "2026-01-25T23:45:39.219444+00:00", "data": {"market": "0x5bc23ef1d55fb8d4a1b21b7c8780aa1b6b019262dda806da8a79dc8ada217f33", "price_changes": [{"asset_id": "56888387443153290473779399645893214898197325618962871997813882665583407269175", "price": "0.16", "size": "1570", "side": "BUY", "hash": "f6ccb3027bd7fa6905bf5020f4b61f9b02d66f47", "best_bid": "0.65", "best_ask": "0.67"}, {"asset_id": "44152243636867873932593431458048174258413868830357636196802887961839805767798", "price": "0.84", "size": "1570", "side": "SELL", "hash": "79c37be2aae8c6e14015af84e12e95737060fc4b", "best_bid": "0.33", "best_ask": "0.35"}], "timestamp": "1769384739085", "event_type": "price_change"}}
{"_local_timestamp": "2026-01-25T23:45:41.587349+00:00", "data": {"market": "0x5bc23ef1d55fb8d4a1b21b7c8780aa1b6b019262dda806da8a79dc8ada217f33", "price_changes": [{"asset_id": "44152243636867873932593431458048174258413868830357636196802887961839805767798", "price": "0.31", "size": "350", "side": "BUY", "hash": "dbe176d7cc655dfb3f69e5f1f16f35b15ecbcbba", "best_bid": "0.33", "best_ask": "0.35"}, {"asset_id": "56888387443153290473779399645893214898197325618962871997813882665583407269175", "price": "0.69", "size": "350", "side": "SELL", "hash": "e40d49db3d088edae35eb1d654ef7494d136eed7", "best_bid": "0.65", "best_ask": "0.67"}], "timestamp": "1769384741512", "event_type": "price_change"}}
{"_local_timestamp": "2026-01-25T23:45:46.394156+00:00", "data": {"market": "0x5bc23ef1d55fb8d4a1b21b7c8780aa1b6b019262dda806da8a79dc8ada217f33", "price_changes": [{"asset_id": "56888387443153290473779399645893214898197325618962871997813882665583407269175", "price": "0.63", "size": "508.79", "side": "BUY", "hash": "41d0ae778a263bf5e025f8a3ffd971ed9fa2f5a9", "best_bid": "0.65", "best_ask": "0.67"}, {"asset_id": "44152243636867873932593431458048174258413868830357636196802887961839805767798", "price": "0.37", "size": "508.79", "side": "SELL", "hash": "c57f0e844418c52db38813277169fb9e7ef4e41a", "best_bid": "0.33", "best_ask": "0.35"}], "timestamp": "1769384746328", "event_type": "price_change"}}
{"_local_timestamp": "2026-01-25T23:45:53.178121+00:00", "data": {"market": "0x5bc23ef1d55fb8d4a1b21b7c8780aa1b6b019262dda806da8a79dc8ada217f33", "price_changes": [{"asset_id": "56888387443153290473779399645893214898197325618962871997813882665583407269175", "price": "0.16", "size": "1470", "side": "BUY", "hash": "54a4ae55971ed3ae279975ad1d203f7a16f6c462", "best_bid": "0.65", "best_ask": "0.67"}, {"asset_id": "44152243636867873932593431458048174258413868830357636196802887961839805767798", "price": "0.84", "size": "1470", "side": "SELL", "hash": "03460bb0304241c7f13434376cd7aacc923c7ce8", "best_bid": "0.33", "best_ask": "0.35"}], "timestamp": "1769384753010", "event_type": "price_change"}}
{"_local_timestamp": "2026-01-25T23:45:53.178711+00:00", "data": {"market": "0x5bc23ef1d55fb8d4a1b21b7c8780aa1b6b019262dda806da8a79dc8ada217f33", "price_changes": [{"asset_id": "56888387443153290473779399645893214898197325618962871997813882665583407269175", "price": "0.21", "size": "250", "side": "BUY", "hash": "54a4ae55971ed3ae279975ad1d203f7a16f6c462", "best_bid": "0.65", "best_ask": "0.67"}, {"asset_id": "44152243636867873932593431458048174258413868830357636196802887961839805767798", "price": "0.79", "size": "250", "side": "SELL", "hash": "03460bb0304241c7f13434376cd7aacc923c7ce8", "best_bid": "0.33", "best_ask": "0.35"}], "timestamp": "1769384753010", "event_type": "price_change"}}
{"_local_timestamp": "2026-01-25T23:45:53.698633+00:00", "data": {"market": "0x5bc23ef1d55fb8d4a1b21b7c8780aa1b6b019262dda806da8a79dc8ada217f33", "price_changes": [{"asset_id": "56888387443153290473779399645893214898197325618962871997813882665583407269175", "price": "0.18", "size": "100", "side": "BUY", "hash": "374b5b25c7bf929ae962bc3a015b219f292d904e", "best_bid": "0.65", "best_ask": "0.67"}, {"asset_id": "44152243636867873932593431458048174258413868830357636196802887961839805767798", "price": "0.82", "size": "100", "side": "SELL", "hash": "e9e1f05acb45e3711309b271948f0d55da191ea2", "best_bid": "0.33", "best_ask": "0.35"}], "timestamp": "1769384753527", "event_type": "price_change"}}
{"_local_timestamp": "2026-01-25T23:45:53.738668+00:00", "data": {"market": "0x5bc23ef1d55fb8d4a1b21b7c8780aa1b6b019262dda806da8a79dc8ada217f33", "price_changes": [{"asset_id": "56888387443153290473779399645893214898197325618962871997813882665583407269175", "price": "0.27", "size": "224.07", "side": "BUY", "hash": "1dca27d226639e00aaeb4919c66acae850945888", "best_bid": "0.65", "best_ask": "0.67"}, {"asset_id": "44152243636867873932593431458048174258413868830357636196802887961839805767798", "price": "0.73", "size": "224.07", "side": "SELL", "hash": "f8767350d11bd61e3d7bb375da0e431d1ee1e93e", "best_bid": "0.33", "best_ask": "0.35"}], "timestamp": "1769384753558", "event_type": "price_change"}}
{"_local_timestamp": "2026-01-25T23:46:05.206472+00:00", "data": {"market": "0x5bc23ef1d55fb8d4a1b21b7c8780aa1b6b019262dda806da8a79dc8ada217f33", "price_changes": [{"asset_id": "44152243636867873932593431458048174258413868830357636196802887961839805767798", "price": "0.23", "size": "1356.6", "side": "BUY", "hash": "0cef4defdead9093a8b21bcfa47458e2b6ac6ae9", "best_bid": "0.33", "best_ask": "0.35"}, {"asset_id": "56888387443153290473779399645893214898197325618962871997813882665583407269175", "price": "0.77", "size": "1356.6", "side": "SELL", "hash": "ac5cf92b5e5fc33c6e5b18c772d48d4846b0673f", "best_bid": "0.65", "best_ask": "0.67"}], "timestamp": "1769384765129", "event_type": "price_change"}}
{"_local_timestamp": "2026-01-25T23:46:05.208557+00:00", "data": {"market": "0x5bc23ef1d55fb8d4a1b21b7c8780aa1b6b019262dda806da8a79dc8ada217f33", "price_changes": [{"asset_id": "44152243636867873932593431458048174258413868830357636196802887961839805767798", "price": "0.26", "size": "591", "side": "BUY", "hash": "b9ff278760f27523c9d425a0b8ad5df534729c5e", "best_bid": "0.33", "best_ask": "0.35"}, {"asset_id": "56888387443153290473779399645893214898197325618962871997813882665583407269175", "price": "0.74", "size": "591", "side": "SELL", "hash": "2c8fb36d7635c327c7ecf17e77b69514053fd56a", "best_bid": "0.65", "best_ask": "0.67"}], "timestamp": "1769384765132", "event_type": "price_change"}}
{"_local_timestamp": "2026-01-25T23:46:05.208990+00:00", "data": {"market": "0x5bc23ef1d55fb8d4a1b21b7c8780aa1b6b019262dda806da8a79dc8ada217f33", "price_changes": [{"asset_id": "44152243636867873932593431458048174258413868830357636196802887961839805767798", "price": "0.29", "size": "615", "side": "BUY", "hash": "7ef24dc791fb1fd136b0b8a3b49d534747734ab1", "best_bid": "0.33", "best_ask": "0.35"}, {"asset_id": "56888387443153290473779399645893214898197325618962871997813882665583407269175", "price": "0.71", "size": "615", "side": "SELL", "hash": "f0d5b5aeaf73ea6e0376934e37bf3402db93a833", "best_bid": "0.65", "best_ask": "0.67"}], "timestamp": "1769384765134", "event_type": "price_change"}}
{"_local_timestamp": "2026-01-25T23:46:05.209429+00:00", "data": {"market": "0x5bc23ef1d55fb8d4a1b21b7c8780aa1b6b019262dda806da8a79dc8ada217f33", "price_changes": [{"asset_id": "44152243636867873932593431458048174258413868830357636196802887961839805767798", "price": "0.19", "size": "3223", "side": "BUY", "hash": "24bd5e661f07f10cb433c8460012538f01aa5607", "best_bid": "0.33", "best_ask": "0.35"}, {"asset_id": "56888387443153290473779399645893214898197325618962871997813882665583407269175", "price": "0.81", "size": "3223", "side": "SELL", "hash": "cf8bc07118cd4f7088536033065bd4a409d7af10", "best_bid": "0.65", "best_ask": "0.67"}], "timestamp": "1769384765137", "event_type": "price_change"}}
{"_local_timestamp": "2026-01-25T23:46:10.586427+00:00", "data": {"market": "0x5bc23ef1d55fb8d4a1b21b7c8780aa1b6b019262dda806da8a79dc8ada217f33", "price_changes": [{"asset_id": "56888387443153290473779399645893214898197325618962871997813882665583407269175", "price": "0.19", "size": "0", "side": "BUY", "hash": "15493b31ad8b5bf4b22bacd0f58ed215370c402e", "best_bid": "0.65", "best_ask": "0.67"}, {"asset_id": "44152243636867873932593431458048174258413868830357636196802887961839805767798", "price": "0.81", "size": "0", "side": "SELL", "hash": "302e712088bcad5d415311dbee24100353a0aed6", "best_bid": "0.33", "best_ask": "0.35"}], "timestamp": "1769384770468", "event_type": "price_change"}}
{"_local_timestamp": "2026-01-25T23:46:12.255153+00:00", "data": {"market": "0x5bc23ef1d55fb8d4a1b21b7c8780aa1b6b019262dda806da8a79dc8ada217f33", "price_changes": [{"asset_id": "56888387443153290473779399645893214898197325618962871997813882665583407269175", "price": "0.16", "size": "1420", "side": "BUY", "hash": "a4f3a281ed0e76968dd0c478142256fc14f8fb4b", "best_bid": "0.65", "best_ask": "0.67"}, {"asset_id": "44152243636867873932593431458048174258413868830357636196802887961839805767798", "price": "0.84", "size": "1420", "side": "SELL", "hash": "8c5cb9e3e39a5cb1b97848b51713dab840f59811", "best_bid": "0.33", "best_ask": "0.35"}], "timestamp": "1769384772187", "event_type": "price_change"}}
{"_local_timestamp": "2026-01-25T23:46:12.777438+00:00", "data": {"market": "0x5bc23ef1d55fb8d4a1b21b7c8780aa1b6b019262dda806da8a79dc8ada217f33", "price_changes": [{"asset_id": "56888387443153290473779399645893214898197325618962871997813882665583407269175", "price": "0.19", "size": "50", "side": "BUY", "hash": "b694c1bb906c9b1ef6ed6b78aa009e09ccb97a20", "best_bid": "0.65", "best_ask": "0.67"}, {"asset_id": "44152243636867873932593431458048174258413868830357636196802887961839805767798", "price": "0.81", "size": "50", "side": "SELL", "hash": "d64c060ca013fb93418a84e195ea2fa71986aa11", "best_bid": "0.33", "best_ask": "0.35"}], "timestamp": "1769384772707", "event_type": "price_change"}}
{"_local_timestamp": "2026-01-25T23:46:17.121437+00:00", "data": {"market": "0x5bc23ef1d55fb8d4a1b21b7c8780aa1b6b019262dda806da8a79dc8ada217f33", "price_changes": [{"asset_id": "44152243636867873932593431458048174258413868830357636196802887961839805767798", "price": "0.05", "size": "1230.58", "side": "BUY", "hash": "24559dc62590f750845abbe827c8c64492a1ec93", "best_bid": "0.33", "best_ask": "0.35"}, {"asset_id": "56888387443153290473779399645893214898197325618962871997813882665583407269175", "price": "0.95", "size": "1230.58", "side": "SELL", "hash": "fca42118179f2fedd38ab35748078763bd276576", "best_bid": "0.65", "best_ask": "0.67"}], "timestamp": "1769384777002", "event_type": "price_change"}}
{"_local_timestamp": "2026-01-25T23:46:17.390721+00:00", "data": {"market": "0x5bc23ef1d55fb8d4a1b21b7c8780aa1b6b019262dda806da8a79dc8ada217f33", "price_changes": [{"asset_id": "44152243636867873932593431458048174258413868830357636196802887961839805767798", "price": "0.02", "size": "2006.22", "side": "BUY", "hash": "3cfc6a901e34eab588af4e9e72f2cfc59d02dc8c", "best_bid": "0.33", "best_ask": "0.35"}, {"asset_id": "56888387443153290473779399645893214898197325618962871997813882665583407269175", "price": "0.98", "size": "2006.22", "side": "SELL", "hash": "e80c909c9ad9936a7c0c70f67f4ad4b62091f16a", "best_bid": "0.65", "best_ask": "0.67"}], "timestamp": "1769384777310", "event_type": "price_change"}}
{"_local_timestamp": "2026-01-25T23:46:17.451950+00:00", "data": {"market": "0x5bc23ef1d55fb8d4a1b21b7c8780aa1b6b019262dda806da8a79dc8ada217f33", "price_changes": [{"asset_id": "56888387443153290473779399645893214898197325618962871997813882665583407269175", "price": "0.16", "size": "1270", "side": "BUY", "hash": "9b4184fb69a00223c3f30811ca353d3183695775", "best_bid": "0.65", "best_ask": "0.67"}, {"asset_id": "44152243636867873932593431458048174258413868830357636196802887961839805767798", "price": "0.84", "size": "1270", "side": "SELL", "hash": "d650008a141aa7b2f066ecd54bed49185f3c7eaa", "best_bid": "0.33", "best_ask": "0.35"}], "timestamp": "1769384777374", "event_type": "price_change"}}
{"_local_timestamp": "2026-01-25T23:46:17.695121+00:00", "data": {"market": "0x5bc23ef1d55fb8d4a1b21b7c8780aa1b6b019262dda806da8a79dc8ada217f33", "price_changes": [{"asset_id": "56888387443153290473779399645893214898197325618962871997813882665583407269175", "price": "0.19", "size": "200", "side": "BUY", "hash": "becc58d37980f4d4ff2e1a9497e07bd7dcd9e67b", "best_bid": "0.65", "best_ask": "0.67"}, {"asset_id": "44152243636867873932593431458048174258413868830357636196802887961839805767798", "price": "0.81", "size": "200", "side": "SELL", "hash": "ef56a99a121c4e3f476f80a5497b89e9cd4a69a6", "best_bid": "0.33", "best_ask": "0.35"}], "timestamp": "1769384777629", "event_type": "price_change"}}
{"_local_timestamp": "2026-01-25T23:46:26.035218+00:00", "data": {"market": "0x5bc23ef1d55fb8d4a1b21b7c8780aa1b6b019262dda806da8a79dc8ada217f33", "price_changes": [{"asset_id": "56888387443153290473779399645893214898197325618962871997813882665583407269175", "price": "0.18", "size": "2432", "side": "BUY", "hash": "b9c056e53e31c68881f8d5771e31dbf392690a6e", "best_bid": "0.65", "best_ask": "0.67"}, {"asset_id": "44152243636867873932593431458048174258413868830357636196802887961839805767798", "price": "0.82", "size": "2432", "side": "SELL", "hash": "ef016c17eda18859ed60e310449c2cbe44749582", "best_bid": "0.33", "best_ask": "0.35"}], "timestamp": "1769384785952", "event_type": "price_change"}}
{"_local_timestamp": "2026-01-25T23:46:31.097120+00:00", "data": {"market": "0x5bc23ef1d55fb8d4a1b21b7c8780aa1b6b019262dda806da8a79dc8ada217f33", "price_changes": [{"asset_id": "44152243636867873932593431458048174258413868830357636196802887961839805767798", "price": "0.29", "size": "432", "side": "BUY", "hash": "1b0fcdb960065a911e278a9e3c5f23da04bf8333", "best_bid": "0.33", "best_ask": "0.35"}, {"asset_id": "56888387443153290473779399645893214898197325618962871997813882665583407269175", "price": "0.71", "size": "432", "side": "SELL", "hash": "18447e210de65a8c4bd93f5122c019a35d3ba92e", "best_bid": "0.65", "best_ask": "0.67"}], "timestamp": "1769384791000", "event_type": "price_change"}}
{"_local_timestamp": "2026-01-25T23:46:34.814761+00:00", "data": {"market": "0x5bc23ef1d55fb8d4a1b21b7c8780aa1b6b019262dda806da8a79dc8ada217f33", "price_changes": [{"asset_id": "44152243636867873932593431458048174258413868830357636196802887961839805767798", "price": "0.29", "size": "615", "side": "BUY", "hash": "e4175506d3ed89ff7f5c517de6c515a6c2ff66e1", "best_bid": "0.33", "best_ask": "0.35"}, {"asset_id": "56888387443153290473779399645893214898197325618962871997813882665583407269175", "price": "0.71", "size": "615", "side": "SELL", "hash": "c34804bbaa853a41bcdc4a0e6b1a1d2500afee86", "best_bid": "0.65", "best_ask": "0.67"}], "timestamp": "1769384794737", "event_type": "price_change"}}
{"_local_timestamp": "2026-01-25T23:46:50.816981+00:00", "data": {"market": "0x5bc23ef1d55fb8d4a1b21b7c8780aa1b6b019262dda806da8a79dc8ada217f33", "price_changes": [{"asset_id": "56888387443153290473779399645893214898197325618962871997813882665583407269175", "price": "0.16", "size": "1120", "side": "BUY", "hash": "301af732a0fc7b91d140703f4734af1a90d5c383", "best_bid": "0.65", "best_ask": "0.67"}, {"asset_id": "44152243636867873932593431458048174258413868830357636196802887961839805767798", "price": "0.84", "size": "1120", "side": "SELL", "hash": "e24d10963344e7caa62da01d83f4a3c76aee5223", "best_bid": "0.33", "best_ask": "0.35"}], "timestamp": "1769384810650", "event_type": "price_change"}}
{"_local_timestamp": "2026-01-25T23:46:50.817866+00:00", "data": {"market": "0x5bc23ef1d55fb8d4a1b21b7c8780aa1b6b019262dda806da8a79dc8ada217f33", "price_changes": [{"asset_id": "56888387443153290473779399645893214898197325618962871997813882665583407269175", "price": "0.21", "size": "150", "side": "BUY", "hash": "301af732a0fc7b91d140703f4734af1a90d5c383", "best_bid": "0.65", "best_ask": "0.67"}, {"asset_id": "44152243636867873932593431458048174258413868830357636196802887961839805767798", "price": "0.79", "size": "150", "side": "SELL", "hash": "e24d10963344e7caa62da01d83f4a3c76aee5223", "best_bid": "0.33", "best_ask": "0.35"}], "timestamp": "1769384810650", "event_type": "price_change"}}
{"_local_timestamp": "2026-01-25T23:46:51.628105+00:00", "data": {"market": "0x5bc23ef1d55fb8d4a1b21b7c8780aa1b6b019262dda806da8a79dc8ada217f33", "price_changes": [{"asset_id": "56888387443153290473779399645893214898197325618962871997813882665583407269175", "price": "0.18", "size": "2582", "side": "BUY", "hash": "27626be3c6a3a8571ed1762c769ce3931f230686", "best_bid": "0.65", "best_ask": "0.67"}, {"asset_id": "44152243636867873932593431458048174258413868830357636196802887961839805767798", "price": "0.82", "size": "2582", "side": "SELL", "hash": "505c0520247d462119efc5c30a747a259c9e3fd9", "best_bid": "0.33", "best_ask": "0.35"}], "timestamp": "1769384811238", "event_type": "price_change"}}
{"_local_timestamp": "2026-01-25T23:46:51.670838+00:00", "data": {"market": "0x5bc23ef1d55fb8d4a1b21b7c8780aa1b6b019262dda806da8a79dc8ada217f33", "price_changes": [{"asset_id": "56888387443153290473779399645893214898197325618962871997813882665583407269175", "price": "0.27", "size": "324.07", "side": "BUY", "hash": "81b4999432665c666fdae0ce94db4749e50c9738", "best_bid": "0.65", "best_ask": "0.67"}, {"asset_id": "44152243636867873932593431458048174258413868830357636196802887961839805767798", "price": "0.73", "size": "324.07", "side": "SELL", "hash": "a1f77a15035a0e83823417c6395c04b4811fee04", "best_bid": "0.33", "best_ask": "0.35"}], "timestamp": "1769384811276", "event_type": "price_change"}}
{"_local_timestamp": "2026-01-25T23:46:58.505673+00:00", "data": {"market": "0x5bc23ef1d55fb8d4a1b21b7c8780aa1b6b019262dda806da8a79dc8ada217f33", "price_changes": [{"asset_id": "56888387443153290473779399645893214898197325618962871997813882665583407269175", "price": "0.19", "size": "150", "side": "BUY", "hash": "7bfce4dfb4ee4b0341b0eb9655ccf61fe25a6676", "best_bid": "0.65", "best_ask": "0.67"}, {"asset_id": "44152243636867873932593431458048174258413868830357636196802887961839805767798", "price": "0.81", "size": "150", "side": "SELL", "hash": "9ee91e4e5e3f681ef09e2cc311ea4e20622ed006", "best_bid": "0.33", "best_ask": "0.35"}], "timestamp": "1769384818398", "event_type": "price_change"}}
{"_local_timestamp": "2026-01-25T23:46:58.506312+00:00", "data": {"market": "0x5bc23ef1d55fb8d4a1b21b7c8780aa1b6b019262dda806da8a79dc8ada217f33", "price_changes": [{"asset_id": "44152243636867873932593431458048174258413868830357636196802887961839805767798", "price": "0.05", "size": "730.58", "side": "BUY", "hash": "44f27aec1ab90be6e49138bcf48e4a4015ff6e06", "best_bid": "0.33", "best_ask": "0.35"}, {"asset_id": "56888387443153290473779399645893214898197325618962871997813882665583407269175", "price": "0.95", "size": "730.58", "side": "SELL", "hash": "9061737a52e61458d204d54983680b3a5732cd8b", "best_bid": "0.65", "best_ask": "0.67"}], "timestamp": "1769384818401", "event_type": "price_change"}}
{"_local_timestamp": "2026-01-25T23:46:58.782957+00:00", "data": {"market": "0x5bc23ef1d55fb8d4a1b21b7c8780aa1b6b019262dda806da8a79dc8ada217f33", "price_changes": [{"asset_id": "44152243636867873932593431458048174258413868830357636196802887961839805767798", "price": "0.02", "size": "2806.22", "side": "BUY", "hash": "8919689b9f29f414160bff9d8557ed0c8e6b9d35", "best_bid": "0.33", "best_ask": "0.35"}, {"asset_id": "56888387443153290473779399645893214898197325618962871997813882665583407269175", "price": "0.98", "size": "2806.22", "side": "SELL", "hash": "fc24abcee032bf3b0e232e9b026245a757a54222", "best_bid": "0.65", "best_ask": "0.67"}], "timestamp": "1769384818702", "event_type": "price_change"}}
{"_local_timestamp": "2026-01-25T23:46:58.801805+00:00", "data": {"market": "0x5bc23ef1d55fb8d4a1b21b7c8780aa1b6b019262dda806da8a79dc8ada217f33", "price_changes": [{"asset_id": "56888387443153290473779399645893214898197325618962871997813882665583407269175", "price": "0.16", "size": "1170", "side": "BUY", "hash": "edc7e6a1b950d0307379e845ed5ecdb4c044ca26", "best_bid": "0.65", "best_ask": "0.67"}, {"asset_id": "44152243636867873932593431458048174258413868830357636196802887961839805767798", "price": "0.84", "size": "1170", "side": "SELL", "hash": "0b7593a49eb16304b509ded4848a4869ff6eb4df", "best_bid": "0.33", "best_ask": "0.35"}], "timestamp": "1769384818716", "event_type": "price_change"}}
{"_local_timestamp": "2026-01-25T23:46:58.984352+00:00", "data": {"market": "0x5bc23ef1d55fb8d4a1b21b7c8780aa1b6b019262dda806da8a79dc8ada217f33", "price_changes": [{"asset_id": "56888387443153290473779399645893214898197325618962871997813882665583407269175", "price": "0.19", "size": "0", "side": "BUY", "hash": "a819a3cb6a86244e493e8b5a762d07ae8af5d11f", "best_bid": "0.65", "best_ask": "0.67"}, {"asset_id": "44152243636867873932593431458048174258413868830357636196802887961839805767798", "price": "0.81", "size": "0", "side": "SELL", "hash": "02a01f01c463ce2ae50fa7026293312e881b7491", "best_bid": "0.33", "best_ask": "0.35"}], "timestamp": "1769384818866", "event_type": "price_change"}}
{"_local_timestamp": "2026-01-25T23:46:59.304947+00:00", "data": {"market": "0x5bc23ef1d55fb8d4a1b21b7c8780aa1b6b019262dda806da8a79dc8ada217f33", "price_changes": [{"asset_id": "56888387443153290473779399645893214898197325618962871997813882665583407269175", "price": "0.16", "size": "1320", "side": "BUY", "hash": "917ee6d0989988d7ce2e80526937c5a0e827199b", "best_bid": "0.65", "best_ask": "0.67"}, {"asset_id": "44152243636867873932593431458048174258413868830357636196802887961839805767798", "price": "0.84", "size": "1320", "side": "SELL", "hash": "5baec731388ce1f2654e523ca8ae3a98054d2652", "best_bid": "0.33", "best_ask": "0.35"}], "timestamp": "1769384819176", "event_type": "price_change"}}
{"_local_timestamp": "2026-01-25T23:47:37.416013+00:00", "data": {"market": "0x5bc23ef1d55fb8d4a1b21b7c8780aa1b6b019262dda806da8a79dc8ada217f33", "price_changes": [{"asset_id": "56888387443153290473779399645893214898197325618962871997813882665583407269175", "price": "0.21", "size": "50", "side": "BUY", "hash": "b9e78db1c3faad600811f176536a0354112df6c2", "best_bid": "0.65", "best_ask": "0.67"}, {"asset_id": "44152243636867873932593431458048174258413868830357636196802887961839805767798", "price": "0.79", "size": "50", "side": "SELL", "hash": "ad0bef55b2f978e6c3e0cc77d8df37f712aa3aab", "best_bid": "0.33", "best_ask": "0.35"}], "timestamp": "1769384857300", "event_type": "price_change"}}
{"_local_timestamp": "2026-01-25T23:47:37.416736+00:00", "data": {"market": "0x5bc23ef1d55fb8d4a1b21b7c8780aa1b6b019262dda806da8a79dc8ada217f33", "price_changes": [{"asset_id": "56888387443153290473779399645893214898197325618962871997813882665583407269175", "price": "0.16", "size": "1170", "side": "BUY", "hash": "b9e78db1c3faad600811f176536a0354112df6c2", "best_bid": "0.65", "best_ask": "0.67"}, {"asset_id": "44152243636867873932593431458048174258413868830357636196802887961839805767798", "price": "0.84", "size": "1170", "side": "SELL", "hash": "ad0bef55b2f978e6c3e0cc77d8df37f712aa3aab", "best_bid": "0.33", "best_ask": "0.35"}], "timestamp": "1769384857300", "event_type": "price_change"}}
{"_local_timestamp": "2026-01-25T23:47:37.690666+00:00", "data": {"market": "0x5bc23ef1d55fb8d4a1b21b7c8780aa1b6b019262dda806da8a79dc8ada217f33", "price_changes": [{"asset_id": "56888387443153290473779399645893214898197325618962871997813882665583407269175", "price": "0.18", "size": "2482", "side": "BUY", "hash": "6a8b32e7e6f5cd211095b2d38b4e6e60f8f529c2", "best_bid": "0.65", "best_ask": "0.67"}, {"asset_id": "44152243636867873932593431458048174258413868830357636196802887961839805767798", "price": "0.82", "size": "2482", "side": "SELL", "hash": "08ef16d23856c3d13354198ceab93eff030ad07f", "best_bid": "0.33", "best_ask": "0.35"}], "timestamp": "1769384857535", "event_type": "price_change"}}
{"_local_timestamp": "2026-01-25T23:47:37.691208+00:00", "data": {"market": "0x5bc23ef1d55fb8d4a1b21b7c8780aa1b6b019262dda806da8a79dc8ada217f33", "price_changes": [{"asset_id": "56888387443153290473779399645893214898197325618962871997813882665583407269175", "price": "0.27", "size": "274.07", "side": "BUY", "hash": "6a8b32e7e6f5cd211095b2d38b4e6e60f8f529c2", "best_bid": "0.65", "best_ask": "0.67"}, {"asset_id": "44152243636867873932593431458048174258413868830357636196802887961839805767798", "price": "0.73", "size": "274.07", "side": "SELL", "hash": "08ef16d23856c3d13354198ceab93eff030ad07f", "best_bid": "0.33", "best_ask": "0.35"}], "timestamp": "1769384857535", "event_type": "price_change"}}
{"_local_timestamp": "2026-01-25T23:47:37.931844+00:00", "data": {"market": "0x5bc23ef1d55fb8d4a1b21b7c8780aa1b6b019262dda806da8a79dc8ada217f33", "price_changes": [{"asset_id": "56888387443153290473779399645893214898197325618962871997813882665583407269175", "price": "0.18", "size": "2632", "side": "BUY", "hash": "379f085ff5ef9c1977dc2d0fff8e9747f4ebbfc6", "best_bid": "0.65", "best_ask": "0.67"}, {"asset_id": "44152243636867873932593431458048174258413868830357636196802887961839805767798", "price": "0.82", "size": "2632", "side": "SELL", "hash": "27eb42a3f45fa2c1f6673beade281fb822a8a601", "best_bid": "0.33", "best_ask": "0.35"}], "timestamp": "1769384857604", "event_type": "price_change"}}
{"_local_timestamp": "2026-01-25T23:47:37.964449+00:00", "data": {"market": "0x5bc23ef1d55fb8d4a1b21b7c8780aa1b6b019262dda806da8a79dc8ada217f33", "price_changes": [{"asset_id": "56888387443153290473779399645893214898197325618962871997813882665583407269175", "price": "0.23", "size": "204.34", "side": "BUY", "hash": "237b507f7cc5f186e7d67baf1f7812fd8b29a1c7", "best_bid": "0.65", "best_ask": "0.67"}, {"asset_id": "44152243636867873932593431458048174258413868830357636196802887961839805767798", "price": "0.77", "size": "204.34", "side": "SELL", "hash": "3fab489dc1f2a52b6315fa7eda6457447b89716d", "best_bid": "0.33", "best_ask": "0.35"}], "timestamp": "1769384857674", "event_type": "price_change"}}
{"_local_timestamp": "2026-01-25T23:47:38.420819+00:00", "data": {"market": "0x5bc23ef1d55fb8d4a1b21b7c8780aa1b6b019262dda806da8a79dc8ada217f33", "price_changes": [{"asset_id": "56888387443153290473779399645893214898197325618962871997813882665583407269175", "price": "0.19", "size": "100", "side": "BUY", "hash": "9463759a252a1c11c295e3a8729ccbef932b9cbd", "best_bid": "0.65", "best_ask": "0.67"}, {"asset_id": "44152243636867873932593431458048174258413868830357636196802887961839805767798", "price": "0.81", "size": "100", "side": "SELL", "hash": "2a834f502bf3e41823fe6fec757289e3a3fb99f1", "best_bid": "0.33", "best_ask": "0.35"}], "timestamp": "1769384858085", "event_type": "price_change"}}
{"_local_timestamp": "2026-01-25T23:47:38.490060+00:00", "data": {"market": "0x5bc23ef1d55fb8d4a1b21b7c8780aa1b6b019262dda806da8a79dc8ada217f33", "price_changes": [{"asset_id": "56888387443153290473779399645893214898197325618962871997813882665583407269175", "price": "0.21", "size": "100", "side": "BUY", "hash": "a7ffd1105a19d6314d5ccb3fdc5d33c70579d578", "best_bid": "0.65", "best_ask": "0.67"}, {"asset_id": "44152243636867873932593431458048174258413868830357636196802887961839805767798", "price": "0.79", "size": "100", "side": "SELL", "hash": "b04fc57fe27380bdba93d2672e9dc0e63ede2939", "best_bid": "0.33", "best_ask": "0.35"}], "timestamp": "1769384858344", "event_type": "price_change"}}
{"_local_timestamp": "2026-01-25T23:47:45.644548+00:00", "data": {"market": "0x5bc23ef1d55fb8d4a1b21b7c8780aa1b6b019262dda806da8a79dc8ada217f33", "price_changes": [{"asset_id": "56888387443153290473779399645893214898197325618962871997813882665583407269175", "price": "0.16", "size": "1120", "side": "BUY", "hash": "9d1ae25a1c87a611769b7c2ef484dc6f501c0b70", "best_bid": "0.65", "best_ask": "0.67"}, {"asset_id": "44152243636867873932593431458048174258413868830357636196802887961839805767798", "price": "0.84", "size": "1120", "side": "SELL", "hash": "64f340281af3482132652be3c545d53c1a4dc6d7", "best_bid": "0.33", "best_ask": "0.35"}], "timestamp": "1769384865560", "event_type": "price_change"}}
{"_local_timestamp": "2026-01-25T23:47:45.950009+00:00", "data": {"market": "0x5bc23ef1d55fb8d4a1b21b7c8780aa1b6b019262dda806da8a79dc8ada217f33", "price_changes": [{"asset_id": "56888387443153290473779399645893214898197325618962871997813882665583407269175", "price": "0.18", "size": "2682", "side": "BUY", "hash": "673f885c1a1702d127571792bbc2786ed61b7931", "best_bid": "0.65", "best_ask": "0.67"}, {"asset_id": "44152243636867873932593431458048174258413868830357636196802887961839805767798", "price": "0.82", "size": "2682", "side": "SELL", "hash": "907db4460c82690d5d585d36407361fb21f5a7ad", "best_bid": "0.33", "best_ask": "0.35"}], "timestamp": "1769384865858", "event_type": "price_change"}}
{"_local_timestamp": "2026-01-25T23:47:55.573366+00:00", "data": {"market": "0x5bc23ef1d55fb8d4a1b21b7c8780aa1b6b019262dda806da8a79dc8ada217f33", "price_changes": [{"asset_id": "56888387443153290473779399645893214898197325618962871997813882665583407269175", "price": "0.18", "size": "350", "side": "BUY", "hash": "cabb77b839798138c03ad61ae90e458c0145e747", "best_bid": "0.65", "best_ask": "0.67"}, {"asset_id": "44152243636867873932593431458048174258413868830357636196802887961839805767798", "price": "0.82", "size": "350", "side": "SELL", "hash": "5018c733563a9d6a992044c6d32693084f79c8d6", "best_bid": "0.33", "best_ask": "0.35"}], "timestamp": "1769384875409", "event_type": "price_change"}}
{"_local_timestamp": "2026-01-25T23:48:02.174600+00:00", "data": {"market": "0x5bc23ef1d55fb8d4a1b21b7c8780aa1b6b019262dda806da8a79dc8ada217f33", "price_changes": [{"asset_id": "44152243636867873932593431458048174258413868830357636196802887961839805767798", "price": "0.19", "size": "3134", "side": "BUY", "hash": "b4aaa257650212e2ac0c263a547a471448a9dbfc", "best_bid": "0.33", "best_ask": "0.35"}, {"asset_id": "56888387443153290473779399645893214898197325618962871997813882665583407269175", "price": "0.81", "size": "3134", "side": "SELL", "hash": "f86f1e4d8def0882e5128b08cce63b85d600dcbb", "best_bid": "0.65", "best_ask": "0.67"}], "timestamp": "1769384882000", "event_type": "price_change"}}
{"_local_timestamp": "2026-01-25T23:48:02.183121+00:00", "data": {"market": "0x5bc23ef1d55fb8d4a1b21b7c8780aa1b6b019262dda806da8a79dc8ada217f33", "price_changes": [{"asset_id": "44152243636867873932593431458048174258413868830357636196802887961839805767798", "price": "0.23", "size": "1321.6", "side": "BUY", "hash": "0e6b9a2d588fdeb7c16dd7ce51f5ba1e9b54ec2e", "best_bid": "0.33", "best_ask": "0.35"}, {"asset_id": "56888387443153290473779399645893214898197325618962871997813882665583407269175", "price": "0.77", "size": "1321.6", "side": "SELL", "hash": "0e7c939b123de54af1aaf0a2dce3469b629efd59", "best_bid": "0.65", "best_ask": "0.67"}], "timestamp": "1769384882001", "event_type": "price_change"}}
{"_local_timestamp": "2026-01-25T23:48:02.616761+00:00", "data": {"market": "0x5bc23ef1d55fb8d4a1b21b7c8780aa1b6b019262dda806da8a79dc8ada217f33", "price_changes": [{"asset_id": "44152243636867873932593431458048174258413868830357636196802887961839805767798", "price": "0.02", "size": "2406.22", "side": "BUY", "hash": "e35e04479f9a47435dd727cfbc3fc3740f1656a7", "best_bid": "0.33", "best_ask": "0.35"}, {"asset_id": "56888387443153290473779399645893214898197325618962871997813882665583407269175", "price": "0.98", "size": "2406.22", "side": "SELL", "hash": "c4de9797045012fb9a62c8529d7ea8d592ba90cc", "best_bid": "0.65", "best_ask": "0.67"}], "timestamp": "1769384882430", "event_type": "price_change"}}
{"_local_timestamp": "2026-01-25T23:48:03.142324+00:00", "data": {"market": "0x5bc23ef1d55fb8d4a1b21b7c8780aa1b6b019262dda806da8a79dc8ada217f33", "price_changes": [{"asset_id": "44152243636867873932593431458048174258413868830357636196802887961839805767798", "price": "0.05", "size": "1130.58", "side": "BUY", "hash": "f16e2afe6d03b3273e1a1ba9577a4bde1b579b8b", "best_bid": "0.33", "best_ask": "0.35"}, {"asset_id": "56888387443153290473779399645893214898197325618962871997813882665583407269175", "price": "0.95", "size": "1130.58", "side": "SELL", "hash": "a6953d221d95d6b70c96560db16bec9aaa60de5c", "best_bid": "0.65", "best_ask": "0.67"}], "timestamp": "1769384882869", "event_type": "price_change"}}
{"_local_timestamp": "2026-01-25T23:48:26.229097+00:00", "data": {"market": "0x5bc23ef1d55fb8d4a1b21b7c8780aa1b6b019262dda806da8a79dc8ada217f33", "price_changes": [{"asset_id": "56888387443153290473779399645893214898197325618962871997813882665583407269175", "price": "0.18", "size": "300", "side": "BUY", "hash": "aecd5ea9bcea93c0cf55d75324d4469ecf037278", "best_bid": "0.65", "best_ask": "0.67"}, {"asset_id": "44152243636867873932593431458048174258413868830357636196802887961839805767798", "price": "0.82", "size": "300", "side": "SELL", "hash": "4e025614a0033f68a61664ca4f24df1fcecb70ad", "best_bid": "0.33", "best_ask": "0.35"}], "timestamp": "1769384905999", "event_type": "price_change"}}
{"_local_timestamp": "2026-01-25T23:48:26.537370+00:00", "data": {"market": "0x5bc23ef1d55fb8d4a1b21b7c8780aa1b6b019262dda806da8a79dc8ada217f33", "price_changes": [{"asset_id": "56888387443153290473779399645893214898197325618962871997813882665583407269175", "price": "0.16", "size": "1170", "side": "BUY", "hash": "30e8a7ab41bf79a5ddcd4e261f1c31ffca87b30e", "best_bid": "0.65", "best_ask": "0.67"}, {"asset_id": "44152243636867873932593431458048174258413868830357636196802887961839805767798", "price": "0.84", "size": "1170", "side": "SELL", "hash": "8476e506c4c58c21ecfe62f7f05155001f89765f", "best_bid": "0.33", "best_ask": "0.35"}], "timestamp": "1769384906289", "event_type": "price_change"}}
{"_local_timestamp": "2026-01-25T23:48:35.963928+00:00", "data": {"market": "0x5bc23ef1d55fb8d4a1b21b7c8780aa1b6b019262dda806da8a79dc8ada217f33", "price_changes": [{"asset_id": "56888387443153290473779399645893214898197325618962871997813882665583407269175", "price": "0.19", "size": "2310", "side": "BUY", "hash": "c51e47678be56eef26bf439cf1216bd2190f878b", "best_bid": "0.65", "best_ask": "0.67"}, {"asset_id": "44152243636867873932593431458048174258413868830357636196802887961839805767798", "price": "0.81", "size": "2310", "side": "SELL", "hash": "b3045583627cf4cf5db15a0a1a69a01c3cffa08b", "best_bid": "0.33", "best_ask": "0.35"}], "timestamp": "1769384915743", "event_type": "price_change"}}
{"_local_timestamp": "2026-01-25T23:48:48.654031+00:00", "data": {"market": "0x5bc23ef1d55fb8d4a1b21b7c8780aa1b6b019262dda806da8a79dc8ada217f33", "price_changes": [{"asset_id": "56888387443153290473779399645893214898197325618962871997813882665583407269175", "price": "0.18", "size": "150", "side": "BUY", "hash": "dc915683b08bcf4c96a7de6cf32086324623f451", "best_bid": "0.65", "best_ask": "0.67"}, {"asset_id": "44152243636867873932593431458048174258413868830357636196802887961839805767798", "price": "0.82", "size": "150", "side": "SELL", "hash": "16ab38019b50fd25e41b3a53804462aeecaa0e26", "best_bid": "0.33", "best_ask": "0.35"}], "timestamp": "1769384928576", "event_type": "price_change"}}
{"_local_timestamp": "2026-01-25T23:48:48.945933+00:00", "data": {"market": "0x5bc23ef1d55fb8d4a1b21b7c8780aa1b6b019262dda806da8a79dc8ada217f33", "price_changes": [{"asset_id": "56888387443153290473779399645893214898197325618962871997813882665583407269175", "price": "0.16", "size": "1320", "side": "BUY", "hash": "20257dcd6e2db0e6b5890c7387b0bebb27401c07", "best_bid": "0.65", "best_ask": "0.67"}, {"asset_id": "44152243636867873932593431458048174258413868830357636196802887961839805767798", "price": "0.84", "size": "1320", "side": "SELL", "hash": "342678c7c2c7487cc6e89d496bf8b5360eefe353", "best_bid": "0.33", "best_ask": "0.35"}], "timestamp": "1769384928849", "event_type": "price_change"}}
{"_local_timestamp": "2026-01-25T23:48:58.078477+00:00", "data": {"market": "0x5bc23ef1d55fb8d4a1b21b7c8780aa1b6b019262dda806da8a79dc8ada217f33", "price_changes": [{"asset_id": "44152243636867873932593431458048174258413868830357636196802887961839805767798", "price": "0.23", "size": "1247.6", "side": "BUY", "hash": "c34c166d39ca5489276f335e265d148448fbdc3e", "best_bid": "0.33", "best_ask": "0.35"}, {"asset_id": "56888387443153290473779399645893214898197325618962871997813882665583407269175", "price": "0.77", "size": "1247.6", "side": "SELL", "hash": "7baf158b28014338fd95dac14f2405242abece88", "best_bid": "0.65", "best_ask": "0.67"}], "timestamp": "1769384938000", "event_type": "price_change"}}
{"_local_timestamp": "2026-01-25T23:48:58.085229+00:00", "data": {"market": "0x5bc23ef1d55fb8d4a1b21b7c8780aa1b6b019262dda806da8a79dc8ada217f33", "price_changes": [{"asset_id": "44152243636867873932593431458048174258413868830357636196802887961839805767798", "price": "0.29", "size": "601", "side": "BUY", "hash": "04ec5b12d8cbec6bd84d7c894a32548dcd75361b", "best_bid": "0.33", "best_ask": "0.35"}, {"asset_id": "56888387443153290473779399645893214898197325618962871997813882665583407269175", "price": "0.71", "size": "601", "side": "SELL", "hash": "00113a10c46775af84be31807381074edd654916", "best_bid": "0.65", "best_ask": "0.67"}], "timestamp": "1769384938003", "event_type": "price_change"}}
{"_local_timestamp": "2026-01-25T23:48:58.085859+00:00", "data": {"market": "0x5bc23ef1d55fb8d4a1b21b7c8780aa1b6b019262dda806da8a79dc8ada217f33", "price_changes": [{"asset_id": "44152243636867873932593431458048174258413868830357636196802887961839805767798", "price": "0.19", "size": "2955", "side": "BUY", "hash": "04ec5b12d8cbec6bd84d7c894a32548dcd75361b", "best_bid": "0.33", "best_ask": "0.35"}, {"asset_id": "56888387443153290473779399645893214898197325618962871997813882665583407269175", "price": "0.81", "size": "2955", "side": "SELL", "hash": "00113a10c46775af84be31807381074edd654916", "best_bid": "0.65", "best_ask": "0.67"}], "timestamp": "1769384938003", "event_type": "price_change"}}
{"_local_timestamp": "2026-01-25T23:49:00.741444+00:00", "data": {"market": "0x5bc23ef1d55fb8d4a1b21b7c8780aa1b6b019262dda806da8a79dc8ada217f33", "price_changes": [{"asset_id": "44152243636867873932593431458048174258413868830357636196802887961839805767798", "price": "0.23", "size": "1356.6", "side": "BUY", "hash": "a479bc9ae665842605ee144166ccee622a84e501", "best_bid": "0.33", "best_ask": "0.35"}, {"asset_id": "56888387443153290473779399645893214898197325618962871997813882665583407269175", "price": "0.77", "size": "1356.6", "side": "SELL", "hash": "bd2740d1db86ea5299e566aee0225948f4eddac3", "best_bid": "0.65", "best_ask": "0.67"}], "timestamp": "1769384940675", "event_type": "price_change"}}
{"_local_timestamp": "2026-01-25T23:49:00.742097+00:00", "data": {"market": "0x5bc23ef1d55fb8d4a1b21b7c8780aa1b6b019262dda806da8a79dc8ada217f33", "price_changes": [{"asset_id": "44152243636867873932593431458048174258413868830357636196802887961839805767798", "price": "0.29", "size": "615", "side": "BUY", "hash": "c6cd4b9b376fc7bcb7c171e8c4db19d776ea77eb", "best_bid": "0.33", "best_ask": "0.35"}, {"asset_id": "56888387443153290473779399645893214898197325618962871997813882665583407269175", "price": "0.71", "size": "615", "side": "SELL", "hash": "95397c5f4d2e0d62549a9ffed8a2c7bc6c7f16c4", "best_bid": "0.65", "best_ask": "0.67"}], "timestamp": "1769384940676", "event_type": "price_change"}}
{"_local_timestamp": "2026-01-25T23:49:00.746393+00:00", "data": {"market": "0x5bc23ef1d55fb8d4a1b21b7c8780aa1b6b019262dda806da8a79dc8ada217f33", "price_changes": [{"asset_id": "44152243636867873932593431458048174258413868830357636196802887961839805767798", "price": "0.19", "size": "3223", "side": "BUY", "hash": "4ac7369a86a2d5807d13e65a175c7e5a0a1b3701", "best_bid": "0.33", "best_ask": "0.35"}, {"asset_id": "56888387443153290473779399645893214898197325618962871997813882665583407269175", "price": "0.81", "size": "3223", "side": "SELL", "hash": "6eaa80f4ccc446fc1405222586f74df42f8d7844", "best_bid": "0.65", "best_ask": "0.67"}], "timestamp": "1769384940677", "event_type": "price_change"}}
{"_local_timestamp": "2026-01-25T23:49:09.169608+00:00", "data": {"market": "0x5bc23ef1d55fb8d4a1b21b7c8780aa1b6b019262dda806da8a79dc8ada217f33", "price_changes": [{"asset_id": "44152243636867873932593431458048174258413868830357636196802887961839805767798", "price": "0.02", "size": "1606.22", "side": "BUY", "hash": "6afa169ccc26fe5dda5daa94eaa11ea3b858ffb0", "best_bid": "0.33", "best_ask": "0.35"}, {"asset_id": "56888387443153290473779399645893214898197325618962871997813882665583407269175", "price": "0.98", "size": "1606.22", "side": "SELL", "hash": "4b34641c85580e16ffd2249f9fcc1bddfccb0430", "best_bid": "0.65", "best_ask": "0.67"}], "timestamp": "1769384949091", "event_type": "price_change"}}
{"_local_timestamp": "2026-01-25T23:49:09.170311+00:00", "data": {"market": "0x5bc23ef1d55fb8d4a1b21b7c8780aa1b6b019262dda806da8a79dc8ada217f33", "price_changes": [{"asset_id": "56888387443153290473779399645893214898197325618962871997813882665583407269175", "price": "0.16", "size": "1270", "side": "BUY", "hash": "dcf8c08574cac84756f3e33cf2170fc5f7bd9323", "best_bid": "0.65", "best_ask": "0.67"}, {"asset_id": "44152243636867873932593431458048174258413868830357636196802887961839805767798", "price": "0.84", "size": "1270", "side": "SELL", "hash": "058558ff415d5d1a7064311c43ad32a932543c1e", "best_bid": "0.33", "best_ask": "0.35"}], "timestamp": "1769384949092", "event_type": "price_change"}}
{"_local_timestamp": "2026-01-25T23:49:09.498644+00:00", "data": {"market": "0x5bc23ef1d55fb8d4a1b21b7c8780aa1b6b019262dda806da8a79dc8ada217f33", "price_changes": [{"asset_id": "56888387443153290473779399645893214898197325618962871997813882665583407269175", "price": "0.19", "size": "2360", "side": "BUY", "hash": "4950ecab023bf61c078d81ac6e3aa8b06ccf6b6d", "best_bid": "0.65", "best_ask": "0.67"}, {"asset_id": "44152243636867873932593431458048174258413868830357636196802887961839805767798", "price": "0.81", "size": "2360", "side": "SELL", "hash": "20787cf24579803879039e7970f3d80c420884a4", "best_bid": "0.33", "best_ask": "0.35"}], "timestamp": "1769384949410", "event_type": "price_change"}}
{"_local_timestamp": "2026-01-25T23:49:09.509429+00:00", "data": {"market": "0x5bc23ef1d55fb8d4a1b21b7c8780aa1b6b019262dda806da8a79dc8ada217f33", "price_changes": [{"asset_id": "44152243636867873932593431458048174258413868830357636196802887961839805767798", "price": "0.05", "size": "1630.58", "side": "BUY", "hash": "298e480c16fb76fc3bef71fa1bf06fddaf4a6ca3", "best_bid": "0.33", "best_ask": "0.35"}, {"asset_id": "56888387443153290473779399645893214898197325618962871997813882665583407269175", "price": "0.95", "size": "1630.58", "side": "SELL", "hash": "210e41704117bf117f90867332e7a3655bf21eab", "best_bid": "0.65", "best_ask": "0.67"}], "timestamp": "1769384949420", "event_type": "price_change"}}
{"_local_timestamp": "2026-01-25T23:49:24.519005+00:00", "data": {"market": "0x5bc23ef1d55fb8d4a1b21b7c8780aa1b6b019262dda806da8a79dc8ada217f33", "price_changes": [{"asset_id": "56888387443153290473779399645893214898197325618962871997813882665583407269175", "price": "0.16", "size": "1120", "side": "BUY", "hash": "ad85426bf917d6048ce0bfabfc58674e0e0a5391", "best_bid": "0.65", "best_ask": "0.67"}, {"asset_id": "44152243636867873932593431458048174258413868830357636196802887961839805767798", "price": "0.84", "size": "1120", "side": "SELL", "hash": "20f72152937f43eb21ba1a5ff473afe3043f0479", "best_bid": "0.33", "best_ask": "0.35"}], "timestamp": "1769384964423", "event_type": "price_change"}}
{"_local_timestamp": "2026-01-25T23:49:24.796471+00:00", "data": {"market": "0x5bc23ef1d55fb8d4a1b21b7c8780aa1b6b019262dda806da8a79dc8ada217f33", "price_changes": [{"asset_id": "56888387443153290473779399645893214898197325618962871997813882665583407269175", "price": "0.19", "size": "2510", "side": "BUY", "hash": "7fc390b5349e298f0d66c0e244303edcf096b1fc", "best_bid": "0.65", "best_ask": "0.67"}, {"asset_id": "44152243636867873932593431458048174258413868830357636196802887961839805767798", "price": "0.81", "size": "2510", "side": "SELL", "hash": "4891177c18e226f279c5458e9c26f1d559c95f0a", "best_bid": "0.33", "best_ask": "0.35"}], "timestamp": "1769384964697", "event_type": "price_change"}}
{"_local_timestamp": "2026-01-25T23:49:25.463590+00:00", "data": {"market": "0x5bc23ef1d55fb8d4a1b21b7c8780aa1b6b019262dda806da8a79dc8ada217f33", "price_changes": [{"asset_id": "56888387443153290473779399645893214898197325618962871997813882665583407269175", "price": "0.19", "size": "2410", "side": "BUY", "hash": "9f7ece94da4178117840f6ec1434f636ae08b5be", "best_bid": "0.65", "best_ask": "0.67"}, {"asset_id": "44152243636867873932593431458048174258413868830357636196802887961839805767798", "price": "0.81", "size": "2410", "side": "SELL", "hash": "84048252c2e6552ecfb85cde81b4d0e20ec3e90d", "best_bid": "0.33", "best_ask": "0.35"}], "timestamp": "1769384965281", "event_type": "price_change"}}
{"_local_timestamp": "2026-01-25T23:49:25.464272+00:00", "data": {"market": "0x5bc23ef1d55fb8d4a1b21b7c8780aa1b6b019262dda806da8a79dc8ada217f33", "price_changes": [{"asset_id": "56888387443153290473779399645893214898197325618962871997813882665583407269175", "price": "0.21", "size": "50", "side": "BUY", "hash": "9f7ece94da4178117840f6ec1434f636ae08b5be", "best_bid": "0.65", "best_ask": "0.67"}, {"asset_id": "44152243636867873932593431458048174258413868830357636196802887961839805767798", "price": "0.79", "size": "50", "side": "SELL", "hash": "84048252c2e6552ecfb85cde81b4d0e20ec3e90d", "best_bid": "0.33", "best_ask": "0.35"}], "timestamp": "1769384965281", "event_type": "price_change"}}
{"_local_timestamp": "2026-01-25T23:49:25.971804+00:00", "data": {"market": "0x5bc23ef1d55fb8d4a1b21b7c8780aa1b6b019262dda806da8a79dc8ada217f33", "price_changes": [{"asset_id": "56888387443153290473779399645893214898197325618962871997813882665583407269175", "price": "0.18", "size": "250", "side": "BUY", "hash": "01897f1ed7491bc29d6f4a4b50d5ad7229c1ff64", "best_bid": "0.65", "best_ask": "0.67"}, {"asset_id": "44152243636867873932593431458048174258413868830357636196802887961839805767798", "price": "0.82", "size": "250", "side": "SELL", "hash": "ebbb9356cf3512a72aa3bc5cb520d1b1e577f3b4", "best_bid": "0.33", "best_ask": "0.35"}], "timestamp": "1769384965790", "event_type": "price_change"}}
{"_local_timestamp": "2026-01-25T23:49:25.981086+00:00", "data": {"market": "0x5bc23ef1d55fb8d4a1b21b7c8780aa1b6b019262dda806da8a79dc8ada217f33", "price_changes": [{"asset_id": "56888387443153290473779399645893214898197325618962871997813882665583407269175", "price": "0.27", "size": "324.07", "side": "BUY", "hash": "b62cc01e05369a73f996d42ebb869b0229f347d7", "best_bid": "0.65", "best_ask": "0.67"}, {"asset_id": "44152243636867873932593431458048174258413868830357636196802887961839805767798", "price": "0.73", "size": "324.07", "side": "SELL", "hash": "63c8307db5c109e4c0f920c330856fa72161f648", "best_bid": "0.33", "best_ask": "0.35"}], "timestamp": "1769384965822", "event_type": "price_change"}}
{"_local_timestamp": "2026-01-25T23:49:41.856314+00:00", "data": {"market": "0x5bc23ef1d55fb8d4a1b21b7c8780aa1b6b019262dda806da8a79dc8ada217f33", "price_changes": [{"asset_id": "56888387443153290473779399645893214898197325618962871997813882665583407269175", "price": "0.21", "size": "0", "side": "BUY", "hash": "8bc9b09b8798e572a00ab1dbe6b3ec75d24767f3", "best_bid": "0.65", "best_ask": "0.67"}, {"asset_id": "44152243636867873932593431458048174258413868830357636196802887961839805767798", "price": "0.79", "size": "0", "side": "SELL", "hash": "e37be0931e6ebbc0ece90a4fa4430e573172d302", "best_bid": "0.33", "best_ask": "0.35"}], "timestamp": "1769384981720", "event_type": "price_change"}}
{"_local_timestamp": "2026-01-25T23:49:41.936309+00:00", "data": {"market": "0x5bc23ef1d55fb8d4a1b21b7c8780aa1b6b019262dda806da8a79dc8ada217f33", "price_changes": [{"asset_id": "44152243636867873932593431458048174258413868830357636196802887961839805767798", "price": "0.05", "size": "1230.58", "side": "BUY", "hash": "5bd4b8133e560e81e2edc4f8f254b8922febc698", "best_bid": "0.33", "best_ask": "0.35"}, {"asset_id": "56888387443153290473779399645893214898197325618962871997813882665583407269175", "price": "0.95", "size": "1230.58", "side": "SELL", "hash": "b41e3d6d9c65c57143ac6ee5a70eb09d468f94f5", "best_bid": "0.65", "best_ask": "0.67"}], "timestamp": "1769384981755", "event_type": "price_change"}}
{"_local_timestamp": "2026-01-25T23:49:42.214123+00:00", "data": {"market": "0x5bc23ef1d55fb8d4a1b21b7c8780aa1b6b019262dda806da8a79dc8ada217f33", "price_changes": [{"asset_id": "44152243636867873932593431458048174258413868830357636196802887961839805767798", "price": "0.02", "size": "2006.22", "side": "BUY", "hash": "1eab2299e2736f6053c8dfd6d64f5d849fbe6d31", "best_bid": "0.33", "best_ask": "0.35"}, {"asset_id": "56888387443153290473779399645893214898197325618962871997813882665583407269175", "price": "0.98", "size": "2006.22", "side": "SELL", "hash": "d3e50a6d58ee9b8a06fe404efce6a5ce836b1f2c", "best_bid": "0.65", "best_ask": "0.67"}], "timestamp": "1769384982095", "event_type": "price_change"}}
{"_local_timestamp": "2026-01-25T23:49:42.416636+00:00", "data": {"market": "0x5bc23ef1d55fb8d4a1b21b7c8780aa1b6b019262dda806da8a79dc8ada217f33", "price_changes": [{"asset_id": "56888387443153290473779399645893214898197325618962871997813882665583407269175", "price": "0.23", "size": "254.34", "side": "BUY", "hash": "5e1d7326232ad8da1ef835745ce0e97f6a1fe395", "best_bid": "0.65", "best_ask": "0.67"}, {"asset_id": "44152243636867873932593431458048174258413868830357636196802887961839805767798", "price": "0.77", "size": "254.34", "side": "SELL", "hash": "0607621b9d626c7f351924b4e95018a85e33f07e", "best_bid": "0.33", "best_ask": "0.35"}], "timestamp": "1769384982236", "event_type": "price_change"}}
{"_local_timestamp": "2026-01-25T23:49:57.788805+00:00", "data": {"market": "0x5bc23ef1d55fb8d4a1b21b7c8780aa1b6b019262dda806da8a79dc8ada217f33", "price_changes": [{"asset_id": "44152243636867873932593431458048174258413868830357636196802887961839805767798", "price": "0.3", "size": "10", "side": "BUY", "hash": "d97decc111bb5c8b9382e20864a13e44dcfd6e68", "best_bid": "0.33", "best_ask": "0.35"}, {"asset_id": "56888387443153290473779399645893214898197325618962871997813882665583407269175", "price": "0.7", "size": "10", "side": "SELL", "hash": "5bc5db8bd0d6960ca527a14a30f4859bbe3e96fc", "best_bid": "0.65", "best_ask": "0.67"}], "timestamp": "1769384997713", "event_type": "price_change"}}
{"_local_timestamp": "2026-01-25T23:49:57.813246+00:00", "data": {"market": "0x5bc23ef1d55fb8d4a1b21b7c8780aa1b6b019262dda806da8a79dc8ada217f33", "price_changes": [{"asset_id": "44152243636867873932593431458048174258413868830357636196802887961839805767798", "price": "0.29", "size": "268", "side": "BUY", "hash": "2c6752e66997e0713b736374c6ca6187a4bbd000", "best_bid": "0.33", "best_ask": "0.35"}, {"asset_id": "56888387443153290473779399645893214898197325618962871997813882665583407269175", "price": "0.71", "size": "268", "side": "SELL", "hash": "2127af3b89c71d6b4a0060690f6a11e172498c1b", "best_bid": "0.65", "best_ask": "0.67"}], "timestamp": "1769384997742", "event_type": "price_change"}}
{"_local_timestamp": "2026-01-25T23:49:57.851140+00:00", "data": {"market": "0x5bc23ef1d55fb8d4a1b21b7c8780aa1b6b019262dda806da8a79dc8ada217f33", "price_changes": [{"asset_id": "44152243636867873932593431458048174258413868830357636196802887961839805767798", "price": "0.3", "size": "301", "side": "BUY", "hash": "12cab42066364cc00ddb0e7e88b533f68f73ecfa", "best_bid": "0.33", "best_ask": "0.35"}, {"asset_id": "56888387443153290473779399645893214898197325618962871997813882665583407269175", "price": "0.7", "size": "301", "side": "SELL", "hash": "439f14f28cc76c266c82a1d1227dfdbf21174cf2", "best_bid": "0.65", "best_ask": "0.67"}], "timestamp": "1769384997776", "event_type": "price_change"}}
{"_local_timestamp": "2026-01-25T23:49:57.881062+00:00", "data": {"market": "0x5bc23ef1d55fb8d4a1b21b7c8780aa1b6b019262dda806da8a79dc8ada217f33", "price_changes": [{"asset_id": "56888387443153290473779399645893214898197325618962871997813882665583407269175", "price": "0.62", "size": "110", "side": "BUY", "hash": "4e9e29487f682836c7ce6641a5d39c88733f9918", "best_bid": "0.65", "best_ask": "0.67"}, {"asset_id": "44152243636867873932593431458048174258413868830357636196802887961839805767798", "price": "0.38", "size": "110", "side": "SELL", "hash": "e4bb3b3e3a94f98d7718d071b6dbb0759832dfee", "best_bid": "0.33", "best_ask": "0.35"}], "timestamp": "1769384997802", "event_type": "price_change"}}
{"_local_timestamp": "2026-01-25T23:50:02.568522+00:00", "data": {"market": "0x5bc23ef1d55fb8d4a1b21b7c8780aa1b6b019262dda806da8a79dc8ada217f33", "price_changes": [{"asset_id": "56888387443153290473779399645893214898197325618962871997813882665583407269175", "price": "0.16", "size": "120", "side": "BUY", "hash": "efbc3503379d4d32e7821bf189b76ec0ab77e24d", "best_bid": "0.65", "best_ask": "0.67"}, {"asset_id": "44152243636867873932593431458048174258413868830357636196802887961839805767798", "price": "0.84", "size": "120", "side": "SELL", "hash": "30b079a45e0657a9996d2ecd775d75e872f7b457", "best_bid": "0.33", "best_ask": "0.35"}], "timestamp": "1769385002284", "event_type": "price_change"}}
{"_local_timestamp": "2026-01-25T23:50:38.135129+00:00", "data": {"market": "0x5bc23ef1d55fb8d4a1b21b7c8780aa1b6b019262dda806da8a79dc8ada217f33", "price_changes": [{"asset_id": "44152243636867873932593431458048174258413868830357636196802887961839805767798", "price": "0.05", "size": "730.58", "side": "BUY", "hash": "eb742ded7a2b814d059bdb8f47fa6614cb6053de", "best_bid": "0.33", "best_ask": "0.35"}, {"asset_id": "56888387443153290473779399645893214898197325618962871997813882665583407269175", "price": "0.95", "size": "730.58", "side": "SELL", "hash": "8f9ad85b01f6e7e5140c79951c8ec075c18de2ac", "best_bid": "0.65", "best_ask": "0.67"}], "timestamp": "1769385038057", "event_type": "price_change"}}
{"_local_timestamp": "2026-01-25T23:50:38.557159+00:00", "data": {"market": "0x5bc23ef1d55fb8d4a1b21b7c8780aa1b6b019262dda806da8a79dc8ada217f33", "price_changes": [{"asset_id": "44152243636867873932593431458048174258413868830357636196802887961839805767798", "price": "0.02", "size": "2806.22", "side": "BUY", "hash": "9f37502947e147fdc81797770679bd1061e17a6b", "best_bid": "0.33", "best_ask": "0.35"}, {"asset_id": "56888387443153290473779399645893214898197325618962871997813882665583407269175", "price": "0.98", "size": "2806.22", "side": "SELL", "hash": "2cc2d5bd06e01e80f31f41480bfc51fca6267480", "best_bid": "0.65", "best_ask": "0.67"}], "timestamp": "1769385038474", "event_type": "price_change"}}
{"_local_timestamp": "2026-01-25T23:51:05.531236+00:00", "data": {"market": "0x5bc23ef1d55fb8d4a1b21b7c8780aa1b6b019262dda806da8a79dc8ada217f33", "price_changes": [{"asset_id": "56888387443153290473779399645893214898197325618962871997813882665583407269175", "price": "0.18", "size": "150", "side": "BUY", "hash": "8fe8458507ddf61514b849758b58314b58226a21", "best_bid": "0.65", "best_ask": "0.67"}, {"asset_id": "44152243636867873932593431458048174258413868830357636196802887961839805767798", "price": "0.82", "size": "150", "side": "SELL", "hash": "6af68fc64f34e9c54e03b0c203aee95cd0d890c8", "best_bid": "0.33", "best_ask": "0.35"}], "timestamp": "1769385065415", "event_type": "price_change"}}
{"_local_timestamp": "2026-01-25T23:51:05.953931+00:00", "data": {"market": "0x5bc23ef1d55fb8d4a1b21b7c8780aa1b6b019262dda806da8a79dc8ada217f33", "price_changes": [{"asset_id": "56888387443153290473779399645893214898197325618962871997813882665583407269175", "price": "0.19", "size": "2510", "side": "BUY", "hash": "17015f30df7a213227f429dca8a50d1983f4e2e6", "best_bid": "0.65", "best_ask": "0.67"}, {"asset_id": "44152243636867873932593431458048174258413868830357636196802887961839805767798", "price": "0.81", "size": "2510", "side": "SELL", "hash": "8662afebf4a9bbacda071c25d4c352165444996b", "best_bid": "0.33", "best_ask": "0.35"}], "timestamp": "1769385065804", "event_type": "price_change"}}
{"_local_timestamp": "2026-01-25T23:51:12.981961+00:00", "data": {"market": "0x5bc23ef1d55fb8d4a1b21b7c8780aa1b6b019262dda806da8a79dc8ada217f33", "price_changes": [{"asset_id": "44152243636867873932593431458048174258413868830357636196802887961839805767798", "price": "0.26", "size": "121", "side": "BUY", "hash": "aa8b5e7838faed7f621d957a1ca303ca18c12607", "best_bid": "0.33", "best_ask": "0.35"}, {"asset_id": "56888387443153290473779399645893214898197325618962871997813882665583407269175", "price": "0.74", "size": "121", "side": "SELL", "hash": "162278b13433b64e4978362e0e1097f3fd98ef18", "best_bid": "0.65", "best_ask": "0.67"}], "timestamp": "1769385072920", "event_type": "price_change"}}
{"_local_timestamp": "2026-01-25T23:51:12.987972+00:00", "data": {"market": "0x5bc23ef1d55fb8d4a1b21b7c8780aa1b6b019262dda806da8a79dc8ada217f33", "price_changes": [{"asset_id": "44152243636867873932593431458048174258413868830357636196802887961839805767798", "price": "0.19", "size": "2955", "side": "BUY", "hash": "aa8b5e7838faed7f621d957a1ca303ca18c12607", "best_bid": "0.33", "best_ask": "0.35"}, {"asset_id": "56888387443153290473779399645893214898197325618962871997813882665583407269175", "price": "0.81", "size": "2955", "side": "SELL", "hash": "162278b13433b64e4978362e0e1097f3fd98ef18", "best_bid": "0.65", "best_ask": "0.67"}], "timestamp": "1769385072920", "event_type": "price_change"}}
{"_local_timestamp": "2026-01-25T23:51:12.988639+00:00", "data": {"market": "0x5bc23ef1d55fb8d4a1b21b7c8780aa1b6b019262dda806da8a79dc8ada217f33", "price_changes": [{"asset_id": "44152243636867873932593431458048174258413868830357636196802887961839805767798", "price": "0.29", "size": "254", "side": "BUY", "hash": "aa8b5e7838faed7f621d957a1ca303ca18c12607", "best_bid": "0.33", "best_ask": "0.35"}, {"asset_id": "56888387443153290473779399645893214898197325618962871997813882665583407269175", "price": "0.71", "size": "254", "side": "SELL", "hash": "162278b13433b64e4978362e0e1097f3fd98ef18", "best_bid": "0.65", "best_ask": "0.67"}], "timestamp": "1769385072920", "event_type": "price_change"}}
{"_local_timestamp": "2026-01-25T23:51:12.989220+00:00", "data": {"market": "0x5bc23ef1d55fb8d4a1b21b7c8780aa1b6b019262dda806da8a79dc8ada217f33", "price_changes": [{"asset_id": "44152243636867873932593431458048174258413868830357636196802887961839805767798", "price": "0.23", "size": "1247.6", "side": "BUY", "hash": "aa8b5e7838faed7f621d957a1ca303ca18c12607", "best_bid": "0.33", "best_ask": "0.35"}, {"asset_id": "56888387443153290473779399645893214898197325618962871997813882665583407269175", "price": "0.77", "size": "1247.6", "side": "SELL", "hash": "162278b13433b64e4978362e0e1097f3fd98ef18", "best_bid": "0.65", "best_ask": "0.67"}], "timestamp": "1769385072920", "event_type": "price_change"}}
{"_local_timestamp": "2026-01-25T23:51:13.174817+00:00", "data": {"market": "0x5bc23ef1d55fb8d4a1b21b7c8780aa1b6b019262dda806da8a79dc8ada217f33", "price_changes": [{"asset_id": "44152243636867873932593431458048174258413868830357636196802887961839805767798", "price": "0.19", "size": "3144", "side": "BUY", "hash": "45bb1065317e6d43e86fe0aa5f92429783adcc7b", "best_bid": "0.33", "best_ask": "0.35"}, {"asset_id": "56888387443153290473779399645893214898197325618962871997813882665583407269175", "price": "0.81", "size": "3144", "side": "SELL", "hash": "561f933d03dcb2aee4bef9c826b4b34f52fd3a6e", "best_bid": "0.65", "best_ask": "0.67"}], "timestamp": "1769385073108", "event_type": "price_change"}}
{"_local_timestamp": "2026-01-25T23:51:13.175718+00:00", "data": {"market": "0x5bc23ef1d55fb8d4a1b21b7c8780aa1b6b019262dda806da8a79dc8ada217f33", "price_changes": [{"asset_id": "44152243636867873932593431458048174258413868830357636196802887961839805767798", "price": "0.23", "size": "1322.6", "side": "BUY", "hash": "39af51838e903b320719f58a9b36c244b2ace3c2", "best_bid": "0.33", "best_ask": "0.35"}, {"asset_id": "56888387443153290473779399645893214898197325618962871997813882665583407269175", "price": "0.77", "size": "1322.6", "side": "SELL", "hash": "fae126fb22a300fda7338f2d4d463ecdfbde7fcf", "best_bid": "0.65", "best_ask": "0.67"}], "timestamp": "1769385073109", "event_type": "price_change"}}
{"_local_timestamp": "2026-01-25T23:51:13.176439+00:00", "data": {"market": "0x5bc23ef1d55fb8d4a1b21b7c8780aa1b6b019262dda806da8a79dc8ada217f33", "price_changes": [{"asset_id": "44152243636867873932593431458048174258413868830357636196802887961839805767798", "price": "0.29", "size": "261", "side": "BUY", "hash": "2db80b05488a96af110b75e7a6fcb0463faef861", "best_bid": "0.33", "best_ask": "0.35"}, {"asset_id": "56888387443153290473779399645893214898197325618962871997813882665583407269175", "price": "0.71", "size": "261", "side": "SELL", "hash": "9530c4689abb01297f6a6e6bf583c971a3071952", "best_bid": "0.65", "best_ask": "0.67"}], "timestamp": "1769385073109", "event_type": "price_change"}}
{"_local_timestamp": "2026-01-25T23:51:13.177086+00:00", "data": {"market": "0x5bc23ef1d55fb8d4a1b21b7c8780aa1b6b019262dda806da8a79dc8ada217f33", "price_changes": [{"asset_id": "44152243636867873932593431458048174258413868830357636196802887961839805767798", "price": "0.26", "size": "576", "side": "BUY", "hash": "4dbaaacd8933976d5c4fe8a36dff0c4770192d51", "best_bid": "0.33", "best_ask": "0.35"}, {"asset_id": "56888387443153290473779399645893214898197325618962871997813882665583407269175", "price": "0.74", "size": "576", "side": "SELL", "hash": "b8649452bf4e3bbe98e60d6d5c94af0fc6142db8", "best_bid": "0.65", "best_ask": "0.67"}], "timestamp": "1769385073110", "event_type": "price_change"}}
{"_local_timestamp": "2026-01-25T23:51:14.587172+00:00", "data": {"market": "0x5bc23ef1d55fb8d4a1b21b7c8780aa1b6b019262dda806da8a79dc8ada217f33", "price_changes": [{"asset_id": "56888387443153290473779399645893214898197325618962871997813882665583407269175", "price": "0.63", "size": "358.79", "side": "BUY", "hash": "eff7d51cba87641ac8923fb86a4130fc6e5a975b", "best_bid": "0.65", "best_ask": "0.67"}, {"asset_id": "44152243636867873932593431458048174258413868830357636196802887961839805767798", "price": "0.37", "size": "358.79", "side": "SELL", "hash": "737ab04d4bb5258af18df7a6ed78f7c24f73a36f", "best_bid": "0.33", "best_ask": "0.35"}], "timestamp": "1769385074461", "event_type": "price_change"}}
{"_local_timestamp": "2026-01-25T23:51:14.587905+00:00", "data": {"market": "0x5bc23ef1d55fb8d4a1b21b7c8780aa1b6b019262dda806da8a79dc8ada217f33", "price_changes": [{"asset_id": "44152243636867873932593431458048174258413868830357636196802887961839805767798", "price": "0.31", "size": "200", "side": "BUY", "hash": "cca6e2656c72a3454806c5ecd79529751043b315", "best_bid": "0.33", "best_ask": "0.35"}, {"asset_id": "56888387443153290473779399645893214898197325618962871997813882665583407269175", "price": "0.69", "size": "200", "side": "SELL", "hash": "c0eec76cc76aea2d54c23c1811a511bcc0480724", "best_bid": "0.65", "best_ask": "0.67"}], "timestamp": "1769385074464", "event_type": "price_change"}}
