{"_local_timestamp": "2026-01-25T23:33:24.820857+00:00", "data": [{"market": "0x8af1519f0b6704eaa52ac0890275b011fbca31729bf93fd956899a2c7ea410c0", "asset_id": "61357261066156427607874461963210376168557582747775514258762252431133388687435", "timestamp": "1769383927611", "hash": "8bf63fb3b5729ab0484881a33606823a6b425e7c", "bids": [{"price": "0.01", "size": "5000"}, {"price": "0.02", "size": "2350"}, {"price": "0.04", "size": "500"}, {"price": "0.05", "size": "5000"}, {"price": "0.06", "size": "600"}, {"price": "0.09", "size": "477.77"}, {"price": "0.1", "size": "700"}, {"price": "0.12", "size": "266.66"}, {"price": "0.14", "size": "1142"}, {"price": "0.15", "size": "2511.66"}, {"price": "0.16", "size": "2624"}, {"price": "0.18", "size": "144.44"}, {"price": "0.19", "size": "10"}, {"price": "0.2", "size": "315"}, {"price": "0.21", "size": "364.28"}, {"price": "0.22", "size": "50"}, {"price": "0.23", "size": "3290"}, {"price": "0.24", "size": "592.33"}, {"price": "0.26", "size": "100"}, {"price": "0.27", "size": "226"}, {"price": "0.41", "size": "200"}, {"price": "0.43", "size": "356.43"}, {"price": "0.44", "size": "37"}, {"price": "0.45", "size": "12"}, {"price": "0.49", "size": "121.1"}, {"price": "0.5", "size": "173.44"}, {"price": "0.51", "size": "16"}, {"price": "0.53", "size": "500"}, {"price": "0.54", "size": "210"}, {"price": "0.55", "size": "494.97"}], "asks": [{"price": "0.99", "size": "5000"}, {"price": "0.98", "size": "1250"}, {"price": "0.96", "size": "1900"}, {"price": "0.95", "size": "331.26"}, {"price": "0.93", "size": "485.71"}, {"price": "0.91", "size": "355.55"}, {"price": "0.9", "size": "2100"}, {"price": "0.89", "size": "254.54"}, {"price": "0.88", "size": "3825"}, {"price": "0.86", "size": "435.71"}, {"price": "0.84", "size": "400"}, {"price": "0.83", "size": "58.92"}, {"price": "0.82", "size": "111.11"}, {"price": "0.7", "size": "446.84"}, {"price": "0.69", "size": "500"}, {"price": "0.68", "size": "40.62"}, {"price": "0.67", "size": "50"}, {"price": "0.66", "size": "82.35"}, {"price": "0.65", "size": "50"}, {"price": "0.61", "size": "1.28"}, {"price": "0.6", "size": "800"}, {"price": "0.59", "size": "247.08"}, {"price": "0.58", "size": "513.71"}], "event_type": "book", "last_trade_price": "0.410"}, {"market": "0x8af1519f0b6704eaa52ac0890275b011fbca31729bf93fd956899a2c7ea410c0", "asset_id": "6991261290382769111733079462092282665787540572081318556604857015498053666166", "timestamp": "1769383927611", "hash": "6eaaa31adda83c72fad9c11ad8bab6b7ed5355cb", "bids": [{"price": "0.01", "size": "5000"}, {"price": "0.02", "size": "1250"}, {"price": "0.04", "size": "1900"}, {"price": "0.05", "size": "331.26"}, {"price": "0.07", "size": "485.71"}, {"price": "0.09", "size": "355.55"}, {"price": "0.1", "size": "2100"}, {"price": "0.11", "size": "254.54"}, {"price": "0.12", "size": "3825"}, {"price": "0.14", "size": "435.71"}, {"price": "0.16", "size": "400"}, {"price": "0.17", "size": "58.92"}, {"price": "0.18", "size": "111.11"}, {"price": "0.3", "size": "446.84"}, {"price": "0.31", "size": "500"}, {"price": "0.32", "size": "40.62"}, {"price": "0.33", "size": "50"}, {"price": "0.34", "size": "82.35"}, {"price": "0.35", "size": "50"}, {"price": "0.39", "size": "1.28"}, {"price": "0.4", "size": "800"}, {"price": "0.41", "size": "247.08"}, {"price": "0.42", "size": "513.71"}], "asks": [{"price": "0.99", "size": "5000"}, {"price": "0.98", "size": "2350"}, {"price": "0.96", "size": "500"}, {"price": "0.95", "size": "5000"}, {"price": "0.94", "size": "600"}, {"price": "0.91", "size": "477.77"}, {"price": "0.9", "size": "700"}, {"price": "0.88", "size": "266.66"}, {"price": "0.86", "size": "1142"}, {"price": "0.85", "size": "2511.66"}, {"price": "0.84", "size": "2624"}, {"price": "0.82", "size": "144.44"}, {"price": "0.81", "size": "10"}, {"price": "0.8", "size": "315"}, {"price": "0.79", "size": "364.28"}, {"price": "0.78", "size": "50"}, {"price": "0.77", "size": "3290"}, {"price": "0.76", "size": "592.33"}, {"price": "0.74", "size": "100"}, {"price": "0.73", "size": "226"}, {"price": "0.59", "size": "200"}, {"price": "0.57", "size": "356.43"}, {"price": "0.56", "size": "37"}, {"price": "0.55", "size": "12"}, {"price": "0.51", "size": "121.1"}, {"price": "0.5", "size": "173.44"}, {"price": "0.49", "size": "16"}, {"price": "0.47", "size": "500"}, {"price": "0.46", "size": "210"}, {"price": "0.45", "size": "494.97"}], "event_type": "book", "last_trade_price": "0.410"}]}
{"_local_timestamp": "2026-01-25T23:33:40.303387+00:00", "data": {"market": "0x8af1519f0b6704eaa52ac0890275b011fbca31729bf93fd956899a2c7ea410c0", "price_changes": [{"asset_id": "61357261066156427607874461963210376168557582747775514258762252431133388687435", "price": "0.2", "size": "215", "side": "BUY", "hash": "61a2e471b6fcca331ae929ab5f475cb977ef8461", "best_bid": "0.55", "best_ask": "0.58"}, {"asset_id": "6991261290382769111733079462092282665787540572081318556604857015498053666166", "price": "0.8", "size": "215", "side": "SELL", "hash": "6a3ce3ed6ffd9633adc356c7e2eb7b857a407f54", "best_bid": "0.42", "best_ask": "0.45"}], "timestamp": "1769384020097", "event_type": "price_change"}}
{"_local_timestamp": "2026-01-25T23:33:40.320078+00:00", "data": {"market": "0x8af1519f0b6704eaa52ac0890275b011fbca31729bf93fd956899a2c7ea410c0", "price_changes": [{"asset_id": "61357261066156427607874461963210376168557582747775514258762252431133388687435", "price": "0.22", "size": "0", "side": "BUY", "hash": "61a2e471b6fcca331ae929ab5f475cb977ef8461", "best_bid": "0.55", "best_ask": "0.58"}, {"asset_id": "6991261290382769111733079462092282665787540572081318556604857015498053666166", "price": "0.78", "size": "0", "side": "SELL", "hash": "6a3ce3ed6ffd9633adc356c7e2eb7b857a407f54", "best_bid": "0.42", "best_ask": "0.45"}], "timestamp": "1769384020097", "event_type": "price_change"}}
{"_local_timestamp": "2026-01-25T23:33:40.746667+00:00", "data": {"market": "0x8af1519f0b6704eaa52ac0890275b011fbca31729bf93fd956899a2c7ea410c0", "price_changes": [{"asset_id": "61357261066156427607874461963210376168557582747775514258762252431133388687435", "price": "0.16", "size": "2724", "side": "BUY", "hash": "91b9c3f8a2d31963e72e4550dc62796ba2a23970", "best_bid": "0.55", "best_ask": "0.58"}, {"asset_id": "6991261290382769111733079462092282665787540572081318556604857015498053666166", "price": "0.84", "size": "2724", "side": "SELL", "hash": "f6588cf9f641d8c6ebde1c54faf80aa84ffa1c95", "best_bid": "0.42", "best_ask": "0.45"}], "timestamp": "1769384020544", "event_type": "price_change"}}
{"_local_timestamp": "2026-01-25T23:33:40.835407+00:00", "data": {"market": "0x8af1519f0b6704eaa52ac0890275b011fbca31729bf93fd956899a2c7ea410c0", "price_changes": [{"asset_id": "61357261066156427607874461963210376168557582747775514258762252431133388687435", "price": "0.23", "size": "3340", "side": "BUY", "hash": "b6952206e8dbc418399ee2d77104fa71c1df9e80", "best_bid": "0.55", "best_ask": "0.58"}, {"asset_id": "6991261290382769111733079462092282665787540572081318556604857015498053666166", "price": "0.77", "size": "3340", "side": "SELL", "hash": "a899a9a59245d0503893aa15084dc9aed877df1a", "best_bid": "0.42", "best_ask": "0.45"}], "timestamp": "1769384020582", "event_type": "price_change"}}
{"_local_timestamp": "2026-01-25T23:33:56.077069+00:00", "data": {"market": "0x8af1519f0b6704eaa52ac0890275b011fbca31729bf93fd956899a2c7ea410c0", "price_changes": [{"asset_id": "61357261066156427607874461963210376168557582747775514258762252431133388687435", "price": "0.55", "size": "394.97", "side": "BUY", "hash": "cf3952bf3c1657412ee6b351c1fa550eec36593d", "best_bid": "0.55", "best_ask": "0.58"}, {"asset_id": "6991261290382769111733079462092282665787540572081318556604857015498053666166", "price": "0.45", "size": "394.97", "side": "SELL", "hash": "40d5943a7a76f20aca732ce75fd9be382b9c1c27", "best_bid": "0.42", "best_ask": "0.45"}], "timestamp": "1769384036003", "event_type": "price_change"}}
{"_local_timestamp": "2026-01-25T23:33:56.083108+00:00", "data": {"market": "0x8af1519f0b6704eaa52ac0890275b011fbca31729bf93fd956899a2c7ea410c0", "price_changes": [{"asset_id": "6991261290382769111733079462092282665787540572081318556604857015498053666166", "price": "0.42", "size": "413.71", "side": "BUY", "hash": "3117e50f943b0cf9f1127ec7370b2512060caa7d", "best_bid": "0.42", "best_ask": "0.45"}, {"asset_id": "61357261066156427607874461963210376168557582747775514258762252431133388687435", "price": "0.58", "size": "413.71", "side": "SELL", "hash": "8acaeadddded74e9c3e00f329dbc939ea713127b", "best_bid": "0.55", "best_ask": "0.58"}], "timestamp": "1769384036003", "event_type": "price_change"}}
{"_local_timestamp": "2026-01-25T23:34:27.866214+00:00", "data": {"market": "0x8af1519f0b6704eaa52ac0890275b011fbca31729bf93fd956899a2c7ea410c0", "price_changes": [{"asset_id": "61357261066156427607874461963210376168557582747775514258762252431133388687435", "price": "0.2", "size": "65", "side": "BUY", "hash": "a109801c41a5acff9e3e9cd90f8efda661910edc", "best_bid": "0.55", "best_ask": "0.58"}, {"asset_id": "6991261290382769111733079462092282665787540572081318556604857015498053666166", "price": "0.8", "size": "65", "side": "SELL", "hash": "87d56bd84a2afbf2b797b33c22922f14c942fd7a", "best_bid": "0.42", "best_ask": "0.45"}], "timestamp": "1769384067617", "event_type": "price_change"}}
{"_local_timestamp": "2026-01-25T23:34:27.876150+00:00", "data": {"market": "0x8af1519f0b6704eaa52ac0890275b011fbca31729bf93fd956899a2c7ea410c0", "price_changes": [{"asset_id": "61357261066156427607874461963210376168557582747775514258762252431133388687435", "price": "0.26", "size": "0", "side": "BUY", "hash": "a109801c41a5acff9e3e9cd90f8efda661910edc", "best_bid": "0.55", "best_ask": "0.58"}, {"asset_id": "6991261290382769111733079462092282665787540572081318556604857015498053666166", "price": "0.74", "size": "0", "side": "SELL", "hash": "87d56bd84a2afbf2b797b33c22922f14c942fd7a", "best_bid": "0.42", "best_ask": "0.45"}], "timestamp": "1769384067617", "event_type": "price_change"}}
{"_local_timestamp": "2026-01-25T23:34:28.489583+00:00", "data": {"market": "0x8af1519f0b6704eaa52ac0890275b011fbca31729bf93fd956899a2c7ea410c0", "price_changes": [{"asset_id": "61357261066156427607874461963210376168557582747775514258762252431133388687435", "price": "0.27", "size": "326", "side": "BUY", "hash": "3806c53d9e5b22e3f01c289e1f662ee368cfa6c7", "best_bid": "0.55", "best_ask": "0.58"}, {"asset_id": "6991261290382769111733079462092282665787540572081318556604857015498053666166", "price": "0.73", "size": "326", "side": "SELL", "hash": "a59c0d0e8325adfa1d02233ab1b788e8fc298989", "best_bid": "0.42", "best_ask": "0.45"}], "timestamp": "1769384068141", "event_type": "price_change"}}
{"_local_timestamp": "2026-01-25T23:34:28.672245+00:00", "data": {"market": "0x8af1519f0b6704eaa52ac0890275b011fbca31729bf93fd956899a2c7ea410c0", "price_changes": [{"asset_id": "61357261066156427607874461963210376168557582747775514258762252431133388687435", "price": "0.16", "size": "2874", "side": "BUY", "hash": "6bff252d2f8aa0931b39dc879bfae0bfc9df179f", "best_bid": "0.55", "best_ask": "0.58"}, {"asset_id": "6991261290382769111733079462092282665787540572081318556604857015498053666166", "price": "0.84", "size": "2874", "side": "SELL", "hash": "c6ab25340b2378829a504e13b685908ee53fd03c", "best_bid": "0.42", "best_ask": "0.45"}], "timestamp": "1769384068222", "event_type": "price_change"}}
{"_local_timestamp": "2026-01-25T23:34:32.823235+00:00", "data": {"market": "0x8af1519f0b6704eaa52ac0890275b011fbca31729bf93fd956899a2c7ea410c0", "price_changes": [{"asset_id": "61357261066156427607874461963210376168557582747775514258762252431133388687435", "price": "0.27", "size": "100", "side": "BUY", "hash": "8749a9af398f9d30df67c7fa592f9461fdefc6f7", "best_bid": "0.55", "best_ask": "0.58"}, {"asset_id": "6991261290382769111733079462092282665787540572081318556604857015498053666166", "price": "0.73", "size": "100", "side": "SELL", "hash": "8997236ab49ca5cf2a3d336c6cafef2f7485523f", "best_bid": "0.42", "best_ask": "0.45"}], "timestamp": "1769384072757", "event_type": "price_change"}}
{"_local_timestamp": "2026-01-25T23:34:32.828894+00:00", "data": {"market": "0x8af1519f0b6704eaa52ac0890275b011fbca31729bf93fd956899a2c7ea410c0", "price_changes": [{"asset_id": "61357261066156427607874461963210376168557582747775514258762252431133388687435", "price": "0.28", "size": "218", "side": "BUY", "hash": "9faa1fc2cefd13959379a38552671bff8c482e43", "best_bid": "0.55", "best_ask": "0.58"}, {"asset_id": "6991261290382769111733079462092282665787540572081318556604857015498053666166", "price": "0.72", "size": "218", "side": "SELL", "hash": "e2ab7719ce3626fb9e517c4fe562b1138ec7c3e5", "best_bid": "0.42", "best_ask": "0.45"}], "timestamp": "1769384072766", "event_type": "price_change"}}
{"_local_timestamp": "2026-01-25T23:35:56.417795+00:00", "data": {"market": "0x8af1519f0b6704eaa52ac0890275b011fbca31729bf93fd956899a2c7ea410c0", "price_changes": [{"asset_id": "61357261066156427607874461963210376168557582747775514258762252431133388687435", "price": "0.2", "size": "15", "side": "BUY", "hash": "9c12b2d21c81b60abf79a9e53089faef67ebdb8d", "best_bid": "0.55", "best_ask": "0.58"}, {"asset_id": "6991261290382769111733079462092282665787540572081318556604857015498053666166", "price": "0.8", "size": "15", "side": "SELL", "hash": "de2122fbc0f480cb9698623569e7c2122b25f41e", "best_bid": "0.42", "best_ask": "0.45"}], "timestamp": "1769384156288", "event_type": "price_change"}}
{"_local_timestamp": "2026-01-25T23:35:56.848252+00:00", "data": {"market": "0x8af1519f0b6704eaa52ac0890275b011fbca31729bf93fd956899a2c7ea410c0", "price_changes": [{"asset_id": "61357261066156427607874461963210376168557582747775514258762252431133388687435", "price": "0.23", "size": "3390", "side": "BUY", "hash": "2a698d54be80aec177f2ea7a85932139f73d9abf", "best_bid": "0.55", "best_ask": "0.58"}, {"asset_id": "6991261290382769111733079462092282665787540572081318556604857015498053666166", "price": "0.77", "size": "3390", "side": "SELL", "hash": "e7e7c2711f59cc9ab6a86c98086b25ae9c139cf7", "best_bid": "0.42", "best_ask": "0.45"}], "timestamp": "1769384156722", "event_type": "price_change"}}
{"_local_timestamp": "2026-01-25T23:36:12.442194+00:00", "data": {"market": "0x8af1519f0b6704eaa52ac0890275b011fbca31729bf93fd956899a2c7ea410c0", "price_changes": [{"asset_id": "61357261066156427607874461963210376168557582747775514258762252431133388687435", "price": "0.44", "size": "28", "side": "BUY", "hash": "366062652530b77b10651141a783df4ca4875e1d", "best_bid": "0.55", "best_ask": "0.58"}, {"asset_id": "6991261290382769111733079462092282665787540572081318556604857015498053666166", "price": "0.56", "size": "28", "side": "SELL", "hash": "f9bf53b98a370e30f754578fa7db1b26b0fd2fca", "best_bid": "0.42", "best_ask": "0.45"}], "timestamp": "1769384172380", "event_type": "price_change"}}
{"_local_timestamp": "2026-01-25T23:36:12.443130+00:00", "data": {"market": "0x8af1519f0b6704eaa52ac0890275b011fbca31729bf93fd956899a2c7ea410c0", "price_changes": [{"asset_id": "61357261066156427607874461963210376168557582747775514258762252431133388687435", "price": "0.43", "size": "333.43", "side": "BUY", "hash": "366062652530b77b10651141a783df4ca4875e1d", "best_bid": "0.55", "best_ask": "0.58"}, {"asset_id": "6991261290382769111733079462092282665787540572081318556604857015498053666166", "price": "0.57", "size": "333.43", "side": "SELL", "hash": "f9bf53b98a370e30f754578fa7db1b26b0fd2fca", "best_bid": "0.42", "best_ask": "0.45"}], "timestamp": "1769384172380", "event_type": "price_change"}}
{"_local_timestamp": "2026-01-25T23:36:12.443960+00:00", "data": {"market": "0x8af1519f0b6704eaa52ac0890275b011fbca31729bf93fd956899a2c7ea410c0", "price_changes": [{"asset_id": "61357261066156427607874461963210376168557582747775514258762252431133388687435", "price": "0.24", "size": "83.33", "side": "BUY", "hash": "366062652530b77b10651141a783df4ca4875e1d", "best_bid": "0.55", "best_ask": "0.58"}, {"asset_id": "6991261290382769111733079462092282665787540572081318556604857015498053666166", "price": "0.76", "size": "83.33", "side": "SELL", "hash": "f9bf53b98a370e30f754578fa7db1b26b0fd2fca", "best_bid": "0.42", "best_ask": "0.45"}], "timestamp": "1769384172380", "event_type": "price_change"}}
{"_local_timestamp": "2026-01-25T23:36:12.446420+00:00", "data": {"market": "0x8af1519f0b6704eaa52ac0890275b011fbca31729bf93fd956899a2c7ea410c0", "price_changes": [{"asset_id": "61357261066156427607874461963210376168557582747775514258762252431133388687435", "price": "0.28", "size": "0", "side": "BUY", "hash": "366062652530b77b10651141a783df4ca4875e1d", "best_bid": "0.55", "best_ask": "0.58"}, {"asset_id": "6991261290382769111733079462092282665787540572081318556604857015498053666166", "price": "0.72", "size": "0", "side": "SELL", "hash": "f9bf53b98a370e30f754578fa7db1b26b0fd2fca", "best_bid": "0.42", "best_ask": "0.45"}], "timestamp": "1769384172380", "event_type": "price_change"}}
{"_local_timestamp": "2026-01-25T23:36:12.606366+00:00", "data": {"market": "0x8af1519f0b6704eaa52ac0890275b011fbca31729bf93fd956899a2c7ea410c0", "price_changes": [{"asset_id": "61357261066156427607874461963210376168557582747775514258762252431133388687435", "price": "0.44", "size": "35", "side": "BUY", "hash": "e2d5970d3de457e3e85f2db2abbb78018a2d886d", "best_bid": "0.55", "best_ask": "0.58"}, {"asset_id": "6991261290382769111733079462092282665787540572081318556604857015498053666166", "price": "0.56", "size": "35", "side": "SELL", "hash": "8d0e9a0bcf8f2a75eb1673b8204d64c9e83aa226", "best_bid": "0.42", "best_ask": "0.45"}], "timestamp": "1769384172540", "event_type": "price_change"}}
{"_local_timestamp": "2026-01-25T23:36:12.610694+00:00", "data": {"market": "0x8af1519f0b6704eaa52ac0890275b011fbca31729bf93fd956899a2c7ea410c0", "price_changes": [{"asset_id": "61357261066156427607874461963210376168557582747775514258762252431133388687435", "price": "0.28", "size": "215", "side": "BUY", "hash": "8d641832aa12f72fafee416a29dfdae868f3a3c7", "best_bid": "0.55", "best_ask": "0.58"}, {"asset_id": "6991261290382769111733079462092282665787540572081318556604857015498053666166", "price": "0.72", "size": "215", "side": "SELL", "hash": "124333ad36b2ee4d420a4cf8a56e7cfe17fc9912", "best_bid": "0.42", "best_ask": "0.45"}], "timestamp": "1769384172541", "event_type": "price_change"}}
{"_local_timestamp": "2026-01-25T23:36:12.611496+00:00", "data": {"market": "0x8af1519f0b6704eaa52ac0890275b011fbca31729bf93fd956899a2c7ea410c0", "price_changes": [{"asset_id": "61357261066156427607874461963210376168557582747775514258762252431133388687435", "price": "0.43", "size": "353.43", "side": "BUY", "hash": "bcc0f3abe2a6974bb616d9155c92c66948a080ab", "best_bid": "0.55", "best_ask": "0.58"}, {"asset_id": "6991261290382769111733079462092282665787540572081318556604857015498053666166", "price": "0.57", "size": "353.43", "side": "SELL", "hash": "97729a10d3dafa5ce95b5afcb18ceb29c3862d53", "best_bid": "0.42", "best_ask": "0.45"}], "timestamp": "1769384172541", "event_type": "price_change"}}
{"_local_timestamp": "2026-01-25T23:36:12.612096+00:00", "data": {"market": "0x8af1519f0b6704eaa52ac0890275b011fbca31729bf93fd956899a2c7ea410c0", "price_changes": [{"asset_id": "61357261066156427607874461963210376168557582747775514258762252431133388687435", "price": "0.24", "size": "579.33", "side": "BUY", "hash": "56b1ba61e4b506e3d0dcd8e9a2d0a0b21bf782ec", "best_bid": "0.55", "best_ask": "0.58"}, {"asset_id": "6991261290382769111733079462092282665787540572081318556604857015498053666166", "price": "0.76", "size": "579.33", "side": "SELL", "hash": "dfd6152867b0e54ce6ad14abe1832cc61db083d9", "best_bid": "0.42", "best_ask": "0.45"}], "timestamp": "1769384172542", "event_type": "price_change"}}
{"_local_timestamp": "2026-01-25T23:36:55.298474+00:00", "data": {"market": "0x8af1519f0b6704eaa52ac0890275b011fbca31729bf93fd956899a2c7ea410c0", "price_changes": [{"asset_id": "61357261066156427607874461963210376168557582747775514258762252431133388687435", "price": "0.27", "size": "0", "side": "BUY", "hash": "e9f992b5770d81c6402505420be1806ac6412a5e", "best_bid": "0.55", "best_ask": "0.58"}, {"asset_id": "6991261290382769111733079462092282665787540572081318556604857015498053666166", "price": "0.73", "size": "0", "side": "SELL", "hash": "1f0db68e7735682bb88b33e9e7da7c55bccbe6e8", "best_bid": "0.42", "best_ask": "0.45"}], "timestamp": "1769384215019", "event_type": "price_change"}}
{"_local_timestamp": "2026-01-25T23:36:56.252929+00:00", "data": {"market": "0x8af1519f0b6704eaa52ac0890275b011fbca31729bf93fd956899a2c7ea410c0", "price_changes": [{"asset_id": "61357261066156427607874461963210376168557582747775514258762252431133388687435", "price": "0.28", "size": "315", "side": "BUY", "hash": "1cc3d4c368a7d196a9a887006d4ca02e269f077a", "best_bid": "0.55", "best_ask": "0.58"}, {"asset_id": "6991261290382769111733079462092282665787540572081318556604857015498053666166", "price": "0.72", "size": "315", "side": "SELL", "hash": "da257836c81ca865a6ac4e591b3315a2203b51ae", "best_bid": "0.42", "best_ask": "0.45"}], "timestamp": "1769384215691", "event_type": "price_change"}}
{"_local_timestamp": "2026-01-25T23:36:57.850035+00:00", "data": {"market": "0x8af1519f0b6704eaa52ac0890275b011fbca31729bf93fd956899a2c7ea410c0", "price_changes": [{"asset_id": "61357261066156427607874461963210376168557582747775514258762252431133388687435", "price": "0.21", "size": "114.28", "side": "BUY", "hash": "fa801e7b14deeeb64f902fd156e2cabfaf67ead8", "best_bid": "0.55", "best_ask": "0.58"}, {"asset_id": "6991261290382769111733079462092282665787540572081318556604857015498053666166", "price": "0.79", "size": "114.28", "side": "SELL", "hash": "543fa82f96e0734ac6605d5cb59f5bf3aef939c7", "best_bid": "0.42", "best_ask": "0.45"}], "timestamp": "1769384217245", "event_type": "price_change"}}
{"_local_timestamp": "2026-01-25T23:36:58.466012+00:00", "data": {"market": "0x8af1519f0b6704eaa52ac0890275b011fbca31729bf93fd956899a2c7ea410c0", "price_changes": [{"asset_id": "61357261066156427607874461963210376168557582747775514258762252431133388687435", "price": "0.24", "size": "83.33", "side": "BUY", "hash": "75452243cf9e1c1eb5cbb49707fd2453a471d4ab", "best_bid": "0.55", "best_ask": "0.58"}, {"asset_id": "6991261290382769111733079462092282665787540572081318556604857015498053666166", "price": "0.76", "size": "83.33", "side": "SELL", "hash": "e36a5311aea0b64e05183a61f4ffc060b6029329", "best_bid": "0.42", "best_ask": "0.45"}], "timestamp": "1769384218146", "event_type": "price_change"}}
{"_local_timestamp": "2026-01-25T23:36:58.466461+00:00", "data": {"market": "0x8af1519f0b6704eaa52ac0890275b011fbca31729bf93fd956899a2c7ea410c0", "price_changes": [{"asset_id": "61357261066156427607874461963210376168557582747775514258762252431133388687435", "price": "0.28", "size": "100", "side": "BUY", "hash": "75452243cf9e1c1eb5cbb49707fd2453a471d4ab", "best_bid": "0.55", "best_ask": "0.58"}, {"asset_id": "6991261290382769111733079462092282665787540572081318556604857015498053666166", "price": "0.72", "size": "100", "side": "SELL", "hash": "e36a5311aea0b64e05183a61f4ffc060b6029329", "best_bid": "0.42", "best_ask": "0.45"}], "timestamp": "1769384218146", "event_type": "price_change"}}
{"_local_timestamp": "2026-01-25T23:36:58.472710+00:00", "data": {"market": "0x8af1519f0b6704eaa52ac0890275b011fbca31729bf93fd956899a2c7ea410c0", "price_changes": [{"asset_id": "61357261066156427607874461963210376168557582747775514258762252431133388687435", "price": "0.25", "size": "240", "side": "BUY", "hash": "e81764bdd0a6799f10e0c38489f573263f97824e", "best_bid": "0.55", "best_ask": "0.58"}, {"asset_id": "6991261290382769111733079462092282665787540572081318556604857015498053666166", "price": "0.75", "size": "240", "side": "SELL", "hash": "30dd04fffae19ba5f1b592510a5dd2a344ee99cc", "best_bid": "0.42", "best_ask": "0.45"}], "timestamp": "1769384218176", "event_type": "price_change"}}
{"_local_timestamp": "2026-01-25T23:36:58.482073+00:00", "data": {"market": "0x8af1519f0b6704eaa52ac0890275b011fbca31729bf93fd956899a2c7ea410c0", "price_changes": [{"asset_id": "61357261066156427607874461963210376168557582747775514258762252431133388687435", "price": "0.23", "size": "3908", "side": "BUY", "hash": "423ac15ec4f7465f3204efdc7758e8a91ab735a4", "best_bid": "0.55", "best_ask": "0.58"}, {"asset_id": "6991261290382769111733079462092282665787540572081318556604857015498053666166", "price": "0.77", "size": "3908", "side": "SELL", "hash": "9f1616ff0f8e4917aff3e8df6546951fe50bbf4f", "best_bid": "0.42", "best_ask": "0.45"}], "timestamp": "1769384218177", "event_type": "price_change"}}
{"_local_timestamp": "2026-01-25T23:37:03.557801+00:00", "data": {"market": "0x8af1519f0b6704eaa52ac0890275b011fbca31729bf93fd956899a2c7ea410c0", "price_changes": [{"asset_id": "61357261066156427607874461963210376168557582747775514258762252431133388687435", "price": "0.25", "size": "0", "side": "BUY", "hash": "79ff7ea3331f1e4f695732f75fea9bae3292f9b3", "best_bid": "0.55", "best_ask": "0.58"}, {"asset_id": "6991261290382769111733079462092282665787540572081318556604857015498053666166", "price": "0.75", "size": "0", "side": "SELL", "hash": "344be4ffcf2be3197be2dc17fa231ae530fc19eb", "best_bid": "0.42", "best_ask": "0.45"}], "timestamp": "1769384223373", "event_type": "price_change"}}
{"_local_timestamp": "2026-01-25T23:37:03.558295+00:00", "data": {"market": "0x8af1519f0b6704eaa52ac0890275b011fbca31729bf93fd956899a2c7ea410c0", "price_changes": [{"asset_id": "61357261066156427607874461963210376168557582747775514258762252431133388687435", "price": "0.23", "size": "3390", "side": "BUY", "hash": "79ff7ea3331f1e4f695732f75fea9bae3292f9b3", "best_bid": "0.55", "best_ask": "0.58"}, {"asset_id": "6991261290382769111733079462092282665787540572081318556604857015498053666166", "price": "0.77", "size": "3390", "side": "SELL", "hash": "344be4ffcf2be3197be2dc17fa231ae530fc19eb", "best_bid": "0.42", "best_ask": "0.45"}], "timestamp": "1769384223373", "event_type": "price_change"}}
{"_local_timestamp": "2026-01-25T23:37:03.564083+00:00", "data": {"market": "0x8af1519f0b6704eaa52ac0890275b011fbca31729bf93fd956899a2c7ea410c0", "price_changes": [{"asset_id": "61357261066156427607874461963210376168557582747775514258762252431133388687435", "price": "0.29", "size": "207", "side": "BUY", "hash": "fc80f09d0180097a08c849499642788cac8a77c0", "best_bid": "0.55", "best_ask": "0.58"}, {"asset_id": "6991261290382769111733079462092282665787540572081318556604857015498053666166", "price": "0.71", "size": "207", "side": "SELL", "hash": "7e719177fa38a13497b63ca05d6eb4965d0eb88f", "best_bid": "0.42", "best_ask": "0.45"}], "timestamp": "1769384223385", "event_type": "price_change"}}
{"_local_timestamp": "2026-01-25T23:37:03.565317+00:00", "data": {"market": "0x8af1519f0b6704eaa52ac0890275b011fbca31729bf93fd956899a2c7ea410c0", "price_changes": [{"asset_id": "61357261066156427607874461963210376168557582747775514258762252431133388687435", "price": "0.24", "size": "579.33", "side": "BUY", "hash": "826aa9f41b12c8102b8894332512d06de2d05559", "best_bid": "0.55", "best_ask": "0.58"}, {"asset_id": "6991261290382769111733079462092282665787540572081318556604857015498053666166", "price": "0.76", "size": "579.33", "side": "SELL", "hash": "fd73119a2b8783d4ace5c7b31d8a0961b1fee837", "best_bid": "0.42", "best_ask": "0.45"}], "timestamp": "1769384223386", "event_type": "price_change"}}
{"_local_timestamp": "2026-01-25T23:37:10.190247+00:00", "data": {"market": "0x8af1519f0b6704eaa52ac0890275b011fbca31729bf93fd956899a2c7ea410c0", "price_changes": [{"asset_id": "61357261066156427607874461963210376168557582747775514258762252431133388687435", "price": "0.25", "size": "296", "side": "BUY", "hash": "7ba768b477f86ab230b551e2ebd039075c72f897", "best_bid": "0.55", "best_ask": "0.58"}, {"asset_id": "6991261290382769111733079462092282665787540572081318556604857015498053666166", "price": "0.75", "size": "296", "side": "SELL", "hash": "d73ad26890bdb702631f532e9454f02233ddc9e6", "best_bid": "0.42", "best_ask": "0.45"}], "timestamp": "1769384230115", "event_type": "price_change"}}
{"_local_timestamp": "2026-01-25T23:37:13.832716+00:00", "data": {"market": "0x8af1519f0b6704eaa52ac0890275b011fbca31729bf93fd956899a2c7ea410c0", "price_changes": [{"asset_id": "61357261066156427607874461963210376168557582747775514258762252431133388687435", "price": "0.24", "size": "83.33", "side": "BUY", "hash": "9a53d610dd3e4c61c746ae50abe895a0c2de0a67", "best_bid": "0.55", "best_ask": "0.58"}, {"asset_id": "6991261290382769111733079462092282665787540572081318556604857015498053666166", "price": "0.76", "size": "83.33", "side": "SELL", "hash": "08e0ab9ca402f95f29131c6d0a33f53968936fa8", "best_bid": "0.42", "best_ask": "0.45"}], "timestamp": "1769384233766", "event_type": "price_change"}}
{"_local_timestamp": "2026-01-25T23:37:13.850798+00:00", "data": {"market": "0x8af1519f0b6704eaa52ac0890275b011fbca31729bf93fd956899a2c7ea410c0", "price_changes": [{"asset_id": "61357261066156427607874461963210376168557582747775514258762252431133388687435", "price": "0.26", "size": "458", "side": "BUY", "hash": "7ef755ee8616cb284ea50df50292469b06d1b1bd", "best_bid": "0.55", "best_ask": "0.58"}, {"asset_id": "6991261290382769111733079462092282665787540572081318556604857015498053666166", "price": "0.74", "size": "458", "side": "SELL", "hash": "e1da1267426056e23a9699eaf98db155a7df5e55", "best_bid": "0.42", "best_ask": "0.45"}], "timestamp": "1769384233783", "event_type": "price_change"}}
{"_local_timestamp": "2026-01-25T23:38:52.084570+00:00", "data": {"market": "0x8af1519f0b6704eaa52ac0890275b011fbca31729bf93fd956899a2c7ea410c0", "price_changes": [{"asset_id": "61357261066156427607874461963210376168557582747775514258762252431133388687435", "price": "0.44", "size": "19", "side": "BUY", "hash": "2dc4d62c68e76003d906aa955a7b13cbf25e1492", "best_bid": "0.55", "best_ask": "0.58"}, {"asset_id": "6991261290382769111733079462092282665787540572081318556604857015498053666166", "price": "0.56", "size": "19", "side": "SELL", "hash": "84a56a659ca3cf1e4e488e52c7442b984895ef0e", "best_bid": "0.42", "best_ask": "0.45"}], "timestamp": "1769384332002", "event_type": "price_change"}}
{"_local_timestamp": "2026-01-25T23:38:52.085136+00:00", "data": {"market": "0x8af1519f0b6704eaa52ac0890275b011fbca31729bf93fd956899a2c7ea410c0", "price_changes": [{"asset_id": "61357261066156427607874461963210376168557582747775514258762252431133388687435", "price": "0.43", "size": "334.43", "side": "BUY", "hash": "a07c57ec285adc46ad1026167347ba6a649e0135", "best_bid": "0.55", "best_ask": "0.58"}, {"asset_id": "6991261290382769111733079462092282665787540572081318556604857015498053666166", "price": "0.57", "size": "334.43", "side": "SELL", "hash": "e3a385bae8d90cf1269714ee8eb4a75e76ef1253", "best_bid": "0.42", "best_ask": "0.45"}], "timestamp": "1769384332007", "event_type": "price_change"}}
{"_local_timestamp": "2026-01-25T23:38:56.168517+00:00", "data": {"market": "0x8af1519f0b6704eaa52ac0890275b011fbca31729bf93fd956899a2c7ea410c0", "price_changes": [{"asset_id": "61357261066156427607874461963210376168557582747775514258762252431133388687435", "price": "0.43", "size": "353.43", "side": "BUY", "hash": "d4473fb327de45de091f03a2836ee225666e2b7c", "best_bid": "0.55", "best_ask": "0.58"}, {"asset_id": "6991261290382769111733079462092282665787540572081318556604857015498053666166", "price": "0.57", "size": "353.43", "side": "SELL", "hash": "c14de73028fb2c365875f0d819862634d9c7baf4", "best_bid": "0.42", "best_ask": "0.45"}], "timestamp": "1769384336101", "event_type": "price_change"}}
{"_local_timestamp": "2026-01-25T23:38:56.168963+00:00", "data": {"market": "0x8af1519f0b6704eaa52ac0890275b011fbca31729bf93fd956899a2c7ea410c0", "price_changes": [{"asset_id": "61357261066156427607874461963210376168557582747775514258762252431133388687435", "price": "0.44", "size": "35", "side": "BUY", "hash": "7acc613f952b32af117d85fa5ffbd8fc7412ad32", "best_bid": "0.55", "best_ask": "0.58"}, {"asset_id": "6991261290382769111733079462092282665787540572081318556604857015498053666166", "price": "0.56", "size": "35", "side": "SELL", "hash": "a756e0c8bdf7ff8a405206d5b6eaecb8b65b7031", "best_bid": "0.42", "best_ask": "0.45"}], "timestamp": "1769384336102", "event_type": "price_change"}}
{"_local_timestamp": "2026-01-25T23:39:22.525567+00:00", "data": {"market": "0x8af1519f0b6704eaa52ac0890275b011fbca31729bf93fd956899a2c7ea410c0", "price_changes": [{"asset_id": "61357261066156427607874461963210376168557582747775514258762252431133388687435", "price": "0.28", "size": "0", "side": "BUY", "hash": "1ea2c63d411a6d7714da048b44de060cc93c46ae", "best_bid": "0.55", "best_ask": "0.58"}, {"asset_id": "6991261290382769111733079462092282665787540572081318556604857015498053666166", "price": "0.72", "size": "0", "side": "SELL", "hash": "9ccbc06110f8003aa1182f7b94b622ebf13ff296", "best_bid": "0.42", "best_ask": "0.45"}], "timestamp": "1769384362224", "event_type": "price_change"}}
{"_local_timestamp": "2026-01-25T23:39:22.921146+00:00", "data": {"market": "0x8af1519f0b6704eaa52ac0890275b011fbca31729bf93fd956899a2c7ea410c0", "price_changes": [{"asset_id": "61357261066156427607874461963210376168557582747775514258762252431133388687435", "price": "0.29", "size": "307", "side": "BUY", "hash": "652ebfa36c2d6e9b13f6bb0cf66921e9bc17d230", "best_bid": "0.55", "best_ask": "0.58"}, {"asset_id": "6991261290382769111733079462092282665787540572081318556604857015498053666166", "price": "0.71", "size": "307", "side": "SELL", "hash": "30dc312c08885caa78b9c7ef3793c62c9fad7306", "best_bid": "0.42", "best_ask": "0.45"}], "timestamp": "1769384362714", "event_type": "price_change"}}
{"_local_timestamp": "2026-01-25T23:39:29.382449+00:00", "data": {"market": "0x8af1519f0b6704eaa52ac0890275b011fbca31729bf93fd956899a2c7ea410c0", "price_changes": [{"asset_id": "61357261066156427607874461963210376168557582747775514258762252431133388687435", "price": "0.29", "size": "100", "side": "BUY", "hash": "9b6d6bfd729b2e24af2aaab296a457b520b9c22e", "best_bid": "0.55", "best_ask": "0.58"}, {"asset_id": "6991261290382769111733079462092282665787540572081318556604857015498053666166", "price": "0.71", "size": "100", "side": "SELL", "hash": "ffcc82bea0eaa3ce87c6c9f6108d66cd7aed81c7", "best_bid": "0.42", "best_ask": "0.45"}], "timestamp": "1769384369315", "event_type": "price_change"}}
{"_local_timestamp": "2026-01-25T23:39:29.382957+00:00", "data": {"market": "0x8af1519f0b6704eaa52ac0890275b011fbca31729bf93fd956899a2c7ea410c0", "price_changes": [{"asset_id": "61357261066156427607874461963210376168557582747775514258762252431133388687435", "price": "0.3", "size": "200", "side": "BUY", "hash": "ca3508f70fe878dc8eb09d5fc3c38fec1fd6f997", "best_bid": "0.55", "best_ask": "0.58"}, {"asset_id": "6991261290382769111733079462092282665787540572081318556604857015498053666166", "price": "0.7", "size": "200", "side": "SELL", "hash": "7e55359e4b060e4252a2abae7e3b20229937e3c9", "best_bid": "0.42", "best_ask": "0.45"}], "timestamp": "1769384369319", "event_type": "price_change"}}
{"_local_timestamp": "2026-01-25T23:39:57.111900+00:00", "data": {"market": "0x8af1519f0b6704eaa52ac0890275b011fbca31729bf93fd956899a2c7ea410c0", "price_changes": [{"asset_id": "61357261066156427607874461963210376168557582747775514258762252431133388687435", "price": "0.43", "size": "334.43", "side": "BUY", "hash": "a470afca6c523d707419feffef6cf0cd08aa21e5", "best_bid": "0.55", "best_ask": "0.58"}, {"asset_id": "6991261290382769111733079462092282665787540572081318556604857015498053666166", "price": "0.57", "size": "334.43", "side": "SELL", "hash": "709490d6c8df9c33a67f91c6b5ed9eeffadbb7ca", "best_bid": "0.42", "best_ask": "0.45"}], "timestamp": "1769384397001", "event_type": "price_change"}}
{"_local_timestamp": "2026-01-25T23:40:07.597210+00:00", "data": {"market": "0x8af1519f0b6704eaa52ac0890275b011fbca31729bf93fd956899a2c7ea410c0", "price_changes": [{"asset_id": "61357261066156427607874461963210376168557582747775514258762252431133388687435", "price": "0.43", "size": "353.43", "side": "BUY", "hash": "7fc102a37cda62a3c7267d456fc6df15af593626", "best_bid": "0.55", "best_ask": "0.58"}, {"asset_id": "6991261290382769111733079462092282665787540572081318556604857015498053666166", "price": "0.57", "size": "353.43", "side": "SELL", "hash": "d2e9f3558890354be480799e181f3e8bf864f887", "best_bid": "0.42", "best_ask": "0.45"}], "timestamp": "1769384407521", "event_type": "price_change"}}
