{"_local_timestamp": "2026-01-25T23:41:07.529773+00:00", "data": [{"market": "0xbeda18055fdc1f5bce0934e2500ed4ee82745b4c78b109e04e8dcf69f98d5d02", "asset_id": "1721314828785517746980964825401510699361790864946226663151397689590042697451", "timestamp": "1769384440571", "hash": "9f2e32862dadb27d516ca7f6b752409eee038cf7", "bids": [{"price": "0.01", "size": "8019.73"}, {"price": "0.02", "size": "1750"}, {"price": "0.03", "size": "10.35"}, {"price": "0.04", "size": "3063.93"}, {"price": "0.05", "size": "250"}, {"price": "0.07", "size": "985.71"}, {"price": "0.09", "size": "355.55"}, {"price": "0.1", "size": "2206.91"}, {"price": "0.11", "size": "254.54"}, {"price": "0.12", "size": "3500"}, {"price": "0.13", "size": "4247"}, {"price": "0.14", "size": "185.71"}, {"price": "0.15", "size": "200"}, {"price": "0.16", "size": "550"}, {"price": "0.18", "size": "118.08"}, {"price": "0.21", "size": "300"}, {"price": "0.22", "size": "119.6"}, {"price": "0.26", "size": "10"}, {"price": "0.27", "size": "218.86"}, {"price": "0.28", "size": "200"}, {"price": "0.29", "size": "239.57"}, {"price": "0.3", "size": "316.09"}, {"price": "0.31", "size": "1165"}, {"price": "0.33", "size": "807"}, {"price": "0.34", "size": "10"}, {"price": "0.35", "size": "244.11"}, {"price": "0.36", "size": "543.55"}, {"price": "0.37", "size": "64.05"}, {"price": "0.38", "size": "260"}, {"price": "0.39", "size": "5327.4"}, {"price": "0.4", "size": "143.63"}, {"price": "0.41", "size": "412.17"}, {"price": "0.42", "size": "253"}, {"price": "0.43", "size": "775.15"}], "asks": [{"price": "0.99", "size": "5610.3"}, {"price": "0.98", "size": "1000"}, {"price": "0.97", "size": "10.65"}, {"price": "0.96", "size": "2750"}, {"price": "0.95", "size": "30"}, {"price": "0.94", "size": "1300"}, {"price": "0.93", "size": "250"}, {"price": "0.92", "size": "425"}, {"price": "0.9", "size": "10"}, {"price": "0.89", "size": "296.15"}, {"price": "0.86", "size": "1892"}, {"price": "0.83", "size": "152.94"}, {"price": "0.82", "size": "2782"}, {"price": "0.81", "size": "200"}, {"price": "0.8", "size": "120"}, {"price": "0.78", "size": "290.9"}, {"price": "0.74", "size": "150"}, {"price": "0.72", "size": "5"}, {"price": "0.55", "size": "50"}, {"price": "0.52", "size": "27.08"}, {"price": "0.5", "size": "26.76"}, {"price": "0.49", "size": "105"}, {"price": "0.48", "size": "50.64"}, {"price": "0.47", "size": "2098.01"}, {"price": "0.46", "size": "1171.25"}, {"price": "0.45", "size": "6632.9"}, {"price": "0.44", "size": "453.08"}], "event_type": "book", "last_trade_price": "0.430"}, {"market": "0xbeda18055fdc1f5bce0934e2500ed4ee82745b4c78b109e04e8dcf69f98d5d02", "asset_id": "72392264258230870796011784251756958130679822179554057734962978782410770260489", "timestamp": "1769384440571", "hash": "4797f59a69486b2cfb912820b2e342216ea07f67", "bids": [{"price": "0.01", "size": "5610.3"}, {"price": "0.02", "size": "1000"}, {"price": "0.03", "size": "10.65"}, {"price": "0.04", "size": "2750"}, {"price": "0.05", "size": "30"}, {"price": "0.06", "size": "1300"}, {"price": "0.07", "size": "250"}, {"price": "0.08", "size": "425"}, {"price": "0.1", "size": "10"}, {"price": "0.11", "size": "296.15"}, {"price": "0.14", "size": "1892"}, {"price": "0.17", "size": "152.94"}, {"price": "0.18", "size": "2782"}, {"price": "0.19", "size": "200"}, {"price": "0.2", "size": "120"}, {"price": "0.22", "size": "290.9"}, {"price": "0.26", "size": "150"}, {"price": "0.28", "size": "5"}, {"price": "0.45", "size": "50"}, {"price": "0.48", "size": "27.08"}, {"price": "0.5", "size": "26.76"}, {"price": "0.51", "size": "105"}, {"price": "0.52", "size": "50.64"}, {"price": "0.53", "size": "2098.01"}, {"price": "0.54", "size": "1171.25"}, {"price": "0.55", "size": "6632.9"}, {"price": "0.56", "size": "453.08"}], "asks": [{"price": "0.99", "size": "8019.73"}, {"price": "0.98", "size": "1750"}, {"price": "0.97", "size": "10.35"}, {"price": "0.96", "size": "3063.93"}, {"price": "0.95", "size": "250"}, {"price": "0.93", "size": "985.71"}, {"price": "0.91", "size": "355.55"}, {"price": "0.9", "size": "2206.91"}, {"price": "0.89", "size": "254.54"}, {"price": "0.88", "size": "3500"}, {"price": "0.87", "size": "4247"}, {"price": "0.86", "size": "185.71"}, {"price": "0.85", "size": "200"}, {"price": "0.84", "size": "550"}, {"price": "0.82", "size": "118.08"}, {"price": "0.79", "size": "300"}, {"price": "0.78", "size": "119.6"}, {"price": "0.74", "size": "10"}, {"price": "0.73", "size": "218.86"}, {"price": "0.72", "size": "200"}, {"price": "0.71", "size": "239.57"}, {"price": "0.7", "size": "316.09"}, {"price": "0.69", "size": "1165"}, {"price": "0.67", "size": "807"}, {"price": "0.66", "size": "10"}, {"price": "0.65", "size": "244.11"}, {"price": "0.64", "size": "543.55"}, {"price": "0.63", "size": "64.05"}, {"price": "0.62", "size": "260"}, {"price": "0.61", "size": "5327.4"}, {"price": "0.6", "size": "143.63"}, {"price": "0.59", "size": "412.17"}, {"price": "0.58", "size": "253"}, {"price": "0.57", "size": "775.15"}], "event_type": "book", "last_trade_price": "0.430"}]}
{"_local_timestamp": "2026-01-25T23:41:12.648707+00:00", "data": {"market": "0xbeda18055fdc1f5bce0934e2500ed4ee82745b4c78b109e04e8dcf69f98d5d02", "price_changes": [{"asset_id": "1721314828785517746980964825401510699361790864946226663151397689590042697451", "price": "0.36", "size": "552.55", "side": "BUY", "hash": "f0f2f5c4cb57bb0dd8159126ad35a23df01929cd", "best_bid": "0.43", "best_ask": "0.44"}, {"asset_id": "72392264258230870796011784251756958130679822179554057734962978782410770260489", "price": "0.64", "size": "552.55", "side": "SELL", "hash": "ea1312ee8329aae750253e20baf9f5f6304d0b6d", "best_bid": "0.56", "best_ask": "0.57"}], "timestamp": "1769384472570", "event_type": "price_change"}}
{"_local_timestamp": "2026-01-25T23:41:12.658914+00:00", "data": {"market": "0xbeda18055fdc1f5bce0934e2500ed4ee82745b4c78b109e04e8dcf69f98d5d02", "price_changes": [{"asset_id": "1721314828785517746980964825401510699361790864946226663151397689590042697451", "price": "0.31", "size": "1184", "side": "BUY", "hash": "26ba4e2c50a4991fea9fdb5f8f11d49358cdbc8e", "best_bid": "0.43", "best_ask": "0.44"}, {"asset_id": "72392264258230870796011784251756958130679822179554057734962978782410770260489", "price": "0.69", "size": "1184", "side": "SELL", "hash": "5a5a386d7995e8972f6dbefbcf2a8452731d99ba", "best_bid": "0.56", "best_ask": "0.57"}], "timestamp": "1769384472571", "event_type": "price_change"}}
{"_local_timestamp": "2026-01-25T23:41:14.735676+00:00", "data": {"market": "0xbeda18055fdc1f5bce0934e2500ed4ee82745b4c78b109e04e8dcf69f98d5d02", "price_changes": [{"asset_id": "1721314828785517746980964825401510699361790864946226663151397689590042697451", "price": "0.12", "size": "0", "side": "BUY", "hash": "23700635d5db99c7f7de44342065188a52701f3d", "best_bid": "0.43", "best_ask": "0.44"}, {"asset_id": "72392264258230870796011784251756958130679822179554057734962978782410770260489", "price": "0.88", "size": "0", "side": "SELL", "hash": "7fcc242383ba8004b67bd9174bb7d170726c18aa", "best_bid": "0.56", "best_ask": "0.57"}], "timestamp": "1769384474536", "event_type": "price_change"}}
{"_local_timestamp": "2026-01-25T23:41:20.745733+00:00", "data": {"market": "0xbeda18055fdc1f5bce0934e2500ed4ee82745b4c78b109e04e8dcf69f98d5d02", "price_changes": [{"asset_id": "1721314828785517746980964825401510699361790864946226663151397689590042697451", "price": "0.13", "size": "400", "side": "BUY", "hash": "5d2ffc21164a1a73919a58c3f786850197d4027e", "best_bid": "0.43", "best_ask": "0.44"}, {"asset_id": "72392264258230870796011784251756958130679822179554057734962978782410770260489", "price": "0.87", "size": "400", "side": "SELL", "hash": "4922af67773698e439c9372a2f1e466c2ad99825", "best_bid": "0.56", "best_ask": "0.57"}], "timestamp": "1769384480656", "event_type": "price_change"}}
{"_local_timestamp": "2026-01-25T23:41:20.781549+00:00", "data": {"market": "0xbeda18055fdc1f5bce0934e2500ed4ee82745b4c78b109e04e8dcf69f98d5d02", "price_changes": [{"asset_id": "1721314828785517746980964825401510699361790864946226663151397689590042697451", "price": "0.11", "size": "4800.54", "side": "BUY", "hash": "4ba6f9ea1b3711864da7f8d9422d9d0edd2fd2db", "best_bid": "0.43", "best_ask": "0.44"}, {"asset_id": "72392264258230870796011784251756958130679822179554057734962978782410770260489", "price": "0.89", "size": "4800.54", "side": "SELL", "hash": "8ba746982b330be0483ba94a1352269cdad9d964", "best_bid": "0.56", "best_ask": "0.57"}], "timestamp": "1769384480697", "event_type": "price_change"}}
{"_local_timestamp": "2026-01-25T23:41:35.455727+00:00", "data": {"market": "0xbeda18055fdc1f5bce0934e2500ed4ee82745b4c78b109e04e8dcf69f98d5d02", "price_changes": [{"asset_id": "1721314828785517746980964825401510699361790864946226663151397689590042697451", "price": "0.14", "size": "3183.71", "side": "BUY", "hash": "c34a20a0592c6bb6f525be61c914f933e31eea6e", "best_bid": "0.43", "best_ask": "0.44"}, {"asset_id": "72392264258230870796011784251756958130679822179554057734962978782410770260489", "price": "0.86", "size": "3183.71", "side": "SELL", "hash": "f5cedcfee084fa0f69fc6973d45ceac2c6a41afe", "best_bid": "0.56", "best_ask": "0.57"}], "timestamp": "1769384495376", "event_type": "price_change"}}
{"_local_timestamp": "2026-01-25T23:41:37.848679+00:00", "data": {"market": "0xbeda18055fdc1f5bce0934e2500ed4ee82745b4c78b109e04e8dcf69f98d5d02", "price_changes": [{"asset_id": "1721314828785517746980964825401510699361790864946226663151397689590042697451", "price": "0.11", "size": "254.54", "side": "BUY", "hash": "c39e98c6b9f7c976cf9e6d98e7681da349105546", "best_bid": "0.43", "best_ask": "0.44"}, {"asset_id": "72392264258230870796011784251756958130679822179554057734962978782410770260489", "price": "0.89", "size": "254.54", "side": "SELL", "hash": "a79f8ab92bf06e20def0d85507c08358dd9bce8c", "best_bid": "0.56", "best_ask": "0.57"}], "timestamp": "1769384497764", "event_type": "price_change"}}
{"_local_timestamp": "2026-01-25T23:41:37.849313+00:00", "data": {"market": "0xbeda18055fdc1f5bce0934e2500ed4ee82745b4c78b109e04e8dcf69f98d5d02", "price_changes": [{"asset_id": "1721314828785517746980964825401510699361790864946226663151397689590042697451", "price": "0.15", "size": "3534", "side": "BUY", "hash": "292cc7eb12c21cb3fc1202e97486e9a4d966842d", "best_bid": "0.43", "best_ask": "0.44"}, {"asset_id": "72392264258230870796011784251756958130679822179554057734962978782410770260489", "price": "0.85", "size": "3534", "side": "SELL", "hash": "60cf3e4f27d29479e59e22ea5fcb1a3e3abff437", "best_bid": "0.56", "best_ask": "0.57"}], "timestamp": "1769384497777", "event_type": "price_change"}}
{"_local_timestamp": "2026-01-25T23:41:48.546998+00:00", "data": {"market": "0xbeda18055fdc1f5bce0934e2500ed4ee82745b4c78b109e04e8dcf69f98d5d02", "price_changes": [{"asset_id": "72392264258230870796011784251756958130679822179554057734962978782410770260489", "price": "0.6", "size": "175.63", "side": "SELL", "hash": "a5bb1178412deca56ff3b8b30135857a03572d1b", "best_bid": "0.56", "best_ask": "0.57"}, {"asset_id": "1721314828785517746980964825401510699361790864946226663151397689590042697451", "price": "0.4", "size": "175.63", "side": "BUY", "hash": "28b018ce8817d325a21f4d9c23cad7cf8c8efa8e", "best_bid": "0.43", "best_ask": "0.44"}], "timestamp": "1769384508475", "event_type": "price_change"}}
{"_local_timestamp": "2026-01-25T23:41:50.859895+00:00", "data": {"market": "0xbeda18055fdc1f5bce0934e2500ed4ee82745b4c78b109e04e8dcf69f98d5d02", "price_changes": [{"asset_id": "1721314828785517746980964825401510699361790864946226663151397689590042697451", "price": "0.15", "size": "3334", "side": "BUY", "hash": "1a05b5508b9aa8cf012234598ef08a0f5eaecb46", "best_bid": "0.43", "best_ask": "0.44"}, {"asset_id": "72392264258230870796011784251756958130679822179554057734962978782410770260489", "price": "0.85", "size": "3334", "side": "SELL", "hash": "555cb7b91171003368a797adeeedcd52b04be20b", "best_bid": "0.56", "best_ask": "0.57"}], "timestamp": "1769384510732", "event_type": "price_change"}}
{"_local_timestamp": "2026-01-25T23:41:52.714655+00:00", "data": {"market": "0xbeda18055fdc1f5bce0934e2500ed4ee82745b4c78b109e04e8dcf69f98d5d02", "price_changes": [{"asset_id": "1721314828785517746980964825401510699361790864946226663151397689590042697451", "price": "0.13", "size": "600", "side": "BUY", "hash": "cbdf2b313c06890df73f2f078f387ec28cd5494e", "best_bid": "0.43", "best_ask": "0.44"}, {"asset_id": "72392264258230870796011784251756958130679822179554057734962978782410770260489", "price": "0.87", "size": "600", "side": "SELL", "hash": "9d31ddf51d43319c3909d01da9bc393da1261886", "best_bid": "0.56", "best_ask": "0.57"}], "timestamp": "1769384511766", "event_type": "price_change"}}
{"_local_timestamp": "2026-01-25T23:42:22.361103+00:00", "data": {"market": "0xbeda18055fdc1f5bce0934e2500ed4ee82745b4c78b109e04e8dcf69f98d5d02", "price_changes": [{"asset_id": "1721314828785517746980964825401510699361790864946226663151397689590042697451", "price": "0.13", "size": "550", "side": "BUY", "hash": "b69f3c7f0d3b8df95104799dce25ecdf06923be5", "best_bid": "0.43", "best_ask": "0.44"}, {"asset_id": "72392264258230870796011784251756958130679822179554057734962978782410770260489", "price": "0.87", "size": "550", "side": "SELL", "hash": "1b04654765bb3ee135d7844de579c4cbd3dc3c16", "best_bid": "0.56", "best_ask": "0.57"}], "timestamp": "1769384542229", "event_type": "price_change"}}
{"_local_timestamp": "2026-01-25T23:42:24.988303+00:00", "data": {"market": "0xbeda18055fdc1f5bce0934e2500ed4ee82745b4c78b109e04e8dcf69f98d5d02", "price_changes": [{"asset_id": "1721314828785517746980964825401510699361790864946226663151397689590042697451", "price": "0.13", "size": "325", "side": "BUY", "hash": "e7616c16b9653000fb209e2f9a7caf0c56397de0", "best_bid": "0.43", "best_ask": "0.44"}, {"asset_id": "72392264258230870796011784251756958130679822179554057734962978782410770260489", "price": "0.87", "size": "325", "side": "SELL", "hash": "de9dcc2ba87d610c01decd03e94dde54a7e1bda0", "best_bid": "0.56", "best_ask": "0.57"}], "timestamp": "1769384544876", "event_type": "price_change"}}
{"_local_timestamp": "2026-01-25T23:42:25.300839+00:00", "data": {"market": "0xbeda18055fdc1f5bce0934e2500ed4ee82745b4c78b109e04e8dcf69f98d5d02", "price_changes": [{"asset_id": "1721314828785517746980964825401510699361790864946226663151397689590042697451", "price": "0.15", "size": "3559", "side": "BUY", "hash": "49f0ea63c0f6e26ae78232bdce1a4e5d267a69ff", "best_bid": "0.43", "best_ask": "0.44"}, {"asset_id": "72392264258230870796011784251756958130679822179554057734962978782410770260489", "price": "0.85", "size": "3559", "side": "SELL", "hash": "fa7cba4ec51ba0ec78ecc7ad01fd9719f52b1783", "best_bid": "0.56", "best_ask": "0.57"}], "timestamp": "1769384545155", "event_type": "price_change"}}
{"_local_timestamp": "2026-01-25T23:43:05.425782+00:00", "data": {"market": "0xbeda18055fdc1f5bce0934e2500ed4ee82745b4c78b109e04e8dcf69f98d5d02", "price_changes": [{"asset_id": "72392264258230870796011784251756958130679822179554057734962978782410770260489", "price": "0.6", "size": "143.63", "side": "SELL", "hash": "14ae1b50179cbeb9b0be80429045f5d50870fdb9", "best_bid": "0.56", "best_ask": "0.57"}, {"asset_id": "1721314828785517746980964825401510699361790864946226663151397689590042697451", "price": "0.4", "size": "143.63", "side": "BUY", "hash": "3eed1319eb449ef075099c3adc4b2feb77334d65", "best_bid": "0.43", "best_ask": "0.44"}], "timestamp": "1769384585321", "event_type": "price_change"}}
{"_local_timestamp": "2026-01-25T23:44:08.601802+00:00", "data": {"market": "0xbeda18055fdc1f5bce0934e2500ed4ee82745b4c78b109e04e8dcf69f98d5d02", "price_changes": [{"asset_id": "1721314828785517746980964825401510699361790864946226663151397689590042697451", "price": "0.13", "size": "200", "side": "BUY", "hash": "904a6da35924e117ef5db18eadf46bc964b20f82", "best_bid": "0.43", "best_ask": "0.44"}, {"asset_id": "72392264258230870796011784251756958130679822179554057734962978782410770260489", "price": "0.87", "size": "200", "side": "SELL", "hash": "361dd37cdc10ddd3ff9b461a7438a296f5e58a6b", "best_bid": "0.56", "best_ask": "0.57"}], "timestamp": "1769384648356", "event_type": "price_change"}}
{"_local_timestamp": "2026-01-25T23:44:09.083071+00:00", "data": {"market": "0xbeda18055fdc1f5bce0934e2500ed4ee82745b4c78b109e04e8dcf69f98d5d02", "price_changes": [{"asset_id": "1721314828785517746980964825401510699361790864946226663151397689590042697451", "price": "0.15", "size": "3684", "side": "BUY", "hash": "d64adf6bf7e52969d159ebcabe995f7c55087f16", "best_bid": "0.43", "best_ask": "0.44"}, {"asset_id": "72392264258230870796011784251756958130679822179554057734962978782410770260489", "price": "0.85", "size": "3684", "side": "SELL", "hash": "6451b3fb66e62d9366f205b06833754c9333ed7e", "best_bid": "0.56", "best_ask": "0.57"}], "timestamp": "1769384648759", "event_type": "price_change"}}
{"_local_timestamp": "2026-01-25T23:44:09.321430+00:00", "data": {"market": "0xbeda18055fdc1f5bce0934e2500ed4ee82745b4c78b109e04e8dcf69f98d5d02", "price_changes": [{"asset_id": "72392264258230870796011784251756958130679822179554057734962978782410770260489", "price": "0.6", "size": "175.63", "side": "SELL", "hash": "d2e1c98a18e67fd73da4932b8d8ba66c5a17f45a", "best_bid": "0.56", "best_ask": "0.57"}, {"asset_id": "1721314828785517746980964825401510699361790864946226663151397689590042697451", "price": "0.4", "size": "175.63", "side": "BUY", "hash": "454c2c18374ce28cabb438db54c7fe08ad165cab", "best_bid": "0.43", "best_ask": "0.44"}], "timestamp": "1769384649178", "event_type": "price_change"}}
{"_local_timestamp": "2026-01-25T23:44:20.768237+00:00", "data": {"market": "0xbeda18055fdc1f5bce0934e2500ed4ee82745b4c78b109e04e8dcf69f98d5d02", "price_changes": [{"asset_id": "1721314828785517746980964825401510699361790864946226663151397689590042697451", "price": "0.13", "size": "0", "side": "BUY", "hash": "95de8c22955cf53f231957f020b105ebfc121c2c", "best_bid": "0.43", "best_ask": "0.44"}, {"asset_id": "72392264258230870796011784251756958130679822179554057734962978782410770260489", "price": "0.87", "size": "0", "side": "SELL", "hash": "866df323f4f6ddbf0d18f689970c039ee0f409cb", "best_bid": "0.56", "best_ask": "0.57"}], "timestamp": "1769384660464", "event_type": "price_change"}}
{"_local_timestamp": "2026-01-25T23:44:21.421960+00:00", "data": {"market": "0xbeda18055fdc1f5bce0934e2500ed4ee82745b4c78b109e04e8dcf69f98d5d02", "price_changes": [{"asset_id": "1721314828785517746980964825401510699361790864946226663151397689590042697451", "price": "0.15", "size": "3884", "side": "BUY", "hash": "7f6e3645c2209e889e403ef26980a58ba8f2eb9e", "best_bid": "0.43", "best_ask": "0.44"}, {"asset_id": "72392264258230870796011784251756958130679822179554057734962978782410770260489", "price": "0.85", "size": "3884", "side": "SELL", "hash": "59f7fd3b5ac60915f4eeda501648abaf3880e71d", "best_bid": "0.56", "best_ask": "0.57"}], "timestamp": "1769384660838", "event_type": "price_change"}}
{"_local_timestamp": "2026-01-25T23:44:55.116975+00:00", "data": {"market": "0xbeda18055fdc1f5bce0934e2500ed4ee82745b4c78b109e04e8dcf69f98d5d02", "price_changes": [{"asset_id": "1721314828785517746980964825401510699361790864946226663151397689590042697451", "price": "0.36", "size": "296.55", "side": "BUY", "hash": "9cccf969ec88fb7b8fc62b8ac1fdaf111eacb749", "best_bid": "0.43", "best_ask": "0.44"}, {"asset_id": "72392264258230870796011784251756958130679822179554057734962978782410770260489", "price": "0.64", "size": "296.55", "side": "SELL", "hash": "f84ee40193e8c399d0d776e6282462b53161f8ce", "best_bid": "0.56", "best_ask": "0.57"}], "timestamp": "1769384695001", "event_type": "price_change"}}
{"_local_timestamp": "2026-01-25T23:44:55.124063+00:00", "data": {"market": "0xbeda18055fdc1f5bce0934e2500ed4ee82745b4c78b109e04e8dcf69f98d5d02", "price_changes": [{"asset_id": "1721314828785517746980964825401510699361790864946226663151397689590042697451", "price": "0.31", "size": "1178", "side": "BUY", "hash": "e1ad723c97728a0a635c8a519daa380c12ed8825", "best_bid": "0.43", "best_ask": "0.44"}, {"asset_id": "72392264258230870796011784251756958130679822179554057734962978782410770260489", "price": "0.69", "size": "1178", "side": "SELL", "hash": "4f35d53e69ca913d5172814390d7d9af8599736c", "best_bid": "0.56", "best_ask": "0.57"}], "timestamp": "1769384695003", "event_type": "price_change"}}
{"_local_timestamp": "2026-01-25T23:45:03.355333+00:00", "data": {"market": "0xbeda18055fdc1f5bce0934e2500ed4ee82745b4c78b109e04e8dcf69f98d5d02", "price_changes": [{"asset_id": "1721314828785517746980964825401510699361790864946226663151397689590042697451", "price": "0.31", "size": "1184", "side": "BUY", "hash": "a83361ba4482778f58f198b757604fcc1eafcca3", "best_bid": "0.43", "best_ask": "0.44"}, {"asset_id": "72392264258230870796011784251756958130679822179554057734962978782410770260489", "price": "0.69", "size": "1184", "side": "SELL", "hash": "41d389aea7c21315ed7d5cd5b07c7006f7303365", "best_bid": "0.56", "best_ask": "0.57"}], "timestamp": "1769384703275", "event_type": "price_change"}}
{"_local_timestamp": "2026-01-25T23:45:03.355962+00:00", "data": {"market": "0xbeda18055fdc1f5bce0934e2500ed4ee82745b4c78b109e04e8dcf69f98d5d02", "price_changes": [{"asset_id": "1721314828785517746980964825401510699361790864946226663151397689590042697451", "price": "0.36", "size": "552.55", "side": "BUY", "hash": "276d20c85ee2949973f6f5b6aea5d415b98e6185", "best_bid": "0.43", "best_ask": "0.44"}, {"asset_id": "72392264258230870796011784251756958130679822179554057734962978782410770260489", "price": "0.64", "size": "552.55", "side": "SELL", "hash": "25d6e4f002b240990a0237915a65672ac1ca39ca", "best_bid": "0.56", "best_ask": "0.57"}], "timestamp": "1769384703276", "event_type": "price_change"}}
{"_local_timestamp": "2026-01-25T23:45:07.080520+00:00", "data": {"market": "0xbeda18055fdc1f5bce0934e2500ed4ee82745b4c78b109e04e8dcf69f98d5d02", "price_changes": [{"asset_id": "1721314828785517746980964825401510699361790864946226663151397689590042697451", "price": "0.31", "size": "70", "side": "BUY", "hash": "89d091737a3905f4ec0a6e7d6381addc1e6c346d", "best_bid": "0.43", "best_ask": "0.44"}, {"asset_id": "72392264258230870796011784251756958130679822179554057734962978782410770260489", "price": "0.69", "size": "70", "side": "SELL", "hash": "58d9cb7382cf001a9993d3d210092300f8d113a5", "best_bid": "0.56", "best_ask": "0.57"}], "timestamp": "1769384707000", "event_type": "price_change"}}
{"_local_timestamp": "2026-01-25T23:45:07.084575+00:00", "data": {"market": "0xbeda18055fdc1f5bce0934e2500ed4ee82745b4c78b109e04e8dcf69f98d5d02", "price_changes": [{"asset_id": "1721314828785517746980964825401510699361790864946226663151397689590042697451", "price": "0.36", "size": "311.55", "side": "BUY", "hash": "927815b46cc382b044df4c9c3c18ce1a10f8f062", "best_bid": "0.43", "best_ask": "0.44"}, {"asset_id": "72392264258230870796011784251756958130679822179554057734962978782410770260489", "price": "0.64", "size": "311.55", "side": "SELL", "hash": "b6e093be22f15a8ba1cc2e63119d1af37fbf3bdf", "best_bid": "0.56", "best_ask": "0.57"}], "timestamp": "1769384707001", "event_type": "price_change"}}
{"_local_timestamp": "2026-01-25T23:45:07.085153+00:00", "data": {"market": "0xbeda18055fdc1f5bce0934e2500ed4ee82745b4c78b109e04e8dcf69f98d5d02", "price_changes": [{"asset_id": "1721314828785517746980964825401510699361790864946226663151397689590042697451", "price": "0.38", "size": "20", "side": "BUY", "hash": "72ba04ff05c19703497957e62dae5ac673e6870c", "best_bid": "0.43", "best_ask": "0.44"}, {"asset_id": "72392264258230870796011784251756958130679822179554057734962978782410770260489", "price": "0.62", "size": "20", "side": "SELL", "hash": "e194796aa8fbf6c31a384d9e1beab40b1ed9c02c", "best_bid": "0.56", "best_ask": "0.57"}], "timestamp": "1769384707002", "event_type": "price_change"}}
{"_local_timestamp": "2026-01-25T23:45:08.603870+00:00", "data": {"market": "0xbeda18055fdc1f5bce0934e2500ed4ee82745b4c78b109e04e8dcf69f98d5d02", "price_changes": [{"asset_id": "1721314828785517746980964825401510699361790864946226663151397689590042697451", "price": "0.43", "size": "773.39", "side": "BUY", "hash": "54403d54551415ad176dc8be2f2c615e9b4567f3", "best_bid": "0.43", "best_ask": "0.44"}, {"asset_id": "72392264258230870796011784251756958130679822179554057734962978782410770260489", "price": "0.57", "size": "773.39", "side": "SELL", "hash": "2ddd579e47002d8f06c805bdcc3cc9c576edc022", "best_bid": "0.56", "best_ask": "0.57"}], "timestamp": "1769384708532", "event_type": "price_change"}}
{"_local_timestamp": "2026-01-25T23:45:08.605147+00:00", "data": {"market": "0xbeda18055fdc1f5bce0934e2500ed4ee82745b4c78b109e04e8dcf69f98d5d02", "asset_id": "1721314828785517746980964825401510699361790864946226663151397689590042697451", "bids": [{"price": "0.01", "size": "8019.73"}, {"price": "0.02", "size": "1750"}, {"price": "0.03", "size": "10.35"}, {"price": "0.04", "size": "3063.93"}, {"price": "0.05", "size": "250"}, {"price": "0.07", "size": "985.71"}, {"price": "0.09", "size": "355.55"}, {"price": "0.1", "size": "2206.91"}, {"price": "0.11", "size": "254.54"}, {"price": "0.14", "size": "3183.71"}, {"price": "0.15", "size": "3884"}, {"price": "0.16", "size": "550"}, {"price": "0.18", "size": "118.08"}, {"price": "0.21", "size": "300"}, {"price": "0.22", "size": "119.6"}, {"price": "0.26", "size": "10"}, {"price": "0.27", "size": "218.86"}, {"price": "0.28", "size": "200"}, {"price": "0.29", "size": "239.57"}, {"price": "0.3", "size": "316.09"}, {"price": "0.31", "size": "70"}, {"price": "0.33", "size": "807"}, {"price": "0.34", "size": "10"}, {"price": "0.35", "size": "244.11"}, {"price": "0.36", "size": "311.55"}, {"price": "0.37", "size": "64.05"}, {"price": "0.38", "size": "20"}, {"price": "0.39", "size": "5327.4"}, {"price": "0.4", "size": "175.63"}, {"price": "0.41", "size": "412.17"}, {"price": "0.42", "size": "253"}, {"price": "0.43", "size": "773.39"}], "asks": [{"price": "0.99", "size": "5610.3"}, {"price": "0.98", "size": "1000"}, {"price": "0.97", "size": "10.65"}, {"price": "0.96", "size": "2750"}, {"price": "0.95", "size": "30"}, {"price": "0.94", "size": "1300"}, {"price": "0.93", "size": "250"}, {"price": "0.92", "size": "425"}, {"price": "0.9", "size": "10"}, {"price": "0.89", "size": "296.15"}, {"price": "0.86", "size": "1892"}, {"price": "0.83", "size": "152.94"}, {"price": "0.82", "size": "2782"}, {"price": "0.81", "size": "200"}, {"price": "0.8", "size": "120"}, {"price": "0.78", "size": "290.9"}, {"price": "0.74", "size": "150"}, {"price": "0.72", "size": "5"}, {"price": "0.55", "size": "50"}, {"price": "0.52", "size": "27.08"}, {"price": "0.5", "size": "26.76"}, {"price": "0.49", "size": "105"}, {"price": "0.48", "size": "50.64"}, {"price": "0.47", "size": "2098.01"}, {"price": "0.46", "size": "1171.25"}, {"price": "0.45", "size": "6632.9"}, {"price": "0.44", "size": "453.08"}], "hash": "54403d54551415ad176dc8be2f2c615e9b4567f3", "timestamp": "1769384708532", "event_type": "book"}}
{"_local_timestamp": "2026-01-25T23:45:08.605920+00:00", "data": {"market": "0xbeda18055fdc1f5bce0934e2500ed4ee82745b4c78b109e04e8dcf69f98d5d02", "asset_id": "72392264258230870796011784251756958130679822179554057734962978782410770260489", "bids": [{"price": "0.01", "size": "5610.3"}, {"price": "0.02", "size": "1000"}, {"price": "0.03", "size": "10.65"}, {"price": "0.04", "size": "2750"}, {"price": "0.05", "size": "30"}, {"price": "0.06", "size": "1300"}, {"price": "0.07", "size": "250"}, {"price": "0.08", "size": "425"}, {"price": "0.1", "size": "10"}, {"price": "0.11", "size": "296.15"}, {"price": "0.14", "size": "1892"}, {"price": "0.17", "size": "152.94"}, {"price": "0.18", "size": "2782"}, {"price": "0.19", "size": "200"}, {"price": "0.2", "size": "120"}, {"price": "0.22", "size": "290.9"}, {"price": "0.26", "size": "150"}, {"price": "0.28", "size": "5"}, {"price": "0.45", "size": "50"}, {"price": "0.48", "size": "27.08"}, {"price": "0.5", "size": "26.76"}, {"price": "0.51", "size": "105"}, {"price": "0.52", "size": "50.64"}, {"price": "0.53", "size": "2098.01"}, {"price": "0.54", "size": "1171.25"}, {"price": "0.55", "size": "6632.9"}, {"price": "0.56", "size": "453.08"}], "asks": [{"price": "0.99", "size": "8019.73"}, {"price": "0.98", "size": "1750"}, {"price": "0.97", "size": "10.35"}, {"price": "0.96", "size": "3063.93"}, {"price": "0.95", "size": "250"}, {"price": "0.93", "size": "985.71"}, {"price": "0.91", "size": "355.55"}, {"price": "0.9", "size": "2206.91"}, {"price": "0.89", "size": "254.54"}, {"price": "0.86", "size": "3183.71"}, {"price": "0.85", "size": "3884"}, {"price": "0.84", "size": "550"}, {"price": "0.82", "size": "118.08"}, {"price": "0.79", "size": "300"}, {"price": "0.78", "size": "119.6"}, {"price": "0.74", "size": "10"}, {"price": "0.73", "size": "218.86"}, {"price": "0.72", "size": "200"}, {"price": "0.71", "size": "239.57"}, {"price": "0.7", "size": "316.09"}, {"price": "0.69", "size": "70"}, {"price": "0.67", "size": "807"}, {"price": "0.66", "size": "10"}, {"price": "0.65", "size": "244.11"}, {"price": "0.64", "size": "311.55"}, {"price": "0.63", "size": "64.05"}, {"price": "0.62", "size": "20"}, {"price": "0.61", "size": "5327.4"}, {"price": "0.6", "size": "175.63"}, {"price": "0.59", "size": "412.17"}, {"price": "0.58", "size": "253"}, {"price": "0.57", "size": "773.39"}], "hash": "2ddd579e47002d8f06c805bdcc3cc9c576edc022", "timestamp": "1769384708532", "event_type": "book"}}
{"_local_timestamp": "2026-01-25T23:45:08.627639+00:00", "data": {"market": "0xbeda18055fdc1f5bce0934e2500ed4ee82745b4c78b109e04e8dcf69f98d5d02", "asset_id": "72392264258230870796011784251756958130679822179554057734962978782410770260489", "price": "0.57", "size": "1.754383", "fee_rate_bps": "0", "side": "BUY", "timestamp": "1769384708561", "event_type": "last_trade_price", "transaction_hash": "0x5b07d23dee58ba86edf0932de96d91f93ff8c6ef809b89102ed40f774900e48a"}}
{"_local_timestamp": "2026-01-25T23:45:28.263136+00:00", "data": {"market": "0xbeda18055fdc1f5bce0934e2500ed4ee82745b4c78b109e04e8dcf69f98d5d02", "price_changes": [{"asset_id": "72392264258230870796011784251756958130679822179554057734962978782410770260489", "price": "0.6", "size": "143.63", "side": "SELL", "hash": "3bc8ccbcce1c4a23df1f465cec5ffdfb7a0877fe", "best_bid": "0.56", "best_ask": "0.57"}, {"asset_id": "1721314828785517746980964825401510699361790864946226663151397689590042697451", "price": "0.4", "size": "143.63", "side": "BUY", "hash": "6a027683c7ea410e7df8a5444e424c60555ffde8", "best_bid": "0.43", "best_ask": "0.44"}], "timestamp": "1769384728190", "event_type": "price_change"}}
{"_local_timestamp": "2026-01-25T23:46:01.111228+00:00", "data": {"market": "0xbeda18055fdc1f5bce0934e2500ed4ee82745b4c78b109e04e8dcf69f98d5d02", "price_changes": [{"asset_id": "1721314828785517746980964825401510699361790864946226663151397689590042697451", "price": "0.38", "size": "263", "side": "BUY", "hash": "44a7564643c903a5de48cf82ec11cc60ae48529d", "best_bid": "0.43", "best_ask": "0.44"}, {"asset_id": "72392264258230870796011784251756958130679822179554057734962978782410770260489", "price": "0.62", "size": "263", "side": "SELL", "hash": "9c67651eb46e4645b0bb4015a1fb2e1d415f8914", "best_bid": "0.56", "best_ask": "0.57"}], "timestamp": "1769384761033", "event_type": "price_change"}}
{"_local_timestamp": "2026-01-25T23:46:01.111782+00:00", "data": {"market": "0xbeda18055fdc1f5bce0934e2500ed4ee82745b4c78b109e04e8dcf69f98d5d02", "price_changes": [{"asset_id": "1721314828785517746980964825401510699361790864946226663151397689590042697451", "price": "0.31", "size": "1184", "side": "BUY", "hash": "11703bff40010f2d475f30e23c15cf7c5a241673", "best_bid": "0.43", "best_ask": "0.44"}, {"asset_id": "72392264258230870796011784251756958130679822179554057734962978782410770260489", "price": "0.69", "size": "1184", "side": "SELL", "hash": "bfaf828b6f1f459981e68190988c725216a81402", "best_bid": "0.56", "best_ask": "0.57"}], "timestamp": "1769384761034", "event_type": "price_change"}}
{"_local_timestamp": "2026-01-25T23:46:01.112268+00:00", "data": {"market": "0xbeda18055fdc1f5bce0934e2500ed4ee82745b4c78b109e04e8dcf69f98d5d02", "price_changes": [{"asset_id": "1721314828785517746980964825401510699361790864946226663151397689590042697451", "price": "0.36", "size": "552.55", "side": "BUY", "hash": "1c9b8b970d4030fd149d04bc8c346c0d36ef2f7f", "best_bid": "0.43", "best_ask": "0.44"}, {"asset_id": "72392264258230870796011784251756958130679822179554057734962978782410770260489", "price": "0.64", "size": "552.55", "side": "SELL", "hash": "bacb9b6760ca17eb1c78cbde8561a7db032f52f0", "best_bid": "0.56", "best_ask": "0.57"}], "timestamp": "1769384761034", "event_type": "price_change"}}
{"_local_timestamp": "2026-01-25T23:46:10.581143+00:00", "data": {"market": "0xbeda18055fdc1f5bce0934e2500ed4ee82745b4c78b109e04e8dcf69f98d5d02", "price_changes": [{"asset_id": "1721314828785517746980964825401510699361790864946226663151397689590042697451", "price": "0.14", "size": "185.71", "side": "BUY", "hash": "0db9e22cea7fcb3ea2b8cfd3cc6f404966ecb595", "best_bid": "0.43", "best_ask": "0.44"}, {"asset_id": "72392264258230870796011784251756958130679822179554057734962978782410770260489", "price": "0.86", "size": "185.71", "side": "SELL", "hash": "150e64d4a4c077b80c63d80ac871da82dbb2a600", "best_bid": "0.56", "best_ask": "0.57"}], "timestamp": "1769384770464", "event_type": "price_change"}}
{"_local_timestamp": "2026-01-25T23:46:19.135795+00:00", "data": {"market": "0xbeda18055fdc1f5bce0934e2500ed4ee82745b4c78b109e04e8dcf69f98d5d02", "price_changes": [{"asset_id": "1721314828785517746980964825401510699361790864946226663151397689590042697451", "price": "0.15", "size": "550", "side": "BUY", "hash": "1f84e64099a98a09e7a193757f8b1ee0b602168e", "best_bid": "0.43", "best_ask": "0.44"}, {"asset_id": "72392264258230870796011784251756958130679822179554057734962978782410770260489", "price": "0.85", "size": "550", "side": "SELL", "hash": "66c1e577941fa8ea60d1ea009d5a367c6bf4034c", "best_bid": "0.56", "best_ask": "0.57"}], "timestamp": "1769384779071", "event_type": "price_change"}}
{"_local_timestamp": "2026-01-25T23:46:19.152939+00:00", "data": {"market": "0xbeda18055fdc1f5bce0934e2500ed4ee82745b4c78b109e04e8dcf69f98d5d02", "price_changes": [{"asset_id": "1721314828785517746980964825401510699361790864946226663151397689590042697451", "price": "0.11", "size": "4800.54", "side": "BUY", "hash": "e13941c99821f0f5d228afe7aca41d4b47c370f6", "best_bid": "0.43", "best_ask": "0.44"}, {"asset_id": "72392264258230870796011784251756958130679822179554057734962978782410770260489", "price": "0.89", "size": "4800.54", "side": "SELL", "hash": "9475ab0eef44eb68e3a1935d79f352adb3e5b020", "best_bid": "0.56", "best_ask": "0.57"}], "timestamp": "1769384779082", "event_type": "price_change"}}
{"_local_timestamp": "2026-01-25T23:46:28.013445+00:00", "data": {"market": "0xbeda18055fdc1f5bce0934e2500ed4ee82745b4c78b109e04e8dcf69f98d5d02", "price_changes": [{"asset_id": "72392264258230870796011784251756958130679822179554057734962978782410770260489", "price": "0.6", "size": "175.63", "side": "SELL", "hash": "d871ea01c91a905df0ddc3b40eb71164d7c422cc", "best_bid": "0.56", "best_ask": "0.57"}, {"asset_id": "1721314828785517746980964825401510699361790864946226663151397689590042697451", "price": "0.4", "size": "175.63", "side": "BUY", "hash": "863e4f9e2bb80bef5d3e144d1c2a651e54121902", "best_bid": "0.43", "best_ask": "0.44"}], "timestamp": "1769384787933", "event_type": "price_change"}}
{"_local_timestamp": "2026-01-25T23:46:30.960408+00:00", "data": {"market": "0xbeda18055fdc1f5bce0934e2500ed4ee82745b4c78b109e04e8dcf69f98d5d02", "price_changes": [{"asset_id": "1721314828785517746980964825401510699361790864946226663151397689590042697451", "price": "0.12", "size": "3500", "side": "BUY", "hash": "8a8f028ec8ea19ff656784f3ac6c665e481a3ef6", "best_bid": "0.43", "best_ask": "0.44"}, {"asset_id": "72392264258230870796011784251756958130679822179554057734962978782410770260489", "price": "0.88", "size": "3500", "side": "SELL", "hash": "191dfbfded5e4670c459b471728f0e2f34c089ae", "best_bid": "0.56", "best_ask": "0.57"}], "timestamp": "1769384790883", "event_type": "price_change"}}
{"_local_timestamp": "2026-01-25T23:46:34.695603+00:00", "data": {"market": "0xbeda18055fdc1f5bce0934e2500ed4ee82745b4c78b109e04e8dcf69f98d5d02", "price_changes": [{"asset_id": "1721314828785517746980964825401510699361790864946226663151397689590042697451", "price": "0.11", "size": "254.54", "side": "BUY", "hash": "8d210ba2db3b811d433a8865443d0061402cd449", "best_bid": "0.43", "best_ask": "0.44"}, {"asset_id": "72392264258230870796011784251756958130679822179554057734962978782410770260489", "price": "0.89", "size": "254.54", "side": "SELL", "hash": "3a62195076359c5fd5147a607f7ca37050bda7f9", "best_bid": "0.56", "best_ask": "0.57"}], "timestamp": "1769384794611", "event_type": "price_change"}}
{"_local_timestamp": "2026-01-25T23:46:34.699924+00:00", "data": {"market": "0xbeda18055fdc1f5bce0934e2500ed4ee82745b4c78b109e04e8dcf69f98d5d02", "price_changes": [{"asset_id": "1721314828785517746980964825401510699361790864946226663151397689590042697451", "price": "0.13", "size": "3847", "side": "BUY", "hash": "10c7e1fe0050665e03caf233401b01322f00d9d6", "best_bid": "0.43", "best_ask": "0.44"}, {"asset_id": "72392264258230870796011784251756958130679822179554057734962978782410770260489", "price": "0.87", "size": "3847", "side": "SELL", "hash": "e3f2d626c22d1399a967939c32fa846dc2cc7630", "best_bid": "0.56", "best_ask": "0.57"}], "timestamp": "1769384794624", "event_type": "price_change"}}
{"_local_timestamp": "2026-01-25T23:46:44.098866+00:00", "data": {"market": "0xbeda18055fdc1f5bce0934e2500ed4ee82745b4c78b109e04e8dcf69f98d5d02", "price_changes": [{"asset_id": "1721314828785517746980964825401510699361790864946226663151397689590042697451", "price": "0.31", "size": "1139", "side": "BUY", "hash": "e074e56c27d7716c21bd8e058865ddf34aa3d572", "best_bid": "0.43", "best_ask": "0.44"}, {"asset_id": "72392264258230870796011784251756958130679822179554057734962978782410770260489", "price": "0.69", "size": "1139", "side": "SELL", "hash": "a29dbf5d304a6225167c8a1312229ce795b4aa74", "best_bid": "0.56", "best_ask": "0.57"}], "timestamp": "1769384804006", "event_type": "price_change"}}
{"_local_timestamp": "2026-01-25T23:46:44.101114+00:00", "data": {"market": "0xbeda18055fdc1f5bce0934e2500ed4ee82745b4c78b109e04e8dcf69f98d5d02", "price_changes": [{"asset_id": "1721314828785517746980964825401510699361790864946226663151397689590042697451", "price": "0.36", "size": "546.55", "side": "BUY", "hash": "9010606a390756b92b9b10359e197f7479d3f01b", "best_bid": "0.43", "best_ask": "0.44"}, {"asset_id": "72392264258230870796011784251756958130679822179554057734962978782410770260489", "price": "0.64", "size": "546.55", "side": "SELL", "hash": "635eacdf45ee45dcfacba7c5bc5a9b7409e01dc0", "best_bid": "0.56", "best_ask": "0.57"}], "timestamp": "1769384804007", "event_type": "price_change"}}
{"_local_timestamp": "2026-01-25T23:46:47.429669+00:00", "data": {"market": "0xbeda18055fdc1f5bce0934e2500ed4ee82745b4c78b109e04e8dcf69f98d5d02", "price_changes": [{"asset_id": "1721314828785517746980964825401510699361790864946226663151397689590042697451", "price": "0.36", "size": "552.55", "side": "BUY", "hash": "569eaf5b36206f158a0f44b48601bddde7e05058", "best_bid": "0.43", "best_ask": "0.44"}, {"asset_id": "72392264258230870796011784251756958130679822179554057734962978782410770260489", "price": "0.64", "size": "552.55", "side": "SELL", "hash": "bb90ffacf53ee9eabc4f1cda91041900cc878cbc", "best_bid": "0.56", "best_ask": "0.57"}], "timestamp": "1769384807348", "event_type": "price_change"}}
{"_local_timestamp": "2026-01-25T23:46:47.430259+00:00", "data": {"market": "0xbeda18055fdc1f5bce0934e2500ed4ee82745b4c78b109e04e8dcf69f98d5d02", "price_changes": [{"asset_id": "1721314828785517746980964825401510699361790864946226663151397689590042697451", "price": "0.31", "size": "1184", "side": "BUY", "hash": "d536241cea9c55c915c4b963b619e19c4f21e1af", "best_bid": "0.43", "best_ask": "0.44"}, {"asset_id": "72392264258230870796011784251756958130679822179554057734962978782410770260489", "price": "0.69", "size": "1184", "side": "SELL", "hash": "14de20f2433046cc8aac2f25c4e455db376aab46", "best_bid": "0.56", "best_ask": "0.57"}], "timestamp": "1769384807349", "event_type": "price_change"}}
{"_local_timestamp": "2026-01-25T23:46:58.772300+00:00", "data": {"market": "0xbeda18055fdc1f5bce0934e2500ed4ee82745b4c78b109e04e8dcf69f98d5d02", "price_changes": [{"asset_id": "1721314828785517746980964825401510699361790864946226663151397689590042697451", "price": "0.11", "size": "304.54", "side": "BUY", "hash": "19e19787621a6fde6d8584b8bc86501b83ed8b35", "best_bid": "0.43", "best_ask": "0.44"}, {"asset_id": "72392264258230870796011784251756958130679822179554057734962978782410770260489", "price": "0.89", "size": "304.54", "side": "SELL", "hash": "ba8a0636b7d56d41711ea556bcc28f6c4fc6b96e", "best_bid": "0.56", "best_ask": "0.57"}], "timestamp": "1769384818683", "event_type": "price_change"}}
{"_local_timestamp": "2026-01-25T23:46:58.964889+00:00", "data": {"market": "0xbeda18055fdc1f5bce0934e2500ed4ee82745b4c78b109e04e8dcf69f98d5d02", "price_changes": [{"asset_id": "1721314828785517746980964825401510699361790864946226663151397689590042697451", "price": "0.15", "size": "325", "side": "BUY", "hash": "7ebd06ee08b0e063550676fb98feade2d7505d8e", "best_bid": "0.43", "best_ask": "0.44"}, {"asset_id": "72392264258230870796011784251756958130679822179554057734962978782410770260489", "price": "0.85", "size": "325", "side": "SELL", "hash": "4b848607517dc248c84d3a98e7667f1c03f0f502", "best_bid": "0.56", "best_ask": "0.57"}], "timestamp": "1769384818859", "event_type": "price_change"}}
{"_local_timestamp": "2026-01-25T23:46:59.285525+00:00", "data": {"market": "0xbeda18055fdc1f5bce0934e2500ed4ee82745b4c78b109e04e8dcf69f98d5d02", "price_changes": [{"asset_id": "1721314828785517746980964825401510699361790864946226663151397689590042697451", "price": "0.11", "size": "529.54", "side": "BUY", "hash": "974f4854cb69cd9067fa4960a00b15b569196b8e", "best_bid": "0.43", "best_ask": "0.44"}, {"asset_id": "72392264258230870796011784251756958130679822179554057734962978782410770260489", "price": "0.89", "size": "529.54", "side": "SELL", "hash": "8cdcb0d1dd04d315749dc2eb40f0f4affa0735c1", "best_bid": "0.56", "best_ask": "0.57"}], "timestamp": "1769384819147", "event_type": "price_change"}}
{"_local_timestamp": "2026-01-25T23:47:37.451501+00:00", "data": {"market": "0xbeda18055fdc1f5bce0934e2500ed4ee82745b4c78b109e04e8dcf69f98d5d02", "price_changes": [{"asset_id": "1721314828785517746980964825401510699361790864946226663151397689590042697451", "price": "0.11", "size": "304.54", "side": "BUY", "hash": "66515f94e66fcdab7d9b95b7ca7fd4bc5ba1a1d6", "best_bid": "0.43", "best_ask": "0.44"}, {"asset_id": "72392264258230870796011784251756958130679822179554057734962978782410770260489", "price": "0.89", "size": "304.54", "side": "SELL", "hash": "49753910e48f87aa416adf907eef4a21bf2aff09", "best_bid": "0.56", "best_ask": "0.57"}], "timestamp": "1769384857316", "event_type": "price_change"}}
{"_local_timestamp": "2026-01-25T23:47:37.948762+00:00", "data": {"market": "0xbeda18055fdc1f5bce0934e2500ed4ee82745b4c78b109e04e8dcf69f98d5d02", "price_changes": [{"asset_id": "1721314828785517746980964825401510699361790864946226663151397689590042697451", "price": "0.13", "size": "4072", "side": "BUY", "hash": "ce5eb8d59e175ad92221596ffe3a554ba9fa1596", "best_bid": "0.43", "best_ask": "0.44"}, {"asset_id": "72392264258230870796011784251756958130679822179554057734962978782410770260489", "price": "0.87", "size": "4072", "side": "SELL", "hash": "460041b2ae123f724e50b4cd285294cb126e80f3", "best_bid": "0.56", "best_ask": "0.57"}], "timestamp": "1769384857605", "event_type": "price_change"}}
{"_local_timestamp": "2026-01-25T23:47:45.618173+00:00", "data": {"market": "0xbeda18055fdc1f5bce0934e2500ed4ee82745b4c78b109e04e8dcf69f98d5d02", "price_changes": [{"asset_id": "1721314828785517746980964825401510699361790864946226663151397689590042697451", "price": "0.11", "size": "254.54", "side": "BUY", "hash": "a9a72fe51d4a8c4465740370fde85672097a012a", "best_bid": "0.43", "best_ask": "0.44"}, {"asset_id": "72392264258230870796011784251756958130679822179554057734962978782410770260489", "price": "0.89", "size": "254.54", "side": "SELL", "hash": "ef27a269cdf758191959e0ef2366db748f17cdbd", "best_bid": "0.56", "best_ask": "0.57"}], "timestamp": "1769384865517", "event_type": "price_change"}}
{"_local_timestamp": "2026-01-25T23:47:45.935644+00:00", "data": {"market": "0xbeda18055fdc1f5bce0934e2500ed4ee82745b4c78b109e04e8dcf69f98d5d02", "price_changes": [{"asset_id": "1721314828785517746980964825401510699361790864946226663151397689590042697451", "price": "0.13", "size": "4122", "side": "BUY", "hash": "501b6e2c3820e42dfdffa18b5d1ffc32ecc7dcdc", "best_bid": "0.43", "best_ask": "0.44"}, {"asset_id": "72392264258230870796011784251756958130679822179554057734962978782410770260489", "price": "0.87", "size": "4122", "side": "SELL", "hash": "b6e18010ae3d5ea3fcba8e0b848696d34f936318", "best_bid": "0.56", "best_ask": "0.57"}], "timestamp": "1769384865837", "event_type": "price_change"}}
{"_local_timestamp": "2026-01-25T23:47:55.533962+00:00", "data": {"market": "0xbeda18055fdc1f5bce0934e2500ed4ee82745b4c78b109e04e8dcf69f98d5d02", "price_changes": [{"asset_id": "1721314828785517746980964825401510699361790864946226663151397689590042697451", "price": "0.12", "size": "0", "side": "BUY", "hash": "67ebd7a75341df911b5403d4e3860cbe4d05982d", "best_bid": "0.43", "best_ask": "0.44"}, {"asset_id": "72392264258230870796011784251756958130679822179554057734962978782410770260489", "price": "0.88", "size": "0", "side": "SELL", "hash": "503955310c4e2c7a72391183adc9d981fc6698d9", "best_bid": "0.56", "best_ask": "0.57"}], "timestamp": "1769384875410", "event_type": "price_change"}}
{"_local_timestamp": "2026-01-25T23:48:50.877234+00:00", "data": {"market": "0xbeda18055fdc1f5bce0934e2500ed4ee82745b4c78b109e04e8dcf69f98d5d02", "price_changes": [{"asset_id": "72392264258230870796011784251756958130679822179554057734962978782410770260489", "price": "0.55", "size": "6869.26", "side": "BUY", "hash": "2404ac41bf1f5c54397c9e9c4af47a3d75e91f93", "best_bid": "0.56", "best_ask": "0.57"}, {"asset_id": "1721314828785517746980964825401510699361790864946226663151397689590042697451", "price": "0.45", "size": "6869.26", "side": "SELL", "hash": "e7de7d0468b0a84cb28ce6df6088279a5bf4108f", "best_bid": "0.43", "best_ask": "0.44"}], "timestamp": "1769384930808", "event_type": "price_change"}}
{"_local_timestamp": "2026-01-25T23:49:01.296416+00:00", "data": {"market": "0xbeda18055fdc1f5bce0934e2500ed4ee82745b4c78b109e04e8dcf69f98d5d02", "price_changes": [{"asset_id": "72392264258230870796011784251756958130679822179554057734962978782410770260489", "price": "0.6", "size": "143.63", "side": "SELL", "hash": "3fd610e3ba895e7c2a5ced766ebb4280aba57db2", "best_bid": "0.56", "best_ask": "0.57"}, {"asset_id": "1721314828785517746980964825401510699361790864946226663151397689590042697451", "price": "0.4", "size": "143.63", "side": "BUY", "hash": "7447fee94f9f26fff508e630e6ca29f2f3559a42", "best_bid": "0.43", "best_ask": "0.44"}], "timestamp": "1769384941222", "event_type": "price_change"}}
{"_local_timestamp": "2026-01-25T23:49:05.300356+00:00", "data": {"market": "0xbeda18055fdc1f5bce0934e2500ed4ee82745b4c78b109e04e8dcf69f98d5d02", "price_changes": [{"asset_id": "1721314828785517746980964825401510699361790864946226663151397689590042697451", "price": "0.13", "size": "275", "side": "BUY", "hash": "61b26a6b4fff2e0fd25aeb642ca012466c825ac2", "best_bid": "0.43", "best_ask": "0.44"}, {"asset_id": "72392264258230870796011784251756958130679822179554057734962978782410770260489", "price": "0.87", "size": "275", "side": "SELL", "hash": "3bff1e5e12efd827f52554c1e617e191dbde654b", "best_bid": "0.56", "best_ask": "0.57"}], "timestamp": "1769384945231", "event_type": "price_change"}}
{"_local_timestamp": "2026-01-25T23:49:05.311891+00:00", "data": {"market": "0xbeda18055fdc1f5bce0934e2500ed4ee82745b4c78b109e04e8dcf69f98d5d02", "price_changes": [{"asset_id": "1721314828785517746980964825401510699361790864946226663151397689590042697451", "price": "0.11", "size": "4800.54", "side": "BUY", "hash": "59fdd2460def435d1ee39b6cbc47c870728b09b8", "best_bid": "0.43", "best_ask": "0.44"}, {"asset_id": "72392264258230870796011784251756958130679822179554057734962978782410770260489", "price": "0.89", "size": "4800.54", "side": "SELL", "hash": "ebdaf6b0d1552c0e6bafd5d1ee4c3c2e746677ba", "best_bid": "0.56", "best_ask": "0.57"}], "timestamp": "1769384945244", "event_type": "price_change"}}
{"_local_timestamp": "2026-01-25T23:49:05.332775+00:00", "data": {"market": "0xbeda18055fdc1f5bce0934e2500ed4ee82745b4c78b109e04e8dcf69f98d5d02", "price_changes": [{"asset_id": "72392264258230870796011784251756958130679822179554057734962978782410770260489", "price": "0.55", "size": "6632.9", "side": "BUY", "hash": "2fc3a06a695adc0113672301e1a7edc4fc380ada", "best_bid": "0.56", "best_ask": "0.57"}, {"asset_id": "1721314828785517746980964825401510699361790864946226663151397689590042697451", "price": "0.45", "size": "6632.9", "side": "SELL", "hash": "482d8b2b10d19d767559675155cea385413c25c4", "best_bid": "0.43", "best_ask": "0.44"}], "timestamp": "1769384945262", "event_type": "price_change"}}
{"_local_timestamp": "2026-01-25T23:49:20.487644+00:00", "data": {"market": "0xbeda18055fdc1f5bce0934e2500ed4ee82745b4c78b109e04e8dcf69f98d5d02", "price_changes": [{"asset_id": "1721314828785517746980964825401510699361790864946226663151397689590042697451", "price": "0.14", "size": "3183.71", "side": "BUY", "hash": "20270b7d0bd9b02a2777392f68f5f4c44fe9fb5f", "best_bid": "0.43", "best_ask": "0.44"}, {"asset_id": "72392264258230870796011784251756958130679822179554057734962978782410770260489", "price": "0.86", "size": "3183.71", "side": "SELL", "hash": "4647d834f3b2161bfdda1cd89218b01046df3577", "best_bid": "0.56", "best_ask": "0.57"}], "timestamp": "1769384960410", "event_type": "price_change"}}
{"_local_timestamp": "2026-01-25T23:49:22.390416+00:00", "data": {"market": "0xbeda18055fdc1f5bce0934e2500ed4ee82745b4c78b109e04e8dcf69f98d5d02", "price_changes": [{"asset_id": "1721314828785517746980964825401510699361790864946226663151397689590042697451", "price": "0.11", "size": "254.54", "side": "BUY", "hash": "69cb0a0224d15abb058acb1f32e10d256fb0c65c", "best_bid": "0.43", "best_ask": "0.44"}, {"asset_id": "72392264258230870796011784251756958130679822179554057734962978782410770260489", "price": "0.89", "size": "254.54", "side": "SELL", "hash": "f1c611d079172ea36bd6d8e78bd129888d8879f1", "best_bid": "0.56", "best_ask": "0.57"}], "timestamp": "1769384962312", "event_type": "price_change"}}
{"_local_timestamp": "2026-01-25T23:49:22.401767+00:00", "data": {"market": "0xbeda18055fdc1f5bce0934e2500ed4ee82745b4c78b109e04e8dcf69f98d5d02", "price_changes": [{"asset_id": "1721314828785517746980964825401510699361790864946226663151397689590042697451", "price": "0.15", "size": "3659", "side": "BUY", "hash": "e18673c2a682df824440ec5257bd11b20fd30d91", "best_bid": "0.43", "best_ask": "0.44"}, {"asset_id": "72392264258230870796011784251756958130679822179554057734962978782410770260489", "price": "0.85", "size": "3659", "side": "SELL", "hash": "bf00af72ab6af950959b88db0f6f8613ff10c906", "best_bid": "0.56", "best_ask": "0.57"}], "timestamp": "1769384962332", "event_type": "price_change"}}
{"_local_timestamp": "2026-01-25T23:49:25.419867+00:00", "data": {"market": "0xbeda18055fdc1f5bce0934e2500ed4ee82745b4c78b109e04e8dcf69f98d5d02", "price_changes": [{"asset_id": "1721314828785517746980964825401510699361790864946226663151397689590042697451", "price": "0.15", "size": "3534", "side": "BUY", "hash": "338aaaa72038d20378422fbfadcd950c6c7baae0", "best_bid": "0.43", "best_ask": "0.44"}, {"asset_id": "72392264258230870796011784251756958130679822179554057734962978782410770260489", "price": "0.85", "size": "3534", "side": "SELL", "hash": "3c727e6c773943dfeea41450838e05d5d27d5b59", "best_bid": "0.56", "best_ask": "0.57"}], "timestamp": "1769384965276", "event_type": "price_change"}}
{"_local_timestamp": "2026-01-25T23:49:26.072363+00:00", "data": {"market": "0xbeda18055fdc1f5bce0934e2500ed4ee82745b4c78b109e04e8dcf69f98d5d02", "price_changes": [{"asset_id": "1721314828785517746980964825401510699361790864946226663151397689590042697451", "price": "0.13", "size": "400", "side": "BUY", "hash": "da4ea9137a509c2c5e810b4259687baa716b7a82", "best_bid": "0.43", "best_ask": "0.44"}, {"asset_id": "72392264258230870796011784251756958130679822179554057734962978782410770260489", "price": "0.87", "size": "400", "side": "SELL", "hash": "992c7cf409a59135440484c8469f40803ccec615", "best_bid": "0.56", "best_ask": "0.57"}], "timestamp": "1769384965826", "event_type": "price_change"}}
{"_local_timestamp": "2026-01-25T23:49:30.322371+00:00", "data": {"market": "0xbeda18055fdc1f5bce0934e2500ed4ee82745b4c78b109e04e8dcf69f98d5d02", "price_changes": [{"asset_id": "1721314828785517746980964825401510699361790864946226663151397689590042697451", "price": "0.15", "size": "3334", "side": "BUY", "hash": "bd257c39c270ccd12b5f8aa00e8159d7c1a2d74f", "best_bid": "0.43", "best_ask": "0.44"}, {"asset_id": "72392264258230870796011784251756958130679822179554057734962978782410770260489", "price": "0.85", "size": "3334", "side": "SELL", "hash": "d335a3e90c4562c725bbccdd1370e17967c6613e", "best_bid": "0.56", "best_ask": "0.57"}], "timestamp": "1769384970047", "event_type": "price_change"}}
{"_local_timestamp": "2026-01-25T23:49:31.144349+00:00", "data": {"market": "0xbeda18055fdc1f5bce0934e2500ed4ee82745b4c78b109e04e8dcf69f98d5d02", "price_changes": [{"asset_id": "1721314828785517746980964825401510699361790864946226663151397689590042697451", "price": "0.13", "size": "600", "side": "BUY", "hash": "2c4e66828a18af33678536603273ae0e5cf5170d", "best_bid": "0.43", "best_ask": "0.44"}, {"asset_id": "72392264258230870796011784251756958130679822179554057734962978782410770260489", "price": "0.87", "size": "600", "side": "SELL", "hash": "b3cc02e6c714d58e82ab6f18620c156992229042", "best_bid": "0.56", "best_ask": "0.57"}], "timestamp": "1769384970740", "event_type": "price_change"}}
{"_local_timestamp": "2026-01-25T23:49:50.721560+00:00", "data": {"market": "0xbeda18055fdc1f5bce0934e2500ed4ee82745b4c78b109e04e8dcf69f98d5d02", "price_changes": [{"asset_id": "1721314828785517746980964825401510699361790864946226663151397689590042697451", "price": "0.13", "size": "550", "side": "BUY", "hash": "541dfc61635e5b2d2201b5041cc53b22e599817d", "best_bid": "0.43", "best_ask": "0.44"}, {"asset_id": "72392264258230870796011784251756958130679822179554057734962978782410770260489", "price": "0.87", "size": "550", "side": "SELL", "hash": "6c95a293dcd1f2289bd7a73fad16ac7bc32c390c", "best_bid": "0.56", "best_ask": "0.57"}], "timestamp": "1769384990642", "event_type": "price_change"}}
{"_local_timestamp": "2026-01-25T23:49:50.981883+00:00", "data": {"market": "0xbeda18055fdc1f5bce0934e2500ed4ee82745b4c78b109e04e8dcf69f98d5d02", "price_changes": [{"asset_id": "1721314828785517746980964825401510699361790864946226663151397689590042697451", "price": "0.11", "size": "304.54", "side": "BUY", "hash": "aa7003aa89dbf97b06d47c7ce448e470d1c07e70", "best_bid": "0.43", "best_ask": "0.44"}, {"asset_id": "72392264258230870796011784251756958130679822179554057734962978782410770260489", "price": "0.89", "size": "304.54", "side": "SELL", "hash": "7bfd8833758030db9e2d615ca5264d230d40cdf3", "best_bid": "0.56", "best_ask": "0.57"}], "timestamp": "1769384990901", "event_type": "price_change"}}
{"_local_timestamp": "2026-01-25T23:50:02.417522+00:00", "data": {"market": "0xbeda18055fdc1f5bce0934e2500ed4ee82745b4c78b109e04e8dcf69f98d5d02", "price_changes": [{"asset_id": "1721314828785517746980964825401510699361790864946226663151397689590042697451", "price": "0.1", "size": "606.91", "side": "BUY", "hash": "0c8f4f3b437ee434d96cb24277408f95311d81d1", "best_bid": "0.43", "best_ask": "0.44"}, {"asset_id": "72392264258230870796011784251756958130679822179554057734962978782410770260489", "price": "0.9", "size": "606.91", "side": "SELL", "hash": "60655eae5af5bc51680b9fc99349f9ed276c5286", "best_bid": "0.56", "best_ask": "0.57"}], "timestamp": "1769385002274", "event_type": "price_change"}}
{"_local_timestamp": "2026-01-25T23:50:02.578994+00:00", "data": {"market": "0xbeda18055fdc1f5bce0934e2500ed4ee82745b4c78b109e04e8dcf69f98d5d02", "price_changes": [{"asset_id": "72392264258230870796011784251756958130679822179554057734962978782410770260489", "price": "0.14", "size": "750", "side": "BUY", "hash": "7f9d696434e774d33cf2d3e882ad67ecf6201ed5", "best_bid": "0.56", "best_ask": "0.57"}, {"asset_id": "1721314828785517746980964825401510699361790864946226663151397689590042697451", "price": "0.86", "size": "750", "side": "SELL", "hash": "a1b771b76ec24ee60211bce8b2c8fda7493c89a8", "best_bid": "0.43", "best_ask": "0.44"}], "timestamp": "1769385002280", "event_type": "price_change"}}
{"_local_timestamp": "2026-01-25T23:50:05.079619+00:00", "data": {"market": "0xbeda18055fdc1f5bce0934e2500ed4ee82745b4c78b109e04e8dcf69f98d5d02", "price_changes": [{"asset_id": "1721314828785517746980964825401510699361790864946226663151397689590042697451", "price": "0.36", "size": "543.55", "side": "BUY", "hash": "48d2e4f2b63c963efc193afb34c68a38d34a2544", "best_bid": "0.43", "best_ask": "0.44"}, {"asset_id": "72392264258230870796011784251756958130679822179554057734962978782410770260489", "price": "0.64", "size": "543.55", "side": "SELL", "hash": "57d9c92579ac15508185b8a086e95dc72e3f0f6d", "best_bid": "0.56", "best_ask": "0.57"}], "timestamp": "1769385005001", "event_type": "price_change"}}
{"_local_timestamp": "2026-01-25T23:50:05.129024+00:00", "data": {"market": "0xbeda18055fdc1f5bce0934e2500ed4ee82745b4c78b109e04e8dcf69f98d5d02", "price_changes": [{"asset_id": "1721314828785517746980964825401510699361790864946226663151397689590042697451", "price": "0.31", "size": "1165", "side": "BUY", "hash": "9f31fc204d679e59555305474115eee9633275df", "best_bid": "0.43", "best_ask": "0.44"}, {"asset_id": "72392264258230870796011784251756958130679822179554057734962978782410770260489", "price": "0.69", "size": "1165", "side": "SELL", "hash": "20fc09509a8a0b5dff985bb8deb98fdf38c9eaf4", "best_bid": "0.56", "best_ask": "0.57"}], "timestamp": "1769385005012", "event_type": "price_change"}}
{"_local_timestamp": "2026-01-25T23:50:05.536499+00:00", "data": {"market": "0xbeda18055fdc1f5bce0934e2500ed4ee82745b4c78b109e04e8dcf69f98d5d02", "price_changes": [{"asset_id": "1721314828785517746980964825401510699361790864946226663151397689590042697451", "price": "0.13", "size": "325", "side": "BUY", "hash": "eac156e539ef3ead84f494b7b36661fce6ae2d2f", "best_bid": "0.43", "best_ask": "0.44"}, {"asset_id": "72392264258230870796011784251756958130679822179554057734962978782410770260489", "price": "0.87", "size": "325", "side": "SELL", "hash": "939d2c0588862b0d995bbccb7be50b4ab15499db", "best_bid": "0.56", "best_ask": "0.57"}], "timestamp": "1769385005454", "event_type": "price_change"}}
{"_local_timestamp": "2026-01-25T23:50:05.830441+00:00", "data": {"market": "0xbeda18055fdc1f5bce0934e2500ed4ee82745b4c78b109e04e8dcf69f98d5d02", "price_changes": [{"asset_id": "1721314828785517746980964825401510699361790864946226663151397689590042697451", "price": "0.15", "size": "3559", "side": "BUY", "hash": "ef644c113f2b698434b793897f945a4f40d68a9a", "best_bid": "0.43", "best_ask": "0.44"}, {"asset_id": "72392264258230870796011784251756958130679822179554057734962978782410770260489", "price": "0.85", "size": "3559", "side": "SELL", "hash": "e736e8a3c8fd02ccba653086990788924e85eea1", "best_bid": "0.56", "best_ask": "0.57"}], "timestamp": "1769385005716", "event_type": "price_change"}}
{"_local_timestamp": "2026-01-25T23:50:24.376201+00:00", "data": {"market": "0xbeda18055fdc1f5bce0934e2500ed4ee82745b4c78b109e04e8dcf69f98d5d02", "price_changes": [{"asset_id": "72392264258230870796011784251756958130679822179554057734962978782410770260489", "price": "0.6", "size": "175.63", "side": "SELL", "hash": "e08ec0068be5f3c85c0c3f21a0b373c8cbc54f8d", "best_bid": "0.56", "best_ask": "0.57"}, {"asset_id": "1721314828785517746980964825401510699361790864946226663151397689590042697451", "price": "0.4", "size": "175.63", "side": "BUY", "hash": "ec178b1a1735573d3004494006369bcdd191c935", "best_bid": "0.43", "best_ask": "0.44"}], "timestamp": "1769385024267", "event_type": "price_change"}}
{"_local_timestamp": "2026-01-25T23:50:38.408790+00:00", "data": {"market": "0xbeda18055fdc1f5bce0934e2500ed4ee82745b4c78b109e04e8dcf69f98d5d02", "price_changes": [{"asset_id": "1721314828785517746980964825401510699361790864946226663151397689590042697451", "price": "0.11", "size": "254.54", "side": "BUY", "hash": "62daefc4eff2c9ba2ea0ff39437bc03136a24c1b", "best_bid": "0.43", "best_ask": "0.44"}, {"asset_id": "72392264258230870796011784251756958130679822179554057734962978782410770260489", "price": "0.89", "size": "254.54", "side": "SELL", "hash": "fbef4187eca56ce76abce58b7e4adbb61f29663d", "best_bid": "0.56", "best_ask": "0.57"}], "timestamp": "1769385038182", "event_type": "price_change"}}
{"_local_timestamp": "2026-01-25T23:51:05.479403+00:00", "data": {"market": "0xbeda18055fdc1f5bce0934e2500ed4ee82745b4c78b109e04e8dcf69f98d5d02", "price_changes": [{"asset_id": "1721314828785517746980964825401510699361790864946226663151397689590042697451", "price": "0.13", "size": "200", "side": "BUY", "hash": "07ed8e3821febe5cb1f53f0125efa6f82122ff59", "best_bid": "0.43", "best_ask": "0.44"}, {"asset_id": "72392264258230870796011784251756958130679822179554057734962978782410770260489", "price": "0.87", "size": "200", "side": "SELL", "hash": "272d155a5935740abacda5e9c2debdfd52e74f54", "best_bid": "0.56", "best_ask": "0.57"}], "timestamp": "1769385065403", "event_type": "price_change"}}
{"_local_timestamp": "2026-01-25T23:51:06.038871+00:00", "data": {"market": "0xbeda18055fdc1f5bce0934e2500ed4ee82745b4c78b109e04e8dcf69f98d5d02", "price_changes": [{"asset_id": "1721314828785517746980964825401510699361790864946226663151397689590042697451", "price": "0.15", "size": "3684", "side": "BUY", "hash": "9c3813940e5c0a709b0c0133b451e7fe4c8a33c6", "best_bid": "0.43", "best_ask": "0.44"}, {"asset_id": "72392264258230870796011784251756958130679822179554057734962978782410770260489", "price": "0.85", "size": "3684", "side": "SELL", "hash": "ded3d5038f84111a699fa5b450bbf5656c05d254", "best_bid": "0.56", "best_ask": "0.57"}], "timestamp": "1769385065798", "event_type": "price_change"}}
{"_local_timestamp": "2026-01-25T23:51:14.572869+00:00", "data": {"market": "0xbeda18055fdc1f5bce0934e2500ed4ee82745b4c78b109e04e8dcf69f98d5d02", "price_changes": [{"asset_id": "1721314828785517746980964825401510699361790864946226663151397689590042697451", "price": "0.41", "size": "262.17", "side": "BUY", "hash": "de09af26574366ef6715d53af920addfedf98c40", "best_bid": "0.43", "best_ask": "0.44"}, {"asset_id": "72392264258230870796011784251756958130679822179554057734962978782410770260489", "price": "0.59", "size": "262.17", "side": "SELL", "hash": "a15c4a0a4690a8cedfdb2464bebfabd12073fa99", "best_bid": "0.56", "best_ask": "0.57"}], "timestamp": "1769385074458", "event_type": "price_change"}}
{"_local_timestamp": "2026-01-25T23:51:14.580355+00:00", "data": {"market": "0xbeda18055fdc1f5bce0934e2500ed4ee82745b4c78b109e04e8dcf69f98d5d02", "price_changes": [{"asset_id": "72392264258230870796011784251756958130679822179554057734962978782410770260489", "price": "0.54", "size": "964.25", "side": "BUY", "hash": "1b0d0a91acec0c3afd5294dc5dbaba67e3558460", "best_bid": "0.56", "best_ask": "0.57"}, {"asset_id": "1721314828785517746980964825401510699361790864946226663151397689590042697451", "price": "0.46", "size": "964.25", "side": "SELL", "hash": "ad860b3565ee3d9498a4e6932bece28ba603e119", "best_bid": "0.43", "best_ask": "0.44"}], "timestamp": "1769385074463", "event_type": "price_change"}}
{"_local_timestamp": "2026-01-25T23:51:21.782593+00:00", "data": {"market": "0xbeda18055fdc1f5bce0934e2500ed4ee82745b4c78b109e04e8dcf69f98d5d02", "price_changes": [{"asset_id": "1721314828785517746980964825401510699361790864946226663151397689590042697451", "price": "0.41", "size": "412.17", "side": "BUY", "hash": "f38d26f4e8264beae4d881cc511210307601bc67", "best_bid": "0.43", "best_ask": "0.44"}, {"asset_id": "72392264258230870796011784251756958130679822179554057734962978782410770260489", "price": "0.59", "size": "412.17", "side": "SELL", "hash": "19938c26356e6b9bb6e100fea794acb1980846e3", "best_bid": "0.56", "best_ask": "0.57"}], "timestamp": "1769385081709", "event_type": "price_change"}}
{"_local_timestamp": "2026-01-25T23:51:21.810861+00:00", "data": {"market": "0xbeda18055fdc1f5bce0934e2500ed4ee82745b4c78b109e04e8dcf69f98d5d02", "price_changes": [{"asset_id": "72392264258230870796011784251756958130679822179554057734962978782410770260489", "price": "0.54", "size": "942.25", "side": "BUY", "hash": "3fb8427697e702e008ffdfc576b850847dc78cd2", "best_bid": "0.56", "best_ask": "0.57"}, {"asset_id": "1721314828785517746980964825401510699361790864946226663151397689590042697451", "price": "0.46", "size": "942.25", "side": "SELL", "hash": "eedd01f34fbe04763bb9673104860dda655b8a9a", "best_bid": "0.43", "best_ask": "0.44"}], "timestamp": "1769385081739", "event_type": "price_change"}}
