{"_local_timestamp": "2026-01-25T23:40:30.684813+00:00", "data": [{"market": "0x91e0a718041ddbf0855fb655cfcb5944636b33ce8ccaaee7dce0940aa80465ab", "asset_id": "82235234359303790318990338986894673350271665663072939428595924891405248197200", "timestamp": "1769384324814", "hash": "bf5ff053759368a56faa84e7fbb0f242c093106e", "bids": [{"price": "0.01", "size": "102881.15"}, {"price": "0.02", "size": "2025"}, {"price": "0.03", "size": "836.3"}, {"price": "0.04", "size": "3760"}, {"price": "0.05", "size": "10113.67"}, {"price": "0.06", "size": "12.3"}, {"price": "0.1", "size": "863.67"}, {"price": "0.12", "size": "378.5"}, {"price": "0.15", "size": "1000"}, {"price": "0.17", "size": "3000"}, {"price": "0.18", "size": "4000"}, {"price": "0.19", "size": "3600"}, {"price": "0.2", "size": "3217.58"}, {"price": "0.21", "size": "3000"}, {"price": "0.22", "size": "1750"}, {"price": "0.23", "size": "1400.03"}, {"price": "0.24", "size": "1500"}, {"price": "0.25", "size": "1420"}, {"price": "0.26", "size": "1905.68"}, {"price": "0.27", "size": "241.26"}, {"price": "0.28", "size": "18.68"}], "asks": [{"price": "0.99", "size": "32.91"}, {"price": "0.98", "size": "25"}, {"price": "0.97", "size": "8.12"}, {"price": "0.93", "size": "514.28"}, {"price": "0.92", "size": "8.21"}, {"price": "0.89", "size": "309.09"}, {"price": "0.88", "size": "1338"}, {"price": "0.87", "size": "5"}, {"price": "0.85", "size": "213.33"}, {"price": "0.84", "size": "1000"}, {"price": "0.82", "size": "155.55"}, {"price": "0.8", "size": "200"}, {"price": "0.79", "size": "1998"}, {"price": "0.78", "size": "123.18"}, {"price": "0.76", "size": "200"}, {"price": "0.75", "size": "3634"}, {"price": "0.74", "size": "99.3"}, {"price": "0.71", "size": "73.96"}, {"price": "0.7", "size": "120"}, {"price": "0.68", "size": "15"}, {"price": "0.67", "size": "10"}, {"price": "0.66", "size": "200"}, {"price": "0.59", "size": "100"}, {"price": "0.58", "size": "8.98"}, {"price": "0.48", "size": "1667.68"}, {"price": "0.44", "size": "98.48"}, {"price": "0.4", "size": "2567.57"}, {"price": "0.39", "size": "500.01"}, {"price": "0.38", "size": "20.96"}, {"price": "0.37", "size": "101.05"}, {"price": "0.36", "size": "519.11"}, {"price": "0.35", "size": "38.55"}, {"price": "0.34", "size": "364"}, {"price": "0.33", "size": "10"}, {"price": "0.32", "size": "399.99"}, {"price": "0.31", "size": "161.28"}, {"price": "0.3", "size": "383.89"}], "event_type": "book", "last_trade_price": "0.700"}, {"market": "0x91e0a718041ddbf0855fb655cfcb5944636b33ce8ccaaee7dce0940aa80465ab", "asset_id": "88263981208537093410063459148292369268178576306830494146004574288996908107420", "timestamp": "1769384324814", "hash": "2b93a3c7da896dc79d61bea3c6fe9170bcf34b69", "bids": [{"price": "0.01", "size": "32.91"}, {"price": "0.02", "size": "25"}, {"price": "0.03", "size": "8.12"}, {"price": "0.07", "size": "514.28"}, {"price": "0.08", "size": "8.21"}, {"price": "0.11", "size": "309.09"}, {"price": "0.12", "size": "1338"}, {"price": "0.13", "size": "5"}, {"price": "0.15", "size": "213.33"}, {"price": "0.16", "size": "1000"}, {"price": "0.18", "size": "155.55"}, {"price": "0.2", "size": "200"}, {"price": "0.21", "size": "1998"}, {"price": "0.22", "size": "123.18"}, {"price": "0.24", "size": "200"}, {"price": "0.25", "size": "3634"}, {"price": "0.26", "size": "99.3"}, {"price": "0.29", "size": "73.96"}, {"price": "0.3", "size": "120"}, {"price": "0.32", "size": "15"}, {"price": "0.33", "size": "10"}, {"price": "0.34", "size": "200"}, {"price": "0.41", "size": "100"}, {"price": "0.42", "size": "8.98"}, {"price": "0.52", "size": "1667.68"}, {"price": "0.56", "size": "98.48"}, {"price": "0.6", "size": "2567.57"}, {"price": "0.61", "size": "500.01"}, {"price": "0.62", "size": "20.96"}, {"price": "0.63", "size": "101.05"}, {"price": "0.64", "size": "519.11"}, {"price": "0.65", "size": "38.55"}, {"price": "0.66", "size": "364"}, {"price": "0.67", "size": "10"}, {"price": "0.68", "size": "399.99"}, {"price": "0.69", "size": "161.28"}, {"price": "0.7", "size": "383.89"}], "asks": [{"price": "0.99", "size": "102881.15"}, {"price": "0.98", "size": "2025"}, {"price": "0.97", "size": "836.3"}, {"price": "0.96", "size": "3760"}, {"price": "0.95", "size": "10113.67"}, {"price": "0.94", "size": "12.3"}, {"price": "0.9", "size": "863.67"}, {"price": "0.88", "size": "378.5"}, {"price": "0.85", "size": "1000"}, {"price": "0.83", "size": "3000"}, {"price": "0.82", "size": "4000"}, {"price": "0.81", "size": "3600"}, {"price": "0.8", "size": "3217.58"}, {"price": "0.79", "size": "3000"}, {"price": "0.78", "size": "1750"}, {"price": "0.77", "size": "1400.03"}, {"price": "0.76", "size": "1500"}, {"price": "0.75", "size": "1420"}, {"price": "0.74", "size": "1905.68"}, {"price": "0.73", "size": "241.26"}, {"price": "0.72", "size": "18.68"}], "event_type": "book", "last_trade_price": "0.700"}, {"market": "0xbb6e02d1b77e26964331305ca9f12da8c6f676e1efe893372485425becbed223", "asset_id": "84564904382008311962069365288283225167949742624603481609433520601697502508513", "timestamp": "1769384280002", "hash": "67b8e6d42e98e33cf5da973d66700a66de748a5d", "bids": [{"price": "0.001", "size": "1114.99"}, {"price": "0.002", "size": "201.69"}, {"price": "0.01", "size": "2273"}, {"price": "0.011", "size": "502.24"}, {"price": "0.012", "size": "7.99"}, {"price": "0.013", "size": "80"}, {"price": "0.014", "size": "18.82"}, {"price": "0.021", "size": "67.21"}, {"price": "0.022", "size": "30"}, {"price": "0.023", "size": "6.59"}, {"price": "0.025", "size": "35"}], "asks": [{"price": "0.999", "size": "1120.08"}, {"price": "0.998", "size": "44.21"}, {"price": "0.99", "size": "31"}, {"price": "0.989", "size": "28.13"}, {"price": "0.9", "size": "360"}, {"price": "0.899", "size": "5.91"}, {"price": "0.85", "size": "226.66"}, {"price": "0.8", "size": "160"}, {"price": "0.799", "size": "9418"}, {"price": "0.76", "size": "116.66"}, {"price": "0.759", "size": "8"}, {"price": "0.71", "size": "89.65"}, {"price": "0.66", "size": "70.58"}, {"price": "0.65", "size": "6"}, {"price": "0.61", "size": "51.28"}, {"price": "0.41", "size": "200"}, {"price": "0.35", "size": "100"}, {"price": "0.14", "size": "250"}, {"price": "0.13", "size": "36.84"}, {"price": "0.11", "size": "191"}, {"price": "0.1", "size": "600"}, {"price": "0.08", "size": "173.21"}, {"price": "0.07", "size": "34"}, {"price": "0.069", "size": "100"}, {"price": "0.057", "size": "100"}, {"price": "0.048", "size": "1365.94"}, {"price": "0.045", "size": "237.93"}, {"price": "0.043", "size": "200"}, {"price": "0.042", "size": "281.4"}, {"price": "0.041", "size": "29.16"}], "event_type": "book", "last_trade_price": "0.959"}, {"market": "0xbb6e02d1b77e26964331305ca9f12da8c6f676e1efe893372485425becbed223", "asset_id": "110473274803190513305909771926634978036732087892207534963402259650286946307044", "timestamp": "1769384280002", "hash": "c215b3460f4cd65a78303e9aad315113e5c26ae2", "bids": [{"price": "0.001", "size": "1120.08"}, {"price": "0.002", "size": "44.21"}, {"price": "0.01", "size": "31"}, {"price": "0.011", "size": "28.13"}, {"price": "0.1", "size": "360"}, {"price": "0.101", "size": "5.91"}, {"price": "0.15", "size": "226.66"}, {"price": "0.2", "size": "160"}, {"price": "0.201", "size": "9418"}, {"price": "0.24", "size": "116.66"}, {"price": "0.241", "size": "8"}, {"price": "0.29", "size": "89.65"}, {"price": "0.34", "size": "70.58"}, {"price": "0.35", "size": "6"}, {"price": "0.39", "size": "51.28"}, {"price": "0.59", "size": "200"}, {"price": "0.65", "size": "100"}, {"price": "0.86", "size": "250"}, {"price": "0.87", "size": "36.84"}, {"price": "0.89", "size": "191"}, {"price": "0.9", "size": "600"}, {"price": "0.92", "size": "173.21"}, {"price": "0.93", "size": "34"}, {"price": "0.931", "size": "100"}, {"price": "0.943", "size": "100"}, {"price": "0.952", "size": "1365.94"}, {"price": "0.955", "size": "237.93"}, {"price": "0.957", "size": "200"}, {"price": "0.958", "size": "281.4"}, {"price": "0.959", "size": "29.16"}], "asks": [{"price": "0.999", "size": "1114.99"}, {"price": "0.998", "size": "201.69"}, {"price": "0.99", "size": "2273"}, {"price": "0.989", "size": "502.24"}, {"price": "0.988", "size": "7.99"}, {"price": "0.987", "size": "80"}, {"price": "0.986", "size": "18.82"}, {"price": "0.979", "size": "67.21"}, {"price": "0.978", "size": "30"}, {"price": "0.977", "size": "6.59"}, {"price": "0.975", "size": "35"}], "event_type": "book", "last_trade_price": "0.959"}]}
{"_local_timestamp": "2026-01-25T23:41:02.613706+00:00", "data": {"market": "0xbb6e02d1b77e26964331305ca9f12da8c6f676e1efe893372485425becbed223", "price_changes": [{"asset_id": "84564904382008311962069365288283225167949742624603481609433520601697502508513", "price": "0.002", "size": "109.65", "side": "BUY", "hash": "0703ca698f08fcf8a96c30623957ac4599186aed", "best_bid": "0.025", "best_ask": "0.041"}, {"asset_id": "110473274803190513305909771926634978036732087892207534963402259650286946307044", "price": "0.998", "size": "109.65", "side": "SELL", "hash": "a8eca584aff9497cd34e185a972e27b135b81081", "best_bid": "0.959", "best_ask": "0.975"}], "timestamp": "1769384462538", "event_type": "price_change"}}
{"_local_timestamp": "2026-01-25T23:41:02.881055+00:00", "data": {"market": "0xbb6e02d1b77e26964331305ca9f12da8c6f676e1efe893372485425becbed223", "price_changes": [{"asset_id": "84564904382008311962069365288283225167949742624603481609433520601697502508513", "price": "0.014", "size": "24.49", "side": "BUY", "hash": "cfd494c5affe46c6a95d8bb274f0af55100a2072", "best_bid": "0.025", "best_ask": "0.041"}, {"asset_id": "110473274803190513305909771926634978036732087892207534963402259650286946307044", "price": "0.986", "size": "24.49", "side": "SELL", "hash": "1ebb1df7759abd8f551b87a13d5434f9511cbf55", "best_bid": "0.959", "best_ask": "0.975"}], "timestamp": "1769384462804", "event_type": "price_change"}}
{"_local_timestamp": "2026-01-25T23:41:02.881488+00:00", "data": {"market": "0xbb6e02d1b77e26964331305ca9f12da8c6f676e1efe893372485425becbed223", "price_changes": [{"asset_id": "84564904382008311962069365288283225167949742624603481609433520601697502508513", "price": "0.002", "size": "204.78", "side": "BUY", "hash": "460bcefad8dc81e128cedbc6b4ed33937ae30c21", "best_bid": "0.025", "best_ask": "0.041"}, {"asset_id": "110473274803190513305909771926634978036732087892207534963402259650286946307044", "price": "0.998", "size": "204.78", "side": "SELL", "hash": "15435e6aa7e9161b84fa6ec9e65357319bb2b236", "best_bid": "0.959", "best_ask": "0.975"}], "timestamp": "1769384462806", "event_type": "price_change"}}
{"_local_timestamp": "2026-01-25T23:41:02.914785+00:00", "data": {"market": "0xbb6e02d1b77e26964331305ca9f12da8c6f676e1efe893372485425becbed223", "price_changes": [{"asset_id": "84564904382008311962069365288283225167949742624603481609433520601697502508513", "price": "0.014", "size": "30.16", "side": "BUY", "hash": "383757292be79b5cff92125f71bdae621082d399", "best_bid": "0.025", "best_ask": "0.041"}, {"asset_id": "110473274803190513305909771926634978036732087892207534963402259650286946307044", "price": "0.986", "size": "30.16", "side": "SELL", "hash": "2c89ecf498a8d128a5e3f27d564d4bac3b5bc399", "best_bid": "0.959", "best_ask": "0.975"}], "timestamp": "1769384462829", "event_type": "price_change"}}
{"_local_timestamp": "2026-01-25T23:41:02.915321+00:00", "data": {"market": "0xbb6e02d1b77e26964331305ca9f12da8c6f676e1efe893372485425becbed223", "price_changes": [{"asset_id": "84564904382008311962069365288283225167949742624603481609433520601697502508513", "price": "0.002", "size": "299.91", "side": "BUY", "hash": "1c19f4e00a3a07106994f9bb2a4455ba63220dfd", "best_bid": "0.025", "best_ask": "0.041"}, {"asset_id": "110473274803190513305909771926634978036732087892207534963402259650286946307044", "price": "0.998", "size": "299.91", "side": "SELL", "hash": "0bb0bcbe04384fe8c4cfe085b993c971895503d9", "best_bid": "0.959", "best_ask": "0.975"}], "timestamp": "1769384462832", "event_type": "price_change"}}
{"_local_timestamp": "2026-01-25T23:41:06.319645+00:00", "data": {"market": "0x91e0a718041ddbf0855fb655cfcb5944636b33ce8ccaaee7dce0940aa80465ab", "price_changes": [{"asset_id": "82235234359303790318990338986894673350271665663072939428595924891405248197200", "price": "0.26", "size": "1805.68", "side": "BUY", "hash": "2890276fe49f315e281f245a4241f34e34288837", "best_bid": "0.28", "best_ask": "0.3"}, {"asset_id": "88263981208537093410063459148292369268178576306830494146004574288996908107420", "price": "0.74", "size": "1805.68", "side": "SELL", "hash": "eb891d94dc17cb2e8e5032f0902a00c9f3e17503", "best_bid": "0.7", "best_ask": "0.72"}], "timestamp": "1769384466199", "event_type": "price_change"}}
{"_local_timestamp": "2026-01-25T23:41:06.332279+00:00", "data": {"market": "0x91e0a718041ddbf0855fb655cfcb5944636b33ce8ccaaee7dce0940aa80465ab", "price_changes": [{"asset_id": "88263981208537093410063459148292369268178576306830494146004574288996908107420", "price": "0.68", "size": "299.99", "side": "BUY", "hash": "5648501413c0cca8e16416c5aa623432ae5f884f", "best_bid": "0.7", "best_ask": "0.72"}, {"asset_id": "82235234359303790318990338986894673350271665663072939428595924891405248197200", "price": "0.32", "size": "299.99", "side": "SELL", "hash": "07d590cfbebf1c0a5b77ab8a0f2628d1b75ee279", "best_bid": "0.28", "best_ask": "0.3"}], "timestamp": "1769384466201", "event_type": "price_change"}}
{"_local_timestamp": "2026-01-25T23:41:13.230267+00:00", "data": {"market": "0xbb6e02d1b77e26964331305ca9f12da8c6f676e1efe893372485425becbed223", "price_changes": [{"asset_id": "84564904382008311962069365288283225167949742624603481609433520601697502508513", "price": "0.002", "size": "109.65", "side": "BUY", "hash": "f733c19e691808c29355b188f6c20fd8fe64ab26", "best_bid": "0.025", "best_ask": "0.041"}, {"asset_id": "110473274803190513305909771926634978036732087892207534963402259650286946307044", "price": "0.998", "size": "109.65", "side": "SELL", "hash": "a945e217057125e5560108aa10d138f97307a7fb", "best_bid": "0.959", "best_ask": "0.975"}], "timestamp": "1769384473157", "event_type": "price_change"}}
{"_local_timestamp": "2026-01-25T23:41:13.232299+00:00", "data": {"market": "0xbb6e02d1b77e26964331305ca9f12da8c6f676e1efe893372485425becbed223", "price_changes": [{"asset_id": "84564904382008311962069365288283225167949742624603481609433520601697502508513", "price": "0.014", "size": "11.34", "side": "BUY", "hash": "f733c19e691808c29355b188f6c20fd8fe64ab26", "best_bid": "0.025", "best_ask": "0.041"}, {"asset_id": "110473274803190513305909771926634978036732087892207534963402259650286946307044", "price": "0.986", "size": "11.34", "side": "SELL", "hash": "a945e217057125e5560108aa10d138f97307a7fb", "best_bid": "0.959", "best_ask": "0.975"}], "timestamp": "1769384473157", "event_type": "price_change"}}
{"_local_timestamp": "2026-01-25T23:41:13.585171+00:00", "data": {"market": "0xbb6e02d1b77e26964331305ca9f12da8c6f676e1efe893372485425becbed223", "price_changes": [{"asset_id": "84564904382008311962069365288283225167949742624603481609433520601697502508513", "price": "0.014", "size": "24.73", "side": "BUY", "hash": "7cbd6a8b50e96a41af867a521ed4594b1c516dd4", "best_bid": "0.025", "best_ask": "0.041"}, {"asset_id": "110473274803190513305909771926634978036732087892207534963402259650286946307044", "price": "0.986", "size": "24.73", "side": "SELL", "hash": "44a004f2cb9d5f730403c660e0bfe2b950df8ae0", "best_bid": "0.959", "best_ask": "0.975"}], "timestamp": "1769384473509", "event_type": "price_change"}}
{"_local_timestamp": "2026-01-25T23:41:13.585553+00:00", "data": {"market": "0xbb6e02d1b77e26964331305ca9f12da8c6f676e1efe893372485425becbed223", "price_changes": [{"asset_id": "84564904382008311962069365288283225167949742624603481609433520601697502508513", "price": "0.002", "size": "203.11", "side": "BUY", "hash": "54df4675b65d9ab7b41a8b2804caf03b5db12906", "best_bid": "0.025", "best_ask": "0.041"}, {"asset_id": "110473274803190513305909771926634978036732087892207534963402259650286946307044", "price": "0.998", "size": "203.11", "side": "SELL", "hash": "ed2e40f50fa580d34d666510589a059b6b49775c", "best_bid": "0.959", "best_ask": "0.975"}], "timestamp": "1769384473510", "event_type": "price_change"}}
{"_local_timestamp": "2026-01-25T23:41:43.294277+00:00", "data": {"market": "0x91e0a718041ddbf0855fb655cfcb5944636b33ce8ccaaee7dce0940aa80465ab", "price_changes": [{"asset_id": "82235234359303790318990338986894673350271665663072939428595924891405248197200", "price": "0.26", "size": "1905.68", "side": "BUY", "hash": "1f010eea683e8f297476b4e5c1da499e43d0c854", "best_bid": "0.28", "best_ask": "0.3"}, {"asset_id": "88263981208537093410063459148292369268178576306830494146004574288996908107420", "price": "0.74", "size": "1905.68", "side": "SELL", "hash": "dac50a5df0ef7639699c06d15e1fc2714534f3a8", "best_bid": "0.7", "best_ask": "0.72"}], "timestamp": "1769384503219", "event_type": "price_change"}}
{"_local_timestamp": "2026-01-25T23:41:44.814431+00:00", "data": {"market": "0x91e0a718041ddbf0855fb655cfcb5944636b33ce8ccaaee7dce0940aa80465ab", "price_changes": [{"asset_id": "88263981208537093410063459148292369268178576306830494146004574288996908107420", "price": "0.68", "size": "399.99", "side": "BUY", "hash": "e2b2c3dc4c86c9030dca886608233e132b6b36e4", "best_bid": "0.7", "best_ask": "0.72"}, {"asset_id": "82235234359303790318990338986894673350271665663072939428595924891405248197200", "price": "0.32", "size": "399.99", "side": "SELL", "hash": "05022bc65774f653fa2d66aea2c15a0a3fa3716f", "best_bid": "0.28", "best_ask": "0.3"}], "timestamp": "1769384504733", "event_type": "price_change"}}
{"_local_timestamp": "2026-01-25T23:41:58.115148+00:00", "data": {"market": "0xbb6e02d1b77e26964331305ca9f12da8c6f676e1efe893372485425becbed223", "price_changes": [{"asset_id": "84564904382008311962069365288283225167949742624603481609433520601697502508513", "price": "0.012", "size": "0", "side": "BUY", "hash": "6f0f874718bdefddae9f839ebdcada9a0789060d", "best_bid": "0.025", "best_ask": "0.041"}, {"asset_id": "110473274803190513305909771926634978036732087892207534963402259650286946307044", "price": "0.988", "size": "0", "side": "SELL", "hash": "8bbc3e4ad9eb04a36fcc1caf3a186b2e341b0b22", "best_bid": "0.959", "best_ask": "0.975"}], "timestamp": "1769384518002", "event_type": "price_change"}}
{"_local_timestamp": "2026-01-25T23:41:58.116978+00:00", "data": {"market": "0xbb6e02d1b77e26964331305ca9f12da8c6f676e1efe893372485425becbed223", "price_changes": [{"asset_id": "84564904382008311962069365288283225167949742624603481609433520601697502508513", "price": "0.002", "size": "197.45", "side": "BUY", "hash": "5a07c81a329304fbcb43f42117d2937fd446ecbb", "best_bid": "0.025", "best_ask": "0.041"}, {"asset_id": "110473274803190513305909771926634978036732087892207534963402259650286946307044", "price": "0.998", "size": "197.45", "side": "SELL", "hash": "c1b45d1e99c4061d29a92fb6373ec454f4cd2b65", "best_bid": "0.959", "best_ask": "0.975"}], "timestamp": "1769384518006", "event_type": "price_change"}}
{"_local_timestamp": "2026-01-25T23:42:44.134547+00:00", "data": {"market": "0x91e0a718041ddbf0855fb655cfcb5944636b33ce8ccaaee7dce0940aa80465ab", "price_changes": [{"asset_id": "88263981208537093410063459148292369268178576306830494146004574288996908107420", "price": "0.03", "size": "0", "side": "BUY", "hash": "e181cfe6a129dbe4e8429417205350422d6658fb", "best_bid": "0.7", "best_ask": "0.72"}, {"asset_id": "82235234359303790318990338986894673350271665663072939428595924891405248197200", "price": "0.97", "size": "0", "side": "SELL", "hash": "93e7abdebf6bd0cce435fd62c30b694e15f257c7", "best_bid": "0.28", "best_ask": "0.3"}], "timestamp": "1769384564000", "event_type": "price_change"}}
{"_local_timestamp": "2026-01-25T23:42:44.143769+00:00", "data": {"market": "0x91e0a718041ddbf0855fb655cfcb5944636b33ce8ccaaee7dce0940aa80465ab", "price_changes": [{"asset_id": "88263981208537093410063459148292369268178576306830494146004574288996908107420", "price": "0.01", "size": "23", "side": "BUY", "hash": "bc51dc59f9e20b94b108422b8db29074b93df4fe", "best_bid": "0.7", "best_ask": "0.72"}, {"asset_id": "82235234359303790318990338986894673350271665663072939428595924891405248197200", "price": "0.99", "size": "23", "side": "SELL", "hash": "18c74c161771d4a245dc439772992cd1a7e81447", "best_bid": "0.28", "best_ask": "0.3"}], "timestamp": "1769384564001", "event_type": "price_change"}}
{"_local_timestamp": "2026-01-25T23:42:47.251298+00:00", "data": {"market": "0x91e0a718041ddbf0855fb655cfcb5944636b33ce8ccaaee7dce0940aa80465ab", "price_changes": [{"asset_id": "88263981208537093410063459148292369268178576306830494146004574288996908107420", "price": "0.21", "size": "0", "side": "BUY", "hash": "5cde5f56ebb9c509d609150452e4dca7da38e84f", "best_bid": "0.7", "best_ask": "0.72"}, {"asset_id": "82235234359303790318990338986894673350271665663072939428595924891405248197200", "price": "0.79", "size": "0", "side": "SELL", "hash": "9ccb2ad3ec40c40aa8e4bd467440f564d92e5881", "best_bid": "0.28", "best_ask": "0.3"}], "timestamp": "1769384566995", "event_type": "price_change"}}
{"_local_timestamp": "2026-01-25T23:42:48.207884+00:00", "data": {"market": "0x91e0a718041ddbf0855fb655cfcb5944636b33ce8ccaaee7dce0940aa80465ab", "price_changes": [{"asset_id": "82235234359303790318990338986894673350271665663072939428595924891405248197200", "price": "0.03", "size": "830.31", "side": "BUY", "hash": "f8f140d472c3b33e71f88a16645f0eb3a6e25588", "best_bid": "0.28", "best_ask": "0.3"}, {"asset_id": "88263981208537093410063459148292369268178576306830494146004574288996908107420", "price": "0.97", "size": "830.31", "side": "SELL", "hash": "7d07eb2949de71d3482e66014d0853c69f1d447d", "best_bid": "0.7", "best_ask": "0.72"}], "timestamp": "1769384568000", "event_type": "price_change"}}
{"_local_timestamp": "2026-01-25T23:42:48.208223+00:00", "data": {"market": "0x91e0a718041ddbf0855fb655cfcb5944636b33ce8ccaaee7dce0940aa80465ab", "price_changes": [{"asset_id": "82235234359303790318990338986894673350271665663072939428595924891405248197200", "price": "0.01", "size": "102873", "side": "BUY", "hash": "1a93ea44a6d8d7f0c3c5501cdc15e9ec82a074d8", "best_bid": "0.28", "best_ask": "0.3"}, {"asset_id": "88263981208537093410063459148292369268178576306830494146004574288996908107420", "price": "0.99", "size": "102873", "side": "SELL", "hash": "7450feb20b949c3d65f9efd03fa664742ce52c80", "best_bid": "0.7", "best_ask": "0.72"}], "timestamp": "1769384568003", "event_type": "price_change"}}
{"_local_timestamp": "2026-01-25T23:42:48.209603+00:00", "data": {"market": "0x91e0a718041ddbf0855fb655cfcb5944636b33ce8ccaaee7dce0940aa80465ab", "price_changes": [{"asset_id": "82235234359303790318990338986894673350271665663072939428595924891405248197200", "price": "0.06", "size": "0", "side": "BUY", "hash": "5d0ffd5f7b1f3c9c7255cb1bc31e7995fa17ebe9", "best_bid": "0.28", "best_ask": "0.3"}, {"asset_id": "88263981208537093410063459148292369268178576306830494146004574288996908107420", "price": "0.94", "size": "0", "side": "SELL", "hash": "3bf06450c6f191ae58dce2780d992fb6be70848c", "best_bid": "0.7", "best_ask": "0.72"}], "timestamp": "1769384568004", "event_type": "price_change"}}
{"_local_timestamp": "2026-01-25T23:42:59.254373+00:00", "data": {"market": "0x91e0a718041ddbf0855fb655cfcb5944636b33ce8ccaaee7dce0940aa80465ab", "price_changes": [{"asset_id": "88263981208537093410063459148292369268178576306830494146004574288996908107420", "price": "0.22", "size": "2031.18", "side": "BUY", "hash": "ea636a14adb3ba1153c1103a3f316e6a8d6bb6c0", "best_bid": "0.7", "best_ask": "0.72"}, {"asset_id": "82235234359303790318990338986894673350271665663072939428595924891405248197200", "price": "0.78", "size": "2031.18", "side": "SELL", "hash": "d91fda973b35e664824795cf8f42af3d49c97d2d", "best_bid": "0.28", "best_ask": "0.3"}], "timestamp": "1769384579030", "event_type": "price_change"}}
{"_local_timestamp": "2026-01-25T23:43:07.334975+00:00", "data": {"market": "0x91e0a718041ddbf0855fb655cfcb5944636b33ce8ccaaee7dce0940aa80465ab", "price_changes": [{"asset_id": "88263981208537093410063459148292369268178576306830494146004574288996908107420", "price": "0.01", "size": "34.06", "side": "BUY", "hash": "5ce39d45bda99cf5839ec6645d259d1d73cf2bf2", "best_bid": "0.7", "best_ask": "0.72"}, {"asset_id": "82235234359303790318990338986894673350271665663072939428595924891405248197200", "price": "0.99", "size": "34.06", "side": "SELL", "hash": "846f013360904e172b408bae8ba6671d6d2048ee", "best_bid": "0.28", "best_ask": "0.3"}], "timestamp": "1769384587169", "event_type": "price_change"}}
{"_local_timestamp": "2026-01-25T23:43:07.335681+00:00", "data": {"market": "0x91e0a718041ddbf0855fb655cfcb5944636b33ce8ccaaee7dce0940aa80465ab", "price_changes": [{"asset_id": "82235234359303790318990338986894673350271665663072939428595924891405248197200", "price": "0.03", "size": "836.3", "side": "BUY", "hash": "5b344003e2b0612a7432dc4c476e67086df52882", "best_bid": "0.28", "best_ask": "0.3"}, {"asset_id": "88263981208537093410063459148292369268178576306830494146004574288996908107420", "price": "0.97", "size": "836.3", "side": "SELL", "hash": "c2c590b824e29412f82cd54de98cfff0750f5a6e", "best_bid": "0.7", "best_ask": "0.72"}], "timestamp": "1769384587169", "event_type": "price_change"}}
{"_local_timestamp": "2026-01-25T23:43:07.336132+00:00", "data": {"market": "0x91e0a718041ddbf0855fb655cfcb5944636b33ce8ccaaee7dce0940aa80465ab", "price_changes": [{"asset_id": "82235234359303790318990338986894673350271665663072939428595924891405248197200", "price": "0.01", "size": "102881.15", "side": "BUY", "hash": "be9ceb23109675ffb66b3d0a263618b893083e3e", "best_bid": "0.28", "best_ask": "0.3"}, {"asset_id": "88263981208537093410063459148292369268178576306830494146004574288996908107420", "price": "0.99", "size": "102881.15", "side": "SELL", "hash": "6e9dde5318c9f9f7902f9450dd364869006322e4", "best_bid": "0.7", "best_ask": "0.72"}], "timestamp": "1769384587170", "event_type": "price_change"}}
{"_local_timestamp": "2026-01-25T23:43:07.336462+00:00", "data": {"market": "0x91e0a718041ddbf0855fb655cfcb5944636b33ce8ccaaee7dce0940aa80465ab", "price_changes": [{"asset_id": "82235234359303790318990338986894673350271665663072939428595924891405248197200", "price": "0.06", "size": "12.3", "side": "BUY", "hash": "e9bef85b7b65689f9f77c1678c0520105dfee401", "best_bid": "0.28", "best_ask": "0.3"}, {"asset_id": "88263981208537093410063459148292369268178576306830494146004574288996908107420", "price": "0.94", "size": "12.3", "side": "SELL", "hash": "d15baff6071ef18b9df8ced87946abfc363a2fc4", "best_bid": "0.7", "best_ask": "0.72"}], "timestamp": "1769384587171", "event_type": "price_change"}}
{"_local_timestamp": "2026-01-25T23:43:07.336773+00:00", "data": {"market": "0x91e0a718041ddbf0855fb655cfcb5944636b33ce8ccaaee7dce0940aa80465ab", "price_changes": [{"asset_id": "88263981208537093410063459148292369268178576306830494146004574288996908107420", "price": "0.03", "size": "7.75", "side": "BUY", "hash": "e14d68a2cba76c822026e3d89cc81d6b4881c2ef", "best_bid": "0.7", "best_ask": "0.72"}, {"asset_id": "82235234359303790318990338986894673350271665663072939428595924891405248197200", "price": "0.97", "size": "7.75", "side": "SELL", "hash": "59768cc9d7870f23be77e14b711f70c41a403ae4", "best_bid": "0.28", "best_ask": "0.3"}], "timestamp": "1769384587172", "event_type": "price_change"}}
{"_local_timestamp": "2026-01-25T23:44:32.442814+00:00", "data": {"market": "0x91e0a718041ddbf0855fb655cfcb5944636b33ce8ccaaee7dce0940aa80465ab", "price_changes": [{"asset_id": "88263981208537093410063459148292369268178576306830494146004574288996908107420", "price": "0.22", "size": "123.18", "side": "BUY", "hash": "366b03bff89e87d76f4cdbeee0914f5d5d3490d2", "best_bid": "0.7", "best_ask": "0.72"}, {"asset_id": "82235234359303790318990338986894673350271665663072939428595924891405248197200", "price": "0.78", "size": "123.18", "side": "SELL", "hash": "1728bd8eaca03472887c473fa648ea9d8e604ed3", "best_bid": "0.28", "best_ask": "0.3"}], "timestamp": "1769384672292", "event_type": "price_change"}}
{"_local_timestamp": "2026-01-25T23:44:40.752343+00:00", "data": {"market": "0xbb6e02d1b77e26964331305ca9f12da8c6f676e1efe893372485425becbed223", "price_changes": [{"asset_id": "84564904382008311962069365288283225167949742624603481609433520601697502508513", "price": "0.012", "size": "8.94", "side": "BUY", "hash": "574b988c54b0609a6a5e7d75c9e799e1d26245e4", "best_bid": "0.025", "best_ask": "0.041"}, {"asset_id": "110473274803190513305909771926634978036732087892207534963402259650286946307044", "price": "0.988", "size": "8.94", "side": "SELL", "hash": "414cff47c66721d0a78773dded2270a06f046183", "best_bid": "0.959", "best_ask": "0.975"}], "timestamp": "1769384680687", "event_type": "price_change"}}
{"_local_timestamp": "2026-01-25T23:44:51.306374+00:00", "data": {"market": "0x91e0a718041ddbf0855fb655cfcb5944636b33ce8ccaaee7dce0940aa80465ab", "price_changes": [{"asset_id": "88263981208537093410063459148292369268178576306830494146004574288996908107420", "price": "0.21", "size": "1998", "side": "BUY", "hash": "9409d6851ec10482d511965b259f36300198dd87", "best_bid": "0.7", "best_ask": "0.72"}, {"asset_id": "82235234359303790318990338986894673350271665663072939428595924891405248197200", "price": "0.79", "size": "1998", "side": "SELL", "hash": "c8be232de26798a317c84caf78ccd261b9c6ebc3", "best_bid": "0.28", "best_ask": "0.3"}], "timestamp": "1769384691242", "event_type": "price_change"}}
{"_local_timestamp": "2026-01-25T23:45:22.850411+00:00", "data": {"market": "0x91e0a718041ddbf0855fb655cfcb5944636b33ce8ccaaee7dce0940aa80465ab", "price_changes": [{"asset_id": "82235234359303790318990338986894673350271665663072939428595924891405248197200", "price": "0.26", "size": "1805.68", "side": "BUY", "hash": "29e0e6a5ddb5b867ee788468c6e35611c6cfe269", "best_bid": "0.28", "best_ask": "0.3"}, {"asset_id": "88263981208537093410063459148292369268178576306830494146004574288996908107420", "price": "0.74", "size": "1805.68", "side": "SELL", "hash": "18010edfdaac2115de44c96b51677fb927c27bfe", "best_bid": "0.7", "best_ask": "0.72"}], "timestamp": "1769384722771", "event_type": "price_change"}}
{"_local_timestamp": "2026-01-25T23:45:22.880673+00:00", "data": {"market": "0x91e0a718041ddbf0855fb655cfcb5944636b33ce8ccaaee7dce0940aa80465ab", "price_changes": [{"asset_id": "88263981208537093410063459148292369268178576306830494146004574288996908107420", "price": "0.68", "size": "299.99", "side": "BUY", "hash": "d67f0fb6da3ecd276d9334c077529af5420e43f6", "best_bid": "0.7", "best_ask": "0.72"}, {"asset_id": "82235234359303790318990338986894673350271665663072939428595924891405248197200", "price": "0.32", "size": "299.99", "side": "SELL", "hash": "91ab07c84cf62eadb1d7b27f07a4f4bdd73704cd", "best_bid": "0.28", "best_ask": "0.3"}], "timestamp": "1769384722775", "event_type": "price_change"}}
{"_local_timestamp": "2026-01-25T23:45:30.081283+00:00", "data": {"market": "0xbb6e02d1b77e26964331305ca9f12da8c6f676e1efe893372485425becbed223", "price_changes": [{"asset_id": "110473274803190513305909771926634978036732087892207534963402259650286946307044", "price": "0.002", "size": "0", "side": "BUY", "hash": "744d6caa5f5b1488d31d6c9c19b9a3e196e35626", "best_bid": "0.959", "best_ask": "0.975"}, {"asset_id": "84564904382008311962069365288283225167949742624603481609433520601697502508513", "price": "0.998", "size": "0", "side": "SELL", "hash": "f559bb5ebc5d269cea8bef6d811673fad8d71bec", "best_bid": "0.025", "best_ask": "0.041"}], "timestamp": "1769384730000", "event_type": "price_change"}}
{"_local_timestamp": "2026-01-25T23:45:55.280649+00:00", "data": {"market": "0x91e0a718041ddbf0855fb655cfcb5944636b33ce8ccaaee7dce0940aa80465ab", "price_changes": [{"asset_id": "82235234359303790318990338986894673350271665663072939428595924891405248197200", "price": "0.26", "size": "1905.68", "side": "BUY", "hash": "74f8a5c669c7e2cba5825e00e8c7e7d8da467dfa", "best_bid": "0.28", "best_ask": "0.3"}, {"asset_id": "88263981208537093410063459148292369268178576306830494146004574288996908107420", "price": "0.74", "size": "1905.68", "side": "SELL", "hash": "825e79d8d5d364db88bfb423f8d43bd4f39a9706", "best_bid": "0.7", "best_ask": "0.72"}], "timestamp": "1769384755213", "event_type": "price_change"}}
{"_local_timestamp": "2026-01-25T23:45:59.040526+00:00", "data": {"market": "0x91e0a718041ddbf0855fb655cfcb5944636b33ce8ccaaee7dce0940aa80465ab", "price_changes": [{"asset_id": "88263981208537093410063459148292369268178576306830494146004574288996908107420", "price": "0.68", "size": "399.99", "side": "BUY", "hash": "754791739ad2cb5a6dfa48ee510d5bfaf154b967", "best_bid": "0.7", "best_ask": "0.72"}, {"asset_id": "82235234359303790318990338986894673350271665663072939428595924891405248197200", "price": "0.32", "size": "399.99", "side": "SELL", "hash": "c45655d320c343e6a8c804eb199b1d4b372882a1", "best_bid": "0.28", "best_ask": "0.3"}], "timestamp": "1769384758967", "event_type": "price_change"}}
{"_local_timestamp": "2026-01-25T23:46:10.668049+00:00", "data": {"market": "0x91e0a718041ddbf0855fb655cfcb5944636b33ce8ccaaee7dce0940aa80465ab", "price_changes": [{"asset_id": "88263981208537093410063459148292369268178576306830494146004574288996908107420", "price": "0.21", "size": "0", "side": "BUY", "hash": "c63a9a2d76387d2b5b63ab72ccdc75f6b0afe863", "best_bid": "0.7", "best_ask": "0.72"}, {"asset_id": "82235234359303790318990338986894673350271665663072939428595924891405248197200", "price": "0.79", "size": "0", "side": "SELL", "hash": "6be8c806d26d4c96c88def08413e432f323291ad", "best_bid": "0.28", "best_ask": "0.3"}], "timestamp": "1769384770461", "event_type": "price_change"}}
{"_local_timestamp": "2026-01-25T23:47:09.610067+00:00", "data": {"market": "0x91e0a718041ddbf0855fb655cfcb5944636b33ce8ccaaee7dce0940aa80465ab", "price_changes": [{"asset_id": "88263981208537093410063459148292369268178576306830494146004574288996908107420", "price": "0.22", "size": "2031.18", "side": "BUY", "hash": "c7f7460c867e645d60ec52bbd94c0dcffdb8b2c9", "best_bid": "0.7", "best_ask": "0.72"}, {"asset_id": "82235234359303790318990338986894673350271665663072939428595924891405248197200", "price": "0.78", "size": "2031.18", "side": "SELL", "hash": "e4a35a3983ce6ef9094248cffc1f752b925319c9", "best_bid": "0.28", "best_ask": "0.3"}], "timestamp": "1769384829471", "event_type": "price_change"}}
{"_local_timestamp": "2026-01-25T23:48:20.860784+00:00", "data": {"market": "0xbb6e02d1b77e26964331305ca9f12da8c6f676e1efe893372485425becbed223", "price_changes": [{"asset_id": "110473274803190513305909771926634978036732087892207534963402259650286946307044", "price": "0.002", "size": "44.28", "side": "BUY", "hash": "bf40f0ba56d1a2c91dce790d5c907be34cee0d89", "best_bid": "0.959", "best_ask": "0.975"}, {"asset_id": "84564904382008311962069365288283225167949742624603481609433520601697502508513", "price": "0.998", "size": "44.28", "side": "SELL", "hash": "c8ef15ec87971c2e7c28bb82bf8765eb4b1f7d0d", "best_bid": "0.025", "best_ask": "0.041"}], "timestamp": "1769384900793", "event_type": "price_change"}}
{"_local_timestamp": "2026-01-25T23:48:31.074876+00:00", "data": {"market": "0xbb6e02d1b77e26964331305ca9f12da8c6f676e1efe893372485425becbed223", "price_changes": [{"asset_id": "84564904382008311962069365288283225167949742624603481609433520601697502508513", "price": "0.012", "size": "0", "side": "BUY", "hash": "84f38afceeb6a4523b66cc696b8e81cd12ace595", "best_bid": "0.025", "best_ask": "0.041"}, {"asset_id": "110473274803190513305909771926634978036732087892207534963402259650286946307044", "price": "0.988", "size": "0", "side": "SELL", "hash": "a1a4a06522a24464db953410f3971c8a0e5008c1", "best_bid": "0.959", "best_ask": "0.975"}], "timestamp": "1769384910995", "event_type": "price_change"}}
{"_local_timestamp": "2026-01-25T23:48:31.393875+00:00", "data": {"market": "0xbb6e02d1b77e26964331305ca9f12da8c6f676e1efe893372485425becbed223", "price_changes": [{"asset_id": "84564904382008311962069365288283225167949742624603481609433520601697502508513", "price": "0.012", "size": "8.94", "side": "BUY", "hash": "0b9290ef50b66e3ccdd8586b4973b307d3d84803", "best_bid": "0.025", "best_ask": "0.041"}, {"asset_id": "110473274803190513305909771926634978036732087892207534963402259650286946307044", "price": "0.988", "size": "8.94", "side": "SELL", "hash": "5a46741d9a149064da040a35c85d282710f0c061", "best_bid": "0.959", "best_ask": "0.975"}], "timestamp": "1769384911310", "event_type": "price_change"}}
{"_local_timestamp": "2026-01-25T23:49:51.233952+00:00", "data": {"market": "0x91e0a718041ddbf0855fb655cfcb5944636b33ce8ccaaee7dce0940aa80465ab", "price_changes": [{"asset_id": "88263981208537093410063459148292369268178576306830494146004574288996908107420", "price": "0.22", "size": "123.18", "side": "BUY", "hash": "d868111650de22a88106be11f64f7b73196c8560", "best_bid": "0.7", "best_ask": "0.72"}, {"asset_id": "82235234359303790318990338986894673350271665663072939428595924891405248197200", "price": "0.78", "size": "123.18", "side": "SELL", "hash": "334b91367fad8a4afd023bbd258f9207d99a9c23", "best_bid": "0.28", "best_ask": "0.3"}], "timestamp": "1769384991044", "event_type": "price_change"}}
{"_local_timestamp": "2026-01-25T23:49:53.443814+00:00", "data": {"market": "0x91e0a718041ddbf0855fb655cfcb5944636b33ce8ccaaee7dce0940aa80465ab", "price_changes": [{"asset_id": "88263981208537093410063459148292369268178576306830494146004574288996908107420", "price": "0.21", "size": "1998", "side": "BUY", "hash": "787b9b5721570277fa122e45125da6dd43db2630", "best_bid": "0.7", "best_ask": "0.72"}, {"asset_id": "82235234359303790318990338986894673350271665663072939428595924891405248197200", "price": "0.79", "size": "1998", "side": "SELL", "hash": "dc58477ad4a56932ea92805ad154cc78090808c0", "best_bid": "0.28", "best_ask": "0.3"}], "timestamp": "1769384993366", "event_type": "price_change"}}
{"_local_timestamp": "2026-01-25T23:50:02.830351+00:00", "data": {"market": "0x91e0a718041ddbf0855fb655cfcb5944636b33ce8ccaaee7dce0940aa80465ab", "price_changes": [{"asset_id": "88263981208537093410063459148292369268178576306830494146004574288996908107420", "price": "0.16", "size": "0", "side": "BUY", "hash": "8cab7766fb61bcf5c3fefbaff61ac14b4de83774", "best_bid": "0.7", "best_ask": "0.72"}, {"asset_id": "82235234359303790318990338986894673350271665663072939428595924891405248197200", "price": "0.84", "size": "0", "side": "SELL", "hash": "f8380293a495682698a915bb2a94d75a9880d814", "best_bid": "0.28", "best_ask": "0.3"}], "timestamp": "1769385002297", "event_type": "price_change"}}
{"_local_timestamp": "2026-01-25T23:50:03.149289+00:00", "data": {"market": "0x91e0a718041ddbf0855fb655cfcb5944636b33ce8ccaaee7dce0940aa80465ab", "price_changes": [{"asset_id": "88263981208537093410063459148292369268178576306830494146004574288996908107420", "price": "0.12", "size": "6", "side": "BUY", "hash": "14a17a8d88d157007c4e4a30784c0c1f2f9277b6", "best_bid": "0.7", "best_ask": "0.72"}, {"asset_id": "82235234359303790318990338986894673350271665663072939428595924891405248197200", "price": "0.88", "size": "6", "side": "SELL", "hash": "c9afcb6f403ddd4b79a24114f9bab9e2da7af3a9", "best_bid": "0.28", "best_ask": "0.3"}], "timestamp": "1769385002725", "event_type": "price_change"}}
{"_local_timestamp": "2026-01-25T23:50:18.047252+00:00", "data": {"market": "0x91e0a718041ddbf0855fb655cfcb5944636b33ce8ccaaee7dce0940aa80465ab", "price_changes": [{"asset_id": "88263981208537093410063459148292369268178576306830494146004574288996908107420", "price": "0.08", "size": "3758.21", "side": "BUY", "hash": "be56c940d7f42b98c33dd88d39cc10d0c5d9a7ef", "best_bid": "0.7", "best_ask": "0.72"}, {"asset_id": "82235234359303790318990338986894673350271665663072939428595924891405248197200", "price": "0.92", "size": "3758.21", "side": "SELL", "hash": "c5bb03e4ba78b5a384876b99e3de4c22771c223f", "best_bid": "0.28", "best_ask": "0.3"}], "timestamp": "1769385017958", "event_type": "price_change"}}
{"_local_timestamp": "2026-01-25T23:50:18.782848+00:00", "data": {"market": "0x91e0a718041ddbf0855fb655cfcb5944636b33ce8ccaaee7dce0940aa80465ab", "price_changes": [{"asset_id": "88263981208537093410063459148292369268178576306830494146004574288996908107420", "price": "0.12", "size": "1338", "side": "BUY", "hash": "421f68fec3bde762a53614dcbaddacfa4d8b580e", "best_bid": "0.7", "best_ask": "0.72"}, {"asset_id": "82235234359303790318990338986894673350271665663072939428595924891405248197200", "price": "0.88", "size": "1338", "side": "SELL", "hash": "bbb3dbe14841322e303172d6005eea1fe7d6bd10", "best_bid": "0.28", "best_ask": "0.3"}], "timestamp": "1769385018708", "event_type": "price_change"}}
{"_local_timestamp": "2026-01-25T23:50:41.621112+00:00", "data": {"market": "0x91e0a718041ddbf0855fb655cfcb5944636b33ce8ccaaee7dce0940aa80465ab", "price_changes": [{"asset_id": "88263981208537093410063459148292369268178576306830494146004574288996908107420", "price": "0.08", "size": "3750", "side": "BUY", "hash": "9978ce3f9e4c474bb03f601a38ebec4d8069bd0a", "best_bid": "0.7", "best_ask": "0.72"}, {"asset_id": "82235234359303790318990338986894673350271665663072939428595924891405248197200", "price": "0.92", "size": "3750", "side": "SELL", "hash": "58b9fe4831e7a500b84181cff2cdf710cbada00f", "best_bid": "0.28", "best_ask": "0.3"}], "timestamp": "1769385041541", "event_type": "price_change"}}
{"_local_timestamp": "2026-01-25T23:50:42.213566+00:00", "data": {"market": "0x91e0a718041ddbf0855fb655cfcb5944636b33ce8ccaaee7dce0940aa80465ab", "price_changes": [{"asset_id": "88263981208537093410063459148292369268178576306830494146004574288996908107420", "price": "0.09", "size": "7.29", "side": "BUY", "hash": "154366e9c40f09d8a7d6d8e4660c98ab4bcae098", "best_bid": "0.7", "best_ask": "0.72"}, {"asset_id": "82235234359303790318990338986894673350271665663072939428595924891405248197200", "price": "0.91", "size": "7.29", "side": "SELL", "hash": "db7a713603e0fcabf5fe88060a9dd12d165f054d", "best_bid": "0.28", "best_ask": "0.3"}], "timestamp": "1769385041898", "event_type": "price_change"}}
